model
size = 5 32 9, scale = 0.05, origin = -y
material 
  colors = A:#FC0 B:#DDD C:#FC6 D:#444 E:#E00
voxels
31-3A8-2(A4-)A133-3A2-3A3-A14-2(A4-)A123-2(3A2-)4(ABA2-)ABA3-17(B4-)B13-2(3C2-3A2-)3C2-3A-2CB3CABA2CABAC-ABA3-20(B4-)B8-2(CBC2-ABA2-)CBC2-ABA-2CB2CEADAECADAC-ADA2-ADA3-18(D4-)2(B4-)B3-2(3C2-3A2-)3C2-3A-2CB3CABA2CABAC-ABA3-20(B4-)B33-2(3A2-)4(ABA2-)ABA3-17(B4-)B38-3A2-3A3-A14-2(A4-)A128-3A8-2(A4-)A107-
