model
size = 20 24 10, scale = 0.05, origin = -y
material 
  colors = A:#D00 B:#EEE C:#00F D:#222
voxels
-------------------- -------------------- -------------------- -------------------- -------------------- -------------------- ----------AA-------- ----------AA-------- -------------------- -------------------- -------------------- -------------------- -------------------- -------------------- -------------------- -------------------- -------------------- -------------------- -------------------- -------------------- -------------------- -------------------- -------------------- -------------------- 
-------------------- -------------------- -------------------- ---------AAA-------- --------AAAAA------- -------AAAAAA------- -------AAAAAA------- -------AAAAAA------- --------AAAAA------- -------------------- -------------------- -------------------- -------------------- -------------------- -------------------- -------------------- -------------------- -------------------- -------------------- -------------------- -------------------- -------------------- -------------------- -------------------- 
-------------------- -------------------- ---------AAAA------- -------AAAAAA------- -------AAAAAAA------ ------AAAAAAAA------ ------AAAAAAAAA----- ------AAAAAAAA------ ------AAAAAAAA------ --------AAAAA------- ----------A--------- -------------------- -------------------- -------------------- -------------------- -------------------- -------------------- -------------------- -------------------- -------------------- -------------------- -------------------- -------------------- -------------------- 
-------------------- ---------AAA-------- -------AAAAAA------- ------AAAAAAAA------ ------AAAAAAAAA----- -----AAAAAAAAAA----- -----AAAAAAAAAA----- -----AAAAAAAAAA----- ------AAAAAAAAA----- -------AAAAAAA------ --------AAAAA------- -------------------- -------------------- -------------------- -------------------- -------------------- -------------------- -------------------- ----D----------D---- ---DDD--------DDD--- ----D----------D---- -------------------- -------------------- -------------------- 
-------------------- --------AAAAA------- -------AAAAAAA------ ------AAAAAAAAA----- -----AAAAAAAAAA----- -----AAAAAAAAAAA---- -----AAAAAAAAAAA---- -----AAAAAAAAAAA---- -----AAAAAAAAAAA---- ------AAAAAAAA------ -------AAAAAA------- ---------AAAA------- -------------------- -------------------- -------------------- -------------------- --CCCCC------CCCCC-- -CCCDCCC----CCCDCCC- -CCDDDCC----CCDDDCC- -CDDDDDC----CDDDDDC- -CCDDDCC----CCDDDCC- -CCCDCCC----CCCDCCC- --CCCCC------CCCCC-- -------------------- 
-------------------- -------AAAAAA------- ------AAAAAAAA------ -----AAAAAAAAAA----- -----AAAAAAAAAAA---- -----AAAAAAAAAAA---- -----AAAAAAAAAAA---- -----AAAAAAAAAAA---- -----AAAAAAAAAAA---- ------AAAAAAAAA----- -------AAAAAAA------ --------AAAAA------- -------------------- -------------------- -------------------- --BBBBB------BBBBB-- -BBBBBBB----BBBBBBB- BBBBBBBBB--BBBBBBBBB BBBBBBBBB--BBBBBBBBB BBBBBBBBB--BBBBBBBBB BBBBBBBBB--BBBBBBBBB BBBBBBBBB--BBBBBBBBB -BBBBBBB----BBBBBBB- --BBBBB------BBBBB-- 
----------AA-------- -------AAAAAA------- ------AAAAAAAAA----- -----AAAAAAAAAA----- -----AAAAAAAAAAA---- -----AAAAAAAAAAA---- ----AAAAAAAAAAAA---- ----AAAAAAAAAAAA---- -----AAAAAAAAAAA---- ------AAAAAAAAA----- ------AAAAAAAA------ --------AAAAA------- -------------------- -------------------- -------------------- --BBBBB------BBBBB-- -BBBBBBB----BBBBBBB- BBBBBBBBB--BBBBBBBBB BBBBBBBBB--BBBBBBBBB BBBBBBBBB--BBBBBBBBB BBBBBBBBB--BBBBBBBBB BBBBBBBBB--BBBBBBBBB -BBBBBBB----BBBBBBB- --BBBBB------BBBBB-- 
----------AA-------- -------AAAAAA------- ------AAAAAAAA------ -----AAAAAAAAAA----- -----AAAAAAAAAAA---- -----AAAAAAAAAAA---- ----AAAAAAAAAAAA---- ----AAAAAAAAAAAA---- -----AAAAAAAAAAA---- ------AAAAAAAAA----- -------AAAAAAA------ --------AAAAA------- -------------------- -------------------- -------------------- --BBBBB------BBBBB-- -BBBBBBB----BBBBBBB- BBBBBBBBB--BBBBBBBBB BBBBBBBBB--BBBBBBBBB BBBBBBBBB--BBBBBBBBB BBBBBBBBB--BBBBBBBBB BBBBBBBBB--BBBBBBBBB -BBBBBBB----BBBBBBB- --BBBBB------BBBBB-- 
-------------------- --------AAAAA------- ------AAAAAAAA------ ------AAAAAAAAA----- -----AAAAAAAAAAA---- -----AAAAAAAAAAA---- -----AAAAAAAAAAA---- -----AAAAAAAAAAA---- -----AAAAAAAAAAA---- ------AAAAAAAAA----- -------AAAAAAA------ --------AAAAA------- -------------------- -------------------- -------------------- ---BBB--------BBB--- -BBBBBBB----BBBBBBB- BBBBBBBB---BBBBBBBB- BBBBBBBBB--BBBBBBBBB BBBBBBBBB--BBBBBBBBB BBBBBBBBB--BBBBBBBBB -BBBBBBB---BBBBBBBB- -BBBBBBB----BBBBBBB- ---BBB--------BBB--- 
-------------------- -------------------- --------AAAAA------- -------AAAAAAA------ ------AAAAAAAA------ ------AAAAAAAAA----- ------AAAAAAAAA----- ------AAAAAAAAA----- ------AAAAAAAAA----- -------AAAAAA------- ---------AAAA------- -------------------- -------------------- -------------------- -------------------- ----B----------B---- --BBBBB------BBBBB-- -BBBBBBB----BBBBBBB- BBBBBBBB----BBBBBBB- BBBBBBBBB--BBBBBBBBB -BBBBBBB----BBBBBBB- -BBBBBBB----BBBBBBB- --BBBBB------BBBBB-- ----B----------B---- 
