model
size = 28 32 14, scale = 0.05, origin = -y
material 
  colors = A:#E00 B:#111 C:#888 D:#777 E:#C00 F:#800 G:#BBB H:#222 I:#444 J:#400
voxels
209-B26-A27-2A2(26-AB)2AB22-BAB2AB21-B2AB-2A21-B2A2B2A21-BAB2ABA21-2B4AB21-B6A22-B4AB22-2B2A2B24-3B444-A27-A24-2(AB)3-A20-3AJB3AB19-2AJAJ-2AEB16-2ABAJ2A-A2EB15-4AB2AB-AEB2A14-2(AF)AJAB2AB7A9-AF3-FBAB2ABA15-F4-2(B2A2B2AB20-)BAB2ABA2(B20-B6A)B20-2B4A2B20-BAB2ABAB19-2BA4BA2B17-B-B2A2B2-B-B17-2AB-B22-2AB-2B21-A-2B24-2AB25-AB26-AB27-B168-A2-AB-B5-A12-2(AB)3(3AB)A10-AB7AB3A2(B2A)8-AB3AB4AB5A2(BA)9-4(AB)A2B3AB2AEB7-AE2AB5AB3ABABE3A7-E2ABAB5AB3ABAB3A8-AB3AB4AB3A2(B2A)7-AB5AB2A2B2AB4AB8-B9AB2AB8A6-EB2A3B2(AB)2ABA3BFBA7-E2A-4B2A2B2A4B-F2A6-EF2-4B2A2B2A4B2-F2(A6-)BAB2ABAB6-F13-2B4A2B20-B6AB20-2B4A2B19-2BAB2ABA2B17-3BA4BA3B16-BAB2A2B2AB-B14-3B2ABAB2AB2-3B12-2B2ABA4B-B2-2B12-BA2(2B3A)B2-B13-2AB3AB4A16-BAB2ABA2BAB2AB15-AB3AB-2B3AB14-2AB4AB5AB19-A112-2B2A16-B3ABA2BABA2B3AB2AB7-B3ABAB3AB7AB2AB5-2(BA)B7AB6AB3AB4-2(3AB)4AB5AB4AB3-3A5(BA)2B3AB6AB2-6AB5AB3ABAB4ABAB2-2B3ABAB5AB3ABAB4A2B3-2(3AB)4AB3A2(B2A)BA4-BAB5AB2A2B2AB4A2B2A4-AB9AB2AB9A4-2AB2A3B2(AB)2ABA3BABA2B4-4A5B2A2(BA)5B4A4-3A6B2A2H2A6B2AB4-EA2B2GC-BAB2ABAB-CG3B2A4-E2BG2C2-BH4AHB2-CG3BA4-E2BG3-CB6ABC3-G2BA5-2B2-GCGBH4AHBCGD2-2B9-3C2BAB2ABA2B2CD11-3C2B2A4B2A2B3C10-3CBAB2A2B2ABAB3C10-C3B2ABAH2AB2A3BC10-G2B2ABA4BAB2A2BC10-2BA2(2B3A)2BA2B10-2B2AB3AH4AB2A2B10-2(2BAB2ABA)2B9-3BAB3A4B3ABA3B8-2B2AB4AH5AB2A2B6-B-3(AB)3AH4A3(BA)-B4-2B2AB4AB-2B-B4AB3AB5-A2B4-B2-2B2-B4-BAB36-B2AB10AB2AB9-20A7-4(2A18-2A6-)2A18-2A5-3A18-3A4-B2A18-2AB3(4-3A18-3A)4-B2A18-2AB4-3A18-3A4-E2A2(18-3A4-3A)18-3A5-BA18-AB7-2(D18-D8-)I18-I3(8-D18-D)8-C18-C8-D18AD7-B20AB5-F23A4-AF22A4-24A5-ABA3-B4AB3AB3-ABA36-B16AB9-9A2-9A7-3(2A18-2A6-)BA18-AB6-2A18-2A5-2(3A18-3A4-)3(B2A18-2AB4-3A18-3A4-)3A18-3A4-E2A18-3A4-B2A18-2A4(B4-BDA18-AD)B4-BIA18-AIB4-BDA18-ADB4-BIA18-AIB4-BC9A2-9ACB3-FB10A2-10ABA3-11A2-11A4-24A4-E23A5-ABA2-B5AB4AB2-ABA9-16B11-A16-A9-A18-A7-B20-B2(6-A20-A)6-B20-B6-A20-A5-3(2A20-2A4-)BA20-AB3(4-2A20-2A)4-BA20-AB2(4-2A20-2A)9(4-BA20-AB)3-3A20-3A3-2A20-2A4-EA20-2A4-24A4-AB2A-B3ABAB2AB3AB-2ABA8-16A11-A16-A9-A18-A7-A20-A2(6-B20-B)2(6-A20-A)5-2(2A20-2A4-)BA20-AB5(4-2A20-2A)4-BA20-AB4-2A20-2A3-9(B2A20-2AB2-)3A20-3A3-EA20-2A4-2A20-2A4-24A4-3(B3A)B2A2(B3A)B8-16A11-2A14-2A9-A18-A7-2(B20-B6-)2(A20-A6-)A20-A5-2A20-2A4-BA20-AB6(4-2A20-2A)4-BA20-AB4-FA20-2A3-7(3A20-3A2-)2(E2A20-3A2-)E2A20-3A3-2(2A20-2A4-)B22AB4-3A2B3AB2A2(B3A)2B3A8-16A11-A16-A9-A18-A7-2(A20-A6-)B20-B2(6-A20-A)3-B7(3A20-3A2B)3(3A20-2AF2B)9(3A20-3A2B)3A20-3A3B2A20-2A2B2-BA20-AB4-24A4-2(2AB)AB3AB4ABA2(B2A)8-16A11-A16-A9-B18-B7-2(A20-A6-)B20-B2(6-A20-A)4-2(2A22-2A2-)3(BA22-AB5(2-2A22-2A)2-)BA22-AB3-A22-A4-2A20-2A4-AB4AB5A2(B4A)BA8-16A11-B16-B9-A18-A7-3(A20-A6-)B20-B6-B20-B4-2A22-2A2(2-BA22-AB)5(2-2A22-2A)2(2-BA22-AB2(2-2A22-2A))2-2A22-2A2-BA22-AB3(2-2A22-2A)2-BA22-AB2-2A22-2A3-2(A22-A4-)2(AB3AB)4ABAB3ABA8-B14AB11-A16-A9-A18-A7-2(A20-A6-)B20-B2(6-A20-A)4-2A22-2A2(2-BA22-AB2(2-2A22-2A))2-2A22-2A2(2-BA22-AB3(2-2A22-2A))2-BA22-AB2(2-2A22-2A)2-BA22-AB2-2A22-2A3-2(A22-A4-)B4AB2A2BAB2A2B2AB4AB8-16A11-A16-A9-A18-A7-A20-A2(6-B20-B)2(6-A20-A)4-4(2A22-2A2-)3(BA22-AB2-2A22-2A2-)6(2A22-2A2-)2(BA22-AB2-2A22-2A2-)2A22-2A3-2(A22-A4-)4AB7AB6AB4A2-
