model
size = 15 15 30, scale = 0.05, origin = -y
material 
  colors = A:#FFF B:#9BADB7 C:#FFFEFE D:#D0980C E:#5B6EE1 F:#A7A7A7 G:#0030D4 H:#0038D4 I:#696A6A J:#EFEFEF K:#BFBFBF L:#F7F7F7 M:#DFDFDF N:#0018CC O:#979797 P:#C7C7C7 Q:#7F7F7F R:#E7E7E7
voxels
--BBBBBBBBBBB-- --AABBBBBBBAA-- --AAABBBBBAAA-- --AAAADADAAAA-- --AAAADADAAAA-- --AAAADADAAAA-- --AAAADADAAAA-- --AAAADADAAAA-- --AAAADADAAAA-- --FAAADADAAAF-- ---FFFFFFFFF--- --------------- --------------- --------------- --------------- 
-BBBBBBBBBBBBB- -AAAAAAAAAAAAA- -A-----------A- -A-----------A- -A-----------A- -A------D----A- -AAAAAAAAAA-AA- -AAAAAAAAAA-AA- -AAAAAAAAAAAAA- -F-----------F- --------------- --------------- --------------- --------------- --------------- 
-BBBBBBBBBBBBB- -AAAAAAAAAAAAA- -A-----------A- -A-----------A- -A-----------A- -A----D------A- -AAAAAAAAAA-AA- -AAAAAAAAAA-AA- -AAA-------AAA- -F-----------F- --------------- --------------- --------------- --------------- --------------- 
-BBBBBBBBBBBBB- -AAAAAAAAAAAAA- -A-----------A- -A-----------A- -A-----------A- -A-----------A- -AAAAAAAAAA-AA- -AAAAAAAAAA-AA- -AAA-------AAA- -F-----------F- --------------- --------------- --------------- --------------- --------------- 
-BBBBBBBBBBBBB- -AAAAAAAAAAAAA- -A-----------A- -A-----------A- -D-----------A- -A-----------A- DDAAAAAAAAA-AA- -AAAAAAAAAA-AA- -AAA-------AAA- -A-----------A- --------------- --------------- --------------- --------------- --------------- 
-BBBBBBBBBBBBB- -AAAAAAAAAAAAA- -A-----------A- -D-----------D- DA-----------D- -D-----------DD DAAAAAAAAAA-AD- -DAAAAAAAAA-ADD -AAA-------AAA- -A-----------A- --------------- --------------- --------------- --------------- --------------- 
-BBBBBBBBBBBBB- DDAAAAAAAAAAAD- DD-----------DD -D-----------D- -A-----------A- -D-----------D- -AAAAAAAAAA-AA- -DAAAAAAAAA-AD- DDAA-------AAD- -D-----------DD --------------- --------------- --------------- --------------- --------------- 
-BBBBBBBBBBBBB- -AAAAAAAAAAAAA- -A-----------A- -D-----------D- -A-----------A- -D-----------DD -AAAAAAAAAA-AA- -DAAAAAAAAA-AD- -AAA-------AAA- -A-----------A- --------------- --------------- --------------- --------------- --------------- 
-BBBBBBBBBBBBB- -DAAAAAAAAAAAD- -D-----------DD DD-----------DD -A-----------A- -D-----------D- -AAAAAAAAAA-AA- -DAAAAAAAAA-ADD -DAA-------AAD- DD-----------D- --------------- --------------- --------------- --------------- --------------- 
-BBBBBBBBBBBBB- -AAAAAAAAAAAAA- -A-----------A- DD-----------D- DD-----------A- -D-----------DD DDAAAAAAAAA-AA- -DAAAAAAAAA-AD- -AAA-------AAA- -A-----------A- --------------- --------------- --------------- --------------- --------------- 
-BBBBBBBBBBBBB- -AAAAAAAAAAAAA- -A-----------A- -A-----------A- -A-----------D- -A-----------A- -AAAAAAAAAA-AD- -AAAAAAAAAA-AA- -AAA-------AAA- -A-----------A- --------------- --------------- --------------- --------------- --------------- 
-BBBBBBBBBBBBB- -AAAAAAAAAAAAA- -A-----------A- -A-----------A- -A-----------A- -A-----------J- -AAAAAAAAAA-AA- -AAAAAAAAAA-AA- -AAA-------AAA- -F-----------F- --------------- --------------- --------------- --------------- --------------- 
-BBBBBBBBBBBBB- -AAAAAAAAAAAAA- -A-----------A- -A-----------A- -A-----------A- -A-----------A- -AAAAAAAAAA-AA- -AAAAAAAAAA-AA- -AAA-------AAA- -F-----------F- --------------- --------------- --------------- --------------- --------------- 
-BBBBBBBBBBBBB- -AAAAAAAAAAAAA- -Q-----------A- -A-----------P- -A-----------A- -J-----------M- -AAAAAAAAAA-AA- -AAAAAAAAAA-AK- -FAA-------AAA- -F-----------F- --------------- --------------- --------------- --------------- --------------- 
-BBBBBBBBBBBBB- -AAAAAAAAAAAAA- -A-----------A- -A-----------J- -AA-A--------A- -A-----------A- -AAAAAAAAAA-AA- -FAAAAAAAAA-AA- --AAAAAAAAAAAA- -F-----------F- --------------- --------------- --------------- --------------- --------------- 
-BBBBBBBBBBBBB- -AAAAAAAAA-AAA- -AAAAAAAAA-AAA- -AAAAAAAAA-AAJ- -AAAAAAAAA-AAJ- -J--AAAAAA-AAA- -AAAAAAAAAAAAM- -AAAAAAAAAAAAA- --AAAAAAAAA--A- -FFAAAAAAA---F- ---AAAA-AAA-A-- --ADDADDDADDA-- --AAAAAAAAAAA-- -ADDAADDDAADDA- -AAAAAAAAAAAAA- 
-BBBBBBBBBBCBB- -AAAAAAAAAAA-A- -AA-AAAAAA---A- -AA-AAAAAA---A- -M--AAAAAA--AA- -A--AAAAAA--AA- -AC-AAAAAA--AA- -AAAAAAAAAAAAA- ---AADDDDDAAA-- ----DDDDDDDAF-- --AA--AAA--AA-- --------------- --------------- --------------- --------------- 
-BBBBBBCCBBBBB- -A-AAAAAAAAA-A- -AAA-----A---A- -AAA---------A- -ACA--------AA- -CCA--------AA- -CC---------A-- ---HHHHHHHHH--- --------------- --------------- --------------- --------------- --------------- --------------- --------------- 
-BBBBBBBCBBCBB- -A---B--C----A- -P-A---KLCC--A- -A-----------A- -KC---------AA- -AC---------AA- -CC---------AA- --HHHHHHHHHHH-- --------------- --------------- --------------- --------------- --------------- --------------- --------------- 
-BBBCBBBCBCCBB- -A------CC---A- -C------CCC--A- -C-----------J- -C-A--------AA- -CC---------AA- --CH--------A-- ---HHHHHHHHH--- --------------- --------------- --------------- --------------- --------------- --------------- --------------- 
-BB-CBBBBCCCBB- -AL------CC--A- -C------CCC--A- -K------CC---A- -CC------A--AA- --C---------A-- ---GGGGGGGGG--- --------------- --------------- --------------- --------------- --------------- --------------- --------------- --------------- 
-BBBCBBBBCCCBB- -LL-------C--A- -C-----------J- -C-------A---A- -CC---------AA- -CC---------AA- --GGGGGGGGGGG-- --------------- --------------- --------------- --------------- --------------- --------------- --------------- --------------- 
-BBBBCBBCBCCBB- -ACA-----CCA-A- -C----------AA- -C-----------A- -CC---------AA- --CNGGG-----A-- ---NGGGGGGGG--- --------------- --------------- --------------- --------------- --------------- --------------- --------------- --------------- 
-BBBBCBCCBCBBB- -A-CA---CCAAAA- -C------AC---A- -C-------A---A- --CC--------A-- ---EEEEEEEEE--- --------------- --------------- --------------- --------------- --------------- --------------- --------------- --------------- --------------- 
-BBBBCCBBBCCBB- -A-------CBCAA- -O-------CCCAR- -CC----------A- -CCEE-------AA- --EEEEEEEEEEE-- --------------- --------------- --------------- --------------- --------------- --------------- --------------- --------------- --------------- 
-BBBBCCCCBBBBB- -A-----C-CB-AA- -CCA--------AA- -CCC-E-------A- --CEEEEEEEEAA-- ---EEEEEEEEE--- --------------- --------------- --------------- --------------- --------------- --------------- --------------- --------------- --------------- 
-BBBBBCCBBBBBB- -OA---CC--B-AA- -C-A--------AA- -CCCCC-C----AA- ---CCCCICCCA--- --------------- --------------- --------------- --------------- --------------- --------------- --------------- --------------- --------------- --------------- 
-BBBBCCCCIBCBB- -AACI-------AA- -ACC--------AA- --CACCCI-ICCA-- ----CICICIC---- --------------- --------------- --------------- --------------- --------------- --------------- --------------- --------------- --------------- --------------- 
--BBBBICBIBBB-- --AC-------CA-- --AC--CI---CA-- ---AICCICCIC--- --------------- --------------- --------------- --------------- --------------- --------------- --------------- --------------- --------------- --------------- --------------- 
---BBBBBBBBB--- ---ICCCICCCI--- ---ICCCICCCI--- ---ICAAIAAAI--- --------------- --------------- --------------- --------------- --------------- --------------- --------------- --------------- --------------- --------------- --------------- 
