model
size = 23 24 16, scale = 0.05, origin = -y
material 
  colors = A:#BBB B:#444
voxels
----------------------- ----------------------- ----------------------- ----------------------- ----------------------- ----------------------- ----------------------- -------A-A-A-A-A------- -------A-A-A-A-A------- -------AAAAAAAAA------- -----AAAAAAAAAAAAA----- ----AAAAAA---AAAAAA---- ----AAAAAA---AAAAAA---- ---AAAAAAAA-AAAAAAAA--- ---AA---AAAAAAA---AA--- ---A-----AAAAA-----A--- ---A-----AAAAA-----A--- ---AA---AAAAAAA---AA--- ----AAAAAAAAAAAAAAA---- -----AAAAAAAAAAAAA----- --------AAAAAAA-------- ----------------------- ----------------------- ----------------------- 
----------AAA---------- --------AAAAAAA-------- ----------------------- ----------------------- ----------------------- -------A-A-A-A-A------- -------A-A-A-A-A------- -------ABA-A-ABA------- ------A-B-B-B-B-A------ ------A---------A------ ----AA---AAAAA---AA---- ---A----A-----A----A--- ---A-----A---A-----A--- --A-------A-A-------A-- --A--BBB---A---BBB--A-- --A-B---B-----B---B-A-- --A-B---B-----B---B-A-- --A-A---A-----A---A-A-- ---A-BBB-------BBB-A--- ---AA-------------AA--- -----AAA-------AAA----- -------AAAAAAAAA------- ----------------------- ----------------------- 
---------AAAAA--------- -------AAA-A-AAA------- --------A-A-A-A-------- --------A-A-A-A-------- ----------------------- -------A-A-A-A-A------- -------AB-B-B-BA------- ------A---B-B---A------ ------A---------A------ -----A-----------A----- ---AA-------------AA--- ---A-----ABBBA-----A--- --A-------BBB-------A-- --A--------B--------A-- -A----B---------B----A- -A---B-B-------B-B---A- --A--B-B-------B-B--A-- --A--BBB-------BBB--A-- --A-----------------A-- ---A---------------A--- ----AA-----------AA---- ------AA-------AA------ --------AAAAAAA-------- ----------------------- 
--------AAAAAAA-------- ------AA-A-A-A-AA------ --------A-A-A-A-------- --------A-A-A-A-------- -------A-------A------- -------ABABABABA------- ------A---------A------ ------A---------A------ -----A-----------A----- ----A-------------A---- ---A---------------A--- --A-----------------A-- --A-----------------A-- -A-------------------A- -A-------------------A- -A----B---------B----A- -A----B---------B----A- --A-----------------A-- --A-----------------A-- ---A---------------A--- ----A-------------A---- -----AA---------AA----- -------AAAAAAAAA------- ----------------------- 
-------AAAAAAAAA------- ------A---------A------ -------A-B-B-B-A------- -------AA-A-A-AA------- -------A-------A------- -------AAAAAAAAA------- ------A---------A------ ------A---------A------ -----A-----------A----- ---AA-------------AA--- ---A---------------A--- --A-----------------A-- --A-----------------A-- -A-------------------A- -A-------------------A- -A-------------------A- -A-------------------A- --A-----------------A-- --A-----------------A-- --A-----------------A-- ---A---------------A--- ----AA-----------AA---- ------AAAA---AAAA------ ----------AAA---------- 
--------AAAAAAA-------- ------AA-------AA------ -------A---B---A------- -------AABA-ABAA------- -------A-------A------- -------AAAAAAAAA------- ------A---------A------ -----A-----------A----- -----A-----------A----- ---AA-------------AA--- --A-----------------A-- --A-----------------A-- -A-------------------A- A---------------------A A---------------------A A---------------------A A---------------------A -A-------------------A- -A-------------------A- --A-----------------A-- --A-----------------A-- ---AA-------------AA--- -----A-----------A----- ------AAAAAAAAAAA------ 
------AAAAAAAAAAA------ ------A---------A------ ------A----B----A------ -------AAAA-AAAA------- -------A-------A------- ------A-AAAAAAA-A------ ------A---------A------ -----A-----------A----- ----A-------------A---- ---A---------------A--- --A-----------------A-- --A-----------------A-- -A-------------------A- -A-------------------A- A---------------------A A---------------------A -A-------------------A- -A-------------------A- -A-------------------A- --A-----------------A-- --A-----------------A-- ---AA-------------AA--- -----AA---------AA----- -------AAAAAAAAA------- 
------AAAAAAAAAAA------ ------A---------A------ ------A----B----A------ ------A-AAA-AAA-A------ -------A-------A------- ------A-AAAAAAA-A------ ------A---------A------ -----A-----------A----- ----A-------------A---- ---A---------------A--- --A-----------------A-- --A-----------------A-- -A-------------------A- -A-------------------A- A---------------------A A---------------------A -A-------------------A- -A-------------------A- -A-------------------A- --A-----------------A-- --AA---------------AA-- ----A-------------A---- -----AA---------AA----- -------AAAAAAAAA------- 
------AAAAAAAAAAA------ -------A-------A------- -------A---B---A------- ------A-AAA-AAA-A------ -----AAA-------AAA----- -----A--AAAAAAA--A----- ------A---------A------ -----A-----------A----- ----A-------------A---- ---A---------------A--- --A-----------------A-- --A-----------------A-- -A-------------------A- -A-------------------A- A---------------------A A---------------------A -A-------------------A- -A-------------------A- -A-------------------A- --A-----------------A-- --A-----------------A-- ---AA-------------AA--- -----AA---------AA----- -------AAAAAAAAA------- 
---------AAAAA--------- --------A-----A-------- -------A---B---A------- -------AAAA-AAAA------- ------AA-------AA------ -----A--AAAAAAA--A----- -----A-----------A----- -----A-----------A----- -----A-----------A----- ---AA-------------AA--- --A-----------------A-- --A-----------------A-- -A-------------------A- -A-------------------A- -A-------------------A- -A-------------------A- -A-------------------A- -A-------------------A- --A-----------------A-- --A-----------------A-- ---A---------------A--- ----A-------------A---- -----AAA-------AAA----- --------AAAAAAA-------- 
----------------------- ---------AAAAA--------- --------AA-B-AA-------- --------A-A-A-A-------- ----------------------- ------AAAAAAAAAAA------ -----A-----------A----- -----A-----------A----- -----A-----------A----- ---AA-------------AA--- ---A---------------A--- --A-----------------A-- --A-----------------A-- -A-------------------A- -A-------------------A- -A-------------------A- -A-------------------A- --A-----------------A-- --A-----------------A-- --A-----------------A-- ---A---------------A--- ----AA-----------AA---- ------AAAA---AAAA------ ----------AAA---------- 
----------------------- ----------------------- ---------AABAA--------- --------AAABAAA-------- -------ABBBBBBBA------- -------AAAAAAAAA------- ------A---------A------ ------A---------A------ -----A-----------A----- ----AA-----------AA---- ---AA-------------AA--- ---A---------------A--- --A-----------------A-- --A-----------------A-- -A-------------------A- -A-------------------A- -A-------------------A- --A-----------------A-- --A-----------------A-- ---A---------------A--- ----A-------------A---- -----AAA-------AAA----- -------AAAA-AAAA------- -----------A----------- 
----------------------- ----------------------- ----------------------- ----------------------- ----------------------- ----------------------- -------AAAAAAAAA------- ------AAAAAAAAAAA------ ------AA-------AA------ ------A---------A------ -----AA---------AA----- ----AA-----------AA---- ---AAA-----------AAA--- ---AA-------------AA--- --AA---------------AA-- --AA---------------AA-- --AA---------------AA-- --AA---------------AA-- ---A---------------A--- ---AA-------------AA--- ----AAAA-------AAAA---- --------A-----A-------- ---------AAAAA--------- ----------------------- 
----------------------- ----------------------- ----------------------- ----------------------- ----------------------- ----------------------- ----------------------- ----------------------- --------AAAAAAA-------- -------AAAAAAAAA------- -------AA-----AA------- ------AA-------AA------ ------AA-------AA------ -----AA---------AA----- ----A-------------A---- ----A-------------A---- ----A-------------A---- ----A-------------A---- ----AA-----------AA---- -----AAAA-----AAAA----- -------AAAA-AAAA------- ---------AAAAA--------- ----------------------- ----------------------- 
----------------------- ----------------------- ----------------------- ----------------------- ----------------------- ----------------------- ----------------------- ----------------------- ----------------------- ----------------------- ---------AAAAA--------- --------AAAAAAA-------- --------AA---AA-------- -------AA-----AA------- -----AAA-------AAA----- -----A-----------A----- -----A-----------A----- -----AA---------AA----- ------AAAAAAAAAAA------ ---------AAAAA--------- -----------A----------- ----------------------- ----------------------- ----------------------- 
----------------------- ----------------------- ----------------------- ----------------------- ----------------------- ----------------------- ----------------------- ----------------------- ----------------------- ----------------------- ----------------------- ----------------------- ----------AAA---------- ---------AAAAA--------- --------AAAAAAA-------- ------AAAAAAAAAAA------ ------AAAAAAAAAAA------ -------AAAAAAAAA------- ----------------------- ----------------------- ----------------------- ----------------------- ----------------------- ----------------------- 
