model
size = 32 11 32, scale = 0.05, origin = -y
material 
  colors = A:#111 B:#E00 C:#0E0 D:#800 E:#080
voxels
2(-30A-34AE11CE2AD11BD5(4A13C2A13B)4AE11CE2AD11BD66A)22(256-2A2(28-4A)28-2A)224-2A2(28-4A)28-2A256-7(2A2(28-4A)28-2A224-)
