model
size = 12 8 10, scale = 0.05, origin = -y
material 
  colors = A:#E00 B:#EEE
voxels
---BBBB----- ---BBBB----- ------------ ------------ ------------ ------------ ------------ ------------ 
--B----B---- --BBBBBB---- ---AAAA----- ---AAAA----- ------------ ------------ ------------ ------------ 
-B------B--- -B------B--- --A----A---- --A----A---- ---AAAA----- ---AAAA----- ------------ ------------ 
B--------B-- BB------BB-- -A------A--- -A------A--- --A----AA--- ---A---AAA-- ----AAAAA--- -----AA----- 
B--------B-- BB------BB-- -A------A--- -A------A--- --A------ABB ---A------BB ----A-A--A-- -----A-AA--- 
B--------B-- BB------BB-- -A------A--- -A------A--- --A------ABB ---A-----BBB ----A-A--A-- -----A-AA--- 
B--------B-- BB------BB-- -A------A--- -A------A--- --A----AA--- ---A---AAA-- ----AAAAA--- -----AA----- 
-B------B--- -B------B--- --A----A---- --A----A---- ---AAAA----- ---AAAA----- ------------ ------------ 
--B----B---- --BBBBBB---- ---AAAA----- ---AAAA----- ------------ ------------ ------------ ------------ 
---BBBB----- ---BBBB----- ------------ ------------ ------------ ------------ ------------ ------------ 
