model
size = 7 30 20, scale = 0.05, origin = -y
material 
  colors = A:#FFC408 B:#724938 C:#FBE251
voxels
------- ------- ------- ------- ------- ------- ------- ------- ------- ------- ------- ------- ------- ------- ------- ------- ------- ------- ------- ------- ------- ------- ------- ------- ------- ------- ------- ------- ------- ---A--- 
------- ------- ------- ------- ------- ------- ------- ------- ------- ------- ------- ------- ------- ------- ------- ------- ------- ------- ------- ------- ------- ------- ------- ------- ------- ------- ------- ------- ------- ---A--- 
------- ------- ------- ------- ------- ------- ------- ------- ------- ------- ------- ------- ------- ------- ------- ------- ------- ------- ------- ------- ------- ------- ------- ------- ------- ------- ------- ------- ---A--- ---A--- 
------- ------- ------- ------- ------- ------- ------- ------- ------- ------- ------- ------- ------- ------- ------- ------- ------- ------- ------- ------- ------- ------- ------- ------- ------- ------- ------- ---A--- --AAA-- ---A--- 
------- ------- ------- ------- ------- ------- ------- ------- ------- ------- ------- ------- ------- ------- ------- ------- ------- ------- ------- ------- ------- ------- ------- ------- ------- ------- ------- --AAA-- --AAA-- ---A--- 
------- ------- ------- ------- ------- ------- ------- ------- ------- ------- ------- ------- ------- ------- ------- ------- ------- ------- ------- ------- ------- ------- ------- ------- ------- ------- ---A--- -AAAAA- --AAA-- ------- 
---B--- --BBB-- ---B--- ------- ------- ------- ------- ------- ------- ------- ------- ------- ------- ------- ------- ------- ------- ------- ------- ------- ------- ------- ------- ------- ------- ---A--- --AAA-- -AAAAA- --AAA-- ------- 
---B--- --BBB-- --ABA-- ---A--- ------- ------- ------- ------- ------- ------- ------- ------- ------- ------- ------- ------- ------- ------- ------- ------- ------- ------- ------- ------- ------- ---A--- --AAA-- -AAAAA- ---A--- ------- 
---A--- --AAA-- -AAAAA- --AAA-- ---A--- ------- ------- ------- ------- ------- ------- ------- ------- ------- ------- ------- ------- ------- ------- ------- ------- ------- ------- ------- ---A--- --AAA-- -AAAAA- -AAAAA- ---A--- ------- 
---A--- --AAA-- -AAAAA- -AAAAA- --AAA-- ---A--- ---A--- ------- ------- ------- ------- ------- ------- ------- ------- ------- ------- ------- ------- ------- ------- ------- ------- ---A--- --AAA-- -AAAAA- -AAAAA- --AAA-- ------- ------- 
---A--- --AAA-- -AAAAA- AAAAAAA -AAAAA- --AAA-- --AAA-- ---A--- ------- ------- ------- ------- ------- ------- ------- ------- ------- ------- ------- ------- ------- ------- ---A--- --AAA-- -AAAAA- AAAAAAA -AAAAA- --AAA-- ------- ------- 
------- --AAA-- -AAAAA- AAAAAAA AAAAAAA -AAAAA- -AAAAA- --AAA-- ---A--- ---A--- ------- ------- ------- ------- ------- ------- ------- ------- ------- ------- ---A--- ---A--- --AAA-- -AAAAA- AAAAAAA CAAAAAC --AAA-- ---A--- ------- ------- 
------- ---A--- --AAA-- -AAAAA- AAAAAAA AAAAAAA -AAAAA- -AAAAA- --AAA-- --AAA-- ---A--- ---A--- ------- ------- ------- ------- ---A--- ---A--- ---A--- --AAA-- --AAA-- --AAA-- -AAAAA- AAAAAAA AAAAAAA -AAAAA- --AAA-- ------- ------- ------- 
------- ------- --AAA-- -AAAAA- -AAAAA- AAAAAAA AAAAAAA -AAAAA- -AAAAA- -AAAAA- --AAA-- --AAA-- --AAA-- ---A--- ---A--- ---A--- ---A--- --AAA-- --AAA-- --AAA-- -AAAAA- -AAAAA- AAAAAAA AAAAAAA -AAAAA- --AAA-- ---A--- ------- ------- ------- 
------- ------- ---A--- --AAA-- -AAAAA- -AAAAA- AAAAAAA AAAAAAA AAAAAAA -AAAAA- -AAAAA- -AAAAA- --AAA-- --AAA-- --AAA-- --AAA-- --AAA-- --AAA-- -AAAAA- -AAAAA- AAAAAAA AAAAAAA AAAAAAA -AAAAA- --AAA-- ---A--- ------- ------- ------- ------- 
------- ------- ------- ---A--- --AAA-- -AAAAA- -AAAAA- AAAAAAA AAAAAAA AAAAAAA AAAAAAA AAAAAAA AAAAAAA -AAAAA- -AAAAA- -AAAAA- -AAAAA- -AAAAA- CAAAAAC AAAAAAA AAAAAAA AAAAAAA -AAAAA- --AAA-- ---A--- ------- ------- ------- ------- ------- 
------- ------- ------- ------- ---A--- --AAA-- --AAA-- -AAAAA- -AAAAA- AAAAAAA AAAAAAA AAAAAAA AAAAAAA AAAAAAA AAAAAAA AAAAAAA AAAAAAA AAAAAAA AAAAAAA -AAAAA- -AAAAA- --AAA-- --AAA-- ---A--- ------- ------- ------- ------- ------- ------- 
------- ------- ------- ------- ------- ---A--- ---A--- --AAA-- --AAA-- -AAAAA- -AAAAA- -AAAAA- AAAAAAA AAAAAAA AAAAAAA AAAAAAA -AAAAA- -AAAAA- --AAA-- --AAA-- ---A--- ---A--- ------- ------- ------- ------- ------- ------- ------- ------- 
------- ------- ------- ------- ------- ------- ------- ---A--- ---A--- --AAA-- --AAA-- -AAAAA- -AAAAA- -AAAAA- -AAAAA- -AAAAA- --AAA-- --AAA-- ---A--- ---A--- ---A--- ------- ------- ------- ------- ------- ------- ------- ------- ------- 
------- ------- ------- ------- ------- ------- ------- ------- ------- ------- ------- ---A--- --AAA-- --AAA-- --AAA-- ---A--- ---A--- ---A--- ------- ------- ------- ------- ------- ------- ------- ------- ------- ------- ------- ------- 
