model
size = 32 32 17, scale = 0.05, origin = -y
material 
  colors = A:#DDD B:#111 C:#333 D:#444 E:#888 F:#555 G:#100 H:#777 I:#AAA J:#666 K:#222 L:#6FF M:#E00 N:#C00 O:#F60 P:#F90 Q:#C03 R:#0FC
voxels
559-3(2F62-)2F798-2F29-3(4D60-)4D733-2F62-2F27-F6DF3(24-F6-F24-8F)27-2M35-R666-2F62-2F26-F8DF3(22-2F6B2F22-10F)21-2J8F2J20-3J6-3J29-3J631-6F26-F4-F24-10F7(22-B8AB)18-L2-J10BJ2-L15-4LJ6-J2N2L27-3J308-2D8-2D280-4F27-6F26-F4BF24-10F22-B8AB21-2(C10AC20-B10AB20-)C10AC17-L2-F10AF2-L17-J3AB2AB3AJ21-J2(2C-)2CJ21-2J7-3J307-5D4-5D248-2F29-4F27-6F26-6F23-3C6A3C19-2B10A2B2(18-C12AC18-B12AB)18-C12AC15-L2-2F10A2F2-L15-2C3AD2AD3A2C18-2CA2(2B-)2BA2C19-C2(EF)2C2(FE)C276-3G6-3G18-7D2-7D49-4D6-4D184-2F29-4F27-6F21-5C6A5C16-3C10A3C3(16-B14AB16-C14AC)14-L-3F10A3F-L13-J3C3AD2AD3A3CJ15-3CB-BD2ADB-B3C18-C2(E-)2C2(-E)C243-5G4-5G18-5G4-5G16-2D5G4D5G2D16-4KB4-B4K17-7D2-7D17-2HDH6-HD2H17-L2-DH6-HD2-L15-L3-2H6-2H3-L13-L18-L12-L18-L11-L9-2F9-L19-4F22-6C4A6C2(16-H14AH)3(17-M12AM17-H14AH)15-2JM12AM2J13-LJH3ABAD2ADAB3AHJL12-2JHCAB-BD2ADB-BACH2J16-C2(E-)2C2(-E)C212-PNP6-PNP19-5G4-5G17-7G2-7G14-2DK5G4D5GK2D15-KG-G6-G-GK16-3D2-G-D2-D-G2-3D16-H2GD-D2-D-D2GH19-IHID4-DIHI21-2H6-2H22-H8-H22-D8-D22-D3-2B3-D16-L2-16B2-L11-L-H14AH-L13-2LB12AB2L15-LB12ABL17-2(O12AO18-B12AB18-)O12AO18-B12AB17-JO12AOJ14-J2NB2ABAD2ADAB2AB2NJ13-JH2AB-BD2ADB-B2AHJ15-3C2(E-)2B2(-E)3C18-C2(EF)2C2(FE)C149-Q8-Q21-3N6-3N18-6G4-6G15-8G2-8G13-D2K5GD2-D5G2KD14-KDG-2G4-2G-GDK15-3D3G-D2-D-3G3D16-4I2D2-2D4I19-3ID4-D3I21-2(2I6-2I22-)2D6-2D22-2D6-2D19-C2B2AC4BC2A2BC3(16-H14AH)3(17-M12AM17-H14AH)16-JM12AMJ15-JH3ABAD2ADAB3AHJ14-JH2AB-BD2ADB-B2AHJ15-3CE-ED2ADE-E3C18-C2(E-)2C2(-E)C180-PNP6-PNP19-5G4-5G17-7G2-7G14-2DK5GD2-D5GK2D14-KD4G4-4GDK15-3D2GH-D2-D-H2G3D14-2IH2K2ID2-D2I2KH2I15-4HID4-DI4H17-2(HI)6-2(IH)19-I2H6-2HI20-DHD6-DHD21-CAC4BCAC19-CBC3A4B3ACB2(C16-C14A)C14-2C16A2C12-E2C14A2CE12-EC16ACE12-E2C14A2CE12-DC16ACD12-E2C14A2CE12-EC16ACE12-E2C14A2CE12-M3C2ABAD2ADAB2A3CM13-3CAB-BD2ADB-BA3C16-2CE-ED2ADE-E2C17-2EC2(E-)2I2(-E)C2E18-CE-EF2CFE-EC241-2D5GD2-D5G2D16-6K2-6K16-8D2-8D16-I5H2-5HI19-I2HD4-D2HI21-2I6-2I54-2BD4-D2B20-2B3A4C3A2B17-C14AC11-E4-C14AC4-E6-2E3-C14AC3-2E6-2ED2C16A2CD2E6-3D20A3D3(6-2ED20AD2E)6-MED20ADEM7-ED20ADE9-D20AD11-E3C2ABAD2ADAB2A3CE13-3C2ABAD2ADAB2A3C16-2CABED2ADEBA2C17-EACABED2ADEBACAE17-2CABE-2A-EBA2C20-C2EF2CF2EC22-F8-F22-M8-M117-3G6-3G18-2D3K2D2-2D3K2D48-7D2-7D18-4I4-4I20-I2HI4-I2HI42-Q30-QM10-B3C2-3CB10-2ME7-2(2C4A)2C7-E2M2E5-C14AC5-2E2MD2E4-C14AC4-2ED2MED2E3-C14AC3-2EDE2MED5E16A5EDEM-ED26ADE2-ED26ADE3-D26AD4-D26AD5-E24AE7-E22AE9-E20AE11-E3C4AD2AD4A3CE13-3C4AD2AD4A3C16-2C3AD2AD3A2C17-EAC3AD2AD3ACAE17-2C3AD2AD3A2C20-3C-2C-3C182-G8-G20-5D4-5D50-5D4-5D52-2H6-2H86-B3C2-3CB20-2(2C4A)2C17-EB12ABE9-E6-EB12ABE6-E2(2-2E5-EB12ABE5-2E)2-7EAB12ABA7E3-5E2AB12AB2A5E4-6EAB12ABA6E5-5EAB12ABA5E7-4EAB12ABA4E9-3EAB12ABA3E11-2EAB12ABA2E13-3C12A3C14-3C12A3C16-2C10A2C17-EBC10ACBE17-BC10ACB20-10C213-3D6-3D213-4B2-4B21-2B2AB2CB2A2B18-C-BAC6ACAB-C16-C-BC8ACB-C16-E-BAC6ACAB-E16-E-BC8ACB-E16-E-BAC6ACAB-E11-6E-BAC6ACAB-6E7-5E-BAC6ACAB-5E9-4E-BAC6ACAB-4E11-3E-BAC6ACAB-3E13-2E-BC8ACB-2E15-C-BAC6ACAB-C16-C-BC8ACB-C16-C-BAC6ACAB-C18-BC8ACB18-E-BAC6ACAB-E18-3B6E3B471-2(B4-B26-)15(6B26-)6B109-
