model
size = 18 11 21, scale = 0.05, origin = -y
material 
  colors = A:#777 B:#444 C:#1E88A8 D:#211E55 E:#9B90C2 F:#F75C2F G:#52433D H:#77428D I:#2EA9DF J:#F7C242 K:#00AA90 L:#555
voxels
-----BBBBBBB------ ------BBBBB------- ------------------ ------------------ ------------------ ------------------ ------------------ ------------------ ------------------ ------------------ ------------------ 
----BBBBBBBBBB---- -----BBBBBBB------ ------------------ ------------------ ------------------ ------------------ ------------------ ------------------ ------------------ ------------------ ------------------ 
---BBBB----BBB---- ----BBBBBBBBB----- ------------------ ------------------ ------------------ ------------------ ------------------ ------------------ ------------------ ------------------ ------------------ 
---BB------BBB---- ---BBBBBBBBBBB---- -------BBB-------- ------------------ ------------------ ------------------ ------------------ ------------------ ------------------ ------------------ ------------------ 
---BB-------BB---- ---BBBBBBBBB-B---- -----BB---BBB----- -------FFF-------- ------------------ ------------------ ------------------ ------------------ ------------------ ------------------ ------------------ 
-------------B---- ---HBBBBBBBBBJ---- ---HH-BBBBB--J---- -----FFFFFJJJ----- ------FFFFJJ------ -------FFFJ------- ------------------ ------------------ ------------------ ------------------ ------------------ 
------------------ ---HBBAAAAABBJ---- ---H-BAAAAABBJ---- ----HFFAAAAB-J---- ----HFFFFFBBJJ---- -----FFFFFBJJ----- -----FFFFFJJ------ --------FF-------- ------------------ ------------------ ------------------ 
------------------ ---HBA-----AABJ--- ---HHAA---AAABJ--- ---HHAAAAAAAB-J--- ---H-BAAAAAABJ---- ----HBFAAAAB-J---- ----HH-FFFB-J----- ------FFFFJJ------ ------------------ ------------------ GGG--------------- 
------------------ --HBA--------ABJ-- --HHAA------AABJ-- --HHAA-----AAB-J-- --H-HAAAAAAAABJ--- ---HHAAAAAAAB-J--- ----HHBAAAAB-J---- -----H-BFFB-J----- ------HHFFJJ------ ------------------ GGGGG------------- 
------------------ --HA----------AK-- --HAA--------ABK-- --HHA-------AABK-- --HHAA-----AAB-K-- ---HBAA---AAABK--- ---H-HAAAAAAB-K--- ----H-BBFFBBJK---- -----HHHFFJJ------ ------------------ --GGGGG----------- 
------------------ -H------------AK-- -HA-----------AK-- --HA---------ABK-- --HBA-------AABK-- --CCAA-----AAB-K-- ---CCAA---AAB-K--- ----CCCAAAAB-K---- -----CCHFJJKK----- ------------------ ---GGGGG---------- 
------------------ -C-------------AK- -CA-----------AKK- -CCA---------AAK-- --CCA-------AABK-- --CCA-------AABK-- ---CCA-----AABK--- ---CCCAAAAAABKK--- -----CCCBJKKK----- --------L--------- -----GGGGG-------- 
------------------ -C-------------AK- -CA-----------ABK- -CCA---------AABK- --CAA-------AAAK-- --CCA-------AABI-- ---CCA-----AABI--- ---C-CAAAAAAB-I--- ----CCCCBBIIII---- --------LL-------- -------GGG-------- 
------------------ -C-------------AI- -CA-----------ABI- -CBA---------AAII- --CBA-------AABI-- --CCA-------AABI-- ---CBA-----AABI--- ---C-DAAAAAAB-I--- ----DDDDDBIIII---- ---------L-------- --------GGGG------ 
------------------ -CC------------AI- -CCA----------ABI- --CA---------AAI-- --CBA-------AABI-- --CBAA-----AAABI-- ---DBAA---AAABI--- ---DDDDAAAA-BII--- -----DDDCCEEE----- ------------------ ----------GGGG---- 
------------------ --CA----------AI-- --CAA--------AAI-- --CBA-------AABI-- --DBAA-----AAABI-- --D-BAA---AAAB-I-- ---D-BAAAAAAE-I--- ----D-DAAAA--E---- -----DDCCCCEE----- ------------------ -----------GGGGG-- 
------------------ --DAA---------AI-- --DBAA------AABI-- --DBAA-----AAABI-- ---DDAA---AAAABI-- ---DDAAAAAAAA-I--- ---D-BAAAAA-E-E--- ----DDDBBBB-EE---- ------DCCCCE------ ------------------ ------------GGGGG- 
------------------ --DDAA------AAAI-- --D-DAA----AAABI-- ---DDAA---AAA--I-- ---D-BAAAAAAAEE--- ---D-BAAAAAAE-E--- ----D-BBAAB--E---- -----DD-BB-EE----- -------CCCC------- ------------------ --------------GGGG 
------------------ ---DDDA----AAEE--- ---D-DAAAAAAEEE--- ---D-DAAAAAAE-E--- ----D-BAAAAAEE---- ----D-BBBBBE-E---- -----D--BB--E----- ------CCCCCE------ ------------------ ------------------ ----------------GG 
------------------ ----DDCAAAAEEE---- ----D-CAAAAE-E---- ----DDCCAA-E-E---- -----D-CCCEEEE---- -----DCC---EE----- ------CCCCEE------ ------------------ ------------------ ------------------ ------------------ 
------------------ -----DCCCCEEE----- -----DCCCCEEE----- ------CCCCEEE----- ------CCCCEE------ --------CCE------- ------------------ ------------------ ------------------ ------------------ ------------------ 
