model
size = 29 11 30, scale = 0.05, origin = -y
material 
  colors = A:#630 B:#AAA C:#FF6 D:#444
voxels
----------CCCCCCCCC---------- --------CC---------CC-------- -------C------C------C------- ------C------CCC------C------ ------C-----CDCDC-----C------ ------C-----CCCCC-----C------ ------C---CCC---CCC---C------ ------C--C---------C--C------ -------C-------------C------- --------CC---------CC-------- ----------CCCCCCCCC---------- 
----------BBBBBBBBB---------- --------BBBBBBBBBBBBB-------- -------BBBBBBBBBBBBBBB------- ------BBBBBBBBBBBBBBBBB------ ------BBBBBBBBBBBBBBBBB------ ------BBBBBBBBBBBBBBBBB------ ------BBBBBBBBBBBBBBBBB------ ------BBBBBBBBBBBBBBBBB------ -------BBBBBBBBBBBBBBB------- --------BBBBBBBBBBBBB-------- ----------BBBBBBBBB---------- 
----------------------------- ----------------------------- ----------------------------- -----AAAAAAAAAAAAAAAA-------- -----AAAAAAAAAAAAAAAA-------- -----AAAAAAAAAAAAAAAA-------- -----AAAAAAAAAAAAAAAA-------- -----AAAAAAAAAAAAAAAA-------- ----------------------------- ----------------------------- ----------------------------- 
----------------------------- ----------------------------- ----------------------------- ----A-AAAAAAAAAAAAAAAAA------ ----A-AAAAAAAAAAAAAAAAA------ ----A-AAAAAAAAAAAAAAAAA------ ----A-AAAAAAAAAAAAAAAAA------ ----A-AAAAAAAAAAAAAAAAA------ ----------------------------- ----------------------------- ----------------------------- 
----------------------------- ----------------------------- ----------------------------- ---A-A----------------AA----- --AA-A----------------AA----- --AA-A----------------AA----- --AA-A----------------AA----- ---A-A----------------AA----- ----------------------------- ----------------------------- ----------------------------- 
----------------------------- ----------------------------- ----------------------------- ----AA-----------------AA---- ----AA-----------------AA---- ----AA-----------------AA---- ----AA-----------------AA---- ----AA-----------------AA---- ----------------------------- ----------------------------- ----------------------------- 
----------------------------- ----------------------------- ----------------------------- ---AA-------------------AA--- ---AA-------------------AA--- ---AA-------------------AA--- ---AA-------------------AA--- ---AA-------------------AA--- ----------------------------- ----------------------------- ----------------------------- 
----------------------------- ----------------------------- ----------------------------- --AA---------------------AA-- --AA---------------------AA-- --AA---------------------AA-- --AA---------------------AA-- --AA---------------------AA-- ----------------------------- ----------------------------- ----------------------------- 
----------------------------- ----------------------------- ----------------------------- --A-----------------------A-- --A-----------------------A-- --A-----------------------A-- --A-----------------------A-- --A-----------------------A-- ----------------------------- ----------------------------- ----------------------------- 
----------------------------- ----------------------------- ----------------------------- -AA-----------------------AA- -AA-----------------------AA- -AA-----------------------AA- -AA-----------------------AA- -AA-----------------------AA- ----------------------------- ----------------------------- ----------------------------- 
----------------------------- ----------------------------- ----------------------------- -A-------------------------A- -A-------------------------A- -A-------------------------A- -A-------------------------A- -A-------------------------A- ----------------------------- ----------------------------- ----------------------------- 
----------------------------- ----------------------------- ----------------------------- -A-------------------------A- -A-------------------------A- -A-------------------------A- -A-------------------------A- -A-------------------------A- ----------------------------- ----------------------------- ----------------------------- 
----------------------------- ----------------------------- ----------------------------- AA-------------------------AA AA-------------------------AA AA-------------------------AA AA-------------------------AA AA-------------------------AA ----------------------------- ----------------------------- ----------------------------- 
----------------------------- ----------------------------- ----------------------------- A---------------------------A A---------------------------A A---------------------------A A---------------------------A A---------------------------A ----------------------------- ----------------------------- ----------------------------- 
----------------------------- ----------------------------- ----------------------------- A---------------------------A A---------------------------A A---------------------------A A---------------------------A A---------------------------A ----------------------------- ----------------------------- ----------------------------- 
----------------------------- ----------------------------- ----------------------------- A---------------------------A A---------------------------A A---------------------------A A---------------------------A A---------------------------A ----------------------------- ----------------------------- ----------------------------- 
----------------------------- ----------------------------- ----------------------------- A---------------------------A A---------------------------A A---------------------------A A---------------------------A A---------------------------A ----------------------------- ----------------------------- ----------------------------- 
----------------------------- ----------------------------- ----------------------------- A---------------------------A A---------------------------A A---------------------------A A---------------------------A A---------------------------A ----------------------------- ----------------------------- ----------------------------- 
----------------------------- ----------------------------- ----------------------------- AA-------------------------AA AA-------------------------AA AA-------------------------AA AA-------------------------AA AA-------------------------AA ----------------------------- ----------------------------- ----------------------------- 
----------------------------- ----------------------------- ----------------------------- -A-------------------------A- -A-------------------------A- -A-------------------------A- -A-------------------------A- -A-------------------------A- ----------------------------- ----------------------------- ----------------------------- 
----------------------------- ----------------------------- ----------------------------- -A-------------------------A- -A-------------------------A- -A-------------------------A- -A-------------------------A- -A-------------------------A- ----------------------------- ----------------------------- ----------------------------- 
----------------------------- ----------------------------- ----------------------------- -AA-----------------------AA- -AA-----------------------AA- -AA-----------------------AA- -AA-----------------------AA- -AA-----------------------AA- ----------------------------- ----------------------------- ----------------------------- 
----------------------------- ----------------------------- ----------------------------- --A-----------------------A-- --A-----------------------A-- --A-----------------------A-- --A-----------------------A-- --A-----------------------A-- ----------------------------- ----------------------------- ----------------------------- 
----------------------------- ----------------------------- ----------------------------- --AA---------------------AA-- --AA---------------------AA-- --AA---------------------AA-- --AA---------------------AA-- --AA---------------------AA-- ----------------------------- ----------------------------- ----------------------------- 
----------------------------- ----------------------------- ----------------------------- ---AA-------------------AA--- ---AA-------------------AA--- ---AA-------------------AA--- ---AA-------------------AA--- ---AA-------------------AA--- ----------------------------- ----------------------------- ----------------------------- 
----------------------------- ----------------------------- ----------------------------- ----AA-----------------AA---- ----AA-----------------AA---- ----AA-----------------AA---- ----AA-----------------AA---- ----AA-----------------AA---- ----------------------------- ----------------------------- ----------------------------- 
----------------------------- ----------------------------- ----------------------------- -----AA---------------AA----- -----AA---------------AA----- -----AA---------------AA----- -----AA---------------AA----- -----AA---------------AA----- ----------------------------- ----------------------------- ----------------------------- 
----------------------------- ----------------------------- ----------------------------- ------AAA-----------AAA------ ------AAA-----------AAA------ ------AAA-----------AAA------ ------AAA-----------AAA------ ------AAA-----------AAA------ ----------------------------- ----------------------------- ----------------------------- 
----------------------------- ----------------------------- ----------------------------- --------AAAA-----AAAA-------- --------AAAA-----AAAA-------- --------AAAA-----AAAA-------- --------AAAA-----AAAA-------- --------AAAA-----AAAA-------- ----------------------------- ----------------------------- ----------------------------- 
----------------------------- ----------------------------- ----------------------------- -----------AAAAAAA----------- -----------AAAAAAA----------- -----------AAAAAAA----------- -----------AAAAAAA----------- -----------AAAAAAA----------- ----------------------------- ----------------------------- ----------------------------- 
