model
size = 30 6 10, scale = 0.05, origin = -y
material 
  colors = A:#111 B:#960 C:#222 D:#444 E:#E00 F:#EEE G:#777
voxels
------------------------------ ------------------------------ ------------------------------ ------------------------------ ------------------------------ ----CCCCCCCCCCCCCCCCCCCCCC---- 
-------E--------------E------- ------E-E------------E-E------ -------E--------------E------- ------------------------------ ----BBBBBBBBBBBBBBBBBBBBBB---- --CCAAAAAAAAAAAAAAAAAAAAAACC-- 
------------------------------ -------G--------------G------- ------------------------------ ------------------------------ --BBBBBBBBBBBBBBBBBBBBBBBBBB-- -CAAAAAAAAAAAAAAAAAAAAAAAAAAC- 
------------------------------ -------G--------------G------- -------D--------------D------- ------------------------------ -BBBBBDDDBBBBBBBBBBBBDDDBBBBB- CAAAAAFAFAAAAAAAAAAAAFAFAAAAAC 
------------------------------ ------------------------------ -------D--------------D------- -------D--------------D------- -BBBBBDBDBBBBBBBBBBBBDBDBBBBB- CAAAAAAAAAAAAAAAAAAAAAAAAAAAAC 
------------------------------ ------------------------------ -------D--------------D------- -------D--------------D------- -BBBBBDBDBBBBBBBBBBBBDBDBBBBB- CAAAAAAAAAAAAAAAAAAAAAAAAAAAAC 
------------------------------ -------G--------------G------- -------D--------------D------- ------------------------------ -BBBBBDDDBBBBBBBBBBBBDDDBBBBB- CAAAAAFAFAAAAAAAAAAAAFAFAAAAAC 
------------------------------ -------G--------------G------- ------------------------------ ------------------------------ --BBBBBBBBBBBBBBBBBBBBBBBBBB-- -CAAAAAAAAAAAAAAAAAAAAAAAAAAC- 
-------E--------------E------- ------E-E------------E-E------ -------E--------------E------- ------------------------------ ----BBBBBBBBBBBBBBBBBBBBBB---- --CCAAAAAAAAAAAAAAAAAAAAAACC-- 
------------------------------ ------------------------------ ------------------------------ ------------------------------ ------------------------------ ----CCCCCCCCCCCCCCCCCCCCCC---- 
