model
size = 28 32 13, scale = 0.05, origin = -y
material 
  colors = A:#2D843B B:#49341A C:#2B5125 D:#696A6D
voxels
260-3(12D16-)12D76-4A23-6A23-4A640-4A17-2(4D2-6A2-4D10-)3(4D10-)4D43-8A19-2(10A18-)10A19-8A105-6A22-6A23-4A414-8A19-10A12-3D2-12A2-3D6-3D-C12AC-3D6-3D-2C10A2C-3D6-3D-A12CA-3D10-2C10A2C14-C12AC3(14-14A)14-C12AC14-2C10A2C14-A12CA14-2C10A2C15-12A17-10A19-8A21-6A330-6C20-10A17-12A15-14A9-2D3-14A3-2D4-2D2-2C12A2C2-2D4-2D2-2AC10AC2A2-2D4-2D2-3A10C3A2-2D7-3AC10AC3A10-A2C12A2CA10-2C14A2C10-C16AC10-2C14A2C10-A2C12A2CA10-3AC10AC3A11-3A10C3A12-A2C10A2CA12-2C12A2C13-14A15-12A17-10A20-6A273-8A19-3C4A3C16-2C2A6C2A2C13-2C12A2C12-C14AC8-D3-C14AC3-D4-D2-2AC12AC2A2-D4-D2-3AC10AC3A2-D4-D-5A10C5A-D6-4AC10AC4A8-3AC12AC3A8-2AC14AC2A8-3C14A3C8-2AC14AC2A8-3AC12AC3A8-4AC10AC4A8-5A10C5A9-3AC10AC3A10-AC14ACA11-C14AC12-2C12A2C13-2C10A2C15-2C8A2C18-8C22-4A189-10A16-C12AC13-A3C8A3CA11-4A10C4A10-3AC10AC3A9-3AC12AC3A5-2D-3C14A3C-2D2-2D-3AC12AC3A-2D2-2D-4AC10AC4A-2D2-2D-5A2C6A2C5A-2D4-5AC10AC5A6-4AC12AC4A6-3AC14AC3A6-4C14A4C6-3AC14AC3A6-4AC12AC4A6-5AC10AC5A7-5A2C6A2C5A8-4AC10AC4A8-2A2C12A2C2A9-3C12A3C10-3AC10AC3A10-4A10C4A11-2AC10AC2A14-AC8ACA19-6A22-6A133-8A19-10A15-2C12A2C12-2AC10AC2A11-4A10C4A9-4AC10AC4A8-3AC12AC3A5-D2-3C14A3C2(2-D)2-3AC12AC3A2(2-D)-9A4B9A-D2-D-8A6B8A-D4-7A8B7A5-2(8A8B8A4-)4C4A8B4A4C2(4-8A8B8A)5-7A8B7A6-8A6B8A6-9A4B9A6-2A3C12A3C2A7-4C12A4C8-4AC10AC4A8-5A10C5A9-3AC10AC3A11-16A13-A2C8A2CA17-8A106-4A21-10A16-14A13-2C12A2C11-18A9-AC16ACA7-8A6B8A6-7A8B7A3-2D-C5A10B5AC2(-4D-5A12B5A)-4D5A14B5A2D2-2(5A14B5A4-)4A16B4A4-2C2A16B2A2C4-4A16B4A3(4-5A14B5A)5-5A12B5A6-AC3A12B3ACA6-4C2A10B2A4C6-8A6B8A7-20A8-20A9-18A11-AC12ACA14-C10AC19-6A77-8A18-12A14-CA2C8A2CAC11-2(C2A)6B2(2AC)9-2AC2A10B2AC2A8-AC2A12B2ACA7-4A14B4A6-3A16B3A3-D2-C2A16B2AC2-3(2D-3A18B3A-)D-3(3A20B3A2-)3C20B3C3(2-3A20B3A)3-2(3A18B3A4-)4A16B4A5-3C16B3C6-4A14B4A7-4A12B4A8-5A10B5A9-6A6B6A11-AC12ACA14-C2AC4AC2AC18-8A76-8C18-3C6A3C14-3C10A3C11-2C4A6B4A2C9-2C3A10B3A2C8-C3A12B3AC7-2C2A14B2A2C6-2CA16BA2C3-D2-C2A16B2AC2-2D-2CA18BA2C2(-2D-C2A18B2AC)-D-3(2CA20BA2C2-)3C20B3C3(2-2CA20BA2C)3-2(3C18B3C4-)4C16B4C5-3C16B3C6-3CA14BA3C7-2C2A12B2A2C8-2C3A10B3A2C9-C5A6B5AC11-16C14-12C18-8C48-8A18-3A6B3A14-3A10B3A11-CA14BAC9-2A16B2A7-2A18B2A6-A20BA5-2A20B2A4-A22BA2-D-C22BC-2D2A22B2A2(2DA24BA)D2A24B3A26B2A26BAC26BCA26B2A26B3A24B2A-2(A24BA2-)2A22B2A3-C22BC4-2A20B2A5-A20BA6-2A18B2A7-2A16B2A9-2A14B2A11-ACA10BACA14-3A6B3A18-8A20-8A18-3A6B3A14-3A2B6-2B3A11-CA2B10-2BAC9-2AB14-B2A7-2AB16-B2A6-AB18-BA5-2AB18-B2A4-AB20-BA2-D-CB20-BC-2D2AB20-B2A2(2DAB22-BA)D2AB22-B3AB24-B2AB24-BACB24-BCAB24-B2AB24-B3AB22-B2A-2(AB22-BA2-)2AB20-B2A3-CB20-BC4-2AB18-B2A5-AB18-BA6-2AB16-B2A7-2AB14-B2A9-2A2B10-2B2A11-ACA2B6-2BACA14-3A6B3A18-8A20-8A18-3A6B3A14-3A2B6-2B3A11-CA2B10-2BAC9-2AB14-B2A7-2AB16-B2A6-AB18-BA5-2AB18-B2A4-AB20-BA2-D-CB20-BC-2D2AB20-B2A2(2DAB22-BA)D2AB22-B3AB24-B2AB24-BACB24-BCAB24-B2AB24-B3AB22-B2A-2(AB22-BA2-)2AB20-B2A3-CB20-BC4-2AB18-B2A5-AB18-BA6-2AB16-B2A7-2AB14-B2A9-2A2B10-2B2A11-ACA2B6-2BACA14-3A6B3A18-8A10-
