model
size = 28 28 11, scale = 0.05, origin = -y
material 
  colors = A:#49341A B:#E4C358 C:#696A6D D:#FFF
voxels
---------------------------- ---------------------------- ---------------------------- ---------------------------- ---------------------------- ---------------------------- ---------------------------- ------------AAAA------------ -----------AAAAAA----------- ----------AAAAAAAA---------- ---------AAAAAAAAAA--------- ---------AAAAAAAAAA--------- ---------AAAAAAAAAA--------- ---------AAAAAAAAAA--------- ---------AAAAAAAAAA--------- --------AAAAAAAAAAAA-------- --------AAAAAAAAAAAA-------- --------AAAAAAAAAAAA-------- --------AAAAAAAAAAAA-------- --------AAAAAAAAAAAA-------- --------AAAAAAAAAAAA-------- ---------AAAAAAAAAA--------- ----------AAAAAAAA---------- ---------------------------- ---------------------------- ---------------------------- ---------------------------- ---------------------------- 
---------------------------- ---------------------------- ---------------------------- ---------------------------- ---------------------------- ----------AAAAAAAA---------- ---------AAAAAAAAAA--------- --------AAAAAAAAAAAA-------- C------AAAAAAAAAAAAAA------C C------AAAAAAAAAAAAAA------C C------AAAAAAAAAAAAAA------C C------AAAAAAAAAAAAAA------C -------AAAAAAAAAAAAAA------- -------AAAAAAAAAAAAAA------- -------AAAAAAAAAAAAAA------- ------AAAAAAAAAAAAAAAA------ ------AAAAAAAAAAAAAAAA------ ------AAAAAAAAAAAAAAAA------ ------AAAAAAAAAAAAAAAA------ ------AAAAAAAAAAAAAAAA------ ------AAAAAAAAAAAAAAAA------ ------AAAAAAAAAAAAAAAA------ ------AAAAAAAAAAAAAAAA------ -------AAAAAAAAAAAAAA------- --------AAAAAAAAAAAA-------- ---------------------------- ---------------------------- ---------------------------- 
---------------------------- ---------------------------- ---------------------------- -----------AAAAAA----------- ----------AAAAAAAA---------- ---------AAAAAAAAAA--------- --------AAAAAAAAAAAA-------- -------AAAAAAAAAAAAAA------- C------AAAAAAAAAAAAAA------C C-----AAAAAAAAAAAAAAAA-----C C-----AAAAAAAAAAAAAAAA-----C C-----AAAAAAAAAAAAAAAA-----C ------AAAAAAAAAAAAAAAA------ ------AAAAAAAAAAAAAAAA------ -----AAAAAAAAAAAAAAAAAA----- -----AAAAAAAAAAAAAAAAAA----- -----AAAAAAAAAAAAAAAAAA----- -----AAAAAAAAAAAAAAAAAA----- -----AAAAAAAAAAAAAAAAAA----- -----AAAAAAAAAAAAAAAAAA----- -----AAAAAAAAAAAAAAAAAA----- -----AAAAAAAAAAAAAAAAAA----- -----AAAAAAAAAAAAAAAAAA----- -----AAAAAAAAAAAAAAAAAA----- ------AAAAAAAAAAAAAAAA------ -------AAAAAAAAAAAAAA------- ---------------------------- ---------------------------- 
---------------------------- ---------------------------- ------------AAAA------------ ----------AAAAAAAA---------- ---------AAAAAAAAAA--------- --------AAAAAAAAAAAA-------- -------AAAAAAAAAAAAAA------- -------AAAAAAAAAAAAAA------- CC----AAAAAAAAAAAAAAAA----CC CC----AAAAAAAAAAAAAAAA----CC CC---AAAAAAAAAAAAAAAAAA---CC CC---AAAAAAAAAAAAAAAAAA---CC -----AAAAAAAAAAAAAAAAAA----- ----AAAAAAAAAAAAAAAAAAAA---- ----AAAAAAAAAAAAAAAAAAAA---- ----AAAAAAAAAAAAAAAAAAAA---- ----AAAAAAAAAAAAAAAAAAAA---- ----AAAAAAAAAAAAAAAAAAAA---- ----AAAAAAAAAAAAAAAAAAAA---- ----AAAAAAAAAAAAAAAAAAAA---- ----AAAAAAAAAAAAAAAAAAAA---- ----AAAAAAAAAAAAAAAAAAAA---- ----AAAAAAAAAAAAAAAAAAAA---- ----AAAAAAAAAAAAAAAAAAAA---- -----AAAAAAAAAAAAAAAAAA----- ------AAAAAAAAAAAAAAAA------ --------AAA------AAA-------- ---------------------------- 
---------------------------- -------------AA------------- ---------A-AAAAAA-A--------- ---------AAAAAAAAAA--------- --------AAAAAAAAAAAA-------- -------AAAAAAAAAAAAAA------- -------AAAAAAAAAAAAAA------- ------AAAAAAAAAAAAAAAA------ -C----AAAAAAAAAAAAAAAA----C- -C---AAAAAAAAAAAAAAAAAA---C- -C---AAAAAAAAAAAAAAAAAA---C- -C---AAAAAAAAAAAAAAAAAA---C- ----AAAAAAAAAAAAAAAAAAAA---- ----AAAAAAAAAAAAAAAAAAAA---- ----AAAAAAAAAAAAAAAAAAAA---- ----AAAAAAAAAAAAAAAAAAAA---- ----AAAAAAAAAAAAAAAAAAAA---- ----AAAAAAAAAAAAAAAAAAAA---- ----AAAAAAAAAAAAAAAAAAAA---- ----AAAAAAAAAAAAAAAAAAAA---- ----AAAAAAAAAAAAAAAAAAAA---- ---AAAAAAAAAAAAAAAAAAAAAA--- ----AAAAAAAAAAAAAAAAAAAA---- ----AAAAAAAAAAAAAAAAAAAA---- ----AAAAAAAAAAAAAAAAAAAA---- -----AAAAAAAAAAAAAAAAAA----- -------AAAAA----AAAAA------- ---------------------------- 
---------------------------- ------------AAAA------------ -----------AAAAAA----------- ---------AAAAAAAAAA--------- --------AAAAAAAAAAAA-------- -------AAAAAAAAAAAAAA------- -------AAAAAAAAAAAAAA------- ------AAAAAAAAAAAAAAAA------ -CC---AAAAAAAAAAAAAAAA---CC- -CC--AAAAAAAAAAAAAAAAAA--CC- -CC--AAAAAAAAAAAAAAAAAA--CC- -CC--AAAAAAAAAAAAAAAAAA--CC- ----AAAAAAAAAAAAAAAAAAAA---- ----AAAAAAAAAAAAAAAAAAAA---- ----AAAAAAAAAAAAAAAAAAAA---- ----AAAAAAAAAAAAAAAAAAAA---- ----AAAAAAAAAAAAAAAAAAAA---- ----AAAAAAAAAAAAAAAAAAAA---- ----AAAAAAAAAAAAAAAAAAAA---- ----AAAAAAAAAAAAAAAAAAAA---- ---AAAAAAAAAAAAAAAAAAAAAA--- ---AAAAAAAAAAAAAAAAAAAAAA--- ---AAAAAAAAAAAAAAAAAAAAAA--- ----AAAAAAAAAAAAAAAAAAAA---- ----AAAAAAAAAAAAAAAAAAAA---- -----AAAAAAAAAAAAAAAAAA----- -------AAAAA----AAAAA------- ---------------------------- 
---------------------------- ------------AAAA------------ -----------AAAAAA----------- ---------AAAAAAAAAA--------- --------AAAAAAAAAAAA-------- -------AAAAAAAAAAAAAA------- -------AAAAAAAAAAAAAA------- ------AAAAAAAAAAAAAAAA------ --C---AAAAAAAAAAAAAAAA---C-- --C--AAAAAAAAAAAAAAAAAA--C-- --C--AAAAAAAAAAAAAAAAAA--C-- --C--AAAAAAAAAAAAAAAAAA--C-- ----AAAAAAAAAAAAAAAAAAAA---- ----AAAAAAAAAAAAAAAAAAAA---- ----AAAAAAAAAAAAAAAAAAAA---- ----AAAAAAAAAAAAAAAAAAAA---- ----AAAAAAAAAAAAAAAAAAAA---- ----AAAAAAAAAAAAAAAAAAAA---- ----AAAAAAAAAAAAAAAAAAAA---- ----AAAAAAAAAAAAAAAAAAAA---- ---AAAAAAAAAAAAAAAAAAAAAA--- ---AAAAAAAAAAAAAAAAAAAAAA--- ---AAAAAAAAAAAAAAAAAAAAAA--- ----AAAAAAAAAAAAAAAAAAAA---- ----AAAAAAAAAAAAAAAAAAAA---- -----AAAAAAAAAAAAAAAAAA----- -------AAAAA----AAAAA------- ---------------------------- 
------------BBBB------------ ----------BBBBBBBB---------- --------BBBBBBBBBBBB-------- -------BBBBBBBBBBBBBB------- ------BBBBBBBBBBBBBBBB------ ------BBBBBBBBBBBBBBBB------ -----BBBBBBBBBBBBBBBBBB----- -----BBBBBBBBBBBBBBBBBB----- --C-BBBBBBBBBBBBBBBBBBBB-C-- --C-BBBBBBBBBBBBBBBBBBBB-C-- --C-BBBBBBBBBBBBBBBBBBBB-C-- --CBBBBBBBBBBBBBBBBBBBBBBC-- ---BBBBBBBBBBBBBBBBBBBBBB--- ---BBBBBBBBBBBBBBBBBBBBBB--- ---BBBBBBBBBBBBBBBBBBBBBB--- ----BBBBBBBBBBBBBBBBBBBB---- ---BBBBBBBBBBBBBBBBBBBBBB--- --BBBBBBBBBBBBBBBBBBBBBBBB-- --BBBBBBBBBBBBBBBBBBBBBBBB-- --BBBBBBBBBBBBBBBBBBBBBBBB-- --BBBBBBBBBBBBBBBBBBBBBBBB-- --BBBBBBBBBBBBBBBBBBBBBBBB-- --BBBBBBBBBBBBBBBBBBBBBBBB-- --BBBBBBBBBBBBBBBBBBBBBBBB-- ---BBBBBBBBBBBBBBBBBBBBBB--- ---BBBBBBBBBBBBBBBBBBBBBB--- ----BBBBBBBBB--BBBBBBBBB---- ------BBBBBB----BBBBBB------ 
---------------------------- ------------B--B------------ ----------BBB--BBB---------- --------BBBBB--BBBBB-------- -------BBBBBB--BBBBBB------- -------BBBBBB--BBBBBB------- ---------------------------- ------BBBBBB----BBBBBB------ ---C-BBBBBBBB--BBBBBBBB-C--- ---C--BBBBBBB--BBBBBBB--C--- ---C--------------------C--- ---C-BBBBBBB----BBBBBBB-C--- ----BBBBBBBBB--BBBBBBBBB---- ----BBBBBBBBB--BBBBBBBBB---- -----BBBBBBBB--BBBBBBBB----- ---------------------------- ----BBBBBBBBB--BBBBBBBBB---- ---BBBBBBBBBB--BBBBBBBBBB--- ---BBBBBBBBBB--BBBBBBBBBB--- ---BBBBBBBBBB--BBBBBBBBBB--- ---BBBBBBBBBB--BBBBBBBBBB--- ---BBBBBBBBBB--BBBBBBBBBB--- ---BBBBBBBBBB--BBBBBBBBBB--- ---BBBBBBBBBB--BBBBBBBBBB--- ----BBBBBBBBB--BBBBBBBBB---- -----BBBBBBBB--BBBBBBBB----- ------BBBBBB----BBBBBB------ ---------------------------- 
---------------------------- ---------------------------- ---------------------------- ---------------------------- ---------------------------- ---------------------------- ---------------------------- ---------------------------- ----CCCCCCCCCCCCCCCCCCCC---- ----CCCCCCCCCCCCCCCCCCCC---- ----CCCCCCCCCCCCCCCCCCCC---- ----CCCCCCCCCCCCCCCCCCCC---- ---------------------------- ---------------------------- ---------------------------- ---------------------------- ---------------------------- -----BBBBBBB----BBBBBBB----- ----BBBBBBBBB--BBBBBBBBB---- ----BBBBBBBBB--BBBBBBBBB---- ----BBBBBBBBB--BBBBBBBBB---- ----BBBBBBBBB--BBBBBBBBB---- ----BBBBBBBBB--BBBBBBBBB---- ----BBBBBBBBB--BBBBBBBBB---- -----BBBBBBBB--BBBBBBBB----- ------BBBBBB----BBBBBB------ ---------------------------- ---------------------------- 
---------------------------- ---------------------------- ---------------------------- ---------------------------- ---------------------------- ---------------------------- ---------------------------- ------------AAAA------------ -----------ADDDDA----------- ----------AAAAADAA---------- ----------AAADDDAA---------- ----------AAAAADAA---------- -----------ADDDDA----------- ------------AAAA------------ ---------------------------- ---------------------------- ---------------------------- ---------------------------- ---------------------------- ---------------------------- ---------------------------- ---------------------------- ---------------------------- ---------------------------- ---------------------------- ---------------------------- ---------------------------- ---------------------------- 
