model
size = 26 22 26, scale = 0.05, origin = -y
material 
  colors = A:#0E0 B:#FC9 C:#FF9 D:#630 E:#111 F:#669 G:#F60 H:#600 I:#F93 J:#FF3 K:#F96 L:#EEE
voxels
-------------------------- -------------------------- -------------------------- -------------------------- ----------------L--------- -------------------------- -------------------------- -------------------------- -------------------------- -------------------------- -------------------------- -------------------------- -------------------------- -------------------------- -------------------------- -------------------------- -------------------------- -------------------------- -------------------------- -------------------------- -------------------------- -------------------------- 
-------------------------- -------------------------- -------------------------- -------------------------- ----------------L--------- -------------------------- -------------------------- -------------------------- -------------------------- -------------------------- -------------------------- -------------------------- -------------------------- -------------------------- -------------------------- -------------------------- -------------------------- -------------------------- -------------------------- -------------------------- -------------------------- -------------------------- 
-------------------------- -------------------------- -------------------------- -------------------------- ----------------K--------- -------------------------- -------------------------- -------------------------- -------------------------- -------------------------- -------------------------- -------------------------- -------------------------- -------------------------- -------------------------- -------------------------- -------------------------- -------------------------- -------------------------- -------------------------- -------------------------- -------------------------- 
-------------------------- -------------------------- -------------------------- -------------------------- ----------------K--------- -------------------------- -------------------------- -------------------------- -------------------------- -------------------------- -------------------------- -------------------------- -------------------------- -------------------------- -------------------------- -------------------------- -------------------------- -------------------------- -------------------------- -------------------------- -------------------------- -------------------------- 
-------------------------- -------------------------- -------------------------- -------FFFFFFFFFFFF------- -------FFFFFFF--K-F------- -------FFFFFFFFFFFF------- -------FFFFFFFFFFFF------- -------------------------- -------------------------- -------------------------- -------------------------- -------------------------- -------------------------- -------------------------- -------------------------- -------------------------- -------------------------- -------------------------- -------------------------- -------------------------- -------------------------- -------------------------- 
-------------------------- -------------------------- -------------------------- -------F----------F------- -------FCCCCCCCCCCF------- -------FCCCCCCCCCCF------- -------FFFFFFFFFFFF------- -------------------------- -----------GGGG----------- -----------GGGG----------- ------EEEEEGGGG----------- ------EEEEEGGGG----------- ------EEEEE--------------- ------EEEEEE-------------- -------------------------- -------------------------- -------------------------- -------------------------- -------------------------- -------------------------- -------------------------- -------------------------- 
-------------------------- -------------------------- ------BBBBBBBBBBBBBB------ ------BBBBBBBBBBBBBB------ ------BBBBBBBBBBBBBB------ ------BBBBBBBBBBBBBB------ ------BBBBBBBBBBBBBB------ -------------------------- -----------GGGG----------- -----------GGGG----------- ------DEEEEGGGGEEEEE------ ------EEEEEGGGGEEEEE------ ------EEEEE----EEEEE------ ------EEEEEEEEEEEEEE------ ------EEEEEEEEEEEEEE------ -------------------------- -------HHHH----HHHH------- -------------------------- -------------------------- -------------------------- -------------------------- -------------------------- 
-------------------------- -------------------------- ------BBBBBBBBBBBBBB------ ------BBBBBBBBBBBBBB------ ------BBBBBBBBBBBBBB------ ------BBBBBBBBBBBBBB------ ------BBBBBBBBBBBBBB------ ------BBBBBBBBBBBBBB------ ------BBBBBBBBBBBBBB------ ------BBBBBBBBBBBBBB------ ------BBBBBBBBBBBBBB------ ------BBBBBBBBBBBBBB------ -----EBBBBBBBBBBBBBBE----- -----EBBBBBBBBBBBBBBE----- ------BBBBBBBBBBBBBB------ ------BBBBBBBBBBBBBB------ ------BBBBBBBBBBBBBB------ ------BBBBBBBBBBBBBB------ ------DDDDDDDDDDDDDD------ -------------------------- -------------------------- -------------------------- 
-------------------------- -------------------------- -----BBBBBBBBBBBBBBBB----- -----BAAAAAAAAAAAAAAB----- -----BAAAAAAAAAAAAAAB----- -----BAAAAAAAAAAAAAAB----- -----BAAAAAAAAAAAAAAB----- -----BAAAAAAAAAAAAAAB----- -----BAAAAAAAAAAAAAAB----- -----BAAAAAAAAAAAAAAB----- -----BAAAAAAAAAAAAAAB----- -----BAAAAAAAAAAAAAAB----- ----EBAAAAAAAAAAAAAABE---- ----EBAAAAAAAAAAAAAABE---- -----BAAAAAAAAAAAAAAB----- -----BAAAAAAAAAAAAAAB----- -----BAAAAAAAAAAAAAAB----- -----BAAAAAAAAAAAAAAB----- -----DCCCCCCCCCCCCCCD----- ------DDDDDDDDDDDDDD------ -------------------------- -------------------------- 
-------------------------- -------BBBBBBBBBBBB------- -----BBBBBBBBBBBBBBBB----- -----BBBBBBBBBBBBBBBBB---- ----BCAAAAAAAAAAAAAACB---- ----BCAAAAAAAAAAAAAACB---- ----BCAAAAAAAAAAAAAACB---- ----BCAAAAAAAAAAAAAACB---- ----BCAAAAAAAAAAAAAACB---- ----BCAAAAAAAAAAAAAACB---- ----BCAAAAAAAAAAAAAACB---- ----BCAAAAAAAAAAAAAACB---- ---EBEAAAAAAAAAAAAAAEB---- ---EBEAAAAAAAAAAAAAAEB---- ----BCAAAAAAAAAAAAAACB---- ---DBCAAAAAAAAAAAAAACBD--- ---DBCAAAAAAAAAAAAAACBD--- ---DDCAAAAAAAAAAAAAACDD--- -----DCCCCCCCCCCCCCCD----- ------DCCCCCCCCCCCCD------ -------DDDDDDDDDDDD------- -------------------------- 
-------------------------- -------BBBBBBBBBBBB------- -----BBBBBBBBBBBBBBBB----- ----BBBBBBBBBBBBBBBBBB---- ---BCCAAAAAAAAAAAAAACBB--- ---BCCAAAAAAAAAAAAAACBB--- ---BCCAAAAAAAAAAAAAACBB--- ---BCCAAAAAAAAAAAAAACBB--- ---BCCAAAAAAAAAAAAAACBB--- ---BCCAAAAAAAAAAAAAACBB--- ---BCCAAAAAAAAAAAAAACBB--- ---BCCAAAAAAAAAAAAAACBB--- --EBEEAAAAAAAAAAAAAAEBB--- --EBEEAAAAAAAAAAAAAAEBB--- ---BCCAAAAAAAAAAAAAACBB--- ---DCCAAAAAAAAAAAAAACCD--- ---DCCAAAAAAAAAAAAAACCD--- ---DDCAAAAAAAAAAAAAACDD--- -----DCCCCCCCCCCCCCCD----- ------DCCCCCCCCCCCCD------ -------DDDDDDDDDDDD------- -------------------------- 
---------BBBBBBBB--------- -------BBBBBBBBBBBB------- -----BBBBBBBBBBBBBBBB----- ----BBBBBBBBBBBBBBBBBB---- ---BCCAAAAAAAAAAAAAACBB--- ---BCCAAAAAAAAAAAAAACBB--- ---BCCAAAAAAAAAAAAAACBB--- ---BCCAAAAAAAAAAAAAACBB--- ---BCCAAAAAAAAAAAAAACBB--- ---BCCAAAAAAAAAAAAAACBB--- ---BCCAAAAAAAAAAAAAACBB--- ---BCCAAAAAAAAAAAAAACBB--- --EBECAAAAAAAAAAAAAACBB--- --EBECAAAAAAAAAAAAAACBB--- ---BCCAAAAAAAAAAAAAACBB--- ---DCCAAAAAAAAAAAAAACCD--- ---DCCAAAAAAAAAAAAAACCD--- ---DDCAAAAAAAAAAAAAACDD--- -----DCCCCCCCCCCCCCCD----- ------DCCCCCCCCCCCCD------ -------DDCCCCCCCCDD------- ---------DDDDDDDD--------- 
---------BBBBBBBB--------- -------BBBBBBBBBBBB------- -----BBBBBBBBBBBBBBBB----- ----BBBBBBBBBBBBBBBBBB---- ---BCCAAAAAAAAAAAAAACBB--- ---BCCAAAAAAAAAAAAAACBB--- ---BCCAAAAAAAAAAAAAACBB--- ---BCCAAAAAAAAAAAAAACBB--- ---BCCAAAAAAAAAAAAAACBB--- ---BCCAAAAAAAAAAAAAACBB--- ---BCCAAAAAAAAAAAAAACBB--- ---BCCAAAAAAAAAAAAAACBB--- ---BCCAAAAAAAAAAAAAACBB--- ---BCCAAAAAAAAAAAAAACBB--- ---BCCAAAAAAAAAAAAAACBB--- ---DCCAAAAAAAAAAAAAACCD--- ---DCCAAAAAAAAAAAAAACCD--- ---DDCAAAAAAAAAAAAAACDD--- -----DCCCCCCCCCCCCCCD----- ------DCCCCCCCCCCCCD------ -------DDCCCCCCCCDD------- ---------DDDDDDDD--------- 
---------BBBBBBBB--------- -------BBBBBBBBBBBB------- -----BBBBBBBBBBBBBBBB----- ----BBBBBBBBBBBBBBBBBB---- ---BCCAAAAAAAAAAAAAACBB--- ---BCCAAAAAAAAAAAAAACBB--- ---BCCAAAAAAAAAAAAAACBB--- ---BCCAAAAAAAAAAAAAACBB--- ---BCCAAAAAAAAAAAAAACBB--- ---BCCAAAAAAAAAAAAAACBB--- ---BCCAAAAAAAAAAAAAACBB--- ---BCCAAAAAAAAAAAAAACBB--- ---BCCAAAAAAAAAAAAAACBB--- ---BCCAAAAAAAAAAAAAACBB--- ---BCCAAAAAAAAAAAAAACBB--- ---DCCAAAAAAAAAAAAAACCD--- ---DCCAAAAAAAAAAAAAACCD--- ---DDCAAAAAAAAAAAAAACDD--- -----DCCCCCCCCCCCCCCD----- ------DCCCCCCCCCCCCD------ -------DDCCCCCCCCDD------- ---------DDDDDDDD--------- 
---------BBBBBBBB--------- -------BBBBBBBBBBBB------- -----BBBBBBBBBBBBBBBB----- ----BBBBBBBBBBBBBBBBBB---- ---BCCAAAAAAAAAAAAAACBB--- ---BCCAAAAAAAAAAAAAACBB--- ---BCCAAAAAAAAAAAAAACBB--- ---BCCAAAAAAAAAAAAAACBB--- ---BCCAAAAAAAAAAAAAACBB-J- ---BCCAAAAAAAAAAAAAACBB--- ---BCCAAAAAAAAAAAAAACBB--- ---BCCAAAAAAAAAAAAAACBB--- ---BCCAAAAAAAAAAAAAACBB--- ---BCCAAAAAAAAAAAAAACBB--- ---BCCAAAAAAAAAAAAAACBB--- ---DCCAAAAAAAAAAAAAACCD--- ---DCCAAAAAAAAAAAAAACCD--- ---DDCAAAAAAAAAAAAAACDD--- -----DCCCCCCCCCCCCCCD----- ------DCCCCCCCCCCCCD------ -------DDCCCCCCCCDD------- ---------DDDDDDDD--------- 
---------BBBBBBBB--------- -------BBBBBBBBBBBB------- -----BBBBBBBBBBBBBBBB----- ----BBBBBBBBBBBBBBBBBB---- ---BCCAAAAAAAAAAAAAACBB--- ---BCCAAAAAAAAAAAAAACBB--- ---BCCAAAAAAAAAAAAAACBB--- ---BCCAAAAAAAAAAAAAACBB-J- BBBBCCAAAAAAAAAAAAAACBBBBB BIBBCCAAAAAAAAAAAAAACBBBIB BIBBCCAAAAAAAAAAAAAACBBBIB BIBBCCAAAAAAAAAAAAAACBBBIB BBBBCCAAAAAAAAAAAAAACBBBBB ---BCCAAAAAAAAAAAAAACBB--- ---BCCAAAAAAAAAAAAAACBB--- ---DCCAAAAAAAAAAAAAACCD--- ---DCCAAAAAAAAAAAAAACCD--- ---DDCAAAAAAAAAAAAAACDD--- -----DCCCCCCCCCCCCCCD----- ------DCCCCCCCCCCCCD------ -------DDCCCCCCCCDD------- ---------DDDDDDDD--------- 
---------BBBBBBBB--------- -------BBBBBBBBBBBB------- -----BBBBBBBBBBBBBBBB----- ----BBBBBBBBBBBBBBBBBB---- ---BCCAAAAAAAAAAAAAACBB--- ---BCCAAAAAAAAAAAAAACBB--- ---BCCAAAAAAAAAAAAAACBB--- ---BCCAAAAAAAAAAAAAACBB-J- BBBBCCAAAAAAAAAAAAAACBBBBB BBBBCCAAAAAAAAAAAAAACBBBBB BBBBCCAAAAAAAAAAAAAACBBBBB BBBBCCAAAAAAAAAAAAAACBBBBB BBBBCCAAAAAAAAAAAAAACBBBBB ---BCCAAAAAAAAAAAAAACBB--- ---BCCAAAAAAAAAAAAAACBB--- ---DCCAAAAAAAAAAAAAACCD--- ---DCCAAAAAAAAAAAAAACCD--- ---DDCAAAAAAAAAAAAAACDD--- -----DCCCCCCCCCCCCCCD----- ------DCCCCCCCCCCCCD------ -------DDCCCCCCCCDD------- ---------DDDDDDDD--------- 
---------BBBBBBBB--------- -------BBBBBBBBBBBB------- -----BBBBBBBBBBBBBBBB----- ----BBBBBBBBBBBBBBBBBB---- ---BCCAAAAAAAAAAAAAACBB--- ---BCCAAAAAAAAAAAAAACBB--- ---BCCAAAAAAAAAAAAAACBB--- ---BCCAAAAAAAAAAAAAACBB--- ---BCCAAAAAAAAAAAAAACBB-J- ---BCCAAAAAAAAAAAAAACBB--- ---BCCAAAAAAAAAAAAAACBB--- ---BCCAAAAAAAAAAAAAACBB--- ---BCCAAAAAAAAAAAAAACBB--- ---BCCAAAAAAAAAAAAAACBB--- ---BCCAAAAAAAAAAAAAACBB--- ---DCCAAAAAAAAAAAAAACCD--- ---DCCAAAAAAAAAAAAAACCD--- ---DDCAAAAAAAAAAAAAACDD--- -----DCCCCCCCCCCCCCCD----- ------DCCCCCCCCCCCCD------ -------DDCCCCCCCCDD------- ---------DDDDDDDD--------- 
---------BBBBBBBB--------- -------BBBBBBBBBBBB------- -----BBBBBBBBBBBBBBBB----- ----BBBBBBBBBBBBBBBBBB---- ---BCCAAAAAAAAAAAAAACBB--- ---BCCAAAAAAAAAAAAAACBB--- ---BCCAAAAAAAAAAAAAACBB--- ---BCCAAAAAAAAAAAAAACBB--- ---BCCAAAAAAAAAAAAAACBB--- ---BCCAAAAAAAAAAAAAACBB--- ---BCCAAAAAAAAAAAAAACBB--- ---BCCAAAAAAAAAAAAAACBB--- ---BCCAAAAAAAAAAAAAACBB--- ---BCCAAAAAAAAAAAAAACBB--- ---BCCAAAAAAAAAAAAAACBB--- ---DCCAAAAAAAAAAAAAACCD--- ---DCCAAAAAAAAAAAAAACCD--- ---DDCAAAAAAAAAAAAAACDD--- -----DCCCCCCCCCCCCCCD----- ------DCCCCCCCCCCCCD------ -------DDCCCCCCCCDD------- ---------DDDDDDDD--------- 
---------BBBBBBBB--------- -------BBBBBBBBBBBB------- -----BBBBBBBBBBBBBBBB----- ----BBBBBBBBBBBBBBBBBB---- ---BCCAAAAAAAAAAAAAACBB--- ---BCCAAAAAAAAAAAAAACBB--- ---BCCAAAAAAAAAAAAAACBB--- ---BCCAAAAAAAAAAAAAACBB--- ---BCCAAAAAAAAAAAAAACBB--- ---BCCAAAAAAAAAAAAAACBB--- ---BCCAAAAAAAAAAAAAACBB--- ---BCCAAAAAAAAAAAAAACBB--- ---BCCAAAAAAAAAAAAAACBB--- ---BCCAAAAAAAAAAAAAACBB--- ---BCCAAAAAAAAAAAAAACBB--- ---DCCAAAAAAAAAAAAAACCD--- ---DCCAAAAAAAAAAAAAACCD--- ---DDCAAAAAAAAAAAAAACDD--- -----DCCCCCCCCCCCCCCD----- ------DCCCCCCCCCCCCD------ -------DDCCCCCCCCDD------- ---------DDDDDDDD--------- 
-------------------------- -------BBBBBBBBBBBB------- -----BBBBBBBBBBBBBBBB----- ----BBBBBBBBBBBBBBBBBB---- ---BCCAAAAAAAAAAAAAACBB--- ---BCCAAAAAAAAAAAAAACBB--- ---BCCAAAAAAAAAAAAAACBB--- ---BCCAAAAAAAAAAAAAACBB--- ---BCCAAAAAAAAAAAAAACBB--- ---BCCAAAAAAAAAAAAAACBB--- ---BCCAAAAAAAAAAAAAACBB--- ---BCCAAAAAAAAAAAAAACBB--- ---BCCAAAAAAAAAAAAAACBB--- ---BCCAAAAAAAAAAAAAACBB--- ---BCCAAAAAAAAAAAAAACBB--- ---DCCAAAAAAAAAAAAAACCD--- ---DCCAAAAAAAAAAAAAACCD--- ---DDCAAAAAAAAAAAAAACDD--- -----DCCCCCCCCCCCCCCD----- ------DCCCCCCCCCCCCD------ -------DDCCCCCCCCDD------- ---------DDDDDDDD--------- 
-------------------------- -------BBBBBBBBBBBB------- -----BBBBBBBBBBBBBBBB----- ----BBBBBBBBBBBBBBBBBB---- ---BCCAAAAAAAAAAAAAACBB--- ---BCCAAAAAAAAAAAAAACBB--- ---BCCAAAAAAAAAAAAAACBB--- ---BCCAAAAAAAAAAAAAACBB--- ---BCCAAAAAAAAAAAAAACBB--- ---BCCAAAAAAAAAAAAAACBB--- ---BCCAAAAAAAAAAAAAACBB--- ---BCCAAAAAAAAAAAAAACBB--- ---BCCAAAAAAAAAAAAAACBB--- ---BCCAAAAAAAAAAAAAACBB--- ---BCCAAAAAAAAAAAAAACBB--- ---DCCAAAAAAAAAAAAAACCD--- ---DCCAAAAAAAAAAAAAACCD--- ---DDCAAAAAAAAAAAAAACDD--- -----DCCCCCCCCCCCCCCD----- ------DCCCCCCCCCCCCD------ -------DDDDDDDDDDDD------- -------------------------- 
-------------------------- -------------------------- -----BBBBBBBBBBBBBBBB----- ----BBBBBBBBBBBBBBBBBB---- ----BBBBBBBBBBBBBBBBBB---- ----BBBBBBBBBBBBBBBBBB---- ----BBBBBBBBBBBBBBBBBB---- ----BBBBBBBBBBBBBBBBBB---- ----BBBBBBBBBBBBBBBBBB---- ----BBBBBBBBBBBBBBBBBB---- ----BBBBBBBBBBBBBBBBBB---- ----BBBBBBBBBBBBBBBBBB---- ----BBBBBBBBBBBBBBBBBB---- ----BBBBBBBBBBBBBBBBBB---- ----BBBBBBBBBBBBBBBBBB---- ---DCCAAAAAAAAAAAAAACCD--- ---DCCAAAAAAAAAAAAAACCD--- ---DDCAAAAAAAAAAAAAACDD--- -----DCCCCCCCCCCCCCCD----- ------DCCCCCCCCCCCCD------ -------DDDDDDDDDDDD------- -------------------------- 
-------------------------- -------------------------- -------------------------- -----DDDDDDDDDDDDDDDD----- -----DDDDDDDDDDDDDDDD----- -----DDDDDDDDDDDDDDDD----- -----DDDDDDDDDDDDDDDD----- -----DDDDDDDDDDDDDDDD----- -----DDDDDDDDDDDDDDDD----- -----DDDDDDDDDDDDDDDD----- -----DDDDDDDDDDDDDDDD----- -----DDDDDDDDDDDDDDDD----- -----DDDDDDDDDDDDDDDD----- -----DDDDDDDDDDDDDDDD----- ----DBBBBBBBBBBBBBBBBD---- ----DCAAAAAAAAAAAAAACD---- ----DCAAAAAAAAAAAAAACD---- ----DCAAAAAAAAAAAAAACD---- -----DCCCCCCCCCCCCCCD----- ------DDDDDDDDDDDDDD------ -------------------------- -------------------------- 
-------------------------- -------------------------- -------------------------- -----DDDDDDDDDDDDDDDD----- -----DDDDDDDDDDDDDDDD----- -----DDDDDDDDDDDDDDDD----- -----DDDDDDDDDDDDDDDD----- -----DDDDDDDDDDDDDDDD----- -----DDDDDDDDDDDDDDDD----- -----DDDDDDDDDDDDDDDD----- -----DDDDDDDDDDDDDDDD----- -----DDDDDDDDDDDDDDDD----- -----DDDDDDDDDDDDDDDD----- -----DDDDDDDDDDDDDDDD----- -----DDDDDDDDDDDDDDDD----- -----DCCCCCCCCCCCCCCD----- -----DCCCCCCCCCCCCCCD----- -----DCCCCCCCCCCCCCCD----- ------DDDDDDDDDDDDDD------ -------------------------- -------------------------- -------------------------- 
-------------------------- -------------------------- -------------------------- ------DDDDDDDDDDDDDD------ ------DDDDDDDDDDDDDD------ ------DDDDDDDDDDDDDD------ ------DDDDDDDDDDDDDD------ ------DDDDDDDDDDDDDD------ ------DDDDDDDDDDDDDD------ ------DDDDDDDDDDDDDD------ ------DDDDDDDDDDDDDD------ ------DDDDDDDDDDDDDD------ ------DDDDDDDDDDDDDD------ ------DDDDDDDDDDDDDD------ ------DDDDDDDDDDDDDD------ ------DDDDDDDDDDDDDD------ ------DDDDDDDDDDDDDD------ ------DDDDDDDDDDDDDD------ -------------------------- -------------------------- -------------------------- -------------------------- 
