model
size = 32, scale = 0.05, origin = -y
material 
  colors = A:#111 B:#00B C:#0E0 D:#FF0 E:#EEE F:#888 G:#6F0 H:#0F0 I:#0F6 J:#3F0 K:#0D0 L:#6C0 M:#3F3 N:#0F3 O:#C90
voxels
7-8AC7A16-8AC8A15-6A2(CA)C6A15-6AO3AC6A15-4ACAC3ACAC4A15-4AC7AC4A15-2AC11AC2A15-CAC11ACAC15-17A119-2G28-CG3CN22-2LI2KGL2CNLI2L18-CI2CG2KCN3CIC18-I2HCG2HKNK3JI18-3CG6J2K2C18-4J3GN4G2K23-CN2C405-7(17A15-)H15AH15-17A22-4D26-3DGI3D23-DI2CGCIMCD21-2GI2G2AG2I2G20-CIK2E2A2ECIC18-L2E2A2EBA2E2A2EL16-C2E2A2EBA2E2A2EC15-H-2E2A2EBA2E2A2E2I15-I2E2A2EBA2E2A2EM16-J2E2A2EBA2E2A2EK17-CI2GCEBAB2CK2C20-10D23-8A26-4A309-18A13-19A12-5(21A11-)CH17AHC2(11-21A)11-6AD8AD5A11-4A2D10A2D3A11-5DE10AE4D11-D2L2CE10BE2C-D14-C2E10B2EC15-MA2E10B2EAC14-CI2E10B2EAI15-C2E10B2EC15-JA2E10B2EC16-2CE10BE2C17-2D10A2D18-14A19-12A22-8A27-2A263-A31-A12-22A3(9-23A)9-9A6B8A9-C6A10B5AC9-5A14BA-2A2(9-4A16B3A)9-3A18B2A9-3A18BAD9-DABF16BLBD10-CLM16BLI12-MA16BAC12-HA16BAJ12-CI16BIC12-JA16BKI13-C16BC14-2D14A2D15-16A16-16A17-14A20-10A24-6A229-2A30-A11-6A2-15A8-2(7A2-16A7-)7A2-8B8A7-7A12B6A7-C5A14B4AC7-5A16B4A7-4A18B3A2(7-3A20B2A)7-2A22BA7-DA22BD8-D2E19BD10-ME18BEJ10-ME17BFEJ10-CE17BFEC10-JE17BFEI10-CI18BCM11-D18AD12-20A13-18A15-16A17-14A19-12A22-8A197-A31-A10-A20-3A7-2A20-3A6-3A20-4A5-8A12B7A5-7A14B6A5-C4A18B3AC5-5A18B4A5-4A20B3A2(5-3A22B2A)5-2A24BA5-DA23B2A6-D23BD8-C22BJ8-MF18B3FH8-MF18B3FC8-JF18B3FG8-D5A17BI9-D4A4B12AD10-5A4B13A11-20A13-18A14-18A16-14A19-12A22-8A208-A21-2A6-2(3A20-4A5-)7A14B6A5-5A18B4A5-4A20B3A5-C3A20B2AC5-3A22B2A5-2A24BA5-2(2A24B2A4-)DA23B2A6-D23BAD6-C23BAJ6-HAF18B3FAH6-MAF18B3FAC6-JAF18B3FAG7-D5A8B9AC8-D5A8B9AD8-6A8B10A9-9A4B9A11-8A4B8A12-20A13-18A16-14A19-12A23-6A176-2A21-2A6-3A21-3A5-3A20-4A4-6A18B4A4-5A20B3A2(4-4A22B2A)4-C2A24BC4-3A24BAC2(3-3A25BA)3-3A23B2A5-DA23BAD5-C26BD4-H3F18B5FH5-2(C2F18B4FC6-)D6A8B10AD6-D6A8B10AD7-6A8B10A8-10A4B10A9-9A4B9A10-22A11-20A13-18A16-14A20-10A26-2A146-2A21-2A6-3A21-3A5-3A21-3A4-2(5A20-4A3-)4A22B3A3-3A24B2A4(3-3A25BA)3-3A23B3A3-D2A23B2AD4-D26BD4-C2(3F23BC4-M)3F23BG4-D7A8B11AD5-D6A8B11A6-7A8B11A6-11A4B11A7-10A4B10A9-22A11-20A13-18A15-16A17-14A21-8A143-2A21-3A5-3A21-3A4-4A21-4A3-5A20-4A3-4AB20-B3A3-3A24B2A5(3-3A25BA)3-3A23B3A3-D2A23B4A2-DA26BAD2-IE26BEC2-GE26BEG3-C3F23BC4-D7A8B11AD2(4-8A8B12A)5-11A4B11A6-11A4B11A7-24A9-22A11-20A13-18A15-16A18-12A24-4A113-2A21-3A5-3A2(21-4A3-4A)B20-B3A3-3A2B20-2B2A3-3A24B2A4(3-3A25BA)3-3A25B2A2(2-3A23B4A)2-DA26B2A2-CE26BFD2(2-CE26BEC)2-D8A8B12AD3-2(8A8B12A4-)12A4B12A5-11A4B11A7-24A8-24A9-22A11-20A14-16A17-14A21-8A111-2A2(21-3A5-3A)21-5A2-4AB20-B4A2-3A2B20-2B3A2(2-3A25B2A)2-3A26BA3(2-3A25B2A)2(2-3A23B4A)2-DA26B2A2-C27BFD2(2-C27BEC)2-D8A12B8AD2-9A12B9A3-8A12B8A4-12A8B8A5-11A8B7A6-26A7-24A9-22A11-20A13-18A16-14A20-10A109-2(3A21-3A5-)3A21-B4A2(2-3A2B20-2B3A)2(2-3A25B2A)2-3A26BA3(2-3A25B2A)2-3A23B4A-4A23B5AD2A26B3ADF29BCGF27B2EG-C27BEC2-D8A12B8AD2(2-9A12B9A)3-12A8B8A4-12A8B8A5-26A7-24A8-24A9-22A12-18A15-16A18-12A24-4A80-2(3A21-3A5-)3A21-B4A3-2A2B20-2B3A3-2A2B20-3B2A3-2A25B2A3-2A26BA3-2A9B16ABA2(3-2A9B18A)2-3A9B18A-4A9B23A9B22A10B19ADF11B16A2BACF11B16A2BDC12B16A2EC-D8A3B17AD2(2-9A3B18A)3-8A3B17A4-8A3B17A5-7A3B16A6-7A3B16A7-6A4B14A9-5A4B13A11-20A14-2A3B11A18-12A23-6A79-2(3A21-3A5-)3A21-B4A3-2A2B20-2B3A3-2A2B20-3B2A3-2A25B2A3-2A26B3(A3-2A9B16AB)A-8A5B16AB10A2(5B27A)5B19AD7A5B16A2BHD2(7A5B16A2B2D)9A3B18AD-2(9A3B18A2-)9A3B18A3-8A3B17A5-7A3B16A6-7A3B16A7-6A12B6A9-5A12B5A11-20A14-2AB13A17-14A21-8A78-2(3A21-3A5-)3A21-B4A3-2A2B20-2B3A3-2A2B20-3B2A2(3-2A26BA)3(3-2A9B16ABA)-8A5B16AB10A5B27A2B30A2B21AH8A2(2B21AHD7A)2B21A2D7A2B21AD-2(7A2B21A2-)30A3-28A4-28A5-26A7-24A9-22A11-20A13-3AB14A16-14A21-8A78-2(3A21-3A5-)3A21-B4A3-2A2B20-2B3A3-2A2B20-3B2A2(3-2A26BA)3(3-2A9B16ABA)-8A5B16AB10A5B27A5(2B21AH8A)2B21AH3(-7A2B21AC)2(2-6A2B20A-C)3-5A2B19A2-C4-3A3B18A3-C5-2A3B17A4-C6-20A5-C7-18A6-C9-14A8-C12-8A11-C66-2(3A21-3A5-)3A21-B4A3-2A2B20-2B3A3-2A2B20-3B2A3-2A25B2A3-2A26B3(A3-2A9B16AB)A-8A2(5B16AB10A)2B30A3(2B21AH8A)2B30A2B22A-2(7A2B21A2-)7A2B21A3-6A2B20A5-5A2B19A6-5A2B19A7-3A3B18A9-2A3B17A11-20A14-16A17-14A21-8A78-2(3A21-3A5-)3A21-B4A3-2A2B20-2B3A3-2A2B20-3B2A3-2A25B2A3-2A26B3(A3-2A9B16AB)A2-7A5B18A-8A5B27A2(2B30A)2B21AH8A2B30A2B22A-2(7A2B21A2-)7A2B21A3-6A2B20A4-6A2B20A5-5A2B19A6-5A2B19A7-3A3B18A9-2A3B17A11-20A14-16A18-12A23-6A79-2(3A21-3A5-)3A21-B4A2(3-2A2B20-2B3A)3-2A25B2A3-2A26B3(A3-2A9B16AB)A2(2-7A5B18A)-8A3(2B30A)2B22A-3(7A2B21A2-)7A2B21A3-6A2B20A4-6A2B20A5-5A2B19A7-4A2B18A8-3A3B18A9-2A3B17A12-18A15-16A18-12A24-4A80-2(3A21-3A5-)3A21-5A3-3AB20-B4A3-2A2B20-2B3A2(3-2A25B2A)3(3-2A9B16ABA)2(2-7A5B18A)7(2-7A2B21A)3-6A2B20A4-6A2B20A5-5A2B19A6-5A2B19A7-4A2B18A9-2A3B17A11-A3B16A13-18A16-14A20-10A109-2(3A21-3A5-)3A21-5A3-3AB20-B4A3-2A2B20-2B3A3-2A24B3A3-2A25B2A3(3-2A9B16ABA)2(2-7A5B18A)6(2-7A2B21A)3-2(6A2B20A4-)6A2B20A5-5A2B19A7-4A2B18A8-4A2B18A9-22A11-20A14-16A17-14A21-8A110-2(3A21-3A5-)3A21-4A4-4A20-4A4-3AB20-B3A4-2A24B2A4-2A25BA3(4-2A9B17A)2(4-6A5B17A)3-3(7A2B21A2-)7A2B21A3-3(6A2B20A4-)6A2B20A5-5A2B19A6-5A2B19A7-4A2B18A9-3A2B17A11-20A13-18A15-16A18-12A24-4A114-A2(21-3A5-3A)21-2(4A4-4A20-)4A4-3A22B3A4-2A24B2A3(4-2A9B17A)2(4-6A5B17A)6(4-6A2B20A)5-2(5A2B19A6-)5A2B19A7-4A2B18A9-3A2B17A11-2A2B16A13-18A15-16A17-14A21-8A166-2(3A29-)2(3A7-2A20-)3A2(7-A22B2A)3(7-8AB16A)3(6-26A)5-28A4-28A5-3(26A6-)26A7-24A8-24A9-22A10-22A11-20A13-18A16-14A20-10A26-2A169-2A30-2A29-3A8-5A14B5A8-3A18B3A2(8-2A20B2A)3(8-8AB15A)8-24A7-5(26A6-)26A7-2(24A8-)24A9-22A11-20A12-20A13-18A16-14A19-12A23-6A179-2(A18-2A11-)6A8B7A11-4A12B5A9-5A14B5A2(8-3A18B3A)3(8-8AB15A)8(8-24A)9-22A10-22A11-20A13-18A14-18A16-14A19-12A22-8A211-19A2(12-20A)12-6A8B7A11-4A12B5A11-3A14B4A11-2A16B3A3(11-6AB14A)8(10-22A)11-20A12-20A13-18A15-16A17-14A19-12A22-8A243-4(18A14-)6A6B6A14-4A10B4A14-2A14B2A3(14-5AB12A)14-18A13-5(20A12-)20A13-18A14-18A15-16A16-16A17-14A20-10A24-6A277-5(16A16-)7A2B7A16-4A8B4A3(16-2A3B11A)3(16-16A)15-18A14-18A15-2(16A16-)16A17-14A18-14A19-12A22-8A27-2A409-8(12A20-)12A19-3(14A18-)14A19-12A20-12A21-10A23-8A26-4A700-4A27-6A25-3(8A24-)8A25-6A27-4A398-
