model
size = 24 14 14, scale = 0.05, origin = -y
material 
  colors = A:#52433D B:#1F1F1F
voxels
------------------------ ------------------------ ------------------------ ------------------------ ------------------------ ------------------------ ------------------------ ------------------------ ------------------------ ------------------------ ------------------------ ------------------AAA--- ------------------------ ------------------------ 
------------------------ ------AAAAAAAAAAAAAAAA-- ------AAAAAAAAAAAAAAAA-- ------AAAAAAAAAAAAAAAA-- ------AAAAAAAAAAAAAAAA-- ------------------------ ------------------------ ------------------------ ------------------------ ------------------------ ------------------------ --------------AAAAAAA--- ------------------------ ------------------------ 
------B-B-B-B-B-B-B-B--- ----AAAAAAAAAAAAAAAAAAA- ----AAAAAAAAAAAAAAAAAAA- ----AAAAAAAAAAAAAAAAAAA- ----AAAAAAAAAAAAAAAAAAA- ------AAAAAAAAAAAAAAAA-- ------AAAAAAAAAAAAAAAA-- ------------------------ ------------------------ ------------------------ ------------------------ --------------AAAAAAAAA- ------------------------ ------------------------ 
----B------------------- --AAAAAAAAAAAAAAAAAAAAAA --AA-------------------A --AA-------------------A --AA-A----------------AA ----AA--A----AA-------A- ----AAAAAA--AAAAAAAAAAA- ------AAAAAAAAAAAAAAAAA- ---------------AAAAAAAA- ---------------AAAAAAAA- --------------AAAAAAAAA- --------------AAAAAAAAA- -----------------------A ------------------------ 
--B---B-B-B-B-B-B-B-B--- -AAAAAAAAAAAAAAAAAAAAAAA -A---------------------A -A---------------------A -AAA-------------------A --AA-------------------A --AAAA------AAAAA------A ----AA---AAA--AAA------A ------AAA-----AAA------A --------------AAA------A --------------AAA------A --------------AAA------A -----------------------A ------------------------ 
----B---------------B--- AAAAAAAAAAAAAAAAAAAAAAAA A----------------------A A----------------------A AA---------------------A -A---------------------A --AA--------ABA--------A --AA-----ABA-BA--------A ----AAABA----AA--------A -------------AA--------A -------------AA--------A --------------A--------A --------------A--------A ------------------------ 
--B---B-B-B-B-B-B-B----- AAAAAAAAAAAAAAAAAAAAAAAA A----------------------A A----------------------A A----------------------A -A---------------------A --A---------AAA--------A --A------AABAAA--------A ---AAAAAB---AAA--------A ------------BAA--------A -------------AA--------A --------------A--------A --------------A--------A --------------A--------- 
--B---B-B-B-B-B-B-B----- AAAAAAAAAAAAAAAAAAAAAAAA A----------------------A A----------------------A A----------------------A -A---------------------A --A---------AAA--------A --A------AABAAA--------A ---AAAAAB---AAA--------A ------------BAA--------A -------------AA--------A --------------A--------A --------------A--------A --------------A--------- 
----B---------------B--- AAAAAAAAAAAAAAAAAAAAAAAA A----------------------A A----------------------A AA---------------------A -A---------------------A --AA--------ABA--------A --AA-----ABA-BA--------A ----AAABA----AA--------A -------------AA--------A -------------AA--------A --------------A--------A --------------A--------A ------------------------ 
--B---B-B-B-B-B-B-B-B--- -AAAAAAAAAAAAAAAAAAAAAAA -A---------------------A -A---------------------A -AAA-------------------A --AA-------------------A --AAAA------AAAAA------A ----AA---AAA--AAA------A ------AAA-----AAA------A --------------AAA------A --------------AAA------A --------------AAA------A -----------------------A ------------------------ 
----B------------------- --AAAAAAAAAAAAAAAAAAAAAA --AA------------------AA --AA-------------------A --AA-A----------------AA ----AA--A----AA-------A- ----AAAAAA--AAAAAAAAAAA- ------AAAAAAAAAAAAAAAAA- ---------------AAAAAAAA- ---------------AAAAAAAA- --------------AAAAAAAAA- --------------AAAAAAAAA- -----------------------A ------------------------ 
------B-B-B-B-B-B-B-B--- ----AAAAAAAAAAAAAAAAAAA- ----AAAAAAAAAAAAAAAAAAA- ----AAAAAAAAAAAAAAAAAAA- ----AAAAAAAAAAAAAAAAAAA- ------AAAAAAAAAAAAAAAA-- ------AAAAAAAAAAAAAAAA-- ------------------------ ------------------------ ------------------------ ------------------------ --------------AAAAAAAAA- ------------------------ ------------------------ 
------------------------ ------AAAAAAAAAAAAAAAA-- ------AAAAAAAAAAAAAAAA-- ------AAAAAAAAAAAAAAAA-- ------AAAAAAAAAAAAAAAA-- ------------------------ ------------------------ ------------------------ ------------------------ ------------------------ ------------------------ --------------AAAAAAA--- ------------------------ ------------------------ 
------------------------ ------------------------ ------------------------ ------------------------ ------------------------ ------------------------ ------------------------ ------------------------ ------------------------ ------------------------ ------------------------ ------------------AAA--- ------------------------ ------------------------ 
