model
size = 30 10 28, scale = 0.05, origin = -y
material 
  colors = A:#52433D B:#6E552F C:#555
voxels
------------------------------ -----------BBBBBBBB----------- -----------BAAAAAAB----------- ------------ABBBBA------------ ------------BABBAB------------ ------------BABBAB------------ -----------BAABBAAB----------- -----------BAAAAAAB----------- -------------BBBB------------- ------------------------------ 
---------AAAAAAAAAAAA--------- ----------AAAAAAAAAA---------- ----------AAAAAAAAAA---------- ----------AAAAAAAAAA---------- ----------AACCCCCCAA---------- ----------AAAAAAAAAA---------- ----------AAAAAAAAAA---------- ---------AAAAAAAAAAAA--------- -----------AAAAAAAA----------- -------------AAAA------------- 
------------------------------ ------------------------------ ------------------------------ --------CCC--------CCC-------- --------CCC--------CCC-------- ------------------------------ ------------------------------ ------------------------------ ------------------------------ ------------------------------ 
------------------------------ ------------------------------ ------------------------------ -----A-CC------------CC-A----- -----A-CC------------CC-A----- ------------------------------ ------------------------------ ------------------------------ ------------------------------ ------------------------------ 
------------------------------ ------------------------------ -----A-B--------------B-A----- -----CCA--------------ACC----- -----CCA--------------ACC----- -----A-B--------------B-A----- ------------------------------ ------------------------------ ------------------------------ ------------------------------ 
------------------------------ ----BBB----------------BBB---- ----AAA----------------AAA---- ----CCA----------------ACC---- ----CCA----------------ACC---- -----AA----------------AA----- -----BB----------------BB----- ------------------------------ ------------------------------ ------------------------------ 
------------------------------ ----B--------------------B---- ----A--------------------A---- ----C--------------------C---- ----C--------------------C---- ----A--------------------A---- ----B--------------------B---- ------------------------------ ------------------------------ ------------------------------ 
------------------------------ ----B--------------------B---- ----A--------------------A---- ---CA--------------------AC--- ---CA--------------------AC--- ----A--------------------A---- ----B--------------------B---- ------------------------------ ------------------------------ ------------------------------ 
------------------------------ ----B--------------------B---- ----A--------------------A---- --CCA--------------------ACC-- --CCA--------------------ACC-- ----A--------------------A---- ----B--------------------B---- ------------------------------ ------------------------------ ------------------------------ 
------------------------------ ---BB--------------------BB--- ---AA--------------------AA--- --CAA--------------------AAC-- --CAA--------------------AAC-- ---AA--------------------AA--- ---BB--------------------BB--- ------------------------------ ------------------------------ ------------------------------ 
------------------------------ ---B----------------------B--- ---A----------------------A--- --CA----------------------AC-- --CA----------------------AC-- ---A----------------------A--- ---B----------------------B--- ------------------------------ ------------------------------ ------------------------------ 
------------------------------ --B------------------------B-- --A------------------------A-- -CA------------------------AC- -CA------------------------AC- --A------------------------A-- --B------------------------B-- ------------------------------ ------------------------------ ------------------------------ 
------------------------------ --B------------------------B-- --A------------------------A-- -CA------------------------AC- -CA------------------------AC- --A------------------------A-- --B------------------------B-- ------------------------------ ------------------------------ ------------------------------ 
------------------------------ --B------------------------B-- --A------------------------A-- -CA------------------------AC- -CA------------------------AC- --A------------------------A-- --B------------------------B-- ------------------------------ ------------------------------ ------------------------------ 
------------------------------ -BB------------------------BB- -AA------------------------AA- ACA------------------------ACA ACA------------------------ACA -AA------------------------AA- --B------------------------B-- ------------------------------ ------------------------------ ------------------------------ 
------------------------------ --B------------------------B-- --A------------------------A-- -CA------------------------AC- -CA------------------------AC- --A------------------------A-- --B------------------------B-- ------------------------------ ------------------------------ ------------------------------ 
------------------------------ --B------------------------B-- --A------------------------A-- -CA------------------------AC- -CA------------------------AC- --A------------------------A-- --B------------------------B-- ------------------------------ ------------------------------ ------------------------------ 
------------------------------ --BB----------------------BB-- --AA----------------------AA-- -CAA----------------------AAC- -CAA----------------------AAC- --AA----------------------AA-- --BB----------------------BB-- ------------------------------ ------------------------------ ------------------------------ 
------------------------------ ---B----------------------B--- ---A----------------------A--- --CA----------------------AC-- --CA----------------------AC-- ---A----------------------A--- ---B----------------------B--- ------------------------------ ------------------------------ ------------------------------ 
------------------------------ ---BB--------------------BB--- ---AA--------------------AA--- --CAA--------------------AAC-- --CAA--------------------AAC-- ---AA--------------------AA--- ---BB--------------------BB--- ------------------------------ ------------------------------ ------------------------------ 
------------------------------ ----B--------------------B---- ----A--------------------A---- --CCA--------------------ACC-- --CCA--------------------ACC-- ----A--------------------A---- ----B--------------------B---- ------------------------------ ------------------------------ ------------------------------ 
------------------------------ ----B--------------------B---- ----A--------------------A---- ---CA--------------------AC--- ---CA--------------------AC--- ----A--------------------A---- ----B--------------------B---- ------------------------------ ------------------------------ ------------------------------ 
------------------------------ -----BB----------------BB----- -----AA----------------AA----- ----CAA----------------AAC---- ----CAA----------------AAC---- -----AA----------------AA----- -----BA----------------AB----- ------------------------------ ------------------------------ ------------------------------ 
------------------------------ ------BB--------------BB------ ------AA--------------AA------ ----CCAA--------------AACC---- ----CCAA--------------AACC---- ------AA--------------AA------ ------BA--------------AB------ ------------------------------ ------------------------------ ------------------------------ 
------------------------------ -------BBB----------BBB------- -------AAA----------AAA------- -----CCAAA----------AAACC----- -----CCAAA----------AAACC----- -------AAA----------AAA------- -------BBA----------ABB------- ------------------------------ ------------------------------ ------------------------------ 
------------------------------ ---------BBB------BBB--------- ---------AAA------AAA--------- -------CCAAA------AAACC------- -------CCAAA------AAACC------- ---------AAA------AAA--------- ---------BBA------ABB--------- ------------------------------ ------------------------------ ------------------------------ 
------------------------------ -----------BBBBBBBB----------- -----------AAAAAAAA----------- --------CCCAAAAAAAACCC-------- --------CCCAAAAAAAACCC-------- -----------AAAAAAAA----------- -----------BBBBBBBB----------- ------------------------------ ------------------------------ ------------------------------ 
------------------------------ ------------------------------ ------------------------------ -----------CCCCCCCC----------- -----------CCCCCCCC----------- ------------------------------ ------------------------------ ------------------------------ ------------------------------ ------------------------------ 
