model
size = 22 27 15, scale = 0.05, origin = -y
material 
  colors = A:#1D2455 B:#52433D C:#222
voxels
---------------------- ---------------------- ---------------------- ---------------------- ---------------------- ---------------------- ---------------------- ---------------------- ---------------------- ---------------------- ---------------------- ---------------------- ---------------------- ---------------------- ---------------------- ---------------------- ---------------------- ---------------------- ---------------------- ----------------C----- ---------------------- ---------------------- ---------------------- ---------------------- ---------------------- ---------------------- ---------------------- 
---------------------- ---------------------- ---------------------- ---------------------- ---------------------- ---------------------- ---------------------- ---------------------- ---------------------- ---------------------- ---------------------- ---------------------- ---------------------- -----B----------B----- -----B----------B----- -----B----------B----- -----B----------B----- -----B----------B----- -----B----------B----- ----------------B----- ---------------------- ---------------C-C---- ---------------------- ---------------------- ---------------------- ---------------------- ---------------------- 
---------------------- ---------------------- ---------------------- ---------------------- ---------------------- ---------------------- ---------------------- ------B--------B------ -----B----------B----- -----B----------B----- -----B----------B----- -----B----------B----- -----B----------B----- ---AAAAAAAAAAAAAAAA--- ---AAAAAAAAAAAAAAAA--- --AAAAAAAAAAAAAAAAAA-- -AAAAAAAAAAAAAAAAAAAA- AAAAAAAAAAAAAAAAAAAAAA AAAAAAAAAAAAAAAAAAAAAA -----B---------BBB---- -----B---------BBB---- -----B--------BBBBB--- ---------------------- ---------------------- ---------------------- ---------------------- ---------------------- 
---------------------- ---------------------- ---------------------- ---------------------- ---------------------- ---------------------- ------B--------B------ ----BAAAAAAAAAAAAB---- ----AAAAAAAAAAAAAA---- ----AAAAAAAAAAAAAA---- ----AAAAAAAAAAAAAA---- ---AAAAAAAAAAAAAAAA--- ---AAAAAAAAAAAAAAAA--- ---AAAAAAAAAAAAAAAA--- --AAAAAAAAAAAAAAAAAA-- --AAAAAAAAAAAAAAAAAA-- AAAAAAAAAAAAAAAAAAAAAA AAAAAAAAAAAAAAAAAAAAAA AAAAAAAAAAAAAAAAAAAAAA AAAAAAAAAAAAAAAAAAAAAA AAAAAAAAAAAAAAAAAAAAAA AAAAAAAAAAAAAAAAAAAAAA -----B--------BBBBB--- ---------------------- ---------------------- ---------------------- ---------------------- 
---------------------- ---------------------- ---------------------- ---------------------- --------AAAAAA-------- ------BAAAAAAAAB------ ----BAAAAAAAAAAAAB---- ----AAAAAAAAAAAAAA---- ----AAAAAAAAAAAAAA---- ---AAAAAAAAAAAAAAAA--- ---AAAAAAAAAAAAAAAA--- ---AAAAAAAAAAAAAAAA--- ---AAAAAAAAAAAAAAAA--- ---AAAAAAAAAAAAAAAA--- -AAAAAAAAAAAAAAAAAAAA- -AAAAAAAAAAAAAAAAAAAA- AAAAAAAAAAAAAAAAAAAAAA AAAAAAAAAAAAAAAAAAAAAA AAAAAAAAAAAAAAAAAAAAAA AAAAAAAAAAAAAAAAAAAAAA AAAAAAAAAAAAAAAAAAAAAA AAAAAAAAAAAAAAAAAAAAAA AAAAAAAAAAAAAAAAAAAAAA -----B--------BBBBB--- ---------------------- ---------------------- ---------------------- 
--------AAAAAA-------- --------AAAAAA-------- --------AAAAAA-------- --------AAAAAA-------- ------AAAAAAAAAA------ ----BAAAAAAAAAAAAB---- ----AAAAAAAAAAAAAA---- ---AAAAAAAAAAAAAAAA--- ---AAAAAAAAAAAAAAAA--- ---AAAAAAAAAAAAAAAA--- --AAAAAAAAAAAAAAAAAA-- --AAAAAAAAAAAAAAAAAA-- --AAAAAAAAAAAAAAAAAA-- -AAAAAAAAAAAAAAAAAAAA- -AAAAAAAAAAAAAAAAAAAA- -AAAAAAAAAAAAAAAAAAAA- AAAAAAAAAAAAAAAAAAAAAA AAAAAAAAAAAAAAAAAAAAAA AAAAAAAAAAAAAAAAAAAAAA AAAAAAAAAAAAAAAAAAAAAA AAAAAAAAAAAAAAAAAAAAAA AAAAAAAAAAAAAAAAAAAAAA AAAAAAAAAAAAAAAAAAAAAA -----B--------BBBBB--- -----B--------BBBBB--- -----B--------BBBBB--- ---------------------- 
-------AAAAAAAA------- -------AAAAAAAA------- -------AAAAAAAA------- -------AAAAAAAA------- -----AAAAAAAAAAAA----- ----AAAAAAAAAAAAAA---- ---AAAAAAAAAAAAAAAA--- ---AAAAAAAAAAAAAAAA--- ---AAAAAAAAAAAAAAAA--- --AAAAAAAAAAAAAAAAAA-- --AAAAAAAAAAAAAAAAAA-- --AAAAAAAAAAAAAAAAAA-- --AAAAAAAAAAAAAAAAAA-- -AAAAAAAAAAAAAAAAAAAA- -AAAAAAAAAAAAAAAAAAAA- -AAAAAAAAAAAAAAAAAAAA- AAAAAAAAAAAAAAAAAAAAAA AAAAAAAAAAAAAAAAAAAAAA AAAAAAAAAAAAAAAAAAAAAA AAAAAAAAAAAAAAAAAAAAAA AAAAAAAAAAAAAAAAAAAAAA AAAAAAAAAAAAAAAAAAAAAA AAAAAAAAAAAAAAAAAAAAAA AAAAAAAAAAAAAAAAAAAAAA -AAAAAAAAAAAAAAAAAAAA- ---AAAAAAAAAAAAAAAA--- -----B----------B----- 
------AAAAAAAAAA------ ------AAAAAAAAAA------ ------AAAAAAAAAA------ ------AAAAAAAAAA------ ----AAAAAAAAAAAAAA---- ----AAAAAAAAAAAAAA---- ---AAAAAAAAAAAAAAAA--- ---AAAAAAAAAAAAAAAA--- ---AAAAAAAAAAAAAAAA--- --AAAAAAAAAAAAAAAAAA-- --AAAAAAAAAAAAAAAAAA-- --AAAAAAAAAAAAAAAAAA-- --AAAAAAAAAAAAAAAAAA-- -AAAAAAAAAAAAAAAAAAAA- -AAAAAAAAAAAAAAAAAAAA- -AAAAAAAAAAAAAAAAAAAA- AAAAAAAAAAAAAAAAAAAAAA AAAAAAAAAAAAAAAAAAAAAA AAAAAAAAAAAAAAAAAAAAAA AAAAAAAAAAAAAAAAAAAAAA AAAAAAAAAAAAAAAAAAAAAA AAAAAAAAAAAAAAAAAAAAAA AAAAAAAAAAAAAAAAAAAAAA AAAAAAAAAAAAAAAAAAAAAA -AAAAAAAAAAAAAAAAAAAA- ---AAAAAAAAAAAAAAAA--- -----B----------B----- 
-----AAAAAAAAAAAA----- -----AAAAAAAAAAAA----- -----AAAAAAAAAAAA----- -----AAAAAAAAAAAA----- ----AAAAAAAAAAAAAA---- ----AAAAAAAAAAAAAA---- ---AAAAAAAAAAAAAAAA--- ---AAAAAAAAAAAAAAAA--- ---AAAAAAAAAAAAAAAA--- --AAAAAAAAAAAAAAAAAA-- --AAAAAAAAAAAAAAAAAA-- --AAAAAAAAAAAAAAAAAA-- --AAAAAAAAAAAAAAAAAA-- -AAAAAAAAAAAAAAAAAAAA- -AAAAAAAAAAAAAAAAAAAA- -AAAAAAAAAAAAAAAAAAAA- AAAAAAAAAAAAAAAAAAAAAA AAAAAAAAAAAAAAAAAAAAAA AAAAAAAAAAAAAAAAAAAAAA AAAAAAAAAAAAAAAAAAAAAA AAAAAAAAAAAAAAAAAAAAAA AAAAAAAAAAAAAAAAAAAAAA AAAAAAAAAAAAAAAAAAAAAA AAAAAAAAAAAAAAAAAAAAAA -AAAAAAAAAAAAAAAAAAAA- ---AAAAAAAAAAAAAAAA--- -----B----------B----- 
-----AAAAAAAAAAAA----- -----AAAAAAAAAAAA----- -----AAAAAAAAAAAA----- -----AAAAAAAAAAAA----- ----AAAAAAAAAAAAAA---- ----AAAAAAAAAAAAAA---- ---AAAAAAAAAAAAAAAA--- ---AAAAAAAAAAAAAAAA--- ---AAAAAAAAAAAAAAAA--- --AAAAAAAAAAAAAAAAAA-- --AAAAAAAAAAAAAAAAAA-- --AAAAAAAAAAAAAAAAAA-- --AAAAAAAAAAAAAAAAAA-- -AAAAAAAAAAAAAAAAAAAA- -AAAAAAAAAAAAAAAAAAAA- -AAAAAAAAAAAAAAAAAAAA- AAAAAAAAAAAAAAAAAAAAAA AAAAAAAAAAAAAAAAAAAAAA AAAAAAAAAAAAAAAAAAAAAA AAAAAAAAAAAAAAAAAAAAAA AAAAAAAAAAAAAAAAAAAAAA AAAAAAAAAAAAAAAAAAAAAA AAAAAAAAAAAAAAAAAAAAAA AAAAAAAAAAAAAAAAAAAAAA -AAAAAAAAAAAAAAAAAAAA- ---AAAAAAAAAAAAAAAA--- -----B----------B----- 
-----AAAAAAAAAAAA----- -----AAAAAAAAAAAA----- -----AAAAAAAAAAAA----- -----AAAAAAAAAAAA----- ----AAAAAAAAAAAAAA---- ----AAAAAAAAAAAAAA---- ---AAAAAAAAAAAAAAAA--- ---AAAAAAAAAAAAAAAA--- ---AAAAAAAAAAAAAAAA--- --AAAAAAAAAAAAAAAAAA-- --AAAAAAAAAAAAAAAAAA-- --AAAAAAAAAAAAAAAAAA-- --AAAAAAAAAAAAAAAAAA-- -AAAAAAAAAAAAAAAAAAAA- -AAAAAAAAAAAAAAAAAAAA- -AAAAAAAAAAAAAAAAAAAA- AAAAAAAAAAAAAAAAAAAAAA AAAAAAAAAAAAAAAAAAAAAA AAAAAAAAAAAAAAAAAAAAAA AAAAAAAAAAAAAAAAAAAAAA AAAAAAAAAAAAAAAAAAAAAA AAAAAAAAAAAAAAAAAAAAAA AAAAAAAAAAAAAAAAAAAAAA AAAAAAAAAAAAAAAAAAAAAA -AAAAAAAAAAAAAAAAAAAA- ---AAAAAAAAAAAAAAAA--- -----B----------B----- 
------AAAAAAAAAA------ -----AAAAAAAAAAAA----- -----AAAAAAAAAAAA----- -----AAAAAAAAAAAA----- ----AAAAAAAAAAAAAA---- ----AAAAAAAAAAAAAA---- ---AAAAAAAAAAAAAAAA--- ---AAAAAAAAAAAAAAAA--- ---AAAAAAAAAAAAAAAA--- --AAAAAAAAAAAAAAAAAA-- --AAAAAAAAAAAAAAAAAA-- --AAAAAAAAAAAAAAAAAA-- --AAAAAAAAAAAAAAAAAA-- -AAAAAAAAAAAAAAAAAAAA- -AAAAAAAAAAAAAAAAAAAA- -AAAAAAAAAAAAAAAAAAAA- -AAAAAAAAAAAAAAAAAAAA- AAAAAAAAAAAAAAAAAAAAAA AAAAAAAAAAAAAAAAAAAAAA AAAAAAAAAAAAAAAAAAAAAA AAAAAAAAAAAAAAAAAAAAAA AAAAAAAAAAAAAAAAAAAAAA AAAAAAAAAAAAAAAAAAAAAA AAAAAAAAAAAAAAAAAAAAAA -AAAAAAAAAAAAAAAAAAAA- ---AAAAAAAAAAAAAAAA--- -----B----------B----- 
---------------------- ---------------------- -----B----------B----- -----B----------B----- -----B----------B----- -----B----------B----- -----B----------B----- -----B----------B----- -----B----------B----- -----B----------B----- -----B----------B----- -----B----------B----- -----B----------B----- -AAAAAAAAAAAAAAAAAAAA- -AAAAAAAAAAAAAAAAAAAA- -AAAAAAAAAAAAAAAAAAAA- -AAAAAAAAAAAAAAAAAAAA- -AAAAAAAAAAAAAAAAAAAA- AAAAAAAAAAAAAAAAAAAAAA AAAAAAAAAAAAAAAAAAAAAA AAAAAAAAAAAAAAAAAAAAAA AAAAAAAAAAAAAAAAAAAAAA AAAAAAAAAAAAAAAAAAAAAA AAAAAAAAAAAAAAAAAAAAAA -AAAAAAAAAAAAAAAAAAAA- ---AAAAAAAAAAAAAAAA--- -----B----------B----- 
---------------------- ---------------------- ---------------------- ---------------------- ---------------------- ---------------------- ---------------------- ---------------------- ---------------------- ---------------------- ---------------------- ---------------------- ---------------------- -----B----------B----- -----B----------B----- -----B----------B----- --AAAAAAAAAAAAAAAAAA-- -AAAAAAAAAAAAAAAAAAAA- -AAAAAAAAAAAAAAAAAAAA- AAAAAAAAAAAAAAAAAAAAAA AAAAAAAAAAAAAAAAAAAAAA AAAAAAAAAAAAAAAAAAAAAA AAAAAAAAAAAAAAAAAAAAAA AAAAAAAAAAAAAAAAAAAAAA -AAAAAAAAAAAAAAAAAAAA- ---AAAAAAAAAAAAAAAA--- -----B----------B----- 
---------------------- ---------------------- ---------------------- ---------------------- ---------------------- ---------------------- ---------------------- ---------------------- ---------------------- ---------------------- ---------------------- ---------------------- ---------------------- ---------------------- ---------------------- ---------------------- -----B----------B----- -----B----------B----- -----B----------B----- -----B----------B----- -----B----------B----- -----B----------B----- -----B----------B----- -----B----------B----- -----B----------B----- -----B----------B----- ---------------------- 
