model
size = 18 32 18, scale = 0.05, origin = -y
material 
  colors = A:#111
voxels
198-5(12A6-)12A421-13A5-12A5-13A5-6(12A6-)12A7-11A333-2(13A4-)14A4-13A5-12A5-13A5-6(12A6-)12A2(7-11A)8-10A263-2(12A5-)2(13A4-)14A4-13A5-12A5-13A5-6(12A6-)12A2(7-11A)3(8-10A)135-10A8-10A31-10A6-11A6-2(12A5-)2(13A4-)14A4-13A5-12A5-13A5-6(12A6-)12A2(7-11A)3(8-10A)9-9A10-8A49-4A11-8(8A9-2(10A8-)10A15-7A9-10A6-11A6-2(12A5-)2(13A4-)14A4-13A5-12A5-13A5-6(12A6-)12A2(7-11A)3(8-10A)9-9A10-8A3(11-7A)10-)8A9-2(10A8-)10A31-10A6-11A6-2(12A5-)2(13A4-)14A4-13A5-12A5-13A5-6(12A6-)12A2(7-11A)3(8-10A)9-9A10-8A49-4A11-8A9-2(10A8-)10A64-2(12A5-)2(13A4-)14A4-13A5-12A5-13A5-6(12A6-)12A2(7-11A)3(8-10A)135-10A8-10A98-2(13A4-)14A4-13A5-12A5-13A5-6(12A6-)12A2(7-11A)8-10A349-13A5-12A5-13A5-6(12A6-)12A7-11A438-5(12A6-)12A276-
