model
size = 16 30 15, scale = 0.05, origin = -y
material 
  colors = A:#DDD B:#FFF C:#BBB D:#AAA E:#888 F:#111 G:#444 H:#222 I:#555 J:#777
voxels
---------------- ---------------- ---------------- ---------------- ---------------- ---------------- ---------------- ---------------- ---------------- ---------------- ---------------- ---------------- ---------------- ---------------- ------ABBB------ -------BB------- --------B------- --------B------- ---------------- ---------------- ---------------- ---------------- --------A------- ---------------- ------B--------- ---------------- ---------------- ---------------- ---------------- ---------------- 
---------------- ---------------- ---------------- ---------------- ---------------- ---------------- ---------------- ---------------- ---------------- ---------------- ---------------- ---------------- ---------------- ---------------- ------AJAJA----- -------AAA------ -------AA------- --------A------- --------B------- --------B------- -------BB------- --------BB------ --------A------- -------A-------- ------A-BA------ --------B------- -------AC------- ------ABB------- -------A-------- ---------------- 
---------------- ---------------- ---------------- ---------------- ---------------- ---------------- ---------------- ---------------- ---------------- ------BBBB------ ---------------- ---------------- ---------------- --------A------- ------AIAJA----- -------AAA------ -------AAC------ -------AA------- -------AA------- -------AA------- ---BBBBAA------- -------AAABBC--- ----B---AA------ -----C-AAA------ ------AEAA------ ------EEAC------ ------EAA------- ------AAA------- ------BAA------- ------AA-------- 
---------------- ---------------- ---------------- ---------------- ---------------- ---------------- --------A------- -------CAA------ ------AAAAA----- -----AAAAAA----- ---------------- -----AAAAAA----- --------A------- --------A------- -----AIHAHD----- ------BAADB----- -----BAAAD------ -------CAC------ ------AAA------- -------AA------- ---AHHHAD------- -------AADDDA--- ----A-AAAA--A--- -----CAAAA------ -----CAAAC------ -----CAAAA------ -----BAA-B------ ------AAA------- -----BAAAA------ ------AA-------- 
---------------- -------A-------- -------A-------- -------A-------- -------A-A------ -------AAA------ -----CAAAAA----- ------CAAA------ -----AAAAAAB---- ----BAAAAAA----- -----IGGGGG----- -----AAAAAAB---- --------AA------ ------CCA-B----- ----CAAAAAA----- ----B-AAAAC----- ----CAAAAAA----- -------AAD------ ------GAAAB----- -------GAE------ ---AFFFAE------- ------CAAHHHB--- ----A--AAA-AA--- ---A-AAAA-CCB--- -----AAA-------- -----AAAAA------ ---BBAAA-A------ ----ACAAAB------ ----CAAAAA------ ----BBAABB------ 
------BAD------- ------DAD------- ------BAA------- ------BAD------- ------BADAB----- ------BAAAB----- -----BAAAAA----- -----AAAAAA----- -----AAAAAAC---- ----CAAAAAAC---- -----EAAAAAI---- -----EAAAAAA---- ---ACAAAAA------ -----AAAAAA----- ----AAAAAAAA---- ---CAAAAAAA----- ----AAAAAAAD---- -----DEAAAD----- -----GAAAE------ ------EAAG------ ---AFFAAF--D---- ---C-CCAAFFAB--- ----AAAAAA-A---- ---CAAAAA-A----- ----CAAAAAA----- -----AAAA------- ---AAAAAAAC----- -----AAAAAC----- ----A-AAAAA----- ----AAAAAA------ 
------AAAB------ ------B--B------ ------A--DD----- ------C--BC----- -----AA--AA----- -----BA--AA----- -----BA--AA----- -----AA--AAC---- ----CAA--AA----- ----AAA--AAA---- ----CAA--AAD---- -----EA--AAC---- ------A--AAAB--- ---ABAA--AAA---- ----AAA--AAAD--- ----A-A--AAAC--- ---AAAA--AAA---- ---CEAA--AAC---- ----FAA--AEE---- A-AAFFA--AF----- --AAAAA--FFIE--- ---A--A--AAAA--- ----A-A--AAAB--- -B-AAAA--AAA---- ---AAAA--AAB---- -----AA--AA----- -----AA--AACA--- ------A--AAB---- --AAAAA--AA----- -A-AAAA--AB----- 
-----AAAAAA----- -----A---AD----- -----B----C----- -----A----A----- -----A----A----- ----BA----ACA--- ----AA----AB---- ---BAA----A----- ----AA----AA---- ----AA----AAA--- ----AA----AAA--- -----D----AA---- -----D----AAA--- ----AA----AA---- -----A----AAA--- ----BA----AA---- ---AAA----AAD--- ---AAA----AA---- ---AAA----AAD--- ---AAA----AF---- ---AAA----AAEA-- ---AAC----AAA--- ----AA----AA---- ----AA----AAA--- -----A----AA---- -----A----AAB--- ---AAA----AA---- ---AAA----AA---- ----AA----AB---- ---AAA----AA---- 
-----AAAAAA----- -----A---AD----- -----A----AA---- ----AA----A----- ----AA----C----- -----A----AA---- ----AA----AC---- ----AA----AA---- ----AA----AAC--- -----A----A----- --AAAA----AA---- ----AA----AAD--- ---AAA----AAD--- -----A----AAA--- ----BA----AAAD-- ---AAA----AAAB-- ---AAA----AAAA-- ---AAA----AAA--- --AAAA----AA---- --AAAA----AADC-- ---AAA----AAAA-- ----AA----AAAA-B ---AAA----AAA--- ---AAA----AAA--- --AABA----AAA--- ---BBA----AAAA-- ---AAA----AAB--- ---AAA----AAA--- ---AAA----AA---- -----A----ABA--- 
-----AAAAD------ -----AA--D------ -----AA--A------ ----AAA--DA----- ----AAA--A------ ----AAA--AAA---- ----AAA--AAA---- ----AAA--AA----- ---A-CA--AAA---- ---AAAA--ABD---- ----AAA--AAA---- ----AAA--AAD---- ---AAAA--A------ ----AAA--A-AA--- ----AAA--AAAC--- -----AA--AAA---- ----A-A--AAAA--- ---AAAA--AAA---- ---CAAA--AAA---- ----AAA--AAAA--- -----AA--AAA---- ----AAA--AAAA--- ---AAAA--AAABA-- ------A--AA----- -----AA--AAAB--- ------A--AAA---- ----AAA--AAAA--- -----DA--AA----- ---CAAA--ABC---- -----DC--A------ 
------AAA------- -----AAAD------- -----AAAA------- -----CAAA------- ----CCAAADA----- -----CAAAAD----- ----CCAADA------ ---CCCAAAAAAC--- -----D-AAAC----- ---AAA-AA------- -----DAAAA------ ----CAAAAA------ -----AAAAAA----- ----AAAAAAAC---- -----CAAAAA----- ----DCAAAAAA---- ----AAAAAAAA---- ----AAAAAAAAD--- ----AAAAAAAA---- ----AAAAA--A---- -----AAAAAAAA--- ---CAAAAAAAAC--- ---AB-AAAAAA---- ----CAAAAAAA---- ----DAAAAAAA---- ------AAAAAAA-A- -----AAAAAB----- ------AAAAD----- ----ABAAAA------ -------AAAC----- 
------D-A------- -----CAD-------- -----CAA-------- -----ADAD------- -----DD-A------- ----AAAADA------ -----AAA-------- -----AACCA------ ------AAAD------ ----AADAAAA----- ------AAAAA----- -----AAAAAA----- -----AAAAA------ ----A-AAAAB----- -----CAAAAA----- -----AAAAA------ ----AAAAAAD----- -----AAAAA------ ----A-AAAAC----- -----CCAAAAA---- ------CA-A-A---- -----CCAAAAC---- ------CAAAAD---- ----A-CAAAAD---- ----AAAAAAA----- ------AAAC------ -----AAAAAA----- ------AAAA------ ------AAAA------ -------AAAA----- 
---------------- ---------------- -------A-------- ---------------- ---------------- -------A-------- ------A--------- ------A--A------ ------DA-------- -------AA------- ------AAAA------ ------DAAA------ -------AAC------ ----A-AAAA------ ------DAAA------ ------AAAA------ -----AAAAA------ -----AAAAAA----- ------AAAAA----- -------AAA------ ------CA-AA----- ------BAAA------ -------AAAB----- ------CCAA------ -------CAAA----- -----CBCA------- ------BAAB------ ------BCAA------ -------AB------- -------AB------- 
---------------- ---------------- ---------------- ---------------- ---------------- ---------------- ---------------- ---------------- ---------------- ---------------- -------C-------- --------A------- -------AA------- -------A-------- -------CD------- -------A-A------ ------BAAA------ ------BAA------- -------BDA------ --------C------- ---------------- ---------A------ --------A------- --------AA------ --------BA------ -------C-------- --------A------- --------A------- --------A------- ---------------- 
---------------- ---------------- ---------------- ---------------- ---------------- ---------------- ---------------- ---------------- ---------------- ---------------- ---------------- ---------------- ---------------- ---------------- ---------------- ---------------- --------A------- ---------------- ---------------- ---------------- ---------------- ---------------- ---------------- --------A------- ---------------- ---------------- ---------------- ---------------- ---------------- ---------------- 
