model
size = 30 27 30, scale = 0.05, origin = -y
material 
  colors = A:#C60 B:#EEE
voxels
-----------AAAAAAAA----------- ------------------------------ ------------------------------ ------------------------------ ------------------------------ ------------------------------ ------------------------------ ------------------------------ ------------------------------ ------------------------------ ------------------------------ ------------------------------ ------------------------------ ------------------------------ ------------------------------ ------------------------------ ------------------------------ ------------------------------ ------------------------------ ------------------------------ ------------------------------ ------------------------------ ------------------------------ ------------------------------ ------------------------------ ------------------------------ ------------------------------ 
--------AAAAAAAAAAAAAA-------- ------------------------------ ------------------------------ ------------------------------ ------------------------------ ------------------------------ ------------------------------ ------------------------------ ------------------------------ ------------------------------ ------------------------------ ------------------------------ ------------------------------ ------------------------------ ------------------------------ ------------------------------ ------------------------------ ------------------------------ ------------------------------ ------------------------------ ------------------------------ ------------------------------ ------------------------------ ------------------------------ ------------------------------ ------------------------------ ------------------------------ 
------AAAAAAAAAAAAAAAAAA------ ------------------------------ ------------------------------ ------------------------------ ------------------------------ ------------------------------ ------------------------------ ------------------------------ ------------------------------ ------------------------------ ------------------------------ ------------------------------ ------------------------------ ------------------------------ ------------------------------ ------------------------------ ------------------------------ ------------------------------ ------------------------------ ------------------------------ ------------------------------ ------------------------------ ------------------------------ ------------------------------ ------------------------------ ------------------------------ ------------------------------ 
-----AAAAAAAAAAAAAAAAAAAA----- ------------------------------ ------------------------------ ------------------------------ ------------------------------ ------------------------------ ------------------------------ ------------------------------ ------------------------------ ------------------------------ ------------------------------ ------------------------------ ------------------------------ ------------------------------ ------------------------------ ------------------------------ ------------------------------ ------------------------------ ------------------------------ ------------------------------ ------------------------------ ------------------------------ ------------------------------ ------------------------------ ------------------------------ ------------------------------ ------------------------------ 
----AAAAAAA--------AAAAAAA---- -----------AAAAAAAA----------- -----------AAAAAAAA----------- -----------AAAAAAAA----------- -----------AAAAAAAA----------- -----------AAAAAAAA----------- ------------------------------ ------------------------------ ------------------------------ ------------------------------ ------------------------------ ------------------------------ ------------------------------ ------------------------------ ------------------------------ ------------------------------ ------------------------------ ------------------------------ ------------------------------ ------------------------------ ------------------------------ ------------------------------ ------------------------------ ------------------------------ ------------------------------ ------------------------------ ------------------------------ 
---AAAAAA------------AAAAAA--- ---------AA--------AA--------- ---------AA--------AA--------- ---------AA--------AA--------- ---------AAAAAAAAAAAA--------- ---------AAAAAAAAAAAA--------- ---------AAAAAAAAAAAA--------- ---------AAAAAAAAAAAA--------- ------------------------------ ------------------------------ ------------------------------ ------------------------------ ------------------------------ ------------------------------ ------------------------------ ------------------------------ ------------------------------ ------------------------------ ------------------------------ ------------------------------ ------------------------------ ------------------------------ ------------------------------ ------------------------------ ------------------------------ ------------------------------ ------------------------------ 
--AAAAAA--------------AAAAAA-- --------A------------A-------- --------A------------A-------- --------A------------A-------- --------AAAA------AAAA-------- --------ABBB------BBBA-------- ---------ABB------BBA--------- ---------ABBBBBBBBBBA--------- ---------BBBBBBBBBBBB--------- ---------BBBBBBBBBBBB--------- ------------------------------ ------------------------------ ------------------------------ ------------------------------ ------------------------------ ------------------------------ ------------------------------ ------------------------------ ------------------------------ ------------------------------ ------------------------------ ------------------------------ ------------------------------ ------------------------------ ------------------------------ ------------------------------ ------------------------------ 
--AAAAA----------------AAAAA-- -------A--------------A------- -------A--------------A------- -------A--------------A------- -------AAA----------AAA------- -------AAB----------BAA------- --------AB----------BA-------- --------ABBB------BBBA-------- --------BBBBBBBBBBBBBB-------- --------BBBBBBBBBBBBBB-------- ---------BBBBBBBBBBBB--------- ---------BBBBBBBBBBBB--------- ------------------------------ ------------------------------ ------------------------------ ------------------------------ ------------------------------ ------------------------------ ------------------------------ ------------------------------ ------------------------------ ------------------------------ ------------------------------ ------------------------------ ------------------------------ ------------------------------ ------------------------------ 
-AAAAA------------------AAAAA- ------A----------------A------ ------A----------------A------ ------A----------------A------ ------AA--------------AA------ ------AA--------------AA------ -------A--------------A------- -------ABB----------BBA------- -------BBBBB------BBBBB------- -------BBAAA------AAABB------- --------BAAA------AAAB-------- --------BAAA------AAAB-------- ---------AAAAAAAAAAAA--------- ---------AAAAAAAAAAAA--------- ------------------------------ ------------------------------ ------------------------------ ------------------------------ ------------------------------ ------------------------------ ------------------------------ ------------------------------ ------------------------------ ------------------------------ ------------------------------ ------------------------------ ------------------------------ 
-AAAA--------------------AAAA- -----A------------------A----- -----A------------------A----- -----A------------------A----- -----AAA--------------AAA----- -----ABB--------------BBA----- ------AB--------------BA------ ------ABB------------BBA------ ------BBBB----------BBBB------ ------BBAA----------AABB------ -------BAA----------AAB------- -------BAA----------AAB------- --------AAAA------AAAA-------- --------AAAAAAAAAAAAAA-------- ---------AAAAAAAAAAAA--------- ---------AAAAAAAAAAAA--------- ---------AAAAAAAAAAAA--------- ------------------------------ ------------------------------ ------------------------------ ------------------------------ ------------------------------ ------------------------------ ------------------------------ ------------------------------ ------------------------------ ------------------------------ 
-AAAA--------------------AAAA- -----A------------------A----- -----A------------------A----- -----A------------------A----- -----AA----------------AA----- -----AB----------------BA----- -----AB----------------BA----- -----ABB--------------BBA----- ------BBB------------BBB------ ------BBA------------ABB------ -------BA------------AB------- -------BA------------AB------- --------AAA--------AAA-------- --------AABB------BBAA-------- ---------ABB------BBA--------- ---------ABB------BBA--------- ---------ABB------BBA--------- ----------BBBBBBBBBB---------- ----------BBBBBBBBBB---------- ------------------------------ ------------------------------ ------------------------------ ------------------------------ ------------------------------ ------------------------------ ------------------------------ ------------------------------ 
AAAA----------------------AAAA ----A--------------------A---- ----A--------------------A---- ----A--------------------A---- ----AAA----------------AAA---- ----AAB----------------BAA---- -----AB----------------BA----- -----ABB--------------BBA----- ------BBB------------BBB------ ------BBA------------ABB------ -------BA------------AB------- -------BA------------AB------- --------AA----------AA-------- --------AAB--------BAA-------- ---------AB--------BA--------- ---------AB--------BA--------- ---------AB--------BA--------- ----------BBB----BBB---------- ----------BBB----BBB---------- -----------BBBBBBBB----------- -----------BBBBBBBB----------- ------------------------------ ------------------------------ ------------------------------ ------------------------------ ------------------------------ ------------------------------ 
AAAA----------------------AAAA ----A--------------------A---- ----A--------------------A---- ----A--------------------A---- ----AA------------------AA---- ----AA------------------AA---- -----A------------------A----- -----AB----------------BA----- ------BB--------------BB------ ------BB--------------BB------ -------B--------------B------- -------B--------------B------- --------A------------A-------- --------AA----------AA-------- ---------A----------A--------- ---------A----------A--------- ---------A----------A--------- ----------BB------BB---------- ----------BB------BB---------- -----------BA----AB----------- -----------BA----AB----------- ------------AAAAAA------------ ------------AAAAAA------------ ------------------------------ ------------------------------ ------------------------------ ------------------------------ 
AAAA----------------------AAAA ----A--------------------A---- ----A--------------------A---- ----A--------------------A---- ----AA------------------AA---- ----AA------------------AA---- -----A------------------A----- -----AB----------------BA----- ------BB--------------BB------ ------BB--------------BB------ -------B--------------B------- -------B--------------B------- --------A------------A-------- --------AA----------AA-------- ---------A----------A--------- ---------A----------A--------- ---------A----------A--------- ----------B--------B---------- ----------B--------B---------- -----------B------B----------- -----------B------B----------- ------------A----A------------ ------------AAAAAA------------ -------------AAAA------------- -------------AAAA------------- ------------------------------ ------------------------------ 
AAAA----------------------AAAA ----A--------------------A---- ----A--------------------A---- ----A--------------------A---- ----AA------------------AA---- ----AA------------------AA---- -----A------------------A----- -----AB----------------BA----- ------BB--------------BB------ ------BB--------------BB------ -------B--------------B------- -------B--------------B------- --------A------------A-------- --------AA----------AA-------- ---------A----------A--------- ---------A----------A--------- ---------A----------A--------- ----------B--------B---------- ----------B--------B---------- -----------B------B----------- -----------B------B----------- ------------A----A------------ ------------AA--AA------------ -------------ABBA------------- -------------ABBA------------- --------------BB-------------- --------------BB-------------- 
AAAA----------------------AAAA ----A--------------------A---- ----A--------------------A---- ----A--------------------A---- ----AA------------------AA---- ----AA------------------AA---- -----A------------------A----- -----AB----------------BA----- ------BB--------------BB------ ------BB--------------BB------ -------B--------------B------- -------B--------------B------- --------A------------A-------- --------AA----------AA-------- ---------A----------A--------- ---------A----------A--------- ---------A----------A--------- ----------B--------B---------- ----------B--------B---------- -----------B------B----------- -----------B------B----------- ------------A----A------------ ------------AA--AA------------ -------------ABBA------------- -------------ABBA------------- --------------BB-------------- --------------BB-------------- 
AAAA----------------------AAAA ----A--------------------A---- ----A--------------------A---- ----A--------------------A---- ----AA------------------AA---- ----AA------------------AA---- -----A------------------A----- -----AB----------------BA----- ------BB--------------BB------ ------BB--------------BB------ -------B--------------B------- -------B--------------B------- --------A------------A-------- --------AA----------AA-------- ---------A----------A--------- ---------A----------A--------- ---------A----------A--------- ----------B--------B---------- ----------B--------B---------- -----------B------B----------- -----------B------B----------- ------------A----A------------ ------------AAAAAA------------ -------------AAAA------------- -------------AAAA------------- ------------------------------ ------------------------------ 
AAAA----------------------AAAA ----A--------------------A---- ----A--------------------A---- ----A--------------------A---- ----AA------------------AA---- ----AA------------------AA---- -----A------------------A----- -----AB----------------BA----- ------BB--------------BB------ ------BB--------------BB------ -------B--------------B------- -------B--------------B------- --------A------------A-------- --------AA----------AA-------- ---------A----------A--------- ---------A----------A--------- ---------A----------A--------- ----------BB------BB---------- ----------BB------BB---------- -----------BA----AB----------- -----------BA----AB----------- ------------AAAAAA------------ ------------AAAAAA------------ ------------------------------ ------------------------------ ------------------------------ ------------------------------ 
AAAA----------------------AAAA ----A--------------------A---- ----A--------------------A---- ----A--------------------A---- ----AAA----------------AAA---- ----AAB----------------BAA---- -----AB----------------BA----- -----ABB--------------BBA----- ------BBB------------BBB------ ------BBA------------ABB------ -------BA------------AB------- -------BA------------AB------- --------AA----------AA-------- --------AAB--------BAA-------- ---------AB--------BA--------- ---------AB--------BA--------- ---------AB--------BA--------- ----------BBB----BBB---------- ----------BBB----BBB---------- -----------BBBBBBBB----------- -----------BBBBBBBB----------- ------------------------------ ------------------------------ ------------------------------ ------------------------------ ------------------------------ ------------------------------ 
-AAAA--------------------AAAA- -----A------------------A----- -----A------------------A----- -----A------------------A----- -----AA----------------AA----- -----AB----------------BA----- -----AB----------------BA----- -----ABB--------------BBA----- ------BBB------------BBB------ ------BBA------------ABB------ -------BA------------AB------- -------BA------------AB------- --------AAA--------AAA-------- --------AABB------BBAA-------- ---------ABB------BBA--------- ---------ABB------BBA--------- ---------ABB------BBA--------- ----------BBBBBBBBBB---------- ----------BBBBBBBBBB---------- ------------------------------ ------------------------------ ------------------------------ ------------------------------ ------------------------------ ------------------------------ ------------------------------ ------------------------------ 
-AAAA--------------------AAAA- -----A------------------A----- -----A------------------A----- -----A------------------A----- -----AAA--------------AAA----- -----ABB--------------BBA----- ------AB--------------BA------ ------ABB------------BBA------ ------BBBB----------BBBB------ ------BBAA----------AABB------ -------BAA----------AAB------- -------BAA----------AAB------- --------AAAA------AAAA-------- --------AAAAAAAAAAAAAA-------- ---------AAAAAAAAAAAA--------- ---------AAAAAAAAAAAA--------- ---------AAAAAAAAAAAA--------- ------------------------------ ------------------------------ ------------------------------ ------------------------------ ------------------------------ ------------------------------ ------------------------------ ------------------------------ ------------------------------ ------------------------------ 
-AAAAA------------------AAAAA- ------A----------------A------ ------A----------------A------ ------A----------------A------ ------AA--------------AA------ ------AA--------------AA------ -------A--------------A------- -------ABB----------BBA------- -------BBBBB------BBBBB------- -------BBAAA------AAABB------- --------BAAA------AAAB-------- --------BAAA------AAAB-------- ---------AAAAAAAAAAAA--------- ---------AAAAAAAAAAAA--------- ------------------------------ ------------------------------ ------------------------------ ------------------------------ ------------------------------ ------------------------------ ------------------------------ ------------------------------ ------------------------------ ------------------------------ ------------------------------ ------------------------------ ------------------------------ 
--AAAAA----------------AAAAA-- -------A--------------A------- -------A--------------A------- -------A--------------A------- -------AAA----------AAA------- -------AAB----------BAA------- --------AB----------BA-------- --------ABBB------BBBA-------- --------BBBBBBBBBBBBBB-------- --------BBBBBBBBBBBBBB-------- ---------BBBBBBBBBBBB--------- ---------BBBBBBBBBBBB--------- ------------------------------ ------------------------------ ------------------------------ ------------------------------ ------------------------------ ------------------------------ ------------------------------ ------------------------------ ------------------------------ ------------------------------ ------------------------------ ------------------------------ ------------------------------ ------------------------------ ------------------------------ 
--AAAAAA--------------AAAAAA-- --------A------------A-------- --------A------------A-------- --------A------------A-------- --------AAAA------AAAA-------- --------ABBB------BBBA-------- ---------ABB------BBA--------- ---------ABBBBBBBBBBA--------- ---------BBBBBBBBBBBB--------- ---------BBBBBBBBBBBB--------- ------------------------------ ------------------------------ ------------------------------ ------------------------------ ------------------------------ ------------------------------ ------------------------------ ------------------------------ ------------------------------ ------------------------------ ------------------------------ ------------------------------ ------------------------------ ------------------------------ ------------------------------ ------------------------------ ------------------------------ 
---AAAAAA------------AAAAAA--- ---------AA--------AA--------- ---------AA--------AA--------- ---------AA--------AA--------- ---------AAAAAAAAAAAA--------- ---------AAAAAAAAAAAA--------- ---------AAAAAAAAAAAA--------- ---------AAAAAAAAAAAA--------- ------------------------------ ------------------------------ ------------------------------ ------------------------------ ------------------------------ ------------------------------ ------------------------------ ------------------------------ ------------------------------ ------------------------------ ------------------------------ ------------------------------ ------------------------------ ------------------------------ ------------------------------ ------------------------------ ------------------------------ ------------------------------ ------------------------------ 
----AAAAAAA--------AAAAAAA---- -----------AAAAAAAA----------- -----------AAAAAAAA----------- -----------AAAAAAAA----------- -----------AAAAAAAA----------- -----------AAAAAAAA----------- ------------------------------ ------------------------------ ------------------------------ ------------------------------ ------------------------------ ------------------------------ ------------------------------ ------------------------------ ------------------------------ ------------------------------ ------------------------------ ------------------------------ ------------------------------ ------------------------------ ------------------------------ ------------------------------ ------------------------------ ------------------------------ ------------------------------ ------------------------------ ------------------------------ 
-----AAAAAAAAAAAAAAAAAAAA----- ------------------------------ ------------------------------ ------------------------------ ------------------------------ ------------------------------ ------------------------------ ------------------------------ ------------------------------ ------------------------------ ------------------------------ ------------------------------ ------------------------------ ------------------------------ ------------------------------ ------------------------------ ------------------------------ ------------------------------ ------------------------------ ------------------------------ ------------------------------ ------------------------------ ------------------------------ ------------------------------ ------------------------------ ------------------------------ ------------------------------ 
------AAAAAAAAAAAAAAAAAA------ ------------------------------ ------------------------------ ------------------------------ ------------------------------ ------------------------------ ------------------------------ ------------------------------ ------------------------------ ------------------------------ ------------------------------ ------------------------------ ------------------------------ ------------------------------ ------------------------------ ------------------------------ ------------------------------ ------------------------------ ------------------------------ ------------------------------ ------------------------------ ------------------------------ ------------------------------ ------------------------------ ------------------------------ ------------------------------ ------------------------------ 
--------AAAAAAAAAAAAAA-------- ------------------------------ ------------------------------ ------------------------------ ------------------------------ ------------------------------ ------------------------------ ------------------------------ ------------------------------ ------------------------------ ------------------------------ ------------------------------ ------------------------------ ------------------------------ ------------------------------ ------------------------------ ------------------------------ ------------------------------ ------------------------------ ------------------------------ ------------------------------ ------------------------------ ------------------------------ ------------------------------ ------------------------------ ------------------------------ ------------------------------ 
-----------AAAAAAAA----------- ------------------------------ ------------------------------ ------------------------------ ------------------------------ ------------------------------ ------------------------------ ------------------------------ ------------------------------ ------------------------------ ------------------------------ ------------------------------ ------------------------------ ------------------------------ ------------------------------ ------------------------------ ------------------------------ ------------------------------ ------------------------------ ------------------------------ ------------------------------ ------------------------------ ------------------------------ ------------------------------ ------------------------------ ------------------------------ ------------------------------ 
