model
size = 32 32 16, scale = 0.05, origin = -y
material 
  colors = A:#005 B:#004 C:#111 D:#FF0 E:#00B F:#00E G:#008 H:#FF9 I:#CC0 J:#CF6 K:#FF3 L:#00D
voxels
975-2I30-2I276-B2A16-ABA9-2(AB)A14-3ABA9-ABA16-B2A10-2B18-2B11-B18-B12-B348-3A20-3A9-2A16-2A2(14-A)17-A12-A19-G10-G20-J10-J14-2CA-4CG2C2D2CG4C-A2C9-CA-4CG2C2I2CG4C-AC105-3(6A12-6A8-)2A3BA12-ABA2BA8-B4AB12-B4AB8-5AB12-B5A3(8-6A12-6A)8-6A12-B5A8-6A12-2(B2A)8-3AB2AB10-2B5A8-5A5B4-5B5A8-3AB2A-3B4-3B-BAB3A8-6A12-B5A8-7AB-B4-B-2B6A8-4AB3A3B2-4B7A8-6AB2A-4B-B8A8-7ABA-4B-2ABA4BA8-AB8A2B7AB4A8-2A2B6ABAB4A2B5A6-EG2B2A2B4AB2AB4AB3A2BGE6-2A2B2AB3AB2AB6A3BA8-4ABAB3AB2AB5AB2ABA8-5A2(B4AB2A)GBA8-6AJ3AB2AB3AJ5BA8-10AB13A8-CABC4AB2A2J2AB4ACBAC8-CABC4AB2A2I2AB4ACBAC71-5(7A12-7A6-)2(7A12-6AB6-)4(7A12-7A6-)7AB10-B2(7A6-7A2B8-2B)7A6-7A4B4-4B7A6-7A2-2B4-2B2-7A6-9A8B9A6-10A6B2(10A6-10A-4B-)10A6-B25A6-26A4-EAB24ABAE4-5(26A6-)C24AC6-C24AC70-8A10-8A3(6-8A10-7AB)6-8A10-8A6-8A2(10-7AB5-9A)2(10-8A5-8AB)10-9A4-8AB10-9A4-8A2B8-B9A4-9AB8-B9A4-8A2B8-B9A4-8ABGB6-BG9A4-9A3B4-3B9A4-10AB6-11A4-11A2B2-2B11A4-12AB2-B12A3(4-28A)2-E30AE2-4(28A4-)28A3-AC26ACA2-AC26ACA4-8B10-8B6-8A10-5A2BA2(6-9A8-8AB)6-8AB8-8AB6-9A4(8-9A6-8AB)8-10A5-8AB8-10A5-9A8-9AB4-10A8-9AB3-2(11A8-11A2-)10AB8-11A2(2-10AB8-10AB)2(2-11A8-11A)2(2-11A-6A-11A)2(2-30A)-D11A8-11AD-12A6-12A3(2-30A)2-29AB2-C10A-6A-10AC2-C28AC4-8B10-8B6-8A10-8A5-B9A2(8-10A4-10A8-10A4-9AB)2(8-10A4-9AB)8-10A4-10A2(8-10A4-B9A)8-9AB4-10A8-9AB3-3(B10A8-11A2-)2(B10A8-10AB2-)B10A8-11A2-12AB4-B12A2-30A2-11A-6A-11A2(2-30A)2(2-11A8-11A)2(2-30A)2(2-29AB)2-C10A8-10AC2-C28AC4-3B-4B10-4B-3B6-3A-4A10-4A-2AB5-4(4A-4AB8-5A-3AB4-)3(4A-4AB8-5A-4A4-)2(4A-5A8-5A-3AB4-)B3A-4AB8-5A-3AB4-4A-4AB8-5A-3AB3-5A-4AB8-5A-5A2-B4A-4AB3(8-5A-4AB2-5A-5A)8-5A-4AB2(2-5A-18A-5A)2-B4A-18A-5A2-5A2(-18A-5A2-B4A)-18A-5A2-5A-5A8-5A-5A2-5A-7A4-7A-5A2-B4A2(-18A-5A2-5A)2(-18A-4AB2-5A)-5A8-5A-5A2-AC26ACA4-8B10-8B6-8A10-7AB5-2(B8AB8-9AB4-)2(9AB8-9AB4-)5AB3AB8-4A2B3AB4-6AB2AB8-3A3B4A4-4A3B2AB8-3A3B3AB4-10A8-9AB4-B9A8-10A4-B8AB8-9AB4-9AB8-9AB3-10AB8-11A2-10AB2(8-10AB2-11A)8-11A2-11A8-B10A2(2-30A)2(2-29AB)2(2-30A)2-12A6-12A2-B11A6-12A2-30A2(2-B29A)2-B28AB2(2-C28AC)4-8B10-8B6-8A10-8A5-4(10A8-10A4-)B3AB2-3A8-3A2-B4A4-4AB2-3A8-3A2-2B3A4-B2A2B2-3A8-3A2-2B2AB4-4AB5A8-5AB3AB2(4-B9A8-10A)4-10A8-10A3-2(11A8-11A2-)11A8-B10A2-11A8-11A2-11A8-B10A2-B29A4(2-30A)2-B29A2(2-30A)2(2-29AB)2(2-30A)2(2-C28AC)68-4(8A10-8A6-)2(2A4-2A10-2A4-2A6-)2A4-2A10-2A4-2A5-4A2B3A10-3A2B3A5-4A2B3A10-3A2B4A4-6AB2A10-2(2AB)3A2(4-B8A10-9A)4-B8A10-B8A4-B8A10-9A4-B7AB9-A2B7A4-B7AB9-AB8A4-B8A8-11A4-9A10-9A3-10A2-6A2-10A2-A2B27A2(2-30A)2(2-29AB)2-B29A3(2-30A)3-C26AC4-C26AC69-3A2B2A12-A2(B2A)7-2A2B2A12-4ABA7-7A12-4AB7(2A6-2A4-A12-A4-)2A6-7A12-4AB2A6-6AB12-B6A6-7A12-7A6-6AB12-B6A6-7A11-AB6A6-7AB10-B7A6-7A12-7A6-26A5-B27A5-B25A5-B27A4-B27A3-2(30A2-)30A4-26A4-30A2-30A3-GC24ACG4-GC24ACG358-2(A22-A8-)4AB2(14-B4A8-5A)14-5A8-5A14-5A3(8-24A)7-26A6-26A5-B27A2(4-28A)4-B27A4-28A5-26A4-30A3-28A6-C22AC8-C22AC425-2BA16-B2A10-2BA16-3A10-2B2A14-2ABA10-4A14-2ABA10-5A4-6A2-3ABA10-7AB2A5B7A10-8ABA3B9A9-9AB2A2B10A7-10AB15A6-11A3B12A6-11A2B13A6-12A2B12A6-B25A5-28A5-26A5-28A4-28A7-C20AC10-C20AC618-2BF2EB2A6-2AB2EF2B9-BEF3AFBA6-ABFDADFEB7-BL-4DHD2B4-ABFH5DLA6-BFAH2ABDAEB4-AEADB2AHAFA6-BEA-H3DAFBA2-ABF2A2DHDAEA6-BEADBABDAEBA2-ABEADBABDAEA6-BF-H3DHDEB4ABEAH3DHDFA6-BF2ADAH2AFB4ABF2AHAD2AFA6-AD2EFE2FEK5ABKE2FEF2EDA7-24A8-11A2-11A9-G3CA4CG2CG4CA3CG10-G20CG620-F2E12-2EF12-EF3-F10-FD-DFE9-E-4DHD8-FH5DF8-F-H3-D-E6-F-D3-H-F8-E2-H3D-F6-F2-2DHD-E8-E-D3-D-E6-E-D3-D-E8-F-H3DHDE6-E-H3DHDF8-F2-D-H2-E6-F2-H-D2-F8-D2EFE2FED6-DE2FEF2ED75-2(2CG4CG)2C14-2(2CG4CG)2C7-
