model
size = 32 27 31, scale = 0.05, origin = -y
material 
  colors = A:#444 B:#888 C:#DDD
voxels
10-3(11A21-)11A755-15A2(17-3A9-3A)17-15A751-19A4(13-3A)13-19A748-21A2(11-2A3-11A3-2A)11-21A16-4(11A21-)11B21-11C17(21-11A)15-23A9-2A2-15A2-2A9-2A2-3A9-3A2-2A9-23A13-4(3A9-3A17-)2BA9-A2B17-2CA9-A2C16(17-3A9-3A)17-15A12-25A7-2A2-17A2-2A7-2A2-2A13-2A2-2A7-25A11-4(2A13-2A15-)BA13-AB15-CA13-AC16(15-2A13-2A)15-17A10-27A5-2A2-19A2-2A5-2A2-2A15-2A2-2A5-27A9-4(2A15-2A13-)BA15-AB13-CA15-AC16(13-2A15-2A)13-19A9-27A5-A2-21A2-A5-A2-2A17-2A2-A5-27A8-4(2A17-2A11-)BA17-AB11-CA17-AC16(11-2A17-2A)11-21A7-29A3-2A-23A-2A3-2A-2A19-2A-2A3-29A6-4(2A19-2A9-)BA19-AB9-CA19-AC16(9-2A19-2A)9-23A6-29A3-A2-23A2-A3-A2-A21-A2-A3-29A6-4(A21-A9-)B21-B9-C21-C16(9-A21-A)9-23A5-31A-2A-25A3(-2A)21-2(2A-)31A4-4(2A21-2A7-)BA21-AB7-CA21-AC16(7-2A21-2A)4(7-25A4-31A-A2-25A2-A-A2-A23-A2-A-31A4-4(A23-A7-)B23-B7-C23-C16(7-A23-A))7-25A4-33A2-25A2-3A2-A23-A2-34A3-4(4(A23-A7-)B23-B7-C23-C16(7-A23-A)7-25A4-31A-A2-25A2-A-A2-A23-A2-A-31A4-)4(A23-A7-)B23-B7-C23-C16(7-A23-A)7-25A4-31A-2A-25A3(-2A)21-2(2A-)31A4-4(2A21-2A7-)BA21-AB7-CA21-AC16(7-2A21-2A)7-25A5-29A3-A2-23A2-A3-A2-A21-A2-A3-29A6-4(A21-A9-)B21-B9-C21-C16(9-A21-A)9-23A6-29A3-2A-23A-2A3-2A-2A19-2A-2A3-29A6-4(2A19-2A9-)BA19-AB9-CA19-AC16(9-2A19-2A)9-23A7-27A5-A2-21A2-A5-A2-2A17-2A2-A5-27A8-4(2A17-2A11-)BA17-AB11-CA17-AC16(11-2A17-2A)11-21A8-27A5-2A2-19A2-2A5-2A2-2A15-2A2-2A5-27A9-4(2A15-2A13-)BA15-AB13-CA15-AC16(13-2A15-2A)13-19A10-25A7-2A2-17A2-2A7-2A2-2A13-2A2-2A7-25A11-4(2A13-2A15-)BA13-AB15-CA13-AC16(15-2A13-2A)15-17A12-23A9-2A2-15A2-2A9-2A2-3A9-3A2-2A9-23A13-4(3A9-3A17-)2BA9-A2B17-2CA9-A2C16(17-3A9-3A)17-15A14-21A2(11-2A3-11A3-2A)11-21A16-4(11A21-)11B21-11C17(21-11A)17-19A4(13-3A)13-19A751-15A2(17-3A9-3A)17-15A755-3(11A21-)11A747-
