model
size = 30 19 12, scale = 0.05, origin = -y
material 
  colors = A:#BBB B:#E83015 C:#FFF D:#FFFFFB E:#AAA F:#888 G:#444 H:#DDD I:#EEE
voxels
----DHHHHHHDDDDDDDDDDHHHHDD--- ----DHHHHHHDDDDDDDDDDDHHDDD--- ----DDHHHHDD---------DDDD----- -----DDDDDD-----------DD------ ------DDDD-------------------- -------DD--------------------- ------------------------------ ------------------------------ ------------------------------ ------------------------------ ------------------------------ ---------I-------------------- ---------G-------------------- ---------G-------------------- ------------------------------ ------------------------------ ------------------------------ ------------------------------ ------------------------------ 
---DAAAAAAEEAEEAEEAAAAAAAAAD-- ---DAAAAAAAAACCCCCCCCCCCCAAD-- ----BBBBBBBBBBBBBBBBBBBBBBB--- ----BBBBBBBFFFFFFFFFBBBBBBB--- ----FFBBBBFFFFHHHHHFFBBBBB---- ----AFFBBFFAFFFHHHHHFFBB------ ----AAFFFFAAAF-HHHHH---------- -----AAAAAAAA---HHH----------- ------AAAAAA------------------ -------AAAAA------------------ ---------AA------------------- ------------------------------ ------------------------------ ---------G-------------------- ---------G-------------------- ------------------------------ ------------------------------ ------------------------------ ------------------------------ 
-DDAAEEAAEEEEEEEEEEAAEEEEEAAD- -DDAACCCCCCCCCCCCCCCCCCCCCCAD- --BBAAAAAAAAAAAAAAAAAAAAAAAB-- --BBA----------------------B-- --FFA---------------------FF-- --ABA-------------------FFF--- --ABA---------F-----FFFFFF---- --ABBAAAAA-AAAAA---AAG-------- --ABBBAAAAAAAAAAAAGA---------- --ABBBBAAAAAAAAGAA------------ --AABBBBBAAAAAA--------------- --AABBBBBBAAAG---------------- --AAABBBBAAA------------------ --AAABBAAAAA------------------ ---AAAA-AAAG------------------ ----AA--AAA------------------- ------------------------------ ------------------------------ ------------------------------ 
DAAAEAAEAAAAAAAAAAAAEAAAAAEAAD D-ACCCCCCCCCCCCCCCCCCCCCCCCCAD -BAAAAAAAAAAAAAAAAAAAAAAAAAAB- -BA-------------------------B- -FA-------------------------F- -BA------------------------AA- -BA---------------------AAAA-- -BA------------------GGG------ -BA---------------BGG--------- -BA-------------BGG----------- -BA-----------BGG------------- -BA----------BG--------------- -BA--------BGG---------------- --A-------BAG----------------- ----------BAG----------------- ----------BB------------------ ----------BB------------------ ----------B------------------- ------------------------------ 
DAAEAEEAEEEEEEEEEEEEAAEAEAAEAD DCCCCCCCCCCCCCCCCCCCCCCCCCCCCD BAAAAAABAABABABBBABBBABABABAAB B----------------------------B FA---------------------------F FA--------------------------AA AA-----------------------AAAA- AA--------------------AAG----- GA------------------AG-------- AA----------------AG---------- -B--------------AG------------ -B-----------AAG-------------- -B----------AG---------------- -B----------A----------------- -G--------BAG----------------- ----------BB------------------ ----------BB------------------ ----------B------------------- ----------B------------------- 
DAEAEEEEAAAAAEEAAAAAAEEEEEAEAD DCCCCCCCCCCCCCCCCCCCCCCCCCCCCD DAAABBABABBABAAABAAABABABBBAAB B----------------------------B B----------------------------F F----------------------------A A------------------------AAAA- A---------------------AAG----- G-------------------AG-------- A-----------------AG---------- G---------------AG------------ A------------AAA-------------- -B----------AG---------------- -B----------A----------------- -G--------BAG----------------- -G--------BB------------------ ----------BB------------------ ----------B------------------- ----------B------------------- 
DAEAEEEEAAAAAEEAAAAAAEEEEEAEAD DCCCCCCCCCCCCCCCCCCCCCCCCCCCCD DAAABBABBABAAABBAABBAABABABAAB B----------------------------B B----------------------------F F----------------------------A A------------------------AAAA- A---------------------AAG----- G-------------------AG-------- A-----------------AG---------- G---------------AG------------ A------------AAA-------------- -B----------AG---------------- -B----------A----------------- -G--------BAG----------------- -G--------BB------------------ ----------BB------------------ ----------B------------------- ----------B------------------- 
DAAEAEEAEEEEEEEEEEEEAAEAEAAEAD DCCCCCCCCCCCCCCCCCCCCCCCCCCCCD BAAAAAABAABABABBBABBBABABBBAAB B----------------------------B FA---------------------------F FB--------------------------AA AB-----------------------AAAA- AB--------------------AAG----- GB------------------AG-------- AB----------------AG---------- -B--------------AG------------ -B-----------AAG-------------- -B----------AG---------------- -B----------A----------------- -G--------BAG----------------- ----------BB------------------ ----------BB------------------ ----------B------------------- ----------B------------------- 
DAAAEAAEAAAAAAAAAAAAEAAAAAEAAD D-ACCCCCCCCCCCCCCCCCCCCCCCCCAD -BAAAAAAAAAAAAAAAAAAAAAAAAAAB- -BA-------------------------B- -FA-------------------------F- -BA------------------------AA- -BA---------------------AAAA-- -BA------------------GGG------ -BA---------------BGG--------- -BA-------------BGG----------- -BA-----------BGG------------- -BA----------BG--------------- -BA--------BGG---------------- --A-------BAG----------------- ----------BAG----------------- ----------BB------------------ ----------BB------------------ ----------B------------------- ------------------------------ 
-DDAAEEAAEEEEEEEEEEAAEEEEEAAD- -DDAACCCCCCCCCCCCCCCCCCCCCCAD- --BBAAAAAAAAAAAAAAAAAAAAAAAB-- --BBA----------------------B-- --FFA--------------------FFF-- --ABA-------------------FFF--- --ABA---------F-----FFFFFF---- --ABBAAAAA-AAAAA---AAG-------- --ABBBAAAAAAAAAAAAGA---------- --ABBBBAAAAAAAAGAA------------ --AABBBBBAAAAAA--------------- --AABBBBBBAAAG---------------- --AAABBBBAAA------------------ --AAABBAAAAA------------------ ---AAAA-AAAG------------------ ----AA--AAA------------------- ------------------------------ ------------------------------ ------------------------------ 
---DAAAAAAEEAEEAEEAAAAAAAAAD-- ---DAAAAAAAAACCCCCCCCCCCCAAD-- ----BBBBBBBBBBBBBBBBBBBBBBB--- ----BBBBBBBFFFFFFFFBBBBBBBB--- ----FFBBBBFFFFHHHHHFFBBBB----- ----AFFBBFFAFFFHHHHHFFBB------ ----AAFFFFAAAF-HHHHH---------- -----AAAAAAAA---HHH----------- ------AAAAAA------------------ -------AAAAA------------------ ---------AA------------------- ------------------------------ ------------------------------ ---------G-------------------- ---------G-------------------- ------------------------------ ------------------------------ ------------------------------ ------------------------------ 
----DHHHHHHDDDDDDDDDDHHHHDD--- ----DHHHHHHDDDDDDDDDDDHHDDD--- ----DDHHHHDD---------DDDD----- -----DDDDDD-----------DD------ ------DDDD-------------------- -------DD--------------------- ------------------------------ ------------------------------ ------------------------------ ------------------------------ ------------------------------ ---------I-------------------- ---------G-------------------- ---------G-------------------- ------------------------------ ------------------------------ ------------------------------ ------------------------------ ------------------------------ 
