model
size = 21 31 31, scale = 0.05, origin = -y
material 
  colors = A:#60C B:#3C6 C:#0F9 D:#200 E:#E00
voxels
--------------------- ----------A---------- --------AAAAA-------- -------AAAAAAA------- -------AAAAAAA------- -------ABAAABA------- -------ABBABBA------- -------ABAAABA------- ------AAAAAAAAA------ ------AABBBBBAA------ ------AAABBBAAA------ ------AAAAAAAAA------ ------AAAAAAAAA------ -------AAAAAAA------- -------AAAAAAA------- -------AAAAAAA------- -------ACCCCCA------- -------CACACAC------- -------CCAAACC------- --------AAAAA-------- --------------------- --------------------- --------------------- --------------------- --------------------- --------------------- --------------------- --------------------- --------------------- --------------------- --------------------- 
-------AAAAAAA------- -------AAA-AAA------- -------AAAAAAA------- ------A-AA-AA-A------ ------A-AAAAA-A------ ------A-AAAAA-A------ ------A-AAAAA-A------ -----AAAAAAAAAAA----- -----A-AAAAAAA-A----- -----AAAAAAAAA-A----- ----AAAAAA-AAAAAA---- ----AAAAA---AAAAA---- ----AAAAAA-AAAAAA---- ----AAAAAA-AAAAAA---- -----AAAAAAAAAAA----- -----AAAAAAAAAAA----- -----ACAAAAAA-CA----- -----ACAAAAAAACA----- -----AC-AAAAA-CA----- -----AAA-AAA-AAA----- ------AAAAAAAAA------ --------AAAAA-------- --------------------- --------------------- --------------------- --------------------- --------------------- --------------------- --------------------- --------------------- --------------------- 
------AAAAAAAAA------ ------A-AAAAA-A------ ------AA-----AA------ ------AA-----AA------ -----A-A-----A-A----- -----A-A-----A-A----- -----A-A-----A-A----- -----AA-------AA----- ----A-A-------A-A---- ----AA--------A-A---- ----AA---------AA---- ---A-A---------A-A--- ---A-A---------A-A--- ---A-AA-------AA-A--- ---AAAA-------AAAA--- ---AAAA-------AAAA--- ----AAA------AAAA---- ---AAAA-------A-AA--- ---AA-AA-----AA-AA--- ----A-AAA---AAA-A---- ----AA--AAAAA--AA---- -----AAA-AAA-AAA----- ------AAAAAAAAA------ --------AAAAA-------- --------------------- --------------------- --------------------- --------------------- --------------------- --------------------- --------------------- 
------AAA---AAA------ -----A-A-----A-A----- -----A-A-----A-A----- -----A-A-----A-A----- -----AA-------AA----- -----AA-------AA----- ----A-A-------A-A---- ----A-A-------A-A---- ----AA---------AA---- ---A-A---------A-A--- ---A-A---------A-A--- ---AA-----------AA--- --A-A-----------AA--- --A-A-----------A-A-- --A-A-----------A-A-- --A-A-----------A-A-- --AAA-----------AAA-- --AAA----------AA-A-- --A-AA---------AA-A-- --AA-A---------A-AA-- ---A--AA-----AA--A--- ---AA--AA---AA--A---- ----AA--AAAA---AA---- -----AAA--A--AAA----- -------AAAAAAA------- ---------AAA--------- --------------------- --------------------- --------------------- --------------------- --------------------- 
-----AA-------AA----- -----AA-------AA----- -----AA-------AA----- ----A-A-------AA----- -----AA-------AA----- -----A---------A----- ----AA---------AA---- ----AA---------AA---- ----AA---------AA---- ---AA-----------AA--- ---AA-----------AA--- --A-A-----------A-A-- --AA-------------AA-- --AA-------------AA-- --AA-------------AA-- --AA-------------AA-- --AA-------------AA-- --AA-------------AA-- --AA-------------AA-- --A-A-----------A-A-- --A-AA---------AA-A-- --A--AA-------AA-AA-- ---A--AA----AA---A--- ----A---AA-AA---A---- -----AA---A---AA----- ------AAA---AAA------ ---------AAA--------- --------------------- --------------------- --------------------- --------------------- 
-----AA-------AA----- -----AA-------AA----- ----AA---------AA---- ----AA---------AA---- ----A-A-------A-A---- ----AA---------AA---- ----AA---------AA---- ----AA---------AA---- ----AA---------AA---- ---AA-----------AA--- --A-A-----------A-A-- --AA-------------AA-- --AA-------------AA-- -A-A-------------AAA- -AA---------------AA- -AA---------------AA- --A---------------A-- --AA-------------AA-- -A-A-------------AAA- -A-A-------------A-A- --AA-------------AA-- --A-A-----------A-A-- --A--A--------AAA-A-- ---A--AA-----AA--A--- ----A---AA-AA---A---- -----A---AA----A----- ------AAA---AAA------ --------AAAAA-------- --------------------- --------------------- --------------------- 
--------------------- ----AA---------AA---- ----AA---------AA---- ----AA---------AA---- ----AA---------AA---- ----AA---------AA---- ----AA---------AA---- ----AA---------AA---- ----AA---------AA---- ---AA-----------AA--- --A-A-----------A-A-- --AA-------------AA-- --AA-------------AA-- -AA---------------AA- -AA---------------AA- -AA---------------AA- -AA---------------AA- -AA---------------AA- -AA---------------AA- -AA---------------AA- -AA---------------AA- -A-A-------------A-A- -A-AA------------A-A- --A-AA---------AA-A-- --AA--AA-----AA--AA-- ----A---A--AA---A---- -----A---AA----A----- ------AAAA--AAA------ ---------AAA--------- --------------------- --------------------- 
--------------------- ----AA---------AA---- ----AA---------AA---- ---A-A---------A-A--- ---A-A---------A-A--- ---A-A---------A-A--- ---A-A---------AA---- ---A-A---------A-A--- ---AA-----------AA--- ---AA-----------AA--- --A-A-----------A-A-- --AA-------------AA-- -A-A-------------A-A- -AA---------------AA- -AA---------------AA- -AA---------------AA- -AA---------------AA- -AA---------------AA- -AA---------------AA- -AA---------------AA- -AA---------------AA- -AA---------------AA- -AA---------------AA- -A-A-------------A-A- -A--AA---------AA--A- --AA--AA-----AA--AA-- ----A---AA-AA---A---- ----AAA---A---AAA---- -------AAAAAAA------- --------------------- --------------------- 
--------------------- ----A-----------A---- ---AA-----------AA--- ---AA-----------AA--- ---AA-----------AA--- ---AA-----------AA--- ---AA-----------AA--- ---AA-----------AA--- ---AA-----------AA--- ---AA-----------AA--- --AA-------------AA-- --AA-------------AA-- -AA---------------AA- -AA---------------AA- -AA---------------AA- -A----------------AA- -AA---------------AA- -AA---------------AA- -AA---------------AA- -AA---------------AA- -AA---------------AA- -AA---------------AA- -AA---------------AA- -AA---------------AA- -A-A-------------A-A- -A--AAA-------AAA--A- --AA---A-----A---AA-- ---AA---AAAAA---AA--- -----AAA-----AAA----- --------AAAAA-------- --------------------- 
--------------------- --------------------- ---AA-----------AA--- ---AA-----------AA--- ---AA-----------AA--- ---A-------------A--- --AA-------------A--- --AA-------------AA-- --AA-------------AA-- --AA-------------AA-- --AA-------------AA-- -AA--------------A-A- -AA---------------AA- -AA---------------AA- -AA---------------AA- -A-----------------A- -A-----------------A- -A-----------------A- -AA---------------AA- -AA---------------AA- -AA---------------AA- -AA---------------AA- -AA---------------AA- -AA---------------AA- -AA---------------AA- -A-AA-----------AA-A- -A---AA-------AA---A- --AA---AA---AA---AA-- ----AA---AAA---AA---- ------AAAAAAAAA------ --------------------- 
--------------------- --------------------- ---AA-----------AA--- ---AA-----------AA--- ---A-------------A--- --AA-------------AA-- --AA-------------AA-- --AA-------------AA-- --AA-------------AA-- --AA-------------AA-- -A-A-------------A-A- -AA---------------AA- -AA---------------AA- -AA---------------AA- -AA---------------AA- BA-----------------AB AA-----------------AA BA-----------------AB BA-----------------AB -A-----------------A- -A-----------------A- -AA---------------AA- -AA---------------AA- -AA---------------AA- -AA---------------AA- -AA---------------AA- -A-AA-----------AA-A- --A--AAA-----AAA--A-- ---AA---AAAAA---AA--- -----AAAAAAAAAAA----- --------------------- 
--------------------- --------------------- ---A-------------A--- --AA-------------AA-- --AA-------------AA-- --AA-------------AA-- --AA-------------AA-- --AA-------------AA-- --AA-------------AA-- -AA---------------AA- -AA---------------AA- -AA---------------AA- -AA---------------AA- -AA---------------AA- -AA---------------AA- AA-----------------AA BA-----------------AB AA-----------------AA AA-----------------AA BA-----------------AB -A-----------------A- -A-----------------A- -A-----------------A- -AA---------------AA- -AA---------------AA- -AA---------------AA- -A-A-------------A-A- -A--AAA-------AAA--A- --A----AA---AA---AA-- ---AAAAA-AAA-AAAA---- --------ABBBA-------- 
--------------------- --------------------- ---A-------------A--- --AA-------------AA-- --AA-------------AA-- --AA-------------AA-- --AA-------------AA-- --A---------------A-- -AA---------------AA- -AA---------------AA- -AA---------------AA- -AA---------------AA- -AA---------------AA- BA-----------------AB BA-----------------AB -A-----------------A- BA-----------------AB AA-----------------AA AA-----------------AA BA-----------------AB BA-----------------AB -A-----------------A- -A-----------------A- -A-----------------A- -AA---------------AA- -AA---------------AA- -AA---------------AA- -A-AA-----------AA-A- --A--AAA-----AAA--A-- ---AAA--AAAAA--AAA--- ------ABBBBBBBA------ 
--------------------- --------------------- --------------------- --AA-------------AA-- --AA-------------AA-- --AA-------------AA-- -AA---------------AA- -AA---------------AA- -AA---------------AA- -AA---------------AA- -AA---------------AA- -AA---------------AA- -A-----------------A- BA-----------------AB AA-----------------AA BA-----------------AB BA-----------------AB BA-----------------AB BA-----------------AB BA-----------------AB BA-----------------AB AA-----------------AA -A-----------------A- -A-----------------A- -A----------------AA- -AA---------------AA- -AA---------------AA- -A-A-------------A-A- --A-AAA-------AAA-A-- --AAA--AAAAAAA--AAA-- -----ABABBBBBABA----- 
--------------------- --------------------- --------------------- --------------------- --------------------- --A---------------A-- -AA---------------AA- -AA---------------AA- -AA---------------AA- -AA---------------AA- -AA---------------AA- -A-----------------A- BA-----------------AB BA-----------------AB AA-----------------AA BA-----------------AB BA-----------------AB BA-----------------AB BA-----------------AB BA-----------------AB BA-----------------AB AA-----------------AA BA-----------------AB -A-----------------A- -A-----------------A- -AA---------------AA- -AA---------------AA- -A-A-------------A-A- --A-AA---------AA-A-- --AA--AAA---AAA--AA-- ----AAABAAAAABAAA---- 
--------------------- --------------------- --------------------- --------------------- --------------------- --A---------------A-- --A---------------A-- -AA---------------AA- -AA---------------AA- -AA---------------AA- -A-----------------A- -A-----------------A- AA-----------------AA BA-----------------AB AA-----------------AA AA-----------------AA AA-----------------AA AA-----------------AA AA-----------------AA AA-----------------AA AA-----------------AA AA-----------------AA BA-----------------AB AA-----------------AA -A-----------------A- -AA---------------AA- -AA---------------AA- -A-A-------------A-A- --A-AA---------AA-A-- --AA--AAA---AAA--AA-- ----ABABAAAAABABA---- 
--------------------- --------------------- --------------------- --------------------- --------------------- --------------------- --A---------------A-- -AA---------------AA- -AA---------------AA- -AA---------------AA- -A-----------------A- -A-----------------A- BA-----------------AB AA-----------------AA BA-----------------AB BA-----------------AB BA-----------------AB AA-----------------AA AA-----------------AA BA-----------------AB BA-----------------AB BA-----------------AB AA-----------------AA BA-----------------AB -A-----------------A- -AA---------------AA- -AA---------------AA- -A-A-------------A-A- --A-AA---------AA-A-- --AA--AA-----AA--AA-- ----BABAAAAAAABAB---- 
--------------------- --------------------- --------------------- --------------------- --------------------- --------------------- --A---------------A-- -AA---------------AA- -AA---------------AA- -AA---------------AA- -AA---------------AA- -A-----------------A- AA-----------------AA BA-----------------AB AA-----------------AA BA-----------------AB AA-----------------AA BA-----------------AB BA-----------------AB AA-----------------AA BA-----------------AB AA-----------------AA BA-----------------AB AA-----------------AA -A-----------------A- -AA---------------AA- -AA---------------AA- -A-A-------------A-A- --A-A-----------A-A-- ---A-AAA-----AAA-A--- ----BAABAAAAABAAB---- 
--------------------- --------------------- --------------------- --------------------- --------------------- --------------------- --------------------- -AA---------------AA- -AA---------------AA- -AA---------------AA- -AA---------------AA- -A-----------------A- BA-----------------AB AA-----------------AA BA-----------------AB BA-----------------AB AA-----------------AA AA-----------------AA AA-----------------AA AA-----------------AA BA-----------------AB BA-----------------AB AA-----------------AA BA-----------------AB -A-----------------A- -AA---------------AA- -AA---------------AA- -A-A-------------A-A- --A-A-----------A-A-- ---AAAAA-----AAAAA--- -----ABAABBBAABA----- 
--------------------- --------------------- --------------------- --------------------- --------------------- --------------------- --------------------- --A---------------A-- -AA---------------AA- -AA---------------AA- -AA---------------AA- -A-----------------A- AA-----------------AA BA-----------------AB AA-----------------AA AA-----------------AA BA-----------------AB AA-----------------AA AA-----------------AA BA-----------------AB AA-----------------AA AA-----------------AA BA-----------------AB AA-----------------AA -A-----------------A- -AA---------------AA- -AA---------------AA- -A-A-------------A-A- --A-A-----------A-A-- ---AAAAAA---AAAAAA--- -----ABBAABAABBA----- 
--------------------- --------------------- --------------------- --------------------- --------------------- --------------------- --------------------- --A---------------A-- -AA---------------AA- -AA---------------AA- -AA---------------AA- -A-----------------A- BA-----------------AB BA-----------------AB AA-----------------AA AA-----------------AA BA-----------------AB AA-----------------AA AA-----------------AA BA-----------------AB AA-----------------AA AA-----------------AA BA-----------------AB BA-----------------AB -A-----------------A- -AA---------------AA- -AA---------------AA- -A-A-------------A-A- --A-AA---------AA-A-- ---AA-AAAAAAAAA-AA--- -----ABBBBBBBBBA----- 
--------------------- --------------------- --------------------- --------------------- --------------------- --------------------- --------------------- --------------------- -AA---------------AA- -AA---------------AA- -AA---------------AA- -AA---------------AA- -A-----------------A- AA-----------------AA BA-----------------AB BA-----------------AB BA-----------------AB BA-----------------AB BA-----------------AB BA-----------------AB BA-----------------AB BA-----------------AB AA-----------------AA AA-----------------AA -AA---------------AA- -AA---------------AA- -AA---------------AA- --AA-------------AA-- --A-AAA-------AAA-A-- ---AAA-AAAAAAA-AAA--- ------ABAAAAABA------ 
--------------------- --------------------- --------------------- --------------------- --------------------- --------------------- --------------------- --------------------- --AA-------------AA-- -A-A-------------A-A- -AA---------------AA- -AA---------------AA- -AA---------------AA- -AA---------------AA- -A-----------------A- AA-----------------AA AA-----------------AA AA-----------------AA AA-----------------AA AA-----------------AA AA-----------------AA AA-----------------AA BA-----------------AB -A----------------AA- -AA---------------AA- -AA---------------AA- -A-A-------------A-A- --A-A-----------A-A-- --AA-AAAA---AAAA-AA-- ----AAA--AAA--AAA---- -------BABBBAB------- 
--------------------- --------------------- --------------------- --------------------- --------------------- --------------------- --------------------- --------------------- --A---------------A-- --AAA-----------AAA-- -A-A-------------A-A- -A-A-------------A-A- -AA---------------AA- -AA---------------AA- -AA---------------AA- -AA---------------AA- -AA---------------AA- B-A---------------A-B BA-----------------AB BA-----------------AB BA-----------------AB BA-----------------AB AA-----------------AA -AA---------------AA- -AA---------------AA- -A-A-------------A-A- --A-A-----------A-A-- --A--AA-------AA--A-- ---AA--AAAAAAA--AA--- -----AAAAAAAAAAA----- --------------------- 
--------------------- --------------------- --------------------- --------------------- --------------------- --------------------- --------------------- --------------------- --------------------- ---AAA---------AAA--- --A-AAAA-----AAAA-A-- --A-A-----------A-A-- -A-A-------------A-A- -AA--------------A-A- -AA---------------AA- -AA---------------AA- -AA---------------AA- -AA---------------AA- A-A---------------A-A AA-----------------AA BA-----------------AB BA-----------------AB -AA---------------AA- -AA---------------AA- -A-A-------------A-A- -A-A------------A--A- --A-AA---------A--A-- ---A--AAA---AAA--A--- ----AA---AAA---AA---- ------AAAAAAAAA------ --------------------- 
--------------------- --------------------- --------------------- --------------------- --------------------- --------------------- --------------------- --------------------- --------------------- ----AA---------AA---- ---AA-AAAAAAAAA-AA--- --AA-AAAAAAAAAAA-AA-- --A-AA---------AA-A-- --AAA-----------A-A-- -A-A-------------A-A- -AA--------------A-A- -AA---------------AA- -AA---------------AA- -AA---------------AA- -AA---------------AA- -AA---------------AA- -AA---------------AA- -AA---------------AA- -A-A-------------A-A- -A-A------------A--A- --A-AA---------A--A-- --A---AA-----AA---A-- ---AA---AAAAA---AA--- -----AAAAAAAAAAA----- --------------------- --------------------- 
--------------------- --------------------- --------------------- --------------------- --------------------- --------------------- --------------------- --------------------- --------------------- --------------------- -----AAAAAAAAAAA----- ----AA-A-----A-AA---- ---A--AAAAAAAAA--A--- --A--AA-------AA--A-- --A-A-----------A-A-- --AA-------------AA-- --AA-------------AA-- -A-A-------------A-A- -A-A-------------A-A- -AA---------------AA- -AA---------------AA- -AA---------------AA- -A-A-------------A-A- -A--A-----------A--A- --A-AA---------A--A-- --A---AA-----AA---A-- ---AA---AAAAA---AA--- -----AAAA---AAAA----- ---------AAA--------- --------------------- --------------------- 
--------------------- --------------------- --------------------- --------------------- --------------------- --------------------- --------------------- --------------------- --------------------- --------------------- --------------------- ------AAAAAAAAA------ ----AAA------AAAA---- ---AA--AAAAAAA--AA--- ---A-AA-------AA-A--- --A-AA---------AA-A-- --A-A-----------A-A-- --A-A-----------A-A-- --A-A-----------A-A-- -A-A-------------A-A- -A-A-------------A-A- -A-AA-----------AAA-- --A-A-----------A-A-- --A--AA-------AA--A-- ---A--AAA---AAA--A--- ---AA---AAAAA---AA--- -----AAA-----AAA----- --------AAAAA-------- --------------------- --------------------- --------------------- 
--------------------- --------------------- --------------------- --------------------- --------------------- --------------------- --------------------- --------------------- --------------------- --------------------- --------------------- --------------------- -------AAAAAAA------- -----AAA-----AAA----- ----AA-AAAAAAA-AA---- ---AA-AAAA-AAAA-AA--- ---A-AA-------AA-A--- ---A-A---------A-A--- --A--A---------A--A-- --A-AA---------AA-A-- --A-AA---------AA-A-- --AA-AA-------AA-AA-- ---A-AAA-----AAA-A--- ---AA--AAAAAAA--AA--- ----AA---AAA---AA---- -----AAAAAAAAAAA----- --------AAAAA-------- --------------------- --------------------- --------------------- --------------------- 
--------------------- --------------------- --------------------- --------------------- --------------------- --------------------- --------------------- --------------------- --------------------- --------------------- --------------------- --------------------- --------------------- --------AAAAA-------- ------AAAAAAAAA------ -----AAAAAAAAAAA----- ----AAAAAAAAAAAAA---- ----AAAAAAAAAAAAA---- ---AA-AAEAAAEAA-AA--- ---AA-AADDEDDAA-AA--- ---AAAAAAAAAAAAAAA--- ----AAAAAAAAAAAAA---- ----AAAAAAAAAAAAA---- -----AAAAAAAAAAA----- ------AAAAAAAAA------ --------------------- --------------------- --------------------- --------------------- --------------------- --------------------- 
--------------------- --------------------- --------------------- --------------------- --------------------- --------------------- --------------------- --------------------- --------------------- --------------------- --------------------- --------------------- --------------------- --------------------- --------------------- --------------------- --------ABBBA-------- -------AABABAA------- -----AABAABAABAA----- -----AAABABABAAA----- ------ABBAAABBA------ -------ABABABA------- --------AAAAA-------- --------------------- --------------------- --------------------- --------------------- --------------------- --------------------- --------------------- --------------------- 
