model
size = 28 32 13, scale = 0.05, origin = -y
material 
  colors = A:#FFF B:#8F563B C:#663931 D:#000 E:#D9A066
voxels
706-C26-3C24-B3CB22-2B3C2B20-3B3C3B18-4B3C5B20-3C38-6D4-11D6-7D5-5BC4B4-6B9-4BC4B-7B11-4BC10B13-4BC8B15-4BC7B16-2(4BC6B17-)E3BC3B3E18-E2BC2BEB20-BEBCBE2B21-BECEB24-BCB26-C111-C26-BCB24-BECEB22-BEBCBEB20-BE2BC2BEB19-E3BC3BEB18-4BC4BE17-5BC5BE16-4B3C4BE3(16-4B3C5B)15-BA3B3C4BAB14-2B3-3C3-3B15-10D7-7D3-D9AD6-D6AD3-B9AB4-2B3A4B5-B8AB-3B4A2B8-B9AB5A2B10-B13A2B12-B12AB14-2(B11AB15-)E9A3B16-B8AE18-B3CAC2AC4(B18-B8C)B18-E8CE18-BE6CEB18-E8CE3(18-B8CB)18-10B17-B10-B16-E2(10-B16-B10-E16-B)10-B16-B2(10-2B14-2B)10-2B15-10D7-8D2-D9AD6-D6AD3-B9AB4-2B7AB4-B8AB-3B5A5B4-B9AB7A2B8-B15A2B10-B12A3B12-B11A2B14-2(B11AB15-)E10A2B15-B9CA2(E3(16-BC8-CB)16-EC8-C)E2(16-BC8-CB)16-2B8-2B16-B10-B16-E10-E3(16-B10-B)15-3(2B10-2B14-)2B10-2B15-10D7-8D2-D9AD6-D7AB2-B9AB4-2B8AB3-B8AB-3B6A4B4-B9AB7A2B8-B15A2B10-B12A3B12-B11A2B14-3(B11AB15-)EA8CA2B15-BC8-CE16-BC8-CB16-EC8-CE16-EC8-CB16-BC8-CE2(16-BC8-CB)16-EC8-CB16-EC8-CE16-BC8-CB16-2B8-B2(E16-B10-)B16-E10-B15-2(2B10-2B14-)2B10-2B99-10D7-8D2-D9AD6-D8AB-B9AB4-2B9AB2-B8AB-3B5A6B3-B9AB7A2B8-B15A2B10-B12A3B12-B11A2B14-2(B11AB15-)E11AB15-B9C2AB15-BC8-C2B15-EC8-CB16-BC8-CE16-BC8-CB16-EC8-CB16-BC8-CE16-E2(C8-CB16-B)C8-CB16-EC8-CE16-2B8-2B16-B10-E16-E10-B15-2B10-2B14-2B10-2B155-10D7-8D2-D9AD6-D8A3B9AB4-2B10AB-B8AB-3B6A7B-B9AB7A2B8-B15A2B10-B12A3B12-B11A2B14-3(B11AB15-)E9C2AB15-EC8-CAB15-BC8-C2B15-BC8-CB16-BC8-CE16-BC8-CB16-EC8-CB16-BC8-CE3(16-BC8-CB)16-EB8-2B16-E10-B15-2B10-BE14-2B10-2B183-10D7-8D2-D9AD6-D8AB-B9AB4-2B8A2B2-B8AB-3B6A5B3-B9AB7A2B8-B15A2B10-B12A3B12-B11A2B14-2(B11AB15-)E11AB15-B9C2AB15-BC8-C2B15-EC8-CB16-BC8-CE16-BC8-CB16-EC8-CB16-BC8-CE16-E2(C8-CB16-B)C8-CB16-EC8-CE16-2B8-2B16-B10-E16-E10-B15-2B10-2B14-2B10-2B155-10D7-8D2-D9AD6-D7AB2-B9AB4-2B7A2B3-B8AB-3B5A5B4-B9AB7A2B8-B15A2B10-B12A3B12-B11A2B14-3(B11AB15-)E9C2AB15-BC8-CE16-BC8-CB16-EC8-CE16-EC8-CB16-BC8-CE2(16-BC8-CB)16-EC8-CB16-EC8-CE16-BC8-CB16-2B8-B2(E16-B10-)B16-E10-B15-2(2B10-2B14-)2B10-2B99-10D7-8D2-D9AD6-D5A2D3-B9AB4-2B7AB4-B8AB-3B4A6B4-B9AB6A3B8-B14A3B10-B13A2B12-B11A2B14-B11AB15-B10A2B15-E10A2B15-B9CA2(E3(16-BC8-CB)16-EC8-C)E2(16-BC8-CB)16-2B8-2B16-B10-B16-E10-E3(16-B10-B)15-3(2B10-2B14-)2B10-2B15-10D7-7D3-D9AD6-D5AD4-B9AB4-2B4A3B5-B8AB-3B2ABA2B8-B9AB3ABA2B10-B12A3B12-B11A2B14-2(B11AB15-)E9A3B16-B8AE18-B8A4(B18-B8C)B18-E8CE18-BE6CEB18-E8CE3(18-B8CB)18-10B17-B10-B16-E2(10-B16-B10-E16-B)10-B16-B2(10-2B14-2B)10-2B32-6D4-11D6-7D5-5BC4B4-6B9-4BC4B-7B11-4BC10B13-4BC8B15-4BC7B16-2(4BC6B17-)E3BC3B3E18-E2BC2BEB20-BEBCBE2B21-BECEB24-BCB26-C111-C26-BCB24-BECEB22-BEBCBEB20-BE2BC2BEB19-E3BC3BEB18-4BC4BE17-5BC5BE16-4B3C4BE3(16-4B3C5B)15-BA3B3C4BAB14-2B3-3C3-3B720-C26-3C24-B3CB22-2B3C2B20-3B3C3B18-4B3C5B16-B3-3C4-B15-
