model
size = 9 11 18, scale = 0.05, origin = -y
material 
  colors = A:#002 B:#0F3 C:#EEE D:#777 E:#0E0 F:#CF3 G:#00E H:#36F I:#555 J:#111
voxels
--------- --------- ----AA--- ----AA--- ----AA--- --------- --------- --------- --------- --------- --------- 
--------- ----AA--- ----AA--- ----AA--- ----AA--- ----AA--- --------- --------- --------- --------- --------- 
----AA--- ----AA--- --------- ----CC--- --------- ----AA--- ----AA--- --------- --------- --------- --------- 
----AA--- ----AA--- ----CC--- ---DAAD-- ----CC--- ----AA--- -----A--- --------- --------- --------- --------- 
----AA--- ----AA--- --------- ----CC--- --------- ----AA--- ----AA--- ---BBB--- --------- --------- --------- 
--------- ----AA--- ----AA--- ----AA--- ----AA--- ----AA--- --------- ---BBB--- ---BHB--- ---BCB--- -EBB-BBB- 
--------- --------- ----AA--- ----AA--- ----AA--- --------- --------- ---BBB--- --------- --------- -B-----B- 
--------- --------- --------- --------- --------- --------- ---BBB--- ---BBB--- --------- --------- EE-----EE 
--------- --------- --------- ---BBB--- ---BBB--- ----BB--- ---BBB--- --------- --------- --------- --------- 
--------- --------- --------- ---BDB--- --------- --------- ---BBB--- ----BB--- --------- --------- --------- 
--------- --------- ----C---- ---BCB--- ---B----- --------- ---BBB--- ----FF--- --------- --------- --------- 
--------- ---CCCC-- ----D---- ----DA--- ---BCA--- ---I----- ---BBB--- ----FF--- --------- --------- --------- 
--------- ----AA--- ----AA--- ---AAA--- ---AAA--- ----AA--- -----B--- ----BB--- --------- --------- --------- 
----AA--- ----AA--- --------- ----CC--- --------- ----AA--- ----JG--- ----GG--- --------- --------- --------- 
----AA--- ----AA--- ----CC--- ---DCCD-- ----CC--- ----AA--- ----AA--- --------- --------- --------- --------- 
----AA--- ----AA--- --------- ----CC--- --------- ----AA--- ----AA--- --------- --------- --------- --------- 
--------- ----AA--- ----AA--- ----AA--- ----AA--- ----AA--- --------- --------- --------- --------- --------- 
--------- --------- ----AA--- ----AA--- ----AA--- --------- --------- --------- --------- --------- --------- 
