model
size = 22 16 28, scale = 0.05, origin = -y
material 
  colors = A:#EEE B:#930 C:#040 D:#F90 E:#E00
voxels
----AAAAAAAAAAAAAA---- ----AAAAAAAAAAAAAA---- ----AACCCCCCAAAAAA---- ----AACCCCCCAAAAAA---- ----AACCAAAACCAAAA---- ----AACCAAAACCAAAA---- ----AAAAAAAACCAAAA---- ----AAAAAAAACCAAAA---- ----AAAAAAAACCAAAA---- ----AAAAAAAACCAAAA---- ----AACCAAAACCAAAA---- ----AACCAAAACCAAAA---- ----AACCCCCCAAAAAA---- ----AACCCCCCAAAAAA---- ----AAAAAAAAAAAAAA---- ----AAAAAAAAAAAAAA---- 
----AAAAAAAAAAAAAA---- ----AAAAAAAAAAAAAA---- ----AACCCCCCAAAAAA---- ----AACCCCCCAAAAAA---- ----AACCAAAACCAAAA---- ----AACCAAAACCAAAA---- ----AAAAAAAACCAAAA---- ----AAAAAAAACCAAAA---- ----AAAAAAAACCAAAA---- ----AAAAAAAACCAAAA---- ----AACCAAAACCAAAA---- ----AACCAAAACCAAAA---- ----AACCCCCCAAAAAA---- ----AACCCCCCAAAAAA---- ----AAAAAAAAAAAAAA---- ----AAAAAAAAAAAAAA---- 
--AAAAAAAAAAAAAAAAAA-- --AAAAAAAAAAAAAAAAAA-- --AAAAAAAAAAAAAAAAAA-- --AAAAAAAAAAAAAAAAAA-- --AAAAAAAAAAAAAAAAAA-- --AAAAAAAAAAAAAAAAAA-- --AAAAAAAAAAAAAAAAAA-- --AAAAAAAAAAAAAAAAAA-- --AAAAAAAAAAAAAAAAAA-- --AAAAAAAAAAAAAAAAAA-- --AAAAAAAAAAAAAAAAAA-- --AAAAAAAAAAAAAAAAAA-- --AAAAAAAAAAAAAAAAAA-- --AAAAAAAAAAAAAAAAAA-- --AAAAAAAAAAAAAAAAAA-- --AAAAAAAAAAAAAAAAAA-- 
--AAAAAAAAAAAAAAAAAA-- --AAAAAAAAAAAAAAAAAA-- --AAAAAAAAAAAAAAAAAA-- --AAAAAAAAAAAAAAAAAA-- --AAAAAAAAAAAAAAAAAA-- --AAAAAAAAAAAAAAAAAA-- --AAAAAAAAAAAAAAAAAA-- --AAAAAAAAAAAAAAAAAA-- --AAAAAAAAAAAAAAAAAA-- --AAAAAAAAAAAAAAAAAA-- --AAAAAAAAAAAAAAAAAA-- --AAAAAAAAAAAAAAAAAA-- --AAAAAAAAAAAAAAAAAA-- --AAAAAAAAAAAAAAAAAA-- --AAAAAAAAAAAAAAAAAA-- --AAAAAAAAAAAAAAAAAA-- 
AAAAAAAAAAAAAAAAAAAAAA AAAAAAAAAAAAAAAAAAAAAA AAAABBBBBBBBBBBBBBAAAA AAAABBBBBBBBBBBBBBAAAA AAAABBBBBBBBBBBBBBAAAA AAAABBBBBBBBBBBBBBAAAA AAAABBBBBBBBBBBBBBAAAA AAAABBBBBBBBBBBBBBAAAA AAAABBBBBBBBBBBBBBAAAA AAAABBBBBBBBBBBBBBAAAA AAAABBBBBBBBBBBBBBAAAA AAAABBBBBBBBBBBBBBAAAA AAAABBBBBBBBBBBBBBAAAA AAAABBBBBBBBBBBBBBAAAA AAAA--------------AAAA AAAA--------------AAAA 
AAAAAAAAAAAAAAAAAAAAAA AAAAAAAAAAAAAAAAAAAAAA AAAABBBBBBBBBBBBBBAAAA AAAABBBBBBBBBBBBBBAAAA AAAABBBBBBBBBBBBBBAAAA AAAABBBBBBBBBBBBBBAAAA AAAABBBBBBBBBBBBBBAAAA AAAABBBBBBBBBBBBBBAAAA AAAABBBBBBBBBBBBBBAAAA AAAABBBBBBBBBBBBBBAAAA AAAABBBBBBBBBBBBBBAAAA AAAABBBBBBBBBBBBBBAAAA AAAABBBBBBBBBBBBBBAAAA AAAABBBBBBBBBBBBBBAAAA AAAA--------------AAAA AAAA--------------AAAA 
AAAAAAAAAAAAAAAAAAAAAA AAAAAAAAAAAAAAAAAAAAAA AAAABBBBBBBBBBBBBBAADD AAAABBBBBBBBBBBBBBAADD AAAABBBBBBBBBBBBBBAADD AAAABBBBBBBBBBBBBBAADD AAAABBBBBBBBBBBBBBAAAA AAAABBBBBBBBBBBBBBAAAA AAAABBBBBBBBBBBBBBAAAA AAAABBBBBBBBBBBBBBAAAA AAAABBBBBBBBBBBBBBAADD AAAABBBBBBBBBBBBBBAADD AAAABBBBBBBBBBBBBBAADD AAAABBBBBBBBBBBBBBAADD AAAA--------------AAAA AAAA--------------AAAA 
AAAAAAAAAAAAAAAAAAAAAA AAAAAAAAAAAAAAAAAAAAAA AAAABBBBBBBBBBBBBBAADD AAAABBBBBBBBBBBBBBAADD AAAABBBBBBBBBBBBBBAADD AAAABBBBBBBBBBBBBBAADD AAAABBBBBBBBBBBBBBAAAA AAAABBBBBBBBBBBBBBAAAA AAAABBBBBBBBBBBBBBAAAA AAAABBBBBBBBBBBBBBAAAA AAAABBBBBBBBBBBBBBAADD AAAABBBBBBBBBBBBBBAADD AAAABBBBBBBBBBBBBBAADD AAAABBBBBBBBBBBBBBAADD AAAA--------------AAAA AAAA--------------AAAA 
AAAAAAAAAAAAAAAAAAAAAA AAAAAAAAAAAAAAAAAAAAAA AAAABBBBBBBBBBBBBBAADD AAAABBBBBBBBBBBBBBAADD EEAABBBBBBBBBBBBBBAAAA EEAABBBBBBBBBBBBBBAAAA EEAABBBBBBBBBBBBBBAAAA EEAABBBBBBBBBBBBBBAAAA EEAABBBBBBBBBBBBBBAAAA EEAABBBBBBBBBBBBBBAAAA EEAABBBBBBBBBBBBBBAAAA EEAABBBBBBBBBBBBBBAAAA AAAABBBBBBBBBBBBBBAADD AAAABBBBBBBBBBBBBBAADD AAAA--------------AAAA AAAA--------------AAAA 
AAAAAAAAAAAAAAAAAAAAAA AAAAAAAAAAAAAAAAAAAAAA AAAABBBBBBBBBBBBBBAADD AAAABBBBBBBBBBBBBBAADD EEAABBBBBBBBBBBBBBAAAA EEAABBBBBBBBBBBBBBAAAA EEAABBBBBBBBBBBBBBAAAA EEAABBBBBBBBBBBBBBAAAA EEAABBBBBBBBBBBBBBAAAA EEAABBBBBBBBBBBBBBAAAA EEAABBBBBBBBBBBBBBAAAA EEAABBBBBBBBBBBBBBAAAA AAAABBBBBBBBBBBBBBAADD AAAABBBBBBBBBBBBBBAADD AAAA--------------AAAA AAAA--------------AAAA 
AAAAAAAAAAAAAAAAAAAAAA AAAAAAAAAAAAAAAAAAAAAA EEAABBBBBBBBBBBBBBAADD EEAABBBBBBBBBBBBBBAADD AAAABBBBBBBBBBBBBBAAAA AAAABBBBBBBBBBBBBBAAAA AAAABBBBBBBBBBBBBBAAAA AAAABBBBBBBBBBBBBBAAAA AAAABBBBBBBBBBBBBBAAAA AAAABBBBBBBBBBBBBBAAAA AAAABBBBBBBBBBBBBBAAAA AAAABBBBBBBBBBBBBBAAAA EEAABBBBBBBBBBBBBBAADD EEAABBBBBBBBBBBBBBAADD AAAA--------------AAAA AAAA--------------AAAA 
AAAAAAAAAAAAAAAAAAAAAA AAAAAAAAAAAAAAAAAAAAAA EEAABBBBBBBBBBBBBBAADD EEAABBBBBBBBBBBBBBAADD AAAABBBBBBBBBBBBBBAAAA AAAABBBBBBBBBBBBBBAAAA AAAABBBBBBBBBBBBBBAAAA AAAABBBBBBBBBBBBBBAAAA AAAABBBBBBBBBBBBBBAAAA AAAABBBBBBBBBBBBBBAAAA AAAABBBBBBBBBBBBBBAAAA AAAABBBBBBBBBBBBBBAAAA EEAABBBBBBBBBBBBBBAADD EEAABBBBBBBBBBBBBBAADD AAAA--------------AAAA AAAA--------------AAAA 
AAAAAAAAAAAAAAAAAAAAAA AAAAAAAAAAAAAAAAAAAAAA EEAABBBBBBBBBBBBBBAAAA EEAABBBBBBBBBBBBBBAAAA AAAABBBBBBBBBBBBBBAADD AAAABBBBBBBBBBBBBBAADD AAAABBBBBBBBBBBBBBAADD AAAABBBBBBBBBBBBBBAADD AAAABBBBBBBBBBBBBBAADD AAAABBBBBBBBBBBBBBAADD AAAABBBBBBBBBBBBBBAADD AAAABBBBBBBBBBBBBBAADD EEAABBBBBBBBBBBBBBAAAA EEAABBBBBBBBBBBBBBAAAA AAAA--------------AAAA AAAA--------------AAAA 
AAAAAAAAAAAAAAAAAAAAAA AAAAAAAAAAAAAAAAAAAAAA EEAABBBBBBBBBBBBBBAAAA EEAABBBBBBBBBBBBBBAAAA AAAABBBBBBBBBBBBBBAADD AAAABBBBBBBBBBBBBBAADD AAAABBBBBBBBBBBBBBAADD AAAABBBBBBBBBBBBBBAADD AAAABBBBBBBBBBBBBBAADD AAAABBBBBBBBBBBBBBAADD AAAABBBBBBBBBBBBBBAADD AAAABBBBBBBBBBBBBBAADD EEAABBBBBBBBBBBBBBAAAA EEAABBBBBBBBBBBBBBAAAA AAAA--------------AAAA AAAA--------------AAAA 
AAAAAAAAAAAAAAAAAAAAAA AAAAAAAAAAAAAAAAAAAAAA EEAABBBBBBBBBBBBBBAAAA EEAABBBBBBBBBBBBBBAAAA EEAABBBBBBBBBBBBBBAAAA EEAABBBBBBBBBBBBBBAAAA AAAABBBBBBBBBBBBBBAAAA AAAABBBBBBBBBBBBBBAAAA AAAABBBBBBBBBBBBBBAAAA AAAABBBBBBBBBBBBBBAAAA EEAABBBBBBBBBBBBBBAAAA EEAABBBBBBBBBBBBBBAAAA EEAABBBBBBBBBBBBBBAAAA EEAABBBBBBBBBBBBBBAAAA AAAA--------------AAAA AAAA--------------AAAA 
AAAAAAAAAAAAAAAAAAAAAA AAAAAAAAAAAAAAAAAAAAAA EEAABBBBBBBBBBBBBBAAAA EEAABBBBBBBBBBBBBBAAAA EEAABBBBBBBBBBBBBBAAAA EEAABBBBBBBBBBBBBBAAAA AAAABBBBBBBBBBBBBBAAAA AAAABBBBBBBBBBBBBBAAAA AAAABBBBBBBBBBBBBBAAAA AAAABBBBBBBBBBBBBBAAAA EEAABBBBBBBBBBBBBBAAAA EEAABBBBBBBBBBBBBBAAAA EEAABBBBBBBBBBBBBBAAAA EEAABBBBBBBBBBBBBBAAAA AAAA--------------AAAA AAAA--------------AAAA 
AAAAAAAAAAAAAAAAAAAAAA AAAAAAAAAAAAAAAAAAAAAA AAAABBBBBBBBBBBBBBAAAA AAAABBBBBBBBBBBBBBAAAA AAAABBBBBBBBBBBBBBAAAA AAAABBBBBBBBBBBBBBAAAA AAAABBBBBBBBBBBBBBAAAA AAAABBBBBBBBBBBBBBAAAA AAAABBBBBBBBBBBBBBAAAA AAAABBBBBBBBBBBBBBAAAA AAAABBBBBBBBBBBBBBAAAA AAAABBBBBBBBBBBBBBAAAA AAAABBBBBBBBBBBBBBAAAA AAAABBBBBBBBBBBBBBAAAA AAAA--------------AAAA AAAA--------------AAAA 
AAAAAAAAAAAAAAAAAAAAAA AAAAAAAAAAAAAAAAAAAAAA AAAABBBBBBBBBBBBBBAAAA AAAABBBBBBBBBBBBBBAAAA AAAABBBBBBBBBBBBBBAAAA AAAABBBBBBBBBBBBBBAAAA AAAABBBBBBBBBBBBBBAAAA AAAABBBBBBBBBBBBBBAAAA AAAABBBBBBBBBBBBBBAAAA AAAABBBBBBBBBBBBBBAAAA AAAABBBBBBBBBBBBBBAAAA AAAABBBBBBBBBBBBBBAAAA AAAABBBBBBBBBBBBBBAAAA AAAABBBBBBBBBBBBBBAAAA AAAA--------------AAAA AAAA--------------AAAA 
--AAAAAAAAAAAAAAAAAA-- --AAAAAAAAAAAAAAAAAA-- --AAAAAAAAAAAAAAAAAA-- --AAAAAAAAAAAAAAAAAA-- --AAAAAAAAAAAAAAAAAA-- --AAAAAAAAAAAAAAAAAA-- --AAAAAAAAAAAAAAAAAA-- --AAAAAAAAAAAAAAAAAA-- --AAAAAAAAAAAAAAAAAA-- --AAAAAAAAAAAAAAAAAA-- --AAAAAAAAAAAAAAAAAA-- --AAAAAAAAAAAAAAAAAA-- --AAAAAAAAAAAAAAAAAA-- --AAAAAAAAAAAAAAAAAA-- --AAAAAAAAAAAAAAAAAA-- --AAAAAAAAAAAAAAAAAA-- 
--AAAAAAAAAAAAAAAAAA-- --AAAAAAAAAAAAAAAAAA-- --AAAAAAAAAAAAAAAAAA-- --AAAAAAAAAAAAAAAAAA-- --AAAAAAAAAAAAAAAAAA-- --AAAAAAAAAAAAAAAAAA-- --AAAAAAAAAAAAAAAAAA-- --AAAAAAAAAAAAAAAAAA-- --AAAAAAAAAAAAAAAAAA-- --AAAAAAAAAAAAAAAAAA-- --AAAAAAAAAAAAAAAAAA-- --AAAAAAAAAAAAAAAAAA-- --AAAAAAAAAAAAAAAAAA-- --AAAAAAAAAAAAAAAAAA-- --AAAAAAAAAAAAAAAAAA-- --AAAAAAAAAAAAAAAAAA-- 
------AAAAAAAAAA------ ------AAAAAAAAAA------ ------AAAAAAAAAA------ ------AAAAAAAAAA------ ------AAAAAAAAAA------ ------AAAAAAAAAA------ ------AAAAAAAAAA------ ------AAAAAAAAAA------ ------AAAAAAAAAA------ ------AAAAAAAAAA------ ------AAAAAAAAAA------ ------AAAAAAAAAA------ ------AAAAAAAAAA------ ------AAAAAAAAAA------ ------AAAAAAAAAA------ ------AAAAAAAAAA------ 
------AAAAAAAAAA------ ------AAAAAAAAAA------ ------AAAAAAAAAA------ ------AAAAAAAAAA------ ------AAAAAAAAAA------ ------AAAAAAAAAA------ ------AAAAAAAAAA------ ------AAAAAAAAAA------ ------AAAAAAAAAA------ ------AAAAAAAAAA------ ------AAAAAAAAAA------ ------AAAAAAAAAA------ ------AAAAAAAAAA------ ------AAAAAAAAAA------ ------AAAAAAAAAA------ ------AAAAAAAAAA------ 
---------------------- ---------------------- ---------------------- ---------------------- --------AAAAAA-------- --------AAAAAA-------- ---------------------- ---------------------- ---------------------- ---------------------- ---------------------- ---------------------- --------AAAAAA-------- --------AAAAAA-------- ---------------------- ---------------------- 
---------------------- ---------------------- ---------------------- ---------------------- --------AAAAAA-------- --------AAAAAA-------- ---------------------- ---------------------- ---------------------- ---------------------- ---------------------- ---------------------- --------AAAAAA-------- --------AAAAAA-------- ---------------------- ---------------------- 
---------------------- ---------------------- ---------------------- ---------------------- --------AAAAAA-------- --------AAAAAA-------- ---------------------- ---------------------- ---------------------- ---------------------- ---------------------- ---------------------- --------AAAAAA-------- --------AAAAAA-------- ---------------------- ---------------------- 
---------------------- ---------------------- ---------------------- ---------------------- --------AAAAAA-------- --------AAAAAA-------- ---------------------- ---------------------- ---------------------- ---------------------- ---------------------- ---------------------- --------AAAAAA-------- --------AAAAAA-------- ---------------------- ---------------------- 
---------------------- ---------------------- ---------------------- ---------------------- --------AAAAAA-------- --------AAAAAA-------- --------AAAAAA-------- --------AAAAAA-------- --------AAAAAA-------- --------AAAAAA-------- --------AAAAAA-------- --------AAAAAA-------- --------AAAAAA-------- --------AAAAAA-------- ---------------------- ---------------------- 
---------------------- ---------------------- ---------------------- ---------------------- --------AAAAAA-------- --------AAAAAA-------- --------AAAAAA-------- --------AAAAAA-------- --------AAAAAA-------- --------AAAAAA-------- --------AAAAAA-------- --------AAAAAA-------- --------AAAAAA-------- --------AAAAAA-------- ---------------------- ---------------------- 
