model
size = 19 21 11, scale = 0.05, origin = -y
material 
  colors = A:#FF0 B:#FF3 C:#111 D:#555 E:#222 F:#888
voxels
---------C--------- ---------E--------- --------CE--------- ------------------- ------------------- ------------------- ------------------- ------------------- ------------------- ------------------- ------------------- ------------------- ------------------- ------------------- ------------------- ------------------- ------------------- ------------------- ------------------- ------------------- ------------------- 
------------------- ------------------- --------C---------- --------E---------- --------E---------- --------C---------- ------------------- ------------------- ------------------- ------------------- ------------------- ------------------- ------------------- ------------------- ------------------- ------------------- ------------------- ------------------- ------------------- ------------------- ------------------- 
------------F------ ------------------- ------------------- ------------------- ------------------- --------C---------- --------E---------- ------------------- ------------------- ------------------- ------------------- ------------------- ------------------- ------------------- ------------------- ------------------- ------------------- ------------------- ------------------- ------------------- ------------------- 
------------F------ ------------------- ------------------- ------------------- ------------------- ------------------- --------C---------- --------C---------- ------------------- ------------------- ------------------- ------------------- ------------------- ------------------- ------------------- ------------------- ------------------- ------------------- ------------------- ------------------- ------------------- 
-----------AA------ ------A------------ ------A------------ --AA-EA------------ --A--AE------------ --B--EA------------ --B--AE------------ ---B-EA-F---------- ----A--AA---------- ----A--AA---------- ----A--AA---------- ----A--AA---------- ----A--AA---------- ---A-A-AA---------- --A--A-BB---------- -A----BBB---------- -A-----B----------- -AAAABBB----------- ------------------- ----AA------------- ------------------- 
-----AAA--AA------- ----AAAA----A------ ---AAAAA----A------ --AAAAAA----A------ -AAAAAAAA---A------ -BBAAAAAA---A------ -BBBAAAAAA--A------ -BBBAAAAAA--A------ --BBAAAAAA--A------ --BAAAAAAA--A------ --AAAAAAAA--A------ --AAAAAAAA--------- --AAAAAAAA--------- --AAAAAAAA--------- --AAAABBBA--------- -AAAABBBBBA-------- -AAAABBBBBAA------- -AAAABBBB---------- -AAAAABB----------- ---AAAA------------ ----AA------------- 
----AAAA--AA-A----- ----AAAA---A-A----- ---AAAAA---A-A----- --AAAAAA---A-A----- -AAAAAAAA--A-A----- -BBAAAAAA--A-A----- -BBBAAAAAA-A-A----- -BBBAAAAAA-A-A----- --BBAAAAAA-AAA----- --BAAAAAAA-AAA----- -DAAAAAAAA-AAA----- --AAAAAAAA--------- --AAAAAAAA--------- DDAAAAAAAA--------- --AAAAAAAA--------- -AAAAABBBAAAAA----- -AAAAABBBAAAAA----- -AAAAABBB---------- -AAAAAAA----------- ---AAAA------------ ----AA------------- 
----AAAA--AA-ACC--- ----AAAA--AA-A----- ---AAAAA---A-A----- --AAAAAA---A-A----- -AAAAAAAA--A-A----- -AAAAAAAA--A-A----- -BBAAAAAAA-A-A----- -BBAAAAAAA-A-A----- --BAAAAAAA-AAA----- --AAAAAAAA-AAA----- -DAAAAAAAA-AAA----- --AAAAAAAA--D------ --AAAAAAAA--D------ DDAAAAAAAA--D------ --AAAAAAAA--D------ -AAAAAAAAAAAAA----- -AAAAAAAAAAAAA----- -AAAAAAAA---------- -AAAAAAA----------- ---AAAA------------ ----AA------------- 
----AAAA--A-A--CC-- ----AAAA----A------ ---AAAAA----A------ --AAAAAA----A------ -AAAAAAAA---A------ -AAAAAAAA---A------ -AAAAAAAAA--A------ -AAAAAAAAA--A------ --AAAAAAAA--A------ --AAAAAAAA--A------ --AAAAAAAA--A------ -DAAAAAAAA--------- -DAAAAAAAA--------- --AAAAAAAA--------- --AAAAAAAA--------- -AAAAAAAAAA-------- -AAAAAAAAAACC------ -AAAAAAAA---------- -AAAAAAA----------- ---AAAA------------ ----AA------------- 
----------A-A---C-- ----------------C-- ------------------- ------------------- ------------------- -----A------------- -----A------------- -----A------------- -----A------------- ------A------------ ------A------------ ------A------------ ------A------------ ------------------- ----AAA---------C-- ----AAA-------CCC-- -----A------CCC---- ------------------- ------------------- ------------------- ------------------- 
------------------- ----------------CCC ------------------C ------------------- ------------------- ------------------- ------------------- ------------------- ------------------- ------------------- ------------------- ------------------- ------------------- ------------------- -----AA---------CCC ----AAA------------ -----A------------- ------------------- ------------------- ------------------- ------------------- 
