model
size = 17 32 9, scale = 0.05, origin = -y
material 
  colors = A:#FF0 B:#CC3 C:#222 D:#111 E:#FF3 F:#555 G:#444 H:#888 I:#777
voxels
207-2(2A15-A16-)2A270-4(2AC)A3-A4(C2A)CA-C2ACA5-2AC5ACA7-2A3BAF7-5A3BAF6-A3BA5-F5-2ABAB-A4-F4-3A3B-2A3-I3-7A-16A9-3A3-3A8-2A5-2A8-2A2-C2-2A8-A6-2A8-3A3-3A8-A-7A8-5A2(3-A)5-3A5-A2-A5-3A2-C2(2-A)6-2A5-A2-A6-3A3-2A9-9A8-7A2B7-8A2B7-A3BA3-3B2A4-4B5-3A5-3B7-A6-2BA3-C3-A6-3B7-A6-4B5-2A6-A3BA3-2A9-6A8-13A4-13A3-4A5-2A3B3-2A7-A4B9-4A4B8-5A11-5A-A9-6A-2A7-3A3BA2-4A2-2A3D4B4-H7-D5B3-F7-CBA3B3-F7-D5B3-F7-C4BA3-F7-D3B2A3-F7-C5A3-H7-D5A3-2A6-C6A2-2A6-D3B3A2-2A6-C4B6A6-ABA2B4A8-A4BA2BH8-D3BA3B9-C4A3B9-D4A5BA6-C5A3BA7-2(D8A8-C8A8-)D7A9-6A8-13A4-13A3-4A5-2A3B3-2A7-A4B9-4A4B8-5A11-5A-A9-B5A-2A7-2B5A7-2AB3D4A12-3(D5A11-C5A11-)D5A3-A7-C6A2-A7-D6A2-A7-C6A2-A7-D6A10-C5A2B9-D4A3B9-C4A3B9-D4A5BA6-C5A3BA7-2(D8A8-C8A8-)8A9-6A8-13A4-13A3-4A5-2A3B3-2A7-A4B9-4A4B8-5A11-5A-A9-2B4A-2A7-3B4A7-A2B3D4A12-2(D5A11-C5A11-)D5A11-C3A2B11-D3A2B11-C3A3B10-D6A10-C6A10-D6A10-C5A2B9-D4A3B9-C4A3B9-D4A5BA6-C5A3BA7-D8A8-C4A3BA8-D4A3BA8-C4A3BA8-8A9-6A8-13A4-13A3-4A5-5A3-2A7-2A3B9-5A3B8-5A11-5A-A9-2B4A-2A7-3B4A8-2B3D4A12-D5A11-C5A11-D5A11-CB4A11-DB2A2B11-CBA3B11-D2A3B11-C2A4B10-D3A3B10-C6A10-7A10-8A9-D5A2B9-C5A2B9-D5A3B2A6-C9A7-D4A3BA8-C3A5B8-D3A5B8-C3A5B8-D4A3B9-6A8-2(13A4-)3A5-5A3-2A8-4A9-2A2-4A8-5A11-5A-A9-2B4A-2A7-3B4A7-A5B4A7-2A3B6A6-2A-8A6-A-2A3B4A6-2A-5B3A6-A-A5BA2B6-3A8B7-3A3BA3B9-5A4B8-6A3B8-9A9-8A9-9A8-B8A8-2B7A7-3B10A4-3B9A5-2B5A3BA3(6-6A5B)7-6A3B9-6A8-4(2AC)A3-A4(C2A)CA-C2ACA2-3E5AC2ACA3-5E5A2-2F2-7E4A2-2F2-3E-3E6-2F2-7E6-I4-5E7-I5-3E8-E3B3E48-2BA2(14-3B)AB12-5B12-2BA2B12-3A2B12-2A2GB12-AG3A12-AG2AG12-2A2GA12-5A12-B2A14-B2A282-2E387-
