model
size = 18 21 9, scale = 0.05, origin = -y
material 
  colors = A:#FF0 B:#FF3 C:#111 D:#222 E:#555 F:#888
voxels
------------------ ---------------CCD -----------------C ------------------ ------------------ ------------------ ------------------ ------------------ ------------------ ------------------ ------------------ ------------------ ------------------ ------------------ ----AA---------CCC ---AAA------------ ----A------------- ------------------ ------------------ ------------------ ------------------ 
---------A-A---C-- ---------------D-- ------------------ ------------------ ------------------ ----A------------- ----A------------- ----A------------- ----A------------- ---A-------------- ---A-------------- ---A-------------- ---A-------------- ------------------ ----AA---------C-- ---BAA-------CCC-- ----A------CCC---- ------------------ ------------------ ------------------ ------------------ 
---AAAA--A-A--CC-- ---AAAA----A------ --BBAAA----A------ -BBBAAA----A------ BBBBAAAA---A------ BBBAAAAA---A------ AAAAAAAAA--A------ AAAAAAAAA--A------ -AAAAAAAA--A------ -AAAAAAAA--A------ -AAAAAAAA--A------ -AAAAAAAA--------- -BBAAAAAA--------- -BBBAAAAA--------- -BBBAAAAA--------- BBBBAAAAAA-------- BBBAAAAAAACC------ AAAAAAAA---------- AAAAAAA----------- --AAAA------------ ---AA------------- 
---AAAA--AA-ACD--- ---AAAA--AA-A----- --BBAAA---A-A----- -BBBAAA---A-A----- BBBBAAAA--A-A----- BBBAAAAA--A-A----- AAAAAAAAA-A-A----- AAAAAAABB-A-A----- -AAAAAABB-AAA----- -AAAAAABB-AAA----- -AAAAAAAA-AAA----- -AAAAAAAA--E------ -BBAAAAAA--E------ -BBBAAAAA--E------ -BBBAAAAA--E------ BBBBAABBBAAAA----- BBBAAABBBAAAA----- AAAAAABB---------- AAAAAAA----------- --AAAA------------ ---AA------------- 
---AAAA--AA-A----- ---AAAA---A-A----- --BBAAA---A-A----- -BBBAAA---A-A----- BBBBAAAA--A-A----- BBBAAAAA--A-A----- AAAAAAABB-A-A----- AAAAAABBB-B-A----- -AAAAABBB-BAA----- -AAAAABBB-BAA----- -AAAAAABB-AAA----- -AAAAAAAA--------- -AAAAAAAA--------- -BBAAAAAA--------- -BBAAABBB--------- BBBAABBBBBAAA----- AAAAABBBBBAAA----- AAAAABBB---------- AAAAAAB----------- --AAAA------------ ---AA------------- 
----AAA--AA------- ---AAAA----A------ --BAAAA----A------ -BBAAAA----A------ BBBAAAAA---A------ AAAAAAAA---A------ AAAAAAABB--A------ AAAAAABBB--A------ -AAAAABBB--A------ -AAAAABBB--A------ -AAAAAABB--A------ -AAAAAAAA--------- -AAAAAAAA--------- -AAAAAAAA--------- -AAAAABBB--------- AAAAABBBBB-------- AAAAABBBBBA------- AAAAABBB---------- AAAAAAB----------- --AAAA------------ ---AA------------- 
----------AA------ -----A------------ -----A------------ -AA-DAF----------- -A--AD------------ -A--DA------------ -A--AD------------ --A-DA------------ ---A--BB---------- ---A--BB---------- ---A--AB---------- ---A--AA---------- ---A--AA---------- --A-A-AA---------- -A--A-BB---------- A----BBB---------- A-----B----------- AAAAABB----------- ------------------ ---AA------------- ------------------ 
-----------F------ ------------------ ------------------ -----D------------ ------------------ ------------------ ------------------ ------------------ ------------------ ------------------ ------------------ ------------------ ------------------ ------------------ ------------------ ------------------ ------------------ ------------------ ------------------ ------------------ ------------------ 
----CD------------ ----D------------- ----CD------------ -----C------------ ------------------ ------------------ ------------------ ------------------ ------------------ ------------------ ------------------ ------------------ ------------------ ------------------ ------------------ ------------------ ------------------ ------------------ ------------------ ------------------ ------------------ 
