model
size = 30 31 18, scale = 0.05, origin = -y
material 
  colors = A:#FF3 B:#CC3 C:#111 D:#222 E:#001 F:#777 G:#AAA H:#F60
voxels
------------------------------ ------------------------------ ------------------------------ ------------------------------ ------------------------------ ------------------------------ -----------------------------D -----------------------------D -----------------------------D ----------------------------CC ----------------------------C- ------------------------------ ------------------------------ ------------------------------ ------------------------------ -----------------------------C -----------------------------D -----------------------------C ------------------------------ ------------------------------ ------------------------------ ------------------------------ ----------------------------C- ------------------------------ ------------------------------ ------------------------------ ------------------------------ ------------------------------ ------------------------------ ------------------------------ ------------------------------ 
------------------------------ ------------------------------ ------------------------------ ------------------------------ ------------------------------ ------------------------------ -----------------------------D ------------------------------ ------------------------------ ------------------------------ ------------------------------ ------------------------------ ------------------------------ --------------AAAAAAAAAA------ -------------EA-AAAAAA-A-----C -------------DAAAAAA-A-A-----D -------------EA-AAAA-A-B------ -------------EAAAA-A-B-B-----D -------------DAAAA-A-B-B-----C -------------EAA-A-A-B-B-----D -------------EAA-A-A-A-B------ -------------DAA-A-A-A-A-----C --------------AAAAAAAAAA----CC -----CCCCCCCAAAAAA------------ ------------------------------ ------------------------------ ------------------------------ ------------------------------ ------------------------------ ------------------------------ ------------------------------ 
--------------AAA------------- --------------AAAA------------ --------------AAAAAA---------- --------------AAAAAAAA-------- --------------AAAAAAAAAA------ ------------------------------ -----------------------------C -----------------------------D ------------------------------ --------------AAAAAAAAAA------ --------------AAAAAAA--A------ --------------AAAAAAAA-A------ --------------AAAAAAAAAA-----C --------------AAAAAAAAAA-----C -------------EAAAAAAAA-------D -------------DAAAAAAAA-------- -------------EAAAAAAAA-------- -------------EAAAAAAAB-------- -------------DAAAAAAAB-------- -------------EAAAAAAAB-------C -------------EAAAAAAAA-------D -------------DAAAAAAAA-------C --------------AAAAAAAA-------- ---CCC--------AAAAAA---------- ------------------G----------- ------------------G----------- ------------------G----------- ------------------G----------- ------------------G----------- ------------------G----------- ------------------G----------- 
-------------DAAC------------- -------------CAACC------------ -------------DAACCCC---------- -------------CAACCCCCC-------- --------------AAAAAAAAAAFF---- ------------------------------ ------------------------------ -----------------------------D -----------------------------C --------------AAAAAAAAAA------ --------------AAAAAAAAAA------ --------------AAAAAAAAAA-A---- --------------AAAAAAAAAA-A---D --------------AAAAAAAAAA-A---- -------------DAAAAAAAA---A---- -------------EAAAAAAAA---A---- -------------EAAAAAAAA---A---- -------------DAAAAAAAA---A---- -------------EAAAAAAAA---A---- -------------EAAAAAAAA---A---- -------------DAAAAAAAA---A---- -------------EAAAAAAAA---B---- --------------AAAAAAAA---B---- --AA----------AAAAAAAA---B---- -------------------------A---- -------------------------A---- -------------------D-----D---- --------------DDDDDDDDDDDD---- ------------------------------ ------------------------------ ------------------------------ 
-------------DAAC------------- -------------CAACC------------ -------------DAACCCC---------- -------------CAACCCCCC-------- --------------AAAAAAAAAAFF---- -------------------------D---- ---BAAAACCCCCCAAAAAAAAAA-D---- -BBB----------AAAAAAAAAA-D---- -B------------AAAAAAAAAA-D---D BB------------AAAAAAAAAA-D---C A-------------AAAAAAAAAA-D---- A-------------AAAAAAAAAAAAA--- --------------AAAAAAAAAAAAA--D --------------AAAAAAAAA-AAA--D -------------DAAAAAAAA--AAA--- -------------EAAAAAAAA--AAA--- -------------EAAAAAAAA--AAA--- -------------DAAAAAAAA--AAA--- -------------EAAAAAAAA--AAA--- -------------EAAAAAAAA--AAA--- -------------DAAAAAAAA--BBB--- -------------EAAAAAAAA--BBB--- --------------AAAAAAAA--BBB--- -AA-----------BBAAAAAA--BBB--- --------------BBBAAAA---BBB--- --------------BBBAAA----AAA--- --------------BBBAA-DDD-DDD--- --------------BBAADDDDDDDD---- ------------------------------ ------------------------------ ------------------------------ 
-------------DAAC------------- -------------CAACC------------ -------------DAACCCC---------- -------------CAACCCCCC-------- --------------AAAAAAAABBBF---- ------------------------------ --------------AAAAAAAAAA------ --------------AAAAAAAAAA------ --------------AAAAAAAAAA------ --------------AAAAAAAAAA-----C --------------AAAAAAAAAA-----C A------------DAAAAAAAAAA-A---- A------------EAAAAAAAAAA-A---- A------------EAAAAAAAAAA-A---C -------------DAAAAAAAA---A---C -------------EAAAAAAAA---A--CD -------------EAAAAAAAA---A-DD- -------------DAAAAAAAA---A---- -------------EAAAAAAAA---A---- -------------EAAAAAAAA---A---- -------------DAAAAAAAA---B---- -------------EAAAAAAAA---B---- --------------AAAAAAAA---B---- A-------------BBAAAAAA---B---- --------------BBBAAAA----B---- --------------BBBAAA-----A---- --------------BBBAA------D---- --------------BBAA------------ ------------------------------ ------------------------------ ------------------------------ 
-------------DAAC------------- -------------CAACC------------ -------------DAACCCC---------- -------------CAACCCCCC-------- --------------CAAAAAABBB------ --------------AAAAAAAABB------ --------------AAAAAAAAAA------ --------------AAAAAAAAAA------ -------------EAAAAAAAAAA------ -------------DAAAAAAAAAA------ -------------EAAAAAAAAAA-----C -------------DAAAAAAAAAA----CD -------------EAAAAAAAAAA------ A------------EAAAAAAAAAA------ A------------DAAAAAAAAAA------ A------------EAAAAAAAAAA------ B------------EAAAAAAAAAA---D-- B------------DAAAAAAAAAA--DD-- B------------EAAAAAAAAAA--C--- A------------EAAAAAAAAAA--C--- A------------DAAAAAAAAAA------ A------------EAAAAAAAAAB------ A-------------AAAAAAAAA------- AB------------BBAAAAAA-------- -BB-----------BBBAAAA--------- --BB----------BBBAAA---------- ---BBA--------BBBAA----------- -----AAAAAAAABBBAA------------ ------------------------------ ------------------------------ ------------------------------ 
-------------DAAAAAAAAAA------ -------------CAAAAAAAABB------ -------------DAAAAAAABBB------ -------------CAAAAAAABBB------ --------------CAAAAAABBB------ --------------DAAAAAAABB------ --------------CAAAAAAAAA------ --------------DAAAAAAAAA------ -------------EAAAAAAAAAA------ -------------DAAAAAAAAAA------ -------------EAAAAAAAAAA------ -------------DAAAAAAAAAA----C- -------------EAAAAAAAAAA---CC- -------------DAAAAAAAAAA--CD-- -------------EAAAAAAAAAA--C--- B------------EAAAAAAAAAA------ -------------DAAAAAAAAAA------ B------------EAAAAAAAAAF------ -------------EAAAAAAAAAF------ -------------DAAAAAAAAAF-CC--- -------------EAAAAAAAAAA------ -------------EAAAAAAAAAA------ --------------AAAAAAAAA------- --------------AAAAAAAA-------- --------------BBAAAAA--------- --B-----------BBAAAA---------- --------------BBAAA----------- ----------AAAAAAAA------------ ------------------------------ ------------------------------ ------------------------------ 
--------------AAAAAAAAAA------ --------------AAAAAAAABB------ --------------AAAAAAABBB------ --------------AAAAAAABBB------ --------------CAAAAAABBB------ --------------DAAAAAAABB------ --------------CAAAAAAAAA------ --------------DAAAAAAAAA------ -------------EAAAAAAAAAA------ -------------DAAAAAAAAAA------ -------------EAAAAAAAAAA------ -------------DAAAAAAAABB------ -------------EAAAAAAAABB------ -------------DAAAAAAAABB------ -------------EAAAAAAAAAA--D--- B------------EAAAAAAAAAA--C--- -------------DAAAAAAAAAF-CD--- B------------EAAAAAAAAAFGG---- -------------EAAAAAAAAAF------ -------------DAAAAAAAAAFGG---- -------------EAAAAAAAAAF------ -------------EAAAAAAAAAA------ --------------AAAAAAAAA------- --------------AAAAAAAA-------- --------------AAAAAAA--------- --B-----------AAAAAA---------- --------------AAAAA----------- ----------AAAAAAAA------------ -----------HH----------------- -----------HH----------------- ------------------------------ 
--------------AAAAAAAAAA------ --------------AAAAAAAAAA------ --------------AAAAAAAABB------ --------------AAAAAAAABB------ --------------CAAAAAAABB------ --------------DAAAAAAAAA------ --------------CAAAAAAAAA------ --------------DAAAAAAAAA------ -------------EAAAAAAAAAA------ -------------DAAAAAAAAAA------ -------------EAAAAAAAABB------ -------------DAAAAAAABBB------ -------------EAAAAAAABBB------ -------------DAAAAAAABBB------ -------------EAAAAAAAABB------ B------------EAAAAAAAAAA------ -------------DAAAAAAAAAF------ B------------EAAAAAAAAAF------ -------------EAAAAAAAAAA------ -------------DAAAAAAAAAF------ -------------EAAAAAAAAAF------ -------------EAAAAAAAAAA------ --------------AAAAAAAAA------- --------------AAAAAAAA-------- --------------AAAAAAA--------- --A-----------AAAAAA---------- --------------AAAAA----------- ----------AAAAAAAA------------ -----------HH----------------- -----------HH----------------- ------------------------------ 
-------------DAAAAAAAAAA------ -------------CAAAAAAAAAA------ -------------DAAAAAAAAAA------ -------------CAAAAAAAAAA------ --------------CAAAAAAAAA------ --------------DAAAAAAAAA------ --------------CAAAAAAAAA------ --------------DAAAAAAAAA------ -------------EAAAAAAAAAA------ -------------DAAAAAAAAAA------ -------------EAAAAAAAABB------ -------------DAAAAAAABBB------ -------------EAAAAAAABBB------ -------------DAAAAAAABBB---C-- -------------EAAAAAAAABB-CCC-- A------------EAAAAAAAAAACC---- -------------DAAAAAAAAAFG--D-- B------------EAAAAAAAAAFG--D-- -------------EAAAAAAAAAF-DDD-- -------------DAAAAAAAAAFGG---- -------------EAAAAAAAAAF------ -------------EAAAAAAAAAA------ --------------AAAAAAAAA------- --------------AAAAAAAA-------- --------------AAAAAAA--------- --A-----------AAAAAA---------- --------------AAAAA----------- ----------AAAAAAAA------------ ------------------------------ ------------------------------ ------------------------------ 
-------------DAAC------------- -------------CAACC------------ -------------DAACCCC---------- -------------CAACCCCCC-------- --------------CAAAAAAAAA------ --------------AAAAAAAAAA------ --------------AAAAAAAAAA------ --------------AAAAAAAAAA------ -------------EAAAAAAAAAA------ -------------DAAAAAAAAAA------ -------------EAAAAAAAABB------ -------------DAAAAAAABBB----CD -------------EAAAAAAABBB----C- A------------EAAAAAAABBB---CC- A------------DAAAAAAAABB------ A------------EAAAAAAAAAA----D- A------------EAAAAAAAAAA---DD- A------------DAAAAAAAAAF---DD- A------------EAAAAAAAAAF------ A------------EAAAAAAAAAF------ A------------DAAAAAAAAAA------ A------------EAAAAAAAAAA------ A-------------AAAAAAAAA------- AA------------AAAAAAAA-------- -AA-----------AAAAAAA--------- --AA----------AAAAAA---------- ---AAA--------AAAAA----------- -----AAAAAAAAAAAAA------------ ------------------------------ ------------------------------ ------------------------------ 
-------------DAAC------------- -------------CAACC------------ -------------DAACCCC---------- -------------CAACCCCCC-------- --------------AAAABBBAAAFF---- ------------------------------ --------------AAAAAAAAAA------ --------------AAAAAAAAAA------ --------------ABBBAAAABB------ --------------ABBBAAAABB-----D --------------ABBBAAAABB-----C A------------DAAAAAAAABB-A---C A------------EAAAAAAAABB-A---- A------------EAAAAAAAABB-A---- -------------DAAAAAAAA---A--DC -------------EAAAAAAAA---B--D- -------------EAAAAAAAA---B---- -------------DAAAAAAAA---B---- -------------EAAAAAAAA---B---- -------------EAAAAAAAA---B---- -------------DAAAAAAAA---A---- -------------EAAAAAAAA---A---- --------------AAAAAAAA---A---- A-------------AAAAAAAA---A---- --------------AAAAAAA----A---- --------------AAAAAA-----A---- --------------AAAAA------D---- --------------AAAA------------ ------------------------------ ------------------------------ ------------------------------ 
-------------DAAC------------- -------------CAACC------------ -------------DAACCCC---------- -------------CAACCCCCC-------- --------------AAAABBBAAAFF---- -------------------------D---- ---BBBAACCCCCCAAAAAAAAAA-D---- -BBB----------ABBBAAAABB-D---- -B------------BBBBBAABBB-B---- AA------------BBBBBAABBB-B---D A-------------BBBBBAABBB-B---- A-------------ABBBAAAABBBAA--- --------------AAAAAAAAAAAAA--- --------------AAAAAAAAA-AAA--- -------------DAAAAAAAA--AAA--C -------------EAAAAAAAA--ABB--- -------------EAAAAAAAA--BBB--- -------------DAAAAAAAA--BBB--- -------------EAAAAAAAA--BBB--- -------------EAAAAAAAA--ABB--- -------------DAAAAAAAA--AAA--- -------------EAAAAAAAA--AAA--- --------------AAAAAAAA--AAA--- -AA-----------AAAAAAAA--AAA--- --------------AAAAAAA---AAA--- --------------AAAAAA----AAA--- --------------AAAAA-DDD-DDD--- --------------AAAADDDDDDDD---- ------------------------------ ------------------------------ ------------------------------ 
-------------DAAC------------- -------------CAACC------------ -------------DAACCCC---------- -------------CAACCCCCC-------- --------------AAAABBBAAAFF---- ------------------------------ ------------------------------ -----------------------------C -----------------------------D --------------BBBBBAABBB-----D --------------BBBBBAABBB------ --------------ABBBAAAABB-A---- --------------AAAAAAAAAA-A---- --------------AAAAAAAAAA-A---- -------------DAAAAAAAA---A---C -------------EAAAAAAAA---B---D -------------EAAAAAAAA---B---- -------------DAAAAAAAA---B---- -------------EAAAAAAAA---B---- -------------EAAAAAAAA---B---- -------------DAAAAAAAA---A---- -------------EAAAAAAAA---A---- --------------AAAAAAAA---A---- --AA----------AAAAAAAA---A---- -------------------------A---- -------------------------A---- -------------------D-----D---- --------------DDDDDDDDDDDD---- ------------------------------ ------------------------------ ------------------------------ 
--------------AAA------------- --------------AAAA------------ --------------AAAABB---------- --------------AAAABBBA-------- --------------AAAAAAAAAA------ ------------------------------ ------------------------------ ----------------------------CC ------------------------------ --------------BBBBBAABBB------ --------------BBBBBAA--B------ --------------ABBBAAAA-B------ --------------AAAAAAAAAA------ --------------AAAAAAAAAA------ -------------EAAAAAAAA-------- -------------DAAAAAAAA-------D -------------EAAAAAAAA-------D -------------EAAAAAAAA------CC -------------DAAAAAAAA-------- -------------EAAAAAAAA-------- -------------EAAAAAAAA-------- -------------DAAAAAAAA-------- --------------AAAAAAAA-------- ---CCC--------AAAAAA---------- ------------------G----------- ------------------G----------- ------------------G----------- ------------------G----------- ------------------G----------- ------------------G----------- ------------------G----------- 
------------------------------ ------------------------------ ------------------------------ ------------------------------ ------------------------------ ------------------------------ ------------------------------ ----------------------------C- ----------------------------D- ----------------------------D- ----------------------------C- ------------------------------ ------------------------------ --------------AAAAAAAAAA------ -------------EA-AAAAAA-A------ -------------DAAAAAA-A-A------ -------------EA-AAAA-A-A-----C -------------EAAAA-A-A-A----C- -------------DAAAA-A-A-A----C- -------------EAA-A-A-A-A------ -------------EAA-A-A-A-A------ -------------DAA-A-A-A-A------ --------------AAAAAAAAAA------ -----CCCCCCCAAAAAA------------ ------------------------------ ------------------------------ ------------------------------ ------------------------------ ------------------------------ ------------------------------ ------------------------------ 
------------------------------ ------------------------------ ------------------------------ ------------------------------ ------------------------------ ------------------------------ ------------------------------ ------------------------------ ------------------------------ ------------------------------ ----------------------------C- ------------------------------ ------------------------------ ------------------------------ ------------------------------ ------------------------------ ------------------------------ ------------------------------ ---------------------------CC- ---------------------------D-- ---------------------------C-- ---------------------------C-- ------------------------------ ------------------------------ ------------------------------ ------------------------------ ------------------------------ ------------------------------ ------------------------------ ------------------------------ ------------------------------ 
