model
size = 30 10 30, scale = 0.05, origin = -y
material 
  colors = A:#700 B:#111 C:#930
voxels
-----------AAAAAAAA----------- ------------------------------ ------------------------------ ------------------------------ ------------------------------ ------------------------------ ------------------------------ ------------------------------ ------------------------------ ------------------------------ 
---------AAAAAAAAAAAA--------- ------------------------------ ------------------------------ ------------------------------ ------------------------------ ------------------------------ ------------------------------ ------------------------------ ------------------------------ ------------------------------ 
------AAAAAAAAAAAAAAAAAA------ ------------------------------ ------------------------------ ------------------------------ ------------------------------ ------------------------------ ------------------------------ ------------------------------ ------------------------------ ------------------------------ 
----AAAAAAAAAAAAAAAAAAAAAA---- ------------------------------ ------------------------------ ------------------------------ ------------------------------ ------------------------------ ------------------------------ ------------------------------ ------------------------------ ------------------------------ 
---AAAAAAAAAAAAAAAAAAAAAAAA--- ------------------------------ ------------------------------ ------------------------------ ------------------------------ ------------------------------ ------------------------------ ------------------------------ ------------------------------ ------------------------------ 
---AAAAAAAAAAAAAAAAAAAAAAAA--- ------------------------------ ------------------------------ ------------------------------ ------------------------------ ------------------------------ ------------------------------ ------------------------------ ------------------------------ ------------------------------ 
--AAAAAAAAAAAAAAAAAAAAAAAAAA-- ------------------------------ ------------------------------ ------------------------------ ------------------------------ ------------------------------ ------------------------------ ------------------------------ ------------------------------ ------------------------------ 
--AAAAAAAAAAAAAAAAAAAAAAAAAA-- -----------BBBBBBBB----------- -----------BBBBBBBB----------- ------------AAAAAA------------ ------------AAAAAA------------ -------------AAAA------------- -------------AAAA------------- --------------AA-------------- --------------AA-------------- ------------------------------ 
--AAAAAAAAAAAAAAAAAAAAAAAAAA-- --------BBBBBBBBBBBBBB-------- ---------BBBBBBBBBBBB--------- ---------AAAAAAAAAAAA--------- ----------AAAAAAAAAA---------- ----------AAAAAAAAAA---------- -----------AAAAAAAA----------- -----------AAAAAAAA----------- ------------AAAAAA------------ -------------AAAA------------- 
-AAAAAAAAAAAA----AAAAAAAAAAAA- --------BBBBBB--BBBBBB-------- --------BBBBBB--BBBBBB-------- --------AAAAAAAAAAAAAA-------- ---------AAAAAAAAAAAA--------- ---------AAAAAAAAAAAA--------- ---------AAAAAAAAAAAA--------- ---------AAAAAAAAAAAA--------- ----------AAAA--AAAA---------- ----------AAAAAAAAAA---------- 
-AAAAAAAAAA--------AAAAAAAAAA- --------BBB--------BBB-------- --------BBBB------BBBB-------- --------AAAA------AAAA-------- --------AAAAA----AAAAA-------- --------AAAAA----AAAAA-------- ---------AAAAA--AAAAA--------- ---------AAAAAAAAAAAA--------- ---------AA--------AA--------- ---------AAAAAAAAAAAA--------- 
AAAAAAAAAA----------AAAAAAAAAA -------BBB----------BBB------- -------BBBB--------BBBB------- --------AAA--------AAA-------- --------AAA--------AAA-------- --------AAA--------AAA-------- --------AAA--------AAA-------- --------AAAAAAAAAAAAAA-------- ---------A----------A--------- ---------AAAAAAAAAAAA--------- 
AAAAAAAAAA----------AAAAAAAAAA -------BBB----------BBB------- -------BBB----------BBB------- -------AAA----------AAA------- -------AAAA--------AAAA------- --------AAA--------AAA-------- --------AAA--------AAA-------- --------AAAAAAAAAAAAAA-------- --------AA----------AA-------- ---------AAAAAAAAAAAA--------- 
AAAAAAAAA------------AAAAAAAAA -------BBB----------BBB------- -------BBB----------BBB------- -------AAA----------AAA------- -------AAA----------AAA------- -------AAA----------AAA------- -------AAAA--------AAAA------- --------AAAAAAAAAAAAAA-------- --------AA----------AA-------- --------AAAAAAAAAAAAAA-------- 
AAAAAAAAA------------AAAAAAAAA -------BB------------BB------- -------BB------------BB------- -------AAA----------AAA------- -------AAA----------AAA------- -------AAA----------AAA------- -------AAA----------AAA------- -------AAAAAAAAAAAAAAAA------- -------AA------------AA------- --------AAAAAAAAAAAAAA-------- 
AAAAAAAAA------------AAAAAAAAA -------BB------------BB------- -------BC------------BB------- -------AAA----------AAA------- -------AAA----------AAA------- -------AAA----------AAA------- -------AAA----------AAA------- -------AAAAAAAAAAAAAAAA------- -------AA------------AA------- --------AAAAAAAAAAAAAA-------- 
AAAAAAAAA------------AAAAAAAAA -------BBB----------BBB------- -------BCC----------BBB------- -------AAA----------AAA------- -------AAA----------AAA------- -------AAA----------AAA------- -------AAAA--------AAAA------- --------AAAAAAAAAAAAAA-------- --------AA----------AA-------- --------AAAAAAAAAAAAAA-------- 
AAAAAAAAAA----------AAAAAAAAAA -------BBB----------BBB------- -------BCC----------BBB------- -------AAA----------AAA------- -------AAAA--------AAAA------- --------AAA--------AAA-------- --------AAA--------AAA-------- --------AAAAAAAAAAAAAA-------- --------AA----------AA-------- ---------AAAAAAAAAAAA--------- 
AAAAAAAAAA----------AAAAAAAAAA -------BBB----------BBB------- -------BBBB--------BBBB------- --------AAA--------AAA-------- --------AAA--------AAA-------- --------AAA--------AAA-------- --------AAA--------AAA-------- --------AAAAAAAAAAAAAA-------- ---------A----------A--------- ---------AAAAAAAAAAAA--------- 
-AAAAAAAAAA--------AAAAAAAAAA- --------BBB--------BBB-------- --------BBBB------BBBB-------- --------AAAA------AAAA-------- --------AAAAA----AAAAA-------- --------AAAAA----AAAAA-------- ---------AAAAA--AAAAA--------- ---------AAAAAAAAAAAA--------- ---------AA--------AA--------- ---------AAAAAAAAAAAA--------- 
-AAAAAAAAAAAA----AAAAAAAAAAAA- --------BBBBBB--BBBBBB-------- --------BBBBBB--BBBBBB-------- --------AAAAAAAAAAAAAA-------- ---------AAAAAAAAAAAA--------- ---------AAAAAAAAAAAA--------- ---------AAAAAAAAAAAA--------- ---------AAAAAAAAAAAA--------- ----------AAAA--AAAA---------- ----------AAAAAAAAAA---------- 
--AAAAAAAAAAAAAAAAAAAAAAAAAA-- --------BBBBBBBBBBBBBB-------- ---------BBBBBBBBBBBB--------- ---------AAAAAAAAAAAA--------- ----------AAAAAAAAAA---------- ----------AAAAAAAAAA---------- -----------AAAAAAAA----------- -----------AAAAAAAA----------- ------------AAAAAA------------ -------------AAAA------------- 
--AAAAAAAAAAAAAAAAAAAAAAAAAA-- -----------BBBBBBBB----------- -----------BBBBBBBB----------- ------------AAAAAA------------ ------------AAAAAA------------ -------------AAAA------------- -------------AAAA------------- --------------AA-------------- --------------AA-------------- ------------------------------ 
--AAAAAAAAAAAAAAAAAAAAAAAAAA-- ------------------------------ ------------------------------ ------------------------------ ------------------------------ ------------------------------ ------------------------------ ------------------------------ ------------------------------ ------------------------------ 
---AAAAAAAAAAAAAAAAAAAAAAAA--- ------------------------------ ------------------------------ ------------------------------ ------------------------------ ------------------------------ ------------------------------ ------------------------------ ------------------------------ ------------------------------ 
---AAAAAAAAAAAAAAAAAAAAAAAA--- ------------------------------ ------------------------------ ------------------------------ ------------------------------ ------------------------------ ------------------------------ ------------------------------ ------------------------------ ------------------------------ 
----AAAAAAAAAAAAAAAAAAAAAA---- ------------------------------ ------------------------------ ------------------------------ ------------------------------ ------------------------------ ------------------------------ ------------------------------ ------------------------------ ------------------------------ 
------AAAAAAAAAAAAAAAAAA------ ------------------------------ ------------------------------ ------------------------------ ------------------------------ ------------------------------ ------------------------------ ------------------------------ ------------------------------ ------------------------------ 
---------AAAAAAAAAAAA--------- ------------------------------ ------------------------------ ------------------------------ ------------------------------ ------------------------------ ------------------------------ ------------------------------ ------------------------------ ------------------------------ 
-----------AAAAAAAA----------- ------------------------------ ------------------------------ ------------------------------ ------------------------------ ------------------------------ ------------------------------ ------------------------------ ------------------------------ ------------------------------ 
