model
size = 16 6 29, scale = 0.05, origin = -y
material 
  colors = A:#111 B:#222 C:#0F0 D:#444 E:#EEE F:#E00 G:#FF0 H:#D00
voxels
---------------- ------A--A------ -----DD--DD----- ---------------- ---------------- ---------------- 
------C--C------ -----AAAAAA----- ----DDBDDBDD---- --BBB------BBB-- --B-B------B-B-- --BBB------BBB-- 
-----CCCCCC----- ----AAAAAAAA---- ----DBBBBBBD---- ---A--------A--- --AHA------AHA-- ---A--------A--- 
-----CCCCCC----- ----AAAAAAAA---- DDDDDBBBBBBDDDDD ---DD------DD--- ---D--------D--- ---------------- 
-----CCCCCC----- ----AAAAAAAA---- -DDDDBBBBBBDDDD- ----D------D---- ---------------- ---------------- 
-----CCDDCC----- ----AAAAAAAA---- --DDDBEBBEBDDD-- ---------------- ---------------- ---------------- 
-----CDFGDC----- ----AAAAAAAA---- ----DBBBBBBD---- ---------------- ---------------- ---------------- 
-----CDGFDC----- ----AAAAAAAA---- ----DBEBBEBD---- ---------------- ---------------- ---------------- 
-----CCDDCC----- ----AAAAAAAA---- ----DBBBBBBD---- ---------------- ---------------- ---------------- 
-----CCCCCC----- ----AAAAAAAA---- ----DBBBBBBD---- ---------------- ---------------- ---------------- 
-----CCCCCC----- ----AAAAAAAA---- ----DBBBBBBD---- ---------------- ---------------- ---------------- 
-----CCCCCC----- ----AAAAAAAA---- ----DBBBBBBD---- ---------------- ---------------- ---------------- 
-----CCCCCC----- ----AAAAAAAA---- ----DBBBBBBD---- ---------------- ---------------- ---------------- 
-----CCCCCC----- ----AAAAAAAA---- ----DBBBBBBD---- ---------------- ---------------- ---------------- 
-----CCCCCC----- ----AAAAAAAA---- ----DBBBBBBD---- ---------------- ---------------- ---------------- 
-----CCCCCC----- ----AAAAAAAA---- ----DBBBBBBD---- ---------------- ---------------- ---------------- 
-----CCCCCC----- ----AAAAAAAA---- ----DBBBBBBD---- ---------------- ---------------- ---------------- 
-----CCDDCC----- ----AAAAAAAA---- ----DBBBBBBD---- ---------------- ---------------- ---------------- 
-----CDFGDC----- ----AAAAAAAA---- ----DBBBBBBD---- ---------------- ---------------- ---------------- 
-----CDGFDC----- ----AAAAAAAA---- ----DBEBBEBD---- ---------------- ---------------- ---------------- 
-----CCDDCC----- ----AAAAAAAA---- ----DBBBBBBD---- ---------------- ---------------- ---------------- 
-----CCCCCC----- ----AAAAAAAA---- ----DBEBBEBD---- ---------------- ---------------- ---------------- 
-----CCCCCC----- ----AAAAAAAA---- ----DBBBBBBD---- ---------------- ---------------- ---------------- 
-----CCCCCC----- ----AAAAAAAA---- ----DBBBBBBD---- ---------------- ---------------- ---------------- 
------CCCC------ ----AAAAAAAA---- ----DBBBBBBD---- ---------------- ---------------- ---------------- 
------CCCC------ -----AAAAAA----- ----DBBBBBBD---- ---------------- ---------------- ---------------- 
-------CC------- -----AAAAAA----- ----DDBBBBDD---- ---------------- ---------------- ---------------- 
---------------- ------AAAA------ -----DBBBBD----- ---------------- ---------------- ---------------- 
---------------- ---------------- ------DDDD------ ---------------- ---------------- ---------------- 
