model
size = 31 31 8, scale = 0.05, origin = -y
material 
  colors = A:#EEE B:#C30 C:#888 D:#777 E:#222 F:#444 G:#0C6 H:#AAA I:#111 J:#FF6 K:#DDD L:#39C M:#F90 N:#96C
voxels
------------------------------- ------------------------------- ----EEEEEEEEEEEEEEEEEEEEEEE---- ----EAAAAAAAAAAAAAAAAAAAAAE---- ----EA--AA-A-AA-AA--AA-A-AE---- ----EAAA-A---AA-AA-A-A-A-AE---- ----EA---A-A-AA-AA-A-A--AAE---- ----EA-AAA-A-AA-AA-A-A-A-AE---- ----EAA--AA--A---AA--A---AE---- ----EAAAAAAAAAAAAAAAAAAAAAE---- ----EEEEEEEEEEEEEEEEEEEEEEE---- ------------------------------- ------------------------------- ------------------------------- ------------------------------- ------------------------------- ------------------------------- ------------------------------- ------------------------------- ------------------------------- ------------------------------- ------------------------------- ------------------------------- ------------------------------- ------------------------------- ------------------------------- ------------------------------- ------------------------------- ------------------------------- ------------------------------- ------------------------------- 
------------------------------- ------------------------------- ------------------------------- ------CCAAAAAAAAAAAAAAACC------ ------FFAAFAFAAFAAFFAAFAF------ ------CAFAFFFAAFAAFAFAFAF------ ------FFFAFAFAAFAAFAFAFFC------ ------FAAAFAFAAFAAFAFAFAF------ ------CFFAAFFAFFFAAFFAFFF------ ------CAAAAAAAAAAAAAAAAAC------ ------CC---------------CC------ ------CC---------------CC------ ------CC---------------CC------ ------CC---------------CC------ ------CC---------------CC------ ------CC---------------CC------ ------------------------------- ------------------------------- ------------------------------- ------------------------------- ------------------------------- ------------------------------- ------------------------------- ------------------------------- ------------------------------- ------------------------------- ------------------------------- ------------------------------- ------------------------------- ------------------------------- ------------------------------- 
------------------------------- ---------D-----------D--------- -------CDD-----------DDC------- ------CCDD-----------DDC------- -----HCCDD-----------DDCCH----- ----HHCCDD-----------DDCCHH---- ----HHCCDD-----------DDCCHH---- ----HHCCDD-----------DDCCHH---- ----HHCCDD-----------DDCCHH---- ----HHCCDD-----------DDCCHH---- ----HHCCDD-----------DDCCHH---- ----HHCCDD-----------DDCCHH---- ----HHCCDD-----------DDCCHH---- ----HHCCDD-----------DDCCHH---- ----HHCCDD-----------DDCCHH---- ----HHCCDD-----------DDCCHH---- ------G-----------------G------ -------G---------------G------- ------G-G-------------G-G------ -------G---------------G------- --------G-------------G-------- ---------G-----------G--------- ----------G-G-----G-G---------- -----------G-G-G-G-G----------- ------------G-G-G-G------------ ------------------------------- ------------------------------- ------------------------------- ------------------------------- ------------------------------- ------------------------------- 
------------------------------- ---------DFF-------FFD--------- -------CDDFF-------FFDDC------- ------CCDDFF-------FFDDC------- -----HCCDDFF-------FFDDCCH----- ----HHCCDDFF-------FFDDCCHH---- ---KHHCCDDFF-------FFDDCCHHK--- --KKHHCCDDFF-------FFDDCCHHKK-- --KKHHCCDDFF-------FFDDCCHHKK-- --KKHHCCDDFF-------FFDDCCHHKK-- --KKHHCCDDFF-------FFDDCCHHKK-- --KKHHCCDDFF-------FFDDCCHHKK-- --KKHHCCDDFF-------FFDDCCHHKK-- --KKHHCCDDFF-------FFDDCCHHKK-- --KKHHCCDDFF-------FFDDCCHHKK-- --KKHHCCDDFF-------FFDDCCHHKK-- ----J-GGL-------------LGG-J---- -----JGG-L-----------L-GGJ----- ----J-GGG-L---------L-GGG-J---- -----J-GGL-L-------L-LGG-J----- ------JGGGL-L-----L-LGGGJ------ -------JGGGL-L-L-L-LGGGJ------- ------J-JGGGG-L-L-GGGGJ-J------ -------J-JGGGGGGGGGGGJ-J------- --------J-J-GGGGGGG-J-J-------- -----------J-J-J-J-J----------- ------------J-J-J-J------------ ------------------------------- ------------------------------- ------------------------------- ------------------------------- 
------------EE---EE------------ ---------DFFEE---EEFFD--------- -------CDDFFEE---EEFFDDC------- ------CCDDFFEE---EEFFDDC------- -----HCCDDFFEE---EEFFDDCCH----- ----HHCCDDFFEE---EEFFDDCCHH---- ---KHHCCDDFFEE---EEFFDDCCHHK--- --KKHHCCDDFFEE---EEFFDDCCHHKK-- --KKHHCCDDFFEE---EEFFDDCCHHKK-- -AKKHHCCDDFFEE---EEFFDDCCHHKKA- -AKKHHCCDDFFEE---EEFFDDCCHHKKA- -AKKHHCCDDFFEE---EEFFDDCCHHKKA- AAKKHHCCDDFFEE---EEFFDDCCHHKKAA AAKKHHCCDDFFE-----EFFDDCCHHKKAA AAKKHHCCDDFF--III--FFDDCCHHKKAA AAKKHHCCDDFF--III--FFDDCCHHKKAA --M-JJGGLLN---IIA---NLLGGJJ-M-- ---MJJGGLL-N-------NNLLGGJJM--- --M-JJGGGLL-N-----N-LLGGGJJ-M-- ---M-JJGGLLL-N-N-N-LLLGGJJ-M--- ----MJJGGGLLL-N-N-LLLGGGJJM---- ---M-MJJGGGLLLLLLLLLGGGJJM-M--- ----M-JJJGGGGLLLLLGGGGJJJ-M---- -----M-JJJGGGGGGGGGGGJJJ-M----- ------M-JJJJGGGGGGGJJJJ-M------ -------M-MJJJJJJJJJJJM-M------- --------M-M-JJJJJJJ-M-M-------- ---------M-M-M-M-M-M-M--------- ------------M-M-M-M------------ ------------------------------- ------------------------------- 
------------EEIIIEE------------ ---------AAAEEIIIEEAAA--------- -------AAAAAEEIIIEEAAAAA------- ------AAAAAAEEIIIEEAAAAAA------ -----AAAAAAAEEIIIEEAAAAAAA----- ----AAAAAAAAEEIIIEEAAAAAAAA---- ---AAAAAAAAAEEIIIEEAAAAAAAAA--- --AAAAAAAAAAEEIIIEEAAAAAAAAAA-- --AAAAAAAAAAEEIIIEEAAAAAAAAAA-- -AAAAAAAAAAAEEIIIEEAAAAAAAAAAA- -AAAAAAAAAAAEEIIIEEAAAAAAAAAAA- -AAAAAAAAAAAEEIIIEEAAAAAAAAAAA- AAAAAAAAAAAAEE---EEAAAAAAAAAAAA AAAAAAAAAAAAE-III-EAAAAAAAAAAAA AAAAAAAAAAAA-IIIII-AAAAAAAAAAAA AAAAAAAAAAAA-IIIII-AAAAAAAAAAAA B-BBBBAAAAAN-IIIAI-NAAAAABBBB-B -BBBBBAAAANAN-III-NAAAAAABBB-B- B-BBBBAAAAANAN---NANAAAAABBBB-B -B-BBBBAAAAANANANANAAAAABBBB-B- --BBBBBAAAAAANANANAAAAAABBB-B-- -B-BBBBBAAAAAAAAAAAAAAABBBBB-B- --B-BBBBBAAAAAAAAAAAAABBBBB-B-- ---B-BBBBBAAAAAAAAAAABBBBB-B--- ----B-BBBBBBAAAAAAABBBBBB-B---- -----B-BBBBBBBBBBBBBBBBB-B----- ------B-BBBBBBBBBBBBBBB-B------ -------B-B-BBBBBBBBB-B-B------- --------B-B-B-B-B-B-B-B-------- ---------B-B-B-B-B-B-B--------- ------------B-B-B-B------------ 
------------AAIIIAA------------ ---------AAAAAIIIAAAAA--------- -------AAAAAAAIIIAAAAAAA------- ------AAAAABBBIIIAAAAAAAA------ -----AAAAAABBBIIIAAAAAAAAA----- ----AAAAAAABBBIIIAAAAAAAAAA---- ---AAAABBBBBBBIIIAAAAAAAAAAA--- --AAAAABBBBBBBIIIBBBBBBBBBBAA-- --AAAAABBBBBBBIIIBBBBBBBBBBAA-- -AAAAAABBBBBBBIIIBBBBBBBBBBAAA- -AAAAAABBBBBBBIIIBBBBBBBBBBAAA- -AAAAAABBBBBBBIIIBBBBBBBBBBAAA- AAAAAAABBBBBBBAAABBBBBBBBBBAAAA AAAAAAABBBBBBAIIIABBBBBBBBBAAAA AAAAAAABBBBBAIIIIIABBBBBBBBAAAA AAAAAAABBBBBAIIIIIABBBBBBBBAAAA BBBBBBBBBBBBAIIIAIABBBBBBBBBBBB BBBBBBBBBBBBBAIIIABBBBBBBBBBBBB BBBBBBBBBBBBBBAAABBBBBBBBBBBBBB -BBBBBBBBBBBBBBBBBBBBBBBBBBBBB- -BBBBBBBBBBBBBBBBBBBBBBBBBBBBB- -BBBBBBBBBBBBBBBBBBBBBBBBBBBBB- --BBBBBBBBBBBBBBBBBBBBBBBBBBB-- --BBBBBBBBBBBBBBBBBBBBBBBBBBB-- ---BBBBBBBBBBBBBBBBBBBBBBBBB--- ----BBBBBBBBBBBBBBBBBBBBBBB---- -----BBBBBBBBBBBBBBBBBBBBB----- ------BBBBBBBBBBBBBBBBBBB------ -------BBBBBBBBBBBBBBBBB------- ---------BBBBBBBBBBBBB--------- ------------BBBBBBB------------ 
------------AAAAAAA------------ ---------AAAAAAAAAAAAA--------- -------AAAAAAAAAAAAAAAAA------- ------AAAAAAAAAAAAAAAAAAA------ -----AAAAAAAAAAAAAAAAAAAAA----- ----AAAAAAAAAAAAAAAAAAAAAAA---- ---AAAAAAAAAAAAAAAAAAAAAAAAA--- --AAAAAAAAAAAAAAAAAAAAAAAAAAA-- --AAAAAAAAAAAAAAAAAAAAAAAAAAA-- -AAAAAAAAAAAAAAAAAAAAAAAAAAAAA- -AAAAAAAAAAAAAAAAAAAAAAAAAAAAA- -AAAAAAAAAAAAAAAAAAAAAAAAAAAAA- AAAAAAAAAAAAAAAAAAAAAAAAAAAAAAA AAAAAAAAAAAAAAAAAAAAAAAAAAAAAAA AAAAAAAAAAAAAAAAAAAAAAAAAAAAAAA AAAAAAAAAAAAAAAAAAAAAAAAAAAAAAA AAAAAAAAAAAAAAAAAAAAAAAAAAAAAAA AAAAAAAAAAAAAAAAAAAAAAAAAAAAAAA AAAAAAAAAAAAAAAAAAAAAAAAAAAAAAA -AAAAAAAAAAAAAAAAAAAAAAAAAAAAA- -AAAAAAAAAAAAAAAAAAAAAAAAAAAAA- -AAAAAAAAAAAAAAAAAAAAAAAAAAAAA- --AAAAAAAAAAAAAAAAAAAAAAAAAAA-- --AAAAAAAAAAAAAAAAAAAAAAAAAAA-- ---AAAAAAAAAAAAAAAAAAAAAAAAA--- ----AAAAAAAAAAAAAAAAAAAAAAA---- -----AAAAAAAAAAAAAAAAAAAAA----- ------AAAAAAAAAAAAAAAAAAA------ -------AAAAAAAAAAAAAAAAA------- ---------AAAAAAAAAAAAA--------- ------------AAAAAAA------------ 
