model
size = 32 23 32, scale = 0.05, origin = -y
material 
  colors = A:#DAA520 B:#9CF C:#BBB D:#800000 E:#F90 F:#060 G:#006 H:#909 I:#6FF J:#FF0 K:#C00 L:#0F0 M:#606 N:#6C0 O:#F3F P:#C6C Q:#FC0 R:#90F S:#03C T:#F00 U:#609 V:#06F W:#F0F X:#C03
voxels
13-6C25-2C4-2C21-4C6-4C24-2D29-DK2D28-DTKD28-D2KD28-2DTD29-2D472-14A18-14A16-2C14A2C16-14A21-6(8A24-)8A403-18A14-18A13-C18AC13-18A16-14A21-5(8A24-)8A25-6A27-4A340-20A12-20A11-C20AC11-20A14-A4-6A4-A16-C4-6A4-C21-6A26-6A25-3(8A24-)8A25-6A338-5A12-5A10-5A12-5A9-C5A12-5AC9-2(5A12-)2(A16-A14-)C16-C115-8A24-8A25-6A27-4A306-5A14-5A8-5A14-5A7-C5A14-5AC7-5A14-5A10-3(A18-A12-)C18-C12-C18-C50-8A24-8A25-6A26-6A304-5A16-5A6-5A16-5A5-C5A16-5AC5-5A16-5A8-3(A20-A10-)C20-C10-C20-C11-2C16-2C19-6A25-8A24-8A25-6A303-5A18-5A4-5A18-5A3-C5A18-5AC3-5A18-5A6-2(A22-A8-)C22-C74-2C16-2C13-2C4-6A4-2C19-8A24-8A25-6A303-4A20-4A4-4A20-4A3-C4A20-4AC3-4A20-4A5-A24-A6-C24-C138-2C4-6A4-2C15-2C2-8A2-2C20-8A24-8A25-6A270-4A22-4A2-4A22-4A-C4A22-4AC-4A22-4A3-A26-A175-6A21-3C-8A-3C20-8A24-8A25-6A270-3A24-3A2-3A24-3A-C3A24-3AC-3A24-3A3-A26-A175-6A22-3C8A3C21-8A24-8A25-6A270-3A24-3A2-3A24-3A-C3A24-3AC-3A24-3A3-A26-A175-6A23-2C8A2C22-8A24-8A25-6A270-3A24-3A-C3A24-3A2C3A24-3AC-3A24-3A4(2-2A26-2A)2(2-3A24-3A)2-5A6-8A6-5A4-26A9-10A4B6A14-8A3B5A21-6A27-4A27-6A25-3A2-3A2(24-A6-A)108-C3A24-3A2C3A24-3AC-8(3A24-3A2-)30A3-28A5-5A12B9A8-3A12B7A13-6A4B6A21-A4BA25-2A4B2A24-2AB2DB2A25-6D141-C3A24-3AC-2(3A24-3A2-)3A24-3A-4(E3A24-3AF)-2(3A24-3A2-)30A3-28A4-6A12B10A6-4A12B8A12-6A4B6A20-A5B2(2A24-2A4B)2A25-6D60-HP30-HS47-C3A24-3AC-3A24-3A2-3A24-3A-E3A24-3AFQ3A24-3ANJ3A24-3ALQ3A24-3ALE3A24-3ANE3A24-3AF-3A24-3A2-30A3-28A4-11A7B10A6-9A7B8A12-6A4B6A20-A5B2A24-2A4B2A25-D4BD26-2D2B2D28-HO29-H2BS28-R2BP29-MR15-C3A24-3AC-3A24-3A2-3A24-3A-E2(3A24-3AFJ)3A24-3ANJ3A24-3ALQ3A24-3ALE3A24-3AF-3A24-3A2-30A3-28A4-11A7B10A6-9A7B8A12-6A4B6A20-A5B2A24-2A4B2A25-D4BD26-6D28-UO29-R2BO28-H2BP29-2M15-C3A24-3AC-2(3A24-3A2-)3A24-3A-4(E3A24-3AF)-2(3A24-3A2-)30A3-28A4-11A7B10A6-9A7B8A12-6A4B6A20-A5B2(2A24-2A4B)2A25-6D60-XW30-UW47-C3A24-3A2C3A24-3AC-8(3A24-3A2-)30A3-28A5-10A7B9A8-8A7B7A13-6A4B6A21-A4BA25-2A4B2A24-3A2DB2A25-6D142-3A24-3A-C3A24-3A2C3A24-3AC-3A24-3A4(2-2A26-2A)2(2-3A24-3A)2-5A6-8A6-5A4-26A9-7A6B7A14-5A6B5A21-A4BA27-4A27-6A25-3A2-3A2(24-A6-A)109-3A24-3A2-3A24-3A-C3A24-3AC-3A24-3A3-A26-A175-6A23-2C8A2C22-2A5BA24-2A5BA25-6A270-3A24-3A2-3A24-3A-C3A24-3AC-3A24-ABA3-A26-A175-6A22-3C8A3C21-2A5BA24-2A5BA25-6A270-4A22-4A2-4A22-4A-C4A22-4AC-4A22-4A3-A26-A175-6A21-3C-8A-3C20-2A5BA24-2A5BA25-6A271-4A20-4A4-4A20-4A3-C4A20-4AC3-4A20-4A5-A24-A6-C24-C138-2C4-6A4-2C15-2C2-8A2-2C20-2A5BA24-2A5BA25-6A271-5A18-5A4-5A18-5A3-C5A18-5AC3-5A18-5A6-2(A22-A8-)C22-C74-2C16-2C13-2C4-6A4-2C19-8A24-8A25-6A304-5A16-5A6-5A16-5A5-C5A16-5AC5-5A16-5A8-3(A20-A10-)C20-C10-C20-C11-2C16-2C19-6A25-8A24-8A25-6A305-5A14-5A8-5A14-5A7-C5A14-5AC7-5A14-5A10-3(A18-A12-)C18-C12-C18-C50-8A24-8A25-6A26-6A306-5A12-5A10-5A12-5A9-C5A12-5AC9-2(5A12-)2(A16-A14-)C16-C115-8A24-8A25-6A27-4A308-20A12-20A11-C20AC11-20A14-A4-6A4-A16-C4-6A4-C21-6A26-6A25-3(8A24-)8A25-6A340-18A14-13A3B2A13-C17ABC13-18A16-14A21-5(8A24-)8A25-6A27-4A343-14A18-14A16-2C14A2C16-14A21-6(8A24-)8A409-6C25-2C4-2C21-4C6-4C24-2G29-GVI2(G28-G2I)G28-2GVG29-2G463-
