model
size = 29 24 19, scale = 0.05, origin = -y
material 
  colors = A:#693 B:#100 C:#363 D:#933 E:#963 F:#FFF G:#EEE H:#BBB I:#393 J:#360
voxels
----------------------------- ----------------------------- ----------------------------- ----------------------------- ----------------------------- ---------------DDDDDDDDDD---- ----------------------------- ---------------EEEEEEEEEE---- ----------------BBBBBBBBB---- ----------------AAAAAAAAA---- -----------------AAAAAAA----- ------------------AAAAA------ ----------------------------- --------------CCCCC---CCCCC-- --------------GBGBB---GBGBB-- --------------GBBGB---GBBGB-- --------------GGBBG---GGBBG-- ---------------CCCC---CCCCC-- ----------------------------- ----------------------------- ----------------------------- ----------------------------- ----------------------------- ----------------------------- 
----------------------------- ----------------------------- ----------------------------- --------------AAAAAAAAA------ --------AAAAAAABBBBBBBBBB---- -------AABBBBBBDDDDDDDDDDD--- -------ABDDDDDD-BBBBBBBBB---- -------AABBBBBBEEEEEEEEEEE--- --------AAEEEEEEBBBBBBBBBB--- ----------ABBBBBAAAAAAAAAA--- -------------AAAAAAAAAAAA---- ------------------AAAAA------ ------------AAAAAA-AAA-AAA--- ----------AACCCCCCCBABCCCCCC- ---------ACCGGGBBBBGBGGBBBBG- ---------AACGGGBBBBGBGGBBBBG- -----------AACGGBBGGBCGGBBGG- -----------BBAACCCCBBCCCCCC-- -------------BBAAAABCCAABB--- ---------------BBBB-BBBB----- ----------------------------- ----------------------------- ----------------------------- ----------------------------- 
----------------------------- ----------------------------- ----------------------------- ------ABBAAAAAAAAAAAAAAB----- ----CABBAAAAAAABBBBBBCCAB---- ----CABACCCCCCCDDDDDDDDDDD--- ----AAAABDDDDDDBBBBBBBBBB---- ---AAAAAABEEEEEEBBBBBBBBBE--- ---AAAAAAAEEEEEEBBBBBBBBBB--- ---AAAAAAAAAAAAAAAAAAAAAAA--- ---AAAAAAAAAAAAAAAAAAAAAAA--- ---AAAAAAAAAAAABBBAAAAABBB--- ---AAAAAAAAAAABBBBBAAABBBBA-- ----AAAAAAAACCCCCCCBABCCCCJC- ----AAAAAACCFFFBHBBFBGGBHBBG- ------AAAAACFFFBBGBFBGGBBGBG- ------AAAAAAACFFBBFFBCGGBBGG- --------AAABBAACCCCBBCCCCCC-- --------AAAAABBAAAABCCAABBA-- --------CAAAAAABBBBCBBBBA---- ---------CAAAAAA---CAAAA----- ----------------------------- ----------------------------- ----------------------------- 
----------------------------- ----------------------------- -------CCCCCCCCCCCCCCC------- ------CAAAAAAAAAAAAAAABB----- ----CCABAAAAAAABBBBBBCCCBB--- ---CAABAABBBBBBDDDDDDDDDDD--- ---CAAAABDDDDDDEEEEEEEEEBB--- --CAAAAAABEEEEEEBBBBBBBBBBE-- --CAAAAAAABBBBBAAAAAAAAAABB-- --CAAAAAAAAAAAAAAAAAAAAAAAA-- --CAAAAAAAAAAAAAAAAAAAAAAA--- ---CAAAAAAAAAAAAAAAAAAAAAB--- ---CCAAAAAAAAABBBBBAAABBBAA-- ----CCAAAAAACCCCCCCBABACCCJC- ----CCAAAACCFFFBHBBFBGGBHBBG- -----BAAAAACFFFBBGBFBGGBBGBG- -----BAAAAAAACFFBBFFBCGGBBGG- ------BCAAABBAACCCCBBCCCCCC-- -------CAAAAABBAAAABAACCBBA-- -------CCAAAAAABBBBCBBBBAA--- ---------CAAAAAAAACCAAAAA---- ----------AAAAAAA--AAAAA----- ----------------------------- ----------------------------- 
----------------------------- -------CCCCCCCCCCCCC--------- -----CCAAAAAAAAAAAAACB------- ---CCCAABBAAAAAAAAAACCBB----- --CCAAABAAAAAAABBBBBBCCBBB--- --CAAABAABBBBBBDDDDDDDDDDD--- --CAAAAABDDDDDDEEEEEEEEEEB--- -CAAAAAAABEEEEEEBBBBBBBBBBE-- -CAAAAAAAABBBBBAAAAAAAAAAAB-- -CAAAAAAAAAAAAAAAAAAAAAAAAA-- -CAAAAAAAAAAAAAAAAAAAAAAAA--- --CAAAAAAAAAAAAAAAAAAAAAAAB-- --CCAAAAAAAAAABBBBBAAABBBABB- --CCAAAAAAAACCCCCCCBABACCCAB- ---CAAAAAACCFFFBHBBFBGGBHBCCB -----CBAAAACFFFBBGBFBGGBBGCCB -----CBAAAAAACFFBBFFBCGGBBCCB ------CAAAABBAACCCCBBCCCCCAB- ------BAAAAAABBAAAABAACCBBAB- -------CCAAAAAABBBBCBBBBAAB-- --------CCAAAAAAAACAAAAAAB--- ---------CAAAAAAACCAAAAAB---- ----------CAAAAA---AAAAB----- ----------------------------- 
-------BBBBBBBBBBBBB--------- -----BBAAAAAAAAAAAAABBB------ ---BBAAAAAAAAAAAAAAAAABB----- --BAAAAABBAAAAAAAAAAAIIB----- -BAAAAABAAAAAAABBBBBBCCBBB--- -CAAAABAABBBBBBDDDDDDDDDDD--- -CAAAAAABDDDDDDEEEEEEEEEEB--- -CAAAAAAABEEEEEEBBBBBBBBBBE-- -CAAAAAAAABBBBBAAAAAAAAAAAB-- -CAAAAAAAAAAAAAAAAAAAAAAAAA-- -CAAAAAAAAAAAAAAAAAAAAAAABB-- --CAAAAAAAAAAAAAAAAAAAAAAB--- --CAAAAAAAAAAABBBBBAAABBBBB-- --CCAAAAAAAACCCCCCCBABACCCAB- ---CAAAAAACCFFFBHBBFBGGBHBACB ----CAAAAAACFFFBBGBFBGGBBGACB ----CAAAAAAAACFFBBFFBCGGBBACB -----CBAAAABBAACCCCBBCCCCCAC- ------BAAAAAABBAAAABAACCBBAB- ------BAAAAAAAABBBBCBBBBAAB-- -------BBBBAAAAAAACAAAAAAAB-- --------BBBAAAAAACAAAAAAAB--- ---------BBAAAABBBBAAAAAB---- ----------BBBBB----BBBBB----- 
-------BCCCCCCCCCCCB--------- -----BBCCCCCCCCCCCCCBBB------ ---BBBBAAAAAAAAAAAAAAAAB----- --CCCCAABBAAAAAAAAAAAIIB----- -BCCCCABAAAAAAABBBBBBCCBBB--- BAAAAABAABBBBBBDDDDDDDDDDDB-- BAAAAAAABDDDDDDEEEEEEEEEEBBB- BAAAAAAAABEEEEEEBBBBBBBBBBBB- BAAAAAAAAABBBBBAAAAAAAAAAABB- BAAAAAAAAAAAAAAAAAAAAAAAAAB-- BAAAAAAAAAAAAAAAAAAAAAAAAB--- -BAAAAAAAAAAAAAAAAAAAAAAAB--- -BAAAAAAAAAAAABBBBBAAABBBBB-- -BBAAAAAAAAACCCCCCCBABACCCAB- -BBAAAAAAACCFFFBHBBFBGGBHBACC --BBAAAAAAACFFFBBGBFBGGBBGACC ---BAAAAAAAAACFFBBFFBCGGBBACC ----BBBAAAABBAACCCCBBCCCCCAB- -----BBAAAAAABBAAAAAAAAAAAAC- ------BAAAAAAAABBBBAAAAACCB-- ------BAAAAAAAAAAACAAAAACCC-- -------BAAAAAAACCAAAAAAACB--- --------BCCCCCCBBBBCCCCCC---- ----------BCBCB----BCBCB----- 
------BBCCCCCCCCCCCBB-------- -----BBCCCCCCCCCCCCCBBC------ ---BBBBAAAAAAAAAAAAAAAAB----- --BCCCAABBAAAAAAAAAAAIIB----- -CCCCCABAAAAAAABBBBBBCCBBB--- BCCCCCCCCBBBBBBDDDDDDDDDDDB-- CCCCCCCCCDDDDDDEEEEEEEEEEBB-- BCCCCCCCCBEEEEEEBBBBBBBBBBB-- CCCCCCCCCABBBBBAAAAAAAAAAAB-- BCCCCCCCCAAAAAAAAAAAAAAAAAB-- BCCCCCCCCAAAAAAAAAAAAAAAAB--- -BCCCCCCCAAAAAAAAAAAAAAAAB--- -CCCCCCCCAAAAABBBBBAAABBBBB-- -BCCCCCCCAAACCCCCCCBABACCAAC- -BCCCCCCCACCFFFBHBBFBGGBHAAC- --BCCCCCCAACFFFBBGBFBGGBBAAC- ---CCCCCCAAAACFFBBFFBCGGBAAC- ----BBBCCAABBAACCCCBBCCCCAAC- -----BBCCAAAABBAAAAAAAAAAAAC- ------BCCAAAAAABBBBAAAAACCC-- ------BCCAAAAAAAAACAAAAACB--- -------BCAAAAAACBBAAAAAACC--- --------CBCCCCCB--BCCCCCB---- ----------CBCBC----CBCBC----- 
------BCCCCCCCCCCCCCB-------- -----BCCCCCCCCCCCCCCCCB------ ---BBCAAAAAAAAAAAAAAAAAC----- --CCCCAABBAAAAAAAAAAAIIB----- -BCCCCABAAAAAAABBBBBBCCCCC--- CCCCCCCCCBBBBBBDDDDDDDDDDCB-- BCCCCCCCCDDDDDDEEEEEEEEEECC-- CCCCCCCCCBEEEEEEBBBBBBBBBCB-- BCCCCCCCCABBBBBAAAAAAAAAACC-- CCCCCCCCCAAAAAAAAAAAAAAAAB--- BCCCCCCCCAAAAAAAAAAAAAAAAC--- -CCCCCCCCAAAAAAAAAAAAAAAAB--- -BCCCCCCCAAAAABBBBBAAABBBAC-- -CCCCCCCCAAACCCCCCCBABACCAA-- -BCCCCCCCACCFFFBHBBFBGGBHAAC- --CCCCCCCAACFFFBBGBFBGGBBAAA- ---BCCCCCAAAACFFBBFFBCGGBAAC- ----BBBCCAABBAACCCCBBCCCCAAA- -----BBCCAAAABBAAAAAAAAAAAA-- ------BCCAAAAAABBBBAAAAACCC-- ------BCCAAAAAAAAACAAAAACC--- -------CCAAAAAAABBAAAAAACC--- --------BCCAAACC--BCCCCCC---- -----------CCC------CCCC----- 
------BAAAAAAAAAAAAAB-------- -----BAAAAAAAAAAAAAAACC------ ---CCAAAAAAAAAAAAAAAAAAB----- --BAAAAABBAAAAAAAAAAAAAA----- -CAAAAABAAAAAAABBBBBBAAAAB--- CCCCCCCCCBBBBBBDDDDDDAAAACC-- CCCCCCCCCDDDDDDEEEEEEAAAACB-- CCCCCCCCCBEEEEEEBBBBBAAAACC-- CCCCCCCCCABBBBBAAAAAAAAAAC--- CCCCCCCCCAAAAAAAAAAAAAAAAC--- CCCCCCCCCAAAAAAAAAAAAAAAAA--- -CCCCCCCCAAAAAAAAAAAAAAAAC--- -CCCCCCCCAAAAABBBBBAAABBBA--- -CCCCCCCCAAACCCCCCCBABACCAC-- -CCCCCCCCACCFFFBHBBFBGGBHAA-- --CCCCCCCAACFFFBBGBFBGGBBAC-- ---CCCCCCAAAACFFBBFFBCGGBAA-- ----BCCCCAABBAACCCCBBCCCCAC-- -----CCCCAAAABBAAAAAAAAAAAA-- ------BCCAAAAAABBBBAAAAAAC--- ------CCCAAAAAAAAACAAAAAAA--- -------BCAAAAAAACBAAAAAAC---- --------CCCACACC--ACACACA---- ----------------------------- 
------BAAAAAAAAAAAAAB-------- -----CAAAAAAAAAAAAAAACC------ ---BBAAAAAAAAAAAAAAAAAAC----- --CAAAAABBAAAAAAAAAAAAAA----- -CAAAAABAAAAAAABBBBBBAAAC---- CAAAAABAABBBBBBDDDDDDAAAAC--- AAAAAAAABDDDDDDEEEEEEAAAAC--- CAAAAAAAABEEEEEEBBBBBAAAAC--- AAAAAAAAAABBBBBAAAAAAAAAAC--- CAAAAAAAAAAAAAAAAAAAAAAAAA--- AAAAAAAAAAAAAAAAAAAAAAAAC---- -CAAAAAAAAAAAAAAAAAAAAAAAA--- -AAAAAAAAAAAAABBBBBAAABBBC--- -CAAAAAAAAAACCCCCCCBABACCA--- -AAAAAAAAACCFFFBHBBFBGGBHAA-- --CAAAAAAAACFFFBBGBFBGGBBAA-- ---AAAAAAAAAACFFBBFFBCGGBAC-- ----CAAAAAABBAACCCCBBCCCCAA-- -----AAAAAAAABBAAAAAAAAAAC--- ------CAAAAAAAABBBBAAAAAAA--- ------AAAAAAAAAAAAAAAAAAC---- -------CAAAAAACCBABAAAAAC---- --------ACACACC-----CACA----- ----------------------------- 
------BBAAAAAAAAAAABB-------- -----BAAAAAAAAAAAAAAACC------ ---CCAAAAAAAAAAAAAAAAAAC----- --AAAAAABBAAAAAAAAAAAAAA----- -CAAAAABAAAAAAABBBBBBAAAA---- AAAAAABAABBBBBBDDDDDDAAAC---- CAAAAAAABDDDDDDEEEEEEAAAAA--- AAAAAAAAABEEEEEEBBBBBAAAAC--- CAAAAAAAAABBBBBAAAAAAAAAAA--- AAAAAAAAAAAAAAAAAAAAAAAAAC--- CAAAAAAAAAAAAAAAAAAAAAAAA---- -AAAAAAAAAAAAAAAAAAAAAAAAA--- -CAAAAAAAAAAAABBBBBAAABBBA--- -AAAAAAAAAAACCCCCCCBABACCC--- -CAAAAAAAACCFFFBHBBFBGGBHA--- --AAAAAAAAACFFFBBGBFBGGBBA--- ---CAAAAAAAAACFFBBFFBCGGBA--- ----AAAAAAABBAACCCCBBCCCCA--- -----CAAAAAAABBAAAAAAAAAAA--- ------AAAAAAAAABBBBAAAAAA---- ------CAAAAAAAAAAAAAAAAAA---- -------ACACACCCBACABACAC----- ----------------------------- ----------------------------- 
-------BAAAAAAAAAAAB--------- -----CCAAAAAAAAAAAAACCC------ ---ACAAAAAAAAAAAAAAAAAAC----- --CAAAAABBAAAAAAAAAAAAAC----- -AAAAAABAAAAAAABBBBBBAAAC---- CAAAAABAABBBBBBDDDDDDAAAA---- AAAAAAAABDDDDDDEEEEEEAAAC---- CAAAAAAAABEEEEEEBBBBBAAAAA--- AAAAAAAAAABBBBBAAAAAAAAAAC--- -CAAAAAAAAAAAAAAAAAAAAAAA---- -AAAAAAAAAAAAAAAAAAAAAAAA---- -CAAAAAAAAAAAAAAAAAAAAAAA---- -AAAAAAAAAAAAABBBBBAAABBAA--- --CAAAAAAAAACCCCCCCBABACAA--- --AAAAAAAACCFFFBHBBFBGGBAA--- --CAAAAAAAACFFFBBGBFBGGBAC--- ---AAAAAAAAAACFFBBFFBCGGAA--- ----CAAAAAABBAACCCCBBCCAA---- -----AAAAAAAABBAAAABAACAA---- ------AAAAAAAAABBBBCBBBAC---- ------AAAAAAAAAAAAAAAAAA----- --------AAACABBAAACAAA------- ----------------------------- ----------------------------- 
-------BBBBBBBBBBBBB--------- -----CCCCCCCCCCCCCCCCC------- ---CAAACCCCCCCCCCCCCCCC------ --AAAAAABBAAAAAAAAAAAAAC----- -AAAAAABAAAAAAABBBBBBAAA----- -AAAAABAABBBBBBDDDDDDAAAA---- -CAAAAAABDDDDDDEEEEEEAAAA---- -AAAAAAAABEEEEEEBBBBBAAAA---- -CAAAAAAAABBBBBAAAAAAAAAA---- -AAAAAAAAAAAAAAAAAAAAAAAA---- -AAAAAAAAAAAAAAAAAAAAAAAC---- --AAAAAAAAAAAAAAAAAAAAAAA---- --CAAAAAAAAAAABBBBBAAABBA---- --AAAAAAAAAACCCCCCCBABACA---- --AAAAAAAACCFFFBHBBFBGGBA---- ---AAAAAAAACFFFBBGBFBGGBA---- ---CAAAAAAAAACFFBBFFBCGGA---- ----AAAAAAABBAACCCCBBCCAA---- -----AAAAAAAABBAAAABAACAA---- ------AAAAAAAAABBBBCAAAA----- -------AACAAAAAAAAAACAA------ ------------AAAAAAA---------- ----------------------------- ----------------------------- 
----------------------------- ------CCCCCCCCCCCCCCC-------- -----CACCCCCCCCCCCCCCC------- ---CAAAAAAAAAAAAAAAAAACC----- --AAAAABAAAAAAABBBBBBAAA----- --AAAABAABBBBBBDDDDDDAAC----- --AAAAAABDDDDDDEEEEEEAAAA---- --AAAAAAABEEEEEEBBBBBAAAA---- --AAAAAAAABBBBBAAAAAAAAAA---- --AAAAAAAAAAAAAAAAAAAAAAA---- --AAAAAAAAAAAAAAAAAAAAAAA---- --AAAAAAAAAAAAAAAAAAAAAAA---- --AAAAAAAAAAAABBBBBAAABBA---- ---CAAAAAAAACCCCCCCBABACA---- ---AAAAAAACCFFFBHBBFBGGBA---- ----AAAAAAACFFFBBGBFBGGBA---- ----AAAAAAAAACFFBBFFBCGGA---- -----CAAAAABBAACCCCBBCCA----- ------AAAAAAABBAAAABAACA----- -------AAAAAAAABBBBCAAA------ ----------AAAAAAAAAAA-------- ----------------------------- ----------------------------- ----------------------------- 
----------------------------- ----------------------------- ------CCCCCCCCCCCCCC--------- -----AAAAAAAAAAAAAAAAA------- ---AAAAAAAAAAAAAAAAAAAAA----- ---AAAAAAAAAAAAAAAAAAAAA----- ---AAAAAAAAAAAAAAAAAAAAA----- ---CAAAAAAAAAAAAAAAAAAAA----- ---AAAAAAAAAAAAAAAAAAAAA----- ---AAAAAAAAAAAAAAAAAAAAA----- ---AAAAAAAAAAAAAAAAAAAAAA---- ---CAAAAAAAAAAAAAAAAAAAAA---- ---AAAAAAAAAAAAAAAAAAAAAA---- ----AAAAAAAAAAAAAAAAAAAAA---- ----AAAAAAAAAAAAAAAAAAAAA---- -----CAAAAAAAAAAAAAAAAAA----- -----AAAAAAAAAAAAAAAAAAA----- ------AAAAAAAAAAAAAAAAA------ -------AAAAAAAAAAAAAAAA------ ---------AAAAAAAAAAAA-------- ----------------------------- ----------------------------- ----------------------------- ----------------------------- 
----------------------------- ----------------------------- ----------------------------- -------AAAAAAAAAAAAA--------- -----CAAAAAAAAAAAAAAAA------- ----AAAAAAAAAAAAAAAAAAAA----- ----AAAAAAAAAAAAAAAAAAAA----- ----AAAAAAAAAAAAAAAAAAAA----- ----AAAAAAAAAAAAAAAAAAAA----- ----AAAAAAAAAAAAAAAAAAAA----- ----AAAAAAAAAAAAAAAAAAAA----- ----AAAAAAAAAAAAAAAAAAAA----- ----AAAAAAAAAAAAAAAAAAAA----- -----AAAAAAAAAAAAAAAAAAA----- -----AAAAAAAAAAAAAAAAAAA----- ------AAAAAAAAAAAAAAAAAA----- -------AAAAAAAAAAAAAAAA------ -------AAAAAAAAAAAAAA-------- ----------------------------- ----------------------------- ----------------------------- ----------------------------- ----------------------------- ----------------------------- 
----------------------------- ----------------------------- ----------------------------- ----------------------------- -------AAAAAAAAAAAA---------- ------AAAAAAAAAAAAAAA-------- ------AAAAAAAAAAAAAAAAA------ -----AAAAAAAAAAAAAAAAAA------ -----AAAAAAAAAAAAAAAAAA------ -----AAAAAAAAAAAAAAAAAA------ -----AAAAAAAAAAAAAAAAAA------ -----AAAAAAAAAAAAAAAAAA------ ------AAAAAAAAAAAAAAAAA------ ------AAAAAAAAAAAAAAAAA------ -------AAAAAAAAAAAAAAAA------ -------AAAAAAAAAAAAAA-------- ----------------------------- ----------------------------- ----------------------------- ----------------------------- ----------------------------- ----------------------------- ----------------------------- ----------------------------- 
----------------------------- ----------------------------- ----------------------------- ----------------------------- ----------------------------- ---------AAAAAAAAAA---------- -------AAAAAAAAAAAAAA-------- -------AAAAAAAAAAAAAA-------- -------AAAAAAAAAAAAAA-------- -------AAAAAAAAAAAAAA-------- -------AAAAAAAAAAAAAA-------- -------AAAAAAAAAAAAAA-------- -------AAAAAAAAAAAAAA-------- ---------AAAAAAAAAA---------- ----------------------------- ----------------------------- ----------------------------- ----------------------------- ----------------------------- ----------------------------- ----------------------------- ----------------------------- ----------------------------- ----------------------------- 
