model
size = 32 27 32, scale = 0.05, origin = -y
material 
  colors = A:#200 B:#099 C:#030 D:#6F6 E:#0FF F:#6F9 G:#0F3 H:#9F9 I:#3F3
voxels
229-7D8-7D9-D7-D6-2(D7-)D9-D4-D9-D5-2D10-D2-D10-2D4-2D10-D2-D10-2D6-D8-D4-D8-D9-3(D6-)D11-6D8-6D21-2D29-D2-D28-D2-D29-2D500-7F8-7F9-9F6-9F2(7-2F)4-2F7-2F6-2F8-DF2-FD8-2F5-2FD8-2F2-2F8-D2F6-FD6-2F4-2F6-DF9-8F6-8F11-6F8-6F21-2B29-B2-B28-B2-B25-4C2B4C26-2D468-7D8-7D9-9D6-9D7-2D7E2D4-2D7E2D6-2DE5HGE2D2-2DEG5HE2D5-3DEG5HE2D2-2DE5HGE3D6-D7E3D2-3D7ED9-8D6-8D11-6D8-6D21-2B29-B2GB27-2B2G2B22-6C2B6C24-2D30-2D561-D26-D201-5C8-5C18-B8CB24-2B2D2B28-2D529-D26-D200-6C8-6C15-3B8C3B19-5B2D5B22-3B2D3B27-2D497-F26-F199-6CA8-A6C12-4BA3C2A3CA4B16-6B2D6B19-5B2D5B22-3B2D3B27-2D465-D26-D198-5C3A8-3A5C10-5B10A5B13-4B-8A-4B16-2B-8A-2B19-5B2D5B23-2B2D2B28-2D433-D26-D165-3C20-3C8-BC5A8-5ACB10-6BA8-A6B11-5B2A6-2A5B13-4B10A4B16-6B2D6B20-4B2D4B26-2D30-2D401-D26-D164-4C20-4C6-BC-5A8-5A-CB9-BA4BA8-A4BAB11-5BA8-A5B13-4B10A4B15-7B2D7B17-6B2D6B21-3B2D3B27-2D401-D26-D131-3C24-3C4-B2C-4A10-4A-2CB6-2BC-5A8-5A-C2B7-2BA4BA8-A4BA2B9-6BA8-A6B11-5B10-5B13-4B10A4B15-3B10A3B18-4B4-4B24-4D400-D26-D98-3C26-3C2-BC-A20-A-CB4-2BCA20-AC2B5-2BA-5A8-5A-A2B7-B2A4BA8-A4B2AB8-7BA8-A7B9-6B10-6B11-5BA8-A5B14-3B10A3B17-4B6A4B21-3D2B3D27-2B79-3C26-6C26-3C226-D26-D98-3C26-3C2-BC-A20-A-CB4-2BCA20-AC2B5-2BA-5A8-5A-A2B6-2B2A4BA8-A4B2A2B7-7BA8-A7B9-6B10-6B11-5BA8-A5B13-4B10A4B16-4B6A4B20-4D2B4D26-2B79-3CA24-A4C2BA24-A2B4C26-3C194-D26-D66-2C28-3CB2C24-2CBC-DBA24-ABD3-B3A20-3AB4-2B7A10-7A2B5-2B-B4A10-4AB-2B7-3B5A8-5A3B8-3B4A10-4A3B9-2B4A10-4A2B12-4B10A4B15-5B6A5B18-4D4B4D24-4B47-2(DCA24-ACD2-)DBA24-ABD-CDBA24-ABD4C26-3C162-C26-C34-2C28-4CA26-A3C2BA24-A2BC-DBA24-ABD3-B3A20-3AB4-2B3A18-3A2B5-4B2A14-2A4B6-4B2A14-2A4B7-3B2A14-2A3B9-2B4A10-4A2B11-5B10A5B14-5B6-5B18-4DB2EB4D23-2B2-2B46-3(DCA24-ACD2-)DBA24-ABD-C2BA24-A2B4C26-3C130-C26-C2-2C28-4C28-5C26-4C2B4A18-4A2BC-DBA-2A18-2A-ABD2-DB4A18-4ABD3-2B3A18-3A2B5-2B-3A14-3A-2B6-2B-3A14-3A-2B7-B-3A14-3A-B9-2B-16A-2B11-2B16A2B14-3B10-3B17-4DBE2HEB4D21-2B4-2B13-DC26-CD2-DCA24-ACD-GBCA24-ACB2GBCA24-ACBG-DCA24-ACD2-DBA24-ABD-CBC26-CB3C7(A26-A4C)A26-A3C2B4A18-4A2BC-DB2-2A18-2A2-BD2-DB2-2A18-2A2-BD3-2B-2A18-2A-2B4-3B-3A14-3A-3B5-2B-3A14-3A-2B7-B-3A14-3A-B9-2B-16A-2B11-2B16A2B13-4B10-4B16-4DEH2BHE4D21-B2-2G2-B13-DC26-CD2-DCA24-ACD-GBCA24-ACB2GBCA24-ACBG-DCA24-ACD2-DCA24-ACD-CBC26-CB3CA26-A4C3A22-3A2C-G3A22-3AG2-E3A22-3AE2-G3A22-3AG-2C2(3A22-3A4C)3A22-3A2C-D-4A18-4A-2(D2-DB4A18-4AB)D3-2B-2A18-2A-2B4-3B-3A14-3A-3B5-2B-3A14-3A-2B7-B-3A14-3A-B9-3B16A3B11-2B16A2B13-4B10-4B16-4DEH2BHE4D21-B2-2G2-B45-DC26-CD2-DCA24-ACD-CBCA24-ACB2CDCA24-ACDC-DBA24-ABD2-2BA24-A2B-C2B2A22-2A2B2C2B2A22-2A2BC-E3A22-3AE-GE3A22-3AEG-E3A22-3AE2-E3A22-3AE-2C-2A22-2A-4C-2A22-2A-2C-2(DB4A18-4ABD2-)DB4A18-4ABD3-2B-2A18-2A-2B5-2B-3A14-3A-2B6-2B-3A14-3A-2B7-B-3A14-3A-B9-3B16A3B11-2B16A2B14-3B10-3B17-4DBE2HEB4D21-2B4-2B77-DCA24-ACD-CBCA24-ACBC-DB2A22-2ABD2-DB26-BD2-DB4A18-4ABD2-DB2-2A18-2A2-BD-C2B2-2A18-2A2-2BC-GBA-2A18-2A-ABG2-EB2-2A18-2A2-BE2-GB2-2A18-2A2-BG-C2B2-2A18-2A2-2B2C2B2-2A18-2A2-2BC-2(DB2-2A18-2A2-BD2-)DB2-2A18-2A2-BD3-B2-2A18-2A2-B4-2B-2A18-2A-2B5-2B-3A14-3A-2B5-2CB-3A14-3A-B2C4-C2B-3A14-3A-2BC7-3B16A3B11-2B16A2B14-16B18-3D2B2E2B3D23-2B2-2B80-A24-A3-3CA24-A3C-DB2A22-2ABD2-DB3A20-3ABD2-DB4A18-4A2(BD2-DB2-2A18-2A2-)BD-C3(2B2-2A18-2A2-2B2C)2B2-2A18-2A2-2BC-3(DB2-2A18-2A2-BD2-)D2B-2A18-2A-2BD3-2B-2A18-2A-2B5-B-2A18-2A-B5-C2B-3A14-3A-2BC4-2CB-3A14-3A-B2C4-C2B-3A14-3A-2BC4-5CB16AB5C9-B16AB15-16B18-4D4B4D24-4B110-3CA24-A3C2-B2A22-2AB4-B3A20-3AB3-DB4A18-4A8(BD2-DB2-2A18-2A2-)BD2-D3B2A18-2A3BD3-2B-2A18-2A-2B4-2B-2A18-2A-2B5-B-2A18-2A-B5-C2B-3A14-3A-2BC5-CB-3A14-3A-BC3-2D4B3A14-3A4B2D2-5CB16AB5C9-2B14A2B16-14B20-10D139-4C24-4C2-2BA22-A2B4-B3A20-3AB4-B4A18-4AB3-7(DB2-2A18-2A2-BD2-)DB-3A18-3A-BD3-3B2A18-2A3B2(4-2B-2A18-2A-2B)5-C-2A18-2A-C3-D2(-C2B-3A14-3A-2BC-2D)-C3B3A14-3A3BC-D2-5CB16AB5C10-2B12A2B17-14B21-8D141-3C24-3C3-2BA22-A2B4-B3A20-3AB4-B4A18-4A2(B4-B2-2A18-2A2-)B3-3(DB2-2A18-2A2-BD2-)DB2-2A18-2A2-BD3-2(B2-2A18-2A2-B4-)4BA18-A4B4-4BA18-A4B5-2B2A18-2A2B7-B2A18-2AB4-D3-C-3A14-3A-C3-D2-4C3A14-3A4C4-5C3A12-3A5C9-2B14A2B15-2B12A2B18-4B4D4B24-4D144-2C24-2C4-CB2A20-2ABC5-B2A20-2AB6-B3A18-3AB5-7(B2-2A18-2A2-B4-)B2-2A18-2A2-B5-3BA18-A3B6-3BA18-A3B3-D2-3BA18-A3B2-2D3-B5A12-5AB3-2D4-B-3A12-3A-B4-D6-B-16A-B13-3B12A3B15-3B10A3B16-16B20-2B4D2B174-3C22-3C4-2CBA20-AB2C5-2BA20-A3(2B6-2B2A18-2A)2B6-B-2A18-2A-B5-2B-2A18-2A-2B4-2B-2A18-2A-2B5-2(B-2A18-2A-B6-)2B2A18-2A2B6-2B2A18-2A2B7-2BA18-A2B4-D3-2BA18-A2B3-D5-2B3A12-3A2B10-3B2A12-2A3B11-3B14A3B13-2B-12A-2B15-4B8A4B16-16B23-2D177-3C22-3C4-2CB5A12-5AB2C6-BA-2A14-2A-A2(B8-B-3A14-3A-)B7-2(2B-3A14-3A-2B6-)2(B2-3A14-3A2-B6-)B2-A18-A2-B6-B2-2A16-2A2-B3-D2(3-B-2A16-2A-B3-2D)3-2B2A16-2A2B3-2D4-B2A16-2AB4-D6-B3A12-3AB12-2B2A12-2A2B13-2B14A2B16-B12AB18-14B22-6B208-3C20-3C6-2CB4A12-4AB2C8-B4A2-8A2-4AB10-B4A2-8A2-4AB9-6(2B4A2-8A2-4A2B8-)2B3A3-8A3-3A2B4-D3-3B2A3-8A3-2A3B3-D5-2B2A3-8A3-2A2B10-2B2A3-8A3-2A2B11-B2A14-2AB13-B2A12-2AB14-2B14A2B15-16B18-12B22-8B240-3C18-3C8-3C3A12-3A3C10-B18AB12-B-2A2-8A2-2A-B11-3(2B-2A2-8A2-2A-2B10-)B2-2A2-8A2-2A3(2-B10-B2-5A6B5A)2-B5-D4-2B-16A-2B4-D6-2B16A2B12-2B16A2B13-B16AB15-B14AB17-2B10A2B19-12B22-8B250-4A19-2C6-6A6-2C10-5C12A5C12-2(3B12A3B14-)3B12A3B13-4B12A4B12-2B-14A-2B12-3B4A6B4A3B12-3B2A10B2A3B8-D3-3B2ABA6BAB2A3B3-D4-D3-3B-ABA6BABA-3B3-D2-3D4-2B-AB8ABA-2B4-3D7-2B-AB8ABA-2B15-4B8A4B16-4B8A4B17-14B20-10B24-6B250-6C25-8C18-2C3-10C3-2C12-20C15-14B18-14B17-16B16-16B18-BAB2E2B2EBAB17-6B2E2B2E6B14-6B2E2B2E6B9-2D4-4B-BE2BEB-4B4-2D10-4B-6B-4B16-4B8-4B17-3B8-3B18-3B8-3B19-12B22-8B27-2B284-6C23-3C6-3C17-5C2-4B2-5C14-4C2-BI2BIB2-4C19-3B2I3B23-10B21-12B20-5B2E5B19-4BE-2G-2(E4B18-4BE4G)E4B12-2D4-4BE-2G-E4B4-2D13-3B6E3B20-12B21-10B23-8B26-4B347-6C23-3C6-3C18-4C8-4C17-2C10-2C87-4D27-2D2-2D19-3D3-2D4-2D3-3D10-2(3D-)D2-2H2-D2(-3D)8-D5-3D2-2H2-3D5-D8-D7-D6-D7-D17-D4-D27-4D398-
