model
size = 32 27 32, scale = 0.05, origin = -y
material 
  colors = A:#200 B:#777 C:#555 D:#888 E:#E00 F:#FF9 G:#AAA H:#FF3 I:#111 J:#FF0 K:#0F3 L:#9F9 M:#CC0
voxels
229-7D8-7D9-D7-D6-2(D7-)D9-D4-D9-D5-2D10-D2-D10-2D4-2D10-D2-D10-2D6-D8-D4-D8-D9-3(D6-)D11-6D8-6D21-2D29-D2-D28-D2-D29-2D500-7G8-7G9-G7FG6-G7FG7-GF7-FG4-GF7-FG6-GF8-FG2-GF8-FG5-2GF8-FG2-GF8-F2G6-GF6-FG4-GF6-FG9-G6FG6-G6FG11-6G8-6G21-2B29-B2-B28-B2-B25-4C2B4C26-2D468-7D8-7D9-9D6-9D7-2D7E2D4-2D7E2D6-2DE2H2F2HE2D2-2DE2H2F2HE2D5-3DE2M2F2ME2D2-2DE2M2F2ME3D6-D7E3D2-3D7ED9-8D6-8D11-6D8-6D21-2B29-B2FB27-2B2F2B22-6C2B6C24-2D30-2D561-D26-D201-5C8-5C18-B8CB24-2B2D2B28-2D529-D26-D200-6C8-6C15-3B8C3B19-5B2D5B22-3B2D3B27-2D497-G26-G199-6CA8-A6C12-4BA3C2A3CA4B16-6B2D6B19-5B2D5B22-3B2D3B27-2D465-D26-D198-5C3A8-3A5C10-5B10A5B13-4B-8A-4B16-2B-8A-2B19-5B2D5B23-2B2D2B28-2D433-D26-D165-3C20-3C8-BC5A8-5ACB10-6BA8-A6B11-5B2A6-2A5B13-4B10A4B16-6B2D6B20-4B2D4B26-2D30-2D401-D26-D164-4C20-4C6-BC-5A8-5A-CB9-BA4BA8-A4BAB11-5BA8-A5B13-4B10A4B15-7B2D7B17-6B2D6B21-3B2D3B27-2D401-D26-D131-3C24-3C4-B2C-4A10-4A-2CB6-2BC-5A8-5A-C2B7-2BA4BA8-A4BA2B9-6BA8-A6B11-5B10-5B13-4B10A4B15-3B10A3B18-4B4-4B24-4D400-D26-D98-3C26-3C2-BC-A20-A-CB4-2BCA20-AC2B5-2BA-5A8-5A-A2B7-B2A4BA8-A4B2AB8-7BA8-A7B9-6B10-6B11-5BA8-A5B14-3B10A3B17-4B6A4B21-3D2B3D27-2B79-3C26-6C26-3C226-D26-D98-3C26-3C2-BC-A20-A-CB4-2BCA20-AC2B5-2BA-5A8-5A-A2B6-2B2A4BA8-A4B2A2B7-7BA8-A7B9-6B10-6B11-5BA8-A5B13-4B10A4B16-4B6A4B20-4D2B4D26-2B79-3CA24-A4C2BA24-A2B4C26-3C194-D26-D66-2C28-3CB2C24-2CBC-DBA24-ABD3-B3A20-3AB4-2B7A10-7A2B5-2B-B4A10-4AB-2B7-3B5A8-5A3B8-3B4A10-4A3B9-2B4A10-4A2B12-4B10A4B15-5B6A5B18-4D4B4D24-4B47-2(DCA24-ACD2-)DBA24-ABD-CDBA24-ABD4C26-3C162-C26-C34-2C28-4CA26-A3C2BA24-A2BC-DBA24-ABD3-B3A20-3AB4-2B3A18-3A2B5-4B2A14-2A4B6-4B2A14-2A4B7-3B2A14-2A3B9-2B4A10-4A2B11-5B10A5B14-5B6-5B18-4DB2EB4D23-2B2-2B46-3(DCA24-ACD2-)DBA24-ABD-C2BA24-A2B4C26-3C130-C26-C2-2C28-4C28-5C26-4C2B4A18-4A2BC-DBA-2A18-2A-ABD2-DB4A18-4ABD3-2B3A18-3A2B5-2B-3A14-3A-2B6-2B-3A14-3A-2B7-B-3A14-3A-B9-2B-16A-2B11-2B16A2B14-3B10-3B17-4DBE2LEB4D21-2B4-2B13-DC26-CD2-DCA24-ACD-EBCA24-ACB2EBCA24-ACBE-DCA24-ACD2-DBA24-ABD-CBC26-CB3C7(A26-A4C)A26-A3C2B4A18-4A2BC-DB2-2A18-2A2-BD2-DB2-2A18-2A2-BD3-2B-2A18-2A-2B4-3B-3A14-3A-3B5-2B-3A14-3A-2B7-B-3A14-3A-B9-2B-16A-2B11-2B16A2B13-4B10-4B16-4DEL2BLE4D21-B2-2K2-B13-DC26-CD2-DCA24-ACD-EBCA24-ACB2EBCA24-ACBE-DCA24-ACD2-DCA24-ACD-CBC26-CB3CA26-A4C3A22-3A2C-2(H3A22-3AH2-)H3A22-3AH-2C2(3A22-3A4C)3A22-3A2C-D-4A18-4A-2(D2-DB4A18-4AB)D3-2B-2A18-2A-2B4-3B-3A14-3A-3B5-2B-3A14-3A-2B7-B-3A14-3A-B9-3B16A3B11-2B16A2B13-4B10-4B16-4DEL2BLE4D21-B2-2K2-B45-DC26-CD2-DCA24-ACD-CBCA24-ACB2CDCA24-ACDC-DBA24-ABD2-2BA24-A2B-C2B2A22-2A2B2C2B2A22-2A2BC-H3A22-3AH-FH3A22-3AHF-H3A22-3AH2-H3A22-3AH-2C-2A22-2A-4C-2A22-2A-2C-2(DB4A18-4ABD2-)DB4A18-4ABD3-2B-2A18-2A-2B5-2B-3A14-3A-2B6-2B-3A14-3A-2B7-B-3A14-3A-B9-3B16A3B11-2B16A2B14-3B10-3B17-4DBE2LEB4D21-2B4-2B77-DCA24-ACD-CBCA24-ACBC-DB2A22-2ABD2-DB26-BD2-DB4A18-4ABD2-DB2-2A18-2A2-BD-C2B2-2A18-2A2-2BC-HBA-2A18-2A-A2(BH2-HB2-2A18-2A2-)BH-C2B2-2A18-2A2-2B2C2B2-2A18-2A2-2BC-2(DB2-2A18-2A2-BD2-)DB2-2A18-2A2-BD3-B2-2A18-2A2-B4-2B-2A18-2A-2B5-2B-3A14-3A-2B5-2CB-3A14-3A-B2C4-C2B-3A14-3A-2BC7-3B16A3B11-2B16A2B14-16B18-3D2B2E2B3D23-2B2-2B80-A24-A3-3CA24-A3C-DB2A22-2ABD2-DB3A20-3ABD2-DB4A18-4A2(BD2-DB2-2A18-2A2-)BD-C3(2B2-2A18-2A2-2B2C)2B2-2A18-2A2-2BC-3(DB2-2A18-2A2-BD2-)D2B-2A18-2A-2BD3-2B-2A18-2A-2B5-B-2A18-2A-B5-C2B-3A14-3A-2BC4-2CB-3A14-3A-B2C4-C2B-3A14-3A-2BC4-5CB16AB5C9-B16AB15-16B18-4D4B4D24-4B110-3CA24-A3C2-B2A22-2AB4-B3A20-3AB3-DB4A18-4A8(BD2-DB2-2A18-2A2-)BD2-D3B2A18-2A3BD3-2B-2A18-2A-2B4-2B-2A18-2A-2B5-B-2A18-2A-B5-C2B-3A14-3A-2BC5-CB-3A14-3A-BC3-2E4B3A14-3A4B2E2-5CB16AB5C9-2B14A2B16-14B20-10D139-4C24-4C2-2BA22-A2B4-B3A20-3AB4-B4A18-4AB3-7(DB2-2A18-2A2-BD2-)DB-3A18-3A-BD3-3B2A18-2A3B2(4-2B-2A18-2A-2B)5-C-2A18-2A-C3-E2(-C2B-3A14-3A-2BC-2E)-C3B3A14-3A3BC-E2-5CB16AB5C10-2B12A2B17-14B21-8D141-3C24-3C3-2BA22-A2B4-B3A20-3AB4-B4A18-4A2(B4-B2-2A18-2A2-)B3-3(DB2-2A18-2A2-BD2-)DB2-2A18-2A2-BD3-2(B2-2A18-2A2-B4-)4BA18-A4B4-4BA18-A4B5-2B2A18-2A2B7-B2A18-2AB4-E3-C-3A14-3A-C3-E2-4C3A14-3A4C4-5C3A12-3A5C9-2B14A2B15-2B12A2B18-4B4D4B24-4D144-2C24-2C4-CB2A20-2ABC5-B2A20-2AB6-B3A18-3AB5-7(B2-2A18-2A2-B4-)B2-2A18-2A2-B5-3BA18-A3B6-3BA18-A3B3-E2-3BA18-A3B2-2E3-B5A12-5AB3-2E4-B-3A12-3A-B4-E6-B-16A-B13-3B12A3B15-3B10A3B16-16B20-2B4D2B174-3C22-3C4-2CBA20-AB2C5-2BA20-A3(2B6-2B2A18-2A)2B6-B-2A18-2A-B5-2B-2A18-2A-2B4-2B-2A18-2A-2B5-2(B-2A18-2A-B6-)2B2A18-2A2B6-2B2A18-2A2B7-2BA18-A2B4-E3-2BA18-A2B3-E5-2B3A12-3A2B10-3B2A12-2A3B11-3B14A3B13-2B-12A-2B15-4B8A4B16-16B23-2D177-3C22-3C4-2CB5A12-5AB2C6-BA-2A14-2A-A2(B8-B-3A14-3A-)B7-2(2B-3A14-3A-2B6-)2(B2-3A14-3A2-B6-)B2-A18-A2-B6-B2-2A16-2A2-B3-E2(3-B-2A16-2A-B3-2E)3-2B2A16-2A2B3-2E4-B2A16-2AB4-E6-B3A12-3AB12-2B2A12-2A2B13-2B14A2B16-B12AB18-14B22-6B208-3C20-3C6-2CB4A12-4AB2C8-B4A2-8A2-4AB10-B4A2-8A2-4AB9-6(2B4A2-8A2-4A2B8-)2B3A3-8A3-3A2B4-E3-3B2A3-8A3-2A3B3-E5-2B2A3-8A3-2A2B10-2B2A3-8A3-2A2B11-B2A14-2AB13-B2A12-2AB14-2B14A2B15-16B18-12B22-8B240-3C18-3C8-3C3A12-3A3C10-B18AB12-B-2A2-8A2-2A-B11-3(2B-2A2-8A2-2A-2B10-)B2-2A2-8A2-2A3(2-B10-B2-5A6B5A)2-B5-E4-2B-16A-2B4-E6-2B16A2B12-2B16A2B13-B16AB15-B14AB17-2B10A2B19-12B22-8B250-4A19-2C6-6A6-2C10-5C12A5C12-2(3B12A3B14-)3B12A3B13-4B12A4B12-2B-14A-2B12-3B4A6B4A3B12-3B2A10B2A3B8-E3-3B2ABA6BAB2A3B3-E4-E3-3B-ABA6BABA-3B3-E2-3E4-2B-AB8ABA-2B4-3E7-2B-AB8ABA-2B15-4B8A4B16-4B8A4B17-14B20-10B24-6B250-6C25-C6EC18-2C3-C2E4C2EC3-2C12-5C2E6C2E5C15-14B18-14B17-16B16-16B18-BABEI2BIEBAB17-6B2E2B2E6B14-6B2E2B2E6B9-2E4-4B-BI2BIB-4B4-2E10-4B-6B-4B16-4B8-4B17-3B8-3B18-3B8-3B19-12B22-8B27-2B284-6C23-3C6-3C17-5C2-4B2-5C14-4C2-B4EB2-4C19-3B2E3B23-4B2E4B21-12B20-5B2I5B19-4BE-2J-E2(4B18-4BIJ2KJI)4B12-2E4-4BI-2J-I4B4-2E13-3BE4IE3B20-12B21-10B23-8B26-4B347-6C23-3C6-3C18-4C8-4C17-2C10-2C87-4E27-2E2-2E19-3E3-2E4-2E3-3E10-2(3E-)E2-2F2-E2(-3E)8-E5-3E2-2F2-3E5-E8-E7-E6-E7-E17-E4-E27-4E398-
