model
size = 10 32 10, scale = 0.05, origin = -y
material 
  colors = A:#630 B:#BBB C:#555 D:#EEE
voxels
45-A7-24(4A6-)2A2B6-4B6-BC-B26-A-A6-A-4A3-7A3-24(8A2-)C6AB2-BC3AC2B2-C2BCB-2C16-2A5-6A4-6A3-25(8A2-)B6AB2-B6AD2-BC2B2CBD5-2A7-5A4-7A2-8A-9A-240AB9ABA2C5A2B2C-CBD2CB3-3A7-6A3-7A2-8A-260AB5AC2AB-C2BCB-BCB3-4A6-6A3-7A2-8A-259A2B2AD5A2B2C-2(CB)2C4-2A8-4A5-5A3-8A2-8A-240AB9AB4AC3A3CB2C-3CB14-2A7-5A4-7A25(2-8A)2-B7A2-BD5AB2-C-C3BCB24-3A6-5A4-25(8A2-)B5A2B2-2B4A2B3-2B3CB46-2A7-24(4A6-)3BA6-BC2B6-BD2B3-
