model
size = 13 24 32, scale = 0.05, origin = -y
material 
  colors = A:#3A000E B:#D8B37B C:#B28065 D:#FCC E:#311300 F:#290F04 G:#491900 H:#FC0 I:#552810
voxels
43-5C8-5B8-5A9-3A254-9C4-2B5D2B2(4-2A5B2A)5-7A238-10C3-11C2-B9DB2-A9BA3-A7BA4-2A5B2A6-5A214-4(C-)C3-11C2-B9DB3(2-A9BA)3-A7BA5-7A212-6(C-)13CB11DBA11BA-A9BA2-A9BA3-A7BA5-7A211-6(C-)14CB11DBA11B2A11BA-A9BA3-A7BA5-7A211-2C4(-C)-2CB11DBA2(11B2A)11BA-A9B2A2-A7BA5-7A211-6(C-)CB11DBA2(11B2A)11BA-A9B2A2-A7BA5-7A211-2C4(-C)-2CB11DBA11B2A11BA-A10BA-A9B2A2-A7BA5-7A212-2C5(-C)-B10DB3(-A10BA)-A9B2A2-A7BA5-7A212-5(C-)2C-B10DB3(-A10BA)2-A9BA2-A7B2A4-7A213-5(C-)C2-B9DB3(2-A9BA)2-2(A8BA3-)9A212-2C3(-C)-2C2-B9DB2(2-A9BA)2-3(A8BA3-)9A18-6G188-4(C-)2C3-B8DB4(3-A8BA)3-A7B2A3-A7BA4-H6AH19-6G175-2C4(-C)3-10C3-B8DB2(3-A8BA)3-A7B2A3-A6-A5-A6BA5-8A5-H6-H19-6G175-10C3-B8DB2(3-A8BA)3-A7BA4-2(A6-A5-)8A5-A6-A5-H6-H32-6G34-5G110-10C3-B8DB2(3-A8BA)3-A7BA4-A6-2A4-2(A6-A5-)2(8A5-)A6-A5-H6-H45-G4-G21-4G85-2(10C3-)B8DB3-A8BA3-A7BA4-A6-2A4-4(A6-A5-)3(8A5-)A6-A5-H6-H32-2G2-2G97-10C3-B8DB3-A8BA3-A7BA2(4-A6-2A)4-6(A6-A5-)3(8A5-)A6-H5-H13-2(G5-)G77-9C4-B7DB2(4-A7BA)2(4-A6-2A)4-9(A6-A5-)3(8A5-)7AH5-H6AG57-9C4-B7DB2(4-A7BA)3(4-A6-2A)4-9(A6-A5-)2(A6-A2(-G)-)A6-A-G2-GA6-BG4-H6AH6-6A32-2(9C4-)B7DB4-A7BA3(4-A6-2A)4-8(A6-A5-)5(F6-F5-)F6-F18-2C2(-C)-2C3(4-9C)4-B7DB4-A7BA3(4-A6-2A)4-8(A6-A5-)F6-F5(5-E6-E)17-2C4(-C)3(3-10C)3-B8DB3-A8BA3-AB6-BA3-2A3(6-2A4-A)6(6-A5-A)6-A4-2F6-2F5(3-2E6-2E)16-4(C-)2C3(3-10C)3-B8DB3-A8BA3-AB6-BA3(3-2A6-2A)3-2A6-A4-2A5(6-A5-A)6-A4-2F6-2F5(3-2E6-2E)17-4(C-)C3(3-10C)3-B8DB3-A8BA3-AB6-BA3-2A6-2A3-2A6-AI3-2A6-2A3-5(2A6-A4-)2A6-A5-A6-A4-2F6-2F5(3-2E6-2E)16-4(C-)2C3(3-10C)3-B8DB3-A8BA3-AB6-BI3-2A6-AI2(3-2A6-2A)3-5(2A6-A4-)2A6-A5-A6-A4-2F6-2F5(3-2E6-2E)17-4(C-)C3(3-10C)3-B8DB3-A8BA3-AB6-BA3-2A6-2A3-2A6-AI3-2A6-2A3-5(2A6-A4-)2A6-A5-A6-A4-2F6-2F5(3-2E6-2E)16-4(C-)2C3(3-10C)3-B8DB3-2A6BA4-2AB4-B2A3(3-3A4-3A)3-5(3A4-2A4-)ABA4-2A5-2(2A4-)3F4-3F3-2EF4-F2E4(3-3E4-3E)17-3(C-)C6-3(8C5-)B6DB6-2(A4BA7-)3(6A7-)5A8-3(6A7-)6A6-7A6-AB5A6-6FEF5-6EF3(E5-EB4EB)E5-8E19-2(C-)C8-3(6C7-)B4DB7-2(A3BA8-)A3B6(A9-A2B)A9-2ABA9-4A8-6A7-6F7-6E3(7-E4BE)7-6E21-C-C9-3(5C8-)5B9-4(3A10-)3A4(11-2A)12-A35-5F5(8-5E)18-
