model
size = 3 31 3, scale = 0.05, origin = -y
material 
  colors = A:#111 B:#AAA C:#09F
voxels
--- --- --- --- --- --- --- --- --- --- --- --- --- --- --- --- --- --- --- --- --- --- --- --- --- --- --- -B- BBB -C- --- 
-B- -A- -A- -A- -A- -A- -A- -A- -A- -A- -A- -A- -A- -A- -A- -A- -A- -A- -A- -A- -A- -A- -A- -A- -A- -A- -B- BBB BCB CCC -C- 
--- --- --- --- --- --- --- --- --- --- --- --- --- --- --- --- --- --- --- --- --- --- --- --- --- --- --- -B- BBB -C- --- 
