model
size = 32 31 18, scale = 0.05, origin = -y
material 
  colors = A:#EEE B:#FF0 C:#111 D:#CC3 E:#222 F:#200 G:#FF3
voxels
7-2(3CE)2(CE)3CE2C18-2E4-2(E2-)E943-17CE14-E2C14E18-B-2(B2-)B23-B5-2(B-)2B2(31-B)20-B10-B785-18C14-EC14BC16-12B2DB18-5B2D7B18-2BGE2C3B2EC2B18-2BDEBCBEBC4B18-3BE3(BC)4B18-3BE2C2(BE)4B18-3BCBE2(BC)2BDB18-BD4(BC)2BDB18-2BGE2CBCB2CE2B18-BD5BE6B18-4B2C2E3C3B18-6BD7B18-14B18-8BD3B2D18-BD4BD7B18-14B16-18B14-F16BF14-7BD2BD7B15-6BD2BD6B16-7BD5BD2B16-6B2D5BD2B16-5B3D2BD5B16-D12BD2B12-5BD18B9-7BD3BD10B14-11B2DB18-6B2E6B20-2(CE)2CE3C18-18C15-CB12ABC17-B2(12AB18-D)3(12AB18-B)3AE8A6(B18-B12A)B18-D2(12AB18-B)12AB16-2B14A2B14-F16AF8-E2C2E-F16AF-EC2EC2-4BF-F16AF-F4B2-BD3B2-B14AB2-2BD2B2-6B-B14AB-5BD-2BD4B-B14AB-2BD7BD3B-B14AB-4BD9B-BA12BAB-7B-4B2ADAB12-BAD2A4B3-3B4AB12-B4A3B6-5BAB10-BA5B10-B-BDB10-BDB-B16-C10-C17-17CE15-CB12ABCE15-2B12ABE17-D12AD18-D3(12AB18-B)3AE8A9(B18-B12A)B16-FD14ADF14-F16AF8-C3-E-F16AF-C3-E2-4BF-F16AF-F4B2-B3AF2-D14AD2-F3AB2-B4AB-D14AD-B4AB-7B2(-D14AD-14B)-DA12BAD-7B-6BDAB12-BAD6B3-5B2AB12-B2A5B6-3B3AB10-B3A3B10-2B2AB10-B2A2B13-3BC10-C3B14-18C14-ECB12ABC17-B12ABE17-B12AD18-D3(12AB18-B)4(12AB18-D)12AD5(18-B12AB)16-FD14ADF14-F16AF8-E3-C-F16AF-C3-E2-4BF-F16AF-F4B2-D3AF2-D14AD2-F3AB2-B4AD-D14AD-D4AB-7B2(-B14AB-14B)-DA4BD2BD4BAD-7B-6BDAB12-BAD6B3-5B2AB12-B2A5B6-3B3AB10-B3A3B2(10-B3AB)13-BDBC10-CBDB14-18C14-ECB12ABC2(17-B12A2B)17-D3(12AB18-B)3(12AB18-D)12AD18-D2(12AB18-B)12AB18-D12AD18-D12AB18-B12AB16-BD14ADB14-F16AF8-E3-C-B16AB-C3-C2-4BF-F16AF-F4B2-D3AF2-D14AD2-F3AB2-B4AD-B14AB-D4AB-D6B-B14AB-7BD6B-D14AD-14B-DA12BAD-7B-6BDAB12-BAD6B3-D4B2AB12-B2A4BD6-3B3AB10-B3A3B10-2D2AB10-B2A2D13-2DBE10-EB2D14-17CE15-CB12ABC16-2B12AB18-B12A2B17-3(B12AB18-)2(B12AD18-)5(B12AB18-)D12AD18-D12AB18-B12AB16-FD14ADF14-F16AF8-C3-C-F16AF-C3-C2-4BF-F16AF-F4B2-B3AF2-D14AD2-F3AB2-B4AD-D14AD-D4AB-D6B-D14AD-7BD6B-D14AD-14B-DA5B2D5BAD-7B-6BDAB12-BAD6B3-5B2AB12-B2A5B6-B2D3AB10-B3A2DB10-D3AB10-B3AD13-BDBC10-CBDB14-18C15-CB12ABC17-B12A2B17-B12AB3(18-B12AD)10(18-B12AB)16-BD14ADB14-B16AB8-C3-C-F16AF-C3-C2-4BF-D16AD-F4B2-D3AF2-B14AB2-F3AB2-B4AD-D14AD-D4AB-7B-B14AB-7BD6B-D14AD-14B-DA4BD2BD4BAD-7B-6BDAB12-BAD6B3-5B2AB12-B2A5B6-D2B3AB10-B3A2BD2(10-B3AB)13-3BE10-E3B14-18C15-EB12ABC17-2(B12AD18-)3(B12AB18-)D3(12AB18-B)2(12AB18-D)4(12AB18-B)12AB16-FD14ADF14-F16AF8-E3-C-F16AF-C3-E2-4BF-F16AF-F4B2-D3AF2-D14AD2-F3AB2-D4AD-D14AD-D4AB-7B2(-D14AD-14B)-DA3B6D3BAD-7B-6BDAB12-BAD6B3-D4B2AB12-B2A4BD6-D2B3AB10-B3A2BD2(10-B3AB)13-3BC10-C3B14-18C15-CB12ABE17-3(D12AB18-)11(B12AB18-)B12AB16-FD14ADF14-B16AB8-C3-E-F16AF-C3-C2-4BF-F16AF-F4B2-B3AF2-D14AD2-F3AB2-D4AD-B14AB-D4AB-7B-D14AD-14B-D14AD-7BD6B-DA12BA2(D-6B)DAB12-BAD6B3-D4B2AB12-B2A4BD6-3B3AB10-B3A3B2(10-B3AB)13-3BC10-E3B14-17CE15-CB12ABC16-2B2(12AB18-B)12AD2(18-B12AB)2(18-B12AD)2(18-B12AB)18-B12AD5(18-B12AB)16-FD14ADF14-F16AF8-C3-C-F16AF-C3-C2-4BF-F16AF-F4B2-B3AF2-D14AD2-F3AB2-B4AD-D14AD-D4AB-D6B2(-D14AD-14B)-DA12BAD-7B-6BDAB12-BAD6B3-5B2AB12-B2A5B6-BDB3AB10-B3ABDB10-D3AB10-B3AD13-2BDC10-CD2B14-E16CE14-ECB12ABCE16-B12AB17-2B12AB18-B12AD2(18-B12AB)3(18-D12AB)3(18-B12AB)18-D3(12AB18-B)12AB16-FD14ADF14-F16AF8-E3-E-F16AF-C3-E2-4BF-F16AF-F4B2-B3AF2-D14AD2-F3AB2-B4AD-D14AD-D4AB-D6B-D14AD-14B-D14AD-15BDA2B8D2BAD8B-6B2AB12-B2A6B3-5B2AB12-B2A5B6-3B3AB10-B3A3B2(10-B3AB)13-3BC10-C3B14-E17C15-CB12ABC17-D14(12AB18-B)12AB16-BD14ADB14-B16AB8-E2C2E-B16AB-CE2CE2-5B-B16AB-2(5B2-)D14AD2-5B2-6B-D14AD-6B-7B-D14AD-14B2D14A2D14B-DAB10DBAD-7B-6B3AB10DB2A7B3-5B3AB10DB3A5B6-3BADAB10-BADA3B10-B2DAB10-BA2DB13-3BE10-E3B14-E17C15-EB12ABE17-D12ABE17-6(B12AB18-)2(B12AD18-)5(B12AB18-)B12AB16-BD14AD3(B14-B16A)B9-4B-B16AB-4B4-4BDB16ABD4B3-5BDB16ABD5B3-2(4BD-B14AB-D4B4-)13BEC13B4-11B4CEC11B6-4B-3BC6-C3B-4B10-B2-B2C8-2CB2-B45-E17C15-C14BE16-15B3(18-5BC2BC5B)18-4B9CB18-3B9C2B18-3B3C3B2C3B18-3B2C4B2C2BD18-3B3C3B2C2BD2(18-4B7C3B)18-3B3C3B2C3B18-3B2C4B2C3B18-3B3C3B2C3B18-3B9C2B16-BFB3F2E2C5EBFB14-B2F4AE2FE4A2FB14-2(2F6A)F3(B14-B16A)B10-5B16AB9-B5-B14A2(B5-)B4-16B4-B7-5B14-5B9-4B14-4B108-2(E7C)2E15-E5C2E8C17-3B4-B2-2B20-2B9-B-B467-4B4-4B19-5BC2-C5B17-2(6BC2BC6B16-)16B11-21B16-16B207-3CE5CE2CE3CEC17-3E7-E686-7B246-
