model
size = 31 30 6, scale = 0.05, origin = -y
material 
  colors = A:#FFF B:#2C3B6D C:#000 D:#D7D7D7 E:#34499B
voxels
------------------------------- ----------------AAD------------ ----------------AAD------------ ----------------AAAD----------- ----------------AAAD----------- ----------------AAAD----------- ----------------AAAD----------- ---------------AAAAD----------- ---------------AAADD----------- --------------AAAADD----------- --------------AAADDD----------- -------------AAAAAAAAAAAAADDD-- -------------AAAAAAAAAAAAAADDD- ------------AAAAAAAAAAAAAAADDD- -EBBBBBBB---AAAAAAAAAAAAAADDD-- -EBBBBBBB--AAAAAAAAAAAAAADDD--- -EBBBBBBB-AAAAAAAAAAAAAAAADDD-- -EBBBBBBB-AAAAAAAAAAAAAAAAADDD- -EBBBBBBB-AAAAAAAAAAAAAAAAADDD- -EBBBBBBB-AAAAAAAAAAAAAAAADDD-- -EBBBBBBB-AAAAAAAAAAAAAAADDD--- -EBBBBBBB-AAAAAAAAAAAAAAAADDD-- -EBBBBBBB-AAAAAAAAAAAAAAAADDD-- -EBBBBBBB-AAAAAAAAAAAAAAADDD--- -EBBBBBBB-AAAAAAAAAAAAAADDD---- -EBBBBBBB-AAAAAAAAAAAAAAADDD--- -EBBBBBBB-AAAAAAAAAAAAAAADDD--- -EBBBBBBB---AAAAAAAAAAAADDD---- -EEEEEEEE---------------------- ------------------------------- 
---------------CCCC------------ ---------------CAAAC----------- ---------------CAAAC----------- ---------------CAAAAC---------- ---------------CAAAAC---------- ---------------CAAAAC---------- ---------------CAAAAC---------- --------------CAAAAAC---------- --------------CAAAAAC---------- -------------CAAAAAAC---------- -------------CAAAAAACCCCCCCCC-- ------------CAAAAAAAAAAAAAAAAC- ------------CAAAAAAAAAAAAAAAAAC -CCCCCCCC--CAAAAAAAAAAAAAAAAAAC CBBBBBBBBC-CAAAAAAAAAAAAAAAAACC CBBBBBBBBCCAAAAAAAAAAAAAAAAACC- CBBBBBBBBCAAAAAAAAAAAAAAAAAAACC CBBBBBBBBCAAAAAAAAAAAAAAAAAAAAC CBBBBBBBBCAAAAAAAAAAAAAAAAAAAAC CBBBBBBBBCAAAAAAAAAAAAAAAAAAACC CBBBBBBBBCAAAAAAAAAAAAAAAAAACC- CBBBBBBBBCAAAAAAAAAAAAAAAAAAAC- CBBBBBBBBCAAAAAAAAAAAAAAAAAAAC- CBBBBBBBBCAAAAAAAAAAAAAAAAAACC- CBBBBBBBBCAAAAAAAAAAAAAAAAACC-- CBBBBBBBBCAAAAAAAAAAAAAAAAAAC-- CBBBBBBBBCAAAAAAAAAAAAAAAAAAC-- CBBBBBBBBCCCAAAAAAAAAAAAAAAC--- CBBBBBBBBC-CCCCCCCCCCCCCCCC---- -CCCCCCCC---------------------- 
---------------CCCC------------ ---------------CAAAC----------- ---------------CAAAC----------- ---------------CAAAAC---------- ---------------CAAAAC---------- ---------------CAAAAC---------- ---------------CAAAAC---------- --------------CAAAAAC---------- --------------CAAAAAC---------- -------------CAAAAAAC---------- -------------CAAAAAACCCCCCCCC-- ------------CAAAAAAAAAAAAAAAAC- ------------CAAAAAAAAAAAAAAAAAC -CCCCCCCC--CAAAAAAAAAAAAAAAAAAC CBBBBBBBBC-CAAAAAAAAAAAAAAAAACC CBBBBBBBBCCAAAAAAAAAAAAAAAAACC- CBBBBBBBBCAAAAAAAAAAAAAAAAAAACC CBBBBBBBBCAAAAAAAAAAAAAAAAAAAAC CBBBBBBBBCAAAAAAAAAAAAAAAAAAAAC CBBBBBBBBCAAAAAAAAAAAAAAAAAAACC CBBBBBBBBCAAAAAAAAAAAAAAAAAACC- CBBBBBBBBCAAAAAAAAAAAAAAAAAAAC- CBBBBBBBBCAAAAAAAAAAAAAAAAAAAC- CBBBBBBBBCAAAAAAAAAAAAAAAAAACC- CBBBBBBBBCAAAAAAAAAAAAAAAAACC-- CBBBBBBBBCAAAAAAAAAAAAAAAAAAC-- CBBBBBBBBCAAAAAAAAAAAAAAAAAAC-- CBBBBBBBBCCCAAAAAAAAAAAAAAAC--- CBBBBBBBBC-CCCCCCCCCCCCCCCC---- -CCCCCCCC---------------------- 
---------------CCCC------------ ---------------CAAAC----------- ---------------CAAAC----------- ---------------CAAAAC---------- ---------------CAAAAC---------- ---------------CAAAAC---------- ---------------CAAAAC---------- --------------CAAAAAC---------- --------------CAAAAAC---------- -------------CAAAAAAC---------- -------------CAAAAAACCCCCCCCC-- ------------CAAAAAAAAAAAAAAAAC- ------------CAAAAAAAAAAAAAAAAAC -CCCCCCCC--CAAAAAAAAAAAAAAAAAAC CBBBBBBBBC-CAAAAAAAAAAAAAAAAACC CBBBBBBBBCCAAAAAAAAAAAAAAAAACC- CBBBBBBBBCAAAAAAAAAAAAAAAAAAACC CBBBBBBBBCAAAAAAAAAAAAAAAAAAAAC CBBBBBBBBCAAAAAAAAAAAAAAAAAAAAC CBBBBBBBBCAAAAAAAAAAAAAAAAAAACC CBBBBBBBBCAAAAAAAAAAAAAAAAAACC- CBBBBBBBBCAAAAAAAAAAAAAAAAAAAC- CBBBBBBBBCAAAAAAAAAAAAAAAAAAAC- CBBBBBBBBCAAAAAAAAAAAAAAAAAACC- CBBBBBBBBCAAAAAAAAAAAAAAAAACC-- CBBBBBBBBCAAAAAAAAAAAAAAAAAAC-- CBBBBBBBBCAAAAAAAAAAAAAAAAAAC-- CBBBBBBBBCCCAAAAAAAAAAAAAAAC--- CBBBBBBBBC-CCCCCCCCCCCCCCCC---- -CCCCCCCC---------------------- 
---------------CCCC------------ ---------------CAAAC----------- ---------------CAAAC----------- ---------------CAAAAC---------- ---------------CAAAAC---------- ---------------CAAAAC---------- ---------------CAAAAC---------- --------------CAAAAAC---------- --------------CAAAAAC---------- -------------CAAAAAAC---------- -------------CAAAAAACCCCCCCCC-- ------------CAAAAAAAAAAAAAAAAC- ------------CAAAAAAAAAAAAAAAAAC -CCCCCCCC--CAAAAAAAAAAAAAAAAAAC CBBBBBBBBC-CAAAAAAAAAAAAAAAAACC CBBBBBBBBCCAAAAAAAAAAAAAAAAACC- CBBBBBBBBCAAAAAAAAAAAAAAAAAAACC CBBBBBBBBCAAAAAAAAAAAAAAAAAAAAC CBBBBBBBBCAAAAAAAAAAAAAAAAAAAAC CBBBBBBBBCAAAAAAAAAAAAAAAAAAACC CBBBBBBBBCAAAAAAAAAAAAAAAAAACC- CBBBBBBBBCAAAAAAAAAAAAAAAAAAAC- CBBBBBBBBCAAAAAAAAAAAAAAAAAAAC- CBBBBBBBBCAAAAAAAAAAAAAAAAAACC- CBBBBBBBBCAAAAAAAAAAAAAAAAACC-- CBBBBBBBBCAAAAAAAAAAAAAAAAAAC-- CBBBBBBBBCAAAAAAAAAAAAAAAAAAC-- CBBBBBBBBCCCAAAAAAAAAAAAAAAC--- CBBBBBBBBC-CCCCCCCCCCCCCCCC---- -CCCCCCCC---------------------- 
------------------------------- ----------------AAD------------ ----------------AAD------------ ----------------AAAD----------- ----------------AAAD----------- ----------------AAAD----------- ----------------AAAD----------- ---------------AAAAD----------- ---------------AAADD----------- --------------AAAADD----------- --------------AAADDD----------- -------------AAAAAAAAAAAAADDD-- -------------AAAAAAAAAAAAAADDD- ------------AAAAAAAAAAAAAAADDD- -EBBBBBBB---AAAAAAAAAAAAAADDD-- -EBBBBBBB--AAAAAAAAAAAAAADDD--- -EBBBBBBB-AAAAAAAAAAAAAAAADDD-- -EBBBBBBB-AAAAAAAAAAAAAAAAADDD- -EBBBBBBB-AAAAAAAAAAAAAAAAADDD- -EBBBBBBB-AAAAAAAAAAAAAAAADDD-- -EBBBBBBB-AAAAAAAAAAAAAAADDD--- -EBBBBBBB-AAAAAAAAAAAAAAAADDD-- -EBBBBBBB-AAAAAAAAAAAAAAAADDD-- -EBBBBBBB-AAAAAAAAAAAAAAADDD--- -EBBBBBBB-AAAAAAAAAAAAAADDD---- -EBBBBBBB-AAAAAAAAAAAAAAADDD--- -EBBBBBBB-AAAAAAAAAAAAAAADDD--- -EBBBBBBB---AAAAAAAAAAAADDD---- -EEEEEEEE---------------------- ------------------------------- 
