model
size = 32 32 17, scale = 0.05, origin = -y
material 
  colors = A:#DDD B:#330 C:#111 D:#033 E:#996 F:#100 G:#E00 H:#6C9 I:#693 J:#666 K:#360 L:#9F6 M:#222 N:#C00 O:#B00 P:#F60 Q:#F90 R:#C03 S:#EEE
voxels
559-3(2D62-)2D798-2D29-3(4B60-)4B733-2D62-2D27-D6BD3(24-D6-D24-8D)27-2G35-S666-2D62-2D26-D8BD3(22-2D6C2D22-10D)21-2JDG4DGD2J20-3J6-3J29-3J631-6D26-D4-D24-10D7(22-C8AC)18-L2-J10CJ2-L15-4LJ6-J2N2L27-3J308-GB8-BG280-4D27-6D26-D4CD24-10D22-C8AC21-2(B10AB20-C10AC20-)B10AB17-L2-D10AD2-L17-J3AC2AC3AJ21-J2(2B-)2BJ21-2J7-3J307-5B4-5B248-2D29-4D27-6D26-6D23-3B6A3B19-2C10A2C2(18-B12AB18-C12AC)18-B12AB15-L2-2D10A2D2-L15-2B3AB2AB3A2B18-2BA2(2C-)2CA2B19-B2(ED)2B2(DE)B276-3F6-3F18-7B2-7B49-4B6-4B184-2D29-4D27-6D21-5B6A5B16-3B10A3B3(16-C14AC16-B14AB)14-L-3D10A3D-L13-J3B3AB2AB3A3BJ15-3BC-CB2ABC-C3B18-B2(E-)2B2(-E)B243-5F4-5F18-5F4-5F16-2B5F4B5F2B16-5D4-5D17-7B2-7B17-2KBI6-IB2K17-L2-BI6-IB2-L15-L3-2I6-2I3-L13-L18-L12-L18-L11-L9-2D9-L19-4D22-2(G2B)4A2(2BG)2(16-K14AK)3(17-G12AG17-K14AK)15-2JG12AG2J13-LJI3ACAB2ABAC3AIJL12-GJIBAC-CB2ABC-CABIJG16-B2(E-)2B2(-E)B212-QNQ6-QNQ19-5F4-5F17-7F2-7F14-GBM5F4B5FMBG15-2D-F6-F-2D16-3B2-F-B2-B-F2-3B16-I2FB-B2-B-B2FI19-HIHB4-BHIH21-2I6-2I22-K8-K22-B8-B22-B3-2C3-B16-L2-16C2-L11-L-I14AI-L13-2LC12AC2L15-LC12ACL17-2(P12AP18-C12AC18-)P12AP18-C12AC17-JP12APJ14-J2NC2ACAB2ABAC2AC2NJ13-JI2AC-CB2ABC-C2AIJ15-3B2(E-)2C2(-E)3B18-B2(ED)2B2(DE)B149-R8-R21-3N6-3N18-6F4-6F15-8F2-8F13-B2M5FB2-B5F2MB14-3D-FD4-DF-3D15-3B3F-B2-B-3F3B16-4H2B2-2B4H19-3HB4-B3H21-2(2H6-2H22-)2B6-2B22-2B6-2B19-D2C2AB4CB2A2CD3(16-K14AK)3(17-G12AG17-K14AK)16-JG12AGJ15-JI3ACAB2ABAC3AIJ14-JI2AC-CB2ABC-C2AIJ15-3BE-EB2ABE-E3B18-B2(E-)2B2(-E)B180-QNQ6-QNQ19-5F4-5F17-7F2-7F14-2BM5FB2-B5FM2B14-MB3FD4-D3FBM15-3B2FI-B2-B-I2F3B14-2HI2M2HB2-B2H2MI2H15-2K2IHB4-BH2I2K17-KHIH6-HIHK19-H2I6-2IH20-BIB6-BIB21-BAB4CBAB19-DCB3A4C3ABC2(D16-D14A)D14-3D14A3D12-EDB14ABDE12-ED16ADE12-EDB14ABDE12-2D16A2D12-EDB14ABDE12-EB16ABE12-E2B14A2BE12-G3B2ACAB2ABAC2A3BG13-3BAC-CB2ABC-CA3B16-2BE-EB2ABE-E2B17-GEB2(E-)2H2(-E)BEG18-BE-ED2BDE-EB241-2B5FB2-B5F2B16-5MD2-D5M16-8B2-8B16-H5I2-5IH19-H2IB4-B2IH21-2H6-2H54-2CB4-B2C20-2C3A4B3A2C17-D14AD11-E4-D14AD4-E6-2E3-D14AD3-2E6-2E4D14A4D2E6-3D20A3D3(6-2ED20AD2E)6-GED20ADEG7-ED20ADE9-D20AD11-E3B2ACAB2ABAC2A3BE13-3B2ACAB2ABAC2A3B16-2BACEB2ABECA2B17-EABACEB2ABECABAE17-2BACE-2A-ECA2B20-B2ED2BD2EB22-D8-D22-G8-G117-3F6-3F18-2B3M2B2-2B3M2B48-7B2-7B18-4H4-4H20-H2IH4-H2IH42-R30-RG10-C3B2-3BC10-2GO7-2D4A2B4A2D7-O3GO5-D14AD5-O3G2OE4-D14AD4-E2O2GOD2E3-B14AB3-2EDO3GD5E16A5ED2G-G3D22A3DG2-GD26ADG3-D26AD4-D26AD5-E24AE7-E22AE9-E20AE11-E3B4AB2AB4A3BE13-3B4AB2AB4A3B16-2B3AB2AB3A2B17-EAB3AB2AB3ABAE17-2B3AB2AB3A2B20-3B-2B-3B182-F8-F20-5B4-5B50-5B4-5B52-2K6-2K86-C3B2-3BC20-2D4A2B4A2D17-EC12ACE9-G6-EC12ACE6-2(G2-GE5-EC12ACE5-E)G2-G6EAC12ACA6EG3-5E2AC12AC2A5E4-6EAC12ACA6E5-5EAC12ACA5E7-4EAC12ACA4E9-3EAC12ACA3E11-2EAC12ACA2E13-3B12A3B14-3B12A3B16-2B10A2B17-ECB10ABCE17-CB10ABC20-10B213-G2B6-2BG213-4C2-4C21-2C2AC2BC2A2C18-B-CAB6ABAC-B16-B-CB8ABC-B16-E-CAB6ABAC-E16-E-CB8ABC-E16-E-CAB6ABAC-E11-6E-CAB6ABAC-6E7-5E-CAB6ABAC-5E9-4E-CAB6ABAC-4E11-3E-CAB6ABAC-3E13-2E-CB8ABC-2E15-B-CAB6ABAC-B16-B-CB8ABC-B16-B-CAB6ABAC-B18-GB8ABG18-G-CAB6ABAC-G18-3C6E3C471-2(C4-C26-)15(6C26-)6C109-
