model
size = 31 31 21, scale = 0.05, origin = -y
material 
  colors = A:#60F B:#3C9 C:#0FC D:#400 E:#003
voxels
------------------------------- ------------------------------- ------------------------------- ------------------------------- ------------------------------- ------------------------------- ------------------------------- ------------------------------- ------------------------------- ------------------------------- ------------------------------- ------------------------------- ----------ABABAAB-------------- ---------ABBBABABBA------------ ---------BBBBBABAAB------------ --------ABBBBBABAA-BB---------- --------BBABABABBBAAB---------- -------BBBBAABABAAABA---------- ------ABBBBAABABAAABA---------- ------ABBBABABABBBAA----------- ------AAABBBBBABAAB------------ ------BBBBBBBBABAA------------- -------BBABBBABAB-------------- ---------BABABAA--------------- ------------------------------- ------------------------------- ------------------------------- ------------------------------- ------------------------------- ------------------------------- ------------------------------- 
------------------------------- ------------------------------- ------------------------------- ------------------------------- ------------------------------- ------------------------------- ----------------AA------------- ------------AAAAAA------------- ---------AAAAAAAAAA------------ --------AAAAAAAAAAAA----------- -------AAAAAAAAAAAAAA---------- -------AAAAAAAAAAAAAAA--------- ------AAAAAAAAAAAAAAAAAA------- ------AAAAAAAAAAAAAAAAAAAA----- -----AAAAAAAAAAAAAAAAAAAAA----- -----AAAAAAAAAAAAAAAAAAAAA----- -----AAAAAAAAAAAAAAAAAAAA------ ----AAA-AAAAAAAAAAAAAAAAA------ ----AA-AAAAAAAAAAAAAAAAAAA----- ---AAAAAAAAAAAAAAAAAAAAAAA----- ---AAAAAAAAAAAAAAAAAAAAAA------ ---AAAAAAAAAAAAAAAAAAAAAA------ ----AAAAAAAAAAAAAAAAAAAAA------ ----AAAAAAAAAAAAAAAAAAAA------- -----AAAAAAAAAAAAAAAAAAA------- ------AAAAAAAAAAAAAAAAA-------- --------AAAAAAAAAAAAAA--------- ----------AAAAAAAAAA----------- ------------------------------- ------------------------------- ------------------------------- 
------------------------------- ------------------------------- ------------------------------- -----------------AAA----------- -----------------AAA----------- ---------------AAAAAA---------- -------------AAAAAAAAA--------- ----------AAAAAAAAAAAA--------- -------AAAAAAAAAAAAAAA--------- -------A-AAAAAAAAAAAAA--------- ------A-AAAAAA--AAAA-AAAAA----- -----AA-AA-------AAAAAAAAAA---- -----A-AA---------AAAAA-AAAA--- ----AAAAA----------AAAAAA-AA--- ----A-AA-----------AAAAAAAAA--- ---AAAAA---------------AAAAA--- ---AAAAA--------------AAAAAA--- ---A-AAA--------------AAAAAA--- --AA-AA--------------AAAA-AA--- --A-AA---------------AAAA-AA--- --A-AA---------------AAAAAA---- --A-AA--------------AAAA-AA---- ---A-AA-------------AAAA-A----- ---A--AA-----------AAAA-A------ ----A--AAA--------AAAA--A------ ----AA--AAAAAAAAAAAAA--A------- -----AAA-AAAAAAAAAA---A-------- -------AAA----------AA--------- --------AAAAAAAAAAAA----------- --------------AAAA------------- ------------------------------- 
------------------------------- ------------------------------- ------------------AAAAA-------- -----------------AAAAAAA------- -----------------AAAAAAA------- -----------------AAAAAAA------- ------------------AAAAAA------- -------------------AAAAA------- --------A----------AAAAA------- ------AAA-----------AAAAAAAA--- -----A-A------------AAA---AA--- -----A-A--------------AAAA-AA-- ----A-A----------------AAAA-A-- ---A-A-------------------AA-A-- ---A-A--------------------A-A-- --A-A---------------------A-A-- --A-A---------------------AA--- --A-A--------------------AAAA-- -A--A--------------------AA-A-- -A-A---------------------A-A--- -A-A---------------------A-A--- --AA--------------------A--A--- --A-A-------------------A-A---- --A--A-----------------A-A----- ---A-AA---------------A-A------ ---A--AA-------------A-A------- ----A---A----------AA-A-------- -----AA--AAAAAAAAAA--AA-------- -------AA-----------A---------- ---------AAAAAAAAAAA----------- ------------------------------- 
------------------------------- ----------------------AAA------ --------------------AAAAAA----- --------------------AAA-AAA---- ---------------------AA-AA----- ----------------------A-AA----- ----------------------A-AAAA--- ----------------------A-AAAA--- ----------------------AAAAAAA-- -----AAA--------------AAAAA-A-- -----AA----------------AAAA-AA- ----A-A-------------------AA-A- ---A-A---------------------A-A- ---A-A---------------------A-A- --A-A----------------------AA-- --AA-----------------------AA-- -A-A-----------------------AA-- -A-A-----------------------AA-- -A-A-----------------------AA-- -AA-----------------------A-A-- -AA-----------------------A-A-- -A-A---------------------A-A--- -A-A--------------------A--A--- --A-A-------------------A-A---- --A-A------------------A-A----- ---A-A---------------AA-A------ ----A-AA------------A--A------- -----A--A---------AA--AA------- ------AA-AAAAAAAAA--AA--------- --------AAAAA----AAA----------- -------------BBAB-------------- 
-------------------------AA---- -----------------------AAAAA--- -----------------------AAAAA--- -----------------------AAA-A--- -----------------------AA-AAA-- -----------------------AAAAAA-- -----------------------AAAA-A-- -----------------------AAAA-AA- ------------------------AAAA-A- -----AA--------------------AAA- ----A-A--------------------AAA- ----AA----------------------AA- ---A-A----------------------AA- --A-A-----------------------AA- --AA------------------------AA- -A-A------------------------AC- -AA-------------------------AA- -AA-------------------------AC- A-A------------------------A-A- A-A------------------------A-A- -AA-----------------------A-A-- -AA-----------------------A-A-- -AA----------------------A-A--- -A-A--------------------A--A--- --A-A------------------A--A---- --A--A----------------A--A----- ---A--A--------------A--A------ ----A--A-----------AA--A------- -----AA-AAA---AAAAA--AA-------- -------AAA-AAA----AAA---------- ----------AAABBAAA------------- 
-------------------------AAAA-- -------------------------AA-A-- --------------------------A-A-- --------------------------A-AA- -------------------------AAA-A- ---------------------------A-A- ---------------------------A-A- ---------------------------AAA- ----------------------------A-A -----------------------------AA ----AAA----------------------AA ---A-A-----------------------AA ---AA------------------------AA --A-A-----------------------AA- -A-A------------------------AA- -AA-------------------------AC- -AA-------------------------AC- -A--------------------------AC- AA--------------------------AA- AA--------------------------AA- AA-------------------------A-A- -AA-----------------------A-A-- -AA-----------------------A-A-- -A-A---------------------A-A--- -A-A--------------------A-A---- --A-A-----------------AA--A---- ---A-A---------------A---A----- ----A-AA-----------AA--AA------ -----A--AA-------AA---A-------- ------AAA-AAAAAAA--AAA--------- ---------BAAAABABBB------------ 
---------------------------AAA- ---------------------------A-A- ---------------------------AAA- ---------------------------AA-A ----------------------------A-A ----------------------------A-A ----------------------------A-A -----------------------------AA -----------------------------AA -----------------------------AA -----AA----------------------AA ---AAA-----------------------AA --A-A------------------------AA --AA-------------------------AA -AA--------------------------AA -AA--------------------------AA -A---------------------------AA AA---------------------------AA BA--------------------------A-A AA--------------------------AA- AA-------------------------A-A- AA-------------------------AA-- -AA-----------------------A-A-- -AA----------------------A-A--- -A-A--------------------A--A--- --A-A------------------A--A---- ---A-A----------------A--A----- ----A-A-------------AA--A------ -----A-AA---------AA--AA------- ------AA-AAAAAAAAA-AAA--------- --------AAABAABBBBA------------ 
---------------------------AAA- ----------------------------AA- -----------------------------AA -----------------------------AA -----------------------------AA -----------------------------AB -----------------------------AA -----------------------------AA -----------------------------AB -----------------------------AB ----AA-----------------------AA ---A-A-----------------------AA --A-A------------------------AA -A-A-------------------------AA -AA--------------------------AA -AA--------------------------AC AA---------------------------AC BA---------------------------AC AE---------------------------AA BD--------------------------A-A AA--------------------------AA- BA-------------------------A-A- AA-------------------------AA-- -AA-----------------------A-A-- -A-A---------------------A-A--- --AA--------------------A-A---- --A-A------------------A-A----- ---AAAA--------------AA-AA----- -----A-AA----------AA--A------- ------AA-AAA---AAAA-AAA-------- --------ABBABBAABAAA----------- 
----------------------------AA- ----------------------------AA- -----------------------------AA -----------------------------AA -----------------------------AA -----------------------------AB -----------------------------AB -----------------------------AB -----------------------------AA -----------------------------AB ----AA-----------------------AA ---A-A------------------------A --A-A------------------------AA -A-A-------------------------AA -AA--------------------------AA -AA--------------------------AA AA---------------------------AC AA---------------------------AC AA---------------------------AA AD---------------------------AA BA--------------------------AA- BA--------------------------AA- BA-------------------------AA-- -AA-----------------------A-A-- -AA----------------------A-A--- --AA---------------------A-A--- --A-A------------------AA-A---- ---A-A----------------A-AA----- ----AAAA------------AA-A------- ------AAAAA------AAAAAA-------- --------AAABBABABABA----------- 
----------------------------AA- ----------------------------A-A -----------------------------AA ------------------------------A -----------------------------AA -----------------------------AA -----------------------------AB -----------------------------AA -----------------------------AA -----------------------------AB ----AA------------------------B ---A-A------------------------A --A-A-------------------------A -A-A--------------------------A -AA--------------------------AA -A---------------------------AC AA---------------------------AA BA---------------------------AC BA---------------------------AA AE---------------------------AA AA--------------------------AA- AA--------------------------AA- AA-------------------------AA-- -AA------------------------AA-- -AA-----------------------AA--- --AA---------------------A-A--- --A-A-------------------A-A---- ---A-A----------------AA-A----- ----AAAA------------AA-AA------ ------AAAAA------AAAAAA-------- --------AAABBBBABBBA----------- 
----------------------------AA- ----------------------------AA- -----------------------------AA -----------------------------AA -----------------------------AA -----------------------------AB -----------------------------AB -----------------------------AB -----------------------------AA -----------------------------AB ----AA-----------------------AA ---A-A------------------------A --A-A------------------------AA -A-A-------------------------AA -AA--------------------------AA -AA--------------------------AA AA---------------------------AC AA---------------------------AC AA---------------------------AA AD---------------------------AA BA--------------------------AA- BA--------------------------AA- BA-------------------------AA-- -AA-----------------------A-A-- -AA----------------------A-A--- --AA--------------------A--A--- --A-A------------------A--A---- ---A-A----------------A--A----- ----AAAA------------AA-AA------ ------AAAAA------AAAAAA-------- --------AAABBABABABA----------- 
---------------------------AAA- ----------------------------AA- -----------------------------AA -----------------------------AA -----------------------------AA -----------------------------AB -----------------------------AA -----------------------------AA -----------------------------AB -----------------------------AB ----AA-----------------------AA ---A-A-----------------------AA --A-A------------------------AA -A-A-------------------------AA -AA--------------------------AA -AA--------------------------AC AA---------------------------AC BA---------------------------AC AE---------------------------AA BD--------------------------A-A AA--------------------------AA- BA-------------------------A-A- AA------------------------A-A-- -AA-----------------------A-A-- -A-A---------------------A-A--- --AA--------------------A-A---- --A-A------------------A-A----- ---AAAA--------------AA-AA----- -----A-AA----------AA--A------- ------AA-AAA---AAAA-AAA-------- --------ABBABBAABAAA----------- 
---------------------------AAA- ---------------------------A-A- ---------------------------AAA- ---------------------------AA-A ----------------------------A-A ----------------------------A-A ----------------------------A-A -----------------------------AA -----------------------------AA -----------------------------AA ----AAA----------------------AA ----AA-----------------------AA --AAA------------------------AA --AA-------------------------AA -AA--------------------------AA -AA--------------------------AA -A--------------------------A-A AA---------------------------AA BA--------------------------A-A AA--------------------------AA- AA-------------------------A-A- AA-------------------------AA-- -AA-----------------------A-A-- -AA----------------------A-A--- -A-A--------------------A--A--- --A-A------------------A--A---- ---A-A----------------A--A----- ----A-A-------------AA--A------ -----A-AA---------AA--AA------- ------AA-AAAAAAAAA-AAA--------- --------AAABAABBBBA------------ 
-------------------------AAAA-- -------------------------AA-A-- --------------------------A-A-- --------------------------A-AA- -------------------------AAA-A- ---------------------------A-A- ---------------------------A-A- ---------------------------AAA- ----------------------------A-A ----------------------------A-A ----AAA----------------------AA ---A-A-----------------------AA ---AA------------------------AA --A-A-----------------------AA- -A-A------------------------AA- -AA-------------------------AC- -AA-------------------------AC- -A--------------------------AC- AA--------------------------AA- AA--------------------------AA- AA-------------------------A-A- -AA-----------------------A-A-- -AA----------------------A--A-- -A-A---------------------A-A--- -A-A--------------------A-A---- --A-A-----------------AA--A---- ---A-A---------------A---A----- ----A-AA-----------AA--AA------ -----A--AA-------AA---A-------- ------AAA-AAAAAAA--AAA--------- ---------BAAAABABBB------------ 
-------------------------AA---- -----------------------AAAAA--- -----------------------AAAAA--- -----------------------AAAAA--- -----------------------AA-AAA-- -----------------------AAAAAA-- -----------------------AAAA-A-- -----------------------AAAA-AA- ------------------------AAAA-A- -----AA--------------------A-A- ----A-A--------------------AAA- ----AA----------------------AA- ---A-A----------------------AA- --A-A-----------------------AA- --AA------------------------AA- -A-A------------------------AC- -AA-------------------------AA- -AA------------------------A-C- A-A------------------------A-A- A-A------------------------A-A- -AA-----------------------A-A-- -AA-----------------------A-A-- -AA----------------------A-A--- -A-A--------------------A--A--- --A-A------------------A--A---- --A--A----------------A--A----- ---A--A--------------A--A------ ----A--A-----------AA--A------- -----AA-AAA---AAAAA--AA-------- -------AAA-AAA----AAA---------- ----------AAABBAAA------------- 
------------------------------- ----------------------AAA------ --------------------AAAAAA----- --------------------AAA-AA----- ---------------------AA-AA----- ----------------------A-AA----- ----------------------AAAAAA--- ----------------------A-AAAA--- ----------------------AAAAAAA-- -----AAA--------------AAAAA-A-- -----AA----------------AAAA-AA- ----A-A-------------------AA-A- ---A-A---------------------A-A- ---A-A---------------------A-A- --A-A----------------------AA-- --AA-----------------------AA-- -A-A-----------------------AA-- -A-A-----------------------AA-- -A-A-----------------------AA-- -AA-----------------------A-A-- -AA-----------------------A-A-- -A-A---------------------A-A--- -A-A---------------------A-A--- --A-A-------------------A-A---- --A--A-----------------A-A----- ---A--A--------------AA-A------ ----A--A------------A--A------- -----A--A---------AA--AA------- ------AA-AAAAAAAAA--AA--------- --------AAAAA----AAA----------- -------------BBAB-------------- 
------------------------------- ------------------------------- ------------------AAAAA-------- -----------------AAAAAAA------- -----------------AAAAAAA------- -----------------AAAAAAA------- ------------------AAAAA-------- -------------------AAAAA------- --------A----------AAAAA------- ------AAA-----------AAAAAAAA--- -----A-A------------AAA---AA--- -----A-A-------------AAAAA-AA-- ----A-A----------------AAAAAA-- ---A--A------------------AA-A-- ---A-A--------------------A-A-- --A-AA--------------------A-A-- --A-A---------------------AA--- --A-A--------------------AA-A-- -A--A--------------------AA-A-- -A-A---------------------A-A--- -A-A---------------------A-A--- --AA--------------------A-A---- --A-A-------------------A-A---- --A--A-----------------A-A----- ---A--A---------------A-A------ ---A---A-------------A-A------- ----A---A----------AA-A-------- -----AA--AAAAAAAAAA--AA-------- -------AA----------AA---------- ---------AAAAAAAAAA------------ ------------------------------- 
------------------------------- ------------------------------- ------------------------------- -----------------AAA----------- -----------------AAA----------- ---------------AAAAAA---------- -------------AAAAAAAA---------- ----------AAAAAAAAAAAA--------- -------AAAAAAAAAAAAAAA--------- -------A-AAAAAAAAAAAAA--------- ------A-AAAAAA--AAAA-AAAAA----- -----AA-AA-------AAAA-AAAAA---- -----A-AA---------AAAAA-AAA---- ----AA-AA----------AAAAAAAAA--- ----A-AA-----------AAAAAAAAA--- ---AA-AA--------------AAAAAA--- ---AAAAA--------------AAAAAA--- ---A-AAA--------------AAAAAA--- --AA-AA--------------AAAAAAA--- --A-AA---------------AAAA-AA--- --A-AA---------------AAAAAA---- --AAAA--------------AAAA-AA---- ---A-AA-------------AAAA-A----- ---A--AAA----------AAAA-A------ ----A--AAA-------AAAAA--A------ ----AA--AAAAAAAAAAAAA--A------- -----AAA-AAAAAAAAAA---A-------- -------AAA----------AA--------- --------AAAAAAAAAAAA----------- ---------------AAA------------- ------------------------------- 
------------------------------- ------------------------------- ------------------------------- ------------------------------- ------------------------------- ------------------------------- ----------------AA------------- ------------AAAAAA------------- ---------AAAAAAAAAA------------ --------AAAAAAAAAAAA----------- -------AAAAAAAAAAAAAA---------- -------AAAAAAAAAAAAAAA--------- ------AAAAAAAAAAAAAAAAAA------- ------AAAAAAAAAAAAAAAAAAAA----- -----AAAAAAAAAAAAAAAAAAAAA----- -----AAAAAAAAAAAAAAAAAAAAA----- -----AAAAAAAAAAAAAAAAAAAA------ ----AAA-AAAAAAAAAAAAAAAAA------ ----AA-AAAAAAAAAAAAAAAAAAA----- ---AAAAAAAAAAAAAAAAAAAAAAA----- ---AAAAAAAAAAAAAAAAAAAAAA------ ----AAAAAAAAAAAAAAAAAAAAA------ ----AAAAAAAAAAAAAAAAAAAAA------ ----AAAAAAAAAAAAAAAAAAAA------- -----AAAAAAAAAAAAAAAAAAA------- ------AAAAAAAAAAAAAAAAA-------- --------AAAAAAAAAAAAAA--------- ----------AAAAAAAAAA----------- ------------------------------- ------------------------------- ------------------------------- 
------------------------------- ------------------------------- ------------------------------- ------------------------------- ------------------------------- ------------------------------- ------------------------------- ------------------------------- ------------------------------- ------------------------------- ------------------------------- ------------------------------- ----------ABABAAB-------------- ---------ABBBABABBA------------ ---------BBBBBABAAB------------ --------ABBBBBABAA-BB---------- --------BBABABABBBAAB---------- -------BBBBAABABAAABA---------- ------ABBBBAABABAAABA---------- ------ABBBABABABBBAA----------- ------AAABBBBBABAAB------------ ------BBBBBBBBABAA------------- -------BBABBBABAB-------------- ---------BABABAA--------------- ------------------------------- ------------------------------- ------------------------------- ------------------------------- ------------------------------- ------------------------------- ------------------------------- 
