model
size = 30 24 13, scale = 0.05, origin = -y
material 
  colors = A:#222 B:#CF0 C:#777
voxels
------------------------------ ------------------------------ ------------------------------ ------------------------------ --A------------------------A-- --A------------------------A-- --A------------------------A-- --A------------------------A-- --A------------------------A-- ------------------------------ ------------------------------ ------------------------------ ------------------------------ ------------------------------ ------------------------------ ------------------------------ ------------------------------ ------------------------------ ------------------------------ ------------------------------ ------------------------------ ------------------------------ ------------------------------ ------------------------------ 
------------------------------ ------------------------------ ------------------------------ --A------------------------A-- --BA----------------------AB-- --BA----------------------AB-- --BA----------------------AB-- --BA----------------------AB-- --BA----------------------AB-- --A------------------------A-- ------------------------------ ------------------------------ ------------------------------ ------------------------------ ------------------------------ ------------------------------ ------------------------------ ------------------------------ ------------------------------ ------------------------------ ------------------------------ ------------------------------ ------------------------------ ------------------------------ 
------------------------------ ------------------------------ --A------------------------A-- --BA----------------------AB-- --BA----------------------AB-- -A--------------------------A- -A--------------------------A- -A--------------------------A- --BA----------------------AB-- --BA----------------------AB-- --A------------------------A-- ------------------------------ ------------------------------ ------------------------------ ------------------------------ ------------------------------ ------------------------------ ------------------------------ ------------------------------ ------------------------------ ------------------------------ ------------------------------ ------------------------------ ------------------------------ 
------------------------------ --A------------------------A-- --BA----------------------AB-- --BA----------------------AB-- -A--------------------------A- A----------------------------A A----------------------------A A----------------------------A -A--------------------------A- --BA----------------------AB-- --BA----------------------AB-- --A------------------------A-- ------------------------------ ------------------------------ ------------------------------ ------------------------------ ------------------------------ ------------------------------ ------------------------------ ------------------------------ ------------------------------ ------------------------------ ------------------------------ ------------------------------ 
--A------------------------A-- --BA----------------------AB-- --BA----------------------AB-- -A--------------------------A- AA--------------------------AA CA--------------------------AC A----------------------------A CA--------------------------AC AA--------------------------AA -A--------------------------A- --BA----------------------AB-- --BA----------------------AB-- --AA----------------------AA-- ---A----------------------A--- ---AA--------------------AA--- ----A--------------------A---- ----A--------------------A---- ----AA------------------AA---- -----AA----------------AA----- ------A----------------A------ ------AA--------------AA------ -------AAA----------AAA------- ---------AAAA----AAAA--------- ------------AAAAAA------------ 
--A------------------------A-- --BA----------------------AB-- -A--------------------------A- A----------------------------A CA--------------------------AC C----------------------------C C----------------------------C C----------------------------C CA--------------------------AC A----------------------------A -A--------------------------A- --BA----------------------AB-- --AA----------------------AA-- ---A----------------------A--- ---AA--------------------AA--- ----A--------------------A---- ----A--------------------A---- ----AA------------------AA---- -----AA----------------AA----- ------A----------------A------ ------AA--------------AA------ -------AAA----------AAA------- ---------AAAA----AAAA--------- ------------AAAAAA------------ 
--A------------------------A-- --BA----------------------AB-- -A--------------------------A- A----------------------------A A----------------------------A C----------------------------C A----------------------------A C----------------------------C A----------------------------A A----------------------------A -A--------------------------A- --BB----------------------BB-- --BB----------------------BB-- ---B----------------------B--- ---BB--------------------BB--- ----B--------------------B---- ----B--------------------B---- ----BB------------------BB---- -----BB----------------BB----- ------B----------------B------ ------BB--------------BB------ -------BBB----------BBB------- ---------BBBB----BBBB--------- ------------BBBBBB------------ 
--A------------------------A-- --BA----------------------AB-- -A--------------------------A- A----------------------------A CA--------------------------AC C----------------------------C C----------------------------C C----------------------------C CA--------------------------AC A----------------------------A -A--------------------------A- --BA----------------------AB-- --AA----------------------AA-- ---A----------------------A--- ---AA--------------------AA--- ----A--------------------A---- ----A--------------------A---- ----AA------------------AA---- -----AA----------------AA----- ------A----------------A------ ------AA--------------AA------ -------AAA----------AAA------- ---------AAAA----AAAA--------- ------------AAAAAA------------ 
--A------------------------A-- --BA----------------------AB-- --BA----------------------AB-- -A--------------------------A- AA--------------------------AA CA--------------------------AC A----------------------------A CA--------------------------AC AA--------------------------AA -A--------------------------A- --BA----------------------AB-- --BA----------------------AB-- --AA----------------------AA-- ---A----------------------A--- ---AA--------------------AA--- ----A--------------------A---- ----A--------------------A---- ----AA------------------AA---- -----AA----------------AA----- ------A----------------A------ ------AA--------------AA------ -------AAA----------AAA------- ---------AAAA----AAAA--------- ------------AAAAAA------------ 
------------------------------ --A------------------------A-- --BA----------------------AB-- --BA----------------------AB-- -A--------------------------A- A----------------------------A A----------------------------A A----------------------------A -A--------------------------A- --BA----------------------AB-- --BA----------------------AB-- --A------------------------A-- ------------------------------ ------------------------------ ------------------------------ ------------------------------ ------------------------------ ------------------------------ ------------------------------ ------------------------------ ------------------------------ ------------------------------ ------------------------------ ------------------------------ 
------------------------------ ------------------------------ --A------------------------A-- --BA----------------------AB-- --BA----------------------AB-- -A--------------------------A- -A--------------------------A- -A--------------------------A- --BA----------------------AB-- --BA----------------------AB-- --A------------------------A-- ------------------------------ ------------------------------ ------------------------------ ------------------------------ ------------------------------ ------------------------------ ------------------------------ ------------------------------ ------------------------------ ------------------------------ ------------------------------ ------------------------------ ------------------------------ 
------------------------------ ------------------------------ ------------------------------ --A------------------------A-- --BA----------------------AB-- --BA----------------------AB-- --BA----------------------AB-- --BA----------------------AB-- --BA----------------------AB-- --A------------------------A-- ------------------------------ ------------------------------ ------------------------------ ------------------------------ ------------------------------ ------------------------------ ------------------------------ ------------------------------ ------------------------------ ------------------------------ ------------------------------ ------------------------------ ------------------------------ ------------------------------ 
------------------------------ ------------------------------ ------------------------------ ------------------------------ --A------------------------A-- --A------------------------A-- --A------------------------A-- --A------------------------A-- --A------------------------A-- ------------------------------ ------------------------------ ------------------------------ ------------------------------ ------------------------------ ------------------------------ ------------------------------ ------------------------------ ------------------------------ ------------------------------ ------------------------------ ------------------------------ ------------------------------ ------------------------------ ------------------------------ 
