model
size = 23 30 29, scale = 0.05, origin = -y
material 
  colors = A:#465D4C B:#444 C:#E2943B D:#777 E:#888 F:#E8B647 G:#BBB H:#555
voxels
----------------------- ----------------------- ----------------------- ----------------------- ----------------------- ----------------------- ----------------------- ----------------------- ----------------------- ----------------------- ----------------------- ----------------------- ----------------------- ----------------------- ----------------------- ----------------------- ----------------------- ----------------------- -------CCCCCCCCC------- -------CCCCCCCCC------- ----------------------- ----------------------- ----------------------- ----------------------- ----------------------- ----------------------- ----------------------- ----------------------- ----------------------- ----------------------- 
----------------------- ----------------------- ----------------------- ----------------------- ----------------------- ----------------------- ----------------------- ----------------------- ----------------------- ----------------------- ----------------------- ----------------------- ----------------------- ----------------------- ----------------------- ----------------------- ----------------------- ----------------------- ------CCEDDDDDECC------ ------CCCFFFFFCCC------ ----------------------- ----------------------- ----------------------- ----------------------- ----------------------- ----------------------- ----------------------- ----------------------- ----------------------- ----------------------- 
----------------------- ----------------------- ----------------------- ----------------------- ----------------------- ----------------------- ----------------------- ----------------------- ----------------------- ----------------------- ----------------------- ----------------------- ----------------------- ----------------------- ----------------------- ----------------------- ----------------------- ----------------------- -----CEEDEEEEEDEEC----- -----CCCFCCCCCFCCC----- ----------------------- ----------------------- ----------------------- ----------------------- ----------------------- ----------------------- ----------------------- ----------------------- ----------------------- ----------------------- 
----------------------- ----------------------- ----------------------- ----------------------- ----------------------- ----------------------- ----------------------- ----------------------- ----------------------- ----------------------- ----------------------- ----------------------- ----------------------- ----------------------- ----------------------- ----------------------- ----------------------- ----------------------- ----CEEDEDDDDDEDEEC---- ----CCCFCFFFFFCFCCC---- ----------------------- ----------------------- ----------------------- ----------------------- ----------------------- ----------------------- ----------------------- ----------------------- ----------------------- ----------------------- 
----------------------- ----------------------- ----------------------- ----------------------- ----------------------- ----------------------- ----------------------- ----------------------- ----------------------- ----------------------- ----------------------- ----------------------- ----------------------- ----------------------- ----------------------- ----------------------- ----------------------- ----------------------- ---CEEDEDEEEEEDEDEEC--- ---CCCFCFCCCCCFCFCCC--- ----------------------- ----------------------- ----------------------- ----------------------- ----------------------- ----------------------- ----------------------- ----------------------- ----------------------- ----------------------- 
----------------------- ----------------------- ----------------------- ----------------------- ----------------------- ----------------------- ----------------------- ----------------------- ----------------------- ----------------------- ----------------------- ----------------------- ----------------------- ----------------------- ----------------------- ----------------------- ----------------------- ----------------------- ---CEDEDEDDDDDEDEDEC--- ---CCFCFCFFFFFCFCFCC--- ----------------------- ----------------------- ----------------------- ----------------------- ----------------------- ----------------------- ----------------------- ----------------------- ----------------------- ----------------------- 
----------------------- ----------------------- ----------------------- ----------------------- ----------------------- ----------------------- ----------------------- ----------------------- ----------------------- ----------------------- ----------------------- ----------------------- ----------------------- ----------------------- ----------------------- ----------------------- ----------------------- ----------------------- --CEDEDEDEEEEEDEDEDEC-- --CCFCFCFCCCCCFCFCFCC-- ----------------------- ----------------------- ----------------------- ----------------------- ----------------------- ----------------------- ----------------------- ----------------------- ----------------------- ----------------------- 
----------------------- ----------------------- ----------------------- ----------------------- ----------------------- ----------------------- ----------------------- ----------------------- ----------------------- ----------------------- ----------------------- ----------------------- ----------------------- ----------------------- ----------------------- ----------------------- ----------------------- ----------------------- --CDEDEDEEDDDEEDEDEDC-- --CFCFCFCCCCCCCFCFCFC-- ---------G-G-G--------- ---------GGGGG--------- --------GGGGGGG-------- --------G--G--G-------- --------GGGGGGG-------- ----------------------- ----------------------- ----------------------- ----------------------- ----------------------- 
----------------------- ----------------------- ----------------------- ----------------------- ----------------------- ----------------------- ----------------------- ----------------------- ----------------------- ----------------------- ----------------------- ----------------------- ----------------------- ----------------------- ----------------------- ----------------------- ----------------------- ----------------------- --CDEDEDEDEEEDEDEDEDC-- --CFCFCAAAAAAAAACFCFC-- ------AAAHBHBHAAA------ ------AAAHHHHHAAA------ ------AAHHHHHHHAA------ ------AAHBBHBBHAA------ -------AHHHHHHHA------- -------AAAAAAAAA------- ----------------------- ----------------------- ----------------------- ----------------------- 
----------------------- ----------------------- ----------------------- ----------------------- ----------------------- ----------------------- ----------------------- ----------------------- ----------------------- ----------------------- ----------------------- ----------------------- ----------------------- ----------------------- ----------------------- ----------------------- ----------------------- ----------------------- --CDEDEBBBBBBBBBEDEDC-- --CFAAABBBBBBBBBAAAFC-- ----AAA----B----AAA---- ----AAA----B----AAA---- -----AA----B----AA----- -----AA----B----AA----- -----AA----B----AA----- ------AAAAAAAAAAA------ --------AAAAAAA-------- ----------------------- ----------------------- ----------------------- 
----------------------- ----------------------- ----------------------- ----------------------- ----------------------- ----------------------- ----------------------- ----------------------- ----------------------- ----------------------- ----------------------- ----------------------- ----------------------- ----------------------- ----------------------- ----------------------- ----------------------- ----------------------- --CDEBB---------BBEDC-- --CAABB---------BBAAC-- ---AA------------AAA--- ---AA------------AAA--- ----AA-----------AA---- -----A-----------A----- -----AA---------AA----- ------AAAAABAAAAA------ -------AAAAAAAAA------- ----------------------- ----------------------- ----------------------- 
----------------------- ----------------------- ----------------------- ----------------------- ----------------------- ----------------------- ----------------------- ----------------------- ----------------------- ----------------------- ----------------------- ----------------------- ----------------------- --A-----------------A-- --A-----------------A-- --A-----------------A-- --A-----------------A-- --A-----------------A-- --ABBB-----------BBBA-- --AABB-----------BBAA-- --AA-B-----------BAAA-- --AA-B-----------BAAA-- ---AAB-----------BAA--- ----AB-----------BA---- -----AA---------AA----- -----AA---------AA----- -------AAAABAAAA------- ----------AAA---------- ----------------------- ----------------------- 
----------------------- ----------------------- ----------------------- ----------------------- ----------------------- ----------------------- ----------------------- ----------------------- ----------------------- --A-----------------A-- --A-----------------A-- --A-----------------A-- --A-----------------A-- --A-----------------A-- --A-----------------A-- --A-----------------A-- --A-----------------A-- --A-----------------A-- --AB---------------BA-- --AB---------------BA-- --A-----------------A-- --A-----------------A-- --AA---------------AA-- ---A---------------A--- ----AAB---------BAA---- ----AAB---------BAA---- ------AAAAABAAAAA------ --------AAAAAAA-------- ----------------------- ----------------------- 
----------------------- ----------------------- ----------------------- ----------------------- ----------------------- ----------------------- ----------------------- ----------------------- -AA-----------------AA- -AA-----------------AA- -AA-----------------AA- -AA-----------------AA- -AA-----------------AA- -AA-----------------AA- -AA-----------------AA- -AA-----------------AA- -AA-----------------AA- -AA-----------------AA- -AAB---------------BAA- -AAB---------------BAG- -AA-----------------AG- -AA-----------------AA- --A----------------AA-- --A----------------AA-- ---A---------------A--- ---AAA-----------AAA--- -----AABAAABAAABAA----- -------AAAAAAAAA------- ----------------------- ----------------------- 
----------------------- ----------------------- ----------------------- ----------------------- ----------------------- ----------------------- ----------------------- AA--------------------- AA-------------------AA AB-------------------BA AB-------------------BA AB-------------------BA AB-------------------BA AB-------------------BA AB-------------------BA AA-------------------AA AA-------------------AA AA-------------------AA AAB-----------------BAA -AB-----------------BG- -A-------------------G- -A-------------------A- --A-----------------A-- --A-----------------A-- ---A---------------A--- ---AAA-----------AAA--- -----AAAB-----BAAA----- -------AAAABAAAA------- ----------AAA---------- ----------------------- 
----------------------- ----------------------- ----------------------- ----------------------- ----------------------- ----------------------- ----------------------- AA-------------------AA AB-------------------BA AB-------------------BA AD-------------------DA AD-------------------DA AD-------------------DA AD-------------------DA AB-------------------BA AB-------------------BA AA-------------------AA AA-------------------AA AAB-----------------BAA AAB-----------------BAA AA-------------------AA -A-------------------A- -AA-----------------AA- --A-----------------A-- --AA---------------AA-- ---AAA-----------AAA--- ----AAAA-------AAAA---- ------AAABABABAAA------ ---------AAAAA--------- ----------------------- 
----------------------- ----------------------- ----------------------- ----------------------- ----------------------- ----------------------- A---------------------A AA-------------------AA AB-------------------BA AD-------------------DA AB-------------------BA AD-------------------DA AB-------------------BA AD-------------------DA AD-------------------DA AB-------------------BA AA-------------------AA AA-------------------AA AB-------------------BA AB-------------------BA AA-------------------AA AA-------------------AA -AA-----------------AA- -AA-----------------AA- --AA---------------AA-- --AAAA-----------AAAA-- ----AAAA-------AAAA---- ------AAAABBBAAAA------ --------AAAAAAA-------- ----------CCC---------- 
C---------------------C C---------------------C C---------------------C C---------------------C C---------------------C C---------------------C C---------------------C CA-------------------AC AB-------------------BA AD-------------------DA AD-------------------DA AB-------------------BA AD-------------------DA AB-------------------BA AD-------------------DA AB-------------------BA AA-------------------AA AA-------------------AA AB-------------------BA AB-------------------BA AB-------------------BA AB-------------------BA -AB-----------------BA- -AB-----------------BA- --AB---------------BA-- --AABB-----------BBAA-- ----AABB-------BBAA---- ------AABBBBBBBAA------ --------AAACAAA-------- ----------CCC---------- 
C---------------------C C---------------------C C---------------------C C---------------------C C---------------------C C---------------------C C---------------------C CA-------------------AC AB-------------------BA AD-------------------DA AB-------------------BA AD-------------------DA AB-------------------BA AD-------------------DA AD-------------------DA AB-------------------BA AA-------------------AA AA-------------------AA AB-------------------BA AB-------------------BA AA-------------------AA AA-------------------AA -AA-----------------AA- -AA-----------------AA- --AA---------------AA-- --AAAA-----------AAAA-- ----AAAA-------AAAA---- ------AAAABBBAAAA------ --------AAAAAAA-------- ----------CCC---------- 
----------------------- ----------------------- ----------------------- ----------------------- ----------------------- ----------------------- A---------------------A AA-------------------AA AB-------------------BA AD-------------------DA AD-------------------DA AB-------------------BA AD-------------------DA AB-------------------BA AD-------------------DA AB-------------------BA AA-------------------AA AA-------------------AA AB-------------------BA AB-------------------BA AA-------------------AA AA-------------------AA -AA-----------------AA- -AA-----------------AA- --AA---------------AA-- --AAAA-----------AAAA-- ----AAAAAB---BAAAAA---- ------AAABABABAAA------ ---------AAAAA--------- ----------------------- 
----------------------- ----------------------- ----------------------- ----------------------- ----------------------- ----------------------- ----------------------- AA-------------------AA AB-------------------BA AB-------------------BA AD-------------------DA AD-------------------DA AD-------------------DA AD-------------------DA AB-------------------BA AB-------------------BA AA-------------------AA AA-------------------AA AB-------------------BA AB-------------------BA AA-------------------AA -A-------------------A- -AA-----------------AA- --A-----------------A-- --AA---------------AA-- ---AAA-----------AAA--- -----AAABA---ABAAA----- -------AAAABAAAA------- ----------AAA---------- ----------------------- 
----------------------- ----------------------- ----------------------- ----------------------- ----------------------- ----------------------- ----------------------- ----------------------- AA-------------------AA AB-------------------BA AB-------------------BA AB-------------------BA AB-------------------BA AB-------------------BA AB-------------------BA AA-------------------AA AA-------------------AA AA-------------------AA AAB-----------------BAA AAB-----------------BAA -A-------------------A- -A-------------------A- --A-----------------A-- --A-----------------A-- ---A---------------A--- ---AAAAB-------BAAAA--- -----AAAAAABAAABAA----- -------AAAAAAAAA------- ----------------------- ----------------------- 
----------------------- ----------------------- ----------------------- ----------------------- ----------------------- ----------------------- ----------------------- ----------------------- -A-------------------A- -A-------------------A- -A-------------------A- -A-------------------A- -A-------------------A- -A-------------------A- -A-------------------A- -A-------------------A- -A-------------------A- -A-------------------A- -AB-----------------BA- -AB-----------------BA- -A-------------------A- -A-------------------A- --A-----------------A-- --A-----------------A-- ---AAAB---------BAAA--- ---AAABA-------ABAAA--- -----AAAAAABAAAAAA----- -------AAAAAAAAA------- ----------------------- ----------------------- 
----------------------- ----------------------- ----------------------- ----------------------- ----------------------- ----------------------- ----------------------- ----------------------- --A-----------------AA- -AA-----------------AA- -AA-----------------AA- -AA-----------------AA- -AA-----------------AA- -AA-----------------AA- -AA-----------------AA- -AA-----------------AA- -AA-----------------AA- -AA-----------------AA- -AAB---------------BAA- -AAB---------------BAA- -AA-----------------AA- --A-----------------A-- --A-----------------A-- ---AAB-----------BAA--- ---AABA---------ABAA--- ----AAAA-------AAAA---- ------AAAAABAAAAA------ ---------AAAAA--------- ----------------------- ----------------------- 
----------------------- ----------------------- ----------------------- ----------------------- ----------------------- ----------------------- ----------------------- ----------------------- --A-----------------A-- --A-----------------A-- --A-----------------A-- --A-----------------A-- --A-----------------A-- --A-----------------A-- --A-----------------A-- --A-----------------A-- --A-----------------A-- --A-----------------A-- --ABB-------------BBA-- --ABB-------------BBA-- --AAB-------------BAA-- --AAB-------------BAA-- ---AB-------------BA--- ---ABA-----------ABA--- ----AAA---------AAA---- -----AAAAAABAAAAAA----- -------AAAAAAAAA------- ----------------------- ----------------------- ----------------------- 
----------------------- ----------------------- ----------------------- ----------------------- ----------------------- ----------------------- ----------------------- ----------------------- ----------------------- --A-----------------A-- --AA---------------AA-- --AA---------------AA-- --AA---------------AA-- --AA---------------AA-- --AA---------------AA-- --AA---------------AA-- --AA---------------AA-- --AA---------------AA-- --AAB-------------BAA-- --AAB-------------BAA-- --AAA-------------AAA-- ---AA-------------AA--- ----A-------------A---- ----AA-----------AA---- -----AA---------AA----- -------AAAABAAAA------- ---------AAAAA--------- ----------------------- ----------------------- ----------------------- 
----------------------- ----------------------- ----------------------- ----------------------- ----------------------- ----------------------- ----------------------- ----------------------- ----------------------- ----------------------- ---AA-------------AA--- ---AA-------------AA--- ---AA-------------AA--- ---AA-------------AA--- ---AA-------------AA--- ---AA-------------AA--- ---AA-------------AA--- ---AA-------------AA--- ---AABB---------BBAA--- ---AABB---------BBAA--- ---AAA-----------AAA--- ----AA-----------AA---- -----A-----------A----- -----A-----------A----- ------AAAAABAAAAA------ ---------AAAAA--------- ----------------------- ----------------------- ----------------------- ----------------------- 
----------------------- ----------------------- ----------------------- ----------------------- ----------------------- ----------------------- ----------------------- ----------------------- ----------------------- ----------------------- ----------------------- ----A-------------A---- ----AA-----------AA---- ----AAA---------AAA---- ----AAAAAAAAAAAAAAA---- ----AAAAAAAAAAAAAAA---- ----AAAAAAAAAAAAAAA---- ----AAAAAAAAAAAAAAA---- ----AAABBBBBBBBBAAA---- ----AAABBBBBBBBBAAA---- ----AAAAAAABAAAAAAA---- -----AAAAAABAAAAAA----- ------AAAAABAAAAA------ ------AAAAABAAAAA------ ---------AAAAA--------- ----------------------- ----------------------- ----------------------- ----------------------- ----------------------- 
----------------------- ----------------------- ----------------------- ----------------------- ----------------------- ----------------------- ----------------------- ----------------------- ----------------------- ----------------------- ----------------------- ----------------------- ----------------------- ----------------------- -------AAAAAAAAA------- ------AAAAAAAAAAA------ ------AAAAAAAAAAA------ ------AAAAAAAAAAA------ ------AAAAAAAAAAA------ ------AAAAAAAAAAA------ ------AAAAAAAAAAA------ -------AAAAAAAAA------- --------AAAAAAA-------- ---------AAAAA--------- ----------------------- ----------------------- ----------------------- ----------------------- ----------------------- ----------------------- 
