model
size = 23 13 29, scale = 0.05, origin = -y
material 
  colors = A:#FBE251 B:#E83015 C:#444 D:#FFF E:#FFFFFB F:#111 G:#FCFAF2 H:#DA2B14
voxels
-------BBBBBBBBB------- ----------------------- -------BBBBBBBBB------- ----------------------- ----------------------- ----------------------- ----------------------- ----------------------- ----------------------- ----------------------- ----------------------- ----------------------- ----------------------- 
------BBBBBBBBBBB------ ----------------------- ------BBBBHBHBBBB------ ----------------------- ----------------------- ----------------------- ----------------------- ----------------------- ----------------------- ----------------------- ----------------------- ----------------------- ----------------------- 
-----BBBBBBBBBBBBB----- --------DDDDDDDD------- -----BBBBBBBBBBBBB----- ----------------------- ----------------------- ----------------------- ----------------------- ----------------------- ----------------------- ----------------------- ----------------------- ----------------------- ----------------------- 
----BBBBBBBBBBBBBBB---- -------DDDDDDDDDD------ ----BBBBBBBBBBBBBBB---- ----------------------- ----------------------- ----------------------- ----------------------- ----------------------- ----------------------- ----------------------- ----------------------- ----------------------- ----------------------- 
---BBBBBBBBBBBBBBBBB--- ------DDDDDDDDDDDD----- ---BBBBBBBBBBBBBBBBB--- ----------------------- ----------------------- ----------------------- ----------------------- ----------------------- ----------------------- ----------------------- ----------------------- ----------------------- ----------------------- 
---BBBBBBBBBBBBBBBBB--- -----DDDDDDDDDDDDD----- ---BBBBBBBBBBBBBBBBB--- ----------------------- ----------------------- ----------------------- ----------------------- ----------------------- ----------------------- ----------------------- ----------------------- ----------------------- ----------------------- 
--BBBBBBBBBBBBBBBBBBB-- ----DDDDDDDDDDDDDDD---- --BBBBBBBBBBBBBBBBBBB-- ----------------------- ----------------------- ----------------------- ----------------------- ----------------------- ----------------------- ----------------------- ----------------------- ----------------------- ----------------------- 
--BBBBBBBBBBBBBBBBBBB-- ----DDDDDDDDDDDDDDD---- --BBBBBBBBBBBBBBBBBBB-- ---------EE-EE--------- --------E--E--E-------- --------E--E--E-------- --------EEEEEEE-------- ---------EE-EE--------- ----------------------- ----------------------- ----------------------- ----------------------- ----------------------- 
--BBBBBBBBBBBBBBBBBBB-- --BBBBBBBBBBBBBBBBBBB-- --BBBBBAAAAAAAAABBBBB-- -------AAEEAEEAA------- -------AEFCEFCEA------- -------AEFFEFFEA------- -------AEEEEEEEA------- -------AAEEAEEAA------- --------AAAAAAA-------- ----------------------- ----------------------- ----------------------- ----------------------- 
--BBBBB--------BBBBBB-- --B----CCCCCCCCCBBBBB-- --BBAAACCCCCCCCCAAABB-- ----AAA----C----AAA---- ----AAA----C----AAA---- -----AA----C----AA----- -----AA----C----AA----- ------A----C----A------ -------AAAAAAAAA------- ---------AAAAA--------- ----------------------- ----------------------- ----------------------- 
----------------------- --BBBCC---------CCBBB-- --BAACC---------CCAAB-- ---AA------------AAA--- ---AA------------AAA--- -----A-----------A----- -----A-----------A----- -----AA---------AA----- ------AAAAACAAAAA------ --------AAAAAAA-------- ----------------------- ----------------------- ----------------------- 
----------------------- --ACCC-----------CCCA-- --AACC-----------CCAA-- --AA-C-----------CAAA-- --AA-C-----------CAAA-- ----AC-----------CA---- ----AC-----------CA---- -----AA---------AA----- -----AA---------AA----- -------AAAACAAAA------- ----------AAA---------- ----------------------- ----------------------- 
----------------------- --AC---------------CA-- --AC---------------CA-- --A-----------------A-- --A-----------------A-- ---A---------------A--- ---A---------------A--- ----AAC---------CAA---- ----AAC---------CAA---- ------AAAAACAAAAA------ --------AAAAAAA-------- ----------------------- ----------------------- 
----------------------- -AAC---------------CAA- -AAC---------------CAG- -AA-----------------AG- -AA-----------------AA- --A----------------AA-- --A----------------AA-- ---A---------------A--- ---AAA-----------AAA--- -----AACAAACAAACAA----- -------AAAAAAAAA------- ----------------------- ----------------------- 
----------------------- -AC-----------------CA- -AC-----------------CG- -A-------------------G- -A-------------------A- --A-----------------A-- --A-----------------A-- ---A---------------A--- ---AAA-----------AAA--- -----AAAC-----CAAA----- -------AAAACAAAA------- ----------AAA---------- ----------------------- 
----------------------- AAC-----------------CAA AAC-----------------CAA AA-------------------AA -A-------------------A- -AA-----------------AA- --A-----------------A-- --AA---------------AA-- ---AAA-----------AAA--- ----AAAA-------AAAA---- ------AAACACACAAA------ ---------AAAAA--------- ----------------------- 
----------------------- AC-------------------CA AC-------------------CA AA-------------------AA AA-------------------AA -AA-----------------AA- -AA-----------------AA- --AA---------------AA-- --AAAA-----------AAAA-- ----AAAA-------AAAA---- ------AAAACCCAAAA------ --------AAAAAAA-------- ----------BBB---------- 
----------------------- AC-------------------CA AC-------------------CA AC-------------------CA AC-------------------CA -AC-----------------CA- -AC-----------------CA- --AC---------------CA-- --AACC-----------CCAA-- ----AACC-------CCAA---- ------AACCCCCCCAA------ --------AAABAAA-------- ----------BBB---------- 
----------------------- AC-------------------CA AC-------------------CA AA-------------------AA AA-------------------AA -AA-----------------AA- -AA-----------------AA- --AA---------------AA-- --AAAA-----------AAAA-- ----AAAA-------AAAA---- ------AAAACCCAAAA------ --------AAAAAAA-------- ----------BBB---------- 
----------------------- AC-------------------CA AC-------------------CA AA-------------------AA AA-------------------AA -AA-----------------AA- -AA-----------------AA- --AA---------------AA-- --AAAA-----------AAAA-- ----AAAAAC---CAAAAA---- ------AAACACACAAA------ ---------AAAAA--------- ----------------------- 
----------------------- AC-------------------CA AC-------------------CA AA-------------------AA -A-------------------A- -AA-----------------AA- --A-----------------A-- --AA---------------AA-- ---AAA-----------AAA--- -----AAACA---ACAAA----- -------AAAACAAAA------- ----------AAA---------- ----------------------- 
----------------------- AAC-----------------CAA AAC-----------------CAA -A-------------------A- -A-------------------A- --A-----------------A-- --A-----------------A-- ---A---------------A--- ---AAAAC-------CAAAA--- -----AAAAAACAAACAA----- -------AAAAAAAAA------- ----------------------- ----------------------- 
----------------------- -AC-----------------CA- -AC-----------------CA- -A-------------------A- -A-------------------A- --A-----------------A-- --A-----------------A-- ---AAAC---------CAAA--- ---AAACA-------ACAAA--- -----AAAAAACAAAAAA----- -------AAAAAAAAA------- ----------------------- ----------------------- 
----------------------- -AAC---------------CAA- -AAC---------------CAA- -AA-----------------AA- --A-----------------A-- --A-----------------A-- ---AAC-----------CAA--- ---AACA---------ACAA--- ----AAAA-------AAAA---- ------AAAAACAAAAA------ ---------AAAAA--------- ----------------------- ----------------------- 
----------------------- --ACC-------------CCA-- --ACC-------------CCA-- --AAC-------------CAA-- --AAC-------------CAA-- ---AC-------------CA--- ---ACA-----------ACA--- ----AAA---------AAA---- -----AAAAAACAAAAAA----- -------AAAAAAAAA------- ----------------------- ----------------------- ----------------------- 
----------------------- --AAC-------------CAA-- --AAC-------------CAA-- --AAA-------------AAA-- --AAA-------------AAA-- ----A-------------A---- ----AA-----------AA---- -----AA---------AA----- -------AAAACAAAA------- ---------AAAAA--------- ----------------------- ----------------------- ----------------------- 
----------------------- ---AACC---------CCAA--- ---AACC---------CCAA--- ---AAA-----------AAA--- ---AAA-----------AAA--- -----A-----------A----- -----A-----------A----- ------AAAAACAAAAA------ ---------AAAAA--------- ----------------------- ----------------------- ----------------------- ----------------------- 
----------------------- ----AAACC-----CCAAA---- ----AAACC-----CCAAA---- ----AAAAC-----CAAAA---- ----AAAAAC---CAAAAA---- ------AAAACCCAAAA------ ------AAAAACAAAAA------ ---------AAAAA--------- ----------------------- ----------------------- ----------------------- ----------------------- ----------------------- 
----------------------- ------AABBBBBBBAA------ ------AABBBBBBBAA------ ------AAA-----AAA------ ------AAAA---AAAA------ --------AAAAAAA-------- ---------AAAAA--------- ----------------------- ----------------------- ----------------------- ----------------------- ----------------------- ----------------------- 
