model
size = 32 17 32, scale = 0.05, origin = -y
material 
  colors = A:#650000 B:#111 C:#3B4042 D:#540000 E:#181818 F:#2F2F2F G:#FFF12E H:#313131 I:#212414 J:#FFF K:#272727 L:#F30 M:#FFFF80
voxels
17-3(8B24-)2(8A24-)8A25-6A27-4A313-3(B2-)B2(22-10B)5(22-10A)23-8A278-2(B-)B2-2(B-)B2(20-12B)6(20-12A)21-10A245-2(B-)I2-I2(-B)19-2(14B18-)6(14A18-)14A19-12A210-2(B-)I6-I2(-B)2(16-16B)6(16-16A)17-14A18-14A20-10A179-B-B10-B-B2(16-16B)7(16-16A)17-14A19-8A2D2A178-B-B2-6E2-B-B15-6BF4CF6B14-18B5(14-18A)15-16A16-16A17-14A19-4(AD)2ADA178-B-I-E6-E-I-B15-5BCFC2FCFC5B14-18B6(14-18A)15-16A17-14A19-3AD6ADA178-B-BE-E4-E-EB-B15-4B3(F2C)F4B14-18B6(14-18A)15-16A17-14A19-2ADAD5ADA176-2(B-)B3(E2-)E2(B-)B12-5B2(CF)2C2(FC)5B12-20B12-6A8B5A13-2(6A8B6A12-)6A8B6A13-5A8B5A14-5A8B5A15-16A17-14A19-7A3D2A176-2(B-)BE3-KE3-E2(B-)B12-5B2CFC2BCF2C5B12-20B2(12-6A8B6A)8-4D6A8B6AD11-6A8B6A12-6A8B6A13-5A8B5A15-16A17-14A19-A4D2AD4A176-2(B-)BE3-EK3-E2(B-)B7-2C3-5B2CFC2BCF2C5B6-C2-H2-20B6-C2-H2-6A8B6A7-2H3-6A8B7A5-2DA3D6A8B6AD4-13A8B7A11-6A8B6A13-5A8B5A15-16A17-14A19-A2(D2A)4DA176-2(B-)B3(E2-)E2(B-)B7-2C3-5B2(CF)2C2(FC)5B6-C2FH2-20B6-C2FH2-6A8B6A7-CH3-6A8B6AD4-2D2A3D6A8B7A4-A6G6A8B6AD11-6A8B6A13-5A8B5A15-16A17-14A19-2AD9A176-2(B-)BE-E4-E-E2(B-)B7-2C3-5B3(F2C)F5B6-3CH2-20B6-3CH2-6A8B6A7-CH3-6A8B6A4-3D2A3D6A8B6A3-6A3D6A8B6A12-6A8B6A13-5A8B5A15-16A17-14A19-3AD2A3(DA)176-2(B-)I-E6-E-I2(-B)7-2C3-6BCFC2FCFC6B6-3CH2-20B6-3CH2-6AB6-B5A8-CH3-6AB6-B6A3-4D2A3D6A8B6A3-A8G6A8B6A12-6A8B5A14-5A8B5A15-16A17-14A19-4A2(D3A)176-B-I-B2-6E2-B-I-B7-2C3-7BF4CF7B6-3CH2-20B6-3CH2-6AB6-B5A8-CH3-6AB6-B5A3-5D2A3D6A8B6A2-16A8B6A12-6A8B5A14-5A8B5A15-16A17-14A19-A2(D2A)DAD2A176-3(B-)B6-3(B-)B7-2C3-20B6-CLMH2-20B6-CMLH2-6AB6-B5A8-CH3-6AB6-B5A3-5D2A3D6AB6-B6A2-A9G6AB6-B6A12-6A8B5A14-5A8B5A15-16A17-14A19-2A2D8A176-4(B-)B2-4(B-)B7-2C3-2(20B6-C2-H2-)6AB6-B5A8-CH3-6AB6-B5A2-6D3A2D6AB6-B6A-17AB6-B6A12-6A8B5A14-5A8B5A15-16A17-14A19-12A176-4(B-)B2-3(B-)B14-2(19B13-)6AB6-B5A13-6AB6-B5A2-11D6AB6-B5A2-A10G6AB6-B6A12-6AB-4B-B5A14-5AB-4B-B5A15-16A17-14A207-3(B-)I-I2-2(I-)B-B14-2(19B13-)2(6AB6-B5A13-)2(6AB6-B6A12-)6AB6-B5A14-5AB-4B-B5A15-16A240-B-B10-B-B15-2(18B14-)5(5AB6-B5A14-)5AB6-B5A17-4A4J4A242-B-B2-6E2-B-B16-5BF4CF5B16-16B5(16-4AB6-B4A)17-3AB6-B3A19-3AB4-B3A20-4A4-4A22-A6-A24-A6-A150-B-E6-E-B20-2BCFC2FCFC2B20-12B7(20-2AB6-B2A)20-3A6-3A21-2(A8-A22-)A8-A117-BE-E4-E-EB19-2B3(F2C)F2B18-14B6(18-3AB6-B3A)18-2A-B6-B-2A19-3A6-3A21-2(A8-A22-)A8-A115-B-B3(E2-)EB-B16-3B2(CF)2C2(FC)3B16-16B5(16-4AB6-B4A)17-3AB6-B3A18-A2-B6-B2-A19-3A6-3A21-2(A8-A22-)A8-A115-B-BE3-EK3-EB-B16-3B2CFC2BCF2C3B16-16B16-3(4AB6-B2AG17-)J3AB6-B2AG17-4AB6-B4A16-4AB6-B4A17-A2-B6-B2-A19-3A6-3A21-A8-A22-A8-A147-B-BE3-KE3-EB-B16-3B2CFC2BCF2C3B16-16B16-4A2(B6-B4A16-J3A)3(B6-B4A16-4A)B6-B4A17-A2-B6-B2-A19-3A6-3A22-A6-A24-A6-A148-B-B3(E2-)EB-B16-3B2(CF)2C2(FC)3B16-16B16-3(4AB6-B2AG17-)J3A2(B6-B2AG17-4A)B6-B4A17-A12-A19-12A23-6A25-A6-A24-A6-A116-B-BE-E4-E-EB-B16-3B3(F2C)F3B16-16B6(16-4A8B4A)17-A12-A19-12A54-8A2(24-A6-A)23-A8-A22-A8-A21-B-E6-E-B19-3BCFC2FCFC3B18-14B5(18-14A)18-6A2G6A19-12A21-10A87-8A3(24-A6-A)22-BI-6E-IB20-3BF4CF3B20-12B20-12A20-3A6G3A20-12A20-4A4G4A20-12A21-4A2-4A24-6A154-6A26-6G26-6A24-3(10B22-)10A22-2A6-2A23-8A24-2A4-2A25-6A296-
