model
size = 32 17 32, scale = 0.05, origin = -y
material 
  colors = A:#001B3A B:#858585 C:#9AA6AB D:#001633 E:#929292 F:#777 G:#20839A H:#7D9EA9 I:#F30 J:#FFFF80
voxels
7-3(8B24-)2(8A24-)8A25-6A27-4A313-3(B2-)B2(22-10B)5(22-10A)23-8A278-2(B-)B2-2(B-)B2(20-12B)6(20-12A)21-10A245-2(B-)H2-H2(-B)19-2(14B18-)6(14A18-)14A19-12A210-2(B-)H6-H2(-B)2(16-16B)6(16-16A)17-14A18-14A20-10A179-B-B10-B-B2(16-16B)7(16-16A)17-14A19-8A2D2A178-B-B2-6E2-B-B15-6BF4CF6B14-18B5(14-18A)15-16A16-16A17-14A19-4(AD)2ADA178-B-H-E6-E-H-B15-5BCFC2FCFC5B14-18B6(14-18A)15-16A17-14A19-3AD6ADA178-B-BE-E4-E-EB-B15-4B3(F2C)F4B14-18B6(14-18A)15-16A17-14A19-2ADAD5ADA176-2(B-)B3(E2-)E2(B-)B12-5B2(CF)2C2(FC)5B12-20B13-5A3(8B6A12-6A)8B6A13-5A8B5A14-5A8B5A15-16A17-14A19-7A3D2A176-2(B-)BE3-EF3-E2(B-)B12-5B2CFC2BCF2C5B12-20B2(12-6A8B6A)11-D6A8B6A4D8-6A8B6A12-6A8B6A13-5A8B5A15-16A17-14A19-A4D2AD4A176-2(B-)BE3-FE3-E2(B-)B12-5B2CFC2BCF2C5B3-2C7-20B2-E2-C6-6A8B6A2-E2-C5-7A8B6A3-2E6-D6A8B6A3DA2D5-7A8B13A5-6A8B6A13-5A8B5A15-16A17-14A19-A2(D2A)4DA176-2(B-)B3(E2-)E2(B-)B12-5B2(CF)2C2(FC)5B3-2C7-20B2-E2FC6-6A8B6A2-E2FC5-D6A8B6A3-EC6-7A8B6A3D2A2D4-D6A8B6A6GA5-6A8B6A13-5A8B5A15-16A17-14A19-2AD9A176-2(B-)BE-E4-E-E2(B-)B12-5B3(F2C)F5B3-2C7-20B2(2-E3C6-6A8B6A)3-EC7-6A8B6A3D2A3D4-6A8B15A3-6A8B6A13-5A8B5A15-16A17-14A19-3AD2A3(DA)176-2(B-)H-E6-E-H2(-B)12-6BCFC2FCFC6B3-2C7-20B2-E3C7-5AB6-B6A2-E3C6-6AB6-B6A3-EC7-6A8B6A3D2A4D3-6A8B6A8GA4-5A8B6A13-5A8B5A15-16A17-14A19-4A2(D3A)176-B-H-B2-6E2-B-H-B12-7BF4CF7B3-2C7-20B2(2-E3C7-5AB6-B6A)3-EC7-6A8B6A3D2A5D2-6A8B16A3-5A8B6A13-5A8B5A15-16A17-14A19-A2(D2A)DAD2A176-3(B-)B6-3(B-)B12-20B3-2C7-20B2-EJIC7-5AB6-B6A2-EIJC7-5AB6-B6A3-EC7-6AB6-B6A3D2A5D2-6AB6-B6A9GA3-5A8B6A13-5A8B5A15-16A17-14A19-2A2D8A176-4(B-)B2-4(B-)B12-20B3-2C7-20B2(2-E2-C7-5AB6-B6A)3-EC7-6AB6-B6A3D2A6D-6AB6-B17A2-5A8B6A13-5A8B5A15-16A17-14A19-12A178-3(B-)B2-4(B-)B2(13-19B)3(13-5AB6-B6A)11D-6AB6-B6A10GA2-5AB-4B-B6A13-5AB-4B-B5A15-16A17-14A209-2(B-)H-H2-2(H-)2(B-)B2(13-19B)2(13-5AB6-B6A)2(12-6AB6-B6A)13-5AB6-B6A13-5AB-4B-B5A15-16A240-B-B10-B-B15-2(18B14-)5(5AB6-B5A14-)5AB6-B5A17-4A4B4A242-B-B2-6E2-B-B16-5BF4CF5B16-16B5(16-4AB6-B4A)17-3AB6-B3A19-3AB4-B3A20-4A4-4A22-A6-A24-A6-A150-B-E6-E-B20-2BCFC2FCFC2B20-12B7(20-2AB6-B2A)20-3A6-3A21-2(A8-A22-)A8-A117-BE-E4-E-EB19-2B3(F2C)F2B18-14B6(18-3AB6-B3A)18-2A-B6-B-2A19-3A6-3A21-2(A8-A22-)A8-A115-B-B3(E2-)EB-B16-3B2(CF)2C2(FC)3B16-16B5(16-4AB6-B4A)17-3AB6-B3A18-A2-B6-B2-A19-3A6-3A21-2(A8-A22-)A8-A115-B-BE3-FE3-EB-B16-3B2CFC2BCF2C3B16-16B3(17-G2AB6-B4A)17-G2AB6-B3AB2(16-4AB6-B4A)17-A2-B6-B2-A19-3A6-3A21-A8-A22-A8-A147-B-BE3-EF3-EB-B16-3B2CFC2BCF2C3B16-16B16-4AB6-B4A2(16-4AB6-B3AB)3(16-4AB6-B4A)17-A2-B6-B2-A19-3A6-3A22-A6-A24-A6-A148-B-B3(E2-)EB-B16-3B2(CF)2C2(FC)3B16-16B3(17-G2AB6-B4A)17-G2AB6-B3AB17-G2AB6-B4A16-4AB6-B4A17-A12-A19-12A23-6A25-A6-A24-A6-A116-B-BE-E4-E-EB-B16-3B3(F2C)F3B16-16B6(16-4A8B4A)17-A12-A19-12A54-8A2(24-A6-A)23-A8-A22-A8-A21-B-E6-E-B19-3BCFC2FCFC3B18-14B5(18-14A)18-6A2G6A19-12A21-10A87-8A3(24-A6-A)22-BH-6E-HB20-3BF4CF3B20-12B20-12A20-3A6G3A20-12A20-4A4G4A20-12A21-4A2-4A24-6A154-6A26-6G26-6A24-3(10B22-)10A22-2A6-2A23-8A24-2A4-2A25-6A306-
