model
size = 32 11 31, scale = 0.05, origin = -y
material 
  colors = A:#111 B:#EEE
voxels
33-A28-A2-3A24-3A3-3A22-3A5-3A20-3A7-3A18-3A196-5A22-5A-6A18-6A3-7A14-7A5-10A2(BA)B11A7-8A7B9A9-6A2B3A4B7A12-4A2(B2A)BA2B4A15-9A3B4A18-8AB3A24-4A46-7A5-8A5-39A4-24A10-20A14-16A18-12A171-30A-34A8-A3-4A3-A8-2A257-2(14A2-)4A3-2A-10A-2A3-4A2(2-2A9-8A9-2A)14-6A26-6A27-4A145-10A6-10A5-3(4A4-)4A3-3A7-3A4-3A7-3A2-3A7-4A2-4A7-3A3-A8-10A8-A14-8A24-8A25-6A27-4A82-8A8-8A7-4A2-3A8-3A2-4A2(5-3A)6-3A5-3A4-3A5-3A6-3A5-3A4-2A2(6-3A)6-2A4-2A7-3A4-3A7-2A13-4A2-4A23-8A24-8A81-6A10-6A9-3A2-2A10-2A2-3A7-3A3-3A8-3A3-2(3A5-)2(2A8-2A5-3A4-3A5-)3A6-2(3A5-)A2(6-3A)6-A14-3A4-3A23-8A25-6A51-4A12-4A11-3A-2A10-2A-3A9-3A2-2A10-2A2-3A7-3A3-2A10-2A3-3A6-2A4-2A10-2A4-2(2A6-2A5-2A8-2A5-)2A13-3A6-3A21-10A24-6A51-4A12-4A11-5A12-5A9-3A2-2A10-2A2-3A8-2A3-2A10-2A3-2A7-3A3-2A10-2A3-3A6-3A3-2A10-2A3-3A7-2(2A4-2A8-)A5-3A6-3A5-A15-4A2-4A23-8A51-3A12-3A13-4A12-4A11-3A-A12-A-3A2(10-2A2-2A)9-3A2-2A10-2A2-3A8-2A3-2A10-2A3-2A8-2A4-A10-A2(4-2A8-2A)4-2A14-4A4-4A22-8A51-3A12-3A13-2(4A12-)2A-A12-A-2A11-2A2-A12-A2(2-2A10-2A)2-2A9-3A2-2A10-2A2-3A8-3A3-A10-A3-3A9-A4-2A8-2A4-A10-A2(4-4A)4-A17-8A51-3A12-3A13-2(4A12-)2A-A12-A-2A12-2A-2A10-2A-2A11-4(2A2-2A10-)2A3-A10-A3-2A10-2A3-2A8-2A3-2A10-2A3-4A4-4A3-2A17-8A51-3A12-3A14-3A12-3A13-2(2A-2A10-2A-2A12-)2A-2A10-2A-2A11-3A-2A10-2A-3A10-2A3-2A8-2A3-2A10-2A3-3A6-3A3-2A10-2A4-10A4-2A17-8A52-2A12-2A15-4A10-4A14-4A10-4A13-5A10-5A12-2A-3A8-3A-2(2A12-2A2-2A8-2A2-)2A12-2A2-3A6-3A2-2A12-2A3-10A3-2A19-6A53-3A10-3A16-4A8-4A15-5A8-5A2(14-2A-2A8-2A-2A)13-2(2A2-3A6-3A2-2A12-)2A3-4A2-4A3-2A12-2A4-8A4-2A20-4A54-2(4A8-4A16-)5A6-5A15-2A-3A6-3A-2(2A14-2A2-3A4-3A2-)2A14-2A2(2-4A)2-3A13-2A3-8A3-2A14-A5-6A5-A80-4A6-4A17-6A4-6A16-2A-4A2-4A-2A16-2A-10A-2A15-3(2A3-8A3-2A14-)2A4-6A4-2(2A14-)2A81-12A19-14A17-3A-8A-3A2(16-2A3-6A3-2A)15-3A4-4A4-3A4(14-2A)15-A14-A82-12A19-3A-6A-3A18-2A10-2A17-3A10-3A4(16-2A12-2A)115-10A21-3A6-3A19-3A8-3A18-2A10-2A17-3A10-3A3(16-2A12-2A)115-10A21-3A6-3A20-2A8-2A19-3A8-3A3(18-2A10-2A)18-A12-A117-8A23-3A4-3A21-3A6-3A19-3A8-2A19-2(2A10-2A18-)2A10-2A149-8A23-3A4-3A21-3A6-3A3(20-2A8-2A)20-A10-A150-8A23-3A4-3A21-3A6-2A21-3A6-3A2(20-2A8-2A)183-6A24-3A4-3A2(22-2A6-2A)22-A8-A216-6A25-3A2-3A23-3A4-3A22-2A6-2A218-2A28-6A25-3A2-3A24-2A4-2A24-A6-A219-2A28-6A25-3A2-3A24-2A4-2A251-2A28-6A26-2A2-2A315-4A302-
