model
size = 4 32 4, scale = 0.05, origin = -y
material 
  colors = A:#99E550 B:#9BADB7 C:#000 D:#FFF E:#FBF236 F:#AC3232
voxels
B2C2B2CB-2B2-EB2-BC2-2B-2(4C4B)-21(2A2-)2A-5C2DCB3(2D2B)2(2DBC2DCB)2DB88A5C2DCB3(2D2B)2DBC2DCB2DEC2DCB2DB88AB2C2B2CB-2B2-FB2-AB2-2B-2(4C4B)-21(2A2-)2A-
