model
size = 25 22 25, scale = 0.05, origin = -y
material 
  colors = A:#FCC B:#EEE C:#3CF D:#F0C E:#DDD F:#F0F
voxels
------------------------- ------------------------- ------------------------- ------------------------- ------------------------- ------------------------- ------------------------- ---------BBBBBBB--------- ------------------------- ------------------------- ------------------------- ------------------------- ------------------------- ------------------------- ------------------------- ------------------------- ------------------------- ------------------------- ------------------------- ------------------------- ------------------------- ------------------------- 
------------------------- ------------------------- ------------------------- ------------------------- ------------------------- ------------------------- ------------------------- -------BBBBBBBBBBB------- ---------CCCCCCC--------- ---------CC-CC-C--------- ---------C--C--C--------- ------------------------- ------------------------- ------------------------- ------------------------- ------------------------- ---------CCCCCCC--------- --------CCC---CCC-------- ------------------------- ------------------------- ------------------------- ------------------------- 
------------------------- ------------------------- ------------------------- ------------------------- ------------------------- ------------------------- ------------------------- -----BBBBBBBBBBBBBBB----- -------CCAAAAAAACC------- -------C-AAAAAAAC-------- ---------AAAAAAA--------- ---------AAAAAAA--------- ---------AAAAAAA--------- ---------AAAAAAA--------- ---------AAAAAAA--------- ---------AAAAAAA--------- -------CCBBBBBBBCC------- --------CEC---CEC-------- ---------E-----E--------- ---------F-----F--------- ---------E-----E--------- ---------F-----F--------- 
------------------------- ------------------------- ------------------------- ------------------------- ------------------------- ------------------------- ------------------------- ----BBBBBBBBBBBBBBBBB---- ------CAAAAAAAAAAAC------ ------CAAAAAAAAAAAC------ ------CAAAAAAAAAAAC------ -------AAAAAAAAAAA------- -------AAAAAAAAAAA------- -------AAAAAAAAAAA------- -------AAAAAAAAAAA------- -------AAAAAAAAAAA------- ------CBBBBBDBBBBBC------ --------CCC---CCC-------- ------------------------- ------------------------- ------------------------- ------------------------- 
------------------------- ------------------------- ------------------------- ------------------------- ------------------------- ------------------------- ------------------------- ---BBBBBBBBBBBBBBBBBBB--- -----CAAAAAAAAAAAAAC----- ------AAAAAAAAAAAAAC----- ------AAAAAAAAAAAAA------ ------AAAAAAAAAAAAA------ ------AAAAAAAAAAAAA------ ------AAAAAAAAAAAAA------ ------AAAAAAAAAAAAA------ ------AAAAAAAAAAAAA------ -----CBBBBBDDDBBBBBC----- ----CCC-----------CCC---- ------------------------- ------------------------- ------------------------- ------------------------- 
------------------------- ------------------------- ------------------------- ------------------------- ------------------------- ------------------------- ------------------------- --BBBBBBBBBBBBBBBBBBBBB-- ----CAAAAAAAAAAAAAAAC---- ----CAAAAAAAAAAAAAAA----- -----AAAAAAAAAAAAAAA----- -----AAAAAAAAAAAAAAA----- -----AAAAAAAAAAAAAAA----- -----AAAAAAAAAAAAAAA----- -----AAAAAAAAAAAAAAA----- -----AAAAAAAAAAAAAAA----- ----CBBBBBDDDDDBBBBBC---- ----CEC-----------CEC---- -----E-------------E----- -----F-------------F----- -----E-------------E----- -----F-------------F----- 
----------BBBBB---------- ------------------------- ------------------------- ------------------------- ------------------------- ------------------------- ------------------------- --BBBBBBBBBBBBBBBBBBBBB-- ---CAAAAAAAAAAAAAAAAAC--- ---CAAAAAAAAAAAAAAAAAC--- ---CAAAAAAAAAAAAAAAAAC--- ----AAAAAAAAAAAAAAAAA---- ----AAAAAAAAAAAAAAAAA---- ----AAAAAAAAAAAAAAAAA---- ----AAAAAAAAAAAAAAAAA---- ----AAAAAAAAAAAAAAAAA---- ---CBBBBBDDDDDDDBBBBBC--- ----CCC-----------CCC---- ------------------------- ------------------------- ------------------------- ------------------------- 
--------BBBBBBBBB-------- ------------------------- ------------------------- ------------------------- ------------------------- ------------------------- ------------------------- -BBBBBBBBBBBBBBBBBBBBBBB- --CAAAAAAAAAAAAAAAAAAAC-- ---AAAAAAAAAAAAAAAAAAAC-- ---AAAAAAAAAAAAAAAAAAA--- ---AAAAAAAAAAAAAAAAAAA--- ---AAAAAAAAAAAAAAAAAAA--- ---AAAAAAAAAAAAAAAAAAA--- ---AAAAAAAAAAAAAAAAAAA--- ---AAAAAAAAAAAAAAAAAAA--- --CBBBBBDDDDDDDDDBBBBBC-- ------------------------- ------------------------- ------------------------- ------------------------- ------------------------- 
-------BBBBBBBBBBB------- ----------BBBBB---------- ------------------------- ------------------------- ------------------------- ------------------------- ------------------------- -BBBBBBBBBBBBBBBBBBBBBBB- --CAAAAAAAAAAAAAAAAAAAC-- --CAAAAAAAAAAAAAAAAAAA--- ---AAAAAAAAAAAAAAAAAAA--- ---AAAAAAAAAAAAAAAAAAA--- ---AAAAAAAAAAAAAAAAAAA--- ---AAAAAAAAAAAAAAAAAAA--- ---AAAAAAAAAAAAAAAAAAA--- ---AAAAAAAAAAAAAAAAAAA--- --CBBBBBDDDDDDDDDBBBBBC-- -CCC-----------------CCC- ------------------------- ------------------------- ------------------------- ------------------------- 
-------BBBBBBBBBBB------- ---------BBBBBBB--------- ------------------------- ------------------------- ------------------------- ------------------------- ------------------------- BBBBBBBBBBBBBBBBBBBBBBBBB -CAAAAAAAAAAAAAAAAAAAAAC- -CAAAAAAAAAAAAAAAAAAAAAC- -CAAAAAAAAAAAAAAAAAAAAAC- --AAAAAAAAAAAAAAAAAAAAA-- --AAAAAAAAAAAAAAAAAAAAA-- --AAAAAAAAAAAAAAAAAAAAA-- --AAAAAAAAAAAAAAAAAAAAA-- --AAAAAAAAAAAAAAAAAAAAA-- -CBBBBBDDDDDDDDDDDBBBBBC- -CEC-----------------CEC- --E-------------------E-- --F-------------------F-- --E-------------------E-- --F-------------------F-- 
------BBBBBBBBBBBBB------ --------BBBBBBBBB-------- -----------BBB----------- ------------------------- ------------------------- ------------------------- ------------------------- BBBBBBBBBBBBBBBBBBBBBBBBB -CAAAAAAAAAAAAAAAAAAAAAC- --AAAAAAAAAAAAAAAAAAAAAC- --AAAAAAAAAAAAAAAAAAAAA-- --AAAAAAAAAAAAAAAAAAAAA-- --AAAAAAAAAAAAAAAAAAAAA-- --AAAAAAAAAAAAAAAAAAAAA-- --AAAAAAAAAAAAAAAAAAAAA-- --AAAAAAAAAAAAAAAAAAAAA-- -CBBBBDDDDDDDDDDDDDBBBBC- -CCC-----------------CCC- ------------------------- ------------------------- ------------------------- ------------------------- 
------BBBBBBBBBBBBB------ --------BBBBBBBBB-------- ----------BBBBB---------- ------------------------- ------------------------- ------------------------- ------------------------- BBBBBBBBBBBBBBBBBBBBBBBBB -CAAAAAAAAAAAAAAAAAAAAAC- -CAAAAAAAAAAAAAAAAAAAAA-- --AAAAAAAAAAAAAAAAAAAAA-- --AAAAAAAAAAAAAAAAAAAAA-- --AAAAAAAAAAAAAAAAAAAAA-- --AAAAAAAAAAAAAAAAAAAAA-- --AAAAAAAAAAAAAAAAAAAAA-- --AAAAAAAAAAAAAAAAAAAAA-- -CBBBDDDDDDDDDDDDDDDBBBC- ------------------------- ------------------------- ------------------------- ------------------------- ------------------------- 
------BBBBBBBBBBBBB------ --------BBBBBBBBB-------- ----------BBBBB---------- ------------B------------ ------------B------------ ------------B------------ ------------B------------ BBBBBBBBBBBBBBBBBBBBBBBBB -CAAAAAAAAAABAAAAAAAAAAC- -CAAAAAAAAAAEAAAAAAAAAAC- -CAAAAAAAAAAEAAAAAAAAAAC- --AAAAAAAAAAEAAAAAAAAAA-- --AAAAAAAAAAEAAAAAAAAAA-- --AAAAAAAAAAEAAAAAAAAAA-- --AAAAAAAAAAEAAAAAAAAAA-- --AAAAAAAAAAEAAAAAAAAAA-- -CBBBDDDDDDDDDDDDDDDBBBC- ------------------------- ------------------------- ------------------------- ------------------------- ------------------------- 
------BBBBBBBBBBBBB------ --------BBBBBBBBB-------- ----------BBBBB---------- ------------------------- ------------------------- ------------------------- ------------------------- BBBBBBBBBBBBBBBBBBBBBBBBB -CAAAAAAAAAAAAAAAAAAAAAC- --AAAAAAAAAAAAAAAAAAAAAC- --AAAAAAAAAAAAAAAAAAAAA-- --AAAAAAAAAAAAAAAAAAAAA-- --AAAAAAAAAAAAAAAAAAAAA-- --AAAAAAAAAAAAAAAAAAAAA-- --AAAAAAAAAAAAAAAAAAAAA-- --AAAAAAAAAAAAAAAAAAAAA-- -CBBBDDDDDDDDDDDDDDDBBBC- ------------------------- ------------------------- ------------------------- ------------------------- ------------------------- 
------BBBBBBBBBBBBB------ --------BBBBBBBBB-------- -----------BBB----------- ------------------------- ------------------------- ------------------------- ------------------------- BBBBBBBBBBBBBBBBBBBBBBBBB -CAAAAAAAAAAAAAAAAAAAAAC- -CAAAAAAAAAAAAAAAAAAAAA-- --AAAAAAAAAAAAAAAAAAAAA-- --AAAAAAAAAAAAAAAAAAAAA-- --AAAAAAAAAAAAAAAAAAAAA-- --AAAAAAAAAAAAAAAAAAAAA-- --AAAAAAAAAAAAAAAAAAAAA-- --AAAAAAAAAAAAAAAAAAAAA-- -CBBBDDDDDDDBDDDDDDDBBBC- -CCC-----------------CCC- ------------------------- ------------------------- ------------------------- ------------------------- 
-------BBBBBBBBBBB------- ---------BBBBBBB--------- ------------------------- ------------------------- ------------------------- ------------------------- ------------------------- BBBBBBBBBBBBBBBBBBBBBBBBB -CAAAAAAAAAAAAAAAAAAAAAC- -CAAAAAAAAAAAAAAAAAAAAAC- -CAAAAAAAAAAAAAAAAAAAAAC- --AAAAAAAAAAAAAAAAAAAAA-- --AAAAAAAAAAAAAAAAAAAAA-- --AAAAAAAAAAAAAAAAAAAAA-- --AAAAAAAAAAAAAAAAAAAAA-- --AAAAAAAAAAAAAAAAAAAAA-- -CBBBBDDDDDBBBDDDDDBBBBC- -CEC-----------------CEC- --E-------------------E-- --F-------------------F-- --E-------------------E-- --F-------------------F-- 
-------BBBBBBBBBBB------- ----------BBBBB---------- ------------------------- ------------------------- ------------------------- ------------------------- ------------------------- -BBBBBBBBBBBBBBBBBBBBBBB- --CAAAAAAAAAAAAAAAAAAAC-- ---AAAAAAAAAAAAAAAAAAAC-- ---AAAAAAAAAAAAAAAAAAA--- ---AAAAAAAAAAAAAAAAAAA--- ---AAAAAAAAAAAAAAAAAAA--- ---AAAAAAAAAAAAAAAAAAA--- ---AAAAAAAAAAAAAAAAAAA--- ---AAAAAAAAAAAAAAAAAAA--- --CBBBBDDDDBBBDDDDBBBBC-- -CCC-----------------CCC- ------------------------- ------------------------- ------------------------- ------------------------- 
--------BBBBBBBBB-------- ------------------------- ------------------------- ------------------------- ------------------------- ------------------------- ------------------------- -BBBBBBBBBBBBBBBBBBBBBBB- --CAAAAAAAAAAAAAAAAAAAC-- --CAAAAAAAAAAAAAAAAAAA--- ---AAAAAAAAAAAAAAAAAAA--- ---AAAAAAAAAAAAAAAAAAA--- ---AAAAAAAAAAAAAAAAAAA--- ---AAAAAAAAAAAAAAAAAAA--- ---AAAAAAAAAAAAAAAAAAA--- ---AAAAAAAAAAAAAAAAAAA--- --CBBBBBDDBBBBBDDBBBBBC-- ------------------------- ------------------------- ------------------------- ------------------------- ------------------------- 
----------BBBBB---------- ------------------------- ------------------------- ------------------------- ------------------------- ------------------------- ------------------------- --BBBBBBBBBBBBBBBBBBBBB-- ---CAAAAAAAAAAAAAAAAAC--- ---CAAAAAAAAAAAAAAAAAC--- ---CAAAAAAAAAAAAAAAAAC--- ----AAAAAAAAAAAAAAAAA---- ----AAAAAAAAAAAAAAAAA---- ----AAAAAAAAAAAAAAAAA---- ----AAAAAAAAAAAAAAAAA---- ----AAAAAAAAAAAAAAAAA---- ---CBBBBBBBBBBBBBBBBBC--- ----CCC-----------CCC---- ------------------------- ------------------------- ------------------------- ------------------------- 
------------------------- ------------------------- ------------------------- ------------------------- ------------------------- ------------------------- ------------------------- --BBBBBBBBBBBBBBBBBBBBB-- ----CAAAAAAAAAAAAAAAC---- -----AAAAAAAAAAAAAAAC---- -----AAAAAAAAAAAAAAA----- -----AAAAAAAAAAAAAAA----- -----AAAAAAAAAAAAAAA----- -----AAAAAAAAAAAAAAA----- -----AAAAAAAAAAAAAAA----- -----AAAAAAAAAAAAAAA----- ----CBBBBBBBBBBBBBBBC---- ----CEC-----------CEC---- -----E-------------E----- -----F-------------F----- -----E-------------E----- -----F-------------F----- 
------------------------- ------------------------- ------------------------- ------------------------- ------------------------- ------------------------- ------------------------- ---BBBBBBBBBBBBBBBBBBB--- -----CAAAAAAAAAAAAAC----- -----CAAAAAAAAAAAAA------ ------AAAAAAAAAAAAA------ ------AAAAAAAAAAAAA------ ------AAAAAAAAAAAAA------ ------AAAAAAAAAAAAA------ ------AAAAAAAAAAAAA------ ------AAAAAAAAAAAAA------ -----CBBBBBBBBBBBBBC----- ----CCC-----------CCC---- ------------------------- ------------------------- ------------------------- ------------------------- 
------------------------- ------------------------- ------------------------- ------------------------- ------------------------- ------------------------- ------------------------- ----BBBBBBBBBBBBBBBBB---- ------CAAAAAAAAAAAC------ ------CAAAAAAAAAAAC------ ------CAAAAAAAAAAAC------ -------AAAAAAAAAAA------- -------AAAAAAAAAAA------- -------AAAAAAAAAAA------- -------AAAAAAAAAAA------- -------AAAAAAAAAAA------- ------CBBBBBBBBBBBC------ --------CCC---CCC-------- ------------------------- ------------------------- ------------------------- ------------------------- 
------------------------- ------------------------- ------------------------- ------------------------- ------------------------- ------------------------- ------------------------- -----BBBBBBBBBBBBBBB----- -------CCAAAAAAACC------- --------CAAAAAAA-C------- ---------AAAAAAA--------- ---------AAAAAAA--------- ---------AAAAAAA--------- ---------AAAAAAA--------- ---------AAAAAAA--------- ---------AAAAAAA--------- -------CCBBBBBBBCC------- --------CEC---CEC-------- ---------E-----E--------- ---------F-----F--------- ---------E-----E--------- ---------F-----F--------- 
------------------------- ------------------------- ------------------------- ------------------------- ------------------------- ------------------------- ------------------------- -------BBBBBBBBBBB------- ---------CCCCCCC--------- ---------C-CC-CC--------- ---------C--C--C--------- ------------------------- ------------------------- ------------------------- ------------------------- ------------------------- ---------CCCCCCC--------- --------CCC---CCC-------- ------------------------- ------------------------- ------------------------- ------------------------- 
------------------------- ------------------------- ------------------------- ------------------------- ------------------------- ------------------------- ------------------------- ---------BBBBBBB--------- ------------------------- ------------------------- ------------------------- ------------------------- ------------------------- ------------------------- ------------------------- ------------------------- ------------------------- ------------------------- ------------------------- ------------------------- ------------------------- ------------------------- 
