model
size = 20 15 20, scale = 0.05, origin = -y
material 
  colors = A:#90C B:#CF6
voxels
-------AAAAAA------- -------------------- -------------------- -------------------- -------------------- -------------------- -------------------- -------------------- -------------------- -------------------- -------------------- -------------------- -------------------- -------------------- -------------------- 
-----AAAAAAAAAA----- -------------------- -------------------- -------------------- -------------------- -------------------- -------------------- -------------------- -------------------- -------------------- -------------------- -------------------- -------------------- -------------------- -------------------- 
---AAAAAAAAAAAAAA--- -------------------- -------------------- -------------------- -------------------- -------------------- -------------------- -------------------- -------------------- -------------------- -------------------- -------------------- -------------------- -------------------- -------------------- 
--AAAAAAAAAAAAAAAA-- -------AAAAAA------- -------AAAAAA------- -------------------- -------------------- -------------------- -------------------- -------------------- -------------------- -------------------- -------------------- -------------------- -------------------- -------------------- -------------------- 
--AAAA--------AAAA-- -----AAAAAAAAAA----- -----AAAAAAAAAA----- -------AAAAAA------- -------AAAAAA------- -------------------- -------------------- -------------------- -------------------- -------------------- -------------------- -------------------- -------------------- -------------------- -------------------- 
-AAAA----------AAAA- ----AAA------AAA---- ----AAAAA--AAAAA---- ------AAAAAAAA------ ------AAAAAAAA------ -------AAAAA-------- -------AAAAA-------- -------------------- -------------------- -------------------- -------------------- -------------------- -------------------- -------------------- -------------------- 
-AAA------------AAA- ----A----------A---- ----AAA------AAA---- -----AA------AA----- -----AAAA--AAAA----- ------AAAAAAA------- ------AAAAAAA------- -------AAAAA-------- -------AAAAA-------- -------------------- -------------------- -------------------- -------------------- -------------------- -------------------- 
AAA--------------AAA ---AA----------AA--- ---AAA--------AAA--- ----AAA------AA----- ----AAA------AA----- -----AAAA--AAA------ -----AAAAAAAAA------ ------AAAAAAA------- ------AAAAAAA------- --------AAA--------- --------AAA--------- -------------------- -------------------- -------------------- -------------------- 
AAA--------------AAA ---AA----------AA--- ---AAA--------AAA--- ----AA--------A----- ----AAA------AA----- -----AAA----AA------ -----AAA----AA------ ------AAAAAAA------- ------BAAAAAA------- -------AAAAA-------- -------AAAAA-------- ---------A---------- ---------A---------- -------------------- -------------------- 
AAA--------------AAA ---AA----------AA--- ---AAA--------AAA--- ----AA--------A----- ----AA--------A----- -----AA------A------ -----AAA----AA------ ------BAA--AA------- ------BAAAAAA------- ------BAAAAA-------- -------AAAAA-------- --------AAA--------- --------AAA--------- ---------A---------- ---------A---------- 
AAA--------------AAA ---AA----------AA--- ---AAA--------AAA--- ----AA--------A----- ----AA--------A----- -----AA------A------ -----AAA----AA------ ------AAA--AA------- ------BAAAAAA------- -------AAAAA-------- -------AAAAA-------- --------AAA--------- --------AAA--------- ---------A---------- ---------A---------- 
AAA--------------AAA ---AA----------AA--- ---AAA--------AAA--- ----AA--------A----- ----AAA------AA----- -----AAA----AA------ -----AAA----AA------ ------AAAAAAA------- ------AAAAAAA------- -------AAAAA-------- -------AAAAA-------- ---------A---------- ---------A---------- -------------------- -------------------- 
AAA--------------AAA ---AA----------AA--- ---AAA--------AAA--- ----AAA------AA----- ----AAA------AA----- -----AAAA--AAA------ -----AAAAAAAAA------ ------AAAAAAA------- ------AAAAAAA------- --------AAA--------- --------AAA--------- -------------------- -------------------- -------------------- -------------------- 
-AAA------------AAA- ----A----------A---- ----AAA------AAA---- -----AA------AA----- -----AAAA--AAAA----- ------AAAAAAA------- ------AAAAAAA------- -------AAAAA-------- -------AAAAA-------- -------------------- -------------------- -------------------- -------------------- -------------------- -------------------- 
-AAAA----------AAAA- ----AAA------AAA---- ----AAAAA--AAAAA---- ------AAAAAAAA------ ------AAAAAAAA------ -------AAAAA-------- -------AAAAA-------- -------------------- -------------------- -------------------- -------------------- -------------------- -------------------- -------------------- -------------------- 
--AAAA--------AAAA-- -----AAAAAAAAAA----- -----AAAAAAAAAA----- -------AAAAAA------- -------AAAAAA------- -------------------- -------------------- -------------------- -------------------- -------------------- -------------------- -------------------- -------------------- -------------------- -------------------- 
--AAAAAAAAAAAAAAAA-- -------AAAAAA------- -------AAAAAA------- -------------------- -------------------- -------------------- -------------------- -------------------- -------------------- -------------------- -------------------- -------------------- -------------------- -------------------- -------------------- 
---AAAAAAAAAAAAAA--- -------------------- -------------------- -------------------- -------------------- -------------------- -------------------- -------------------- -------------------- -------------------- -------------------- -------------------- -------------------- -------------------- -------------------- 
-----AAAAAAAAAA----- -------------------- -------------------- -------------------- -------------------- -------------------- -------------------- -------------------- -------------------- -------------------- -------------------- -------------------- -------------------- -------------------- -------------------- 
-------AAAAAA------- -------------------- -------------------- -------------------- -------------------- -------------------- -------------------- -------------------- -------------------- -------------------- -------------------- -------------------- -------------------- -------------------- -------------------- 
