model
size = 29 15 5, scale = 0.05, origin = -y
material 
  colors = A:#F0C B:#EEE
voxels
----------------------------- -----------AAAAAAA----------- --------AAAAAAAAAAAAA-------- ------AAAAAAAAAAAAAAAAA------ -----AAAAAAAAAAAAAAAAAAA----- ----AAAAAAAAAAAAAAAAAAAAA---- ---AAAAAAA---------AAAAAAA--- --AAAAA---------------AAAAA-- --AAA-------------------AAA-- -AAA---------------------AAA- -AA-----------------------AA- -AA-----------------------AA- AA-------------------------AA AA-------------------------AA AA--------------------------- 
----------------------------- -----------AAAAAAA----------- --------AAAAAAAAAAAAA-------- ------AAAAAAAAAAAAAAAAA------ -----AAAAAAAAAAAAAAAAAAA----- ----AAAAAAAAAAAAAAAAAAAAA---- ---AAAAAAA---------AAAAAAA--- --AAAAA---------------AAAAA-- --AAA-------------------AAA-- -AAA---------------------AAA- -AA-----------------------AA- -AA-----------------------AA- AA-------------------------AA AA-------------------------AA AA--------------------------- 
----------------------------- -----------AAAAAAA----------- --------AAAAAAAAAAAAA-------- ------AAAAAAAAAAAAAAAAA------ -----AAAAAAAAAAAAAAAAAAA----- ----AAAAAAAAAAAAAAAAAAAAA---- ---AAAAAAA---------AAAAAAA--- --AAAAA---------------AAAAA-- --AAA-------------------AAA-- -AAA---------------------AAA- -AA-----------------------AA- -AA-----------------------AA- AA-------------------------AA AA-------------------------AA AA--------------------------- 
----------------------------- -----------AAAAAAA----------- --------AAAAAAAAAAAAA-------- ------AAAAAAAAAAAAAAAAA------ -----AAAAAAAAAAAAAAAAAAA----- ----AAAAAAAAAAAAAAAAAAAAA---- ---AAAAAAA---------AAAAAAA--- --AAAAA---------------AAAAA-- --AAA-------------------AAA-- -AAA---------------------AAA- -AA-----------------------AA- -AA-----------------------AA- AA-------------------------AA AA-------------------------AA AA--------------------------- 
-----------BBB--BBB---------- -----------BBB--BBB---------- -----------BBB--BBB---------- -----------BBB--BBB---------- ----------------------------- ----------------------------- ----------------------------- ----------------------------- ----------------------------- ----------------------------- ----------------------------- ----------------------------- ----------------------------- ----------------------------- ----------------------------- 
