model
size = 23 11 29, scale = 0.05, origin = -y
material 
  colors = A:#8F563B B:#663931 C:#FFF D:#D9A066
voxels
---------AAAAA--------- ----------------------- ----------------------- ----------------------- ----------------------- ----------------------- ----------------------- ----------------------- ----------------------- ----------------------- ----------------------- 
------AAAAAAAAAAA------ ------AAAA---AAAA------ ----------------------- ----------------------- ----------------------- ----------------------- ----------------------- ----------------------- ----------------------- ----------------------- ----------------------- 
-----AAAAAAAAAAAAA----- -----AA---------AA----- -----A-----------A----- ----------------------- ----------------------- ----------------------- ----------------------- ----------------------- ----------------------- ----------------------- ----------------------- 
----AAAAAAAAAAAAAAA---- ----AA-----------AA---- ----A-------------A---- ----------------------- ----------------------- ----------------------- ----------------------- ----------------------- ----------------------- ----------------------- ----------------------- 
---AAAAAAAAAAAAAAAAA--- ---ACA-----------ACA--- ---AA-------------AA--- ---A---------------A--- ----------------------- ----------------------- ----------------------- ----------------------- ----------------------- ----------------------- ----------------------- 
---AAAAAAAAAAAAAAAAA--- --ACA-------------ACA-- --AA---------------AA-- --AA---------------AA-- ----------------------- ----------------------- ----------------------- ----------------------- ----------------------- ----------------------- ----------------------- 
---AAAAAAAAAAAAAAAAA--- --AA----AAAAAAA----AA-- --AA---------------AA-- --A-----------------A-- ----------------------- ----------------------- ----------------------- ----------------------- ----------------------- ----------------------- ----------------------- 
---AAAAAAAAAAAAAAAAA--- --AA--AAAACCCAAAA--AA-- --AA------DBD------AA-- --A-------BDB-------A-- ----------AAA---------- ----------AAA---------- ----------AAA---------- ----------AAA---------- ----------AAA---------- ----------AAA---------- ----------AAA---------- 
---AAAAAAAAAAAAAAAAA--- --AA--ACAAAAAAACA--AA-- -AAA---BDBBCCBDB---AAA- -A-----DBDCBCDBD-----A- -------AAACCCAAA------- --------AACCCAA-------- --------AACCCAA-------- ---------ACCCA--------- ---------ACCCA--------- ---------ACCCA--------- ---------AAAAA--------- 
---AAAAA-------AAAAA--- --A---AA-------AA---A-- -AA----DB--BB-BD----AA- -A-----BCBB-BBCB-----A- -------ACCBBBCCA------- --------ACBCBCA-------- --------ACCCCCA-------- --------ACCCBCA-------- --------ACCCCCA-------- --------ACCBCCA-------- --------AAA-AAA-------- 
---AAAA---------AAAA--- --A---AA-------AA---A-- -AA----BB-----BB----AA- AA-----DBB---BCD-----AA -------ACB---BCA------- --------AB-B-BA-------- --------ABBBBBA-------- --------ACBB-BA-------- --------ACCCBCA-------- --------ACCBCCA-------- --------ABB-BBA-------- 
---AAAA---------AAAA--- --A---AB-------BA---A-- -AA----DB-----BD----AA- A------BB-----BB------A -------AB-----BA------- --------AB---BA-------- --------AB---BA-------- --------AB---BA-------- --------ACBB-BA-------- ---------BCBBB--------- ---------BB-BB--------- 
---AAAA---------AAAA--- --A---AB-------BA---A-- -A-----BB-----BB-----A- A------DB-----BD------A -------AB-----BA------- --------AB---BA-------- --------AB---BA-------- --------AB---BA-------- --------AB-B-BA-------- ---------BBB-B--------- ---------BB-BB--------- 
---AAAA---------AAAA--- --A---AB-------BA---A-- -A-----DB-----BD-----A- A------BB-----BB------A -------AB-----BA------- --------AB---BA-------- --------AB---BA-------- --------AB---BA-------- ---------BBB-B--------- ---------BCBBB--------- ---------BB-BB--------- 
---AAAA---------AAAA--- --A---AB-------BA---A-- -A-----BB-----BB-----A- A------DB-----BD------A -------AB-----BA------- --------AB---BA-------- --------AB---BA-------- --------AB---BA-------- ---------BB--B--------- ---------BCB-B--------- ---------BB-BB--------- 
---AAAA---------AAAA--- --A---AB-------BA---A-- -A-----DB-----BD-----A- A------BB-----BB------A -------AB-----BA------- --------AB---BA-------- --------AB---BA-------- --------AB---BA-------- ---------B---B--------- ---------BBBBB--------- ---------BB-BB--------- 
---AAAA---------AAAA--- --A---AB-------BA---A-- -A-----BB-----BB-----A- A------DB-----BD------A -------AB-----BA------- --------AB---BA-------- --------AB--BBA-------- --------ACB-BCA-------- ---------BB-BB--------- ---------BCBCB--------- ---------BB-BB--------- 
---AAAA---------AAAA--- --A---AB-------BA---A-- -AA----DB-----BD----AA- A------BB-----BB------A -------AB-----BA------- --------ABB--BA-------- --------ACBBBCA-------- --------ACCBCCA-------- --------ACCBCCA-------- ---------BCBCB--------- ---------BB-BB--------- 
---AAAA---------AAAA--- --A---AB-------BA---A-- -AA----BB-----BB----AA- AA-----DBB---BCD-----AA -------ACBB-BBCA------- --------ACCBBCA-------- --------ACCCCCA-------- --------ACCCCCA-------- --------ACCCCCA-------- --------ACCBCCA-------- --------ABB-BBA-------- 
---AAAAA-------AAAAA--- --A---AA-------AA---A-- -AA----DBB----BD----AA- -A-----BCCBBBBBB-----A- -------ACCCBCCCA------- --------ACCCCCA-------- --------ACCCCCA-------- --------ACCCCCA-------- --------ACCCCCA-------- --------ACCBCCA-------- --------AAA-AAA-------- 
---AAAAAAAAAAAAAAAAA--- --A---ACAAAAAAACA--AA-- -AA----BDBBBBBDB---AAA- -A-----DBDCCCDBD-----A- -------AAACCCAAA------- --------AACCCAA-------- --------AACCCAA-------- ---------ACCCA--------- ---------ACCCA--------- ---------ACCCA--------- ---------AAAAA--------- 
---AAAAAAAAAAAAAAAAA--- --AA--AAAACCCAAAA--AA-- --AA------DBD------AA-- ----------BDB---------- ----------AAA---------- ----------AAA---------- ----------AAA---------- ----------AAA---------- ----------AAA---------- ----------AAA---------- ----------AAA---------- 
---AAAAAAAAAAAAAAAAA--- --AA----AAAAAAA----AA-- --AA---------------AA-- ----------------------- ----------------------- ----------------------- ----------------------- ----------------------- ----------------------- ----------------------- ----------------------- 
---AAAAAAAAAAAAAAAAA--- --AA---------------AA-- ----------------------- ----------------------- ----------------------- ----------------------- ----------------------- ----------------------- ----------------------- ----------------------- ----------------------- 
---AAAAAAAAAAAAAAAAA--- ---A---------------A--- ----------------------- ----------------------- ----------------------- ----------------------- ----------------------- ----------------------- ----------------------- ----------------------- ----------------------- 
----AAAAAAAAAAAAAAA---- ----AA-----------AA---- ----------------------- ----------------------- ----------------------- ----------------------- ----------------------- ----------------------- ----------------------- ----------------------- ----------------------- 
-----AAAAAAAAAAAAA----- -----AA---------AA----- ----------------------- ----------------------- ----------------------- ----------------------- ----------------------- ----------------------- ----------------------- ----------------------- ----------------------- 
------AAAAAAAAAAA------ ------AA-------AA------ ----------------------- ----------------------- ----------------------- ----------------------- ----------------------- ----------------------- ----------------------- ----------------------- ----------------------- 
---------AAAAA--------- ----------------------- ----------------------- ----------------------- ----------------------- ----------------------- ----------------------- ----------------------- ----------------------- ----------------------- ----------------------- 
