model
size = 32 32 16, scale = 0.05, origin = -y
material 
  colors = A:#FCFAF2
voxels
12-15(8A24-)8A23-10A21-12A19-6(14A18-)14A19-12A21-10A182-14(A8-A22-)A8-A21-2A8-2A19-2A10-2A17-8(2A12-2A16-)3A10-3A17-14A19-12A148-14(A10-A20-)A10-A19-2A10-2A17-A14-A16-A14-A15-5(2A14-)2A13-3A14-3A12-3A14-3A11-4A14-4A10-4A14-4A11-3A14-3A13-2A14-2A16-14A20-10A116-14(A12-A18-)A12-A17-2A12-2A16-A14-A15-A16-A14-A16-A13-2A16-2A12-2A16-2A11-3A16-3A9-2(4A16-4A8-)4A16-4A9-3A16-3A11-3A14-3A13-2A14-2A16-14A21-8A84-15(A14-A16-)A14-A15-A16-A14-A16-A13-3(A18-A12-)A18-A11-2A18-2A8-A-A20-A-A5-4A20-4A6-2A20-2A9-2A18-2A11-3A14-3A13-2A14-2A16-14A21-8A51-15(A16-A14-)A16-A13-4(A18-A12-)A18-A104-2A24-2A3-4A22-4A4-2A22-2A7-3A18-3A9-4A14-4A12-2A14-2A16-3A8-3A21-A6-2(A18-)18(A12-A18-)A230-4A24-4A2-3A22-3A6-A22-A9-3A16-3A13-2A12-2A18-3A6-3A2(16-17(A18-A12-)A18-A262-4A24-4A-4A22-4A4-2A22-2A7-3A18-3A10-4A12-4A16-A10-A)16-18(A18-A12-)A18-A230-4A24-4A2-3A22-3A6-A22-A9-3A16-3A13-2A12-2A18-3A6-3A17-15(A16-A14-)A16-A13-4(A18-A12-)A18-A104-2A24-2A3-4A22-4A4-2A22-2A7-3A18-3A9-3A16-3A12-6A6-6A16-4A6-4A21-8A19-17(A16-A14-)A16-A13-3(A18-A12-)A18-A11-2A18-2A8-A-2A18-2A-A5-5A18-5A6-2A20-2A9-2A18-2A11-2A16-2A13-18A16-14A21-8A52-16(A14-A16-)A14-A15-A16-A14-A16-A13-2A16-2A12-2A16-2A11-3A16-3A9-2(4A16-4A8-)4A16-4A9-3A16-3A11-3A14-3A13-18A16-14A20-10A84-15(A12-A18-)A12-A17-A14-A16-A14-A15-3(2A14-)2A13-2(3A14-3A12-)3A14-3A11-4A14-4A10-4A14-4A11-3A14-3A13-18A16-14A19-12A116-15(A10-A20-)A10-A19-A12-A17-7(2A12-2A16-)2A12-2A17-14A18-14A19-12A149-15(10A22-)10A21-12A19-6(14A18-)14A19-12A20-12A21-10A171-
