model
size = 24 22 24, scale = 0.05, origin = -y
material 
  colors = A:#3F9 B:#CF3 C:#F96 D:#0C0 E:#00F F:#D00 G:#03F H:#777 I:#AAA J:#444
voxels
------------------------ ------------------------ ------------------------ ------------------------ ------------------------ ------------------------ ------------------------ ------------------------ ------------------------ ------------------------ ------------------------ ------------------------ ------------------------ ------------------------ --------EEEEEEEE-------- ------------------------ ------------------------ ------------------------ ------------------------ ------------------------ ------------------------ ------------------------ 
------------------------ ------------------------ ------------------------ ------------------------ ------------------------ ------------------------ ------------------------ ------------------------ ------------------------ ------------------------ ------------------------ ------------------------ ------------------------ ------------------------ ------EED-------EE------ --------DDDDDDDD-------- ------------------------ ------------------------ ------------------------ ------------------------ ------------------------ ------------------------ 
------------------------ ------------------------ ------------------------ ------------------------ ------------------------ ------------------------ ------------------------ ------------------------ ------------------------ ------------------------ ------------------------ ------------------------ ------------------------ ------------------------ -----ED-----------E----- ------DDD------DDD------ ---------AAAAAA--------- ------------------------ ------------------------ ------------------------ ------------------------ ------------------------ 
------------------------ ------------------------ ------------------------ ------------------------ ------------------------ ------------------------ ------------------------ ------------------------ ------------------------ ------------------------ ------------------------ ------------------------ ------------------------ ------------------------ ---EED-------------EE--- -----DD-----------D----- -------AAAAAAAAAAAA----- -----------BB----------- ------------------------ ------------------------ ------------------------ ------------------------ 
------------------------ ------------------------ ------------------------ ------------------------ ------------------------ ------------------------ ------------------------ ------------------------ ------------------------ ------------------------ ------------------------ ------------------------ ------------------------ ------------------------ ---ED---------------EE-- ----DA-------------D---- -----AAAAA-----AAAA----- --------BBBBBBBB-------- ------------------------ ------------------------ ------------------------ ------------------------ 
------------------------ ------------------------ ------------------------ ------------------------ ------------------------ ------------------------ ------------------------ ------------------------ ------------------------ ------------------------ ------------------------ ------------------------ ------------------------ ------------------------ --ED-----------------EE- ---DA---------------D--- ----AAAA---------AAA---- ------BBBBBBBBBBBB------ ----------CCCC---------- ------------------------ ------------------------ ------------------------ 
------------------------ ------------------------ ------------------------ ------------------------ ------------------------ ------------------------ ------------------------ ------------------------ ------------------------ ------------------------ ------------------------ ------------------------ ------------------------ ------------------------ -ED-------------------E- --DD----------------DD-- ----AAA-----------AA---- -----BBBBB-----BBBB----- --------CCCCCCCC-------- ------------------------ ------------------------ ------------------------ 
------------------------ ------------------------ ------------------------ ------------------------ ------------------------ ------------------------ ------------------------ ------------------------ ------------------------ ------------------------ ------------------------ ------------------------ ------------------------ ------------------------ -ED-------------------E- --DA-----------------D-- ---AAA-------------AA--- -----BBBB-------BBB----- -------CCCCCCCCCC------- ------------------------ ------------------------ ------------------------ 
------------------------ ------------------------ ------------------------ ------------------------ ------------------------ ------------------------ ------------------------ ------------------------ ------------------------ ------------------------ ------------------------ ------------------------ ------------------------ ------------------------ ED--------------------E- -DD------------------DD- ---AA--------------AA--- ----BBBB---------BBB---- ------CCCCC---CCCC------ ----------FFFF---------- ------------------------ ------------------------ 
------------------------ ------------------------ ------------------------ ------------------------ ------------------------ ------------------------ ------------------------ ------------------------ ------------------------ ------------------------ ------------------------ ------------------------ ------------------------ ------------------------ ED---------------------E -DA-------------------D- --AAA---------------AA-- ----BBB-----------BB---- ------CCCC-----CCC------ ---------FFFFFF--------- ------------------------ ------------------------ 
------------------------ ------------------------ ------------------------ ------------------------ ------------------------ ------------------------ ------------------------ ------------------------ ------------------------ ------------------------ ------------------------ ------------------------ ------------------------ ------------------------ ED---------------------E -DA-------------------D- --AA----------------AA-- ----BBB-----------BB---- -----CCCC--GGG--CCC----- --------FFFGGGFF-------- -----------GGG---------- ------------------------ 
------------B----------- ------------C----------- ------------F----------- ------------J----------- ------------H----------- ------------H----------- ------------H----------- ------------H----------- ------------H----------- ------------H----------- ------------H----------- ------------H----------- ------------H----------- ------------H----------- ED----------H----------E -DA---------H---------D- --AA--------H-------AA-- ---BBBB-----H-----BBB--- -----CCCC--GIG--CCC----- --------FFFGAGFF-------- -----------GIG---------- ------------H----------- 
------------A----------- ------------------------ ------------C----------- ------------------------ ------------------------ ------------------------ ------------------------ ------------------------ ------------------------ ------------------------ ------------------------ ------------------------ ------------------------ ------------------------ ED---------------------E -DA-------------------D- --AA----------------AA-- ---BBBB-----------BBB--- -----CCCC--GGG--CCC----- --------FFFGGGFF-------- -----------GGG---------- ------------------------ 
------------D----------- ------------------------ ------------B----------- ------------------------ ------------------------ ------------------------ ------------------------ ------------------------ ------------------------ ------------------------ ------------------------ ------------------------ ------------------------ ------------------------ ED--------------------EE -DA-------------------D- --AAA---------------AA-- ----BBB-----------BB---- -----CCCCC-----CCCC----- --------FFFFFFFF-------- ------------------------ ------------------------ 
------------E----------- ------------D----------- ------------A----------- ------------------------ ------------------------ ------------------------ ------------------------ ------------------------ ------------------------ ------------------------ ------------------------ ------------------------ ------------------------ ------------------------ ED--------------------E- -DA-------------------D- --AAA--------------AAA-- ----BBBB---------BBB---- ------CCCCC---CCCC------ ---------FFFFFF--------- ------------------------ ------------------------ 
------------------------ ------------------------ ------------------------ ------------------------ ------------------------ ------------------------ ------------------------ ------------------------ ------------------------ ------------------------ ------------------------ ------------------------ ------------------------ ------------------------ EDD-------------------E- -DDA-----------------DD- ---AAA-------------AA--- ----BBBBB-------BBBB---- ------CCCCCCCCCCCC------ ----------FFFF---------- ------------------------ ------------------------ 
------------------------ ------------------------ ------------------------ ------------------------ ------------------------ ------------------------ ------------------------ ------------------------ ------------------------ ------------------------ ------------------------ ------------------------ ------------------------ ------------------------ -ED------------------E-- --DA-----------------D-- ---AAAA-----------AAA--- -----BBBBB-----BBBB----- -------CCCCCCCCCC------- ------------------------ ------------------------ ------------------------ 
------------------------ ------------------------ ------------------------ ------------------------ ------------------------ ------------------------ ------------------------ ------------------------ ------------------------ ------------------------ ------------------------ ------------------------ ------------------------ ------------------------ -EDD-----------------E-- --DDA---------------DD-- ----AAAA---------AAA---- -----BBBBBBBBBBBBBB----- --------CCCCCCCC-------- ------------------------ ------------------------ ------------------------ 
------------------------ ------------------------ ------------------------ ------------------------ ------------------------ ------------------------ ------------------------ ------------------------ ------------------------ ------------------------ ------------------------ ------------------------ ------------------------ ------------------------ --EDD---------------E--- ---DAA-------------AD--- ----AAAAA------AAAAA---- ------BBBBBBBBBBBB------ ----------CCCC---------- ------------------------ ------------------------ ------------------------ 
------------------------ ------------------------ ------------------------ ------------------------ ------------------------ ------------------------ ------------------------ ------------------------ ------------------------ ------------------------ ------------------------ ------------------------ ------------------------ ------------------------ ---EDD-------------E---- ----AAA-----------AD---- -----AAAAA---AAAAAA----- --------BBBBBBBB-------- ------------------------ ------------------------ ------------------------ ------------------------ 
------------------------ ------------------------ ------------------------ ------------------------ ------------------------ ------------------------ ------------------------ ------------------------ ------------------------ ------------------------ ------------------------ ------------------------ ------------------------ ------------------------ ---EEDD-----------EE---- -----DDAA-------ADD----- -------AAAAAAAAAA------- -----------BB----------- ------------------------ ------------------------ ------------------------ ------------------------ 
------------------------ ------------------------ ------------------------ ------------------------ ------------------------ ------------------------ ------------------------ ------------------------ ------------------------ ------------------------ ------------------------ ------------------------ ------------------------ ------------------------ -----EDDD-------EEE----- ------DDDA----ADDD------ ---------AAAAAA--------- ------------------------ ------------------------ ------------------------ ------------------------ ------------------------ 
------------------------ ------------------------ ------------------------ ------------------------ ------------------------ ------------------------ ------------------------ ------------------------ ------------------------ ------------------------ ------------------------ ------------------------ ------------------------ ------------------------ ------EED------EEE------ --------DDDDDDDD-------- ------------------------ ------------------------ ------------------------ ------------------------ ------------------------ ------------------------ 
------------------------ ------------------------ ------------------------ ------------------------ ------------------------ ------------------------ ------------------------ ------------------------ ------------------------ ------------------------ ------------------------ ------------------------ ------------------------ ------------------------ --------EEEEEEEE-------- ------------------------ ------------------------ ------------------------ ------------------------ ------------------------ ------------------------ ------------------------ 
