model
size = 23 30 23, scale = 0.05, origin = -y
material 
  colors = A:#444 B:#888 C:#222 D:#111
voxels
--------CDDDDDC-------- --------CCDDDCC-------- --------CCDDDCC-------- --------CCDDDCC-------- --------CCDDDCC-------- --------CCDDDCC-------- --------CCDDDCC-------- --------CCDDDCC-------- --------CCDDDCC-------- --------CCDDDCC-------- -------CCCDDDCCC------- -------CCCDDDCCC------- -------CCCDDDCCC------- -------CCCDDDCCC------- ------CCCCDDDCCCC------ -----CCCCCDDDCCCCC----- -----CCCCCDDDCCCCC----- -----CCCCDDDDDCCCC----- -----CCDDDDDDDDDCC----- -----DDDDDDDDDDDDD----- ------DDDDDDDDDDD------ ------CCCCCCCCCCC------ ------AAACCBCCAAA------ ------AAAACBCAAAA------ ------AAAACBCAAAA------ ----------------------- ----------------------- ----------------------- ----------------------- ----------------------- 
------AAA-----AAA------ --------A-----A-------- --------A-----A-------- --------B-----B-------- -------BB-----BB------- -------BB-----BB------- ------BBB------BB------ -----BBB-------BBB----- -----BBB-------BBB----- ----BBBB-------BBBB---- ---BBBBC-------CBBBB--- ---BBBBC-------CBBBB--- -----BBC-------CBB----- -----BBC-------CBB----- -----BCC-------CCB----- ------CC-------CC------ ------CC-------CCB----- ----C-------------C---- ----C-------------C---- ----D-C-----------D---- ----DDD---------DDD---- ----CCC---------CCC---- ----AAC---------AAA---- ----AAC----------AA---- ----AACAACC-CCAACAA---- ------AAAACBCAAAA------ ----------------------- ----------------------- ----------------------- ----------------------- 
----AA--A-----AA-AA---- --------A-----AA------- --------A------A------- --------B------A------- -------B-------A------- -------A-------A------- ------AB-------BA------ -----AA---------A------ -----A----------------- -----A----------A------ ---BBB----------ABBB--- --BB-B-----------BBBB-- ---BBB-----------BBB--- ---BBB-----------BBB--- ---BBB----------BBBB--- --BBBB----------B-BBB-- --BBBB----------BBBBB-- ----C-------------C---- ----C-------------C---- ----A-------------A---- ---DD-------------DD--- ---CC-------------CC--- ---AA-------------AA--- ----A-------------A---- ----A-------------A---- -----AAAAACBCAAAAA----- ----------------------- ----------------------- ----------------------- ----------------------- 
-CAA--AA--------A--AAC- -C-----A--------A----C- -C-----A--------A----C- -C-----A--------A----C- -C-----A--------A----C- -C-----A--------A----C- -C-----A--------A----C- -C--------------A----C- -C-----A--------A----C- -C---AA---------A----C- -C-BBB-----------BBBAC- -C----------------A--C- -CBB---------------BBC- -CBB---------------BBC- -CBBBBB---------BBBBBC- -CBBBBB---------BBBBBC- -CBBBBB---------BBBBBC- -CCC---------------CCC- -CCC---------------CCC- -CCD--------------ADCC- -DDD---------------DDD- -CCC---------------CCC- -AAA---------------AAA- -AAA---------------AAA- --AA---------------AA-- --AAAACAACCBCCAACAAAA-- --AAAAAAAACBCAAAAAAAA-- -----AAAAACBCAAAAA----- ----------------------- ----------------------- 
-AA--AA----------A---A- -AA--AA----------A---A- -AA--AA----------A---A- -AA--AA----------A---A- -AA--AA----------A---A- -AA--AA----------A---A- -AA--AA----------A---A- -AA--AA---------AA---A- -AA--AAA--------AA---A- -AA--AA----------A---A- -AAAAB-----------AAAAA- -AA------------------A- -AA------------------A- -AA------------------A- -AA------------------A- -AA------------------A- -AA------------------A- -A------------------AA- -A-------------------A- -C-------------------C- -D-------------------D- -C-------------------C- -A-------------------A- -A-------------------A- -A-------------------A- -A---------------AA--A- --AAA-------A----AAAA-- -----AAAAACBCAAAAA----- ----------------------- ----------------------- 
-AAAAA------------A--A- -AA--A------------A--A- -AA--A------------A--A- -AA--A------------A--A- -AA--A------------A--A- -AA--A------------A--A- -AA--A------------A--A- -AA--A------------A--A- -AA--A------------A--A- -AA--A------------A--A- -A-AAA------------AAAA- -A-------------------A- -A-------------------A- -A-------------------A- -A-------------------A- -A-------------------A- -A-------------------A- -A-------------------A- -A-------------------A- -C-------------------C- -D-------------------D- -C-------------------C- -AA------------------A- -A-------------------A- -A-------------------A- -A-------------------A- --AA----------------A-- ---AAAAAAACBCAAAAAAA--- -----AAAAACBCAAAAA----- ----------------------- 
---AA--------------AAA- -A-AA--------------AAA- -A-AA--------------AAA- -A-AA--------------AAA- -A-AA--------------AAA- -A-AA--------------AAA- -A-AA--------------AAA- -A-AA--------------AAA- -A-AA--------------AAA- -A-AA--------------AAA- -A-AA--------------AAA- -A--A--------------AAA- -A------------------AA- -A-------------------A- -A-------------------A- -A-------------------A- -A-------------------A- -A-------------------A- -A-------------------A- -C-------------------C- -D-------------------D- -C-------------------C- -A-------------------A- -A-------------------A- -A-------------------A- -A-------------------A- --A-----------------A-- ---A----AAA---AA---A--- ----AAAAAACBCAAAAAA---- ----------------------- 
----------------------- -A-------------------A- -A-------------------A- -A-------------------A- -A-------------------A- -A-------------------A- -A-A-----------------A- -A-------------------A- -A-------------------A- -A-------------------A- -A-------------------A- -A-------------------A- -A-------------------A- -A-------------------A- -A-------------------A- -A-------------------A- -A-------------------A- -A-------------------A- -A-------------------A- -C-------------------C- -D-------------------D- -C-------------------C- -A-------------------A- -A-------------------A- -A-------------------A- -A-------------------A- --A-----------------A-- ---AA--------------A--- ----AAAAAACBCAAAAAA---- -----AAAAACBCAAAAA----- 
----------------------- -A-------------------A- -A-------------------A- -A-------------------A- -A-------------------A- -A-------------------A- -A-------------------A- -A-------------------A- -A-------------------A- -A-------------------A- -A-------------------A- -A-------------------A- -A-------------------A- -A-------------------A- -A-------------------A- -A-------------------A- -A-------------------A- -A-------------------A- -A-------------------A- -C-------------------C- -C-------------------C- -C-------------------C- -A-------------------A- -A-------------------A- -A-------------------A- -A-------------------A- --A-----------------A-- ---AA--------------A--- ----A-------------A---- -----AAAAACBCAAAAA----- 
----------------------- --A-----------------A-- --A-----------------A-- --A-----------------A-- --A-----------------A-- --A-----------------A-- --A-----------------A-- --A-----------------A-- --A-----------------A-- --A-----------------A-- --A-----------------A-- --A-----------------A-- --A-----------------A-- --A-----------------A-- --A-----------------A-- -A-------------------A- BB-------------------BB BB-------------------BB -A-------------------A- -A-------------------A- -A-------------------A- -A-------------------A- -A-------------------A- -A-------------------A- -A-------------------A- -A-------------------A- --A-----------------A-- ---AA--------------A--- ----A-------------A---- -----AAAAACBCAAAAA----- 
----------------------- AA-------------------AA AA-------------------AA AA-------------------AA AA-------------------AA AA-------------------AA AA-------------------AA AA-------------------AA AA-------------------AA AA-------------------AA AA-------------------AA AA-------------------AA AA-------------------AA AA-------------------AA AA-------------------AA -A-------------------A- BB-------------------BB -A-------------------A- -A-------------------A- -A-------------------A- AA-------------------AA AA-------------------AA -A-------------------A- -A-------------------A- -A-------------------A- -A-------------------A- --A-----------------A-- ---A---------------A--- ----A-------------A---- -----AAAAACBCAAAAA----- 
----------------------- ----------------------- BB-------------------BB BB-------------------BB BB-------------------BB BB-------------------BB BB-------------------BB BB-------------------BB BB-------------------BB BB-------------------BB BB-------------------BB BB-------------------BB BB-------------------BB BB-------------------BB BB-------------------BB -A-------------------A- BB-------------------BB AA-------------------AA BB-------------------BB BB-------------------BB BB-------------------BB BB-------------------BB AA-------------------AA -A-------------------A- -AA------------------A- -A-------------------A- --A-----------------A-- ---AA--------------A--- ----A------------AA---- -----AAAAACBCAAAAA----- 
----------------------- ----------------------- BB-------------------BB BB-------------------BB BB-------------------BB BB-------------------BB BB-------------------BB BB-------------------BB BB-------------------BB BB-------------------BB BB-------------------BB BB-------------------BB BB-------------------BB BB-------------------BB BB-------------------BB -A-------------------A- BB-------------------BB AA-------------------AA BB-------------------BB BB-------------------BB BB-------------------BB BB-------------------BB AA-------------------AA -A-------------------A- -AA------------------A- -A-------------------A- --A-----------------A-- ---AA--------------A--- ----AA------------A---- -----AAAAACBCAAAAA----- 
----------------------- ----------------------- AA-------------------AA AA-------------------AA AA-------------------AA AA-------------------AA AA-------------------AA AA-------------------AA AA-------------------AA AA-------------------AA AA-------------------AA AA-------------------AA AA-------------------AA AA-------------------AA AA-------------------AA -A-------------------A- BB-------------------BB -A-------------------A- -A-------------------A- -A-------------------A- AA-------------------AA AA-------------------AA -A-------------------A- -A-------------------A- -AA------------------A- -A-------------------A- --A-----------------A-- ---AA--------------A--- ----A-------------A---- -----AAAAACBCAAAAA----- 
----------------------- ----------------------- ----------------------- -A-------------------A- -A-------------------A- -A-------------------A- -A-------------------A- -A-------------------A- -A-------------------A- -A-------------------A- -A-------------------A- -A-------------------A- -A-------------------A- -A-------------------A- -A-------------------A- -A-------------------A- BB-------------------BB BB-------------------BB -A-------------------A- -A-------------------A- -A-------------------A- -A-------------------A- -A-------------------A- -A-------------------A- -AA------------------A- -A-------------------A- --A-----------------A-- ---A---------------A--- ----A-------------A---- -----AAAAACBCAAAAA----- 
----------------------- ----------------------- ----------------------- -A-------------------A- -A-------------------A- -A-------------------A- -A-------------------A- -A-------------------A- -A-------------------A- -A-------------------A- -A-------------------A- -A-------------------A- -A-------------------A- -A-------------------A- -A-------------------A- -A-------------------A- -A-------------------A- -A-------------------A- -A-------------------A- -A-------------------A- -A-------------------A- -A-------------------A- -A-------------------A- -A-------------------A- -AA------------------A- -A-------------------A- --A-----------------A-- ---A---------------A--- ----A-------------A---- -----AAAAACBCAAAAA----- 
----------------------- ----------------------- ----------------------- -A-------------------A- -A-------------------A- -A-------------------A- -A-------------------A- -A-------------------A- -A-------------------A- -A-------------------A- -A-------------------A- -A-------------------A- -A-------------------A- -A-------------------A- -A-------------------A- -A-------------------A- -A-------------------A- -A-------------------A- -A-------------------A- -A-------------------A- -A-------------------A- -A-------------------A- -A-------------------A- -A-------------------A- -A-------------------A- -A-------------------A- --A-----------------A-- ---A---------------A--- ----A-------------A---- -----AAAAACBCAAAAA----- 
----------------------- ----------------------- ----------------------- ----------------------- -A-------------------A- -A-------------------A- -A-------------------A- -A-------------------A- -A-------------------A- -A-------------------A- -A-------------------A- -A-------------------A- -A-------------------A- -A-------------------A- -A-------------------A- -A-------------------A- -A-------------------A- -A-------------------A- -A-------------------A- -A-------------------A- -A-------------------A- -A-------------------A- -A-------------------A- -A-------------------A- -A-------------------A- -A-------------------A- --A-----------------A-- ---A---------------A--- ----AAAAAACBCAAAAAA---- -----AAAAACBCAAAAA----- 
----------------------- ----------------------- ----------------------- ----------------------- -A-------------------A- -A-------------------A- -A-------------------A- -A-------------------A- -A-------------------A- -A-------------------A- -A-------------------A- -A-------------------A- -A-------------------A- -A-------------------A- -A-------------------A- -A-------------------A- -A-------------------A- -A-------------------A- -A-------------------A- -A-------------------A- -A-------------------A- -A-------------------A- -A-------------------A- -A-------------------A- -A-------------------A- -A-------------------A- --A-----------------A-- ---A---------------A--- ----AAAAAACBCAAAAAA---- ----------------------- 
----------------------- ----------------------- ----------------------- ----------------------- -A-------------------A- -A-------------------A- -A-------------------A- -A-------------------A- -A-------------------A- -A-------------------A- -A-------------------A- -A-------------------A- -A-------------------A- -A-------------------A- -A-------------------A- -A-------------------A- -A-------------------A- -A-------------------A- -A-------------------A- -A-------------------A- -A-------------------A- -A-------------------A- -A------------------AA- -AA-----------------AA- --A-----------------A-- --A-----------------A-- --A-----------------A-- ---AAAAAAACBCAAAAAAA--- -----AAAAACBCAAAAA----- ----------------------- 
----------------------- ----------------------- ----------------------- ----------------------- --AA---------------AA-- --AA---------------AA-- --AA---------------AA-- --AA---------------AA-- --AA---------------AA-- --AA---------------AA-- --AA---------------AA-- --AA---------------AA-- --AA---------------AA-- --AA---------------AA-- --AA---------------AA-- --AA---------------AA-- --AA---------------AA-- --AA---------------AA-- --AA---------------AA-- --AA---------------AA-- --AA---------------AA-- --AA---------------AA-- --AAA--------------AA-- --AAA-------------AAA-- --AAA-------------AAA-- --AAA-------------AAA-- --AAA--AAACBCAAAAAAAA-- -----AAAAACBCAAAAA----- ----------------------- ----------------------- 
----------------------- ----------------------- ----------------------- ----------------------- ----A-------------A---- ----A-------------A---- ----A-------------A---- ----A-------------A---- ----A-------------A---- ----A-------------A---- ----A-------------A---- ----A-------------A---- ----A-------------A---- ----A-------------A---- ----A-------------A---- ----A-------------A---- ----A-------------A---- ----A-------------A---- ----A-------------A---- ----A-------------A---- ----A-------------A---- ----A-------------A---- ----A------------AA---- ----AA------------A---- ----AA------------A---- ----AAAAAACBCAAAAA----- -----AAAAACBCAAAAA----- ----------------------- ----------------------- ----------------------- 
----------------------- ----------------------- ----------------------- ----------------------- -----AAAAAAAAAAAAA----- -----AAAAAAAAAAAAA----- -----AAAAAAAAAAAAA----- -----AAAAAAAAAAAAA----- -----AAAAAAAAAAAAA----- -----AAAAAAAAAAAAA----- -----AAAAAAAAAAAAA----- -----AAAAAAAAAAAAA----- -----AAAAAAAAAAAAA----- -----AAAAAAAAAAAAA----- -----AAAAAAAAAAAAA----- -----AAAAAAAAAAAAA----- -----AAAAAADAAAAAA----- -----AAAAACBCAAAAA----- -----AAAAACBCAAAAA----- -----AAAAACBCAAAAA----- -----AAAAACBCAAAAA----- -----AAAAACBCAAAAA----- -----AAAAACBCAAAAA----- -----AAAAACBCAAAAA----- -----AAAAACBCAAAAA----- -----AAAAACBCAAAAA----- ----------------------- ----------------------- ----------------------- ----------------------- 
