model
size = 16 14 31, scale = 0.05, origin = -y
material 
  colors = A:#EEE B:#F90 C:#E00 D:#F96 E:#555 F:#AAA G:#F9C H:#F9F
voxels
------BBBB------ -------CC------- ---------------- ---------------- ---------------- ---------------- ---------------- ---------------- ---------------- ---------------- ---------------- ---------------- ---------------- ---------------- 
-----BBAABB----- ------CCCC------ -------AA------- ---------------- ---------------- ---------------- ---------------- ---------------- ---------------- ---------------- ---------------- ---------------- ---------------- ---------------- 
----BBBAABBB---- -----CCCCCC----- ------AAAA------ -------AA------- ---------------- ---------------- ---------------- ---------------- ---------------- ---------------- ---------------- ---------------- ---------------- ---------------- 
---BBBBAABBBB--- ----CCCCCCCC---- -----AAAAAA----- ------AAAA------ -------AA------- ---------------- ---------------- ---------------- ---------------- ---------------- ---------------- ---------------- ---------------- ---------------- 
--BBBBBAABBBBB-- ---CCCCCCCCCC--- ----AAAAAAAA---- -----AAAAAA----- ------AAAA------ -------AA------- ---------------- ---------------- ---------------- ---------------- ---------------- ---------------- ---------------- ---------------- 
--BBBBBAABBBBB-- --CCCCCCCCCCCC-- ---AAAAAAAAAA--- ----AAAAAAAA---- -----AAAAAA----- ------AAAA------ ---------------- ---------------- ---------------- ---------------- ---------------- ---------------- ---------------- ---------------- 
--BBBBBAABBBBB-- --CCCCCCCCCCCC-- --AAAAAAAAAAAA-- ---AAAAAAAAAA--- ----AAAAAAAA---- -----AAAAAA----- ------AAAA------ ---------------- ---------------- ---------------- ---------------- ---------------- ---------------- ---------------- 
-BBBBBBAABBBBBB- --CAAAAAAAAAAC-- --CAAAAAAAAAAC-- --AAAAAAAAAAAA-- ---AAAAAAAAAA--- ----AAAAAAAA---- -----AAAAAA----- ---------------- ---------------- ---------------- ---------------- ---------------- ---------------- ---------------- 
-BBBBBBAABBBBBB- -CCAAAAAAAAAACC- --CAAAAAAAAAAC-- --AAAAAAAAAAAA-- --AAAAAAAAAAAA-- ---AAAAAAAAAA--- ----AAAAAAAA---- ------AAAA------ ---------------- ---------------- ---------------- ---------------- ---------------- ---------------- 
-BBBBBBAABBBBBB- -CCAAAAAAAAAACC- -CCAAAAAAAAAACC- --AAAAAAAAAAAA-- --AAAAAAAAAAAA-- ---AAAAAAAAAA--- ----AAAAAAAA---- ----CAAAAAAC---- -----C----C----- ---------------- ---------------- ---------------- ---------------- ---------------- 
-BBBBBBAABBBBBB- -CCAAAAAAAAAACC- -CCAAAAAAAAAACC- -AAAAAAAAAAAAAA- --AAAAAAAAAAAA-- ---AAAAAAAAAA--- ----AAAAAAAA---- ----FAAAAAAF---- ------CCCC------ ---------------- ---------------- ---------------- ---------------- ---------------- 
-BBBBBBAABBBBBB- -CCAAAAAAAAAACC- -CCAAAAAAAAAACC- -AAAAAAAAAAAAAA- -AAAAAAAAAAAAAA- ---AAAAAAAAAA--- ----AAAAAAAA---- -----AAAAAA----- ------AAAA------ ---------------- ---------------- ---------------- ---------------- ---------------- 
-BBBBBBAABBBBBB- -CCAAAAAAAAAACC- -CCAAAAAAAAAACC- -AAAAAAAAAAAAAA- --AAAAAAAAAAAA-- --AAAAAAAAAAAA-- ----AAAAAAAA---- ----CAAAAAAC---- -----CAAAAC----- ------CCCC------ ---------------- ---------------- ---------------- ---------------- 
-BBBBBBAABBBBBB- -CCAAAAAAAAAACC- --CAAAAAAAAAAC-- --AAAAAAAAAAAA-- --AAAAAAAAAAAA-- --AAAAAAAAAAAA-- ---AAAAAAAAAA--- ----FAAAAAAF---- ------AAAA------ ---------------- ---------------- ---------------- ---------------- ---------------- 
-BBBBB-AA-BBBBB- --CAAAAAAAAAAC-- --CAAA----AAAC-- --AAAA----AAAA-- --AAAA----AAAA-- ---AAA----AAA--- ---AAA----AAA--- ----AA----AA---- -----AAAAAA----- -----CAAAAC----- ------CCCC------ ---------------- ---------------- ---------------- 
---------------- ---BAAAAAAAAB--- --CAAA----AAAC-- --AAAA----AAAA-- ---AAA----AAA--- ---AAA----AAA--- ----AA----AA---- -----A----A----- ----F-AAAA-F---- -----CAAAAC----- ---------------- ---------------- ---------------- ---------------- 
---------------- ---BADADAAAAB--- ---BA------AB--- --AAA------AAA-- ---AA------AA--- ----AA----AA---- -----A----A----- ----AA----AA---- ----A-AAAA-A---- ------AAAA------ ---------------- ---------------- ---------------- ---------------- 
---------------- ---BAADADAAAB--- ---BA------AB--- --AAA------AAA-- ---AA------AA--- ----AA----AA---- -----A----A----- ----AA----AA---- ----AAAAAAAA---- -----AAAAAA----- ------AAAA------ ------CCCC------ ---------------- ---------------- 
---------------- ---BAAAAADAAB--- ---BA------AB--- --AAA------AAA-- ---AA------AA--- ---AA------AA--- ----AA----AA---- -----A----A----- ----AAAAAAAA---- ----CAAAAAAC---- -----C----C----- ---------------- ---------------- ---------------- 
---------------- ---BAAAAAAAAB--- --CAA------AAC-- --AAAA----AAAA-- --AAAA----AAAA-- ---AAA----AAA--- ---AAA----AAA--- ----AA----AA---- ----AA----AA---- ----FAAAAAAF---- -----AAAAAA----- -----AAAAAA----- ---------------- ---------------- 
-BBBBBBBBBBBBBB- -CCAAAAAAAAAACC- --CAA------AAC-- --AAAA----AAAA-- --AAAA----AAAA-- --AAAA----AAAA-- --AAAA----AAAA-- ---AAA----AAA--- ----AA----AA---- ---------------- -----AAAAAA----- -----AAAAAA----- -----AAAAAA----- ---------------- 
BBBBBBBBBBBBBBBB -CCAAABBBBAAACC- -CCAA------AACC- -AAAAA----AAAAA- -AAAAA----AAAAA- -AAAAA----AAAAA- -AAAAA----AAAAA- --AAAA----AAAA-- --AAAA----AAAA-- --AAAA----AAAA-- ---AAA----AAA--- ---A--------A--- ---------------- ---------------- 
BBBBBBBBBHHBBBBB CCCAABBBBBBAACCC -CCAA------AACC- -AAAAA----AAAAA- -AAAAA----AAAAA- -AAAAA----AAAAA- -AAAAA----AAAAA- ----AA----AAA--- --AAAA----AAAA-- --AAAA----AAAA-- --AAA------AAA-- --AA--------AA-- ---A--------A--- ---------------- 
BBBBBBBBGGHBBBBB CCCAABBBBBBAACCC -CCAA------AACC- -AAAAA----AAAAA- -AAAAA----AAAAA- -AAAAA----AAAAA- -AAAAA----AAAAA- --AAAA----AAAA-- --AAAA----AAAA-- --EAAA----AAAE-- --EAA------AAE-- --A----------A-- --A----------A-- ---------------- 
BBBBBBBBGGBBBBBB CCCAABBBBBBAACCC -CCAA------AACC- -AAAAA----AAAAA- -AAAAA----AAAAA- -AAAAA----AAAAA- -AAAAA----AAAAA- --AAAA----AAAA-- --AAAA----AAAA-- --EAAA----AAAE-- --EAA------AAE-- --A----------A-- --A----------A-- ---------------- 
BBBBBBBBBBBBBBBB CCCAABBBBBBAACCC -CCAA------AACC- -AAAAA----AAAAA- -AAAAA----AAAAA- -AAAAA----AAAAA- -AAAAA----AAAAA- ----AA----AAA--- --AAAA----AAAA-- --AAAA----AAAA-- --AAA------AAA-- --AA--------AA-- ---A--------A--- ---------------- 
BBBBBBBBBBBBBBBB -CCCCCBBBBCCCCC- -AAAAA----AAAAA- -AAAAA----AAAAA- -AAAAA----AAAAA- -AAAAA----AAAAA- -AAAAA----AAAAA- --AAAA----AAAA-- --AAAA----AAAA-- --AAAA----AAAA-- --AAAA----AAAA-- ---AAA----AAA--- ----AA----AA---- ---------------- 
-BBBBBBBBBBBBBB- -CCCCCAAAACCCCC- --AAAAAAAAAAAA-- --AAAAAAAAAAAA-- --AAAAAAAAAAAA-- --AAAAAAAAAAAA-- --AAAAAAAAAAAA-- ---AAAAAAAAAA--- --AAAAAAAAAAAA-- --AAAAAAAAAAAA-- ---AAAAAAAAAA--- ----AAAAAAAA---- -----AAAAAA----- -------AA------- 
--BBBBBBBBBBBB-- --CCCCAAAACCCC-- ---AAAAAAAAAA--- ---AAAAAAAAAA--- ---AAAAAAAAAA--- ---AAAAAAAAAA--- ---AAAAAAAAAA--- -------AA-AA---- ---AAAAAAAAAA--- ----AAAAAAAA---- -----AAAAAA----- -------AA------- ---------------- -------AA------- 
---BBBBBBBBBB--- ---CCCAAAACCC--- ----AAAAAAAA---- ----AAAAAAAA---- ----AAAAAAAA---- ----AAAAAAAA---- ----AAAAAAAA---- -----A-AA-A----- -----AAAAAA----- -----AAAAAA----- -------AA------- ---------------- ---------------- ---------------- 
----BBBBBBBB---- ----CCBBBBCC---- ------ABBD------ -----AAADAA----- -----AADAAA----- ------AADA------ -------DA------- ---------------- ---------------- ---------------- ---------------- ---------------- ---------------- ---------------- 
