model
size = 16 14 31, scale = 0.05, origin = -y
material 
  colors = A:#EEE B:#3CF C:#F90 D:#111 E:#F96 F:#555 G:#AAA H:#F9C I:#F9F
voxels
------CCCC------ -------BB------- ---------------- ---------------- ---------------- ---------------- ---------------- ---------------- ---------------- ---------------- ---------------- ---------------- ---------------- ---------------- 
-----CCBBCC----- ------BBBB------ -------AA------- ---------------- ---------------- ---------------- ---------------- ---------------- ---------------- ---------------- ---------------- ---------------- ---------------- ---------------- 
----CCCBBCCC---- -----BBBBBB----- ------AAAA------ -------AA------- ---------------- ---------------- ---------------- ---------------- ---------------- ---------------- ---------------- ---------------- ---------------- ---------------- 
---CCCCBBCCCC--- ----BBBBBBBB---- -----AAAAAA----- ------AAAA------ -------AA------- ---------------- ---------------- ---------------- ---------------- ---------------- ---------------- ---------------- ---------------- ---------------- 
--CCCCCBBCCCCC-- ---BBBBBBBBBB--- ----AAAAAAAA---- -----AAAAAA----- ------AAAA------ -------AA------- ---------------- ---------------- ---------------- ---------------- ---------------- ---------------- ---------------- ---------------- 
--CCCCCBBCCCCC-- --BBBBBBBBBBBB-- ---AAAAAAAAAA--- ----AAAAAAAA---- -----AAAAAA----- ------AAAA------ ---------------- ---------------- ---------------- ---------------- ---------------- ---------------- ---------------- ---------------- 
--CCCCCBBCCCCC-- --BBBBBBBBBBBB-- --AAAAAAAAAAAA-- ---AAAAAAAAAA--- ----AAAAAAAA---- -----AAAAAA----- ------AAAA------ ---------------- ---------------- ---------------- ---------------- ---------------- ---------------- ---------------- 
-CCCCCCBBCCCCCC- --BBBBBBBBBBBB-- --AAAAAAAAAAAA-- --AAAAAAAAAAAA-- ---AAAAAAAAAA--- ----AAAAAAAA---- -----AAAAAA----- ---------------- ---------------- ---------------- ---------------- ---------------- ---------------- ---------------- 
-CCCCCCBBCCCCCC- -BBBBBBBBBBBBBB- --BAAAAAAAAAAB-- --AAAAAAAAAAAA-- --AAAAAAAAAAAA-- ---AAAAAAAAAA--- ----AAAAAAAA---- ------AAAA------ ---------------- ---------------- ---------------- ---------------- ---------------- ---------------- 
-CCCCCCBBCCCCCC- -BBBBBBBBBBBBBB- -BAAAAAAAAAAAAB- --AAAAAAAAAAAA-- --AAAAAAAAAAAA-- ---AAAAAAAAAA--- ----AAAAAAAA---- ----DAAAAAAD---- -----D----D----- ---------------- ---------------- ---------------- ---------------- ---------------- 
-CCCCCCBBCCCCCC- -BBBBBBBBBBBBBB- -BAAAAAAAAAAAAB- -AAAAAAAAAAAAAA- --AAAAAAAAAAAA-- ---AAAAAAAAAA--- ----AAAAAAAA---- ----GAAAAAAG---- ------DDDD------ ---------------- ---------------- ---------------- ---------------- ---------------- 
-CCCCCCBBCCCCCC- -BBBBBBBBBBBBBB- -BAAAAAAAAAAAAB- -AAAAAAAAAAAAAA- -AAAAAAAAAAAAAA- ---AAAAAAAAAA--- ----AAAAAAAA---- -----AAAAAA----- ------BBBB------ ---------------- ---------------- ---------------- ---------------- ---------------- 
-CCCCCCBBCCCCCC- -BBBBBBBBBBBBBB- -BAAAAAAAAAAAAB- -AAAAAAAAAAAAAA- --AAAAAAAAAAAA-- --AAAAAAAAAAAA-- ----AAAAAAAA---- ----DAAAAAAD---- -----DBBBBD----- ------DDDD------ ---------------- ---------------- ---------------- ---------------- 
-CCCCCCBBCCCCCC- -BBBBBBBBBBBBBB- --BAAAAAAAAAAB-- --AAAAAAAAAAAA-- --AAAAAAAAAAAA-- --AAAAAAAAAAAA-- ---AAAAAAAAAA--- ----GAAAAAAG---- ------BBBB------ ---------------- ---------------- ---------------- ---------------- ---------------- 
-CCCCC-BB-CCCCC- --BBBBBBBBBBBB-- --AAAA----AAAB-- --AAAA----AAAA-- --AAAA----AAAA-- ---AAA----AAA--- ---AAA----AAA--- ----AA----AA---- -----BBBBBB----- -----DBBBBD----- ------DDDD------ ---------------- ---------------- ---------------- 
---------------- ---CBBBBBBBBC--- --BAAA----AAAB-- --AAAA----AAAA-- ---AAA----AAA--- ---AAA----AAA--- ----AA----AA---- -----A----A----- ----G-BBBB-G---- -----DBBBBD----- ---------------- ---------------- ---------------- ---------------- 
---------------- ---CBEBEBBBBC--- ---CB------BC--- --AAB------BAA-- ---AB------BA--- ----AA----AA---- -----A----A----- ----AA----AA---- ----B-BBBB-B---- ------BBBB------ ---------------- ---------------- ---------------- ---------------- 
---------------- ---CBBEBEBBBC--- ---CB------BC--- --AAB------BAA-- ---AB------BA--- ----AA----AA---- -----A----A----- ----AA----AA---- ----BBBBBBBB---- -----BBBBBB----- ------BBBB------ ------DDDD------ ---------------- ---------------- 
---------------- ---CBBBBBEBBC--- ---CB------BC--- --AAB------BAA-- ---AB------BA--- ---AB------BA--- ----AA----AA---- -----A----A----- ----BBBBBBBB---- ----DBBBBBBD---- -----D----D----- ---------------- ---------------- ---------------- 
---------------- ---CBBBBBBBBC--- --BBB------BBB-- --AAAA----AAAA-- --AAAA----AAAA-- ---AAA----AAA--- ---AAA----AAA--- ----AA----AA---- ----AA----AA---- ----GBBBBBBG---- -----BBBBBB----- -----BBBBBB----- ---------------- ---------------- 
-CCCCCCCCCCCCCC- -BBBBBBBBBBBBBB- --BBB------BBB-- --AAAA----AAAA-- --AAAA----AAAA-- --AAAA----AAAA-- --AAAA----AAAA-- ---AAA----AAA--- ----AA----AA---- ---------------- -----BBBBBB----- -----BBBBBB----- -----BBBBBB----- ---------------- 
CCCCCCCCCCCCCCCC -BBBBBCCCCBBBBB- -BBBB------BBBB- -AAAAA----AAAAA- -AAAAA----AAAAA- -AAAAA----AAAAA- -AAAAA----AAAAA- --AAAA----AAAA-- --BAAA----AAAB-- --BBAA----AABB-- ---BBB----BBB--- ---B--------B--- ---------------- ---------------- 
CCCCCCCCCIICCCCC BBBBBCCCCCCBBBBB -BBBB------BBBB- -BAAAA----AAAAB- -BAAAA----AAAAB- -AAAAA----AAAAA- -AAAAA----AAAAA- ----AA----AAA--- --BAAA----AAAB-- --BBAA----AABB-- --BBB------BBB-- --BB--------BB-- ---B--------B--- ---------------- 
CCCCCCCCHHICCCCC BBBBBCCCCCCBBBBB -BBBB------BBBB- -AAAAA----AAAAA- -AAAAA----AAAAA- -AAAAA----AAAAA- -AAAAA----AAAAA- --AAAA----AAAA-- --BAAA----AAAB-- --FBAA----AABF-- --FBB------BBF-- --B----------B-- --B----------B-- ---------------- 
CCCCCCCCHHCCCCCC BBBBBCCCCCCBBBBB -BBBB------BBBB- -AAAAA----AAAAA- -AAAAA----AAAAA- -AAAAA----AAAAA- -AAAAA----AAAAA- --AAAA----AAAA-- --BAAA----AAAB-- --FBAA----AABF-- --FBB------BBF-- --B----------B-- --B----------B-- ---------------- 
CCCCCCCCCCCCCCCC BBBBBCCCCCCBBBBB -BBBB------BBBB- -BAAAA----AAAAB- -AAAAA----AAAAA- -AAAAA----AAAAA- -AAAAA----AAAAA- ----AA----AAA--- --BAAA----AAAB-- --BBAA----AABB-- --BBB------BBB-- --BB--------BB-- ---B--------B--- ---------------- 
CCCCCCCCCCCCCCCC -BBBBBCCCCBBBBB- -BBBBB----BBBBB- -AAAAA----AAAAA- -AAAAA----AAAAA- -AAAAA----AAAAA- -AAAAA----AAAAA- --AAAA----AAAA-- --BBAA----AABB-- --BBBA----ABBB-- --BBBB----BBBB-- ---BBB----BBB--- ----BB----BB---- ---------------- 
-CCCCCCCCCCCCCC- -BBBBBBBBBBBBBB- --BBBBBBBBBBBB-- --AAAAAAAAAAAA-- --AAAAAAAAAAAA-- --AAAAAAAAAAAA-- --AAAAAAAAAAAA-- ---AAAAAAAAAA--- --BBBBAAAAABBB-- --BBBBAAAABBBB-- ---BBBBBBBBBB--- ----BBBBBBBB---- -----BBBBBB----- -------BB------- 
--CCCCCCCCCCCC-- --BBBBBBBBBBBB-- ---BBAAAAAAAB--- ---AAAAAAAAAA--- ---AAAAAAAAAA--- ---AAAAAAAAAA--- ---AAAAAAAAAA--- -------AA-AA---- ---BBBAAAABBB--- ----BBBBBBBB---- -----BBBBBB----- -------BB------- ---------------- -------AA------- 
---CCCCCCCCCC--- ---BBBBBBBBBB--- ----BBBBBBBB---- ----AAAAAAAA---- ----AAAAAAAA---- ----AAAAAAAA---- ----AAAAAAAA---- -----A-AA-A----- -----BBBBBB----- -----BBBBBB----- -------BB------- ---------------- ---------------- ---------------- 
----CCCCCCCC---- ----BBCCCCBB---- ------BCCE------ -----AAAEAA----- -----AAEAAA----- ------AAEA------ -------EA------- ---------------- ---------------- ---------------- ---------------- ---------------- ---------------- ---------------- 
