model
size = 30 23 9, scale = 0.05, origin = -y
material 
  colors = A:#F90 B:#FF3 C:#111 D:#777 E:#EEE F:#AAA G:#555 H:#690
voxels
------------------------------ ------------------------------ ------------------------------ ------------------------------ ------------------------------ ------------------------------ ------------------------------ ------------------------------ -----AABAAABAAAAAAAAAEAEA----- ----AAAABABABAAAAAAAEEEEEA---- -----AAAABAAABAAAAAAAEAAEEA--- ----------------AAAAAEAAAEA--- -----------------AAAAEEEEAAA-- ------------------AAAEAAAEA--- -------------------AAEAAEEA--- -----------------CDAEEEEEAA--- -------------------AAEAEAA---- --------------------AAAAA----- ---------------------AAAA----- ---------------------AAAA----- ---------------------AAAA----- ----------------------AA------ ------------------------------ 
------------------------------ ------------------------------ ------------------------------ -----FF-----------FFF--------- -------F------------F--------- -----FF-------------FF-------- --CCCCCCCCCCCCCCCCCFCCCCC----- ---AAAAAAAAAAAAAAAAAAAAAA----- --AAAAAAAAAAAAAAAAAAAAAAAA---- --AAAAAAAAAAAAAAAAAAAAAAAAA--- ---AAAAAAAAAAAAAAAAAAAAAAAAA-- ----AAAAAAAAAAAAAAAAAAAAAAAA-- ----------------AAAAAAAAAAAAA- -----------------AAAAAAAAAAA-- -----------------AAAAAAAAAA--- ----------------DDAAAAAAAAA--- ------------------AAAAAAAAA--- ------------------AAAAAAAA---- -----------------CDAAAAAAA---- -------------------AAAAAAA---- -------------------AAAAAAA---- -------------------AAAAAAA---- --------------------DDDDD----- 
------------------------------ ------------------------------ --CD----DCD----DCD----DC------ ---DDDDDD-DDDDDD-DDDDDD------- -----DDD----------DDDD-------- -----D-D------------DDD------- -CCCCCCCCCCCCCCCCDDDCCCCCC---- -AAAAAAAAAAAAAAAAADDDAAAAA---- -AAAAAAAAAAAAAAAAAAAAAAAAAA--- -AAAAAAAAAAAAAAAAAAAAAAAAAAA-- --AAAAAAAAAAAAAAAAAAAAAAAAAA-- ---AAAAAAAAAAAAAAAAAAAAAAAAAA- -----AAAAAAAAAAAAAAAAAAAAAAAA- ---------------AAAAAAAAAAAAAA- ---------------AAAAAAAAAAAAA-- ---------------DAAAAAAAAAAAA-- ----------------AAAAAAAAAAA--- -----------------AAAAAAAAAA--- ----------------DAAA-----AA--- -----------------AAA-----AA--- ------------------AA-----AA--- ------------------AA-----AA--- -------------------D-----D---- 
--B------B------B------B------ -BBB----BBB----BBB----BBB---H- BBBBB--BBBBB--BBBBB--BBBBB--H- -BBB----BBB----BBB----BBB---H- --B------B------B------B---CC- ---------------------------CC- C-------------------CCCCCCC--- ACCAAAAAAAAAAAAAAAAAAAAAAAA--- AAAAAAAAAAAAAAAAAAAAAAAAAAAA-- AAAAAAAAAAAAAAAAAAAAAAAAAAAA-- -AAAAAAAAAAAAAAAAAAAAAAAAAAAA- --AAAAAAAAAAAAAAAAAAAAAAAAAAA- ----AAAGAGAGAGAAAAAAAAAAAAAAA- --------------AAAAAAAAAAAAAAA- ---------------GAAAAAAAAAAAAA- --------------DAAAAAAAAAAAAAA- ---------------GAAAAAAAAAAAAA- ----------------AAAAAAAAAAADA- ---------------DAAA-------ADA- ----------------GAA-------ADA- -----------------AA-------AD-- -----------------AA-------AD-- ------------------D-------D--- 
-BBB----BBB----BBB----BBB----- BBBBB--BBBBB--BBBBB--BBBBB--H- BBBBB--BBBBB--BBBBB--BBBBB-HHH BBBBB--BBBBB--BBBBB--BBBBB-HHH -BBB----BBB----BBB----BBB--CCC ---------------------------CCC C-------------------CCCCCCC--- AAAAAAAAAAAAAAAAAAAAAAAAAAA--- AAAAAAAAAAAAAAAAAAAAAAAAAAAA-- AAAAAAAAAAAAAAAAAAAAAAAAAAAAA- -AAAAAAAAAAAAAAAAAAAAAAAAAAAA- --AAAAAAAAAAAAAAAAAAAAAAAAAAA- ----AAAGAGAGAGAAAAAAAAAAAAAAA- --------------AAAAAAAAAAAAAAA- ---------------GAAAAAAAAAAAAA- --------------DAAAAAAAAAAAAAA- ---------------GAAAAAAAAAAAAA- ----------------AAAAAAAAAAADA- ---------------DAAA-------ADA- ----------------GAA-------ADA- -----------------AA-------ADA- -----------------AA-------ADA- ------------------D-------DA-- 
--B------B------B------B------ -BBB----BBB----BBB----BBB---H- BBBBB--BBBBB--BBBBB--BBBBB--H- -BBB----BBB----BBB----BBB---H- --B------B------B------B---CC- ---------------------------CC- C-------------------CCCCCCC--- ACCAAAAAAAAAAAAAAAAAAAAAAAA--- AAAAAAAAAAAAAAAAAAAAAAAAAAAA-- AAAAAAAAAAAAAAAAAAAAAAAAAAAA-- -AAAAAAAAAAAAAAAAAAAAAAAAAAAA- --AAAAAAAAAAAAAAAAAAAAAAAAAAA- ----AAAGAGAGAGAAAAAAAAAAAAAAA- --------------AAAAAAAAAAAAAAA- ---------------GAAAAAAAAAAAAA- --------------DAAAAAAAAAAAAAA- ---------------GAAAAAAAAAAAAA- ----------------AAAAAAAAAAADA- ---------------DAAA-------ADA- ----------------GAA-------ADA- -----------------AA-------AD-- -----------------AA-------AD-- ------------------D-------D--- 
------------------------------ ------------------------------ --CD----DCD----DCD----DC------ ---DDDDDD-DDDDDD-DDDDDD------- -----DDD----------D-DD-------- -----DDD------------DDD------- -CCCCCCCCCCCCCCCCDDDCCCCCC---- -AAAAAAAAAAAAAAAAADDDAAAAA---- -AAAAAAAAAAAAAAAAAAAAAAAAAA--- -AAAAAAAAAAAAAAAAAAAAAAAAAAA-- --AAAAAAAAAAAAAAAAAAAAAAAAAA-- ---AAAAAAAAAAAAAAAAAAAAAAAAAA- -----AAAAAAAAAAAAAAAAAAAAAAAA- ---------------AAAAAAAAAAAAAA- ---------------AAAAAAAAAAAAA-- ---------------DAAAAAAAAAAAA-- ----------------AAAAAAAAAAA--- -----------------AAAAAAAAAA--- ----------------DAAA-----AA--- -----------------AAA-----AA--- ------------------AA-----AA--- ------------------AA-----AA--- -------------------D-----D---- 
------------------------------ ------------------------------ ------------------------------ -----FF-----------FFF--------- -------F------------F--------- -----FF-------------FF-------- --CCCCCCCCCCCCCCCCCFCCCCC----- ---AAAAAAAAAAAAAAAAAAAAAA----- --AAAAAAAAAAAAAAAAAAAAAAAA---- --AAAAAAAAAAAAAAAAAAAAAAAAA--- ---AAAAAAAAAAAAAAAAAAAAAAAAA-- ----AAAAAAAAAAAAAAAAAAAAAAAA-- ----------------AAAAAAAAAAAAA- -----------------AAAAAAAAAAA-- -----------------AAAAAAAAAA--- ----------------DDAAAAAAAAA--- ------------------AAAAAAAAA--- ------------------AAAAAAAA---- -----------------CDAAAAAAA---- -------------------AAAAAAA---- -------------------AAAAAAA---- -------------------AAAAAAA---- --------------------DDDDD----- 
------------------------------ ------------------------------ ------------------------------ ------------------------------ ------------------------------ ------------------------------ ------------------------------ ------------------------------ -----AAAAAAAAAAAAAAAAEAEA----- ----AAAAAAAAAAAAAAAAEEEEEA---- -----AAAAAAAAAAAAAAEEAAEAAA--- ----------------AAAEAAAEAAA--- -----------------AAAEEEEAAAA-- ------------------AEAAAEAAA--- -------------------EEAAEAAA--- -----------------CDAEEEEEAA--- -------------------AAEAEAA---- --------------------AAAAA----- ---------------------AAAA----- ---------------------AAAA----- ---------------------AAAA----- ----------------------AA------ ------------------------------ 
