model
size = 16 14 16, scale = 0.05, origin = -y
material 
  colors = A:#111
voxels
---------------- ---------------- ---------------- ---------------- ------AAAA------ -----AAAAAA----- -----AAAAAA----- -----AAAAAA----- ------AAAA------ ---------------- ---------------- ---------------- ---------------- ---------------- 
---------------- ---------------- -----AAAAAA----- ----AAAAAAAA---- ---AAAAAAAAAA--- ---AAAAAAAAAA--- ---AAAAAAAAAA--- ---AAAAAAAAAA--- ---AAAAAAAAAA--- ----AAAAAAAA---- -----AAAAAA----- ---------------- ---------------- ---------------- 
---------------- -----AAAAAA----- ----AAAAAAAA---- ---AAAAAAAAAA--- --AAAAAAAAAAAA-- --AAAAAAAAAAAA-- --AAAAAAAAAAAA-- --AAAAAAAAAAAA-- --AAAAAAAAAAAA-- ---AAAAAAAAAA--- ----AAAAAAAA---- -----AAAAAA----- ---------------- ---------------- 
-----AAAAAA----- ----AAAAAAAA---- ---AAAAAAAAAA--- --AAAAAAAAAAAA-- -AAAAAAAAAAAAAA- -AAAAAAAAAAAAAA- -AAAAAAAAAAAAAA- -AAAAAAAAAAAAAA- -AAAAAAAAAAAAAA- --AAAAAAAAAAAA-- ---AAAAAAAAAA--- ----AAAAAAAA---- -----AAAAAA----- ---------------- 
----AAAAAAAA---- ---AAAAAAAAAA--- --AAAAAAAAAAAA-- -AAAAAAAAAAAAAA- -AAAAAAAAAAAAAA- -AAAAAAAAAAAAAA- -AAAAAAAAAAAAAA- -AAAAAAAAAAAAAA- -AAAAAAAAAAAAAA- -AAAAAAAAAAAAAA- --AAAAAAAAAAAA-- ---AAAAAAAAAA--- ----AAAAAAAA---- ---------------- 
---AAAAAAAAAA--- --AAAAAAAAAAAA-- -AAAAAAAAAAAAAA- -AAAAAAAAAAAAAA- -AAAAAAAAAAAAAA- AAAAAAAAAAAAAAAA AAAAAAAAAAAAAAAA AAAAAAAAAAAAAAAA -AAAAAAAAAAAAAA- -AAAAAAAAAAAAAA- -AAAAAAAAAAAAAA- --AAAAAAAAAAAA-- ---AAAAAAAAAA--- ------AAAA------ 
---AAAAAAAAAA--- --AAAAAAAAAAAA-- -AAAAAAAAAAAAAA- -AAAAAAAAAAAAAA- AAAAAAAAAAAAAAAA AAAAAAAAAAAAAAAA AAAAAAAAAAAAAAAA AAAAAAAAAAAAAAAA AAAAAAAAAAAAAAAA -AAAAAAAAAAAAAA- -AAAAAAAAAAAAAA- --AAAAAAAAAAAA-- ---AAAAAAAAAA--- -----AAAAAA----- 
---AAAAAAAAAA--- --AAAAAAAAAAAA-- -AAAAAAAAAAAAAA- -AAAAAAAAAAAAAA- AAAAAAAAAAAAAAAA AAAAAAAAAAAAAAAA AAAAAAAAAAAAAAAA AAAAAAAAAAAAAAAA AAAAAAAAAAAAAAAA -AAAAAAAAAAAAAA- -AAAAAAAAAAAAAA- --AAAAAAAAAAAA-- ---AAAAAAAAAA--- -----AAAAAA----- 
---AAAAAAAAAA--- --AAAAAAAAAAAA-- -AAAAAAAAAAAAAA- -AAAAAAAAAAAAAA- AAAAAAAAAAAAAAAA AAAAAAAAAAAAAAAA AAAAAAAAAAAAAAAA AAAAAAAAAAAAAAAA AAAAAAAAAAAAAAAA -AAAAAAAAAAAAAA- -AAAAAAAAAAAAAA- --AAAAAAAAAAAA-- ---AAAAAAAAAA--- -----AAAAAA----- 
---AAAAAAAAAA--- --AAAAAAAAAAAA-- -AAAAAAAAAAAAAA- -AAAAAAAAAAAAAA- AAAAAAAAAAAAAAAA AAAAAAAAAAAAAAAA AAAAAAAAAAAAAAAA AAAAAAAAAAAAAAAA AAAAAAAAAAAAAAAA -AAAAAAAAAAAAAA- -AAAAAAAAAAAAAA- --AAAAAAAAAAAA-- ---AAAAAAAAAA--- -----AAAAAA----- 
---AAAAAAAAAA--- --AAAAAAAAAAAA-- -AAAAAAAAAAAAAA- -AAAAAAAAAAAAAA- -AAAAAAAAAAAAAA- AAAAAAAAAAAAAAAA AAAAAAAAAAAAAAAA AAAAAAAAAAAAAAAA -AAAAAAAAAAAAAA- -AAAAAAAAAAAAAA- -AAAAAAAAAAAAAA- --AAAAAAAAAAAA-- ---AAAAAAAAAA--- ------AAAA------ 
----AAAAAAAA---- ---AAAAAAAAAA--- --AAAAAAAAAAAA-- -AAAAAAAAAAAAAA- -AAAAAAAAAAAAAA- -AAAAAAAAAAAAAA- -AAAAAAAAAAAAAA- -AAAAAAAAAAAAAA- -AAAAAAAAAAAAAA- -AAAAAAAAAAAAAA- --AAAAAAAAAAAA-- ---AAAAAAAAAA--- ----AAAAAAAA---- ---------------- 
-----AAAAAA----- ----AAAAAAAA---- ---AAAAAAAAAA--- --AAAAAAAAAAAA-- -AAAAAAAAAAAAAA- -AAAAAAAAAAAAAA- -AAAAAAAAAAAAAA- -AAAAAAAAAAAAAA- -AAAAAAAAAAAAAA- --AAAAAAAAAAAA-- ---AAAAAAAAAA--- ----AAAAAAAA---- -----AAAAAA----- ---------------- 
---------------- -----AAAAAA----- ----AAAAAAAA---- ---AAAAAAAAAA--- --AAAAAAAAAAAA-- --AAAAAAAAAAAA-- --AAAAAAAAAAAA-- --AAAAAAAAAAAA-- --AAAAAAAAAAAA-- ---AAAAAAAAAA--- ----AAAAAAAA---- -----AAAAAA----- ---------------- ---------------- 
---------------- ---------------- -----AAAAAA----- ----AAAAAAAA---- ---AAAAAAAAAA--- ---AAAAAAAAAA--- ---AAAAAAAAAA--- ---AAAAAAAAAA--- ---AAAAAAAAAA--- ----AAAAAAAA---- -----AAAAAA----- ---------------- ---------------- ---------------- 
---------------- ---------------- ---------------- ---------------- ------AAAA------ -----AAAAAA----- -----AAAAAA----- -----AAAAAA----- ------AAAA------ ---------------- ---------------- ---------------- ---------------- ---------------- 
