model
size = 28 14 29, scale = 0.05, origin = -y
material 
  colors = A:#222 B:#C93 C:#DDD D:#EEE E:#FFF F:#C96
voxels
-----BBB------------BBB----- -----BBB------------BBB----- -----AAA------------AAA----- -----AAA------------AAA----- -----AAA------------AAA----- ---------------------------- ---------------------------- ---------------------------- ---------------------------- ---------------------------- ---------------------------- ---------------------------- ---------------------------- ---------------------------- 
----BBBBB----------BFFBB---- ----BBBBB----------BBBBB---- ----AAAAA----------AAAAA---- ----AAAAA----------AAAAA---- ----AAAAA----------AAAAA---- -----AAA------------AAA----- ---------------------------- ---------------------------- ---------------------------- ---------------------------- ---------------------------- ---------------------------- ---------------------------- ---------------------------- 
---BBBBBBB--------BBFFBBB--- ---BBBBBBB--------BBBBBBB--- ---AAAAAAA--------AAAAAAA--- ---AAAAAAA--------AAAAAAA--- ---AAAAAAA--------AAAAAAA--- ----AAAAA----------AAAAA---- ---------------------------- ---------------------------- ---------------------------- ---------------------------- ---------------------------- ---------------------------- ---------------------------- ---------------------------- 
--BBBBBBBB--------BBFFBBBB-- --BBBBBBBB--------BBBBBBBB-- --AAAAAAAA--------AAAAAAAA-- --AAAAAAAA--------AAAAAAAA-- --AAAAAAAA--------AAAAAAAA-- ---AAAAAA----------AAAAAA--- ---------------------------- ---------------------------- ---------------------------- ---------------------------- ---------------------------- ---------------------------- ---------------------------- ---------------------------- 
--BBBBBBBBB------BBBFFBBBB-- --BBBBBBBBB------BBBBBBBBB-- --AAAAAAAAA------AAAAAAAAA-- --AAAAAAAAA------AAAAAAAAA-- --AAAAAAAAA------AAAAAAAAA-- --AAAAAAAA--------AAAAAAAA-- ---------------------------- ---------------------------- ---------------------------- ---------------------------- ---------------------------- ---------------------------- ---------------------------- ---------------------------- 
-BBBBBBBBBBB----BBBBFFBBBBB- -BBBBBBBBBBB----BBBBBBBBBBB- -AAAAAAAAAAA----AAAAAAAAAAA- -AAAAAAAAAAA----AAAAAAAAAAA- -AAAAAAAAAAA----AAAAAAAAAAA- --AAAAAAAAA------AAAAAAAAA-- ---AAAAAA----------AAAAAA--- ---------------------------- ---------------------------- ---------------------------- ---------------------------- ---------------------------- ---------------------------- ---------------------------- 
-BBBBBBBBBBB----BBBBFFBBBBB- -BBBBBBBBBBB----BBBBBBBBBBB- -AAAAAAAAAAA----AAAAAAAAAAA- -AAAAAAAAAAA----AAAAAAAAAAA- -AAAAAAAAAAA----AAAAAAAAAAA- --AAAAAAAAA------AAAAAAAAA-- ---AAAAAA----------AAAAAA--- ----AAAA------------AAAA---- ---------------------------- ---------------------------- ---------------------------- ---------------------------- ---------------------------- ---------------------------- 
BBBBBBBBBBBB----BBBBBBBBBBBB BBBBBBBBBBBB----BBBBBBBBBBBB AAAAAAAAAAAA----AAAAAAAAAAAA AAAAAAAAAAAA----AAAAAAAAAAAA AAAAAAAAAAAA----AAAAAAAAAAAA -AAAAAAAAAA------AAAAAAAAAA- --AAAAAAA----------AAAAAAA-- ----AAAA------------AAAA---- ---------------------------- ---------------------------- ---------------------------- ---------------------------- ---------------------------- ---------------------------- 
BBBBBBBBBBBB----BBBBBBBBBBBB BBBBBBBBBBBB----BBBBBBBBBBBB ABBBBBBBBBBA----ABBBBBBBBBBA AAAAAAAAAAAA----AAAAAAAAAAAA AAAAAAAAAAAA----AAAAAAAAAAAA -AAAAAAAAAA------AAAAAAAAAA- --AAAAAAA----------AAAAAAA-- ----AAAA------------AAAA---- ---------------------------- ---------------------------- ---------------------------- ---------------------------- ---------------------------- ---------------------------- 
BBBBBBBBBBBB----BBBBBBBBBBBB BBBBBBBBBBBB----BBBBBBBBBBBB ABBBBBBBBBBB----BBBBBBBBBBBA AAAAAAAAAAAA----AAAAAAAAAAAA AAAAAAAAAAAA----AAAAAAAAAAAA -AAAAAAAAAA------AAAAAAAAAA- -AAAAAAAAA--------AAAAAAAAA- ---AADDA------------ADDAA--- ---------------------------- ---------------------------- ---------------------------- ---------------------------- ---------------------------- ---------------------------- 
BBBBBBBBBBBB----BBBBBBBBBBBB BBBBBBBBBBBB----BBBBBBBBBBBB ABBBBBBBBBBB----BBBBBBBBBBBA AAAAAAAAAAAA----AAAAAAAAAAAA AAAAAAAAAAAA----AAAAAAAAAAAA -AAAAAAAAAA------AAAAAAAAAA- -AAAAAAAAA--------AAAAAAAAA- --AAAAAAA----------AAAAAAA-- ---------------------------- ---------------------------- ---------------------------- ---------------------------- ---------------------------- ---------------------------- 
BBBBBBBBBBB------BBBBBBBBBBB BBBBBBBBBBB------BBBBBBBBBBB BBBBBBBBBBB------BBBBBBBBBBB AAAAAAAAAAA------AAAAAAAAAAA AAAAAAAAAAA------AAAAAAAAAAA -AAAAAAAAAA------AAAAAAAAAA- -AAAAAAAAA--------AAAAAAAAA- --AADDDEA----------ADDDDAA-- ---------------------------- ---------------------------- ---------------------------- ---------------------------- ---------------------------- ---------------------------- 
BBBBBBBBBBB------BBBBBBBBBBB BBBBBBBBBBB------BBBBBBBBBBB BBBBBBBBBBB------BBBBBBBBBBB AAAAAAAAAAA------AAAAAAAAAAA AAAAAAAAAAA------AAAAAAAAAAA -AAAAAAAAAA------AAAAAAAAAA- -AAAAAAAAA--------AAAAAAAAA- --AAAAAAA----------AAAAAAA-- ---------------------------- ---------------------------- ---------------------------- ---------------------------- ---------------------------- ---------------------------- 
-BBBBBBBBB--------BBBBBBBBB- -BBBBBBBBB--------BBBBBBBBB- -BBBBBBBBB--------BBBBBBBBB- -AAAAAAAAA--------AAAAAAAAA- -AAAAAAAAA--------AAAAAAAAA- -AAAAAAAAA--------AAAAAAAAA- -AAAAAAAAA--------AAAAAAAAA- --AAAAAAA----------AAAAAAA-- ---DDDDE------------DDDDD--- ---------------------------- ---------------------------- ---------------------------- ---------------------------- ---------------------------- 
-BBBBBBBBB--------BBBBBBBBB- -BBBBBBBBB--------BBBBBBBBB- -BBBBBBBBB--------BBBBBBBBB- -AAAAAAAAA--------AAAAAAAAA- -AAAAAAAAA--------AAAAAAAAA- -AAAAAAAAA--------AAAAAAAAA- -AAAAAAAAA--------AAAAAAAAA- --AAAAAAA----------AAAAAAA-- ---AAAAA------------AAAAA--- ---------------------------- ---------------------------- ---------------------------- ---------------------------- ---------------------------- 
-BBBBBBBBB--------BBBBBBBBB- -BBBBBBBBB--------BBBBBBBBB- -BBBBBBBBB--------BBBBBBBBB- -AAAAAAAAA--------AAAAAAAAA- -AAAAAAAAA--------AAAAAAAAA- -AAAAAAAAA--------AAAAAAAAA- -AAAAAAAAA--------AAAAAAAAA- --AAAAAAA----------AAAAAAA-- ---DDDDD------------DDDDD--- ---------------------------- ---------------------------- ---------------------------- ---------------------------- ---------------------------- 
-BBBBBBBBB--------BBBBBBBBB- -BBBBBBBBB--------BBBBBBBBB- -BBBBBBBBB--------BBBBBBBBB- -AAAAAAAAA--------AAAAAAAAA- -AAAAAAAAA--------AAAAAAAAA- -AAAAAAAAA--------AAAAAAAAA- -AAAAAAAAA--------AAAAAAAAA- --AAAAAAA----------AAAAAAA-- ---AAAAA------------AAAAA--- ---AAAAA------------AAAAA--- ---------------------------- ---------------------------- ---------------------------- ---------------------------- 
-BBBBBBBBB--------BBBBBBBBB- -BBBBBBBBB--------BBBBBBBBB- -BBBBBBBBB--------BBBBBBBBB- -AAAAAAAAA--------AAAAAAAAA- -AAAAAAAAA--------AAAAAAAAA- -AAAAAAAAA--------AAAAAAAAA- -AAAAAAAAA--------AAAAAAAAA- --AAAAAAA----------AAAAAAA-- ---DAAAD------------DAAAD--- ---EDDDE------------EDDDE--- ---------------------------- ---------------------------- ---------------------------- ---------------------------- 
-BBBBBBBBBB------BBBBBBBBBB- -BBBBBBBBBB------BBBBBBBBBB- -BBBBBBBBBB------BBBBBBBBBB- -AAAAAAAAAA------AAAAAAAAAA- -AAAAAAAAAA------AAAAAAAAAA- -AAAAAAAAAA------AAAAAAAAAA- -AAAAAAAAAA------AAAAAAAAAA- --AAAAAAA----------AAAAAAA-- ---AAAAA------------AAAAA--- ---AAAAA------------AAAAA--- ---------------------------- ---------------------------- ---------------------------- ---------------------------- 
-BBBBBBBBBB------BBBBBBBBBB- -BBBBBBBBBB------BBBBBBBBBB- -BBBBBBBBBB------BBBBBBBBBB- -AAAAAAAAAA------AAAAAAAAAA- -AAAAAAAAAA------AAAAAAAAAA- -AAAAAAAAAA------AAAAAAAAAA- -AAAAAAAAAA------AAAAAAAAAA- --AAAAAAAAA------AAAAAAAAA-- --AAAAAAAAA------AAAAAAAAA-- ---AAAAAA----------AAAAAA--- ---------------------------- ---------------------------- ---------------------------- ---------------------------- 
BBBBBBBBBBBB----BBBBBBBBBBBB BBBBBBBBBBBB----BBBBBBBBBBBB BBBBBBBBBBBB----BBBBBBBBBBBB BBBBBBBBBBBB----BBBBBBBBBBBB AAAAAAAAAAAA----AAAAAAAAAAAA AAAAAAAAAAAA----AAAAAAAAAAAA -AAAAAAAAAA------AAAAAAAAAA- -AAAAAAAAAA------AAAAAAAAAA- -AAAAAAAAAA------AAAAAAAAAA- --AAAAAAAA--------AAAAAAAA-- ---AAAAAA----------AAAAAA--- ---AAAAAA----------AAAAAA--- ----AAAA------------AAAA---- ---------------------------- 
BBBBBBBBBBBB----BBBBBBBBBBBB BBBBBBBBBBBB----BBBBBBBBBBBB EBBBBBBBBBBE----EBBBBBBBBBBE BBBBBBBBBBBB----BBBBBBBBBBBB AAAAAAAAAAAA----AAAAAAAAAAAA AAAAAAAAAAAA----AAAAAAAAAAAA -AAAAAAAAAA------AAAAAAAAAA- -AAAAAAAAAA------AAAAAAAAAA- -AAAAAAAAAA------AAAAAAAAAA- --AAAAAAAA--------AAAAAAAA-- ---AAAAAA----------AAAAAA--- ---AAAAAA----------AAAAAA--- ---AAAAAA----------AAAAAA--- ----AAAA------------AAAA---- 
BBBBBBBBBBBB----BBBBBBBBBBBB BBBBBBBBBBBB----BBBBBBBBBBBB EBBBBBBBBBBE----EBBBBBBBBBBE BBBBBBBBBBBB----BBBBBBBBBBBB AAAAAAAAAAAA----AAAAAAAAAAAA AAAAAAAAAAAA----AAAAAAAAAAAA -AAAAAAAAAA------AAAAAAAAAA- -AACCCCCCAA------AACCCCCCAA- -AACCCCCCAA------AACCCCCCAA- --ACCCCCCA--------ACCCCCCA-- ---------------------------- ---------------------------- ---------------------------- ---------------------------- 
BBBBBBBBBBBB----BBBBBBBBBBBB BBBBBBBBBBBB----BBBBBBBBBBBB EBBBBBBBBBBE----EBBBBBBBBBBE BBBBBBBBBBBB----BBBBBBBBBBBB AAAAAAAAAAAA----AAAAAAAAAAAA AAAAAAAAAAAA----AAAAAAAAAAAA -AAAAAAAAAA------AAAAAAAAAA- -AAC----CAA------AAC----CAA- -AAC----CAA------AAC----CAA- --AC----CA--------AC----CA-- ---------------------------- ---------------------------- ---------------------------- ---------------------------- 
BBBBBBBBBBBB----BBBBBBBBBBBB BBBBBBBBBBBB----BBBBBBBBBBBB EBBBBBBBBBBE----EBBBBBBBBBBE BBBBBBBBBBBB----BBBBBBBBBBBB AAAAAAAAAAAA----AAAAAAAAAAAA AAAAAAAAAAAA----AAAAAAAAAAAA -AAAAAAAAAA------AAAAAAAAAA- -AAC----CAA------AAC----CAA- -AAC----CAA------AAC----CAA- --AC----CA--------AC----CA-- ---------------------------- ---------------------------- ---------------------------- ---------------------------- 
BBBBBBBBBBBB----BBBBBBBBBBBB BBBBBBBBBBBB----BBBBBBBBBBBB BBBBBBBBBBBB----BBBBBBBBBBBB BBBBBBBBBBBB----BBBBBBBBBBBB AAAAAAAAAAAA----AAAAAAAAAAAA AAAAAAAAAAAA----AAAAAAAAAAAA -AAAAAAAAAA------AAAAAAAAAA- -AAC----CAA------AAC----CAA- -AAC----CAA------AAC----CAA- --AC----CA--------AC----CA-- ---------------------------- ---------------------------- ---------------------------- ---------------------------- 
-BBBBBBBBBB------BBBBBBBBBB- -BBBBBBBBBB------BBBBBBBBBB- -BBBBBBBBBB------BBBBBBBBBB- -BBBBBBBBBB------BBBBBBBBBB- -AAAAAAAAAA------AAAAAAAAAA- -AAAAAAAAAA------AAAAAAAAAA- -AAAAAAAAA--------AAAAAAAAA- -AACCCCCCA--------ACCCCCCAA- -AACCCCCCA--------ACCCCCCAA- --ACCCCCCA--------ACCCCCCA-- ---------------------------- ---------------------------- ---------------------------- ---------------------------- 
--BBBBBBBB--------BBBBBBBB-- --BBBBBBBB--------BBBBBBBB-- -BBBBBBBBB--------BBBBBBBBB- -BBBBBBBBB--------BBBBBBBBB- -AAAAAAAAA--------AAAAAAAAA- -AAAAAAAAA--------AAAAAAAAA- --AAAAAAA----------AAAAAAA-- --AAAAAAAA--------AAAAAAAA-- --AAAAAAAA--------AAAAAAAA-- ---AAAAAA----------AAAAAA--- ---------------------------- ---------------------------- ---------------------------- ---------------------------- 
---BBBBBB----------BBBBBB--- ---BBBBBB----------BBBBBB--- ---BBBBBB----------BBBBBB--- ---BBBBBB----------BBBBBB--- ---AAAAAA----------AAAAAA--- ---AAAAAA----------AAAAAA--- ---AAAAAA----------AAAAAA--- ---AAAAAA----------AAAAAA--- ---------------------------- ---------------------------- ---------------------------- ---------------------------- ---------------------------- ---------------------------- 
