model
size = 32 29 32, scale = 0.05, origin = -y
material 
  colors = A:#EEE B:#222 C:#E00 D:#111 E:#F0C F:#DDD
voxels
302-4D27-6D25-2(8D24-)5DF2D24-4D2F2D25-6D27-4D604-4C26-8C23-10C21-4C4A4C20-3C6A3C19-3(3C8A3C18-)3C8A3C19-3C6A3C20-4C4A4C21-10C23-8C26-4C445-2A27-8A22-12A19-14A18-14A17-2(16A16-)16A15-18A14-18A15-2(16A16-)16A17-14A18-14A19-12A22-8A27-2A348-6A24-10A20-14A17-16A16-16A15-18A14-18A13-5(20A12-)20A13-18A14-18A15-16A16-16A17-14A20-10A24-6A281-8A22-12A19-14A17-16A15-18A13-20A12-20A11-7(22A10-)22A11-20A12-20A13-18A15-16A17-14A19-12A22-8A216-8A22-12A19-14A16-18A14-18A13-20A11-22A10-22A9-7(24A8-)24A9-22A10-22A11-20A13-18A14-18A16-14A19-12A22-8A153-6A23-12A19-14A16-18A13-20A12-20A11-22A9-2(24A8-)24A7-5(26A6-)26A7-2(24A8-)24A9-22A11-20A12-20A13-18A16-14A19-12A23-6A119-12A19-14A16-18A13-20A11-22A10-22A9-24A8-24A7-3(26A6-)26A5-28A4-28A5-3(26A6-)26A7-24A8-24A9-22A10-22A11-20A13-18A16-14A20-10A26-2A88-A12BA17-2A12B2A15-3A12B3A13-4A12B4A11-5A12B5A9-6A12B6A7-2(7A12B7A6-)7A12B7A5-7(8A12B8A4-)28A5-2(26A6-)26A7-24A9-22A11-20A13-18A15-16A17-14A21-8A84-AB12-BA15-2AB12-B2A13-3AB12-B3A11-4AB12-B4A9-5AB12-B5A7-6AB12-B6A6-6AB12-B6A5-3(7AB12-B7A4-)7AB12-B7A3-3(C7AB12-B7AC2-)C7AB12-B7AC3-7AB12-B7A4-8A12B8A2(4-28A)5-26A6-26A7-24A9-22A11-20A13-18A15-16A18-12A24-4C54-AB12-BA14-3AB12-B3A11-4AB12-B4A9-5AB12-B5A8-5AB12-B5A7-6AB12-B6A5-2(7AB12-B7A4-)7AB12-B7A3-7(C7AB12-B7AC2-)C8A12B8AC3-2(28A4-)28A5-26A7-24A8-24A9-22A11-20A14-16A17-14A21-8C51-2AB12-B2A13-3AB12-B3A11-4AB12-B4A9-5AB12-B5A7-6AB12-B6A6-6AB12-B6A5-7AB12-B7A4-7AB12-B7A3-8(C7AB12-B7AC2-)C8A12B8AC2-C28AC3-28A4-28A5-26A6-26A7-24A9-22A11-20A13-18A16-14A20-10C50-2AB12-B2A12-4AB12-B4A9-5AB12-B5A8-5AB12-B5A7-6AB12-B6A5-7AB12-B7A4-7AB12-B7A3-3(C7AB12-B7AC2-)C7AB12-B7AC-D3(8AB12-B8A2D)8AB12-B8AD-C7AB12-B7AC2-C8A12B8A2(C2-C28A)C3-28A4-28A5-26A7-24A8-24A9-22A12-18A15-16A18-4C4A4C24-4D20-3AB12-B3A11-4AB12-B4A9-5AB12-B5A7-6AB12-B6A6-6AB12-B6A5-7AB12-B7A4-7AB12-B7A3-2(C7AB12-B7AC2-)C7AB12-B7AC-D5(8AB12-B8A2D)8AB12-B8AD-C8A12B8A2(C2-C28A)C3-28A4-28A5-26A6-26A7-24A9-22A11-20A14-16A18-3C6A3C23-6D19-3AB12-B3A11-4AB4-A2-A4-B4A9-5AB4-E2-E4-B5A7-6AB4-E2-E4-B6A6-6AB4-E2-E4-B6A5-7AB4-E2-E4-B7A3-2(C7AB4-E2-E4-B7AC2-)C7AB4-E2-E4-B7AC-D3(8AB4-E2-E4-B8A2D)8A2(B4-E2-E4-B8AD9A)B4-E2-E4-B8A2D8AB4-E2-E4-B8A2D9A4BA2BA4B9AD-2(C28AC2-)C28AC3-28A5-26A6-26A7-24A9-22A11-20A14-16A17-3C8A3C21-4D2F2D18-3AB12-B3A11-4AB5-2A5-B4A9-5AB5-2E5-B5A7-6AB5-2E5-B6A5-7AB5-2E5-B7A4-7AB5-2E5-B7A3-2(C7AB5-2E5-B7AC2-)C7AB5-2E5-B7AC-D4(8AB5-2E5-B8A2D)8AB5-2E5-B8AD9AB5-2E5-B8A2D8AB5-2E5-B8A2D9A5B2A5B9AD-2(C28AC2-)C28AC3-28A4-28A5-26A7-24A9-22A11-20A13-18A16-3C8A3C21-5DF2D18-3AB12-B3A11-4AB5-2A5-B4A9-5AB5-2E5-B5A7-6AB5-2E5-B6A5-7AB5-2E5-B7A4-7AB5-2E5-B7A3-2(C7AB5-2E5-B7AC2-)C7AB5-2E5-B7AC-D5(8AB5-2E5-B8A2D)8AB5-2E5-B8AFD8AB5-2E5-B8A2D9A5B2A5B9AD-2(C28AC2-)C28AC3-28A4-28A5-26A7-24A9-22A11-20A13-18A16-3C8A3C21-8D18-3AB12-B3A11-4AB4-A2-A4-B4A9-5AB4-E2-E4-B5A7-6AB4-E2-E4-B6A6-6AB4-E2-E4-B6A5-7AB4-E2-E4-B7A3-2(C7AB4-E2-E4-B7AC2-)C7AB4-E2-E4-B7AC-D4(8AB4-E2-E4-B8A2D)2(8AB4-E2-E4-B8AFD)8AB4-E2-E4-B8A2D9A4BA2BA4B9AD-2(C28AC2-)C28AC3-28A5-26A6-26A7-24A9-22A11-20A14-16A17-3C8A3C21-8D18-3AB12-B3A11-4AB12-B4A9-5AB12-B5A7-6AB12-B6A6-6AB12-B6A5-7AB12-B7A4-7AB12-B7A3-2(C7AB12-B7AC2-)C7AB12-B7AC-D5(8AB12-B8A2D)8AB12-B8AD-C8A12B8A2(C2-C28A)C3-28A4-28A5-26A6-26A7-24A9-22A11-20A14-16A18-3C6A3C23-6D20-2AB12-B2A12-4AB12-B4A9-5AB12-B5A8-5AB12-B5A7-6AB12-B6A5-7AB12-B7A4-7AB12-B7A3-3(C7AB12-B7AC2-)C7AB12-B7AC-D3(8AB12-B8A2D)8AB12-B8AD-C7AB12-B7AC2-C8A12B8A2(C2-C28A)C3-28A4-28A5-26A7-24A8-24A9-22A12-18A15-16A18-4C4A4C24-4D21-2AB12-B2A13-3AB12-B3A11-4AB12-B4A9-5AB12-B5A7-6AB12-B6A6-6AB12-B6A5-7AB12-B7A4-7AB12-B7A3-8(C7AB12-B7AC2-)C8A12B8AC2-C28AC3-28A4-28A5-26A6-26A7-24A9-22A11-20A13-18A16-14A20-10C51-AB12-BA14-3AB12-B3A11-4AB12-B4A9-5AB12-B5A8-5AB12-B5A7-6AB12-B6A5-2(7AB12-B7A4-)7AB12-B7A3-7(C7AB12-B7AC2-)C8A12B8AC3-2(28A4-)28A5-26A7-24A8-24A9-22A11-20A14-16A17-14A21-8C52-AB12-BA15-2AB12-B2A13-3AB12-B3A11-4AB12-B4A9-5AB12-B5A7-6AB12-B6A6-6AB12-B6A5-3(7AB12-B7A4-)7AB12-B7A3-3(C7AB12-B7AC2-)C7AB12-B7AC3-7AB12-B7A4-8A12B8A2(4-28A)5-26A6-26A7-24A9-22A11-20A13-18A15-16A18-12A24-4C55-A12BA17-2A12B2A15-3A12B3A13-4A12B4A11-5A12B5A9-6A12B6A7-2(7A12B7A6-)7A12B7A5-7(8A12B8A4-)28A5-2(26A6-)26A7-24A9-22A11-20A13-18A15-16A17-14A21-8A86-12A19-14A16-18A13-20A11-22A10-22A9-24A8-24A7-3(26A6-)26A5-28A4-28A5-3(26A6-)26A7-24A8-24A9-22A10-22A11-20A13-18A16-14A20-10A26-2A92-6A23-12A19-14A16-18A13-20A12-20A11-22A9-2(24A8-)24A7-5(26A6-)26A7-2(24A8-)24A9-22A11-20A12-20A13-18A16-14A19-12A23-6A153-8A22-12A19-14A16-18A14-18A13-20A11-22A10-22A9-7(24A8-)24A9-22A10-22A11-20A13-18A14-18A16-14A19-12A22-8A216-8A22-12A19-14A17-16A15-18A13-20A12-20A11-7(22A10-)22A11-20A12-20A13-18A15-16A17-14A19-12A22-8A281-6A24-10A20-14A17-16A16-16A15-18A14-18A13-5(20A12-)20A13-18A14-18A15-16A16-16A17-14A20-10A24-6A348-2A27-8A22-12A19-14A18-14A17-2(16A16-)16A15-18A14-18A15-2(16A16-)16A17-14A18-14A19-12A22-8A27-2A445-4C26-8C23-10C21-4C4A4C20-3C6A3C19-3(3C8A3C18-)3C8A3C19-3C6A3C20-4C4A4C21-10C23-8C26-4C604-4D27-6D25-2(8D24-)2DF5D24-2D2F4D25-6D27-4D398-
