model
size = 32, scale = 0.05, origin = -y
material 
  colors = A:#C0C B:#F0C C:#EEE D:#111 E:#F6F F:#E00
voxels
2(E1056-)E1055-E32-2(E1056-)E1055-3(E1056-)E31-3(E1056-)E1055-2(E1056-)E32-E1055-2(E1056-)E5(31-C)127-8B761-3(C32-)C28-C3-C27-C4-C26-C5-C25-C5-C24-BD5ADB792-C222-BAD4ADB824-C190-B2AD3ADAB855-C158-B3AD2ADAB887-C126-B4ADAD2AB918-C94-B5A2D2AB950-C31-C30-B7D3AB1013-2B5AD2AB1015-2B4AD2AB1016-2B3ADAB1018-2B2ADAB1019-2BADB1021-2BF32-2F
