model
size = 28 28 17, scale = 0.05, origin = -y
material 
  colors = A:#FF9 B:#EBD15F C:#A8A8A8 D:#5E6E86 E:#ADB57B F:#9C9 G:#8F8F8F H:#6B8F6B I:#6E6E6E J:#B33E3E K:#B32121 L:#B36969
voxels
---------------------------- ---------------------------- ---------------------------- ---------------------------- ---------------------------- ---------------------------- ---------------------------- ---------------------------- ---------------------------- ---------------------------- ---------------------------- ---------------------------- -------------------------C-- -------------------------C-- -------------------------C-- ---------------------------- ---------------------------- -------------------------C-- -------------------------C-- -------------------------C-- ---------------------------- ---------------------------- ---------------------------- ---------------------------- ---------------------------- ---------------------------- ---------------------------- ---------------------------- 
---------------------------- ---------------------------- ---------------------------- ---------------------------- ---------------------------- ---------------------------- ------------------------AAE- ------------------------AAE- ------------------------AAE- ------------------------AAE- ------------------------AAE- ------------------------AAE- ------------------------AAE- ------------------------AAE- ------------------------AAE- ------------------------AAE- ------------------------AAE- ------------------------AAE- ------------------------AAE- ------------------------AAE- ------------------------AAE- ------------------------AAE- ---------------------------- ---------------------------- ---------------------------- ---------------------------- ---------------------------- ---------------------------- 
---------------------------- ---------------------------- ---------------------------- ---------------------------- ---------------------------- ------------------------AAE- ------------------------AAE- ------------------------AAD- ------------------------BAD- ------------------------BAD- ------------------------BAD- ------------------------BAD- ------------------------BAD- ------------------------BAD- ------------------------BAD- ------------------------BAD- ------------------------BAD- ------------------------BAD- ------------------------BAD- ------------------------BAD- ------------------------AAD- ------------------------AAE- ------------------------AAE- ---------------------------- ---------------------------- ---------------------------- ---------------------------- ---------------------------- 
---------AABBAABB----------- -------BB--------AAB-------- -----AA-------------BA------ ----B-----------------A----- ---B-------------------BB--- --A---------------------AAE- -A----------------------AAD- -B----------------------BADG AA----------------------CADC AA----------------------CAD- AA----------------------CADG AA----------------------CADC AA----------------------CAD- AA----------------------CADG AA----------------------CADC AA----------------------CAD- AA----------------------CAF- AA----------------------CAF- AA----------------------CAF- AA----------------------CAF- -B----------------------BAF- -A----------------------AAD- --A---------------------AAE- ---B-------------------BB--- ----B-----------------A----- -----AA-------------BA------ -------BB--------AAB-------- ---------AABBAABB----------- 
---------AABBAABB----------- -------BB--------AAB-------- -----AA-------------BA------ ----B-----------------A----- ---B-------------------BB--- --A---------------------AAE- -A----------------------BAD- -B----------------------CADI AA----------------------CADG AB----------------------CAD- AB----------------------CADI AB----------------------CADG AB----------------------CAD- AB----------------------CADI AB----------------------CADG AC----------------------CAD- AB----------------------CAF- AB----------------------CAF- AB----------------------CAF- AA----------------------CAH- -B----------------------CAF- -A----------------------BAD- --A---------------------AAE- ---B-------------------BB--- ----B-----------------A----- -----AA-------------BA------ -------BB--------AAB-------- ---------AABBAABB----------- 
---------AABBAABB----------- -------BB--------AAB-------- -----AA-------------BA------ ----B-----------------A----- ---B-------------------BB--- --A---------------------AAE- -A----------------------BAD- -B----------------------CAD- AA----------------------CAD- AB----------------------CAD- AB----------------------CAD- AB----------------------CAD- AB----------------------CAD- AB----------------------CAD- AB----------------------CAD- AC----------------------CAD- AB----------------------CAF- AB----------------------CAH- AB----------------------CAH- AA----------------------CAH- -B----------------------CAF- -A----------------------BAD- --A---------------------AAE- ---B-------------------BB--- ----B-----------------A----- -----AA-------------BA------ -------BB--------AAB-------- ---------AABBAABB----------- 
---------BBAABBAA----------- -------AA--------BBA-------- -----BB-------------AB------ ----A-----------------B----- ---A-------------------AA--- --B---------------------AAE- -B----------------------BAD- -A----------------------CADG AA----------------------CADC AB----------------------CAD- AB----------------------CADG AB----------------------CADC AB----------------------CAD- AB----------------------CADG AB----------------------CADC AC----------------------CAD- AB----------------------CAF- AB----------------------CAF- AB----------------------CAF- AA----------------------CAF- -A----------------------CAF- -B----------------------BAD- --B---------------------AAE- ---A-------------------AA--- ----A-----------------B----- -----BB-------------AB------ -------AA--------BBA-------- ---------BBAABBAA----------- 
---------AABBAABB----------- -------BB--------AAB-------- -----AA-------------BA------ ----B-----------------A----- ---B-------------------BB--- --A---------------------AAE- -A----------------------BAD- -B----------------------CADI AA----------------------CADG AB----------------------CAD- AB----------------------CADI AB----------------------CADG AB----------------------CAD- AB----------------------CADI AB----------------------CADG AC----------------------CAD- AB----------------------CAF- AB----------------------CAH- AB----------------------CAH- AA----------------------CAH- -B----------------------CAF- -A----------------------BAD- --A---------------------AAE- ---B-------------------BB--- ----B-----------------A----- -----AA-------------BA------ -------BB--------AAB-------- ---------AABBAABB----------- 
---------BBAABBAA----------- -------AA--------BBA-------- -----BB-------------AB------ ----A-----------------B----- ---A-------------------AA--- --B---------------------AAE- -B----------------------BAD- -A----------------------CAD- AA----------------------CAD- AB----------------------CAD- AB----------------------CAD- AB----------------------CAD- AB----------------------CAD- AB----------------------CAD- AB----------------------CAD- AC----------------------CAD- AB----------------------CAF- AB----------------------CAH- AB----------------------CAF- AA----------------------CAH- -A----------------------CAF- -B----------------------BAD- --B---------------------AAE- ---A-------------------AA--- ----A-----------------B----- -----BB-------------AB------ -------AA--------BBA-------- ---------BBAABBAA----------- 
---------AABBAABB----------- -------BB--------AAB-------- -----AA-------------BA------ ----B-----------------A----- ---B-------------------BB--- --A---------------------AAE- -A----------------------BAD- -B----------------------CADG AA----------------------CADC AB----------------------CAD- AB----------------------CADG AB----------------------CADC AB----------------------CAD- AB----------------------CADG AB----------------------CADC AC----------------------CAD- AB----------------------CAF- AB----------------------CAH- AB----------------------CAH- AA----------------------CAH- -B----------------------CAF- -A----------------------BAD- --A---------------------AAE- ---B-------------------BB--- ----B-----------------A----- -----AA-------------BA------ -------BB--------AAB-------- ---------AABBAABB----------- 
---------BBAABBAA----------- -------AA--------BBA-------- -----BB-------------AB------ ----A-----------------B----- ---A-------------------AA--- --B---------------------AAE- -B----------------------BAD- -A----------------------CADI AA----------------------CADG AB----------------------CAD- AB----------------------CADI AB----------------------CADG AB----------------------CAD- AB----------------------CADI AB----------------------CADG AC----------------------CAD- AB----------------------CAF- AB----------------------CAF- AB----------------------CAF- AA----------------------CAF- -A----------------------CAF- -B----------------------BAD- --B---------------------AAE- ---A-------------------AA--- ----A-----------------B----- -----BB-------------AB------ -------AA--------BBA-------- ---------BBAABBAA----------- 
---------AABBAABB----------- -------BB--------AAB-------- -----AA-------------BA------ ----B-----------------A----- ---B-------------------BB--- --A---------------------AAE- -A----------------------BAD- -B----------------------CAD- AA----------------------CAD- AB----------------------CAD- AB----------------------CAD- AB----------------------CAD- AB----------------------CAD- AB----------------------CAD- AB----------------------CAD- AC----------------------CAD- AB----------------------CAF- AB----------------------CAF- AB----------------------CAF- AA----------------------CAH- -B----------------------CAF- -A----------------------BAD- --A---------------------AAE- ---B-------------------BB--- ----B-----------------A----- -----AA-------------BA------ -------BB--------AAB-------- ---------AABBAABB----------- 
---------AABBAABB----------- -------BB--------AAB-------- -----AA-------------BA------ ----B-----------------A----- ---B-------------------BB--- --A---------------------AAE- -A----------------------BAD- -B----------------------CADJ AA----------------------CADL AB----------------------CAD- AB----------------------CADG AB----------------------CADC AB----------------------CAD- AB----------------------CADG AB----------------------CADC AC----------------------CAD- AB----------------------CAF- AB----------------------CAH- AB----------------------CAH- AA----------------------CAH- -B----------------------CAF- -A----------------------BAD- --A---------------------AAE- ---B-------------------BB--- ----B-----------------A----- -----AA-------------BA------ -------BB--------AAB-------- ---------AABBAABB----------- 
---------AABBAABB----------- -------BB--------AAB-------- -----AA-------------BA------ ----B-----------------A----- ---B-------------------BB--- --A---------------------AAE- -A----------------------AAD- -B----------------------BADK AA----------------------CADJ AA----------------------CAD- AA----------------------CADI AA----------------------CADG AA----------------------CAD- AA----------------------CADI AA----------------------CADG AA----------------------CAD- AA----------------------CAF- AA----------------------CAF- AA----------------------CAF- AA----------------------CAF- -B----------------------BAF- -A----------------------AAD- --A---------------------AAE- ---B-------------------BB--- ----B-----------------A----- -----AA-------------BA------ -------BB--------AAB-------- ---------AABBAABB----------- 
---------------------------- ---------------------------- ---------------------------- ---------------------------- ---------------------------- ------------------------AAE- ------------------------AAE- ------------------------AAD- ------------------------BAD- ------------------------BAD- ------------------------BAD- ------------------------BAD- ------------------------BAD- ------------------------BAD- ------------------------BAD- ------------------------BAD- ------------------------BAD- ------------------------BAD- ------------------------BAD- ------------------------BAD- ------------------------AAD- ------------------------AAE- ------------------------AAE- ---------------------------- ---------------------------- ---------------------------- ---------------------------- ---------------------------- 
---------------------------- ---------------------------- ---------------------------- ---------------------------- ---------------------------- ---------------------------- ------------------------AAE- ------------------------AAE- ------------------------AAE- ------------------------AAE- ------------------------AAE- ------------------------AAE- ------------------------AAE- ------------------------AAE- ------------------------AAE- ------------------------AAE- ------------------------AAE- ------------------------AAE- ------------------------AAE- ------------------------AAE- ------------------------AAE- ------------------------AAE- ---------------------------- ---------------------------- ---------------------------- ---------------------------- ---------------------------- ---------------------------- 
---------------------------- ---------------------------- ---------------------------- ---------------------------- ---------------------------- ---------------------------- ---------------------------- ---------------------------- ---------------------------- ---------------------------- ---------------------------- ---------------------------- -------------------------C-- -------------------------C-- -------------------------C-- ---------------------------- ---------------------------- -------------------------C-- -------------------------C-- -------------------------C-- ---------------------------- ---------------------------- ---------------------------- ---------------------------- ---------------------------- ---------------------------- ---------------------------- ---------------------------- 
