model
size = 30 30 32, scale = 0.05, origin = -y
material 
  colors = A:#111 B:#EEE C:#444 D:#DDD E:#555 F:#222 G:#888 H:#777 I:#BBB J:#AAA K:#00B L:#D00 M:#E00 N:#500 O:#F69
voxels
673-F2AF26-4A805-2F2C2F24-AF2CFA3(24-2A2C2A)743-2F4C2F22-F6AF3(22-3A2B3A)23-A-2B-A683-F6CF22-2F4C2F22-F2A2B2AF3(22-8A)22-3A2-3A23-A4-A593-2C4F2C21-CE2C2F2CEC20-F3C2E3C3(F20-F3A2B3A)F2(20-4A2M4A)21-3A2O3A23-A4-A506-2A28-2A24-2C2F2A2F2C19-4C4F4C18-2C3A2B3A2C3(18-F4A2B4AF)2(18-5A2B5A)18-4AL2ML4A19-3AL2OL3A21-2A4-2A23-A4-A501-2C3F2A3F2C18-3C2F2B2F3C17-2C4A2B4A2C16-C5A2B5AC15-FC5A2B5ACF14-2F5A2B5A2F14-AF5A2B5AFA3(14-7A2B7A)14-6AL2NL6A17-3AL2-L3A21-2A4-2A23-A4-A356-2A27-4A24-F6AF21-C2F4A2FC18-E2C3F2A3F2CE16-E12AE15-CE5A2B5AEC14-C6A2B6AC13-2C6A2B6A2C2(12-F7A2B7AF)4(12-8A2B8A)12-7AL2NL7A14-5AL2-L5A19-2A4-2A23-A4-A266-2A27-4A24-F6AF22-F6AF21-2F6A2F19-2C8A2C16-E2CB3A2B3AB2CE14-EGAB3A2B3ABAGE13-EG2AB3A2B3AB2AGE12-C3AB3A2B3AB3AC11-EC3AB3A2B3AB3ACE3(10-F4AB3A2B3AB4AF)4(10-5AB3A2B3AB5A)11-4AB2A4L2AB4A13-3AB2A4L2AB3A16-AB2A4-2ABA21-A4-A236-2A25-F6AF22-F6AF20-CF3A2B3AFC17-CGF3A2B3AFGC15-3CB3A2B3AB3C14-ECAB3A2B3ABACE13-EACAB3A2B3ABACAE12-EACAB3A2B3ABACAE11-2(C2ACAB3A2B3ABAC2AC10-)E2ACAB3A2B3ABAC2AE10-F2ACAB3A2B3ABAC2AF9-F3ACAB3A2B3ABAC3AF2(8-4ACAB3A2B3ABAC4A)7-5ACAB3A2B3ABAC5A7-4ACAB3A2B3ABAC4A9-3ACAB3A2B3ABAC3A11-2ACAB8ABAC2A13-ACAB8ABACA15-CAB3A2-3ABAC18-B2A4-2AB204-2A27-4A25-F4AF22-CF6AFC19-CB3A2B3ABC17-C2(2B3A)2BC15-EH2(2B3A)2BHE14-EH2(2B3A)2BHE13-EAH2(2B3A)2BHAE12-EAH2(2B3A)2BHAE11-CGAH2(2B3A)2BHAGC10-EGAH2(2B3A)2BHAGE10-FGAH2(2B3A)2BHAGF9-2(F2GAH2(2B3A)2BHA2GF8-)A2GAH2(2B3A)2BHA2GA7-2(2A2GAH2(2B3A)2BHA2G2A6-)2A2GAH2(2B3A)2BHA2G2A7-A2GAH2(2B3A)2BHA2GA10-GAH2B8A2BHAG13-AH2B8A2BHA15-H2B8A2BH18-B2A4-2AB203-4A22-2C2FA2BA2F2C17-2C2F6A2F2C15-3CB3A2B3AB3C13-E2C2(2B3A)2B2CE11-CE2C2(2B3A)2B2CEC10-CE2C2(2B3A)2B2CEC9-3E2C2(2B3A)2B2C3E8-2EG2C2(2B3A)2B2CG2E8-CEG2C2(2B3A)2B2CGEC7-3CG2C2(2B3A)2B2CG3C6-E2CG2C2(2B3A)2B2CG2CE5-3FCG2C2(2B3A)2B2CGC3F2(4-2FACG2C2(2B3A)2B2CGCA2F)3-4ACG2C2(2B3A)2B2CGC4A2-4ACG2C2(2B3A)2B2CGC4A3-3ACG2C2(2B3A)2B2CGC3A5-2ACG2C2(2B3A)2B2CGC2A7-ACG2C2(2B3A)2B2CGCA9-CG2C2BAB4ABA2B2CGC12-2C2BAB4ABA2B2C15-C2BAB4ABA2BC18-BAB4ABAB22-B4-B172-HF6AFH19-CB3A2B3ABC17-CDB3A2B3ABDC15-CBDB3A2B3ABDBC13-HCBDB3A2B3ABDBCH11-H2CBDB3A2B3ABDB2CH10-3CBDB3A2B3ABDB3C9-4CBDB3A2B3ABDB4C8-4CBDB3A2B3ABDB4C7-5CBDB3A2B3ABDB5C6-5CBDB3A2B3ABDB5C5-2(FG4CBDB3A2B3ABDB4CGF4-)FG4CBDB3A2B3ABDB4CGF3-FAG4CBDB3A2B3ABDB4CGAF2(2-2AG4CBDB3A2B3ABDB4CG2A)3-AG4CBDB3A2B3ABDB4CGA5-G4CBDB3A2B3ABDB4CG7-4CBDB3A2B3ABDB4C9-3CBDBA2B2I2BABDB3C11-2CBDBA2B2I2BABDB2C14-BDBA2B2I2BABDB17-DBA2B2I2BABD21-2B2I2B171-C2HF4AF2HC17-CD4A2B4ADC15-H2D4A2B4A2DH13-HB2D4A2B4A2DBH11-HCB2D4A2B4A2DBCH9-HGCB2D4A2B4A2DBCGH8-HGCB2D4A2B4A2DBCGH7-2CGCB2D4A2B4A2DBCG2C6-2CGCB2D4A2B4A2DBCG2C5-3CGCB2D4A2B4A2DBCG3C4-3CGCB2D4A2B4A2DBCG3C3-2(FA2CGCB2D4A2B4A2DBCG2CAF2-)FA2CGCB2D4A2B4A2DBCG2CAF-F2A2CGCB2D4A2B4A2DBCG2C2AF3A2CGCB2D4A2B4A2DBCG2C3A-2A2CGCB2D4A2B4A2DBCG2C2A3-A2CGCB2D4A2B4A2DBCG2CA5-2CGCB2D4A2B4A2DBCG2C7-CGCB2D4A2B4A2DBCGC9-GCB2D10A2DBCG11-CB2D10A2DBC13-B2D10A2DB16-D10AD19-2(10A20-)10A22-6A80-2CHF6AFH2C15-H2D4A2B4A2DH13-H3D4A2B4A3DH11-HB3D4A2B4A3DBH9-HDB3D4A2B4A3DBDH8-HDB3D4A2B4A3DBDH7-ECDB3D4A2B4A3DBDCE6-2CDB3D4A2B4A3DBD2C6-ECDB3D4A2B4A3DBDCE5-3CDB3D4A2B4A3DBD3C3-2(FA2CDB3D4A2B4A3DBD2CAF2-)FA2CDB3D4A2B4A3DBD2CAF-FCA2CDB3D4A2B4A3DBD2CACFACA2CDB3D4A2B4A3DBD2CAC2ACA2CDB3D4A2B4A3DBD2CACA-CA2CDB3D4A2B4A3DBD2CAC3-A2CDB3D4A2B4A3DBD2CA5-2CDB3D4A2B4A3DBD2C7-CDB3D4A2B4A3DBDC9-DB3D2AB4AB2A3DBD11-B3D2AB4AB2A3DB13-3D2AB4AB2A3D15-2D2AB4AB2A2D18-2(A2B4A2BA20-)A2B4A2BA21-2B4A2B25-2A52-C2H2F4A2F2HC15-HB5A2B5ABH13-HDB5A2B5ABDH11-HBDB5A2B5ABDBH9-H2BDB5A2B5ABD2BH8-H2BDB5A2B5ABD2BH7-ED2BDB5A2B5ABD2BDE6-CD2BDB5A2B5ABD2BDC5-ECD2BDB5A2B5ABD2BDCE4-2CD2BDB5A2B5ABD2BD2C3-2(FACD2BDB5A2B5ABD2BDCAF2-)FACD2BDB5A2B5ABD2BDCAF-FCACD2BDB5A2B5ABD2BDCACF2(AC)D2BDB5A2B5ABD2BDCAC2ACACD2BDB5A2B5ABD2BD2(CA)-CACD2BDB5A2B5ABD2BDCAC3-ACD2BDB5A2B5ABD2BDCA5-CD2BDB5A2B5ABD2BDC7-D2BDB5A2B5ABD2BD9-2BDB3AJ4AJ3ABD2B11-BDB3AJ4AJ3ABDB13-DB3AJ4AJ3ABD15-B3AJ4AJ3AB17-2(2ABJ4AJB2A18-)2ABJ4AJB2A20-BJ4AJB23-J4AJ26-2A22-3C2F4A2F3C15-HBAI3A2B3AIABH13-HDBAI3A2B3AIABDH11-HBDBAI3A2B3AIABDBH9-H2BDBAI3A2B3AIABD2BH8-H2BDBAI3A2B3AIABD2BH7-H3BDBAI3A2B3AIABD3BH6-C3BDBAI3A2B3AIABD3BC5-EC3BDBAI3A2B3AIABD3BCE4-2C3BDBAI3A2B3AIABD3B2C3-2(F2C3BDBAI3A2B3AIABD3B2CF2-)F2C3BDBAI3A2B3AIABD3B2CF-FH2C3BDBAI3A2B3AIABD3B2CHFAH2C3BDBAI3A2B3AIABD3B2CH2AH2C3BDBAI3A2B3AIABD3B2CHA-H2C3BDBAI3A2B3AIABD3B2CH3-2C3BDBAI3A2B3AIABD3B2C5-C3BDBAI3A2B3AIABD3BC7-3BDBAI3A2B3AIABD3B9-2BDBAIAB4ABAIABD2B11-BDBAIAB4ABAIABDB13-DBAIAB4ABAIABD15-BAIAB4ABAIAB17-2(AI2B4A2BIA18-)AI2B4A2BIA19-I2B4A2BI22-B4AB25-4A21-2CHCF4AFCH2C15-HBAB3A2B3ABABH13-H2BAB3A2B3ABA2BH11-HD2BAB3A2B3ABA2BDH9-HBD2BAB3A2B3ABA2BDBH8-HBD2BAB3A2B3ABA2BDBH7-H2BD2BAB3A2B3ABA2BD2BH6-E2BD2BAB3A2B3ABA2BD2BE5-EC2BD2BAB3A2B3ABA2BD2BCE4-2C2BD2BAB3A2B3ABA2BD2B2C3-2(F2C2BD2BAB3A2B3ABA2BD2B2CF2-)F2C2BD2BAB3A2B3ABA2BD2B2CF-FA2C2BD2BAB3A2B3ABA2BD2B2CAF2A2C2BD2BAB3A2B3ABA2BD2B2C4A2C2BD2BAB3A2B3ABA2BD2B2C2A-A2C2BD2BAB3A2B3ABA2BD2B2CA3-2C2BD2BAB3A2B3ABA2BD2B2C5-C2BD2BAB3A2B3ABA2BD2BC7-2BD2BAB3A2B3ABA2BD2B9-BD2BABA2B2A2BABA2BDB11-D2BABA2B2A2BABA2BD13-2BABA2B2A2BABA2B15-2(BA)2B2A2B2(AB)17-2(ABI2B2A2BIBA18-)ABI2B2A2BIBA19-BI2B2A2BIB22-2B2A2B50-2CHCF4AFCH2C15-HBAB3A2B3ABABH13-H2BAB3A2B3ABA2BH11-E3BAB3A2B3ABA3BE9-HD3BABA6CABA3BDH8-HD3BAB8CBA3BDH7-HBD3BABC2A2B2ACBA3BDBH6-EBD3BAB3A2B3ABA3BDBE5-E2BD3BAB3A2B3ABA3BD2BE4-C2BD3BAB3A2B3ABA3BD2BC3-2(FC2BD3BAB3A2B3ABA3BD2BCF2-)FC2BD3BAB3A2B3ABA3BD2BCF-FAC2BD3BAB3A2B3ABA3BD2BCAF2AC2BD3BAB3A2B3ABA3BD2BC4AC2BD3BAB3A2B3ABA3BD2BC2A-AC2BD3BAB3A2B3ABA3BD2BCA3-C2BD3BAB3A2B3ABA3BD2BC5-2BD3BAB3A2B3ABA3BD2B7-BD3BAB3A2B3ABA3BDB9-D3BABA2B2I2BABA3BD11-3BABA2B2I2BABA3B13-2BABA2B2I2BABA2B15-2(BA)2B2I2B2(AB)17-2(A4B2I4BA18-)A4B2I4BA20-3B2I3B80-EFAF4AFAFE16-2EB4A2B4AB2E13-HBJB4A2B4ABJBH11-E2BJB4A2B4ABJ2BE9-EC2BJB2A6C2ABJ2BCE8-EC2BJBA8CABJ2BCE7-HDC2BJBAC2A2B2ACABJ2BCDH6-CDC2BJB4A2B4ABJ2BCDC5-ECDC2BJB4A2B4ABJ2BCDCE4-2CDC2BJB4A2B4ABJ2BCD2C3-2(F2CDC2BJB4A2B4ABJ2BCD2CF2-)F2CDC2BJB4A2B4ABJ2BCD2CF-FH2CDC2BJB4A2B4ABJ2BCD2CHFAH2CDC2BJB4A2B4ABJ2BCD2CH2AH2CDC2BJB4A2B4ABJ2BCD2CHA-H2CDC2BJB4A2B4ABJ2BCD2CH3-2CDC2BJB4A2B4ABJ2BCD2C5-CDC2BJB4A2B4ABJ2BCDC7-DC2BJB4A2B4ABJ2BCD9-C2BJB2AE4IE2ABJ2BC11-2BJB2AE4IE2ABJ2B13-BJB2AE4IE2ABJB15-JB2AE4IE2ABJ21-4I26-4I142-C-F6AF-C16-2EAC3A2B3ACA2E14-EBAK3A2B3AKABE13-E2BAHC6HCHA2BE11-EC2B12C2BCE9-E2CB14CB2CE7-E8C2A2B2A8CE6-8C3A2B3A8C5-E7CK3A2B3AK7CE4-CE4CBAK3A2B3AKAB4CEC3-F5E2BAK3A2B3AKA2B5EF2-FH4C2BAK3A2B3AKA2B4CHF2-FE4C2BAK3A2B3AKA2B4CEF-2FH4C2BAK3A2B3AKA2B4CH2FACH4C2BAK3A2B3AKA2B4CHC2ACH4C2BAK3A2B3AKA2B4CHCA-CH4C2BAK3A2B3AKA2B4CHC3-H4C2BAK3A2B3AKA2B4CH5-4C2BAK3A2B3AKA2B4C7-3C2BAK3A2B3AKA2B3C9-2C2BAK2(2AI)2AKA2B2C11-C2BAK2(2AI)2AKA2BC13-2BAK2(2AI)2AKA2B15-BAK2(2AI)2AKAB21-I2AI26-I2-I172-2CF6AF2C17-EC4A2B4ACE14-2E2AHC6HCH2A2E12-ECA12CACE10-2E18C2E7-2EA6C2A2B2A6CA2E6-CE6C3A2B3A6CEC5-2E6C4A2B4A6C2E4-CE4C6A2B6A4CEC3-F5EC6A2B6AC5E2(F2-F3EA2C6A2B6A2CA3E)F-2F3EA2C6A2B6A2CA3E2F2A3EA2C6A2B6A2CA3E4A3EA2C6A2B6A2CA3E2A-A3EA2C6A2B6A2CA3EA3-3EA2C6A2B6A2CA3E5-2EA2C6A2B6A2CA2E7-EA2C6A2B6A2CAE9-A2C4A2B2E2B4A2CA11-2C4A2B2E2B4A2C13-C4A2B2E2B4AC15-4A2B2E2B4A258-CH6AHC18-ECHC6HCHCE15-E14CE13-E16CE9-3E6C2A2B2A6C3E6-8C3A2B3A8C5-E7C4A2B4A7CE4-CE4C2(2B4A)2B4CEC3-F5ED2(2B4A)2BD5E2(F2-FEG3ED2(2B4A)2BD3EGE)F-2FAG3ED2(2B4A)2BD3EGA2FAEAG3ED2(2B4A)2BD3EGAE2AEAG3ED2(2B4A)2BD3EGAEA-EAG3ED2(2B4A)2BD3EGAE3-AG3ED2(2B4A)2BD3EGA5-G3ED2(2B4A)2BD3EG7-3ED2(2B4A)2BD3E9-2ED2B2A2B2E2B2A2BD2E11-ED2B2A2B2E2B2A2BDE13-D2B2A2B2E2B2A2BD317-CF6AFC19-C2F6C2FC17-2CF8CF2C14-3C2FC2A2B2AC2F3C11-2C4F3A2B3A4F2C9-C5FB3A2B3AB5FC7-C4F3B3A2B3A3B4FC5-5F4B3A2B3A4B5F3-F-F2CD4B3A2B3A4BD2CF-F2-2FE2CD4B3A2B3A4BD2CE2F2-F2E2CD4B3A2B3A4BD2C2EF3(2-A2E2CD4B3A2B3A4BD2C2EA)3-2E2CD4B3A2B3A4BD2C2E5-E2CD4B3A2B3A4BD2CE7-2CD4B3A2B3A4BD2C9-CD4BA2B2E2BA4BDC11-D4BA2B2E2BA4BD378-6A23-8A22-3A2B3A22-F2A2B2AF21-F3A2B3AF18-3F3A2B3A3F15-3FJ3A2B3AJ3F10-5FDBJ3A2B3AJBD5F6-FCDB2DBJ3A2B3AJB2DBDCF5-2FCDB2DBJ3A2B3AJB2DBDC2F3-2(2AECDB2DBJ3A2B3AJB2DBDCE2A2-)2AECDB2DBJ3A2B3AJB2DBDCE2A3-AECDB2DBJ3A2B3AJB2DBDCEA5-ECDB2DBJ3A2B3AJB2DBDCE7-CDB2DBJ3A2B3AJB2DBDC9-DB2DBJAB4EBAJB2DBD467-6A23-2(8A22-)F6AF21-4A2B4A18-2F4A2B4A2F11-5FC2E3A2B3A2EC5F7-F3EC2E3A2B3A2EC3EF6-3(2A4EC2E3A2B3A2EC4E2A4-)2A4EC2E3A2B3A2EC4E2A5-A4EC2E3A2B3A2EC4EA7-4EC2E3A2B3A2EC4E585-2(8A22-)8A16-3F14A3F10-F2GCEC8ACEC2GF7-A2F3GCEC3A2B3ACEC3G2FA3(4-2AE3GCEC3A2B3ACEC3GE2A)5-AE3GCEC3A2B3ACEC3GEA702-A2-A4-A2-A10-A6F3A-6A-3A6F2(A2-A2E3G2E12A2E3G2E)A2-A2E3G2E5A2B5A2E3G2EA11-4A2B4A737-A14-A7-A6FA14-A6F2(2A2E3G2EA3-6A3-A2E3G2E)A12-6A762-A5F18-5F2AE3GE2A14-2(2AE3GE)2A14-2AE3GEA780-3A24-4A2E3A18-3A2E2A2E3A18-3A2EA811-2A24-2A2-2A24-2A511-
