model
size = 22 25 15, scale = 0.05, origin = -y
material 
  colors = A:#1D2455
voxels
---------------------- ---------------------- ---------------------- ---------------------- ---------------------- ---------------------- ---------------------- ---------------------- ---------------------- ---------------------- ---------------------- ---------------------- ---------------------- ---------------------- ---------------------- ---------------------- ----------AA---------- ----------AA---------- ----------AA---------- ----------AA---------- ---AAAAAAAAAAAAAAAA--- ---AAAAAAAAAAAAAAAA--- ---AAAAAAAAAAAAAAAA--- ---------------------- ---------------------- 
---------------------- ----------AA---------- AAAAAAAAA-AA-AAAAAAAAA AAAAAAAAA-AA-AAAAAAAAA AAAAAAAAA-AA-AAAAAAAAA AAAAAAAAA-AA-AAAAAAAAA ----------AA---------- ----------AA---------- ----------AA---------- -AAAAAAAA-AA-AAAAAAAA- -AAAAAAAA-AA-AAAAAAAA- -AAAAAAAA-AA-AAAAAAAA- -AAAAAAAA-AA-AAAAAAAA- -AAAAAAAA-AA-AAAAAAAA- ----------AA---------- ----------AA---------- --AAAAAAAAAAAAAAAAAA-- --AAAAAAAAAAAAAAAAAA-- --AAAAAAAAAAAAAAAAAA-- --AAAAAAAAAAAAAAAAAA-- ---AAAAAAAAAAAAAAAA--- ---AAAAAAAAAAAAAAAA--- ---AAAAAAAAAAAAAAAA--- ----AAAAAAAAAAAAAA---- ----AAAAAAAAAAAAAA---- 
-AAAAAAAAA--AAAAAAAAA- -AAAAAAAAAAAAAAAAAAAA- AAAAAAAAAAAAAAAAAAAAAA AAAAAAAAAAAAAAAAAAAAAA AAAAAAAAAAAAAAAAAAAAAA AAAAAAAAAAAAAAAAAAAAAA -AAAAAAAAAAAAAAAAAAAA- -AAAAAAAAAAAAAAAAAAAA- AAAAAAAAAAAAAAAAAAAAAA AAAAAAAAAAAAAAAAAAAAAA -AAAAAAAAAAAAAAAAAAAA- -AAAAAAAAAAAAAAAAAAAA- -AAAAAAAAAAAAAAAAAAAA- -AAAAAAAAAAAAAAAAAAAA- -AAAAAAAAAAAAAAAAAAAA- -AAAAAAAAAAAAAAAAAAAA- --AAAAAAAAAAAAAAAAAA-- --AAAAAAAAAAAAAAAAAA-- --AAAAAAAAAAAAAAAAAA-- --AAAAAAAAAAAAAAAAAA-- ---AAAAAAAAAAAAAAAA--- ---AAAAAAAAAAAAAAAA--- ---AAAAAAAAAAAAAAAA--- ----AAAAAAAAAAAAAA---- ----AAAAAAAAAAAAAA---- 
-AAAAAAAAA--AAAAAAAAA- -AAAAAAAAAAAAAAAAAAAA- AAAAAAAAAAAAAAAAAAAAAA AAAAAAAAAAAAAAAAAAAAAA AAAAAAAAAAAAAAAAAAAAAA AAAAAAAAAAAAAAAAAAAAAA -AAAAAAAAAAAAAAAAAAAA- -AAAAAAAAAAAAAAAAAAAA- AAAAAAAAAAAAAAAAAAAAAA AAAAAAAAAAAAAAAAAAAAAA -AAAAAAAAAAAAAAAAAAAA- -AAAAAAAAAAAAAAAAAAAA- -AAAAAAAAAAAAAAAAAAAA- -AAAAAAAAAAAAAAAAAAAA- -AAAAAAAAAAAAAAAAAAAA- -AAAAAAAAAAAAAAAAAAAA- --AAAAAAAAAAAAAAAAAA-- --AAAAAAAAAAAAAAAAAA-- --AAAAAAAAAAAAAAAAAA-- --AAAAAAAAAAAAAAAAAA-- ---AAAAAAAAAAAAAAAA--- ---AAAAAAAAAAAAAAAA--- ---AAAAAAAAAAAAAAAA--- ----AAAAAAAAAAAAAA---- ----AAAAAAAAAAAAAA---- 
-AAAAAAAAA--AAAAAAAAA- -AAAAAAAAAAAAAAAAAAAA- AAAAAAAAAAAAAAAAAAAAAA AAAAAAAAAAAAAAAAAAAAAA AAAAAAAAAAAAAAAAAAAAAA AAAAAAAAAAAAAAAAAAAAAA -AAAAAAAAAAAAAAAAAAAA- -AAAAAAAAAAAAAAAAAAAA- AAAAAAAAAAAAAAAAAAAAAA AAAAAAAAAAAAAAAAAAAAAA -AAAAAAAAAAAAAAAAAAAA- -AAAAAAAAAAAAAAAAAAAA- -AAAAAAAAAAAAAAAAAAAA- -AAAAAAAAAAAAAAAAAAAA- -AAAAAAAAAAAAAAAAAAAA- -AAAAAAAAAAAAAAAAAAAA- --AAAAAAAAAAAAAAAAAA-- --AAAAAAAAAAAAAAAAAA-- --AAAAAAAAAAAAAAAAAA-- --AAAAAAAAAAAAAAAAAA-- ---AAAAAAAAAAAAAAAA--- ---AAAAAAAAAAAAAAAA--- ---AAAAAAAAAAAAAAAA--- ----AAAAAAAAAAAAAA---- ----AAAAAAAAAAAAAA---- 
-AAAAAAAAA--AAAAAAAAA- -AAAAAAAAAAAAAAAAAAAA- AAAAAAAAAAAAAAAAAAAAAA AAAAAAAAAAAAAAAAAAAAAA AAAAAAAAAAAAAAAAAAAAAA AAAAAAAAAAAAAAAAAAAAAA -AAAAAAAAAAAAAAAAAAAA- -AAAAAAAAAAAAAAAAAAAA- AAAAAAAAAAAAAAAAAAAAAA AAAAAAAAAAAAAAAAAAAAAA -AAAAAAAAAAAAAAAAAAAA- -AAAAAAAAAAAAAAAAAAAA- -AAAAAAAAAAAAAAAAAAAA- -AAAAAAAAAAAAAAAAAAAA- -AAAAAAAAAAAAAAAAAAAA- -AAAAAAAAAAAAAAAAAAAA- --AAAAAAAAAAAAAAAAAA-- --AAAAAAAAAAAAAAAAAA-- --AAAAAAAAAAAAAAAAAA-- --AAAAAAAAAAAAAAAAAA-- ---AAAAAAAAAAAAAAAA--- ---AAAAAAAAAAAAAAAA--- ---AAAAAAAAAAAAAAAA--- ----AAAAAAAAAAAAAA---- ----AAAAAAAAAAAAAA---- 
-AAAAAAAAA--AAAAAAAAA- -AAAAAAAAAAAAAAAAAAAA- AAAAAAAAAAAAAAAAAAAAAA AAAAAAAAAAAAAAAAAAAAAA AAAAAAAAAAAAAAAAAAAAAA AAAAAAAAAAAAAAAAAAAAAA -AAAAAAAAAAAAAAAAAAAA- -AAAAAAAAAAAAAAAAAAAA- AAAAAAAAAAAAAAAAAAAAAA AAAAAAAAAAAAAAAAAAAAAA -AAAAAAAAAAAAAAAAAAAA- -AAAAAAAAAAAAAAAAAAAA- -AAAAAAAAAAAAAAAAAAAA- -AAAAAAAAAAAAAAAAAAAA- -AAAAAAAAAAAAAAAAAAAA- -AAAAAAAAAAAAAAAAAAAA- --AAAAAAAAAAAAAAAAAA-- --AAAAAAAAAAAAAAAAAA-- --AAAAAAAAAAAAAAAAAA-- --AAAAAAAAAAAAAAAAAA-- ---AAAAAAAAAAAAAAAA--- ---AAAAAAAAAAAAAAAA--- ---AAAAAAAAAAAAAAAA--- ----AAAAAAAAAAAAAA---- ----AAAAAAAAAAAAAA---- 
-AAAAAAAAA--AAAAAAAAA- -AAAAAAAAAAAAAAAAAAAA- AAAAAAAAAAAAAAAAAAAAAA AAAAAAAAAAAAAAAAAAAAAA AAAAAAAAAAAAAAAAAAAAAA AAAAAAAAAAAAAAAAAAAAAA -AAAAAAAAAAAAAAAAAAAA- -AAAAAAAAAAAAAAAAAAAA- AAAAAAAAAAAAAAAAAAAAAA AAAAAAAAAAAAAAAAAAAAAA -AAAAAAAAAAAAAAAAAAAA- -AAAAAAAAAAAAAAAAAAAA- -AAAAAAAAAAAAAAAAAAAA- -AAAAAAAAAAAAAAAAAAAA- -AAAAAAAAAAAAAAAAAAAA- -AAAAAAAAAAAAAAAAAAAA- --AAAAAAAAAAAAAAAAAA-- --AAAAAAAAAAAAAAAAAA-- --AAAAAAAAAAAAAAAAAA-- --AAAAAAAAAAAAAAAAAA-- ---AAAAAAAAAAAAAAAA--- ---AAAAAAAAAAAAAAAA--- ---AAAAAAAAAAAAAAAA--- ----AAAAAAAAAAAAAA---- ----AAAAAAAAAAAAAA---- 
-AAAAAAAAA--AAAAAAAAA- -AAAAAAAAAAAAAAAAAAAA- AAAAAAAAAAAAAAAAAAAAAA AAAAAAAAAAAAAAAAAAAAAA AAAAAAAAAAAAAAAAAAAAAA AAAAAAAAAAAAAAAAAAAAAA -AAAAAAAAAAAAAAAAAAAA- -AAAAAAAAAAAAAAAAAAAA- AAAAAAAAAAAAAAAAAAAAAA AAAAAAAAAAAAAAAAAAAAAA -AAAAAAAAAAAAAAAAAAAA- -AAAAAAAAAAAAAAAAAAAA- -AAAAAAAAAAAAAAAAAAAA- -AAAAAAAAAAAAAAAAAAAA- -AAAAAAAAAAAAAAAAAAAA- -AAAAAAAAAAAAAAAAAAAA- --AAAAAAAAAAAAAAAAAA-- --AAAAAAAAAAAAAAAAAA-- --AAAAAAAAAAAAAAAAAA-- --AAAAAAAAAAAAAAAAAA-- ---AAAAAAAAAAAAAAAA--- ---AAAAAAAAAAAAAAAA--- ---AAAAAAAAAAAAAAAA--- ----AAAAAAAAAAAAAA---- ----AAAAAAAAAAAAAA---- 
-AAAAAAAAA--AAAAAAAAA- -AAAAAAAAAAAAAAAAAAAA- AAAAAAAAAAAAAAAAAAAAAA AAAAAAAAAAAAAAAAAAAAAA AAAAAAAAAAAAAAAAAAAAAA AAAAAAAAAAAAAAAAAAAAAA -AAAAAAAAAAAAAAAAAAAA- -AAAAAAAAAAAAAAAAAAAA- AAAAAAAAAAAAAAAAAAAAAA AAAAAAAAAAAAAAAAAAAAAA -AAAAAAAAAAAAAAAAAAAA- -AAAAAAAAAAAAAAAAAAAA- -AAAAAAAAAAAAAAAAAAAA- -AAAAAAAAAAAAAAAAAAAA- -AAAAAAAAAAAAAAAAAAAA- -AAAAAAAAAAAAAAAAAAAA- --AAAAAAAAAAAAAAAAAA-- --AAAAAAAAAAAAAAAAAA-- --AAAAAAAAAAAAAAAAAA-- --AAAAAAAAAAAAAAAAAA-- ---AAAAAAAAAAAAAAAA--- ---AAAAAAAAAAAAAAAA--- ---AAAAAAAAAAAAAAAA--- ----AAAAAAAAAAAAAA---- ----AAAAAAAAAAAAAA---- 
-AAAAAAAAA--AAAAAAAAA- -AAAAAAAAAAAAAAAAAAAA- AAAAAAAAAAAAAAAAAAAAAA AAAAAAAAAAAAAAAAAAAAAA AAAAAAAAAAAAAAAAAAAAAA AAAAAAAAAAAAAAAAAAAAAA -AAAAAAAAAAAAAAAAAAAA- -AAAAAAAAAAAAAAAAAAAA- AAAAAAAAAAAAAAAAAAAAAA AAAAAAAAAAAAAAAAAAAAAA -AAAAAAAAAAAAAAAAAAAA- -AAAAAAAAAAAAAAAAAAAA- -AAAAAAAAAAAAAAAAAAAA- -AAAAAAAAAAAAAAAAAAAA- -AAAAAAAAAAAAAAAAAAAA- -AAAAAAAAAAAAAAAAAAAA- --AAAAAAAAAAAAAAAAAA-- --AAAAAAAAAAAAAAAAAA-- --AAAAAAAAAAAAAAAAAA-- --AAAAAAAAAAAAAAAAAA-- ---AAAAAAAAAAAAAAAA--- ---AAAAAAAAAAAAAAAA--- ---AAAAAAAAAAAAAAAA--- ----AAAAAAAAAAAAAA---- -----AAAAAAAAAAAA----- 
-AAAAAAAAA--AAAAAAAAA- -AAAAAAAAAAAAAAAAAAAA- AAAAAAAAAAAAAAAAAAAAAA AAAAAAAAAAAAAAAAAAAAAA AAAAAAAAAAAAAAAAAAAAAA AAAAAAAAAAAAAAAAAAAAAA -AAAAAAAAAAAAAAAAAAAA- -AAAAAAAAAAAAAAAAAAAA- AAAAAAAAAAAAAAAAAAAAAA AAAAAAAAAAAAAAAAAAAAAA -AAAAAAAAAAAAAAAAAAAA- -AAAAAAAAAAAAAAAAAAAA- -AAAAAAAAAAAAAAAAAAAA- -AAAAAAAAAAAAAAAAAAAA- -AAAAAAAAAAAAAAAAAAAA- -AAAAAAAAAAAAAAAAAAAA- --AAAAAAAAAAAAAAAAAA-- --AAAAAAAAAAAAAAAAAA-- --AAAAAAAAAAAAAAAAAA-- ---AAAAAAAAAAAAAAAA--- ---AAAAAAAAAAAAAAAA--- ---AAAAAAAAAAAAAAAA--- ----AAAAAAAAAAAAAA---- -----AAAAAAAAAAAA----- ------AAAAAAAAAA------ 
-AAAAAAAAA--AAAAAAAAA- -AAAAAAAAAAAAAAAAAAAA- AAAAAAAAAAAAAAAAAAAAAA AAAAAAAAAAAAAAAAAAAAAA AAAAAAAAAAAAAAAAAAAAAA AAAAAAAAAAAAAAAAAAAAAA -AAAAAAAAAAAAAAAAAAAA- -AAAAAAAAAAAAAAAAAAAA- AAAAAAAAAAAAAAAAAAAAAA AAAAAAAAAAAAAAAAAAAAAA -AAAAAAAAAAAAAAAAAAAA- -AAAAAAAAAAAAAAAAAAAA- -AAAAAAAAAAAAAAAAAAAA- -AAAAAAAAAAAAAAAAAAAA- -AAAAAAAAAAAAAAAAAAAA- --AAAAAAAAAAAAAAAAAA-- ---AAAAAAAAAAAAAAAA--- ---AAAAAAAAAAAAAAAA--- ---AAAAAAAAAAAAAAAA--- ---AAAAAAAAAAAAAAAA--- ----AAAAAAAAAAAAAA---- ----AAAAAAAAAAAAAA---- -----AAAAAAAAAAAA----- -------AAAAAAAA------- --------AAAAAA-------- 
---------------------- ---------------------- ---------------------- ---------------------- ---------------------- ---------------------- ---------------------- -AAAAAAAAAAAAAAAAAAAA- AAAAAAAAAAAAAAAAAAAAAA AAAAAAAAAAAAAAAAAAAAAA -AAAAAAAAAAAAAAAAAAAA- -AAAAAAAAAAAAAAAAAAAA- -AAAAAAAAAAAAAAAAAAAA- --AAAAAAAAAAAAAAAAAA-- --AAAAAAAAAAAAAAAAAA-- ---AAAAAAAAAAAAAAAA--- ---AAAAAAAAAAAAAAAA--- ---AAAAAAAAAAAAAAAA--- ----AAAAAAAAAAAAAA---- ----AAAAAAAAAAAAAA---- ----AAAAAAAAAAAAAA---- -----AAAAAAAAAAAA----- ---------------------- ---------------------- ---------------------- 
---------------------- ---------------------- ---------------------- ---------------------- ---------------------- ---------------------- ---------------------- ---------------------- ---------------------- ---------------------- -AAAAAAAAAAAAAAAAAAAA- -AAAAAAAAAAAAAAAAAAAA- -AAAAAAAAAAAAAAAAAAAA- --AAAAAAAAAAAAAAAAAA-- ---AAAAAAAAAAAAAAAA--- ---AAAAAAAAAAAAAAAA--- ---------------------- ---------------------- ---------------------- ---------------------- ---------------------- ---------------------- ---------------------- ---------------------- ---------------------- 
