model
size = 11 16 13, scale = 0.05, origin = -y
material 
  colors = A:#1D2455
voxels
----AAAAAAA ---AAAAA--A --AAAA----A -AAAA-----A ----------- ----------- ----------- ----------- ----------- ----------- ------AAAAA ------AAAAA ----AAAAAAA ----------- ----------- ----------- 
--AAAAAAAAA -AAAAAAAAAA AAAAAAAAAAA AAAAA----AA -AAA------- AA--------- ----------- ----------- ---------A- -----AAAAA- A----AAAAAA AA-AAAAAAAA A-AAAAAAAAA --AAAA----- --A-------- ----------- 
-AAAAAAAAAA AAAAAAAAAAA AAAAAAAAAAA AAAAAAAAAAA AAAAAAAAAA- AAAAAAAAAA- AAAAAAAAA-- AAAAAAAAA-- -AAAAAAAAA- -AAAAAAAAA- AAAAAAAAAAA AAAAAAAAAAA AAAAAAAAAAA -AAAAAAAAA- -AAAAAAAAA- AAAAAAAAA-- 
AAAAAAAAAAA AAAAAAAAAAA AAAAAAAAAAA AAAAAAAAAAA AAAAAAAAAA- AAAAAAAAAA- AAAAAAAAA-- AAAAAAAAA-- -AAAAAAAAA- -AAAAAAAAA- AAAAAAAAAAA AAAAAAAAAAA AAAAAAAAAAA -AAAAAAAAA- -AAAAAAAAA- AAAAAAAAA-- 
AAAAAAAAAAA AAAAAAAAAAA AAAAAAAAAAA AAAAAAAAAAA AAAAAAAAAA- AAAAAAAAAA- AAAAAAAAA-- AAAAAAAAA-- -AAAAAAAAA- -AAAAAAAAA- AAAAAAAAAAA AAAAAAAAAAA AAAAAAAAAAA -AAAAAAAAA- -AAAAAAAAA- AAAAAAAAA-- 
AAAAAAAAAAA AAAAAAAAAAA AAAAAAAAAAA AAAAAAAAAAA AAAAAAAAAA- AAAAAAAAAA- AAAAAAAAA-- AAAAAAAAA-- -AAAAAAAAA- -AAAAAAAAA- AAAAAAAAAAA AAAAAAAAAAA AAAAAAAAAAA -AAAAAAAAA- -AAAAAAAAA- AAAAAAAAA-- 
AAAAAAAAAAA AAAAAAAAAAA AAAAAAAAAAA AAAAAAAAAAA AAAAAAAAAA- AAAAAAAAAA- AAAAAAAAA-- AAAAAAAAA-- -AAAAAAAAA- -AAAAAAAAA- AAAAAAAAAAA AAAAAAAAAAA AAAAAAAAAAA -AAAAAAAAA- -AAAAAAAAA- AAAAAAAAA-- 
AAAAAAAAAAA AAAAAAAAAAA AAAAAAAAAAA AAAAAAAAAAA AAAAAAAAAA- AAAAAAAAAA- AAAAAAAAA-- AAAAAAAAA-- -AAAAAAAAA- -AAAAAAAAA- AAAAAAAAAAA AAAAAAAAAAA AAAAAAAAAAA -AAAAAAAAA- -AAAAAAAAA- AAAAAAAAA-- 
AAAAAAAAAAA AAAAAAAAAAA AAAAAAAAAAA AAAAAAAAAAA AAAAAAAAAA- AAAAAAAAAA- AAAAAAAAA-- AAAAAAAAA-- -AAAAAAAAA- -AAAAAAAAA- AAAAAAAAAAA AAAAAAAAAAA AAAAAAAAAAA -AAAAAAAAA- -AAAAAAAAA- AAAAAAAAA-- 
AAAAAAAAAAA AAAAAAAAAAA AAAAAAAAAAA AAAAAAAAAAA AAAAAAAAAA- AAAAAAAAAA- AAAAAAAAA-- AAAAAAAAA-- -AAAAAAAAA- -AAAAAAAAA- AAAAAAAAAAA AAAAAAAAAAA AAAAAAAAAAA -AAAAAAAAA- -AAAAAAAAA- AAAAAAAAA-- 
AAAAAAAAAAA AAAAAAAAAAA AAAAAAAAAAA AAAAAAAAAAA AAAAAAAAAA- AAAAAAAAAA- AAAAAAAAA-- AAAAAAAAA-- -AAAAAAAAA- -AAAAAAAAA- AAAAAAAAAAA AAAAAAAAAAA AAAAAAAAAAA -AAAAAAAAA- -AAAAAAAAA- AAAAAAAAA-- 
AAAAAAAAAAA AAAAAAAAAAA AAAAAAAAAAA AAAAAAAAAAA AAAAAAAAAA- AAAAAAAAAA- AAAAAAAAA-- AAAAAAAAA-- -AAAAAAAAA- -AAAAAAAAA- AAAAAAAAAAA AAAAAAAAAAA AAAAAAAAAAA -AAAAAAAAA- -AAAAAAAAA- AAAAAAAAA-- 
AAAAAAAAAAA AAAAAAAAAAA AAAAAAAAAAA AAAAAAAAAAA AAAAAAAAAA- AAAAAAAAAA- AAAAAAAAA-- AAAAAAAAA-- -AAAAAAAAA- -AAAAAAAAA- AAAAAAAAAAA AAAAAAAAAAA AAAAAAAAAAA -AAAAAAAAA- -AAAAAAAAA- AAAAAAAAA-- 
