model
size = 18 12 18, scale = 0.05, origin = -y
material 
  colors = A:#005 B:#004 C:#00B
voxels
-----BBBBBBBB----- ------------------ ------------------ ------------------ ------------------ ------------------ ------------------ ------------------ ------------------ ------------------ ------------------ ------------------ 
----BBBBBBBBBB---- ------------------ ------------------ ------------------ ------------------ ------------------ ------------------ ------------------ ------------------ ------------------ ------------------ ------------------ 
---BBBBBBBBBBBB--- ------AAAAAA------ ------AAAAAA------ ------AAAAAA------ ------AAAAAA------ ------CCCCCC------ ------AAAAAA------ ------AAAAAA------ ------AAAAAA------ ------AAAAAA------ ------CCCCCC------ ------------------ 
--BBBB------BBBB-- ----AA------AA---- ----AA------AA---- ----AA------AA---- ----AA------AA---- ----CC------CC---- ----AA------AA---- ----AA------AA---- ----AA------AA---- ----AA------AA---- ----CC------CC---- ------AAAAAA------ 
-BBB----------BBB- ---A----------A--- ---A----------A--- ---A----------A--- ---A----------A--- ---C----------C--- ---A----------A--- ---A----------A--- ---A----------A--- ---A----------A--- ---C----------C--- ----AAAAAAAAAA---- 
BBBB----------BBBB ---A----------A--- ---A----------A--- ---A----------A--- ---A----------A--- ---C----------C--- ---A----------A--- ---A----------A--- ---A----------A--- ---A----------A--- ---C----------C--- ----AAAAAAAAAA---- 
BBB------------BBB --A------------A-- --A------------A-- --A------------A-- --A------------A-- --C------------C-- --A------------A-- --A------------A-- --A------------A-- --A------------A-- --C------------C-- ---AAAAAAAAAAAA--- 
BBB------------BBB --A------------A-- --A------------A-- --A------------A-- --A------------A-- --C------------C-- --A------------A-- --A------------A-- --A------------A-- --A------------A-- --C------------C-- ---AAAAAAAAAAAA--- 
BBB------------BBB --A------------A-- --A------------A-- --A------------A-- --A------------A-- --C------------C-- --A------------A-- --A------------A-- --A------------A-- --A------------A-- --C------------C-- ---AAAAAAAAAAAA--- 
BBB------------BBB --A------------A-- --A------------A-- --A------------A-- --A------------A-- --C------------C-- --A------------A-- --A------------A-- --A------------A-- --A------------A-- --C------------C-- ---AAAAAAAAAAAA--- 
BBB------------BBB --A------------A-- --A------------A-- --A------------A-- --A------------A-- --C------------C-- --A------------A-- --A------------A-- --A------------A-- --A------------A-- --C------------C-- ---AAAAAAAAAAAA--- 
BBB------------BBB --A------------A-- --A------------A-- --A------------A-- --A------------A-- --C------------C-- --A------------A-- --A------------A-- --A------------A-- --A------------A-- --C------------C-- ---AAAAAAAAAAAA--- 
BBBB----------BBBB ---A----------A--- ---A----------A--- ---A----------A--- ---A----------A--- ---C----------C--- ---A----------A--- ---A----------A--- ---A----------A--- ---A----------A--- ---C----------C--- ----AAAAAAAAAA---- 
-BBB----------BBB- ---A----------A--- ---A----------A--- ---A----------A--- ---A----------A--- ---C----------C--- ---A----------A--- ---A----------A--- ---A----------A--- ---A----------A--- ---C----------C--- ----AAAAAAAAAA---- 
--BBBB------BBBB-- ----AA------AA---- ----AA------AA---- ----AA------AA---- ----AA------AA---- ----CC------CC---- ----AA------AA---- ----AA------AA---- ----AA------AA---- ----AA------AA---- ----CC------CC---- ------AAAAAA------ 
---BBBBBBBBBBBB--- ------AAAAAA------ ------AAAAAA------ ------AAAAAA------ ------AAAAAA------ ------CCCCCC------ ------AAAAAA------ ------AAAAAA------ ------AAAAAA------ ------AAAAAA------ ------CCCCCC------ ------------------ 
----BBBBBBBBBB---- ------------------ ------------------ ------------------ ------------------ ------------------ ------------------ ------------------ ------------------ ------------------ ------------------ ------------------ 
-----BBBBBBBB----- ------------------ ------------------ ------------------ ------------------ ------------------ ------------------ ------------------ ------------------ ------------------ ------------------ ------------------ 
