model
size = 20 17 20, scale = 0.05, origin = -y
material 
  colors = A:#700 B:#D00
voxels
------BBBBBBB------- -------------------- -------------------- -------------------- -------------------- -------------------- -------------------- -------------------- -------------------- -------------------- -------------------- -------------------- -------------------- -------------------- -------------------- -------------------- -------------------- 
-----BBBBBBBBBB----- -------------------- -------------------- -------------------- -------------------- -------------------- -------------------- -------------------- -------------------- -------------------- -------------------- -------------------- -------------------- -------------------- -------------------- -------------------- -------------------- 
----BBBBBBBBBBBB---- -------------------- -------------------- -------------------- -------------------- -------------------- -------------------- -------------------- -------------------- -------------------- -------------------- -------------------- -------------------- -------------------- -------------------- -------------------- -------------------- 
---BBBBBBBBBBBBBB--- -------AAAAAA------- -------AAAAAA------- -------AAAAAA------- -------AAAAAA------- -------AAAAAA------- -------AAAAAA------- -------AAAAAA------- -------AAAAAA------- -------AAAAAA------- -------AAAAAA------- -------AAAAAA------- -------AAAAAA------- -------AAAAAA------- -------AAAAAA------- -------AAAAAA------- -------------------- 
--BBBBB------BBBBB-- -----AA------AA----- -----AA------AA----- -----AA------AA----- -----AA------AA----- -----AA------AA----- -----AA------AA----- -----AA------AA----- -----AA------AA----- -----AA------AA----- -----AA------AA----- -----AAAAAAAAAA----- -----AAAAAAAAAA----- -----AAAAAAAAAA----- -----AAAAAAAAAA----- -----AAAAAAAAAA----- -------AAAAAA------- 
-BBBB----------BBBB- ----A----------A---- ----A----------A---- ----A----------A---- ----A----------A---- ----A----------A---- ----A----------A---- ----A----------A---- ----A----------A---- ----A----------A---- ----A----------A---- ----AAAAAAAAAAAA---- ----AAAAAAAAAAAA---- ----AAAAAAAAAAAA---- ----AAAAAAAAAAAA---- ----AAAAAAAAAAAA---- -----AAAAAAAAAA----- 
BBBBB----------BBBBB ----A----------A---- ----A----------A---- ----A----------A---- ----A----------A---- ----A----------A---- ----A----------A---- ----A----------A---- ----A----------A---- ----A----------A---- ----A----------A---- ----AAAAAAAAAAAA---- ----AAAAAAAAAAAA---- ----AAAAAAAAAAAA---- ----AAAAAAAAAAAA---- ----AAAAAAAAAAAA---- -----AAAAAAAAAA----- 
BBBB------------BBBB ---A------------A--- ---A------------A--- ---A------------A--- ---A------------A--- ---A------------A--- ---A------------A--- ---A------------A--- ---A------------A--- ---A------------A--- ---A------------A--- ---AAAAAAAAAAAAAA--- ---AAAAAAAAAAAAAA--- ---AAAAAAAAAAAAAA--- ---AAAAAAAAAAAAAA--- ---AAAAAAAAAAAAAA--- ----AAAAAAAAAAAA---- 
BBBB------------BBBB ---A------------A--- ---A------------A--- ---A------------A--- ---A------------A--- ---A------------A--- ---A------------A--- ---A------------A--- ---A------------A--- ---A------------A--- ---A------------A--- ---AAAAAAAAAAAAAA--- ---AAAAAAAAAAAAAA--- ---AAAAAAAAAAAAAA--- ---AAAAAAAAAAAAAA--- ---AAAAAAAAAAAAAA--- ----AAAAAAAAAAAA---- 
BBBB------------BBBB ---A------------A--- ---A------------A--- ---A------------A--- ---A------------A--- ---A------------A--- ---A------------A--- ---A------------A--- ---A------------A--- ---A------------A--- ---A------------A--- ---AAAAAAAAAAAAAA--- ---AAAAAAAAAAAAAA--- ---AAAAAAAAAAAAAA--- ---AAAAAAAAAAAAAA--- ---AAAAAAAAAAAAAA--- ----AAAAAAAAAAAA---- 
BBBB------------BBBB ---A------------A--- ---A------------A--- ---A------------A--- ---A------------A--- ---A------------A--- ---A------------A--- ---A------------A--- ---A------------A--- ---A------------A--- ---A------------A--- ---AAAAAAAAAAAAAA--- ---AAAAAAAAAAAAAA--- ---AAAAAAAAAAAAAA--- ---AAAAAAAAAAAAAA--- ---AAAAAAAAAAAAAA--- ----AAAAAAAAAAAA---- 
BBBB------------BBBB ---A------------A--- ---A------------A--- ---A------------A--- ---A------------A--- ---A------------A--- ---A------------A--- ---A------------A--- ---A------------A--- ---A------------A--- ---A------------A--- ---AAAAAAAAAAAAAA--- ---AAAAAAAAAAAAAA--- ---AAAAAAAAAAAAAA--- ---AAAAAAAAAAAAAA--- ---AAAAAAAAAAAAAA--- ----AAAAAAAAAAAA---- 
BBBB------------BBBB ---A------------A--- ---A------------A--- ---A------------A--- ---A------------A--- ---A------------A--- ---A------------A--- ---A------------A--- ---A------------A--- ---A------------A--- ---A------------A--- ---AAAAAAAAAAAAAA--- ---AAAAAAAAAAAAAA--- ---AAAAAAAAAAAAAA--- ---AAAAAAAAAAAAAA--- ---AAAAAAAAAAAAAA--- ----AAAAAAAAAAAA---- 
BBBBB----------BBBBB ----A----------A---- ----A----------A---- ----A----------A---- ----A----------A---- ----A----------A---- ----A----------A---- ----A----------A---- ----A----------A---- ----A----------A---- ----A----------A---- ----AAAAAAAAAAAA---- ----AAAAAAAAAAAA---- ----AAAAAAAAAAAA---- ----AAAAAAAAAAAA---- ----AAAAAAAAAAAA---- -----AAAAAAAAAA----- 
-BBBB----------BBBB- ----A----------A---- ----A----------A---- ----A----------A---- ----A----------A---- ----A----------A---- ----A----------A---- ----A----------A---- ----A----------A---- ----A----------A---- ----A----------A---- ----AAAAAAAAAAAA---- ----AAAAAAAAAAAA---- ----AAAAAAAAAAAA---- ----AAAAAAAAAAAA---- ----AAAAAAAAAAAA---- -----AAAAAAAAAA----- 
--BBBBB------BBBBB-- -----AA------AA----- -----AA------AA----- -----AA------AA----- -----AA------AA----- -----AA------AA----- -----AA------AA----- -----AA------AA----- -----AA------AA----- -----AA------AA----- -----AA------AA----- -----AAAAAAAAAA----- -----AAAAAAAAAA----- -----AAAAAAAAAA----- -----AAAAAAAAAA----- -----AAAAAAAAAA----- -------AAAAAA------- 
---BBBBBBBBBBBBBB--- -------AAAAAA------- -------AAAAAA------- -------AAAAAA------- -------AAAAAA------- -------AAAAAA------- -------AAAAAA------- -------AAAAAA------- -------AAAAAA------- -------AAAAAA------- -------AAAAAA------- -------AAAAAA------- -------AAAAAA------- -------AAAAAA------- -------AAAAAA------- -------AAAAAA------- -------------------- 
----BBBBBBBBBBBB---- -------------------- -------------------- -------------------- -------------------- -------------------- -------------------- -------------------- -------------------- -------------------- -------------------- -------------------- -------------------- -------------------- -------------------- -------------------- -------------------- 
-----BBBBBBBBBB----- -------------------- -------------------- -------------------- -------------------- -------------------- -------------------- -------------------- -------------------- -------------------- -------------------- -------------------- -------------------- -------------------- -------------------- -------------------- -------------------- 
------BBBBBBBB------ -------------------- -------------------- -------------------- -------------------- -------------------- -------------------- -------------------- -------------------- -------------------- -------------------- -------------------- -------------------- -------------------- -------------------- -------------------- -------------------- 
