model
size = 16 4 26, scale = 0.05, origin = -y
material 
  colors = A:#111 B:#444 C:#222
voxels
-------CC------- ---------------- ---------------- ---------------- 
-------CC------- -------CC------- ---------------- ---------------- 
-------CC------- -------CC------- ---------------- ---------------- 
-------CC------- -------CC------- ---------------- ---------------- 
-------CC------- -------CC------- ---------------- ---------------- 
-------CC------- -------CC------- ---------------- ---------------- 
-------CC------- -------CC------- ---------------- ---------------- 
-------CC------- -------CC------- -------CC------- ---------------- 
-------CC------- -------CC------- -------CC------- ---------------- 
---------------- -------BB------- -------BB------- ---------------- 
---------------- -----AAAAAA----- -----AAAAAA----- -------BB------- 
---------------- ---AA------AA--- ---AA------AA--- -----AAAAAA----- 
---------------- --A----------A-- --A----------A-- ---AABBBBBBAA--- 
---------------- -A------------A- -A------------A- --AABAAAAAABAA-- 
---------------- -A------------A- -A------------A- --ABAAAAAAAABA-- 
---------------- A--------------A A--------------A -ABAAAAAAAAAABA- 
---------------- A--------------A A--------------A -ABAAAAAAAAAABA- 
---------------- A--------------A A--------------A -ABAAAAAAAAAABA- 
---------------- A--------------A A--------------A -ABAAAAAAAAAABA- 
---------------- A--------------A A--------------A -ABAAAAAAAAAABA- 
---------------- A--------------A A--------------A -ABAAAAAAAAAABA- 
---------------- -A------------A- -A------------A- --ABAAAAAAAABA-- 
---------------- -A------------A- -A------------A- --AABAAAAAABAA-- 
---------------- --A----------A-- --A----------A-- ---AABBBBBBAA--- 
---------------- ---AA------AA--- ---AA------AA--- -----AAAAAA----- 
---------------- -----AAAAAA----- -----AAAAAA----- -------BB------- 
