model
size = 32 32 31, scale = 0.05, origin = -y
material 
  colors = A:#FFF B:#9FF C:#C6F D:#30F E:#93F F:#004 G:#C3F H:#00B I:#66F J:#FC9 K:#60F L:#008 M:#007 N:#005 O:#6FF P:#EEE Q:#BBB R:#F90 S:#C96 T:#963 U:#F93 V:#FF9 W:#F96 X:#960 Y:#60C Z:#F0F Aa:#FF3 Ab:#FF6 Ac:#F0C Ad:#3FF Ae:#0FF Af:#F3F Ag:#CF3 Ah:#FC6
voxels
93-Ab1789-Ab193-Ab61-Ab-O-Ab61-Ab133-I991-O30-3O30-O745-8C24-8G8-Ab15-8G24-EA6E24-8E24-IAe6I24-3AeIA3I24-KAe6K14-I9-8K24-DA6D24-8D24-8H24-7HU24-6LUAa24-3M2L2MU24-8N24-3FAc4F24-8F24-8A42-Af365-8A22-12C20-12G20-10GAG2(20-12E)20-12I20-A11I2(20-12K)2(20-12D)2(20-12H)20-10LUL20-5M2L5M20-12N2(20-12F)20-2A8B2A21-10A373-12A18-16C2(16-4G8-4G)2(16-4E8-4E)2(16-4I8-4I)2(16-4K8-4K)2(16-4D8-4D)2(16-4H8-4H)16-Af3L8-LA2L16-4M8-4M16-4N8-4N2(16-4F8-4F)16-2A12B2A18-12A370-16A15-18C2(14-3G12-3G)2(14-3E12-3E)14-Ac2I12-3I14-3I12-3I14-3K12-2KAc14-3K12-3K2(14-3D12-3D)2(14-3H12-3H)14-3L12-3L14-3M12-3M14-3N12-3N2(14-3F12-3F)14-2A14B2A16-2A10B2A20-10A338-18A13-20C2(12-3G14-3G)2(12-3E14-3E)2(12-3I14-3I)2(12-3K14-3K)2(12-3D14-3D)2(12-3H14-3H)12-3L14-3L12-3M14-3M12-3N14-3N2(12-3F14-3F)12-2A16B2A14-2A12B2A18-2A8B2A22-8A307-8AL9A13-20C2(12-2G16-2G)2(12-2E16-2E)2(12-2I16-2I)2(12-2K16-2K)2(12-2D16-2D)2(12-2H16-2H)12-2L16-2L12-2M16-MAa12-2N16-2N2(12-2F16-2F)12-A13BO4BA13-2A11B2OB2A16-2A9BO2A20-10A151-8P146-20A11-22C10-AaG18-2G10-2G18-2G2(10-2E18-2E)2(10-2I18-2I)10-2K18-2K10-UK18-2K2(10-2D18-2D)10-2H18-2H10-2H18-HE10-2L18-2L10-2M18-2M10-2N18-2N2(10-2F18-2F)10-A14BO5BA11-2A12B2O2B2A14-2A10BOB2A18-12A118-8Q22-3P6-3P55-TR2TRT26-JS2JSJ26-TR2WRT19-3A2(L5A)L4A11-22C2(10-2G18-2G)2(10-2E18-2E)2(10-2I18-2I)10-VK18-2K10-UK18-2K10-VD18-2D10-2D18-2D10-2H18-HZ10-2H18-HE10-2L18-LZ10-2M18-2M10-2N18-2N2(10-2F18-2F)10-A6B6-2BO5BA10-2A5B6-2B2O3B2A12-2A3B6-2BO2B2A16-4A5-B4A22-2(6A26-)6A24-2QOJ2WJO2Q20-2P3-JU2X3-2P23-X2JU25-2R6J2R22-R8JR22-STJS2JSJTS16-3(ALA3L)AL2A9-24C2(8-2G20-2G)2(8-2E20-2E)8-2I20-2I8-VI20-2I8-VK20-2K8-UK20-2K8-VD20-2D8-VD20-D2(Z8-2H20-H)E8-2L20-LZ8-2M20-MZ8-2N20-2N2(8-2F20-2F)8-A6B8-BO6BA9-2A4B8-B2O3B2A12-A3B8-BO3BA15-4A7-B4A20-2(AB4-BA24-)AB4-BA22-2Q2J4-2J2Q19-P-U2J4-JSJ-P20-XJU4-UJX21-S3J4-3JS20-4J4-4J20-RJWRJ2SJRWJR15-22A9-24C2(8-2G20-2G)8-2E20-2E8-2E20-EAf2(8-VI20-2I)8-VD20-DK8-UD20-DK8-VD20-2D8-VD20-DZ8-VH20-HZ8-2H20-HE8-LY20-YZ8-2M20-MZ8-2M20-2M2(8-2F20-2F)8-A5B10-O6BA9-2A3B10-2O3B2A12-A2B10-O3BA15-3A9-B3A19-2(AB6-BA22-)AB6-BA20-2QWJ6-JW2Q17-2P-2J6-JS-2P19-XJ6-2J21-R2J6-2JR20-3J6-3J20-TJRJW2RWJRJT15-L2ALA2LA3L3(AL)2A3L9-24C2(8-2G20-2G)2(8-2E20-2E)2(8-VI20-2I)8-VD20-DK8-U3(D20-2D8-V)H20-HZ8-2H20-HE8-LY20-YZ2(8-2M20-2M)2(8-2F20-2F)8-A5B11-6BA9-2A3B11-O3B2A12-A2B11-3BA15-2A11-B2A18-2(AB8-BA20-)AB8-BA19-QOJ8-JOQ17-P2-S8-J2-P19-J8-X20-3J8-3J18-W2J8-2JW18-2RSJTJ2TJTJS2R14-2L2(AL)2A4(LA)L2ALAL9-24C2(8-2G20-2G)2(8-2E20-2E)2(8-VI20-2I)8-VD20-DK8-U3(D20-2D8-V)H20-2H8-2H20-HE8-LY20-YL2(8-2M20-2M)2(8-2F20-2F)8-A5B11-6BA9-2A3B11-O3B2A12-A2B11-3BA15-2A11-B2A18-2(A10-A20-)A10-A19-QJ10-JQ17-P-X10-U-P18-J10-J19-2(2J10-2J18-)2(SJ)WR2JRW2(JS)14-L2(A2L)A3L3(AL)2A3L9-24C2(8-2G20-2G)2(8-2E20-2E)8-2I20-2I8-VI20-2I8-VD20-DK8-U2(D20-2D8-V)D20-2D2(8-2H20-2H)8-LY20-YL2(8-2M20-2M)2(8-2F20-2F)8-A5B11-6BA9-2A3B11-O3B2A12-A2B11-3BA15-2A11-B2A18-2(A10-A20-)A10-A19-QX10-XQ17-P-J10-J-P18-U10-U19-TJ10-JT18-RJ10-JR18-JW2RJS2WSJ2RWJ14-2(L2ALA)3(LA)L2ALAL9-24C2(8-2G20-2G)2(8-2E20-2E)2(8-2I20-2I)8-VD20-DK8-UD20-2D8-VD20-2D8-2D20-2D2(8-2H20-2H)8-LY20-YL2(8-2M20-2M)2(8-2F20-2F)8-A5B11-6BA9-2A3B11-O3B2A12-A2B11-3BA15-2A11-B2A18-2(A10-A20-)A10-A19-QAh10-AhQ17-P-U10-X-P18-J10-J19-WJ10-JW18-2J10-2J18-TSJT2J2T2JTJST14-L2ALA2L2(A3L)A2L2(AL)9-24C2(8-2G20-2G)2(8-2E20-2E)8-2I20-IAa8-2I20-2I8-KD20-DK8-UD20-DK2(8-2D20-2D)2(8-2H20-2H)8-AY20-YL2(8-2M20-2M)2(8-2F20-2F)8-A5B10-O6BA9-2A3B10-2O3B2A12-A2B10-O3BA15-2A10-2B2A18-2(AB8-BA20-)AB8-BA19-QOJ8-JOQ17-P2-J8-U2-P19-X8-U20-3J8-3J18-S2J8-2JS18-RJRSJT2JTJSRJR14-22A9-24C8-2G20-2G8-AcE2(20-2E8-2E)20-2E2(8-2I20-2I)2(8-2K20-2K)2(8-2D20-2D)8-2H20-HA8-2H20-2H8-2L20-2L8-2M20-2M8-2N20-2N2(8-2F20-2F)8-A6B8-8BA9-2A4B8-3O3B2A12-A2BO8-2O3BA15-3A8-OB3A19-2(AO6-OA22-)AB6-BA20-2QXJ6-JX2Q17-2P-SJ6-JS-2P19-2J6-2J21-T2J6-2JT20-3J6-3J20-S2JTW2RWT2JS16-3(LA3LA)LA11-22C10-2G18-2G10-EG18-GE2(10-2E18-2E)2(10-2I18-2I)2(10-2K18-2K)2(10-2D18-2D)2(10-2H18-2H)10-2L18-2L10-2M18-2M10-2N18-2N2(10-2F18-2F)10-A6B6-8BA10-2A5B6-7B2A12-2A3B6-5B2A16-3A6-2B3A21-2(AB4-BA24-)AB4-BA22-2Q2J4-2J2Q19-P-JUX4-XSJ-P20-XSJ4-SJX21-R3J4-3JR20-S3J4-3JS20-2TWRJ2SJRW2T16-3A2(L5A)L4A11-22C10-2G18-GU10-EG18-GE2(10-2E18-2E)2(10-2I18-2I)2(10-2K18-2K)2(10-2D18-2D)2(10-2H18-2H)10-2L18-2L10-2M18-2M10-2N18-2N2(10-2F18-2F)10-A20BA11-2A16B2A14-2A12B2A18-3A6B3A23-2(6A26-)6A24-2QOX2UXO2Q20-2P3-JS2J3-2P23-UJXU25-W8JW22-TS6JST22-RTRS2JSRTR18-18A13-20C2(12-2G16-2G)2(12-2E16-2E)12-AcI16-2I12-2I16-2I2(12-2K16-2K)2(12-2D16-2D)2(12-2H16-2H)12-2L16-2L12-2M16-2M12-2N16-2N2(12-2F16-2F)12-A18BA13-2A14B2A16-2A10B2A20-10A119-8Q22-3P6-3P11-Ab43-WT2JTW26-JS2RSJ26-TJ2WJT20-8AL9A13-20C2(12-3G14-3G)2(12-3E14-3E)2(12-3I14-3I)2(12-3K14-3K)2(12-3D14-3D)2(12-3H14-3H)12-3L14-3L12-3M14-3M12-3N14-3N12-3F14-3F12-3F14-2FAc12-2A16B2A14-2A12B2A18-2A8B2A22-8A152-8P148-16A15-18C2(14-3G12-3G)2(14-3E12-3E)2(14-3I12-3I)2(14-3K12-3K)2(14-3D12-3D)14-O2H12-3H14-3H12-3H14-3L12-3L14-3M12-3M14-Ac2N12-3N2(14-3F12-3F)14-2A14B2A16-2A10B2A20-10A140-G61-G-O-G61-G72-12A18-16C2(16-4G8-4G)16-4E8-4E16-EAa2E8-4E16-4I8-3IA16-4I8-4I2(16-4K8-4K)16-4D8-4D16-O3D8-4D16-2O2H8-4H16-O3H8-4H16-4L8-4L16-4M8-4M16-4N8-4N2(16-4F8-4F)16-2A12B2A18-12A374-8A22-12C2(20-12G)2(20-12E)2(20-12I)2(20-12K)2(20-12D)2(20-12H)20-12L20-5M2L4MU20-12N2(20-12F)20-2A8B2A21-10A236-Ab170-8C24-6GAaG24-5G3Aa14-A9-6EAaE24-3E3O2E24-2I5OI24-I7Ad24-2K5OK24-3K3O2K24-8D24-4DA3D2(24-8H)24-LAf6L24-3M2L3M24-8N2(24-8F)24-8A937-Ag380-A610-O30-3O30-O991-Ag481-
