model
size = 22 19 14, scale = 0.05, origin = -y
material 
  colors = A:#111 B:#373C38 C:#E83015 D:#26453D E:#FFC408
voxels
BBBBBBBDDCCCCDDBBBBBBB AAAAAAADDCCCCDDAAAAAAA AAAAAAADDCCCCDDAAAAAAA ---------------------- ---------------------- ---------------------- ---------------------- ---------------------- ---------------------- ---------------------- ---------------------- ---------------------- ---------------------- ---------------------- ---------------------- ---------------------- ---------------------- ---------------------- ---------------------- 
BAAAAAAAAAAAAAAAAAAAAB AA-------------------A AA-------------------A -BBBBBBDDCCCCDDBBBBBB- -AAAAAADDCCCCDDAAAAAA- -AAAAAADDCCCCDDAAAAAA- -AAAAAADDCCCCDDAAAAAA- -AAAAAADDCCCCDDAAAAAA- -AAAAAADDCCCCDDAAAAAA- -BBBBBBDDCCCCDDBBBBBB- ---------------------- ---------------------- ---------------------- ---------------------- ---------------------- ---------------------- ---------------------- ---------------------- ---------------------- 
BAAAAAAAAAAAAAAAAAAAAB AA-------------------A AA-------------------A -B------------------B- -A------------------A- -A------------------A- -A------------------A- -A------------------A- -A------------------A- -B------------------B- -AAAAAADDCCCCDDAAAAAA- ---------------------- ---------------------- ---------------------- ---------------------- ---------------------- ---------------------- ---------------------- ---------------------- 
BAAAAAAAAAAAAAAAAAAAAB AA-------------------A AA-------------------A -B------------------B- -A------------------A- -A------------------A- -A------------------A- -A------------------A- -A------------------A- -B------------------B- -A------------------A- -AAAAAADDCCCCDDAAAAAA- ---------------------- ---------------------- ---------------------- ---------------------- ---------------------- ---------------------- ---------------------- 
BAAAAAAAAAAAAAAAAAAAAB AA-------------------A AA-------------------A -B------------------B- -A------------------A- -A------------------D- -C------------------D- -C------------------D- -A------------------A- -B------------------B- -A------------------A- -A------------------A- -AAAAAADDCCCCDDAAAAAA- ---------------------- ---------------------- ---------------------- ---------------------- ---------------------- ---------------------- 
BAAAAAAAAAAAAAAAAAAAAB AA-------------------A AA-------------------A -B------------------B- -A------------------A- -C------------------D- -A------------------A- -A------------------A- -A------------------A- -B------------------B- -A------------------A- -A------------------A- -A------------------A- -AAAAEAEDCCCCDEAEAAAA- ------B--------B------ ------B--------B------ -------B------B------- --------B----B-------- ---------BBBB--------- 
BAAAAAAAAAAAAAAAAAAAAB AA-------------------A AA-------------------A -B------------------B- -A------------------A- -A------------------A- -C------------------A- -C------------------A- -A------------------A- -B------------------B- -A------------------A- -A------------------A- -A------------------A- -EBBBBBBBBBBBBBBBBBBE- ---------------------- ---------------------- ---------------------- ---------------------- ---------------------- 
BAAAAAAAAAAAAAAAAAAAAB AA-------------------A AA-------------------A -B------------------B- -A------------------A- -A------------------A- -A------------------C- -A------------------C- -A------------------A- -B------------------B- -A------------------A- -A------------------A- -A------------------A- -EBBBBBBBBBBBBBBBBBBE- ---------------------- ---------------------- ---------------------- ---------------------- ---------------------- 
BAAAAAAAAAAAAAAAAAAAAB AA-------------------A AA-------------------A -B------------------B- -A------------------A- -D------------------C- -A------------------A- -A------------------A- -A------------------A- -B------------------B- -A------------------A- -A-----------------AA- -A------------AA----A- -AAAAEAEDCCCCDEAEAAAA- ------B--------B------ ------B--------B------ -------B------B------- --------B----B-------- ---------BBBB--------- 
BAAAAAAAAAAAAAAAAAAAAB AA-------------------A AA-------------------A -B------------------B- -A------------------A- -D------------------A- -D------------------C- -D------------------C- -A------------------A- -B------------------B- -A-----------------AA- -A-------------AA---A- -AAAAAADDCCCCDDAAAAAA- ---------------------- ---------------------- ---------------------- ---------------------- ---------------------- ---------------------- 
BAAAAAAAAAAAAAAAAAAAAB AA-------------------A AA-------------------A -B------------------B- -A------------------A- -A------------------A- -A------------------A- -A------------------A- -A------------------A- -B-----------------AB- -AA-------------AA--A- -AAAAAADDCCCCDDAAAAAA- ---------------------- ---------------------- ---------------------- ---------------------- ---------------------- ---------------------- ---------------------- 
BAAAAAAAAAAAAAAAAAAAAB AA-------------------A AA-------------------A -B------------------B- -A------------------A- -A------------------A- -A------------------A- -A------------------A- -A---------------A-AA- -B---------------AA-B- -AAAAAADDCCCCDDAAAAAA- ---------------------- ---------------------- ---------------------- ---------------------- ---------------------- ---------------------- ---------------------- ---------------------- 
BAAAAAAAAAAAAAAAAAAAAB AA-------------------A AA-------------------A -BBBBBBDDCCCCDDBBBBBB- -AAAAAADDCCCCDDAAAAAA- -AAAAAADDCCCCDDAAAAAA- -AAAAAADDCCCCDDAAAAAA- -AAAAAADDCCCCDDAAAAAA- -AAAAAADDCCCCDDAAAAAA- -BBBBBBDDCCCCDDBBBBBB- ---------------------- ---------------------- ---------------------- ---------------------- ---------------------- ---------------------- ---------------------- ---------------------- ---------------------- 
BBBBBBBDDCCCCDDBBBBBBB AAAAAAADDCCCCDDAAAAAAA AAAAAAADDCCCCDDAAAAAAA ---------------------- ---------------------- ---------------------- ---------------------- ---------------------- ---------------------- ---------------------- ---------------------- ---------------------- ---------------------- ---------------------- ---------------------- ---------------------- ---------------------- ---------------------- ---------------------- 
