model
size = 29 31 19, scale = 0.05, origin = -y
material 
  colors = A:#444 B:#111 C:#630 D:#963 E:#777 F:#222
voxels
----------------------------- ----------------------------- ----------------------------- ----------------------------- ----------------------------- ----------------------------- ----------------------------- ----------------------------- ----------------------------- ----------------------------- ----------------------------- ----------------------------- ----------------------------- ----------------------------- ----------------------------- ----------------------------- ----------------------------- ----------------------------- ------------------------BBB-- ----------------------------- ----------------------------- ----------------------------- ----------------------------- ----------------------------- ----------------------------- ----------------------------- ----------------------------- ----------------------------- ----------------------------- ----------------------------- ----------------------------- 
------------------------BBB-- -------------------------D--- ------------------------DBD-- -------------------------D--- ------------------------DBD-- -------------------------D--- ------------------------DBD-- -------------------------D--- ------------------------DBD-- -------------------------D--- ------------------------DBD-- -------------------------D--- ------------------------DBD-- -------------------------D--- ------------------------DBD-- -------------------------D--- ------------------------DBD-- -------------------------D--- -----------------------BBBBB- ----------------------------- ----------------------------- ----------------------------- ----------------------------- ----------------------------- ----------------------------- ----------------------------- ----------------------------- ----------------------------- ----------------------------- ----------------------------- ----------------------------- 
-----------------------BBBBB- ------------------------CCC-- -----------------------DCCCD- ------------------------CCC-- -----------------------DCCCD- ------------------------CCC-- -----------------------DCCCD- ------------------------CCC-- -----------------------DCCCD- ------------------------CCC-- -----------------------DCCCD- ------------------------CCC-- -----------------------DCCCD- ------------------------CCC-- -----------------------DCCCD- ------------------------CCC-- -----------------------DCCCD- ------------------------CCC-- ----------------------BBBBBBB -------------------------F--- ----------------------------- ----------------------------- ----------------------------- ----------------------------- ----------------------------- ----------------------------- ----------------------------- ----------------------------- ----------------------------- ----------------------------- ----------------------------- 
-----------------------BBBBB- -----------------------DCCCD- -----------------------BCCCB- -----------------------DCCCD- -----------------------BCCCB- -----------------------DCCCD- -----------------------BCCCB- -----------------------DCCCD- -----------------------BCCCB- -----------------------DCCCD- -----------------------BCCCB- -----------------------DCCCD- -----------------------BCCCB- -----------------------DCCCD- -----------------------BCCCB- -----------------------DCCCD- -----------------------BCCCB- -----------------------DCCCD- ----------------------BBBCBBB ------------------------FEF-- -------------------------E--- -------------------------E--- -------------------------E--- -------------------------E--- -------------------------E--- ----------------------------- ----------------------------- ----------------------------- ----------------------------- ----------------------------- ----------------------------- 
-----------------------BBBBB- ------------------------CCC-- -----------------------DCCCD- ------------------------CCC-- -----------------------DCCCD- -----B------------------CCC-- -----------------------DCCCD- ------------------------CCC-- -----------------------DCCCD- ------------------------CCC-- -----------------------DCCCD- ------------------------CCC-- -----------------------DCCCD- ------------------------CCC-- -----------------------DCCCD- ------------------------CCC-- -----------------------DCCCD- ------------------------CCC-- ----------------------BBBBBBB -------------------------F--- ----------------------------- ----------------------------- ----------------------------- ----------------------------- ----------------------------- -------------------------E--- ----------------------------- ----------------------------- ----------------------------- ----------------------------- ----------------------------- 
------------------------BBB-- -------------------------D--- ------------------------DBD-- ----B-B------------------D--- ---B-A-B----------------DBD-- ----AAA------------------D--- ---B-A-B----------------DBD-- ----B-B------------------D--- ------------------------DBD-- -------------------------D--- ------------------------DBD-- -------------------------D--- ------------------------DBD-- -------------------------D--- ------------------------DBD-- -------------------------D--- ------------------------DBD-- -------------------------D--- -----------------------BBBBB- ----------------------------- ----------------------------- ----------------------------- ----------------------------- ----------------------------- ----------------------------- ----------------------------- --------------------------E-- ----------------------------- ----------------------------- ----------------------------- ----------------------------- 
----------------------------- ----------------------------- -----B----------------------- --B-AAA-B-------------------- ---AAAAA--------------------- --BAAAAAB-------------------- ---AAAAA--------------------- --B-AAA-B-------------------- -----B----------------------- ----------------------------- ----------------------------- ----------------------------- ----------------------------- ----------------------------- ----------------------------- ----------------------------- ----------------------------- ----------------------------- ------------------------BBB-- ----------------------------- ----------------------------- ----------------------------- ----------------------------- ----------------------------- ----------------------------- ----------------------------- ----------------------------- --------------------------E-- ----------------------------- ----------------------------- ----------------------------- 
----------------------------- ----B-B---------------------- ----AAA---------------------- ---AAAAA--------------------- -BAAAAAAAB------------------- --AAAAAAA-------------------- -BAAAAAAAB------------------- ---AAAAA--------------------- ----AAA---------------------- ----B-B---------------------- ----------------------------- ----------------------------- ----------------------------- ----------------------------- ----------------------------- ----------------------------- ----------------------------- ----------------------------- ----------------------------- ----------------------------- ----------------------------- ----------------------------- ----------------------------- ----------------------------- ----------------------------- ----------------------------- ----------------------------- ----------------------------- -------------------------E--- ------------------------E---- ----------------------------- 
----------------------------- ---B-A-B--------------------- ---AAAAA--------------------- -BAAAAAAAB------------------- --AAAAAAA-------------------- -AAAAAAAAA------------------- --AAAAAAA-------------------- -BAAAAAAAB------------------- ---AAAAA--------------------- ---B-A-B--------------------- ----------------------------- ----------------------------- ----------------------------- ----------------------------- ----------------------------- ----------------------------- ----------------------------- ----------------------------- ----------------------------- ----------------------------- ----------------------------- ----------------------------- ----------------------------- ----------------------------- ----------------------------- ----------------------------- ----------------------------- ----------------------------- ----------------------------- ----------------------------- ------------------------E---- 
-----B----------------------- ----AAA---------------------- --BAAAAAB-------------------- --AAAAAAA-------------------- -AAAAAAAAA------------------- BAAAAAAAAAB------------------ -AAAAAAAAA------------------- --AAAAAAA-------------------- --BAAAAAB-------------------- ----AAA---------------------- -----B----------------------- -----E----------------------- -----E----------------------- -----E----------------------- ----------------------------- ----------------------------- ----------------------------- ----------------------------- ----------------------------- ----------------------------- ----------------------------- ----------------------------- ----------------------------- ----------------------------- ----------------------------- ----------------------------- ----------------------------- ----------------------------- ----------------------------- ----------------------E------ -----------------------E----- 
----------------------------- ---B-A-B--------------------- ---AAAAA--------------------- -BAAAAAAAB------------------- --AAAAAAA-------------------- -AAAAAAAAA------------------- --AAAAAAA-------------------- -BAAAAAAAB------------------- ---AAAAA--------------------- ---B-A-B--------------------- ----------------------------- ----------------------------- ----------------------------- ----------------------------- ------E---------------------- ----------------------------- ----------------------------- ----------------------------- ----------------------------- ----------------------------- ----------------------------- ----------------------------- ----------------------------- ----------------------------- ----------------------------- ----------------------------- ----------------------------- ----------------------------- ----------------------------- ---------------------E------- ----------------------------- 
----------------------------- ----B-B---------------------- ----AAA---------------------- ---AAAAA--------------------- -BAAAAAAAB------------------- --AAAAAAA-------------------- -BAAAAAAAB------------------- ---AAAAA--------------------- ----AAA---------------------- ----B-B---------------------- ----------------------------- ----------------------------- ----------------------------- ----------------------------- ----------------------------- -------E--------------------- ----------------------------- ----------------------------- ----------------------------- ----------------------------- ----------------------------- ----------------------------- ----------------------------- ----------------------------- ----------------------------- ----------------------------- ----------------------------- ----------------------------- ---------------------E------- ----------------------------- ----------------------------- 
----------------------------- ----------------------------- -----B----------------------- --B-AAA-B-------------------- ---AAAAA--------------------- --BAAAAAB-------------------- ---AAAAA--------------------- --B-AAA-B-------------------- -----B----------------------- ----------------------------- ----------------------------- ----------------------------- ----------------------------- ----------------------------- ----------------------------- ----------------------------- --------E-------------------- ----------------------------- ----------------------------- ----------------------------- ----------------------------- ----------------------------- ----------------------------- ----------------------------- ----------------------------- ----------------------------- ----------------------------- -------------------E--------- --------------------E-------- ----------------------------- ----------------------------- 
----------------------------- ----------------------------- ----------------------------- ----B-B---------------------- ---B-A-B--------------------- ----AAA---------------------- ---B-A-B--------------------- ----B-B---------------------- ----------------------------- ----------------------------- ----------------------------- ----------------------------- ----------------------------- ----------------------------- ----------------------------- ----------------------------- ---------E------------------- ----------------------------- ----------------------------- ----------------------------- ----------------------------- ----------------------------- ----------------------------- ----------------------------- ----------------------------- ----------------------------- ----------------------------- ------------------E---------- ----------------------------- ----------------------------- ----------------------------- 
----------------------------- ----------------------------- ----------------------------- ----------------------------- ----------------------------- -----B----------------------- ----------------------------- ----------------------------- ----------------------------- ----------------------------- ----------------------------- ----------------------------- ----------------------------- ----------------------------- ----------------------------- ----------------------------- ----------------------------- ---------E------------------- ----------E------------------ ----------------------------- ----------------------------- ----------------------------- ----------------------------- ----------------------------- ----------------------------- -----------------E----------- ------------------E---------- ----------------------------- ----------------------------- ----------------------------- ----------------------------- 
----------------------------- ----------------------------- ----------------------------- ----------------------------- ----------------------------- ----------------------------- ----------------------------- ----------------------------- ----------------------------- ----------------------------- ----------------------------- ----------------------------- ----------------------------- ----------------------------- ----------------------------- ----------------------------- ----------------------------- ----------------------------- ----------------------------- -----------E----------------- ----------------------------- ----------------------------- ----------------------------- ----------------------------- ----------------------------- ----------------E------------ ----------------------------- ----------------------------- ----------------------------- ----------------------------- ----------------------------- 
----------------------------- ----------------------------- ----------------------------- ----------------------------- ----------------------------- ----------------------------- ----------------------------- ----------------------------- ----------------------------- ----------------------------- ----------------------------- ----------------------------- ----------------------------- ----------------------------- ----------------------------- ----------------------------- ----------------------------- ----------------------------- ----------------------------- ----------------------------- ------------E---------------- ----------------------------- ----------------------------- ----------------------------- ----------------------------- ----------------E------------ ----------------------------- ----------------------------- ----------------------------- ----------------------------- ----------------------------- 
----------------------------- ----------------------------- ----------------------------- ----------------------------- ----------------------------- ----------------------------- ----------------------------- ----------------------------- ----------------------------- ----------------------------- ----------------------------- ----------------------------- ----------------------------- ----------------------------- ----------------------------- ----------------------------- ----------------------------- ----------------------------- ----------------------------- ----------------------------- ----------------------------- ------------E---------------- -------------E--------------- ----------------------------- ----------------------------- ---------------E------------- ----------------------------- ----------------------------- ----------------------------- ----------------------------- ----------------------------- 
----------------------------- ----------------------------- ----------------------------- ----------------------------- ----------------------------- ----------------------------- ----------------------------- ----------------------------- ----------------------------- ----------------------------- ----------------------------- ----------------------------- ----------------------------- ----------------------------- ----------------------------- ----------------------------- ----------------------------- ----------------------------- ----------------------------- ----------------------------- ----------------------------- ----------------------------- ----------------------------- --------------E-------------- ---------------E------------- ----------------------------- ----------------------------- ----------------------------- ----------------------------- ----------------------------- ----------------------------- 
