model
size = 32 31 32, scale = 0.05, origin = -y
material 
  colors = A:#222 B:#AAA C:#444 D:#9CF E:#888 F:#555 G:#F90 H:#777 I:#FC3 J:#FF6 K:#FFC L:#F69 M:#D00 N:#FC0 O:#960 P:#06F Q:#F93 R:#09F S:#EEE T:#FC9
voxels
32-3E26-3E65-2C461-T3(31-F)31-T280-5AI2GI5A9-3E6-5AI2GI5A6-3E-E7-5AI2GI5A7-E2-B28-B-CB28-B3-2C492-F343-6AI2GI6A8-3E5-5ADI2GI6A5-3E8-5ADI2GI6A16-5A2I2G2I5A10-B26-B2-2CB26-B5-2C459-F342-3A12-3A14-13A2(-4A14-A12D)-4A14-4AJNI4J2NJ4A10-B24-B4-2CB24-B7-2C426-F341-3A14-3A12-15A2(-4A12-2A12DA)-4A12-2J16D2J12-5A10G5A10-B22-B6-2CB22-B9-2C392-2(2B30-)2B276-3A16-3A2(10-17A-4A)10-22A10-2J15A2D3J10-AD3AG10AG3ADA10-2A4-3A4K3A4-2A10-B20-B8-2CB20-B11-2C326-4B28-4B20-6F2-4B28-4B29-2B243-3A18-3A8-19A-4A8-24A8-12A-11A8-3J9A-5A2D4J8-A2D2AG6A-5AG2AD2A9-2A3-A10DA3-2A11-A4-2AKI2GIK2A4-A12-B18-B10-2CB18-B13-2C162-2(E31-)E2-4B25-E2(-6H21-4E)-6H18-7F-6H20-4E2-6H27-4B241-2(3A20-3A6-)2(26A6-)J3D17A4DA7-4AG14AG4A13-A9D4A19-2AKIG2MGIK2A49-B16-B12-2CB16-B15-2C129-E31-E2-4A25-E-6B24-E2(8B20-4E)8B17-7F8B18-5E-8B19-4E3-4B240-3A22-3A4-4A20-4A2(4-5A18-5A)5-6A14-6A7-3AG16AG3A12-A10D5A17-2AKIGM2DMGIK2A81-2(B14-)2CB2C12-B114-4E4B24-3E6B23-2E8B22-2E2(8B18-6E)8B17-7F8B18-4E2-8B19-3E3-6B26-6H26-6B174-3A24-3A2-5A20-5A2(2-6A18-6A)4-6A14-6A7-2AG18AG2A11-A11D6A15-2AKIG2L2A2LGIK2A113-B4-C2OC4-B16-2CB2C2-C2OC4-B23-C2OC28-4C25-SE6B24-S8B23-S9B22-S9B2(17-5E10B)16-7F9B17-4E-10B18-3E3-6B21-2E3-H2B3H26-6B174-2A26-2A2(2-5A20-5A)2-6A18-6A4-4A18-4A7-AGDA16-2AGA10-20A13-2AKIGMLA2PALMGIKDA113-B2-6C2-B20-B2-6C2-B18-2CB8C2-B23-6C21-E2-A8B20-2(E2-A9B19-)E2-A8B2(H17-5E9B)H16-7F8BH17-4E-9BH18-3E3-6B21-2E3-H2B3H26-6B174-2A26-2A2(2-5A20-5A)2-6A18-6A4-JA-A18-A-2A7-G-DA16-2A-Q9-AD17A2DA11-2AKIGMLAP2APALMGIK2A21-2A30-2E30-2A26-3(B8CB22-)B8CB3(18-2ESA10B)18-2ESA2(9BH17-5E)9BH16-7F8BH17-2E3-9BH18-E5-6B26-H2B3H26-6B174-2A26-2A2(2-5A20-5A)2-6A18-6A4-NA-A18-A-AJ7-G-DA16-2A-Q9-AD17A2DA11-AKIGMLAP4APALMGI2A20-4A28-4E28-4A25-3(10C22-)10C4(18-2E2-10B)17-3E14BF14-3E14BF13-7F11BF14-2E2-12B2F21-6B26-H2B3H26-6B28-2B61-4F79-2A26-2A2(2-5A20-5A)2-6A18-6A4-NA-A18-A-AI7-G-DA16-2A-Q9-AD6A6-5A2DA11-KIGMLAP6-PALMGIK19-6A26-6E26-6A23-3(12C20-)12C3(16-3E-12B)16-3E2-10B17-3E14B15-3E14B14-7F11B19-12B3F20-6B26-H2B3H26-6B27-4B28-4C27-C4-C78-2A26-2A2-N4A20-3A2N2-2ND2A20-3A2N2-2ND3A18-4A2N4-JA-A18-A-AI7-G-DA16-2A-Q9-KD6A6-5A2DK11-IGMLAGP6-PGALMGI19-6A25-8E25-6A22-4(14C18-)2(14B18-)14B20-10B21-12BF19-2(11BR20-)12B4F19-6B26-H2B3H2(26-6B)26-6C25-F6-F26-C2-C47-GA26-AG2-G4A20-3ADG2-G2D2A20-3ADG2-2GD3A18-4A2G4-JA-A18-A-AJ7-K-DA16-2A-Q9-ID6A6-5A2DI11-IGML2GP6-P2GLMGI19-6A24-8ECE24-6A22-3(O12CO18-)14C3(18-14B)20-10B19-2E12BF17-2(2E11BR18-)2E12B5F17-3(8B24-)8B25-6C25-F6-F59-2C16-GA26-AG2-G4A20-3ADG2-G2D2A20-3ADG2-2GD3A18-4A2G4-JA-A18-A-AJ7-K-DA16-2A-Q9-ID6A6-5A2DI11-IGML2GP6-P2GLMGI19-6A24-8ECE24-6A22-3(O12CO18-)14C3(18-14B)20-10B19-2E12BF16-3E11BR12-T4-3E11BR7-T4-F5-2E12B5F2-F4-10F8B10F4-F9-8B9-F4-T9-8B9-T14-8B25-6C25-F6-F59-2C16-2A26-2A2-N4A20-3A2N2-2ND2A20-3A2N2-2ND3A18-4A2N4-JA-A18-A-AI7-G-DA16-2A-Q9-KD6A6-5A2DK11-IGMLAGP6-PGALMGI19-6A25-8E25-6A22-4(14C18-)2(14B18-)14B20-10B19-2E12BF16-3E11BR17-3E11BR18-2E12B4F19-6B26-H3B2H2(26-6B)26-6C25-F6-F26-C2-C47-2A26-2A2(2-5A20-5A)2-6A18-6A4-IA-A18-A-AI7-G-DA16-2A-Q9-AD6A6-5A2DA11-KIGMLAP6-PALMGIK19-6A26-6E26-6A23-4(12C20-)2(12B20-)12B21-10B19-3(E14B17-)2E12B3F20-6B26-H3B2H26-6B27-4B28-4C27-C4-C78-2A26-2A2(2-5A20-5A)2-6A18-6A4-IA-A18-A-AJ7-G-DA16-2A-Q9-AD17AD2A11-AKIGMLAP4APALMGIKA20-4A28-4E28-4A25-4(10C22-)3(10B22-)10B20-2(14BF17-)14BF18-12B2F21-6B26-H3B2H26-6B28-2B61-4F79-2A26-2A2(2-5A20-5A)2-6A18-6A4-JA-A18-A-2A7-G-DA16-2A-Q9-AD17AD2A11-2AKIGMLAP2APALMGIK2A21-2A30-2E30-2A26-4(B8CB22-)3(10B22-)9B4(H22-H8B)H24-6B26-H3B2H26-6B174-2A26-2A2(2-5A20-5A)2-6A18-6A4-4A18-4A7-AGDA16-2AGA10-18ADA13-2AKIGMLA2PALMGIK2A113-2(B2-6C2-B20-)B2-6C2-B23-6C25-8B23-2(10B22-)9B2(H22-H8B)H24-R6BH22-H8BH24-6B26-H3B2H26-6B174-3A24-3A2-5A20-5A2(2-6A18-6A)4-6A14-2A3DA7-2AGD16ADG2A11-3A14DA15-2AKIG2L2A2LGIK2A113-B4-C2OC4-B18-B4-C2OC4-B23-C2OC28-4C27-6B25-8B23-2(10B22-)3(H9B22-)H9B24-6B26-H3B2H26-6B175-3A22-3A4-4A20-4A2(4-5A18-5A)5-6A14-2A3DA7-3AG16AG3A12-2A13DA17-2AKIGM2DMGIK2A81-B14-B16-B14-B118-4B27-6B25-5(8B24-)8B25-6B26-6H26-6B176-2(3A20-3A6-)2(26A6-)J21A3DA7-5A14DG4A13-A12DA19-2AKIG2MGIK2A49-B16-B14-B16-B181-4A27-6B25-4(8B24-)8B26-4B242-3A18-3A8-4A-14A-4A8-10A7D7A8-9A2D2-4D7A8-4J7D2-4D4A3J8-A2D2AG5D2-5DG2A2DA9-2A3-A10DA3-2A11-A4-2AKI2GIK2A4-A2(12-B18-B)244-4B27-4(6H26-)6H27-4B243-3A16-3A10-4A-12A-4A10-4A-4A7DA-4A10-8A8D6A10-3J13D4A2J10-AD3AG10DG3ADA10-2A4-3A4K3A4-2A2(10-B20-B)339-3(4B28-)4B29-2B245-3A14-3A12-4A-10A-4A12-4A-3A7D-4A12-4A-2A8D-4A12-2J2DA10D4AJ12-5A10G5A10-B22-B8-B22-B403-2(2B30-)2B278-3A12-3A14-4A-8A-4A14-4A-2A5DA-4A14-4A-A6DA-4A14-4AJNI4JINJ4A10-B24-B6-B24-B435-F343-6AI2GI6A8-3E5-6AI2GI6A5-3E8-6AI2GID-4A16-5A2I2G2I5A10-B26-B4-B26-B466-F344-5AI2GI5A9-3E6-5AI2GI5A6-3E-E7-5AI2GI5A7-E2(2-B28-B)497-F367-3E26-3E528-T3(31-F)31-T271-
