model
size = 20 11 20, scale = 0.05, origin = -y
material 
  colors = A:#630 B:#111
voxels
-------------------- -------------------- -------------------- -------------------- -------------------- -------------------- -------------------- -------------------- BB------------------ BB------------------ -------------------- 
-------------------- -------------------- -------------------- -------------------- -------------------- -------------------- -------------------- -------------------- BAA----------------- BAA----------------- -------------------- 
-------------------- -------------------- -------------------- -------------------- -------------------- -------------------- -------------------- -------------------- -AAA---------------- -AAA---------------- -------------------- 
-------------------- -------------------- -------------------- -------------------- -------------------- -------------------- -------------------- -------------------- --A----------------- --AAA--------------- ---AA--------------- 
-------------------- -------------------- -------------------- -------------------- -------------------- -------------------- -------------------- -------------------- -------------------- ---AAA-------------- ---AAA-------------- 
-------------------- -------------------- -------------------- -------------------- -------------------- -------------------- -------------------- -------------------- -------------------- ----AAA------------- ----AAA------------- 
-------------------- -------------------- -------------------- -------------------- -------------------- -------------------- -------------------- -------------------- -------------------- -----AAA------------ -----AAA------------ 
-------------------- -------------------- -------------------- -------------------- -------------------- -------------------- -------------------- -------------------- -------------------- ------AAAA---------- ------AAA----------- 
-------------------- -------------------- -------------------- -------------------- -------------------- -------------------- -------------------- -------------------- --------AAA--------- -------AAA---------- -------AA----------- 
-------------------- -------------------- -------------------- -------------------- -------------------- -------------------- ---------AA--------- ---------AA--------- --------AAA--------- -------AAA---------- -------------------- 
-------------------- -------------------- -------------------- ------------AAA----- ----------AAAAAA---- ----------AAAAAA---- ---------AAAAAAA---- ---------AAAAAA----- --------AAA--------- -------------------- -------------------- 
-------------------- -------------------- -------------------- -------------AAAAA-- ----------A--AAAAA-- ----------A--AAAAA-- ----------AA-AAAAA-- ----------AAAAAAAA-- -------------------- -------------------- -------------------- 
-------------------- -------------------- --------------AAA--- ----------A-AAAAAAA- ----------A-AAAAAAA- ----------A-AAAAAAA- ----------AAAAAAAAA- ----------AAAAAAAAA- --------------AAA--- -------------------- -------------------- 
-------------------- --------------AAA--- -------------AAAAA-- ----------AAAA---AAA ----------AAAA---AAA ----------AAAA---AAA ----------AAAA---AAA ----------AAAA---AAA -------------A---A-- -------------------- -------------------- 
-------------------- -------------AAAAA-- ------------AAAAAAA- ----------AAA-----AA ----------AAA-----AA ----------AAA-----AA ----------AAA-----AA ----------AAA-----AA ------------A-----A- -------------------- -------------------- 
---------------A---- -------------AAAAA-- ------------AAAAAAA- -----------AA-----AA ----------AAA-----AA ----------AAA-----AA ----------AAA-----AA -----------AA-----AA ------------A-----A- -------------------- -------------------- 
-------------------- -------------AAAAA-- ------------AAAAAAA- -----------AA-----AA -----------AA-----AA -----------AA-----AA -----------AA-----AA -----------AA-----AA ------------A-----A- -------------------- -------------------- 
-------------------- --------------AAA--- -------------AAAAA-- -----------AAA---AAA -----------AAA---AAA -----------AAA---AAA -----------AAA---AAA -----------AAA---AAA -------------A---A-- -------------------- -------------------- 
-------------------- -------------------- --------------AAA--- ------------AAAAAAA- ------------AAAAAAA- ------------AAAAAAA- ------------AAAAAAA- ------------AAAAAAA- --------------AAA--- -------------------- -------------------- 
-------------------- -------------------- -------------------- -------------AAAAA-- -------------AAAAA-- -------------AAAAA-- -------------AAAAA-- -------------AAAAA-- -------------------- -------------------- -------------------- 
