model
size = 27 11 29, scale = 0.05, origin = -y
material 
  colors = A:#00F B:#09F C:#700 D:#D00 E:#066 F:#800 G:#00B H:#033 I:#AAA J:#0F3 K:#001 L:#FF9 M:#060 N:#FC9 O:#F6F P:#FC6 Q:#FCF R:#A00 S:#500 T:#633 U:#600 V:#222 W:#CC6 X:#630 Y:#FF3 Z:#FF6 Aa:#B00 Ab:#FF0 Ac:#60F Ad:#609 Ae:#603 Af:#111 Ag:#010 Ah:#0B0
voxels
- - - - - - - - - - - - - - - - - - - - - - - - - - -   - - - - - - - - - - - - - - - - - - - - - - - - - - -   - - - - - - - - - - - - - - - - - - - - - - - - - - -   - - - - - - - - - - - - - - - - - - - - - - - - - - -   - - - - - - - - - - - - - - - - - - - - - - - - - - -   - - - - - - - - - - - - - - - - - - - - - - - - - - -   - - - - - - - - - - - - - - - - - - - - - - - - - - -   - - - - - - - - - - - - - - - - B - - - - - - - - - -   - - - - - - - - - - - - - - - - - - - - - - - - - - -   - - - - - - - - - - - - - - - - - - - - - - - - - - -   - - - - - - - - - - - - - - - - - - - - - - - - - - -   
- - - - - - - - - - - - - - - - - U - U - - - - - - -   - - - - - - - - - - - - - - - - - F - F - - - - - - -   - - - - - - - - - - - - - - - - - F - F - - - - - - -   - - - - - - - - - - - - - - - - - F - F - - - - - - -   - - - - - - - - - - - - - - - - - F F F - - - - - - -   - - - - - - - - - - - - - - - - - - Ab- - - - - - - -   - - - - - - - - - - - - - - - - - - Ab- B - - - - - -   - - - - - - - - - - - - - - - - B AbAbAbB - B - - - -   - - - - - - - - - - - - - - - - - - B - - - - - - - -   - - - - - - - - - - - - - - - - - A G A - - - - - - -   - - - - - - - - - - - - - - - - - AhAhAh- - - - - - -   
- - - - - - - - - - - - - - - - - - - - - - - Ae- Ae-   - - - - - - - - - - - - - - - - - - - - - - - A - A -   - - - - - - - - - - - - - - - - - - - - - - - A - A -   - - - - - - - - - - - - - - - - - - - - - - - A - A -   - - - - - - - - - - - - - - - - - - - - - - - A A A -   - - - - - - - - - - - - - - - - - - - - - - - - D - -   - - - - - - - - - - - - - - - - - - - - - - - - D - B   - - - - - - - - B - - - - - - - - - - - - - B D D D B   - - - - - - - - - - - - - - - - - - - - - - - - B - -   - - - - - - - - - - - - - - - - - - - - - - - A G A -   - - - - - - - - - - - - - - - - - - - - - - - W W W -   
- - - - - - - - - T - T - - - - - - - - - - - - - - -   - - - - - - - - - A - A - - - - - - - - - - - - - - -   - - - - - - - - - A - A - - - - - - - - - - - - - - -   - - - - - - - - - A - A - - - - - - - - - - - - - - -   - - - - - - - - - A A A - - - - - - - - - - - - - - -   - - - - - - - - - - Q - - - - - - - - - - - - - - - -   - - - - - - - - - - Q - B - - - - - - - - - - - - - -   - - B - - - - - B Q Q Q B - - - I - - - - - - - - - -   - - - - - - - - - - B - - - - - - - - - - - - - - - -   - - - - - - - - - A G A - - - - - - - - - - - - - - -   - - - - - - - - - K K K - - - - - - - - - - - - - - -   
- - - X - X - - - - - - - - - - - M - M - - - - - - -   - - - A - A - - - - - - - - - - - M - M - - - - - - -   - - - A - A - - - - - - - - - - - M - M - - - - - - -   - - - A - A - - - - - - - - - - - M - M - - - - - - -   - - - A A A - - - - - - - - - - - M M M - - - - - - -   - - - - O - - - - - - - - - - - - - P - - - - - - - -   - - - - O - B - - - - - - - - - - - P - I - - - - - -   - - B O O O B - - - - - - - - - I P P P I - - - - - -   - - - - B - - - - - - - - - - - - - I - - - - - - - -   - - - A G A - - - - - - - - - - - A G A - - - - - - -   - - - K K K - - - - - - - - - - - S S S - - - - - - -   
- - - - - - - - - - - - - - - - - - - - - - - - - - -   - - - - - - - - - - - - - - - - - - - - - - - - - - -   - - - - - - - - - - - - - - - - - - - - - - - - - - -   - - - - - - - - - - - - - - - - - - - - - - - - - - -   - - - - - - - - - - - - - - - - - - - - - - - - - - -   - - - - - - - - - - - - - - - - - - - - - - - - - - -   - - - - - - - - - - - - - - - - - - - - - - - - - - -   - - - - - - - - - I - - - - - - - - - - - - - - - - -   - - - - - - - - - - - - - - - - - - - - - - - - - - -   - - - - - - - - - - - - - - - - - - - - - - - - - - -   - - - - - - - - - - - - - - - - - - - - - - - - - - -   
- - - - - - - - - - A - A - - - - - - - - - - - - - -   - - - - - - - - - - A - A - - - - - - - - - - - - - -   - - - - - - - - - - A - A - - - - - - - - - - - - - -   - - - - - - - - - - A - A - - - - - - - - - - - - - -   - - - - - - - - - - A A A - - - - - - - - - - - - - -   - - - - - - - - - - - J - - - - - - - - - - - - - - -   - - - - - - - - - - - J - I - - - - - - - - - - - - -   - - - - - - - - - I J J J I - - - - - - - - - - - - -   - - - - - - - - - - - I - - - - - - - - - - - - - - -   - - - - - - - - - - A G A - - - - - - - - - - - - - -   - - - - - - - - - - F F F - - - - - - - - - - - - - -   
- - - - - - - - - - - - - - - - - - - - - - - - - - -   - - - - - - - - - - - - - - - - - - - - - - - - - - -   - - - - - - - - - - - - - - - - - - - - - - - - - - -   - - - - - - - - - - - - - - - - - - - - - - - - - - -   - - - - - - - - - - - - - - - - - - - - - - - - - - -   - - - - - - - - - - - - - - - - - - - - - - - - - - -   - - - - - - - - - - - - - - - - - - - - - - - - - - -   - - - - - - - - - - - - - - - - - - - - - B - - - - -   - - - - - - - - - - - - - - - - - - - - - - - - - - -   - - - - - - - - - - - - - - - - - - - - - - - - - - -   - - - - - - - - - - - - - - - - - - - - - - - - - - -   
- - - - - - - - - - - - - - - - - - - - - - Ae- Ae- -   - - - - - - - - - - - - - - - - - - - - - - C - C - -   - - - - - - - - - - - - - - - - - - - - - - C - C - -   - - - - - - - - - - - - - - - - - - - - - - C - C - -   - - - - - - - - - - - - - - - - - - - - - - C C C - -   - - - - - - - - - - - - - - - - - - - - - - - Q - - -   - - - - - - - - - - - - - - - - - - - - - - - Q - B -   B - - - - - - - - - - - - - - - - - - - - I Q Q Q B -   - - - - - - - - - - - - - - - - - - - - - - - B - - -   - - - - - - - - - - - - - - - - - - - - - - A G A - -   - - - - - - - - - - - - - - - - - - - - - - AgAgAg- -   
- Ad- Ad- - - - - - - - - - - - - - - - - - - - - - -   - H - H - - - - - - - - - - - - - - - - - - - - - - -   - H - H - - - - - - - - - - - - - - - - - - - - - - -   - H - H - - - - - - - - - - - - - - - - - - - - - - -   - H H H - - - - - - - - - - - - - - - - - - - - - - -   - - L - - - - - - - - - - - - - - - - - - - - - - - -   - - L - I - - - - - - - - - - - - - - - - - - - - - -   B L L L B - - - - B - - - - - B - - - - - - - - - - -   - - B - - - - - - - - - - - - - - - - - - - - - - - -   - A G A - - - - - - - - - - - - - - - - - - - - - - -   - C C C - - - - - - - - - - - - - - - - - - - - - - -   
- - - - - - - - - - U - U - - - X - X - - - - - - - -   - - - - - - - - - - A - A - - - F - F - - - - - - - -   - - - - - - - - - - A - A - - - F - F - - - - - - - -   - - - - - - - - - - A - A - - - F - F - - - - - - - -   - - - - - - - - - - A A A - - - F L F - - - - - - - -   - - - - - - - - - - - J - - - - - L - - - - - - - - -   - - - - - - - - - - - J - B - - - L - B - - - - - - -   - - - - - - - - - B J J J B - B L L L B - - - - - - -   - - - - - - - - - - - B - - - - - B - - - - - - - - -   - - - - - - - - - - A G A - - - A G A - - - - - - - -   - - - - - - - - - - W W W - - - C C C - - - - - - - -   
- - - - - - - - - - - - - - - - - - - - - - - - - - -   - - - - - - - - - - - - - - - - - - - - - - - - - - -   - - - - - - - - - - - - - - - - - - - - - - - - - - -   - - - - - - - - - - - - - - - - - - - - - - - - - - -   - - - - - - - - - - - - - - - - - - - - - - - - - - -   - - - - - - - - - - - - - - - - - - - - - - - - - - -   - - - - - - - - - - - - - - - - - - - - - - - - - - -   - - B - - - - - - - - - - - - - - - - - - - - - - - -   - - - - - - - - - - - - - - - - - - - - - - - - - - -   - - - - - - - - - - - - - - - - - - - - - - - - - - -   - - - - - - - - - - - - - - - - - - - - - - - - - - -   
- - - E - E - - - - - - - - - - - - - - - - - - - - -   - - - E - E - - - - - - - - - - - - - - - - - - - - -   - - - E - E - - - - - - - - - - - - - - - - - - - - -   - - - E - E - - - - - - - - - - - - - - - - - - - - -   - - - E E E - - - - - - - - - - - - - - - - - - - - -   - - - - Aa- - - - - - - - - - - - - - - - - - - - - -   - - - - Aa- I - - - - - - - - - - - - - - - - - - - -   - - B AaAaAaB - B - - - - - - - - - - B - - - - - - -   - - - - B - - - - - - - - - - - - - - - - - - - - - -   - - - A G A - - - - - - - - - - - - - - - - - - - - -   - - - S S S - - - - - - - - - - - - - - - - - - - - -   
- - - - - - - - - C - C - - - - - - - - X - X - - - -   - - - - - - - - - C - C - - - - - - - - A - A - - - -   - - - - - - - - - C - C - - - - - - - - A - A - - - -   - - - - - - - - - C - C - - - - - - - - A - A - - - -   - - - - - - - - - C C C - - - - - - - - A A A - - - -   - - - - - - - - - - Z - - - - - - - - - - N - - - - -   - - - - - - - - - - Z - I - - - - - - - - N - B - - -   - - - - - - - - B Z Z Z I - - - - - - B N N N B - - -   - - - - - - - - - - B - - - - - - - - - - B - - - - -   - - - - - - - - - A G A - - - - - - - - A G A - - - -   - - - - - - - - - K K K - - - - - - - - V V V - - - -   
- - - - - - - - - - - - - - - - - - - - - - - - - - -   - - - - - - - - - - - - - - - - - - - - - - - - - - -   - - - - - - - - - - - - - - - - - - - - - - - - - - -   - - - - - - - - - - - - - - - - - - - - - - - - - - -   - - - - - - - - - - - - - - - - - - - - - - - - - - -   - - - - - - - - - - - - - - - - - - - - - - - - - - -   - - - - - - - - - - - - - - - - - - - - - - - - - - -   - - - - - - - - - - - - - - - - - - - - - - - - - - -   - - - - - - - - - - - - - - - - - - - - - - - - - - -   - - - - - - - - - - - - - - - - - - - - - - - - - - -   - - - - - - - - - - - - - - - - - - - - - - - - - - -   
- - - - - - - - - - - - - - - - - - - - - - - - - - -   - - - - - - - - - - - - - - - - - - - - - - - - - - -   - - - - - - - - - - - - - - - - - - - - - - - - - - -   - - - - - - - - - - - - - - - - - - - - - - - - - - -   - - - - - - - - - - - - - - - - - - - - - - - - - - -   - - - - - - - - - - - - - - - - - - - - - - - - - - -   - - - - - - - - - - - - - - - - - - - - - - - - - - -   - - - - - - - - - - - - - - - - - - - - - - - - - - -   - - - - - - - - - - - - - - - - - - - - - - - - - - -   - - - - - - - - - - - - - - - - - - - - - - - - - - -   - - - - - - - - - - - - - - - - - - - - - - - - - - -   
- - - - - - - - - - - - - - - - - - - - - - - - - - -   - - - - - - - - - - - - - - - - - - - - - - - - - - -   - - - - - - - - - - - - - - - - - - - - - - - - - - -   - - - - - - - - - - - - - - - - - - - - - - - - - - -   - - - - - - - - - - - - - - - - - - - - - - - - - - -   - - - - - - - - - - - - - - - - - - - - - - - - - - -   - - - - - - - - - - - - - - - - - - - - - - - - - - -   - - - - - - - - - - - - - B - - - - - - - - - - - - -   - - - - - - - - - - - - - - - - - - - - - - - - - - -   - - - - - - - - - - - - - - - - - - - - - - - - - - -   - - - - - - - - - - - - - - - - - - - - - - - - - - -   
- - - - - - - - - - - - - - Ad- Ad- - - - - - - - - -   - - - - - - - - - - - - - - H - H - - - - - - - - - -   - - - - - - - - - - - - - - H - H - - - - - - - - - -   - - - - - - - - - - - - - - H - H - - - - - - - - - -   - - - - - - - - - - - - - - H H H - - - - - - - - - -   - - - - - - - - - - - - - - - O - - - - - - - - - - -   - - - - - - - - - - - - - - - O - B - - - - - - - - -   - - - B - - - - - - - - - B O O O B - - - - - - - - -   - - - - - - - - - - - - - - - B - - - - - - - - - - -   - - - - - - - - - - - - - - A G A - - - - - - - - - -   - - - - - - - - - - - - - - AfAfAf- - - - - - - - - -   
- - - - T - T - - - - - - - - - - - - - - - - - - - -   - - - - Ac- Ac- - - - - - - - - - - - - - - - - - - -   - - - - D - D - - - - - - - - - - - - - - - - - - - -   - - - - D - D - - - - - - - - - - - - - - - - - - - -   - - - - D D D - - - - - - - - - - - - - - - - - - - -   - - - - - J - - - - - - - - - - - - - - - - - - - - -   - - - - - J - B - - - - - - - - - - - - - - - - - - -   - - - B J J J B - - - - - - - - - - - - - - - - - - -   - - - - - B - - - - - - - - - - - - - - - - - - - - -   - - - - A G A - - - - - - - - - - - - - - - - - - - -   - - - - V V V - - - - - - - - - - - - - - - - - - - -   
- - - - - - - - - - - - - - - - - - - - - - - - - - -   - - - - - - - - - - - - - - - - - - - - - - - - - - -   - - - - - - - - - - - - - - - - - - - - - - - - - - -   - - - - - - - - - - - - - - - - - - - - - - - - - - -   - - - - - - - - - - - - - - - - - - - - - - - - - - -   - - - - - - - - - - - - - - - - - - - - - - - - - - -   - - - - - - - - - - - - - - - - - - - - - - - - - - -   - - - - - - - - - - - - - - - - - - - - - - - - - - -   - - - - - - - - - - - - - - - - - - - - - - - - - - -   - - - - - - - - - - - - - - - - - - - - - - - - - - -   - - - - - - - - - - - - - - - - - - - - - - - - - - -   
- - - - - - - - - - - - - - - - - - - - - - - - - - -   - - - - - - - - - - - - - - - - - - - - - - - - - - -   - - - - - - - - - - - - - - - - - - - - - - - - - - -   - - - - - - - - - - - - - - - - - - - - - - - - - - -   - - - - - - - - - - - - - - - - - - - - - - - - - - -   - - - - - - - - - - - - - - - - - - - - - - - - - - -   - - - - - - - - - - - - - - - - - - - - - - - - - - -   - - - - - - - - - - - - - - - I - - - - - - - - - - -   - - - - - - - - - - - - - - - - - - - - - - - - - - -   - - - - - - - - - - - - - - - - - - - - - - - - - - -   - - - - - - - - - - - - - - - - - - - - - - - - - - -   
- - - - - - - - - - - - - - - - Ac- Ac- - - - - - - -   - - - - - - - - - - - - - - - - C - C - - - - - - - -   - - - - - - - - - - - - - - - - C - C - - - - - - - -   - - - - - - - - - - - - - - - - C - C - - - - - - - -   - - - - - - - - - - - - - - - - C C C - - - - - - - -   - - - - - - - - - - - - - - - - - P - - - - - - - - -   - - - - - - - - - - - - - - - - - P - B - - - - - - -   - - - - - - - - - - - - - - - I P P P B - - - - - - -   - - - - - - - - - - - - - - - - - B - - - - - - - - -   - - - - - - - - - - - - - - - - A G A - - - - - - - -   - - - - - - - - - - - - - - - - K K K - - - - - - - -   
- - - - - - - - - - - - - - - - - - - - - - - - - - -   - - - - - - - - - - - - - - - - - - - - - - - - - - -   - - - - - - - - - - - - - - - - - - - - - - - - - - -   - - - - - - - - - - - - - - - - - - - - - - - - - - -   - - - - - - - - - - - - - - - - - - - - - - - - - - -   - - - - - - - - - - - - - - - - - - - - - - - - - - -   - - - - - - - - - - - - - - - - - - - - - - - - - - -   - - - - - - - - - - - - - - - - - - - - - - B - - - -   - - - - - - - - - - - - - - - - - - - - - - - - - - -   - - - - - - - - - - - - - - - - - - - - - - - - - - -   - - - - - - - - - - - - - - - - - - - - - - - - - - -   
- - - - - - - - - - - - - - - - - - - - - - - T - T -   - - - - - - - - - - - - - - - - - - - - - - - A - A -   - - - - - - - - - - - - - - - - - - - - - - - A - A -   - - - - - - - - - - - - - - - - - - - - - - - A - A -   - - - - - - - - - - - - - - - - - - - - - - - A A A -   - - - - - - - - - - - - - - - - - - - - - - - - Y - -   - - - - - - - - - - - - - - - - - - - - - - - - Y - B   - - - - - - - - - - - - - - - - - - - - - - B Y Y Y B   - - - - - - - - - - - - - - - - - - - - - - - - B - -   - - - - - - - - - - - - - - - - - - - - - - - A G A -   - - - - - - - - - - - - - - - - - - - - - - - D D D -   
- - - - - - - - - - - - - - - - - - - - - - - - - - -   - - - - - - - - - - - - - - - - - - - - - - - - - - -   - - - - - - - - - - - - - - - - - - - - - - - - - - -   - - - - - - - - - - - - - - - - - - - - - - - - - - -   - - - - - - - - - - - - - - - - - - - - - - - - - - -   - - - - - - - - - - - - - - - - - - - - - - - - - - -   - - - - - - - - - - - - - - - - - - - - - - - - - - -   - - - - - - - - - B - - - - - - - - - - - - - - - - -   - - - - - - - - - - - - - - - - - - - - - - - - - - -   - - - - - - - - - - - - - - - - - - - - - - - - - - -   - - - - - - - - - - - - - - - - - - - - - - - - - - -   
- - - - - - - - - - U - U - - - - - - - - - - - - - -   - - - - - - - - - - R - R - - - - - - - - - - - - - -   - - - - - - - - - - R - R - - - - - - - - - - - - - -   - - - - - - - - - - R - R - - - - - - - - - - - - - -   - - - - - - - - - - R R R - - - - - - - - - - - - - -   - - - - - - - - - - - N - - - - - - - - - - - - - - -   - - - - - - - - - - - N - B - - - - - - - - - - - - -   - - - - - - - - - B N N N B - - - - - - - - - - - - -   - - - - - - - - - - - B - - - - - - - - - - - - - - -   - - - - - - - - - - A G A - - - - - - - - - - - - - -   - - - - - - - - - - S S S - - - - - - - - - - - - - -   
- - - - - - - - - - - - - - - - - - - - - - - - - - -   - - - - - - - - - - - - - - - - - - - - - - - - - - -   - - - - - - - - - - - - - - - - - - - - - - - - - - -   - - - - - - - - - - - - - - - - - - - - - - - - - - -   - - - - - - - - - - - - - - - - - - - - - - - - - - -   - - - - - - - - - - - - - - - - - - - - - - - - - - -   - - - - - - - - - - - - - - - - - - - - - - - - - - -   - - - - - - - - - - - - - - - - - - - - - - - - - - -   - - - - - - - - - - - - - - - - - - - - - - - - - - -   - - - - - - - - - - - - - - - - - - - - - - - - - - -   - - - - - - - - - - - - - - - - - - - - - - - - - - -   
- - - - - - - - - - - - - - - - - - - - - - - - - - -   - - - - - - - - - - - - - - - - - - - - - - - - - - -   - - - - - - - - - - - - - - - - - - - - - - - - - - -   - - - - - - - - - - - - - - - - - - - - - - - - - - -   - - - - - - - - - - - - - - - - - - - - - - - - - - -   - - - - - - - - - - - - - - - - - - - - - - - - - - -   - - - - - - - - - - - - - - - - - - - - - - - - - - -   - - - - - - - - - - - - - - - - - B - - - - - - - - -   - - - - - - - - - - - - - - - - - - - - - - - - - - -   - - - - - - - - - - - - - - - - - - - - - - - - - - -   - - - - - - - - - - - - - - - - - - - - - - - - - - -   
- - - - - - - - - - - - - - - - - - E - E - - - - - -   - - - - - - - - - - - - - - - - - - T - T - - - - - -   - - - - - - - - - - - - - - - - - - E - E - - - - - -   - - - - - - - - - - - - - - - - - - E - E - - - - - -   - - - - - - - - - - - - - - - - - - E E E - - - - - -   - - - - - - - - - - - - - - - - - - - D - - - - - - -   - - - - - - - - - - - - - - - - - - - D - B - - - - -   - - - - - - - - - - - - - - - - - B D D D B - - - - -   - - - - - - - - - - - - - - - - - - - B - - - - - - -   - - - - - - - - - - - - - - - - - - A G A - - - - - -   - - - - - - - - - - - - - - - - - - C C C - - - - - -   
