model
size = 18 18 19, scale = 0.05, origin = -y
material 
  colors = A:#C31518
voxels
------------------ ------------------ ------------------ ------------------ --------------A--- --------------A--- --------------A--- --------------A--- --------------A--- --------------A--- ------------------ ------------------ ------------------ ------------------ ------------------ ------------------ ------------------ ------------------ 
--------------A--- --------------A--- --------------A--- --------------A--- --------------A--- ------------------ ------------------ ------------------ ------------------ -------------A---- -------------A---- -------------A---- -------------A---- -------------A---- -------------A---- -------------AAA-- ------AAAAAA--AA-- ------------------ 
----------------A- ----------------A- ----------------A- ----------------A- ----------------A- ----------------AA -----------------A -----------------A -----------------A -----------------A -----------------A ----------------AA ----------------A- ----------------A- --------------AAA- ------AAAAAA--AAA- ----AAAAAAAAAAAAA- ------AAAAAA--AA-- 
------------------ ------------------ ------------------ ------------------ ------------------ ------------------ ------------------ ------------------ ------------------ ------------------ ------------------ ------------------ ------------------ ------------------ --------------AA-- ----AA------AAAAA- ---AAA------AAAAA- ----AA------AAAA-- 
------------------ ------------------ ------------------ ------------------ ------------------ ------------------ ------------------ ------------------ ------------------ ------------------ ------------------ ------------------ ------------------ ------------------ ------------------ ---A----------A--- --AA----------AA-- ---A----------A--- 
------------------ ------------------ ------------------ ------------------ ------------------ ------------------ ------------------ ------------------ ------------------ ------------------ ------------------ ------------------ ------------------ ------------------ ------------------ --A------------A-- -AA------------AA- --A------------A-- 
------------------ ------------------ ------------------ ------------------ ------------------ ------------------ ------------------ ------------------ ------------------ ------------------ ------------------ ------------------ ------------------ ------------------ ------------------ --A------------A-- -AA------------AA- --A------------A-- 
------------------ ------------------ ------------------ ------------------ ------------------ ------------------ ------------------ ------------------ ------------------ ------------------ ------------------ ------------------ ------------------ ------------------ ------------------ -A--------------A- AA--------------AA -A--------------A- 
------------------ ------------------ ------------------ ------------------ ------------------ ------------------ ------------------ ------------------ ------------------ ------------------ ------------------ ------------------ ------------------ ------------------ ------------------ -A--------------A- AA--------------AA -A--------------A- 
------------------ ------------------ ------------------ ------------------ ------------------ ------------------ ------------------ ------------------ ------------------ ------------------ ------------------ ------------------ ------------------ ------------------ ------------------ -A--------------A- AA--------------AA -A--------------A- 
------------------ ------------------ ------------------ ------------------ ------------------ ------------------ ------------------ ------------------ ------------------ ------------------ ------------------ ------------------ ------------------ ------------------ ------------------ -A--------------A- AA--------------AA -A--------------A- 
------------------ ------------------ ------------------ ------------------ ------------------ ------------------ ------------------ ------------------ ------------------ ------------------ ------------------ ------------------ ------------------ ------------------ ------------------ -A--------------A- AA--------------AA -A--------------A- 
------------------ ------------------ ------------------ ------------------ ------------------ ------------------ ------------------ ------------------ ------------------ ------------------ ------------------ ------------------ ------------------ ------------------ ------------------ -A--------------A- AA--------------AA -A--------------A- 
------------------ ------------------ ------------------ ------------------ ------------------ ------------------ ------------------ ------------------ ------------------ ------------------ ------------------ ------------------ ------------------ ------------------ ------------------ --A------------A-- -AA------------AA- --A------------A-- 
------------------ ------------------ ------------------ ------------------ ------------------ ------------------ ------------------ ------------------ ------------------ ------------------ ------------------ ------------------ ------------------ ------------------ ------------------ --A------------A-- -AA------------AA- --A------------A-- 
------------------ ------------------ ------------------ ------------------ ------------------ ------------------ ------------------ ------------------ ------------------ ------------------ ------------------ ------------------ ------------------ ------------------ ------------------ ---A----------A--- --AA----------AA-- ---A----------A--- 
------------------ ------------------ ------------------ ------------------ ------------------ ------------------ ------------------ ------------------ ------------------ ------------------ ------------------ ------------------ ------------------ ------------------ ------------------ ----AA------AA---- ---AAA------AAA--- ----AA------AA---- 
------------------ ------------------ ------------------ ------------------ ------------------ ------------------ ------------------ ------------------ ------------------ ------------------ ------------------ ------------------ ------------------ ------------------ ------------------ ------AAAAAA------ ----AAAAAAAAAA---- ------AAAAAA------ 
------------------ ------------------ ------------------ ------------------ ------------------ ------------------ ------------------ ------------------ ------------------ ------------------ ------------------ ------------------ ------------------ ------------------ ------------------ ------------------ ------AAAAAA------ ------------------ 
