model
size = 30 20 31, scale = 0.05, origin = -y
material 
  colors = A:#04003E B:#EBD15F C:#A7CFDA D:#A0883A E:#FFF F:#248369 G:#B32121
voxels
------------------------------ ------------------------------ ------------------------------ ------------------------------ ------------------------------ ------------------------------ --------------CE-------------- ------------CCCEEC------------ ------------CCCEEC------------ -----------CCCECCCE----------- -----------CCEEECCE----------- ------------CEEECC------------ ------------EECCCC------------ --------------CC-------------- ------------------------------ ------------------------------ ------------------------------ ------------------------------ ------------------------------ ------------------------------ 
------------------------------ ------------------------------ ------------------------------ ------------------------------ ------------FFFFFF------------ ----------FFBBBBBBFF---------- ----------BBBCBBCBBB---------- ---------BBBBBBBBBBBB--------- ---------BBCBBBBBBCBB--------- ---------DBBBBBBBBBBD--------- ---------BBBBBBBBBBBB--------- ---------DBCBBBBBBCBD--------- ---------BBBBBBBBBBBB--------- ----------BBBCBBCBBB---------- ----------BBBBBBBBBB---------- ------------BBBBBB------------ ------------------------------ ------------------------------ ------------------------------ ------------------------------ 
------------------------------ ------------------------------ ------------BBBBBB------------ ----------BBBBBBBBBB---------- --------BBBBBBBBBBBBBB-------- --------BBBBBBBBBBBBBB-------- --------BDBBBBBBBBBBDB-------- -------BBBBBBBBBBBBBBBB------- -------BDBBBBBBBBBBBBDB------- -------DBBBBBBBBBBBBBBD------- -------BDBBBBBBBBBBBBDB------- -------DBBBBBBBBBBBBBBD------- -------BDBBBBBBBBBBBBDB------- --------BDBBBBBBBBBBDB-------- --------BDBBBBBBBBBBDB-------- --------BBDDBBBBBBDDBB-------- ----------BBBBBBBBBB---------- ------------BBBBBB------------ ------------------------------ ------------------------------ 
-------------AAAA------------- ----------AAAAAAAAAA---------- --------AAAAAAAAAAAAAA-------- --------AAAAAAAAAAAAAA-------- --------AAAAAAAAAAAAAA-------- -------BAAAAAAAAAAAAAAB------- ------BBAAAAAAAAAAAAAABB------ ------BBAAAAAAAAAAAAAABB------ ------BBAAAAAAAAAAAAAABB------ ------BBAAAAAAAAAAAAAABB------ ------BBAAAAAAAAAAAAAABB------ ------BBAAAAAAAAAAAAAABB------ ------BBAAAAAAAAAAAAAABB------ ------BBAAAAAAAAAAAAAABB------ -------BAAAAAAAAAAAAAAB------- --------AAAAAAAAAAAAAA-------- --------AAAAAAAAAAAAAA-------- --------AAAAAAAAAAAAAA-------- ----------AAAAAAAAAA---------- -------------AAAA------------- 
------------------------------ ------------------------------ ------------------------------ -------AA------------AA------- ------AAA------------AAA------ ------AAA------------AAA------ ------AAA------------AAA------ -----BAAA------------AAAB----- -----BAAA------------AAAB----- -----BAAA------------AAAB----- -----BAAA------------AAAB----- -----BAAA------------AAAB----- -----BAAA------------AAAB----- ------AAA------------AAA------ ------AAA------------AAA------ ------AAA------------AAA------ -------AA------------AA------- ------------------------------ ------------------------------ ------------------------------ 
------------------------------ ------------------------------ ------------------------------ ------------------------------ ------------------------------ -----A------------------A----- -----A------------------A----- -----A------------------A----- -----A------------------A----- -----A------------------A----- -----A------------------A----- -----A------------------A----- -----A------------------A----- -----A------------------A----- -----A------------------A----- ------------------------------ ------------------------------ ------------------------------ ------------------------------ ------------------------------ 
------------------------------ ------------------------------ ------------------------------ ------------------------------ ------------------------------ ----A--------------------A---- ----A--------------------A---- ----A--------------------A---- ---BA--------------------AB--- ---BA--------------------AB--- ---BA--------------------AB--- ---BA--------------------AB--- ----A--------------------A---- ----A--------------------A---- ----A--------------------A---- ------------------------------ ------------------------------ ------------------------------ ------------------------------ ------------------------------ 
------------------------------ ------------------------------ ------------------------------ ------------------------------ ------------------------------ ---A----------------------A--- ---A----------------------A--- --BA----------------------AB-- --FA----------------------AF-- --FA----------------------AF-- --FA----------------------AF-- --FA----------------------AF-- --BA----------------------AB-- ---A----------------------A--- ---A----------------------A--- ------------------------------ ------------------------------ ------------------------------ ------------------------------ ------------------------------ 
------------------------------ ------------------------------ ------------------------------ ------------------------------ ------------------------------ --A------------------------A-- -BA------------------------AB- -DA------------------------AD- -EA------------------------AE- -EA------------------------AE- -EA------------------------AE- -EA------------------------AE- -DA------------------------AD- -BA------------------------AB- --A------------------------A-- ------------------------------ ------------------------------ ------------------------------ ------------------------------ ------------------------------ 
------------------------------ ------------------------------ ------------------------------ ------------------------------ ------------------------------ --A------------------------A-- -BA------------------------AB- -DA------------------------AD- -EA------------------------AE- -EA------------------------AE- -EA------------------------AE- -EA------------------------AE- -DA------------------------AD- -BA------------------------AB- --A------------------------A-- ------------------------------ ------------------------------ ------------------------------ ------------------------------ ------------------------------ 
------------------------------ ------------------------------ ------------------------------ ------------------------------ ------------------------------ -A--------------------------A- -A--------------------------A- BA--------------------------AB GA--------------------------AG GA--------------------------AG GA--------------------------AG GA--------------------------AG BA--------------------------AB -A--------------------------A- -A--------------------------A- ------------------------------ ------------------------------ ------------------------------ ------------------------------ ------------------------------ 
------------------------------ ------------------------------ ------------------------------ ------------------------------ ------------------------------ -A--------------------------A- -A--------------------------A- -A--------------------------A- BA--------------------------AB BA--------------------------AB BA--------------------------AB BA--------------------------AB -A--------------------------A- -A--------------------------A- -A--------------------------A- ------------------------------ ------------------------------ ------------------------------ ------------------------------ ------------------------------ 
------------------------------ ------------------------------ ------------------------------ ------------------------------ ------------------------------ -A--------------------------A- -A--------------------------A- -A--------------------------A- -A--------------------------A- -A--------------------------A- -A--------------------------A- -A--------------------------A- -A--------------------------A- -A--------------------------A- -A--------------------------A- ------------------------------ ------------------------------ ------------------------------ ------------------------------ ------------------------------ 
------------------------------ ------------------------------ ------------------------------ ------------------------------ ------------------------------ A----------------------------A A----------------------------A A----------------------------A A----------------------------A A----------------------------A A----------------------------A A----------------------------A A----------------------------A A----------------------------A A----------------------------A ------------------------------ ------------------------------ ------------------------------ ------------------------------ ------------------------------ 
------------------------------ ------------------------------ ------------------------------ ------------------------------ ------------------------------ A----------------------------A A----------------------------A A----------------------------A A----------------------------A A----------------------------A A----------------------------A A----------------------------A A----------------------------A A----------------------------A A----------------------------A ------------------------------ ------------------------------ ------------------------------ ------------------------------ ------------------------------ 
------------------------------ ------------------------------ ------------------------------ ------------------------------ ------------------------------ A----------------------------A A----------------------------A A----------------------------A A----------------------------A A----------------------------A A----------------------------A A----------------------------A A----------------------------A A----------------------------A A----------------------------A ------------------------------ ------------------------------ ------------------------------ ------------------------------ ------------------------------ 
------------------------------ ------------------------------ ------------------------------ ------------------------------ ------------------------------ A----------------------------A A----------------------------A A----------------------------A A----------------------------A A----------------------------A A----------------------------A A----------------------------A A----------------------------A A----------------------------A A----------------------------A ------------------------------ ------------------------------ ------------------------------ ------------------------------ ------------------------------ 
------------------------------ ------------------------------ ------------------------------ ------------------------------ ------------------------------ A----------------------------A A----------------------------A A----------------------------A A----------------------------A A----------------------------A A----------------------------A A----------------------------A A----------------------------A A----------------------------A A----------------------------A ------------------------------ ------------------------------ ------------------------------ ------------------------------ ------------------------------ 
------------------------------ ------------------------------ ------------------------------ ------------------------------ ------------------------------ A----------------------------A A----------------------------A A----------------------------A A----------------------------A A----------------------------A A----------------------------A A----------------------------A A----------------------------A A----------------------------A A----------------------------A ------------------------------ ------------------------------ ------------------------------ ------------------------------ ------------------------------ 
------------------------------ ------------------------------ ------------------------------ ------------------------------ ------------------------------ A----------------------------A A----------------------------A A----------------------------A A----------------------------A A----------------------------A A----------------------------A A----------------------------A A----------------------------A A----------------------------A A----------------------------A ------------------------------ ------------------------------ ------------------------------ ------------------------------ ------------------------------ 
------------------------------ ------------------------------ ------------------------------ ------------------------------ ------------------------------ A----------------------------A A----------------------------A A----------------------------A A----------------------------A A----------------------------A A----------------------------A A----------------------------A A----------------------------A A----------------------------A A----------------------------A ------------------------------ ------------------------------ ------------------------------ ------------------------------ ------------------------------ 
------------------------------ ------------------------------ ------------------------------ ------------------------------ ------------------------------ -A--------------------------A- -A--------------------------A- -A--------------------------A- -A--------------------------A- -A--------------------------A- -A--------------------------A- -A--------------------------A- -A--------------------------A- -A--------------------------A- -A--------------------------A- ------------------------------ ------------------------------ ------------------------------ ------------------------------ ------------------------------ 
------------------------------ ------------------------------ ------------------------------ ------------------------------ ------------------------------ -A--------------------------A- -A--------------------------A- -A--------------------------A- -A--------------------------A- -A--------------------------A- -A--------------------------A- -A--------------------------A- -A--------------------------A- -A--------------------------A- -A--------------------------A- ------------------------------ ------------------------------ ------------------------------ ------------------------------ ------------------------------ 
------------------------------ ------------------------------ ------------------------------ ------------------------------ ------------------------------ --A------------------------A-- --A------------------------A-- --A------------------------A-- --A------------------------A-- --A------------------------A-- --A------------------------A-- --A------------------------A-- --A------------------------A-- --A------------------------A-- --A------------------------A-- ------------------------------ ------------------------------ ------------------------------ ------------------------------ ------------------------------ 
------------------------------ ------------------------------ ------------------------------ ------------------------------ ------------------------------ --A------------------------A-- --A------------------------A-- --A------------------------A-- --A------------------------A-- --A------------------------A-- --A------------------------A-- --A------------------------A-- --A------------------------A-- --A------------------------A-- --A------------------------A-- ------------------------------ ------------------------------ ------------------------------ ------------------------------ ------------------------------ 
------------------------------ ------------------------------ ------------------------------ ------------------------------ ------------------------------ ---A----------------------A--- ---A----------------------A--- ---A----------------------A--- ---A----------------------A--- ---A----------------------A--- ---A----------------------A--- ---A----------------------A--- ---A----------------------A--- ---A----------------------A--- ---A----------------------A--- ------------------------------ ------------------------------ ------------------------------ ------------------------------ ------------------------------ 
------------------------------ ------------------------------ ------------------------------ ------------------------------ ------------------------------ ----A--------------------A---- ----A--------------------A---- ----A--------------------A---- ----A--------------------A---- ----A--------------------A---- ----A--------------------A---- ----A--------------------A---- ----A--------------------A---- ----A--------------------A---- ----A--------------------A---- ------------------------------ ------------------------------ ------------------------------ ------------------------------ ------------------------------ 
------------------------------ ------------------------------ ------------------------------ ------------------------------ ------------------------------ -----A------------------A----- -----A------------------A----- -----A------------------A----- -----A------------------A----- -----A------------------A----- -----A------------------A----- -----A------------------A----- -----A------------------A----- -----A------------------A----- -----A------------------A----- ------------------------------ ------------------------------ ------------------------------ ------------------------------ ------------------------------ 
------------------------------ ------------------------------ ------------------------------ ------------------------------ ------------------------------ ------AA--------------AA------ ------AA--------------AA------ ------AA--------------AA------ ------AA--------------AA------ ------AA--------------AA------ ------AA--------------AA------ ------AA--------------AA------ ------AA--------------AA------ ------AA--------------AA------ ------AA--------------AA------ ------------------------------ ------------------------------ ------------------------------ ------------------------------ ------------------------------ 
------------------------------ ------------------------------ ------------------------------ ------------------------------ ------------------------------ --------AA----------AA-------- --------AA----------AA-------- --------AA----------AA-------- --------AA----------AA-------- --------AA----------AA-------- --------AA----------AA-------- --------AA----------AA-------- --------AA----------AA-------- --------AA----------AA-------- --------AA----------AA-------- ------------------------------ ------------------------------ ------------------------------ ------------------------------ ------------------------------ 
------------------------------ ------------------------------ ------------------------------ ------------------------------ ------------------------------ ----------AAAAAAAAAA---------- ----------AAAAAAAAAA---------- ----------AAAAAAAAAA---------- ----------AAAAAAAAAA---------- ----------AAAAAAAAAA---------- ----------AAAAAAAAAA---------- ----------AAAAAAAAAA---------- ----------AAAAAAAAAA---------- ----------AAAAAAAAAA---------- ----------AAAAAAAAAA---------- ------------------------------ ------------------------------ ------------------------------ ------------------------------ ------------------------------ 
