model
size = 31 22 31, scale = 0.05, origin = -y
material 
  colors = A:#FC0 B:#0F6 C:#F90 D:#F03 E:#F93 F:#F0C G:#99F H:#F63 I:#66F J:#30F K:#CFF L:#3CF M:#0F3
voxels
------------------------------- -------------I-B-I------------- ------------------------------- ------------------------------- ------------------------------- ------------------------------- ------------------------------- ------------------------------- ------------------------------- ------------------------------- ------------------------------- ------------------------------- ------------------------------- ------------------------------- ------------------------------- ------------------------------- ------------------------------- ------------------------------- ------------------------------- ------------------------------- ------------------------------- ------------------------------- 
------------AAAAAAA------------ ------------AAAAAAA------------ ------------AAAAAAA------------ --------------GLG-------------- ---------------G--------------- ------------------------------- --------------FKF-------------- ---------------F--------------- ------------------------------- --------------EBE-------------- ---------------E--------------- ------------------------------- --------------BJB-------------- ---------------B--------------- ------------------------------- ------------------------------- ------------------------------- ------------------------------- ------------------------------- ------------------------------- ------------------------------- ------------------------------- 
---------AAAAAAAAAAAAA--------- ---------DADAAAAAAADAD--------- ---------AAAAAAAAAAAAA--------- ------------AAGLGAA------------ ------------AAAGAAA------------ ------------AAAAAAA------------ ------------AAFKFAA------------ ------------AAAFAAA------------ ------------AAAAAAA------------ -----------CAAEBEAAC----------- ------------AAAEAAA------------ ------------AAAAAAA------------ ------------AABJBAA------------ -------------AABAA------------- --------------AAA-------------- ---------------A--------------- ------------------------------- ------------------------------- ------------------------------- ------------------------------- ------------------------------- ------------------------------- 
-------AAAAA-------AAAAA------- -------DAAAA-------AAAAD------- -------AAAAA-------AAAAA------- ---------AAA-------AAA--------- ---------AAA-------AAA--------- ---------AAA-------AAA--------- ---------AAA-------AAA--------- ---------AAA-------AAA--------- ---------AAA-------AAA--------- ---------CAA-------AAC--------- ----------AA-------AA---------- ------------------------------- ------------------------------- ------------------------------- ------------------------------- ------------------------------- ------------------------------- ------------------------------- ------------------------------- ------------------------------- ------------------------------- ------------------------------- 
------AAAA-----------AAAA------ ------AAAA-----------AAAA------ ------AAAA-----------AAAA------ -------AAA-----------AAA------- -------AAA-----------AAA------- -------AAA-----------AAA------- -------AAA-----------AAA------- -------AAA-----------AAA------- -------AAA-----------AAA------- -------CAA-----------AAC------- --------AA-----------AA-------- ------------------------------- ------------------------------- ------------------------------- ------------------------------- ------------------------------- ------------------------------- ------------------------------- ------------------------------- ------------------------------- ------------------------------- ------------------------------- 
-----AAA---------------AAA----- -----DAA---------------AAD----- -----AAA---------------AAA----- ------AA---------------AA------ ------AA---------------AA------ ------AA---------------AA------ ------AA---------------AA------ ------AA---------------AA------ ------AA---------------AA------ ------CA---------------AC------ -------A---------------A------- ------------------------------- ------------------------------- ------------------------------- ------------------------------- ------------------------------- ------------------------------- ------------------------------- ------------------------------- ------------------------------- ------------------------------- ------------------------------- 
----AAA-----------------AAA---- ----AAA-----------------AAA---- ----AAA-----------------AAA---- -----AA-----------------AA----- -----AA-----------------AA----- -----AA-----------------AA----- -----AA-----------------AA----- -----AA-----------------AA----- -----AA-----------------AA----- -----CA-----------------AC----- ------A-----------------A------ ------------------------------- ------------------------------- ------------------------------- ------------------------------- ------------------------------- ------------------------------- ------------------------------- ------------------------------- ------------------------------- ------------------------------- ------------------------------- 
---AAA-------------------AAA--- ---DAA-------------------AAD--- ---AAA-------------------AAA--- ----AA-------------------AA---- ----AA-------------------AA---- ----AA-------------------AA---- ----AA-------------------AA---- ----AA-------------------AA---- ----AA-------------------AA---- ----CA-------------------AC---- -----A-------------------A----- ------------------------------- ------------------------------- ------------------------------- ------------------------------- ------------------------------- ------------------------------- ------------------------------- ------------------------------- ------------------------------- ------------------------------- ------------------------------- 
---AA---------------------AA--- ---AA---------------------AA--- ---AA---------------------AA--- ----A---------------------A---- ----A---------------------A---- ----A---------------------A---- ----A---------------------A---- ----A---------------------A---- ----A---------------------A---- ----A---------------------A---- ----A---------------------A---- ------------------------------- ------------------------------- ------------------------------- ------------------------------- ------------------------------- ------------------------------- ------------------------------- ------------------------------- ------------------------------- ------------------------------- ------------------------------- 
--AAA---------------------AAA-- --DAA---------------------AAD-- --AAA---------------------AAA-- ---AA---------------------AA--- ---AA---------------------AA--- ---AA---------------------AA--- ---AA---------------------AA--- ---AA---------------------AA--- ---AA---------------------AA--- ---CA---------------------AC--- ----A---------------------A---- ------------------------------- ------------------------------- ------------------------------- ------------------------------- ------------------------------- ------------------------------- ------------------------------- ------------------------------- ------------------------------- ------------------------------- ------------------------------- 
--AA-----------------------AA-- --AA-----------------------AA-- --AA-----------------------AA-- ---A-----------------------A--- ---A-----------------------A--- ---A-----------------------A--- ---A-----------------------A--- ---A-----------------------A--- ---A-----------------------A--- ---A-----------------------A--- ---A-----------------------A--- ------------------------------- ------------------------------- ------------------------------- ------------------------------- ------------------------------- ------------------------------- ------------------------------- ------------------------------- ------------------------------- ------------------------------- ------------------------------- 
--AA-----------------------AA-- --DA-----------------------AD-- --AA-----------------------AA-- ---A-----------------------A--- ---A-----------------------A--- ---A-----------------------A--- ---A-----------------------A--- ---A-----------------------A--- ---A-----------------------A--- --CA-----------------------AC-- ---A-----------------------A--- ------------------------------- ------------------------------- ------------------------------- ------------------------------- ------------------------------- ------------------------------- ------------------------------- ------------------------------- ------------------------------- ------------------------------- ------------------------------- 
-AA-------------------------AA- -AA-------------------------AA- -AA-------------------------AA- --A-------------------------A-- --A-------------------------A-- --A-------------------------A-- --A-------------------------A-- --A-------------------------A-- --A-------------------------A-- --A-------------------------A-- --A-------------------------A-- --A-------------------------A-- --A-------------------------A-- ------------------------------- ------------------------------- ------------------------------- ------------------------------- ------------------------------- ------------------------------- ------------------------------- ------------------------------- ------------------------------- 
-AA-------------------------AA- IAA-------------------------AAI -AA-------------------------AA- --A-------------------------A-- --A-------------------------A-- --A-------------------------A-- --A-------------------------A-- --A-------------------------A-- --A-------------------------A-- --A-------------------------A-- --A-------------------------A-- --A-------------------------A-- --A-------------------------A-- --A-------------------------A-- ------------------------------- ------------------------------- ----------------------------H-- ------------------------------- ------------------------------- ------------------------------- ----------------------------H-- ------------------------------- 
-AA-------------------------AA- -AA-------------------------AA- -AA-------------------------AA- -GG-------------------------GG- --A-------------------------A-- --A-------------------------A-- -FF-------------------------FF- --A-------------------------A-- --A-------------------------A-- -EE-------------------------EE- --A-------------------------A-- --A-------------------------A-- -BB-------------------------BB- --A-------------------------A-- --A-------------------------A-- ----------------------------H-- ----------------------------H-- ----------------------------H-- ----------------------------H-- ----------------------------H-- ----------------------------H-- ----------------------------H-- 
-AA-------------------------AA- MAA-------------------------AAM -AA-------------------------AA- -LL-------------------------LL- -GG-------------------------GG- --A-------------------------A-- -KK-------------------------KK- -FF-------------------------FF- --A-------------------------A-- -BB-------------------------BB- -EE-------------------------EE- --A-------------------------A-- -JJ-------------------------JJ- -BB-------------------------BB- --A-------------------------A-- --A-------------------------A-- ----------------------------H-- ------------------------------- ----------------------------H-- ------------------------------- ----------------------------H-- ------------------------------- 
-AA-------------------------AA- -AA-------------------------AA- -AA-------------------------AA- -GG-------------------------GG- --A-------------------------A-- --A-------------------------A-- -FF-------------------------FF- --A-------------------------A-- --A-------------------------A-- -EE-------------------------EE- --A-------------------------A-- --A-------------------------A-- -BB-------------------------BB- --A-------------------------A-- --A-------------------------A-- ----------------------------H-- ----------------------------H-- ------------------------------- ----------------------------H-- ------------------------------- ----------------------------H-- ----------------------------H-- 
-AA-------------------------AA- IAA-------------------------AAI -AA-------------------------AA- --A-------------------------A-- --A-------------------------A-- --A-------------------------A-- --A-------------------------A-- --A-------------------------A-- --A-------------------------A-- --A-------------------------A-- --A-------------------------A-- --A-------------------------A-- --A-------------------------A-- --A-------------------------A-- ------------------------------- ------------------------------- ----------------------------H-- ----------------------------H-- ------------------------------- ----------------------------H-- ----------------------------H-- ------------------------------- 
-AA-------------------------AA- -AA-------------------------AA- -AA-------------------------AA- --A-------------------------A-- --A-------------------------A-- --A-------------------------A-- --A-------------------------A-- --A-------------------------A-- --A-------------------------A-- --A-------------------------A-- --A-------------------------A-- --A-------------------------A-- --A-------------------------A-- ------------------------------- ------------------------------- ------------------------------- ------------------------------- ------------------------------- ------------------------------- ------------------------------- ------------------------------- ------------------------------- 
--AA-----------------------AA-- --DA-----------------------AD-- --AA-----------------------AA-- ---A-----------------------A--- ---A-----------------------A--- ---A-----------------------A--- ---A-----------------------A--- ---A-----------------------A--- ---A-----------------------A--- --CA-----------------------AC-- ---A-----------------------A--- ------------------------------- ------------------------------- ------------------------------- ------------------------------- ------------------------------- ------------------------------- ------------------------------- ------------------------------- ------------------------------- ------------------------------- ------------------------------- 
--AA-----------------------AA-- --AA-----------------------AA-- --AA-----------------------AA-- ---A-----------------------A--- ---A-----------------------A--- ---A-----------------------A--- ---A-----------------------A--- ---A-----------------------A--- ---A-----------------------A--- ---A-----------------------A--- ---A-----------------------A--- ------------------------------- ------------------------------- ------------------------------- ------------------------------- ------------------------------- ------------------------------- ------------------------------- ------------------------------- ------------------------------- ------------------------------- ------------------------------- 
--AAA---------------------AAA-- --DAA---------------------AAD-- --AAA---------------------AAA-- ---AA---------------------AA--- ---AA---------------------AA--- ---AA---------------------AA--- ---AA---------------------AA--- ---AA---------------------AA--- ---AA---------------------AA--- ---CA---------------------AC--- ----A---------------------A---- ------------------------------- ------------------------------- ------------------------------- ------------------------------- ------------------------------- ------------------------------- ------------------------------- ------------------------------- ------------------------------- ------------------------------- ------------------------------- 
---AA---------------------AA--- ---AA---------------------AA--- ---AA---------------------AA--- ----A---------------------A---- ----A---------------------A---- ----A---------------------A---- ----A---------------------A---- ----A---------------------A---- ----A---------------------A---- ----A---------------------A---- ----A---------------------A---- ------------------------------- ------------------------------- ------------------------------- ------------------------------- ------------------------------- ------------------------------- ------------------------------- ------------------------------- ------------------------------- ------------------------------- ------------------------------- 
---AAA-------------------AAA--- ---DAA-------------------AAD--- ---AAA-------------------AAA--- ----AA-------------------AA---- ----AA-------------------AA---- ----AA-------------------AA---- ----AA-------------------AA---- ----AA-------------------AA---- ----AA-------------------AA---- ----CA-------------------AC---- -----A-------------------A----- ------------------------------- ------------------------------- ------------------------------- ------------------------------- ------------------------------- ------------------------------- ------------------------------- ------------------------------- ------------------------------- ------------------------------- ------------------------------- 
----AAA-----------------AAA---- ----AAA-----------------AAA---- ----AAA-----------------AAA---- -----AA-----------------AA----- -----AA-----------------AA----- -----AA-----------------AA----- -----AA-----------------AA----- -----AA-----------------AA----- -----AA-----------------AA----- -----CA-----------------AC----- ------A-----------------A------ ------------------------------- ------------------------------- ------------------------------- ------------------------------- ------------------------------- ------------------------------- ------------------------------- ------------------------------- ------------------------------- ------------------------------- ------------------------------- 
-----AAA---------------AAA----- -----DAA---------------AAD----- -----AAA---------------AAA----- ------AA---------------AA------ ------AA---------------AA------ ------AA---------------AA------ ------AA---------------AA------ ------AA---------------AA------ ------AA---------------AA------ ------CA---------------AC------ -------A---------------A------- ------------------------------- ------------------------------- ------------------------------- ------------------------------- ------------------------------- ------------------------------- ------------------------------- ------------------------------- ------------------------------- ------------------------------- ------------------------------- 
------AAAA-----------AAAA------ ------AAAA-----------AAAA------ ------AAAA-----------AAAA------ -------AAA-----------AAA------- -------AAA-----------AAA------- -------AAA-----------AAA------- -------AAA-----------AAA------- -------AAA-----------AAA------- -------AAA-----------AAA------- -------CAA-----------AAC------- --------AA-----------AA-------- ------------------------------- ------------------------------- ------------------------------- ------------------------------- ------------------------------- ------------------------------- ------------------------------- ------------------------------- ------------------------------- ------------------------------- ------------------------------- 
-------AAAAA-------AAAAA------- -------DAAAA-------AAAAD------- -------AAAAA-------AAAAA------- ---------AAA-------AAA--------- ---------AAA-------AAA--------- ---------AAA-------AAA--------- ---------AAA-------AAA--------- ---------AAA-------AAA--------- ---------AAA-------AAA--------- ---------CAA-------AAC--------- ----------AA-------AA---------- ------------------------------- ------------------------------- ------------------------------- ------------------------------- ------------------------------- ------------------------------- ------------------------------- ------------------------------- ------------------------------- ------------------------------- ------------------------------- 
---------AAAAAAAAAAAAA--------- ---------DADAAAAAAADAD--------- ---------AAAAAAAAAAAAA--------- ------------AAGLGAA------------ ------------AAAGAAA------------ ------------AAAAAAA------------ ------------AAFKFAA------------ ------------AAAFAAA------------ ------------AAAAAAA------------ -----------CAAEBEAAC----------- ------------AAAEAAA------------ ------------AAAAAAA------------ ------------AABJBAA------------ -------------AABAA------------- --------------AAA-------------- ---------------A--------------- ------------------------------- ------------------------------- ------------------------------- ------------------------------- ------------------------------- ------------------------------- 
------------AAAAAAA------------ ------------AAAAAAA------------ ------------AAAAAAA------------ --------------GLG-------------- ---------------G--------------- ------------------------------- --------------FKF-------------- ---------------F--------------- ------------------------------- --------------EBE-------------- ---------------E--------------- ------------------------------- --------------BJB-------------- ---------------B--------------- ------------------------------- ------------------------------- ------------------------------- ------------------------------- ------------------------------- ------------------------------- ------------------------------- ------------------------------- 
------------------------------- -------------I-M-I------------- ------------------------------- ------------------------------- ------------------------------- ------------------------------- ------------------------------- ------------------------------- ------------------------------- ------------------------------- ------------------------------- ------------------------------- ------------------------------- ------------------------------- ------------------------------- ------------------------------- ------------------------------- ------------------------------- ------------------------------- ------------------------------- ------------------------------- ------------------------------- 
