model
size = 22 32 25, scale = 0.05, origin = -y
material 
  colors = A:#1ABAFF B:#1F95D1 C:#C31518 D:#006E85 E:#FFF F:#A19273 G:#000 H:#7B6132 I:#CECECE
voxels
252-2(2A20-)2A657-4A18-4A19-2(2A20-)2C20-2C86-2C16-4C2-4C12-3C4-3C256-3(6A16-)2(6C16-)6I16-6E14-10C12-3C4F3C14-2(6A16-)C4AC17-C2AC18-4C19-2(2C20-)2C19-4C16-8C11-6C2A6C8-5C4A5C9-12A11-3A4-3A212-6A14-2(10A12-)10C11-12C9-C2-8I2-C8-C2-8E2-C9-12C10-4C4F4C9-2(2A2C6A2C2A8-)5C4A5C2(8-6C2A6C)12-2C2A2C17-C2AC18-C2AC17-2C2A2C12-4H6C4H7-7C2A7C6-6C4A6C7-14A8-5A4D5A9-4D2BDB4D13-3BD2B170-6D13-2(12A10-)12C9-14C7-2(2C2G8E2G2C6-)4C8A4C6-D3C8A3CD6-D14AD5-4AC8AC4A4-2A3C8A3C2A5-2(4C8A4C6-)C4FC4AC4FC7-3G2F4A2F3G8-2GDEF4AFE2GD8-3EFC4ACF3E7-H3F2C4A2C3FH5-5C8A5C4-3C12A3C5-16A6-16A7-6DB7D9-6BD5B12-3ABD3A147-6D13-3D6A3D8-2(16A6-)16A5-2(BC14ACB4-)2(2B14A2B4-)2D14A2D2(4-18A)4-C17A4-C16AC4-2C3E8A3E2C4-CF3E8A3EFC4-F4E8A4EF4-2F3E8A3E2F4-HF3E8A3EFH2(4-C16AC)2(4-18A)5-7DB8D7-7BD6B9-5ABD5A12-3ABD3A125-6B13-3D6A3D8-AD12ADA2(6-16A)5-2(2B14A2B4-)B16AB4-2B14A2B4-D16AD4-18A3-3(20A2-)3(2C16A2C2-)HE16AEH2(2-2C16A2C)3-2(18A4-)18A5-B6ABD6AB6-2B5ABD5A2B7-6ABD6A10-4ABD4A14-2ABD2A104-6A13-D2B6A2BD8-AD12ADA5-5(18A4-)B16AB4-D16AD4-18A3-4(20A2-)5(C18AC2-)20A2-20A3-18A4-8ABD8A5-B6ABD6AB6-7ABD7A8-5ABD5A11-4ABD4A15-ABDA83-6A13-B10AB8-2D12A2D5-4(18A4-)18A3-20A2-BD16ADB2-D18AD6(2-20A)2(2-C18AC)4(2-20A)3-8ABD8A5-7ABD7A6-7ABD7A7-6ABD6A9-5ABD5A12-3ABD3A37-6D2(16-6A)13-12A8-DB12ABD5-18A4-18A3-4(20A2-)BD16ADB2-D18AD12(2-20A)3-8ABD8A4-8ABD8A5-7ABD7A6-7ABD7A8-5ABD5A11-4ABD4A15-ABDA15-2D6-2D2(12-2A6-2A)11-7A2C3A9-B12AB7-D14AD5-18A3-4(20A2-)BD16ADB2-D18AD6(2-20A)3(2-D18AD)3(2-20A)2-9ABD9A3-8ABD8A4-8ABD8A5-7ABD7A7-6ABD6A10-4ABD4A14-2ABD2A13-2(D10-)4(A10-)5A4C3A9-B12AB7-D14AD5-17AD3-2(20A2-)3(9AB10A2-)D8AB9AD5(2-9AB10A)2-D8AB9AD3(2-B8AB9AB)3(2-9AB10A)2-9ABD9A3-8ABD8A4-8ABD8A5-7ABD7A7-6ABD6A9-5ABD5A13-2ABD2A13-2(D10-)4(A10-)3A4CA2C2A9-14A7-B14AB5-D16AD3-2(20A2-)9(9AB10A2-)B8AB9AB7(2-9AB10A)3-8AB9A4-8AB9A5-7AB8A7-6AB7A9-5ABD5A12-3ABD3A12-2(D10-)3(A10-)A9-2A4C3A2C3A8-14A7-B14AB5-D16AD3-2(20A2-)16(9AB10A2-)9AB10A3-8AB9A4-8AB9A5-7AB8A7-6AB7A9-5ABD5A12-3ABD3A11-D12-D2(8-A12-A)8-2A2C3A4C3A8-14A7-B14AB5-2B14A2B4-D16AD3-20A5(2-9AB10A)-10A4(B21A)B11A-6(9AB10A2-)9AB10A3-8AB9A4-8AB9A5-7AB8A7-6AB7A9-5ABD5A13-2ABD2A2(12-D)2(8-A12-A)8-5A4CA2C2A8-14A8-B12AB7-B14AB5-B16AB4-D16AD4-D7AB8AD3-2(AD7AB8ADA2-)9AB10A-10A6(B21A)B11A-5(9AB10A2-)9AB10A3-8AB9A4-8AB9A5-7AB8A7-6AB7A10-4ABD4A14-2ABD2A2(12-D)2(8-A12-A)8-3A4C3A2C2A8-14A8-B12AB7-2B12A2B6-2B12A2B5-3B12A3B2(4-2B6AB7A2B)3-2B7AB8A2B2-BD7AB8ADB-10A6(B21A)B11A-4(9AB10A2-)9AB10A3-8AB9A4-8AB9A5-7AB8A6-7AB8A8-5AB6A11-4ABD4A15-ABDA14-2(D10-)3(A10-)A9-3A2C3A4C2A2(8-14A)8-2B10A2B7-2(3B10A3B6-)B6AB7AB6-B6AB7AB5-B7AB8AB4-D7AB8AD3-2D7AB8A2D-A2B7AB8A2B2A2B7AB8A2B11A3(B21A)B11A-3(9AB10A2-)9AB10A3-8AB9A4-8AB9A5-7AB8A6-7AB8A7-6AB7A9-5ABD5A12-3ABD3A34-2(D10-)4(A10-)5A4C3A10-12A9-14A2(8-2B10A2B)7-3B10A3B3(6-B6AB7AB)5-B7AB8AB4-B7AB8AB3-DB7AB8ABD2-DB7AB8ABD-10A2(B21A)B11A-B8AB9AB3(2-9AB10A)3-8AB9A4-8AB9A5-7AB8A6-7AB8A7-6AB7A8-6AB7A10-4ABD4A14-2ABD2A35-2(D10-)4(A10-)3A4C5A10-12A2(10-B10AB)9-2(2B10A2B8-)B2A2BAB2A2B2AB7-B3A2BAB2A2B3AB6-B2A3BAB2A3B2AB6-6BAB2A6B5-B7AB8AB4-B7AB8AB3-2B7AB8A2B3(2-B8AB9AB)2(2-9AB10A)3-2(8AB9A4-)8AB9A5-7AB8A6-7AB8A7-6AB7A8-6AB7A9-5ABD5A12-3ABD3A57-2D6-2D2(12-2A6-2A)12-AB2C4ABA11-A2B6A2BA4(10-3B6A3B)9-6AB7A8-6AB7A7-4(7AB8A6-)7AB8A5-4(8AB9A4-)8AB9A5-3(7AB8A6-)7AB8A7-6AB7A8-6AB7A9-5ABD5A11-4ABD4A15-ABDA61-6D3(16-2ABD2A)15-B2ABD2AB14-B2ABD2AB13-B2A2BAB2AB11-B2ABA2(B2A)B10-2A2BAB2A2B2A2(10-5AB6A)9-3(6AB7A8-)6AB7A7-3(AB5AB6ABA6-)3(7AB8A6-)7AB8A7-2(6AB7A8-)6AB7A9-5AB6A10-5AB6A11-4ABD4A14-2ABD2A215-ABDA17-2ABD2A15-3ABD3A13-4ABD4A12-4ABD4A11-3ABAB2AB3A10-2A2BAB2A2B2A2(10-5AB6A)9-6(6AB7A8-)6AB7A9-5AB6A10-5AB6A11-4AB5A12-4ABD4A13-3ABD3A16-ABDA347-2ABD2A15-3ABD3A13-4ABD4A2(12-4AB5A)11-4(5AB6A10-)5AB6A11-4AB5A12-4AB5A13-3ABD3A14-3ABD3A15-2ABD2A457-ABDA17-2ABD2A16-2ABD2A15-3(3ABD3A14-)3ABD3A15-2ABD2A16-2ABD2A17-ABDA185-
