model
size = 32 32 12, scale = 0.05, origin = -y
material 
  colors = A:#FCFAF2
voxels
10-13(12A20-)12A19-2(14A18-)14A17-16A16-16A15-18A14-18A13-20A12-20A11-22A10-22A11-20A13-18A17-12A147-14(A12-A18-)A12-A17-2A12-2A2(16-A14-A)15-A16-A13-2A16-2A12-2A16-2A11-3A16-3A9-2(4A16-4A8-)3A18-3A9-2A18-2A11-2A16-2A13-4A10-4A16-14A21-8A84-15(A14-A16-)A14-A15-A16-A14-A16-A13-A18-A12-A18-A11-2(2A18-2A10-)2A18-2A8-A-A20-A-A5-4A20-4A6-2A20-2A9-2A18-2A11-3A14-3A13-2A14-2A16-14A21-8A51-16(A16-A14-)A16-A13-A18-A12-A18-A11-2A18-2A10-2A18-2A103-2A24-2A3-4A22-4A4-2A22-2A7-3A18-3A9-4A14-4A12-2A14-2A16-3A8-3A21-A6-2(A18-)17(A12-A18-)A11-2A18-2A229-4A24-4A2-3A22-3A6-A22-A9-3A16-3A13-2A12-2A18-3A6-3A2(16-16(A18-A12-)A18-A11-2A18-2A261-4A24-4A-4A22-4A4-2A22-2A7-3A18-3A10-4A12-4A16-A10-A)16-17(A18-A12-)A18-A11-2A18-2A229-4A24-4A2-3A22-3A6-A22-A9-3A16-3A13-2A12-2A18-3A6-3A17-16(A16-A14-)A16-A13-A18-A12-A18-A11-2A18-2A10-2A18-2A103-2A24-2A3-4A22-4A4-2A22-2A7-3A18-3A9-3A16-3A12-4A10-4A16-4A6-4A21-8A19-17(A16-A14-)A16-A13-A18-A12-A18-A11-2(2A18-2A10-)2A18-2A8-A-2A18-2A-A5-5A18-5A6-2A20-2A9-2A18-2A11-2A16-2A13-2A14-2A16-14A21-8A52-16(A14-A16-)A14-A15-A16-A14-A16-A13-2A16-2A12-2A16-2A11-3A16-3A9-2(4A16-4A8-)4A16-4A9-3A16-3A11-3A14-3A13-3A12-3A16-14A20-10A84-15(14A18-)14A17-16A16-16A15-18A14-18A13-2(20A12-)20A11-22A10-22A11-20A13-18A17-12A138-
