model
size = 32, scale = 0.05, origin = -y
material 
  colors = A:#001 B:#F0C C:#0E0 D:#888 E:#AAA F:#222 G:#EEE H:#00E
voxels
3-6B14-6C5-8B12-8C3-4B2-4B10-2(4C2-)3B4-3B10-3C4-3C2(2-2B2-2F2-2B10-2C2-2F2-2C)2-3B4-3B10-3C4-3C2(2-4B)10-4C2-4C3-8B12-8C5-6B14-6C710-6B14-6C5-B6AB12-C6AC3-B3A2-3AB10-C3A2-3AC2-B2A4-2AB10-C2A4-2A2(C2-BA2-2F2-AB10-CA2-2F2-A)C2-B2A4-2AB10-C2A4-2AC2-B3A2-3AB10-C3A2-3A3(C3-B6AB12-C6AC5-6B14-6C710-6B14-6C5-B6AB12-C6AC3-2(B8AB10-C8AC2-)2(B3A2F3AB10-C3A2F3AC2-)B8AB10-C8AC2-B8AB10-C8A)C3-B6AB12-C6AC5-6B14-6C710-6B14-6C5-B6AB12-C6AC3-2(B8AB10-C8AC2-)B3AF4AB10-C4AF3AC2-B3A2F3AB10-C3A2F3A2(C2-B8AB10-C8A)C3-B6AB12-C6AC5-6B14-6C710-6B14-6C5-8B12-8C3-4B2F4B10-4C2F4C2-3B4F3B10-3C4F3C2(2-2B2F2A2F2B10-2C2F2A2F2C)2-3B4F3B10-3C4F3C2-4B2F4B10-4C2F4C3-8B12-8C5-6B14-6C840-2(2D18-2D10-2D18-2D970-)2D18-2D10-2D18-2D104-3AD18-D3A6-5A2(16-5A5-6A)16-6A4-GAG2AG16-6A4-3(GA)16-6A4-2G2AGA16-6A4-GAG2AG16-6A4-2G4A16-6A4-6A16-5A5-11(6A26-)2A4EG25-2A4E157-2D18-2D10-2D18-2D104-3AD18-D3A6-6A14-6A5-2(7A14-7A4-)2(6AG2(14-7A4-7A)14-7A4-)7(6A26-)6A-G24-6A26-6AGA24-5AE26-5AEAG24-3A3E156-4D16-4D7-2D2AD16-D2AD8-4D16-4D69-5AD18-D5A3(2-30A)2-2A5-4A2G2A2GA2G10A2-2A5-2(AG)3A2G4AG9A2-2A5-2(AG)3AGAG2AG10A2-2A5-4A2G2AG2A3G9A2(2-2A5-23A)2-2A5-7A18-2(2A5-6A19-)2A5-5A20-2A5-4A21-2A5-3A22-2A5-2A23-2A5-AEA22-2A5-AE23-2A5-2EG22-2A5-2E23-2A5-2EA22-2A5-2E153-5D16-4D2(7-D3AD16-D2AD)8-3D18-3D36-6AD18-D5A-98A5(7-25A)7-22A-2A7-19A4-2A7-6A17-2A7-A5E2(A-G-)A8-2A7-A3E2(G-)A-G-A-G8-2A7-A3E19-2A7-AEGAG18-2A7-AE21-2A7-AEGA19-2A7-AE21-2A7-AEAG19-2A7-AE21-2A7-AEGA19-2A7-AE152-5D16-4D2(7-D3AD16-D2AD)8-DAD18-DAD8-3D18-3D4-6AD18-D103A6(9-23A)2(9-19A3-A)9-6EG8E3A4-A9-3E2(G-A-)G-A8-2(A9-3E19-A9-3EA18-A9-3E19-A9-3EG18-)A9-3E144-3H3-5D16-4D2(-3H3-D3AD16-D2AD)2(-3H4-DAD18-DAD)-3H6AD18-D103A6(9-23A)2(9-20A2-A)9-4A5(EA)E4A3-A9-4A2(-G-A)-G8-2(A9-2AE19-A9-2AEG18-A9-2AE19-A9-2AEA18-)A9-3E144-HFH3-5D16-4D2(-3H3-D3AD16-D2AD)2(-3H4-DAD18-DAD)-3H6AD18-D103A6(9-23A)9-21A-A9-20A2-A9-4A5(EA)E4A3-A9-3A2(G-A-)G-A8-2(A9-2AE19-A9-2AEA18-A9-2AE19-A9-2AEG18-)A9-3E144-HFH3-5D16-4D2(-3H3-D3AD16-D2AD)2(-3H4-DAD18-DAD)-3H6AD18-D103A6(9-23A)9-21A-A9-20A2-A9-4A5(EA)E4A3-A9-4A2(-G-A)-G8-2(A9-2AE19-A9-2AEG18-A9-2AE19-A9-2AEA18-)A9-3E144-3H3-5D16-4D2(-3H3-D3AD16-D2AD)2(-3H4-DAD18-DAD)-3H6AD18-D103A6(9-23A)2(9-20A2-A)9-4A5(EA)E4A3-A9-3A2(G-A-)G-A8-2(A9-2AE19-A9-2AEA18-A9-2AE19-A9-2AEG18-)A9-3E150-5D16-4D2(7-D3AD16-D2AD)8-DAD18-DAD8-3D18-3D4-6AD18-D103A6(9-23A)2(9-19A3-A)9-15E3A4-A9-3E2(A-G-)A-G8-2(A9-3E19-A9-3EG18-A9-3E19-A9-3EA18-)A9-3E150-5D16-4D2(7-D3AD16-D2AD)8-3D18-3D36-6AD18-D5A-98A5(7-25A)7-22A-2A7-19A4-2A7-6A17-2A7-A5E2(G-A-)G8-2A7-A3E2(G-A-)G-A8-2A7-A3E19-2A7-AEAGA18-2A7-AE21-2A7-AEAG19-2A7-AE21-2A7-AEGA19-2A7-AE21-2A7-AEAG19-2A7-AE153-4D16-4D7-2D2AD16-D2AD8-4D16-4D69-5AD18-D5A3(2-30A)6(2-2A5-23A)2-2A5-7A18-2(2A5-6A19-)2A5-5A20-2A5-4A21-2A5-2AG22-2A5-2A23-2A5-AEG22-2A5-AE23-2A5-2EA22-2A5-2E23-2A5-2EG22-2A5-2E155-2D18-2D10-2D18-2D104-3AD18-D3A6-6A14-6A5-8(7A14-7A4-)7(6A26-)6A-A24-6A26-7AG24-5AE26-5AEGA24-3A3E157-2D18-2D10-2D18-2D104-3AD18-D3A6-5A2(16-5A5-6A)16-6A4-2A3EA16-6A4-A5E16-6A4-2(A2E)16-6A4-A5E16-6A4-2A3EA16-6A4-6A16-5A5-11(6A26-)2A4EA25-2A4E157-2D18-2D10-2D18-2D970-2D18-2D10-2D18-2D840-6C14-6B5-8C12-8B3-4C2F4C10-4B2F4B2-3C4F3C10-3B4F3B2(2-2C2F2A2F2C10-2B2F2A2F2B)2-3C4F3C10-3B4F3B2-4C2F4C10-4B2F4B3-8C12-8B5-6C14-6B710-6C14-6B5-C6AC12-B6AB3-2(C8AC10-B8AB2-)C3AF4AC10-B4AF3AB2-C3A2F3AC10-B3A2F3A2(B2-C8AC10-B8A)3(B3-C6AC12-B6AB5-6C14-6B710-6C14-6B5-C6AC12-B6AB3-2(C8AC10-B8AB2-)2(C3A2F3AC10-B3A2F3AB2-)C8AC10-B8AB2-C8AC10-B8A)B3-C6AC12-B6AB5-6C14-6B710-6C14-6B5-C6AC12-B6AB3-C3A2-3AC10-B3A2-3AB2-C2A4-2AC10-B2A4-2A2(B2-CA2-2F2-AC10-BA2-2F2-A)B2-C2A4-2AC10-B2A4-2AB2-C3A2-3AC10-B3A2-3AB3-C6AC12-B6AB5-6C14-6B710-6C14-6B5-8C12-8B3-4C2-4C10-2(4B2-)3C4-3C10-3B4-3B2(2-2C2-2F2-2C10-2B2-2F2-2B)2-3C4-3C10-3B4-3B2(2-4C)10-4B2-4B3-8C12-8B5-6C14-6B707-
