model
size = 25 6 26, scale = 0.05, origin = -y
material 
  colors = A:#0F6 B:#3F9 C:#F0F D:#F63 E:#FF3 F:#0F9 G:#66F H:#39F I:#0FF J:#F9F K:#FCF L:#FF6 M:#FF0 N:#F90 O:#F93
voxels
------------------------- -----------CC------------ ----------C--C----------- ----------C--C----------- -----------CC------------ ------------------------- 
-----------CC------------ ----------JBBJ----------- ---------CCLLCC---------- ---------CCLLCC---------- ----------JCCJ----------- -----------CC------------ 
------------------------- ----II-BBBBBBBBFF-HH----- ---I--I-AAAAAAAA-H--H---- ---I--I----------H--H---- ----II------------HH----- ------------------------- 
----DD------------EE----- ---KDDKBB------FFGEEG---- --DDGGDDA------AEFNNEE--- --DDGGDD--------EMOOME--- ---KDDK----------GEEG---- ----DD------------EE----- 
------------------------- ----BBB----------FBBB---- ----AAA----------AAAA---- ------------------------- ------------------------- ------------------------- 
------------------------- ---BBB-------------BBF--- ---AAA-------------AAA--- ------------------------- ------------------------- ------------------------- 
------------------------- --BBB---------------BBF-- --AAA---------------AAA-- ------------------------- ------------------------- ------------------------- 
------------------------- --BB-----------------BB-- --AA-----------------AA-- ------------------------- ------------------------- ------------------------- 
------------------------- -BB-------------------BB- -AA-------------------AA- ------------------------- ------------------------- ------------------------- 
------------------------- -BB-------------------BB- -AA-------------------AA- ------------------------- ------------------------- ------------------------- 
------------------------- BB---------------------BB AA---------------------AA ------------------------- ------------------------- ------------------------- 
------------------------- BB---------------------BB AA---------------------AA ------------------------- ------------------------- ------------------------- 
------------------------- BB---------------------BB AA---------------------AA ------------------------- ------------------------- ------------------------- 
------------------------- BB---------------------BB AA---------------------AA ------------------------- ------------------------- ------------------------- 
------------------------- BB---------------------BB AA---------------------AA ------------------------- ------------------------- ------------------------- 
------------------------- BB---------------------BB AA---------------------AA ------------------------- ------------------------- ------------------------- 
------------------------- BB---------------------BB AA---------------------AA ------------------------- ------------------------- ------------------------- 
------------------------- -BB-------------------BB- -AA-------------------AA- ------------------------- ------------------------- ------------------------- 
------------------------- -BB-------------------BB- -AA-------------------AA- ------------------------- ------------------------- ------------------------- 
------------------------- --BB-----------------BB-- --AA-----------------AA-- ------------------------- ------------------------- ------------------------- 
------------------------- --BBB---------------BBB-- --AAA---------------AAA-- ------------------------- ------------------------- ------------------------- 
------------------------- ---BBB-------------BBB--- ---AAA-------------AAA--- ------------------------- ------------------------- ------------------------- 
------------------------- ----BBB-----------BBB---- ----AAA-----------AAA---- ------------------------- ------------------------- ------------------------- 
------------------------- -----BBBB-------BBBB----- -----AAAA-------AAAA----- ------------------------- ------------------------- ------------------------- 
------------------------- -------BBBBBBBBBBB------- -------AAAAAAAAAAA------- ------------------------- ------------------------- ------------------------- 
------------------------- ---------BBBBBBB--------- ---------AAAAAAA--------- ------------------------- ------------------------- ------------------------- 
