model
size = 16 30 32, scale = 0.05, origin = -y
material 
  colors = A:#3C3A27 B:#6B5637 C:#3D4B2C D:#292929 E:#2D4028
voxels
6-2(5B11-)5B28-3A12-2(5A11-)5A12-3A346-9B2(7-2B5A2B)9-5E10-7A8-9A7-9A8-8A8-7A10-5A328-11B5-B2A5B2AB5-B9AB6-2E5A2E7-9A6-11A5-11A6-10A7-8A8-7A11-4A311-13B3-BA9BAB3-B11AB4-E9AE5-11A4-13A3-13A4-12A5-10A7-8A9-7A11-2A296-13B3-BA9BAB3-B11AB4-E9AE4-3(13A3-)13A4-12A5-10A7-8A10-5A293-15B-BA11BAB-B13AB2-E11AE3-13A2-2(15A-)15A2-13A4-12A5-10A8-6A12-3A278-15B-BA11BAB-B13AB2-E11AE2-4(15A-)15A2-13A4-11A7-8A10-4A278-15B-BA11BAB-B13AB2-E11AE2-4(15A-)15A2-13A4-11A6-9A10-4A278-15B-BA11BAB-B13AB2-E11AE2-4(15A-)15A2-13A4-11A7-7A11-4A278-15B-BA11BAB-B13AB2-E11AE3-13A2-2(15A-)15A2-13A4-12A5-9A8-7A11-4A279-13B3-BA9BAB3-B11AB4-E9AE4-3(13A3-)13A4-12A4-11A6-9A9-6A11-4A279-13B3-BA9BAB3-B11AB4-E9AE5-11A4-2(13A3-)13A4-11A6-9A8-8A9-6A11-3A281-11B5-BA7BAB5-B9AB6-E7AE6-10A6-11A4-13A3-13A4-11A6-9A8-8A9-5A12-3A281-11B5-BA7BAB5-B9AB6-E7A2(E7-9A6-11A4-13A3-13A4-11A6-9A8-7A10-5A12-3A282-10B6-BA6BAB6-B8AB7-E6A)E7-9A6-11A5-11A4-13A4-11A6-9A8-7A10-5A13-2C282-10B6-BA6BAB6-B8AB7-E6AE7-9A6-11A5-11A4-13A4-11A6-9A8-7A10-5A10-2(7A9-)7A10-5A74-6A10-6A11-4A122-10B6-BA6BAB6-B8AB7-E6AE7-9A6-2(11A5-)12A4-11A6-9A8-7A9-C5AC8-8A7-10A6-10A7-8A8-8A40-8A7-10A6-10A7-8A8-8A103-11B5-BA7BAB5-B9AB6-E7AE6-10A5-2(3A7-2A4-)3A7-3A3-3A7-2A5-2A7-A7-C6AC7-5(10A6-)10A7-8C7-3(10A6-)10A2(7-9A)8-7C9-7A2(9-3AC3A)9-2ACAC2A9-D5AD7-11B5-BA7BAB5-B9AB6-E7AE6-10A5-3A2(7-2A3-4A)7-2A4-3A7-2A5-2A7-A2(7-C6AC7-10A5-12A4-2(13A3-)12A5-10A)7-C6AC8-4(9A7-)9D6-11B5-BA7BAB5-B9AB6-E7AE6-11A4-3A7-3A2-4A7-4A-4A7-4A2-3A7-3A4-2A7-2A6-C7-C6-2A7-2A2(4-13A2-15A-15A2-13A4-11A6-C7AC6-11A)3(5-11A)5-11D5-11B5-BA7BAB5-B9AB6-E7AE6-11A4-3A7-3A2-4A7-4A-4A7-4A2-3A7-3A4-2A7-2A6-C7-C6-2A7-2A2(4-4A5-4A2-5A5-5A-5A5-5A2-4A5-4A4-3A5-3A6-CA5-AC6-3A5-3A)6(5-3A)2(5-3D)4-13B3-BA9BAB3-B11AB4-E9AE4-13A2-4A2(7-9A)7-4A-4A7-4A2-3A7-3A4-CA7-AC4-3A7-3A2-5A6-10A5-11A5-5A-5A5-5A2-4A5-4A4-C2A5-2AC4-4A5-4A2-5A2(5-11A)5-5A-5A5-5A2-4A5-4A4-C2A5-2AC4-4(4A5-4A3-)4D5-4D5(3-13B3-BA9BAB3-B11AB4-E9AE4-13A3(2-4A2(7-9A)7-4A-4A7-4A2-3A7-3A4-CA7-AC4-3A7-3A)3(3-3A7-3A)3-3D7-3D)4-11B5-BA7BAB5-B9AB6-E7AE6-11A2(4-4A5-4A2-5A5-5A-5A5-5A2-4A5-4A4-3A5-3A6-CA5-AC6-3A5-3A)4-4A5-4A2-5A5-5A-5A5-5A2-4A5-4A4-2(3A5-)C2A5-AC6-8(3A5-)2(3D5-)11B5-B2A5B2AB5-B9AB6-2E5A2E6-11A5-11A4-13A3-13A4-11A5-11A6-2C5A2C6-11A5-11A4-13A3-13A4-11A5-11A6-2C5AC7-11A5-11A4-13A3-13A4-11A5-11A6-2C5A2C6-4(11A5-)11D6-9B2(7-2B5A2B)9-5E3(9-9A6-3(11A5-)11A6-9A9-5C)9-4(9A7-)9D9-2(5B11-)5B3(27-5A10-7A8-9A7-9A8-7A10-5A)27-5A2(11-2AC2A)11-2(AC)A11-5A5-
