model
size = 11 14 13, scale = 0.05, origin = -y
material 
  colors = A:#1D2455
voxels
--AA------- -AAAAAAAAAA -AAAAAAAAAA -AAAAAAAAAA -AAAAAAAAAA -AAAAAAAAAA --AAAAAAAAA --AAAAAAAAA -AAAAAAAAA- -AAAAAAAAA- AAAAAAAAAA- AAAAAAAAAAA AAAAAAAAAAA -AAAAAAAAA- 
-AAA------- AAAAAAAAAAA AAAAAAAAAAA AAAAAAAAAAA -AAAAAAAAAA -AAAAAAAAAA --AAAAAAAAA --AAAAAAAAA -AAAAAAAAA- -AAAAAAAAA- AAAAAAAAAA- AAAAAAAAAAA AAAAAAAAAAA -AAAAAAAAA- 
AAAA------- AAAAAAAAAAA AAAAAAAAAAA AAAAAAAAAAA -AAAAAAAAAA -AAAAAAAAAA --AAAAAAAAA --AAAAAAAAA -AAAAAAAAA- -AAAAAAAAA- AAAAAAAAAA- AAAAAAAAAAA AAAAAAAAAAA -AAAAAAAAA- 
AAAA------- AAAAAAAAAAA AAAAAAAAAAA AAAAAAAAAAA -AAAAAAAAAA -AAAAAAAAAA --AAAAAAAAA --AAAAAAAAA -AAAAAAAAA- -AAAAAAAAA- AAAAAAAAAA- AAAAAAAAAAA AAAAAAAAAAA -AAAAAAAAA- 
AAAA------- AAAAAAAAAAA AAAAAAAAAAA AAAAAAAAAAA -AAAAAAAAAA -AAAAAAAAAA --AAAAAAAAA --AAAAAAAAA -AAAAAAAAA- -AAAAAAAAA- AAAAAAAAAA- AAAAAAAAAAA AAAAAAAAAAA -AAAAAAAAA- 
AAAA------- AAAAAAAAAAA AAAAAAAAAAA AAAAAAAAAAA -AAAAAAAAAA -AAAAAAAAAA --AAAAAAAAA --AAAAAAAAA -AAAAAAAAA- -AAAAAAAAA- AAAAAAAAAA- AAAAAAAAAAA AAAAAAAAAAA -AAAAAAAAA- 
AAAA------- AAAAAAAAAAA AAAAAAAAAAA AAAAAAAAAAA -AAAAAAAAAA -AAAAAAAAAA --AAAAAAAAA --AAAAAAAAA -AAAAAAAAA- -AAAAAAAAA- AAAAAAAAAA- AAAAAAAAAAA AAAAAAAAAAA -AAAAAAAAA- 
AAAA------- AAAAAAAAAAA AAAAAAAAAAA AAAAAAAAAAA -AAAAAAAAAA -AAAAAAAAAA --AAAAAAAAA --AAAAAAAAA -AAAAAAAAA- -AAAAAAAAA- AAAAAAAAAA- AAAAAAAAAAA AAAAAAAAAAA -AAAAAAAAA- 
AAAA------- AAAAAAAAAAA AAAAAAAAAAA AAAAAAAAAAA -AAAAAAAAAA -AAAAAAAAAA --AAAAAAAAA --AAAAAAAAA -AAAAAAAAA- -AAAAAAAAA- AAAAAAAAAA- AAAAAAAAAAA AAAAAAAAAAA -AAAAAAAAA- 
AAAA------- AAAAAAAAAAA AAAAAAAAAAA AAAAAAAAAAA -AAAAAAAAAA -AAAAAAAAAA --AAAAAAAAA --AAAAAAAAA -AAAAAAAAA- -AAAAAAAAA- AAAAAAAAAA- AAAAAAAAAAA AAAAAAAAAAA -AAAAAAAAA- 
AAAA------- AAAAAAAAAAA AAAAAAAAAAA AAAAAAAAAAA -AAAAAAAAAA -AAAAAAAAAA --AAAAAAAAA --AAAAAAAAA -AAAAAAAAA- -AAAAAAAAA- AAAAAAAAAA- AAAAAAAAAAA AAAAAAAAAAA -AAAAAAAAA- 
AAAA------- AAAAAAAAAAA AAAAAAAAAAA AAAAAAAAAA- -AAAAAAAA-- -A----AAAA- --------AA- ---------A- ----------- -AAAA------ AAAAAA----- AAAAAAA---- AAAAAAAA--- -AAAAAAAA-- 
A---------- AAAA------- AAAAAA----- AAAAAAAA--- ------AA--- --------A-- ----------- ----------- ----------- ----------- AAAAA------ AAAAA------ AAAAAAA---- ----------- 
