model
size = 10 7 8, scale = 0.05, origin = -y
material 
  colors = A:#9CF
voxels
---------- ---------- --AAAAAA-- --AAAAAA-- ---------- ---------- ---------- 
---------- -A------A- -A-A-AA-A- -A------A- --AAAAAA-- --A-AA-A-- --A-AA-A-- 
-A------A- --A----A-- -A------A- -AA----AA- -AA----AA- ----AA---- ---------- 
-A------A- -A------A- --A----A-- -A------A- -AA----AA- AA-AAAA-AA A--------A 
-A------A- -A------A- -A------A- --A----A-- -AA----AA- ----AA---- ---------- 
---------- -A------A- -A------A- -A------A- --AAAAAA-- --A-AA-A-- --A-AA-A-- 
---A--A--- --A-AA-A-- --A----A-- --AAAAAA-- ---------- ---------- ---------- 
---A--A--- ---AAAA--- ---AAAA--- ---------- ---------- ---------- ---------- 
