model
size = 24 22 10, scale = 0.05, origin = -y
material 
  colors = A:#777 B:#888 C:#444 D:#555 E:#700 F:#AAA
voxels
------------------------ ------------------------ ------------------------ ------------------------ ------------------------ ------------------------ ------------------------ ------------------------ ------------------------ ---------E--E--E-------- ---------E--E--E-------- ---------E--E--E-------- ---------E--E--E-------- ------------------------ ------------------------ ------------------------ ------------------------ ------------------------ ------------------------ ------------------------ ------------------------ ------------------------ 
------------------------ ------------------------ ------------------------ ------------------------ ------------------------ ------------------------ ------------------------ ------------------------ ---------E--E--E-------- ------------------------ ------------------------ ------------------------ ------------------------ ---------E--E--E-------- ------------------------ ------------------------ ------------------------ ------------------------ ------------------------ ------------------------ ------------------------ ------------------------ 
--------BBB----AAA------ ------AA----------AA---- -----A-------------AA--- ---BB---------------A--- --BB-----------------A-- -BB-------------------A- -BB-------------------A- BB---------------------B B--------E--E--E-------B B----------------------B B----------------------B B----------------------B B----------------------B B--------E--E--E-------B BBB-------------------BB -BB-------------------B- -BBB-----------------BB- --BBB---------------BB-- ---BBB-------------BB--- ---BBBB-----------BBB--- -----BBBB-------BBB----- ------BBBBBBBBBBBB------ 
--------AAAAAAAA-------- ------AAA------DDD------ -----AA----------DD----- ----AA-------------A---- ---AA---------------A--- --AD-----------------D-- --AD-----------------D-- -AD------------------DD- -DD------E--E--E------D- -D--------------------D- -D--------------------D- -D--------------------D- -D--------------------D- -DD------E--E--E------D- -AAA-----------------DA- --AA-----------------D-- --AAD---------------AA-- ---AAD-------------AA--- ----AAD-----------AA---- -----AAAA-------AAA----- ------AAAAAAAAAAAA------ --------AAAAAAAA-------- 
------------------------ ---------CCCCCC--------- -------CCCCCCCCCC------- -----ACCCC--D--CCCC----- ----ACCC-D--D--D-CCCA--- ----CCC--D--D--D--CCC--- ---ACC---D--D--D---CC--- ---CCC---D--D--D---CC--- --ACC----D--D--D----CC-- --CCC----D--D--D----CC-- --CCDDDDDDDDDDDDDDDDCC-- --CC-----D--D--D----CC-- --CC-----D--D--D----CC-- --ACC----D--D--D---CCC-- ---ACC---D--D--D---CC--- ---ACCC--D--D--D--CCC--- ----ACCC-D--D--D-CCC---- ----AACCCD--D--DCCCA---- -----AACCCC-D-CCCCA----- -------AACCCCCCCA------- ---------AAAAAA--------- ------------------------ 
------------------------ ------------------------ -----------AA----------- --------AAAAAAAA-------- ------AAAAAAAAAAAA------ -----AAAAA-----AAAA----- -----AAAA-------AAA----- ----AAAA---------AAA---- ----AAA-----------AA---- ----AAA-----------AA---- ---AAAA-----F-----AAA--- ---AAAA-----------AAA--- ----AAA-----------AA---- ----AAAA---------AAA---- ----AAAAA-------AAAA---- -----AAAAA-----AAAA----- -----AAAAAAAAAAAAAA----- ------AAAAAAAAAAAA------ --------AAAAAAAA-------- -----------AA----------- ------------------------ ------------------------ 
------------------------ ------------------------ ------------------------ ------------------------ ----------AAAA---------- --------AABBBBBA-------- -------AABBBBBBBA------- ------AABBB---BBBA------ ------ABBB-----BBB------ -----AABB-------BBA----- -----AABB---F---BBA----- -----AABB-------BBA----- -----AABBB-----BBBA----- ------AABBB---BBBA------ ------AAABBBBBBBAA------ -------AAABBBBBAA------- --------AAAAAAAA-------- ----------AAAA---------- ------------------------ ------------------------ ------------------------ ------------------------ 
------------------------ ------------------------ ------------------------ ------------------------ ------------------------ ------------------------ ------------------------ ----------AAAA---------- ---------AAAAAA--------- --------AAA---AA-------- --------AAA-A-AA-------- --------AAA---AA-------- --------AAAAAAAA-------- ---------AAAAAA--------- ----------AAAA---------- ------------------------ ------------------------ ------------------------ ------------------------ ------------------------ ------------------------ ------------------------ 
------------------------ ------------------------ ------------------------ ------------------------ ------------------------ ------------------------ ------------------------ ------------------------ ------------------------ -----------FFF---------- -----------FFF---------- -----------FFF---------- ------------------------ ------------------------ ------------------------ ------------------------ ------------------------ ------------------------ ------------------------ ------------------------ ------------------------ ------------------------ 
------------------------ ------------------------ ------------------------ ------------------------ ------------------------ ------------------------ ------------------------ ------------------------ ------------------------ -----------FFF---------- -----------FFF---------- -----------FFF---------- ------------------------ ------------------------ ------------------------ ------------------------ ------------------------ ------------------------ ------------------------ ------------------------ ------------------------ ------------------------ 
