model
size = 32 24 16, scale = 0.05, origin = -y
material 
  colors = A:#005 B:#004 C:#FF0 D:#111 E:#00B F:#00E G:#008 H:#FF6 I:#FF9 J:#AAA K:#CF6 L:#00D M:#777 N:#FF3 O:#CC0
voxels
719-2J29-J2MJ529-3A20-3A9-2A16-2A2(14-A)17-A12-A19-G10-G20-C10-C14-2DA-4DG2D2C2DG4D-A2D9-DA-4DGD4JDG4D-AD9-2(H2C)12-2(2CH)3(8-6A12-6A)8-6A12-B5A8-6A12-2(B2A)8-3AB2AB10-2B5A8-5A5B4-5B5A8-3AB2A-3B4-3B-BAB3A8-6A12-B5A8-7AB-B4-B-2B6A8-4AB3A3B2-4B7A8-6AB2A-4B-B8A8-7ABA-4B-2ABA4BA8-AB8A2B7AB4A8-2A2B6ABAB4A2B5A6-EG2B2A2B4AB2AB4AB3A2BGE6-2A2B2AB3AB2AB6A3BA8-4ABAB3AB2AB5AB2ABA8-5A2(B4AB2A)GBA8-6AK3AB2AB3AK5BA8-10AB13A8-DABD4AB2A2K2AB4ADBAD8-DABD4AB2A2O2AB4ADBAD7-H5AC12-C5AH4(6-7A12-7A)6-7AB10-B2(7A6-7A2B8-2B)7A6-7A4B4-4B7A6-7A2-2B4-2B2-7A6-9A8B9A6-10A6B2(10A6-10A-4B-)10A6-B25A6-26A4-EAB24ABAE4-5(26A6-)D24AD6-D24AD5-2C6AC10-C6AC5-9A2(10-8A5-8AB)10-9A4-8AB10-9A4-8A2B8-B9A4-9AB8-B9A4-8A2B8-B9A4-8ABGB6-BG9A4-9A3B4-3B9A4-10AB6-11A4-11A2B2-2B11A4-12AB2-B12A3(4-28A)2-E30AE2-4(28A4-)28A3-AD26ADA2-AD26ADA4-C7AC8-C7AC6-2(8AB8-10A5-)9A8-10A4-10A8-10A3-2(11A8-11A2-)10AB8-11A2(2-10AB8-10AB)2(2-11A8-11A)2(2-11A-6A-11A)2(2-30A)-C11A8-11AC-12A6-12A4(2-30A)2-D10A-6A-10AD2-D28AD3-H8AC8-C8AH4-10A2(8-10A4-B9A)8-10A4-10A8-10A3-3(B10A8-11A2-)2(B10A8-10AB2-)B10A8-11A2-12AB4-B12A2-30A2-11A-6A-11A2(2-30A)2(2-11A8-11A)4(2-30A)2-D10A8-10AD2-D28AD3-C2A2-4AC8-C4A2-2AC4-H2A2-5A8-5A2-2AH4-C2A2-5A8-5A2-2AC4-C2A2-4AB8-5A2-2AC4-H2A2-4AB8-5A2-2AH3-2(C3A2-4AB8-5A2-3AC2-)C3A2-5A8-5A2-3AC2(2-H3A2-5A8-5A2-3AH)2(2-C3A2-18A2-3AC)2-H3A2-18A2-3AH3(2-C3A2-18A2-3AC)2-C3A2-5A8-5A2-3AC2-C3A2-7A4-7A4(2-3AC2-C3A2-18A)2-3AC2-4A2-5A8-5A2-4A2-AD26ADA3-C3AB2C2AC8-C2A2CB3AC4-10A8-10A4-B9A8-10A4-B8AB8-10A4-9AB8-10A3-2(10AB8-11A2-)2(11A8-11A2-)11A8-B10A6(2-30A)2-12A6-12A2-B11A6-12A2-30A3(2-B29A)2(2-D28AD)3-C2ACH2-CAC8-CAC2-HC2AC4-4AB5A8-5AB4A2(4-B9A8-10A)4-10A8-10A3-2(11A8-11A2-)11A8-B10A2-11A8-11A2-11A8-B10A2(2-B29A4(2-30A))2(2-30A)2(2-D28AD)4-HC4-CH10-HC4-CH5-4A2B3A10-3A2B3A5-4A2B3A10-3A2B4A4-6AB2A10-2(2AB)3A2(4-B8A10-9A)4-B8A10-B8A4-B8A10-9A4-B7AB9-A2B7A4-B7AB9-AB8A4-B8A8-11A4-9A10-9A3-10A2-6A2-10A2-A2B27A4(2-30A)2-B29A3(2-30A)3-D26AD4-D26AD5-CH4-H12-H4-HC3(6-2A4-A12-A4-2A)6-7A12-4AB2A6-6AB12-B6A6-7A12-7A6-6AB12-B6A6-7A11-AB6A6-7AB10-B7A6-7A12-7A6-26A5-B27A5-B25A5-B27A4-B27A3-2(30A2-)30A4-26A4-30A2-30A3-GD24ADG4-GD24ADG102-2(A22-A8-)4AB2(14-B4A8-5A)14-5A8-5A14-5A3(8-24A)7-26A6-26A5-B27A2(4-28A)4-B27A4-28A5-26A4-30A3-28A6-D22AD8-D22AD169-3A16-B2A10-3A16-3A2(10-4A14-4A)10-5A4-6A2-5A10-7AB2A5B7A10-8ABA3B9A9-9AB2A2B10A7-10AB15A6-11A3B12A6-11A2B13A6-12A2B12A6-B25A5-28A5-26A5-28A4-28A7-D20AD10-D20AD362-2BF2EB2A6-2AB2EF2B9-BEF3AFBA6-ABFCACFEB7-BL-4CIC2B4-ABFI5CLA6-BFAI2ABCAEB4-AEACB2AIAFA6-BEA-I3CAFBA2-ABF2A2CICAEA6-BEACBABCAEBA2-ABEACBABCAEA6-BF-I3CICEB4ABEAI3CICFA6-BF2ACAI2AFB4ABF2AIAC2AFA6-AC2EFE2FEN5ABNE2FEF2ECA7-24A8-11A2-11A9-G3DA4DG2DG4DA3DG10-G20DG364-F2E12-2EF12-EF3-F10-FC-CFE9-E-4CIC8-FI5CF8-F-I3-C-E6-F-C3-I-F8-E2-I3C-F6-F2-2CIC-E8-E-C3-C-E6-E-C3-C-E8-F-I3CICE6-E-I3CICF8-F2-C-I2-E6-F2-I-C2-F8-C2EFE2FEC6-CE2FEF2EC75-2(2DG4DG)2D14-2(2DG4DG)2D7-
