model
size = 16 30 32, scale = 0.05, origin = -y
material 
  colors = A:#FFF B:#FFD24C C:#C1C1C1 D:#888 E:#555 F:#D8D8D8 G:#FFD684
voxels
6-2(5B11-)5B28-3A12-2(5A11-)5A12-3A346-9B2(7-2B5A2B)9-5E10-7A8-2(9A7-)8A9-7A10-5A328-11B5-B2A5B2AB5-B9AB6-2E5A2E7-9A6-2(11A5-)10A7-8A9-7A10-4A312-13B3-BA9BAB3-B11AB4-E9AE5-11A4-2(13A3-)12A5-10A7-8A8-7A12-2A297-13B3-BA9BAB3-B11AB4-E9AE4-13A3(2-14A)3-12A5-10A7-8A9-5A295-15B-BA11BAB-B13AB2-E11AE2-14A2-15AF2(15A-)14A3-12A5-10A8-6A11-3A280-15B-BA11BAB-B13AB2-E11AE2-31AF31A-15A2-13A4-11A6-8A10-4A279-15B-BA11BAB-B13AB2-E11AE2-15AF31AF15A-15A2-13A4-11A6-9A9-4A279-15B-BA11BAB-B13AB2-E11AE2-4(15A-)15A2-13A4-11A6-8A10-4A279-15B-BA11BAB-B13AB2-E11AE3-13A2-2(15A-)15A2-13A3-12A5-10A8-7A10-4A280-13B3-BA9BAB3-B11AB4-E9AE4-13A3-13A2(2-14A)3-12A4-12A6-9A8-6A11-4A280-13B3-BA9BAB3-B11AB4-E9AE4-12A4-13A2(2-14A)3-12A5-10A7-8A9-6A12-3A281-11B5-BA7BAB5-B9AB6-E7AE6-11A4-12A3-14A2-14A3-12A5-10A7-8A10-5A12-3A281-11B5-BA7BAB5-B9AB6-E7AE6-10A5-12A4-13A2-14A3-12A5-10A7-8A10-5A12-3A281-10B6-BA6BAB6-B8AB7-E6AE7-10A5-12A3-14A2-14A3-12A6-9A7-8A10-5A12-3A281-10B6-BA6BAB6-B8AB7-E6AE7-10A5-2(12A4-)13A3-12A6-9A8-7A10-5A12-2D282-10B6-BA6BAB6-B8AB7-E6AE8-9A5-2(12A4-)13A4-11A6-9A8-7A10-5A10-2(7A9-)7A10-5A74-7A9-7A10-5A120-10B6-BA6BAB6-B8AB7-E6AE8-9A6-11A2(4-12A)5-11A6-9A8-7A9-D5AD9-7A8-F7AF7-F7AF8-7A9-7A41-7A8-F7AF7-F7AF8-7A9-7A103-11B5-BA7BAB5-B9AB6-E7AE7-10A5-2A7-3A4-2A7-3A3-3A7-3A4-2A7-3A5-A7-2A7-D6AD7-5(10A6-)10A7-8D7-5(10A6-)10A7-7D9-7A2(9-3AG3A)9-2AGAG2A9-C5AC7-11B5-BA7BAB5-B9AB6-E7AE7-10A5-2A7-3A4-2(2A7-4A3-)2A7-3A5-A7-2A2(7-D6AD7-10A5-2(12A3-F)12A4-12A5-10A)7-D6AD4(7-9A)7-9C6-11B5-BA7BAB5-B9AB6-E7AE6-11A4-3A7-4A-4A7-3A2-4A7-3AC2-3A7-4A3-2A7-2A6-D7-D6-2A7-2A2(4-13A2-15A-15A2-13A4-11A6-D7AD6-11A)3(5-11A)5-11C5-11B5-BA7BAB5-B9AB6-E7AE6-11A4-3A7-4A-4A7-3AC-4A7-3A3-3A7-4A3-2A7-3A5-D7-D6-2A7-2A2(4-4A5-5A-5A5-4A2-5A5-4AC2-4A5-5A3-3A5-3A6-DA5-AD6-3A5-3A)6(5-3A)2(5-3C)4-13B3-BA9BAB3-B11AB4-E9AE4-13A2-4A7-9A7-3A-5A7-3AC-4A7-4A2-3A7-3A4-DA7-AD4-3A7-3A2-4A6-11A5-4AC6A5-4A2-5A5-5A2-4A5-4A4-D2A5-2AD4-4A5-4A2-5A5-11A5-4AC6A5-4A2-5A5-5A2-4A5-4A4-D2A5-2AD4-4(4A5-4A3-)4C5-4C2(3-13B3-BA9BAB3-B11AB4-E9AE4-13A2-4A7-9A7-3AC5A7-3A2-2(4A7-4A2-3A7-3A4-DA7-AD4-3A7-3A2-4A7-9A7-3A-5A7-3AC-)4A7-4A2-3A7-3A4-DA7-AD4-4(3A7-3A3-)3C7-3C3-13B3-BA9BAB3-B11AB4-E9AE4-13A2-4A7-9A7-3A-5A7-3AC-2(4A7-4A2-3A7-3A4-DA7-AD4-3A7-3A2-4A7-9A7-3AC5A7-3A2-)4A7-4A2-3A7-3A4-DA7-AD4-4(3A7-3A3-)3C7-3C)3-13B3-BA9BAB3-B11AB4-E9AE4-13A2-4A7-9A7-3AC5A7-3A2-2(4A7-4A2-3A7-3A4-DA7-AD4-3A7-3A2-4A7-9A7-3A-5A7-3AC-)4A7-4A2-3A7-3A4-DA7-AD4-4(3A7-3A3-)3C7-3C4-11B5-BA7BAB5-B9AB6-E7AE6-11A2(4-4A5-4A2-5A5-5A-5A5-5A2-4A5-4A4-3A5-3A6-DA5-AD6-3A5-3A)4-4A5-4A2-5A5-5A-5A5-5A2-4A5-4A4-3A5-3A6-DA5-2AD8(5-3A)2(5-3C)5-11B5-B2A5B2AB5-B9AB6-2E5A2E6-11A5-11A4-13A3-13A4-11A5-11A6-2D5A2D6-11A5-11A4-13A3-13A4-11A5-11A7-D5A2D6-11A5-11A4-13A3-13A4-11A5-11A6-2D5A2D6-4(11A5-)11C6-9B2(7-2B5A2B)9-5E3(9-9A6-3(11A5-)11A6-9A9-5D)9-4(9A7-)9C9-2(5B11-)5B3(27-5A10-7A8-9A7-9A8-7A10-5A)27-5A2(11-2AG2A)11-2(AG)A11-5A5-
