model
size = 9 30 9, scale = 0.05, origin = -y
material 
  colors = A:#222 B:#FFFFCE C:#95A59A D:#D0D0D0 E:#1B813E F:#555 G:#2F2F2F H:#E83015 I:#FD0 J:#EEE K:#5DAC81 L:#F7D94C M:#BDC0BA N:#656765 O:#868686 P:#D0104C Q:#2EA9DF R:#DDD S:#7BA23F T:#111
voxels
--------- --------- --------- --------- --------- --------- --------- --------- --------- --------- --------- --------- --------- --------- --------- --------- --------- --------- --------- --FAFAF-- BAGFGFGAB BBAAAAABB -BBBBBBB- --------- --------- --------- --------- --------- --------- --------- 
--------- --------- --------- --------- --------- --------- --------- --------- --------- --------- --------- --------- --------- --------- --------- --------- --------- --------- -AAAAAAA- BAAAAAAAB BAAAAAAAB BAAAAAAAB BBBBBBBBB --------- --------- --------- --------- --------- --------- --------- 
--BBBBB-- -BGGNGGB- --------- --------- --------- --------- --------- --------- --------- --------- --------- --------- --------- --------- --------- --------- --------- -AAAAAAA- BAAAAAAAB BAAAAAAAB BAAAAAAAB BAAAAAAAB BBBBABBBB ----N---- --------- --------- --------- --------- --------- --------- 
-BBBBBBB- BAAAAAAAB -AAAAAAA- --------- --J-J-J-- --------- --J-J-J-- --------- --J-J-J-- --------- --S---H-- --------- --KEEEE-- --KEEEE-- --KEEEE-- --KKKKK-- -AAAAAAA- BAAAAAAAB BAAAAAAAB BAAAAAAAB BAAAAAAAB BAAAAAAAB BBBAAABBB ---GAG--- ----G---- --------- --------- --------- --------- --------- 
BBCCCCCBB BAAAAAAAB BADADDDAB -AAAAAAA- -ADADADA- -AAAAAAA- -ADADADA- -AAAAAAA- -ADADADA- -AAAAAAA- -AAAAAAA- -AAAAAAA- -AAAAAAA- -AAAAAAA- -AAAAAAA- -AAAAAAA- BAAAAAAAB BAAAAAAAB BAAAAAAAB BAAAAAAAB BAAAAAAAB BAAAAAAAB BBAAAAABB --NAAAN-- ---GAG--- ----A---- ----A---- ----A---- ----A---- ----T---- 
BBCBBBCBB BAAADDDAB BD-F---DB BD-FDHDDB BD-G-G-DB BD-G-G-DB BD-I-I-DB BD-I-I-DB BD-I-G-DB BDD--G-DB BADDDDDAB BAAAAAAAB BAAAAAAAB BAAAAAAAB BAAAAAAAB BAAAAAAAB BAAAAAAAB BAAAAAAAB BAAAAAAAB BAAAAAAAB BAAAAAAAB BAAAAAAAB CCCAAACCC ---GAG--- ----G---- --------- --------- --------- --------- --------- 
BCCCCCCCB BAAADDDAB BAGFFO-DB BAFGHGHAB BAFGHGHAB BAFGFGFAB BAFIFIFAB BAHIHIFAB BAHIHIFAB BD-OFOFDB BADODODAB BAAAAAAAB BAEEEEEAB BAEEEEEAB BAEEEEEAB BAEEEEEAB BAEEEEEAB BAEEEEEAB BAEEEEEAB BAEEEEEAB BAEEEEEAB CAAAAAAAC -CCCACCC- ----N---- --------- --------- --------- --------- --------- --------- 
-CLCLCLC- CADADDDAC CD-F---DC CD-F-H-DC CD-F-H-DC CD-F-F-DC CD-F-F-DC CD-H-F-DC CD-H-F-DC CD---F-DC CADDDDDAC CAAPAAAAC CA-P-R-AC CAPP---AC CAR--QQAC CA---Q-AC CA-MFFMAC CA--FF-AC CA-MFFMAC CA--FF-AC CA-MFGMAC CAAAAAAAC -CCCCCCC- --------- --------- --------- --------- --------- --------- --------- 
--LCLCL-- -CCCCCCC- -CC---CC- -CCC---C- -C-CC--C- -C--CC-C- -C---CCC- -C----CC- -CC----C- -CC----C- -CCCCCCC- -CCCCCCC- -C---CCC- -C--CCCC- -C--CC-C- -C-CC--C- -CCC---C- -CC----C- -CC----C- -CC---CC- -C---CCC- -CCCCCCC- --CCCCC-- --------- --------- --------- --------- --------- --------- --------- 
