model
size = 32 32 30, scale = 0.05, origin = -y
material 
  colors = A:#1C1208 B:#20180C C:#EEE D:#111 E:#F9F F:#888 G:#F9C H:#555 I:#636
voxels
7-C17-C14-2(A15-)2A13-2A941-2C17-2C11-3A15-3A11-2(4A13-)2(2B13-2A15-)2B13-2A844-3C17-3C9-4A15-4A9-5A13-5A11-2(3B13-3A13-)3B13-2AB14-3B11-2AB2(15-3B11-A2B)15-3A11-2AB17-2(A11-A19-)A11-A621-4C17-4C7-5A15-5A7-6A13-6A9-2(4B13-4A11-)4B13-A3B12-3(4B11-A3B13-)4A11-A3B15-2(2A11-2A17-)2A11-2A19-2(A9-A21-)B9-A2(21-BA7-2A)87-A5-A2(25-A5-B)303-5C17-5C5-6A15-6A5-7A13-7A7-3B2A2(13-5A9-5B)13-A4B10-2(5B11-A4B11-)2B3A11-A4B11-2B3A11-A4B12-2B2A11-2A2B2(13-2B2A11-4A)15-3A9-3A17-2BA9-3A17-3B9-2AB17-3BA7-2A2B17-3BA7-A3B19-BA7-AB21-2A7-2A21-3A5-3A21-3A5-2BA21-3A5-3B23-A2(5-B25-B)5-B25-2B3-2B2(25-2B3-2A)111-5C17-5C5-6A15-6A5-7A13-7A6-2B4A13-6A7-4B2A13-6A7-5BA13-2A2B2A8-4B2A11-2A4B9-3B3A11-A5B9-B5A11-A5B9-3B3A11-2A4B10-3B2A11-3A2B11-3B2A11-4AB11-3B2A11-5A13-B3A9-4A15-2B2A9-4A15-3BA9-A3B2(15-4BA7-A4B)16-2B2A7-A3B17-B3A7-A3B17-5A5-3A2B17-5A5-B3AB17-5A5-2BA2B19-3A2(5-3B21-3B)5-2BA21-4B3-2B2A21-4B3-3AB21-4B3-2A2B23-BA2(3-2A25-2A)3-2A14-6C17-6C3-7A15-6AB3-8A13-6A2B4-7A13-5A2B5-A2B4A13-5A2B5-4B3A13-6AB6-3B4A11-3A2B2A7-2B5A11-2A4BA7-7A11-2A5B7-A2B4A11-3A4B9-2B3A2(11-3A2B11-3B2A)11-4AB12-2(2B3A9-5A13-)3B2A9-A4B2(13-4B2A7-A5B)14-2(2B3A7-A4B15-)2B4A5-3A3B15-B5A5-3A3B15-6A5-BA4B17-4A5-4B19-A2BA5-2BAB19-4B5-B3A19-4B5-2A2B2(19-4B5-A3B)20-2BA2(5-A2B21-3A)5-2AB12-6C17-6C3-7A15-5A2B3-8A13-5A3B4-2(7A13-5A2B5-)7A13-5A2B6-2(7A11-7A7-)7A11-4A3B7-7A11-3A4B8-3B3A2(11-3A3B9-4B2A)11-3A3B10-3B3A9-5AB11-3B3A9-6A11-2B4A9-2A2B2A11-6A9-A5B11-3B3A9-6B12-3B2A9-5B2(13-3B2A9-A4B)13-3B2A9-5B13-2B3A9-5B15-2(3A9-3B17-)2AB9-A2B2(17-A2B9-3B)17-2AB9-3B18-2(2A9-2B19-)2A9-2B10-7C2A13-2A7C-9A13-6A3B-9A13-5A4B2-2(8A13-5A3B3-)8A13-5A3B4-7A13-6AB5-7A13-7A5-7A13-3A4B5-7A13-2A5B6-A2B3A13-2A4B7-4B2A13-2A4B7-5BA13-2A4B9-3BA13-3AB11-2B2A13-4A11-B3A13-3AB11-4A13-4B11-3BA13-4B12-8(3B13-)2BA13-3B14-2(2B13-2B15-)BA13-2B15-2A13-BA2(15-2A13-2B)16-2(A13-B17-)A13-B9-7C2A13-2A7C-9A13-7A2B-9A13-6A3B2-2(8A13-5A3B3-)8A13-6A2B4-7A13-6AB5-B6A13-7A5-B6A13-4A2BA5-7A13-3A4B6-6A13-2A4B7-A2B3A13-2A4B7-4B2A13-3A3B8-3B2A13-4AB9-2B3A13-5A9-5A13-2A3B9-5A13-A4B9-A2B2A13-A4B10-3BA2(13-A3B11-4B)13-4B11-3BA13-3BA11-4B2(13-4B12-3B)13-3BA12-3B2(13-2BA)13-3A2(13-B2A)2(13-2BA)14-BA13-2B15-2A13-BA15-2A13-2A7-9C15-A7C9A15-17A15-6A2B2-7A15-5A2B3-B6A15-5A2B3-2B5A15-4A3B4-B5A15-4A2B5-2B4A15-5AB5-2B4A15-6A5-B5A15-3A2BA6-5A15-2A3B7-B4A15-2A3B7-2B3A15-3A2B8-B3A2(15-4A9-4A)15-A3B2(9-4A15-4B)10-2BA2(15-6B8-3B)15-A4BA8-3B15-B5A8-3B2(15-2B4A9-2B)15-B2A3C9-3(2B15-2A13-)2B15-2A14-2(B15-A15-)A15-A7-9C15-A7C9A15-8A2B7A15-8A-2B6A15-5A3B-3B5A15-4A4B-4B4A15-4A4B2-2(3B4A15-4A3B3-)3B4A15-5A2B3-3B4A15-7A4-2B4A15-6A5-3B3A15-6A5-4B2A15-6A6-3B2A15-5A7-2B3A15-5A7-B4A15-2A2BA7-5A15-A4B7-5A15-5B8-4A15-6B7-4A15-A3B-A7-4A15-2A2B-A7-A2BA15-4A-A7-4B15-4A-A8-3B15-4A-D8-3B15-4A-C8-3B15-3A11-3B15-4A10-3B15-3AD10-3B15-3A12-2(2B15-2A13-)2B15-2A6-8C17-7C2B6A17-7A3B5A17-7A-3B4A17-4A3B2(-4B3A17-3A4B)2-2(3B3A17-3A3B3-)3B3A17-4A2B3-3B3A17-6A4-3B2A2(17-5A5-4BA)17-5A6-2(3BA17-4A7-)2B2A17-4A7-4A17-A2BA7-4A17-4B8-3A17-4BA7-3A17-A2B2(-A7-3A17-3A)-A7-A2(2B17-3A-A8-)2B17-3A-C8-2(2B17-2A11-)2B17-2AD10-2B17-2A12-2(B17-A13-)B17-A-D4-8C17-7C3B5A17-7A4B4A17-7A-3B4A17-5A2B-4B3A17-4A3B-4B3A17-3A4B2-3B3A17-3A3B3-3B3A17-4A2B3-3B3A17-5AB3-3B3A17-6A4-3B2A2(17-5A5-4BA)17-3A2B6-2(3BA17-2A2B7-)2B2A17-3AB2(7-4A17-4A)8-3A17-5A3(7-3A17-3A-A)7-2BA2(17-3A-A8-2B)17-3AIC8-BA2(17-2AF10-2B)17-2AD10-2B17-3A2(11-B17-A-A)11-B17-A-2D3-8C17-7C3B5A17-7A4B2(4A17-7A-3B)4A17-5A2B-4B3A17-4A3B2-3B3A17-4A2B3-3B3A17-5AB3-3B3A17-6A3-2B4A17-6A4-2B3A17-5A5-3B2A17-3A2B5-4BA17-2A3B6-3BA17-A3B7-2B2A17-A3B7-B3A17-2A2B7-4A17-3AB7-4A17-4A8-3A17-5A2(7-3A17-3A-A)7-2BA17-3A-A7-3B2(17-3A-A8-2B)17-3A-C8-2B17-2AH10-BA17-2AH10-2B17-3AD9-2B2(17-4A10-B)17-4A10-A17-A4D2-8C17-7C2B6A17-7A3B5A3(17-7A-3B4A)17-7A2-3B3A17-4A2B3-3B3A17-3A3B3-2B4A17-3A3B3-B5A17-4A2B4-5A17-5A5-2B3A17-2A3B5-3B2A17-A4B6-2B2A17-A3B7-B3A2(17-A3B7-4A)17-2A2B7-4A17-4A8-3A17-5A2(7-3A17-3A-A)2(7-3B17-3A-A)8-2B17-3A-A8-2B17-3A-C8-2(2B17-2AF10-)2A17-2AD10-2A3(17-3A11-B)17-2A2D3-8C17-7C8A17-7A2B6A17-7A-2B5A17-7A-3B4A17-7A-4B3A17-4A2BA2-4B2A17-3A3B3-4B2A17-2A4B3-3B3A17-2A4B3-2B4A17-3A3B4-5A17-4AB5-5A17-2A3B5-5A17-A4B6-3(4A17-A3B7-)4A17-2A2B7-4A17-4A8-3A17-5A2(7-3A17-3A-A)2(7-3B17-3A-A)8-2B17-3A-D8-2B17-3A-C8-2(2B17-2A11-)2A17-2AD10-2B17-2A12-2(B17-A13-)B17-A2D4-9C15-A7C9A15-17A15-8A-8A15-8A-4B4A15-8A-5B3A15-4A4B2-3(4B3A15-3A4B3-)3B4A15-3A4B4-2(6A15-4A2B5-)6A15-3A3B6-2(5A15-2A3B7-)5A15-3A2B7-5A15-4AB7-5A15-5A8-3(4A15-6A7-)2B2A15-6A7-3BA2(15-6A8-3B)15-3A3C8-2BA15-3A11-B2A15-4A10-3A15-3AD10-3B15-3A12-2(2B15-2A13-)2B15-2A6-9C15-A7C9A15-17A15-8A2-7A15-7A3-3B4A15-7A3-4B3A15-4A3B4-3(3B3A15-3A3B5-)2B4A15-3A3B6-5A15-4AB7-5A15-5A7-5A15-4AB8-4A15-2A2B2(9-4A15-A3B)9-4A15-2A2B9-4A15-4A10-3(3A15-3A11-)3A15-B2A11-B2A15-2BA12-2(BA15-2B13-)2A15-2B13-2A15-BA13-2A15-2A13-2B15-2A14-2(B15-A15-)B15-A8-9C13-2A7C2(-9A13-9A)2-8A13-8A3-2B6A13-8A3-3B5A13-6A2B4-3B4A13-5A2B2(5-3B4A13-4A3B)5-3B4A13-5A2B6-B5A2(13-6A7-6A)13-3A2BA8-5A13-2A3B2(9-5A13-A4B)9-5A13-2A3B9-5A13-3A2B10-4A13-4A11-4A13-A2BA3(11-4A13-4B)12-4(3A13-3B13-)3A13-2BA13-B2A13-3A14-BA2(13-2A15-2B)13-2A8-9C13-9C2(-9A13-9A)2-2(8A13-8A3-)2B6A13-8A4-2B5A13-6AB5-3B4A2(13-5A2B5-4B3A)13-6AB6-2B4A13-6A7-BA2B2A13-6A7-A4BA13-2A4B9-2(3BA13-A3B11-)2B2A2(13-A3B11-4A)13-2A2B12-3A13-A2B13-3A13-3B13-2BA5(13-3B)14-BA5(13-2B15-2A)13-BA16-2(B13-A17-)A13-A10-10C9-10C2(3-10A9-10A)4-2(9A9-9A5-)9A9-9A6-2B6A9-8A7-3B5A9-8A7-4B4A9-8A7-5B3A9-8A8-2(4B3A9-7A9-)5B2A9-4A3B10-2(4B2A9-3A3B11-)3B3A9-3A3B11-2B4A9-3A3B11-6A9-4A2B12-5A9-2A3B13-2B3A9-A4B13-3B2A9-5B13-4BA9-5B13-5B9-5B15-2(3B9-3B17-)A2B9-3B17-3A9-3B17-A2B9-3B17-3B9-3B18-2(2B9-2B19-)2B9-2A11-12C5-12C2(3-12A5-12A)4-4(11A5-)3A2B6A5-11A6-3(5B5A5-10A7-)6B4A5-10A9-4B4A5-4A2B2A11-4B4A5-3A4BA11-4B4A5-3A5B12-3B4A5-4A3B2(13-3B4A5-5A2B)13-2B5A5-6AB13-7A5-7A14-6A5-4A2B15-2B4A5-3A3B15-3B3A5-2A4B15-4B2A5-A5B15-5BA5-A5B17-2(4B5-A3B19-)3BA5-A3B19-2B2A5-4B19-3BA5-4B19-4B5-4B20-3B5-3B21-3B5-A2B21-3B5-3A13-27C2(5-27A)6-11A2E12A7-2A2B7A2EG11A7-A4B7A2G11A8-3(5B18A9-)5B13A2B3A10-4B12A4BA2(11-4B11A6B)13-2BA2B9A3B15-6B9A2B15-6B11A15-B2A2B12A15-17A16-6A2B7A17-B4A4B5AB17-2B3A4B4A2B17-4B2A2B4A3B17-5B6A4B19-3B2(2A2B)21-3BA4B2AB21-11B21-2BA8B21-2B2A7B21-3B2A2BA3B23-B5AB2(25-B6A)15-27C5-27A5-21A2B4A7-A2B15A4BA9-4B14A4BA9-5B14A2B2A10-3(4B17A11-)6B10A4BA12-2(6B8A5B13-)6B8A5B15-5B7A3B17-6B7A2B17-6B9A17-A4B10A17-2(2A2B)7A19-3A4B4A2(21-2A6B3A)21-2BA4B4A21-3BA2B4AB23-BA4BA2(25-7B)2(25-A6B)25-2A5B112-25C7-20A2B3A7-19A4B2A9-3B13A5B11-4B12A5B11-4B13A4B12-3B14A2B13-3B16A13-5B14A13-6B5A2B2A4B15-2(5B3A7B17-)5B4A2BA3B19-4B6AB3(21-4B7A)21-7B4A23-4(6BA25-)A4B2A305-23C9-18A4BA9-17A6B11-2B13A4B13-3B3A2B7A4B13-3B2A4B6A4B14-2B2A4B7A2B15-2B3A2B10A15-5B5A2B5A15-6B3A4B2A2B17-2(4B2A7B19-)4B3A6B22-2B3A2B3(25-2B5A)25-5B2A466-21C11-17A4B11-16A5B13-5A2B7A3B15-B3A4B6A3B15-2BA6B5A3B17-A6B6A19-2A4B7A19-5B2A4B2A19-4B2A6BA22-2(B2A4B25-)B2A4B628-17C15-16AB15-15A2B17-2A4B6AB19-A6B5AB19-A6B6A22-2(4B3A25-)3BA3B25-3A4B726-13C2(19-13A)22-3B4A2(25-4B3A)844-
