model
size = 14 26 13, scale = 0.05, origin = -y
material 
  colors = A:#FF6 B:#9CF C:#C63 D:#CF3
voxels
-------------- -----CCCC----- ----ACDCC----- ----ACDDC----- -------------- -------------- -------------- -------------- -------------- -------------- -------------- -------------- -------------- -------------- -------------- -------------- -------------- -------------- -------------- -------------- -------------- -------------- -------------- -------------- -------------- -------------- 
-----CCCC----- ----AB-BBA---- ----A---BA---- ----A----A---- --AAACCDDAAA-- -AAA------AAA- -AAA------AAA- AAAAA----AAAAA AAAAA----AAAAA AAAAA----AAAAA AAAAA----AAAAA AAAAA----AAAAA AAAAA----AAAAA AAAAA----AAAAA -AAAA----AAAA- -AAAA----AAAA- -AAAA----AAAA- -AAAA----AAAA- -AAAA----AAAA- -AAAA----AAAA- -AAAA----AAAA- -AAAACDDCAAAA- -AAA-CDCC-AAA- -----CCCC----- -----CCCC----- -------------- 
------CCC----- ----AC--CA---- ----AC---A---- --AAA----AAA-- -AAAA---CAAAA- AAA--------AAA AA----------AA AB--C----C--AA A---C----C---A A---C----C---A A---C----C---A A---C----C---A A---C----C---A AB--C----C--AA AB--C----C--AA AB--C----C--AA AB--C----C--AA AB--C----C--AA AB--C----C--AA AB--C----C--AA AB--BCCDDA--AA AB--B----A--AA ABBBAC--CABBAA -AAAA----AAAA- ----A----A---- ----ACCCCA---- 
-------------- ----AAAAAA---- ---AA----AA--- -AAAACC--AAAA- -AA-ACCCAA-AA- AA--CCCDDC--AA A---CDDDD----A A---ADDD-C---A A---BDD--C---A A---BDDC-C---A A---C-DDCC---A A---C--DDC---A A---C-DDDC---A A---C-DDDC---A A---BDDD-C---A A---BDD--C---A A---BDDC-C---A A---C-DDCA---A A---C-DDDA---A A---BCCCDA---A A---B-BB-A---A A---BBBBBA---A AB--BB--BB--AA -AAAB----BAAA- --AAA----AAA-- ----ACCCCA---- 
-------------- ----AAAAAA---- --AAA---AAAA-- -AAAA----AAAA- -A--AC---A--A- AA------BB--AA A---ABBBBC---A A---BBBBCB---A A---BBBCCB---A A---BBBCCB---A A---BCB-CB---A A---BCCB-B---A A---BC-BBB---A A---BCBBBB---A A---B-BBCB---A A---BBBCCB---A A---BBB-CB---A A---BCBB-B---A A---BCBBBB---A A---BCBBBB---A A---B-AABB---A A---BB--BB---A AB--BB---B--AA AAA-B----A-BBA -AAAA----AAAA- ----ACCCCA---- 
-------------- ----AAAAA----- --AAAA--AAAA-- -AA-A----A-AA- -A--A----A--A- AA------BB--AA A---B---BB---A A---B---BB---A A---B---BB---A A---B---BB---A A---B---BB---A A---B---BB---A A---B---BB---A A---B---BB---A A---B---BB---A A---B---BB---A A---B---BB---A A---B---BB---A A---B---BB---A A---B---BB---A A--BB----B---A A--BB----B---A A--BB----AB--A AA-AA----BB-BA -AAAA----AAAA- ---AAAAAAAA--- 
-------------- --AAAAAAAAAA-- --AAAAAAAAAA-- -AA-A---AA-AA- -A--A----A--A- AA-------B--AA A---B----B---A A---B----B---A A---B----B---A A---B----B---A A---B----B---A A---B----B---A A---B----B---A A---B----B---A A---B----B---A A---B----B---A A---B----B---A A---B----B---A A---B----B---A A--BB----B---A A--BB---CA---A A--BB----AB--A A--BB----AB--A AA-AC----AB-BA -AAAAA--AAAAA- ---AAAAAAAA--- 
-------------- --AAA----AAA-- --AAAAAAAAAA-- -AA-A-AAAA-AA- -A--A---AA--A- AA------BB--AA A---B----B---A A---B----B---A A---B----B---A A---B----B---A A---B----B---A A---B----B---A A---B----B---A A---B----B---A A---B----B---A A---B----B---A A---B----B---A A---B----B---A A---B----B---A A--BB----B---A A--BB----B---A A--BB----B---A A--BA----B---A AA-ABC--AB--BA -AAAAAAAAAAAA- ---AAAAAAAA--- 
-------------- -------------- --AAAAAAAAAA-- -AA-AAAAAA-AA- -A--ACCAAA--A- AA-----BBB--AA AA--BB--BB--AA A---BB--BB---A A---BB--BB---A A---BB--BB---A A---BB--BB---A A---BB--BB---A A---BB--BB---A A---BB--BB---A A---BB--BB---A A---BB--BB---A A---BB--BB---A A---BA--BB---A A---BA--BB---A A---BB--AB---A A---BB--AB---A A---BB--AB---A AB--BCAABB--AA AA--BBAABB--BA -AAAAAAAAAAAA- ---AA----AA--- 
-------------- -------------- --AAAAAAAAAA-- -AAA--AA--AAA- -AA--AAAA--AA- -A-----BB---A- AB---BBBB---AA AA---BBBB---AA AA---BBBB---AA AB---BBBB---AA AB---BBBB---AA AB---BBBB---AA AB---BBBB---AA AB---BBBB---AA AB---BBBB---AA AB---BAAB---AA AB---BAAB---AA AB---BABB---AA AB---BAAB---AA AB--BBAAB---AA AB--BBAAB---AA AB--BBAAB---AA AB---BBBB---AA -AA--BBBB--BA- -AAAAAAAAAAAA- ---AA----AA--- 
-------------- -------------- ---AAAAAAAA--- --AAAAAAAAAA-- -AAA------AAA- -AB--------BA- -A----------A- -A----------A- -A----------A- -A----------A- -A----------A- -A----------A- -A----------A- -A----------A- -A----------A- -A----------A- -A----------A- -A----------A- -A----------A- -A----------A- -A----------A- -A----------A- -A----------A- -AB--------BA- --AAAAAAAAAA-- -------------- 
-------------- -------------- -------------- ---AAAAAAAA--- --AAAAAAAAAA-- -AAAAAAAAAAAA- -AAAAAAAAAAAA- -AAAAAAAAAAAA- -AAAA----AAAA- -AAAA----AAAA- -AAA------AAA- -AAA------AAA- -AA--------AA- -AA--------AA- -AA--------AA- -AA--------AA- -AA--------AA- -AA--------AA- -AA--------AA- -AA--------AA- -AA--------AA- -AA--------AA- -AAA------AAA- -AAAAAAAAAAAA- --AAAAAAAAAA-- -------------- 
-------------- -------------- -------------- -------------- -------------- -------------- -------------- ----AAAAAA---- ----AAAAAA---- ---AAAAAAAA--- ---AAAAAAAA--- --AAAAAAAAAA-- --AAAAAAAAAA-- --AAAAAAAAAA-- --AAAAAAAAAA-- --AAAAAAAAAA-- --AAAAAAAAAA-- --AAAAAAAAAA-- --AAAAAAAAAA-- --AAAAAAAAAA-- --AAAAAAAAAA-- --AAAAAAAAAA-- --AAAAAAAAAA-- ---AAAAAAAA--- -------------- -------------- 
