model
size = 32, scale = 0.05, origin = -y
material 
  colors = A:#100 B:#EEE C:#001
voxels
783-7(A31-)A831-6(A31-)A927-3(A31-)A895-4(A31-)A895-A31-A63-A31-A863-A31-A95-A31-A831-2(A31-)A95-A31-A799-2(A31-)A159-A24-3(16B16-16A16-)16B16-16A503-2(A31-)A216-3(16B16-16A16-)16B16-16A471-2(A31-)A248-3(16B16-16A16-)16B16-16A407-3(A31-)A280-3(16B16-16A16-)16B16-16A343-4(A31-)A312-3(16B16-16A16-)16B16-16A279-4(A31-)A376-3(16B16-16A16-)16B16-16A183-5(A31-)A440-7BAC3(7B16-16A16-7B2A)7B16-16A23-6(2A30-)2(A31-)A504-6B2A2C3(6B16-16A16-6B2ABA)6B16-16A22-4(2A-A28-)2A30-2A600-6B2A2C3(6B16-16A16-6B4A)6B16-16A22-4(4A28-)4A27-6A2(26-2A2-2A)25-3A2-3A24-2A4-2A23-3A4-3A22-2A6-2A21-3A6-3A20-2A8-2A19-3A8-3A17-3A10-3A8-A6-3A12-3A6-3A4-3A14-3A4-4A3-3A16-3A3-4A-4A18-4A-7A22-9A24-11A18-15A16-8A8-7BAC3(7B16-16A16-7B2A)7B16-16A23-5(2A30-)3(A31-)A504-3(16B16-16A16-)16B16-16A183-5(A31-)A440-3(16B16-16A16-)16B16-16A279-4(A31-)A376-3(16B16-16A16-)16B16-16A343-4(A31-)A312-3(16B16-16A16-)16B16-16A407-3(A31-)A280-3(16B16-16A16-)16B16-16A471-2(A31-)A248-3(16B16-16A16-)16B16-16A503-2(A31-)A991-2(A31-)A159-A831-2(A31-)A95-A31-A863-A31-A95-A31-A895-A31-A63-A31-A895-4(A31-)A927-3(A31-)A831-6(A31-)A799-7(A31-)A16-
