model
size = 32, scale = 0.05, origin = -y
material 
  colors = A:#001 B:#BBB C:#FF0 D:#080 E:#E00
voxels
32A699-3C290-32A698-5C28-2(3E29-)3E194-32A426-5C237-D29-2C-2C28-2(E-E29-)E-E194-32A284-3(D31-)D44-7C236-D29-5C28-2(3E29-)3E194-28AB3A28-7(D31-)D159-D11-9C11-D191-D62-3C290-32A423-11C10-2(D31-)D127-D355-6A20B6A6-4(20A12-)20A269-11C25-2(3E29-)3E14-2(D31-)D387-6A20B6A6-4(20A12-)20A50-6(D31-)D26-5C-5C25-2(E-E29-)E-E466-6A20B6A6-4(20A12-)6AD13A18-D250-11C25-2(3E29-)3E466-6A20B6A6-2(20A12-)2(6AD13A12-)20A269-11C558-6A20B6A6-20A12-6AD13A3(12-20A)270-9C559-6A20B6A6-4(20A12-)20A271-7C560-6A20B6A6-4(20A12-)20A92-3(D31-)D83-5C39-4(D31-)D285-5C103-6A20B6A6-3(20A12-)16AD3A12-16AD3A28-D31-D159-2(D31-)D191-D31-D220-7C102-6A20B6A6-20A3(12-16AD3A)12-20A540-D187-9C101-6A20B6A6-4(20A12-)20A572-D31-D122-11C100-6A20B6A6-4(20A12-)20A473-5C158-D90-11C25-2(3E29-)3E8-6A20B6A6-4(20A12-)20A236-2(D31-)D170-9C188-D31-D26-5C-5C25-2(E-E29-)E-E8-6A20B6A6-4(20A12-)20A204-D31-D95-D31-D105-11C246-11C25-2(3E29-)3E8-6A20B6A6-20A2(12-D19A)2(12-20A)204-D159-D105-11C246-11C100-6A20B6A6-3(20A12-)D19A12-20A204-D127-D136-13C246-9C101-6A20B6A6-4(20A12-)D19A204-D127-D136-13C24-2(3E29-)3E156-7C102-6A20B6A6-5(20A12-)D31-D159-D31-D95-D78-D31-D25-6C-6C24-2(E-E29-)E-E14-3C140-5C103-6A20B6A6-4(20A12-)20A76-D31-D159-D31-D46-2(D31-)D57-13C24-2(3E29-)3E13-5C247-6A20B6A6-4(20A12-)20A140-4(D31-)D14-D31-D16-D14-D16-D31-D72-13C103-7C27-2(3E29-)3E152-6A20B6A6-4(20A12-)20A251-D31-D144-D31-D9-11C11-2(D31-)D28-3C-3C27-2(E-E29-)E-E152-6A16B10A6-4(20A12-)20A219-D31-D218-11C104-7C27-2(3E29-)3E152-32A341-D31-D251-9C106-5C247-32A277-D31-D317-5C109-3C248-32A277-D714-32A213-D31-D746-32A21-5(D31-)D810-
