model
size = 22 24 9, scale = 0.05, origin = -y
material 
  colors = A:#385460 B:#476673 C:#161616 D:#E4E4E4 E:#272A3D
voxels
------A--------------- ------AAAA------------ ---------AA----------- -------AAAA----------- ------AAAAA----------- ------AAAAA----------- ------AAAAA----------- ------AAAAA----------- ------AAAAA----------- ---------------------- ------------------A--- --------------AAAAA--- --------------AA------ --------------AA------ ---------------------- ---------------------- ---------------------- ---------------------- ---------------------- ---------------------- ---------------------- ---------------------- ---------------------- ---------------------- 
---------------------- ---------------------- ---------------------- -------AAAA----------- -------AAAA----------- ------AAAAAA---------- ------AAAAAA---------- ------AAAAAA---------- ------AAAAAA---------- ------AAAAAA---------- ---------------------- --------------A------- --------------AA------ --------------AA------ ---------------------- ---------------------- ---------------------- ---------------------- ---------------------- ---------------------- ---------------------- ---------------------- ---------------------- ---------------------- 
---------------------- ---------------------- ---------------------- ---------------------- ---------------------- -----AAAAAAAAAA------- ----AAAAAAAAAAAA------ ---AAAAAAAAAAAAA------ --AAAAAAAAAAAAAAA----- --AAAAAAAAAAAAAAA----- --AAAAAAAAAAAAAAA----- -AAAAAAAAAAAAAAAA----- --AA---AAAAAAAAAA----- ---------AAAAAAAA----- ----------AAAAAAA----- ---------------------- -----------AAAAAAAAAA- -----------AAAAAA----- -----------AAAAAAAAAAA -----------AAAAAAAAAAA -----------AAAAAAAAAAA -----------AAADAAAAAAA -----------AABBBAAAAAA ------------AAAAAAAAA- 
---------------------- ---------------------- ---------------------- ---------------------- -------AABBB---------- -----AAAAAAABBB------- ----AAAAAAAAAAAB------ ---AAAAAAAAAAAAAB----- --AAAAAAAAAAAAAAB----- --AAAAAAAAAAAAAAB----- -AAAAAAAAAAAAAAAB----- -AAAAAAAAAAAAAAAB----- -AAAA--AAAAAAAAAA----- AAAA----AAAAAAAAA----- AAA------AAAAAAAA----- -A----------AAAA------ -----------AAAAAAAAAA- -----------AAACA------ -----------AAAAAAAAAAA -----------AAAAAAAAAAA -----------AAAAAAAAAAA -----------AAAAAAAAAAE -----------AAAAAAAAAAA ------------AAAAAAAAA- 
---------------------- ---------------------- ---------------------- ---------------------- -------AAABB---------- -----AAAAAAABBB------- ----AAAAAAAAAAAB------ ---AAAAAAAAAAAAAB----- --AAAAAAAAAAAAAAB----- --AAAAAAAAAAAAAAB----- -AAAAAAAAAAAAAAAB----- -AAAAAAAAAAAAAAAB----- AAAAA--AAAAAAAAAA----- AAAA----AAAAAAAAA----- AAA------AAAAAAAA----- AAA--------AAAAA------ AA---------AAAAAAAAAA- -----------AAAC------- -----------AAAAAAAAAAA -----------AAAAAAAAAAA -----------AAAAAAAAAAA -----------AAAAAAAAAAA -----------AAAAAAAAAAA ------------AAAAAAAAA- 
---------------------- ---------------------- ---------------------- ---------------------- -------AABBB---------- -----AAAAAAABBB------- ----AAAAAAAAAAAB------ ---AAAAAAAAAAAAAB----- --AAAAAAAAAAAAAAB----- --AAAAAAAAAAAAAAB----- -AAAAAAAAAAAAAAAB----- -AAAAAAAAAAAAAAAB----- AAAA---AAAAAAAAAA----- AAAA----AAAAAAAAA----- AAA------AAAAAAAA----- AA----------AAAA------ AA---------AAAAAAAAAA- A----------AAACA------ -----------AAAAAAAAAAA -----------AAAAAAAAAAA -----------AAAAAAAAAAA -----------AAAAAAAAAAE -----------AAAAAAAAAAA ------------AAAAAAAAA- 
---------------------- ---------------------- ---------------------- ---------------------- ---------------------- -----AAAAAAAAAA------- ----AAAAAAAAAAAA------ ---AAAAAAAAAAAAA------ ---AAAAAAAAAAAAAA----- --AAAAAAAAAAAAAAA----- --AAAAAAAAAAAAAAA----- -AAAAAAAAAAAAAAAA----- -AAA---AAAAAAAAAA----- --A------AAAAAAAA----- ----------AAAAAAA----- ---------------------- A----------AAAAAAAAAA- A----------AAAAAA----- -----------AAAAAAAAAAA -----------AAAAAAAAAAA -----------AAAAAAAAAAA -----------AAADAAAAAAA -----------AABBBAAAAAA ------------AAAAAAAAA- 
---------------------- ---------------------- ---------------------- ----------AAAA-------- ----------AAAAA------- -------AAAAAAAA------- -------AAAAAAAA------- -------AAAAAAAA------- -------AAAAAA--------- --------AAAAA--------- ---------------------- ---------------A------ ---------------AA----- ---------------AA----- ---------------------- ---------------------- ---------------------- A--------------------- A--------------------- ---------------------- ---------------------- ---------------------- ---------------------- ---------------------- 
--------------AA------ --------------A------- --------------A------- ----------AAAAA------- ----------AAAAA------- ----------AAAAA------- ----------AAAAA------- ----------AAAAA------- ---------------------- ---------------------- -------------------A-- ---------------AAAAA-- ---------------AA----- ---------------AA----- ---------------------- ---------------------- ---------------------- ---------------------- ---------------------- ---------------------- ---------------------- ---------------------- ---------------------- ---------------------- 
