model
size = 13 22 16, scale = 0.05, origin = -y
material 
  colors = A:#FF0 B:#080 C:#E00
voxels
------------- ------------- ------------- ------------- ------------- ------------- ------------- ------------- ------------- ------------- ------------- ------------- ------------- ------------- ------------- ------------- ------------- ------------- ----AAAAA---- ------------- ------------- ------------- 
------------- ------------- ------------- ------------- ------------- ------------- ------------- ------------- ------------- ------------- ------------- ------------- ------------- ------------- ------------- ------------- ------------- ------------- --AAAAAAAAA-- ------------- ------------- ------------- 
------------- ------------- ------------- ------------- ------------- ------------- ------------- ------------- ------------- ------------- ------------- ------------- ------------- ------------- ------------- ------------- ------------- ------------- -AAAAAAAAAAA- ------------- ------------- ------------- 
------------- ------------- ------------- ------------- ------------- ------------- ------------- ------------- ------------- ------------- ------------- ------------- ------------- ------------- ------------- ------------- ------------- ------------- -AAAAAAAAAAA- ------------- ------------- ------------- 
------------- ------------- ------------- ------------- ------------- ------------- ------------- ------------- ------------- ------------- ------------- ------------- ------------- ------------- ------------- ------------- ------------- ------------- AAAAAAAAAAAAA ------------- ------------- ------------- 
------------- ------------- ------------- ------------- ------------- ------------- ------------- ------------- ------------- ------------- ------------- ------------- ------------- ------------- ------------- ------------- ------------- ------------- AAAAAAAAAAAAA -----CCC----- -----CCC----- -----CCC----- 
------------- ------------- ------------- ------------- ------------- ------------- ------------- ------------- ------------- ------------- ------------- ------------- ------------- ------------- ------------- ------------- ------B------ ------B------ AAAAAA-AAAAAA -----C-C----- -----C-C----- -----C-C----- 
------------- ------------- ------------- ------------- ------------- ------------- ------------- ------------- ------------- ------------- ------------- ------------- ------------- ------------- ------B------ ------B------ ------B------ ------------- AAAAAAAAAAAAA -----CCC----- -----CCC----- -----CCC----- 
------------- ------------- ------------- ------------- ------------- ------------- ------------- ------------- ------------- ------------- ------------- ------------- ------B------ ------B------ ------B------ ------------- ------------- ------------- AAAAAAAAAAAAA ------------- ------------- ------------- 
------------- ------------- ------------- ------------- ------------- ------------- ------------- ------------- ------------- ------------- ------------- ------B------ ------B------ ------------- ------------- ------------- ------------- ------------- -AAAAAAAAAAA- ------------- ------------- ------------- 
------------- ------------- ------------- ------------- ------------- ------------- ------------- ------------- ------------- ------------- ------B------ ------B------ ------------- ------------- ------------- ------------- ------------- ------------- -AAAAAAAAAAA- ------------- ------------- ------------- 
------------- ------------- ------------- ------------- ------------- ------------- ------------- ------------- ------------- ------B------ ------B------ ------------- ------------- ------------- ------------- ------------- ------------- ------------- --AAAAAAAAA-- ------------- ------------- ------------- 
------------- ------------- ------------- ------------- ------------- ------------- ------------- ------B------ ------B------ ------------- ------------- ------------- ------------- ------------- ------------- ------------- ------------- ------------- ----AAAAA---- ------------- ------------- ------------- 
------------- ------------- ------------- ------------- ------------- ------------- ------------- ------B------ ------------- ------------- ------------- ------------- ------------- ------------- ------------- ------------- ------------- ------------- ------------- ------------- ------------- ------------- 
------------- ------------- ------------- ------------- ------------- ------B------ ------B------ ------------- ------------- ------------- ------------- ------------- ------------- ------------- ------------- ------------- ------------- ------------- ------------- ------------- ------------- ------------- 
------B------ ------B------ ------B------ ------B------ ------B------ ------------- ------------- ------------- ------------- ------------- ------------- ------------- ------------- ------------- ------------- ------------- ------------- ------------- ------------- ------------- ------------- ------------- 
