model
size = 26 31 26, scale = 0.05, origin = -y
material 
  colors = A:#BBB B:#888 C:#09F D:#F90
voxels
----------BBBBB----------- ---------DDDDDDD---------- -------------------------- -------------------------- -------------------------- -------------------------- -------------------------- -------------------------- -------------------------- -------------------------- -------------------------- -------------------------- -------------------------- -------------------------- -------------------------- -------------------------- -------------------------- -------------------------- -------------------------- -------------------------- -------------------------- -------------------------- -------------------------- -------------------------- -------------------------- -------------------------- -------------------------- -------------------------- -------------------------- -------------------------- -------------------------- 
--------BBBBBBBBB--------- -------BDCCCCCCCDB-------- -------DDDDDDDDDDD-------- -----------DDD------------ ----------DDDDD----------- ----------DDDDD----------- ----------DDDDD----------- -------------------------- -------------------------- -------------------------- -------------------------- -------------------------- -------------------------- -------------------------- -------------------------- -------------------------- -------------------------- -------------------------- -------------------------- -------------------------- -------------------------- -------------------------- -------------------------- -------------------------- -------------------------- -------------------------- -------------------------- -------------------------- -------------------------- -------------------------- -------------------------- 
---------BBBBBBB---------- ------BBBCCCAACCBBB------- ------BCCCCAAAACCCB------- ------BBBBBAAABBBBB------- ------BBBBAAAAABBBBB------ --------BBAAAAABB--------- ---------BCAAACBB--------- ---------BBBBBBB---------- ---------BBBBBBB---------- -----------BBB------------ -------------------------- -------------------------- -------------------------- -------------------------- -------------------------- -------------------------- -------------------------- -------------------------- -------------------------- -------------------------- -------------------------- -------------------------- -------------------------- -------------------------- -------------------------- -------------------------- -------------------------- -------------------------- -------------------------- -------------------------- -------------------------- 
----------BB--B----------- -------BBBAA--ABBBB------- -----BBCCAA----ACCCB------ -----DCCCA-----ACCCD------ -----DDCCA-----ACCCD------ -------DCA-----ACDDD------ -------DDAA---AACD-------- -------DDCAA-AAADD-------- --------DCAAAAACD--------- --------DDDCACDDD--------- ----------DDDDDD---------- -------------------------- -------------------------- -------------------------- -------------------------- -------------------------- -------------------------- -------------------------- -------------------------- -------------------------- -------------------------- -------------------------- -------------------------- -------------------------- -------------------------- -------------------------- -------------------------- -------------------------- -------------------------- -------------------------- -------------------------- 
-------------------------- --------B-------B--------- -----BBBA-------ABBB------ ----BCCCA-------AACCB----- ----BCCCA-------AACCDB---- ----BBBAA-------AACDD----- ------BCA-------ACB------- ------BCAA------ACB------- ------BBCA-----ACBB------- -------BCCAA-AACCB-------- --------BBCCACCCB--------- ---------BBBBBBB---------- -------------------------- -------------------------- ----------BBBB------------ ----------B--B------------ ---------B----B----------- --------B------B---------- -------B--------B--------- -------B--------B--------- ------B----------B-------- ------B----------B-------- ------B----------B-------- -------B--------B--------- --------B------B---------- ---------B----B----------- ----------BBBB------------ -------------------------- -------------------------- -------------------------- -------------------------- 
-------------------------- -------------------------- -------B----------B------- -----AAA----------AA------ ---BBCAA----------ACAB---- ---BCCA-----------ACCDB--- ---BDDAA---------AADDD---- -----DCA---------ACDD----- -----DCCA-------ACCD------ ------DCCA-----ACCDD------ -------DCCAAAAACCDD------- --------DCCCACCDDD-------- ---------AAAAAA----------- ---------AAAAAA----------- ---------ACAACA----------- --------AAA--AAA---------- -------AAA-----AA--------- ------AAA-------AA-------- ------AA---------A-------- ------AA---------AA------- -----AA-----------A------- -----AA-----------AA------ -----AA-----------A------- ------AA--------AA-------- -------AA------AA--------- --------AA----AA---------- ---------AAAAAA----------- ----------AAAA------------ -----------AAA------------ -------------------------- -------------------------- 
-------------------------- -------------------------- -------------------------- -------------------------- ----BB-------------AA----- --BACA-------------ACAB--- --BCCA-------------ACCB--- --BDDCA-----------ACCDB--- --BDDCAA---------AACDD---- -----DCAA-------AACCD----- -----DDCAA-----AACCD------ ------DDCCAA-AACCCD------- --------DCAAAAAAAD-------- ---------AAAAAAA---------- ---------AAAAAAAA--------- -------AAAAAAAACAA-------- -------AA------ACA-------- ------ACA-------ACA------- ------AA---------AA------- -----ACA---------AA------- -----ACA----------AAB----- -----AA-----------ACB----- ----BCCA----------AA------ -----ACA---------AAA------ ------ACA-------AA-------- -------ACA-----AA--------- --------ACAAAAAA---------- ---------ACCCCAA---------- ----------AAAAA----------- -------------------------- -------------------------- 
-------------------------- -------------------------- -------------------------- -------------------------- -------------------------- ---AA---------------AA---- -BACA---------------ACAB-- -BCCCA-------------ACCCB-- -BDDCA-------------ACCDB-- ----DCA-----------ACCD---- ----DCCA---------ACCD----- -----DCCAA-----AACCD------ ------DDCA-----ACCD------- --------AA-----AAA-------- ---------A-----ACA-------- -------AAA-----ACA-------- -------AA------ACCA------- ------ACA-------ACA------- ------AA---------AA------- -----ACA---------AA------- -----ACA----------AAB----- -----AA-----------ACB----- ----BCCA----------AA------ ----BACA---------ACA------ ------ACA-------AAA------- -------AAA-----AAA-------- -------AACAAAAACA--------- ---------ACCCCCA---------- ---------AAAAAAA---------- -------------------------- -------------------------- 
-------------------------- -------------------------- -------------------------- -------------------------- -------------------------- -------------------------- --AAA---------------AAAB-- -BCCA---------------ACCB-- -BCCA---------------ACCB-- -BDDCA-------------ACCDB-- ---DCCA-----------ACCD---- ----DCCA---------ACCD----- -----DDCA-------AADD------ -------AA-------AA-------- --------A-------AA-------- -------AA-------ACA------- ------ACA-------ACA------- ------AAA--------AA------- -----AA-----------AA------ ----BCA-----------AA------ ----BCA-----------ACB----- ----BCA-----------ACB----- ----BCA-----------ACB----- ----BCA-----------ACB----- -----ACA----------AA------ ------AA---------AA------- ------ACAAA----AAA-------- -------AACCAAAACA--------- ---------ACCCCCA---------- ----------BBBBB----------- -------------------------- 
-------------------------- -------------------------- -------------------------- -------------------------- -------------------------- -------------------------- -------------------------- -BAA-----------------AAB-- -BCCA----------------ACB-- -BCCA---------------ACDB-- -BDCCA-------------ACD---- ---DCCA-----------ACCD---- ----DDCA---------ACDD----- ------AA---------AA------- -------A---------A-------- -------A---------AA------- ------AA---------AA------- -----AA-----------AA------ -----AA-----------AA------ ----BCA------------AB----- ----BCA------------AB----- ----BCA-----------ACB----- ----BCA-----------ACB----- ----BA------------ACB----- -----AA-----------ACB----- -----AA-----------AA------ ------AA---------AA------- -------AAAAAAAAAAA-------- --------ACCCCCCCA--------- ---------BBBBBBB---------- -------------------------- 
-------------------------- -------------------------- -------------------------- -------------------------- -------------------------- -------------------------- -------------------------- -------------------------- -BAA-----------------AAAB- BCCCA----------------ACCB- BDCCA---------------ACDDB- --DCCA-------------ACCD--- ---DDCAA----------ACDD---- -----DCA----------AD------ ------AA----------A------- ------AA----------A------- -----ACA----------AA------ -----AA-----------AA------ ----BA-------------AB----- ----BA-------------AB----- ----BA-------------ACB---- ----BA-------------ACB---- ----BA-------------ACB---- ----BA------------ACB----- ----BA------------ACB----- -----AA-----------ACB----- -----ACA---------ACA------ ------ACA-------ACA------- -------AAAAAAAAAAA-------- ---------BCCCCCB---------- ----------BBBBB----------- 
-------------------------- -------------------------- -------------------------- -------------------------- -------------------------- -------------------------- -------------------------- -------------------------- --A-------------------A--- BACA------------------AAAB BCCA-----------------ACCCB BDCCA---------------ACDDB- --DDDAA-----------AADD---- -----DA-----------AD------ ------A-----------A------- ------A-----------A------- -----AA-----------AA------ ----BA-------------AB----- ----BA-------------AB----- ----BA--------------B----- ---BCA-------------ACB---- ---BCA-------------ACB---- ---BCA-------------ACB---- ---BCA-------------ACB---- ----BA-------------ACB---- -----A-------------AB----- -----AA-----------AA------ ------AA---------ACA------ -------AAAAAAAAAAAA------- ---------ACCCCCA---------- ---------BBBBBBB---------- 
-------------------------- -------------------------- -------------------------- -------------------------- -------------------------- -------------------------- -------------------------- -------------------------- -------------------------- -AA-------------------AA-- BCA------------------ACCB- BCCA-----------------ACCB- BDDCAAA-----------AAACDDB- -D-DDDA-----------ADDD---- ------A-----------A------- ------A-----------A------- -----AA-----------AA------ ----BA-------------AB----- ----B---------------B----- ----BA--------------B----- ---BCA--------------B----- ---BCA--------------AB---- ---BCA-------------ACB---- ----BA-------------ACB---- ----BA-------------ACB---- ----BA-------------AB----- -----AA-----------ACB----- ------AA---------AAA------ -------AAA-----AAA-------- --------BBAAAAABB--------- ----------BBBBB----------- 
-------------------------- -------------------------- -------------------------- -------------------------- -------------------------- -------------------------- -------------------------- -------------------------- -------------------------- -------------------------- BAA------------------AAAB- BCCA-----------------ACCB- BCDCAAA-----------AAACDD-- -D-DDDA-----------ADDD---- ------A-----------A------- ------A-----------AA------ -----AA-----------AA------ ----BA-------------AB----- ----B---------------B----- ----B---------------B----- ----B---------------B----- ----B---------------B----- ----B---------------B----- ----B---------------B----- ----BA--------------B----- ----BA-------------AB----- -----AA-----------AA------ ------AA---------AAA------ -------AAA------AA-------- --------BBBBBBBBB--------- -------------------------- 
-------------------------- -------------------------- -------------------------- -------------------------- -------------------------- -------------------------- -------------------------- -------------------------- -------------------------- BAA-------------------DDDB BCCA-----------------ACCCB BDCCA----------------ACDB- -DDDCAA-----------AAADDD-- ----DDA-----------ADD----- ------A-----------A------- ------A-----------A------- -----AA-----------AA------ ----BA-------------AB----- ----BA--------------B----- ----B---------------B----- ----B---------------B----- ----B---------------B----- ----B---------------B----- ----B---------------B----- ----BA-------------AB----- -----A-------------AB----- -----AA-----------AA------ ------AA---------AA------- -------AAA-----AAA-------- ---------BBBBBBBB--------- -------------------------- 
-------------------------- -------------------------- -------------------------- -------------------------- -------------------------- -------------------------- -------------------------- -------------------------- BAA-------------------DDB- BCCA------------------ACCB BDCA-----------------ACDB- --DCA---------------ACD--- ---DDAA-----------AADD---- -----DA-----------AD------ ------A-----------A------- ------A-----------A------- -----AA-----------AA------ -----A-------------AB----- ----BA-------------AB----- ----BA--------------B----- ----B---------------B----- ----B---------------B----- ----B---------------B----- ----BA--------------B----- ----BA-------------AB----- -----AA------------A------ -----AA-----------AA------ ------AAA-------AAA------- -------AAAA---AAAA-------- ---------BBBBBBB---------- -------------------------- 
-------------------------- -------------------------- -------------------------- -------------------------- -------------------------- -------------------------- -------------------------- --AA-----------------AA--- BACA-----------------ACAB- BCCCA----------------ACDB- BDDCA---------------ACD-B- ---DCAA------------ACCD--- ----DCCA---------AACDD---- -----DDA---------ACD------ -------A---------AA------- ------AA---------AA------- -----ACA---------ACA------ -----AA-----------AA------ -----A-------------AB----- ----BA-------------AB----- ----BA-------------AB----- ----BA--------------B----- ----BA-------------AB----- ----BA-------------AB----- -----A-------------AB----- -----AA-----------AA------ ------AA---------ACA------ ------AAA-------AAA------- --------AAAAAAAAA--------- ----------BBBBB----------- -------------------------- 
-------------------------- -------------------------- -------------------------- -------------------------- -------------------------- -------------------------- ---AA---------------AA---- -BACA---------------ACAB-- -BCCA---------------ACCCB- -BDCCA--------------ACDDB- ---DCAA------------ACD---- ----DCCA---------AACDD---- -----DCCA-------ACCDD----- ------DCA-------ACD------- -------AA-------AA-------- -------AA-------AA-------- ------ACA-------ACA------- -----ACA---------ACA------ -----AA-----------AA------ -----AA------------A------ -----A-------------AB----- -----A-------------AB----- -----A-------------AB----- -----AA------------A------ -----AA-----------AA------ -----ACA---------ACA------ ------ACA-------ACA------- -------ACAA---AACA-------- --------AAAAAAAAA--------- -------------------------- -------------------------- 
-------------------------- -------------------------- -------------------------- -------------------------- -------------------------- ----A---------------A----- --BAA---------------AAB--- -BCCCA--------------ACCB-- -BDCCA-------------ACCDB-- ---DCCA-----------AACD---- ----DCCA---------AACD----- -----DCCA-------ACCD------ ------DCCA-----ACCD------- -------DAA-----AAA-------- --------AA-----AA--------- --------AA-----AA--------- -------ACA-----ACA-------- ------ACA-------ACA------- ------AA---------ACA------ -----AA-----------AA------ -----AA-----------AA------ -----AA-----------AA------ -----AA-----------AA------ -----AA-----------AA------ ------AA---------ACA------ ------ACA-------ACA------- -------ACAA---AACA-------- --------AACAAACAA--------- ----------AAAAA----------- -------------------------- -------------------------- 
-------------------------- -------------------------- -------------------------- -------------------------- -----A-------------A------ ---BAA-------------AAAB--- --BCCA-------------ACCB--- --BDDCA------------ACDB--- ---DDCA-----------ACDDB--- ----DCCA---------ACCD----- -----DCCA-------ACCD------ ------DCCAA---AACCD------- -------DDCAAAAACDD-------- ---------AAAAAAD---------- ----------AAAAA----------- ---------AAAAAAA---------- --------AAAAAAAAA--------- -------ACAA---AACA-------- ------AAA-------AAA------- ------AAA-------AAA------- -----ACA---------ACA------ -----ACA---------ACA------ -----ACA---------ACA------ -----ACAA-------AACA------ ------AAAA-----AAAA------- -------AAAA---AAAA-------- --------AACAAACAA--------- ----------AAAAA----------- -------------------------- -------------------------- -------------------------- 
-------------------------- -------------------------- -------------------------- -----AA-----------AA------ ---BACA-----------ACBB---- ---BCCA-----------ACCCB--- ---BDCA-----------ACDD---- -----DCA----------ACD----- -----DCA---------ACD------ -----DDCA-------ACCD------ ------DCCA-----ACCD------- -------DCCAAAAACCD-------- --------DDDCCCCDD--------- -----------DDDD----------- -------------------------- -------------------------- ----------AAAAA----------- --------AAAAAAAAA--------- --------AAAAAAAAA--------- -------AAAA---AAAA-------- ------AAAA-----AAAA------- ----BBCAAA-----AACCB------ ----BBCAAA-----AACCB------ ------AAAAA---AAAAA------- --------AAAAAAAAA--------- ---------AAAAAAA---------- ----------AAAAA----------- -------------------------- -------------------------- -------------------------- -------------------------- 
-------------------------- -------------------------- ------AA---------AA------- ----BACA---------ACAB----- ---BCCCA---------ACCCB---- ---BDCCA---------ACCDB---- ---B-DCA---------ACD------ -----DDCA-------AACD------ ------DCA-------ACDD------ -------DCAA---AACDD------- -------DDCAAAAACCD-------- --------DDCCCCCDD--------- ----------DDDDD----------- -------------------------- -------------------------- -------------------------- -------------------------- -------------------------- ----------BBBBB----------- ---------BBBBBBB---------- ---------BBBBBBB---------- ----BBB--BBBBBBB-BBBB----- ----BBB--BBBBBBB-BBBB----- ---------BBBBBBB---------- ----------BBBBB----------- -------------------------- -------------------------- -------------------------- -------------------------- -------------------------- -------------------------- 
-------------------------- -------AAA-----BBB-------- -----AACAA-----AACAB------ ----BCCCAA------ACCCB----- ----BCCDA-------ABCCB----- ----BDDDAA------ABBBB----- ------DDAA-----AABB------- -------DCA-----ACBB------- -------DCAAA-AAACB-------- --------DCCAAACCD--------- ---------DDCCCDDD--------- ----------DDDDD----------- -------------------------- -------------------------- -------------------------- -------------------------- -------------------------- -------------------------- -------------------------- -------------------------- -----BB----------BBB------ ----BCB----------ACCB----- ----BBB----------BBBB----- -------------------------- -------------------------- -------------------------- -------------------------- -------------------------- -------------------------- -------------------------- -------------------------- 
---------BBBBBBB---------- ------BAACAAAAACBBB------- -----BBCCCAA-AACCCCB------ -----BBDDCAA-AAADDCB------ -----BB-DAAA-AAAD-BB------ -----B--DCAA-AAAD--------- --------DCAAAAACD--------- --------DDAAAAADD--------- --------DDDCACDDD--------- ---------DDDDDDD---------- -----------DDD------------ -------------------------- -------------------------- -------------------------- -------------------------- -------------------------- -------------------------- -------------------------- -------------------------- -------------------------- -----BB----------BBB------ -----BB----------BCB------ -----BB----------BBB------ -------------------------- -------------------------- -------------------------- -------------------------- -------------------------- -------------------------- -------------------------- -------------------------- 
--------BBBBBBBBB--------- -------BCCCCCCCCCB-------- -------BDCDCACDCDBB------- -------B-DDDDDDD-BB------- ---------DDDDDDD---------- ---------DDDDDDD---------- ---------DDDDDDD---------- ----------DDDDD----------- -----------DDD------------ -------------------------- -------------------------- -------------------------- -------------------------- -------------------------- -------------------------- -------------------------- -------------------------- -------------------------- -------------------------- -------------------------- -------------------------- ------------------B------- -------------------------- -------------------------- -------------------------- -------------------------- -------------------------- -------------------------- -------------------------- -------------------------- -------------------------- 
---------BBBBBBBB--------- --------BBBBBBBBB--------- --------BB-BBB-BB--------- -------------------------- -------------------------- -------------------------- -------------------------- -------------------------- -------------------------- -------------------------- -------------------------- -------------------------- -------------------------- -------------------------- -------------------------- -------------------------- -------------------------- -------------------------- -------------------------- -------------------------- -------------------------- -------------------------- -------------------------- -------------------------- -------------------------- -------------------------- -------------------------- -------------------------- -------------------------- -------------------------- -------------------------- 
