model
size = 11 30 11, scale = 0.05, origin = -y
material 
  colors = A:#FF0 B:#080 C:#E00
voxels
----------- ----------- ----------- ----------- ----------- ----------- -----B----- -----B----- -----B----- -----B----- ----------- ----------- ----------- -----B----- -----B----- -----B----- -----B----- -----B----- ----------- ----------- ----------- ----------- ----------- ----------- ----------- ----------- ---AAAAA--- ----------- ----------- ----------- 
----------- ----------- -----B----- -----B----- -----B----- -----B----- ----------- ----------- ----------- ----------- -----B----- -----B----- -----B----- ----------- ----------- ----------- ----------- ----------- -----B----- -----B----- ----------- ----------- ----------- ----------- ----------- ----------- --AAAAAAA-- ----------- ----------- ----------- 
-----B----- -----B----- -----B----- ----------- ----------- ----------- ----------- ----------- ----------- ----------- ----------- ----------- ----------- ----------- ----------- ----------- ----------- ----------- ----------- ----------- -----B----- ----------- ----------- ----------- ----------- ----------- -AAAAAAAAA- ----------- ----------- ----------- 
----------- ----------- ----------- ----------- ----------- ----------- ----------- ----------- ----------- ----------- ----------- ----------- ----------- ----------- ----------- ----------- ----------- ----------- ----------- ----------- ----------- -----B----- -----B----- ----------- ----------- ----------- AAAAAAAAAAA ----------- ----------- ----------- 
----------- ----------- ----------- ----------- ----------- ----------- ----------- ----------- ----------- ----------- ----------- ----------- ----------- ----------- ----------- ----------- ----------- ----------- ----------- ----------- ----------- ----------- ----------- -----B----- ----------- ----------- AAAAAAAAAAA ----CCC---- ----CCC---- ----CCC---- 
----------- ----------- ----------- ----------- ----------- ----------- ----------- ----------- ----------- ----------- ----------- ----------- ----------- ----------- ----------- ----------- ----------- ----------- ----------- ----------- ----------- ----------- ----------- ----------- -----B----- -----B----- AAAAA-AAAAA ----C-C---- ----C-C---- ----C-C---- 
----------- ----------- ----------- ----------- ----------- ----------- ----------- ----------- ----------- ----------- ----------- ----------- ----------- ----------- ----------- ----------- ----------- ----------- ----------- ----------- ----------- ----------- ----------- ----------- ----------- ----------- AAAAAAAAAAA ----CCC---- ----CCC---- ----CCC---- 
----------- ----------- ----------- ----------- ----------- ----------- ----------- ----------- ----------- ----------- ----------- ----------- ----------- ----------- ----------- ----------- ----------- ----------- ----------- ----------- ----------- ----------- ----------- ----------- ----------- ----------- AAAAAAAAAAA ----------- ----------- ----------- 
----------- ----------- ----------- ----------- ----------- ----------- ----------- ----------- ----------- ----------- ----------- ----------- ----------- ----------- ----------- ----------- ----------- ----------- ----------- ----------- ----------- ----------- ----------- ----------- ----------- ----------- -AAAAAAAAA- ----------- ----------- ----------- 
----------- ----------- ----------- ----------- ----------- ----------- ----------- ----------- ----------- ----------- ----------- ----------- ----------- ----------- ----------- ----------- ----------- ----------- ----------- ----------- ----------- ----------- ----------- ----------- ----------- ----------- --AAAAAAA-- ----------- ----------- ----------- 
----------- ----------- ----------- ----------- ----------- ----------- ----------- ----------- ----------- ----------- ----------- ----------- ----------- ----------- ----------- ----------- ----------- ----------- ----------- ----------- ----------- ----------- ----------- ----------- ----------- ----------- ---AAAAA--- ----------- ----------- ----------- 
