model
size = 11 16 11, scale = 0.05, origin = -y
material 
  colors = A:#FF0 B:#E00 C:#080
voxels
----------- ----------- ----------- ----------- ----------- ----------- ----------- ----------- ----------- ----------- ----------- ----------- ---AAAAA--- ----------- ----------- ----------- 
----------- ----------- ----------- ----------- ----------- ----------- ----------- ----------- ----------- ----------- ----------- ----------- --AAAAAAA-- ----------- ----------- ----------- 
----------- ----------- ----------- ----------- ----------- ----------- ----------- ----------- ----------- ----------- ----------- ----------- -AAAAAAAAA- ----------- ----------- ----------- 
----------- ----------- ----------- ----------- ----------- ----------- ----------- ----------- ----------- ----------- ----------- ----------- AAAAAAAAAAA ----------- ----------- ----------- 
----------- ----------- ----------- ----------- ----------- ----------- ----------- ----------- ----------- ----------- ----------- ----------- AAAAAAAAAAA ----BBB---- ----BBB---- ----BBB---- 
----------- ----------- ----------- ----------- ----------- -----C----- -----C----- -----C----- -----C----- -----C----- -----C----- -----C----- AAAAA-AAAAA ----B-B---- ----B-B---- ----B-B---- 
----------- ----------- ----------- -----C----- -----C----- ----------- ----------- ----------- ----------- ----------- ----------- ----------- AAAAAAAAAAA ----BBB---- ----BBB---- ----BBB---- 
----------- -----C----- -----C----- ----------- ----------- ----------- ----------- ----------- ----------- ----------- ----------- ----------- AAAAAAAAAAA ----------- ----------- ----------- 
-----C----- ----------- ----------- ----------- ----------- ----------- ----------- ----------- ----------- ----------- ----------- ----------- -AAAAAAAAA- ----------- ----------- ----------- 
----------- ----------- ----------- ----------- ----------- ----------- ----------- ----------- ----------- ----------- ----------- ----------- --AAAAAAA-- ----------- ----------- ----------- 
----------- ----------- ----------- ----------- ----------- ----------- ----------- ----------- ----------- ----------- ----------- ----------- ---AAAAA--- ----------- ----------- ----------- 
