model
size = 5 24 7, scale = 0.05, origin = -y
material 
  colors = A:#E00 B:#080 C:#FF0
voxels
----- ----- ----- ----- ----- ----- ----- ----- ----- ----- ----- ----- ----- ----- ----- ----- ----- ----- ----- ----- -CCC- ----- ----- ----- 
----- ----- ----- ----- ----- ----- ----- ----- ----- ----- ----- ----- ----- ----- ----- ----- ----- ----- ----- ----- CCCCC -AAA- -AAA- -AAA- 
----- ----- ----- ----- ----- ----- ----- ----- ----- ----- ----- ----- ----- ----- ----- ----- ----- ----- ----- --B-- CC-CC -A-A- -A-A- -A-A- 
----- ----- ----- ----- ----- ----- ----- --B-- --B-- --B-- --B-- ----- ----- ----- ----- ----- ----- ----- ----- --B-- CCCCC -AAA- -AAA- -AAA- 
--B-- --B-- --B-- --B-- --B-- --B-- --B-- ----- ----- ----- ----- --B-- --B-- ----- ----- ----- ----- ----- --B-- ----- -CCC- ----- ----- ----- 
----- ----- ----- ----- ----- ----- ----- ----- ----- ----- ----- ----- --B-- --B-- --B-- ----- ----- ----- --B-- ----- ----- ----- ----- ----- 
----- ----- ----- ----- ----- ----- ----- ----- ----- ----- ----- ----- ----- ----- ----- --B-- --B-- --B-- ----- ----- ----- ----- ----- ----- 
