model
size = 7 26 12, scale = 0.05, origin = -y
material 
  colors = A:#080 B:#FF0 C:#E00
voxels
------- ------- ------- ------- ------- ------- ------- ------- ------- ------- ------- ---A--- ---A--- ---A--- ------- ------- ------- ------- ------- ------- ------- ------- ------- ------- ------- ------- 
------- ------- ------- ------- ------- ------- ------- ------- ------- ------- ---A--- ---A--- ------- ------- ---A--- ---A--- ------- ------- ------- ------- ------- ------- ------- ------- ------- ------- 
---A--- ---A--- ------- ------- ------- ------- ------- ------- ------- ------- ---A--- ------- ------- ------- ------- ---A--- ------- ------- ------- ------- ------- ------- ------- ------- ------- ------- 
------- ------- ---A--- ------- ------- ------- ------- ------- ------- ------- ---A--- ------- ------- ------- ---A--- ------- ------- ------- ------- ------- ------- ------- ------- ------- ------- ------- 
------- ------- ------- ---A--- ------- ------- ------- ------- ------- ------- ---A--- ------- ------- ------- ---A--- ------- ------- ------- ------- ------- ------- ------- ------- ------- ------- ------- 
------- ------- ------- ------- ---A--- ---A--- ------- ------- ------- ------- ---A--- ---A--- ------- ------- ---A--- ------- ------- ------- ------- ------- ------- ------- --BBB-- ------- ------- ------- 
------- ------- ------- ------- ------- ------- ---A--- ---A--- ------- ------- ------- ------- ---A--- ---A--- ------- ------- ------- ------- ------- ------- ------- ------- -BBBBB- ------- ------- ------- 
------- ------- ------- ------- ------- ------- ------- ------- ---A--- ---A--- ---A--- ---A--- ---A--- ------- ---A--- ---A--- ---A--- ------- ------- ------- ------- ------- BBBBBBB --CCC-- --CCC-- --CCC-- 
------- ------- ------- ------- ------- ------- ------- ------- ------- ------- ------- ------- ------- ------- ------- ------- ------- ---A--- ---A--- ---A--- ---A--- ---A--- BBB-BBB --C-C-- --C-C-- --C-C-- 
------- ------- ------- ------- ------- ------- ------- ------- ------- ------- ------- ------- ------- ------- ------- ------- ------- ------- ------- ------- ------- ------- BBBBBBB --CCC-- --CCC-- --CCC-- 
------- ------- ------- ------- ------- ------- ------- ------- ------- ------- ------- ------- ------- ------- ------- ------- ------- ------- ------- ------- ------- ------- -BBBBB- ------- ------- ------- 
------- ------- ------- ------- ------- ------- ------- ------- ------- ------- ------- ------- ------- ------- ------- ------- ------- ------- ------- ------- ------- ------- --BBB-- ------- ------- ------- 
