model
size = 17 21 32, scale = 0.05, origin = -y
material 
  colors = A:#465D4C B:#111 C:#00AA90 D:#24936E E:#0C4842 F:#2B5F75 G:#58B2DC
voxels
3-2B-4B-2B7-10B10-4D13-4C13-4A14-2A265-3B-4B-3B5-12B6-10D8-8A9-8A10-6A13-2A15-2D230-14B3-14B4-3D6A3D6-10A8-8A9-8A10-6A12-D2AD14-2E213-14B3-14B4-3D6A3D5-12A6-10A8-8A9-8A10-D4AD12-4F211-16B-16B2-4D6A4D4-12A5-12A6-10A8-8A9-2D4A2D10-6E13-2E197-14B-16B2-4D6A4D3-14A4-12A5-12A6-10A8-2D4A2D10-6E12-4E14-2E178-14B3-16B2-4D6A4D3-14A4-13A4-12A6-10A7-D8AD8-8F10-6F12-4F177-16B-16B2-4D6A4D3-14A4-13A4-12A6-10A7-D8AD8-8E9-8E12-2E179-2(15B2-)4D6A4D3-14A4-13A4-12A6-10A7-D8AD8-8E9-8E11-4E177-16B-16B2-4D6A4D3-14A4-13A4-12A6-10A7-D8AD8-8E9-8E12-2E178-14B3-16B2-4D6A4D3-14A4-13A4-12A6-10A7-D8AD8-8F10-6F193-16B-16B3-2AD6A4D5-12A6-11A5-11A6-10A7-D8AD8-8E11-4E195-14B3-14B4-D9A3D2(5-12A)5-11A6-10A7-D8AD8-8E11-4E198-11B3-14B4-D9ADAD2(6-11A)6-10A6-11A6-D8AD8-3F2B3F11-F2BF13-4F98-4C13-C2FC12-6C11-C4FC11-6C10-8B7-12B5-D9ADAD2(6-11A)6-10A7-10A6-D8AD8-8E11-4A2(13-4E)14-2F15-2C15-2F15-2C14-4A12-B4AB10-2(2C4A2C9-)2C4B2C9-8B7-12B5-D9ADAD2(6-11A)6-10A7-10A6-D8AD8-8E10-2(6A11-)6A12-3(4A13-)4A12-6A10-2B4A2B8-2(2C6A2C7-)2C6B2C8-8B7-12B5-D9ADAD2(6-11A)6-10A7-10A6-D8ADAE6-8E3(9-8A)10-6A11-6A12-4A13-4A11-8A9-2B4A2B8-2(C8AC7-)C8BC8-8B7-2B-9B5-D9ADAD2(6-11A)6-10A7-10AE5-D8ADAE6-D6AD2AE6-2(8A9-)8A10-3(6A11-)6A9-10A7-3B4A3B6-2(2C8A2C5-)2C8B2C6-9B7-2B2-8B5-D2A-6ADAD2(6-A-9A)6-10A2(E5-11A)C5-11AE6-10AE6-2(9A8-)3(8A9-)8A8-10A7-3B4A3B6-2(C10AC5-)C10BC5-10B7-2B-9B5-D9ADAD2(5-12A)5-11A6-3(11AE5-)11A2(5-12A)6-4(9A8-)10A7-3B4A3B6-2(C10AC5-)C10BC4-15B2-15B3-D10A2D4-13A5-12A5-2(10A7-)10A3C3-11A3C3-2(12A5-)12A6-5(10A7-)3B4A3B6-2(C10AC5-)C10BC3-17B-16B-2D10A3D2-15A3-14A4-9A8-9A4C3-10A2CF4-10A2CG4-11A3C3-12A5-12A6-4(10A7-)11A6-3B4A3B6-2(C10AC5-)C10BC3-15B3-16B-2D10A3D2(2-15A)3-12A2C4-10ACG5-10ACF4-11ACG4-11ACF4-11A3C3-12A6-3(10A7-)2(11A6-)3B4A3B6-2(C10AC5-)C10BC5-15B-16B-2D10A3D2(2-15A)2-14AC3-12AG5-10ACF5-10ACG4-11ACF4-11A3C3-10A4(2C7-8A)2C6-9A2C6-3B4A2BC6-2(C10AC5-)C10BC3-17B-16B-2D10A3D2(2-15A)2-13A4-14AC4-10ACF5-10ACG5-10A3C4-10A7-11A7-10A3(8-9A)6-11A6-3B4A3B6-2(2C8A2C5-)2C8B2C3-15B3-16B-2D10A3D2(2-15A)2-13A5-12A6-2(10A3C4-)11A6-11A7-10A6-5(10A7-)3B4A3B6-2(2C8A2C5-)2C8B2C5-15B-15B2-2D10A2D2(3-14A)4-12A6-11A6-2(10A7-)11A7-10A7-8A10-3(6A11-)6A10-8A9-B6AB8-2(C8AC7-)C8BC4-16B2-14B3-2D10A2D3-14A4-12A4(6-11A)7-10A7-8A10-6A79-6A11-6B9-2(10C7-)10C5-14B3-14B5-10D5(7-10A)8-3A2C3A9-3A2C3A12-6(2C15-)2A15-2A13-6C10-8C9-8C7-10B7-12B7-8D3(9-8A)2(9-3A2C3A)10-2A2-2A132-2C15-2C62-10B7-10B9-6D3(11-6A)12-A2CA13-A2-A232-8B9-8B12-3(2C15-)2C263-
