model
size = 30 8 19, scale = 0.05, origin = -y
material 
  colors = A:#001 B:#9CF C:#EEE D:#111
voxels
---AAAAAAAAA------AAAAAAAAA--- --AAAAAAAAAAA----AAAAAAAAAAA-- -AAAACACAAAAAA--AAAACACAAAAAA- AAAACACAAAAAAA--AAACACAAAAAAA- AAACACAAAAAAAAAAAACACAAAAAAAA- AAAAAAAAAAAAAAAAAAAAAAAAAAAAA- AAAAAAAAAAAAAAAAAAAAAAAAAAAAA- ------------------------------ 
---BBBBBBBBB------BBBBBBBBB--- --BBBBBBBBBBB----BBBBBBBBBBB-- -BBBBBBBBBBBBB--BBBBBBBBBBBBB- -ABBBBBBBBBBBB--BBBBBBBBBBBBBA -ABBBBBBBBBBBBBBBBBBBBBBBBBBBA -ABBBBBBBBBBBBBBBBBBBBBBBBBBBA -ABBBBBBBBBBBBBBBBBBBBBBBBBBBA -AAAAAAAAAAAAAAAAAAAAAAAAAAAA- 
---AAAAAAAAA------AAAAAAAAA--- --AAAAAAAAAAA----AAAAAAAAAAA-- -AAAAAAAAAAAAA--AAAAAAAAAAAAA- --AAAAAAAAAAAA--AAAAAAAAAAAAA- --AAAAAAAAAAAAAAAAAAAAAAAAAAA- --AAAAAAAAAAAAAAAAAAAAAAAAAAA- --AAAAAAAAAAAAAAAAAAAAAAAAAAA- -AAAAAAAAAAAAAAAAAAAAAAAAAAAA- 
------------------------------ ------------------------------ ------------------------------ -A--------------------------A- -A--------------------------A- -A--------------------------A- -A--------------------------A- -A--------------------------A- 
------------------------------ ------------------------------ ------------------------------ -A--------------------------A- -A--------------------------A- -A--------------------------A- -A--------------------------A- -A--------------------------A- 
------------------------------ ------------------------------ ------------------------------ -A--------------------------A- -A--------------------------A- -A--------------------------A- -A--------------------------A- -A--------------------------A- 
------------------------------ ------------------------------ ------------------------------ -A--------------------------A- -A--------------------------A- -D--------------------------A- -A--------------------------A- -A--------------------------A- 
------------------------------ ------------------------------ ------------------------------ -A--------------------------A- -A--------------------------A- -A--------------------------A- -A--------------------------A- -A--------------------------A- 
------------------------------ ------------------------------ ------------------------------ -A--------------------------A- -A--------------------------A- -A--------------------------A- -A--------------------------A- -A--------------------------A- 
------------------------------ ------------------------------ ------------------------------ -A--------------------------A- -A--------------------------A- -A--------------------------A- -A--------------------------A- -A--------------------------A- 
------------------------------ ------------------------------ ------------------------------ ------------------------------ -A--------------------------A- -A--------------------------A- -A--------------------------A- -A--------------------------A- 
------------------------------ ------------------------------ ------------------------------ ------------------------------ ------------------------------ -D---------------------------- -A--------------------------A- -A--------------------------A- 
------------------------------ ------------------------------ ------------------------------ ------------------------------ ------------------------------ ------------------------------ -A--------------------------A- -A--------------------------A- 
------------------------------ ------------------------------ ------------------------------ ------------------------------ ------------------------------ ------------------------------ -A--------------------------A- -A--------------------------A- 
------------------------------ ------------------------------ ------------------------------ ------------------------------ ------------------------------ ------------------------------ -A--------------------------A- -A--------------------------A- 
------------------------------ ------------------------------ ------------------------------ ------------------------------ ----------------------------A- -D--------------------------A- -A--------------------------A- -A--------------------------A- 
------------------------------ ------------------------------ ------------------------------ ----------------------------A- -D--------------------------A- -D--------------------------A- -A--------------------------A- -A--------------------------A- 
------------------------------ ------------------------------ ------------------------------ -A--------------------------A- -A--------------------------A- -A--------------------------A- -A--------------------------A- -A--------------------------A- 
------------------------------ ------------------------------ ------------------------------ -A--------------------------A- -A--------------------------A- -A--------------------------A- -A--------------------------A- -A--------------------------A- 
