model
size = 17 21 32, scale = 0.05, origin = -y
material 
  colors = A:#572A3F B:#111 C:#FFB11B D:#EFBB24 E:#43341B F:#9F353A G:#D0104C
voxels
4-2B-4B-2B7-10B10-4D13-4C13-4A14-2A265-3B-4B-3B5-12B6-10D8-8A9-8A10-6A13-2A15-2D230-14B3-14B4-3D6A3D6-10A8-8A9-8A10-6A12-D2AD14-2E213-14B3-14B4-3D6A3D5-12A6-10A8-8A9-8A10-D4AD12-4F211-16B-16B2-4D6A4D4-12A5-12A6-10A8-8A9-2D4A2D10-6E13-2E195-14B3-16B2-4D6A4D3-14A4-12A5-12A6-10A8-2D4A2D10-6E12-4E14-2E180-14B-16B2-4D6A4D3-14A3-13A5-12A6-10A7-D8AD8-8F10-6F12-4F177-16B-16B2-4D6A4D3-14A3-13A5-12A6-10A7-D8AD8-8E9-8E12-2E178-15B2-15B3-4D6A4D3-14A3-13A5-12A6-10A7-D8AD8-8E9-8E11-4E177-16B-16B2-4D6A4D3-14A3-13A5-12A6-10A7-D8AD8-8E9-8E12-2E180-14B-16B2-4D6A4D3-14A3-13A5-12A6-10A7-D8AD8-8F10-6F193-16B-16B2-4D6AD2A4-12A5-2(11A7-)10A7-D8AD8-8E11-4E195-2(14B3-)3D9AD4-12A5-12A6-11A7-10A7-D8AD8-8E11-4E195-11B6-14B3-DAD9AD4-11A6-11A7-10A7-11A7-D8AD8-3F2B3F11-F2BF13-4F98-4C13-C2FC12-6C11-C4FC11-6C10-8B7-12B4-DAD9AD4-11A6-11A2(7-10A)8-D8AD8-8E11-4A2(13-4E)14-2F15-2C15-2F15-2C14-4A12-B4AB10-2(2C4A2C9-)2C4B2C9-8B7-12B4-DAD9AD4-11A6-11A2(7-10A)8-D8AD8-8E10-2(6A11-)6A12-3(4A13-)4A12-6A10-2B4A2B8-2(2C6A2C7-)2C6B2C8-8B7-12B4-DAD9AD4-11A6-11A2(7-10A)6-EAD8AD8-8E3(9-8A)10-6A11-6A12-4A13-4A11-8A9-2B4A2B8-2(C8AC7-)C8BC8-8B7-9B-2B4-DAD9AD4-11A6-11A7-2(10A6-E)AD8AD5-E2AD6AD3(9-8A)10-3(6A11-)6A9-10A7-3B4A3B6-2(2C8A2C5-)2C8B2C7-9B6-8B2-2B4-DAD6A-2AD4-2(9A-A6-)E10A6-E11A5-C2(11A5-E)10A2(8-9A)4(9-8A)8-10A7-3B4A3B6-2(C10AC5-)C10BC7-10B5-9B-2B4-DAD9AD4-12A5-12A6-3(11A5-E)2(11A6-)12A5-12A7-3(9A8-)9A7-10A7-3B4A3B6-2(C10AC5-)C10BC3-15B2-15B3-2D10AD4-13A4-12A2(7-10A)4-3C10A4-3C11A3(5-12A)6-5(10A7-)3B4A3B6-2(C10AC5-)C10BC2-33B2-3D10A2D2-15A2-14A7-9A4-4C9A5-F2C10A4-G2C10A3-3C11A2(5-12A)6-3(10A7-)10A6-11A7-3B4A3B6-2(C10AC5-)C10BC4-31B2-3D10A2D2(2-15A)2-2C12A4-GC10A5-FC10A5-GC11A4-FC11A3-3C11A5-12A6-2(10A7-)10A2(6-11A)7-3B4A3B6-2(C10AC5-)C10BC2-15B2-16B2-3D10A2D2(2-15A)2-C14A3-G12A4-FC10A5-GC10A5-FC11A3-3C11A5-2C10A5-4(2C8A7-)2C9A7-C2B4A3B6-2(C10AC5-)C10BC2-33B2-3D10A2D2(2-15A)4-13A2-C14A3-FC10A5-GC10A4-3C10A7-10A6-11A6-10A7-3(9A8-)11A7-3B4A3B6-2(2C8A2C5-)2C8B2C4-31B2-3D10A2D2(2-15A)4-13A4-12A3-3C10A4-3C10A2(6-11A)6-10A8-5(10A7-)3B4A3B6-2(2C8A2C5-)2C8B2C2-2(15B3-)2D10A2D2(3-14A)4-12A5-11A2(7-10A)6-11A6-10A9-8A10-3(6A11-)6A10-8A9-B6AB8-2(C8AC7-)C8BC4-16B2-14B3-2D10A2D3-14A4-12A5-4(11A6-)10A9-8A10-6A79-6A11-6B9-2(10C7-)10C5-14B3-14B5-10D5(7-10A)8-3A2C3A9-3A2C3A12-6(2C15-)2A15-2A13-6C10-2(8C9-)10B5-12B7-8D3(9-8A)2(9-3A2C3A)10-2A2-2A132-2C15-2C62-10B7-10B9-6D3(11-6A)12-A2CA13-A2-A232-8B9-8B12-3(2C15-)2C262-
