model
size = 32 17 32, scale = 0.05, origin = -y
material 
  colors = A:#161616 B:#858585 C:#9AA6AB D:#929292 E:#777 F:#FFF G:#0F0F0F H:#898989 I:#7EA97D J:#A97DA5 K:#A9937D L:#7D7EA9 M:#A2A97D N:#F30 O:#FFFF80 P:#827DA9 Q:#A97D7D
voxels
17-3(8B24-)2(8A24-)8A25-6A27-4A313-3(B2-)B2(22-10B)5(22-10A)23-8A278-2(B-)B2-2(B-)B2(20-12B)6(20-12A)21-10A245-2(B-)J2-I2(-B)19-2(14B18-)6(14A18-)14A19-12A210-2(B-)M6-P2(-B)2(16-16B)6(16-16A)17-14A18-14A20-10A179-B-B10-B-B2(16-16B)7(16-16A)17-14A19-8A2G2A178-B-B2-6D2-B-B15-6BE4CE6B14-18B5(14-18A)15-16A16-16A17-14A19-4(AG)2AGA178-B-Q-D6-D-K-B15-5BCEC2ECEC5B14-18B6(14-18A)15-16A17-14A19-3AG6AGA178-B-BD-D4-D-DB-B15-4B3(E2C)E4B14-18B6(14-18A)15-16A17-14A19-2AGAG5AGA176-2(B-)B3(D2-)D2(B-)B12-5B2(CE)2C2(EC)5B12-20B12-6A8B5A13-2(6A8B6A12-)6A8B6A13-5A8B5A14-5A8B5A15-16A17-14A19-7A3G2A176-2(B-)BD3-ED3-D2(B-)B12-5B2CEC2BCE2C5B12-20B2(12-6A8B6A)8-10A8B6AG11-6A8B6A12-6A8B6A13-5A8B5A15-16A17-14A19-A4G2AG4A176-2(B-)BD3-DE3-D2(B-)B7-2C3-5B2CEC2BCE2C5B6-C2-D2-20B6-C2-D2-6A8B6A7-2D3-6A8B7A5-12A8B6AG4-13A8B7A11-6A8B6A13-5A8B5A15-16A17-14A19-A2(G2A)4GA176-2(B-)B3(D2-)D2(B-)B7-2C3-5B2(CE)2C2(EC)5B6-C2ED2-20B6-C2ED2-6A8B6A7-CD3-6A8B6AG4-13A8B7A4-A6F6A8B6AG11-6A8B6A13-5A8B5A15-16A17-14A19-2AG9A176-2(B-)BD-D4-D-D2(B-)B7-2C3-5B3(E2C)E5B6-3CD2-20B6-3CD2-6A8B6A7-CD3-6A8B6A4-14A8B6A3-15A8B6A12-6A8B6A13-5A8B5A15-16A17-14A19-3AG2A3(GA)176-2(B-)I-D6-D-L2(-B)7-2C3-6BCEC2ECEC6B6-3CD2-20B6-3CD2-6AB6-B5A8-CD3-6AB6-B6A3-15A8B6A3-A8F6A8B6A12-6A8B5A14-5A8B5A15-16A17-14A19-4A2(G3A)176-B-J-B2-6D2-B-Q-B7-2C3-7BE4CE7B6-3CD2-20B6-3CD2-6AB6-B5A8-CD3-6AB6-B5A3-16A8B6A2-16A8B6A12-6A8B5A14-5A8B5A15-16A17-14A19-A2(G2A)GAG2A176-3(B-)B6-3(B-)B7-2C3-20B6-CNOD2-20B6-COND2-6AB6-B5A8-CD3-6AB6-B5A3-16AB6-B6A2-A9F6AB6-B6A12-6A8B5A14-5A8B5A15-16A17-14A19-2A2G8A176-4(B-)B2-4(B-)B7-2C3-2(20B6-C2-D2-)6AB6-B5A8-CD3-6AB6-B5A2-17AB6-B6A-17AB6-B6A12-6A8B5A14-5A8B5A15-16A17-14A19-12A176-4(B-)B2-3(B-)B14-2(19B13-)6AB6-B5A13-6AB6-B5A2-17AB6-B5A2-A10F6AB6-B6A12-6AB-4B-B5A14-5AB-4B-B5A15-16A17-14A207-3(B-)P-K2-L-M2(-B)14-2(19B13-)2(6AB6-B5A13-)2(6AB6-B6A12-)6AB6-B5A14-5AB-4B-B5A15-16A240-B-B10-B-B15-2(18B14-)5(5AB6-B5A14-)5AB6-B5A17-4A4H4A242-B-B2-6D2-B-B16-5BE4CE5B16-16B5(16-4AB6-B4A)17-3AB6-B3A19-3AB4-B3A20-4A4-4A22-A6-A24-A6-A150-B-D6-D-B20-2BCEC2ECEC2B20-12B7(20-2AB6-B2A)20-3A6-3A21-2(A8-A22-)A8-A117-BD-D4-D-DB19-2B3(E2C)E2B18-14B6(18-3AB6-B3A)18-2A-B6-B-2A19-3A6-3A21-2(A8-A22-)A8-A115-B-B3(D2-)DB-B16-3B2(CE)2C2(EC)3B16-16B5(16-4AB6-B4A)17-3AB6-B3A18-A2-B6-B2-A19-3A6-3A21-2(A8-A22-)A8-A115-B-BD3-DE3-DB-B16-3B2CEC2BCE2C3B16-16B16-3(4AB6-B2AF17-)K3AB6-B2AF17-4AB6-B4A16-4AB6-B4A17-A2-B6-B2-A19-3A6-3A21-A8-A22-A8-A147-B-BD3-ED3-DB-B16-3B2CEC2BCE2C3B16-16B16-4AB6-B4A16-I3AB6-B4A16-J3A3(B6-B4A16-4A)B6-B4A17-A2-B6-B2-A19-3A6-3A22-A6-A24-A6-A148-B-B3(D2-)DB-B16-3B2(CE)2C2(EC)3B16-16B16-3(4AB6-B2AF17-)L3A2(B6-B2AF17-4A)B6-B4A17-A12-A19-12A23-6A25-A6-A24-A6-A116-B-BD-D4-D-DB-B16-3B3(E2C)E3B16-16B6(16-4A8B4A)17-A12-A19-12A54-8A2(24-A6-A)23-A8-A22-A8-A21-B-D6-D-B19-3BCEC2ECEC3B18-14B5(18-14A)18-6A2F6A19-12A21-10A87-8A3(24-A6-A)22-BI-6D-JB20-3BE4CE3B20-12B20-12A20-3A6F3A20-12A20-4A4F4A20-12A21-4A2-4A24-6A154-6A26-6F26-6A24-3(10B22-)10A22-2A6-2A23-8A24-2A4-2A25-6A296-
