model
size = 31 32 32, scale = 0.05, origin = -y
material 
  colors = A:#0FE B:#161869 C:#05061C D:#6E39FF E:#006E85 F:#A9FFE6 G:#000 H:#00FF7B I:#FFF J:#8D6497
voxels
539-8E87-4A584-6E22-12E19-12E22-3I2FI25-F3I2F25-2F3IF25-3F3I25-4F2I25-5FI25-6F20-16E79-12A20-10A23-6A518-12E16-18E13-18E15-14F17-10FI3F17-11FI2F17-12FIF17-10FI2FI17-10F2I2F17-10F3IF14-20E11-20E44-16A15-16A16-14A19-10A23-6A243-2(4E58-)4E27-4E24-10E17-18E11-22E9-22E11-4(18F13-)18F11-E-16FIF-E9-E-17FI-E2(9-22E)44-C12BC17-C12AC16-AB12ACA15-16A17-12A21-8A208-2(10E52-)10E21-3E4A3E19-5E4A5E13-2(9E4A9E9-)4EC12AC4E10-2(3FC12AC3F11-)3FC12AC3F10-E3FC12AC3FE8-2(HE3FC12AC3FEH7-)HE3FC12AC3FEH8-4EC12AC4E9-4EC12AC4E12-B15C15-BC12ACB16-2(C12AC17-)C12AC16-16A17-12A21-8A176-12E21-8G21-12E22-6G21-14E15-4E10A4E13-4E10A4E11-2(5E12A5E9-)3EBC12ACB3E10-F2BC12AC2BF10-2(EF2BC12AC2BFE9-)EF2BC12AC2BFE8-2(2HF2BC12AC2BF2H7-)2HF2BC12AC2BF2H8-2E2BC12AC2B2E9-2E2BC12AC2B2E11-2BC12AC2B14-2(BC12ACB15-)BC12ACB16-C12AC17-C12AC16-16A17-12A21-8A144-14E19-G3C2A3CG19-6E2A6E19-2G2C2A2C2G17-8E2A8E15-C12AC14-3EC12AC3E10-3EBC12ACB3E2(9-2E2BC12AC2B2E)9-EF2BC12AC2BF3(E9-E3BC12AC3B)E7-2(3H3BC12AC3B3H5-)3H3BC12AC3B3H7-4BC12AC4B9-4BC12AC4B10-3BC12AC3B11-3BC12AC3B12-2BC12AC2B13-2BC12AC2B14-BC12ACB16-C12AC17-C12AC16-16A17-12A21-8A113-14E19-G8AG19-2E10A2E15-4E10A4E15-C12AC17-C12AC14-2EBC12ACB2E10-3EBC12ACB3E2(9-2E2BC12AC2B2E)3(9-E3BC12AC3BE)8-5BC12AC5B6-2(3H3BC12AC3B3H5-)3H3BC12AC3B3H6-5BC12AC5B8-2(4BC12AC4B9-)4BC12AC4B10-3BC12AC3B11-3BC12AC3B12-2BC12AC2B14-BC12ACB16-C12AC17-C12AC16-16A17-12A110-16E2(15-3E10A3E)14-4E10A4E15-C12AC16-BC12ACB13-E2BC12AC2BE10-2(2E2BC12AC2B2E9-)E3BC12AC3BE9-E3BC12AC3BE8-2(5BC12AC5B7-)5BC12AC5B6-2(3H3BC12AC3B3H5-)3H3BC12AC3B3H6-2(5BC12AC5B7-)5BC12AC5B8-4BC12AC4B9-4BC12AC4B10-3BC12AC3B11-3BC12AC3B12-2BC12AC2B14-BC12ACB16-C12AC16-AB12ACA16-14A20-8A81-16E15-2E12A2E14-3E12A3E15-C12AC17-C12AC16-BC12ACB13-E2BC12AC2BE10-2E2BC12AC2B2E2(9-E3BC12AC3BE)8-5BC12AC5B7-5BC12AC5B6-6BC12AC6B5-6BC12AC6B4-2(4H3BC12AC3B4H3-)4H3BC12AC3B4H4-6BC12AC6B5-6BC12AC6B6-5BC12AC5B7-5BC12AC5B8-4BC12AC4B9-4BC12AC4B10-3BC12AC3B12-2BC12AC2B14-BC12ACB16-C12AC17-C12AC16-16A17-12A22-6A51-16E15-2E12A2E14-3E12A3E15-C12AC16-BC12ACB15-BC12ACB13-3BC12AC3B10-E3BC12AC3BE9-E3BC12AC3BE8-5BC12AC5B7-5BC12AC5B6-2(6BC12AC6B5-)6BC12AC6B4-2(4H3BC12AC3B4H3-)4H3BC12AC3B4H4-2(6BC12AC6B5-)6BC12AC6B6-5BC12AC5B7-5BC12AC5B8-4BC12AC4B9-4BC12AC4B10-3BC12AC3B13-BC12ACB15-BC12ACB16-C12AC16-AB12ACA16-14A19-10A49-16E15-AE12AEA16-C12AC17-C12AC16-BC12ACB14-2BC12AC2B12-3BC12AC3B10-4BC12AC4B8-5BC12AC5B7-5BC12AC5B6-2(6BC12AC6B5-)6BC12AC6B4-7BC12AC7B3(3-4H3BC12AC3B4H)3-7BC12AC7B4-2(6BC12AC6B5-)6BC12AC6B6-5BC12AC5B7-5BC12AC5B8-4BC12AC4B10-3BC12AC3B12-2BC12AC2B14-BC12ACB16-C12AC17-C12AC16-16A17-12A48-16E15-AE12AEA16-C12AC16-BC12ACB15-BC12ACB13-3BC12AC3B10-4BC12AC4B9-4BC12AC4B8-5BC12AC5B6-2(6BC12AC6B5-)6BC12AC6B4-2(7BC12AC7B3-)3(4H3BC12AC3B4H3-)7BC12AC7B3-7BC12AC7B4-2(6BC12AC6B5-)6BC12AC6B6-5BC12AC5B8-4BC12AC4B9-4BC12AC4B10-3BC12AC3B13-BC12ACB15-BC12ACB16-C12AC16-16A17-12A23-4A21-16E15-16A16-C12AC16-BC12ACB14-2BC12AC2B12-3BC12AC3B10-4BC12AC4B8-5BC12AC5B7-5BC12AC5B6-6BC12AC6B5-6BC12AC6B4-2(7BC12AC7B3-)7BC12AC7B2-2(5H3BC12AC3B5H-)5H3BC12AC3B5H2-2(7BC12AC7B3-)7BC12AC7B4-6BC12AC6B5-6BC12AC6B6-5BC12AC5B7-5BC12AC5B8-4BC12AC4B10-3BC12AC3B12-2BC12AC2B14-BC12ACB16-C12AC16-AB12ACA16-14A21-6A20-16E15-16A16-C12AC16-DC12ACD14-2DC12AC2D12-3DC12AC3D10-4DC12AC4D8-5DC12AC5D7-5DC12AC5D6-6DC12AC6D5-6DC12AC6D4-7DC12AC7D3-7DC12AC7D2-3H5DC12AC5D3H3-2(26G5-)26G3-3H5DC12AC5D3H2-7DC12AC7D3-7DC12AC7D4-6DC12AC6D5-6DC12AC6D6-5DC12AC5D7-5DC12AC5D8-4DC12AC4D10-3DC12AC3D12-2DC12AC2D14-DC12ACD16-C12AC16-AB12ACA16-14A20-8A19-16E15-16A16-C12AC16-DC12ACD14-2DC12AC2D12-3DC12AC3D10-4DC12AC4D8-5DC12AC5D7-5DC12AC5D6-6DC12AC6D5-6DC12AC6D4-7DC12AC7D3-7DC12AC7D2-3H5DC12AC5D3H3-26G2-29G2-G2-26G2-G3H5DC12AC5D3H2(J-7DC12AC7D-)2(J2-6DC12AC6D2-)2(J3-5DC12AC5D3-)J4-4DC12AC4D4-J5-3DC12AC3D5-J6-2DC12AC2D6-J7-DC12ACD7-J8-C12AC8-J7-AB12ACA7-J8-14A8-J11-8A19-16E15-16A16-C12AC16-DC12ACD14-2DC12AC2D12-3DC12AC3D10-4DC12AC4D8-5DC12AC5D7-5DC12AC5D6-6DC12AC6D5-6DC12AC6D4-7DC12AC7D3-7DC12AC7D2-3H5DC12AC5D3H3-2(26G5-)26G3-3H5DC12AC5D3H2-7DC12AC7D3-7DC12AC7D4-6DC12AC6D5-6DC12AC6D6-5DC12AC5D7-5DC12AC5D8-4DC12AC4D10-3DC12AC3D12-2DC12AC2D14-DC12ACD16-C12AC16-AB12ACA16-14A20-8A19-16E15-16A16-C12AC16-BC12ACB14-2BC12AC2B12-3BC12AC3B10-4BC12AC4B8-5BC12AC5B7-5BC12AC5B6-6BC12AC6B5-6BC12AC6B4-2(7BC12AC7B3-)7BC12AC7B2-2(3H5DC12AC5D3H-)3H5DC12AC5D3H2-2(7BC12AC7B3-)7BC12AC7B4-6BC12AC6B5-6BC12AC6B6-5BC12AC5B7-5BC12AC5B8-4BC12AC4B10-3BC12AC3B12-2BC12AC2B14-BC12ACB16-C12AC16-AB12ACA16-14A21-6A20-16E15-16A16-C12AC16-BC12ACB15-BC12ACB13-3BC12AC3B10-4BC12AC4B9-4BC12AC4B8-5BC12AC5B6-2(6BC12AC6B5-)6BC12AC6B4-2(7BC12AC7B3-)3(7DC12AC7D3-)7BC12AC7B3-7BC12AC7B4-2(6BC12AC6B5-)6BC12AC6B6-5BC12AC5B8-4BC12AC4B9-4BC12AC4B10-3BC12AC3B13-BC12ACB15-BC12ACB16-C12AC16-16A17-12A23-4A21-16E15-16A16-C12AC17-C12AC16-BC12ACB14-2BC12AC2B12-3BC12AC3B10-4BC12AC4B8-5BC12AC5B7-5BC12AC5B6-2(6BC12AC6B5-)6BC12AC6B4-7BC12AC7B3(3-7DC12AC7D)3-7BC12AC7B4-2(6BC12AC6B5-)6BC12AC6B6-5BC12AC5B7-5BC12AC5B8-4BC12AC4B10-3BC12AC3B12-2BC12AC2B14-BC12ACB16-C12AC17-C12AC16-16A17-12A49-14E17-14A16-AB12ACA16-C12AC16-BC12ACB15-BC12ACB13-3BC12AC3B10-4BC12AC4B9-4BC12AC4B8-5BC12AC5B7-5BC12AC5B6-3(6BC12AC6B5-)3(6DC12AC6D5-)2(6BC12AC6B5-)6BC12AC6B6-5BC12AC5B7-5BC12AC5B8-4BC12AC4B9-4BC12AC4B10-3BC12AC3B13-BC12ACB15-BC12ACB16-C12AC16-AB12ACA16-14A19-10A51-12E19-12A17-16A16-C12AC17-C12AC16-BC12ACB14-2BC12AC2B12-3BC12AC3B10-4BC12AC4B9-4BC12AC4B8-5BC12AC5B7-5BC12AC5B6-2(6BC12AC6B5-)3(6DC12AC6D5-)6BC12AC6B5-6BC12AC6B6-5BC12AC5B7-5BC12AC5B8-4BC12AC4B9-4BC12AC4B10-3BC12AC3B12-2BC12AC2B14-BC12ACB16-C12AC17-C12AC16-16A17-12A22-6A54-10E21-10A19-14A16-16A16-C12AC16-BC12ACB14-2BC12AC2B12-3BC12AC3B11-3BC12AC3B10-4BC12AC4B9-4BC12AC4B8-3(5BC12AC5B7-)3(5DC12AC5D7-)2(5BC12AC5B7-)5BC12AC5B8-4BC12AC4B9-4BC12AC4B10-3BC12AC3B11-3BC12AC3B12-2BC12AC2B14-BC12ACB16-C12AC16-AB12ACA16-14A19-10A85-6E25-6A22-12A17-16A16-C12AC17-C12AC16-BC12ACB14-2BC12AC2B12-3BC12AC3B11-3BC12AC3B10-2(4BC12AC4B9-)4BC12AC4B8-5BC12AC5B3(7-5DC12AC5D)7-5BC12AC5B8-2(4BC12AC4B9-)4BC12AC4B10-3BC12AC3B11-3BC12AC3B12-2BC12AC2B14-BC12ACB16-C12AC17-C12AC16-16A17-12A22-6A148-8A20-14A16-16A16-C12AC17-C12AC16-BC12ACB14-2BC12AC2B13-2BC12AC2B12-3BC12AC3B11-3BC12AC3B10-2(4BC12AC4B9-)3(4DC12AC4D9-)4BC12AC4B9-4BC12AC4B10-3BC12AC3B11-3BC12AC3B12-2BC12AC2B13-2BC12AC2B14-BC12ACB16-C12AC17-C12AC16-AB12ACA16-14A20-8A208-10A19-14A16-16A16-C12AC17-C12AC16-2(BC12ACB15-)BC12ACB14-2BC12AC2B12-2(3BC12AC3B11-)3(3DC12AC3D11-)3BC12AC3B11-3BC12AC3B12-2BC12AC2B14-2(BC12ACB15-)BC12ACB16-C12AC17-C12AC16-AB12ACA16-14A19-10A241-4A24-10A19-14A16-16A16-2(C12AC17-)C12AC16-2(BC12ACB15-)BC12ACB14-2BC12AC2B3(13-2DC12AC2D)13-2BC12AC2B14-2(BC12ACB15-)BC12ACB16-2(C12AC17-)C12AC16-AB12ACA16-14A19-10A24-4A275-4A24-10A19-14A16-16A15-AB12ACA16-2(C12AC17-)C12AC16-2(BC12ACB15-)3(DC12ACD15-)BC12ACB15-BC12ACB16-2(C12AC17-)C12AC16-AB12ACA15-16A16-14A19-10A24-4A366-8A21-12A18-14A16-16A15-AB12ACA16-8(C12AC17-)C12AC16-AB12ACA15-16A16-14A18-12A21-8A458-6A23-10A20-12A18-14A16-8(16A15-)16A16-14A18-12A20-10A23-6A552-6A24-8A22-10A20-6(12A19-)12A20-10A22-8A24-6A739-4A26-3(6A25-)6A26-4A416-
