model
size = 31 32 32, scale = 0.05, origin = -y
material 
  colors = A:#00E32D B:#F05 C:#FFF D:#CBDB23 E:#000 F:#00921A G:#FF0 H:#5B001C
voxels
539-8A87-4A584-6A22-12A19-12A22-3G2DG25-D3G2D25-2D3GD25-3D3G25-4D2G25-5DG25-6D20-16A79-12A20-10A23-6A518-12A16-18A13-18A15-14D17-10DG3D17-11DG2D17-12DGD17-10DG2DG17-10D2G2D17-10D3GD14-20A11-20A44-16A15-16A16-14A19-10A23-6A243-2(4A58-)4A27-4A24-10A17-18A11-22A9-22A11-4(18D13-)18D11-A-16DGD-A9-A-17DG-A2(9-22A)44-14C17-C12AC16-AB12ACA15-16A17-12A21-8A208-2(10A52-)10A21-10A19-14A13-2(22A9-)4AC12AC4A10-2(3DC12AC3D11-)3DC12AC3D10-A3DC12AC3DA8-2(FA3DC12AC3DAF7-)FA3DC12AC3DAF8-4AC12AC4A9-4AC12AC4A12-B14CB15-BC12ACB16-2(C12AC17-)C12AC16-16A17-12A21-8A176-12A21-8E21-12A22-6E21-14A15-18A13-18A11-2(22A9-)3ABC12ACB3A10-D2BC12AC2BD10-2(AD2BC12AC2BDA9-)AD2BC12AC2BDA8-2(2FD2BC12AC2BD2F7-)2FD2BC12AC2BD2F8-2A2BC12AC2B2A9-2A2BC12AC2B2A11-2BC12AC2B14-2(BC12ACB15-)BC12ACB16-C12AC17-C12AC16-16A17-12A21-8A144-14A19-E3C2A3CE19-14A19-2E2C2A2C2E17-18A15-C12AC14-3AC12AC3A10-3ABC12ACB3A2(9-2A2BC12AC2B2A)9-AD2BC12AC2BD3(A9-A3BC12AC3B)A7-2(3F3BC12AC3B3F5-)3F3BC12AC3B3F7-4BC12AC4B9-4BC12AC4B10-3BC12AC3B11-3BC12AC3B12-2BC12AC2B13-2BC12AC2B14-BC12ACB16-C12AC17-C12AC16-16A17-12A21-8A113-14A19-E8AE19-14A15-18A15-C12AC17-C12AC14-2ABC12ACB2A10-3ABC12ACB3A2(9-2A2BC12AC2B2A)3(9-A3BC12AC3BA)8-5BC12AC5B6-2(3F3BC12AC3B3F5-)3F3BC12AC3B3F6-5BC12AC5B8-2(4BC12AC4B9-)4BC12AC4B10-3BC12AC3B11-E2BC12AC2BE12-2BC12AC2B14-BC12ACB16-C12AC17-C12AC16-16A17-12A110-2(16A15-)16A14-18A15-C12AC16-BC12ACB13-A2BC12AC2BA10-2(2A2BC12AC2B2A9-)A3BC12AC3BA9-A3BC12AC3BA8-5BC12AC5B7-E4BC12AC4BE7-5BC12AC5B6-2(3F3BC12AC3B3F5-)3F3BC12AC3B3F6-5BC12AC5B7-E4BC12AC4BE7-5BC12AC5B8-4BC12AC4B9-4BC12AC4B10-3BC12AC3B11-3BC12AC3B12-2BC12AC2B14-BC12ACB16-C12AC16-AB12ACA16-14A20-8A81-16A15-16A14-18A15-C12AC17-C12AC16-BC12ACB13-A2BC12AC2BA10-2A2BC12AC2B2A2(9-A3BC12AC3BA)8-5BC12AC5B7-5BC12AC5B6-6BC12AC6B5-6BC12AC6B4-2(4F3BC12AC3B4F3-)4F3BC12AC3B4F4-6BC12AC6B5-6BC12AC6B6-5BC12AC5B7-5BC12AC5B8-4BC12AC4B9-4BC12AC4B10-3BC12AC3B12-2BC12AC2B14-BC12ACB16-C12AC17-C12AC16-16A17-12A22-6A51-16A15-16A14-18A15-C12AC16-BC12ACB15-BC12ACB13-3BC12AC3B10-A3BC12AC3BA9-A3BC12AC3BA8-5BC12AC5B7-5BC12AC5B6-2(6BC12AC6B5-)6BC12AC6B4-2(4F3BC12AC3B4F3-)4F3BC12AC3B4F4-2(6BC12AC6B5-)6BC12AC6B6-5BC12AC5B7-E4BC12AC4BE8-4BC12AC4B9-4BC12AC4B10-3BC12AC3B13-BC12ACB15-BC12ACB16-C12AC16-AB12ACA16-14A19-10A49-16A15-16A16-C12AC17-C12AC16-BC12ACB14-2BC12AC2B12-3BC12AC3B10-4BC12AC4B8-5BC12AC5B7-5BC12AC5B6-2(6BC12AC6B5-)6BC12AC6B4-7BC12AC7B3(3-4F3BC12AC3B4F)3-7BC12AC7B4-2(6BC12AC6B5-)6BC12AC6B6-5BC12AC5B7-5BC12AC5B8-4BC12AC4B10-E2BC12AC2BE12-2BC12AC2B14-BC12ACB16-C12AC17-C12AC16-16A17-12A48-16A15-16A16-C12AC16-BC12ACB15-BC12ACB13-3BC12AC3B10-E3BC12AC3BE9-4BC12AC4B8-5BC12AC5B6-2(6BC12AC6B5-)E5BC12AC5BE4-2(7BC12AC7B3-)3(4F3BC12AC3B4F3-)7BC12AC7B3-7BC12AC7B4-2(6BC12AC6B5-)6BC12AC6B6-5BC12AC5B8-4BC12AC4B9-4BC12AC4B10-3BC12AC3B13-BC12ACB15-BC12ACB16-C12AC16-16A17-12A23-4A21-16A15-16A16-C12AC16-BC12ACB14-2BC12AC2B12-3BC12AC3B10-4BC12AC4B8-5BC12AC5B7-5BC12AC5B6-6BC12AC6B5-6BC12AC6B4-2(7BC12AC7B3-)7BC12AC7B2-2(5F3BC12AC3B5F-)5F3BC12AC3B5F2-2(7BC12AC7B3-)7BC12AC7B4-6BC12AC6B5-6BC12AC6B6-5BC12AC5B7-5BC12AC5B8-4BC12AC4B10-3BC12AC3B12-2BC12AC2B14-BC12ACB16-C12AC16-AB12ACA16-14A21-6A20-16A15-16A16-C12AC16-BC12ACB14-2BC12AC2B12-3BC12AC3B10-4BC12AC4B8-5BC12AC5B7-5BC12AC5B6-6BC12AC6B5-6BC12AC6B4-7BC12AC7B3-7BC12AC7B2-3F5BC12AC5B3F3-2(26E5-)26E3-3F5BC12AC5B3F2-7BC12AC7B3-7BC12AC7B4-6BC12AC6B5-6BC12AC6B6-5BC12AC5B7-5BC12AC5B8-4BC12AC4B10-3BC12AC3B12-2BC12AC2B14-BC12ACB16-C12AC16-AB12ACA16-14A20-8A19-16A15-16A16-C12AC16-BC12ACB14-2BC12AC2B12-3BC12AC3B10-4BC12AC4B8-5BC12AC5B7-5BC12AC5B6-6BC12AC6B5-6BC12AC6B4-7BC12AC7B3-7BC12AC7B2-3F5BC12AC5B3F3-26E2-29E2-E2-26E2-E3F5BC12AC5B3F2(H-7BC12AC7B-)2(H2-6BC12AC6B2-)H3-5BC12AC4B4-H3-5BC12AC5B3-H4-4BC12AC4B4-H5-3BC12AC3B5-H6-2BC12AC2B6-H7-BC12ACB7-H8-C12AC8-H7-AB12ACA7-H8-14A8-H11-8A19-16A15-16A16-C12AC16-BC12ACB14-2BC12AC2B12-3BC12AC3B10-4BC12AC4B8-5BC12AC5B7-5BC12AC5B6-6BC12AC6B5-6BC12AC6B4-E6BC12AC6BE3-7BC12AC7B2-3F5BC12AC5B3F3-2(26E5-)26E3-3F5BC12AC5B3F2-7BC12AC7B3-E6BC12AC6BE4-6BC12AC6B5-6BC12AC6B6-5BC12AC5B7-5BC12AC5B8-E3BC12AC3BE10-3BC12AC3B12-2BC12AC2B14-BC12ACB16-C12AC16-AB12ACA16-14A20-8A19-16A15-16A16-C12AC16-BC12ACB14-2BC12AC2B12-3BC12AC3B10-4BC12AC4B8-5BC12AC5B7-5BC12AC5B6-6BC12AC6B5-6BC12AC6B4-2(7BC12AC7B3-)7BC12AC7B2-2(3F5BC12AC5B3F-)3F5BC12AC5B3F2-2(7BC12AC7B3-)7BC12AC7B4-6BC12AC6B5-6BC12AC6B6-5BC12AC5B7-5BC12AC5B8-4BC12AC4B10-3BC12AC3B12-2BC12AC2B14-BC12ACB16-C12AC16-AB12ACA16-14A21-6A20-16A15-16A16-C12AC16-BC12ACB15-BC12ACB13-3BC12AC3B10-4BC12AC4B9-4BC12AC4B8-5BC12AC5B6-2(6BC12AC6B5-)6BC12AC6B4-6(7BC12AC7B3-)7BC12AC7B4-2(6BC12AC6B5-)6BC12AC6B6-5BC12AC5B8-4BC12AC4B9-4BC12AC4B10-3BC12AC3B13-BC12ACB15-BC12ACB16-C12AC16-16A17-12A23-4A21-16A15-16A16-C12AC17-C12AC16-BC12ACB14-2BC12AC2B12-3BC12AC3B10-E3BC12AC3BE8-5BC12AC5B7-5BC12AC5B6-2(6BC12AC6B5-)6BC12AC6B4-4(7BC12AC7B3-)7BC12AC7B4-2(6BC12AC6B5-)6BC12AC6B6-5BC12AC5B7-5BC12AC5B8-4BC12AC4B10-3BC12AC3B12-2BC12AC2B14-BC12ACB16-C12AC17-C12AC16-16A17-12A49-14A17-14A16-AB12ACA16-C12AC16-BC12ACB15-BC12ACB13-3BC12AC3B10-4BC12AC4B9-4BC12AC4B8-5BC12AC5B7-5BC12AC5B6-8(6BC12AC6B5-)6BC12AC6B6-5BC12AC5B7-E4BC12AC4BE8-4BC12AC4B9-4BC12AC4B10-3BC12AC3B13-BC12ACB15-BC12ACB16-C12AC16-AB12ACA16-14A19-10A51-12A19-12A17-16A16-C12AC17-C12AC16-BC12ACB14-2BC12AC2B12-3BC12AC3B10-4BC12AC4B9-4BC12AC4B8-5BC12AC5B7-5BC12AC5B6-6BC12AC6B5-E5BC12AC5BE5(5-6BC12AC6B)6-5BC12AC5B7-5BC12AC5B8-4BC12AC4B9-4BC12AC4B10-3BC12AC3B12-2BC12AC2B14-BC12ACB16-C12AC17-C12AC16-16A17-12A22-6A54-10A21-10A19-14A16-16A16-C12AC16-BC12ACB14-2BC12AC2B12-3BC12AC3B11-3BC12AC3B10-4BC12AC4B9-4BC12AC4B8-8(5BC12AC5B7-)5BC12AC5B8-4BC12AC4B9-4BC12AC4B10-3BC12AC3B11-3BC12AC3B12-2BC12AC2B14-BC12ACB16-C12AC16-AB12ACA16-14A19-10A85-6A25-6A22-12A17-16A16-C12AC17-C12AC16-BC12ACB14-2BC12AC2B12-3BC12AC3B11-3BC12AC3B10-E3BC12AC3BE2(9-4BC12AC4B)8-4(5BC12AC5B7-)E4BC12AC4BE8-2(4BC12AC4B9-)4BC12AC4B10-3BC12AC3B11-3BC12AC3B12-2BC12AC2B14-BC12ACB16-C12AC17-C12AC16-16A17-12A22-6A148-8A20-14A16-16A16-C12AC17-C12AC16-BC12ACB14-2BC12AC2B13-2BC12AC2B12-3BC12AC3B11-3BC12AC3B10-6(4BC12AC4B9-)4BC12AC4B10-3BC12AC3B11-3BC12AC3B12-EBC12ACBE13-2BC12AC2B14-BC12ACB16-C12AC17-C12AC16-AB12ACA16-14A20-8A208-10A19-14A16-16A16-C12AC17-C12AC16-2(BC12ACB15-)BC12ACB14-2BC12AC2B12-6(3BC12AC3B11-)3BC12AC3B12-2BC12AC2B14-2(BC12ACB15-)BC12ACB16-C12AC17-C12AC16-AB12ACA16-14A19-10A241-4A24-10A19-14A16-16A16-2(C12AC17-)C12AC16-2(BC12ACB15-)BC12ACB14-2BC12AC2B13-EBC12ACBE3(13-2BC12AC2B)14-2(BC12ACB15-)BC12ACB16-2(C12AC17-)C12AC16-AB12ACA16-14A19-10A24-4A275-4A24-10A19-14A16-16A15-AB12ACA16-2(C12AC17-)C12AC16-6(BC12ACB15-)BC12ACB16-2(C12AC17-)C12AC16-AB12ACA15-16A16-14A19-10A24-4A366-8A21-12A18-14A16-16A15-AB12ACA16-8(C12AC17-)C12AC16-AB12ACA15-16A16-14A18-12A21-8A458-6A23-10A20-12A18-14A16-8(16A15-)16A16-14A18-12A20-10A23-6A552-6A24-8A22-10A20-6(12A19-)12A20-10A22-8A24-6A739-4A26-3(6A25-)6A26-4A416-
