model
size = 30 13 6, scale = 0.05, origin = -y
material 
  colors = A:#EEE
voxels
------------------------------ ------------------------------ ------------------------------ -------------AAA-------------- ------------AAAAA------------- ------------AAAAA------------- ------------AAAAA------------- ------------AAAAA------------- ------------AAAAA------------- -------------AAA-------------- ------------------------------ ------------------------------ ------------------------------ 
------------------------------ ---AA-------------------AAAA-- ---AAAAA--------------AAAAAA-- ---AAAAAAA---AAA-----AAAAAAA-- ---AAAAAAAAAAAAAAAAAAAAAAAAA-- ---AAAAAAAAAAAAAAAAAAAAAAAAAA- -A-AAAAAAAAAAAAAAAAAAAAAAAAAA- ---AAAAAAAAAAAAAAAAAAAAAAAAA-- ---AAAAAAAAAAAAAAAAAAAAAAAAA-- ---AAAAAA----AAA-----AAAAAAA-- ---AAAA----------------AAAAA-- ---A---------------------AAA-- ------------------------------ 
--AAAAA------------------AA--- --AAAAAAA--------------AAAAAA- -AAAAAAAAAA-----------AAAAAAA- -AAAAAAAAAAA-AAA--AAAAAAAAAAA- -AAAAAAAAAAAAAAAAAAAAAAAAAAAAA AAAAAAAAAAAAAAAAAAAAAAAAAAAAAA AAAAAAAAAAAAAAAAAAAAAAAAAAAAAA AAAAAAAAAAAAAAAAAAAAAAAAAAAAAA -AAAAAAAAAAAAAAAAAAAAAAAAAAAA- -AAAAAAAAAA--AAA--AAAAAAAAAAA- -AAAAAAAAA---------AAAAAAAAAA- -AAAAAAA--------------AAAAAAA- -AAAA-------------------AAAAA- 
--AAAAA------------------AAA-- --AAAAAAA--------------AAAAAA- -AAAAAAAAAA-----------AAAAAAA- -AAAAAAAAAA-AAAA--AAAAAAAAAAA- -AAAAAAAAAAAAAAAAAAAAAAAAAAAAA AAAAAAAAAAAAAAAAAAAAAAAAAAAAAA AAAAAAAAAAAAAAAAAAAAAAAAAAAAAA AAAAAAAAAAAAAAAAAAAAAAAAAAAAAA -AAAAAAAAAAAAAAAAAAAAAAAAAAAA- -AAAAAAAAAA--AAA--AAAAAAAAAAA- -AAAAAAAAA---------AAAAAAAAAA- -AAAAAAA--------------AAAAAAA- -AAAA-------------------AAAAA- 
------------------------------ ---AA-------------------AAAA-- ---AAAAA--------------AAAAAA-- --AAAAAAAA---AAA-----AAAAAAA-- --AAAAAAAAAAAAAAAAAAAAAAAAAA-- --AAAAAAAAAAAAAAAAAAAAAAAAAAA- -AAAAAAAAAAAAAAAAAAAAAAAAAAAA- --AAAAAAAAAAAAAAAAAAAAAAAAAA-- --AAAAAAAAAAAAAAAAAAAAAAAAAA-- --AAAAAAA----AAA-----AAAAAAA-- --AAAAA----------------AAAAA-- --AA---------------------AAA-- ------------------------------ 
------------------------------ ------------------------------ ------------------------------ -------------AAA-------------- ------------AAAAA------------- ------------AAAAA------------- ------------AAAAA------------- ------------AAAAA------------- ------------AAAAA------------- -------------AAA-------------- ------------------------------ ------------------------------ ------------------------------ 
