model
size = 23 31 12, scale = 0.05, origin = -y
material 
  colors = A:#E00 B:#D00 C:#222 D:#111 E:#400 F:#BBB G:#700 H:#EEE
voxels
----------------------- ----------------------- ----------------------- ----------------------- ----------------------- ----------------------- ----------------------- ----------------------- ----------------------- ----------------------- ----------------------- ----------------------- ----------------------- -----------A----------- -----------B----------- ----------------------- ----------------------- ----------------------- ----------------------- ----------------------- ----------------------- ----------------------- ----------------------- ----------------------- ----------------------- ----------------------- ----------------------- ----------------------- ----------------------- ----------------------- ----------------------- 
----------------------- ----------------------- ----------------------- ----------------------- ----------------------- ----------------------- ----------------------- ----------------------- ----------------------- ----------------------- ----------------------- ----------------------- ----------------------- ----------B-B---------- ----------AAA---------- -----------A----------- -----------B----------- -----------A----------- ----------------------- ----------------------- ----------------------- ----------------------- ----------------------- ----------------------- ----------------------- ----------------------- ----------------------- ----------------------- ----------------------- ----------------------- ----------------------- 
----------------------- ----------------------- ----------------------- ----------------------- ----------------------- ----------------------- ----------------------- ----------------------- ----------------------- ----------------------- ----------------------- ----------------------- ----------------------- ----------B-B---------- ----------A-A---------- -----------A----------- -----------B----------- -----------A----------- -----------B----------- -----------A----------- ----------------------- ----------------------- ----------------------- ----------------------- ----------------------- ----------------------- ----------------------- ----------------------- ----------------------- ----------------------- ----------------------- 
----------------------- ----------------------- ----------------------- ----------------------- ----------------------- ----------------------- ----------------------- ----------------------- ----------------------- ----------------------- ----------------------- ----------------------- ----------------------- ---------A---A--------- ---------B---B--------- ----------B-B---------- ----------AAA---------- ----------BAB---------- ----------AAA---------- ----------BAB---------- ----------ABA---------- -----------A----------- ----------------------- ----------------------- ----------------------- ----------------------- ----------------------- ----------------------- ----------------------- ----------------------- ----------------------- 
---------BADAB--------- --------BABCBAB-------- --------ABCDCBA-------- --------BADCDAB-------- --------ADCDCDA-------- --------BGEGEGB-------- --------GFHFHFG-------- --------F-----H-------- ----------------------- ----------------------- --------HFHFHFH-------- --------CDC-CDC-------- --------ABABABA-------- --------B-----B-------- --------A-----A-------- --------BA---AB-------- --------ABA-ABA-------- --------BAA-AAB-------- --------ABA-ABA-------- --------BAAAAAA-------- --------GEAAAEG-------- --------FABABAF-------- ----------AAA---------- --------DABABAD-------- --------GBABABG-------- --------DABCBAD-------- --------ABADABA-------- --------BCDCDCB-------- --------ABADABA-------- --------BABCBAB-------- --------ABABABA-------- 
---------AAAAA--------- -------AAAAAAAAA------- ------ABAAAAAAABA------ -----ABAAAAAAAAABA----- -----BABAAAAAAABAB----- -----ABAAAAAAAAABA----- -----BABAAAAAAABAB----- -----AEGA-----AGEA----- -----BHF-------FHB----- -----H-----------H----- -----FHFAAAAAAAFHF----- -----EGEAAAAAAAEGE----- -----CDCAAA-AAACDC----- -----ABAA-----AABA----- -----BABA-----ABAB----- -----ABAAA---AAABA----- -----BABAAA-AAABAB----- -----ABAAAA-AAAABA----- -----BABAAA-AAABAB----- -----AGEAAAAAAAEGA----- -----FHFAAAAAAAFHF----- --------AAAAAAA-------- ---------AAAAA--------- -----CDCAAAAAAACDC----- -----BABAAAAAAABAB----- -----GBCAAAAAAACBG----- -----DCBAAAAAAABCD----- -----ABAAAAAAAAABA----- -----BABAAAAAAABAB----- -----ABAAAAAAAAABA----- -----BABAAAAAAABAB----- 
----------------------- -------A-------A------- -----AAA-------AAA----- ----BAAA-------AAAA---- ----AAAA-------AAAA---- ---ABAAA-------AAABA--- ---BAAAA-------AAAAB--- ---ABAAA-------AAABA--- ---BAAAA-------AAAAB--- ---AB------------ABA--- ---BAAAA-------AAAAB--- ---ABAAA-------AAABA--- ---BEAAA-------AAAEB--- ---ECAAA-------AAACE--- ---CAAAA-------AAAAC--- ---ABAAA-------AAABA--- ---BAAAA-------AAAAB--- ---ABAAA-------AAABA--- ---BAAAA-------AAAAB--- ---ABAAA-------AAABA--- ---BGAAA-------AAAGB--- ---HF-------------FH--- ----------------------- ---CDAAA-------AAADC--- ---BAAAA-------AAAAB--- ---ABAAA-------AAABA--- ---ECAAA-------AAACE--- ---CBAAA-------AAAAC--- ---BAAAA-------AAAAB--- ---ABAAA-------AAABA--- ---BAAAA-------AAAAB--- 
----------------------- ----------------------- -----A-----------A----- ----BA-----------AA---- ---AAA-----------AAA--- --BAAA-----------AAAB-- --AAAA-----------AAAA-- --BAAA-----------AAAB-- --AAAA-----------AAAA-- --BAAA-----------AAAB-- --AAAA-----------AAAA-- --BAAA-----------AAAB-- --EAAA-----------AAAE-- --CAAA-----------AAAC-- --AAAA-----------AAAA-- --BAAA-----------AAAB-- --AAAA-----------AAAA-- --BAAA-----------AAAB-- --AAAA-----------AAAA-- --AAAA-----------AAAB-- --AAAA-----------AAAA-- --BAA-------------AAB-- --A-----------------A-- --BAAA-----------AAAB-- --AAAA-----------AAAA-- --EAAA-----------AAAE-- --CAAA-----------AAAC-- --AAAA-----------AAAB-- --AAAA-----------AAAA-- --BAAA-----------AAAB-- --AAAA-----------AAAA-- 
----------------------- ----------------------- ----------------------- ----------------------- ---B---------------A--- --AA---------------AA-- -BAA---------------AAB- -AAA---------------AAA- -BAA---------------AAB- -AAA---------------AAA- -BAA---------------AAB- -AAA---------------AAA- -BAA---------------AAB- -AAA---------------AAA- -BAA---------------AAB- -AAA---------------AAA- -BAA---------------AAB- -AAA---------------AAA- -BAA---------------AAB- -AAA---------------AAA- -BAA---------------AAB- -AAA---------------AAA- -BAA----------------AB- -AAA---------------AAA- -BAA---------------AAB- -AAA---------------AAA- -BAA---------------AAB- -AAA---------------AAA- -BAA---------------AAB- -AAA---------------AAA- --AA---------------AA-- 
----------------------- ----------------------- ----------------------- ----------------------- ----------------------- --B-----------------A-- -AA-----------------AA- -BA-----------------AA- AAA-----------------AAA BAA-----------------AAB AAA-----------------AAA BAA-----------------AAB AAA-----------------AAA BAA-----------------AAB AAA-----------------AAA BAA-----------------AAB AAA-----------------AAA BAA-----------------AAB AAA-----------------AAA BAA-----------------AAB AAA-----------------AAA BAA-----------------AAB AAA-----------------AAA BAA-----------------AAB AAA-----------------AAA BAA-----------------AAB AAA-----------------AAA BAA-----------------AAB AAA-----------------AAA -AA-----------------AA- --A-----------------A-- 
----------------------- ----------------------- ----------------------- ----------------------- ----------------------- ----------------------- -B-------------------A- -A-------------------A- BA-------------------AB AA-------------------AA BA-------------------AB AA-------------------AA BA-------------------AB AA-------------------AA BA-------------------AB AA-------------------AA BA-------------------AB AA-------------------AA BA-------------------AB AA-------------------AA BA-------------------AB AA-------------------AA BA-------------------AB AA-------------------AA BA-------------------AB AA-------------------AA BA-------------------AB AA-------------------AA BA-------------------AB -A-------------------A- ----------------------- 
----------------------- ----------------------- ----------------------- ----------------------- ----------------------- ----------------------- ----------------------- ----------------------- A---------------------- B---------------------B A---------------------A B---------------------B A---------------------A B---------------------B A---------------------A B---------------------B A---------------------A B---------------------B A---------------------A B---------------------B A---------------------A B---------------------B A---------------------A B---------------------B A---------------------A B---------------------B A---------------------A B---------------------B A---------------------A ----------------------- ----------------------- 
