model
size = 23 31 12, scale = 0.05, origin = -y
material 
  colors = A:#FC9 B:#FF9 C:#FFF D:#F66 E:#DDD F:#FC3 G:#EEE H:#09F I:#111
voxels
----------------------- ----------------------- ----------------------- ----------------------- ----------------------- ----------------------- ----------------------- ----------------------- ----------------------- ----------------------- ----------------------- ----------------------- ----------------------- -----------C----------- -----------B----------- ----------------------- ----------------------- ----------------------- ----------------------- ----------------------- ----------------------- ----------------------- ----------------------- ----------------------- ----------------------- ----------------------- ----------------------- ----------------------- ----------------------- ----------------------- ----------------------- 
----------------------- ----------------------- ----------------------- ----------------------- ----------------------- ----------------------- ----------------------- ----------------------- ----------------------- ----------------------- ----------------------- ----------------------- ----------------------- ----------AAA---------- ----------AAA---------- -----------C----------- -----------B----------- -----------C----------- -----------B----------- -----------C----------- ----------------------- ----------------------- ----------------------- ----------------------- ----------------------- ----------------------- ----------------------- ----------------------- ----------------------- ----------------------- ----------------------- 
----------------------- ----------------------- ----------------------- ----------------------- ----------------------- ----------------------- ----------------------- ----------------------- ----------------------- ----------------------- ----------------------- ----------------------- ----------------------- ----------A-A---------- ----------AAA---------- -----------C----------- -----------A----------- -----------C----------- -----------A----------- -----------C----------- -----------B----------- ----------------------- ----------------------- ----------------------- ----------------------- ----------------------- ----------------------- ----------------------- ----------------------- ----------------------- ----------------------- 
----------------------- ----------------------- ----------------------- ----------------------- ----------------------- ----------------------- ----------------------- ----------------------- ----------------------- ----------------------- ----------------------- ----------------------- ----------------------- ---------CA-AC--------- ---------BA--B--------- ----------AAA---------- ----------AAA---------- ----------AAA---------- ----------AAA---------- ----------AAA---------- ----------AAA---------- -----------C----------- ----------------------- ----------------------- ----------------------- ----------------------- ----------------------- ----------------------- ----------------------- ----------------------- ----------------------- 
----------------------- ----------------------- ----------------------- ----------------------- ----------------------- ------DDDDDDDDDDD------ -----D-----------D----- -----D-----------D----- -----D-----------D----- ------DDDDDDDDDDD------ --------ABABABA-------- --------ACACACA-------- --------ABABABA-------- --------AA---AA-------- --------AA---AA-------- --------ACA-ACA-------- --------ABA-ABA-------- --------ACA-ACA-------- --------FBA-ABF-------- --------ACAAACA-------- --------ABAAABA-------- --------DCAAACD-------- ----------ABA---------- ---------CA-AC--------- --------A-----A-------- ----------EEE---------- ----------EIE---------- ----------EEE---------- --------A-----A-------- ---------CACAC--------- ----------------------- 
----------------------- -------CACACACAC------- ------ABABABABABA------ -----CACACACACACAC----- -----BABABABABABAB----- -----CDDDDDDDDDDDC----- -----DGG-GG-GG-GGD----- -----D-----------D----- -----DGG-GG-GG-GGD----- -----BDDAAAAAAADDB----- -----BABAAAAAAABAB----- -----CACAAAAAAACAC----- -----BABAAAAAAABAB----- -----CACA-----ACAC----- -----BABA-----ABAB----- -----CACAA---AACAC----- -----BABAAA-AAABAB----- -----CACAAA-AAACAC----- -----BFBAAA-AAABFB----- -----CACAAAAAAACAC----- --------AAAAAAA-------- --------DAAAAAD-------- ---------AAAAA--------- -----CABAAAAAAACAC----- -----BABAFHFHFABAB----- -----CACFHAAAHFCAC----- -----BAFHFAAAFHFAB----- -----CACFHAAAHFCAC----- -----BABAFHFHFABAB----- -----CACAAAAAAACAC----- -----BABABABABABAB----- 
---------AAAAA--------- -------AAAAAAAAA------- -----BAAAAAAAAAAAB----- ----AAAAAAAAAAAAAAA---- ----AAAAAAAAAAAAAAA---- ---CAAAAAAAAAAAAAAAC--- ---BAA-----------AAB--- ---CAA-----------AAC--- ---BAA-----------AAB--- ---CAAAAAAAAAAAAAAAC--- ---BAAAAAAAAAAAAAAAB--- ---CAAAAAAAAAAAAAAAC--- ---BAAAAAAAAAAAAAAAB--- ---CAAAAA-----AAAAAC--- ---BAAAAA-----AAAAAB--- ---CAAAAAA---AAAAAAC--- ---BAAAAAAA-AAAAAAAB--- ---CAAAAAAA-AAAAAAAC--- ---BFAAAAAA-AAAAAAFB--- ---CAAAAAAAAAAAAAAAC--- ---BDEEEAAAAAAAEEEDB--- ---DDE-EAAAAAAAE-EDD--- -----EEE-AAAAA-EEE----- ---CAAAAAAAAAAAAAAAC--- ---BAAAAAAAAAAAAAAAB--- ---CAAAAAAAAAAAAAAAC--- ---BAAAAAAAAAAAAAAAB--- ---CAAAAAAAAAAAAAAAC--- ---BAAAAAAAAAAAAAAAB--- ---CAAAAAAAAAAAAAAAC--- ---BAAAAAAAAAAAAAAAB--- 
----------------------- ----------------------- -----A-----------A----- ----AA-----------AA---- ---BAA-----------AA---- --ABAA-----------AAAA-- --ABAA-----------AAAA-- --AAAA-----------AAAA-- --AAAA-----------AAAA-- --AAAA-----------AAAA-- --AA---------------AA-- --AA---------------AA-- --AA---------------AA-- --AA---------------AA-- --AA---------------AA-- --AA---------------AA-- --AA---------------AA-- --AA---------------AA-- --AA---------------AA-- --AA---------------AA-- --AAA-------------AAA-- --AAA-------------AAA-- --A-----------------A-- --AA---------------AA-- --AAA-------------AAA-- --AAAA-----------AAAA-- --AAAA-----------AAAA-- --AAAA-----------AAAA-- --AAAA-----------AAAA-- --AAAA-----------AAAA-- --AAAA-----------AAAA-- 
----------------------- ----------------------- ----------------------- ----------------------- ---A---------------A--- --AA---------------AA-- -BAA---------------AAB- -BAA---------------AAC- -BAA---------------AAB- -CAA---------------AAC- -BA-----------------AB- -CA-----------------AC- -BA-----------------AB- -CA-----------------AC- -BA-----------------AB- -CA-----------------AC- -BA-----------------AB- -CA-----------------AC- -BA-----------------AB- -CA-----------------AC- -BA-----------------AB- -CA-----------------AC- -BA-----------------AB- -CA-----------------AC- -BAA----------------AB- -CAA---------------AAC- -BAA---------------AAB- -CAA---------------AAC- -BAA---------------AAB- -CAA---------------AAC- --AA---------------AA-- 
----------------------- ----------------------- ----------------------- ----------------------- ----------------------- --A-----------------A-- -AA-----------------AA- -AA-----------------AA- AAA-----------------AAA AAA-----------------AAA AAA-----------------AAA AAA-----------------AAA AAA-----------------AAA AAA-----------------AAA AAA-----------------AAA AAA-----------------AAA AAA-----------------AAA AAA-----------------AAA AAA-----------------AAA AAA-----------------AAA AAA-----------------AAA AAA-----------------AAA AAA-----------------AAA AAA-----------------AAA AAA-----------------AAA AAA-----------------AAA AAA-----------------AAA AAA-----------------AAA AAA-----------------AAA -AA-----------------AA- --A-----------------A-- 
----------------------- ----------------------- ----------------------- ----------------------- ----------------------- ----------------------- -A-------------------A- -A-------------------A- AA-------------------AA AA-------------------AA AA-------------------AA AA-------------------AA AA-------------------AA AA-------------------AA AA-------------------AA AA-------------------AA AA-------------------AA AA-------------------AA AA-------------------AA AA-------------------AA AA-------------------AA AA-------------------AA AA-------------------AA AA-------------------AA AA-------------------AA AA-------------------AA AA-------------------AA AA-------------------AA AA-------------------AA -A-------------------A- ----------------------- 
----------------------- ----------------------- ----------------------- ----------------------- ----------------------- ----------------------- ----------------------- ----------------------- A---------------------- A---------------------A A---------------------A A---------------------A A---------------------A A---------------------A A---------------------A A---------------------A A---------------------A A---------------------A A---------------------A A---------------------A A---------------------A A---------------------A A---------------------A A---------------------A A---------------------A A---------------------A A---------------------A A---------------------A A---------------------A ----------------------- ----------------------- 
