model
size = 30 32 26, scale = 0.05, origin = -y
material 
  colors = A:#F5F5F5 B:#000 C:#EAEAEA D:#EDEDED E:#CFCFCF F:#FF69C8 G:#FFF
voxels
520-2(10A20-)10A889-2(12A18-)12A19-10A20-10A22-6A799-2(4A8-4A14-)4A8-4A16-2(12A18-)12A19-10A20-10A736-5(3A12-)3A13-2(4A8-4A14-)16A15-14A17-12A19-10A21-8A676-DA16-AD2(10-2A16-2A)11-G2A12-2AG2(12-3A)2(12-5A8-5A)13-15AC15-6A2-6A17-12A20-C2AC4A23-3AC2A556-D20-F8-E20-E8-2A18-AD2(8-2A18-2A)9-2(2A16-2A10-)3A14-3A11-2A14-2A12-4A10-4A13-3A10-3A15-4A6-4A17-12A19-10A524-F20-D5(8-A20-A)9-2(A18-A10-)2A16-2A11-A16-A2(12-2A14-2A)13-3A10-3A15-4A6-4A17-12A21-6A435-D22-F6-E22-E7-A20-A8-A20-A7-3(A22-A6-)A22-A7-2(A20-A8-)2A18-2A9-A18-A11-2(2A14-2A12-)C2A12-2AC13-3A10-3A15-4A6-4A18-10A22-C5A375-F22-D8(6-A22-A)7-2(A20-A8-)2A18-2A9-A18-A10-2A16-2A11-A16-A12-2A14-2A2(12-3A)13-4A8-4A16-3A6-3A20-8A343-D24-F5-2(A22-A6-)2A20-2A7-A20-A7-A22-A6-A22-A5-2(A24-A4-)A24-A5-C22-A6-A22-A7-A20-A8-A20-A9-2A16-2A10-2A16-2A11-2A14-2A2(12-3A)13-3A10-3A16-2A8-2A19-AC6A2C41-B26-B-3B24-3B-B26-B152-F26-D3-E24-E3(4-A24-A)4-2A22-2A5-2(A22-A6-)A22-A5-A24-C2(4-A24-A)5-A22-A6-A22-A7-2(A20-A8-)2A18-2A9-A18-A10-2A16-2A11-2A14-2A2(12-3A)14-2A10-2A17-4A4-4A22-4A13-3B2(24-6B)24-3B-E26-E62-E26-E2-D26-F3-5(A24-A4-)2A22-2A5-A22-A6-A22-A5-2A22-2A3(4-A24-A)5-2(A22-A6-)2A20-2A7-A20-A8-2A18-2A8-2A18-AC9-2A16-2A10-3A14-3A11-3A12-3A14-2A10-2A17-3A6-3A21-6A13-B26-B-3B24-3B-B26-B32-E26-E2-E26-E62-D26-F3-4(A24-A4-)4(2A22-2A4-)2(A24-A4-)A24-A5-A22-A6-C22-A6-2A20-2A7-A20-A2(8-2A18-2A)8-3A16-3A9-3A14-3A11-3A12-3A14-2A10-2A17-3A6-3A21-6A283-E26-E3-3(A24-A4-)2A22-2A4-A24-A5-A22-A5-2A22-2A3(4-A24-A)5-2(A22-A6-)2A20-2A7-A20-A2(8-2A18-2A)8-3A16-3A9-3A14-3A11-3A12-3A14-2A10-2A17-3A6-3A21-2AC3A314-F24-D2(4-A24-A)4-2A22-2A4-A24-A5-A22-A6-A22-A5-2(A24-A4-)A24-A5-2(A22-A6-)2A20-2A7-A20-A2(8-2A18-2A)9-2A16-2A10-3A14-3A11-3A12-3A14-2A10-2A17-3A6-C2A21-6A344-D24-F4-E24-E2(4-A24-A)5-A22-A6-A22-A5-2(A24-A4-)A24-A5-A22-A6-A22-A7-2(A20-A8-)CA18-2A9-A18-A10-2A16-2A11-2A14-2A2(12-3A)14-2A10-2A17-4A4-4A22-4A405-F24-D4-A24-A5-A22-A6-A22-A5-2(A24-A4-)A24-A5-A22-A6-A22-A7-A20-A8-A20-A9-2A16-2A10-2A16-2A11-2A14-2A2(12-3A)13-3A10-3A16-2A8-2A19-10A462-D24-F5-4(A22-A6-)A22-A7-2(A20-A8-)2A18-2A9-A18-A10-2A16-2A11-A16-A12-2A14-2A2(12-3A)13-4A8-4A16-3A6-3A20-7AC494-E22-E4(6-A22-A)7-A20-A8-A20-C8-2A18-2A9-A18-A11-2(2A14-2A12-)3A12-3A13-3A10-2AC15-4A6-4A18-10A22-6A525-F22-D6-2A20-2A7-A20-A8-A20-A9-2(A18-A10-)2A16-2A11-A16-A2(12-2A14-2A)13-C2A10-3A15-4A6-4A17-12A21-C5A585-DA20-2A7-A20-A8-A20-A9-2(2A16-2A10-)3A14-3A11-2A14-2A12-4A10-4A13-3A10-3A15-4A6-4A17-12A19-10A615-2(A18-A10-)A18-A11-2(2A14-2A12-)3(3A12-)3A13-5A6-5A15-4A6-4A17-C11A20-5AC2A23-6A618-D16-D12-A16-A12-A16-C13-2A12-AC14-CA12-2A14-4A8-4A15-3A8-3A18-10A20-10A21-2AC5A678-2(2A12-2A14-)2A12-2A16-2(2A8-2A18-)11AC18-12A21-6A741-DA8-AD2(18-2A8-2A)20-2(8A22-)8A23-2AC3A773-D6AD22-8A22-5AC2A23-6A342-
