model
size = 30 32 26, scale = 0.05, origin = -y
material 
  colors = A:#252525 B:#FFF C:#717171 D:#C10000 E:#F00 F:#E2E2E2 G:#000 H:#FF6B01
voxels
521-2(8B22-)3B2H3B25-2H863-2(2B8C2B18-)2B8C2B20-8B22-8B828-2(2B2C8-2C2B14-)2B2C8-2C2B16-2(2B8C2B18-)2BG6BG2B18-B3G4B3GB19-BG6BGB736-2(B2C12-2CB12-)B2C12-2CB13-2(2B2C8-2C2B14-)2B2A8C2A2B15-2BA8CA2B18-10B20-4B2A4B21-2B4A2B676-2(BC16-CB10-)BC16-CB11-2(BAC12-CAB12-)3A2C8-2C3A12-ABA2C8-2CABA13-A2B2A6C2A2BA15-AB2A2C2-2C2ABA17-AB8ABA20-8A23-6A556-E20-E8-F20-F3(8-AC18-CA)9-2(2A16-2A10-)3A14-3A11-2A14-2A12-4A10-4A13-3A10-3A15-4A6-4A17-12A19-10A524-E20-E5(8-A20-A)9-2(A18-A10-)2A16-2A11-A16-A2(12-2A14-2A)13-3A10-3A15-4A6-4A17-12A21-6A435-E22-E6-F22-F7-A20-A8-A20-A7-3(A22-A6-)A22-A7-2(A20-A8-)2A18-2A9-A18-A11-2(2A14-2A12-)3A12-3A13-3A10-3A15-4A6-4A18-10A22-6A375-E22-E8(6-A22-A)7-2(A20-A8-)2A18-2A9-A18-A10-2A16-2A11-A16-A12-2A14-2A2(12-3A)13-4A8-4A16-3A6-3A20-8A343-E24-E5-2(A22-A6-)2A20-2A7-A20-A7-A22-A6-A22-A5-2(A24-A4-)A24-A5-A22-A6-A22-A7-A20-A8-A20-A9-2A16-2A10-2A16-2A11-2A14-2A2(12-3A)13-3A10-3A16-2A8-2A19-10A41-D26-D-3D24-3D-D26-D152-E26-E3-F24-F3(4-A24-A)4-2A22-2A5-2(A22-A6-)A22-A5-2(A24-A4-)A24-A5-A22-A6-A22-A7-2(A20-A8-)2A18-2A9-A18-A10-2A16-2A11-2A14-2A2(12-3A)14-2A10-2A17-4A4-4A22-4A13-3D2(24-6D)24-3D-F26-F62-F26-F2-E26-E3-5(A24-A4-)2A22-2A5-A22-A6-A22-A5-2A22-2A3(4-A24-A)5-2(A22-A6-)2A20-2A7-A20-A2(8-2A18-2A)9-2A16-2A10-3A14-3A11-3A12-3A14-2A10-2A17-3A6-3A21-6A13-D26-D-3D24-3D-D26-D32-F26-F2-F26-F62-E26-E3-4(A24-A4-)4(2A22-2A4-)2(A24-A4-)A24-A5-2(A22-A6-)2A20-2A7-A20-A2(8-2A18-2A)8-3A16-3A9-3A14-3A11-3A12-3A14-2A10-2A17-3A6-3A21-6A283-F26-F3-3(A24-A4-)2A22-2A4-A24-A5-A22-A5-2A22-2A3(4-A24-A)5-2(A22-A6-)2A20-2A7-A20-A2(8-2A18-2A)8-3A16-3A9-3A14-3A11-3A12-3A14-2A10-2A17-3A6-3A21-6A314-E24-E2(4-A24-A)4-2A22-2A4-A24-A5-A22-A6-A22-A5-2(A24-A4-)A24-A5-2(A22-A6-)2A20-2A7-A20-A2(8-2A18-2A)9-2A16-2A10-3A14-3A11-3A12-3A14-2A10-2A17-3A6-3A21-6A344-E24-E4-F24-F2(4-A24-A)5-A22-A6-A22-A5-2(A24-A4-)A24-A5-A22-A6-A22-A7-2(A20-A8-)2A18-2A9-A18-A10-2A16-2A11-2A14-2A2(12-3A)14-2A10-2A17-4A4-4A22-4A405-E24-E4-A24-A5-A22-A6-A22-A5-2(A24-A4-)A24-A5-A22-A6-A22-A7-A20-A8-A20-A9-2A16-2A10-2A16-2A11-2A14-2A2(12-3A)13-3A10-3A16-2A8-2A19-10A462-E24-E5-4(A22-A6-)A22-A7-2(A20-A8-)2A18-2A9-A18-A10-2A16-2A11-A16-A12-2A14-2A2(12-3A)13-4A8-4A16-3A6-3A20-8A494-F22-F4(6-A22-A)7-2(A20-A8-)2A18-2A9-A18-A11-2(2A14-2A12-)3A12-3A13-3A10-3A15-4A6-4A18-10A22-6A525-E22-E6-2A20-2A7-A20-A8-A20-A9-2(A18-A10-)2A16-2A11-A16-A2(12-2A14-2A)13-3A10-3A15-4A6-4A17-12A21-6A585-EA20-AE7-A20-A8-A20-A9-2(2A16-2A10-)3A14-3A11-2A14-2A12-4A10-4A13-3A10-3A15-4A6-4A17-12A19-10A615-E18-E2(10-A18-A)11-2(2A14-2A12-)3(3A12-)3A13-5A6-5A15-4A6-4A17-12A20-8A23-6A618-2(A16-A12-)A16-A13-2(2A12-2A14-)4A8-4A15-3A8-3A18-10A20-10A21-8A678-AE12-EA2(14-2A12-2A)16-2(2A8-2A18-)12A18-12A20-A6-A740-2(2A8-2A18-)2A8-2A20-8A21-10A20-4A2-4A20-3A4-3A21-A6-A742-E6AE2(22-8A)25-2A344-
