model
size = 30 17 12, scale = 0.05, origin = -y
material 
  colors = A:#EEE B:#FFF C:#CE3925 D:#BBB E:#777977 F:#AAA G:#DCDCDC H:#444 I:#E3E3E3 J:#B6B6B6
voxels
----IFJFJFFAIAIAIAIAIFJFFAI--- ----AFFJFJFAAAAAAAAAAAFJAAA--- ----AAFFJFAA---------AAAA----- -----AAAAAA-----------AA------ ------AAAA-------------------- -------AA--------------------- ------------------------------ ------------------------------ ------------------------------ ------------------------------ ------------------------------ ---------A-------------------- ---------H-------------------- ---------H-------------------- ------------------------------ ------------------------------ ------------------------------ 
---AGCCCCCCGGGGGGGGGGCCCCGGA-- ---AAAAAAAAAABBBBBBBBBBBBAAA-- ----CCCCCCCCCCCCCCCCCCCCCCC--- ----FCCCCCCEEFFFFFEECCCCCCC--- ----EECCCCEEEEFFFFFEECCCC----- ----DEECCEEDEEEFFEFFEECC------ ----DDEEEEDDDE-FFFEF---------- -----DDDDDDCD---FFFFF--------- ------DDDDCD-----FF----------- -------DDDDD------------------ ---------DD------------------- ------------------------------ ------------------------------ ---------H-------------------- ---------H-------------------- ------------------------------ ------------------------------ 
-AIBBBBBBBBBEBBBBBBEBBBBBBBBI- -AAAABBBBBBBBBBBBBBBBBBBBBBAA- --CCAAAAAAAAAAAAAAAAAAAAAAAC-- --FFA----------------------C-- --EEA--------------------EEE-- --DCA-------------------EEE--- --DCA---------D-----DEEEEE---- --DCCAAAAA-AADDD---AFH-------- --DCCCAAAAAADDDDDAHF---------- --DCCCCAAAAADDDHFF------------ --DDCFCCCAADDDF--------------- --DDCCFCCCDDFH---------------- ---DDCCCCDDD------------------ ----DDCDDDDD------------------ -----DD-DHDH------------------ --------DDD------------------- ------------------------------ 
IBBBEGGGGEGBBEEEEEEBGGEEGGEBBA A-ABBBBBBBBBBBBBBBBBBBBBBBBBAA -CAAAAAAAAAAAAAAAAAAAAAAAAAAC- -FA-------------------------C- -EA-------------------------E- -EA------------------------DD- -EA------------------CCCDDDD-- -EA----------------CCHHH------ -EA--------------CCHH--------- -EA------------CCHH----------- -EA-----------CHH------------- -E----------CCH--------------- -----------CHH---------------- -----------CH----------------- -----------CH----------------- -----------C------------------ ------------------------------ 
ABCEGGBBGGEGBGBGBGBGGBGGBGGCBI ABBBBBBBBBBBBBBBBBBBBBBBBBBBBA CAAAAACAACACACCCACCCACCACACAAC F----------------------------C EA---------------------------E FA--------------------------AD EA-----------------------DDDD- FA--------------------DDH----- EA------------------DH-------- FA----------------DH---------- -E--------------DH------------ -E-----------ADH-------------- -E---------CAH---------------- -----------CD----------------- -----------CH----------------- -----------C------------------ -----------C------------------ 
IBCGGBEEBGGBEBEBEBGGBEBBEBGCBA ABBBBBBBBBBBBBBBBBBBBBBBBBBBBA AAACCACACCACAAACAAACACAACCCAAC F----------------------------C F----------------------------E F----------------------------D F------------------------DDDD- F---------------------DDH----- F-------------------DH-------- F-----------------DH---------- C---------------DH------------ F------------ADD-------------- -E---------CAH---------------- -D---------AD----------------- -----------AH----------------- -----------C------------------ -----------C------------------ 
ABCGGBEEBGGBEBEBEBGGBEBBEBGCBI ABBBBBBBBBBBBBBBBBBBBBBBBBBBBA AAACCACCACAAACCAACCAACAACACAAC F----------------------------C F----------------------------E F----------------------------D F------------------------DDDD- F---------------------DDH----- F-------------------DH-------- F-----------------DH---------- C---------------DH------------ F------------ADD-------------- -E---------CAH---------------- -D---------AD----------------- -----------AH----------------- -----------C------------------ -----------C------------------ 
IBCEGGBBGGEGBGBGBGBGGBGGBGGCBA ABBBBBBBBBBBBBBBBBBBBBBBBBBBBA CAAAAACAACACACCCACCCACAACCCAAC F----------------------------C EA---------------------------E FA--------------------------AD EA-----------------------DDDD- FA--------------------DDH----- EA------------------DH-------- FA----------------DH---------- -E--------------DH------------ -E-----------ADH-------------- -E---------CAH---------------- -----------CD----------------- -----------CH----------------- -----------C------------------ -----------C------------------ 
ABBBEGGGGEGBBEEEEEEBGGEEGGEBBI A-ABBBBBBBBBBBBBBBBBBBBBBBBBAA -CAAAAAAAAAAAAAAAAAAAAAAAAAAC- -FA-------------------------C- -EA-------------------------E- -EA------------------------DD- -EA------------------CCCDDDD-- -EA----------------CCHHH------ -EA--------------CCHH--------- -EA------------CCHH----------- -EA-----------CHH------------- -E----------CCH--------------- -----------CHH---------------- -----------CH----------------- -----------CH----------------- -----------C------------------ ------------------------------ 
-IAGBBBBBBBBEBBBBBBEBBBBBBBBA- -AAAABBBBBBBBBBBBBBBBBBBBBBAA- --CCAAAAAAAAAAAAAAAAAAAAAAAC-- --FFA----------------------C-- --EEA--------------------EEE-- --DCA-------------------EEE--- --DCA---------D-----DEEEEE---- --DCCAAAAA-AADDD---AFH-------- --DCCCAAAAAADDDDDAHF---------- --DCCCCAAAAADDDHFF------------ --DDCECCCAADDDF--------------- --DDCCECCCDDFH---------------- ---DDCCCCDDD------------------ ----DDCDDDDD------------------ -----DD-DHDH------------------ --------DDD------------------- ------------------------------ 
---IGCCCCCCGGGGGGGGGGCCCCGGI-- ---AAAAAAAAAABBBBBBBBBBBBAAA-- ----CCCCCCCCCCCCCCCCCCCCCCC--- ----FCCCCCCEEFFFFFEECCCCCCC--- ----EECCCCEEEEFFFFFEECCCC----- ----DEECCEEDEEEFFEFFEECC------ ----DDEEEEDDDE-FFFEF---------- -----DDDDDDCD---FFFFF--------- ------DDDDCD-----FF----------- -------DDDDD------------------ ---------DD------------------- ------------------------------ ------------------------------ ---------H-------------------- ---------H-------------------- ------------------------------ ------------------------------ 
----AFJFJFFIAIAIAIAIAFJFFIA--- ----AFFJFJFAAAAAAAAAAAFJAAA--- ----AAFFJFAA---------AAAA----- -----AAAAAA-----------AA------ ------AAAA-------------------- -------AA--------------------- ------------------------------ ------------------------------ ------------------------------ ------------------------------ ------------------------------ ---------A-------------------- ---------H-------------------- ---------H-------------------- ------------------------------ ------------------------------ ------------------------------ 
