model
size = 32 32 22, scale = 0.05, origin = -y
material 
  colors = A:#CC83B6 B:#FF0072 C:#956 D:#FFC5FC E:#111 F:#444 G:#ED9F9F H:#777 I:#DB00EF J:#800 K:#700 L:#222 M:#500 N:#EEE
voxels
425-2GI2G4-2GI2G20-G8-G22-G8-G885-3F6-3F19-5F4-5F17-G5BG2-G5BG17-2DB2D4-2DB2D19-DBD6-DBD21-H8-H22-I8-I820-F3-F4-F3-F18-F3-F4-F3-F17-GB4-G2-G4-BG17-D3-D4-D3-D18-D3-D4-D3-D19-HBH6-HBH20-HBH6-HBH21-B8-B788-F3-F4-F3-F18-F3-F4-F3-F17-IB3-BG2-GB3-BI16-GD3-BG2-GB3-DG16-GD3-D4-D3-DG17-H3BH4-H3BH18-I2BH6-H2BI19-3B6-3B21-D8-D22-D8-D725-3F6-3F19-5F4-5F17-G5BG2-G5BG17-3DBD4-DB3D18-3DBD4-DB3D19-HBH6-HBH20-HBH6-HBH21-B8-B54-D8-D154-2E28-6E597-G5FD2-D5FG17-3DBD-2D-DB3D19-3D2-2D2-3D21-H3-2D3-H22-H3-2D3-H26-2D30-2D26-3D4H3D24-6D123-2(4E28-)E2-E2(28-L2-L)28-F2-F14-6G2D2H2B3F2-3F2B2H2D6G237-2A2-2A25-3A2-3A25-A4-A28-2(2D30-)2H24-5D-2H-5D20-D3-2D3-D22-D3-2D3-D26-2D286-2E29-4E378-3(3A2-3A24-)8A27-2B6(30-2D)286-2E30-2E186-CA6-AC151-3A2-3A23-4A2-4A2(22-10A)23-C2A2B2AC24-3C2B3C58-5(D2BD28-)4D253-2E30-2E186-CA6-AC22-CA6-AC23-A6-A23-3A4-3A23-3A2-3A23-10A22-10A21-12A20-12A21-C8AC22-10C55-8A24-2A4B2A24-2CD2BD2C24-2AD2BD2A24-ACD2BDCA25-A4DA59-4C93-2B93-4B29-2E30-2E186-CA6-AC22-C2A4-2AC22-C8AC2(22-10A)21-3(12A20-)A10CA21-C8-C87-2A4B2A22-2C2A4B2A2C2(20-4A4B4A)20-2ACA4BAC2A21-C8AC23-3C2B3C27-2B61-4B28-B2-B27-2B2E2B28-2B60-2B2-2B28-2E155-A6-A23-3A-2A-3A21-2(C10AC20-)4(12A20-)2A2C4A2C2A21-C2-4F2-C25-4B28-4B25-3A4B3A21-CA8BAC21-E8BE18-2A-EA8BAE-2A14-2A-EA8BAE-2A15-A-2A8B2A-A19-2CE4BE2C25-2(4B28-)4E26-2B4E2B24-B2E2-2EB3(24-8E)24-B6EB27-2E123-A6-A23-3A-2A-3A22-10A21-4(C10AC20-)C10AC15-K2JB-CAC6ACAC-B2JK13-B2-C-F4-F-C2-B16-B4-6F4-B16-B4-F4BF4-B16-B2-3C4B3C2-B16-F-C10AC-F16-F2-E8AE2-F14-2A2BE10AE2B2A12-2A2B12A2B2A13-BA-12A-AB17-I2CE4AE2CI24-4B28-4B27-B4-B25-2B4-2B23-2B6-2B2(22-B3-2I3-B)22-B8-B22-2B6-2B23-3B2-3B27-2E30-2B91-A2-2A2-A24-8A23-2(10A22-)10A21-12A20-12A17-JM-A3C4A3CA-MJ18-C2-4F2-C25-4F28-F2AF25-3C4A3C21-C10AC21-E8AE18-2A-E10AE-2A14-2A-E10AE-2A15-A-AC8ACA-A20-8C27-2B29-4B27-B4-B25-2B4-2B23-2B6-2B26-2I26-B3-2I3-B54-2B6-2B23-B-B2-B-B26-4B125-2A27-8A24-3A2-3A24-8A23-10A21-12A20-12A15-K2J3-10C3-2JK16-C8-C58-2C27-8C22-2C8A2C3(20-12A)21-C8AC24-6C59-4B27-B4-B25-2B4-2B23-2B6-2B26-2I26-B3-2I3-B54-2B6-2B23-B-B2-B-B26-4B125-2A27-2(2A-)2A25-6A26-6A25-8A23-2(10A22-)3C4A3C22-10C58-2C27-8C23-C8AC2(22-10A)23-C6AC25-6A28-2C61-4B27-B4-B25-2B4-2B23-2B6-2B26-2I26-B3-2I3-B54-2B6-2B23-B-B2-B-B26-4B157-2B29-A2BA28-A2BA27-2A2B2A25-2A4B2A24-A2B2I2BA25-C4BC26-2C2B2C91-4C26-2C4A2C24-8A24-AC4ACA25-6A27-4A123-B4-B25-2B4-2B23-2B6-2B26-2I26-B3-2I3-B54-2B6-2B23-B-B2-B-B26-4B189-2(2B30-)2B29-4B27-2B2-2B27-4B29-2B94-2C28-2C2A2C26-AC2ACA27-4C29-2A187-2B4-2B23-2B6-2B26-2I26-B3-NI3-B54-2B6-2B23-B-B2-B-B26-4B509-2B30-2B251-B6-B23-2B6-2B54-B8-B54-2B6-2B23-B-B2-B-B26-4B794-B6-B23-2B6-2B2(22-B8-B)54-2B6-2B23-B-B2-B-B26-4B857-3(B8-B22-)2B6-2B23-B-B2-B-B26-4B889-2(B8-B22-)B8-B23-3B2-3B26-4B46-
