model
size = 27 27 24, scale = 0.05, origin = -y
material 
  colors = A:#639 B:#222 C:#555 D:#111 E:#5A2C87 F:#777 G:#7138AB H:#BBB I:#888 J:#444 K:#DDD L:#AAA M:#CC3
voxels
--------------------------- --------------------------- ------------------A-------- --------------------A------ --------------------------- ------------------A-AA----- ------------------A-------- --------------------------- --------------------------- --------------------------- --------------------------- --------------------------- --------------------------- --------------------------- --------------------------- --------------------------- --------------------------- --------------------------- --------------------------- --------------------------- --------------------------- --------------------------- --------------------------- --------------------------- --------------------------- --------------------------- --------------------------- 
--------------------------- --------------------------- -------------A--A-AAA------ -----------E-A--AAAAAAA---- ----A-A------A--E-AAAAA---- ------A----AAAA-GAAAAAAA--- -----------A-A--AAAAGAEA--- --------------------------- --------------------------- --------------------------- --------------------------- --------------------------- --------------------------- --------------------------- --------------------------- --------------------------- --------------------------- --------------------------- --------------------------- --------------------------- --------------------------- --------------------------- --------------------------- --------------------------- --------------------------- --------------------------- --------------------------- 
-------EA--------AAA------- -------AA-AA----AAAA------- ---------AAA---AAAAA------- --AAAAAA---E-A-AAAAAA------ --GAAAAAAAAEEA-AAAAAA------ --A-AAAAGAAAAAA-AAAAA-A---- ---------AAAAAA-AAAAAAA-A-- --------------AAAAAAAA-AA-- -----------AA---AA---A----- --------------------------- --------------------------- --------------------------- --------------------------- --------------------------- --------------------------- --------------------------- --------------------------- --------------------------- --------------------------- --------------------------- --------------------------- --------------------------- --------------------------- --------------------------- --------------------------- --------------------------- --------------------------- 
------AAAA-AA--AAAAAA------ ----AAAAAAAAGAAAAAAAA------ --AAAA-EAAAAAAAAAAAAA------ --AAAAAAAAAAAAAAAAA-------- --AAAAAAAAAAAAAAAAA-------- --AAAAAAAAAAAAAAAAA-------- --AGA--EAAAAAAAAAAA-A---AA- ------------AAAAAAAAAAAAA-- ---------AGAAAAAAA-AEA-A--- --------------------------- --------------------------- --------------------------- --------------------------- --------------------------- --------------------------- --------------------------- --------------------------- --------------------------- --------------------------- --------------------------- --------------------------- --------------------------- --------------------------- --------------------------- --------------------------- --------------------------- --------------------------- 
------AA--A----AAAGAAA----- A-A--AAAAAAAAAAAAAAAAA----- AAAAAAAAAAAAAAAAAAAAAA--A-- -AAAAAAAAAAAAAAAA--AAA--A-- -AAAAAAAAAAAAAAAA--AAA--A-- -AAAAAAAAAAAAAAAA--AAA--A-- --AAAAAAAAAAAAAAA--AAA--A-- -----AAAAAAAAAAAAAAAAAAAA-- -------EAAAAEAAAAAAAAAAE--- --------------------------- --------------------------- --------------------------- --------------------------- --------------------------- --------------------------- --------------------------- --------------------------- --------------------------- --------------------------- --------------------------- --------------------------- --------------------------- --------------------------- --------------------------- --------------------------- --------------------------- --------------------------- 
-----AAA-A--AAAAA-AAAAAA--- --AAAAAAAAAAAAAAAAAAAAAA--- -AAAAAAAAAAAAAAAAAAAAAAA--- -AAAAAAAAAAAAAAAAAAAAAAAA-- -AAAAAAAAAAAAAAAAAAAAAAAAA- AAAAAAAAAAAAAAAAAAAAAAAAAA- --AAAAAAAAAAAAAAAAAAAAAAA-- ---AAAAAAAAAAAAAAAAAAAAAA-- -----AAAAA-AAA---AAAAGAAA-- --------------------------- --------------------------- --------------------------- --------------------------- --------------------------- --------------------------- --------------------------- --------------------------- --------------------------- --------------------------- --------------------------- --------------------------- --------------------------- --------H--------H--------- --------------------------- --------------------------- --------------------------- --------------------------- 
-A-AAAA---AAAAAAA--AAAAA--- --AAAAAAAAAAAAAAAAAAAAAAA-- --AAAAAAAAAAAAAAAAAAAAA---- --AAAAAAAAAAAAAAAAAAAAAA--- --AAAAAAAAAAAAAAAAAAAAAA--- --AAAAAAAAAAAAAAAAAAAAAA-A- -AAAAAAAAAAAAAAAAAAAAAAAE-- ---AAAAAAAAAAAA-AAAAAAAAA-- ---AAAA-----AA-----AAAAA--- --------------------------- --------------------------- --------------------------- --------------------------- --------------------------- --------------------------- --------------------------- --------------------------- --------------------------- --------------------------- --------------------------- --------------------------- ---------H------H---------- --------------------------- --------------------------- --------------------------- --------------------------- --------------------------- 
----AA---AAA-AAAAG-AGA----- ---AAAAAAAAAAAAAAAAAAAA---- ---AAAAAAAAAAAAAAAAAAAAAA-- -AAAAAAAAAAAAAAAAAAAAAAA--- -EAAAAAAAAAAAAAAAAAAAAAA--- -AAAAAAAAAAAAAA-AAAAAAAAAAA -AAAAAAAAAAAAA---AAAAAAAAA- --AAAAAAAH--AAA-HHAAAAAA--- --AAGAA-CC------CC-AGAA---- --------CC------CC--------- --------------------------- --------------------------- --------------------------- --------------------------- --------------------------- --------------------------- --------------------------- --------------------------- ------------BB------------- ----------BBLLBB----------- ---------BHBBBBHB---------- ---------BBDBBDBB---------- ---------BBMBBMBB---------- ---------BBBBBBBB---------- -----------BBBB------------ --------------------------- --------------------------- 
--AAAA-AAAAE-AAAAAAAAA----- --AAAAAAAAAAAAAAAAAAAA-AA-- --AAAAAAAAAAAAAAAAAAAAAAA-- -AAAAAAAAAAAAAAAAAAAAAAAA-- -AAAAAAAAAAAAAAAAAAAAAAAAA- -AAAAAAAAAAAAAAAAAAAAAAAAA- -AAAAAAAA-AAAAAA-AAAAAAAAA- --EAAAAAAC--AAA-CC-AAAAA--- ---AAA-AAC---A--CCAAAAAA--- --------AC------CC--------- --------CC------CC--------- --------CC------CC--------- --------JJ------JJ--------- --------DB------BD--------- --------DD------DD--------- --------DD------DD--------- --------DD------DD--------- --------------------------- -----------BBBB------------ ----------BBBBBB----------- ---------BBBBBBBB---------- ---------BBBBBBBB---------- ---------BBBBBBBB---------- ---------BBBBBBBB---------- ----------BBBBBB----------- -----------BBBB------------ --------------------------- 
-AAAAAAAAAAA-AAGAAA-AA----- -AAAAAAAAAAAAAAAAAAAAA-A--- -AAAAAAAAAAAAAAAAAAAAA-AA-- -AAAAAAAAAAAAAAAAAAAAAAAA-- -AAAAAAAAAAAAAAAAAAAAAAAA-- -AAAAAAAAAAAAAAA-AAAAAAAA-- -AAAAAAAA--AAAA---AAAAAAA-- --AAAAAACC--AAA-CC-AAAAA--- --AAAAAACC------CC-AAAA---- ------AACC------CC--------- --------DC------CC--------- --------DC------CC--------- --------DJ------JD--------- --------BB------BB--------- --------DD------DD--------- --------DD------DD--------- --------DD------DD--------- --------DDDDDDDDDD--------- --------BDDDDDDDDB--------- ---------BBBBBBBB---------- ---------BBBBBBBB---------- ---------BBBBBBBB---------- ---------BBBBBBBB---------- ---------BBBBBBBB---------- ----------BBBBBB----------- -----------BBBB------------ --------------------------- 
--AEEAAAAEA---AAAA-AAAA---- AAAAAAAAAAAA-AAAAAAAAAA---- AAAAAAAAAAAAAAAAAAAAAAAA--- AAAAAAAAAAAAAAAAAAAAAAAA--- AAAAAAAAAAAAAAAAAAAAAAAAA-- GAAAAAAA--AAAAAAAAAAAAAAAA- -AAAAAAAA---A----AAAAAAAAA- --AAAAAAAH--A---HAAAAAAA--- ---AAAAAA---------AAAAAA--- --------------------------- --------------------------- --------------------------- --------------------------- --------BBBBIIBBBB--------- --------BBBBBBBBBB--------- --------BBBBBBBBBB--------- --------BBBBBBBBBB--------- --------FFFFFFFFFF--------- --------BDDDDDDDDB--------- ---------BBBBBBBB---------- ---------BBBBBBBB---------- ---------BBBBBBBB---------- ---------BBBBBBBB---------- ---------CBBBBBBC---------- ---------CBBBBBBC---------- ---------CKBBBBKC---------- ---------CK----KC---------- 
---AAAAAAA-G--AAAAAAAAA---- ---AAAAAAAAAAAAAAAAAAAAA--- -AAAAAAAAAAAAAAAAAAAAAAAA-- -AAAAAAAAAAAAAAAAAAAAAAAA-- -AAAAAAAAAAAAAAAAAAAAAAAAA- -AAAAAAAA-AAAAAAAAAAAAAAAA- -AAAAAAAAA------AAAAAAAAA-- --AAAAAAAH------HHAAAAAA--- --AAAAAAAB------BB-AAAG---- --------BB------BB--------- --------D--------D--------- --------DBBBIIBBBD--------- --------BBBBIIBBBB--------- --------BBBBBBBBBB--------- --------BBBBBBBBBB--------- --------DBBBBBBBBD--------- --------BBBBBBBBBB--------- --------FFFFFFFFFF--------- ---------DDDDDDDD---------- ---------BBBBBBBB---------- ---------BBBBBBBB---------- ---------BBBBBBBB---------- ----------BBBBBB----------- ----------BBBBBB----------- ----------BB--BB----------- ----------CC--CC----------- ----------CC--CC----------- 
-A-AAAAAAA------A-AAA--AA-- AAAAAAAAAAAAAAAAAAAAAAAAA-- GAAAAAAAAAAAAAAAAAAAAAAA--- AAAAAAAAAAAAAAAAAAAAAAAAAA- -AAAAAAAAAAAAAAAAAAAAAAAAAA -AAAAAAAAAAAAAAAAAAAAAAAAA- -AAAAAAAAA-------AAAAAAAAA- --AAAAAAAA------HH--AAAAA-- --AAAEAAAB--BB--BB--A------ --------BBBBIIBBBB--------- --------BBBBIIBBBB--------- --------BBBBBBBBBB--------- --------CCCCCCCCCC--------- --------DBCCCCCCBD--------- --------BBBBBBBBBB--------- --------BBBBBBBBBB--------- --------BBBBBBBBBB--------- ---------FFFFFFFF---------- ---------DDDDDDDD---------- ---------BBBBBBBB---------- ----------BBBBBB----------- ----------BBBBBB----------- ----------BBBBBB----------- -----------BBBB------------ --------------------------- --------------------------- --------------------------- 
-A-A--AAAA--A-A---AAAAAA--- -AAAAAAAAAAAAAAAAAAAAAAA--- -AAAAAAAAAAAAAAAAAAAAAAA--- -AAAAAAAAAAAAAAAAAAAAAAAAA- -EAAAAAAAAAAAAAAAAAAAAAAAA- -AAAAAAAAA-AAAAAAAAAAAAAAA- --AAAAAAAA--------AAAAAAAA- --EAAAAAAABBBBBBHHAAAAAAA-- ---A-AAAABBBBBBBBB---AAE--- --------BBBBBBBBBB--------- --------BBBBBBBBBB--------- --------BBBBBBBBBB--------- --------CCCCCCCCCC--------- --------BBCCCCCCBB--------- --------DBBBBBBBBD--------- --------BBBBBBBBBB--------- --------BBBBBBBBBB--------- ---------FFFFFFFF---------- ----------DDDDDD----------- ----------BBBBBB----------- --------------------------- --------------------------- --------------------------- --------------------------- --------------------------- --------------------------- --------------------------- 
---AAA-AA-A-A--AA-AAG--A--- -AAAAAAAAAAAAAAAAAAAA--AA-- -AAAAAAAAAAAAAAAAAAAA--AA-A -AAAAAAAAAAAAAAAAAAAA--AAAA -AAAAAAAAAAAAAAAAAAAA--AAAA -AAAAAAAAAAAAAAAAAAAA--AAAA --AAAAAAAA--------AAA--AA-- --EAAAAAABBBBBBBBB-AA--AA-- ---AA-A-BBBBBBBBBB--EAAA--- --------BBBBBBBBBB--------- --------DBBBBBBBBD--------- --------BBBBBBBBBB--------- --------CCCCCCCCCC--------- --------BBCCCCCCBB--------- --------BBBBBBBBBB--------- ---------BBBBBBBB---------- ----------BBBBBB----------- -----------FFFF------------ -----------DDDD------------ --------------------------- --------------------------- --------------------------- --------------------------- --------------------------- --------------------------- --------------------------- --------------------------- 
---A-AAAAAAAAE-AA-AAAAAA--- -AAAAAAAAAAAAAAAAAAAAAAAA-- -AAAAAAAAAAAAAAAAAAAAAAAA-- -AAAAAAAAAAAAAAAAAAAAAAAAA- -EAAAAAAAAAAAAAAAAAAAAAAAA- -AAAAAAAAAAAAAAAAAAAAAAAAA- -AAAAAAAA---A-----AAAAAAAA- --AAAAAABBBBBBBBBB-AAAAAA-- --AAAAAABBBBBBBBBB--AAAAA-- --------BBBBBBBBBB--------- --------BBBBBBBBBB--------- --------BBBBBBBBBB--------- --------CCCCCCCCCC--------- --------BBCCCCCCBB--------- ---------BBBBBBBB---------- ----------BBBBBB----------- --------------------------- --------------------------- --------------------------- --------------------------- --------------------------- --------------------------- --------------------------- --------------------------- --------------------------- --------------------------- --------------------------- 
---A-AAAAAAAAAAAA-AAAAA---- AA-AAAAAAAAAAAAAAAAAAAAA--- -EAAAAAAAAAAAAAAAAAAAAAAA-- -AAAAAAAAAAAAAAAAAAAA-AA--- -AAAAAAAAAAAAAAAAAAAA-AAAA- AAAAAAAAAAAAAAAAAAAAA-AAAA- -AAAAAAAAA--AAA---AAA-AAAA- --AAAAAAABBBBBBBBB-AA-AA--- --AAAAAAABBBBBBBBB-AAAGA--- --------BBBBBBBBBB--------- --------BBBBBBBBBB--------- --------BBBBBBBBBB--------- --------CCCCCCCCCC--------- ---------BBBBBBBB---------- --------------------------- --------------------------- --------------------------- --------------------------- --------------------------- --------------------------- --------------------------- --------------------------- --------------------------- --------------------------- --------------------------- --------------------------- --------------------------- 
A-AA-AAEAA---AAAA-AAAAA---- AEAAAAAAAAAAAAAAAAAAAAAAA-- AAAAAAAAAAAAAAAAAAAAAAAAA-- AAAAAAAAAAAAAAAAAAAAA-AAA-- GAAAAAAAAAAAAAAAAAAAA-AAAA- GAAAAAAAAAAAAAAAAAAAA-AAAA- AAAAAAAAAA-A-AA--AAAA-AAAA- -AAAAAAABBBBBBBBBB-AA-AAA-- ---AAAA-BBBBBBBBBB-AAAAE--- --------BBBBBBBBBB--------- --------BBBBBBBBBB--------- ---------BBBBBBBB---------- ---------CCCCCCCC---------- --------------------------- --------------------------- --------------------------- --------------------------- --------------------------- --------------------------- --------------------------- --------------------------- --------------------------- --------------------------- --------------------------- --------------------------- --------------------------- --------------------------- 
--AA-A----A-AAAAA--AAA----- --AAA-AAAAAAAAAAAAAAAA-A--- -AAAAAAAAAAAAAAAAAAAAA-AA-- -AAAAAAAAAAAAAAAAAAAAAAAA-- -AAAAAAAAAAAAAAAAAAAAAAAAA- -AAAAAAAAAAAAAAAAAAAAAAAAA- -AAAAAAAAA---AA--AAAAAAAA-- --AAAAAA-BBBBBBBBAAAAAAA--- --AA-AAA-BBBBBBBB---AAAA--- ---------BBBBBBBB---------- --------------------------- --------------------------- --------------------------- --------------------------- --------------------------- --------------------------- --------------------------- --------------------------- --------------------------- --------------------------- --------------------------- --------------------------- --------------------------- --------------------------- --------------------------- --------------------------- --------------------------- 
--AA---AAAAAAGAA-A--GA----- AAAAA-AAAAAAAAAA-A--AA----- AAAAAAAAAAAAAAAAA----A----- AAAAAAAAAAAAAAAAAAAAAAAAA-- AAAAAAAAAAAAAAAAAAAAAAAAAAA -AAAAAAAAAAAAAAAAAAAAAAAAA- -AAAAAAA-----AAA--AAAAAAAA- -GAAAAAA--BBBBBB---A-AA---- ---AEA----BBBBBB---A-EA---- ------------BB------------- --------------------------- --------------------------- --------------------------- --------------------------- --------------------------- --------------------------- --------------------------- --------------------------- --------------------------- --------------------------- --------------------------- --------------------------- --------------------------- --------------------------- --------------------------- --------------------------- --------------------------- 
--AAAEAAAAAAAAAAAAGAAAA---- ---AAAAAAAAAAAAAAAAA-AA---- --AAAAAAAAAAAEAAA-A-A------ -GAAAAAAAAA-AAAAAAAAA-AAA-- -AAAAAAAAAA-A--AAAAAAAAA-A- -AAAAAAAAAA-A--AGAAAAAAAAA- -AEAAAAA--A-------AAAAAAA-- ----AAAA----BB--------AAA-- ------------BB------------- ------------BB------------- ------------BB------------- --------------------------- --------------------------- --------------------------- --------------------------- --------------------------- --------------------------- --------------------------- --------------------------- --------------------------- --------------------------- --------------------------- --------------------------- --------------------------- --------------------------- --------------------------- --------------------------- 
----AAAA-EA-AEAAAA-AA------ ---AAAAAAAAAA--AAA--AAA---- -AAAAAAA------A--AAA------- -AAAAAAA------AAAAAAAAA---- -AAAAAEG---------A-AAAAAA-- -EAAAAAA---------AAEAAAA--- -AAAAA----------------EAA-- ----AE----------------A---- --------------------------- ------------BB------------- -----------BBB------------- -----------BB-------------- ----------BB--------------- ---------BBB--------------- ---------BB---------------- --------------------------- --------------------------- --------------------------- --------------------------- --------------------------- --------------------------- --------------------------- --------------------------- --------------------------- --------------------------- --------------------------- --------------------------- 
-----A--------------------- ---AAAEAAA----AA--AA-A----- ---AAA--------------------- ---AAA--------------------- ---AAA-------------A------- --AA----------------------- --------------------------- --------------------------- --------------------------- --------------------------- -----------BB-------------- ----------BBB-------------- ----------BB--------------- ---------BBB--------------- ---------BB---------------- --------BB----------------- -------BBB----------------- -------BB------------------ -------BB------------------ -------BB------------------ -------BB------------------ ------BB------------------- ------BB------------------- --------------------------- --------------------------- --------------------------- --------------------------- 
--------------------------- --------------------------- --------------------------- --------------------------- --------------------------- --------------------------- --------------------------- --------------------------- --------------------------- --------------------------- --------------------------- --------------------------- --------------------------- --------------------------- ---------B----------------- --------BB----------------- --------BB----------------- -------BB------------------ -------BB------------------ -------BB------------------ ------BBB------------------ ------BB------------------- ------BB------------------- --------------------------- --------------------------- --------------------------- --------------------------- 
