model
size = 30 32 26, scale = 0.05, origin = -y
material 
  colors = A:#25B6BE B:#717171 C:#FFF D:#000 E:#22A6B0 F:#EDEDED G:#1F97A0 H:#CFCFCF I:#65B8BE J:#0B555B K:#FFBA6C
voxels
520-10A20-4A2K4A20-A2CA2KA2CA23-4K862-2(2A8B2A18-)AC8B2A19-3C4K3C2(20-C2D4C2DC)21-2C4-2C768-2(2A2B8-2B2A14-)2A2B8-2B2A16-2A8B2A18-CA8BAC18-2C2D3CA2D2C19-4C2A4C20-A2C4A2CA736-2(A2B12-2BA12-)A2B12-2BA13-2(2A2B8-2B2A14-)4A8B4A15-3A8B3A18-G8CGA19-10A23-4AGA676-FB16-BF2(10-AB16-BA)11-2(2AB12-B2A12-)3A2B8-2B3A12-3A2B8-2B3A13-5A6B4AE15-4A2B2-2B4A17-12A20-E2AE4A23-3AI2A556-F20-J8-H20-H8-AB18-BF2(8-AB18-BA)9-2(2A16-2A10-)3A14-3A11-2A14-2A12-4A10-4A13-3A10-3A15-4A6-4A17-12A19-9AG524-J20-F5(8-A20-A)9-2(A18-A10-)2A16-2A11-A16-A2(12-2A14-2A)13-3A10-3A15-4A6-4A17-12A21-6A435-F22-J6-H22-H7-A20-A8-A20-A7-3(A22-A6-)A22-A7-2(A20-A8-)2A18-2A9-A18-A11-2(2A14-2A12-)E2A12-2AE13-3A10-3A15-4A6-4A18-10A22-I3AGA375-J22-F8(6-A22-A)7-2(A20-A8-)2A18-2A9-A18-A10-2A16-2A11-A16-A12-2A14-2A2(12-3A)13-4A8-4A16-3A6-3A20-8A343-F24-J5-2(A22-A6-)2A20-2A7-A20-A7-A22-A6-A22-A5-2(A24-A4-)A24-A5-E22-A6-A22-A7-A20-A8-A20-A9-2A16-2A10-GA16-2A11-2A14-2A2(12-3A)13-3A10-3A16-2A8-AG19-AI6A2I41-D26-D-3D24-3D-D26-D152-J26-F3-H24-H3(4-A24-A)4-2A22-2A5-2(A22-A6-)A22-A5-A24-E2(4-A24-A)5-A22-A6-A22-A7-2(A20-A8-)2A18-2A9-A18-A10-2A16-2A11-2A14-2A2(12-3A)14-2A10-2A17-4A4-4A22-4A13-3D2(24-6D)24-3D-H26-H62-H26-H2-F26-J3-5(A24-A4-)2A22-2A5-A22-A6-A22-A5-2A22-2A3(4-A24-A)5-2(A22-A6-)2A20-2A7-A20-A8-2A18-2A8-2A18-AE9-2A16-2A10-2AG14-3A11-3A12-3A14-2A10-2A17-3A6-3A21-6A13-D26-D-3D24-3D-D26-D32-H26-H2-H26-H62-F26-J3-4(A24-A4-)4(2A22-2A4-)2(A24-A4-)A24-A5-A22-A6-E22-A6-2A20-AG7-A20-A8-GA18-2A8-2A18-2A8-3A16-3A9-3A14-3A11-3A12-3A14-2A10-2A17-3A6-3A21-6A283-H26-H3-3(A24-A4-)2A22-2A4-A24-A5-A22-A5-2A22-2A3(4-A24-A)5-2(A22-A6-)2A20-2A7-A20-A2(8-2A18-2A)8-3A16-3A9-3A14-3A11-3A12-3A14-2A10-2A17-3A6-3A21-2AI3A314-J24-F2(4-A24-A)4-2A22-2A4-A24-A5-A22-A6-A22-A5-2(A24-A4-)A24-A5-2(A22-A6-)2A20-2A7-A20-A2(8-2A18-2A)9-2A16-2A10-3A14-3A10-I3A12-3A11-JI-2A10-2A12-JI3-3A6-E2A13-I7-6A344-F24-J4-H24-H2(4-A24-A)5-A22-A6-A22-A5-2(A24-A4-)A24-A5-A22-A6-A22-A7-2(A20-A8-)EA18-2A9-A18-A10-2A16-2A11-2A14-2A12-3A12-2A2I13-2A10-2AIJI14-4A4-4A2-IJ18-4A7-I397-J24-F4-A24-A5-A22-A6-A22-A5-2(A24-A4-)A24-A5-A22-A6-A22-A7-A20-A8-A20-A9-2A16-2A10-2A16-2A11-2A14-2A12-2AG12-3A13-3A10-G2A16-2A8-AG19-10A462-F24-J5-4(A22-A6-)G22-G7-2(A20-A8-)2A18-2A9-A18-A10-2A16-2A11-A16-A12-2A14-2A2(12-3A)13-4A8-4A16-3A6-3A20-7AI494-H22-H4(6-A22-A)7-A20-A8-A20-E8-2A18-2A9-A18-A11-2(2A14-2A12-)3A12-3A13-3A10-2AE15-4A6-4A18-10A22-AG4A525-J22-F6-2A20-2A7-A20-A8-A20-A9-2(A18-A10-)2A16-2A11-A16-A2(12-2A14-2A)13-E2A10-3A15-4A6-4A17-12A21-E5A585-FA20-2A7-A20-A8-A20-A9-2(2A16-2A10-)3A14-3A11-2A14-2A12-4A10-3AG13-3A10-3A15-4A6-4A17-2(3AG)4A19-8AGA615-2(A18-A10-)A18-A11-2(2A14-2A12-)3(3A12-)3A13-5A6-5A15-4A6-4A17-E11A20-5AE2A23-6A618-F16-F12-A16-G12-A16-E13-2A12-AE14-EA12-2A14-4A8-4A15-3A8-3A18-10A20-10A21-2AE5A678-2A12-2A14-AG12-2A14-2A12-2A16-2(2A8-2A18-)11AE18-9AG2A21-6A741-FA8-AF2(18-2A8-2A)20-2(8A22-)8A23-2AE3A773-F6AF22-8A22-5AE2A23-6A342-
