model
size = 32 32 30, scale = 0.05, origin = -y
material 
  colors = A:#FF0 B:#EEE C:#555 D:#444 E:#111 F:#E00
voxels
97-E7-E1015-E7-E982-3A3-C-3A21-AEA-C3-ACA21-3A5-3A885-ACA5BACA21-11B21-4B-BCB2CD21-4BDB-B2CD21-4B2(-B)2CD21-11B853-2(7B3CD21-)4BA2B3CD21-6BA3CD21-4BABA3CD21-7BC3B853-5(7B3CD21-)11B853-7B3CD21-10AD21-2BA6BAD21-2(BA)5BAD21-A3BA2B3AD21-11B25-3D30-12(E31-)EF30-E2F29-EF17331-A-A29-A-A25-8A24-9A2(25-2A3-3A24-2A3-2A25-2(6A26-)2A3-2A25-2A3-3A22-9A23-8A28-A-A29-A-A665-2A4-FA24-2A5-2A)25-2A3-3A24-2A3-2A25-2(6A26-)2A3-2A25-2A3-3A22-9A23-8A28-A-A29-A-A665-2A2FE2FA24-2A5-2A25-2A3-3A24-2A3-2A25-2(6A26-)2(2A3-2A25-2A3-3A22-9A23-8A28-A-A29-A-A665-2AF4-A24-3A4-2A25-2A3-3A24-2A3-2A25-2A3-A26-6A26-)2A3-2A25-2A3-3A22-9A23-8A28-A-A29-A-A605-A-A29-A-A25-8A24-9A25-2A3-3A24-2A3-2A25-2(6A26-)2A3-2A25-2A3-3A22-9A23-8A28-A-A29-A-A3-
