model
size = 22 20 25, scale = 0.05, origin = -y
material 
  colors = A:#FFE2C5 B:#563F2E C:#EEE D:#FFFFFB E:#00AA90 F:#F8B09C G:#111
voxels
---------------------- ---------------------- ---------------------- ---------------------- ---------------------- ----------BB---------- --------BBAABB-------- -------BB----BB------- ------BB------BB------ -----BB--------BB----- -----BB--------BB----- ------BB------BB------ -------BB----BB------- --------BBAABB-------- ----------BB---------- ---------------------- ---------------------- ---------------------- ---------------------- ---------------------- 
---------------------- ---------------------- ---------------------- ---------------------- ---------------------- --------BBBBBB-------- -------BBAAAABB------- ------BB------BB------ -----BB--------BB----- ----BB----------BB---- ----BB----------BB---- -----BB--------BB----- ------BB------BB------ -------BBAAAABB------- --------BBBBBB-------- ---------------------- ---------------------- ---------------------- ---------------------- ---------------------- 
---------------------- ---------------------- ---------------------- ---------------------- ---------BBBB--------- -------BBBAABBB------- ------BAAA--AAAB------ -----BB--------BB----- ----BB----------BB---- ----B------------B---- ----B------------B---- ----BB----------BB---- -----BB--------BB----- ------BAAA--AAAB------ -------BBBAABBB------- ---------BBBB--------- ---------------------- ---------------------- ---------------------- ---------------------- 
---------------------- ---------------------- ---------------------- ----------BB---------- --------BBBBBB-------- ------BBBB--BBBB------ -----B----------B----- ----BB----------BB---- ----B------------B---- ---B--------------B--- ---B--------------B--- ----B------------B---- ----BB----------BB---- -----B----------B----- ------BBBB--BBBB------ --------BBBBBB-------- ----------BB---------- ---------------------- ---------------------- ---------------------- 
---------------------- ---------------------- ---------------------- ---------BBBB--------- ------BBBBAABBBB------ -----BBBB----BBBB----- ----BBB--------BBB---- ----BB----------BB---- ---B--------------B--- ---B--------------B--- ---B--------------B--- ---B--------------B--- ----BB----------BB---- ----BBB--------BBB---- -----BBBB----BBBB----- ------BBBBAABBBB------ ---------BBBB--------- ---------------------- ---------------------- ---------------------- 
---------------------- ---------------------- ----------BB---------- -------BBBAABBB------- -----BBBBA--ABBBB----- ----BBBB------BBBB---- ----BB----------BB---- ---B--------------B--- ---B--------------B--- --B----------------B-- --B----------------B-- ---B--------------B--- ---B--------------B--- ----BB----------BB---- ----BBBB------BBBB---- -----BBBBA--ABBBB----- -------BBBAABBB------- ----------BB---------- ---------------------- ---------------------- 
---------------------- ---------------------- --------BFFFFB-------- ------BBAA--AABB------ -----BBA------ABB----- ----BBA--------ABB---- ---BBB----------BBB--- ---B--------------B--- --B----------------B-- --B----------------B-- --B----------------B-- --B----------------B-- ---B--------------B--- ---BBB----------BBB--- ----BBA--------ABB---- -----BBA------ABB----- ------BBAA--AABB------ --------BFFFFB-------- ---------------------- ---------------------- 
---------------------- ---------------------- -------BF----FB------- -----BBBA----ABBB----- -----BAA------AAB----- ----BB----------BB---- ---BB------------BB--- --BB--------------BB-- --B----------------B-- --B----------------B-- --B----------------B-- --B----------------B-- --BB--------------BB-- ---BB------------BB--- ----BB----------BB---- -----BAA------AAB----- -----BBBA----ABBB----- -------BF----FB------- ---------------------- ---------------------- 
---------------------- --------BBBBBB-------- ------BBA----ABB------ -----BAA------AAB----- -----BA--------AB----- ----BB----------BB---- ---BB------------BB--- ---BB------------BB--- --BB--------------BB-- --B----------------B-- --B----------------B-- --BB--------------BB-- ---BB------------BB--- ---BB------------BB--- ----BB----------BB---- -----BA--------AB----- -----BAA------AAB----- ------BBA----ABB------ --------BBBBBB-------- ---------------------- 
---------AAAA--------- -------BBA--ABB------- ------BAA----AAB------ -----BAA------AAB----- -----BA--------AB----- ----BB----------BB---- ----B------------B---- ---BB------------BB--- ---B--------------B--- ---B--------------B--- ---B--------------B--- ---B--------------B--- ---BB------------BB--- ----B------------B---- ----BB----------BB---- -----BA--------AB----- -----BAA------AAB----- ------BAA----AAB------ -------BBA--ABB------- ---------AAAA--------- 
--------AAAAAA-------- -------AAA--AAA------- -------AA----AA------- ------AA------AA------ -----AA--------AA----- -----AA--------AA----- ----BA----------AB---- ----B------------B---- ---B--------------B--- ---B--------------B--- ---B--------------B--- ---B--------------B--- ----B------------B---- ----BA----------AB---- -----AA--------AA----- -----AA--------AA----- ------AA------AA------ -------AA----AA------- -------AAA--AAA------- --------AAAAAA-------- 
---------AAAA--------- --------AAAAAA-------- -------AA----AA------- ------AA------AA------ -----AA--------AA----- ----AAA--------AAA---- ----AA----------AA---- ---BA------------AB--- ---B--------------B--- ---B--------------B--- ---B--------------B--- ---B--------------B--- ---BA------------AB--- ----AA----------AA---- ----AAA--------AAA---- -----AA--------AA----- ------AA------AA------ -------AA----AA------- --------AAAAAA-------- ---------AAAA--------- 
----------AA---------- ---------AAAA--------- --------AA--AA-------- -------AA----AA------- -----AAA------AAA----- ----AA----------AA---- ---BAA----------AAB--- ---BA------------AB--- --BB--------------BB-- --BB--------------BB-- --BB--------------BB-- --BB--------------BB-- ---BA------------AB--- ---BAA----------AAB--- ----AA----------AA---- -----AAA------AAA----- -------AA----AA------- --------AA--AA-------- ---------AAAA--------- ----------AA---------- 
---------------------- ----------AA---------- ---------AAAA--------- --------AA--AA-------- ----AAAA------AAAA---- ----AAA--------AAA---- ---AAA----------AAA--- --AA--------------AA-- --A----------------A-- --A----------------A-- --A----------------A-- --A----------------A-- --AA--------------AA-- ---AAA----------AAA--- ----AAA--------AAA---- ----AAAA------AAAA---- --------AA--AA-------- ---------AAAA--------- ----------AA---------- ---------------------- 
---------------------- ---------------------- ----------AA---------- ---------AAAA--------- ----AAAAAA--AAAAAA---- ---AAAAA------AAAAA--- --AAAA----------AAAA-- --A----------------A-- --A----------------A-- -A------------------A- -A------------------A- --A----------------A-- --A----------------A-- --AAAA----------AAAA-- ---AAAAA------AAAAA--- ----AAAAAA--AAAAAA---- ---------AAAA--------- ----------AA---------- ---------------------- ---------------------- 
---------------------- ---------------------- ---------------------- ----------AA---------- ---AAAAAAAAAAAAAAAA--- ---AAAAAA----AAAAAA--- --A--AA--------AA--A-- --A----------------A-- -A------------------A- -A------------------A- -A------------------A- -A------------------A- --A----------------A-- --A--AA--------AA--A-- ---AAAAAA----AAAAAA--- ---AAAAAAAAAAAAAAAA--- ----------AA---------- ---------------------- ---------------------- ---------------------- 
---------------------- ---------------------- ---------------------- ---------------------- ---AA---AAAAA-DDD-A--- --A-ADDDAAAAAACCCA-A-- --A-ACCCAAAAAAACCA-A-- -AA-ACCAA-----ADDA-AA- -A--ADDA------------A- AA------------------AA AA------------------AA -A--ADDA------------A- -AA-ACCAA-----ADDA-AA- --A-ACCCAAAAAAACCA-A-- --A-ADDDAAAAAACCCA-A-- ---AA---AAAAA-DDD-A--- ---------------------- ---------------------- ---------------------- ---------------------- 
---------------------- ---------------------- ---------------------- ---------------------- ---A-----AAAAD---CA--- --A-C---DAAAACE-EC-A-- --A-CE-ECA--AAEGEC-A-- -A--CEGEA-----DEED--A- -A--DEED------------A- AA------------------AA AA------------------AA -A--DEED------------A- -A--CEGEA-----DEED--A- --A-CE-ECA--AAEGEC-A-- --A-C---DAAAACE-EC-A-- ---A-----AAAAD---CA--- ---------------------- ---------------------- ---------------------- ---------------------- 
---------------------- ---------------------- ---------------------- ----------AA---------- ---A-----AAAAD---CA--- --AAC---DAAAACE-ECAA-- --A-CE-ECAAAAAEGEC-A-- -AA-CEGEA-----DEED-AA- -A--DEED------------A- -A------------------A- -A------------------A- -A--DEED------------A- -AA-CEGEA-----DEED-AA- --A-CE-ECAAAAAEGEC-A-- --AAC---DAAAACE-ECAA-- ---A-----AAAAD---CA--- ----------AA---------- ---------------------- ---------------------- ---------------------- 
---------------------- ---------------------- ---------------------- ---A-----AAAA-----A--- ---AA---A-----DDD-A--- ---AADDDAAAAAACCCAA--- --AAACCCAAAAAAACCAAA-- --A-ACCAA-----ADD--A-- -A---DDA------------A- -A------------------A- -A------------------A- -A---DDA------------A- --A-ACCAA-----ADD--A-- --AAACCCAAAAAAACCAAA-- ---AADDDAAAAAACCCAA--- ---AA---A-----DDD-A--- ---A-----AAAA-----A--- ---------------------- ---------------------- ---------------------- 
---------------------- ---------------------- ---B--------------B--- ----AAAAAAAAAAAAAA---- ---AAA---AAAA---AAA--- ---A-AAAAAAAAAAAA-A--- ---A-AAAAAAAAAAAA-A--- --A----------------A-- --A----------------A-- --A----------------A-- --A----------------A-- --A----------------A-- --A----------------A-- ---A-AAAAAAAAAAAA-A--- ---A-AAAAAAAAAAAA-A--- ---AAA---AAAA---AAA--- ----AAAAAAAAAAAAAA---- ---B--------------B--- ---------------------- ---------------------- 
---------------------- ---------------------- ----BBBBB----BBBBB---- ----AAA-AAAAAA-AAA---- ----A-----AA-----A---- ---A--------------A--- ---A--------------A--- ---A--------------A--- ---A--------------A--- --AA--------------AA-- --AA--------------AA-- ---A--------------A--- ---A--------------A--- ---A--------------A--- ---A--------------A--- ----A-----AA-----A---- ----AAA-AAAAAA-AAA---- ----BBBBB----BBBBB---- ---------------------- ---------------------- 
---------------------- ---------------------- ---------------------- -----AAAAA--AAAAA----- ----AA---AAAA---AA---- ----A------------A---- ----A------------A---- ---A--------------A--- ---A--------------A--- ---A--------------A--- ---A--------------A--- ---A--------------A--- ---A--------------A--- ----A------------A---- ----A------------A---- ----AA---AAAA---AA---- -----AAAAA--AAAAA----- ---------------------- ---------------------- ---------------------- 
---------------------- ---------------------- ---------------------- ---------------------- ------AAAAAAAAAA------ -----AAAAA--AAAAA----- ----AA----------AA---- ----AA----------AA---- ----A------------A---- ----A------------A---- ----A------------A---- ----A------------A---- ----AA----------AA---- ----AA----------AA---- -----AAAAA--AAAAA----- ------AAAAAAAAAA------ ---------------------- ---------------------- ---------------------- ---------------------- 
---------------------- ---------------------- ---------------------- ---------------------- ---------------------- ----------AA---------- ------AAAAAAAAAA------ ------AAAAAAAAAA------ -----AAAAAAAAAAAA----- -----AAAAAAAAAAAA----- -----AAAAAAAAAAAA----- -----AAAAAAAAAAAA----- ------AAAAAAAAAA------ ------AAAAAAAAAA------ ----------AA---------- ---------------------- ---------------------- ---------------------- ---------------------- ---------------------- 
