model
size = 29 3 29, scale = 0.05, origin = -y
material 
  colors = A:#222 B:#555
voxels
-------------BB-------------- ------------BAAB------------- -------------BB-------------- 
---------AAAAAAAAAA---------- ---------AAAAAAAAAA---------- ---------AAAAAAAAAA---------- 
----AAAAAA--------AAAAA------ ---AAAAAAA--------AAAAA------ ----AAAAAA--------AAAAA------ 
-----A----------------AA----- -----A----------------AA----- -----A----------------AA----- 
----AA-----------------AA---- ----AA-----------------AA---- ----AA-----------------AA---- 
---AA-------------------AA--- ---AA-------------------AA--- ---AA-------------------AA--- 
--AA---------------------AA-- --AA---------------------AA-- --AA---------------------AA-- 
--A-----------------------A-- --A-----------------------A-- --A-----------------------A-- 
-AA-----------------------AA- -AA-----------------------AA- -AA-----------------------AA- 
-A-------------------------A- -A-------------------------A- -A-------------------------A- 
-A-------------------------A- -A-------------------------A- -A-------------------------A- 
AA-------------------------AA AA-------------------------AA AA-------------------------AA 
A---------------------------A A---------------------------A A---------------------------A 
A---------------------------A A---------------------------A A---------------------------A 
A---------------------------A A---------------------------A A---------------------------A 
A---------------------------A A---------------------------A A---------------------------A 
A---------------------------A A---------------------------A A---------------------------A 
AA-------------------------AA AA-------------------------AA AA-------------------------AA 
-A-------------------------A- -A-------------------------A- -A-------------------------A- 
-A-------------------------A- -A-------------------------A- -A-------------------------A- 
-AA-----------------------AA- -AA-----------------------AA- -AA-----------------------AA- 
--A-----------------------A-- --A-----------------------A-- --A-----------------------A-- 
--AA---------------------AA-- --AA---------------------AA-- --AA---------------------AA-- 
---AA-------------------AA--- ---AA-------------------AA--- ---AA-------------------AA--- 
----AA-----------------AA---- ----AA-----------------AA---- ----AA-----------------AA---- 
-----AA---------------AA----- -----AA---------------AA----- -----AA---------------AA----- 
------AAA-----------AAA------ ------AAA-----------AAA------ ------AAA-----------AAA------ 
--------AAAA-----AAAA-------- --------AAAA-----AAAA-------- --------AAAA-----AAAA-------- 
-----------AAAAAAA----------- -----------AAAAAAA----------- -----------AAAAAAA----------- 
