model
size = 29 3 29, scale = 0.05, origin = -y
material 
  colors = A:#222 B:#0FF C:#555
voxels
-------------CC-------------- ------------CAAC------------- -------------CC-------------- 
---------AAAAAAAAAA---------- ---------ABAAAAAABA---------- ---------AAAAAAAAAA---------- 
----AAAAAA--------AAAAA------ ---AABABAA--------ABABA------ ----AAAAAA--------AAAAA------ 
-----A----------------AA----- -----B----------------AB----- -----A----------------AA----- 
----AA-----------------AA---- ----AA-----------------AA---- ----AA-----------------AA---- 
---AA-------------------AA--- ---BA-------------------AB--- ---AA-------------------AA--- 
--AA---------------------AA-- --AA---------------------AA-- --AA---------------------AA-- 
--A-----------------------A-- --B-----------------------B-- --A-----------------------A-- 
-AA-----------------------AA- -AA-----------------------AA- -AA-----------------------AA- 
-A-------------------------A- -B-------------------------B- -A-------------------------A- 
-A-------------------------A- -A-------------------------A- -A-------------------------A- 
AA-------------------------AA BA-------------------------AB AA-------------------------AA 
A---------------------------A A---------------------------A A---------------------------A 
A---------------------------A B---------------------------B A---------------------------A 
A---------------------------A A---------------------------A A---------------------------A 
A---------------------------A B---------------------------B A---------------------------A 
A---------------------------A A---------------------------A A---------------------------A 
AA-------------------------AA BA-------------------------AB AA-------------------------AA 
-A-------------------------A- -A-------------------------A- -A-------------------------A- 
-A-------------------------A- -B-------------------------B- -A-------------------------A- 
-AA-----------------------AA- -AA-----------------------AA- -AA-----------------------AA- 
--A-----------------------A-- --B-----------------------B-- --A-----------------------A-- 
--AA---------------------AA-- --AA---------------------AA-- --AA---------------------AA-- 
---AA-------------------AA--- ---BA-------------------AB--- ---AA-------------------AA--- 
----AA-----------------AA---- ----AA-----------------AA---- ----AA-----------------AA---- 
-----AA---------------AA----- -----BA---------------AB----- -----AA---------------AA----- 
------AAA-----------AAA------ ------ABA-----------ABA------ ------AAA-----------AAA------ 
--------AAAA-----AAAA-------- --------ABAA-----AABA-------- --------AAAA-----AAAA-------- 
-----------AAAAAAA----------- -----------BABABAB----------- -----------AAAAAAA----------- 
