model
size = 25 15 32, scale = 0.05, origin = -y
material 
  colors = A:#EEE B:#E00 C:#444
voxels
9-7B18-2A3B2A18-2ABAB2A19-A3BA21-3A268-11B4(14-11A)15-9A17-7A214-5B5-5B2(10-5A5-5A)10-15A11-13A12-13A13-11A15-9A18-5A163-5B9-5B2(6-B4A9-4AB)6-B5A7-5AB6-B6A5-6A2(B6-B-15A-)B9-13A13-11A16-7A137-3B13-3B3(6-4A11-4A)6-5A9-2(5A7-)5A8-B7A-7AB8-B15AB8-B-13A-B11-11A16-7A111-4B13-4B3(4-4A13-4A)5-4A11-4A6-5A9-5A6-2(6A7-)17A9-2(B13AB10-)B-11A-B15-5A87-3B15-3B2(4-3A15-3A)2(4-4A13-4A)4-5A11-5A5-5A9-5A6-7A5-7A7-17A9-15A11-B11AB12-B-9A-B82-4B15-4B3(2-4A15-4A)2-5A13-5A3-4A13-4A4-5A11-5A5-6A7-6A6-19A7-17A9-15A12-B9AB14-B-7A-B58-3B17-3B2(2-3A17-3A)2(2-4A15-4A)2-5A13-5A3-5A11-5A4-6A9-6A2(5-7A)7-17A9-15A11-13A14-B7AB58-4B17-4B4A17-8A17-4A-2(4A15-4A2-)5A13-5A2-6A11-6A3-6A9-6A2(5-7A)6-19A7-17A10-13A13-2AB5AB2A18-3A36-2B2A17-A3B4A17-8A17-9A15-5A-4A15-4A2(2-5A13-5A)3-6A9-6A4-2(8A5-)19A7-17A9-15A12-11A17-B3AB35-2B2A17-A3B4A17-8A17-9A15-10A15-5A-5A13-5A2-6A11-6A3-6A9-6A4-2(8A5-)19A7-17A9-15A12-11A16-2ABAB2A34-2B2A17-A3B4A17-8A17-9A15-10A15-5A-5A13-5A2-6A11-6A3-6A9-6A4-2(8A5-)19A7-17A9-15A12-11A16-3AB3A21-C12-2B3A15-2A3B5A2(15-10A)15-11A13-6A-5A13-5A2-6A11-6A3-7A7-7A4-21A5-19A7-17A9-15A12-11A16-2ABAB2A34-2B3A15-2A3B5A15-10A15-11A13-6A-5A13-5A2-6A11-6A2-7A9-7A3-8A5-8A4-21A5-19A7-17A9-15A12-11A17-B3AB35-2B4A13-3A3B6A13-12A13-6A-5A13-5A2-6A11-6A2-7A9-7A2-8A7-8A3-21A5-19A6-19A7-17A10-13A13-2AB5AB2A18-3A37-B4A13-3A2B3(2-6A11-6A)2-7A9-7A2-8A7-8A3-10A-10A4-21A5-19A7-17A9-15A11-13A14-B7AB59-B6A9-5A2B2(2-7A9-7A)2-8A7-8A2-9A5-9A3-21A4-21A5-19A6-19A7-17A9-15A12-B9AB14-B-7A-B58-B8A5-7A2B3-2(8A5-8A4-)2(21A4-)21A5-19A6-19A7-17A9-15A11-B11AB12-B-9A-B82-B20A2B3-2(21A4-)21A5-2(19A6-)19A7-17A9-2(B13AB10-)B-11A-B15-5A86-11BA11B4-3(19A6-)19A7-17A2(8-B15AB)8-B-13A-B11-11A16-7A110-23B4-4(B17AB6-)B-15A-B6-B-15A-B9-13A13-11A16-7A135-23B6-2(15A10-)15A11-13A12-13A13-11A15-9A18-5A161-23B8-3(11A14-)11A15-9A17-7A211-21B38-3B25-2(B24-)B21-3B213-21B355-19B356-19B357-17B359-15B362-11B366-7B359-
