model
size = 30 14 12, scale = 0.05, origin = -y
material 
  colors = A:#222 B:#EEE C:#2F2F2F D:#A23625 E:#E2943B F:#C7802D G:#282828 H:#777
voxels
----BBBBBBBBBBBBBBBBBBBBB----- ---BBBBBBBBBBBBBBBBBBBBBBB---- ---BBBBBBBBBBBBBBBBBBBBBBB---- ---AAAAA------AAAAAAAAG------- -----------------AAA---------- ------------------------------ ------------------------------ ------------------------------ ------------H----------------- ------------B----------------- ------------B----------------- ------------------------------ ------------------------------ ------------------------------ 
--BBBEFEFEFEFEFEFEFEFEFEBBB--- --BBDDDDDDDDDDDDDDDDDDDDDBBB-- --BBBBBBBBBBBBBBBBBBBBBBBBBB-- ---AAAAAAAAAAAAAAAAAAAAAG----- ---CCCCCC----AAAAAAAA--------- ---AAAAACC-------AAA---------- ---AAAADDCC------------------- ----AA-DD-CCC----------------- ------------C----------------- ------------------------------ ------------B----------------- ------------B----------------- ------------------------------ ------------------------------ 
--BFEFEFEFEFEFEFEFEFEFEFEFBBB- -BBDDDDDDDDDDDDDDDDDDDDDDDDBB- -BBAAAAAAAAAAAAAAAAAAAAAAAAAB- --AAAAAAAAAAAAAAAAAAAAAAAAAG-- --CAAAAAACCCCAAAAAAAACCCG----- --AAAAAAAAGACCCCCAAACG-------- --AAAAAAAAAGAGAGAC------------ --CCAAAAAAAAAAGC-------------- --CCCCCGAGAGAC---------------- ---CCCCCCAGA------------------ -----CCCCCCG------------------ ---------CCGB----------------- ----------AA------------------ ------------------------------ 
-BBEFEFEFEFEFEFEFEFEFEFEFEFEB- BBDCCCCCCCCCCCCCCCCCCCCCCCCDB- BBA------------------------AB- -AA------------------------A-- -CA---------------------ACG--- -AA-----------------AACG------ -AA---------------GCB--------- -C--------------GAB----------- -C---------AAAGAB------------- -----------AAGA--------------- -----------AAAB--------------- -----------AAA---------------- -----------AA----------------- ------------------------------ 
BBEFEFEFEFEFEFEFEFEFEFEFEFEFBB BDCCCCDCCDCDCDDDCDDDCDDCDCDCBB BA--------------------------AB AA-------------------------AG- CC----------------------AGAC-- AA------------------AAAGC----- AA----------------AAAB-------- -C--------------AAAB---------- -C---------AAAAAAB------------ -C---------AAAAB-------------- -----------AAAA--------------- -----------AAAB--------------- -----------AAA---------------- -----------AA----------------- 
BEFEFEFEFEFEFEFEFEFEFEFEFEFEFB BDCDDCDCDDCDCCCDCCCDCDCCDDDCDB BA--------------------------AB DA-------------------------AA- CC----------------------AAGC-- AA------------------AAGAC----- AA----------------AAGB-------- AA--------------AAGB---------- -C---------AAAAAGB------------ -C---------AAAAB-------------- -----------AAAG--------------- -----------BAAB--------------- -----------BAA---------------- -----------AA----------------- 
BFEFEFEFEFEFEFEFEFEFEFEFEFEFEB BDCDDCDDCDCCCDDCCDDCCDCCDCDCDB BA--------------------------AB DA-------------------------AA- CC----------------------AGAC-- AA------------------AAAGC----- AA----------------AAAB-------- AA--------------AAAB---------- -C---------AAAAAAB------------ -C---------AAAAB-------------- -----------AAAA--------------- -----------BAAB--------------- -----------BAA---------------- -----------AA----------------- 
BBFEFEFEFEFEFEFEFEFEFEFEFEFEBB BDCCCCDCCDCDCDDDCDDDCDCCDDDCBB BA--------------------------AB AA-------------------------AG- CC----------------------AAGC-- AA------------------AAGAC----- AA----------------AAGB-------- -C--------------AAGB---------- -C---------AAAAAGB------------ -C---------AAAAB-------------- -----------AAAG--------------- -----------AAAB--------------- -----------AAA---------------- -----------AA----------------- 
-BBFEFEFEFEFEFEFEFEFEFEFEFEFB- BBDCCCCCCCCCCCCCCCCCCCCCCCCDB- BBA------------------------AB- -AA------------------------A-- -CA---------------------ACG--- -AA-----------------AACG------ -AA---------------GAB--------- -C--------------GAB----------- -C---------AAAGAB------------- -----------AAGA--------------- -----------AAAB--------------- -----------AAA---------------- -----------AA----------------- ------------------------------ 
--BEFEFEFEFEFEFEFEFEFEFEFEBBB- -BBDDDDDDDDDDDDDDDDDDDDDDDDBB- -BBAAAAAAAAAAAAAAAAAAAAAAAAAB- --AAAAAAAAAAAAAAAAAAAAAAAAAG-- --CAAAAAACCCCCAAAAAAACCCG----- --AAAAAAAAGACCCCCCAACG-------- --AAAAAAAAAGAGAGAC------------ --CCAAGAAAAAAAGC-------------- --CCCCCGAGAGAC---------------- ---CCCCCCAGAA----------------- -----CCCCCCG------------------ ---------CCGB----------------- ----------AA------------------ ------------------------------ 
--BBBFEFEFEFEFEFEFEFEFEFBBB--- --BBDDDDDDDDDDDDDDDDDDDDDBBB-- --BBBBBBBBBBBBBBBBBBBBBBBBBB-- ---AAAAAAAAAAAAAAAAAAAAAG----- ---CCCCCC----AAAAAAAA--------- ---AAAAACC-------AAA---------- ---AAAADDCC------------------- ----AA-DD-CCC----------------- ------------C----------------- ------------------------------ ------------B----------------- ------------B----------------- ------------------------------ ------------------------------ 
----BBBBBBBBBBBBBBBBBBBBB----- ---BBBBBBBBBBBBBBBBBBBBBBB---- ---BBBBBBBBBBBBBBBBBBBBBBB---- ---AAAAA------AAAAAAAAG------- -----------------AAA---------- ------------------------------ ------------------------------ ------------------------------ ------------H----------------- ------------B----------------- ------------B----------------- ------------------------------ ------------------------------ ------------------------------ 
