model
size = 13 32 20, scale = 0.05, origin = -y
material 
  colors = A:#555 B:#39C C:#111 D:#444 E:#222 F:#777 G:#E00 H:#001 I:#EEE
voxels
16-2H3-2H5-H2-2H-2H381-10E3-2E2B3E2BE3-EB2E2(2BE)3-10E367-E8AF2(3-E8AE)3-10E353-13A-E8AF2(3-E8AE)3-10E340-12A-13A14-2(E8AE3-)10E327-11A2-9A-2A-13A14-2(E8AE3-)10E237-2C10-5(10C3-)10A3-11A2-9A-2A-13A-E8AF3(3-E8AE)5-7A109-3(8C5-)C6-C3(5-8C)30-2A10-A2B6F4(C3-9B)C3-10A3-11A2-9A-2A-13A-E8AF3(3-E8AE)5-7A6-6A7-6D4(7-D3-2D)7-D4-D7-6D6-3(C6BC5-)C6G2(C5-C6B)C5-C2B2(CB)C6-2D-F-D7-2D-F-D5-2A2D-F-D4-A4B2(FB)4(C3-9B)C3-10A3-11A2-9A-2A-13A14-2(E8AE3-)E8AE10-2A11-A7(12-D)6-2(C6BC5-)3(C7BF4-)C6BC5-C6BC6-D2(BG)D7-D2(BG)D5-2A2BGBGD4-AB7-5(C12-)A2(12-2A)10-4A14-2(E8AE3-)E8AE10-2A11-A7(12-D)6-C6BC5-5(C7BF4-)C6BC6-D4BD7-D4BD5-2A5BD4-AB7-5(C12-)A2(12-2A)10-4A14-2(E8AE3-)E8AE10-2A11-A7(12-D)6-C6BC5(F4-C7B)F4-C6BCF5-D4BD7-D4BD5-2A5BD4-AB7-5(C12-)A2(12-2A)10-4A-E8AF3(3-E8AE)4-8A6-6A7-6D7-D3H3(2D7-D3-)2D7-D4-D7-D4AD6-C6BC2(F4-C7B)F4-C6BI5-2(C7BF4-)C6BCF5-D4BD7-D4BD5-2A5BD4-AB7-5(C12-)A2(12-2A)10-4A-E8AF3(3-E8AE)4-8A6-6A7-D4BD7-D3HBD3(7-D-A-2D)7-D-H2-D7-DAB2AD6-C6BC5(F4-C7B)F4-C6BCF5-D4BD7-D4BD5-2A5BD4-5(A8BC3-)10A3-11A2-9A-2A-13A14-2(E8AE3-)E8AE4-8A6-6A7-D4BD7-D3HBD3(7-D3-2D)7-D4-D7-D4AD6-C6BC5-5(C7BF4-)C6BC6-D4BD7-D4BD5-2A5BD5-4(A7BC4-)A7BC3-10A3-11A2-9A-2A-13A14-2(E8AE3-)E8AE4-8A6-6A7-4DBD4(7-D3-2D)7-D4-D7-D4AD6-2(C6BC5-)3(C7BF4-)C6BC5-C6BC6-2(D4BD7-)D4BD6-4(A6BC5-)A6BC3-10A3-11A2-9A-2A-13A14-2(E8AE3-)E8AE4-8A6-6A7-4DBD4(7-D3-2D)7-D4-D7-D4AD6-3(C6BC5-)CB3G2B3(C5-C6B)C6-D4BD7-D4BD6-A5BD6-4(A6BC5-)A6BC3-10A3-11A2-9A-2A-13A-E8AF3(3-E8AE)4-8A6-6A7-6D4(7-D3-2D)7-D4-D7-6D6-2(C6BC5-)C5DBC5-CD3-DBC5-C5DB2(C5-C6B)C6-6D7-6D6-A6BC5-ABG4B4(C5-ABGB2AB)C5-A3B2ABC3-11A2-9A-2A-13A14-2(E8AE3-)E8AE4-8A109-2(8C5-)3(C5-2C5-)8C5-8C32-7C6-C-5C4(6-C-C2-2C)6-3C2-2C16-9A-2A-13A14-2(E8AE3-)10E353-13A-9EF3(3-10E)366-
