model
size = 32 32 31, scale = 0.05, origin = -y
material 
  colors = A:#111 B:#EEE C:#555 D:#E00 E:#6FF F:#AAA G:#444 H:#888 I:#FC0 J:#F30 K:#222 L:#F60 M:#0E0 N:#777 O:#CCF P:#CC3 Q:#F66 R:#FF0 S:#F3F T:#F00 U:#F39 V:#FFF W:#F36 X:#F9F Y:#F33 Z:#CC6 Aa:#CCC Ab:#FCF Ac:#CF9 Ad:#CFC Ae:#FF9 Af:#FC9 Ag:#CF3 Ah:#CF6 Ai:#FF3 Aj:#F99 Ak:#F6C Al:#FC6 Am:#F09 An:#FCC Ao:#FFC Ap:#F9C Aq:#F0C Ar:#F96 As:#F6F At:#FF6 Au:#F06 Av:#CFF Aw:#FC3 Ax:#F63 Ay:#F69 Az:#F0F Ba:#CC0
voxels
99-2(D24-D102-)D24-D652-3(D-)2D3(-D)12-M4-B14-B4-M8-FB8-5F5-BF8-D-BN-B6-2(FG)F3-B-NB-D8-BN8-5F5-NB8-M-FB-B3-3F8-B-BF-M8-BN5-FGF10-NB8-D-BF-B3-3F8-B-FB-D8-NF5-FGF10-FN8-M-NF-B3-3F8-B-FN-M8-BF8-5F5-FB8-D-FB-B6-2(FG)F3-B-BF-D8-2D8-5F5-2D10-2D-B14-B-2D8-DMD3-3(D-)2D3(-D)3-DMD43-2(16A16-A14-A16-)2(A2-2M6-2M2-A16-)A14-A16-16A266-28A4-7AZAkQAnIV5AWAkAe7A4-7AYAxAwSQU5AVJAj7A4-7AOJLOTR5AUSAh7A4-7AAqAlP3AAaAcAeUAcRST7A4-7AAhRAb3AOAyAoQZAjAtAr7A4-7AUIAi3AArAiPLYPZAd7A4-7AQLAn3ATApAsAcOXAmU7A4-7ALAaS3AApAbVAaAqWAtX7A4-7AAfYOPAgQ5AIAzAk7A4-3A2B2AAfAlWXZT5AQAsAd7A4-3A2B2AAeAuVWRI5ATLAc7A4-7APAbAgAjSY5AAiPL7A4-7ARAoAvAhAmOBaAg2AdAfAbXAa7A4-28A4-5A-16A-5A10-16A16-3(AB)A2B3(AB)A16-16A16-A2-2B6-2B2-2(A16-A-B2AB4-B2AB-)A16-A2-2B6-2B2-A16-16A266-10(28A4-)2(3A2B23A4-)3(28A4-)5A-16A-5A10-3(16A16-)AB4AG2BG4ABA16-AG5A2G5AGA16-7A2B7A16-6AB2GB4ABA16-3(16A266-10(28A4-)2(3A2B23A4-)3(28A4-)5A-16A-5A10-7(16A16-))16A266-6(28A4-)28A3-3(C28AC2-)2(C3A2B23AC2-)2(C28AC2-)2(C28AC3-5A-16A-5A10-7(16A16-)16A266-6(28A4-)28A3-C28AC-C2(B28AB2C)2(B3A2B23AB2C)B28AB2CB28ABC-)C28AC3-5A-16A-5A10-7(16A16-)16A22-4A29-2G209-6(28A4-)28A3-C28AC-C2(B28AB2C)2(B3A2B23AB2C)B28AB2CB28ABC-C28AC3-5A-16A-5A10-7(16A16-)16A21-6A27-4G29-2G177-6(28A4-)28A3-C28AC-C2(B28AB2C)2(B3A2B23AB2C)B28AB2CB28ABC-C28AC3-5A-16A-5A10-7(16A16-)16A21-6A26-6G27-4G29-2G145-6(28A4-)28A3-C28AC-C2(B28AB2C)2(B3A2B23AB2C)B28AB2CB28ABC-C28AC3-5A-16A-5A10-7(16A16-)16A21-6A26-2G2A2G25-H6GC23-2H2-2G2-HF21-CF8-2H19-HC10-CF17-FC12-FH15-AH14-CA9-6(28A4-)28A3-C28AC-C2(B28AB2C)2(B3A2B23AB2C)B28AB2CB28ABC-C28AC3-5A-16A-5A10-7(16A16-)16A21-6A27-4G29-2G177-6(28A4-)28A3-C28AC-C2(B28AB2C)2(B3A2B23AB2C)B28AB2CB28ABC-C28AC3-5A-16A-5A10-7(16A16-)16A22-4A29-2G209-2(6(28A4-)28A3-C28AC-C2(B28AB2C)2(B3A2B23AB2C)B28AB2CB28ABC-C28AC3-5A-16A-5A10-7(16A16-)16A266-)6(28A4-)28A3-C28AC-C5(B28AB2C)B28ABC-C28AC3-5A-16A-5A10-7(16A16-)16A266-6(28A4-)28A3-7(C28AC2-)C28AC3-2(5A-16A-5A10-7(16A16-)16A266-15(28A4-))5A-16A-5A10-7(16A16-)2(16A433-C12-C178-C12-C113-8(16A16-))16A433-C12-C17-6(KC12-CK16-)5(K14-K16-)KC-C8-C-CK462-4(3D14-3D12-)3D14-3D13-2D14-2D77-9(3B14-3B12-)3BC-C8-C-C4(3B12-B-B14-B-B12-3B14-)3B12-3B14-3B171-D3-D12-D3-D10-2D-ID12-DI-2D10-D-I-D12-D-I-D10-2(D-)D12-2(D-)D10-D2-LD12-DL2-D11-2(4D12-)3D14-3D43-9(E4B12-4BE10-)E4B-C8-C-4B9(E10-E3BE12-E3B)E10-5E12-5E137-D5-D10-D5-D8-DJ4-D10-D4-JD8-DJ3-ID10-DI3-JD8-D5-D10-D5-D8-DIL-DID10-DID-LID9-2DJ2D12-2DJ2D11-2(D2BD12-)3D14-3D2(10-7B)9(8-7B10-7B)8-7B10C7B8-7B2C6-2C3(7B8-7BC8-C)3(7B8-7B10-)7B9-5B12-5B10-5B12-5B11-3E14-3E106-DJ4-D10-D4-JD8-D5-D10-D5-D8-DI4-D10-D4-ID8-DLI3-D10-D3-ILD8-D-DJLID10-DILJD-D8-DJD-DBD10-DBD-DJD9-DBIBD12-DBIBD5-C5-D-BD12-DB-D5-2(CH)C3B-3B2C6-2C3B-3B4(CH)3BD3B10C3BD3B2(HC)-HCH2(3B-)8C2(-3B)HCH2-CHC2(3B-)8C2(-3B)CHC3-HC2(3B-)8C2(-3B)CH4-CH2(3B-)8C2(-3B)HC5-C2(3B-)8C2(-3B)C6-C2(3B-)8C2(-3B)C7-2(3B-)8C2(-3B)8-2(3B-)8C2(-3B)9-2B-3B10C3B-2B10-2B-3B2C6-2C3B-2B10-2B-3BC8-C3B-2B10-2B-3B10-3B-2B6(10-6B)9-7B10-7B8-7B10-7B9-5B12-5B11-EBE14-EBE13-D16-D75-D5-D10-D5-D8-D4-ID10-DI4-D8-D5-D10-D5-D8-D-3J-D10-D-3J-D8-D-LIL-D10-D-LIL-D9-DJ3D12-3DJD11-2(4D12-)D-D14-D-D10-7B2C6-2C7B8-7B4C2-4C2(7B8-7B-8C-)6(7B8-7B3(-2C)-)7B8-7B10C7B8-7B2C6-2C3(7B8-7BC8-C)3(7B8-7B10-)7B9-5B12-5B10-5B12-5B11-3E14-3E107-3(D3-D12-D3-D10-)DJ2-D12-D2-JD10-D-I-D12-D-I-D11-DB2D12-2DBD13-D16-D44-4(E3BE12-E3BE10-)2(E3BE2-H6-H2-3(E3BE10-E3BE12-)E3BE10-)6(E3BE12-E3BE10-)2EB2E12-2EB2E10-5E12-5E139-4(3D14-3D12-)3D14-3D13-D16-D77-2(3B14-3B12-)BCB14-BCB12-3B3-H6-H3-3B12-BCB3-H6-H3-2(BCB12-BCB14-)BCB12-3B14-3B2(12-BCB3-H6-H3-BCB)8(12-BCB14-BCB)13-B16-B167-
