model
size = 32 21 32, scale = 0.05, origin = -y
material 
  colors = A:#FF6 B:#F90
voxels
13-20(2A30-)2A29-5(5A27-)5(4AB27-)10(5A27-)5A5(26-6A)5(26-5AB)9(26-6A)26-A2B3A26-6A26-5(7A25-)2(5AB26-)5A2B25-2(5AB26-)9(7A25-)A4B2A25-7A5(24-8A)24-5(6AB25-)9(8A24-)A6BA24-8A24-5(9A23-)7A2B3(23-6AB-B)23-7A2B4(23-9A)3(23-B8A)2(23-9A)23-A6B2A23-9A22-12(11A21-)11A2(22-B9A)21-2B2(9A22-B)9A21-11A21-A8B2A14(21-11A)5(22-B9A)21-11A21-A8B2A21-11A20-13A19-10A2BA11(19-13A)19-2A3(B10A19-A-)B10A19-2AB10A19-13A19-A9B3A19-3A5-5A19-8A24-8A4BA9(19-13A)19-3(11AB20-)3(2AB10A19-)2(13A19-)A9B3A19-2A7-4A18-8A24-8A6BA7(17-15A)17-B14A17-B11AB-B17-B11A3(B19-12A)B19-3(15A17-)6AB8A17-A11B3A17-2A9-4A17-7A25-7A7BA6(17-15A)2(17-B14A)17-B11AB-B17-B11AB19-B12AB18-2(12AB19-)13ABA17-15A2(17-6AB8A)17-A11B3A17-2A9-4A16-8A24-8A8BA5(15-17A)2(16-B15A)15-2B12AB2A16-B11AB-BA16-2(B11AB18-A)B11AB18-13AB18-14AB2A15-17A2(15-7AB9A)17-11B4A16-2A4-B4-5A15-8A4-B4-A14-8A9BA3(14-18A)2(14-17AB)3(15-B15AB)15-B12AB3A15-2(B11AB-B2A14-A)B11AB-B2A14-14A2B2A2(14-18A)2(14-7AB10A)14-A-10B6A15-2A9-6A13-9A9-A13-9A9BA3(13-19A)2(13-18AB)13-A2B3(15AB13-A-B)16A13-A2B2(12AB3A13-2AB)16A13-19A3(14-18A)14-7AB10A16-A9B6A16-A9-6A12-10A9-2A12-9A10BA3(13-19A)13-3(17AB14-)2(AB15AB14-)3(AB17A13-)6(19A13-)3A8B8A13-4A7-8A11-11A7-3A11-10A10BA3(12-20A)12-4(18AB13-)2AB15AB13-2(2AB17A12-)7(20A12-)4A7B8A13-6A5-8A12-12A5-5A10-11A10BA3(11-21A)5(11-18AB-A)9(11-21A)11-20A12-20A10-23A9-12A10BA4(9-23A)3(9-21A-A)10(9-23A)9-2A3B18A9-23A9-24A8-13A9B2A17(8-24A)8-A5B6A5B7A8-24A7-26A6-16A5B5A17(6-26A)6-A7B4A7B7A6-2A3-21A2(6-26A)6-17(25A7-)A7B3A9B5A7-A5-19A6-25A7-25A3B17(4-28A)4-2A7B2A11B6A4-2A2-B2-6A3-12A4-24A8-24A4B4-17(27A5-)2A6B3A11B5A5-2A5-5A5-10A5-6A3-15A2-B5-6A4B14A5B7(3-29A)6(3-28AB)4(3-29A)3-3A4B4A11B7A3-3A3-5A7-11A2-6A5-14A7-6A6B13A5B3-7(28A4-)7(27AB4-)3(28A4-)11A11B6A4-11A3-B3-10A3-6A2-B2-15A3-2A-6A7B13A4BA7(-31A)-29A3(B3-B27A)2B-AB27A2(B2-29A)B2-3(31A-)12A11B8A-12A7-12A-6A5-27A7B50A6(-31A)2-4(B27AB3-)B27AB2-AB27A2(B2-29A)BA2(-31A)-13A9B9A-13A5-13A-7A3-28A7B49A6(2-30A)2(3-B27AB)2-2B2(27AB3-B)2(27AB2-AB)27AB2-29AB2(2-30A)2-14A7B9A2-14A3-13A2-39A5B244A-B28ABA-B27A2B3(A-B27AB-)2(2AB27A2B)30A2B80A5B81A6B25A6B20A-5A7B14A3B2A-5A7B14ABAB2A-5A7B14A3B2A-6A5B20A-7A3B10A3B8A-19A5B7A-2AB16A6B6A-A-B4A5B7A6B6A-A-B3A7B7A5B5AB-A-B2A9B7A3B6AB-2AB2A9B14A3B-2AB2A9B13A4B-BAB2A9B13A4B-B4A9B13A4B-B5A7B14A4B-7A5B19A2(-31A)-38A3-28A5-27A2-B2-16A3-8A5-16A-B-9A3-17A3-55A3-28A5-27A2-B2-15A5-7A5-14A7-7A3-14A9-16AB6A9-14A3-6A4-B4-13A5-5A9-13A2-B2-5A9-13A5-6A7-15A3-8A5-85A
