model
size = 32 6 32, scale = 0.05, origin = -y
material 
  colors = A:#6C3 B:#070 C:#CC3
voxels
3-4B5-8B5-4B165-B4AB3-B8AB3-B4AB163-B6A4-8A4-6AB161-B7A4-8A4-7AB160-B7A16-7AB5-C2AC4-C4AC4-C2AC133-B5A20-5AB4-C4A4-6A4-4AC132-B4A22-4AB4-5A4-6A4-5A18-4A111-B3A22-3AB5-5A14-5A11-3A4-4A4-3A139-C3A16-3AC11-3A4-4A4-3A21-4A149-2A14-2A16-2A3-4A3-2A178-2(2A4-)2A24-2A48-B28-B108-A3-2A3-A24-6B13-B3A24-3AB108-A6-A24-B6-B12-B3A24-3AB4-CA20-AC10-2A16-2A81-B8-B11-B3A24-3AB4-2A20-2A10-2(3A14-)2A12-2A51-2(B8-B11-B3A24-3AB4-2A20-2A10-2(3A14-)3A10-3A19-A8-A22-)B8-B11-B3A24-3AB4-2A20-2A10-2(3A14-)2A12-2A51-B8-B11-B3A24-3AB4-CA20-AC10-2A16-2A81-B8-B11-B3A24-3AB108-A6-A24-B6-B13-B28-B108-A3-2A3-A24-6B118-2(2A4-)2A24-2A118-2A14-2A16-2A3-4A3-2A109-C3A16-3AC11-3A4-4A4-3A21-4A79-B3A22-3AB5-5A14-5A11-3A4-4A4-3A103-B4A22-4AB4-5A4-6A4-5A18-4A110-B5A20-5AB4-C4A4-6A4-4AC132-B7A16-7AB5-C2AC4-C4AC4-C2AC133-B7A4-8A4-7AB161-B6A4-8A4-6AB163-B4AB3-B8AB3-B4AB165-4B5-8B5-4B163-
