model
size = 26 5 24, scale = 0.05, origin = -y
material 
  colors = A:#000 B:#FFF
voxels
---AAAAAAA------AAAAAAA--- --AABABAAAA----AABABAAAA-- -AABABAAAAAA--AABABAAAAAA- AABABAAAAAAA--ABABAAAAAAAA AAAAAAAAAAAAAAAAAAAAAAAAAA 
-------------------------- -------------------------- -------------------------- -------------------------- A------------------------A 
-------------------------- -------------------------- -------------------------- -------------------------- A------------------------A 
-------------------------- -------------------------- -------------------------- -------------------------- A------------------------A 
-------------------------- -------------------------- -------------------------- -------------------------- A------------------------A 
-------------------------- -------------------------- -------------------------- -------------------------- A------------------------A 
-------------------------- -------------------------- -------------------------- -------------------------- A------------------------A 
-------------------------- -------------------------- -------------------------- -------------------------- A------------------------A 
-------------------------- -------------------------- -------------------------- -------------------------- A------------------------A 
-------------------------- -------------------------- -------------------------- -------------------------- A------------------------A 
-------------------------- -------------------------- -------------------------- -------------------------- A------------------------A 
-------------------------- -------------------------- -------------------------- -------------------------- A------------------------A 
-------------------------- -------------------------- -------------------------- -------------------------- A------------------------A 
-------------------------- -------------------------- -------------------------- -------------------------- A------------------------A 
-------------------------- -------------------------- -------------------------- -------------------------- A------------------------A 
-------------------------- -------------------------- -------------------------- -------------------------- A------------------------A 
-------------------------- -------------------------- -------------------------- -------------------------- A------------------------A 
-------------------------- -------------------------- -------------------------- -------------------------- A------------------------A 
-------------------------- -------------------------- -------------------------- -------------------------- A------------------------A 
-------------------------- -------------------------- -------------------------- -------------------------- A------------------------A 
-------------------------- -------------------------- -------------------------- -------------------------- A------------------------A 
-------------------------- -------------------------- -------------------------- -------------------------- A------------------------A 
-------------------------- -------------------------- -------------------------- A------------------------A -------------------------- 
-------------------------- -------------------------- -------------------------- A------------------------A -------------------------- 
