model
size = 30 32 30, scale = 0.05, origin = -y
material 
  colors = A:#118452 B:#7D0028 C:#9AA9BC D:#520064 E:#1DE188 F:#01512E G:#1CC23D H:#9AD0FF I:#3A5D95 J:#3588FE K:#259A3E L:#FFF M:#71F7B2 N:#FEEA41 O:#FF7200 P:#347AB5 Q:#FFD240 R:#1E1729 S:#990027 T:#FDA228 U:#EA0019 V:#FFF1E9 W:#9F0E65
voxels
324-2N28-2N432-4M26-4M20-2E4M24-2E4M406-2N28-2N432-4M26-4M20-2E4M24-2E4M218-3(2L28-)2L34-2T2N26-2T2N78-4(2L28-)2(2P28-)6E2-2E20-6E2-2(2E10-2E6-2E8-)2E8-2E2-2N2T2-6E4M10-2E2-2N2T2-6E4M8-2(2E2-2N4D2U2E4M12-)2(2E2-2U2D2A2E2M16-)4G6E20-4G6E216-3(2L28-)2L34-2T2N26-2T2N78-4(2L28-)2(2P28-)6E2-2E20-6E2-2(2E10-2E6-2E8-)2E8-2E2-2N2T2-6E4M10-2E2-2N2T2-6E4M8-2(2E2-2N4D2U2E4M12-)2(2E2-2U2D2A2E2M16-)4G6E20-4G6E92-8B22-8B20-4G2(2F2P)2F16-4G2(2F2P)2F14-2(2K2P2F6-2L16-)2G2L10-2T2Q12-2G2L10-2T2Q26-2T2Q2N24-2T2Q2N30-2N28-2N70-2(2L8-2L18-)2P2-2H4F2P18-2P2-2H4F2P14-2E6G6R2D2E2G10-2E6G6R2(2D2E2G8-2K4Q2A2R6-)2D2E2G6-2K2Q4A2T2A6R2A2H8-2K2Q4A2T2A6R2A2H6-2(2G6Q10A4H8-)2G2T4Q2I4A4H4J8-2G2T4Q2I4A4H4J10-2K2A4I4H6J12-2K2A4I4H6J4(22-8B)20-4G2(2F2P)2F16-4G2(2F2P)2F14-2(2K2P2F6-2L16-)2G2L10-2T2Q12-2G2L10-2T2Q26-2T2Q2N24-2T2Q2N30-2N28-2N70-2(2L8-2L18-)2P2-2H4F2P18-2P2-2H4F2P14-2E6G6R2D2E2G10-2E6G6R2(2D2E2G8-2K4Q2A2R6-)2D2E2G6-2K2Q4A2T2A6R2A2H8-2K2Q4A2T2A6R2A2H6-2(2G6Q10A4H8-)2G2T4Q2I4A4H4J8-2G2T4Q2I4A4H4J10-2K2A4I4H6J12-2K2A4I4H6J2(22-8B)18-2(16B14-)2(4F2C10B2F12-4F2C10B2F10-4A2EWB8-2O12-4A2EWB8-2O10-2K2G6B6-2O2S2T8-2K2G6B6-2O2S2T26-2O4T24-2O4T190-6A8B2F14-6A8B2F12-2K16A4E8-2K16A2(4E6-2K8A6D4A)4E4-2(2K20A2H6-)2(2G18A2J8-)2G18A2I8-2G18A2I2(10-2A2I12A4I)4(14-16B)14-)2(2F4C2B6C2B2P12-)2F2C2B2-4S2W2-2L12-2F2C2B2-4S2W2-2L8-4A2E2C2B2-2S6O10-4A2E2C2B2-2S6O8-2(2E2F2L6D18-)2E4-6D18-2E4-3(6D24-)8D8-2L12-8D8-2L2(10-2L2D6C8B2P)2(10-2P16A2D)2(6-2G20A2D)6-2(2G22A2M4-)2G20A2H6-2G20A2H2(8-20A2J)10-2I14A2I12-2I14A2I4(14-16B)14-2(2F4C2B6C2B2P12-)2F2C2B2-4S2W2-2L12-2F2C2B2-4S2W2-2L8-4A2E2C2B2-2S6O10-4A2E2C2B2-2S6O8-2(2E2F2L6D18-)2E4-6D18-2E4-3(6D24-)8D8-2L12-8D8-2L2(10-2L2D6C8B2P)10-2P16A2D10-2P5A8B3A2(2D6-2G20A)2D6-2(2G22A2M4-)2G20A2H6-2G20A2H2(8-20A2J)10-2I14A2I12-2I14A2I2(14-16B)12-2(20B10-)2(2I14C2B2F10-)2(2F6C2(2B2S)14-)2F4C2B2-2S4O14-2F4C2B2-2S4O12-2A2I4C2D20-2A2I4(4C2D18-2E2G2D)4C2D22-2(2D6C2D20-)2D8C8B2F10-2D8C8B2F6-4G18A2R2E4-4G7A8B3A2R2E4-2G18A2D8-2G18A2D10-2(2K18A2R2M6-)2(20A2H8-)2F18A2J8-2F18A2(2J10-2I16A)2J4(10-20B)2(10-2I14C2B2F)10-2(2F6C2(2B2S)14-)2F4C2B2-2S4O14-2F4C2B2-2S4O12-2A2I4C2D20-2A2I4(4C2D18-2E2G2D)4C2D22-2(2D6C2D20-)2D8C8B2F10-2D8C8B2F6-4G18A2R2E4-4G7A8B3A2R2E4-2G18A2D8-2G18A2D10-2(2K18A2R2M6-)2(20A2H8-)2F18A2J8-2F18A2(2J10-2I16A)2J4(10-20B)2(10-2I14C2B2P)10-2(2I8C4B2S4-2L8-)2(2J6C2B6S4-2L8-)2(2B6C2D20-)2B2O4C2D20-2B2O4C2(2D18-2K2B6C)2(2D18-2K2E6C)2D18-2(2K2E8C8B2F8-)2K18A2R2E6-2K12A3B3A2R2E6-2(18A2D10-)2(20A2R2E6-)2F20A2M6-2F20A2M8-2(2I16A2H10-)2(2I16A2J10-)4(20B10-)2(2I14C2B2P10-)2(2I8C4B2S4-2L8-)2(2J6C2B6S4-2L8-)2(2B6C2D20-)2B2O4C2D20-2B2O4C2(2D18-2K2B6C)2(2D18-2K2E6C)2D18-2(2K2E8C8B2F8-)2K18A2R2E6-2K9A6B3A2R2E6-2(18A2D10-)2(20A2R2E6-)2F20A2M6-2F20A2M8-2(2I16A2H10-)2(2I16A2J10-)2(4(20B10-)2(2I10C2S4B2F10-)2(2J8C2B18-)2H8C2B18-2H8C2B4(20-2U6C2D)20-2O6C4D6-2L10-2O6C4D6-2(2L8-2H8C6D4-)2L2(6-2F2N14C2B2H2P)6-2F18A2R2E6-2F9A6B3A2R2E6-2F16A2D10-2F16A2D12-2(2I16A2R2E8-)2(2I18A2M8-)2(2I16A2H10-)2(2J16A2J10-))4(20B10-)2(2J12C2B2C2G10-)2H10C2S4B2F10-2H10C2S4B2F12-2(2N2V6C6B14-)2(2N8C4D16-)2(2U8C4D16-)3(2O10C2D16-)2O10C2D14-2(2H2B12C2A12-)2H16A2G10-2H10A3B3A2G10-2(2I16A2R2E8-)2(2I18A2E8-)2(2J18A2E8-)2(2J18A2M8-)2(2H16A2H10-)4(20B10-)2(2J12C2B2C2G10-)2H10C2S4B2F10-2H10C2S4B2F12-2(2N2V6C6B14-)2(2N8C4D16-)2(2U8C4D16-)3(2O10C2D16-)2O10C2D14-2(2H2B12C2A12-)2H16A2G10-2H5A8B3A2G10-2(2I16A2R2E8-)2(2I18A2E8-)2(2J18A2E8-)2(2J18A2M8-)2(2H16A2H10-)20B10-20B12-2(16B14-)2(2(2J12C2F2G12-)2H12C2E2P12-2H12C2E2P2(14-2V10C2B2L)14-4(2N8C2D18-)2(2U8C2D18-)2(2N8C2D2-2L14-)2U10C2A2P14-2U10C2A2P12-2H14A2G12-2H3A8B3A2G2(12-2J16A)2(12-2J14A2T)12-2(2H16A2U10-)2(2H16A2E2M8-)2(2B14A2H12-)4(16B14-))2(2H2J8C4F14-)4H8C2F2H2K12-4H8C2F2H2K2(16-2N6C2E2B2G)16-2(2T2U2D2C2D20-)2(2O2U2O4D20-)2(2O2N2D2C2D20-)2(2U6C2D20-)2B6C2D2A18-2B6C2D2A14-2(4H12A2G12-)2(2H2J12A2Q12-)2(2H2J12A2F2T10-)2(2B2H12A2F2D10-)2(2B2H12A2F2E2M8-)2(4B12A2I2E10-)4(16B14-)2(2H2J8C4F14-)4H8C2F2H2K12-4H8C2F2H2K2(16-2N6C2E2B2G)16-2(2T2U2D2C2D20-)2(2O2U2O4D20-)2(2O2N2D2C2D20-)2(2U6C2D20-)2B6C2D2A18-2B6C2D2A14-2(4H12A2G12-)2(2H2J12A2Q12-)2(2H2J12A2F2T10-)2(2B2H12A2F2D10-)2(2B2H12A2F2E2M8-)2(4B12A2I2E10-)16B14-16B18-2(8B22-)2(2J6I22-)2H2J2I2F2-2A18-2H2J2I2F2-2A2(20-2H2J2F2K2E)22-2(2B2F2L24-)3(2B2D26-)2B2(2D24-2H2F)2D22-2(2H4F2D2L20-)2(2H6A2P2A2G2E14-)2(2I10A2Q16-)2(4I8A2F2N14-)2(2J2I8A2F2D14-)2(2J4I6A2F2D14-)2(2H2J10I2E2M12-)4(8B22-)2(2J6I22-)2H2J2I2F2-2A18-2H2J2I2F2-2A2(20-2H2J2F2K2E)22-2(2B2F2L24-)3(2B2D26-)2B2(2D24-2H2F)2D22-2(2H4F2D2L20-)2(2H6A2P2A2G2E14-)2(2I10A2Q16-)2(4I8A2F2N14-)2(2J2I8A2F2D14-)2(2J4I6A2F2D14-)2(2H2J10I2E2M12-)8B22-8B210-2A2K26-2A2K24-2(2A2F26-)2G28-3(2G26-2K)28-3(2K26-2F)2(2K2G24-2F)2A2-2A4K2E16-2F2A2-2A4K2E18-2(2A2K4A2Q20-)2F6A2F2N18-2F6A2F2N2(20-2F4A2F2U)24-4A2E2M22-4A2E2M260-2A2K26-2A2K24-2(2A2F26-)2G28-3(2G26-2K)28-3(2K26-2F)2(2K2G24-2F)2A2-2A4K2E16-2F2A2-2A4K2E18-2(2A2K4A2Q20-)2F6A2F2N18-2F6A2F2N2(20-2F4A2F2U)24-4A2E2M22-4A2E2M2(320-2E28-2E2(26-4E)26-2E28-2E148-2(2G28-)4G26-4G28-2(2G4K2E22-)4G2Q24-4G2Q2(26-2G2T)28-2K2G2E24-2K2G2E)804-3(2G2E26-)2G2E2(28-2G)806-3(2G2E26-)2G2E2(28-2G)62-
