model
size = 24 24 27, scale = 0.05, origin = -y
material 
  colors = A:#555 B:#777 C:#444
voxels
------------------------ ------------------------ ------------------------ ---C-------------------- ------------------------ ------------------------ ------------------------ ------------------------ ------------------------ ------------------------ ------------------------ ------------------------ ------------------------ ------------------------ ------------------------ ------------------------ ------------------------ ------------------------ ------------------------ ------------------------ ------------------------ ------------------------ ------------------------ ------------------------ 
BBBBBBBBBBBB------------ B----------------------- B-BBB------------------- B-BBB------------------- B-BBB------------------- B----------------------- B----------------------- B----------------------- B----------------------- B----------------------- B----------------------- B----------------------- ------------------------ ------------------------ ------------------------ ------------------------ ------------------------ ------------------------ ------------------------ ------------------------ ------------------------ ------------------------ ------------------------ ------------------------ 
AAAAAAAAAAAAB----------- AAAAAAAAAAAA------------ AAAAAAAAAAAA------------ AAAAAAAAAAAA------------ AAAAAAAAAAA------------- AAAAAAAAAAA------------- AAAAAAAAAAA------------- AAAAAAAAAA-------------- AAAAAAAAA--------------- AAAAAAA----------------- AAA--------------------- AA---------------------- B----------------------- ------------------------ ------------------------ ------------------------ ------------------------ ------------------------ ------------------------ ------------------------ ------------------------ ------------------------ ------------------------ ------------------------ 
----------AAAB---------- ----------AAA----------- ----------AAA----------- ----------AAA----------- ----------AAA----------- ----------AA------------ ----------AA------------ ----------AA------------ ---AAAAAAAA------------- ---AAAAAAA-------------- ---AAAAA---------------- AAAA-------------------- AAA--------------------- B----------------------- ------------------------ ------------------------ ------------------------ ------------------------ ------------------------ ------------------------ ------------------------ ------------------------ ------------------------ ------------------------ 
-----------AAAB--------- -----------AAA---------- -----------AAA---------- -----------AAA---------- -----------AAA---------- -----------AAA---------- -----------AA----------- -----------AA----------- -----------AA----------- ----AAAAAAAA------------ ----AAAAAAA------------- ----AAAAA--------------- AAAAA------------------- AAAA-------------------- B----------------------- ------------------------ ------------------------ ------------------------ ------------------------ ------------------------ ------------------------ ------------------------ ------------------------ ------------------------ 
------------AAAB-------- ------------AAA--------- ------------AAA--------- ------------AAA--------- ------------AAA--------- ------------AAA--------- ------------AAA--------- ------------AA---------- ------------AA---------- ------------AA---------- -----AAAAAAAA----------- -----AAAAAAA------------ -----AAAAA-------------- AAAAAA------------------ AAAAA------------------- B----------------------- ------------------------ ------------------------ ------------------------ ------------------------ ------------------------ ------------------------ ------------------------ ------------------------ 
-------------AAAB------- -------------AAA-------- -------------AAA-------- -------------AAA-------- -------------AAA-------- -------------AAA-------- -------------AAA-------- -------------AAA-------- -------------AA--------- -------------AA--------- -------------AA--------- ------AAAAAAA----------- ------AAAAAAA----------- ------AAAAA------------- AAAAAA------------------ AAAAAA------------------ B----------------------- ------------------------ ------------------------ ------------------------ ------------------------ ------------------------ ------------------------ ------------------------ 
--------------AAAB------ --------------AAA------- --------------AAA------- --------------AAA------- --------------AAA------- --------------AAA------- --------------AAA------- --------------AAA------- --------------AAA------- --------------AA-------- --------------AA-------- -------AAAAAAAAA-------- -------AAAAAAA---------- -------AAAAAAA---------- AAAAAAAAAAAA------------ AAAAAAA----------------- AAAAAAA----------------- B----------------------- ------------------------ ------------------------ ------------------------ ------------------------ ------------------------ ------------------------ 
--------------AAAAB----- --------------AAAA------ --------------AAAA------ --------------AAAA------ --------------AAAA------ --------------AAAA------ --------------AAAA------ --------------AAAA------ --------------AAAA------ --------------AAABBBBBBB --------------AAABBBBBBB --------------AAABBBBBBB -------AAAAAAAA--------- -------AAAAAAAA--------- -------AAAAAAAA--------- AAAAAAAAAAAA------------ AAAAAAABBB-------------- AAAAAAABBB-------------- B------BBB-------------- -------BBB-------------- -------BBB-------------- -------BBB-------------- -------BBB-------------- -------BBB-------------- 
--------------AAAAAB---- --------------AAAAA----- --------------AAAAA----- --------------AAAAA----- --------------AAAAA----- --------------AAAAA----- --------------AAAAA----- --------------AAAAA----- --------------AAAAA----- --------------AAAAABBBBB --------------AAAABBBBBB --------------AAAABBBBBB ------------AAAAAA------ ------------AAAA-------- ------------AAAA-------- -------AAAAAA----------- -------AAAAAA----------- AAAAAAAAAB-------------- AAAAAAAAAB-------------- B------BBB-------------- -------BBB-------------- -------BBB-------------- -------BBB-------------- -------BBB-------------- 
--------------AAAAAAB--- --------------AAAAAA---- --------------AAAAAA---- --------------AAAAAA---- --------------AAAAAA---- --------------AAAAAA---- --------------AAAAAA---- --------------AAAAAA---- --------------AAAAAA---- --------------AAAAAABBBB --------------AAAAABBBBB --------------AAAAABBBBB ------------AAAAAAA----- ------------AAAAA------- ------------AAAAA------- -------AAAAAAA---------- -------AAAAAAA---------- AAAAAAAAAAAAAA---------- AAAAAAAAAA-------------- AAAAAAAAAA-------------- B------BBB-------------- -------BBB-------------- -------BBB-------------- -------BBB-------------- 
--------------AAAAAAB--- --------------AAAAAA---- --------------AAAAAA---- --------------AAAAAA---- --------------AAAAAA---- --------------AAAAAA---- --------------AAAAAA---- --------------AAAAAA---- --------------AAAAAA---- --------------AAAAAA---- --------------AAAAA----- --------------AAAAA----- ------------AAAAAAA----- ------------AAAAA------- ------------AAAAA------- -------AAAAAAA---------- -------AAAAAAA---------- -------AAAAAAA---------- AAAAAAAAAA-------------- AAAAAAAAAA-------------- B----------------------- ------------------------ ------------------------ ------------------------ 
--------------AAAAAAAB-- --------------AAAAAAA--- --------------AAAAAAA--- --------------AAAAAAA--- --------------AAAAAAA--- --------------AAAAAAA--- --------------AAAAAAA--- --------------AAAAAAA--- --------------AAAAAAA--- --------------AAAAAAA--- --------------AAAAAA---- --------------AAAAAA---- ------------AAAAAAAA---- ------------AAAAAA------ ------------AAAAAA------ -------AAAAAAAAAA------- -------AAAAAAAA--------- -------AAAAAAAA--------- AAAAAAAAAAAAAA---------- AAAAAAAAAAA------------- AAAAAAAAAAA------------- B----------------------- ------------------------ ------------------------ 
--------------AAAAAAAB-- --------------AAAAAAA--- --------------AAAAAAA--- --------------AAAAAAA--- --------------AAAAAAA--- --------------AAAAAAA--- --------------AAAAAAA--- --------------AAAAAAA--- --------------AAAAAAA--- --------------AAAAAAA--- --------------AAAAAA---- --------------AAAAAA---- ------------AAAAAAAA---- ------------AAAAAA------ ------------AAAAAA------ -------AAAAAAAAAA------- -------AAAAAAAA--------- -------AAAAAAAA--------- AAAAAAAAAAAAAA---------- AAAAAAAAAAA------------- AAAAAAAAAAA------------- B----------------------- ------------------------ ------------------------ 
--------------AAAAAAAB-- --------------AAAAAAA--- --------------AAAAAAA--- --------------AAAAAAA--- --------------AAAAAAA--- --------------AAAAAAA--- --------------AAAAAAA--- --------------AAAAAAA--- --------------AAAAAAA--- --------------AAAAAAA--- --------------AAAAAA---- --------------AAAAAA---- ------------AAAAAAAA---- ------------AAAAAA------ ------------AAAAAA------ -------AAAAAAAAAA------- -------AAAAAAAA--------- -------AAAAAAAA--------- AAAAAAAAAAAAAA---------- AAAAAAAAAAA------------- AAAAAAAAAAA------------- B----------------------- ------------------------ ------------------------ 
--------------AAAAAAB--- --------------AAAAAA---- --------------AAAAAA---- --------------AAAAAA---- --------------AAAAAA---- --------------AAAAAA---- --------------AAAAAA---- --------------AAAAAA---- --------------AAAAAA---- --------------AAAAAA---- --------------AAAAA----- --------------AAAAA----- ------------AAAAAAA----- ------------AAAAA------- ------------AAAAA------- -------AAAAAAA---------- -------AAAAAAA---------- -------AAAAAAA---------- AAAAAAAAAA-------------- AAAAAAAAAA-------------- B----------------------- ------------------------ ------------------------ ------------------------ 
--------------AAAAAAB--- --------------AAAAAA---- --------------AAAAAA---- --------------AAAAAA---- --------------AAAAAA---- --------------AAAAAA---- --------------AAAAAA---- --------------AAAAAA---- --------------AAAAAA---- --------------AAAAAA---- --------------AAAAA----- --------------AAAAA----- ------------AAAAAAA----- ------------AAAAA------- ------------AAAAA------- -------AAAAAAA---------- -------AAAAAAA---------- AAAAAAAAAAAAAA---------- AAAAAAAAAA-------------- AAAAAAAAAA-------------- B----------------------- ------------------------ ------------------------ ------------------------ 
--------------AAAAAB---- --------------AAAAA----- --------------AAAAA----- --------------AAAAA----- --------------AAAAA----- --------------AAAAA----- --------------AAAAA----- --------------AAAAA----- --------------AAAAA----- --------------AAAAA----- --------------AAAA------ --------------AAAA------ ------------AAAAAA------ ------------AAAA-------- ------------AAAA-------- -------AAAAAA-BBB------- -------AAAAAA-BBBB------ AAAAAAAAA------BBBB----- AAAAAAAAA-------BBBB---- B----------------BBB---- -----------------BBB---- ------------------------ ------------------------ ------------------------ 
--------------AAAAB----- --------------AAAA------ --------------AAAA------ --------------AAAA------ --------------AAAA------ --------------AAAA------ --------------AAAA------ --------------AAAA------ --------------AAAA------ --------------AAA------- --------------AAA------- --------------AAA------- -------AAAAAAAA--------- -------AAAAAAAA--------- -------AAAAAAAABB------- AAAAAAAAAAAA--BBB------- AAAAAAAA------BBBB------ AAAAAAAA-------BBBB----- B---------------BBBB---- -----------------BBB---- -----------------BBB---- ------------------------ ------------------------ ------------------------ 
--------------AAAB------ --------------AAA------- --------------AAA------- --------------AAA------- --------------AAA------- --------------AAA------- --------------AAA------- --------------AAA------- --------------AAA------- --------------AA-------- --------------AA-------- -------AAAAAAAAA-------- -------AAAAAAA---------- -------AAAAAAA---------- AAAAAAAAAAAA------------ AAAAAAA----------------- AAAAAAA----------------- B----------------------- ------------------------ ------------------------ ------------------------ ------------------------ ------------------------ ------------------------ 
-------------AAAB------- -------------AAA-------- -------------AAA-------- -------------AAA-------- -------------AAA-------- -------------AAA-------- -------------AAA-------- -------------AAA-------- -------------AA--------- -------------AA--------- -------------AA--------- ------AAAAAAA----------- ------AAAAAAA----------- ------AAAAA------------- AAAAAA------------------ AAAAAA------------------ B----------------------- ------------------------ ------------------------ ------------------------ ------------------------ ------------------------ ------------------------ ------------------------ 
------------AAAB-------- ------------AAA--------- ------------AAA--------- ------------AAA--------- ------------AAA--------- ------------AAA--------- ------------AAA--------- ------------AA---------- ------------AA---------- ------------AA---------- -----AAAAAAAA----------- -----AAAAAAA------------ -----AAAAA-------------- AAAAAA------------------ AAAAA------------------- B----------------------- ------------------------ ------------------------ ------------------------ ------------------------ ------------------------ ------------------------ ------------------------ ------------------------ 
-----------AAAB--------- -----------AAA---------- -----------AAA---------- -----------AAA---------- -----------AAA---------- -----------AAA---------- -----------AA----------- -----------AA----------- -----------AA----------- ----AAAAAAAA------------ ----AAAAAAA------------- ----AAAAA--------------- AAAAA------------------- AAAA-------------------- B----------------------- ------------------------ ------------------------ ------------------------ ------------------------ ------------------------ ------------------------ ------------------------ ------------------------ ------------------------ 
----------AAAB---------- ----------AAA----------- ----------AAA----------- ----------AAA----------- ----------AAA----------- ----------AA------------ ----------AA------------ ----------AA------------ ---AAAAAAAA------------- ---AAAAAAA-------------- ---AAAAA---------------- AAAA-------------------- AAA--------------------- B----------------------- ------------------------ ------------------------ ------------------------ ------------------------ ------------------------ ------------------------ ------------------------ ------------------------ ------------------------ ------------------------ 
AAAAAAAAAAAAB----------- AAAAAAAAAAAA------------ AAAAAAAAAAAA------------ AAAAAAAAAAAA------------ AAAAAAAAAAA------------- AAAAAAAAAAA------------- AAAAAAAAAAA------------- AAAAAAAAAA-------------- AAAAAAAAA--------------- AAAAAAA----------------- AAA--------------------- AA---------------------- B----------------------- ------------------------ ------------------------ ------------------------ ------------------------ ------------------------ ------------------------ ------------------------ ------------------------ ------------------------ ------------------------ ------------------------ 
BBBBBBBBBBBB------------ B----------------------- B-BBB------------------- B-BBB------------------- B-BBB------------------- B----------------------- B----------------------- B----------------------- B----------------------- B----------------------- B----------------------- B----------------------- ------------------------ ------------------------ ------------------------ ------------------------ ------------------------ ------------------------ ------------------------ ------------------------ ------------------------ ------------------------ ------------------------ ------------------------ 
------------------------ ------------------------ ------------------------ ---C-------------------- ------------------------ ------------------------ ------------------------ ------------------------ ------------------------ ------------------------ ------------------------ ------------------------ ------------------------ ------------------------ ------------------------ ------------------------ ------------------------ ------------------------ ------------------------ ------------------------ ------------------------ ------------------------ ------------------------ ------------------------ 
