model
size = 27 27 29, scale = 0.05, origin = -y
material 
  colors = A:#BBB B:#AAA C:#888 D:#DDD E:#09F F:#080 G:#006
voxels
--------------AA----------- --------------AA----------- --------------------------- --------------------------- --------------------------- --------------------------- --------------------------- --------------------------- --------------------------- --------------------------- --------------------------- --------------------------- --------------------------- --------------------------- --------------------------- --------------------------- --------------------------- --------------------------- --------------------------- --------------------------- --------------------------- --------------------------- --------------------------- --------------------------- --------------------------- --------------------------- --------------------------- 
------------ACAAAA--------- ------------CAACCA--------- --------------------------- --------------------------- --------------------------- --------------------------- --------------------------- --------------------------- --------------------------- --------------------------- --------------------------- --------------------------- --------------------------- --------------------------- --------------------------- --------------------------- --------------------------- --------------------------- --------------------------- --------------------------- --------------------------- --------------------------- --------------------------- --------------------------- --------------------------- --------------------------- --------------------------- 
---------AAAAAAAAAAC------- ---------BFEACCCAAAA------- --------------------------- --------------------------- --------------------------- --------------------------- --------------------------- --------------------------- --------------------------- --------------------------- --------------------------- --------------------------- --------------------------- --------------------------- --------------------------- --------------------------- --------------------------- --------------------------- --------------------------- --------------------------- --------------------------- --------------------------- --------------------------- --------------------------- --------------------------- --------------------------- --------------------------- 
-------BBAAAAAAAAAAACAA---- -------ABBAEACCAAFAACAE---- --------------------------- --------------------------- --------------------------- --------------------------- --------------------------- --------------------------- --------------------------- --------------------------- --------------------------- --------------------------- --------------------------- --------------------------- --------------------------- --------------------------- --------------------------- --------------------------- --------------------------- --------------------------- --------------------------- --------------------------- --------------------------- --------------------------- --------------------------- --------------------------- --------------------------- 
-----AAAAAAAAAAAAAAAAAAA--- -----AAAABAECACAFFCCAEEA--- --------------------------- --------------------------- --------------------------- --------------------------- --------------------------- --------------------------- --------------------------- --------------------------- --------------------------- --------------------------- --------------------------- --------------------------- --------------------------- --------------------------- --------------------------- --------------------------- --------------------------- --------------------------- --------------------------- --------------------------- --------------------------- --------------------------- --------------------------- --------------------------- --------------------------- 
----AAAAAAAAAAAAAAAAAAAAA-- ----AAAAA-AAAAAAACAGAEAAA-- ---------BBECAAAF---------- -------------CCC----------- -------------CAC----------- --------------------------- --------------------------- --------------------------- --------------------------- --------------------------- --------------------------- --------------------------- --------------------------- --------------------------- --------------------------- --------------------------- --------------------------- --------------------------- --------------------------- --------------------------- --------------------------- --------------------------- --------------------------- --------------------------- --------------------------- --------------------------- --------------------------- 
----AAAAAA-------AAAAAAAAA- ----AGGAAA-------A-AAEBBBB- --------A-AAA--AAAC-------- --------AAEBFAA-FC--------- --------AAEEBA--CC--------- ---------AAEBAAAC---------- -------------BA------------ --------------------------- --------------------------- --------------------------- --------------------------- --------------------------- --------------------------- --------------------------- --------------------------- --------------------------- --------------------------- --------------------------- --------------------------- --------------------------- --------------------------- --------------------------- --------------------------- --------------------------- --------------------------- --------------------------- --------------------------- 
---AAAAA-----------AAAAAAA- ---GGGGA----------A-BEBAAA- -------AAA-------A-B------- -------A-A----AAAAC-------- -------G-A----AAAAC-------- --------G-AAAA---AC-------- ---------AAEB--AGE--------- ----------AEBBAGG---------- -------------BB------------ --------------------------- --------------------------- --------------------------- --------------------------- --------------------------- --------------------------- --------------------------- --------------------------- --------------------------- --------------------------- --------------------------- --------------------------- --------------------------- --------------------------- --------------------------- --------------------------- --------------------------- --------------------------- 
--AAAAA------------AAAAAAA- --AGGGA------------A-EBDDD- ------DAA---------AAE------ ------D--A--------AE------- ------D--A--------AE------- -------D-AA-A-AAAAA-------- --------G--A-AA--AC-------- --------DA-------C--------- ---------AAEA--AE---------- ----------AEACBAE---------- -------------CB------------ --------------------------- --------------------------- --------------------------- --------------------------- --------------------------- --------------------------- --------------------------- --------------------------- --------------------------- --------------------------- --------------------------- --------------------------- --------------------------- --------------------------- --------------------------- --------------------------- 
--AAAAA-------------AAAAAA- --AGG-A-------------AEBAAA- -----AA-------------D------ ------AAA---------AAE------ ------A-A---------A-D------ ------A-A-AA------AB------- -------A-A--AA-DA-B-------- --------G-----D--AA-------- --------G--------C--------- ---------G-------C--------- ----------AEA--AC---------- ----------AEEBAE----------- ----------AAEBAE----------- -------------FA------------ --------------------------- --------------------------- --------------------------- --------------------------- --------------------------- --------------------------- --------------------------- --------------------------- --------------------------- --------------------------- --------------------------- --------------------------- --------------------------- 
--AAAAA--------------AAAAAA --AAA-A-------------AEBDDDD -----A-A------------D------ ------A-A---------AAG------ ------A-A----------AD------ ------A-A-------AAAD------- -------A-AAAA--D-A-B------- -------A-----AA---B-------- --------A----AA---B-------- --------G----AA--D--------- ---------G---AA--F--------- ---------G---AA-C---------- ---------G---AA-C---------- ----------DAEAAEC---------- ----------DAEFAC----------- ----------DAEFC------------ ----------AAEEC------------ ----------AAFEC------------ -----------AFEC------------ -------------EA------------ -------------AA------------ --------------A------------ --------------A------------ --------------A------------ --------------------------- --------------------------- --------------------------- 
-AAAAAA-------------AAAAAAA -DDD--A-------------A---AAA ----B--A------------G------ -----D-A----------AG------- -----D-A---------AD-G------ ------D-AA-------D--B------ ------A--A-----AD--A------- -------A--AAA--A---B------- -------A----A--A--A-------- --------A---A--A--B-------- --------A---A--A-B--------- ---------A--A--D-B--------- ---------A--A--D-B--------- ---------A--A--AB---------- ----------A-A--AF---------- ----------A-A--C----------- ----------D-A--C----------- ----------D-D--C----------- ------------E--C----------- ------------G--C----------- -------------D-F----------- -------------D-F----------- -------------A-F----------- -------------D-F----------- -------------A-A----------- -------------AAA----------- -------------AAA----------- 
-AAAAAA-------------AAAAAAA -DAA--A-------------A---AAA ----B--A----------A-AGBD--- -----D-A---------A-A------- -----D-A---------A--------- ------D-AA------B---G------ ------E--A-----A---G------- -------E--AAA--C---G------- -------E----A--C--B-------- --------E---A--C--B-------- --------E---A--C-B--------- ---------E--A--C-B--------- ---------E--A--A-B--------- ---------E--A--AD---------- ----------E-A--AD---------- ----------E-A--D----------- ----------E-A--D----------- ----------E-E--D----------- ------------E--D----------- ------------G--E----------- ---------------E----------- ---------------E----------- -------------G-D----------- ---------------D----------- -------------G-A----------- -------------A-A----------- ---------------A----------- 
-AAAAAA-------------AAAAAAA -AAF--A-------------A---AAF ----B--A----------A-AAGG--- -----B-A---------A-AG------ -----E-A---------B--------- ------E-AA------B---------- ------E--A-----A----------- -------E--AAA--A----------- -------D----A--A----------- --------A---A--A----------- --------D---A--A----------- ---------A--A--A-C--------- ---------D--A--C----------- ---------F--A--C----------- ----------F-A--C----------- ----------D-A-------------- ----------D-A-------------- ----------D-A-------------- -----------DA-------------- -----------DD--G----------- ---------------G----------- -------------A-G----------- -------------A------------- -------------A------------- -------------D-D----------- --------------------------- --------------------------- 
-AAAAAA-------------AAAAAAA -CCCC-A-------------A--FFFF -----EA----------AAA-FG---- -----E-AA--------F--F------ -----E--A--------F--C------ ------B-A------AF---C------ ------C--A-----F---C------- -------F--AAA--A----------- -------F----A--A--C-------- --------F---A--A----------- --------F---A--A----------- ---------F--A--A----------- ---------F--A--A----------- ---------F--A--B----------- ----------B-A--B----------- ----------B--A-B----------- ----------B--A-A----------- ----------FDGA-A----------- -------------G------------- -------------G------------- -------------BA------------ --------------A------------ -------------DA------------ -------------D------------- --------------------------- --------------------------- --------------------------- 
AAAAAAA-------------AAAAAAF CAAEE-A------------A---BAAA -----E-A-------A-AA--CB---- -----F--AAAAA--A-A--C------ -----C---AAAA--A-A--A------ ------B--AAAA-A-A---B------ -------B--AAAAA----A------- -------B-----AA---A-------- --------B----AA---A-------- --------B----AA--A--------- ---------B---AA--A--------- ---------B---AA-B---------- ---------B---AA-B---------- ----------B--AA-B---------- ----------BDCAAC----------- ----------AACABC----------- ----------ADCBCA----------- -------------GC------------ -------------BC------------ --------------C------------ --------------------------- --------------------------- --------------------------- --------------------------- --------------------------- --------------------------- --------------------------- 
-AAAAAA--A----------AAAAAAF -AAEA-A--A--------AA-BBBAAA -----A-A-A-------A--B------ -----A--A-AAA-AAA---A------ -----F------A-A-A---A------ ------A------A-----A------- -------A-----------A------- -------A----------A-------- --------A---------A-------- --------B--------B--------- ---------A------B---------- ----------FDC--CA---------- ----------FDC--CA---------- ----------AFCABC----------- -------------GB------------ --------------------------- --------------------------- --------------------------- --------------------------- --------------------------- --------------------------- --------------------------- --------------------------- --------------------------- --------------------------- --------------------------- --------------------------- 
-AAAAAAA--CAA------AAAAAAAF -AAAAA-A--AAA-----A--ABBAAA ------AA--AAAAA-AA--A------ ------A-AA---A-A---A------- ------A------A-----A------- -------A-----------A------- -------A----------A-------- --------F---------A-------- ---------F-------B--------- ---------FADC--CA---------- ----------BDCBBC----------- -------------CB------------ -------------BB------------ --------------------------- --------------------------- --------------------------- --------------------------- --------------------------- --------------------------- --------------------------- --------------------------- --------------------------- --------------------------- --------------------------- --------------------------- --------------------------- --------------------------- 
-AAAAAAAA---------AAAAACAC- -AAAAAA-A--------A--AACBAC- -------AA------AA--A------- -------C-AAAAAA----A------- -------F-----------A------- -------FF---------A-------- --------FA-------B--------- ---------FCCA--CAB--------- ----------BCDBBCA---------- -------------BB------------ --------------------------- --------------------------- --------------------------- --------------------------- --------------------------- --------------------------- --------------------------- --------------------------- --------------------------- --------------------------- --------------------------- --------------------------- --------------------------- --------------------------- --------------------------- --------------------------- --------------------------- 
--AAAAAAAAAAA----AAAAAAACC- --ABA-A--AAAA---A--AAACBAA- ------CC-AAAAAAA--A-------- --------C--------AA-------- --------C--------AA-------- ---------CADB---GB--------- ----------CDBBCCF---------- -------------BC------------ --------------------------- --------------------------- --------------------------- --------------------------- --------------------------- --------------------------- --------------------------- --------------------------- --------------------------- --------------------------- --------------------------- --------------------------- --------------------------- --------------------------- --------------------------- --------------------------- --------------------------- --------------------------- --------------------------- 
--AAAAAAAAAAAAAA-AAAAAAA--- --AAACAG-----AAAA-AAAAAB--- --------GDBBC---GB--------- ---------ADBACFFG---------- ---------BABBCCBG---------- -------------ACB----------- --------------------------- --------------------------- --------------------------- --------------------------- --------------------------- --------------------------- --------------------------- --------------------------- --------------------------- --------------------------- --------------------------- --------------------------- --------------------------- --------------------------- --------------------------- --------------------------- --------------------------- --------------------------- --------------------------- --------------------------- --------------------------- 
--AAAAAAAAAAA---AAAAAAAAC-- --AAAABBADBACAAABBBAAAABB-- -------------CFG----------- --------------------------- --------------------------- --------------------------- --------------------------- --------------------------- --------------------------- --------------------------- --------------------------- --------------------------- --------------------------- --------------------------- --------------------------- --------------------------- --------------------------- --------------------------- --------------------------- --------------------------- --------------------------- --------------------------- --------------------------- --------------------------- --------------------------- --------------------------- --------------------------- 
--AAAAAAAAAAAAAAAAAAAAA---- ---AAAFABBBACAFABBBBAAA---- --------------------------- --------------------------- --------------------------- --------------------------- --------------------------- --------------------------- --------------------------- --------------------------- --------------------------- --------------------------- --------------------------- --------------------------- --------------------------- --------------------------- --------------------------- --------------------------- --------------------------- --------------------------- --------------------------- --------------------------- --------------------------- --------------------------- --------------------------- --------------------------- --------------------------- 
----AAAAAAAAAAAAAAAAAAA---- ----AAFAADBBCAFAABCABBA---- --------------------------- --------------------------- --------------------------- --------------------------- --------------------------- --------------------------- --------------------------- --------------------------- --------------------------- --------------------------- --------------------------- --------------------------- --------------------------- --------------------------- --------------------------- --------------------------- --------------------------- --------------------------- --------------------------- --------------------------- --------------------------- --------------------------- --------------------------- --------------------------- --------------------------- 
-----AAAAAAAAAAAAAAAB------ -----AAADBACBBFAABCCB------ --------------------------- --------------------------- --------------------------- --------------------------- --------------------------- --------------------------- --------------------------- --------------------------- --------------------------- --------------------------- --------------------------- --------------------------- --------------------------- --------------------------- --------------------------- --------------------------- --------------------------- --------------------------- --------------------------- --------------------------- --------------------------- --------------------------- --------------------------- --------------------------- --------------------------- 
------AAAAAAAAAAAAAAB------ ------ADABAAABBAABBA------- --------------------------- --------------------------- --------------------------- --------------------------- --------------------------- --------------------------- --------------------------- --------------------------- --------------------------- --------------------------- --------------------------- --------------------------- --------------------------- --------------------------- --------------------------- --------------------------- --------------------------- --------------------------- --------------------------- --------------------------- --------------------------- --------------------------- --------------------------- --------------------------- --------------------------- 
-------AAAAAAAAAAA--------- -------ABBAAAABBAA--------- --------------------------- --------------------------- --------------------------- --------------------------- --------------------------- --------------------------- --------------------------- --------------------------- --------------------------- --------------------------- --------------------------- --------------------------- --------------------------- --------------------------- --------------------------- --------------------------- --------------------------- --------------------------- --------------------------- --------------------------- --------------------------- --------------------------- --------------------------- --------------------------- --------------------------- 
--------A-AAAAAAAA--------- ---------BAAAAFBA---------- --------------------------- --------------------------- --------------------------- --------------------------- --------------------------- --------------------------- --------------------------- --------------------------- --------------------------- --------------------------- --------------------------- --------------------------- --------------------------- --------------------------- --------------------------- --------------------------- --------------------------- --------------------------- --------------------------- --------------------------- --------------------------- --------------------------- --------------------------- --------------------------- --------------------------- 
-----------FFCCA----------- ------------A-C------------ --------------------------- --------------------------- --------------------------- --------------------------- --------------------------- --------------------------- --------------------------- --------------------------- --------------------------- --------------------------- --------------------------- --------------------------- --------------------------- --------------------------- --------------------------- --------------------------- --------------------------- --------------------------- --------------------------- --------------------------- --------------------------- --------------------------- --------------------------- --------------------------- --------------------------- 
