model
size = 22 32 23, scale = 0.05, origin = -y
material 
  colors = A:#3FF B:#6C0 C:#6C3 D:#6C6 E:#6C9 F:#6CC G:#9F0 H:#9CC I:#9CF J:#6CF K:#6F0 L:#6F3 M:#6F6 N:#6F9 O:#6FC P:#6FF Q:#3F9 R:#3FC S:#3F6 T:#3F0 U:#3F3 V:#3CC W:#3CF X:#39F Y:#396 Z:#399 Aa:#39C Ab:#C30
voxels
8-7G15-7I15-7H15-7P15-7O15-7N15-7M15-7L15-7K15-7J15-7F15-7E15-7D15-7C15-7B15-7A365-11G11-11I11-11H11-11P11-11O11-11N11-11M11-11L11-11K11-11J11-11F11-11E11-11D11-11C11-11B11-11A13-7R341-15G7-15I7-15H7-15P7-15O7-15N7-15M7-15L7-15K7-15J7-15F7-15E7-15D7-15C7-15B7-15A9-2R7-2R13-7Q318-17G5-17I5-17H5-17P5-17O5-17N5-17M5-17L5-17K5-17J5-17F5-17E5-17D5-17C5-17B5-17A7-R11-R10-3Q5-S2Q14-5S296-7G5-6G4-7I5-6I4-7H5-6H4-7P5-6P4-7O5-6O4-7N5-6N4-7M5-6M4-7L5-6L4-7K5-6K4-7J5-6J4-7F5-7F3-7E5-7E3-7D5-7D3-7C5-7C3-7B5-7B3-2(7A5-)R13-R8-2Q9-2Q11-2S5-2S15-5U274-5G9-4G4-5I9-4I4-5H9-4H4-5P9-4P4-5O9-4O4-5N9-4N4-5M9-4M4-5L9-4L4-5K9-4K4-5J9-4J4-5F9-5F3-5E9-5E3-5D9-5D3-5C9-5C3-5B9-5B3-5A9-5A4-R15-R6-Q13-Q8-2S9-2S11-2U5-2U15-5T251-5G11-3G-G-5I11-3I-I-5H11-3H-H-5P11-3P-P-5O11-3O-O-5N11-3N-N-5M11-3M-M-5L11-3L-L-5K11-3K-K-5J11-3J-J-5F11-5F-5E11-5E-5D11-5D-5C11-5C-5B11-5B-5A11-5A2-R17-R4-2Q13-2Q7-S11-S10-U9-U12-2T5-2T15-5W229-4G14-2(G-)4I14-2(I-)4H14-2(H-)4P14-2(P-)4O14-2(O-)4N14-2(N-)4M14-2(M-)4L14-2(L-)4K14-2(K-)4J14-2(J-)4F14-3F-4E14-3E-4D14-3D-4C13-4C-4B13-4B-4A13-4A2-R17-R4-Q15-Q6-S13-S8-U11-U10-2T7-2T13-W5-W16-5V206-5G17-5I17-5H17-5P17-5O17-5N17-5M17-5L17-5K17-5J17-5F17-5E17-5D17-5C13-C3-5B13-B3-5A13-A4-R19-R2-2Q15-2Q5-S13-S8-U11-U10-T9-T12-W7-W14-2V3-2V17-3Y185-4G18-4I18-4H18-4P18-4O18-4N18-4M18-4L18-4K18-4J18-4F18-4E18-4D18-4C18-4B18-4A2(19-R)2-Q17-Q4-S15-S6-U13-U8-T11-T10-W9-W12-2V5-2V15-Y3-Y18-3Z163-4G18-4I18-4H18-4P18-4O18-4N18-4M18-4L18-4K18-4J18-4F18-4E18-4D18-4C18-4B18-4A2(19-R)2-Q17-Q4-S15-S6-U13-U8-T11-T10-W9-W12-V7-V14-Y5-Y16-Z3-Z18-3Aa86-X20-X-X20-X10-4G18-4I18-4H18-4P18-4O18-4N18-4M18-4L18-4K18-4J18-4F18-4E18-4D18-4C18-4B7-X10-4A7-AbG10-R19-R2-Q17-Q4-S15-S6-U13-U8-T11-T10-W9-W12-V7-V14-Y5-Y16-Z3-Z18-Aa-Aa20-4(X21-)X20-3X9-4G18-4I18-4H18-4P18-4O18-4N18-4M18-4L18-4K18-4J18-4F18-4E18-4D18-4C18-4B18-4A2(19-R)2-Q17-Q4-S15-S6-U13-U8-T11-T10-W9-W12-V7-V14-Y5-Y16-Z3-Z18-3Aa86-X20-X-X20-X10-4G18-4I18-4H18-4P18-4O18-4N18-4M18-4L18-4K18-4J18-4F18-4E18-4D18-4C18-4B18-4A2(19-R)2-Q17-Q4-S15-S6-U13-U8-T11-T10-W9-W12-2V5-2V15-Y3-Y18-3Z163-5G17-5I17-5H17-5P17-5O17-5N17-5M17-5L17-5K17-5J17-5F17-5E17-5D17-5C13-C3-5B13-B3-5A13-A4-R19-R2-2Q15-2Q5-S13-S8-U11-U10-T9-T12-W7-W14-2V3-2V17-3Y186-4G18-4I18-4H18-4P18-4O18-4N18-4M18-4L18-4K18-4J18-4F18-4E18-4D18-4C18-4B13-B4-4A13-A5-R17-R4-Q15-Q6-S13-S8-U11-U10-2T7-2T13-W5-W16-5V207-5G17-5I17-5H17-5P17-5O17-5N17-5M17-5L17-5K17-5J17-5F17-5E17-5D17-5C17-5B11-B5-5A11-A6-R17-R4-QAb13-2Q7-S11-S10-U9-U12-2T5-2T15-5W230-5G17-5I17-5H17-5P17-5O17-5N17-5M17-5L17-5K17-5J17-5F17-5E17-5D17-5C9-C7-5B9-2B6-5A9-2A7-R15-R6-Q13-Q8-2S9-2S11-2U5-2U15-5T252-5G-G9-2G4-5I-I9-2I4-5H-H9-2H4-5P-P9-2P4-5O-O9-2O4-5N-N9-2N4-5M-M9-2M4-5L-L9-2L4-5K-K9-2K4-5J-J9-2J4-5F-F9-3F3-5E-E8-4E3-5D-D8-4D3-5C-C5-2C-4C3-5B-B5-2B-4B3-5A-A5-2A-4A5-R13-R8-2Q9-2Q11-2S5-2S15-5U275-6G4-G-5G5-6I4-I-5I5-6H4-H-5H5-6P4-P-5P5-6O4-O-5O5-6N4-N-5N5-6M4-M-5M5-6L4-L-5L5-6K4-K-5K5-6J4-J-5J5-6F4-F-5F5-6E4-E-5E5-6D4-D-5D5-6C4-C-5C5-6B4-B-5B5-6A4-A-5A7-R11-R10-3Q5-3Q14-5S298-15G7-15I7-15H7-15P7-15O7-15N7-15M7-15L7-15K7-15J7-15F7-15E7-15D7-15C7-15B7-15A9-2R7-2R13-7Q321-11G11-11I11-11H11-11P11-11O11-11N11-11M11-11L11-11K11-11J11-11F11-11E11-11D11-11C11-11B11-11A13-7R345-7G15-7I15-7H15-7P15-7O15-7N15-7M15-7L15-7K15-7J15-7F15-7E15-7D15-7C15-7B15-7A359-
