model
size = 31 7 31, scale = 0.05, origin = -y
material 
  colors = A:#111 B:#888 C:#444
voxels
------------------------------- ------------------------------- ------------------------------- -----------------CCC----------- ------------------------------- ------------------------------- ------------------------------- 
-----------CCCCCCCCC----------- -----------CAAAAAAAC----------- -------B-B-CAAAAAAAC-B--------- -----------CAAACCCCC----------- -------B-B-CAAAAAAAC-B--------- -----------CAAAAAAAC----------- -----------CCCCCCCCC----------- 
------------------------------- ------AAAAAAAAAAAAAAAA--------- -----BAAAAAAAAAAAAAAAA-B------- ------AAAAAAAAAAAAAAAA--------- -----BAAAAAAAAAAAAAAAA-B------- ------AAAAAAAAAAAAAAAA--------- ------------------------------- 
------------------------------- -----A-AAAAAAAAAAAAAAAAA------- -----A-AAAAAAAAAAAAAAAAA------- -----A-AAAAAAAAAAAAAAAAA------- -----A-AAAAAAAAAAAAAAAAA------- -----A-AAAAAAAAAAAAAAAAA------- ------------------------------- 
------------------------------- ----A-A----------------AA------ ---AABA----------------AAB----- ---AA-A----------------AA------ ---AABA----------------AAB----- ----A-A----------------AA------ ------------------------------- 
------------------------------- -----AA-----------------AA----- -----AA-----------------AA----- -----AA-----------------AA----- -----AA-----------------AA----- -----AA-----------------AA----- ------------------------------- 
------------------------------- ----AA-------------------AA---- ---BAA-------------------AAB--- ----AA-------------------AA---- ---BAA-------------------AAB--- ----AA-------------------AA---- ------------------------------- 
------------------------------- ---AA---------------------AA--- ---AA---------------------AA--- ---AA---------------------AA--- ---AA---------------------AA--- ---AA---------------------AA--- ------------------------------- 
------------------------------- ---A-----------------------A--- --BA-----------------------AB-- ---A-----------------------A--- --BA-----------------------AB-- ---A-----------------------A--- ------------------------------- 
------------------------------- --AA-----------------------AA-- --AA-----------------------AA-- --AA-----------------------AA-- --AA-----------------------AA-- --AA-----------------------AA-- ------------------------------- 
------------------------------- --A-------------------------A-- -BA-------------------------AB- --A-------------------------A-- -BA-------------------------AB- --A-------------------------A-- ------------------------------- 
------------------------------- --A-------------------------A-- --A-------------------------A-- --A-------------------------A-- --A-------------------------A-- --A-------------------------A-- ------------------------------- 
------------------------------- -AA-------------------------AA- BAA-------------------------AAB -AA-------------------------AA- BAA-------------------------AAB -AA-------------------------AA- ------------------------------- 
------------------------------- -A---------------------------A- -A---------------------------A- -A---------------------------A- -A---------------------------A- -A---------------------------A- ------------------------------- 
------------------------------- -A---------------------------A- BA---------------------------AB -A---------------------------A- BA---------------------------AB -A---------------------------A- ------------------------------- 
------------------------------- -A---------------------------A- -A---------------------------A- -A---------------------------A- -A---------------------------A- -A---------------------------A- ------------------------------- 
------------------------------- -A---------------------------A- BA---------------------------AB -A---------------------------A- BA---------------------------AB -A---------------------------A- ------------------------------- 
------------------------------- -A---------------------------A- -A---------------------------A- -A---------------------------A- -A---------------------------A- -A---------------------------A- ------------------------------- 
------------------------------- -AA-------------------------AA- BAA-------------------------AAB -AA-------------------------AA- BAA-------------------------AAB -AA-------------------------AA- ------------------------------- 
------------------------------- --A-------------------------A-- --A-------------------------A-- --A-------------------------A-- --A-------------------------A-- --A-------------------------A-- ------------------------------- 
------------------------------- --A-------------------------A-- -BA-------------------------AB- --A-------------------------A-- -BA-------------------------AB- --A-------------------------A-- ------------------------------- 
------------------------------- --AA-----------------------AA-- --AA-----------------------AA-- --AA-----------------------AA-- --AA-----------------------AA-- --AA-----------------------AA-- ------------------------------- 
------------------------------- ---A-----------------------A--- --BA-----------------------AB-- ---A-----------------------A--- --BA-----------------------AB-- ---A-----------------------A--- ------------------------------- 
------------------------------- ---AA---------------------AA--- ---AA---------------------AA--- ---AA---------------------AA--- ---AA---------------------AA--- ---AA---------------------AA--- ------------------------------- 
------------------------------- ----AA-------------------AA---- ---BAA-------------------AAB--- ----AA-------------------AA---- ---BAA-------------------AAB--- ----AA-------------------AA---- ------------------------------- 
------------------------------- -----AA-----------------AA----- -----AA-----------------AA----- -----AA-----------------AA----- -----AA-----------------AA----- -----AA-----------------AA----- ------------------------------- 
------------------------------- ------AA---------------AA------ -----BAA---------------AAB----- ------AA---------------AA------ -----BAA---------------AAB----- ------AA---------------AA------ ------------------------------- 
------------------------------- -------AAA-----------AAA------- -------AAA-----------AAA------- -------AAA-----------AAA------- -------AAA-----------AAA------- -------AAA-----------AAA------- ------------------------------- 
------------------------------- ---------AAAA-----AAAA--------- -------B-AAAA-----AAAA-B------- ---------AAAA-----AAAA--------- -------B-AAAA-----AAAA-B------- ---------AAAA-----AAAA--------- ------------------------------- 
------------------------------- ------------AAAAAAA------------ ---------B-BAAAAAAAB-B--------- ------------AAAAAAA------------ ---------B-BAAAAAAAB-B--------- ------------AAAAAAA------------ ------------------------------- 
------------------------------- ------------------------------- -------------B-B-B------------- ------------------------------- -------------B-B-B------------- ------------------------------- ------------------------------- 
