model
size = 29 7 30, scale = 0.05, origin = -y
material 
  colors = A:#963 B:#444
voxels
----------------------------- ----------------------------- ----------------------------- ----------------BBB---------- ----------------------------- ----------------------------- ----------------------------- 
----------BBBBBBBBB---------- ----------BAAAAAAAB---------- ----------BAAAAAAAB---------- ----------BAAABBBBB---------- ----------BAAAAAAAB---------- ----------BAAAAAAAB---------- ----------BBBBBBBBB---------- 
----------------------------- -----AAAAAAAAAAAAAAAA-------- -----AAAAAAAAAAAAAAAA-------- -----AAAAAAAAAAAAAAAA-------- -----AAAAAAAAAAAAAAAA-------- -----AAAAAAAAAAAAAAAA-------- ----------------------------- 
----------------------------- ----A-AAAAAAAAAAAAAAAAA------ ----A-AAAAAAAAAAAAAAAAA------ ----A-AAAAAAAAAAAAAAAAA------ ----A-AAAAAAAAAAAAAAAAA------ ----A-AAAAAAAAAAAAAAAAA------ ----------------------------- 
----------------------------- ---A-A----------------AA----- --AABA----------------AA----- --AA-A----------------AA----- --AABA----------------AA----- ---A-A----------------AA----- ----------------------------- 
----------------------------- ----AA-----------------AA---- ----AA-----------------AA---- ----AA-----------------AA---- ----AA-----------------AA---- ----AA-----------------AA---- ----------------------------- 
----------------------------- ---AA-------------------AA--- ---AA-------------------AA--- ---AA-------------------AA--- ---AA-------------------AA--- ---AA-------------------AA--- ----------------------------- 
----------------------------- --AA---------------------AA-- --AA---------------------AA-- --AA---------------------AA-- --AA---------------------AA-- --AA---------------------AA-- ----------------------------- 
----------------------------- --A-----------------------A-- --A-----------------------A-- --A-----------------------A-- --A-----------------------A-- --A-----------------------A-- ----------------------------- 
----------------------------- -AA-----------------------AA- -AA-----------------------AA- -AA-----------------------AA- -AA-----------------------AA- -AA-----------------------AA- ----------------------------- 
----------------------------- -A-------------------------A- -A-------------------------A- -A-------------------------A- -A-------------------------A- -A-------------------------A- ----------------------------- 
----------------------------- -A-------------------------A- -A-------------------------A- -A-------------------------A- -A-------------------------A- -A-------------------------A- ----------------------------- 
----------------------------- AA-------------------------AA AA-------------------------AA AA-------------------------AA AA-------------------------AA AA-------------------------AA ----------------------------- 
----------------------------- A---------------------------A A---------------------------A A---------------------------A A---------------------------A A---------------------------A ----------------------------- 
----------------------------- A---------------------------A A---------------------------A A---------------------------A A---------------------------A A---------------------------A ----------------------------- 
----------------------------- A---------------------------A A---------------------------A A---------------------------A A---------------------------A A---------------------------A ----------------------------- 
----------------------------- A---------------------------A A---------------------------A A---------------------------A A---------------------------A A---------------------------A ----------------------------- 
----------------------------- A---------------------------A A---------------------------A A---------------------------A A---------------------------A A---------------------------A ----------------------------- 
----------------------------- AA-------------------------AA AA-------------------------AA AA-------------------------AA AA-------------------------AA AA-------------------------AA ----------------------------- 
----------------------------- -A-------------------------A- -A-------------------------A- -A-------------------------A- -A-------------------------A- -A-------------------------A- ----------------------------- 
----------------------------- -A-------------------------A- -A-------------------------A- -A-------------------------A- -A-------------------------A- -A-------------------------A- ----------------------------- 
----------------------------- -AA-----------------------AA- -AA-----------------------AA- -AA-----------------------AA- -AA-----------------------AA- -AA-----------------------AA- ----------------------------- 
----------------------------- --A-----------------------A-- --A-----------------------A-- --A-----------------------A-- --A-----------------------A-- --A-----------------------A-- ----------------------------- 
----------------------------- --AA---------------------AA-- --AA---------------------AA-- --AA---------------------AA-- --AA---------------------AA-- --AA---------------------AA-- ----------------------------- 
----------------------------- ---AA-------------------AA--- ---AA-------------------AA--- ---AA-------------------AA--- ---AA-------------------AA--- ---AA-------------------AA--- ----------------------------- 
----------------------------- ----AA-----------------AA---- ----AA-----------------AA---- ----AA-----------------AA---- ----AA-----------------AA---- ----AA-----------------AA---- ----------------------------- 
----------------------------- -----AA---------------AA----- -----AA---------------AA----- -----AA---------------AA----- -----AA---------------AA----- -----AA---------------AA----- ----------------------------- 
----------------------------- ------AAA-----------AAA------ ------AAA-----------AAA------ ------AAA-----------AAA------ ------AAA-----------AAA------ ------AAA-----------AAA------ ----------------------------- 
----------------------------- --------AAAA-----AAAA-------- --------AAAA-----AAAA-------- --------AAAA-----AAAA-------- --------AAAA-----AAAA-------- --------AAAA-----AAAA-------- ----------------------------- 
----------------------------- -----------AAAAAAA----------- -----------AAAAAAA----------- -----------AAAAAAA----------- -----------AAAAAAA----------- -----------AAAAAAA----------- ----------------------------- 
