model
size = 20 10 10, scale = 0.05, origin = -y
material 
  colors = A:#111 B:#967249 C:#78552B D:#CA7A2C E:#F05E1C F:#AF5F3C
voxels
--------BBBB-------- --------CCCC-------- -------------------- -------------------- -------------------- -------------------- -------------------- -------------------- -------------------- -------------------- 
-------B----B------- -------CCCCCC------- --------BBBB-------- -------------------- -------------------- -------------------- -------------------- -------------------- -------------------- -------------------- 
------B------B------ ------C------C------ -------B----B------- --------DDDD-------- -------------------- -------------------- -------------------- -------------------- -------------------- -------------------- 
-----B--------B----- -----CC------CC----- ------B------B------ -------D----D------- --------EEEE-------- -------------------- -------------------- ---------AA--------- -------------------- -------------------- 
-----B--------B----- -----CC------CC----- ------B------B------ -------D----D------- --------E--E-------- ---------FF--------- -------------------- ---------AA--------- ---------AA--------- ---AAA--------AAA--- 
-----B--------B----- -----CC------CC----- ------B------B------ -------D----D------- --------E--E-------- ---------FF--------- ---------AA--------- ---------AA--------- --AAAAA------AAAAA-- -------------------- 
-----B--------B----- -----CC------CC----- ------B------B------ -------D----D------- --------EEEE-------- ---------AA--------- -------AAAAAA------- -AAAAAAA----AAAAAAA- -------------------- -------------------- 
------B------B------ ------C------C------ -------B----B------- --------DDDD-------- ---------AA--------- -------AAAAAA------- AAA--AAA-AA-AAA--AAA -------------------- -------------------- -------------------- 
-------B----B------- -------CCCCCC------- --------BBBB-------- ---------AA--------- ---------AA--------- ---------AA--------- -------------------- -------------------- -------------------- -------------------- 
--------BBBB-------- --------CCCC-------- -------------------- ---------AA--------- -------------------- -------------------- -------------------- -------------------- -------------------- -------------------- 
