model
size = 23 16 22, scale = 0.05, origin = -y
material 
  colors = A:#9CF B:#555 C:#EEE D:#888 E:#444 F:#BBB G:#9CC H:#DDD I:#777 J:#AAA
voxels
-AAAAAAAAAAAAAAAAAAAA-- -AAAAAAAAAAAAAAAAAAAA-- ----------------------- ----------------------- ----------------------- ----------------------- ----------------------- ----------------------- ----------------------- ----------------------- ----------------------- ----------------------- ----------------------- ----------------------- ----------------------- ----------------------- 
AAAAAAAAAAAAAAAAAAAAAA- AAAAAAAAAAAAAAAAAAAAAA- ----------------------- ----------------------- ----------------------- ----------------------- ----------------------- ----------------------- ----------------------- ----------------------- ----------------------- ----------------------- ----------------------- ----------------------- ----------------------- ----------------------- 
AA------------------AA- AA------------------AA- --AAAAAAAAAAAAAAAAAA--- --AAAAAAAAAAAAGAAAAA--- --AAAAAAAAAAAGAGAAAA--- --AAAAAAAAAAAAGAAAAA--- --AAAAAAAAAAAAAAAAAA--- --AAAAAAAAAAAAAAAAAA--- --AAAAAAAAAAAAAAAAAA--- ----------------------- ----------------------- ----------------------- ----------------------- ----------------------- ----------------------- ----------------------- 
AA------------------AA- AA------------------AA- --A----------------A--- --A----------------A--- --A----------------A--- --A----------------A--- --A----------------A--- --AAAAAAAAAAAAAAAAAA--- --AAAAAAAAAAAAAAAAAA--- ----------------------- ----------------------- ----------------------- ----------------------- ----------------------- ----------------------- ----------------------- 
AA------------------AA- AA------------------AA- --A----------------A--- --A----------------A--- --A----------------A--- --A----------------A--- --A----------------A--- --AAAAAAAAAAAAAAAAAA--- --AAAAAAAAAAAAAAAAAA--- ----------------------- ----------------------- ----------------------- ----------------------- ----------------------- ----------------------- ----------------------- 
AA------------------AA- AA------------------AA- --A----------------A--- --A----------------A--- --G----------------A--- --A----------------A--- --A----------------A--- --AAAAAAAAAAAAAAAAAA--- --AAAAAAAAAAAAAAAAAA--- ----------------------- ----------------------- ----------------------- ----------------------- ----------------------- ----------------------- ----------------------- 
AA------------------AA- AA------------------AA- --A----------------A-F- --G----------------A--- --A----------------A--- --G----------------A--- --A----------------A--- --AAAAAAAAAAAAAAAAAA--- --AAAAAAAAAAAAAAAAAA--- ----------------------- ----------------------- ----------------------- ----------------------- ----------------------- ----------------------- ----------------------- 
AA------------------AA- AA------------------AA- --A----------------A--- --A----------------A-F- --G----------------A--- --A----------------A--- --A----------------A-B- --AAAAAAAAAAAAAAAAAA-B- --AAAAAAAAAAAAAAAAAA--- ----------------------- ----------------------- ----------------------- ----------------------- ----------------------- ----------------------- ----------------------- 
AA------------------AA- AA------------------AA- --A----------------A--- --A----------------A--- --A----------------A-F- --A----------------A-F- --A----------------A-B- --AAAAAAAAAAAAAAAAAA--H --AAAAAAAAAAAAAAAAAA--H ----------------------- ----------------------- ----------------------- ----------------------- ----------------------- ----------------------- ----------------------- 
AA------------------AA- AA------------------AA- --A----------------A--- --A----------------A-B- --A----------------A-B- --A----------------A-H- --A----------------A-F- --AAAAAAAAAAAAAAAAAA-HH --AAAAAAAAAAAAAAAAAA--B ----------------------B ----------------------- ----------------------- ----------------------- ----------------------- ----------------------- ----------------------- 
AA------------------AA- AA------------------AA- --A----------------A--- --A----------------A--- --A----------------A-B- --A----------------A-H- --A----------------A-H- --AAAAAAAAAAAAAAAAAA--F --AAAAAAAAAAAAAAAAAA--B ----------------------B ----------------------B ----------------------- ----------------------- ----------------------- ----------------------- ----------------------- 
AA------------------AA- AA------------------AA- --A----------------A--- --A----------------A--- --A----------------A--- --A----------------A--- --A----------------A--B --AAAAAAAAAAAAAAAAAA--B --AAAAAAAAAAAAAAAAAA--F ----------------------D ----------------------D ----------------------D ----------------------D ----------------------- ----------------------- ----------------------- 
AA------------------AA- AA------------------AA- --A----------------A--- --A----------------A--- --A----------------A--- --A----------------A--- --A----------------A--B --AAAAAAAAAAAAAAAAAA--B --AAAAAAAAAAAAAAAAAA--D ----------------------F ----------------------C ----------------------C ----------------------C ----------------------C ----------------------- ----------------------- 
AA------------------AA- AA------------------AA- --A----------------A--- --A----------------A--- --A----------------A--- --A----------------A--- --A----------------A--- --AAAAAAAAAAAAAAAAAA--B --AAAAAAAAAAAAAAAAAA--D ----------------------C ----------------------F ----------------------C ----------------------C ----------------------C ----------------------C ----------------------- 
AA------------------AA- AA------------------AA- --A----------------A--- --A----------------A--- --A----------------A--- --A----------------A--- --A----------------A--- --AAAAAAAAAAAAAAAAAA--- --AAAAAAAAAAAAAAAAAA--D ----------------------C ----------------------C ----------------------F ----------------------E ----------------------E ----------------------E ----------------------E 
AA------------------AA- AA------------------AA- --A----------------A--- --A----------------A--- --A----------------A--- --A----------------A--- --A----------------A--- --AAAAAAAAAAAAAAAAAA--- --AAAAAAAAAAAAAAAAAA--D ----------------------C ----------------------C ----------------------E ----------------------E ----------------------E ----------------------B ----------------------I 
AA------------------AA- AA------------------AA- --A----------------A--- --A----------------A--- --A----------------A--- --A----------------A--- --A----------------A--- --AAAAAAAAAAAAAAAAAA--- --AAAAAAAAAAAAAAAAAA--- ----------------------C ----------------------C ----------------------E ----------------------E ----------------------B ----------------------I ----------------------D 
AA------------------AA- AA------------------AA- --A----------------A--- --A----------------A--- --A----------------A--- --A----------------A--- --A----------------A--- --AAAAAAAAAAAAAAAAAA--- --AAAAAAAAAAAAAAAAAA--- ----------------------- ----------------------C ----------------------E ----------------------B ----------------------I ----------------------D ----------------------J 
AA------------------AA- AA------------------AA- --A----------------A--- --A----------------A--- --A----------------A--- --A----------------A--- --A----------------A--- --AAAAAAAAAAAAAAAAAA--- --AAAAAAAAAAAAAAAAAA--- ----------------------- ----------------------- ----------------------E ----------------------I ----------------------D ----------------------J ----------------------C 
AA------------------AA- AA------------------AA- --AAAAAAAAAAAAAAAAAA--- --AAAAAAAAAAAAAAAAAA--- --AAAAAAAAAAAAAAAAAA--- --AAAAAAAAAAAAAAAAAA--- --AAAAAAAAAAAAAAAAAA--- --AAAAAAAAAAAAAAAAAA--- --AAAAAAAAAAAAAAAAAA--- ----------------------- ----------------------- ----------------------- ----------------------- ----------------------- ----------------------- ----------------------- 
AAAAAAAAAAAAAAAAAAAAAA- AAAAAAAAAAAAAAAAAAAAAA- ----------------------- ----------------------- ----------------------- ----------------------- ----------------------- ----------------------- ----------------------- ----------------------- ----------------------- ----------------------- ----------------------- ----------------------- ----------------------- ----------------------- 
-AAAAAAAAAAAAAAAAAAAA-- -AAAAAAAAAAAAAAAAAAAA-- ----------------------- ----------------------- ----------------------- ----------------------- ----------------------- ----------------------- ----------------------- ----------------------- ----------------------- ----------------------- ----------------------- ----------------------- ----------------------- ----------------------- 
