model
size = 22 32 32, scale = 0.05, origin = -y
material 
  colors = A:#AAA B:#FC3 C:#FC0 D:#010 E:#777 F:#F60 G:#888
voxels
269-2AEA2CACAE2A10-4ACA2C4A10-E2AE2CACE2AE10-2AEACA2CAE2A10-A2EA2CACA2EA10-4ACA2C4A10-E2AE2CACE2AE10-2AEACA2CAE2A472-2AEACA2CAE2A10-E3A2CAC3AE10-4ACA2C8(4A10-4A4C)4A10-AE2A2CAC2AEA10-4ACA2C4A10-2AEA2CACAE2A362-AE2ACA2C2AEA10-4A2CAC2(4A10-4A4C)4A10-2AEA4CAE2A10-E3A4C3AE10-AE2A4C2AEA10-4A4C4A10-3AE4CE3A10-AE2A4C2AEA10-2(EA)4C2(AE)5(10-4A4C4A)10-E3ACA2C3AE10-2AEA2CACAE2A78-8A14-8A188-4A2CAC2(4A10-4A4C)4A10-2AEA4CAE2A10-AE2A4C2AEA186-6(4A4C4A10-)AE2ACA2C2AEA54-2A8B2A10-2A8B2A12-8B144-2(EA)CA2C2(AE)2(10-4A4C4A)10-AE2A4C2AEA274-E3A4C3AE10-2AEA4CAE2A3(10-4A4C4A)10-2AEA2CACAE2A31-A12BA8-A12BA9-12B12-8A100-AE2A2CAC2AEA10-4A4C4A10-3EA4CA3E362-2(AE2A4C2AEA10-)2(4A4C4A10-)E3ACA2C3AE8-A14BA6-A4B6C4BA7-4B6-4B9-3A6-3A76-3AECA2CE3A2(10-4A4C4A)406-AE2A4C2AEA3(10-4A4C4A)7-A16BA4-A3B2C6B2C3BA5-3B2-2D2B2D2-3B7-2A4-2G4-2A53-AE2A2CAC2AEA10-4A4C4A10-AE2A4C2AEA450-2AEA4CAE2A2(10-4A4C4A)7-18B4-3BC10BC3B4-3B-10D-3B5-2A12-2A52-4A4C4A10-4A4C4A494-4A4C4A10-4A4C4A6-A18BA2-A2BC12BC2BA3-2B-12D-2B5-A14-A30-5CA6C2(10-12C)494-AE2A4C2AEA10-2(4A4C4A6-A18BA2-A2BC12BC2BA3-2B-12D-2B5-A14-A30-12C10-12C538-)AE2A4C2AEA5-A20B2A3BC12BC3BA-3B-DA10D-3B3-2A14-2A7-12C10-12C561-12B4-A20B2A2BC14BC2BA-2B-3DA10D-2B3-A16-A7-6C2F4C10-12C561-12B4-A20B2A2BC14BC2BA-2B-4DA9D-2B3-A16-A7-6C2F4C10-12C561-12B4-A20B2A2BC14BC2BA-2B-5DA8D-2B3-A16-A7-5CF2CF3C10-12C561-12B4-A20B2A2BC14BC2BA-2B-B5D2G5DB-2B3-A-G5-2A5-G-A7-3C2F4C2FC10-12C561-12B4-A20B2A2BC14BC2BA-2B-B5D2G2A3DB-2B3-A-G5-2A5-G-A7-3C2F4C2FC10-12C561-12B4-A20B2A2BC14BC2BA-2B-8D3A3D-2B3-A16-A7-9C2BC10-12C561-12B4-A20B2A2BC14BC2BA-2B-9D3A2D-2B3-A16-A7-12C10-12C561-12B4-A20B2A2BC14BC2BA-2B-10D2A2D-2B3-A16-A29-12C10-12C538-AE2A4C2AEA5-A20B2A3BC12BC3BA-3B-12D-3B3-2A14-2A29-12C10-12C538-4A4C4A6-A18BA2-A2BC12BC2BA3-2B-12D-2B5-A14-A30-5CA6C2(10-12C)494-AE2A4C2AEA10-4A4C4A6-A18BA2-A2BC12BC2BA3-2B-12D-2B5-A14-A52-4A4C4A10-4A4C4A494-4A4C4A10-4A4C4A6-A18BA2-A2BC12BC2BA3-2B-12D-2B5-A14-A52-AE2A2CAC2AEA10-4A4C4A10-AE2A4C2AEA450-2AEA4CAE2A2(10-4A4C4A)7-18B4-3BC10BC3B4-3B-10D-3B5-2A12-2A74-3AECA2CE3A2(10-4A4C4A)406-AE2A4C2AEA3(10-4A4C4A)7-A16BA4-A3B2C6B2C3BA5-3B2-2D2B2D2-3B7-2A4-2G4-2A97-AE2A2CAC2AEA10-4A4C4A10-3EA4CA3E362-2(AE2A4C2AEA10-)2(4A4C4A10-)E3ACA2C3AE8-A14BA6-A4B6C4BA7-4B6-4B9-3A6-3A120-2(EA)CA2C2(AE)2(10-4A4C4A)10-AE2A4C2AEA274-E3A4C3AE10-2AEA4CAE2A3(10-4A4C4A)10-2AEA2CACAE2A31-A12BA8-A12BA9-12B12-8A144-4A2CAC2(4A10-4A4C)4A10-2AEA4CAE2A10-AE2A4C2AEA186-6(4A4C4A10-)AE2ACA2C2AEA54-2A8B2A10-2A8B2A12-8B188-AE2ACA2C2AEA10-4A2CAC2(4A10-4A4C)4A10-2AEA4CAE2A10-E3A4C3AE10-AE2A4C2AEA10-4A4C4A10-3AE4CE3A10-AE2A4C2AEA10-2(EA)4C2(AE)5(10-4A4C4A)10-E3ACA2C3AE10-2AEA2CACAE2A78-8A14-8A254-2AEACA2CAE2A10-E3A2CAC3AE10-4ACA2C8(4A10-4A4C)4A10-AE2A2CAC2AEA10-4ACA2C4A10-2AEA2CACAE2A472-2AEA2CACAE2A10-4ACA2C4A10-E2AE2CACE2AE10-2AEACA2CAE2A10-A2EA2CACA2EA10-4ACA2C4A10-E2AE2CACE2AE10-2AEACA2CAE2A269-
