model
size = 30 21 30, scale = 0.05, origin = -y
material 
  colors = A:#555 B:#777
voxels
------------------------------ ------------------------------ ------------------------------ ------------------------------ ------------------------------ ------------------------------ ------------------------------ ------------------------------ ------------------------------ ------------------------------ ------------------------------ ------------------------------ ------------------------------ ------------------------------ ------------------------------ ------------------------------ ------------------------------ ------------------------------ -----------BB----BB----------- -----------BB----BB----------- ------------------------------ 
------------------------------ ------------------------------ ------------------------------ ------------------------------ ------------------------------ ------------------------------ ------------------------------ ------------------------------ ------------------------------ ------------------------------ ------------------------------ ------------------------------ ------------------------------ ------------------------------ ------------------------------ ------------------------------ ------------------------------ ------------------------------ -----------BB----BB----------- -----------BB----BB----------- ------------------------------ 
------------------------------ ------------------------------ ------------------------------ ------------------------------ ------------------------------ ------------------------------ ------------------------------ ------------------------------ ------------------------------ ------------------------------ ------------------------------ ------------------------------ ------------------------------ ------------------------------ ------------------------------ ------------------------------ ------------AAAAAAA----------- ------------AAAAAAA----------- -----------BAAAAAAA----------- -----------BAAAAAAA----------- ------------AAAAAAA----------- 
------------------------------ ------------------------------ ------------------------------ ------------------------------ ------------------------------ ------------------------------ ------------------------------ ------------------------------ ------------------------------ ------------------------------ ------------------------------ ------------------------------ ------------------------------ ------------------------------ ------------------------------ ------------------------------ ----------AAAAAAAAAAA--------- ----------AAAAAAAAAAA--------- ----------AAAAAAAAAAA--------- ----------AAAAAAAAAAA--------- ----------AAAAAAAAAAA--------- 
------------------------------ ------------BB--BB------------ ------------BB--BB------------ ------------------------------ ------------------------------ ------------------------------ ------------------------------ ------------------------------ ------------------------------ ------------------------------ ------------------------------ ------------------------------ ------------------------------ ------------------------------ ------------------------------ ------------------------------ --------AAAAAAAAAAAAAAA------- --------AAAAAAAAAAAAAAA------- --------AAAAAAAAAAAAAAABB----- --------AAAAAAAAAAAAAAABB----- --------AAAAAAAAAAAAAAA------- 
------------AAAAAAA----------- ------------AAAAAAA----------- ------------AAAAAAA----------- ------------AAAAAAA----------- ------------------------------ ------------------------------ ------------------------------ ------------------------------ ------------AAAAAAA----------- ------------AAAAAAA----------- ------------AAAAAAA----------- ------------AAAAAAA----------- ------------AAAAAAA----------- ------------AAAAAAA----------- ------------AAAAAAA----------- ------------AAAAAAA----------- -------AAAAAAAAAAAAAAAAA------ -------AAAAAAAAAAAAAAAAA------ -----BBAAAAAAAAAAAAAAAAAB----- -----BBAAAAAAAAAAAAAAAAAB----- -------AAAAAAAAAAAAAAAAA------ 
-----------AAAAAAAAA---------- -----------AAAAAAAAA---------- -----------AAAAAAAAA---------- -----------AAAAAAAAA---------- ------------------------------ ------------------------------ ------------------------------ ------------------------------ -----------AAAAAAAAA---------- -----------AAAAAAAAA---------- -----------AAAAAAAAA---------- -----------AAAAAAAAA---------- -----------AAAAAAAAA---------- -----------AAAAAAAAA---------- -----------AAAAAAAAA---------- -----------AAAAAAAAA---------- ------AAAAAAAAAAAAAAAAAAA----- ------AAAAAAAAAAAAAAAAAAA----- -----BAAAAAAAAAAAAAAAAAAA----- -----BAAAAAAAAAAAAAAAAAAA----- ------AAAAAAAAAAAAAAAAAAA----- 
---------AAAAAAAAAAAA--------- ---------AAAAAAAAAAAA--------- ---------AAAAAAAAAAAA--------- ---------AAAAAAAAAAAA--------- -------------AAAAA------------ -------------AAAAA------------ -------------AAAAA------------ -------------AAAAA------------ ---------AAAAAAAAAAAA--------- ---------AAAAAAAAAAAA--------- ---------AAAAAAAAAAAA--------- ---------AAAAAAAAAAAA--------- ---------AAAAAAAAAAAA--------- ---------AAAAAAAAAAAA--------- ---------AAAAAAAAAAAA--------- ---------AAAAAAAAAAAA--------- -----AAAAAAAAAAAAAAAAAAAAA---- -----AAAAAAAAAAAAAAAAAAAAA---- -----AAAAAAAAAAAAAAAAAAAAA---- -----AAAAAAAAAAAAAAAAAAAAA---- -----AAAAAAAAAAAAAAAAAAAAA---- 
--------AAAAAAAAAAAAAA-------- ------BBAAAAAAAAAAAAAABB------ ------BBAAAAAAAAAAAAAABB------ --------AAAAAAAAAAAAAA-------- ------------AAAAAAA----------- ------------AAAAAAA----------- ------------AAAAAAA----------- ------------AAAAAAA----------- --------AAAAAAAAAAAAAA-------- --------AAAAAAAAAAAAAA-------- --------AAAAAAAAAAAAAA-------- --------AAAAAAAAAAAAAA-------- --------AAAAAAAAAAAAAA-------- --------AAAAAAAAAAAAAA-------- --------AAAAAAAAAAAAAA-------- --------AAAAAAAAAAAAAA-------- ----AAAAAAAAAAAAAAAAAAAAAAA--- ----AAA-----------------AAA--- ----AAA-----------------AAA--- ----AAA-----------------AAA--- ----AAA-----------------AAA--- 
-------AA-------------A------- ------BAA-------------AB------ ------BAA-------------AB------ -------AAAAAAAAAAAAAAAA------- -----------AAAAAAAAA---------- -----------AAAAAAAAA---------- -----------AAAAAAAAA---------- -----------AAAAAAAAA---------- -------AAAAAAAAAAAAAAAA------- -------AAAAAAAAAAAAAAAA------- -------AAAAAAAAAAAAAAAA------- -------AAAAAAAAAAAAAAAA------- -------AAAAAAAAAAAAAAAA------- -------AAAAAAAAAAAAAAAA------- -------AAAAAAAAAAAAAAAA------- -------AAAAAAAAAAAAAAAA------- ----AAAAAAAAAAAAAAAAAAAAAAA--- ----AAA-----------------AAA--- ----AAA-----------------AAA--- ----AAA-----------------AAA--- ----AAA-----------------AAA--- 
------AAA-------------AA------ ------AAA-------------AA------ ------AAA-------------AA------ ------AAAAAAAAAAAAAAAAAA------ ----------AAAAAAAAAAA--------- ----------AAAAAAAAAAA--------- ----------AAAAAAAAAAA--------- ----------AAAAAAAAAAA--------- ------AAAAAAAAAAAAAAAAAA------ ------AAA-------------AA------ ------AAA-------------AA------ ------AAA-------------AA------ ------AAA-------------AA------ ------AAA-------------AA------ ------AAA-------------AA------ ------AAA-------------AA------ ---AAAAAA-------------AAAAAA-- ---AAAA-----------------AAAA-- ---AAAA-----------------AAAA-- ---AAAA-----------------AAAA-- ---AAAA-----------------AAAA-- 
-----AAAA-------------AAA----- -----AAAA-------------AAA----- -----AAAA-------------AAA----- -----AAAAA-----------AAAA----- --------AA-----------AA------- --------AA-----------AA------- --------AA-----------AA------- --------AA-----------AA------- -----AAAAA-----------AAAA----- -----AAAA-------------AAA----- -----AAAA-------------AAA----- -----AAAA-------------AAA----- -----AAAA-------------AAA----- -----AAAA-------------AAA----- -----AAAA-------------AAA----- -----AAAA-------------AAA----- ---AAAAAA-------------AAAAAA-- ---AAAA-----------------AAAA-- BB-AAAA-----------------AAAABB BB-AAAA-----------------AAAABB ---AAAA-----------------AAAA-- 
-----AAAA-------------AAAA---- -----AAAA-------------AAAA---- -----AAAA-------------AAAA---- -----AAAAA-----------AAAAA---- -------AAA-----------AA------- -------AAA-----------AA------- -------AAA-----------AA------- -------AAA-----------AA------- -----AAAAA-----------AAAAA---- -----AAAA-------------AAAA---- -----AAAA-------------AAAA---- -----AAAA-------------AAAA---- -----AAAA-------------AAAA---- -----AAAA-------------AAAA---- -----AAAA-------------AAAA---- -----AAAA-------------AAAA---- --AAAAAAA-------------AAAAAA-- --AAAAA-----------------AAAA-- BBAAAAA-----------------AAAABB BBAAAAA-----------------AAAABB --AAAAA-----------------AAAA-- 
-----AAAA-------------AAAA---- ----BAAAA-------------AAAAB--- ----BAAAA-------------AAAAB--- -----AAAAA-----------AAAAA---- -------AAA-----------AAA------ -------AAA-----------AAA------ -------AAA-----------AAA------ -------AAA-----------AAA------ -----AAAAA-----------AAAAA---- -----AAAA-------------AAAA---- -----AAAA-------------AAAA---- -----AAAA-------------AAAA---- -----AAAA-------------AAAA---- -----AAAA-------------AAAA---- -----AAAA-------------AAAA---- -----AAAA-------------AAAA---- --AAAAAAA-------------AAAAAA-- --AAAAA-----------------AAAA-- --AAAAA-----------------AAAA-- --AAAAA-----------------AAAA-- --AAAAA-----------------AAAA-- 
-----AAAA-------------AAAA---- ----BAAAA-------------AAAAB--- ----BAAAA-------------AAAAB--- -----AAAAA-----------AAAAA---- -------AAA-----------AAA------ -------AAA-----------AAA------ -------AAA-----------AAA------ -------AAA-----------AAA------ -----AAAAA-----------AAAAA---- -----AAAA-------------AAAA---- -----AAAA-------------AAAA---- -----AAAA-------------AAAA---- -----AAAA-------------AAAA---- -----AAAA-------------AAAA---- -----AAAA-------------AAAA---- -----AAAA-------------AAAA---- --AAAAAAA-------------AAAAAA-- --AAAAA-----------------AAAA-- --AAAAA-----------------AAAA-- --AAAAA-----------------AAAA-- --AAAAA-----------------AAAA-- 
-----AAAA-------------AAAA---- -----AAAA-------------AAAA---- -----AAAA-------------AAAA---- -----AAAAA-----------AAAAA---- -------AAA-----------AAA------ -------AAA-----------AAA------ -------AAA-----------AAA------ -------AAA-----------AAA------ -----AAAAA-----------AAAAA---- -----AAAA-------------AAAA---- -----AAAA-------------AAAA---- -----AAAA-------------AAAA---- -----AAAA-------------AAAA---- -----AAAA-------------AAAA---- -----AAAA-------------AAAA---- -----AAAA-------------AAAA---- --AAAAAAA-------------AAAAAA-- --AAAAA-----------------AAAA-- --AAAAA-----------------AAAA-- --AAAAA-----------------AAAA-- --AAAAA-----------------AAAA-- 
-----AAAA-------------AAAA---- -----AAAA-------------AAAA---- -----AAAA-------------AAAA---- -----AAAAA-----------AAAAA---- -------AAA-----------AAA------ -------AAA-----------AAA------ -------AAA-----------AAA------ -------AAA-----------AAA------ -----AAAAA-----------AAAAA---- -----AAAA-------------AAAA---- -----AAAA-------------AAAA---- -----AAAA-------------AAAA---- -----AAAA-------------AAAA---- -----AAAA-------------AAAA---- -----AAAA-------------AAAA---- -----AAAA-------------AAAA---- --AAAAAAA-------------AAAAAA-- --AAAAA-----------------AAAA-- --AAAAA-----------------AAAA-- --AAAAA-----------------AAAA-- --AAAAA-----------------AAAA-- 
-----AAAA-------------AAAA---- ----BAAAA-------------AAAAB--- ----BAAAA-------------AAAAB--- -----AAAAA-----------AAAAA---- -------AAA-----------AAA------ -------AAA-----------AAA------ -------AAA-----------AAA------ -------AAA-----------AAA------ -----AAAAA-----------AAAAA---- -----AAAA-------------AAAA---- -----AAAA-------------AAAA---- -----AAAA-------------AAAA---- -----AAAA-------------AAAA---- -----AAAA-------------AAAA---- -----AAAA-------------AAAA---- -----AAAA-------------AAAA---- --AAAAAAA-------------AAAAAA-- --AAAAA-----------------AAAA-- --AAAAA-----------------AAAA-- --AAAAA-----------------AAAA-- --AAAAA-----------------AAAA-- 
-----AAAA-------------AAAA---- ----BAAAA-------------AAAAB--- ----BAAAA-------------AAAAB--- -----AAAAA-----------AAAAA---- -------AAA-----------AAA------ -------AAA-----------AAA------ -------AAA-----------AAA------ -------AAA-----------AAA------ -----AAAAA-----------AAAAA---- -----AAAA-------------AAAA---- -----AAAA-------------AAAA---- -----AAAA-------------AAAA---- -----AAAA-------------AAAA---- -----AAAA-------------AAAA---- -----AAAA-------------AAAA---- -----AAAA-------------AAAA---- --AAAAAAA-------------AAAAAA-- --AAAAA-----------------AAAA-- BBAAAAA-----------------AAAABB BBAAAAA-----------------AAAABB --AAAAA-----------------AAAA-- 
-----AAAA-------------AAAA---- -----AAAA-------------AAAA---- -----AAAA-------------AAAA---- -----AAAAA-----------AAAAA---- --------AA-----------AA------- --------AA-----------AA------- --------AA-----------AA------- --------AA-----------AA------- -----AAAAA-----------AAAAA---- -----AAAA-------------AAAA---- -----AAAA-------------AAAA---- -----AAAA-------------AAAA---- -----AAAA-------------AAAA---- -----AAAA-------------AAAA---- -----AAAA-------------AAAA---- -----AAAA-------------AAAA---- ---AAAAAA-------------AAAAAA-- ---AAAA-----------------AAAA-- BB-AAAA-----------------AAAABB BB-AAAA-----------------AAAABB ---AAAA-----------------AAAA-- 
------AAA-------------AA------ ------AAA-------------AA------ ------AAA-------------AA------ ------AAAA-----------AAA------ --------AA-----------AA------- --------AA-----------AA------- --------AA-----------AA------- --------AA-----------AA------- ------AAAA-----------AAA------ ------AAA-------------AA------ ------AAA-------------AA------ ------AAA-------------AA------ ------AAA-------------AA------ ------AAA-------------AA------ ------AAA-------------AA------ ------AAA-------------AA------ ---AAAAAA-------------AAAAAA-- ---AAAA-----------------AAAA-- ---AAAA-----------------AAAA-- ---AAAA-----------------AAAA-- ---AAAA-----------------AAAA-- 
------AAA-------------AA------ ------AAA-------------AA------ ------AAA-------------AA------ ------AAAAAAAAAAAAAAAAAA------ ---------AAAAAAAAAAAAA-------- ---------AAAAAAAAAAAAA-------- ---------AAAAAAAAAAAAA-------- ---------AAAAAAAAAAAAA-------- ------AAAAAAAAAAAAAAAAAA------ ------AAA-------------AA------ ------AAA-------------AA------ ------AAA-------------AA------ ------AAA-------------AA------ ------AAA-------------AA------ ------AAA-------------AA------ ------AAA-------------AA------ ----AAAAA-------------AAAAA--- ----AAA-----------------AAA--- ----AAA-----------------AAA--- ----AAA-----------------AAA--- ----AAA-----------------AAA--- 
-------AAAAAAAAAAAAAAAA------- ------BAAAAAAAAAAAAAAAAB------ ------BAAAAAAAAAAAAAAAAB------ -------AAAAAAAAAAAAAAAA------- ----------AAAAAAAAAAA--------- ----------AAAAAAAAAAA--------- ----------AAAAAAAAAAA--------- ----------AAAAAAAAAAA--------- -------AAAAAAAAAAAAAAAA------- -------AAAAAAAAAAAAAAAA------- -------AAAAAAAAAAAAAAAA------- -------AAAAAAAAAAAAAAAA------- -------AAAAAAAAAAAAAAAA------- -------AAAAAAAAAAAAAAAA------- -------AAAAAAAAAAAAAAAA------- -------AAAAAAAAAAAAAAAA------- ----AAAAAAAAAAAAAAAAAAAAAAA--- ----AAA-----------------AAA--- ----AAA-----------------AAA--- ----AAA-----------------AAA--- ----AAA-----------------AAA--- 
--------AAAAAAAAAAAAAA-------- ------BBAAAAAAAAAAAAAABB------ ------BBAAAAAAAAAAAAAABB------ --------AAAAAAAAAAAAAA-------- ------------AAAAAAA----------- ------------AAAAAAA----------- ------------AAAAAAA----------- ------------AAAAAAA----------- --------AAAAAAAAAAAAAA-------- --------AAAAAAAAAAAAAA-------- --------AAAAAAAAAAAAAA-------- --------AAAAAAAAAAAAAA-------- --------AAAAAAAAAAAAAA-------- --------AAAAAAAAAAAAAA-------- --------AAAAAAAAAAAAAA-------- --------AAAAAAAAAAAAAA-------- -----AAAAAAAAAAAAAAAAAAAAA---- -----AAAAAAAAAAAAAAAAAAAAA---- -----AAAAAAAAAAAAAAAAAAAAA---- -----AAAAAAAAAAAAAAAAAAAAA---- -----AAAAAAAAAAAAAAAAAAAAA---- 
---------AAAAAAAAAAAA--------- ---------AAAAAAAAAAAA--------- ---------AAAAAAAAAAAA--------- ---------AAAAAAAAAAAA--------- ------------------------------ ------------------------------ ------------------------------ ------------------------------ ---------AAAAAAAAAAAA--------- ---------AAAAAAAAAAAA--------- ---------AAAAAAAAAAAA--------- ---------AAAAAAAAAAAA--------- ---------AAAAAAAAAAAA--------- ---------AAAAAAAAAAAA--------- ---------AAAAAAAAAAAA--------- ---------AAAAAAAAAAAA--------- ------AAAAAAAAAAAAAAAAAAA----- ------AAAAAAAAAAAAAAAAAAA----- ----BBAAAAAAAAAAAAAAAAAAAB---- ----BBAAAAAAAAAAAAAAAAAAAB---- ------AAAAAAAAAAAAAAAAAAA----- 
-----------AAAAAAAAA---------- -----------AAAAAAAAA---------- -----------AAAAAAAAA---------- -----------AAAAAAAAA---------- ------------------------------ ------------------------------ ------------------------------ ------------------------------ -----------AAAAAAAAA---------- -----------AAAAAAAAA---------- -----------AAAAAAAAA---------- -----------AAAAAAAAA---------- -----------AAAAAAAAA---------- -----------AAAAAAAAA---------- -----------AAAAAAAAA---------- -----------AAAAAAAAA---------- -------AAAAAAAAAAAAAAAAA------ -------AAAAAAAAAAAAAAAAA------ ----BB-AAAAAAAAAAAAAAAAABB---- ----BB-AAAAAAAAAAAAAAAAABB---- -------AAAAAAAAAAAAAAAAA------ 
------------------------------ ------------BB--BB------------ ------------BB--BB------------ ------------------------------ ------------------------------ ------------------------------ ------------------------------ ------------------------------ ------------------------------ ------------------------------ ------------------------------ ------------------------------ ------------------------------ ------------------------------ ------------------------------ ------------------------------ --------AAAAAAAAAAAAAAA------- --------AAAAAAAAAAAAAAA------- --------AAAAAAAAAAAAAAA------- --------AAAAAAAAAAAAAAA------- --------AAAAAAAAAAAAAAA------- 
------------------------------ ------------------------------ ------------------------------ ------------------------------ ------------------------------ ------------------------------ ------------------------------ ------------------------------ ------------------------------ ------------------------------ ------------------------------ ------------------------------ ------------------------------ ------------------------------ ------------------------------ ------------------------------ ----------AAAAAAAAAAA--------- ----------AAAAAAAAAAA--------- ----------AAAAAAAAAAA--------- ----------AAAAAAAAAAA--------- ----------AAAAAAAAAAA--------- 
------------------------------ ------------------------------ ------------------------------ ------------------------------ ------------------------------ ------------------------------ ------------------------------ ------------------------------ ------------------------------ ------------------------------ ------------------------------ ------------------------------ ------------------------------ ------------------------------ ------------------------------ ------------------------------ ------------------------------ ------------------------------ ----------BB------BB---------- ----------BB------BB---------- ------------------------------ 
------------------------------ ------------------------------ ------------------------------ ------------------------------ ------------------------------ ------------------------------ ------------------------------ ------------------------------ ------------------------------ ------------------------------ ------------------------------ ------------------------------ ------------------------------ ------------------------------ ------------------------------ ------------------------------ ------------------------------ ------------------------------ ----------BB------BB---------- ----------BB------BB---------- ------------------------------ 
