model
size = 30 32 19, scale = 0.05, origin = -y
material 
  colors = A:#444 B:#111 C:#BBB D:#777 E:#EEE
voxels
552-E-2E-E24-6E23-3E2-3E2(22-E2-2E2-E)23-6E25-4E228-26(20A10-)20A11-18A13-16A15-14A17-12A19-10A14-A6B8-6B26(A8-A4C2B8-2B4C)A8-2A3C2B8-2B3C2A9-2A2C2B8-2B2C2A11-2A3C8B3C2A13-2A12C2A15-2A10D2A11-A5B12-5B27(A6-A3C2B12-2B3C)A7-A2C2B12-2B2CA9-A3C12B3CA11-A16CA13-2A12D2A9-A4B16-4B26(A4-A3CB16-B3C)A5-A2CB16-B2CA7-ACB16-BCA9-AC16BCA11-A16CA13-A14DA9-A3B18-3B27(A4-A2CB18-B2C)A5-ACB18-BCA7-AC18BCA9-A18CA11-A16DA8-3B20-3B24(4-BCB20-BCB)4(4-ACB20-BCA)5-AC20BCA7-A7C6B7CA9-A18DA7-25(3B20-3B4-)3B20-3B2-2D2(3B20-3B4D)3B20-3B5D9B6-9B7D8B6-8B16D6-12D2-25(B24-B4-)B24-B2-2D26-2D120-D2B6D12-6D2B2(D2-25(B24-B4-)B24-B2-2D26-2D120-D6BD14-D6B)D2-25(B24-B4-)B24-B2-2D26-2D120-D2B6D12-6D2BD2-25(3B20-3B4-)3B20-3B2-2D2(3B20-3B4D)3B20-3B5D9B6-9B7D8B6-8B16D6-12D2-3B20-3B24(4-BCB20-BCB)4(4-ACB20-BCA)5-AC20BCA7-A7C6B7CA9-A18DA7-A3B18-3B27(A4-A2CB18-B2C)A5-ACB18-BCA7-AC18BCA9-A18CA11-A16DA8-A4B16-4B26(A4-A3CB16-B3C)A5-A2CB16-B2CA7-ACB16-BCA9-AC16BCA11-A16CA13-A14DA10-A5B12-5B27(A6-A3C2B12-2B3C)A7-A2C2B12-2B2CA9-A3C12B3CA11-A16CA13-2A12D2A11-A6B8-6B24(A8-A4C2B8-2B4C)2(A8-A2CBC2B8-2B4C)A8-2ACBC2B8-2B3C2A9-2ABC2B8-2B2C2A11-2A3C8B3C2A13-2A12C2A15-14A13-26(20A10-)20A11-18A13-16A15-14A17-12A39-
