model
size = 30 13 6, scale = 0.05, origin = -y
material 
  colors = A:#111 B:#222 C:#333 D:#444 E:#555
voxels
------------------------------ ------------------------------ ------------------------------ -------------AAA-------------- ------------AAAAA------------- ------------AAAAA------------- ------------AAAAA------------- ------------AAAAA------------- ------------AAAAA------------- -------------AAA-------------- ------------------------------ ------------------------------ ------------------------------ 
------------------------------ ---AA-------------------AAAA-- ---AAAAA--------------AAAAAA-- ---AAAAAAA---AAA-----AAAAAAA-- ---AAAAAAAAAABCCAAAAAAAAAAAA-- ---AAAAAAAAABBBBBAAAAAAAAAAAA- -A-AAAAAAAAABBCCBAAAAAAAAAAAA- ---AAAAAAAAABDDDBAAAAAAAAAAA-- ---AAAAAAAAAABBBAAAAAAAAAAAA-- ---AAAAAA----AAA-----AAAAAAA-- ---AAAA----------------AAAAA-- ---A---------------------AAA-- ------------------------------ 
--AAAAA------------------AA--- --ABBAAAA--------------AAAAAA- -AABBCCCAAA-----------ABBBBBA- -AAABCCDCBAA-AAA--AAAADDDEECA- -AAAAAAABCCBABCCAACDCBBBCDDEAA AAACBBBAAAABBBBBBCAAAAAAAAACDA ADADDDDDCCCCBBCCBBCBBBBBBBAABA AAACBBBAABBBCDDDBBBBBCCDDDDCAA -AAAAAAAABBAAEDDAACBAAABCDDDA- -AAABBBCCAA--AAA--AAABAAAABBA- -AACCCCAAA---------AAAACBBBBA- -AADAAAA--------------AAACCCA- -AAAA-------------------AAAAA- 
--AAAAA------------------AAA-- --ABBAAAA--------------AAAAAA- -AABBCCCAAA-----------ABBBBBA- -AAABCCDCBA-AAAA--AAAADDDEECA- -AAAAAAABCCABBCCAACDCBBBCDDEAA AACCBBBAAAABBBBBBCAAAAAAAAACDA ADDDDDDDCCCCBBCCBBCBBBBBBBAABA AABCBBBAABBBCDDDBBBBBCCDDDDCAA -AAAAAAAABBAAEDDAAABAAABCDDDA- -ABABBBCCAA--AAA--AAABAAAABBA- -ACCCCCAAA---------AAAACBBBBA- -AADAAAA--------------AAACCCA- -AAAA-------------------AAAAA- 
------------------------------ ---AA-------------------AAAA-- ---AAAAA--------------AAAAAA-- --AAAAAAAA---AAA-----AAAAAAA-- --AAAAAAAAAAABCCAAAAAAAAAAAA-- --AAAAAAAAAABBBBBAAAAAAAAAAAA- -AAAAAAAAAAABBCCBAAAAAAAAAAAA- --AAAAAAAAAABDDDBAAAAAAAAAAA-- --AAAAAAAAAAABBBAAAAAAAAAAAA-- --AAAAAAA----AAA-----AAAAAAA-- --AAAAA----------------AAAAA-- --AA---------------------AAA-- ------------------------------ 
------------------------------ ------------------------------ ------------------------------ -------------AAA-------------- ------------AAAAA------------- ------------AAAAA------------- ------------AAAAA------------- ------------AAAAA------------- ------------AAAAA------------- -------------AAA-------------- ------------------------------ ------------------------------ ------------------------------ 
