model
size = 15 27 4, scale = 0.05, origin = -y
material 
  colors = A:#111
voxels
--------------- --------------- --------------- --------------- --------------- --------------- --------------- --------------- --------------- --------------- --------------- --------------- --------------- --------------- --------------- --------------- --------------- --------------- --------------- --------------- --------------- --------------- --------------- ----AAAAAAA---- ---AAAAAAAAA--- -AAAAAAAAAAAAA- AAAAAAAAAAAAAAA 
-----AAAAA----- ---AAAAAAAAA--- -AAAAAAAAAAAAA- AAAAAAAAAAAAAAA AAAAAAAAAAAAAAA AAAAAAAAAAAAAAA AAAAAAAAAAAAAAA AAAAAAAAAAAAAAA AAAAAAAAAAAAAAA AAAAAAAAAAAAAAA AAAAAAAAAAAAAAA AAAAAAAAAAAAAAA AAAAAAAAAAAAAAA AAAAAAAAAAAAAAA AAAAAAAAAAAAAAA AAAAAAAAAAAAAAA AAAAAAAAAAAAAAA AAAAAAAAAAAAAAA AAAAAAAAAAAAAAA AAAAAAAAAAAAAAA AAAAAAAAAAAAAAA AAAAAAAAAAAAAAA --AAAAAAAAAAA-- ----AAAAAAA---- ---AAAAAAAAA--- -AAAAAAAAAAAAA- AAAAAAAAAAAAAAA 
-----AAAAA----- ---AAAAAAAAA--- -AAAAAAAAAAAAA- AAAAAAAAAAAAAAA AAAAAAAAAAAAAAA AAAAAAAAAAAAAAA AAAAAAAAAAAAAAA AAAAAAAAAAAAAAA AAAAAAAAAAAAAAA AAAAAAAAAAAAAAA AAAAAAAAAAAAAAA AAAAAAAAAAAAAAA AAAAAAAAAAAAAAA AAAAAAAAAAAAAAA AAAAAAAAAAAAAAA AAAAAAAAAAAAAAA AAAAAAAAAAAAAAA AAAAAAAAAAAAAAA AAAAAAAAAAAAAAA AAAAAAAAAAAAAAA AAAAAAAAAAAAAAA AAAAAAAAAAAAAAA --AAAAAAAAAAA-- ----AAAAAAA---- ---AAAAAAAAA--- -AAAAAAAAAAAAA- AAAAAAAAAAAAAAA 
--------------- --------------- --------------- --------------- --------------- --------------- --------------- --------------- --------------- --------------- --------------- --------------- --------------- --------------- --------------- --------------- --------------- --------------- --------------- --------------- --------------- --------------- --------------- ----AAAAAAA---- ---AAAAAAAAA--- -AAAAAAAAAAAAA- AAAAAAAAAAAAAAA 
