model
size = 31 14 26, scale = 0.05, origin = -y
material 
  colors = A:#09F B:#EEE C:#CFF D:#9CF E:#03C F:#69C G:#33F H:#06C
voxels
-------BBBBBBBBBBBBBBBBB------- -------BBBBBBBBBBBBBBBBB------- -------BBBBBBBBBBBBBBBBB------- --------B---------------------- --------B---------------------- --------B---------------------- ------------------------------- ------------------------------- ------------------------------- ------------------------------- ------------------------------- ------------------------------- ------------------------------- ------------------------------- 
------BBBBBBBBBBBBBBBBBBB------ ------BABAAAAAAAAAAAAAABB------ ------BABAAAAAAAAAAAAAABB------ -------ABAAAAAAAAAAAAAAB------- -------ABAAAAAAAAAAAAAAB------- --------BB-------------B------- ---------B--------------------- ---------B--------------------- ------------------------------- ------------------------------- ------------------------------- ------------------------------- ------------------------------- ------------------------------- 
-----BBBBBBBBBBBBBBBBBBBBB----- -----BAAABAAAAAAAAAAAABABB----- -----BAAABAAAAAAAAAAAABABB----- ------AAABAAAAAAAAAAAABA------- ------AAABAAAAAAAAAAAABA------- -------AABAAAAAAAAAAAAB-------- -------AABAAAAAAAAAAAAB-------- -------BBBBBBBBBBBBBBBB-------- ------------------------------- ------------------------------- ------------------------------- ------------------------------- ------------------------------- ------------------------------- 
----BBBBBBBBBBBBBBBBBBBBBBB---- ----BAAAAABAAAAAAAAAABAAABB---- ----BAAAAABAAAAAAAAAABAAABB---- -----AAAAABAAAAAAAAAABAAA------ -----AAAAABAAAAAAAAAABAAA------ ------AAAABAAAAAAAAAABAA------- ------AAAABAAAAAAAAAABAA------- ------B---BAAAAAAAAAABAB------- ----------B----------B--------- ------------------------------- ------------------------------- ------------------------------- ------------------------------- ------------------------------- 
---BBBBBBBBBBBBBBBBBBBBBBBBB--- ---BABAAAAABAAAAAAAABAAAAABB--- ---BABAAAAABAAAAAAAABAAAAABB--- ----BBAAAAABAAAAAAAABAAAAAB---- ----BBAAAAABAAAAAAAABAAAAAB---- ----BBAAAAABAAAAAAAABAAAA-B---- -----BAAAAABAAAAAAAABAAAA------ -----B-----BAAAAAAAABAAAB------ -----------BAAAAAAAABA--------- -----------B--------B---------- --------------------B---------- ------------------------------- ------------------------------- ------------------------------- 
BBBBBBBBBBBBBBBBBBBBBBBBBBBBBBB -BBAAABAAAABBBBBBBBBAAAAABABBB- --BAAABAAAABBBBBBBBBAAAAABABB-- ---AAABAAAABBBBBBBBBAAAAABA---- ---AAABAAAABBBBBBBBBAAAAABA---- ----AABAAAABBBBBBBBBAAAAAB----- ----AABAAAABBBBBBBBBAAAAAB----- -----BBAAAABBBBBBBBBAAAAAB----- ------BAAAABBBBBBBBBAAAA------- ------B----BAAAAAAABAA--------- -----------BAAAAAAABAA--------- -------------------B----------- ------------------------------- ------------------------------- 
BBBBBBBBBBBBBBBBBBBBBBBBBBBBBBB -BBAAAABAABDCCCCCCDDBAAABAAABB- --BAAAABAABDCCCCCCDDBAAABAAAB-- ---AAAABAABDCCCCCCDDBAAABAAA--- ---AAAABAABDCCCCCCDDBAAABAAA--- ----AAABAABDCCCCCCDDBAAABAA---- ----AAABAABDCCCCCCDDBAAABAA---- -----BABAABDCCCCCCDDBAAABBB---- ------ABAABDCCCCCCDDBAAAB------ -------BAAADCCCCCCDDBAA-B------ -------BAAADCCCCCCDDBAA-------- -----------BBBBBBBBBB---------- ------------------------------- ------------------------------- 
BBBBBBBBBBBBBBBBBBBBBBBBBBBBBBB -BBAAAAABBDDCCCCCCCDDBABAAAABB- --BAAAAABBDDCCCCCCCDDBABAAAAB-- ---AAAAABBDDCCCCCCCDDBABAAAA--- ---AAAAABBDDCCCCCCCDDBABAAAA--- ----AAAABBDDCCCCCCCDDBABAAA---- ----AAAABBDDCCCCCCCDDBABAAA---- -----BAABBDDCCCCCCCDDBABAAB---- ------AABBDDCCCCCCCDDBABAA----- -------ABBDDCCCCCCCDDBAB------- -------ABBDDCCCCCCCDDBAB------- --------BBBDCCCCCCDEBB--------- ------------EEEEEEE------------ ------------------------------- 
BBBBBBBBBBBBBBBBBBBBBBBBBBBBBBB -BBAAAAAABDCCCCCCCCCDBBAAAAABB- --BAAAAAABDCCCCCCCCCDBBAAAAAB-- ---AAAAAABDCCCCCCCCCDBBAAAAA--- ---AAAAAABDCCCCCCCCCDBBAAAAA--- ----AAAAABDCCCCCCCCCDBBAAAA---- ----AAAAABDCCCCCCCCCDBBAAAA---- -----BAAABDCCCCCCCCCDBBAAAB---- ------AAABDCCCCCCCCCDBBAAA----- -------AABDCCCCCCCCCDBBA------- -------AABDCCCCCCCCCDBBA------- ---------BDCCCCCCCCDEBB-------- ----------EECCCCCCEE----------- ------------EEEEEE------------- 
BBBBBBBBBBBBBBBBBBBBBBBBBBBBBBB -BBAAAAAFBCCCCCCCCCCCBAAAAAABB- --BAAAAAFBCCCCCCCCCCCBAAAAAAB-- ---AAAAAFBCCCCCCCCCCCBAAAAAA--- ---AAAAAFBCCCCCCCCCCCBAAAAAA--- ----AAAAFBCCCCCCCCCCCBAAAAA---- ----AAAAFBCCCCCCCCCCCBAAAAA---- -----BAAFBCCCCCCCCCCCBAAAAB---- ------AAFBCCCCCCCCCCCBAAAA----- -------AFBCCCCCCCCCCCBAA------- -------AFBCCCCCCCCCCCBAA------- ---------BCCCCCCCCCCCB--------- ----------ECCCCCCCCEE---------- -----------EEEEEEEE------------ 
BBBBBBBBBBBBBBBBBBBBBBBBBBBBBBB -BBAAAAAABCCCCBBBBCCCBAAAAAABB- --BAAAAAABCCCCDDDDCCCBAAAAAAB-- ---AAAAAABCCCCDDDDCCCBAAAAAA--- ---AAAAAABCCCCDDDDCCCBAAAAAA--- ----AAAAABCCCCDDDDCCCBAAAAA---- ----AAAAABCCCCDDDDCCCBAAAAA---- -----BAAABCCCCDDDDCCCBAAAAB---- ------AAABCCCCDDDDCCCBAAAA----- -------AABCCCCDDDDCCCBAA------- -------AABCCCCDDDDCCCBAA------- ---------BCCCCDDDDCCCB--------- ----------ECCCDDDDCCE---------- -----------EEEEHHEEE----------- 
BBBBBBBBBBBBBBBBBBBBBBBBBBBBBBB -BBAAAAAABCCCBBBBBCCCBAAAAAABB- --BAAAAAABCCCDDDDDCCCBAAAAAAB-- ---AAAAAABCCCDDDDDCCCBAAAAAA--- ---AAAAAABCCCDDDDDCCCBAAAAAA--- ----AAAAABCCCDDDDDCCCBAAAAA---- ----AAAAABCCCDDDDDCCCBAAAAA---- -----BAAABCCCDDDDDCCCBAAAAB---- ------AAABCCCDDDDDCCCBAAAA----- -------AABCCCDDDDDCCCBAA------- -------AABCCCDDDDDCCCBAA------- ---------BCCCDDDDDCCCB--------- ----------ECCDDDDDCCE---------- -----------EEEHHHEEE----------- 
BBBBBBBBBBGBGBBBGBBGBGBBBBBBBBB -BBAAAAAABCCCBBBBBCCCBAAAAAABB- --BAAAAAABCCCDDDDDCCCBAAAAAAB-- ---AAAAAABCCCDDDDDCCCBAAAAAA--- ---AAAAAABCCCDDDDDCCCBAAAAAA--- ----AAAAABCCCDDDDDCCCBAAAAA---- ----AAAAABCCCDDDDDCCCBAAAAA---- -----BAAABCCCDDDDDCCCBAAAAB---- ------AAABCCCDDDDDCCCBAAAA----- -------AABCCCDDDDDCCCBAA------- -------AABCCCDDDDDCCCBAA------- ---------BCCCDDDDDCCCB--------- ----------ECCDDDDDCCE---------- -----------EEEEHEEEE----------- 
BBBBBBBBBBBBGBGBGBGBGBGBBBBBBBB -BBAAAAAABCCCBBBBBCCCBAAAAAABB- --BAAAAAABCCCDDDDDCCCBAAAAAAB-- ---AAAAAABCCCDDDDDCCCBAAAAAA--- ---AAAAAABCCCDDDDDCCCBAAAAAA--- ----AAAAABCCCDDDDDCCCBAAAAA---- ----AAAAABCCCDDDDDCCCBAAAAA---- -----BAAABCCCDDDDDCCCBAAAAB---- ------AAABCCCDDDDDCCCBAAAA----- -------AABCCCDDDDDCCCBAA------- -------AABCCCDDDDDCCCBAA------- ---------BCCCDDDDDCCCB--------- ----------ECCDDDDDCCE---------- -----------EEEEEEEEE----------- 
BBBBBBBBBBBBBGBGBBGBBBGBBBBBBBB -BBAAAAAABCCCCCCCCCCCBAAAAAABB- --BAAAAAABCCCCCCCCCCCBAAAAAAB-- ---AAAAAABCCCCCCCCCCCBAAAAAA--- ---AAAAAABCCCCCCCCCCCBAAAAAA--- ----AAAAABCCCCCCCCCCCBAAAAA---- ----AAAAABCCCCCCCCCCCBAAAAA---- -----BAAABCCCCCCCCCCCBAAAAB---- ------AAABCCCCCCCCCCCBAAAA----- -------AABCCCCCCCCCCCBAA------- -------AABCCCCCCCCCCCBAA------- ---------BCCCCCCCCCCCB--------- ----------ECCCCCCCCCE---------- -----------EEEEEEEEE----------- 
BBBBBBBBBBBBBBBBBBBBBBBBBBBBBBB -BBAAAAAABDCCCCCCCCCCBAAAAAABB- --BAAAAAABDCCCCCCCCCCBAAAAAAB-- ---AAAAAABDCCCCCCCCCCBAAAAAA--- ---AAAAAABDCCCCCCCCCCBAAAAAA--- ----AAAAABDCCCCCCCCCCBAAAAA---- ----AAAAABDCCCCCCCCCCBAAAAA---- -----BAAABDCCCCCCCCCCBAAAAB---- ------AAABDCCCCCCCCCCBAAAA----- -------AABDCCCCCCCCCCBAA------- -------AABDCCCCCCCCCCBAA------- ---------BDCCCCCCCCCCB--------- ----------ECCCCCCCCCE---------- -----------EEEEEEEEE----------- 
BBBBBBBBBBBBBBBBBBBBBBBBBBBBBBB -BBAAAAAABDDCCCCCCCCDBAAAAAABB- --BAAAAAABDDCCCCCCCCDBAAAAAAB-- ---AAAAAABDDCCCCCCCCDBAAAAAA--- ---AAAAAABDDCCCCCCCCDBAAAAAA--- ----AAAAABDDCCCCCCCCDBAAAAA---- ----AAAAABDDCCCCCCCCDBAAAAA---- -----BAAABDDCCCCCCCCDBAAAAB---- ------AAABDDCCCCCCCCDBAAAA----- -------AABDDCCCCCCCCDBAA------- -------AABDDCCCCCCCCDBAA------- ---------BDDCCCCCCCCDB--------- ----------EEECCCCCCEE---------- -------------EEEEEE------------ 
BBBBBBBBBBBBBBBBBBBBBBBBBBBBBBB -BBAAAAAABBDDCCCCCCDBBBBAAAABB- --BAAAAAABBDDCCCCCCDBBBBAAAAB-- ---AAAAAABBDDCCCCCCDBBBBAAAA--- ---AAAAAABBDDCCCCCCDBBBBAAAA--- ----AAAAABBDDCCCCCCDBBBBAAA---- ----AAAAABBDDCCCCCCDBBBBAAA---- -----BAAABBDDCCCCCCDBBBBAAB---- ------AAABBDDCCCCCCDBBBBAA----- -------AABBDDCCCCCCDBBBB------- -------AABBDDCCCCCCDBBBB------- ---------BBEDCCCCCCDBBB-------- ------------EEEEEEEE----------- ------------------------------- 
BBBBBBBBBBBBBBBBBBBBBBBBBBBBBBB -BBAAAAABAABBBBBBBBBBAAABAAABB- --BAAAAABAABBBBBBBBBBAAABAAAB-- ---AAAAABAABBBBBBBBBBAAABAAA--- ---AAAAABAABBBBBBBBBBAAABAAA--- ----AAAABAABBBBBBBBBBAAABAA---- ----AAAABAABBBBBBBBBBAAABAA---- -----BAABAABBBBBBBBBBAAABB----- ------AABAABBBBBBBBBBAAAB------ -------ABAABBBBBBBBBBAA-B------ -------ABAABBBBBBBBBBAA-------- --------B--BBBBBBBBBB---------- ------------------------------- ------------------------------- 
BBBBBBBBBBBBBBBBBBBBBBBBBBBBBBB -BBBAAABAAAABAAAAAFABAAAABAABB- --BBAAABAAAABAAAAAFABAAAABAAB-- ----AAABAAAABAAAAAFABAAAABAA--- ----AAABAAAABAAAAAFABAAAABAA--- -----AABAAAABAAAAAFABAAAAB----- -----AABAAAABAAAAAFABAAAAB----- -----BABAAAABAAAAAFABAAABB----- ------ABAAAABAAAAAFABAAA------- -------BAAAABAAAAAFABAA-------- ----------AABAAAAAFABAA-------- ------------B-------B---------- ------------------------------- ------------------------------- 
---BBBBBBBBBBBBBBBBBBBBBBBBB--- ---BBABAAAABAAAAAAAAABAAAABB--- ---BBABAAAABAAAAAAAAABAAAABB--- -----ABAAAABAAAAAAAAABAAAAB---- -----ABAAAABAAAAAAAAABAAAAB---- -----BBAAAABAAAAAAAAABAAA-B---- -----BBAAAABAAAAAAAAABAAA------ -----BBAAAABAAAAAAAAABAAB------ ------BAAAABAAAAAAAAABAA------- ------B--AABAAAAAAAAAB--------- ----------ABAAAAAAAAAB--------- ------------------------------- ------------------------------- ------------------------------- 
----BBBBBBBBBBBBBBBBBBBBBBB---- ----BBAAAABAAAAAAAAAAABAAAB---- ----BBAAAABAAAAAAAAAAABAAAB---- -----BAAAABAAAAAAAAAAABAAA----- -----BAAAABAAAAAAAAAAABAAA----- -----B-AAABAAAAAAAAAAABAA------ -------AAABAAAAAAAAAAABAA------ -------BAABAAAAAAAAAAABBB------ --------AABAAAAAAAAAAAB-------- ----------B-----------B-------- ------------------------------- ------------------------------- ------------------------------- ------------------------------- 
-----BBBBBBBBBBBBBBBBBBBBB----- -----BBAABAAAAAAAAAAAAABAB----- -----BBAABAAAAAAAAAAAAABAB----- -------AABAAAAAAAAAAAAABA------ -------AABAAAAAAAAAAAAABA------ --------ABAAAAAAAAAAAAAB------- --------ABAAAAAAAAAAAAAB------- --------BBAAAAAAAABBBBBB------- ---------BAAAAAAAA------------- ---------B--------------------- ------------------------------- ------------------------------- ------------------------------- ------------------------------- 
------BBBBBBBBBBBBBBBBBBB------ ------BABAAAAAAAAAAAAAAAB------ ------BABAAAAAAAAAAAAAAAB------ -------ABAAAAAAAAAAAAAAAB------ -------ABAAAAAAAAAAAAAAAB------ --------BAAAAAAAAAAAAAA-B------ --------BAAAAAAAAAAAAAA-------- --------BBBBBBBBBBB------------ ------------------------------- ------------------------------- ------------------------------- ------------------------------- ------------------------------- ------------------------------- 
-------BBBBBBBBBBBBBBBBB------- -------BAAAAAAAAAAAAAAAB------- -------BAAAAAAAAAAAAAAAB------- -------BAAAAAAAAAAAAAAA-------- -------BAAAAAAAAAAAAAAA-------- -------B----------------------- ------------------------------- ------------------------------- ------------------------------- ------------------------------- ------------------------------- ------------------------------- ------------------------------- ------------------------------- 
--------BBBBBBBBBBBBBBB-------- --------BBBBBBBBBBBBBBB-------- --------BBBBBBBBBBBBBBB-------- ------------------------------- ------------------------------- ------------------------------- ------------------------------- ------------------------------- ------------------------------- ------------------------------- ------------------------------- ------------------------------- ------------------------------- ------------------------------- 
