model
size = 32, scale = 0.05, origin = -y
material 
  colors = A:#00E B:#3F6 C:#EEE D:#E00 E:#080 F:#60C G:#066 H:#00F I:#D00 J:#0E0 K:#001 L:#006 M:#009 N:#00C O:#030 P:#033 Q:#003 R:#002 S:#3F3 T:#070
voxels
13(9AB8AB2A11-)9AB8AB13A18EB13E9A2(B8AB22A)B8AB13A9EB22E9AB8AB22AB8AB5G8C9AB8AB5F8C3(9AB8ABH12-)9AB8ABS4(12-9AB8ABI)H11-9A10BIH11-9A2S9IH13(11-21A)11-32AE30AE96AE30AE50A6G4R4C18A6F4K4C18ABH4-4K4-2(18ABH12-)18ABS4(12-18ABI)H11-9A10BIH11-9A2S9IH13(11-21A)11-32AE30AE96AE30AE50A6G8C18A6F8C3(18ABH12-)18ABS4(12-18ABI)H11-9A10BIH11-9A2S9IH13(11-D20A)11-D31AD30AE3(D31A)E30AED31AD17A6G4R4CD17A6F4K4CD17ABH4-4K4-2(D17ABH12-)D17ABS4(12-D17ABI)H11-D8A3BPOHNMLQIH11-9D2(3JPOHNMLQD12-D20A12(11-21A)11-32AE30AE96AE30AE50A6G8C18A6F8C3(18ABH12-)18ABS4(12-18ABI)H11-9A3BPOHNMLQIH11-6A3D)3JPOHNMLQD12-D20A12(11-21A)11-32AE30AE96AE30AE28A4H18A6G4R4C18A6F4R4C18ABH4-4R4-2(18ABH12-)18ABS4(12-18ABI)H11-9A3BPOHNMLQIH11-6A3D3JPOHNMLQD12-D20A12(11-21A)11-32AE30AE96AE30AE50A6G8C18A6F8C3(18ABH12-)18ABS4(12-18ABI)H11-9A3BPOHNMLQIH11-6A3D3JPOHNMLQD12-D20A12(11-21A)11-32AE30AE96AE30AE50A6G4K4C18A6F4K4C18ABH4-4K4-2(18ABH12-)18ABS4(12-18ABI)H11-9A3BPOHNMLQIH11-6A3D3JPOHNMLQD12-D20A12(11-21A)11-32AE30AE96AE30AE50A6G8C18A6F3C-4C3(18ABH12-)18ABS4(12-18ABI)H11-9A3BPOHNMLQIH11-6A3D3JPOHNMLQD12-D20A12(11-21A)11-32AE30AE96AE30AE50A6G4K4C18A6F4K4C18AB5-4K4-7(18AB13-)9A3BPOHNMLQ13-6A3D3JPOHNMLQD12-D20A12(11-21A)11-32AE30AE96AE30AE50A6G8C18A6F8C8(18AB13-)9A3BPOHNMLQ13-6A3D3JPOHNMLQD12-D20AT4K6-D20AT10-11(D20A11-)D31AD30AE3(D31A)E30AED31AD17A6G8CD17A6F8C8(D17AB13-)D8A3BPOHNMLQ13-4D2A3D3JPOHNMLQD12-D13(20A11-J)31AE30AE3(J31A)J30AEJ23A4K4AJ17A6G4K4CJ17A6F4K4CJ17AB5-4K4-7(J17AB13-)J8A3BPOHNMLQ13-9D3JPOHNMLQD12-D20AT4K6-D20AT10-11(D20A11-)D31AD30AE3(D31A)E30AED31AD17A6G8CD17A6F8C8(D17AB13-)D8A3BPOHNMLQ13-9D3JPOHNMLQD12-D13(20A11-J)31AE30AE3(J31A)E30AEJ31AJ17A6G4K4CJ17A6F4K4CJ17AB5-4K4-7(J17AB13-)J8A3BPOHNMLQ13-12JPOHNMLQD12-D20AT4K6-D20AT10-11(D20A11-)D31AD30AE3(D31A)E30AED31AD17A6G8CD17A6F8C8(D17AB13-)D8A3BPOHNMLQ13-9D3JPOHNMLQD12-D13(20A11-J)31AE30AE3(J31A)J30AEJ31AJ17A6G8CJ17A6F8C8(J17AB13-)J8A3BPOHNMLQ13-9D3JPOHNMLQD12-13(D20A11-)D31AD30AE3(D31A)E30AED31AD17A6G4K4CD17A6F4K4CD17AB5-4K4-7(D17AB13-)D8A3BPOHNMLQ13-4D2A3D3JPOHNMLQD12-D20A12(11-21A)11-32AE30AE96AE30AE50A6G8C18A6F8C8(18AB13-)9A3BPOHNMLQ13-6A3D3JPOHNMLQD12-D20A12(11-21A)11-32AE30AE96AE30AE50A6G4K4C18A6F4K4C18AB5-4K4-7(18AB13-)9A3BPOHNMLQ13-6A3D3JPOHNMLQD12-D20A12(11-21A)11-32AE30AE96AE30AE50A6G8C18A6F8C3(18ABH12-)18ABS4(12-18ABI)H11-9A3BPOHNMLQIH11-6A3D3JPOHNMLQD12-D20A12(11-21A)11-32AE30AE96AE30AE50A6G4K4C18A6F4K4C18ABH4-4K4-2(18ABH12-)2(18ABS4(12-18ABI)H11-9A3BPOHNMLQIH11-6A3D3JPOHNMLQD12-D20A12(11-21A)11-32AE30AE96AE30AE50A6G8C18A6F8C3(18ABH12-))18ABS4(12-18ABI)H11-9A3BPOHNMLQIH11-6A3D2SBPOHNMLQI12-D20A12(11-21A)11-32AE30AE96AE30AE50A6G4R4C18A6F4R4C18ABH4-4R4-2(18ABH12-)18ABS4(12-18ABI)H11-9A3BPOHNMLQIH11-6A3D2SBPOHNMLQI12-D20A12(11-21A)11-32AE30AE96AE30AE50A6G8C18A6F8C3(18ABH12-)18ABS4(12-18ABI)H11-9A3BPOHNML-IH11-6A3D2SBPOHNMLQI12-D20A12(11-21A)11-32AE30AE96AE30AE50A6G4R4C18A6F4R4C18ABH4-4R4-2(18ABH12-)18ABS4(12-18ABI)H11-9A3BPOHNMLQIH11-6A3D2SBPOHNMLQI12-13(D20A11-)D31AE30AE3(D31A)D30AED31AD17A6G8CD17A6F8C3(D17ABH12-)D17ABS4(12-D17ABI)H11-D8A3BPOHNMLQIH11-9D2SBPOHNMLQI12-13(21A11-)32AE30AE96AE30AE50A6G8C18A6F8C3(18ABH12-)18ABS4(12-18ABI)H11-9A10BIH11-9A2S9IH13(11-21A)11-32AE27AE2AE96AE30AE50A6G4K4C18A6F4K4C18ABH4-4K4-2(18ABH12-)18ABS4(12-18ABI)H11-9A10BIH11-9A2S9IH13(11-9AB8AB2A)11-9AB8AB13A18EB9E-3E9A2(B8AB22A)B8AB13A9EB22E9AB8AB22AB8AB5G8C9AB8AB5F8C3(9AB8ABH12-)9AB8ABS4(12-9AB8ABI)H11-9A10BIH11-9A2S9IH11-
