model
size = 32, scale = 0.05, origin = -y
material 
  colors = A:#00B B:#D00 C:#009 D:#0D0 E:#63F F:#001 G:#EEE H:#F60 I:#FC9 J:#C03 K:#F6C L:#C33 M:#C06 N:#C30 O:#C0F P:#F90 Q:#FCC R:#C00 S:#F66 T:#B00 U:#800 V:#00E W:#0F3 X:#444 Y:#939 Z:#111 Aa:#A00
voxels
9-4(6(12D20-)12D820-)2D2-8D6(20-12D)820-6(12D20-)12D2156-2(30E2-)30G924-4E2-26EA3E2-E26GAGE2-30G4-F-F2-2(F-)2(F2-F-)F-F2-F-F621-2(Z-)F241-2(30E2-)E26GAFE2-28GFG4-F-F2-2(F-)2(F2-F-)F-F2-F-F610-2C9-2(Z-)F16-2(2C30-)2(LC30-)2(2C30-)LC30-LC28-2(2CLC28E)C2LC2(GF)2G2(FG)2(F2GFG)FGF2GFGF2CLC2(-F)2-2(F-)2(F2-F-)F-F2-F-F2CLC28-C2LC28-CL2C27-B4C28-2C2J28-2C416-2C9-2(X-)X14-4C9-5X14-4C28-CL2C2(28-C2LC)3(28-2CLC)28-2LCE28C-JC29E-2C28E2-2CB2(AF)2A2(FA)2(F2AFA)FAF2AFA2-2C2(2BFBF)2(BF2BF)2(BF)2BF2B-2C29B-2C8B3P11B2H5B-LC4B2HB3L2P2L2HB4P3BH4B-2CB27-B-RCB27-B-R2J27-3R384-2C11-X16-7(2C30-)CJ30-CL30C2(-JL29E)-JCB2(AF)2A2(FA)2(F2AFA)FAF2AFAB-JC2(2BFBF)2(BF2BF)2(BF)2BF2B-2(CL28B2-)LC28B2-JCB27G2-JCB27-B-2JC27-SBJ384-F12-F274-L29CG2(JL7-F11-F6-2F2-)2C7BF11BF8B2-JC2(28B2-JL)28B2-LC28B2-JCB3(GF)2(2GFGF)2(GF2GF)G2-BRB3(-F)2(2-F-F)2(-F2-F)3-C2J27-S2J384-14F274-33C7-F11-F6-2FX-PL7-F11-F6-2F2-PL7BF11BF8B2-JC28B2-JP28B2-2J28B2-LJ28B2-2JB3(GF)2(2GFGF)2(GF2GF)G2-CJB3(-F)2(2-F-F)2(-F2-F)3-CPR27-S2R672-33C7-F18-2F2-2C7-F18-2F2-PL7BF20B2-PL28B2-JP28B2-BP28B2-RC28B2-LCB3(GF)2(2GFGF)2(GF2GF)G2-JPB3(-F)2(2-F-F)2(-F2-F)3-CPN27-2IO672-8C6I6C2I11C11-10B9-2C11-2B-7B9-BC13-5B-2B9-BC13-7B10-JL13-7B10-JP13-7B10-RP11-9B10-LP11-9B10-MP3-2(B-)2B-11B-4B-B2-JMN27BS2I11-3V658-8CI4CI6CI12C11-10B9-2C11-2B-7B9-BR13-5B-2B9-CR13-7B10-RJ13-7B10-JC13-7B10-MK3B8-9B10-MC2B9-9B10-PJB10-9B10-PCNMKHN3LPLH3ISP2L2I2K2L2I2P2LI5(-W)-3V5(-2F)15-F627-33C11-10B9-CR11-2B-7B9-BC13-5B-2B9-2C13-7B10-RJ13-7B10-CJ13-7B10-2M10-10B10-PJB10-9B10-PJ11-9B10-CMNOK5L2P2INMS2PKN2(P2I)OL3PI11-3V5(-2F)15-F627-8CNCNP2C2NC2NP3NP4C2NPCR11-10B9-PM11-2B-7B9-BC13-5B-2B9-2C13-7B10-RJ13-7B10-MJB12-7B10-PJB9-B2-7B10-PM10-B2-7B10-JM13-7B10-CON2KMONMORMIH6KNRP3ION2SOLI5(-W)-3V5(-2F)643-R3C2M2C2SCP2C2K3CPMCSP8CM11-10B9-CM11-2B-7B9-2C13-5B-2B9-BC13-7B10-RJB12-7B10-PJ9-2B2-7B10-PM10-B2-2(7B10-RJ13-)7B10-JOJKJ3ONMOM3KMSNMNO2MKO3LSBOLR167-18E6(14-E16-E)295-4CM15CM12C2-B8-10B2-3B4-2C11-2B-7B2-B6-2C13-5B-2B9-2C13-7B10-OMB8-B3-7B10-PM9-B3-2(7B10-MJ13-)7B10-MC13-7B10-2R30CJOR2KM2O3NKJI2H2S2NOJLKLN2LS2OL2OMN2K3HO2KNHI2N2S2N2LNKNROSALAROMNR2KHRHKMOHI2ON2SRLJOLKOAS2L2ROABNOKHKNK5H2N2J2SLOLK2L2SR2A5ON2K3MLHL3HR2OS3LKJBJS2AB3JOL2NK2OLO2HOLI3HA2LR2K2HS3R3JOL2NA2KL2O2HMIOMB5HKHJBS2A2JOJL2NM3K4O2HIL2H2R2HK2JRS2RJOJAL3NJ3K4LMI5H3JK2ASBR2O2AN4LKL3KOA2H2I2M4JK2ASJAOJAJN2A2NOK2M2KH-R2AIJM2ARKAJS2JM2JN6HK2H2PN4JI3PJA2K2SJA288-33C11-10B9-2C11-2B-7B9-2C13-8B9-2C13-4B13-CI8-2B3-4B13-PI13-4B13-RJ13-4B13-BC13-4B13-HR13-4B13-H31CMJ30ARJ2(31AM)30ABM31AJ30AR32AJ30AH32AM31AO32AM2NM2JOAK7HJ5M3PK2S3M288-8CR3CR10CR9CB10-7B12-2CB10-2B-4B12-CR13-5B12-CM8-B4-4B13-PI8-B4-4B13-RC13-4B13-RJ13-4B13-HR13-4B13-HJ13-4B13-IJ30CIR30AI31A2(IM30A)IJ30A2(I31A)HJ30ARM31AO62A2M2NM3JOHK3IPMOM2H3MRMK2PSMAJA288-20CO5CO3CO2C11-3B16-CR30-2C6-2B22-BC7-2B4-2B15-PI13-2B15-RC13-2B15-R3(J13-2B15-I)J30CM31ABM30AKM62ARJ62AH31AHJ30AIM30AIO30ABM30AM2NJAJ3HIK2L3IOJOQ2H3MKSPAJMBA288-3CJ12CJ8CJ6CR30-2C5-B9-B14-BC6-2B22-BC2(5-3B)2(14-2I13-3B)2(14-IJ13-3B)14-BC13-3B14-MJ30C2M30ABM30AKM30AB31ARJ30ABH30A2H30ARO31AO30ABO30AIJ30AINMJA2JH2IOKLMP2IJOMQHM2NKM2B2JMB288-R32C4-2B9-B14-2C5-B9-B2(14-BC5-4B4-3B)14-IM13-3B14-2I13-3B14-HI13-3B14-HM2(13-3B14-2M)30CB31A2B30ABM30AKH2(30A2H)2(30AHP)30AHO30ABJ30ASO30AIN5JHNBA2KNPM2I2L3KH2K2NB2AMK288-20C6Q7C4-2B9-B14-BC15-B14-JC4-2B7-3B14-2J2(30-PJ)30-JI30-HI30-MI30-BI30C2B30ARO2(30A2H)30AKJ30AHJ30AMH30AM2(I30AH)I30AKI30A7IHJB2A10KN2HBM2N2MKI288-26C6QC30-QC3-2B10-B14-BJ4-B25-BJ30-2C30-PJ30-2J30-H2(J30-Q)I30C4(QI30A)KB30AQO2(30A2I)30AIH30AIM30AIL30A2I4N4HAMLBP2NBIAMQNA2HBJN3KI288-31CQC3-B11-B14-QCB2-B11-B14-QJ30-BC2(30-2C)30-2J2(30-QJ)30-HJ30CHJ30A2H30AMO30ABI30AHI30AK31AKI30AKP30AKH31AB30AHL30A2B2O2JH2B4HOPO2NIA2QAMK2H2KIBJARC28-QJ2(RC28-2C)RJ28-2(CJ)2(28-CJ2C)28-2J2C28-4C28-3C-28C-2C3-B11-B-B2-6B4-QC30-Q2(J30-B)C30-BC2(30-QJ)30-BC30-H31CHP30A2B30ABH30AHB30AKH2(30AKI)30AMP2(31AH)30AHL30AHB2AO2HB4L2HPHON2I2QA3N2HI2JAB2C28-2JCJ28-Q2CJ28-2Q2C28-CJ2C28-4C28-CJCL28-CJ2L28-CJLC28-2C2L11CTJ7T4CU6C2L7CU2TU8JTC6S3C2L3C2U4M10I2SU2BU2CSQCL3HUY4O2IU2C2Y2TS3I7LQ5L3H2T2I2O2Aa6KJ2IJTB2CLQ2LUYULT2H2IC3OL2K2S2O4K2BU2LQLC2PU2LTCI4K4I2K4N2I6KLCPUTM2L2IKH2PITCPQKQBJOJI2HLTCKLCP2TMN2LIK2P2I2HKQH2K2HSIL2NBC2BUPTU2NMHIKHBINH2KQHS2KP2HSMN2BQ-H2PNO2HCIK2L2IHKOHSHIK2PI2S2MQAPAHPNOHMLKL2JNIHKSH3IKLI2Q2SQMBP2H2P2HL2KMJ2O2IKSHIH2K3IQUQNTM2P2IPH3KPI3NS3IHA2K2IPI2QS2NK3QI3KO2P2I3SH2P3KIB2SI2Q2ANMPAQ2KH3P2SILB2P3K3LBAHO2Q2U2MP3K3QHJLM2IP2KQ2H2N3LHQIQ2U2M2IO2LBO4Q21KHUO2BY2N4K3Q2I4HUHQ2IQOTNUAHUOB2NOBK2LNPLB2KH4IQIAUQ2N2TUHUB2N3OA2HKP2K2HAH8QNUATAL2BN2OB3K9HIQI2LNOBTUATH7LO2A2O2PA3HIQ2L5I2H2TA
