model
size = 32 26 32, scale = 0.05, origin = -y
material 
  colors = A:#600 B:#FF0 C:#400 D:#CC0 E:#200
voxels
387-2(2AC)3A2C2AC3AC7A7-18A2C4AC743-7AC5A4C8A6-27A5-26AC6-2AC8AC13A710-6AC5A8C7A4-7AC2A2C16AC3-21AC6AC4-3AC6A12C5A708-3A2CAC15-3C4A2-C3A2CAC15-8A-8A15-C7A2-3AC3A15-7A707-2AC22-C2AC2-C2AC22-5A-4A22-5A2-C2A22-4A707-2AC22-C2AC2-3AC22-5A-4A22-4AC2-C2A22-C3A707-3A22-C2AC2-C2AC22-5A-4A22-4AC2-3A22-C3A511-2(2B30-)2B130-C2A22-C3A2-4A22-5A-C3A22-5A2-3A22-4A159-DB2(30-2B)286-BD30-3B29-2B130-AC24-C2A2-3A24-4A-C2A24-3AC2-2A24-3A159-DB30-3B29-2B286-2D30-3B29-2B130-AC24-C2A2-C2A24-4A-3A24-4A2-2A24-3A159-2B30-3B29-2B286-BD30-3B29-2(2B30-BD30-)BD2-AC24-CABD-3A24-2ABD-2AC24-2ABD2-CA24-2A3(BD30-)2(2D30-)2B30-3B29-2B286-2D30-2(3B29-)3(2BD29-)2BD-AC24-CA3B3A24-2A3B2AC24-2A3B-2A24-2A3B4(29-2BD)2(29-3B)29-2B286-2D30-2(3B29-)3(BDB29-)BDB-AC24-EA3BC2A24-EA2BD3A24-EA3B-2A24-EA3B4(29-BDB)2(29-3B)29-2B158-2B2(30-BD)30-2D30-BD30-3B29-BDB129-AC24-EABD-3A24-EA2BDC2A24-EA3B-2A24-EADB158-BDB29-3B29-6(2B30-)4(3B29-)2BD29-BDB129-AC24-EABD-3A24-CA2BD3A24-2A3B-2A24-EADB158-BDB5(29-3B)29-6(2B30-)2BD29-BDB129-AC24-EA2B-3A24-CA2BDC2A24-2A3B-2A24-EADB158-B2D29-3B29-4(2B30-)2B158-BD30-2BD29-BDB129-AC24-EABD-3A24-EA2BDC2A24-EA3B-2A24-EA2B158-B2D29-3B29-DB286-2D30-2BD29-BDB129-AC24-EABD-3A24-CA2BDCAC24-2A3B-2A24-EA2B158-B2D29-3B29-DB158-2B4(30-BD)30-2BD29-BDB129-AC24-EABD-3A24-EA3B2AC24-EA3B-2A24-EA2B158-B2D29-3B29-2(2B30-)DB3(30-2B)30-4(3B29-)2BD29-BDB129-AC24-EABD-2(3A24-EA3B)-2A24-EA2B158-BDB5(29-3B)29-4(2B30-)2D30-3B29-2BD29-BDB129-2C24-2ABD-3A24-2A2BD3A24-2A3B-2A24-2A2B158-BDB29-3B29-4(2B30-)2B158-2B30-3B29-BDB129-AC24-CA2(3B3A24-2A)2BD-CA24-2ABDB157-BDB29-3B29-2B286-2D30-3B29-2BD29-BDB93-BDB-AC24-CA3B3A24-2A2B-C2A24-2A2B2-CA24-2A3B29-BDB93-B2D2(29-3B)29-2B318-BD30-2(3B29-)B2D29-BDB29-3B-AC24-CABD2(-3A24-4A)2-2A24-2ABD30-3B29-B2D29-BDB2(29-3B)29-2B382-BD30-2(3B29-)2BD29-2D2-3A22-C3A2-C3A22-5A-4A22-5A2-3A22-4A31-DB30-3B29-2BD29-3B29-2B446-DB30-BD30-DB34-3A22-C2AC2-4A22-5A-4A22-5A2-3A22-4A63-2(2B30-)2B578-2AC22-C2AC2-4A22-5A-C3A22-5A2-3A22-4A707-2AC22-C2AC2-4A22-5A-C3A22-4AC2-3A22-4A707-3A4C14-A3C3AC2-4AC3A14-2C7A-C3AC2AC14-C8A2-3AC3A14-8A707-7A2CA7C10AC4-28AC3-7AC21A4-10A3C14A709-2A10C13AC6-26AC5-27A6-AC8AC6A2C3A2CA743-9AC3AC6A2C3A7-4AC2AC8A2CA3C2AC388-
