model
size = 32 32 19, scale = 0.05, origin = -y
material 
  colors = A:#C00 B:#800 C:#400 D:#444 E:#FF0 F:#E00 G:#0E0
voxels
195-AD2A18-2ADA6-AD2A18-2ADA5-2(2AD2A18-2AD2A4-)2AD2A18-2AD2A5-AD2A18-2ADA6-AD2A18-2ADA742-AD2A18-2ADA6-AD2A18-2ADA5-A3BA18-A3BA3-4(A4BA18-A4BA2-)A4BA18-A4BA3-A3BA18-A3BA5-AD2A18-2ADA6-AD2A18-2ADA646-AD2A18-2ADA5-A3BA18-A3BA3-2A3BA18-A3B2A3(2-ABD3B18-3BDBA)4(2-A2BD2B18-2BD2BA)2-2A3BA18-A3B2A3-A3BA18-A3BA5-AD2A18-2ADA582-AD2A18-2ADA5-A3BA18-A3BA3-5BA18-A4BA2-A2BD2B18-2BD2BA2-C28-C6(2-B28-D)2-A3BDB18-BD3BA2-A4BA18-A4BA3-A3BA18-A3BA5-AD2A18-2ADA518-AD2A18-2ADA5-A3BA18-A3BA3-A4BA18-A4BA2-A2B2DB18-B2D2BA2-C28-C2-B28-D-A5(C28-C2A)C28-CA-B28-D2-3A2DA18-A2D3A2-A4BA18-A4BA3-A3BA18-A3BA5-AD2A18-2ADA485-2AD2A18-2AD2A3-A4BA18-A4BA2-A2BD2B18-2BD2BA2-C28-C2-B28-D-A7(C28-C2A)C28-CA-B28-D2-4ADA18-AD4A2-A4BA18-A4BA3-2AD2A18-2AD2A453-AD2A18-2ADA4-2A3BA18-A3B2A2-AC4A18-4ACA2(2-C28-C)-AC28-C2AC28-C2EC28-CAEC28-C2A2(C28-CAE)C28-C2AC28-CEAC28-C2AC28-CA-B28-D2-B4CB18-B4CD2-2A3BA18-A3B2A4-AD2A18-2ADA421-5A18-5A3-A4BA18-A4BA2-AC4A18-4ACA2-C28-C-AC28-C2AC28-CAE2(2(C28-CEA)C28-C2E)C28-CEA3(C28-C2A)B4CB18-B4CB2A5BA18-A4BDAB-A3BA18-A3BA-2B-2AD2A18-2AD2A-2(2B30-)B2A28-2A-2E26-2E3-2A24-2A5-2A22-2A7-2A20-2A9-2A18-2A11-2A16-2A13-2A14-2A15-6AE2AE6A17-5AE2AE5A11-2AE2A18-2AE2A3-F4BA18-A4BA2-ACD3A18-3ADCA2-C28-C-E2(C28-C2E)2(C28-CEAC28-C2AC28-CAE)2(C28-C2E)C28-CEBC28-C3BD2CDB18-BD2CD8BA18-A4BD2B-4BA18-A3BA-BA-2AD2A18-2AD2A-2A30-AB30-B2A28-2A-2E26-2E3-2A24-2A5-2A22-2A7-2A20-2A9-2A18-2A11-2A16-2A13-2A14-2A15-6AE2AE6A17-5AE2AE5A11-5A18-5A3-A4BA18-A4BA2-AC4A18-4ACA2-C28-C-3(AC28-C2AC28-CAEC28-CE)A3(C28-C2A)BDCDAB18-BADCDB2A5BA18-A4BD2A-4BA18-A3BA2(-2A)D2A18-2AD2A-2A30-AB30-B2A28-2A-2E26-2E3-2A24-2A5-2A22-2A7-2A20-2A9-2A18-2A11-2A16-2A13-2A14-2A15-6AE2AE6A17-5AE2AE5A11-2AE2A18-2AE2A3-G4BA18-A4BA2-AC4A18-4ACA2-C28-C-E2(C28-C2E)2(C28-CEAC28-C2AC28-CAE)2(C28-C2E)C28-CEBC28-C3B2CDAB18-BAD2C8BA18-A4BD2B-4BA18-A3BA-BA-2AD2A18-2AD2A-2A30-AB30-B2A28-2A-2E26-2E3-2A24-2A5-2A22-2A7-2A20-2A9-2A18-2A11-2A16-2A13-2A14-2A15-6AE2AE6A17-5AE2AE5A11-5A18-5A3-A4BA18-A4BA2-4ADA18-AD4A2-C28-C-AC28-C2AC28-CAE2(C28-C2E2(C28-CAE))C28-CEA3(C28-C2A)B3CDB18-BD3CB2A5BA18-A4BDAB-4BA18-A3BA-2B-2AD2A18-2AD2A-2(2B30-)B2A28-2A-2E26-2E3-2A24-2A5-2A22-2A7-2A20-2A9-2A18-2A11-2A16-2A13-2A14-2A15-6AE2AE6A17-5AE2AE5A12-AD2A18-2ADA4-2A3BA18-A3B2A2-3AD2A18-2AD3A2-C28-C2-B28-D-AC28-CAEC28-C2A2(C28-CEA)C28-C2AC28-CEAC28-C2E2(C28-C2A)C28-CA-C28-C2-B4CB18-B4CD3-4BA18-A3BA4-2AD2A18-2AD2A452-2AD2A18-2AD2A4-A3BD18-D3BA3-3A2DA18-A2D3A2-C28-C2-B28-D-A7(C28-C2A)C28-CA-C28-C2-A2BD2B18-2BD2BA2-A4BA18-A4BA3-2AD2A18-2AD2A485-AD2A18-2ADA5-A3BA18-A3BA3-A5B18-5BA2-6A18-6A2(2-C28-C)-A5(C28-C2A)C28-CA-C28-C2-A2BD2B18-2(2BD)2-A4BA18-A4BA3-A3BA18-A3BA4-2AD2A18-2AD2A517-AD2A18-2ADA5-A3BA18-A3BA3-A5B18-5BA2-3AD2A18-2AD3A7(2-C28-C)2-6A18-5AD2-A4BA18-A4BA3-A3BA18-A3BA5-AD2A18-2ADA582-AD2A18-2ADA5-A3BA18-A3BA3-A4BD18-D4B2(A2-A5B18-5B)2(A2-ABD3B18-3BDB)2(A2-A2BD2B18-2BD2B)A2-A5B18-5BA2-2A3BA18-A3B2A3-A3BA18-A3BA5-AD2A18-2ADA646-AD2A18-2ADA5-2AD2A18-2AD2A3-5(A4BA18-A4BA2-)A4BA18-A4BA3-A3BA18-A3BA5-AD2A18-2ADA6-AD2A18-2ADA741-6(2AD2A18-2AD2A4-)2AD2A18-2AD2A610-
