model
size = 32 32 19, scale = 0.05, origin = -y
material 
  colors = A:#111 B:#555 C:#222 D:#444 E:#FF0 F:#E00 G:#0E0
voxels
195-AD2A18-2ADA5-4(2AD2A18-2AD2A4-)2AD2A18-2AD2A5-AD2A18-2ADA742-AD2A18-2ADA6-AD2A18-2ADA5-A3BA18-A3BA3-4(A4BA18-A4BA2-)A4BA18-A4BA3-A3BA18-A3BA5-AD2A18-2ADA6-AD2A18-2ADA646-AD2A18-2ADA5-A3BA18-A3BA3-2A3BA18-A3B2A3(2-ACD3C18-3CDCA)4(2-A2CD2C18-2CD2CA)2-2A3BA18-A3B2A3-A3BA18-A3BA5-AD2A18-2ADA582-AD2A18-2ADA5-A3BA18-A3BA3-5BA18-A4BA2-A2CD2C18-2CD2CA2-A28-A6(2-B28-D)2-A3CDC18-CD3CA2-A4BA18-A4BA3-A3BA18-A3BA5-AD2A18-2ADA518-AD2A18-2ADA5-A3BA18-A3BA3-A4BA18-A4BA2-A2C2DC18-C2D2CA2-A28-C2-B28-D-2A5(28-4A)28-2A-B28-D2-3A2DA18-A2D3A2-A4BA18-A4BA3-A3BA18-A3BA5-AD2A18-2ADA485-2AD2A18-2AD2A3-A4BA18-A4BA2-A2CD2C18-2CD2CA2-A28-A2-B28-D-2A7(28-4A)28-2A-B28-D2-4ADA18-AD4A2-A4BA18-A4BA3-2AD2A18-2AD2A453-AD2A18-2ADA4-2A3BA18-A3B2A2-6A18-6A2-B28-A2-B28-D-2A28-4A28-A2EA28-2AEA28-4A2(28-2AEA)28-4A28-AE2A28-4A28-2A-B28-D2-B4AC18-C4AD2-2A3BA18-A3B2A4-AD2A18-2ADA421-5A18-5A3-A4BA18-A4BA2-6A18-6A2-B28-D-2A28-4A28-2AE2(A2(28-AE2A)28-A2E)A28-AE2A2(28-4A)28-3AB4AC18-C4AB2A5BA18-A4BDAC-A3BA18-A3BA-2C-2AD2A18-2AD2A-2(2C30-)C2A28-2A-2E26-2E3-2A24-2A5-2A22-2A7-2A20-2A9-2A18-2A11-2A16-2A13-2A14-2A15-6AE2AE6A17-5AE2AE5A11-2AE2A18-2AE2A3-F4BA18-A4BA2-2AD3A18-3AD2A2-B28-D-E2(A28-A2E)2(A28-AE2A28-4A28-2AE)2(A28-A2E)A28-AECA28-A2CBD2ADC18-CD2ADB2C5BA18-A4BD2C-4BA18-A3BA-CA-2AD2A18-2AD2A-2A30-AC30-C2A28-2A-2E26-2E3-2A24-2A5-2A22-2A7-2A20-2A9-2A18-2A11-2A16-2A13-2A14-2A15-6AE2AE6A17-5AE2AE5A11-5A18-5A3-A4BA18-A4BA2-6A18-6A2-B28-D-3(2A28-4A28-2AEA28-AE)2A2(28-4A)28-3AB2(DA)C18-C2(AD)B2A5BA18-A4BD2A-4BA18-A3BA2(-2A)D2A18-2AD2A-2A30-AC30-C2A28-2A-2E26-2E3-2A24-2A5-2A22-2A7-2A20-2A9-2A18-2A11-2A16-2A13-2A14-2A15-6AE2AE6A17-5AE2AE5A11-2AE2A18-2AE2A3-G4BA18-A4BA2-6A18-6A2-B28-D-E2(A28-A2E)2(A28-AE2A28-4A28-2AE)2(A28-A2E)A28-AECA28-A2CB2ADAC18-CAD2AB2C5BA18-A4BD2C-4BA18-A3BA-CA-2AD2A18-2AD2A-2A30-AC30-C2A28-2A-2E26-2E3-2A24-2A5-2A22-2A7-2A20-2A9-2A18-2A11-2A16-2A13-2A14-2A15-6AE2AE6A17-5AE2AE5A11-5A18-5A3-A4BA18-A4BA2-4ADA18-AD4A2-B28-D-2A28-4A28-2AE2(A28-A2E2(A28-2AE))A28-AE2A2(28-4A)28-3AB3ADC18-CD3AB2A5BA18-A4BDAC-4BA18-A3BA-2C-2AD2A18-2AD2A-2(2C30-)C2A28-2A-2E26-2E3-2A24-2A5-2A22-2A7-2A20-2A9-2A18-2A11-2A16-2A13-2A14-2A15-6AE2AE6A17-5AE2AE5A12-AD2A18-2ADA4-2A3BA18-A3B2A2-3AD2A18-2AD3A2-A28-A2-B28-D-2A28-2AEA28-4A2(28-AE2A)28-4A28-AE2A28-A2EA2(28-4A)28-2A-B28-D2-B4AC18-C4AD3-4BA18-A3BA4-2AD2A18-2AD2A452-2AD2A18-2AD2A4-A3BD18-D3BA3-3A2DA18-A2D3A2-A28-A2-B28-D-2A7(28-4A)28-2A-B28-D2-A2CD2C18-2CD2CA2-A4BA18-A4BA3-2AD2A18-2AD2A485-AD2A18-2ADA5-A3BA18-A3BA3-A5B18-5BA2-6A18-6A2-A28-A2-B28-D-2A5(28-4A)28-2A-B28-D2-A2CD2C18-2(2CD)2-A4BA18-A4BA3-A3BA18-A3BA4-2AD2A18-2AD2A517-AD2A18-2ADA5-A3BA18-A3BA3-A5B18-5BA2-3AD2A18-2AD3A7(2-B28-D)2-6A18-5AD2-A4BA18-A4BA3-A3BA18-A3BA5-AD2A18-2ADA582-AD2A18-2ADA5-A3BA18-A3BA3-A4BD18-D4B2(A2-A5C18-5C)2(A2-ACD3C18-3CDC)2(A2-A2CD2C18-2CD2C)A2-A5C18-5CA2-2A3BA18-A3B2A3-A3BA18-A3BA5-AD2A18-2ADA646-AD2A18-2ADA5-2AD2A18-2AD2A3-5(A4BA18-A4BA2-)A4BA18-A4BA3-A3BA18-A3BA5-AD2A18-2ADA6-AD2A18-2ADA741-6(2AD2A18-2AD2A4-)2AD2A18-2AD2A610-
