model
size = 22 25 20, scale = 0.05, origin = -y
material 
  colors = A:#FFE2C5 B:#563F2E C:#EEE D:#FFFFFB E:#00AA90 F:#F8B09C G:#111
voxels
---------------------- ---------------------- ---------------------- ---------------------- ---------------------- ---------------------- ---------------------- ---------------------- ---------------------- ---------AAAA--------- --------AAAAAA-------- ---------AAAA--------- ----------AA---------- ---------------------- ---------------------- ---------------------- ---------------------- ---------------------- ---------------------- ---------------------- ---------------------- ---------------------- ---------------------- ---------------------- ---------------------- 
---------------------- ---------------------- ---------------------- ---------------------- ---------------------- ---------------------- ---------------------- ---------------------- --------BBBBBB-------- -------BBA--ABB------- -------AAA--AAA------- --------AAAAAA-------- ---------AAAA--------- ----------AA---------- ---------------------- ---------------------- ---------------------- ---------------------- ---------------------- ---------------------- ---------------------- ---------------------- ---------------------- ---------------------- ---------------------- 
---------------------- ---------------------- ---------------------- ---------------------- ---------------------- ----------BB---------- --------BFFFFB-------- -------BF----FB------- ------BBA----ABB------ ------BAA----AAB------ -------AA----AA------- -------AA----AA------- --------AA--AA-------- ---------AAAA--------- ----------AA---------- ---------------------- ---------------------- ---------------------- ---------------------- ---------------------- ---B--------------B--- ----BBBBB----BBBBB---- ---------------------- ---------------------- ---------------------- 
---------------------- ---------------------- ---------------------- ----------BB---------- ---------BBBB--------- -------BBBAABBB------- ------BBAA--AABB------ -----BBBA----ABBB----- -----BAA------AAB----- -----BAA------AAB----- ------AA------AA------ ------AA------AA------ -------AA----AA------- --------AA--AA-------- ---------AAAA--------- ----------AA---------- ---------------------- ---------------------- ----------AA---------- ---A-----AAAA-----A--- ----AAAAAAAAAAAAAA---- ----AAA-AAAAAA-AAA---- -----AAAAA--AAAAA----- ---------------------- ---------------------- 
---------------------- ---------------------- ---------BBBB--------- --------BBBBBB-------- ------BBBBAABBBB------ -----BBBBA--ABBBB----- -----BBA------ABB----- -----BAA------AAB----- -----BA--------AB----- -----BA--------AB----- -----AA--------AA----- -----AA--------AA----- -----AAA------AAA----- ----AAAA------AAAA---- ----AAAAAA--AAAAAA---- ---AAAAAAAAAAAAAAAA--- ---AA---AAAAA-DDD-A--- ---A-----AAAAD---CA--- ---A-----AAAAD---CA--- ---AA---A-----DDD-A--- ---AAA---AAAA---AAA--- ----A-----AA-----A---- ----AA---AAAA---AA---- ------AAAAAAAAAA------ ---------------------- 
----------BB---------- --------BBBBBB-------- -------BBBAABBB------- ------BBBB--BBBB------ -----BBBB----BBBB----- ----BBBB------BBBB---- ----BBA--------ABB---- ----BB----------BB---- ----BB----------BB---- ----BB----------BB---- -----AA--------AA----- ----AAA--------AAA---- ----AA----------AA---- ----AAA--------AAA---- ---AAAAA------AAAAA--- ---AAAAAA----AAAAAA--- --A-ADDDAAAAAACCCA-A-- --A-C---DAAAACE-EC-A-- --AAC---DAAAACE-ECAA-- ---AADDDAAAAAACCCAA--- ---A-AAAAAAAAAAAA-A--- ---A--------------A--- ----A------------A---- -----AAAAA--AAAAA----- ----------AA---------- 
--------BBAABB-------- -------BBAAAABB------- ------BAAA--AAAB------ -----B----------B----- ----BBB--------BBB---- ----BB----------BB---- ---BBB----------BBB--- ---BB------------BB--- ---BB------------BB--- ----B------------B---- ----BA----------AB---- ----AA----------AA---- ---BAA----------AAB--- ---AAA----------AAA--- --AAAA----------AAAA-- --A--AA--------AA--A-- --A-ACCCAAAAAAACCA-A-- --A-CE-ECA--AAEGEC-A-- --A-CE-ECAAAAAEGEC-A-- --AAACCCAAAAAAACCAAA-- ---A-AAAAAAAAAAAA-A--- ---A--------------A--- ----A------------A---- ----AA----------AA---- ------AAAAAAAAAA------ 
-------BB----BB------- ------BB------BB------ -----BB--------BB----- ----BB----------BB---- ----BB----------BB---- ---B--------------B--- ---B--------------B--- --BB--------------BB-- ---BB------------BB--- ---BB------------BB--- ----B------------B---- ---BA------------AB--- ---BA------------AB--- --AA--------------AA-- --A----------------A-- --A----------------A-- -AA-ACCAA-----ADDA-AA- -A--CEGEA-----DEED--A- -AA-CEGEA-----DEED-AA- --A-ACCAA-----ADD--A-- --A----------------A-- ---A--------------A--- ---A--------------A--- ----AA----------AA---- ------AAAAAAAAAA------ 
------BB------BB------ -----BB--------BB----- ----BB----------BB---- ----B------------B---- ---B--------------B--- ---B--------------B--- --B----------------B-- --B----------------B-- --BB--------------BB-- ---B--------------B--- ---B--------------B--- ---B--------------B--- --BB--------------BB-- --A----------------A-- --A----------------A-- -A------------------A- -A--ADDA------------A- -A--DEED------------A- -A--DEED------------A- -A---DDA------------A- --A----------------A-- ---A--------------A--- ---A--------------A--- ----A------------A---- -----AAAAAAAAAAAA----- 
-----BB--------BB----- ----BB----------BB---- ----B------------B---- ---B--------------B--- ---B--------------B--- --B----------------B-- --B----------------B-- --B----------------B-- --B----------------B-- ---B--------------B--- ---B--------------B--- ---B--------------B--- --BB--------------BB-- --A----------------A-- -A------------------A- -A------------------A- AA------------------AA AA------------------AA -A------------------A- -A------------------A- --A----------------A-- --AA--------------AA-- ---A--------------A--- ----A------------A---- -----AAAAAAAAAAAA----- 
-----BB--------BB----- ----BB----------BB---- ----B------------B---- ---B--------------B--- ---B--------------B--- --B----------------B-- --B----------------B-- --B----------------B-- --B----------------B-- ---B--------------B--- ---B--------------B--- ---B--------------B--- --BB--------------BB-- --A----------------A-- -A------------------A- -A------------------A- AA------------------AA AA------------------AA -A------------------A- -A------------------A- --A----------------A-- --AA--------------AA-- ---A--------------A--- ----A------------A---- -----AAAAAAAAAAAA----- 
------BB------BB------ -----BB--------BB----- ----BB----------BB---- ----B------------B---- ---B--------------B--- ---B--------------B--- --B----------------B-- --B----------------B-- --BB--------------BB-- ---B--------------B--- ---B--------------B--- ---B--------------B--- --BB--------------BB-- --A----------------A-- --A----------------A-- -A------------------A- -A--ADDA------------A- -A--DEED------------A- -A--DEED------------A- -A---DDA------------A- --A----------------A-- ---A--------------A--- ---A--------------A--- ----A------------A---- -----AAAAAAAAAAAA----- 
-------BB----BB------- ------BB------BB------ -----BB--------BB----- ----BB----------BB---- ----BB----------BB---- ---B--------------B--- ---B--------------B--- --BB--------------BB-- ---BB------------BB--- ---BB------------BB--- ----B------------B---- ---BA------------AB--- ---BA------------AB--- --AA--------------AA-- --A----------------A-- --A----------------A-- -AA-ACCAA-----ADDA-AA- -A--CEGEA-----DEED--A- -AA-CEGEA-----DEED-AA- --A-ACCAA-----ADD--A-- --A----------------A-- ---A--------------A--- ---A--------------A--- ----AA----------AA---- ------AAAAAAAAAA------ 
--------BBAABB-------- -------BBAAAABB------- ------BAAA--AAAB------ -----B----------B----- ----BBB--------BBB---- ----BB----------BB---- ---BBB----------BBB--- ---BB------------BB--- ---BB------------BB--- ----B------------B---- ----BA----------AB---- ----AA----------AA---- ---BAA----------AAB--- ---AAA----------AAA--- --AAAA----------AAAA-- --A--AA--------AA--A-- --A-ACCCAAAAAAACCA-A-- --A-CE-ECA--AAEGEC-A-- --A-CE-ECAAAAAEGEC-A-- --AAACCCAAAAAAACCAAA-- ---A-AAAAAAAAAAAA-A--- ---A--------------A--- ----A------------A---- ----AA----------AA---- ------AAAAAAAAAA------ 
----------BB---------- --------BBBBBB-------- -------BBBAABBB------- ------BBBB--BBBB------ -----BBBB----BBBB----- ----BBBB------BBBB---- ----BBA--------ABB---- ----BB----------BB---- ----BB----------BB---- ----BB----------BB---- -----AA--------AA----- ----AAA--------AAA---- ----AA----------AA---- ----AAA--------AAA---- ---AAAAA------AAAAA--- ---AAAAAA----AAAAAA--- --A-ADDDAAAAAACCCA-A-- --A-C---DAAAACE-EC-A-- --AAC---DAAAACE-ECAA-- ---AADDDAAAAAACCCAA--- ---A-AAAAAAAAAAAA-A--- ---A--------------A--- ----A------------A---- -----AAAAA--AAAAA----- ----------AA---------- 
---------------------- ---------------------- ---------BBBB--------- --------BBBBBB-------- ------BBBBAABBBB------ -----BBBBA--ABBBB----- -----BBA------ABB----- -----BAA------AAB----- -----BA--------AB----- -----BA--------AB----- -----AA--------AA----- -----AA--------AA----- -----AAA------AAA----- ----AAAA------AAAA---- ----AAAAAA--AAAAAA---- ---AAAAAAAAAAAAAAAA--- ---AA---AAAAA-DDD-A--- ---A-----AAAAD---CA--- ---A-----AAAAD---CA--- ---AA---A-----DDD-A--- ---AAA---AAAA---AAA--- ----A-----AA-----A---- ----AA---AAAA---AA---- ------AAAAAAAAAA------ ---------------------- 
---------------------- ---------------------- ---------------------- ----------BB---------- ---------BBBB--------- -------BBBAABBB------- ------BBAA--AABB------ -----BBBA----ABBB----- -----BAA------AAB----- -----BAA------AAB----- ------AA------AA------ ------AA------AA------ -------AA----AA------- --------AA--AA-------- ---------AAAA--------- ----------AA---------- ---------------------- ---------------------- ----------AA---------- ---A-----AAAA-----A--- ----AAAAAAAAAAAAAA---- ----AAA-AAAAAA-AAA---- -----AAAAA--AAAAA----- ---------------------- ---------------------- 
---------------------- ---------------------- ---------------------- ---------------------- ---------------------- ----------BB---------- --------BFFFFB-------- -------BF----FB------- ------BBA----ABB------ ------BAA----AAB------ -------AA----AA------- -------AA----AA------- --------AA--AA-------- ---------AAAA--------- ----------AA---------- ---------------------- ---------------------- ---------------------- ---------------------- ---------------------- ---B--------------B--- ----BBBBB----BBBBB---- ---------------------- ---------------------- ---------------------- 
---------------------- ---------------------- ---------------------- ---------------------- ---------------------- ---------------------- ---------------------- ---------------------- --------BBBBBB-------- -------BBA--ABB------- -------AAA--AAA------- --------AAAAAA-------- ---------AAAA--------- ----------AA---------- ---------------------- ---------------------- ---------------------- ---------------------- ---------------------- ---------------------- ---------------------- ---------------------- ---------------------- ---------------------- ---------------------- 
---------------------- ---------------------- ---------------------- ---------------------- ---------------------- ---------------------- ---------------------- ---------------------- ---------------------- ---------AAAA--------- --------AAAAAA-------- ---------AAAA--------- ----------AA---------- ---------------------- ---------------------- ---------------------- ---------------------- ---------------------- ---------------------- ---------------------- ---------------------- ---------------------- ---------------------- ---------------------- ---------------------- 
