model
size = 24 20 24, scale = 0.05, origin = -y
material 
  colors = A:#DDD B:#777 C:#111
voxels
------------------------ ------------------------ ------------------------ ------------------------ ------------------------ ------------------------ ------------------------ ------------------------ ------------------------ ------------------------ ----------AAAA---------- -------AAAAAAAAAA------- ------------------------ ------------------------ ------------------------ ------------------------ ------------------------ ------------------------ ------------------------ ------------------------ 
------------------------ ------------------------ ------------------------ ------------------------ ------------------------ ------------------------ ------------------------ ------------------------ ------------------------ ----------AAAA---------- -------AAAAAAAAAA------- -----AA----------AA----- ------------------------ ------------------------ ------------------------ ------------------------ ------------------------ ------------------------ ------------------------ ------------------------ 
------------------------ ------------------------ ------------------------ ------------------------ ------------------------ ------------------------ ------------------------ ------------------------ ----------AAAA---------- -------AAAAAAAAAA------- -----AA----------AA----- ----A--------------A---- ------------------------ ------------------------ ------------------------ ------------------------ ------------------------ ------------------------ ------------------------ ------------------------ 
------BBBBBB------------ ------BBBBBB------------ -------BBBB------------- ------------------------ ------------------------ ------------------------ ------------------------ ------------------------ -------AAAAAAAAAA------- -----AA----------AA----- ----A--------------A---- ---A----------------A--- ------------------------ ------------------------ ------------------------ ------------------------ ------------------------ ------------------------ ------------------------ ------------------------ 
----BB------BB---------- ----BBBBBBBBBB---------- -----BBBBBBBB----------- ------BBBBBB------------ -------BBBB------------- ------------------------ ------------------------ --------AAAAAAAA-------- ------AA--------AA------ ----AA------------AA---- ---A----------------A--- --A------------------A-- ------------------------ ------------------------ ------------------------ ------------------------ ------------------------ ------------------------ ------------------------ ------------------------ 
---BB--------BB--------- ---BBB------BBB--------- ----BBBBBBBBBB---------- ----BBBBBBBBBB---------- -----BBBBBBBB----------- -------BBBB------------- -----------AA----------- -------AAAA--AAAA------- -----AA----------AA----- ---AA--------------AA--- --A------------------A-- -A--------------------A- ------------------------ ------------------------ ------------------------ ------------------------ ------------------------ ------------------------ ------------------------ ------------------------ 
---B----------B--------- ---BB--------BB--------- ---BBB------BBB--------- ----BBBBBBBBBB---------- ----BBBBBBBBBB---------- ------BBBBBB------------ --------AAAAAAAA-------- ------AA--------AA------ ----AA------------AA---- ---A----------------A--- --A------------------A-- -A--------------------A- ------------------------ ------------------------ ------------------------ ------------------------ ------------------------ ------------------------ ------------------------ ------------------------ 
--B------------B-------- --BB----------BB-------- ---BB--------BB--------- ---BBB------BBB--------- ----BBBBBBBBBB---------- -----BBAAAAAAA---------- -------AAAAAAAAAA------- -----AA----------AA----- ---AA--------------AA--- --A------------------A-- -A--------------------A- A----------------------A ------------------------ ------------------------ ------------------------ ------------------------ ------------------------ ------------------------ ------------------------ ------------------------ 
--B------------B-------- --BB----------BB-------- --BBB--------BBB-------- ---BBB------BBB--------- ---BBBBBBBBBBBB--------- ----BBBAAAAAAA---------- ------AAAA----AAAA------ ----AA------------AA---- ---A----------------A--- --A------------------A-- -A--------------------A- A----------------------A ------------------------ ------------------------ ------------------------ ------------------------ ------------------------ ------------------------ ------------------------ ------------------------ 
--B------------B-------- --BB----------BB-------- --BBB--------BBB-------- ---BBB------BBB--------- ---BBBBBBBBBBBB--------- ----BBBAAAAAAAA--------- ------AAA------AAA------ ----AA------------AA---- ---A----------------A--- --A------------------A-- -A--------------------A- A----------------------A ------------------------ ------------------------ ------------------------ ------------------------ ------------------------ ------------------------ ------------------------ ------------------------ 
--B------------B-------- --BB----------BB-------- --BBB--------BBB-------- ---BBB------BBB--------- ---BBBBBBBBBBBB--------- ----BBBAAAAAAAAA-------- ------AA--------AA------ ----AA------------AA---- --AA----------------AA-- -AA------------------AA- AA--------------------AA A----------------------A ------------------------ ------------------------ ------------------------ ------------------------ ------------------------ ------------------------ -----------CC----------- ------------------------ 
--B------------B-------- --BB----------BB-------- --BBB--------BBB-------- ---BBB------BBB--------- ---BBBBBBBBBBBB--------- ----BBBAAAAAAAAA-------- -----AAA---BB---AAA----- ----A------BB------A---- --AA-------BB-------AA-- -AA--------BB--------AA- AA---------BB---------AA A----------BB----------A -----------BB----------- -----------BB----------- -----------BB----------- -----------BB----------- -----------BB----------- -----------CC----------- ----------CCCC---------- -----------CC----------- 
--B------------B-------- --BB----------BB-------- ---BB--------BB--------- ---BBB------BBB--------- ----BBBBBBBBBB---------- -----BBAAAAAAAAA-------- -----AAA---BB---AAA----- ----A------BB------A---- --AA-------BB-------AA-- -AA--------BB--------AA- AA---------BB---------AA A----------BB----------A -----------BB----------- -----------BB----------- -----------BB----------- -----------BB----------- -----------BB----------- -----------CC----------- ----------CCCC---------- -----------CC----------- 
---B----------B--------- ---BB--------BB--------- ---BBB------BBB--------- ----BBBBBBBBBB---------- ----BBBBBBBBBB---------- ------BAAAAAAAAA-------- ------AA--------AA------ ----AA------------AA---- --AA----------------AA-- -AA------------------AA- AA--------------------AA A----------------------A ------------------------ ------------------------ ------------------------ ------------------------ ------------------------ ------------------------ -----------CC----------- ------------------------ 
---BB--------BB--------- ---BBB------BBB--------- ----BBBBBBBBBB---------- ----BBBBBBBBBB---------- -----BBBBBBBB----------- -------AAAAAAAA--------- ------AAA------AAA------ ----AA------------AA---- ---A----------------A--- --A------------------A-- -A--------------------A- A----------------------A ------------------------ ------------------------ ------------------------ ------------------------ ------------------------ ------------------------ ------------------------ ------------------------ 
----BB------BB---------- ----BBBBBBBBBB---------- -----BBBBBBBB----------- ------BBBBBB------------ -------BBBB------------- ----------AAAA---------- ------AAAA----AAAA------ ----AA------------AA---- ---A----------------A--- --A------------------A-- -A--------------------A- A----------------------A ------------------------ ------------------------ ------------------------ ------------------------ ------------------------ ------------------------ ------------------------ ------------------------ 
------BBBBBB------------ ------BBBBBB------------ -------BBBB------------- ------------------------ ------------------------ ------------------------ -------AAAAAAAAAA------- -----AA----------AA----- ---AA--------------AA--- --A------------------A-- -A--------------------A- A----------------------A ------------------------ ------------------------ ------------------------ ------------------------ ------------------------ ------------------------ ------------------------ ------------------------ 
------------------------ ------------------------ ------------------------ ------------------------ ------------------------ ------------------------ --------AAAAAAAA-------- ------AA--------AA------ ----AA------------AA---- ---A----------------A--- --A------------------A-- -A--------------------A- ------------------------ ------------------------ ------------------------ ------------------------ ------------------------ ------------------------ ------------------------ ------------------------ 
------------------------ ------------------------ ------------------------ ------------------------ ------------------------ ------------------------ -----------AA----------- -------AAAA--AAAA------- -----AA----------AA----- ---AA--------------AA--- --A------------------A-- -A--------------------A- ------------------------ ------------------------ ------------------------ ------------------------ ------------------------ ------------------------ ------------------------ ------------------------ 
------------------------ ------------------------ ------------------------ ------------------------ ------------------------ ------------------------ ------------------------ --------AAAAAAAA-------- ------AA--------AA------ ----AA------------AA---- ---A----------------A--- --A------------------A-- ------------------------ ------------------------ ------------------------ ------------------------ ------------------------ ------------------------ ------------------------ ------------------------ 
------------------------ ------------------------ ------------------------ ------------------------ ------------------------ ------------------------ ------------------------ ------------------------ -------AAAAAAAAAA------- -----AA----------AA----- ----A--------------A---- ---A----------------A--- ------------------------ ------------------------ ------------------------ ------------------------ ------------------------ ------------------------ ------------------------ ------------------------ 
------------------------ ------------------------ ------------------------ ------------------------ ------------------------ ------------------------ ------------------------ ------------------------ ----------AAAA---------- -------AAAAAAAAAA------- -----AA----------AA----- ----A--------------A---- ------------------------ ------------------------ ------------------------ ------------------------ ------------------------ ------------------------ ------------------------ ------------------------ 
------------------------ ------------------------ ------------------------ ------------------------ ------------------------ ------------------------ ------------------------ ------------------------ ------------------------ ----------AAAA---------- -------AAAAAAAAAA------- -----AA----------AA----- ------------------------ ------------------------ ------------------------ ------------------------ ------------------------ ------------------------ ------------------------ ------------------------ 
------------------------ ------------------------ ------------------------ ------------------------ ------------------------ ------------------------ ------------------------ ------------------------ ------------------------ ------------------------ ----------AAAA---------- -------AAAAAAAAAA------- ------------------------ ------------------------ ------------------------ ------------------------ ------------------------ ------------------------ ------------------------ ------------------------ 
