model
size = 18 8 8, scale = 0.05, origin = -y
material 
  colors = A:#111 B:#FC0 C:#EEE
voxels
------AAAAAA------ -----AACAACAA----- -----AAACCAAA----- -----AAACCAAA----- -----BACAACAB----- ------BAAAAB------ -------BAAB------- --------BB-------- 
-----AA----AA----- ----A-AA--AA-A---- ----A-AAAAAA-A---- -------AAAA------- ------------------ ------------------ ------------------ ------------------ 
---AAAA----AAAA--- --AA-AA----AA-AA-- --AA-AAA--AAA-AA-- --AB--AAAAAA--BA-- -BB------------BB- ------------------ ------------------ ------------------ 
--AAAA------AAAA-- -A--BAA----AAB--A- -A---AA----AA---A- -A----AAAAAA----A- B-------AA-------B ------------------ ------------------ ------------------ 
--AAAA------AAAA-- -A--BAA----AAB--A- -A---AA----AA---A- -A----AAAAAA----A- B-------AA-------B ------------------ ------------------ ------------------ 
---AAAA----AAAA--- --AA-AA----AA-AA-- --AA-AAA--AAA-AA-- --AB--AAAAAA--BA-- -BB------------BB- ------------------ ------------------ ------------------ 
-----AA----AA----- ----A-AA--AA-A---- ----A-AAAAAA-A---- -------AAAA------- ------------------ ------------------ ------------------ ------------------ 
------AAAAAA------ -----AACAACAA----- -----AAACCAAA----- -----AAACCAAA----- -----BACAACAB----- ------BAAAAB------ -------BAAB------- --------BB-------- 
