model
size = 19 30 31, scale = 0.05, origin = -y
material 
  colors = A:#111 B:#0F0 C:#E00 D:#777 E:#00E F:#93C G:#C09 H:#FF6 I:#F06 J:#F6F K:#FC9
voxels
------------------- ------------------- ------------------- ------------------- ------------------- ------------------- ------------------- ------------------- ------------------- ------------------- ------------------- ------------------- ------------------- ------------------- ------------------- ------------------- ------------------- ------------------- ------------------- ------------------- ------------------- ------------------- ------------------- ------------------- ------------------- ------------------- ------------------- ------------------- ------------------- ----CAAAAAAAAAC---- 
------------------- ------------------- ------------------- ------------------- ------------------- ------------------- ------------------- ------------------- ------------------- ------------------- ------------------- ------------------- ------------------- ------------------- ------------------- ------------------- ------------------- ------------------- ------------------- ------------------- ------------------- ------------------- ------------------- ------------------- ------------------- ------------------- ------------------- ------------------- ------------------- ----C---------C---- 
------------------- ------------------- ------------------- ------------------- ------------------- ------------------- ------------------- ------------------- ------------------- ------------------- ------------------- ------------------- ------------------- ------------------- ------------------- ------------------- ------------------- ------------------- ------------------- ------------------- ------------------- ------------------- ------------------- ------------------- ------------------- ------------------- ------------------- ------------------- ----C---------C---- ----C---------C---- 
------------------- ------------------- ------------------- ------------------- ------------------- ------------------- ------------------- ------------------- ------------------- ------------------- ------------------- ------------------- ------------------- ------------------- ------------------- ------------------- ------------------- ------------------- ------------------- ------------------- ------------------- ------------------- ------------------- ------------------- ------------------- ------------------- ------------------- ----C---------C---- ----C---------C---- ------------------- 
------------------- ------------------- ------------------- ------------------- ------------------- ------------------- ------------------- ------------------- ------------------- ------------------- ------------------- ------------------- ------------------- ------------------- ------------------- ------------------- ------------------- ------------------- ------------------- ------------------- ------------------- ------------------- ------------------- ------------------- ------------------- ------------------- ----C---------C---- ----C---------C---- ------------------- ------------------- 
------------------- ------------------- ------------------- ------------------- ------------------- ------------------- ------------------- ------------------- ------------------- ------------------- ------------------- ------------------- ------------------- ------------------- ------------------- ------------------- ------------------- ------------------- ------------------- ------------------- ------------------- ------------------- ------------------- ------------------- ------------------- ----C---------C---- ----C---------C---- ------------------- ------------------- ------------------- 
------------------- ------------------- ------------------- ------------------- ------------------- ------------------- ------------------- ------------------- ------------------- ------------------- ------------------- ------------------- ------------------- ------------------- ------------------- ------------------- ------------------- ------------------- ------------------- ------------------- ------------------- ------------------- ------------------- ------------------- ----C---------C---- ----C---------C---- ------------------- ------------------- ------------------- ------------------- 
------------------- ------------------- ------------------- ------------------- ------------------- ------------------- ------------------- ------------------- ------------------- ------------------- ------------------- ------------------- ------------------- ------------------- ------------------- ------------------- ------------------- ------------------- ------------------- ------------------- ------------------- ------------------- ------------------- ----C---------C---- ----C---------C---- ------------------- ------------------- ------------------- ------------------- ------------------- 
------------------- ------------------- ------------------- ------------------- ------------------- ------------------- ------------------- ------------------- ------------------- ------------------- ------------------- ------------------- ------------------- ------------------- ------------------- ------------------- ------------------- ------------------- ------------------- ------------------- ------------------- ------------------- ----C---------C---- ----C---------C---- ------------------- ------------------- ------------------- ------------------- ------------------- ------------------- 
------------------- ------------------- ------------------- ------------------- ------------------- ------------------- ------------------- ------------------- ------------------- ------------------- ------------------- ------------------- ------------------- ------------------- ------------------- ------------------- ------------------- ------------------- ------------------- ------------------- ------------------- ----C---------C---- ----C---------C---- ------------------- ------------------- ------------------- ------------------- ------------------- ------------------- ------------------- 
------------------- ------------------- ------------------- ------------------- ------------------- ------------------- ------------------- ------------------- ------------------- ------------------- ------------------- ------------------- ------------------- ------------------- ------------------- ------------------- ------------------- ------------------- ------------------- ------------------- ----CFFFFFFFFFC---- ----CEEEEEEEEEC---- ----EEEEEEEEEEE---- ------------------- ------------------- ------------------- ------------------- ------------------- ------------------- ------------------- 
------------------- ------------------- ------------------- ------------------- ------------------- ------------------- ------------------- ------------------- ------------------- ------------------- ------------------- ------------------- ------------------- ------------------- ------------------- ------------------- ------------------- ------------------- ----CCCCCCCCCCC---- ----CFFFFFFFFFC---- ----CBBBBBBBBBC---- ----E---------E---- ----E---------E---- ------------------- ------------------- ------------------- ------------------- ------------------- ------------------- ------------------- 
------------------- ------------------- ------------------- ------------------- ------------------- ------------------- ------------------- ------------------- ------------------- ------------------- ------------------- ------------------- ------------------- ------------------- ------------------- ------------------- ------------------- ------------------- ----CGGGGGGGGGC---- ----CCCCCCCCCCC---- ----FBBBBBBBBBF---- ----E---------E---- ----E---------E---- ------------------- ------------------- ------------------- ------------------- ------------------- ------------------- ------------------- 
------------------- ------------------- ------------------- ------------------- ------------------- ------------------- ------------------- ------------------- ------------------- ------------------- ------------------- ------------------- ------------------- ------------------- ------------------- ------------------- ------------------- ----CGGGGGGGGGC---- ----CBBBBBBBBBC---- ----FBBBBBBBBBF---- ----F---------F---- ----E---------E---- ----E---------E---- ------------------- ------------------- ------------------- ------------------- ------------------- ------------------- ------------------- 
------------------- ------------------- ------------------- ------------------- ------------------- ------------------- ------------------- ------------------- ------------------- ------------------- ------------------- ------------------- ------------------- ------------------- ------------------- ------------------- ----CIIIIIIIIIC---- ----CBBBBBBBBBC---- ----G---------G---- ----F---------F---- ----F---------F---- ----E---------E---- ----E---------E---- ------------------- ------------------- ------------------- ------------------- ------------------- ------------------- ------------------- 
------------------- ------------------- ------------------- ------------------- ------------------- ------------------- ------------------- ------------------- ------------------- ------------------- ------------------- ------------------- ------------------- ------------------- ------------------- ----CIIIIIIIIIC---- ----CBBBBBBBBBC---- ----G---------G---- ----G---------G---- ----F---------F---- ----F---------F---- ----E---------E---- ----E---------E---- ------------------- ------------------- ------------------- ------------------- ------------------- ------------------- ------------------- 
------------------- ------------------- ------------------- ------------------- ------------------- ------------------- ------------------- ------------------- ------------------- ------------------- ------------------- ------------------- ------------------- ------------------- ----CJJJJJJJJJC---- ----CBBBBBBBBBC---- ----I---------I---- ----G---------G---- ----G---------G---- ----F---------F---- ----F---------F---- ----E---------E---- ----E---------E---- ------------------- ------------------- ------------------- ------------------- ------------------- ------------------- ------------------- 
------------------- ------------------- ------------------- ------------------- ------------------- ------------------- ------------------- ------------------- ------------------- ------------------- ------------------- ------------------- ------------------- ----CJJJJJJJJJC---- ----CBBBBBBBBBC---- ----I---------I---- ----I---------I---- ----G---------G---- ----G---------G---- ----F---------F---- ----F---------F---- ----E---------E---- ----E---------E---- ------------------- ------------------- ------------------- ------------------- ------------------- ------------------- ------------------- 
------------------- ------------------- ------------------- ------------------- ------------------- ------------------- ------------------- ------------------- ------------------- ------------------- ------------------- ------------------- ----CKKKKKKKKKC---- ----CBBBBBBBBBC---- ----J---------J---- ----I---------I---- ----I---------I---- ----G---------G---- ----G---------G---- ----F---------F---- ----F---------F---- ----E---------E---- ----E---------E---- ------------------- ------------------- ------------------- ------------------- ------------------- ------------------- ------------------- 
------------------- ------------------- ------------------- ------------------- ------------------- ------------------- ------------------- ------------------- ------------------- ------------------- ------------------- ----CCCCCCCCCCC---- ----C---------C---- ----J---------J---- ----J---------J---- ----I---------I---- ----I---------I---- ----G---------G---- ----G---------G---- ----F---------F---- ----F---------F---- ----E---------E---- ----E---------E---- ------------------- ------------------- ------------------- ------------------- ------------------- ------------------- ------------------- 
------------------- ------------------- D-D-------------D-D D-D-------------D-D D-D-------------D-D D-D-------------D-D D-D-------------D-D ------------------- ------------------- ------------------- ----CHHHHHHHHHC---- ----CBBBBBBBBBC---- ----K---------K---- ----J---------J---- ----J---------J---- ----I---------I---- ----I---------I---- ----G---------G---- ----G---------G---- ----F---------F---- ----F---------F---- ----E---------E---- ----E---------E---- ------------------- ------------------- ------------------- ------------------- ------------------- ------------------- ------------------- 
------------------- D-D-------------D-D D-A-------------A-A A-A-------------A-A A-A-------------A-A A-A-------------A-A A-A-------------A-A D-D-------------D-D ------------------- ----CHHHHHHHHHC---- ----CBBBBBBBBBC---- ----KBBBBBBBBBK---- ----K---------K---- ----J---------J---- ----J---------J---- ----I---------I---- ----I---------I---- ----G---------G---- ----G---------G---- ----F---------F---- ----F---------F---- ----E---------E---- ----E---------E---- ------------------- ------------------- ------------------- ------------------- ------------------- ------------------- ------------------- 
D-D-------------D-D A-A-------------A-A A-A-------------A-A A-A-------------A-A A-A-------------A-A A-A-------------A-A A-A-------------A-A A-A-------------A-A D-D-CHHHHHHHHHC-D-D ----CBBBBBBBBBC---- ----HBBBBBBBBBH---- ----KBBBBBBBBBK---- ----K---------K---- ----J---------J---- ----J---------J---- ----I---------I---- ----I---------I---- ----G---------G---- ----G---------G---- ----F---------F---- ----F---------F---- ----E---------E---- ----E---------E---- ------------------- ------------------- ------------------- ------------------- ------------------- ------------------- ------------------- 
D-D-------------D-D A-A-------------A-A A-A-------------A-A A-A-------------A-A A-A-------------A-A A-A-------------A-A A-A-------------A-A A-A-C---------C-A-A D-D-CHHHHHHHHHC-D-D ----HBBBBBBBBBH---- ----HBBBBBBBBBH---- ----KBBBBBBBBBK---- ----K---------K---- ----J---------J---- ----J---------J---- ----I---------I---- ----I---------I---- ----G---------G---- ----G---------G---- ----F---------F---- ----F---------F---- ----E---------E---- ----E---------E---- ------------------- ------------------- ------------------- ------------------- ------------------- ------------------- ------------------- 
D-D-------------D-D A-A-------------A-A A-A-------------A-A A-A-------------A-A CCCCCCCCCCCCCCCCCCC A-A-C---------C-A-A A-A-C---------C-A-A A-A-C---------C-A-A D-D-HHHHHHHHHHH-D-D ----HHHHHHHHHHH---- ----HHHHHHHHHHH---- ----KKKKKKKKKKK---- ----KKKKKKKKKKK---- ----JJJJJJJJJJJ---- ----JJJJJJJJJJJ---- ----IIIIIIIIIII---- ----IIIIIIIIIII---- ----GGGGGGGGGGG---- ----GGGGGGGGGGG---- ----FFFFFFFFFFF---- ----FFFFFFFFFFF---- ----EEEEEEEEEEE---- ----EEEEEEEEEEE---- --------------C---- --------------C---- --------------C---- --------------C---- --------------C---- --------------C---- --------------C---- 
D-D-------------D-D A-A-------------A-A A-A-------------A-A A-A-------------A-A A-A-------------A-A A-H-------------A-A A-A-------------A-A A-A-------------A-A D-D-------------D-D ------------------- ------------------- ------------------- ------------------- ------------------- ------------------- ------------------- ------------------- ------------------- ------------------- ------------------- ------------------- ------------------- ------------------- ------------------- ------------------- --------------H---- --------------I---- --------------H---- --------------I---- --------------H---- 
D-D-------------D-D A-A-------------A-A A-A-------------A-A A-A-------------A-A A-A-------------A-A A-A-------------A-A A-A-------------A-A A-A-------------A-A D-D-------------D-D ------------------- ------------------- ------------------- ------------------- ------------------- ------------------- ------------------- ------------------- ------------------- ------------------- ------------------- ------------------- ------------------- ------------------- ------------------- ------------------- --------------I---- --------------G---- --------------G---- --------------G---- --------------I---- 
------------------- D-D-------------D-D A-A-------------A-A A-A-------------A-A A-A-------------A-A A-A-------------A-A A-A-------------A-A D-D-------------D-D ------------------- ------------------- ------------------- ------------------- ------------------- ------------------- ------------------- ------------------- ------------------- ------------------- ------------------- ------------------- ------------------- ------------------- ------------------- ------------------- ------------------- ------------------- --------------G---- --------------J---- --------------G---- ------------------- 
------------------- ------------------- D-D-------------D-D D-D-------------D-D D-D-------------D-D D-D-------------D-D D-D-------------D-D ------------------- ------------------- ------------------- ------------------- ------------------- ------------------- ------------------- ------------------- ------------------- ------------------- ------------------- ------------------- ------------------- ------------------- ------------------- ------------------- ------------------- ------------------- ------------------- --------------I---- --------------I---- --------------I---- ------------------- 
------------------- ------------------- ------------------- ------------------- ------------------- ------------------- ------------------- ------------------- ------------------- ------------------- ------------------- ------------------- ------------------- ------------------- ------------------- ------------------- ------------------- ------------------- ------------------- ------------------- ------------------- ------------------- ------------------- ------------------- ------------------- ------------------- ------------------- --------------I---- ------------------- ------------------- 
------------------- ------------------- ------------------- ------------------- ------------------- ------------------- ------------------- ------------------- ------------------- ------------------- ------------------- ------------------- ------------------- ------------------- ------------------- ------------------- ------------------- ------------------- ------------------- ------------------- ------------------- ------------------- ------------------- ------------------- ------------------- ------------------- ------------------- --------------H---- ------------------- ------------------- 
