model
size = 32 30 32, scale = 0.05, origin = -y
material 
  colors = A:#AAA B:#444 C:#888 D:#222 E:#555 F:#777 G:#D00 H:#F60 I:#960 J:#09F K:#EEE L:#FC9 M:#F90 N:#FC3 O:#FFC
voxels
3C26-3C65-2B461-L3(31-E)31-L271-3C26-3C-C28-C2-A28-A-BA28-A3-2B492-E335-3C26-3C66-A26-A2-2BA26-A5-2B459-E466-A24-A4-2BA24-A7-2B426-E499-A22-A6-2BA22-A9-2B392-2(2A30-)2A468-A20-A8-2BA20-A11-2B326-4A28-4A20-6E2-4A28-4A29-2A469-A18-A10-2BA18-A13-2B162-2(C31-)C2-4A25-C2(-6F21-4C)-6F18-7E-6F20-4C2-6F27-4A501-A16-A12-2BA16-A15-2B129-C31-C2-4D25-C-6A24-C2(8A20-4C)8A17-7E8A18-5C-8A19-4C3-4A534-2(A14-)2BA2B12-A114-4C4A24-3C6A23-2C8A22-2C2(8A18-6C)8A17-7E8A18-4C2-8A19-3C3-6A26-6F26-6A380-2D120-A4-B2IB4-A16-2BA2B2-B2IB4-A23-B2IB28-4B25-KC6A24-K8A23-K9A22-K9A2(17-5C10A)16-7E9A17-4C-10A18-3C3-6A21-2C3-F2A3F26-6A379-4D120-A2-6B2-A20-A2-6B2-A18-2BA8B2-A23-6B21-C2-D8A20-2(C2-D9A19-)C2-D8A2(F17-5C9A)F16-7E8AF17-4C-9AF18-3C3-6A21-2C3-F2A3F26-6A378-6D28-2D30-2C30-2D26-3(A8BA22-)A8BA3(18-2CKD10A)18-2CKD2(9AF17-5C)9AF16-7E8AF17-2C3-9AF18-C5-6A26-F2A3F26-6A377-8D26-4D28-4C28-4D25-3(10B22-)10B4(18-2C2-10A)17-3C14AE14-3C14AE13-7E11AE14-2C2-12A2E21-6A26-F2A3F26-6A28-2A61-4E251-6G24-10D24-6D26-6C26-6D23-3(12B20-)12B3(16-3C-12A)16-3C2-10A17-3C14A15-3C14A14-7E11A19-12A3E20-6A26-F2A3F26-6A27-4A28-4B27-B4-B187-4H28-4H27-6G23-12D23-6D26-6C26-6D22-4(14B18-)2(14A18-)14A20-10A21-12AE19-2(11AJ20-)12A4E19-6A26-F2A3F2(26-6A)26-6B25-E6-E26-B2-B61-2O30-2N30-2M29-4H28-4H27-6G23-12D23-6D26-6C26-6D22-3(I12BI18-)14B3(18-14A)20-10A19-2C12AE17-2(2C11AJ18-)2C12A5E17-3(8A24-)8A25-6B25-E6-E59-2B30-2O30-2N30-2M29-4H28-4H27-6G23-12D23-6D26-6C26-6D22-3(I12BI18-)14B3(18-14A)20-10A19-2C12AE16-3C11AJ12-L4-3C11AJ7-L4-E5-2C12A5E2-E4-10E8A10E4-E9-8A9-E4-L9-8A9-L14-8A25-6B25-E6-E59-2B125-4H28-4H27-6G23-12D23-6D26-6C26-6D22-4(14B18-)2(14A18-)14A20-10A19-2C12AE16-3C11AJ17-3C11AJ18-2C12A4E19-6A26-F3A2F2(26-6A)26-6B25-E6-E26-B2-B219-6G24-10D24-6D26-6C26-6D23-4(12B20-)2(12A20-)12A21-10A19-3(C14A17-)2C12A3E20-6A26-F3A2F26-6A27-4A28-4B27-B4-B281-8D26-4D28-4C28-4D25-4(10B22-)3(10A22-)10A20-2(14AE17-)14AE18-12A2E21-6A26-F3A2F26-6A28-2A61-4E283-6D28-2D30-2C30-2D26-4(A8BA22-)3(10A22-)9A4(F22-F8A)F24-6A26-F3A2F26-6A379-4D120-2(A2-6B2-A20-)A2-6B2-A23-6B25-8A23-2(10A22-)9A2(F22-F8A)F24-J6AF22-F8AF24-6A26-F3A2F26-6A380-2D120-A4-B2IB4-A18-A4-B2IB4-A23-B2IB28-4B27-6A25-8A23-2(10A22-)3(F9A22-)F9A24-6A26-F3A2F26-6A469-A14-A16-A14-A118-4A27-6A25-5(8A24-)8A25-6A26-6F26-6A436-A16-A14-A16-A181-4D27-6A25-4(8A24-)8A26-4A468-A18-A12-A18-A244-4A27-4(6F26-)6F27-4A435-A20-A10-A20-A339-3(4A28-)4A29-2A403-A22-A8-A22-A403-2(2A30-)2A402-A24-A6-A24-A435-E335-3C26-3C66-A26-A4-A26-A466-E335-3C26-3C-C28-C2(2-A28-A)497-E335-3C26-3C528-L3(31-E)31-L271-
