model
size = 32, scale = 0.05, origin = -y
material 
  colors = A:#AAA B:#444 C:#222 D:#EEE E:#BBB F:#960 G:#888 H:#DDD I:#D00 J:#F60 K:#A00 L:#6CF M:#555 N:#FFC O:#FC3 P:#F90
voxels
32-3C26-3C961-G28-G-CGC26-CGC-G28-G2(2-A28-A)897-3C26-3C66-A26-A4-A26-A997-A24-A6-A24-A999-A22-A8-A22-A1001-A20-A10-A20-A1003-A18-A12-A18-A1005-A16-A14-A16-A1007-A14-A16-A14-A887-2C120-A4-B2FB4-A18-A4-B2FB4-A23-B2FB28-4B2(28-A2EA)28-4A5(28-M2-M)28-4E29-2E477-4C120-2(A2-6B2-A20-)A2-6B2-A23-6B3(26-D4AD)26-DA2FA4(D26-DB2-B)D26-DA2FAD27-D2AD29-2D444-6C28-2C30-2G30-2C26-3(A8BA22-)A8BA23-4(H6AH24-)H2A2F2A3(H24-HAB2-BA)H24-H2A2F2AH25-H4AH27-H2AH29-2H411-8C26-4C28-4G28-4C25-4(10B22-)5(E8AE22-)E3A2F3A2(E22-E2AB2-B2A)E22-E3A2F3AE23-E6AE25-E4AE27-E2AE29-2E348-6I24-10C24-6C26-6G26-6C23-4(K10BK20-)6(D10AD20-)2(D4A2L4AD20-)D10AD20-2D8A2D21-2D6A2D23-2D4A2D25-2D2A2D27-4D29-2D221-4J28-4J27-6I23-12C23-6C26-6G26-6C22-4(14B18-)4(14A18-)14A19-F10AF20-F10AF19-2(14A18-)14A19-12A21-10A23-8A25-6A27-D3A29-2A94-2N30-2O30-2P29-4J28-4J27-6I23-12C23-6C26-6G26-6C22-3(F12BF18-)14B4(18-B12AB)18-BF10AFB20-L8AL22-L8AL20-BF10AF3(B18-B12A)B19-B10AB21-B8AB23-B6AB25-B4AB27-B2AB29-2B62-2N30-2O30-2P29-4J28-4J27-6I23-12C23-6C26-6G26-6C22-3(F12BF18-)14B4(18-B12AB)18-BF10AFB20-L8AL22-L8AL20-BF10AF3(B18-B12A)B19-B10AB21-B8AB23-B6AB25-B4AB27-B2AB29-2B157-4J28-4J27-6I23-12C23-6C26-6G26-6C22-4(14B18-)4(14A18-)14A19-F10AF20-F10AF19-2(14A18-)14A19-12A21-10A23-8A25-6A27-4A29-2A252-6I24-10C24-6C26-6G26-6C23-4(K10BK20-)6(D10AD20-)2(D4A2L4AD20-)D10AD20-2D8A2D21-2D6A2D23-2D4A2D25-2D2A2D27-4D29-2D315-8C26-4C28-4G28-4C25-4(10B22-)5(E8AE22-)E3A2F3A2(E22-E2AB2-B2A)E22-E3A2F3AE23-E6AE25-E4AE27-E2AE29-2E380-6C28-2C30-2G30-2C26-3(A8BA22-)A8BA23-4(H6AH24-)H2A2F2A3(H24-HAB2-BA)H24-H2A2F2AH25-H4AH27-H2AH29-2H413-4C120-2(A2-6B2-A20-)A2-6B2-A23-6B3(26-D4AD)26-DA2FA4(D26-DB2-B)D26-DA2FAD27-D2AD29-2D446-2C120-A4-B2FB4-A18-A4-B2FB4-A23-B2FB28-4B2(28-A2EA)28-4A5(28-B2-B)28-4E29-2E567-A14-A16-A14-A943-A16-A14-A16-A941-A18-A12-A18-A939-A20-A10-A20-A937-A22-A8-A22-A935-A24-A6-A24-A835-3C26-3C66-A26-A4-A26-A835-G28-G-CGC26-CGC-G28-G2(2-A28-A)897-3C26-3C960-
