model
size = 22 25 20, scale = 0.05, origin = -y
material 
  colors = A:#FF0 B:#888 C:#222
voxels
----AAAAAAAAAAAAAA---- ----AAAAAAAAAAAAAA---- ----AAAAAAAAAAAAAA---- ----BBBBBBBBBBBBBB---- ----BBBBBBBBBBBBBB---- ----AAAAAAAAAAAAAA---- ----AAAAAAAAAAAAAA---- ----AAAAAAAAAAAAAA---- ----BBBBBBBBBBBBBB---- ----BBBBBBBBBBBBBB---- ----AAAAAAAAAAAAAA---- ----AAAAAAAAAAAAAA---- ----AAAAAAAAAAAAAA---- ----AAAAAAAAAAAAAA---- ----AAAAAAAAAAAAAA---- ----AAAAAAAAAAAAAA---- ----AAAA------AAAA---- ----AAA--------AAA---- ---------------------- ---------------------- ---------------------- ---------------------- ---------------------- ---------------------- ---------------------- 
---A--------------A--- ---A--------------A--- ---A--------------A--- ---B--------------B--- ---B--------------B--- ---A--------------A--- ---A--------------A--- ---A--------------A--- ---B--------------B--- ---B--------------B--- ---A--------------A--- ---A--------------A--- ---A--------------A--- ---A--------------A--- ---A--------------A--- ---A--------------A--- ---A--------------A--- ---AAA----------AAA--- ----AA----------AA---- ----A------------A---- ----A------------A---- ---------------------- ---------------------- ---------------------- ---------------------- 
--A----------------A-- --A----------------A-- --A----------------A-- --B----------------B-- --B----------------B-- --A----------------A-- --A----------------A-- --A----------------A-- --B----------------B-- --B----------------B-- --A----------------A-- --A----------------A-- --A----------------A-- --A----------------A-- --A----------------A-- --A----------------A-- --A----------------A-- --AA--------------AA-- ---A--------------A--- ---A--------------A--- ---AA------------AA--- ----A------------A---- ---------------------- ---------------------- ---------------------- 
-A------------------A- -A------------------A- -A------------------A- -B------------------B- -B------------------B- -A------------------A- -A------------------A- -A------------------A- -B------------------B- -B------------------B- -A------------------A- -A------------------A- -A------------------A- -A------------------A- -A------------------A- -A------------------A- -A------------------A- -AA----------------AA- --A----------------A-- --A----------------A-- --AA--------------AA-- ---AA------------AA--- ----A------------A---- ---------------------- ---------------------- 
A--------------------A A--------------------A A--------------------A B--------------------B B--------------------B A--------------------A A--------------------A A--------------------A B--------------------B B--------------------B A--------------------A A--------------------A A--------------------A A--------------------A A--------------------A A--------------------A A--------------------A AA------------------AA AA------------------AA AA------------------AA -AA----------------AA- --AA--------------AA-- ---AA------------AA--- ----A------------A---- ---------------------- 
---------------------- ---------------------- ---------------------- ---------------------- ---------------------- ---------------------- A--------------------A A--------------------A ---------------------- ---------------------- ---------------------- ---------------------- ---------------------- ---------------------- ---------------------- ---------------------- ---------------------- ---------------------- ---------------------- ---------------------- -A------------------A- -AA----------------AA- --AA--------------AA-- ---AA------------AA--- ---------------------- 
---------------------- ---------------------- ---------------------- ---------------------- ---------------------- ---------------------- A--------------------A A--------------------A ---------------------- ---------------------- ---------------------- ---------------------- ---------------------- ---------------------- ---------------------- ---------------------- ---------------------- ---------------------- ---------------------- ---------------------- ---------------------- -A------------------A- -AA----------------AA- --AAA------------AAA-- ----A------------A---- 
---------------------- ---------------------- ---------------------- ---------------------- ---------------------- ---------------------- A--------------------A A--------------------A ---------------------- ---------------------- ---------------------- ---------------------- ---------------------- ---------------------- ---------------------- ---------------------- ---------------------- ---------------------- ---------------------- ---------------------- ---------------------- ---------------------- -A------------------A- -AAA--------------AAA- --AAA------------AAA-- 
---------------------- ---------------------- ---------------------- ---------------------- ---------------------- ---------------------- C--------------------C C--------------------C ---------------------- ---------------------- ---------------------- ---------------------- ---------------------- ---------------------- ---------------------- ---------------------- ---------------------- ---------------------- ---------------------- ---------------------- ---------------------- ---------------------- ---------------------- -A------------------A- -AAAA------------AAAA- 
---------------------- ---------------------- ---------------------- ---------------------- ---------------------- ---------------------- A--------------------A A--------------------A ---------------------- ---------------------- ---------------------- ---------------------- ---------------------- ---------------------- ---------------------- ---------------------- ---------------------- ---------------------- ---------------------- ---------------------- ---------------------- ---------------------- ---------------------- ---------------------- -AAA--------------AAA- 
---------------------- ---------------------- ---------------------- ---------------------- ---------------------- ---------------------- C--------------------C C--------------------C ---------------------- ---------------------- ---------------------- ---------------------- ---------------------- ---------------------- ---------------------- ---------------------- ---------------------- ---------------------- ---------------------- ---------------------- ---------------------- ---------------------- ---------------------- ---------------------- -AAA--------------AAA- 
---------------------- ---------------------- ---------------------- ---------------------- ---------------------- ---------------------- A--------------------A A--------------------A ---------------------- ---------------------- ---------------------- ---------------------- ---------------------- ---------------------- ---------------------- ---------------------- ---------------------- ---------------------- ---------------------- ---------------------- ---------------------- ---------------------- ---------------------- -A------------------A- -AAAA------------AAAA- 
---------------------- ---------------------- ---------------------- ---------------------- ---------------------- ---------------------- A--------------------A A--------------------A ---------------------- ---------------------- ---------------------- ---------------------- ---------------------- ---------------------- ---------------------- ---------------------- ---------------------- ---------------------- ---------------------- ---------------------- ---------------------- ---------------------- -A------------------A- -AAA--------------AAA- --AAA------------AAA-- 
---------------------- ---------------------- ---------------------- ---------------------- ---------------------- ---------------------- A--------------------A A--------------------A ---------------------- ---------------------- ---------------------- ---------------------- ---------------------- ---------------------- ---------------------- ---------------------- ---------------------- ---------------------- ---------------------- ---------------------- ---------------------- -A------------------A- -AA----------------AA- --AAA------------AAA-- ----A------------A---- 
---------------------- ---------------------- ---------------------- ---------------------- ---------------------- ---------------------- A--------------------A A--------------------A ---------------------- ---------------------- ---------------------- ---------------------- ---------------------- ---------------------- ---------------------- ---------------------- ---------------------- ---------------------- ---------------------- ---------------------- -A------------------A- -AA----------------AA- --AA--------------AA-- ---AA------------AA--- ---------------------- 
---------------------- A--------------------A A--------------------A B--------------------B B--------------------B A--------------------A A--------------------A A--------------------A B--------------------B B--------------------B A--------------------A A--------------------A A--------------------A A--------------------A A--------------------A A--------------------A A--------------------A AA------------------AA AA------------------AA AA------------------AA -AA----------------AA- --AA--------------AA-- ---AA------------AA--- ----A------------A---- ---------------------- 
---------------------- -A------------------A- -A------------------A- -B------------------B- -B------------------B- -A------------------A- -A------------------A- -A------------------A- -B------------------B- -B------------------B- -A------------------A- -A------------------A- -A------------------A- -A------------------A- -A------------------A- -A------------------A- -A------------------A- -AA----------------AA- --A----------------A-- --A----------------A-- --AA--------------AA-- ---AA------------AA--- ----A------------A---- ---------------------- ---------------------- 
---------------------- --A----------------A-- --A----------------A-- --B----------------B-- --B----------------B-- --A----------------A-- --A----------------A-- --A----------------A-- --B----------------B-- --B----------------B-- --A----------------A-- --A----------------A-- --A----------------A-- --A----------------A-- --A----------------A-- --A----------------A-- --A----------------A-- --AA--------------AA-- ---A--------------A--- ---A--------------A--- ---AA------------AA--- ----A------------A---- ---------------------- ---------------------- ---------------------- 
---------------------- ---A--------------A--- ---A--------------A--- ---B--------------B--- ---B--------------B--- ---A--------------A--- ---A--------------A--- ---A--------------A--- ---B--------------B--- ---B--------------B--- ---A--------------A--- ---A--------------A--- ---A--------------A--- ---A--------------A--- ---A--------------A--- ---A--------------A--- ---A--------------A--- ---AA------------AA--- ----A------------A---- ----A------------A---- ----A------------A---- ---------------------- ---------------------- ---------------------- ---------------------- 
---------------------- ----AAAAAAAAAAAAAA---- ----AAAAAAAAAAAAAA---- ----BBBBBBBBBBBBBB---- ----BBBBBBBBBBBBBB---- ----AAAAAAAAAAAAAA---- ----AAAAAAAAAAAAAA---- ----AAAAAAAAAAAAAA---- ----BBBBBBBBBBBBBB---- ----BBBBBBBBBBBBBB---- ----AAAAAAAAAAAAAA---- ----AAAAAAAAAAAAAA---- ----AAAAAAAAAAAAAA---- ----AAAAAAAAAAAAAA---- ----AAAAAAAAAAAAAA---- ----AAA--------AAA---- ----AA----------AA---- ----A------------A---- ---------------------- ---------------------- ---------------------- ---------------------- ---------------------- ---------------------- ---------------------- 
