model
size = 32 24 32, scale = 0.05, origin = -y
material 
  colors = A:#333 B:#F90 C:#9CF D:#E00 E:#C09 F:#36F G:#990 H:#CF0 I:#33F J:#444 K:#09F L:#F39 M:#00F N:#111 O:#0FF P:#3FF Q:#663 R:#C0F S:#EEE T:#9F0 U:#C93
voxels
167-2(3B12-)2B-N-2B8-2B-N-2B9-2B-3G-2B6-2B-3G-2B7-2B-G3-G-2B4-2B-G3-G-2B6-B-G5-G-B4-B-G5-G-B5-B-G7-G-B2-B-G7-G-2(B4-BNG7-GNB2QBNG7-GN)B4-B-G7-G-B2-B-G7-G-B5-B-G5-G-B4-B-G5-G-B6-2B-G3-G-2B4-2B-G3-G-2B7-2B-3G-2B6-2B-3G-2B9-2B-N-2B8-2B-N-2B2(12-3B)207-2(B14-B16-)B14-B15-3B12-3B8-L4-B3CB4-2L4-B3CB4-L3-M2-A4DCA2(2-M)2-AC4DA2-M5-MAD4-2DAM4-MA2D4-DAM6-AD7-DA4-AD7-DA5-2(AD9-DA2-AD9-DA4-)AD9-DC2ACD9-DA4-ID9-DC2ACD9-DI4-AD9-DA2-AD9-DA5-AD7-DA4-AD7-DA6-ACD5-D2A4-2AD5-DCA6-MACD3-DCAM4-MACD3-DCAM5-M2-AC3DCA2(2-M)2-AC3DCA2-M3-L4-B3CB4-2L4-B3CB4-L8-3B12-3B15-2(B14-B16-)B14-B48-L14-L16-B14-B15-3B12-3B14-3B12-3B13-5B10-5B11-A5BA8-A5BA9-2A5C2A6-2A5C2A7-3AD3H2C2A4-2A2C3HD3A5-3ADH3-HDC2A2-2ACDH3-HD3A4-2ADT5-HD2A2-2ADH5-TD2A3-2ACH7-HC4ACH7-HC2A2-2ACH3-S3-H2C2A2CH3-S3-HC2A2-IACH3-S3-H2C2A2CH3-S3-HCAI2-2ACH7-HC4ACH7-HC2A3-A2CH5-HC2A2-2ACH5-H2CA4-2A2CH3-HC2A4-2ACH3-H2C2A5-4A3HC3A4-3AC3H4A7-2A5C2A6-2A5C2A9-AB3CBA8-AB3CBA11-2BU2B10-2BU2B13-3B12-3B14-3B12-3B15-B14-B16-L14-L144-B14-B15-3B12-3B11-2A5B10-5B2A7-3AB3KBA8-AB3KB3A5-4AO3-OC3A2-3ACO3-O4A3-4AP5-O3A2-3AO5-P4A2-2ACK2-3J2-K2C2A2CK2-3J2-KC2A2-2ACK-5J-K2C2A2CK-5J-KC2A2-IACK-5J-K2C2A2CK-5J-KCAI2-2ACK2-3J2-K6AK2-3J2-KC2A2-A3CO5-P3A2-3AP5-O3CA3-4AP3-P4A2-4AP3-P4A6-2AB3KB3A4-3AB3KB2A2(10-5B)13-3B12-3B15-B14-B395-2(3AB3FB3A4-)5A5F4A2-4A5F5A2-4A2F3C2F8A2F3C2F4A2-4AF5CF8AF5CF4A2-I3AF5CF8AF5CF3AI2-4A2F3C2F8A2F3C2F4A2-5A5F4A2-4A5F5A4-3AB3FB4A2-4AB3FB3A580-A28-A-2A28-2AIA28-AI2A28-2A641-A28-A-4(2A28-2AIA28-AI2A28-2A672-)2(2A28-2AIE28-EI704-)3(2A28-2AIE28-EI673-A28-A-)AE28-EAIE28-EI4(AE28-EA641-A28-A-AE28-EA32-)3(AE28-EA672-AE28-EA32-)AE28-EA609-R28-R2-A28-A-AE28-EA32-AE28-EA-A28-A2-R28-R609-3(AE28-EA32-AE28-EA672-)AE28-EAIE28-EIAE28-EA2(672-2A28-2AIA28-AI2A28-2A)673-A28-A2-I28-I2-A28-A674-L28-L2-I28-I2-L28-L321-
