model
size = 32 32 22, scale = 0.05, origin = -y
material 
  colors = A:#960 B:#222 C:#930 D:#CC0 E:#E00 F:#F0C G:#AAA H:#09F I:#0C0 J:#30C K:#FC0 L:#111 M:#EEE
voxels
36-E-M-D305-BMB28-5B27-M3BM27-5B28-BMB93-BMB28-5B27-M3BM27-5B28-BMB325-28C4-23CB2CBC4-28C4-23C4BC4-28C2(4-C3G3D3H3I3F3E3JC4BC4-C3G3D3H3I3F3E3J6C)13(4-C3G3D3H3I3F3E3J6C)4-28C3(292-22(28A4-)28A)293-12(26A6-)2(L24AL3(6-26A)6-)26A6-26A326-10(26A6-)2(L24AL3(6-26A)6-)L24AL3(6-26A)326-12(26A6-)2(L24AL3(6-26A)6-)26A6-26A16-5B27-5B273-10(26A6-)2(L24AL3(6-26A)6-)L24AL3(6-26A)15-7B25-7B26-5B241-12(26A6-)2(L24AL3(6-26A)6-)26A6-26A14-9B23-9B24-7B27-3B243-19(24A8-)24A14-2(11B21-)11B22-9B25-5B242-19(24A8-)24A14-2(11B21-)11B22-9B24-7B27-4B25-3B4-3B19-3B10-3B140-19(24A8-)24A14-2(11B21-)11B22-9B24-7B114-3B16-3B7-3B22-3B2-2K28-2K36-19(24A8-)24A14-2(11B21-)11B22-9B24-7B241-19(24A8-)24A14-2(11B21-)11B22-9B25-5B307-16(22A10-)22A16-3(9B23-)9B24-7B27-3B308-16(22A10-)22A17-3(7B25-)7B26-5B339-16(22A10-)22A18-3(5B27-)5B371-16(22A10-)22A490-22A10-DAMAE17A4(10-22A)10-2AK16AK2A10-2(AK)14A2(KA)10-K3AK12AK4A10-22A3(10-2AK16AK2A)10-5K12A4KA2(10-22A)528-15(16A16-)16A528-2(16A16-)6(A14BA16-16A16-)A14BA16-16A421-
