model
size = 32 16 28, scale = 0.05, origin = -y
material 
  colors = A:#4A4A4A
voxels
153-2A29-4A30-3A2(30-2A)29-3A27-4A29-2A316-5A30-3(4A28-)4A25-5A29-2A285-4A4-3A20-7A2-5A19-2(7A-6A18-)7A-5A19-7A-3A20-7A26-4A228-4A19-6A3-5A17-8A2-7A14-10A4(-8A12-11A)-7A14-10A-5A17-8A2-4A19-6A163-4A20-4A4-6A16-8A2-7A13-11A-9A10-12A-10A3(8-24A)8-23A10-12A-7A13-11A-6A16-8A2-4A20-4A100-2A23-A6-5A17-7A3-7A13-11A-9A9-13A-13A4-70A-85A4-24A9-13A-7A13-11A-5A18-6A3-2A23-A70-4A20-3A5-6A14-9A3-9A9-13A-264A11-12A-6A15-8A3-3A21-3A62-A6-4A18-A-4A4-8A11-11A2-31A-268A6-13A-7A13-10A2-4A18-A-4A29-A31-A6-5A-A13-2(A-)5A3-30A2-31A-287A-7A-A11-10A2-5A15-2(A-)5A28-A31-A-A4-5A-A2-A8-3(A-)5A3-30A2-31A-287A-7A2(-A)7-A-10A2-5A15-2(A-)5A28-A-A29-A-A4-5A2(2-A)6(-A)-5A3-30A2-31A-287A-7A6(-A)-10A2-5A15-2(A-)5A28-A-A29-A-A4-6A2-8(A-)5A3-30A2-31A-59A3-29A4(5-27A)2-66A-7A6(-A)-10A2-6A14-2(A-)5A28-A-A29-A-A4-6A2-8(A-)2(5A3-30A2-2(31A-)6(27A5-)2(31A-)7A6(-A)-10A2-6A14-2(A-)5A28-A-A29-A-A4-7A8(-A)-)2(5A3-30A2-2(31A-)6(27A5-)2(31A-)7A6(-A)-10A2-6A14-2(A-)5A28-A-A29-A-A4-6A2-8(A-))5A3-30A2-31A-59A3-29A4(5-27A)2-66A-7A6(-A)-10A2-6A14-2(A-)5A28-A-A29-A-A4-5A2(2-A)6(-A)-5A3-30A2-31A-287A-7A6(-A)-10A2-5A15-2(A-)5A28-A-A29-A-A4-5A-A2-A8-3(A-)5A3-30A2-31A-287A-7A2(-A)7-A-10A2-5A15-2(A-)5A28-A-A29-A6-5A-A13-2(A-)5A3-30A2-31A-287A-7A-A11-10A2-5A15-2(A-)5A28-A31-A6-4A18-A-4A4-8A11-11A2-31A-268A6-13A-7A13-10A2-4A18-A-4A29-A38-4A20-3A5-6A14-9A3-9A9-13A-264A11-12A-6A15-8A3-3A21-3A69-2A23-A6-5A17-7A3-7A13-11A-9A9-13A-11A6-70A-83A6-24A9-13A-7A13-11A-5A17-7A3-2A23-A102-4A20-4A4-6A16-8A2-7A13-11A-9A10-12A-10A3(8-24A)8-23A10-12A-7A13-11A-6A16-8A2-3A21-4A164-4A19-6A3-5A17-8A2-7A14-10A4(-8A12-11A)-7A14-10A-5A17-8A2-3A20-6A251-4A4-3A20-7A2-5A19-2(7A-6A18-)7A-5A19-7A-3A20-7A26-4A315-5A30-3(4A28-)4A25-5A29-2A286-2A29-4A30-3A2(30-2A)29-3A27-4A29-2A133-
