model
size = 10 27 3, scale = 0.05, origin = -y
material 
  colors = A:#777 B:#555 C:#111 D:#F00 E:#8F2B19
voxels
---CC----- ---------- ---------- ---------- ---------- ---------- ---AA----- -AA--AA--- ---DD----- ---------- ---------- ---------- ---------- ---------- ---------- ---------- ---------- ---------- ---------- ---------- ---------- ---------- ---------- ---------- ---------- ---------- ---------- 
--ECCE---- ---EE----- ---CC----- ---EE----- ---CC----- ---EE----- --A--A---- AA-DD-AA-- -AD--DA--- --ADDA---- --AAAA---- -BAAA----- -BAAA----- -BAA------ BAAA------ BAA------- BAA------- BAA------- BAA------- BAA------- BAA------- -BA------- -BAA------ --BAA----- ---BAA---- -----BAA-- -------BBB 
---CC----- ---------- ---------- ---------- ---------- ---------- ---AA----- -AA--AA--- ---DD----- ---------- ---------- ---------- ---------- ---------- ---------- ---------- ---------- ---------- ---------- ---------- ---------- ---------- ---------- ---------- ---------- ---------- ---------- 
