model
size = 26 32 18, scale = 0.05, origin = -y
material 
  colors = A:#CF6 B:#111 C:#DDD
voxels
452-3(2A2-2A20-)2A2-2A21-3(A2-A22-)A2-A619-A4-A18-4A2-4A16-4A2-4A17-3A2-3A19-2A2-2A21-3(A2-A22-)A2-A617-3A4-3A14-6A2-6A12-6A2-6A13-5A2-5A17-2A2-2A21-3(A2-A22-)A2-A615-5A4-5A3(12-6A2-6A)16-2A2-2A21-3(A2-A22-)A2-A614-6A4-6A2(10-7A2-7A)11-6A2-6A16-2A2-2A21-3(A2-A22-)A2-A613-2(5A8-)4A10-4A2(8-5A)9-4A8-4A322-3(5A6-5A10-)5A6-5A321-3(4A10-4A8-)4A10-4A321-4(5A6-5A10-)5A6-5A294-2(5A10-5A6-)5A10-5A7-4A10-4A321-5(5A6-5A10-)5A6-5A268-2A16-2A5-3A16-3A4-5A12-5A5-4A12-4A267-18A8-18A9-5A6-5A10-5A6-5A36-2(5A6-5A10-)5A6-5A13-2A6-2A220-A16-A6-3A16-3A3-4A16-4A2(2-6A12-6A)3-4A14-4A240-18A8-18A9-5A6-5A10-5A6-5A62-5A6-5A10-5A6-5A13-2A6-2A16-2A6-2A192-3A16-3A4-3A16-3A3-4A16-4A-6A14-12A14-6A-5A14-5A109-18A8-A5BC4BC5BA8-AB2C2BC4BC2B2CBA8-A5BC4BC5BA8-A6C4B6CA2(8-18A)9-2(5A6-5A10-)5A6-5A36-4(5A6-5A10-)5A6-5A163-A2-A14-A2-A4-4A14-4A2-6A2(14-12A)14-6A-5A14-5A109-18A4(8-A16BA)2(8-18A)35-5A6-5A10-5A6-5A62-3(5A6-5A10-)5A6-5A11-14A12-14A11-4(16A10-)16A6-4A16-4A-5A3(16-10A)16-5A108-18A4(8-A16BA)2(8-18A)35-2(5A6-5A10-)5A6-5A62-2(5A6-5A10-)16A10-16A11-14A11-4(16A10-)16A6-24A-104A4-18A10-14B13-12A18-4A15-6(18A8-)18A61-2(5A6-5A10-)5A6-5A62-5A6-5A8(10-16A)6-24A-104A4-18A10-B12AB13-12A18-4A15-6(18A8-)18A87-2(5A6-5A10-)5A6-5A62-7(16A10-)16A6-2A2-16A2-2A-104A4-18A10-B12AB13-12A18-4A15-6(18A8-)18A9-2(A-)A6-2(A-)A5(10-5A6-5A)62-8(16A10-)16A6-24A-52A-24A5-18A10-B12AB12-14A17-4A15-6(18A8-)18A9-2(A-)A6-2(A-)A5(10-5A6-5A)63-6A2-6A8(12-14A)10-18A4-26A-24A3-22A6-18A9-16A239-
