model
size = 30 15 12, scale = 0.05, origin = -y
material 
  colors = A:#03C B:#63C C:#300
voxels
-----ACCAB----------BACCA----- ---BBACCABABAAAAAABABACCABB--- --BCCABBCCCAAABBAAACCCBBACCB-- -ACCCACCACCAACCCCAACCACCACCCA- -AAABAACABBAABCCBAABBACAABAAA- BAACBBCABBAAABAABAAABBACBBCAAB CCACABCABBCBBACCABBCBBACBACACC BACACBCBCCAAACAACAAACCBCBCACAB ACAAAAAAAACACABBACACAAAAAAAACA BBAAACACACBAAABBAAABCACACAAABB -ACABBAABACBAAAAAABCABAABBACA- -ACBACAACCAAAACCAAAACCAACABCA- --CABAAAAACBAAAAAABCAAAAABAC-- ---ABCAAAACCAAAAAACCAAAACBA--- -----BAAAA----------AAAAB----- 
-----CCBCA----------ACBCC----- ---AAAAAAAACBBBBBBCAAAAAAAA--- --AAAAAAAAAAAAAAAAAAAAAAAAAA-- -AAAAAAAAAAAAAAAAAAAAAAAAAAAA- -AAAAAAABBBBAAAAAABBBBAAAAAAA- AAAAAAABBBBBBAAAABBBBBBAAAAAAA AAAAAABBBBBBBBAABBBBBBBBAAAAAA AAAAAABBBBBBBBAABBBBBBBBAAAAAA AAAAAABBBBBBBBAABBBBBBBBAAAAAA AAAAAABBBBBBBBAABBBBBBBBAAAAAA -AAAAAABBBBBBAAAABBBBBBAAAAAA- -AAAAAAABBBBAAAAAABBBBAAAAAAA- --AAAAAAAAAAAAAAAAAAAAAAAAAA-- ---AAAAAAAACBBBBBBCAAAAAAAA--- -----CCBCA----------ACBCC----- 
-----ABCBB----------BBCBA----- ---AAAAAAACABCAACBACAAAAAAA--- --AAAAAAAAAAAAAAAAAAAAAAAAAA-- -AAAAA------------------AAAAA- -AAAAA------------------AAAAA- AAAAAA------------------AAAAAA AAAAAA------------------AAAAAA AAAAAA------------------AAAAAA AAAAAA------------------AAAAAA AAAAAA------------------AAAAAA -AAAAA------------------AAAAA- -AAAAA------------------AAAAA- --AAAA------------------AAAA-- ---AAAAAAACABCAACBACAAAAAAA--- -----ABCBB----------BBCBA----- 
-----CCCCA----------ACCCC----- ---AAAAAAACBACBBCABCAAAAAAA--- --AAAACABBCBBCAACBBCBBACAAAA-- -AAAAA------------------AAAAA- -AAAAA------------------AAAAA- AAAAAA------------------AAAAAA AAAAAA------------------AAAAAA AAAAAA------------------AAAAAA AAAAAA------------------AAAAAA AAAAAA------------------AAAAAA -AAAAA------------------AAAAA- -AAAAA------------------AAAAA- --AAAA------------------AAAA-- ---AAAAAAACBACBBCABCAAAAAAA--- -----CCCCA----------ACCCC----- 
-----BCBAB----------BABCB----- ---AAAAAAACBAACCAABCAAAAAAA--- --AAAA------------------AAAA-- -AAAAA------------------AAAAA- -AAAAA------------------AAAAA- AAAAAA------------------AAAAAA AAAAAA------------------AAAAAA AAAAAA------------------AAAAAA AAAAAA------------------AAAAAA AAAAAA------------------AAAAAA -AAAAA------------------AAAAA- -AAAAA------------------AAAAA- --AAAA------------------AAAA-- ---AAAAAAACBAACCAABCAAAAAAA--- -----BCBAB----------BABCB----- 
-----ABACA----------ACABA----- ---AAAAAAAACBBAABBCAAAAAAAA--- --AAAA------------------AAAA-- -AAAAA------------------AAAAA- -AAAAA------------------AAAAA- AAAAAA------------------AAAAAA AAAAAA------------------AAAAAA AAAAAA------------------AAAAAA AAAAAA------------------AAAAAA AAAAAA------------------AAAAAA -AAAAA------------------AAAAA- -AAAAA------------------AAAAA- --AAAA------------------AAAA-- ---AAAAAAAACBBAABBCAAAAAAAA--- -----ABACA----------ACABA----- 
-----BBACB----------BCABB----- ---AAAAACCABBBCCBBBACCAAAAA--- --AAAC------------------CAAA-- -AAAAB------------------BAAAA- -AAAAC------------------CAAAA- AAAAAA------------------AAAAAA AAAAAB------------------BAAAAA AAAAAC------------------CAAAAA AAAAAB------------------BAAAAA AAAAAC------------------CAAAAA -AAAAA------------------AAAAA- -AAAAA------------------AAAAA- --AAAC------------------CAAA-- ---AABABBABBCBBBBCBBABBABAA--- -----CBABC----------CBABC----- 
------------------------------ ---AB--------------------BA--- --AAC--------------------CAA-- -AAAC--------------------CAAA- -AAAC--------------------CAAA- AAAAB--------------------BAAAA AAAAC--------------------CAAAA AAAAC--------------------CAAAA AAAAC--------------------CAAAA AAAAA--------------------AAAAA -AAAA--------------------AAAA- -AAAB--------------------BAAA- --AAA--------------------AAA-- ---AC--------------------CA--- ------------------------------ 
------------------------------ ---A----------------------A--- --AB----------------------BA-- -AAA----------------------AAA- -AAC----------------------CAA- AAAB----------------------BAAA AAAC----------------------CAAA AAAC----------------------CAAA AAAC----------------------CAAA AAAC----------------------CAAA -AAB----------------------BAA- -AAC----------------------CAA- --AC----------------------CA-- ---B----------------------B--- ------------------------------ 
------------------------------ ------------------------------ --C------------------------C-- -AA------------------------AA- -AC------------------------CA- AAC------------------------CAA AAA------------------------AAA AAB------------------------BAA AAB------------------------BAA AAA------------------------AAA -AB------------------------BA- -AB------------------------BA- --C------------------------C-- ------------------------------ ------------------------------ 
------------------------------ ------------------------------ ------------------------------ -B--------------------------B- -B--------------------------B- AB--------------------------BA AB--------------------------BA AA--------------------------AA AC--------------------------CA AB--------------------------BA -B--------------------------B- -B--------------------------B- ------------------------------ ------------------------------ ------------------------------ 
------------------------------ ------------------------------ ------------------------------ ------------------------------ ------------------------------ C----------------------------C B----------------------------B B----------------------------B A----------------------------A C----------------------------C ------------------------------ ------------------------------ ------------------------------ ------------------------------ ------------------------------ 
