model
size = 30 15 12, scale = 0.05, origin = -y
material 
  colors = A:#6CC B:#66F C:#099
voxels
-----BBAAB----------BAABB----- ---BBBBAAABBBBBBBBBBAAABBBB--- --AAABBBBAAABBAABBAAABBBBAAA-- -AABABABBAAAABBBBAAAABBABABAA- -AABAABABBBBABAABABBBBABAABAA- BAAAAAAAAAAABAAAABAAAAAAAAAAAB BBBBBAAAABABABBBBABABAAAABBBBB BAAABABBBBBBABBBBABBBBBBABAAAB ABABAAABABABABAABABABABAAABABA AABABAABAABBBAAAABBBAABAABABAA -BAABABABBABBABBABBABBABABAAB- -BABBABABBBABBBBBBABBBABABBAB- --BBABAAABAABABBABAABAAABABB-- ---BBBAABAABABAABABAABAABBB--- -----ABBAA----------AABBA----- 
-----ABABA----------ABABA----- ---AAAAAAAAAABAABAAAAAAAAAA--- --AAAAAAAAAAAAAAAAAAAAAAAAAA-- -AAAAAAAAAAAAAAAAAAAAAAAAAAAA- -AAAAAAACCCCAAAAAACCCCAAAAAAA- AAAAAAACCCCCCAAAACCCCCCAAAAAAA AAAAAACCCCCCCCAACCCCCCCCAAAAAA AAAAAACCCCCCCCAACCCCCCCCAAAAAA AAAAAACCCCCCCCAACCCCCCCCAAAAAA AAAAAACCCCCCCCAACCCCCCCCAAAAAA -AAAAAACCCCCCAAAACCCCCCAAAAAA- -AAAAAAACCCCAAAAAACCCCAAAAAAA- --AAAAAAAAAAAAAAAAAAAAAAAAAA-- ---AAAAAAAAAABAABAAAAAAAAAA--- -----ABABA----------ABABA----- 
-----BAAAA----------AAAAB----- ---AAAAAAABBBABBABBBAAAAAAA--- --AAAAAAAAAAAAAAAAAAAAAAAAAA-- -AAAAA------------------AAAAA- -AAAAA------------------AAAAA- AAAAAA------------------AAAAAA AAAAAA------------------AAAAAA AAAAAA------------------AAAAAA AAAAAA------------------AAAAAA AAAAAA------------------AAAAAA -AAAAA------------------AAAAA- -AAAAA------------------AAAAA- --AAAA------------------AAAA-- ---AAAAAAABBBABBABBBAAAAAAA--- -----BAAAA----------AAAAB----- 
-----AABAA----------AABAA----- ---AAAAAAABBAAAAAABBAAAAAAA--- --AAAAAABAABAABBAABAABAAAAAA-- -AAAAA------------------AAAAA- -AAAAA------------------AAAAA- AAAAAA------------------AAAAAA AAAAAA------------------AAAAAA AAAAAA------------------AAAAAA AAAAAA------------------AAAAAA AAAAAA------------------AAAAAA -AAAAA------------------AAAAA- -AAAAA------------------AAAAA- --AAAA------------------AAAA-- ---AAAAAAABBAAAAAABBAAAAAAA--- -----AABAA----------AABAA----- 
-----BABAA----------AABAB----- ---AAAAAAABBABBBBABBAAAAAAA--- --AAAA------------------AAAA-- -AAAAA------------------AAAAA- -AAAAA------------------AAAAA- AAAAAA------------------AAAAAA AAAAAA------------------AAAAAA AAAAAA------------------AAAAAA AAAAAA------------------AAAAAA AAAAAA------------------AAAAAA -AAAAA------------------AAAAA- -AAAAA------------------AAAAA- --AAAA------------------AAAA-- ---AAAAAAABBABBBBABBAAAAAAA--- -----BABAA----------AABAB----- 
-----AAABB----------BBAAA----- ---AAAAAAABBBABBABBBAAAAAAA--- --AAAA------------------AAAA-- -AAAAA------------------AAAAA- -AAAAA------------------AAAAA- AAAAAA------------------AAAAAA AAAAAA------------------AAAAAA AAAAAA------------------AAAAAA AAAAAA------------------AAAAAA AAAAAA------------------AAAAAA -AAAAA------------------AAAAA- -AAAAA------------------AAAAA- --AAAA------------------AAAA-- ---AAAAAAABBBABBABBBAAAAAAA--- -----AAABB----------BBAAA----- 
-----AAABB----------BBAAA----- ---AAAAABBBAABBBBAABBBAAAAA--- --AAAB------------------BAAA-- -AAAAB------------------BAAAA- -AAAAA------------------AAAAA- AAAAAB------------------BAAAAA AAAAAB------------------BAAAAA AAAAAA------------------AAAAAA AAAAAA------------------AAAAAA AAAAAB------------------BAAAAA -AAAAA------------------AAAAA- -AAAAB------------------BAAAA- --AAAA------------------AAAA-- ---AAAABAAABABAABABAAABAAAA--- -----BABAA----------AABAB----- 
------------------------------ ---AA--------------------AA--- --AAB--------------------BAA-- -AAAA--------------------AAAA- -AAAB--------------------BAAA- AAAAB--------------------BAAAA AAAAA--------------------AAAAA AAAAA--------------------AAAAA AAAAA--------------------AAAAA AAAAA--------------------AAAAA -AAAA--------------------AAAA- -AAAA--------------------AAAA- --AAA--------------------AAA-- ---AB--------------------BA--- ------------------------------ 
------------------------------ ---A----------------------A--- --AB----------------------BA-- -AAA----------------------AAA- -AAA----------------------AAA- AAAB----------------------BAAA AAAA----------------------AAAA AAAA----------------------AAAA AAAA----------------------AAAA AAAB----------------------BAAA -AAB----------------------BAA- -AAB----------------------BAA- --AB----------------------BA-- ---B----------------------B--- ------------------------------ 
------------------------------ ------------------------------ --A------------------------A-- -AA------------------------AA- -AA------------------------AA- AAA------------------------AAA AAB------------------------BAA AAA------------------------AAA AAB------------------------BAA AAB------------------------BAA -AA------------------------AA- -AA------------------------AA- --B------------------------B-- ------------------------------ ------------------------------ 
------------------------------ ------------------------------ ------------------------------ -B--------------------------B- -B--------------------------B- AB--------------------------BA AA--------------------------AA AB--------------------------BA AB--------------------------BA AA--------------------------AA -B--------------------------B- -B--------------------------B- ------------------------------ ------------------------------ ------------------------------ 
------------------------------ ------------------------------ ------------------------------ ------------------------------ ------------------------------ A----------------------------A B----------------------------B A----------------------------A A----------------------------A A----------------------------A ------------------------------ ------------------------------ ------------------------------ ------------------------------ ------------------------------ 
