model
size = 30 15 12, scale = 0.05, origin = -y
material 
  colors = A:#F9F B:#555 C:#F03
voxels
-----BBABA----------ABABB----- ---ABAABBBABABBBBABABBBAABA--- --AAAAAABABBAAAAAABBABAAAAAA-- -AAABAAAAAAAAABBAAAAAAAAABAAA- -ABAAABBBBBAABAABAABBBBBAAABA- BBABABBBAABABBBBBBABAABBBABABB AABBABABABABAABBAABABABABABBAA AAAABBAABBABBBAABBBABBAABBAAAA AABABAABBAABABAABABAABBAABABAA BAAAABBBBABBABBBBABBABBBBAAAAB -BBBABBBBBBABAAAABABBBBBBABBB- -BABBAAABABABBAABBABABAAABBAB- --AAABBBBBAABABBABAABBBBBAAA-- ---AABBAABBBAABBAABBBAABBAA--- -----AAABB----------BBAAA----- 
-----AAAAA----------AAAAA----- ---AAAAAAAAAAAAAAAAAAAAAAAA--- --AAAAAAAAAAAAAAAAAAAAAAAAAA-- -AAAAAAAAAAAAAAAAAAAAAAAAAAAA- -AAAAAAACCCCAAAAAACCCCAAAAAAA- AAAAAAACCCCCCAAAACCCCCCAAAAAAA AAAAAACCCCCCCCAACCCCCCCCAAAAAA AAAAAACCCCCCCCAACCCCCCCCAAAAAA AAAAAACCCCCCCCAACCCCCCCCAAAAAA AAAAAACCCCCCCCAACCCCCCCCAAAAAA -AAAAAACCCCCCAAAACCCCCCAAAAAA- -AAAAAAACCCCAAAAAACCCCAAAAAAA- --AAAAAAAAAAAAAAAAAAAAAAAAAA-- ---AAAAAAAAAAAAAAAAAAAAAAAA--- -----AAAAA----------AAAAA----- 
-----AAAAA----------AAAAA----- ---AAAAAAAAAAAAAAAAAAAAAAAA--- --AAAAAAAAAAAAAAAAAAAAAAAAAA-- -AAAAA------------------AAAAA- -AAAAA------------------AAAAA- AAAAAA------------------AAAAAA AAAAAA------------------AAAAAA AAAAAA------------------AAAAAA AAAAAA------------------AAAAAA AAAAAA------------------AAAAAA -AAAAA------------------AAAAA- -AAAAA------------------AAAAA- --AAAA------------------AAAA-- ---AAAAAAAAAAAAAAAAAAAAAAAA--- -----AAAAA----------AAAAA----- 
-----AAAAA----------AAAAA----- ---AAAAAAAAAAAAAAAAAAAAAAAA--- --AAAAAABAAABABBABAAABAAAAAA-- -AAAAA------------------AAAAA- -AAAAA------------------AAAAA- AAAAAA------------------AAAAAA AAAAAA------------------AAAAAA AAAAAA------------------AAAAAA AAAAAA------------------AAAAAA AAAAAA------------------AAAAAA -AAAAA------------------AAAAA- -AAAAA------------------AAAAA- --AAAA------------------AAAA-- ---AAAAAAAAAAAAAAAAAAAAAAAA--- -----AAAAA----------AAAAA----- 
-----AAAAA----------AAAAA----- ---AAAAAAAAAAAAAAAAAAAAAAAA--- --AAAA------------------AAAA-- -AAAAA------------------AAAAA- -AAAAA------------------AAAAA- AAAAAA------------------AAAAAA AAAAAA------------------AAAAAA AAAAAA------------------AAAAAA AAAAAA------------------AAAAAA AAAAAA------------------AAAAAA -AAAAA------------------AAAAA- -AAAAA------------------AAAAA- --AAAA------------------AAAA-- ---AAAAAAAAAAAAAAAAAAAAAAAA--- -----AAAAA----------AAAAA----- 
-----AAAAA----------AAAAA----- ---AAAAAAAAAAAAAAAAAAAAAAAA--- --AAAA------------------AAAA-- -AAAAA------------------AAAAA- -AAAAA------------------AAAAA- AAAAAA------------------AAAAAA AAAAAA------------------AAAAAA AAAAAA------------------AAAAAA AAAAAA------------------AAAAAA AAAAAA------------------AAAAAA -AAAAA------------------AAAAA- -AAAAA------------------AAAAA- --AAAA------------------AAAA-- ---AAAAAAAAAAAAAAAAAAAAAAAA--- -----AAAAA----------AAAAA----- 
-----BBBAA----------AABBB----- ---AABBAAAAABBBBBBAAAAABBAA--- --AAAB------------------BAAA-- -AAAAB------------------BAAAA- -AAAAB------------------BAAAA- AAAAAA------------------AAAAAA AAAAAB------------------BAAAAA AAAAAA------------------AAAAAA AAAAAA------------------AAAAAA AAAAAA------------------AAAAAA -AAAAA------------------AAAAA- -AAAAA------------------AAAAA- --AAAA------------------AAAA-- ---AAABABBBABAAAABABBBABAAA--- -----AAABB----------BBAAA----- 
------------------------------ ---AA--------------------AA--- --AAB--------------------BAA-- -AAAA--------------------AAAA- -AAAA--------------------AAAA- AAAAB--------------------BAAAA AAAAA--------------------AAAAA AAAAA--------------------AAAAA AAAAA--------------------AAAAA AAAAB--------------------BAAAA -AAAB--------------------BAAA- -AAAB--------------------BAAA- --AAB--------------------BAA-- ---AB--------------------BA--- ------------------------------ 
------------------------------ ---B----------------------B--- --AB----------------------BA-- -AAA----------------------AAA- -AAB----------------------BAA- AAAA----------------------AAAA AAAB----------------------BAAA AAAB----------------------BAAA AAAA----------------------AAAA AAAA----------------------AAAA -AAA----------------------AAA- -AAA----------------------AAA- --AB----------------------BA-- ---B----------------------B--- ------------------------------ 
------------------------------ ------------------------------ --B------------------------B-- -AB------------------------BA- -AB------------------------BA- AAA------------------------AAA AAA------------------------AAA AAB------------------------BAA AAA------------------------AAA AAB------------------------BAA -AB------------------------BA- -AA------------------------AA- --B------------------------B-- ------------------------------ ------------------------------ 
------------------------------ ------------------------------ ------------------------------ -B--------------------------B- -A--------------------------A- AB--------------------------BA AB--------------------------BA AB--------------------------BA AA--------------------------AA AB--------------------------BA -A--------------------------A- -A--------------------------A- ------------------------------ ------------------------------ ------------------------------ 
------------------------------ ------------------------------ ------------------------------ ------------------------------ ------------------------------ B----------------------------B A----------------------------A A----------------------------A B----------------------------B A----------------------------A ------------------------------ ------------------------------ ------------------------------ ------------------------------ ------------------------------ 
