model
size = 30 15 12, scale = 0.05, origin = -y
material 
  colors = A:#008 B:#C36 C:#004
voxels
-----BBBAB----------BABBB----- ---AABBAABAABBAABBAABAABBAA--- --ABBBBABBABBBAABBBABBABBBBA-- -BBBABBABAABBBBBBBBAABABBABBB- -AABABBBBABBBAAAABBBABBBBABAA- AABABABAAAAAAABBAAAAAAABABABAA BAAAABAAABAAABAABAAABAAABAAAAB BABAABBAABABAAAAAABABAABBAABAB AAABBBAAABABABBBBABABAAABBBAAA ABBBAABBBAAABBBBBBAAABBBAABBBA -ABABBABBBAABBAABBAABBBABBABA- -ABAAABABBBBABBBBABBBBABAAABA- --BBBBAABABAAAAAAAABABAABBBB-- ---BBABAAAAAABBBBAAAAAABABB--- -----AABAA----------AABAA----- 
-----BABAB----------BABAB----- ---AAAAAAABAABAABAABAAAAAAA--- --AAAAAAAAAAAAAAAAAAAAAAAAAA-- -AAAAAAAAAAAAAAAAAAAAAAAAAAAA- -AAAAAAACCCCAAAAAACCCCAAAAAAA- BAAAAAACCCCCCAAAACCCCCCAAAAAAB BAAAAACCCCCCCCAACCCCCCCCAAAAAB BAAAAACCCCCCCCAACCCCCCCCAAAAAB BAAAAACCCCCCCCAACCCCCCCCAAAAAB BAAAAACCCCCCCCAACCCCCCCCAAAAAB -AAAAAACCCCCCAAAACCCCCCAAAAAA- -AAAAAAACCCCAAAAAACCCCAAAAAAA- --AAAAAAAAAAAAAAAAAAAAAAAAAA-- ---AAAAAAABAABAABAABAAAAAAA--- -----BABAB----------BABAB----- 
-----BBBAB----------BABBB----- ---AAAAAAABBBBBBBBBBAAAAAAA--- --AAAAAAAAAAAAAAAAAAAAAAAAAA-- -AAAAA------------------AAAAA- -AAAAA------------------AAAAA- BAAAAA------------------AAAAAB BAAAAA------------------AAAAAB BAAAAA------------------AAAAAB BAAAAA------------------AAAAAB BAAAAA------------------AAAAAB -AAAAA------------------AAAAA- -AAAAA------------------AAAAA- --AAAA------------------AAAA-- ---AAAAAAABBBBBBBBBBAAAAAAA--- -----BBBAB----------BABBB----- 
-----BBBAB----------BABBB----- ---AAAAAAABBABBBBABBAAAAAAA--- --AAAAAAAAAAAAAAAAAAAAAAAAAA-- -AAAAA------------------AAAAA- -AAAAA------------------AAAAA- BAAAAA------------------AAAAAB BAAAAA------------------AAAAAB BAAAAA------------------AAAAAB BAAAAA------------------AAAAAB BAAAAA------------------AAAAAB -AAAAA------------------AAAAA- -AAAAA------------------AAAAA- --AAAA------------------AAAA-- ---AAAAAAABBABBBBABBAAAAAAA--- -----BBBAB----------BABBB----- 
-----ABBBB----------BBBBA----- ---AAAAAAABBAAAAAABBAAAAAAA--- --AAAA------------------AAAA-- -AAAAA------------------AAAAA- -AAAAA------------------AAAAA- BAAAAA------------------AAAAAB BAAAAA------------------AAAAAB AAAAAA------------------AAAAAA BAAAAA------------------AAAAAB BAAAAA------------------AAAAAB -AAAAA------------------AAAAA- -AAAAA------------------AAAAA- --AAAA------------------AAAA-- ---AAAAAAABBAAAAAABBAAAAAAA--- -----ABBBB----------BBBBA----- 
-----BABBB----------BBBAB----- ---AAAAAAABBBABBABBBAAAAAAA--- --AAAA------------------AAAA-- -AAAAA------------------AAAAA- -AAAAA------------------AAAAA- BAAAAA------------------AAAAAB BAAAAA------------------AAAAAB BAAAAA------------------AAAAAB BAAAAA------------------AAAAAB BAAAAA------------------AAAAAB -AAAAA------------------AAAAA- -AAAAA------------------AAAAA- --AAAA------------------AAAA-- ---AAAAAAABBBABBABBBAAAAAAA--- -----BABBB----------BBBAB----- 
-----AAAAA----------AAAAA----- ---AAAAAAAAAAAAAAAAAAAAAAAA--- --AAAA------------------AAAA-- -AAAAA------------------AAAAA- -AAAAA------------------AAAAA- AAAAAA------------------AAAAAA BAAAAA------------------AAAAAB BAAAAA------------------AAAAAB BAAAAA------------------AAAAAB AAAAAA------------------AAAAAA -AAAAA------------------AAAAA- -AAAAA------------------AAAAA- --AAAA------------------AAAA-- ---AAAAAAAAAAAAAAAAAAAAAAAA--- -----AAAAA----------AAAAA----- 
------------------------------ ---AA--------------------AA--- --AAA--------------------AAA-- -AAAA--------------------AAAA- -AAAA--------------------AAAA- AAAAA--------------------AAAAA BAAAA--------------------AAAAB AAAAA--------------------AAAAA BAAAA--------------------AAAAB AAAAA--------------------AAAAA -AAAA--------------------AAAA- -AAAA--------------------AAAA- --AAA--------------------AAA-- ---AA--------------------AA--- ------------------------------ 
------------------------------ ---A----------------------A--- --AA----------------------AA-- -AAA----------------------AAA- -AAA----------------------AAA- BAAA----------------------AAAB AAAA----------------------AAAA BAAA----------------------AAAB AAAA----------------------AAAA BAAA----------------------AAAB -AAA----------------------AAA- -AAA----------------------AAA- --AA----------------------AA-- ---A----------------------A--- ------------------------------ 
------------------------------ ------------------------------ --A------------------------A-- -AA------------------------AA- -AA------------------------AA- AAA------------------------AAA BAA------------------------AAB BAA------------------------AAB BAA------------------------AAB AAA------------------------AAA -AA------------------------AA- -AA------------------------AA- --A------------------------A-- ------------------------------ ------------------------------ 
------------------------------ ------------------------------ ------------------------------ -A--------------------------A- -A--------------------------A- BA--------------------------AB AA--------------------------AA AA--------------------------AA AA--------------------------AA BA--------------------------AB -A--------------------------A- -A--------------------------A- ------------------------------ ------------------------------ ------------------------------ 
------------------------------ ------------------------------ ------------------------------ ------------------------------ ------------------------------ A----------------------------A A----------------------------A A----------------------------A A----------------------------A A----------------------------A ------------------------------ ------------------------------ ------------------------------ ------------------------------ ------------------------------ 
