model
size = 30 15 12, scale = 0.05, origin = -y
material 
  colors = A:#010 B:#F3C C:#C3F
voxels
-----AAACA----------ACAAA----- ---CBAAAACACBAAAABCACAAAABC--- --AAAACCAAACAACCAACAAACCAAAA-- -CBACACBAAABAAAAAABAAABCACABC- -CCABAAABABAAACCAAABABAAABACC- AAABAAAABCBCCACCACCBCBAAAABAAA BBCACABCACCBACAACABCCACBACACBB CAACCCCBCABAABAABAABACBCCCCAAC ACABBABCABACCCAACCCABACBABBACA AACACABACABAABBBBAABACABACACAA -BCAABAAACAAAAAAAAAACAAABAACB- -CBCACACABAABACCABAABACACACBC- --ABABCABBBABAAAABABBBACBABA-- ---ABCCAACCBABBBBABCCAACCBA--- -----ACCAB----------BACCA----- 
-----AAAAA----------AAAAA----- ---AAAAAAAAAAAAAAAAAAAAAAAA--- --AAAAAAAAAAAAAAAAAAAAAAAAAA-- -AAAAAAAAAAAAAAAAAAAAAAAAAAAA- -AAAAAAABBBBAAAAAABBBBAAAAAAA- AAAAAAABBBBBBAAAABBBBBBAAAAAAA AAAAAABBBBBBBBAABBBBBBBBAAAAAA AAAAAABBBBBBBBAABBBBBBBBAAAAAA AAAAAABBBBBBBBAABBBBBBBBAAAAAA AAAAAABBBBBBBBAABBBBBBBBAAAAAA -AAAAAABBBBBBAAAABBBBBBAAAAAA- -AAAAAAABBBBAAAAAABBBBAAAAAAA- --AAAAAAAAAAAAAAAAAAAAAAAAAA-- ---AAAAAAAAAAAAAAAAAAAAAAAA--- -----AAAAA----------AAAAA----- 
-----AAAAA----------AAAAA----- ---AAAAAAAAAAAAAAAAAAAAAAAA--- --AAAAAAAAAAAAAAAAAAAAAAAAAA-- -AAAAA------------------AAAAA- -AAAAA------------------AAAAA- AAAAAA------------------AAAAAA AAAAAA------------------AAAAAA AAAAAA------------------AAAAAA AAAAAA------------------AAAAAA AAAAAA------------------AAAAAA -AAAAA------------------AAAAA- -AAAAA------------------AAAAA- --AAAA------------------AAAA-- ---AAAAAAAAAAAAAAAAAAAAAAAA--- -----AAAAA----------AAAAA----- 
-----AAAAA----------AAAAA----- ---AAAAAAAAAAAAAAAAAAAAAAAA--- --AAAAAACABAAAAAAAABACAAAAAA-- -AAAAA------------------AAAAA- -AAAAA------------------AAAAA- AAAAAA------------------AAAAAA AAAAAA------------------AAAAAA BAAAAA------------------AAAAAB AAAAAA------------------AAAAAA AAAAAA------------------AAAAAA -AAAAA------------------AAAAA- -AAAAA------------------AAAAA- --AAAA------------------AAAA-- ---AAAAAAAAAAAAAAAAAAAAAAAA--- -----AAAAA----------AAAAA----- 
-----AAAAA----------AAAAA----- ---AAAAAAAAAAAAAAAAAAAAAAAA--- --AAAA------------------AAAA-- -AAAAA------------------AAAAA- -AAAAA------------------AAAAA- BAAAAA------------------AAAAAB CAAAAA------------------AAAAAC AAAAAA------------------AAAAAA CAAAAA------------------AAAAAC BAAAAA------------------AAAAAB -AAAAA------------------AAAAA- -AAAAA------------------AAAAA- --AAAA------------------AAAA-- ---AAAAAAAAAAAAAAAAAAAAAAAA--- -----AAAAA----------AAAAA----- 
-----AAAAA----------AAAAA----- ---AAAAAAAAAAAAAAAAAAAAAAAA--- --AAAA------------------AAAA-- -AAAAA------------------AAAAA- -AAAAA------------------AAAAA- AAAAAA------------------AAAAAA AAAAAA------------------AAAAAA AAAAAA------------------AAAAAA AAAAAA------------------AAAAAA AAAAAA------------------AAAAAA -AAAAA------------------AAAAA- -AAAAA------------------AAAAA- --AAAA------------------AAAA-- ---AAAAAAAAAAAAAAAAAAAAAAAA--- -----AAAAA----------AAAAA----- 
-----ABCAC----------CACBA----- ---AAAACAAAABAAAABAAAACAAAA--- --AAAA------------------AAAA-- -AAAAC------------------CAAAA- -AAAAB------------------BAAAA- AAAAAA------------------AAAAAA AAAAAB------------------BAAAAA CAAAAA------------------AAAAAC AAAAAB------------------BAAAAA AAAAAA------------------AAAAAA -AAAAB------------------BAAAA- -AAAAA------------------AAAAA- --AAAA------------------AAAA-- ---AAAAAABCAAAAAAAACBAAAAAA--- -----BAABA----------ABAAB----- 
------------------------------ ---AA--------------------AA--- --AAA--------------------AAA-- -AAAA--------------------AAAA- -AAAA--------------------AAAA- AAAAA--------------------AAAAA CAAAC--------------------CAAAC AAAAA--------------------AAAAA CAAAC--------------------CAAAC AAAAA--------------------AAAAA -AAAA--------------------AAAA- -AAAA--------------------AAAA- --AAB--------------------BAA-- ---AA--------------------AA--- ------------------------------ 
------------------------------ ---A----------------------A--- --AC----------------------CA-- -AAA----------------------AAA- -AAA----------------------AAA- BAAA----------------------AAAB AAAA----------------------AAAA AAAA----------------------AAAA AAAA----------------------AAAA BAAA----------------------AAAB -AAA----------------------AAA- -AAC----------------------CAA- --AB----------------------BA-- ---B----------------------B--- ------------------------------ 
------------------------------ ------------------------------ --A------------------------A-- -AA------------------------AA- -AA------------------------AA- AAA------------------------AAA CAC------------------------CAC AAB------------------------BAA CAA------------------------AAC AAA------------------------AAA -AC------------------------CA- -AC------------------------CA- --A------------------------A-- ------------------------------ ------------------------------ 
------------------------------ ------------------------------ ------------------------------ -A--------------------------A- -A--------------------------A- AA--------------------------AA AA--------------------------AA AA--------------------------AA AC--------------------------CA AA--------------------------AA -B--------------------------B- -C--------------------------C- ------------------------------ ------------------------------ ------------------------------ 
------------------------------ ------------------------------ ------------------------------ ------------------------------ ------------------------------ A----------------------------A A----------------------------A A----------------------------A A----------------------------A A----------------------------A ------------------------------ ------------------------------ ------------------------------ ------------------------------ ------------------------------ 
