model
size = 30 15 12, scale = 0.05, origin = -y
material 
  colors = A:#CF0 B:#306 C:#9F6
voxels
-----BBBBB----------BBBBB----- ---ABBABABBAAAAAAAABBABABBA--- --BBBABBBBABBBBBBBBABBBBABBB-- -BABBAABAAABBBBBBBBAAABAABBAB- -AAAAABAAABBBABBABBBAAABAAAAA- BAABBBBAAAAABAAAABAAAAABBBBAAB BBABBABBBABBABAABABBABBBABBABB BBABAABBBBABBAAAABBABBBBAABABB AAABABBBBABBABAABABBABBBBABAAA ABABAAAABBAABAAAABAABBAAAABABA -ABBBBAABBAABBAABBAABBAABBBBA- -BAAAABAABBBBAAAABBBBAABAAAAB- --ABAABBAAAABABBABAAAABBAABA-- ---BABABAAABABAABABAAABABAB--- -----BABBB----------BBBAB----- 
-----AAAAB----------BAAAA----- ---AAAAAAAAABABBABAAAAAAAAA--- --AAAAAAAAAAAAAAAAAAAAAAAAAA-- -AAAAAAAAAAAAAAAAAAAAAAAAAAAA- -AAAAAAACCCCAAAAAACCCCAAAAAAA- AAAAAAACCCCCCAAAACCCCCCAAAAAAA AAAAAACCCCCCCCAACCCCCCCCAAAAAA AAAAAACCCCCCCCAACCCCCCCCAAAAAA AAAAAACCCCCCCCAACCCCCCCCAAAAAA AAAAAACCCCCCCCAACCCCCCCCAAAAAA -AAAAAACCCCCCAAAACCCCCCAAAAAA- -AAAAAAACCCCAAAAAACCCCAAAAAAA- --AAAAAAAAAAAAAAAAAAAAAAAAAA-- ---AAAAAAAAABABBABAAAAAAAAA--- -----AAAAB----------BAAAA----- 
-----AABAA----------AABAA----- ---AAAAAAAAAABAABAAAAAAAAAA--- --AAAAAAAAAAAAAAAAAAAAAAAAAA-- -AAAAA------------------AAAAA- -AAAAA------------------AAAAA- AAAAAA------------------AAAAAA AAAAAA------------------AAAAAA AAAAAA------------------AAAAAA AAAAAA------------------AAAAAA AAAAAA------------------AAAAAA -AAAAA------------------AAAAA- -AAAAA------------------AAAAA- --AAAA------------------AAAA-- ---AAAAAAAAAABAABAAAAAAAAAA--- -----AABAA----------AABAA----- 
-----ABAAA----------AAABA----- ---AAAAAAAAAAAAAAAAAAAAAAAA--- --AAAABBBBABBBBBBBBABBBBAAAA-- -AAAAA------------------AAAAA- -AAAAA------------------AAAAA- AAAAAA------------------AAAAAA AAAAAA------------------AAAAAA AAAAAA------------------AAAAAA AAAAAA------------------AAAAAA AAAAAA------------------AAAAAA -AAAAA------------------AAAAA- -AAAAA------------------AAAAA- --AAAA------------------AAAA-- ---AAAAAAAAAAAAAAAAAAAAAAAA--- -----ABAAA----------AAABA----- 
-----AAABA----------ABAAA----- ---AAAAAAABAAABBAAABAAAAAAA--- --AAAA------------------AAAA-- -AAAAA------------------AAAAA- -AAAAA------------------AAAAA- AAAAAA------------------AAAAAA AAAAAA------------------AAAAAA AAAAAA------------------AAAAAA AAAAAA------------------AAAAAA AAAAAA------------------AAAAAA -AAAAA------------------AAAAA- -AAAAA------------------AAAAA- --AAAA------------------AAAA-- ---AAAAAAABAAABBAAABAAAAAAA--- -----AAABA----------ABAAA----- 
-----ABAAA----------AAABA----- ---AAAAAAAAAAAAAAAAAAAAAAAA--- --AAAA------------------AAAA-- -AAAAA------------------AAAAA- -AAAAA------------------AAAAA- AAAAAA------------------AAAAAA AAAAAA------------------AAAAAA AAAAAA------------------AAAAAA AAAAAA------------------AAAAAA AAAAAA------------------AAAAAA -AAAAA------------------AAAAA- -AAAAA------------------AAAAA- --AAAA------------------AAAA-- ---AAAAAAAAAAAAAAAAAAAAAAAA--- -----ABAAA----------AAABA----- 
-----BBBBA----------ABBBB----- ---AABBBBBBABABBABABBBBBBAA--- --AAAB------------------BAAA-- -AAAAB------------------BAAAA- -AAAAB------------------BAAAA- AAAAAB------------------BAAAAA AAAAAB------------------BAAAAA AAAAAB------------------BAAAAA AAAAAA------------------AAAAAA AAAAAB------------------BAAAAA -AAAAB------------------BAAAA- -AAAAB------------------BAAAA- --AAAA------------------AAAA-- ---AAAABBBBBBBBBBBBBBBBAAAA--- -----ABBAB----------BABBA----- 
------------------------------ ---AB--------------------BA--- --AAB--------------------BAA-- -AAAB--------------------BAAA- -AAAB--------------------BAAA- AAAAB--------------------BAAAA AAAAB--------------------BAAAA AAAAB--------------------BAAAA AAAAB--------------------BAAAA AAAAB--------------------BAAAA -AAAB--------------------BAAA- -AAAA--------------------AAAA- --AAB--------------------BAA-- ---AB--------------------BA--- ------------------------------ 
------------------------------ ---A----------------------A--- --AB----------------------BA-- -AAB----------------------BAA- -AAB----------------------BAA- AAAB----------------------BAAA AAAB----------------------BAAA AAAB----------------------BAAA AAAB----------------------BAAA AAAB----------------------BAAA -AAA----------------------AAA- -AAB----------------------BAA- --AB----------------------BA-- ---B----------------------B--- ------------------------------ 
------------------------------ ------------------------------ --A------------------------A-- -AA------------------------AA- -AB------------------------BA- AAB------------------------BAA AAB------------------------BAA AAB------------------------BAA AAA------------------------AAA AAB------------------------BAA -AB------------------------BA- -AB------------------------BA- --A------------------------A-- ------------------------------ ------------------------------ 
------------------------------ ------------------------------ ------------------------------ -B--------------------------B- -A--------------------------A- AB--------------------------BA AB--------------------------BA AA--------------------------AA AA--------------------------AA AA--------------------------AA -B--------------------------B- -A--------------------------A- ------------------------------ ------------------------------ ------------------------------ 
------------------------------ ------------------------------ ------------------------------ ------------------------------ ------------------------------ B----------------------------B B----------------------------B A----------------------------A B----------------------------B B----------------------------B ------------------------------ ------------------------------ ------------------------------ ------------------------------ ------------------------------ 
