model
size = 30 15 12, scale = 0.05, origin = -y
material 
  colors = A:#F9C B:#FC3 C:#CF3
voxels
-----ABAAA----------AAABA----- ---BAABBBBAAAABBAAAABBBBAAB--- --ABAABABBBABABBABABBBABAABA-- -BBBBABBABABBBAABBBABABBABBBB- -ABABABBAAABAAAAAABAAABBABABA- BAAAAABBAAABABBBBABAAABBAAAAAB AABBBBBAAABBBBAABBBBAAABBBBBAA BABBBABAAABBAABBAABBAAABABBBAB AABABBABABAABABBABAABABABBABAA BBAABBBBABBBBBAABBBBBABBBBAABB -ABABABBAABBBBBBBBBBAABBABABA- -ABBBBAAAABBBAAAABBBAAAABBBBA- --AAAABBABABBAAAABBABABBAAAA-- ---BABBAABABAABBAABABAABBAB--- -----BABBA----------ABBAB----- 
-----AAAAA----------AAAAA----- ---AAAAAAAAAAAAAAAAAAAAAAAA--- --AAAAAAAAAAAAAAAAAAAAAAAAAA-- -AAAAAAAAAAAAAAAAAAAAAAAAAAAA- -AAAAAAACCCCAAAAAACCCCAAAAAAA- AAAAAAACCCCCCAAAACCCCCCAAAAAAA AAAAAACCCCCCCCAACCCCCCCCAAAAAA AAAAAACCCCCCCCAACCCCCCCCAAAAAA AAAAAACCCCCCCCAACCCCCCCCAAAAAA AAAAAACCCCCCCCAACCCCCCCCAAAAAA -AAAAAACCCCCCAAAACCCCCCAAAAAA- -AAAAAAACCCCAAAAAACCCCAAAAAAA- --AAAAAAAAAAAAAAAAAAAAAAAAAA-- ---AAAAAAAAAAAAAAAAAAAAAAAA--- -----AAAAA----------AAAAA----- 
-----AAAAA----------AAAAA----- ---AAAAAAAAAAAAAAAAAAAAAAAA--- --AAAAAAAAAAAAAAAAAAAAAAAAAA-- -AAAAA------------------AAAAA- -AAAAA------------------AAAAA- AAAAAA------------------AAAAAA AAAAAA------------------AAAAAA AAAAAA------------------AAAAAA AAAAAA------------------AAAAAA AAAAAA------------------AAAAAA -AAAAA------------------AAAAA- -AAAAA------------------AAAAA- --AAAA------------------AAAA-- ---AAAAAAAAAAAAAAAAAAAAAAAA--- -----AAAAA----------AAAAA----- 
-----AAAAA----------AAAAA----- ---AAAAAAAAAAAAAAAAAAAAAAAA--- --AAAABBBABABBAABBABABBBAAAA-- -AAAAA------------------AAAAA- -AAAAA------------------AAAAA- AAAAAA------------------AAAAAA AAAAAA------------------AAAAAA AAAAAA------------------AAAAAA AAAAAA------------------AAAAAA AAAAAA------------------AAAAAA -AAAAA------------------AAAAA- -AAAAA------------------AAAAA- --AAAA------------------AAAA-- ---AAAAAAAAAAAAAAAAAAAAAAAA--- -----AAAAA----------AAAAA----- 
-----AAAAA----------AAAAA----- ---AAAAAAAAAAAAAAAAAAAAAAAA--- --AAAA------------------AAAA-- -AAAAA------------------AAAAA- -AAAAA------------------AAAAA- AAAAAA------------------AAAAAA AAAAAA------------------AAAAAA AAAAAA------------------AAAAAA AAAAAA------------------AAAAAA AAAAAA------------------AAAAAA -AAAAA------------------AAAAA- -AAAAA------------------AAAAA- --AAAA------------------AAAA-- ---AAAAAAAAAAAAAAAAAAAAAAAA--- -----AAAAA----------AAAAA----- 
-----AAAAA----------AAAAA----- ---AAAAAAAAAAAAAAAAAAAAAAAA--- --AAAA------------------AAAA-- -AAAAA------------------AAAAA- -AAAAA------------------AAAAA- AAAAAA------------------AAAAAA AAAAAA------------------AAAAAA AAAAAA------------------AAAAAA AAAAAA------------------AAAAAA AAAAAA------------------AAAAAA -AAAAA------------------AAAAA- -AAAAA------------------AAAAA- --AAAA------------------AAAA-- ---AAAAAAAAAAAAAAAAAAAAAAAA--- -----AAAAA----------AAAAA----- 
-----ABBAA----------AABBA----- ---AAABAABBAAABBAAABBAABAAA--- --AAAB------------------BAAA-- -AAAAA------------------AAAAA- -AAAAB------------------BAAAA- AAAAAB------------------BAAAAA AAAAAA------------------AAAAAA AAAAAB------------------BAAAAA AAAAAA------------------AAAAAA AAAAAB------------------BAAAAA -AAAAB------------------BAAAA- -AAAAA------------------AAAAA- --AAAA------------------AAAA-- ---AABABBAABBAAAABBAABBABAA--- -----BAABB----------BBAAB----- 
------------------------------ ---AA--------------------AA--- --AAB--------------------BAA-- -AAAB--------------------BAAA- -AAAA--------------------AAAA- AAAAB--------------------BAAAA AAAAB--------------------BAAAA AAAAA--------------------AAAAA AAAAB--------------------BAAAA AAAAA--------------------AAAAA -AAAA--------------------AAAA- -AAAB--------------------BAAA- --AAA--------------------AAA-- ---AA--------------------AA--- ------------------------------ 
------------------------------ ---B----------------------B--- --AA----------------------AA-- -AAA----------------------AAA- -AAA----------------------AAA- AAAA----------------------AAAA AAAA----------------------AAAA AAAB----------------------BAAA AAAB----------------------BAAA AAAA----------------------AAAA -AAA----------------------AAA- -AAB----------------------BAA- --AA----------------------AA-- ---B----------------------B--- ------------------------------ 
------------------------------ ------------------------------ --A------------------------A-- -AB------------------------BA- -AB------------------------BA- AAB------------------------BAA AAB------------------------BAA AAB------------------------BAA AAA------------------------AAA AAB------------------------BAA -AA------------------------AA- -AA------------------------AA- --B------------------------B-- ------------------------------ ------------------------------ 
------------------------------ ------------------------------ ------------------------------ -B--------------------------B- -A--------------------------A- AA--------------------------AA AA--------------------------AA AA--------------------------AA AB--------------------------BA AB--------------------------BA -A--------------------------A- -A--------------------------A- ------------------------------ ------------------------------ ------------------------------ 
------------------------------ ------------------------------ ------------------------------ ------------------------------ ------------------------------ A----------------------------A A----------------------------A A----------------------------A A----------------------------A A----------------------------A ------------------------------ ------------------------------ ------------------------------ ------------------------------ ------------------------------ 
