model
size = 30 15 12, scale = 0.05, origin = -y
material 
  colors = A:#606 B:#070 C:#303
voxels
-----ABACA----------ACABA----- ---AABAAACACAAAAAACACAAABAA--- --AAABBBBACCAAAAAACCABBBBAAA-- -CBAABAACAAAAACCAAAAACAABAABC- -CBAABAAABACBACCABCABAAABAABC- AAAABAAAAABCABAABACBAAAAABAAAA BABCABAAAAAAACAACAAAAAAABACBAB CBBCABAAACBAACAACAABCAAABACBBC CACBCCABBBCCBABBABCCBBBACCBCAC AAABABBABABCAACCAACBABABBABAAA -BABACAACAAACAAAACAAACAACABAB- -BABBAAABAACBBCCBBCAABAAABBAB- --BABAAACACABBAABBACACAAABAB-- ---AABCAACBCCACCACCBCAACBAA--- -----AAACB----------BCAAA----- 
-----AAAAA----------AAAAA----- ---AAAAAAAAAAAAAAAAAAAAAAAA--- --AAAAAAAAAAAAAAAAAAAAAAAAAA-- -AAAAAAAAAAAAAAAAAAAAAAAAAAAA- -AAAAAAABBBBAAAAAABBBBAAAAAAA- CAAAAAABBBBBBAAAABBBBBBAAAAAAC BAAAAABBBBBBBBAABBBBBBBBAAAAAB CAAAAABBBBBBBBAABBBBBBBBAAAAAC BAAAAABBBBBBBBAABBBBBBBBAAAAAB CAAAAABBBBBBBBAABBBBBBBBAAAAAC -AAAAAABBBBBBAAAABBBBBBAAAAAA- -AAAAAAABBBBAAAAAABBBBAAAAAAA- --AAAAAAAAAAAAAAAAAAAAAAAAAA-- ---AAAAAAAAAAAAAAAAAAAAAAAA--- -----AAAAA----------AAAAA----- 
-----AAAAA----------AAAAA----- ---AAAAAAAAAAAAAAAAAAAAAAAA--- --AAAAAAAAAAAAAAAAAAAAAAAAAA-- -AAAAA------------------AAAAA- -AAAAA------------------AAAAA- AAAAAA------------------AAAAAA AAAAAA------------------AAAAAA CAAAAA------------------AAAAAC AAAAAA------------------AAAAAA AAAAAA------------------AAAAAA -AAAAA------------------AAAAA- -AAAAA------------------AAAAA- --AAAA------------------AAAA-- ---AAAAAAAAAAAAAAAAAAAAAAAA--- -----AAAAA----------AAAAA----- 
-----AAAAA----------AAAAA----- ---AAAAAAAAAAAAAAAAAAAAAAAA--- --AAAAAAAAAAAAAAAAAAAAAAAAAA-- -AAAAA------------------AAAAA- -AAAAA------------------AAAAA- BAAAAA------------------AAAAAB CAAAAA------------------AAAAAC CAAAAA------------------AAAAAC CAAAAA------------------AAAAAC BAAAAA------------------AAAAAB -AAAAA------------------AAAAA- -AAAAA------------------AAAAA- --AAAA------------------AAAA-- ---AAAAAAAAAAAAAAAAAAAAAAAA--- -----AAAAA----------AAAAA----- 
-----AAAAA----------AAAAA----- ---AAAAAAAAAAAAAAAAAAAAAAAA--- --AAAA------------------AAAA-- -AAAAA------------------AAAAA- -AAAAA------------------AAAAA- AAAAAA------------------AAAAAA CAAAAA------------------AAAAAC AAAAAA------------------AAAAAA CAAAAA------------------AAAAAC AAAAAA------------------AAAAAA -AAAAA------------------AAAAA- -AAAAA------------------AAAAA- --AAAA------------------AAAA-- ---AAAAAAAAAAAAAAAAAAAAAAAA--- -----AAAAA----------AAAAA----- 
-----AAAAA----------AAAAA----- ---AAAAAAAAAAAAAAAAAAAAAAAA--- --AAAA------------------AAAA-- -AAAAA------------------AAAAA- -AAAAA------------------AAAAA- BAAAAA------------------AAAAAB BAAAAA------------------AAAAAB AAAAAA------------------AAAAAA BAAAAA------------------AAAAAB BAAAAA------------------AAAAAB -AAAAA------------------AAAAA- -AAAAA------------------AAAAA- --AAAA------------------AAAA-- ---AAAAAAAAAAAAAAAAAAAAAAAA--- -----AAAAA----------AAAAA----- 
-----AAAAA----------AAAAA----- ---AAAAAAAAAAAAAAAAAAAAAAAA--- --AAAA------------------AAAA-- -AAAAA------------------AAAAA- -AAAAA------------------AAAAA- AAAAAA------------------AAAAAA CAAAAA------------------AAAAAC CAAAAA------------------AAAAAC CAAAAA------------------AAAAAC AAAAAA------------------AAAAAA -AAAAA------------------AAAAA- -AAAAA------------------AAAAA- --AAAA------------------AAAA-- ---AAAAAAAAAAAAAAAAAAAAAAAA--- -----AAAAA----------AAAAA----- 
------------------------------ ---AA--------------------AA--- --AAA--------------------AAA-- -AAAA--------------------AAAA- -AAAA--------------------AAAA- AAAAA--------------------AAAAA CAAAA--------------------AAAAC AAAAA--------------------AAAAA CAAAA--------------------AAAAC AAAAA--------------------AAAAA -AAAA--------------------AAAA- -AAAA--------------------AAAA- --AAA--------------------AAA-- ---AA--------------------AA--- ------------------------------ 
------------------------------ ---A----------------------A--- --AA----------------------AA-- -AAA----------------------AAA- -AAA----------------------AAA- BAAA----------------------AAAB CAAA----------------------AAAC CAAA----------------------AAAC CAAA----------------------AAAC BAAA----------------------AAAB -AAA----------------------AAA- -AAA----------------------AAA- --AA----------------------AA-- ---A----------------------A--- ------------------------------ 
------------------------------ ------------------------------ --A------------------------A-- -AA------------------------AA- -AA------------------------AA- AAA------------------------AAA CAA------------------------AAC BAA------------------------AAB CAA------------------------AAC AAA------------------------AAA -AA------------------------AA- -AA------------------------AA- --A------------------------A-- ------------------------------ ------------------------------ 
------------------------------ ------------------------------ ------------------------------ -A--------------------------A- -A--------------------------A- CA--------------------------AC CA--------------------------AC AA--------------------------AA CA--------------------------AC CA--------------------------AC -A--------------------------A- -A--------------------------A- ------------------------------ ------------------------------ ------------------------------ 
------------------------------ ------------------------------ ------------------------------ ------------------------------ ------------------------------ A----------------------------A A----------------------------A A----------------------------A A----------------------------A A----------------------------A ------------------------------ ------------------------------ ------------------------------ ------------------------------ ------------------------------ 
