model
size = 30 15 12, scale = 0.05, origin = -y
material 
  colors = A:#69C B:#00A C:#C0C
voxels
-----BCCCC----------CCCCB----- ---ACCABACBBACAACABBCABACCA--- --BCACBAAABABCCCCBABAAABCACB-- -AAAAAAAACAABABBABAACAAAAAAAA- -AAACAAAAAABABCCBABAAAAAACAAA- BBBCACBBCCACCBCCBCCACCBBCACBBB ABAABBAABCBBABBBBABBCBAABBAABA BBBCCBCACAABABAABABAACACBCCBBB BAAAACAAAACCCCAACCCCAAAACAAAAB ABABAABAAAAABBAABBAAAAABAABABA -AAAAABCBAAACCCCCCAAABCBAAAAA- -CBAAABABCBAAAAAAAABCBABAAABC- --AAAACCBAACCAAAACCAABCCAAAA-- ---BCACAAAAABAAAABAAAAACACB--- -----ACACC----------CCACA----- 
-----BBCAB----------BACBB----- ---AAAAAAAABCCBBCCBAAAAAAAA--- --AAAAAAAAAAAAAAAAAAAAAAAAAA-- -AAAAAAAAAAAAAAAAAAAAAAAAAAAA- -AAAAAAABBBBAAAAAABBBBAAAAAAA- AAAAAAABBBBBBAAAABBBBBBAAAAAAA AAAAAABBBBBBBBAABBBBBBBBAAAAAA AAAAAABBBBBBBBAABBBBBBBBAAAAAA AAAAAABBBBBBBBAABBBBBBBBAAAAAA AAAAAABBBBBBBBAABBBBBBBBAAAAAA -AAAAAABBBBBBAAAABBBBBBAAAAAA- -AAAAAAABBBBAAAAAABBBBAAAAAAA- --AAAAAAAAAAAAAAAAAAAAAAAAAA-- ---AAAAAAAABCCBBCCBAAAAAAAA--- -----BBCAB----------BACBB----- 
-----ABBBA----------ABBBA----- ---AAAAAAAABCBBBBCBAAAAAAAA--- --AAAAAAAAAAAAAAAAAAAAAAAAAA-- -AAAAA------------------AAAAA- -AAAAA------------------AAAAA- AAAAAA------------------AAAAAA AAAAAA------------------AAAAAA AAAAAA------------------AAAAAA AAAAAA------------------AAAAAA AAAAAA------------------AAAAAA -AAAAA------------------AAAAA- -AAAAA------------------AAAAA- --AAAA------------------AAAA-- ---AAAAAAAABCBBBBCBAAAAAAAA--- -----ABBBA----------ABBBA----- 
-----CBBBC----------CBBBC----- ---AAAAAAACAABCCBAACAAAAAAA--- --AAAAAAAAAAAAAAAAAAAAAAAAAA-- -AAAAA------------------AAAAA- -AAAAA------------------AAAAA- AAAAAA------------------AAAAAA AAAAAA------------------AAAAAA AAAAAA------------------AAAAAA AAAAAA------------------AAAAAA AAAAAA------------------AAAAAA -AAAAA------------------AAAAA- -AAAAA------------------AAAAA- --AAAA------------------AAAA-- ---AAAAAAACAABCCBAACAAAAAAA--- -----CBBBC----------CBBBC----- 
-----CCBBB----------BBBCC----- ---AAAAAAAACBBCCBBCAAAAAAAA--- --AAAA------------------AAAA-- -AAAAA------------------AAAAA- -AAAAA------------------AAAAA- AAAAAA------------------AAAAAA AAAAAA------------------AAAAAA AAAAAA------------------AAAAAA AAAAAA------------------AAAAAA AAAAAA------------------AAAAAA -AAAAA------------------AAAAA- -AAAAA------------------AAAAA- --AAAA------------------AAAA-- ---AAAAAAAACBBCCBBCAAAAAAAA--- -----CCBBB----------BBBCC----- 
-----CCABC----------CBACC----- ---AAAAAAABAAACCAAABAAAAAAA--- --AAAA------------------AAAA-- -AAAAA------------------AAAAA- -AAAAA------------------AAAAA- AAAAAA------------------AAAAAA AAAAAA------------------AAAAAA AAAAAA------------------AAAAAA AAAAAA------------------AAAAAA AAAAAA------------------AAAAAA -AAAAA------------------AAAAA- -AAAAA------------------AAAAA- --AAAA------------------AAAA-- ---AAAAAAABAAACCAAABAAAAAAA--- -----CCABC----------CBACC----- 
-----AAAAA----------AAAAA----- ---AAAAAAAAAAAAAAAAAAAAAAAA--- --AAAA------------------AAAA-- -AAAAA------------------AAAAA- -AAAAA------------------AAAAA- AAAAAA------------------AAAAAA AAAAAA------------------AAAAAA AAAAAA------------------AAAAAA AAAAAA------------------AAAAAA AAAAAA------------------AAAAAA -AAAAA------------------AAAAA- -AAAAA------------------AAAAA- --AAAA------------------AAAA-- ---AAAAAAAAAAAAAAAAAAAAAAAA--- -----AAAAA----------AAAAA----- 
------------------------------ ---AA--------------------AA--- --AAA--------------------AAA-- -AAAA--------------------AAAA- -AAAA--------------------AAAA- AAAAA--------------------AAAAA AAAAA--------------------AAAAA AAAAA--------------------AAAAA AAAAA--------------------AAAAA AAAAA--------------------AAAAA -AAAA--------------------AAAA- -AAAA--------------------AAAA- --AAA--------------------AAA-- ---AA--------------------AA--- ------------------------------ 
------------------------------ ---A----------------------A--- --AA----------------------AA-- -AAA----------------------AAA- -AAA----------------------AAA- AAAA----------------------AAAA AAAA----------------------AAAA AAAA----------------------AAAA AAAA----------------------AAAA AAAA----------------------AAAA -AAA----------------------AAA- -AAA----------------------AAA- --AA----------------------AA-- ---A----------------------A--- ------------------------------ 
------------------------------ ------------------------------ --A------------------------A-- -AA------------------------AA- -AA------------------------AA- AAA------------------------AAA AAA------------------------AAA AAA------------------------AAA AAA------------------------AAA AAA------------------------AAA -AA------------------------AA- -AA------------------------AA- --A------------------------A-- ------------------------------ ------------------------------ 
------------------------------ ------------------------------ ------------------------------ -A--------------------------A- -A--------------------------A- AA--------------------------AA AA--------------------------AA AA--------------------------AA AA--------------------------AA AA--------------------------AA -A--------------------------A- -A--------------------------A- ------------------------------ ------------------------------ ------------------------------ 
------------------------------ ------------------------------ ------------------------------ ------------------------------ ------------------------------ A----------------------------A A----------------------------A A----------------------------A A----------------------------A A----------------------------A ------------------------------ ------------------------------ ------------------------------ ------------------------------ ------------------------------ 
