model
size = 32 31 32, scale = 0.05, origin = -y
material 
  colors = A:#EEE B:#AAA C:#555 D:#777
voxels
925-2(3C29-)3C892-3A29-3AC28-3AC29-3C859-3A29-4A28-4AC28-3AC30-2C826-3A29-4A28-5A28-4A30-2A794-D30-D3A29-4A28-5A28-4A30-2A827-2D29-D3A28-D4A28-4A30-2A859-A-2D28-4A28-2D2A30-2A859-A31-2A31-BA2D29-2D859-21(A31-2A31-BA892-)A31-2A31-BA924-2A31-BA957-BA990-
