model
size = 32 31 32, scale = 0.05, origin = -y
material 
  colors = A:#090 B:#500 C:#C93 D:#050 E:#D00
voxels
925-2(3D29-)3D892-3B29-BABD28-2BAD29-3D859-3B29-BA2B28-2BABD28-3BD30-2D826-3B29-BA2B28-2BA2B28-4B30-2B794-E30-E3B29-BA2B28-B2A2B28-4B30-2B827-2E29-E3B28-EBA2B28-2BAB30-2B859-A-2E28-2A2B28-2E2B30-2B859-A31-2A31-CA2E29-2E859-21(A31-2A31-CA892-)A31-2A31-CA924-2A31-CA957-CA990-
