model
size = 18 30 18, scale = 0.05, origin = -y
material 
  colors = A:#888 B:#777 C:#700 D:#500 E:#800 F:#555 G:#B00
voxels
------------------ ------------------ ------------------ ------------------ ------------------ ------------------ ------------------ ------------------ ------------------ ------------------ ------------------ ------------------ ------------------ ------------------ ------------------ ------------------ ----------F------- ------------------ ------------------ ------------------ ------------------ ------------------ ------------------ ------------------ ------------------ ------------------ ------------------ ------------------ ------------------ ------------------ 
------------------ ------------------ ------------------ ------------------ ------------------ ------------------ ------------------ ---------F-------- ------------------ ------------------ --------F--------- ------------------ ------------------ ------------------ ------------------ ----------B------- ------------------ ------------------ ------------------ ------------------ ------------------ ------------------ ------------------ ------------------ ------------------ ------------------ ------------------ ------------------ ------------------ ------------------ 
------------------ ------------------ ------B----------- ------------------ ------------------ ------------------ ------------------ ---------A-------- ------------------ ------------------ --------B--------- ------------------ ------------------ ------------------ ----------B------- ------------------ ------------------ ------------------ ------------------ ------------------ ------------------ ------------------ ------------------ ------------------ ------------------ ------------------ ------------------ ------------------ ------------------ ------------------ 
------------------ ------------------ ------------------ ------B----------- ------------------ ------------------ ------------------ ---------A-------- ------------------ ------------------ --------B--------- ------------------ ------------------ ----------B------- ------------------ ------------------ ------------------ ------------------ ------------------ ------------------ ------------------ ------------------ ------------------ ------------------ ------------------ ------------------ ------------------ ------------------ ------------------ ------------------ 
------------------ ------------------ ------------------ ------------------ ------A----------- ------------------ ------------------ ---------A-------- --------AA-------- --------AA-------- --------B--------- ------------------ ----------A------- ------------------ ------------------ ------------------ ------------------ ------------------ ------------------ ------------------ ------------------ ------------------ ------------------ ------------------ ------------------ ------------------ ------------------ ------------------ ------------------ ------------------ 
------------------ ------------------ ------------------ ------------------ ------------------ ------B----------- -------AAAA------- -------AAAAA------ ------AAAAAA------ ------AAAAAA------ -------AAAAA------ --------AAA------- ------------------ ------------------ ------------------ ------------------ ------------------ ------------------ ------------------ ------------------ ------------------ ------------------ ------------------ ------------------ ------------------ ------------------ ------------------ ------------------ ------------------ ------------------ 
------------------ ------------------ ------------------ ------------------ ------------------ -------BAAA------- ------BAAAA------- ------AAAAAAA----- -----AAAAAAAA----- -----AAAAAAAA----- ------AAAAAAA----- -------AAAAA------ --------AA-------- ------------------ ------------------ ------------------ ------------------ ------------------ ------------------ ------------------ ------------------ ------------------ ------------------ ------------------ ------------------ ------------------ ------------------ ------------------ ------------------ ------------------ 
--------F--------- --------A--------- --------B-------F- --------B------B-- --------BA----B--- ------AAAAAA-B---- ------AAAAAAB----- -----AAAAAAAA----- -----AAAAAAAAA---- -----AAAAAAAAA---- -----AAAAAAAA----- ------AAAAAAA----- -------AAAAA------ ------------------ ------------------ ------------------ ------------------ ------------------ ------------------ ------------------ ------------------ ------------------ ------------------ ------------------ ------------------ ------------------ ------------------ ------------------ ------------------ ------------------ 
------------------ ------------------ ------------------ ------------------ -------AAAA------- ------AAAAAAA----- -----AAAAAAAA----- FAAAAAAAAAAAAA---- ----AAAAAAAAAA---- ----AAAAAAAAAA---- -----AAAAAAAAABBBF -----AAAAAAAA----- ------AAAAAA------ --------BBB------- --------BBB------- --------BAB---EEE- ---------A----EEE- ---------A----EDE- ---------A----EDE- ---------A----EDE- ---------A----EDE- --------------EDD- --------------DDD- ---------A----DGD- ---------A----EGD- ---------A----EED- ---------A---EAAE- ---------A---A---- ---------A-AA----- ------------------ 
------------------ ------------------ ------------------ ------------------ -------AAAA------- ------AAAAAAA----- -----AAAAAAAA----- -----AAAAAAAAA---- ----AAAAAAAAAA---- ----AAAAAAAAAA---- FBBBBAAAAAAAAB---- -----AAAAAAAA----- ------AAAAAA------ --------BAB------- --------BAB------- --------BBB---CAC- --------------CAC- --------------CAC- --------------DAC- --------BBB---CAC- --------BAB---CAG- --------B-B---CAD- --------B-B---CAD- --------BAB---CAD- --------BBB---CAD- --------------CAD- --------------CAC- --------BABAA----- --------BA-AB----- --------BBBBB----- 
---------F-------- ---------A-------- ---------A-------- ---------A-------- --------AAA------- ------AAAAAAA----- -----AAAAAAAA----- -----AAAAAAAAAAAAF -----AAAAAAAAA---- -----AAAAAAAAA---- -----AAAAAAAA----- ------AAAAAAA----- -------AAAAA------ --------BBB------- --------BBB------- --------BAB---CCC- ---------A----CCC- ---------A----CCG- ---------A----DDG- ---------A----DDD- ---------A----DDD- --------------CDC- --------------DCC- ---------A----DDC- ---------A----DDC- ---------A----CDG- ---------A---CAAC- ---------A---A---- ---------A-AA----- ------------------ 
------------------ ------------------ ------------------ --F--------------- ---A-------------- ----A--AAAAA------ -----A-AAAAAA----- -----AAAAAAAA----- -----AAAAAAAA----- -----AAAAAAAA----- -----AAAAAAAA----- ------AAAAA------- -------AAAA------- ------------------ ------------------ ------------------ ------------------ ------------------ ------------------ ------------------ ------------------ ------------------ ------------------ ------------------ ------------------ ------------------ ------------------ ------------------ ------------------ ------------------ 
------------------ ------------------ ------------------ ------------------ ------------------ -------AAAA------- -------AAAAA------ ------AAAAAAA----- ------AAAAAAA----- ------AAAAAAA----- -----AAAAAAAA----- ----A--AAAAA------ ---A-------------- --A--------------- -F---------------- ------------------ ------------------ ------------------ ------------------ ------------------ ------------------ ------------------ ------------------ ------------------ ------------------ ------------------ ------------------ ------------------ ------------------ ------------------ 
------------------ ------------------ ------------------ ------------------ ------------------ -----------A------ ------------------ --------AAA------- -------AAAA------- -------AAAA------- --------AA-------- ------------------ -----------B------ ------------------ ------------------ ------------------ ------------------ ------------------ ------------------ ------------------ ------------------ ------------------ ------------------ ------------------ ------------------ ------------------ ------------------ ------------------ ------------------ ------------------ 
------------------ ------------------ ------------------ ------------------ -----------A------ ------------------ ------------------ ----------A------- ------------------ ------------------ --------A--------- ------------------ ------------------ -----------B------ ------------------ ------------------ ------------------ ------------------ ------------------ ------------------ ------------------ ------------------ ------------------ ------------------ ------------------ ------------------ ------------------ ------------------ ------------------ ------------------ 
------------------ ------------------ ------------------ -----------A------ ------------------ ------------------ ------------------ ----------A------- ------------------ ------------------ --------A--------- ------------------ ------------------ ------------------ -----------B------ ------------------ ------------------ ------------------ ------------------ ------------------ ------------------ ------------------ ------------------ ------------------ ------------------ ------------------ ------------------ ------------------ ------------------ ------------------ 
------------------ ------------------ -----------F------ ------------------ ------------------ ------------------ ------------------ ----------A------- ------------------ ------------------ --------A--------- ------------------ ------------------ ------------------ ------------------ -----------B------ ------------------ ------------------ ------------------ ------------------ ------------------ ------------------ ------------------ ------------------ ------------------ ------------------ ------------------ ------------------ ------------------ ------------------ 
------------------ -----------F------ ------------------ ------------------ ------------------ ------------------ ------------------ ----------F------- ------------------ ------------------ --------A--------- ------------------ ------------------ ------------------ ------------------ ------------------ -----------F------ ------------------ ------------------ ------------------ ------------------ ------------------ ------------------ ------------------ ------------------ ------------------ ------------------ ------------------ ------------------ ------------------ 
