model
size = 32 20 11, scale = 0.05, origin = -y
material 
  colors = A:#BBB B:#AAA C:#555 D:#111 E:#444 F:#777 G:#D00 H:#0E0
voxels
36-5C14-5C7-C5DC12-C5DC5-C7DC10-C7DC3-C9DC-6C-C9DC2-C9DC-C4AC-C9DC2-2(C4D)C-CD2ADC-2(C4D)C2-C9DC-C4AC-C9DC2-C9DC-6C-C9DC3-C7DC10-C7DC5-C5DC12-C5DC7-5C3-G6-H3-5C260-36B5A3B4(CD)3B5A7B7A2B4(CD)2BA5-A5B9A10BA7-A3B11AB6ABA9-A4(2B11AB6-B11-)3B9A10B9-5B7A12B7-3B3DB5A3BA6BA3B5-B4DCD26BDC4D4B5(2ED)2E5B3D7-5(2ED)2E168-B30A12(2B12A18-)8B17-8B7-5(2ED)2E168-2(B30A12(2B12A18-)33B192-)2(B30A12(2B12A18-)2B2A26B-2B-4(2C26-C3-)29C3-29C2-)B30A12(2B12A18-)33B192-B5A19F6A12(2B12A18-)33B192-B5AF17EF6A4(2B12A18-)2B12A14-A3-7(2B12A18-)33B192-6B2(F17EF13B)19F359B192-
