model
size = 21 31 31, scale = 0.05, origin = -y
material 
  colors = A:#06F B:#00F C:#DDD D:#C3F E:#200 F:#E00
voxels
--------------------- ----------A---------- --------AAAAA-------- -------AAAAAAA------- -------AAAAAAA------- -------ABABABA------- -------ABABABA------- -------AABBBAA------- ------AAAAAAAAA------ ------AAAAAAAAA------ ------AAABBBAAA------ ------AAAAAAAAA------ ------AAAAAAAAA------ -------AAAAAAA------- -------AAAAAAB------- -------AAAAAAB------- -------AAAAAAA------- -------AADDDAA------- -------DDDDDDD------- --------AAAAA-------- --------------------- --------------------- --------------------- --------------------- --------------------- --------------------- --------------------- --------------------- --------------------- --------------------- --------------------- 
-------AAAAAAA------- -------AAA-AAA------- -------AAAAAAA------- ------A-AA-AA-A------ ------A-AAAAA-A------ ------A-AAAAA-A------ ------A-AAAAA-A------ -----AAAAAAAAAAA----- -----A-AAAAAAA-A----- -----AAAAAAAAA-A----- ----AAAAAA-AAAAAA---- ----AAAAA---AAAAA---- ----AAAAAA-AAAAAA---- ----AAAAAA-AAAAAA---- -----AAAAAAAAAAA----- -----AAAAAAAAACB----- -----AAAAAAAA-AA----- -----DAAAAAAAAAD----- -----AA-AAAAA-AA----- -----AAA-AAA-AAA----- ------AAAAAAAAA------ --------AAAAA-------- --------------------- --------------------- --------------------- --------------------- --------------------- --------------------- --------------------- --------------------- --------------------- 
------AAAAAAAAA------ ------A-AAAAA-A------ ------AA-----AA------ ------AA-----AA------ -----A-A-----A-A----- -----A-A-----A-A----- -----A-A-----A-A----- -----AA-------AA----- ----A-A-------A-A---- ----AA--------A-A---- ----AA---------AA---- ---A-A---------A-A--- ---A-A---------A-A--- ---A-AA-------AA-A--- ---AAAA-------AAAA--- ---AAAA-------AABA--- ----AAA------AAAA---- ---AAAA-------A-AA--- ---AA-AA-----AA-AA--- ----A-AAA---AAA-A---- ----AA--AAAAA--AA---- -----AAA-AAA-AAA----- ------AAAAAAAAA------ --------AAAAA-------- --------------------- --------------------- --------------------- --------------------- --------------------- --------------------- --------------------- 
------AAA---AAA------ -----A-A-----A-A----- -----A-A-----A-A----- -----A-A-----A-A----- -----AA-------AA----- -----AA-------AA----- ----A-A-------A-A---- ----A-A-------A-A---- ----AA---------AA---- ---A-A---------A-A--- ---A-A---------A-A--- ---AA-----------AA--- --A-A-----------AA--- --A-A-----------A-A-- --A-A-----------A-A-- --A-A-----------A-A-- --AAA-----------AAA-- --AAA----------AA-A-- --A-AA---------AA-A-- --AA-A---------A-AA-- ---A--AA-----AA--A--- ---AA--AA---AA--A---- ----AA--AAAA---AA---- -----AAA--A--AAA----- -------AAAAAAA------- ---------AAA--------- --------------------- --------------------- --------------------- --------------------- --------------------- 
-----AA-------AA----- -----AA-------AA----- -----AA-------AA----- ----A-A-------AA----- -----AA-------AA----- -----A---------A----- ----AA---------AA---- ----AA---------AA---- ----AA---------AA---- ---AA-----------AA--- ---AA-----------AA--- --A-A-----------A-A-- --AA-------------AA-- --AA-------------AA-- --AA-------------AA-- --AA-------------AA-- --AA-------------AA-- --AA-------------AA-- --AA-------------AA-- --A-A-----------A-A-- --A-AA---------AA-A-- --A--AA-------AA-AA-- ---A--AA----AA---A--- ----A---AA-AA---A---- -----AA---A---AA----- ------AAA---AAA------ ---------AAA--------- --------------------- --------------------- --------------------- --------------------- 
-----AA-------AA----- -----AA-------AA----- ----AA---------AA---- ----AA---------AA---- ----A-A-------A-A---- ----AA---------AA---- ----AA---------AA---- ----AA---------AA---- ----AA---------AA---- ---AA-----------AA--- --A-A-----------A-A-- --AA-------------AA-- --AA-------------AA-- -A-A-------------AAA- -AA---------------AA- -AA---------------AA- --A---------------A-- --AA-------------AA-- -A-A-------------AAA- -A-A-------------A-A- --AA-------------AA-- --A-A-----------A-A-- --A--A--------AAA-A-- ---A--AA-----AA--A--- ----A---AA-AA---A---- -----A---AA----A----- ------AAA---AAA------ --------AAAAA-------- --------------------- --------------------- --------------------- 
--------------------- ----AA---------AA---- ----AA---------AA---- ----AA---------AA---- ----AA---------AA---- ----AA---------AA---- ----AA---------AA---- ----AA---------AA---- ----AA---------AA---- ---AA-----------AA--- --A-A-----------A-A-- --AA-------------AA-- --AA-------------AA-- -AA---------------AA- -AA---------------AA- -AA---------------AA- -AA---------------AA- -AA---------------AA- -AA---------------AA- -AA---------------AA- -AA---------------AA- -A-A-------------A-A- -A-AA------------A-A- --A-AA---------AA-A-- --AA--AA-----AA--AA-- ----A---A--AA---A---- -----A---AA----A----- ------AAAA--AAA------ ---------AAA--------- --------------------- --------------------- 
--------------------- ----AA---------AA---- ----AA---------AA---- ---A-A---------A-A--- ---A-A---------A-A--- ---A-A---------A-A--- ---A-A---------AA---- ---A-A---------A-A--- ---AA-----------AA--- ---AA-----------AA--- --A-A-----------A-A-- --AA-------------AA-- -A-A-------------A-A- -AA---------------AA- -AA---------------AA- -AA---------------AA- -AA---------------AA- -AA---------------AA- -AA---------------AA- -AA---------------AA- -AA---------------AA- -AA---------------AA- -AA---------------AA- -A-A-------------A-A- -A--AA---------AA--A- --AA--AA-----AA--AA-- ----A---AA-AA---A---- ----AAA---A---AAA---- -------AAAAAAA------- --------------------- --------------------- 
--------------------- ----A-----------A---- ---AA-----------AA--- ---AA-----------AA--- ---AA-----------AA--- ---AA-----------AA--- ---AA-----------AA--- ---AA-----------AA--- ---AA-----------AA--- ---AA-----------AA--- --AA-------------AA-- --AA-------------AA-- -AA---------------AA- -AA---------------AA- -AA---------------AA- -A----------------AA- -AA---------------AA- -AA---------------AA- -AA---------------AA- -AA---------------AA- -AA---------------AA- -AA---------------AA- -AA---------------AA- -AA---------------AA- -A-A-------------A-A- -A--AAA-------AAA--A- --AA---A-----A---AA-- ---AA---AAAAA---AA--- -----AAA-----AAA----- --------AAAAA-------- --------------------- 
--------------------- --------------------- ---AA-----------AA--- ---AA-----------AA--- ---AA-----------AA--- ---A-------------A--- --AA-------------A--- --AA-------------AA-- --AA-------------AA-- --AA-------------AA-- --AA-------------AA-- -AA--------------A-A- -AA---------------AA- -AA---------------AA- -AA---------------AA- -A-----------------A- -A-----------------A- -A-----------------A- -AA---------------AA- -AA---------------AA- -AA---------------AA- -AA---------------AA- -AA---------------AA- -AA---------------AA- -AA---------------AA- -A-AA-----------AA-A- -A---AA-------AA---A- --AA---AA---AA---AA-- ----AA---AAA---AA---- ------AAAAAAAAA------ --------------------- 
--------------------- --------------------- ---AA-----------AA--- ---AA-----------AA--- ---A-------------A--- --AA-------------AA-- --AA-------------AA-- --AA-------------AA-- --AA-------------AA-- --AA-------------AA-- -A-A-------------A-A- -AA---------------AA- -AA---------------AA- -AA---------------AA- -AA---------------AA- AA-----------------AA CA-----------------AC AA-----------------AA AA-----------------AA -A-----------------A- -A-----------------A- -AA---------------AA- -AA---------------AA- -AA---------------AA- -AA---------------AA- -AA---------------AA- -A-AA-----------AA-A- --A--AAA-----AAA--A-- ---AA---AAAAA---AA--- -----AAAAAAAAAAA----- --------------------- 
--------------------- --------------------- ---A-------------A--- --AA-------------AA-- --AA-------------AA-- --AA-------------AA-- --AA-------------AA-- --AA-------------AA-- --AA-------------AA-- -AA---------------AA- -AA---------------AA- -AA---------------AA- -AA---------------AA- -AA---------------AA- -AA---------------AA- BA-----------------AB AA-----------------AA AA-----------------AA AA-----------------AA AA-----------------AA -A-----------------A- -A-----------------A- -A-----------------A- -AA---------------AA- -AA---------------AA- -AA---------------AA- -A-A-------------A-A- -A--AAA-------AAA--A- --A----AA---AA---AA-- ---AAAAA-AAA-AAAA---- --------BBBBB-------- 
--------------------- --------------------- ---A-------------A--- --AA-------------AA-- --AA-------------AA-- --AA-------------AA-- --AA-------------AA-- --A---------------A-- -AA---------------AA- -AA---------------AA- -AA---------------AA- -AA---------------AA- -AA---------------AA- AA-----------------AA CA-----------------AC -A-----------------A- AA-----------------AA AA-----------------AA AA-----------------AA AA-----------------AA BA-----------------AB -A-----------------A- -A-----------------A- -A-----------------A- -AA---------------AA- -AA---------------AA- -AA---------------AA- -A-AA-----------AA-A- --A--AAA-----AAA--A-- ---AAA--AAAAA--AAA--- ------CBCACACBC------ 
--------------------- --------------------- --------------------- --AA-------------AA-- --AA-------------AA-- --AA-------------AA-- -AA---------------AA- -AA---------------AA- -AA---------------AA- -AA---------------AA- -AA---------------AA- -AA---------------AA- -A-----------------A- AA-----------------AA AA-----------------AA BA-----------------AB BA-----------------AB AA-----------------AA AA-----------------AA BA-----------------AB BA-----------------AB AA-----------------AA -A-----------------A- -A-----------------A- -A----------------AA- -AA---------------AA- -AA---------------AA- -A-A-------------A-A- --A-AAA-------AAA-A-- --AAA--AAAAAAA--AAA-- -----ACABBCBBACA----- 
--------------------- --------------------- --------------------- --------------------- --------------------- --A---------------A-- -AA---------------AA- -AA---------------AA- -AA---------------AA- -AA---------------AA- -AA---------------AA- -A-----------------A- BA-----------------AB AA-----------------AA BA-----------------AB CA-----------------AC AA-----------------AA AA-----------------AA AA-----------------AA AA-----------------AA CA-----------------AC BA-----------------AB AA-----------------AA -A-----------------A- -A-----------------A- -AA---------------AA- -AA---------------AA- -A-A-------------A-A- --A-AA---------AA-A-- --AA--AAA---AAA--AA-- ----ABAABCCCBAABA---- 
--------------------- --------------------- --------------------- --------------------- --------------------- --A---------------A-- --A---------------A-- -AA---------------AA- -AA---------------AA- -AA---------------AA- -A-----------------A- -A-----------------A- AA-----------------AA AA-----------------AA AA-----------------AA AA-----------------AA BA-----------------AB AA-----------------AA AA-----------------AA BA-----------------AB AA-----------------AA AA-----------------AA AA-----------------AA AA-----------------AA -A-----------------A- -AA---------------AA- -AA---------------AA- -A-A-------------A-A- --A-AA---------AA-A-- --AA--AAA---AAA--AA-- ----CABACBCBCABAC---- 
--------------------- --------------------- --------------------- --------------------- --------------------- --------------------- --A---------------A-- -AA---------------AA- -AA---------------AA- -AA---------------AA- -A-----------------A- -A-----------------A- BA-----------------AB AA-----------------AA AA-----------------AA AA-----------------AA AA-----------------AA AA-----------------AA AA-----------------AA AA-----------------AA AA-----------------AA AA-----------------AA AA-----------------AA BA-----------------AB -A-----------------A- -AA---------------AA- -AA---------------AA- -A-A-------------A-A- --A-AA---------AA-A-- --AA--AA-----AA--AA-- ----BBBABAAABABBB---- 
--------------------- --------------------- --------------------- --------------------- --------------------- --------------------- --A---------------A-- -AA---------------AA- -AA---------------AA- -AA---------------AA- -AA---------------AA- -A-----------------A- AA-----------------AA BA-----------------AB AA-----------------AA AA-----------------AA AA-----------------AA BA-----------------AB BA-----------------AB AA-----------------AA AA-----------------AA AA-----------------AA BA-----------------AB AA-----------------AA -A-----------------A- -AA---------------AA- -AA---------------AA- -A-A-------------A-A- --A-A-----------A-A-- ---A-AAA-----AAA-A--- ----AABCBAAABCBAA---- 
--------------------- --------------------- --------------------- --------------------- --------------------- --------------------- --------------------- -AA---------------AA- -AA---------------AA- -AA---------------AA- -AA---------------AA- -A-----------------A- BA-----------------AB CA-----------------AC AA-----------------AA CA-----------------AC AA-----------------AA CA-----------------AC CA-----------------AC AA-----------------AA CA-----------------AC AA-----------------AA CA-----------------AC BA-----------------AB -A-----------------A- -AA---------------AA- -AA---------------AA- -A-A-------------A-A- --A-A-----------A-A-- ---AAAAA-----AAAAA--- -----ABCAAAAACBA----- 
--------------------- --------------------- --------------------- --------------------- --------------------- --------------------- --------------------- --A---------------A-- -AA---------------AA- -AA---------------AA- -AA---------------AA- -A-----------------A- CA-----------------AC AA-----------------AA CA-----------------AC CA-----------------AC AA-----------------AA CA-----------------AC CA-----------------AC AA-----------------AA CA-----------------AC CA-----------------AC AA-----------------AA CA-----------------AC -A-----------------A- -AA---------------AA- -AA---------------AA- -A-A-------------A-A- --A-A-----------A-A-- ---AAAAAA---AAAAAA--- -----AAAACACAAAA----- 
--------------------- --------------------- --------------------- --------------------- --------------------- --------------------- --------------------- --A---------------A-- -AA---------------AA- -AA---------------AA- -AA---------------AA- -A-----------------A- CA-----------------AC AA-----------------AA AA-----------------AA AA-----------------AA BA-----------------AB AA-----------------AA AA-----------------AA BA-----------------AB AA-----------------AA AA-----------------AA AA-----------------AA CA-----------------AC -A-----------------A- -AA---------------AA- -AA---------------AA- -A-A-------------A-A- --A-AA---------AA-A-- ---AA-AAAAAAAAA-AA--- -----AACACBCACAA----- 
--------------------- --------------------- --------------------- --------------------- --------------------- --------------------- --------------------- --------------------- -AA---------------AA- -AA---------------AA- -AA---------------AA- -AA---------------AA- -A-----------------A- AA-----------------AA AA-----------------AA CA-----------------AC BA-----------------AB AA-----------------AA AA-----------------AA BA-----------------AB CA-----------------AC AA-----------------AA AA-----------------AA CA-----------------AC -AA---------------AA- -AA---------------AA- -AA---------------AA- --AA-------------AA-- --A-AAA-------AAA-A-- ---AAA-AAAAAAA-AAA--- ------CCCAAACCC------ 
--------------------- --------------------- --------------------- --------------------- --------------------- --------------------- --------------------- --------------------- --AA-------------AA-- -A-A-------------A-A- -AA---------------AA- -AA---------------AA- -AA---------------AA- -AA---------------AA- -A-----------------A- AA-----------------AA AA-----------------AA CA-----------------AC CA-----------------AC AA-----------------AA AA-----------------AA CA-----------------AC BA-----------------AB -A----------------AA- -AA---------------AA- -AA---------------AA- -A-A-------------A-A- --A-A-----------A-A-- --AA-AAAA---AAAA-AA-- ----AAA--AAA--AAA---- -------AAAAAAA------- 
--------------------- --------------------- --------------------- --------------------- --------------------- --------------------- --------------------- --------------------- --A---------------A-- --AAA-----------AAA-- -A-A-------------A-A- -A-A-------------A-A- -AA---------------AA- -AA---------------AA- -AA---------------AA- -AA---------------AA- -AA---------------AA- C-A---------------A-C CA-----------------AC AA-----------------AA CA-----------------AC CA-----------------AC CA-----------------AC -AA---------------AA- -AA---------------AA- -A-A-------------A-A- --A-A-----------A-A-- --A--AA-------AA--A-- ---AA--AAAAAAA--AA--- -----AAAAAAAAAAA----- --------------------- 
--------------------- --------------------- --------------------- --------------------- --------------------- --------------------- --------------------- --------------------- --------------------- ---AAA---------AAA--- --A-AAAA-----AAAA-A-- --A-A-----------A-A-- -A-A-------------A-A- -AA--------------A-A- -AA---------------AA- -AA---------------AA- -AA---------------AA- -AA---------------AA- B-A---------------A-B CA-----------------AC AA-----------------AA BA-----------------AB -AA---------------AA- -AA---------------AA- -A-A-------------A-A- -A-A------------A--A- --A-AA---------A--A-- ---A--AAA---AAA--A--- ----AA---AAA---AA---- ------AAAAAAAAA------ --------------------- 
--------------------- --------------------- --------------------- --------------------- --------------------- --------------------- --------------------- --------------------- --------------------- ----AA---------AA---- ---AA-AAAAAAAAA-AA--- --AA-AAAAAAAAAAA-AA-- --A-AA---------AA-A-- --AAA-----------A-A-- -A-A-------------A-A- -AA--------------A-A- -AA---------------AA- -AA---------------AA- -AA---------------AA- -AA---------------AA- -AA---------------AA- -AA---------------AA- -AA---------------AA- -A-A-------------A-A- -A-A------------A--A- --A-AA---------A--A-- --A---AA-----AA---A-- ---AA---AAAAA---AA--- -----AAAAAAAAAAA----- --------------------- --------------------- 
--------------------- --------------------- --------------------- --------------------- --------------------- --------------------- --------------------- --------------------- --------------------- --------------------- -----AAAAAAAAAAA----- ----AA-A-----A-AA---- ---A--AAAAAAAAA--A--- --A--AA-------AA--A-- --A-A-----------A-A-- --AA-------------AA-- --AA-------------AA-- -A-A-------------A-A- -A-A-------------A-A- -AA---------------AA- -AA---------------AA- -AA---------------AA- -A-A-------------A-A- -A--A-----------A--A- --A-AA---------A--A-- --A---AA-----AA---A-- ---AA---AAAAA---AA--- -----AAAA---AAAA----- ---------AAA--------- --------------------- --------------------- 
--------------------- --------------------- --------------------- --------------------- --------------------- --------------------- --------------------- --------------------- --------------------- --------------------- --------------------- ------AAAAAAAAA------ ----AAA------AAAA---- ---AA--AAAAAAA--AA--- ---A-AA-------AA-A--- --A-AA---------AA-A-- --A-A-----------A-A-- --A-A-----------A-A-- --A-A-----------A-A-- -A-A-------------A-A- -A-A-------------A-A- -A-AA-----------AAA-- --A-A-----------A-A-- --A--AA-------AA--A-- ---A--AAA---AAA--A--- ---AA---AAAAA---AA--- -----AAA-----AAA----- --------AAAAA-------- --------------------- --------------------- --------------------- 
--------------------- --------------------- --------------------- --------------------- --------------------- --------------------- --------------------- --------------------- --------------------- --------------------- --------------------- --------------------- -------AAAAAAA------- -----AAA-----AAA----- ----AA-AAAAAAA-AA---- ---AA-AAAA-AAAA-AA--- ---A-AA-------AA-A--- ---A-A---------A-A--- --A--A---------A--A-- --A-AA---------AA-A-- --A-AA---------AA-A-- --AA-AA-------AA-AA-- ---A-AAA-----AAA-A--- ---AA--AAAAAAA--AA--- ----AA---AAA---AA---- -----AAAAAAAAAAA----- --------AAAAA-------- --------------------- --------------------- --------------------- --------------------- 
--------------------- --------------------- --------------------- --------------------- --------------------- --------------------- --------------------- --------------------- --------------------- --------------------- --------------------- --------------------- --------------------- --------AAAAA-------- ------AAAAAAAAA------ -----AAAAAAAAAAA----- ----AAAAAAAAAAAAA---- ----AAAAAAAAAAAAA---- ---AA-AAFAAAFAA-AA--- ---AA-AAEEFEEAA-AA--- ---AAAAAAAAAAAAAAA--- ----AAAAAAAAAAAAA---- ----AAAAAAAAAAAAA---- -----AAAAAAAAAAA----- ------AAAAAAAAA------ --------------------- --------------------- --------------------- --------------------- --------------------- --------------------- 
--------------------- --------------------- --------------------- --------------------- --------------------- --------------------- --------------------- --------------------- --------------------- --------------------- --------------------- --------------------- --------------------- --------------------- --------------------- --------------------- --------AABAA-------- -------BAAAAAB------- -----AABBAAABBAA----- -----ABCAACAACBA----- ------BABAAABAB------ -------AACCCAA------- --------AAAAA-------- --------------------- --------------------- --------------------- --------------------- --------------------- --------------------- --------------------- --------------------- 
