model
size = 32 31 32, scale = 0.05, origin = -y
material 
  colors = A:#AAA B:#C96 C:#EEE D:#633 E:#555
voxels
24(CA990-3A30-)CA2E29-2E927-2E28-2A2B28-2E2B30-2B893-2E29-E3B28-EB2AB28-2BAB30-2B860-E30-E3B29-4B28-B3A2(B28-4B30-2B892-3B29-4B28-2B2A)D28-3BD30-2D892-3B29-3BD28-2BAD29-3D925-2(3D29-)3D
