model
size = 30 15 12, scale = 0.05, origin = -y
material 
  colors = A:#063 B:#C6F C:#FF0
voxels
-----ABAAA----------AAABA----- ---BBBAABBAABABBABAABBAABBB--- --BBAABAAAABABBBBABAAAABAABB-- -AABBBBBBABABBBBBBABABBBBBBAA- -BAAABABAAAAABBBBAAAAABABAAAB- AABBABAABAABBAAAABBAABAABABBAA BAABBBBAAAAABAAAABAAAAABBBBAAB BAAAABAAAAABABAABABAAAAABAAAAB AAABBABBABBBBAAAABBBBABBABBAAA AAABBAABAAABBBAABBBAAABAABBAAA -BAAAABABABBBBBBBBBBABABAAAAB- -AAAABAABABAABAABAABABAABAAAA- --BABBAAAABBAABBAABBAAAABBAB-- ---AAABBAAAABBBBBBAAAABBAAA--- -----AAABB----------BBAAA----- 
-----AAAAA----------AAAAA----- ---AAAAAAAAAAAAAAAAAAAAAAAA--- --AAAAAAAAAAAAAAAAAAAAAAAAAA-- -AAAAAAAAAAAAAAAAAAAAAAAAAAAA- -AAAAAAACCCCAAAAAACCCCAAAAAAA- AAAAAAACCCCCCAAAACCCCCCAAAAAAA AAAAAACCCCCCCCAACCCCCCCCAAAAAA AAAAAACCCCCCCCAACCCCCCCCAAAAAA AAAAAACCCCCCCCAACCCCCCCCAAAAAA AAAAAACCCCCCCCAACCCCCCCCAAAAAA -AAAAAACCCCCCAAAACCCCCCAAAAAA- -AAAAAAACCCCAAAAAACCCCAAAAAAA- --AAAAAAAAAAAAAAAAAAAAAAAAAA-- ---AAAAAAAAAAAAAAAAAAAAAAAA--- -----AAAAA----------AAAAA----- 
-----AAAAA----------AAAAA----- ---AAAAAAAAAAAAAAAAAAAAAAAA--- --AAAAAAAAAAAAAAAAAAAAAAAAAA-- -AAAAA------------------AAAAA- -AAAAA------------------AAAAA- AAAAAA------------------AAAAAA AAAAAA------------------AAAAAA AAAAAA------------------AAAAAA AAAAAA------------------AAAAAA AAAAAA------------------AAAAAA -AAAAA------------------AAAAA- -AAAAA------------------AAAAA- --AAAA------------------AAAA-- ---AAAAAAAAAAAAAAAAAAAAAAAA--- -----AAAAA----------AAAAA----- 
-----AAAAA----------AAAAA----- ---AAAAAAAAAAAAAAAAAAAAAAAA--- --AAAABBBABABABBABABABBBAAAA-- -AAAAA------------------AAAAA- -AAAAA------------------AAAAA- AAAAAA------------------AAAAAA AAAAAA------------------AAAAAA AAAAAA------------------AAAAAA AAAAAA------------------AAAAAA AAAAAA------------------AAAAAA -AAAAA------------------AAAAA- -AAAAA------------------AAAAA- --AAAA------------------AAAA-- ---AAAAAAAAAAAAAAAAAAAAAAAA--- -----AAAAA----------AAAAA----- 
-----AAAAA----------AAAAA----- ---AAAAAAAAAAAAAAAAAAAAAAAA--- --AAAA------------------AAAA-- -AAAAA------------------AAAAA- -AAAAA------------------AAAAA- AAAAAA------------------AAAAAA AAAAAA------------------AAAAAA AAAAAA------------------AAAAAA AAAAAA------------------AAAAAA AAAAAA------------------AAAAAA -AAAAA------------------AAAAA- -AAAAA------------------AAAAA- --AAAA------------------AAAA-- ---AAAAAAAAAAAAAAAAAAAAAAAA--- -----AAAAA----------AAAAA----- 
-----AAAAA----------AAAAA----- ---AAAAAAAAAAAAAAAAAAAAAAAA--- --AAAA------------------AAAA-- -AAAAA------------------AAAAA- -AAAAA------------------AAAAA- AAAAAA------------------AAAAAA AAAAAA------------------AAAAAA AAAAAA------------------AAAAAA AAAAAA------------------AAAAAA AAAAAA------------------AAAAAA -AAAAA------------------AAAAA- -AAAAA------------------AAAAA- --AAAA------------------AAAA-- ---AAAAAAAAAAAAAAAAAAAAAAAA--- -----AAAAA----------AAAAA----- 
-----BAAAA----------AAAAB----- ---AABBBBABBBABBABBBABBBBAA--- --AAAB------------------BAAA-- -AAAAA------------------AAAAA- -AAAAA------------------AAAAA- AAAAAA------------------AAAAAA AAAAAB------------------BAAAAA AAAAAB------------------BAAAAA AAAAAB------------------BAAAAA AAAAAB------------------BAAAAA -AAAAB------------------BAAAA- -AAAAA------------------AAAAA- --AAAB------------------BAAA-- ---AABBBAABABABBABABAABBBAA--- -----ABBBB----------BBBBA----- 
------------------------------ ---AB--------------------BA--- --AAA--------------------AAA-- -AAAB--------------------BAAA- -AAAB--------------------BAAA- AAAAB--------------------BAAAA AAAAB--------------------BAAAA AAAAB--------------------BAAAA AAAAB--------------------BAAAA AAAAA--------------------AAAAA -AAAA--------------------AAAA- -AAAB--------------------BAAA- --AAB--------------------BAA-- ---AA--------------------AA--- ------------------------------ 
------------------------------ ---A----------------------A--- --AA----------------------AA-- -AAA----------------------AAA- -AAB----------------------BAA- AAAB----------------------BAAA AAAA----------------------AAAA AAAA----------------------AAAA AAAA----------------------AAAA AAAA----------------------AAAA -AAB----------------------BAA- -AAB----------------------BAA- --AA----------------------AA-- ---A----------------------A--- ------------------------------ 
------------------------------ ------------------------------ --A------------------------A-- -AB------------------------BA- -AB------------------------BA- AAB------------------------BAA AAA------------------------AAA AAA------------------------AAA AAB------------------------BAA AAB------------------------BAA -AB------------------------BA- -AA------------------------AA- --B------------------------B-- ------------------------------ ------------------------------ 
------------------------------ ------------------------------ ------------------------------ -B--------------------------B- -B--------------------------B- AA--------------------------AA AA--------------------------AA AA--------------------------AA AB--------------------------BA AA--------------------------AA -B--------------------------B- -B--------------------------B- ------------------------------ ------------------------------ ------------------------------ 
------------------------------ ------------------------------ ------------------------------ ------------------------------ ------------------------------ B----------------------------B A----------------------------A A----------------------------A B----------------------------B B----------------------------B ------------------------------ ------------------------------ ------------------------------ ------------------------------ ------------------------------ 
