model
size = 30 15 12, scale = 0.05, origin = -y
material 
  colors = A:#C0C B:#700 C:#6C6
voxels
-----ABCBA----------ABCBA----- ---CBABABBCAAAAAAAACBBABABC--- --ABACBBCBAABAAAABAABCBBCABA-- -AABBAABBBAABAAAABAABBBAABBAA- -BCAAACABBCABBAABBACBBACAAACB- ABBACAACACABAAAAAABACACAACABBA BCBBBAAACAAACACCACAAACAAABBBCB AABAABACACACAAAAAACACACABAABAA BBBCABABABABACBBCABABABABACBBB BCCACBCCCAAABCCCCBAAACCCBCACCB -CBAAAAAACBBBAAAABBBCAAAAAABC- -CABCBCABBBACACCACABBBACBCBAC- --BCACABABAAACBBCAAABABACACB-- ---BCBBAAAACCABBACCAAAABBCB--- -----BCBCA----------ACBCB----- 
-----AAAAA----------AAAAA----- ---AAAAAAAAAAAAAAAAAAAAAAAA--- --AAAAAAAAAAAAAAAAAAAAAAAAAA-- -AAAAAAAAAAAAAAAAAAAAAAAAAAAA- -AAAAAAABBBBAAAAAABBBBAAAAAAA- BAAAAAABBBBBBAAAABBBBBBAAAAAAB CAAAAABBBBBBBBAABBBBBBBBAAAAAC AAAAAABBBBBBBBAABBBBBBBBAAAAAA CAAAAABBBBBBBBAABBBBBBBBAAAAAC BAAAAABBBBBBBBAABBBBBBBBAAAAAB -AAAAAABBBBBBAAAABBBBBBAAAAAA- -AAAAAAABBBBAAAAAABBBBAAAAAAA- --AAAAAAAAAAAAAAAAAAAAAAAAAA-- ---AAAAAAAAAAAAAAAAAAAAAAAA--- -----AAAAA----------AAAAA----- 
-----AAAAA----------AAAAA----- ---AAAAAAAAAAAAAAAAAAAAAAAA--- --AAAAAAAAAAAAAAAAAAAAAAAAAA-- -AAAAA------------------AAAAA- -AAAAA------------------AAAAA- AAAAAA------------------AAAAAA AAAAAA------------------AAAAAA AAAAAA------------------AAAAAA AAAAAA------------------AAAAAA AAAAAA------------------AAAAAA -AAAAA------------------AAAAA- -AAAAA------------------AAAAA- --AAAA------------------AAAA-- ---AAAAAAAAAAAAAAAAAAAAAAAA--- -----AAAAA----------AAAAA----- 
-----AAAAA----------AAAAA----- ---AAAAAAAAAAAAAAAAAAAAAAAA--- --AAAAAAAAAAAAAAAAAAAAAAAAAA-- -AAAAA------------------AAAAA- -AAAAA------------------AAAAA- AAAAAA------------------AAAAAA CAAAAA------------------AAAAAC AAAAAA------------------AAAAAA CAAAAA------------------AAAAAC AAAAAA------------------AAAAAA -AAAAA------------------AAAAA- -AAAAA------------------AAAAA- --AAAA------------------AAAA-- ---AAAAAAAAAAAAAAAAAAAAAAAA--- -----AAAAA----------AAAAA----- 
-----AAAAA----------AAAAA----- ---AAAAAAAAAAAAAAAAAAAAAAAA--- --AAAA------------------AAAA-- -AAAAA------------------AAAAA- -AAAAA------------------AAAAA- AAAAAA------------------AAAAAA AAAAAA------------------AAAAAA AAAAAA------------------AAAAAA AAAAAA------------------AAAAAA AAAAAA------------------AAAAAA -AAAAA------------------AAAAA- -AAAAA------------------AAAAA- --AAAA------------------AAAA-- ---AAAAAAAAAAAAAAAAAAAAAAAA--- -----AAAAA----------AAAAA----- 
-----AAAAA----------AAAAA----- ---AAAAAAAAAAAAAAAAAAAAAAAA--- --AAAA------------------AAAA-- -AAAAA------------------AAAAA- -AAAAA------------------AAAAA- AAAAAA------------------AAAAAA CAAAAA------------------AAAAAC AAAAAA------------------AAAAAA CAAAAA------------------AAAAAC AAAAAA------------------AAAAAA -AAAAA------------------AAAAA- -AAAAA------------------AAAAA- --AAAA------------------AAAA-- ---AAAAAAAAAAAAAAAAAAAAAAAA--- -----AAAAA----------AAAAA----- 
-----ACAAA----------AAACA----- ---AABAAABBAACAACAABBAAABAA--- --AAAA------------------AAAA-- -AAAAC------------------CAAAA- -AAAAA------------------AAAAA- AAAAAB------------------BAAAAA CAAAAC------------------CAAAAC BAAAAA------------------AAAAAB CAAAAA------------------AAAAAC AAAAAB------------------BAAAAA -AAAAB------------------BAAAA- -AAAAA------------------AAAAA- --AAAC------------------CAAA-- ---AAACAAAABCAAAACBAAAACAAA--- -----AAABA----------ABAAA----- 
------------------------------ ---AA--------------------AA--- --AAC--------------------CAA-- -AAAA--------------------AAAA- -AAAA--------------------AAAA- AAAAA--------------------AAAAA AAAAC--------------------CAAAA AAAAA--------------------AAAAA AAAAA--------------------AAAAA AAAAA--------------------AAAAA -AAAA--------------------AAAA- -AAAC--------------------CAAA- --AAA--------------------AAA-- ---AA--------------------AA--- ------------------------------ 
------------------------------ ---B----------------------B--- --AB----------------------BA-- -AAB----------------------BAA- -AAA----------------------AAA- CAAA----------------------AAAC AAAA----------------------AAAA AAAA----------------------AAAA AAAA----------------------AAAA CAAA----------------------AAAC -AAA----------------------AAA- -AAA----------------------AAA- --AA----------------------AA-- ---A----------------------A--- ------------------------------ 
------------------------------ ------------------------------ --A------------------------A-- -AA------------------------AA- -AA------------------------AA- AAA------------------------AAA CAA------------------------AAC AAA------------------------AAA CAC------------------------CAC AAA------------------------AAA -AA------------------------AA- -AA------------------------AA- --A------------------------A-- ------------------------------ ------------------------------ 
------------------------------ ------------------------------ ------------------------------ -A--------------------------A- -A--------------------------A- AA--------------------------AA BB--------------------------BB AB--------------------------BA BC--------------------------CB AC--------------------------CA -A--------------------------A- -A--------------------------A- ------------------------------ ------------------------------ ------------------------------ 
------------------------------ ------------------------------ ------------------------------ ------------------------------ ------------------------------ A----------------------------A C----------------------------C A----------------------------A A----------------------------A A----------------------------A ------------------------------ ------------------------------ ------------------------------ ------------------------------ ------------------------------ 
