model
size = 30 15 12, scale = 0.05, origin = -y
material 
  colors = A:#090 B:#F36 C:#909
voxels
-----CCCCB----------BCCCC----- ---BBBAAAAAAAABBAAAAAAAABBB--- --ACCACCAABABAAAABABAACCACCA-- -CAACBAAACCACAAAACACCAAABCAAC- -BACAACAABBBCBCCBCBBBAACAACAB- AABBBAAACAABAABBAABAACAAABBBAA CAACBCAACAACCCAACCCAACAACBCAAC AABBAAAAAACABAAAABACAAAAAABBAA AABCCAAAACBAAAAAAAABCAAAACCBAA CBAAAACBBCABAAAAAABACBBCAAAABC -BCACACAACAAABBBBAAACAACACACB- -AAAAABBBBAAAABBAAAABBBBAAAAA- --AAABBAACBACABBACABCAABBAAA-- ---CBABBACABAAAAAABACABBABC--- -----CCAAC----------CAACC----- 
-----ACCCB----------BCCCA----- ---AAAAAAACCCCCCCCCCAAAAAAA--- --AAAAAAAAAAAAAAAAAAAAAAAAAA-- -AAAAAAAAAAAAAAAAAAAAAAAAAAAA- -AAAAAAABBBBAAAAAABBBBAAAAAAA- BAAAAAABBBBBBAAAABBBBBBAAAAAAB AAAAAABBBBBBBBAABBBBBBBBAAAAAA AAAAAABBBBBBBBAABBBBBBBBAAAAAA AAAAAABBBBBBBBAABBBBBBBBAAAAAA BAAAAABBBBBBBBAABBBBBBBBAAAAAB -AAAAAABBBBBBAAAABBBBBBAAAAAA- -AAAAAAABBBBAAAAAABBBBAAAAAAA- --AAAAAAAAAAAAAAAAAAAAAAAAAA-- ---AAAAAAACCCCCCCCCCAAAAAAA--- -----ACCCB----------BCCCA----- 
-----CCACA----------ACACC----- ---AAAAAAABCCBAABCCBAAAAAAA--- --AAAAAAAAAAAAAAAAAAAAAAAAAA-- -AAAAA------------------AAAAA- -AAAAA------------------AAAAA- CAAAAA------------------AAAAAC AAAAAA------------------AAAAAA AAAAAA------------------AAAAAA AAAAAA------------------AAAAAA CAAAAA------------------AAAAAC -AAAAA------------------AAAAA- -AAAAA------------------AAAAA- --AAAA------------------AAAA-- ---AAAAAAABCCBAABCCBAAAAAAA--- -----CCACA----------ACACC----- 
-----BCBCA----------ACBCB----- ---AAAAAAACBBACCABBCAAAAAAA--- --AAAAAAAAAAAAAAAAAAAAAAAAAA-- -AAAAA------------------AAAAA- -AAAAA------------------AAAAA- AAAAAA------------------AAAAAA AAAAAA------------------AAAAAA CAAAAA------------------AAAAAC AAAAAA------------------AAAAAA AAAAAA------------------AAAAAA -AAAAA------------------AAAAA- -AAAAA------------------AAAAA- --AAAA------------------AAAA-- ---AAAAAAACBBACCABBCAAAAAAA--- -----BCBCA----------ACBCB----- 
-----CCCCA----------ACCCC----- ---AAAAAAAACABCCBACAAAAAAAA--- --AAAA------------------AAAA-- -AAAAA------------------AAAAA- -AAAAA------------------AAAAA- AAAAAA------------------AAAAAA CAAAAA------------------AAAAAC AAAAAA------------------AAAAAA CAAAAA------------------AAAAAC AAAAAA------------------AAAAAA -AAAAA------------------AAAAA- -AAAAA------------------AAAAA- --AAAA------------------AAAA-- ---AAAAAAAACABCCBACAAAAAAAA--- -----CCCCA----------ACCCC----- 
-----BBBBA----------ABBBB----- ---AAAAAAABBCACCACBBAAAAAAA--- --AAAA------------------AAAA-- -AAAAA------------------AAAAA- -AAAAA------------------AAAAA- AAAAAA------------------AAAAAA AAAAAA------------------AAAAAA AAAAAA------------------AAAAAA AAAAAA------------------AAAAAA AAAAAA------------------AAAAAA -AAAAA------------------AAAAA- -AAAAA------------------AAAAA- --AAAA------------------AAAA-- ---AAAAAAABBCACCACBBAAAAAAA--- -----BBBBA----------ABBBB----- 
-----AAAAA----------AAAAA----- ---AAAAAAAAAAAAAAAAAAAAAAAA--- --AAAA------------------AAAA-- -AAAAA------------------AAAAA- -AAAAA------------------AAAAA- AAAAAA------------------AAAAAA AAAAAA------------------AAAAAA BAAAAA------------------AAAAAB AAAAAA------------------AAAAAA AAAAAA------------------AAAAAA -AAAAA------------------AAAAA- -AAAAA------------------AAAAA- --AAAA------------------AAAA-- ---AAAAAAAAAAAAAAAAAAAAAAAA--- -----AAAAA----------AAAAA----- 
------------------------------ ---AA--------------------AA--- --AAA--------------------AAA-- -AAAA--------------------AAAA- -AAAA--------------------AAAA- AAAAA--------------------AAAAA AAAAA--------------------AAAAA AAAAA--------------------AAAAA AAAAA--------------------AAAAA AAAAA--------------------AAAAA -AAAA--------------------AAAA- -AAAA--------------------AAAA- --AAA--------------------AAA-- ---AA--------------------AA--- ------------------------------ 
------------------------------ ---A----------------------A--- --AA----------------------AA-- -AAA----------------------AAA- -AAA----------------------AAA- CAAA----------------------AAAC AAAA----------------------AAAA CAAA----------------------AAAC AAAA----------------------AAAA CAAA----------------------AAAC -AAA----------------------AAA- -AAA----------------------AAA- --AA----------------------AA-- ---A----------------------A--- ------------------------------ 
------------------------------ ------------------------------ --A------------------------A-- -AA------------------------AA- -AA------------------------AA- AAA------------------------AAA AAA------------------------AAA AAA------------------------AAA AAA------------------------AAA AAA------------------------AAA -AA------------------------AA- -AA------------------------AA- --A------------------------A-- ------------------------------ ------------------------------ 
------------------------------ ------------------------------ ------------------------------ -A--------------------------A- -A--------------------------A- AA--------------------------AA AA--------------------------AA BA--------------------------AB AA--------------------------AA AA--------------------------AA -A--------------------------A- -A--------------------------A- ------------------------------ ------------------------------ ------------------------------ 
------------------------------ ------------------------------ ------------------------------ ------------------------------ ------------------------------ A----------------------------A A----------------------------A A----------------------------A A----------------------------A A----------------------------A ------------------------------ ------------------------------ ------------------------------ ------------------------------ ------------------------------ 
