model
size = 32 4 32, scale = 0.05, origin = -y
material 
  colors = A:#FF0
voxels
44-8A24-8A56-8A21-14A18-14A21-8A21-14A16-18A14-18A16-14A16-5A8-5A13-20A12-20A13-5A8-5A13-3A14-3A11-7A8-7A10-7A8-7A11-3A14-3A11-3A16-3A9-5A14-5A8-5A14-5A9-3A16-3A9-3A18-3A7-5A16-5A6-5A16-5A7-3A18-3A7-3A20-3A5-5A18-5A4-5A18-5A5-3A20-3A5-3A22-2A5-4A20-4A4-4A20-4A5-2A22-2A5-2(2A24-2A3-4A22-4A2-4A22-4A3-2A24-2A4-)2A24-2A3-4A22-4A2-4A22-4A3-2A24-2A3-7(2A26-2A-4A24-8A24-4A-2A26-2A2-)2A26-2A-4A24-8A24-4A-2A26-2A3-2(2A24-2A3-4A22-4A2-4A22-4A3-2A24-2A4-)2A24-2A3-4A22-4A2-4A22-4A3-2A24-2A5-2A22-2A5-4A20-4A4-4A20-4A5-2A22-2A6-3A20-3A5-5A18-5A4-5A18-5A6-2A20-2A8-3A18-3A7-5A16-5A6-5A16-5A7-3A18-3A9-3A16-3A9-5A14-5A8-5A14-5A9-3A16-3A11-3A14-3A11-7A8-7A10-7A8-7A11-3A14-3A13-5A8-5A13-20A12-20A13-5A8-5A16-14A16-18A14-18A15-15A21-8A21-14A18-14A21-8A56-8A24-8A44-
