model
size = 24 32 32, scale = 0.05, origin = -y
material 
  colors = A:#845A2B B:#7F562A C:#AE5233 D:#800 E:#DDD F:#111
voxels
24-5A2-3A-2A5-5A-53AB2AB6AB16A2(B6A)B4A2B3AB2A2D2AB6AB4A2B3ABAD2ADAB6AB4AB6AD3AD4AB2AB4AB2(5AD)3AB7AB3A2D6AD3AB7AB2AD9AD2AB7AB2AD3AB6AD11AD4AB7AD9AD5AB2(8AD)5AB9AD6AD4A2(BA)B2A2B3AD7A2B2AB3AB2A2B4AD6A2B2AB3AB2A2B5AD5A2B6AB2A2B6AB12AB2A2B6ABAB7AB9A2-2A2(BA)4-2A2(B6A5-4ABA5-A)B2A2B3A4-4ABA5-AB2A2B3A4-6A4-2AB2A2B3A4-7A-4AB5AB23A2(B5AB4AB12A)B5AB4AB21A23-9(2A22-)4(BA22-)7(2A22-)2(2A2-6C6-7C-)2A2-C3E2C6-2C3E2C-2A2-CEFE2C6-2CEFE2C-2A2-C3E2C6-2C3E2C2(-2A2-6C6-7C)-2(BA22-)2A22-3AB5ABAB13A2(23-A)23-6(2A22-)4(AB22-)2A3(22-BA)8(22-2A)5(22-AB)22-2B22-B2A2(BAB3A)B6AB2A47-A23-10(2A22-)4(AB22-)14(2A22-)2(3ABAB)3AB6AB2A24-A2(22-2A)4(22-BA)23(22-2A)22-3ABAB4A2(B5A)B2A47-6(2A22-)5(BA22-)8(2A22-)7(BA22-)3(2A22-)4A2B4ABAB3AB5AB2A47-4(2A22-)3(AB22-)6(2A22-)3(BA22-)3(2A22-)8(AB22-)2(2A22-)4A2B2ABAB2AB3AB4AB2A24-A23-A6(22-2A)3(22-AB)14(22-2A)5(22-BA)22-4A2B2AB4AB3AB4AB2A24-A23-A12(22-2A)22-AB15(22-2A)22-4A2B2AB5AB3AB4ABA47-A23-3(2A22-)6(BA22-)3(2A22-)2(AB22-)5(2B22-)BA8(22-2A)22-4A2B2A2B4AB3AB4ABA47-24(2A22-)4(BA22-)2A22-5AB2A2B5AB7ABA47-19(2A22-)2(BA22-)8(2A22-)2(2AB)2A2B8AB4ABA24-A23-A3(22-2A)4(22-2B)22-AB17(22-2A)2(22-BA)2(22-2A)B6AB2AB5AB4ABA24-2(A23-)A6(22-2A)22-BA3(22-2B)2(22-AB)5(22-2A)2(22-AB)2(22-2B)2(22-BA)4(22-2A)22-3AB6ABAB6AB3ABA71-22(2A22-)3(AB22-)2(2B22-)2A22-3AB6ABAB6AB3ABA47-A23-14(2A22-)BA3(22-AB)10(22-2A)22-3AB6ABAB4ABAB5A47-6(2A22-)5(BA22-)2(2B22-)3(AB22-)2(BA22-)6(2A22-)2(BA22-)3(2A22-)4AB5AB2AB3AB2AB4A24-A8(22-2A)3(22-AB)7(22-2A)2(22-BA)6(22-2A)22-BA2(22-2A)22-2(4ABAB)3AB2ABAB2A24-A20(22-2A)2(22-BA)5(22-2A)2(22-BA)22-2(4ABAB)3AB2ABAB2A47-12(2A22-)10(AB22-)2B22-AB5(22-2A)22-5A2(BAB3A)B2ABAB2A2(23-A)23-3(2A22-)8(BA22-)15(2A22-)2(BA22-)B4ABAB9AB2A2(BA)B24-A12(22-2A)7(22-BA)3(22-2A)5(22-BA)2(22-2A)22-3AB4AB6AB4ABAB2A48-A10(22-2A)3(22-BA)8(22-2A)22-AB6(22-2A)22-3AB4AB3AB2A2(B4A)48-A7(22-2A)3(22-BA)6(22-2A)5(22-BA)3(22-AB)2(22-2B)22-AB22-2A22-3AB4AB3A2(B2A)BAB4A48-A3(22-2A)7(22-AB)22-2A5(22-AB)6(22-2A)3(22-BA)3(22-2A)22-3AB5A2(B2A)BAB2AB4A23-18(2A22-)6(AB22-)6(2A22-)2(4AB)2(2AB)AB7A24-A7(22-2A)13(22-BA)7(22-2A)2(22-BA)22-4AB7A2(B3A)B4A47-29(2A22-)4AB2AB8AB3AB4A47-A23-8(2A22-)3(BA22-)2B7(22-AB)3(22-2B)4(22-2A)2(22-BA)22-B6AB7AB5AB3A71-4(2A22-)4(BA22-)14(2A22-)4(BA22-)2(2A22-)7AB4AB8AB3A23-10(2A22-)6(BA22-)11(2A22-)3(AB22-)7AB5AB7AB3A25-2(A2-)2(2A3-)2A4-3A-11A2-10A-73AB23AB25AB2A2(B4A)B10AB2A2(B4A)B13A2(B4A)B12A2(B5AB13AB3A)B4AB6AB7AB3AB4AB6AB7AB8AB3AB2AB5AB3AB6AB3AB2AB5AB3AB4ABAB3AB2AB6AB2AB5A2B3AB9AB2AB5A2B2(3AB)11A3(B3A)B11AB3AB7A2(B5A)B3AB7AB5ABAB2A2(B3A)2(B4A)2(B2A)3(2(B3A)B4AB7AB2A)2(B3A)2(BAB2AB4A)B3ABAB2AB4ABAB2AB10AB2AB3A2(B2A)B10AB9AB7AB11A
