model
size = 19 28 19, scale = 0.05, origin = -y
material 
  colors = A:#222 B:#444 C:#777
voxels
------------------- ------------------- ------------------- ------------------- ------------------- ----------AAAAAA--- ----------AAAAAA--- ------------------- ------------------- ------------------- ------------------- ------------------- ------------------- ------------------- ------------------- ------------------- ------------------- ------------------- ------------------- ------------------- ------------------- ------------------- ------------------- ------------------- ------------------- ------------------- ------------------- ------------------- 
----AAAAAAAA------- ---AA----AAAAA----- --AA-----AAAAAA---- -AA------AAAAAAAA-- -A-------AAAAAAAA-- -A-------AAAAAAAA-- AA-------AAAAAAAA-- A--------AAAAAAAA-- A--------AACAAAAA-- A--------AACAAAAA-- A--------AACAAAAA-- A--------AACAAAAA-- A--------AACAAAAA-- A--------AACAAAAA-- A--------AACAAAAA-- A--------AACAAAAA-- A--------AACAAAAA-- A--------AACAAAAA-- A--------AACAAAAA-- A--------AACAAAAA-- A--------AACAAAAA-- AA-------AACAAAAA-- -A-------AACAAAAA-- -A-------AAACAA---- -AA------AAAAA----- --AA-----AAAA------ ---AA--AAA--------- ----AAAA----------- 
----AAAAAAAA------- ---AA----AAAAA----- --AA-----AAAAAA---- -AA------AAAAAAAA-- -A------AAAAAAAAAAA -A------AAAAAAAAAAA AA------AAAAAAAAAAA A--------AAAAAAAAAA A--------AAAAAAAAAA A-------AAAAAAAAAAA A-------AAAAAAAAAAA A-------AAAAAAAAAAA A-------AAAAAAAAAAA A-------AAAAAAAAA-- A-------AAAAAAAAA-- A-------AAAAAAAAA-- A-------AAAAAAAAA-- A-------AAAAAAAAA-- A-------AAAAAAAAA-- A-------AAAAAAAAA-- A-------AAAAAAAAA-- AA------AAAAAAAAA-- -A------AAAAAAAAA-- -A------AAAAAAA---- -AA-----AAAAAA----- --AA-----AAAA------ ---AA--AAA--------- ----AAAA----------- 
---------AAA------- ---------AAAAA----- ---------AAAAAA---- ---------AAAAAAAA-- --------AAAAAAAAAAA --------AAAAAAAAAAA --------AAAAAAAAAAA ---------AAAAAAAAAA ---------AAAAAAAAAA --------AAAAAAAAAAA --------AAAAAAAAAAB --------AAAAAAAAAAA --------AAAAAAAAAAA --------AAAAAAAAA-- --------AAAAAAAAA-- --------AAAAAAAAA-- --------AAAAAAAAA-- --------AAAAAAAAA-- --------AAAAAAAAA-- --------AAAAAAAAA-- --------AAAAAAAAA-- --------AAAAAAAAA-- --------AAAAAAAAA-- --------AAAAAAA---- --------AAAAAA----- ---------AAAA------ ------------------- ------------------- 
---------AAA------- ---------AAAAA----- ---------AAAAAA---- ---------AAAAAAAA-- --------AAAAAAAAAAA --------AAAAAAAAAAA --------AAAAAAAAAAA ---------AAAAAAAAAA ---------AAAAAAAAAA --------AAAAAAAAAAA --------AAAAAAAAAAB --------AAAAAAAAAAA --------AAAAAAAAAAA --------AAAAAAAAA-- --------AAAAAAAAA-- --------AAAAAAAAA-- --------AAAAAAAAA-- --------AAAAAAAAA-- --------AAAAAAAAA-- --------AAAAAAAAA-- --------AAAAAAAAA-- --------AAAAAAAAA-- --------AAAAAAAAA-- --------AAAAAAA---- --------AAAAAA----- ---------AAAA------ ------------------- ------------------- 
---------AAA------- ---------AAAAA----- ---------AAAAAA---- ---------AAAAAAAA-- --------AAAAAAAAAAA --------AAAAAAAAAAA --------AAAAAAAAAAA ---------AAAAAAAAAA ---------AAAAAAAAAA --------AAAAAAAAAAA --------AAAAAAAAAAB --------AAAAAAAAAAA --------AAAAAAAAAAA --------AAAAAAAAA-- --------AAAAAAAAA-- --------AAAAAAAAA-- --------AAAAAAAAA-- --------AAAAAAAAA-- --------AAAAAAAAA-- --------AAAAAAAAA-- --------AAAAAAAAA-- --------AAAAAAAAA-- --------AAAAAAAAA-- --------AAAAAAA---- --------AAAAAA----- ---------AAAA------ ------------------- ------------------- 
---------AAA------- ---------AAAAA----- ---------AAAAAA---- ---------AAAAAAAA-- --------AAAAAAAAAAA --------AAAAAAAAAAA --------AAAAAAAAAAA ---------AAAAAAAAAA ---------AAAAAAAAAA --------AAAAAAAAAAA --------AAAAAAAAAAB --------AAAAAAAAAAA --------AAAAAAAAAAA --------AAAAAAAAA-- --------AAAAAAAAA-- --------AAAAAAAAA-- --------AAAAAAAAA-- --------AAAAAAAAA-- --------AAAAAAAAA-- --------AAAAAAAAA-- --------AAAAAAAAA-- --------AAAAAAAAA-- --------AAAAAAAAA-- --------AAAAAAA---- --------AAAAAA----- ---------AAAA------ ------------------- ------------------- 
---------AAA------- ---------AAAAA----- ---------AAAAAA---- ---------AAAAAAAA-- --------AAAAAAAAAAA --------AAAAAAAAAAA --------AAAAAAAAAAA ---------AAAAAAAAAA ---------AAAAAAAAAA --------AAAAAAAAAAA --------AAAAAAAAAAB --------AAAAAAAAAAA --------AAAAAAAAAAA --------AAAAAAAAA-- --------AAAAAAAAA-- --------AAAAAAAAA-- --------AAAAAAAAA-- --------AAAAAAAAA-- --------AAAAAAAAA-- --------AAAAAAAAA-- --------AAAAAAAAA-- --------AAAAAAAAA-- --------AAAAAAAAA-- --------AAAAAAA---- --------AAAAAA----- ---------AAAA------ ------------------- ------------------- 
---------AAA------- ---------AAAAA----- ---------AAAAAA---- ---------AAAAAAAA-- --------AAAAAAAAAAA --------AAAAAAAAAAA --------AAAAAAAAAAA ---------AAAAAAAAAA ---------AAAAAAAAAA --------AAAAAAAAAAA --------AAAAAAAAAAB --------AAAAAAAAAAA --------AAAAAAAAAAA --------AAAAAAAAA-- --------AAAAAAAAA-- --------AAAAAAAAA-- --------AAAAAAAAA-- --------AAAAAAAAA-- --------AAAAAAAAAC- --------AAAAAAAAAC- --------AAAAAAAAA-- --------AAAAAAAAA-- --------AAAAAAAAA-- --------AAAAAAA---- --------AAAAAA----- ---------AAAA------ ------------------- ------------------- 
---------AAA------- ---------AAAAA----- ---------AAAAAA---- ---------AAAAAAAA-- --------AAAAAAAAAAA --------AAAAAAAAAAA --------AAAAAAAAAAA ---------AAAAAAAAAA ---------AAAAAAAAAA --------AAAAAAAAAAA --------AAAAAAAAAAB --------AAAAAAAAAAA --------AAAAAAAAAAA --------AAAAAAAAA-- --------AAAAAAAAA-- --------AAAAAAAAA-- --------AAAAAAAAA-- --------AAAAAAAAAC- --------AAAAAAAAA-- --------AAAAAAAAA-- --------AAAAAAAAAC- --------AAAAAAAAA-- --------AAAAAAAAA-- --------AAAAAAA---- --------AAAAAA----- ---------AAAA------ ------------------- ------------------- 
---------AAA------- ---------AAAAA----- ---------AAAAAA---- ---------AAAAAAAA-- --------AAAAAAAAAAA --------AAAAAAAAAAA --------AAAAAAAAAAA ---------AAAAAAAAAA ---------AAAAAAAAAA --------AAAAAAAAAAA --------AAAAAAAAAAB --------AAAAAAAAAAA --------AAAAAAAAAAA --------AAAAAAAAA-- --------AAAAAAAAA-- --------AAAAAAAAA-- --------AAAAAAAAA-- --------AAAAAAAAAC- --------AAAAAAAAA-- --------AAAAAAAAA-- --------AAAAAAAAAC- --------AAAAAAAAA-- --------AAAAAAAAA-- --------AAAAAAA---- --------AAAAAA----- ---------AAAA------ ------------------- ------------------- 
---------AAA------- ---------AAAAA----- ---------AAAAAA---- ---------AAAAAAAA-- --------AAAAAAAAAAA --------AAAAAAAAAAA --------AAAAAAAAAAA ---------AAAAAAAAAA ---------AAAAAAAAAA --------AAAAAAAAAAA --------AAAAAAAAAAB --------AAAAAAAAAAA --------AAAAAAAAAAA --------AAAAAAAAA-- --------AAAAAAAAA-- --------AAAAAAAAA-- --------AAAAAAAAA-- --------AAAAAAAAA-- --------AAAAAAAAA-- --------AAAAAAAAA-- --------AAAAAAAAA-- --------AAAAAAAAA-- --------AAAAAAAAA-- --------AAAAAAA---- --------AAAAAA----- ---------AAAA------ ------------------- ------------------- 
---------AAA------- ---------AAAAA----- ---------AAAAAA---- ---------AAAAAAAA-- --------AAAAAAAAAAA --------AAAAAAAAAAA --------AAAAAAAAAAA ---------AAAAAAAAAA ---------AAAAAAAAAA --------AAAAAAAAAAA --------AAAAAAAAAAB --------AAAAAAAAAAA --------AAAAAAAAAAA --------AAAAAAAAA-- --------AAAAAAAAA-- --------AAAAAAAAA-- --------AAAAAAAAA-- --------AAAAAAAAA-- --------AAAAAAAAA-- --------AAAAAAAAA-- --------AAAAAAAAA-- --------AAAAAAAAA-- --------AAAAAAAAA-- --------AAAAAAA---- --------AAAAAA----- ---------AAAA------ ------------------- ------------------- 
---------AAA------- ---------AAAAA----- ---------AAAAAA---- ---------AAAAAAAA-- --------AAAAAAAAAAA --------AAAAAAAAAAA --------AAAAAAAAAAA ---------AAAAAAAAAA ---------AAAAAAAAAA --------AAAAAAAAAAA --------AAAAAAAAAAB --------AAAAAAAAAAA --------AAAAAAAAAAA --------AAAAAAAAA-- --------AAAAAAAAA-- --------AAAAAAAAA-- --------AAAAAAAAA-- --------AAAAAAAAA-- --------AAAAAAAAA-- --------AAAAAAAAA-- --------AAAAAAAAA-- --------AAAAAAAAA-- --------AAAAAAAAA-- --------AAAAAAA---- --------AAAAAA----- ---------AAAA------ ------------------- ------------------- 
---------AAA------- ---------AAAAA----- ---------AAAAAA---- ---------AAAAAAAA-- --------AAAAAAAAAAA --------AAAAAAAAAAA --------AAAAAAAAAAA ---------AAAAAAAAAA ---------AAAAAAAAAA --------AAAAAAAAAAA --------AAAAAAAAAAB --------AAAAAAAAAAA --------AAAAAAAAAAA --------AAAAAAAAA-- --------AAAAAAAAA-- --------AAAAAAAAA-- --------AAAAAAAAA-- --------AAAAAAAAA-- --------AAAAAAAAA-- --------AAAAAAAAA-- --------AAAAAAAAA-- --------AAAAAAAAA-- --------AAAAAAAAA-- --------AAAAAAA---- --------AAAAAA----- ---------AAAA------ ------------------- ------------------- 
---------AAA------- ---------AAAAA----- ---------AAAAAA---- ---------AAAAAAAA-- --------AAAAAAAAAAA --------AAAAAAAAAAA --------AAAAAAAAAAA ---------AAAAAAAAAA ---------AAAAAAAAAA --------AAAAAAAAAAA --------AAAAAAAAAAB --------AAAAAAAAAAA --------AAAAAAAAAAA --------AAAAAAAAA-- --------AAAAAAAAA-- --------AAAAAAAAA-- --------AAAAAAAAA-- --------AAAAAAAAA-- --------AAAAAAAAA-- --------AAAAAAAAA-- --------AAAAAAAAA-- --------AAAAAAAAA-- --------AAAAAAAAA-- --------AAAAAAA---- --------AAAAAA----- ---------AAAA------ ------------------- ------------------- 
---------AAA------- ---------AAAAA----- ---------AAAAAA---- ---------AAAAAAAA-- --------AAAAAAAAAAA --------AAAAAAAAAAA --------AAAAAAAAAAA ---------AAAAAAAAAA ---------AAAAAAAAAA --------AAAAAAAAAAA --------AAAAAAAAAAB --------AAAAAAAAAAA --------AAAAAAAAAAA --------AAAAAAAAA-- --------AAAAAAAAA-- --------AAAAAAAAA-- --------AAAAAAAAA-- --------AAAAAAAAA-- --------AAAAAAAAA-- --------AAAAAAAAA-- --------AAAAAAAAA-- --------AAAAAAAAA-- --------AAAAAAAAA-- --------AAAAAAA---- --------AAAAAA----- ---------AAAA------ ------------------- ------------------- 
----AAAAAAAA------- ---AA----AAAAA----- --AA-----AAAAAA---- -AA------AAAAAAAA-- -A------AAAAAAAAAAA -A------AAAAAAAAAAA AA------AAAAAAAAAAA A--------AAAAAAAAAA A--------AAAAAAAAAA A-------AAAAAAAAAAA A-------AAAAAAAAAAA A-------AAAAAAAAAAA A-------AAAAAAAAAAA A-------AAAAAAAAA-- A-------AAAAAAAAA-- A-------AAAAAAAAA-- A-------AAAAAAAAA-- A-------AAAAAAAAA-- A-------AAAAAAAAA-- A-------AAAAAAAAA-- A-------AAAAAAAAA-- AA------AAAAAAAAA-- -A------AAAAAAAAA-- -A------AAAAAAA---- -AA-----AAAAAA----- --AA-----AAAA------ ---AA--AAA--------- ----AAAA----------- 
----AAAAAAAA------- ---AA----AABAA----- --AA-----AABABA---- -AA------AABABAAA-- -A-------AABABAAA-- -A-------AABABAAA-- AA-------AABABAAA-- A--------AABABAAA-- A--------AABABAAA-- A--------AABABAAA-- A--------AABABAAA-- A--------AABABAAA-- A--------AABABAAA-- A--------AABABAAA-- A--------AABABAAA-- A--------AABABAAA-- A--------AABABAAA-- A--------AABABAAA-- A--------AABABAAA-- A--------AABABAAA-- A--------AABABAAA-- AA-------AABABAAA-- -A-------AABABAAA-- -A-------AABABA---- -AA------AABAA----- --AA-----AAAA------ ---AA--AAA--------- ----AAAA----------- 
