model
size = 20 29 13, scale = 0.05, origin = -y
material 
  colors = A:#222 B:#777 C:#AAA D:#555 E:#FFF F:#FFC G:#009 H:#00C I:#00F J:#444 K:#D00 L:#0E0 M:#500
voxels
-------------------- ---CCCCCCCCCCCCCCCC- ---AAAAAAAAAAAA--AA- ---AAAAAAAAAAAAAAAA- ---AAAAAAAAAAAAAAAA- ---AAAAAAAAAAAAAAAA- ---AAAAAAAAAAAAAAAA- ---AAAAA---------AA- ---AAAAA---------AA- ---AAAAA---------AA- ---AAAAAAAAAAAAAAAA- ---CCCCCCCCCCCCCCCC- ---AAAAAAAAAAAAAAA-- ---AAAAAAA---------- -------------------- -------------------- -------------------- -------------------- -------------------- -------------------- -------------------- -------------------- -------------------- -------------------- -------------------- -------------------- -------------------- -------------------- -------------------- 
---DDDDDDDDDDDDDDDD- -CCAAAAAAAAAAAAAAAAC -AAAAAAAAAAAAAALKAAA -AAAAAAAAAAAAAAAAAAA -AAAAAAAAAAAAAAAAAAA -AAAAAAAAAAAAAAAAAAA -AAAAAAAAAAAAAAAAAAA -AAAAAAAIIIIIIIIIAAA -AAAAAAAHHHHHHHHHAAA -AAAAAAAGGGGGGGGGAAA -AAAAAAAAAAAAAAAAAAA -CCAAAAAAAAAAAAAAACC -AAABBBBBBBBBBBBBA-- -AAAAAAAAAAAAAAAAA-- -------------------- -------------------- -------------------- -------------------- -------------------- -------------------- -------------------- -------------------- -------------------- -------------------- -------------------- -------------------- -------------------- -------------------- -------------------- 
-DDDAAAAAAAAAAAAAAD- CBBAAAAAAAAAAAAAAAAC ABBAAAAAAAAAAAAAAAAA ABBAAAAAAAAAAAAAAAAA ABBAAAAAAAAAAAAAAAAA ABBAAAAAAAAAAAAAAAAA ABBAAAAAAAAAAAAAAAAA ABBAAAAABBBBBBBBBAAA ABBAAAAABBBBBBBBBAAA ABBAAAAABBBBBBBBBAAA ABBAAAAAAAAAAAAAAAAA CBBAAAAAAAAAAAAAAACC ABBABBBBBBBBBBBBBA-- AAAAAAAAAAAAAAAAAA-- -----DDD------------ -----DDD------------ -----FFF------------ -----FFF------------ -----EEE------------ -----EEE------------ -----EEE------------ -----DDD------------ -----DDD------------ -------------------- -------------------- -------------------- -------------------- -------------------- -------------------- 
-DAAAAAAAAAAAAAAAAD- CBBAAAAAAAAAAAAAAAAC ABBAAAAAAAAAAAAAAAAA ABBAAAAAAAAAAAAAAAAA ABBAAAAAAAAAAAAAAAAA ABBAAAAAAAAAAAAAAAAA ABBAAAAAAAAAAAAAAAAA ABBAAAAABBBBBBBBBAAA ABBAAAAABBBBBBBBBAAA ABBAAAAABBBBBBBBBAAA ABBAAAAAAAAAAAAAAAAA CBBAAAAAAAAAAAAAAACC ABBABBBBBBBBBBBBBA-- AAAAAAAAAAAAAAAAAA-- ----DBBBD----------- ----DBBBD----------- ----FBBBF----------- ----FBBBF----------- ----EBBBE----------- ----EBBBE----------- ----EBBBE----------- ----DBBBD----------- ----DDDDD----------- -------------------- -------------------- -------------------- -------------------- -------------------- -------------------- 
-DAAAAAAAAAAAAAAAAD- CBBAAAAAAAAAAAAAAAAC ABBAAAAAAAAAAAAAAAAA ABBAAAAAAAAAAAAAAAAA ABBAAAAAAAAAAAAAAAAA ABBAAAAAAAAAAAAAAAAA ABBAAAAAAAAAAAAAAAAA ABBAAAAABBBBBBBBBAAA ABBAAAAABBBBBBBBBAAA ABBAAAAABBBBBBBBBAAA ABBAAAAAAAAAAAAAAAAA CBBAAAAAAAAAAAAAAACC ABBABAAABBBBBBBBBA-- AAAAAAAAAAAAAAAAAA-- ---DBAJABD---------- ---DBAMABD---------- ---FBAAABF---------- ---FBBBBBF---------- ---EBBBBBE---------- ---EBBBBBE---------- ---EBBBBBE---------- ---DBBBBBD---------- ---DDBBBDD---------- -----CCC------------ -----CCC------------ -----CCC------------ -----CCC------------ -----CCC------------ ------C------------- 
-DAAAAAAAAAAAAAAAAD- CBBAAAAAAAAAAAAAAAAC ABBAAAAAAAAAAAAAAAAA ABBAAAAAAAAAAAAAAAAA ABBAAAAAAAAAAAAAAAAA ABBAAAAAAAAAAAAAAAAA ABBAAAAAAAAAAAAAAAAA ABBAAAAAABBBBBBBBAAA ABBAAAAAABBBBBBBBAAA ABBAAAAAABBBBBBBBAAA ABBAAAAAAAAAAAAAAAAA CBBAAAAAAAAAAAAAAACC ABBAAAAAABBBBBBBBA-- AABAAAAAAABAAAAAAA-- --DBAAAAABD--------- --DBAAAAABD--------- --FBAAAAABF--------- --FBAAAAABF--------- --EBAAAAABE--------- --EBAAAAABE--------- --EBJJJJJBE--------- --DBBBBBBBD--------- --DDBBBBBDD--------- ----CBBBC----------- ----CBBBC----------- ----CBBBC----------- ----CBBBC----------- ----CBBBC----------- -----CCC------------ 
-DAAAAAAAAAAAAAAAAD- CBBAAAAAAAAAAAAAAAAC ABBAAAAAAAAAAAAAAAAA ABBAAAAAAAAAAAAAAAAA ABBAAAAAAAAAAAAAAAAA ABBAAAAAAAAAAAAAAAAA ABBAAAAAAAAAAAAAAAAA ABBAAAAAABBBBBBBBAAA ABBAAAAAABBBBBBBBAAA ABBAAAAAABBBBBBBBAAA ABBAAAAAAAAAAAAAAAAA CBBAAAAAAAAAAAAAAACC ABBAAAAAABBBBBBBBA-- AABAAAAAAABAAAAAAA-- --DBAAAAABD--------- --DBAAAAABD--------- --FBAAAAABF--------- --FBAAAAABF--------- --EBAAAAABE--------- --EBAAAAABE--------- --EBJAAJJBE--------- --DBBBBBBBD--------- --DDBBBBBDD--------- ----CBBBC----------- ----CBBBC----------- ----CBBBC----------- ----CBBBC----------- ----CBBBC----------- ----CCCCC----------- 
-DAAAAAAAAAAAAAAAAD- CBBAAAAAAAAAAAAAAAAC ABBAAAAAAAAAAAAAAAAA ABBAAAAAAAAAAAAAAAAA ABBAAAAAAAAAAAAAAAAA ABBAAAAAAAAAAAAAAAAA ABBAAAAAAAAAAAAAAAAA ABBAAAAAABBBBBBBBAAA ABBAAAAAABBBBBBBBAAA ABBAAAAAABBBBBBBBAAA ABBAAAAAAAAAAAAAAAAA CBBAAAAAAAAAAAAAAACC ABBAAAAAABBBBBBBBA-- AABAAAAAAABAAAAAAA-- --DBAAAAABD--------- --DBAAAAABD--------- --FBAAAAABF--------- --FBAAAAABF--------- --EBAAAAABE--------- --EBAAAAABE--------- --EBJAAJJBE--------- --DBBBBBBBD--------- --DDBBBBBDD--------- ----CBBBC----------- ----CBBBC----------- ----CBBBC----------- ----CBBBC----------- ----CBBBC----------- -----CCC------------ 
-DAAAAAAAAAAAAAAAAD- CBBBBAAABBBBBBBBBBBC ABBBBAAABBBBBBBBBBBA ABBBBAAABBBBBBBBBBBA ABBBBAAABBBBBBBBBBBA ABBBBAAABBBBBBBBBBBA ABBBBAAABBBBBBBBBBBA ABBBBAAABBBBBBBBBBBA ABBBBAAABBBBBBBBBBBA ABBBBAAABBBBBBBBBBBA ABBBBAAABBBBBBBBBBBA CBBBBAAABBBBBBBBBBCC ABBBBAAABBBBBBBBBA-- AAABBAAABBAAAAAAAA-- ---DBAAABD---------- ---DBAAABD---------- ---FBAAABF---------- ---FBAAABF---------- ---EBAAABE---------- ---EBAAABE---------- ---EBJJJBE---------- ---DBBBBBD---------- ---DDBBBBD---------- -----CCC------------ -----CCC------------ -----CCC------------ -----CCC------------ -----CCC------------ ------C------------- 
-DAAAAAAAAAAAAAAAAD- CBBBBBBBBBBBBBBBBBBC ABBBBBBBBBBBBBBBBBBA ABBBBBBBBBBBBBBBBBBA ABBBBBBBBBBBBBBBBBBA ABBBBBBBBBBBBBBBBBBA ABBBBBBBBBBBBBBBBBBA ABBBBBBBBBBBBBBBBBBA ABBBBBBBBBBBBBBBBBBA ABBBBBBBBBBBBBBBBBBA ABBBBBBBBBBBBBBBBBBA CBBBBBBBBBBBBBBBBBCC ABBBBBBBBBBBBBBBBA-- AAAABBBBBAAAAAAAAA-- ----DBBBD----------- ----DBBBD----------- ----FBBBF----------- ----FBBBF----------- ----EBBBE----------- ----EBBBE----------- ----EBBBE----------- ----DBBBD----------- ----DDDDD----------- -------------------- -------------------- -------------------- -------------------- -------------------- -------------------- 
-DDDAAAAAAAAAAAAAAD- CBBBBBBBBBBBBBBBBBBC ABBBBBBBBBBBBBBBBBBA ABBBBBBBBBBBBBBBBBBA ABBBBBBBBBBBBBBBBBBA ABBBBBBBBBBBBBBBBBBA ABBBBBBBBBBBBBBBBBBA ABBBBBBBBBBBBBBBBBBA ABBBBBBBBBBBBBBBBBBA ABBBBBBBBBBBBBBBBBBA ABBBBBBBBBBBBBBBBBBA CBBBBBBBBBBBBBBBBBCC ABBBBBBBBBBBBBBBBA-- AAAAABBBAAAAAAAAAA-- -----DDD------------ -----DDD------------ -----FFF------------ -----FFF------------ -----EEE------------ -----EEE------------ -----EEE------------ -----DDD------------ -----DDD------------ -------------------- -------------------- -------------------- -------------------- -------------------- -------------------- 
---DDDDDDDDDDDDDDDD- -CCABBBBBBBBBBBBBBBC -AABBBBBBBBBBBBLKBBA -AABBBBBBBBBBBBBBBBA -AABBBBBBBBBBBBBBBBA -AABBBBBBBBBBBBBBBBA -AABBBBBBBBBBBBBBBBA -AABBBBBIIIIIIIIIBBA -AABBBBBHHHHHHHHHBBA -AABBBBBGGGGGGGGGBBA -AABBBBBBBBBBBBBBBBA -CCBBBBBBBBBBBBBBBCC -AABBBBBBBBBBBBBBA-- -AAAAAAAAAAAAAAAAA-- -------------------- -------------------- -------------------- -------------------- -------------------- -------------------- -------------------- -------------------- -------------------- -------------------- -------------------- -------------------- -------------------- -------------------- -------------------- 
-------------------- ---CCCCCCCCCCCCCCCC- ---AAAAAAAAAAAA--AA- ---AAAAAAAAAAAAAAAA- ---AAAAAAAAAAAAAAAA- ---AAAAAAAAAAAAAAAA- ---AAAAAAAAAAAAAAAA- ---AAAAA---------AA- ---AAAAA---------AA- ---AAAAA---------AA- ---AAAAAAAAAAAAAAAA- ---CCCCCCCCCCCCCCCC- ---AAAAAAAAAAAAAAA-- ---AAAAAAA---------- -------------------- -------------------- -------------------- -------------------- -------------------- -------------------- -------------------- -------------------- -------------------- -------------------- -------------------- -------------------- -------------------- -------------------- -------------------- 
