model
size = 20 29 13, scale = 0.05, origin = -y
material 
  colors = A:#33C B:#777 C:#222 D:#AAA E:#555 F:#FCF G:#FFF H:#050 I:#090 J:#0C0 K:#0F3 L:#444 M:#D00 N:#0E0 O:#500
voxels
-------------------- ---DDDDDDDDDDDDDDDD- ---AAAAAAAAAAAA--AA- ---AAAAAAAAAAAAAAAA- ---AAAAAAAAAAAAAAAA- ---AAAAAAAAAAAAAAAA- ---AAAAAAAAAAAAAAAA- ---AAAAA---------AA- ---AAAAA---------AA- ---AAAAA---------AA- ---AAAAAAAAAAAAAAAA- ---DDDDDDDDDDDDDDDD- ---AAAAAAAAAAAAAAA-- ---AAAAAAA---------- -------------------- -------------------- -------------------- -------------------- -------------------- -------------------- -------------------- -------------------- -------------------- -------------------- -------------------- -------------------- -------------------- -------------------- -------------------- 
---EEEEEEEEEEEEEEEE- -DDCCCCCCCCCCCCCCCCD -AACAAAACAAAACCNMCCA -AACCCAAAAAACCCCCCCA -AACCCCCAAAACCCCCCCA -AACCCCCCCAAACCCCCCA -AACCCCCCCAAAACCCCCA -AACCCCCKKKKKKKKKCCA -AACCCCCJJJJJJJJJCCA -AACCCAAIIIIIIIIICCA -AACCAAAAACCCCCCCCCA -DDCCCCCCCCCCCCCCCDD -AAAAAAAAAAAAAAAAA-- -AAAAAAAAAAAAAAAAA-- -------------------- -------------------- -------------------- -------------------- -------------------- -------------------- -------------------- -------------------- -------------------- -------------------- -------------------- -------------------- -------------------- -------------------- -------------------- 
-EEEAAAAAAAAAAAAAAE- DBBCCCCCCCCCCCCCCCCD ABBCAAAACAAAACCCCCCA ABBCCCAAAAAACCCCCCCA ABBCCCCCAAAACCCCCCCA ABBCCCCCCCAAACCCCCCA ABBCCCCCCCAAAACCCCCA ABBCCCCCBBBBBBBBBCCA ABBCCCCCBBBBBBBBBCCA ABBCCCAABBBBBBBBBCCA ABBCCAAAAACCCCCCCCCA DBBCCCCCCCCCCCCCCCDD ABBCBBBBBBBBBAAAAA-- AAAAAAAAAAAAAAAAAA-- -----EEE------------ -----EEE------------ -----FFF------------ -----FFF------------ -----GGG------------ -----GGG------------ -----GGG------------ -----EEE------------ -----EEE------------ -------------------- -------------------- -------------------- -------------------- -------------------- -------------------- 
-EAAAAAAAAAAAAAAAAE- DBBCCCCCCCCCCCCCCCCD ABBCAAAACAAAACCCCCCA ABBCCCAAAAAACCCCCCCA ABBCCCCCAAAACCCCCCCA ABBCCCCCCCAAACCCCCCA ABBCCCCCCCAAAACCCCCA ABBCCCCCBBBBBBBBBCCA ABBCCCCCBBBBBBBBBCCA ABBCCCAABBBBBBBBBCCA ABBCCAAAAACCCCCCCCCA DBBCCCCCCCCCCCCCCCDD ABBCBBBBBBBBBAAAAA-- AAAAAAAAAAAAAAAAAA-- ----EBBBE----------- ----EBBBE----------- ----FFFFF----------- ----FFFFF----------- ----GBBBG----------- ----GBBBG----------- ----GBBBG----------- ----EBBBE----------- ----EEEEE----------- -------------------- -------------------- -------------------- -------------------- -------------------- -------------------- 
-EAAAAAAAAAAAAAAAAE- DBBCCCCCCCCCCCCCCCCD ABBCAAAACAAAACCCCCCA ABBCCCAAAAAACCCCCCCA ABBCCCCCAAAACCCCCCCA ABBCCCCCCCAAACCCCCCA ABBCCCCCCCAAAACCCCCA ABBCCCCCBBBBBBBBBCCA ABBCCCCCBBBBBBBBBCCA ABBCCCAABBBBBBBBBCCA ABBCCAAAAACCCCCCCCCA DBBCCCCCCCCCCCCCCCDD ABBCBCCCBBBBBAAAAA-- AAAAAAAAAAAAAAAAAA-- ---EBCLCBE---------- ---EBCOCBE---------- ---FFFFFFF---------- ---FFFFFFF---------- ---GBBBBBG---------- ---GBBBBBG---------- ---GBBBBBG---------- ---EBBBBBE---------- ---EEBBBEE---------- -----DDD------------ -----DDD------------ -----DDD------------ -----DDD------------ -----DDD------------ ------D------------- 
-EAAAAAAAAAAAAAAAAE- DBBCCCCCCCCCCCCCCCCD ABBCAAAACAAAACCCCCCA ABBCCCAAAAAACCCCCCCA ABBCCCCCAAAACCCCCCCA ABBCCCCCCCAAACCCCCCA ABBCCCCCCCAAAACCCCCA ABBCCCCCCBBBBBBBBCCA ABBCCCCCCBBBBBBBBCCA ABBCCCAACBBBBBBBBCCA ABBCCAAAAACCCCCCCCCA DBBCCCCCCCCCCCCCCCDD ABBCCCCCCBBBBAAAAA-- AAAAAAAAAAAAAAAAAA-- --EBCCCCCBE--------- --EBCCCCCBE--------- --FFFFFFFFF--------- --FFFFFFFFF--------- --GBCCCCCBG--------- --GBCCCCCBG--------- --GBLLLLLBG--------- --EBBBBBBBE--------- --EEBBBBBEE--------- ----DBBBD----------- ----DBBBD----------- ----DBBBD----------- ----DBBBD----------- ----DBBBD----------- -----DDD------------ 
-EAAAAAAAAAAAAAAAAE- DBBCCCCCCCCCCCCCCCCD ABBCAAAACAAAACCCCCCA ABBCCCAAAAAACCCCCCCA ABBCCCCCAAAACCCCCCCA ABBCCCCCCCAAACCCCCCA ABBCCCCCCCAAAACCCCCA ABBCCCCCCBBBBBBBBCCA ABBCCCCCCBBBBBBBBCCA ABBCCCAACBBBBBBBBCCA ABBCCAAAAACCAAAAAAAA DBBCCCCCCCCCCCCCCCDD ABBCCCCCCBBBBAAAAA-- AAAAAAAAAAAAAAAAAA-- --EBCCCCCBE--------- --EBCCCCCBE--------- --FFFCCCCFF--------- --FFFCCCFFF--------- --GBCCCCCBG--------- --GBCCCCCBG--------- --GBLCCLLBG--------- --EBBBBBBBE--------- --EEBBBBBEE--------- ----DBBBD----------- ----DBBBD----------- ----DBBBD----------- ----DBBBD----------- ----DBBBD----------- ----DDDDD----------- 
-EAAAAAAAAAAAAAAAAE- DBBCCCCCCCCCCCCCCCCD ABBCAAAACAAAACCCCCCA ABBCCCAAAAAACCCCCCCA ABBCCCCCAAAACCCCCCCA ABBCCCCCCCAAACCCCCCA ABBCCCCCCCAAAACCCCCA ABBCCCCCCBBBBBBBBCCA ABBCCCCCCBBBBBBBBCCA ABBCCCAACBBBBBBBBCCA ABBCCAAAAACCAAAAAAAA DBBCCCCCCCCCCCCCCCDD ABBCCCCCCBBBBAAAAA-- AAAAAAAAAAAAAAAAAA-- --EBCCCCCBE--------- --EBCCCCCBE--------- --FFFCCCCFF--------- --FFFCCCFFF--------- --GBCCCCCBG--------- --GBCCCCCBG--------- --GBLCCLLBG--------- --EBBBBBBBE--------- --EEBBBBBEE--------- ----DBBBD----------- ----DBBBD----------- ----DBBBD----------- ----DBBBD----------- ----DBBBD----------- -----DDD------------ 
-EAAAAAAAAAAAAAAAAE- DBBBBCCCBBBBBBBBBBBD ABBBAAAABAAAABBBBBBA ABBBBCAAAAAABBBBBBBA ABBBBCCCAAAABBBBBBBA ABBBBCCCBBAAABBBBBBA ABBBBCCCBBAAAABBBBBA ABBBBCCCBBBBBBBBBBBA ABBBBCCCBBBBBBBBBBBA ABBBBCAABBBBAAAAAAAA ABBBBAAAAABBAAAAAAAA DBBBBCCCBBBBBBBBBBDD ABBBBCCCBBBBBAAAAA-- AAAAAAAAAAAAAAAAAA-- ---EBCCCBE---------- ---EBCCCBE---------- ---FFFFFFF---------- ---FFCCCFF---------- ---GBCCCBG---------- ---GBCCCBG---------- ---GBLLLBG---------- ---EBBBBBE---------- ---EEBBBBE---------- -----DDD------------ -----DDD------------ -----DDD------------ -----DDD------------ -----DDD------------ ------D------------- 
-EAAAAAAAAAAAAAAAAE- DBBBBBBBBBBBBBBBBBBD AHHBAAAABAAAABBBBBBA AHHBBBAAAAAABBBBBBBA AHHBBBBBAAAABBBBBBBA AHHBBBBBBBAAABBBBBBA AHHBBBBBBBAAAABBBBBA AHHBBBBBBBBBBBBBBBBA AHHBBBBBBBBBBBBBBBBA AHHBBBAABBBBBBBBBBBA AHHBBAAAAABBBBBBBBBA DBBBBBBBBBBBBBBBBBDD ABBBBBBBBBBBBAAAAA-- AAAAAAAAAAAAAAAAAA-- ----EBBBE----------- ----EBBBE----------- ----FFFFF----------- ----FFFFF----------- ----GBBBG----------- ----GBBBG----------- ----GBBBG----------- ----EBBBE----------- ----EEEEE----------- -------------------- -------------------- -------------------- -------------------- -------------------- -------------------- 
-EEEAAAAAAAAAAAAAAE- DBBBBBBBBBBBBBBBBBBD AHHBAAAABAAAABBBBBBA AHHBBBAAAAAABBBBBBBA AHHBBBBBAAAABBBBBBBA AHHBBBBBBBAAABBBBBBA AHHBBBBBBBAAAABBBBBA AHHBBBBBBBBBBBBBBBBA AHHBBBBBBBBBBBBBBBBA AHHBBBAABBBBBBBBBBBA AHHBBAAAAABBBBBBBBBA DBBBBBBBBBBBBBBBBBDD AABAAAAAAAAAAAAAAA-- AAAAAAAAAAAAAAAAAA-- -----EEE------------ -----EEE------------ -----FFF------------ -----FFF------------ -----GGG------------ -----GGG------------ -----GGG------------ -----EEE------------ -----EEE------------ -------------------- -------------------- -------------------- -------------------- -------------------- -------------------- 
---EEEEEEEEEEEEEEEE- -DDCBBBBBBBBBBBBBBBD -AABAAAABAAAABBNMBBA -AABBBAAAAAABBBBBBBA -AABBBBBAAAABBBBBBBA -AABBBBBBBAAABBBBBBA -AABBBBBBBAAAABBBBBA -AABBBBBKKKKKKKKKBBA -AABBBBBJJJJJJJJJBBA -AABBBAAIIIIIIIIIBBA -AABBAAAAABBBBBBBBBA -DDBBBBBBBBBBBBBBBDD -AAAAAAAAAAAABBBBA-- -AAAAAAAAAAAAAAAAA-- -------------------- -------------------- -------------------- -------------------- -------------------- -------------------- -------------------- -------------------- -------------------- -------------------- -------------------- -------------------- -------------------- -------------------- -------------------- 
-------------------- ---DDDDDDDDDDDDDDDD- ---AAAAAAAAAAAA--AA- ---AAAAAAAAAAAAAAAA- ---AAAAAAAAAAAAAAAA- ---AAAAAAAAAAAAAAAA- ---AAAAAAAAAAAAAAAA- ---AAAAA---------AA- ---AAAAA---------AA- ---AAAAA---------AA- ---AAAAAAAAAAAAAAAA- ---DDDDDDDDDDDDDDDD- ---AAAAAAAAAAAAAAA-- ---AAAAAAA---------- -------------------- -------------------- -------------------- -------------------- -------------------- -------------------- -------------------- -------------------- -------------------- -------------------- -------------------- -------------------- -------------------- -------------------- -------------------- 
