model
size = 20 29 13, scale = 0.05, origin = -y
material 
  colors = A:#777 B:#222 C:#400 D:#AAA E:#555 F:#FFF G:#FFC H:#009 I:#00C J:#00F K:#444 L:#D00 M:#0E0 N:#500
voxels
-------------------- ---DDDDDDDDDDDDDDDD- ---CCCCCCCCCCCC--CC- ---CCCCCCCCCCCCCCCC- ---CCCCCCCCCCCCCCCC- ---CCCCCCCCCCCCCCCC- ---CCCCCCCCCCCCCCCC- ---CCCCC---------CC- ---CCCCC---------CC- ---CCCCC---------CC- ---CCCCCCCCCCCCCCCC- ---DDDDDDDDDDDDDDDD- ---CCCCCCCCCCCCCCC-- ---CCCCCCC---------- -------------------- -------------------- -------------------- -------------------- -------------------- -------------------- -------------------- -------------------- -------------------- -------------------- -------------------- -------------------- -------------------- -------------------- -------------------- 
---EEEEEEEEEEEEEEEE- -DDBBBBBBBBBBBBBBBBD -CCBBBBBBBBBBBBMLBBC -CCBBBBBBBBBBBBBBBBC -CCBBBBBBBBBBBBBBBBC -CCBBBBBBBBBBBBBBBBC -CCBBBBBBBBBBBBBBBBC -CCBBBBBJJJJJJJJJBBC -CCBBBBBIIIIIIIIIBBC -CCBBBBBHHHHHHHHHBBC -CCBBBBBBBBBBBBBBBBC -DDBBBBBBBBBBBBBBBDD -CCBAAAAAAAAAAAAAC-- -CCCCCCCCCCCCCCCCC-- -------------------- -------------------- -------------------- -------------------- -------------------- -------------------- -------------------- -------------------- -------------------- -------------------- -------------------- -------------------- -------------------- -------------------- -------------------- 
-EEECCCCCCCCCCCCCCE- DAABBBBBBBBBBBBBBBBD CAABBBBBBBBBBBBBBBBC CAABBBBBBBBBBBBBBBBC CAABBBBBBBBBBBBBBBBC CAABBBBBBBBBBBBBBBBC CAABBBBBBBBBBBBBBBBC CAABBBBBAAAAAAAAABBC CAABBBBBAAAAAAAAABBC CAABBBBBAAAAAAAAABBC CAABBBBBBBBBBBBBBBBC DAABBBBBBBBBBBBBBBDD CAABAAAAAAAAAAAAAC-- CCCCCBBBCCCCCCCCCC-- -----EEE------------ -----EEE------------ -----GGG------------ -----GGG------------ -----FFF------------ -----FFF------------ -----FFF------------ -----EEE------------ -----EEE------------ -------------------- -------------------- -------------------- -------------------- -------------------- -------------------- 
-ECCCCCCCCCCCCCCCCE- DAABBBBBBBBBBBBBBBBD CAABBBBBBBBBBBBBBBBC CAABBBBBBBBBBBBBBBBC CAABBBBBBBBBBBBBBBBC CAABBBBBBBBBBBBBBBBC CAABBBBBBBBBBBBBBBBC CAABBBBBAAAAAAAAABBC CAABBBBBAAAAAAAAABBC CAABBBBBAAAAAAAAABBC CAABBBBBBBBBBBBBBBBC DAABBBBBBBBBBBBBBBDD CAABAAAAAAAAAAAAAC-- CCCCBBBBBCCCCCCCCC-- ----EAAAE----------- ----EAAAE----------- ----GAAAG----------- ----GAAAG----------- ----FAAAF----------- ----FAAAF----------- ----FAAAF----------- ----EAAAE----------- ----EEEEE----------- -------------------- -------------------- -------------------- -------------------- -------------------- -------------------- 
-ECCCCCCCCCCCCCCCCE- DAABBBBBBBBBBBBBBBBD CAABBBBBBBBBBBBBBBBC CAABBBBBBBBBBBBBBBBC CAABBBBBBBBBBBBBBBBC CAABBBBBBBBBBBBBBBBC CAABBBBBBBBBBBBBBBBC CAABBBBBAAAAAAAAABBC CAABBBBBAAAAAAAAABBC CAABBBBBAAAAAAAAABBC CAABBBBBBBBBBBBBBBBC DAABBBBBBBBBBBBBBBDD CAABABBBAAAAAAAAAC-- CCCBBBBBBBCCCCCCCC-- ---EABKBAE---------- ---EABNBAE---------- ---GABBBAG---------- ---GAAAAAG---------- ---FAAAAAF---------- ---FAAAAAF---------- ---FAAAAAF---------- ---EAAAAAE---------- ---EEAAAEE---------- -----DDD------------ -----DDD------------ -----DDD------------ -----DDD------------ -----DDD------------ ------D------------- 
-ECCCCCCCCCCCCCCCCE- DAABBBBBBBBBBBBBBBBD CAABBBBBBBBBBBBBBBBC CAABBBBBBBBBBBBBBBBC CAABBBBBBBBBBBBBBBBC CAABBBBBBBBBBBBBBBBC CAABBBBBBBBBBBBBBBBC CAABBBBBBAAAAAAAABBC CAABBBBBBAAAAAAAABBC CAABBBBBBAAAAAAAABBC CAABBBBBBBBBBBBBBBBC DAABBBBBBBBBBBBBBBDD CAABBBBBBAAAAAAAAC-- CCABBBBBBBACCCCCCC-- --EABBBBBAE--------- --EABBBBBAE--------- --GABBBBBAG--------- --GABBBBBAG--------- --FABBBBBAF--------- --FABBBBBAF--------- --FAKKKKKAF--------- --EAAAAAAAE--------- --EEAAAAAEE--------- ----DAAAD----------- ----DAAAD----------- ----DAAAD----------- ----DAAAD----------- ----DAAAD----------- -----DDD------------ 
-ECCCCCCCCCCCCCCCCE- DAABBBBBBBBBBBBBBBBD CAABBBBBBBBBBBBBBBBC CAABBBBBBBBBBBBBBBBC CAABBBBBBBBBBBBBBBBC CAABBBBBBBBBBBBBBBBC CAABBBBBBBBBBBBBBBBC CAABBBBBBAAAAAAAABBC CAABBBBBBAAAAAAAABBC CAABBBBBBAAAAAAAABBC CAABBBBBBBBBBBBBBBBC DAABBBBBBBBBBBBBBBDD CAABBBBBBAAAAAAAAC-- CCABBBBBBBACCCCCCC-- --EABBBBBAE--------- --EABBBBBAE--------- --GABBBBBAG--------- --GABBBBBAG--------- --FABBBBBAF--------- --FABBBBBAF--------- --FAKBBKKAF--------- --EAAAAAAAE--------- --EEAAAAAEE--------- ----DAAAD----------- ----DAAAD----------- ----DAAAD----------- ----DAAAD----------- ----DAAAD----------- ----DDDDD----------- 
-ECCCCCCCCCCCCCCCCE- DAABBBBBBBBBBBBBBBBD CAABBBBBBBBBBBBBBBBC CAABBBBBBBBBBBBBBBBC CAABBBBBBBBBBBBBBBBC CAABBBBBBBBBBBBBBBBC CAABBBBBBBBBBBBBBBBC CAABBBBBBAAAAAAAABBC CAABBBBBBAAAAAAAABBC CAABBBBBBAAAAAAAABBC CAABBBBBBBBBBBBBBBBC DAABBBBBBBBBBBBBBBDD CAABBBBBBAAAAAAAAC-- CCABBBBBBBACCCCCCC-- --EABBBBBAE--------- --EABBBBBAE--------- --GABBBBBAG--------- --GABBBBBAG--------- --FABBBBBAF--------- --FABBBBBAF--------- --FAKBBKKAF--------- --EAAAAAAAE--------- --EEAAAAAEE--------- ----DAAAD----------- ----DAAAD----------- ----DAAAD----------- ----DAAAD----------- ----DAAAD----------- -----DDD------------ 
-ECCCCCCCCCCCCCCCCE- DAAAABBBAAAAAAAAAAAD CAAAABBBAAAAAAAAAAAC CAAAABBBAAAAAAAAAAAC CAAAABBBAAAAAAAAAAAC CAAAABBBAAAAAAAAAAAC CAAAABBBAAAAAAAAAAAC CAAAABBBAAAAAAAAAAAC CAAAABBBAAAAAAAAAAAC CAAAABBBAAAAAAAAAAAC CAAAABBBAAAAAAAAAAAC DAAAABBBAAAAAAAAAADD CAAAABBBAAAAAAAAAC-- CCCAABBBAACCCCCCCC-- ---EABBBAE---------- ---EABBBAE---------- ---GABBBAG---------- ---GABBBAG---------- ---FABBBAF---------- ---FABBBAF---------- ---FAKKKAF---------- ---EAAAAAE---------- ---EEAAAAE---------- -----DDD------------ -----DDD------------ -----DDD------------ -----DDD------------ -----DDD------------ ------D------------- 
-ECCCCCCCCCCCCCCCCE- DAAAAAAAAAAAAAAAAAAD CAAAAAAAAAAAAAAAAAAC CAAAAAAAAAAAAAAAAAAC CAAAAAAAAAAAAAAAAAAC CAAAAAAAAAAAAAAAAAAC CAAAAAAAAAAAAAAAAAAC CAAAAAAAAAAAAAAAAAAC CAAAAAAAAAAAAAAAAAAC CAAAAAAAAAAAAAAAAAAC CAAAAAAAAAAAAAAAAAAC DAAAAAAAAAAAAAAAAADD CAAAAAAAAAAAAAAAAC-- CCCCAAAAACCCCCCCCC-- ----EAAAE----------- ----EAAAE----------- ----GAAAG----------- ----GAAAG----------- ----FAAAF----------- ----FAAAF----------- ----FAAAF----------- ----EAAAE----------- ----EEEEE----------- -------------------- -------------------- -------------------- -------------------- -------------------- -------------------- 
-EEECCCCCCCCCCCCCCE- DAAAAAAAAAAAAAAAAAAD CAAAAAAAAAAAAAAAAAAC CAAAAAAAAAAAAAAAAAAC CAAAAAAAAAAAAAAAAAAC CAAAAAAAAAAAAAAAAAAC CAAAAAAAAAAAAAAAAAAC CAAAAAAAAAAAAAAAAAAC CAAAAAAAAAAAAAAAAAAC CAAAAAAAAAAAAAAAAAAC CAAAAAAAAAAAAAAAAAAC DAAAAAAAAAAAAAAAAADD CAAAAAAAAAAAAAAAAC-- CCCCCAAACCCCCCCCCC-- -----EEE------------ -----EEE------------ -----GGG------------ -----GGG------------ -----FFF------------ -----FFF------------ -----FFF------------ -----EEE------------ -----EEE------------ -------------------- -------------------- -------------------- -------------------- -------------------- -------------------- 
---EEEEEEEEEEEEEEEE- -DDBAAAAAAAAAAAAAAAD -CCAAAAAAAAAAAAMLAAC -CCAAAAAAAAAAAAAAAAC -CCAAAAAAAAAAAAAAAAC -CCAAAAAAAAAAAAAAAAC -CCAAAAAAAAAAAAAAAAC -CCAAAAAJJJJJJJJJAAC -CCAAAAAIIIIIIIIIAAC -CCAAAAAHHHHHHHHHAAC -CCAAAAAAAAAAAAAAAAC -DDAAAAAAAAAAAAAAADD -CCAAAAAAAAAAAAAAC-- -CCCCCCCCCCCCCCCCC-- -------------------- -------------------- -------------------- -------------------- -------------------- -------------------- -------------------- -------------------- -------------------- -------------------- -------------------- -------------------- -------------------- -------------------- -------------------- 
-------------------- ---DDDDDDDDDDDDDDDD- ---CCCCCCCCCCCC--CC- ---CCCCCCCCCCCCCCCC- ---CCCCCCCCCCCCCCCC- ---CCCCCCCCCCCCCCCC- ---CCCCCCCCCCCCCCCC- ---CCCCC---------CC- ---CCCCC---------CC- ---CCCCC---------CC- ---CCCCCCCCCCCCCCCC- ---DDDDDDDDDDDDDDDD- ---CCCCCCCCCCCCCCC-- ---CCCCCCC---------- -------------------- -------------------- -------------------- -------------------- -------------------- -------------------- -------------------- -------------------- -------------------- -------------------- -------------------- -------------------- -------------------- -------------------- -------------------- 
