model
size = 20 29 13, scale = 0.05, origin = -y
material 
  colors = A:#777 B:#222 C:#050 D:#AAA E:#555 F:#040 G:#020 H:#FFF I:#C33 J:#070 K:#009 L:#00C M:#00F N:#444 O:#D00 P:#0E0 Q:#500
voxels
-------------------- ---DDDDDDDDDDDDDDDD- ---GCCCCGCCCCFF--CG- ---GGFCCCCCCGFFCCCF- ---JGFFFCCCCFGGCCCF- ---CCGGFFFCCCGGCCCC- ---CCGGGGFCCCCGCJJC- ---CCCGG---------JC- ---CCCCG---------CC- ---GCCCC---------CG- ---GGCCCCCJGCCCCCCF- ---DDDDDDDDDDDDDDDD- ---FGFCCCCFFFCCCFG-- ---GGFFCCC---------- -------------------- -------------------- -------------------- -------------------- -------------------- -------------------- -------------------- -------------------- -------------------- -------------------- -------------------- -------------------- -------------------- -------------------- -------------------- 
---EEEEEEEEEEEEEEEE- -DDBBBBBBBBBBBBBBBBD -FGBBBBBBBBBBBBPOBBF -FCBBBBBBBBBBBBBBBBF -CCBBBBBBBBBBBBBBBBC -CCBBBBBBBBBBBBBBBBC -CCBBBBBBBBBBBBBBBBC -CCBBBBBMMMMMMMMMBBC -CCBBBBBLLLLLLLLLBBG -CCBBBBBKKKKKKKKKBBG -CGBBBBBBBBBBBBBBBBF -DDBBBBBBBBBBBBBBBDD -FCBAAAAAAAAAAAAAJ-- -FJCFFFCCCJFFCCCGG-- -------------------- -------------------- -------------------- -------------------- -------------------- -------------------- -------------------- -------------------- -------------------- -------------------- -------------------- -------------------- -------------------- -------------------- -------------------- 
-EEECCCCCCCCCCCCCCE- DAABBBBBBBBBBBBBBBBD FAABBBBBBBBBBBBBBBBF FAABBBBBBBBBBBBBBBBC JAABBBBBBBBBBBBBBBBG GAABBBBBBBBBBBBBBBBG FAABBBBBBBBBBBBBBBBJ GAABBBBBAAAAAAAAABBC CAABBBBBAAAAAAAAABBC CAABBBBBAAAAAAAAABBC CAABBBBBBBBBBBBBBBBC DAABBBBBBBBBBBBBBBDD CAABAAAAAAAAAAAAAF-- FFCCCBBBCGGFFCCCCC-- -----EEE------------ -----EEE------------ -----III------------ -----III------------ -----HHH------------ -----HHH------------ -----HHH------------ -----EEE------------ -----EEE------------ -------------------- -------------------- -------------------- -------------------- -------------------- -------------------- 
-ECCCCCCCCCCCCCCCCE- DAABBBBBBBBBBBBBBBBD FAABBBBBBBBBBBBBBBBC FAABBBBBBBBBBBBBBBBC GAABBBBBBBBBBBBBBBBG GAABBBBBBBBBBBBBBBBG GAABBBBBBBBBBBBBBBBG CAABBBBBAAAAAAAAABBF CAABBBBBAAAAAAAAABBC GAABBBBBAAAAAAAAABBC GAABBBBBBBBBBBBBBBBC DAABBBBBBBBBBBBBBBDD CAABAAAAAAAAAAAAAF-- CCCCBBBBBGGGGCCCJF-- ----EAAAE----------- ----EAAAE----------- ----IAAAI----------- ----IAAAI----------- ----HAAAH----------- ----HAAAH----------- ----HAAAH----------- ----EAAAE----------- ----EEEEE----------- -------------------- -------------------- -------------------- -------------------- -------------------- -------------------- 
-ECCCCCCCCCCCCCCCCE- DAABBBBBBBBBBBBBBBBD FAABBBBBBBBBBBBBBBBC CAABBBBBBBBBBBBBBBBG CAABBBBBBBBBBBBBBBBG GAABBBBBBBBBBBBBBBBF CAABBBBBBBBBBBBBBBBF CAABBBBBAAAAAAAAABBF GAABBBBBAAAAAAAAABBF GAABBBBBAAAAAAAAABBC JAABBBBBBBBBBBBBBBBC DAABBBBBBBBBBBBBBBDD CAABABBBAAAAAAAAAC-- CCCBBBBBBBGGCCCFFF-- ---EABNBAE---------- ---EABQBAE---------- ---IABBBAI---------- ---IAAAAAI---------- ---HAAAAAH---------- ---HAAAAAH---------- ---HAAAAAH---------- ---EAAAAAE---------- ---EEAAAEE---------- -----DDD------------ -----DDD------------ -----DDD------------ -----DDD------------ -----DDD------------ ------D------------- 
-ECCCCCCCCCCCCCCCCE- DAABBBBBBBBBBBBBBBBD GAABBBBBBBBBBBBBBBBF CAABBBBBBBBBBBBBBBBC CAABBBBBBBBBBBBBBBBC CAABBBBBBBBBBBBBBBBC CAABBBBBBBBBBBBBBBBC CAABBBBBBAAAAAAAABBF CAABBBBBBAAAAAAAABBF FAABBBBBBAAAAAAAABBC GAABBBBBBBBBBBBBBBBC DAABBBBBBBBBBBBBBBDD FAABBBBBBAAAAAAAAC-- GGABBBBBBBACCFFGGF-- --EABBBBBAE--------- --EABBBBBAE--------- --IABBBBBAI--------- --IABBBBBAI--------- --HABBBBBAH--------- --HABBBBBAH--------- --HANNNNNAH--------- --EAAAAAAAE--------- --EEAAAAAEE--------- ----DAAAD----------- ----DAAAD----------- ----DAAAD----------- ----DAAAD----------- ----DAAAD----------- -----DDD------------ 
-ECCCCCCCCCCCCCCCCE- DAABBBBBBBBBBBBBBBBD CAABBBBBBBBBBBBBBBBF CAABBBBBBBBBBBBBBBBF FAABBBBBBBBBBBBBBBBC FAABBBBBBBBBBBBBBBBC FAABBBBBBBBBBBBBBBBC CAABBBBBBAAAAAAAABBC CAABBBBBBAAAAAAAABBC CAABBBBBBAAAAAAAABBC FAABBBBBBBBBBBBBBBBJ DAABBBBBBBBBBBBBBBDD FAABBBBBBAAAAAAAAJ-- GGABBBBBBBAFCCCGGG-- --EABBBBBAE--------- --EABBBBBAE--------- --IABBBBBAI--------- --IABBBBBAI--------- --HABBBBBAH--------- --HABBBBBAH--------- --HANBBNNAH--------- --EAAAAAAAE--------- --EEAAAAAEE--------- ----DAAAD----------- ----DAAAD----------- ----DAAAD----------- ----DAAAD----------- ----DAAAD----------- ----DDDDD----------- 
-ECCCCCCCCCCCCCCCCE- DAABBBBBBBBBBBBBBBBD CAABBBBBBBBBBBBBBBBG CAABBBBBBBBBBBBBBBBF GAABBBBBBBBBBBBBBBBC FAABBBBBBBBBBBBBBBBC CAABBBBBBBBBBBBBBBBC CAABBBBBBAAAAAAAABBC CAABBBBBBAAAAAAAABBC CAABBBBBBAAAAAAAABBG CAABBBBBBBBBBBBBBBBJ DAABBBBBBBBBBBBBBBDD FAABBBBBBAAAAAAAAG-- GJABBBBBBBAJFCCCCG-- --EABBBBBAE--------- --EABBBBBAE--------- --IABBBBBAI--------- --IABBBBBAI--------- --HABBBBBAH--------- --HABBBBBAH--------- --HANBBNNAH--------- --EAAAAAAAE--------- --EEAAAAAEE--------- ----DAAAD----------- ----DAAAD----------- ----DAAAD----------- ----DAAAD----------- ----DAAAD----------- -----DDD------------ 
-ECCCCCCCCCCCCCCCCE- DAAAABBBAAAAAAAAAAAD CAAAABBBAAAAAAAAAAAG CAAAABBBAAAAAAAAAAAG CAAAABBBAAAAAAAAAAAF CAAAABBBAAAAAAAAAAAC CAAAABBBAAAAAAAAAAAC CAAAABBBAAAAAAAAAAAC CAAAABBBAAAAAAAAAAAC CAAAABBBAAAAAAAAAAAJ CAAAABBBAAAAAAAAAAAJ DAAAABBBAAAAAAAAAADD CAAAABBBAAAAAAAAAC-- CCCAABBBAAFJJCCCCG-- ---EABBBAE---------- ---EABBBAE---------- ---IABBBAI---------- ---IABBBAI---------- ---HABBBAH---------- ---HABBBAH---------- ---HANNNAH---------- ---EAAAAAE---------- ---EEAAAAE---------- -----DDD------------ -----DDD------------ -----DDD------------ -----DDD------------ -----DDD------------ ------D------------- 
-ECCCCCCCCCCCCCCCCE- DAAAAAAAAAAAAAAAAAAD FCCAAAAAAAAAAAAAAAAG CCCAAAAAAAAAAAAAAAAC CCCAAAAAAAAAAAAAAAAC GCCAAAAAAAAAAAAAAAAC GCCAAAAAAAAAAAAAAAAC CCCAAAAAAAAAAAAAAAAC CCCAAAAAAAAAAAAAAAAF CCCAAAAAAAAAAAAAAAAF CCCAAAAAAAAAAAAAAAAC DAAAAAAAAAAAAAAAAADD CAAAAAAAAAAAAAAAAC-- JCCCAAAAAJFJJFFCCC-- ----EAAAE----------- ----EAAAE----------- ----IAAAI----------- ----IAAAI----------- ----HAAAH----------- ----HAAAH----------- ----HAAAH----------- ----EAAAE----------- ----EEEEE----------- -------------------- -------------------- -------------------- -------------------- -------------------- -------------------- 
-EEECCCCCCCCCCCCCCE- DAAAAAAAAAAAAAAAAAAD FCCAAAAAAAAAAAAAAAAC FCCAAAAAAAAAAAAAAAAC JCCAAAAAAAAAAAAAAAAC GCCAAAAAAAAAAAAAAAAC GCCAAAAAAAAAAAAAAAAG GCCAAAAAAAAAAAAAAAAF CCCAAAAAAAAAAAAAAAAF CCCAAAAAAAAAAAAAAAAC FCCAAAAAAAAAAAAAAAAC DAAAAAAAAAAAAAAAAADD FAAAAAAAAAAAAAAAAF-- FFGCCAAACCCCFFGGFF-- -----EEE------------ -----EEE------------ -----III------------ -----III------------ -----HHH------------ -----HHH------------ -----HHH------------ -----EEE------------ -----EEE------------ -------------------- -------------------- -------------------- -------------------- -------------------- -------------------- 
---EEEEEEEEEEEEEEEE- -DDBAAAAAAAAAAAAAAAD -FGAAAAAAAAAAAAPOAAC -CCAAAAAAAAAAAAAAAAC -CCAAAAAAAAAAAAAAAAJ -CFAAAAAAAAAAAAAAAAG -GFAAAAAAAAAAAAAAAAG -CFAAAAAMMMMMMMMMAAG -CFAAAAALLLLLLLLLAAF -CCAAAAAKKKKKKKKKAAC -CCAAAAAAAAAAAAAAAAC -DDAAAAAAAAAAAAAAADD -FJAAAAAAAAAAAAAAF-- -FGGCCCCCCCCGGGJFF-- -------------------- -------------------- -------------------- -------------------- -------------------- -------------------- -------------------- -------------------- -------------------- -------------------- -------------------- -------------------- -------------------- -------------------- -------------------- 
-------------------- ---DDDDDDDDDDDDDDDD- ---GCCCCFFFFCGC--CC- ---GCCGGCFFGCGGCCCG- ---CCCGCCFGGCJGCCCG- ---FFFFCCFGGCCFFCGG- ---FGJCCCGFCCFFFFCG- ---CGGCC---------CC- ---CGGGC---------CC- ---CGGFF---------CC- ---CGFFFFFCCCCGCCCC- ---DDDDDDDDDDDDDDDD- ---GGCCFFCCCCGGCCF-- ---GCCCCFF---------- -------------------- -------------------- -------------------- -------------------- -------------------- -------------------- -------------------- -------------------- -------------------- -------------------- -------------------- -------------------- -------------------- -------------------- -------------------- 
