model
size = 16 21 13, scale = 0.05, origin = -y
material 
  colors = A:#DDD B:#960 C:#CC6
voxels
---------------- ---------------- ---------------- ---------------- ---------------- ---------------- ---------------- ---------------- ---------------- ----CCCCC------- ---CC---CC------ --CC-----CC----- -CC-------CC---- -C---------C---- -C---------C---- -C---------C---- -CC-------CC---- --CC-----CC----- ---CC---CC------ ----CCCCC------- ---------------- 
---------------- ---------------- ---------------- ---------------- ---------------- ---------------- ---------------- ---------------- ----BBBBB------- --BBAAAAABB----- -BBAAAAAAABB---- -BAAAAAAAAAB--B- BAAAAAAAAAAAB-B- BAAAAAAAAAAABCBC BAAAAAAAAAAAB--C BAAAAAAAAAAABCCC BAAAAAAAAAAAB--- -BAAAAAAAAAB---- -BBAAAAAAABB---- --BBAAAAABB----- ----BBBBB------- 
---------------- ---------------- ---------------- ---------------- ---------------- ---------------- ---------------- ---------------- --------------B- --------------B- --------------B- --------------B- ---------------- ---------------- ---------------- ---------------- ---------------- ---------------- ---------------- ---------------- ---------------- 
---------------- ---------------- ---------------- ---------------- ---------------- ---------------- --------------B- --------------B- --------------B- ---------------- ---------------- ---------------- ---------------- ---------------- ---------------- ---------------- ---------------- ---------------- ---------------- ---------------- ---------------- 
---------------- ---------------- --------------B- --------------B- --------------B- --------------B- --------------B- ---------------- ---------------- ---------------- ---------------- ---------------- ---------------- ---------------- ---------------- ---------------- ---------------- ---------------- ---------------- ---------------- ---------------- 
---------------- --------------B- --------------B- ---------------- ---------------- ---------------- ---------------- ---------------- ---------------- ---------------- ---------------- ---------------- ---------------- ---------------- ---------------- ---------------- ---------------- ---------------- ---------------- ---------------- ---------------- 
--------------B- --------------B- ---------------- ---------------- ---------------- ---------------- ---------------- ---------------- ---------------- ---------------- ---------------- ---------------- ---------------- ---------------- ---------------- ---------------- ---------------- ---------------- ---------------- ---------------- ---------------- 
--------------B- ---------------- ---------------- ---------------- ---------------- ---------------- ---------------- ---------------- ---------------- ---------------- ---------------- ---------------- ---------------- ---------------- ---------------- ---------------- ---------------- ---------------- ---------------- ---------------- ---------------- 
--------------B- ---------------- ---------------- ---------------- ---------------- ---------------- ---------------- ---------------- ---------------- ---------------- ---------------- ---------------- ---------------- ---------------- ---------------- ---------------- ---------------- ---------------- ---------------- ---------------- ---------------- 
--------------B- --------------B- ---------------- ---------------- ---------------- ---------------- ---------------- ---------------- ---------------- ---------------- ---------------- ---------------- ---------------- ---------------- ---------------- ---------------- ---------------- ---------------- ---------------- ---------------- ---------------- 
---------------- --------------B- --------------B- ---------------- ---------------- ---------------- ---------------- ---------------- ---------------- ---------------- ---------------- ---------------- ---------------- ---------------- ---------------- ---------------- ---------------- ---------------- ---------------- ---------------- ---------------- 
---------------- ---------------- --------------B- --------------B- --------------B- --------------B- --------------B- ---------------- ---------------- ---------------- ---------------- ---------------- ---------------- ---------------- ---------------- ---------------- ---------------- ---------------- ---------------- ---------------- ---------------- 
---------------- ---------------- ---------------- ---------------- ---------------- ---------------- --------------B- ---------------- ---------------- ---------------- ---------------- ---------------- ---------------- ---------------- ---------------- ---------------- ---------------- ---------------- ---------------- ---------------- ---------------- 
