model
size = 31 30 31, scale = 0.05, origin = -y
material 
  colors = A:#FFF B:#FBFBFB C:#070707 D:#A0A0A0 E:#0A3D0B F:#181818 G:#1C1C1C H:#005AF8 I:#090909 J:#0A0A0A K:#535353 L:#030303 M:#606060
voxels
----------CCG-G-G-GCC---------- ----------AAG-G-G-GAA---------- ------------G-G-G-G------------ --------JJ--G-G-G-G--JJ-------- --------JJ--G-G-G-G--JJ-------- --------------G-G-------------- --------------G-G-------------- --------------G-G-------------- --------------G-G-------------- ------------------------------- ------------------------------- ------------------------------- ------------------------------- ------------------------------- ------------------------------- ------------------------------- ------------------------------- ------------------------------- ------------------------------- ------------------------------- ------------------------------- ------------------------------- ------------------------------- ------------------------------- ------------------------------- ------------------------------- ------------------------------- ------------------------------- ------------------------------- ------------------------------- 
----------CCCICICICCC---------- ------AAAABBCICICICBBAAAA------ ------A----ACICICICA----A------ ------A-CC-ACICICICA-CC-A------ ------A-CC-AIICICIIA-CC-A------ ------A----A-ICICI-A----A------ ------AAAAAA-ICICI-AAAAAA------ --------------CIC-------------- --------------GIG-------------- ------------------------------- ------------------------------- ------------------------------- ------------------------------- ------------------------------- ------------------------------- ------------------------------- ------------------------------- ------------------------------- ------------------------------- ------------------------------- ------------------------------- ------------------------------- ------------------------------- ------------------------------- ------------------------------- ------------------------------- ------------------------------- ------------------------------- ------------------------------- ------------------------------- 
------CCCCCCCCCCCCCCCCCCC------ -----ABBBBBBBBCCCBBBBBBBBA----- -----AB----BBBCCCBBB----BA----- -----AB-CC-BBBCCCBBB-CC-BA----- -----AB-CC-BBBCCCBBB-CC-BA----- -----AB----BABCCCBAB----BA----- -----AB----BABCCCBAB----BA----- -----AAAAAAAAACCCAAAAAAAAA----- -------------AGGGA------------- ------------------------------- ------------------------------- ------------------------------- ------------------------------- ------------------------------- ------------------------------- ------------------------------- ------------------------------- ------------------------------- ------------------------------- ------------------------------- ------------------------------- ------------------------------- ------------------------------- ------------------------------- ------------------------------- ------------------------------- ------------------------------- ------------------------------- ------------------------------- ------------------------------- 
------C-----------------CC----- -----BBAAAAA--------AAAABB----- ----ABBAAAAA--------AAAABBA---- ----ABBAAAAA--------AAAABBA---- ----ABBAAAAA--------AAAABBA---- ----ABBAAAAA--------ABAABBA---- ----ABBAAAAA--------ABAABBA---- -----BBBBBBB--------BBBBBB----- -----------AABBBBBAA----------- ------------AAAAAAA------------ ------------------------------- ------------------------------- ------------------------------- ------------------------------- ------------------------------- ------------------------------- ------------------------------- ------------------------------- ------------------------------- ------------------------------- ------------------------------- ------------------------------- ------------------------------- ------------------------------- ------------------------------- ------------------------------- ------------------------------- ------------------------------- ------------------------------- ------------------------------- 
------C------------------C----- -----BB------------------B----- ----ABB------------------BA---- ----ABB------------------BA---- ----ABB------------------BA---- ----ABB------------------BA---- ----ABB------------------BA---- -----BB------------------B----- -----AAAAAAAA------AAAAAAA----- ------AAAAAABBBBBBBAAAAAA------ --------A-ACACACACACA-A-------- ----------ACACACACACA---------- ------------ACACACA------------ --------------ACA-------------- ------------------------------- ------------------------------- ------------------------------- ------------------------------- ------------------------------- ------------------------------- ------------------------------- ------------------------------- ------------------------------- ------------------------------- ------------------------------- ------------------------------- ------------------------------- ------------------------------- ------------------------------- ------------------------------- 
------CC----------------CC----- -----BBB----------------BB----- ----ABBB----------------BBA---- ----ABBB----------------BBA---- ----ABBB----------------BBA---- ----ABBB----------------BBA---- ----ABBB----------------BBA---- -----BBB----------------BB----- -----BBBB---------------BB----- ------BCAAABBBBBBBBBAAACB------ -------AACABBBBBBBBBACAA------- ---------AACACACACACAA--------- -----------BBBBBBBBB----------- ------------AAAAAAA------------ --------------AAA-------------- ------------------------------- ------------------------------- ------------------------------- ------------------------------- ------------------------------- ------------------------------- ------------------------------- ------------------------------- ------------------------------- ------------------------------- ------------------------------- ------------------------------- ------------------------------- ------------------------------- ------------------------------- 
-------C----------------C------ ------BB----------------B------ ------BB----------------BA----- ------BB----------------BA----- ------BB----------------BA----- ------BB----------------BA----- ------BB----------------BA----- ------BB----------------BA----- ------BBB---------------BA----- ------BBBB-------------BBA----- ------BBBB-------------BBA----- ------BBBB------------ABB------ -------BBBBBBBBBBBBBBBB-------- --------AAAAAAAAAAAAAAA-------- -------------AAAAA------------- --------------AAA-------------- ------------------------------- ------------------------------- ------------------------------- ------------------------------- ------------------------------- ------------------------------- ------------------------------- ------------------------------- ------------------------------- ------------------------------- ------------------------------- ------------------------------- ------------------------------- ------------------------------- 
-------C----------------C------ ------BB----------------B------ -----ABB----------------BAA---- -----ABB----------------BAA---- -----ABB----------------BAA---- -----ABB----------------BAA---- -----ABB----------------BAA---- ------BB----------------BA----- ------BBB---------------BA----- -----ABBBB-------------BBA----- -----ABBBB-------------BBA----- -----ABBBB-------------BBA----- -----ABBBB-------------BBA----- ------AAAAAAAAAAAAAAAAAAA------ -------AAAAAAAAAAAAAAAAA------- -------------AAAAA------------- -------------AAAAA------------- ------------------------------- ------------------------------- ------------------------------- ------------------------------- ------------------------------- ------------------------------- ------------------------------- ------------------------------- ------------------------------- ------------------------------- ------------------------------- ------------------------------- ------------------------------- 
------CC----------------CC----- -----BBB----------------BBA---- ----ABBB----------------BBA---- ----ABBB----------------BBA---- ----ABBB----------------BBA---- ----ABBB----------------BBA---- ----ABBB----------------BBA---- ----ABBB----------------BBA---- ----ABBBB---------------BBA---- ---AABBBBB-------------BBBAA--- ---AABBBBB-------------BBBAA--- ---AABBBBB-------------BBBAA--- ----ABBBBB-------------BBBA---- ----AAAAAA--------------AAA---- -----AAAAA--------------AA----- ------AAAAAAAAAAAAAAAAAAA------ ------------AAAAAAA------------ ------------AAAAAAA------------ ------------------------------- ------------------------------- ------------------------------- ------------------------------- ------------------------------- ------------------------------- ------------------------------- ------------------------------- ------------------------------- ------------------------------- ------------------------------- ------------------------------- 
------C------------------C----- -----BB------------------BA---- ---AABB------------------BAA--- ---AABB------------------BAA--- ---AABB------------------BAA--- ----ABB------------------BAA--- -----BB------------------BA---- -----BB------------------BA---- -----BBBB----------------BA---- ----ABBBBB-------------BBBA---- ----ABBBBB-------------BBBA---- ---AABBBBB-------------BBBAA--- ---AABBBBB-------------BBBAA--- ---AAAAAAA--------------AAAA--- ----AAAAAA--------------AA----- -----DAAAA------------AAAD----- -----DAAAAAAAAAAAAAAAAAAAD----- -----DAAAAAAAAAAAAAAAAAAAD----- -----A-----AAAAAAAAA-----A----- -------------AAAAA------------- ------------------------------- ------------------------------- ------------------------------- ------------------------------- ------------------------------- ------------------------------- ------------------------------- ------------------------------- ------------------------------- ------------------------------- 
-----CC-------------------C---- ----BBB-------------------B---- --AABBB-------------------BA--- --AABBB-------------------BAA-- --AABBB-------------------BAA-- ---ABBB-------------------BAA-- ----BBB-------------------BA--- ----BBB-------------------BA--- ----BBB-------------------B---- ----BBB-----------------BBB---- ----BBB-----------------BBB---- ----BBB-----------------BBB---- ----BBB-----------------BBB---- ----AAA-----------------AAAA--- ---AAAA-----------------AAAA--- ----DAA-----------------AAD---- ----DAA-----------------AAD---- ----DAAAAA-------------AAAD---- ----AA--AAAAAAAAAAAAAAA--AA---- ----A-----AAAAAAAAAAA-----A---- ----A--------AAAAA--------A---- ----A---------AAA---------A---- ----AA---------A---------AA---- -----AAAAAAAAAAAAAAAAAAAAA----- ------------------------------- ------------------------------- ------------------------------- ------------------------------- ------------------------------- ------------------------------- 
-----C--------------------C---- ---CC---------------------BC--- --AB----------------------BBA-- -AAB----------------------BBAA- -AAB----------------------BBAA- --AB----------------------BBAA- ---A----------------------BBA-- ---A----------------------BBA-- ----B---------------------BB--- ----B--------------------BB---- ----B--------------------BB---- ----B--------------------BB---- ----B--------------------BB---- ----AAA------------------AA---- ----AAA------------------AA---- ---AAAA------------------AAA--- ---AAAA------------------AD---- ---DAAA------------------AD---- ---DAAEE---------------EEAD---- ---DAEEEEE-----------EEEEEA---- ---AAEEEEEEEE-----EEEEEEEEA---- ----AEEEEEEEEE---EEEEEEEEEA---- ----AAEEEEEEEEE-EEEEEEEEEAA---- ----AAAAAAAAAAAAAAAAAAAAAAA---- ----FFFFFFFFFFFFFFFFFFFFFFF---- ------------------------------- ------------------------------- ------------------------------- ------------------------------- ------------------------------- 
------------------------------- ---C-----------------------C--- --AB-----------------------BAA- AAAB-----------------------BAAA AAAB-----------------------BAAA HHAB-----------------------BAAH --HB-----------------------BAH- ---B-----------------------BA-- ----B----------------------A--- ----B--------------------BB---- ----B--------------------BB---- ----B--------------------BB---- ----B--------------------BB---- ----AAA------------------AA---- ----AAA------------------AA---- ----AAA------------------AA---- ---AAAA------------------AAA--- ---DAA-------------------AMD--- ---DAA------------------AAMD--- ---DAA-----------------LLAMD--- ---AAA-----------------LLAA---- ---AAA-----------------LLAA---- ----AA-CC--------------LLAA---- ----AA-----------------AAAA---- --FFAA-----------------AAAFF--- ----AAAAAAAAAAAAAAAAAAAAAA----- ------------------------------- ------------------------------- ------------------------------- ------------------------------- 
------------------------------- ---C-----------------------C--- -AAB-----------------------BAA- AAAB-----------------------BAAA AAAB-----------------------BAAA AHAB-----------------------BAAA -AAB-----------------------BAA- ---A-----------------------BA-- ----B----------------------A--- ----B---------------------B---- ----B---------------------B---- ----B---------------------B---- ----B---------------------B---- ----A--------------------AA---- ----A---------------------A---- ----A---------------------A---- ----A--------------------AA---- ---AA--------------------AAA--- ---AA-------------------AAAA--- ---AAA-----------------AAAAA--- ---AAA-----------------AAAAA--- ---AAAAAA--------------AAAA---- ---AAAAAA--------------AAAA---- ---AAAAAA--------------AAAA---- --FFAAAAA--------------AAAFF--- ----AAAAA--------------AAA----- ----AAAAAAAAAAAAAAAAAAAAA------ ------------------------------- ------------------------------- ------------------------------- 
------------------------------- ---C-----------------------C--- -AAB-----------------------BAA- AAAB-----------------------BAAA AAAB-----------------------BAAA HAAB-----------------------BAAH -HAB-----------------------BAH- --HB-----------------------BH-- ---BB----------------------A--- ----B---------------------B---- ----B---------------------B---- ----B---------------------B---- ----B---------------------B---- ----A---------------------A---- ----A---------------------A---- ----A---------------------A---- ----A---------------------A---- ----A--------------------AA---- ---AA--------------------AAA--- --AAA-------------------AAAA--- --AAA-------------------AAAA--- ---AA-------------------AAAA--- ---AA------------------AAAA---- ---AA------------------AAAA---- --FCA------------------AAACF--- ---AAAAAA--------------AAAA---- ----AAAAA--------------AAA----- -----AAAAAAAAAAAAAAAAAAA------- ------------------------------- ------------------------------- 
------------------------------- --CC-----------------------C--- -ABB-----------------------BBA- AABB-----------------------BBAA AABB-----------------------BBAA AABB-----------------------BBAA -ABB-----------------------BBA- --AB-----------------------BB-- ---AB----------------------BA-- ---AB---------------------BB--- ----B---------------------B---- ----B---------------------B---- ----B---------------------B---- ----A---------------------A---- ----A---------------------A---- ----A---------------------A---- ----A---------------------A---- ---AA---------------------A---- --AAA--------------------AAA--- --AAA--------------------AAAA-- --AAA--------------------AAAA-- --AAA-------------------AAAA--- ---AA-------------------AAAA--- ---AA-------------------AAA---- --FAA-------------------AACF--- ---DAA------------------AAD---- ----DAA----------------AAD----- -----AAA---------------AA------ ------AAAAAAAAAAAAAAAAA-------- ---------AAAAAAAAAAAA---------- 
------------------------------- --C------------------------BC-- -AB------------------------BBA- AAB------------------------BBAA AAB------------------------BBAA HAB------------------------BBAH -HB------------------------BBH- --H------------------------BH-- ---HB----------------------BH-- ---AB---------------------BA--- ----B---------------------B---- ----B---------------------B---- ----B---------------------B---- ----A---------------------A---- ----A---------------------A---- ----A---------------------A---- ----A---------------------A---- ---AA---------------------AA--- -AAAA---------------------AAA-- -AAAA---------------------AAAA- -AAAA--------------------AAAAA- -AAAA--------------------AAAA-- --AAA--------------------AAA--- ---AA--------------------AAA--- --FAA--------------------ACF--- ---DA--------------------AD---- ----DA------------------AD----- -----A-----------------AA------ ------AA--------------AA------- --------AAAAAAAAAAAAAA--------- 
------------------------------- --C-------------------------C-- -AB-------------------------BA- AAB-------------------------BAA AAB-------------------------BAA AAB-------------------------BAA -AB-------------------------BA- --A-------------------------B-- ---A------------------------A-- ---AB---------------------BB--- ----B---------------------B---- ----B---------------------B---- ----B---------------------B---- ----A---------------------A---- ----A---------------------A---- ---AA---------------------A---- ---AA---------------------AA--- --AAA---------------------AAA-- -AAAA---------------------AAAA- DAAAA---------------------AAAKD DAAAA---------------------AAAKD -AAAA----------------------AAA- -AAAA--------------------AAAA-- --AAA--------------------AAA--- --AAA--------------------AAA--- ---AA--------------------AA---- ----DA------------------AD----- -----A-----------------AA------ ------AA--------------AA------- -------AAAAAAAAAAAAAAA--------- 
------------------------------- --C-------------------------C-- -AB-------------------------BA- AAB-------------------------BAA AAB-------------------------BAA HAB-------------------------BAH -HB-------------------------BH- --H-------------------------H-- --HBB-----------------------H-- --AAB----------------------A--- --AAB---------------------BB--- --AAB---------------------BB--- --AAB---------------------BB--- --AAA---------------------AA--- --AAA---------------------AAA-- --AAA---------------------AAA-- --AAA---------------------AAA-- -AAAA---------------------AAAA- -AAAA---------------------AAAA- DAAAA---------------------AAAKD DAAAA---------------------AAAKD -AAAA---------------------AAAA- -AAAA--------------------AAAAA- -AAAA--------------------AAAA-- --AAA--------------------AAA--- ---AA--------------------AA---- ----AA------------------AA----- -----A-----------------AA------ ------AA--------------AA------- -------AAAAAAAAAAAAAAA--------- 
---C------------------------C-- --CB------------------------BA- -ABB------------------------BA- AABB------------------------BAA AABB------------------------BAA AABB------------------------BAA AABB------------------------BAA -ABB------------------------BA- -AABB-----------------------BA- -ABBB----------------------BBA- -ABBB----------------------BBA- -ABBB---------------------BBBA- -ABBB---------------------BBBA- -AAAA---------------------AAAA- -AAAA---------------------AAAA- -AAAA---------------------AAAA- -AAAA---------------------AAAA- -AAAA---------------------AAAA- -AAAA---------------------AAAA- DAAAA---------------------AAAKD DAAAA---------------------AAAKD -AAAA--------------------AAAAA- -AAAA--------------------AAAAA- -AAAA--------------------AAAA-- --AAA--------------------AAA--- ---AA-------------------AAA---- ----AA------------------AA----- -----A-----------------AA------ ------AA--------------AA------- -------AAAAAAAAAAAAAAA--------- 
---C------------------------C-- --AB------------------------BA- -ABB------------------------BA- AABB------------------------BAA AABB------------------------BAA AABB------------------------BAA AABB------------------------BAA AABB------------------------BAA --ABB-----------------------BA- --ABB----------------------BB-- --ABB----------------------BB-- --ABB---------------------BBB-- --ABB---------------------BBB-- --AAA---------------------AAA-- --AAA---------------------AAA-- --AAA---------------------AAA-- --AAA---------------------AAA-- -AAAA---------------------AAAA- -AAAA---------------------AAAA- DAAAA---------------------AAAKD DAAAA---------------------AAAKD -AAAA--------------------AAAAA- -AAAA--------------------AAAA-- --AAA--------------------AAA--- --AAA-------------------AAAA--- ---AA-------------------AAA---- ----AA------------------AA----- -----A-----------------AA------ ------AA--------------AA------- -------AAAAAAAAAAAAAAA--------- 
---CC-----------------------C-- --ABB-----------------------B-- -ABBB-----------------------BA- AABBB-----------------------BA- AABBB-----------------------BAA AABBB-----------------------BAA AABBB-----------------------BAA --BBB-----------------------BA- --ABBB----------------------B-- --ABBB---------------------BB-- --ABBB---------------------BB-- --ABBB--------------------BBB-- --ABBB--------------------BBB-- --AAAA--------------------AAA-- --AAAA--------------------AAA-- --AAAA--------------------AAA-- --AAAA--------------------AAA-- --AAAA--------------------AAA-- -AAAAA--------------------AAA-- -AAAAA--------------------AAAA- -AAAA---------------------AAAA- -AAAAA--------------------AAA-- --AAAA-------------------AAA--- --AAAA-------------------AAA--- ---AAA------------------AAA---- ---AAA------------------AAA---- ----AA------------------AA----- -----A-----------------AA------ ------AA--------------AA------- -------AAAAAAAAAAAAAAA--------- 
----C----------------------C--- --ABB----------------------BA-- --ABB----------------------BAA- -AABB----------------------BAA- AAABB----------------------BAA- AAABB----------------------BAA- -AABB----------------------BAA- --ABB----------------------BA-- ---ABBB--------------------A--- ---ABBB--------------------A--- ---ABBB--------------------A--- ---ABBB-------------------BA--- ---ABBB-------------------BA--- ---AAAA-------------------AA--- ---AAAA-------------------AA--- ---AAAA-------------------AA--- ---AAAA-------------------AA--- ---AAAA-------------------A---- ---AAAA-------------------A---- ---AAAA-------------------A---- ----AAA-------------------A---- ----AAA-------------------A---- ----AAA------------------AA---- ----AAA-----------------AAA---- ----AAA-----------------AAA---- ----AAA-----------------AAA---- ----AAA-----------------AA----- -----AA----------------AA------ ------AAAAAAAAAAAAAAAAAA------- ---------AAAAAAAAAAAA---------- 
----CC-------------------CC---- ---ABB-------------------BBA--- --AABB-------------------BBAA-- --AABB-------------------BBAA-- --AABB-------------------BBAA-- --AABB-------------------BBAA-- --AABB-------------------BBAA-- ---ABB-------------------BBA--- ----ABBB-----------------BA---- ----ABBB----------------BBA---- ----ABBB----------------BBA---- ----ABBB----------------BBA---- ----ABBB----------------BBA---- ----AAAA----------------AAA---- ----AAAA-----------------AA---- ----AAAA----------------AAA---- ----AAAA----------------AA----- ----AAAA----------------AA----- ----AAAA----------------AA----- ----AAAA----------------AA----- ----AAAA----------------AA----- ----AAAA----------------AA----- -----AAA----------------AA----- -----AAA----------------AA----- -----AAA----------------AA----- -----AAA----------------AA----- -----AAA----------------AA----- -----AAAAAAAAAAAAAAAAAAAA------ -------AAAAAAAAAAAAAAAA-------- ------------------------------- 
-----CC-----------------CC----- ----ABB-----------------BBA---- ---AABB-----------------BBAA--- ---AABB-----------------BBAA--- ---AABB-----------------BBAA--- ---AABB-----------------BBAA--- ---AABB-----------------BBAA--- ----ABB-----------------BBA---- -----ABB----------------BA----- -----ABB----------------BA----- -----ABB----------------BA----- -----ABB----------------BA----- -----ABB----------------BA----- -----AAA----------------AA----- -----AAA----------------AA----- -----AAA----------------A------ -----AAA----------------A------ -----AAA----------------A------ -----AAA---------------AA------ -----AAA---------------AA------ -----AAA---------------AA------ -----AAA---------------AA------ -----ADD---------------DA------ -----ADD---------------DA------ ------DD---------------DA------ ------ADDAAAAAAAAAAAAADAA------ ------AAAAAAAAAAAAAAAAAAA------ -------AAAAAAAAAAAAAAAA-------- ------------------------------- ------------------------------- 
------CCC-------------CCC------ -----ABBB-------------BBBA----- ----AABBB-------------BBBAA---- ----AABBB-------------BBBAA---- ----AABBB-------------BBBAA---- ----AABBB-------------BBBAA---- ----AABBB-------------BBBAA---- -----ABBB-------------BBBA----- ------AAB-------------BAA------ ------ABBBBBBBBBBBBBBBBAA------ ------ABBBBBBBBBBBBBBBBAA------ ------AABBBBBBBBBBBBBBBAA------ ------AABBBBBBBBBBBBBBBAA------ ------AAAAAAAAAAAAAAAAAAA------ -------AAAAAAAAAAAAAAAAA------- -------AAAAAAAAAAAAAAAAA------- -------AAAAAAAAAAAAAAAAA------- -------AAAAAAAAAAAAAAAAA------- --------AAAAAAAAAAAAAAA-------- --------AAAAAAAAAAAAAAA-------- --------AAAAAAAAAAAAAAA-------- --------AAAAAAAAAAAAAAA-------- --------DDDAAAAAAAAADDD-------- --------DDDAAAAAAAAADDD-------- --------DDDAAAAAAAAADDD-------- ---------DDAAAAAAAAADD--------- ----------AAAAAAAAAAA---------- ------------------------------- ------------------------------- ------------------------------- 
--------CCCC-------CCCC-------- ------AABBBB-------BBBBAA------ -----AAABBBB-------BBBBAAA----- -----AAABBBB-------BBBBAAA----- -----AAABBBB-------BBBBAAA----- -----AAABBBB-------BBBBAAA----- -----AAABBBB-------BBBBAAA----- ------AABBBB-------BBBBAA------ -------AAAAB-------BAAAA------- -------ABBBBBBBBBBBBAAAA------- -------ABBBBBBBBBBBBAAAA------- --------BBBBBBBBBBBBAAA-------- --------BBBBBBBBBBBBAAA-------- ---------AAAAAAAAAAAAA--------- ---------AAAAAAAAAAAAA--------- ---------AAAAAAAAAAAAA--------- ---------AAAAAAAAAAAAA--------- ---------AAAAAAAAAAAAA--------- ---------AAAAAAAAAAAAA--------- ----------AAAAAAAAAAA---------- -----------AAAAAAAAA----------- -----------AAAAAAAAA----------- -----------DAAAAAAAD----------- -----------DAAAAAAAD----------- -----------DAAAAAAAD----------- -----------AAAAAAAAD----------- ------------------------------- ------------------------------- ------------------------------- ------------------------------- 
-----------CCCC-CCCC----------- --------AAABBBB-BBBBAAA-------- ------AAAAABBBB-BBBBAAAAA------ ------AAAAABBBB-BBBBAAAAA------ ------AAAAABBBB-BBBBAAAAA------ ------AAAAABBBB-BBBBAAAAA------ ------AAAAABBBB-BBBBAAAAA------ -------AAAABBBB-BBBBAAAA------- ---------AAAAAB-BAAAAA--------- ---------AAABBBBBBBAAA--------- ----------AABBBBBBBAA---------- ----------AABBBBBBBAA---------- -----------ABBBBBBBA----------- -----------AAAAAAAAA----------- -----------AAAAAAAAA----------- -----------AAAAAAAAA----------- ------------AAAAAAA------------ ------------AAAAAAA------------ ------------AAAAAAA------------ ------------AAAAAAA------------ ------------AAAAAAA------------ ------------AAAAAAA------------ ------------AAAAAAD------------ ------------AAAAAAD------------ ------------AAAAAAD------------ ------------------------------- ------------------------------- ------------------------------- ------------------------------- ------------------------------- 
--------------CCC-------------- -----------AAABBBAAA----------- --------AAAAAABBBAAAAAA-------- --------AAAAAABBBAAAAAA-------- --------AAAAAABBBAAAAAA-------- --------AAAAAABBBAAAAAA-------- --------AAAAAABBBAAAAAA-------- ----------AAAABBBAAAA---------- -----------AAAAAAAAA----------- ------------AABBBAA------------ ------------AABBBAA------------ -------------ABBBA------------- -------------ABBBA------------- -------------AAAAA------------- -------------AAAAA------------- -------------AAAAA------------- -------------AAAAA------------- -------------AAAAA------------- -------------AAAAA------------- -------------AAAAA------------- -------------AAAAA------------- -------------AAAAA------------- --------------AAA-------------- ------------------------------- ------------------------------- ------------------------------- ------------------------------- ------------------------------- ------------------------------- ------------------------------- 
------------------------------- --------------AAA-------------- ----------AAAAAAAAAAA---------- ---------AAAAAAAAAAAA---------- ---------AAAAAAAAAAAA---------- ----------AAAAAAAAAAA---------- -----------AAAAAAAAA----------- -------------AAAAA------------- ------------------------------- ------------------------------- ------------------------------- ------------------------------- ------------------------------- ------------------------------- ------------------------------- ------------------------------- ------------------------------- ------------------------------- ------------------------------- ------------------------------- ------------------------------- ------------------------------- ------------------------------- ------------------------------- ------------------------------- ------------------------------- ------------------------------- ------------------------------- ------------------------------- ------------------------------- 
------------------------------- ------------------------------- ------------AAAAAAA------------ ------------AAAAAAAA----------- ------------AAAAAAAA----------- ------------AAAAAAA------------ --------------AAA-------------- ------------------------------- ------------------------------- ------------------------------- ------------------------------- ------------------------------- ------------------------------- ------------------------------- ------------------------------- ------------------------------- ------------------------------- ------------------------------- ------------------------------- ------------------------------- ------------------------------- ------------------------------- ------------------------------- ------------------------------- ------------------------------- ------------------------------- ------------------------------- ------------------------------- ------------------------------- ------------------------------- 
