model
size = 31 30 31, scale = 0.05, origin = -y
material 
  colors = A:#FFF B:#FBFBFB C:#820806 D:#070707 E:#A0A0A0 F:#03350B G:#181818 H:#1C1C1C I:#005AF8 J:#090909 K:#0A0A0A L:#535353 M:#030303 N:#606060
voxels
----------DDH-H-H-HDD---------- ----------CCH-H-H-HCC---------- ------------H-H-H-H------------ --------KK--H-H-H-H--KK-------- --------KK--H-H-H-H--KK-------- --------------H-H-------------- --------------H-H-------------- --------------H-H-------------- --------------H-H-------------- ------------------------------- ------------------------------- ------------------------------- ------------------------------- ------------------------------- ------------------------------- ------------------------------- ------------------------------- ------------------------------- ------------------------------- ------------------------------- ------------------------------- ------------------------------- ------------------------------- ------------------------------- ------------------------------- ------------------------------- ------------------------------- ------------------------------- ------------------------------- ------------------------------- 
----------DDDJDJDJDDD---------- ------CCCCCBDJDJDJDBCCCCC------ ------C----CDJDJDJDC----C------ ------C-DD-CDJDJDJDC-DD-C------ ------C-DD-CJJDJDJJC-DD-C------ ------C----C-JDJDJ-C----C------ ------CCCCCC-JDJDJ-CCCCCC------ --------------DJD-------------- --------------HJH-------------- ------------------------------- ------------------------------- ------------------------------- ------------------------------- ------------------------------- ------------------------------- ------------------------------- ------------------------------- ------------------------------- ------------------------------- ------------------------------- ------------------------------- ------------------------------- ------------------------------- ------------------------------- ------------------------------- ------------------------------- ------------------------------- ------------------------------- ------------------------------- ------------------------------- 
------DDDDDDDDDDDDDDDDDDD------ -----CBCCCCBBBDDDBBBCCCCBC----- -----CB----CBBDDDBBC----CC----- -----CB-DD-CBBDDDBBC-DD-CC----- -----CB-DD-CBBDDDBBC-DD-CC----- -----CB----CCBDDDBCC----CC----- -----CB----CCBDDDBCC----CC----- -----CCCCCCCCCDDDCCCCCCCCC----- -------------CHHHC------------- ------------------------------- ------------------------------- ------------------------------- ------------------------------- ------------------------------- ------------------------------- ------------------------------- ------------------------------- ------------------------------- ------------------------------- ------------------------------- ------------------------------- ------------------------------- ------------------------------- ------------------------------- ------------------------------- ------------------------------- ------------------------------- ------------------------------- ------------------------------- ------------------------------- 
------D-----------------DD----- -----CBAAAAA--------AAAABC----- ----CBBCCCCA--------CCCCBBC---- ----CBBCAACA--------CAACBBC---- ----CBBCAACA--------CAACBBC---- ----CBBCCCCA--------CCCCBBC---- ----CBBCCCCA--------CCCCBBC---- -----CCCCCCB--------CCCCCC----- -----------CCBBBBBCC----------- ------------CCCCCCC------------ ------------------------------- ------------------------------- ------------------------------- ------------------------------- ------------------------------- ------------------------------- ------------------------------- ------------------------------- ------------------------------- ------------------------------- ------------------------------- ------------------------------- ------------------------------- ------------------------------- ------------------------------- ------------------------------- ------------------------------- ------------------------------- ------------------------------- ------------------------------- 
------D------------------D----- -----CB------------------C----- ----CBB------------------BC---- ----CBB------------------BC---- ----CBB------------------BC---- ----CBB------------------BC---- ----CBB------------------BC---- -----CB------------------C----- -----CCCCCCAA------ACCCCCC----- ------CCCCCCBBBBBBBCCCCCC------ --------C-CDCDCDCDCDC-C-------- ----------CDCDCDCDCDC---------- ------------CDCDCDC------------ --------------CDC-------------- ------------------------------- ------------------------------- ------------------------------- ------------------------------- ------------------------------- ------------------------------- ------------------------------- ------------------------------- ------------------------------- ------------------------------- ------------------------------- ------------------------------- ------------------------------- ------------------------------- ------------------------------- ------------------------------- 
------DD----------------DD----- -----CBB----------------BC----- ----CCBB----------------BBC---- ----CCBB----------------BBC---- ----CCBB----------------BBC---- ----CCBB----------------BBC---- ----CCBB----------------BBC---- -----CBB----------------BC----- -----CBBB---------------BC----- ------CDAAABBBBBBBBBAAADC------ -------CCDABBBBBBBBBADCC------- ---------CCDADADADADCC--------- -----------CBBBBBBBC----------- ------------CCAAACC------------ --------------CCC-------------- ------------------------------- ------------------------------- ------------------------------- ------------------------------- ------------------------------- ------------------------------- ------------------------------- ------------------------------- ------------------------------- ------------------------------- ------------------------------- ------------------------------- ------------------------------- ------------------------------- ------------------------------- 
-------D----------------D------ ------BB----------------B------ ------CB----------------BC----- ------CB----------------BC----- ------CB----------------BC----- ------CB----------------BC----- ------CB----------------BC----- ------CB----------------BC----- ------CBB---------------BC----- ------CBBB-------------BBC----- ------CBBB-------------BCA----- ------BCCB------------CCC------ -------BCCCBBBBBBBBBCCC-------- --------AAACCAAAAACCAAA-------- -------------CAAAC------------- --------------CCC-------------- ------------------------------- ------------------------------- ------------------------------- ------------------------------- ------------------------------- ------------------------------- ------------------------------- ------------------------------- ------------------------------- ------------------------------- ------------------------------- ------------------------------- ------------------------------- ------------------------------- 
-------D----------------D------ ------BB----------------B------ -----ABB----------------BAA---- -----CBB----------------BAC---- -----CBB----------------BAC---- -----CBB----------------BAC---- -----CBB----------------BAC---- ------CB----------------BC----- ------CBB---------------BC----- -----ABBBB-------------BBA----- -----ABBBB-------------BBA----- -----ABBBB-------------BBA----- -----ABBBB-------------BBA----- ------AAAAAAAAAAAAAAAAAAA------ -------AAAAACAAAAACAAAAA------- -------------CAAAC------------- -------------CCCCC------------- ------------------------------- ------------------------------- ------------------------------- ------------------------------- ------------------------------- ------------------------------- ------------------------------- ------------------------------- ------------------------------- ------------------------------- ------------------------------- ------------------------------- ------------------------------- 
------DD----------------DD----- -----BBB----------------BBA---- ----ABBB----------------BBA---- ----ABBB----------------BBA---- ----ABBB----------------BBA---- ----ABBB----------------BBA---- ----ABBB----------------BBA---- ----ABBB----------------BBA---- ----ABBBB---------------BBA---- ---AABBBBB-------------BBBAA--- ---AABBBBB-------------BBBAA--- ---AABBBBB-------------BBBAA--- ----ABBBBB-------------BBBA---- ----AAAAAA--------------AAA---- -----AAAAA--------------AA----- ------AAAAAAAAAAAAAAAAAAA------ ------------AAAAAAA------------ ------------AACCCAA------------ ------------------------------- ------------------------------- ------------------------------- ------------------------------- ------------------------------- ------------------------------- ------------------------------- ------------------------------- ------------------------------- ------------------------------- ------------------------------- ------------------------------- 
------D------------------D----- -----BB------------------BA---- ---AABB------------------BAA--- ---AABB------------------BAA--- ---AABB------------------BAA--- ----ABB------------------BAA--- -----BB------------------BA---- -----BB------------------BA---- -----BBBB----------------BA---- ----ABBBBB-------------BBBA---- ----ABBBBB-------------BBBA---- ---AABBBBB-------------BBBAA--- ---AABBBBB-------------BBBAA--- ---AAAAAAA--------------AAAA--- ----AAAAAA--------------AA----- -----EAAAA------------AAAE----- -----EAAAAAAAAAAAAAAAAAAAE----- -----EAAAAAAAAAAAAAAAAAAAE----- -----A-----AAACCCAAA-----A----- -------------ACCCA------------- ------------------------------- ------------------------------- ------------------------------- ------------------------------- ------------------------------- ------------------------------- ------------------------------- ------------------------------- ------------------------------- ------------------------------- 
-----DD-------------------D---- ----BBB-------------------B---- --AABBB-------------------BA--- --AABBB-------------------BAA-- --AABBB-------------------BAA-- ---ABBB-------------------BAA-- ----BBB-------------------BA--- ----BBB-------------------BA--- ----BBB-------------------B---- ----BBB-----------------BBB---- ----BBB-----------------BBB---- ----BBB-----------------BBB---- ----BBB-----------------BBB---- ----AAA-----------------AAAA--- ---AAAA-----------------AAAA--- ----EAA-----------------AAE---- ----EAA-----------------AAE---- ----EAAAAA-------------AAAE---- ----AA--AAAAAAAAAAAAAAA--AA---- ----A-----AAAAAAAAAAA-----A---- ----A--------ACCCA--------A---- ----A---------CCC---------A---- ----AA---------C---------AA---- -----AAAAAAAAACCCAAAAAAAAA----- ------------------------------- ------------------------------- ------------------------------- ------------------------------- ------------------------------- ------------------------------- 
-----D--------------------D---- ---DD---------------------BD--- --AB----------------------BBA-- -AAB----------------------BBAA- -AAB----------------------BBAA- --AB----------------------BBAA- ---A----------------------BBA-- ---A----------------------BBA-- ----B---------------------BB--- ----B--------------------BB---- ----B--------------------BB---- ----B--------------------BB---- ----B--------------------BB---- ----AAA------------------AA---- ----AAA------------------AA---- ---AAAA------------------AAA--- ---AAAA------------------AE---- ---EAAA------------------AE---- ---EAAFF---------------FFAE---- ---EAFFFFF-----------FFFFFA---- ---AAFFFFFFFF-----FFFFFFFFA---- ----AFFFFFFFFF---FFFFFFFFFA---- ----AAFFFFFFFFF-FFFFFFFFFAA---- ----AAAAAAAAAAAAAAAAAAAAAAA---- ----GGGGGGGGGGGGGGGGGGGGGGG---- ------------------------------- ------------------------------- ------------------------------- ------------------------------- ------------------------------- 
------------------------------- ---D-----------------------D--- --AB-----------------------BAA- AAAB-----------------------BAAA AAAB-----------------------BAAA IIAB-----------------------BAAI --IB-----------------------BAI- ---B-----------------------BA-- ----B----------------------A--- ----B--------------------BB---- ----B--------------------BB---- ----B--------------------BB---- ----B--------------------BB---- ----AAA------------------AA---- ----AAA------------------AA---- ----AAA------------------AA---- ---AAAA------------------AAA--- ---EAA-------------------ANE--- ---EAA------------------AANE--- ---EAA-----------------MMANE--- ---AAA-----------------MMAA---- ---AAA-----------------MMAA---- ----AA-DD--------------MMAA---- ----AA-----------------AAAA---- --GGAA-----------------AAAGG--- ----AAAAAAAAAACCCAAAAAAAAA----- ------------------------------- ------------------------------- ------------------------------- ------------------------------- 
------------------------------- ---D-----------------------D--- -AAB-----------------------BAA- AAAB-----------------------BAAA AAAB-----------------------BAAA AIAB-----------------------BAAA -AAB-----------------------BAA- ---A-----------------------BA-- ----B----------------------A--- ----B---------------------B---- ----B---------------------B---- ----B---------------------B---- ----B---------------------B---- ----A--------------------AA---- ----A---------------------A---- ----A---------------------A---- ----A--------------------AA---- ---AA--------------------AAA--- ---AA-------------------AAAA--- ---AAA-----------------AAAAA--- ---AAA-----------------AAAAA--- ---AAAAAA--------------AAAA---- ---AAAAAA--------------AAAA---- ---AAAAAA--------------AAAA---- --GGAAAAA--------------AAAGG--- ----AAAAA--------------AAA----- ----AAAAAAAAAACCCAAAAAAAA------ ------------------------------- ------------------------------- ------------------------------- 
------------------------------- ---D-----------------------D--- -AAB-----------------------BAA- AAAB-----------------------BAAA AAAB-----------------------BAAA IAAB-----------------------BAAI -IAB-----------------------BAI- --IB-----------------------BI-- ---BB----------------------A--- ----B---------------------B---- ----B---------------------B---- ----B---------------------B---- ----B---------------------B---- ----A---------------------A---- ----A---------------------A---- ----A---------------------A---- ----A---------------------A---- ----A--------------------AA---- ---AA--------------------AAA--- --AAA-------------------AAAA--- --AAA-------------------AAAA--- ---AA-------------------AAAA--- ---AA------------------AAAA---- ---AA------------------AAAA---- --GDA------------------AAADG--- ---AAAAAA--------------AAAA---- ----AAAAA--------------AAA----- -----AAAAAAAACCCCCAAAAAA------- ------------------------------- ------------------------------- 
------------------------------- --DD-----------------------D--- -ABB-----------------------BBA- AABB-----------------------BBAA AABB-----------------------BBAA AABB-----------------------BBAA -ABB-----------------------BBA- --AB-----------------------BB-- ---AB----------------------BA-- ---AB---------------------BB--- ----B---------------------B---- ----B---------------------B---- ----B---------------------B---- ----A---------------------A---- ----A---------------------A---- ----A---------------------A---- ----A---------------------A---- ---AA---------------------A---- --AAA--------------------AAA--- --AAA--------------------AAAA-- --AAA--------------------AAAA-- --AAA-------------------AAAA--- ---AA-------------------AAAA--- ---AA-------------------AAA---- --GAA-------------------AADG--- ---EAA------------------AAE---- ----EAA----------------AAE----- -----AAA---------------AA------ ------AAAAAAACCCCCAAAAA-------- ---------AAACCCCCCCAA---------- 
------------------------------- --D------------------------BD-- -AB------------------------BBA- AAB------------------------BBAA AAB------------------------BBAA IAB------------------------BBAI -IB------------------------BBI- --I------------------------BI-- ---IB----------------------BI-- ---AB---------------------BA--- ----B---------------------B---- ----B---------------------B---- ----B---------------------B---- ----A---------------------A---- ----A---------------------A---- ----A---------------------A---- ----A---------------------A---- ---AA---------------------AA--- -AAAA---------------------AAA-- -AAAA---------------------AAAA- -AAAA--------------------AAAAA- -AAAA--------------------AAAA-- --AAA--------------------AAA--- ---AA--------------------AAA--- --GAA--------------------ADG--- ---EA--------------------AE---- ----EA------------------AE----- -----A-----------------AA------ ------AA--------------AA------- --------AAAACCCCCCCAAA--------- 
------------------------------- --D-------------------------D-- -AB-------------------------BA- AAB-------------------------BAA AAB-------------------------BAA AAB-------------------------BAA -AB-------------------------BA- --A-------------------------B-- ---A------------------------A-- ---AB---------------------BB--- ----B---------------------B---- ----B---------------------B---- ----B---------------------B---- ----A---------------------A---- ----A---------------------A---- ---AA---------------------A---- ---AA---------------------AA--- --AAA---------------------AAA-- -AAAA---------------------AAAA- EAAAA---------------------AAALE EAAAA---------------------AAALE -AAAA----------------------AAA- -AAAA--------------------AAAA-- --AAA--------------------AAA--- --AAA--------------------AAA--- ---AA--------------------AA---- ----EA------------------AE----- -----A-----------------AA------ ------AA--------------AA------- -------AAAAACCCCCCCAAA--------- 
------------------------------- --D-------------------------D-- -AB-------------------------BA- AAB-------------------------BAA AAB-------------------------BAA IAB-------------------------BAI -IB-------------------------BI- --I-------------------------I-- --IBB-----------------------I-- --AAB----------------------A--- --AAB---------------------BB--- --AAB---------------------BB--- --AAB---------------------BB--- --AAA---------------------AA--- --AAA---------------------AAA-- --AAA---------------------AAA-- --AAA---------------------AAA-- -AAAA---------------------AAAA- -AAAA---------------------AAAA- EAAAA---------------------AAALE EAAAA---------------------AAALE -AAAA---------------------AAAA- -AAAA--------------------AAAAA- -AAAA--------------------AAAA-- --AAA--------------------AAA--- ---AA--------------------AA---- ----AA------------------AA----- -----A-----------------AA------ ------AA--------------AA------- -------AAAAACCCCCCCAAA--------- 
---D------------------------D-- --DB------------------------BA- -ABB------------------------BA- AABB------------------------BAA AABB------------------------BAA AABB------------------------BAA AABB------------------------BAA -ABB------------------------BA- -AABB-----------------------BA- -ABBB----------------------BBA- -ABBB----------------------BBA- -ABBB---------------------BBBA- -ABBB---------------------BBBA- -AAAA---------------------AAAA- -AAAA---------------------AAAA- -AAAA---------------------AAAA- -AAAA---------------------AAAA- -AAAA---------------------AAAA- -AAAA---------------------AAAA- EAAAA---------------------AAALE EAAAA---------------------AAALE -AAAA--------------------AAAAA- -AAAA--------------------AAAAA- -AAAA--------------------AAAA-- --AAA--------------------AAA--- ---AA-------------------AAA---- ----AA------------------AA----- -----A-----------------AA------ ------AA--------------AA------- -------AAAAACCCCCCCAAA--------- 
---D------------------------D-- --AB------------------------BA- -ABB------------------------BA- AABB------------------------BAA AABB------------------------BAA AABB------------------------BAA AABB------------------------BAA AABB------------------------BAA --ABB-----------------------BA- --ABB----------------------BB-- --ABB----------------------BB-- --ABB---------------------BBB-- --ABB---------------------BBB-- --AAA---------------------AAA-- --AAA---------------------AAA-- --AAA---------------------AAA-- --AAA---------------------AAA-- -AAAA---------------------AAAA- -AAAA---------------------AAAA- EAAAA---------------------AAALE EAAAA---------------------AAALE -AAAA--------------------AAAAA- -AAAA--------------------AAAA-- --AAA--------------------AAA--- --AAA-------------------AAAA--- ---AA-------------------AAA---- ----AA------------------AA----- -----A-----------------AA------ ------AA--------------AA------- -------AAAAACCCCCCCAAA--------- 
---DD-----------------------D-- --ABB-----------------------B-- -ABBB-----------------------BA- AABBB-----------------------BA- AABBB-----------------------BAA AABBB-----------------------BAA AABBB-----------------------BAA --BBB-----------------------BA- --ABBB----------------------B-- --ABBB---------------------BB-- --ABBB---------------------BB-- --ABBB--------------------BBB-- --ABBB--------------------BBB-- --AAAA--------------------AAA-- --AAAA--------------------AAA-- --AAAA--------------------AAA-- --AAAA--------------------AAA-- --AAAA--------------------AAA-- -AAAAA--------------------AAA-- -AAAAA--------------------AAAA- -AAAA---------------------AAAA- -AAAAA--------------------AAA-- --AAAA-------------------AAA--- --AAAA-------------------AAA--- ---AAA------------------AAA---- ---AAA------------------AAA---- ----AA------------------AA----- -----A-----------------AA------ ------AA--------------AA------- -------AAAAACCCCCCCAAA--------- 
----D----------------------D--- --ABB----------------------BA-- --ABB----------------------BAA- -AABB----------------------BAA- AAABB----------------------BAA- AAABB----------------------BAA- -AABB----------------------BAA- --ABB----------------------BA-- ---ABBB--------------------A--- ---ABBB--------------------A--- ---ABBB--------------------A--- ---ABBB-------------------BA--- ---ABBB-------------------BA--- ---AAAA-------------------AA--- ---AAAA-------------------AA--- ---AAAA-------------------AA--- ---AAAA-------------------AA--- ---AAAA-------------------A---- ---AAAA-------------------A---- ---AAAA-------------------A---- ----AAA-------------------A---- ----AAA-------------------A---- ----AAA------------------AA---- ----AAA-----------------AAA---- ----AAA-----------------AAA---- ----AAA-----------------AAA---- ----AAA-----------------AA----- -----AA----------------AA------ ------AAAAAAAAAAAAAAAAAA------- ---------AAACCCCCCCAA---------- 
----DD-------------------DD---- ---ABB-------------------BBA--- --AABB-------------------BBAA-- --AABB-------------------BBAA-- --AABB-------------------BBAA-- --AABB-------------------BBAA-- --AABB-------------------BBAA-- ---ABB-------------------BBA--- ----ABBB-----------------BA---- ----ABBB----------------BBA---- ----ABBB----------------BBA---- ----ABBB----------------BBA---- ----ABBB----------------BBA---- ----AAAA----------------AAA---- ----AAAA-----------------AA---- ----AAAA----------------AAA---- ----AAAA----------------AA----- ----AAAA----------------AA----- ----AAAA----------------AA----- ----AAAA----------------AA----- ----AAAA----------------AA----- ----AAAA----------------AA----- -----AAA----------------AA----- -----AAA----------------AA----- -----AAA----------------AA----- -----AAA----------------AA----- -----AAA----------------AA----- -----AAAAAAAAAAAAAAAAAAAA------ -------AAAAACCCCCCCAAAA-------- ------------------------------- 
-----DD-----------------DD----- ----ABB-----------------BBA---- ---AABB-----------------BBAA--- ---AABB-----------------BBAA--- ---AABB-----------------BBAA--- ---AABB-----------------BBAA--- ---AABB-----------------BBAA--- ----ABB-----------------BBA---- -----ABB----------------BA----- -----ABB----------------BA----- -----ABB----------------BA----- -----ABB----------------BA----- -----ABB----------------BA----- -----AAA----------------AA----- -----AAA----------------AA----- -----AAA----------------A------ -----AAA----------------A------ -----AAA----------------A------ -----AAA---------------AA------ -----AAA---------------AA------ -----AAA---------------AA------ -----AAA---------------AA------ -----AEE---------------EA------ -----AEE---------------EA------ ------EE---------------EA------ ------AEEAAAAAAAAAAAAAEAA------ ------AAAAAAAAAAAAAAAAAAA------ -------AAAAACCCCCCCAAAA-------- ------------------------------- ------------------------------- 
------DDD-------------DDD------ -----ABBB-------------BBBA----- ----AABBB-------------BBBAA---- ----AABBB-------------BBBAA---- ----AABBB-------------BBBAA---- ----AABBB-------------BBBAA---- ----AABBB-------------BBBAA---- -----ABBB-------------BBBA----- ------AAB-------------BAA------ ------ABBBBBBBBBBBBBBBBAA------ ------ABBBBBBBBBBBBBBBBAA------ ------AABBBBBBBBBBBBBBBAA------ ------AABBBBBBBBBBBBBBBAA------ ------AAAAAAAAAAAAAAAAAAA------ -------AAAAAAAAAAAAAAAAA------- -------AAAAAAAAAAAAAAAAA------- -------AAAAAAAAAAAAAAAAA------- -------AAAAAAAAAAAAAAAAA------- --------AAAAAAAAAAAAAAA-------- --------AAAAAAAAAAAAAAA-------- --------AAAAAAAAAAAAAAA-------- --------AAAAAAAAAAAAAAA-------- --------EEEAAAAAAAAAEEE-------- --------EEEAAAAAAAAAEEE-------- --------EEEAAAAAAAAAEEE-------- ---------EEAAAAAAAAAEE--------- ----------AAACCCCCAAA---------- ------------------------------- ------------------------------- ------------------------------- 
--------DDDD-------DDDD-------- ------AABBBB-------BBBBAA------ -----AAABBBB-------BBBBAAA----- -----AAABBBB-------BBBBAAA----- -----AAABBBB-------BBBBAAA----- -----AAABBBB-------BBBBAAA----- -----AAABBBB-------BBBBAAA----- ------AABBBB-------BBBBAA------ -------AAAAB-------BAAAA------- -------ABBBBBBBBBBBBAAAA------- -------ABBBBBBBBBBBBAAAA------- --------BBBBBBBBBBBBAAA-------- --------BBBBBBBBBBBBAAA-------- ---------AAAAAAAAAAAAA--------- ---------AAAAAAAAAAAAA--------- ---------AAAAAAAAAAAAA--------- ---------AAAAAAAAAAAAA--------- ---------AAAAAAAAAAAAA--------- ---------AAAAAAAAAAAAA--------- ----------AAAAAAAAAAA---------- -----------AAAAAAAAA----------- -----------AAAAAAAAA----------- -----------EAAAAAAAE----------- -----------EAAAAAAAE----------- -----------EAAAAAAAE----------- -----------AAACCCAAE----------- ------------------------------- ------------------------------- ------------------------------- ------------------------------- 
-----------DDDD-DDDD----------- --------AAABBBB-BBBBAAA-------- ------AAAAABBBB-BBBBAAAAA------ ------AAAAABBBB-BBBBAAAAA------ ------AAAAABBBB-BBBBAAAAA------ ------AAAAABBBB-BBBBAAAAA------ ------AAAAABBBB-BBBBAAAAA------ -------AAAABBBB-BBBBAAAA------- ---------AAAAAB-BAAAAA--------- ---------AAABBBBBBBAAA--------- ----------AABBBBBBBAA---------- ----------AABBBBBBBAA---------- -----------ABBBBBBBA----------- -----------AAAAAAAAA----------- -----------AAAAAAAAA----------- -----------AAAAAAAAA----------- ------------AAAAAAA------------ ------------AAAAAAA------------ ------------AAAAAAA------------ ------------AAAAAAA------------ ------------AAAAAAA------------ ------------AAAAAAA------------ ------------AAAAAAE------------ ------------AACCCAE------------ ------------AACCCAE------------ ------------------------------- ------------------------------- ------------------------------- ------------------------------- ------------------------------- 
--------------DDD-------------- -----------AAABBBAAA----------- --------AAAAAABBBAAAAAA-------- --------AAAAAABBBAAAAAA-------- --------AAAAAABBBAAAAAA-------- --------AAAAAABBBAAAAAA-------- --------AAAAAABBBAAAAAA-------- ----------AAAABBBAAAA---------- -----------AAAAAAAAA----------- ------------AABBBAA------------ ------------AABBBAA------------ -------------ABBBA------------- -------------ABBBA------------- -------------AAAAA------------- -------------AAAAA------------- -------------AAAAA------------- -------------AAAAA------------- -------------AAAAA------------- -------------AAAAA------------- -------------AAAAA------------- -------------AAAAA------------- -------------AAAAA------------- --------------CCC-------------- ------------------------------- ------------------------------- ------------------------------- ------------------------------- ------------------------------- ------------------------------- ------------------------------- 
------------------------------- --------------AAA-------------- ----------AAAAAAAAAAA---------- ---------AAAAAAAAAAAA---------- ---------AAAAAAAAAAAA---------- ----------AAAAAAAAAAA---------- -----------AAAAAAAAA----------- -------------AAAAA------------- ------------------------------- ------------------------------- ------------------------------- ------------------------------- ------------------------------- ------------------------------- ------------------------------- ------------------------------- ------------------------------- ------------------------------- ------------------------------- ------------------------------- ------------------------------- ------------------------------- ------------------------------- ------------------------------- ------------------------------- ------------------------------- ------------------------------- ------------------------------- ------------------------------- ------------------------------- 
------------------------------- ------------------------------- ------------AAAAAAA------------ ------------AAAAAAAA----------- ------------AAAAAAAA----------- ------------AAAAAAA------------ --------------AAA-------------- ------------------------------- ------------------------------- ------------------------------- ------------------------------- ------------------------------- ------------------------------- ------------------------------- ------------------------------- ------------------------------- ------------------------------- ------------------------------- ------------------------------- ------------------------------- ------------------------------- ------------------------------- ------------------------------- ------------------------------- ------------------------------- ------------------------------- ------------------------------- ------------------------------- ------------------------------- ------------------------------- 
