model
size = 19 31 19, scale = 0.05, origin = -y
material 
  colors = A:#F6F B:#FF4BFF C:#FF09FF D:#DDD E:#AAA F:#E44BFF
voxels
------------------- ------------------- ------------------- ------------------- ------------------- ----------BBBBBB--- ----------BBBBBB--- ------------------- ------------------- ------------------- ------------------- ------------------- ------------------- ------------------- ------------------- ------------------- ------------------- ------------------- ------------------- ------------------- ------------------- ------------------- ------------------- ------------------- ------------------- ------------------- ------------------- ------------------- ------------------- ------------------- ------------------- 
----BBBBBAAA------- ---BB----AAAAA----- --BB-----AAAAAA---- -BB------AAAAAAAA-- -B-------AAAAAAAA-- -B-------AAAAAAAA-- BB-------AAAAAAAA-- B--------AAAAAAAA-- B--------AAAAAAAA-- B--------AAAAAAAA-- B--------AAAAAAAA-- B--------AAEAAAAA-- B--------AAEAAAAA-- B--------AAEAAAAA-- B--------AAEAAAAA-- B--------AAEAAAAA-- B--------AAEAAAAA-- B--------AAEAAAAA-- B--------AAEAAAAA-- B--------AAEAAAAA-- B--------AAEAAAAA-- BB-------AAEAAAAA-- -B-------AAEAAAAA-- -B-------AAAEAA---- -BB------AAAAA----- --BB-----AAAA------ ---BB--BAA--------- ----BBBB----------- ------------------- ------------------- ------------------- 
----BBBBBAAA------- ---BB----AAAAA----- --BB-----AAAAAA---- -BB------AAAAAAAA-- -B------BAAAAAAAABB -B------BAAAAAAAABB BB------BAAAAAAAABB B--------ACCCAAAABB B--------ACCCAAAABB B-------BACCCAAAABB B-------BACCCAAAABB B-------BACCCAAAABB B-------BACCCAAAABB B-------BACCCAAAA-- B-------BACCCAAAA-- B-------BACCCAAAA-- B-------BACCCAAAA-- B-------BACCCAAAA-- B-------BCCCAAAAA-- B-------BCCCAAAAA-- B-------BCCCAAAAA-- BB------BCCCAAAAA-- -B------BCCCAAAAA-- -B------BFFFAAA---- -BB-----BAAAAA----- --BB-----AAAA------ ---BB--BAA--------- ----BBBB----------- ------------------- ------------------- ------------------- 
---------AAA------- ---------AAAAA----- ---------AAAAAA---- ---------AAAAAAAA-- --------BAAAAAAAABB --------BAAAAAAAABB --------BAAAAAAAABB ---------ACCCAAAABB ---------ACCCAAAABB --------BACCCAAAABB --------BACCCAAAABB --------BACCCAAAABB --------BACCCAAAABB --------BACCCAAAA-- --------BACCCAAAA-- --------BACCCAAAA-- --------BACCCAAAA-- --------BACCCAAAA-- --------BCCCAAAAA-- --------BCCCAAAAA-- --------BCCCAAAAA-- --------BCCCAAAAA-- --------BCCCAAAAA-- --------BCCCAAA---- --------BCCCAA----- ---------AAAA------ -----------A------- -----------A------- -----------A------- ------------------- ------------------- 
---------AAA------- ---------AAAAA----- ---------AAAAAA---- ---------AAAAAAAA-- --------BAAAAAAAABB --------BAAACAAAABB --------BACCCAAAABB ---------ACCCAAAABB ---------ACCCAAAABB --------BACCCAAAABB --------BACCCAAAABE --------BACCCAAAABB --------BACCCAAAABB --------BACCCAAAA-- --------BACCCAAAA-- --------BACCCAAAD-- --------BACCCAAAD-- --------BACCCAAAD-- --------BCCCAAAAD-- --------BCCCAAAAA-- --------BCCCAAAAA-- --------BCCCAAAAA-- --------BCCCAAAAA-- --------BCCCAAA---- --------BCCCAA----- ---------AAAA------ -----------D------- -----------D------- -----------A------- -----------A------- ------------------- 
---------AAA------- ---------AAAAA----- ---------AAAAAA---- ---------AAAAAAAA-- --------BAAAAAAAABB --------BAAACAAAABB --------BACCCAAAABB ---------ACCCAAAABB ---------ACCCAAAABB --------BACCCAAAABB --------BACCCAAAABE --------BACCCAAAABB --------BACCCAAAABB --------BACCCAAAA-- --------BACCCAAAD-- --------BACCCAAAD-- --------BACCCAAAD-- --------BACCCAAAD-- --------BCCCAAAAD-- --------BCCCAAAAD-- --------BCCCAAAAD-- --------BCCCAAAAD-- --------BCCCAAAAA-- --------BCCCAAA---- --------BCCCAA----- ---------AAAA------ -----------D------- -----------D------- -----------D------- -----------A------- -----------A------- 
---------AAA------- ---------AAAAA----- ---------AAACAA---- ---------AAACAAAA-- --------BAAACAAAABB --------BAAACAAAABB --------BACCCAAAABB ---------ACCCAAAABB ---------ACCCAAAABB --------BACCCAAAABB --------BACCCAAAABE --------BACCCAAAABB --------BACCCAAAABB --------BACCCAAAA-- --------BACCCAAAD-- --------BACCCAAAD-- --------BACCCAAAD-- --------BACCCAAAD-- --------BCCCAAAAD-- --------BCCCAAAAA-- --------BCCCAAAAA-- --------BCCCAAAAD-- --------BCCCAAAAA-- --------BCCCAAA---- --------BCCCAA----- ---------AAAA------ -----------D------- -----------D------- -----------A------- -----------A------- ------------------- 
---------AAA------- ---------AAAAA----- ---------AAACAA---- ---------AAACAAAA-- --------BAAACAAAABB --------BAAACAAAABB --------BACCCAAAABB ---------ACCCAAAABB ---------ACCCAAAABB --------BACCCAAAABB --------BACCCAAAABE --------BAAAAAAAABB --------BAAAAAAAABB --------BACCCAAAA-- --------BACCCAAAD-- --------BACCCAAAD-- --------BACCCAAAA-- --------BACCCAAAA-- --------BCCCAAAAD-- --------BCCCAAAAD-- --------BCCCAAAAD-- --------BCCCAAAAD-- --------BCCCAAAAA-- --------BCCCAAA---- --------BCCCAA----- ---------AAAA------ -----------A------- -----------A------- -----------A------- ------------------- ------------------- 
---------AAA------- ---------AAAAA----- ---------AAACAA---- ---------AAACAAAA-- --------BAAACAAAABB --------BAAACAAAABB --------BACCCAAAABB ---------ACCCAAAABB ---------ACCCAAAABB --------BACCCAAAABB --------BACCCAAAABE --------BAAAAAAAABB --------BAAAAAAAABB --------BACCCAAAD-- --------BACCCAAAD-- --------BACCCAAAD-- --------BACCCAAAD-- --------BACCCAAAD-- --------BCCCAAAAD-- --------BCCCAAAAA-- --------BCCCAAAAA-- --------BCCCAAAAA-- --------BCCCAAAAA-- --------BCCCAAA---- --------BCCCAA----- ---------AAAA------ ------------------- ------------------- ------------------- ------------------- ------------------- 
---------AAA------- ---------AAAAA----- ---------AAACAA---- ---------AAACAAAA-- --------BAAACAAAABB --------BAAACAAAABB --------BACCCAAAABB ---------ACCCAAAABB ---------ACCCAAAABB --------BACCCAAAABB --------BACCCAAAABE --------BAAAAAAAABB --------BAAAAAAAABB --------BACCCAAAD-- --------BACCCAAAD-- --------BACCCAAAD-- --------BACCCAAAD-- --------BACCCAAAD-- --------BCCCAAAAD-- --------BCCCAAAAA-- --------BCCCAAAAA-- --------BCCCAAAAA-- --------BCCCAAAAA-- --------BCCCAAA---- --------BCCCAA----- ---------AAAA------ ------------------- ------------------- ------------------- ------------------- ------------------- 
---------AAA------- ---------AAAAA----- ---------AAACAA---- ---------AAACAAAA-- --------BAAACAAAABB --------BAAACAAAABB --------BACCCAAAABB ---------ACCCAAAABB ---------ACCCAAAABB --------BACCCAAAABB --------BACCCAAAABE --------BAAAAAAAABB --------BAAAAAAAABB --------BACCCAAAD-- --------BACCCAAAD-- --------BACCCAAAD-- --------BACCCAAAD-- --------BACCCAAAD-- --------BCCCAAAAD-- --------BCCCAAAAA-- --------BCCCAAAAA-- --------BCCCAAAAA-- --------BCCCAAAAA-- --------BCCCAAA---- --------BCCCAA----- ---------AAAA------ ------------------- ------------------- ------------------- ------------------- ------------------- 
---------AAA------- ---------AAAAA----- ---------AAACAA---- ---------AAACAAAA-- --------BAAACAAAABB --------BAAACAAAABB --------BACCCAAAABB ---------ACCCAAAABB ---------ACCCAAAABB --------BACCCAAAABB --------BACCCAAAABE --------BAAAAAAAABB --------BAAAAAAAABB --------BACCCAAAA-- --------BACCCAAAD-- --------BACCCAAAD-- --------BACCCAAAA-- --------BACCCAAAA-- --------BCCCAAAAD-- --------BCCCAAAAD-- --------BCCCAAAAD-- --------BCCCAAAAD-- --------BCCCAAAAA-- --------BCCCAAA---- --------BCCCAA----- ---------AAAA------ ------------------- ------------------- ------------------- ------------------- ------------------- 
---------AAA------- ---------AAAAA----- ---------AAACAA---- ---------AAACAAAA-- --------BAAACAAAABB --------BAAACAAAABB --------BACCCAAAABB ---------ACCCAAAABB ---------ACCCAAAABB --------BACCCAAAABB --------BACCCAAAABE --------BAAAAAAAABB --------BAAAAAAAABB --------BACCCAAAA-- --------BACCCAAAD-- --------BACCCAAAD-- --------BACCCAAAD-- --------BACCCAAAD-- --------BCCCAAAAD-- --------BCCCAAAAA-- --------BCCCAAAAA-- --------BCCCAAAAD-- --------BCCCAAAAA-- --------BCCCAAA---- --------BCCCAA----- ---------AAAA------ -----------A------- -----------A------- -----------A------- ------------------- ------------------- 
---------AAA------- ---------AAAAA----- ---------AAACAA---- ---------AAACAAAA-- --------BAAACAAAABB --------BAAACAAAABB --------BACCCAAAABB ---------ACCCAAAABB ---------ACCCAAAABB --------BACCCAAAABB --------BACCCAAAABE --------BAAAAAAAABB --------BAAAAAAAABB --------BACCCAAAA-- --------BACCCAAAD-- --------BACCCAAAD-- --------BACCCAAAD-- --------BACCCAAAD-- --------BCCCAAAAD-- --------BCCCAAAAD-- --------BCCCAAAAD-- --------BCCCAAAAD-- --------BCCCAAAAA-- --------BCCCAAA---- --------BCCCAA----- ---------AAAA------ -----------D------- -----------D------- -----------A------- -----------A------- ------------------- 
---------AAA------- ---------AAAAA----- ---------AAACAA---- ---------AAACAAAA-- --------BAAACAAAABB --------BAAACAAAABB --------BCCCCAAAABB ---------ACCCAAAABB ---------ACCCAAAABB --------BACCCAAAABB --------BCCCCAAAABE --------BAAAAAAAABB --------BAAAAAAAABB --------BCCAAAAAA-- --------BCCAAAAAA-- --------BCCAAAAAD-- --------BCCAAAAAD-- --------BCCAAAAAD-- --------BCCAAAAAD-- --------BCCAAAAAA-- --------BCCAAAAAA-- --------BCCAAAAAA-- --------BCCAAAAAA-- --------BCCAAAA---- --------BCCAAA----- ---------AAAA------ -----------D------- -----------D------- -----------D------- -----------A------- -----------A------- 
---------AAA------- ---------AAAAA----- ---------AAACAA---- ---------AAACAAAA-- --------BAAACAAAABB --------BAAACAAAABB --------BCCCCAAAABB ---------ACCCAAAABB ---------ACCCAAAABB --------BACCCAAAABB --------BCCCCAAAABE --------BAAAAAAAABB --------BAAAAAAAABB --------BCCAAAAAA-- --------BCCAAAAAA-- --------BCCAAAAAA-- --------BCCAAAAAA-- --------BCCAAAAAA-- --------BCCAAAAAA-- --------BCCAAAAAA-- --------BCCAAAAAA-- --------BCCAAAAAA-- --------BCCAAAAAA-- --------BCCAAAA---- --------BCCAAA----- ---------AAAA------ -----------D------- -----------D------- -----------A------- -----------A------- ------------------- 
---------AAA------- ---------AAAAA----- ---------AAACAA---- ---------AAACAAAA-- --------BAAACAAAABB --------BAAACAAAABB --------BCCCCAAAABB ---------ACCCAAAABB ---------ACCCAAAABB --------BACCCAAAABB --------BCCCCAAAABB --------BAAAAAAAABB --------BAAAAAAAABB --------BAAAAAAAA-- --------BAAAAAAAA-- --------BAAAAAAAA-- --------BAAAAAAAA-- --------BAAAAAAAA-- --------BAAAAAAAA-- --------BAAAAAAAA-- --------BAAAAAAAA-- --------BAAAAAAAA-- --------BAAAAAAAA-- --------BAAAAAA---- --------BAAAAA----- ---------AAAA------ -----------A------- -----------A------- -----------A------- ------------------- ------------------- 
----BBBBBAAA------- ---BB----AAAAA----- --BB-----AAACAA---- -BB------AAACAAAA-- -B------BAAACAAAABB -B------BAAACAAAABB BB------BCCCCAAAABB B--------ACCCAAAABB B--------ACCCAAAABB B-------BACCCAAAABB B-------BCCCCAAAABB B-------BAAAAAAAABB B-------BAAAAAAAABB B-------BAAAAAAAA-- B-------BAAAAAAAA-- B-------BAAAAAAAA-- B-------BAAAAAAAA-- B-------BAAAAAAAA-- B-------BAAAAAAAA-- B-------BAAAAAAAA-- B-------BAAAAAAAA-- BB------BAAAAAAAA-- -B------BAAAAAAAA-- -B------BAAAAAA---- -BB-----BAAAAA----- --BB-----AAAA------ ---BB--BAA--------- ----BBBB----------- ------------------- ------------------- ------------------- 
----BBBBBAAA------- ---BB----AAAAA----- --BB-----AABAAA---- -BB------AABAAAAA-- -B-------AABABAAA-- -B-------AABABAAA-- BB-------AABABAAA-- B--------AABABAAA-- B--------AABABAAA-- B--------AABABAAA-- B--------AABABAAA-- B--------AABABAAA-- B--------AABABAAA-- B--------AABABAAA-- B--------AABABAAA-- B--------AABABAAA-- B--------AABABAAA-- B--------AABABAAA-- B--------AABABAAA-- B--------AABABAAA-- B--------AABABAAA-- BB-------AABABAAA-- -B-------AABABAAA-- -B-------AABAAA---- -BB------AABAA----- --BB-----AAAA------ ---BB--BAA--------- ----BBBB----------- ------------------- ------------------- ------------------- 
