model
size = 19 28 19, scale = 0.05, origin = -y
material 
  colors = A:#0FF B:#FFF C:#D00 D:#0A0 E:#AAA F:#F30 G:#E00 H:#CF3 I:#00FF26 J:#F0C K:#007
voxels
------------------- ------------------- ------------------- ------------------- ------------------- ----------AAAAAA--- ----------AAAAAA--- ------------------- ------------------- ------------------- ------------------- ------------------- ------------------- ------------------- ------------------- ------------------- ------------------- ------------------- ------------------- ------------------- ------------------- ------------------- ------------------- ------------------- ------------------- ------------------- ------------------- ------------------- 
----AAAAAAAA------- ---AA----AAAAA----- --AA-----AAAAAA---- -AA------AAAAAAAA-- -A-------AAAAAAAA-- -A-------AAAAAAAA-- AA-------AAAAAAAA-- A--------AAAAAAAA-- A--------AAAAAAAA-- A--------AAEAAAAA-- A--------AAEAAAAA-- A--------AAEAAAAA-- A--------AAEAAAAA-- A--------AAEAAAAA-- A--------AAEAAAAA-- A--------AAEAAAAA-- A--------AAEAAAAA-- A--------AAEAAAAA-- A--------AAEAAAAA-- A--------AAEAAAAA-- A--------AAEAAAAA-- AA-------AAEAAAAA-- -A-------AAEAAAAA-- -A-------AAAEAA---- -AA------AAAAA----- --AA-----AAAA------ ---AA--AAA--------- ----AAAA----------- 
----AAAAAAAA------- ---AA----AAAAA----- --AA-----AAAAAA---- -AA------AAAAAAAA-- -A------AAAAAAAAAAA -A------AAAAAAAAAAA AA------AAAAAAAAAAA A--------AAAAAAAAAA A--------AAAAAAAAAA A-------AAAAAAAAAAA A-------AAAAAAAAAAA A-------AAAAAAAAAAA A-------AAAAAAAAAAA A-------AAAAAAAAA-- A-------AAAAAAAAA-- A-------AAAAAAAAA-- A-------AAAAAAAAA-- A-------AAAAAAAAA-- A-------AAAAAAAAA-- A-------AAAAAAAAA-- A-------AAAAAAAAA-- AA------AAAAAAAAA-- -A------AAAAAAAAA-- -A------AAAAAAA---- -AA-----AAAAAA----- --AA-----AAAA------ ---AA--AAA--------- ----AAAA----------- 
---------AAA------- ---------AAAAA----- ---------AAAAAA---- ---------AAAAAAAA-- --------AAAAAAAAAAA --------AAAAAAAAAAA --------AAAAAAAAAAA ---------AAAAAAAAAA ---------AAAAAAAAAA --------AAAAAAAAAAA --------AAAAAAAAAAA --------AAAAAAAAAAA --------AAAAAAAAAAA --------AAAAAAAAA-- --------AAAAAAAAA-- --------AAAAAAAAA-- --------AAAAAAAAA-- --------AAAAAAAAA-- --------AAAAAAAAA-- --------AAAAAAAAA-- --------AAAAAAAAA-- --------AAAAAAAAA-- --------AAAAAAAAA-- --------AAAAAAA---- --------AAAAAA----- ---------AAAA------ ------------------- ------------------- 
---------AAA------- ---------AAAAA----- ---------AAAAAA---- ---------AAAAAAAA-- --------AAAAAAAAAAA --------AAAAAAAAAAA --------AAAAAAAAAAA ---------AAAAAAAAAA ---------AAAAAAAAAA --------AAAAAAAAAAA --------AAAAAAAAAAA --------AAAAAAAAAAA --------AAAAAAAAAAA --------AAAAAAAAA-- --------AAAAAAAAA-- --------AAAAAAAAA-- --------AAAAAAAAA-- --------AAAAAAAAA-- --------AAAAAAAAA-- --------AAAAAAAAA-- --------AAAAAAAAA-- --------AAAAAAAAA-- --------AAAAAAAAA-- --------AAAAAAA---- --------AAAAAA----- ---------AAAA------ ------------------- ------------------- 
---------AAA------- ---------AAAAA----- ---------AAAAAA---- ---------AAAAAAAA-- --------AAAAAAAAAAA --------AAAAAAAAAAA --------AAAAAAAAAAA ---------AAAAAAAAAD ---------AAAAAAAAAA --------AAAAAAAAAAA --------AAAAAAAAAAA --------AAAAAAAAAAA --------AAAAAAAAAAA --------AAAAAAAAA-- --------AAAAAAAAA-- --------AAAAAAAAB-- --------AAAAAAAAA-- --------AAAAAAAAA-- --------AAAAAAAAA-- --------AAAAAAAAA-- --------AAAAAAAAA-- --------AAAAAAAAA-- --------AAAAAAAAA-- --------AAAAAAA---- --------AAAAAA----- ---------AAAA------ ------------------- ------------------- 
---------AAA------- ---------AAAAA----- ---------AAAAAA---- ---------AAAAAAAA-- --------AAAAAAAAAAA --------AAAAAAAAAAA --------AAAAAAAAAAA ---------AAAAAAAAAD ---------AAAAAAAAAD --------AAAAAAAAAAA --------AAAAAAAAAAA --------AAAAAAAAAAA --------AAAAAAAAAAA --------AAAAAAAAA-- --------AAAAAAAAA-- --------AAAAAAAAB-- --------AAAAAAAAC-- --------AAAAAAAAA-- --------AAAAAAAAA-- --------AAAAAAAAA-- --------AAAAAAAAA-- --------AAAAAAAAA-- --------AAAAAAAAA-- --------AAAAAAA---- --------AAAAAA----- ---------AAAA------ ------------------- ------------------- 
---------AAA------- ---------AAAAA----- ---------AAAAAA---- ---------AAAAAAAA-- --------AAAAAAAAAAA --------AAAAAAAAAAA --------AAAAAAAAAAA ---------AAAAAAAAAG ---------AAAAAAAAAD --------AAAAAAAAAAD --------AAAAAAAAAAA --------AAAAAAAAAAA --------AAAAAAAAAAA --------AAAAAAAAA-- --------AAAAAAAAA-- --------AAAAAAAAB-- --------AAAAAAAAC-- --------AAAAAAAAC-- --------AAAAAAAAA-- --------AAAAAAAAA-- --------AAAAAAAAA-- --------AAAAAAAAA-- --------AAAAAAAAA-- --------AAAAAAA---- --------AAAAAA----- ---------AAAA------ ------------------- ------------------- 
---------AAA------- ---------AAAAA----- ---------AAAAAA---- ---------AAAAAAAA-- --------AAAAAAAAAAA --------AAAAAAAAAAA --------AAAAAAAAAAA ---------AAAAAAAAAD ---------AAAAAAAAAD --------AAAAAAAAAAD --------AAAAAAAAAAD --------AAAAAAAAAAA --------AAAAAAAAAAA --------AAAAAAAAA-- --------AAAAAAAAA-- --------AAAAAAAAB-- --------AAAAAAAAC-- --------AAAAAAAAC-- --------AAAAAAAAC-- --------AAAAAAAAA-- --------AAAAAAAAA-- --------AAAAAAAAA-- --------AAAAAAAAA-- --------AAAAAAA---- --------AAAAAA----- ---------AAAA------ ------------------- ------------------- 
---------AAA------- ---------AAAAA----- ---------AAAAAA---- ---------AAAAAAAA-- --------AAAAAAAAAAA --------AAAAAAAAAAF --------AAAAAAAAAAF ---------AAAAAAAAAD ---------AAAAAAAAAI --------AAAAAAAAAAD --------AAAAAAAAAAK --------AAAAAAAAAAD --------AAAAAAAAAAA --------AAAAAAAAA-- --------AAAAAAAAA-- --------AAAAAAAAB-- --------AAAAAAAAC-- --------AAAAAAAAC-- --------AAAAAAAAC-- --------AAAAAAAAC-- --------AAAAAAAAA-- --------AAAAAAAAA-- --------AAAAAAAAA-- --------AAAAAAA---- --------AAAAAA----- ---------AAAA------ ------------------- ------------------- 
---------AAA------- ---------AAAAA----- ---------AAAAAA---- ---------AAAAAAAA-- --------AAAAAAAAAAA --------AAAAAAAAAAF --------AAAAAAAAAAF ---------AAAAAAAAAD ---------AAAAAAAAAD --------AAAAAAAAAAD --------AAAAAAAAAAD --------AAAAAAAAAAD --------AAAAAAAAAAA --------AAAAAAAAA-- --------AAAAAAAAA-- --------AAAAAAAAB-- --------AAAAAAAAC-- --------AAAAAAAAC-- --------AAAAAAAAC-- --------AAAAAAAAC-- --------AAAAAAAAA-- --------AAAAAAAAA-- --------AAAAAAAAA-- --------AAAAAAA---- --------AAAAAA----- ---------AAAA------ ------------------- ------------------- 
---------AAA------- ---------AAAAA----- ---------AAAAAA---- ---------AAAAAAAA-- --------AAAAAAAAAAA --------AAAAAAAAAAA --------AAAAAAAAAAA ---------AAAAAAAAAD ---------AAAAAAAAAJ --------AAAAAAAAAAD --------AAAAAAAAAAD --------AAAAAAAAAAA --------AAAAAAAAAAA --------AAAAAAAAA-- --------AAAAAAAAA-- --------AAAAAAAAB-- --------AAAAAAAAC-- --------AAAAAAAAC-- --------AAAAAAAAC-- --------AAAAAAAAC-- --------AAAAAAAAB-- --------AAAAAAAAB-- --------AAAAAAAAA-- --------AAAAAAA---- --------AAAAAA----- ---------AAAA------ ------------------- ------------------- 
---------AAA------- ---------AAAAA----- ---------AAAAAA---- ---------AAAAAAAA-- --------AAAAAAAAAAA --------AAAAAAAAAAA --------AAAAAAAAAAA ---------AAAAAAAAAD ---------AAAAAAAAAD --------AAAAAAAAAAD --------AAAAAAAAAAA --------AAAAAAAAAAA --------AAAAAAAAAAA --------AAAAAAAAA-- --------AAAAAAAAA-- --------AAAAAAAAB-- --------AAAAAAAAC-- --------AAAAAAAAC-- --------AAAAAAAAC-- --------AAAAAAAAC-- --------AAAAAAAAB-- --------AAAAAAAAB-- --------AAAAAAAAA-- --------AAAAAAA---- --------AAAAAA----- ---------AAAA------ ------------------- ------------------- 
---------AAA------- ---------AAAAA----- ---------AAAAAA---- ---------AAAAAAAA-- --------AAAAAAAAAAA --------AAAAAAAAAAA --------AAAAAAAAAAA ---------AAAAAAAAAH ---------AAAAAAAAAD --------AAAAAAAAAAA --------AAAAAAAAAAA --------AAAAAAAAAAA --------AAAAAAAAAAA --------AAAAAAAAA-- --------AAAAAAAAA-- --------AAAAAAAAB-- --------AAAAAAAAC-- --------AAAAAAAAC-- --------AAAAAAAAC-- --------AAAAAAAAA-- --------AAAAAAAAB-- --------AAAAAAAAB-- --------AAAAAAAAA-- --------AAAAAAA---- --------AAAAAA----- ---------AAAA------ ------------------- ------------------- 
---------AAA------- ---------AAAAA----- ---------AAAAAA---- ---------AAAAAAAA-- --------AAAAAAAAAAA --------AAAAAAAAAAA --------AAAAAAAAAAA ---------AAAAAAAAAD ---------AAAAAAAAAA --------AAAAAAAAAAA --------AAAAAAAAAAA --------AAAAAAAAAAA --------AAAAAAAAAAA --------AAAAAAAAA-- --------AAAAAAAAA-- --------AAAAAAAAB-- --------AAAAAAAAA-- --------AAAAAAAAA-- --------AAAAAAAAA-- --------AAAAAAAAA-- --------AAAAAAAAA-- --------AAAAAAAAA-- --------AAAAAAAAA-- --------AAAAAAA---- --------AAAAAA----- ---------AAAA------ ------------------- ------------------- 
---------AAA------- ---------AAAAA----- ---------AAAAAA---- ---------AAAAAAAA-- --------AAAAAAAAAAA --------AAAAAAAAAAA --------AAAAAAAAAAA ---------AAAAAAAAAA ---------AAAAAAAAAA --------AAAAAAAAAAA --------AAAAAAAAAAA --------AAAAAAAAAAA --------AAAAAAAAAAA --------AAAAAAAAA-- --------AAAAAAAAA-- --------AAAAAAAAA-- --------AAAAAAAAA-- --------AAAAAAAAA-- --------AAAAAAAAA-- --------AAAAAAAAA-- --------AAAAAAAAA-- --------AAAAAAAAA-- --------AAAAAAAAA-- --------AAAAAAA---- --------AAAAAA----- ---------AAAA------ ------------------- ------------------- 
---------AAA------- ---------AAAAA----- ---------AAAAAA---- ---------AAAAAAAA-- --------AAAAAAAAAAA --------AAAAAAAAAAA --------AAAAAAAAAAA ---------AAAAAAAAAA ---------AAAAAAAAAA --------AAAAAAAAAAA --------AAAAAAAAAAA --------AAAAAAAAAAA --------AAAAAAAAAAA --------AAAAAAAAA-- --------AAAAAAAAA-- --------AAAAAAAAA-- --------AAAAAAAAA-- --------AAAAAAAAA-- --------AAAAAAAAA-- --------AAAAAAAAA-- --------AAAAAAAAA-- --------AAAAAAAAA-- --------AAAAAAAAA-- --------AAAAAAA---- --------AAAAAA----- ---------AAAA------ ------------------- ------------------- 
----AAAAAAAA------- ---AA----AAAAA----- --AA-----AAAAAA---- -AA------AAAAAAAA-- -A------AAAAAAAAAAA -A------AAAAAAAAAAA AA------AAAAAAAAAAA A--------AAAAAAAAAA A--------AAAAAAAAAA A-------AAAAAAAAAAA A-------AAAAAAAAAAA A-------AAAAAAAAAAA A-------AAAAAAAAAAA A-------AAAAAAAAA-- A-------AAAAAAAAA-- A-------AAAAAAAAA-- A-------AAAAAAAAA-- A-------AAAAAAAAA-- A-------AAAAAAAAA-- A-------AAAAAAAAA-- A-------AAAAAAAAA-- AA------AAAAAAAAA-- -A------AAAAAAAAA-- -A------AAAAAAA---- -AA-----AAAAAA----- --AA-----AAAA------ ---AA--AAA--------- ----AAAA----------- 
----AAAAAAAA------- ---AA----AAAAA----- --AA-----AAAAAA---- -AA------AABABABA-- -A-------AAABBBAA-- -A-------AABBABBA-- AA-------AAABBBAA-- A--------AABABABA-- A--------AAAAAAAA-- A--------AAAAAAAA-- A--------AABABABA-- A--------AAABBBAA-- A--------AABBABBA-- A--------AAABBBAA-- A--------AABABABA-- A--------AAAAAAAA-- A--------AAAAAAAA-- A--------AABABABA-- A--------AAABBBAA-- A--------AABBABBA-- A--------AAABBBAA-- AA-------AABABABA-- -A-------AAAAAAAA-- -A-------AAAAAA---- -AA------AAAAA----- --AA-----AAAA------ ---AA--AAA--------- ----AAAA----------- 
