model
size = 10 8 30, scale = 0.05, origin = -y
material 
  colors = A:#FF5900 B:#FFF C:#101010 D:#F1D998 E:#787878 F:#E0E0E0 G:#989898 H:#404040 I:#1F1F1F J:#9191AE K:#40414E L:#535353 M:#575757 N:#000 O:#071 P:#A80000 Q:#393939
voxels
----DD---- ----DD---- ----DD---- ---------- ---------- ---------- ---------- ---------- 
---DDDD--- ---DDDD--- ---DDDD--- ---------- ---------- ---------- ---------- ---------- 
---DDDD--- ---------- ---DDDD--- ---DDDD--- ---------- ---------- ---------- ---------- 
---DDDD--- ---------- ----N----- ---DDDD--- ---------- ---------- ---------- ---------- 
---DDDD--- ---------- ----N----- ---ABDD--- ---AAAA--- ---------- ---------- ---------- 
---AAAA--- --AAAAAA-- --AABAAA-- --ABBBBA-- ---AAAA--- ---------- ---------- ---------- 
---AAAA--- I-ABBBBA-- I-ABBBBA-- --ABBBBA-- ---AAAA--- ---------- ---------- ---------- 
---AAAA--- I-ABBBBA-- IQBBBBBA-- --ABBBBA-- ---AAAA--- ---------- ---------- ---------- 
---AAAA--- --ABBBBA-- --ABBBBA-- --ABBBBA-- ---AAAA--- ---------- ---------- ---------- 
---------- --AAAAAA-- --ABBBBBM- --ABBBBA-- ---APOA--- ---------- ---------- ---------- 
---------- ---GGGGG-- --ABBBBBM- --ABBBBA-- ---AAAA--- ---------- ---------- ---------- 
-CCCCCCC-- -CCCCCCC-- -CCCCCBCCC CCCCCCBCCC CCCCCCBCCC CCC-CCC-CC -CC-----CC --CCCCCCC- 
---------- ---------- ------E--- ------F--- ------E--- ---------- ---------- ---------- 
---------- ---------- ------E--- ------F--- ------E--- ------L--- ---------- ---------- 
---------- ------J--- ------E--- ------F--- ------E--- ---------- ---------- ---------- 
---------- ---------- ------E--- ------H--- ------E--- ------K--- ---------- ---------- 
---------- ------E--- ------E--- ------F--- ------E--- ---------- ---------- ---------- 
---------- ---------- ------E--- ------F--- ------E--- ------E--- ---------- ---------- 
---------- ------L--- ------E--- ------H--- ------E--- ---------- ---------- ---------- 
---------- ---------- ------E--- ------F--- ------E--- ------J--- ---------- ---------- 
---------- ------E--- ------E--- ------F--- ------E--- ---------- ---------- ---------- 
---------- ---------- ------E--- ------H--- ------E--- ------E--- ---------- ---------- 
---------- ------K--- ------E--- ------F--- ------E--- ---------- ---------- ---------- 
---------- ---------- ------E--- ------F--- ------E--- ------E--- ---------- ---------- 
---------- ------E--- ------E--- ------H--- ------E--- ---------- ---------- ---------- 
---------- ---------- ------E--- ------F--- ------E--- ------E--- ---------- ---------- 
---------- ------E--- ------E--- ------F--- ------E--- ---------- ---------- ---------- 
---------- ---------- ------E--- ------H--- ------E--- ------K--- ---------- ---------- 
---------- ------J--- ------E--- ------F--- ------E--- ---------- ---------- ---------- 
---------- ---------- ------E--- ------L--- ---------- ---------- ---------- ---------- 
