model
size = 31 19 10, scale = 0.05, origin = -y
material 
  colors = A:#603838 B:#734747 C:#E4E4E4 D:#161616
voxels
------------------------------- ------------------------------- ------------------------------- ------------------------------- ------------------------------- ------------------------------- ------------------------------- ------------------------------- ------------------------------- ------------------------------- ------------------------------- ------------------------------- ------------------------------- A------------------------------ ------------------------------- ------------------------------- ------------------------------- ------------------------------- ------------------------------- 
----------A-------------------- ----------AAAA----------------- -------------AA---------------- -------------AA---------------- -------------AA---------------- -----------AAAA---------------- -----------AAAA---------------- -----------AAAA---------A------ -----------AAA-----AAAAAA------ -------------------AA---------- -------------------AA---------- ------------------------------- ------------------------------- AA----------------------------- ------------------------------- ------------------------------- ------------------------------- ------------------------------- ------------------------------- 
------------------------------- ------------------------------- ------------------------------- ------------------------------- -------------AA---------------- -----------AAAA---------------- -----------AAAAA--------------- -----------AAAAA--------------- -----------AAAAA---A----------- -----------AAAA----AA---------- -------------------AA---------- ------------------------------- --A---------------------------- -AA---------------------------- ------------------------------- ------------------------------- ------------------------------- ------------------------------- ------------------------------- 
------------------------------- ------------------------------- ------------------------------- ------------------------------- ------------------------------- ------------------------------- ----------AAAAAAAAA------------ ---------AAAAAAAAAAAA---------- --------AAAAAAAAAAAAAA--------- -------AAAAAAAAAAAAAAA--------- ----AAA-AAAAAAAAAAAAAA--------- ---AAA-----------AAAA---------- --AA--------------------------- -AA---------------------------- ------------------------------- ------------------------------- ------------------------------- ------------------------------- ------------------------------- 
------------------------------- ------------------------------- ------------------------------- ------------------------------- ------------------------------- -----------BBBBBBBB------------ ----------ABBBBBBBBBB---------- ---------AAAAAAAAAAAAB--------- --------AAAAAAAAAAAAAB--------- ----AAAAAAAAAAAAAAAAAB--------- ----AAAAAAAAAAAAAAAAAB--------- --AAAAA----AAAAAAAAAAA--------- --AA---------AA----AA---------- ------------------------------- ------------------------------- ------------------------------- ------------------------------- ------------------------------- ------------------------------- 
------------------------------- ------------------------------- ------------------------------- ------------------------------- ------------------------------- ----------BBBBBBBBB------------ ---------BBBBBBBBBBBB---------- --------BBBAAAAAAAAAAB--------- ------BBBBBAAAAAAAAAAB--------- -----BBBBBBAAAAAAAAAAB--------- ----AAAAAAAAAAAAAAAAAB--------- ---AAAAA--AAAAAAAAAAAAB-------- ---A--------AAAA--AAAA--------- -------------------AAAAAAAAAAA- --------------------AAAAA------ --------------------AAAAAAAAAAA --------------------AAAACAAAAA- ---------------------AABBBAAA-- ----------------------AAAAA---- 
------------------------------- ------------------------------- ------------------------------- ------------------------------- ------------------------------- -----------BBBBBBBB------------ ----------ABBBBBBBBBB---------- ---------AAAAAAAAAAAAB--------- --------AAAAAAAAAAAAAB--------- ------AAAAAAAAAAAAAAAB--------- ------AAAAAAAAAAAAAAAB--------- ------A----AAAAAAAAAAAB-------- -------------AA----AAABB------- --------------------AABBAAAAAA- --------------------AAAD------- --------------------AAAAAAAAAAA --------------------AAAAAAAAAAA ---------------------AAAAAAAA-- ----------------------AAAAA---- 
------------------------------- ------------------------------- ------------------------------- ------------------------------- ------------------------------- ------------------------------- ----------AAAAAAAAA------------ ----------AAAAAAAAAAA---------- ---------AAAAAAAAAAAAA--------- --------AAAAAAAAAAAAAA--------- -------AAAAAAAAAAAAAAA--------- -----------------AAAA---------- ------------------------------- ----------------------AAAAAAAA- --------------------AAAAA------ --------------------AAAAAAAAAAA --------------------AAAACAAAAA- ---------------------AABBBAAA-- ----------------------AAAAA---- 
------------------------------- ------------------------------- ------------------------------- ---------------AA-------------- ---------------AA-------------- -------------AAAA-------------- -----------AAAAAA-------------- -----------AAAAAA-------------- -----------AAAAAA---A---------- ------------AAA-----AA--------- --------------------AA--------- ------------------------------- ------------------------------- ------------------------------- ------------------------------- ------------------------------- ------------------------------- ------------------------------- ------------------------------- 
----------------AA------------- ----------------A-------------- ----------------A-------------- ---------------AA-------------- ---------------AA-------------- -------------AAAA-------------- -------------AAAA-------------- -------------AAAA--------A----- --------------AAA---AAAAAA----- --------------------AA--------- --------------------AA--------- ------------------------------- ------------------------------- ------------------------------- ------------------------------- ------------------------------- ------------------------------- ------------------------------- ------------------------------- 
