model
size = 27 18 11, scale = 0.05, origin = -y
material 
  colors = A:#933 B:#111 C:#EEE D:#AAA
voxels
-----BBBBBBBBBBBBBBBBBBBB-- -----AAAAAAAAAAAAAAAAAAAA-- -----CCCCCCCCCCCCCCCCCCCC-- -----DDDDDDDDDDDDDDDDDDDD-- -----AAAAAAAAAAACCCAAAAAA-- -------AAAAAAACCCBCCCAAAA-- ----------AAACCCBBBCCCAAA-- -------------CCBBBBBCCAAA-- -------------CCCBBBCCCAAC-- --------------CCCBCCC--AC-- ----------------CCC-----C-- --------------------------- --------------------------- --------------------------- --------------------------- --------------------------- --------------------------- --------------------------- 
--BBBBBBBBBBBBBBBBBBBBBBBB- --AAA--------------------A- --CCC--------------------C- --DDD--------------------D- --AAAA-------------------A- -----AA-AAAAAAAAAAAAAAAAAA- -----AAAAA---------------A- --------AAAAACCCBBBBBBCAAA- ----------AAACCCCBCCCBBBAC- ------------AACCCCCCCAACCC- --------------AACCCAAAAACC- ----------------AAAAABAAAC- -------------------ABABAAA- -------------------AABABAA- -------------------ABABABA- -------------------AAAAAAA- -------------------AAA----- --------------------------- 
-BBBBBBBBBBBBBBBBBBBBBBBBBB -A-----------------------AA -C-----------------------CC -D-----------------------DD -AA-A--------------------AA --AAA--------------------AA -----AC------------------AA -----CCC-----------------AA --------BA---------------AA ----------BAAA-----------C- ------------BA-----------C- --------------AB---------C- ----------------AAA------A- ----------------AAA------A- -----------------BA------A- -----------------BA------A- -----------------AAA--BBBB- -----------------AABBBB---- 
BBBBBBBBBBBBBBBBBBBBBBBBBBB A------------------------AA C------------------------CC D------------------------DD AA-----------------------AA -AA----------------------AA ---CC--------------------AC -----CDC-----------------AA --------BC---------------AA ----------BC-------------CA ------------BC-----------CC --------------B-----------C ---------------B----------C ---------------BB---------A -----------------B--------A -----------------B--------A -----------------C-------BB -----------------C--------- 
BBBBBBBBBBBBBBBBBBBBBBBBBBB A------------------------AA C------------------------CC D------------------------DD A------------------------AA AA-----------------------AC -ACDC--------------------AC -----DCC-----------------AC -------DBBC--------------AA ---------BCB-------------CA -----------BCC-----------CC -------------BC-----------B --------------CB----------C ---------------BC---------A ----------------CB--------A ----------------B---------A ----------------A---------B ----------------A---------- 
BBBBBBBBBBBBBBBBBBBBBBBBBBB A------------------------AA C------------------------CC D------------------------DD A------------------------AC AA-----------------------AC -ACCD--------------------AB -----CDC-----------------AC -------DBBC--------------AC ---------BCB-------------CA -----------BCC-----------CC -------------CC-----------B --------------CB----------C ---------------BC---------A ----------------C---------A ----------------B---------A ----------------A---------B ----------------A---------- 
BBBBBBBBBBBBBBBBBBBBBBBBBBB A------------------------AA C------------------------CC D------------------------DD A------------------------AA AA-----------------------AC -ACDC--------------------AC -----DCC-----------------AC -------DBBC--------------AA ---------BCB-------------CA -----------BCC-----------CC -------------BC-----------B --------------CB----------C ---------------BC---------A ----------------CB--------A ----------------B---------A ----------------A---------B ----------------A---------- 
BBBBBBBBBBBBBBBBBBBBBBBBBBB A------------------------AA C------------------------CC D------------------------DD AA-----------------------AA -AA----------------------AA ---CC--------------------AC -----CDC-----------------AA --------BC---------------AA ----------BC-------------CA ------------BC-----------CC --------------B-----------C ---------------B----------C ---------------BB---------A -----------------B--------A -----------------B--------A -----------------C-------BB -----------------C--------- 
-BBBBBBBBBBBBBBBBBBBBBBBBBB -A-----------------------AA -C-----------------------CC -D-----------------------DD -AA-A--------------------AA --AAA--------------------AA -----A-------------------AA -----CCC-----------------AA --------BA---------------AA ----------BA-------------C- ------------BAA----------C- --------------AB---------C- ----------------A--------A- ----------------AAA------A- -----------------BA------A- -----------------BA------A- -----------------AAA--BBBB- -----------------AABBBBB--- 
--BBBBBBBBBBBBBBBBBBBBBBBB- --AAA--------------------A- --CCC--------------------C- --DDD--------------------D- --AAAA-------------------A- -----AA-AAAAAAAAAAAAAAAAAA- -----AAAAAAAAAAAAAAAAAAAAA- --------AAAAACCCBBBCCCC--A- ----------AAACCCCCCCCCCBBA- ------------AACCCCCCCAACCC- --------------AACCCAAAAACC- ----------------AAAAABAAAC- ----------------AAAABABAAA- -------------------AABABAA- -------------------ABABABA- -------------------AAAAAAA- -------------------AAA----- --------------------------- 
-----BBBBBBBBBBBBBBBBBBBB-- -----AAAAAAAAAAAAAAAAAAAA-- -----CCCCCCCCCCCCCCCCCCCC-- -----DDDDDDDDDDDDDDDDDDDD-- -----AAAAAAAAAAACCCAAAAAA-- -------AAAAAAACCCBCCCAAAA-- ----------AAACCCBBBCCCAAA-- -------------CCBBBBBCCAAA-- -------------CCCBBBCCCAAC-- --------------CCCBCCC--AC-- ----------------CCC-----C-- --------------------------- --------------------------- --------------------------- --------------------------- --------------------------- --------------------------- --------------------------- 
