model
size = 30 16 32, scale = 0.05, origin = -y
material 
  colors = A:#EEE B:#E00
voxels
6-18A12-18A431-20A10-20A429-6(22A8-22A428-)22A8-22A10-18A12-2A14B2A12-2AB2A2(3BA)BAB2A12-2ABA4BA3B2(AB)2A12-2AB2A3BA3B3AB2A12-2ABA4BA3B2(AB)2A12-2(2AB)5A2(BA)B2A12-2A14B2A2(12-18A)130-22A8-22A10-2(18A12-)6(2A14B2A12-)18A12-2(18A130-22A8-22A10-9(18A12-))18A130-6(6A10-6A8-)5(22A8-)22A128-6(6A10-6A8-)5(22A8-)22A126-2(6(6A14-6A4-)26A4-26A6-3(22A8-)22A12-14A16-14A70-)6(4A18-4A4-)26A4-26A6-3(22A8-)22A12-14A16-14A70-6(4A18-4A4-)26A4-26A6-3(3(22A8-)22A12-14A16-14A68-4A5(22-8A)22-64A4-)2(3(22A8-)22A12-14A16-14A22-2A28-2A14-4A5(22-8A)22-64A4-)5(3(22A8-)22A12-14A16-14A68-4A5(22-8A)22-64A4-)3(22A8-)22A12-14A16-14A70-2(6(4A18-4A4-)26A4-26A6-3(22A8-)22A126-)6(6A14-6A4-)26A4-26A6-3(22A8-)22A126-7(26A4-)26A6-3(22A8-)22A124-
