model
size = 23 12 29, scale = 0.05, origin = -y
material 
  colors = A:#111 B:#444 C:#222 D:#CB4042 E:#AB3B3A F:#C73E3A
voxels
-------AAAAAAAAA------- -------AAAAAAAAA------- ----------------------- ----------------------- ----------------------- ----------------------- ----------------------- ----------------------- ----------------------- ----------------------- ----------------------- ----------------------- 
------AADEEEEEDAA------ ------AAACCCCCAAA------ ----------------------- ----------------------- ----------------------- ----------------------- ----------------------- ----------------------- ----------------------- ----------------------- ----------------------- ----------------------- 
-----ADDEDDDDDEDDA----- -----AAACAAAAACAAA----- ----------------------- ----------------------- ----------------------- ----------------------- ----------------------- ----------------------- ----------------------- ----------------------- ----------------------- ----------------------- 
----ADDEDEEEEEDEDDA---- ----AAACACCCCCACAAA---- ----------------------- ----------------------- ----------------------- ----------------------- ----------------------- ----------------------- ----------------------- ----------------------- ----------------------- ----------------------- 
---ADDEDEDDDDDEDEDDA--- ---AAACACAAAAACACAAA--- ----------------------- ----------------------- ----------------------- ----------------------- ----------------------- ----------------------- ----------------------- ----------------------- ----------------------- ----------------------- 
---ADEDEDEEEEEDEDEDA--- ---AACACACCCCCACACAA--- ----------------------- ----------------------- ----------------------- ----------------------- ----------------------- ----------------------- ----------------------- ----------------------- ----------------------- ----------------------- 
--ADEDEDEDDDDDEDEDEDA-- --AACACACAAAAACACACAA-- ----------------------- ----------------------- ----------------------- ----------------------- ----------------------- ----------------------- ----------------------- ----------------------- ----------------------- ----------------------- 
--AEDEDEDDEEEDDEDEDEA-- --ACACACAACCCAACACACA-- ----------------------- ----------------------- ----------------------- ----------------------- ----------------------- ----------------------- ----------------------- ----------------------- ----------------------- ----------------------- 
--AEDEDEDEDDDEDEDEDEA-- --ACACAAAAAAAAAAACACA-- ------AAAFFAAFFFA------ ------AAAAAFAFAFA------ ------AAAFAFAFFFA------ ------AAFFFAFAAAA------ ------AAFAFAFAFAA------ -------AFFFAAFFA------- --------AAAAAAA-------- ----------------------- ----------------------- ----------------------- 
--AEDEDBBBBBBBBBDEDEA-- --ACAAABBBBBBBBBAAACA-- ----AAAAAAABAAAAAAA---- ----AAAAAAABAAAAAAA---- -----AAAAAABAAAAAA----- -----AAAAAABAAAAAA----- -----AAAAAABAAAAAA----- ------AAAAAAAAAAA------ -------AAAACAAAA------- ----------------------- ----------------------- ----------------------- 
--AEDBB---------BBDEA-- --AAABB---------BBAAA-- ---AAA-----------AAA--- ---AAA-----------AAA--- ----AA-----------AA---- ----AA-----------AA---- ----AAA---------AAA---- -----AAAAAABAAAAAA----- ------AAAAAAAAAAA------ ----------ACA---------- ----------------------- ----------------------- 
--CBBB-----------BBBC-- --CABB-----------BBAC-- --CAAB-----------BAAC-- --CAAB-----------BAAC-- ---CAB-----------BAC--- ---CAB-----------BAC--- ----CAA---------AAC---- -----CAA-------AAC----- ------AAAAABAAAAA------ --------AAACAAA-------- ----------------------- ----------------------- 
--AB---------------BA-- --AB---------------BA-- --A-----------------A-- --A-----------------A-- ---A---------------A--- ---A---------------A--- ----AAB---------BAA---- ----ACBA-------ABCA---- ------CAAAABAAAAC------ --------AAACAAA-------- ----------------------- ----------------------- 
-AAB---------------BAA- -AAB---------------BAA- -AA-----------------AA- -AA-----------------AA- --A----------------AA-- --A----------------AA-- ---A---------------A--- ---AAA-----------AAA--- -----AABAAABAAABAA----- -------CAAACAAAC------- ----------------------- ----------------------- 
-AB-----------------BA- -AB-----------------BA- -A-------------------A- -A-------------------A- --A-----------------A-- --A-----------------A-- ---A---------------A--- ---AAA-----------AAA--- -----AAABA---ABAAA----- -------ACAABAACA------- ----------ACA---------- ----------------------- 
AAB-----------------BAA AAB-----------------BAA AA-------------------AA -A-------------------A- -AA-----------------AA- --A-----------------A-- --AA---------------AA-- ---AAA-----------AAA--- ----AAAA-------AAAA---- ------AAABABABAAA------ ---------CACAC--------- ----------------------- 
AB-------------------BA AB-------------------BA AA-------------------AA AA-------------------AA -AA-----------------AA- -AA-----------------AA- --AA---------------AA-- --AAAA-----------AAAA-- ----AAAA-------AAAA---- ------AAAABBBAAAA------ --------AAAAAAA-------- ----------FEF---------- 
CB-------------------BC CB-------------------BC CB-------------------BC CB-------------------BC -CB-----------------BC- -CB-----------------BC- --CB---------------BC-- --CCBB-----------BBCC-- ----CCBB-------BBCC---- ------CCBBBBBBBCC------ --------CCAAACC-------- ----------EEE---------- 
AB-------------------BA AB-------------------BA AA-------------------AA AA-------------------AA -AA-----------------AA- -AA-----------------AA- --AA---------------AA-- --AAAA-----------AAAA-- ----AAAA-------AAAA---- ------AAAABBBAAAA------ --------AAAAAAA-------- ----------FEF---------- 
AB-------------------BA AB-------------------BA AA-------------------AA AA-------------------AA -AA-----------------AA- -AA-----------------AA- --AA---------------AA-- --AAAA-----------AAAA-- ----AAAAAB---BAAAAA---- ------AAABABABAAA------ ---------CACAC--------- ----------------------- 
AB-------------------BA AB-------------------BA AA-------------------AA -A-------------------A- -AA-----------------AA- --A-----------------A-- --AA---------------AA-- ---AAA-----------AAA--- -----AAABA---ABAAA----- -------ACAABAACA------- ----------ACA---------- ----------------------- 
AAB-----------------BAA AAB-----------------BAA -A-------------------A- -A-------------------A- --A-----------------A-- --A-----------------A-- ---A---------------A--- ---AAAAB-------BAAAA--- -----AAAAAABAAABAA----- -------CAAACAAAC------- ----------------------- ----------------------- 
-AB-----------------BA- -AB-----------------BA- -A-------------------A- -A-------------------A- --A-----------------A-- --A-----------------A-- ---AAAB---------BAAA--- ---AAABA-------ABAAA--- -----AAAAAABAAAAAA----- -------CAAACAAAC------- ----------------------- ----------------------- 
-AAB---------------BAA- -AAB---------------BAA- -AA-----------------AA- --A-----------------A-- --A-----------------A-- ---AAB-----------BAA--- ---AABA---------ABAA--- ----AAAA-------AAAA---- ------CAAAABAAAAC------ ---------AACAA--------- ----------------------- ----------------------- 
--ABB-------------BBA-- --ABB-------------BBA-- --AAB-------------BAA-- --AAB-------------BAA-- ---CB-------------BC--- ---CBA-----------ABC--- ----CAA---------AAC---- -----CAAAAABAAAAAC----- -------AAAACAAAA------- ----------------------- ----------------------- ----------------------- 
--CAB-------------BAC-- --CAB-------------BAC-- --CAA-------------AAC-- --CCA-------------ACC-- ----A-------------A---- ----AA-----------AA---- -----AA---------AA----- -------AAAABAAAA------- ---------AACAA--------- ----------------------- ----------------------- ----------------------- 
---AABB---------BBAA--- ---AABB---------BBAA--- ---AAA-----------AAA--- ---AAA-----------AAA--- -----A-----------A----- -----A-----------A----- ------AAAAABAAAAA------ ---------AACAA--------- ----------------------- ----------------------- ----------------------- ----------------------- 
----AAABB-----BBAAA---- ----AAABB-----BBAAA---- ----AAAAB-----BAAAA---- ----AAAAAB---BAAAAA---- ------AAAABBBAAAA------ ------AAAAABAAAAA------ ---------AACAA--------- ----------------------- ----------------------- ----------------------- ----------------------- ----------------------- 
------AAFCFCFCFAA------ ------AAFFFFFFFAA------ ------AAA-----AAA------ ------AAAA---AAAA------ --------AAACAAA-------- ---------AACAA--------- ----------------------- ----------------------- ----------------------- ----------------------- ----------------------- ----------------------- 
