model
size = 30 14 12, scale = 0.05, origin = -y
material 
  colors = A:#77969A B:#6699A1 C:#EEE D:#F75C2F E:#DDD F:#C7802D G:#E2943B H:#9B6E23 I:#EFBB24 J:#255359 K:#86A697 L:#D9AB42 M:#90B44B N:#B481BB O:#B1B479
voxels
----ECECECECECECECECECECE----- ---CECECECECECECECECECECEC---- ---CECECECECECECECECECECEC---- ----AAAAAAAAAAAAAAAAAAA------- -----BB---------AAAA---------- ------------------------------ ------------------------------ ------------------------------ ------------I----------------- ------------C----------------- ------------C----------------- ------------------------------ ------------------------------ ------------------------------ 
--ECCGFGFGFGFGFGFGFGFGFGCCE--- --ECDDDDDDDDDDDDDDDDDDDDDCEC-- --ECCCCCCCCCCCCCCCCCCCCCCCEC-- ---AAAAAAAAAAAAAAAAAAAALI----- ---BBBB-D----AAAAAAAA--------- ---AABD-D-D------BBB---------- ---AAAD-D-D------------------- ----BADDDDDBB----------------- ------D-D-D-B----------------- -------D-D-------------------- ------D---D-C----------------- ------------C----------------- ------------------------------ ------------------------------ 
--CFGFGFGFGHHHHHHHGHHFGFGFCCE- -CCDDDDDDDDDDDDDDDDDDDDDDDDCE- -CCAAAAAAAAAAAAAAAAAAAAAAAAAE- --AAAAAAAAAAAAAAAAAAAAAAIIII-- --BAAAAAABBBBAAAAAAAABBLI----- --AAAAAAAAAABBBBBAAABB-------- --AAAAABBAAAAAAAAB------------ --BBAAAAAAAAAAAB-------------- --BBBBBAAAAAAB---------------- ---BBBBBBBAA------------------ -----BBBBBBA------------------ ---------BBAC----------------- ----------AA------------------ ------------------------------ 
-CCGFGFGFGFHHHHHHGFHHGFGFGFGC- CCDBBBBBBBBBBBBBBBBBBBBBBBBBC- CCA-------------------------C- -AA------------------------I-- -BA---------------------III--- -AA-----------------AJBL------ -AA---------------JJC--------- -B--------------JJC----------- -B---------AAAAJC------------- -----------AAJJ--------------- -----------KAJC--------------- -----------KAJ---------------- -----------KJ----------------- ------------------------------ 
CCGFGFGFGFGFGFHHGFHHGFGFGFGFCE CDBBBBDBBDBDBDDDBDDDBDDBDBDBCE CA--------------------------CE AA-------------------------AI- BB----------------------IIII-- AA------------------AAJLI----- BA----------------AAAC-------- -B--------------AAAC---------- -B---------KAAAAAC------------ -B---------AAAAC-------------- -----------KAAA--------------- -----------MAAC--------------- -----------KAA---------------- -----------AA----------------- 
CGFGFGFGFGHHHHHHHHHGFGFGFGFGFE CDBDDBDBDDBDBBBDBBBDBDBBDDDBDE CA--------------------------CE IA-------------------------AI- IB----------------------IIII-- IA------------------AAJLI----- IA----------------AAAC-------- IA--------------AAAC---------- -B---------OAAAAAC------------ -B---------KAAAC-------------- -----------KAAA--------------- -----------KAAC--------------- -----------KAA---------------- -----------NA----------------- 
CFGFGFGFGFHHHHHHHHHFGFGFGFGFGE CDBDDBDDBDBBBDDBBDDBBDBBDBDBDE CA--------------------------CE IA-------------------------AI- IB----------------------IIII-- IA------------------AAJLI----- IA----------------AAAC-------- IA--------------AAAC---------- -B---------OAAAAAC------------ -B---------KAAAC-------------- -----------KAAA--------------- -----------KAAC--------------- -----------KAA---------------- -----------NA----------------- 
CCFGFGFGFGFGFGHHFGHHFGFGFGFGCE CDBBBBDBBDBDBDDDBDDDBDBBDDDBCE CA--------------------------CE AA-------------------------AI- BB----------------------IIII-- AA------------------AAJLI----- BA----------------AAAC-------- -B--------------AAAC---------- -B---------KAAAAAC------------ -B---------AAAAC-------------- -----------KAAA--------------- -----------MAAC--------------- -----------KAA---------------- -----------AA----------------- 
-CCFGFGFGFGHHHHHHFGHHFGFGFGFC- CCDBBBBBBBBBBBBBBBBBBBBBBBBBC- CCA-------------------------C- -AA------------------------I-- -BA---------------------III--- -AA-----------------AJBL------ -AA---------------JJC--------- -B--------------JJC----------- -B---------AAAAJC------------- -----------AAJJ--------------- -----------KAJC--------------- -----------KAJ---------------- -----------KJ----------------- ------------------------------ 
--CGFGFGFGFHHHHHHHFHHGFGFGCCE- -CCDDDDDDDDDDDDDDDDDDDDDDDDCE- -CCAAAAAAAAAAAAAAAAAAAAAAAAAE- --AAAAAAAAAAAAAAAAAAAAAAIIII-- --BAAAAAABBBBBAAAAAAABBLI----- --AAAAAAAAAABBBBBBAABB-------- --AAAAABAAAAAAAAAB------------ --BBAAAAAAAAAAAB-------------- --BBBAABABAAAB---------------- ---BBBBABABAA----------------- -----BABBBAA------------------ ---------BBAC----------------- ----------AA------------------ ------------------------------ 
--ECCFGFGFGFGFGFGFGFGFGFCCE--- --ECDDDDDDDDDDDDDDDDDDDDDCEC-- --ECCCCCCCCCCCCCCCCCCCCCCCEC-- ---AAAAAAAAAAAAAAAAAAAALI----- ---BBBB-D----AAAAAAAA--------- ---AABD-D-D------BBB---------- ---AAAD-D-D------------------- ----BADDDDDBB----------------- ------D-D-D-B----------------- -------D-D-------------------- ------D---D-C----------------- ------------C----------------- ------------------------------ ------------------------------ 
----ECECECECECECECECECECE----- ---CECECECECECECECECECECEC---- ---CECECECECECECECECECECEC---- ----AAAAAAAAAAAAAAAAAAA------- ----------------AAAA---------- ------------------------------ ------------------------------ ------------------------------ ------------I----------------- ------------C----------------- ------------C----------------- ------------------------------ ------------------------------ ------------------------------ 
