model
size = 30 27 9, scale = 0.05, origin = -y
material 
  colors = A:#AAA B:#5D5D5D C:#313131 D:#91989F E:#777 F:#111 G:#EEE H:#C4E0E4 I:#BBB J:#E83015 K:#FFFFFB
voxels
------------------------------ ---BBBBB--------------BBBBB--- --BB---BB------------BB---BB-- -BB-----BB----------BB-----BB- -B-------B----------B-------B- -B-------B----------B-------B- -B-------B----------B-------B- -BB-----BB----------BB-----BB- --BB---BB------------BB---BB-- ---BBBBB--------------BBBBB--- ------------------------------ ------------------------------ ------------------------------ ------------------------------ ------------------------------ ------------------------------ ------------------------------ ------------------------------ ------------------------------ ------------------------------ ------------------------------ ------------------------------ ------------------------------ ------------------------------ ------------------------------ ------------------------------ ------------------------------ 
------------------------------ ---BBBBB--------------BBBBB--- --BBCBCBB---E-E-EE---BBCBCBB-- -BBCBCBCBB----------BBCBCBCBB- -BCBCBCBCB----------BCBCBCBCB- -BBCBCBCBB----------BBCBCBCBB- -BCBCBCBCB----------BCBCBCBCB- -BBCBCBCBB----------BBCBCBCBB- --BBCBCBB------------BBCBCBB-- ---BBBBB--------------BBBBB--- --B------------------------B-- -B-B--------G-G-G-J-------B-B- --B------------------------B-- ------------------------------ ------------------------------ ------------------------------ ------------------------------ ------------------------------ ------------------------------ ------------------------------ ------------------------------ ------------------------------ ------------------------------ ------------------------------ ------------------------------ ------------------------------ ------------------------------ 
---AAAAAAAAAAAAAAAAAAAAAAAA--- --AAAAAAAAABBBBBBBBAAAAAAAAA-- -AAAAAAAAAABBBBBBBBAAAAAAAAAA- AAAAAAAAAAABBBBBBBBAAAAAAAAAAA AAAAAAAAAAAB------BAAAAAAAAAAA AAAAAAAAAAAB------BAAAAAAAAAAA AAAAAAAAAAAB------BAAAAAAAAAAA AAAAAAAAAAABBBBBBBBAAAAAAAAAAA AAAAAAAAAAAB-B--B-BAAAAAAAAAAA AAAAAAAAAAABBBBBBBBAAAAAAAAAAA AAAAAAAAAAAAAAAAAAAAAAAAAAAAAA AABAABBDBBDBBDBBBBBDBBDBBAABAA AAAAABDBBDBBDBBDBBDBBDBBDAAAAA -AAAAA-AA-AA-AA-AA-AA-AA-AAAA- ------------------------------ ------------------------------ ------------------------------ ------------------------------ ------------------------------ ------------------------------ ------------------------------ ------------------------------ ------------------------------ ------------------------------ ------------------------------ ------------------------------ ------------------------------ 
-AAA----------------------AAA- AAAAFFF-FFF-FFF-FFF----FFBAAAA AAAAAAAAAAAAAAAAAAAAAAAAAAAAAA AAAAAAAAAAAAAAAAAAAAAAAAAAAAAA AAAAAAAAAAAAHHHHHHAAAAAAAAAAAA AAAAAAAAAAAAHKFFKHAAAAAAAAAAAA AAAAAAAAAAAAHHHHHHAAAAAAAAAAAA AAAAAAAAAAAAAAAAAAAAAAAAAAAAAA AAAAAAAAAAAAIEIIEIAAAAAAAAAAAA AAAAAAAAAAAAAAAAAAAAAAAAAAAAAA AAAAAAAAAAAAAAAAAAAAAAAAAAAAAA AAAAAAAAAAAAAAAAAAAAAAAAAAAAAA AAAAAAEEEEEEEEEEEEEEEEEEEAAAAA AAAAAA-------------------AAAAA ------------------------------ ------------------------------ ------------------------------ ------------------------------ ------------------------------ ------------------------------ ------------------------------ ------------------------------ ------------------------------ ------------------------------ ------------------------------ ------------------------------ ------------------------------ 
AA-A----------------------A-AA AAEAF-F-F-F-F-F-F-F-FFFFF-AEAA -CAAAAAAAAAAAAAAAAAAAAAAAAAAC- -BAAAAAAAAAAAAAAAAAAAAAAAAAAB- -CAAAAAAAAAAAAAAAAAAAAAAAAAAC- -BAAAAAAAAAAAAAAAAAAAAAAAAAAB- AAAAAAAAAAAAAAAAAAAAAAAAAAAAAA AAAAAAAAAAAAAAAAAAAAAAAAAAAAAA -CAAAAAAAAAAAAAAAAAAAAAAAAAAC- -BAAAAAAAAAAAAAAAAAAAAAAAAAAB- -CAAAAAAAAAAAAAAAAAAAAAAAAAAC- -BAAAAAAAAAAAAAAAAAAAAAAAAAAB- AAAAAAAAAAAAAAAAAAAAAAAAAAAAAA AAAAAAAAAAAAAAAAAAAAAAAAAAAAAA --BBB--------------------BBB-- ------------------------------ ------------------------------ ------------------------------ ------------------------------ ------------------------------ ------------------------------ ------------------------------ ------------------------------ ------------------------------ ------------------------------ ------------------------------ ------------------------------ 
AAAAF---------------------AAAA -CAAF-FFF-FFF-FFF-FFF--FFBAAC- AAAAAAAAAAAAAAAAAAAAAAAAAAAAAA AAAAAAAAAAAAAAAAAAAAAAAAAAAAAA AAAAAAAAAAAAAAAAAAAAAAAAAAAAAA AAAAAAAAAAAAAAAAAAAAAAAAAAAAAA -BAAAAAAAAAAAAAAAAAAAAAAAAAAB- -CAAAAAAAAAAAAAAAAAAAAAAAAAAC- AAAAAAAAAAAAAAAAAAAAAAAAAAAAAA AAAAAAAAAAAAAAAAAAAAAAAAAAAAAA AAAAAAAAAAAAAAAAAAAAAAAAAAAAAA AAAAAAAAAAAAAAAAAAAAAAAAAAAAAA -BAAAAGGGGGGGGJGGGGGGGGGAAAAB- AAAEAA------------------AAEAAA --BDB--------------------BDB-- ---D----------------------D--- ---D----------------------D--- ---DDDDDDDDDDDDDDDDDDDDDDDD--- ------------------------------ ------------------------------ ------------------------------ ------------------------------ ------------------------------ ------------------------------ ------------------------------ ------------------------------ ------------------------------ 
AA-AFAAAAAAAAAAAAAAAAAAAAAA-AA AAEAAAAAAAAAAAAAAAAAAAAAAAAEAA -CAAAAAAAAAAAAAAAAAAAAAAAAAAC- -BAAAAAAAAAAAAAAAAAAAAAAAAAAB- -CAAAAAAAAAAAAAAAAAAAAAAAAAAC- -BAAAAAAAAAAAAAAAAAAAAAAAAAAB- AAAAAAAAAAAAAAAAAAAAAAAAAAAAAA AAAAAAAAAAAAAAAAAAAAAAAAAAAAAA -CAAAAAAAAAAAAAAAAAAAAAAAAAAC- -BAAAAAAAAAAAAAAAAAAAAAAAAAAB- -CAAAAAAAAAAAAAAAAAAAAAAAAAAC- -BAAAAAAAAAAAAAAAAAAAAAAAAAAB- AAAAAAGCGCGCGCJCGCGCGCGCAAAAAA AAA-AA------------------AA-AAA --B-B--------------------B-B-- ------------------------------ ------------------------------ ------------------------------ ------------------------------ ------------------------------ ------------------------------ ------------------------------ ------------------------------ ------------------------------ ------------------------------ ------------------------------ ------------------------------ 
-AAAF---------------------AAA- AAAAAAAAAAAAAAAAAAAAAAAAAAAAAA AAEAAAAAAAAAAAAAAAAAAAAAAAAEAA AAAAAAAAAAAAAAAAAAAAAAAAAAAAAA AAAAAAAAAAAAAAAAAAAAAAAAAAAAAA AAAAAAAAAAAAAAAAAAAAAAAAAAAAAA AAAAAAAAAAAAAAAAAAAAAAAAAAAAAA AAAAAAAAAAAAAAAAAAAAAAAAAAAAAA AAAAAAAAAAAAAAAAAAAAAAAAAAAAAA AAAAAAAAAAAAAAAAAAAAAAAAAAAAAA AAAAAAAAAAAAAAAAAAAAAAAAAAAAAA AAEAAAAAAAAAAAAAAAAAAAAAAAAEAA AAAAAAAEEEEEEEEEEEEEEEEEEAAAAA AAA-AAAAAAAAAAAAAAAAAAAAAA-AAA ------------------------------ ------------------------------ ------------------------------ ------------------------------ ------------------------------ ------------------------------ ------------------------------ ------------------------------ ------------------------------ ------------------------------ ------------------------------ ------------------------------ ------------------------------ 
--AAFAAAAAAAAAAAAAAAAAAAA-AA-- -AAAFAAAAAAAAAAAAAAAAAAAA-AAA- -A-AFAAAAAAAAAAAAAAAAAAAA-A-A- AAAA-AAAAAAAAAAAAAAAAAAAA-AAAA AAAA----------------------AAAA AAAAAAAAAAAAAAAAAAAAAAAAAAAAAA AAAAAAAAAAAAAAAAAAAAAAAAAAAAAA AAAAAAAAAAAAAAAAAAAAAAAAAAAAAA AAAAAAAAAAAAAAAAAAAAAAAAAAAAAA AAAAAAAAAAAAAAAAAAAAAAAAAAAAAA AAAAAAAAAAAAAAAAAAAAAAAAAAAAAA AA-AAAAAAAAAAAAAAAAAAAAAAAA-AA AAAAADD------------------AAAAA -AA---DD-------------------AA- -------D---------------------- -------DD--------------------- --------D--------------------- --------DD-------------------- ---------D-------------------- ---------DD------------------- ----------D------------------- ----------DD------------------ -----------D------------------ -----------DD----------------- ------------D----------------- ------------DD---------------- -------------B---------------- 
