model
size = 30 14 12, scale = 0.05, origin = -y
material 
  colors = A:#A36336 B:#A7A7A7 C:#656765 D:#EEE E:#C7802D F:#E2943B G:#E83015 H:#535953
voxels
----BBBBBBBBBBBBBBBBBBBBB----- ---BBBBBBBBBBBBBBBBBBBBBBB---- ---DDDDDDDDDDDDDDDDDDDDDDD---- ----AAAAAAAAAAAAAAAAAAA------- -----BB---------AAAA---------- ------------------------------ ------------------------------ ------------------------------ ------------G----------------- ------------D----------------- ------------D----------------- ------------------------------ ------------------------------ ------------------------------ 
--BBBFEFEFEFEFEFEFEFEFEFBBB--- --BDBBBBBBBBBBBBBBBBBBBBBDBB-- --DDDDDDDDDDDDDDDDDDDDDDDDDD-- ---AAAAAAAAAAAAAAAAAAAAAA----- ---BBBBBB----AABAAAAG--------- ---AAHHAHB-------HHH---------- ---AAAA--HB------------------- ----HA----HBB----------------- ------------C----------------- ------------------------------ ------------D----------------- ------------D----------------- ------------------------------ ------------------------------ 
--BEFEFEFEFEFEFEFEFEFEFEFEBBB- -BDBBBBBBBBBBBBBBBBBBBBBBBBDB- -DDAAAAAAAAAAAAAAAAAAAAAAAAAD- --AAAAAAAAAAAAAAAAAAAAAAAAAA-- --BBBBBAACCCCAAAAAAAABBBB----- --AAAAAAAAAAHCCCBAAABC-------- --AAAAAAAAAAAAAAAB------------ --HCAAAGGAAAAAAC-------------- --CCCCHAAAAAAB---------------- ---CCCCCCHAA------------------ -----CCCCCHA------------------ ---------CCAD----------------- ----------AA------------------ ------------------------------ 
-BBFEFEFEFEFEFEFEFEFEFEFEFEFB- BDBCCCCCCCCCCCCCCCCCCCCCCCCCB- DDA-------------------------D- -AA------------------------A-- -BB---------------------ABB--- -AA-----------------AACC------ -AA---------------BBD--------- -C--------------AAD----------- -H---------AAAAAD------------- -----------AAAA--------------- -----------AAAD--------------- -----------AAA---------------- -----------AA----------------- ------------------------------ 
BBFEFEFEFEFEFEFEFEFEFEFEFEFEBB BBCCCCGCCGCGCGGGCGGGCGGCGCGCDB DA--------------------------DD AA-------------------------AA- BB----------------------AAAB-- AA------------------AAAAC----- HA----------------AAAD-------- -C--------------AAAD---------- -C---------AAAAAAD------------ -H---------AAAAD-------------- -----------AAAA--------------- -----------AAAD--------------- -----------AAA---------------- -----------AA----------------- 
BFEFEFEFEFEFEFEFEFEFEFEFEFEFEB BBCGGCGCGGCGCCCGCCCGCGCCGGGCBB DA--------------------------DD GA-------------------------AA- BB----------------------AAAB-- AA------------------AAAAC----- AA----------------AAAD-------- HA--------------AAAD---------- -C---------AAAAAAD------------ -C---------AAAAD-------------- -----------AAAA--------------- -----------DAAD--------------- -----------DAA---------------- -----------AA----------------- 
BEFEFEFEFEFEFEFEFEFEFEFEFEFEFB BBCGGCGGCGCCCGGCCGGCCGCCGCGCBB DA--------------------------DD GA-------------------------AA- BB----------------------AAAB-- AA------------------AAAAC----- AA----------------AAAD-------- HA--------------AAAD---------- -C---------AAAAAAD------------ -C---------AAAAD-------------- -----------AAAA--------------- -----------DAAD--------------- -----------DAA---------------- -----------AA----------------- 
BBEFEFEFEFEFEFEFEFEFEFEFEFEFBB BBCCCCGCCGCGCGGGCGGGCGCCGGGCDB DA--------------------------DD AA-------------------------AA- BB----------------------AAAB-- AA------------------AAAAC----- HA----------------AAAD-------- -C--------------AAAD---------- -C---------AAAAAAD------------ -H---------AAAAD-------------- -----------AAAA--------------- -----------AAAD--------------- -----------AAA---------------- -----------AA----------------- 
-BBEFEFEFEFEFEFEFEFEFEFEFEFEB- BDBCCCCCCCCCCCCCCCCCCCCCCCCCB- DDA-------------------------D- -AA------------------------A-- -BB---------------------ABB--- -AA-----------------AACC------ -AA---------------BBD--------- -C--------------AAD----------- -H---------AAAAAD------------- -----------AAAA--------------- -----------AAAD--------------- -----------AAA---------------- -----------AA----------------- ------------------------------ 
--BFEFEFEFEFEFEFEFEFEFEFEFBBB- -BDBBBBBBBBBBBBBBBBBBBBBBBBDB- -DDAAAAAAAAAAAAAAAAAAAAAAAAAD- --AAAAAAAAAAAAAAAAAAAAAAAAAA-- --BBBBAAACCCCCAAAAAAABBBB----- --AAAAAAAAAAHCCCBCAABC-------- --AAAAAAAAAAAAAAAB------------ --HCAAAGGAAAAAAC-------------- --CCCCHAAAAAAB---------------- ---CCCCCCHAAA----------------- -----CCCCCHA------------------ ---------CCAD----------------- ----------AA------------------ ------------------------------ 
--BBBEFEFEFEFEFEFEFEFEFEBBB--- --BDBBBBBBBBBBBBBBBBBBBBBDBB-- --DDDDDDDDDDDDDDDDDDDDDDDDDD-- ---AAAAAAAAAAAAAAAAAAAAAA----- ---BBBBBB----AABAAAAG--------- ---AAHHAHB-------HHH---------- ---AAAA--HB------------------- ----HA----HBB----------------- ------------C----------------- ------------------------------ ------------D----------------- ------------D----------------- ------------------------------ ------------------------------ 
----BBBBBBBBBBBBBBBBBBBBB----- ---BBBBBBBBBBBBBBBBBBBBBBB---- ---DDDDDDDDDDDDDDDDDDDDDDD---- ----AAAAAAAAAAAAAAAAAAA------- -----BB---------AAAA---------- ------------------------------ ------------------------------ ------------------------------ ------------G----------------- ------------D----------------- ------------D----------------- ------------------------------ ------------------------------ ------------------------------ 
