model
size = 23 12 29, scale = 0.05, origin = -y
material 
  colors = A:#222 B:#444 C:#FFD24D D:#CB603C E:#A53131 F:#945F41 G:#FCFAF2
voxels
-------CCCCCCCCC------- -------CCCCCCCCC------- ----------------------- ----------------------- ----------------------- ----------------------- ----------------------- ----------------------- ----------------------- ----------------------- ----------------------- ----------------------- 
------CCDFFFFFDCC------ ------CCCEEEEECCC------ ----------------------- ----------------------- ----------------------- ----------------------- ----------------------- ----------------------- ----------------------- ----------------------- ----------------------- ----------------------- 
-----CDDFDDDDDFDDC----- -----CCCECCCCCECCC----- ----------------------- ----------------------- ----------------------- ----------------------- ----------------------- ----------------------- ----------------------- ----------------------- ----------------------- ----------------------- 
----CDDFDFFFFFDFDDC---- ----CCCECEEEEECECCC---- ----------------------- ----------------------- ----------------------- ----------------------- ----------------------- ----------------------- ----------------------- ----------------------- ----------------------- ----------------------- 
---CDDFDFDDDDDFDFDDC--- ---CCCECECCCCCECECCC--- ----------------------- ----------------------- ----------------------- ----------------------- ----------------------- ----------------------- ----------------------- ----------------------- ----------------------- ----------------------- 
---CDFDFDFFFFFDFDFDC--- ---CCECECEEEEECECECC--- ----------------------- ----------------------- ----------------------- ----------------------- ----------------------- ----------------------- ----------------------- ----------------------- ----------------------- ----------------------- 
--CDFDFDFDDDDDFDFDFDC-- --CCECECECCCCCECECECC-- ----------------------- ----------------------- ----------------------- ----------------------- ----------------------- ----------------------- ----------------------- ----------------------- ----------------------- ----------------------- 
--CFDFDFDDFFFDDFDFDFC-- --CECECECCEEECCECECEC-- ------C-CEEC-C-E------- ------CC-E-CC--E------- ------C-CEEC-C-E------- ------C-CE-C-C-E------- ------CC-EEC-CEEE------ ----------------------- ----------------------- ----------------------- ----------------------- ----------------------- 
--CFDFDFDFDDDFDFDFDFC-- --CECECAAAAAAAAACECEC-- ------AAAAAAAAAAA------ ------AAAAAAAAAAA------ ------AAAAAAAAAAA------ ------AAAAAAAAAAA------ ------AAAAAAAAAAA------ -------AAAAAAAAA------- --------AAAAAAA-------- ----------------------- ----------------------- ----------------------- 
--CFDFDBBBBBBBBBDFDFC-- --CEAAABBBBBBBBBAAAEC-- ----AAAAAAABAAAAAAA---- ----AAAAAAABAAAAAAA---- -----AAAAAABAAAAAA----- -----AAAAAABAAAAAA----- -----AAAAAABAAAAAA----- ------AAAAAAAAAAA------ -------AAAAAAAAA------- ----------------------- ----------------------- ----------------------- 
--CFDBB---------BBDFC-- --CAABB---------BBAAC-- ---AAA-----------AAA--- ---AAA-----------AAA--- ----AA-----------AA---- ----AA-----------AA---- ----AAA---------AAA---- -----AAAAAABAAAAAA----- ------AAAAAAAAAAA------ ----------AAA---------- ----------------------- ----------------------- 
--ABBB-----------BBBA-- --AABB-----------BBAA-- --AA-B-----------BAAA-- --AA-B-----------BAAA-- ---AAB-----------BAA--- ---AAB-----------BAA--- ----AAA---------AAA---- -----AAA-------AAA----- ------AAAAABAAAAA------ --------AAAAAAA-------- ----------------------- ----------------------- 
--AB---------------BA-- --AB---------------BA-- --A-----------------A-- --A-----------------A-- ---A---------------A--- ---A---------------A--- ----AAB---------BAA---- ----AABA-------ABAA---- ------AAAAABAAAAA------ --------AAAAAAA-------- ----------------------- ----------------------- 
-AAB---------------BAA- -AAB---------------BAG- -AA-----------------AG- -AA-----------------AA- --A----------------AA-- --A----------------AA-- ---A---------------A--- ---AAA-----------AAA--- -----AABAAABAAABAA----- -------AAAAAAAAA------- ----------------------- ----------------------- 
-AB-----------------BA- -AB-----------------BG- -A-------------------G- -A-------------------A- --A-----------------A-- --A-----------------A-- ---A---------------A--- ---AAA-----------AAA--- -----AAABA---ABAAA----- -------AAAABAAAA------- ----------AAA---------- ----------------------- 
AAB-----------------BAA AAB-----------------BAA AA-------------------AA -A-------------------A- -AA-----------------AA- --A-----------------A-- --AA---------------AA-- ---AAA-----------AAA--- ----AAAA-------AAAA---- ------AAABABABAAA------ ---------AAAAA--------- ----------------------- 
AB-------------------BA AB-------------------BA AA-------------------AA AA-------------------AA -AA-----------------AA- -AA-----------------AA- --AA---------------AA-- --AAAA-----------AAAA-- ----AAAA-------AAAA---- ------AAAABBBAAAA------ --------AAAAAAA-------- ----------CCC---------- 
AB-------------------BA AB-------------------BA AB-------------------BA AB-------------------BA -AB-----------------BA- -AB-----------------BA- --AB---------------BA-- --AABB-----------BBAA-- ----AABB-------BBAA---- ------AABBBBBBBAA------ --------AAACAAA-------- ----------CCC---------- 
AB-------------------BA AB-------------------BA AA-------------------AA AA-------------------AA -AA-----------------AA- -AA-----------------AA- --AA---------------AA-- --AAAA-----------AAAA-- ----AAAA-------AAAA---- ------AAAABBBAAAA------ --------AAAAAAA-------- ----------CCC---------- 
AB-------------------BA AB-------------------BA AA-------------------AA AA-------------------AA -AA-----------------AA- -AA-----------------AA- --AA---------------AA-- --AAAA-----------AAAA-- ----AAAAAB---BAAAAA---- ------AAABABABAAA------ ---------AAAAA--------- ----------------------- 
AB-------------------BA AB-------------------BA AA-------------------AA -A-------------------A- -AA-----------------AA- --A-----------------A-- --AA---------------AA-- ---AAA-----------AAA--- -----AAABA---ABAAA----- -------AAAABAAAA------- ----------AAA---------- ----------------------- 
AAB-----------------BAA AAB-----------------BAA -A-------------------A- -A-------------------A- --A-----------------A-- --A-----------------A-- ---A---------------A--- ---AAAAB-------BAAAA--- -----AAAAAABAAABAA----- -------AAAAAAAAA------- ----------------------- ----------------------- 
-AB-----------------BA- -AB-----------------BA- -A-------------------A- -A-------------------A- --A-----------------A-- --A-----------------A-- ---AAAB---------BAAA--- ---AAABA-------ABAAA--- -----AAAAAABAAAAAA----- -------AAAAAAAAA------- ----------------------- ----------------------- 
-AAB---------------BAA- -AAB---------------BAA- -AA-----------------AA- --A-----------------A-- --A-----------------A-- ---AAB-----------BAA--- ---AABA---------ABAA--- ----AAAA-------AAAA---- ------AAAAABAAAAA------ ---------AAAAA--------- ----------------------- ----------------------- 
--ABB-------------BBA-- --ABB-------------BBA-- --AAB-------------BAA-- --AAB-------------BAA-- ---AB-------------BA--- ---ABA-----------ABA--- ----AAA---------AAA---- -----AAAAAABAAAAAA----- -------AAAAAAAAA------- ----------------------- ----------------------- ----------------------- 
--AAB-------------BAA-- --AAB-------------BAA-- --AAA-------------AAA-- --AAA-------------AAA-- ----A-------------A---- ----AA-----------AA---- -----AA---------AA----- -------AAAABAAAA------- ---------AAAAA--------- ----------------------- ----------------------- ----------------------- 
---AABB---------BBAA--- ---AABB---------BBAA--- ---AAA-----------AAA--- ---AAA-----------AAA--- -----A-----------A----- -----A-----------A----- ------AAAAABAAAAA------ ---------AAAAA--------- ----------------------- ----------------------- ----------------------- ----------------------- 
----AAABB-----BBAAA---- ----AAABB-----BBAAA---- ----AAAAB-----BAAAA---- ----AAAAAB---BAAAAA---- ------AAAABBBAAAA------ ------AAAAABAAAAA------ ---------AAAAA--------- ----------------------- ----------------------- ----------------------- ----------------------- ----------------------- 
------AACECECECAA------ ------AACCCCCCCAA------ ------AAA-----AAA------ ------AAAA---AAAA------ --------AAAAAAA-------- ---------AAAAA--------- ----------------------- ----------------------- ----------------------- ----------------------- ----------------------- ----------------------- 
