model
size = 29 12 29, scale = 0.05, origin = -y
material 
  colors = A:#FF0 B:#E00 C:#0E0 D:#06C E:#111 F:#EEE G:#777
voxels
----------------------------- ----------------------------- ----------F------------------ ----------------------------- ----------------------------- ----------------------------- ----------------------------- ----------------------------- ----------------------------- ----------------------------- ----------------------------- ----------------------------- 
----------------------------- ----------------------------- ----------BAAAAAAAA---------- ----------------------------- ----------------------------- ----------------------------- ----------------------------- ----------------------------- ----------------------------- ----------------------------- ----------------------------- ----------------------------- 
----------------------------- ----------------------------- -------BBB---------AAA------- ----------BAAAAAAAA---------- ----------BAAAAAAAA---------- ----------------------------- ----------------------------- ----------------------------- ----------------------------- ----------------------------- ----------------------------- ----------------------------- 
----------------------------- ----------------------------- -------BBB---------AAAF------ ----------BAAAAAAAA---------- ----------BAAAAAAAA---------- ----------------------------- ----------------------------- ----------------------------- ----------------------------- ----------------------------- ----------------------------- ----------------------------- 
----------------------------- ----------------------------- ----BBB---------------DDD---- -------BBB---------ADD------- -------BBB---------ADD------- ----------BAAAAAAAA---------- ----------------------------- ----------------------------- ----------------------------- ----------------------------- ----------------------------- ----------------------------- 
----------------------------- ----------------------------- ----B------------------DD---- -----BB---------------D------ -----BB---------------D------ -------BBB---------DDD------- ----------BAAAAAAAA---------- ----------BAAAAAAAA---------- ----------------------------- ----------------------------- ----------------------------- ----------------------------- 
----------------------------- ----------------------------- ----B------------------DD---- -----BB---------------D------ -----BB---------------D------ -------BBB---------DDD------- ----------BAAAAAAAA---------- ----------BAAAAAAAA---------- ----------------------------- ----------------------------- ----------------------------- ----------------------------- 
----------------------------- ----------------------------- --BB---------------------D--- ----B------------------DD---- ----B------------------DD---- -----BBB------------DDD------ --------BB---------D--------- --------BB---------D--------- ----------BAAAAAADD---------- ----------------------------- ----------------------------- ----------------------------- 
----------------------------- ----------------------------- --BB---------------------D--- ----B------------------DD---- ----B------------------DD---- -----BB---------------D------ -------BGG---------GDD------- -------BGG---------GDD------- --------BBBAAAAAADDD--------- ----------------------------- ----------------------------- ----------------------------- 
-----------EEEEEE------------ -----------EEEEEE------------ --BB---------------------D--- ----B------------------DD---- ----B------------------DD---- -----BB--G---------G--D------ -------B------------DD------- -------B------------DD------- --------BBBAAAAAADDD--------- ----------------------------- ----------------------------- ----------------------------- 
---------GE------EEG--------- ---------GE------EEG--------- FB-------G---------G------DD- --BB-----G---------G-----D--- --BB-----G---------G-----D--- ----B------------------DD---- -----BB---------------D------ -----BB---------------D------ -------BBBB------DDDDD------- -----------BBAAAD------------ -----------BBAAAD------------ ----------------------------- 
--------EE---------E--------- --------EE---------E--------- -C------------------------DD- --CC---------------------D--- --CC---------------------D--- ----C------------------DD---- -----CC---------------D------ -----CC---------------D------ -------CCC---------DDD------- ----------BBBAAADDD---------- ----------BBBAAADDD---------- ----------------------------- 
--------E----------E--------- --------E----------E--------- -C------------------------DDF --CC---------------------D--- --CC---------------------D--- ----C------------------DD---- -----CC---------------D------ -----CC---------------D------ -------CCC---------DDD------- ----------BBBAAADDD---------- ----------BBBAAADDD---------- ----------------------------- 
--------E----------E--------- --------E----------E--------- -C------------------------CC- --CC---------------------C--- --CC---------------------C--- ----C------------------CC---- -----CC---------------C------ -----CC---------------C------ -------CCC---------CCC------- ----------CCCFFFCCC---------- ----------CCCFFFCCC---------- -------------FFF------------- 
--------E----------E--------- --------E----------E--------- -C------------------------CC- --CC---------------------C--- --CC---------------------C--- ----C------------------CC---- -----CC---------------C------ -----CC---------------C------ -------CCC---------CCC------- ----------CCCFFFCCC---------- ----------CCCFFFCCC---------- -------------FFF------------- 
--------E----------E--------- --------E----------E--------- -C------------------------CC- --CC---------------------C--- --CC---------------------C--- ----C------------------CC---- -----CC---------------C------ -----CC---------------C------ -------CCC---------CCC------- ----------CCCFFFCCC---------- ----------CCCFFFCCC---------- -------------FFF------------- 
--------EE---------E--------- --------EE---------E--------- -C------------------------CC- --CC---------------------C--- --CC---------------------C--- ----C------------------CC---- -----CC---------------C------ -----CC---------------C------ -------CCC---------CCC------- ----------DDDAAABBB---------- ----------DDDAAABBB---------- ----------------------------- 
----------E-------EG--------- ---------GE-------EG--------- -C-------G---------G------CC- --CC-----G---------G-----C--- --CC-----G---------------C--- ----C------------------CC---- -----DD---------------C------ -----DD---------------C------ -------DDDD------BBBBB------- -----------DDAAAB------------ -----------DDAAAB------------ ----------------------------- 
----------E------EE---------- ----------E------EE---------- -C------------------------CC- --CC---------------------C--- --CC----G----------G-----C--- ----C------------------CC---- -----DD---------------C------ -----DD---------------C------ -------DDDD------BBBBB------- -----------DDAAAB------------ -----------DDAAAB------------ ----------------------------- 
-----------EEEEEE------------ -----------EEEEEE------------ -FCC---------------------C--- ----D------------------CC---- ----D------------------CC---- -----DD-G----------G--B------ -------DG----------GBB------- -------DG----------GBB------- --------DDDAAAAAABBB--------- ----------------------------- ----------------------------- ----------------------------- 
----------------------------- ----------------------------- --DD---------------------C--- ----D------------------BB---- ----D------------------BB---- -----DDD------------BBB------ --------DD---------B--------- --------DD---------B--------- ----------DAAAAAABB---------- ----------------------------- ----------------------------- ----------------------------- 
----------------------------- ----------------------------- --DD---------------------C--- ----D------------------BB---- ----D------------------BB---- -----DDD------------BBB------ --------DD---------B--------- --------DD---------B--------- ----------DAAAAAABB---------- ----------------------------- ----------------------------- ----------------------------- 
----------------------------- ----------------------------- ----D------------------BBF--- -----DD---------------B------ -----DD---------------B------ -------DDD---------BBB------- ----------AAAAAAABB---------- ----------AAAAAAABB---------- ----------------------------- ----------------------------- ----------------------------- ----------------------------- 
----------------------------- ----------------------------- ----DDD---------------BBB---- -------DAA---------BBB------- -------DAA---------BBB------- ----------AAAAAAABB---------- ----------------------------- ----------------------------- ----------------------------- ----------------------------- ----------------------------- ----------------------------- 
----------------------------- ----------------------------- ----DDD---------------BBB---- -------DAA---------BBB------- -------DAA---------BBB------- ----------AAAAAAABB---------- ----------------------------- ----------------------------- ----------------------------- ----------------------------- ----------------------------- ----------------------------- 
----------------------------- ----------------------------- ------FAAA---------BBB------- ----------AAAAAAABB---------- ----------AAAAAAABB---------- ----------------------------- ----------------------------- ----------------------------- ----------------------------- ----------------------------- ----------------------------- ----------------------------- 
----------------------------- ----------------------------- ----------AAAAAAABB---------- ----------------------------- ----------------------------- ----------------------------- ----------------------------- ----------------------------- ----------------------------- ----------------------------- ----------------------------- ----------------------------- 
----------------------------- ----------------------------- ----------AAAAAAABB---------- ----------------------------- ----------------------------- ----------------------------- ----------------------------- ----------------------------- ----------------------------- ----------------------------- ----------------------------- ----------------------------- 
----------------------------- ----------------------------- -----------------F----------- ----------------------------- ----------------------------- ----------------------------- ----------------------------- ----------------------------- ----------------------------- ----------------------------- ----------------------------- ----------------------------- 
