model
size = 23 12 29, scale = 0.05, origin = -y
material 
  colors = A:#00AA90 B:#EEE C:#F75C2F D:#FF9252 E:#F7824C F:#A5845F
voxels
-------CCCCCCCCC------- -------CCCCCCCCC------- ----------------------- ----------------------- ----------------------- ----------------------- ----------------------- ----------------------- ----------------------- ----------------------- ----------------------- ----------------------- 
------CCDEEEEEDCC------ ------CCCFFFFFCCC------ ----------------------- ----------------------- ----------------------- ----------------------- ----------------------- ----------------------- ----------------------- ----------------------- ----------------------- ----------------------- 
-----CDDEDDDDDEDDC----- -----CCCFCCCCCFCCC----- ----------------------- ----------------------- ----------------------- ----------------------- ----------------------- ----------------------- ----------------------- ----------------------- ----------------------- ----------------------- 
----CDDEDEEEEEDEDDC---- ----CCCFCFFFFFCFCCC---- ----------------------- ----------------------- ----------------------- ----------------------- ----------------------- ----------------------- ----------------------- ----------------------- ----------------------- ----------------------- 
---CDDEDEDDDDDEDEDDC--- ---CCCFCFCCCCCFCFCCC--- ----------------------- ----------------------- ----------------------- ----------------------- ----------------------- ----------------------- ----------------------- ----------------------- ----------------------- ----------------------- 
---CDEDEDEEEEEDEDEDC--- ---CCFCFCFFFFFCFCFCC--- ----------------------- ----------------------- ----------------------- ----------------------- ----------------------- ----------------------- ----------------------- ----------------------- ----------------------- ----------------------- 
--CDEDEDEDDDDDEDEDEDC-- --CCFCFCFCCCCCFCFCFCC-- ----------------------- ----------------------- ----------------------- ----------------------- ----------------------- ----------------------- ----------------------- ----------------------- ----------------------- ----------------------- 
--CEDEDEDDEEEDDEDEDEC-- --CFCFCFCCFFFCCFCFCFC-- ----------------------- ------A-ACCCAA-CC------ ------AAAC-CA-AC------- ------A-ACCCA-AC------- ------A-A---AA-C------- --------A-------------- ----------------------- ----------------------- ----------------------- ----------------------- 
--CEDEDEDEDDDEDEDEDEC-- --CFCFCAAAAAAAAACFCFC-- ------BBBBBBBBBBB------ ------BBBBBBBBBBB------ ------BBBBBBBBBBB------ ------BBBBBBBBBBB------ ------BBBBBBBBBBB------ -------BBBBBBBBB------- --------BBBBBBB-------- ----------------------- ----------------------- ----------------------- 
--CEDEDBBBBBBBBBDEDEC-- --CFAAABBBBBBBBBAAAFC-- ----BBAAAAABAAAAABB---- ----BBAAAAABAAAAABB---- -----BAAAAABAAAAAB----- -----BAAAAABAAAAAB----- -----BAAAAABAAAAAB----- ------BAAAAAAAABB------ -------BBBBBBBBB------- ----------------------- ----------------------- ----------------------- 
--CEDBB---------BBDEC-- --CAABB---------BBAAC-- ---BAA-----------AAB--- ---BAA-----------AAB--- ----BA-----------AB---- ----BA-----------AB---- ----BAA---------AAB---- -----BAAAAABAAAAAB----- ------BBBBAAABBBB------ ----------BBB---------- ----------------------- ----------------------- 
--ABBB-----------BBBA-- --AABB-----------BBAA-- --AAAB-----------BAAA-- --AAAB-----------BAAA-- ---BAB-----------BAB--- ---BAB-----------BAB--- ----BAA---------AAB---- -----BAA-------AAB----- ------BBAAABAAABB------ --------BBBBBBB-------- ----------------------- ----------------------- 
--AB---------------BA-- --AB---------------BA-- --A-----------------A-- --A-----------------A-- ---A---------------A--- ---A---------------A--- ----AAB---------BAA---- ----ABBA-------ABBA---- ------BBAAABAAABB------ --------BBBBBBB-------- ----------------------- ----------------------- 
-AAB---------------BAA- -AAB---------------BAA- -AA-----------------AA- -AA-----------------AA- --AA---------------AA-- --AA---------------AA-- ---A---------------A--- ---AAA-----------AAA--- -----AABAAABAAABAA----- -------ABBBBBBBA------- ----------------------- ----------------------- 
-AB-----------------BA- -AB-----------------BA- -A-------------------A- -A-------------------A- --A-----------------A-- --A-----------------A-- ---A---------------A--- ---AAA-----------AAA--- -----AAABA---ABAAA----- -------AABABABAA------- ----------BBB---------- ----------------------- 
AAB-----------------BAA AAB-----------------BAA AA-------------------AA -A-------------------A- -AA-----------------AA- --A-----------------A-- --AA---------------AA-- ---AAA-----------AAA--- ----AAAA-------AAAA---- ------AAABABABAAA------ ---------ABBBA--------- ----------------------- 
AB-------------------BA AB-------------------BA AA-------------------AA AA-------------------AA -AA-----------------AA- -AA-----------------AA- --AA---------------AA-- --AAAA-----------AAAA-- ----AAAA-------AAAA---- ------AAAABBBAAAA------ --------AAAAAAA-------- ----------CCC---------- 
AB-------------------BA AB-------------------BA AB-------------------BA AB-------------------BA -AB-----------------BA- -AB-----------------BA- --AB---------------BA-- --AABB-----------BBAA-- ----AABB-------BBAA---- ------AABBBBBBBAA------ --------AAACAAA-------- ----------CCC---------- 
AB-------------------BA AB-------------------BA AA-------------------AA AA-------------------AA -AA-----------------AA- -AA-----------------AA- --AA---------------AA-- --AAAA-----------AAAA-- ----AAAA-------AAAA---- ------AAAABBBAAAA------ --------AAAAAAA-------- ----------CCC---------- 
AB-------------------BA AB-------------------BA AA-------------------AA AA-------------------AA -AA-----------------AA- -AA-----------------AA- --AA---------------AA-- --AAAA-----------AAAA-- ----AAAAAB---BAAAAA---- ------AAABABABAAA------ ---------AAAAA--------- ----------------------- 
AB-------------------BA AB-------------------BA AA-------------------AA -A-------------------A- -AA-----------------AA- --A-----------------A-- --AA---------------AA-- ---AAA-----------AAA--- -----AAABA---ABAAA----- -------AAAABAAAA------- ----------AAA---------- ----------------------- 
AAB-----------------BAA AAB-----------------BAA -A-------------------A- -A-------------------A- --A-----------------A-- --A-----------------A-- ---A---------------A--- ---AAAAB-------BAAAA--- -----AAAAAABAAABAA----- -------AAAAAAAAA------- ----------------------- ----------------------- 
-AB-----------------BA- -AB-----------------BA- -A-------------------A- -A-------------------A- --A-----------------A-- --A-----------------A-- ---AAAB---------BAAA--- ---AAABA-------ABAAA--- -----AAAAAABAAAAAA----- -------AAAAAAAAA------- ----------------------- ----------------------- 
-AAB---------------BAA- -AAB---------------BAA- -AA-----------------AA- --A-----------------A-- --A-----------------A-- ---AAB-----------BAA--- ---AABA---------ABAA--- ----AAAA-------AAAA---- ------AAAAABAAAAA------ ---------AAAAA--------- ----------------------- ----------------------- 
--ABB-------------BBA-- --ABB-------------BBA-- --AAB-------------BAA-- --AAB-------------BAA-- ---AB-------------BA--- ---ABA-----------ABA--- ----AAA---------AAA---- -----AAAAAABAAAAAA----- -------AAAAAAAAA------- ----------------------- ----------------------- ----------------------- 
--AAB-------------BAA-- --AAB-------------BAA-- --AAA-------------AAA-- --AAA-------------AAA-- ----A-------------A---- ----AA-----------AA---- -----AA---------AA----- -------AAAABAAAA------- ---------AAAAA--------- ----------------------- ----------------------- ----------------------- 
---AABB---------BBAA--- ---AABB---------BBAA--- ---AAA-----------AAA--- ---AAA-----------AAA--- -----A-----------A----- -----A-----------A----- ------AAAAABAAAAA------ ---------AAAAA--------- ----------------------- ----------------------- ----------------------- ----------------------- 
----AAABB-----BBAAA---- ----AAABB-----BBAAA---- ----AAAAB-----BAAAA---- ----AAAAAB---BAAAAA---- ------AAAABBBAAAA------ ------AAAAABAAAAA------ ---------AAAAA--------- ----------------------- ----------------------- ----------------------- ----------------------- ----------------------- 
------AACFCFCFCAA------ ------AACCCCCCCAA------ ------AAA-----AAA------ ------AAAA---AAAA------ --------AAAAAAA-------- ---------AAAAA--------- ----------------------- ----------------------- ----------------------- ----------------------- ----------------------- ----------------------- 
