model
size = 26 20 30, scale = 0.05, origin = -y
material 
  colors = A:#CC0 B:#888 C:#444 D:#CC9 E:#111 F:#EEE G:#555
voxels
-------------------------- -------------------------- -------------------------- -------------------------- -------------------------- -------------------------- -------------------------- -------------------------- -------------------------- -------------------------- -------------------------- -------------------------- ----------CCCCCC---------- ----------BBBBBB---------- ----------CCCCCC---------- ----------BBBBBB---------- -------------------------- -------------------------- -------------------------- -------------------------- 
-------------------------- -------------------------- -------------------------- -------------------------- -------------------------- -------------------------- -------------------------- -------------------------- -------------------------- -------------------------- ----------CCCCCC---------- ----------BBBBBB---------- ----------BBBBBB---------- -------------------------- -------------------------- ----------BBBBBB---------- ----------CCCCCC---------- ----------BBBBBB---------- ----------B----B---------- -------------------------- 
-------------------------- -------------------------- -------------------------- -------------------------- -------------------------- -------------------------- -------------------------- -------------------------- ----------CCCCCC---------- ----------BBBBBB---------- ----------BBBBBB---------- -------------------------- -------------------------- -------------------------- -------------------------- -------------------------- -------------------------- ------------DD------------ ----------AAEEAA---------- ----------BA--AB---------- 
-------------------------- -------------------------- -------------------------- -------------------------- -------------------------- -------------------------- ----------CCCCCC---------- ----------BBBBBB---------- ----------BBBBBB---------- -------------------------- -------------------------- -------------------------- -------------------------- -------------------------- -------------------------- -------------------------- -------------------------- ----------DAAAAD---------- --------AAAAAAAAAA-------- ---------ABBBBBBA--------- 
-------------------------- -------------------------- -------------------------- -------------------------- ----------CCCCCC---------- ----------BBBBBB---------- ----------BBBBBB---------- -------------------------- -------------------------- -------------------------- -------------------------- -------------------------- -------------------------- -------------------------- -------------------------- -------------------------- -------------------------- --------DAAAAAAAAD-------- ------AAAAAAAAAAAAAA------ -----------A--A----------- 
-------------------------- -------------------------- ----------CCCCCC---------- ----------BBBBBB---------- ----------BBBBBB---------- -------------------------- -------------------------- -------------------------- -------------------------- -------------------------- -------------------------- -------------------------- -------------------------- -------------------------- -------------------------- -------------------------- -------------------------- ------DAAAAAAAAAAAAD------ -----AAAAAAAAAAAAAAAA----- -----A-A--A-AA-A--A-A----- 
-------------------------- ----------BBBBBB---------- ----------BBBBBB---------- -------------------------- -------------------------- -------------------------- -------------------------- -------------------------- -------------------------- -------------------------- -------------------------- -------------------------- -------------------------- -------------------------- -------------------------- -------------------------- -------------------------- -----DAAAAAAAAAAAAAAD----- ----AAAAAAAAAAAAAAAAAA---- ----A-A-AA------AA-A-A---- 
-------------------------- ----------BBBBBB---------- -------------------------- -------------------------- -------------------------- -------------------------- -------------------------- -------------------------- -------------------------- -------------------------- -------------------------- -------------------------- -------------------------- -------------------------- -------------------------- -------------------------- -------------------------- ----DAAAAAAAAAAAAAAAAD---- ---AAAAAAAAAAAAAAAAAAAA--- ---A-A-A-AA-AA-AA-A-E-A--- 
----------CCCCCC---------- ----------BBBBBB---------- -------------------------- -------------------------- -------------------------- -------------------------- -------------------------- -------------------------- -------------------------- -------------------------- -------------------------- -------------------------- -------------------------- -------------------------- -------------------------- -------------------------- -------------------------- --ADAAAAAAAAAAAAAAAAAADA-- --AAAAAAAAAAAAAAAAAAAAAA-- --A-A-A-A-D-AA-D-A-E-A-A-- 
----------BBBBBB---------- -------------------------- -------------------------- -------------------------- -------------------------- -------------------------- -------------------------- -------------------------- -------------------------- -------------------------- -------------------------- -------------------------- -------------------------- -------------------------- -------------------------- -------------------------- -------------------------- --DAAAAAAAAAAAAAAAAAAAAD-- -AAAAAAAAAAAAAAAAAAAAAAAA- --AA-A-A-FFF--FFF-E-A-AA-- 
----------BBBBBB---------- -------------------------- -------------------------- -------------------------- -------------------------- -------------------------- -------------------------- -------------------------- -------------------------- -------------------------- -------------------------- -------------------------- -------------------------- -------------------------- -------------------------- -------------------------- -------------------------- --DAAAAAAAAAAAAAAAAAAAAD-- -AAAAAAAAAAAAAAAAAAAAAAAA- --A-----F---FF---E-----A-- 
----------BBBBBB---------- -------------------------- -------------------------- -------------------------- -------------------------- -------------------------- -------------------------- -------------------------- -------------------------- -------------------------- -------------------------- -------------------------- -------------------------- -------------------------- -------------------------- -------------------------- -------------------------- -DAAAAAAAAAAAAAAAAAAAAAAD- -AAAAAAAAAAAAAAAEAAAAAAAA- -A--A--F----FF--E-F--A--A- 
----------BBBBBB---------- -------------------------- -------------------------- -------------------------- -------------------------- -------------------------- -------------------------- -------------------------- -------------------------- -------------------------- -------------------------- -------------------------- -------------------------- -------------------------- -------------------------- -------------------------- -------------------------- -DAAAAAAAAAAAAAAAAAAAAAAD- AAAAAAAAAAAAAAAAAAAAAAAAAA ---AFFFF--A-DD-E--FFFFA--- 
----------EEEEEE---------- -------------------------- -------------------------- -------------------------- -------------------------- -------------------------- -------------------------- -------------------------- -------------------------- -------------------------- -------------------------- -------------------------- -------------------------- -------------------------- -------------------------- -------------------------- -------------------------- DAAAAAAAAAAAAAAAAAAAAAAAAD AAAAAAAAAAAAAAEAAAAAAAAAAA A-A----F------E---F----A-A 
----------EEGGEE---------- -------------------------- -------------------------- -------------------------- -------------------------- -------------------------- -------------------------- -------------------------- -------------------------- -------------------------- -------------------------- -------------------------- -------------------------- -------------------------- -------------------------- -------------------------- -------------------------- DAAAAAAAAAAAAAAAAAAAAAAAAD EAAEEEEAEAEAAAAAAAAAAAAAAE ---EEEEEEEEEGFA-A-F------- 
----------EEGGEE---------- -------------------------- -------------------------- -------------------------- -------------------------- -------------------------- -------------------------- -------------------------- -------------------------- -------------------------- -------------------------- -------------------------- -------------------------- -------------------------- -------------------------- -------------------------- -------------------------- DAAAAAAAAAAAAAAAAAAAAAAAAD EAAAAAAAAAAAAAAAAAAAAAAAAE ----FFFF-A-AFGA-A-FFFF---- 
----------EEEEEE---------- -------------------------- -------------------------- -------------------------- -------------------------- -------------------------- -------------------------- -------------------------- -------------------------- -------------------------- -------------------------- -------------------------- -------------------------- -------------------------- -------------------------- -------------------------- -------------------------- DAAAAAAAAAAAAAAAAAAAAAAAAD AAAAAAAAAAAAAAAAAAAAAAAAAA A-A----F----------F----A-A 
----------BBBBBB---------- -------------------------- -------------------------- -------------------------- -------------------------- -------------------------- -------------------------- -------------------------- -------------------------- -------------------------- -------------------------- -------------------------- -------------------------- -------------------------- -------------------------- -------------------------- -------------------------- -DAAAAAAAAAAAAAAAAAAAAAAD- AAAAAAAAAAAAAAAAAAAAAAAAAA ---A---FFFFFFFFFFFF---A--- 
----------BBBBBB---------- -------------------------- -------------------------- -------------------------- -------------------------- -------------------------- -------------------------- -------------------------- -------------------------- -------------------------- -------------------------- -------------------------- -------------------------- -------------------------- -------------------------- -------------------------- -------------------------- -DAAAAAAAAAAAAAAAAAAAAAAD- -AAAAAAAAAAAAAAAAAAAAAAAA- -A--A--F----------F--A--A- 
----------BBBBBB---------- -------------------------- -------------------------- -------------------------- -------------------------- -------------------------- -------------------------- -------------------------- -------------------------- -------------------------- -------------------------- -------------------------- -------------------------- -------------------------- -------------------------- -------------------------- -------------------------- --DAAAAAAAAAAAAAAAAAAAAD-- -AAAAAAAAAAAAAAAAAAAAAAAA- --A---------AA---------A-- 
----------BBBBBB---------- -------------------------- -------------------------- -------------------------- -------------------------- -------------------------- -------------------------- -------------------------- -------------------------- -------------------------- -------------------------- -------------------------- -------------------------- -------------------------- -------------------------- -------------------------- -------------------------- --DAAAAAAAAAAAAAAAAAAAAD-- -AAAAAAAAAAAAAAAAAAAAAAAA- --AA-A-A--D----D--A-A-AA-- 
----------CCCCCC---------- ----------BBBBBB---------- -------------------------- -------------------------- -------------------------- -------------------------- -------------------------- -------------------------- -------------------------- -------------------------- -------------------------- -------------------------- -------------------------- -------------------------- -------------------------- -------------------------- -------------------------- --ADAAAAAAAAAAAAAAAAAADA-- --AAAAAAAAAAAAAAAAAAAAAA-- --A-A-A-A-D-AA-D-A-A-A-A-- 
-------------------------- ----------BBBBBB---------- -------------------------- -------------------------- -------------------------- -------------------------- -------------------------- -------------------------- -------------------------- -------------------------- -------------------------- -------------------------- -------------------------- -------------------------- -------------------------- -------------------------- -------------------------- ----DAAAAAAAAAAAAAAAAD---- ---AAAAAAAAAAAAAAAAAAAA--- ---A-A-A-AA-AA-AA-A-A-A--- 
-------------------------- ----------BBBBBB---------- ----------BBBBBB---------- -------------------------- -------------------------- -------------------------- -------------------------- -------------------------- -------------------------- -------------------------- -------------------------- -------------------------- -------------------------- -------------------------- -------------------------- -------------------------- -------------------------- -----DAAAAAAAAAAAAAAD----- ----AAAAAAAAAAAAAAAAAA---- ----A-A-AA------AA-A-A---- 
-------------------------- -------------------------- ----------CCCCCC---------- ----------BBBBBB---------- ----------BBBBBB---------- -------------------------- -------------------------- -------------------------- -------------------------- -------------------------- -------------------------- -------------------------- -------------------------- -------------------------- -------------------------- -------------------------- -------------------------- ------DAAAAAAAAAAAAD------ -----AAAAAAAAAAAAAAAA----- -----A-A--A-AA-A--A-A----- 
-------------------------- -------------------------- -------------------------- -------------------------- ----------CCCCCC---------- ----------BBBBBB---------- ----------BBBBBB---------- -------------------------- -------------------------- -------------------------- -------------------------- -------------------------- -------------------------- -------------------------- -------------------------- -------------------------- -------------------------- --------DAAAAAAAAD-------- ------AAAAAAAAAAAAAA------ -----------A--A----------- 
-------------------------- -------------------------- -------------------------- -------------------------- -------------------------- -------------------------- ----------CCCCCC---------- ----------BBBBBB---------- ----------BBBBBB---------- -------------------------- -------------------------- -------------------------- -------------------------- -------------------------- -------------------------- -------------------------- -------------------------- ----------DAAAAD---------- --------AAAAAAAAAA-------- ---------ABBBBBBA--------- 
-------------------------- -------------------------- -------------------------- -------------------------- -------------------------- -------------------------- -------------------------- -------------------------- ----------CCCCCC---------- ----------BBBBBB---------- ----------BBBBBB---------- -------------------------- -------------------------- -------------------------- -------------------------- -------------------------- -------------------------- ------------DD------------ ----------AAEEAA---------- ----------BA--AB---------- 
-------------------------- -------------------------- -------------------------- -------------------------- -------------------------- -------------------------- -------------------------- -------------------------- -------------------------- -------------------------- ----------CCCCCC---------- ----------BBBBBB---------- ----------BBBBBB---------- -------------------------- -------------------------- ----------BBBBBB---------- ----------CCCCCC---------- ----------BBBBBB---------- ----------B----B---------- -------------------------- 
-------------------------- -------------------------- -------------------------- -------------------------- -------------------------- -------------------------- -------------------------- -------------------------- -------------------------- -------------------------- -------------------------- -------------------------- ----------CCCCCC---------- ----------BBBBBB---------- ----------CCCCCC---------- ----------BBBBBB---------- -------------------------- -------------------------- -------------------------- -------------------------- 
