model
size = 15 32 5, scale = 0.05, origin = -y
material 
  colors = A:#222 B:#777 C:#630 D:#888 E:#333 F:#444 G:#080 H:#E00
voxels
317-A4-G4-A4-11A443-3F7-A3-5F3-A2-13A7-3E12-CEC12-E2C12-3C12-2CE12-CEC12-3E13-G29-B13-3B11-17(2(BD)B10-)2(BD)B5-G4-2(BD)B4-GA2-GF2(BD)BFG2-16A5-2(E3CE2(10-5C)10-)E3CE11-GHG13-G313-3F7-A3-5F3-A2-13A7-3E12-CEC12-2CE12-3C12-E2C12-CEC12-3E13-G339-A4-G4-A4-11A137-
