model
size = 25 30 26, scale = 0.05, origin = -y
material 
  colors = A:#050 B:#070 C:#EEE D:#777 E:#080 F:#C03 G:#001 H:#555 I:#FC0 J:#444 K:#F9F L:#E00
voxels
------------------------- ------------------------- ------------------------- ------------------------- ------------------------- ------------------------- ------------------------- ------------------------- ------------------------- ------------------------- ------------------------- ------------------------- ------------------------- ------------------------- ------------------------- --D---------------------- ------------------------- ------------------------- ------------------------- ------------------------- ------------------------- ------------------------- ------------------------- ------------------------- ------------------------- ------------------------- ------------------------- ------------------------- ------------------------- ------------------------- 
------------------------- ------------------------- ------------------------- ------------------------- ------------------------- ------------------------- ------------------------- ------------------------- ------------------------- ------------------------- ------------------------- ------------------------- ------------------------- ------------------------- ------------------------- ------------------------- ------------------------- ------------------------- ------------------------- ------------------------- ------------------------- ------------------------- ------------------------- ------------------------- ------------------------- ------------------------- ------------------------- ------------------------- ------------------------- ------------------------- 
------------------------- ------------------------- ------------------------- ------------------------- ------------------------- ------------------------- ------------------------- ------------------------- ------------------------- ------------------------- ------------------------- ------------------------- ------------------------- ------------------------- ------------------------- ------------------------- ------------------------- -HD---------------------- ------------------------- ------------------------- ------------------------- ------------------------- ------------------------- ------------------------- ------------------------- ------------------------- ------------------------- ------------------------- ------------------------- ------------------------- 
------------------------- ------------------------- ------------------------- ------------------------- ------------------------- ------------------------- ------------------------- ------------------------- ------------------------- ------------------------- ------------------------- ------------------------- ------------------------- ------------------------- ------------------------- ------------------------- ------------------------- DDH---------------------- ------------------------- ------------------------- ------------------------- ------------------------- ------------------------- ------------------------- ------------------------- ------------------------- ------------------------- ------------------------- ------------------------- ------------------------- 
------------------------- ------------------------- ------------------------- ------------------------- ------------------------- ------------------------- ------------------------- ------------------------- ------------------------- ------------------------- ------------------------- ------------------------- H------------------------ ------------------------- ------------------------- ------------------------- ------------------------- CDD---------------------- ------------------------- --DH--------------------- ------------------------- --H---------------------- ------------------------- ------------------------- ------------------------- ------------------------- ------------------------- ------------------------- ------------------------- ------------------------- 
------------------------- ------------------------- ------------------------- ------------------------- ------------------------- ------------------------- ------------------------- ------------------------- ------------------------- ------------------------- -----------------III----- -----------------IAI----- D----------------IAI----- H----------------AAA----- D----------------AAA----- -----------------AAB----- -----------------ABB----- --DD--------------------- ------------------------- -CCD--------------------- --DD--------------------- --H---------------------- ------------------------- ------------------------- ------------------------- ------------------------- ------------------------- ------------------------- ------------------------- ------------------------- 
------------------------- ------------------------- ------------------------- ------------------------- ------------------------- ------------------------- ------------------------- ------------------------- ------------------------- ------------------------- ------------------I------ -H---------------IAAA---- ------------------AAA---- ----------------EAAAA---- ----------------AAAAA---- ----------------AAAA----- -----------------AAA----- ------------------------- ------------------------- ------------------------- --D---------------------- ------------------------- ------------------------- ------------------------- ------------------------- ------------------------- ------------------------- ------------------------- ------------------------- ------------------------- 
------------------------- ------------------------- ------------------------- ------------------------- ------------------------- ------------------------- ------------------------- ------------------------- ------------------------- ------------------------- -H----------------------- -----------------AAAA---- -----------------AAAA---- ----------------AAAAA---- ----------------AAAAA---- ----------------AAAAA---- -----------------AAA----- -DD--------------AAA----- ------------------------- ------------------------- ------------------------- ------------------------- ------------------------- ------------------------- ------------------------- ------------------------- ------------------------- ------------------------- ------------------------- ------------------------- 
------------------------- ------------------------- ------------------------- ------------------------- ------------------AAA---- --------------AAAABBAA--- -------------AAAAABAAAA-- -------------BAAAAAAAAA-- ------------BBAAAAAAAAAA- -D----------AAAAAAAAAAAA- ------------AAAAAAAAAAAA- ------------AAAAAAAAAAAA- ------------AAAAAAAAAAAA- ------------AAAAAAAA-AAA- ------------AAAAAAAA-AAA- ------------AAAAAAAA-AAB- ------------AAAAAAAAAAAA- ------------AAAAAAAAAAAA- ------------AAAAAAAAAAAA- ------------AAAAAAAAAAAA- ------------AAAAAAAAAAAA- ------------AAAAAAAAAABB- --------------AABAAAAAA-- ---------------AAAAAAAA-- ---------------ABAAABA--- ----------------AAAAA---- ------------------------- ------------------------- ------------------------- ------------------------- 
------------------------- ------------------------- ------------------------- --------------------A---- ------------AAAAAAAAAA--- ----------AAAAAAAAAAAAA-- ---------EAAAAAAAAAAAAAA- ---------ABAAAAAAAAAAAAA- ---------AAAAAAAAAAAAAAA- -D-------AAAAAAAAAAAAAAA- -D-------AAAAAAAAAAAAAAA- ---------AAAAAAAAAAAAAAA- ---------AAAAAAAAAAAAAAA- ---------AAAAAAAAAAAAAAA- ---------AAAAAAAAAAAAAAA- ---------AAAAAAAAAAAAAAA- ---------AAAAAAAAAAAAAAA- ---------AAAAAAAAAAAAAAA- ---------AAAAAAAAAAAAAAA- ---------AAAAAAAAAAAAAAA- ---------AAAAAAAAAAAAAAA- ---------AAAAAAAAAAAAAAA- ---------AAAAAAAAAAAAAAA- ----------AAAAAAAAAAAAA-- -------------BAAAAAAAA--- --------------AAAAAAA---- ---------------AABAA----- ------------------------- ------------------------- ------------------------- 
------------------------- ------------------------- ------------------------- -----------------AAAAA--- ------------EAAAAAAAAAA-- ---------EAA-AAAAAAAAAAA- ---------AAAAAAAAAAAAAAA- ---------AAAAAAAAAAAAAAA- ---------AAAAAAAAAAAAAAA- ---------AAAAAAAAAAAAAAA- ---------AAAAAAAAAAAAAAA- ---------AAAAAAAAAAAAAAA- ---------EAAAAAAAAAAAAAA- ---------AAAAAAAAAAAAAAA- ---------AAAAAAAAAAAAAAA- ---------AAAAAAAAAAAAAAA- ---------AAAAAAAAAAAAAAA- ---------AAAAAAAAAAAAAAA- ---------AAAAAAAAAAAAAAA- ---------AAAAAAAAAAAAAAA- --------JAAAAAAAAAAAAAAA- ---------AAAAAAAAAAAAAAA- ---------AAAAAAAAAAAAAAA- ---------AAAAAAAAAAAAAA-- ---------AAAAAAAAAAAAAA-- ----------AAAAAAAAAAAAA-- -------------AAAAAAAAA--- --------------AAAAAAA---- ------------------------- ------------------------- 
------------------------- ------------------------- ------------------------- ---------------AAAAAA-A-- ---------E-EAAAAAAAAAAAA- ---------AAAAAAAAAAAAAAA- ---------AAAAAAAAAAAAAAA- ---------AAAAAAAAAAAAAAA- ---------AAAAAAAAAAAAAAA- ---------AAAAAAAAAAAAAAA- ---------AAAAAAAAAAAAAAA- ---------KAAAAAAAAAAAAAA- ---------KAAAAAAAAAAAAAA- ---------AAAAAAAAAAAAAAA- ---------AAAAAAAAAAAAAAA- --------CAAAAAAAAAAAAAAA- --------CAAAAAAAAAAAAAAA- --------FAAAAAAAAAAAAAAA- --------FAAAAAAAAAAAAAAA- ---------AAAAAAAAAAAAAAA- ---------AAAAAAAAAAAAAAA- --------JAAAAAAAAAAAAAAA- ---------AAAAAAAAAAAAAAA- ---------AAAAAAAAAAAAAAA- ---------AAAAAAAAAAAAAAA- ---------BAAAAAAAAAAAAAA- ------------AAAAAAAAAAA-- -------------BAAAAAAAA--- ----------------AAB------ ------------------------- 
------------------------- ------------------------- ------------------------- -------------AAAAAAAA---- ---------EAAAAAAAAAAAA-A- ---------AAAAAAAAAAAAAAA- ---------AAAAAAAAAAAAAAA- ---------AAAAAAAAAAAAAAA- ---------GAAAAAAAAAAAAAAA ---------AAAAAAAAAAAAAAAA ---------AAAAAAAAAAAAAAAA ---------AAAAAAAAAAAAAAAA ---------KAAAAAAAAAAAAAAA ---------AAAAAAAAAAAAAAAA --------CAAAAAAAAAAAAAAAA --------GAAAAAAAAAAAAAAAA --------CAAAAAAAAAAAAAAAA --------CAAAAAAAAAAAAAAAA --------FAAAAAAAAAAAAAAAA --------FAAAAAAAAAAAAAAAA ---------AAAAAAAAAAAAAAAA --------JAAAAAAAAAAAAAAAA ---------AAAAAAAAAAAAAAAA ---------AAAAAAAAAAAAAAAA ---------AAAAAAAAAAAAAAA- ---------AAAAAAAAAAAAAAA- ---------BAAAAAAAAAAAAAA- ------------ABAAAAAAAAA-- --------------AAAAAA----- ------------------------- 
---------------------AAAA ---------------------AAAB -----------------AA--AABA ------------AAAAAAAAAAAAA ---------EAAAAAAAAAAAAAAA ---------AAAAAAAAAAAAAAAA ---------AAAAAAAAAAAAAAAA ---------AAAAAAAAAAAAAAAA --LCCCCCCAAAAAAAAAAAAAAAA ---------AAAAAAAAAAAAAAAA ---------AAAAAAAAAAAAAAAA ---------AAAAAAAAAAAAAAAA ---------AAAAAAAAAAAAAAAA ---------AAAAAAAAAAAAAAAA ---------AAAAAAAAAAAAAAAA --------CAAAAAAAAAAAAAAAA --------CAAAAAAAAAAAAAAAA --------FAAAAAAAAAAAAAAAA --------FAAAAAAAAAAAAAAAA ---------AAAAAAAAAAAAAAAA ---------AAAAAAAAAAAAAAAA --------JAAAAAAAAAAAAAAAA ---------AAAAAAAAAAAAAAAA ---------AAAAAAAAAAAAAAAA ---------AAAAAAAAAAAAAAAA ---------AAAAAAAAAAAAAAA- ---------AAAAAAAAAAAAAAA- -----------AAAAAAAAAAAAA- -------------AAAAABAAA--- ------------------------- 
--------------------AAAAA --------------------AAAAA --------------AAAAAAAAAAA ------------AAAAAAAAAAAAA ---------AAAAAAAAAAAAAAAA ---------AAAAAAAAAAAAAAAA ---------AAAAAAAAAAAAAAAA ---------AAAAAAAAAAAAAAAA ---------GAAAAAAAAAAAAAAA ---------AAAAAAAAAAAAAAAA ---------AAAAAAAAAAAAAAAA --------GAAAAAAAAAAAAAAAA ---------AAAAAAAAAAAAAAAA ---------AAAAAAAAAAAAAAAA ---------AAAAAAAAAAAAAAAA ---------AAAAAAAAAAAAAAAA ---------AAAAAAAAAAAAAAAA ---------AAAAAAAAAAAAAAAA ---------AAAAAAAAAAAAAAAA ---------AAAAAAAAAAAAAAAA ---------AAAAAAAAAAAAAAAA ---------AAAAAAAAAAAAAAAA ---------AAAAAAAAAAAAAAAA ---------AAAAAAAAAAAAAAAA ---------AAAAAAAAAAAAAAAA ---------AAAAAAAAAAAAAAAA ---------AAAAAAAAAAAAAAA- -----------BAAAAAAAAAAAA- ------------AAAAAAAAAA--- ---------------AAABA----- 
---------------------AAAA ---------------------AAAA --------------AAAAAAAAAAA ------------AAAAAAAAAAAAA ---------AAAAAAAAAAAAAAAA ---------AAAAAAAAAAAAAAAA ---------AAAAAAAAAAAAAAAA ---------AAAAAAAAAAAAAAAA ---------GAAAAAAAAAAAAAAA ---------AAAAAAAAAAAAAAAA ---------AAAAAAAAAAAAAAAA ---------AAAAAAAAAAAAAAAA --------GAAAAAAAAAAAAAAAA ---------AAAAAAAAAAAAAAAA ---------AAAAAAAAAAAAAAAA ---------AAAAAAAAAAAAAAAA ---------AAAAAAAAAAAAAAAA ---------AAAAAAAAAAAAAAAA ---------AAAAAAAAAAAAAAAA ---------AAAAAAAAAAAAAAAA ---------AAAAAAAAAAAAAAAA ---------AAAAAAAAAAAAAAAA ---------AAAAAAAAAAAAAAAA ---------AAAAAAAAAAAAAAAA ---------AAAAAAAAAAAAAAAA ---------AAAAAAAAAAAAAAAA ---------AAAAAAAAAAAAAAA- -----------AAAAAAAAAAAAA- ------------BAAAAAAAAA--- ---------------AAAAA----- 
--------------------AAAAA --------------------AAAAA --------------AAAAAAAAAAA ------------AAAAAAAAAAAAA ---------AAAAAAAAAAAAAAAA ---------AAAAAAAAAAAAAAAA ---------AAAAAAAAAAAAAAAA ---------AAAAAAAAAAAAAAAA ---------GAAAAAAAAAAAAAAA ---------AAAAAAAAAAAAAAAA ---------AAAAAAAAAAAAAAAA --------GAAAAAAAAAAAAAAAA ---------AAAAAAAAAAAAAAAA ---------AAAAAAAAAAAAAAAA ---------AAAAAAAAAAAAAAAA ---------AAAAAAAAAAAAAAAA ---------AAAAAAAAAAAAAAAA ---------AAAAAAAAAAAAAAAA ---------AAAAAAAAAAAAAAAA ---------AAAAAAAAAAAAAAAA ---------AAAAAAAAAAAAAAAA ---------AAAAAAAAAAAAAAAA ---------AAAAAAAAAAAAAAAA ---------AAAAAAAAAAAAAAAA ---------AAAAAAAAAAAAAAAA ---------AAAAAAAAAAAAAAAA ---------AAAAAAAAAAAAAAA- -----------AAAAAAAAAAAAA- ------------AAAAAAAAAA--- ---------------AAAAA----- 
---------------------AAAA ---------------------AAAA -----------------AA--AAAA ------------AAAAAAAAAAAAA ---------AAAAAAAAAAAAAAAA ---------AAAAAAAAAAAAAAAA ---------AAAAAAAAAAAAAAAA ---------AAAAAAAAAAAAAAAA ---------GAAAAAAAAAAAAAAA ---------AAAAAAAAAAAAAAAA ---------AAAAAAAAAAAAAAAA ---------AAAAAAAAAAAAAAAA ---------AAAAAAAAAAAAAAAA ---------AAAAAAAAAAAAAAAA ---------AAAAAAAAAAAAAAAA --------CAAAAAAAAAAAAAAAA --------CAAAAAAAAAAAAAAAA --------FAAAAAAAAAAAAAAAA --------FAAAAAAAAAAAAAAAA ---------AAAAAAAAAAAAAAAA ---------AAAAAAAAAAAAAAAA --------JAAAAAAAAAAAAAAAA ---------AAAAAAAAAAAAAAAA ---------AAAAAAAAAAAAAAAA ---------AAAAAAAAAAAAAAAA ---------AAAAAAAAAAAAAAA- ---------AAAAAAAAAAAAAAA- -----------AAAAAAAAAAAAA- -------------AAABAAAAA--- ------------------------- 
------------------------- ------------------------- ------------------------- -------------AAAAAAAA---- ---------AAAAAAAAAAAAA-A- ---------AAAAAAAAAAAAAAA- ---------AAAAAAAAAAAAAAA- ---------GAAAAAAAAAAAAAA- ---------AAAAAAAAAAAAAAAA ---------AAAAAAAAAAAAAAAA ---------AAAAAAAAAAAAAAAA ---------AAAAAAAAAAAAAAAA ---------KAAAAAAAAAAAAAAA ---------AAAAAAAAAAAAAAAA --------CAAAAAAAAAAAAAAAA --------GAAAAAAAAAAAAAAAA --------CAAAAAAAAAAAAAAAA --------CAAAAAAAAAAAAAAAA --------FAAAAAAAAAAAAAAAA --------FAAAAAAAAAAAAAAAA ---------AAAAAAAAAAAAAAAA --------JAAAAAAAAAAAAAAAA ---------AAAAAAAAAAAAAAAA ---------AAAAAAAAAAAAAAAA ---------AAAAAAAAAAAAAAA- ---------AAAAAAAAAAAAAAA- ----------AAAAAAAAAAAAAA- ------------AAAAAAAAAAA-- --------------AAAAAA----- ------------------------- 
------------------------- ------------------------- ------------------------- ---------------AAAAAA-A-- ---------E-AAAAAAAAAAAAA- ---------AAAAAAAAAAAAAAA- ---------AAAAAAAAAAAAAAA- ---------AAAAAAAAAAAAAAA- ---------AAAAAAAAAAAAAAA- ---------AAAAAAAAAAAAAAA- ---------AAAAAAAAAAAAAAA- ---------KAAAAAAAAAAAAAA- ---------KAAAAAAAAAAAAAA- ---------AAAAAAAAAAAAAAA- ---------AAAAAAAAAAAAAAA- --------CAAAAAAAAAAAAAAA- --------CAAAAAAAAAAAAAAA- --------FAAAAAAAAAAAAAAA- --------FAAAAAAAAAAAAAAA- ---------AAAAAAAAAAAAAAA- ---------AAAAAAAAAAAAAAA- --------JAAAAAAAAAAAAAAA- ---------AAAAAAAAAAAAAAA- ---------AAAAAAAAAAAAAAA- ---------AAAAAAAAAAAAAAA- ---------BAAAAAAAAAAAAAA- -----------AAAAAAAAAAAA-- -------------AAAAAAAAA--- ----------------AAA------ ------------------------- 
------------------------- ------------------------- ------------------------- -----------------AAAAA--- ------------AAAAAAAAAAA-- ---------EAA-AAAAAAAAAAA- ---------AAAAAAAAAAAAAAA- ---------AAAAAAAAAAAAAAA- ---------AAAAAAAAAAAAAAA- ---------AAAAAAAAAAAAAAA- ---------AAAAAAAAAAAAAAA- ---------AAAAAAAAAAAAAAA- ---------EAAAAAAAAAAAAAA- ---------AAAAAAAAAAAAAAA- ---------AAAAAAAAAAAAAAA- ---------AAAAAAAAAAAAAAA- ---------AAAAAAAAAAAAAAA- ---------AAAAAAAAAAAAAAA- ---------AAAAAAAAAAAAAAA- ---------AAAAAAAAAAAAAAA- --------JAAAAAAAAAAAAAAA- ---------AAAAAAAAAAAAAAA- ---------AAAAAAAAAAAAAAA- ---------AAAAAAAAAAAAAA-- ---------BAAAAAAAAAAAAA-- ----------AAAAAAAAAAAAA-- -------------AAAAAAAAA--- --------------AAAAAAA---- ------------------------- ------------------------- 
------------------------- ------------------------- ------------------------- --------------------A---- ------------AAAAAAAAAA--- ----------AAAAAAAAAAAAA-- ---------AAAAAAAAAAAAAAA- ---------AAABAAAAAAAAAAA- ---------AABAAAAAAAAAAAA- ---------AAAAAAAAAAAAAAA- ---------AAAAAAAAAAAAAAA- ---------AAAAAAAAAAAAAAA- ---------AAAAAAAAAAAAAAA- ---------AAAAAAAAAAAAAAA- ---------AAAAAAAAAAAAAAA- ---------AAAAAAAAAAAAAAA- ---------AAAAAAAAAAAAAAA- ---------AAAAAAAAAAAAAAA- ---------AAAAAAAAAAAAAAA- ---------AAAAAAAAAAAAAAA- ---------AAAAAAAAAAAAAAA- ---------AAAAAAAAAAAAAAA- ---------BAAAAAAAAAAAAAA- ----------AAAAAAAAAAAAA-- -------------AAAAAAAAA--- --------------AAAAAAA---- ---------------AAAAA----- ------------------------- ------------------------- ------------------------- 
------------------------- ------------------------- ------------------------- ------------------------- ------------------AAA---- --------------AAAAAAAA--- -------------BAAAAAAAAA-- -------------AAAAAAAAAA-- ------------BAAAAAAAAAAA- ------------AAAAAAAAAAAA- ------------AAAAAAAAAAAA- ------------AAAAAAAAAAAA- ------------AAAAAAAAAAAA- ------------AAAAAAAA-AAA- ------------AAAAAAAA-AAA- ------------AAAAAAAA-AAA- ------------AAAAAAAAAAAA- ------------AAAAAAAAAAAA- ------------AAAAAAAAAAAA- ------------AAAAAAAAAAAA- ------------AAAAAAAAAAAA- ------------AAAAAAAAAAAA- --------------AAAAAAAAA-- ---------------AAAAAAAA-- ---------------AAAAAAA--- ----------------AAAAA---- ------------------------- ------------------------- ------------------------- ------------------------- 
------------------------- ------------------------- ------------------------- ------------------------- ------------------------- ------------------------- ------------------------- ------------------------- ------------------------- ------------------------- ------------------------- ------------------AAA---- -----------------AAAA---- ----------------AAAAA---- ----------------AAAAA---- ----------------AAAAA---- -----------------AAA----- -----------------AAA----- ------------------------- ------------------------- ------------------------- ------------------------- ------------------------- ------------------------- ------------------------- ------------------------- ------------------------- ------------------------- ------------------------- ------------------------- 
------------------------- ------------------------- ------------------------- ------------------------- ------------------------- ------------------------- ------------------------- ------------------------- ------------------------- ------------------------- ------------------------- ------------------AAA---- ------------------AAA---- ----------------AAAAA---- ----------------AAAAA---- ----------------EAAA----- -----------------AAA----- ------------------------- ------------------------- ------------------------- ------------------------- ------------------------- ------------------------- ------------------------- ------------------------- ------------------------- ------------------------- ------------------------- ------------------------- ------------------------- 
------------------------- ------------------------- ------------------------- ------------------------- ------------------------- ------------------------- ------------------------- ------------------------- ------------------------- ------------------------- ------------------------- ------------------------- ------------------A------ -----------------EAA----- -----------------AAA----- -----------------AAA----- ------------------------- ------------------------- ------------------------- ------------------------- ------------------------- ------------------------- ------------------------- ------------------------- ------------------------- ------------------------- ------------------------- ------------------------- ------------------------- ------------------------- 
