model
size = 21 20 28, scale = 0.05, origin = -y
material 
  colors = A:#FFD700
voxels
--------------------- --------------------- --------------------- --------------------- --------------------- --------------------- --------------------- --------------------- -------------A------- --------------------- --------------------- --------------------- --------------------- --------------------- --------------------- --------------------- --------------------- --------------------- --------------------- --------------------- 
--------------------- --------------------- --------------------- --------------------- --------------------- --------------------- --------------------- --------------------- -----------AAAAAA---- --------------AA----- --------------AA----- --------------------- --------------------- --------------------- --------------------- --------------------- --------------------- --------------------- --------------------- --------------------- 
--------------------- --------------------- --------------------- --------------------- ---------A----------- ----------AAA-------- ---------AAA--------- ---------AAAA-------- -----------AAAAAA---- -------------AAAA---- --------------AAAA--- --------------A------ ---------------AAA--- -----------------A--- --------------------- --------------------- --------------------- --------------------- --------------------- --------------------- 
--------------------- --------------------- --------------------- --------------------- ---------AA---------- ---------AAAA-------- ---------AAAA-------- ---------AAAA-------- ----------AAAAAAA---- -------------AAAA---- -------------AAAAA--- -------------AAAAAA-- ---------------AAAA-- -----------------A--- --------------------- --------------------- --------------------- --------------------- --------------------- --------------------- 
--------------------- --------------------- --------------------- --------------------- -------AAAA---------- -------AAAAAA-------- -------AAAAAA-------- ---------AAAA-------- ----------AAAAAA----- --------------AAA---- -------------AAAA---- --------------AAAAA-- ---------------AAAA-- ----------------AA--- -----------------AA-- -----------------AA-- --------------------- --------------------- --------------------- --------------------- 
--------------------- --------A------------ ------AA------------- --------------------- -------AA------------ --------AAA---------- -------AAAAAA-------- --------A-AAA-------- -----------AAAAA----- -------------A-AA---- --------------A------ --------------AAA-A-- ---------------AAAA-- -----------------AAA- -----------------AAA- -----------------AA-- ------------------A-- --------------------- --------------------- --------------------- 
--------A------------ -----AAAA------------ -----AAAA------------ -----AAAA------------ -------AA------------ -------AAA----------- -------AAA----------- --------------------- --------------A------ --------------------- --------------------- ---------------AA-A-- ---------------AA-A-- ----------------AAAA- -----------------AAA- -----------------AAA- ------------------A-- --------------------- --------------------- --------------------- 
--------A------------ ------A-A------------ ------AAA------------ -----AAAA------------ -------AA------------ -------AA------------ --------------------- --------------------- --------------------- --------------------- --------------------- --------------------- ------------------A-- ----------------AAAA- -----------------AAA- -----------------AAA- ------------------AA- --------------------- --------------------- --------------------- 
--------------------- -----AA-A------------ -----AAAA------------ ----AAAAA------------ ------AAA------------ --------------------- --------------------- --------------------- --------------------- --------------------- --------------------- --------------------- ------------------A-- ------------------AA- ------------------AA- ------------------AA- ------------------AAA --------------------- --------------------- --------------------- 
--AAAA--------------- --AA-AA-------------- ---AAAA-------------- -----AA-------------- --------------------- --------------------- --------------------- --------------------- --------------------- --------------------- --------------------- --------------------- --------------------- --------------------- --------------------- --------------------- ------------------AAA ------------------AAA -------------------A- --------------------- 
---AAA--------------- ----AAA-------------- ---AAA--------------- --A-AA--------------- --------------------- --------------------- --------------------- --------------------- --------------------- --------------------- --------------------- --------------------- --------------------- --------------------- --------------------- --------------------- ------------------AAA ------------------AAA -------------------A- --------------------- 
--------------------- --AAA---------------- ---AA-A-------------- --AA-A--------------- --------------------- --------------------- --------------------- --------------------- --------------------- --------------------- --------------------- --------------------- --------------------- --------------------- --------------------- --------------------- -------------------AA ------------------AAA ------------------AAA -------------------A- 
--AAA---------------- --AAA---------------- --AAA---------------- --AAAA--------------- --------------------- --------------------- --------------------- --------------------- --------------------- --------------------- --------------------- --------------------- --------------------- --------------------- --------------------- --------------------- -------------------AA ------------------AAA ------------------AAA ------------------AA- 
--AA----------------- A-AAAA--------------- --AAAA--------------- --A-AA--------------- --------------------- --------------------- --------------------- --------------------- --------------------- --------------------- --------------------- --------------------- --------------------- --------------------- --------------------- --------------------- --------------------A ------------------AAA --------------------A ------------------AA- 
--AA----------------- --AAAA--------------- --AAAA--------------- --AAA---------------- --------------------- --------------------- --------------------- --------------------- --------------------- --------------------- --------------------- --------------------- --------------------- --------------------- --------------------- --------------------- --------------------- ------------------AAA --------------------- ------------------AA- 
--A------------------ -AAAAA--------------- -AAAAA--------------- -AA-AA--------------- --------------------- --------------------- --------------------- --------------------- --------------------- --------------------- --------------------- --------------------- --------------------- --------------------- --------------------- --------------------- -------------------A- ------------------AAA --------------------- ------------------AA- 
--AA----------------- --AAA---------------- -AAAA---------------- -AA-A---------------- --------------------- --------------------- --------------------- --------------------- --------------------- --------------------- --------------------- --------------------- --------------------- --------------------- --------------------- --------------------- -------------------A- ------------------AAA ------------------AAA ------------------AA- 
--------------------- --------------------- ---A----------------- AAAAA---------------- -AA------------------ --------------------- --------------------- --------------------- --------------------- --------------------- --------------------- --------------------- --------------------- --------------------- --------------------- --------------------- --------------------- ------------------AAA ------------------AA- ------------------AA- 
--------------------- --------------------- ---A----------------- -AAAA---------------- -AAAA---------------- ---A----------------- --------------------- ---A----------------- --------------------- --------------------- --------------------- --------------------- --------------------- --------------------- --------------------- --------------------- --------------------- -----------------AAA- -----------------AAA- -----------------AAA- 
--------------------- --------------------- ---A----------------- --AAA---------------- --AAA---------------- ----AA--------------- ---AAA--------------- ---A----------------- --------------------- --------------------- --------------------- --------------------- --------------------- --------------------- --------------------- --------------------- -----------------A--- -----------------AAA- -----------------AAA- -----------------AAA- 
--------------------- --------------------- --------------------- --A-A---------------- ---AAA--------------- ---AAA--------------- ----AA--------------- ---AA---------------- --------------------- --------------------- --------------------- --------------------- --------------------- --------------------- --------------------- --------------------- -----------------A--- -----------------AAA- -----------------AA-- -----------------A--- 
--------------------- --------------------- ---A----------------- ---AA---------------- ---AAA--------------- --AAAA--------------- --AAAA--------------- ---AAA--------------- --------------------- --------------------- --------------------- --------------------- --------------------- --------------------- --------------------- --------------------- --------------A--A--- ---------------A-AAA- -----------------AA-- -----------------A--- 
--------------------- --------------------- --------------------- --------------------- ---AAA--------------- ---AAA--------------- --AAAA--------------- ---AAAA-------------- --------------------- --------------------- --------------------- --------------------- --------------------- --------------------- --------------------- --------------------- ---------------AAA--- ---------------AAA--- --------------AA----- --------------------- 
--------------------- --------------------- --------------------- --------------------- -----A--------------- -----A--------------- ---AAA--------------- --AAAAA-------------- --------------------- --------------------- ------A-------------- --------------------- --------------------- --------------------- --------------------- ---------------A----- --------------AAA---- --------------AAAA--- --------------AAA---- --------------------- 
--------------------- --------------------- --------------------- --------------------- --------------------- ---AAA--------------- ---AAA--------------- ----AAAA------------- ------AAA------------ ------AAA------------ ------A--A----------- ----------A---------- --------------------- -----------A--------- ---------A----------- ------------AAAAA---- -----------A-AAAA---- --------------AA----- --------------------- --------------------- 
--------------------- --------------------- --------------------- --------------------- --------------------- --------------------- -----A--------------- ------AA------------- -----AAAA------------ ------AAA------------ ------AAAAA---------- -------AAAAA--------- -------A-AAAA-------- ---------AAAA-------- ---------AAAA-------- ---------AAAAAAA----- -----------A--------- --------------------- --------------------- --------------------- 
--------------------- --------------------- --------------------- --------------------- --------------------- --------------------- --------------------- --------------------- -----AA-------------- ------A-------------- ------A-A------------ --------------------- ---------AAA--------- ----------AA--------- -----------A--------- --------------------- --------------------- --------------------- --------------------- --------------------- 
--------------------- --------------------- --------------------- --------------------- --------------------- --------------------- --------------------- --------------------- --------------------- ------A-------------- --------------------- --------------------- ----------AA--------- --------------------- --------------------- --------------------- --------------------- --------------------- --------------------- --------------------- 
