model
size = 31 31 9, scale = 0.05, origin = -y
material 
  colors = A:#7B3F00 B:#FFE599
voxels
------------------------------- --------------AAAAA------------ ----------AAAAAAAAAAAA--------- --------AAAAAAAAAAAAAAAA------- -------AAAAAAAAAAAAAAAAAA------ ------AAAAAAAAAAAAAAAAAAAA----- -----AAAAAAAAAAAAAAAAAAAAAA---- ----AAAAAAAAAAAAAAAAAAAAAAAA--- ---AAAAAAAAAA------AAAAAAAAAA-- ---AAAAAAAA----------AAAAAAAA-- --AAAAAAAA------------AAAAAAAA- --AAAAAAA--------------AAAAAAA- --AAAAAAA--------------AAAAAAA- -AAAAAAA----------------AAAAAA- -AAAAAAA----------------AAAAAAA -AAAAAAA----------------AAAAAAA -AAAAAAA----------------AAAAAAA -AAAAAAA----------------AAAAAAA --AAAAAA----------------AAAAAAA --AAAAAAA--------------AAAAAAA- --AAAAAAA--------------AAAAAAA- --AAAAAAAA------------AAAAAAAA- ---AAAAAAAA----------AAAAAAAA-- ---AAAAAAAAAA------AAAAAAAAAA-- ----AAAAAAAAAAAAAAAAAAAAAAAA--- -----AAAAAAAAAAAAAAAAAAAAAA---- ------AAAAAAAAAAAAAAAAAAAA----- -------AAAAAAAAAAAAAAAAAA------ --------AAAAAAAAAAAAAAAA------- ----------AAAAAAAAAAAA--------- -------------AAAAA------------- 
--------------BBBB------------- ----------BBBB----BBBB--------- --------BB------------BB------- ------BB----------------BB----- -----BB------------------BB---- ----BB--------------------BB--- ---BB----------------------BB-- ---B------------------------B-- --B----------BBBBBB----------B- --B--------BB------BB--------B- -B--------BB--------BB--------B -B-------BB----------BB-------B -B-------B------------B-------B -B------B--------------B------B B-------B--------------B------- B-------B--------------B------- B-------B--------------B------- B-------B--------------B------- -B------B--------------B------B -B-------B------------B-------B -B-------BB----------BB-------B -B--------BB--------BB--------B --B--------BB------BB--------B- --B----------BBBBBB----------B- ---B------------------------B-- ---BB----------------------BB-- ----BB--------------------BB--- -----BB------------------BB---- ------BB----------------BB----- --------BB------------BB------- ----------BBBB----BBBB--------- 
-----------BBBBBBBBBB---------- --------BBB----------BBB------- -------B----------------B------ -----BB------------------BB---- ----B----------------------B--- ---B------------------------B-- ---B------------------------B-- --B--------------------------B- -B-------------BB-------------B -B-----------BB--BB-----------B -B---------BB------BB---------B B---------B----------B--------- B---------B----------B--------- B--------B------------B-------- B--------B------------B-------- B-------B--------------B------- B-------B--------------B------- B--------B------------B-------- B--------B------------B-------- B---------B----------B--------- B---------B----------B--------- -B---------BB------BB---------B -B-----------BB--BB-----------B -B-------------BB-------------B --B--------------------------B- ---B------------------------B-- ---B------------------------B-- ----B----------------------B--- -----BB------------------BB---- -------B----------------B------ --------BBB----------BBB------- 
----------BBBBBBBBBBBB--------- --------BB------------BB------- -------B----------------B------ -----BB------------------BB---- ----B----------------------B--- ---B------------------------B-- ---B------------------------B-- --B--------------------------B- -B----------------------------B -B-----------BBBBBB-----------B B-----------B------B----------- B----------B--------B---------- B---------B----------B--------- B--------B------------B-------- B--------B------------B-------- B--------B------------B-------- B--------B------------B-------- B--------B------------B-------- B--------B------------B-------- B---------B----------B--------- B----------B--------B---------- B-----------B------B----------- -B-----------BBBBBB-----------B -B----------------------------B --B--------------------------B- ---B------------------------B-- ---B------------------------B-- ----B----------------------B--- -----BB------------------BB---- -------B----------------B------ --------BB------------BB------- 
----------BBBBBBBBBBBB--------- --------BB------------BB------- ------BB----------------BB----- -----B--------------------B---- ----B----------------------B--- ---B------------------------B-- --B--------------------------B- --B--------------------------B- -B----------------------------B -B-----------BBBBBB-----------B B-----------B------B----------- B----------B--------B---------- B---------B----------B--------- B--------B------------B-------- B--------B------------B-------- B--------B------------B-------- B--------B------------B-------- B--------B------------B-------- B--------B------------B-------- B---------B----------B--------- B----------B--------B---------- B-----------B------B----------- -B-----------BBBBBB-----------B -B----------------------------B --B--------------------------B- --B--------------------------B- ---B------------------------B-- ----B----------------------B--- -----B--------------------B---- ------BB----------------BB----- --------BB------------BB------- 
----------BBBBBBBBBBBB--------- --------BB------------BB------- -------B----------------B------ -----BB------------------BB---- ----B----------------------B--- ---B------------------------B-- ---B------------------------B-- --B--------------------------B- -B----------------------------B -B-----------BBBBBB-----------B B-----------B------B----------- B----------B--------B---------- B---------B----------B--------- B--------B------------B-------- B--------B------------B-------- B--------B------------B-------- B--------B------------B-------- B--------B------------B-------- B--------B------------B-------- B---------B----------B--------- B----------B--------B---------- B-----------B------B----------- -B-----------BBBBBB-----------B -B----------------------------B --B--------------------------B- ---B------------------------B-- ---B------------------------B-- ----B----------------------B--- -----BB------------------BB---- -------B----------------B------ --------BB------------BB------- 
-----------BBBBBBBBBB---------- --------BBB----------BBB------- -------B----------------B------ -----BB------------------BB---- ----B----------------------B--- ---B------------------------B-- ---B------------------------B-- --B--------------------------B- -B-------------BB-------------B -B-----------BB--BB-----------B -B---------BB------BB---------B B---------B----------B--------- B---------B----------B--------- B--------B------------B-------- B--------B------------B-------- B-------B--------------B------- B-------B--------------B------- B--------B------------B-------- B--------B------------B-------- B---------B----------B--------- B---------B----------B--------- -B---------BB------BB---------B -B-----------BB--BB-----------B -B-------------BB-------------B --B--------------------------B- ---B------------------------B-- ---B------------------------B-- ----B----------------------B--- -----BB------------------BB---- -------B----------------B------ --------BBB----------BBB------- 
--------------BBBB------------- ----------BBBB----BBBB--------- --------BB------------BB------- ------BB----------------BB----- -----BB------------------BB---- ----BB--------------------BB--- ---BB----------------------BB-- ---B------------------------B-- --B----------BBBBBB----------B- --B--------BB------BB--------B- -B--------BB--------BB--------B -B-------BB----------BB-------B -B-------B------------B-------B -B------B--------------B------B B-------B--------------B------- B-------B--------------B------- B-------B--------------B------- B-------B--------------B------- -B------B--------------B------B -B-------B------------B-------B -B-------BB----------BB-------B -B--------BB--------BB--------B --B--------BB------BB--------B- --B----------BBBBBB----------B- ---B------------------------B-- ---BB----------------------BB-- ----BB--------------------BB--- -----BB------------------BB---- ------BB----------------BB----- --------BB------------BB------- ----------BBBB----BBBB--------- 
------------------------------- -------------AAAAAA------------ ----------AAAAAAAAAAAA--------- --------AAAAAAAAAAAAAAAA------- -------AAAAAAAAAAAAAAAAAA------ ------AAAAAAAAAAAAAAAAAAAA----- -----AAAAAAAAAAAAAAAAAAAAAA---- ----AAAAAAAAAAAAAAAAAAAAAAAA--- ---AAAAAAAAAA------AAAAAAAAAA-- ---AAAAAAAA----------AAAAAAAA-- --AAAAAAAA------------AAAAAAAA- --AAAAAAA--------------AAAAAAA- --AAAAAAA--------------AAAAAAA- -AAAAAAA----------------AAAAAAA -AAAAAAA----------------AAAAAAA -AAAAAAA----------------AAAAAAA -AAAAAAA----------------AAAAAAA -AAAAAAA----------------AAAAAAA -AAAAAAA----------------AAAAAAA --AAAAAAA--------------AAAAAAA- --AAAAAAA--------------AAAAAAA- --AAAAAAAA------------AAAAAAAA- ---AAAAAAAA----------AAAAAAAA-- ---AAAAAAAAAA------AAAAAAAAAA-- ----AAAAAAAAAAAAAAAAAAAAAAAA--- -----AAAAAAAAAAAAAAAAAAAAAA---- ------AAAAAAAAAAAAAAAAAAAA----- -------AAAAAAAAAAAAAAAAAA------ --------AAAAAAAAAAAAAAAA------- ----------AAAAAAAAAAAA--------- -------------AAAAAA------------ 
