model
size = 32 32 4, scale = 0.05, origin = -y
material 
  colors = A:#000 B:#222 C:#9CF
voxels
12-8B21-3B8A3B17-B7AB6AB14-2B6AB2AB6A2B11-B7AB4AB7AB9-B7AB6AB7AB7-B7AB8AB7AB6-B6AB10AB6AB5-B6AB12AB6AB3-B6AB14AB6AB2-B5AB4A2-10AB5AB2-B4AB5A2-11AB4AB-B4AB6A2-12AB4A2B3AB7A2-13AB3A2B2AB8A2-14AB2A2BAB9A2-15ABA2B11A2-16A4B10A2-17A2BAB9A2-15ABA2B2AB8A3-13AB2AB-B2AB7A3-A-10AB2AB2-B3AB6A2-2(A-)8AB3AB2-B4AB5A2-2A-8AB4AB3-B4AB16AB4AB5-B4AB14AB4AB6-B5AB12AB5AB7-B5AB10AB5AB9-B5AB8AB5AB11-2B4AB6AB4A2B14-3(B4A)B17-3B2(2AB)2A3B21-8B24-8B21-3B8A3B16-2B3C8A3C2B13-B5C8A5CB11-BA5C8A5CAB9-BA6C8A6CAB7-B8C8A8CB5-B9C8A9CB4-B9C8A9CB3-B28A2(B2-B10A2B16A)B-B7(9A2C2B6A2C9A2B)9A2C3B5A2C9AB-B10A3BAB13AB2-B10A2B2(AB)12AB2-B10A2B2AB13AB3-B9C8A9CB4-2B8C8A8C2B5-B8C8A8CB7-BA6C8A6CAB9-BA5C8A5CAB11-B5C8A5CB13-2B3C8A3C2B16-3B8A3B21-8B24-8B21-3B8A3B16-2B3C8A3C2B13-B5C8A5CB11-BA5C8A5CAB9-BA6C8A6CAB7-B8C8A8CB5-B9C8A9CB4-B9C8A9CB3-2(B28AB2-)B28AB-B7(9A2C8A2C9A2B)9A2C8A2C9AB-2(B28AB2-)B28AB3-B9C8A9CB4-2B8C8A8C2B5-B8C8A8CB7-BA6C8A6CAB9-BA5C8A5CAB11-B5C8A5CB13-2B3C8A3C2B16-3B8A3B21-8B24-8B21-3B8A3B17-B6A2B6AB14-2B6AB2AB6A2B11-B7AB4AB7AB9-B7AB6AB7AB7-B7AB8AB7AB6-B6AB10AB6AB5-B6AB12AB6AB3-B6AB7A2(B6A)B2-B5AB7ABAB6AB5AB2-B4AB7A2(BA)B6AB4AB-B4AB7A3(BA)B6AB4A2B3AB7ABAB3ABAB6AB3A2B2AB15ABAB6AB2A2BAB8ABA2BAB3ABAB6ABA2B9AB3ABAB4ABAB7A2B8AB3AB2AB5ABAB6A2BAB9AB3AB5ABAB4ABA2B2AB7A2(B4A)BAB4AB2AB-B2AB6A4BAB3ABAB4AB2AB2-B3AB13ABAB4AB3AB2-B4AB11ABA2(B4A)B3-B4AB5A5BA2(B4A)B5-B4AB9A2(B4A)B6-B5AB4A4B4AB5AB7-B5AB10AB5AB9-B5AB8AB5AB11-2B4AB6AB4A2B14-3(B4A)B17-3B2(2AB)2A3B21-8B12-
