model
size = 23 30 29, scale = 0.05, origin = -y
material 
  colors = A:#EBB471 B:#444 C:#BC9F77 D:#6E552F E:#AA8F6B F:#888 G:#777 H:#855B32 I:#FFFFFB J:#E83015
voxels
----------------------- ----------------------- ----------------------- ----------------------- ----------------------- ----------------------- ----------------------- ----------------------- ----------------------- ----------------------- ----------------------- ----------------------- ----------------------- ----------------------- ----------------------- ----------------------- ----------------------- ----------------------- -------DDDDDDDDD------- -------DDDDDDDDD------- ----------------------- ----------------------- ----------------------- ----------------------- ----------------------- ----------------------- ----------------------- ----------------------- ----------------------- ----------------------- 
----------------------- ----------------------- ----------------------- ----------------------- ----------------------- ----------------------- ----------------------- ----------------------- ----------------------- ----------------------- ----------------------- ----------------------- ----------------------- ----------------------- ----------------------- ----------------------- ----------------------- ----------------------- ------DDFGGGGGFDD------ ------DDDHHHHHDDD------ ----------------------- ----------------------- ----------------------- ----------------------- ----------------------- ----------------------- ----------------------- ----------------------- ----------------------- ----------------------- 
----------------------- ----------------------- ----------------------- ----------------------- ----------------------- ----------------------- ----------------------- ----------------------- ----------------------- ----------------------- ----------------------- ----------------------- ----------------------- ----------------------- ----------------------- ----------------------- ----------------------- ----------------------- -----DFFGFFFFFGFFD----- -----DDDHDDDDDHDDD----- ----------------------- ----------------------- ----------------------- ----------------------- ----------------------- ----------------------- ----------------------- ----------------------- ----------------------- ----------------------- 
----------------------- ----------------------- ----------------------- ----------------------- ----------------------- ----------------------- ----------------------- ----------------------- ----------------------- ----------------------- ----------------------- ----------------------- ----------------------- ----------------------- ----------------------- ----------------------- ----------------------- ----------------------- ----DFFGFGGGGGFGFFD---- ----DDDHDHHHHHDHDDD---- ----------------------- ----------------------- ----------------------- ----------------------- ----------------------- ----------------------- ----------------------- ----------------------- ----------------------- ----------------------- 
----------------------- ----------------------- ----------------------- ----------------------- ----------------------- ----------------------- ----------------------- ----------------------- ----------------------- ----------------------- ----------------------- ----------------------- ----------------------- ----------------------- ----------------------- ----------------------- ----------------------- ----------------------- ---DFFGFGFFFFFGFGFFD--- ---DDDHDHDDDDDHDHDDD--- ----------------------- ----------------------- ----------------------- ----------------------- ----------------------- ----------------------- ----------------------- ----------------------- ----------------------- ----------------------- 
----------------------- ----------------------- ----------------------- ----------------------- ----------------------- ----------------------- ----------------------- ----------------------- ----------------------- ----------------------- ----------------------- ----------------------- ----------------------- ----------------------- ----------------------- ----------------------- ----------------------- ----------------------- ---DFGFGFGGGGGFGFGFD--- ---DDHDHDHHHHHDHDHDD--- ----------------------- ----------------------- ----------------------- ----------------------- ----------------------- ----------------------- ----------------------- ----------------------- ----------------------- ----------------------- 
----------------------- ----------------------- ----------------------- ----------------------- ----------------------- ----------------------- ----------------------- ----------------------- ----------------------- ----------------------- ----------------------- ----------------------- ----------------------- ----------------------- ----------------------- ----------------------- ----------------------- ----------------------- --DFGFGFGFFFFFGFGFGFD-- --DDHDHDHDDDDDHDHDHDD-- ----------------------- ----------------------- ----------------------- ----------------------- ----------------------- ----------------------- ----------------------- ----------------------- ----------------------- ----------------------- 
----------------------- ----------------------- ----------------------- ----------------------- ----------------------- ----------------------- ----------------------- ----------------------- ----------------------- ----------------------- ----------------------- ----------------------- ----------------------- ----------------------- ----------------------- ----------------------- ----------------------- ----------------------- --DGFGFGFFGGGFFGFGFGD-- --DHDHDHDDDDDDDHDHDHD-- --------III-III-------- --------IJI-IJI-------- --------BBBBBBB-------- -------B-------B------- ----------------------- ----------------------- ----------------------- ----------------------- ----------------------- ----------------------- 
----------------------- ----------------------- ----------------------- ----------------------- ----------------------- ----------------------- ----------------------- ----------------------- ----------------------- ----------------------- ----------------------- ----------------------- ----------------------- ----------------------- ----------------------- ----------------------- ----------------------- ----------------------- --DGFGFGFGFFFGFGFGFGD-- --DHDHDAAAAAAAAADHDHD-- ------AAAAAAAAAAA------ ------AAAAAAAAAAA------ ------AAAAAAAAAAA------ ------AAAAAAAAAAA------ -------AAAAAAAAA------- -------AAAAAAAAA------- ----------------------- ----------------------- ----------------------- ----------------------- 
----------------------- ----------------------- ----------------------- ----------------------- ----------------------- ----------------------- ----------------------- ----------------------- ----------------------- ----------------------- ----------------------- ----------------------- ----------------------- ----------------------- ----------------------- ----------------------- ----------------------- ----------------------- --DGFGFBBBBBBBBBFGFGD-- --DHAAABBBBBBBBBAAAHD-- ----AAA----B----AAA---- ----AAA----B----AAA---- -----AA----B----AA----- -----AA----B----AA----- -----AA----B----AA----- ------AAAAAAAAAAA------ --------AAAAAAA-------- ----------------------- ----------------------- ----------------------- 
----------------------- ----------------------- ----------------------- ----------------------- ----------------------- ----------------------- ----------------------- ----------------------- ----------------------- ----------------------- ----------------------- ----------------------- ----------------------- ----------------------- ----------------------- ----------------------- ----------------------- ----------------------- --DGFBB---------BBFGD-- --DAABB---------BBAAD-- ---AAA-----------AAA--- ---AAA-----------AAA--- ----AA-----------AA---- -----A-----------A----- -----AA---------AA----- ------AAAAABAAAAA------ -------AAAAAAAAA------- ----------------------- ----------------------- ----------------------- 
----------------------- ----------------------- ----------------------- ----------------------- ----------------------- ----------------------- ----------------------- ----------------------- ----------------------- ----------------------- ----------------------- ----------------------- ----------------------- --A-----------------A-- --A-----------------A-- --A-----------------A-- --A-----------------A-- --A-----------------A-- --ABBB-----------BBBA-- --AABB-----------BBAA-- --AAAB-----------BAAA-- --AAAB-----------BAAA-- ---AAB-----------BAA--- ----AB-----------BA---- -----AA---------AA----- -----AA---------AA----- -------AAAABAAAA------- ----------AAA---------- ----------------------- ----------------------- 
----------------------- ----------------------- ----------------------- ----------------------- ----------------------- ----------------------- ----------------------- ----------------------- ----------------------- --A-----------------A-- --A-----------------A-- --A-----------------A-- --A-----------------A-- --A-----------------A-- --A-----------------A-- --A-----------------A-- --A-----------------A-- --A-----------------A-- --AB---------------BA-- --AB---------------BA-- --A-----------------A-- --A-----------------A-- --AA---------------AA-- ---A---------------A--- ----AAB---------BAA---- ----AAB---------BAA---- ------AAAAABAAAAA------ --------AAAAAAA-------- ----------------------- ----------------------- 
----------------------- ----------------------- ----------------------- ----------------------- ----------------------- ----------------------- ----------------------- ----------------------- -AA-----------------AA- -AE-----------------EA- -AC-----------------CA- -AC-----------------CA- -AC-----------------CA- -AE-----------------EA- -AC-----------------CA- -AC-----------------CA- -AC-----------------CA- -AE-----------------EA- -AAB---------------BAA- -AAB---------------BAA- -AA-----------------AA- -AA-----------------AA- --AA---------------AA-- --AA---------------AA-- ---A---------------A--- ---AAA-----------AAA--- -----AABAAABAAABAA----- -------AAAAAAAAA------- ----------------------- ----------------------- 
----------------------- ----------------------- ----------------------- ----------------------- ----------------------- ----------------------- ----------------------- AA--------------------- AE-------------------AA AC-------------------CA AE-------------------EA AC-------------------CA AE-------------------EA AC-------------------CA AE-------------------CA AC-------------------CA AE-------------------EA AC-------------------CA AAB-----------------BAA -AB-----------------BA- -A-------------------A- -A-------------------A- --A-----------------A-- --A-----------------A-- ---A---------------A--- ---AAA-----------AAA--- -----AAAB-----BAAA----- -------AAAABAAAA------- ----------AAA---------- ----------------------- 
----------------------- ----------------------- ----------------------- ----------------------- ----------------------- ----------------------- ----------------------- AA-------------------AA AC-------------------CA AC-------------------CA AC-------------------CA AE-------------------EA AC-------------------CA AC-------------------CA AC-------------------CA AE-------------------EA AC-------------------CA AC-------------------CA AAB-----------------BAA AAB-----------------BAA AA-------------------AA -A-------------------A- -AA-----------------AA- --A-----------------A-- --AA---------------AA-- ---AAA-----------AAA--- ----AAAA-------AAAA---- ------AAABABABAAA------ ---------AAAAA--------- ----------------------- 
----------------------- ----------------------- ----------------------- ----------------------- ----------------------- ----------------------- A---------------------A AA-------------------AA AE-------------------EA AC-------------------CA AE-------------------EA AC-------------------CA AE-------------------EA AC-------------------CA AE-------------------EA AC-------------------CA AE-------------------CA AC-------------------CA AB-------------------BA AB-------------------BA AA-------------------AA AA-------------------AA -AA-----------------AA- -AA-----------------AA- --AA---------------AA-- --AAAA-----------AAAA-- ----AAAA-------AAAA---- ------AAAABBBAAAA------ --------AAAAAAA-------- ----------DDD---------- 
D---------------------D D---------------------D D---------------------D D---------------------D D---------------------D D---------------------D D---------------------D DA-------------------AD AC-------------------CA AE-------------------EA AC-------------------CA AC-------------------CA AC-------------------CA AE-------------------EA AC-------------------CA AC-------------------CA AC-------------------CA AE-------------------EA AB-------------------BA AB-------------------BA AB-------------------BA AB-------------------BA -AB-----------------BA- -AB-----------------BA- --AB---------------BA-- --AABB-----------BBAA-- ----AABB-------BBAA---- ------AABBBBBBBAA------ --------AAADAAA-------- ----------DDD---------- 
D---------------------D D---------------------D D---------------------D D---------------------D D---------------------D D---------------------D D---------------------D DA-------------------AD AE-------------------EA AC-------------------CA AE-------------------EA AC-------------------CA AE-------------------EA AC-------------------CA AE-------------------EA AC-------------------CA AE-------------------EA AC-------------------CA AB-------------------BA AB-------------------BA AA-------------------AA AA-------------------AA -AA-----------------AA- -AA-----------------AA- --AA---------------AA-- --AAAA-----------AAAA-- ----AAAA-------AAAA---- ------AAAABBBAAAA------ --------AAAAAAA-------- ----------DDD---------- 
----------------------- ----------------------- ----------------------- ----------------------- ----------------------- ----------------------- A---------------------A AA-------------------AA AC-------------------CA AC-------------------CA AC-------------------CA AE-------------------EA AC-------------------CA AC-------------------CA AC-------------------CA AE-------------------EA AC-------------------CA AC-------------------CA AB-------------------BA AB-------------------BA AA-------------------AA AA-------------------AA -AA-----------------AA- -AA-----------------AA- --AA---------------AA-- --AAAA-----------AAAA-- ----AAAAAB---BAAAAA---- ------AAABABABAAA------ ---------AAAAA--------- ----------------------- 
----------------------- ----------------------- ----------------------- ----------------------- ----------------------- ----------------------- ----------------------- AA-------------------AA AE-------------------EA AC-------------------CA AE-------------------EA AC-------------------CA AE-------------------EA AC-------------------CA AE-------------------EA AC-------------------CA AE-------------------EA AC-------------------CA AB-------------------BA AB-------------------BA AA-------------------AA -A-------------------A- -AA-----------------AA- --A-----------------A-- --AA---------------AA-- ---AAA-----------AAA--- -----AAABA---ABAAA----- -------AAAABAAAA------- ----------AAA---------- ----------------------- 
----------------------- ----------------------- ----------------------- ----------------------- ----------------------- ----------------------- ----------------------- ----------------------- AA-------------------AA AE-------------------EA AC-------------------CA AC-------------------CA AC-------------------CA AE-------------------EA AC-------------------CA AC-------------------CA AC-------------------CA AE-------------------EA AAB-----------------BAA AAB-----------------BAA -A-------------------A- -A-------------------A- --A-----------------A-- --A-----------------A-- ---A---------------A--- ---AAAAB-------BAAAA--- -----AAAAAABAAABAA----- -------AAAAAAAAA------- ----------------------- ----------------------- 
----------------------- ----------------------- ----------------------- ----------------------- ----------------------- ----------------------- ----------------------- ----------------------- -A-------------------A- -AC-----------------CA- -AE-----------------EA- -AC-----------------CA- -AE-----------------EA- -AC-----------------CA- -AE-----------------EA- -AC-----------------CA- -AE-----------------EA- -AC-----------------CA- -AB-----------------BA- -AB-----------------BA- -A-------------------A- -A-------------------A- --A-----------------A-- --A-----------------A-- ---AAAB---------BAAA--- ---AAABA-------ABAAA--- -----AAAAAABAAAAAA----- -------AAAAAAAAA------- ----------------------- ----------------------- 
----------------------- ----------------------- ----------------------- ----------------------- ----------------------- ----------------------- ----------------------- ----------------------- --A-----------------AA- -AE-----------------CA- -AC-----------------CA- -AE-----------------EA- -AC-----------------CA- -AC-----------------CA- -AC-----------------CA- -AE-----------------EA- -AC-----------------CA- -AC-----------------CA- -AAB---------------BAA- -AAB---------------BAA- -AA-----------------AA- --A-----------------A-- --A-----------------A-- ---AAB-----------BAA--- ---AABA---------ABAA--- ----AAAA-------AAAA---- ------AAAAABAAAAA------ ---------AAAAA--------- ----------------------- ----------------------- 
----------------------- ----------------------- ----------------------- ----------------------- ----------------------- ----------------------- ----------------------- ----------------------- --A-----------------A-- --A-----------------A-- --A-----------------A-- --AC----------------A-- --AE---------------EA-- --AC---------------CA-- --AE---------------EA-- --AC---------------CA-- --AE---------------EA-- --AC---------------CA-- --ABB-------------BBA-- --ABB-------------BBA-- --AAB-------------BAA-- --AAB-------------BAA-- ---AB-------------BA--- ---ABA-----------ABA--- ----AAA---------AAA---- -----AAAAAABAAAAAA----- -------AAAAAAAAA------- ----------------------- ----------------------- ----------------------- 
----------------------- ----------------------- ----------------------- ----------------------- ----------------------- ----------------------- ----------------------- ----------------------- ----------------------- --A-----------------A-- --AA---------------AA-- --AE---------------AA-- --AC---------------CA-- --AE---------------EA-- --AC---------------CA-- --AC---------------CA-- --AC---------------CA-- --AE---------------EA-- --AAB-------------BAA-- --AAB-------------BAA-- --AAA-------------AAA-- ---AA-------------AA--- ----A-------------A---- ----AA-----------AA---- -----AA---------AA----- -------AAAABAAAA------- ---------AAAAA--------- ----------------------- ----------------------- ----------------------- 
----------------------- ----------------------- ----------------------- ----------------------- ----------------------- ----------------------- ----------------------- ----------------------- ----------------------- ----------------------- ---AA-------------AA--- ---AA-------------AA--- ---AE-------------AA--- ---AC-------------CA--- ---AE-------------EA--- ---ACE-----------ECA--- ---AEC-----------CEA--- ---ACC-----------CCA--- ---AABB---------BBAA--- ---AABB---------BBAA--- ---AAA-----------AAA--- ----AA-----------AA---- -----A-----------A----- -----A-----------A----- ------AAAAABAAAAA------ ---------AAAAA--------- ----------------------- ----------------------- ----------------------- ----------------------- 
----------------------- ----------------------- ----------------------- ----------------------- ----------------------- ----------------------- ----------------------- ----------------------- ----------------------- ----------------------- ----------------------- ----A-------------A---- ----AA-----------AA---- ----AAA---------AAA---- ----AAAAAAAAAAAAAAA---- ----AACCCECCCECCCAA---- ----AAECECECECECEAA---- ----AACECCCECCCECAA---- ----AAABBBBBBBBBAAA---- ----AAABBBBBBBBBAAA---- ----AAAAAAABAAAAAAA---- -----AAAAAABAAAAAA----- ------AAAAABAAAAA------ ------AAAAABAAAAA------ ---------AAAAA--------- ----------------------- ----------------------- ----------------------- ----------------------- ----------------------- 
----------------------- ----------------------- ----------------------- ----------------------- ----------------------- ----------------------- ----------------------- ----------------------- ----------------------- ----------------------- ----------------------- ----------------------- ----------------------- ----------------------- -------AAAAAAAAA------- ------AAAAAAAAAAA------ ------AAAAAAAAAAA------ ------AAAAAAAAAAA------ ------AAAAAAAAAAA------ ------AAAAAAAAAAA------ ------AAAAAAAAAAA------ -------AAAAAAAAA------- --------AAAAAAA-------- ---------AAAAA--------- ----------------------- ----------------------- ----------------------- ----------------------- ----------------------- ----------------------- 
