model
size = 15 32 32, scale = 0.05, origin = -y
material 
  colors = A:#E00 B:#111 C:#222 D:#EEE E:#FC0
voxels
412-2(E14-)E13-2(3E12-3E402-2(3B12-)3B27-)3E12-3E11-5C19(10-5A)10-5C86-2(3B12-)3B27-3E12-3E9-5CA3C6-9A14(6-D8A)4(6-9A)6-9C8-5A86-3B12-3B27-3E12-3E8-6CA4C4-11A4-2D9A12(4-11A)4-2D9A4(4-11A)4-11C5-9A8-5A71-3B12-3B28-2E12-3E7-7CA5C2-13A2-3D10A12(2-13A)2-3D10A4(2-13A)2-13C3-11A6-7A9-5A71-3B28-2E12-3E7-7CA5C2-13A2-3D10A8(2-13A)3(2-D12A)2-13A2-3D10A4(2-13A)2-9A4C3-11A5-9A7-7A10-3E57-3B28-2B12-3B6-8CA6C15A4D131A2(2D13A)2D28A4D71A7C3A5C-13A3-11A5-9A8-EA3E11-3E73-2B12-3B6-8CA6C15A3D87AD14AD29A2(2D13A)2D28A4D71A15C-13A3-11A5-9A7-7E9-5E11-5(CAC12-)3E6-6C3A6C2(15A3D87AD14AD29A2(2D13A)2D28A4D71A15C-13A3-11A5-9A7-7E9-5E11-5(CAC12-)3E6-15C)15A3D27A9(2D13A)2D28A4D71A15C-13A3-11A5-9A8-5E11-3E12-3B11-2(5B10-)5B11-3B22-13C2-13A2-2D11A2-13A10(2-D12A)2-13A2-3D10A4(2-13A)2-13C3-11A5-9A7-7A10-3E42-2(3B12-)3B37-13C2-13A2-2D11A2-13A10(2-D12A)2-13A2-3D10A4(2-13A)2-13C3-11A6-7A9-5A56-2(3B12-)3B38-11C4-11A4-D10A12(4-11A)4-2D9A4(4-11A)4-11C5-9A8-5A56-2(3B12-)3B54-9C6-9A14(6-D8A)4(6-9A)6-9C8-5A71-2(3B12-)3B56-5C19(10-5A)10-5C71-2(2(3B12-)3B432-)2(3B12-)3B447-2(3B12-)3B432-2(3B12-)3B282-4(3B12-)3B102-2(3B12-)2(3B267-13(3B12-))3B252-3(3B12-)3B87-5(3B12-)3B267-2(3B12-)2(3B447-3B12-)3B12-3B432-3B11-2(5B10-)5B11-3B402-3B11-5B9-2(7B8-)7B9-5B11-3B387-3B11-B3-B9-B5-B8-2(B2-)B8-B5-B9-B3-B11-3B321-
