model
size = 22 8 27, scale = 0.05, origin = -y
material 
  colors = A:#111 B:#FF9 C:#FC0 D:#EEE
voxels
---AAAAAAAAAAAAAAAAAAA ---A------------------ ---A------------------ ---A------------------ ---A------------------ ---A------------------ ---A------------------ ---AAAAAAAAAAAAAAAAAAA 
---AAAAAAAAAAAAAAAAAAA ---CBBBBBBBBBBBBBBBBB- ---CBBBBBBBBBBBBBBBBB- ---CBBBBBBBBBBBBBBBBB- ---CBBBBBBBBBBBBBBBBB- ---CBBBBBBBBBBBBBBBBB- ---ABBBBBBBBBBBBBBBBB- ---AACCCCCACCCCACCCCCA 
---AAAAAAAAAAAAAAAAAAA ---CAAAAAAAAAAAAAAAAB- ---AAAAAAAAAAAAAAAAAB- ---AAAAAAAAAAAAAAAAAB- ---AAAAAAAAAAAAAAAAAB- ---AAAAAAAAAAAAAAAAAB- ---AAAAAAAAAAAAAAAAAB- ---AACAAAAACAACACAAAAA 
---AAAAAAAAAAAAAAAAAAA ---CAAAAAAAAAAAAAAAAB- ---AAAAAAAAAAAAAAAAAB- ---AAAAAAAAAAAAAAAAAB- ---AAAAAAAAAAAAAAAAAB- ---AAAAAAAAAAAAAAAAAB- ---AAAAAAAAAAAAAAAAAB- ---AACAAAAACAACACAAAAA 
---AAAAAAAAAAAAAAAAAAA ---CAAAAAAAAAAAAAAAAB- ---AAAAAAAAAAAAAAAAAB- ---AAAAAAAAAAAAAAAAAB- ---AAAAAAAAAAAAAAAAAB- ---AAAAAAAAAAAAAAAAAB- ---AAAAAAAAAAAAAAAAAB- ---AACAAAAACAACACAAAAA 
---AAAAAAAAAAAAAAAAAAA ---CAAAAAAAAAAAAAAAAB- ---AAAAAAAAAAAAAAAAAB- ---AAAAAAAAAAAAAAAAAB- ---AAAAAAAAAAAAAAAAAB- ---AAAAAAAAAAAAAAAAAB- ---AAAAAAAAAAAAAAAAAB- ---AACAAAAACAACACAAAAA 
---AAAAAAAAAAAAAAAAAAA ---CAAAAAAAAAAAAAAAAB- ---AAAAAAAAAAAAAAAAAB- ---AAAAAAAAAAAAAAAAAB- ---AAAAAAAAAAAAAAAAAB- ---AAAAAAAAAAAAAAAAAB- ---AAAAAAAAAAAAAAAAAB- ---AACAAAAACCCCACAAAAA 
---AAAAAAAAAAAAAAAAAAA ---AAAAAAAAAAAAAAAAAB- ---AAAAAAAAAAAAAAAAAB- ---AAAAAAAAAAAAAAAAAB- ---AAAAAAAAAAAAAAAAAB- ---AAAAAAAAAAAAAAAAAB- ---AAAAAAAAAAAAAAAAAB- ---AACAAAAAAAAAACAAAAA 
---AAAAAAAAAAAAAAAAAAA ---AAAAAAAAAAAAAAAAAB- ---AAAAAAAAAAAAAAAAAB- ---AAAAAAAAAAAAAAAAAB- ---AAAAAAAAAAAAAAAAAB- ---AAAAAAAAAAAAAAAAAB- ---AAAAAAAAAAAAAAAAAB- ---AAAAAACCCACAAAAAAAA 
---AAAAAAAAAAAAAAAAAAA ---CAAAAAAAAAAAAAAAAB- ---CAAAAAAAAAAAAAAAAB- ---CAAAAAAAAAAAAAAAAB- ---CAAAAAAAAAAAAAAAAB- ---CAAAAAAAAAAAAAAAAB- ---AAAAAAAAAAAAAAAAAB- ---AAAAAACACACCCAAAAAA 
---AAAAAAAAAAAAAAAAAAA ---CAAAAAAAAAAAAAAAAB- ---AAAAAAAAAAAAAAAAAB- ---AAAAAAAAAAAAAAAAAB- ---AAAAAAAAAAAAAAAAAB- ---CAAAAAAAAAAAAAAAAB- ---AAAAAAAAAAAAAAAAAB- ---AAAAAACACACAAAAAAAA 
---AAAAAAAAAAAAAAAAAAA ---CAAAAAAAAAAAAAAAAB- ---AAAAAAAAAAAAAAAAAB- ---AAAAAAAAAAAAAAAAAB- ---AAAAAAAAAAAAAAAAAB- ---CAAAAAAAAAAAAAAAAB- ---AAAAAAAAAAAAAAAAAB- ---AAAAAACCCACCCAAAAAA 
---AAAAAAAAAAAAAAAAAAA ---CAAAAAAAAAAAAAAAAB- ---AAAAAAAAAAAAAAAAAB- ---AAAAAAAAAAAAAAAAAB- ---AAAAAAAAAAAAAAAAAB- ---CAAAAAAAAAAAAAAAAB- ---AAAAAAAAAAAAAAAAAB- ---AAAAAAAAAAAAAAAAAAA 
---AAAAAAAAAAAAAAAAAAA ---CAAAAAAAAAAAAAAAAB- ---AAAAAAAAAAAAAAAAAB- ---AAAAAAAAAAAAAAAAAB- ---AAAAAAAAAAAAAAAAAB- ---CAAAAAAAAAAAAAAAAB- ---AAAAAAAAAAAAAAAAAB- ---AACCAACCCACCCACACAA 
---AAAAAAAAAAAAAAAAAAA ---CAAAAAAAAAAAAAAAAB- ---AAAAAAAAAAAAAAAAAB- ---AAAAAAAAAAAAAAAAAB- ---AAAAAAAAAAAAAAAAAB- ---CAAAAAAAAAAAAAAAAB- ---AAAAAAAAAAAAAAAAAB- ---AACACACACACACACACAA 
---AAAAAAAAAAAAAAAAAAA ---CAAAAAAAAAAAAAAAAB- ---CAAAAAAAAAAAAAAAAB- ---CAAAAAAAAAAAAAAAAB- ---CAAAAAAAAAAAAAAAAB- ---CAAAAAAAAAAAAAAAAB- ---AAAAAAAAAAAAAAAAAB- ---AACCAACACACACACCAAA 
---AAAAAAAAAAAAAAAAAAA ---AAAAAAAAAAAAAAAAAB- ---AAAAAAAAAAAAAAAAAB- ---AAAAAAAAAAAAAAAAAB- ---AAAAAAAAAAAAAAAAAB- ---AAAAAAAAAAAAAAAAAB- ---AAAAAAAAAAAAAAAAAB- ---AACACACCCACCCACCAAA 
---AAAAAAAAAAAAAAAAAAA ---AAAAAAAAAAAAAAAAAB- ---AAAAAAAAAAAAAAAAAB- ---AAAAAAAAAAAAAAAAAB- ---AAAAAAAAAAAAAAAAAB- ---AAAAAAAAAAAAAAAAAB- ---AAAAAAAAAAAAAAAAAB- ---AACCAAAAAAAAAACACAA 
---AAAAAAAAAAAAAAAAAAA ---CAAAAAAAAAAAAAAAAB- ---CAAAAAAAAAAAAAAAAB- ---CAAAAAAAAAAAAAAAAB- ---CAAAAAAAAAAAAAAAAB- ---CAAAAAAAAAAAAAAAAB- ---AAAAAAAAAAAAAAAAAB- ---AAAAAAAAAAAAAAAAAAA 
---AAAAAAAAAAAAAAAAAAA ---CAAAAAAAAAAAAAAAAB- ---AAAAAAAAAAAAAAAAAB- ---AAAAAAAAAAAAAAAAAB- ---AAAAAAAAAAAAAAAAAB- ---AAAAAAAAAAAAAAAAAB- ---AAAAAAAAAAAAAAAAAB- ---AACACACCCACCACAAAAA 
---AAAAAAAAAAAAAAAAAAA ---CAAAAAAAAAAAAAAAAB- ---AAAAAAAAAAAAAAAAAB- ---AAAAAAAAAAAAAAAAAB- ---AAAAAAAAAAAAAAAAAB- ---AAAAAAAAAAAAAAAAAB- ---AAAAAAAAAAAAAAAAAB- ---AACACACACACAACAAAAA 
---AAAAAAAAAAAAAAAAAAA ---CAAAAAAAAAAAAAAAAB- ---AAAAAAAAAAAAAAAAAB- ---AAAAAAAAAAAAAAAAAB- D--AAAAAAAAAAAAAAAAAB- ---AAAAAAAAAAAAAAAAAB- ---AAAAAAAAAAAAAAAAAB- ---AACCCACACACAACAAAAA 
---AAAAAAAAAAAAAAAAAAA ---CAAAAAAAAAAAAAAAAB- ---AAAAAAAAAAAAAAAAAB- ---AAAAAAAAAAAAAAAAAB- D--AAAAAAAAAAAAAAAAAB- ---AAAAAAAAAAAAAAAAAB- ---AAAAAAAAAAAAAAAAAB- ---AACACACCCACACACAAAA 
---AAAAAAAAAAAAAAAAAAA ---CBBBBBBBBBBBBBBBBB- ---ABBBBBBBBBBBBBBBBB- ---ABBBBBBBBBBBBBBBBB- A--AABBBBBBBBBBBBBBBB- ---ABBBBBBBBBBBBBBBBB- ---ABBBBBBBBBBBBBBBBB- ---AAAAAAAAAAAAAAAAAAA 
---AAAAAAAAAAAAAAAAAAA ---A------------------ ---A------------------ ---A------------------ A--AA----------------- ---A------------------ ---A------------------ ---AAAAAAAAAAAAAAAAAAA 
---------------------- ---------------------- ---------------------- ---------------------- A---A----------------- ---------------------- ---------------------- ---------------------- 
---------------------- ---------------------- ---------------------- ---------------------- AAAAA----------------- ---------------------- ---------------------- ---------------------- 
