model
size = 11 32 11, scale = 0.05, origin = -y
material 
  colors = A:#111 B:#888 C:#633 D:#EEE E:#BBB
voxels
3-2DE2D6-2E3D22(6-5A)6-3A2B6-A2B2A6-B2A2B7-ABC50-D5-E4-D5-D22(4-A5-A)4-6AC4-6AB4-5ABA4-5ABC5-5B37-2(D7-D2-)21(A7-A2-)A7-4(C2-8A)C3-A2B3AC5-2BCAB25-D9-2D9-DA21(9-2A)8-2(2C9A)CB9A2C-8AC2-2A2B5A3-A2B3AB5-2BAB15-A9-ED3A6-D4A20(6-5A)6-B4A5-CB4(9A2C)-9A3-7A5-4AC6-ABC5-A9-E4A6-D4A19(6-5A)6-C2(4A6-B)10AB21AC11A-8AC3-6AB5-4AC6-A3B4-D9-ED9-DA20(9-2A)9-BA9-11AB10AB21AC-9A3-5A2B5-4AB6-A2B5-D9-ED9-DA21(9-2A)9-B20A2C9A2C-9A2-8AC3-5A2B5-ABAC16-2(D7-D2-)21(A7-A2-)A7-C2-9A2(2-8AC)2-8AB3-3A3CB5-BA3C27-2(D5-E4-)22(A5-A4-)3(6AB4-)6AB5-A2B2C39-2(2D2ED6-)22(5A6-)4AC6-4CB6-CB2CB7-2CB48-
