model
size = 32 32 30, scale = 0.05, origin = -y
material 
  colors = A:#808483 B:#586366 C:#EEE D:#200 E:#111 F:#400 G:#633 H:#222 I:#600 J:#444 K:#500 L:#800 M:#700 N:#C00 O:#C06 P:#D00 Q:#996 R:#030 S:#C36 T:#F6C U:#E00 V:#360 W:#330 X:#F9F Y:#888 Z:#F9C Aa:#B00 Ab:#F30 Ac:#555 Ad:#0CF Ae:#0FF Af:#636
voxels
7-C17-C14-D15-A15-DA13-2A941-2C17-2C11-2GA15-3A11-2G2A13-4A13-G2(B13-2A15-D)B13-2A844-3C17-3C9-D3A15-4A9-DG3A13-3A2D11-2(G2B13-3A13-)F2B13-2AB14-D2B11-2AB2(15-3B11-A2B)15-3A11-2AB17-2(A11-A19-)A11-A621-4C17-4C7-F4A15-5A7-DG4A13-4ADA9-D3B13-3AD11-D3B13-4A11-G3B13-A3B12-2(G3B11-A3B13-)D3B11-A3B13-D3A11-A3B15-2(2A11-2A17-)2A11-2A19-A9-A21-A9-F21-B9-A2(21-BA7-2A)87-A5-A2(25-A5-B)303-5C17-5C5-G5A15-5AG5-2G5A13-6AR7-G2B2A13-4AD9-D4B13-4AF9-D4B13-A4B10-D4B11-A4B11-G4B11-A4B11-FB3A11-A4B11-GB3A11-A4B12-DB2A11-2A2B13-DB2A11-4A13-GB2A11-2A2D15-3A9-2AF17-2BA9-ADF17-D2B9-2AB17-2DBA7-2A2B17-CDBA7-A3B19-BA7-AB21-2A7-2A21-3A5-3A21-3A5-2BA21-3A5-3B23-A2(5-B25-B)5-B25-2B3-2B2(25-2B3-2A)111-5C17-5C5-D5A15-6A5-D6A13-7A6-GB4A13-6A7-F3B2A13-5AF7-F4BA13-2A2BAF8-G3B2A11-2A4B9-D2B3A11-A5B9-D5A11-A5B9-D2B3A11-2A4B10-G2B2A11-3A2B11-G2B2A11-4AF11-D2B2A11-2A3D13-D3A9-3AF15-DB2A9-4A15-D2BA9-A3B15-D3BA7-A4B15-Q3BA7-A4B16-CB2A7-A3B17-B3A7-A3B17-5A5-3A2B17-5A5-B3AB17-5A5-2BA2B19-3A2(5-3B21-3B)5-2BA21-4B3-2B2A21-4B3-3AB21-4B3-2A2B23-BA2(3-2A25-2A)3-2A14-6C17-6C3-F6A15-6AG3-F7A13-6ABR4-F6A13-5A2B5-F2B4A13-5A2B5-D3B3A13-6AF6-G2B4A11-3A2BAF7-GB5A11-2A4BF7-F6A11-2A5B7-DGB4A11-3A4B9-DB3A2(11-3ABF11-D2B2A)11-4AB12-2(DB3A9-5A13-)D2B2A9-A4B13-D3B2A7-A5B13-4B2A7-A5B14-2(2B3A7-A4B15-)TB4A5-3A3B15-B5A5-3A3B15-C5A5-BA4B17-4A5-4B19-A2BA5-2BAB19-4B5-B3A19-4B5-2A2B2(19-4B5-A3B)20-2BA2(5-A2B21-3A)5-2AB12-6C17-6C3-G6A15-5ABH3-G7A13-5A3B4-2(G6A13-5A2B5-)GD5A13-5A2B6-2(D6A11-6AF7-)G6A11-4A3B7-G6A11-3A4B8-F2B3A2(11-3A2BF9-G3B2A)11-3A3B10-D2B3A9-5AB11-D2B3A9-6A11-DB4A9-2A2B2A11-T5A9-A5B11-T2B3A9-6B12-T2B2A9-5B13-T2B2(2A9-A4B13-3B)2A9-5B13-2B3A9-5B15-2(C2A9-3B17-)2AB9-A2B2(17-A2B9-3B)17-2AB9-3B18-2(2A9-2B19-)2A9-2B10-7C2A13-2A7C-D8A13-6A2BG-D8A13-5A3BR2-D7A13-5A3B3-F7A13-5A3B3-3D5A13-5A3B4-2(GD5A13-6AF5-)F6A13-3A3BF5-G6A13-2A4BF6-G2B3A13-2A3BF7-D3B2A13-2A4B7-2G3BA13-2A4B9-G2BA13-3AB11-DB2A13-4A11-D3A13-3AB11-T3A13-4B11-3BA13-4B12-8(3B13-)2BA13-3B14-CB13-2B15-QB13-2B15-DA13-2B15-2A13-BA2(15-2A13-2B)16-2(A13-B17-)A13-B9-7C2A13-2A7C-F8A13-7ABE-F8A13-6A2BH2-F7A13-5A3B3-D7A13-5A3B3-3D5A13-6A2B4-2(2D5A13-6AF5-)D6A13-4A2BF5-D6A13-3A3BM6-D5A13-2A3BD7-G2B3A13-2A3BF7-G3B2A13-3A3B8-G2B2A13-4AB9-DB3A13-5A9-D4A13-2A3B9-D4A13-A4B9-D2B2A13-A4B10-3BA13-A3B11-4B13-A3B11-D3B13-4B11-D2BA13-3BA11-D3B2(13-4B12-D2B)13-3BA12-D2B2(13-2BA)13-3A2(13-B2A)2(13-2BA)14-BA13-2B15-2A13-BA15-2A13-2A7-9C15-A7CE8A15-7A3E7A15-6A2B2-E6A15-5ABC3-E6A15-5A2B3-F2D4A15-4A3B4-2D4A15-4A2B5-2D4A15-5AF5-DB4A15-5AM5-E5A15-3A2BM6-E2(4A15-2A2BD7-D)B3A15-3A2B8-2(D3A15-4A9-)E3A15-A3B2(9-E3A15-4B)10-DBA2(15-6B8-D2B)15-A4BA8-D2B15-B5A8-D2B2(15-2B4A9-GB)15-B2A3C9-GB3(15-2A13-2B)15-2A14-2(B15-A15-)A15-A7-9C15-A7CE8A15-7AJEB7A15-8A-FB6A15-5A2BC-F2B5A15-4A3BH-2F2B4A15-4A4B2-F2B4A15-4A3B3-F2B4A15-4A2BF3-D2B4A15-5ABF3-D2B4A15-6AM4-DB4A15-5AD5-D2B3A15-5AD5-D3B2A15-5AB6-E2B2A15-5A7-EB3A15-5A7-E4A15-2A2BA7-E4A15-A4B7-D4A15-5B8-D3A15-6B7-D3A15-A3B-A7-D3A15-2A2B-A7-D2BA15-4A-A7-G3B15-4A-A8-G2B15-4A-E8-3B15-4A-C8-3B15-3A11-3B15-4A10-3B15-3AE10-3B15-3A12-2(2B15-2A13-)2B15-2A6-8C17-7CDB6A17-6AH2FB5A17-6AH-F2B4A17-4A2BJ-O3B3A17-3A3BC-D3B3A17-3A3BC2-N2B3A17-3A3B3-F2B3A17-3A2BC3-D2B3A17-4ABF3-E2B3A17-5AM4-E2B2A2(17-4AD5-D3BA)17-4AB6-E2BA17-4A7-C2BA17-4A7-DB2A17-4A7-D3A17-A2BA7-E3A17-4B8-Ae2A17-4BA7-E2A17-A2B2(-A7-G2A17-3A)-A7-A2(2B17-3A-A8-)2B17-3A-C8-2(2B17-2A11-)2B17-2AE10-2B17-2A12-2(B17-A13-)B17-A-E4-8C17-7CK2B5A17-6AE2F2B4A17-6AJ-F2B4A17-5ABH-K3B3A17-4A2BH-K3B3A17-3A3BC2-L2B3A17-3A3B3-D2B3A17-4ABC3-F2B3A17-5AF3-D2B3A17-5AM4-E2B2A17-4AM5-D3BA17-4AD5-C3BA17-3A2B6-Q2BA17-2A2B7-C2BA17-2A2B7-QB2A17-3AB7-D3A17-4A7-G3A17-4A8-G2A17-5A7-G2A17-3A-A7-D2A17-3A-A7-3A17-3A-A7-2BA2(17-3A-A8-2B)17-3AAfC8-BA2(17-2AY10-2B)17-2AE10-2B17-3A2(11-B17-A-A)11-B17-A-2E3-8C17-7CK2B5A17-6AJ2F2B4A17-6AE-F2B4A17-6AJ-D2B4A17-5ABC-F3B3A17-4A2BC2-K2B3A17-4A2B3-D2B3A17-5AB3-L2B3A17-5AC3-DB4A17-5AF4-DB3A17-4AM5-C2B2A17-3ABD5-C3BA17-2A3B6-C2BA17-A3B7-CB2A17-A3B7-C3A17-2A2B7-G3A17-3AB7-E3A17-4A8-E2A17-5A7-D2A17-3A-A7-3A17-3A-A7-2BA17-3A-A7-3B2(17-3A-A8-2B)17-3A-C8-2B17-2AAc10-BA17-2AAc10-2B17-3AE9-2B2(17-4A10-B)17-4A10-A17-A4E2-8C17-7CDB6A17-6AJO2B5A17-6AJ-K2B4A17-6AC-D2B4A17-6AC-N2B4A17-7A2-N2B3A17-4A2B3-F2B3A17-3A3B3-OB4A17-3A2BC3-L5A17-4ABF4-5A17-4AM5-QB3A17-2A2BD5-C2B2A17-A4B6-CB2A17-A3B7-B3A17-A3B7-4A17-A3B7-E3A17-2A2B7-D3A17-4A8-D2A17-5A2(7-3A17-3A-A)2(7-3B17-3A-A)8-2B17-3A-A8-2B17-3A-C8-2(2B17-2AY10-)2A17-2AE10-2A3(17-3A11-B)17-2A2E3-8C17-7CK7A17-6AEKB6A17-6AJ-DB5A17-6AC-L2B4A17-7A-L3B3A17-4A2BA2-L3B2A17-3A3B3-D3B2A17-2A4B3-D2B3A17-2A3BC3-OB4A17-3A2BF4-D4A17-4AM5-C4A17-2A2BD5-Q4A17-A3BD6-3(4A17-A3B7-)4A17-2A2B7-4A17-4A8-3A17-5A2(7-3A17-3A-A)2(7-3B17-3A-A)8-2B17-3A-E8-2B17-3A-C8-2(2B17-2A11-)2A17-2AE10-2B17-2A12-2(B17-A13-)B17-A2E4-9C15-A7CK8A15-7AEO8A15-7AJ-D7A15-7AH-D3B4A15-8A-DO3B3A15-4A4B2-O3B3A15-3A4B3-O3B3A15-3A3BM3-F3B3A15-3A3BM3-2LB4A15-3A3BF4-L5A15-4ABM5-C5A15-4ABM5-6A15-3A2BD6-2(5A15-2A3B7-)C4A15-3A2B7-5A15-4AB7-5A15-5A8-2C2A15-6A7-4A15-3AJ2A7-4A15-6A7-2B2A15-6A7-3BA2(15-6A8-3B)15-3A3C8-2BA15-3A11-B2A15-4A10-3A15-3AE10-3B15-3A12-2(2B15-2A13-)2B15-2A6-9C15-A7CK8A15-7AHD8A15-7AH2-D6A15-7A3-O2B4A15-7A3-F3B3A15-4A3B4-L2B3A15-3A3B5-L2B3A15-3A2BM5-N2B3A15-3A2BM5-LB4A15-3A2BM6-N4A15-4AD7-C4A15-4AD7-5A15-4AD8-4A15-2ABD9-C3A15-A2BD9-C3A15-A3B9-4A15-2A2B9-Q3A15-4A10-C2A3(15-3A11-3A)15-B2A11-B2A15-2BA12-2(BA15-2B13-)2A15-2B13-2A15-BA13-2A15-2A13-2B15-2A14-2(B15-A15-)B15-A8-9C13-2A7C-D8A13-8AG-3N6A13-8AR2-2N6A13-8A3-LB6A13-8A3-D2B5A13-6A2B4-D2B4A13-5A2B5-D2(2B4A13-4A2BM5-L)2B4A13-5A2B6-N5A13-5AD7-L5A13-5AM7-D5A13-3A2BAd8-D4A13-2A2BD9-Q2(4A13-A4B9-C)4A13-2A3B9-Q4A13-3A2B10-4A13-3AJ11-4A13-A2BA2(11-4A13-4B)11-4A13-3BJ12-4(3A13-3B13-)3A13-2BA13-B2A13-3A14-BA2(13-2A15-2B)13-2A8-9C13-9C-2D7A13-9A-3N6A13-8AR2-2N6A13-8A3-F7A13-8A3-OB6A13-8A4-LB5A13-6AM5-O2B4A13-5ABM5-2D2B3A13-5A2B5-4D3A13-6AD6-3D3A13-5AD7-LA2B2A13-5AD7-L4BA13-2A2B2D9-L2(2BA13-A3B11-D)B2A13-A3B11-D3A13-A3B11-4A13-2A2B12-3A13-A2B13-3A13-2BH13-2BA5(13-3B)14-BA13-BJ15-2A13-2B15-2A13-BJ15-DA13-2B15-LA13-2B15-DA13-BA16-2(K13-A17-)A13-A10-10C9-10C3-D9A9-9AG3-2N8A9-9AR4-N8A9-9A5-L8A9-8AD5-3D6A9-8AM6-LD6A9-7AM7-D2B5A9-8A7-D3B4A9-8A7-N2D2B3A9-7AD8-2D2B3A9-6AC9-4B3A9-6AD9-D4B2A9-4A2BD10-2(4B2A9-3A3B11-)3B3A9-3A3B11-2B4A9-3A2BU11-6A9-4A2B12-5A9-2A2BJ13-2B3A9-A4B13-3B2A9-4BH13-4BA9-4BJ13-5B9-4BJ15-2(3B9-3B17-)D2B9-2BJ17-N2A9-3B17-N2B9-3B17-L2B9-3B18-KB9-2B19-DB9-2B19-KB9-2A11-12C5-12C3-D11A5-12A3-2O10A5-12A4-F10A5-11A5-L10A5-10AD5-3D2B6A5-10AD6-LD2(3B5A5-10A7-2K)3B5A5-10A7-3D3B4A5-9AC9-D3B4A5-4A2B2A11-4B4A5-3A4BA11-4B4A5-3A5B12-3B4A5-4A3B13-3B4A5-5A2B13-3B4A5-5ABH13-2B5A5-6AB13-7A5-6AH14-6A5-4ABJ15-2B4A5-3A2BH15-3B3A5-2A3BH15-4B2A5-A4BJ15-5BA5-A5B17-4B5-A3B19-D3B5-A3B19-2IBA5-A2BJ19-2I2A5-4B19-I2BA5-4B19-I3B5-4B20-2DB5-3B21-ISB5-A2B21-KIB5-3A13-27C5-K25AG5-D25AR6-O10A2X12A7-OA2B7A2XZ11A7-2D3B7A2Z11A8-D2(4B18A9-K)4B18A9-5B13A2B3A10-4B12A4BA2(11-4B11A6B)13-2BA2B9A3B15-6B9A2B15-6B10AU15-B2A2B11AH15-16AU16-ID4A2B5A2H17-BI3A4B5AB17-2B3A4B4ABH17-4B2A2B4ABIJ17-5B6A2BIB19-BDB2A2B2A2I21-DIBA4BAIB21-ID9B21-IDA8B21-LD2A7B21-SIB2A2BA3B23-KAa4AB25-IKAa4A25-S2KAa3A15-27C5-K25AG5-4D17A2B3AW7-2DB15A4BA9-4B14A4BA9-5B14A2B2A10-4B17A11-D3B17A11-4B17A11-6B10A4BA12-2(6B8A5B13-)6B8A5B15-5B7A3B17-6B7AUB17-BI4B8AH17-IP3B8A2H17-ID2B2A2B5AAbJ19-D2A4B4A21-2D6BA2D21-ID6BA2D21-DPA4B2A2I21-BDBA2B3ADS23-I2D2BDP25-DIL2DLS25-3DIS2I25-A3B2IB25-A6B25-KA5B112-25C7-K19A2B2AG7-3D16A4BEW9-D2B13A4BE11-4B12A4BE11-4B13A3BE12-3B14ABE13-3B16A13-5B14A13-6B5A2B2A4B15-2(5B3A6BC17-)5B4A2BA3B19-BI2B6AC21-ID2B5ACH21-DI2B5AAbH21-I3B5A2H21-7B3AH23-4BDID25-3BI2PD25-3I2PIP25-2DPI2BA25-DBD2BAD305-23C9-K17A4BE9-17A5BE11-2B13A4B13-3B3A2B7A3BJ13-3B2A4B6A3BE14-2B2A4B7AJC15-2B3A2B8AJC15-5B5A2B3A2C15-6B3A4B2ACB17-4B2A4BCEC19-4B2A4BCBC19-4BP2A3B3C22-2PIA3C25-2D3A2C25-2B4AU25-2B3A2J25-5BAH466-21C11-AE15A2BHB11-16A3BHB13-AE3A2B7ABEV15-B3A4B6AB2J15-2BA6B5ABHJ17-AE5B3AHCE19-2AE3B4AHCE19-5B2A3BCEJ19-2BIB2A4BCEC22-2ICH3C25-PI5C25-IPI3CH628-17C15-EG13AGB15-EV13AEG17-HJH3B4A2JE19-EHJ4B3A2JE19-AEH4B3AJHE22-JHBEJHE25-EHCBEHE25-BE2CEBE25-2AE4C726-13C19-JH2GHGAHAJA2G19-HJVWE2(HA)GJVH22-EJEGAHV25-EHEWAHE25-JEBEJHE844-
