model
size = 31 32 22, scale = 0.05, origin = -y
material 
  colors = A:#808483 B:#586366 C:#111 D:#222 E:#100 F:#500 G:#200 H:#777 I:#600 J:#800 K:#700 L:#A00 M:#888 N:#B00 O:#400 P:#D00 Q:#F33 R:#E00 S:#C03 T:#300 U:#900 V:#C33 W:#C00 X:#F03 Y:#933 Z:#001 Aa:#FF0 Ab:#903 Ac:#C60 Ad:#603 Ae:#966 Af:#633 Ag:#444 Ah:#F00 Ai:#303 Aj:#333 Ak:#F30 Al:#39F
voxels
694-D2(5-D23-2C5-2C23-C)5-D179-2(AB3-2B24-)2A3-BA335-D3-C25-2(D5-D24-)D5-C24-C5-C23-2D5-2C21-D-C5-D-D21-2D5-CD21-D-D5-D-D2(21-DC5-2D-D19-D-D5-3D)21-2D5-2D23-D5-D146-2(3AB3-2B2A20-)4A3-B3A22-2A3-2A24-2A3-AC24-2A3-2C24-2A2-3C24-2A-4C24-2A4CA24-A3C-AB24-3C2-AB24-2C3-2A24-CA3-2A24-DA3-2A24-A5-A23-3(DA5-AD22-)DA5-A2D20-2DA5-A2D20-D-A5-ADC20-2DA5-A2D19-3DA5-A3D18-C2DA5-A3D19-3D5-4D18-4D5-3DC19-2DC5-2DC21-2D5-2C23-C5-C114-4AB3-2B3A18-5A3-B4A18-2B3A3-4AC19-3(2B2A3-2A2C20-)2B2A3-2ACA20-B3A3-2A2B3(20-4A3-A3B)20-AC2A3-A3B20-2C2A3-2A2B20-2C2A3-4A20-CDA5-3A20-C3(2A5-3A20-D)2A5-3A20-3A5-3A19-D3A5-4A17-CD3A5-4AB16-C4A5-5A17-4A5-4A18-D3A5-3AD18-2D2A5-2A2D18-3DC5-C3D19-2DC5-3D21-CD5-2C23-D5-D82-2(5A5-5A16-)3B2A5-4AC17-3(3BA5-3AC18-)3BA5-4A18-2B2A5-A3B4(18-4A5-4B)18-4A5-A3B18-4A5-4A2(18-C3A5-3AB)18-C3A5-4A17-2C3A5-5A15-2CD3A5-4A2B13-A2CD3A5-4A3B11-2A2C4A2(5-4A4B10-A2C5A)5-5A3B11-2C5A5-7A13-C5A5-6A15-5A5-5A17-4A5-4A18-4D5-4D19-3D5-2DC21-DC5-2D23-D5-C50-2B2A2F7-4A14-2B2A2F7-3AC14-3BA2F7-3AC15-2(3B-F7-2AC16-)3B-F7-3A16-3B-F7-2AB16-2BA6(2F7-3B16-3A)2F7-A2B16-3A2F7-A2B15-B3A2F7-A3B13-BAC2A2F7-A4B11-B2AC2A2F7-2A4B9-3A2C2A2F7-3A4B7-2(8A2F7-2A6B6-)8A2F7-3A4BA6-8A2F7-4A2B2A6-M7A2F7-8A7-A2C4A2F7-7A9-3C5A5-8A11-2C5A5-6AH13-C5A5-6A16-3DC5-C3D20-2D5-2D22-2D5-2C48-2(3BA11-3AC12-)3BA11-3AC13-3B11-2AC14-3B11-2AB14-3B11-A2B14-3B11-3B14-B2A3(11-3B14-3A)11-2BA14-3A11-B2A14-3A11-A2B2(14-B2A11-3B)13-2B2A11-4B11-3B2A11-5B9-3B3A11-A4BA7-7A11-3A2B2A5-2(8A11-2A4B2A4-)8A11-3A2B3A4-M7A11-8A4-8A11-3A4HC5-C6A11-3A4H7-M8A5-6A3H9-C7A5-6AHC11-2C5A5-4AHAH15-4A5-4A18-2C2D5-3DC20-CD5-2D48-2(3B13-2AD12-)3B13-3A13-BA13-2A4(14-2B13-2B)14-BA2(13-2B14-2A)2(13-2A14-2A)13-AB14-BA2(13-2B)A13-3B11-3BA13-4B9-4BA13-4BA7-4B2A13-A2B3A5-7A13-7A3-4(8A13-8A2-)8A13-2A6H3-C6A13-2A5H5-C8A7-5A4H7-M7A7-5A3H9-3C4A7-5A2H13-4A7-3AC17-3D7-3D20-D7-D47-2(4B13-3AC10-)3BA13-4A11-2BA13-3A4(12-3B13-3B)12-2BA2(13-3B12-3A)2(13-3A12-3A)13-3A12-B2A13-A2B12-2BA13-3B10-4BA13-4BA7-4B2A13-A2B3A5-2A2B3A13-7A3-6(8A13-8A2-)8A13-8A3-9A9-9A5-2M6A9-6A2C7-3C4A9-6AC11-C3A9-2A2C16-2D9-2D19-D9-D46-2(3B15-3A10-)2BA15-3A11-BA15-2A4(12-2B15-2B)12-BA2(15-2B12-2A)3(15-2A12-2A)15-2A12-BA15-2A9-4BA15-5A5-2A2B2A15-6A3-2(7A15-7A2-)7A15-7A-8A2(15-16A)15-8A-2(7A15-7A2-)9A11-9A3-M7A11-7AC5-3C4A11-7A9-2C2A11-A2CA15-D11-C18-C11-C45-2(3A15-3A10-)3A15-3A11-2A15-2A12-BA15-2A2(12-2B15-2B)12-BA2(15-2B12-2A)4(15-2A12-2A)15-2A11-3A15-3A8-5A15-5A5-6A15-6A3-7A15-7A2-7A15-7A-8A4(15-16A)15-8A-7A15-7A2-9A11-9A3-M7A11-8A4-M7A11-7AD5-D4C2A11-4AHDH12-D11-D18-D11-C45-2(3A15-3A10-)3A15-3A11-10(2A15-2A12-)2A15-2A11-3A15-3A8-5A15-5A5-6A15-6A3-7A15-7A2-7A15-7A-8A4(15-16A)15-8A-7A15-7A2-9A11-9A3-8A11-8A4-D7A11-7AD4-3D3C2A11-2AH2A3D2(11-D)18-C11-C18-D11-C14-2(3A15-3A10-)3A15-3A11-10(2A15-2A12-)2A15-2A11-3A15-3A8-5A15-5A5-6A15-6A3-7A15-7A2-7A15-7A-8A4(15-16A)15-8A-7A15-7A2-9A11-9A3-8A11-8A4-DAM5A11-7AD5-2MD2C2A11-2A2CA2D12-2(D11-D18-)D11-D14-3A15-3A10-3A15-2AD10-3A15-3A11-11(2A15-2A12-)2A15-2A9-5A15-5A5-6A15-6A3-2(7A15-7A2-)7A15-7A-8A2(15-16A)15-8A-2(7A15-7A2-)9A11-9A3-8A11-7AC5-PMC4A11-6AC9-2C2A11-2A2C15-D11-D18-C11-C18-D11-D14-2(4A13-3AC10-)4A13-3AC11-3A13-2AC10(12-3A13-3A)12-3A13-A2B10-5A13-4BA7-6A13-4B2A5-7A13-A2B4A3-5(8A13-8A2-)8A13-6AHA2-P7A13-6AHA3-P8A9-8AH5-C7A9-8A7-M6A9-6AH11-2C2A9-4A16-CD9-2D18-CD9-2D19-C9-DC15-2(3A13-2AC12-)3A13-2AC13-2A13-AC9(14-2A13-2A)14-2A13-AB14-2B13-2B12-A3B13-4B9-A4B13-5B7-2A4B13-4B2A5-3A4B13-A2B4A3-5A2BA3(13-8A2-8A)13-8A2-2AC5A13-6AHA3-MC5A13-6AH5-C8A7-8AC7-C7A7-7AH9-2M5A7-4A3C12-2C3A7-4A19-D7-D22-C7-D22-D7-D17-2(4A11-3AC12-)4A11-3AC13-4(3A11-2AC14-)5(3A11-3A14-)A2B11-3A14-3B11-A2B2(14-3B11-3B)12-5B11-2BR2B9-6B11-5BR7-A6B11-A4B2A5-3A4BA11-A2B5A4-4A2B2A11-4B4A4-P7A11-4B4A4-8A11-A2B5A4-PC6A11-5A3H5-C6A11-B4A2H7-W14A4B3AC9-2M12A4B2AC11-MAC11A2BHAH15-C12A21-C4D2C24-D6C24-2(D3C)18-4A9-4A14-2A2B9-4A14-A3B9-B3A15-3B9-B2A16-3B9-3A2(16-3B9-2AC)16-A2B9-2AC16-2AB9-2AC16-3A9-3A16-2AB3(9-3A16-3B)9-2AB3(16-3B9-A2B)13-3BF2B9-A3BAaB9-B4FBA9-2ABAaAcAaA7-3F4BA9-A4BAcRA6-2F4B2A9-6B2A6-F2W5A9-6B2A6-FP6A9-A4B3A6-CWP5A9-4B2A2H7-2W5A9-3B3AH9-G12A6B2A11-12A6BA14-3C8A4B140-A2B2A5-2B3A16-4BA5-3B2A16-5B5-4BA17-4BAAjAg2A4B18-4BADAfYAe3BA18-4BV3GSIE2A18-4BGQFVGKAi2A18-4BXQF2GAdCAC18-4B2FGRSDZAC18-A2B3EINGZ2AC18-2B2EGEG2OFEAC18-2BEOQPUEG2F2A18-2B2E2G3EOIFA18-2B5EG2E2IA18-4BJKFG2E2IA18-2BEGJKFGEGIFB18-AhVSLJKGTOFKJB18-SVSLJGIK2IKEA18-QVSLGJY2JKOAB15-FX2QXAhEGIUJKLA3B2R11-WNG2NA2EG2UJE2A2BRAcAaR10-WP3NA3ELAb2F2E2RAk2BAa10-GWP3A3ELJFI5E3B11-WG3A3EILJITG3E2B13-5A3ETIFT4EB14-3ACA4E5G3B16-3CA7E2B173-3BA8BA18-4BA8B18-4B3A6B18-4BAAjAg2A3B19-4BADAfYAe3B19-4BV3GSIEA19-4BGQFVGKAiA19-4BXQF2GAdCA19-4B2FGRSDZA19-A2B3EINGZAC19-2B2EGEG2OFEC19-2BEOQPUEG2FC19-2B2E2G3EOIF19-2B5EG2E2I19-4BJKFG2E2I19-2BEGJKFGEGIF19-2GSLJKGTOFKJ19-GVSLJGIK2IKE19-GVSLGJY2JKOA19-QXAhEGIUJKLAB19-NP2EG2UJE2AB19-NA3ELAb2F2ER19-GA3ELJFI3E19-2A3EILJITGE19-2AC3ETIFTAlE19-A2C4E5G206-2N9B20-11B20-3BA7B22-BAGAg2IG24-BADAfYAeG24-BV3GSI24-BGQFVGK24-BXQF2GAd24-B2FGRSD24-3EINGZ24-2(EG)2OF24-OQPUEGF24-E2G3EO24-4EG2E24-BJKFG2E24-GJKFGEG24-LJKGTOF24-LJGIK2I24-LGJY2JK24-EGIUJKL24-EG2UJEA24-2ELAb2FE24-2ELJFIE24-2EILJIT24-3ETIFT241-2I2G3B24-N2ING2B24-BNGINGB911-
