model
size = 32 21 31, scale = 0.05, origin = -y
material 
  colors = A:#010101 B:#1E1E1E C:#0D0D0D
voxels
304-C32-C638-A31-2C31-A606-2A30-A31-AC31-C483-2A30-C31-C26-2A30-3A29-3A30-C483-2A29-3AB28-AC26-3A-AC26-A-A2(29-3A)412-A31-2A31-A35-4A25-A2-AC25-6A26-2A-2A28-A-A29-3A380-2(2A30-)3A29-3A30-2A2-3A25-3A-A26-6A26-2A-2A27-2A-2A28-3A347-2A30-3A3-AB24-4A2-2AB24-4A-2A22-A2-4A-2A25-7A25-6A26-2A-4A25-A3-A27-2A-2A28-4A29-C30-2C29-2AC22-2A-4A2C21-2B2-2A4C26-2C162-2A4-B25-2A4-AB22-5A2-4A2(21-9A-A)21-5A-5A21-11A24-A3-4A24-A3-A27-2A2-A28-4A27-5A25-7A22-9A21-9AC19-BCA2C6AB21-2B2C2AB-2B25-3B29-B106-A23-2A6-2A22-2(3A5-3A21-)11A21-A-2A3-2A-A21-5A5-A21-4A3-4A23-2A3-3A24-3A2-2A26-6A25-7A23-8A21-5A3-2AB19-5A3-3AB19-2C3A-5AB21-B3ABA2B26-2B-C128-A8-B21-2(2A8-2A20-)2A7-3A20-3A6-3A20-A9-2A19-3A8-2A18-5A6-3A16-2A2C3A5-3A16-A-ACB4A4-2A24-2A4-A24-3A3-2A22-4A3-2A21-4A4-3A20-3A5-3A21-5A-2A26-AC2A31-C95-A8-B22-A8-2A20-2A8-2A19-3A8-3A3(18-2A10-2A)16-4A10-2A15-4A10-2A14-5A2-A7-3A13-10A5-3AB13-4AC2B3A5-A19-C2-4A4-2A21-4A5-A22-3A5-2A22-3A4-2A23-7A27-2B158-2A8-2A20-2A8-2A19-3A9-3A17-A12-3A15-2A12-3A15-3A11-3A13-4A11-3A12-B3A13-2A11-AC3A13-2A11-4A13-3AB11-12A5-A4B12-2ACA2B3A5-2A19-2BA-2A5-AB22-3A4-2A23-7AB25-2C2B220-A10-A19-2A9-4A15-3A10-2A-3A13-3A14-3A12-3A13-4A11-4A12-3A2B9-5A12-2AC9-B3A16-2A8-4A17-2A10-B3A6-2A6-5A8-2B4CA-5A5-2A14-2B6A2-A5-2A16-4B3-8A24-5A2B217-2A7-3A18-3A8-4A16-4A9-4A14-4A11-5A11-3A17-3A9-3A18-2A10-4A13-3A2B8-5A13-2A2C7-C4A15-2A7-B4A17-2A9-B2A8-2A4-6A10-B2C2A2-10A2C16-5A3-5A2C25-A2B2A2B217-2A7-2A19-4A7-3A16-B3A10-3AB14-2A13-3AB12-2A14-4A10-3A15-6A8-3A20-AB7-5A16-3AB8-5A12-2ABA8-2C5A12-2A9-C5A14-2A10-6A4-11A12-5C10AB21-2A5-BA251-3A6-3A18-B3A8-3A15-B3A10-4A15-3A13-3A2B9-3A14-6A7-4A15-6A7-2A19-5AB5-4A17-5A8-5A12-4A11-6A10-2AB12-8A8-2A14-9A-5AB17-C5A-2AB23-A229-A6-A21-B3A6-3AC16-B3A9-4A14-5A10-4A14-3A11-A-3A-A9-3A15-3A-A5-5A16-3A8-B2A18-7A5-B5A14-4A12-2ABA11-2AC17-2A9-4A18-2A7-C2A22-7A281-2A4-2A20-B5A4-3A-C16-4A9-4A13-B5A10-4AB13-3A11-6A10-5A11-A2-3A4-2B2AC4A14-4A7-B5A15-4A9-7A11-4A14-2B2A9-2AC18-3A8-AB20-5A-3AC27-BA284-6A23-5A2-4A20-3A7-6AB15-2A10-5A14-2A11-6A12-3A8-A2-3A-3A8-C5A8-2A3-4A2(9-6A)13-5A8-3AB18-3A8-AC20-4A3-3AC22-6A30-B286-4A25-9A21-4A6-3A3-A14-2A11-3A-2A13-2A11-7A12-2A8-A2-7A12-2A8-2A-6A13-4A7-6A16-5A4-4A20-11A22-10A24-3B348-8A21-5A4-4A18-3A9-4A2-A12-2A-2A8-4A2-2AB10-3A-2A8-7AB11-7A2-11A13-15A19-10A24-6A28-2B380-6A23-11A18-5A-10A16-5A-6A-4A15-16A-C4AB9-16A23-4A-3A30-A440-2A2-2A24-4A2-3A19-16A15-5A-7A-4A14-18A3-C11-3A6-A-5A28-3A30-B440-2A2-2A25-3A2-3A21-5A3-5A16-7A5-6A13-6A7-6A14-3A10-2AB30-A31-B440-A3-2A25-2A3-2A21-6A3-5A15-8A5-6A13-6A8-5A13-3A12-A2B29-A31-B440-A4-A25-BA3-2A21-4A7-2A16-2A-4A7-5A12-CAC-2A9-5A13-C15-AB29-2A502-2A4-A52-3A9-3A-A12-BC2-A11-4A30-2B28-2A502-B5-B52-2A11-2A14-BC15-3A30-2B29-A502-B5-B52-A13-A14-B16-A-2A30-B29-A561-A47-2A30-B454-
