model
size = 30 15 12, scale = 0.05, origin = -y
material 
  colors = A:#FC3 B:#36F C:#BBB
voxels
-----ABBBA----------ABBBA----- ---BABAAABAAAAAAAAAABAAABAB--- --BABABBBABBBBAABBBBABBBABAB-- -AAABABABAAABBBBBBAAABABABAAA- -BBBBBAABBBBAAAAAABBBBAABBBBB- BBBBAABBBAABBBAABBBAABBBAABBBB AABBABABABABBBBBBBBABABABABBAA BAABBBBBBBAAAAAAAAAABBBBBBBAAB ABABBBBAAABBAABBAABBAAABBBBABA BBBAABABAAAAABAABAAAAABABAABBB -BBBBABABBBAABBBBAABBBABABBBB- -ABBABABABBBABBBBABBBABABABBA- --ABBBABBBBAABBBBAABBBBABBBA-- ---BABBBBAAABBBBBBAAABBBBAB--- -----BBBBA----------ABBBB----- 
-----ABABB----------BBABA----- ---AAAAAAABBAABBAABBAAAAAAA--- --AAAAAAAAAAAAAAAAAAAAAAAAAA-- -AAAAAAAAAAAAAAAAAAAAAAAAAAAA- -AAAAAAACCCCAAAAAACCCCAAAAAAA- BAAAAAACCCCCCAAAACCCCCCAAAAAAB AAAAAACCCCCCCCAACCCCCCCCAAAAAA BAAAAACCCCCCCCAACCCCCCCCAAAAAB AAAAAACCCCCCCCAACCCCCCCCAAAAAA BAAAAACCCCCCCCAACCCCCCCCAAAAAB -AAAAAACCCCCCAAAACCCCCCAAAAAA- -AAAAAAACCCCAAAAAACCCCAAAAAAA- --AAAAAAAAAAAAAAAAAAAAAAAAAA-- ---AAAAAAABBAABBAABBAAAAAAA--- -----ABABB----------BBABA----- 
-----ABABA----------ABABA----- ---AAAAAAABBBBBBBBBBAAAAAAA--- --AAAAAAAAAAAAAAAAAAAAAAAAAA-- -AAAAA------------------AAAAA- -AAAAA------------------AAAAA- AAAAAA------------------AAAAAA BAAAAA------------------AAAAAB AAAAAA------------------AAAAAA BAAAAA------------------AAAAAB AAAAAA------------------AAAAAA -AAAAA------------------AAAAA- -AAAAA------------------AAAAA- --AAAA------------------AAAA-- ---AAAAAAABBBBBBBBBBAAAAAAA--- -----ABABA----------ABABA----- 
-----BAAAB----------BAAAB----- ---AAAAAAAABBBBBBBBAAAAAAAA--- --AAAABABBBBBBBBBBBBBBABAAAA-- -AAAAA------------------AAAAA- -AAAAA------------------AAAAA- BAAAAA------------------AAAAAB BAAAAA------------------AAAAAB BAAAAA------------------AAAAAB BAAAAA------------------AAAAAB BAAAAA------------------AAAAAB -AAAAA------------------AAAAA- -AAAAA------------------AAAAA- --AAAA------------------AAAA-- ---AAAAAAAABBBBBBBBAAAAAAAA--- -----BAAAB----------BAAAB----- 
-----BAABA----------ABAAB----- ---AAAAAAABAABAABAABAAAAAAA--- --AAAA------------------AAAA-- -AAAAA------------------AAAAA- -AAAAA------------------AAAAA- BAAAAA------------------AAAAAB BAAAAA------------------AAAAAB AAAAAA------------------AAAAAA BAAAAA------------------AAAAAB BAAAAA------------------AAAAAB -AAAAA------------------AAAAA- -AAAAA------------------AAAAA- --AAAA------------------AAAA-- ---AAAAAAABAABAABAABAAAAAAA--- -----BAABA----------ABAAB----- 
-----BBAAA----------AAABB----- ---AAAAAAAABBBAABBBAAAAAAAA--- --AAAA------------------AAAA-- -AAAAA------------------AAAAA- -AAAAA------------------AAAAA- AAAAAA------------------AAAAAA BAAAAA------------------AAAAAB BAAAAA------------------AAAAAB BAAAAA------------------AAAAAB AAAAAA------------------AAAAAA -AAAAA------------------AAAAA- -AAAAA------------------AAAAA- --AAAA------------------AAAA-- ---AAAAAAAABBBAABBBAAAAAAAA--- -----BBAAA----------AAABB----- 
-----ABBBB----------BBBBA----- ---AABBAABBBBBAABBBBBAABBAA--- --AAAB------------------BAAA-- -AAAAB------------------BAAAA- -AAAAB------------------BAAAA- AAAAAA------------------AAAAAA BAAAAB------------------BAAAAB BAAAAB------------------BAAAAB BAAAAB------------------BAAAAB AAAAAB------------------BAAAAA -AAAAB------------------BAAAA- -AAAAB------------------BAAAA- --AAAB------------------BAAA-- ---AABBBBBBBBBBBBBBBBBBBBAA--- -----BABBA----------ABBAB----- 
------------------------------ ---AB--------------------BA--- --AAB--------------------BAA-- -AAAB--------------------BAAA- -AAAB--------------------BAAA- AAAAB--------------------BAAAA BAAAB--------------------BAAAB BAAAB--------------------BAAAB BAAAB--------------------BAAAB AAAAA--------------------AAAAA -AAAA--------------------AAAA- -AAAB--------------------BAAA- --AAB--------------------BAA-- ---AA--------------------AA--- ------------------------------ 
------------------------------ ---A----------------------A--- --AB----------------------BA-- -AAB----------------------BAA- -AAB----------------------BAA- BAAB----------------------BAAB BAAB----------------------BAAB BAAB----------------------BAAB BAAA----------------------AAAB BAAA----------------------AAAB -AAB----------------------BAA- -AAB----------------------BAA- --AB----------------------BA-- ---B----------------------B--- ------------------------------ 
------------------------------ ------------------------------ --A------------------------A-- -AB------------------------BA- -AA------------------------AA- BAA------------------------AAB BAB------------------------BAB BAA------------------------AAB BAB------------------------BAB BAA------------------------AAB -AB------------------------BA- -AA------------------------AA- --A------------------------A-- ------------------------------ ------------------------------ 
------------------------------ ------------------------------ ------------------------------ -A--------------------------A- -B--------------------------B- BB--------------------------BB BB--------------------------BB AA--------------------------AA BB--------------------------BB BB--------------------------BB -A--------------------------A- -B--------------------------B- ------------------------------ ------------------------------ ------------------------------ 
------------------------------ ------------------------------ ------------------------------ ------------------------------ ------------------------------ A----------------------------A B----------------------------B B----------------------------B B----------------------------B B----------------------------B ------------------------------ ------------------------------ ------------------------------ ------------------------------ ------------------------------ 
