model
size = 30 15 12, scale = 0.05, origin = -y
material 
  colors = A:#069 B:#C30 C:#500
voxels
-----AABCA----------ACBAA----- ---AAABCABACABCCBACABACBAAA--- --BCCBAAABACABBBBACABAAABCCB-- -BAAAACCABCABAAAABACBACCAAAAB- -ABCAAAAACABBAAAABBACAAAAACBA- AAABCCACACABACAACABACACACCBAAA ABACCACCAAABBAAAABBAAACCACCABA BABBAABAAAAACCBBCCAAAAABAABBAB BBAABACAACABCABBACBACAACABAABB AAAABBAACACBAAAAAABCACAABBAAAA -AACBAAABABCBACCABCBABAAABCAA- -CAAAABABCAACABBACAACBABAAAAC- --AAAACAAAABAABBAABAAAACAAAA-- ---AACABABCAAAAAAAACBABACAA--- -----BABCC----------CCBAB----- 
-----BACBC----------CBCAB----- ---AAAAAAAACACAACACAAAAAAAA--- --AAAAAAAAAAAAAAAAAAAAAAAAAA-- -AAAAAAAAAAAAAAAAAAAAAAAAAAAA- -AAAAAAABBBBAAAAAABBBBAAAAAAA- AAAAAAABBBBBBAAAABBBBBBAAAAAAA CAAAAABBBBBBBBAABBBBBBBBAAAAAC AAAAAABBBBBBBBAABBBBBBBBAAAAAA CAAAAABBBBBBBBAABBBBBBBBAAAAAC AAAAAABBBBBBBBAABBBBBBBBAAAAAA -AAAAAABBBBBBAAAABBBBBBAAAAAA- -AAAAAAABBBBAAAAAABBBBAAAAAAA- --AAAAAAAAAAAAAAAAAAAAAAAAAA-- ---AAAAAAAACACAACACAAAAAAAA--- -----BACBC----------CBCAB----- 
-----CCBBB----------BBBCC----- ---AAAAAAABCCCBBCCCBAAAAAAA--- --AAAAAAAAAAAAAAAAAAAAAAAAAA-- -AAAAA------------------AAAAA- -AAAAA------------------AAAAA- BAAAAA------------------AAAAAB AAAAAA------------------AAAAAA AAAAAA------------------AAAAAA AAAAAA------------------AAAAAA BAAAAA------------------AAAAAB -AAAAA------------------AAAAA- -AAAAA------------------AAAAA- --AAAA------------------AAAA-- ---AAAAAAABCCCBBCCCBAAAAAAA--- -----CCBBB----------BBBCC----- 
-----ABABA----------ABABA----- ---AAAAAAACCCAAAACCCAAAAAAA--- --AAAAAAAAAAAAAAAAAAAAAAAAAA-- -AAAAA------------------AAAAA- -AAAAA------------------AAAAA- AAAAAA------------------AAAAAA AAAAAA------------------AAAAAA CAAAAA------------------AAAAAC AAAAAA------------------AAAAAA AAAAAA------------------AAAAAA -AAAAA------------------AAAAA- -AAAAA------------------AAAAA- --AAAA------------------AAAA-- ---AAAAAAACCCAAAACCCAAAAAAA--- -----ABABA----------ABABA----- 
-----CACAB----------BACAC----- ---AAAAAAACBCCCCCCBCAAAAAAA--- --AAAA------------------AAAA-- -AAAAA------------------AAAAA- -AAAAA------------------AAAAA- CAAAAA------------------AAAAAC AAAAAA------------------AAAAAA AAAAAA------------------AAAAAA AAAAAA------------------AAAAAA CAAAAA------------------AAAAAC -AAAAA------------------AAAAA- -AAAAA------------------AAAAA- --AAAA------------------AAAA-- ---AAAAAAACBCCCCCCBCAAAAAAA--- -----CACAB----------BACAC----- 
-----BACAC----------CACAB----- ---AAAAAAABBBCAACBBBAAAAAAA--- --AAAA------------------AAAA-- -AAAAA------------------AAAAA- -AAAAA------------------AAAAA- AAAAAA------------------AAAAAA AAAAAA------------------AAAAAA AAAAAA------------------AAAAAA AAAAAA------------------AAAAAA AAAAAA------------------AAAAAA -AAAAA------------------AAAAA- -AAAAA------------------AAAAA- --AAAA------------------AAAA-- ---AAAAAAABBBCAACBBBAAAAAAA--- -----BACAC----------CACAB----- 
-----AAAAA----------AAAAA----- ---AAAAAAAAAAAAAAAAAAAAAAAA--- --AAAA------------------AAAA-- -AAAAA------------------AAAAA- -AAAAA------------------AAAAA- AAAAAA------------------AAAAAA AAAAAA------------------AAAAAA CAAAAA------------------AAAAAC AAAAAA------------------AAAAAA AAAAAA------------------AAAAAA -AAAAA------------------AAAAA- -AAAAA------------------AAAAA- --AAAA------------------AAAA-- ---AAAAAAAAAAAAAAAAAAAAAAAA--- -----AAAAA----------AAAAA----- 
------------------------------ ---AA--------------------AA--- --AAA--------------------AAA-- -AAAA--------------------AAAA- -AAAA--------------------AAAA- AAAAA--------------------AAAAA AAAAA--------------------AAAAA CAAAA--------------------AAAAC AAAAA--------------------AAAAA AAAAA--------------------AAAAA -AAAA--------------------AAAA- -AAAA--------------------AAAA- --AAA--------------------AAA-- ---AA--------------------AA--- ------------------------------ 
------------------------------ ---A----------------------A--- --AA----------------------AA-- -AAA----------------------AAA- -AAA----------------------AAA- CAAA----------------------AAAC BAAA----------------------AAAB CAAA----------------------AAAC BAAA----------------------AAAB CAAA----------------------AAAC -AAA----------------------AAA- -AAA----------------------AAA- --AA----------------------AA-- ---A----------------------A--- ------------------------------ 
------------------------------ ------------------------------ --A------------------------A-- -AA------------------------AA- -AA------------------------AA- AAA------------------------AAA AAA------------------------AAA AAA------------------------AAA AAA------------------------AAA AAA------------------------AAA -AA------------------------AA- -AA------------------------AA- --A------------------------A-- ------------------------------ ------------------------------ 
------------------------------ ------------------------------ ------------------------------ -A--------------------------A- -A--------------------------A- AA--------------------------AA AA--------------------------AA AA--------------------------AA AA--------------------------AA AA--------------------------AA -A--------------------------A- -A--------------------------A- ------------------------------ ------------------------------ ------------------------------ 
------------------------------ ------------------------------ ------------------------------ ------------------------------ ------------------------------ A----------------------------A A----------------------------A A----------------------------A A----------------------------A A----------------------------A ------------------------------ ------------------------------ ------------------------------ ------------------------------ ------------------------------ 
