model
size = 30 15 12, scale = 0.05, origin = -y
material 
  colors = A:#399 B:#F00 C:#0FF
voxels
-----BBBAB----------BABBB----- ---AAAAABABBBABBABBBABAAAAA--- --BBAABBABAABBBBBBAABABBAABB-- -BBAABBBABAAAAAAAAAABABBBAABB- -ABABBAAAABBBBAABBBBAAAABBABA- AAABABAABAAAAABBAAAAABAABABAAA AAABBBBBAAABBAAAABBAAABBBBBAAA ABABABABABAABBBBBBAABABABABABA BABBBBABBABAABBBBAABABBABBBBAB BAAAAABBBAAAABAABAAAABBBAAAAAB -BAABABAAAABBAAAABBAAAABABAAB- -AAABBBBABBAAAAAAAABBABBBBAAA- --BABABBAABBBBAABBBBAABBABAB-- ---ABBAAAAABBBAABBBAAAAABBA--- -----ABABB----------BBABA----- 
-----ABAAA----------AAABA----- ---AAAAAAAAAAAAAAAAAAAAAAAA--- --AAAAAAAAAAAAAAAAAAAAAAAAAA-- -AAAAAAAAAAAAAAAAAAAAAAAAAAAA- -AAAAAAACCCCAAAAAACCCCAAAAAAA- AAAAAAACCCCCCAAAACCCCCCAAAAAAA AAAAAACCCCCCCCAACCCCCCCCAAAAAA AAAAAACCCCCCCCAACCCCCCCCAAAAAA AAAAAACCCCCCCCAACCCCCCCCAAAAAA AAAAAACCCCCCCCAACCCCCCCCAAAAAA -AAAAAACCCCCCAAAACCCCCCAAAAAA- -AAAAAAACCCCAAAAAACCCCAAAAAAA- --AAAAAAAAAAAAAAAAAAAAAAAAAA-- ---AAAAAAAAAAAAAAAAAAAAAAAA--- -----ABAAA----------AAABA----- 
-----ABBAB----------BABBA----- ---AAAAAAABAABAABAABAAAAAAA--- --AAAAAAAAAAAAAAAAAAAAAAAAAA-- -AAAAA------------------AAAAA- -AAAAA------------------AAAAA- AAAAAA------------------AAAAAA AAAAAA------------------AAAAAA AAAAAA------------------AAAAAA AAAAAA------------------AAAAAA AAAAAA------------------AAAAAA -AAAAA------------------AAAAA- -AAAAA------------------AAAAA- --AAAA------------------AAAA-- ---AAAAAAABAABAABAABAAAAAAA--- -----ABBAB----------BABBA----- 
-----BBBBB----------BBBBB----- ---AAAAAAABAABAABAABAAAAAAA--- --AAAABAABBBBBBBBBBBBAABAAAA-- -AAAAA------------------AAAAA- -AAAAA------------------AAAAA- AAAAAA------------------AAAAAA AAAAAA------------------AAAAAA AAAAAA------------------AAAAAA AAAAAA------------------AAAAAA AAAAAA------------------AAAAAA -AAAAA------------------AAAAA- -AAAAA------------------AAAAA- --AAAA------------------AAAA-- ---AAAAAAABAABAABAABAAAAAAA--- -----BBBBB----------BBBBB----- 
-----AAAAB----------BAAAA----- ---AAAAAAAAAAABBAAAAAAAAAAA--- --AAAA------------------AAAA-- -AAAAA------------------AAAAA- -AAAAA------------------AAAAA- AAAAAA------------------AAAAAA AAAAAA------------------AAAAAA AAAAAA------------------AAAAAA AAAAAA------------------AAAAAA AAAAAA------------------AAAAAA -AAAAA------------------AAAAA- -AAAAA------------------AAAAA- --AAAA------------------AAAA-- ---AAAAAAAAAAABBAAAAAAAAAAA--- -----AAAAB----------BAAAA----- 
-----BABBA----------ABBAB----- ---AAAAAAAAABBBBBBAAAAAAAAA--- --AAAA------------------AAAA-- -AAAAA------------------AAAAA- -AAAAA------------------AAAAA- AAAAAA------------------AAAAAA AAAAAA------------------AAAAAA AAAAAA------------------AAAAAA AAAAAA------------------AAAAAA AAAAAA------------------AAAAAA -AAAAA------------------AAAAA- -AAAAA------------------AAAAA- --AAAA------------------AAAA-- ---AAAAAAAAABBBBBBAAAAAAAAA--- -----BABBA----------ABBAB----- 
-----BBBBA----------ABBBB----- ---AABBABBAAABAABAAABBABBAA--- --AAAA------------------AAAA-- -AAAAB------------------BAAAA- -AAAAB------------------BAAAA- AAAAAB------------------BAAAAA AAAAAB------------------BAAAAA AAAAAA------------------AAAAAA AAAAAB------------------BAAAAA AAAAAA------------------AAAAAA -AAAAB------------------BAAAA- -AAAAA------------------AAAAA- --AAAB------------------BAAA-- ---AAABBBBBBBBBBBBBBBBBBAAA--- -----BBBBA----------ABBBB----- 
------------------------------ ---AB--------------------BA--- --AAB--------------------BAA-- -AAAA--------------------AAAA- -AAAB--------------------BAAA- AAAAB--------------------BAAAA AAAAB--------------------BAAAA AAAAB--------------------BAAAA AAAAA--------------------AAAAA AAAAA--------------------AAAAA -AAAB--------------------BAAA- -AAAA--------------------AAAA- --AAA--------------------AAA-- ---AA--------------------AA--- ------------------------------ 
------------------------------ ---A----------------------A--- --AB----------------------BA-- -AAB----------------------BAA- -AAA----------------------AAA- AAAB----------------------BAAA AAAB----------------------BAAA AAAB----------------------BAAA AAAB----------------------BAAA AAAB----------------------BAAA -AAB----------------------BAA- -AAB----------------------BAA- --AA----------------------AA-- ---B----------------------B--- ------------------------------ 
------------------------------ ------------------------------ --A------------------------A-- -AA------------------------AA- -AB------------------------BA- AAB------------------------BAA AAA------------------------AAA AAB------------------------BAA AAB------------------------BAA AAA------------------------AAA -AB------------------------BA- -AB------------------------BA- --B------------------------B-- ------------------------------ ------------------------------ 
------------------------------ ------------------------------ ------------------------------ -B--------------------------B- -B--------------------------B- AB--------------------------BA AB--------------------------BA AB--------------------------BA AB--------------------------BA AA--------------------------AA -B--------------------------B- -B--------------------------B- ------------------------------ ------------------------------ ------------------------------ 
------------------------------ ------------------------------ ------------------------------ ------------------------------ ------------------------------ A----------------------------A B----------------------------B B----------------------------B B----------------------------B B----------------------------B ------------------------------ ------------------------------ ------------------------------ ------------------------------ ------------------------------ 
