model
size = 30 15 12, scale = 0.05, origin = -y
material 
  colors = A:#063 B:#070 C:#008
voxels
-----BCBBB----------BBBCB----- ---BBBBCCAABABCCBABAACCBBBB--- --CBAAABABBCABBBBACBBABAAABC-- -ACACCBABAAACACCACAAABABCCACA- -BBACCBAACCAACAACAACCAABCCABB- BAAAABAAABCABAAAABACBAAABAAAAB BBBBBACBBABACACCACABABBCABBBBB CAABCBAAAAABAAAAAABAAAAABCBAAC AAAABABAAAAAABCCBAAAAAABABAAAA AABBAABCAAAAAABBAAAAAACBAABBAA -CCAABBBACACAACCAACACABBBAACC- -BCCBABBBCABBBAABBBACBBBABCCB- --ACACAABAACBBCCBBCAABAACACA-- ---ACCCAAABCCAAAACCBAAACCCA--- -----BBCAC----------CACBB----- 
-----AAAAA----------AAAAA----- ---AAAAAAAAAAAAAAAAAAAAAAAA--- --AAAAAAAAAAAAAAAAAAAAAAAAAA-- -AAAAAAAAAAAAAAAAAAAAAAAAAAAA- -AAAAAAABBBBAAAAAABBBBAAAAAAA- AAAAAAABBBBBBAAAABBBBBBAAAAAAA AAAAAABBBBBBBBAABBBBBBBBAAAAAA CAAAAABBBBBBBBAABBBBBBBBAAAAAC AAAAAABBBBBBBBAABBBBBBBBAAAAAA AAAAAABBBBBBBBAABBBBBBBBAAAAAA -AAAAAABBBBBBAAAABBBBBBAAAAAA- -AAAAAAABBBBAAAAAABBBBAAAAAAA- --AAAAAAAAAAAAAAAAAAAAAAAAAA-- ---AAAAAAAAAAAAAAAAAAAAAAAA--- -----AAAAA----------AAAAA----- 
-----AAAAA----------AAAAA----- ---AAAAAAAAAAAAAAAAAAAAAAAA--- --AAAAAAAAAAAAAAAAAAAAAAAAAA-- -AAAAA------------------AAAAA- -AAAAA------------------AAAAA- AAAAAA------------------AAAAAA AAAAAA------------------AAAAAA AAAAAA------------------AAAAAA AAAAAA------------------AAAAAA AAAAAA------------------AAAAAA -AAAAA------------------AAAAA- -AAAAA------------------AAAAA- --AAAA------------------AAAA-- ---AAAAAAAAAAAAAAAAAAAAAAAA--- -----AAAAA----------AAAAA----- 
-----AAAAA----------AAAAA----- ---AAAAAAAAAAAAAAAAAAAAAAAA--- --AAAABCCBBBBABBABBBBCCBAAAA-- -AAAAA------------------AAAAA- -AAAAA------------------AAAAA- CAAAAA------------------AAAAAC AAAAAA------------------AAAAAA AAAAAA------------------AAAAAA AAAAAA------------------AAAAAA CAAAAA------------------AAAAAC -AAAAA------------------AAAAA- -AAAAA------------------AAAAA- --AAAA------------------AAAA-- ---AAAAAAAAAAAAAAAAAAAAAAAA--- -----AAAAA----------AAAAA----- 
-----AAAAA----------AAAAA----- ---AAAAAAAAAAAAAAAAAAAAAAAA--- --AAAA------------------AAAA-- -AAAAA------------------AAAAA- -AAAAA------------------AAAAA- AAAAAA------------------AAAAAA AAAAAA------------------AAAAAA BAAAAA------------------AAAAAB AAAAAA------------------AAAAAA AAAAAA------------------AAAAAA -AAAAA------------------AAAAA- -AAAAA------------------AAAAA- --AAAA------------------AAAA-- ---AAAAAAAAAAAAAAAAAAAAAAAA--- -----AAAAA----------AAAAA----- 
-----AAAAA----------AAAAA----- ---AAAAAAAAAAAAAAAAAAAAAAAA--- --AAAA------------------AAAA-- -AAAAA------------------AAAAA- -AAAAA------------------AAAAA- AAAAAA------------------AAAAAA AAAAAA------------------AAAAAA AAAAAA------------------AAAAAA AAAAAA------------------AAAAAA AAAAAA------------------AAAAAA -AAAAA------------------AAAAA- -AAAAA------------------AAAAA- --AAAA------------------AAAA-- ---AAAAAAAAAAAAAAAAAAAAAAAA--- -----AAAAA----------AAAAA----- 
-----ABBAB----------BABBA----- ---AAABCBABBCBBBBCBBABCBAAA--- --AAAC------------------CAAA-- -AAAAC------------------CAAAA- -AAAAA------------------AAAAA- AAAAAB------------------BAAAAA AAAAAC------------------CAAAAA AAAAAC------------------CAAAAA AAAAAA------------------AAAAAA AAAAAB------------------BAAAAA -AAAAC------------------CAAAA- -AAAAB------------------BAAAA- --AAAC------------------CAAA-- ---AABCBBCCBBCCCCBBCCBBCBAA--- -----CBBBA----------ABBBC----- 
------------------------------ ---AA--------------------AA--- --AAA--------------------AAA-- -AAAC--------------------CAAA- -AAAC--------------------CAAA- AAAAC--------------------CAAAA CAAAB--------------------BAAAC AAAAB--------------------BAAAA CAAAC--------------------CAAAC AAAAC--------------------CAAAA -AAAB--------------------BAAA- -AAAB--------------------BAAA- --AAA--------------------AAA-- ---AA--------------------AA--- ------------------------------ 
------------------------------ ---A----------------------A--- --AB----------------------BA-- -AAA----------------------AAA- -AAB----------------------BAA- BAAA----------------------AAAB AAAB----------------------BAAA AAAC----------------------CAAA AAAC----------------------CAAA BAAC----------------------CAAB -AAB----------------------BAA- -AAA----------------------AAA- --AB----------------------BA-- ---B----------------------B--- ------------------------------ 
------------------------------ ------------------------------ --C------------------------C-- -AB------------------------BA- -AA------------------------AA- AAB------------------------BAA CAB------------------------BAC AAB------------------------BAA CAC------------------------CAC AAC------------------------CAA -AB------------------------BA- -AB------------------------BA- --B------------------------B-- ------------------------------ ------------------------------ 
------------------------------ ------------------------------ ------------------------------ -B--------------------------B- -B--------------------------B- AB--------------------------BA AC--------------------------CA AC--------------------------CA AA--------------------------AA AA--------------------------AA -C--------------------------C- -B--------------------------B- ------------------------------ ------------------------------ ------------------------------ 
------------------------------ ------------------------------ ------------------------------ ------------------------------ ------------------------------ B----------------------------B B----------------------------B C----------------------------C B----------------------------B C----------------------------C ------------------------------ ------------------------------ ------------------------------ ------------------------------ ------------------------------ 
