model
size = 30 15 12, scale = 0.05, origin = -y
material 
  colors = A:#0A0 B:#AAA C:#002
voxels
-----AAAAA----------AAAAA----- ---CBAACAAABACCCCABAAACAABC--- --BCABCAABACAAAAAACABAACBACB-- -AABCBAACACBAAAAAABCACAABCBAA- -BAAACCAAAAAAAAAAAAAAAACCAAAB- BBAACAACCACAACAACAACACCAACAABB BCBCBCABCCACBAAAABCACCBACBCBCB CACAACACABAACACCACAABACACAACAC AACAACBACBCBAAAAAABCBCABCAACAA CABAAACACBABAAAAAABABCACAAABAC -AAAABBABAAAACAACAAAABABBAAAA- -BBCBCABACBACCCCCCABCABACBCBB- --BCABAAABAACACCACAABAAABACB-- ---BACABCABCAACCAACBACBACAB--- -----AAAAC----------CAAAA----- 
-----AAAAA----------AAAAA----- ---AAAAAAAAAAAAAAAAAAAAAAAA--- --AAAAAAAAAAAAAAAAAAAAAAAAAA-- -AAAAAAAAAAAAAAAAAAAAAAAAAAAA- -AAAAAAABBBBAAAAAABBBBAAAAAAA- AAAAAAABBBBBBAAAABBBBBBAAAAAAA AAAAAABBBBBBBBAABBBBBBBBAAAAAA AAAAAABBBBBBBBAABBBBBBBBAAAAAA AAAAAABBBBBBBBAABBBBBBBBAAAAAA AAAAAABBBBBBBBAABBBBBBBBAAAAAA -AAAAAABBBBBBAAAABBBBBBAAAAAA- -AAAAAAABBBBAAAAAABBBBAAAAAAA- --AAAAAAAAAAAAAAAAAAAAAAAAAA-- ---AAAAAAAAAAAAAAAAAAAAAAAA--- -----AAAAA----------AAAAA----- 
-----AAAAA----------AAAAA----- ---AAAAAAAAAAAAAAAAAAAAAAAA--- --AAAAAAAAAAAAAAAAAAAAAAAAAA-- -AAAAA------------------AAAAA- -AAAAA------------------AAAAA- AAAAAA------------------AAAAAA AAAAAA------------------AAAAAA AAAAAA------------------AAAAAA AAAAAA------------------AAAAAA AAAAAA------------------AAAAAA -AAAAA------------------AAAAA- -AAAAA------------------AAAAA- --AAAA------------------AAAA-- ---AAAAAAAAAAAAAAAAAAAAAAAA--- -----AAAAA----------AAAAA----- 
-----AAAAA----------AAAAA----- ---AAAAAAAAAAAAAAAAAAAAAAAA--- --AAAACAACCAABAABAACCAACAAAA-- -AAAAA------------------AAAAA- -AAAAA------------------AAAAA- AAAAAA------------------AAAAAA AAAAAA------------------AAAAAA AAAAAA------------------AAAAAA AAAAAA------------------AAAAAA AAAAAA------------------AAAAAA -AAAAA------------------AAAAA- -AAAAA------------------AAAAA- --AAAA------------------AAAA-- ---AAAAAAAAAAAAAAAAAAAAAAAA--- -----AAAAA----------AAAAA----- 
-----AAAAA----------AAAAA----- ---AAAAAAAAAAAAAAAAAAAAAAAA--- --AAAA------------------AAAA-- -AAAAA------------------AAAAA- -AAAAA------------------AAAAA- AAAAAA------------------AAAAAA AAAAAA------------------AAAAAA AAAAAA------------------AAAAAA AAAAAA------------------AAAAAA AAAAAA------------------AAAAAA -AAAAA------------------AAAAA- -AAAAA------------------AAAAA- --AAAA------------------AAAA-- ---AAAAAAAAAAAAAAAAAAAAAAAA--- -----AAAAA----------AAAAA----- 
-----AAAAA----------AAAAA----- ---AAAAAAAAAAAAAAAAAAAAAAAA--- --AAAA------------------AAAA-- -AAAAA------------------AAAAA- -AAAAA------------------AAAAA- AAAAAA------------------AAAAAA AAAAAA------------------AAAAAA AAAAAA------------------AAAAAA AAAAAA------------------AAAAAA AAAAAA------------------AAAAAA -AAAAA------------------AAAAA- -AAAAA------------------AAAAA- --AAAA------------------AAAA-- ---AAAAAAAAAAAAAAAAAAAAAAAA--- -----AAAAA----------AAAAA----- 
-----AAAAC----------CAAAA----- ---AACAAACAAACAACAAACAAACAA--- --AAAB------------------BAAA-- -AAAAC------------------CAAAA- -AAAAB------------------BAAAA- AAAAAA------------------AAAAAA AAAAAA------------------AAAAAA AAAAAA------------------AAAAAA AAAAAB------------------BAAAAA AAAAAB------------------BAAAAA -AAAAC------------------CAAAA- -AAAAA------------------AAAAA- --AAAC------------------CAAA-- ---AAAAAABBBAAAAAABBBAAAAAA--- -----ACBCC----------CCBCA----- 
------------------------------ ---AC--------------------CA--- --AAB--------------------BAA-- -AAAC--------------------CAAA- -AAAB--------------------BAAA- AAAAC--------------------CAAAA AAAAC--------------------CAAAA AAAAA--------------------AAAAA AAAAA--------------------AAAAA AAAAB--------------------BAAAA -AAAA--------------------AAAA- -AAAA--------------------AAAA- --AAA--------------------AAA-- ---AC--------------------CA--- ------------------------------ 
------------------------------ ---B----------------------B--- --AA----------------------AA-- -AAA----------------------AAA- -AAA----------------------AAA- AAAA----------------------AAAA AAAA----------------------AAAA AAAB----------------------BAAA AAAA----------------------AAAA AAAA----------------------AAAA -AAC----------------------CAA- -AAC----------------------CAA- --AB----------------------BA-- ---C----------------------C--- ------------------------------ 
------------------------------ ------------------------------ --A------------------------A-- -AA------------------------AA- -AA------------------------AA- AAA------------------------AAA AAB------------------------BAA AAC------------------------CAA AAC------------------------CAA AAB------------------------BAA -AA------------------------AA- -AA------------------------AA- --C------------------------C-- ------------------------------ ------------------------------ 
------------------------------ ------------------------------ ------------------------------ -C--------------------------C- -A--------------------------A- AC--------------------------CA AA--------------------------AA AC--------------------------CA AA--------------------------AA AC--------------------------CA -B--------------------------B- -A--------------------------A- ------------------------------ ------------------------------ ------------------------------ 
------------------------------ ------------------------------ ------------------------------ ------------------------------ ------------------------------ C----------------------------C A----------------------------A B----------------------------B B----------------------------B B----------------------------B ------------------------------ ------------------------------ ------------------------------ ------------------------------ ------------------------------ 
