model
size = 30 15 12, scale = 0.05, origin = -y
material 
  colors = A:#0FF B:#F63 C:#603
voxels
-----AABAB----------BABAA----- ---AAACABAACACBBCACAABACAAA--- --CBABBCBAABABAABABAABCBBABC-- -AACBBAACBABCAAAACBABCAABBCAA- -ABBACAABACAABBBBAACABAACABBA- BCAAAAABBCAAACCCCAAACBBAAAAACB ACAACCBACABAABBBBAABACABCCAACA BACBABCAACAACBAABCAACAACBABCAB CABAAAAABABABCAACBABABAAAAABAC CAAAAAACBAABAABBAABAABCAAAAAAC -BABAAABAAAAABCCBAAAAABAAABAB- -BCBAAAAABCCACCCCACCBAAAAABCB- --ACBCCCBACCACAACACCABCCCBCA-- ---CBCBACBABBBAABBBABCABCBC--- -----ACBAB----------BABCA----- 
-----AAAAA----------AAAAA----- ---AAAAAAAAAAAAAAAAAAAAAAAA--- --AAAAAAAAAAAAAAAAAAAAAAAAAA-- -AAAAAAAAAAAAAAAAAAAAAAAAAAAA- -AAAAAAABBBBAAAAAABBBBAAAAAAA- AAAAAAABBBBBBAAAABBBBBBAAAAAAA AAAAAABBBBBBBBAABBBBBBBBAAAAAA AAAAAABBBBBBBBAABBBBBBBBAAAAAA AAAAAABBBBBBBBAABBBBBBBBAAAAAA AAAAAABBBBBBBBAABBBBBBBBAAAAAA -AAAAAABBBBBBAAAABBBBBBAAAAAA- -AAAAAAABBBBAAAAAABBBBAAAAAAA- --AAAAAAAAAAAAAAAAAAAAAAAAAA-- ---AAAAAAAAAAAAAAAAAAAAAAAA--- -----AAAAA----------AAAAA----- 
-----AAAAA----------AAAAA----- ---AAAAAAAAAAAAAAAAAAAAAAAA--- --AAAAAAAAAAAAAAAAAAAAAAAAAA-- -AAAAA------------------AAAAA- -AAAAA------------------AAAAA- AAAAAA------------------AAAAAA AAAAAA------------------AAAAAA AAAAAA------------------AAAAAA AAAAAA------------------AAAAAA AAAAAA------------------AAAAAA -AAAAA------------------AAAAA- -AAAAA------------------AAAAA- --AAAA------------------AAAA-- ---AAAAAAAAAAAAAAAAAAAAAAAA--- -----AAAAA----------AAAAA----- 
-----AAAAA----------AAAAA----- ---AAAAAAAAAAAAAAAAAAAAAAAA--- --AAAABAABACAAAAAACABAABAAAA-- -AAAAA------------------AAAAA- -AAAAA------------------AAAAA- AAAAAA------------------AAAAAA AAAAAA------------------AAAAAA AAAAAA------------------AAAAAA AAAAAA------------------AAAAAA AAAAAA------------------AAAAAA -AAAAA------------------AAAAA- -AAAAA------------------AAAAA- --AAAA------------------AAAA-- ---AAAAAAAAAAAAAAAAAAAAAAAA--- -----AAAAA----------AAAAA----- 
-----AAAAA----------AAAAA----- ---AAAAAAAAAAAAAAAAAAAAAAAA--- --AAAA------------------AAAA-- -AAAAA------------------AAAAA- -AAAAA------------------AAAAA- AAAAAA------------------AAAAAA AAAAAA------------------AAAAAA AAAAAA------------------AAAAAA AAAAAA------------------AAAAAA AAAAAA------------------AAAAAA -AAAAA------------------AAAAA- -AAAAA------------------AAAAA- --AAAA------------------AAAA-- ---AAAAAAAAAAAAAAAAAAAAAAAA--- -----AAAAA----------AAAAA----- 
-----AAAAA----------AAAAA----- ---AAAAAAAAAAAAAAAAAAAAAAAA--- --AAAA------------------AAAA-- -AAAAA------------------AAAAA- -AAAAA------------------AAAAA- AAAAAA------------------AAAAAA AAAAAA------------------AAAAAA AAAAAA------------------AAAAAA AAAAAA------------------AAAAAA AAAAAA------------------AAAAAA -AAAAA------------------AAAAA- -AAAAA------------------AAAAA- --AAAA------------------AAAA-- ---AAAAAAAAAAAAAAAAAAAAAAAA--- -----AAAAA----------AAAAA----- 
-----AAAAA----------AAAAA----- ---AACAAAAAAAABBAAAAAAAACAA--- --AAAA------------------AAAA-- -AAAAA------------------AAAAA- -AAAAB------------------BAAAA- AAAAAA------------------AAAAAA AAAAAA------------------AAAAAA AAAAAA------------------AAAAAA AAAAAA------------------AAAAAA AAAAAA------------------AAAAAA -AAAAA------------------AAAAA- -AAAAA------------------AAAAA- --AAAB------------------BAAA-- ---AAAABAACACAAAACACAABAAAA--- -----AABAA----------AABAA----- 
------------------------------ ---AA--------------------AA--- --AAC--------------------CAA-- -AAAB--------------------BAAA- -AAAA--------------------AAAA- AAAAA--------------------AAAAA AAAAA--------------------AAAAA AAAAB--------------------BAAAA AAAAA--------------------AAAAA AAAAB--------------------BAAAA -AAAA--------------------AAAA- -AAAC--------------------CAAA- --AAA--------------------AAA-- ---AA--------------------AA--- ------------------------------ 
------------------------------ ---A----------------------A--- --AB----------------------BA-- -AAB----------------------BAA- -AAB----------------------BAA- AAAA----------------------AAAA AAAA----------------------AAAA AAAC----------------------CAAA AAAA----------------------AAAA AAAA----------------------AAAA -AAA----------------------AAA- -AAA----------------------AAA- --AA----------------------AA-- ---C----------------------C--- ------------------------------ 
------------------------------ ------------------------------ --A------------------------A-- -AA------------------------AA- -AA------------------------AA- AAA------------------------AAA AAA------------------------AAA AAA------------------------AAA AAA------------------------AAA AAB------------------------BAA -AA------------------------AA- -AA------------------------AA- --A------------------------A-- ------------------------------ ------------------------------ 
------------------------------ ------------------------------ ------------------------------ -A--------------------------A- -A--------------------------A- AA--------------------------AA AA--------------------------AA AA--------------------------AA AA--------------------------AA AA--------------------------AA -A--------------------------A- -C--------------------------C- ------------------------------ ------------------------------ ------------------------------ 
------------------------------ ------------------------------ ------------------------------ ------------------------------ ------------------------------ B----------------------------B A----------------------------A A----------------------------A B----------------------------B A----------------------------A ------------------------------ ------------------------------ ------------------------------ ------------------------------ ------------------------------ 
