model
size = 30 15 12, scale = 0.05, origin = -y
material 
  colors = A:#444 B:#C09 C:#CC0
voxels
-----BBBAB----------BABBB----- ---BBBAABABABAAAABABABAABBB--- --BABABBBBBBAABBAABBBBBBABAB-- -AABAAABBBBAAAAAAAABBBBAAABAA- -AABAABABBAABBAABBAABBABAABAA- BBABBBBBABBBBABBABBBBABBBBBABB BABAAABABBABBAAAABBABBABAAABAB ABABBABABAAABAAAABAAABABABBABA BABBAAAAABABBBBBBBBABAAAAABBAB BABBAABBAAAABBBBBBAAAABBAABBAB -BABBABAABAABBAABBAABAABABBAB- -AABBABABBABAABBAABABBABABBAA- --BABAAAABBAABAABAABBAAAABAB-- ---BBBBAABAAAABBAAAABAABBBB--- -----BBAAA----------AAABB----- 
-----BABBB----------BBBAB----- ---AAAAAAABBABAABABBAAAAAAA--- --AAAAAAAAAAAAAAAAAAAAAAAAAA-- -AAAAAAAAAAAAAAAAAAAAAAAAAAAA- -AAAAAAACCCCAAAAAACCCCAAAAAAA- BAAAAAACCCCCCAAAACCCCCCAAAAAAB BAAAAACCCCCCCCAACCCCCCCCAAAAAB AAAAAACCCCCCCCAACCCCCCCCAAAAAA BAAAAACCCCCCCCAACCCCCCCCAAAAAB BAAAAACCCCCCCCAACCCCCCCCAAAAAB -AAAAAACCCCCCAAAACCCCCCAAAAAA- -AAAAAAACCCCAAAAAACCCCAAAAAAA- --AAAAAAAAAAAAAAAAAAAAAAAAAA-- ---AAAAAAABBABAABABBAAAAAAA--- -----BABBB----------BBBAB----- 
-----BBBBB----------BBBBB----- ---AAAAAAAABABAABABAAAAAAAA--- --AAAAAAAAAAAAAAAAAAAAAAAAAA-- -AAAAA------------------AAAAA- -AAAAA------------------AAAAA- AAAAAA------------------AAAAAA AAAAAA------------------AAAAAA BAAAAA------------------AAAAAB AAAAAA------------------AAAAAA AAAAAA------------------AAAAAA -AAAAA------------------AAAAA- -AAAAA------------------AAAAA- --AAAA------------------AAAA-- ---AAAAAAAABABAABABAAAAAAAA--- -----BBBBB----------BBBBB----- 
-----BBBAA----------AABBB----- ---AAAAAAAABBBBBBBBAAAAAAAA--- --AAAABBBBABBBAABBBABBBBAAAA-- -AAAAA------------------AAAAA- -AAAAA------------------AAAAA- BAAAAA------------------AAAAAB BAAAAA------------------AAAAAB AAAAAA------------------AAAAAA BAAAAA------------------AAAAAB BAAAAA------------------AAAAAB -AAAAA------------------AAAAA- -AAAAA------------------AAAAA- --AAAA------------------AAAA-- ---AAAAAAAABBBBBBBBAAAAAAAA--- -----BBBAA----------AABBB----- 
-----BABBB----------BBBAB----- ---AAAAAAABBBBBBBBBBAAAAAAA--- --AAAA------------------AAAA-- -AAAAA------------------AAAAA- -AAAAA------------------AAAAA- AAAAAA------------------AAAAAA AAAAAA------------------AAAAAA AAAAAA------------------AAAAAA AAAAAA------------------AAAAAA AAAAAA------------------AAAAAA -AAAAA------------------AAAAA- -AAAAA------------------AAAAA- --AAAA------------------AAAA-- ---AAAAAAABBBBBBBBBBAAAAAAA--- -----BABBB----------BBBAB----- 
-----BBAAB----------BAABB----- ---AAAAAAABBBBAABBBBAAAAAAA--- --AAAA------------------AAAA-- -AAAAA------------------AAAAA- -AAAAA------------------AAAAA- BAAAAA------------------AAAAAB BAAAAA------------------AAAAAB BAAAAA------------------AAAAAB BAAAAA------------------AAAAAB BAAAAA------------------AAAAAB -AAAAA------------------AAAAA- -AAAAA------------------AAAAA- --AAAA------------------AAAA-- ---AAAAAAABBBBAABBBBAAAAAAA--- -----BBAAB----------BAABB----- 
-----ABABB----------BBABA----- ---AABBBBBBBBBBBBBBBBBBBBAA--- --AAAA------------------AAAA-- -AAAAB------------------BAAAA- -AAAAA------------------AAAAA- AAAAAA------------------AAAAAA AAAAAB------------------BAAAAA BAAAAB------------------BAAAAB AAAAAB------------------BAAAAA AAAAAB------------------BAAAAA -AAAAB------------------BAAAA- -AAAAB------------------BAAAA- --AAAB------------------BAAA-- ---AABBABBBBBAAAABBBBBABBAA--- -----AABBB----------BBBAA----- 
------------------------------ ---AB--------------------BA--- --AAB--------------------BAA-- -AAAB--------------------BAAA- -AAAB--------------------BAAA- BAAAB--------------------BAAAB BAAAA--------------------AAAAB AAAAA--------------------AAAAA BAAAB--------------------BAAAB BAAAB--------------------BAAAB -AAAB--------------------BAAA- -AAAB--------------------BAAA- --AAB--------------------BAA-- ---AB--------------------BA--- ------------------------------ 
------------------------------ ---B----------------------B--- --AB----------------------BA-- -AAB----------------------BAA- -AAA----------------------AAA- AAAB----------------------BAAA BAAA----------------------AAAB AAAB----------------------BAAA BAAB----------------------BAAB AAAB----------------------BAAA -AAB----------------------BAA- -AAB----------------------BAA- --AB----------------------BA-- ---B----------------------B--- ------------------------------ 
------------------------------ ------------------------------ --B------------------------B-- -AB------------------------BA- -AB------------------------BA- BAB------------------------BAB BAB------------------------BAB AAA------------------------AAA BAA------------------------AAB BAA------------------------AAB -AA------------------------AA- -AB------------------------BA- --B------------------------B-- ------------------------------ ------------------------------ 
------------------------------ ------------------------------ ------------------------------ -B--------------------------B- -B--------------------------B- AB--------------------------BA AA--------------------------AA BB--------------------------BB AB--------------------------BA AB--------------------------BA -B--------------------------B- -B--------------------------B- ------------------------------ ------------------------------ ------------------------------ 
------------------------------ ------------------------------ ------------------------------ ------------------------------ ------------------------------ B----------------------------B B----------------------------B B----------------------------B A----------------------------A B----------------------------B ------------------------------ ------------------------------ ------------------------------ ------------------------------ ------------------------------ 
