model
size = 30 15 12, scale = 0.05, origin = -y
material 
  colors = A:#699 B:#366 C:#FFC
voxels
-----BAAAA----------AAAAB----- ---BBBBBABBBAAAAAABBBABBBBB--- --BBABBBABAAABAABAAABABBBABB-- -AAABAAAAABABABBABABAAAAABAAA- -BBAABBABABAAABBAAABABABBAABB- BBBAAAAAABBAAAAAAAABBAAAAAABBB BAAABABBBBABABAABABABBBBABAAAB BABABAAAAABAABBBBAABAAAAABABAB AAABAAAABABAAABBAAABABAAAABAAA BBBAABBABAABAABBAABAABABBAABBB -AABAABABBAAABAABAAABBABAABAA- -AAABAAABBABBBAABBBABBAAABAAA- --AAABABBAABBAAAABBAABBABAAA-- ---BBBBBBBABAAAAAABABBBBBBB--- -----BAABA----------ABAAB----- 
-----BBBBB----------BBBBB----- ---AAAAAAABBBBAABBBBAAAAAAA--- --AAAAAAAAAAAAAAAAAAAAAAAAAA-- -AAAAAAAAAAAAAAAAAAAAAAAAAAAA- -AAAAAAACCCCAAAAAACCCCAAAAAAA- AAAAAAACCCCCCAAAACCCCCCAAAAAAA AAAAAACCCCCCCCAACCCCCCCCAAAAAA AAAAAACCCCCCCCAACCCCCCCCAAAAAA AAAAAACCCCCCCCAACCCCCCCCAAAAAA AAAAAACCCCCCCCAACCCCCCCCAAAAAA -AAAAAACCCCCCAAAACCCCCCAAAAAA- -AAAAAAACCCCAAAAAACCCCAAAAAAA- --AAAAAAAAAAAAAAAAAAAAAAAAAA-- ---AAAAAAABBBBAABBBBAAAAAAA--- -----BBBBB----------BBBBB----- 
-----BABBB----------BBBAB----- ---AAAAAAABBBBBBBBBBAAAAAAA--- --AAAAAAAAAAAAAAAAAAAAAAAAAA-- -AAAAA------------------AAAAA- -AAAAA------------------AAAAA- AAAAAA------------------AAAAAA AAAAAA------------------AAAAAA AAAAAA------------------AAAAAA AAAAAA------------------AAAAAA AAAAAA------------------AAAAAA -AAAAA------------------AAAAA- -AAAAA------------------AAAAA- --AAAA------------------AAAA-- ---AAAAAAABBBBBBBBBBAAAAAAA--- -----BABBB----------BBBAB----- 
-----BBBAB----------BABBB----- ---AAAAAAAABABAABABAAAAAAAA--- --AAAAABBBBBBBBBBBBBBBBAAAAA-- -AAAAA------------------AAAAA- -AAAAA------------------AAAAA- AAAAAA------------------AAAAAA AAAAAA------------------AAAAAA AAAAAA------------------AAAAAA AAAAAA------------------AAAAAA AAAAAA------------------AAAAAA -AAAAA------------------AAAAA- -AAAAA------------------AAAAA- --AAAA------------------AAAA-- ---AAAAAAAABABAABABAAAAAAAA--- -----BBBAB----------BABBB----- 
-----BABAA----------AABAB----- ---AAAAAAABBBBAABBBBAAAAAAA--- --AAAA------------------AAAA-- -AAAAA------------------AAAAA- -AAAAA------------------AAAAA- AAAAAA------------------AAAAAA AAAAAA------------------AAAAAA AAAAAA------------------AAAAAA AAAAAA------------------AAAAAA AAAAAA------------------AAAAAA -AAAAA------------------AAAAA- -AAAAA------------------AAAAA- --AAAA------------------AAAA-- ---AAAAAAABBBBAABBBBAAAAAAA--- -----BABAA----------AABAB----- 
-----BABBB----------BBBAB----- ---AAAAAAABABBBBBBABAAAAAAA--- --AAAA------------------AAAA-- -AAAAA------------------AAAAA- -AAAAA------------------AAAAA- AAAAAA------------------AAAAAA AAAAAA------------------AAAAAA AAAAAA------------------AAAAAA AAAAAA------------------AAAAAA AAAAAA------------------AAAAAA -AAAAA------------------AAAAA- -AAAAA------------------AAAAA- --AAAA------------------AAAA-- ---AAAAAAABABBBBBBABAAAAAAA--- -----BABBB----------BBBAB----- 
-----BBAAA----------AAABB----- ---AABBBAABBBABBABBBAABBBAA--- --AAAB------------------BAAA-- -AAAAB------------------BAAAA- -AAAAB------------------BAAAA- AAAAAB------------------BAAAAA AAAAAB------------------BAAAAA AAAAAB------------------BAAAAA AAAAAB------------------BAAAAA AAAAAA------------------AAAAAA -AAAAB------------------BAAAA- -AAAAB------------------BAAAA- --AAAB------------------BAAA-- ---AABBBBBBBBBBBBBBBBBBBBAA--- -----BBBBA----------ABBBB----- 
------------------------------ ---AB--------------------BA--- --AAB--------------------BAA-- -AAAB--------------------BAAA- -AAAB--------------------BAAA- AAAAB--------------------BAAAA AAAAB--------------------BAAAA AAAAB--------------------BAAAA AAAAB--------------------BAAAA AAAAB--------------------BAAAA -AAAA--------------------AAAA- -AAAB--------------------BAAA- --AAB--------------------BAA-- ---AA--------------------AA--- ------------------------------ 
------------------------------ ---A----------------------A--- --AA----------------------AA-- -AAA----------------------AAA- -AAA----------------------AAA- AAAB----------------------BAAA AAAA----------------------AAAA AAAA----------------------AAAA AAAA----------------------AAAA AAAB----------------------BAAA -AAB----------------------BAA- -AAB----------------------BAA- --AB----------------------BA-- ---A----------------------A--- ------------------------------ 
------------------------------ ------------------------------ --A------------------------A-- -AA------------------------AA- -AB------------------------BA- AAB------------------------BAA AAA------------------------AAA AAB------------------------BAA AAB------------------------BAA AAB------------------------BAA -AB------------------------BA- -AA------------------------AA- --B------------------------B-- ------------------------------ ------------------------------ 
------------------------------ ------------------------------ ------------------------------ -B--------------------------B- -A--------------------------A- AA--------------------------AA AB--------------------------BA AB--------------------------BA AA--------------------------AA AB--------------------------BA -B--------------------------B- -A--------------------------A- ------------------------------ ------------------------------ ------------------------------ 
------------------------------ ------------------------------ ------------------------------ ------------------------------ ------------------------------ B----------------------------B A----------------------------A B----------------------------B B----------------------------B B----------------------------B ------------------------------ ------------------------------ ------------------------------ ------------------------------ ------------------------------ 
