model
size = 30 15 12, scale = 0.05, origin = -y
material 
  colors = A:#630 B:#200 C:#6FC
voxels
-----ACCBB----------BBCCA----- ---CCBCCACABACBBCABACACCBCC--- --AABABBACACAAAAAACACABBABAA-- -BBAAACABAAABBAABBAAABACAAABB- -AABABAABAACAAAAAACAABAABABAA- ABACACABAABACCCCCCABAABACACABA BBBAACACAABBAABBAABBAACACAABBB ACAAAABAACABBABBABBACAABAAAACA BBABACCBAAABCBBBBCBAAABCCABABB ABCACCBACCBAACAACAABCCABCCACBA -AAABACACAABAACCAABAACACABAAA- -BCAABCCBAAAAAAAAAAAABCCBAACB- --BCBBABCABAABBBBAABACBABBCB-- ---BCCBBBCACACAACACACBBBCCB--- -----AAABB----------BBAAA----- 
-----AABAA----------AABAA----- ---AAAAAAAAACAAAACAAAAAAAAA--- --AAAAAAAAAAAAAAAAAAAAAAAAAA-- -AAAAAAAAAAAAAAAAAAAAAAAAAAAA- -AAAAAAABBBBAAAAAABBBBAAAAAAA- BAAAAAABBBBBBAAAABBBBBBAAAAAAB CAAAAABBBBBBBBAABBBBBBBBAAAAAC AAAAAABBBBBBBBAABBBBBBBBAAAAAA CAAAAABBBBBBBBAABBBBBBBBAAAAAC BAAAAABBBBBBBBAABBBBBBBBAAAAAB -AAAAAABBBBBBAAAABBBBBBAAAAAA- -AAAAAAABBBBAAAAAABBBBAAAAAAA- --AAAAAAAAAAAAAAAAAAAAAAAAAA-- ---AAAAAAAAACAAAACAAAAAAAAA--- -----AABAA----------AABAA----- 
-----BCBBA----------ABBCB----- ---AAAAAAABACACCACABAAAAAAA--- --AAAAAAAAAAAAAAAAAAAAAAAAAA-- -AAAAA------------------AAAAA- -AAAAA------------------AAAAA- BAAAAA------------------AAAAAB CAAAAA------------------AAAAAC CAAAAA------------------AAAAAC CAAAAA------------------AAAAAC BAAAAA------------------AAAAAB -AAAAA------------------AAAAA- -AAAAA------------------AAAAA- --AAAA------------------AAAA-- ---AAAAAAABACACCACABAAAAAAA--- -----BCBBA----------ABBCB----- 
-----CCABB----------BBACC----- ---AAAAAAAABABAABABAAAAAAAA--- --AAAABAAAAAAABBAAAAAAABAAAA-- -AAAAA------------------AAAAA- -AAAAA------------------AAAAA- AAAAAA------------------AAAAAA AAAAAA------------------AAAAAA CAAAAA------------------AAAAAC AAAAAA------------------AAAAAA AAAAAA------------------AAAAAA -AAAAA------------------AAAAA- -AAAAA------------------AAAAA- --AAAA------------------AAAA-- ---AAAAAAAABABAABABAAAAAAAA--- -----CCABB----------BBACC----- 
-----AAACB----------BCAAA----- ---AAAAAAABBABCCBABBAAAAAAA--- --AAAA------------------AAAA-- -AAAAA------------------AAAAA- -AAAAA------------------AAAAA- AAAAAA------------------AAAAAA AAAAAA------------------AAAAAA CAAAAA------------------AAAAAC AAAAAA------------------AAAAAA AAAAAA------------------AAAAAA -AAAAA------------------AAAAA- -AAAAA------------------AAAAA- --AAAA------------------AAAA-- ---AAAAAAABBABCCBABBAAAAAAA--- -----AAACB----------BCAAA----- 
-----ACCAC----------CACCA----- ---AAAAAAAAABAAAABAAAAAAAAA--- --AAAA------------------AAAA-- -AAAAA------------------AAAAA- -AAAAA------------------AAAAA- BAAAAA------------------AAAAAB BAAAAA------------------AAAAAB AAAAAA------------------AAAAAA BAAAAA------------------AAAAAB BAAAAA------------------AAAAAB -AAAAA------------------AAAAA- -AAAAA------------------AAAAA- --AAAA------------------AAAA-- ---AAAAAAAAABAAAABAAAAAAAAA--- -----ACCAC----------CACCA----- 
-----BAAAA----------AAAAB----- ---AABAAAACAAAAAAAACAAAABAA--- --AAAA------------------AAAA-- -AAAAA------------------AAAAA- -AAAAA------------------AAAAA- CAAAAA------------------AAAAAC AAAAAA------------------AAAAAA BAAAAB------------------BAAAAB AAAAAB------------------BAAAAA CAAAAA------------------AAAAAC -AAAAA------------------AAAAA- -AAAAC------------------CAAAA- --AAAA------------------AAAA-- ---AAAAAAAACAAAAAACAAAAAAAA--- -----ABCAC----------CACBA----- 
------------------------------ ---AA--------------------AA--- --AAA--------------------AAA-- -AAAB--------------------BAAA- -AAAA--------------------AAAA- BAAAA--------------------AAAAB AAAAC--------------------CAAAA BAAAA--------------------AAAAB AAAAB--------------------BAAAA BAAAC--------------------CAAAB -AAAB--------------------BAAA- -AAAA--------------------AAAA- --AAA--------------------AAA-- ---AA--------------------AA--- ------------------------------ 
------------------------------ ---C----------------------C--- --AA----------------------AA-- -AAA----------------------AAA- -AAA----------------------AAA- AAAA----------------------AAAA BAAC----------------------CAAB AAAA----------------------AAAA BAAC----------------------CAAB AAAA----------------------AAAA -AAA----------------------AAA- -AAA----------------------AAA- --AA----------------------AA-- ---A----------------------A--- ------------------------------ 
------------------------------ ------------------------------ --B------------------------B-- -AA------------------------AA- -AC------------------------CA- CAA------------------------AAC AAC------------------------CAA CAA------------------------AAC AAB------------------------BAA CAA------------------------AAC -AA------------------------AA- -AA------------------------AA- --A------------------------A-- ------------------------------ ------------------------------ 
------------------------------ ------------------------------ ------------------------------ -C--------------------------C- -A--------------------------A- AA--------------------------AA CA--------------------------AC AB--------------------------BA CA--------------------------AC AA--------------------------AA -A--------------------------A- -A--------------------------A- ------------------------------ ------------------------------ ------------------------------ 
------------------------------ ------------------------------ ------------------------------ ------------------------------ ------------------------------ B----------------------------B A----------------------------A A----------------------------A A----------------------------A B----------------------------B ------------------------------ ------------------------------ ------------------------------ ------------------------------ ------------------------------ 
