model
size = 30 15 12, scale = 0.05, origin = -y
material 
  colors = A:#C33 B:#F66 C:#693
voxels
-----AABBA----------ABBAA----- ---CCCBAABAAAACCAAAABAABCCC--- --ABCABABACCAABBAACCABABACBA-- -AACAABAACBACAAAACABCAABAACAA- -BAABBACAABCAABBAACBAACABBAAB- CCBBBCBACAACCAAAACCAACABCBBBCC AAAAAACCCABABAAAABABACCCAAAAAA BACBBBCAABBBAAAAAABBBAACBBBCAB ABAACBBCAAAABACCABAAAACBBCAABA ABCACBACAAACABAABACAAACABCACBA -CAAACABBAACCAAAACCAABBACAAAC- -AAABCABCCABABCCBABACCBACBAAA- --AACCCAAABBBAAAABBBAAACCCAA-- ---BCACACCAACCCCCCAACCACACB--- -----BAAAB----------BAAAB----- 
-----CACCA----------ACCAC----- ---AAAAAAACBCBBBBCBCAAAAAAA--- --AAAAAAAAAAAAAAAAAAAAAAAAAA-- -AAAAAAAAAAAAAAAAAAAAAAAAAAAA- -AAAAAAABBBBAAAAAABBBBAAAAAAA- CAAAAAABBBBBBAAAABBBBBBAAAAAAC CAAAAABBBBBBBBAABBBBBBBBAAAAAC BAAAAABBBBBBBBAABBBBBBBBAAAAAB CAAAAABBBBBBBBAABBBBBBBBAAAAAC CAAAAABBBBBBBBAABBBBBBBBAAAAAC -AAAAAABBBBBBAAAABBBBBBAAAAAA- -AAAAAAABBBBAAAAAABBBBAAAAAAA- --AAAAAAAAAAAAAAAAAAAAAAAAAA-- ---AAAAAAACBCBBBBCBCAAAAAAA--- -----CACCA----------ACCAC----- 
-----BCBCB----------BCBCB----- ---AAAAAAABCBAAAABCBAAAAAAA--- --AAAAAAAAAAAAAAAAAAAAAAAAAA-- -AAAAA------------------AAAAA- -AAAAA------------------AAAAA- AAAAAA------------------AAAAAA CAAAAA------------------AAAAAC AAAAAA------------------AAAAAA CAAAAA------------------AAAAAC AAAAAA------------------AAAAAA -AAAAA------------------AAAAA- -AAAAA------------------AAAAA- --AAAA------------------AAAA-- ---AAAAAAABCBAAAABCBAAAAAAA--- -----BCBCB----------BCBCB----- 
-----BBCCA----------ACCBB----- ---AAAAAAABBBCBBCBBBAAAAAAA--- --AAAACCCACCBBBBBBCCACCCAAAA-- -AAAAA------------------AAAAA- -AAAAA------------------AAAAA- BAAAAA------------------AAAAAB AAAAAA------------------AAAAAA AAAAAA------------------AAAAAA AAAAAA------------------AAAAAA BAAAAA------------------AAAAAB -AAAAA------------------AAAAA- -AAAAA------------------AAAAA- --AAAA------------------AAAA-- ---AAAAAAABBBCBBCBBBAAAAAAA--- -----BBCCA----------ACCBB----- 
-----CACAC----------CACAC----- ---AAAAAAACBBCAACBBCAAAAAAA--- --AAAA------------------AAAA-- -AAAAA------------------AAAAA- -AAAAA------------------AAAAA- AAAAAA------------------AAAAAA AAAAAA------------------AAAAAA CAAAAA------------------AAAAAC AAAAAA------------------AAAAAA AAAAAA------------------AAAAAA -AAAAA------------------AAAAA- -AAAAA------------------AAAAA- --AAAA------------------AAAA-- ---AAAAAAACBBCAACBBCAAAAAAA--- -----CACAC----------CACAC----- 
-----CBBCA----------ACBBC----- ---AAAAAAAACACCCCACAAAAAAAA--- --AAAA------------------AAAA-- -AAAAA------------------AAAAA- -AAAAA------------------AAAAA- CAAAAA------------------AAAAAC BAAAAA------------------AAAAAB CAAAAA------------------AAAAAC BAAAAA------------------AAAAAB CAAAAA------------------AAAAAC -AAAAA------------------AAAAA- -AAAAA------------------AAAAA- --AAAA------------------AAAA-- ---AAAAAAAACACCCCACAAAAAAAA--- -----CBBCA----------ACBBC----- 
-----CBBCC----------CCBBC----- ---AACBCBCACAAAAAACACBCBCAA--- --AAAC------------------CAAA-- -AAAAB------------------BAAAA- -AAAAB------------------BAAAA- CAAAAC------------------CAAAAC BAAAAB------------------BAAAAB BAAAAB------------------BAAAAB BAAAAB------------------BAAAAB CAAAAC------------------CAAAAC -AAAAC------------------CAAAA- -AAAAC------------------CAAAA- --AAAA------------------AAAA-- ---AACBBBBACBBBBBBCABBBBCAA--- -----CBBCB----------BCBBC----- 
------------------------------ ---AC--------------------CA--- --AAC--------------------CAA-- -AAAC--------------------CAAA- -AAAB--------------------BAAA- BAAAB--------------------BAAAB BAAAC--------------------CAAAB AAAAA--------------------AAAAA BAAAA--------------------AAAAB BAAAB--------------------BAAAB -AAAC--------------------CAAA- -AAAC--------------------CAAA- --AAC--------------------CAA-- ---AC--------------------CA--- ------------------------------ 
------------------------------ ---B----------------------B--- --AC----------------------CA-- -AAA----------------------AAA- -AAC----------------------CAA- CAAC----------------------CAAC AAAB----------------------BAAA AAAC----------------------CAAA AAAC----------------------CAAA CAAC----------------------CAAC -AAC----------------------CAA- -AAA----------------------AAA- --AB----------------------BA-- ---B----------------------B--- ------------------------------ 
------------------------------ ------------------------------ --B------------------------B-- -AC------------------------CA- -AC------------------------CA- AAB------------------------BAA BAC------------------------CAB AAB------------------------BAA BAC------------------------CAB AAB------------------------BAA -AB------------------------BA- -AA------------------------AA- --B------------------------B-- ------------------------------ ------------------------------ 
------------------------------ ------------------------------ ------------------------------ -B--------------------------B- -C--------------------------C- AC--------------------------CA AC--------------------------CA AA--------------------------AA AC--------------------------CA AC--------------------------CA -B--------------------------B- -C--------------------------C- ------------------------------ ------------------------------ ------------------------------ 
------------------------------ ------------------------------ ------------------------------ ------------------------------ ------------------------------ A----------------------------A B----------------------------B B----------------------------B B----------------------------B C----------------------------C ------------------------------ ------------------------------ ------------------------------ ------------------------------ ------------------------------ 
