model
size = 32, scale = 0.05, origin = -y
material 
  colors = A:#000 B:#E00 C:#9CF D:#FF0 E:#0C0 F:#170B00 G:#FF6 H:#F03 I:#201010
voxels
15-3F30-F31-3F30-F30-3F30-I30-3I30-I27-I2-F2I25-F2I-2I26-IF-3I27-F2-F29-4A27-6A25-2(8A24-)8B24-8B25-6D27-4D413-3F4-F24-4F2-3F24-3F3-F26-2F26-F2-3F25-I2F2-2F26-F2-3F25-I2F-3F25-3F-3F25-7F24-FI5F25-3F-4F23-12A20-12A19-2(14A18-)14B18-14B19-12D20-12D21-10D23-8E26-4E315-F-3F3-3F20-3F-2F3-2IF21-F2-3F2-FIF20-3F6-FIF20-3F-3F2-I22-I2F2-F2-3F21-3F-3F2-F22-I2F2-F2-3F21-I2F-3F2-F22-I2F-2F2-3F21-IF-4F2-F21-3F2-3F-3F17-2(16A16-)16A15-18A14-18B15-16B2(16-4D6G6D)17-3D6G5D18-14E19-12E22-8A27-2A251-3F7-F21-3F3(6-3F20-I2F)5-4F20-I2F5-3F22-F6-3F21-3F5-3F22-F6-3F29-3F26-F2-3F25-3F-3F16-18A13-3(20A12-)2(20B12-)6D6G8D13-5D6G7D14-5D6G7D15-16E16-16E17-14A20-10A24-6B218-F13-F16-3F11-3F16-F8-F3-2I16-3F6-3F-F-IF16-F7-2F3-FI24-3F2-2I26-F4-F25-3F2-3F25-F4-I25-3F2-FIF25-F3-FI25-3F-3I4(10-22A)2(10-22B)2(10-7D6G9D)11-6D6G8D12-20E13-18E15-16A17-14A19-2B7H3B22-8B198-3F29-3F3(28-4F)28-4(3F29-)3F28-4F28-3F9-4(24A8-)2(24B8-)8D6G10D8-8D6G10D9-7D6G9D10-22E11-20E13-18A14-18A16-2B9H3B19-2B8H2B22-8D167-F30-3F29-2F29-5F28-4FI26-3F-F28-F-2FI26-3F-F28-F30-3F29-2F29-3F9-24A7-3(26A6-)2(26B6-)9D6G11D7-2(8D6G10D8-)24E9-22E11-20A12-20A13-4B8CH5B16-2B8CH3B19-12D23-6D233-3F28-3F3(I29-2F)I133-24A7-26A6-26A5-28A4-28B5-26B3(6-9D6G11D)7-24E8-24E9-22A10-22A11-5B8CH6B13-4B8CH5B16-14D20-10D26-2A108-3F30-F30-3F27-4F28-3FIF27-3F3(I29-2F)29-3F30-F30-3F4(4-28A)2(4-28B)2(4-10D6G12D)5-9D6G11D2(6-26E)7-24A9-22A11-5B8CH6B13-4B8CH5B15-3D9C4D17-3D8C3D21-3B2A3B105-2(3F29-)3F28-4F27-5F2(28-2FIF)28-2F2(I28-3F)2(29-3F)2(4-28A)3-2(30A2-)30B2-30B3-3(10D6G12D4-)28E5-26E6-26A7-24A9-6B8CH7B11-5B8CH6B13-4D9C5D15-DAD9C2DAD18-A3B4C3BA24-B2AB75-3(3F30-F30-)3F28-4F28-2F-F27-3F30-F30-3F3-4(30A2-)2(30B2-)11D6G13D2-11D6G13D3-10D6G12D2(4-28E)5-26A7-24A8-7B8CH8B9-6B8CH7B11-5D9C6D14-3D9C4D17-3A8C3A21-3B2A3B234-2(FI30-)F31-2F97-30A3(2-19A7C4A)2(2-30B)3(2-11D18GD)3-28E4-28E5-26A6-26A7-7B8CH8B9-6B8CH7B11-5D9C6D13-4D9C5D16-BA10CAB20-A3B2A3BA428-30A2-19A7C4A-20A7C25A7C5A10B2C30B2C20B-3(11D18GD2-)12E7C11E3-11E7C10E4-10A4C14A5-9A4C13A7-7B8CH8B8-7B8CH8B9-6D13C3D12-4D13CD15-2B12C2B18-3AB4CB3A24-B2AB76-FI157-2FI28-3F30-2F30-3F30-F30-3F-30A-10A2(17C15A)17C5A10B2C30B2C20B12DG6C11G2D-2(11DG6C11GD2-)12E7C11E3-11E7C10E4-10A4C14A5-9A4C13A6-10B6CH9B7-9B6CH8B9-7D12C3D11-6D12C2D14-2B12C2B18-3A6C3A23-6A43-F31-FI30-FI62-2F30-2F28-3F29-3FI28-3F30-2(3F29-)3F42A2(17C15A)17C5A10B2C30B2C20B11D2G6C11G13D2G6C11G2D-10D2G6C11GD2(2-12E7C11E)3-10A4C14A5-9A4C13A6-10B6CH9B7-9B6CH8B9-7D12C3D11-6D12C2D14-B14CB17-2BA8CA2B21-8A43-F30-F32-2(I30-F)31-2F29-2FI28-3FI29-2F30-3F30-F30-3F-41A2(17C15A)17C5A10B2C30B2C20B11D2G6C11G13D2G6C11G2D-10D2G6C11GD2(2-12E7C11E)3-10A4C14A4-10A4C14A5-10B6CH9B7-9B6CH8B9-7D12C3D11-6D12C2D13-2A14C2A16-3A8C3A21-8A139-3(I30-F)I29-F130-42A2(17C15A)17C5A10B2C30B2C20B11D2G6C11G13D2G6C11G2D-10D2G6C11GD2(2-12E7C11E)3-10A4C14A4-10A4C14A5-10B6CH9B7-9B6CH8B9-7D12C3D11-6D12C2D13-2A14C2A16-3A8C3A21-8A42-F30-3F29-2F29-3F30-F30-3F30-F64-F97-42A2(17C15A)17C5A10B2C30B2C20B11D2G6C11G13D2G6C11G2D-10D2G6C11GD2(2-30E)3-10A4C14A5-9A4C13A6-10B6CH9B7-9B6CH8B9-7D12C3D11-6D12C2D14-B14CB17-2BA8CA2B21-8A41-3F29-3F28-4F28-4(3F29-)3FI29-2F30-3F29-2F29-3F2-30A-10A2(17C15A)17C5A10B2C30B2C20B11D2G6C11G2D-2(10D2G6C11GD2-)30E3-28E4-10A4C14A5-9A4C13A6-10B6CH9B7-9B6CH8B9-7D12C3D11-6D12C2D14-2B12C2B18-3A6C3A23-6A43-F30-3F29-2F29-3F30-F30-3F29-2(3FI28-)3F30-3F28-3FI28-3F2-30A2-9A17C4A-10A17C15A17C5A10B2C30B2C20B-3(10D2G9C8GD2-)30E3-28E4-10A4C14A5-9A4C13A7-9B8H7B8-9B8H7B9-7D12C3D12-5D12CD15-2B12C2B18-3AB4CB3A24-B2AB235-2FI28-3F30-2(2FI29-)2F29-3F2-30A3(2-9A17C4A)2(2-9B2C19B)3(2-10D2G9C8GD)3-28E4-28E5-26A6-26A7-9B8H7B9-8B8H6B11-6D9C5D13-5D9C4D16-BA10CAB20-A3B2A3BA263-F-I28-4FI28-F-F98-30A3(2-9A17C4A)2(2-9B2C19B)2(2-10D2G7C11D)3-9D2G7C10D2(4-28E)5-26A7-24A8-9B8H7B9-8B8H6B11-6D9C5D14-4D9C3D17-3A8C3A21-3B2A3B200-F30-3(3F29-)3F100-28A4-8A17C3A3-2(9A17C4A2-)9B2C19B2-9B2C19B3-3(9D2G7C10D4-)28E5-26E6-26A7-24A9-8B8H6B11-7B8H5B13-5D9C4D15-DA2D9CDAD18-A3B4C3BA24-B2AB138-F30-4(3F29-)3FI2(29-2F29-3F)5-28A3(4-8A17C3A)2(4-8B2C18B)2(4-9D2G7C10D)5-8D2G7C9D2(6-26E)7-24A9-22A11-7B8H5B13-6B8H4B15-4D9C3D17-3D8C3D21-3B2A3B104-3F28-4(3F29-)4F28-3F30-2FI2(28-4F28-3F)6-26A2(6-7A17C2A)5-8A17C3A4-8B2C18B5-7B2C17B3(6-8D2G7C9D)7-24E8-24E9-22A10-22A11-7B8H5B13-6B8H4B16-14D20-10D26-2A106-4F28-5F27-2(3FI28-)3F4(I29-2F)29-3F29-2F29-3F7-24A7-3(7A17C2A6-)2(7B2C17B6-)8D2G7C9D7-2(7D2G7C8D8-)24E9-22E11-20A12-20A13-6B8H4B16-4B8H2B19-12D23-6D137-4F2(27-5F)28-2FI13-F12-F2-2F13-3F10-3F-2FI13-F11-2F3-F25-3F30-2F30-3F29-2F29-3F10-4(24A8-)2(6B2C16B8-)7D2G7C8D8-7D2G7C8D9-6D2G7C7D10-22E11-20E13-18A14-18A16-4B8H2B19-3B7H2B22-8D152-F17-F12-3F15-3F2(12-F)3-2F12-3F10-3F-3F12-3F10-3F2-F13-3F10-3I16-3F9-4I16-3F9-2IF18-F10-2I2F29-3I28-F3I28-3F11-4(22A10-)2(5B2C15B10-)6D2G7C7D10-6D2G7C7D11-5D2G7C6D12-20E13-18E15-16A17-14A19-12B22-8B183-2(3F29-)3F2-F7-3F16-3F-3F6-3F16-3F2-F7-3F16-3F10-3F16-3F2-F7-2F17-3F-3F5-F-F17-3F2-F4-F2-2F17-3F6-2FI2(-F)17-F7-2F3-F17-3F5-3F-3F13-18A13-3(20A12-)2(4B2C14B12-)5D2G7C6D13-4D2G7C5D14-4D2G7C5D15-16E16-16E17-14A20-10A24-6B217-F3-F4-F21-3F-3F2-3F21-F2-3F3-2F2-F17-3I-3F3-FI2-2F17-I2-I2F2(3-F)21-2IF2-2FI21-F2-2IF3-F21-I2F2(-2IF2-2FI20-3I)-I2F2-2FI20-3I2-F2-3FI20-2(3F-)3F18-2(16A16-)16A15-18A14-3B2C13B15-2B2C12B2(16-3D9G4D)17-2D9G3D18-14E19-12E22-8A27-2A254-2(3F2-3F24-)3F2-4F23-3F3-F2(I24-3F2-2F)IF23-3F2-3F24-3F2-3F21-F2-3F2-2FI20-3F-3F2-2FI21-F2-3F2-F22-2(3F-)3F2(20-12A)19-2(14A18-)14B18-14B19-12D20-12D21-10D23-8E26-4E318-F4-F25-3F2-4F24-F4-2F30-F26-F4-FIF23-2FI2-2F-F24-I4-F30-3F25-F4-F25-2F2(I30-)3F28-4A27-6A25-2(8A24-)8B24-8B25-6D27-4D398-
