model
size = 27 15 30, scale = 0.05, origin = -y
material 
  colors = A:#111 B:#222
voxels
----------AAAAAAA---------- ----------AAAAAAA---------- --------------------------- --------------------------- --------------------------- --------------------------- --------------------------- --------------------------- --------------------------- --------------------------- --------------------------- --------------------------- --------------------------- --------------------------- --------------------------- 
--------AAAAAAAAAAAA------- --------AAA------AAA------- --------------------------- --------------------------- --------------------------- --------------------------- --------------------------- --------------------------- --------------------------- --------------------------- --------------------------- --------------------------- --------------------------- --------------------------- --------------------------- 
-------AAAAAAAAAAAAAA------ -------A-----------AA------ --------------------------- --------------------------- --------------------------- --------------------------- --------------------------- --------------------------- --------------------------- --------------------------- --------------------------- --------------------------- --------------------------- --------------------------- --------------------------- 
-----AAAAAAAAAAAAAAAAAA---- -----AAA------------AAA---- --------------------------- --------------------------- --------------------------- --------------------------- --------------------------- --------------------------- --------------------------- --------------------------- --------------------------- --------------------------- --------------------------- --------------------------- --------------------------- 
----AAAAAAAAAAAAAAAAAAAA--- ----AA----------------AA--- --------------------------- --------------------------- --------------------------- --------------------------- --------------------------- --------------------------- --------------------------- --------------------------- --------------------------- --------------------------- --------------------------- --------------------------- --------------------------- 
---AAAAAAAAAAAAAAAAAAAAAA-- ---AA------BBBBBB-----AAA-- -----------BBBBBB---------- -----------AAAAAA---------- -----------AAAAAA---------- -----------AAAAAA---------- -----------AAAAAA---------- -----------AAAAAA---------- -----------AAAAAA---------- -----------AAAAAA---------- -----------AAAAAA---------- --------------------------- --------------------------- --------------------------- --------------------------- 
---AAAAAAAA------AAAAAAAA-- ---A-----BB------B-----AA-- ---------BB------B--------- ---------AA------A--------- ---------AA------A--------- ---------AA------A--------- ---------AA------A--------- ---------AA------A--------- ---------AA------A--------- ---------AA------A--------- ---------AAA-----A--------- ------------AAAAA---------- --------------------------- --------------------------- --------------------------- 
--AAAAAAA---------AAAAAAAA- --AA----B---------BB----AA- --------B---------BB------- --------A---------AA------- --------A---------AA------- --------A---------AA------- --------A---------AA------- --------A---------AA------- --------A---------AA------- --------A---------AA------- --------AA--------AA------- ----------AAA---AA--------- -------------AAA----------- -------------AAA----------- --------------------------- 
-AAAAAAA------------AAAAAA- -AA----B------------B----A- -------B------------B------ -------A------------A------ -------A------------A------ -------A------------A------ -------A------------A------ -------A------------A------ -------A------------A------ -------A------------A------ -------A-----------AA------ --------AAA------AA-------- -----------AA---A---------- -----------AAA-AA---------- --------------A------------ 
-AAAAAAA------------AAAAAA- -A-----B------------B----A- -------B------------B------ -------A------------A------ -------A------------A------ -------A------------A------ -------A------------A------ -------A------------A------ -------A------------A------ -------A------------A------ -------A------------A------ --------A---------AA------- ---------AA------A--------- ---------AAA-----A--------- ------------AAAAA---------- 
-AAAAAA--------------AAAAA- -A----B--------------B---A- ------B--------------B----- ------A--------------A----- ------A--------------A----- ------A--------------A----- ------A--------------A----- ------A--------------A----- ------A--------------A----- ------A--------------A----- ------A--------------A----- -------A-----------AA------ --------A---------A-------- --------AA-------AA-------- ----------AAAAAAA---------- 
AAAAAAA--------------AAAAAA AA----B--------------B---AA ------B--------------B----- ------A--------------A----- ------A--------------A----- ------A--------------A----- ------A--------------A----- ------A--------------A----- ------A--------------A----- ------A--------------A----- ------A--------------A----- -------A------------A------ --------A----------A------- --------A---------AA------- ---------AAAAAAAAA--------- 
AAAAAA----------------AAAAA A----B----------------B---A -----B----------------B---- -----A----------------A---- -----A----------------A---- -----A----------------A---- -----A----------------A---- -----A----------------A---- -----A----------------A---- -----A----------------A---- -----A----------------A---- ------AA------------AA----- --------A----------A------- --------A----------A------- --------AAAAAAAAAAA-------- 
AAAAAA----------------AAAAA A----B----------------B---A -----B----------------B---- -----A----------------A---- -----A----------------A---- -----A----------------A---- -----A----------------A---- -----A----------------A---- -----A----------------A---- -----A----------------A---- -----A----------------A---- ------A--------------A----- -------A------------A------ -------A------------A------ --------AAAAAAAAAAAA------- 
AAAAAA----------------AAAAA A----B----------------B---A -----A----------------B---- -----A----------------A---- -----A----------------A---- -----A----------------A---- -----A----------------A---- -----A----------------A---- -----A----------------A---- -----A----------------A---- -----A----------------A---- ------A--------------A----- -------A------------A------ -------A------------A------ --------AAAAAAAAAAAA------- 
AAAAAA----------------AAAAA A----B----------------B---A -----A----------------B---- -----A----------------A---- -----A----------------A---- -----A----------------A---- -----A----------------A---- -----A----------------A---- -----A----------------A---- -----A----------------A---- -----A----------------A---- ------A--------------A----- -------A------------A------ -------A------------A------ --------AAAAAAAAAAAA------- 
AAAAAA----------------AAAAA A----B----------------B---A -----B----------------B---- -----A----------------A---- -----A----------------A---- -----A----------------A---- -----A----------------A---- -----A----------------A---- -----A----------------A---- -----A----------------A---- -----A----------------A---- ------AA------------AA----- --------A----------A------- --------A----------A------- --------AAAAAAAAAAAA------- 
AAAAAA----------------AAAAA A----B----------------B--AA -----B----------------B---- -----A----------------A---- -----A----------------A---- -----A----------------A---- -----A----------------A---- -----A----------------A---- -----A----------------A---- -----A---------------AA---- -----AA--------------AA---- -------A------------A------ --------A----------A------- --------A----------A------- ---------AAAAAAAAAA-------- 
AAAAAAA--------------AAAAAA AA----B--------------B---AA ------B--------------B----- ------A--------------A----- ------A--------------A----- ------A--------------A----- ------A--------------A----- ------A--------------A----- ------A--------------A----- ------A--------------A----- ------A--------------A----- -------A------------A------ --------A----------A------- --------A---------AA------- ---------AAAAAAAAA--------- 
-AAAAAA--------------AAAAA- -A----B--------------B---A- ------B--------------B----- ------A--------------A----- ------A--------------A----- ------A--------------A----- ------A--------------A----- ------A--------------A----- ------A--------------A----- ------A-------------AA----- ------AA------------AA----- --------A----------A------- --------A---------A-------- --------A---------A-------- ---------AAAAAAAAA--------- 
-AAAAAAA------------AAAAAA- -A-----B------------B----A- -------B------------B------ -------A------------A------ -------A------------A------ -------A------------A------ -------A------------A------ -------A------------A------ -------A------------A------ -------A------------A------ -------A------------A------ --------A----------A------- ---------A-------AA-------- ---------AA-----AAA-------- -----------AAAAA----------- 
-AAAAAAA------------AAAAAA- -AA----B------------B----A- -------B------------B------ -------A------------A------ -------A------------A------ -------A------------A------ -------A------------A------ -------A------------A------ -------A------------A------ -------A-----------AA------ -------A-----------AA------ --------A--------AA-------- ---------AAA----A---------- ----------AAAA-AA---------- -------------AA------------ 
--AAAAAAA---------AAAAAAAA- --AA----B---------BB----AA- --------B---------BB------- --------A---------AA------- --------A---------AA------- --------A---------AA------- --------A---------AA------- --------A---------AA------- --------A---------AA------- --------A--------AAA------- --------A--------AAA------- ---------AAA----A---------- ------------A--A----------- ------------AAAA----------- --------------------------- 
---AAAAAAAA------AAAAAAAA-- ---A-----BB------B------A-- ---------BB------B--------- ---------AA------A--------- ---------AA------A--------- ---------AA------A--------- ---------AA------A--------- ---------AA------A--------- ---------AA------A--------- ---------AA------A--------- ---------AAA-----A--------- ------------AAAAA---------- -------------AA------------ --------------------------- --------------------------- 
---AAAAAAAAAAAAAAAAAAAAAA-- ---AA------BBBBBB------AA-- -----------BBBBBB---------- -----------AAAAAA---------- -----------AAAAAA---------- -----------AAAAAA---------- -----------AAAAAA---------- -----------AAAAAA---------- -----------AAAAAA---------- -----------AAAAAA---------- -----------AAAAAA---------- --------------------------- --------------------------- --------------------------- --------------------------- 
----AAAAAAAAAAAAAAAAAAAA--- ----AA----------------AA--- --------------------------- --------------------------- --------------------------- --------------------------- --------------------------- --------------------------- --------------------------- --------------------------- --------------------------- --------------------------- --------------------------- --------------------------- --------------------------- 
-----AAAAAAAAAAAAAAAAAA---- -----AAA------------AAA---- --------------------------- --------------------------- --------------------------- --------------------------- --------------------------- --------------------------- --------------------------- --------------------------- --------------------------- --------------------------- --------------------------- --------------------------- --------------------------- 
-------AAAAAAAAAAAAAA------ -------A-----------AA------ --------------------------- --------------------------- --------------------------- --------------------------- --------------------------- --------------------------- --------------------------- --------------------------- --------------------------- --------------------------- --------------------------- --------------------------- --------------------------- 
--------AAAAAAAAAAAA------- --------AAA------AAA------- --------------------------- --------------------------- --------------------------- --------------------------- --------------------------- --------------------------- --------------------------- --------------------------- --------------------------- --------------------------- --------------------------- --------------------------- --------------------------- 
----------AAAAAAA---------- ----------AAAAAAA---------- --------------------------- --------------------------- --------------------------- --------------------------- --------------------------- --------------------------- --------------------------- --------------------------- --------------------------- --------------------------- --------------------------- --------------------------- --------------------------- 
