model
size = 30 15 12, scale = 0.05, origin = -y
material 
  colors = A:#09C B:#0D0 C:#DDD
voxels
-----ABAAA----------AAABA----- ---BAAAAABBABABBABABBAAAAAB--- --ABABABAABBAAAAAABBAABABABA-- -BBABABABBBBBABBABBBBBABABABB- -AABBABABBABBBBBBBBABBABABBAA- BBBAABBAAAAAABAABAAAAAABBAABBB BABBBABBAABAAAAAAAABAABBABBBAB BAABBBBAAAABAABBAABAAAABBBBAAB ABBBBBABBBABAABBAABABBBABBBBBA AAAABABBBABAAABBAAABABBBABAAAA -ABABAAABAABAABBAABAABAAABABA- -ABBBBBBBAABABAABABAABBBBBBBA- --BBBBABABABBABBABBABABABBBB-- ---BAAAABBBBABAABABBBBAAAAB--- -----BBBBA----------ABBBB----- 
-----AAAAA----------AAAAA----- ---AAAAAAAAAAAAAAAAAAAAAAAA--- --AAAAAAAAAAAAAAAAAAAAAAAAAA-- -AAAAAAAAAAAAAAAAAAAAAAAAAAAA- -AAAAAAACCCCAAAAAACCCCAAAAAAA- AAAAAAACCCCCCAAAACCCCCCAAAAAAA AAAAAACCCCCCCCAACCCCCCCCAAAAAA AAAAAACCCCCCCCAACCCCCCCCAAAAAA AAAAAACCCCCCCCAACCCCCCCCAAAAAA AAAAAACCCCCCCCAACCCCCCCCAAAAAA -AAAAAACCCCCCAAAACCCCCCAAAAAA- -AAAAAAACCCCAAAAAACCCCAAAAAAA- --AAAAAAAAAAAAAAAAAAAAAAAAAA-- ---AAAAAAAAAAAAAAAAAAAAAAAA--- -----AAAAA----------AAAAA----- 
-----AAAAA----------AAAAA----- ---AAAAAAAAAAAAAAAAAAAAAAAA--- --AAAAAAAAAAAAAAAAAAAAAAAAAA-- -AAAAA------------------AAAAA- -AAAAA------------------AAAAA- AAAAAA------------------AAAAAA AAAAAA------------------AAAAAA AAAAAA------------------AAAAAA AAAAAA------------------AAAAAA AAAAAA------------------AAAAAA -AAAAA------------------AAAAA- -AAAAA------------------AAAAA- --AAAA------------------AAAA-- ---AAAAAAAAAAAAAAAAAAAAAAAA--- -----AAAAA----------AAAAA----- 
-----AAAAA----------AAAAA----- ---AAAAAAAAAAAAAAAAAAAAAAAA--- --AAAAAAABABBBAABBBABAAAAAAA-- -AAAAA------------------AAAAA- -AAAAA------------------AAAAA- AAAAAA------------------AAAAAA AAAAAA------------------AAAAAA AAAAAA------------------AAAAAA AAAAAA------------------AAAAAA AAAAAA------------------AAAAAA -AAAAA------------------AAAAA- -AAAAA------------------AAAAA- --AAAA------------------AAAA-- ---AAAAAAAAAAAAAAAAAAAAAAAA--- -----AAAAA----------AAAAA----- 
-----AAAAA----------AAAAA----- ---AAAAAAAAAAAAAAAAAAAAAAAA--- --AAAA------------------AAAA-- -AAAAA------------------AAAAA- -AAAAA------------------AAAAA- AAAAAA------------------AAAAAA AAAAAA------------------AAAAAA BAAAAA------------------AAAAAB AAAAAA------------------AAAAAA AAAAAA------------------AAAAAA -AAAAA------------------AAAAA- -AAAAA------------------AAAAA- --AAAA------------------AAAA-- ---AAAAAAAAAAAAAAAAAAAAAAAA--- -----AAAAA----------AAAAA----- 
-----AAAAA----------AAAAA----- ---AAAAAAAAAAAAAAAAAAAAAAAA--- --AAAA------------------AAAA-- -AAAAA------------------AAAAA- -AAAAA------------------AAAAA- AAAAAA------------------AAAAAA AAAAAA------------------AAAAAA BAAAAA------------------AAAAAB AAAAAA------------------AAAAAA AAAAAA------------------AAAAAA -AAAAA------------------AAAAA- -AAAAA------------------AAAAA- --AAAA------------------AAAA-- ---AAAAAAAAAAAAAAAAAAAAAAAA--- -----AAAAA----------AAAAA----- 
-----ABABA----------ABABA----- ---AAAABBBAABABBABAABBBAAAA--- --AAAB------------------BAAA-- -AAAAA------------------AAAAA- -AAAAB------------------BAAAA- AAAAAB------------------BAAAAA AAAAAB------------------BAAAAA AAAAAB------------------BAAAAA AAAAAB------------------BAAAAA AAAAAA------------------AAAAAA -AAAAA------------------AAAAA- -AAAAA------------------AAAAA- --AAAA------------------AAAA-- ---AAAAAAAABBBAABBBAAAAAAAA--- -----AABAA----------AABAA----- 
------------------------------ ---AB--------------------BA--- --AAB--------------------BAA-- -AAAA--------------------AAAA- -AAAB--------------------BAAA- BAAAB--------------------BAAAB AAAAA--------------------AAAAA AAAAB--------------------BAAAA AAAAB--------------------BAAAA BAAAB--------------------BAAAB -AAAB--------------------BAAA- -AAAB--------------------BAAA- --AAB--------------------BAA-- ---AA--------------------AA--- ------------------------------ 
------------------------------ ---A----------------------A--- --AA----------------------AA-- -AAA----------------------AAA- -AAB----------------------BAA- AAAA----------------------AAAA AAAA----------------------AAAA AAAA----------------------AAAA AAAA----------------------AAAA AAAB----------------------BAAA -AAA----------------------AAA- -AAA----------------------AAA- --AB----------------------BA-- ---A----------------------A--- ------------------------------ 
------------------------------ ------------------------------ --B------------------------B-- -AB------------------------BA- -AB------------------------BA- AAB------------------------BAA AAA------------------------AAA AAB------------------------BAA AAB------------------------BAA AAB------------------------BAA -AA------------------------AA- -AB------------------------BA- --B------------------------B-- ------------------------------ ------------------------------ 
------------------------------ ------------------------------ ------------------------------ -A--------------------------A- -B--------------------------B- BB--------------------------BB AA--------------------------AA AB--------------------------BA AB--------------------------BA BB--------------------------BB -A--------------------------A- -B--------------------------B- ------------------------------ ------------------------------ ------------------------------ 
------------------------------ ------------------------------ ------------------------------ ------------------------------ ------------------------------ B----------------------------B A----------------------------A B----------------------------B A----------------------------A A----------------------------A ------------------------------ ------------------------------ ------------------------------ ------------------------------ ------------------------------ 
