model
size = 30 15 12, scale = 0.05, origin = -y
material 
  colors = A:#C9C B:#93F C:#F66
voxels
-----CACBA----------ABCAC----- ---CCAABABCBBAAAABBCBABAACC--- --CACCBACCBBABAABABBCCABCCAC-- -BAACCCAAACABAAAABACAAACCCAAB- -ACCACAABABBBABBABBBABAACACCA- ACACBABAAABABACCABABAAABABCACA CCABAAACCACCBCCCCBCCACCAAABACC CBAACACABBACBBBBBBCABBACACAABC ACCAAACBCAABBCBBCBBAACBCAAACCA CCABBABBCAAAAACCAAAAACBBABBACC -CCAAABBAAACAACCAACAAABBAAACC- -ABBAAABAACACAAAACACAABAAABBA- --BCACCBBCCACAAAACACCBBCCACB-- ---ACBCBCCABCAAAACBACCBCBCA--- -----ABACA----------ACABA----- 
-----BBBAA----------AABBB----- ---AAAAAAACCBAAAABCCAAAAAAA--- --AAAAAAAAAAAAAAAAAAAAAAAAAA-- -AAAAAAAAAAAAAAAAAAAAAAAAAAAA- -AAAAAAABBBBAAAAAABBBBAAAAAAA- AAAAAAABBBBBBAAAABBBBBBAAAAAAA AAAAAABBBBBBBBAABBBBBBBBAAAAAA AAAAAABBBBBBBBAABBBBBBBBAAAAAA AAAAAABBBBBBBBAABBBBBBBBAAAAAA AAAAAABBBBBBBBAABBBBBBBBAAAAAA -AAAAAABBBBBBAAAABBBBBBAAAAAA- -AAAAAAABBBBAAAAAABBBBAAAAAAA- --AAAAAAAAAAAAAAAAAAAAAAAAAA-- ---AAAAAAACCBAAAABCCAAAAAAA--- -----BBBAA----------AABBB----- 
-----BCCAC----------CACCB----- ---AAAAAAAABCCAACCBAAAAAAAA--- --AAAAAAAAAAAAAAAAAAAAAAAAAA-- -AAAAA------------------AAAAA- -AAAAA------------------AAAAA- AAAAAA------------------AAAAAA AAAAAA------------------AAAAAA AAAAAA------------------AAAAAA AAAAAA------------------AAAAAA AAAAAA------------------AAAAAA -AAAAA------------------AAAAA- -AAAAA------------------AAAAA- --AAAA------------------AAAA-- ---AAAAAAAABCCAACCBAAAAAAAA--- -----BCCAC----------CACCB----- 
-----CCBBC----------CBBCC----- ---AAAAAAABABBAABBABAAAAAAA--- --AAAAAAAAAAAAAAAAAAAAAAAAAA-- -AAAAA------------------AAAAA- -AAAAA------------------AAAAA- AAAAAA------------------AAAAAA AAAAAA------------------AAAAAA AAAAAA------------------AAAAAA AAAAAA------------------AAAAAA AAAAAA------------------AAAAAA -AAAAA------------------AAAAA- -AAAAA------------------AAAAA- --AAAA------------------AAAA-- ---AAAAAAABABBAABBABAAAAAAA--- -----CCBBC----------CBBCC----- 
-----CBBAC----------CABBC----- ---AAAAAAACBACCCCABCAAAAAAA--- --AAAA------------------AAAA-- -AAAAA------------------AAAAA- -AAAAA------------------AAAAA- AAAAAA------------------AAAAAA AAAAAA------------------AAAAAA AAAAAA------------------AAAAAA AAAAAA------------------AAAAAA AAAAAA------------------AAAAAA -AAAAA------------------AAAAA- -AAAAA------------------AAAAA- --AAAA------------------AAAA-- ---AAAAAAACBACCCCABCAAAAAAA--- -----CBBAC----------CABBC----- 
-----CABBB----------BBBAC----- ---AAAAAAAACCCBBCCCAAAAAAAA--- --AAAA------------------AAAA-- -AAAAA------------------AAAAA- -AAAAA------------------AAAAA- AAAAAA------------------AAAAAA AAAAAA------------------AAAAAA AAAAAA------------------AAAAAA AAAAAA------------------AAAAAA AAAAAA------------------AAAAAA -AAAAA------------------AAAAA- -AAAAA------------------AAAAA- --AAAA------------------AAAA-- ---AAAAAAAACCCBBCCCAAAAAAAA--- -----CABBB----------BBBAC----- 
-----AAAAA----------AAAAA----- ---AAAAAAAAAAAAAAAAAAAAAAAA--- --AAAA------------------AAAA-- -AAAAA------------------AAAAA- -AAAAA------------------AAAAA- AAAAAA------------------AAAAAA AAAAAA------------------AAAAAA AAAAAA------------------AAAAAA AAAAAA------------------AAAAAA AAAAAA------------------AAAAAA -AAAAA------------------AAAAA- -AAAAA------------------AAAAA- --AAAA------------------AAAA-- ---AAAAAAAAAAAAAAAAAAAAAAAA--- -----AAAAA----------AAAAA----- 
------------------------------ ---AA--------------------AA--- --AAA--------------------AAA-- -AAAA--------------------AAAA- -AAAA--------------------AAAA- AAAAA--------------------AAAAA AAAAA--------------------AAAAA AAAAA--------------------AAAAA AAAAA--------------------AAAAA AAAAA--------------------AAAAA -AAAA--------------------AAAA- -AAAA--------------------AAAA- --AAA--------------------AAA-- ---AA--------------------AA--- ------------------------------ 
------------------------------ ---A----------------------A--- --AA----------------------AA-- -AAA----------------------AAA- -AAA----------------------AAA- AAAA----------------------AAAA AAAA----------------------AAAA AAAA----------------------AAAA AAAA----------------------AAAA AAAA----------------------AAAA -AAA----------------------AAA- -AAA----------------------AAA- --AA----------------------AA-- ---A----------------------A--- ------------------------------ 
------------------------------ ------------------------------ --A------------------------A-- -AA------------------------AA- -AA------------------------AA- AAA------------------------AAA AAA------------------------AAA AAA------------------------AAA AAA------------------------AAA AAA------------------------AAA -AA------------------------AA- -AA------------------------AA- --A------------------------A-- ------------------------------ ------------------------------ 
------------------------------ ------------------------------ ------------------------------ -A--------------------------A- -A--------------------------A- AA--------------------------AA AA--------------------------AA AA--------------------------AA AA--------------------------AA AA--------------------------AA -A--------------------------A- -A--------------------------A- ------------------------------ ------------------------------ ------------------------------ 
------------------------------ ------------------------------ ------------------------------ ------------------------------ ------------------------------ A----------------------------A A----------------------------A A----------------------------A A----------------------------A A----------------------------A ------------------------------ ------------------------------ ------------------------------ ------------------------------ ------------------------------ 
