model
size = 30 15 12, scale = 0.05, origin = -y
material 
  colors = A:#369 B:#800 C:#006
voxels
-----AABCB----------BCBAA----- ---AAAABCAAAAAAAAAAAACBAAAA--- --AAACBBBAAAAAAAAAAAABBBCAAA-- -AABACACAACCBBAABBCCAACACABAA- -BABCAAAABCBBCAACBBCBAAAACBAB- ABAAAACBCAACBCAACBCAACBCAAAABA CBCABCAAAAAABAAAABAAAAAACBACBC ABAABACAAAACAAAAAACAAAACABAABA BAACAABACABACABBACABACABAACAAB CACCBAAAAABCBACCABCBAAAAABCCAC -BCABBAAABAABAAAABAABAAABBACB- -ABABACCCACAAAAAAAACACCCABABA- --ABAACBAAACBAAAABCAAABCAABA-- ---BBAAAAABBAACCAABBAAAAABB--- -----ABBAA----------AABBA----- 
-----AAAAA----------AAAAA----- ---AAAAAAAAAAAAAAAAAAAAAAAA--- --AAAAAAAAAAAAAAAAAAAAAAAAAA-- -AAAAAAAAAAAAAAAAAAAAAAAAAAAA- -AAAAAAABBBBAAAAAABBBBAAAAAAA- CAAAAAABBBBBBAAAABBBBBBAAAAAAC CAAAAABBBBBBBBAABBBBBBBBAAAAAC BAAAAABBBBBBBBAABBBBBBBBAAAAAB CAAAAABBBBBBBBAABBBBBBBBAAAAAC CAAAAABBBBBBBBAABBBBBBBBAAAAAC -AAAAAABBBBBBAAAABBBBBBAAAAAA- -AAAAAAABBBBAAAAAABBBBAAAAAAA- --AAAAAAAAAAAAAAAAAAAAAAAAAA-- ---AAAAAAAAAAAAAAAAAAAAAAAA--- -----AAAAA----------AAAAA----- 
-----AAAAA----------AAAAA----- ---AAAAAAAAAAAAAAAAAAAAAAAA--- --AAAAAAAAAAAAAAAAAAAAAAAAAA-- -AAAAA------------------AAAAA- -AAAAA------------------AAAAA- CAAAAA------------------AAAAAC CAAAAA------------------AAAAAC BAAAAA------------------AAAAAB CAAAAA------------------AAAAAC CAAAAA------------------AAAAAC -AAAAA------------------AAAAA- -AAAAA------------------AAAAA- --AAAA------------------AAAA-- ---AAAAAAAAAAAAAAAAAAAAAAAA--- -----AAAAA----------AAAAA----- 
-----AAAAA----------AAAAA----- ---AAAAAAAAAAAAAAAAAAAAAAAA--- --AAAAAAABCABBBBBBACBAAAAAAA-- -AAAAA------------------AAAAA- -AAAAA------------------AAAAA- BAAAAA------------------AAAAAB BAAAAA------------------AAAAAB AAAAAA------------------AAAAAA BAAAAA------------------AAAAAB BAAAAA------------------AAAAAB -AAAAA------------------AAAAA- -AAAAA------------------AAAAA- --AAAA------------------AAAA-- ---AAAAAAAAAAAAAAAAAAAAAAAA--- -----AAAAA----------AAAAA----- 
-----AAAAA----------AAAAA----- ---AAAAAAAAAAAAAAAAAAAAAAAA--- --AAAA------------------AAAA-- -AAAAA------------------AAAAA- -AAAAA------------------AAAAA- CAAAAA------------------AAAAAC AAAAAA------------------AAAAAA BAAAAA------------------AAAAAB AAAAAA------------------AAAAAA CAAAAA------------------AAAAAC -AAAAA------------------AAAAA- -AAAAA------------------AAAAA- --AAAA------------------AAAA-- ---AAAAAAAAAAAAAAAAAAAAAAAA--- -----AAAAA----------AAAAA----- 
-----AAAAA----------AAAAA----- ---AAAAAAAAAAAAAAAAAAAAAAAA--- --AAAA------------------AAAA-- -AAAAA------------------AAAAA- -AAAAA------------------AAAAA- BAAAAA------------------AAAAAB BAAAAA------------------AAAAAB BAAAAA------------------AAAAAB BAAAAA------------------AAAAAB BAAAAA------------------AAAAAB -AAAAA------------------AAAAA- -AAAAA------------------AAAAA- --AAAA------------------AAAA-- ---AAAAAAAAAAAAAAAAAAAAAAAA--- -----AAAAA----------AAAAA----- 
-----CCACA----------ACACC----- ---AACABAABABAAAABABAABACAA--- --AAAC------------------CAAA-- -AAAAA------------------AAAAA- -AAAAA------------------AAAAA- BAAAAC------------------CAAAAB BAAAAA------------------AAAAAB CAAAAC------------------CAAAAC BAAAAC------------------CAAAAB BAAAAC------------------CAAAAB -AAAAA------------------AAAAA- -AAAAA------------------AAAAA- --AAAB------------------BAAA-- ---AABACBACACCBBCCACABCABAA--- -----BCBCB----------BCBCB----- 
------------------------------ ---AB--------------------BA--- --AAA--------------------AAA-- -AAAB--------------------BAAA- -AAAB--------------------BAAA- CAAAA--------------------AAAAC AAAAA--------------------AAAAA AAAAB--------------------BAAAA AAAAA--------------------AAAAA CAAAC--------------------CAAAC -AAAA--------------------AAAA- -AAAA--------------------AAAA- --AAB--------------------BAA-- ---AA--------------------AA--- ------------------------------ 
------------------------------ ---A----------------------A--- --AB----------------------BA-- -AAA----------------------AAA- -AAC----------------------CAA- CAAA----------------------AAAC CAAA----------------------AAAC AAAA----------------------AAAA CAAB----------------------BAAC CAAC----------------------CAAC -AAA----------------------AAA- -AAB----------------------BAA- --AB----------------------BA-- ---A----------------------A--- ------------------------------ 
------------------------------ ------------------------------ --B------------------------B-- -AA------------------------AA- -AA------------------------AA- AAA------------------------AAA CAA------------------------AAC AAA------------------------AAA CAA------------------------AAC AAC------------------------CAA -AA------------------------AA- -AC------------------------CA- --B------------------------B-- ------------------------------ ------------------------------ 
------------------------------ ------------------------------ ------------------------------ -B--------------------------B- -A--------------------------A- BA--------------------------AB BA--------------------------AB AA--------------------------AA BA--------------------------AB BB--------------------------BB -B--------------------------B- -A--------------------------A- ------------------------------ ------------------------------ ------------------------------ 
------------------------------ ------------------------------ ------------------------------ ------------------------------ ------------------------------ A----------------------------A B----------------------------B B----------------------------B A----------------------------A A----------------------------A ------------------------------ ------------------------------ ------------------------------ ------------------------------ ------------------------------ 
