model
size = 30 15 12, scale = 0.05, origin = -y
material 
  colors = A:#6F6 B:#09F C:#0CF
voxels
-----ABABB----------BBABA----- ---CBAAAACABBBCCBBBACAAAABC--- --ABAAABACAAACCCCAAACABAAABA-- -BABBCCAAABCBAAAABCBAAACCBBAB- -AACCBAAAAABCBAABCBAAAAABCCAA- AABAABBACAAAAABBAAAAACABBAABAA AABAAABBBBBBBCCCCBBBBBBBAAABAA CCABCABCACACABCCBACACACBACBACC ABCABCAAABABAABBAABABAAACBACBA AABBAAABCABACBAABCABACBAAABBAA -AACABBCCAAABAAAABAAACCBBACAA- -AAAACBAABBCBBCCBBCBBAABCAAAA- --AAAACAABBCCBCCBCCBBAACAAAA-- ---AAABBAABBAACCAABBAABBAAA--- -----AAACB----------BCAAA----- 
-----AAAAA----------AAAAA----- ---AAAAAAAAAAAAAAAAAAAAAAAA--- --AAAAAAAAAAAAAAAAAAAAAAAAAA-- -AAAAAAAAAAAAAAAAAAAAAAAAAAAA- -AAAAAAABBBBAAAAAABBBBAAAAAAA- AAAAAAABBBBBBAAAABBBBBBAAAAAAA AAAAAABBBBBBBBAABBBBBBBBAAAAAA BAAAAABBBBBBBBAABBBBBBBBAAAAAB AAAAAABBBBBBBBAABBBBBBBBAAAAAA AAAAAABBBBBBBBAABBBBBBBBAAAAAA -AAAAAABBBBBBAAAABBBBBBAAAAAA- -AAAAAAABBBBAAAAAABBBBAAAAAAA- --AAAAAAAAAAAAAAAAAAAAAAAAAA-- ---AAAAAAAAAAAAAAAAAAAAAAAA--- -----AAAAA----------AAAAA----- 
-----AAAAA----------AAAAA----- ---AAAAAAAAAAAAAAAAAAAAAAAA--- --AAAAAAAAAAAAAAAAAAAAAAAAAA-- -AAAAA------------------AAAAA- -AAAAA------------------AAAAA- BAAAAA------------------AAAAAB AAAAAA------------------AAAAAA AAAAAA------------------AAAAAA AAAAAA------------------AAAAAA BAAAAA------------------AAAAAB -AAAAA------------------AAAAA- -AAAAA------------------AAAAA- --AAAA------------------AAAA-- ---AAAAAAAAAAAAAAAAAAAAAAAA--- -----AAAAA----------AAAAA----- 
-----AAAAA----------AAAAA----- ---AAAAAAAAAAAAAAAAAAAAAAAA--- --AAAACCBAACABAABACAABCCAAAA-- -AAAAA------------------AAAAA- -AAAAA------------------AAAAA- BAAAAA------------------AAAAAB AAAAAA------------------AAAAAA AAAAAA------------------AAAAAA AAAAAA------------------AAAAAA BAAAAA------------------AAAAAB -AAAAA------------------AAAAA- -AAAAA------------------AAAAA- --AAAA------------------AAAA-- ---AAAAAAAAAAAAAAAAAAAAAAAA--- -----AAAAA----------AAAAA----- 
-----AAAAA----------AAAAA----- ---AAAAAAAAAAAAAAAAAAAAAAAA--- --AAAA------------------AAAA-- -AAAAA------------------AAAAA- -AAAAA------------------AAAAA- BAAAAA------------------AAAAAB AAAAAA------------------AAAAAA BAAAAA------------------AAAAAB AAAAAA------------------AAAAAA BAAAAA------------------AAAAAB -AAAAA------------------AAAAA- -AAAAA------------------AAAAA- --AAAA------------------AAAA-- ---AAAAAAAAAAAAAAAAAAAAAAAA--- -----AAAAA----------AAAAA----- 
-----AAAAA----------AAAAA----- ---AAAAAAAAAAAAAAAAAAAAAAAA--- --AAAA------------------AAAA-- -AAAAA------------------AAAAA- -AAAAA------------------AAAAA- AAAAAA------------------AAAAAA CAAAAA------------------AAAAAC AAAAAA------------------AAAAAA CAAAAA------------------AAAAAC AAAAAA------------------AAAAAA -AAAAA------------------AAAAA- -AAAAA------------------AAAAA- --AAAA------------------AAAA-- ---AAAAAAAAAAAAAAAAAAAAAAAA--- -----AAAAA----------AAAAA----- 
-----CAAAC----------CAAAC----- ---AACCAACAACAAAACAACAACCAA--- --AAAA------------------AAAA-- -AAAAA------------------AAAAA- -AAAAA------------------AAAAA- AAAAAC------------------CAAAAA BAAAAA------------------AAAAAB AAAAAA------------------AAAAAA BAAAAA------------------AAAAAB AAAAAA------------------AAAAAA -AAAAA------------------AAAAA- -AAAAC------------------CAAAA- --AAAA------------------AAAA-- ---AAACAAAAACABBACAAAAACAAA--- -----AABAA----------AABAA----- 
------------------------------ ---AB--------------------BA--- --AAA--------------------AAA-- -AAAA--------------------AAAA- -AAAA--------------------AAAA- CAAAA--------------------AAAAC CAAAA--------------------AAAAC BAAAC--------------------CAAAB CAAAB--------------------BAAAC CAAAC--------------------CAAAC -AAAA--------------------AAAA- -AAAC--------------------CAAA- --AAA--------------------AAA-- ---AC--------------------CA--- ------------------------------ 
------------------------------ ---A----------------------A--- --AC----------------------CA-- -AAA----------------------AAA- -AAA----------------------AAA- CAAB----------------------BAAC AAAA----------------------AAAA AAAA----------------------AAAA AAAA----------------------AAAA CAAB----------------------BAAC -AAB----------------------BAA- -AAA----------------------AAA- --AB----------------------BA-- ---A----------------------A--- ------------------------------ 
------------------------------ ------------------------------ --A------------------------A-- -AC------------------------CA- -AB------------------------BA- AAB------------------------BAA BAA------------------------AAB AAB------------------------BAA BAA------------------------AAB AAB------------------------BAA -AC------------------------CA- -AC------------------------CA- --A------------------------A-- ------------------------------ ------------------------------ 
------------------------------ ------------------------------ ------------------------------ -A--------------------------A- -A--------------------------A- AA--------------------------AA AB--------------------------BA AB--------------------------BA AA--------------------------AA AA--------------------------AA -A--------------------------A- -A--------------------------A- ------------------------------ ------------------------------ ------------------------------ 
------------------------------ ------------------------------ ------------------------------ ------------------------------ ------------------------------ A----------------------------A B----------------------------B C----------------------------C B----------------------------B B----------------------------B ------------------------------ ------------------------------ ------------------------------ ------------------------------ ------------------------------ 
