model
size = 30 15 12, scale = 0.05, origin = -y
material 
  colors = A:#3F9 B:#036 C:#663
voxels
-----CBBAA----------AABBC----- ---AAABBBAACAAAAAACAABBBAAA--- --CAACBCCACBBAAAABBCACCBCAAC-- -CBCBCCAAAAACAAAACAAAAACCBCBC- -AAABAACAAABABCCBABAAACAABAAA- AAAAABAAACABBBBBBBBACAAABAAAAA CACCAABAAACBABAABABCAAABAACCAC BAAAAAABAAACBBAABBCAAABAAAAAAB BABAAAAACAAACAAAACAAACAAAAABAB BAAAABACBAACCBCCBCCAABCABAAAAB -ACBCBAAABCBCAAAACBCBAAABCBCA- -AAAACACABCBAAAAAABCBACACAAAA- --ABAACCCBACBBAABBCABCCCAABA-- ---AAAABAACBBACCABBCAABAAAA--- -----BCCBA----------ABCCB----- 
-----AAAAA----------AAAAA----- ---AAAAAAAAAAAAAAAAAAAAAAAA--- --AAAAAAAAAAAAAAAAAAAAAAAAAA-- -AAAAAAAAAAAAAAAAAAAAAAAAAAAA- -AAAAAAABBBBAAAAAABBBBAAAAAAA- BAAAAAABBBBBBAAAABBBBBBAAAAAAB BAAAAABBBBBBBBAABBBBBBBBAAAAAB BAAAAABBBBBBBBAABBBBBBBBAAAAAB BAAAAABBBBBBBBAABBBBBBBBAAAAAB BAAAAABBBBBBBBAABBBBBBBBAAAAAB -AAAAAABBBBBBAAAABBBBBBAAAAAA- -AAAAAAABBBBAAAAAABBBBAAAAAAA- --AAAAAAAAAAAAAAAAAAAAAAAAAA-- ---AAAAAAAAAAAAAAAAAAAAAAAA--- -----AAAAA----------AAAAA----- 
-----AAAAA----------AAAAA----- ---AAAAAAAAAAAAAAAAAAAAAAAA--- --AAAAAAAAAAAAAAAAAAAAAAAAAA-- -AAAAA------------------AAAAA- -AAAAA------------------AAAAA- AAAAAA------------------AAAAAA AAAAAA------------------AAAAAA AAAAAA------------------AAAAAA AAAAAA------------------AAAAAA AAAAAA------------------AAAAAA -AAAAA------------------AAAAA- -AAAAA------------------AAAAA- --AAAA------------------AAAA-- ---AAAAAAAAAAAAAAAAAAAAAAAA--- -----AAAAA----------AAAAA----- 
-----AAAAA----------AAAAA----- ---AAAAAAAAAAAAAAAAAAAAAAAA--- --AAAACCACABBCCCCBBACACCAAAA-- -AAAAA------------------AAAAA- -AAAAA------------------AAAAA- AAAAAA------------------AAAAAA AAAAAA------------------AAAAAA CAAAAA------------------AAAAAC AAAAAA------------------AAAAAA AAAAAA------------------AAAAAA -AAAAA------------------AAAAA- -AAAAA------------------AAAAA- --AAAA------------------AAAA-- ---AAAAAAAAAAAAAAAAAAAAAAAA--- -----AAAAA----------AAAAA----- 
-----AAAAA----------AAAAA----- ---AAAAAAAAAAAAAAAAAAAAAAAA--- --AAAA------------------AAAA-- -AAAAA------------------AAAAA- -AAAAA------------------AAAAA- CAAAAA------------------AAAAAC AAAAAA------------------AAAAAA BAAAAA------------------AAAAAB AAAAAA------------------AAAAAA CAAAAA------------------AAAAAC -AAAAA------------------AAAAA- -AAAAA------------------AAAAA- --AAAA------------------AAAA-- ---AAAAAAAAAAAAAAAAAAAAAAAA--- -----AAAAA----------AAAAA----- 
-----AAAAA----------AAAAA----- ---AAAAAAAAAAAAAAAAAAAAAAAA--- --AAAA------------------AAAA-- -AAAAA------------------AAAAA- -AAAAA------------------AAAAA- AAAAAA------------------AAAAAA AAAAAA------------------AAAAAA BAAAAA------------------AAAAAB AAAAAA------------------AAAAAA AAAAAA------------------AAAAAA -AAAAA------------------AAAAA- -AAAAA------------------AAAAA- --AAAA------------------AAAA-- ---AAAAAAAAAAAAAAAAAAAAAAAA--- -----AAAAA----------AAAAA----- 
-----BBCCA----------ACCBB----- ---AABCCBBBABABBABABBBCCBAA--- --AAAA------------------AAAA-- -AAAAC------------------CAAAA- -AAAAB------------------BAAAA- BAAAAB------------------BAAAAB AAAAAB------------------BAAAAA AAAAAB------------------BAAAAA AAAAAB------------------BAAAAA BAAAAB------------------BAAAAB -AAAAB------------------BAAAA- -AAAAA------------------AAAAA- --AAAB------------------BAAA-- ---AACACABACBCBBCBCABACACAA--- -----CBBAB----------BABBC----- 
------------------------------ ---AA--------------------AA--- --AAC--------------------CAA-- -AAAC--------------------CAAA- -AAAC--------------------CAAA- AAAAB--------------------BAAAA AAAAC--------------------CAAAA CAAAB--------------------BAAAC AAAAA--------------------AAAAA AAAAC--------------------CAAAA -AAAB--------------------BAAA- -AAAA--------------------AAAA- --AAC--------------------CAA-- ---AB--------------------BA--- ------------------------------ 
------------------------------ ---A----------------------A--- --AB----------------------BA-- -AAA----------------------AAA- -AAC----------------------CAA- CAAA----------------------AAAC BAAA----------------------AAAB BAAB----------------------BAAB BAAC----------------------CAAB CAAC----------------------CAAC -AAB----------------------BAA- -AAC----------------------CAA- --AA----------------------AA-- ---A----------------------A--- ------------------------------ 
------------------------------ ------------------------------ --B------------------------B-- -AB------------------------BA- -AB------------------------BA- CAA------------------------AAC CAB------------------------BAC AAC------------------------CAA CAB------------------------BAC CAC------------------------CAC -AB------------------------BA- -AC------------------------CA- --B------------------------B-- ------------------------------ ------------------------------ 
------------------------------ ------------------------------ ------------------------------ -B--------------------------B- -C--------------------------C- AB--------------------------BA BC--------------------------CB AC--------------------------CA BA--------------------------AB AC--------------------------CA -B--------------------------B- -C--------------------------C- ------------------------------ ------------------------------ ------------------------------ 
------------------------------ ------------------------------ ------------------------------ ------------------------------ ------------------------------ C----------------------------C B----------------------------B B----------------------------B B----------------------------B B----------------------------B ------------------------------ ------------------------------ ------------------------------ ------------------------------ ------------------------------ 
