model
size = 30 15 12, scale = 0.05, origin = -y
material 
  colors = A:#3F6 B:#F0F C:#F36
voxels
-----AAAAA----------AAAAA----- ---BABAAAABBAABBAABBAAAABAB--- --BBAAAAABBAABAABAABBAAAAABB-- -AAAABABBBABBABBABBABBBABAAAA- -ABBAAAAAABABBBBBBABAAAAAABBA- BBABBBABABBBAABBAABBBABABBBABB BBBBAABAABAAABAABAAABAABAABBBB BABABBBBBABAABBBBAABABBBBBABAB AABAAABBBBAABAAAABAABBBBAAABAA ABBAABBAAABABAAAABABAAABBAABBA -AABBAABBABAABAABAABABBAABBAA- -AABBBABBBAABBBBBBAABBBABBBAA- --BBBBBABBBABAAAABABBBABBBBB-- ---AABBBBBAABAAAABAABBBBBAA--- -----AAABB----------BBAAA----- 
-----ABBBA----------ABBBA----- ---AAAAAAABAABAABAABAAAAAAA--- --AAAAAAAAAAAAAAAAAAAAAAAAAA-- -AAAAAAAAAAAAAAAAAAAAAAAAAAAA- -AAAAAAACCCCAAAAAACCCCAAAAAAA- AAAAAAACCCCCCAAAACCCCCCAAAAAAA BAAAAACCCCCCCCAACCCCCCCCAAAAAB BAAAAACCCCCCCCAACCCCCCCCAAAAAB BAAAAACCCCCCCCAACCCCCCCCAAAAAB AAAAAACCCCCCCCAACCCCCCCCAAAAAA -AAAAAACCCCCCAAAACCCCCCAAAAAA- -AAAAAAACCCCAAAAAACCCCAAAAAAA- --AAAAAAAAAAAAAAAAAAAAAAAAAA-- ---AAAAAAABAABAABAABAAAAAAA--- -----ABBBA----------ABBBA----- 
-----BBBBA----------ABBBB----- ---AAAAAAABBABAABABBAAAAAAA--- --AAAAAAAAAAAAAAAAAAAAAAAAAA-- -AAAAA------------------AAAAA- -AAAAA------------------AAAAA- BAAAAA------------------AAAAAB BAAAAA------------------AAAAAB BAAAAA------------------AAAAAB BAAAAA------------------AAAAAB BAAAAA------------------AAAAAB -AAAAA------------------AAAAA- -AAAAA------------------AAAAA- --AAAA------------------AAAA-- ---AAAAAAABBABAABABBAAAAAAA--- -----BBBBA----------ABBBB----- 
-----BAAAB----------BAAAB----- ---AAAAAAAAAABBBBAAAAAAAAAA--- --AAAABBBAABAABBAABAABBBAAAA-- -AAAAA------------------AAAAA- -AAAAA------------------AAAAA- AAAAAA------------------AAAAAA BAAAAA------------------AAAAAB BAAAAA------------------AAAAAB BAAAAA------------------AAAAAB AAAAAA------------------AAAAAA -AAAAA------------------AAAAA- -AAAAA------------------AAAAA- --AAAA------------------AAAA-- ---AAAAAAAAAABBBBAAAAAAAAAA--- -----BAAAB----------BAAAB----- 
-----BBBAB----------BABBB----- ---AAAAAAABBBABBABBBAAAAAAA--- --AAAA------------------AAAA-- -AAAAA------------------AAAAA- -AAAAA------------------AAAAA- BAAAAA------------------AAAAAB BAAAAA------------------AAAAAB BAAAAA------------------AAAAAB BAAAAA------------------AAAAAB BAAAAA------------------AAAAAB -AAAAA------------------AAAAA- -AAAAA------------------AAAAA- --AAAA------------------AAAA-- ---AAAAAAABBBABBABBBAAAAAAA--- -----BBBAB----------BABBB----- 
-----ABBBA----------ABBBA----- ---AAAAAAABBABAABABBAAAAAAA--- --AAAA------------------AAAA-- -AAAAA------------------AAAAA- -AAAAA------------------AAAAA- AAAAAA------------------AAAAAA BAAAAA------------------AAAAAB BAAAAA------------------AAAAAB BAAAAA------------------AAAAAB AAAAAA------------------AAAAAA -AAAAA------------------AAAAA- -AAAAA------------------AAAAA- --AAAA------------------AAAA-- ---AAAAAAABBABAABABBAAAAAAA--- -----ABBBA----------ABBBA----- 
-----AAABA----------ABAAA----- ---AAABABAAAAAAAAAAAABABAAA--- --AAAA------------------AAAA-- -AAAAB------------------BAAAA- -AAAAB------------------BAAAA- BAAAAA------------------AAAAAB BAAAAB------------------BAAAAB AAAAAA------------------AAAAAA BAAAAB------------------BAAAAB BAAAAB------------------BAAAAB -AAAAB------------------BAAAA- -AAAAB------------------BAAAA- --AAAA------------------AAAA-- ---AABBAABBABABBABABBAABBAA--- -----ABBAA----------AABBA----- 
------------------------------ ---AA--------------------AA--- --AAA--------------------AAA-- -AAAA--------------------AAAA- -AAAA--------------------AAAA- BAAAA--------------------AAAAB BAAAA--------------------AAAAB BAAAA--------------------AAAAB BAAAB--------------------BAAAB BAAAA--------------------AAAAB -AAAA--------------------AAAA- -AAAA--------------------AAAA- --AAA--------------------AAA-- ---AA--------------------AA--- ------------------------------ 
------------------------------ ---B----------------------B--- --AA----------------------AA-- -AAA----------------------AAA- -AAB----------------------BAA- BAAA----------------------AAAB AAAB----------------------BAAA BAAB----------------------BAAB AAAB----------------------BAAA BAAA----------------------AAAB -AAB----------------------BAA- -AAA----------------------AAA- --AB----------------------BA-- ---B----------------------B--- ------------------------------ 
------------------------------ ------------------------------ --B------------------------B-- -AA------------------------AA- -AB------------------------BA- BAB------------------------BAB AAB------------------------BAA AAB------------------------BAA AAA------------------------AAA BAA------------------------AAB -AB------------------------BA- -AA------------------------AA- --A------------------------A-- ------------------------------ ------------------------------ 
------------------------------ ------------------------------ ------------------------------ -B--------------------------B- -B--------------------------B- BA--------------------------AB AB--------------------------BA AB--------------------------BA AB--------------------------BA BB--------------------------BB -B--------------------------B- -A--------------------------A- ------------------------------ ------------------------------ ------------------------------ 
------------------------------ ------------------------------ ------------------------------ ------------------------------ ------------------------------ A----------------------------A B----------------------------B A----------------------------A A----------------------------A B----------------------------B ------------------------------ ------------------------------ ------------------------------ ------------------------------ ------------------------------ 
