model
size = 30 15 12, scale = 0.05, origin = -y
material 
  colors = A:#400 B:#444 C:#903
voxels
-----ACBAA----------AABCA----- ---ABCAABCACACCCCACACBAACBA--- --AAAAACCCBACAAAACABCCCAAAAA-- -CAAAAAAABCBAAAAAABCBAAAAAAAC- -AAACAACCACCCCAACCCCACCAACAAA- ACCCBCCBACACBCBBCBCACABCCBCCCA ACCAAACCAABACAAAACABAACCAAACCA CCACCCABACCCAAAAAACCCABACCCACC AACACCAABCBCABCCBACBCBAACCACAA CBABAABAACACBCAACBCACAABAABABC -BCACABCCAAAABBBBAAAACCBACACB- -ACCCACBACCBBABBABBCCABCACCCA- --CAAABCBAABAAAAAABAABCBAAAC-- ---BAACAAACAAABBAAACAAACAAB--- -----CAABB----------BBAAC----- 
-----AAAAC----------CAAAA----- ---AAAAAAACAAAAAAAACAAAAAAA--- --AAAAAAAAAAAAAAAAAAAAAAAAAA-- -AAAAAAAAAAAAAAAAAAAAAAAAAAAA- -AAAAAAABBBBAAAAAABBBBAAAAAAA- BAAAAAABBBBBBAAAABBBBBBAAAAAAB AAAAAABBBBBBBBAABBBBBBBBAAAAAA BAAAAABBBBBBBBAABBBBBBBBAAAAAB AAAAAABBBBBBBBAABBBBBBBBAAAAAA BAAAAABBBBBBBBAABBBBBBBBAAAAAB -AAAAAABBBBBBAAAABBBBBBAAAAAA- -AAAAAAABBBBAAAAAABBBBAAAAAAA- --AAAAAAAAAAAAAAAAAAAAAAAAAA-- ---AAAAAAACAAAAAAAACAAAAAAA--- -----AAAAC----------CAAAA----- 
-----ACABA----------ABACA----- ---AAAAAAAAAAAAAAAAAAAAAAAA--- --AAAAAAAAAAAAAAAAAAAAAAAAAA-- -AAAAA------------------AAAAA- -AAAAA------------------AAAAA- AAAAAA------------------AAAAAA AAAAAA------------------AAAAAA AAAAAA------------------AAAAAA AAAAAA------------------AAAAAA AAAAAA------------------AAAAAA -AAAAA------------------AAAAA- -AAAAA------------------AAAAA- --AAAA------------------AAAA-- ---AAAAAAAAAAAAAAAAAAAAAAAA--- -----ACABA----------ABACA----- 
-----AACAC----------CACAA----- ---AAAAAAACABAAAABACAAAAAAA--- --AAAAAAAAAAAAAAAAAAAAAAAAAA-- -AAAAA------------------AAAAA- -AAAAA------------------AAAAA- AAAAAA------------------AAAAAA AAAAAA------------------AAAAAA BAAAAA------------------AAAAAB AAAAAA------------------AAAAAA AAAAAA------------------AAAAAA -AAAAA------------------AAAAA- -AAAAA------------------AAAAA- --AAAA------------------AAAA-- ---AAAAAAACABAAAABACAAAAAAA--- -----AACAC----------CACAA----- 
-----CABAA----------AABAC----- ---AAAAAAAAAABAABAAAAAAAAAA--- --AAAA------------------AAAA-- -AAAAA------------------AAAAA- -AAAAA------------------AAAAA- AAAAAA------------------AAAAAA CAAAAA------------------AAAAAC BAAAAA------------------AAAAAB CAAAAA------------------AAAAAC AAAAAA------------------AAAAAA -AAAAA------------------AAAAA- -AAAAA------------------AAAAA- --AAAA------------------AAAA-- ---AAAAAAAAAABAABAAAAAAAAAA--- -----CABAA----------AABAC----- 
-----AABAA----------AABAA----- ---AAAAAAAAAAAAAAAAAAAAAAAA--- --AAAA------------------AAAA-- -AAAAA------------------AAAAA- -AAAAA------------------AAAAA- BAAAAA------------------AAAAAB AAAAAA------------------AAAAAA CAAAAA------------------AAAAAC AAAAAA------------------AAAAAA BAAAAA------------------AAAAAB -AAAAA------------------AAAAA- -AAAAA------------------AAAAA- --AAAA------------------AAAA-- ---AAAAAAAAAAAAAAAAAAAAAAAA--- -----AABAA----------AABAA----- 
-----AAAAA----------AAAAA----- ---AAAAAAAAAAAAAAAAAAAAAAAA--- --AAAA------------------AAAA-- -AAAAA------------------AAAAA- -AAAAA------------------AAAAA- AAAAAA------------------AAAAAA AAAAAA------------------AAAAAA CAAAAA------------------AAAAAC AAAAAA------------------AAAAAA AAAAAA------------------AAAAAA -AAAAA------------------AAAAA- -AAAAA------------------AAAAA- --AAAA------------------AAAA-- ---AAAAAAAAAAAAAAAAAAAAAAAA--- -----AAAAA----------AAAAA----- 
------------------------------ ---AA--------------------AA--- --AAA--------------------AAA-- -AAAA--------------------AAAA- -AAAA--------------------AAAA- CAAAA--------------------AAAAC AAAAA--------------------AAAAA CAAAA--------------------AAAAC AAAAA--------------------AAAAA CAAAA--------------------AAAAC -AAAA--------------------AAAA- -AAAA--------------------AAAA- --AAA--------------------AAA-- ---AA--------------------AA--- ------------------------------ 
------------------------------ ---A----------------------A--- --AA----------------------AA-- -AAA----------------------AAA- -AAA----------------------AAA- AAAA----------------------AAAA AAAA----------------------AAAA AAAA----------------------AAAA AAAA----------------------AAAA AAAA----------------------AAAA -AAA----------------------AAA- -AAA----------------------AAA- --AA----------------------AA-- ---A----------------------A--- ------------------------------ 
------------------------------ ------------------------------ --A------------------------A-- -AA------------------------AA- -AA------------------------AA- AAA------------------------AAA AAA------------------------AAA AAA------------------------AAA AAA------------------------AAA AAA------------------------AAA -AA------------------------AA- -AA------------------------AA- --A------------------------A-- ------------------------------ ------------------------------ 
------------------------------ ------------------------------ ------------------------------ -A--------------------------A- -A--------------------------A- AA--------------------------AA CA--------------------------AC AA--------------------------AA CA--------------------------AC AA--------------------------AA -A--------------------------A- -A--------------------------A- ------------------------------ ------------------------------ ------------------------------ 
------------------------------ ------------------------------ ------------------------------ ------------------------------ ------------------------------ A----------------------------A A----------------------------A A----------------------------A A----------------------------A A----------------------------A ------------------------------ ------------------------------ ------------------------------ ------------------------------ ------------------------------ 
