model
size = 30 15 12, scale = 0.05, origin = -y
material 
  colors = A:#500 B:#F36 C:#6F3
voxels
-----BBBCA----------ACBBB----- ---CCAAAAAAAAABBAAAAAAAAACC--- --CACABABABABABBABABABABACAC-- -BABBAAAACACAAAAAACACAAAABBAB- -CCAACCABCBAAAAAAAABCBACCAACC- CACCAABBAAAABAAAABAAAABBAACCAC CACACAAACBBAAAAAAAABBCAAACACAC AACBBAABABAAACAACAAABABAABBCAA AABAABBBAAAAABCCBAAAAABBBAABAA ABACBBAAAAAAACBBCAAAAAAABBCABA -CBACABBBABACCCCCCABABBBACABC- -AAACACBABBAAACCAAABBABCACAAA- --AACAABACAABACCABAACABAACAA-- ---BBAACCABAABAABAABACCAABB--- -----BCABC----------CBACB----- 
-----AAAAA----------AAAAA----- ---AAAAAAAAAAAAAAAAAAAAAAAA--- --AAAAAAAAAAAAAAAAAAAAAAAAAA-- -AAAAAAAAAAAAAAAAAAAAAAAAAAAA- -AAAAAAABBBBAAAAAABBBBAAAAAAA- CAAAAAABBBBBBAAAABBBBBBAAAAAAC AAAAAABBBBBBBBAABBBBBBBBAAAAAA CAAAAABBBBBBBBAABBBBBBBBAAAAAC AAAAAABBBBBBBBAABBBBBBBBAAAAAA CAAAAABBBBBBBBAABBBBBBBBAAAAAC -AAAAAABBBBBBAAAABBBBBBAAAAAA- -AAAAAAABBBBAAAAAABBBBAAAAAAA- --AAAAAAAAAAAAAAAAAAAAAAAAAA-- ---AAAAAAAAAAAAAAAAAAAAAAAA--- -----AAAAA----------AAAAA----- 
-----AAAAA----------AAAAA----- ---AAAAAAAAAAAAAAAAAAAAAAAA--- --AAAAAAAAAAAAAAAAAAAAAAAAAA-- -AAAAA------------------AAAAA- -AAAAA------------------AAAAA- CAAAAA------------------AAAAAC CAAAAA------------------AAAAAC AAAAAA------------------AAAAAA CAAAAA------------------AAAAAC CAAAAA------------------AAAAAC -AAAAA------------------AAAAA- -AAAAA------------------AAAAA- --AAAA------------------AAAA-- ---AAAAAAAAAAAAAAAAAAAAAAAA--- -----AAAAA----------AAAAA----- 
-----AAAAA----------AAAAA----- ---AAAAAAAAAAAAAAAAAAAAAAAA--- --AAAAAAAAAAAAAAAAAAAAAAAAAA-- -AAAAA------------------AAAAA- -AAAAA------------------AAAAA- BAAAAA------------------AAAAAB CAAAAA------------------AAAAAC AAAAAA------------------AAAAAA CAAAAA------------------AAAAAC BAAAAA------------------AAAAAB -AAAAA------------------AAAAA- -AAAAA------------------AAAAA- --AAAA------------------AAAA-- ---AAAAAAAAAAAAAAAAAAAAAAAA--- -----AAAAA----------AAAAA----- 
-----AAAAA----------AAAAA----- ---AAAAAAAAAAAAAAAAAAAAAAAA--- --AAAA------------------AAAA-- -AAAAA------------------AAAAA- -AAAAA------------------AAAAA- AAAAAA------------------AAAAAA CAAAAA------------------AAAAAC BAAAAA------------------AAAAAB CAAAAA------------------AAAAAC AAAAAA------------------AAAAAA -AAAAA------------------AAAAA- -AAAAA------------------AAAAA- --AAAA------------------AAAA-- ---AAAAAAAAAAAAAAAAAAAAAAAA--- -----AAAAA----------AAAAA----- 
-----AAAAA----------AAAAA----- ---AAAAAAAAAAAAAAAAAAAAAAAA--- --AAAA------------------AAAA-- -AAAAA------------------AAAAA- -AAAAA------------------AAAAA- CAAAAA------------------AAAAAC CAAAAA------------------AAAAAC CAAAAA------------------AAAAAC CAAAAA------------------AAAAAC CAAAAA------------------AAAAAC -AAAAA------------------AAAAA- -AAAAA------------------AAAAA- --AAAA------------------AAAA-- ---AAAAAAAAAAAAAAAAAAAAAAAA--- -----AAAAA----------AAAAA----- 
-----AAAAA----------AAAAA----- ---AAAAAAAAAAAAAAAAAAAAAAAA--- --AAAA------------------AAAA-- -AAAAA------------------AAAAA- -AAAAA------------------AAAAA- BAAAAA------------------AAAAAB AAAAAA------------------AAAAAA BAAAAA------------------AAAAAB AAAAAA------------------AAAAAA BAAAAA------------------AAAAAB -AAAAA------------------AAAAA- -AAAAA------------------AAAAA- --AAAA------------------AAAA-- ---AAAAAAAAAAAAAAAAAAAAAAAA--- -----AAAAA----------AAAAA----- 
------------------------------ ---AA--------------------AA--- --AAA--------------------AAA-- -AAAA--------------------AAAA- -AAAA--------------------AAAA- AAAAA--------------------AAAAA CAAAA--------------------AAAAC AAAAA--------------------AAAAA CAAAA--------------------AAAAC AAAAA--------------------AAAAA -AAAA--------------------AAAA- -AAAA--------------------AAAA- --AAA--------------------AAA-- ---AA--------------------AA--- ------------------------------ 
------------------------------ ---A----------------------A--- --AA----------------------AA-- -AAA----------------------AAA- -AAA----------------------AAA- AAAA----------------------AAAA CAAA----------------------AAAC BAAA----------------------AAAB CAAA----------------------AAAC AAAA----------------------AAAA -AAA----------------------AAA- -AAA----------------------AAA- --AA----------------------AA-- ---A----------------------A--- ------------------------------ 
------------------------------ ------------------------------ --A------------------------A-- -AA------------------------AA- -AA------------------------AA- AAA------------------------AAA AAA------------------------AAA CAA------------------------AAC AAA------------------------AAA AAA------------------------AAA -AA------------------------AA- -AA------------------------AA- --A------------------------A-- ------------------------------ ------------------------------ 
------------------------------ ------------------------------ ------------------------------ -A--------------------------A- -A--------------------------A- AA--------------------------AA AA--------------------------AA AA--------------------------AA AA--------------------------AA AA--------------------------AA -A--------------------------A- -A--------------------------A- ------------------------------ ------------------------------ ------------------------------ 
------------------------------ ------------------------------ ------------------------------ ------------------------------ ------------------------------ A----------------------------A A----------------------------A A----------------------------A A----------------------------A A----------------------------A ------------------------------ ------------------------------ ------------------------------ ------------------------------ ------------------------------ 
