model
size = 30 15 12, scale = 0.05, origin = -y
material 
  colors = A:#93C B:#060 C:#939
voxels
-----ABBBB----------BBBBA----- ---ABAAAABBBAAAAAABBBAAAABA--- --ABAABAAABABAAAABABAAABAABA-- -ABABBBABABAABAABAABABABBBABA- -BBBAAAAABBAABBBBAABBAAAAABBB- BBABABAABABBABBBBABBABAABABABB AAABBAAAAABBAABBAABBAAAAABBAAA BABABBABAABBAAAAAABBAABABBABAB BABAABBBBBAAAABBAAAABBBBBAABAB ABAABBABBAAAABAABAAAABBABBAABA -BAABABABABABAAAABABABABABAAB- -BABBBABBBBABBBBBBABBBBABBBAB- --BAABAABBABBABBABBABBAABAAB-- ---BAABBAAABBAAAABBAAABBAAB--- -----ABABB----------BBABA----- 
-----AAAAA----------AAAAA----- ---AAAAAAAAAAAAAAAAAAAAAAAA--- --AAAAAAAAAAAAAAAAAAAAAAAAAA-- -AAAAAAAAAAAAAAAAAAAAAAAAAAAA- -AAAAAAACCCCAAAAAACCCCAAAAAAA- BAAAAAACCCCCCAAAACCCCCCAAAAAAB AAAAAACCCCCCCCAACCCCCCCCAAAAAA AAAAAACCCCCCCCAACCCCCCCCAAAAAA AAAAAACCCCCCCCAACCCCCCCCAAAAAA BAAAAACCCCCCCCAACCCCCCCCAAAAAB -AAAAAACCCCCCAAAACCCCCCAAAAAA- -AAAAAAACCCCAAAAAACCCCAAAAAAA- --AAAAAAAAAAAAAAAAAAAAAAAAAA-- ---AAAAAAAAAAAAAAAAAAAAAAAA--- -----AAAAA----------AAAAA----- 
-----AAAAA----------AAAAA----- ---AAAAAAAAAAAAAAAAAAAAAAAA--- --AAAAAAAAAAAAAAAAAAAAAAAAAA-- -AAAAA------------------AAAAA- -AAAAA------------------AAAAA- BAAAAA------------------AAAAAB AAAAAA------------------AAAAAA BAAAAA------------------AAAAAB AAAAAA------------------AAAAAA BAAAAA------------------AAAAAB -AAAAA------------------AAAAA- -AAAAA------------------AAAAA- --AAAA------------------AAAA-- ---AAAAAAAAAAAAAAAAAAAAAAAA--- -----AAAAA----------AAAAA----- 
-----AAAAA----------AAAAA----- ---AAAAAAAAAAAAAAAAAAAAAAAA--- --AAAABBBBAABBBBBBAABBBBAAAA-- -AAAAA------------------AAAAA- -AAAAA------------------AAAAA- AAAAAA------------------AAAAAA AAAAAA------------------AAAAAA AAAAAA------------------AAAAAA AAAAAA------------------AAAAAA AAAAAA------------------AAAAAA -AAAAA------------------AAAAA- -AAAAA------------------AAAAA- --AAAA------------------AAAA-- ---AAAAAAAAAAAAAAAAAAAAAAAA--- -----AAAAA----------AAAAA----- 
-----AAAAA----------AAAAA----- ---AAAAAAAAAAAAAAAAAAAAAAAA--- --AAAA------------------AAAA-- -AAAAA------------------AAAAA- -AAAAA------------------AAAAA- AAAAAA------------------AAAAAA BAAAAA------------------AAAAAB AAAAAA------------------AAAAAA BAAAAA------------------AAAAAB AAAAAA------------------AAAAAA -AAAAA------------------AAAAA- -AAAAA------------------AAAAA- --AAAA------------------AAAA-- ---AAAAAAAAAAAAAAAAAAAAAAAA--- -----AAAAA----------AAAAA----- 
-----AAAAA----------AAAAA----- ---AAAAAAAAAAAAAAAAAAAAAAAA--- --AAAA------------------AAAA-- -AAAAA------------------AAAAA- -AAAAA------------------AAAAA- AAAAAA------------------AAAAAA BAAAAA------------------AAAAAB BAAAAA------------------AAAAAB BAAAAA------------------AAAAAB AAAAAA------------------AAAAAA -AAAAA------------------AAAAA- -AAAAA------------------AAAAA- --AAAA------------------AAAA-- ---AAAAAAAAAAAAAAAAAAAAAAAA--- -----AAAAA----------AAAAA----- 
-----BBBAA----------AABBB----- ---AAAAAAABBBBAABBBBAAAAAAA--- --AAAB------------------BAAA-- -AAAAA------------------AAAAA- -AAAAB------------------BAAAA- AAAAAB------------------BAAAAA AAAAAB------------------BAAAAA AAAAAA------------------AAAAAA AAAAAB------------------BAAAAA AAAAAA------------------AAAAAA -AAAAB------------------BAAAA- -AAAAB------------------BAAAA- --AAAB------------------BAAA-- ---AAAAABABABABBABABABAAAAA--- -----BABAB----------BABAB----- 
------------------------------ ---AB--------------------BA--- --AAA--------------------AAA-- -AAAB--------------------BAAA- -AAAB--------------------BAAA- AAAAA--------------------AAAAA BAAAB--------------------BAAAB AAAAB--------------------BAAAA BAAAB--------------------BAAAB AAAAA--------------------AAAAA -AAAA--------------------AAAA- -AAAA--------------------AAAA- --AAB--------------------BAA-- ---AA--------------------AA--- ------------------------------ 
------------------------------ ---A----------------------A--- --AA----------------------AA-- -AAB----------------------BAA- -AAB----------------------BAA- AAAA----------------------AAAA AAAB----------------------BAAA AAAA----------------------AAAA AAAA----------------------AAAA AAAA----------------------AAAA -AAA----------------------AAA- -AAB----------------------BAA- --AB----------------------BA-- ---A----------------------A--- ------------------------------ 
------------------------------ ------------------------------ --B------------------------B-- -AB------------------------BA- -AA------------------------AA- AAA------------------------AAA AAA------------------------AAA BAB------------------------BAB AAA------------------------AAA AAB------------------------BAA -AA------------------------AA- -AB------------------------BA- --B------------------------B-- ------------------------------ ------------------------------ 
------------------------------ ------------------------------ ------------------------------ -A--------------------------A- -B--------------------------B- AB--------------------------BA AA--------------------------AA AA--------------------------AA AA--------------------------AA AA--------------------------AA -B--------------------------B- -A--------------------------A- ------------------------------ ------------------------------ ------------------------------ 
------------------------------ ------------------------------ ------------------------------ ------------------------------ ------------------------------ A----------------------------A B----------------------------B B----------------------------B B----------------------------B B----------------------------B ------------------------------ ------------------------------ ------------------------------ ------------------------------ ------------------------------ 
