model
size = 30 15 12, scale = 0.05, origin = -y
material 
  colors = A:#690 B:#D00 C:#001
voxels
-----AAABB----------BBAAA----- ---AABBAABBABBBBBBABBAABBAA--- --BAABBAAAAAAABBAAAAAAABBAAB-- -BAAABABBABBBAAAABBBABBABAAAB- -BAAABAAAABAAABBAAABAAAABAAAB- BAABABBBABBBAAAAAABBBABBBABAAB AABAABABBBABAABBAABABBBABAABAA AABBABAABABAABBBBAABABAABABBAA BAABAAAABABBBBAABBBBABAAAABAAB BBABAABBBBBAAAAAAAABBBBBAABABB -BBABBBBAABABABBABABAABBBBABB- -BBABABABAABABBBBABAABABABABB- --ABBBBBBBBBABBBBABBBBBBBBBA-- ---BAAABBABBBBBBBBBBABBAAAB--- -----AAAAB----------BAAAA----- 
-----AAAAA----------AAAAA----- ---AAAAAAAAAAAAAAAAAAAAAAAA--- --AAAAAAAAAAAAAAAAAAAAAAAAAA-- -AAAAAAAAAAAAAAAAAAAAAAAAAAAA- -AAAAAAACCCCAAAAAACCCCAAAAAAA- AAAAAAACCCCCCAAAACCCCCCAAAAAAA AAAAAACCCCCCCCAACCCCCCCCAAAAAA AAAAAACCCCCCCCAACCCCCCCCAAAAAA AAAAAACCCCCCCCAACCCCCCCCAAAAAA AAAAAACCCCCCCCAACCCCCCCCAAAAAA -AAAAAACCCCCCAAAACCCCCCAAAAAA- -AAAAAAACCCCAAAAAACCCCAAAAAAA- --AAAAAAAAAAAAAAAAAAAAAAAAAA-- ---AAAAAAAAAAAAAAAAAAAAAAAA--- -----AAAAA----------AAAAA----- 
-----AAAAA----------AAAAA----- ---AAAAAAAAAAAAAAAAAAAAAAAA--- --AAAAAAAAAAAAAAAAAAAAAAAAAA-- -AAAAA------------------AAAAA- -AAAAA------------------AAAAA- AAAAAA------------------AAAAAA AAAAAA------------------AAAAAA BAAAAA------------------AAAAAB AAAAAA------------------AAAAAA AAAAAA------------------AAAAAA -AAAAA------------------AAAAA- -AAAAA------------------AAAAA- --AAAA------------------AAAA-- ---AAAAAAAAAAAAAAAAAAAAAAAA--- -----AAAAA----------AAAAA----- 
-----AAAAA----------AAAAA----- ---AAAAAAAAAAAAAAAAAAAAAAAA--- --AAAAABABABBBAABBBABABAAAAA-- -AAAAA------------------AAAAA- -AAAAA------------------AAAAA- AAAAAA------------------AAAAAA AAAAAA------------------AAAAAA AAAAAA------------------AAAAAA AAAAAA------------------AAAAAA AAAAAA------------------AAAAAA -AAAAA------------------AAAAA- -AAAAA------------------AAAAA- --AAAA------------------AAAA-- ---AAAAAAAAAAAAAAAAAAAAAAAA--- -----AAAAA----------AAAAA----- 
-----AAAAA----------AAAAA----- ---AAAAAAAAAAAAAAAAAAAAAAAA--- --AAAA------------------AAAA-- -AAAAA------------------AAAAA- -AAAAA------------------AAAAA- AAAAAA------------------AAAAAA BAAAAA------------------AAAAAB AAAAAA------------------AAAAAA BAAAAA------------------AAAAAB AAAAAA------------------AAAAAA -AAAAA------------------AAAAA- -AAAAA------------------AAAAA- --AAAA------------------AAAA-- ---AAAAAAAAAAAAAAAAAAAAAAAA--- -----AAAAA----------AAAAA----- 
-----AAAAA----------AAAAA----- ---AAAAAAAAAAAAAAAAAAAAAAAA--- --AAAA------------------AAAA-- -AAAAA------------------AAAAA- -AAAAA------------------AAAAA- AAAAAA------------------AAAAAA AAAAAA------------------AAAAAA AAAAAA------------------AAAAAA AAAAAA------------------AAAAAA AAAAAA------------------AAAAAA -AAAAA------------------AAAAA- -AAAAA------------------AAAAA- --AAAA------------------AAAA-- ---AAAAAAAAAAAAAAAAAAAAAAAA--- -----AAAAA----------AAAAA----- 
-----ABAAB----------BAABA----- ---AAAAABAAAABBBBAAAABAAAAA--- --AAAB------------------BAAA-- -AAAAA------------------AAAAA- -AAAAB------------------BAAAA- AAAAAB------------------BAAAAA AAAAAA------------------AAAAAA AAAAAA------------------AAAAAA AAAAAB------------------BAAAAA AAAAAA------------------AAAAAA -AAAAA------------------AAAAA- -AAAAB------------------BAAAA- --AAAA------------------AAAA-- ---AABBBBBABBAAAABBABBBBBAA--- -----BBBAA----------AABBB----- 
------------------------------ ---AB--------------------BA--- --AAA--------------------AAA-- -AAAB--------------------BAAA- -AAAB--------------------BAAA- BAAAA--------------------AAAAB BAAAB--------------------BAAAB AAAAB--------------------BAAAA BAAAB--------------------BAAAB BAAAB--------------------BAAAB -AAAB--------------------BAAA- -AAAA--------------------AAAA- --AAA--------------------AAA-- ---AA--------------------AA--- ------------------------------ 
------------------------------ ---A----------------------A--- --AA----------------------AA-- -AAB----------------------BAA- -AAA----------------------AAA- AAAB----------------------BAAA AAAB----------------------BAAA AAAB----------------------BAAA AAAA----------------------AAAA AAAB----------------------BAAA -AAB----------------------BAA- -AAA----------------------AAA- --AA----------------------AA-- ---A----------------------A--- ------------------------------ 
------------------------------ ------------------------------ --B------------------------B-- -AB------------------------BA- -AB------------------------BA- AAA------------------------AAA BAA------------------------AAB BAA------------------------AAB BAA------------------------AAB AAA------------------------AAA -AA------------------------AA- -AA------------------------AA- --A------------------------A-- ------------------------------ ------------------------------ 
------------------------------ ------------------------------ ------------------------------ -B--------------------------B- -B--------------------------B- AB--------------------------BA AA--------------------------AA AA--------------------------AA AA--------------------------AA AB--------------------------BA -B--------------------------B- -B--------------------------B- ------------------------------ ------------------------------ ------------------------------ 
------------------------------ ------------------------------ ------------------------------ ------------------------------ ------------------------------ A----------------------------A A----------------------------A A----------------------------A A----------------------------A B----------------------------B ------------------------------ ------------------------------ ------------------------------ ------------------------------ ------------------------------ 
