model
size = 30 15 12, scale = 0.05, origin = -y
material 
  colors = A:#0A0 B:#FFC C:#63C
voxels
-----AABCA----------ACBAA----- ---CBAACCAACCCCCCCCAACCAABC--- --AAAABBBABBACBBCABBABBBAAAA-- -BAABAAACAACAAAAAACAACAAABAAB- -CCCBAABBCAABAAAABAACBBAABCCC- ACBABCBABBABCAAAACBABBABCBABCA BABABAAAABBABBAABBABBAAAABABAB BACAAAABAABCBACCABCBAABAAAACAB ABACCACAABCABBAABBACBAACACCABA CCACCACCCAABCBCCBCBAACCCACCACC -ABAAAAACAACCCBBCCCAACAAAAABA- -AAACCBCCACACBBBBCACACCBCCAAA- --BCAAABAACAAACCAAACAABAAACB-- ---ACAAAABCCAAAAAACCBAAAACA--- -----BAACA----------ACAAB----- 
-----AAAAA----------AAAAA----- ---AAAAAAAAAAAAAAAAAAAAAAAA--- --AAAAAAAAAAAAAAAAAAAAAAAAAA-- -AAAAAAAAAAAAAAAAAAAAAAAAAAAA- -AAAAAAABBBBAAAAAABBBBAAAAAAA- BAAAAAABBBBBBAAAABBBBBBAAAAAAB AAAAAABBBBBBBBAABBBBBBBBAAAAAA BAAAAABBBBBBBBAABBBBBBBBAAAAAB AAAAAABBBBBBBBAABBBBBBBBAAAAAA BAAAAABBBBBBBBAABBBBBBBBAAAAAB -AAAAAABBBBBBAAAABBBBBBAAAAAA- -AAAAAAABBBBAAAAAABBBBAAAAAAA- --AAAAAAAAAAAAAAAAAAAAAAAAAA-- ---AAAAAAAAAAAAAAAAAAAAAAAA--- -----AAAAA----------AAAAA----- 
-----AAAAA----------AAAAA----- ---AAAAAAAAAAAAAAAAAAAAAAAA--- --AAAAAAAAAAAAAAAAAAAAAAAAAA-- -AAAAA------------------AAAAA- -AAAAA------------------AAAAA- CAAAAA------------------AAAAAC AAAAAA------------------AAAAAA AAAAAA------------------AAAAAA AAAAAA------------------AAAAAA CAAAAA------------------AAAAAC -AAAAA------------------AAAAA- -AAAAA------------------AAAAA- --AAAA------------------AAAA-- ---AAAAAAAAAAAAAAAAAAAAAAAA--- -----AAAAA----------AAAAA----- 
-----AAAAA----------AAAAA----- ---AAAAAAAAAAAAAAAAAAAAAAAA--- --AAAABBABBAAACCAAABBABBAAAA-- -AAAAA------------------AAAAA- -AAAAA------------------AAAAA- AAAAAA------------------AAAAAA AAAAAA------------------AAAAAA CAAAAA------------------AAAAAC AAAAAA------------------AAAAAA AAAAAA------------------AAAAAA -AAAAA------------------AAAAA- -AAAAA------------------AAAAA- --AAAA------------------AAAA-- ---AAAAAAAAAAAAAAAAAAAAAAAA--- -----AAAAA----------AAAAA----- 
-----AAAAA----------AAAAA----- ---AAAAAAAAAAAAAAAAAAAAAAAA--- --AAAA------------------AAAA-- -AAAAA------------------AAAAA- -AAAAA------------------AAAAA- BAAAAA------------------AAAAAB BAAAAA------------------AAAAAB AAAAAA------------------AAAAAA BAAAAA------------------AAAAAB BAAAAA------------------AAAAAB -AAAAA------------------AAAAA- -AAAAA------------------AAAAA- --AAAA------------------AAAA-- ---AAAAAAAAAAAAAAAAAAAAAAAA--- -----AAAAA----------AAAAA----- 
-----AAAAA----------AAAAA----- ---AAAAAAAAAAAAAAAAAAAAAAAA--- --AAAA------------------AAAA-- -AAAAA------------------AAAAA- -AAAAA------------------AAAAA- AAAAAA------------------AAAAAA AAAAAA------------------AAAAAA AAAAAA------------------AAAAAA AAAAAA------------------AAAAAA AAAAAA------------------AAAAAA -AAAAA------------------AAAAA- -AAAAA------------------AAAAA- --AAAA------------------AAAA-- ---AAAAAAAAAAAAAAAAAAAAAAAA--- -----AAAAA----------AAAAA----- 
-----CAABA----------ABAAC----- ---AACAAABBCABBBBACBBAAACAA--- --AAAA------------------AAAA-- -AAAAA------------------AAAAA- -AAAAC------------------CAAAA- AAAAAA------------------AAAAAA AAAAAC------------------CAAAAA AAAAAB------------------BAAAAA AAAAAC------------------CAAAAA AAAAAA------------------AAAAAA -AAAAC------------------CAAAA- -AAAAB------------------BAAAA- --AAAA------------------AAAA-- ---AAACCACAAAAAAAAAACACCAAA--- -----CCCCB----------BCCCC----- 
------------------------------ ---AC--------------------CA--- --AAA--------------------AAA-- -AAAB--------------------BAAA- -AAAC--------------------CAAA- AAAAB--------------------BAAAA AAAAA--------------------AAAAA CAAAA--------------------AAAAC AAAAB--------------------BAAAA AAAAB--------------------BAAAA -AAAC--------------------CAAA- -AAAB--------------------BAAA- --AAC--------------------CAA-- ---AB--------------------BA--- ------------------------------ 
------------------------------ ---A----------------------A--- --AC----------------------CA-- -AAC----------------------CAA- -AAA----------------------AAA- AAAB----------------------BAAA CAAB----------------------BAAC AAAC----------------------CAAA CAAB----------------------BAAC AAAB----------------------BAAA -AAA----------------------AAA- -AAB----------------------BAA- --AC----------------------CA-- ---C----------------------C--- ------------------------------ 
------------------------------ ------------------------------ --B------------------------B-- -AB------------------------BA- -AB------------------------BA- BAA------------------------AAB AAB------------------------BAA CAA------------------------AAC AAC------------------------CAA BAB------------------------BAB -AC------------------------CA- -AB------------------------BA- --C------------------------C-- ------------------------------ ------------------------------ 
------------------------------ ------------------------------ ------------------------------ -A--------------------------A- -B--------------------------B- AB--------------------------BA BA--------------------------AB BC--------------------------CB BA--------------------------AB AB--------------------------BA -A--------------------------A- -C--------------------------C- ------------------------------ ------------------------------ ------------------------------ 
------------------------------ ------------------------------ ------------------------------ ------------------------------ ------------------------------ C----------------------------C A----------------------------A C----------------------------C B----------------------------B C----------------------------C ------------------------------ ------------------------------ ------------------------------ ------------------------------ ------------------------------ 
