model
size = 30 15 12, scale = 0.05, origin = -y
material 
  colors = A:#C9F B:#3C6 C:#300
voxels
-----ABAAB----------BAABA----- ---ABAABBBAAAABBAAAABBBAABA--- --BBAAAABAABABBBBABAABAAAABB-- -ABABAAABABBAAAAAABBABAAABABA- -BBAAAAABBBABBBBBBABBBAAAAABB- BBAABABBBBBABBBBBBABBBBBABAABB AAABBBABABBABAAAABABBABABBBAAA AAABABABABBBAAAAAABBBABABABAAA BBABABBAAABAAABBAAABAAABBABABB AABBAABBABAABAAAABAABABBAABBAA -ABBBBABBBBBBBBBBBBBBBBABBBBA- -BBABABBBBABBAAAABBABBBBABABB- --AAABBBBBBBABBBBABBBBBBBAAA-- ---BBABABABBAABBAABBABABABB--- -----BBBAA----------AABBB----- 
-----AAAAB----------BAAAA----- ---AAAAAAAAAABBBBAAAAAAAAAA--- --AAAAAAAAAAAAAAAAAAAAAAAAAA-- -AAAAAAAAAAAAAAAAAAAAAAAAAAAA- -AAAAAAACCCCAAAAAACCCCAAAAAAA- AAAAAAACCCCCCAAAACCCCCCAAAAAAA AAAAAACCCCCCCCAACCCCCCCCAAAAAA AAAAAACCCCCCCCAACCCCCCCCAAAAAA AAAAAACCCCCCCCAACCCCCCCCAAAAAA AAAAAACCCCCCCCAACCCCCCCCAAAAAA -AAAAAACCCCCCAAAACCCCCCAAAAAA- -AAAAAAACCCCAAAAAACCCCAAAAAAA- --AAAAAAAAAAAAAAAAAAAAAAAAAA-- ---AAAAAAAAAABBBBAAAAAAAAAA--- -----AAAAB----------BAAAA----- 
-----ABBAB----------BABBA----- ---AAAAAAABBAABBAABBAAAAAAA--- --AAAAAAAAAAAAAAAAAAAAAAAAAA-- -AAAAA------------------AAAAA- -AAAAA------------------AAAAA- AAAAAA------------------AAAAAA AAAAAA------------------AAAAAA AAAAAA------------------AAAAAA AAAAAA------------------AAAAAA AAAAAA------------------AAAAAA -AAAAA------------------AAAAA- -AAAAA------------------AAAAA- --AAAA------------------AAAA-- ---AAAAAAABBAABBAABBAAAAAAA--- -----ABBAB----------BABBA----- 
-----AABBA----------ABBAA----- ---AAAAAAAAABBBBBBAAAAAAAAA--- --AAAAAAAAAAAAAAAAAAAAAAAAAA-- -AAAAA------------------AAAAA- -AAAAA------------------AAAAA- AAAAAA------------------AAAAAA AAAAAA------------------AAAAAA AAAAAA------------------AAAAAA AAAAAA------------------AAAAAA AAAAAA------------------AAAAAA -AAAAA------------------AAAAA- -AAAAA------------------AAAAA- --AAAA------------------AAAA-- ---AAAAAAAAABBBBBBAAAAAAAAA--- -----AABBA----------ABBAA----- 
-----BAAAB----------BAAAB----- ---AAAAAAAAABBBBBBAAAAAAAAA--- --AAAA------------------AAAA-- -AAAAA------------------AAAAA- -AAAAA------------------AAAAA- AAAAAA------------------AAAAAA AAAAAA------------------AAAAAA AAAAAA------------------AAAAAA AAAAAA------------------AAAAAA AAAAAA------------------AAAAAA -AAAAA------------------AAAAA- -AAAAA------------------AAAAA- --AAAA------------------AAAA-- ---AAAAAAAAABBBBBBAAAAAAAAA--- -----BAAAB----------BAAAB----- 
-----ABABB----------BBABA----- ---AAAAAAABBBBAABBBBAAAAAAA--- --AAAA------------------AAAA-- -AAAAA------------------AAAAA- -AAAAA------------------AAAAA- AAAAAA------------------AAAAAA AAAAAA------------------AAAAAA AAAAAA------------------AAAAAA AAAAAA------------------AAAAAA AAAAAA------------------AAAAAA -AAAAA------------------AAAAA- -AAAAA------------------AAAAA- --AAAA------------------AAAA-- ---AAAAAAABBBBAABBBBAAAAAAA--- -----ABABB----------BBABA----- 
-----AAAAA----------AAAAA----- ---AAAAAAAAAAAAAAAAAAAAAAAA--- --AAAA------------------AAAA-- -AAAAA------------------AAAAA- -AAAAA------------------AAAAA- AAAAAA------------------AAAAAA AAAAAA------------------AAAAAA AAAAAA------------------AAAAAA AAAAAA------------------AAAAAA AAAAAA------------------AAAAAA -AAAAA------------------AAAAA- -AAAAA------------------AAAAA- --AAAA------------------AAAA-- ---AAAAAAAAAAAAAAAAAAAAAAAA--- -----AAAAA----------AAAAA----- 
------------------------------ ---AA--------------------AA--- --AAA--------------------AAA-- -AAAA--------------------AAAA- -AAAA--------------------AAAA- AAAAA--------------------AAAAA AAAAA--------------------AAAAA AAAAA--------------------AAAAA AAAAA--------------------AAAAA AAAAA--------------------AAAAA -AAAA--------------------AAAA- -AAAA--------------------AAAA- --AAA--------------------AAA-- ---AA--------------------AA--- ------------------------------ 
------------------------------ ---A----------------------A--- --AA----------------------AA-- -AAA----------------------AAA- -AAA----------------------AAA- AAAA----------------------AAAA AAAA----------------------AAAA AAAA----------------------AAAA AAAA----------------------AAAA AAAA----------------------AAAA -AAA----------------------AAA- -AAA----------------------AAA- --AA----------------------AA-- ---A----------------------A--- ------------------------------ 
------------------------------ ------------------------------ --A------------------------A-- -AA------------------------AA- -AA------------------------AA- AAA------------------------AAA AAA------------------------AAA AAA------------------------AAA AAA------------------------AAA AAA------------------------AAA -AA------------------------AA- -AA------------------------AA- --A------------------------A-- ------------------------------ ------------------------------ 
------------------------------ ------------------------------ ------------------------------ -A--------------------------A- -A--------------------------A- AA--------------------------AA AA--------------------------AA AA--------------------------AA AA--------------------------AA AA--------------------------AA -A--------------------------A- -A--------------------------A- ------------------------------ ------------------------------ ------------------------------ 
------------------------------ ------------------------------ ------------------------------ ------------------------------ ------------------------------ A----------------------------A A----------------------------A A----------------------------A A----------------------------A A----------------------------A ------------------------------ ------------------------------ ------------------------------ ------------------------------ ------------------------------ 
