model
size = 30 15 12, scale = 0.05, origin = -y
material 
  colors = A:#C0C B:#001 C:#390
voxels
-----ABBBA----------ABBBA----- ---ABBABBBBAABBBBAABBBBABBA--- --BBAABBAAABABAABABAAABBAABB-- -ABBABABBBBBAABBAABBBBBABABBA- -BAABABABBBAAABBAAABBBABABAAB- ABBABABAABBAAABBAAABBAABABABBA AAABBABABBABBABBABBABBABABBAAA BBBBBBBBBBABABAABABABBBBBBBBBB AABABBBAAABABBBBBBABAAABBBABAA AAAAAABABAABAAAAAABAABABAAAAAA -AAAAAABABBAABBBBAABBABAAAAAA- -BABBAABBABAAAAAAAABABBAABBAB- --AAAABBAABBBBAABBBBAABBAAAA-- ---BABABAAAABAAAABAAAABABAB--- -----ABABA----------ABABA----- 
-----BAABB----------BBAAB----- ---AAAAAAABBAAAAAABBAAAAAAA--- --AAAAAAAAAAAAAAAAAAAAAAAAAA-- -AAAAAAAAAAAAAAAAAAAAAAAAAAAA- -AAAAAAACCCCAAAAAACCCCAAAAAAA- BAAAAAACCCCCCAAAACCCCCCAAAAAAB BAAAAACCCCCCCCAACCCCCCCCAAAAAB AAAAAACCCCCCCCAACCCCCCCCAAAAAA BAAAAACCCCCCCCAACCCCCCCCAAAAAB BAAAAACCCCCCCCAACCCCCCCCAAAAAB -AAAAAACCCCCCAAAACCCCCCAAAAAA- -AAAAAAACCCCAAAAAACCCCAAAAAAA- --AAAAAAAAAAAAAAAAAAAAAAAAAA-- ---AAAAAAABBAAAAAABBAAAAAAA--- -----BAABB----------BBAAB----- 
-----AAABA----------ABAAA----- ---AAAAAAABBAABBAABBAAAAAAA--- --AAAAAAAAAAAAAAAAAAAAAAAAAA-- -AAAAA------------------AAAAA- -AAAAA------------------AAAAA- BAAAAA------------------AAAAAB BAAAAA------------------AAAAAB BAAAAA------------------AAAAAB BAAAAA------------------AAAAAB BAAAAA------------------AAAAAB -AAAAA------------------AAAAA- -AAAAA------------------AAAAA- --AAAA------------------AAAA-- ---AAAAAAABBAABBAABBAAAAAAA--- -----AAABA----------ABAAA----- 
-----BAAAA----------AAAAB----- ---AAAAAAAABBABBABBAAAAAAAA--- --AAAABBBBAABABBABAABBBBAAAA-- -AAAAA------------------AAAAA- -AAAAA------------------AAAAA- AAAAAA------------------AAAAAA AAAAAA------------------AAAAAA AAAAAA------------------AAAAAA AAAAAA------------------AAAAAA AAAAAA------------------AAAAAA -AAAAA------------------AAAAA- -AAAAA------------------AAAAA- --AAAA------------------AAAA-- ---AAAAAAAABBABBABBAAAAAAAA--- -----BAAAA----------AAAAB----- 
-----BBBAA----------AABBB----- ---AAAAAAAAABBBBBBAAAAAAAAA--- --AAAA------------------AAAA-- -AAAAA------------------AAAAA- -AAAAA------------------AAAAA- BAAAAA------------------AAAAAB BAAAAA------------------AAAAAB BAAAAA------------------AAAAAB BAAAAA------------------AAAAAB BAAAAA------------------AAAAAB -AAAAA------------------AAAAA- -AAAAA------------------AAAAA- --AAAA------------------AAAA-- ---AAAAAAAAABBBBBBAAAAAAAAA--- -----BBBAA----------AABBB----- 
-----BBABA----------ABABB----- ---AAAAAAABBBAAAABBBAAAAAAA--- --AAAA------------------AAAA-- -AAAAA------------------AAAAA- -AAAAA------------------AAAAA- AAAAAA------------------AAAAAA AAAAAA------------------AAAAAA AAAAAA------------------AAAAAA AAAAAA------------------AAAAAA AAAAAA------------------AAAAAA -AAAAA------------------AAAAA- -AAAAA------------------AAAAA- --AAAA------------------AAAA-- ---AAAAAAABBBAAAABBBAAAAAAA--- -----BBABA----------ABABB----- 
-----ABAAA----------AAABA----- ---AAABABBBBAAAAAABBBBABAAA--- --AAAA------------------AAAA-- -AAAAA------------------AAAAA- -AAAAA------------------AAAAA- AAAAAA------------------AAAAAA BAAAAB------------------BAAAAB BAAAAA------------------AAAAAB BAAAAA------------------AAAAAB AAAAAA------------------AAAAAA -AAAAA------------------AAAAA- -AAAAB------------------BAAAA- --AAAB------------------BAAA-- ---AABABAABBABAABABBAABABAA--- -----BBBBB----------BBBBB----- 
------------------------------ ---AA--------------------AA--- --AAB--------------------BAA-- -AAAA--------------------AAAA- -AAAB--------------------BAAA- BAAAB--------------------BAAAB BAAAA--------------------AAAAB BAAAB--------------------BAAAB BAAAB--------------------BAAAB BAAAA--------------------AAAAB -AAAA--------------------AAAA- -AAAB--------------------BAAA- --AAB--------------------BAA-- ---AA--------------------AA--- ------------------------------ 
------------------------------ ---B----------------------B--- --AB----------------------BA-- -AAB----------------------BAA- -AAA----------------------AAA- AAAB----------------------BAAA BAAB----------------------BAAB BAAA----------------------AAAB BAAB----------------------BAAB AAAA----------------------AAAA -AAB----------------------BAA- -AAA----------------------AAA- --AB----------------------BA-- ---B----------------------B--- ------------------------------ 
------------------------------ ------------------------------ --A------------------------A-- -AA------------------------AA- -AA------------------------AA- AAB------------------------BAA AAA------------------------AAA AAB------------------------BAA AAA------------------------AAA AAB------------------------BAA -AB------------------------BA- -AB------------------------BA- --A------------------------A-- ------------------------------ ------------------------------ 
------------------------------ ------------------------------ ------------------------------ -A--------------------------A- -B--------------------------B- BA--------------------------AB BB--------------------------BB AB--------------------------BA BA--------------------------AB BB--------------------------BB -B--------------------------B- -A--------------------------A- ------------------------------ ------------------------------ ------------------------------ 
------------------------------ ------------------------------ ------------------------------ ------------------------------ ------------------------------ B----------------------------B A----------------------------A B----------------------------B B----------------------------B A----------------------------A ------------------------------ ------------------------------ ------------------------------ ------------------------------ ------------------------------ 
