model
size = 30 15 12, scale = 0.05, origin = -y
material 
  colors = A:#6F0 B:#960 C:#100
voxels
-----AABAC----------CABAA----- ---AAAACCBBABCCCCBABBCCAAAA--- --AAACABCBABCAAAACBABCBACAAA-- -BABCAACAABBAAAAAABBAACAACBAB- -AABAABBBCAAAAAAAAAACBBBAABAA- ACCACAACABABACBBCABABACAACACCA BBAAACABAAABBAAAABBAAABACAAABB BAAACABCBCAAACAACAAACBCBACAAAB AAACACBABCACBBAABBCACBABCACAAA AACAACCAACBABBAABBABCAACCAACAA -ACACCACAAAAAAAAAAAAAACACCACA- -ABBAACAAAABAAAAAABAAAACAABBA- --AABCAAAAAACABBACAAAAAACBAA-- ---AACABBBAAAAAAAAAABBBACAA--- -----AABCC----------CCBAA----- 
-----AAAAA----------AAAAA----- ---AAAAAAAAAAAAAAAAAAAAAAAA--- --AAAAAAAAAAAAAAAAAAAAAAAAAA-- -AAAAAAAAAAAAAAAAAAAAAAAAAAAA- -AAAAAAABBBBAAAAAABBBBAAAAAAA- AAAAAAABBBBBBAAAABBBBBBAAAAAAA AAAAAABBBBBBBBAABBBBBBBBAAAAAA AAAAAABBBBBBBBAABBBBBBBBAAAAAA AAAAAABBBBBBBBAABBBBBBBBAAAAAA AAAAAABBBBBBBBAABBBBBBBBAAAAAA -AAAAAABBBBBBAAAABBBBBBAAAAAA- -AAAAAAABBBBAAAAAABBBBAAAAAAA- --AAAAAAAAAAAAAAAAAAAAAAAAAA-- ---AAAAAAAAAAAAAAAAAAAAAAAA--- -----AAAAA----------AAAAA----- 
-----AAAAA----------AAAAA----- ---AAAAAAAAAAAAAAAAAAAAAAAA--- --AAAAAAAAAAAAAAAAAAAAAAAAAA-- -AAAAA------------------AAAAA- -AAAAA------------------AAAAA- AAAAAA------------------AAAAAA AAAAAA------------------AAAAAA AAAAAA------------------AAAAAA AAAAAA------------------AAAAAA AAAAAA------------------AAAAAA -AAAAA------------------AAAAA- -AAAAA------------------AAAAA- --AAAA------------------AAAA-- ---AAAAAAAAAAAAAAAAAAAAAAAA--- -----AAAAA----------AAAAA----- 
-----AAAAA----------AAAAA----- ---AAAAAAAAAAAAAAAAAAAAAAAA--- --AAAABBCCCBCCAACCBCCCBBAAAA-- -AAAAA------------------AAAAA- -AAAAA------------------AAAAA- CAAAAA------------------AAAAAC CAAAAA------------------AAAAAC CAAAAA------------------AAAAAC CAAAAA------------------AAAAAC CAAAAA------------------AAAAAC -AAAAA------------------AAAAA- -AAAAA------------------AAAAA- --AAAA------------------AAAA-- ---AAAAAAAAAAAAAAAAAAAAAAAA--- -----AAAAA----------AAAAA----- 
-----AAAAA----------AAAAA----- ---AAAAAAAAAAAAAAAAAAAAAAAA--- --AAAA------------------AAAA-- -AAAAA------------------AAAAA- -AAAAA------------------AAAAA- BAAAAA------------------AAAAAB AAAAAA------------------AAAAAA AAAAAA------------------AAAAAA AAAAAA------------------AAAAAA BAAAAA------------------AAAAAB -AAAAA------------------AAAAA- -AAAAA------------------AAAAA- --AAAA------------------AAAA-- ---AAAAAAAAAAAAAAAAAAAAAAAA--- -----AAAAA----------AAAAA----- 
-----AAAAA----------AAAAA----- ---AAAAAAAAAAAAAAAAAAAAAAAA--- --AAAA------------------AAAA-- -AAAAA------------------AAAAA- -AAAAA------------------AAAAA- CAAAAA------------------AAAAAC CAAAAA------------------AAAAAC BAAAAA------------------AAAAAB CAAAAA------------------AAAAAC CAAAAA------------------AAAAAC -AAAAA------------------AAAAA- -AAAAA------------------AAAAA- --AAAA------------------AAAA-- ---AAAAAAAAAAAAAAAAAAAAAAAA--- -----AAAAA----------AAAAA----- 
-----AABAB----------BABAA----- ---AAAAAAABCBBAABBCBAAAAAAA--- --AAAA------------------AAAA-- -AAAAB------------------BAAAA- -AAAAB------------------BAAAA- AAAAAC------------------CAAAAA CAAAAA------------------AAAAAC BAAAAA------------------AAAAAB CAAAAA------------------AAAAAC AAAAAB------------------BAAAAA -AAAAA------------------AAAAA- -AAAAB------------------BAAAA- --AAAC------------------CAAA-- ---AAAABABAAABAABAAABABAAAA--- -----ACBBA----------ABBCA----- 
------------------------------ ---AC--------------------CA--- --AAA--------------------AAA-- -AAAC--------------------CAAA- -AAAA--------------------AAAA- AAAAB--------------------BAAAA AAAAC--------------------CAAAA CAAAB--------------------BAAAC AAAAC--------------------CAAAA AAAAA--------------------AAAAA -AAAA--------------------AAAA- -AAAA--------------------AAAA- --AAA--------------------AAA-- ---AC--------------------CA--- ------------------------------ 
------------------------------ ---A----------------------A--- --AC----------------------CA-- -AAC----------------------CAA- -AAA----------------------AAA- CAAC----------------------CAAC BAAA----------------------AAAB CAAA----------------------AAAC BAAA----------------------AAAB CAAC----------------------CAAC -AAA----------------------AAA- -AAA----------------------AAA- --AA----------------------AA-- ---B----------------------B--- ------------------------------ 
------------------------------ ------------------------------ --A------------------------A-- -AA------------------------AA- -AA------------------------AA- AAA------------------------AAA AAC------------------------CAA AAA------------------------AAA AAA------------------------AAA AAC------------------------CAA -AA------------------------AA- -AC------------------------CA- --C------------------------C-- ------------------------------ ------------------------------ 
------------------------------ ------------------------------ ------------------------------ -A--------------------------A- -C--------------------------C- BA--------------------------AB BA--------------------------AB AB--------------------------BA BA--------------------------AB BC--------------------------CB -A--------------------------A- -C--------------------------C- ------------------------------ ------------------------------ ------------------------------ 
------------------------------ ------------------------------ ------------------------------ ------------------------------ ------------------------------ C----------------------------C A----------------------------A A----------------------------A B----------------------------B B----------------------------B ------------------------------ ------------------------------ ------------------------------ ------------------------------ ------------------------------ 
