model
size = 30 15 12, scale = 0.05, origin = -y
material 
  colors = A:#C93 B:#CC0 C:#636
voxels
-----BBBAB----------BABBB----- ---BBAAAABBBAAAAAABBBAAAABB--- --BABBBABAABAAAAAABAABABBBAB-- -BBBBAABAABABABBABABAABAABBBB- -AABAABBBBBABABBABABBBBBAABAA- AAABBBABBBBABBAABBABBBBABBBAAA AAAABABAABABABAABABABAABABAAAA BAAAABBBAABBABBBBABBAABBBAAAAB BBAABBAABAAAABBBBAAAABAABBAABB AABBAABBBABABBAABBABABBBAABBAA -AABBBABBBBBAAAAAABBBBBABBBAA- -AABBBBAAABAAAAAAAABAAABBBBAA- --BABBAAABBBBAAAABBBBAAABBAB-- ---BABBBBAAABBAABBAAABBBBAB--- -----BABBA----------ABBAB----- 
-----AAAAA----------AAAAA----- ---AAAAAAAAAAAAAAAAAAAAAAAA--- --AAAAAAAAAAAAAAAAAAAAAAAAAA-- -AAAAAAAAAAAAAAAAAAAAAAAAAAAA- -AAAAAAACCCCAAAAAACCCCAAAAAAA- AAAAAAACCCCCCAAAACCCCCCAAAAAAA AAAAAACCCCCCCCAACCCCCCCCAAAAAA AAAAAACCCCCCCCAACCCCCCCCAAAAAA AAAAAACCCCCCCCAACCCCCCCCAAAAAA AAAAAACCCCCCCCAACCCCCCCCAAAAAA -AAAAAACCCCCCAAAACCCCCCAAAAAA- -AAAAAAACCCCAAAAAACCCCAAAAAAA- --AAAAAAAAAAAAAAAAAAAAAAAAAA-- ---AAAAAAAAAAAAAAAAAAAAAAAA--- -----AAAAA----------AAAAA----- 
-----AAAAA----------AAAAA----- ---AAAAAAAAAAAAAAAAAAAAAAAA--- --AAAAAAAAAAAAAAAAAAAAAAAAAA-- -AAAAA------------------AAAAA- -AAAAA------------------AAAAA- AAAAAA------------------AAAAAA AAAAAA------------------AAAAAA AAAAAA------------------AAAAAA AAAAAA------------------AAAAAA AAAAAA------------------AAAAAA -AAAAA------------------AAAAA- -AAAAA------------------AAAAA- --AAAA------------------AAAA-- ---AAAAAAAAAAAAAAAAAAAAAAAA--- -----AAAAA----------AAAAA----- 
-----AAAAA----------AAAAA----- ---AAAAAAAAAAAAAAAAAAAAAAAA--- --AAAAAAABAAABBBBAAABAAAAAAA-- -AAAAA------------------AAAAA- -AAAAA------------------AAAAA- AAAAAA------------------AAAAAA AAAAAA------------------AAAAAA AAAAAA------------------AAAAAA AAAAAA------------------AAAAAA AAAAAA------------------AAAAAA -AAAAA------------------AAAAA- -AAAAA------------------AAAAA- --AAAA------------------AAAA-- ---AAAAAAAAAAAAAAAAAAAAAAAA--- -----AAAAA----------AAAAA----- 
-----AAAAA----------AAAAA----- ---AAAAAAAAAAAAAAAAAAAAAAAA--- --AAAA------------------AAAA-- -AAAAA------------------AAAAA- -AAAAA------------------AAAAA- AAAAAA------------------AAAAAA AAAAAA------------------AAAAAA AAAAAA------------------AAAAAA AAAAAA------------------AAAAAA AAAAAA------------------AAAAAA -AAAAA------------------AAAAA- -AAAAA------------------AAAAA- --AAAA------------------AAAA-- ---AAAAAAAAAAAAAAAAAAAAAAAA--- -----AAAAA----------AAAAA----- 
-----AAAAA----------AAAAA----- ---AAAAAAAAAAAAAAAAAAAAAAAA--- --AAAA------------------AAAA-- -AAAAA------------------AAAAA- -AAAAA------------------AAAAA- AAAAAA------------------AAAAAA AAAAAA------------------AAAAAA AAAAAA------------------AAAAAA AAAAAA------------------AAAAAA AAAAAA------------------AAAAAA -AAAAA------------------AAAAA- -AAAAA------------------AAAAA- --AAAA------------------AAAA-- ---AAAAAAAAAAAAAAAAAAAAAAAA--- -----AAAAA----------AAAAA----- 
-----ABABA----------ABABA----- ---AABAAAAAAABBBBAAAAAAABAA--- --AAAA------------------AAAA-- -AAAAA------------------AAAAA- -AAAAA------------------AAAAA- AAAAAA------------------AAAAAA AAAAAA------------------AAAAAA AAAAAA------------------AAAAAA AAAAAB------------------BAAAAA AAAAAB------------------BAAAAA -AAAAA------------------AAAAA- -AAAAB------------------BAAAA- --AAAB------------------BAAA-- ---AABABBBBABBBBBBABBBBABAA--- -----BBABA----------ABABB----- 
------------------------------ ---AB--------------------BA--- --AAA--------------------AAA-- -AAAA--------------------AAAA- -AAAA--------------------AAAA- AAAAB--------------------BAAAA AAAAA--------------------AAAAA AAAAA--------------------AAAAA AAAAB--------------------BAAAA AAAAB--------------------BAAAA -AAAA--------------------AAAA- -AAAB--------------------BAAA- --AAB--------------------BAA-- ---AB--------------------BA--- ------------------------------ 
------------------------------ ---A----------------------A--- --AB----------------------BA-- -AAB----------------------BAA- -AAB----------------------BAA- AAAB----------------------BAAA AAAA----------------------AAAA AAAA----------------------AAAA AAAA----------------------AAAA AAAA----------------------AAAA -AAA----------------------AAA- -AAA----------------------AAA- --AB----------------------BA-- ---B----------------------B--- ------------------------------ 
------------------------------ ------------------------------ --A------------------------A-- -AA------------------------AA- -AB------------------------BA- AAB------------------------BAA AAA------------------------AAA AAA------------------------AAA AAA------------------------AAA AAB------------------------BAA -AA------------------------AA- -AA------------------------AA- --B------------------------B-- ------------------------------ ------------------------------ 
------------------------------ ------------------------------ ------------------------------ -B--------------------------B- -A--------------------------A- AA--------------------------AA AA--------------------------AA AB--------------------------BA AA--------------------------AA AA--------------------------AA -A--------------------------A- -B--------------------------B- ------------------------------ ------------------------------ ------------------------------ 
------------------------------ ------------------------------ ------------------------------ ------------------------------ ------------------------------ A----------------------------A A----------------------------A A----------------------------A A----------------------------A B----------------------------B ------------------------------ ------------------------------ ------------------------------ ------------------------------ ------------------------------ 
