model
size = 30 15 12, scale = 0.05, origin = -y
material 
  colors = A:#903 B:#FCF C:#9F6
voxels
-----BBABA----------ABABB----- ---AABBABABBBBBBBBBBABABBAA--- --AAAABBBBBBABBBBABBBBBBAAAA-- -ABBABBBAABABBAABBABAABBBABBA- -BBABBABBBBABBBBBBABBBBABBABB- AAAABABBBBBBBABBABBBBBBBABAAAA ABBBAABAAAABABAABABAAAABAABBBA AABAAAABABBAAABBAAABBABAAAABAA ABBBAABBAABBABAABABBAABBAABBBA BBABABABAABAAABBAAABAABABABABB -AABBBAABAAAABAABAAAABAABBBAA- -AAAABBBABBAABAABAABBABBBAAAA- --BBABAABBBABBAABBABBBAABABB-- ---BBABAABABBBAABBBABAABABB--- -----ABABB----------BBABA----- 
-----ABAAA----------AAABA----- ---AAAAAAABBABBBBABBAAAAAAA--- --AAAAAAAAAAAAAAAAAAAAAAAAAA-- -AAAAAAAAAAAAAAAAAAAAAAAAAAAA- -AAAAAAACCCCAAAAAACCCCAAAAAAA- AAAAAAACCCCCCAAAACCCCCCAAAAAAA AAAAAACCCCCCCCAACCCCCCCCAAAAAA AAAAAACCCCCCCCAACCCCCCCCAAAAAA AAAAAACCCCCCCCAACCCCCCCCAAAAAA AAAAAACCCCCCCCAACCCCCCCCAAAAAA -AAAAAACCCCCCAAAACCCCCCAAAAAA- -AAAAAAACCCCAAAAAACCCCAAAAAAA- --AAAAAAAAAAAAAAAAAAAAAAAAAA-- ---AAAAAAABBABBBBABBAAAAAAA--- -----ABAAA----------AAABA----- 
-----AAAAA----------AAAAA----- ---AAAAAAAAABAAAABAAAAAAAAA--- --AAAAAAAAAAAAAAAAAAAAAAAAAA-- -AAAAA------------------AAAAA- -AAAAA------------------AAAAA- AAAAAA------------------AAAAAA AAAAAA------------------AAAAAA AAAAAA------------------AAAAAA AAAAAA------------------AAAAAA AAAAAA------------------AAAAAA -AAAAA------------------AAAAA- -AAAAA------------------AAAAA- --AAAA------------------AAAA-- ---AAAAAAAAABAAAABAAAAAAAAA--- -----AAAAA----------AAAAA----- 
-----AAAAB----------BAAAA----- ---AAAAAAAAABAAAABAAAAAAAAA--- --AAAAAAABAABBAABBAABAAAAAAA-- -AAAAA------------------AAAAA- -AAAAA------------------AAAAA- AAAAAA------------------AAAAAA AAAAAA------------------AAAAAA AAAAAA------------------AAAAAA AAAAAA------------------AAAAAA AAAAAA------------------AAAAAA -AAAAA------------------AAAAA- -AAAAA------------------AAAAA- --AAAA------------------AAAA-- ---AAAAAAAAABAAAABAAAAAAAAA--- -----AAAAB----------BAAAA----- 
-----ABABA----------ABABA----- ---AAAAAAAABAAAAAABAAAAAAAA--- --AAAA------------------AAAA-- -AAAAA------------------AAAAA- -AAAAA------------------AAAAA- AAAAAA------------------AAAAAA AAAAAA------------------AAAAAA AAAAAA------------------AAAAAA AAAAAA------------------AAAAAA AAAAAA------------------AAAAAA -AAAAA------------------AAAAA- -AAAAA------------------AAAAA- --AAAA------------------AAAA-- ---AAAAAAAABAAAAAABAAAAAAAA--- -----ABABA----------ABABA----- 
-----AAAAB----------BAAAA----- ---AAAAAAAAABAAAABAAAAAAAAA--- --AAAA------------------AAAA-- -AAAAA------------------AAAAA- -AAAAA------------------AAAAA- AAAAAA------------------AAAAAA AAAAAA------------------AAAAAA AAAAAA------------------AAAAAA AAAAAA------------------AAAAAA AAAAAA------------------AAAAAA -AAAAA------------------AAAAA- -AAAAA------------------AAAAA- --AAAA------------------AAAA-- ---AAAAAAAAABAAAABAAAAAAAAA--- -----AAAAB----------BAAAA----- 
-----BBAAB----------BAABB----- ---AABAABABBAABBAABBABAABAA--- --AAAA------------------AAAA-- -AAAAB------------------BAAAA- -AAAAB------------------BAAAA- AAAAAA------------------AAAAAA AAAAAA------------------AAAAAA AAAAAA------------------AAAAAA AAAAAA------------------AAAAAA AAAAAA------------------AAAAAA -AAAAB------------------BAAAA- -AAAAA------------------AAAAA- --AAAA------------------AAAA-- ---AAAAAAAABABAABABAAAAAAAA--- -----BABAB----------BABAB----- 
------------------------------ ---AA--------------------AA--- --AAB--------------------BAA-- -AAAB--------------------BAAA- -AAAA--------------------AAAA- AAAAA--------------------AAAAA AAAAA--------------------AAAAA AAAAA--------------------AAAAA AAAAB--------------------BAAAA AAAAA--------------------AAAAA -AAAA--------------------AAAA- -AAAA--------------------AAAA- --AAA--------------------AAA-- ---AA--------------------AA--- ------------------------------ 
------------------------------ ---A----------------------A--- --AA----------------------AA-- -AAA----------------------AAA- -AAA----------------------AAA- AAAA----------------------AAAA AAAA----------------------AAAA AAAA----------------------AAAA AAAB----------------------BAAA AAAA----------------------AAAA -AAB----------------------BAA- -AAB----------------------BAA- --AB----------------------BA-- ---A----------------------A--- ------------------------------ 
------------------------------ ------------------------------ --A------------------------A-- -AB------------------------BA- -AA------------------------AA- AAA------------------------AAA AAB------------------------BAA AAA------------------------AAA AAB------------------------BAA AAB------------------------BAA -AA------------------------AA- -AA------------------------AA- --A------------------------A-- ------------------------------ ------------------------------ 
------------------------------ ------------------------------ ------------------------------ -A--------------------------A- -B--------------------------B- AB--------------------------BA AA--------------------------AA AA--------------------------AA AA--------------------------AA AA--------------------------AA -A--------------------------A- -A--------------------------A- ------------------------------ ------------------------------ ------------------------------ 
------------------------------ ------------------------------ ------------------------------ ------------------------------ ------------------------------ B----------------------------B A----------------------------A B----------------------------B A----------------------------A A----------------------------A ------------------------------ ------------------------------ ------------------------------ ------------------------------ ------------------------------ 
