model
size = 30 15 12, scale = 0.05, origin = -y
material 
  colors = A:#C30 B:#CC9 C:#C63
voxels
-----BABBB----------BBBAB----- ---ABABABBABBAAAABBABBABABA--- --AAABBBBABABBBBBBABABBBBAAA-- -BABBBAABBBAAAAAAAABBBAABBBAB- -ABBABABBABAAABBAAABABBABABBA- AABABABABAAABAAAABAAABABABABAA ABBBBBABBABBBBAABBBBABBABBBBBA ABAABBABBABAAAAAAAABABBABBAABA BBAAAABBAAAAAABBAAAAAABBAAAABB BBBBAAAABABABBBBBBABABAAAABBBB -BAAABABABABBAAAABBABABABAAAB- -AABBBBBBAAABBBBBBAAABBBBBBAA- --ABABBABABAAAAAAAABABABBABA-- ---ABBABAAABBBBBBBBAAABABBA--- -----BABBB----------BBBAB----- 
-----BAABA----------ABAAB----- ---AAAAAAABAAABBAAABAAAAAAA--- --AAAAAAAAAAAAAAAAAAAAAAAAAA-- -AAAAAAAAAAAAAAAAAAAAAAAAAAAA- -AAAAAAACCCCAAAAAACCCCAAAAAAA- BAAAAAACCCCCCAAAACCCCCCAAAAAAB BAAAAACCCCCCCCAACCCCCCCCAAAAAB BAAAAACCCCCCCCAACCCCCCCCAAAAAB BAAAAACCCCCCCCAACCCCCCCCAAAAAB BAAAAACCCCCCCCAACCCCCCCCAAAAAB -AAAAAACCCCCCAAAACCCCCCAAAAAA- -AAAAAAACCCCAAAAAACCCCAAAAAAA- --AAAAAAAAAAAAAAAAAAAAAAAAAA-- ---AAAAAAABAAABBAAABAAAAAAA--- -----BAABA----------ABAAB----- 
-----ABAAA----------AAABA----- ---AAAAAAAAABAAAABAAAAAAAAA--- --AAAAAAAAAAAAAAAAAAAAAAAAAA-- -AAAAA------------------AAAAA- -AAAAA------------------AAAAA- BAAAAA------------------AAAAAB BAAAAA------------------AAAAAB BAAAAA------------------AAAAAB BAAAAA------------------AAAAAB BAAAAA------------------AAAAAB -AAAAA------------------AAAAA- -AAAAA------------------AAAAA- --AAAA------------------AAAA-- ---AAAAAAAAABAAAABAAAAAAAAA--- -----ABAAA----------AAABA----- 
-----AAABB----------BBAAA----- ---AAAAAAABBAABBAABBAAAAAAA--- --AAAAAAAAAAAABBAAAAAAAAAAAA-- -AAAAA------------------AAAAA- -AAAAA------------------AAAAA- BAAAAA------------------AAAAAB BAAAAA------------------AAAAAB BAAAAA------------------AAAAAB BAAAAA------------------AAAAAB BAAAAA------------------AAAAAB -AAAAA------------------AAAAA- -AAAAA------------------AAAAA- --AAAA------------------AAAA-- ---AAAAAAABBAABBAABBAAAAAAA--- -----AAABB----------BBAAA----- 
-----BBAAA----------AAABB----- ---AAAAAAABBABAABABBAAAAAAA--- --AAAA------------------AAAA-- -AAAAA------------------AAAAA- -AAAAA------------------AAAAA- BAAAAA------------------AAAAAB BAAAAA------------------AAAAAB BAAAAA------------------AAAAAB BAAAAA------------------AAAAAB BAAAAA------------------AAAAAB -AAAAA------------------AAAAA- -AAAAA------------------AAAAA- --AAAA------------------AAAA-- ---AAAAAAABBABAABABBAAAAAAA--- -----BBAAA----------AAABB----- 
-----ABBBB----------BBBBA----- ---AAAAAAAABAAAAAABAAAAAAAA--- --AAAA------------------AAAA-- -AAAAA------------------AAAAA- -AAAAA------------------AAAAA- BAAAAA------------------AAAAAB BAAAAA------------------AAAAAB BAAAAA------------------AAAAAB BAAAAA------------------AAAAAB BAAAAA------------------AAAAAB -AAAAA------------------AAAAA- -AAAAA------------------AAAAA- --AAAA------------------AAAA-- ---AAAAAAAABAAAAAABAAAAAAAA--- -----ABBBB----------BBBBA----- 
-----BAAAA----------AAAAB----- ---AABABBAAAABAABAAAABBABAA--- --AAAA------------------AAAA-- -AAAAB------------------BAAAA- -AAAAA------------------AAAAA- BAAAAB------------------BAAAAB BAAAAA------------------AAAAAB BAAAAA------------------AAAAAB BAAAAB------------------BAAAAB BAAAAA------------------AAAAAB -AAAAB------------------BAAAA- -AAAAA------------------AAAAA- --AAAA------------------AAAA-- ---AAABAABAABABBABAABAABAAA--- -----BBAAB----------BAABB----- 
------------------------------ ---AB--------------------BA--- --AAA--------------------AAA-- -AAAA--------------------AAAA- -AAAA--------------------AAAA- BAAAA--------------------AAAAB AAAAA--------------------AAAAA AAAAB--------------------BAAAA AAAAB--------------------BAAAA BAAAA--------------------AAAAB -AAAB--------------------BAAA- -AAAB--------------------BAAA- --AAA--------------------AAA-- ---AA--------------------AA--- ------------------------------ 
------------------------------ ---A----------------------A--- --AB----------------------BA-- -AAA----------------------AAA- -AAA----------------------AAA- BAAA----------------------AAAB AAAA----------------------AAAA AAAA----------------------AAAA AAAA----------------------AAAA BAAA----------------------AAAB -AAB----------------------BAA- -AAA----------------------AAA- --AA----------------------AA-- ---A----------------------A--- ------------------------------ 
------------------------------ ------------------------------ --A------------------------A-- -AB------------------------BA- -AA------------------------AA- AAB------------------------BAA BAA------------------------AAB BAA------------------------AAB BAA------------------------AAB AAB------------------------BAA -AA------------------------AA- -AA------------------------AA- --A------------------------A-- ------------------------------ ------------------------------ 
------------------------------ ------------------------------ ------------------------------ -A--------------------------A- -A--------------------------A- BB--------------------------BB BA--------------------------AB BA--------------------------AB BA--------------------------AB BB--------------------------BB -A--------------------------A- -A--------------------------A- ------------------------------ ------------------------------ ------------------------------ 
------------------------------ ------------------------------ ------------------------------ ------------------------------ ------------------------------ A----------------------------A A----------------------------A B----------------------------B A----------------------------A A----------------------------A ------------------------------ ------------------------------ ------------------------------ ------------------------------ ------------------------------ 
