model
size = 30 15 12, scale = 0.05, origin = -y
material 
  colors = A:#C33 B:#C0F C:#010
voxels
-----BAAAC----------CAAAB----- ---AAAAACBACAAAAAACABCAAAAA--- --ACAAABABBAABAABAABBABAAACA-- -ACACBBAABBAAAAAAAABBAABBCACA- -CABABACBAACCBBBBCCAABCABABAC- AAACBABAAABACCBBCCABAAABABCAAA AABCBAAABCAABBAABBAACBAAABCBAA BBCACCABABAABCAACBAABABACCACBB ABCABAAAACBABABBABABCAAAABACBA CACAACAAABCABACCABACBAAACAACAC -ACABAACACBCCCAACCCBCACAABACA- -ABCCCCCAAAABACCABAAAACCCCCBA- --ABBACACAACACAACACAACACABBA-- ---AAACCACACAABBAACACACCAAA--- -----BCAAC----------CAACB----- 
-----BCAAA----------AAACB----- ---AAAAAAAABAACCAABAAAAAAAA--- --AAAAAAAAAAAAAAAAAAAAAAAAAA-- -AAAAAAAAAAAAAAAAAAAAAAAAAAAA- -AAAAAAABBBBAAAAAABBBBAAAAAAA- AAAAAAABBBBBBAAAABBBBBBAAAAAAA AAAAAABBBBBBBBAABBBBBBBBAAAAAA CAAAAABBBBBBBBAABBBBBBBBAAAAAC AAAAAABBBBBBBBAABBBBBBBBAAAAAA AAAAAABBBBBBBBAABBBBBBBBAAAAAA -AAAAAABBBBBBAAAABBBBBBAAAAAA- -AAAAAAABBBBAAAAAABBBBAAAAAAA- --AAAAAAAAAAAAAAAAAAAAAAAAAA-- ---AAAAAAAABAACCAABAAAAAAAA--- -----BCAAA----------AAACB----- 
-----BACCA----------ACCAB----- ---AAAAAAABCBBAABBCBAAAAAAA--- --AAAAAAAAAAAAAAAAAAAAAAAAAA-- -AAAAA------------------AAAAA- -AAAAA------------------AAAAA- AAAAAA------------------AAAAAA AAAAAA------------------AAAAAA AAAAAA------------------AAAAAA AAAAAA------------------AAAAAA AAAAAA------------------AAAAAA -AAAAA------------------AAAAA- -AAAAA------------------AAAAA- --AAAA------------------AAAA-- ---AAAAAAABCBBAABBCBAAAAAAA--- -----BACCA----------ACCAB----- 
-----ABBCA----------ACBBA----- ---AAAAAAAAABABBABAAAAAAAAA--- --AAAAABACCCBACCABCCCABAAAAA-- -AAAAA------------------AAAAA- -AAAAA------------------AAAAA- AAAAAA------------------AAAAAA CAAAAA------------------AAAAAC AAAAAA------------------AAAAAA CAAAAA------------------AAAAAC AAAAAA------------------AAAAAA -AAAAA------------------AAAAA- -AAAAA------------------AAAAA- --AAAA------------------AAAA-- ---AAAAAAAAABABBABAAAAAAAAA--- -----ABBCA----------ACBBA----- 
-----ACACC----------CCACA----- ---AAAAAAABBCBBBBCBBAAAAAAA--- --AAAA------------------AAAA-- -AAAAA------------------AAAAA- -AAAAA------------------AAAAA- AAAAAA------------------AAAAAA CAAAAA------------------AAAAAC CAAAAA------------------AAAAAC CAAAAA------------------AAAAAC AAAAAA------------------AAAAAA -AAAAA------------------AAAAA- -AAAAA------------------AAAAA- --AAAA------------------AAAA-- ---AAAAAAABBCBBBBCBBAAAAAAA--- -----ACACC----------CCACA----- 
-----AAAAB----------BAAAA----- ---AAAAAAAAACAAAACAAAAAAAAA--- --AAAA------------------AAAA-- -AAAAA------------------AAAAA- -AAAAA------------------AAAAA- AAAAAA------------------AAAAAA AAAAAA------------------AAAAAA CAAAAA------------------AAAAAC AAAAAA------------------AAAAAA AAAAAA------------------AAAAAA -AAAAA------------------AAAAA- -AAAAA------------------AAAAA- --AAAA------------------AAAA-- ---AAAAAAAAACAAAACAAAAAAAAA--- -----AAAAB----------BAAAA----- 
-----AABAA----------AABAA----- ---AACCABAABAABBAABAABACCAA--- --AAAA------------------AAAA-- -AAAAA------------------AAAAA- -AAAAA------------------AAAAA- CAAAAC------------------CAAAAC AAAAAA------------------AAAAAA CAAAAC------------------CAAAAC AAAAAC------------------CAAAAA CAAAAC------------------CAAAAC -AAAAB------------------BAAAA- -AAAAB------------------BAAAA- --AAAA------------------AAAA-- ---AAAAAACAAACAACAAACAAAAAA--- -----AAACB----------BCAAA----- 
------------------------------ ---AB--------------------BA--- --AAA--------------------AAA-- -AAAA--------------------AAAA- -AAAB--------------------BAAA- AAAAA--------------------AAAAA AAAAA--------------------AAAAA AAAAA--------------------AAAAA AAAAC--------------------CAAAA AAAAA--------------------AAAAA -AAAA--------------------AAAA- -AAAB--------------------BAAA- --AAA--------------------AAA-- ---AB--------------------BA--- ------------------------------ 
------------------------------ ---B----------------------B--- --AB----------------------BA-- -AAC----------------------CAA- -AAA----------------------AAA- AAAB----------------------BAAA AAAC----------------------CAAA BAAB----------------------BAAB AAAA----------------------AAAA AAAC----------------------CAAA -AAA----------------------AAA- -AAB----------------------BAA- --AB----------------------BA-- ---C----------------------C--- ------------------------------ 
------------------------------ ------------------------------ --A------------------------A-- -AB------------------------BA- -AA------------------------AA- AAC------------------------CAA BAA------------------------AAB AAB------------------------BAA BAA------------------------AAB AAC------------------------CAA -AB------------------------BA- -AC------------------------CA- --C------------------------C-- ------------------------------ ------------------------------ 
------------------------------ ------------------------------ ------------------------------ -B--------------------------B- -A--------------------------A- AC--------------------------CA AA--------------------------AA AB--------------------------BA AC--------------------------CA AB--------------------------BA -A--------------------------A- -A--------------------------A- ------------------------------ ------------------------------ ------------------------------ 
------------------------------ ------------------------------ ------------------------------ ------------------------------ ------------------------------ C----------------------------C B----------------------------B A----------------------------A B----------------------------B A----------------------------A ------------------------------ ------------------------------ ------------------------------ ------------------------------ ------------------------------ 
