model
size = 30 15 12, scale = 0.05, origin = -y
material 
  colors = A:#9F6 B:#C6F C:#C3C
voxels
-----ACAAA----------AAACA----- ---ACCABAACCBCCCCBCCAABACCA--- --BACAAAABAAABBBBAAABAAAACAB-- -ACABAACBCAABBBBBBAACBCAABACA- -BACBABAAABBBACCABBBAAABABCAB- CCAAABCABBABABAABABABBACBAAACC CBBACCBAABCBAACCAABCBAABCCABBC AACACAABBBCCCCAACCCCBBBAACACAA CCAAAAABCCABACBBCABACCBAAAAACC BACABBBACAAABACCABAAACABBBACAB -AABBCABAAAAABAABAAAAABACBBAA- -ACCABACABAAAABBAAAABACABACCA- --ACBBAAAAABBACCABBAAAAABBCA-- ---ABBCCAABBBBCCBBBBAACCBBA--- -----ABCCB----------BCCBA----- 
-----AAAAA----------AAAAA----- ---AAAAAAAAAAAAAAAAAAAAAAAA--- --AAAAAAAAAAAAAAAAAAAAAAAAAA-- -AAAAAAAAAAAAAAAAAAAAAAAAAAAA- -AAAAAAABBBBAAAAAABBBBAAAAAAA- BAAAAAABBBBBBAAAABBBBBBAAAAAAB AAAAAABBBBBBBBAABBBBBBBBAAAAAA AAAAAABBBBBBBBAABBBBBBBBAAAAAA AAAAAABBBBBBBBAABBBBBBBBAAAAAA BAAAAABBBBBBBBAABBBBBBBBAAAAAB -AAAAAABBBBBBAAAABBBBBBAAAAAA- -AAAAAAABBBBAAAAAABBBBAAAAAAA- --AAAAAAAAAAAAAAAAAAAAAAAAAA-- ---AAAAAAAAAAAAAAAAAAAAAAAA--- -----AAAAA----------AAAAA----- 
-----AAAAA----------AAAAA----- ---AAAAAAAAAAAAAAAAAAAAAAAA--- --AAAAAAAAAAAAAAAAAAAAAAAAAA-- -AAAAA------------------AAAAA- -AAAAA------------------AAAAA- BAAAAA------------------AAAAAB CAAAAA------------------AAAAAC BAAAAA------------------AAAAAB CAAAAA------------------AAAAAC BAAAAA------------------AAAAAB -AAAAA------------------AAAAA- -AAAAA------------------AAAAA- --AAAA------------------AAAA-- ---AAAAAAAAAAAAAAAAAAAAAAAA--- -----AAAAA----------AAAAA----- 
-----AAAAA----------AAAAA----- ---AAAAAAAAAAAAAAAAAAAAAAAA--- --AAAACCAAACAABBAACAAACCAAAA-- -AAAAA------------------AAAAA- -AAAAA------------------AAAAA- CAAAAA------------------AAAAAC CAAAAA------------------AAAAAC AAAAAA------------------AAAAAA CAAAAA------------------AAAAAC CAAAAA------------------AAAAAC -AAAAA------------------AAAAA- -AAAAA------------------AAAAA- --AAAA------------------AAAA-- ---AAAAAAAAAAAAAAAAAAAAAAAA--- -----AAAAA----------AAAAA----- 
-----AAAAA----------AAAAA----- ---AAAAAAAAAAAAAAAAAAAAAAAA--- --AAAA------------------AAAA-- -AAAAA------------------AAAAA- -AAAAA------------------AAAAA- CAAAAA------------------AAAAAC AAAAAA------------------AAAAAA BAAAAA------------------AAAAAB AAAAAA------------------AAAAAA CAAAAA------------------AAAAAC -AAAAA------------------AAAAA- -AAAAA------------------AAAAA- --AAAA------------------AAAA-- ---AAAAAAAAAAAAAAAAAAAAAAAA--- -----AAAAA----------AAAAA----- 
-----AAAAA----------AAAAA----- ---AAAAAAAAAAAAAAAAAAAAAAAA--- --AAAA------------------AAAA-- -AAAAA------------------AAAAA- -AAAAA------------------AAAAA- BAAAAA------------------AAAAAB CAAAAA------------------AAAAAC BAAAAA------------------AAAAAB CAAAAA------------------AAAAAC BAAAAA------------------AAAAAB -AAAAA------------------AAAAA- -AAAAA------------------AAAAA- --AAAA------------------AAAA-- ---AAAAAAAAAAAAAAAAAAAAAAAA--- -----AAAAA----------AAAAA----- 
-----AAABA----------ABAAA----- ---AAAAAAACAAAAAAAACAAAAAAA--- --AAAC------------------CAAA-- -AAAAA------------------AAAAA- -AAAAB------------------BAAAA- CAAAAA------------------AAAAAC BAAAAA------------------AAAAAB AAAAAA------------------AAAAAA BAAAAA------------------AAAAAB CAAAAB------------------BAAAAC -AAAAB------------------BAAAA- -AAAAC------------------CAAAA- --AAAC------------------CAAA-- ---AAAACAACAAAAAAAACAACAAAA--- -----BABBA----------ABBAB----- 
------------------------------ ---AA--------------------AA--- --AAA--------------------AAA-- -AAAA--------------------AAAA- -AAAA--------------------AAAA- BAAAA--------------------AAAAB BAAAB--------------------BAAAB CAAAA--------------------AAAAC BAAAA--------------------AAAAB BAAAA--------------------AAAAB -AAAA--------------------AAAA- -AAAA--------------------AAAA- --AAA--------------------AAA-- ---AA--------------------AA--- ------------------------------ 
------------------------------ ---B----------------------B--- --AA----------------------AA-- -AAA----------------------AAA- -AAA----------------------AAA- AAAA----------------------AAAA BAAB----------------------BAAB CAAA----------------------AAAC BAAA----------------------AAAB AAAA----------------------AAAA -AAB----------------------BAA- -AAC----------------------CAA- --AA----------------------AA-- ---A----------------------A--- ------------------------------ 
------------------------------ ------------------------------ --A------------------------A-- -AA------------------------AA- -AA------------------------AA- CAB------------------------BAC AAA------------------------AAA BAA------------------------AAB AAA------------------------AAA CAA------------------------AAC -AA------------------------AA- -AB------------------------BA- --A------------------------A-- ------------------------------ ------------------------------ 
------------------------------ ------------------------------ ------------------------------ -A--------------------------A- -A--------------------------A- CC--------------------------CC AA--------------------------AA CA--------------------------AC AA--------------------------AA CA--------------------------AC -A--------------------------A- -B--------------------------B- ------------------------------ ------------------------------ ------------------------------ 
------------------------------ ------------------------------ ------------------------------ ------------------------------ ------------------------------ A----------------------------A A----------------------------A A----------------------------A B----------------------------B A----------------------------A ------------------------------ ------------------------------ ------------------------------ ------------------------------ ------------------------------ 
