model
size = 30 15 12, scale = 0.05, origin = -y
material 
  colors = A:#0F0 B:#020 C:#FF0
voxels
-----BBBBB----------BBBBB----- ---ABBBAABAABABBABAABAABBBA--- --BBBBABBABBBAAAABBBABBABBBB-- -AABBABAAABBAABBAABBAAABABBAA- -BBAAABABBBBABAABABBBBABAAABB- BBBABBBBBBBAAABBAAABBBBBBBABBB ABBABBAABABBBAAAABBBABAABBABBA ABBAAABABAABAAAAAABAABABAAABBA AABABBABABAAAABBAAAABABABBABAA ABAABBAAABBBBBAABBBBBAAABBAABA -BAAABBAABBAAABBAAABBAABBAAAB- -AAABBAABBBBABAABABBBBAABBAAA- --AABBBBBAAAAAAAAAAAABBBBBAA-- ---AABBAAABAAAAAAAABAAABBAA--- -----ABBAB----------BABBA----- 
-----BBBBB----------BBBBB----- ---AAAAAAAABBBAABBBAAAAAAAA--- --AAAAAAAAAAAAAAAAAAAAAAAAAA-- -AAAAAAAAAAAAAAAAAAAAAAAAAAAA- -AAAAAAACCCCAAAAAACCCCAAAAAAA- AAAAAAACCCCCCAAAACCCCCCAAAAAAA AAAAAACCCCCCCCAACCCCCCCCAAAAAA AAAAAACCCCCCCCAACCCCCCCCAAAAAA AAAAAACCCCCCCCAACCCCCCCCAAAAAA AAAAAACCCCCCCCAACCCCCCCCAAAAAA -AAAAAACCCCCCAAAACCCCCCAAAAAA- -AAAAAAACCCCAAAAAACCCCAAAAAAA- --AAAAAAAAAAAAAAAAAAAAAAAAAA-- ---AAAAAAAABBBAABBBAAAAAAAA--- -----BBBBB----------BBBBB----- 
-----BABBB----------BBBAB----- ---AAAAAAABBBABBABBBAAAAAAA--- --AAAAAAAAAAAAAAAAAAAAAAAAAA-- -AAAAA------------------AAAAA- -AAAAA------------------AAAAA- AAAAAA------------------AAAAAA AAAAAA------------------AAAAAA AAAAAA------------------AAAAAA AAAAAA------------------AAAAAA AAAAAA------------------AAAAAA -AAAAA------------------AAAAA- -AAAAA------------------AAAAA- --AAAA------------------AAAA-- ---AAAAAAABBBABBABBBAAAAAAA--- -----BABBB----------BBBAB----- 
-----BBBBA----------ABBBB----- ---AAAAAAABABBBBBBABAAAAAAA--- --AAAABABBBABAAAABABBBABAAAA-- -AAAAA------------------AAAAA- -AAAAA------------------AAAAA- AAAAAA------------------AAAAAA AAAAAA------------------AAAAAA AAAAAA------------------AAAAAA AAAAAA------------------AAAAAA AAAAAA------------------AAAAAA -AAAAA------------------AAAAA- -AAAAA------------------AAAAA- --AAAA------------------AAAA-- ---AAAAAAABABBBBBBABAAAAAAA--- -----BBBBA----------ABBBB----- 
-----BAABB----------BBAAB----- ---AAAAAAAABBBBBBBBAAAAAAAA--- --AAAA------------------AAAA-- -AAAAA------------------AAAAA- -AAAAA------------------AAAAA- AAAAAA------------------AAAAAA AAAAAA------------------AAAAAA AAAAAA------------------AAAAAA AAAAAA------------------AAAAAA AAAAAA------------------AAAAAA -AAAAA------------------AAAAA- -AAAAA------------------AAAAA- --AAAA------------------AAAA-- ---AAAAAAAABBBBBBBBAAAAAAAA--- -----BAABB----------BBAAB----- 
-----BBAAB----------BAABB----- ---AAAAAAABBBBAABBBBAAAAAAA--- --AAAA------------------AAAA-- -AAAAA------------------AAAAA- -AAAAA------------------AAAAA- AAAAAA------------------AAAAAA AAAAAA------------------AAAAAA AAAAAA------------------AAAAAA AAAAAA------------------AAAAAA AAAAAA------------------AAAAAA -AAAAA------------------AAAAA- -AAAAA------------------AAAAA- --AAAA------------------AAAA-- ---AAAAAAABBBBAABBBBAAAAAAA--- -----BBAAB----------BAABB----- 
-----BBBAB----------BABBB----- ---AABBABAAABABBABAAABABBAA--- --AAAB------------------BAAA-- -AAAAA------------------AAAAA- -AAAAA------------------AAAAA- AAAAAA------------------AAAAAA AAAAAA------------------AAAAAA AAAAAA------------------AAAAAA AAAAAB------------------BAAAAA AAAAAA------------------AAAAAA -AAAAA------------------AAAAA- -AAAAB------------------BAAAA- --AAAA------------------AAAA-- ---AAAAAABAABAAAABAABAAAAAA--- -----ABBAA----------AABBA----- 
------------------------------ ---AB--------------------BA--- --AAB--------------------BAA-- -AAAA--------------------AAAA- -AAAA--------------------AAAA- AAAAB--------------------BAAAA AAAAA--------------------AAAAA AAAAB--------------------BAAAA AAAAB--------------------BAAAA AAAAB--------------------BAAAA -AAAA--------------------AAAA- -AAAB--------------------BAAA- --AAB--------------------BAA-- ---AA--------------------AA--- ------------------------------ 
------------------------------ ---A----------------------A--- --AA----------------------AA-- -AAB----------------------BAA- -AAA----------------------AAA- AAAB----------------------BAAA AAAB----------------------BAAA AAAA----------------------AAAA AAAA----------------------AAAA AAAB----------------------BAAA -AAA----------------------AAA- -AAB----------------------BAA- --AB----------------------BA-- ---B----------------------B--- ------------------------------ 
------------------------------ ------------------------------ --A------------------------A-- -AA------------------------AA- -AA------------------------AA- AAB------------------------BAA AAB------------------------BAA AAB------------------------BAA AAB------------------------BAA AAA------------------------AAA -AB------------------------BA- -AB------------------------BA- --A------------------------A-- ------------------------------ ------------------------------ 
------------------------------ ------------------------------ ------------------------------ -B--------------------------B- -B--------------------------B- AA--------------------------AA AB--------------------------BA AA--------------------------AA AB--------------------------BA AA--------------------------AA -A--------------------------A- -B--------------------------B- ------------------------------ ------------------------------ ------------------------------ 
------------------------------ ------------------------------ ------------------------------ ------------------------------ ------------------------------ B----------------------------B B----------------------------B B----------------------------B B----------------------------B A----------------------------A ------------------------------ ------------------------------ ------------------------------ ------------------------------ ------------------------------ 
