model
size = 29 31 6, scale = 0.05, origin = -y
material 
  colors = A:#111 B:#EEE
voxels
----------------------------- A-BA------------------------- AABAAAA---------------------- AABAAABB--------------------- A-BAABBAA-------------------- -----BAAAA------------------- ------AAAB------------------- -------BB-------------------- ------BBBA------------------- ------AAAA------------------- -------BB-------------------- ------AAAA------------------- ------AAAA------------------- -------BB-------------------- ------AAAA------------------- ------AAAA------------------- -------BB-------------------- ------AAAA------------------- ------AAAA------------------- -------BBB------------------- -------AAAA------------------ -------AAAB------------------ --------BBB------------------ --------BBAB----------------- --------AAABA---------------- ---------AABAABB------------- ----------ABAABBAAB-AA-BB---- -----------BAABBAABBAAABBA--- --------------BBAABBAAABBA--- -----------------AB-AA-BB---- ----------------------------- 
A-BA------------------------- AABAAAA---------------------- AABAAAAB--------------------- AABAAAAAA-------------------- AABAAAAAAA------------------- A-BABAAAAAA------------------ -----AAAAAB------------------ ------BBBB------------------- -----BBBBBA------------------ -----AAAAAA------------------ ------BBBB------------------- -----AAAAAA------------------ -----AAAAAA------------------ ------BBBB------------------- -----AAAAAA------------------ -----ABBBBA------------------ ------BAAB------------------- -----AAAAAA------------------ -----AAAAAA------------------ ------BAAAB------------------ ------AAAAAA----------------- ------AAAAAB----------------- -------BAAAB----------------- -------BAAABA---------------- -------AAAABAABB------------- --------AAABAABBAAB-AA-BB---- ---------AABAABBAABBAAABBBAA- ----------ABAABBAABBAAABBBAA- -----------BAABBAABBAAABBBA-- --------------BBAABBAAABBB--- -----------------AB-AA-BB---- 
AABAA------------------------ AABAAAAB--------------------- AABAAAAAB-------------------- AABAAAAAAA------------------- AABAAAAAAAA------------------ AABAAAAAAAA------------------ ----BAAAAAB------------------ -----BBBBBB------------------ -----AAAAAA------------------ -----AAAAAA------------------ -----BBBBBB------------------ -----AAAAAA------------------ -----AAAAAA------------------ -----BBBBBB------------------ -----AAAAAA------------------ -----AAAAAA------------------ -----BAAAAB------------------ -----AAAAAA------------------ -----AAAAAA------------------ -----BAAAAAB----------------- ------AAAAAA----------------- ------AAAAAB----------------- ------BAAAABB---------------- -------BAAABAA--------------- -------AAAABAABBA------------ -------AAAABAABBAABBAAABBBAA- --------AAABAABBAABBAAABBBBAA ---------AABAABBAABBAAABBBBAA ----------ABAABBAABBAAABBBBA- -------------ABBAABBAAABBBA-- ----------------AABBAAABBB--- 
AABAA------------------------ AABAAAAB--------------------- AABAAAAAB-------------------- AABAAAAAAA------------------- AABAAAAAAAA------------------ AABAAAAAAAA------------------ ----BAAAAAB------------------ -----BAAAAB------------------ -----AAAAAA------------------ -----AAAAAA------------------ -----BAAAAB------------------ -----AAAAAA------------------ -----AAAAAA------------------ -----BAAAAB------------------ -----AAAAAA------------------ -----AAAAAA------------------ -----BAAAAB------------------ -----AAAAAA------------------ -----AAAAAA------------------ -----BAAAAAB----------------- ------AAAAAA----------------- ------AAAAAA----------------- ------BAAAABB---------------- -------BAAABAA--------------- -------AAAABAABBA------------ -------AAAABAABBAABBAAABBAAA- --------AAABAABBAABBAAABBAAAA ---------AABAABBAABBAAABBAAAA ----------ABAABBAABBAAABBAAA- -------------ABBAABBAAABBAA-- ----------------AABBAAABBB--- 
A-BA------------------------- AABAAAA---------------------- AABAAAAB--------------------- AABAAAAAB-------------------- AABAAAAAAA------------------- A-BABAAAAAA------------------ -----BAAAAB------------------ ------BAAB------------------- -----AAAAAA------------------ -----AAAAAA------------------ ------BAAB------------------- -----AAAAAA------------------ -----AAAAAA------------------ ------BAAB------------------- -----AAAAAA------------------ -----AAAAAA------------------ ------BAAB------------------- -----AAAAAA------------------ -----AAAAAA------------------ ------BAAAB------------------ ------AAAAAA----------------- ------AAAAAA----------------- -------BAAAB----------------- -------BAAABA---------------- -------AAAABAABB------------- --------AAABAABBAAB-AA-BB---- ---------AABAABBAABBAAABBAAA- ----------ABAABBAABAAAABBAAA- -----------BAABBAABAAAABBAA-- --------------BBAABBAAABBB--- -----------------AB-AA-BB---- 
----------------------------- A-BA------------------------- AABAAAB---------------------- AABAAABB--------------------- A-BAABBAA-------------------- -----BAAAA------------------- ------BBBB------------------- -------BB-------------------- ------AAAA------------------- ------AAAA------------------- -------BB-------------------- ------AAAA------------------- ------AAAA------------------- -------BB-------------------- ------AAAA------------------- ------AAAA------------------- -------BB-------------------- ------AAAA------------------- ------AAAA------------------- -------BBB------------------- -------AAAA------------------ -------AAAA------------------ --------BBB------------------ --------BBBB----------------- --------AAABA---------------- ---------AABAABB------------- ----------ABAABBAAB-AA-BB---- -----------BAABBAABBAAABBA--- --------------BBAABBAAABBA--- -----------------AB-AA-BB---- ----------------------------- 
