model
size = 24 31 24, scale = 0.05, origin = -y
material 
  colors = A:#AAA B:#00D C:#C0F D:#690 E:#63F F:#C90 G:#E00 H:#555 I:#F36 J:#F33 K:#FFC L:#609 M:#F99 N:#F6C O:#933
voxels
-----------BB----------- ------------------------ ------------------------ ------------------------ ------------------------ ------------------------ ------------------------ ------------------------ ------------------------ ------------------------ ------------------------ ------------------------ ------------------------ ------------------------ ------------------------ ------------------------ ------------------------ ------------------------ ------------------------ ------------------------ ------------------------ ------------------------ ------------------------ ------------------------ ------------------------ ------------------------ ------------------------ ------------------------ ------------------------ ------------------------ ------------------------ 
--------BBBBBBAA-------- ----------BBBB---------- -----------BO----------- ------------------------ ------------------------ ------------------------ ------------------------ ------------------------ ------------------------ ------------------------ ------------------------ ------------------------ ------------------------ ------------------------ ------------------------ ------------------------ ------------------------ ------------------------ ------------------------ ------------------------ ------------------------ ------------------------ ------------------------ ------------------------ ------------------------ ------------------------ ------------------------ ------------------------ ------------------------ ------------------------ ------------------------ 
------BEBEBBBHHHHH------ -------EBEBBBHHHH------- --------BEBBBBHH-------- ----------BBBB---------- ------------------------ ------------------------ ------------------------ ------------------------ ------------------------ ------------------------ ------------------------ ------------------------ ------------------------ ------------------------ ------------------------ ------------------------ ------------------------ ------------------------ ------------------------ ------------------------ ------------------------ ------------------------ ------------------------ ------------------------ ------------------------ ------------------------ ------------------------ ------------------------ ------------------------ ------------------------ ------------------------ 
-----BBBBBBBAAAAAAA----- ------BBBBBBBAAAAA------ -------BBBBBBAAAA------- --------BBABBBAA-------- ---------AAABBB--------- ----------AAAB---------- ------------------------ ------------------------ ------------------------ ------------------------ ------------------------ ------------------------ ------------------------ ------------------------ ------------------------ ------------------------ ------------------------ ------------------------ ------------------------ ------------------------ ------------------------ ------------------------ ------------------------ ------------------------ ------------------------ ------------------------ ------------------------ ------------------------ ------------------------ ------------------------ ------------------------ 
----BBBBBEBBAAAAAAAA---- -----EJEEEBBAAAAAAA----- -----BBBBAAABAAAAAA----- ------EEEEAAAAAAAA------ -------AAAAAAABAA------- --------AAAAAABB-------- ---------AAAAAB--------- ----------AAAB---------- ------------------------ ------------------------ ------------------------ ------------------------ ------------------------ ------------------------ ------------------------ ------------------------ ------------------------ ------------------------ ------------------------ ------------------------ ------------------------ ------------------------ ------------------------ ------------------------ ------------------------ ------------------------ ------------------------ ------------------------ ------------------------ ------------------------ ------------------------ 
---BBBBBBBBBAAAAAAAAA--- ----BEBBBBABAAAAAAAA---- ----BBBBAAAAAAAAAAAA---- -----EBEAAAAAAAAAAA----- ------BAAAAAAAAAAA------ -------AAAAAAAABB------- -------AAAAAAABBB------- --------AAAAAABB-------- ---------AAAABB--------- ----------ABBB---------- ------------------------ ------------------------ ------------------------ ------------------------ ------------------------ ------------------------ ------------------------ ------------------------ ------------------------ ------------------------ ------------------------ ------------------------ ------------------------ ------------------------ ------------------------ ------------------------ ------------------------ ------------------------ ------------------------ ------------------------ ------------------------ 
--BBBBBEBEBBAAAAAAAAAB-- ---BBEBEBEAAAAAAAAAAA--- ----BEBAAAAAAAAAAAAA---- ----BEBEEEAAAAAAAAAA---- -----BAAAAAAAAAAAAB----- ------AAAAAAAAABBB------ ------AAAAAAAAABBB------ -------AAAAAAABJB------- --------AAAAAABB-------- ---------AAABBB--------- ---------DDBDBB--------- -----------BD----------- ------------------------ ------------------------ ------------------------ ------------------------ ------------------------ ------------------------ ------------------------ ------------------------ ------------------------ ------------------------ ------------------------ ------------------------ ------------------------ ------------------------ ------------------------ ------------------------ ------------------------ ------------------------ ------------------------ 
--BBBABBBBBBAAAAAAAAAB-- --BBAAABAAAAAAAAAAAABB-- ---AAAAAAAAAAAAAAAAAB--- ----AAAAAAAAAAAAAAAB---- ----BAAAAAAAAAABABBB---- -----BAAAAAAAACCCBC----- -----BAAAAAAAAABCBC----- ------AAAAAAAACCCB------ -------AAAAAAACBB------- -------BAAAAABCCC------- --------DBBBDBBB-------- ---------BBBBBB--------- ----------BBBB---------- -----------BB----------- ------------------------ ------------------------ ------------------------ ------------------------ ------------------------ ------------------------ ------------------------ ------------------------ ------------------------ ------------------------ ------------------------ ------------------------ ------------------------ ------------------------ ------------------------ ------------------------ ------------------------ 
-BBAAAAABBBBBAAAAAAAAAB- --AAAAAAAAAABAAAAAAAAB-- --AAAAAAAAAAAAAAAAAABB-- ---AAAAAAAAAAABAAABBB--- ----AAAAAAAAAAABBBBB---- ----AAAAAAAAAACBBBCB---- -----BAAAAAAAAABBBB----- -----BBAAAAAAACBBBB----- ------BAAAAAAABBBB------ -------BBAAABBBBB------- -------BDBDDDBABB------- --------BBBBDAAA-------- ---------BDDDAA--------- ---------BBBBAA--------- ----------DDDB---------- -----------BB----------- ------------------------ ------------------------ ------------------------ ------------------------ ------------------------ ------------------------ ------------------------ ------------------------ ------------------------ ------------------------ ------------------------ ------------------------ ------------------------ ---------G-------------- ------------------------ 
-BAAAAAAABBBBBAAAAAAAAA- --AAAAAAABABBBBAAAAAAA-- --AAAAAAAAAAABBBAAAAAA-- ---AAAAAAAAAAABKBBAAA--- ---AAAAAAAAAAABBBIBBB--- ----AAAAAAAAAACBCCCB---- ----BABAAAAAAABBBBCB---- -----BBAAAAAAACBCCC----- -----BAAAAAAABBJBBB----- ------BAAAABBACCCC------ ------BBDBDBDAAAAB------ -------BBBBAAAAAA------- --------DBBAAAAA-------- --------CCCACAAA-------- ---------BCBCAA--------- ----------CBCA---------- ----------BBCB---------- -----------BC----------- ------------------------ ------------------------ ------------------------ ------------------------ ------------------------ ------------------------ ------------------------ ------------------------ ------------------------ ------------------------ ---------F-------------- --------------F--------- ------------------------ 
-BAAAAAAABBBBBBAAAAAAAA- -AAAAAAAAABBBBBBAAAAAAA- --AAAAAAAAAABBBBAAAAAA-- --AAAAAAAAAAABBBBAAAAA-- ---AAAAAAAAAAABBBBBAB--- ---AAAAAAAAAAACBCBCBB--- ----AAAAAAAAAABBBBBB---- ----BAAAAAAAABCBBBBB---- -----AAAAAAABBABBBB----- -----AAAAAAAAACACBB----- ------AADDDADAAAAA------ -------AAADADAAAA------- -------BDBDADAAAA------- --------CBBACAAA-------- --------DBDDDAAA-------- ---------BBBAAA--------- ---------BBBBBA--------- ----------BBB----------- -----------BB----------- ------------------------ ------------------------ ------------------------ ------------------------ ------------------------ ------------------------ ------------------------ ------------------------ ---------G-------------- -------------G---------- ------------------------ ------------------------ 
BAAAAAAAAABBBBBAAAAAAAAA -AAAAAAAAABBBBBAAAAAAAA- -AAAAAAAAABBBBBBAAAAAAA- --AAAAAAAAABBBBBAAAAAA-- ---AAAAAAAAABBBIBIAAA--- ---AAAAAAAAAABCCCBCBB--- ----AAAAAAAABBBBCBCB---- ----BAAAAAAABBCBCBCB---- -----AAAAAAAAACABBB----- -----AAAAAAAAACACCC----- ------AAAAAAAAAAAA------ ------AAAAAAAAAAAA------ -------BABAAAAAAA------- -------JCBCCCAAAA------- --------BBBACAAA-------- --------CKCCCAAA-------- ---------BABBAA--------- ---------CCCCKB--------- ----------AAAB---------- -----------AB----------- ------------------------ ------------M----------- -----------F------------ ------------G----------- ------------F----------- -----------GF----------- ----------F-F----------- -------------F---------- ------------------------ ------------------------ ------------------------ 
BBAAAAAAABBBBBBAAAAAAAAA -AAAAAAAAABBBBBAAAAAAAA- -AAAAAAAAABBBBBAAAAAAAA- --AAAAAAAABBBBBBAAAAAA-- ---AAAAAAABBBBBBBAAAA--- ---AAAAAAAAABBBKBBBBB--- ----AAAAAAAABJCCCBCB---- ----AAAAAAAAABBBCICB---- -----AAAAAAAAACCCBC----- -----AAAAAAAAACAAAC----- ------AAAAAAAACCCA------ ------AAAAAAAAAAAA------ -------AAAAAAAAAA------- -------BCBCACAAAA------- --------BIAAAAAA-------- --------CAAAAAAA-------- ---------AAAAAA--------- ---------ACAAAB--------- ----------BAAB---------- -----------AA----------- -----------AA----------- -----------A------------ -----------FL----------- -----------GG----------- -----------FFF---------- ------------FG---------- -------------F---------- -------------G---------- --------------G--------- ------------------------ ------------------------ 
-BAAAAAAABBBBBBAAAAAAAA- -BAAAAAAABBBBBBAAAAAAAA- --AAAAAAAABBBBBBAAAAAA-- --AAAAAAABBBBBBBAAAAAA-- ---AAAAAAAABBBBBBBAAA--- ---AAAAAAAAABBBBBBBJB--- ----AAAAAAAAABCBBBCB---- ----AAAAAAAAABBBBBBB---- -----AAAAAAAAACABBB----- -----AAAAAAAAAAAAAB----- ------AAAAAAAAAAAA------ -------AAAAAAAAAA------- -------AAAAAAAAAA------- --------CCCACAAA-------- --------BKCACAAA-------- ---------ACACAA--------- ---------AAAAAA--------- ----------CCCB---------- -----------AA----------- ------------------------ ------------------------ ------------------------ ------------------------ ------------------------ ------------------------ ------------------------ ------------F----------- ------------F----------- ------------F----------- ------------F-F--------- ------------------------ 
-BBAAAAABBBBBBBAAAAAAAA- --AAAAAAABBBBBBBAAAAAA-- --AAAAAAABBBBBBBAAAAAA-- ---AAAAAABBBBBBBBAAAA--- ---AAAAAAABBBBBBBBBAB--- ----AAAAAAAABKBBBBBB---- ----BAAAAADDDBCBCCCB---- -----AAAAAAADBDBBBC----- -----AAAAADDDBCBCCC----- ------AAAADAAADAAB------ ------AAAADDDACCCC------ -------AAAAAAAAAA------- --------AAAAAAAA-------- --------BBBAAAAA-------- ---------AAAAAA--------- ----------AAAB---------- ----------AAAB---------- -----------AA----------- ------------------------ ------------------------ ------------------------ ------------------------ ------------------------ ------------------------ ------------------------ ------------------------ ------------------------ ------------------------ ------------------------ ------------------------ ------------G--G-------- 
-BBBBABBBBGBBBBBAAAAAAA- --BBCCCBCBBBBBBBAAAAAA-- --BAAACACBBBBBDDDADAAA-- ---BCCCICBBBBBBBDBDAA--- ----CABBCBBBBBDDDBDB---- ----CCCACAABBBDBBBDB---- -----AAAAADABBCDCBC----- -----AAAAAAABBBBBBB----- ------AAAADAABCBBB------ -------AAAAABAAAB------- -------AAAAAAACAC------- --------AAAAAAAA-------- ---------BBAAAA--------- ---------BBAAAA--------- ----------AABB---------- -----------AB----------- ------------------------ ------------------------ ------------------------ ------------------------ ------------------------ ------------------------ ------------------------ ------------------------ ------------------------ ------------------------ ------------------------ ------------------------ ------------------------ ------------------------ ------------------------ 
--BBBBBBBBBBAAAAAAAAAA-- --BBCBBKCBBBBAAABBAAAB-- ---BBBBBBBBBBBDBIBDAB--- ----CBBBBIBBBBBBBBJB---- ----BBBBBBBBBBDBBBBB---- -----BBAAABBBBBBBBB----- -----BAAAADBDDCCCBC----- ------AAAAAABBDBCE------ -------AAADADDCBC------- -------AAAAABBCBB------- --------AADDDDCB-------- ---------ABBIAA--------- ----------BBAA---------- -----------BB----------- ------------------------ ------------------------ ------------------------ ------------------------ ------------------------ ------------------------ ------------------------ ------------------------ ------------------------ ------------------------ ------------------------ ------------------------ ------------------------ ------------------------ ------------------------ ------------------------ ------------------------ 
--BBBBBBBBBAAAAAAABBBB-- ---BCBCCCBBAAAAAAABBB--- ----BBBBCBBBAADADDDB---- ----CBCCCBBBBAAABBDB---- -----BBBBBBBBBDBDDD----- ------CCCBBBBBBBBB------ ------BBABDBDBDDDD------ -------AAABBBBIBB------- --------AADBBBBB-------- ---------ABBBBB--------- ---------BDBDBB--------- -----------BB----------- ------------------------ ------------------------ ------------------------ ------------------------ ------------------------ ------------------------ ------------------------ ------------------------ ------------------------ ------------------------ ------------------------ ------------------------ ------------------------ ------------------------ ------------------------ ------------------------ ------------------------ ------------------------ ------------------------ 
---BBBBBBBAAAAAAAAABB--- ----CBCBCBBAAAAAAABB---- ----BBBBBBBAAADADADB---- -----BBBBBBBAAAAABB----- ------BBBBBBBBDBBB------ -------BBBBBBBBBB------- -------BJBDDDBDBD------- --------BBBBDBDB-------- ---------BDBDED--------- ----------DBBB---------- ------------------------ ------------------------ ------------------------ ------------------------ ------------------------ ------------------------ ------------------------ ------------------------ ------------------------ ------------------------ ------------------------ ------------------------ ------------------------ ------------------------ ------------------------ ------------------------ ------------------------ ------------------------ ------------------------ ------------------------ ------------------------ 
----EEEEEBAAAAAAAAAB---- -----CCBCBAAAAAAAAA----- -----BCJCBBAAADDDAD----- ------CICBBAAAAADA------ -------BBBBBBADAD------- --------CBBBBBDB-------- ---------BBBBBD--------- ----------BBBB---------- ------------------------ ------------------------ ------------------------ ------------------------ ------------------------ ------------------------ ------------------------ ------------------------ ------------------------ ------------------------ ------------------------ ------------------------ ------------------------ ------------------------ ------------------------ ------------------------ ------------------------ ------------------------ ------------------------ ------------------------ ------------------------ ------------------------ ------------------------ 
-----BBBBBAAAAAAAAA----- ------BBBBAAAAAAAA------ -------BBBAAAAAAA------- --------BBBAAAAA-------- ---------BBBAAA--------- ----------BBBB---------- ------------------------ ------------------------ ------------------------ ------------------------ ------------------------ ------------------------ ------------------------ ------------------------ ------------------------ ------------------------ ------------------------ ------------------------ ------------------------ ------------------------ ------------------------ ------------------------ ------------------------ ------------------------ ------------------------ ------------------------ ------------------------ ------------------------ ------------------------ ------------------------ ------------------------ 
------BBBBAAAAAAAA------ -------BIBAAAAAAA------- --------NBBAAAAA-------- ----------BAAA---------- ------------------------ ------------------------ ------------------------ ------------------------ ------------------------ ------------------------ ------------------------ ------------------------ ------------------------ ------------------------ ------------------------ ------------------------ ------------------------ ------------------------ ------------------------ ------------------------ ------------------------ ------------------------ ------------------------ ------------------------ ------------------------ ------------------------ ------------------------ ------------------------ ------------------------ ------------------------ ------------------------ 
--------BBAAAAAA-------- ----------BAAA---------- -----------AA----------- ------------------------ ------------------------ ------------------------ ------------------------ ------------------------ ------------------------ ------------------------ ------------------------ ------------------------ ------------------------ ------------------------ ------------------------ ------------------------ ------------------------ ------------------------ ------------------------ ------------------------ ------------------------ ------------------------ ------------------------ ------------------------ ------------------------ ------------------------ ------------------------ ------------------------ ------------------------ ------------------------ ------------------------ 
-----------HH----------- ------------------------ ------------------------ ------------------------ ------------------------ ------------------------ ------------------------ ------------------------ ------------------------ ------------------------ ------------------------ ------------------------ ------------------------ ------------------------ ------------------------ ------------------------ ------------------------ ------------------------ ------------------------ ------------------------ ------------------------ ------------------------ ------------------------ ------------------------ ------------------------ ------------------------ ------------------------ ------------------------ ------------------------ ------------------------ ------------------------ 
