model
size = 29 16 29, scale = 0.05, origin = -y
material 
  colors = A:#06C B:#F36 C:#070 D:#EEE E:#CF0 F:#E00 G:#0E0 H:#F0C I:#007
voxels
----------------------------- ----------------------------- ----------------------------- ----------------------------- ----------------------------- ----------------------------- ----------------------------- ----------------------------- ----------------------------- ----------------------------- --------------AAAAAAADDAAAAAA --------------AAAAAAADDAAAAAA --------------AIIAAAADDAAAAAA ----------------------------- ----------------------------- ----------------------------- 
---------------AAAAAADDAAAAI- ---------------AAAAAADDAAAAI- ---------------AAAAAADDAAAAA- ---------------AAAAAADDAAIAA- ---------------AIAAAADDAAAAA- ---------------AAAAAADDAAAAA- ---------------AAAAAADDAAAAA- ---------------AAAAAADDAAAAA- ---------------AAAAAADDAAAAI- CCCCCCCFFCCCC--AAAAAADDAAAAI- CCCCCCCFFCCCC-AAAAAAADDAAAAAA --------------AAAAAAADDAAAAAA --------------AAAAAAADDAAAAAA ----------------------------- ----------------------------- ------------------------DD--- 
-CCCCCCFFCCC---AAAAAADDAAAAA- -CCCCCGFFCCC---AAAAAAAAAAAAA- -CCCCGGFFCCC---AAAAAAAAAAAAA- -CCCCCCFFCCC---AAAAAAAAAAAAA- -CCCCCCFFCCC---AAAAAAAAAAAAA- -CCCCCCFFCCC---AAAAAAAAAAAAA- -CCCCCCFFCCC---AAAAAAAAAAAAA- -CCCCCCFFCCC---AAAAAAAAAAAAA- -CGCCCCFFCCC---AAAAAAAAAAAAA- CCGGCCCFFCCCC--AAAAAAAAAAAAI- CCCGCCCFFCCCC-AAAAAAADDAAAAAA --------------AAAAAAADDAAAAAA --------------AAAAAAADDAAAAAA ----------------------------- ----------------------DDD---- -----------------DD---------- 
-CCCCCCFFCCC---AAAAAADDAAAAA- -CCCCCCCCCCC---AAAAAAAAAAAAA- -CCCGGCCCCCC---AAAAAAAAAAAAA- -CCCGCCCCCCC---AAAAAAAAAAAAA- -CCCCCCCCCCC---AAAAAAAAAAAAA- -CCCCCCCCCCC---AAAAAAAAAAAAA- -CCCCCCCCCCC---AAAAAAAAAAAAA- -GCCCCCCCCCC---AAAAAAAAAAAAA- -CGCCCCCCCCC---AAAAAAAAAAAAA- CCCCCCCFFCCCC--AAAAAAAAAAAAI- CCCCCCCFFCCCC-AAAAAAADDAAAAAA --------------AAAAAAADDAAAAAA --------------AAAAAAADDAAAAAA ----------------------DDD---- -----------------DDD---DD---- ----------------D------------ 
-CCCCCCFFCCC---AAAAAADDAAAAA- -CCGGCCCCCCC---AAAAAAAAAAAAA- -CCCGCCCCCCC---AAAAAAAAAAAAA- -CCCCCCCCCCC---AAAAAAAAAAAAA- -CCCCCCCCCCC---AAAAAAAAAAAAA- -CCCCCCCCCCC---AAAAAAAAAAAAA- -CCCCCCCCCCC---AAAAAAAAAAAAA- -GCCCCCCCCCC---AAAAAAAAAAAAA- -CCCCCCCCGCC---AAAAAAAAAAAAA- CCCCCCCFFGGCC--AAAAAAAAAAAAA- CCCCCCCFFCGCC-AAAAAAADAAAAAAA --------F-----AAAAAAADAAAAAAA ---FFF--------AAAAAAADAAAAAAA ------------------DDD-DD-D--- -----------------DD------D--- ----------------------------- 
-CCGCCCFFCCC---AAAAAADDAAAAA- -CCCCCCCCCCC---AAAAAAAAAAAAA- -CCCCCCCCCCC---AAAAAAAAAAAAA- -CCCCCCCCCCC---AAAAAAAAAAAAA- -CCCCCCCCCCC---AAAAAAAAAAAAA- -CCCCCCCCCCC---AAAAAAAAAAAAA- -CCCCCCCCCCC---AAAAAAAAAAAAA- -CCCCCCCGCCC---AAAAAAAAAAAAA- -CCCCCCCCGCC---AAAAAAAAAAAAA- CCCCCCCFCCCCC--AAAAAAAAAAAAA- CCCCCCCFCCCCC-AAAAAAADAAAAAAA ----FFF-FF----AAAAAAADAAAAAAA ---FF----F----AAAAAAADAAAAAAA ------------------DDD-DDDDD-- -----------------------DDDD-- ----------------------------- 
-CCCCCCFFCCC---DDDDDDDDDDDDD- -CCCCCCCCCCC---DDDDDDDDDDDDD- -CCCCCCCCCCC---DDDDDDDDDDDDD- -CCCCCCCCCCC---DDDDDDDDDDDDD- -CCCCCCCCCCC---D-----------D- -CCCCCCCCCCC---D-----------D- -CCCCCCGCCCC---D-----------D- -CCCCCCGGCCC---D-----------D- -CCCCCCGGCCC---D-----------D- CCCCCCCFCCCCC--D-----------D- CCCCCCCFCCCCC-DDAAAAAAAAAAADD ----FFF-FFF---DDAAAAAAAAAAADD ---------FF---DDAAAAAAAAAAADD ----------------DDDDDDDDDDD-- ----------------DDDDD-DDDDD-- ----------------------------- 
-FFFFFFFFFFF---DDDDDDDDDDDDD- -FFFFFFFFFFF---DDDDDDDDDDDDD- -FFFFFFFFFFF---DDDDDDDDDDDDD- -FFFFFFFFFFF---DDDDDDDDDDDDD- -F---------F---D-----------D- -F---------F---D-----------D- -F---------F---D-----------D- -F---------F---D-----------D- -F---------F---D-----------D- FFCCCCGCCCCFF--D-----------D- FFCCCCCCCCCFF-DDAAAAADDAAAADD --FFFFFFFFF---DDAAAAADDAAAADD --FFFFF-FFF---DDAAAAADDAAAADD ----------------DDDDDDDDDDD-- ----------------DDDDD--DDDD-- ----------------------------- 
-FFFFFFFFFFF---AAAAAADDAAAAI- -FFFFFFFFFFF---AAAAAADDAAAAA- -FFFFFFFFFFF---AAAAAADDAAAAI- -FFFFFFFFFFF---AAAAAADDAAAAA- -F---------F---AAAAAADDAAAAA- -F---------F---AAAAAADDAAAAA- -F---------F---AAAAAADDAAAAA- -F---------F---AAAAAADDAAAAA- -F---------F---AAAAAADDAAAAA- FFCCCCCFFCCFF--AAAAAADDAAAAA- FFCCCCCFFCCFF-AAAAAAADDAAAAAA --FFFFFFFFF---AAAAAAADDAAAAAA --FFFFF--FF---AAAAAAADDAAAAAA -----------------DDDD--DDD--- -----------------DDDD--DDD--- ----------------------------- 
-CCCCCCFFCCC---AAAAAADDAAAAA- -CCCCCCFFCCC---AAAAAADDAAAAA- -CCCCCCFFCCC---AAAAAADDAAAAA- -CCCCCCFFCCC---AAAAAADDAAAAA- -CCCGCCFFCCC---AAAAAADDAAAAA- -CCCGGCFFCCC---AAAAAADDAAAAA- -CCCCGCFFCCC---AAAAAADDAAAAA- -CCCCCCFFCCC---AAAAAADDAAAAA- -CCCCCGFFCCC---AAAAAADDAAAAA- CCCCCGGFFCCCC--AAAAAADDAAAAA- CCCCCCCFFCCCC-AAAAAAADDAAAAAA ---FFFF--F----AAAAAAADDAAAAAA ---FFFF--F----AAAAAAADDAAAAAA -----------------D----------- -----------------D----------- ----------------------------- 
-CCCCCCFFCCC---AAAAAADDAAAAA- -CCCCCCFFCCC---AAAAAADDAAAAA- -CCCCCCFFCCC---AAAAAADDAAAAA- -CCGCCCFFCCC---AAAAAADDAAAAA- -CCCGCCFFCCC---AAAAAADDAAAAA- -CCCCCCFFCCC---AAAAAADDAAAAA- -CCCCCCFFCCC---AAAAAADDAAAAA- -CCCCCCFFCCC---AAAAAADDAAAAA- -CCCCCCFFCCC---AAAAAADDAAAAA- CCCCGGCFFCCCC--AAAAAADDAAAAA- CCCCGCCFFCCCC-AAAAAAADDAAAAAA --------------AAAAAAADDAAAAAA --------------AAAAAAADDAAAAAA ----------------------------- ----------------------------- ----------------------------- 
-CCCCCCFFCCC---AAAAAADDAAAAA- -CCCCCCFFCCC---AAAAAADDAAAAA- -CGCCCCFFCCC---AAAAAADDAAAAA- -CGGCCCHHCCC---AAAAAADDAAAAA- -CCCCCCFFCCC---AAAAAADDAAAAA- -CCCCCCFFCCC---AAAAAADDAAAAA- -CCCCCCFFCCC---AAAAAADDAAAAA- -CCCCCCFFCCC---AAAAAADDAAAAA- -CCGGCCFFCCC---AAAAAADDAAAAA- CCCCGCCFFCCCC--AAAAAADDAAAAI- CCCCCCCFFCCCC-AAAAAAADDAAAAAA --------------AAAAAAADDAAAAAA --------------AAAAAAADDAAAAAA ----------------------------- ----------------------------- ----------------------------- 
---------------IAAAAIDDAAAAI- ---------------AIAAAADDAAAAA- ---------------AAAAAADDAAAAA- ---------------AAAAAADDAAAAA- ---------------AAAAAADDAAAAA- ---------------AAAAAADDAAAAA- ---------------AIAAAADDAAAAA- ---------------AAAAAADDAAAAA- ---------------AAAAAADDAIAAA- CCCCCCCFFCCCC--AAAAAADDAAAAI- CCCCCCCFFCCCC-AAAAAAADDAAAAAA --------------AAAAAAADDAAAAAA --------------AAAAAAADDAAAAAA ----------------------------- ----------------------------- ----------------------------- 
----------------------------- ----------------------------- ----------------------------- ----------------------------- ----------------------------- ----------------------------- ----------------------------- ----------------------------- ----------------------------- ----------------------------- --------------AAAAAAADDAAAAAI --------------AAAAAAADDAAAAAA --------------AAAAAAADDAAAAAA ----------------------------- ----------------------------- ----------------------------- 
----------------------------- ----------------------------- ----------------------------- ----------------------------- ----------------------------- ----------------------------- ----------------------------- ----------------------------- ----------------------------- ----------------------------- --------BBBBBBEEBBBBBH------- --------BBBBBBEEBBBBBB------- --------BBBBBBEEBBBBBB------- ----------------------------- ----------------------------- ----------------------------- 
---------HBBBBEEHBBBH-------- ---------HBBBBEEHBBBH-------- ---------BBBBBEEHBBBB-------- ---------BBBBBEEHBBBB-------- ---------BBBBBEEBBBBB-------- ---------BBBBBEEBBBBB-------- ---------BBBBBEEBBBBB-------- ---------BBBBBEEBBBHB-------- ---------HBHBBEEBBBHB-------- ---------HHHHBEEBBBHH-------- --------BBBBBBEEBBBBBB------- --------BBBBBBEEBBBBBB------- --------BBBBBBEEBBBBBB------- ----------------------------- ----------------------------- ----------------------------- 
---------BBBBBEEBBBBB-------- ---------BBBBBEEBBBBB-------- ---------BBBBBEEBBBBB-------- ---------BBBBBEEBBBBB-------- ---------BBBBB--BBBBB-------- ---------BBBBB--BBBBB-------- ---------BBBBB--BBBBB-------- ---------BBBBB--BBBBB-------- ---------BBBBB--BBBBB-------- ---------BBBBB--BBBBB-------- --------BBBBBBBBBBBBBB------- --------BBBBBBBBBBBBBB------- --------BBBBBBBBBBBBBB------- -------------EEE------------- -------------EEE------------- ----------------------------- 
---------BBBBBEEBBBBB-------- ---------BBBBBEEBBBBB-------- ---------BBBBBEEBBBBB-------- ---------HBBBBEEBBBBB-------- ---------BBBBB--BBBBB-------- ---------BBBBB--BBBBB-------- ---------BBBBB--BBBBB-------- ---------BBBBB--BBBBB-------- ---------BBBBB--BBBBH-------- ---------BBBBB--BBBBB-------- --------BBBBBBBBBBBBBB------- --------BBBBBBBBBBBBBB------- --------BBBBBBBBBBBBBB------- ------------EEEEE------------ ------------EEEEE------------ ---------E------------------- 
---------BBBBBEEBBBBB-------- ---------BBBBBEEBBBBB-------- ---------BBBBBEEBBBBB-------- ---------BBBBBEEBBBBB-------- ---------BBBBB--BBBBB-------- ---------BBBBB--BBBBB-------- ---------BBBBB--BBBBB-------- ---------BBBBB--BBBBB-------- ---------BBBBB--BBBBH-------- ---------BBBBB--BBBBB-------- --------BBBBBBBBBBBBBB------- --------BBBBBBBBBBBBBB------- --------BBBBBBBBBBBBBB------- -----------E-EEEE------------ ----------EE-EEEE------------ ---------E------------------- 
---------BBBBBEEBBBBB-------- ---------BBBBBEEBBBBB-------- ---------BBBBBEEBBBBB-------- ---------BBBBBEEBBBBB-------- ---------BBBBB--BBBBB-------- ---------BBBBB--BBBBB-------- ---------BBBBB--BBBBB-------- ---------BBBBB--BBBBB-------- ---------BBBBB--BBBBH-------- ---------BBBBB--BBBBB-------- --------BBBBBBBBBBBBBB------- --------BBBBBBBBBBBBBB------- --------BBBBBBBBBBBBBB------- -----------EEEEEE------------ ----------EE-EEEE------------ ----------------------------- 
---------EEEEEEEEEEEE-------- ---------EBBBBEEEEEEE-------- ---------EBBBBEEEEEEE-------- ---------EBBBBEEEEEEE-------- ---------EBBBB--EEEEE-------- ---------EBBBB--EEEEE-------- ---------EBBBB--EEEEE-------- ---------EBBBB--EEEEE-------- ---------EBBBB--EEEEE-------- ---------EBBBB--EEEEE-------- --------EEEEBBBEEEEEEE------- --------EEEEBBBEEEEEEE------- --------EEEEBBBEEEEEEE------- -----------EEEEE------------- ----------E---E-------------- ----------------------------- 
---------EEEEEEEEEEEE-------- ---------EBBBBEEEEEEE-------- ---------EBBBBEEEEEEE-------- ---------EBBBBEEEEEEE-------- ---------EBBBB--EEEEE-------- ---------EBBBB--EEEEE-------- ---------EBBBB--EEEEE-------- ---------EBBBB--EEEEE-------- ---------EBBBB--EEEEE-------- ---------EBBBB--EEEEE-------- --------EEEEEEBEEEEEEE------- --------EEEEEEBEEEEEEE------- --------EEEEEEBEEEEEEE------- --------------EE------------- ----------------------------- ----------------------------- 
---------BBBBBEEBBBBH-------- ---------BBBBBEEBBBBB-------- ---------BBBBBEEBBBBB-------- ---------BBBBBEEBBBBB-------- ---------BBBBB--BBBBB-------- ---------BBBBB--BBBBB-------- ---------BBBBB--BBBBB-------- ---------BBBBB--BBBBB-------- ---------BBBBB--BBBBB-------- ---------BBBBB--BBBBB-------- --------BBBBBBBBBBBBBB------- --------BBBBBBBBBBBBBB------- --------BBBBBBBBBBBBBB------- ------------EEEEE------------ --------------EEE------------ ----------------------------- 
---------BBBBBEEBBBBB-------- ---------BBBBBEEBBBBB-------- ---------BBBBBEEBBBBB-------- ---------BBBBBEEBBBBB-------- ---------BBBBB--BBBBB-------- ---------BBBBB--BBBBB-------- ---------BBBBB--BBBBB-------- ---------BBBBB--BBBBB-------- ---------BBBBB--BBBBB-------- ---------BBBBB--BBBBB-------- --------BBBBBBBBBBBBBB------- --------BBBBBBBBBBBBBB------- --------BBBBBBBBBBBBBB------- ------------EEEEE------------ -----------E--EEE------------ ----------------------------- 
---------BBBBBEEBBBBB-------- ---------BBBBBEEBBBBB-------- ---------BBBBBEEBBBBB-------- ---------BBBBBEEBBBBB-------- ---------BBBBB--BBBBB-------- ---------BBBBB--BBBBB-------- ---------BBBBB--BBBBB-------- ---------BBBBB--BBBBB-------- ---------BBBBB--BBBBB-------- ---------BBBBB--BBBBB-------- --------BBBBBBBBBBBBBB------- --------BBBBBBBBBBBBBB------- --------BBBBBBBBBBBBBB------- ------------EEEEE------------ -----------EE-EEE------------ ----------E------------------ 
---------BBBBBEEBBBBB-------- ---------BBBBBEEBBBBB-------- ---------BBBBBEEBBBBB-------- ---------BBBBBEEBBBBB-------- ---------BBBBB--BBBBB-------- ---------BBBBB--BBBBB-------- ---------BBBBB--BBBBB-------- ---------BBBBB--BBBBB-------- ---------BBBBB--BBBBB-------- ---------BBBBB--BBBBB-------- --------BBBBBBBBBBBBBB------- --------BBBBBBBBBBBBBB------- --------BBBBBBBBBBBBBB------- --------------EEEE----------- -----------EE-EEEE----------- ----------E------------------ 
---------BBBBBEEBBBBB-------- ---------BBBBBEEBBBBH-------- ---------BBBBBEEBBBBB-------- ---------BBBBBEEBBBBB-------- ---------HBBBB--BBBBB-------- ---------BBBBB--BBBBB-------- ---------BBBBB--BBBBH-------- ---------BBBBB--BBBBB-------- ---------BBBBB--BBBBB-------- ---------BBBBB--BBBBB-------- --------BBBBBBBBBBBBBB------- --------BBBBBBBBBBBBBB------- --------HBBBBBBBBBBBBB------- --------------EE------------- --------------EE------------- -----------E----------------- 
---------BBBBBEEBBBBH-------- ---------BBBBBEEBBBBH-------- ---------BBBBBEEBBBBB-------- ---------BBBBBEEBBBBB-------- ---------BBBBBEEBBBBB-------- ---------BBBBBEEBBBBB-------- ---------BBBBBEEBBBBB-------- ---------BBBBBEEBBBBB-------- ---------BBBBBEEBBBBB-------- ---------BBBBBEEBBBBB-------- --------BBBBBBEEBBBBBB------- --------BBBBBBEEBBBBBB------- --------HBBBBBEEBBBBBB------- ----------------------------- ----------------------------- ----------------------------- 
----------------------------- ----------------------------- ----------------------------- ----------------------------- ----------------------------- ----------------------------- ----------------------------- ----------------------------- ----------------------------- ----------------------------- --------BBBBBBEEBBBBBB------- --------BBBBBBEEBBBBBB------- --------BBBBBBEEBBBBBB------- ----------------------------- ----------------------------- ----------------------------- 
