model
size = 26 31 27, scale = 0.05, origin = -y
material 
  colors = A:#06C B:#EEE
voxels
-------------------------- -------------------------- -------------------------- -------------------------- -------------------------- -------------------------- -------------------------- -------------------------- -------------------------- -------------------------- -------------------------- -------------------------- -------------------------- -------------------------- -------------------------- -------------------------- -------------------------- -------------------------- -------------------------- -------------------------- -------------------------- -------------------------- -------------------------- -------------------------- -------------------------- -------------------------- -------------------------- -------------------------- -------------------------- -------------------------- -----------------B-------- 
-------------------------- -------------------------- -------------------------- -------------------------- -------------------------- -------------------------- -----------BBBB----------- -----------BBBB----------- -----------BBBB----------- -----------BBBB----------- -----------BBBB----------- -----------BBBB----------- -----------BBBB----------- -----------BBBB----------- -----------BBBB----------- -----------BBBB----------- -----------BBBB----------- -----------BBBB----------- -----------BBBB----------- -----------BBBB----------- AAAAAAAAAAABBBBAAAAAAAAAAA AAAAAAAAAAABBBBAAAAAAAAAAA AAAAAAAAAAABBBBAAAAAAAAAAA AAAAAAAAAAABBBBAAAAAAAAAAA AAAAAAAAAAABBBBAAAAAAAAAAA AAAAAAAAAAABBBBAAAAAAAAAAA -------------------------- -------------------------- -------------------------- ----------------BBB------- ----------------BBBBB----- 
-----------BBBB----------- -----------BBBB----------- -----------BBBB----------- -----------BBBB----------- -----------BBBB----------- -----------BBBB----------- -----------BBBB----------- -AAAAAAAAAABBBBAAAAAAAAAA- -AAAAAAAAAABBBBAAAAAAAAAA- -AAAAAAAAAABBBBAAAAAAAAAA- -AAAAAAAAAABBBBAAAAAAAAAA- -AAAAAAAAAABBBBAAAAAAAAAA- -AAAAAAAAAABBBBAAAAAAAAAA- -AAAAAAAAAABBBBAAAAAAAAAA- -AAAAAAAAAABBBBAAAAAAAAAA- -AAAAAAAAAABBBBAAAAAAAAAA- -AAAAAAAAAABBBBAAAAAAAAAA- -AAAAAAAAAABBBBAAAAAAAAAA- -AAAAAAAAAABBBBAAAAAAAAAA- -AAAAAAAAAABBBBAAAAAAAAAA- AAAAAAAAAAABBBBAAAAAAAAAAA A------------------------A A------------------------A A------------------------A A------------------------A AAAAAAAAAAABBBBAAAAAAAAAAA -------------------------- -------------------------- -------------------------- ---------------BBBBBB----- -----------------BBBB----- 
--AAAAAAAAAAAAAAAAAAAAAA-- --AAAAAAAAAAAAAAAAAAAAAA-- --AAAAAAAAAAAAAAAAAAAAAA-- --AAAAAAAAAAAAAAAAAAAAAA-- --AAAAAAAAAAAAAAAAAAAAAA-- --AAAAAAAAAAAAAAAAAAAAAA-- --AAAAAAAAAAAAAAAAAAAAAAA- -AAAAAAAAAAAAAAAAAAAAAAAA- -A----------------------A- -A----------------------A- -A----------------------A- -A----------------------A- -A----------------------A- -A----------------------A- -A----------------------A- -A----------------------A- -A----------------------A- -A----------------------A- -A----------------------A- -A----------------------A- AA-----------------------A A------------------------A A------------------------A A------------------------A A------------------------A AAAAAAAAAAABBBBAAAAAAAAAAA -------------------------- -------------------------- ---------------BBBB------- ---------------BBBBBB----- -----BB-------------B----- 
--AAAAAAAAAAAAAAAAAAAAAA-- --A--------------------A-- --A--------------------A-- --A--------------------A-- --A--------------------A-- --A--------------------A-- --A--------------------AA- -AA---------------------A- -A----------------------A- -A----------------------A- -A----------------------A- -A----------------------A- -A----------------------A- -A----------------------A- -A----------------------A- -A----------------------A- -A----------------------A- -A----------------------A- -A----------------------A- -A----------------------A- AA-----------------------A A------------------------A A------------------------A A------------------------A A------------------------A AAAAAAAAAAABBBBAAAAAAAAAAA -------------------------- -------------------------- --------------BBBBBB------ -----BBB---------BBB------ ---BBBB------------------- 
--AAAAAAAAAAAAAAAAAAAAAA-- --A--------------------A-- --A--------------------A-- --A--------------------A-- --A--------------------A-- --A--------------------A-- --A--------------------AA- -AA---------------------A- -A----------------------A- -A----------------------A- -A----------------------A- -A----------------------A- -A----------------------A- -A----------------------A- -A----------------------A- -A----------------------A- -A----------------------A- -A----------------------A- -A----------------------A- -A----------------------A- AA-----------------------A A------------------------A A------------------------A A------------------------A A------------------------A AAAAAAAAAAABBBBAAAAAAAAAAA --------------BBBB-------- --------------BBBBB------- ------BBB-----BBBBBB------ ---BBBBB-----------B------ --BBBB-------------------- 
--AAAAAAAAAAAAAAAAAAAAAA-- --A--------------------A-- --A--------------------A-- --A--------------------A-- --A--------------------A-- --A--------------------A-- --A--------------------AA- -AA---------------------A- -A----------------------A- -A----------------------A- -A----------------------A- -A----------------------A- -A----------------------A- -A----------------------A- -A----------------------A- -A----------------------A- -A----------------------A- -A----------------------A- -A----------------------A- -A----------------------A- AA-----------------------A A------------------------A A------------------------A A------------------------A A------------------------A AAAAAAAAAAABBBBAAAAAAAAAAA ---------B----BBBBB------- --------BB----BBBBB------- ----BBBBBB------BBB------- --BBBBB------------------- --BB---------------------- 
--AAAAAAAAAAAAAAAAAAAAAA-- --A--------------------A-- --A--------------------A-- --A--------------------A-- --A--------------------A-- --A--------------------A-- --A--------------------AA- -AA---------------------A- -A----------------------A- -A----------------------A- -A----------------------A- -A----------------------A- -A----------------------A- -A----------------------A- -A----------------------A- -A----------------------A- -A----------------------A- -A----------------------A- -A----------------------A- -A----------------------A- AA-----------------------A A------------------------A A------------------------A A------------------------A A------------------------A AAAAAAAAAAABBBBAAAAAAAAAAA ------BBBB----BBBBB------- ------BBBB----BBBBB------- ----BBBBB---------B------- ---BB--------------------- -------------------------- 
--AAAAAAAAAAAAAAAAAAAAAA-- --A--------------------A-- --A--------------------A-- --A--------------------A-- --A--------------------A-- --A--------------------A-- --A--------------------AA- -AA---------------------A- -A----------------------A- -A----------------------A- -A----------------------A- -A----------------------A- -A----------------------A- -A----------------------A- -A----------------------A- -A----------------------A- -A----------------------A- -A----------------------A- -A----------------------A- -A----------------------A- AA-----------------------A A------------------------A A------------------------A A------------------------A A------------------------A AAAAAAAAAAABBBBAAAAAAAAAAA -----BBBBBB---BBBB-BBB---- -----BBBBBB---BBBB-BBB---- ----BBBB-----------BBB---- -------------------BB----- -------------------------- 
--AAAAAAAAAAAAAAAAAAAAAA-- --A--------------------A-- --A--------------------A-- --A--------------------A-- --A--------------------A-- --A--------------------A-- --A--------------------AA- -AA---------------------A- -A----------------------A- -A----------------------A- -A----------------------A- -A----------------------A- -A----------------------A- -A----------------------A- -A----------------------A- -A----------------------A- -A----------------------A- -A----------------------A- -A----------------------A- -A----------------------A- AA-----------------------A A------------------------A A------------------------A A------------------------A A------------------------A AAAAAAAAAAABBBBAAAAAAAAAAA -----BBBBBB---BBBBBBBB---- -----BBBBBB---BBBBBBBB---- -----------------BBBBB---- ------------------BBBB---- -------------------------- 
--AAAAAAAAAAAAAAAAAAAAAA-- --A--------------------A-- --A--------------------A-- --A--------------------A-- --A--------------------A-- --A--------------------A-- --A--------------------AA- -AA---------------------A- -A----------------------A- -A----------------------A- -A----------------------A- -A----------------------A- -A----------------------A- -A----------------------A- -A----------------------A- -A----------------------A- -A----------------------A- -A----------------------A- -A----------------------A- -A----------------------A- AA-----------------------A A------------------------A A------------------------A A------------------------A A------------------------A AAAAAAAAAAABBBBAAAAAAAAAAA ------BBBBB--BBBBBBBBBB--- ------BBBBB--B-BBBBBBBB--- ---------------BBBBBBBB--- -----------------BBBBB---- -------------------------- 
--AAAAAAAAAAAAAAAAAAAAAA-- --A--------------------A-- --A--------------------A-- --A--------------------A-- --A--------------------A-- --A--------------------A-- --A--------------------AA- -AA---------------------A- -A----------------------A- -A----------------------A- -A----------------------A- -A----------------------A- -A----------------------A- -A----------------------A- -A----------------------A- -A----------------------A- -A----------------------A- -A----------------------A- -A----------------------A- -A----------------------A- AA-----------------------A A------------------------A A------------------------A A------------------------A A------------------------A AAAAAAAAAAABBBBAAAAAAAAAAA ---BBBBBBBBBBBBBBBBBBBB--- ---BBBBBB--BBBBBBBBBBBB--- ---BBBBBB-----BBBBBBBBB--- ----BBB---------BBBBBB---- -------------------------- 
-BAAAAAAAAAAAAAAAAAAAAAAB- -BA--------------------AB- -BA--------------------AB- -BA--------------------AB- -BA--------------------AB- -BA--------------------ABB BBA--------------------ABB BBA---------------------BB BB----------------------BB BB----------------------BB BB----------------------BB BB----------------------BB BB----------------------BB BB----------------------BB BB----------------------BB BB----------------------BB BB----------------------BB BB----------------------BB BB----------------------BB BB----------------------BB BB-----------------------B B------------------------B B------------------------B B------------------------B B------------------------B BBBBBBBBBBBBBBBBBBBBBBBBBB --BBBBBBBBBBBBBBBBBBBBB--- --BBBBBBBBBBBBBBBBBBBBB--- --BBBBBBBBB---BBBBBBBBB--- ---BBBBB--------BBBBBBB--- -------------------------- 
-BAAAAAAAAAAAAAAAAAAAAAAB- -BA--------------------AB- -BA--------------------AB- -BA--------------------AB- -BA--------------------AB- -BA--------------------ABB BBA--------------------ABB BBA---------------------BB BB----------------------BB BB----------------------BB BB----------------------BB BB----------------------BB BB----------------------BB BB----------------------BB BB----------------------BB BB----------------------BB BB----------------------BB BB----------------------BB BB----------------------BB BB----------------------BB BB-----------------------B B------------------------B B------------------------B B------------------------B B------------------------B BBBBBBBBBBBBBBBBBBBBBBBBBB --BBBBBBBBBBBBBBBBBBBBB--- ---BBBBBBBBBBBBBBBBBBBB--- --BBBBBBBBB----BBBBBBBB--- ---BBBBB--------BBBBBBB--- -------------------------- 
-BAAAAAAAAAAAAAAAAAAAAAAB- -BA--------------------AB- -BA--------------------AB- -BA--------------------AB- -BA--------------------AB- -BA--------------------ABB BBA--------------------ABB BBA---------------------BB BB----------------------BB BB----------------------BB BB----------------------BB BB----------------------BB BB----------------------BB BB----------------------BB BB----------------------BB BB----------------------BB BB----------------------BB BB----------------------BB BB----------------------BB BB----------------------BB BB-----------------------B B------------------------B B------------------------B B------------------------B B------------------------B BBBBBBBBBBBBBBBBBBBBBBBBBB --BBBBBBBBBBBBBBBBBBBBB--- --BBBBBBBBBBBBBBBBBBBBB--- --BBBBBBBBB----BBBBBBBBB-- ---BBBBBB--------BBBBBB--- -------------------------- 
-BAAAAAAAAAAAAAAAAAAAAAAB- -BA--------------------AB- -BA--------------------AB- -BA--------------------AB- -BA--------------------AB- -BA--------------------ABB BBA--------------------ABB BBA---------------------BB BB----------------------BB BB----------------------BB BB----------------------BB BB----------------------BB BB----------------------BB BB----------------------BB BB----------------------BB BB----------------------BB BB----------------------BB BB----------------------BB BB----------------------BB BB----------------------BB BB-----------------------B B------------------------B B------------------------B B------------------------B B------------------------B BBBBBBBBBBBBBBBBBBBBBBBBBB --BBBBBBBBBBB-BBBBBBBB---- --BBBBBBBBBBB-BBBBBBBB---- --BBBBBBBBBB---BBBBBBB---- ---BBBBBB---------BBB----- -------------------------- 
--AAAAAAAAAAAAAAAAAAAAAA-- --A--------------------A-- --A--------------------A-- --A--------------------A-- --A--------------------A-- --A--------------------A-- --A--------------------AA- -AA---------------------A- -A----------------------A- -A----------------------A- -A----------------------A- -A----------------------A- -A----------------------A- -A----------------------A- -A----------------------A- -A----------------------A- -A----------------------A- -A----------------------A- -A----------------------A- -A----------------------A- AA-----------------------A A------------------------A A------------------------A A------------------------A A------------------------A AAAAAAAAAAABBBBAAAAAAAAAAA ---BBBBBBBBB---BBBBBB----- ---BBBBBBBBB---BBBBBB----- ---BBBBBBBBB---BBBBBB----- ----BBBBB----------------- -------------------------- 
--AAAAAAAAAAAAAAAAAAAAAA-- --A--------------------A-- --A--------------------A-- --A--------------------A-- --A--------------------A-- --A--------------------A-- --A--------------------AA- -AA---------------------A- -A----------------------A- -A----------------------A- -A----------------------A- -A----------------------A- -A----------------------A- -A----------------------A- -A----------------------A- -A----------------------A- -A----------------------A- -A----------------------A- -A----------------------A- -A----------------------A- AA-----------------------A A------------------------A A------------------------A A------------------------A A------------------------A AAAAAAAAAAABBBBAAAAAAAAAAA ----BBBB--------BBB------- ---BBBBBB-------BBBB------ ---BBBBBBB------BBBB------ ----BBBB------------------ -------------------------- 
--AAAAAAAAAAAAAAAAAAAAAA-- --A--------------------A-- --A--------------------A-- --A--------------------A-- --A--------------------A-- --A--------------------A-- --A--------------------AA- -AA---------------------A- -A----------------------A- -A----------------------A- -A----------------------A- -A----------------------A- -A----------------------A- -A----------------------A- -A----------------------A- -A----------------------A- -A----------------------A- -A----------------------A- -A----------------------A- -A----------------------A- AA-----------------------A A------------------------A A------------------------A A------------------------A A------------------------A AAAAAAAAAAABBBBAAAAAAAAAAA ----BB-------------------- ---BBB-------------------- ----BB-------------------- -------------------------- -------------------------- 
--AAAAAAAAAAAAAAAAAAAAAA-- --A--------------------A-- --A--------------------A-- --A--------------------A-- --A--------------------A-- --A--------------------A-- --A--------------------AA- -AA---------------------A- -A----------------------A- -A----------------------A- -A----------------------A- -A----------------------A- -A----------------------A- -A----------------------A- -A----------------------A- -A----------------------A- -A----------------------A- -A----------------------A- -A----------------------A- -A----------------------A- AA-----------------------A A------------------------A A------------------------A A------------------------A A------------------------A AAAAAAAAAAABBBBAAAAAAAAAAA -------------------------- -------------------------- -------------------------- -------------------------- -------------------------- 
--AAAAAAAAAAAAAAAAAAAAAA-- --A--------------------A-- --A--------------------A-- --A--------------------A-- --A--------------------A-- --A--------------------A-- --A--------------------AA- -AA---------------------A- -A----------------------A- -A----------------------A- -A----------------------A- -A----------------------A- -A----------------------A- -A----------------------A- -A----------------------A- -A----------------------A- -A----------------------A- -A----------------------A- -A----------------------A- -A----------------------A- AA-----------------------A A------------------------A A------------------------A A------------------------A A------------------------A AAAAAAAAAAABBBBAAAAAAAAAAA -------------------------- -------------------------- -------------------------- -------------------------- -------------------------- 
--AAAAAAAAAAAAAAAAAAAAAA-- --A--------------------A-- --A--------------------A-- --A--------------------A-- --A--------------------A-- --A--------------------A-- --A--------------------AA- -AA---------------------A- -A----------------------A- -A----------------------A- -A----------------------A- -A----------------------A- -A----------------------A- -A----------------------A- -A----------------------A- -A----------------------A- -A----------------------A- -A----------------------A- -A----------------------A- -A----------------------A- AA-----------------------A A------------------------A A------------------------A A------------------------A A------------------------A AAAAAAAAAAABBBBAAAAAAAAAAA -------------------------- -------------------------- -------------------------- -------------------------- -------------------------- 
--AAAAAAAAAAAAAAAAAAAAAA-- --A--------------------A-- --A--------------------A-- --A--------------------A-- --A--------------------A-- --A--------------------A-- --A--------------------AA- -AA---------------------A- -A----------------------A- -A----------------------A- -A----------------------A- -A----------------------A- -A----------------------A- -A----------------------A- -A----------------------A- -A----------------------A- -A----------------------A- -A----------------------A- -A----------------------A- -A----------------------A- AAAAAAAAAAAAAAAAAAAAAAAAAA AAAAAAAAAAAAAAAAAAAAAAAAAA AAAAAAAAAAAAAAAAAAAAAAAAAA AAAAAAAAAAAAAAAAAAAAAAAAAA AAAAAAAAAAAAAAAAAAAAAAAAAA AAAAAAAAAAABBBBAAAAAAAAAAA -------------------------- -------------------------- -------------------------- -------------------------- -------------------------- 
--AAAAAAAAAAAAAAAAAAAAAA-- --A--------------------A-- --A--------------------A-- --A--------------------A-- --A--------------------A-- --A--------------------A-- --A--------------------AA- -AA---------------------A- -A----------------------A- -A----------------------A- -A----------------------A- -A----------------------A- -A----------------------A- -A----------------------A- -A----------------------A- -A----------------------A- -A----------------------A- -A----------------------A- -A----------------------A- -A----------------------A- AAAAAAAAAAAAAAAAAAAAAAAAAA AAAAAAAAAAAAAAAAAAAAAAAAAA AAAAAAAAAAAAAAAAAAAAAAAAAA AAAAAAAAAAAAAAAAAAAAAAAAAA AAAAAAAAAAAAAAAAAAAAAAAAAA AAAAAAAAAAABBBBAAAAAAAAAAA -------------------------- -------------------------- -------------------------- -------------------------- -------------------------- 
--AAAAAAAAAAAAAAAAAAAAAA-- --AAAAAAAAAAAAAAAAAAAAAA-- --AAAAAAAAAAAAAAAAAAAAAA-- --AAAAAAAAAAAAAAAAAAAAAA-- --AAAAAAAAAAAAAAAAAAAAAA-- --AAAAAAAAAAAAAAAAAAAAAA-- --AAAAAAAAAAAAAAAAAAAAAAA- -AA---------------------A- -A----------------------A- -A----------------------A- -A----------------------A- -A----------------------A- -A----------------------A- -A----------------------A- -A----------------------A- -A----------------------A- -A----------------------A- -A----------------------A- -A----------------------A- -A----------------------A- AAAAAAAAAAAAAAAAAAAAAAAAAA AAAAAAAAAAAAAAAAAAAAAAAAAA AAAAAAAAAAAAAAAAAAAAAAAAAA AAAAAAAAAAAAAAAAAAAAAAAAAA AAAAAAAAAAAAAAAAAAAAAAAAAA AAAAAAAAAAABBBBAAAAAAAAAAA -------------------------- -------------------------- -------------------------- -------------------------- -------------------------- 
-----------BBBB----------- -----------BBBB----------- -----------BBBB----------- -----------BBBB----------- -----------BBBB----------- -----------BBBB----------- --AAAAAAAAABBBBAAAAAAAAAA- -AAAAAAAAAABBBBAAAAAAAAAA- -AAAAAAAAAABBBBAAAAAAAAAA- -AAAAAAAAAABBBBAAAAAAAAAA- -AAAAAAAAAABBBBAAAAAAAAAA- -AAAAAAAAAABBBBAAAAAAAAAA- -AAAAAAAAAABBBBAAAAAAAAAA- -AAAAAAAAAABBBBAAAAAAAAAA- -AAAAAAAAAABBBBAAAAAAAAAA- -AAAAAAAAAABBBBAAAAAAAAAA- -AAAAAAAAAABBBBAAAAAAAAAA- -AAAAAAAAAABBBBAAAAAAAAAA- -AAAAAAAAAABBBBAAAAAAAAAA- -AAAAAAAAAABBBBAAAAAAAAAA- AAAAAAAAAAABBBBAAAAAAAAAAA AAAAAAAAAAABBBBAAAAAAAAAAA AAAAAAAAAAABBBBAAAAAAAAAAA AAAAAAAAAAABBBBAAAAAAAAAAA AAAAAAAAAAABBBBAAAAAAAAAAA AAAAAAAAAAABBBBAAAAAAAAAAA -------------------------- -------------------------- -------------------------- -------------------------- -------------------------- 
-------------------------- -------------------------- -------------------------- -------------------------- -------------------------- -----------BBBB----------- -----------BBBB----------- -----------BBBB----------- -----------BBBB----------- -----------BBBB----------- -----------BBBB----------- -----------BBBB----------- -----------BBBB----------- -----------BBBB----------- -----------BBBB----------- -----------BBBB----------- -----------BBBB----------- -----------BBBB----------- -----------BBBB----------- -----------BBBB----------- AAAAAAAAAAABBBBAAAAAAAAAAA AAAAAAAAAAABBBBAAAAAAAAAAA AAAAAAAAAAABBBBAAAAAAAAAAA AAAAAAAAAAABBBBAAAAAAAAAAA AAAAAAAAAAABBBBAAAAAAAAAAA AAAAAAAAAAABBBBAAAAAAAAAAA -------------------------- -------------------------- -------------------------- -------------------------- -------------------------- 
