model
size = 29 28 27, scale = 0.05, origin = -y
material 
  colors = A:#900 B:#C30 C:#050 D:#080 E:#CF3 F:#0B0 G:#EEE H:#630 I:#CC6 J:#CC9 K:#CF0 L:#C60 M:#F96 N:#F9F O:#F33 P:#F99 Q:#F36 R:#FCF S:#F6F T:#F0C U:#FC6 V:#FC3 W:#FF6 X:#F0F Y:#FFF Z:#CFC Aa:#F9C Ab:#F06 Ac:#CC3 Ad:#F03 Ae:#F3F Af:#F90 Ag:#CFF Ah:#CCF Ai:#F60 Aj:#F69 Ak:#F66 Al:#F6C Am:#F09 An:#CCC Ao:#F3C Ap:#FF9 Aq:#CC0 Ar:#CF6
voxels
- - - - - - - - - - - - - - - - - - - - - - - - - - - - -   - - - - - - - - - - - - - - - - - - - - - - - - - - - - -   - - - - - - - - - - - - - - - - - - - - - - - - - - - - -   - - - - - - - - - - - - - - - - - - - - - - - - - - - - -   - - - - - - - - - - - - - - - - - - - - - - - - - - - - -   - - - - - - - - - - - A A A A A A - - - - - - - - - - - -   - - - - - - - - - - - A A A A A A - - - - - - - - - - - -   - - - - - - - - - - - A A A E A A - - - - - - - - - - - -   - - - - - - - - - - - - A A A A A - - - - - - - - - - - -   - - - - - - - - - - - - - - - - - - - - - - - - - - - - -   - - - - - - - - - - - - - - - - - - - - - - - - - - - - -   - - - - - - - - - - - - - - - - - - - - - - - - - - - - -   - - - - - - - - - - - - - - - - - - - - - - - - - - - - -   - - - - - - - - - - - - - - - - - - - - - - - - - - - - -   - - - - - - - - - - - - - - - - - - - - - - - - - - - - -   - - - - - - - - - - - - - - - - - - - - - - - - - - - - -   - - - - - - - - - - - - - - - - - - - - - - - - - - - - -   - - - - - - - - - - - - - - - - - - - - - - - - - - - - -   - - - - - - - - - - - - - - - - - - - - - - - - - - - - -   - - - - - - - - - - - - - - - - - - - - - - - - - - - - -   - - - - - - - - - - - - - - - - - - - - - - - - - - - - -   - - - - - - - - - - - - - - - - - - - - - - - - - - - - -   - - - - - - - - - - - - - - - - - - - - - - - - - - - - -   - - - - - - - - - - - - - - - - - - - - - - - - - - - - -   - - - - - - - - - - - - - - - - - - - - - - - - - - - - -   - - - - - - - - - - - - - - - - - - - - - - - - - - - - -   - - - - - - - - - - - - - - - - - - - - - - - - - - - - -   - - - - - - - - - - - - - - - - - - - - - - - - - - - - -   
- - - - - - - - - - - - - - - - - - - - - - - - - - - - -   - - - - - - - - - - - - - - - - - - - - - - - - - - - - -   - - - - - - - - - - - - - - - - - - - - - - - - - - - - -   - - - - - - - - - - - - - - - - - - - - - - - - - - - - -   - - - - - - - - - A A A A A A A A A A - - - - - - - - - -   - - - - - - - - - A A A A A A A A A A A - - - - - - - - -   - - - - - - - - - A A A - - - - - A A A - - - - - - - - -   - - - - - - - - - A A A - A A - - A A A - - - - - - - - -   - - - - - - - - - A A J A I A A A A A - - - - - - - - - -   - - - - - - - - - - A A A A A A A A - - - - - - - - - - -   - - - - - - - - - - - - - - - - - - - - - - - - - - - - -   - - - - - - - - - - - - - - - - - - - - - - - - - - - - -   - - - - - - - - - - - - - - - - - - - - - - - - - - - - -   - - - - - - - - - - - - - - - - - - - - - - - - - - - - -   - - - - - - - - - - - - - - - - - - - - - - - - - - - - -   - - - - - - - - - - - - - - - - - - - - - - - - - - - - -   - - - - - - - - - - - - - - - - - - - - - - - - - - - - -   - - - - - - - - - - - - - - - - - - - - - - - - - - - - -   - - - - - - - - - - - - - - - - - - - - - - - - - - - - -   - - - - - - - - - - - - - - - - - - - - - - - - - - - - -   - - - - - - - - - - - - - - - - - - - - - - - - - - - - -   - - - - - - - - - - - - - - - - - - - - - - - - - - - - -   - - - - - - - - - - - - - - - - - - - - - - - - - - - - -   - - - - - - - - - - - - - - - - - - - - - - - - - - - - -   - - - - - - - - - - - - - - - - - - - - - - - - - - - - -   - - - - - - - - - - - - - - - - - - - - - - - - - - - - -   - - - - - - - - - - - - - - - - - - - - - - - - - - - - -   - - - - - - - - - - - - - - - - - - - - - - - - - - - - -   
- - - - - - - - - - - - - - - - - - - - Z - - - - - - - -   - - - - - - - - - - - - - - - - - - - - - - - - - - - - -   - - - - - - - - - - - - - - - - - - - - O - - - - - - - -   - - - - - - - - - - - - - - - - - - - - - - - - - - - - -   - - - - - - - - A A A A A A A A A A A A A - - - - - - - -   - - - - - - - A A A - - - - - - - - A A A - - - - - - - -   - - - - - - - A A - - - - - - - - - - A A - - - - - - - -   - - - - - - - A A - A A L A A A A A - A A - - - - - - - -   - - - - - - - - A A A - A A A A - A E A A - - - - - - - -   - - - - - - - - A A A A L A A A A A A A - - - - - - - - -   - - - - - - - - - - - - - - - - - - - - - - - - - - - - -   - - - - - - - - - - - - - - - - - - - - - - - - - - - - -   - - - - - - - - - - - - - - - - - - - - - - - - - - - - -   - - - - - - - - - - - - - - - - - - - - - - - - - - - - -   - - - - - - - - - - - - - - - - - - - - - - - - - - - - -   - - - - - - - - - - - - - - - - - - - - - - - - - - - - -   - - - - - - - - - - - - - - - - - - - - - - - - - - - - -   - - - - - - - - - - - - - - - - - - - - - - - - - - - - -   - - - - - - - - - - - - - - - - - - - - - - - - - - - - -   - - - - - - - - - - - - - - - - - - - - - - - - - - - - -   - - - - - - - - - - - - - - - - - - - - - - - - - - - - -   - - - - - - - - - - - - - - - - - - - - - - - - - - - - -   - - - - - - - - - - - - - - - - - - - - - - - - - - - - -   - - - - - - - - - - - - - - - - - - - - - - - - - - - - -   - - - - - - - - - - - - - - - - - - - - - - - - - - - - -   - - - - - - - - - - - - - - - - - - - - - - - - - - - - -   - - - - - - - - - - - - - - - - - - - - - - - - - - - - -   - - - - - - - - - - - - - - - - - - - - - - - - - - - - -   
- - - - - - - - - - - - - - - - - - - - - - - - - - - - -   - - - - - - - Aj- - - - - - - - - - - O - - - - - - - - -   - - - - - - - - - - - - - - - - - - - - - - - - - - - - -   - - - - - - - - - R - - - - - - - - - - Ar- - - - - - - -   - - - - - - - A A A A A A A A A A A A A A - - - - - - - -   - - - - - - A A A - - - - A A - - - - - A A - - - - - - -   - - - - - - A A - - - - - - - - - - - - - A - - - - - - -   - - - - - - A A A A A A A A A A A A A A - A - - - - - - -   - - - - - - A A E A A I A J A A A A A A A A - - - - - - -   - - - - - - - A A A A A A A A A A A A J A - - - - - - - -   - - - - - - - - - - - - D C C B - - - - - - - - - - - - -   - - - - - - - - - - - - - - - - - - - - - - - - - - - - -   - - - - - - - - - - - - - - - - - - - - - - - - - - - - -   - - - - - - - - - - - - - - - - - - - - - - - - - - - - -   - - - - - - - - - - - - - - - - - - - - - - - - - - - - -   - - - - - - - - - - - - - - - - - - - - - - - - - - - - -   - - - - - - - - - - - - - - - - - - - - - - - - - - - - -   - - - - - - - - - - - - - - - - - - - - - - - - - - - - -   - - - - - - - - - - - - - - - - - - - - - - - - - - - - -   - - - - - - - - - - - - - - - - - - - - - - - - - - - - -   - - - - - - - - - - - - - - - - - - - - - - - - - - - - -   - - - - - - - - - - - - - - - - - - - - - - - - - - - - -   - - - - - - - - - - - - - - - - - - - - - - - - - - - - -   - - - - - - - - - - - - - - - - - - - - - - - - - - - - -   - - - - - - - - - - - - - - - - - - - - - - - - - - - - -   - - - - - - - - - - - - - - - - - - - - - - - - - - - - -   - - - - - - - - - - - - - - - - - - - - - - - - - - - - -   - - - - - - - - - - - - - - - - - - - - - - - - - - - - -   
- - - - - - - M - - - - - - - - - - - - - - - - - - - - -   - - - - - - - - - - - - - - - - - - - - - - Y - - - - - -   - - - - - - - Z P - - - - - - - - - - - - - - - - - - - -   - - - - - - T - - - - - - - - - - - - - - - Aq- - - - - -   - - - - - A A A A A A - - - - - - A A A A A A A - - - - -   - - - - - A A - - A A - - - - - - A A A - - A A - - - - -   - - - - - A - - - A A A - - - - - A A A - - A A - - - - -   - - - - - J - I A A E A A A E A A A A A K - A A - - - - -   - - - - - A A - A A A A A C A A A A A A - A A A - - - - -   - - - - - A A A - A E A A C E A A A A - A A A - - - - - -   - - - - - - - - - - B B F C C B B B - - - - - - - - - - -   - - - - - - - - - - - B C C C B B - - - - - - - - - - - -   - - - - - - - - - - - - C C C D - - - - - - - - - - - - -   - - - - - - - - - - - - - - - - - - - - - - - - - - - - -   - - - - - - - - - - - - - - - - - - - - - - - - - - - - -   - - - - - - - - - - - - - - - - - - - - - - - - - - - - -   - - - - - - - - - - - - - - - - - - - - - - - - - - - - -   - - - - - - - - - - - - - - - - - - - - - - - - - - - - -   - - - - - - - - - - - - - - - - - - - - - - - - - - - - -   - - - - - - - - - - - - - - - - - - - - - - - - - - - - -   - - - - - - - - - - - - - - - - - - - - - - - - - - - - -   - - - - - - - - - - - - - - - - - - - - - - - - - - - - -   - - - - - - - - - - - - - - - - - - - - - - - - - - - - -   - - - - - - - - - - - - - - - - - - - - - - - - - - - - -   - - - - - - - - - - - - - - - - - - - - - - - - - - - - -   - - - - - - - - - - - - - - - - - - - - - - - - - - - - -   - - - - - - - - - - - - - - - - - - - - - - - - - - - - -   - - - - - - - - - - - - - - - - - - - - - - - - - - - - -   
- - - - - - - - - - - - - - - - - - - - - - P - - - - - -   - - - - - - - - - - - - - - - - - - - - - - - - - - - - -   - - - - - - - - - - - - - - - - - - - - - - - N - - - - -   - - - Ac- M - - Ad- - - - - - - - - - - - - - - - - - - -   - - - - - A A A A - - - - - - - - - - A A A A A - - - - -   - - - - A A - - A - - - - - - - - - - A A - - A A - - - -   - - - - A - - - A A - - - - - - - - A A A - - A A - - - -   - - - - A - A A A A A A A A A A A A A A A A - A A - - - -   - - - - A A - A A A A A A A A A A A A A A - A A A - - - -   - - - - - A K A A A A A A A A A A A A I A J A A - - - - -   - - - - - - - - B B B B C C D B B B B B - - - - - - - - -   - - - - - - - - - B B B C C C B B B B - - - - - - - - - -   - - - - - - - - - - B D C C C C B B - - - - - - - - - - -   - - - - - - - - - - - B B B B B B - - - - - - - - - - - -   - - - - - - - - - - - - B B B B - - - - - - - - - - - - -   - - - - - - - - - - - - - - - - - - - - - - - - - - - - -   - - - - - - - - - - - - - - - - - - - - - - - - - - - - -   - - - - - - - - - - - - - - - - - - - - - - - - - - - - -   - - - - - - - - - - - - - - - - - - - - - - - - - - - - -   - - - - - - - - - - - - - - - - - - - - - - - - - - - - -   - - - - - - - - - - - - - - - - - - - - - - - - - - - - -   - - - - - - - - - - - - - - - - - - - - - - - - - - - - -   - - - - - - - - - - - - - - - - - - - - - - - - - - - - -   - - - - - - - - - - - - - - - - - - - - - - - - - - - - -   - - - - - - - - - - - - - - - - - - - - - - - - - - - - -   - - - - - - - - - - - - - - - - - - - - - - - - - - - - -   - - - - - - - - - - - - - - - - - - - - - - - - - - - - -   - - - - - - - - - - - - - - - - - - - - - - - - - - - - -   
- - - - - - - - - - - - - - - - - - - - - - - - - - - - -   - - Ac- - - - - - - - - - - - - - - - - - - - - - Ai- - -   - - - - - - - - - Aa- - - - - - - - - - - - - - - - - - -   - - - - Q - - - - - - - - - - - - - - - - - - - - R - - -   - - - - A A A A A - - - - - - - - - - - A A A A A - - - -   - - - A A - - A A - - - - - - - - - - - A - - A A - - - -   - - - A A - - A A - - - - - - - - - - - A - - - A - - - -   - - - A A I A J A A A A A A A A A A A A A A A - A - - - -   - - - - A - A A A A A A A A A A A A E A A A - A A - - - -   - - - - A A A A A A A A A A A A A A A A A A A A A - - - -   - - - - - - - B B B B B B B B B B B B B B - - - - - - - -   - - - - - - - - B B B B B B B B B B B B - - - - - - - - -   - - - - - - - - - B B C D D C C B B B - - - - - - - - - -   - - - - - - - - - B B B B B B B B B B - - - - - - - - - -   - - - - - - - - - - B B B B B B B B - - - - - - - - - - -   - - - - - - - - - - - B B B B B B - - - - - - - - - - - -   - - - - - - - - - - - - B B B B - - - - - - - - - - - - -   - - - - - - - - - - - - - - - - - - - - - - - - - - - - -   - - - - - - - - - - - - - - - - - - - - - - - - - - - - -   - - - - - - - - - - - - - - - - - - - - - - - - - - - - -   - - - - - - - - - - - - - - - - - - - - - - - - - - - - -   - - - - - - - - - - - - - - - - - - - - - - - - - - - - -   - - - - - - - - - - - - - - - - - - - - - - - - - - - - -   - - - - - - - - - - - - - - - - - - - - - - - - - - - - -   - - - - - - - - - - - - - - - - - - - - - - - - - - - - -   - - - - - - - - - - - - - - - - - - - - - - - - - - - - -   - - - - - - - - - - - - - - - - - - - - - - - - - - - - -   - - - - - - - - - - - - - - - - - - - - - - - - - - - - -   
- - Ab- - - - - - - - - - - - - - - - - - - - - - N - - -   - - - - - - - - - - - - - - - - - - - - - - - - - - - - -   - - - P - - - - - - - - - - - - - - - - - - - - - - M - -   - - - - - - - - - - - - - - - - - - - - - - - - - - - - -   - - - A A A A A - - - - - - - - - - - - - A A A A - - - -   - - - A A - A A - - - - - - - - - - - - - A - - A - - - -   - - - A - - A A - - - - - - - - - - - - - A - - - - - - -   - - - A A A A A A A A A A A A A A A A A A A A A - - - - -   - - - A E A A A E A A A A A A A A A A A A A A - A - - - -   - - - A A - A A A A A A A A A A A A A A A A A A A - - - -   - - - - - - B B B B B B B B B B B B B B B B - - - - - - -   - - - - - - - B B B B B B B B B B B B B B - - - - - - - -   - - - - - - - - B B B B B B B B B B B B - - - - - - - - -   - - - - - - - - B B B B B B B B B B B B - - - - - - - - -   - - - - - - - - - B B B B B B B B F C - - - - - - - - - -   - - - - - - - - - - B B B B B B B B - - - - - - - - - - -   - - - - - - - - - - - B B B B B B - - - - - - - - - - - -   - - - - - - - - - - - B B B B B B - - - - - - - - - - - -   - - - - - - - - - - - - - B B - - - - - - - - - - - - - -   - - - - - - - - - - - - - - - - - - - - - - - - - - - - -   - - - - - - - - - - - - - - - - - - - - - - - - - - - - -   - - - - - - - - - - - - - - - - - - - - - - - - - - - - -   - - - - - - - - - - - - - - - - - - - - - - - - - - - - -   - - - - - - - - - - - - - - - - - - - - - - - - - - - - -   - - - - - - - - - - - - - - - - - - - - - - - - - - - - -   - - - - - - - - - - - - - - - - - - - - - - - - - - - - -   - - - - - - - - - - - - - - - - - - - - - - - - - - - - -   - - - - - - - - - - - - - - - - - - - - - - - - - - - - -   
- - - - - - - - - - - - - - - - - - - - - - - - - - - - -   - - - - - - - - - - - - - - - - - - - - - - - - - - - - -   - - - - - - - - - - - - - - - - - - - - - - - - - - - - -   - - - - - - - - - - - - - - - - - - - - - - - - - - - - -   - - - A A A - - - - - - - - - - - - - - - - A A A A - - -   - - - A - A - - - - - - - - - - - - - - - - A - - A - - -   - - - - - A A - - - - - - - - - - - - - - A A - - A - - -   - - - - A A A A A A A A A A A A A A A A A A A A - A - - -   - - - A A A A A A A A A A A A A A A A A A A A A - A - - -   - - - A A A A A A A A A A A A A A A A A A A A - A - - - -   - - - - - - B B B B B B B B B B B B B B B B - - - - - - -   - - - - - - B B B B B B B B B B B B B B B B - - - - - - -   - - - - - - - B B B B B B B B B B B D C C - - - - - - - -   - - - - - - - C C D B B B B B B B B C C D - - - - - - - -   - - - - - - - - B B B B B B B B B C C C - - - - - - - - -   - - - - - - - - - B B B B B B B B B B - - - - - - - - - -   - - - - - - - - - B B B B B B B B B B - - - - - - - - - -   - - - - - - - - - - B B B B B B B B - - - - - - - - - - -   - - - - - - - - - - - B B B B B B - - - - - - - - - - - -   - - - - - - - - - - - - B B B B - - - - - - - - - - - - -   - - - - - - - - - - - - - B F - - - - - - - - - - - - - -   - - - - - - - - - - - - - - - - - - - - - - - - - - - - -   - - - - - - - - - - - - - - - - - - - - - - - - - - - - -   - - - - - - - - - - - - - - - - - - - - - - - - - - - - -   - - - - - - - - - - - - - - - - - - - - - - - - - - - - -   - - - - - - - - - - - - - - - - - - - - - - - - - - - - -   - - - - - - - - - - - - - - - - - - - - - - - - - - - - -   - - - - - - - - - - - - - - - - - - - - - - - - - - - - -   
- - - - - - - - - - - - - - - - - - - - - - - - - - - - -   - - - - - - - - - - - - - - - - - - - - - - - - - - - - -   - - - - - - - - - - - - - - - - - - - - - - - - - - - - -   - - - - - - - - - - - - - - - - - - - - - - - - - - - - -   - - - A A A - - - - - - - - - - - - - - - - A A A A - - -   - - - - - A - - - - - - - - - - - - - - - - A A - A - - -   - - - - - A - - - - - - - - - - - - - - - - A A - A - - -   - - - A A A A A A A A A A A A A A A A A A A A A A A - - -   - - - A A A A A A A A A A A A A A A A A A A A A - A - - -   - - - A A A A A A A A A A A A A A A A A A A A A A A - - -   - - - - - B B B B B B B B B B B B B B C B B B - - - - - -   - - - - - - D C C B B B B B B B B B B C B B - - - - - - -   - - - - - - C C D B B B B B B B B B F C C B - - - - - - -   - - - - - - - C C C B B B B B B B B C C C - - - - - - - -   - - - - - - - B B B B B B B B B B C C C C - - - - - - - -   - - - - - - - - B B B B B B B B B B B H - - - - - - - - -   - - - - - - - - - B B B B B B B B B B - - - - - - - - - -   - - - - - - - - - B B B B B B B B B B - - - - - - - - - -   - - - - - - - - - - B B B B B D C C - - - - - - - - - - -   - - - - - - - - - - - C C D B C C - - - - - - - - - - - -   - - - - - - - - - - - B B B C C C - - - - - - - - - - - -   - - - - - - - - - - - - B B B B - - - - - - - - - - - - -   - - - - - - - - - - - - - B B - - - - - - - - - - - - - -   - - - - - - - - - - - - - - - - - - - - - - - - - - - - -   - - - - - - - - - - - - - - - - - - - - - - - - - - - - -   - - - - - - - - - - - - - - - - - - - - - - - - - - - - -   - - - - - - - - - - - - - - - - - - - - - - - - - - - - -   - - - - - - - - - - - - - - - - - - - - - - - - - - - - -   
- - - - - - - - - - - - - - - - - - - - - - - - - - Ak- -   - - - - - - - - - - - - - - - - - - - - - - - - - - - - -   - - - - M - - - - - - - - - - - - - - - - - - - - - - - -   - - - W - - - - - - - - - - - - - - - - - - - - - - - - -   - - - A A - - - - - - - - - - - - - - - - - - A A A - - -   - A A - - A - - - - - - - - - - - - - - - - - A - A A - -   - A A - - A - - - - - - - - - - - - - - - - A A - A A - -   - A A A A A A A A A A A A A A A A A A A A A A A A A A - -   - - - - A A A A A A A A A A A A A A A A A A A A - A - - -   - - - A A A A C A A A A A A A A A A A A A A A A A A - - -   - - - - - B B C B B B B B B B B B B B B B B B - - - - - -   - - - - - B F C C B B B B B B B B B B B B B B - - - - - -   - - - - - - C C C B B B B B B B B B C C D B - - - - - - -   - - - - - - C C C D B B B B B B B B C C C B - - - - - - -   - - - - - - - H B B B B B B B B B D C C C - - - - - - - -   - - - - - - - B B B B B B B B B B B B B B - - - - - - - -   - - - - - - - - B B B B B B B B C B B B - - - - - - - - -   - - - - - - - - B B D C C B B B C B B B - - - - - - - - -   - - - - - - - - - B C C D B B F C C B - - - - - - - - - -   - - - - - - - - - - C C C C B C C C - - - - - - - - - - -   - - - - - - - - - - B B B B C C C C - - - - - - - - - - -   - - - - - - - - - - - B B B B B H - - - - - - - - - - - -   - - - - - - - - - - - - B B B B - - - - - - - - - - - - -   - - - - - - - - - - - - B B B B - - - - - - - - - - - - -   - - - - - - - - - - - - - B B - - - - - - - - - - - - - -   - - - - - - - - - - - - - - - - - - - - - - - - - - - - -   - - - - - - - - - - - - - - - - - - - - - - - - - - - - -   - - - - - - - - - - - - - - - - - - - - - - - - - - - - -   
- - - - - - - - - - - - - - - - - - - - - - - - - - - - -   - - - - - - - - - - - - - - - - - - - - - - - - - - Al- -   - - - - - - - - - - - - - - - - - - - - - - - - - - - - -   S - N - - Q - - - - - - - - - - - - - - - - - - U - - - -   - - - A A - - - - - - - - - - - - - - - - - - A A A - - -   - A A - - - - - - - - - - - - - - - - - - - - A - A A - -   - A - - - - - - - - - - - - - - - - - - - - - A - - A - -   - A - A A A A A A A A A A A A A A A A A A A A A A - A - -   - A A A A A A A A A A A A A A A A A A A A A A A A A - - -   - - - A A A A A A A A A A A A A A A A A A A A A - A - - -   - - - - B B B B B B B B B B B B B B B B B B B B - - - - -   - - - - - B C C D B B B B B B B B B B B B B B - - - - - -   - - - - - B C C C B B B B B B B B B B B B B B - - - - - -   - - - - - - C C C C B B B B B B B B B B B B - - - - - - -   - - - - - - B B B B B B B B B B B C D D C C - - - - - - -   - - - - - - - B B B B C B B B B B B B B B - - - - - - - -   - - - - - - - B B B B C B B B B B B B B B - - - - - - - -   - - - - - - - - B B F C C B B B B B B B - - - - - - - - -   - - - - - - - - - B C C C B B C C D B - - - - - - - - - -   - - - - - - - - - C C C C D B C C C B - - - - - - - - - -   - - - - - - - - - - B H B B D C C C - - - - - - - - - - -   - - - - - - - - - - B B B B B B B B - - - - - - - - - - -   - - - - - - - - - - - B B B B B B - - - - - - - - - - - -   - - - - - - - - - - - B B B B B B - - - - - - - - - - - -   - - - - - - - - - - - - B B B B - - - - - - - - - - - - -   - - - - - - - - - - - - - B B - - - - - - - - - - - - - -   - - - - - - - - - - - - - - - - - - - - - - - - - - - - -   - - - - - - - - - - - - - - - - - - - - - - - - - - - - -   
- - - V - - - - - - - - - - - - - - - - - - - - - - - - -   - - - - W - - - - - - - - - - - - - - - - - - - - - - - -   - - - - - - N - - - - - - - - - - - - - - - - - - - Am- -   - Ao- - - - - - - - - - - - - - - - - - - - - - - - - - -   - - - A A - - - - - - - - - - - - - - - - - - - A A A - -   - A A - - - - - - - - - - - - - - - - - - - - A A A A - -   - A - - - - - - - - - - - - - - - - - - - - - A - - A - -   - A A A A A A A A A A A A A A A A A A A A A A A A A A - -   - A A A A A A A A A A A A A A A A A A A A A A A A A A - -   - - - A A A A A A A A A A A A A A A A A A A A A A A - - -   - - - - B B B B B B B B B B B B B B B B B B B B - - - - -   - - - - - B B B B B B B B B B B B B B B B B B - - - - - -   - - - - - B B B B B B B B B B B B B B B B B B - - - - - -   - - - - - - D D C C B B B B B B B B B B B B - - - - - - -   - - - - - - B B B B B B B B B B B B B B B B - - - - - - -   - - - - - - - B B B B B B B B B B B B B B - - - - - - - -   - - - - - - - B B B B B B B B B B B B B B - - - - - - - -   - - - - - - - - B B C C D B B B B B B B - - - - - - - - -   - - - - - - - - B B C C C B B B B B B B - - - - - - - - -   - - - - - - - - - D C C C C B B B B B - - - - - - - - - -   - - - - - - - - - B B B B B C D D C C - - - - - - - - - -   - - - - - - - - - - B B B B B B B B - - - - - - - - - - -   - - - - - - - - - - B B B B B B B B - - - - - - - - - - -   - - - - - - - - - - - B B B B B B - - - - - - - - - - - -   - - - - - - - - - - - B D C C B B - - - - - - - - - - - -   - - - - - - - - - - - - C C D B - - - - - - - - - - - - -   - - - - - - - - - - - - - C C - - - - - - - - - - - - - -   - - - - - - - - - - - - - B B - - - - - - - - - - - - - -   
- - - - - - - - - - - - - - - - - - - - - - - - - - - - -   - - - - - - - - - - - - - - - - - - - - - - - - - - - - -   - - - T - - - - - - - - - - - - - - - - - - - - - - - - -   - - - - - - - - - - - - - - - - - - - - - - - - - - - - -   - - - A A - - - - - - - - - - - - - - - - - - - A A A - -   - E A - - - - - - - - - - - - - - - - - - - - A A A A - -   - A - - - - - - - - - - - - - - - - - - - - - A - - A - -   - E A A A E A A A A A A A A A A A A A A A A A A A A A - -   - A A A A A A A A A A A A A A A A A A A A A A A A A A - -   - - - A A A A A A A A A A A A A A A A A A A A A A A - - -   - - - - B B B B B B B B B B B B B B B B B B B B - - - - -   - - - - - B B B B B B B B B B B B B B B B B B - - - - - -   - - - - - B B B B B B B B B B B B B F C C C D - - - - - -   - - - - - - B B B B B B B B B B B B B B B B - - - - - - -   - - - - - - B B B B B B B B B B B B B B B B - - - - - - -   - - - - - - - B B B B B B B B B B B B B B - - - - - - - -   - - - - - - - B B B B B B B B B B B B B B - - - - - - - -   - - - - - - - - B B B B B B B B B B B B - - - - - - - - -   - - - - - - - - B B B B B B B B B B B B - - - - - - - - -   - - - - - - - - - C D D C C B B B B B - - - - - - - - - -   - - - - - - - - - B B B B B B B B B B - - - - - - - - - -   - - - - - - - - - - B B B B B B B B - - - - - - - - - - -   - - - - - - - - - - B B B C C C C D - - - - - - - - - - -   - - - - - - - - - - - B B C B B B - - - - - - - - - - - -   - - - - - - - - - - - B F C C B B - - - - - - - - - - - -   - - - - - - - - - - - - C C C B - - - - - - - - - - - - -   - - - - - - - - - - - - - C C - - - - - - - - - - - - - -   - - - - - - - - - - - - - H B - - - - - - - - - - - - - -   
- - - - - - - - - - - - - - - - - - - - - - - - - - - - -   - - - - - - - - - - - - - - - - - - - - - - - - - - - - -   - - - - - - - - - - - - - - - - - - - - - - - - - - - - -   - - - - S - - - - - - - - - - - - - - - - - - - - - - - -   - - - A A - - - - - - - - - - - - - - - - - - A A A - - -   - A A - - - - - - - - - - - - - - - - - - - - A A A A - -   - A - - - - - - - - - - - - - - - - - - - - - A - - A - -   - A - A A A A A A A A A A A A A A A A A A A A A A - A - -   - A A A A A A A A A A A A A A A A A A A A A A A A A A - -   - - - A A A A A A A A A A A A A A A A A A A A A - A - - -   - - - - B B B B B B B B B B B B B B B D C C B B - - - - -   - - - - - B B B B B B B B B B B B B B C C D B - - - - - -   - - - - - B B B B B B B B B B B B B C C C C C - - - - - -   - - - - - - B B B B B B B B B B B B B B B B - - - - - - -   - - - - - - B B B B B B B B B B B B B B B B - - - - - - -   - - - - - - - B B B B B B B B B B B B B B - - - - - - - -   - - - - - - - B B B B B B B B B B B B B B - - - - - - - -   - - - - - - - - B F C C C D B B B B B B - - - - - - - - -   - - - - - - - - - B B B B B B B B B B - - - - - - - - - -   - - - - - - - - - B B B B B B B B B B - - - - - - - - - -   - - - - - - - - - - B B B B D C C B - - - - - - - - - - -   - - - - - - - - - - B B B B C C D B - - - - - - - - - - -   - - - - - - - - - - - B B C C C C - - - - - - - - - - - -   - - - - - - - - - - - B B B B B B - - - - - - - - - - - -   - - - - - - - - - - - - C C D B - - - - - - - - - - - - -   - - - - - - - - - - - - - C C - - - - - - - - - - - - - -   - - - - - - - - - - - - - - - - - - - - - - - - - - - - -   - - - - - - - - - - - - - - - - - - - - - - - - - - - - -   
- - - - - - - - - - - - - - - - - - - - - - - - - - - - -   - - - - - - - - - - - - - - - - - - - - - - - - - - - - -   - - - - - - - - - - - - - - - - - - - - - - - - - - O - -   - - - - - - - - - - - - - - - - - - - - - - - - - Ad- - -   - - - K A - - - - - - - - - - - - - - - - - - A A A - - -   - A A - - - - - - - - - - - - - - - - - - - - A - A A - -   - A - - - - - - - - - - - - - - - - - - - - - A - - A - -   - A - L A A A A A A A A A A A A A A A A A A A A A - A - -   - A A - A A A A A A A A A A A A A A A A C A A A - A - - -   - - - A A A A A A A A A A A A A A A A A C A A A - A - - -   - - - - - B B B B B B B B B B B B B B F C C B - - - - - -   - - - - - B B B B B B B B B B B B B B C C C B - - - - - -   - - - - - - B B B B B B B B B B B B C C C C - - - - - - -   - - - - - - B B B B B B B B B B B B B B H B - - - - - - -   - - - - - - - B B B B B B B B B B B B B B - - - - - - - -   - - - - - - - B B B D C C B B F C C C D B - - - - - - - -   - - - - - - - - B B C C D B B B B B B B - - - - - - - - -   - - - - - - - - B C C C C C B B B B B B - - - - - - - - -   - - - - - - - - - B B B B B B C B B B - - - - - - - - - -   - - - - - - - - - - B B B B B C B B - - - - - - - - - - -   - - - - - - - - - - B B B B F C C B - - - - - - - - - - -   - - - - - - - - - - - B B B C C C - - - - - - - - - - - -   - - - - - - - - - - - - B C C C - - - - - - - - - - - - -   - - - - - - - - - - - - B B B H - - - - - - - - - - - - -   - - - - - - - - - - - - - B B - - - - - - - - - - - - - -   - - - - - - - - - - - - - - - - - - - - - - - - - - - - -   - - - - - - - - - - - - - - - - - - - - - - - - - - - - -   - - - - - - - - - - - - - - - - - - - - - - - - - - - - -   
- - - - - - - - - - - - - - - - - - - - - - - - - - - - -   - - - - - - - - - - - - - - - - - - - - - - - - - - - U -   - - - - - - - - - - - - - - - - - - - - - - - - - - - - -   - - - - - - - - - - - - - - - - - - - - - - - - - - - - -   - - - A A A - - - - - - - - - - - - - - - - A A A A - - -   - - - - - A - - - - - - - - - - - - - - - - A A - A - - -   - - - - - A - - - - - - - - - - - - - - - - A A - A - - -   - - - A A A A A A A A A A A A A A A A A A A A A A A - - -   - - - A A A A A A A A A A A A A A A A A A A A A - A - - -   - - - A A A A A A A A A A A A A A A A A A A A A A A - - -   - - - - - B B B B B B B B B B B B B B C C D B - - - - - -   - - - - - - B B B B B B B B B B B B B C C C - - - - - - -   - - - - - - B B B B B B B B B B B B D C C C - - - - - - -   - - - - - - - B B B B C B B B B D C C B B - - - - - - - -   - - - - - - - B B B B C B B B B C C D B B - - - - - - - -   - - - - - - - - B B F C C B B C C C C C - - - - - - - - -   - - - - - - - - - B C C C B B B B B B - - - - - - - - - -   - - - - - - - - - C C C C D B B B B B - - - - - - - - - -   - - - - - - - - - - B H B B B B B B - - - - - - - - - - -   - - - - - - - - - - - B B B B B B - - - - - - - - - - - -   - - - - - - - - - - - B B B C C D - - - - - - - - - - - -   - - - - - - - - - - - - B B C C - - - - - - - - - - - - -   - - - - - - - - - - - - - D C - - - - - - - - - - - - - -   - - - - - - - - - - - - - - - - - - - - - - - - - - - - -   - - - - - - - - - - - - - - - - - - - - - - - - - - - - -   - - - - - - - - - - - - - - - - - - - - - - - - - - - - -   - - - - - - - - - - - - - - - - - - - - - - - - - - - - -   - - - - - - - - - - - - - - - - - - - - - - - - - - - - -   
- - - - - - - - - - - - - - - - - - - - - - - - - - Ab- -   - - - - - - - - - - - - - - - - - - - - - - - - - - - - -   - - - - - - - - - - - - - - - - - - - - - - - - - - - - -   - - - - - - - - - - - - - - - - - - - - - - - - - - - - -   - - - A A A - - - - - - - - - - - - - - - - A A A A - - -   - - - A - E - - - - - - - - - - - - - - - - A - - A - - -   - - - - - A A - - - - - - - - - - - - - - A A - - A - - -   - - - - A E A A A A A A A A A A A A A A A A A A - A - A -   - - - A A A A A A A A A A A A A A A A A A A A A - A - - -   - - - A A A A A A A A A A A A A A A A A A A A - A - - - -   - - - - - - B B B B B B B B B B B B B B B B - - - - - - -   - - - - - - B B B B B B B B B B B C B B B B - - - - - - -   - - - - - - - B B B B B B B B B B C C D D - - - - - - - -   - - - - - - - B B B B B B B B B F C C B B - - - - - - - -   - - - - - - - - B B B B B B B B C C C B - - - - - - - - -   - - - - - - - - - B C C D B B C C C C - - - - - - - - - -   - - - - - - - - - B C C C B B B B H B - - - - - - - - - -   - - - - - - - - - - C C C C B B B B - - - - - - - - - - -   - - - - - - - - - - - B B B B B B - - - - - - - - - - - -   - - - - - - - - - - - - B B B B - - - - - - - - - - - - -   - - - - - - - - - - - - - B B - - - - - - - - - - - - - -   - - - - - - - - - - - - - - - - - - - - - - - - - - - - -   - - - - - - - - - - - - - - - - - - - - - - - - - - - - -   - - - - - - - - - - - - - - - - - - - - - - - - - - - - -   - - - - - - - - - - - - - - - - - - - - - - - - - - - - -   - - - - - - - - - - - - - - - - - - - - - - - - - - - - -   - - - - - - - - - - - - - - - - - - - - - - - - - - - - -   - - - - - - - - - - - - - - - - - - - - - - - - - - - - -   
- - - - - - - - - - - - - - - - - - - - - - - - - - - - -   - - - - - - - - - - - - - - - - - - - - - - - - - - - - X   - - - - - S - - - - - - - - - - - - - - - - - - - - - Aa-   - - - - - - P - - - - - - - - - - - - - - - - - - - Ap- -   - - - A A A A - - - - - - - - - - - - - - A A A A A - - -   - - - A - A A - - - - - - - - - - - - - - A A - - A - - -   - - - A - A A - - - - - - - - - - - - - - A A - - A A - -   - - - A A A A A A A A A A A A A A A A A E A A A - A - - -   - - - A - A A A A A A A A A A A A A A A A A A - A - - - -   - - - A A - A A A A A A A A A A A A A A E A - A E - - - -   - - - - - - B B B B B B B B B B B B B B B B - - - - - - -   - - - - - - - B B B B B B B B B B B B B B - - - - - - - -   - - - - - - - - B F C C C D B B B B B B - - - - - - - - -   - - - - - - - - B B B B B B B B C C D B - - - - - - - - -   - - - - - - - - - B B B B B B B C C C - - - - - - - - - -   - - - - - - - - - - B B B B B D C C - - - - - - - - - - -   - - - - - - - - - - - B B B B B B - - - - - - - - - - - -   - - - - - - - - - - - D C C B B B - - - - - - - - - - - -   - - - - - - - - - - - - - B B - - - - - - - - - - - - - -   - - - - - - - - - - - - - - - - - - - - - - - - - - - - -   - - - - - - - - - - - - - - - - - - - - - - - - - - - - -   - - - - - - - - - - - - - - - - - - - - - - - - - - - - -   - - - - - - - - - - - - - - - - - - - - - - - - - - - - -   - - - - - - - - - - - - - - - - - - - - - - - - - - - - -   - - - - - - - - - - - - - - - - - - - - - - - - - - - - -   - - - - - - - - - - - - - - - - - - - - - - - - - - - - -   - - - - - - - - - - - - - - - - - - - - - - - - - - - - -   - - - - - - - - - - - - - - - - - - - - - - - - - - - - -   
- - - - - - - - - - - - - - - - - - - - - - - - - - - - -   - - - - - - Af- - - - - - - - - - - - - - - - - - - - - -   - - - - - - - - - - - - - - - - - - - - - - - - - - - - -   - - - - - - - - - - - - - - - - - - - - - - - - - - - - -   - - - A A A A A - - - - - - - - - - - - - A A A A - - - -   - - - A A - A A - - - - - - - - - - - - - A - - A - - - -   - - - A - - A A - - - - - - - - - - - - - A - - - - - - -   - - - A - A A A A A A A A A A A A A A A A A A - - - - - -   - - - A E - A A E A A A A A A A A A A A A J - - A - - - -   - - - A A - A A A A A A A A A A A A A A A A A A A - - - -   - - - - - - - B B B D C C B B G B B B B B - - - - - - - -   - - - - - - - - B B C C D B B B B B B B - - - - - - - - -   - - - - - - - - - C C C C C B B B B B - - - - - - - - - -   - - - - - - - - - B B B B B B B B B B - - - - - - - - - -   - - - - - - - - - - B B B B B B B B - - - - - - - - - - -   - - - - - - - - - - - B B B B C D - - - - - - - - - - - -   - - - - - - - - - - - - B B B B - - - - - - - - - - - - -   - - - - - - - - - - - - - - - - - - - - - - - - - - - - -   - - - - - - - - - - - - - - - - - - - - - - - - - - - - -   - - - - - - - - - - - - - - - - - - - - - - - - - - - - -   - - - - - - - - - - - - - - - - - - - - - - - - - - - - -   - - - - - - - - - - - - - - - - - - - - - - - - - - - - -   - - - - - - - - - - - - - - - - - - - - - - - - - - - - -   - - - - - - - - - - - - - - - - - - - - - - - - - - - - -   - - - - - - - - - - - - - - - - - - - - - - - - - - - - -   - - - - - - - - - - - - - - - - - - - - - - - - - - - - -   - - - - - - - - - - - - - - - - - - - - - - - - - - - - -   - - - - - - - - - - - - - - - - - - - - - - - - - - - - -   
- - - - - R - - - - - - - - - - - - - - - - - - - - - - -   - - - - - - - - - - - - - - - - - - - - - - - - - - - - -   - - - - - - - - - - - - - - - - - - - - Q - - - - - - - -   - - - - - - - - - - - - - - - - - - - - - N - - - - - - -   - - - - - A A A A - - - - - - - - - - A A A A A - - - - -   - - - - A A A - A - - - - - - - - - - A A - - A A - - - -   - - - - A - - - A A - - - - - - - - A A A - - A A - - - -   - - - - A - A I A A A A A A A A A A A A A A - A A - - - -   - - - - A A - A A A A C A A A A A A A A A - A A A - - - -   - - - - - A A A A A A C A A A A A A A A A A L A - - - - -   - - - - - - - - B B F C C B G G G B B B - - - - - - - - -   - - - - - - - - - B C C C B B B B B B - - - - - - - - - -   - - - - - - - - - - C C C D B B B B - - - - - - - - - - -   - - - - - - - - - - - H B B B B B - - - - - - - - - - - -   - - - - - - - - - - - - B B B B - - - - - - - - - - - - -   - - - - - - - - - - - - - - - - - - - - - - - - - - - - -   - - - - - - - - - - - - - - - - - - - - - - - - - - - - -   - - - - - - - - - - - - - - - - - - - - - - - - - - - - -   - - - - - - - - - - - - - - - - - - - - - - - - - - - - -   - - - - - - - - - - - - - - - - - - - - - - - - - - - - -   - - - - - - - - - - - - - - - - - - - - - - - - - - - - -   - - - - - - - - - - - - - - - - - - - - - - - - - - - - -   - - - - - - - - - - - - - - - - - - - - - - - - - - - - -   - - - - - - - - - - - - - - - - - - - - - - - - - - - - -   - - - - - - - - - - - - - - - - - - - - - - - - - - - - -   - - - - - - - - - - - - - - - - - - - - - - - - - - - - -   - - - - - - - - - - - - - - - - - - - - - - - - - - - - -   - - - - - - - - - - - - - - - - - - - - - - - - - - - - -   
- - - - - - - - - - Y - - - - - - - - - - - - - - - - - -   - - - - - - - - - - - Ah- - - - - - - - - - - Ae- - - - -   - - - - - - - - - - - - - - - - - - - - - - - - - - - - -   - - - - - - - - - - - - - - - - - - - - - - - - - - - - -   - - - - - A A A A A A - - - - - - A A A A A A A - - - - -   - - - - - A K - - A A - - - - - - A A A - - A A - - - - -   - - - - - A - - - A A A - - - - - A A A - A A A - - - - -   - - - - - A - A A A A A A A A A A A A A A - A A - - - - -   - - - - - A L - A A A A A A A A A A A A - I A J - - - - -   - - - - - A K A - A A A A A A A A A A - A A A - - - - - -   - - - - - - - - - - C C D G G G G G - - - - - - - - - - -   - - - - - - - - - - - C C B B B B - - - - - - - - - - - -   - - - - - - - - - - - - C C B B - - - - - - - - - - - - -   - - - - - - - - - - - - - - - - - - - - - - - - - - - - -   - - - - - - - - - - - - - - - - - - - - - - - - - - - - -   - - - - - - - - - - - - - - - - - - - - - - - - - - - - -   - - - - - - - - - - - - - - - - - - - - - - - - - - - - -   - - - - - - - - - - - - - - - - - - - - - - - - - - - - -   - - - - - - - - - - - - - - - - - - - - - - - - - - - - -   - - - - - - - - - - - - - - - - - - - - - - - - - - - - -   - - - - - - - - - - - - - - - - - - - - - - - - - - - - -   - - - - - - - - - - - - - - - - - - - - - - - - - - - - -   - - - - - - - - - - - - - - - - - - - - - - - - - - - - -   - - - - - - - - - - - - - - - - - - - - - - - - - - - - -   - - - - - - - - - - - - - - - - - - - - - - - - - - - - -   - - - - - - - - - - - - - - - - - - - - - - - - - - - - -   - - - - - - - - - - - - - - - - - - - - - - - - - - - - -   - - - - - - - - - - - - - - - - - - - - - - - - - - - - -   
- - - - - - - - - - - - U - - - - - - - - - - - - - - - -   - - - - - - - - - - - - - O - - - - - - - - - - - - - - -   - - - - - - - - - - Ag- - - - - - - - - - - - - - - - - -   - - - - - - - - - - - - - - - - - G - - - - - - - - - - -   - - - - - - A A A A A A A A A A A A A A A A A - - - - - -   - - - - - A A A - - A A A A A A A A - - - A A - - - - - -   - - - - - A A - - - A A A A A A A A - - - A A - - - - - -   - - - - - I A - A A A A A A A A A A A A - A A - - - - - -   - - - - - A A A - A A A A A A A A A A - - A A - - - - - -   - - - - - - A A A - A A A A A A A A - A E A - - - - - - -   - - - - - - - - - - - - B B G G - - - - - - - - - - - - -   - - - - - - - - - - - - - - - - - - - - - - - - - - - - -   - - - - - - - - - - - - - - - - - - - - - - - - - - - - -   - - - - - - - - - - - - - - - - - - - - - - - - - - - - -   - - - - - - - - - - - - - - - - - - - - - - - - - - - - -   - - - - - - - - - - - - - - - - - - - - - - - - - - - - -   - - - - - - - - - - - - - - - - - - - - - - - - - - - - -   - - - - - - - - - - - - - - - - - - - - - - - - - - - - -   - - - - - - - - - - - - - - - - - - - - - - - - - - - - -   - - - - - - - - - - - - - - - - - - - - - - - - - - - - -   - - - - - - - - - - - - - - - - - - - - - - - - - - - - -   - - - - - - - - - - - - - - - - - - - - - - - - - - - - -   - - - - - - - - - - - - - - - - - - - - - - - - - - - - -   - - - - - - - - - - - - - - - - - - - - - - - - - - - - -   - - - - - - - - - - - - - - - - - - - - - - - - - - - - -   - - - - - - - - - - - - - - - - - - - - - - - - - - - - -   - - - - - - - - - - - - - - - - - - - - - - - - - - - - -   - - - - - - - - - - - - - - - - - - - - - - - - - - - - -   
- - - - - - - - - - - - - - - - - - - - - - - - - - - - -   - - - - - - - - - - - - - - - - - - - - - - - - - - - - -   - - - - - - - - - - - - X - - - - - - - - - - - - - - - -   - - - - - - - - - - - M - - - - - - - - - - - - - - - - -   - - - - - - - A A A A A A A A A A A A A A - - - - - - - -   - - - - - - A A A - - - - A A - - - - - A A - - - - - - -   - - - - - - A A - - - - - - - - - - - - - A - - - - - - -   - - - - - - A A - - A A A A A A A A - - - A - - - - - - -   - - - - - - A A E - - - A A A E - - - A A A - - - - - - -   - - - - - - - A A A A - - A A - - A A A A - - - - - - - -   - - - - - - - - - - - - - - - - - - - - - - - - - - - - -   - - - - - - - - - - - - - - - - - - - - - - - - - - - - -   - - - - - - - - - - - - - - - - - - - - - - - - - - - - -   - - - - - - - - - - - - - - - - - - - - - - - - - - - - -   - - - - - - - - - - - - - - - - - - - - - - - - - - - - -   - - - - - - - - - - - - - - - - - - - - - - - - - - - - -   - - - - - - - - - - - - - - - - - - - - - - - - - - - - -   - - - - - - - - - - - - - - - - - - - - - - - - - - - - -   - - - - - - - - - - - - - - - - - - - - - - - - - - - - -   - - - - - - - - - - - - - - - - - - - - - - - - - - - - -   - - - - - - - - - - - - - - - - - - - - - - - - - - - - -   - - - - - - - - - - - - - - - - - - - - - - - - - - - - -   - - - - - - - - - - - - - - - - - - - - - - - - - - - - -   - - - - - - - - - - - - - - - - - - - - - - - - - - - - -   - - - - - - - - - - - - - - - - - - - - - - - - - - - - -   - - - - - - - - - - - - - - - - - - - - - - - - - - - - -   - - - - - - - - - - - - - - - - - - - - - - - - - - - - -   - - - - - - - - - - - - - - - - - - - - - - - - - - - - -   
- - - - - - - - - - - - - - - - - - - - - - - - - - - - -   - - - - - - - - - - - - - - - - - - - - - - - - - - - - -   - - - - - - - - - - - - - - - - - - - - - - - - - - - - -   - - - - - - - - - - - - - V - - - - - - - - - - - - - - -   - - - - - - - - - A A A A A A A A A A - - - - - - - - - -   - - - - - - - - - A A A A A A A A A A A - - - - - - - - -   - - - - - - - - - A A A - - - - - A A A - - - - - - - - -   - - - - - - - - - A A A - A I - - A A A - - - - - - - - -   - - - - - - - - - A A A A A A A A A A - - - - - - - - - -   - - - - - - - - - - A A A A A A A A - - - - - - - - - - -   - - - - - - - - - - - - - - - - - - - - - - - - - - - - -   - - - - - - - - - - - - - - - - - - - - - - - - - - - - -   - - - - - - - - - - - - - - - - - - - - - - - - - - - - -   - - - - - - - - - - - - - - - - - - - - - - - - - - - - -   - - - - - - - - - - - - - - - - - - - - - - - - - - - - -   - - - - - - - - - - - - - - - - - - - - - - - - - - - - -   - - - - - - - - - - - - - - - - - - - - - - - - - - - - -   - - - - - - - - - - - - - - - - - - - - - - - - - - - - -   - - - - - - - - - - - - - - - - - - - - - - - - - - - - -   - - - - - - - - - - - - - - - - - - - - - - - - - - - - -   - - - - - - - - - - - - - - - - - - - - - - - - - - - - -   - - - - - - - - - - - - - - - - - - - - - - - - - - - - -   - - - - - - - - - - - - - - - - - - - - - - - - - - - - -   - - - - - - - - - - - - - - - - - - - - - - - - - - - - -   - - - - - - - - - - - - - - - - - - - - - - - - - - - - -   - - - - - - - - - - - - - - - - - - - - - - - - - - - - -   - - - - - - - - - - - - - - - - - - - - - - - - - - - - -   - - - - - - - - - - - - - - - - - - - - - - - - - - - - -   
- - - - - - - - - - - - - - - - - - - - - - - - - - - - -   - - - - - - - - - - - - - - - - - - - - - - - - - - - - -   - - - - - - - - - - - - - - - - - - - - - - - - - - - - -   - - - - - - - - - - - - - - - - - - - - - - - - - - - - -   - - - - - - - - - - - - - - - A - - - - - - - - - - - - -   - - - - - - - - - - - A A K A A A - - - - - - - - - - - -   - - - - - - - - - - - A A L A A A - - - - - - - - - - - -   - - - - - - - - - - - A A A A A A - - - - - - - - - - - -   - - - - - - - - - - - - A L A A A - - - - - - - - - - - -   - - - - - - - - - - - - - - - - - - - - - - - - - - - - -   - - - - - - - - - - - - - - - - - - - - - - - - - - - - -   - - - - - - - - - - - - - - - - - - - - - - - - - - - - -   - - - - - - - - - - - - - - - - - - - - - - - - - - - - -   - - - - - - - - - - - - - - - - - - - - - - - - - - - - -   - - - - - - - - - - - - - - - - - - - - - - - - - - - - -   - - - - - - - - - - - - - - - - - - - - - - - - - - - - -   - - - - - - - - - - - - - - - - - - - - - - - - - - - - -   - - - - - - - - - - - - - - - - - - - - - - - - - - - - -   - - - - - - - - - - - - - - - - - - - - - - - - - - - - -   - - - - - - - - - - - - - - - - - - - - - - - - - - - - -   - - - - - - - - - - - - - - - - - - - - - - - - - - - - -   - - - - - - - - - - - - - - - - - - - - - - - - - - - - -   - - - - - - - - - - - - - - - - - - - - - - - - - - - - -   - - - - - - - - - - - - - - - - - - - - - - - - - - - - -   - - - - - - - - - - - - - - - - - - - - - - - - - - - - -   - - - - - - - - - - - - - - - - - - - - - - - - - - - - -   - - - - - - - - - - - - - - - - - - - - - - - - - - - - -   - - - - - - - - - - - - - - - - - - - - - - - - - - - - -   
- - - - - - - - - - - - - - - - An- - - - - - - - - - - -   - - - - - - - - - - - - - - - - - T - - - - - - - - - - -   - - - - - - - - - - - - - - - - K - - - - - - - - - - - -   - - - - - - - - - - - - - - - Ae- - - - - - - - - - - - -   - - - - - - - - - - - - - - - - - - - - - - - - - - - - -   - - - - - - - - - - - - - - - - - - - - - - - - - - - - -   - - - - - - - - - - - - - - - - - - - - - - - - - - - - -   - - - - - - - - - - - - - - - - - - - - - - - - - - - - -   - - - - - - - - - - - - - - - - - - - - - - - - - - - - -   - - - - - - - - - - - - - - - - - - - - - - - - - - - - -   - - - - - - - - - - - - - - - - - - - - - - - - - - - - -   - - - - - - - - - - - - - - - - - - - - - - - - - - - - -   - - - - - - - - - - - - - - - - - - - - - - - - - - - - -   - - - - - - - - - - - - - - - - - - - - - - - - - - - - -   - - - - - - - - - - - - - - - - - - - - - - - - - - - - -   - - - - - - - - - - - - - - - - - - - - - - - - - - - - -   - - - - - - - - - - - - - - - - - - - - - - - - - - - - -   - - - - - - - - - - - - - - - - - - - - - - - - - - - - -   - - - - - - - - - - - - - - - - - - - - - - - - - - - - -   - - - - - - - - - - - - - - - - - - - - - - - - - - - - -   - - - - - - - - - - - - - - - - - - - - - - - - - - - - -   - - - - - - - - - - - - - - - - - - - - - - - - - - - - -   - - - - - - - - - - - - - - - - - - - - - - - - - - - - -   - - - - - - - - - - - - - - - - - - - - - - - - - - - - -   - - - - - - - - - - - - - - - - - - - - - - - - - - - - -   - - - - - - - - - - - - - - - - - - - - - - - - - - - - -   - - - - - - - - - - - - - - - - - - - - - - - - - - - - -   - - - - - - - - - - - - - - - - - - - - - - - - - - - - -   
