model
size = 29 28 27, scale = 0.05, origin = -y
material 
  colors = A:#EEE B:#60C C:#3FF D:#C99 E:#888 F:#3F6 G:#0D0 H:#F96 I:#F9F J:#F99 K:#F33 L:#F36 M:#FCF N:#F6F O:#F0C P:#FC6 Q:#FC3 R:#FF6 S:#F0F T:#FFF U:#CFC V:#F9C W:#F06 X:#CC3 Y:#F3F Z:#F03 Aa:#F90 Ab:#CFF Ac:#CCF Ad:#F60 Ae:#F69 Af:#F66 Ag:#F6C Ah:#F09 Ai:#CF0 Aj:#CCC Ak:#F3C Al:#FF9 Am:#CC0 An:#CF6
voxels
- - - - - - - - - - - - Aj- - - - - - - - - - - - - - - -   - - - - - - - - - - - O - - - - - - - - - - - - - - - - -   - - - - - - - - - - - - Ai- - - - - - - - - - - - - - - -   - - - - - - - - - - - - - Y - - - - - - - - - - - - - - -   - - - - - - - - - - - - - - - - - - - - - - - - - - - - -   - - - - - - - - - - - - - - - - - - - - - - - - - - - - -   - - - - - - - - - - - - - - - - - - - - - - - - - - - - -   - - - - - - - - - - - - - - - - - - - - - - - - - - - - -   - - - - - - - - - - - - - - - - - - - - - - - - - - - - -   - - - - - - - - - - - - - - - - - - - - - - - - - - - - -   - - - - - - - - - - - - - - - - - - - - - - - - - - - - -   - - - - - - - - - - - - - - - - - - - - - - - - - - - - -   - - - - - - - - - - - - - - - - - - - - - - - - - - - - -   - - - - - - - - - - - - - - - - - - - - - - - - - - - - -   - - - - - - - - - - - - - - - - - - - - - - - - - - - - -   - - - - - - - - - - - - - - - - - - - - - - - - - - - - -   - - - - - - - - - - - - - - - - - - - - - - - - - - - - -   - - - - - - - - - - - - - - - - - - - - - - - - - - - - -   - - - - - - - - - - - - - - - - - - - - - - - - - - - - -   - - - - - - - - - - - - - - - - - - - - - - - - - - - - -   - - - - - - - - - - - - - - - - - - - - - - - - - - - - -   - - - - - - - - - - - - - - - - - - - - - - - - - - - - -   - - - - - - - - - - - - - - - - - - - - - - - - - - - - -   - - - - - - - - - - - - - - - - - - - - - - - - - - - - -   - - - - - - - - - - - - - - - - - - - - - - - - - - - - -   - - - - - - - - - - - - - - - - - - - - - - - - - - - - -   - - - - - - - - - - - - - - - - - - - - - - - - - - - - -   - - - - - - - - - - - - - - - - - - - - - - - - - - - - -   
- - - - - - - - - - - - - - - - - - - - - - - - - - - - -   - - - - - - - - - - - - - - - - - - - - - - - - - - - - -   - - - - - - - - - - - - - - - - - - - - - - - - - - - - -   - - - - - - - - - - - - - - - - - - - - - - - - - - - - -   - - - - - - - - - - - - - A - - - - - - - - - - - - - - -   - - - - - - - - - - - - A A A A A A - - - - - - - - - - -   - - - - - - - - - - - - A A A A A A - - - - - - - - - - -   - - - - - - - - - - - - A A A A A A - - - - - - - - - - -   - - - - - - - - - - - - A A A A A - - - - - - - - - - - -   - - - - - - - - - - - - - - - - - - - - - - - - - - - - -   - - - - - - - - - - - - - - - - - - - - - - - - - - - - -   - - - - - - - - - - - - - - - - - - - - - - - - - - - - -   - - - - - - - - - - - - - - - - - - - - - - - - - - - - -   - - - - - - - - - - - - - - - - - - - - - - - - - - - - -   - - - - - - - - - - - - - - - - - - - - - - - - - - - - -   - - - - - - - - - - - - - - - - - - - - - - - - - - - - -   - - - - - - - - - - - - - - - - - - - - - - - - - - - - -   - - - - - - - - - - - - - - - - - - - - - - - - - - - - -   - - - - - - - - - - - - - - - - - - - - - - - - - - - - -   - - - - - - - - - - - - - - - - - - - - - - - - - - - - -   - - - - - - - - - - - - - - - - - - - - - - - - - - - - -   - - - - - - - - - - - - - - - - - - - - - - - - - - - - -   - - - - - - - - - - - - - - - - - - - - - - - - - - - - -   - - - - - - - - - - - - - - - - - - - - - - - - - - - - -   - - - - - - - - - - - - - - - - - - - - - - - - - - - - -   - - - - - - - - - - - - - - - - - - - - - - - - - - - - -   - - - - - - - - - - - - - - - - - - - - - - - - - - - - -   - - - - - - - - - - - - - - - - - - - - - - - - - - - - -   
- - - - - - - - - - - - - - - - - - - - - - - - - - - - -   - - - - - - - - - - - - - - - - - - - - - - - - - - - - -   - - - - - - - - - - - - - - - - - - - - - - - - - - - - -   - - - - - - - - - - - - - - - Q - - - - - - - - - - - - -   - - - - - - - - - - A A A A A A A A A A - - - - - - - - -   - - - - - - - - - E E A A A A A A A A A - - - - - - - - -   - - - - - - - - - E E A - - - - - A A A - - - - - - - - -   - - - - - - - - - A A A - - A A - A A A - - - - - - - - -   - - - - - - - - - - A A A A A A A E E A - - - - - - - - -   - - - - - - - - - - - A A A A A A E E - - - - - - - - - -   - - - - - - - - - - - - - - - - - - - - - - - - - - - - -   - - - - - - - - - - - - - - - - - - - - - - - - - - - - -   - - - - - - - - - - - - - - - - - - - - - - - - - - - - -   - - - - - - - - - - - - - - - - - - - - - - - - - - - - -   - - - - - - - - - - - - - - - - - - - - - - - - - - - - -   - - - - - - - - - - - - - - - - - - - - - - - - - - - - -   - - - - - - - - - - - - - - - - - - - - - - - - - - - - -   - - - - - - - - - - - - - - - - - - - - - - - - - - - - -   - - - - - - - - - - - - - - - - - - - - - - - - - - - - -   - - - - - - - - - - - - - - - - - - - - - - - - - - - - -   - - - - - - - - - - - - - - - - - - - - - - - - - - - - -   - - - - - - - - - - - - - - - - - - - - - - - - - - - - -   - - - - - - - - - - - - - - - - - - - - - - - - - - - - -   - - - - - - - - - - - - - - - - - - - - - - - - - - - - -   - - - - - - - - - - - - - - - - - - - - - - - - - - - - -   - - - - - - - - - - - - - - - - - - - - - - - - - - - - -   - - - - - - - - - - - - - - - - - - - - - - - - - - - - -   - - - - - - - - - - - - - - - - - - - - - - - - - - - - -   
- - - - - - - - - - - - - - - - - - - - - - - - - - - - -   - - - - - - - - - - - - - - - - - - - - - - - - - - - - -   - - - - - - - - - - - - - - - - S - - - - - - - - - - - -   - - - - - - - - - - - - - - - - - H - - - - - - - - - - -   - - - - - - - - A A A A A A A A A A A A A A - - - - - - -   - - - - - - - A A - - - - - A A - - - - A A A - - - - - -   - - - - - - - A - - - - - - - - - - - - - A A - - - - - -   - - - - - - - A - - - A A A A A A A A - - A A - - - - - -   - - - - - - - A A A - - - A A A A - - - A E E - - - - - -   - - - - - - - - A A A A - - A A - - E A A E - - - - - - -   - - - - - - - - - - - - - - - - - - - - - - - - - - - - -   - - - - - - - - - - - - - - - - - - - - - - - - - - - - -   - - - - - - - - - - - - - - - - - - - - - - - - - - - - -   - - - - - - - - - - - - - - - - - - - - - - - - - - - - -   - - - - - - - - - - - - - - - - - - - - - - - - - - - - -   - - - - - - - - - - - - - - - - - - - - - - - - - - - - -   - - - - - - - - - - - - - - - - - - - - - - - - - - - - -   - - - - - - - - - - - - - - - - - - - - - - - - - - - - -   - - - - - - - - - - - - - - - - - - - - - - - - - - - - -   - - - - - - - - - - - - - - - - - - - - - - - - - - - - -   - - - - - - - - - - - - - - - - - - - - - - - - - - - - -   - - - - - - - - - - - - - - - - - - - - - - - - - - - - -   - - - - - - - - - - - - - - - - - - - - - - - - - - - - -   - - - - - - - - - - - - - - - - - - - - - - - - - - - - -   - - - - - - - - - - - - - - - - - - - - - - - - - - - - -   - - - - - - - - - - - - - - - - - - - - - - - - - - - - -   - - - - - - - - - - - - - - - - - - - - - - - - - - - - -   - - - - - - - - - - - - - - - - - - - - - - - - - - - - -   
- - - - - - - - - - - - - - - - P - - - - - - - - - - - -   - - - - - - - - - - - - - - - K - - - - - - - - - - - - -   - - - - - - - - - - - - - - - - - - Ab- - - - - - - - - -   - - - - - - - - - - - J - - - - - - - - - - - - - - - - -   - - - - - - A A A A A A A A A A A A A A A A A - - - - - -   - - - - - - E E - - - A A A A A A A A - - A A A - - - - -   - - - - - - E E - - - A A A A A A A A - - - A A - - - - -   - - - - - - A A - A A A A A A A A A A A A - A A - - - - -   - - - - - - A E - - A A A A A A A A A A - E E E - - - - -   - - - - - - - E E A - A A A A A A A A - A E E - - - - - -   - - - - - - - - - - - - - B B B B - - - - - - - - - - - -   - - - - - - - - - - - - - - - - - - - - - - - - - - - - -   - - - - - - - - - - - - - - - - - - - - - - - - - - - - -   - - - - - - - - - - - - - - - - - - - - - - - - - - - - -   - - - - - - - - - - - - - - - - - - - - - - - - - - - - -   - - - - - - - - - - - - - - - - - - - - - - - - - - - - -   - - - - - - - - - - - - - - - - - - - - - - - - - - - - -   - - - - - - - - - - - - - - - - - - - - - - - - - - - - -   - - - - - - - - - - - - - - - - - - - - - - - - - - - - -   - - - - - - - - - - - - - - - - - - - - - - - - - - - - -   - - - - - - - - - - - - - - - - - - - - - - - - - - - - -   - - - - - - - - - - - - - - - - - - - - - - - - - - - - -   - - - - - - - - - - - - - - - - - - - - - - - - - - - - -   - - - - - - - - - - - - - - - - - - - - - - - - - - - - -   - - - - - - - - - - - - - - - - - - - - - - - - - - - - -   - - - - - - - - - - - - - - - - - - - - - - - - - - - - -   - - - - - - - - - - - - - - - - - - - - - - - - - - - - -   - - - - - - - - - - - - - - - - - - - - - - - - - - - - -   
- - - - - - - - - - - - - - - - - - T - - - - - - - - - -   - - - - - Y - - - - - - - - - - - Ac- - - - - - - - - - -   - - - - - - - - - - - - - - - - - - - - - - - - - - - - -   - - - - - - - - - - - - - - - - - - - - - - - - - - - - -   - - - - - A A A A A A A A A A A A A A A A A A A - - - - -   - - - - - A E - - A A A A A A A A A A A - - A A - - - - -   - - - - - A E E - A A A A A A A A A A A - - - A - - - - -   - - - - - A A - A A A A A A A A A A A A A A - A - - - - -   - - - - - A A E - A A A A A A A A A A A A - E E - - - - -   - - - - - - A E E - A A A A A A A A A A - A E E - - - - -   - - - - - - - - - - - B B B B B B B B - - - - - - - - - -   - - - - - - - - - - - - B B B B B B - - - - - - - - - - -   - - - - - - - - - - - - - B B B B - - - - - - - - - - - -   - - - - - - - - - - - - - - - - - - - - - - - - - - - - -   - - - - - - - - - - - - - - - - - - - - - - - - - - - - -   - - - - - - - - - - - - - - - - - - - - - - - - - - - - -   - - - - - - - - - - - - - - - - - - - - - - - - - - - - -   - - - - - - - - - - - - - - - - - - - - - - - - - - - - -   - - - - - - - - - - - - - - - - - - - - - - - - - - - - -   - - - - - - - - - - - - - - - - - - - - - - - - - - - - -   - - - - - - - - - - - - - - - - - - - - - - - - - - - - -   - - - - - - - - - - - - - - - - - - - - - - - - - - - - -   - - - - - - - - - - - - - - - - - - - - - - - - - - - - -   - - - - - - - - - - - - - - - - - - - - - - - - - - - - -   - - - - - - - - - - - - - - - - - - - - - - - - - - - - -   - - - - - - - - - - - - - - - - - - - - - - - - - - - - -   - - - - - - - - - - - - - - - - - - - - - - - - - - - - -   - - - - - - - - - - - - - - - - - - - - - - - - - - - - -   
- - - - - - - - - - - - - - - - - - - - - - - M - - - - -   - - - - - - - - - - - - - - - - - - - - - - - - - - - - -   - - - - - - - - L - - - - - - - - - - - - - - - - - - - -   - - - - - - - I - - - - - - - - - - - - - - - - - - - - -   - - - - - A A A A A A A A A A A A A A A A A A A - - - - -   - - - - A A - - A A A A A A A A A A A A A - A A A - - - -   - - - - A A - - A A A A A A A A A A A A A - - - A - - - -   - - - - A A - A A A A A A A A A A A A A A A A - A - - - -   - - - - A A A - A A A A A A A A A A C C C A - A A - - - -   - - - - - A A A A A A A A A A A A A C C C A A A - - - - -   - - - - - - - - - B B B B B B B B B D C C - - - - - - - -   - - - - - - - - - - B B B B B B B B D C - - - - - - - - -   - - - - - - - - - - - B B B B B B B D - - - - - - - - - -   - - - - - - - - - - - - B B B B B B - - - - - - - - - - -   - - - - - - - - - - - - - B B B B - - - - - - - - - - - -   - - - - - - - - - - - - - - - - - - - - - - - - - - - - -   - - - - - - - - - - - - - - - - - - - - - - - - - - - - -   - - - - - - - - - - - - - - - - - - - - - - - - - - - - -   - - - - - - - - - - - - - - - - - - - - - - - - - - - - -   - - - - - - - - - - - - - - - - - - - - - - - - - - - - -   - - - - - - - - - - - - - - - - - - - - - - - - - - - - -   - - - - - - - - - - - - - - - - - - - - - - - - - - - - -   - - - - - - - - - - - - - - - - - - - - - - - - - - - - -   - - - - - - - - - - - - - - - - - - - - - - - - - - - - -   - - - - - - - - - - - - - - - - - - - - - - - - - - - - -   - - - - - - - - - - - - - - - - - - - - - - - - - - - - -   - - - - - - - - - - - - - - - - - - - - - - - - - - - - -   - - - - - - - - - - - - - - - - - - - - - - - - - - - - -   
- - - - - - - - - - - - - - - - - - - - - - - - - - - - -   - - - - - - - - - - - - - - - - - - - - - - Aa- - - - - -   - - - - - - - - - - - - - - - - - - - - - - - - - - - - -   - - - - - - - - - - - - - - - - - - - - - - - - - - - - -   - - - - A A A A A A A A A A A A A A A A A A A A A A - - -   - - - - A - - A A A A A A A A A A A A A A A A - A A - - -   - - - - - - - A A A A A A A A A A A A A A A A - - A - - -   - - - - - - A A A A A A A A A A A A A A A A A A - A - - -   - - - - E - - A A A A A A A A A A C C C C D A - A A - - -   - - - - A A A A A A A A A A A A A C C C C D A - A A - - -   - - - - - - - - B B B B B B B B B C C C C C - - - - - - -   - - - - - - - - - B B B B B B B B D C C C - - - - - - - -   - - - - - - - - - - B B B B B B B D C C - - - - - - - - -   - - - - - - - - - - B B B B B B B C C C - - - - - - - - -   - - - - - - - - - - - B B B B B B C C - - - - - - - - - -   - - - - - - - - - - - - B B B B B B - - - - - - - - - - -   - - - - - - - - - - - - - B B B B - - - - - - - - - - - -   - - - - - - - - - - - - - - - - - - - - - - - - - - - - -   - - - - - - - - - - - - - - - - - - - - - - - - - - - - -   - - - - - - - - - - - - - - - - - - - - - - - - - - - - -   - - - - - - - - - - - - - - - - - - - - - - - - - - - - -   - - - - - - - - - - - - - - - - - - - - - - - - - - - - -   - - - - - - - - - - - - - - - - - - - - - - - - - - - - -   - - - - - - - - - - - - - - - - - - - - - - - - - - - - -   - - - - - - - - - - - - - - - - - - - - - - - - - - - - -   - - - - - - - - - - - - - - - - - - - - - - - - - - - - -   - - - - - - - - - - - - - - - - - - - - - - - - - - - - -   - - - - - - - - - - - - - - - - - - - - - - - - - - - - -   
- - - - - - - - - - - - - - - - - - - - - - - - - - - - -   S - - - - - - - - - - - - - - - - - - - - - - - - - - - -   - V - - - - - - - - - - - - - - - - - - - - - N - - - - -   - - Al- - - - - - - - - - - - - - - - - - - J - - - - - -   - - - A A A A A A A A A A A A A A A A A A A A A A A - - -   - - - A - - A A A A A A A A A A A A A A A A A A A A - - -   - - A A - - A A A A A A A A A A A A A A A A A A A A - - -   - - - A - E A A A A A A A A A A A A A A A A A A A A - - -   - - - - E - A A A A A A A A A A C C C C C C D A - A - - -   - - - - A A - A A A A A A A A A C C C C C C C - A A - - -   - - - - - - - B B B B B B B B B C C C C C C C - - - - - -   - - - - - - - - B B B B B B B B C C C C C C - - - - - - -   - - - - - - - - - B C C C B B B C C C C C - - - - - - - -   - - - - - - - - - B C C C B B B C C C C C - - - - - - - -   - - - - - - - - - - D C C B B B C C C C - - - - - - - - -   - - - - - - - - - - - C C B B B B B B - - - - - - - - - -   - - - - - - - - - - - - C B B B B B - - - - - - - - - - -   - - - - - - - - - - - - C B B B B B - - - - - - - - - - -   - - - - - - - - - - - - - - B B - - - - - - - - - - - - -   - - - - - - - - - - - - - - - - - - - - - - - - - - - - -   - - - - - - - - - - - - - - - - - - - - - - - - - - - - -   - - - - - - - - - - - - - - - - - - - - - - - - - - - - -   - - - - - - - - - - - - - - - - - - - - - - - - - - - - -   - - - - - - - - - - - - - - - - - - - - - - - - - - - - -   - - - - - - - - - - - - - - - - - - - - - - - - - - - - -   - - - - - - - - - - - - - - - - - - - - - - - - - - - - -   - - - - - - - - - - - - - - - - - - - - - - - - - - - - -   - - - - - - - - - - - - - - - - - - - - - - - - - - - - -   
- - W - - - - - - - - - - - - - - - - - - - - - - - - - -   - - - - - - - - - - - - - - - - - - - - - - - - - - - - -   - - - - - - - - - - - - - - - - - - - - - - - - - - - - -   - - - - - - - - - - - - - - - - - - - - - - - - - - - - -   - - - A A A A A A A A A A A A A A A A A A A A A A A - - -   - - - A - - A A A A A A A A A A A A A A A A A A A A - - -   - - - A - - A A A A A A A A A A A A A A A A A A A A - - -   - A - A - A A A A A A A A A A A A A A A A A A A A A - - -   - - - A - A A A A A A A A A A A C C C C C C C A A A - - -   - - - - A - A A A A A A A A A A C C C C C C C A A A - - -   - - - - - - - B B B B B B B B B C C C C C C C - - - - - -   - - - - - - - B B B B B B B B B C C C C C C C - - - - - -   - - - - - - - - B C C C C D B B C C C C C F - - - - - - -   - - - - - - - - B C C C C D B B C C C C C F - - - - - - -   - - - - - - - - - C C C C C B B D C C C C - - - - - - - -   - - - - - - - - - - C C C C B B B B B B - - - - - - - - -   - - - - - - - - - - C F F C B B B B B B - - - - - - - - -   - - - - - - - - - - - F F C B B B B B - - - - - - - - - -   - - - - - - - - - - - - D D B B B B - - - - - - - - - - -   - - - - - - - - - - - - - B B B B - - - - - - - - - - - -   - - - - - - - - - - - - - - B B - - - - - - - - - - - - -   - - - - - - - - - - - - - - - - - - - - - - - - - - - - -   - - - - - - - - - - - - - - - - - - - - - - - - - - - - -   - - - - - - - - - - - - - - - - - - - - - - - - - - - - -   - - - - - - - - - - - - - - - - - - - - - - - - - - - - -   - - - - - - - - - - - - - - - - - - - - - - - - - - - - -   - - - - - - - - - - - - - - - - - - - - - - - - - - - - -   - - - - - - - - - - - - - - - - - - - - - - - - - - - - -   
- - - - - - - - - - - - - - - - - - - - - - - - - - - - -   - P - - - - - - - - - - - - - - - - - - - - - - - - - - -   - - - - - - - - - - - - - - - - - - - - - - - - - - - - -   - - - - - - - - - - - - - - - - - - - - - - - - - - - - -   - - - A A A A A A A A A A A A A A A A A A A A A A A - - -   - - - A - A A A A A A A A A A A A A A A A A A A A A - - -   - - - A - A A A A A A A A A A A A A A A A A A A A A - - -   - - - A A A A A A A A A A A A A A A A A A A A A A A - - -   - - - A - A A A A A A A A A A A D C C C C C C A A A - - -   - - - A A A A A A A A A A A A A D C C C C C D A A A - - -   - - - - - - B B B B B B B B B B C C C C C C D B - - - - -   - - - - - - - B B B B B B B B B C C C C C C D - - - - - -   - - - - - - - B C C C C C C D B C C C C C F F - - - - - -   - - - - - - - - F F C C C C C B D C C C C F - - - - - - -   - - - - - - - - F F C C C C C B D D C C C C - - - - - - -   - - - - - - - - - C C C C C C B B B B B B - - - - - - - -   - - - - - - - - - - C F F C C B B B B B - - - - - - - - -   - - - - - - - - - - C F F C C B B B B B - - - - - - - - -   - - - - - - - - - - - C C C C B B B B - - - - - - - - - -   - - - - - - - - - - - - B B B B B B - - - - - - - - - - -   - - - - - - - - - - - - B B B B B B - - - - - - - - - - -   - - - - - - - - - - - - - B B B B - - - - - - - - - - - -   - - - - - - - - - - - - - - B B - - - - - - - - - - - - -   - - - - - - - - - - - - - - - - - - - - - - - - - - - - -   - - - - - - - - - - - - - - - - - - - - - - - - - - - - -   - - - - - - - - - - - - - - - - - - - - - - - - - - - - -   - - - - - - - - - - - - - - - - - - - - - - - - - - - - -   - - - - - - - - - - - - - - - - - - - - - - - - - - - - -   
- - - - - - - - - - - - - - - - - - - - - - - - - - - - -   - - - - - - - - - - - - - - - - - - - - - - - - - - - - -   - - K - - - - - - - - - - - - - - - - - - - - - - - - - -   - - - Z - - - - - - - - - - - - - - - - - - - - - - - - -   - - - E A A A A A A A A A A A A A A A A A A A A A A - - -   - - E E - A A A A A A A A A A A A A A A A A A A A A A A -   - - A - - A A A A A A A A A A A A A A A A A A A A A - A -   - - A - A A A A A A A A A A A A A A A A A A A A A A - A -   - - - A - A A A A A A A A A A A A D C C C D A A A - A A -   - - - A - A A A A A A A A A A A A C C C C D A A A A - - -   - - - - - - B B B B B B B B B B B C C C C D B B - - - - -   - - - - - - B B B B B B B B B B B C C C C D B B - - - - -   - - - - - - - B C C C C C C C B B C C C C D B - - - - - -   - - - - - - - B F F C C C C C B B C C C C D B - - - - - -   - - - - - - - - F F C C C C C B B D C C C D - - - - - - -   - - - - - - - - C C C C C C C B B B B B B B - - - - - - -   - - - - - - - - - C C C C C C B B B B B B - - - - - - - -   - - - - - - - - - C C C C C C B B B B B B - - - - - - - -   - - - - - - - - - - C C C C C B B B B B - - - - - - - - -   - - - - - - - - - - - B B B B B B B B - - - - - - - - - -   - - - - - - - - - - - B B B B B B B B - - - - - - - - - -   - - - - - - - - - - - - B B C C C B - - - - - - - - - - -   - - - - - - - - - - - - - B C C C - - - - - - - - - - - -   - - - - - - - - - - - - - B D C C - - - - - - - - - - - -   - - - - - - - - - - - - - - D C - - - - - - - - - - - - -   - - - - - - - - - - - - - - - - - - - - - - - - - - - - -   - - - - - - - - - - - - - - - - - - - - - - - - - - - - -   - - - - - - - - - - - - - - - - - - - - - - - - - - - - -   
- - - - - - - - - - - - - - - - - - - - - - - - - - - - -   - - - - - - - - - - - - - - - - - - - - - - - - - - - - -   - - - - - - - - - - - - - - - - - - - - - - - - - - - - -   - - - - - - - - - - - - - - - - - - - - - - - - N - - - -   - - - E A A A A A A A A A A A A A A A A A A A A A A - - -   - - E E A A A A A A A A A A A A A A A A A A A A A A A A -   - - A - - A A A A A A A A A A A A A A A A A A A A A - A -   - - A - A A A A A A A A A A A A A A A A A A A A A A - A -   - - A A A A A A A A A A A A A A A A C D D A A A A A A A -   - - - A - A A A A A A A A A A A A A C C D A A A A A - - -   - - - - - B B B B B B B B B B B B B C C C B B B B - - - -   - - - - - - B B B B B B B B B B B B D C C B B B - - - - -   - - - - - - B B D C C C C C C B B B C C C B B B - - - - -   - - - - - - - B D C C C C C D B B B C C D B B - - - - - -   - - - - - - - B C C C C C C D B B B C C D B B - - - - - -   - - - - - - - - C C C C C C D B B B B B B B - - - - - - -   - - - - - - - - C C C C C C D B B B B B B B - - - - - - -   - - - - - - - - - C C C C C D B B B B B B - - - - - - - -   - - - - - - - - - - C C C C C B B B B B - - - - - - - - -   - - - - - - - - - - B B B B B B B B B B - - - - - - - - -   - - - - - - - - - - - B B B B B B B B - - - - - - - - - -   - - - - - - - - - - - B B C C C C D B - - - - - - - - - -   - - - - - - - - - - - - B C C C F F - - - - - - - - - - -   - - - - - - - - - - - - B C C F F F - - - - - - - - - - -   - - - - - - - - - - - - - D C F F - - - - - - - - - - - -   - - - - - - - - - - - - - - C C - - - - - - - - - - - - -   - - - - - - - - - - - - - - - - - - - - - - - - - - - - -   - - - - - - - - - - - - - - - - - - - - - - - - - - - - -   
- - - - - - - - - - - - - - - - - - - - - - - - - - - - -   - - - - - - - - - - - - - - - - - - - - - - - - - - - - -   - - - - - - - - - - - - - - - - - - - - - - - - - O - - -   - - - - - - - - - - - - - - - - - - - - - - - - - - - - -   - - A A A A A A A A A A A A A A A A A A A A A A A A - - -   - - A A A A A A A A A A A A A A A A A A A A A A A A A A -   - - A - - A A A A A A A A A A A A A A A A A A A A A A A -   - - A A A A A A A A A A A A A A A A A A A A A A A A A A -   - - A A A A A A A A A A A A A A A A A A A A A A A A A A -   - - - A A A A A A A A A A A A A A A A A A A A A A A - - -   - - - - - B B B B B B B B B B B B B B B B B B B B - - - -   - - - - - - B B B B B B B B B B B B B B B B B B - - - - -   - - - - - - B B B D C C C D B B B B B B B B B B - - - - -   - - - - - - - B B C C C C D B B B B B B B G G - - - - - -   - - - - - - - B B C C C C D B B B B B B B G G - - - - - -   - - - - - - - - B C C C C D B B B B B B B B - - - - - - -   - - - - - - - - B C C C C D B B B B B B B B - - - - - - -   - - - - - - - - - C C C C D B B B B B B B - - - - - - - -   - - - - - - - - - D C C C D B B B B B B B - - - - - - - -   - - - - - - - - - - B B B B B B B B B B - - - - - - - - -   - - - - - - - - - - B B B B B B B B B B - - - - - - - - -   - - - - - - - - - - - B C C C C C C D - - - - - - - - - -   - - - - - - - - - - - B F F C C F F C - - - - - - - - - -   - - - - - - - - - - - - F F C F F F - - - - - - - - - - -   - - - - - - - - - - - - C C C F F C - - - - - - - - - - -   - - - - - - - - - - - - - C C C C - - - - - - - - - - - -   - - - - - - - - - - - - - - C C - - - - - - - - - - - - -   - - - - - - - - - - - - - - C C - - - - - - - - - - - - -   
- - - - - - - - - - - - - - - - - - - - - - - - - Q - - -   - - - - - - - - - - - - - - - - - - - - - - - - R - - - -   - - Ah- - - - - - - - - - - - - - - - - - - I - - - - - -   - - - - - - - - - - - - - - - - - - - - - - - - - - - Ak-   - - A A A A A A A A A A A A A A A A A A A A A A A A - - -   - - A A A A A A A A A A A A A A A A A A A A A A A A A A -   - - A - - A A A A A A A A A A A A A A A A A A A A A A A -   - - E E A A A A A A A A A A A A A A A A A A A A A A A A -   - - E E A A A A A A A A A A A A A A A A A A A A A A A A -   - - - A A A A A A A A A A A A A A A A A A A A A A A - - -   - - - - - B B B B B B B B B B B B B B B B B B B B - - - -   - - - - - - B B B B B B B B B B B B B B B B B B - - - - -   - - - - - - B B B B C D D B B B B B B B B B B B - - - - -   - - - - - - - G G B C C D B B B B B B B B G G - - - - - -   - - - - - - - G G B C C C B B B B B B B B G G - - - - - -   - - - - - - - - B B D C C B B B B B B B B B - - - - - - -   - - - - - - - - B B C C C B B B B B B B B B - - - - - - -   - - - - - - - - - B C C D B B B B B B B B - - - - - - - -   - - - - - - - - - B C C D B B B B B B B B - - - - - - - -   - - - - - - - - - - B B B B B B B B B B - - - - - - - - -   - - - - - - - - - - B B B B B B B B B B - - - - - - - - -   - - - - - - - - - - - B C C C C C C C - - - - - - - - - -   - - - - - - - - - - - B F F C C C C C - - - - - - - - - -   - - - - - - - - - - - - F F C C C C - - - - - - - - - - -   - - - - - - - - - - - - C C C C C C - - - - - - - - - - -   - - - - - - - - - - - - - C C C C - - - - - - - - - - - -   - - - - - - - - - - - - - - C C - - - - - - - - - - - - -   - - - - - - - - - - - - - - C C - - - - - - - - - - - - -   
- - - - - - - - - - - - - - - - - - - - - - - - - - - - -   - - Ag- - - - - - - - - - - - - - - - - - - - - - - - - -   - - - - - - - - - - - - - - - - - - - - - - - - - - - - -   - - - - P - - - - - - - - - - - - - - - - - - L - - I - N   - - - A A A A A A A A A A A A A A A A A A A A A A A - - -   - - A A - A A A A A A A A A A A A A A A A A A A A A A A -   - - A - - A A A A A A A A A A A A A A A A A A A A A - A -   - - E - A A A A A A A A A A A A A A A A A A A A A A - A -   - - - E A A A A A A A A A A A A A A C C C A A A A A A A -   - - - A - A A A A A A A A A A A A A C C C A A A A A - - -   - - - - - B B B B B B B B B B B B B D C C B B B B - - - -   - - - - - - B B B B B B B B B B B B D C C B G G - - - - -   - - - - - - B B B B B B B B B B B B D C C B G G - - - - -   - - - - - - - G G B B B B B B B B B C C C B B - - - - - -   - - - - - - - G G B B B B B B B B B C D D B B - - - - - -   - - - - - - - - B B B B B B B B B B B B B B - - - - - - -   - - - - - - - - B B B B B B B B B B B B B B - - - - - - -   - - - - - - - - - B B B B B B B B B B B B - - - - - - - -   - - - - - - - - - - B B B B B B B B B B - - - - - - - - -   - - - - - - - - - - B B B B B B B B B B - - - - - - - - -   - - - - - - - - - - - B B B B B B B B - - - - - - - - - -   - - - - - - - - - - - B D C C C C C C - - - - - - - - - -   - - - - - - - - - - - - D C C C C C - - - - - - - - - - -   - - - - - - - - - - - - C C C C C C - - - - - - - - - - -   - - - - - - - - - - - - - C C C C - - - - - - - - - - - -   - - - - - - - - - - - - - - C C - - - - - - - - - - - - -   - - - - - - - - - - - - - - - - - - - - - - - - - - - - -   - - - - - - - - - - - - - - - - - - - - - - - - - - - - -   
- - Af- - - - - - - - - - - - - - - - - - - - - - - - - -   - - - - - - - - - - - - - - - - - - - - - - - - - - - - -   - - - - - - - - - - - - - - - - - - - - - - - - H - - - -   - - - - - - - - - - - - - - - - - - - - - - - - - R - - -   - - - A A A A A A A A A A A A A A A A A A A A A A A - - -   - - A A - A A A A A A A A A A A A A A A A A A A A A A A -   - - A A - A A A A A A A A A A A A A A A A A A A A A A A -   - - A A A A A A A A A A A A A A A A A A A A A A A A A A -   - - - A - A A A A A A A A A A A A C C C C D A A A A - - -   - - - A A A A A A A A A A A A A A C C C C D A A A A - - -   - - - - - - B B B B B B B B B B B C C C C C B B - - - - -   - - - - - - B B B B B B B B B B B D C C C C G G - - - - -   - - - - - - - B B B B B B B B B B D C C C C G - - - - - -   - - - - - - - B B B B B B B B B B C C C C C B - - - - - -   - - - - - - - - B B B B B B B B B C C C D D - - - - - - -   - - - - - - - - B B B B B B B B B B B B B B - - - - - - -   - - - - - - - - - B B B B B B B B B B B B - - - - - - - -   - - - - - - - - - B B B B B B B B B B B B - - - - - - - -   - - - - - - - - - - B B B B B B B B B B - - - - - - - - -   - - - - - - - - - - - B B B B B B B B - - - - - - - - - -   - - - - - - - - - - - B B B B B B B B - - - - - - - - - -   - - - - - - - - - - - - B D C C C D - - - - - - - - - - -   - - - - - - - - - - - - - C C C C - - - - - - - - - - - -   - - - - - - - - - - - - - C C C C - - - - - - - - - - - -   - - - - - - - - - - - - - - C C - - - - - - - - - - - - -   - - - - - - - - - - - - - - - - - - - - - - - - - - - - -   - - - - - - - - - - - - - - - - - - - - - - - - - - - - -   - - - - - - - - - - - - - - - - - - - - - - - - - - - - -   
- - - - - - - - - - - - - - - - - - - - - - - - - - - - -   - - - - - - - - - - - - - - - - - - - - - - - - - - - - -   - - - - - - - - - - - - - - - - - - - - - - - - - - - - -   - - - - - - - - - - - - - - - - - - - - - - - - - - - - -   - - - A A A A A A A A A A A A A A A A A A A A A A A - - -   - - - A - A A A A A A A A A A A A A A A A A A A A A - - -   - - - A - A A A A A A A A A A A A A A A A A A A A A - - -   - - - A A A A A A A A A A A A A A A A A A A A A E E - - -   - - - A - A A A A A A A A A A A C C C C C C D A E E - - -   - - - A A A A A A A A A A A A A C C C C C C C A A A - - -   - - - - - - B B B B B B B B B B C C C C C C C B - - - - -   - - - - - - - B B B B B B B B B C C C C C C C - - - - - -   - - - - - - - B B B B B B B B B C C C C C C C - - - - - -   - - - - - - - - B B B B B B B B C C C C C C - - - - - - -   - - - - - - - - B B B B B B B B C C C C C C - - - - - - -   - - - - - - - - - B G G B B B B B B B B B - - - - - - - -   - - - - - - - - - - G G B B B B B B B B - - - - - - - - -   - - - - - - - - - - B B B B B B B G G B - - - - - - - - -   - - - - - - - - - - - B B B B B B G G - - - - - - - - - -   - - - - - - - - - - - - B B B B B B - - - - - - - - - - -   - - - - - - - - - - - - B B B B B B - - - - - - - - - - -   - - - - - - - - - - - - - B C D D - - - - - - - - - - - -   - - - - - - - - - - - - - - C C - - - - - - - - - - - - -   - - - - - - - - - - - - - - - - - - - - - - - - - - - - -   - - - - - - - - - - - - - - - - - - - - - - - - - - - - -   - - - - - - - - - - - - - - - - - - - - - - - - - - - - -   - - - - - - - - - - - - - - - - - - - - - - - - - - - - -   - - - - - - - - - - - - - - - - - - - - - - - - - - - - -   
- - - - - - - - - - - - - - - - - - - - - - - - - - - - -   - - - - - - - - - - - - - - - - - - - - - - - - - - - - -   - - - - - - - - - - - - - - - - - - - - - - - - - - - - -   - - - - - - - - - - - - - - - - - - - - - - - - - - - - -   - - - A A A A A A A A A A A A A A A A A A A A A A A - - -   - - - A - - A A A A A A A A A A A A A A A A A A A A - - -   - - - A - - A A A A A A A A A A A A A A A A A A A A - - -   - - - E - A A A A A C C C A A A A A A A A A A A E E - - -   - - - E - A A A A A D C C A A A C C C C C C C A E E - - -   - - - - A - A A A A D C C A A A C C C C C C C A A A - - -   - - - - - - - B B B D C C B B B C C C C C C C - - - - - -   - - - - - - - B B B C C C B B B C C C C C C C - - - - - -   - - - - - - - - B B C D D B B B C C C C C C - - - - - - -   - - - - - - - - B B B B B B B B C C C F F C - - - - - - -   - - - - - - - - - B B B B B B B D C C F F - - - - - - - -   - - - - - - - - - - G G B B B B B B B B - - - - - - - - -   - - - - - - - - - - G G B B B B B B B B - - - - - - - - -   - - - - - - - - - - - B B B B B B G G - - - - - - - - - -   - - - - - - - - - - - - B B B B B G - - - - - - - - - - -   - - - - - - - - - - - - - B B B B - - - - - - - - - - - -   - - - - - - - - - - - - - - B B - - - - - - - - - - - - -   - - - - - - - - - - - - - - - - - - - - - - - - - - - - -   - - - - - - - - - - - - - - - - - - - - - - - - - - - - -   - - - - - - - - - - - - - - - - - - - - - - - - - - - - -   - - - - - - - - - - - - - - - - - - - - - - - - - - - - -   - - - - - - - - - - - - - - - - - - - - - - - - - - - - -   - - - - - - - - - - - - - - - - - - - - - - - - - - - - -   - - - - - - - - - - - - - - - - - - - - - - - - - - - - -   
- - - I - - - - - - - - - - - - - - - - - - - - - - W - -   - - - - - - - - - - - - - - - - - - - - - - - - - - - - -   - - H - - - - - - - - - - - - - - - - - - - - - - J - - -   - - - - - - - - - - - - - - - - - - - - - - - - - - - - -   - - - - A A A A A A A A A A A A A A A A A A A A A A - - -   - - - - A - - A A A A A A A A A A A A A A A A - A A - - -   - - - - - - - A A A A A A A A A A A A A A A A A A A - - -   - - - - - A A A A C C C C D A A A A A A A A A A A A - - -   - - - - E - A A A C C C C C A A D C C C C C C A A A - - -   - - - - A A A A A D C C C C A A D C C C C C D - A A - - -   - - - - - - - B B D C C C C B B C C C C C C D - - - - - -   - - - - - - - - B C C C C C B B C C C C C C - - - - - - -   - - - - - - - - - C C C D D B B C C C C C - - - - - - - -   - - - - - - - - - B B B B B B B D C C F F - - - - - - - -   - - - - - - - - - - B B B B B B D D C F - - - - - - - - -   - - - - - - - - - - - B B B B B B B B - - - - - - - - - -   - - - - - - - - - - - - B B B B B B - - - - - - - - - - -   - - - - - - - - - - - - B B B B B B - - - - - - - - - - -   - - - - - - - - - - - - - - B B - - - - - - - - - - - - -   - - - - - - - - - - - - - - - - - - - - - - - - - - - - -   - - - - - - - - - - - - - - - - - - - - - - - - - - - - -   - - - - - - - - - - - - - - - - - - - - - - - - - - - - -   - - - - - - - - - - - - - - - - - - - - - - - - - - - - -   - - - - - - - - - - - - - - - - - - - - - - - - - - - - -   - - - - - - - - - - - - - - - - - - - - - - - - - - - - -   - - - - - - - - - - - - - - - - - - - - - - - - - - - - -   - - - - - - - - - - - - - - - - - - - - - - - - - - - - -   - - - - - - - - - - - - - - - - - - - - - - - - - - - - -   
- - - - - - - - - - - - - - - - - - - - - - - - - - - - -   - - - Ad- - - - - - - - - - - - - - - - - - - - - - X - -   - - - - - - - - - - - - - - - - - - - V - - - - - - - - -   - - - M - - - - - - - - - - - - - - - - - - - - L - - - -   - - - - E E A A A A A A A A A A A A A A A A A A A - - - -   - - - - E E - - A A A A A A A A A A A A A A - - A A - - -   - - - - A - - - C A A A A A A A A A A A A A A A A A - - -   - - - - A - A A C C C C C C C A A A A A A A A A A A - - -   - - - - A A - A C C C C C C C A A D C C C D A - A - - - -   - - - - A A A A C C C C C C C A A C C C C D A A A - - - -   - - - - - - - - C C C C C C C B B C C C C D - - - - - - -   - - - - - - - - - C C F F C C B B C C C C - - - - - - - -   - - - - - - - - - - C F F C C B B C C C - - - - - - - - -   - - - - - - - - - - B B B B G G B C C C - - - - - - - - -   - - - - - - - - - - - B B B G G B D C - - - - - - - - - -   - - - - - - - - - - - - B B B B B B - - - - - - - - - - -   - - - - - - - - - - - - - B B B B - - - - - - - - - - - -   - - - - - - - - - - - - - - - - - - - - - - - - - - - - -   - - - - - - - - - - - - - - - - - - - - - - - - - - - - -   - - - - - - - - - - - - - - - - - - - - - - - - - - - - -   - - - - - - - - - - - - - - - - - - - - - - - - - - - - -   - - - - - - - - - - - - - - - - - - - - - - - - - - - - -   - - - - - - - - - - - - - - - - - - - - - - - - - - - - -   - - - - - - - - - - - - - - - - - - - - - - - - - - - - -   - - - - - - - - - - - - - - - - - - - - - - - - - - - - -   - - - - - - - - - - - - - - - - - - - - - - - - - - - - -   - - - - - - - - - - - - - - - - - - - - - - - - - - - - -   - - - - - - - - - - - - - - - - - - - - - - - - - - - - -   
- - - - - - J - - - - - - - - - - - - - - - - - - - - - -   - - - - - - - - - - - - - - - - - - - - - - - - - - - - -   - - - - - I - - - - - - - - - - - - - - - - - - - - - - -   - - - - - - - - - - - - - - - - - - - - Z - - H - X - - -   - - - - - E A A A A A A A A A A A A A A A A A A - - - - -   - - - - E E - - A A A A A A A A A A A A A - - A A - - - -   - - - - A A - - C C C A A A A A A A A A A A A - A - - - -   - - - - A A - A C C C C C C C A A A A A A A A - A - - - -   - - - - A A A - C C C C C C C A A A C D D A - A A - - - -   - - - - - A A A C C C C C C C A A A C C D A A A - - - - -   - - - - - - - - - C C C C C C B B B C C C - - - - - - - -   - - - - - - - - - - C F F C C B B B D C - - - - - - - - -   - - - - - - - - - - - F F C C B B B C - - - - - - - - - -   - - - - - - - - - - - - B B G G B B - - - - - - - - - - -   - - - - - - - - - - - - - B G G B - - - - - - - - - - - -   - - - - - - - - - - - - - - - - - - - - - - - - - - - - -   - - - - - - - - - - - - - - - - - - - - - - - - - - - - -   - - - - - - - - - - - - - - - - - - - - - - - - - - - - -   - - - - - - - - - - - - - - - - - - - - - - - - - - - - -   - - - - - - - - - - - - - - - - - - - - - - - - - - - - -   - - - - - - - - - - - - - - - - - - - - - - - - - - - - -   - - - - - - - - - - - - - - - - - - - - - - - - - - - - -   - - - - - - - - - - - - - - - - - - - - - - - - - - - - -   - - - - - - - - - - - - - - - - - - - - - - - - - - - - -   - - - - - - - - - - - - - - - - - - - - - - - - - - - - -   - - - - - - - - - - - - - - - - - - - - - - - - - - - - -   - - - - - - - - - - - - - - - - - - - - - - - - - - - - -   - - - - - - - - - - - - - - - - - - - - - - - - - - - - -   
- - - - - - - - - - - - - - - - - - - - - H - - - - - - -   - - - - - - T - - - - - - - - - - - - - - - - - - - - - -   - - - - - - - - - - - - - - - - - - - - J U - - - - - - -   - - - - - - Am- - - - - - - - - - - - - - - O - - - - - -   - - - - - A A A A A A A A A A A A A A A A A E E - - - - -   - - - - - A A - - A A A A A A A A A A A - - E E - - - - -   - - - - - A A - - C C C A A A A A A A A A A - A - - - - -   - - - - - A A - E C C C C C D A A A A A A A - A - - - - -   - - - - - A A E - C C C C C D A A A A A A - A A - - - - -   - - - - - - A A C - C C C C D A A A A A - A A A - - - - -   - - - - - - - - - - - C C C D B B B B - - - - - - - - - -   - - - - - - - - - - - - C C D B B B - - - - - - - - - - -   - - - - - - - - - - - - - C C B B - - - - - - - - - - - -   - - - - - - - - - - - - - - - - - - - - - - - - - - - - -   - - - - - - - - - - - - - - - - - - - - - - - - - - - - -   - - - - - - - - - - - - - - - - - - - - - - - - - - - - -   - - - - - - - - - - - - - - - - - - - - - - - - - - - - -   - - - - - - - - - - - - - - - - - - - - - - - - - - - - -   - - - - - - - - - - - - - - - - - - - - - - - - - - - - -   - - - - - - - - - - - - - - - - - - - - - - - - - - - - -   - - - - - - - - - - - - - - - - - - - - - - - - - - - - -   - - - - - - - - - - - - - - - - - - - - - - - - - - - - -   - - - - - - - - - - - - - - - - - - - - - - - - - - - - -   - - - - - - - - - - - - - - - - - - - - - - - - - - - - -   - - - - - - - - - - - - - - - - - - - - - - - - - - - - -   - - - - - - - - - - - - - - - - - - - - - - - - - - - - -   - - - - - - - - - - - - - - - - - - - - - - - - - - - - -   - - - - - - - - - - - - - - - - - - - - - - - - - - - - -   
- - - - - - - - - - - - - - - - - - - - - - - - - - - - -   - - - - - - - - - K - - - - - - - - - - - Ae- - - - - - -   - - - - - - - - - - - - - - - - - - - - - - - - - - - - -   - - - - - - - - An- - - - - - - - - - M - - - - - - - - -   - - - - - - - - A A A A A A A A A A A A A A - - - - - - -   - - - - - - - A A A A A A - A A A A A A A A E - - - - - -   - - - - - - - A - A A A A - A A A A A A A A A - - - - - -   - - - - - - - E - C C C C D A A A A A A A A A - - - - - -   - - - - - - - E E C C C C D A A A A A E E A A - - - - - -   - - - - - - - - A C C C C D A A A A A E E A - - - - - - -   - - - - - - - - - - - - - D B B B - - - - - - - - - - - -   - - - - - - - - - - - - - - - - - - - - - - - - - - - - -   - - - - - - - - - - - - - - - - - - - - - - - - - - - - -   - - - - - - - - - - - - - - - - - - - - - - - - - - - - -   - - - - - - - - - - - - - - - - - - - - - - - - - - - - -   - - - - - - - - - - - - - - - - - - - - - - - - - - - - -   - - - - - - - - - - - - - - - - - - - - - - - - - - - - -   - - - - - - - - - - - - - - - - - - - - - - - - - - - - -   - - - - - - - - - - - - - - - - - - - - - - - - - - - - -   - - - - - - - - - - - - - - - - - - - - - - - - - - - - -   - - - - - - - - - - - - - - - - - - - - - - - - - - - - -   - - - - - - - - - - - - - - - - - - - - - - - - - - - - -   - - - - - - - - - - - - - - - - - - - - - - - - - - - - -   - - - - - - - - - - - - - - - - - - - - - - - - - - - - -   - - - - - - - - - - - - - - - - - - - - - - - - - - - - -   - - - - - - - - - - - - - - - - - - - - - - - - - - - - -   - - - - - - - - - - - - - - - - - - - - - - - - - - - - -   - - - - - - - - - - - - - - - - - - - - - - - - - - - - -   
- - - - - - - - U - - - - - - - - - - - - - - - - - - - -   - - - - - - - - - - - - - - - - - - - - - - - - - - - - -   - - - - - - - - K - - - - - - - - - - - - - - - - - - - -   - - - - - - - - - - - - - - - - - - - - - - - - - - - - -   - - - - - - - - A A A A A A A A A A A A A - - - - - - - -   - - - - - - - - A E E A - A A A A A A A A A - - - - - - -   - - - - - - - - A E - A - A A A A A A - A A - - - - - - -   - - - - - - - - A A - C D A A A A A A - A A - - - - - - -   - - - - - - - - A A C E - A A A A - A E E - - - - - - - -   - - - - - - - - - A D E E A A A A A A E E - - - - - - - -   - - - - - - - - - - - - - - - - - - - - - - - - - - - - -   - - - - - - - - - - - - - - - - - - - - - - - - - - - - -   - - - - - - - - - - - - - - - - - - - - - - - - - - - - -   - - - - - - - - - - - - - - - - - - - - - - - - - - - - -   - - - - - - - - - - - - - - - - - - - - - - - - - - - - -   - - - - - - - - - - - - - - - - - - - - - - - - - - - - -   - - - - - - - - - - - - - - - - - - - - - - - - - - - - -   - - - - - - - - - - - - - - - - - - - - - - - - - - - - -   - - - - - - - - - - - - - - - - - - - - - - - - - - - - -   - - - - - - - - - - - - - - - - - - - - - - - - - - - - -   - - - - - - - - - - - - - - - - - - - - - - - - - - - - -   - - - - - - - - - - - - - - - - - - - - - - - - - - - - -   - - - - - - - - - - - - - - - - - - - - - - - - - - - - -   - - - - - - - - - - - - - - - - - - - - - - - - - - - - -   - - - - - - - - - - - - - - - - - - - - - - - - - - - - -   - - - - - - - - - - - - - - - - - - - - - - - - - - - - -   - - - - - - - - - - - - - - - - - - - - - - - - - - - - -   - - - - - - - - - - - - - - - - - - - - - - - - - - - - -   
- - - - - - - - - - - - - - - - - - - - - - - - - - - - -   - - - - - - - - - - - - - - - - - - - - - - - - - - - - -   - - - - - - - - - - - - - - - - - - - - - - - - - - - - -   - - - - - - - - - - - - - - - - - - - - - - - - - - - - -   - - - - - - - - - - A A A A A A A A A A - - - - - - - - -   - - - - - - - - - E E A A A A A A A A A - - - - - - - - -   - - - - - - - - - E E A - - A A - A A A - - - - - - - - -   - - - - - - - - - A A A - - A A - A A A - - - - - - - - -   - - - - - - - - - - A E E A A A A A A A - - - - - - - - -   - - - - - - - - - - - E E A A A A A A - - - - - - - - - -   - - - - - - - - - - - - - - - - - - - - - - - - - - - - -   - - - - - - - - - - - - - - - - - - - - - - - - - - - - -   - - - - - - - - - - - - - - - - - - - - - - - - - - - - -   - - - - - - - - - - - - - - - - - - - - - - - - - - - - -   - - - - - - - - - - - - - - - - - - - - - - - - - - - - -   - - - - - - - - - - - - - - - - - - - - - - - - - - - - -   - - - - - - - - - - - - - - - - - - - - - - - - - - - - -   - - - - - - - - - - - - - - - - - - - - - - - - - - - - -   - - - - - - - - - - - - - - - - - - - - - - - - - - - - -   - - - - - - - - - - - - - - - - - - - - - - - - - - - - -   - - - - - - - - - - - - - - - - - - - - - - - - - - - - -   - - - - - - - - - - - - - - - - - - - - - - - - - - - - -   - - - - - - - - - - - - - - - - - - - - - - - - - - - - -   - - - - - - - - - - - - - - - - - - - - - - - - - - - - -   - - - - - - - - - - - - - - - - - - - - - - - - - - - - -   - - - - - - - - - - - - - - - - - - - - - - - - - - - - -   - - - - - - - - - - - - - - - - - - - - - - - - - - - - -   - - - - - - - - - - - - - - - - - - - - - - - - - - - - -   
- - - - - - - - - - - - - - - - - - - - - - - - - - - - -   - - - - - - - - - - - - - - - - - - - - - - - - - - - - -   - - - - - - - - - - - - - - - - - - - - - - - - - - - - -   - - - - - - - - - - - - - - - - - - - - - - - - - - - - -   - - - - - - - - - - - - - - - - - - - - - - - - - - - - -   - - - - - - - - - - - - A A A A A A - - - - - - - - - - -   - - - - - - - - - - - - A A A A A A - - - - - - - - - - -   - - - - - - - - - - - - A A A A A A - - - - - - - - - - -   - - - - - - - - - - - - A A A A A - - - - - - - - - - - -   - - - - - - - - - - - - - - - - - - - - - - - - - - - - -   - - - - - - - - - - - - - - - - - - - - - - - - - - - - -   - - - - - - - - - - - - - - - - - - - - - - - - - - - - -   - - - - - - - - - - - - - - - - - - - - - - - - - - - - -   - - - - - - - - - - - - - - - - - - - - - - - - - - - - -   - - - - - - - - - - - - - - - - - - - - - - - - - - - - -   - - - - - - - - - - - - - - - - - - - - - - - - - - - - -   - - - - - - - - - - - - - - - - - - - - - - - - - - - - -   - - - - - - - - - - - - - - - - - - - - - - - - - - - - -   - - - - - - - - - - - - - - - - - - - - - - - - - - - - -   - - - - - - - - - - - - - - - - - - - - - - - - - - - - -   - - - - - - - - - - - - - - - - - - - - - - - - - - - - -   - - - - - - - - - - - - - - - - - - - - - - - - - - - - -   - - - - - - - - - - - - - - - - - - - - - - - - - - - - -   - - - - - - - - - - - - - - - - - - - - - - - - - - - - -   - - - - - - - - - - - - - - - - - - - - - - - - - - - - -   - - - - - - - - - - - - - - - - - - - - - - - - - - - - -   - - - - - - - - - - - - - - - - - - - - - - - - - - - - -   - - - - - - - - - - - - - - - - - - - - - - - - - - - - -   
