model
size = 18 12 19, scale = 0.05, origin = -y
material 
  colors = A:#06F B:#036
voxels
-BBBBBBBBBBBBBBBB- -BBBBBBBBBBBBBBBB- ------------------ ------------------ ------------------ ------------------ ------------------ ------------------ ------------------ ------------------ ------------------ ------------------ 
BBBBBBBBBBBBBBBBBB BBBBBBBBBBBBBBBBBB ------------------ ------------------ ------------------ ------------------ ------------------ ------------------ ------------------ ------------------ ------------------ ------------------ 
BB--------------BB BB--------------BB --AAAAAAAAAAAAAA-- --AAAAAAAAAAAAAA-- --AAAAAAAAAAAAAA-- --AAAAAAAAAAAAAA-- --AAAAAAAAAAAAAA-- --AAAAAAAAAAAAAA-- ---AAAAAAAAAAAA--- ------------------ ------------------ ------------------ 
BB--------------BB BB--------------BB --A------------A-- --A------------A-- --A------------A-- --A------------A-- --A------------A-- --AAAAAAAAAAAAAA-- --AAAAAAAAAAAAAA-- ------------------ ------------------ ------------------ 
BB--------------BB BB--------------BB --A------------A-- --A------------A-- --A------------A-- --A------------A-- --A------------A-- --AAAAAAAAAAAAAA-- --AAAAAAAAAAAAAA-- ------------------ ------------------ ------------------ 
BB--------------BB BB--------------BB --A------------A-- --A------------A-- --A------------A-- --A------------A-- --A------------A-- --AAAAAAAAAAAAAA-- --AAAAAAAAAAAAAA-- ------------------ ------------------ ------------------ 
BB--------------BB BB--------------BB --A------------A-- --A------------A-- --A------------A-- --A------------A-- --A------------A-- --AAAAAAAAAAAAAA-- --AAAAAAAAAAAAAA-- --------AA-------- ------------------ ------------------ 
BB--------------BB BB--------------BB --A------------A-- --A------------A-- --A------------A-- --A------------A-- --A------------A-- --AAAAAAAAAAAAAA-- --AAAAAAAAAAAAAA-- -------AAAA------- ------------------ ------------------ 
BB--------------BB BB--------------BB --A------------A-- --A------------A-- --A------------A-- --A------------A-- --A------------A-- --AAAAAAAAAAAAAA-- --AAAAAAAAAAAAAA-- -------AAAA------- -------AAAA------- ------------------ 
BB--------------BB BB--------------BB --A------------A-- --A------------A-- --A------------A-- --A------------A-- --A------------A-- --AAAAAAAAAAAAAA-- --AAAAAAAAAAAAAA-- ------AAAAAA------ -------AAAA------- --------AA-------- 
BB--------------BB BB--------------BB --A------------A-- --A------------A-- --A------------A-- --A------------A-- --A------------A-- --AAAAAAAAAAAAAA-- --AAAAAAAAAAAAAA-- -------AAAA------- -------AAAA------- ------------------ 
BB--------------BB BB--------------BB --A------------A-- --A------------A-- --A------------A-- --A------------A-- --A------------A-- --AAAAAAAAAAAAAA-- --AAAAAAAAAAAAAA-- -------AAAA------- ------------------ ------------------ 
BB--------------BB BB--------------BB --A------------A-- --A------------A-- --A------------A-- --A------------A-- --A------------A-- --AAAAAAAAAAAAAA-- --AAAAAAAAAAAAAA-- --------AA-------- ------------------ ------------------ 
BB--------------BB BB--------------BB --A------------A-- --A------------A-- --A------------A-- --A------------A-- --A------------A-- --AAAAAAAAAAAAAA-- --AAAAAAAAAAAAAA-- ------------------ ------------------ ------------------ 
BB--------------BB BB--------------BB --A------------A-- --A------------A-- --A------------A-- --A------------A-- --A------------A-- --AAAAAAAAAAAAAA-- --AAAAAAAAAAAAAA-- ------------------ ------------------ ------------------ 
BB--------------BB BB--------------BB --A------------A-- --A------------A-- --A------------A-- --A------------A-- --A------------A-- --AAAAAAAAAAAAAA-- --AAAAAAAAAAAAAA-- ------------------ ------------------ ------------------ 
BB--------------BB BB--------------BB --AAAAAAAAAAAAAA-- --AAAAAAAAAAAAAA-- --AAAAAAAAAAAAAA-- --AAAAAAAAAAAAAA-- --AAAAAAAAAAAAAA-- --AAAAAAAAAAAAAA-- ---AAAAAAAAAAAA--- ------------------ ------------------ ------------------ 
BBBBBBBBBBBBBBBBBB BBBBBBBBBBBBBBBBBB ------------------ ------------------ ------------------ ------------------ ------------------ ------------------ ------------------ ------------------ ------------------ ------------------ 
-BBBBBBBBBBBBBBBB- -BBBBBBBBBBBBBBBB- ------------------ ------------------ ------------------ ------------------ ------------------ ------------------ ------------------ ------------------ ------------------ ------------------ 
