model
size = 29 28 27, scale = 0.05, origin = -y
material 
  colors = A:#6C9 B:#010 C:#070 D:#EEE E:#0E0 F:#F96 G:#F9F H:#F99 I:#F33 J:#F36 K:#FCF L:#F6F M:#F0C N:#FC6 O:#FC3 P:#FF6 Q:#F0F R:#FFF S:#CFC T:#F9C U:#F06 V:#CC3 W:#F3F X:#F03 Y:#F90 Z:#CFF Aa:#CCF Ab:#F60 Ac:#F69 Ad:#F66 Ae:#F6C Af:#F09 Ag:#CF0 Ah:#CCC Ai:#F3C Aj:#FF9 Ak:#CC0 Al:#CF6
voxels
- - - - - - - - - - - - - - - - - - - - - - - - - - - - -   - - - - - - - - - - - - - - - - - - - - - - - - - - - - -   - - - - - - - - - - - - - - - - - - - - - - - - - - - - -   - - - - - - - - - - - - - - - - - - - - - - - - - - - - -   - - - - - - - - - - - - - - - - - - - - - - - - - - - - -   - - - - - - - - - - - A A A A A A - - - - - - - - - - - -   - - - - - - - - - - - A A A A A A - - - - - - - - - - - -   - - - - - - - - - - - A A A A A A - - - - - - - - - - - -   - - - - - - - - - - - - A A A A A - - - - - - - - - - - -   - - - - - - - - - - - - - - - - - - - - - - - - - - - - -   - - - - - - - - - - - - - - - - - - - - - - - - - - - - -   - - - - - - - - - - - - - - - - - - - - - - - - - - - - -   - - - - - - - - - - - - - - - - - - - - - - - - - - - - -   - - - - - - - - - - - - - - - - - - - - - - - - - - - - -   - - - - - - - - - - - - - - - - - - - - - - - - - - - - -   - - - - - - - - - - - - - - - - - - - - - - - - - - - - -   - - - - - - - - - - - - - - - - - - - - - - - - - - - - -   - - - - - - - - - - - - - - - - - - - - - - - - - - - - -   - - - - - - - - - - - - - - - - - - - - - - - - - - - - -   - - - - - - - - - - - - - - - - - - - - - - - - - - - - -   - - - - - - - - - - - - - - - - - - - - - - - - - - - - -   - - - - - - - - - - - - - - - - - - - - - - - - - - - - -   - - - - - - - - - - - - - - - - - - - - - - - - - - - - -   - - - - - - - - - - - - - - - - - - - - - - - - - - - - -   - - - - - - - - - - - - - - - - - - - - - - - - - - - - -   - - - - - - - - - - - - - - - - - - - - - - - - - - - - -   - - - - - - - - - - - - - - - - - - - - - - - - - - - - -   - - - - - - - - - - - - - - - - - - - - - - - - - - - - -   
- - - - - - - - - - - - - - - - - - - - - - - - - - - - -   - - - - - - - - - - - - - - - - - - - - - - - - - - - - -   - - - - - - - - - - - - - - - - - - - - - - - - - - - - -   - - - - - - - - - - - - - - - - - - - - - - - - - - - - -   - - - - - - - - - A A A A A A A A A A - - - - - - - - - -   - - - - - - - - - A A A A A A A A A A A - - - - - - - - -   - - - - - - - - - A A A - - - - - A A A - - - - - - - - -   - - - - - - - - - A A A - A A - - A A A - - - - - - - - -   - - - - - - - - - A A A A A A A A A A - - - - - - - - - -   - - - - - - - - - - A A A A A A A A - - - - - - - - - - -   - - - - - - - - - - - - - - - - - - - - - - - - - - - - -   - - - - - - - - - - - - - - - - - - - - - - - - - - - - -   - - - - - - - - - - - - - - - - - - - - - - - - - - - - -   - - - - - - - - - - - - - - - - - - - - - - - - - - - - -   - - - - - - - - - - - - - - - - - - - - - - - - - - - - -   - - - - - - - - - - - - - - - - - - - - - - - - - - - - -   - - - - - - - - - - - - - - - - - - - - - - - - - - - - -   - - - - - - - - - - - - - - - - - - - - - - - - - - - - -   - - - - - - - - - - - - - - - - - - - - - - - - - - - - -   - - - - - - - - - - - - - - - - - - - - - - - - - - - - -   - - - - - - - - - - - - - - - - - - - - - - - - - - - - -   - - - - - - - - - - - - - - - - - - - - - - - - - - - - -   - - - - - - - - - - - - - - - - - - - - - - - - - - - - -   - - - - - - - - - - - - - - - - - - - - - - - - - - - - -   - - - - - - - - - - - - - - - - - - - - - - - - - - - - -   - - - - - - - - - - - - - - - - - - - - - - - - - - - - -   - - - - - - - - - - - - - - - - - - - - - - - - - - - - -   - - - - - - - - - - - - - - - - - - - - - - - - - - - - -   
- - - - - - - - - - - - - - - - - - - - S - - - - - - - -   - - - - - - - - - - - - - - - - - - - - - - - - - - - - -   - - - - - - - - - - - - - - - - - - - - I - - - - - - - -   - - - - - - - - - - - - - - - - - - - - - - - - - - - - -   - - - - - - - - A A A A A A A A A A A A A - - - - - - - -   - - - - - - - A A A - - - - - - - - A A A - - - - - - - -   - - - - - - - A A - - - - - - - - - - A A - - - - - - - -   - - - - - - - A A - A A A A A A A A - A A - - - - - - - -   - - - - - - - - A A A - A A A A - A A A A - - - - - - - -   - - - - - - - - A A A A A A A A A A A A - - - - - - - - -   - - - - - - - - - - - - - - - - - - - - - - - - - - - - -   - - - - - - - - - - - - - - - - - - - - - - - - - - - - -   - - - - - - - - - - - - - - - - - - - - - - - - - - - - -   - - - - - - - - - - - - - - - - - - - - - - - - - - - - -   - - - - - - - - - - - - - - - - - - - - - - - - - - - - -   - - - - - - - - - - - - - - - - - - - - - - - - - - - - -   - - - - - - - - - - - - - - - - - - - - - - - - - - - - -   - - - - - - - - - - - - - - - - - - - - - - - - - - - - -   - - - - - - - - - - - - - - - - - - - - - - - - - - - - -   - - - - - - - - - - - - - - - - - - - - - - - - - - - - -   - - - - - - - - - - - - - - - - - - - - - - - - - - - - -   - - - - - - - - - - - - - - - - - - - - - - - - - - - - -   - - - - - - - - - - - - - - - - - - - - - - - - - - - - -   - - - - - - - - - - - - - - - - - - - - - - - - - - - - -   - - - - - - - - - - - - - - - - - - - - - - - - - - - - -   - - - - - - - - - - - - - - - - - - - - - - - - - - - - -   - - - - - - - - - - - - - - - - - - - - - - - - - - - - -   - - - - - - - - - - - - - - - - - - - - - - - - - - - - -   
- - - - - - - - - - - - - - - - - - - - - - - - - - - - -   - - - - - - - Ac- - - - - - - - - - - I - - - - - - - - -   - - - - - - - - - - - - - - - - - - - - - - - - - - - - -   - - - - - - - - - K - - - - - - - - - - Al- - - - - - - -   - - - - - - - A A A A A A A A A A A A A A - - - - - - - -   - - - - - - A A A - - - - A A - - - - - A A - - - - - - -   - - - - - - A A - - - - - - - - - - - - - A - - - - - - -   - - - - - - A A A A A A A A A A A A A A - A - - - - - - -   - - - - - - A A A A A A A B B B A A A A A A - - - - - - -   - - - - - - - A A A A A A B E B A A A A A - - - - - - - -   - - - - - - - - - - - - C B E B - - - - - - - - - - - - -   - - - - - - - - - - - - - - - - - - - - - - - - - - - - -   - - - - - - - - - - - - - - - - - - - - - - - - - - - - -   - - - - - - - - - - - - - - - - - - - - - - - - - - - - -   - - - - - - - - - - - - - - - - - - - - - - - - - - - - -   - - - - - - - - - - - - - - - - - - - - - - - - - - - - -   - - - - - - - - - - - - - - - - - - - - - - - - - - - - -   - - - - - - - - - - - - - - - - - - - - - - - - - - - - -   - - - - - - - - - - - - - - - - - - - - - - - - - - - - -   - - - - - - - - - - - - - - - - - - - - - - - - - - - - -   - - - - - - - - - - - - - - - - - - - - - - - - - - - - -   - - - - - - - - - - - - - - - - - - - - - - - - - - - - -   - - - - - - - - - - - - - - - - - - - - - - - - - - - - -   - - - - - - - - - - - - - - - - - - - - - - - - - - - - -   - - - - - - - - - - - - - - - - - - - - - - - - - - - - -   - - - - - - - - - - - - - - - - - - - - - - - - - - - - -   - - - - - - - - - - - - - - - - - - - - - - - - - - - - -   - - - - - - - - - - - - - - - - - - - - - - - - - - - - -   
- - - - - - - F - - - - - - - - - - - - - - - - - - - - -   - - - - - - - - - - - - - - - - - - - - - - R - - - - - -   - - - - - - - S H - - - - - - - - - - - - - - - - - - - -   - - - - - - M - - - - - - - - - - - - - - - Ak- - - - - -   - - - - - A A A A A A - - - - - - A A A A A A A - - - - -   - - - - - A A - - A A - - - - - - A A A - - A A - - - - -   - - - - - A - - - A A A - - - - - A A A - - A A - - - - -   - - - - - A - A A A A A A A A A A A A A A - A A - - - - -   - - - - - A A - A A A A A B B B A A A A - A A A - - - - -   - - - - - A A A - A A A A B E B A A A - A A A - - - - - -   - - - - - - - - - - B B B B B B B B - - - - - - - - - - -   - - - - - - - - - - - E E E B E E - - - - - - - - - - - -   - - - - - - - - - - - - B B B B - - - - - - - - - - - - -   - - - - - - - - - - - - - - - - - - - - - - - - - - - - -   - - - - - - - - - - - - - - - - - - - - - - - - - - - - -   - - - - - - - - - - - - - - - - - - - - - - - - - - - - -   - - - - - - - - - - - - - - - - - - - - - - - - - - - - -   - - - - - - - - - - - - - - - - - - - - - - - - - - - - -   - - - - - - - - - - - - - - - - - - - - - - - - - - - - -   - - - - - - - - - - - - - - - - - - - - - - - - - - - - -   - - - - - - - - - - - - - - - - - - - - - - - - - - - - -   - - - - - - - - - - - - - - - - - - - - - - - - - - - - -   - - - - - - - - - - - - - - - - - - - - - - - - - - - - -   - - - - - - - - - - - - - - - - - - - - - - - - - - - - -   - - - - - - - - - - - - - - - - - - - - - - - - - - - - -   - - - - - - - - - - - - - - - - - - - - - - - - - - - - -   - - - - - - - - - - - - - - - - - - - - - - - - - - - - -   - - - - - - - - - - - - - - - - - - - - - - - - - - - - -   
- - - - - - - - - - - - - - - - - - - - - - H - - - - - -   - - - - - - - - - - - - - - - - - - - - - - - - - - - - -   - - - - - - - - - - - - - - - - - - - - - - - G - - - - -   - - - V - F - - X - - - - - - - - - - - - - - - - - - - -   - - - - - A A A A - - - - - - - - - - A A A A A - - - - -   - - - - A A - - A - - - - - - - - - - A A - - A A - - - -   - - - - A - - - A A - - - - - - - - A A A - - A A - - - -   - - - - A - A A A A A A A A A A A A B B B A - A A - - - -   - - - - A A - A A A A A A A A A A A B E B - A A A - - - -   - - - - - A A A B B B D D D D D D D B E B A A A - - - - -   - - - - - - - - B D B B B B B B B B B B - - - - - - - - -   - - - - - - - - - B B E E E B E E E B - - - - - - - - - -   - - - - - - - - - - B B B B B B B B - - - - - - - - - - -   - - - - - - - - - - - B B B B B E - - - - - - - - - - - -   - - - - - - - - - - - - E B C B - - - - - - - - - - - - -   - - - - - - - - - - - - - - - - - - - - - - - - - - - - -   - - - - - - - - - - - - - - - - - - - - - - - - - - - - -   - - - - - - - - - - - - - - - - - - - - - - - - - - - - -   - - - - - - - - - - - - - - - - - - - - - - - - - - - - -   - - - - - - - - - - - - - - - - - - - - - - - - - - - - -   - - - - - - - - - - - - - - - - - - - - - - - - - - - - -   - - - - - - - - - - - - - - - - - - - - - - - - - - - - -   - - - - - - - - - - - - - - - - - - - - - - - - - - - - -   - - - - - - - - - - - - - - - - - - - - - - - - - - - - -   - - - - - - - - - - - - - - - - - - - - - - - - - - - - -   - - - - - - - - - - - - - - - - - - - - - - - - - - - - -   - - - - - - - - - - - - - - - - - - - - - - - - - - - - -   - - - - - - - - - - - - - - - - - - - - - - - - - - - - -   
- - - - - - - - - - - - - - - - - - - - - - - - - - - - -   - - V - - - - - - - - - - - - - - - - - - - - - - Ab- - -   - - - - - - - - - T - - - - - - - - - - - - - - - - - - -   - - - - J - - - - - - - - - - - - - - - - - - - - K - - -   - - - - A A A A A - - - - - - - - - - - A A A A A - - - -   - - - A A - - A A - - - - - - - - - - - A - - A A - - - -   - - - A A - - A A - - - - - - - - - A A A - - - A - - - -   - - - A A A A A A A A A A A A A A A B B B A A - A - - - -   - - - - A - A A A A A A A A A A A A B E B A - A A - - - -   - - - - A A A A B B D D D D D D D D D D D A A A A - - - -   - - - - - - - C B D D C C C C B B B B B B - - - - - - - -   - - - - - - - - B B B B B C C B B E E E - - - - - - - - -   - - - - - - - - - E E E B C C B B B B - - - - - - - - - -   - - - - - - - - - B B B B B B B B B C - - - - - - - - - -   - - - - - - - - - - E E E B B E B B - - - - - - - - - - -   - - - - - - - - - - - B B B B B B - - - - - - - - - - - -   - - - - - - - - - - - - E E E B - - - - - - - - - - - - -   - - - - - - - - - - - - - - - - - - - - - - - - - - - - -   - - - - - - - - - - - - - - - - - - - - - - - - - - - - -   - - - - - - - - - - - - - - - - - - - - - - - - - - - - -   - - - - - - - - - - - - - - - - - - - - - - - - - - - - -   - - - - - - - - - - - - - - - - - - - - - - - - - - - - -   - - - - - - - - - - - - - - - - - - - - - - - - - - - - -   - - - - - - - - - - - - - - - - - - - - - - - - - - - - -   - - - - - - - - - - - - - - - - - - - - - - - - - - - - -   - - - - - - - - - - - - - - - - - - - - - - - - - - - - -   - - - - - - - - - - - - - - - - - - - - - - - - - - - - -   - - - - - - - - - - - - - - - - - - - - - - - - - - - - -   
- - U - - - - - - - - - - - - - - - - - - - - - - G - - -   - - - - - - - - - - - - - - - - - - - - - - - - - - - - -   - - - H - - - - - - - - - - - - - - - - - - - - - - F - -   - - - - - - - - - - - - - - - - - - - - - - - - - - - - -   - - - A A A A A - - - - - - - - - - - - - A A A A - - - -   - - - A A - A A - - - - - - - - - - - - - A - - A - - - -   - - - A - - A A - - - - - - - - - - - - - A - - - - - - -   - - - A A A A A A A A A A A A A A A A A A A A A - - - - -   - - - A A A A A A A A A A A A A A A A A A A A - A - - - -   - - - A A - B B B A D D D D D D D D D D D A A A A - - - -   - - - - - - B E B D D C C C C C C C B B D D - - - - - - -   - - - - - - - E D D C C C C C C C C B E B - - - - - - - -   - - - - - - - - D B B C C C C C C C B E - - - - - - - - -   - - - - - - - - B B B B B B B B B C B E - - - - - - - - -   - - - - - - - - - B E E E B B E B C B - - - - - - - - - -   - - - - - - - - - - B B B B B B B B - - - - - - - - - - -   - - - - - - - - - - - B E E E B D - - - - - - - - - - - -   - - - - - - - - - - - B B B B B D - - - - - - - - - - - -   - - - - - - - - - - - - - B C - - - - - - - - - - - - - -   - - - - - - - - - - - - - - - - - - - - - - - - - - - - -   - - - - - - - - - - - - - - - - - - - - - - - - - - - - -   - - - - - - - - - - - - - - - - - - - - - - - - - - - - -   - - - - - - - - - - - - - - - - - - - - - - - - - - - - -   - - - - - - - - - - - - - - - - - - - - - - - - - - - - -   - - - - - - - - - - - - - - - - - - - - - - - - - - - - -   - - - - - - - - - - - - - - - - - - - - - - - - - - - - -   - - - - - - - - - - - - - - - - - - - - - - - - - - - - -   - - - - - - - - - - - - - - - - - - - - - - - - - - - - -   
- - - - - - - - - - - - - - - - - - - - - - - - - - - - -   - - - - - - - - - - - - - - - - - - - - - - - - - - - - -   - - - - - - - - - - - - - - - - - - - - - - - - - - - - -   - - - - - - - - - - - - - - - - - - - - - - - - - - - - -   - - - A A A - - - - - - - - - - - - - - - - A A A A - - -   - - - A - A - - - - - - - - - - - - - - - - A - - A - - -   - - - - - A A - - - - - - - - - - - - - - A A - - A - - -   - - - - A A A A A A A A A A A A A A A A A A A A - A - - -   - - - A A A A A A A A A A A A A A A A A B B B A - A - - -   - - - A A A B B B A D D D D D D D D D D D E B - A - - - -   - - - - - - B E B D D D C C C C C C B D D D - - - - - - -   - - - - - - B E D D C C C C C C C C B E B D - - - - - - -   - - - - - - - E D D B C C C C C C C B E B - - - - - - - -   - - - - - - - B B B B C C C C C C C B E B - - - - - - - -   - - - - - - - - E E B C C C C C C C B B - - - - - - - - -   - - - - - - - - - B B C C C C B B B B - - - - - - - - - -   - - - - - - - - - B D D D D D B E E E - - - - - - - - - -   - - - - - - - - - - C C C B B B B B - - - - - - - - - - -   - - - - - - - - - - - B B B E B B - - - - - - - - - - - -   - - - - - - - - - - - - E B E B - - - - - - - - - - - - -   - - - - - - - - - - - - - B E - - - - - - - - - - - - - -   - - - - - - - - - - - - - - - - - - - - - - - - - - - - -   - - - - - - - - - - - - - - - - - - - - - - - - - - - - -   - - - - - - - - - - - - - - - - - - - - - - - - - - - - -   - - - - - - - - - - - - - - - - - - - - - - - - - - - - -   - - - - - - - - - - - - - - - - - - - - - - - - - - - - -   - - - - - - - - - - - - - - - - - - - - - - - - - - - - -   - - - - - - - - - - - - - - - - - - - - - - - - - - - - -   
- - - - - - - - - - - - - - - - - - - - - - - - - - - - -   - - - - - - - - - - - - - - - - - - - - - - - - - - - - -   - - - - - - - - - - - - - - - - - - - - - - - - - - - - -   - - - - - - - - - - - - - - - - - - - - - - - - - - - - -   - - - A A A - - - - - - - - - - - - - - - - A A A A - - -   - - - - - A - - - - - - - - - - - - - - - - A A - A - - -   - - - - - A - - - - - - - - - - - - - - - - A A - A - - -   - - - A A A A A A A A A A A A A A A A A A A A A A A - - -   - - - A A A A A A A A A A A A A A A A A B B B A - A - - -   - - - A A B B B A A A D D D D D D A A A B E B A A A - - -   - - - - - B E B C D D D D D D D D D D D D D B - - - - - -   - - - - - - E B C D D D C C C C C C C D D D - - - - - - -   - - - - - - E B D D D C C C C C C C C C D D - - - - - - -   - - - - - - - B B B B C C C C C C C B B B - - - - - - - -   - - - - - - - E E E B C C C C C C C B E E - - - - - - - -   - - - - - - - - B B B D D D D B B B B B - - - - - - - - -   - - - - - - - - - B B B D D D B E E E - - - - - - - - - -   - - - - - - - - - B E B C B B B B B B - - - - - - - - - -   - - - - - - - - - - B B B B E B B E - - - - - - - - - - -   - - - - - - - - - - - B B B B B B - - - - - - - - - - - -   - - - - - - - - - - - E E E B E B - - - - - - - - - - - -   - - - - - - - - - - - - B B B E - - - - - - - - - - - - -   - - - - - - - - - - - - - B B - - - - - - - - - - - - - -   - - - - - - - - - - - - - - - - - - - - - - - - - - - - -   - - - - - - - - - - - - - - - - - - - - - - - - - - - - -   - - - - - - - - - - - - - - - - - - - - - - - - - - - - -   - - - - - - - - - - - - - - - - - - - - - - - - - - - - -   - - - - - - - - - - - - - - - - - - - - - - - - - - - - -   
- - - - - - - - - - - - - - - - - - - - - - - - - - Ad- -   - - - - - - - - - - - - - - - - - - - - - - - - - - - - -   - - - - F - - - - - - - - - - - - - - - - - - - - - - - -   - - - P - - - - - - - - - - - - - - - - - - - - - - - - -   - - - A A - - - - - - - - - - - - - - - - - - A A A - - -   - A A - - A - - - - - - - - - - - - - - - - - A - A A - -   - A A - - A - - - - - - - - - - - - - - - - A A - A A - -   - A A A A A A A A A A A A A A A A A A A A A A A A A A - -   - - - - A A A A A A A A A A A A A A A A A A A A - A - - -   - - - A A B B B A A A A A A A A A A A A A A A A A A - - -   - - - - - B E B C C C D D D D D D D D D C C C - - - - - -   - - - - - B E B C C D D D D D D D D D D D B C - - - - - -   - - - - - - E B C D D D D D D D D D D D D D - - - - - - -   - - - - - - B B B D D D D D D D D D B B B B - - - - - - -   - - - - - - - E B D D D D D D D D D B E E - - - - - - - -   - - - - - - - E B C D D D D D D D D B B B - - - - - - - -   - - - - - - - - D D D B C C C C C B E B - - - - - - - - -   - - - - - - - - D D D D D D C C C B E B - - - - - - - - -   - - - - - - - - - B B B B B D B B B E - - - - - - - - - -   - - - - - - - - - - B B B B B B B B - - - - - - - - - - -   - - - - - - - - - - B E E E B E B B - - - - - - - - - - -   - - - - - - - - - - - B B B B E B - - - - - - - - - - - -   - - - - - - - - - - - - B B B E - - - - - - - - - - - - -   - - - - - - - - - - - - B B B B - - - - - - - - - - - - -   - - - - - - - - - - - - - E E - - - - - - - - - - - - - -   - - - - - - - - - - - - - - - - - - - - - - - - - - - - -   - - - - - - - - - - - - - - - - - - - - - - - - - - - - -   - - - - - - - - - - - - - - - - - - - - - - - - - - - - -   
- - - - - - - - - - - - - - - - - - - - - - - - - - - - -   - - - - - - - - - - - - - - - - - - - - - - - - - - Ae- -   - - - - - - - - - - - - - - - - - - - - - - - - - - - - -   L - G - - J - - - - - - - - - - - - - - - - - - N - - - -   - - - A A - - - - - - - - - - - - - - - - - - A A A - - -   - A A - - - - - - - - - - - - - - - - - - - - A - A A - -   - A - - - - - - - - - - - - - - - - - - - - - A - - A - -   - A - A A A A A A A A A A A A A A A A A A A A A A - A - -   - A A A B B B A A A A A A A A A A A A A A A A A A A - - -   - - - A B E B A A A A A A A A A A A A A A A A A - A - - -   - - - - B E B C C C C C C C C C C C C C C C C C - - - - -   - - - - - E B C C C C C C C C C C C C B B B C - - - - - -   - - - - - B B C C C C C D D D D D D D B E B C - - - - - -   - - - - - - B B B C C C D D D D D D D B E B - - - - - - -   - - - - - - B E B C C C C C C C C C C B E B - - - - - - -   - - - - - - - B B B D D D D D C C B B B B - - - - - - - -   - - - - - - - E E B D D D D D D C B E B C - - - - - - - -   - - - - - - - - B B C C C C D D C B E B - - - - - - - - -   - - - - - - - - - C C C C C D D C B E - - - - - - - - - -   - - - - - - - - - C B B B D D D C B B - - - - - - - - - -   - - - - - - - - - - D D D D D D C C - - - - - - - - - - -   - - - - - - - - - - D D D D C C C C - - - - - - - - - - -   - - - - - - - - - - - E B B B B B - - - - - - - - - - - -   - - - - - - - - - - - B B B B B B - - - - - - - - - - - -   - - - - - - - - - - - - E E E B - - - - - - - - - - - - -   - - - - - - - - - - - - - B B - - - - - - - - - - - - - -   - - - - - - - - - - - - - - - - - - - - - - - - - - - - -   - - - - - - - - - - - - - - - - - - - - - - - - - - - - -   
- - - O - - - - - - - - - - - - - - - - - - - - - - - - -   - - - - P - - - - - - - - - - - - - - - - - - - - - - - -   - - - - - - G - - - - - - - - - - - - - - - - - - - Af- -   - Ai- - - - - - - - - - - - - - - - - - - - - - - - - - -   - - - A A - - - - - - - - - - - - - - - - - - - A A A - -   - A A - - - - - - - - - - - - - - - - - - - - A A A A - -   - A - - - - - - - - - - - - - - - - - - - - - A - - A - -   - A A A A A A A A A A A A A A A A A A A A A A A A A A - -   - A A A B B B A A A A A A A A A A A A A A A A A A A A - -   - - - A B E B A A A A A A A A A A A A A A A A A A A - - -   - - - - B E B C C C C C C C C C C C C C B B B C - - - - -   - - - - - E B C C C C C C C C C C C C C B E B - - - - - -   - - - - - B B B B C C C C C C C C C C C B E B - - - - - -   - - - - - - B E B C C C C C C C C C C C B E - - - - - - -   - - - - - - D D D D D D C C C C C C C C B B - - - - - - -   - - - - - - - B B B D D D D D D C C C C C - - - - - - - -   - - - - - - - E E B C C C C D D D C B B B - - - - - - - -   - - - - - - - - B B C C C C C D D C B E - - - - - - - - -   - - - - - - - - C C C C C C C D D C B E - - - - - - - - -   - - - - - - - - - C B B B C C D D C B - - - - - - - - - -   - - - - - - - - - C B E B D D D B B B - - - - - - - - - -   - - - - - - - - - - D D D D D C B E - - - - - - - - - - -   - - - - - - - - - - B E B C B B B E - - - - - - - - - - -   - - - - - - - - - - - B B C B E B - - - - - - - - - - - -   - - - - - - - - - - - C B B B E B - - - - - - - - - - - -   - - - - - - - - - - - - B E B E - - - - - - - - - - - - -   - - - - - - - - - - - - - E B - - - - - - - - - - - - - -   - - - - - - - - - - - - - E B - - - - - - - - - - - - - -   
- - - - - - - - - - - - - - - - - - - - - - - - - - - - -   - - - - - - - - - - - - - - - - - - - - - - - - - - - - -   - - - M - - - - - - - - - - - - - - - - - - - - - - - - -   - - - - - - - - - - - - - - - - - - - - - - - - - - - - -   - - - A A - - - - - - - - - - - - - - - - - - - A A A - -   - A A - - - - - - - - - - - - - - - - - - - - A A A A - -   - A - - - - - - - - - - - - - - - - - - - - - A - - A - -   - A A A A A A A A A A A A A A A A A A A A A A A A A A - -   - A A A A A A A A A A A A A A A A A A A A A A A A A A - -   - - - A A A A A A A A A A A A A A A A A A A A A A A - - -   - - - - C C C C C C C C C C C C C C C C B B B C - - - - -   - - - - - C C C C C C C C C C C C C C C B E B - - - - - -   - - - - - C B B B C C C C C C C C C C C B E B - - - - - -   - - - - - - B B B C C C C C C C C C C C B E - - - - - - -   - - - - - - E E B D D D D D D C C C C C B B - - - - - - -   - - - - - - - B B C C C C C D D C C C C B - - - - - - - -   - - - - - - - E B C C C C C C D D C B B B - - - - - - - -   - - - - - - - - B B B B C C C C D C B E - - - - - - - - -   - - - - - - - - B B E B C C C C D C B E - - - - - - - - -   - - - - - - - - - B E B C C C D D C B - - - - - - - - - -   - - - - - - - - - B B B B C D D D B B - - - - - - - - - -   - - - - - - - - - - E E B D D D B E - - - - - - - - - - -   - - - - - - - - - - B B B C C C B E - - - - - - - - - - -   - - - - - - - - - - - C C C C C B - - - - - - - - - - - -   - - - - - - - - - - - C B B B C B - - - - - - - - - - - -   - - - - - - - - - - - - B E B C - - - - - - - - - - - - -   - - - - - - - - - - - - - E B - - - - - - - - - - - - - -   - - - - - - - - - - - - - E B - - - - - - - - - - - - - -   
- - - - - - - - - - - - - - - - - - - - - - - - - - - - -   - - - - - - - - - - - - - - - - - - - - - - - - - - - - -   - - - - - - - - - - - - - - - - - - - - - - - - - - - - -   - - - - L - - - - - - - - - - - - - - - - - - - - - - - -   - - - A A - - - - - - - - - - - - - - - - - - A A A - - -   - A A - - - - - - - - - - - - - - - - - - - - A A A A - -   - A - - A A A - - - - - - - - - - - - - - - - A - - A - -   - A - A B B B A A A A A A A A A A A A A A A A A A - A - -   - A A A B E B A A A A A A A A A A A A A A A A A A A A - -   - - - A B E B A A A A A A A A A A A A A A A A A - A - - -   - - - - B E B C C C C C C C C C C C C C C C C C - - - - -   - - - - - B B C C C C C C C C C C C C C C C C - - - - - -   - - - - - C C C C C C C C C C C C C C C B B B - - - - - -   - - - - - - B B B C C C C C C C C C C C B E - - - - - - -   - - - - - - E E B D D D D D D C C C C C B E - - - - - - -   - - - - - - - B B C C C C C D D C C C C B - - - - - - - -   - - - - - - - E B C C C C C C D D B B B B - - - - - - - -   - - - - - - - - B B B B C C C C D B E B - - - - - - - - -   - - - - - - - - - B E B C C C B D B E - - - - - - - - - -   - - - - - - - - - B B B B C C B D B E - - - - - - - - - -   - - - - - - - - - - B B B B B D D B - - - - - - - - - - -   - - - - - - - - - - E E B D D B E B - - - - - - - - - - -   - - - - - - - - - - - B B E B B B - - - - - - - - - - - -   - - - - - - - - - - - C B E B B C - - - - - - - - - - - -   - - - - - - - - - - - - B E B B - - - - - - - - - - - - -   - - - - - - - - - - - - - B B - - - - - - - - - - - - - -   - - - - - - - - - - - - - - - - - - - - - - - - - - - - -   - - - - - - - - - - - - - - - - - - - - - - - - - - - - -   
- - - - - - - - - - - - - - - - - - - - - - - - - - - - -   - - - - - - - - - - - - - - - - - - - - - - - - - - - - -   - - - - - - - - - - - - - - - - - - - - - - - - - - I - -   - - - - - - - - - - - - - - - - - - - - - - - - - X - - -   - - - A A - - - - - - - - - - - - - - - - - - A A A - - -   - A A - - - - - - - - - - - - - - - - - - - - A - A A - -   - A - - A A A - - - - - - - - - - - - - - - - A - - A - -   - A - A B B B A A A A A A A A A A A A A A A A A A - A - -   - A A - B E B A A A A A A A A A A A A A A A A A - A - - -   - - - A B E B A A A A A A A A A A A A A A A A A - A - - -   - - - - - E B B B C C C C C C C C C C C C C C - - - - - -   - - - - - B B E B C C C C C C C C C C C C C C - - - - - -   - - - - - - B E B C C C C C C C C C C B B B - - - - - - -   - - - - - - B E B C C C C C C C C C C B E B - - - - - - -   - - - - - - - D D D D D D D D C B B B B E - - - - - - - -   - - - - - - - C C B E B C D D D B E B B E - - - - - - - -   - - - - - - - - C B E B B C C D D B B B - - - - - - - - -   - - - - - - - - C B E B B C C D D B E B - - - - - - - - -   - - - - - - - - - B B B B B C B D B E - - - - - - - - - -   - - - - - - - - - - B B B B C D D B - - - - - - - - - - -   - - - - - - - - - - E E B B D D D B - - - - - - - - - - -   - - - - - - - - - - - B B D B B E - - - - - - - - - - - -   - - - - - - - - - - - - B E B B - - - - - - - - - - - - -   - - - - - - - - - - - - B E B B - - - - - - - - - - - - -   - - - - - - - - - - - - - E B - - - - - - - - - - - - - -   - - - - - - - - - - - - - - - - - - - - - - - - - - - - -   - - - - - - - - - - - - - - - - - - - - - - - - - - - - -   - - - - - - - - - - - - - - - - - - - - - - - - - - - - -   
- - - - - - - - - - - - - - - - - - - - - - - - - - - - -   - - - - - - - - - - - - - - - - - - - - - - - - - - - N -   - - - - - - - - - - - - - - - - - - - - - - - - - - - - -   - - - - - - - - - - - - - - - - - - - - - - - - - - - - -   - - - A A A - - - - - - - - - - - - - - - - A A A A - - -   - - - - - A - - - - - - - - - - - - - - - - A A - A - - -   - - - - - A - - - - - - - - - - - - - - A A A A - A - - -   - - - A A A A A A A A A A A A A A A A A B B B A A A - - -   - - - A A A A A A A A A A A A A A A A A B E B A - A - - -   - - - A A B B B A A A A A A A A A A A A B E B A A A - - -   - - - - - B E B B C C C C C C C C C C C B E B - - - - - -   - - - - - - E B B C C C C C C C C C C C B B - - - - - - -   - - - - - - E B B C C C C C C C C C C B B B - - - - - - -   - - - - - - - B B C C C C C C C C C C B E - - - - - - - -   - - - - - - - D D D D B C C C C B B B B E - - - - - - - -   - - - - - - - - B B B B D D D D B E B B - - - - - - - - -   - - - - - - - - - E E B B D D D B B B - - - - - - - - - -   - - - - - - - - - B B B E B D D D B B - - - - - - - - - -   - - - - - - - - - - B B B B B B D B - - - - - - - - - - -   - - - - - - - - - - - B E E E B D - - - - - - - - - - - -   - - - - - - - - - - - B B B B B B - - - - - - - - - - - -   - - - - - - - - - - - - D B E B - - - - - - - - - - - - -   - - - - - - - - - - - - - B B - - - - - - - - - - - - - -   - - - - - - - - - - - - - - - - - - - - - - - - - - - - -   - - - - - - - - - - - - - - - - - - - - - - - - - - - - -   - - - - - - - - - - - - - - - - - - - - - - - - - - - - -   - - - - - - - - - - - - - - - - - - - - - - - - - - - - -   - - - - - - - - - - - - - - - - - - - - - - - - - - - - -   
- - - - - - - - - - - - - - - - - - - - - - - - - - U - -   - - - - - - - - - - - - - - - - - - - - - - - - - - - - -   - - - - - - - - - - - - - - - - - - - - - - - - - - - - -   - - - - - - - - - - - - - - - - - - - - - - - - - - - - -   - - - A A A - - - - - - - - - - - - - - - - A A A A - - -   - - - A - A - - - - - - - - - - - - - - - - A - - A - - -   - - - - - A A - - - - - - - - - - - - - A A A - - A - - -   - - - - A A A A A A A A A A A A A A A A B B B A - A - A -   - - - A A A A A A A A A A A A A A A A A B E B A - A - - -   - - - A A B B B A A A A A A A A A A A A B E B - A - - - -   - - - - - - E B C C C C C C C C C C B B B E - - - - - - -   - - - - - - E B B B B C C C C C C C B E B B - - - - - - -   - - - - - - - B B E B C C C C C C C B E B - - - - - - - -   - - - - - - - B B E B B B B C B B B B E B - - - - - - - -   - - - - - - - - B E B B E B C B E B B B - - - - - - - - -   - - - - - - - - - B B B D D C B E B C - - - - - - - - - -   - - - - - - - - - E E B D D D B E B C - - - - - - - - - -   - - - - - - - - - - B B D D D D B B - - - - - - - - - - -   - - - - - - - - - - - B B B B B E - - - - - - - - - - - -   - - - - - - - - - - - - E E E B - - - - - - - - - - - - -   - - - - - - - - - - - - - B B - - - - - - - - - - - - - -   - - - - - - - - - - - - - - - - - - - - - - - - - - - - -   - - - - - - - - - - - - - - - - - - - - - - - - - - - - -   - - - - - - - - - - - - - - - - - - - - - - - - - - - - -   - - - - - - - - - - - - - - - - - - - - - - - - - - - - -   - - - - - - - - - - - - - - - - - - - - - - - - - - - - -   - - - - - - - - - - - - - - - - - - - - - - - - - - - - -   - - - - - - - - - - - - - - - - - - - - - - - - - - - - -   
- - - - - - - - - - - - - - - - - - - - - - - - - - - - -   - - - - - - - - - - - - - - - - - - - - - - - - - - - - Q   - - - - - L - - - - - - - - - - - - - - - - - - - - - T -   - - - - - - H - - - - - - - - - - - - - - - - - - - Aj- -   - - - A A A A - - - - - - - - - - - - - - A A A A A - - -   - - - A - A A - - - - - - - - - - - - - - A A - - A - - -   - - - A - A A - - - - - - - - - - - - - - A A - - A A - -   - - - A A A A A A A A A A A A A A A A A A A A A - A - - -   - - - A - A A A A A A A A A A A A A A A A A A - A - - - -   - - - A A - A A A A A A A A A A A A B B B A - A A - - - -   - - - - - - C C C C C C C C C C C C B E B C - - - - - - -   - - - - - - - C B B B B C C C C C C B E B - - - - - - - -   - - - - - - - - B E B B C C C C C C B E - - - - - - - - -   - - - - - - - - B E B B B B C B B B B B - - - - - - - - -   - - - - - - - - - E B B E B B B E B B - - - - - - - - - -   - - - - - - - - - - B B E B E B E B - - - - - - - - - - -   - - - - - - - - - - - B E B E B E - - - - - - - - - - - -   - - - - - - - - - - - D D B E B B - - - - - - - - - - - -   - - - - - - - - - - - - - B B - - - - - - - - - - - - - -   - - - - - - - - - - - - - - - - - - - - - - - - - - - - -   - - - - - - - - - - - - - - - - - - - - - - - - - - - - -   - - - - - - - - - - - - - - - - - - - - - - - - - - - - -   - - - - - - - - - - - - - - - - - - - - - - - - - - - - -   - - - - - - - - - - - - - - - - - - - - - - - - - - - - -   - - - - - - - - - - - - - - - - - - - - - - - - - - - - -   - - - - - - - - - - - - - - - - - - - - - - - - - - - - -   - - - - - - - - - - - - - - - - - - - - - - - - - - - - -   - - - - - - - - - - - - - - - - - - - - - - - - - - - - -   
- - - - - - - - - - - - - - - - - - - - - - - - - - - - -   - - - - - - Y - - - - - - - - - - - - - - - - - - - - - -   - - - - - - - - - - - - - - - - - - - - - - - - - - - - -   - - - - - - - - - - - - - - - - - - - - - - - - - - - - -   - - - A A A A A - - - - - - - - - - - - - A A A A - - - -   - - - A A - A A - - - - - - - - - - - - - A - - A - - - -   - - - A - - A B A A - - - - - - - - - - - A - - - - - - -   - - - A - A A B E B A A A A A A A A A A A A A - - - - - -   - - - A A - A B E B A A A A A A A A A A A A - - A - - - -   - - - A A - A B E B B B A A A A A A B B B A A A A - - - -   - - - - - - - B B B E B C C C B B B B E B - - - - - - - -   - - - - - - - - C B E B B C C B B E B E - - - - - - - - -   - - - - - - - - - B E B B C C B B E B - - - - - - - - - -   - - - - - - - - - B B B B C C B B E B - - - - - - - - - -   - - - - - - - - - - E B B B B B B B - - - - - - - - - - -   - - - - - - - - - - - B B B E B E - - - - - - - - - - - -   - - - - - - - - - - - - C B E B - - - - - - - - - - - - -   - - - - - - - - - - - - - - - - - - - - - - - - - - - - -   - - - - - - - - - - - - - - - - - - - - - - - - - - - - -   - - - - - - - - - - - - - - - - - - - - - - - - - - - - -   - - - - - - - - - - - - - - - - - - - - - - - - - - - - -   - - - - - - - - - - - - - - - - - - - - - - - - - - - - -   - - - - - - - - - - - - - - - - - - - - - - - - - - - - -   - - - - - - - - - - - - - - - - - - - - - - - - - - - - -   - - - - - - - - - - - - - - - - - - - - - - - - - - - - -   - - - - - - - - - - - - - - - - - - - - - - - - - - - - -   - - - - - - - - - - - - - - - - - - - - - - - - - - - - -   - - - - - - - - - - - - - - - - - - - - - - - - - - - - -   
- - - - - K - - - - - - - - - - - - - - - - - - - - - - -   - - - - - - - - - - - - - - - - - - - - - - - - - - - - -   - - - - - - - - - - - - - - - - - - - - J - - - - - - - -   - - - - - - - - - - - - - - - - - - - - - G - - - - - - -   - - - - - A A A A A A - - - - - - - - A A A A A - - - - -   - - - - A A A - A A A - - - - - - - - A A - - A A - - - -   - - - - A - - - B B - - - - - - - - A A A - - A A - - - -   - - - - A - A B E B A A A A A A A A A A A A - A A - - - -   - - - - A A - B E B A B B B A A A A A A A - A A A - - - -   - - - - - A A B E B B B E B A A A A A A A A A A - - - - -   - - - - - - - - B B E B E B B B B B B C - - - - - - - - -   - - - - - - - - - B E B B B E B B E B - - - - - - - - - -   - - - - - - - - - - E B B B E B B E - - - - - - - - - - -   - - - - - - - - - - - B B B E B B - - - - - - - - - - - -   - - - - - - - - - - - - B B B B - - - - - - - - - - - - -   - - - - - - - - - - - - - - - - - - - - - - - - - - - - -   - - - - - - - - - - - - - - - - - - - - - - - - - - - - -   - - - - - - - - - - - - - - - - - - - - - - - - - - - - -   - - - - - - - - - - - - - - - - - - - - - - - - - - - - -   - - - - - - - - - - - - - - - - - - - - - - - - - - - - -   - - - - - - - - - - - - - - - - - - - - - - - - - - - - -   - - - - - - - - - - - - - - - - - - - - - - - - - - - - -   - - - - - - - - - - - - - - - - - - - - - - - - - - - - -   - - - - - - - - - - - - - - - - - - - - - - - - - - - - -   - - - - - - - - - - - - - - - - - - - - - - - - - - - - -   - - - - - - - - - - - - - - - - - - - - - - - - - - - - -   - - - - - - - - - - - - - - - - - - - - - - - - - - - - -   - - - - - - - - - - - - - - - - - - - - - - - - - - - - -   
- - - - - - - - - - R - - - - - - - - - - - - - - - - - -   - - - - - - - - - - - Aa- - - - - - - - - - - W - - - - -   - - - - - - - - - - - - - - - - - - - - - - - - - - - - -   - - - - - - - - - - - - - - - - - - - - - - - - - - - - -   - - - - - A A A A A A - - - - - - A A A A A A A - - - - -   - - - - - A A - - A A - - - - - - A A A - - A A - - - - -   - - - - - A - - - A A A - - - - - A A A - A A A - - - - -   - - - - - A - A A A A A A A A A A A A A A - A A - - - - -   - - - - - A A - A A A B B B A A A A A A - A A A - - - - -   - - - - - A A A - A A B E B A A A A A - A A A - - - - - -   - - - - - - - - - - C B E B B B C C - - - - - - - - - - -   - - - - - - - - - - - B E B E B C - - - - - - - - - - - -   - - - - - - - - - - - - B B E B - - - - - - - - - - - - -   - - - - - - - - - - - - - - - - - - - - - - - - - - - - -   - - - - - - - - - - - - - - - - - - - - - - - - - - - - -   - - - - - - - - - - - - - - - - - - - - - - - - - - - - -   - - - - - - - - - - - - - - - - - - - - - - - - - - - - -   - - - - - - - - - - - - - - - - - - - - - - - - - - - - -   - - - - - - - - - - - - - - - - - - - - - - - - - - - - -   - - - - - - - - - - - - - - - - - - - - - - - - - - - - -   - - - - - - - - - - - - - - - - - - - - - - - - - - - - -   - - - - - - - - - - - - - - - - - - - - - - - - - - - - -   - - - - - - - - - - - - - - - - - - - - - - - - - - - - -   - - - - - - - - - - - - - - - - - - - - - - - - - - - - -   - - - - - - - - - - - - - - - - - - - - - - - - - - - - -   - - - - - - - - - - - - - - - - - - - - - - - - - - - - -   - - - - - - - - - - - - - - - - - - - - - - - - - - - - -   - - - - - - - - - - - - - - - - - - - - - - - - - - - - -   
- - - - - - - - - - - - N - - - - - - - - - - - - - - - -   - - - - - - - - - - - - - I - - - - - - - - - - - - - - -   - - - - - - - - - - Z - - - - - - - - - - - - - - - - - -   - - - - - - - - - - - - - - - - - H - - - - - - - - - - -   - - - - - - A A A A A A A A A A A A A A A A A - - - - - -   - - - - - A A A - - A A A A A A A A - - - A A - - - - - -   - - - - - A A - - - A A A A A A A A - - - A A - - - - - -   - - - - - A A - A A A A A A A A A A A A - A A - - - - - -   - - - - - A A A - A A A A A A A A A A - - A A - - - - - -   - - - - - - A A A - A A A A A A A A - A A A - - - - - - -   - - - - - - - - - - - - C C C C - - - - - - - - - - - - -   - - - - - - - - - - - - - - - - - - - - - - - - - - - - -   - - - - - - - - - - - - - - - - - - - - - - - - - - - - -   - - - - - - - - - - - - - - - - - - - - - - - - - - - - -   - - - - - - - - - - - - - - - - - - - - - - - - - - - - -   - - - - - - - - - - - - - - - - - - - - - - - - - - - - -   - - - - - - - - - - - - - - - - - - - - - - - - - - - - -   - - - - - - - - - - - - - - - - - - - - - - - - - - - - -   - - - - - - - - - - - - - - - - - - - - - - - - - - - - -   - - - - - - - - - - - - - - - - - - - - - - - - - - - - -   - - - - - - - - - - - - - - - - - - - - - - - - - - - - -   - - - - - - - - - - - - - - - - - - - - - - - - - - - - -   - - - - - - - - - - - - - - - - - - - - - - - - - - - - -   - - - - - - - - - - - - - - - - - - - - - - - - - - - - -   - - - - - - - - - - - - - - - - - - - - - - - - - - - - -   - - - - - - - - - - - - - - - - - - - - - - - - - - - - -   - - - - - - - - - - - - - - - - - - - - - - - - - - - - -   - - - - - - - - - - - - - - - - - - - - - - - - - - - - -   
- - - - - - - - - - - - - - - - - - - - - - - - - - - - -   - - - - - - - - - - - - - - - - - - - - - - - - - - - - -   - - - - - - - - - - - - Q - - - - - - - - - - - - - - - -   - - - - - - - - - - - F - - - - - - - - - - - - - - - - -   - - - - - - - A A A A A A A A A A A A A A - - - - - - - -   - - - - - - A A A - - - - A A - - - - - A A - - - - - - -   - - - - - - A A - - - - - - - - - - - - - A - - - - - - -   - - - - - - A A - - A A A A A A A A - - - A - - - - - - -   - - - - - - A A A - - - A A A A - - - A A A - - - - - - -   - - - - - - - A A A A - - A A - - A A A A - - - - - - - -   - - - - - - - - - - - - - - - - - - - - - - - - - - - - -   - - - - - - - - - - - - - - - - - - - - - - - - - - - - -   - - - - - - - - - - - - - - - - - - - - - - - - - - - - -   - - - - - - - - - - - - - - - - - - - - - - - - - - - - -   - - - - - - - - - - - - - - - - - - - - - - - - - - - - -   - - - - - - - - - - - - - - - - - - - - - - - - - - - - -   - - - - - - - - - - - - - - - - - - - - - - - - - - - - -   - - - - - - - - - - - - - - - - - - - - - - - - - - - - -   - - - - - - - - - - - - - - - - - - - - - - - - - - - - -   - - - - - - - - - - - - - - - - - - - - - - - - - - - - -   - - - - - - - - - - - - - - - - - - - - - - - - - - - - -   - - - - - - - - - - - - - - - - - - - - - - - - - - - - -   - - - - - - - - - - - - - - - - - - - - - - - - - - - - -   - - - - - - - - - - - - - - - - - - - - - - - - - - - - -   - - - - - - - - - - - - - - - - - - - - - - - - - - - - -   - - - - - - - - - - - - - - - - - - - - - - - - - - - - -   - - - - - - - - - - - - - - - - - - - - - - - - - - - - -   - - - - - - - - - - - - - - - - - - - - - - - - - - - - -   
- - - - - - - - - - - - - - - - - - - - - - - - - - - - -   - - - - - - - - - - - - - - - - - - - - - - - - - - - - -   - - - - - - - - - - - - - - - - - - - - - - - - - - - - -   - - - - - - - - - - - - - O - - - - - - - - - - - - - - -   - - - - - - - - - A A A A A A A A A A - - - - - - - - - -   - - - - - - - - - A A A A A A A A A A A - - - - - - - - -   - - - - - - - - - A A A - - - - - A A A - - - - - - - - -   - - - - - - - - - A A A - A A - - A A A - - - - - - - - -   - - - - - - - - - A A A A A A A A A A - - - - - - - - - -   - - - - - - - - - - A A A A A A A A - - - - - - - - - - -   - - - - - - - - - - - - - - - - - - - - - - - - - - - - -   - - - - - - - - - - - - - - - - - - - - - - - - - - - - -   - - - - - - - - - - - - - - - - - - - - - - - - - - - - -   - - - - - - - - - - - - - - - - - - - - - - - - - - - - -   - - - - - - - - - - - - - - - - - - - - - - - - - - - - -   - - - - - - - - - - - - - - - - - - - - - - - - - - - - -   - - - - - - - - - - - - - - - - - - - - - - - - - - - - -   - - - - - - - - - - - - - - - - - - - - - - - - - - - - -   - - - - - - - - - - - - - - - - - - - - - - - - - - - - -   - - - - - - - - - - - - - - - - - - - - - - - - - - - - -   - - - - - - - - - - - - - - - - - - - - - - - - - - - - -   - - - - - - - - - - - - - - - - - - - - - - - - - - - - -   - - - - - - - - - - - - - - - - - - - - - - - - - - - - -   - - - - - - - - - - - - - - - - - - - - - - - - - - - - -   - - - - - - - - - - - - - - - - - - - - - - - - - - - - -   - - - - - - - - - - - - - - - - - - - - - - - - - - - - -   - - - - - - - - - - - - - - - - - - - - - - - - - - - - -   - - - - - - - - - - - - - - - - - - - - - - - - - - - - -   
- - - - - - - - - - - - - - - - - - - - - - - - - - - - -   - - - - - - - - - - - - - - - - - - - - - - - - - - - - -   - - - - - - - - - - - - - - - - - - - - - - - - - - - - -   - - - - - - - - - - - - - - - - - - - - - - - - - - - - -   - - - - - - - - - - - - - - - A - - - - - - - - - - - - -   - - - - - - - - - - - A A A A A A - - - - - - - - - - - -   - - - - - - - - - - - A A A A A A - - - - - - - - - - - -   - - - - - - - - - - - A A A A A A - - - - - - - - - - - -   - - - - - - - - - - - - A A A A A - - - - - - - - - - - -   - - - - - - - - - - - - - - - - - - - - - - - - - - - - -   - - - - - - - - - - - - - - - - - - - - - - - - - - - - -   - - - - - - - - - - - - - - - - - - - - - - - - - - - - -   - - - - - - - - - - - - - - - - - - - - - - - - - - - - -   - - - - - - - - - - - - - - - - - - - - - - - - - - - - -   - - - - - - - - - - - - - - - - - - - - - - - - - - - - -   - - - - - - - - - - - - - - - - - - - - - - - - - - - - -   - - - - - - - - - - - - - - - - - - - - - - - - - - - - -   - - - - - - - - - - - - - - - - - - - - - - - - - - - - -   - - - - - - - - - - - - - - - - - - - - - - - - - - - - -   - - - - - - - - - - - - - - - - - - - - - - - - - - - - -   - - - - - - - - - - - - - - - - - - - - - - - - - - - - -   - - - - - - - - - - - - - - - - - - - - - - - - - - - - -   - - - - - - - - - - - - - - - - - - - - - - - - - - - - -   - - - - - - - - - - - - - - - - - - - - - - - - - - - - -   - - - - - - - - - - - - - - - - - - - - - - - - - - - - -   - - - - - - - - - - - - - - - - - - - - - - - - - - - - -   - - - - - - - - - - - - - - - - - - - - - - - - - - - - -   - - - - - - - - - - - - - - - - - - - - - - - - - - - - -   
- - - - - - - - - - - - - - - - Ah- - - - - - - - - - - -   - - - - - - - - - - - - - - - - - M - - - - - - - - - - -   - - - - - - - - - - - - - - - - Ag- - - - - - - - - - - -   - - - - - - - - - - - - - - - W - - - - - - - - - - - - -   - - - - - - - - - - - - - - - - - - - - - - - - - - - - -   - - - - - - - - - - - - - - - - - - - - - - - - - - - - -   - - - - - - - - - - - - - - - - - - - - - - - - - - - - -   - - - - - - - - - - - - - - - - - - - - - - - - - - - - -   - - - - - - - - - - - - - - - - - - - - - - - - - - - - -   - - - - - - - - - - - - - - - - - - - - - - - - - - - - -   - - - - - - - - - - - - - - - - - - - - - - - - - - - - -   - - - - - - - - - - - - - - - - - - - - - - - - - - - - -   - - - - - - - - - - - - - - - - - - - - - - - - - - - - -   - - - - - - - - - - - - - - - - - - - - - - - - - - - - -   - - - - - - - - - - - - - - - - - - - - - - - - - - - - -   - - - - - - - - - - - - - - - - - - - - - - - - - - - - -   - - - - - - - - - - - - - - - - - - - - - - - - - - - - -   - - - - - - - - - - - - - - - - - - - - - - - - - - - - -   - - - - - - - - - - - - - - - - - - - - - - - - - - - - -   - - - - - - - - - - - - - - - - - - - - - - - - - - - - -   - - - - - - - - - - - - - - - - - - - - - - - - - - - - -   - - - - - - - - - - - - - - - - - - - - - - - - - - - - -   - - - - - - - - - - - - - - - - - - - - - - - - - - - - -   - - - - - - - - - - - - - - - - - - - - - - - - - - - - -   - - - - - - - - - - - - - - - - - - - - - - - - - - - - -   - - - - - - - - - - - - - - - - - - - - - - - - - - - - -   - - - - - - - - - - - - - - - - - - - - - - - - - - - - -   - - - - - - - - - - - - - - - - - - - - - - - - - - - - -   
