model
size = 32, scale = 0.05, origin = -y
material 
  colors = A:#777 B:#111 C:#EEE D:#050 E:#300 F:#FC0 G:#500 H:#F93 I:#F39 J:#CFC K:#F09 L:#FFF M:#F0C N:#080 O:#FC9 P:#F33 Q:#CCC R:#F6C S:#FCC T:#CF9 U:#FF0 V:#F3C W:#F90 X:#FC6 Y:#F9F Z:#F99 Aa:#F03 Ab:#FC3 Ac:#FCF Ad:#FF3 Ae:#60C Af:#F3F Ag:#CCF Ah:#F60 Ai:#FF9 Aj:#001 Ak:#CF6 Al:#F66 Am:#F96 An:#F36 Ao:#F06 Ap:#FFC Aq:#CC6 Ar:#CF0 As:#F9C At:#CFF Au:#F63 Av:#CF3 Aw:#F00 Ax:#E00 Ay:#FF6 Az:#F6F Ba:#CC0 Bb:#CC3 Bc:#39F Bd:#CC9 Be:#555 Bf:#F0F Bg:#F30 Bh:#F69 Bi:#888
voxels
43-D37-P59-D69-W163-P60-S31-Aw34-K123-QAp30-X159-L31-Au184-L159-L21-FVD29-3(2F30-)HF58-2Bc125-Ac114-Ao34-AyAk36-Ag456-2(2F30-)2FP29-2(BF30-)BF14-AeD14-2F21-T8-2F17-Ab7-D-Bc2-HF15-D5-U3-2D144-Ao562-W25-2E4-2F24-2E4-BF2-MAf10-Al8-2EG4-BFDZ13-Aa6-3E5-BF21-3EG5-BF4AB2A16EG6-BF4AB2A6EG2E2(GE)CE8-BF4AB2A2E7GC13-BF4AB25-2F30-HF91-At94-Ab66-H63-V31-Aa57-J108-MAo152-W31-2F24-2E4-BFA23-2E4-AFA8-Bb-ATD9-3E3-2BF10-As2-DAa7-3E4-2BFB12-Z7-4E4-3BC3AB2A8-AeV2-5E5-CB2C3AB2A7-D4-3E7-2BAeC3AB2A7-TAd14-BT4AB25-B31-2F12-H17-H2A12-Bf17-2A50-Z39-Aw3-D46-UAyAa34-H7-Ab23-Ab12-D53-Av25-L5-Aa40-D37-Ae10-Aw5-O3-MAk8-VH3-Aq2-Az5-As7-I9-D-Aa2-MAg11-Ac23-AoH30-Ao47-F31-BF30-BFA29-CF3(A28-3B)3(A28-2BC)A28-A2B30-B31-B3-2A26-F31-F32-2A146-Q311-Bd82-F31-BFA29-C2(FA28-2B)2A28-BFCA5-Z22-4(2BCA28-)2B2A29-A2C29-B4-C26-B31-F3-3D26-2A-C2D3(29-CDC)29-CDAx2(29-CDC)29-N2D29-2ND281-H31-BFA29-BFA28-2B2A6(28-2BCA)28-2B2A28-2B-C29-B31-B3-3D25-F2-4D26-2AC3D28-2CDC28-AjCDBe28-CAjDC28-AjCDC28-CAjDAx28-2CDC2(29-N2D)30-N250-FA30-B2A29-B2A3(28-2BCA)3(28-4B)5-I22-2BCA28-2B2A28-2B-C29-B31-B2-5D24-F-5DAe25-2AD3-D26-CD3-C26-2C3-Be26-3C2-C26-2C3-Aj2(26-2C3-C)26-2N3-D26-2D3-D27-3DN2(29-3D)30-2(D31-)D30-3D57-F31-BC2A28-2B2(A28-3B)A5(28-4B)5-T22-2B2A28-2B-C29-B31-B2-5D24-F-6D25-2AD2C-D26-CD2C-C26-4C-Be26-Aj3C-C26-4C-C26-2C3-Aj22-D3-2C3-C2(26-2D3-D)27-2D-D29-D-D5(29-3D)57-F31-BC30-ABA2(28-2B2A)5(28-4B)28-2B2A28-C2B30-B31-H2-5D24-X-6D25-2ADC2-D26-CDC2-C26-Aj3C-C26-4C-C26-Aj3C-C26-AxC3-C26-2C3-C2(26-2D3-D)27-4D2(29-3D)30-2(D31-)D30-3D89-F31-BA30-B2A2(28-2BAG)28-2B2A2(28-4B)28-2B2A28-CB2A29-2B30-B2(31-F)3-3D26-A-2C2D4(28-2CDC)28-AxCDC28-2CDC29-3D29-N2D30-N200-M81-F31-H2(31-B)2A28-2BCA28-AB2A28-2B2A-F26-2B2A-K26-AB2A-X27-2(B31-)H3-C27-F31-F3-2D27-A2-CD3(30-2C)2(30-AxC)30-2C2(30-2N)346-2(F31-)BA30-2(BCA29-)4(B2A29-)F31-F63-F520-K150-F31-H3-D27-F31-2B30-2(B2A29-)F2A29-2(F31-)F63-F31-F703-4(F2A29-)H2A92-2F95-F703-H2A29-FC30-2(F2A29-)F2A92-2F2A93-H317-Bb284-P36-3(F2A29-)3(B2A29-)3(F2A29-)F2A61-F2A29-H2A255-AcS30-BgAf59-Ak256-WA30-F3(2A29-B)3(31-B)2A6-Aa22-B2A6-Av18-W3-F2A29-F2A61-F2A254-AqWAvH29-PAaO29-AtArI28-AcQHAc251-WA30-F2A29-B2A29-C2A28-BCB25-W3-2(BCB29-)BCB23-Am5-3B30-B2A6-Ae18-I3-B2(2A29-F)2AI28-F2A30-2A190-MAtPH27-LJYAgAbM26-AlSKMWAd26-2AbRAkTAc26-AhAsVIAqZ28-AiAl188-F31-BA30-2(BA)28-B2(2A28-BC)3(B29-BC)B29-2CB29-BC2(2A29-B)2(2A29-F)2A30-2A158-ILSF27-BgYAlAfApAo25-AuAiRAbAgLAyT25-ZJAhAnAuApQ24-JAkTBbLMQL26-PAcIJXAn26-XAdUS28-Bd-Z156-F31-B2A29-3(C2A28-B)5(CB29-B)C2A-Av26-BC2(2A29-B)2A29-H2A30-2A128-Am29-AyAmJK27-AiBfAwIAvF25-AoYAzAsYAaApJ23-AnBdZAhXRArLIR22-UAtMAsBaJHAuYV23-SWYLTOMR25-KAtUPIJ27-SAiXAc26-Ar2-ArBd124-H3-R27-BCA28-2BC2(A28-B2C)A28-5(BCB29-)B2CA28-B2C2(A29-BC)A29-FCA6-D15-Af7-2A6-D9-SAt13-P126-AfAtAuAg27-BbAgQBgMAl25-KOAnHXAkAhAk24-XAyLArUITAwAp22-ApAoJIAzFAlQAmAf23-AoLUV2AhLJ25-AlZOQOAn28-AdPO30-X124-F31-B30-2BC3(A28-B2C)A28-3(BCB29-)BCB17-Ag11-B2CA16-Az11-B2C2(A29-BC)A29-FCA30-2A6-D9-Q141-AmJKBa27-BfAwIAvFAm26-AzAsYAaApJK24-ZAhXRArLIR25-AsBaJHAuYV26-LTOMRAi25-AtUPI2J29-Ac156-F16-S14-BA14-Ad14-B31-B3A2(28-B2CA)25-Ab2-B2CA24-D3-2(BCB29-)2(B2CA28-)B2C2(A29-BC)A6-U22-FCA30-2A3-Ae186-AmRKAr27-AkWVRAzAv27-ApAi2VAq26-AmAfAqAiOU26-JKMAqAdO28-Ad-Ak187-F31-BA30-BA29-B31-BC2A5(28-B2CA)17-An10-B2CA28-CBiCA29-BCA6-Ad22-FCA29-HCA30-2A177-U25-ZS19-HAf28-PAaOBh29-ArIM28-Q-Ac252-F31-BA30-CA29-2B30-2(BC2A28-)B2CA16-F11-2(B2CA28-)CBCA29-B2A29-B-A29-FCA2(30-2A)13-AiJ31-Bh59-Ag9-Al11-DT19-O44-Q8-Ai52-I31-Al2-Ah35-K32-Y31-An29-XP20-Aq160-F26-E4-BA25-E4-CA25-E3-2(2B30-)2B2A28-CB2CA22-Y4-CB2CA27-BBi2CA5-Ad22-B31-F-A29-F2A30-2A130-D49-Au280-Ay117-K7-HY48-F16-Ab8-2E4-F5-H7-K11-2E4-B24-G2E4-BA22-3E5-BA21-4E5-B-4AB2A11EG5E6-B5AB2A12EG2E8-B5ABAB8ESW13-B5AB25-H31-F113-O2-K11-Ag8-K34-P135-Y20-Ae11-Ad4-Aw204-R-An99-D87-D25-F31-F23-2E6-B22-EGE3-Ag2-B4-2(AB)3E2G12E3-Bc2-B4-2(AB)2EG2E2GE7G8-F4-2(AB)6EG2EV13-F4-AB25-F25-Ap37-U21-F33-Ba29-Ai30-Ah145-D179-F21-Ac75-Af79-O89-O10-R33-An11-F19-Af11-3(F31-)F222-As304-T-S213-Ae3-Q48-S42-Q3-Ae35-M35-Ab223-Am188-Ba179-R11-Ah30-Aq46-Q126-
