model
size = 29 21 24, scale = 0.05, origin = -y
material 
  colors = A:#C90 B:#C96 C:#630 D:#E00 E:#800 F:#C99 G:#CC0 H:#EEE I:#F90 J:#B00
voxels
----------------------------- ----------------------------- ----------------------------- ----------------------------- ---------AAAAA--------------- ----------------------------- ----------------------------- ----------------------------- ----------------------------- ----------------------------- ----------------------------- ----------------------------- ----------------------------- ----------------------------- ----------------------------- ----------------------------- ----------------------------- ----------------------------- ----------------------------- ----------------------------- ----------------------------- 
----------------------------- ----------------------------- -------AAAAAAAAA------------- -------CCCCCCCCC------------- ------AAAAAAAAAAA------------ ----------------------------- ----------------------------- ----------------------------- ----------------------------- ----------------------------- ----------------------------- ----------------------------- ----------------------------- ----------------------------- ----------------------------- ----------------------------- ----------------------------- ----------------------------- ----------------------------- ----------------------------- ----------------------------- 
----------------------------- ----------------------------- -----AAAAAAAAAAAAA----------- -----CCCCCCCCCCCCC----------- -----AAAA-----AAAGA---------- ----------------------------- ----------------------------- ----------------------------- ----------------------------- ---------AAAAAA-------------- ---------AAAAAA-------------- ---------CAAAAA-------------- ----------------------------- ----------------------------- ----------------------------- ----------------------------- ----------------------------- ----------------------------- ----------------------------- ----------------------------- ----------------------------- 
----------------------------- ----------------------------- ----AAAAAAAAAAAAAAA---------- ----CCCCCCBBBBCCCCC---------- ---AAAA---BBBB--AAAA--------- ---------BBBBB--------------- ---------BBBBB--------------- ---------BBBBB--------------- ---------BBBBBB-------------- -------AAAAAAAAAA------------ -------ACAAAAAAAA------------ -------AACAAAAAAA------------ ---------BBBBBB-------------- ----------DDD---------------- ----------------------------- ----------------------------- ----------------------------- ----------------------------- ----------------------------- ----------------------------- ----------------------------- 
----------------------------- ----------------------------- ---AAAAAAAAAAAAAAAAA--------- ---CCCCBBBBBBBBBCCCC--------- --GAA--BBBBBBBBB--AAA-------- -------BBBB--BBB------------- -------FBB---BBB------------- -------BBB---BBB------------- -------BBB---BBBB------------ ------AAAAAAAAAAAA----------- ------AACAAAAAAAAA----------- ------AAAAAAAAAAAA----------- -------BBBBBBBBBB------------ -------DDDDDDDDD------------- ----------------------------- ----------------------------- ----------------------------- ----------------------------- ----------------------------- ----------------------------- ----------------------------- 
----------------------------- ----------------------------- --AAAAAAAAAAAAAAAAAAA-------- --CCCCBBBBBBBBBBBBCCC-------- --AA--BBBB----BEEE-CAA------- ------BB-------BBF----------- ------BB-------EFF----------- ------BB-------EBB----------- ------BB-------EEE----------- -----CAAAAAAAAAAAAA---------- -----AAAAAAAAAAAAAA---------- -----AAAAAAAAAAAAAA---------- ------BBB-----BBBB----------- ------DDDDDDDDDDD------------ ----------------------------- ----------------------------- ----------------------------- ----------------------------- ----------------------------- ----------------------------- ----------------------------- 
----------------------------- ----------------------------- --AAAAAAAAAAAAAAAAAAA-------- --CCCBBBBBBBBBBBBBCCC-------- -AAA-BBB-------EBB--AA------- -----BB----------B----------- -----BB----------B----------- -----BB----------B----------- -----BB----------B----------- ----AAAAAAAAAAAAAAAA--------- ----AAAAAAAAAAAAAAAA--------- ----AAAAAAAAAAAAAAAA--------- -----BBB--------BBB---------- -----DDDBBBBBBBDDD----------- --------BBFBFBB-------------- ----------------------------- ----------------------------- ----------------------------- ----------------------------- ----------------------------- ----------------------------- 
----------------------------- ----------------------------- -AAAAAAAAAAAAAAAAAAAAA------- -CCCCBBBBBBBBBBBBBBCCC------- -AA--BB---------BEE-AAG------ -----B-----------BB---------- -----B-----------EE---------- -----B-----------BB---------- ----BB-----------EE---------- ----AAAAAAAAAAAAAAAAA-------- ----AAAAAAAAAAAAAAAAA-------- ----AAAAAAAAAAAAAAAAA-------- ----BBB----------BB---------- -----DDBBBBBBBBBDDD---------- -------BBBBBBBBB------------- ----------------------------- ----------------------------- ----------------------------- ----------------------------- ----------------------------- ----------------------------- 
----------------------------- ----------------------------- -AAAAAAAAAAAAAAAAAAAAA------- -CCCBBBBBBBBBBBBBBBCCC------- AA--BB-----------EB--AA------ ----BB------------B---------- ----BB------------B---------- ----BB------------B---------- ----BB------------B---------- ---AAAAAAAAAAAAAAAAAA-------- ---AAAAAAAAAAAAAAAAAA-------- ---CAAAAAAAAAAAAAAAAA-------- ----BB-----------BBB--------- ----DDDBBB---BBBBDD---------- -------BBBBBBFBBB------------ ----------------------------- ----------------------------- ----------------------------- ----------------------------- ----------------------------- ----------------------------- 
----------------------------A ----------------------------- -AAAAAAAAAAAAAAAAAAAAAA------ -CCCBBBBBBBBBBBBBBBBCCC------ AA--BB------------BE-AA------ ----B-------------BE--------- ----B-------------BF--------- ----B-------------BB--------- ----B-------------EF--------- ---AAAAAAAAAAAAAAAAAA-------- ---AAAAAAAAAAAAAAAAAA-------- ---CAAAAAAAAAAAAAAAAA-------- ----BB------------BB--------- ----DDBBB------BBDDD--------- ------BBBBBBFBBBB------------ ----------------------------- ----------------------------- ----------------------------- ----------------------------- ----------------------------- ----------------------------- 
----------------------------- ----------------------------- -AAAAAAAAAAAAAAAAAAAAAA------ -CCCBBBBBBBBBBBBBBBBCCC------ GA--BB------------BB-AA------ ----B--------------B--------- ----B--------------B--------- ----B--------------B--------- ----B--------------B--------- ---AAAAAAAAAAAAAAAAAA-------- ---AAAAAAAAAAAAAAAAAA-------- ---AAAAAAAAAAAAAAAAAA-------- ----B-------------BB--------- ----DDBBB-BBB--BBDDD--------- ------BBBBBBBBBBB------------ ----------H------------------ ----------H------------------ ----------H------------------ ----------------------------- ----------J------------------ ----------------------------- 
----------------------------- ----------------------------- AAAAAAAAAAAAAAAAAAAAAAA------ CCCCBBBBBBBBBBBBBBBBCCC------ AA--BB------------BB-AA------ ----B--------------B--------- ----B--------------B--------- ----B--------------B--------- ----B--------------B--------- ---AAAAAAAAAAAAAAAAAA-------- ---AAAAAAAAAAAAAAAAAA-------- ---AAAAAAAAAAAAAAAAAA-------- ----B-------------BB--------- ----DDBB--BBBB-BBDDD--------- ------BBBBBBBBBBB------------ ------------H---------------- ------------H---------------- ------------H---------------- ------------H---------------- ----------------------------- ------------I---------------- 
----------------------------- ----------------------------- AAAAAAAAAAAAAAAAAAAAAAA------ CCCCBBBBBBBBBBBBBBBBCCC------ AA--EE------------BB-AA------ ----B--------------B--------- ----F--------------B--------- ----B--------------B--------- ----E--------------B--------- ---AAAAAAAA-AAAAAAAAA-------- ---AAAAAAAA-AAAAAAAAA-------- ---AAAAAAAA-AAAAAAAAA-------- ----B-------------BB--------- ----DDBBB--BBB-BBDDD--------- ------BBBBBBBBBBB------------ ----------------------------- ----------------------------- ----------------------------- ----------------------------- ----------------------------- ----------------------------- 
----------------------------- ----------------------------- -AAAAAAAAAAAAAAAAAAAAAA------ -CCCBBBBBBBBBBBBBBBBCCC------ AA--BB------------BB-AA------ ----B-------------BB--------- ----B-------------BB--------- ----B-------------BB--------- ----B-------------BB--------- ---AAAAAAAAAAAAAAAAAA-------- ---AAAAAAAAAAAAAAAAAA-------- ---AAAAAAAAAAAAAAAAAA-------- ----BB------------BB--------- ----DDBBB-----BBBDD---------- ------BBBBBBBBBBB------------ ----------------------------- ----------------------------- ----------------------------- ----------------------------- ----------------------------- ----------------------------- 
----------------------------- ----------------------------- -AAAAAAAAAAAAAAAAAAAAAA------ -CCCBBBBBBBBBBBBBBBCCCC------ AA--BEE----------BB--AG------ ----BB------------B---------- ----BE------------B---------- ----BB------------B---------- ----EE------------B---------- ---AAAAAAAAEEEAEAAAAA-------- ---AAAAAAAAAAAAAAAAAA-------- ---AAAAAAAAAAAAAAAAAA-------- ----BB-----------BB---------- -----DDBBBB-BBBBBDD---------- -------BBBBBBBBBB------------ ----------------------------- ----------------------------- ----------------------------- ----------------------------- ----------------------------- ----------------------------- 
----------------------------- ----------------------------- -AAAAAAAAAAAAAAAAAAAAA------- -CCCCBBBBBBBBBBBBBBCCC------- AA---FB---------BBB--AA------ -----BB----------BB---------- -----B-----------BB---------- -----B-----------BB---------- -----E-----------BB---------- ----AAAAAAAAAAAAAAAG--------- ----AAAAAAAAAAAAAAAA--------- ----CAAAAAAAAAAAAAAA--------- -----BB---------BBB---------- -----DDDBBBBBBBBDDD---------- --------BBBBBBBB------------- ----------------------------- ----------------------------- ----------------------------- ----------------------------- ----------------------------- ----------------------------- 
----------------------------- ----------------------------- -AAAAAAAAAAAAAAAAAAAAA------- -CCCCCBBBBBBBBBBBBCCCC------- -AA---BEB------BBB--AA------- -----FBE--------BB----------- -----FB---------BB----------- -----BB---------BB----------- -----FE---------BB----------- ----CAAAAAAEEEEEAAAC--------- ----AAAAAAAAAAAAAAAA--------- ----GAAAAAAAAAAAAAAG--------- -----BBB-------BBB----------- ------DDDBBBBBDDDD----------- ---------BBBBB--------------- ----------------------------- ----------------------------- ----------------------------- ----------------------------- ----------------------------- ----------------------------- 
----------------------------- ----------------------------- --AAAAAAAAAAAAAAAAAAA-------- --CCCCCBBBBBBBBBBCCCC-------- -AAA---BBBBBBBBBB---AA------- ------BBB-----BEB------------ ------BBB------BB------------ ------BBB------BB------------ ------BBB------BB------------ -----AAAAAAEAEAAAAA---------- -----AAAAAAAAAAAAAA---------- -----AAAAAAAAAAAAAG---------- ------BBBB---BBBB------------ -------DDDDDDDDDD------------ ----------------------------- ----------------------------- ----------------------------- ----------------------------- ----------------------------- ----------------------------- ----------------------------- 
----------------------------- ----------------------------- --AAAAAAAAAAAAAAAAAAA-------- --CCCCCCBBBBBBBCCCCCC-------- --AA----BBBBBBB----AA-------- --------BBBEFFBE------------- --------BBBBBFBE------------- --------BBBFBFBE------------- --------BBBEBBBB------------- -----AAAAAAEAEEEAAA---------- -----AAAAAAAAAAAAAG---------- -----GAAAAAAAAAAAAC---------- --------BBBBBBBB------------- --------DDDDDDD-------------- ----------------------------- ----------------------------- ----------------------------- ----------------------------- ----------------------------- ----------------------------- ----------------------------- 
----------------------------- ----------------------------- ---AAAAAAAAAAAAAAAAA--------- ---CCCCCCCCCCCCCCCCC--------- ---AAA------------AAA-------- ----------------------------- ----------------------------- ----------------------------- ----------------------------- -------AAAAAAAAAA------------ -------CAAAAAAAAA------------ -------GCAAAAAAAA------------ ----------------------------- ----------------------------- ----------------------------- ----------------------------- ----------------------------- ----------------------------- ----------------------------- ----------------------------- ----------------------------- 
----------------------------- ----------------------------- ----AAAAAAAAAAAAAAA---------- ----CCCCCCCCCCCCCCC---------- ---AGAA---------AAAA--------- ----------------------------- ----------------------------- ----------------------------- ----------------------------- ----------------------------- ----------------------------- ----------------------------- ----------------------------- ----------------------------- ----------------------------- ----------------------------- ----------------------------- ----------------------------- ----------------------------- ----------------------------- ----------------------------- 
----------------------------- ----------------------------- ------AAAAAAAAAAAA----------- ------CCCCCCCCCCCC----------- -----AAAA-----AAAAA---------- ----------------------------- ----------------------------- ----------------------------- ----------------------------- ----------------------------- ----------------------------- ----------------------------- ----------------------------- ----------------------------- ----------------------------- ----------------------------- ----------------------------- ----------------------------- ----------------------------- ----------------------------- ----------------------------- 
----------------------------- ----------------------------- --------AAAAAAA-------------- --------CCCCCCC-------------- ------AAAAAAAAAAA------------ ----------------------------- ----------------------------- ----------------------------- ----------------------------- ----------------------------- ----------------------------- ----------------------------- ----------------------------- ----------------------------- ----------------------------- ----------------------------- ----------------------------- ----------------------------- ----------------------------- ----------------------------- ----------------------------- 
----------------------------- ----------------------------- ----------------------------- ----------------------------- ----------AGA---------------- ----------------------------- ----------------------------- ----------------------------- ----------------------------- ----------------------------- ----------------------------- ----------------------------- ----------------------------- ----------------------------- ----------------------------- ----------------------------- ----------------------------- ----------------------------- ----------------------------- ----------------------------- ----------------------------- 
