model
size = 17 32 16, scale = 0.05, origin = -y
material 
  colors = A:#963 B:#960 C:#630
voxels
265-2(2C15-)2C11-2C2-2C11-4(2C15-)2C151-5C15(12-5A)4(C11-5A)3(2C10-5A)2C10-C4A2C10-5C129-9C15(8-2A5-2A)7(6-2C2A5-2A)8-2C5-2A8-2C5-2C12-3(A33-)A11-11C12(6-A4-2B3-A)9(5-CA4-2B3-A)5-CA5-B3-A6-C4-2B3-C6-C21-3(B2-A30-)B2-A7-13C14(4-A5-2(2B-)A)3(4-A5-BC-2B-A)3(4-A6-C-2B-A)2(4-A6-C2-B-A)4-A6-C-2B-2(C4-C6-)3(A4-C-B14-C11-)A4-C-B7-13C14(4-A-2B2-2(2B-)A)5(4-A-2B2-B2-2B-A)4-A-B6-2B-A4-A-2(B3-)B-A4-A-B6-AC-A4-A-2(B3-)C-C4-C9-C-C6-3(2(B3-)C16-C8-)2(B3-)C5-15C2-A9(2-2B5-2B2(2-A))4(2-BC5-2B2-AC-A)7(2-BC5-2B2-A2CA)2-B2(C5-2B2-AC-C3-)C5-B3-C6-C9-C6-3(C5-B10-C16-)C5-B6-15C2-A2(2-2B)8(5-2(A2-)2B2-2B)2(5-2(A2-)B3-2B)3(5-A-CA2-B3-2B)5-A2CA2-B3-2B5-4(A2CA2-B3-B6-)A2CA2-B10-A2CA2-B3-B6-AC-C13-AC4-B3-B6-C16-C5-3(B3-B2-A26-)B3-B9-15C10(2-A6-2B5-A)2-3(A6-BC5-A-C)A6-B7(C5-A2CA7-)C5-AC-C7-C5-AC4-A4-C2-A2-C10-C5-C10-C16-C11-A4-C2-A13-2(C16-)C11-A4-C2-A5-15C10(2-A6-2B2-2B-A)11(2-A6-B3-2B-A)2-C10-2B-A9-B3-2B-C16-C5-A2(3-B)29-B3-B25-A2(3-B)29-B3-B5-15C2-A2-20(BC6-2B-2(A2-))BC6-2B-A2-C10-BC-A5-B7-BC-C14-C-C5-3(B8-C16-C7-)B8-C5-13C12(4-A-BC2(2-2B)A)5(C3-A-BC2(2-2B)A)C3-A-BC3-B2-2BAC3-A-BC2(2-2B)AC3-A-BC6-2BAC3-A-BC2-B3-2BAC3-A2-C6-2BAC6-C2-C3-3C7-3(C16-C2-B3-B9-)C16-C2-B3-B6-13C4-A7(-BC2-2B2(4-A))7(-BC2-BC2(4-A))3(-B3-BC2(4-A))3(-B3-BC4-AC3-A)5-2C4-AC3-C-2(C4-)AC10-C4-C6-B4-C16-C2-A8-B4-C16-2(C2-A13-C11-B4-)C2-A7-11C7(6-A4-2B3-A)5(6-A4-B4-A)6-A-C2-7(B4-A6-A4-)B4-A6-A9-A6-C4-B4-A11-C4-C7-A20-B12-A20-2(B29-A3-)B12-9C12(8-2A5-2A)8-9(A6-2AC7-)C6-2AC7-C6-2C29-3(A33-)A14-5C13(12-5A)8(10-2C5A)10-4C3A10-7C142-
