model
size = 5 31 17, scale = 0.05, origin = -y
material 
  colors = A:#960 B:#C60 C:#FC9 D:#FC0 E:#963
voxels
--A-- ----- ----- ----- ----- ----- ----- ----- ----- ----- ----- ----- ----- ----- ----- ----- ----- ----- ----- ----- ----- ----- ----- ----- ----- ----- ----- ----- ----- ----- --A-- 
-DAD- --A-- ----- ----- ----- ----- ----- ----- ----- ----- ----- ----- ----- ----- ----- ----- ----- ----- ----- ----- ----- ----- ----- ----- ----- ----- ----- ----- ----- --A-- -DAD- 
DDADD --A-- --A-- --C-- --C-- --C-- --C-- --C-- --C-- --C-- --C-- --C-- --C-- --C-- --E-- --E-- --E-- --C-- --C-- --C-- --C-- --C-- --C-- --C-- --C-- --C-- --C-- --C-- --A-- --A-- DDADD 
DAAAD -AAA- -AAA- ----- ----- ----- ----- ----- ----- ----- ----- ----- ----- ----- ----- ----- ----- ----- ----- ----- ----- ----- ----- ----- ----- ----- ----- ----- -AAA- -AAA- DAAAD 
-AAA- -BAA- -AAA- ----- ----- ----- ----- ----- ----- ----- ----- ----- ----- ----- ----- ----- ----- ----- ----- ----- ----- ----- ----- ----- ----- ----- ----- ----- -AAA- -BAB- -AAA- 
--B-- -AAA- -AAA- ----- ----- ----- ----- ----- ----- ----- ----- ----- ----- ----- ----- ----- ----- ----- ----- ----- ----- ----- ----- ----- ----- ----- ----- ----- -AAB- -BAA- --B-- 
--B-- -AAB- -BAA- ----- ----- ----- ----- ----- ----- ----- ----- ----- ----- ----- ----- ----- ----- ----- ----- ----- ----- ----- ----- ----- ----- ----- ----- ----- -BAA- -AAA- --B-- 
--B-- -AAA- -AAB- -BAA- ----- ----- ----- ----- ----- ----- ----- ----- ----- ----- ----- ----- ----- ----- ----- ----- ----- ----- ----- ----- ----- ----- ----- -AAA- -AAB- -AAA- --B-- 
----- --B-- -AAA- -BAB- ----- ----- ----- ----- ----- ----- ----- ----- ----- ----- ----- ----- ----- ----- ----- ----- ----- ----- ----- ----- ----- ----- ----- -BAB- -AAA- --B-- ----- 
----- --B-- -AAA- -BAA- -AAB- ----- ----- ----- ----- ----- ----- ----- ----- ----- ----- ----- ----- ----- ----- ----- ----- ----- ----- ----- ----- ----- -AAA- -BAA- -AAA- --B-- ----- 
----- ----- --B-- -AAA- -BAB- ----- ----- ----- ----- ----- ----- ----- ----- ----- ----- ----- ----- ----- ----- ----- ----- ----- ----- ----- ----- ----- -BAB- -AAA- --B-- ----- ----- 
----- ----- ----- --B-- -BAA- -BAB- ----- ----- ----- ----- ----- ----- ----- ----- ----- ----- ----- ----- ----- ----- ----- ----- ----- ----- ----- -AAB- -AAA- --B-- ----- ----- ----- 
----- ----- ----- ----- --B-- -AAA- -BAB- ----- ----- ----- ----- ----- ----- ----- ----- ----- ----- ----- ----- ----- ----- ----- ----- ----- -AAB- -BAA- --B-- ----- ----- ----- ----- 
----- ----- ----- ----- ----- --B-- -BAA- -AAB- ----- ----- ----- ----- ----- ----- ----- ----- ----- ----- ----- ----- ----- ----- ----- -AAB- -BAA- --B-- ----- ----- ----- ----- ----- 
----- ----- ----- ----- ----- ----- --B-- -AAA- -BAB- -BBB- ----- ----- ----- ----- ----- ----- ----- ----- ----- ----- ----- -AAB- -BAB- -AAA- --B-- ----- ----- ----- ----- ----- ----- 
----- ----- ----- ----- ----- ----- ----- --B-- --B-- -AAB- -BAB- -AAA- ----- ----- ----- ----- ----- ----- ----- -AAA- -AAA- -BAA- --B-- --B-- ----- ----- ----- ----- ----- ----- ----- 
----- ----- ----- ----- ----- ----- ----- ----- ----- --B-- --B-- --B-- --A-- --A-- --A-- --A-- --A-- --A-- --A-- --B-- --B-- --B-- ----- ----- ----- ----- ----- ----- ----- ----- ----- 
