model
size = 27 29 27, scale = 0.05, origin = -y
material 
  colors = A:#D00 B:#F90 C:#9CF D:#90C E:#606 F:#90F G:#C3C H:#609 I:#636 J:#93C
voxels
------------BBB------------ ------------BBB------------ ------------BBB------------ ------------BBB------------ ------------BBB------------ ------------BBB------------ ------------BBB------------ ------------BBB------------ ------------BBB------------ ------------BBB------------ ------------BBB------------ ------------BBB------------ ------------BBB------------ ------------BBB------------ ------------BBB------------ ------------BBB------------ ------------BBB------------ ------------BBB------------ ------------BBB------------ ------------BBB------------ ------------BBB------------ ------------BBB------------ --------------------------- --------------------------- --------------------------- --------------------------- --------------------------- --------------------------- --------------------------- 
------------BBB------------ -AAAAAAAAAAACCCAAAAAAAAAAA- -AAAAAAAAAAACCCAAAAAAAAAAA- -AAAAAAAAAAABBBAAAAAAAAAAA- -AAAAAAAAAAABBBAAAAAAAAAAA- -AAAAAAAAAAABBBAAAAAAAAAAA- -AAAAAAAAAAABBBAAAAAAAAAAA- -AAAAAAAAAAABBBAAAAAAAAAAA- -AAAAAAAAAAABBBAAAAAAAAAAA- -AAAAAAAAAAABBBAAAAAAAAAAA- -AAAAAAAAAAABBBAAAAAAAAAAA- -AAAAAAAAAAABBBAAAAAAAAAAA- -AAAAAAAAAAABBBAAAAAAAAAAA- -AAAAAAAAAAABBBAAAAAAAAAAA- -AAAAAAAAAAABBBAAAAAAAAAAA- -AAAAAAAAAAABBBAAAAAAAAAAA- -AAAAAAAAAAABBBAAAAAAAAAAA- -AAAAAAAAAAABBBAAAAAAAAAAA- -AAAAAAAAAAABBBAAAAAAAAAAA- -AAAAAAAAAAABBBAAAAAAAAAAA- -AAAAAAAAAAABBBAAAAAAAAAAA- ------------BBB------------ --------------------------- --------------------------- --------------------------- --------------------------- --------------------------- --------------------------- --------------------------- 
------------BBB------------ -AAAAAAAAAAACCCAAAAAAAAAAA- -AAAAAAAAAAACCCAAAAAAAAAAA- -AAAAAAAAAAABBBAAAAAAAAAAA- -AAAAAAAAAAABBBAAAAAAAAAAA- -AAAAAAAAAAABBBAAAAAAAAAAA- -AAAAAAAAAAABBBAAAAAAAAAAA- -AAAAAAAAAAABBBAAAAAAAAAAA- -AAAAAAAAAAABBBAAAAAAAAAAA- -AAAAAAAAAAABBBAAAAAAAAAAA- -AAAAAAAAAAABBBAAAAAAAAAAA- -AAAAAAAAAAABBBAAAAAAAAAAA- -AAAAAAAAAAABBBAAAAAAAAAAA- -AAAAAAAAAAABBBAAAAAAAAAAA- -AAAAAAAAAAABBBAAAAAAAAAAA- -AAAAAAAAAAABBBAAAAAAAAAAA- -AAAAAAAAAAABBBAAAAAAAAAAA- -AAAAAAAAAAABBBAAAAAAAAAAA- -AAAAAAAAAAABBBAAAAAAAAAAA- -AAAAAAAAAAABBBAAAAAAAAAAA- -AAAAAAAAAAABBBAAAAAAAAAAA- ------------BBB------------ --------------------------- --------------------------- --------------------------- --------------------------- --------------------------- --------------------------- --------------------------- 
------------BBB------------ -AAAAAAAAAAACCCAAAAAAAAAAA- -AAAAAAAAAAACCCAAAAAAAAAAA- -AAAAAAAAAAABBBAAAAAAAAAAA- -AAAAAAAAAAABBBAAAAAAAAAAA- -AAAAAAAAAAABBBAAAAAAAAAAA- -AAAAAAAAAAABBBAAAAAAAAAAA- -AAAAAAAAAAABBBAAAAAAAAAAA- -AAAAAAAAAAABBBAAAAAAAAAAA- -AAAAAAAAAAABBBAAAAAAAAAAA- -AAAAAAAAAAABBBAAAAAAAAAAA- -AAAAAAAAAAABBBAAAAAAAAAAA- -AAAAAAAAAAABBBAAAAAAAAAAA- -AAAAAAAAAAABBBAAAAAAAAAAA- -AAAAAAAAAAABBBAAAAAAAAAAA- -AAAAAAAAAAABBBAAAAAAAAAAA- -AAAAAAAAAAABBBAAAAAAAAAAA- -AAAAAAAAAAABBBAAAAAAAAAAA- -AAAAAAAAAAABBBAAAAAAAAAAA- -AAAAAAAAAAABBBAAAAAAAAAAA- -AAAAAAAAAAABBBAAAAAAAAAAA- ------------BBB------------ --------------------------- --------------------------- --------------------------- --------------------------- --------------------------- --------------------------- --------------------------- 
------------BBB------------ -AAAAAAAAAAACCCAAAAAAAAAAA- -AAAAAAAAAAACCCAAAAAAAAAAA- -AAAAAAAAAAABBBAAAAAAAAAAA- -AAAAAAAAAAABBBAAAAAAAAAAA- -AAAAAAAAAAABBBAAAAAAAAAAA- -AAAAAAAAAAABBBAAAAAAAAAAA- -AAAAAAAAAAABBBAAAAAAAAAAA- -AAAAAAAAAAABBBAAAAAAAAAAA- -AAAAAAAAAAABBBAAAAAAAAAAA- -AAAAAAAAAAABBBAAAAAAAAAAA- -AAAAAAAAAAABBBAAAAAAAAAAA- -AAAAAAAAAAABBBAAAAAAAAAAA- -AAAAAAAAAAABBBAAAAAAAAAAA- -AAAAAAAAAAABBBAAAAAAAAAAA- -AAAAAAAAAAABBBAAAAAAAAAAA- -AAAAAAAAAAABBBAAAAAAAAAAA- -AAAAAAAAAAABBBAAAAAAAAAAA- -AAAAAAAAAAABBBAAAAAAAAAAA- -AAAAAAAAAAABBBAAAAAAAAAAA- -AAAAAAAAAAABBBAAAAAAAAAAA- ------------BBB------------ --------------------------- --------------------------- --------------------------- --------------------------- --------------------------- --------------------------- --------------------------- 
------------BBB------------ -AAAAAAAAAAACCCAAAAAAAAAAA- -AAAAAAAAAAACCCAAAAAAAAAAA- -AAAAAAAAAAABBBAAAAAAAAAAA- -AAAAAAAAAAABBBAAAAAAAAAAA- -AAAAAAAAAAABBBAAAAAAAAAAA- -AAAAAAAAAAABBBAAAAAAAAAAA- -AAAAAAAAAAABBBAAAAAAAAAAA- -AAAAAAAAAAABBBAAAAAAAAAAA- -AAAAAAAAAAABBBAAAAAAAAAAA- -AAAAAAAAAAABBBAAAAAAAAAAA- -AAAAAAAAAAABBBAAAAAAAAAAA- -AAAAAAAAAAABBBAAAAAAAAAAA- -AAAAAAAAAAABBBAAAAAAAAAAA- -AAAAAAAAAAABBBAAAAAAAAAAA- -AAAAAAAAAAABBBAAAAAAAAAAA- -AAAAAAAAAAABBBAAAAAAAAAAA- -AAAAAAAAAAABBBAAAAAAAAAAA- -AAAAAAAAAAABBBAAAAAAAAAAA- -AAAAAAAAAAABBBAAAAAAAAAAA- -AAAAAAAAAAABBBAAAAAAAAAAA- ------------BBB------------ --------------------------- --------------------------- --------------------------- --------------------------- --------------------------- --------------------------- --------------------------- 
------------BBB------------ -AAAAAAAAAAACCCAAAAAAAAAAA- -AAAAAAAAAAACCCAAAAAAAAAAA- -AAAAAAAAAAABBBAAAAAAAAAAA- -AAAAAAAAAAABBBAAAAAAAAAAA- -AAAAAAAAAAABBBAAAAAAAAAAA- -AAAAAAAAAAABBBAAAAAAAAAAA- -AAAAAAAAAAABBBAAAAAAAAAAA- -AAAAAAAAAAABBBAAAAAAAAAAA- -AAAAAAAAAAABBBAAAAAAAAAAA- -AAAAAAAAAAABBBAAAAAAAAAAA- -AAAAAAAAAAABBBAAAAAAAAAAA- -AAAAAAAAAAABBBAAAAAAAAAAA- -AAAAAAAAAAABBBAAAAAAAAAAA- -AAAAAAAAAAABBBAAAAAAAAAAA- -AAAAAAAAAAABBBAAAAAAAAAAA- -AAAAAAAAAAABBBAAAAAAAAAAA- -AAAAAAAAAAABBBAAAAAAAAAAA- -AAAAAAAAAAABBBAAAAAAAAAAA- -AAAAAAAAAAABBBAAAAAAAAAAA- -AAAAAAAAAAABBBAAAAAAAAAAA- ------------BBB------------ --------------------------- --------------------------- --------------------------- --------------------------- --------------------------- --------------------------- --------------------------- 
------------BBB------------ -AAAAAAAAAAACCCAAAAAAAAAAA- -AAAAAAAAAAACCCAAAAAAAAAAA- -AAAAAAAAAAABBBAAAAAAAAAAA- -AAAAAAAAAAABBBAAAAAAAAAAA- -AAAAAAAAAAABBBAAAAAAAAAAA- -AAAAAAAAAAABBBAAAAAAAAAAA- -AAAAAAAAAAABBBAAAAAAAAAAA- -AAAAAAAAAAABBBAAAAAAAAAAA- -AAAAAAAAAAABBBAAAAAAAAAAA- -AAAAAAAAAAABBBAAAAAAAAAAA- -AAAAAAAAAAABBBAAAAAAAAAAA- -AAAAAAAAAAABBBAAAAAAAAAAA- -AAAAAAAAAAABBBAAAAAAAAAAA- -AAAAAAAAAAABBBAAAAAAAAAAA- -AAAAAAAAAAABBBAAAAAAAAAAA- -AAAAAAAAAAABBBAAAAAAAAAAA- -AAAAAAAAAAABBBAAAAAAAAAAA- -AAAAAAAAAAABBBAAAAAAAAAAA- -AAAAAAAAAAABBBAAAAAAAAAAA- -AAAAAAAAAAABBBAAAAAAAAAAA- ------------BBB------------ --------------------------- --------------------------- --------------------------- --------------------------- --------------------------- --------------------------- --------------------------- 
------------BBB------------ -AAAAAAAAAAACCCAAAAAAAAAAA- -AAAAAAAAAAACCCAAAAAAAAAAA- -AAAAAAAAAAABBBAAAAAAAAAAA- -AAAAAAAAAAABBBAAAAAAAAAAA- -AAAAAAAAAAABBBAAAAAAAAAAA- -AAAAAAAAAAABBBAAAAAAAAAAA- -AAAAAAAAAAABBBAAAAAAAAAAA- -AAAAAAAAAAABBBAAAAAAAAAAA- -AAAAAAAAAAABBBAAAAAAAAAAA- -AAAAAAAAAAABBBAAAAAAAAAAA- -AAAAAAAAAAABBBAAAAAAAAAAA- -AAAAAAAAAAABBBAAAAAAAAAAA- -AAAAAAAAAAABBBAAAAAAAAAAA- -AAAAAAAAAAABBBAAAAAAAAAAA- -AAAAAAAAAAABBBAAAAAAAAAAA- -AAAAAAAAAAABBBAAAAAAAAAAA- -AAAAAAAAAAABBBAAAAAAAAAAA- -AAAAAAAAAAABBBAAAAAAAAAAA- -AAAAAAAAAAABBBAAAAAAAAAAA- -AAAAAAAAAAABBBAAAAAAAAAAA- ------------BBB------------ --------------------------- --------------------------- --------------------------- --------------------------- --------------------------- --------------------------- --------------------------- 
------------BBB------------ -AAAAAAAAAAACCCAAAAAAAAAAA- -AAAAAAAAAAACCCAAAAAAAAAAA- -AAAAAAAAAAABBBAAAAAAAAAAA- -AAAAAAAAAAABBBAAAAAAAAAAA- -AAAAAAAAAAABBBAAAAAAAAAAA- -AAAAAAAAAAABBBAAAAAAAAAAA- -AAAAAAAAAAABBBAAAAAAAAAAA- -AAAAAAAAAAABBBAAAAAAAAAAA- -AAAAAAAAAAABBBAAAAAAAAAAA- -AAAAAAAAAAABBBAAAAAAAAAAA- -AAAAAAAAAAABBBAAAAAAAAAAA- -AAAAAAAAAAABBBAAAAAAAAAAA- -AAAAAAAAAAABBBAAAAAAAAAAA- -AAAAAAAAAAABBBAAAAAAAAAAA- -AAAAAAAAAAABBBAAAAAAAAAAA- -AAAAAAAAAAABBBAAAAAAAAAAA- -AAAAAAAAAAABBBAAAAAAAAAAA- -AAAAAAAAAAABBBAAAAAAAAAAA- -AAAAAAAAAAABBBAAAAAAAAAAA- -AAAAAAAAAAABBBAAAAAAAAAAA- ------------BBB------------ --------------------------- --------------------------- --------------------------- --------------------------- --------------------------- --------------------------- --------------------------- 
------------BBB------------ -AAAAAAAAAAACCCAAAAAAAAAAA- -AAAAAAAAAAACCCAAAAAAAAAAA- -AAAAAAAAAAABBBAAAAAAAAAAA- -AAAAAAAAAAABBBAAAAAAAAAAA- -AAAAAAAAAAABBBAAAAAAAAAAA- -AAAAAAAAAAABBBAAAAAAAAAAA- -AAAAAAAAAAABBBAAAAAAAAAAA- -AAAAAAAAAAABBBAAAAAAAAAAA- -AAAAAAAAAAABBBAAAAAAAAAAA- -AAAAAAAAAAABBBAAAAAAAAAAA- -AAAAAAAAAAABBBAAAAAAAAAAA- -AAAAAAAAAAABBBAAAAAAAAAAA- -AAAAAAAAAAABBBAAAAAAAAAAA- -AAAAAAAAAAABBBAAAAAAAAAAA- -AAAAAAAAAAABBBAAAAAAAAAAA- -AAAAAAAAAAABBBAAAAAAAAAAA- -AAAAAAAAAAABBBAAAAAAAAAAA- -AAAAAAAAAAABBBAAAAAAAAAAA- -AAAAAAAAAAABBBAAAAAAAAAAA- -AAAAAAAAAAABBBAAAAAAAAAAA- ------------BBB------------ --------------------------- --------------------------- --------------------------- -------------D------------- --------------------------- --------------------------- --------------------------- 
------------BBB------------ -AAAAAAAAAAACCCAAAAAAAAAAA- -AAAAAAAAAAACCCAAAAAAAAAAA- -AAAAAAAAAAABBBAAAAAAAAAAA- -AAAAAAAAAAABBBAAAAAAAAAAA- -AAAAAAAAAAABBBAAAAAAAAAAA- -AAAAAAAAAAABBBAAAAAAAAAAA- -AAAAAAAAAAABBBAAAAAAAAAAA- -AAAAAAAAAAABBBAAAAAAAAAAA- -AAAAAAAAAAABBBAAAAAAAAAAA- -AAAAAAAAAAABBBAAAAAAAAAAA- -AAAAAAAAAAABBBAAAAAAAAAAA- -AAAAAAAAAAABBBAAAAAAAAAAA- -AAAAAAAAAAABBBAAAAAAAAAAA- -AAAAAAAAAAABBBAAAAAAAAAAA- -AAAAAAAAAAABBBAAAAAAAAAAA- -AAAAAAAAAAABBBAAAAAAAAAAA- -AAAAAAAAAAABBBAAAAAAAAAAA- -AAAAAAAAAAABBBAAAAAAAAAAA- -AAAAAAAAAAABBBAAAAAAAAAAA- -AAAAAAAAAAABBBAAAAAAAAAAA- ------------BBB------------ --------------------------- --------------------------- ------------GGJ------------ ------------DDJ------------ ------------DDJ------------ --------------------------- --------------------------- 
BBBBBBBBBBBBBBBBBBBBBBBBBBB BCCCCCCCCCCCCCCCCCCCCCCCCCB BCCCCCCCCCCCCCCCCCCCCCCCCCB BCCCCCCCCCCCCCCCCCCCCCCCCCB BCCCCCCCCCCCCCCCCCCCCCCCCCB BCCCCCCCCCCCCCCCCCCCCCCCCCB BCCCCCCCCCCCCCCCCCCCCCCCCCB BCCCCCCCCCCCCCCCCCCCCCCCCCB BCCCCCCCCCCCCCCCCCCCCCCCCCB BCCCCCCCCCCCCCCBBBBBBBBBBBB BCCCCCCCCCCCCCCBBBBBBBBBBBB BCCCCCCCCCCCCCCBBBBBBBBBBBB BCCCCCCCCCCCCCCBBBBBBBBBBBB BCCCCCCCCCCCCCCBBBBBBBBBBBB BCCCCCCCCCCCCCCBBBBBBBBBBBB BCCCCCCCCCCCCCCBBBBBBBBBBBB BCCCCCCCCCCCCCCBBBBBBBBBBBB BCCCCCCCCCCCCCCBBBBBBBBBBBB BCCCCCCCCCCCCCCBBBBBBBBBBBB BCCCCCCCCCCCCCCBBBBBBBBBBBB BCCCCCCCCCCCCCCBBBBBBBBBBBB BBBBBBBBBBBBBCBBBBBBBBBBBBB -------------G------------- ------------GGI------------ -----------GGGII----------- -----------DDFJF----------- -----------DDFJF----------- ------------DFF------------ --------------------------- 
BBBBBBBBBBBBBBBBBBBBBBBBBBB BCCCCCCCCCCCCCCCCCCCCCCCCCB BCCCCCCCCCCCCCCCCCCCCCCCCCB BCCCCCCCCCCCCCCCCCCCCCCCCCB BCCCCCCCCCCCCCCCCCCCCCCCCCB BCCCCCCCCCCCCCCCCCCCCCCCCCB BCCCCCCCCCCCCCCCCCCCCCCCCCB BCCCCCCCCCCCCCCCCCCCCCCCCCB BCCCCCCCCCCCCCCCCCCCCCCCCCB BCCCCCCCCCCCCCCBBBBBBBBBBBB BCCCCCCCCCCCCCCBBBBBBBBBBBB BCCCCCCCCCCCCCCBBBBBBBBBBBB BCCCCCCCCCCCCCCBBBBBBBBBBBB BCCCCCCCCCCCCCCBBBBBBBBBBBB BCCCCCCCCCCCCCCBBBBBBBBBBBB BCCCCCCCCCCCCCCBBBBBBBBBBBB BCCCCCCCCCCCCCCBBBBBBBBBBBB BCCCCCCCCCCCCCCBBBBBBBBBBBB BCCCCCCCCCCCCCCBBBBBBBBBBBB BCCCCCCCCCCCCCCBBBBBBBBBBBB BCCCCCCCCCCCCCCBBBBBBBBBBBB BBBBBBBBBBBBBCCBBBBBBBBBBBB ------------EEE------------ ------------EEE------------ -----------ECCII----------- ----------EEDFFFF---------- -----------DDFFF----------- ------------DFF------------ -------------G------------- 
BBBBBBBBBBBBBBBBBBBBBBBBBBB BCCCCCCCCCCCCCCCCCCCCCCCCCB BCCCCCCCCCCCCCCCCCCCCCCCCCB BCCCCCCCCCCCCCCCCCCCCCCCCCB BCCCCCCCCCCCCCCCCCCCCCCCCCB BCCCCCCCCCCCCCCCCCCCCCCCCCB BCCCCCCCCCCCCCCCCCCCCCCCCCB BCCCCCCCCCCCCCCCCCCCCCCCCCB BCCCCCCCCCCCCCCCCCCCCCCCCCB BCCCCCCCCCCCCCCBBBBBBBBBBBB BCCCCCCCCCCCCCCBBBBBBBBBBBB BCCCCCCCCCCCCCCBBBBBBBBBBBB BCCCCCCCCCCCCCCBBBBBBBBBBBB BCCCCCCCCCCCCCCBBBBBBBBBBBB BCCCCCCCCCCCCCCBBBBBBBBBBBB BCCCCCCCCCCCCCCBBBBBBBBBBBB BCCCCCCCCCCCCCCBBBBBBBBBBBB BCCCCCCCCCCCCCCBBBBBBBBBBBB BCCCCCCCCCCCCCCBBBBBBBBBBBB BCCCCCCCCCCCCCCBBBBBBBBBBBB BCCCCCCCCCCCCCCBBBBBBBBBBBB BBBBBBBBBBBBBCBBBBBBBBBBBBB -------------E------------- ------------EEE------------ -----------ECCCG----------- -----------EDCCG----------- -----------DDCCG----------- ------------DHH------------ --------------------------- 
------------BBB------------ -AAAAAAAAAAACCCAAAAAAAAAAA- -AAAAAAAAAAACCCAAAAAAAAAAA- -AAAAAAAAAAACCCAAAAAAAAAAA- -AAAAAAAAAAACCCAAAAAAAAAAA- -AAAAAAAAAAACCCAAAAAAAAAAA- -AAAAAAAAAAACCCAAAAAAAAAAA- -AAAAAAAAAAACCCAAAAAAAAAAA- -AAAAAAAAAAACCCAAAAAAAAAAA- -AAAAAAAAAAACCCAAAAAAAAAAA- -AAAAAAAAAAACCCAAAAAAAAAAA- -AAAAAAAAAAACCCAAAAAAAAAAA- -AAAAAAAAAAACCCAAAAAAAAAAA- -AAAAAAAAAAACCCAAAAAAAAAAA- -AAAAAAAAAAACCCAAAAAAAAAAA- -AAAAAAAAAAACCCAAAAAAAAAAA- -AAAAAAAAAAABBBAAAAAAAAAAA- -AAAAAAAAAAABBBAAAAAAAAAAA- -AAAAAAAAAAABBBAAAAAAAAAAA- -AAAAAAAAAAABBBAAAAAAAAAAA- -AAAAAAAAAAABBBAAAAAAAAAAA- ------------BBB------------ --------------------------- --------------------------- ------------HHH------------ ------------HHH------------ ------------HHH------------ --------------------------- --------------------------- 
------------BBB------------ -AAAAAAAAAAACCCAAAAAAAAAAA- -AAAAAAAAAAACCCAAAAAAAAAAA- -AAAAAAAAAAACCCAAAAAAAAAAA- -AAAAAAAAAAACCCAAAAAAAAAAA- -AAAAAAAAAAACCCAAAAAAAAAAA- -AAAAAAAAAAACCCAAAAAAAAAAA- -AAAAAAAAAAACCCAAAAAAAAAAA- -AAAAAAAAAAACCCAAAAAAAAAAA- -AAAAAAAAAAACCCAAAAAAAAAAA- -AAAAAAAAAAACCCAAAAAAAAAAA- -AAAAAAAAAAACCCAAAAAAAAAAA- -AAAAAAAAAAACCCAAAAAAAAAAA- -AAAAAAAAAAACCCAAAAAAAAAAA- -AAAAAAAAAAACCCAAAAAAAAAAA- -AAAAAAAAAAACCCAAAAAAAAAAA- -AAAAAAAAAAABBBAAAAAAAAAAA- -AAAAAAAAAAABBBAAAAAAAAAAA- -AAAAAAAAAAABBBAAAAAAAAAAA- -AAAAAAAAAAABBBAAAAAAAAAAA- -AAAAAAAAAAABBBAAAAAAAAAAA- ------------BBB------------ --------------------------- --------------------------- --------------------------- -------------E------------- --------------------------- --------------------------- --------------------------- 
------------BBB------------ -AAAAAAAAAAACCCAAAAAAAAAAA- -AAAAAAAAAAACCCAAAAAAAAAAA- -AAAAAAAAAAACCCAAAAAAAAAAA- -AAAAAAAAAAACCCAAAAAAAAAAA- -AAAAAAAAAAACCCAAAAAAAAAAA- -AAAAAAAAAAACCCAAAAAAAAAAA- -AAAAAAAAAAACCCAAAAAAAAAAA- -AAAAAAAAAAACCCAAAAAAAAAAA- -AAAAAAAAAAACCCAAAAAAAAAAA- -AAAAAAAAAAACCCAAAAAAAAAAA- -AAAAAAAAAAACCCAAAAAAAAAAA- -AAAAAAAAAAACCCAAAAAAAAAAA- -AAAAAAAAAAACCCAAAAAAAAAAA- -AAAAAAAAAAACCCAAAAAAAAAAA- -AAAAAAAAAAACCCAAAAAAAAAAA- -AAAAAAAAAAABBBAAAAAAAAAAA- -AAAAAAAAAAABBBAAAAAAAAAAA- -AAAAAAAAAAABBBAAAAAAAAAAA- -AAAAAAAAAAABBBAAAAAAAAAAA- -AAAAAAAAAAABBBAAAAAAAAAAA- ------------BBB------------ --------------------------- --------------------------- --------------------------- --------------------------- --------------------------- --------------------------- --------------------------- 
------------BBB------------ -AAAAAAAAAAACCCAAAAAAAAAAA- -AAAAAAAAAAACCCAAAAAAAAAAA- -AAAAAAAAAAACCCAAAAAAAAAAA- -AAAAAAAAAAACCCAAAAAAAAAAA- -AAAAAAAAAAACCCAAAAAAAAAAA- -AAAAAAAAAAACCCAAAAAAAAAAA- -AAAAAAAAAAACCCAAAAAAAAAAA- -AAAAAAAAAAACCCAAAAAAAAAAA- -AAAAAAAAAAACCCAAAAAAAAAAA- -AAAAAAAAAAACCCAAAAAAAAAAA- -AAAAAAAAAAACCCAAAAAAAAAAA- -AAAAAAAAAAACCCAAAAAAAAAAA- -AAAAAAAAAAACCCAAAAAAAAAAA- -AAAAAAAAAAACCCAAAAAAAAAAA- -AAAAAAAAAAACCCAAAAAAAAAAA- -AAAAAAAAAAABBBAAAAAAAAAAA- -AAAAAAAAAAABBBAAAAAAAAAAA- -AAAAAAAAAAABBBAAAAAAAAAAA- -AAAAAAAAAAABBBAAAAAAAAAAA- -AAAAAAAAAAABBBAAAAAAAAAAA- ------------BBB------------ --------------------------- --------------------------- --------------------------- --------------------------- --------------------------- --------------------------- --------------------------- 
------------BBB------------ -AAAAAAAAAAACCCAAAAAAAAAAA- -AAAAAAAAAAACCCAAAAAAAAAAA- -AAAAAAAAAAACCCAAAAAAAAAAA- -AAAAAAAAAAACCCAAAAAAAAAAA- -AAAAAAAAAAACCCAAAAAAAAAAA- -AAAAAAAAAAACCCAAAAAAAAAAA- -AAAAAAAAAAACCCAAAAAAAAAAA- -AAAAAAAAAAACCCAAAAAAAAAAA- -AAAAAAAAAAACCCAAAAAAAAAAA- -AAAAAAAAAAACCCAAAAAAAAAAA- -AAAAAAAAAAACCCAAAAAAAAAAA- -AAAAAAAAAAACCCAAAAAAAAAAA- -AAAAAAAAAAACCCAAAAAAAAAAA- -AAAAAAAAAAACCCAAAAAAAAAAA- -AAAAAAAAAAACCCAAAAAAAAAAA- -AAAAAAAAAAABBBAAAAAAAAAAA- -AAAAAAAAAAABBBAAAAAAAAAAA- -AAAAAAAAAAABBBAAAAAAAAAAA- -AAAAAAAAAAABBBAAAAAAAAAAA- -AAAAAAAAAAABBBAAAAAAAAAAA- ------------BBB------------ --------------------------- --------------------------- --------------------------- --------------------------- --------------------------- --------------------------- --------------------------- 
------------BBB------------ -AAAAAAAAAAACCCAAAAAAAAAAA- -AAAAAAAAAAACCCAAAAAAAAAAA- -AAAAAAAAAAACCCAAAAAAAAAAA- -AAAAAAAAAAACCCAAAAAAAAAAA- -AAAAAAAAAAACCCAAAAAAAAAAA- -AAAAAAAAAAACCCAAAAAAAAAAA- -AAAAAAAAAAACCCAAAAAAAAAAA- -AAAAAAAAAAACCCAAAAAAAAAAA- -AAAAAAAAAAACCCAAAAAAAAAAA- -AAAAAAAAAAACCCAAAAAAAAAAA- -AAAAAAAAAAACCCAAAAAAAAAAA- -AAAAAAAAAAACCCAAAAAAAAAAA- -AAAAAAAAAAACCCAAAAAAAAAAA- -AAAAAAAAAAACCCAAAAAAAAAAA- -AAAAAAAAAAACCCAAAAAAAAAAA- -AAAAAAAAAAABBBAAAAAAAAAAA- -AAAAAAAAAAABBBAAAAAAAAAAA- -AAAAAAAAAAABBBAAAAAAAAAAA- -AAAAAAAAAAABBBAAAAAAAAAAA- -AAAAAAAAAAABBBAAAAAAAAAAA- ------------BBB------------ --------------------------- --------------------------- --------------------------- --------------------------- --------------------------- --------------------------- --------------------------- 
------------BBB------------ -AAAAAAAAAAACCCAAAAAAAAAAA- -AAAAAAAAAAACCCAAAAAAAAAAA- -AAAAAAAAAAACCCAAAAAAAAAAA- -AAAAAAAAAAACCCAAAAAAAAAAA- -AAAAAAAAAAACCCAAAAAAAAAAA- -AAAAAAAAAAACCCAAAAAAAAAAA- -AAAAAAAAAAACCCAAAAAAAAAAA- -AAAAAAAAAAACCCAAAAAAAAAAA- -AAAAAAAAAAACCCAAAAAAAAAAA- -AAAAAAAAAAACCCAAAAAAAAAAA- -AAAAAAAAAAACCCAAAAAAAAAAA- -AAAAAAAAAAACCCAAAAAAAAAAA- -AAAAAAAAAAACCCAAAAAAAAAAA- -AAAAAAAAAAACCCAAAAAAAAAAA- -AAAAAAAAAAACCCAAAAAAAAAAA- -AAAAAAAAAAABBBAAAAAAAAAAA- -AAAAAAAAAAABBBAAAAAAAAAAA- -AAAAAAAAAAABBBAAAAAAAAAAA- -AAAAAAAAAAABBBAAAAAAAAAAA- -AAAAAAAAAAABBBAAAAAAAAAAA- ------------BBB------------ --------------------------- --------------------------- --------------------------- --------------------------- --------------------------- --------------------------- --------------------------- 
------------BBB------------ -AAAAAAAAAAACCCAAAAAAAAAAA- -AAAAAAAAAAACCCAAAAAAAAAAA- -AAAAAAAAAAACCCAAAAAAAAAAA- -AAAAAAAAAAACCCAAAAAAAAAAA- -AAAAAAAAAAACCCAAAAAAAAAAA- -AAAAAAAAAAACCCAAAAAAAAAAA- -AAAAAAAAAAACCCAAAAAAAAAAA- -AAAAAAAAAAACCCAAAAAAAAAAA- -AAAAAAAAAAACCCAAAAAAAAAAA- -AAAAAAAAAAACCCAAAAAAAAAAA- -AAAAAAAAAAACCCAAAAAAAAAAA- -AAAAAAAAAAACCCAAAAAAAAAAA- -AAAAAAAAAAACCCAAAAAAAAAAA- -AAAAAAAAAAACCCAAAAAAAAAAA- -AAAAAAAAAAACCCAAAAAAAAAAA- -AAAAAAAAAAABBBAAAAAAAAAAA- -AAAAAAAAAAABBBAAAAAAAAAAA- -AAAAAAAAAAABBBAAAAAAAAAAA- -AAAAAAAAAAABBBAAAAAAAAAAA- -AAAAAAAAAAABBBAAAAAAAAAAA- ------------BBB------------ --------------------------- --------------------------- --------------------------- --------------------------- --------------------------- --------------------------- --------------------------- 
------------BBB------------ -AAAAAAAAAAACCCAAAAAAAAAAA- -AAAAAAAAAAACCCAAAAAAAAAAA- -AAAAAAAAAAACCCAAAAAAAAAAA- -AAAAAAAAAAACCCAAAAAAAAAAA- -AAAAAAAAAAACCCAAAAAAAAAAA- -AAAAAAAAAAACCCAAAAAAAAAAA- -AAAAAAAAAAACCCAAAAAAAAAAA- -AAAAAAAAAAACCCAAAAAAAAAAA- -AAAAAAAAAAACCCAAAAAAAAAAA- -AAAAAAAAAAACCCAAAAAAAAAAA- -AAAAAAAAAAACCCAAAAAAAAAAA- -AAAAAAAAAAACCCAAAAAAAAAAA- -AAAAAAAAAAACCCAAAAAAAAAAA- -AAAAAAAAAAACCCAAAAAAAAAAA- -AAAAAAAAAAACCCAAAAAAAAAAA- -AAAAAAAAAAABBBAAAAAAAAAAA- -AAAAAAAAAAABBBAAAAAAAAAAA- -AAAAAAAAAAABBBAAAAAAAAAAA- -AAAAAAAAAAABBBAAAAAAAAAAA- -AAAAAAAAAAABBBAAAAAAAAAAA- ------------BBB------------ --------------------------- --------------------------- --------------------------- --------------------------- --------------------------- --------------------------- --------------------------- 
------------BBB------------ -AAAAAAAAAAACCCAAAAAAAAAAA- -AAAAAAAAAAACCCAAAAAAAAAAA- -AAAAAAAAAAACCCAAAAAAAAAAA- -AAAAAAAAAAACCCAAAAAAAAAAA- -AAAAAAAAAAACCCAAAAAAAAAAA- -AAAAAAAAAAACCCAAAAAAAAAAA- -AAAAAAAAAAACCCAAAAAAAAAAA- -AAAAAAAAAAACCCAAAAAAAAAAA- -AAAAAAAAAAACCCAAAAAAAAAAA- -AAAAAAAAAAACCCAAAAAAAAAAA- -AAAAAAAAAAACCCAAAAAAAAAAA- -AAAAAAAAAAACCCAAAAAAAAAAA- -AAAAAAAAAAACCCAAAAAAAAAAA- -AAAAAAAAAAACCCAAAAAAAAAAA- -AAAAAAAAAAACCCAAAAAAAAAAA- -AAAAAAAAAAABBBAAAAAAAAAAA- -AAAAAAAAAAABBBAAAAAAAAAAA- -AAAAAAAAAAABBBAAAAAAAAAAA- -AAAAAAAAAAABBBAAAAAAAAAAA- -AAAAAAAAAAABBBAAAAAAAAAAA- ------------BBB------------ --------------------------- --------------------------- --------------------------- --------------------------- --------------------------- --------------------------- --------------------------- 
------------BBB------------ -AAAAAAAAAAACCCAAAAAAAAAAA- -AAAAAAAAAAACCCAAAAAAAAAAA- -AAAAAAAAAAACCCAAAAAAAAAAA- -AAAAAAAAAAACCCAAAAAAAAAAA- -AAAAAAAAAAACCCAAAAAAAAAAA- -AAAAAAAAAAACCCAAAAAAAAAAA- -AAAAAAAAAAACCCAAAAAAAAAAA- -AAAAAAAAAAACCCAAAAAAAAAAA- -AAAAAAAAAAACCCAAAAAAAAAAA- -AAAAAAAAAAACCCAAAAAAAAAAA- -AAAAAAAAAAACCCAAAAAAAAAAA- -AAAAAAAAAAACCCAAAAAAAAAAA- -AAAAAAAAAAACCCAAAAAAAAAAA- -AAAAAAAAAAACCCAAAAAAAAAAA- -AAAAAAAAAAACCCAAAAAAAAAAA- -AAAAAAAAAAABBBAAAAAAAAAAA- -AAAAAAAAAAABBBAAAAAAAAAAA- -AAAAAAAAAAABBBAAAAAAAAAAA- -AAAAAAAAAAABBBAAAAAAAAAAA- -AAAAAAAAAAABBBAAAAAAAAAAA- ------------BBB------------ --------------------------- --------------------------- --------------------------- --------------------------- --------------------------- --------------------------- --------------------------- 
------------BBB------------ ------------BBB------------ ------------BBB------------ ------------BBB------------ ------------BBB------------ ------------BBB------------ ------------BBB------------ ------------BBB------------ ------------BBB------------ ------------BBB------------ ------------BBB------------ ------------BBB------------ ------------BBB------------ ------------BBB------------ ------------BBB------------ ------------BBB------------ ------------BBB------------ ------------BBB------------ ------------BBB------------ ------------BBB------------ ------------BBB------------ ------------BBB------------ --------------------------- --------------------------- --------------------------- --------------------------- --------------------------- --------------------------- --------------------------- 
