model
size = 17 14 32, scale = 0.05, origin = -y
material 
  colors = A:#636 B:#EEE C:#639 D:#001 E:#669 F:#800 G:#9FF H:#CF0 I:#E00 J:#777
voxels
68-16D3-13D189-34A2H13A4H13A2H-15A2-15A137-68A-15A2-15A137-14A3-85A170-53A13B2A-A13-A86-4D2(9-8D)9-4D34-36A13B2A-A13BA2-A13-A52-4D9-4D4C2(9-8C)9-4C4D9-4D17-36A13B2A-A13BA2-A13-A52-4D9-4D4C9-4CF3G9FG-GF4C9-4C4D9-4D17-36A13B2ABA13BAB-A13BA2-A13-A35-4D9-4D4C2(9-8C)9-4C4D9-4D17-36A13B2ABA13BAB-A13BA2-A13-A52-4D2(9-8D)9-4D34-36A13B2ABA13BAB-A13BA2-A13-A120-53A13B2ABA13BA2BA13BAB-A13BA2-A13-A70-15A-85AB15A2B15AB-15A2-15A69-102AB15A2B15AJB15AB-15A2-15A52-102AB2(15A2B)15AB-15A2-15A52-153A-15A2-15A52-102AB2(15A2B)15AB-15A2-15A52-102AB15A2B15AB-15A86-102AB15AB-2A11B2A2-A13BA86-119A-A13BA103-119A-A13BA120-87A13B2A85-4D2(9-8D)9-4D17-18A15C2(2A15-)2A-13B-A68-4D9-4D4C2(9-8C)9-4C4D9-4D17-A15C3(2A15-)A68-4D9-4D4C9-4CF3G9FG2-F4C9-4C4D9-4D17-A15C3(2A15-)A68-4D9-4D4C2(9-8C)9-4C4D9-4D17-A15C2(2A15-)2A-13E-A85-4D2(9-8D)9-4D17-18A15C2(2A15-)A2-13E-A136-35A15C2(2A15-)2(A2-13E121-52A15C2A15-A16-)A2-13E121-52A15CA16-A19-13E121-52A2(15EA-)15E2-15E137-I15DI17D136-
