model
size = 18 17 7, scale = 0.05, origin = -y
material 
  colors = A:#630 B:#111
voxels
------------------ ------------------ ------------------ ------------------ ------------------ ------------------ ------------------ ------------------ ------------------ ------------------ ------------------ ------------------ ------------------ ---------------A-- ------------------ ------------------ ------------------ 
------------------ ------------------ ------------------ ------------------ ------------------ ------------------ ------------------ ------------------ ------------------ ------------------ ------------------ ------------------ ---------------A-- ------------------ ------------------ ------------------ ------------------ 
--B------------B-- --B------------B-- --B------------B-- ---B----------B--- ----B--------B---- -----B------B----- -----ABBBBBBA----- -----AA----AA----- ----A--------A---- ----A--------A---- ---A----------A--- --A------------A-- ---A-------------- ----------------A- -----------------A ------------------ ------------------ 
--B------------B-- --B------------B-- --B------------B-- ---B----------B--- ----B--------B---- -----B------B----- -----ABBBBBBA----- -----AA----AA----- ----A--------A---- ----A--------A---- ---A--------A-A--- --A--------A---A-- ----------------A- ------------------ ------------------ -A---------------- ------------------ 
------------------ ------------------ ------------------ ------------------ ------------------ ------------------ ------------------ ------------------ ------------------ ------------------ ------------------ ------------------ --A-------------A- ------------------ ------------------ -A---------------- ------------------ 
------------------ ------------------ ------------------ ------------------ ------------------ ------------------ ------------------ ------------------ ------------------ ------------------ ------------------ ------------------ ------------------ --A-------------A- -A---------------- A----------------- A----------------- 
------------------ ------------------ ------------------ ------------------ ------------------ ------------------ ------------------ ------------------ ------------------ ------------------ ------------------ ------------------ ----------------A- ------------------ ------------------ ------------------ ------------------ 
