model
size = 19 19 20, scale = 0.05, origin = -y
material 
  colors = A:#222 B:#555 C:#444 D:#F9C E:#888 F:#F30 G:#F9F
voxels
------------------- ------------------- ------------------- ------------------- ------------------- ------------------- ------------------- ---------C--------- -----BBBBBBBBB----- ----B---------B---- -----BBBBBBBBB----- --------BBB-------- ------------------- ------------------- ------------------- ------------------- ------------------- ------------------- ------------------- 
------------------- ------------------- ------------------- -------AAAAA------- ------A--A--A------ ------AA-A-AA------ ------AAAAAAA------ -----AAA-A-AAA----- -----B--B-B--B----- ----BFFFFFFFFFB---- -----B-------B----- -----AAA---AAA----- -------AAAAA------- ---------C--------- ------------------- ------------------- ------------------- ------------------- ------------------- 
------------------- ------------------- ---------B--------- -------AA-AA------- ------AFF-FFA------ ------A-F-F-A------ -----B-------B----- -----A--C-C--A----- ----A---------A---- ---B-----------B--- ----A---------A---- -----AA-----AA----- -------A---A------- --------C-C-------- ---------E--------- ------------------- ------------------- ------------------- ------------------- 
------------------- ---------B--------- --------A-A-------- ------AA---AA------ ------A-----A------ -----A-------A----- ----B---------B---- ----B---------B---- ---B-----------B--- --E-------------E-- ---B-----------B--- ---BAC-------CAB--- ------C-----C------ -------EEEEE------- ------------------- ---------E--------- ------------------- ------------------- ------------------- 
---------B--------- ---------A--------- -------AA-AA------- ------A-----A------ -------F---F------- ----BAB-----AAB---- ---B-----------B--- ---B-----------B--- --A-------------A-- --A-------------A-- --A-------------A-- --AA-----------AA-- ----EC-D-D---CE---- ------E-D-DDE------ --------D---------- ------------------- ---------E--------- ------------------- ------------------- 
---------B--------- --------A-A-------- -------B---B------- ------A-----A------ -------F---F------- ----BAB-----AAB---- ---B-----------B--- --A-------------A-- --A-------------A-- ---C-----------C--- --A-------------A-- -AC-------------CA- ---CC-D-----D-CC--- -----E-DDDDD-E----- -----E----DD-E----- -----E--DD---E----- ---------E--------- ------------------- ------------------- 
------------------- -------BBCBB------- ------B-----B------ ------A-----A------ -------F---F------- ----BAB-----AAB---- ---B-----------B--- --A-------------A-- --A-------------A-- ---C-----------C--- --A-------------A-- AA---------------AA --CC-D----D-D--CC-- ----E-G-DD-G-DE---- -------GD---------- --------D---------- ------E-----E------ ---------E--------- ------------------- 
------------------- ------------------- -------BCCCB------- ------A-----A------ -------F---F------- ----BAB-----AAB---- ---B-----------B--- --A-------------A-- --A-------------A-- ---C-----------C--- --A-------------A-- AA---------------AA --CC--D-DD-G-D-CC-- ----ED-D--D-D-E---- -------D--D-D------ -------G-D--------- ------------------- -------E-E-E------- ------------------- 
------------------- ---------A--------- -------BC-CB------- ------A-----A------ ------A-----A------ ----BA-------AB---- ---B-----------B--- --A-------------A-- --A-------------A-- ---C-----------C--- --A-------------A-- AA---------------AA -AC--D-G-D--D---CA- ---CE-D-D-DG-DEC--- -------DDD-D------- --------GG--------- ---------D--------- --------E-E-------- ---------E--------- 
------------------- -------CC-CC------- -----AC-----CA----- -----A-------A----- -----A-------A----- ----B---------B---- ---B-----------B--- --A-------------A-- --A-------------A-- ---C-----------C--- --A-------------A-- AA---------------AA -AC----D-D-D-D--CA- ---CEDD-G-G-D-EC--- ------D-G---D------ --------G-D-------- ------------------- ------------------- ---------E--------- 
------------------- ------CC---CC------ -----AC-----CA----- -----A-------A----- -----A-------A----- ----B---------B---- ---B-----------B--- --A-------------A-- --A-------------A-- ---C-----------C--- --A-------------A-- AA---------------AA -AC-----D---G---CA- ---C-D-D-D-D-D-C--- ----E-D---D---E---- ----E--DDDD---E---- -----E--D-D--E----- ------EE---EE------ --------EEE-------- 
------------------- ------------------- ------C-----C------ ------C-----C------ -----A-------A----- ----B---------B---- ---B-----------B--- --A-------------A-- --A-------------A-- ---C-----------C--- --A-------------A-- AA---------------AA -AC--D----------CA- ---CE-G-GG-DDDEC--- -------D--D-D------ --------DGDD------- ------------------- ------------------- ---------E--------- 
------------------- -------C---C------- ------C-----C------ ------C-----C------ -----A-------A----- ----B---------B---- ---B-----------B--- --A-------------A-- --A-------------A-- ---C-----------C--- --A-------------A-- AA---------------AA --C--D-----GD---C-- ---CE-D---D--DEC--- ------DDDD--------- -------D--D-------- ---------D--------- --------E-E-------- ---------E--------- 
------------------- --------C-C-------- -------CC-CC------- -------C---C------- -----AC-----CA----- ----B---------B---- ---B-----------B--- --A-------------A-- --A-------------A-- ---C-----------C--- --A-------------A-- -A---------------A- --CC--D---G--D-CC-- ----ED-DGG-DD-E---- ---------G-D------- --------DG--------- ------------------- -------E-E-E------- ------------------- 
------------------- ---------C--------- ---------C--------- --------C-C-------- -----ACC---CCA----- ----B---------B---- ----B---------B---- ---B-----------B--- --A-------------A-- --A-------------A-- --A-------------A-- --A-------------A-- ---C-DDDD-DGD--C--- ----E----D---DE---- ---------D--------- ------------------- ------E-----E------ ---------E--------- ------------------- 
------------------- ------------------- ---------C--------- --------C-C-------- ------CC---CC------ ----BC-------CB---- ----B---------B---- ---B-----------B--- ---B-----------B--- ---B-----------B--- ---B-----------B--- ---B-----------B--- ----C-DD------C---- -----E--D-DDDE----- -----E---D---E----- -----E-------E----- ---------E--------- ------------------- ------------------- 
------------------- ------------------- ------------------- ---------C--------- -------CC-CC------- -----BC-----CB----- -----B-------B----- ----B---------B---- ----B---------B---- ----B---------B---- ----B---------B---- ----B---------B---- ----EC-D---D-C----- ------E-DDD-E------ ------------------- ------------------- ---------E--------- ------------------- ------------------- 
------------------- ------------------- ------------------- ------------------- ---------C--------- ------BBC-CBB------ ------B-----B------ -----B-------B----- -----B-------B----- -----B-------B----- -----B-------B----- -----B-------B----- ------C-----C------ -------EEEEE------- ------------------- ---------E--------- ------------------- ------------------- ------------------- 
------------------- ------------------- ------------------- ------------------- ------------------- ------C-AAA-C------ -------A---A------- ------A-F-F-A------ ------A-F-F-A------ ------A-F-F-A------ ------A-F-F-A------ ------A-----A------ -------CC-CC------- ---------E--------- ---------E--------- ------------------- ------------------- ------------------- ------------------- 
------------------- ------------------- ------------------- ------------------- ------------------- --------AAA-------- -------AAAAA------- -------A-A-A------- -------A-A-A------- -------A-A-A------- -------A-A-A------- -------AAAAA------- ---------E--------- ------------------- ------------------- ------------------- ------------------- ------------------- ------------------- 
