model
size = 28 31 23, scale = 0.05, origin = -y
material 
  colors = A:#FAF1F1 B:#F2C511 C:#BBB4B4 D:#B6971F E:#EDFA06 F:#000
voxels
---------------------------- ---------------------------- ---------------------------- ---------------------------- ---------------------------- ---------------------------- ---------------------------- ---------------------------- ---------------------------- ---------------------------- ---------------------------- ---------------------------- ---------------------------- ---------------------------- ---------------------------- ---------------------------- ---------------------------- ---------------------------- ---------------------------- ---------------------------- ----------C----------------- ----------AC---------------- ----------AA---------------- -----------AA--------------- ---------------------------- --------------AA------------ ---------------------------- ---------------------------- ---------------------------- ---------------------------- ---------------------------- 
-------CCCCCCCCC------------ -------BBBBBBBBB------------ ---------AA-A--------------- --------AA--A--------------- --------AAAAA--------------- ---------AAA---------------- ---------------------------- ---------------------------- ---------------------------- ---------------------------- ---------------------------- ---------------------------- ---------------------------- ---------------------------- ---------------------------- ---------------------------- ---------------------------- ---------------------------- ---------------------------- --------------A------------- ----------CC--A------------- ---------AAAAA-------------- ---------AAAAA-------------- ----------AAA--------------- ----------AA---------------- -------CCCCCCCBBA----------- --------AAAAAAAA------------ ---------------------------- ---------------------------- ---------------------------- ---------------------------- 
------CCCCCCCCCCC----------- ------CBBBBBBBBBC----------- --------BBBBB-B------------- --------BBBBBBB------------- --------BBBEBBB------------- --------BBBBBBB------------- --------BBBBBBB------------- --------BEBBBBB------------- --------BBBBBBB------------- --------BBBBBEB------------- --------BBBBBBB------------- --------EEEBBBB------------- --------EBEBBBB------------- --------EEEBBBB------------- --------BBBEBBB------------- --------BBBBBBB------------- --------BBBBBBB------------- --------BBBBEEE------------- --------BBAAEBE------------- --------BAACAAEAA----------- --------CCAAAAAA------------ ------AAAAAAAAAAA----------- ------CAAAAAAAAA------------ -------AAAAAAAA-A----------- ------A-AAAAAAA------------- ------CBBAAAAABBC----------- -------AAAAAAA-AA----------- ---------------------------- ---------------------------- ---------------------------- ---------------------------- 
-----CCCCCCCCCCCCC---------- -----BBBBBBBBBBBBB---------- -------DBBBBBBBDD----------- -------DBBBBBBEEE----------- -------DBBBBBBEDE----------- -------DBBBBBBEEE----------- -------DBBBBBBBDD----------- -------DBBBBBBBDD----------- -------DBBBBBBBDD----------- -------DBBBBBBBDD----------- -------DBBBBBBBDD----------- -------DEBEBBBBDD----------- -------DBBBBBBBDD----------- -------DEBEBBBBDD----------- -------DBBBBBBBDD----------- -------DBBBBBBBDD----------- -------DBBBBBBBDD----------- -------DBAAAAAEDD----------- -------DAAAAAAADD----------- -------AAAAAAAAADA---------- ------AAAAAAAAAAA----------- -----AAAAAAAAAAADA---------- -----AAAAAAAAAAAA----------- ------CAAAAAAAAADA---------- ------AAAAAAAAAA------------ -----CBAAAAAAAAABCA--------- ------AAAAAAAAA-AA---------- --------------A------------- ---------------------------- ---------------------------- ---------------------------- 
----CCCCCCCCCCCCCCC--------- ----BBBBBBBBBBBBBBB--------- ------BBBBBBBBBBB----------- ------BBBBBBBBEBE----------- ------BBBBBBBBBBB----------- ------EEBBBBBBEBE----------- ------BEBBBBBBBBB----------- ------EEBBBBBBBBB----------- ------BBBBBBBBBBB----------- ------BBBBBBBBBBB----------- ------BBBBBBBBBBB----------- ------BBEEEBBBBBB----------- ------BBEBEBBBBBB----------- ------BBEEEBBBBBB----------- ------BBBBBBBBBBB----------- ------BBBBBBBBBBB----------- ------BBBBBBBBBBB----------- ------BAAAAAAAAAB----------- ------AAAAAAAAAAB----------- ------AAAAAAAAAAB----------- ------AAAAAAAAAABA---------- -----AAAAAAAAAAAAA---------- -----AAAAAAAAAAAAA---------- ------AAAAAAAAAAAA---------- ------AAAAAAAAAAB----------- ----CBAAAAAAAAAABBC--------- -----AAAAAAAAAAA-AA--------- ----------AAA--------------- ---------------------------- ---------------------------- ---------------------------- 
---CCCCCCCCCCCCCCCCC-------- ---BBBBBBBBBBBBBBBBB-------- -----DBBBBBBBBBBBB---------- -----DBBBBBBBBEEEB---------- -----DBBBBBBBBEBEB---------- -----EBEBBBBBBEEEB---------- -----DBBBBBBBBBBBB---------- -----EBEBBBBBBBBBB---------- -----DBBBBBBBBBBBB---------- -----DBBBBBBBBBBBB---------- -----DBBBBBBBBBBEE---------- -----DBBBBBBBBBBEB---------- -----DBBBBBBBBBBEE---------- -----DBBBBBBBBBBBB---------- -----DBBBBBBBBBBBB---------- -----DBBBBBBBBBBBB---------- -----DBBBBBBBBBBBB---------- -----DAAAAAAAAAABB---------- -----DAAAAAAAAAABB---------- -----DAAAAAAAAAAAB---------- -----DAAAAAAAAAAAA---------- -----EAAAAAAAAAAAA---------- ---CADAAAAAAAAAAAA---------- -----EAAAAAAAAAAAA---------- -----DAAAAAAAAAAAA---------- ---CBBAAAAAAAAAAABBC-------- ----AAAAAAAAAAAA--A--------- --------AAAAACA-A----------- ---------AACCC-------------- ---------------------------- ---------------------------- 
--CCCCFFFCCCCCCCCCCCC------- --BBBBBBBBBBBBBBBBBBC------- ----BBBBBBBBBBBBBBD--------- ----BBBBBBBBBBBBBBD--------- ----BBBBBBBBBBBBBBD--------- ----BEEEBBBBBBBBBBD--------- ----BEBEBBBBBBBBBBD--------- ----BEEEBBBBBBBBBBD--------- ----BBBBBBBBBBBBBBD--------- ----BBBBBBBBBBBBBBD--------- ----BBBBBBBBBBBBEBE--------- ----BBBBBBBBBBBBBBD--------- ----BBBBBBBBBBBBEBE--------- ----BBBBBBBBBBBBBBD--------- ----BBBBBAAAAABBBBD--------- ----BBBAAAAAAAAABBD--------- ----BBAAAAAAAAAABBD--------- ----BAAAAAAAAAAAAAD--------- ----AAAAAAAAAAAAAAA--------- ----AAAAAAAAAAAAAAA--------- ---CAAAAAAAAAAAAAAA--------- ---CAAAAAAAAAAAAAAA--------- ---CAAAAAAAAAAAAAAA--------- ---AAAAAAAAAAAAAAAE--------- ---AAAAAAAAAAAAAAAA--------- --ABAAAAAAAAAAAAAAABC------- ----AAAAAAAAAAAAAAAA-------- ------AAAAAAAAACAA---------- ------AAAAAAAAAAA----------- -------AAAAAAAAA------------ ---------------------------- 
--CCCFCFCCCCCCCCCCCCC------- --BBBBBBBBBBBBBBBBBBB------- --ADBBBBBBBBBBBBBBBB-------- --ADBBBBBBBBBBBBBBBB-------- ---DBBBBBBBBBBBBBBBB-------- ---DBBBBBBBBBBBBBBBB-------- ---DBBBBBBBBBBBBBBBB-------- ---DBBBBBBBBBBBBBBBB-------- ---DBBBBBBBBBBBBBBBB-------- ---DBBBBBBBBBBBBBBBB-------- ---DBBBBBBBBBBBBEEEB-------- ---DBBBBBBBBBBBBEBEB-------- ---DBBBBBBBBBBBBEEEB-------- ---DBBBBBBAABBBBBBBB-------- ---DBBBBAAAAAAABBBBB-------- --ADBBAAAAAAAAAABBBB-------- --ADBBAAAAAAAAAABBBB-------- --ADAAAAAAAAAAAAAAAB-------- ---DAAAAAAAAAAAAAAAB-------- --ACAAAAAAAAAAAAAAAB-------- --AAAAAAAAAAAAAAAAAB-------- --AAAAAAAAAAAAAAAAAB-------- --AAAAAAAAAAAAAAAAAB-------- ---AAAAAAAAAAAAAAAAB-------- ---AAAAAAAAAAAAAAAAB-------- --AAAAAAAAAAAAAAAAABC------- ----AAAAAAAAAAAAAAAA-------- ------AAAAAAAAAAAA---------- ------AAAAAAAAAAA----------- ------AAAAAAAAAA------------ ------A-------A------------- 
--CCCCFFFCCCCCCCCCCCCC------ --BBBBBBBBBBBBBBBBBBBC------ --AEBBBBBBBBBBBBBBBB-------- --ABBBBBBBBBBBBBBBBBC------- ---BBBBBBBBBBBBBBBBBC----C-- ---BBBBBBBBBBBBBBBBBC----C-- ---BBBBBBBBBBBBBBBBBC------- ---BBBBBBBBBBBBBBBBBC------- ---BBBBBBBBBBBBBBBBBC------- ---BBBBBBBBBBBBBBBBBC------- ---EBBBBBBBBBBBBBBBBC----CC- ---BBBBBBBBBBBBBBBBBC----CC- ---BBBBBBBBBBBBBBBBBC----CC- ---BBBBBBAAAAABBBBBBC-----C- ---BBBBAAAAAAAAABBBBC-----C- ---BBBAAAAAAAAAABBBBC-----C- -AABBBAAAAAAAAAAABBBC-----C- --ABAAAAAAAAAAAAAAABC-----C- ---AAAAAAAAAAAAAAAABC-----C- --AAAAAAAAAAAAAAAAABC-----C- --AAAAAAAAAAAAAAAAABC-----C- --AAAAAAAAAAAAAAAAABCC----C- --AAAAAAAAAAAAAAAAABCCCCCC-- --AAAAAAAAAAAAAAAAAB-CCCCC-- --AAAAAAAAAAAAAAAAAB-------- --AAAAAAAAAAAAAAAAABC------- ---AAAAAAAAAAAAAAAAA-------- -----AAAAAAAAAAAAAAA-------- ------AAAAAAAAAAAEAA-------- ------AAAAAAAAAAAA---------- ------A--------------------- 
--CCCCCCCCCCCCCCCCCCCC------ --BBBBBBBBBBBBBBBBBBBC------ ---BBBBBBBBBBBBBBBBBC------- --ABBBBBBBBBBBBBBBBBCCCCCC-- --ABBBBBBBBBBBBBBBBBBC---CC- ---BBBBBBBBBBBBBBBBBC----C-- ---BBBBBBBBBBBBBBBBBC---CC-- ---BBBBBBBBBBBBBBBBBC---CC-- ---BBBBBBBBBBBBBBBBBC---CC-- ---BBBBBBBBBBBBBBBBBC---CC-- ---BBBBBBBBBBBBBBBBBC----CC- ---BBBBBBBBBBBBBBBBBC----CC- ---BBBBBBBAABBBBBBBBC----CBC --ABBBBBAAAAAAABBBBBC-----BC --ABBBAAAAAAAAAABBBBC-----BC -AABBBAAAAAAAAAABBBBC-----BC --ABBBAAAAAAAAAAAABBC-----BC -AAAAAAAAAAAAAAAAAABC-----BC --AAAAAAAAAAAAAAAAABC-----BC --AAAAAAAAAAAAAAAAABC-----BC --AAAAAAAAAAAAAAAAABC-----BC -AAAAAAAAAAAAAAAAAABBC----C- -AAAAAAAAAAAAAAAAAABBBCCCCC- --AAAAAAAAAAAAAAAAABCCCCCC-- --AAAAAAAAAAAAAAAAAB-------- --AAAAAAAAAAAAAAAAABC------- ---AAAAAAAAAAAAAAAA--------- -----AAAAAAAAAAAAAA--------- -----AAAAAAAAAAAAAAA-------- ------AAAAAAAACAAA---------- -------A---A-----A---------- 
--CCCFCFFCCCCCCCCCCCCCC----- --BBBBBBBBBBBBBBBBBBBCC----- --ABBBBBBBBBBBBBBBBBC------- --ABBBBBBBBBBBBBBBBBCCCCCC-- ---BBBBBBBBBBBBBBBBBBC---CC- ---EBBBBBBBBBBBBBBBBC----C-- ---BBBBBBBBBBBBBBBBBC---CC-- ---BBBBBBBBBBBBBBBBBC---CC-- ---BBBBBBBBBBBBBBBBBC---CC-- ---BBBBBBBBBBBBBBBBBC---CC-- ---BBBBBBBBBBBBBBBBBC----CC- ---BBBBBBBBBBBBBBBBBC----CC- --ABBBBBBAAAAABBBBBBC----CBC --ABBBBAAAAAAAAABBBBC-----BC --ABBBAAAAAAAAAABBBBC-----BC --ABBBAAAAAAAAAAABBBC-----BC --ABBBAAAAAAAAAAAABBC-----BC --AAAAAAAAAAAAAAAAABC-----BC -AAAAAAAAAAAAAAAAAABC-----BC --AAAAAAAAAAAAAAAAABC-----BC AAAAAAAAAAAAAAAAAAABC-----BC AAAAAAAAAAAAAAAAAAABBC----C- -AAAAAAAAAAAAAAAAAABBBCCCCC- -AAAAAAAAAAAAAAAAAABCCCCCC-- -AAAAAAAAAAAAAAAAAAB-------- --AAAAAAAAAAAAAAAAABC------- --AAAAAAAAAAAAAAAAAA-------- ----AAAAAAAAAAAAAAAA-------- -----AAAAAAAAAAAAAA--------- ------AAAAAAAAAAAA---------- ---------------------------- 
--CCCCCCCCCCCCCCCCCCCC------ --BBBBBBBBBBBBBBBBBBBC------ --ABBBBBBBBBBBBBBBBB-------- --ABBBBBBBBBBBBBBBBBC------- ---BBBBBBBBBBBBBBBBBC----C-- ---BBBBBBBBBBBBBBBBBC----C-- ---BBBBBBBBBBBBBBBBBC------- ---BBBBBBBBBBBBBBBBBC------- ---BBBBBBBBBBBBBBBBBC------- ---BBBBBBBBBBBBBBBBBC------- --ABBBBBBBBBBBBBBBBBC----CC- --ABBBBBBBBBBBBBBBBBC----CC- --ABBBBBBAAAAABBBBBBC----CC- --ABBBBAAAAAAAAABBBBC-----C- ---BBBAAAAAAAAAABBBBC-----C- --ABBBAAAAAAAAAAABBBC-----C- ---BBBAAAAAAAAAAAABBC-----C- --AAAAAAAAAAAAAAAAABC-----C- --AAAAAAAAAAAAAAAAABC-----C- --AAAAAAAAAAAAAAAAABCA----C- -AAAAAAAAAAAAAAAAAABE-----C- AEAAAAAAAAAAAAAAAAABCC----C- AEEAAAAAAAAAAAAAAAABCCCCCC-- -AEAAAAAAAAAAAAAAAAB--CCCC-- -CEAAAAAAAAAAAAAAAABA------- --AAAAAAAAAAAAAAAAABC------- --AAAAAAAAAAAAAAAAA--------- ----AAAAAAAAAAAAAAA--------- -----AAAAAAAAAAAAAA--------- ------AAAAAAAAAAAA---------- ----------A----------------- 
--CCCCFCCCCCCCCCCCCCC------- --BBBBBBBBBBBBBBBBBBB------- ---DBBBBBBBBBBBBBBBB-------- ---DBBBBBBBBBBBBBBBB-------- ---DBBBBBBBBBBBBEEEB-------- ---DBBBBBBBBBBBBEBEB-------- ---DBBBBBBBBBBBBEEEB-------- ---DBBBBBBBBBBBBBBBB-------- ---DBBBBBBBBBBBBBBBB-------- --ADBBBBBBBBBBBBBBBB-------- ---DBBBBBBBBBBBBBBBB-------- ---CBBBBBBBBBBBBBBBB-------- ---CBBBBBBAAABBBBBBB-------- --ADBBBBAAAAAAABBBBB-------- --ADBBAAAAAAAAAABBBB-------- --ADBBAAAAAAAAAAABBB-------- --ADBBAAAAAAAAAAAABB-------- ---AAAAAAAAAAAAAAAAB-------- ---AAAAAAAAAAAAAAAABA------- --AAAAAAAAAAAAAAAAABA------- --AAAAAAAAAAAAAAAAABA------- -AEAAAAAAAAAAAAAAAABA------- -AEAAAAAAAAAAAAAAAAB-------- -AEAAAAAAAAAAAAAAAABA------- --AAAAAAAAAAAAAAAAAB-------- --AAAAAAAAAAAAAAAAABC------- ---AAAAAAAAAAAAAAAAA-------- ----AAAAAAAAAAAAAAA--------- -----AAAAAAAAAAAAA---------- ------AAAAEAAAAAA----------- ----------AA---------------- 
--CCCFCFCCCCCCCCCCCCC------- --BBBBBBBBBBBBBBBBBBB------- ----BBBBBBBBBBBBBBD--------- ----EBBBBBBBBBBBBBD--------- ----BBBBBBBBBBBBEBE--------- ----BBBBBBBBBBBBBBD--------- ----BBBBBBBBBBBBEBE--------- ----EBBBBBBBBBBBBBD--------- ---ABBBBBBBBBBBBBBD--------- ---ABBBBBBBBBBBBBBD--------- ---ABBBBBBBBBBBBBBD--------- ---ABEEEBBBBBBBBBBD--------- ---ABEBEBBAABBBBBBD--------- ---ABEEEAAAAAAABBBD--------- ---ABBAAAAAAAAAABBD--------- ----BBAAAAAAAAAABBD--------- ---ABBAAAAAAAAAAAAD--------- ---AAAAAAAAAAAAAAAA--------- ---AAAAAAAAAAAAAAAAA-------- --AAAAAAAAAAAAAAAAAA-------- --AAAAAAAAAAAAAAAAAAA------- -AEAAAAAAAAAAAAAAAAAA------- -AEAAAAAAAAAAAAAAAAAA------- --AAAAAAAAAAAAAAAAAA-------- --AAAAAAAAAAAAAAAAAA-------- --AAAAAAAAAAAAAAAAABC------- ---AAAAAAAAAAAAAAAA--------- -----AAAAAAAAAAAAA---------- -----AAAAAAAAAAAAA---------- ------AAEAAEAAAA------------ --------A--A---------------- 
---CCFFFFCCCCCCCCCCC-------- ---BBBBBBBBBBBBBBBBB-------- -----DBBBBBBBBBBBB---------- -----DBBBBBBBBBBBB---------- -----DBBBBBBBBBBEE---------- -----DBBBBBBBBBBEB---------- -----DBBBBBBBBBBEE---------- -----DBBBBBBBBBBBB---------- -----DBBBBBBBBBBBB---------- -----DBBBBBBBBBBBB---------- -----DBBBBBBBBBBBB---------- ----AEBEBBBBBBBBBB---------- -----EBBBBBBBBBBBB---------- -----EBEBAAAAABBBB---------- -----DBAAAAAAAAABB---------- -----DAAAAAAAAAABB---------- ----ADAAAAAAAAAAABA--------- ----AAAAAAAAAAAAAAA--------- ---AAAAAAAAAAAAAAAA--------- ---AAAAAAAAAAAAAAAA--------- --AAAAAAAAAAAAAAAAAA-------- --AAAAAAAAAAAAAAAAAA-------- --AAAAAAAAAAAAAAAAAA-------- --AAAAAAAAAAAAAAAAA--------- --AAAAAAAAAAAAAAAAA--------- ---AAAAAAAAAAAAAAAAC-------- ---AAAAAAAAAAAAAAAA--------- -----AAAAAAAAAAAAA---------- ------AAAAAAAAAAAA---------- ------AEEAAAAAAA------------ -------AC------------------- 
----CCCCCCCCCCCCCCC--------- ----BBBBBBBBBBBBBBC--------- ------BBBBBBBBBBB----------- ------BBBBBBBBBBB----------- ------BBBBBBBBBBB----------- ------BBBBBBBBBBE----------- ------BBBBBBBBBBB----------- ------BBBBBBBBBBB----------- ------BBBBBBBBBBB----------- ------BBBBBBBBBBB----------- ------BBBBBBBBBBB----------- ------EEBBBBBBBBB----------- ------EEBBBBEEEBB----------- -----AEEBBAAEBEBB----------- ------BBAAAAAAABB----------- ------AAAAAAAAAAB----------- ------AAAAAAAAAABA---------- ----AAAAAAAAAAAAAAA--------- ----AAAAAAAAAAAAAAA--------- ---AAAAAAAAAAAAAAAA--------- ---AAAAAAAAAAAAAAAA--------- --AAAAAAAAAAAAAAAAA--------- --AAAAAAAAAAAAAAAAA--------- ---AAAAAAAAAAAAAAAA--------- ---AAAAAAAAAAAAAAAA--------- ---AAAAAAAAAAAAAAAA--------- ----AAAAAAAAAAAAAAA--------- ------AAAAAAAAAAAA---------- ------AAAAAAAAAAA----------- ------AAAAAAAAAA------------ ---------------------------- 
-----CCCCCCCCCCCCC---------- -----BBBBBBBBBBBBB---------- -------DBBBBBBBDD----------- -------DBBBBBBBDD----------- -------DBBBBBBBDD----------- -------DBBBBBBBDD----------- -------DBBBBBBBDE----------- -------DBBBBBBBDD----------- -------DBBBBBBBDD----------- -------DBBBBBBBDD----------- -------DBBBBBBBDD----------- ------ADBBBBBBBDC----------- -------DBBBBEBEDC----------- ------ADBBBBBBBDC----------- -------DBBBBEBEDD----------- -------DBBAAABBDD----------- -------DAAAAAAADD----------- ------AAAAAAAAAAA----------- ------AAAAAAAAAAAA---------- -----AAAAAAAAAAAAA---------- -----AAAAAAAAAAAAA---------- ----AAAAAAAAAAAAAAA--------- ----AAAAAAAAAAAAAAA--------- ----CAAAAAAAAAAAAAA--------- -----AAAAAAAAAAAAA---------- -----AAAAAAAAAAAAA---------- ------AAAAAAAAAAAA---------- ------AAAAAAAAAA------------ -------CAAAAAAAA------------ ----------AAA--------------- ---------------------------- 
------CCCCCCCCCCC----------- ------CBBBBBBBBBB----------- --------BBBBBBB------------- --------BBBBBBB------------- --------BBBBBBB------------- --------BBBBBBB------------- --------BBBBBBB------------- --------BBBBBBB------------- --------BBBBBBBA------------ --------BBBBBBBAA----------- --------BBBBBBBAC----------- --------BEBBBBBAC----------- -------ABBBBEEEAAC---------- -------ABBBBEBEAC----------- -------ABBBBEEEC------------ -------ABBBBBBBA------------ -------ABAAAAABA------------ ------AAAAAAAAAA------------ ------AAAAAAAAAAA----------- ------AAAAAAAAAAAA---------- -----AAAAAAAAAAAAA---------- -----AAAAAAAAAAAAA---------- -----AAAAAAAAAAAAA---------- -----CAAAAAAAAAAAA---------- -----AAAAAAAAAAAAA---------- ------AAAAAAAAAAAA---------- ------AAAAAAAAAAA----------- -------CAAAAAAAA------------ --------CAAAAAA------------- ---------------------------- ---------------------------- 
-------CCCCCCCCC------------ -------BBBBBBBBB------------ ---------------------------- ---------------------------- ---------------------------- ---------------------------- ---------------------------- ---------------------------- ---------------------------- ---------------------------- ---------------------------- ---------------------------- ---------------------------- --------A------------------- ---------------------------- -----------A--AA------------ -----------A---------------- -------AAAAAAAAA------------ ------AAAAAAAAAA------------ ------AC--AAAAAA------------ ------AAAAAAAAAA------------ ------AAAAAAAAAAA----------- ------AAAAAAAAAAA----------- ------AAAAAAAAAAA----------- ------AAAAAAAAAA------------ ------AAAAAAAAAA------------ ------ACAAAAAAAA------------ ----------AAA--------------- ---------------------------- ---------------------------- ---------------------------- 
---------------------------- ---------------------------- ---------------------------- ---------------------------- ---------------------------- ---------------------------- ---------------------------- ---------------------------- ---------------------------- ---------------------------- ---------------------------- ---------------------------- ---------------------------- ---------------------------- ---------------------------- ---------------------------- ---------------------------- -------AAAAA--AA------------ ------AAA---A--A------------ ------A---ACAA-------------- ------A--AA--AA------------- ------A-AAAAAAAAA----------- -------A--AAAAAAA----------- -------A-AAAAAAAA----------- ------AAAAAAAAAA------------ --------AAAAAAAA------------ -------AAAAAAAAA------------ ----------AAA--------------- ---------------------------- ---------------------------- ---------------------------- 
---------------------------- ---------------------------- ---------------------------- ---------------------------- ---------------------------- ---------------------------- ---------------------------- ---------------------------- ---------------------------- ---------------------------- ---------------------------- ---------------------------- ---------------------------- ---------------------------- ---------------------------- ---------------------------- ---------------------------- ---------------------------- ---------------------------- ---------------------------- -------------C-------------- ---------C-AAAA------------- ----------CAAAC------------- ---------AA-AAC------------- -----------AAAA------------- --------AAAAA--------------- ---------------------------- ---------------------------- ---------------------------- ---------------------------- ---------------------------- 
---------------------------- ---------------------------- ---------------------------- ---------------------------- ---------------------------- ---------------------------- ---------------------------- ---------------------------- ---------------------------- ---------------------------- ---------------------------- ---------------------------- ---------------------------- ---------------------------- ---------------------------- ---------------------------- ---------------------------- ---------------------------- ---------------------------- ---------------------------- ---------------------------- -----------AAAC------------- ------------CC-------------- ----------A-AA-------------- -----------A---------------- -----------A---------------- ---------------------------- ---------------------------- ---------------------------- ---------------------------- ---------------------------- 
---------------------------- ---------------------------- ---------------------------- ---------------------------- ---------------------------- ---------------------------- ---------------------------- ---------------------------- ---------------------------- ---------------------------- ---------------------------- ---------------------------- ---------------------------- ---------------------------- ---------------------------- ---------------------------- ---------------------------- ---------------------------- ---------------------------- ---------------------------- ---------------------------- -----------A---------------- ---------------------------- -------------C-------------- ---------------------------- ---------------------------- ---------------------------- ---------------------------- ---------------------------- ---------------------------- ---------------------------- 
