model
size = 24 12 29, scale = 0.05, origin = -y
material 
  colors = A:#252525 B:#E83015 C:#E03C8A D:#FBE251 E:#F05E1C F:#FFB11B G:#FFC408 H:#FFF I:#111
voxels
-------BBBBBBBBBB------- -------BBBBBBBBBB------- ------------------------ ------------------------ ------------------------ ------------------------ ------------------------ ------------------------ ------------------------ ------------------------ ------------------------ ------------------------ 
------BBBBBBBBBBBB------ ------BCCDCECDCCCB------ ------------------------ ------------------------ ------------------------ ------------------------ ------------------------ ------------------------ ------------------------ ------------------------ ------------------------ ------------------------ 
-----BBBBBBBBBBBBBB----- -----BCDCCEEECCDCDB----- ------------------------ ------------------------ ------------------------ ------------------------ ------------------------ ------------------------ ------------------------ ------------------------ ------------------------ ------------------------ 
----BBBBBBBEEBBBBBBB---- ----BCCCCEEFEECCCCCB---- ------------------------ ------------------------ ------------------------ ------------------------ ------------------------ ------------------------ ------------------------ ------------------------ ------------------------ ------------------------ 
---BBBBBBBEGGEBBBBBBB--- ---BCDCCEEFDFEECDCDCB--- ------------------------ ------------------------ ------------------------ ------------------------ ------------------------ ------------------------ ------------------------ ------------------------ ------------------------ ------------------------ 
---BBBBBBEGDDGEBBBBBB--- ---BCCCEEFDCDFEECCCCB--- ------------------------ ------------------------ ------------------------ ------------------------ ------------------------ ------------------------ ------------------------ ------------------------ ------------------------ ------------------------ 
--BBBBBBEGDDDDGEBBBBBB-- --BCDCDEFDCCCDFECDCDCB-- ------------------------ ------------------------ ------------------------ ------------------------ ------------------------ ------------------------ ------------------------ ------------------------ ------------------------ ------------------------ 
--BBBBBEGDDCCDDGEBBBBB-- --BCCCEEDCCHCCDEECCCCB-- ------------------------ ---FF-FF--DDDD---BB----- ---FF-FF-DD--DD--BB----- ---FFFFF-DD--DD--BB----- ---FF-FF-DD--DD--BB----- ---FF-FF--DDDD--BBBB---- ------------------------ ------------------------ ------------------------ ------------------------ 
--BBBBEGDDCCCCDDGEBBBB-- --BDCCDAAAAADAAAADCCDB-- ------AAAAAAAAAAAA------ ------AAAAAAAAAAAA------ ------AAAAAAAAAAAA------ ------AAAAAAAAAAAA------ ------AAAAAAAAAAAA------ -------AAAAAAAAAA------- --------AAACCAAA-------- ------------------------ ------------------------ ------------------------ 
--BBBEGDDCCHHCCDDGEBBB-- --BCAAAGDDCHHCDDGAAACB-- ----AAABGDDCCDDGBAAA---- ----AAAABGDDDDGBAAAA---- -----AAAABGDDGBAAAA----- -----AAAAABGGBAAAAA----- -----AAAAAABBAAAAAA----- ------AAAAAAAAAAAA------ -------AAAACCAAAA------- ------------------------ ------------------------ ------------------------ 
--BBEGD----------DGEBB-- --BBBBB----------BBBBB-- ---AAA------------AAA--- ---AAA------------AAA--- ----AA------------AA---- ----AA------------AA---- ----AAA----------AAA---- -----AAAAAACCAAAAAA----- ------AAAAAAAAAAAA------ ----------ACCA---------- ------------------------ ------------------------ 
--BEGD------------DGEB-- --BBBB------------BBBB-- --AA-C------------CAAA-- --AA-C------------CAAA-- ---AAC------------CAA--- ---AAC------------CAA--- ----AAA----------AAA---- -----AAA--------AAA----- ------AAAAACCAAAAA------ --------AAACCAAA-------- ------------------------ ------------------------ 
--EB----------------BE-- --BB----------------BB-- --A------------------A-- --A------------------A-- ---A----------------A--- ---A----------------A--- ----AAC----------CAA---- ----AACA--------ACAA---- ------AAAAACCAAAAA------ --------AAACCAAA-------- ------------------------ ------------------------ 
-FBB----------------BBF- -EBB----------------BBE- -BA------------------AB- -AA------------------AA- --A-----------------AA-- --A-----------------AA-- ---A----------------A--- ---AAA------------AAA--- -----AACAAACCAAACAA----- -------AAAACCAAAA------- ------------------------ ------------------------ 
-DB------------------BD- -FB------------------BF- -EA------------------IE- -BA------------------AB- --A------------------A-- --A------------------A-- ---A----------------A--- ---AAA------------AAA--- -----AAACA----ACAAA----- -------AAAACCAAAA------- ----------ACCA---------- ------------------------ 
CBB------------------BBC DAB------------------BAD FA--------------------AF -EA------------------AE- -BA------------------AB- --A------------------A-- --AA----------------AA-- ---AAA------------AAA--- ----AAAA--------AAAA---- ------AAACACCACAAA------ ---------AACCAA--------- ------------------------ 
CB--------------------BC CB--------------------BC DA--------------------AD FA--------------------AF -EA------------------AE- -BA------------------AB- --AA----------------AA-- --AAAA------------AAAA-- ----AAAA--------AAAA---- ------AAAACCCCAAAA------ --------AAAAAAAA-------- -----------BB----------- 
HB--------------------BH CB--------------------BC CC--------------------CC DC--------------------CD -FC------------------CF- -EC------------------CE- --BC----------------CB-- --CCCC------------CCCC-- ----CCCC--------CCCC---- ------CCCCCHHCCCCC------ --------CCADAACC-------- ----------BDDB---------- 
CB--------------------BC CB--------------------BC DA--------------------AD FA--------------------AF -EA------------------AE- -BA------------------AB- --AA----------------AA-- --AAAA------------AAAA-- ----AAAA--------AAAA---- ------AAAACCCCAAAA------ --------AAAAAAAA-------- -----------BB----------- 
CB--------------------BC DB--------------------BD FA--------------------AF EA--------------------AE -BA------------------AB- -AA------------------AI- --AA----------------AA-- --AAAA------------AAAA-- ----AAAAAC----CAAAAA---- ------AAADACCADAAA------ ---------AACCAA--------- ------------------------ 
DB--------------------BD FB--------------------BF EA--------------------AE -BA------------------AB- -AA------------------AI- --A------------------A-- --AA----------------AA-- ---AAA------------AAA--- -----AAACA----ACAAA----- -------AAAACCAAAA------- ----------ACCA---------- ------------------------ 
FBB------------------BBF EAB------------------BAE -BA------------------AB- -A-------------------AI- --A------------------A-- --A------------------A-- ---A----------------A--- ---AAAAC--------CAAAA--- -----AAAAAACCAAADAA----- -------AAAACCAAAA------- ------------------------ ------------------------ 
-EB------------------BE- -BB------------------BB- -A--------------------I- -A--------------------A- --A------------------A-- --A------------------A-- ---AAAC----------CAAA--- ---AAADA--------ADAAA--- -----AAAAAACCAAAAAA----- -------AAAACCAAAA------- ------------------------ ------------------------ 
-BAB----------------BAB- -AAB----------------BBA- -AA------------------AA- --A------------------A-- --A------------------A-- ---AAC------------CAA--- ---AADA----------ADAA--- ----AAAA--------AAAA---- ------AAAAACCAAAAA------ ---------AACCAA--------- ------------------------ ------------------------ 
--ABB--------------BBA-- --ADB--------------BBA-- --AAC--------------CAA-- --AAC--------------CAA-- ---AC--------------CA--- ---ADA------------ADA--- ----AAA----------AAA---- -----AAAAAACCAAAAAA----- -------AAAACCAAAA------- ------------------------ ------------------------ ------------------------ 
--AAB--------------BAA-- --AAB--------------BBA-- --AAA--------------AAA-- --AAA--------------AAA-- ----A--------------A---- ----AA------------AA---- -----AA----------AA----- -------AAAACCAAAA------- ---------AACCAA--------- ------------------------ ------------------------ ------------------------ 
---AABB----------BBAA--- ---AABB----------BBBA--- ---AAA------------AAA--- ---AAA------------AAA--- -----A------------A----- -----A------------A----- ------AAAAACCAAAAA------ ---------AACCAA--------- ------------------------ ------------------------ ------------------------ ------------------------ 
----AAABG------GBAAA---- ----AAABG------GBBAA---- ----AAAAB------BAAAA---- ----AAAAAB----BAAAAA---- ------AAAABGGBAAAA------ ------AAAAABBAAAAA------ ---------AACCAA--------- ------------------------ ------------------------ ------------------------ ------------------------ ------------------------ 
------BBGDCHHCDGBB------ ------ABEGDCCDGEBA------ ------AAB------BAA------ ------AAAB----BAAA------ --------AABGGBAA-------- ---------AABBAA--------- ------------------------ ------------------------ ------------------------ ------------------------ ------------------------ ------------------------ 
