model
size = 16 20 19, scale = 0.05, origin = -y
material 
  colors = A:#09C B:#EEE
voxels
---------------- ---------------- ---------------- ---------------- ---------------- ---------------- ---------------- ---------------- ------BBBB------ ------AAAA------ ------AAAA------ ------BBBB------ ---------------- ---------------- ---------------- ---------------- ---------------- ---------------- ---------------- ---------------- 
---------------- ---------------- ---------------- ---------------- ---------------- ---------------- ------BBBB------ -----BBBBBB----- ----ABAAAABA---- ----AAAAAAAA---- ----BBAAAABB---- ----BAAAAAAB---- -----BBAABB----- ------BBBB------ ---------------- ---------------- ---------------- ---------------- ---------------- ---------------- 
---------------- ---------------- ---------------- ---------------- ------AAAA------ ----AAAAAAAA---- ---AAAAAAABAA--- ---AAAAAAAAAA--- --AAAAAAAAAAAA-- --AAAAAAAAAAAA-- --BAAAAAAAAAAB-- --AAAAAAAAAAAA-- ---BBAAAAAABB--- ---BBAAAAAABB--- ----BBBBBBBB---- ------BAAB------ ---------------- ---------------- ---------------- ---------------- 
---------------- ---------------- ---------------- ----AAAAAAAA---- ----AAAAAAAA---- ---AAAAAAAAAA--- -AAAAAAAAAAAAAA- -AAAAAAAAAAAAAA- -AAAAAAAAAAAAAA- -AAAAAAAAAAAAAA- -AAAAAAAAAAAAAA- -BAAAAAAAAAAAAB- -AAAAAAAAAAAAAA- -AAAAAAAAAAAAAA- ---AAAAAAAAAA--- ----ABAAAABA---- ----AAAAAAAA---- ---------------- ---------------- ---------------- 
---------------- ---------------- ------AAAA------ ----AAAAAAAA---- ---AAAAAAAAAA--- --AAAAAAAAAAAA-- -AAAAAAAAAAAAAA- -AAAAAAAAAAAAAA- AAAAAAAAAAAAAAAA AAAAAAAAAAAAAAAA AAAAAAAAAAAAAAAA AAAAAAAAAAAAAAAA -AAAAAAAAAAAAAA- -AAAAAAAAAAAAAA- --AAAAAAAAAAAA-- ---AAAAAAAAAA--- ----AAAAAAAA---- ------AAAA------ ---------------- ---------------- 
---------------- ---------------- ----AAAAAAAA---- ---AAAAAAAAAA--- --AAAAAAAAAAAA-- -AAAAAAAAAAAAAA- AAAAAAAAAAAAAAAA AAAAAAAAAAAAAAAA AAAAAAAAAAAAAAAA AAAAAAAAAAAAAAAA AAAAAAAAAAAAAAAA AAAAAAAAAAAAAAAA AAAAAAAAAAAAAAAA AAAAAAAAAAAAAAAA -AAAAAAAAAAAAAA- --AAAAAAAAAAAA-- ---AAAAAAAAAA-A- ----AAAAAAAA---- ---------------- ---------------- 
---------------- ------AAAA------ ---AAAAAAAAAA--- -AAAAAAAAAAAAAA- -AAAAAAAAAAAAAA- AAAAAAAAAAAAAAAA AAAAAAAAAAAAAAAA AAAAAAAAAAAAAAAA AAAAAAAAAAAAAAAA AAAAAAAAAAAAAAAA AAAAAAAAAAAAAAAA AAAAAAAAAAAAAAAA AAAAAAAAAAAAAAAA AAAAAAAAAAAAAAAA AAAAAAAAAAAAAAAA -AAAAAAAAAAAAAA- -AAAAAAAAAAAAAA- ---BAAAAAAAAA--- ------AAAA------ ---------------- 
---------------- -----AAAAAA----- ---AAAAAAAAAA--- -AAAAAAAAAAAAAA- -AAAAAAAAAAAAAA- AAAAAAAAAAAAAAAA AAAAAAAAAAAAAAAA AAAAAAAAAAAAAAAA AAAAAAAAAAAAAAAA AAAAAAAAAAAAAAAA AAAAAAAAAAAAAAAA AAAAAAAAAAAAAAAA AAAAAAAAAAAAAAAA AAAAAAAAAAAAAAAA AAAAAAAAAAAAAAAA -AAAAAAAAAAAAAA- -AAAAAAAAAAAAAA- ---BAAAAAAAAA--- -----AAAAAA----- -------AA------- 
------AAAA------ ----AAAAAAAA---- --AAAAAAAAAAAA-- -AAAAAAAAAAAAAA- AAAAAAAAAAAAAAAA AAAAAAAAAAAAAAAA AAAAAAAAAAAAAAAA AAAAAAAAAAAAAAAA AAAAAAAAAAAAAAAA AAAAAAAAAAAAAAAA AAAAAAAAAAAAAAAA AAAAAAAAAAAAAAAA AAAAAAAAAAAAAAAA AAAAAAAAAAAAAAAA AAAAAAAAAAAAAAAA AAAAAAAAAAAAAAAA -AAAAAAAAAAAAAA- --BAAAAAAAAAAA-- ----AAAAAAAA---- ------AAAA------ 
------AAAA------ ----AAAAAAAA---- --AAAAAAAAAAAA-- -AAAAAAAAAAAAAA- AAAAAAAAAAAAAAAA AAAAAAAAAAAAAAAA AAAAAAAAAAAAAAAA AAAAAAAAAAAAAAAA AAAAAAAAAAAAAAAA AAAAAAAAAAAAAAAA AAAAAAAAAAAAAAAA AAAAAAAAAAAAAAAA AAAAAAAAAAAAAAAA AAAAAAAAAAAAAAAA AAAAAAAAAAAAAAAA AAAAAAAAAAAAAAAA -AAAAAAAAAAAAAA- --AAAAAAAAAAAA-- ----AAAAAAAA-AA- -----AAAAAA---A- 
------AAAA------ ----AAAAAAAA---- --AAAAAAAAAAAA-- -AAAAAAAAAAAAAA- AAAAAAAAAAAAAAAA AAAAAAAAAAAAAAAA AAAAAAAAAAAAAAAA AAAAAAAAAAAAAAAA AAAAAAAAAAAAAAAA AAAAAAAAAAAAAAAA AAAAAAAAAAAAAAAA AAAAAAAAAAAAAAAA AAAAAAAAAAAAAAAA AAAAAAAAAAAAAAAA AAAAAAAAAAAAAAAA AAAAAAAAAAAAAAAA -AAAAAAAAAAAAAA- --AAAAAAAAAAAA-- ----AAAAAAAA---- -----AAAAAA----- 
------AAAA------ ----AAAAAAAA---- --AAAAAAAAAAAA-- -AAAAAAAAAAAAAA- AAAAAAAAAAAAAAAA AAAAAAAAAAAAAAAA AAAAAAAAAAAAAAAA AAAAAAAAAAAAAAAA AAAAAAAAAAAAAAAA AAAAAAAAAAAAAAAA AAAAAAAAAAAAAAAA AAAAAAAAAAAAAAAA AAAAAAAAAAAAAAAA AAAAAAAAAAAAAAAA AAAAAAAAAAAAAAAA AAAAAAAAAAAAAAAA -AAAAAAAAAAAAAA- --AAAAAAAAAAAA-- ----AAAAAAAA---- ------AAAA------ 
---------------- -----AAAAAA----- ---AAAAAAAAAA--- -AAAAAAAAAAAAAA- -AAAAAAAAAAAAAA- AAAAAAAAAAAAAAAA AAAAAAAAAAAAAAAA AAAAAAAAAAAAAAAA AAAAAAAAAAAAAAAA AAAAAAAAAAAAAAAA AAAAAAAAAAAAAAAA AAAAAAAAAAAAAAAA AAAAAAAAAAAAAAAA AAAAAAAAAAAAAAAA AAAAAAAAAAAAAAAA -AAAAAAAAAAAAAA- -AAAAAAAAAAAAAA- ---AAAAAAAAAA--- -----AAAAAA----- -------AA------- 
---------------- ------AAAA------ ---AAAAAAAAAA--- -AAAAAAAAAAAAAA- -AAAAAAAAAAAAAA- AAAAAAAAAAAAAAAA AAAAAAAAAAAAAAAA AAAAAAAAAAAAAAAA AAAAAAAAAAAAAAAA AAAAAAAAAAAAAAAA AAAAAAAAAAAAAAAA AAAAAAAAAAAAAAAA AAAAAAAAAAAAAAAA AAAAAAAAAAAAAAAA AAAAAAAAAAAAAAAA -AAAAAAAAAAAAAA- -AAAAAAAAAAAAAA- ---AAAAAAAAAA--- ------AAAA------ ---------------- 
---------------- ---------------- ----AAAAAAAA---- ---AAAAAAAAAA--- --AAAAAAAAAAAA-- -AAAAAAAAAAAAAA- AAAAAAAAAAAAAAAA AAAAAAAAAAAAAAAA AAAAAAAAAAAAAAAA AAAAAAAAAAAAAAAA AAAAAAAAAAAAAAAA AAAAAAAAAAAAAAAA AAAAAAAAAAAAAAAA AAAAAAAAAAAAAAAA -AAAAAAAAAAAAAA- --AAAAAAAAAAAA-- ---AAAAAAAAAA--- ----AAAAAAAA---- ---------------- ---------------- 
---------------- ---------------- ------AAAA------ ----AAAAAAAA---- ---AAAAAAAAAA--- --AAAAAAAAAAAA-- -AAAAAAAAAAAAAA- -AAAAAAAAAAAAAA- AAAAAAAAAAAAAAAA AAAAAAAAAAAAAAAA AAAAAAAAAAAAAAAA AAAAAAAAAAAAAAAA -AAAAAAAAAAAAAA- -AAAAAAAAAAAAAA- --AAAAAAAAAAAA-- ---AAAAAAAAAA--- ----AAAAAAAA---- ------AAAA------ ---------------- ---------------- 
---------------- ---------------- ---------------- ----AAAAAAAA---- ----AAAAAAAA---- ---AAAAAAAAAA--- -AAAAAAAAAAAAAA- -AAAAAAAAAAAAAA- -AAAAAAAAAAAAAA- -AAAAAAAAAAAAAA- -AAAAAAAAAAAAAA- -AAAAAAAAAAAAAA- -AAAAAAAAAAAAAA- -AAAAAAAAAAAAAA- ---AAAAAAAAAA--- ----AAAAAAAA---- ----AAAAAAAA---- ---------------- ---------------- ---------------- 
---------------- ---------------- ---------------- ---------------- ------AAAA------ ----AAAAAAAA---- ---AAAAAAAAAA--- ---AAAAAAAAAA--- --AAAAAAAAAAAA-- --AAAAAAAAAAAA-- --AAAAAAAAAAAA-- --AAAAAAAAAAAA-- ---AAAAAAAAAA--- ---AAAAAAAAAA--- ----AAAAAAAA---- ------AAAA------ ---------------- ---------------- ---------------- ---------------- 
---------------- ---------------- ---------------- ---------------- ---------------- ---------------- ------AAAA------ -----AAAAAA----- ----AAAAAAAA---- ----AAAAAAAA---- ----AAAAAAAA---- ----AAAAAAAA---- -----AAAAAA----- ------AAAA------ ---------------- ---------------- ---------------- ---------------- ---------------- ---------------- 
