model
size = 32 10 32, scale = 0.05, origin = -y
material 
  colors = A:#F0C B:#3CF C:#E00 D:#001 E:#0CC F:#0F3 G:#111 H:#EEE
voxels
A3(30-2A)30-A192-A6(30-2A)30-A96-A4(30-2A)30-AH30-HA30-2A30-A128-A30-2A30-AH30-HF30-FH30-HA30-2A30-A128-A30-2A30-AH30-HA3(30-2A)30-A128-A5(30-2A)30-A160-A2(30-2A)30-AE30-EA30-A192-2(A30-D)E30-D2(A30-D192-A30-DA30-AE30-E)A30-D192-A30-2A30-AE30-EA30-A192-2(A30-D)E30-DA30-D192-A30-DA30-AE30-EA30-D192-2(A30-D)E30-DA30-D192-A30-2A30-AE30-EA30-A192-2(A30-D)E30-EA30-D2(192-A30-DA30-AE30-EA30-A)192-A30-2A30-AE30-EA30-A192-2(A30-D)E30-DA30-D192-A30-DA30-AE30-EA30-D160-A30-2A30-AE30-DE30-EA30-A128-A2(30-2A)30-AE30-EA30-2A30-A96-A2(30-2A)30-AE30-DE30-EA30-2A30-D64-A3(30-2A)30-AE3(30-DA)30-D32-A3(30-2A)30-AE30-2E30-DA30-2A30-AF30-DA4(30-2A)30-AE30-EA30-2A30-AF30-2F30-FA3(30-2A)30-AE30-2E30-E2(A30-D)2(F30-D)13A5-14AG12A5-13A2GA9-2A5-2A10-A2GA9-3A3-3A10-AGEA9-4A-4A10-AE2A9-9A10-AD2A9-9A10-2AFA9-9A10-ADF30A2F30AD13A5-14AG12A5-13AGFA9-2A5-2A10-AFGA9-3A3-3A10-AG2A9-4A-4A10-4A9-9A10-ADFA9-9A10-A2FA9-9A10-ADF30A2F30AD13A5-14AG12A5-13A2GA9C2A5-2A10BA2GA9C3A3-3A10BAG2A9C4A-4A10B2AF3(A9C9A10BA2F)30A2F30AF14A4-28A4-16A9-3A4-3A2(9-4A)2-2(4A9-)10A9-2AF3(A9-10A9-A2F)30A2F30AF
