model
size = 32, scale = 0.05, origin = -y
material 
  colors = A:#111 B:#EEE
voxels
398-4A27-6A25-3(8A24-)5AB2A25-6A27-4A700-4B26-8B23-10B21-4B4A4B20-3B6A3B19-3(3B8A3B18-)3B8A3B19-3B6A3B20-4B4A4B21-10B23-8B26-4B541-2A27-8A22-4A4B4A19-3A8B3A18-2A10B2A17-2A4B4A4B2A16-2A3B6A3B2A16-A3B8A3BA15-2A3B8A3B2A14-2A3B8A3B2A15-A3B8A3BA16-2A3B6A3B2A16-2A4B4A4B2A17-2A10B2A18-3A8B3A19-4A4B4A22-8A27-2A444-6A24-10A20-14A17-6A4B6A16-4A8B4A15-4A10B4A14-3A4B4A4B3A13-4A3B6A3B4A4(12-3A3B8A3B3A)12-4A3B6A3B4A13-3A4B4A4B3A14-4A10B4A15-4A8B4A16-6A4B6A17-14A20-10A24-6A377-8A22-12A19-14A17-16A15-7A4B7A13-6A8B6A12-5A10B5A11-5A4B4A4B5A10-5A3B6A3B5A4(10-4A3B8A3B4A)10-5A3B6A3B5A10-5A4B4A4B5A11-5A10B5A12-6A8B6A13-7A4B7A15-16A17-14A19-12A22-8A312-8A22-12A19-14A16-18A14-18A13-8A4B8A11-7A8B7A10-6A10B6A9-6A4B4A4B6A8-2(6A3B)6A4(8-5A3B8A3B5A)8-2(6A3B)6A8-6A4B4A4B6A9-6A10B6A10-7A8B7A11-8A4B8A13-18A14-18A16-14A19-12A22-8A249-6A23-12A19-14A16-18A13-20A12-20A11-9A4B9A9-8A8B8A8-7A10B7A8-6A4B4A4B6A7-7A3B6A3B7A4(6-6A3B8A3B6A)6-7A3B6A3B7A7-6A4B4A4B6A8-7A10B7A8-8A8B8A9-9A4B9A11-20A12-20A13-18A16-14A19-12A23-6A188-2A26-10A20-14A16-18A13-20A11-22A10-22A9-10A4B10A8-8A8B8A7-8A10B8A6-7A4B4A4B7A6-7A3B6A3B7A6-6A3B8A3B6A5-7A3B8A3B7A4-7A3B8A3B7A5-6A3B8A3B6A6-7A3B6A3B7A6-7A4B4A4B7A6-8A10B8A7-8A8B8A8-10A4B10A9-22A10-22A11-20A13-18A16-14A20-10A26-2A155-8A21-14A17-16A15-18A13-20A11-22A9-24A7-11A4B11A6-9A8B9A6-8A10B8A5-8A4B4A4B8A4-8A3B6A3B8A4(4-7A3B8A3B7A)4-8A3B6A3B8A4-8A4B4A4B8A5-8A10B8A6-9A8B9A6-11A4B11A7-24A9-22A11-20A13-18A15-16A17-14A21-8A122-4A24-12A18-16A15-18A13-20A11-22A9-24A7-26A6-11A4B11A5-10A8B10A4-9A10B9A4-8A4B4A4B8A4-8A3B6A3B8A3-3(2(8A3B)8A2-)2(8A3B)8A3-8A3B6A3B8A4-8A4B4A4B8A4-9A10B9A4-10A8B10A5-11A4B11A6-26A7-24A9-22A11-20A13-18A15-16A18-12A24-4A90-8A21-14A17-16A14-20A11-22A9-24A8-24A7-26A5-12A4B12A4-10A8B10A4-9A10B9A3-9A4B4A4B9A2-9A3B6A3B9A4(2-2(8A3B)8A)2-9A3B6A3B9A2-9A4B4A4B9A3-9A10B9A4-10A8B10A4-12A4B12A5-26A7-24A8-24A9-22A11-20A14-16A17-14A21-8A87-10A20-14A16-18A13-20A11-22A9-24A7-26A6-26A5-12A4B12A4-10A8B10A3-10A10B10A2-9A4B4A4B9A2-9A3B6A3B9A4(2-2(8A3B)8A)2-9A3B6A3B9A2-9A4B4A4B9A2-10A10B10A3-10A8B10A4-12A4B12A5-26A6-26A7-24A9-22A11-20A13-18A16-14A20-10A57-4A24-12A18-16A15-18A12-22A9-24A8-24A7-26A5-28A4-12A4B12A3-11A8B11A2-10A10B10A2-9A4B4A4B9A2-9A3B6A3B9A-9A3(3B8A3B18A)3B8A3B9A-9A3B6A3B9A2-9A4B4A4B9A2-10A10B10A2-11A8B11A3-12A4B12A4-28A5-26A7-24A8-24A9-22A12-18A15-16A18-12A24-4A27-6A23-12A18-16A14-20A11-22A9-24A7-26A6-26A5-28A4-12A4B12A3-11A8B11A2-10A10B10A2-9A4B4A4B9A-10A3B6A3B19A3(3B8A3B18A)3B8A3B19A3B6A3B10A-9A4B4A4B9A2-10A10B10A2-11A8B11A3-12A4B12A4-28A5-26A6-26A7-24A9-22A11-20A14-16A18-12A23-6A25-8A21-14A17-16A14-20A11-22A9-24A7-26A6-26A5-28A3-13A4B13A2-11A8B11A2-10A10B10A-10A4B4A4B20A3B6A3B19A3(3B8A3B18A)3B8A3B19A3B6A3B20A4B4A4B10A-10A10B10A2-11A8B11A2-13A4B13A3-28A5-26A6-26A7-24A9-22A11-20A14-16A17-2(14A21-8A24-8A21-14A16-18A13-20A11-22A9-24A7-26A5-28A4-28A3-13A4B13A2-11A8B11A2-10A10B10A-10A4B4A4B20A3B6A3B19A3(3B8A3B18A)3B8A3B19A3B6A3B20A4B4A4B10A-10A10B10A2-11A8B11A2-13A4B13A3-28A4-28A5-26A7-24A9-22A11-20A13-18A16-)14A21-8A24-8A21-14A17-16A14-20A11-22A9-24A7-26A6-26A5-28A3-13A4B13A2-11A8B11A2-10A10B10A-10A4B4A4B20A3B6A3B19A3(3B8A3B18A)3B8A3B19A3B6A3B20A4B4A4B10A-10A10B10A2-11A8B11A2-13A4B13A3-28A5-26A6-26A7-24A9-22A11-20A14-16A17-14A21-8A25-6A23-12A18-16A14-20A11-22A9-24A7-26A6-26A5-28A4-12A4B12A3-11A8B11A2-10A10B10A2-9A4B4A4B9A-10A3B6A3B19A3(3B8A3B18A)3B8A3B19A3B6A3B10A-9A4B4A4B9A2-10A10B10A2-11A8B11A3-12A4B12A4-28A5-26A6-26A7-24A9-22A11-20A14-16A18-12A23-6A27-4A24-12A18-16A15-18A12-22A9-24A8-24A7-26A5-28A4-12A4B12A3-11A8B11A2-10A10B10A2-9A4B4A4B9A2-9A3B6A3B9A-9A3(3B8A3B18A)3B8A3B9A-9A3B6A3B9A2-9A4B4A4B9A2-10A10B10A2-11A8B11A3-12A4B12A4-28A5-26A7-24A8-24A9-22A12-18A15-16A18-12A24-4A57-10A20-14A16-18A13-20A11-22A9-24A7-26A6-26A5-12A4B12A4-10A8B10A3-10A10B10A2-9A4B4A4B9A2-9A3B6A3B9A4(2-2(8A3B)8A)2-9A3B6A3B9A2-9A4B4A4B9A2-10A10B10A3-10A8B10A4-12A4B12A5-26A6-26A7-24A9-22A11-20A13-18A16-14A20-10A87-8A21-14A17-16A14-20A11-22A9-24A8-24A7-26A5-12A4B12A4-10A8B10A4-9A10B9A3-9A4B4A4B9A2-9A3B6A3B9A4(2-2(8A3B)8A)2-9A3B6A3B9A2-9A4B4A4B9A3-9A10B9A4-10A8B10A4-12A4B12A5-26A7-24A8-24A9-22A11-20A14-16A17-14A21-8A90-4A24-12A18-16A15-18A13-20A11-22A9-24A7-26A6-11A4B11A5-10A8B10A4-9A10B9A4-8A4B4A4B8A4-8A3B6A3B8A3-3(2(8A3B)8A2-)2(8A3B)8A3-8A3B6A3B8A4-8A4B4A4B8A4-9A10B9A4-10A8B10A5-11A4B11A6-26A7-24A9-22A11-20A13-18A15-16A18-12A24-4A122-8A21-14A17-16A15-18A13-20A11-22A9-24A7-11A4B11A6-9A8B9A6-8A10B8A5-8A4B4A4B8A4-8A3B6A3B8A4(4-7A3B8A3B7A)4-8A3B6A3B8A4-8A4B4A4B8A5-8A10B8A6-9A8B9A6-11A4B11A7-24A9-22A11-20A13-18A15-16A17-14A21-8A155-2A26-10A20-14A16-18A13-20A11-22A10-22A9-10A4B10A8-8A8B8A7-8A10B8A6-7A4B4A4B7A6-7A3B6A3B7A6-6A3B8A3B6A5-7A3B8A3B7A4-7A3B8A3B7A5-6A3B8A3B6A6-7A3B6A3B7A6-7A4B4A4B7A6-8A10B8A7-8A8B8A8-10A4B10A9-22A10-22A11-20A13-18A16-14A20-10A26-2A188-6A23-12A19-14A16-18A13-20A12-20A11-9A4B9A9-8A8B8A8-7A10B7A8-6A4B4A4B6A7-7A3B6A3B7A4(6-6A3B8A3B6A)6-7A3B6A3B7A7-6A4B4A4B6A8-7A10B7A8-8A8B8A9-9A4B9A11-20A12-20A13-18A16-14A19-12A23-6A249-8A22-12A19-14A16-18A14-18A13-8A4B8A11-7A8B7A10-6A10B6A9-6A4B4A4B6A8-2(6A3B)6A4(8-5A3B8A3B5A)8-2(6A3B)6A8-6A4B4A4B6A9-6A10B6A10-7A8B7A11-8A4B8A13-18A14-18A16-14A19-12A22-8A312-8A22-12A19-14A17-16A15-7A4B7A13-6A8B6A12-5A10B5A11-5A4B4A4B5A10-5A3B6A3B5A4(10-4A3B8A3B4A)10-5A3B6A3B5A10-5A4B4A4B5A11-5A10B5A12-6A8B6A13-7A4B7A15-16A17-14A19-12A22-8A377-6A24-10A20-14A17-6A4B6A16-4A8B4A15-4A10B4A14-3A4B4A4B3A13-4A3B6A3B4A4(12-3A3B8A3B3A)12-4A3B6A3B4A13-3A4B4A4B3A14-4A10B4A15-4A8B4A16-6A4B6A17-14A20-10A24-6A444-2A27-8A22-12A19-14A18-14A17-2(16A16-)16A15-18A14-18A15-2(16A16-)16A17-14A18-14A19-12A22-8A27-2A541-4A26-8A23-10A21-12A20-12A19-3(14A18-)14A19-12A20-12A21-10A23-8A26-4A700-4A27-6A25-3(8A24-)8A25-6A27-4A398-
