model
size = 32, scale = 0.05, origin = -y
material 
  colors = A:#DDD B:#0CF C:#E00 D:#002 E:#EEE
voxels
398-4D27-6D25-3(8D24-)5DE2D25-6D27-4D700-4B26-8B23-10B21-4B4A4B20-3B6A3B19-3(3B8A3B18-)3B8A3B19-3B6A3B20-4B4A4B21-10B23-8B26-4B541-2B27-8B22-12B19-14B18-14B17-6B4A6B16-5B6A5B16-4B8A4B15-5B8A5B14-5B8A5B15-4B8A4B16-5B6A5B16-6B4A6B17-14B18-14B19-12B22-8B27-2B444-6A24-10A20-14A17-6A4B6A16-4A8B4A15-4A10B4A14-3A4B4A4B3A13-4A3B6A3B4A4(12-3A3B8A3B3A)12-4A3B6A3B4A13-3A4B4A4B3A14-4A10B4A15-4A8B4A16-6A4B6A17-14A20-10A24-6A377-8A22-12A19-14A17-16A15-7A4B6AC13-6A8B5AC12-5A10B4AC11-5A4B4A4B5A10-5A3B6A3B5A10-4A3B8A3B4A10-4A3B8A3B3AC2(10-4A3B8A3B4A)10-5A3B6A3B5A10-C2(4A4B)5A11-5A10B5A12-6A8B5AC13-7A4B7A15-16A17-14A19-12A22-8A312-8A22-2C10A19-13AC16-18A14-C17A13-C7A4B8A11-C6A8B6AC10-6A10B6A9-6A4B4A4B6A8-2(6A3B)6A2(8-5A3B8A3B5A)8-5A3B8A3B4AC8-5A3B8A3B5A8-2(6A3B)6A8-6A4B4A4B6A9-6A10B6A10-C6A8B7A11-C7A4B7AC13-18A14-16A2C16-C13A19-12A22-8A249-6A23-C11A19-14A16-16ACA13-20A12-20A11-9A4B9A9-C7A8B7AC8-7A10B7A8-6A4B4A4B6A7-7A3B6A3B7A3(6-6A3B8A3B6A)6-6A3B8A3B5AC6-7A3B6A3B7A7-6A4B4A4B6A8-C6A10B7A8-8A8B8A9-9A4B9A11-19AC12-20A13-18A16-14A19-12A23-6A188-2A26-10A20-C13A16-16A2C13-20A11-22A10-22A9-10A4B10A8-8A8B8A7-C7A10B7AC6-7A4B4A4B7A6-7A3B6A3B7A6-6A3B8A3B6A5-7A3B8A3B7A4-7A3B8A3B7A5-6A3B8A3B5AC6-7A3B6A3B7A6-C6A4B4A4B7A6-C7A10B8A7-8A8B8A8-10A4B9AC9-21AC10-22A11-20A13-2C16A16-14A20-10A26-2A155-8A21-14A17-C15A15-18A13-20A11-22A9-24A7-11A4B11A6-9A8B9A6-C7A10B7AC5-8A4B4A4B7AC4-8A3B6A3B8A4(4-7A3B8A3B7A)4-8A3B6A3B7AC4-C7A4B4A4B7AC5-8A10B8A6-9A8B9A6-11A4B10AC7-24A9-22A11-20A13-C17A15-16A17-14A21-8A122-4A24-12A18-C15A15-17AC13-20A11-22A9-24A7-26A6-11A4B11A5-C9A8B10A4-9A10B9A4-8A4B4A4B7AC4-8A3B6A3B8A3-2(2(8A3B)8A2-)C7A2(3B8A)2-C7A2(3B8A)3-C7A3B6A3B8A4-8A4B4A4B7AC4-9A10B9A4-10A8B10A5-11A4B10AC6-26A7-24A9-22A11-C19A13-18A15-16A18-12A24-4A90-8A21-14A17-C15A14-19AC11-22A9-24A8-24A7-26A5-12A4B12A4-C9A8B10A4-9A10B9A3-9A4B4A4B8AC2-9A3B6A3B9A2-2(8A3B)8A2(2-C7A2(3B8A))2-2(8A3B)8A2-9A3B6A3B9A2-9A4B4A4B9A3-9A10B8AC4-10A8B10A4-12A4B12A5-25AC7-24A8-24A9-22A11-20A14-16A17-14A21-8A87-10A20-14A16-C17A13-19AC11-22A9-24A7-26A6-26A5-12A4B12A4-10A8B10A3-C9A10B10A2-9A4B4A4B8AC2-9A3B6A3B9A2-2(8A3B)8A2-C7A2(3B8A)2(2-2(8A3B)8A)2-9A3B6A3B9A2-9A4B4A4B9A2-10A10B9AC3-10A8B10A4-12A4B12A5-25AC6-26A7-24A9-C21A11-20A13-18A16-14A20-10A57-4A24-12A18-16A15-17AC12-2C20A9-24A8-24A7-26A5-28A4-12A4B12A3-11A8B11A2-C9A10B10A2-9A4B4A4B9A2-9A3B6A3B8AC-C2(8A3B)8AC9A2(3B8A3B18A)3B8A3B9A-9A3B6A3B9A2-9A4B4A4B9A2-10A10B10A2-11A8B10AC3-12A4B12A4-28A5-25AC7-24A8-24A9-C21A12-18A15-16A18-12A24-4A27-6A23-12A18-16A14-19AC11-22A9-C23A7-26A6-26A5-28A4-12A4B12A3-11A8B11A2-C9A10B10A2-9A4B4A4B9A-C9A3B6A3B19A3B8A3B9AC2(8A3B)8AC9A3B8A3B18A3B8A3B19A3B6A3B10A-9A4B4A4B9A2-10A10B10A2-11A8B11A3-12A4B12A4-27AC5-25AC6-26A7-C23A9-22A11-20A14-16A18-12A23-6A25-8A21-14A17-16A14-19AC11-22A9-24A7-C25A6-26A5-28A3-13A4B13A2-11A8B11A2-10A10B10A-C9A4B4A4B20A3B6A3B19A3B8A3B18A2(3B8A)2C2(8A3B)18A3B8A3B19A3B6A3B20A4B4A4B10A-10A10B10A2-11A8B11A2-13A4B12AC3-28A5-25AC6-C25A7-24A9-22A11-20A14-16A17-14A21-8A24-8A21-14A16-18A13-19AC11-22A9-24A7-26A5-C27A4-28A3-13A4B13A2-11A8B11A2-10A10B10A-C9A4B4A4B20A3B6A3B19A2(3B8A3B18A)2(3B8A)2C2(8A3B)19A3B6A3B20A4B4A4B10A-10A10B10A2-11A8B11A2-13A4B12AC3-28A4-28A5-C24AC7-24A9-22A11-20A13-18A16-14A21-8A24-8A21-14A16-18A13-20A11-21AC9-24A7-26A5-28A4-C27A3-13A4B13A2-11A8B11A2-10A10B10A-C9A4B4A4B20A3B6A3B19A2(3B8A3B18A)2(3B8A)2C2(8A3B)19A3B6A3B20A4B4A4B10A-10A10B10A2-11A8B11A2-13A4B12AC3-28A4-28A5-C24AC7-24A9-22A11-20A13-18A16-14A21-8A24-8A21-14A17-16A14-20A11-21AC9-24A7-26A6-26A5-28A3-C12A4B13A2-11A8B11A2-C9A10B10A-10A4B4A4B20A3B6A3B19A2(3B8A3B18A)2(3B8A)2C2(8A3B)19A3B6A3B20A4B4A4B10A-10A10B10A2-11A8B10AC2-13A4B13A3-28A5-C25A6-26A7-24A9-22A11-20A14-16A17-14A21-8A25-6A23-12A18-16A14-20A11-21AC9-23AC7-26A6-26A5-28A4-C11A4B12A3-11A8B11A2-C9A10B10A2-9A4B4A4B9A-10A3B6A3B19A3(3B8A3B18A)2(3B8A)2C9A3B6A3B10A-9A4B4A4B9A2-10A10B10A2-11A8B10AC3-12A4B12A4-C27A5-26A6-26A7-23AC9-22A11-20A14-16A18-12A23-6A27-4A24-12A18-16A15-18A12-22A9-24A8-23AC7-26A5-28A4-12A4B12A3-C10A8B11A2-10A10B10A2-9A4B4A4B9A2-9A3B6A3B9A-9A3(3B8A3B18A)2(3B8A)C-C8A3B6A3B9A2-9A4B4A4B9A2-10A10B9AC2-11A8B11A3-C11A4B12A4-28A5-26A7-23AC8-24A9-22A12-18A15-16A18-12A24-4A57-10A20-14A16-18A13-20A11-22A9-23AC7-26A6-26A5-12A4B12A4-10A8B10A3-C9A10B10A2-9A4B4A4B9A2-9A3B6A3B9A3(2-2(8A3B)8A)2-2(8A3B)7AC2-C8A3B6A3B9A2-9A4B4A4B9A2-10A10B9AC3-10A8B10A4-C11A4B12A5-26A6-26A7-23AC9-22A11-20A13-18A16-14A20-10A87-8A21-14A17-16A14-20A11-22A9-24A8-23AC7-26A5-12A4B12A4-10A8B10A4-C8A10B9A3-9A4B4A4B9A2-9A3B6A3B9A3(2-2(8A3B)8A)2-C7A3B8A3B7AC2-9A3B6A3B9A2-9A4B4A4B8AC3-9A10B9A4-C9A8B10A4-12A4B12A5-26A7-23AC8-24A9-22A11-20A14-16A17-14A21-8A90-4A24-12A18-16A15-18A13-20A11-22A9-24A7-25AC6-11A4B10AC5-10A8B9AC4-9A10B8AC4-C7A4B4A4B7AC4-8A3B6A3B8A3-3(2(8A3B)8A2-)C7A3B8A3B7AC3-8A3B6A3B7AC4-C7A4B4A4B8A4-C8A10B9A4-10A8B10A5-11A4B11A6-26A7-24A9-22A11-20A13-18A15-16A18-12A24-4A122-8A21-14A17-16A15-18A13-20A11-22A9-24A7-11A4B11A6-9A8B9A6-8A10B8A5-8A4B4A4B8A4-C7A3B6A3B7AC2(4-7A3B8A3B7A)4-7A3B8A3B6AC4-C6A3B8A3B7A4-C7A3B6A3B8A4-8A4B4A4B7AC5-8A10B8A6-9A8B9A6-11A4B11A7-23AC9-22A11-20A13-18A15-16A17-14A21-8A155-2A26-10A20-14A16-18A13-20A11-22A10-22A9-10A4B10A8-8A8B8A7-8A10B8A6-7A4B4A4B7A6-7A3B6A3B7A6-C5A3B8A3B5AC5-7A3B8A3B7A4-C6A3B8A3B6AC5-6A3B8A3B6A6-7A3B6A3B7A6-7A4B4A4B7A6-8A10B7AC7-8A8B7AC8-10A4B9AC9-22A10-22A11-20A13-18A16-14A20-10A26-2A188-6A23-12A19-14A16-18A13-20A12-20A11-9A4B9A9-8A8B8A8-7A10B7A8-6A4B4A4B6A7-7A3B6A3B7A6-6A3B8A3B6A6-C5A3B8A3B5AC6-C5A3B8A3B6A6-6A3B8A3B6A6-7A3B6A3B7A7-6A4B4A4B6A8-7A10B7A8-8A8B8A9-9A4B9A11-20A12-20A13-18A16-14A19-12A23-6A249-8A22-12A19-14A16-18A14-18A13-8A4B8A11-7A8B7A10-6A10B6A9-6A4B4A4B6A8-2(6A3B)6A8-5A3B8A3B5A8-C4A3B8A3B4AC2(8-5A3B8A3B5A)8-2(6A3B)6A8-6A4B4A4B6A9-6A10B6A10-7A8B7A11-8A4B8A13-18A14-18A16-14A19-12A22-8A312-8A22-12A19-14A17-16A15-7A4B7A13-6A8B6A12-5A10B5A11-5A4B4A4B5A10-5A3B6A3B5A10-4A3B8A3B4A10-C3A3B8A3B3AC2(10-4A3B8A3B4A)10-5A3B6A3B5A10-5A4B4A4B5A11-5A10B5A12-6A8B6A13-7A4B7A15-16A17-14A19-12A22-8A377-6A24-10A20-14A17-6A4B6A16-4A8B4A15-4A10B4A14-3A4B4A4B3A13-4A3B6A3B4A12-ACA3B8A3B3A12-C2A3B8A3B2AC2(12-3A3B8A3B3A)12-4A3B6A3B4A13-3A4B4A4B3A14-4A10B4A15-4A8B4A16-6A4B6A17-14A20-10A24-6A444-2A27-8A22-12A19-14A18-14A17-2(16A16-)C15A15-18A14-17AC15-15AC2(16-16A)17-14A18-14A19-12A22-8A27-2A541-4A26-8A23-10A21-12A20-12A19-14A18-3C11A18-11A2CA18-13AC19-12A20-12A21-10A23-8A26-4A700-4C27-6C25-3(8C24-)8C25-6C27-4C398-
