model
size = 28 32 32, scale = 0.05, origin = -y
material 
  colors = A:#F39 B:#EEE C:#BBB D:#FF0 E:#00E F:#9CF G:#FF9 H:#700 I:#C36 J:#002 K:#001
voxels
4-G2(27-F)8(923-F)123-D799-F95-D827-F66-3A25-K828-F11-A26-3A26-2A27-A810-2A14-F10-3AK25-2A26-A811-2A25-4A13-F11-2A27-A50-2D6-3D749-2A25-4A25-2A14-F11-A48-5D6-4D746-A-2A25-4A25-2A25-A2-A13-F9-A4-A15-7A6-6A689-2(D27-)D2A25-4A25-2A25-A2-A13-F9-A4-A16-6A6-6A692-D27-D25-2AD24-4A25-2A25-A2-A23-A4-A12-F4-5A6-5A135-D26-K611-4A25-2A25-A2-A23-A4-A18-4A6-4A8-F126-AD611-2A25-4A25-2A25-A2-A23-A4-A20-2A6-2A38-F98-3A25-3A27-A561-2H19-A27-A155-F43-A26-3A25-3A26-2A50-2D483-2B23-H3B18-2A5-3H18-A6-B176-F16-A26-2A25-3A27-A47-5D6-3D472-H3-C23-H-B18-A5-4B18-A5-3B192-A9-3F13-3A23-A-3A25-2A25-A20-7A6-4D470-HB3-C22-H2BC16-5A4-2BC24-3B2C26-2C162-A25-4A8-F-F13-3A25-A2-A23-A4-A16-6A6-4A295-2C173-HB3-C23-3C15-6A4-3C24-B3C25-4C131-D27-D2-A24-D-3A23-4A8-F3-F12-A2-A23-A4-A21-A6-4A297-C24-C-BC24-2C26-2C90-HB3-C23-C3(BC24-2C)B2C5-I19-B7-E2(27-G)E2(25-GEG)24-G2EG13-2A9-G4EG10-4A7-GE4JG11-2A7-GEJ5EG9-A2-A6-G7EG8-A4-A6-GEJ2EJG22-G3EG24-GEG26-G178-B27-2(2CB24-B)2CB25-C-B88-HB27-2CB24-B2CB6-I17-B2CB6-I18-2CBC26-B107-D27-D26-AD24-4A25-2A25-A2-A23-A4-A299-3B25-2(4B24-)2B-B88-2H26-3B8-I16-2(4B24-)4B25-3B161-A26-4A26-2(A28-)A299-3(4B24-)3B27-B17-I27-I15-2B10-I15-4B2(23-5B)23-6B23-4B25-B137-A26-2A26-A387-2B25-3B15-I28-I73-B25-4B24-4B23-5B23-B-4B22-B194-A27-A402-2I186-3B23-B-3B25-2B219-2A26-A429-I46-H27-3H357-4A203-
