model
size = 20 32 11, scale = 0.05, origin = -y
material 
  colors = A:#EEE B:#FFC C:#BBB D:#DCDCB0 E:#EAEAA2 F:#888 G:#DFDFA0 H:#777 I:#C9C982 J:#444 K:#0B0 L:#0A0 M:#222 N:#070 O:#800 P:#0C0 Q:#0E0 R:#603 S:#0F0 T:#4E0027 U:#606 V:#CF3 W:#FFF X:#AAA Y:#0F3 Z:#050 Aa:#555 Ab:#700 Ac:#040 Ad:#CC9
voxels
48-2(F17-F2-)F17-F35-2M18-2M5-R2U8-6M3-TRU8-6M3-2TR-2UR6-2M9-TRU6-2M9-2TR383-EG7BGE3BE5-E6BE5B-2B4-7BAE3B-B-2B3-5BAEGAE3B-B-2B2-6BAIBA4B-3B2-7BA10B2-BEBGE7BGE4B2-B2E2AE4BG2EIE3B2-2BI2AIE3B3AGE3B2-B6A3B3AGI2EB2-B6A3B2(3AB)2-2BE2A2E7B3AB2-3B2AE8B3CB2(2-18B)2-3B11E4B2-BGE10-EG3B2-BE12-E3B2-BE13-EG6(B2-BE14-E)B2-BE14-2B2-2B14-BE2-E2B12-BEI2-G7BGE5BEBE2-EDE6BEDGE4BD22-GB-12B-2B2-G13BG5-B12CDCB4-B6CA4CDADCB3-B4CA2CA4CDADCB2-B5CA2CA4CD2CB2-B6CA9CB2-B16CB2-B2C2A12CB2-B2C2A5C3A4C2(B2-B6A3C3AC3A)B2-B2C2A9C3AB2-B2C2A12C3(B2-B16C)B2-B2C10F4CB2-BC12F3CB2-BC2F10-F2C5(B2-BC2F10-2FC)B2-BCAbF2(10-2FCB2-BC2F)10-2FCB2-B2C12F2CB2-B16CB2-E16CE3-16D3-18B2-10BG4B5-B14AB4-B15AB3-14(B16AB2-)B16AG2-B3AYQA6SY3AE2-B3A3QW6K3AB2-B3A2L8K3AB2-B3AN3LNANLKL3AB2-B4A3PX5P3AB2-B3AN2(XL)KLKZN3AB2-B3A2KW7L3AE2-B3ANZW3N2KLQ3AG2-B3AAcA2N2L2N2Q3AD3(2-B16AB)3-D14AD3-BIEBEG12B2-E8BEI4B5-B14AE4-B15AE3-14(B16AB2-)B16AG2-B17AJ-E17AJ-I2(17AJ-B)16AD2-B16AG2-2(B15AJ3-)B4AC10AJ3-2(B16AB2-)B16AB3-DC13AD3-E2-2AaE12B2-8B2-EBG2B5-B7A2J5AB4-B15AG3-B16AG6(2-D16AD2-B16AB)2-B16AB2-B16AE2-B16AD2-G16AB-J17AI-J17AG-J17AE2-B16AG2-2(B15AJ3-)B4AC10AJ3-3(B16AB2-)E16AB2-G3EBI12B2-8B2-IBG2B5-B7A2J5AB4-B15AB3-6(B16AB2-D16AD2-)5(B16AB2-)E16AB2-B16AG2-I16AB2-D16AB2-B16AB2-E16AB2-I16AB2-B16AB2-E2(16AB2-B)16AB2-18B2-15B5-B14AB4-B15AB3-6(B16AB2-D16AD2-)9(B16AB2-)B3AB8AB3AB2-E3A2(B8AB3AB3-J2A)B8CB3AB2-D2(3AB8CB3AB2-B)3AB8CB3AB2-GBE15B2-14BG5-B14AB4-B15AB3-6(B16AB2-D16AD2-)B16AB2-BJ14AJ6(B2-B16A)B2-B3AD8AD3AB2-B2AB-H6CH-B2AB2-G2A2(B-H6CH-B2AB3-JA)B-H6CH-B2AB2-GJAB-H6CH-BAJB2-B2AB-H6CH-B2AB2-B2AB-8H-B2AB2-IE2B10-4B2-EIG10BEG5-11BE4B4-2BI12A2B3-2B14A2B2-2D14A2D2-2B14AEB2-2D14A2D2-IE14A2B2-2D14A2D2-BG14AEB2-2D14A2D2-2B14AEB2-2D14A2D2-GE14A2B2-2D14A2D2-2B14AEB2-B-Ad12AB-B2-2B14AIB2-2B14AGB2-BE14A2G2-BI14AEB2-BE14AIB2-BG14A2B2-BE2AD8AD2A2B2-BE2(AB-H6CH-BA2B2-2B)EB-H6CH-4B2-3BD-HO4VOH-EG2B2-B-2B-H6OH-ID-B2(2-4B-8H-4B)2-E3B10-4B45-E4BEG5B7-2(14B6-14D6-)13BE6-14D6-E12BI6-14D6-IE12B2(6-14D6-14B)6-13BE2(6-13BG)6-G12BE6-14B6-I13B2(6-14B)6-E13B6-E8BED3B7-DGIE6BGB104-
