model
size = 21 26 30, scale = 0.05, origin = -y
material 
  colors = A:#F93 B:#FC0 C:#AAA D:#06C
voxels
--------------------- --------------------- --------------------- --------------------- --------------------- --------------------- --------------------- --------------------- --------------------- --------------------- --------------------- --------------------- --------------------- --------------------- --------------------- --------------------- --------------------- ----------BBB-------- ----------BBBBB------ -----------BBB------- --------------------- --------------------- --------------------- --------------------- --------------------- --------------------- 
--------------------- --------------------- --------------------- --------------------- --------------------- --------------------- --------------------- --------------------- --------------------- --------------------- --------------------- --------------------- --------------------- --------------------- --------------------- --------------------- --------------------- ----------BB--------- ---------BAABBB------ ---------BBAAAB------ ----------BBBB------- --------------------- --------------------- --------------------- --------------------- --------------------- 
--------------------- --------------------- --------------------- --------------------- --------------------- --------------------- --------------------- --------------------- --------------------- --------------------- --------------------- --------------------- --------------------- --------------------- --------------------- --------------------- --------------------- --------------------- --------BBBBBBBB----- --------BA----AB----- ---------BBAABB------ -----------BB-------- --------------------- --------------------- --------------------- --------------------- 
--------------------- --------------------- --------------------- --------------------- --------------------- --------------------- --------------------- --------------------- --------------------- --------------------- --------------------- ----------AA--------- --------------------- --------------------- --------------------- --------------------- --------------------- --------------------- -------BBBBBBBBB----- -------BA-----AAB---- --------BAAA-AABB---- ---------BBAABB------ -----------BB-------- --------------------- --------------------- --------------------- 
--------------------- --------------------- --------------------- --------------------- --------------------- --------------------- --------------------- ---------AAAA-------- ---------A--A-------- ----------AA--------- --------------------- ----------AA--------- ----------AA--------- --------------------- --------------------- --------------------- --------------------- --------------------- -------------B------- ------BBBBBBBBBBB---- ------BB-------AAB--- -----BB-B----AABB---- ------BBBBBAABBB----- --------BBBBBB------- --------------------- --------------------- 
--------------------- --------------------- --------------------- --------------------- --------------------- ----------AA--------- ---------AAAA-------- ---------AAAA-------- --------AAAAAA------- ---------AAAA-------- ---------AAAA-------- ----------AA--------- ---------AAAA-------- ---------A--A-------- --------------------- --------------------- --------------------- --------------------- ----------BB--------- ------BBBBBBBBBBB---- -----B-----------B--- -----BA--------AAB--- -----BAAB----BBBB---- ------BBBBBBBBB------ --------------------- --------------------- 
--------------------- --------------------- --------------------- --------------------- ----------AA--------- ---------AAAA-------- --------AAAAAA------- --------AAAAAA------- --------AAAAAA------- --------AAAAAA------- --------AAAAAA------- ---------AAAA-------- --------AAAAAA------- ---------AAAA-------- ---------CAAC-------- ---------AAAA-------- ---------AAAA-------- ---------A--AA------- --------AAAAA-------- -----BBBBBBBBBBBB---- -----B-----------BB-- -----B----------AB--- -----BA-------AAB---- -----BBBBB--BBBBB---- ----------BB--------- --------------------- 
--------------------- --------------------- --------------------- --------------------- ---------AAAA-------- --------AAAAAA------- -------AAAAAAAA------ -------AAAAAAAA------ -------AAAAAAAA------ -------AAAAAAAA------ -------AAAAAAAA------ -------AAAAAAAA------ -------AAAAAAAA------ -------AAAAAAAA------ ------CDCAAAACDC----- -------BBAAAABB------ -------AAAAAAAA------ -------AAAAAAAA------ -------AAAAAAAA------ -----BBBBBBBBBBBB---- ----B---A--A-----BB-- ----B------------AB-- ----BA----------AB--- -----BBB-----BBBB---- --------BBBBB-------- --------------------- 
--------------------- --------------------- ----------AA--------- ---------AAAA-------- -------AAAAAAAA------ ------AAAAAAAAAA----- -----AAAAAAAAAAAA---- -----AAAAAAAAAAAA---- -----AAAAAAAAAAAA---- -----AAAAAAAAAAAA---- -----AAAAAAAAAAAA---- -----AAAAAAAAAAAA---- -----AAAAAAAAAAAA---- -----AAAAAAAAAAAA---- -----CAAAAAAAAAAC---- -----AAAAAAAAAAAA---- -----BBAAAAAAAABB---- -----AAAAAAAAAAAA---- -----AAAAAAAAAAAA---- -----BA--AAAAAAAB---- ---BB-BBBBBBBBBB-BB-- ---BA--BBBBBBBB--AB-- ---BA---BBBBBB---AB-- ---BB----------BBB--- -----BBBBBBBBBB------ --------------------- 
--------------------- --------------------- ---------AAAA-------- --------AAAAAA------- ------AAAAAAAAAA----- -----AAAAAAAAAAAA---- -----AAAAAAAAAAAA---- -----AAAAAAAAAAAA---- -----AAAAAAAAAAAA---- -----AAAAAAAAAAAA---- -----AAAAAAAAAAAA---- -----AAAAAAAAAAAA---- -----AAAAAAAAAAAA---- -----AAAAAAAAAAAA---- -----AAAAAAAAAAAA---- -----AAAAAAAAAA-A---- -----AAAAAAAAAAAA---- -----AAAAAAAAAAAA---- -----AAAAAAAAAAAA---- -----AA--AAAAAAAA---- ---BBAAA------AAABB-- --BA--AAA----AAB--AB- --BA---AAAAAAAA--AB-- --BBA----BBBB---BB--- ----BBABBBBBBBBB----- ------BBBBB---------- 
--------------------- ----------AA--------- ---------AAAA-------- -------AAA--AAA------ -----AAAAAAAAAAAA---- -----AAAAAAAAAAAA---- -----AAAAAAAAAAAA---- -----AAAAAAAAAAAA---- ----AAAAAAAAAAAAAA--- ----AAAAAAAAAAAAAA--- ----AAAAAAAAAAAAAA--- ----AAAAAAAAAAAAAA--- ----AAAAAAAAAAAAAA--- ----AAAAAAAAAAAAAA--- ----AAAAAAAAAAAAAA--- -----AAAAAAAAAA-A---- -----AAAAAAAAAAAA---- -----AAAAAAAAAAAA---- -----AAAAAAAAAAAA---- -----AA--AAAAAAAA---- ---B-AA-------AAABB-- --BA-AAA------AAA-AB- --B---AAAA--AAAA-AAB- --BB----BBBBBA---BB-- ----BAA---BBBBBBB---- -----BBBBBBBB-------- 
-----------A--------- ---------AAAA-------- --------AAAAAA------- ------AAAA--AAAA----- -----AAAAAAAAAAAA---- -----AAAAAAAAAAAA---- ----AAAAAAAAAAAAAA--- ----AAAAAAAAAAAAAA--- ----AAAAAAAAAAAAAA--- ----AAAAAAAAAAAAAA--- ----AAAAAAAAAAAAAA--- ----AAAAAAAAAAAAAA--- ----AAAAAAAAAAAAAA--- ----AAAAAAAAAAAAAA--- ----AAAAAAAAAAAAAA--- ----AAAAAAAAAAA-AA--- ----AAAAAAAAAAAAAA--- ----AAAAAAAAAAAAAA--- -----AAAAAAAAAAAA---- ---BAAA--AAAAAAAA---- --BA-AA-------AAABB-- --BA-AA-------AAA-AB- --B--AAAA----AAAA-AB- --BB---BBBBBBAA--BB-- ----BAA-----BABBB---- -----BBBBBBBBB------- 
----------AA--------- --------AAAAAA------- ------AAAAAAAAAA----- -----AAAAA--AAAAA---- -----AAAAAAAAAAAA---- ----AAAAAAAAAAAAAA--- ----AAAAAAAAAAAAAA--- ----AAAAAAAAAAAAAA--- ---AAAAAAAAAAAAAAAA-- ---AAAAAAAAAAAAAAAA-- ---AAAAAAAAAAAAAAAA-- ---AAAAAAAAAAAAAAAA-- ---AAAAAAAAAAAAAAAA-- ---AAAAAAAAAAAAAAAA-- ---AAAAAAAAAAAAAAAA-- ---AAAAAAAAAAAAAAAA-- ----AAAAAAAAAAAAAAAA- ---AAAAAAAAAAAAAAAAAB --BAAAAAAAAAAAAAAAAAB --BAAAAAAAAAAAAAABBBB --B--A---------AAAB-- --B--A----------A-ABB --B--AA--------AA--AB -BBB--ABBB--BAAA--BB- ----BBA-------ABBB--- ------BBBBBBBBB------ 
---------A-AAA------- -------AA--AAA------- ------AAA--AAAAA----- -----AA-----AAAAA---- ----AA------AAAAAA--- ----AA------AAAAAA--- ----AA------AAAAAA--- ---AAA------AAAAAAA-- ---AAA------AAAAAAA-- ---AAA------AAAAAAA-- ---AAA------AAAAAAA-- ---AAA------AAAAAAA-- ---AAA------AAAAAAA-- ---AAA------AAAAAAA-- ---AAAAAAAAAAAAAAAA-- ---AAAAAAAAAAAAAAAAB- --BAAAAAAAAAAAAA-AAAB --BAAAAAAAAAAA---B-AB --BAAAAAAAAAA----B--B --B-B-----BB-----B-BB --B--------------AB-- --B--A----------AAAB- -BA--AA--------AA-AAB -BB---ABB----AAA-ABB- ----BBA------AABBB--- ------BBBBBBBBB------ 
--------AAAAAAA------ -------AAAAAAAA------ -----AAAAAAAAAAA----- -----AAAAAAAAAAAA---- ----AAAAAAAAAAAAAA--- ----AAAAAAAAAAAAAA--- ----AAAAAAAAAAAAAA--- ---AAAAAAAAAAAAAAAA-- ---AAAAAAAAAAAAAAAA-- ---AAAAAAAAAAAAAAAA-- ---BAAAAAAAAAAAAAAA-- ---AAAAAAAAAAAAAAAAB- ---AAAAAAAAAAAAAAAA-- ---AAAAAAAAAAAAAAAA-- ---AAAAAAAAAAAAAAAAB- ---AAAAAAAAAAAAAA-AB- --BAAAAAAAAAAA---AB-B --B-BBBBBBBBB----B--B -BA-B-----BB-----B--B -BA-B------------B-B- -BA--------------AB-- --B--A----------AAAB- -BA--AA--------AA-AB- -BB---ABB----AAA-BB-- ---BBBA------ABBB---- ------BBBBBBBB------- 
--------AAAAAA------- -------AAAAAAAA------ -----AAAAAAAAAA------ -----AAAAAAAAAAAA---- ----AAAAAAAAAAAAAA--- ----AAAAAAAAAAAAAA--- ----AAAAAAAAAAAAAA--- ---AAAAAAAAAAAAAAAA-- ---AAAAAAAAAAAAAAAA-- ---AAAAAAAAAAAAAAAA-- --BAAAAAAAAAAAAAAAAB- --BAAAAAAAAAAAAAAAAB- --BAAAAAAAAAAAAAAAAB- --BAAAAAAAAAAAAAAAAB- ---AAAAAAAAAAAAAAAAB- --BAAAAAAAAAAAA---AAB --BAAAAAAAAAA----AB-B -BABA------------AB-B -BA-B------------B--B -B--B------------B--- -BA--------------AB-- -BA--A----------AAB-- -BA--AA--------AAAAB- -BB---ABB----AAA-BB-- ---BBBA------ABBB---- ------BBBBBBBB------- 
---------AAAAAA------ ------AAAAAAAAAA----- ------AAAAAAAAAAA---- -----AAAAAAAAAAAA---- -----AAAAAAAAAAAAA--- ----AAAAAAAAAAAAAA--- ----AAAAAAAAAAAAAA--- ---AAAAAAAAAAAAAAAA-- ---AAAAAAAAAAAAAAAA-- ---AAAAAAAAAAAAAAAA-- --BAAAAAAAAAAAAAAAAB- --B-AAAAAAAAAAAAAAAB- --B-AAAAAAAAAAAAAAAB- --BAAAAAAAAAAAAAAAAB- -BAAAAAAAAAAAAAA--AAB -BAA---AAAAAA-----AAB -BAA-----AA-------B-B -BBBA------------AB-B -B--B------------B--B -B--B------------B--B -B---A----------AABBB -B---A----------AB--- -B---AAA------AAAAB-- -BB----BBB--BAA-AB--- ---BBBA-----BBBBB---- ------BBBBBBB-------- 
----------AAAAA------ --------AAAAAAAA----- ------AAAAAAAAAAA---- -----AAAAAAAAAAAAA--- ----AAAAAAAAAAAAAA--- ----AAAAAAAAAAAAAA--- ----AAAAAAAAAAAAAA--- ---AAAAAAAAAAAAAAAA-- ---AAAAAAAAAAAAAAAA-- ---AAAAAAAAAAAAAAAA-- ---AAAAAAAAAAAAAAAAB- --BAAAAAAAAAAAAAAAAB- --BAAAAAAAAAAAAAAAAB- --BAAAAAAAAAAAAAA-AAB --BA---AAAAAAA----AAB -B-A-----A--------B-B -BAAA------------AB-B -B-BA------------AB-B BB--B------------B--B BB--B------------B--- -B---A----------AAABB -B---A----------AAB-- -B---AAA------AAAB--- -BB----BBB--BAA-BB--- ---BBBA-----BBBB----- ------BBBBBBB-------- 
---------AAAAA------- ---------AAAAAAA----- -------AAAAAAAAAA---- -----AAAAAAAAAAAAA--- ----AAAAAAAAAAAAAA--- ----AAAAAAAAAAAAAA--- ----AAAAAAAAAAAAAA--- ----AAAAAAAAAAAAAA--- ---AAAAAAAAAAAAAAAA-- ---AAAAAAAAAAAAAAAA-- ---AAAAAAAAAAAAAAAA-- ---AAAAAAAAAAAAAAAA-- -BAAAAAAAAAAAAAAAAAB- -BAA--AAAAAAAAAAA-AAB --BA-----AAAA-----B-B -B-AA------------AB-B -BAAA------------AB-B -B--B------------B--B BB--B------------B--B BB--B------------B--B BB---A----------A-AAB -B---A----------AABB- -B---AAA------AAAB--- -BB----BBB--BAA-B---- ---BBBA-----BBBB----- ------BBBBBBB-------- 
----------AAA-------- ---------AAAAAAA----- ------AAAAAAAAAAA---- -----AAAAAAAAAAAAA--- ---AAAAAAAAAAAAAAA--- ---AAAAAAAAAAAAAAAA-- ----AAAAAAAAAAAAAA--- ----AAAAAAAAAAAAAA--- ----AAAAAAAAAAAAAAA-- ---AAAAAAAAAAAAAAAA-- ---AAAAAAAAAAAAAAAA-- ---AAAAAAAAAAAAAAAAB- -BAAAAAAAAAAAAAAAAAAB --BAA---AAAAAA---AAAB --BAA------------AB-B -B-AA------------AB-B -B--B------------B--B -B--B------------B--B -B--B------------B--B BB------------------B -B---B----------A--AB -B---AA--------AABBBB -BA--AAAA----AAAAB--- -BBA---AAAAAAABBB---- ---BBBBBAAAABBB------ ------BBBBBBB-------- 
--------------------- ---------AAAAAA------ ------AAAAAAAAAAA---- ----AAAAAAAAAAAAA---- ---AAAAAAAAAAAAAAA--- ---AAAAAAAAAAAAAAAA-- ---AAAAAAAAAAAAAAA--- ----AAAAAAAAAAAAAA--- ----AAAAAAAAAAAAAAA-- ---AAAAAAAAAAAAAAAA-- --AAAAAAAAAAAAAAAAA-- -BAAAAAAAAAAAAAAAAAAB -B--B----BBBBB---B-BB -B--B------------B--B -B--B------------B--B -B--B------------B--B -B--B------------B-B- -B-----------------AB -B---A----------B--AB -B---BAA------BBB--B- -BA--AAAAA--AABBABBB- -BAA----AAAAAA-BB---- --BAA----AAAAABBB---- ---BBBBB--AABB------- --------BBBB--------- --------------------- 
--------------------- ----------AAAAA------ -------AAAAAAAAAA---- -----AAAAAAAAAAAA---- ----AAAAAAAAAAAAAAA-- ----AAAAAAAAAAAAAA--- ---AAAAAAAAAAAAAAA--- ---AAAAAAAAAAAAAAA--- ----AAAAAAAAAAAAAAAA- ---AAAAAAAAAAAAAAAAA- -BAAAAAAAAAAAAAAAAAA- -BA-B-BBBAAAABBBBBBB- -B--B------------B--B -B--B------------B--B -B--B------------B-BB -B-----------------AB -B-----------------B- -B---A----------B--B- -BA--AAA------BBB-BB- -BA--AAAA----BBBBBBB- -BAA----AAAAAB-BAB--- --BAA---AAAAABBBB---- ---BBA----AAABBB----- -----BBBBBBBB-------- --------------------- --------------------- 
--------------------- -----------AAA------- ---------AAAAAAA----- ------AAAAAAAAAA----- ----AAAAAAAAAAAAAAA-- -----AAAAAAAAAAAAA--- ---AAAAAAAAAAAAAAA--- ---AAAAAAAAAAAAAAAA-- ---AAAAAAAAAAAAAAAAA- --AAAAAAAAAAAAAAAAAA- --AA--AAAAAAAAAAAAAB- -BA----AAAAAAAAABB-AB -BA----------------AB -BA--A----------B--AB -BA--A----------B--AB -BA--A--AAAA----B--B- -BA--AA-AAAA---AB-BB- -BA--AAA------AAB-BB- -BA--AAAA----BAABBBB- --B----AAA--ABA--BB-- --BAA---AAAAA-AAB---- ---BBA----AA-BBB----- -----BAAAAAAAB------- -----BBBBBBBB-------- --------------------- --------------------- 
--------------------- -----------A--------- ---------AAAAA------- --------AAAAAAAA----- ------AAAAAAAAAAAA--- -----AAAAAAAAAAAA---- ----AAAAAAAAAAAAAA--- ---AAAAAAAAAAAAAAAA-- --AAAAAAAAAAAAAAAAAA- --AA-AAAAAAAAAAAAAAB- --BA-AAAAAAAAAAAAAAB- --BB-A--AAAAAAAAB--AB --BB-B--A--A----B--BB --BBBAA-A--A---AB--B- --BBBAA--AA----AB-BB- --BBBAA--------AB-BB- --BB-AAAA----AAABBB-- --BB--AA-AA--AAA-BB-- --BB---AAA-AAAA--BB-- --BB----AAAAAA--BB--- ---BBA----AA-ABB----- -----BAA--AAABB------ -----BBBBBBBB-------- --------------------- --------------------- --------------------- 
--------------------- --------------------- ------------A-------- -------A------------- -------AA----AAA----- ---------AAAAAAAA---- -----AAAAAAAAAAAAA--- ---AAAAAAAAAAAAAAAA-- --BA-AAAAAAAAAAAAAAA- --BBA-BAAAAAAAAAAAAB- ---BA-AAAAAAAAABB--AB ----BAAAA----ABB-ABB- ----BA-AAAAAAAB--BB-- -----B-AAAAAAAA-AB--- ---BBB-AAAAAAAA-AB--- -----B-AAAAAAAAAAB--- ----BA---A--A-AAB---- ----BAA-------ABB---- ----BBA------AABB---- ----BBAA-----ABB----- -----BBBBBBBAB------- ------BBBBBBB-------- --------------------- --------------------- --------------------- --------------------- 
--------------------- --------------------- --------------------- --------------------- --------------A------ -------------AAA----- --------A----AAAA---- -----AAAA----AAAA---- ---BAAAAA----AAAAAAA- ----B--AAAAAAAAAAAAB- ----BA--ABAAAAB---BB- ----BAA-AAAAAB---B--- -----BAAAAAAAA-AB---- -----BBAAA--AAAAB---- -----BAA------ABB---- -----BAA-----AABB---- -----BBAA----ABB----- -----BBBAAAAABB------ ------BBBBBBABB------ ------BBBBBBBB------- ------------B-------- --------------------- --------------------- --------------------- --------------------- --------------------- 
--------------------- --------------------- --------------------- --------------------- --------------------- --------------------- -----------AA-------- ------AAAAAAAAA------ ------AAAAAAAA-AA---- ------BAAAAABABBAABB- -----BA---------BBB-- -----BAA---------B--- ------BBA----AABB---- -------BA----ABB----- ------BBAA---AB------ ------BBBAAAABB------ -------BBBBBBB------- --------BBBBB-------- ------------B-------- --------------------- --------------------- --------------------- --------------------- --------------------- --------------------- --------------------- 
--------------------- --------------------- --------------------- --------------------- --------------------- --------------------- --------------------- --------AAAA--------- -------A--A-A-------- ------BAAAAABBBBBB--- -----BA-------BBB---- ------BB-------B-B--- --------BBBAABB--B--- --------BBBBBB------- --------BBBBBB------- ---------BBBB-------- --------------------- --------------------- --------------------- --------------------- --------------------- --------------------- --------------------- --------------------- --------------------- --------------------- 
--------------------- --------------------- --------------------- --------------------- --------------------- --------------------- --------------------- --------------------- --------------------- ------BBBBBBB-------- ------BBAAAAABBB----- -------BBB---BBBB---- ----------BBB-------- --------------------- --------------------- --------------------- --------------------- --------------------- --------------------- --------------------- --------------------- --------------------- --------------------- --------------------- --------------------- --------------------- 
--------------------- --------------------- --------------------- --------------------- --------------------- --------------------- --------------------- --------------------- --------------------- --------------------- --------BBBBBB------- ---------BBBBBB------ --------------------- --------------------- --------------------- --------------------- --------------------- --------------------- --------------------- --------------------- --------------------- --------------------- --------------------- --------------------- --------------------- --------------------- 
