model
size = 32 31 25, scale = 0.05, origin = -y
material 
  colors = A:#E00 B:#001 C:#EEE D:#555 E:#0E0
voxels
264-5C5-5C16-3CA3C3-3CA3C15-2C3A2C3-2C3A2C14-2C5A2C-2CAC3A2C2(13-C7AC-C7AC)13-CAC5AC-C5ACAC13-2C2AC2A2C-2C2AC2A2C14-7C3-7C15-7C3-7C16-5C5-5C530-14A18-14B15-20B12-20B11-3B5C5B5C4B9-2(2(3B7C)4B8-)5(2B9CB9C3B8-)2(2(3B7C)4B8-)4B5C5B5C2BA2B8-20BA3B8-3BA14B2A4B9-3B2A17B11-20B17-10A372-15A15-2A14-2A13-2A16-2A11-A-A16-A-A9-6A12-6A8-24A8-AD20-DA8-A22-A7-8(A24-A6-)A24-A7-A22-A8-2A20-2A10-20A16-12A337-18A12-22A9-24A2(8-AB20ABA)7-2AB20AB2A6-A11D2-11DA6-A2D8-4D8-2DA6-A2D9-2B9-2D7(A6-AD22-D)A6-A2D3-D12-D3-2DA6-2A2D-3D10-3D-2D2A7-2A20D2A9-22A14-14A21-8A305-4A-12A-4A9-24A8-24A7-2(2AB20AB2A6-)2AB8A-2A-8AB2A6-2ABD8B2-8BDB2A6-2A2B18-2B2A6-2AB3-C12-C3-B2A2(6-AB4-2C10-2C4-BA)2(6-AB4-3C8-3C4-BA)6-AB3-3C10-3C3-BA6-AB4-2C10-2C4-BA6-AB22-BA2(6-2AB20-B2A)6-3A20-3A7-2A20D2A10-4AB10AB4A17-B8AB23-8A272-8A-6A-8A7-3A2B16A2B3A3(6-2AB20AB2A)6-2AB3A6-2B6-3AB2A5-3ABD8B2-8BDB3A4-3A2B18-2B3A4-2A2B3-2C10-2C3-2B2A4-3AB2-4C8-4C2-B3A4-3AB3-3C8-3C3-3(B3A4-3AB2-4C8-4C2-)B3A4-3AB2-3C10-3C2-B3A5-2AB3-C12-C3-B2A6-A2B20-2BA6-2AB20-B2A6-3A2B16-2B3A7-4A16B4A10-3AB12AB3A16-E10AE21-B8AB23-8A239-9A-6A-9A3(6-26A)6-3AB18AB3A5-3A2(2B8-)2B3A4-3ABD8B2-8BDB3A3-A-2A2B2-2C10-2C2-2B2A-A2-A-2AB2-4C8-4C2-B2A-A2-4AB2-4C8-4C2-B4A3-3AB-6C6-6C-B3A3-4AB-6C6-6C2(-B4A2-4AB-5C8-5C)-B4A3-3AB2-3C10-3C2-B3A4-3AB3-2C10-2C3-B3A5-2(2AB20-B2A6-)3A2B16-2B3A6-5A16B5A8-22A13-BE12AEB18-E10AE21-B8AB25-4A209-3(26A6-)26A5-4AB18AB4A4-3A2(2B8-)2B3A5-2ABD8B2-8BDB2A3-A2-2A2B2-2C10-2C2-2B2A2-2A-3AB2-4C8-4C2-B3A-6AB2-5C6-5C2-3(B10AB-6C6-6C-)B5A-4AB-6C6-6C-B4A2-4AB2-3C10-3C2-B4A3-3AB3-2C10-2C3-B3A4-3AB20-B3A5-2AB20-B2A6-A-A2B16-2BA-A6-A2-2A16B2A2-A7-2A-18A-2A12-16A17-B12AB19-2B8A2B22-8A89-2(6A26-)6A25-8A15-8A10-8A6-26A6-4A-16A-4A6-3A-18A-3A5-3A-B18AB-3A3-2(A-)2(2B8-)2B3(-A)2-2AB-8B2-8B-B2(2A2-)2A2B-4C8-4C-2B2A2-2A-3AB2-4C8-4C2-B3A-6A3(B-6C6-6C-B10A)B-5C8-5C-B10AB-6C6-6C-B5A-4AB2-4C8-4C2-B4A2-4AB3-C12-C3-B4A3-3AB20-B3A5-2AB20-B2A6-3A2B16-2B3A6-5A16B5A7-24A10-20A13-18A15-16A18-12A21-10A55-3(8A24-)8A15-8A10-8A6-26A6-3A2-16A2-3A6-2A-20A-2A5-4AB18AB4A3-2(A-)2(2B8-)2B3(-A)2-2ABD8B2-8BDB2(2A2-)2A2B-3C10-3C-2B2A2-2A-3AB2-5C6-5C2-B3A-6AB2-5C6-5C2-4(B10AB-6C6-6C-)B5A-4AB20-B4A2-4AB2-4B8-4B2-B4A3-3AB2-3B10-3B2-B3A5-2AB20-B2A6-3A2B16-2B3A6-5A16B5A7-24A9-22A11-20A14-16A17-14A20-10A24-6A25-3(8A24-)8A15-8A10-8A6-4A-16A-4A6-3A-18A-3A6-2A-20A-2A5-2A-AB18ABA-2A3-A-2A2(2B8-)2B2A-A2-A-2A10B2-10B2A2(-A)2-2A2B18-2B2A2-2A-3AB20-B3A-6A2(B2-4B8-4B2-B10A)B-6B6-6B-B10AB2-5B6-5B2-B10AB-6B6-6B-B5A-4AB2-4B8-4B2-B4A2-4AB2-3B10-3B2-B4A3-3AB2-3B10-3B2-B3A5-2AB20-B2A6-3A2(2B7-)2B3A6-5A16B5A7-24A9-22A11-20A13-18A16-14A20-10A23-4(8A24-)8A15-6AB12-B6A6-4A-16A-4A6-3A-18A-3A6-2A-10AB9A-2A5-2A-AB18ABA-2A4-3A2(2B8-)2B3A3-2(A-2AB20-B2A-A2-)4AB20-6(B4A2-4AB2-4B8-4B2-)B4A3-3AB2-3B10-3B2-B3A4-3AB20-B3A5-2AB20-B2A6-3A2(2B7-)2B3A6-5A8BA7B5A7-24A9-22A11-20A13-18A16-14A19-12A22-4(8A24-)8A16-6A12-6A8-3A3-12A3-3A7-3A-18A-3A6-2A-20A-2A6-A-22A-A5-28A4-4A20B4A3-2(A-3A20B3A-A2-)5A20B5A2-5A2B3-10B3-2B5A2-5A5B-8B-5B2(5A2-5A20B)5A3-4A20B4A4-3A22B3A5-2(2A22B2A6-)5A8BA7B5A6-5A7B2A7B5A7-24A9-22A11-20A13-18A15-16A18-12A22-4(8A24-)8A17-5A12-5A9-3A3-12A3-3A8-2A-18A-2A7-2A-20A-2A6-A-22A-A6-26A5-8(28A4-)28A5-4(26A6-)26A7-24A9-22A11-20A13-18A15-16A18-12A22-8A25-3(6A26-)6A18-5A12-5A9-3A3-12A3-3A8-2A-18A-2A8-A-20A-A7-A-22A-A14(6-26A)7-24A8-24A9-22A11-20A13-18A16-14A19-12A22-8A146-2(5A10-)3A4-10A4-3A8-2A-18A-2A8-A-20A-A3(8-24A)7-11(26A6-)26A7-24A8-24A9-22A11-20A13-18A16-14A20-10A23-8A147-4A10-4A13-2A3-10A3-2A10-3A-16A-3A8-2A-18A-2A8-A-20A-A3(8-24A)7-9(26A6-)26A7-2(24A8-)24A10-20A13-18A15-16A18-12A21-10A179-5A6-5A15-2A4-6A4-2A12-3A-14A-3A10-2A-16A-2A9-2A-18A-2A8-A-20A-A3(8-24A)7-26A7-24A7-5(26A6-)26A7-24A7-26A8-22A11-20A13-18A15-16A17-14A20-10A24-6A182-14A17-2A12-2A15-2A-12A-2A13-2A-14A-2A11-2A-16A-2A9-2A-18A-2A8-A-20A-A9-22A9-2(24A8-)24A7-3(26A6-)26A7-2(24A8-)24A9-22A11-20A13-18A15-16A17-14A19-12A22-8A279-10A21-12A18-16A15-18A13-20A12-20A11-22A9-8(24A8-)24A10-20A12-20A13-18A15-16A18-12A21-10A25-4A282-8A23-10A21-12A18-16A15-18A14-18A13-20A11-22A9-5(24A8-)24A9-22A10-22A12-18A14-18A15-16A18-12A21-10A23-8A344-8A23-10A21-12A18-16A16-16A15-18A13-20A11-6(22A10-)22A11-20A14-16A16-16A18-12A21-10A23-8A408-8A23-10A21-12A19-14A17-16A15-18A13-6(20A12-)20A13-18A16-14A19-12A21-10A23-8A472-8A23-10A21-12A19-14A17-16A15-5(18A14-)18A15-16A16-16A18-12A21-10A23-8A601-6A24-10A22-10A21-3(12A20-)12A21-2(10A22-)10A299-
