model
size = 30 15 30, scale = 0.05, origin = -y
material 
  colors = A:#6A4028
voxels
----------AAA------AA--------- -------------------AA--------- ------------------------------ ------------------------------ ------------------------------ ------------------------------ ------------------------------ ------------------------------ ------------------------------ ------------------------------ ------------------------------ ------------------------------ ------------------------------ ------------------------------ ------------------------------ 
A------A--AA------AAAAA------- ------------------AAAAA------- -------------------AA--------- ------------------------------ ------------------------------ ------------------------------ ------------------------------ ------------------------------ ------------------------------ ------------------------------ ------------------------------ ------------------------------ ------------------------------ ------------------------------ ------------------------------ 
------AA----------AAAAAA------ ------------------AAAAAA------ -------------------AAAA------- ------------------------------ ------------------------------ ------------------------------ ------------------------------ ------------------------------ ------------------------------ ------------------------------ ------------------------------ ------------------------------ ------------------------------ ------------------------------ ------------------------------ 
----AA-------AA----AAAAA--A--- ----A--------AA----AAAAA------ --------------------AAA------- --------------------AA-------- ------------------------------ ------------------------------ ------------------------------ ------------------------------ ------------------------------ ------------------------------ ------------------------------ ------------------------------ ------------------------------ ------------------------------ ------------------------------ 
---A-A---AAAAAAA---AAAA--A---- ----A----AA-AAA----AAAA------- ---------A---AA----AAAA------- -------------------AAAA------- --------------------AA-------- ------------------------------ ------------------------------ ------------------------------ ------------------------------ ------------------------------ ------------------------------ ------------------------------ ------------------------------ ------------------------------ ------------------------------ 
-------AAAAAAAAAAAAAAAAA------ --------AAAAAAAAAAAAAAA------- --------AAAA-AAAAAAAAAA------- ---------A---------AAAA------- --------------------AA-------- ------------------------------ ------------------------------ ------------------------------ ------------------------------ ------------------------------ ------------------------------ ------------------------------ ------------------------------ ------------------------------ ------------------------------ 
-------AAAAAAAAAAAAAAAAAAA---- ------AAAAAAAAAAAAAAAAAAA----- ------AAAAAAAAAAAAAAAAAAA----- ---------AA-AAAA--A-AAA------- ------------AA---------------- ------------------------------ ------------------------------ ------------------------------ ------------------------------ ------------------------------ ------------------------------ ------------------------------ ------------------------------ ------------------------------ ------------------------------ 
-A---AAAAAAAAAAAAAAAAAAAAAA--- -----AAAAAAAAAAAAAAAAAAAAA---- -----AAAAAAAAAAAAAAAAAAAAA---- -----AAAAAAAAAAAAAAAAAAAAA---- -------A--AAAAAA----AAAAA----- ------------AAA--------------- ------------------------------ ------------------------------ ------------------------------ ------------------------------ ------------------------------ ------------------------------ ------------------------------ ------------------------------ ------------------------------ 
-----AAAAAAAAAAAAAAAAAAAAAA--- -----AAAAAAAAAAAAAAAAAAAAAA--- -----AAAAAAAAAAAAAAAAAAAAAA--- -----AAAAAAAAAAA--AAAAAAAA---- ------AAAAAAAAAA---AAAAAAA---- -----------AAAA--------------- ------------AA---------------- ------------------------------ ------------------------------ ------------------------------ ------------------------------ ------------------------------ ------------------------------ ------------------------------ ------------------------------ 
-----AAAAAAAAAAAAAAAAAAAAAA--- -----AAAAAAAAAAAAAAAAAAAAAA--- -----AAAAAAAAAAAAAAAAAAAAAA--- -----AAAAAAAAAAAAAAAAAAAAAA--- ------AAAAAAAAAAAAAAAAAAAA---- ------AAAAAAAAAAAAAAAAAA------ -------AAAAAAAA-AAAA-AA------- ---------AA------------------- ------------------------------ ------------------------------ ------------------------------ ------------------------------ ------------------------------ ------------------------------ ------------------------------ 
-----AAAAAAAAAAAAAAAAAAAAAA--- -----AAAAAAAAAAAAAAAAAAAAAA--- -----AAAAAAAAAAAAAAAAAAAAAA--- -----AAAAAAAAAAAAAAAAAAAAAA--- -----AAAAAAAAAAAAAAAAAAAAA---- -----AAAAAAAAAAAAAAAAAAA------ ------AAAAAAAAAAAAAAAAA------- --------AAAAA----------------- ------------------------------ ------------------------------ ------------------------------ ------------------------------ ------------------------------ ------------------------------ ------------------------------ 
----AAAAAAAAAAAAAAAAAAAAAAAAA- -----AAAAAAAAAAAAAAAAAAAAAA--- -----AAAAAAAAAAAAAAAAAAAAAA--- -----AAAAAAAAAAAAAAAAAAAAA---- -----AAAAAAAAAAAAAAAAAAAAA---- -----AAAAAAAAAAAAAAAAAA------- -----AAAAAAAAAAAAAAAAA-------- -------AAAAAAA---AA----------- ---------AAAA----------------- ------------------------------ ------------------------------ ------------------------------ ------------------------------ ------------------------------ ------------------------------ 
---AAAAAAAAAAAAAAAAAAAAAAAAAAA ---AAAAAAAAAAAAAAAAAAAAAAAAAA- ---AAAAAAAAAAAAAAAAAAAAAAAA--- ---AAAAAAAAAAAAAAAAAAAAAAA---- ---AAAAAAAAAAAAAAAAAAAAAAA---- -----AAAAAAAAAAAAAAAAAA------- -----AAAAAAAAAAAAAAAAA-------- -------AAAAAAAAAAAAAA--------- -------AAAAAAA---AA----------- ---------AAAAA---------------- -----------AA----------------- -----------AA----------------- ------------------------------ ------------------------------ ------------------------------ 
---AAAAAAAAAAAAAAAAAAAAAAAAAAA --AAAAAAAAAAAAAAAAAAAAAAAAAAA- --AAAAAAAAAAAAAAAAAAAAAAAA---- ---AAAAAAAAAAAAAAAAAAAAAAA---- ---AAAAAAAAAAAAAAAAAAAAAA----- -----AAAAAAAAAAAAAAAAAA------- -----AAAAAAAAAAAAAAAAA-------- -------AAAAAAAAAAAAAA--------- -------AAAAAAA--AAA----------- ---------AAAAA--A------------- -----------AAA---------------- ----------AAAAA--------------- ------------------------------ ------------------------------ ------------------------------ 
----AAAAAAAAAAAAAAAAAAAAAAAAA- ---AAAAAAAAAAAAAAAAAAAAAAAAA-- ----AAAAAAAAAAAAAAAAAAAAAA---- ----AAAAAAAAAAAAAAAAAAAA------ ----AAAAAAAAAAAAAAAAAAAA------ -----AAAAAAAAAAAAAAAAAA------- -----AAAAAAAAAAAAAAAAAA------- ------AAAAAAAAAAAAAAA--------- -------AAAAAAAAAAAAA---------- ---------AAAA-AAAA------------ ---------AAAAAAAAA------------ ---------AAAAAAAA------------- -----------AAAA--------------- ------------------------------ ------------------------------ 
----AAAAAAAAAAAAAAAAAAAAAAAA-- -----AAAAAAAAAAAAAAAAAAAAAA--- ----AAAAAAAAAAAAAAAAAAAAAAA--- ----AAAAAAAAAAAAAAAAAAAAAA---- ----AAAAAAAAAAAAAAAAAAAA------ -----AAAAAAAAAAAAAAAAAA------- -----AAAAAAAAAAAAAAAAA-------- -------AAAAAAAAAAAAAA--------- -------AAAAAAAAAAAAA---------- ---------AAAAAAAAAA----------- ---------AAAAAAAAAA----------- ---------AAAAAAAAA------------ -----------AAAA--------------- --------------A--------------- ------------------------------ 
--AA-AAAAAAAAAAAAAAAAAAAAAAA-- -----AAAAAAAAAAAAAAAAAAAAAA--- -----AAAAAAAAAAAAAAAAAAAAA---- -----AAAAAAAAAAAAAAAAAAA------ -----AAAAAAAAAAAAAAAAAAA------ -----AAAAAAAAAAAAAAAAA-------- -----AAAAAAAAAAAAAAAA--------- -------AAAAAAAAAAAAAA--------- ---------AAAAAAAAAAAA--------- ---------AAAAAAAAAA----------- ---------AAA-AAAAAA----------- ---------AAA-AAAAAA----------- ---------AAA-AAA-------------- ------------AAAA-------------- --------------A--------------- 
---A-AAAAAAAAAAAAAAAAAAAAAAA-- -----AAAAAAAAAAAAAAAAAAAAAAA-- -----AAAAAAAAAAAAAAAAAAAAAA--- -----AAAAAAAAAAAAAAAAAAAA----- -----AAAAAAAAAAAAAAAAAAAA----- -----AAAAAAAAAAAAAAAAAA------- ------AAAAAAAAAAAAAAAAA------- --------AAAAAAAAAAAAA--------- ---------AAAAAAAAAAA---------- ---------AAAAAAAAAA----------- ---------AAAAAAAAAA----------- ---------AAAAA-AAAA----------- ---------AAAAAAA-------------- ------------A-AA-------------- ------------------------------ 
-----AAAAAAAAAAAAAAAAAAAAAAA-- -----AAAAAAAAAAAAAAAAAAAAAAA-- -----AAAAAAAAAAAAAAAAAAAAAA--- -----AAAAAAAAAAAAAAAAAAAAA---- ------AAAAAAAAAAAAAAAAAAA----- ------AAAAAAAAAAAAAAAAAA------ -------AAAAAAAAAAAAAAAA------- --------AAAAAAAAAAAAA--------- ---------AAAAAAAAAAAA--------- ---------AAAAAAAAAAA---------- ----------AAAAAAA-A----------- ---------AAAAA-AA------------- -----------AAAAA-------------- --------------AA-------------- ------------------------------ 
-----AAAAAAAAAAAAAAAAAAAAAAAA- -----AAAAAAAAAAAAAAAAAAAAAAA-- -----AAAAAAAAAAAAAAAAAAAAA---- -------AAAAAAAAAAAAAAAAAAA---- -------AAAAAAAAAAAAAAAAAAA---- --------AAAAAAAAAAAAAAAAA----- ---------AAAAAAAAAAAAAA------- ---------AAAAAAAAAAAA--------- ---------AAAAAAAAAAA---------- ----------AAAAAAAAA----------- --------------AAA-A----------- --------------AA-------------- ---------------A-------------- ------------------------------ ------------------------------ 
---A-AAAAAAAAAAAAAAAAAAAAAAAA- -----AAAAAAAAAAAAAAAAAAAAAAA-- -----AAAAAAAAAAAAAAAAAAAAA---- -------AAAAAAAAAAAAAAAAAAA---- -------AAAAAAAAAAAAAAAAAAA---- -------AAAAAAAAAAAAAAAAAA----- ---------AAAAAAAAAAAAAAA------ ---------AAAAAAAAAAAA--------- ---------AAAAAAAAAAA---------- ----------AAAAAAAAA----------- --------------AAAAA----------- --------------AA-------------- ------------------------------ ------------------------------ ------------------------------ 
-----AAAAAAAAAAAAAAAAAAAAAAA-- -----AAAAAAAAAAAAAAAAAAAAA---- ------AAAAAAAAAAAAAAAAAAAA---- -------AAAAAAAAAAAAAAAAAAA---- -------AAAAAAAAAAAAAAAAAAA---- --------AAAAAAAAAAAAAAAA------ ----------AAAAAAAAAAAAA------- ---------AA-AAAAAAA----------- ------------AAAAAAA----------- -------------AAAAA------------ ------------------------------ ------------------------------ ------------------------------ ------------------------------ ------------------------------ 
-----AAAAAAAAAAAAAAAAAAAAAA--- -----AAAAAAAAAAAAAAAAAAAAAA--- -----AAAAAAAAAAAAAAAAAAAAA---- -------AAAAAAAAAAAAAAAAAAA---- --------AAAAAAAAAAAAAAAAA----- ---------A-AAAAAAAAAAAAA------ -----------AAAAAAAAAAAA------- ------------AAAAAAA----------- -------------AAAAA------------ ---------------A-------------- ------------------------------ ------------------------------ ------------------------------ ------------------------------ ------------------------------ 
-A--AAAAAAAAAAA-AAAAAAAAAAA--- -----AAAAAAAAAAAAAAAAAAAAAA--- -----AAAAAAAAAAAAAAAAAAAAAA--- ---------AAAAAAAAAAAAAAA------ -----------AAAAAAAAAAAAA------ ------------AAAAAAA-AA-------- ------------AAAAAAA----------- ------------------------------ ------------------------------ ------------------------------ ------------------------------ ------------------------------ ------------------------------ ------------------------------ ------------------------------ 
---AAAAAAAAAAAAAAAAAAAAAAAA--- -----AAAAAAAAAAAAAAAAAAAAAA--- -------AAAAAAAAAAAAAAAAAAA---- ----------AAAAAAAAAAAAA------- -----------AAAAAAAAAAAA------- --------------AAA------------- --------------AA-------------- ------------------------------ ------------------------------ ------------------------------ ------------------------------ ------------------------------ ------------------------------ ------------------------------ ------------------------------ 
---AAAAAAAAAAAAAAAAAAAAAAA---- -----AAAAAAAAAAAAAAAAAAAAA---- ------AAAAAAAAAAAAAAAAA-AA---- -------AA-AAAA--AAAA---------- ----------------AAA----------- ------------------------------ ------------------------------ ------------------------------ ------------------------------ ------------------------------ ------------------------------ ------------------------------ ------------------------------ ------------------------------ ------------------------------ 
----AAAAAAAAAAAAAAAAAAAA------ ------AAAAAAAAAAAAAA-AA------- ------AAAA-AAA--AAAA---------- -------AA-------AAA----------- ------------------------------ ------------------------------ ------------------------------ ------------------------------ ------------------------------ ------------------------------ ------------------------------ ------------------------------ ------------------------------ ------------------------------ ------------------------------ 
-AAA--AAAAAAAAAAAAAAAAAA--AA-- --A----AA-AAAA---AA--AA---A--- -------AA--------------------- ------------------------------ ------------------------------ ------------------------------ ------------------------------ ------------------------------ ------------------------------ ------------------------------ ------------------------------ ------------------------------ ------------------------------ ------------------------------ ------------------------------ 
-AAA---AA-AAAA---AA--AA---AA-- --A--------------------------- ------------------------------ ------------------------------ ------------------------------ ------------------------------ ------------------------------ ------------------------------ ------------------------------ ------------------------------ ------------------------------ ------------------------------ ------------------------------ ------------------------------ ------------------------------ 
-AA--------------------------A ------------------------------ ------------------------------ ------------------------------ ------------------------------ ------------------------------ ------------------------------ ------------------------------ ------------------------------ ------------------------------ ------------------------------ ------------------------------ ------------------------------ ------------------------------ ------------------------------ 
