model
size = 24 12 29, scale = 0.05, origin = -y
material 
  colors = A:#252525 B:#46C68E C:#5BFFB8 D:#B481BB E:#6F3381
voxels
-------CCCCCCCCCC------- -------CCCCCCCCCC------- ------------------------ ------------------------ ------------------------ ------------------------ ------------------------ ------------------------ ------------------------ ------------------------ ------------------------ ------------------------ 
------CCDEEEEEEDCC------ ------CCCBBBBBBCCC------ ------------------------ ------------------------ ------------------------ ------------------------ ------------------------ ------------------------ ------------------------ ------------------------ ------------------------ ------------------------ 
-----CDDEDDDDDDEDDC----- -----CCCBCCCCCCBCCC----- ------------------------ ------------------------ ------------------------ ------------------------ ------------------------ ------------------------ ------------------------ ------------------------ ------------------------ ------------------------ 
----CDDEDEEEEEEDEDDC---- ----CCCBCBBBBBBCBCCC---- ------------------------ ------------------------ ------------------------ ------------------------ ------------------------ ------------------------ ------------------------ ------------------------ ------------------------ ------------------------ 
---CDDEDEDDDDDDEDEDDC--- ---CCCBCBCCCCCCBCBCCC--- ------------------------ ------------------------ ------------------------ ------------------------ ------------------------ ------------------------ ------------------------ ------------------------ ------------------------ ------------------------ 
---CDEDEDEEEEEEDEDEDC--- ---CCBCBCBBBBBBCBCBCC--- ------------------------ ------------------------ ------------------------ ------------------------ ------------------------ ------------------------ ------------------------ ------------------------ ------------------------ ------------------------ 
--CDEDEDEDDDDDDEDEDEDC-- --CCBCBCBCCCCCCBCBCBCC-- ------------------------ ------------------------ ------------------------ ------------------------ ------------------------ ------------------------ ------------------------ ------------------------ ------------------------ ------------------------ 
--CEDEDEDDEEEEDDEDEDEC-- --CBCBCBCCBBBBCCBCBCBC-- ------------------------ ----------CCCC---------- ---------CC--CC--------- ---------CC--CC--------- ---------CC--CC--------- ----------CCCC---------- ------------------------ ------------------------ ------------------------ ------------------------ 
--CEDEDEDEDDDDEDEDEDEC-- --CBCBCAAAAABAAAACBCBC-- ------AAAAAAAAAAAA------ ------AAAAAAAAAAAA------ ------AAAAAAAAAAAA------ ------AAAAAAAAAAAA------ ------AAAAAAAAAAAA------ -------AAAAAAAAAA------- --------AAAAAAAA-------- ------------------------ ------------------------ ------------------------ 
--CEDEDBBBBBBBBBBDEDEC-- --CBAAABBBBBBBBBBAAABC-- ----AAAAAAABBAAAAAAA---- ----AAAAAAABBAAAAAAA---- -----AAAAAABBAAAAAA----- -----AAAAAABBAAAAAA----- -----AAAAAABBAAAAAA----- ------AAAAAAAAAAAA------ -------AAAAAAAAAA------- ------------------------ ------------------------ ------------------------ 
--CEDBB----------BBDEC-- --CAABB----------BBAAC-- ---AAA------------AAA--- ---AAA------------AAA--- ----AA------------AA---- ----AA------------AA---- ----AAA----------AAA---- -----AAAAAABBAAAAAA----- ------AAAAAAAAAAAA------ ----------AAAA---------- ------------------------ ------------------------ 
--ABBB------------BBBA-- --AABB------------BBAA-- --AAAB------------BAAA-- --AAAB------------BAAA-- ---AAB------------BAA--- ---AAB------------BAA--- ----AAA----------AAA---- -----AAA--------AAA----- ------AAAAABBAAAAA------ --------AAAAAAAA-------- ------------------------ ------------------------ 
--AB----------------BA-- --AB----------------BA-- --A------------------A-- --A------------------A-- ---A----------------A--- ---A----------------A--- ----AAB----------BAA---- ----AABA--------ABAA---- ------AAAAABBAAAAA------ --------AAAAAAAA-------- ------------------------ ------------------------ 
-AAB----------------BAA- -AAB----------------BAA- -AA------------------AA- -AA------------------AA- --AA----------------AA-- --AA----------------AA-- ---A----------------A--- ---AAA------------AAA--- -----AABAAABBAAABAA----- -------AAAAAAAAAA------- ------------------------ ------------------------ 
-AB------------------BA- -AB------------------BA- -A--------------------A- -A--------------------A- --A------------------A-- --A------------------A-- ---A----------------A--- ---AAA------------AAA--- -----AAABA----ABAAA----- -------AAAABBAAAA------- ----------AAAA---------- ------------------------ 
AAB------------------BAA AAB------------------BAA AA--------------------AA -A--------------------A- -AA------------------AA- --A------------------A-- --AA----------------AA-- ---AAA------------AAA--- ----AAAA--------AAAA---- ------AAABABBABAAA------ ---------AAAAAA--------- ------------------------ 
AB--------------------BA AB--------------------BA AA--------------------AA AA--------------------AA -AA------------------AA- -AA------------------AA- --AA----------------AA-- --AAAA------------AAAA-- ----AAAA--------AAAA---- ------AAAABBBBAAAA------ --------AAAAAAAA-------- -----------CC----------- 
AB--------------------BA AB--------------------BA AB--------------------BA AB--------------------BA -AB------------------BA- -AB------------------BA- --AB----------------BA-- --AABB------------BBAA-- ----AABB--------BBAA---- ------AABBBBBBBBAA------ --------AAACAAAA-------- ----------CCCC---------- 
AB--------------------BA AB--------------------BA AA--------------------AA AA--------------------AA -AA------------------AA- -AA------------------AA- --AA----------------AA-- --AAAA------------AAAA-- ----AAAA--------AAAA---- ------AAAABBBBAAAA------ --------AAAAAAAA-------- -----------CC----------- 
AB--------------------BA AB--------------------BA AA--------------------AA AA--------------------AA -AA------------------AA- -AA------------------AA- --AA----------------AA-- --AAAA------------AAAA-- ----AAAAAB----BAAAAA---- ------AAABABBABAAA------ ---------AAAAAA--------- ------------------------ 
AB--------------------BA AB--------------------BA AA--------------------AA -A--------------------A- -AA------------------AA- --A------------------A-- --AA----------------AA-- ---AAA------------AAA--- -----AAABA----ABAAA----- -------AAAABBAAAA------- ----------AAAA---------- ------------------------ 
AAB------------------BAA AAB------------------BAA -A--------------------A- -A--------------------A- --A------------------A-- --A------------------A-- ---A----------------A--- ---AAAAB--------BAAAA--- -----AAAAAABBAAABAA----- -------AAAAAAAAAA------- ------------------------ ------------------------ 
-AB------------------BA- -AB------------------BA- -A--------------------A- -A--------------------A- --A------------------A-- --A------------------A-- ---AAAB----------BAAA--- ---AAABA--------ABAAA--- -----AAAAAABBAAAAAA----- -------AAAAAAAAAA------- ------------------------ ------------------------ 
-AAB----------------BAA- -AAB----------------BAA- -AA------------------AA- --A------------------A-- --A------------------A-- ---AAB------------BAA--- ---AABA----------ABAA--- ----AAAA--------AAAA---- ------AAAAABBAAAAA------ ---------AAAAAA--------- ------------------------ ------------------------ 
--ABB--------------BBA-- --ABB--------------BBA-- --AAB--------------BAA-- --AAB--------------BAA-- ---AB--------------BA--- ---ABA------------ABA--- ----AAA----------AAA---- -----AAAAAABBAAAAAA----- -------AAAAAAAAAA------- ------------------------ ------------------------ ------------------------ 
--AAB--------------BAA-- --AAB--------------BAA-- --AAA--------------AAA-- --AAA--------------AAA-- ----A--------------A---- ----AA------------AA---- -----AA----------AA----- -------AAAABBAAAA------- ---------AAAAAA--------- ------------------------ ------------------------ ------------------------ 
---AABB----------BBAA--- ---AABB----------BBAA--- ---AAA------------AAA--- ---AAA------------AAA--- -----A------------A----- -----A------------A----- ------AAAAABBAAAAA------ ---------AAAAAA--------- ------------------------ ------------------------ ------------------------ ------------------------ 
----AAABB------BBAAA---- ----AAABB------BBAAA---- ----AAAAB------BAAAA---- ----AAAAAB----BAAAAA---- ------AAAABBBBAAAA------ ------AAAAABBAAAAA------ ---------AAAAAA--------- ------------------------ ------------------------ ------------------------ ------------------------ ------------------------ 
------AACBCBCBCBAA------ ------AACCCCCCCCAA------ ------AAA------AAA------ ------AAAA----AAAA------ --------AAAAAAAA-------- ---------AAAAAA--------- ------------------------ ------------------------ ------------------------ ------------------------ ------------------------ ------------------------ 
