model
size = 17 26 12, scale = 0.05, origin = -y
material 
  colors = A:#FFC17A B:#FD0 C:#222 D:#AB8B00 E:#555 F:#FF8B17 G:#444 H:#D9BC00 I:#AAA J:#B69A00 K:#A00 L:#FFF M:#BBB N:#500 O:#777 P:#E00 Q:#C4945D R:#9D550E
voxels
----------------- ----------------- ----------------- ----------------- ----------------- ----------------- ----------------- ----------------- ----------------- ----------------- ----------------- ----------------- ----------------- ----------------- ----------------- ----------------- ----------------- ----------------- ----------------- ----------------- ----------------- ----------------- ----------------- -----B----------- ----------------- ----------------- 
----C----------CC ----------------- ----------------- ----------------- ----------------- ----------------- ----------------- ----------------- ----------------- ----------------- ----------------- ----------------- ----------------- ----------------- ----------------- ----------------- ----------------- ----------------- ----GGMIIIGIIIHG- ----DGEEEEEEEEJG- ---HHHEEEEEEEEBB- ----B------------ ----B------------ ---------------B- ----------------B -----------B----- 
----C----------CC ----GC---------CG -----F---------F- -----FF-------FF- ----------------- ----------------- ----------------- ----------------- ------CCCA-Q-C--- ------CC---AGG--- ----------------- ----------------- --------AAAA----- -------AAKKAA---- ------AAKAAAAA--- -----ALAAAAALAA-- -----GCLAAANCLA-- ----GGAAAAAAAAAB- ---HCCMIIICIIIHG- ---HDCEEEEEEEEJG- ---HHHEEGGEEEEBB- ---BDDDDDDDDDJBH- ---HH-DB-DDDJBHJ- ---DB--H---H-B-BB -------B---B-B--B ---B------------- 
----C----------CC ----GC---------CG ----FF--------FFF -----FF-------FF- -----FF-------F-- ----------------- ----------------- ----------------- ------C---------- ------CC-----GG-- -------CC--CCC--- ----------------- -------AAAAAA---- ------AAAKKAAA--- -----AAAKAAAAB--- ----BAAAAAAALAB-- -----GOCAAANCLA-- ----GCCCCCAAAAAB- ----GCMIIICIIIHG- ----DCEEEEEEEEJG- ---HHHEEGGEEEEBB- ----DDDDDDDDDJBH- ---HHBDB-DDDJBHJ- ---BB-BD-B-BH--B- -----------B----- ----------------- 
----------------- ----------------- ----------------- -----FF-FFFFF-FF- -----FFCFFFFFFF-- -------FFFFFFF--- -------FFCGCFF--- -------FFCGCFF--- -------FCAGQCC--- -------CCCAACC--- -------CCCCCCC--- --------CCRC----- -------AAAAAA---- ------AAAKKAAA--- -----AAAKAAAAB--- ----BAAAAAAALAAA- -----GOCAAANCLAA- ----GCCCCCAAAAAB- ----GCMIIICIIIHG- ----DCEEEEEEEEJG- ---HHHEEGGEEEEBB- ---BDDDDDDDDDJBH- ---HHBDB-DDDJBHJ- ---BB----B---BB-- --BB------------- --B-------------- 
----------------- ----------------- ----------------- -----FFFFFFFFFFF- -----FFCFFFFFFF-- -------FFFFFFF--- ------CFFCGCFF--- -------FFCGCFF--- -------FCAGQCC--- -------CCCAACC--- -------CCCCCCC--- --------CCRC----- -------AAAAAA---- ------AAAKKAAB--- -----AAAKAAAABB-- -----AAAAAAALAA-- -----GOCAAANCLA-- ----GCCCCCAAAAAB- ----GCMIIICIIIHG- ----DCEEEEEEEEJG- ---HHHEEGGEEEEBB- ---BDDDDDDDDDJBH- ----HBD-DDDDJBH-- ---BB------------ --------B-------- --------B-------- 
----------------- ----------------- ----------------- ------FF-----F--- ------FFFFFFFF--- -------FFFFFFF--- ------CFFFFFFF--- -------FFPPPFF--- -------FCPPPCC--- -------CCCCCCC--- -------CCCCCCC--- --------CCRC----- --------AAAAA---- ------AAAKKAAB--- -----AAAKAAAABH-- ----BAAAAAAALABB- -----GOCAAANCLBB- ----GCCCCCAAAAA-- ----GCMIIICIIIHG- ----DCEEEEEEEEJG- ---HHHEEGGEEEEBB- ---BDDDDDDDDDJB-- ---HHBDBDDDDJBHJ- ------B-BBHB--BH- ------B---------- ----------------- 
----------------- ----------------- ----------------- ----------------- ----------------- ----------------- ----------------- ----------------- ----------------- ----------------- ----------------- ----------------- -------BBBBBB---- ------AAAKKABD--- -----AAAKAAAABB-- ----BAAAAAAALABB- ----BCOCAAANCLBB- ----GCCCCCAAAAAB- ----GCMIIICIIIHG- ----DCEEEEEEEEJG- ---HHHEEGGEEEEBB- ---BDDDDDDDDDJB-- ---HHBB-DDDDJBH-- ---BB-------BD-B- -----------B---BB -----------B-B--B 
----------------- ----------------- ----------------- ----------------- ----------------- ----------------- ----------------- ----------------- ----------------- ----------------- ----------------- ----------------- -------BBBBBD---- ------AAAKKABB--- -----AAAKAAAAAB-- ----BAAAAAAALABB- ----BCOCAAANCLB-- ----GCCCCCAAAAAB- ----GCMIIICIIIHG- ----DCEEEEEEEEJG- ---HHHEEGGEEEEB-- ---BDDDDDDDDDJBH- ---HHBBBDDDDJBHJ- ----D-B-D--B----- ----------------- --------B-------- 
----------------- ----------------- ----------------- ----------------- ----------------- ----------------- ----------------- ----------------- ----------------- ----------------- ----------------- ----------------- -------BBBBB----- ------BDDDDDBB--- GGG---BADDADADB-- -----BBDDDDDDDB-- --GGBGOCADANCLB-- ----GCCCCCAAAAA-- ----GGGGGGGGGGHG- ----DCEEEEEEEEJG- ---HHHEEGGEEEEBB- ---BDDDDDDDDDJB-- -----BDBDDDDJBH-- -----BB-BBBB-B--- ----------B------ ----------------- 
----------------- ----------------- ----------------- ----------------- ----------------- ----------------- ----------------- ----------------- ----------------- ----------------- ----------------- ----------------- ----------------- ----------------- GGG----B--B-B---- ----------------- --GG---BH-BHBB--- -----GGGGGBBBBB-- ----------------- ----DGGGGGGGGGJ-- ----HHDEGGEEEEB-- ----D--DDDDDDJB-- --------DDDDJB--- --------BB--BB--- -----BB-B-------- ----------------- 
----------------- ----------------- ----------------- ----------------- ----------------- ----------------- ----------------- ----------------- ----------------- ----------------- ----------------- ----------------- ----------------- ----------------- ----------------- ----------------- ----------------- ----------------- ----------------- ----------------- ------DDDDDDDDB-- ----------------- ----------------- ----------------- ----------------- ----------------- 
