model
size = 24 25 23, scale = 0.05, origin = -y
material 
  colors = A:#111 B:#EEE C:#888 D:#222 E:#555 F:#444
voxels
------------------------ ------------------------ ------------------------ ------------------------ ------------------------ ------------------------ ------------------------ ------------------------ ------------------------ ----------BBB----------- ---------BBBBB---------- --------BBBBBBB--------- --------BBBBBBB--------- --------BBBBBBB--------- ---------BBBBB---------- ----------BBB----------- ------------------------ ------------------------ ------------------------ ------------------------ ------------------------ ------------------------ ------------------------ ------------------------ ------------------------ 
------------------------ ------------------------ ------------------------ ------------------------ ------------------------ ------------------------ ------------------------ --------BBBBBBB--------- -------BBBBBBBBB-------- ------BBBBBBBBBBB------- ------BBBBBBBBBBB------- ------BBBBBBBBBBB------- ------BBBBBBBBBBB------- ------BBBBBBBBBBB------- ------BBBBBBBBBBB------- ------BBBBBBBBBBB------- -------BBBBBBBBB-------- --------BBBBBBB--------- ------------------------ ------------------------ ------------------------ ------------------------ ------------------------ ------------------------ ------------------------ 
------------------------ ------------------------ ------------------------ ------------------------ ------------------------ ---------BBBBB---------- -------BBBBBBBBB-------- -------ABBBBBBBBB------- ------ABBBBBBBBBBB------ -----BBBBBBBBBBBBB------ ---BBBBBBBBBBBBBBBB----- ---BBBBBBBBBBBBBBBB----- ---BBB-ABBBBBBBBBBB----- ---BBBBBBBBBBBBBBBB----- ---BBBBBBBBBBBBBBBB----- -----BBBBBBBBBBBBB------ -----BBBBBBBBBBBBB------ ------BBBBBBBBBBB------- -------BBBBBBBBB-------- ---------BBBBB---------- ------------------------ ------------------------ ------------------------ ------------------------ ------------------------ 
------------------------ ------------------------ ------------------------ ------------------------ --------BBBBBBB--------- ------CCBBBBBBBBB------- ------ABBBBBBBBBBB------ -----AABBBBBBBBBBBB----- ----BBBBBB-AAAAABBB----- ---BB-ABB-AAAAAAABBB---- ---B--AA-AAAAAAAAABB---- -------AAAAAAAAAAABB---- --------AAAAAAAAAABB---- -------AAAAAAAAAAABB---- ---C-B-A-AAAAAAAAABB---- ---BB-ABB-AAAAAAABBB---- ----BBBBBB-AAAAABBB----- ----BBBBBBBBBBBBBBB----- ----BBBBBBBBBBBBBB------ ------BBBBBBBBBBB------- --------BBBBBBB--------- ------------------------ ------------------------ ------------------------ ------------------------ 
------------------------ ------------------------ ------------------------ --------BBBBBBB--------- ------BBBBBBBBBBB------- ------ABBBBBBBBBBB------ -----ABBBB-AAAABBBB----- ---C-ABBB-AAAAAAABBB---- ---B-AAB-AAAAAAAAABB---- --B--A-AAAAAAAAAAAABB--- --------AAAAAAAAAAABB--- ---------AAAAAAAAAABB--- ---------AAAAAAAAAABB--- ---------AAAAAAAAAABB--- --------AAAAAAAAAAABB--- -CB----AAAAAAAAAAAABB--- -BBB--AA-AAAAAAAAABB---- --BB-AABB-AAAAAAABBB---- ----BBBBBBBBBBBBBBB----- ----BBBBBBBBBBBBBB------ ------BBBBBBBBBBB------- --------BBBBBBB--------- ------------------------ ------------------------ ------------------------ 
------------------------ ------------------------ ---------BBBBB---------- ------BBBBBBBBBBB------- ----CCBBBBBBBBBBBB------ -----ABBBB-AAAAABBB----- ----AAB-AAAAAAAAAAAB---- --BB-A-AAAAAAAAAAAABB--- --BB-AAAAAAAAAAAAAAAB--- --------AAAAAAAAAAAAB--- ---------AAAAAAAAAAAAB-- ---------AAAAAAAAAAAAB-- ----------AAAAAAAAAAAB-- ---------AAAAAAAAAAAAB-- ---------AAAAAAAAAAAAB-- ---------AAAAAAAAAAAB--- --------AAAAAAAAAAAAB--- -BB----AAAAAAAAAAAABB--- ---B-AAB-AAAAAAAAABB---- ----BBBBBB-AAAAABBB----- ----BBBBBBBBBBBBBB------ ------BBBBBBBBBBB------- ---------BBBBB---------- ------------------------ ------------------------ 
------------------------ ------------------------ ------BBBBBBBBBB-------- -----BABBBBBBBBBBB------ ----AABBBB-AAAABBBB----- ----AABB-AAAAAAAAABB---- --CA-A-AAAAAAAAAAAABB--- --CB-AAAAAAAAAAAAAAAB--- -BB--A-AAAAAAAAAAAAAAB-- ---------AAAAAAAAAAAAB-- ----------AAAAAAAAAAAB-- ----------AAAAAAAAAAAB-- ----------AAAAAAAAAAAB-- ----------AAAAAAAAAAAB-- ----------AAAAAAAAAAAB-- ---------AAAAAAAAAAAAB-- ---------AAAAAAAAAAAAB-- --------FAAAAAAAAAAAB--- --BB--AAAAAAAAAAAAABB--- ---B-ABB-AAAAAAAAABB---- ----BBBBBB-AAAABBBB----- ----BBBBBBBBBBBBBB------ -------BBBBBBBBB-------- ------------------------ ------------------------ 
------------------------ --------BBBBBBB--------- ----BBBBBBBBBBBBB------- ---CCCBBBBBBBBBBBBB----- ---ABBBBB-AAAAAAABBB---- ---A-AB-AAAAAAAAAAABB--- ---A-A-AAAAAAAAAAAAAB--- BBBB-AAAAAAAAAAAAAAAAB-- BB---A--AAAAAAAAAAAAAB-- ---------AAAAAAAAAAAAAB- ----------AAAAAAAAAAAAB- ----------AAAAAAAAAAAAB- ----------AAAAAAAAAAAAB- ----------AAAAAAAAAAAAB- ----------AAAAAAAAAAAAB- ----------AAAAAAAAAAAAB- ---------AAAAAAAAAAAAB-- ---------AAAAAAAAAAAAB-- --B----AAAAAAAAAAAABB--- --BB-AA-AAAAAAAAAAABB--- ---B-ABBB-AAAAAAABBB---- ----BBBBBBBBBBBBBBB----- ------BBBBBBBBBBB------- --------BBBBBBB--------- ------------------------ 
------------------------ -------BBBBBBBBB-------- ----BBBBBBBBBBBBBB------ ----AABBBB-AAAAABBB----- ---AAABB-AAAAAAAAABB---- ---A-A-AAAAAAAAAAAABB--- -CBB-AAAAAAAAAAAAAAAAB-- BBBB-AAAAAAAAAAAAAAAAB-- BBB--A-AAAAAAAAAAAAAAAB- ---------AAAAAAAAAAAAAB- ---------AAAAAAAAAAAAAB- ----------AAAAAAAAAAAAB- ----------AAAAAAAAAAAAB- ----------AAAAAAAAAAAAB- ----------AAAAAAAAAAAAB- ----------AAAAAAAAAAAAB- ----------AAAAAAAAAAAAB- ---------AAAAAAAAAAAAB-- -B------AAAAAAAAAAAABB-- --BB-AAAAAAAAAAAAAABB--- ---B-ABB-AAAAAAAAABB---- ----BBBBBB-AAAAABBB----- -----BBBBBBBBBBBBB------ -------BBBBBBBBB-------- ------------------------ 
----------BBB----------- ------BBBBBBBBBBB------- ----BBABBBB-AAABBB------ ---CBBBB-AAAAAAAAABB---- ----AAB-AAAAAAAAAAABB--- ---A-A-AAAAAAAAAAAAAB--- -BBB-AAAAAAAAAAAAAAAAB-- BBBB-AAAAAAAAAAAAAAAAAB- BBD-AAAAAAAAAAAAAAAAAAB- -B-------AAAAAAAAAAAAAB- ---------AAAAAAAAAAAAAB- ---------AAAAAAAAAAAAAAB ----------AAAAAAAAAAAAAB ----------AAAAAAAAAAAAAB ----------AAAAAAAAAAAAB- ----------AAAAAAAAAAAAB- ---------AAAAAAAAAAAAAB- C--------AAAAAAAAAAAAAB- -BB----AAAAAAAAAAAAAAB-- --BB-AAAAAAAAAAAAAAAB--- --BB-AB-AAAAAAAAAAABB--- ---BBBBB-AAAAAAAAABB---- -----BBBBBBBBBBBBB------ ------BBBBBBBBBBB------- ----------BBB----------- 
---------BBBBBB--------- ------BBBBBBBBBBB------- ---CCCBBBB-AAAAABBB----- ---AAABB-AAAAAAAAABB---- ----AA-AAAAAAAAAAAABB--- -EAA-A-AAAAAAAAAAAAABB-- -CBB-AAAAAAAAAAAAAAAAB-- BBBB-AAAAAAAAAAAAAAAAAB- BBB-AAAAAAAAAAAAAAAAAAB- --D--A--AAAAAAAAAAAAAAAB BB---A---AAAAAAAAAAAAAAB ---------AAAAAAAAAAAAAAB ---------AAAAAAAAAAAAAAB ---------AAAAAAAAAAAAAAB ----------AAAAAAAAAAAAAB ----------AAAAAAAAAAAAAB B--------AAAAAAAAAAAAAB- BB------AAAAAAAAAAAAAAB- -BBB-AAAAAAAAAAAAAAAAB-- -BBB-A-AAAAAAAAAAAAABB-- --BB-A-AAAAAAAAAAAABB--- ---B-ABB-AAAAAAAAABB---- ----BBBBBBBBBBBBBBB----- ------BBBBBBBBBBB------- ---------BBBBB---------- 
--------BBBBBBB--------- ----BBBBBBBBBBBBB------- ---BAABBBB-AAAAABBB----- ---EBBBB-AAAAAAAAABB---- ----AA-AAAAAAAAAAAABB--- --AA-A-AAAAAAAAAAAAABB-- -BBB-AAAAAAAAAAAAAAAAB-- BBBB-AAAAAAAAAAAAAAAAAB- BBB-AAAAAAAAAAAAAAAAAAB- BBB-AAAAAAAAAAAAAAAAAAAB BB-AA-AAAAAAAAAAAAAAAAAB BB-A---AAAAAAAAAAAAAAAAB -B------AAAAAAAAAAAAAAAB -B-------AAAAAAAAAAAAAAB BB-------AAAAAAAAAAAAAAB CB-------AAAAAAAAAAAAAAB BB------AAAAAAAAAAAAAAB- BBB----AAAAAAAAAAAAAAAB- -BBBB-AAAAAAAAAAAAAAAB-- -BBB-A-AAAAAAAAAAAAABB-- --BB-A-AAAAAAAAAAAABB--- ---B-ABB-AAAAAAAAABB---- ----BBBBBBBBBBBBBBB----- ------BBBBBBBBBBB------- --------BBBBBBB--------- 
---------BBBBBB--------- ------BBBBBBBBBBB------- ---CCCBBBB-AAAABBBB----- ---ABBBB-AAAAAAAAABB---- ----AA-AAAAAAAAAAAABB--- -EAA-A-AAAAAAAAAAAAABB-- -CBB-AAAAAAAAAAAAAAAAB-- BBBB-AAAAAAAAAAAAAAAAAB- BBB-AAAAAAAAAAAAAAAAAAB- --D-----AAAAAAAAAAAAAAAB BB-------AAAAAAAAAAAAAAB ---------AAAAAAAAAAAAAAB ---------AAAAAAAAAAAAAAB ---------AAAAAAAAAAAAAAB ----------AAAAAAAAAAAAAB ----------AAAAAAAAAAAAAB B--------AAAAAAAAAAAAAB- BB------AAAAAAAAAAAAAAB- -BBB--AAAAAAAAAAAAAAAB-- -BBB-A-AAAAAAAAAAAAABB-- --BB-A-AAAAAAAAAAAABB--- ---BBBBB-AAAAAAAAABB---- ----BBBBBBBBBBBBBBB----- ------BBBBBBBBBBB------- ---------BBBBB---------- 
----------BBB----------- ------BBBBBBBBBBB------- ----BBABBBB-AAABBB------ ---CBBBB-AAAAAAAAABB---- --AAAAB-AAAAAAAAAAABB--- ---A-A-AAAAAAAAAAAAAB--- -BBB-AAAAAAAAAAAAAAAAB-- BBBB-AAAAAAAAAAAAAAAAAB- BBD-AAAAAAAAAAAAAAAAAAB- -B-------AAAAAAAAAAAAAB- ---------AAAAAAAAAAAAAB- ---------AAAAAAAAAAAAAAB ----------AAAAAAAAAAAAAB ----------AAAAAAAAAAAAAB ----------AAAAAAAAAAAAB- ----------AAAAAAAAAAAAB- ---------AAAAAAAAAAAAAB- C--------AAAAAAAAAAAAAB- -BB----AAAAAAAAAAAAAAB-- --BB-AAAAAAAAAAAAAAAB--- --BB-AB-AAAAAAAAAAABB--- ---BBBBB-AAAAAAAAABB---- -----BBBBBBBBBBBBB------ ------BBBBBBBBBBB------- ----------BBB----------- 
------------------------ -------BBBBBBBBB-------- ----BBBBBBBBBBBBBB------ -----ABBBB-AAAAABBB----- ---AABBB-AAAAAAAAABB---- ---A-A-AAAAAAAAAAAABB--- -CBB-AAAAAAAAAAAAAAAAB-- BBBB-AAAAAAAAAAAAAAAAB-- BBB--A-AAAAAAAAAAAAAAAB- ---------AAAAAAAAAAAAAB- ---------AAAAAAAAAAAAAB- ----------AAAAAAAAAAAAB- ----------AAAAAAAAAAAAB- ----------AAAAAAAAAAAAB- ----------AAAAAAAAAAAAB- ----------AAAAAAAAAAAAB- ----------AAAAAAAAAAAAB- ---------AAAAAAAAAAAAB-- -B------AAAAAAAAAAAABB-- --BB-AAAAAAAAAAAAAABB--- ---B-ABB-AAAAAAAAABB---- ----BBBBBB-AAAAABBB----- -----BBBBBBBBBBBBB------ -------BBBBBBBBB-------- ------------------------ 
------------------------ --------BBBBBBB--------- -----BBBBBBBBBBBB------- ---CCCBBBBBBBBBBBBB----- ---AABBBB-AAAAAAABBB---- ---A-AB-AAAAAAAAAAABB--- ---A-A-AAAAAAAAAAAAAB--- BBBB-AAAAAAAAAAAAAAAAB-- BB---A--AAAAAAAAAAAAAB-- ---------AAAAAAAAAAAAAB- ----------AAAAAAAAAAAAB- ----------AAAAAAAAAAAAB- ----------AAAAAAAAAAAAB- ----------AAAAAAAAAAAAB- ----------AAAAAAAAAAAAB- ----------AAAAAAAAAAAAB- ---------AAAAAAAAAAAAB-- ---------AAAAAAAAAAAAB-- --B----AAAAAAAAAAAABB--- --BB-AA-AAAAAAAAAAABB--- ---B-ABBB-AAAAAAABBB---- ----BBBBBBBBBBBBBBB----- ------BBBBBBBBBBB------- --------BBBBBBB--------- ------------------------ 
------------------------ ------------------------ ------BBBBBBBBBB-------- -----BABBBBBBBBBBB------ -----ABBBB-AAAABBBB----- ----ABBB-AAAAAAAAABB---- --CA-A-AAAAAAAAAAAABB--- --CB-AAAAAAAAAAAAAAAB--- BBB--A-AAAAAAAAAAAAAAB-- ---------AAAAAAAAAAAAB-- ---------AAAAAAAAAAAAB-- ----------AAAAAAAAAAAB-- ----------AAAAAAAAAAAB-- ----------AAAAAAAAAAAB-- ----------AAAAAAAAAAAB-- ---------AAAAAAAAAAAAB-- ---------AAAAAAAAAAAAB-- --------FAAAAAAAAAAAB--- --BB-AAAAAAAAAAAAAABB--- ---B-ABB-AAAAAAAAABB---- ----BBBBBB-AAAABBBB----- -----BBBBBBBBBBBBB------ -------BBBBBBBBB-------- ------------------------ ------------------------ 
------------------------ ------------------------ ---------BBBBB---------- ------BBBBBBBBBBB------- -----CBBBBBBBBBBBB------ -----ABBBB-AAAAABBB----- ----ABB-AAAAAAAAAAAB---- --BB-A-AAAAAAAAAAAABB--- --BB-AAAAAAAAAAAAAAAB--- -----A--AAAAAAAAAAAAB--- ---------AAAAAAAAAAAAB-- ---------AAAAAAAAAAAAB-- ----------AAAAAAAAAAAB-- ---------AAAAAAAAAAAAB-- ---------AAAAAAAAAAAAB-- ---------AAAAAAAAAAAB--- --------AAAAAAAAAAAAB--- --B--A-AAAAAAAAAAAABB--- ---B-AAB-AAAAAAAAABB---- ----BBBBBB-AAAAABBB----- -----BBBBBBBBBBBBB------ ------BBBBBBBBBBB------- ---------BBBBB---------- ------------------------ ------------------------ 
------------------------ ------------------------ ------------------------ --------BBBBBBB--------- ------BBBBBBBBBBB------- ------ABBBBBBBBBBB------ -----ABBBB-AAAABBBB----- ---CABBBB-AAAAAAABBB---- ---B-AAB-AAAAAAAAABB---- --B--A-AAAAAAAAAAAABB--- -----A--AAAAAAAAAAABB--- ---------AAAAAAAAAABB--- ---------AAAAAAAAAABB--- ---------AAAAAAAAAABB--- --------AAAAAAAAAAABB--- --C--A-AAAAAAAAAAAABB--- --BB-AAA-AAAAAAAAABB---- ---B-AABB-AAAAAAABBB---- ----BBBBBBBBBBBBBBB----- -----BBBBBBBBBBBBB------ ------BBBBBBBBBBB------- --------BBBBBBB--------- ------------------------ ------------------------ ------------------------ 
------------------------ ------------------------ ------------------------ ------------------------ --------BBBBBBB--------- ------CCBBBBBBBBB------- ------ABBBBBBBBBBB------ -----AABBBBBBBBBBBB----- ----BBBBBB-AAAAABBB----- ---BB-ABB-AAAAAAABBB---- ---B--AA-AAAAAAAAABB---- -------AAAAAAAAAAABB---- --------AAAAAAAAAABB---- -------AAAAAAAAAAABB---- ---B-B-A-AAAAAAAAABB---- ---BB-ABB-AAAAAAABBB---- ----BBBBBB-AAAAABBB----- ----BBBBBBBBBBBBBBB----- -----BBBBBBBBBBBBB------ ------BBBBBBBBBBB------- --------BBBBBBB--------- ------------------------ ------------------------ ------------------------ ------------------------ 
------------------------ ------------------------ ------------------------ ------------------------ ------------------------ ---------BBBBB---------- -------BBBBBBBBB-------- -------ABBBBBBBBB------- ------ABBBBBBBBBBB------ -----BBBBBBBBBBBBB------ ---BBBBBBBBBBBBBBBB----- ---BBBBBBBBBBBBBBBB----- ---BBB-ABBBBBBBBBBB----- ---BBBBBBBBBBBBBBBB----- ---BBBBBBBBBBBBBBBB----- -----BBBBBBBBBBBBB------ -----BBBBBBBBBBBBB------ ------BBBBBBBBBBB------- -------BBBBBBBBB-------- ---------BBBBB---------- ------------------------ ------------------------ ------------------------ ------------------------ ------------------------ 
------------------------ ------------------------ ------------------------ ------------------------ ------------------------ ------------------------ ------------------------ --------BBBBBBB--------- -------BBBBBBBBB-------- ------BBBBBBBBBBB------- ------BBBBBBBBBBB------- ------BBBBBBBBBBB------- ------BBBBBBBBBBB------- ------BBBBBBBBBBB------- ------BBBBBBBBBBB------- ------BBBBBBBBBBB------- -------BBBBBBBBB-------- --------BBBBBBB--------- ------------------------ ------------------------ ------------------------ ------------------------ ------------------------ ------------------------ ------------------------ 
------------------------ ------------------------ ------------------------ ------------------------ ------------------------ ------------------------ ------------------------ ------------------------ ------------------------ ----------BBB----------- ---------BBBBB---------- --------BBBBBBB--------- --------BBBBBBB--------- --------BBBBBBB--------- ---------BBBBB---------- ----------BBB----------- ------------------------ ------------------------ ------------------------ ------------------------ ------------------------ ------------------------ ------------------------ ------------------------ ------------------------ 
