model
size = 23 25 25, scale = 0.05, origin = -y
material 
  colors = A:#800 B:#EEE C:#500 D:#888 E:#222 F:#555
voxels
----------------------- ----------------------- ----------------------- ----------------------- ----------------------- ----------------------- ----------------------- ----------------------- ----------------------- ----------------------- -----------B----------- -----------B----------- -----------B----------- -----------B----------- -----------B----------- ----------------------- ----------------------- ----------------------- ----------------------- ----------------------- ----------------------- ----------------------- ----------------------- ----------------------- ----------------------- 
----------------------- ----------------------- ----------------------- ----------------------- ----------------------- ----------------------- ----------------------- ---------BBBBB--------- --------BBBBBBB-------- -------BBB-B-BBB------- ----------BBB---------- -----------B----------- ----------------------- ----------------------- -----------B----------- -----------B----------- ----------BBB---------- ---------BBBBB--------- ----------------------- ----------------------- ----------------------- ----------------------- ----------------------- ----------------------- ----------------------- 
----------------------- ----------------------- ----------------------- ----------------------- ----------------------- ----------FCF---------- --------DBDBDBD-------- -------BBBBBBBBB------- ------BBBBBBBBBBB------ ---------B-B-B--------- ----------BBB---------- -----------B----------- ----------------------- ----------------------- ----------------------- ----------------------- -----------B----------- ----------BBB---------- --------BBBBBBB-------- ----------BBB---------- ----------------------- ----------------------- ----------------------- ----------------------- ----------------------- 
----------------------- ----------------------- ----------------------- ----------------------- ---------CCCCC--------- -------CCCBBBCCC------- ------DCBBBBBBBCD------ -----BDBBBBBBBBBDB----- -----BB-BEBBBEB-BB----- ----B-----CBC-----B---- -----------A----------- -----------A----------- ----------------------- ----------------------- ----------------------- ----B-------------B---- ----------------------- -----B-----B-----B----- ------BB-BBBBB-BB------ -------BBBBBBBBB------- ---------BBBBB--------- ----------------------- ----------------------- ----------------------- ----------------------- 
----------------------- ----------------------- ----------------------- ---------CCCCC--------- -------CCBBBBBCC------- ------CBBBBBBBBBC------ -----CBBBBBBBBBBBC----- ----DBBBBBBBBBBBBBD---- ----BB---AAAAA---BB---- ---B-------A-------B--- ---B-------A-------B--- ----------------------- ----------------------- ----------------------- ---B---------------B--- ---B---------------B--- ----B-------------B---- ----B-------------B---- -----BB---BBB---BB----- ------BBBBBBBBBBB------ -------BBBBBBBBB------- ---------BBBBB--------- ----------------------- ----------------------- ----------------------- 
----------------------- ----------------------- ----------DCD---------- -------DCBBDABAD------- ------CBDAAAAAADA------ -----CBAAAAAAAAAAC----- ----CBAAAAAAAAAAAAA---- ---CBAAAAAAAAAAAAAAA--- ---BAAAAAAAAAAAAAAAB--- ---BAA-----AA-----AB--- --B-A-------A-------B-- --B-----------------B-- --B-----------------B-- --B-----------------B-- --B-----------------B-- ---BA--------------B--- ---BA--------------B--- ---BAA------------AB--- ----BAA----BA----ABB--- -----BAAAAAAAAAAABB---- ------BAAAAAAAAABB----- -------BBBBAABBBB------ ----------BBB---------- ----------------------- ----------------------- 
----------------------- ----------------------- --------BCDBDCB-------- ------CDBBBBBBBDC------ -----DBBBBBBBBBBBD----- ----CBBBBBBBBBBBBBC---- ---CBBBBAAAAAAABBBBA--- ---CBBAAAAAAAAAAABBA--- --CBAA---AAAAA---AABC-- --BA-------A-------AB-- --BA-------A-------AB-- --B-----------------B-- --B-----------------B-- --B-----------------B-- --BB---------------BB-- --BC---------------CB-- --BBA-------------ABB-- ---BA-------------AB--- ---BBAA---AAA---AABB--- ----BBBAAABBBAAABBB---- -----BBBBBBBBBBBBB----- ------BBBBBBBBBBB------ --------BBBBBBB-------- ----------------------- ----------------------- 
----------------------- ---------BBBBB--------- -------BBBBBBBBB------- -----BBBBBBBBBBBBB----- ----BBBBBBAAABBBBBB---- ---DBBBBAAAAAAABBBBD--- ---BBBAAAAAAAAAAABBB--- --CBBAAAAAAAAAAAAABBC-- --BBBAA-AAAAAAA-AABBB-- -BBBA------A------ABBB- -BBA-------A-------ABB- -BBA-------A-------ABB- -BC-----------------CB- -BBA---------------ABB- -BBA---------------ABB- -BBBA-------------ABBB- --BBA-------------ABB-- --BBBA-----A-----ABBB-- ---BBBAA-AAAAA-AABBB--- ---BBBBBAAAAAAABBBBB--- ----BBBBBBAAABBBBBB---- -----BBBBBBBBBBBBB----- -------BBBBBBBBB------- ---------BBBBB--------- ----------------------- 
----------------------- --------BBBBBBB-------- ------BBBBBBBBBBB------ -----BBBBBBBBBBBBB----- ----BBBBBAAAAABBBBB---- ---DBBBAAAAAAAAABBBD--- --BBBAAAAAAAAAAAAABBB-- --BBBAAAAAAAAAAAAABBB-- -BBBBAAAAAAAAAAAAABBBB- -BBBAA----AAA----AABBB- -BBBA------A------ABBB- -BBA-------A-------ABB- -BBA-------A-------ABB- -BBA---------------ABB- -BBBA-------------ABBB- -BBBA-------------ABBB- -BBBBA-----A-----ABBBB- --BBBAA---AAA---AABBB-- --BBBBAAAAAAAAAAABBBB-- ---BBBBAAAAAAAAABBBB--- ----BBBBBAAAAABBBBB---- -----BBBBBBBBBBBBB----- ------BBBBBBBBBBB------ --------BBBBBBB-------- ----------------------- 
-----------B----------- -------BBBBBBBBB------- ------BBBBBBBBBBB------ ----BBBBBAAAAABBBBB---- ---BBBBBAAAAAAABBBBB--- ---BBBAAAAAAAAAAABBB--- --BBBAAAAAAAAAAAAABBB-- -BBBBAAAAAAAAAAAAABBBB- -BBBAAAAAAAAAAAAAAABBB- -BBBAAAAAAAAAAAAAAABBB- -BBAAAA-AAAAAAA-AAAABB- BBBAAA---AAAAA---AAABBB BBBAA-----AAA-----AABBB BBBAAA----AAA----AAABBB -BBAAA-----A-----AAABB- -BBBAAA----A----AAABBB- -BBBAAAA-AAAAA-AAAABBB- -BBBBAAAAAAAAAAAAABBBB- --BBBAAAAAAAAAAAAABBB-- ---BBBAAAAAAAAAAABBB--- ---BBBBBAAAAAAABBBBB--- ----BBBBBAAAAABBBBB---- ------BBBBBBBBBBB------ -------BBBBBBBBB------- -----------B----------- 
----------BBB---------- -------BBBBBBBBB------- -----BBBBBBBBBBBBB----- ----BBBBBAAAAABBBBB---- ---BBBBAAAAAAAAABBBB--- --BBBBAAAAAAAAAAABBBB-- --BBBAAAAAAAAAAAAABBB-- -BBBAAAAAAAAAAAAAAABBB- -BBBAAAAAAAAAAAAAAABBB- -BBAAAAAAAAAAAAAAAAABB- BBBAAAAAAAAAAAAAAAAABBB BBBAAAAAAAAAAAAAAAAABBB BBBAAAAAAAAAAAAAAAAABBB BBBAAAAAAAAAAAAAAAAABBB BBBAAAAAAAAAAAAAAAAABBB -BBAAAAAAAAAAAAAAAAABB- -BBBAAAAAAAAAAAAAAABBB- -BBBAAAAAAAAAAAAAAABBB- --BBBAAAAAAAAAAAAABBB-- --BBBBAAAAAAAAAAABBBB-- ---BBBBAAAAAAAAABBBB--- ----BBBBBAAAAABBBBB---- -----BBBBBBBBBBBBB----- -------BBBBBBBBB------- ----------BBB---------- 
---------BBBBB--------- -------BBBBBBBBB------- -----BBBBBAAABBBBB----- ----BBBBAAAAAAABBBB---- ---BBBAAAAAAAAAAABBB--- --BBBAAAAAAAAAAAAABBB-- --BBAAAAAAAAAAAAAAABB-- -BBBAAAAAAAAAAAAAAABBB- -BBAAAAAAAAAAAAAAAAABB- BBBAAAAAAAAAAAAAAAAABBB BBBAAAAAAAAAAAAAAAAABBB BBBAAAAAAAAAAAAAAAAABBB BBBAAAAAAAAAAAAAAAAABBB BBBAAAAAAAAAAAAAAAAABBB BBBAAAAAAAAAAAAAAAAABBB BBBAAAAAAAAAAAAAAAAABBB -BBAAAAAAAAAAAAAAAAABB- -BBBAAAAAAAAAAAAAAABBB- --BBBAAAAAAAAAAAAABBB-- --BBBAAAAAAAAAAAAABBB-- ---BBBAAAAAAAAAAABBB--- ----BBBBAAAAAAABBBB---- -----BBBBBBBBBBBBB----- -------BBBBBBBBB------- ---------BBBBB--------- 
---------BBBBB--------- -------BBBBBBBBB------- -----BBBBAAAAABBBB----- ----BBBBAAAAAAABBBB---- ---BBBAAAAAAAAAAABBB--- --BBBAAAAAAAAAAAAABBB-- --BBAAAAAAAAAAAAAAABB-- -BBBAAAAAAAAAAAAAAABBB- -BBAAAAAAAAAAAAAAAAABB- BBBAAAAAAAAAAAAAAAAABBB BBBAAAAAAAAAAAAAAAAABBB BBBAAAAAAAAAAAAAAAAABBB BBBAAAAAAAAAAAAAAAAABBB BBBAAAAAAAAAAAAAAAAABBB BBBAAAAAAAAAAAAAAAAABBB BBBAAAAAAAAAAAAAAAAABBB -BBAAAAAAAAAAAAAAAAABB- -BBBAAAAAAAAAAAAAAABBB- --BBBAAAAAAAAAAAAABBB-- --BBBAAAAAAAAAAAAABBB-- ---BBBAAAAAAAAAAABBB--- ----BBBBAAAAAAABBBB---- -----BBBBBBBBBBBBB----- -------BBBBBBBBB------- ---------BBBBB--------- 
---------BBBBB--------- -------BBBBBBBBB------- -----BBBBAAAAABBBB----- ----BBBBAAAAAAABBBB---- ---BBBAAAAAAAAAAABBB--- --BBBAAAAAAAAAAAAABBB-- --BBAAAAAAAAAAAAAAABB-- -BBBAAAAAAAAAAAAAAABBB- -BBAAAAAAAAAAAAAAAAABB- BBBAAAAAAAAAAAAAAAAABBB BBBAAAAAAAAAAAAAAAAABBB BBBAAAAAAAAAAAAAAAAABBB BBBAAAAAAAAAAAAAAAAABBB BBBAAAAAAAAAAAAAAAAABBB BBBAAAAAAAAAAAAAAAAABBB BBBAAAAAAAAAAAAAAAAABBB -BBAAAAAAAAAAAAAAAAABB- -BBBAAAAAAAAAAAAAAABBB- --BBBAAAAAAAAAAAAABBB-- --BBBAAAAAAAAAAAAABBB-- ---BBBAAAAAAAAAAABBB--- ----BBBBAAAAAAABBBB---- -----BBBBBBBBBBBBB----- -------BBBBBBBBB------- ---------BBBBB--------- 
----------BBB---------- -------BBBBBBBBB------- -----BBBBAAAAABBBB----- ----BBBBAAAAAAABBBB---- ---BBBAAAAAAAAAAABBB--- --BBBAAAAAAAAAAAAABBB-- --BBAAAAAAAAAAAAAAABB-- -BBBAAAAAAAAAAAAAAABBB- -BBAAAAAAAAAAAAAAAAABB- -BBAAAAAAAAAAAAAAAAABB- BBBAAAAAAAAAAAAAAAAABBB BBBAAAAAAAAAAAAAAAAABBB BBBAAAAAAAAAAAAAAAAABBB BBBAAAAAAAAAAAAAAAAABBB BBBAAAAAAAAAAAAAAAAABBB -BBAAAAAAAAAAAAAAAAABB- -BBAAAAAAAAAAAAAAAAABB- -BBBAAAAAAAAAAAAAAABBB- --BBBAAAAAAAAAAAAABBB-- --BBBAAAAAAAAAAAAABBB-- ---BBBAAAAAAAAAAABBB--- ----BBBBAAAAAAABBBB---- -----BBBBBBBBBBBBB----- -------BBBBBBBBB------- ----------BBB---------- 
----------BBB---------- -------BBBBBBBBB------- ------BBBBBAABBBB------ ----BBBBAAAAAAABBBB---- ---BBBBAAAAAAAAABBBB--- ---BBAAAAAAAAAAAAABB--- --BBBAAAAAAAAAAAAABBB-- -BBBAAAAAAAAAAAAAAABBB- -BBAAAAAAAAAAAAAAAAABB- -BBAAAAAAAAAAAAAAAAABB- -BBAAAAAAAAAAAAAAAAABB- BBBAAAAAAAAAAAAAAAAABBB BBBAAAAAAAAAAAAAAAAABBB BBBAAAAAAAAAAAAAAAAABBB -BBAAAAAAAAAAAAAAAAABB- -BBAAAAAAAAAAAAAAAAABB- -BBAAAAAAAAAAAAAAAAABB- -BBBAAAAAAAAAAAAAAABBB- --BBBAAAAAAAAAAAAABBB-- ---BBAAAAAAAAAAAAABB--- ---BBBBAAAAAAAAABBBB--- ----BBBBAAAAAAABBBB---- ------BBBBBBBBBBB------ -------BBBBBBBBB------- -----------B----------- 
----------------------- --------BBBBBBB-------- ------BBBBBBBBBBB------ -----BBBBAAAAABBBB----- ----BBBAAAAAAAAABBB---- ---BBBAAAAAAAAAAABBB--- --BBBAAAAAAAAAAAAABBB-- --BBAAAAAAAAAAAAAAABB-- -BBBAAAAAAAAAAAAAAABBB- -BBAAAAAAAAAAAAAAAAABB- -BBAAAAAAAAAAAAAAAAABB- -BBAAAAAAAAAAAAAAAAABB- -BBAAAAAAAAAAAAAAAAABB- -BBAAAAAAAAAAAAAAAAABB- -BBAAAAAAAAAAAAAAAAABB- -BBAAAAAAAAAAAAAAAAABB- -BBBAAAAAAAAAAAAAAABBB- --BBAAAAAAAAAAAAAAABB-- --BBBAAAAAAAAAAAAABBB-- ---BBBAAAAAAAAAAABBB--- ----BBBAAAAAAAAABBB---- -----BBBBAAAAABBBB----- ------BBBBBBBBBBB------ --------BBBBBBB-------- ----------------------- 
----------------------- ---------BBBBB--------- -------BBBBBBBBB------- -----BBBBAAAAABBBB----- ----BBBBAAAAAAABBBB---- ---BBBAAAAAAAAAAABBB--- ---BBAAAAAAAAAAAAABB--- --BBBAAAAAAAAAAAAABBB-- --BBAAAAAAAAAAAAAAABB-- -BBBAAAAAAAAAAAAAAABBB- -BBAAAAAAAAAAAAAAAAABB- -BBAAAAAAAAAAAAAAAAABB- -BBAAAAAAAAAAAAAAAAABB- -BBAAAAAAAAAAAAAAAAABB- -BBAAAAAAAAAAAAAAAAABB- -BBBAAAAAAAAAAAAAAABBB- --BBAAAAAAAAAAAAAAABB-- --BBBAAAAAAAAAAAAABBB-- ---BBAAAAAAAAAAAAABB--- ---BBBAAAAAAAAAAABBB--- ----BBBBAAAAAAABBBB---- -----BBBBAAAAABBBB----- -------BBBBBBBBB------- ---------BBBBB--------- ----------------------- 
----------------------- ----------------------- --------BBBBBBB-------- ------BBBBBBBBBBB------ -----BBBBAAAAABBBB----- ----BBBAAAAAAAAABBB---- ---BBAAAAAAAAAAAAABB--- ---BBAAAAAAAAAAAAABB--- --BBBAAAAAAAAAAAAABBB-- --BBAAAAAAAAAAAAAAABB-- --BBAAAAAAAAAAAAAAABB-- --BBAAAAAAAAAAAAAAABB-- --BBAAAAAAAAAAAAAAABB-- --BBAAAAAAAAAAAAAAABB-- --BBAAAAAAAAAAAAAAABB-- --BBAAAAAAAAAAAAAAABB-- --BBBAAAAAAAAAAAAABBB-- ---BBAAAAAAAAAAAAABB--- ---BBBAAAAAAAAAAABBB--- ----BBBAAAAAAAAABBB---- -----BBBBAAAAABBBB----- ------BBBBBBBBBBB------ --------BBBBBBB-------- ----------------------- ----------------------- 
----------------------- ----------------------- ----------BBB---------- -------BBBBBBBBB------- ------BBBBBBBBBBB------ -----BBBBAAAAABBBB----- ----BBBAAAAAAAAABBB---- ---BBBAAAAAAAAAAABBB--- ---BBAAAAAAAAAAAAABB--- ---BBAAAAAAAAAAAAABB--- --BBBAAAAAAAAAAAAABBB-- --BBBAAAAAAAAAAAAABBB-- --BBBAAAAAAAAAAAAABBB-- --BBBAAAAAAAAAAAAABBB-- --BBBAAAAAAAAAAAAABBB-- ---BBAAAAAAAAAAAAABB--- ---BBAAAAAAAAAAAAABB--- ---BBBAAAAAAAAAAABBB--- ----BBBBAAAAAAABBBB---- -----BBBBAAAAABBBB----- ------BBBBBBBBBBB------ -------BBBBBBBBB------- ----------BBB---------- ----------------------- ----------------------- 
----------------------- ----------------------- ----------------------- ---------BBBBB--------- -------BBBBBBBBB------- ------BBBBBBBBBBB------ -----BBBAAAAAAABBB----- ----BBBAAAAAAAAABBB---- ----BBAAAAAAAAAAABB---- ---BBBAAAAAAAAAAABBB--- ---BBAAAAAAAAAAAAABB--- ---BBAAAAAAAAAAAAABB--- ---BBAAAAAAAAAAAAABB--- ---BBAAAAAAAAAAAAABB--- ---BBAAAAAAAAAAAAABB--- ---BBBAAAAAAAAAAABBB--- ----BBAAAAAAAAAAABB---- ----BBBAAAAAAAAABBB---- -----BBBBAAAAABBBB----- ------BBBBBBBBBBB------ -------BBBBBBBBB------- ---------BBBBB--------- ----------------------- ----------------------- ----------------------- 
----------------------- ----------------------- ----------------------- ----------------------- ---------BBBBB--------- -------BBBBBBBBB------- ------BBBBAAABBBB------ -----BBBBAAAAABBBB----- -----BBBAAAAAAABBB----- ----BBBAAAAAAAAABBB---- ----BBAAAAAAAAAAABB---- ----BBAAAAAAAAAAABB---- ----BBAAAAAAAAAAABB---- ----BBAAAAAAAAAAABB---- ----BBBAAAAAAAAABBB---- ----BBBAAAAAAAAABBB---- -----BBBAAAAAAABBB----- -----BBBBAAAAABBBB----- ------BBBBBBBBBBB------ -------BBBBBBBBB------- ---------BBBBB--------- ----------------------- ----------------------- ----------------------- ----------------------- 
----------------------- ----------------------- ----------------------- ----------------------- ----------------------- ----------BBB---------- --------BBBBBBB-------- -------BBBBBBBBB------- ------BBBAAAAABBB------ ------BBBAAAAABBB------ -----BBBAAAAAAABBB----- -----BBBAAAAAAABBB----- -----BBBAAAAAAABBB----- -----BBBAAAAAAABBB----- -----BBBAAAAAAABBB----- ------BBBAAAAABBB------ ------BBBAAAAABBB------ -------BBBBBBBBB------- --------BBBBBBB-------- ----------BBB---------- ----------------------- ----------------------- ----------------------- ----------------------- ----------------------- 
----------------------- ----------------------- ----------------------- ----------------------- ----------------------- ----------------------- ----------------------- ---------BBBBB--------- --------BBBBBBB-------- -------BBBBBBBBB------- -------BBBBBBBBB------- -------BBBBBBBBB------- -------BBBBBBBBB------- -------BBBBBBBBB------- -------BBBBBBBBB------- -------BBBBBBBBB------- --------BBBBBBB-------- ---------BBBBB--------- ----------------------- ----------------------- ----------------------- ----------------------- ----------------------- ----------------------- ----------------------- 
----------------------- ----------------------- ----------------------- ----------------------- ----------------------- ----------------------- ----------------------- ----------------------- ----------------------- ----------BBB---------- ----------BBB---------- ---------BBBBB--------- ---------BBBBB--------- ---------BBBBB--------- ----------BBB---------- ----------BBB---------- ----------------------- ----------------------- ----------------------- ----------------------- ----------------------- ----------------------- ----------------------- ----------------------- ----------------------- 
