model
size = 12 31 19, scale = 0.05, origin = -y
material 
  colors = A:#111 B:#555 C:#777 D:#222 E:#BBB F:#444
voxels
------------ ------------ -----------A ------------ ------------ ------------ ------------ ------------ ------------ ------------ ------------ ------------ ------------ ------------ ------------ ------------ ------------ ------------ ------------ ------------ ------------ ------------ ------------ ------------ ------------ ------------ ------------ ------------ ------------ ------------ ------------ 
------------ ------------ -----------A ------------ ------------ ------------ ------------ ------------ ------------ ------------ ------------ ------------ ------------ ------------ ------------ ------------ ------------ ------------ ------------ ------------ ------------ ------------ ------------ -----AA----- ------------ ------------ --------A--- ------------ ------------ ------------ ------------ 
------------ ------------ -----------A ----------AA ------------ ------------ ------------ ------------ ------------ ------------ ------------ ------------ ------------ ------------ ------------ ------------ ------------ ------------ ------------ ------------ ------------ ------------ ------------ -----AA----- ------------ ------------ ------------ ---------A-- ------------ ------------ ------------ 
------------ ------------ ------------ ----------A- ---------A-- ------------ ------------ ------------ ------------ ------------ ------------ ------------ ------------ ------------ ------------ ------------ ------------ ------------ ------------ ------------ ------------ ------------ ------A----- ----AAAA---- ---A-AA----- ------------ ------------ ---------A-- ------------ ------------ ------------ 
------------ ------------ ------------ ------------ ---------A-- --------AA-- ------------ ------------ ------------ ------------ ------------ ------------ ------------ ------------ ------------ ------------ ------------ ------------ ------------ ------------ ------------ ------------ ----AAA----- ----AAAD---- ---A-AA----- ------------ ---------A-- ------------ ------------ ---------A-- ------------ 
---------A-- ------------ ------------ --------A--- --------A--- --------A--- --------A--- --------A--- --------A--- --------A--- --------A--- --------A--- --------A--- ------------ ------------ ------------ ------------ ------------ ------------ ------------ -----B------ -----BB----- -----CB----- -----CDD---- -----A------ ------------ --------A--- ------------ ------------ --------A--- ------------ 
---------A-- ---------A-- ------AA-A-- ------A-AA-- ------A-AA-- ------A-AA-- ------A-AA-- ------A-AA-- ------A-A--- ------D-A--- ------D-A--- ------D-A--- ------D-A--- ------D-A--- ------D----- ------------ -----B------ -----B------ ----CBBD---- ----CBBDD--- ----CBBDD--- ----CBAD---- ----CBAD---- -----CAA---- -----AAA---- ----AAAAA--- -------AA--- ------------ --------AA-- ------------ ------------ 
------------ ---------A-- -----ADB-A-- ----AABABA-- ----AABABA-- ----AABABA-- ----AABABA-- ----AABABA-- ----AABAAA-- ----AABAAA-- ----AABAAA-- ----AABABA-- ----AABABA-- ----AABAA--- -----BBA---- ----BBBB---- -----BBB---- ---CCBBB---- ---CABABD--- --CCABABD--- --ECABABD--- --EEABABA--- A-CCABABA--- --ACCBBBA--- --CCBBBBA--- ----AAAAA--- -----AAAA--- ------------ --------AA-- ------------ ------------ 
------------ ------------ ------AB-A-- ------ABAA-- ------ABAA-- ------ABAA-- ------ABAA-- ------ABAA-- ------ABAAA- ------ABAAA- ----AABAAAA- ----AABABAA- ----AABABA-- ----AABAA--- ----BABA---- ----BBABB--- ---BCBABA--- ---EABABA--- --EBABABA--- --EBABABA--- --EBABABA--- --EBABABA--- AABBABABA--- -AAAAAAAA--- --AAAAAAA--- ---AAAAAAA-- ----AAAAAA-- ----CC--AA-- ------------ --------AA-- --------AA-- 
------------ ------------ ------------ -------A-A-- -------A---- -------A-A-- -------A-A-- -------A-A-- -------A-AA- -------A-AA- ------ABBAA- ----AABABAA- ----AABABA-- ----AABAAA-- ----BABA---- ----BBABA--- ---BABABA--- --FBABABA--- --FBABABA--- --EBABABA--- --FBABABA--- --EBABABA--- --EBABABA--- -ABBBBBBA--- -AABBBBBA--- --DAAAAAAA-- ----CAAAAA-- ----CC-AAA-- --------AA-- --------AA-- ------------ 
------------ ------------ ------AB-A-- ------ABAA-- ------ABAA-- ------ABAA-- ------ABAA-- ------ABAA-- ------ABAAA- ------ABAAA- ----AABAAAA- ----AABABAA- ----AABABA-- ----AABAA--- ----BABA---- ----BBABB--- ---BCBABA--- ---EABABA--- --EBABABA--- --EBABABA--- --EBABABA--- --EBABABA--- AABBABABA--- -AAAAAAAA--- --AAAAAAA--- ---AAAAAAA-- ----AAAAAA-- ----CC--AA-- ------------ --------AA-- --------AA-- 
------------ ---------A-- -----ADB-A-- ----AABABA-- ----AABABA-- ----AABABA-- ----AABABA-- ----AABABA-- ----AABAAA-- ----AABAAA-- ----AABAAA-- ----AABABA-- ----AABABA-- ----AABAA--- -----BBA---- ----BBBB---- -----BBB---- ---CBBBB---- ---CABABD--- --CCABABD--- --ECABABD--- --EEABABA--- A-CCABABA--- --ACCBBBA--- --CCBBBBA--- ----AAAAA--- -----AAAA--- ------------ --------AA-- ------------ ------------ 
---------A-- ---------A-- ------AA-A-- ------A-AA-- ------A-AA-- ------A-AA-- ------A-AA-- ------A-AA-- ------A-A--- ------D-A--- ------D-A--- ------D-A--- ------D-A--- ------D-A--- ------D----- ------------ -----B------ -----B------ ----CBBD---- ----CBBDD--- ----CBBDD--- ----CBAD---- ----CBAD---- -----CAA---- -----AAA---- ----AAAAAA-- -------AA--- ------------ --------AA-- ------------ ------------ 
---------A-- ------------ ------------ --------A--- --------A--- --------A--- --------A--- --------A--- --------A--- --------A--- --------A--- --------A--- --------A--- ------------ ------------ ------------ ------------ ------------ ------------ ------------ -----B------ -----BB----- -----BB----- -----CCD---- -----A------ ------------ --------A--- ------------ ------------ --------A--- ------------ 
------------ ------------ ------------ ------------ ---------A-- --------AA-- ------------ ------------ ------------ ------------ ------------ ------------ ------------ ------------ ------------ ------------ ------------ ------------ ------------ ------------ ------------ ------------ -----AA----- ----AAAD---- ---A-AA----- ------------ ---------A-- ------------ ------------ ---------A-- ------------ 
------------ ------------ ------------ ----------A- ---------A-- ------------ ------------ ------------ ------------ ------------ ------------ ------------ ------------ ------------ ------------ ------------ ------------ ------------ ------------ ------------ ------------ ------------ -----A------ -----AAA---- ---A-AA----- ------------ ------------ ---------A-- ------------ ------------ ------------ 
------------ ------------ -----------A ----------AA ------------ ------------ ------------ ------------ ------------ ------------ ------------ ------------ ------------ ------------ ------------ ------------ ------------ ------------ ------------ ------------ ------------ ------------ ------------ -----AA----- ------------ ------------ ------------ ---------A-- ------------ ------------ ------------ 
------------ ------------ -----------A ------------ ------------ ------------ ------------ ------------ ------------ ------------ ------------ ------------ ------------ ------------ ------------ ------------ ------------ ------------ ------------ ------------ ------------ ------------ ------------ -----AA----- ------------ ------------ --------A--- ------------ ------------ ------------ ------------ 
------------ ------------ -----------A ------------ ------------ ------------ ------------ ------------ ------------ ------------ ------------ ------------ ------------ ------------ ------------ ------------ ------------ ------------ ------------ ------------ ------------ ------------ ------------ ------------ ------------ ------------ ------------ ------------ ------------ ------------ ------------ 
