model
size = 26 29 22, scale = 0.05, origin = -y
material 
  colors = A:#606 B:#111 C:#222 D:#63F E:#EEE F:#66F G:#001
voxels
-------------------------- -------------------------- -------------------------- -------------------------- -------------------------- -------------------------- -------------------------- -------------------------- -------------------------- -------------------------- -------------------------- -------------------------- -------------------------- -------------------------- -------------------------- -------------------------- -------------------------- -------------------------- -------------------------- -------------------------- -------------------------- ----------BBBBBB---------- ----------BBBBBB---------- -------------------------- -------------------------- -------------------------- -------------------------- -------------------------- -------------------------- 
-------------------------- -------------------------- -------------------------- -------------------------- -------------------------- -------------------------- -------------------------- -------------------------- -------------------------- -------------------------- -------------------------- -------------------------- -------------------------- -------------------------- -------------------------- -------------------------- -------------------------- -------------------------- -------------------------- -------------------------- --------BBBBBBBBBB-------- ------BBBBBBBBBBBBBB------ ---------BBBCBBBB--------- -------------------------- -------------------------- -------------------------- -------------------------- -------------------------- -------------------------- 
-------------------------- -------------------------- -------------------------- -------------------------- -------------------------- -------------------------- -------------------------- -------------------------- -------------------------- -------------------------- -------------------------- -------------------------- -------------------------- -------------------------- -------------------------- -------------------------- -------------------------- -------------------------- -------------------------- ---------BBBBBBBB--------- ----BBBBBBBBBBBBBBBBBB---- ----BBBCCCCCBBBBBBBBBB---- -------------------------- -------------------------- -------------------------- -------------------------- -------------------------- -------------------------- -------------------------- 
-------------------------- -------------------------- -------------------------- -------------------------- -------------------------- -------------------------- -------------------------- -------------------------- -------------------------- -------------------------- -------------------------- -------------------------- -------------------------- -------------------------- -------------------------- -------------------------- -------------------------- -------------------------- -------------------------- ------BBBBBBBBBBBBBB------ ----BBBBCBBBBBBBBBBBBBC--- ----CCCC----------BBBB---- -------------------------- -------------------------- -------------------------- -------------------------- -------------------------- -------------------------- -------------------------- 
-------------------------- -------------------------- -------------------------- -------------------------- -------------------------- -------------------------- -------------------------- -------------------------- -------------------------- -------------------------- -------------------------- -------------AA----------- -------------DA----------- --------------A----------- -------------------------- -------------------------- -------------------------- -------------------------- -------------------------- ---BBBBBBBBBBBBBBBBBBBBB-- ---BBCCC----------BBBBBC-- -------------------------- -------------------------- -------------------------- -------------------------- -------------------------- -------------------------- -------------------------- -------------------------- 
-------------------------- -------------------------- -------------------------- -------------------------- -------------------------- -------------------------- -------------------------- -------------------------- -------------------------- -------------AA----------- -------------AA----------- ------------A--A---------- ------------A--A---------- -------------A-A---------- --------------AA---------- -------------------------- -------------------------- -------------------------- -------------------------- --BBBBBBBBBBBBBBBBCBBBBC-- ---CCB-----CCCCB----BBBC-- -------------------------- -------------------------- -------------------------- -------------------------- -------------------------- -------------------------- -------------------------- -------------------------- 
-------------------------- -------------------------- -------------------------- -------------------------- -----------AAADAA--------- ----------AAAADAAA-------- ----------DAAAAAAA-------- ---------DDAAAAAAAA------- ---------AAAAAAAAAA------- ---------AAAAAAAAAA------- ---------AAAAAAAAAA------- ---------AAAAAAAAAA------- ---------AAAAAABAAD------- ---------AAAAAAAAAA------- ---------AAAAAAAAAA------- ---------AAAAAAAAAA------- ---------AAAAAAAAAA------- ---------AAAAAAAADD------- -----------ADAAAAA-------- -BBBBBBBBBBBBBBBBBCBBBBBC- --------CBBBBBBBCC-------- ---------CCCBBBCC--------- ----------BBBBBB---------- ----------BBBBBB---------- -----------BBBBB---------- ------------BBB----------- -------------------------- -------------------------- -------------------------- 
-------------------------- -------------------------- -------------------------- -------------AAAA--------- --------A-AAAAAAAAA------- -------AAAAAAAAAAAA------- -------AAAAAAAAAAAA------- -------AAAAAAAAAAAA------- -------AAAAAAAAAAAA------- -------AAAAAAAAAAAA------- -------AAAAAAAAAAAA------- -------AAAAAAAAAAAA------- -------AAAAAAAAAAAA------- -------AAAAAAAAAAAA------- -------AAAAAAAAAAAA------- -------AAAAAAAAAAAA------- ------CAAAAAAAAAAAA------- -------AAAAAAAAAAAA------- -BB----AAAAAAAAAAAA-----B- -BBBBBBBBBBAAAAABBBBBBBBB- -------BBBBBAAABBBC------- --------BBBBBBBBBC-------- --------BBBBBBBBBC-------- --------CBBBBBBBBC-------- ---------CBBBBBBB--------- ---------BBBBBBBB--------- -------------------------- -------------------------- -------------------------- 
-------------------------- -------------------------- -------------------------- -----------AAAAA-A-------- -------AAAAAAAAAAAA------- -------AAAAAAAAAAAA------- -------AAAAAAAAAAAA------- -------AAAAAAAAAAAA------- -------AAAAAAAAAAAA------- -------AAAAAAAAAAAA------- -------AAAAAAAAAAAA------- -------AAAAAAAAAAAA------- ------EAAAAAAAAAAAA------- ------EAAAAAAAAAAAA------- ------FAAAAAAAAAAAA------- ------FAAAAAAAAAAAA------- -------AAAAAAAAAAAA------- ------CAAAAAAAAAAAA------- BBBB---AAAAAAAAAAAA----BBB BBBBBBBBAAAAAAAAAABBBBBBBB ------BBAAAAAAAAAABB------ -------BBBBBBBBBBBCC------ -------BBBBBBBBBBBCB------ --------BBBBBBBBBBC------- --------CBBBBBBBBBC------- --------CBBBBBBBBBC------- --------BBBBBBBBBBB------- --------BBBBBBBBBB-------- --------BBBB---BBB-------- 
-------------------------- -------------------------- -------------------------- ----------AAAAAA---------- -------AAAAAAAAAAAA------- -------AAAAAAAAAAAA------- -------AAAAAAAAAAAA------- -------AAAAAAAAAAAA------- -------AAAAAAAAAAAA------- -------AAAAAAAAAAAA------- -------AAAAAAAAAAAA------- -------AAAAAAAAAAAA------- ------GAAAAAAAAAAAA------- ------EAAAAAAAAAAAA------- ------EAAAAAAAAAAAA------- ------FAAAAAAAAAAAA------- -------AAAAAAAAAAAA------- ------CAAAAAAAAAAAA------- BBBB---AAAAAAAAAAAA----BBB BBBBBBBBAAAAAAAAAAABBBBBBB ------BBAAAAAAAAAABB------ ------BBBABBBBBBABBB------ -------BBABBBBBBABBB------ -------BB-BBBBBB-BBB------ -------BB-BBBBBB-BBB------ -------BB-BBBBBB-BBB------ --------B-BBBBBB-BB------- --------BBBBBBBBBBB------- --------BBBBBBBBBB-------- 
----------------AAA------- ----------------AAA------- -------------AA-AAD------- ---------AAAAAAAAAA------- -------AAAAAAAAAAAA------- -------AAAAAAAAAAAA------- -------AAAAAAAAAAAA------- -------BAAAAAAAAAAA------- -------AAAAAAAAAAAA------- -------AAAAAAAAAAAA------- -------AAAAAAAAAAAA------- -------AAAAAAAAAAAA------- ------EAAAAAAAAAAAA------- ------EAAAAAAAAAAAA------- ------FAAAAAAAAAAAA------- ------FAAAAAAAAAAAA------- -------AAAAAAAAAAAA------- ------CAAAAAAAAAAAA------- BBBB---AAAAAAAAAAAA----BBB BBBBBBBBAAAAAAAAAAABBBBBBB ------BBAAAAAAAAAAAB------ ------BBBBBBBBBBBBBB------ -------BBBBBBBBBBBBB------ -------BBBBBBBBBBBBB------ -------BBBBBBBBBBBBB------ -------BBBBBBBBBBBBB------ -------BBBBBBBBBBBBB------ --------BBBBBBBBBBB------- --------BBBBBBBBBB-------- 
----------------AAA------- ----------------AAA------- -----------AAAAAAAA------- ---------AAAAAAAAAA------- -------AAAAAAAAAAAA------- -------AAAAAAAAAAAA------- -------BAAAAAAAAAAA------- -------AAAAAAAAAAAA------- -------AAAAAAAAAAAA------- -------AAAAAAAAAAAA------- ------GAAAAAAAAAAAA------- -------AAAAAAAAAAAA------- -------AAAAAAAAAAAA------- -------AAAAAAAAAAAA------- -------AAAAAAAAAAAA------- -------AAAAAAAAAAAA------- -------AAAAAAAAAAAA------- -------AAAAAAAAAAAA------- BBBB---AAAAAAAAAAAA----BBB BBBBBBBBAAAAAAAAAAABBCBBBB ------BBAAAAAAAAAAAB------ ------BBBBBBBBBBBBBB------ ------BBBBBBBBBBBBBB------ -------BBBBBBBBBBBBB------ -------BBBBBBBBBBBBB------ -------BBBBBBBBBBBBB------ -------BBBBBBBBBBBBB------ --------BBBBBBBBBBB------- -------------------------- 
---------------AAAA------- ---------------AAAA------- -----------AAAAAAAA------- ---------AAAAAAAAAA------- -------AAAAAAAAAAAA------- -------AAAAAAAAAAAA------- -------BAAAAAAAAAAA------- -------AAAAAAAAAAAA------- -------AAAAAAAAAAAA------- ------GAAAAAAAAAAAA------- -------AAAAAAAAAAAA------- -------AAAAAAAAAAAA------- -------AAAAAAAAAAAA------- -------AAAAAAAAAAAA------- -------AAAAAAAAAAAA------- -------AAAAAAAAAAAA------- -------AAAAAAAAAAAA------- -------AAAAAAAAAAAA------- BBBB---AAAAAAAAAAAA----BBB BBBBBBBBAAAAAAAAAAABBCBBBB ------BBAAAAAAAAAAAB------ ------BBBBBBBBBBBBBB------ -------BBBBBBBBBBBBB------ -------BBBBBBBBBBBBB------ -------CBBBBBBBBBBBB------ -------CBBBBBBBBBBBB------ --------BBBBBBBBBBB------- --------BBBBBBBBBBB------- --------BBBBBBBBBB-------- 
----------------AAA------- ----------------AAA------- -------------AA-AAA------- ---------AAAAAAAAAA------- -------AAAAAAAAAAAA------- -------AAAAAAAAAAAA------- -------BAAAAAAAAAAA------- -------AAAAAAAAAAAA------- -------AAAAAAAAAAAA------- -------AAAAAAAAAAAA------- -------AAAAAAAAAAAA------- -------AAAAAAAAAAAA------- ------EAAAAAAAAAAAA------- ------EAAAAAAAAAAAA------- ------FAAAAAAAAAAAA------- ------FAAAAAAAAAAAA------- -------AAAAAAAAAAAA------- -------CAAAAAAAAAAA------- BBBB---AAAAAAAAAAAA----BBB BBBBBBBBAAAAAAAAAABBBBBBBB ------BBAAAAAAAAAABB------ -------BBBBBBBBBBBBB------ -------BBBBBBBBBBBBB------ -------BBBBBBBBBBBBB------ --------BBBBBBBBBBB------- --------BBBBBBBBBBB------- --------BBBBBBBBBBB------- --------BBBBBBBBBBB------- --------BBBBBBBBBB-------- 
-------------------------- -------------------------- -------------------------- ----------AAAAAA---------- -------AAAAAAAAAAAA------- -------AAAAAAAAAAAA------- -------AAAAAAAAAAAA------- -------BAAAAAAAAAAA------- -------AAAAAAAAAAAA------- -------AAAAAAAAAAAA------- -------AAAAAAAAAAAA------- -------AAAAAAAAAAAA------- ------GAAAAAAAAAAAA------- ------EAAAAAAAAAAAA------- ------EAAAAAAAAAAAA------- ------FAAAAAAAAAAAA------- -------AAAAAAAAAAAA------- ------CAAAAAAAAAAAA------- BBBB---AAAAAAAAAAAA----BBB BBBBBBBBBAAAAAAAABBBBBBBBB -------BBAAAAAAAABBB------ -------BBBBBBBBBBBBC------ --------BBBBBBBBBBB------- --------BBBBBBBBBBB------- --------CBBBBBBBBBB------- --------BBBBBBBBBBB------- --------CBBBBBBBBB-------- --------CBB-----BB-------- -------------------------- 
-------------------------- -------------------------- -------------------------- -------------AAAA--------- -------AA-AAAAAAAAA------- -------AAAAAAAAAAAA------- -------AAAAAAAAAAAA------- -------AAAAAAAAAAAA------- -------AAAAAAAAAAAA------- -------AAAAAAAAAAAA------- -------AAAAAAAAAAAA------- -------AAAAAAAAAAAA------- ------EAAAAAAAAAAAA------- ------EAAAAAAAAAAAA------- ------FAAAAAAAAAAAA------- ------FAAAAAAAAAAAA------- -------AAAAAAAAAAAA------- ------CAAAAAAAAAAAA------- -BB----AAAAAAAAAAAA-----B- -BCBBBBBBBAAAAAABBBBBBBBB- -------BBBBAAAAABBB------- --------BBBBBBBBBBC------- --------BBBBBBBBBB-------- --------BBBBBBBBBB-------- --------BBBBBBBBBB-------- --------CBBBBBBBBB-------- -------------------------- -------------------------- -------------------------- 
-------------------------- -------------------------- -------------------------- ---------------A---------- --------AAAAAAAAAA-------- -------AAAAAAAAAAAA------- -------AADAAAAAAAAA------- -------ADAAAAAAAAAA------- -------AAAAAAAAAAAA------- -------AAAAAAAAAAAA------- -------AAAAAAAAAAAA------- -------AAAAAAAAAAAA------- -------AAAAAAAAAAAA------- -------AAAAAAAAAAAA------- -------AAAAAAAAAAAA------- -------AAAAAAAAAAAA------- ------CAAAAAAAAAAAA------- -------AAAAAAAAAAAA------- -------AAAAAAAAAAAA------- --CBBBBBBBBBBBBBBBBBBBBB-- ---CB-----BCBBBB-----BBB-- -----------BBCBB---------- -------------------------- -------------------------- -------------------------- -------------------------- -------------------------- -------------------------- -------------------------- 
-------------------------- -------------------------- -------------------------- -------------------------- -----------AAAAAA--------- ----------DAAAAAAA-------- ----------AAAAAAAA-------- ---------DAAAAAAAAA------- ---------AAAAAAAAAA------- ---------AAAAAAAAAA------- ---------AAAAAAAAAA------- ---------AAAAAA-AAA------- ---------AAAAAA-AAA------- ---------AAAAAAAAAA------- ---------AAAAAAAAAA------- ---------AAAAAAAAAA------- ---------AAAAAAAAAA------- ---------AAAAAAAAAA------- -----------AAAAAAA-------- --BBBBBBBBBBBBBBBBBBBBBB-- ---CBBBB----CCCC---BBBBB-- -------------------------- -------------------------- -------------------------- -------------------------- -------------------------- -------------------------- -------------------------- -------------------------- 
-------------------------- -------------------------- -------------------------- -------------------------- -------------------------- -------------------------- -------------------------- -------------------------- -------------------------- --------------AA---------- -------------AAA---------- ------------AAAA---------- ------------AAAA---------- -------------AA----------- -------------AA----------- -------------------------- -------------------------- -------------------------- -------------------------- ---BBBBBBBBBBBBBBBBBBBBB-- ---CCBBBBB------BBBBBBBB-- -------------------------- -------------------------- -------------------------- -------------------------- -------------------------- -------------------------- -------------------------- -------------------------- 
-------------------------- -------------------------- -------------------------- -------------------------- -------------------------- -------------------------- -------------------------- -------------------------- -------------------------- -------------------------- --------------A----------- -------------DA----------- -------------AA----------- -------------------------- -------------------------- -------------------------- -------------------------- -------------------------- -------------------------- -----BBBBBBBBBBBBBBBB----- ----BBBBBBBBBBBBBBBBBBB--- ----CCB-------------BB---- -------------------------- -------------------------- -------------------------- -------------------------- -------------------------- -------------------------- -------------------------- 
-------------------------- -------------------------- -------------------------- -------------------------- -------------------------- -------------------------- -------------------------- -------------------------- -------------------------- -------------------------- -------------------------- -------------------------- -------------------------- -------------------------- -------------------------- -------------------------- -------------------------- -------------------------- -------------------------- -------------------------- -------BBBBBBBBBBBBB------ -----BBBBBBBBBBBBBBBB----- -------------------------- -------------------------- -------------------------- -------------------------- -------------------------- -------------------------- -------------------------- 
-------------------------- -------------------------- -------------------------- -------------------------- -------------------------- -------------------------- -------------------------- -------------------------- -------------------------- -------------------------- -------------------------- -------------------------- -------------------------- -------------------------- -------------------------- -------------------------- -------------------------- -------------------------- -------------------------- -------------------------- -------------------------- --------BBBBBBBBBBB------- ---------BBBBBBBB--------- -------------------------- -------------------------- -------------------------- -------------------------- -------------------------- -------------------------- 
