model
size = 32 21 17, scale = 0.05, origin = -y
material 
  colors = A:#BEBED6 B:#EEE C:#9CF D:#5F5FA6 E:#AAA F:#777 G:#888 H:#2F2F8E I:#8E8EBE J:#444 K:#BBB L:#111 M:#222 N:#555
voxels
52-5K28-2G635-5K26-6E87-A31-4(IA30-)DA30-D356-2K22-GE3-G2E2-2E19-3E2K2G4EG20-7E27-DI-EAE27-F2-3E27-F-3A27-F-A2E27-F-IAI27-FBAE27-J-2A23-2D2I2D2E24-8E24-2I3E282-2G13E16-4D-7C2-2B17-3J-6C3E22-2D5-C2E24-DF3-2CEB25-F3BC2E25-F2B-C2EA23-J-2B-CIA23-2J-2BC2EA21-3J2-2B3E18-JA2J6B2E21-L3B4CBE23-D-2C-3D25-D2HD220-7G23-2E-6A5E15-2DJ-G-8AC2-B15-JN3-7A-2C2B15-5F-6A-2C2B16-A2-A2F4-A2-2C2B15-B2-BABFJ3-A-ACBA14-B2-B3-AJ3-A-A2CA14-B2-B-2AFB3-A-ACAI13-2F-F2A2F2B2-C2-2C2A12-5D2F4B3-2C-2A14-LM-C3B4C-2C2A18-B4C4BC-2D20-L2C2B3A2D22-D5H2D216-11G19-2D-2C6-2C2E15-D2JC-G-5A3-3CA14-J-C4B5A2-2AC-B13-FA-4B5-A-2A-C2B12-FA10B-A-2A2C2B16-3B2-3BA2-A-C2A16-B2AB-3BA2-2AC2A10-B4-2A7BA2-2AC2I9-DF2-D9B-A-2A2C2A8-I2D3-C8B3A2C-2A10-2D2-C-3C3B-3A2C2A14-MBC4-4A-2C3D16-2LA6-2AHD20-D5A2(HD)23-2D3H158-6F22-4G6A2G18-2D2A4-A4-C3E13-DJ-C-A2G6A2-A3CB12-G-C-4BA2-2(A-)3AC-B11-FA-A5B2A2BA-2A-AC-B10-FB-11BA-4ACA11-B3-A8BA2-A-2ACA14-AB2-5BA2-4AC2A6-DF-4A2-7BA2-4AC2A5-ID5-10BA-4A2C2A6-A2C4-8BA2-2A3C2A7-DI4-A3-4BA2-2A2CA2I10-D3-4A3-3A3C3D13-D-C2-5A2-C3D17-DC4-4AHD21-D8H153-8F22-2G3A4-A3G17-2DA2-5A3-2C2E14-DC2-9A2-A-2CB11-J2C-6A2-3A-4ACB10-GA-15A-2ACA9-FA2-12A-7A11-14A-A-3ACA9-15A-5AC-AI3-I18A-6AC3AI-3D15A-6A2C3AI-D2-D14A-5AC-2A5-3D12A2-4A2C2I9-2D11A-2A3C2D12-D2A-6A2-3C3D15-D2C6-2A3D19-9HD152-8F22-2GA7-3G16-3DA2-5A4-C3E12-DIC2-9A2-A-2CB11-D3-6A2-3A-4A2CB9-3A-14A-A-CA9-FA2-12A-7A5-B5-14A-A-3ACA3-2B5-14A-6A3CBIB19A-9A2CI3D15A-8A4CI2D-15A-6AC2A4I-D14A2-5A2CI3-DID2-2D12A-4A2C2D5-2D4-D2A-6A4-2CH2D8-D5-2HC8-3C2D10-H7-6H3CD2H26-2H4D28-H4D28-4D29-4D19-8F22-2G3A4-A3G17-2DA2-5A3-2C2E14-DC2-9A2-A-2CB11-J2C-A2BABA2-ABA-4ACB10-GA-2A5B2A2B4A-2ACB9-FA2-11BA-5ACA11-4A8B2A-A-3ACA9-5A8B2A-5AC-AI3-I7A9B2A-6AC3AI-D3A13BA-6A2C3AI-D2-DA11B2A-5AC-2A5-2DA3BA7BA2-4A2C2I9-D2B5A3B2A-2A3C2D12-D2A-6A2-3C3D15-D2C6-2A3D19-D8HD154-6F22-4G6A2G18-2D2A4-A4-C3E13-2D-C-A2G6A2-A3CB12-J-C-4BA2-2(A-)3AC-B11-FA-A5B2A2BA-2A-AC-B10-FB-11BA-4ACA11-B3-A8BA2-A-2ACA14-AB2-5BA2-4AC2A6-DF-4A2-7BA2-4AC2A5-ID5-10BA-4A2C2A6-A2C4-8BA2-2A3C2A7-DI4-A3-4BA2-2A2CA2I10-D3-4A3-3A3C3D13-D-C2-5A2-C3D17-DC4-4AHD21-D8H184-11G19-2D-2C6-2C2E15-2DJC-G-5A3-3CA14-J-C4B5A2-2AC-B13-FA-4B5-A-2A-C2B12-FA10B-A-2A2C2B16-3B2-3BA2-A-C2A16-B2AB-3BA2-2AC2A10-B4-2A7BA2-2AC2I9-DF2-D9B-A-2A2C2A8-I2D3-C8B3A2C-2A10-2D2-C-3C3B-3A2C2A14-MBC4-4A-2C3D16-2LA6-2AHD20-D5A3HD23-D3HD189-7G23-2E-6A5E16-2D-G-8AC2-B15-JN3-7A-2C2B15-5F-6A-2C2B16-A2-A2F4-A2-2C2B15-B2-BABFJ3-A-ACBA14-B2-B3-AJ3-A-A2CA14-B2-B-2AFB3-A-ACAI13-2F-F2A2F2B2-C2-2C2A13-3D3F4B3-2C-2A13-DLM-C3B4C-2C2A18-B4C4BC-2D20-L2C2B3A2D22-D6HD248-2G13E17-3D-7C2-2B17-3J-6C3E22-DJ5-C2E24-DF3-2CEB25-F3BC2E25-F2B-C2EA23-J-2B-CIA23-2J-2BC2EA21-3J2-2B3E18-JA2J6B2E21-L3B4CBE23-D-2C-3D25-2DHD230-2K22-GE3-G2E2-2E19-3E2K2G4EG20-2D5E27-JI-EAE27-F2-3E27-F-3A27-F-A2E27-F-IAI27-FBAE27-J-2A23-DE2(D2E)24-8E24-2I3E261-5K26-6E87-A31-IA30-AD3(30-2A)30-A357-5K28-2G585-
