model
size = 7 31 13, scale = 0.05, origin = -y
material 
  colors = A:#111 B:#DDD C:#888 D:#444
voxels
--CCC-- ------- ------- ------- ------- ------- ------- ------- ------- ------- ------- ------- ------- ------- ------- ------- ------- ------- ------- ------- ------- ------- ------- ------- ------- ------- ------- ------- ------- ------- ------- 
-CBBBC- --CCC-- ------- ------- ------- ------- ------- ------- ------- ------- ------- ------- ------- ------- ------- ------- ------- ------- ------- ------- ------- ------- ------- ------- ------- ------- ------- ------- ------- ------- ------- 
-CBBBB- -CBBBC- ------- ------- ------- ------- ------- ------- ------- ------- ------- ------- ------- ------- ------- ------- ------- ------- ------- ------- ------- ------- ------- ------- ------- ------- ------- ------- ------- ------- ------- 
-BBBBB- -BBBBB- ------- ------- ------- ------- ------- ------- ------- ------- ------- ------- ------- ------- ------- ------- ------- ------- ------- ------- ------- ------- ------- ------- ------- ------- ------- ------- ------- ------- ------- 
-BBBBB- -CBBBB- ------- ------- ------- ------- ------- ------- ------- ------- ------- ------- ------- ------- ------- ------- ------- ------- ------- ------- ------- ------- ------- ------- ------- ------- ------- ------- ------- ------- ------- 
-BBBBB- -CBBBB- ------- ------- ------- ------- ------- ------- ------- ------- ------- ------- ------- ------- ------- ------- ------- ------- ------- ------- ------- ------- ------- ------- ------- ------- ------- ------- ------- ------- ------- 
BBBBBBB BCBBBBC ------- ------- ------- ------- ------- ------- ------- ------- ------- ------- ------- ------- ------- ------- ------- ------- ------- ------- ------- ------- ------- ------- ------- ------- ------- ------- ------- ------- ------- 
BBBBBBB BBBBBBB ------- -AAAAA- ------- ------- ------- ------- ------- ------- ------- ------- ------- ------- ------- ------- ------- ------- ------- ------- ------- ------- ------- ------- ------- ------- ------- ------- ------- ------- ------- 
BBBBBBB BBBB-BB -AAAAAB AAAAAAA -AAAAD- -AAAAA- --AAA-- --AAA-- --AAA-- --AAA-- --AAA-- --AAA-- --AAA-- --AAA-- --AAA-- --AAA-- --AAA-- --AAA-- --AAA-- --AAA-- --AAA-- --AAA-- --AAA-- --AAA-- --AAA-- --AAA-- --AAA-- --AAA-- --AAA-- --AAA-- --AAA-- 
BBBBBBB BBBB-BB -BBB-B- AAAAAAA -AAAAA- -AAAAA- -AAAAA- -AAAAA- -AAAAA- -AAAAA- -AAAAA- -AAAAA- -AAAAA- -AAAAA- -AAAAA- -AAAAA- -AAAAA- -AAAAA- -AAAAA- -AAAAA- -AAAAA- -AAAAA- -AAAAA- -AAAAA- -AAAAA- -AAAAA- -AAAAA- -AAAAA- -AAAAA- -AAAAA- -AAAAA- 
BBBBBB- -BBBBB- -BBB-B- AAAAAAA -AAAAD- -AAAAA- -AAAAA- -AAAAA- -AAAAA- -AAAAA- -AAAAA- -AAAAA- -AAAAA- -AAAAA- -AAAAA- -AAAAA- -AAAAA- -AAAAA- -AAAAA- -AAAAA- -AAAAA- -AAAAA- -AAAAA- -AAAAA- -AAAAA- -AAAAA- -AAAAA- -AAAAA- -AAAAA- -AAAAA- -AAAAD- 
-BBBBB- -BBB-B- -BBBBB- AAAAAAA -AAAD-- --AAA-- --AAA-- --AAA-- --AAA-- --AAA-- --AAA-- --AAA-- --AAA-- --AAA-- --AAA-- --AAA-- --AAA-- --AAA-- --AAA-- --AAA-- --AAA-- --AAA-- --AAA-- --AAA-- --AAA-- --AAA-- --AAA-- --AAA-- --AAA-- --AAA-- --AAA-- 
-BBBBB- -BBBBB- --BBB-- --AAAA- ------- ------- ------- ------- ------- ------- ------- ------- ------- ------- ------- ------- ------- ------- ------- ------- ------- ------- ------- ------- ------- ------- ------- ------- ------- ------- ------- 
