model
size = 16 32 26, scale = 0.05, origin = -y
material 
  colors = A:#06F B:#06C C:#03C D:#039 E:#EEE F:#700 G:#400
voxels
40-3D2(13-ACA)13-3(2A14-)2A15-A14-3(3A13-)2(2A14-)2A15-A13-3A13-2(4A12-)4A13-3A2(14-2A)172-DB-D12-DC-B12-BC3(-B12-2A)-B12-2B-B2(12-AB2A12-4A)12-4A12-CA-A12-BC-A12-2A-A11-2(AC)A11-AC3A11-A2C3A10-2C4A11-5A11-2(4A12-)4A14-A141-D2BD12-DC-B12-2B-B12-2A-C12-2A-B12-2A-A12-2B-B11-BAB-A11-B2A-B11-BAB-B11-B2ABA11-3ABA11-ACA2B11-B2C2B11-A2C2A11-AC3A11-A2C2A11-A2B3A10-AC4A10-6A10-BAB2AB2(10-6A)11-2(4A12-)CAB14-2A95-D15-2(CA14-)2C13-2AB2(13-3A)12-2ABA12-2A-B11-3A-A11-3ABA11-3A2B11-AB3A11-B2CBA11-ABC2A11-A3CA11-ACB2A11-6A10-2BAC2A10-6A10-BA2B2A9-AB5A9-7A10-2(5A11-)2B3A12-3A255-B15-B14-2A13-ACA13-AC2A12-A2CA11-AB2A11-4A11-5ABA10-6A9-8A4(9-7A)10-5A12-4A14-A48-A2-AD7-5A2-AD7-4AB2-2A7-2A2CA-3A7-4AB-3A7-5A-2A8-5A-2A9-7A9-4AB2A9-6A11-AB3A11-A3B13-AB3(14-2A)13-C2A11-2AC4A8-B7A7-10A6-3ABC5A2(6-10A)6-8A2B2(6-10A)7-8A8-6A11-5A12-4A14-A32-3A-AD5-10AD5-11A5-4A4CA2C5-4A4C3A5-2AC7AB5-10A6-3AC5AC6-A-8A8-8A7-BAB4ABA8-3BAB3A8-7A8-8A7-8A9-A2CAB2A9-AB6A7-9A6-2B8A6-7AB3A5-4AB5A6-AB8A6-10A6-2AB7A2(6-10A)7-9A7-B6A9-7A10-5A13-2A32-5A4-C5AB6A4-6A2B4A2(5-11A)5-8AB2A5-AB6AB2A2(5-AB9A)5-A-9A4-2A4B6A5-2ABAB2A2B2A4-2A2B2AB5A5-2ABAB3AB7-2ABAB4A6-4A4C2A7-2AB4C2A5-3AC7A5-12A4-4AC7A4-2B5A2B3A4-10ABA3-B10ABA4-3A2B6A5-AC9A6-10A7-9A7-7A9-7A10-5A12-3A32-6A3-5A2B6A3(3-13A)3-6AC6A2(3-9A2B2A)2(4-11AB)4-5AB6A6-3A2B2ABAB4-A-BABCB5A3-2A2BAB7A4-2ABA2B6A3-9AB3A3-13A3-3ABAB7A2-13A3-2B2AB8A2-AC2BA3B2(2AB)2-5AB3AB2A2B2-12ABA3-4AB7AB3-2AB9A5-AB9A7-2AB6A7-8A8-7A9-D5A10-3D2A32-2C4A3-6AB6A3-6A2B5A3-7AB5A3-6A2B5A3-6AB6A3-AC4A2B2AB2A3-6A2B2AB2A3-2BA4B6A3-13A3-3AC2AB6A2-B5A2B6A3-6AB4A2B3-A-ABA2B6A4-2(2AB)6A2-4A2(BA)2B4A3-13A-AC5AB3A2B2A-15A-AB12A2(2-14A)2-11A3B2-13AB2-7AC6A3-B11A6-10A6-D8A7-D7A9-D5A10-5E13-3E17-5A-A-6AB6A2-A-4A3BAC3A2-7A2B5A2-7A2(B6A3-6A)2B5A2-14A2-4A4B6A2-AB8AC3A2-5A4B3ABA2-2B2A2C5A2BA2-4AC2A2C3BAB3-2B2A3B4ABA3-2ABA3B6A3-2(AB)A3B3ABA2-4AB5A2(BA)-AC4A2B2A3B2A-BAC4AB7A-3B12A-A2(B5A)BA2-B4AB7A3-B2A2BCA2B2A2B3-3AB8AB3-AB9A2B3-BD9AB4-BD10A6-E8A7-E7A8-E2A2E2A10-EA2-EA10-2E2-E17-5A2(-3A)2B6A-BAB-2A3BAB2C2A-3A-7AB3A-2A2B3AB2A2B3A-4AB2A4B4A-8ABAB4A-4AB5A2B3A-3A8B4A-6A2B3AC3A-5A7BA2B-B7A4B2AB-2AB2A2B2AB3ABA2-A2B4A2B3ABA2-2AB3ABCB5A2-AB4A3B2AB2A2-5ABA2B2A2BA-AC2BA5B2A3B-15A2-2(2AB)8A2-12A2B3-8AC2ABA-DFB3AB6ACA-2D12A3-GD2ABAB2AB3A4-FB9A5-F8A2B5-F9A7-EBA2E3A8-E2A2-EA9-EAE2-EA9-2E3-E17-2B3ADB2D-B5AB6A2D-6AB2C2ADA2DA2BA5B3ADABD3BA4B4ADA2DA2B4AB4ADA2D2AB4A2B3ADA2D2AB9ADA2DAB2A4B4ADA2D7ABC3ADA2D4ABAB2A2BADA2DC3A3B2A2BADA2DBAB2A2B3A2BDA2D2(4A2B)-2DAB4A2B2C3A-2D2B3A4B4A-3D4ABA2B2ABA-D2C2A6B2A2B-DF4AB8A-DB3A2B8A-DC4AB8A-D-8ACAB2A2-F4AB2AB3ABA2-F3A2B7A3-F2A5B5A4-F2A3B3ABA5-F5A2BA2B5-F9A7-G2A2EABA7-F2AE2-EA8-F2A3-EA8-F2E3-E17-2BA2BD3A-B3A4B3AD3A-2ABA4B3AD3AB2AC2B2(CB)2AD2(3AB)2CBCABAD5A2B2A5BCD4AB5ABAB2AD4AB7AB2AD2(4AB)2A2BAD6A2BA4B2AD7ABA2B2A2BD6A2BA2B2ABAD2A3BA2B5ABAD7A5BA2B-D6A3B2C3A-D2A2B2(AB)A2B2AB-D4AB3A3B2AB-DBC4AB2AB4A-DC8A2B3A-DC2A2BA4B3AB-DC12AB-2D8AC3AB2-F13A2-F12A3-FB10AB4-F10A5-F4ABAB2AB5-F3A2E4A7-G2A2-E2A7-F2AE2-EA8-F2A3-EA8-F2E3-E17-BC3A-A2C-5A2BC2(3A-)AB4ABC2(3A-)8AB2A-B4AC5AC2BA-2ABAB7AB2A-AC2ABA2B3ACB2A-AC4AB2A2BC2BA-A2C8AC3A-9A2BCBAB-4AB10A-B3AB10A-2A2(BA)B8A2-2AB6ABC3A2-ACB6A2B3A2-2ABAC2ACAC4A2-4ABA2CBC2BAB-ACB6A3BACA-ACB4A2B6A2-B5A4B4A2-B5A2B4A2B3-11A2B-DF12AB-2D9AB2A3-2D11A4-F10A5-F4ABA2B2A5-F4AB4A7-E2A2E3A8-EAE2-EA9-EA3-EA10-E3-E17-5A-A-13A2-A-12A2-ABA2C4A2B3A2-3A2C9A3-3AB5AB3A3-9A3BA2-10A2B2A2-5AB4A2B2A2-2(3AB)2A2BAB2-B9A2B2A2-6A2(B3A)2-2ABA2B4A2B2A2-2(BA)B2A5B2A2-AB2A2BA4B3A3-B3AB2AB5A2-3AC3BABCB3A2-3A2BABA2B4A-AB9A2B2A-AB8AC2B2A-AC6ABAC2ABA2-7ABAC2ABA2-AB5ABA2B2A3-B2A2BA4B3A3-11ABA3-2D2AB4AC2A4-2DAB8A6-E8A7-E7A8-E2A2E2A9-5EAB11-4E16-6A3-13A3-B12A3-AB7AB3A3-9AB3A3-13A3-2AB10A3-9AB3A3-9A2B2A3-4A2B3A2B2A3-4AB2A3B3A3-5AB3A2B2A4-4A2(2B2A)5-4A4B3A4-5A4B3A3-B2C10A3-A2C2A2(B3A)-10AB4A-10A2B2AB-10AB4A-8ABA2B3A-8ABA2B2A2-8AB5A2-7A4B3A2-13A4-4AB7A6-10A6-D8A7-D7A9-D5A10-E2ABA32-6A2(3-13A)3-8AB4A2(3-13A)3-9AB3A3-7A2B4A4-6A2B4A4-7A4BA4-7A3B2A6-2AB2A3B2A5-2(3AB)3A5-2A2B5AB5-4A2(B2A)BA3-12AB3-5A2(B3A)3-6A2BAB3A-13A4-8A2(BA)3-5AB3A3B2A2-5AB4AB3A2-5AB8A3-4AB6ABA3-12A5-3AB7A7-9A7-3AB4A8-7A9-D5A10-E2D2A32-3A6-C10A6-12A2(5-11A)5-10A6-7AB3A5-2(3AB6A6-)B-AB6A6-2A4BAB2A6-3A3BAB2A6-3AB3A2B-B5-5AB4A6-8A8-9A7-9A5-7AB3A5-11A5-9AB2A4-12A4-AB9A4-12A5-11A5-2AB8A6-10A7-9A7-3AB3A9-6A11-5A12-D2A32-2A9-7A9-6AB2A7-8A2-B5-2(9A7-)7A2B7-10A6-10A7-8A9-8A8-5A2BA8-5A2B7-5AB2AB7-5ABAB9-4ABAB9-B5ABA7-5AB2A7-10A2(6-8ABA)2(6-5AB4A)6-4AB3ABA6-4AB5A7-3AB5A7-9A7-3AB3A9-6A11-5A13-2A32-B11-3A2B4(11-5A)-A9-AB3A-A10-2(7A9-)6A10-4ABA11-4A12-3A14-AB14-2B14-BA13-3A12-6A8-8A8-4AB3A8-9A2(7-4AB4A)3(7-9A)7-8A8-6A11-5A12-4A14-A223-A15-A14-2A13-3A13-AB2A12-2A4(BA11-3A)BA10-4AB2A9-7A9-6A10-AB5A9-7A10-2AB2A12-AB2A14-A79-D15-2(2A14-)2A3(13-3A)12-4A12-2A-A11-2AB-A11-A2B2A2(11-B4A)2(11-5A11-AB3A)2(11-5A)11-2AB2A11-6A9-6A10-6A3(11-5A)12-3A93-2DAD12-2(2A-2A11-)BA-A12-AB-A12-2A-B12-AB-A11-A2B2(-A11-3A)-A11-4AB3(11-5A)11-B4A11-4AB11-B3AB11-B5A10-6A10-5AB3(10-6A)11-2(4A12-)ABA14-2A93-DA-D3(12-2A-A)12-AB2(-A12-2A)-A12-AB2A4(12-4A)2(12-2A-A)12-BA-A2(11-5A)11-B5A10-B2(5A11-)2(4A12-)4A14-A142-3D2(13-3A)13-2A14-AB2(14-BA)15-A14-3(3A13-)2(2A14-)2A15-A13-3A13-2(4A12-)4A13-A2(BA14-)2A133-
