model
size = 21 25 31, scale = 0.05, origin = -y
material 
  colors = A:#E00 B:#B00 C:#EEE D:#DDD
voxels
--------------------- --------------------- ---------CCC--------- --------CCCCC-------- --------CCCCC-------- --------CCCCC-------- ---------CCC--------- --------------------- --------------------- --------------------- --------------------- --------------------- --------------------- --------------------- --------------------- --------------------- --------------------- --------------------- --------------------- --------------------- --------------------- --------------------- --------------------- --------------------- --------------------- 
--------------------- --------------------- -------CCCCDDD------- -------CCCCCCC------- -------CCCCDDD------- -------CCCCDCD------- -------CCCCDCD------- -------CCCCCC-------- --------CCCCC-------- --------------------- --------------------- --------------------- --------------------- --------------------- --------------------- --------------------- --------------------- --------------------- --------------------- --------------------- --------------------- --------------------- --------------------- --------------------- --------------------- 
--------------------- --------------------- -----CCCCCCCCCCD----- -----CCAAAAAAACC----- -----CCAAAAAADCC----- -----CCAAAAAAACC----- -----CCAAAAAAACD----- -----CCAAAAAACC------ -----CCCAAAAACC------ ------CCCCCCCC------- --------------------- --------------------- --------------------- --------------------- --------------------- --------------------- --------------------- --------------------- --------------------- --------------------- --------------------- --------------------- --------------------- --------------------- --------------------- 
------CCCCCDDD------- ------CCCCCCCD------- ----CCAAAAADDDCDC---- ----CAAAAAADA--DC---- ----CAAAAAADA--DC---- ----CAAAAAADA--AC---- ----CAAAAAADA-DDC---- ----CAABBBBBB-ACC---- ----CAABAAAAABAC----- -----CCBBBBBBBCC----- --------------------- --------------------- --------------------- --------------------- --------------------- --------------------- --------------------- --------------------- --------------------- --------------------- --------------------- --------------------- --------------------- --------------------- --------------------- 
------DAAAAAAAC------ ---CCCDAAAAAAACCC---- ---DDADAAAAAAAAAAD--- ---CDADAAAAAA---AC--- ---CDDDAAAAAA---AD--- ---CADDAAAAAA---AC--- ---CDDDAAAAAA---AD--- ---CAAABAAAAA--AAC--- ---CAAAAAAAAAAAACC--- ----CA-ABBBBBBBC----- --------------------- --------------------- --------------------- --------------------- --------------------- --------------------- --------------------- --------------------- --------------------- --------------------- --------------------- --------------------- --------------------- --------------------- --------------------- 
-----CAAAAADDDDD----- --CCCAAAAAAAADAACC--- --CADADAAAADADADDD--- --CAAAAAAAAAAAAAAC--- --DAAAAAAAADADADDD--- --CAAAAAAAAAAAAAAD--- --CADADAAAADDDDDAD--- --CAAAABBBABBBAAAC--- --CCBAAAABABAAABBC--- -----AABBBABABB------ ------ABABBBBB------- --------ABBBA-------- --------------------- --------------------- --------------------- --------------------- --------------------- --------------------- --------------------- --------------------- --------------------- --------------------- --------------------- --------------------- --------------------- 
-----DDAAAADDDDD----- --DCDAAAAAAAAAAADCD-- --DADADAAAADDDDADDD-- --CADAAAAAAADADAADD-- --DDDADAAAADDDDDDDD-- --CAAADAAAAAAAAAAAC-- --DDDADAAAADADAAADC-- --CAAAAAAAABABAAAAC-- --CBBAAAAAAAAAAABBC-- -----AAAAAAAABAB----- -----BAAAAAAAAB------ ------AAAAAAABB------ -------AAAAAAA------- --------AAABA-------- --------------------- --------------------- --------------------- --------------------- --------------------- --------------------- --------------------- --------------------- --------------------- --------------------- --------------------- 
--CCDADAAAADADDDDD--- --CAAAAAAAAAADAAAAC-- -CAAAADAAAADDDDDADC-- -CAAAAAAAAADAAAAAAC-- -CAAAADAAAADDDADDDD-- -CAAAAAAAAAAAAAAAAC-- -CAADADAAAADADADDDC-- -CAAAAABBBBBABAAAAC-- --CBAAAAABAAAAAABBC-- ----BAABABABBBAB----- ----BBBBBBAAAAAB----- -----BABABABBBAB----- ------BBABAAABB------ ------ABBBBBAB------- -------BBBAAA-------- --------BBAA--------- --------------------- --------------------- --------------------- --------------------- --------------------- --------------------- --------------------- --------------------- --------------------- 
--DDDADAAAAADDDADAD-- -CDAAAAAAAAADAAADAC-- -CDADDDAAAAADADDDAD-- -CAAAAAAAAAADAAAAAD-- -CDADDDAAAAADADDDADC- -CAAAADAAAAAAAAAAAAC- -DDDDADAAAAAAAAAAAAC- -CAAAAABAAABABAAAAC-- --CBAAAAAAAAAAAAABC-- ----BAABAAAAABAAB---- ----BAAAAAABBBBBB---- ----BAABABABABAA----- -----BABAB-BBBBB----- -----BABAB-AABB------ ------AAAA-BBB------- -------AAAABAB------- --------ABABA-------- ---------AAA--------- --------------------- --------------------- --------------------- --------------------- --------------------- --------------------- --------------------- 
-CAADADAAAAAAAAAAAD-- -CAAAAAAAAAAAAAAAAC-- -CAAAADAAAAAAAAAAAD-- -CAAAAAAAAAAAAAAAAAC- -CDADADAAAAAAAAADADC- -CAAAAAAAAAAAAAAAA-C- -CDAAADAAAAAAAAAAAAC- -CAAAAABABBBABAAAAAC- --CBAAAAABAAAAAAABC-- ----BAABBBBBABAAB---- ----BBABBBABAAAAB---- ----BBABBBABABAAB---- ----BBABABAAAAAB----- -----BABABABBBAB----- -----BBBABAAABBB----- ------AAABAAAAB------ ------BBABAAAA------- -------AAAAAA-------- --------AAAA--------- --------------------- --------------------- --------------------- --------------------- --------------------- --------------------- 
-CDDDADAAAAADADADDD-- -CDAAAAAAAAAAAAAAAC-- CDDDDADAAAAADADADDDC- CCAAAAAAAAAAAAAAAADCC CDDADADAAAAADDDDDA-CC -CAAAAAAAAAAAAAAAA-CC -CDADDDAAAAAAAAAAA-C- -CCAAAAAAAAAAAAAAACC- ---BAAAAAAAAAAAAB---- ----AAAAAAAAAAAAB---- ----AAABABABBBABB---- ----AAAAAAAAABABB---- ----AAAAABABBBAB----- ----BAAAAAABAAAB----- -----BAAABABABBB----- -----BAAAAABAAB------ ------ABABABABB------ ------AAAAAAAA------- -------AAAAAAA------- --------AAAAA-------- --------------------- --------------------- --------------------- --------------------- --------------------- 
-CAAAAAAAAAADAAAAAD-- CCAAAAAAAAAAAAAAAAC-- CCAAAAAAAAAADADADADC- CCAAAAAAAAAAAAAAAA-CC CCAAAAAAAAAADADAAA-C- CCAAAAAAAAAAAAAAAA-CC -CAAAAAAAAAAAAAAAA-C- -CCAAAAAAAAAAAAAABCC- ---BAAAAAAAAAAAAB---- ----AAAAAAAAAAAAB---- ----BBBBABAAAAABB---- ----ABAAAAAAAAAAA---- ----ABABBBAAAAAAA---- ----AAAAAAAAAAAA----- ----BBABBBAAAAAA----- -----BAAABAA-AAB----- -----BBBABAA-AB------ ------AAAAAA-AB------ ------AAAAAAAB------- -------AAAAAAA------- --------AAAAA-------- --------------------- --------------------- --------------------- --------------------- 
-CAAAAAAAAAADDDDDAD-- CCAAAAAAAAAADAAAAAC-- CCAAAAAAAAAADDDADADC- CCAAAAAAAAAAAAAAAA-CC CCAAAAAAAAAADADADD-CC CCAAAAAAAAAAAAAAAA-CC -CAAAAAAAAAAAAAAAAAC- -CCBAAAAAAAAAAAAABCC- ----BBBBBBBAAAAAB---- ----BAAAAABAAAAAB---- ----BBBBBBBBBBBBB---- ----AAAABABAABAAA---- ----BBBABBBBABABB---- ----BABAABBAAAAAA---- ----BBBBBBBBABAB----- ----BAAAAAAAAAAA----- -----BABBBBBBBBB----- -----BABAAAAABB------ ------ABBBBBABB------ ------AAAAABAB------- -------BBBABB-------- --------ABAA--------- --------------------- --------------------- --------------------- 
-CAAAAAAAAAAAAAAAAC-- CCAAAAAAAAAAAAAAAAC-- CCAAAAAAAAAAAAAAAAAC- CCAAAAAAAAAAAAAAAAAC- CCAAAAAAAAAAAAAAAAAC- CCAAAAAAAAAAAAAAAAAC- -CAAAAAAAAAAAAAAAAAC- -CCBAAAAAAAAAAAAABC-- ----BAAAAAAAAAAAB---- ----AAAAAAAAAAAAB---- ----ABBBBBBBAAABB---- ----ABAAAAAAAAAAA---- ----BBBBABABAAAAA---- ----BAAAAAAAAAAAA---- ----BBABBBBBABAB----- ----AAAAAAAAA-AA----- -----BABBBABA-AA----- -----AAAAAAAAAAB----- -----BAAAAABABB------ ------AAAAAAAAB------ ------AAABAAAA------- -------AAAAAA-------- --------------------- --------------------- --------------------- 
-CAAAAAAAAAAAAAAAAC-- -CAAAAAAAAAAAAAAAAC-- CCAAAAAAAAAAAAAAAAC-- CCAAAAAAAAAAAAAAAAC-- CCAAAAAAAAAAAAAAAAC-- -CAAAAAAAAAAAAAAAAC-- -CCBAAAAAAAAAAAAABC-- ----AAAAAAAAAAAAB-C-- ----BBBABBBBBBBAB---- ----AABABAAAAABAB---- ----BBBABBBBBBBBB---- ----BAAABAAABBBAA---- ----BABBBBBBBBBBA---- ----BAAABABBABBA----- ----BABBBABBBBBB----- ----AAAAAAAAA--A----- -----AABBBABB--B----- -----AAAABABAAAA----- -----BABBBBBBBB------ ------ABBAABAAB------ ------ABBBBBBB------- -------BAAAABB------- --------BBBBB-------- --------------------- --------------------- 
-CAAAAAAAAAAAAAAAAC-- -CAAAAAAAAAAAAAAAAC-- -CAAAAAAAAAAAAAAAAC-- -CAAAAAAAAAAAAAAAAC-- -CAAAAAAAAAAAAAAAAC-- -CAAAAAAAAAAAAAAAAC-- -CCBAAAAAAAAAAAAABC-- ----AAAAAAAAAAAAB---- ----BAAABABAAAAB----- ----BAAAAAAAAAAB----- ----BAAAAABABABB----- ----BAAAAAAAAAAB----- ----BAAAAABAAAAA----- ----BAAAAAAAAAAA----- ----BAAABABABABA----- -----AAAAAAAA--A----- -----AAAAAABA--A----- -----ABBBBBBBAAA----- -----ABABAAABBA------ -----BBBBBBABAA------ ------AAAABABBB------ ------BBBABBBA------- -------ABABBB-------- --------------------- --------------------- 
--CAAAAAAAAAAAAAAAC-- --CAAAAAAAAAAAAAAAC-- -CAAAAAAAAAAAAAAAAC-- -CAAAAAAAAAAAAAAAAC-- -CAAAAAAAAAAAAAAAAC-- --CAAAAAAAAAAAAAAAC-- --CBAAAAAAAAAAAABCC-- ----BAAAAAAAAAAB----- ----BBBBBBBABBBB----- ----BABAAABABAAB----- -----BBABBBABABB----- -----AAABAAABAAB----- -----ABABBBBBABA----- -----AAABABAAABA----- -----BBBBABBBABA----- -----AAAAAAAAAAA----- -----AABBBBBABAA----- -----ABAABAAAAAA----- -----AABBBBBBBB------ -----BAAAABABAA------ ------ABBBBBBBB------ ------AABAAABB------- -------BBBBBBB------- --------BABA--------- --------------------- 
--CAAAAAAAAAAAAAAC--- --CAAAAAAAAAAAAAAAC-- --CAAAAAAAAAAAAAAAC-- --CAAAAAAAAAAAAAAAC-- --CAAAAAAAAAAAAAAAC-- --CAAAAAAAAAAAAAAAC-- --CBBAAAAAAAAAAABC--- -----BAAAAAAAAAB----- -----BAABABABABB----- -----BAAAAAAAAAB----- -----BAAAABAAABB----- -----BAAAAAAAAB------ -----ABABABAAAB------ -----AAAAAAAAAB------ -----ABAAABABAB------ -----AAAAAAAAAA------ -----AABAAABABA------ -----ABBBABBBAA------ -----AABBABABBB------ -----BBBBABABAA------ ------BBABBBABB------ ------BABBBABAA------ -------BABAABB------- --------BBBAB-------- --------------------- 
---CAAAAAAAAAAAAAC--- --CAAAAAAAAAAAAAAC--- --CAAAAAAAAAAAAAAC--- --CAAAAAAAAAAAAAAC--- --CAAAAAAAAAAAAAAC--- ---CAAAAAAAAAAAAAC--- ---CBAAAAAAAAAABCC--- -----BAAAAAAAAB------ ------BBBBBBBAB------ ------BAAABAAAB------ ------BBBABABBB------ ------BAAAAAABB------ ------BABABABBB------ ------BAAAAAABB------ ------BABBBBBBB------ ------AAAAAAAAB------ ------ABABBBABA------ ------AAABBABAA------ ------ABBBBBBBB------ ------ABAABABAA------ ------ABBBBBBBB------ ------AAAAAABAA------ ------ABBBBBBB------- -------AAABAB-------- ---------BBB--------- 
---CAAAAAAAAAAAAC---- ---CAAAAAAAAAAAAC---- ---CAAAAAAAAAAAAAC--- ---CAAAAAAAAAAAAAC--- ---CAAAAAAAAAAAAC---- ---CAAAAAAAAAACCC---- ------BBAAAABB--C---- ------BBAAAABB------- -------BBAAABB------- -------BBBBBBB------- -------BBBBBBB------- -------BBBBBB-------- --------BBBBB-------- --------BBBBB-------- -------BBBBBB-------- -------BBBBAAB------- ------BBAAAAAA------- ------BBBBBABA------- ------AABAAABAB------ ------BABABBBAA------ ------AABAAAAAB------ ------BABABBBAA------ ------AABABABA------- -------BBBBABA------- --------BABA--------- 
----CCAAAAAAAAAC----- ----CAAAAAAAAAACC---- ----CAAAAAAAAAACC---- ----CAAAAAAAAAACC---- ----CAAAAAAAAAACC---- ----CAAAAAAABBCC----- --------BBBB--------- ---------BBB--------- ---------BBB--------- --------------------- --------------------- --------------------- --------------------- --------------------- --------------------- --------------------- --------AAAAA-------- -------AAABABA------- ------AABABBBA------- ------BAAABABAA------ ------AABBBBBAB------ ------BABABABAA------ ------AABBBABA------- -------ABAAABA------- --------BABA--------- 
------CCCCCCCCC------ -----CCCAAAACCC------ -----CCAAAAAACC------ -----CCAAAAAACC------ -----CCAAAAAAAC------ -----CCCBBBBCCC------ --------------------- --------------------- --------------------- --------------------- --------------------- --------------------- --------------------- --------------------- --------------------- --------------------- --------------------- ---------BB---------- -------ABAAAA-------- ------BBBBBABB------- ------BAAAAAAA------- ------BBBABABA------- ------AAAAAAAA------- -------ABABBBA------- --------AAAAA-------- 
--------------------- --------CCCC--------- -------CCCCCC-------- -------CCCCCC-------- -------CCCCCCC------- --------CCCCC-------- --------------------- --------------------- --------------------- --------------------- --------------------- --------------------- --------------------- --------------------- --------------------- --------------------- --------------------- --------------------- --------AAAAA-------- -------AAAAAAB------- ------AAAAAAAB------- ------AAAAAAAA------- ------AAAAAAAA------- -------AAAAAAA------- --------AAAA--------- 
--------------------- --------------------- --------------------- --------------------- --------------------- --------------------- --------------------- --------------------- --------------------- --------------------- --------------------- --------------------- --------------------- --------------------- --------------------- --------CCCC--------- --------CCCC--------- --------ACCC--------- -------AAAAAA-------- -------BAAAAAB------- -------BAAAAAB------- -------AAAAAAB------- -------AAAAAAB------- -------AAAAAA-------- ---------AAA--------- 
--------------------- --------------------- --------------------- --------------------- --------------------- --------------------- --------------------- --------------------- --------------------- --------------------- --------------------- --------------------- --------------------- ---------CCC--------- -------CCCCCC-------- -------CCCCCCC------- -------CC--CCC------- -------CC--CCC------- -------CA--CA-------- -------B----B-------- -------BAAAAB-------- -------BAAAAB-------- -------BAAAAB-------- --------AAAA--------- --------------------- 
--------------------- --------------------- --------------------- --------------------- --------------------- --------------------- --------------------- --------------------- --------------------- --------------------- --------------------- --------------------- --------------------- --------CCCCC-------- -------DDD-DCD------- -------C----CD------- -------D----CD------- -------D----DD------- -------D----DD------- -------CA---A-------- -------BAAAAB-------- --------BAAAB-------- --------BBAB--------- --------------------- --------------------- 
--------------------- --------------------- --------------------- --------------------- --------------------- --------------------- --------------------- --------------------- --------------------- --------------------- --------------------- --------------------- --------CCC---------- -------CCCCCC-------- -------CC---CD------- -------C-----C------- -------C-----C------- -------C-----C------- -------C----CD------- -------CA--AAC------- --------BAAAB-------- ---------BAB--------- --------------------- --------------------- --------------------- 
--------------------- --------------------- --------------------- --------------------- --------------------- --------------------- --------------------- --------------------- --------------------- --------------------- --------------------- --------------------- --------CCCC--------- -------CCDCDC-------- -------DD---CD------- -------D-----C------- -------D-----D------- -------D-----D------- -------D----CD------- -------CAAAACC------- --------AAAA--------- --------------------- --------------------- --------------------- --------------------- 
--------------------- --------------------- --------------------- --------------------- --------------------- --------------------- --------------------- --------------------- --------------------- --------------------- --------------------- --------------------- --------CCC---------- --------CCCCC-------- -------CC--CCD------- -------C----CC------- -------C-----D------- -------C----CC------- -------CA---CD------- -------CCAACC-------- ---------AA---------- --------------------- --------------------- --------------------- --------------------- 
--------------------- --------------------- --------------------- --------------------- --------------------- --------------------- --------------------- --------------------- --------------------- --------------------- --------------------- --------------------- --------------------- --------CDCC--------- -------DCDCDD-------- -------CCC-CCC------- -------DC--DDD------- -------CC--CCD------- -------DDDDDC-------- --------CCCCC-------- --------------------- --------------------- --------------------- --------------------- --------------------- 
--------------------- --------------------- --------------------- --------------------- --------------------- --------------------- --------------------- --------------------- --------------------- --------------------- --------------------- --------------------- --------------------- --------------------- ---------CCC--------- --------CCCC--------- --------CDCDC-------- --------CCCCC-------- ---------DCC--------- --------------------- --------------------- --------------------- --------------------- --------------------- --------------------- 
