model
size = 26 29 23, scale = 0.05, origin = -y
material 
  colors = A:#CC9 B:#111 C:#001 D:#222 E:#C96 F:#EEE
voxels
-------------------------- -------------------------- -------------------------- -------------------------- -------------------------- -------------------------- -------------------------- -------------------------- -------------------------- -------------------------- -------------------------- -------------------------- -------------------------- -------------------------- -------------------------- -------------------------- -------------------------- -------------------------- -------------------------- -------------------------- -------------------------- ----------BBBBBB---------- ----------BBBBBB---------- -------------------------- -------------------------- -------------------------- -------------------------- -------------------------- -------------------------- 
-------------------------- -------------------------- -------------------------- -------------------------- -------------------------- -------------------------- -------------------------- -------------------------- -------------------------- -------------------------- -------------------------- -------------------------- -------------------------- -------------------------- -------------------------- -------------------------- -------------------------- -------------------------- -------------------------- -------------------------- --------BBBBBBBBBB-------- ------BBBBBBBBBBBBBB------ ---------BBBDBBBB--------- -------------------------- -------------------------- -------------------------- -------------------------- -------------------------- -------------------------- 
-------------------------- -------------------------- -------------------------- -------------------------- -------------------------- -------------------------- -------------------------- -------------------------- -------------------------- -------------------------- -------------------------- -------------------------- -------------------------- -------------------------- -------------------------- -------------------------- -------------------------- -------------------------- -------------------------- ---------BBBBBBBB--------- ----BBBBBBBBBBBBBBBBBB---- ----BBBDDDDDBBBBBBBBBB---- -------------------------- -------------------------- -------------------------- -------------------------- -------------------------- -------------------------- -------------------------- 
-------------------------- -------------------------- -------------------------- -------------------------- -------------------------- -------------------------- -------------------------- -------------------------- -------------------------- -------------------------- -------------------------- -------------------------- -------------------------- -------------------------- -------------------------- -------------------------- -------------------------- -------------------------- -------------------------- ------BBBBBBBBBBBBBB------ ----BBBBDBBBBBBBBBBBBBD--- ----DDDD----------BBBB---- -------------------------- -------------------------- -------------------------- -------------------------- -------------------------- -------------------------- -------------------------- 
-------------------------- -------------------------- -------------------------- -------------------------- -------------------------- -------------------------- -------------------------- -------------------------- -------------------------- -------------------------- -------------------------- -------------AA----------- -------------EA----------- -------------CAC---------- --------------CC---------- -------------------------- -------------------------- -------------------------- -------------------------- ---BBBBBBBBBBBBBBBBBBBBB-- ---BBDDD----------BBBBBD-- -------------------------- -------------------------- -------------------------- -------------------------- -------------------------- -------------------------- -------------------------- -------------------------- 
-------------------------- -------------------------- -------------------------- -------------------------- -------------------------- -------------------------- -------------------------- -------------------------- -------------------------- -------------AA----------- -------------AA----------- ------------D--A---------- ---------CCDD--A-C-------- ---------CCCCA-ACCC------- ---------CCCCCAACCC------- ---------CC---CC---------- -------------------------- -------------------------- -------------------------- --BBBBBBBBBBBBBBBBDBBBBD-- ---DDB-----DDDDB----BBBD-- -------------------------- -------------------------- -------------------------- -------------------------- -------------------------- -------------------------- -------------------------- -------------------------- 
-------------------------- -------------------------- -------------------------- -------------------------- -----------AAAEAA--------- ----------AAAAEAAA-------- ----------EAAAAAAA-------- ---------EEAAAAAAAA------- ---------AAADAAAAAA------- ---------AAAAAAAAAA------- ---------AADDAAAAAA------- ------CCCAADAAAAAAA------- ------CCCAAAAAABAAC------- ------CCCAAAAAAAAAAC------ ------CCCAAAAAAAAAAC------ ------CCCAADDDAADDD------- ---------ADDDDDDDBD------- ---------DDDBDBBBBB------- -----------BBBBBBB-------- -BBBBBBBBBBBBBBBBBBBBBBBD- --------DBBBBBBBDD-------- ---------DDDBBBDD--------- ----------BBBBBB---------- ----------BBBBBB---------- -----------BBBBB---------- ------------BBB----------- -------------------------- -------------------------- -------------------------- 
-------------------------- -----------------------CC- -----------------------C-- -------------AAAA--------- --------A-AAAAAAAAA------- -------AAAAAAAAAAAA------- -------AAAAAAAAAAAA------- -------AAAAAAAAAAAA------- -------AAAAAAAAAAAA------- -------AAAAAAAAAAAA------- -------AAAAAAAAAAAA------- ------CAAAAAAAAAAAAC------ ------CAAAAAAAAAAAAC------ ------CAAAAAAAAAAAAC------ ------CAAAAAAAAAAAC------- ------CAAAAAAAAAAAD------- ------CAAAAAAAAAAAD------- -------AAAAAAAAAAAD------- -BB----DDDBAAAAAAAB-----B- -BBBBBBBBBBAAAAABBBBBBBBB- -------BBBBBAAABBBD------- --------BBBBBBBBBD-------- --------BBBBBBBBBD-------- --------DBBBBBBBBD-------- ---------DBBBBBBB--------- ---------BBBBBBBB--------- -------------------------- -------------------------- -------------------------- 
------------------------C- -----------------------CC- -----------------------CC- -----------AAAAA-A----CC-- -------AAAAAAAAAAAA---CC-- -------AAAAAAAAAAAA-C----- -------AAAAAAAAAAAA------- -------AAAAAAAAAAAA------- -------AAAAAAAAAAAA------- -------AAAAAAAAAAAA------- ------CAAAAAAAAAAAA------- ------CAAAAAAAAAAAAC------ ------CAAAAAAAAAAAAC------ ------CAAAAAAAAAAAAC------ ------CAAAAAAAAAAAAC------ ------CAAAAAAAAAAAD------- ------CAAAAAAAAAAAD------- ------DAAAAAAAAAAAD------- BBBB---AAAAAAAAAAAB----BBB BBBBBBBBAAAAAAAAAABBBBBBBB ------BBAAAAAAAAAABB------ -------BBBBBBBBBBBDD------ -------BBBBBBBBBBBDB------ --------BBBBBBBBBBD------- --------DBBBBBBBBBD------- --------DBBBBBBBBBD------- --------BBBBBBBBBBB------- --------BBBBBBBBBB-------- --------BBBB---BBB-------- 
-------------------------- -----------------------CC- -----------------------C-- ----------AAAAAA------CC-- -------AAAAAAAAAAAA---C--- -------AAAAAAAAAAAA-CCC--- -------AAAAAAAAAAAA-CC---- -------AAAAAAAAAAAA-C----- -------AAAAAAAAAAAA------- -------AAAAAAAAAAAA------- ------CAAAAAAAAAAAAC------ ------CAAAAAAAAAAAAC------ ------CAAAAAAAAAAAAC------ -------FAAAAAAAAAAAC------ -------AAAAAAAAAAAACC----- ------CAAAAAAAAAAAD------- ------CAAAAAAAAAAAD------- ------DAAAAAAAAAAAD------- BBBB---AAAAAAAAAAAB----BBB BBBBBBBBAAAAAAAAAAABBBBBBB ------BBAAAAAAAAAABB------ ------BBBABBBBBBABBB------ -------BBABBBBBBABBB------ -------BB-BBBBBB-BBB------ -------BB-BBBBBB-BBB------ -------BB-BBBBBB-BBB------ --------B-BBBBBB-BB------- --------BBBBBBBBBBB------- --------BBBBBBBBBB-------- 
----------------AAA------- ----------------AAA------- -------------AA-AAE----C-- ---------AAAAAAAAAA---CC-- -------AAAAAAAAAAAA---C--- -------AAAAAAAAAAAA-CCC--- -------AAAAAAAAAAAA-CC---- -------AAAAAAAAAAAA-CC---- -------AAAAAAAAAAAA------- -------AAAAAAAAAAAA------- ------CAAAAAAAAAAAAC------ ------CAAAAAAAAAAAAC------ ------CAAAAAAAAAAAACC----- ------CAAAAAAAAAAAAC------ ------CAAAAAAAAAAAACCC---- ------CAAAAAAAAAAAAC------ ------CAAAAAAAAAAAD------- ------DAAAAAAAAAAAD------- BBBB---AAAAAAAAAAAB----BBB BBBBBBBBAAAAAAAAAAABBBBBBB ------BBAAAAAAAAAAAB------ ------BBBBBBBBBBBBBB------ -------BBBBBBBBBBBBB------ -------BBBBBBBBBBBBB------ -------BBBBBBBBBBBBB------ -------BBBBBBBBBBBBB------ -------BBBBBBBBBBBBB------ --------BBBBBBBBBBB------- --------BBBBBBBBBB-------- 
----------------AAA------- ----------------AAA------- -----------AAAAAAAA------- ---------AAAAAAAAAA------- -------AAAAAAAAAAAA---C--- -------AAAAAAAAAAAA-CCC--- -------BAAAAAAAAAAA-CC---- -------AAAAAAAAAAAACC----- -------AAAAAAAAAAAAC------ -------AAAAAAAAAAAAC------ -------AAAAAAAAAAAAC------ ------CAAAAAAAAAAAACC----- ------CAAAAAAAAAAAACCCC--- ------CAAAAAAAAAAAACCCC--- ------CAAAAAAAAAAAACCC---- ------CAAAAAAAAAAAACC----- -------AAAAAAAAAAAD------- -------AAAAAAAAAAAD------- BBBB---AAAAAAAAAAAB----BBB BBBBBBBBAAAAAAAAAAABBDBBBB ------BBAAAAAAAAAAAB------ ------BBBBBBBBBBBBBB------ ------BBBBBBBBBBBBBB------ -------BBBBBBBBBBBBB------ -------BBBBBBBBBBBBB------ -------BBBBBBBBBBBBB------ -------BBBBBBBBBBBBB------ --------BBBBBBBBBBB------- -------------------------- 
---------------AAAA------- ---------------AAAA------- -----------AAAAAAAA------- ---------AAAAAAAAAA------- -------AAAAAAAAAAAA------- -------AAAAAAAAAAAA------- -------BAAAAAAAAAAA------- -------AAAAAAAAAAAA------- -------AAAAAAAAAAAA------- ------AAAAAAAAAAAAA------- -------AAAAAAAAAAA-C------ ------CAAAAAAAAAAAACC----- ------CAAAAAAAAAAAACCCC--- ------CAAAAAAAAAAAACCCC--- ------CAAAAAAAAAAAACCC---- ------CAAAAAAAAAAAD------- -------AAAAAAAAAAAD------- -------AAAAAAAAAAAD------- BBBB---AAAAAAAAAAAD----BBB BBBBBBBBAAAAAAAAAAABBDBBBB ------BBAAAAAAAAAAAB------ ------BBBBBBBBBBBBBB------ -------BBBBBBBBBBBBB------ -------BBBBBBBBBBBBB------ -------DBBBBBBBBBBBB------ -------DBBBBBBBBBBBB------ --------BBBBBBBBBBB------- --------BBBBBBBBBBB------- --------BBBBBBBBBB-------- 
----------------AAA------- ----------------AAA------- -------------AA-AAA------- ---------AAAAAAAAAA------- -------AAAAAAAAAAAA------- -------AAAAAAAAAAAA------- -------BAAAAAAAAAAA------- -------AAAAAAAAAAAA------- -------AAAAAAAAAAAA------- -------AAAAAAAAAAAA------- -------AAAAAAAAAAAACC----- ------CAAAAAAAAAAAA-C----- ------CAAAAAAAAAAAACCCC--- ------CAAAAAAAAAAAACCCC--- ------CAAAAAAAAAAAC-CCC--- ------CAAAAAAAAAAAAC------ ------CAAAAAAAAAAAD------- -------DAAAAAAAAAAD------- BBBB---AAAAAAAAAAAB----BBB BBBBBBBBAAAAAAAAAABBBBBBBB ------BBAAAAAAAAAABB------ -------BBBBBBBBBBBBB------ -------BBBBBBBBBBBBB------ -------BBBBBBBBBBBBB------ --------BBBBBBBBBBB------- --------BBBBBBBBBBB------- --------BBBBBBBBBBB------- --------BBBBBBBBBBB------- --------BBBBBBBBBB-------- 
-------------------------- -------------------------- -------------------------- ----------AAAAAA---------- -------AAAAAAAAAAAA------- -------AAAAAAAAAAAA------- -------AAAAAAAAAAAA------- -------AAAAAAAAAAAA------- -------AAAAAAAAAAAA------- -------AAAAAAAAAAAA------- ------CAAAAAAAAAAAAC------ ------CAAAAAAAAAAAA-C----- ------CAAAAAAAAAAAACCC---- -------FAAAAAAAAAAACCCC--- -------AAAAAAAAAAAC-CC---- ------CAAAAAAAAAAAC------- ------CAAAAAAAAAAAD------- ------DAAAAAAAAAAAB------- BBBB---AAAAAAAAAAAB----BBB BBBBBBBBBAAAAAAAABBBBBBBBB -------BBAAAAAAAABBB------ -------BBBBBBBBBBBBD------ --------BBBBBBBBBBB------- --------BBBBBBBBBBB------- --------DBBBBBBBBBB------- --------BBBBBBBBBBB------- --------DBBBBBBBBB-------- --------DBB-----BB-------- -------------------------- 
-------------------------- -------------------------- -------------------------- -------------AAAA--------- -------AA-AAAAAAAAA------- -------AAAAAAAAAAAA------- -------AAAAAAAAAAAA------- -------AAAAAAAAAAAA------- -------AAAAAAAAAAAA-CC---- -------AAAAAAAAAAAA-CC---- ------CAAAAAAAAAAAA-C----- ------CAAAAAAAAAAAA------- ------CAAAAAAAAAAAACC----- ------CAAAAAAAAAAAACC----- ------CAAAAAAAAAAAC-C----- ------CAAAAAAAAAAAD------- ------CAAAAAAAAAAAD------- ------DAAAAAAAAAAAB------- -BB----AAAAAAAAAAAB-----B- -BDBBBBBBBAAAAAABBBBBBBBB- -------BBBBAAAAABBB------- --------BBBBBBBBBBD------- --------BBBBBBBBBB-------- --------BBBBBBBBBB-------- --------BBBBBBBBBB-------- --------DBBBBBBBBB-------- -------------------------- -------------------------- -------------------------- 
-------------------------- -------------------------- -------------------------- ---------------A---------- --------AAAAAAAAAA-------- -------AAAAAAAAAAAA------- -------AAEAAAAAAAAA-CCC--- -------AEAAAAAAAAAA-CC---- -------AAAAAAAAAAAA-CC---- -------AAAAAAAAAAAA-CC---- ------CAAAAAAAAAAAA-CC---- ------CAAAAAAAAAAAA------- ------CAAAAAAAAAAAAC------ ------CAAAAAAAAAAAAC------ ------CAAAAAAAAAAAC------- ------CAAAAAAAAAAAD------- ------CAAAAAAAAAAAD------- -------AAAAAAAAAAAB------- -------AADDAAAAAAAB------- --DBBBBBBBBBBBBBBBBBBBBB-- ---DB-----BDBBBB-----BBB-- -----------BBDBB---------- -------------------------- -------------------------- -------------------------- -------------------------- -------------------------- -------------------------- -------------------------- 
-------------------------- -------------------------- -------------------------- -------------------------- -----------AAAAAA--------- ----------EAAAAAAA----C--- ----------AAAAAAAA---CC--- ---------EAAAAAAAAA-CCC--- ---------AAAAAAAAAA-CC---- ---------AADAAAAAAA------- ---------AAAAAAAAAA------- -------CCADDAAA-AAA------- ------CCCAAAAAA-DAC------- ------CCCAAAAAAAAAAC------ ------CCCAAAAAAAAAAC------ ------CCCAADDCAADDD------- ---------DDDDDDDDDD------- ---------DDDDDDBBDB------- -----------DDBDDBB-------- --BBBBBBBBBBBBBBBBBBBBBB-- ---DBBBB----DDDD---BBBBB-- -------------------------- -------------------------- -------------------------- -------------------------- -------------------------- -------------------------- -------------------------- -------------------------- 
-------------------------- -------------------------- -------------------------- -------------------------- -------------------------- ----------------------C--- -------------------------- --------------------CC---- --------------------CC---- --------------AA---------- -------------AAA---------- ------------DAAA---------- ---------CCCDAAA-C-------- ---------CCCCAD-CCC------- ---------CCCCCA-CCC------- ---------CC---CC---------- -------------------------- -------------------------- -------------------------- ---BBBBBBBBBBBBBBBBBBBBB-- ---DDBBBBB------BBBBBBBB-- -------------------------- -------------------------- -------------------------- -------------------------- -------------------------- -------------------------- -------------------------- -------------------------- 
-------------------------- -------------------------- -------------------------- -------------------------- -----------------------C-- ----------------------CC-- ----------------------CC-- --------------------CCC--- -------------------------- -------------------------- --------------A----------- -------------EA----------- -------------AA----------- -------------C-C---------- --------------CC---------- -------------------------- -------------------------- -------------------------- -------------------------- -----BBBBBBBBBBBBBBBB----- ----BBBBBBBBBBBBBBBBBBB--- ----DDB-------------BB---- -------------------------- -------------------------- -------------------------- -------------------------- -------------------------- -------------------------- -------------------------- 
-------------------------- -------------------------- -------------------------- ------------------------C- -----------------------CC- -----------------------CC- ----------------------CC-- -------------------------- -------------------------- -------------------------- -------------------------- -------------------------- -------------------------- -------------------------- -------------------------- -------------------------- -------------------------- -------------------------- -------------------------- -------------------------- -------BBBBBBBBBBBBB------ -----BBBBBBBBBBBBBBBB----- -------------------------- -------------------------- -------------------------- -------------------------- -------------------------- -------------------------- -------------------------- 
-------------------------- -------------------------- -------------------------- -------------------------- ------------------------C- -----------------------CC- -------------------------- -------------------------- -------------------------- -------------------------- -------------------------- -------------------------- -------------------------- -------------------------- -------------------------- -------------------------- -------------------------- -------------------------- -------------------------- -------------------------- -------------------------- --------BBBBBBBBBBB------- ---------BBBBBBBB--------- -------------------------- -------------------------- -------------------------- -------------------------- -------------------------- -------------------------- 
-------------------------- -------------------------- -------------------------- -------------------------- ------------------------C- -----------------------CC- -------------------------- -------------------------- -------------------------- -------------------------- -------------------------- -------------------------- -------------------------- -------------------------- -------------------------- -------------------------- -------------------------- -------------------------- -------------------------- -------------------------- -------------------------- -------------------------- -------------------------- -------------------------- -------------------------- -------------------------- -------------------------- -------------------------- -------------------------- 
