model
size = 10 32 21, scale = 0.05, origin = -y
material 
  colors = A:#070 B:#EEE C:#050 D:#E00 E:#080 F:#0D0 G:#BBB H:#DDD
voxels
91-A9-2A60-3A7-F-A7-3A7-AFA205-F9-2A8-2A9-A40-3A2(6-4A)6-E3A6-F3A7-F2A7-2A9-A176-F2(9-FA)8-2A9-A28-3(4A6-)3(E3A6-)F3A7-3A30-D8-2BG7-3B7-3D103-F9-FA8-2(2A9-)A9-F2A7-C2A16-3(4A6-)3(E3A6-)F3A7-F2E29-B-G7-B-B7-D-D7-3B7-G2B8-HD83-A9-FA9-2A8-2A9-3A7-F2(2A7-C)2A5(6-4A)6-E3A6-2EFE49-3D7-G2B7-3B7-3D7-3B94-A9-2A9-A9-3A7-3A8-2A6-2C2A7-3A5(6-4A)6-2AFA60-2B7-3D2(7-3B)7-DHD95-A9-2A8-3A2(8-2A)6-2C2A6-C2(3A7-)3A3(6-4A)7-AF71-2B7-3B7-D-D7-G2B105-3A3(8-2A)7-C2A7-2CA7-3A2C5-3(3A7-)3A6-CA81-3D7-B-B7-3B126-2(2AC7-)2A2C4-3CA3C2-2C3A3C-3C3A2C4-C3AC4-2C3A5-2C3A79-3D2(7-3B)7-3D8-2(D2(9-B)9-)D9-G9-B9-D2(9-B)9-DC8-GC8-B2C5-CAD2(2C2-4CAB)2C4-2CADC5-C2AG5-C3AB9-D2(9-B)9-D9-B9-2B8-2D7-3B7-B-B7-3D8-2B7-B-B7-G-B3(7-D-D2(7-B-B))7-D-D7-2(B-BC6-)D-DC5-CA-B2C-4CA-BC2-4CA-DC3-3CA-BC5-CA-B7-D-D7-B-B7-G-B2(7-D-D2(7-B-B))7-3D7-2BG17-3B4(7-3D2(7-3B))C6-DBDC4-C2A2BC3-C-CA2BC4-2CA2D2(C3-3CA2B)C6-3(3D2(7-3B)7-)DHD7-2BG28-2(2D2(8-2B)8-)2D8-2B5-A2-2B5-3A2D6-2AGB6-2A2B6-2A2DC5-FA2BC6-ABG2C2-CF2A2DC4-C2A2B2C3-2CA2B2C2-3CA2DC5-2A2(2B8-BG8-2D8-)2(2B8-)DH104-A9-2A9-A9-3A3(8-2A)2C6-FA2C4-C3(3A3C4-)E2A3C4-E2A2C5-3A2C4-C3AC164-2(2A9-A9-)3A7-E2(2A8-)FA5-C-C2A6-C3A6-4AC-2C2-4A-2C3-4A-2C4-3(3A7-)F2A145-A2(9-2A8-2A)9-3A7-F2A8-FA8-2A5-2C3A5(6-4A)2(7-3A)7-F2A155-2A8-2A9-2A8-EA9-EA8-F2A7-E2A7-2C7-4A6-F3A5(6-4A)7-F2A7-FEA155-A9-2A2(9-E)A8-EF28-E3A6-F3A6(6-4A)7-3A7-EA156-A9-EA8-2E49-4A6-F2(3A6-E)3A3(6-4A)6-E3A7-3E237-3A6-4A5(6-E3A)7-3E267-E2A7-E2A2(6-E3A)6-4E134-
