model
size = 30 32 28, scale = 0.05, origin = -y
material 
  colors = A:#003 B:#EEE C:#E00 D:#222 E:#C60 F:#111
voxels
4(F29-)2E28-4(E29-)22(A29-)A149-2E149-A3(29-B)3(29-A)2(29-C5(29-A))29-C3(29-A)299-2(A29-B29-)3(A29-)2(C5(29-A)29-)2(C3(29-A)300-A3(29-B)3(29-A)2(29-C5(29-A))29-)C3(29-A)299-2(A3(29-B)3(29-A)2(29-C5(29-A))29-C3(29-A)300-)2A3(28-2B)3(28-2A)2(28-2C5(28-2A))28-2C3(28-2A)300-3A3(27-3B)3(27-3A)2(27-3C5(27-3A))27-3C3(27-3A)300-2A3(28-2B)3(28-2A)2(28-2C5(28-2A))28-2C3(28-2A)2(300-A3(29-B)3(29-A)2(29-C5(29-A))29-C3(29-A))299-3(A3(29-B)3(29-A)2(29-C5(29-A))29-C3(29-A)300-)A3(29-B)3(29-A)2(29-C5(29-A))29-C3(29-A)299-A3(29-B)3(29-A)2(29-C5(29-A))29-C3(29-A)300-A3(29-B)3(29-A)29-C11(29-A)29-C3(29-A)300-A3(29-B)3(29-A)29-C2(29-A)7(29-D)2(29-A)29-C3(29-A)300-2A3(28-2B)3(28-2A)28-2C2(28-2A)2(28-2D2(28-2B))28-2D2(28-2A)28-2C3(28-2A)300-2A3(28-2B)2(28-2A)4(28-AD)7(28-DA)4(28-AD)2(28-2A)300-2A3(28-2B)2(28-2A)28-2D2(28-2B)28-2D7(28-2A)28-2D2(28-2B)28-2D2(28-2A)300-A3(29-B)2(29-A)4(29-D)7(29-A)4(29-D)2(29-A)300-A3(29-B)2(29-A)29-D2(29-B)29-D7(29-A)29-D2(29-B)29-D2(29-A)300-2(A29-B29-)2(A29-)D2(29-B)29-D7(29-A)29-D2(29-B)29-D2(29-A)300-A3(29-B)2(29-A)4(29-D)7(29-A)4(29-D)2(29-A)299-22(A29-)A300-22(A29-)A
