model
size = 19 28 19, scale = 0.05, origin = -y
material 
  colors = A:#FC0 B:#222 C:#000
voxels
------------------- ------------------- ------------------- ------------------- ------------------- ----------BBBBBB--- ----------BBBBBB--- ------------------- ------------------- ------------------- ------------------- ------------------- ------------------- ------------------- ------------------- ------------------- ------------------- ------------------- ------------------- ------------------- ------------------- ------------------- ------------------- ------------------- ------------------- ------------------- ------------------- ------------------- 
----AAAAAAAA------- ---AA----AAAAA----- --AA-----AAAAAA---- -AA------AAAAAAAA-- -A-------AAAAAAAA-- -A-------AAAAAAAA-- AA-------AAAAAAAA-- A--------AAAAAAAA-- A--------AABAAAAA-- A--------AABAAAAA-- A--------AABAAAAA-- A--------AABAAAAA-- A--------AABAAAAA-- A--------AABAAAAA-- A--------AABAAAAA-- A--------AABAAAAA-- A--------AABAAAAA-- A--------AABAAAAA-- A--------AABAAAAA-- A--------AABAAAAA-- A--------AABAAAAA-- AA-------AABAAAAA-- -A-------AABAAAAA-- -A-------AABAAAAA-- -AA------AAABAA---- --AA-----AAAAA----- ---AA--AAA--------- ----AAAA----------- 
----AAAAAAAA------- ---AA----AAAAA----- --AA-----AAAAAA---- -AA------AAAAAAAA-- -A------BAAAAAAAAAA -A------BAAAAAAAAAA AA------BAAAAAAAAAA A--------AAAAAAAAAA A--------AAAAAAAAAA A-------AAAAAAAAAAA A-------AAAAAAAAAAA A-------AAAAAAAAAAA A-------AAAAAAAAAAA A-------AAAAAAAAA-- A-------AAAAAAAAA-- A-------AAAAAAAAA-- A-------AAAAAAAAA-- A-------AAAAAAAAA-- A-------AAAAAAAAA-- A-------AAAAAAAAA-- A-------AAAAAAAAA-- AA------AAAAAAAAA-- -A------AAAAAAAAA-- -A------AAAAAAAAA-- -AA-----AAAAAAA---- --AA-----AAAAA----- ---AA--AAA--------- ----AAAA----------- 
---------AAA------- ---------AAAAA----- ---------AAAAAA---- ---------AAAAAAAA-- --------BAAAAAAAAAA --------BAAAAAAAAAA --------BAAAAAAAAAA ---------AAAAAAAAAA ---------AAAAAAAAAA --------AAAAAAAAAAA --------AAAAAAAAAAA --------AAAAAAAAAAB --------AAAAAAAAAAA --------AAAAAAAAA-- --------AAAAAAAAA-- --------AAAAAAAAA-- --------AAAAAAAAA-- --------AAAAAAAAA-- --------AAAAAAAAA-- --------AAAAAAAAA-- --------AAAAAAAAA-- --------AAAAAAAAA-- --------AAAAAAAAA-- --------AAAAAAAAA-- --------AAAAAAA---- ---------AAAAA----- ------------------- ------------------- 
---------AAA------- ---------AAAAA----- ---------AAAAAA---- ---------AAAAAAAA-- --------BAAAAAAAAAA --------BAAAAAAAAAA --------BAAAAAAAAAA ---------AAAAAAAAAA ---------AAAAAAAAAA --------AAAAAAAAAAA --------AAAAAAAAAAA --------AAAAAAAAAAB --------AAAAAAAAAAA --------AAAAAAAAA-- --------AAAAAAAAA-- --------AAAAAAAAA-- --------AAAAAAAAA-- --------AAAAAAAAA-- --------AAAAAAAAA-- --------AAAAAAAAA-- --------AAAAAAAAA-- --------AAAAAAAAA-- --------AAAAAAAAA-- --------AAAAAAAAA-- --------AAAAAAA---- ---------AAAAA----- ------------------- ------------------- 
---------AAA------- ---------AAAAA----- ---------AAAAAA---- ---------AAAAAAAA-- --------BAAAAAAAAAA --------BAAAAAAAAAA --------BAAAAAAAAAA ---------AAAAAAAAAA ---------AAAAAAAAAA --------AAAAAAAAAAA --------AAAAAAAAAAA --------AAAAAAAAAAB --------AAAAAAAAAAA --------AAAAAAAAA-- --------AAAAAAAAA-- --------AAAAAAAAA-- --------AAAAAAAAA-- --------AAAAAAAAA-- --------AAAAAAAAA-- --------AAAAAAAAA-- --------AAAAAAAAA-- --------AAAAAAAAA-- --------AAAAAAAAA-- --------AAAAAAAAA-- --------AAAAAAA---- ---------AAAAA----- ------------------- ------------------- 
---------AAA------- ---------AAAAA----- ---------AAAAAA---- ---------AAAAAAAA-- --------BAAAAAAAAAA --------BAAAAAAAAAA --------BAAAAAAAAAA ---------AAAAAAAAAA ---------AAAAAAAAAA --------AAAAAAAAAAA --------AAAAAAAAAAA --------AAAAAAAAAAB --------AAAAAAAAAAA --------AAAAAAAAA-- --------AAAAAAAAA-- --------AAAAAAAAA-- --------AAAAAAAAA-- --------AAAAAAAAA-- --------AAAAAAAAA-- --------AAAAAAAAA-- --------AAAAAAAAA-- --------AAAAAAAAA-- --------AAAAAAAAA-- --------AAAAAAAAA-- --------AAAAAAA---- ---------AAAAA----- ------------------- ------------------- 
---------AAA------- ---------AAAAA----- ---------AAAAAA---- ---------AAAAAAAA-- --------BAAAAAAAAAA --------BAAAAAAAAAA --------BAAAAAAAAAA ---------AAAAAAAAAA ---------AAAAAAAAAA --------AAAAAAAAAAA --------AAAAAAAAAAA --------AAAAAAAAAAB --------AAAAAAAAAAA --------AAAAAAAAA-- --------AAAAAAAAA-- --------AAAAAAAAC-- --------AAAAAAAAA-- --------AAAAAAAAA-- --------AAAAAAAAA-- --------AAAAAAAAA-- --------AAAAAAAAA-- --------AAAAAAAAC-- --------AAAAAAAAA-- --------AAAAAAAAA-- --------AAAAAAA---- ---------AAAAA----- ------------------- ------------------- 
---------AAA------- ---------AAAAA----- ---------AAAAAA---- ---------AAAAAAAA-- --------BAAAAAAAAAA --------BAAAAAAAAAA --------BAAAAAAAAAA ---------AAAAAAAAAA ---------AAAAAAAAAA --------AAAAAAAAAAA --------AAAAAAAAAAA --------AAAAAAAAAAB --------AAAAAAAAAAA --------AAAAAAAAA-- --------AAAAAAAAC-- --------AAAAAAAAC-- --------AAAAAAAAC-- --------AAAAAAAAC-- --------AAAAAAAAC-- --------AAAAAAAAC-- --------AAAAAAAAC-- --------AAAAAAAAC-- --------AAAAAAAAC-- --------AAAAAAAAA-- --------AAAAAAA---- ---------AAAAA----- ------------------- ------------------- 
---------AAA------- ---------AAAAA----- ---------AAAAAA---- ---------AAAAAAAA-- --------BAAAAAAAAAA --------BAAAAAAAAAA --------BAAAAAAAAAA ---------AAAAAAAAAA ---------AAAAAAAAAA --------AAAAAAAAAAA --------AAAAAAAAAAA --------AAAAAAAAAAB --------AAAAAAAAAAA --------AAAAAAAAA-- --------AAAAAAAAA-- --------AAAAAAAAC-- --------AAAAAAAAA-- --------AAAAAAAAA-- --------AAAAAAAAC-- --------AAAAAAAAA-- --------AAAAAAAAA-- --------AAAAAAAAC-- --------AAAAAAAAA-- --------AAAAAAAAA-- --------AAAAAAA---- ---------AAAAA----- ------------------- ------------------- 
---------AAA------- ---------AAAAA----- ---------AAAAAA---- ---------AAAAAAAA-- --------BAAAAAAAAAA --------BAAAAAAAAAA --------BAAAAAAAAAA ---------AAAAAAAAAA ---------AAAAAAAAAA --------AAAAAAAAAAA --------AAAAAAAAAAA --------AAAAAAAAAAB --------AAAAAAAAAAA --------AAAAAAAAA-- --------AAAAAAAAC-- --------AAAAAAAAC-- --------AAAAAAAAA-- --------AAAAAAAAA-- --------AAAAAAAAC-- --------AAAAAAAAA-- --------AAAAAAAAA-- --------AAAAAAAAC-- --------AAAAAAAAC-- --------AAAAAAAAA-- --------AAAAAAA---- ---------AAAAA----- ------------------- ------------------- 
---------AAA------- ---------AAAAA----- ---------AAAAAA---- ---------AAAAAAAA-- --------BAAAAAAAAAA --------BAAAAAAAAAA --------BAAAAAAAAAA ---------AAAAAAAAAA ---------AAAAAAAAAA --------AAAAAAAAAAA --------AAAAAAAAAAA --------AAAAAAAAAAB --------AAAAAAAAAAA --------AAAAAAAAA-- --------AAAAAAAAA-- --------AAAAAAAAC-- --------AAAAAAAAA-- --------AAAAAAAAC-- --------AAAAAAAAC-- --------AAAAAAAAA-- --------AAAAAAAAA-- --------AAAAAAAAC-- --------AAAAAAAAA-- --------AAAAAAAAA-- --------AAAAAAA---- ---------AAAAA----- ------------------- ------------------- 
---------AAA------- ---------AAAAA----- ---------AAAAAA---- ---------AAAAAAAA-- --------BAAAAAAAAAA --------BAAAAAAAAAA --------BAAAAAAAAAA ---------AAAAAAAAAA ---------AAAAAAAAAA --------AAAAAAAAAAA --------AAAAAAAAAAA --------AAAAAAAAAAB --------AAAAAAAAAAA --------AAAAAAAAA-- --------AAAAAAAAA-- --------AAAAAAAAA-- --------AAAAAAAAC-- --------AAAAAAAAC-- --------AAAAAAAAA-- --------AAAAAAAAC-- --------AAAAAAAAC-- --------AAAAAAAAA-- --------AAAAAAAAA-- --------AAAAAAAAA-- --------AAAAAAA---- ---------AAAAA----- ------------------- ------------------- 
---------AAA------- ---------AAAAA----- ---------AAAAAA---- ---------AAAAAAAA-- --------BAAAAAAAAAA --------BAAAAAAAAAA --------BAAAAAAAAAA ---------AAAAAAAAAA ---------AAAAAAAAAA --------AAAAAAAAAAA --------AAAAAAAAAAA --------AAAAAAAAAAB --------AAAAAAAAAAA --------AAAAAAAAA-- --------AAAAAAAAA-- --------AAAAAAAAA-- --------AAAAAAAAA-- --------AAAAAAAAA-- --------AAAAAAAAA-- --------AAAAAAAAA-- --------AAAAAAAAA-- --------AAAAAAAAA-- --------AAAAAAAAA-- --------AAAAAAAAA-- --------AAAAAAA---- ---------AAAAA----- ------------------- ------------------- 
---------AAA------- ---------AAAAA----- ---------AAAAAA---- ---------AAAAAAAA-- --------BAAAAAAAAAA --------BAAAAAAAAAA --------BAAAAAAAAAA ---------AAAAAAAAAA ---------AAAAAAAAAA --------AAAAAAAAAAA --------AAAAAAAAAAA --------AAAAAAAAAAB --------AAAAAAAAAAA --------AAAAAAAAA-- --------AAAAAAAAA-- --------AAAAAAAAA-- --------AAAAAAAAA-- --------AAAAAAAAA-- --------AAAAAAAAA-- --------AAAAAAAAA-- --------AAAAAAAAA-- --------AAAAAAAAA-- --------AAAAAAAAA-- --------AAAAAAAAA-- --------AAAAAAA---- ---------AAAAA----- ------------------- ------------------- 
---------AAA------- ---------AAAAA----- ---------AAAAAA---- ---------ABBBBBAA-- --------BABBBBBAAAA --------BABBBBBBAAA --------BABBBBBBAAA ---------ABBBBBBAAA ---------ABBBBBBAAA --------AABBBBBBAAA --------AABBBBBBAAA --------AABBBBBBAAB --------AABBBBBBAAA --------AABBBBBBA-- --------AABBBBBBA-- --------AABBBBBBA-- --------AABBBBBBA-- --------AABBBBBBA-- --------AABBBBBBA-- --------AABBBBBBA-- --------AABBBBBBA-- --------AABBBBBBA-- --------AABBBBBAA-- --------AABBBBAAA-- --------AABBBAA---- ---------AAAAA----- ------------------- ------------------- 
---------AAA------- ---------AAAAA----- ---------AAAAAA---- ---------ABBBBBAA-- --------BABBBBBAAAA --------BABBBBBBAAA --------BABBBBBBAAA ---------ABBBBBBAAA ---------ABBBBBBAAA --------AABBBBBBAAA --------AABBBBBBAAA --------AABBBBBBAAB --------AABBBBBBAAA --------AABBBBBBA-- --------AABBBBBBA-- --------AABBBBBBA-- --------AABBBBBBA-- --------AABBBBBBA-- --------AABBBBBBA-- --------AABBBBBBA-- --------AABBBBBBA-- --------AABBBBBBA-- --------AABBBBBAA-- --------AABBBBAAA-- --------AABBBAA---- ---------AAAAA----- ------------------- ------------------- 
----AAAAAAAA------- ---AA----AAAAA----- --AA-----AAAAAA---- -AA------AABBBBAA-- -A------BAABBBBAAAA -A------BAABBBBBAAA AA------BAABBBBBAAA A--------AABBBBBAAA A--------AABBBBBAAA A-------AAABBBBBAAA A-------AAABBBBBAAA A-------AAABBBBBAAA A-------AAABBBBBAAA A-------AAABBBBBA-- A-------AAABBBBBA-- A-------AAABBBBBA-- A-------AAABBBBBA-- A-------AAABBBBBA-- A-------AAABBBBBA-- A-------AAABBBBBA-- A-------AAABBBBBA-- AA------AAABBBBBA-- -A------AAABBBBAA-- -A------AAABBBAAA-- -AA-----AAABBAA---- --AA-----AAAAA----- ---AA--AAA--------- ----AAAA----------- 
----AAAAAAAA------- ---AA----AAAAA----- --AA-----AAAAAA---- -AA------AABABAAA-- -A-------AABABAAA-- -A-------AABABAAA-- AA-------AABABAAA-- A--------AABABAAA-- A--------AABABAAA-- A--------AABABAAA-- A--------AABABAAA-- A--------AABABAAA-- A--------AABABAAA-- A--------AABABAAA-- A--------AABABAAA-- A--------AABABAAA-- A--------AABABAAA-- A--------AABABAAA-- A--------AABABAAA-- A--------AABABAAA-- A--------AABABAAA-- AA-------AABABAAA-- -A-------AABABAAA-- -A-------AABABAAA-- -AA------AABAAA---- --AA-----AAAAA----- ---AA--AAA--------- ----AAAA----------- 
