model
size = 23 12 29, scale = 0.05, origin = -y
material 
  colors = A:#005CAF B:#444 C:#EEE D:#E83015 E:#1B813E F:#197738 G:#D52E19 H:#FCFAF2
voxels
-------DDDDDDDDD------- -------DDDDDDDDD------- ----------------------- ----------------------- ----------------------- ----------------------- ----------------------- ----------------------- ----------------------- ----------------------- ----------------------- ----------------------- 
------DDEFFFFFEDD------ ------DDDGGGGGDDD------ ----------------------- ----------------------- ----------------------- ----------------------- ----------------------- ----------------------- ----------------------- ----------------------- ----------------------- ----------------------- 
-----DEEFEEEEEFEED----- -----DDDGDDDDDGDDD----- ----------------------- ----------------------- ----------------------- ----------------------- ----------------------- ----------------------- ----------------------- ----------------------- ----------------------- ----------------------- 
----DEEFEFFFFFEFEED---- ----DDDGDGGGGGDGDDD---- ----------------------- ----------------------- ----------------------- ----------------------- ----------------------- ----------------------- ----------------------- ----------------------- ----------------------- ----------------------- 
---DEEFEFEEEEEFEFEED--- ---DDDGDGDDDDDGDGDDD--- ----------------------- ----------------------- ----------------------- ----------------------- ----------------------- ----------------------- ----------------------- ----------------------- ----------------------- ----------------------- 
---DEFEFEFFFFFEFEFED--- ---DDGDGDGGGGGDGDGDD--- ----------------------- ----------------------- ----------------------- ----------------------- ----------------------- ----------------------- ----------------------- ----------------------- ----------------------- ----------------------- 
--DEFEFEFEEEEEFEFEFED-- --DDGDGDGDDDDDGDGDGDD-- ----------------------- ----------------------- ----------------------- ----------------------- ----------------------- ----------------------- ----------------------- ----------------------- ----------------------- ----------------------- 
--DFEFEFEEFFFEEFEFEFD-- --DGDGDGDDGGGDDGDGDGD-- ------BBB--B--BB------- ------B--B-B-B--B------ ------BBB--B-B--------- ------B--B-B-B--B------ ------BBB--B--BB------- -----------B----------- --------BBBBBBB-------- ----------------------- ----------------------- ----------------------- 
--DFEFEFEFEEEFEFEFEFD-- --DGDGDAAAAAAAAADGDGD-- ------CCCCCCCCCCC------ ------CCCCCCCCCCC------ ------CCCCCCCCCCC------ ------CCCCCCCCCCC------ ------CCCCCCCCCCC------ -------CCCCCCCCC------- --------CCCCCCC-------- ----------------------- ----------------------- ----------------------- 
--DFEFEBBBBBBBBBEFEFD-- --DGAAABBBBBBBBBAAAGD-- ----CCAAAAABAAAAACC---- ----CCAAAAABAAAAACC---- -----CAAAAABAAAAAC----- -----CAAAAABAAAAAC----- -----CAAAAABAAAAAC----- ------CAAAAAAAAAC------ -------CCCCCCCCC------- ----------------------- ----------------------- ----------------------- 
--DFEBB---------BBEFD-- --DAABB---------BBAAD-- ---CAA-----------AAC--- ---CAA-----------AAC--- ----CA-----------AC---- ----CA-----------AC---- ----CAA---------AAC---- -----CAAAAABAAAAAC----- ------CCCCAAACCCC------ ----------CCC---------- ----------------------- ----------------------- 
--ABBB-----------BBBA-- --AABB-----------BBAA-- --AA-B-----------BAAA-- --AA-B-----------BAAA-- ---CAB-----------BAC--- ---CAB-----------BAC--- ----CAA---------AAC---- -----CAA-------AAC----- ------CCAAABAAACC------ --------CCCCCCC-------- ----------------------- ----------------------- 
--AB---------------BA-- --AB---------------BA-- --A-----------------A-- --A-----------------A-- ---A---------------A--- ---A---------------A--- ----AAB---------BAA---- ----ACBA-------ABCA---- ------CCAAABAAACC------ --------CCCCCCC-------- ----------------------- ----------------------- 
-AAB---------------BAA- -AAB---------------BAH- -AA-----------------AH- -AA-----------------AA- --A----------------AA-- --A----------------AA-- ---A---------------A--- ---AAA-----------AAA--- -----AABAAABAAABAA----- -------ACCCCCCCA------- ----------------------- ----------------------- 
-AB-----------------BA- -AB-----------------BH- -A-------------------H- -A-------------------A- --A-----------------A-- --A-----------------A-- ---A---------------A--- ---AAA-----------AAA--- -----AAABA---ABAAA----- -------AACABACAA------- ----------CCC---------- ----------------------- 
AAB-----------------BAA AAB-----------------BAA AA-------------------AA -A-------------------A- -AA-----------------AA- --A-----------------A-- --AA---------------AA-- ---AAA-----------AAA--- ----AAAA-------AAAA---- ------AAABABABAAA------ ---------ACCCA--------- ----------------------- 
AB-------------------BA AB-------------------BA AA-------------------AA AA-------------------AA -AA-----------------AA- -AA-----------------AA- --AA---------------AA-- --AAAA-----------AAAA-- ----AAAA-------AAAA---- ------AAAABBBAAAA------ --------AAAAAAA-------- ----------DDD---------- 
AB-------------------BA AB-------------------BA AB-------------------BA AB-------------------BA -AB-----------------BA- -AB-----------------BA- --AB---------------BA-- --AABB-----------BBAA-- ----AABB-------BBAA---- ------AABBBBBBBAA------ --------AAADAAA-------- ----------DDD---------- 
AB-------------------BA AB-------------------BA AA-------------------AA AA-------------------AA -AA-----------------AA- -AA-----------------AA- --AA---------------AA-- --AAAA-----------AAAA-- ----AAAA-------AAAA---- ------AAAABBBAAAA------ --------AAAAAAA-------- ----------DDD---------- 
AB-------------------BA AB-------------------BA AA-------------------AA AA-------------------AA -AA-----------------AA- -AA-----------------AA- --AA---------------AA-- --AAAA-----------AAAA-- ----AAAAAB---BAAAAA---- ------AAABABABAAA------ ---------AAAAA--------- ----------------------- 
AB-------------------BA AB-------------------BA AA-------------------AA -A-------------------A- -AA-----------------AA- --A-----------------A-- --AA---------------AA-- ---AAA-----------AAA--- -----AAABA---ABAAA----- -------AAAABAAAA------- ----------AAA---------- ----------------------- 
AAB-----------------BAA AAB-----------------BAA -A-------------------A- -A-------------------A- --A-----------------A-- --A-----------------A-- ---A---------------A--- ---AAAAB-------BAAAA--- -----AAAAAABAAABAA----- -------AAAAAAAAA------- ----------------------- ----------------------- 
-AB-----------------BA- -AB-----------------BA- -A-------------------A- -A-------------------A- --A-----------------A-- --A-----------------A-- ---AAAB---------BAAA--- ---AAABA-------ABAAA--- -----AAAAAABAAAAAA----- -------AAAAAAAAA------- ----------------------- ----------------------- 
-AAB---------------BAA- -AAB---------------BAA- -AA-----------------AA- --A-----------------A-- --A-----------------A-- ---AAB-----------BAA--- ---AABA---------ABAA--- ----AAAA-------AAAA---- ------AAAAABAAAAA------ ---------AAAAA--------- ----------------------- ----------------------- 
--ABB-------------BBA-- --ABB-------------BBA-- --AAB-------------BAA-- --AAB-------------BAA-- ---AB-------------BA--- ---ABA-----------ABA--- ----AAA---------AAA---- -----AAAAAABAAAAAA----- -------AAAAAAAAA------- ----------------------- ----------------------- ----------------------- 
--AAB-------------BAA-- --AAB-------------BAA-- --AAA-------------AAA-- --AAA-------------AAA-- ----A-------------A---- ----AA-----------AA---- -----AA---------AA----- -------AAAABAAAA------- ---------AAAAA--------- ----------------------- ----------------------- ----------------------- 
---AABB---------BBAA--- ---AABB---------BBAA--- ---AAA-----------AAA--- ---AAA-----------AAA--- -----A-----------A----- -----A-----------A----- ------AAAAABAAAAA------ ---------AAAAA--------- ----------------------- ----------------------- ----------------------- ----------------------- 
----AAABB-----BBAAA---- ----AAABB-----BBAAA---- ----AAAAB-----BAAAA---- ----AAAAAB---BAAAAA---- ------AAAABBBAAAA------ ------AAAAABAAAAA------ ---------AAAAA--------- ----------------------- ----------------------- ----------------------- ----------------------- ----------------------- 
------AADGDGDGDAA------ ------AADDDDDDDAA------ ------AAA-----AAA------ ------AAAA---AAAA------ --------AAAAAAA-------- ---------AAAAA--------- ----------------------- ----------------------- ----------------------- ----------------------- ----------------------- ----------------------- 
