model
size = 21 30 3, scale = 0.05, origin = -y
material 
  colors = A:#E00 B:#EEE
voxels
---AAAAAAAAAAAAAAA--- ---ABBBBBBBBBBBBBA--- ---ABAAAAAAAAAAABA--- ---ABAABABAABBBABA--- --AABABBBBBAABAABA--- -AABAAABABAAABAABA--- -ABAAABBBBBAABAAABA-- AABAAAABABAABBAAAABA- ABAAABBBAAAAAAAAAABA- ABAABAAABBBAAAAAAAABA ABABAAABAAABBAAAAAABA ABAAAABAAABAABAAAAABA ABAAABAAABAAABAAAAABA ABAABAAABAAABABAAAABA ABAAAAABAABBBBAAAAABA AABAAAAAABAAAAAAAABAA -AABBAAAABBAAAAABBAA- --AAABBAAAABBBBBAAA-- ----AAABBBAAAABA----- ------AAAABAAABA----- ---------ABAAABA----- ---------ABAAABA----- ---------ABAAABA----- ---------ABAAABA----- ---------ABAAABA----- ---------ABAAABA----- ---------ABAAABA----- ---------ABAAABA----- ---------AABBBAA----- ----------AAAAA------ 
---AAA---------AAA--- ---AAA---------AAA--- ---AAA---------AAA--- ---AAA---------AAA--- --AAAA---------AAA--- -AAAAA---------AAA--- -AAAAA---------AAAA-- AAAAAA---------AAAAA- AAAAAA---------AAAAA- AAAAAA---------AAAAAA AAAAAA---------AAAAAA AAAAAA---------AAAAAA AAAAAA---------AAAAAA AAAAAA---------AAAAAA AAAAAA---------AAAAAA AAAAAA---------AAAAAA -AAAAA---------AAAAA- --AAAAAAAAAAAAAAAAA-- ----AAAAAAAAAAAA----- ------AAAAAAAAAA----- ---------AAAAAAA----- ---------AAAAAAA----- ---------AAAAAAA----- ---------AAAAAAA----- ---------AAAAAAA----- ---------AAAAAAA----- ---------AAAAAAA----- ---------AAAAAAA----- ---------AAAAAAA----- ----------AAAAA------ 
---AAAAAAAAAAAAAAA--- ---ABBBBBBBBBBBBBA--- ---ABAAAAAAAAAAABA--- ---ABABBBAABABAABA--- --AABAABAABBBBBABA--- -AABAAABAAABABAABA--- -ABAAAABAABBBBBABAA-- AABAAAABBAABABAAABAA- ABAAABBBAAAAAAAAAABA- ABAABAAABBBAAAAAAABAA ABABAAABAAABBAAAAAABA ABAAAABAAABAABAAAAABA ABAAABAAABAAABBAAAABA ABAAAAAABAAABABAAAABA ABAAAAABAABBBBAAAAABA AABAAAAAABAAAAAAAABAA -AABBAAAABBAAAAABBAA- --AAABBAAAABBBBBAAA-- ----AAABBBAAAABA----- ------AAAABAAABA----- ---------ABAAABA----- ---------ABAAABA----- ---------ABAAABA----- ---------ABAAABA----- ---------ABAAABA----- ---------ABAAABA----- ---------ABAAABA----- ---------ABAAABA----- ---------AABBBAA----- ----------AAAAA------ 
