model
size = 16 14 21, scale = 0.05, origin = -y
material 
  colors = A:#BBB B:#630 C:#993 D:#555 E:#D00 F:#111 G:#930
voxels
---------------- ---------------- ---------------- ---------------- ---------------- ---------------- ---------------- ---------------- ---------------- ---------------- -------GG------- ---------------- ---------------- ---------------- 
---------------- ---------------- ---------------- ---------------- ---------------- ---------------- ---------------- ---------------- ---------------- ---------------- -------GG------- ---------------- ---------------- ---------------- 
---------------- ---------------- ---------------- ---------------- ---------------- ---------------- ---------------- -------EE------- -------EE------- -------EE------- ------AAAA------ ------AAAA------ ------FAAF------ ------AAAA------ 
---------------- BBBBBBBBBBBBBBBB BBBBBBBBBBBBBBBB ---C------------ ---------------- ---------------- ---------------- ---------------- -------EE------- ------AAAA------ ------AAAA------ ------AAAA------ ------AAAA------ ------AAAA------ 
---------------- BBBBBBBBBBBBBBBB B--C--C--------B ---------------- ---------------- ------AAAA------ ------AAAA------ ------AAAA------ ------AAAA------ ------AAAA------ ------AAAA------ ------AAAA------ ------AAAA------ ------AAAA------ 
--BBBBBBBBBBBB-- BBBBBBBBBBBBBBBB B-----AAAAC-CC-B -----AAAAAA----- -----AAAAAA----- -----AAAAAA----- -----AAAAAA----- ------AAAA------ ------AAAA------ ------AAAA------ ------AAAA------ ------AAAA------ -------AA------- -------AA------- 
--B----------B-- BBBBBBBBBBBBBBBB B-C--AAAAAACC--B ----AAAAAAAA---- ----AAAAAAAA---- ----AAAAAAAA---- -----AAAAAA----- -----AAAAAA----- ------AAAA------ ------AAAA------ -------AA------- ---------------- ---------------- ---------------- 
--B----------B-- BBBBBBBBBBBBBBBB B-C--AAAAAA----B ----AAAAAAAA---- ----AAAAAAAA---- ----AAAAAAAA---- ----AAAAAAAA---- -----AAAAAA----- ------AAAA------ -------AA------- ---------------- ---------------- ---------------- ---------------- 
--B----------B-- BBBBBBBBBBBBBBBB B----AAAAAA--C-B ----AAAAAAAA---- ----AAAAAAAA---- ----AAAAAAAA---- ----AAAAAAAA---- -----AAAAAA----- ------AAAA------ -------AA------- ---------------- ---------------- ---------------- ---------------- 
--B----------B-- BBBBBBBAABBBBBBB B--C-AAAAAA--C-B ----AAAAAAAA---- ----AAAAAAAA---- ----AAAAAAAA---- ----AAAAAAAA---- -----AAAAAA----- ------AAAA------ -------AA------- ---------------- ---------------- ---------------- ---------------- 
--B----------B-- BBBBBBBAABBBBBBB B----AAAAAA--C-B ----AAAAAAAA---- ----AAAAAAAA---- ----AAAAAAAA---- ----AAAAAAAA---- -----AAAAAA----- ------AAAA------ ---------------- ---------------- ---------------- ---------------- ---------------- 
--B----------B-- BBBBBBBAABBBBBBB B-C--AAAAAA--C-B ----AAAAAAAA---- ----AAAAAAAA---- ----AAAAAAAA---- ----AAAAAAAA---- -----AAAAAA----- ------AAAA------ ---------------- ---------------- ---------------- ---------------- ---------------- 
--B----------B-- BBBBBBBAABBBBBBB BCC--AAAAAA--C-B ----AAAAAAAA---- ----FAAAAAAF---- ----AAAAAAAA---- ----AAAAAAAA---- -----AAAAAA----- ------AAAA------ ---------------- ---------------- ---------------- ---------------- ---------------- 
--B----------B-- BBBBBBBBBBBBBBBB B----AAAAAA-C--B ----FAAAAAAF---- ----AAAAAAAA---- ----AAAAAAAA---- -----AAAAAA----- -----AAAAAA----- ------AAAA------ ---------------- ---------------- ---------------- ---------------- ---------------- 
--B----------B-- BBBBBBBBBBBBBBBB B----AAAAAA----B ----AAAAAAAA---- ----AAAAAAAA---- -----AAAAAA----- -----AAAAAA----- ------AAAA------ ------AAAA------ ---------------- ---------------- ---------------- ---------------- ---------------- 
--B----------B-- BBBBBBBBBBBBBBBB B-CC-AAAAAA----B ----AAAAAAAA---- ----AAAAAAAA---- -----AAAAAA----- ------AAAA------ ------AAAA------ -------AA------- ---------------- ---------------- ---------------- ---------------- ---------------- 
--BBBBBBBBBBBB-- BBBBBBBBBBBBBBBB B-CC--AAAA---C-B -----AAAAAA----- -----AAAAAA----- ------AAAA------ ------AAAA------ -------AA------- -------AA------- ---------------- ---------------- ---------------- ---------------- ---------------- 
---------------- BBBBBBBBBBBBBBBB B-----------C--B ---------------- -------AA------- -------AA------- -------AA------- -------AA------- -------AA------- -------AA------- ---------------- ---------------- ---------------- ---------------- 
---------------- BBBBBBBBBBBBBBBB BBBBBBBBBBBBBBBB ---------------- ---------------- -------AA------- -------AA------- -------AA------- -------AA------- -------AA------- -------AA------- ---------------- ---------------- ---------------- 
---------------- ---------------- ---------------- ---------------- ---------------- ---------------- -------AA------- -------AA------- -------AA------- -------AA------- -------DD------- -------DD------- ---------------- ---------------- 
---------------- ---------------- ---------------- ---------------- ---------------- ---------------- ---------------- ---------------- -------AA------- -------AA------- -------DD------- -------DD------- -------DD------- ---------------- 
