model
size = 30 32 16, scale = 0.05, origin = -y
material 
  colors = A:#EEE B:#222 C:#D05B5B D:#507AAF
voxels
38-D10BC17-DBC8-DBC15-DBC10-DBC13-DBC5-D4BC-DBC11-DBC10-DBC-DBC10-DBC11-2(DBC)10-DBC14-DBC10-DBC5-D3BC4-DBC10-DBC4-DBC-DBC3-3(DBC10-2(DBC3-)DBC2-)DBC10-DBC4-2(DBC2-)DBC22-DBC13-D2B2(CDB)C3-DBCD2BCBCDBC4-2(DBC)4BCD3BCDBC-2(DBC)4-2(DBC)BCD2(BC)3-DBC-2(DBC)5-D2BC-D2BCDBC4-D2BC3BC15-DBC-DBC3-DBC10-DBC5-2(DBC)3-DBC10-DBC6-D2BC4-2(DBC10-)DBC14-DBC11-D6B9-DBC17-D3BC5-DBC14-D3BC8-DBC13-DBC11-2(DBC)11-D2BC9-D3(BC)12-D2BC7-D2BC-D3B4-D6BC9-DBC5-D5BC49-12(12A17-14A15-16A13-18A11-20A9-8(22A8-)22A7-25A4-27A2(2-28A)3-26A5-24A7-3(22A8-)26A4-27A3-26A4-23A7-24A6-25A5-24A6-5A-16A9-3A5-7A19-)12A17-14A15-16A13-18A11-20A9-8(22A8-)22A7-25A4-27A2(2-28A)3-26A5-24A7-3(22A8-)26A4-27A3-26A4-23A7-24A6-25A5-24A6-5A-16A9-3A5-7A49-12A17-14A15-16A13-18A11-8(20A10-)20A9-22A7-25A2(4-26A)5-24A7-22A9-3(20A10-)21A9-25A5-22A8-21A9-22A8-23A7-4A-16A9-3A5-7A109-12A17-14A15-16A13-8(18A12-)18A11-20A9-23A2(6-24A)7-22A9-20A11-3(18A12-)19A11-2(20A10-)19A11-20A10-3A-15A11-2A5-7A71-
