model
size = 23 30 29, scale = 0.05, origin = -y
material 
  colors = A:#E83015 B:#444 C:#AE2626 D:#2D6D4B E:#FEDFE1 F:#FB9966 G:#222 H:#DDD I:#888 J:#777 K:#FFFFFB L:#7DB9DE M:#EEE N:#555
voxels
----------------------- ----------------------- ----------------------- ----------------------- ----------------------- ----------------------- ----------------------- ----------------------- ----------------------- ----------------------- ----------------------- ----------------------- ----------------------- ----------------------- ----------------------- ----------------------- ----------------------- ----------------------- -------DDDDDDDDD------- -------DDDDDDDDD------- ----------------------- ----------------------- ----------------------- ----------------------- ----------------------- ----------------------- ----------------------- ----------------------- ----------------------- ----------------------- 
----------------------- ----------------------- ----------------------- ----------------------- ----------------------- ----------------------- ----------------------- ----------------------- ----------------------- ----------------------- ----------------------- ----------------------- ----------------------- ----------------------- ----------------------- ----------------------- ----------------------- ----------------------- ------DDIJJJJJIDD------ ------DDDEEEEEDDD------ ----------------------- ----------------------- ----------------------- ----------------------- ----------------------- ----------------------- ----------------------- ----------------------- ----------------------- ----------------------- 
----------------------- ----------------------- ----------------------- ----------------------- ----------------------- ----------------------- ----------------------- ----------------------- ----------------------- ----------------------- ----------------------- ----------------------- ----------------------- ----------------------- ----------------------- ----------------------- ----------------------- ----------------------- -----DIIJIIIIIJIID----- -----DDDEDDDDDEDDD----- ----------------------- ----------------------- ----------------------- ----------------------- ----------------------- ----------------------- ----------------------- ----------------------- ----------------------- ----------------------- 
----------------------- ----------------------- ----------------------- ----------------------- ----------------------- ----------------------- ----------------------- ----------------------- ----------------------- ----------------------- ----------------------- ----------------------- ----------------------- ----------------------- ----------------------- ----------------------- ----------------------- ----------------------- ----DIIJIJJJJJIJIID---- ----DDDEDEEEEEDEDDD---- ----------------------- ----------------------- ----------------------- ----------------------- ----------------------- ----------------------- ----------------------- ----------------------- ----------------------- ----------------------- 
----------------------- ----------------------- ----------------------- ----------------------- ----------------------- ----------------------- ----------------------- ----------FFF---------- ----------FFF---------- ----------------------- ----------------------- ----------------------- ----------------------- ----------------------- ----------------------- ----------------------- ----------------------- ----------------------- ---DIIJIJIIIIIJIJIID--- ---DDDEDEDDDDDEDEDDD--- ----------------------- ----------------------- ----------------------- ----------------------- ----------------------- ----------------------- ----------------------- ----------------------- ----------------------- ----------------------- 
----------------------- ----------------------- ----------------------- ----------------------- ----------------------- ----------------------- ----------------------- ----------FFF---------- ----------FFF---------- ----------FFF---------- ----------------------- ----------------------- ----------------------- ----------------------- ----------------------- ----------------------- ----------------------- ----------------------- ---DIJIJIJJJJJIJIJID--- ---DDEDEDEEEEEDEDEDD--- ----------------------- ----------------------- ----------------------- ----------------------- ----------------------- ----------------------- ----------------------- ----------------------- ----------------------- ----------------------- 
----------------------- ----------------------- ----------------------- ----------------------- ----------------------- ----------------------- ----------------------- ----------FFF---------- ---------FFFFF--------- ----------FFF---------- ----------FFF---------- -----------F----------- ----------------------- ----------------------- ----------------------- ----------------------- ----------------------- ----------------------- --DIJIJIJIIIIIJIJIJID-- --DDEDEDEDDDDDEDEDEDD-- ----------------------- ----------------------- ----------------------- ----------------------- ----------------------- ----------------------- ----------------------- ----------------------- ----------------------- ----------------------- 
----------------------- ----------------------- ----------------------- ----------------------- ----------------------- -------H-H-H-H-H------- --------HHHFHHH-------- ----------FFF---------- ---------FFFFF--------- ---------FFFFF--------- ----------FFF---------- ----------FFF---------- ----------FFF---------- -----------F----------- ----------------------- ----------------------- ----------------------- ----------------------- --DJIJIJIIJJJIIJIJIJD-- --DEDEDEDDDDDDDEDEDED-- -----------M----------- ----------------------- -----------M----------- ------------M---------- ------------M---------- ----------MM----------- ----------------------- ----------------------- ----------------------- ----------------------- 
----------------------- ----------------------- ----------------------- ----------------------- --------H-H-H-H-------- ------HHHHHHHHHHH------ -------HHGGGGGHH------- ---------FFFFF--------- ---------FFFFF--------- ---------FFFFF--------- ---------FFFFF--------- -----GGGG-FFF-GGGG----- ----G----GFFFG----G---- ----G----GFFFG----G---- ----G----GFFFG----G---- -----GGGGGGFGGGGGG----- ----------GGG---------- -----HHHH-----HHHH----- --DJIJIJIJIIIJIJIJIJD-- --DEDEDAAAAAAAAADEDED-- ------AAAAAAAAAAA------ ------AAAAAAAAAAA------ ------AAAAAAAAAAA------ ------AAAAAAAAAAA------ -------AAAAAAAAA------- -------AAAAAAAAA------- ----------------------- ----------------------- ----------------------- ----------------------- 
----------------------- ----------------------- ----------------------- -------H-H-H-H-H------- ------HHHHHHHHHHH------ ------HHHHHHHHHHH------ -------HHHHFHHHH------- --------HHFFFHH-------- ---------FFFFF--------- ---------FFFFF--------- ---------FFFFF--------- -----GGGG-FFF-GGGG----- ----GKKLNGFFFGKKLNG---- ----GKKLLGFFFGKKLLG---- ----GKKKKGFFFGKKKKG---- -----GGGGGGFGGGGGG----- ----------GGG---------- -----HHHHH----HHHHH---- --DJIJIBBBBBBBBBIJIJD-- --DEAAABBBBBBBBBAAAED-- ----AAA----A----AAA---- ----AAA----A----AAA---- -----AA----A----AA----- -----AA----A----AA----- -----AA----A----AA----- ------AAAAAAAAAAA------ --------AAAAAAA-------- ----------------------- ----------------------- ----------------------- 
----------------------- ----------------------- ----------------------- ----------------------- ----------------------- ----------------------- ----------------------- ----------------------- ----------------------- ----------------------- ----------------------- ----------------------- ----------------------- ----------------------- ----G-------------G---- ----------------------- ----------------------- ----------------------- --DJIBB---------BBIJD-- --DAABB---------BBAAD-- ---AAA-----------AAA--- ---AAA-----------AAA--- ----AA-----------AA---- -----A-----------A----- -----AA---------AA----- ------AAAAAAAAAAA------ -------AAAAAAAAA------- ----------------------- ----------------------- ----------------------- 
----------------------- ----------------------- ----------------------- ----------------------- ----------------------- ----------------------- ----------------------- ----------------------- ----------------------- ----------------------- ----------------------- ----------------------- ----------------------- --A-----------------A-- --A-G-------------G-A-- --A-----------------A-- --A-----------------A-- --A-----------------A-- --ABBB-----------BBBA-- --AABB-----------BBAA-- --AAAB-----------BAAA-- --AAAB-----------BAAA-- ---AAB-----------BAA--- ----AB-----------BA---- -----AA---------AA----- -----AA---------AA----- -------AAAAAAAAA------- ----------AAA---------- ----------------------- ----------------------- 
----------------------- ----------------------- ----------------------- ----------------------- ----------------------- ----------------------- ----------------------- ----------------------- ----------------------- --A-----------------A-- --A-----------------A-- --A-----------------A-- --A-----------------A-- --A-----------------A-- --A-G-------------G-A-- --A-----------------A-- --A-----------------A-- --A-----------------A-- --AB---------------BA-- --AB---------------BA-- --A-----------------A-- --A-----------------A-- --AA---------------AA-- ---A---------------A--- ----AAB---------BAA---- ----AAB---------BAA---- ------AAAAABAAAAA------ --------AAAAAAA-------- ----------------------- ----------------------- 
----------------------- ----------------------- ----------------------- ----------------------- ----------------------- ----------------------- ----------------------- ----------------------- -AA-----------------AA- -AE-----------------EA- -AC-----------------CA- -AC-----------------CA- -AC-----------------CA- -AE-----------------EA- -AC-G-------------G-CA- -AC-----------------CA- -AC-----------------CA- -AE-----------------EA- -AAB---------------BAA- -AAB---------------BAA- -AA-----------------AA- -AA-----------------AA- --AA---------------AA-- --AA---------------AA-- ---A---------------A--- ---AAA-----------AAA--- -----AABAAABAAABAA----- -------AAAAAAAAA------- ----------------------- ----------------------- 
----------------------- ----------------------- ----------------------- ----------------------- ----------------------- ----------------------- ----------------------- AA--------------------- AE-------------------AA AC-------------------CA AE-------------------EA AC-------------------CA AE-------------------EA AC-------------------CA AE--G-------------G--CA AC-------------------CA AE-------------------EA AC-------------------CA AAB-----------------BAA -AB-----------------BA- -A-------------------A- -A-------------------A- --A-----------------A-- --A-----------------A-- ---A---------------A--- ---AAA-----------AAA--- -----AAAB-----BAAA----- -------AAAABAAAA------- ----------AAA---------- ----------------------- 
----------------------- ----------------------- ----------------------- ----------------------- ----------------------- ----------------------- ----------------------- AA-------------------AA AC-------------------CA AC-------------------CA AC-------------------CA AE-------------------EA AC-------------------CA AC-------------------CA AC--G-------------G--CA AE-------------------EA AC-------------------CA AC-------------------CA AAB-----------------BAA AAB-----------------BAA AA-------------------AA -A-------------------A- -AA-----------------AA- --A-----------------A-- --AA---------------AA-- ---AAA-----------AAA--- ----AAAA-------AAAA---- ------AAABABABAAA------ ---------AAAAA--------- ----------------------- 
----------------------- ----------------------- ----------------------- ----------------------- ----------------------- ----------------------- A---------------------A AA-------------------AA AE-------------------EA AC-------------------CA AE-------------------EA AC-------------------CA AE-------------------EA AC-------------------CA AE--G-------------G--EA AC-------------------CA AE-------------------CA AC-------------------CA AB-------------------BA AB-------------------BA AA-------------------AA AA-------------------AA -AA-----------------AA- -AA-----------------AA- --AA---------------AA-- --AAAA-----------AAAA-- ----AAAA-------AAAA---- ------AAAABBBAAAA------ --------AAAAAAA-------- ----------DDD---------- 
D---------------------D D---------------------D D---------------------D D---------------------D D---------------------D D---------------------D D---------------------D DA-------------------AD AC-------------------CA AE-------------------EA AC-------------------CA AC-------------------CA AC-------------------CA AE-------------------EA AC--G-------------G--CA AC-------------------CA AC-------------------CA AE-------------------EA AB-------------------BA AB-------------------BA AB-------------------BA AB-------------------BA -AB-----------------BA- -AB-----------------BA- --AB---------------BA-- --AABB-----------BBAA-- ----AABB-------BBAA---- ------AABBBBBBBAA------ --------AAADAAA-------- ----------DDD---------- 
D---------------------D D---------------------D D---------------------D D---------------------D D---------------------D D---------------------D D---------------------D DA-------------------AD AE-------------------EA AC-------------------CA AE-------------------EA AC-------------------CA AE-------------------EA AC-------------------CA AE--G-------------G--EA AC-------------------CA AE-------------------EA AC-------------------CA AB-------------------BA AB-------------------BA AA-------------------AA AA-------------------AA -AA-----------------AA- -AA-----------------AA- --AA---------------AA-- --AAAA-----------AAAA-- ----AAAA-------AAAA---- ------AAAABBBAAAA------ --------AAAAAAA-------- ----------DDD---------- 
----------------------- ----------------------- ----------------------- ----------------------- ----------------------- ----------------------- A---------------------A AA-------------------AA AC-------------------CA AC-------------------CA AC-------------------CA AE-------------------EA AC--G-------------G--CA AC--G-------------G--CA AC--G-------------G--CA AE-------------------EA AC-------------------CA AC-------------------CA AB-------------------BA AB-------------------BA AA-------------------AA AA-------------------AA -AA-----------------AA- -AA-----------------AA- --AA---------------AA-- --AAAA-----------AAAA-- ----AAAAAB---BAAAAA---- ------AAABABABAAA------ ---------AAAAA--------- ----------------------- 
----------------------- ----------------------- ----------------------- ----------------------- ----------------------- ----------------------- ----------------------- AA-------------------AA AE-------------------EA AC-------------------CA AE-------------------EA AC-------------------CA AE-------------------EA AC-------------------CA AE-------------------EA AC-------------------CA AE-------------------EA AC-------------------CA AB-------------------BA AB-------------------BA AA-------------------AA -A-------------------A- -AA-----------------AA- --A-----------------A-- --AA---------------AA-- ---AAA-----------AAA--- -----AAABA---ABAAA----- -------AAAABAAAA------- ----------AAA---------- ----------------------- 
----------------------- ----------------------- ----------------------- ----------------------- ----------------------- ----------------------- ----------------------- ----------------------- AA-------------------AA AE-------------------EA AC-------------------CA AC-------------------CA AC-------------------CA AE-------------------EA AC-------------------CA AC-------------------CA AC-------------------CA AE-------------------EA AAB-----------------BAA AAB-----------------BAA -A-------------------A- -A-------------------A- --A-----------------A-- --A-----------------A-- ---A---------------A--- ---AAAAB-------BAAAA--- -----AAAAAABAAABAA----- -------AAAAAAAAA------- ----------------------- ----------------------- 
----------------------- ----------------------- ----------------------- ----------------------- ----------------------- ----------------------- ----------------------- ----------------------- -A-------------------A- -AC-----------------CA- -AE-----------------EA- -AC-----------------CA- -AE-----------------EA- -AC-----------------CA- -AE-----------------EA- -AC-----------------CA- -AE-----------------EA- -AC-----------------CA- -AB-----------------BA- -AB-----------------BA- -A-------------------A- -A-------------------A- --A-----------------A-- --A-----------------A-- ---AAAB---------BAAA--- ---AAABA-------ABAAA--- -----AAAAAABAAAAAA----- -------AAAAAAAAA------- ----------------------- ----------------------- 
----------------------- ----------------------- ----------------------- ----------------------- ----------------------- ----------------------- ----------------------- ----------------------- --A-----------------AA- -AE-----------------CA- -AC-----------------CA- -AE-----------------EA- -AC-----------------CA- -AC-----------------CA- -AC-----------------CA- -AE-----------------EA- -AC-----------------CA- -AC-----------------CA- -AAB---------------BAA- -AAB---------------BAA- -AA-----------------AA- --A-----------------A-- --A-----------------A-- ---AAB-----------BAA--- ---AABA---------ABAA--- ----AAAA-------AAAA---- ------AAAAABAAAAA------ ---------AAAAA--------- ----------------------- ----------------------- 
----------------------- ----------------------- ----------------------- ----------------------- ----------------------- ----------------------- ----------------------- ----------------------- --A-----------------A-- --A-----------------A-- --A-----------------A-- --AC----------------A-- --AE---------------EA-- --AC---------------CA-- --AE---------------EA-- --AC---------------CA-- --AE---------------EA-- --AC---------------CA-- --ABB-------------BBA-- --ABB-------------BBA-- --AAB-------------BAA-- --AAB-------------BAA-- ---AB-------------BA--- ---ABA-----------ABA--- ----AAA---------AAA---- -----AAAAAABAAAAAA----- -------AAAAAAAAA------- ----------------------- ----------------------- ----------------------- 
----------------------- ----------------------- ----------------------- ----------------------- ----------------------- ----------------------- ----------------------- ----------------------- ----------------------- --A-----------------A-- --AA---------------AA-- --AE---------------AA-- --AC---------------CA-- --AE---------------EA-- --AC---------------CA-- --AC---------------CA-- --AC---------------CA-- --AE---------------EA-- --AAB-------------BAA-- --AAB-------------BAA-- --AAA-------------AAA-- ---AA-------------AA--- ----A-------------A---- ----AA-----------AA---- -----AA---------AA----- -------AAAABAAAA------- ---------AAAAA--------- ----------------------- ----------------------- ----------------------- 
----------------------- ----------------------- ----------------------- ----------------------- ----------------------- ----------------------- ----------------------- ----------------------- ----------------------- ----------------------- ---AA-------------AA--- ---AA-------------AA--- ---AE-------------AA--- ---AC-------------CA--- ---AE-------------EA--- ---ACE-----------ECA--- ---AEC-----------CEA--- ---ACC-----------CCA--- ---AABB---------BBAA--- ---AABB---------BBAA--- ---AAA-----------AAA--- ----AA-----------AA---- -----A-----------A----- -----A-----------A----- ------AAAAABAAAAA------ ---------AAAAA--------- ----------------------- ----------------------- ----------------------- ----------------------- 
----------------------- ----------------------- ----------------------- ----------------------- ----------------------- ----------------------- ----------------------- ----------------------- ----------------------- ----------------------- ----------------------- ----A-------------A---- ----AA-----------AA---- ----AAA---------AAA---- ----AAAAAAAAAAAAAAA---- ----AACCCECCCECCCAA---- ----AAECECECECECEAA---- ----AACECCCECCCECAA---- ----AAABBBBBBBBBAAA---- ----AAABBBBBBBBBAAA---- ----AAAAAAABAAAAAAA---- -----AAAAAABAAAAAA----- ------AAAAABAAAAA------ ------AAAAABAAAAA------ ---------AAAAA--------- ----------------------- ----------------------- ----------------------- ----------------------- ----------------------- 
----------------------- ----------------------- ----------------------- ----------------------- ----------------------- ----------------------- ----------------------- ----------------------- ----------------------- ----------------------- ----------------------- ----------------------- ----------------------- ----------------------- -------AAAAAAAAA------- ------AAAAAAAAAAA------ ------AAAAAAAAAAA------ ------AAAAAAAAAAA------ ------AAAAAAAAAAA------ ------AAAAAAAAAAA------ ------AAAAAAAAAAA------ -------AAAAAAAAA------- --------AAAAAAA-------- ---------AAAAA--------- ----------------------- ----------------------- ----------------------- ----------------------- ----------------------- ----------------------- 
