model
size = 23 30 29, scale = 0.05, origin = -y
material 
  colors = A:#EBB471 B:#444 C:#222 D:#BC9F77 E:#6E552F F:#FB9966 G:#AA8F6B H:#888 I:#777 J:#855B32 K:#FFFFFB L:#7DB9DE M:#555
voxels
----------------------- ----------------------- ----------------------- ----------------------- ----------------------- ----------------------- ----------------------- ----------------------- ----------------------- ----------------------- ----------------------- ----------------------- ----------------------- ----------------------- ----------------------- ----------------------- ----------------------- ----------------------- -------EEEEEEEEE------- -------EEEEEEEEE------- ----------------------- ----------------------- ----------------------- ----------------------- ----------------------- ----------------------- ----------------------- ----------------------- ----------------------- ----------------------- 
----------------------- ----------------------- ----------------------- ----------------------- ----------------------- ----------------------- ----------------------- ----------------------- ----------------------- ----------------------- ----------------------- ----------------------- ----------------------- ----------------------- ----------------------- ----------------------- ----------------------- ----------------------- ------EEHIIIIIHEE------ ------EEEJJJJJEEE------ ----------------------- ----------------------- ----------------------- ----------------------- ----------------------- ----------------------- ----------------------- ----------------------- ----------------------- ----------------------- 
----------------------- ----------------------- ----------------------- ----------------------- ----------------------- ----------------------- ----------------------- ----------------------- ----------------------- ----------------------- ----------------------- ----------------------- ----------------------- ----------------------- ----------------------- ----------------------- ----------------------- ----------------------- -----EHHIHHHHHIHHE----- -----EEEJEEEEEJEEE----- ----------------------- ----------------------- ----------------------- ----------------------- ----------------------- ----------------------- ----------------------- ----------------------- ----------------------- ----------------------- 
----------------------- ----------------------- ----------------------- ----------------------- ----------------------- ----------------------- ----------------------- ----------------------- ----------------------- ----------------------- ----------------------- ----------------------- ----------------------- ----------------------- ----------------------- ----------------------- ----------------------- ----------------------- ----EHHIHIIIIIHIHHE---- ----EEEJEJJJJJEJEEE---- ----------------------- ----------------------- ----------------------- ----------------------- ----------------------- ----------------------- ----------------------- ----------------------- ----------------------- ----------------------- 
----------------------- ----------------------- ----------------------- ----------------------- ----------------------- ----------------------- ----------------------- ----------FFF---------- ----------FFF---------- ----------------------- ----------------------- ----------------------- ----------------------- ----------------------- ----------------------- ----------------------- ----------------------- ----------------------- ---EHHIHIHHHHHIHIHHE--- ---EEEJEJEEEEEJEJEEE--- ----------------------- ----------------------- ----------------------- ----------------------- ----------------------- ----------------------- ----------------------- ----------------------- ----------------------- ----------------------- 
----------------------- ----------------------- ----------------------- ----------------------- ----------------------- ----------------------- ----------------------- ----------FFF---------- ----------FFF---------- ----------FFF---------- ----------------------- ----------------------- ----------------------- ----------------------- ----------------------- ----------------------- ----------------------- ----------------------- ---EHIHIHIIIIIHIHIHE--- ---EEJEJEJJJJJEJEJEE--- ----------------------- ----------------------- ----------------------- ----------------------- ----------------------- ----------------------- ----------------------- ----------------------- ----------------------- ----------------------- 
----------------------- ----------------------- ----------------------- ----------------------- ----------------------- ----------------------- ----------------------- ----------FFF---------- ---------FFFFF--------- ----------FFF---------- ----------FFF---------- -----------F----------- ----------------------- ----------------------- ----------------------- ----------------------- ----------------------- ----------------------- --EHIHIHIHHHHHIHIHIHE-- --EEJEJEJEEEEEJEJEJEE-- ----------------------- ----------------------- ----------------------- ----------------------- ----------------------- ----------------------- ----------------------- ----------------------- ----------------------- ----------------------- 
----------------------- ----------------------- ----------------------- ----------------------- ----------------------- -------C-C-C-C-C------- --------CCCFCCC-------- ----------FFF---------- ---------FFFFF--------- ---------FFFFF--------- ----------FFF---------- ----------FFF---------- ----------FFF---------- -----------F----------- ----------------------- ----------------------- ----------------------- ----------------------- --EIHIHIHHIIIHHIHIHIE-- --EJEJEJEEEEEEEJEJEJE-- -----------C----------- ----------------------- -----------C----------- ------------C---------- ------------C---------- ----------CC----------- ----------------------- ----------------------- ----------------------- ----------------------- 
----------------------- ----------------------- ----------------------- ----------------------- --------C-C-C-C-------- ------CCCCCCCCCCC------ -------CCCCCCCCC------- ---------FFFFF--------- ---------FFFFF--------- ---------FFFFF--------- ---------FFFFF--------- -----CCCC-FFF-CCCC----- ----C----CFFFC----C---- ----C----CFFFC----C---- ----C----CFFFC----C---- -----CCCCCCFCCCCCC----- ----------CCC---------- -----CCCC-----CCCC----- --EIHIHIHIHHHIHIHIHIE-- --EJEJEAAAAAAAAAEJEJE-- ------AAAAAAAAAAA------ ------AAAAAAAAAAA------ ------AAAAAAAAAAA------ ------AAAAAAAAAAA------ -------AAAAAAAAA------- -------AAAAAAAAA------- ----------------------- ----------------------- ----------------------- ----------------------- 
----------------------- ----------------------- ----------------------- -------C-C-C-C-C------- ------CCCCCCCCCCC------ ------CCCCCCCCCCC------ -------CCCCFCCCC------- --------CCFFFCC-------- ---------FFFFF--------- ---------FFFFF--------- ---------FFFFF--------- -----CCCC-FFF-CCCC----- ----CKKLMCFFFCKKLMC---- ----CKKLLCFFFCKKLLC---- ----CKKKKCFFFCKKKKC---- -----CCCCCCFCCCCCC----- ----------CCC---------- -----CCCCC----CCCCC---- --EIHIHBBBBBBBBBHIHIE-- --EJAAABBBBBBBBBAAAJE-- ----AAA----A----AAA---- ----AAA----A----AAA---- -----AA----A----AA----- -----AA----A----AA----- -----AA----A----AA----- ------AAAAAAAAAAA------ --------AAAAAAA-------- ----------------------- ----------------------- ----------------------- 
----------------------- ----------------------- ----------------------- ----------------------- ----------------------- ----------------------- ----------------------- ----------------------- ----------------------- ----------------------- ----------------------- ----------------------- ----------------------- ----------------------- ----C-------------C---- ----------------------- ----------------------- ----------------------- --EIHBB---------BBHIE-- --EAABB---------BBAAE-- ---AAA-----------AAA--- ---AAA-----------AAA--- ----AA-----------AA---- -----A-----------A----- -----AA---------AA----- ------AAAAAAAAAAA------ -------AAAAAAAAA------- ----------------------- ----------------------- ----------------------- 
----------------------- ----------------------- ----------------------- ----------------------- ----------------------- ----------------------- ----------------------- ----------------------- ----------------------- ----------------------- ----------------------- ----------------------- ----------------------- --A-----------------A-- --A-C-------------C-A-- --A-----------------A-- --A-----------------A-- --A-----------------A-- --ABBB-----------BBBA-- --AABB-----------BBAA-- --AAAB-----------BAAA-- --AAAB-----------BAAA-- ---AAB-----------BAA--- ----AB-----------BA---- -----AA---------AA----- -----AA---------AA----- -------AAAAAAAAA------- ----------AAA---------- ----------------------- ----------------------- 
----------------------- ----------------------- ----------------------- ----------------------- ----------------------- ----------------------- ----------------------- ----------------------- ----------------------- --A-----------------A-- --A-----------------A-- --A-----------------A-- --A-----------------A-- --A-----------------A-- --A-C-------------C-A-- --A-----------------A-- --A-----------------A-- --A-----------------A-- --AB---------------BA-- --AB---------------BA-- --A-----------------A-- --A-----------------A-- --AA---------------AA-- ---A---------------A--- ----AAB---------BAA---- ----AAB---------BAA---- ------AAAAABAAAAA------ --------AAAAAAA-------- ----------------------- ----------------------- 
----------------------- ----------------------- ----------------------- ----------------------- ----------------------- ----------------------- ----------------------- ----------------------- -AA-----------------AA- -AG-----------------GA- -AD-----------------DA- -AD-----------------DA- -AD-----------------DA- -AG-----------------GA- -AD-C-------------C-DA- -AD-----------------DA- -AD-----------------DA- -AG-----------------GA- -AAB---------------BAA- -AAB---------------BAA- -AA-----------------AA- -AA-----------------AA- --AA---------------AA-- --AA---------------AA-- ---A---------------A--- ---AAA-----------AAA--- -----AABAAABAAABAA----- -------AAAAAAAAA------- ----------------------- ----------------------- 
----------------------- ----------------------- ----------------------- ----------------------- ----------------------- ----------------------- ----------------------- AA--------------------- AG-------------------AA AD-------------------DA AG-------------------GA AD-------------------DA AG-------------------GA AD-------------------DA AG--C-------------C--DA AD-------------------DA AG-------------------GA AD-------------------DA AAB-----------------BAA -AB-----------------BA- -A-------------------A- -A-------------------A- --A-----------------A-- --A-----------------A-- ---A---------------A--- ---AAA-----------AAA--- -----AAAB-----BAAA----- -------AAAABAAAA------- ----------AAA---------- ----------------------- 
----------------------- ----------------------- ----------------------- ----------------------- ----------------------- ----------------------- ----------------------- AA-------------------AA AD-------------------DA AD-------------------DA AD-------------------DA AG-------------------GA AD-------------------DA AD-------------------DA AD--C-------------C--DA AG-------------------GA AD-------------------DA AD-------------------DA AAB-----------------BAA AAB-----------------BAA AA-------------------AA -A-------------------A- -AA-----------------AA- --A-----------------A-- --AA---------------AA-- ---AAA-----------AAA--- ----AAAA-------AAAA---- ------AAABABABAAA------ ---------AAAAA--------- ----------------------- 
----------------------- ----------------------- ----------------------- ----------------------- ----------------------- ----------------------- A---------------------A AA-------------------AA AG-------------------GA AD-------------------DA AG-------------------GA AD-------------------DA AG-------------------GA AD-------------------DA AG--C-------------C--GA AD-------------------DA AG-------------------DA AD-------------------DA AB-------------------BA AB-------------------BA AA-------------------AA AA-------------------AA -AA-----------------AA- -AA-----------------AA- --AA---------------AA-- --AAAA-----------AAAA-- ----AAAA-------AAAA---- ------AAAABBBAAAA------ --------AAAAAAA-------- ----------EEE---------- 
E---------------------E E---------------------E E---------------------E E---------------------E E---------------------E E---------------------E E---------------------E EA-------------------AE AD-------------------DA AG-------------------GA AD-------------------DA AD-------------------DA AD-------------------DA AG-------------------GA AD--C-------------C--DA AD-------------------DA AD-------------------DA AG-------------------GA AB-------------------BA AB-------------------BA AB-------------------BA AB-------------------BA -AB-----------------BA- -AB-----------------BA- --AB---------------BA-- --AABB-----------BBAA-- ----AABB-------BBAA---- ------AABBBBBBBAA------ --------AAAEAAA-------- ----------EEE---------- 
E---------------------E E---------------------E E---------------------E E---------------------E E---------------------E E---------------------E E---------------------E EA-------------------AE AG-------------------GA AD-------------------DA AG-------------------GA AD-------------------DA AG-------------------GA AD-------------------DA AG--C-------------C--GA AD-------------------DA AG-------------------GA AD-------------------DA AB-------------------BA AB-------------------BA AA-------------------AA AA-------------------AA -AA-----------------AA- -AA-----------------AA- --AA---------------AA-- --AAAA-----------AAAA-- ----AAAA-------AAAA---- ------AAAABBBAAAA------ --------AAAAAAA-------- ----------EEE---------- 
----------------------- ----------------------- ----------------------- ----------------------- ----------------------- ----------------------- A---------------------A AA-------------------AA AD-------------------DA AD-------------------DA AD-------------------DA AG-------------------GA AD--C-------------C--DA AD--C-------------C--DA AD--C-------------C--DA AG-------------------GA AD-------------------DA AD-------------------DA AB-------------------BA AB-------------------BA AA-------------------AA AA-------------------AA -AA-----------------AA- -AA-----------------AA- --AA---------------AA-- --AAAA-----------AAAA-- ----AAAAAB---BAAAAA---- ------AAABABABAAA------ ---------AAAAA--------- ----------------------- 
----------------------- ----------------------- ----------------------- ----------------------- ----------------------- ----------------------- ----------------------- AA-------------------AA AG-------------------GA AD-------------------DA AG-------------------GA AD-------------------DA AG-------------------GA AD-------------------DA AG-------------------GA AD-------------------DA AG-------------------GA AD-------------------DA AB-------------------BA AB-------------------BA AA-------------------AA -A-------------------A- -AA-----------------AA- --A-----------------A-- --AA---------------AA-- ---AAA-----------AAA--- -----AAABA---ABAAA----- -------AAAABAAAA------- ----------AAA---------- ----------------------- 
----------------------- ----------------------- ----------------------- ----------------------- ----------------------- ----------------------- ----------------------- ----------------------- AA-------------------AA AG-------------------GA AD-------------------DA AD-------------------DA AD-------------------DA AG-------------------GA AD-------------------DA AD-------------------DA AD-------------------DA AG-------------------GA AAB-----------------BAA AAB-----------------BAA -A-------------------A- -A-------------------A- --A-----------------A-- --A-----------------A-- ---A---------------A--- ---AAAAB-------BAAAA--- -----AAAAAABAAABAA----- -------AAAAAAAAA------- ----------------------- ----------------------- 
----------------------- ----------------------- ----------------------- ----------------------- ----------------------- ----------------------- ----------------------- ----------------------- -A-------------------A- -AD-----------------DA- -AG-----------------GA- -AD-----------------DA- -AG-----------------GA- -AD-----------------DA- -AG-----------------GA- -AD-----------------DA- -AG-----------------GA- -AD-----------------DA- -AB-----------------BA- -AB-----------------BA- -A-------------------A- -A-------------------A- --A-----------------A-- --A-----------------A-- ---AAAB---------BAAA--- ---AAABA-------ABAAA--- -----AAAAAABAAAAAA----- -------AAAAAAAAA------- ----------------------- ----------------------- 
----------------------- ----------------------- ----------------------- ----------------------- ----------------------- ----------------------- ----------------------- ----------------------- --A-----------------AA- -AG-----------------DA- -AD-----------------DA- -AG-----------------GA- -AD-----------------DA- -AD-----------------DA- -AD-----------------DA- -AG-----------------GA- -AD-----------------DA- -AD-----------------DA- -AAB---------------BAA- -AAB---------------BAA- -AA-----------------AA- --A-----------------A-- --A-----------------A-- ---AAB-----------BAA--- ---AABA---------ABAA--- ----AAAA-------AAAA---- ------AAAAABAAAAA------ ---------AAAAA--------- ----------------------- ----------------------- 
----------------------- ----------------------- ----------------------- ----------------------- ----------------------- ----------------------- ----------------------- ----------------------- --A-----------------A-- --A-----------------A-- --A-----------------A-- --AD----------------A-- --AG---------------GA-- --AD---------------DA-- --AG---------------GA-- --AD---------------DA-- --AG---------------GA-- --AD---------------DA-- --ABB-------------BBA-- --ABB-------------BBA-- --AAB-------------BAA-- --AAB-------------BAA-- ---AB-------------BA--- ---ABA-----------ABA--- ----AAA---------AAA---- -----AAAAAABAAAAAA----- -------AAAAAAAAA------- ----------------------- ----------------------- ----------------------- 
----------------------- ----------------------- ----------------------- ----------------------- ----------------------- ----------------------- ----------------------- ----------------------- ----------------------- --A-----------------A-- --AA---------------AA-- --AG---------------AA-- --AD---------------DA-- --AG---------------GA-- --AD---------------DA-- --AD---------------DA-- --AD---------------DA-- --AG---------------GA-- --AAB-------------BAA-- --AAB-------------BAA-- --AAA-------------AAA-- ---AA-------------AA--- ----A-------------A---- ----AA-----------AA---- -----AA---------AA----- -------AAAABAAAA------- ---------AAAAA--------- ----------------------- ----------------------- ----------------------- 
----------------------- ----------------------- ----------------------- ----------------------- ----------------------- ----------------------- ----------------------- ----------------------- ----------------------- ----------------------- ---AA-------------AA--- ---AA-------------AA--- ---AG-------------AA--- ---AD-------------DA--- ---AG-------------GA--- ---ADG-----------GDA--- ---AGD-----------DGA--- ---ADD-----------DDA--- ---AABB---------BBAA--- ---AABB---------BBAA--- ---AAA-----------AAA--- ----AA-----------AA---- -----A-----------A----- -----A-----------A----- ------AAAAABAAAAA------ ---------AAAAA--------- ----------------------- ----------------------- ----------------------- ----------------------- 
----------------------- ----------------------- ----------------------- ----------------------- ----------------------- ----------------------- ----------------------- ----------------------- ----------------------- ----------------------- ----------------------- ----A-------------A---- ----AA-----------AA---- ----AAA---------AAA---- ----AAAAAAAAAAAAAAA---- ----AADDDGDDDGDDDAA---- ----AAGDGDGDGDGDGAA---- ----AADGDDDGDDDGDAA---- ----AAABBBBBBBBBAAA---- ----AAABBBBBBBBBAAA---- ----AAAAAAABAAAAAAA---- -----AAAAAABAAAAAA----- ------AAAAABAAAAA------ ------AAAAABAAAAA------ ---------AAAAA--------- ----------------------- ----------------------- ----------------------- ----------------------- ----------------------- 
----------------------- ----------------------- ----------------------- ----------------------- ----------------------- ----------------------- ----------------------- ----------------------- ----------------------- ----------------------- ----------------------- ----------------------- ----------------------- ----------------------- -------AAAAAAAAA------- ------AAAAAAAAAAA------ ------AAAAAAAAAAA------ ------AAAAAAAAAAA------ ------AAAAAAAAAAA------ ------AAAAAAAAAAA------ ------AAAAAAAAAAA------ -------AAAAAAAAA------- --------AAAAAAA-------- ---------AAAAA--------- ----------------------- ----------------------- ----------------------- ----------------------- ----------------------- ----------------------- 
