model
size = 28 30 30, scale = 0.05, origin = -y
material 
  colors = A:#563F2E B:#FB9966 C:#E83015 D:#FFF E:#EDEDED F:#7DB9DE G:#222 H:#EEE I:#555 J:#DDD
voxels
---------------------------- ---------------------------- ---------------------------- ---------------------------- ---------------------------- ---------------------------- ---------------------------- ---------------------------- ---------------------------- -------------BB------------- ------------BBBB------------ ------------BBBB------------ -------------BB------------- ---------------------------- ---------------------------- ---------------------------- ---------------------------- ---------------------------- ---------------------------- ---------------------------- ---------------------------- ---------------------------- ---------------------------- ---------------------------- ---------------------------- ---------------------------- ---------------------------- ---------------------------- ---------------------------- ---------------------------- 
---------------------------- ---------------------------- ---------------------------- ---------------------------- ---------------------------- ---------------------------- ---------------------------- ---------------------------- -------------BB------------- ------------BBBB------------ -----------BBBBBB----------- -----------BBBBBB----------- ------------BBBB------------ ------------BBBB------------ -------------BB------------- ---------------------------- ---------------------------- ---------------------------- ---------------------------- ---------------------------- ---------------------------- ---------------------------- ---------------------------- ---------------------------- ---------------------------- ---------------------------- ---------------------------- ---------------------------- ---------------------------- ---------------------------- 
---------------------------- ---------------------------- ---------------------------- ---------------------------- ---------------------------- ---------------------------- ---------------------------- -------------BB------------- ------------BBBB------------ -----------BBBBBB----------- ----------BBBBBBBB---------- ----------BBBBBBBB---------- -----------BBBBBB----------- -----------BBBBBB----------- ------------BBBB------------ -------------BB------------- -------------BB------------- ---------------------------- ---------------------------- ---------------------------- ---------------------------- ---------------------------- ---------------------------- ---------------------------- ---------------------------- ---------------------------- ---------------------------- ---------------------------- ---------------------------- ---------------------------- 
---------------------------- ---------------------------- ---------------------------- ---------------------------- -------AAAAAAAAAAAAAA------- ----------AAAAAAAA---------- ------------AAAA------------ -------------BB------------- ------------BBBB------------ -----------BBBBBB----------- ----------BBBBBBBB---------- ----------BBBBBBBB---------- ----------BBBBBBBB---------- -----------BBBBBB----------- ------------BBBB------------ -------------BB------------- -------------BB------------- -------------BB------------- -------------BB------------- -------------BB------------- ---------------------------- ---------------------------- ---------------------------- ---------------------------- ---------------------------- ---------------------------- ---------------------------- ---------------------------- ---------------------------- ---------------------------- 
---------------------------- ---------------------------- ---------------------------- ------AAAAAAAAAAAAAAAA------ -----AAAAAAAAAAAAAAAAAA----- ------AAAAAAAAAAAAAAAA------ --------AAAAAAAAAAAA-------- -------------BB------------- ------------BBBB------------ -----------BBBBBB----------- ----------BBBBBBBB---------- ----------BBBBBBBB---------- ----------BBBBBBBB---------- -----------BBBBBB----------- -----------BBBBBB----------- -----------BBBBBB----------- ------------BBBB------------ ------------BBBB------------ ------------BBBB------------ -------------BB------------- -------------BB------------- -------------BB------------- -------------BB------------- ---------------------------- ---------------------------- ---------------------------- ---------------------------- ---------------------------- ---------------------------- ---------------------------- 
---------------------------- ---------------------------- -----A-A-A-A-AA-A-A-A-A----- -----AAAAAAAAAAAAAAAAAA----- ----AAAAAAAAAAAAAAAAAAAA---- -----AAAAAAAAAAAAAAAAAA----- ------AAAAAAAAAAAAAAAA------ --------AAA--BB-AAAA-------- ------------BBBBB----------- -----------BBBBBBB---------- ---------BBBBBBBBBB--------- ---------BBBBBBBBBB--------- ---------BBBBBBBBBB--------- ----------BBBBBBBB---------- -----------BBBBBB----------- -----------BBBBBB----------- ------------BBBB------------ ------------BBBB------------ ------------BBBB------------ ------------BBBB------------ ------------BBBB------------ ------------BBBB------------ ------------BBBB------------ -------------BB------------- ---------------------------- ---------------------------- ---------------------------- ---------------------------- ---AAAAAA----------AAAAAA--- ---------------------------- 
---------------------------- ---------------------------- -----A-A-A-A-AA-A-A-A-A----- ----AAAAAAAAAAAAAAAAAAAA---- ---AAAAAAAAAAAAAAAAAAAAAA--- ----AAAAAAAAAAAAAAAAAAAA---- -----AAAAAAAAAAAAAAAAAA----- ------AAAAAABBBBAAAAAA------ -----------BBBBBB----------- ----------BBBBBBBB---------- ---------BBBBBBBBBB--------- ---------BBBBBBBBBB--------- ---------BBBBBBBBBB--------- ----------BBBBBBBB---------- -----------BBBBBBB---------- -----------BBBBBB----------- --CCCCCCCC--BBBB--CCCCCCCC-- --CCCCCCCC--BBBB--CCCCCCCC-- CC--------CCBBBBCC--------CC CC--------CCBBBBCC--------CC CC--------CCBBBBCC--------CC CC--------CCBBBBCC--------CC CC--------CCBBBBCC--------CC CC--------CCBBBBCC--------CC --CCCCCCCCCCCBBCCCCCCCCCCC-- --CCCCCCCC-CCCCCC-CCCCCCCC-- ------------CCCC------------ ---AAAAAA----------AAAAAA--- --AAAAAAAA--------AAAAAAAA-- ---AAAAAA----------AAAAAA--- 
---------------------------- ---------------------------- ----AA-A-A-A-AA-A-A-A-AA---- --AAAAAAAAAAAAAAAAAAAAAAAA-- --AAAAAAAAAAAAAAAAAAAAAAAA-- ---AAAAAAAAAAAAAAAAAAAAAA--- ----AAAAAAAAAAAAAAAAAAAA---- -----AAAAAAABBBBAAAAAAA----- -------AAAABBBBBBAAAA------- ----------BBBBBBBB---------- ---------BBBBBBBBBB--------- ---------BBBBBBBBBB--------- ---------BBBBBBBBBB--------- ----------BBBBBBBB---------- ----------BBBBBBBB---------- -----------BBBBBB----------- --CCCCCCCC-BBBBBB-CCCCCCCC-- --CCCCCCCC--BBBB--CCCCCCCC-- CCDDDDDDDECCBBBBCCDDDDDDDECC CCDDHFFHDEAABBBBCCDDHFFHDECC CCDDFIIFDEAABBBBCCDDFIIFDECC CCDDFIJFDEAABBBBCCDDFIJFDECC CCDDHFFHDEAABBBBCCDDHFFHDECC CCEEEEEEEEAABBBBCCEEEEEEEECC --CCCCCCCCCCABBACCAAAAAAAC-- --CCCCCCCC-CAAAAC-CCCCCCCC-- ------------CCCC------------ --AAAAAAAA--------AAAAAAAA-- -AAAAAAAAAA------AAAAAAAAAA- --AAAAAAAA--------AAAAAAAA-- 
----------GGGGGGGG---------- ---------------------------- ----AA-A-A-A-AA-A-A-A-AA---- --AAAAAAAAAAAAAAAAAAAAAAAA-- --AAAAAAAAAAAAAAAAAAAAAAAA-- ---AAAAAAAAAAAAAAAAAAAAAA--- ----AAAAAAAAAAAAAAAAAAAA---- -----AAAAAAABBBBAAAAAAA----- -------AAAABBBBBBAAAA------- ----------BBBBBBBB---------- ---------BBBBBBBBBB--------- ---------BBBBBBBBBB--------- ---------BBBBBBBBBB--------- ----------BBBBBBBB---------- ----------BBBBBBBB---------- -----------BBBBBB----------- --CCCCCCCC-BBBBBB-CCCCCCCC-- --CCCCCCCC--BBBB--CCCCCCCC-- CC--------CCBBBBCC--------CC CC--------CCBBBBCC--------CC CC--------CCBBBBCC--------CC CC--------CCBBBBCC--------CC CC--------CCBBBBCC--------CC CC--------CCBBBBCC--------CC --CCCCCCCCCCCBBCCCCCCCCCCC-- --CCCCCCCC-CCCCCC-CCCCCCCC-- ------------CCCC------------ --AAAAAAAA--------AAAAAAAA-- -AAAAAAAAAA------AAAAAAAAAA- --AAAAAAAA--------AAAAAAAA-- 
---------------------------- ---------------------------- ---------------------------- ---------------------------- ---------------------------- ---------------------------- ---------------------------- ---------------------------- ---------------------------- ---------------------------- ---------------------------- ---------------------------- ---------------------------- ---------------------------- ---------------------------- ---------------------------- ---------------------------- ---------------------------- ---------------------------- ---------------------------- ---------------------------- ---------------------------- CE------------------------EC CE------------------------EC ---------------------------- ---------------------------- ---------------------------- ---------------------------- ---------------------------- ---------------------------- 
---------------------------- ---------------------------- ---------------------------- ---------------------------- ---------------------------- ---------------------------- ---------------------------- ---------------------------- ---------------------------- ---------------------------- ---------------------------- ---------------------------- ---------------------------- ---------------------------- ---------------------------- ---------------------------- ---------------------------- ---------------------------- ---------------------------- ---------------------------- ---------------------------- ---------------------------- CC------------------------CC CC------------------------CC ---------------------------- ---------------------------- ---------------------------- ---------------------------- ---------------------------- ---------------------------- 
---------------------------- ---------------------------- ---------------------------- ---------------------------- ---------------------------- ---------------------------- ---------------------------- ---------------------------- ---------------------------- ---------------------------- ---------------------------- ---------------------------- ---------------------------- ---------------------------- ---------------------------- ---------------------------- ---------------------------- ---------------------------- ---------------------------- ---------------------------- ---------------------------- ---------------------------- CC------------------------CC CC------------------------CC ---------------------------- ---------------------------- ---------------------------- ---------------------------- ---------------------------- ---------------------------- 
---------------------------- ---------------------------- ---------------------------- ---------------------------- ---------------------------- ---------------------------- ---------------------------- ---------------------------- ---------------------------- ---------------------------- ---------------------------- ---------------------------- ---------------------------- ---------------------------- ---------------------------- ---------------------------- ---------------------------- ---------------------------- ---------------------------- ---------------------------- ---------------------------- ---------------------------- CC------------------------CC CC------------------------CC ---------------------------- ---------------------------- ---------------------------- ---------------------------- ---------------------------- ---------------------------- 
---------------------------- ---------------------------- ---------------------------- ---------------------------- ---------------------------- ---------------------------- ---------------------------- ---------------------------- ---------------------------- ---------------------------- ---------------------------- ---------------------------- ---------------------------- ---------------------------- ---------------------------- ---------------------------- ---------------------------- ---------------------------- ---------------------------- ---------------------------- ---------------------------- ---------------------------- CC------------------------CC CC------------------------CC ---------------------------- ---------------------------- ---------------------------- ---------------------------- ---------------------------- ---------------------------- 
---------------------------- ---------------------------- ---------------------------- ---------------------------- ---------------------------- ---------------------------- ---------------------------- ---------------------------- ---------------------------- ---------------------------- ---------------------------- ---------------------------- ---------------------------- ---------------------------- ---------------------------- ---------------------------- ---------------------------- ---------------------------- ---------------------------- ---------------------------- ---------------------------- ---------------------------- CC------------------------CC CC------------------------CC ---------------------------- ---------------------------- ---------------------------- ---------------------------- ---------------------------- ---------------------------- 
---------------------------- ---------------------------- ---------------------------- ---------------------------- ---------------------------- ---------------------------- ---------------------------- ---------------------------- ---------------------------- ---------------------------- ---------------------------- ---------------------------- ---------------------------- ---------------------------- ---------------------------- ---------------------------- ---------------------------- ---------------------------- ---------------------------- ---------------------------- ---------------------------- ---------------------------- CC------------------------CC CC------------------------CC ---------------------------- ---------------------------- ---------------------------- ---------------------------- ---------------------------- ---------------------------- 
---------------------------- ---------------------------- ---------------------------- ---------------------------- ---------------------------- ---------------------------- ---------------------------- ---------------------------- ---------------------------- ---------------------------- ---------------------------- ---------------------------- ---------------------------- ---------------------------- ---------------------------- ---------------------------- ---------------------------- ---------------------------- ---------------------------- ---------------------------- ---------------------------- ---------------------------- CC------------------------CC CC------------------------CC ---------------------------- ---------------------------- ---------------------------- ---------------------------- ---------------------------- ---------------------------- 
---------------------------- ---------------------------- ---------------------------- ---------------------------- ---------------------------- ---------------------------- ---------------------------- ---------------------------- ---------------------------- ---------------------------- ---------------------------- ---------------------------- ---------------------------- ---------------------------- ---------------------------- ---------------------------- ---------------------------- ---------------------------- ---------------------------- ---------------------------- ---------------------------- ---------------------------- CC------------------------CC CC------------------------CC ---------------------------- ---------------------------- ---------------------------- ---------------------------- ---------------------------- ---------------------------- 
---------------------------- ---------------------------- ---------------------------- ---------------------------- ---------------------------- ---------------------------- ---------------------------- ---------------------------- ---------------------------- ---------------------------- ---------------------------- ---------------------------- ---------------------------- ---------------------------- ---------------------------- ---------------------------- ---------------------------- ---------------------------- ---------------------------- ---------------------------- ---------------------------- ---------------------------- CC------------------------CC CC------------------------CC ---------------------------- ---------------------------- ---------------------------- ---------------------------- ---------------------------- ---------------------------- 
---------------------------- ---------------------------- ---------------------------- ---------------------------- ---------------------------- ---------------------------- ---------------------------- ---------------------------- ---------------------------- ---------------------------- ---------------------------- ---------------------------- ---------------------------- ---------------------------- ---------------------------- ---------------------------- ---------------------------- ---------------------------- ---------------------------- ---------------------------- ---------------------------- ---------------------------- CC------------------------CC CC------------------------CC ---------------------------- ---------------------------- ---------------------------- ---------------------------- ---------------------------- ---------------------------- 
---------------------------- ---------------------------- ---------------------------- ---------------------------- ---------------------------- ---------------------------- ---------------------------- ---------------------------- ---------------------------- ---------------------------- ---------------------------- ---------------------------- ---------------------------- ---------------------------- ---------------------------- ---------------------------- ---------------------------- ---------------------------- ---------------------------- ---------------------------- ---------------------------- ---------------------------- CC------------------------CC CC------------------------CC ---------------------------- ---------------------------- ---------------------------- ---------------------------- ---------------------------- ---------------------------- 
---------------------------- ---------------------------- ---------------------------- ---------------------------- ---------------------------- ---------------------------- ---------------------------- ---------------------------- ---------------------------- ---------------------------- ---------------------------- ---------------------------- ---------------------------- ---------------------------- ---------------------------- ---------------------------- ---------------------------- ---------------------------- ---------------------------- ---------------------------- ---------------------------- ---------------------------- CC------------------------CC CC------------------------CC ---------------------------- ---------------------------- ---------------------------- ---------------------------- ---------------------------- ---------------------------- 
---------------------------- ---------------------------- ---------------------------- ---------------------------- ---------------------------- ---------------------------- ---------------------------- ---------------------------- ---------------------------- ---------------------------- ---------------------------- ---------------------------- ---------------------------- ---------------------------- ---------------------------- ---------------------------- ---------------------------- ---------------------------- ---------------------------- ---------------------------- ---------------------------- ---------------------------- CC------------------------CC CC------------------------CC ---------------------------- ---------------------------- ---------------------------- ---------------------------- ---------------------------- ---------------------------- 
---------------------------- ---------------------------- ---------------------------- ---------------------------- ---------------------------- ---------------------------- ---------------------------- ---------------------------- ---------------------------- ---------------------------- ---------------------------- ---------------------------- ---------------------------- ---------------------------- ---------------------------- ---------------------------- ---------------------------- ---------------------------- ---------------------------- ---------------------------- ---------------------------- ---------------------------- CC------------------------CC CC------------------------CC ---------------------------- ---------------------------- ---------------------------- ---------------------------- ---------------------------- ---------------------------- 
---------------------------- ---------------------------- ---------------------------- ---------------------------- ---------------------------- ---------------------------- ---------------------------- ---------------------------- ---------------------------- ---------------------------- ---------------------------- ---------------------------- ---------------------------- ---------------------------- ---------------------------- ---------------------------- ---------------------------- ---------------------------- ---------------------------- ---------------------------- ---------------------------- ---------------------------- CC------------------------CC CC------------------------CC ---------------------------- ---------------------------- ---------------------------- ---------------------------- ---------------------------- ---------------------------- 
---------------------------- ---------------------------- ---------------------------- ---------------------------- ---------------------------- ---------------------------- ---------------------------- ---------------------------- ---------------------------- ---------------------------- ---------------------------- ---------------------------- ---------------------------- ---------------------------- ---------------------------- ---------------------------- ---------------------------- ---------------------------- ---------------------------- ---------------------------- ---------------------------- ---------------------------- CC------------------------CC CC------------------------CC ---------------------------- ---------------------------- ---------------------------- ---------------------------- ---------------------------- ---------------------------- 
---------------------------- ---------------------------- ---------------------------- ---------------------------- ---------------------------- ---------------------------- ---------------------------- ---------------------------- ---------------------------- ---------------------------- ---------------------------- ---------------------------- ---------------------------- ---------------------------- ---------------------------- ---------------------------- ---------------------------- ---------------------------- ---------------------------- ---------------------------- ---------------------------- ---------------------------- CC------------------------CC CC------------------------CC ---------------------------- ---------------------------- ---------------------------- ---------------------------- ---------------------------- ---------------------------- 
---------------------------- ---------------------------- ---------------------------- ---------------------------- ---------------------------- ---------------------------- ---------------------------- ---------------------------- ---------------------------- ---------------------------- ---------------------------- ---------------------------- ---------------------------- ---------------------------- ---------------------------- ---------------------------- ---------------------------- ---------------------------- ---------------------------- ---------------------------- ---------------------------- CC------------------------CC CC------------------------CC CC------------------------CC ---------------------------- ---------------------------- ---------------------------- ---------------------------- ---------------------------- ---------------------------- 
---------------------------- ---------------------------- ---------------------------- ---------------------------- ---------------------------- ---------------------------- ---------------------------- ---------------------------- ---------------------------- ---------------------------- ---------------------------- ---------------------------- ---------------------------- ---------------------------- ---------------------------- ---------------------------- ---------------------------- ---------------------------- CC------------------------CC CC------------------------CC CC------------------------CC CC------------------------CC CC------------------------CC ---------------------------- ---------------------------- ---------------------------- ---------------------------- ---------------------------- ---------------------------- ---------------------------- 
---------------------------- ---------------------------- ---------------------------- ---------------------------- ---------------------------- ---------------------------- ---------------------------- ---------------------------- ---------------------------- ---------------------------- ---------------------------- ---------------------------- ---------------------------- ---------------------------- ---------------------------- ---------------------------- ---------------------------- CC------------------------CC CC------------------------CC CC------------------------CC CC------------------------CC ---------------------------- ---------------------------- ---------------------------- ---------------------------- ---------------------------- ---------------------------- ---------------------------- ---------------------------- ---------------------------- 
