model
size = 28 30 30, scale = 0.05, origin = -y
material 
  colors = A:#222 B:#FB9966 C:#FFF D:#BBB E:#7DB9DE F:#EEE G:#555 H:#777 I:#DDD
voxels
---------------------------- ---------------------------- ---------------------------- ---------------------------- ---------------------------- ---------------------------- ---------------------------- ---------------------------- ---------------------------- -------------BB------------- ------------BBBB------------ ------------BBBB------------ -------------BB------------- ---------------------------- ---------------------------- ---------------------------- ---------------------------- ---------------------------- ---------------------------- ---------------------------- ---------------------------- ---------------------------- ---------------------------- ---------------------------- ---------------------------- ---------------------------- ---------------------------- ---------------------------- ---------------------------- ---------------------------- 
---------------------------- ---------------------------- ---------------------------- ---------------------------- ---------------------------- ---------------------------- ---------------------------- ---------------------------- -------------BB------------- ------------BBBB------------ -----------BBBBBB----------- -----------BBBBBB----------- ------------BBBB------------ ------------BBBB------------ -------------BB------------- ---------------------------- ---------------------------- ---------------------------- ---------------------------- ---------------------------- ---------------------------- ---------------------------- ---------------------------- ---------------------------- ---------------------------- ---------------------------- ---------------------------- ---------------------------- ---------------------------- ---------------------------- 
---------------------------- ---------------------------- ---------------------------- ---------------------------- ---------------------------- ---------------------------- ---------------------------- -------------BB------------- ------------BBBB------------ -----------BBBBBB----------- ----------BBBBBBBB---------- ----------BBBBBBBB---------- -----------BBBBBB----------- -----------BBBBBB----------- ------------BBBB------------ -------------BB------------- -------------BB------------- ---------------------------- ---------------------------- ---------------------------- ---------------------------- ---------------------------- ---------------------------- ---------------------------- ---------------------------- ---------------------------- ---------------------------- ---------------------------- ---------------------------- ---------------------------- 
---------------------------- ---------------------------- ---------------------------- ---------------------------- -------AAAAAAAAAAAAAA------- ----------AAAAAAAA---------- ------------AAAA------------ -------------BB------------- ------------BBBB------------ -----------BBBBBB----------- ----------BBBBBBBB---------- ----------BBBBBBBB---------- ----------BBBBBBBB---------- -----------BBBBBB----------- ------------BBBB------------ -------------BB------------- -------------BB------------- -------------BB------------- -------------BB------------- -------------BB------------- ---------------------------- ---------------------------- ---------------------------- ---------------------------- ---------------------------- ---------------------------- ---------------------------- ---------------------------- ---------------------------- ---------------------------- 
---------------------------- ---------------------------- ---------------------------- ------AAAAAAAAAAAAAAAA------ -----AAAAAAAAAAAAAAAAAA----- ------AAAAAAAAAAAAAAAA------ --------AAAAAAAAAAAA-------- -------------BB------------- ------------BBBB------------ -----------BBBBBB----------- ----------BBBBBBBB---------- ----------BBBBBBBB---------- ----------BBBBBBBB---------- -----------BBBBBB----------- -----------BBBBBB----------- -----------BBBBBB----------- ------------BBBB------------ ------------BBBB------------ ------------BBBB------------ -------------BB------------- -------------BB------------- -------------BB------------- -------------BB------------- ---------------------------- ---------------------------- ---------------------------- ---------------------------- ---------------------------- ---------------------------- ---------------------------- 
---------------------------- ---------------------------- -----A-A-A-A-AA-A-A-A-A----- -----AAAAAAAAAAAAAAAAAA----- ----AAAAAAAAAAAAAAAAAAAA---- -----AAAAAAAAAAAAAAAAAA----- ------AAAAAAAAAAAAAAAA------ --------AAA--BB-AAAA-------- ------------BBBBB----------- -----------BBBBBBB---------- ---------BBBBBBBBBB--------- ---------BBBBBBBBBB--------- ---------BBBBBBBBBB--------- ----------BBBBBBBB---------- -----------BBBBBB----------- -----------BBBBBB----------- ------------BBBB------------ ------------BBBB------------ ------------BBBB------------ ------------BBBB------------ ------------BBBB------------ ------------BBBB------------ ------------BBBB------------ -------------BB------------- ---------------------------- ---------------------------- ---------------------------- ---------------------------- ---AAAAAA----------AAAAAA--- ---------------------------- 
---------------------------- ---------------------------- -----A-A-A-A-AA-A-A-A-A----- ----AAAAAAAAAAAAAAAAAAAA---- ---AAAAAAAAAAAAAAAAAAAAAA--- ----AAAAAAAAAAAAAAAAAAAA---- -----AAAAAAAAAAAAAAAAAA----- ------AAAAAABBBBAAAAAA------ -----------BBBBBB----------- ----------BBBBBBBB---------- ---------BBBBBBBBBB--------- ---------BBBBBBBBBB--------- ---------BBBBBBBBBB--------- ----------BBBBBBBB---------- -----------BBBBBBB---------- -----------BBBBBB----------- --AAAAAAAA--BBBB--AAAAAAAA-- --AAAAAAAA--BBBB--AAAAAAAA-- AA--------AABBBBAA--------AA AA--------AABBBBAA--------AA AA--------AABBBBAA--------AA AA--------AABBBBAA--------AA AA--------AABBBBAA--------AA AA--------AABBBBAA--------AA --AAAAAAAAAAABBAAAAAAAAAAA-- --AAAAAAAA-AAAAAA-AAAAAAAA-- ------------AAAA------------ ---AAAAAA----------AAAAAA--- --AAAAAAAA--------AAAAAAAA-- ---AAAAAA----------AAAAAA--- 
---------------------------- ---------------------------- ----AA-A-A-A-AA-A-A-A-AA---- --AAAAAAAAAAAAAAAAAAAAAAAA-- --AAAAAAAAAAAAAAAAAAAAAAAA-- ---AAAAAAAAAAAAAAAAAAAAAA--- ----AAAAAAAAAAAAAAAAAAAA---- -----AAAAAAABBBBAAAAAAA----- -------AAAABBBBBBAAAA------- ----------BBBBBBBB---------- ---------BBBBBBBBBB--------- ---------BBBBBBBBBB--------- ---------BBBBBBBBBB--------- ----------BBBBBBBB---------- ----------BBBBBBBB---------- -----------BBBBBB----------- --AAAAAAAA-BBBBBB-AAAAAAAA-- --AAAAAAAA--BBBB--AAAAAAAA-- AACCCCCCCDAABBBBAACCCCCCCDAA AACCFEEFCDAABBBBAACCFEEFCDAA AACCEGGECDAABBBBAACCEGGECDAA AACCEGIECDAABBBBAACCEGIECDAA AACCFEEFCDAABBBBAACCFEEFCDAA AADDDDDDDDAABBBBAADDDDDDDDAA --AAAAAAAAAAABBAAAAAAAAAAA-- --AAAAAAAA-AAAAAA-AAAAAAAA-- ------------AAAA------------ --AAAAAAAA--------AAAAAAAA-- -AAAAAAAAAA------AAAAAAAAAA- --AAAAAAAA--------AAAAAAAA-- 
----------AAAAAAAA---------- ---------------------------- ----AA-A-A-A-AA-A-A-A-AA---- --AAAAAAAAAAAAAAAAAAAAAAAA-- --AAAAAAAAAAAAAAAAAAAAAAAA-- ---AAAAAAAAAAAAAAAAAAAAAA--- ----AAAAAAAAAAAAAAAAAAAA---- -----AAAAAAABBBBAAAAAAA----- -------AAAABBBBBBAAAA------- ----------BBBBBBBB---------- ---------BBBBBBBBBB--------- ---------BBBBBBBBBB--------- ---------BBBBBBBBBB--------- ----------BBBBBBBB---------- ----------BBBBBBBB---------- -----------BBBBBB----------- --AAAAAAAA-BBBBBB-AAAAAAAA-- --AAAAAAAA--BBBB--AAAAAAAA-- AA--------AABBBBAA--------AA AA--------AABBBBAA--------AA AA--------AABBBBAA--------AA AA--------AABBBBAA--------AA AA--------AABBBBAA--------AA AA--------AABBBBAA--------AA --AAAAAAAAAAABBAAAAAAAAAAA-- --AAAAAAAA-AAAAAA-AAAAAAAA-- ------------AAAA------------ --AAAAAAAA--------AAAAAAAA-- -AAAAAAAAAA------AAAAAAAAAA- --AAAAAAAA--------AAAAAAAA-- 
---------------------------- ---------------------------- ---------------------------- ---------------------------- ---------------------------- ---------------------------- ---------------------------- ---------------------------- ---------------------------- ---------------------------- ---------------------------- ---------------------------- ---------------------------- ---------------------------- ---------------------------- ---------------------------- ---------------------------- ---------------------------- ---------------------------- ---------------------------- ---------------------------- ---------------------------- AH------------------------HA AH------------------------HA ---------------------------- ---------------------------- ---------------------------- ---------------------------- ---------------------------- ---------------------------- 
---------------------------- ---------------------------- ---------------------------- ---------------------------- ---------------------------- ---------------------------- ---------------------------- ---------------------------- ---------------------------- ---------------------------- ---------------------------- ---------------------------- ---------------------------- ---------------------------- ---------------------------- ---------------------------- ---------------------------- ---------------------------- ---------------------------- ---------------------------- ---------------------------- ---------------------------- AA------------------------AA AA------------------------AA ---------------------------- ---------------------------- ---------------------------- ---------------------------- ---------------------------- ---------------------------- 
---------------------------- ---------------------------- ---------------------------- ---------------------------- ---------------------------- ---------------------------- ---------------------------- ---------------------------- ---------------------------- ---------------------------- ---------------------------- ---------------------------- ---------------------------- ---------------------------- ---------------------------- ---------------------------- ---------------------------- ---------------------------- ---------------------------- ---------------------------- ---------------------------- ---------------------------- AA------------------------AA AA------------------------AA ---------------------------- ---------------------------- ---------------------------- ---------------------------- ---------------------------- ---------------------------- 
---------------------------- ---------------------------- ---------------------------- ---------------------------- ---------------------------- ---------------------------- ---------------------------- ---------------------------- ---------------------------- ---------------------------- ---------------------------- ---------------------------- ---------------------------- ---------------------------- ---------------------------- ---------------------------- ---------------------------- ---------------------------- ---------------------------- ---------------------------- ---------------------------- ---------------------------- AA------------------------AA AA------------------------AA ---------------------------- ---------------------------- ---------------------------- ---------------------------- ---------------------------- ---------------------------- 
---------------------------- ---------------------------- ---------------------------- ---------------------------- ---------------------------- ---------------------------- ---------------------------- ---------------------------- ---------------------------- ---------------------------- ---------------------------- ---------------------------- ---------------------------- ---------------------------- ---------------------------- ---------------------------- ---------------------------- ---------------------------- ---------------------------- ---------------------------- ---------------------------- ---------------------------- AA------------------------AA AA------------------------AA ---------------------------- ---------------------------- ---------------------------- ---------------------------- ---------------------------- ---------------------------- 
---------------------------- ---------------------------- ---------------------------- ---------------------------- ---------------------------- ---------------------------- ---------------------------- ---------------------------- ---------------------------- ---------------------------- ---------------------------- ---------------------------- ---------------------------- ---------------------------- ---------------------------- ---------------------------- ---------------------------- ---------------------------- ---------------------------- ---------------------------- ---------------------------- ---------------------------- AA------------------------AA AA------------------------AA ---------------------------- ---------------------------- ---------------------------- ---------------------------- ---------------------------- ---------------------------- 
---------------------------- ---------------------------- ---------------------------- ---------------------------- ---------------------------- ---------------------------- ---------------------------- ---------------------------- ---------------------------- ---------------------------- ---------------------------- ---------------------------- ---------------------------- ---------------------------- ---------------------------- ---------------------------- ---------------------------- ---------------------------- ---------------------------- ---------------------------- ---------------------------- ---------------------------- AA------------------------AA AA------------------------AA ---------------------------- ---------------------------- ---------------------------- ---------------------------- ---------------------------- ---------------------------- 
---------------------------- ---------------------------- ---------------------------- ---------------------------- ---------------------------- ---------------------------- ---------------------------- ---------------------------- ---------------------------- ---------------------------- ---------------------------- ---------------------------- ---------------------------- ---------------------------- ---------------------------- ---------------------------- ---------------------------- ---------------------------- ---------------------------- ---------------------------- ---------------------------- ---------------------------- AA------------------------AA AA------------------------AA ---------------------------- ---------------------------- ---------------------------- ---------------------------- ---------------------------- ---------------------------- 
---------------------------- ---------------------------- ---------------------------- ---------------------------- ---------------------------- ---------------------------- ---------------------------- ---------------------------- ---------------------------- ---------------------------- ---------------------------- ---------------------------- ---------------------------- ---------------------------- ---------------------------- ---------------------------- ---------------------------- ---------------------------- ---------------------------- ---------------------------- ---------------------------- ---------------------------- AA------------------------AA AA------------------------AA ---------------------------- ---------------------------- ---------------------------- ---------------------------- ---------------------------- ---------------------------- 
---------------------------- ---------------------------- ---------------------------- ---------------------------- ---------------------------- ---------------------------- ---------------------------- ---------------------------- ---------------------------- ---------------------------- ---------------------------- ---------------------------- ---------------------------- ---------------------------- ---------------------------- ---------------------------- ---------------------------- ---------------------------- ---------------------------- ---------------------------- ---------------------------- ---------------------------- AA------------------------AA AA------------------------AA ---------------------------- ---------------------------- ---------------------------- ---------------------------- ---------------------------- ---------------------------- 
---------------------------- ---------------------------- ---------------------------- ---------------------------- ---------------------------- ---------------------------- ---------------------------- ---------------------------- ---------------------------- ---------------------------- ---------------------------- ---------------------------- ---------------------------- ---------------------------- ---------------------------- ---------------------------- ---------------------------- ---------------------------- ---------------------------- ---------------------------- ---------------------------- ---------------------------- AA------------------------AA AA------------------------AA ---------------------------- ---------------------------- ---------------------------- ---------------------------- ---------------------------- ---------------------------- 
---------------------------- ---------------------------- ---------------------------- ---------------------------- ---------------------------- ---------------------------- ---------------------------- ---------------------------- ---------------------------- ---------------------------- ---------------------------- ---------------------------- ---------------------------- ---------------------------- ---------------------------- ---------------------------- ---------------------------- ---------------------------- ---------------------------- ---------------------------- ---------------------------- ---------------------------- AA------------------------AA AA------------------------AA ---------------------------- ---------------------------- ---------------------------- ---------------------------- ---------------------------- ---------------------------- 
---------------------------- ---------------------------- ---------------------------- ---------------------------- ---------------------------- ---------------------------- ---------------------------- ---------------------------- ---------------------------- ---------------------------- ---------------------------- ---------------------------- ---------------------------- ---------------------------- ---------------------------- ---------------------------- ---------------------------- ---------------------------- ---------------------------- ---------------------------- ---------------------------- ---------------------------- AA------------------------AA AA------------------------AA ---------------------------- ---------------------------- ---------------------------- ---------------------------- ---------------------------- ---------------------------- 
---------------------------- ---------------------------- ---------------------------- ---------------------------- ---------------------------- ---------------------------- ---------------------------- ---------------------------- ---------------------------- ---------------------------- ---------------------------- ---------------------------- ---------------------------- ---------------------------- ---------------------------- ---------------------------- ---------------------------- ---------------------------- ---------------------------- ---------------------------- ---------------------------- ---------------------------- AA------------------------AA AA------------------------AA ---------------------------- ---------------------------- ---------------------------- ---------------------------- ---------------------------- ---------------------------- 
---------------------------- ---------------------------- ---------------------------- ---------------------------- ---------------------------- ---------------------------- ---------------------------- ---------------------------- ---------------------------- ---------------------------- ---------------------------- ---------------------------- ---------------------------- ---------------------------- ---------------------------- ---------------------------- ---------------------------- ---------------------------- ---------------------------- ---------------------------- ---------------------------- ---------------------------- AA------------------------AA AA------------------------AA ---------------------------- ---------------------------- ---------------------------- ---------------------------- ---------------------------- ---------------------------- 
---------------------------- ---------------------------- ---------------------------- ---------------------------- ---------------------------- ---------------------------- ---------------------------- ---------------------------- ---------------------------- ---------------------------- ---------------------------- ---------------------------- ---------------------------- ---------------------------- ---------------------------- ---------------------------- ---------------------------- ---------------------------- ---------------------------- ---------------------------- ---------------------------- ---------------------------- AA------------------------AA AA------------------------AA ---------------------------- ---------------------------- ---------------------------- ---------------------------- ---------------------------- ---------------------------- 
---------------------------- ---------------------------- ---------------------------- ---------------------------- ---------------------------- ---------------------------- ---------------------------- ---------------------------- ---------------------------- ---------------------------- ---------------------------- ---------------------------- ---------------------------- ---------------------------- ---------------------------- ---------------------------- ---------------------------- ---------------------------- ---------------------------- ---------------------------- ---------------------------- ---------------------------- AA------------------------AA AA------------------------AA ---------------------------- ---------------------------- ---------------------------- ---------------------------- ---------------------------- ---------------------------- 
---------------------------- ---------------------------- ---------------------------- ---------------------------- ---------------------------- ---------------------------- ---------------------------- ---------------------------- ---------------------------- ---------------------------- ---------------------------- ---------------------------- ---------------------------- ---------------------------- ---------------------------- ---------------------------- ---------------------------- ---------------------------- ---------------------------- ---------------------------- ---------------------------- ---------------------------- AA------------------------AA AA------------------------AA ---------------------------- ---------------------------- ---------------------------- ---------------------------- ---------------------------- ---------------------------- 
---------------------------- ---------------------------- ---------------------------- ---------------------------- ---------------------------- ---------------------------- ---------------------------- ---------------------------- ---------------------------- ---------------------------- ---------------------------- ---------------------------- ---------------------------- ---------------------------- ---------------------------- ---------------------------- ---------------------------- ---------------------------- ---------------------------- ---------------------------- ---------------------------- AA------------------------AA AA------------------------AA AA------------------------AA ---------------------------- ---------------------------- ---------------------------- ---------------------------- ---------------------------- ---------------------------- 
---------------------------- ---------------------------- ---------------------------- ---------------------------- ---------------------------- ---------------------------- ---------------------------- ---------------------------- ---------------------------- ---------------------------- ---------------------------- ---------------------------- ---------------------------- ---------------------------- ---------------------------- ---------------------------- ---------------------------- ---------------------------- AA------------------------AA AA------------------------AA AA------------------------AA AA------------------------AA AA------------------------AA ---------------------------- ---------------------------- ---------------------------- ---------------------------- ---------------------------- ---------------------------- ---------------------------- 
---------------------------- ---------------------------- ---------------------------- ---------------------------- ---------------------------- ---------------------------- ---------------------------- ---------------------------- ---------------------------- ---------------------------- ---------------------------- ---------------------------- ---------------------------- ---------------------------- ---------------------------- ---------------------------- ---------------------------- AA------------------------AA AA------------------------AA AA------------------------AA AA------------------------AA ---------------------------- ---------------------------- ---------------------------- ---------------------------- ---------------------------- ---------------------------- ---------------------------- ---------------------------- ---------------------------- 
