model
size = 32 30 13, scale = 0.05, origin = -y
material 
  colors = A:#EEE B:#C6C6C6 C:#2D2D2D D:#444 E:#BBB F:#AAA G:#777 H:#51A8DD I:#C73E3A J:#656765 K:#24936E L:#262B51 M:#222 N:#113285 O:#90C3E3 P:#155DAF Q:#C23529 R:#E84331 S:#F9F9F9
voxels
709-19A12-21A11-22A10-23A2(9-24A)585-16B13-2(F19B12-)F3(19B13-)2(11A8D13-)2(11A8D12-F)11A7DG12-F19A14-25A44-8E24-8E467-18B12-F19B14-G15BD13-F11B6D14-F11B5D6C9-F11B2(5D6CGC7-F11A)5D6CGC8-15AD6C9-F15A2D16-G13A3D13-F19A13-27A7-24A12-EG4EGE24-E-4E-E467-2B-12B-2B12-F3BG12BG2B12-F16BD14-F11B5D6C8-JF11B5D6CGC6-2J11B3D10-L5-2J2(11A3D10-L6-F)15AD6CGC7-F15AD6C9-F15A2D14-F18A13-F19A14-27A10-8E24-8E401-2H29-2H8-4G17-2H2-18B9-2H2-20B8-H3-15BD6C6-H2-F11B5D6CGC4-H-JF11B3D10-L3-2H2J11BD10-NO6-2J11AD10-NO7-F11AD10-NO10-K12A9-L9-K12AD6CGC9-BK12AD6C11-GK15A13-F19A14-27A10-8E24-8E27-2(2E30-)EM30-MD28-2HDM28-H-MD28-H-EM4(28-H-2E)21-8H-2E21-H8-2E29-4G21-18B13-20B12-15BD6CGC7-F11B3D10-L5-JF11BD10-NO6-2J11B10-P8-2J11A10-P9-F2H9A10-P9-F-2H12A7-NO7-F2-B12A9-L6-F2-K12AD6CGC7-F-GK15A13-F19A14-27A10-8E24-8E27-2(2E30-)EM30-MD30-DM30-MD30-EM6(30-2E)29-4G21-18B13-20B12-15BD6CGC7-F11B3D10-L6-F11BD10-NO7-F11B2(10-P9-F11A)10-P12-K12A7-NO10-K12A9-L8-BK12AD6CGC9-GK15A13-F19A14-27A10-8E24-8E27-2(2E30-)EM30-MD28-2IDM28-I-MD28-I-EM4(28-I-2E)21-8I-2E21-I8-2E29-4G21-18B13-20B12-15BD6CGC7-F11B3D10-L5-JF11BD10-NO6-2J11B10-P8-2J11A10-P9-FQ10A10-S9-F-QK12A7-NO7-F2-B12A9-L6-F2-K12AD6CGC7-F-GK15A13-F19A14-27A10-8E24-8E401-2I29-2I8-4G17-2I2-18B9-2I2-20B8-I3-15BD6C6-I2-F13B3D6CGC4-I-JF12B2D10-L3-2I2J11BD10-NO6-2J11AD10-NO7-F11AD10-NO10-K12A9-L9-K12AD6CGC9-BK12AD6C11-GK15A13-F19A14-27A10-EG4EGE24-E-4E-E467-2B-12B-2B12-F3BG12BG2B12-F15B2D14-F-14BD6C8-JF-13B2D6CGC6-2J12B2D10-L5-2J2(12A2D10-L6-F)15AD6CGC7-F15AD6C9-F15A2D14-F18A13-F19A14-27A10-8E24-8E467-18B12-F19B14-G14B2D13-F15B2D14-F15BD6C9-F14B2(2D6CGC7-F14A)2D6CGC8-15AD6C9-F15ADR16-G13A3D13-F19A13-27A7-24A520-16B13-2(F19B12-)F3(19B13-)2(15A4D13-)2(15A4D12-F)15A3DG12-F19A14-25A743-19A12-21A11-22A10-23A2(9-24A)67-
