model
size = 32 30 19, scale = 0.05, origin = -y
material 
  colors = A:#FFC17A B:#FD0 C:#222 D:#AB8B00 E:#555 F:#D9BC00 G:#444 H:#BBB I:#B69A00 J:#AAA K:#A00 L:#FFF M:#777 N:#453800 O:#500 P:#33C
voxels
17-3A26-9A21-12A19-5A5K3ABA17-4AK5L3A2B15-6A2K3AK3A3B13-B20A11-B18A2B11-3ALMP8ALML4A11-A2CM2CO6AOMCMLC2A10-B3A2CO8AO3C3A9-2G11C10AB8-GCFC16H3CG8-GCFC6H5C6HFBG8-GCFC2JH4J2C2JC5JFBG8-FDFC16EG2IG7-4FC10EC5EGFIF7-5FG4EGEG8EF3B8-2BFDN2DN12CF3B7-F4B11D2N3CF3B7-2D3F13D3ID2I8-3F3BD2BF-4DF2DI2B3FI7-D3BF4B2-2(D2B)2(D3B)7-3B2-F2BD3-BD-F2BF5-BF12-2B4-B3-2B21-B8-2B27-B31-B94-3A26-9A21-12A19-5A5K3ABA15-FD4AK5L3A2B15-6A2K3AK3A3B13-B19AB11-B18A2B10-B3ALMP8ALML4A10-BA2CM2CO6AOMCMLC2A10-B3A2CO8AO3C3A9-2G11C10A9-GCFC16H3CG8-GCFC6H5C6HFBG8-GCFC2JH4J2C2JC5JFBG8-GDFC16EG2IG5-D5FC10EC5EGFIF6-6FG4EGEG8EF3B8-2BFDN2DN12CF3BI6-F4B11D2N3CF3B2I5-2D3F13D3ID2IF7-3F3BD2B-5DF2DI2B3FI11-F4B2-6BDBF5B13-3B2-3B-3B2-3B16-2B3-2B7-B22-B8-B31-B118-3A26-9A21-12A19-5A5K3ABA17-4AK5L3A2B15-6A2K3AK3A3B14-20A9-2AB21A8-AB3ALMP8ALML4AB10-A2CM2CO6AOMCMLC3A10-3A2CO8AO3C4A8-2G11C10AB8-GCFC16H3CG8-GCFC6H5C6HFBG8-GCFC2JH4J2C2JC5JFBG8-GDFC16EG2IG7-4FC10EC5EGFIF6-6FG4EGEG8EF3BI7-2BFDN2DN12CF3BI6-F4B11D2N3CF3B2I4-F2D3F13D3ID2I8-3F3BD2BF-4DF2DI2B3FI11-F4B2-2BDF2BD7B7-3B9-B7-3BD7-4B18-B9-2B20-B8-3B29-2B30-B77-3A26-9A21-12A19-5A5K3ABA17-4AK5L3A2B15-6A2K3AK3A4B13-19AB12-20A9-AB3ALMP8ALML4ABA9-A2CM2CO6AOMCMLC3A10-3A2CO8AO3C3A9-2G11C10AB8-GCFC16H3CG8-GCFC6H5C6HFBG8-GCFC2JH4J2C2JC5JFBG8-GDFC16EG2IG7-4FC10EC5EGFIF7-5FG4EGEG8EF3B8-2BFDN2DN12CF3BI6-D4B11D2N3CF3BI5-F2D3F13D3ID2IF7-3FB2-D2BF5DF2DI2B3FI14-2B-2D2BF2BD6B8-3B18-2B8-4B18-B9-3B19-B8-B-B9-2(B31-)B65-3A26-9A21-12A19-5A5K3A2B17-4AK5L3A3B14-6A2K3AK3A4B13-19AB12-20A11-3ALMP8ALML4A11-A2CM2CO6AOMCMLC2A10-B3A2CO8AO3C3A9-2G11C10AB8-GCFC16H3CG8-GCFC6H5C6HFBG8-GCFC2JH4J2C2JC5JFBG8-GDFC16EG2IG7-4FC10EC5EGFIF7-5FG4EGEG8EF3B8-2BFDN2DN12CF3BI6-F4B11D2N3CF3B6-F2D3F13D3ID2IF8-2F3BDB2-5DF2DI2B3F12-F2-B3-3DF2BD6B8-3B12-B26-3(2B30-)2B96-3A26-9A21-12AB18-5A5K3A2B16-D4AK5L3A2BA14-6A2K3AK3A3B14-18ABA12-18A3B10-3ALMP8ALML2A3B9-DA2CM2CO6AOMCMLC2BF9-B3A2CO8AO3CA3B8-2G11C9AF9-GCFC16H3CG8-GCFC6H5C6HFBG8-GCFC2JH4J2C2JC5JFBG8-GDFC16EG2IG5-D5FC10EC5EGFIF6-6FG4EGEG8EF3B8-2BFDN2DN12CF3B7-F4B11D2N3CF3B2I5-2D3F13D3ID2I8-3F3BD2B-5DF2DI2B3F12-F4B-4DFBFD6B14-B3-3B2-3B20-B3-3B2-2B21-B4-2B2-B22-B4-B128-3A26-9A21-12AD18-5A5K3A2B16-D4AK5L3A2BA14-6A2K3AK3A3BF13-18ABA12-18A3B9-B3ALMP8ALML2A3B10-A2CM2CO6AOMCMLC3B9-B3A2CO8AO3CA2B9-2G11C9AF9-GCFC16H3CG8-GCFC6H5C6HFBG8-GCFC2JH4J2C2JC5JFBG8-GDFC16EG2IG5-D5FC10EC5EGFIF6-6FG4EGEG8EF3B8-2BFDN2DN12CF3B7-F4B11D2N3CF3BI5-F2D3F13D3ID2I8-3F3BD2BF5DF2DI2B3FI8-B2-F4BF4DF2BD7B12-3B2-3B2F3B4-2BFB12-B3-3B2-2B21-B8-B215-12AF18-5A5K3AB2D15-B4AK5L3A3B14-6A2K3AK3A4B12-B18A2B11-B18A3B8-2B3ALMP8ALML2A3B9-DA2CM2CO6AOMCMLC3B9-B3A2CO8AO3CA2B9-2G11C10AB8-GCFC16H3CG8-GCFC6H5C6HFBG8-GCFC2JH4J2C2JC5JFBG8-GDFC16EG2IG6-5FC10EC5EGFIF7-5FG4EGEG8EF3BI7-2BFDN2DN12CF3BI6-F4B11D2N3CF3BI5-F2D3F13D3ID2I8-3F3BD2BF5DF2DI2B3FI7-3B-F4BF4D2F9B8-2B2-3B2-F2B2-F2-3B-F3B8-B3-B5-B2-2B-2B3-3B12-B9-B-B182-3BD3B23-11A2B17-B5A5K2A2B2D15-F4AK5L2A4B14-6A2K3AK3A4B12-B18A2B11-B18A2B9-2B3ALMP8ALML2A2B9-2BA2CM2CO6AOMCMLC3B9-B3A2CO8AO3CA2B9-2G11C10AB8-GCFC16H3CG8-GCFC6H5C6HFBG8-GCFC2JH4J2C2JC5JFBG8-GDFC16EG2IG5-D5FC10EC5EGFIF6-6FG4EGEG8EF3BI7-2BFDN2DN12CF3BIF5-F4B11D2N3CF3BI5-F2D3F13D3ID2I8-3F2B-B2-B5DF2DI2B3F8-4B2-B3-4DF10B7-3BD7-B6-2BD2-3B7-2B15-2B3-4B6-2B16-B4-3B21-B2-2B4-2B21-2B2-B4-2B21-B88-3BD6B20-11A2B17-B5A5K2A3BF15-B4AK5L2A3BF14-6A2K3AK6AB12-B18A2B11-B18A2BD8-2B3ALMP8ALML2A2B9-2BA2CM2CO6AOMCMLC3B8-2B3A2CO8AO3CA2BF8-2G11C10A9-GCFC16H3CG8-GCFC6H5C6HFBG8-GCFC2JH4J2C2JC5JFBG8-GDFC16EG2IG6-5FC10EC5EGFIF6-6FG4EGEG8EF3B8-2BFDN2DN12CF3B7-F4B11D2N3CF3B7-2D3F13D3ID2IF7-3F2B-B2-B5DF2DI2B3F8-4B2-B3-4DF7B10-3BD14-3B2-FDF7-2B16-B5-2B6-2B23-B21-B9-B21-B31-2B58-DB27-D2BD5BD20-11ABF17-B5A5K2A4B14-FD4AK5L2A4B14-6A2K3AK6AB12-B18A2B11-B18A2BF9-B3ALMP8ALML2A2BD8-2BA2CM2CO6AOMCMLC2B10-B3A2CO8AO3CA2BF8-2G11C10AB8-GCFC16H3CG8-GCFC6H5C6HFBG8-GCFC2JH4J2C2JC5JFBG8-GDFC16EG2IG7-4FC10EC5EGFIF7-5FG4EGEG8EF2B9-2BFDN2DN12CF3B7-D4B11D2N3CF3B6-F2D3F13D3ID2IF7-3F7B5DF2DI2B3FI8-DB-F7B2DF2BD3BF11-BD3-B2-BDB3-2B89-B31-B97-3B26-DBD3B3D21-D10AB19-5A5K2A3B6-G9-D4AK5L2A4B5-5G4-2B4A2K3AK5A2B8-2G2-BAB16A2B11-B18A2B3-2G6-3ALMP8ALML2A2BF4-4G-BA2CM2CO6AOMCMLC2B7-3GB3A2CO8AO3CA2B9-2G11C10AB8-GCFC16H3CG8-GCFC6H5C6HFBG8-GCFC2JH4J2C2JC5JFBG8-GDFC16EG2IG5-D5FC10EC5EGFIF6-6FG4EGEG8EF3BI7-2BFDN2DN12CF3BI6-F4B11D2N3CF3B2I5-2D3F13D3ID2I8-3F3BD2BF5DF2DI2B2F13-F7B2DF2BD4B14-3B2-4BF2BF2-D16-2(2B3-)2B21-B3-2B4-B185-3BD3B2D21-D10AB19-2B3A5K2A3B6-G10-2B2AK5L2A4B5-5G5-2B3A2K3AK5A2B8-4G-3B15AB11-G-3B15A2B3-2G5-5BMP8ALML2A3B4-4G-BA2CM2CO6AOMCMLC2B7-3GB3A2CO8AO3CA2B9-2G11C10A9-GCFC16H3CG8-GCFC6H5C6HFBG8-GCFC2JH4J2C2JC5JFBG8-GDFC16EG2IG6-5FC10EC5EGFIF7-5FG4EGEG8EF3BI7-2BFDN2DN12CF3BI6-F4B11D2N3CF3BI6-2D3F13D3ID2I11-3BD2BF5DF2DI2B2F13-F7B2DF2BD3BFB13-3B2-4BD3B2-DB15-2(2B3-)2B21-B3-B4-B31-B185-D6B-3F20-BD2-B2D2(B-)D8-G11-F2(D-)FB-F2D-D7-5G6-4B-D8B11-4G2-16B13-G2-2BDB2-BF3B-B-3B5-2G6-G20B5-4G-GAC19B7-3GB2A19B10-G11C10AB9-GF21G2(9-GF18GFBG)9-DFC16EG2IG7-4FC10EC5EGFIF8-4FG4EGEG8EF2B9-2BFDN2DN12CF2B-I6-F4B11D2N3CF2B10-3F13D3ID2I11-3BD2BF5DF2DI2B3FI17-3F3-5B15-4B2-3B-2F2-3B15-3B3-2(2B2-)3B15-2B5-B3-B2-3B15-2B9-B2-B232-G31-5G7-3B2(3-2B)71-2G32-4G2-2(B-)2B-FB-3BF5B9-3G4B3-B4-9B12-11C10B105-GDF18G3I8-3FC10EC5EGFIF9-3FG4EGEG8EF2B9-2BF3-DN3C2B3C2(BC)F2B9-3B3-9DNB3CFB11-2F3-11D3ID2I18-3D-D-2DI2B21-3F5-3B21-4B4-3B15-2B4-3B6-B16-2B4-2B24-2B4-2B3-B21-B245-3G9-B6-B76-2G32-2G67-12G9B106-GDF18G3I9-2F17BGFIF10-F-16BF2B11-F3-3BFB2-3B-F-BF17-6D-2DB-3BF13-F5-5D2-2D3ID20-3D2(-D)-IB22-3F5-BD22-2F7-B22-2B31-B25-2B4-B2-B22-B8-2B21-B8-B598-16GFB276-2B30-B25-B5-B25-B933-B31-B927-B31-B15-
