model
size = 20 29 7, scale = 0.05, origin = -y
material 
  colors = A:#111 B:#373C38 C:#555 D:#444 E:#222 F:#EEE
voxels
-------------------- -------------------- -------------------- -------------------- -------------------- -------------------- -------------------- -------------------- -------------------- -------------------- -------------------- -------------------- -------------------- -------------------- -------------------- -----C--------C----- -----C--------C----- -----B--------B----- -----A--------A----- -----A--------A----- -----B--------B----- -----BA------AB----- -----AE------EA----- -----AA------AA----- -----CB------BC----- -----CA------AC----- ------B------B------ -------------------- -------------------- 
-------------------- -------------------- -------------------- -------------------- -------------------- -------------------- -------------------- -------------------- ----A----------A---- ----E----------E---- ----DA--------AD---- ----AB--------BA---- ----BA--------AB---- ----CA--------AC---- ----AA--------AA---- ----AA--------AA---- ----AA--------AA---- ----BC--------CB---- ----AA--------AA---- ----BA--------AB---- ----BA--------AB---- ----BD--------DB---- ----BC--------CB---- ----CA--------AC---- ----AA--------AA---- ----BAA------AAB---- ----ABA------ABA---- ----AA--------AA---- -------------------- 
-------------------- -------------------- -------------------- -------------------- -------------------- -------------------- ---A------------A--- ---B------------B--- ---AA----------AA--- ---AA----------AA--- ---EA----------AE--- ---AB----------BA--- ---BD----------DB--- ---BC----------CB--- ---AA----------AA--- ---AA----------AA--- ---AA----------AA--- ---BA----------AB--- ---AA----------AA--- ---BC----------CB--- ---AA----------AA--- ---AA----------AA--- ---BA----------AB--- ---BD----------DB--- ---BA----------AB--- ---BA----------AB--- ---AFB--------BFA--- ----AEB------BEA---- -----B--------B----- 
-------------------- -------------------- -------------------- -------------------- -------------------- -------------------- ---A------------A--- --AE------------EA-- --DA------------AD-- --AA------------AA-- --CA------------AC-- --AD------------DA-- --AD------------DA-- --BA------------AB-- --AA------------AA-- --AA------------AA-- --AA------------AA-- --BA------------AB-- --BA------------AB-- --AC------------CA-- --AA------------AA-- --CA------------AC-- --CA------------AC-- --BA------------AB-- ---B------------B--- ---AA----------AA--- ---AFB--------BFA--- ----CBB------BBC---- -----B--------B----- 
-------------------- -------------------- -------------------- -------------------- --A--------------A-- --A--------------A-- --D--------------D-- --A--------------A-- -CE--------------EC- -BA--------------AB- -AA--------------AA- -AA--------------AA- -AA--------------AA- -BA--------------AB- -BA--------------AB- -EA--------------AE- -AA--------------AA- -BA--------------AB- -BA--------------AB- -AA--------------AA- -EA--------------AE- -DA--------------AD- --B--------------B-- --A--------------A-- --BA------------AB-- --AAA----------AAA-- ---AFB--------BFA--- ----DDB------BDD---- -----B--------B----- 
-------------------- -------------------- -C----------------C- -D----------------D- -A----------------A- -A----------------A- -A----------------A- -A----------------A- -D----------------D- BA----------------AB AA----------------AA BA----------------AB EA----------------AE CA----------------AC BC----------------CB BB----------------BB AA----------------AA BA----------------AB AC----------------CA BE----------------EB -A----------------A- -B----------------B- -B----------------B- -AA--------------AA- -BFA------------AFB- --AFA----------AFA-- ---AFB--------BFA--- ----BB--------BB---- -------------------- 
B------------------B C------------------C C------------------C C------------------C A------------------A C------------------C A------------------A A------------------A A------------------A A------------------A A------------------A A------------------A A------------------A A------------------A B------------------B C------------------C B------------------B B------------------B A------------------A E------------------E B------------------B B------------------B AA----------------AA -AA--------------AA- -BAA------------AAB- --BAA----------AAB-- ---AAA--------AAA--- -------------------- -------------------- 
