model
size = 32 29 13, scale = 0.05, origin = -y
material 
  colors = A:#EEE B:#C6C6C6 C:#BBB D:#2D2D2D E:#444 F:#AAA G:#777 H:#51A8DD I:#C73E3A J:#656765 K:#24936E L:#262B51 M:#222 N:#113285 O:#90C3E3 P:#155DAF Q:#C23529 R:#E84331 S:#F9F9F9
voxels
677-19A12-21A11-22A10-23A2(9-24A)553-16B13-2(F19B12-)F3(19B13-)2(11A8E13-)2(11A8E12-F)11A7EG12-F19A14-25A34-7(2C30-)2C259-18B12-F19B14-G15BE13-F11B6E14-F11B5E6D9-F11B2(5E6DGD7-F11A)5E6DGD8-15AE6D9-F15A2E16-G13A3E13-F19A13-27A7-24A2-2C30-G31-4(2C30-)G31-2C259-2B-12B-2B12-F3BG12BG2B12-F16BE14-F11B5E6D8-JF11B5E6DGD6-2J11B3E10-L5-2J2(11A3E10-L6-F)15AE6DGD7-F15AE6D9-F15A2E14-F18A13-F19A14-27A7(2C30-)2C193-2H29-2H8-4G17-2H2-18B9-2H2-20B8-H3-15BE6D6-H2-F11B5E6DGD4-H-JF11B3E10-L3-2H2J11BE10-NO6-2J11AE10-NO7-F11AE10-NO10-K12A9-L9-K12AE6DGD9-BK12AE6D11-GK15A13-F19A14-27A3(2C30-)14CM17-13CME17-2C9-2HEM17-2C9-H-ME17-2C9-H-CM4(28-H-2C)21-8H-2C21-H8-2C29-4G21-18B13-20B12-15BE6DGD7-F11B3E10-L5-JF11BE10-NO6-2J11B10-P8-2J11A10-P9-F2H9A10-P9-F-2H12A7-NO7-F2-B12A9-L6-F2-K12AE6DGD7-F-GK15A13-F19A14-27A3(2C30-)14CM17-13CME17-2C11-EM17-2C11-ME17-2C11-CM6(30-2C)29-4G21-18B13-20B12-15BE6DGD7-F11B3E10-L6-F11BE10-NO7-F11B2(10-P9-F11A)10-P12-K12A7-NO10-K12A9-L8-BK12AE6DGD9-GK15A13-F19A14-27A3(2C30-)14CM17-13CME17-2C9-2IEM17-2C9-I-ME17-2C9-I-CM4(28-I-2C)21-8I-2C21-I8-2C29-4G21-18B13-20B12-15BE6DGD7-F11B3E10-L5-JF11BE10-NO6-2J11B10-P8-2J11A10-P9-FQ10A10-S9-F-QK12A7-NO7-F2-B12A9-L6-F2-K12AE6DGD7-F-GK15A13-F19A14-27A7(2C30-)2C193-2I29-2I8-4G17-2I2-18B9-2I2-20B8-I3-15BE6D6-I2-F13B3E6DGD4-I-JF12B2E10-L3-2I2J11BE10-NO6-2J11AE10-NO7-F11AE10-NO10-K12A9-L9-K12AE6DGD9-BK12AE6D11-GK15A13-F19A14-27A2C30-G31-4(2C30-)G31-2C259-2B-12B-2B12-F3BG12BG2B12-F15B2E14-F-14BE6D8-JF-13B2E6DGD6-2J12B2E10-L5-2J2(12A2E10-L6-F)15AE6DGD7-F15AE6D9-F15A2E14-F18A13-F19A14-27A7(2C30-)2C259-18B12-F19B14-G14B2E13-F15B2E14-F15BE6D9-F14B2(2E6DGD7-F14A)2E6DGD8-15AE6D9-F15AER16-G13A3E13-F19A13-27A7-24A488-16B13-2(F19B12-)F3(19B13-)2(15A4E13-)2(15A4E12-F)15A3EG12-F19A14-25A711-19A12-21A11-22A10-23A2(9-24A)67-
