model
size = 31 32 21, scale = 0.05, origin = -y
material 
  colors = A:#800 B:#844F00 C:#222 D:#F8C200
voxels
4-2D29-2D128-21A10-21A9-7A10C14-7A2(3C20-8A)2(3C19-9A)3C18-10A3C12-2A4-9A-3C12-3A2-9A2-3C13-12A3-3C13-11A4-3C14-10A4-3CB13-B8A5-2C2B12-3B6A5-4B12-18B13-17B6(14-16B15-15B16-14B17-13B18-12B19-11B21-9B23-7B25-5B27-2D29-2D128-21A10-21A9-7A10C14-7A2(3C20-8A)2(3C19-9A)3C18-10A3C12-2A4-9A-3C12-3A2-9A2-3C13-12A3-3C13-11A4-3C14-10A4-3CB14-8A5-2C2B15-6A5-4B2(13-17B))14-16B15-15B16-14B17-13B18-12B19-11B21-9B23-7B57-2D29-2D128-21A10-21A9-7A10C14-7A2(3C20-8A)2(3C19-9A)3C18-10A3C12-2A4-9A-3C12-3A2-9A2-3C13-12A3-3C13-11A4-3C14-10A4-3CB14-8A5-2C2B15-6A5-4B2(13-17B)14-16B15-15B16-14B17-13B18-12B19-11B21-9B87-2D29-2D128-21A10-21A9-7A10C14-7A2(10C13-8A)2(10C12-9A)3C18-10A3C12-2A4-9A-3C12-3A2-9A2-3C13-12A3-3C13-11A4-3C14-10A4-3CB14-8A5-2C2B15-6A5-4B2(13-17B)14-16B15-15B16-14B17-13B18-12B19-11B117-2D29-2D128-21A10-21A9-7A10C14-7A2(10C13-8A)2(10C12-9A)3C18-10A3C12-2A4-9A-3C12-3A2-9A2-3C13-12A3-3C13-11A4-3C14-10A4-3CB14-8A5-2C2B15-6A4-5B2(13-17B)14-16B15-15B16-14B17-13B18-12B147-2D29-2D128-21A10-21A9-8A23-7A2(23-8A)2(22-9A)21-10A15-2A4-9A16-3A2-9A4B14-12A6B13-11A7B14-10A8B13-B8A9B12-3B6A9B12-18B13-17B14-16B15-15B16-14B17-13B177-2D29-2D128-21A10-21A9-8A23-7A2(23-8A)2(22-9A)21-10A15-2A4-9A16-3A2-9A3B15-12A5B14-11A7B14-10A7B14-B8A8B13-3B6A9B12-18B13-17B14-16B15-15B16-14B207-2D29-2D128-21A10-21A9-8A23-7A2(23-8A)2(22-9A)21-10A15-2A4-9A16-3A2-9A2B16-12A4B15-11A6B15-10A6B16-8A7B15-2B6A8B2(14-16B)15-15B16-15B237-2D29-2D128-21A10-21A9-8A23-7A2(23-8A)2(22-9A)21-10A15-2A4-9A16-3A2-9AB17-12A3B16-11A5B16-10A5B17-8A6B17-B6A7B16-14B17-13B17-14B268-2D29-2D128-21A10-21A9-8A23-7A2(23-8A)2(22-9A)21-10A15-2A4-9A16-3A2-9AB17-12A3B16-11A4B17-10A4B18-8A5B18-B6A6B17-13B18-13B299-2D29-2D128-21A10-21A9-8A23-7A2(23-8A)2(22-9A)21-10A15-2A4-9A16-3A2-9AB17-12A2B17-11A3B18-10A3B19-8A4B19-B6A5B19-12B330-2(2D29-2D128-21A10-21A9-8A23-7A2(23-8A)2(22-9A)21-10A15-2A4-9A16-3A2-9A18-12A19-11A21-10A22-8A24-6A366-)2D29-2D128-21A10-21A9-8A23-7A2(23-8A)2(22-9A)21-10A15-2A4-9A16-3A2-9A18-12A19-11A21-10A22-8A24-6A363-2(30D-)2D29-2(2D5-2D22-)2(2D5-2D21A-)9D21A-9D6A2(23-8A)2(22-9A)21-10A15-2A4-9A16-3A2-9A18-12A19-11A21-10A22-8A24-6A363-2(30D-)2D29-2(2D5-2D22-)2(2D5-2D21A-)9D21A-9D21A2(8-23A)2(7-24A)6-24A-2A4-9A16-3A2-9A18-12A19-11A21-10A22-8A24-6A362-
