model
size = 30 17 21, scale = 0.05, origin = -y
material 
  colors = A:#800 B:#F8C200
voxels
BBBBBBBBBBBBBBBBBBBBBBBBBBBBBB BBBBBBBBBBBBBBBBBBBBBBBBBBBBBB BB---------------------------- BB-----BB--------------------- BB-----BB--------------------- BB-----BBAAAAAAAAAAAAAAAAAAAAA BB-----BBAAAAAAAAAAAAAAAAAAAAA BBBBBBBBBAAAAAAAAAAAAAAAAAAAAA BBBBBBBBB-AAA--------AAAAAAAAA -----------AAA---------AAAAAAA ------------AAA----------AAAAA -------------AAA-----------AAA --------------AA-------------A --------------AA-------------- -------------AA--------------- ---------AAAAAA--------------- ---------AAAAAA--------------- 
BBBBBBBBBBBBBBBBBBBBBBBBBBBBBB BBBBBBBBBBBBBBBBBBBBBBBBBBBBBB BB---------------------------- BB-----BB--------------------- BB-----BB--------------------- BB-----BBAAAAAAAAAAAAAAAAAAAAA BB-----BBAAAAAAAAAAAAAAAAAAAAA BBBBBBBBBAAAAAAAAAAAAAAAAAAAAA BBBBBBBBB-AAA----------------- -----------AAA---------------- ------------AAA--------------- -------------AAA-------------- --------------AA-------------- --------------AA-------------- -------------AA--------------- ---------AAAAAA--------------- ---------AAAAAA--------------- 
---BB------------------------- ---BB------------------------- ------------------------------ ------------------------------ ------------------------------ ---------AAAAAAAAAAAAAAAAAAAAA ---------AAAAAAAAAAAAAAAAAAAAA ---------AAAAAAAAAAAAAAA------ ----------AAA----------------- -----------AAA---------------- ------------AAA--------------- -------------AAA-------------- --------------AA-------------- --------------AA-------------- -------------AA--------------- ---------AAAAAA--------------- ---------AAAAAA--------------- 
---BB------------------------- ---BB------------------------- ------------------------------ ------------------------------ ------------------------------ ---------AAAAAAAAAAAAAAAAAAAAA ---------AAAAAAAAAAAAAAAAAAAAA ---------AAAAAAAAAAAAAAA------ ----------AAA----------------- -----------AAA---------------- ------------AAA--------------- -------------AAA-------------- --------------AA-------------- --------------AA-------------- -------------AA--------------- ---------AAAAAA--------------- ---------AAAAAA--------------- 
---BB------------------------- ---BB------------------------- ------------------------------ ------------------------------ ------------------------------ ---------AAAAAAAAAAAAAAAAAAAAA ---------AAAAAAAAAAAAAAAAAAAAA ---------AAAAAAAAAAAAAAA------ ----------AAA----------------- -----------AAA---------------- ------------AAA--------------- -------------AAA-------------- --------------AA-------------- --------------AA-------------- -------------AA--------------- ---------AAAAAA--------------- ---------AAAAAA--------------- 
---BB------------------------- ---BB------------------------- ------------------------------ ------------------------------ ------------------------------ ---------AAAAAAAAAAAAAAAAAAAAA ---------AAAAAAAAAAAAAAAAAAAAA ---------AAAAAAAAAAAAAAA------ ----------AAA----------------- -----------AAA---------------- ------------AAA--------------- -------------AAA-------------- --------------AA-------------- --------------AA-------------- -------------AA--------------- ---------AAAAAA--------------- ---------AAAAAA--------------- 
---BB------------------------- ---BB------------------------- ------------------------------ ------------------------------ ------------------------------ ---------AAAAAAAAAAAAAAAAAAAAA ---------AAAAAAAAAAAAAAAAAAAAA ---------AAAAAAAAAAAAAAA------ ----------AAA----------------- -----------AAA---------------- ------------AAA--------------- -------------AAA-------------- --------------AA-------------- --------------AA-------------- -------------AA--------------- ---------AAAAAA--------------- ---------AAAAAA--------------- 
---BB------------------------- ---BB------------------------- ------------------------------ ------------------------------ ------------------------------ ---------AAAAAAAAAAAAAAAAAAAAA ---------AAAAAAAAAAAAAAAAAAAAA ---------AAAAAAAAAAAAAAA------ ----------AAA----------------- -----------AAA---------------- ------------AAA--------------- -------------AAA-------------- --------------AA-------------- --------------AA-------------- -------------AA--------------- ---------AAAAAA--------------- ---------AAAAAA--------------- 
---BB------------------------- ---BB------------------------- ------------------------------ ------------------------------ ------------------------------ ---------AAAAAAAAAAAAAAAAAAAAA ---------AAAAAAAAAAAAAAAAAAAAA ---------AAAAAAAAAAAAAAA------ ----------AAA----------------- -----------AAA---------------- ------------AAA--------------- -------------AAA-------------- --------------AA-------------- --------------AA-------------- -------------AA--------------- ---------AAAAAA--------------- ---------AAAAAA--------------- 
---BB------------------------- ---BB------------------------- ------------------------------ ------------------------------ ------------------------------ ---------AAAAAAAAAAAAAAAAAAAAA ---------AAAAAAAAAAAAAAAAAAAAA ---------AAAAAAAAAAAAAAA------ ----------AAA----------------- -----------AAA---------------- ------------AAA--------------- -------------AAA-------------- --------------AA-------------- --------------AA-------------- -------------AA--------------- ---------AAAAAA--------------- ---------AAAAAA--------------- 
---BB------------------------- ---BB------------------------- ------------------------------ ------------------------------ ------------------------------ ---------AAAAAAAAAAAAAAAAAAAAA ---------AAAAAAAAAAAAAAAAAAAAA ---------AAAAAAAAAAAAAAA------ ----------AAA----------------- -----------AAA---------------- ------------AAA--------------- -------------AAA-------------- --------------AA-------------- --------------AA-------------- -------------AA--------------- ---------AAAAAA--------------- ---------AAAAAA--------------- 
---BB------------------------- ---BB------------------------- ------------------------------ ------------------------------ ------------------------------ ---------AAAAAAAAAAAAAAAAAAAAA ---------AAAAAAAAAAAAAAAAAAAAA ---------AAAAAAAAAAAAAAA------ ----------AAA----------------- -----------AAA---------------- ------------AAA--------------- -------------AAA-------------- --------------AA-------------- --------------AA-------------- -------------AA--------------- ---------AAAAAA--------------- ---------AAAAAA--------------- 
---BB------------------------- ---BB------------------------- ------------------------------ ------------------------------ ------------------------------ ---------AAAAAAAAAAAAAAAAAAAAA ---------AAAAAAAAAAAAAAAAAAAAA ---------AAAAAAAAAAAAAAA------ ----------AAA----------------- -----------AAA---------------- ------------AAA--------------- -------------AAA-------------- --------------AA-------------- --------------AA-------------- -------------AA--------------- ---------AAAAAA--------------- ---------AAAAAA--------------- 
---BB------------------------- ---BB------------------------- ------------------------------ ------------------------------ ------------------------------ ---------AAAAAAAAAAAAAAAAAAAAA ---------AAAAAAAAAAAAAAAAAAAAA ---------AAAAAAAAAAAAAAA------ ----------AAA----------------- -----------AAA---------------- ------------AAA--------------- -------------AAA-------------- --------------AA-------------- --------------AA-------------- -------------AA--------------- ---------AAAAAA--------------- ---------AAAAAA--------------- 
---BB------------------------- ---BB------------------------- ------------------------------ ------------------------------ ------------------------------ ---------AAAAAAAAAAAAAAAAAAAAA ---------AAAAAAAAAAAAAAAAAAAAA ---------AAAAAAAAAAAAAAA------ ----------AAA----------------- -----------AAA---------------- ------------AAA--------------- -------------AAA-------------- --------------AA-------------- --------------AA-------------- -------------AA--------------- ---------AAAAAA--------------- ---------AAAAAA--------------- 
---BB------------------------- ---BB------------------------- ------------------------------ ------------------------------ ------------------------------ ---------AAAAAAAAAAAAAAAAAAAAA ---------AAAAAAAAAAAAAAAAAAAAA ---------AAAAAAAAAAAAAAA------ ----------AAA----------------- -----------AAA---------------- ------------AAA--------------- -------------AAA-------------- --------------AA-------------- --------------AA-------------- -------------AA--------------- ---------AAAAAA--------------- ---------AAAAAA--------------- 
---BB------------------------- ---BB------------------------- ------------------------------ ------------------------------ ------------------------------ ---------AAAAAAAAAAAAAAAAAAAAA ---------AAAAAAAAAAAAAAAAAAAAA ---------AAAAAAAAAAAAAAA------ ----------AAA----------------- -----------AAA---------------- ------------AAA--------------- -------------AAA-------------- --------------AA-------------- --------------AA-------------- -------------AA--------------- ---------AAAAAA--------------- ---------AAAAAA--------------- 
---BB------------------------- ---BB------------------------- ------------------------------ ------------------------------ ------------------------------ ---------AAAAAAAAAAAAAAAAAAAAA ---------AAAAAAAAAAAAAAAAAAAAA ---------AAAAAAAAAAAAAAA------ ----------AAA----------------- -----------AAA---------------- ------------AAA--------------- -------------AAA-------------- --------------AA-------------- --------------AA-------------- -------------AA--------------- ---------AAAAAA--------------- ---------AAAAAA--------------- 
---BB------------------------- ---BB------------------------- ------------------------------ ------------------------------ ------------------------------ ---------AAAAAAAAAAAAAAAAAAAAA ---------AAAAAAAAAAAAAAAAAAAAA ---------AAAAAAAAAAAAAAA------ ----------AAA----------------- -----------AAA---------------- ------------AAA--------------- -------------AAA-------------- --------------AA-------------- --------------AA-------------- -------------AA--------------- ---------AAAAAA--------------- ---------AAAAAA--------------- 
---BB------------------------- ---BB------------------------- ------------------------------ ------------------------------ ------------------------------ ---------AAAAAAAAAAAAAAAAAAAAA ---------AAAAAAAAAAAAAAAAAAAAA ---------AAAAAAAAAAAAAAA------ ----------AAA----------------- -----------AAA---------------- ------------AAA--------------- -------------AAA-------------- --------------AA-------------- --------------AA-------------- -------------AA--------------- ---------AAAAAA--------------- ---------AAAAAA--------------- 
---BB------------------------- ---BB------------------------- ------------------------------ ------------------------------ ------------------------------ ---------AAAAAAAAAAAAAAAAAAAAA ---------AAAAAAAAAAAAAAAAAAAAA ---------AAAAAAAAAAAAAAA------ ----------AAA----------------- -----------AAA---------------- ------------AAA--------------- -------------AAA-------------- --------------AA-------------- --------------AA-------------- -------------AA--------------- ---------AAAAAA--------------- ---------AAAAAA--------------- 
