model
size = 31 29 22, scale = 0.05, origin = -y
material 
  colors = A:#111 B:#909 C:#777 D:#AAA E:#C6C F:#F0C
voxels
------------------------------- ------------------------------- ------------------------------- ------------------------------- ------------------------------- ------------------------------- ------------------------------- ------------------------------- ------------------------------- ------------------------------- ------------------------------- ------------------------------- -------------FFFFF------------- ------------------------------- ------------------------------- ------------------------------- ------------------------------- ------------------------------- ------------------------------- ------------------------------- ------------------------------- ------------------------------- ------------------------------- ------------------------------- ------------------------------- ------------------------------- ------------------------------- ------------------------------- ------------------------------- 
------------------------------- ------------------------------- ------------------------------- ------------------------------- ------------------------------- ------------------------------- ------------------------------- ------------------------------- ------------------------------- ------------------------------- ------------------------------- ------------------------------- -----------FFAAAAAFF----------- ------------------------------- ------------------------------- ------------------------------- ------------------------------- ------------------------------- ------------------------------- ------------------------------- ------------------------------- ------------------------------- ------------------------------- ------------------------------- ------------------------------- ------------------------------- ------------------------------- ------------------------------- ------------------------------- 
------------------------------- ------------------------------- ------------------------------- ------------------------------- ------------------------------- ------------------------------- ------------------------------- ------------------------------- ------------------------------- ------------------------------- ------------------------------- ------------------------------- ----------FAAAAAAAAAF---------- ------------------------------- ------------------------------- ------------------------------- ------------------------------- ------------------------------- ------------------------------- ------------------------------- ------------------------------- ------------------------------- ------------------------------- ------------------------------- ------------------------------- ------------------------------- ------------------------------- ------------------------------- ------------------------------- 
------------BBB--BBB----------- -----------BB------BB---------- ----------BB--------BB--------- ---------BB----------BB-------- ---------B------------B-------- ---------B------------B-------- ---------B------------B-------- ---------B------------B-------- ---------B------------B-------- ---------B------------B-------- ---------B------------B-------- --------BB------------BB------- -------BBFAAAAAAAAAAAF-BB------ -------B----------------B------ -------B----------------B------ -------B----------------B------ -------B----------------B------ -------B----------------B------ -------B----------------B------ -------B----------------B------ -------B----------------B------ ------------------------------- ------------------------------- ------------------------------- ------------------------------- ------------------------------- ------------------------------- ------------------------------- ------------------------------- 
--------------B--B------------- ------------------------------- ------------------------------- ------------------------------- ------------------------------- ------------------------------- ------------------------------- ------------------------------- ------------------------------- ------------------------------- ------------------------------- ------------------------------- ---------FAAAAAAAAAAAF--------- ------------------------------- ------------------------------- ----------E-E--EEE--E---------- ---------E-E-E-E-E--E---------- ---------E---E-E-E-EEE--------- ------------------------------- ------------------------------- -------B----------------B------ -------B----------------B------ -------B----------------B------ ------------------------------- ------------------------------- ------------------------------- ------------------------------- ------------------------------- ------------------------------- 
--------------B--B------------- ------------------------------- ------------------------------- ------------------------------- ------------------------------- ------------------------------- ------------------------------- ------------------------------- ------------------------------- ------------------------------- ------------------------------- ------------------------------- --------FAAAAAAAAAAAAAF-------- ---------AAAAAAAAAAAAA--------- ---------AAAAAAAAAAAAA--------- ---------AAAAAAAAAAAAA--------- ---------AAAAAAAAAAAAA--------- ---------AAAAAAAAAAAAA--------- ---------AAAAAAAAAAAAA--------- ------------------------------- ------------AA-AA-AA----------- ------------A--AA-A------------ -------B----A--AA-A-----B------ -------B----------------B------ ------------------------------- ------------------------------- ------------------------------- ------------------------------- ------------------------------- 
--------------B--B------------- ------------------------------- ------------------------------- ------------------------------- ------------------------------- ------------------------------- ------------------------------- ------------------------------- ------------------------------- ------------------------------- ------------------------------- ------------------------------- --------FAAAA-----AAAAF-------- ----------AAA-----AA----------- ----------AA-------A----------- ----------AAA-----AA----------- ----------AAA-----AAA---------- ----------AAAAAAAAAA----------- ----------AAAAAAAAAA----------- -----------EEEEEEEEEE---------- -----------EEEEEEEEEE---------- -----------EEEEEEEEEE---------- -----------EEEEEEEEEE---------- -------B---EEEEEEEEEE---B------ ------BB----------------BB----- ------B------------------B----- ------B------------------B----- ------------------------------- ------------------------------- 
------------------------------- ------------------------------- ------------------------------- ------------------------------- ------------------------------- ------------------------------- ------------------------------- ------------------------------- ------------------------------- ------------------------------- ------------------------------- ------------------------------- --------FAA---------AAF-------- ----------A---------A---------- ---------AA---------AA--------- ----------A---------A---------- ----------A---------A---------- ----------A---------A---------- -----------A-------A----------- ------------AAAAAAA------------ ---------------A--------------- ------------------------------- ------------------------------- ------------------------------- ------------------------------- ------------------------------- ------B------------------B----- ------B------------------B----- ------------------------------- 
------------------------------- ------------------------------- ------------------------------- ------------------------------- ------------------------------- ------------------------------- ------------------------------- ------------------------------- ------------------------------- ------------------------------- ------------------------------- ------------------------------- --------FA-----------AF-------- ---------A-----------A--------- ---------A-----------A--------- ---------A-----------A--------- ---------A-----------A--------- ---------A-----------A--------- ----------A---------A---------- -----------A-------A----------- ------------AAAAAAA------------ ------------------------------- ------------------------------- ------------------------------- ------------------------------- ------------------------------- ------------------------------- ------B------------------B----- ------B------------------B----- 
------------------------------- ------------------------------- ------------------------------- ------------------------------- ------------------------------- ------------------------------- ------------------------------- ------------------------------- ------------------------------- ------------------------------- ------------------------------- ------------------------------- --------F-------------F-------- --------A-------------A-------- --------A-------------A-------- --------A-------------A-------- --------A-------------A-------- ---------A-----------A--------- ---------A-----------A--------- ----------A---------A---------- -----------AA-----AA----------- -------------AAAAA------------- ------------------------------- ------------------------------- ------------------------------- ------------------------------- ------------------------------- ------------------------------- ------B------------------B----- 
------------------------------- ------------------------------- ------------------------------- ------------------------------- ------------------------------- ------------------------------- ------------------------------- ------------------------------- ------------------------------- ------------------------------- ------------------------------- ------------------------------- --------F-------------F---CCC-- --------A-------------A---AAA-- --------A-------------A---AAA-- --------A-------------A---AAA-- --------A-------------A---AAA-- --------A-------------A---AAA-- ---------A-----------A----AAA-- ---------A-----------A----AAA-- ----------AA-------AA-----AAA-- ------------AAAAAAA-------AAA-- --------------------------AAA-- --------------------------DDD-- ------------------------------- ------------------------------- ------------------------------- ------B------------------B----- ------B------------------B----- 
------------------------------- ------------------------------- ------------------------------- ------------------------------- ------------------------------- ------------------------------- ------------------------------- ------------------------------- ------------------------------- ------------------------------- ------------------------------- ------------------------------- --CCC--C---------------C-CCCCC- --AAA--A---------------A-AAAAA- --AAA--A---------------A-AAAAA- --AAA--A---------------A-AAAAA- --AAA--A---------------A-AAAAA- --AAA---A-------------A--AAAAA- --AAA---A-------------A--AAAAA- --AAA----A-----------A---AAAAA- --AAA-----A---------A----AAAAA- --AAA------AA-----AA-----AAAAA- --AAA--------AAAAA-------AAAAA- --DDD--------------------DDDDD- ------------------------------- ------------------------------- ------------------------------- ------B------------------B----- ------------------------------- 
------------------------------- ------------------------------- ------------------------------- ------------------------------- ------------------------------- ------------------------------- ------------------------------- ------------------------------- ------------------------------- ------------------------------- ------------------------------- ------------------------------- -CCCCC-C---------------CCCCCCCC -AAAAA-A---------------AAAAAAAA -AAAAA-A---------------AAAAAAAA -AAAAA-A---------------AAAAAAAA -AAAAA-A---------------AAAAAAAA -AAAAA--A-------------A-AAAAAAA -AAAAA--A-------------A-AAAAAAA -AAAAA---A-----------A--AAAAAAA -AAAAA----A---------A---AAAAAAA -AAAAA-----AA-----AA----AAAAAAA -AAAAA-------AAAAA------AAAAAAA -DDDDD------------------DDDDDDD ------------------------------- -----B--------------------B---- -----BB------------------BB---- ------B------------------B----- ------------------------------- 
------------------------------- ------------------------------- ------------------------------- ------------------------------- ------------------------------- ------------------------------- ------------------------------- ------------------------------- ------------------------------- ------------------------------- ------------------------------- ------------------------------- CCCCCCCC-------A-------CCCCCCCC AAAAAAAA---------------AAAAAAAA AAAAAAAA---------------AAAAAAAA AAAAAAAA---------------AAAAAAAA AAAAAAAA---------------AAAAAAAA AAAAAAA-A-------------A-AAAAAAA AAAAAAA-A-------------A-AAAAAAA AAAAAAA--A-----------A--AAAAAAA AAAAAAA--AA---------AA--AAAAAAA AAAAAAA----AA-----AA----AAAAAAA AAAAAAA------AAAAA------AAAAAAA DDDDDDD--------A--------DDDDDDD -----B--------------------B---- -----B--------------------B---- ------------------------------- ------------------------------- ------------------------------- 
------------------------------- ------------------------------- ------------------------------- ------------------------------- ------------------------------- ------------------------------- ------------------------------- ------------------------------- ------------------------------- ------------------------------- ------------------------------- ------------------------------- CCCCCCCC---------------CCCCCCCC AAAAAAAA---------------AAAAAAAA AAAAAAAA---------------AAAAAAAA AAAAAAAA---------------AAAAAAAA AAAAAAAA---------------AAAAAAAA AAAAAAA-A-------------A-AAAAAAA AAAAAAA-A-------------A-AAAAAAA AAAAAAA--A-----------A--AAAAAAA AAAAAAA---A---------A---AAAAAAA AAAAAAA----AA-----AA----AAAAAAA AAAAAAA------AAAAA------AAAAAAA DDDDDDD-----------------DDDDDDD ------------------------------- ------------------------------- ------------------------------- ------------------------------- ------------------------------- 
------------------------------- ------------------------------- ------------------------------- ------------------------------- ------------------------------- ------------------------------- ------------------------------- ------------------------------- ------------------------------- ------------------------------- ------------------------------- ------------------------------- CCCCCCCC---------------F-CCCCC- AAAAAAAA---------------A-AAAAA- AAAAAAAA---------------A-AAAAA- AAAAAAAA---------------A-AAAAA- AAAAAAAA---------------A-AAAAA- AAAAAAA-A-------------A--AAAAA- AAAAAAA-A-------------A--AAAAA- AAAAAAA--A-----------A---AAAAA- AAAAAAA---A---------A----AAAAA- AAAAAAA----AA-----AA-----AAAAA- AAAAAAA------AAAAA-------AAAAA- DDDDDDD------------------DDDDD- ------------------------------- ------------------------------- ------------------------------- ------------------------------- ------------------------------- 
------------------------------- ------------------------------- ------------------------------- ------------------------------- ------------------------------- ------------------------------- ------------------------------- ------------------------------- ------------------------------- ------------------------------- ------------------------------- ------------------------------- -CCCCC--A-------------F---CCC-- -AAAAA--A-------------A---AAA-- -AAAAA--A-------------A---AAA-- -AAAAA--A-------------A---AAA-- -AAAAA--A-------------A---AAA-- -AAAAA--A-------------A---AAA-- -AAAAA---A-----------A----AAA-- -AAAAA---A-----------A----AAA-- -AAAAA----AA-------AA-----AAA-- -AAAAA------AAAAAAA-------AAA-- -AAAAA--------------------AAA-- -DDDDD--------------------DDD-- ------------------------------- ------------------------------- ------------------------------- ------------------------------- ------------------------------- 
------------------------------- ------------------------------- ------------------------------- ------------------------------- ------------------------------- ------------------------------- ------------------------------- ------------------------------- ------------------------------- ------------------------------- ------------------------------- ------------------------------- --CCC---F-------------F-------- --AAA---A-------------A-------- --AAA---A-------------A-------- --AAA---A-------------A-------- --AAA---A-------------A-------- --AAA----A-----------A--------- --AAA----A-----------A--------- --AAA-----A---------A---------- --AAA------AA-----AA----------- --AAA--------AAAAA------------- --AAA-------------------------- --DDD-------------------------- ------------------------------- ------------------------------- ------------------------------- ------------------------------- ------------------------------- 
------------------------------- ------------------------------- ------------------------------- ------------------------------- ------------------------------- ------------------------------- ------------------------------- ------------------------------- ------------------------------- ------------------------------- ------------------------------- ------------------------------- ---------F-----------F--------- ---------A-----------A--------- ---------A-----------A--------- ---------A-----------A--------- ---------A-----------A--------- ---------A-----------A--------- ----------A---------A---------- -----------A-------A----------- ------------AAAAAAA------------ ------------------------------- ------------------------------- ------------------------------- ------------------------------- ------------------------------- ------------------------------- ------------------------------- ------------------------------- 
------------------------------- ------------------------------- ------------------------------- ------------------------------- ------------------------------- ------------------------------- ------------------------------- ------------------------------- ------------------------------- ------------------------------- ------------------------------- ------------------------------- ----------F---------F---------- ----------A---------A---------- ---------AA---------AA--------- ----------A---------A---------- ----------A---------A---------- ----------AA-------AA---------- -----------AA-----AA----------- ------------AAAAAAA------------ ---------------A--------------- ------------------------------- ------------------------------- ------------------------------- ------------------------------- ------------------------------- ------------------------------- ------------------------------- ------------------------------- 
------------------------------- ------------------------------- ------------------------------- ------------------------------- ------------------------------- ------------------------------- ------------------------------- ------------------------------- ------------------------------- ------------------------------- ------------------------------- ------------------------------- -----------FF-----FF----------- -----------AA-----AA----------- -----------AA-----AA----------- -----------AA-----AA----------- -----------AA-----AA----------- ------------AAAAAAA------------ -------------AAAAA------------- ------------------------------- ------------------------------- ------------------------------- ------------------------------- ------------------------------- ------------------------------- ------------------------------- ------------------------------- ------------------------------- ------------------------------- 
------------------------------- ------------------------------- ------------------------------- ------------------------------- ------------------------------- ------------------------------- ------------------------------- ------------------------------- ------------------------------- ------------------------------- ------------------------------- ------------------------------- -------------FFFFF------------- ------------------------------- -------------AAAAA------------- -------------AAAAA------------- -------------AAAAA------------- ------------------------------- ------------------------------- ------------------------------- ------------------------------- ------------------------------- ------------------------------- ------------------------------- ------------------------------- ------------------------------- ------------------------------- ------------------------------- ------------------------------- 
