model
size = 31 29 22, scale = 0.05, origin = -y
material 
  colors = A:#020 B:#FF3 C:#F60 D:#777 E:#AAA
voxels
------------------------------- ------------------------------- ------------------------------- ------------------------------- ------------------------------- ------------------------------- ------------------------------- ------------------------------- ------------------------------- ------------------------------- ------------------------------- ------------------------------- -------------BBBBB------------- ------------------------------- ------------------------------- ------------------------------- ------------------------------- ------------------------------- ------------------------------- ------------------------------- ------------------------------- ------------------------------- ------------------------------- ------------------------------- ------------------------------- ------------------------------- ------------------------------- ------------------------------- ------------------------------- 
------------------------------- ------------------------------- ------------------------------- ------------------------------- ------------------------------- ------------------------------- ------------------------------- ------------------------------- ------------------------------- ------------------------------- ------------------------------- ------------------------------- -----------BBAAAAABB----------- ------------------------------- ------------------------------- ------------------------------- ------------------------------- ------------------------------- ------------------------------- ------------------------------- ------------------------------- ------------------------------- ------------------------------- ------------------------------- ------------------------------- ------------------------------- ------------------------------- ------------------------------- ------------------------------- 
------------------------------- ------------------------------- ------------------------------- ------------------------------- ------------------------------- ------------------------------- ------------------------------- ------------------------------- ------------------------------- ------------------------------- ------------------------------- ------------------------------- ----------BAAAAAAAAAB---------- ------------------------------- ------------------------------- ------------------------------- ------------------------------- ------------------------------- ------------------------------- ------------------------------- ------------------------------- ------------------------------- ------------------------------- ------------------------------- ------------------------------- ------------------------------- ------------------------------- ------------------------------- ------------------------------- 
------------CCC--CCC----------- -----------CC------CC---------- ----------CC--------CC--------- ---------CC----------CC-------- ---------C------------C-------- ---------C------------C-------- ---------C------------C-------- ---------C------------C-------- ---------C------------C-------- ---------C------------C-------- ---------C------------C-------- --------CC------------CC------- -------CCBAAAAAAAAAAAB-CC------ -------C----------------C------ -------C----------------C------ -------C----------------C------ -------C----------------C------ -------C----------------C------ -------C----------------C------ -------C----------------C------ -------C----------------C------ ------------------------------- ------------------------------- ------------------------------- ------------------------------- ------------------------------- ------------------------------- ------------------------------- ------------------------------- 
--------------C--C------------- ------------------------------- ------------------------------- ------------------------------- ------------------------------- ------------------------------- ------------------------------- ------------------------------- ------------------------------- ------------------------------- ------------------------------- ------------------------------- ---------BAAAAAAAAAAAB--------- --------------A-B-------------- -------------B-A-A------------- ---------------A--------------- ------------------------------- ------------------------------- ------------------------------- ------------------------------- -------C----------------C------ -------C----------------C------ -------C----------------C------ ------------------------------- ------------------------------- ------------------------------- ------------------------------- ------------------------------- ------------------------------- 
--------------C--C------------- ------------------------------- ------------------------------- ------------------------------- ------------------------------- ------------------------------- ------------------------------- ------------------------------- ------------------------------- ------------------------------- ------------------------------- ------------------------------- --------BAAAAAAAAAAAAAB-------- ------------BA-A-B------------- -----------BA-A-B-B------------ -----------B-BA-BB-A----------- -------------ABABA------------- ------------------------------- ------------------------------- ------------------------------- ------------------------------- ------------------------------- -------C----------------C------ -------C----------------C------ ------------------------------- ------------------------------- ------------------------------- ------------------------------- ------------------------------- 
--------------C--C------------- ------------------------------- ------------------------------- ------------------------------- ------------------------------- ------------------------------- ------------------------------- ------------------------------- ------------------------------- ------------------------------- ------------------------------- ------------------------------- --------BAAAA-----AAAAB-------- -----------AB-----AA----------- -----------B-------A----------- -----------AA-----AA----------- ----------BAA-----BAA---------- -----------AAABABBAA----------- ------------AAAAAAA------------ ------------------------------- ------------------------------- ------------------------------- ------------------------------- -------C----------------C------ ------CC----------------CC----- ------C------------------C----- ------C------------------C----- ------------------------------- ------------------------------- 
------------------------------- ------------------------------- ------------------------------- ------------------------------- ------------------------------- ------------------------------- ------------------------------- ------------------------------- ------------------------------- ------------------------------- ------------------------------- ------------------------------- --------BAA---------AAB-------- ----------A---------A---------- ---------AA---------AA--------- ----------A---------A---------- ----------A---------A---------- ----------B---------A---------- -----------A-------A----------- ------------AAAAAAA------------ ---------------A--------------- ------------------------------- ------------------------------- ------------------------------- ------------------------------- ------------------------------- ------C------------------C----- ------C------------------C----- ------------------------------- 
------------------------------- ------------------------------- ------------------------------- ------------------------------- ------------------------------- ------------------------------- ------------------------------- ------------------------------- ------------------------------- ------------------------------- ------------------------------- ------------------------------- --------BA-----------AB-------- ---------A-----------A--------- ---------A-----------A--------- ---------A-----------A--------- ---------A-----------A--------- ---------A-----------A--------- ----------A---------A---------- -----------A-------A----------- ------------AAAAAAA------------ ------------------------------- ------------------------------- ------------------------------- ------------------------------- ------------------------------- ------------------------------- ------C------------------C----- ------C------------------C----- 
------------------------------- ------------------------------- ------------------------------- ------------------------------- ------------------------------- ------------------------------- ------------------------------- ------------------------------- ------------------------------- ------------------------------- ------------------------------- ------------------------------- --------B-------------B-------- --------A-------------A-------- --------A-------------A-------- --------A-------------A-------- --------A-------------A-------- ---------A-----------A--------- ---------A-----------A--------- ----------A---------A---------- -----------AA-----AA----------- -------------AAAAA------------- ------------------------------- ------------------------------- ------------------------------- ------------------------------- ------------------------------- ------------------------------- ------C------------------C----- 
------------------------------- ------------------------------- ------------------------------- ------------------------------- ------------------------------- ------------------------------- ------------------------------- ------------------------------- ------------------------------- ------------------------------- ------------------------------- ------------------------------- --------B-------------B---DDD-- --------A-------------A---BBA-- --------A-------------A---BAB-- --------A-------------A---BBA-- --------A-------------A---BAB-- --------A-------------A---BBA-- ---------A-----------A----AAA-- ---------A-----------A----ABA-- ----------AA-------AA-----BAB-- ------------AAAAAAA-------BAB-- --------------------------AAA-- --------------------------EEE-- ------------------------------- ------------------------------- ------------------------------- ------C------------------C----- ------C------------------C----- 
------------------------------- ------------------------------- ------------------------------- ------------------------------- ------------------------------- ------------------------------- ------------------------------- ------------------------------- ------------------------------- ------------------------------- ------------------------------- ------------------------------- --DDD--D---------------D-DDDDD- --BBA--A---------------A-AAAAA- --BAB--A---------------A-AAAAA- --BBA--A---------------A-AAAAA- --BAB--A---------------A-AAAAA- --BBA---A-------------A--AAAAA- --AAA---A-------------A--AAAAA- --ABA----A-----------A---AAAAA- --BAB-----A---------A----AAAAA- --BAB------AA-----AA-----AAAAA- --AAA--------AAAAA-------AAAAA- --EEE--------------------EEEEE- ------------------------------- ------------------------------- ------------------------------- ------C------------------C----- ------------------------------- 
------------------------------- ------------------------------- ------------------------------- ------------------------------- ------------------------------- ------------------------------- ------------------------------- ------------------------------- ------------------------------- ------------------------------- ------------------------------- ------------------------------- -DDDDD-D---------------DDDDDDDD -AAAAA-A---------------AAAAAAAA -AAAAA-A---------------AAAAAAAA -AAAAA-A---------------AAAAAAAA -AAAAA-A---------------AAAAAAAA -AAAAA--A-------------A-AAAAAAA -AAAAA--A-------------A-AAAAAAA -AAAAA---A-----------A--AAAAAAA -AAAAA----A---------A---AAAAAAA -AAAAA-----AA-----AA----AAAAAAA -AAAAA-------AAAAA------AAAAAAA -EEEEE------------------EEEEEEE ------------------------------- -----C--------------------C---- -----CC------------------CC---- ------C------------------C----- ------------------------------- 
------------------------------- ------------------------------- ------------------------------- ------------------------------- ------------------------------- ------------------------------- ------------------------------- ------------------------------- ------------------------------- ------------------------------- ------------------------------- ------------------------------- DDDDDDDD-------A-------DDDDDDDD AAAAAAAA---------------AAAAAAAA AAAAAAAA---------------AAAAAAAA AAAAAAAA---------------AAAAAAAA AAAAAAAA---------------AAAAAAAA AAAAAAA-A-------------A-AAAAAAA AAAAAAA-A-------------A-AAAAAAA AAAAAAA--A-----------A--AAAAAAA AAAAAAA--AA---------AA--AAAAAAA AAAAAAA----AA-----AA----AAAAAAA AAAAAAA------AAAAA------AAAAAAA EEEEEEE--------B--------EEEEEEE -----C--------------------C---- -----C--------------------C---- ------------------------------- ------------------------------- ------------------------------- 
------------------------------- ------------------------------- ------------------------------- ------------------------------- ------------------------------- ------------------------------- ------------------------------- ------------------------------- ------------------------------- ------------------------------- ------------------------------- ------------------------------- DDDDDDDD---------------DDDDDDDD AAAAAAAA---------------AAAAAAAA AAAAAAAA---------------AAAAAAAA AAAAAAAA---------------AAAAAAAA AAAAAAAA---------------AAAAAAAA AAAAAAA-A-------------A-AAAAAAA AAAAAAA-A-------------A-AAAAAAA AAAAAAA--A-----------A--AAAAAAA AAAAAAA---A---------A---AAAAAAA AAAAAAA----AA-----AA----AAAAAAA AAAAAAA------AAAAA------AAAAAAA EEEEEEE-----------------EEEEEEE ------------------------------- ------------------------------- ------------------------------- ------------------------------- ------------------------------- 
------------------------------- ------------------------------- ------------------------------- ------------------------------- ------------------------------- ------------------------------- ------------------------------- ------------------------------- ------------------------------- ------------------------------- ------------------------------- ------------------------------- DDDDDDDD---------------D-DDDDD- AAAAAAAA---------------A-AAAAA- AAAAAAAA---------------A-AAAAA- AAAAAAAA---------------A-AAAAA- AAAAAAAA---------------A-AAAAA- AAAAAAA-A-------------A--AAAAA- AAAAAAA-A-------------A--AAAAA- AAAAAAA--A-----------A---AAAAA- AAAAAAA---A---------A----AAAAA- AAAAAAA----AA-----AA-----AAAAA- AAAAAAA------AAAAA-------AAAAA- EEEEEEE------------------EEEEE- ------------------------------- ------------------------------- ------------------------------- ------------------------------- ------------------------------- 
------------------------------- ------------------------------- ------------------------------- ------------------------------- ------------------------------- ------------------------------- ------------------------------- ------------------------------- ------------------------------- ------------------------------- ------------------------------- ------------------------------- -DDDDD--A-------------A---DDD-- -AAAAA--A-------------A---ABB-- -AAAAA--A-------------A---BAB-- -AAAAA--A-------------A---ABB-- -AAAAA--A-------------A---BAB-- -AAAAA--A-------------A---ABB-- -AAAAA---A-----------A----AAA-- -AAAAA---A-----------A----ABA-- -AAAAA----AA-------AA-----BAB-- -AAAAA------AAAAAAA-------BAB-- -AAAAA--------------------AAA-- -EEEEE--------------------EEE-- ------------------------------- ------------------------------- ------------------------------- ------------------------------- ------------------------------- 
------------------------------- ------------------------------- ------------------------------- ------------------------------- ------------------------------- ------------------------------- ------------------------------- ------------------------------- ------------------------------- ------------------------------- ------------------------------- ------------------------------- --DDD---A-------------A-------- --ABB---A-------------A-------- --BAB---A-------------A-------- --ABB---A-------------A-------- --BAB---A-------------A-------- --ABB----A-----------A--------- --AAA----A-----------A--------- --ABA-----A---------A---------- --BAB------AA-----AA----------- --BAB--------AAAAA------------- --AAA-------------------------- --EEE-------------------------- ------------------------------- ------------------------------- ------------------------------- ------------------------------- ------------------------------- 
------------------------------- ------------------------------- ------------------------------- ------------------------------- ------------------------------- ------------------------------- ------------------------------- ------------------------------- ------------------------------- ------------------------------- ------------------------------- ------------------------------- ---------A-----------A--------- ---------A-----------A--------- ---------A-----------A--------- ---------A-----------A--------- ---------A-----------A--------- ---------A-----------A--------- ----------A---------A---------- -----------A-------A----------- ------------AAAAAAA------------ ------------------------------- ------------------------------- ------------------------------- ------------------------------- ------------------------------- ------------------------------- ------------------------------- ------------------------------- 
------------------------------- ------------------------------- ------------------------------- ------------------------------- ------------------------------- ------------------------------- ------------------------------- ------------------------------- ------------------------------- ------------------------------- ------------------------------- ------------------------------- ----------A---------A---------- ----------A---------A---------- ---------AA---------AA--------- ----------A---------A---------- ----------A---------A---------- ----------AA-------AA---------- -----------AA-----AA----------- ------------AAAAAAA------------ ---------------A--------------- ------------------------------- ------------------------------- ------------------------------- ------------------------------- ------------------------------- ------------------------------- ------------------------------- ------------------------------- 
------------------------------- ------------------------------- ------------------------------- ------------------------------- ------------------------------- ------------------------------- ------------------------------- ------------------------------- ------------------------------- ------------------------------- ------------------------------- ------------------------------- -----------AA-----AA----------- -----------AA-----AA----------- -----------AA-----AA----------- -----------AA-----AA----------- -----------AA-----AA----------- ------------AAAAAAA------------ -------------AAAAA------------- ------------------------------- ------------------------------- ------------------------------- ------------------------------- ------------------------------- ------------------------------- ------------------------------- ------------------------------- ------------------------------- ------------------------------- 
------------------------------- ------------------------------- ------------------------------- ------------------------------- ------------------------------- ------------------------------- ------------------------------- ------------------------------- ------------------------------- ------------------------------- ------------------------------- ------------------------------- -------------BBBBB------------- ------------------------------- -------------AAAAA------------- -------------AAAAA------------- -------------AAAAA------------- ------------------------------- ------------------------------- ------------------------------- ------------------------------- ------------------------------- ------------------------------- ------------------------------- ------------------------------- ------------------------------- ------------------------------- ------------------------------- ------------------------------- 
