model
size = 17 12 22, scale = 0.05, origin = -y
material 
  colors = A:#020 B:#DDD
voxels
------AAAAA------ ----------------- ----------------- ----------------- ----------------- ----------------- ----------------- ----------------- ----------------- ----------------- ----------------- ----------------- 
----AAAAAAAAA---- ----------------- ----------------- ----------------- ----------------- ----------------- ----------------- ----------------- ----------------- ----------------- ----------------- ----------------- 
---AAAAAAAAAAA--- ----------------- ----------------- ----------------- ----------------- ----------------- ----------------- ----------------- ----------------- ----------------- ----------------- ----------------- 
--AAAAAAAAAAAAA-- ----------------- ----------------- ----------------- ----------------- ----------------- ----------------- ----------------- ----------------- ----------------- ----------------- ----------------- 
--AAAAAAAAAAAAA-- -------B-B------- ------B-B-B------ --------B-------- ----------------- ----------------- ----------------- ----------------- ----------------- ----------------- ----------------- ----------------- 
-AAAAAAAAAAAAAAA- ------A-A-A------ -----B-A-A-B----- ----B-AA-AA-B---- ------AAAAA------ ----------------- --------B-------- ----------------- ----------------- ----------------- ----------------- ----------------- 
-AAAAA-----AAAAA- ----AA-----AA---- ----A-------A---- ----AA-----AA---- ---BAA-----AAB--- ----BAAAAAAAB---- -----BAAAAAB----- ---------B------- ----------------- ----------------- ----------------- ----------------- 
-AAA---------AAA- ---A---------A--- --AA---------AA-- ---A---------A--- ---A---------A--- ---A---------A--- ----A-------A---- -----AAAAAAA----- --------A-------- ----------------- ----------------- ----------------- 
-AA-----------AA- --A-----------A-- --A-----------A-- --A-----------A-- --A-----------A-- --A-----------A-- ---A---------A--- ----A-------A---- -----AAAAAAA----- ----------------- ----------------- ----------------- 
-A-------------A- -A-------------A- -A-------------A- -A-------------A- -A-------------A- --A-----------A-- --A-----------A-- ---A---------A--- ----AA-----AA---- ------AAAAA------ ----------------- ----------------- 
-A-------------A- -A-------------A- -A-------------A- -A-------------A- -A-------------A- -A-------------A- --A-----------A-- --A-----------A-- ---AA-------AA--- -----AAAAAAA----- ----------------- ----------------- 
A---------------A A---------------A A---------------A A---------------A A---------------A -A-------------A- -A-------------A- --A-----------A-- ---A---------A--- ----AA-----AA---- ------AAAAA------ ----------------- 
A---------------A A---------------A A---------------A A---------------A A---------------A -A-------------A- -A-------------A- --A-----------A-- ---A---------A--- ----AA-----AA---- ------AAAAA------ ----------------- 
A-------A-------A A---------------A A---------------A A---------------A A---------------A -A-------------A- -A-------------A- --A-----------A-- --AA---------AA-- ----AA-----AA---- ------AAAAA------ --------A-------- 
A---------------A A---------------A A---------------A A---------------A A---------------A -A-------------A- -A-------------A- --A-----------A-- ---A---------A--- ----AA-----AA---- ------AAAAA------ ----------------- 
A---------------A A---------------A A---------------A A---------------A A---------------A -A-------------A- -A-------------A- --A-----------A-- ---A---------A--- ----AA-----AA---- ------AAAAA------ ----------------- 
-A-------------A- -A-------------A- -A-------------A- -A-------------A- -A-------------A- -A-------------A- --A-----------A-- --A-----------A-- ---AA-------AA--- -----AAAAAAA----- ----------------- ----------------- 
-A-------------A- -A-------------A- -A-------------A- -A-------------A- -A-------------A- --A-----------A-- --A-----------A-- ---A---------A--- ----AA-----AA---- ------AAAAA------ ----------------- ----------------- 
--A-----------A-- --A-----------A-- --A-----------A-- --A-----------A-- --A-----------A-- --A-----------A-- ---A---------A--- ----A-------A---- -----AAAAAAA----- ----------------- ----------------- ----------------- 
---A---------A--- ---A---------A--- --AA---------AA-- ---A---------A--- ---A---------A--- ---AA-------AA--- ----AA-----AA---- -----AAAAAAA----- --------A-------- ----------------- ----------------- ----------------- 
----AA-----AA---- ----AA-----AA---- ----AA-----AA---- ----AA-----AA---- ----AA-----AA---- -----AAAAAAA----- ------AAAAA------ ----------------- ----------------- ----------------- ----------------- ----------------- 
------AAAAA------ ----------------- ------AAAAA------ ------AAAAA------ ------AAAAA------ ----------------- ----------------- ----------------- ----------------- ----------------- ----------------- ----------------- 
