model
size = 10 25 3, scale = 0.05, origin = -y
material 
  colors = A:#333 B:#222 C:#FFF D:#444 E:#DDD F:#555 G:#777 H:#EEE I:#666 J:#06C K:#039 L:#6F9 M:#888 N:#111
voxels
BBBBBBBBBB ---------- ---------- ---------- ---------- ---------- ---------- ---------- ---------- ---------- ---------- ---------- ---------- ---------- ---------- ---------- ---------- ---------- ---------- ---------- ---------- ---------- ---------- ---------- ---------- 
DFMMDBBBBB GFFDDBBBBB ---------- FFIIIIIDBB CCCHHHCCCC CCHEEEHCCC CCHEEEHHCC CCHEEEHHCC CCHEEEHHCC CCHEEEHHCC CCEEEEHHCC CCEEEEEHCC CCEEEEEECC CCEEEEEECC CCEEEEEECC CCEHEEEECC CCEEHHEECC CCEHEHEECC CCHHHHHHCL GBKBBBBABB GAKKKKKKAB FFJJJJJJFB FFFFFFFFFB FBFFFFFFFB FFFFFFFFFN 
DFBBBBBBBB GFFDDBBBBB ---------- FFIIIIIDBB FAAAAAAAAB FAAAAAAAAB DAAAAAAAAA FAAAAAAAAB FAAAAAAAAB FAAAAAAAAB GAJLLLLLAB GAGGGGGGAB GAGAAAGAAB GAGGGAGAAB GAAAGAGGAB GAGGGAGAAB GAAAAAAAAB GDDDDDDDDB GDDDDDDDDJ GD-DDDDDDB GD------DB ID------DB IDDDDDIIDB FDDDDDIBDB -DDDDDDDD- 
