model
size = 32 5 16, scale = 0.05, origin = -y
material 
  colors = A:#9CF B:#777 C:#EEE D:#222 E:#00E F:#DDD G:#444 H:#555 I:#E00 J:#6FF K:#500 L:#0F6
voxels
71AC6(F2C)F3C2A2(7B23-2B32-33A5-25A-A5-AC6(F2C)F3CA-)2(BD)3B23-2B3-G2(28-33A5-25A-A5-A2(C2D)CF3(C2D)2CF2DCA-2(BD)3B23-2B2(-G))28-33A5-25A-A5-A2(C2D)CF3(C2D)2CF2DCA-2(BD)3B23-2B-G30-33A5-25A-A5-A2(C2D)CF3(C2D)2CF2DCA-2(BD)3B2(23-2B32-33A5-25A-A5-A2(C2D)CF3(C2D)2CF2DCA-7B)23-2B32-33A5-25A-A5-25A-32B32-33A31-A31-2(B3E)3(BE)2B7(IK)IB32-33A31-A5-2A24-2(3BE)B3EBE18B32-33A31-A5-2A24-2(B3E)2(BE)B3E3B2GB2G8B19-2G-2G8-33A31-A5-2A24-B2(E3B)3EBE2BE8B4J3B32-33A31-A5-2A24-2(B3E)2BE2B3E2B2H2(BH)B4JBLB18-2H2(-H)8-33A31-A31-32B32-
