model
size = 7 20 25, scale = 0.05, origin = -y
material 
  colors = A:#FFFFFB B:#E83015 C:#0F4C3A D:#FFC408
voxels
DCBBBCD ACBBBCA ACBBBCA ACBBBCA ACBBBCA ACBBBCA ACBBBCA ACBBBCA ACBBBCA ACBBBCA ACBBBCA ACBBBCA ACBBBCA ACBBBCA ACBBBCA ACBBBCA DCBBBCD ------- ------- ------- 
ACBBBCA AAAAAAA AAAAAAA AAAAAAA AAAAAAA AAAAAAA AAAAAAA AAAAAAA AAAAAAA AAAAAAA AAAAAAA AAAAAAA AAAAAAA AAAAAAA AAAAAAA AAAAAAA ACBBBCA ------- ------- ------- 
ACBBBCA AAAAAAC AAAAAAC AAAAAAC AAAAAAA AAAAAAA AAAAAAA AAAAAAA AAAAAAA AAAAAAA AAAAAAA AAAAAAA AAAAAAA AAAAAAA AAAAAAA AAAAAAA ACBBBCA ------- ------- ------- 
ACBBBCA AAAAAAC AAAAAAA AAAAAAA AAAAAAA AAAAAAA AAAAAAA AAAAAAA AAAAAAA AAAAAAA AAAAAAA AAAAAAA AAAAAAA AAAAAAA AAAAAAA AAAAAAA ACBBBCA ------- ------- ------- 
ACBBBCA AAAAAAA AAAAAAA AAAAAAA AAAAAAA AAAAAAA AAAAAAA AAAAAAA AAAAAAA AAAAAAA AAAAAAA AAAAAAA AAAAAAA AAAAAAA AAAAAAA AAAAAAA ACBBBCA ------- ------- ------- 
ACBBBCA AAAAAAA AAAAAAB AAAAAAB AAAAAAA AAAAAAA AAAAAAA AAAAAAA AAAAAAA AAAAAAA AAAAAAA AAAAAAA AAAAAAA AAAAAAA AAAAAAA AAAAAAA ACBBBCA ------- ------- ------- 
ACBBBCA AAAAAAB AAAAAAA AAAAAAA AAAAAAA AAAAAAA AAAAAAA AAAAAAA AAAAAAA AAAAAAA AAAAAAA AAAAAAA AAAAAAA AAAAAAA AAAAAAA AAAAAAA ACDDDCA ---D--- ---D--- ---D--- 
ACBBBCA AAAAAAA AAAAAAB AAAAAAB AAAAAAA AAAAAAA AAAAAAA AAAAAAA AAAAAAA AAAAAAA AAAAAAA AAAAAAA AAAAAAA AAAAAAA AAAAAAA AAAAAAA ACBBBCA ------- ------- ---D--- 
ACBBBCA AAAAAAA AAAAAAA AAAAAAA AAAAAAA AAAAAAA AAAAAAA AAAAAAA AAAAAAA AAAAAAA AAAAAAA AAAAAAA AAAAAAA AAAAAAA AAAAAAA AAAAAAA ACBBBCA ------- ------- ---D--- 
ACBBBCA AAAAAAA AAAAAAA AAAAAAA AAAAAAA AAAAAAA AAAAAAA AAAAAAA AAAAAAA AAAAAAA AAAAAAA AAAAAAA AAAAAAA DAAAAAA DAAAAAA AAAAAAA ACBBBCA ------- ------- ---D--- 
ACBBBCA AAAAAAA AAAAAAA AAAAAAA AAAAAAA AAAAAAA AAAAAAA AAAAAAA AAAAAAA AAAAAAA AAAAAAA AAAAAAA AAAAAAA DAAAAAD DAAAAAD AAAAAAA ACBBBCA ------- ------- ---D--- 
ACBBBCA AAAAAAA AAAAAAA AAAAAAA AAAAAAA AAAAAAA AAAAAAA AAAAAAA AAAAAAA AAAAAAA AAAAAAA AAAAAAA AAAAAAA DAAAAAD DAAAAAD AAAAAAA ACBBBCA ------- ------- ---D--- 
ACBBBCA AAAAAAA AAAAAAA AAAAAAA AAAAAAA AAAAAAA AAAAAAA AAAAAAA AAAAAAA AAAAAAA AAAAAAA AAAAAAA AAAAAAA DAAAAAD DAAAAAD AAAAAAA ACBBBCA ------- ------- ---D--- 
ACBBBCA AAAAAAA AAAAAAA AAAAAAA AAAAAAA AAAAAAA AAAAAAA AAAAAAA AAAAAAA AAAAAAA AAAAAAA AAAAAAA AAAAAAA DAAAAAD DAAAAAD AAAAAAA ACBBBCA ------- ------- ---D--- 
ACBBBCA AAAAAAA AAAAAAA AAAAAAA AAAAAAA AAAAAAA AAAAAAA AAAAAAA AAAAAAA AAAAAAA AAAAAAA AAAAAAA AAAAAAA DAAAAAD DAAAAAD AAAAAAA ACBBBCA ------- ------- ---D--- 
ACBBBCA AAAAAAA AAAAAAA AAAAAAA AAAAAAA AAAAAAA AAAAAAA AAAAAAA AAAAAAA AAAAAAA AAAAAAA AAAAAAA AAAAAAA AAAAAAA AAAAAAA AAAAAAA ACBBBCA ------- ------- ---D--- 
ACBBBCA AAAAAAA AAAAAAA AAAAAAA AAAAAAA AAAAAAA AAAAAAA AAAAAAA AAAAAAA AAAAAAA AAAAAAA AAAAAAA AAAAAAA AAAAAAA AAAAAAA AAAAAAA ACBBBCA ------- ------- ---D--- 
ACBBBCA AAAAAAA BAAAAAA BAAAAAA AAAAAAA AAAAAAA AAAAAAA AAAAAAA AAAAAAA AAAAAAA AAAAAAA AAAAAAA AAAAAAA AAAAAAA AAAAAAA AAAAAAA ACDDDCA ---D--- ---D--- ---D--- 
ACBBBCA BAAAAAA AAAAAAA AAAAAAA AAAAAAA AAAAAAA AAAAAAA AAAAAAA AAAAAAA AAAAAAA AAAAAAA AAAAAAA AAAAAAA AAAAAAA AAAAAAA AAAAAAA ACBBBCA ------- ------- ------- 
ACBBBCA AAAAAAA BAAAAAA BAAAAAA AAAAAAA AAAAAAA AAAAAAA AAAAAAA AAAAAAA AAAAAAA AAAAAAA AAAAAAA AAAAAAA AAAAAAA AAAAAAA AAAAAAA ACBBBCA ------- ------- ------- 
ACBBBCA AAAAAAA AAAAAAA AAAAAAA AAAAAAA AAAAAAA AAAAAAA AAAAAAA AAAAAAA AAAAAAA AAAAAAA AAAAAAA AAAAAAA AAAAAAA AAAAAAA AAAAAAA ACBBBCA ------- ------- ------- 
ACBBBCA CAAAAAA AAAAAAA AAAAAAA AAAAAAA AAAAAAA AAAAAAA AAAAAAA AAAAAAA AAAAAAA AAAAAAA AAAAAAA AAAAAAA AAAAAAA AAAAAAA AAAAAAA ACBBBCA ------- ------- ------- 
ACBBBCA CAAAAAA CAAAAAA CAAAAAA AAAAAAA AAAAAAA AAAAAAA AAAAAAA AAAAAAA AAAAAAA AAAAAAA AAAAAAA AAAAAAA AAAAAAA AAAAAAA AAAAAAA ACBBBCA ------- ------- ------- 
ACBBBCA AAAAAAA AAAAAAA AAAAAAA AAAAAAA AAAAAAA AAAAAAA AAAAAAA AAAAAAA AAAAAAA AAAAAAA AAAAAAA AAAAAAA AAAAAAA AAAAAAA AAAAAAA ACBBBCA ------- ------- ------- 
DCBBBCD ACBBBCA ACBBBCA ACBBBCA ACBBBCA ACBBBCA ACBBBCA ACBBBCA ACBBBCA ACBBBCA ACBBBCA ACBBBCA ACBBBCA ACBBBCA ACBBBCA ACBBBCA DCBBBCD ------- ------- ------- 
