model
size = 28 28 14, scale = 0.05, origin = -y
material 
  colors = A:#111
voxels
-----A---------------------- ---------------------------- ---------------------------- ---------------------------- ---------------------------- ---------------------------- ---------------------------- ---------------------------- ---------------------------- ---------------------------- ---------------------------- ---------------------------- ---------------------------- ---------------------------- ---------------------------- ---------------------------- ---------------------------- ---------------------------- ---------------------------- ---------------------------- ---------------------------- ---------------------------- ---------------------------- ---------------------------- ---------------------------- ---------------------------- ---------------------------- ---------------------------- 
---------------------------- ----A----------------------- ----A----------------------- ---------------------------- ---------------------------- ---------------------------- ---------------------------- ---------------------------- ---------------------------- ---------------------------- ---------------------------- ---------------------------- ---------------------------- ---------------------------- ---------------------------- ---------------------------- ---------------------------- ---------------------------- ---------------------------- ---------------------------- ---------------------------- ---------------------------- ---------------------------- ---------------------------- ---------------------------- ---------------------------- ---------------------------- ---------------------------- 
---------------------------- ---------------------------- ---------------------------- ---AA----------------------- --AA------------------------ --A------------------------- ---------------------------- ---------------------------- ---------------------------- ---------------------------- ---------------------------- ---------------------------- ---------------------------- ---------------------------- ---------------------------- ---------------------------- ---------------------------- ---------------------------- ---------------------------- ---------------------------- ---------------------------- ---------------------------- ---------------------------- ---------------------------- ---------------------------- -----------A---------------- ------------A--A------------ -------------AA------------- 
---------------------------- ---------------------------- ---------------------------- ---------------------------- --AA------------------------ --A------------------------- -AA------------------------- --A------------------------- -A-------------------------- ---------------------------- ---------------------------- ---------------------------- ---------------------------- ---------------------------- ---------------------------- ---------------------------- ---------------------------- ---------------------------- ---------------------------- ---------------------------- ---------------------------- ---------------------------- ---------------------------- ---------------------------- ----------A-----A----------- -----------A----A----------- ------------AAAA------------ ------------AAA------------- 
---------------------------- ----A----------------------- ---------------------------- ---------------------------- ---------------------------- -AAA------------------------ -AA------------------------- -AA------------------------- -AA------------------------- -AA------------------------- -A-------------------------- --A------------------------- ---------------------------- ---------------------------- ---------------------------- ---------------------------- ---------------------------- ---------------------------- ---------------------------- ---------------------------- ---------------------------- ---------------------------- -----------------A---------- ---------A-------A---------- ----------A-----A----------- ----------AAA--AA----------- -----------AAAAA------------ -------------AA------------- 
---------------------------- ---------------------------- ----A----------------------- ----A----------------------- ---------------------------- ---A------------------------ -AAA------------------------ -AA------------------------- AAA------------------------- AAAA------------------------ -AA------------------------- -AA------------------------- --A------------------------- --A------------------------A ---A-----------------------A ---A-----------------------A ----A----------------------- ---------------------------- --------------------A------- --------------------A------- ------------------AA-------- -----------------AA--------- -----------------A---------- --------AA-----AAA---------- ---------AAA----A----------- ----------AAAA-AA----------- -----------AAAAA------------ ------------AAA------------- 
---------------------------- ---------------------------- ---------------------------- ----A----------------------- ---AA----------------------- ---A------------------------ --AA------------------------ --A------------------------- -AA------------------------- AAA------------------------- AAAA------------------------ AAAA------------------------ -AA-----------------------AA --AA-----------------------A --AAA---------------------AA ---AA---------------------A- ---AA------------------A-AA- ----A----------------AAA---- -----A-------------AAA------ -----------------AAAA------- ------A----------AAA-------- ----------------AAA--------- -------A-------AAA---------- --------AA-----AAA---------- ---------AAA--AAA----------- -----------AAAAAA----------- ------------AAAA------------ ---------------------------- 
---------------------------- ---------------------------- ----A----------------------- ---------------------------- ---AA----------------------- -A-AA----------------------- -A-A------------------------ -A-A------------------------ -AAA------------------------ AAAA------------------------ AAAA------------------------ AAAA---------------------AA- -AAA---------------------AAA -AAAA---------------------AA --AAA--------------------AA- --AAAA------------------AAA- ---AAA---------------AAAAA-- ---AAA--------------AAAA---- ----AA------------AAAA------ -----AA----------AAAA------- ------A---------AAA--------- ------AA-------AAA---------- -------AAA--AAAAAA---------- --------AAAAAAAAA----------- ----------AAAAAA------------ -----------AAAAA------------ -------------AA------------- ---------------------------- 
---------------------------- ---------------------------- ---------------------------- ----A----------------------- ----A----------------------- ----A----------------------- ---AA----------------------- -AAA------------------------ -AAA------------------------ -AAA------------------------ AAAA------------------------ AAAA---------------------A-- -AAA--------------------AA-- --AA-------------A---A-AAAA- --AA------------A-A-A-AAAAA- --AAAA----------A-AAAAAAAA-- ---AAA---------A-AAAAAAAA--- ---AAAA------A--AAAAAA------ ---AAAA-------A-AAAAAA------ ----AAA--A-A-AAAAAAA-------- -----AAA----AAAAAA---------- ------AAA-AAAAAA------------ -------AAAAAAAA------------- ---------AAAAAA------------- ------------A-A------------- ---------------------------- ---------------------------- ---------------------------- 
---------------------------- ---------------------------- ---------------------------- ---------------------------- ----A----------------------- ----A----------------------- ---AAA---------------------- ---AA----------------------- ---AA----------------------- -AAAA----------------------- -AAAA----------A------------ -AAAAA--------A--------AA--- -AAAA----------A-------AA--- --AAA---------AAAAAAAAAAAA-- --AAAA---------AAAAAAAAAA--- --AAAAA-----A-AAAAAAAAAA---- ---AAAA----A-AAAAAAAAAA----- ---AAAA--A--AAAAAAAAAA------ ---AAA--A-A-AAAAAAAAA------- ----AAAA-AAAAAAAAAAA-------- -----AAA-AAAAAAAAA---------- -------AAAAAAAAA------------ ----------AAAAA------------- -----------A---------------- ---------------------------- ---------------------------- ---------------------------- ---------------------------- 
---------------------------- ---------------------------- -----A---------------------- ---------------------------- ---------------------------- ----A----------------------- ----AA---------------------- ----AA---------------------- ---AA---------A------------- --AAA---------AA------------ --AAAA--------AA------------ --AAAA--------AA-----A------ --AAAA--------AAAAA-AAA----- --AAAAA----A-AAAAAAAAAAA---- --AAAAA---AAAAAAAAAAAAAA---- ---AAAAA-AAAAAAAAAAAAA------ ----AAAAAAAAAAAAAAAAAAA----- -----AAAAAAAAAAAAAAAA------- ------AAAAAAAAAA--AAA------- ------AAAAAAA------A-------- -------AAAAA---------------- --------AAAA---------------- ---------------------------- ---------------------------- ---------------------------- ---------------------------- ---------------------------- ---------------------------- 
---------------------------- ---------------------------- ---------------------------- -----A---------------------- -----A---------------------- -----AA--------------------- ----AA---------------------- ----AA-----A---------------- ----A---------A------------- ---AAA-A----AAAA------------ ---AAA---A-A-AAAA----------- ---AAAA---A-AAAAAA-A-------- ---AAAA-A-AAAAAAAAAAAA------ ---AAAA-AAAAAAAAAAAAAA------ ---AAAAAAAAAAAAAAAAAAAA----- ----AAAAAAAAAAAAAAA-AA------ ----AAAAAAAAAAAA--A--------- -----AAAAAAAAAAA--A--------- ------AAAAAAA--------------- -------AAAAAA--------------- ---------------------------- ---------------------------- ---------------------------- ---------------------------- ---------------------------- ---------------------------- ---------------------------- ---------------------------- 
---------------------------- ---------------------------- ---------------------------- ---------------------------- ---------------------------- -----AAA-------------------- -----AAA----A--------------- -----AA----AA--------------- -----AAAA-AAA--------------- ----AAAAAAAAAA-------------- ----AAAAAAAAAA-------------- -----AAAAAAAAA-------------- -----AAAAAAAA--------------- ----AAAAAAAAA--------------- -----AAAAAAAA--------------- -----AAAAAAAA--------------- ------AAAAAAA--------------- ------AAAAAAA--------------- ---------------------------- ---------------------------- ---------------------------- ---------------------------- ---------------------------- ---------------------------- ---------------------------- ---------------------------- ---------------------------- ---------------------------- 
---------------------------- ---------------------------- ---------------------------- -------A-------------------- -------A-A------------------ -------A-A-A---------------- -------AAAAA---------------- ------AAAAAAA--------------- ------AAAAAAA--------------- ------AAAAAAA--------------- ------AAAAAAA--------------- ------AAAAAAA--------------- ------AAAAAAA--------------- ------AAAAAAA--------------- ------AAAAAAA--------------- ------AAAAAAA--------------- ---------------------------- ---------------------------- ---------------------------- ---------------------------- ---------------------------- ---------------------------- ---------------------------- ---------------------------- ---------------------------- ---------------------------- ---------------------------- ---------------------------- 
