model
size = 28 28 14, scale = 0.05, origin = -y
material 
  colors = A:#040404 B:#04052D C:#000F5B
voxels
-----C---------------------- ---------------------------- ---------------------------- ---------------------------- ---------------------------- ---------------------------- ---------------------------- ---------------------------- ---------------------------- ---------------------------- ---------------------------- ---------------------------- ---------------------------- ---------------------------- ---------------------------- ---------------------------- ---------------------------- ---------------------------- ---------------------------- ---------------------------- ---------------------------- ---------------------------- ---------------------------- ---------------------------- ---------------------------- ---------------------------- ---------------------------- ---------------------------- 
---------------------------- ----C----------------------- ----C----------------------- ---------------------------- ---------------------------- ---------------------------- ---------------------------- ---------------------------- ---------------------------- ---------------------------- ---------------------------- ---------------------------- ---------------------------- ---------------------------- ---------------------------- ---------------------------- ---------------------------- ---------------------------- ---------------------------- ---------------------------- ---------------------------- ---------------------------- ---------------------------- ---------------------------- ---------------------------- ---------------------------- ---------------------------- ---------------------------- 
---------------------------- ---------------------------- ---------------------------- ---CC----------------------- --CC------------------------ --C------------------------- ---------------------------- ---------------------------- ---------------------------- ---------------------------- ---------------------------- ---------------------------- ---------------------------- ---------------------------- ---------------------------- ---------------------------- ---------------------------- ---------------------------- ---------------------------- ---------------------------- ---------------------------- ---------------------------- ---------------------------- ---------------------------- ---------------------------- -----------A---------------- ------------A--A------------ -------------AA------------- 
---------------------------- ---------------------------- ---------------------------- ---------------------------- --CC------------------------ --C------------------------- -CC------------------------- --C------------------------- -C-------------------------- ---------------------------- ---------------------------- ---------------------------- ---------------------------- ---------------------------- ---------------------------- ---------------------------- ---------------------------- ---------------------------- ---------------------------- ---------------------------- ---------------------------- ---------------------------- ---------------------------- ---------------------------- ----------A-----A----------- -----------A----A----------- ------------AAAA------------ ------------AAA------------- 
---------------------------- ----C----------------------- ---------------------------- ---------------------------- ---------------------------- -CCC------------------------ -CC------------------------- -CC------------------------- -CC------------------------- -CC------------------------- -C-------------------------- --C------------------------- ---------------------------- ---------------------------- ---------------------------- ---------------------------- ---------------------------- ---------------------------- ---------------------------- ---------------------------- ---------------------------- ---------------------------- -----------------A---------- ---------A-------A---------- ----------A-----A----------- ----------AAA--AA----------- -----------AAAAA------------ -------------AA------------- 
---------------------------- ---------------------------- ----C----------------------- ----C----------------------- ---------------------------- ---C------------------------ -CCC------------------------ -CB------------------------- CBB------------------------- BBBB------------------------ -BB------------------------- -CB------------------------- --B------------------------- --C------------------------A ---B-----------------------A ---B-----------------------A ----B----------------------- ---------------------------- --------------------A------- --------------------A------- ------------------AA-------- -----------------AA--------- -----------------A---------- --------AA-----AAA---------- ---------AAA----A----------- ----------AAAA-AA----------- -----------AAAAA------------ ------------AAA------------- 
---------------------------- ---------------------------- ---------------------------- ----C----------------------- ---CC----------------------- ---C------------------------ --CC------------------------ --B------------------------- -BB------------------------- CBB------------------------- BBBC------------------------ BBBB------------------------ -BB-----------------------AA --BB-----------------------A --BBB---------------------AA ---BB---------------------A- ---BB------------------A-AA- ----B----------------AAA---- -----B-------------AAA------ -----------------AAAA------- ------A----------AAA-------- ----------------AAA--------- -------A-------AAA---------- --------AA-----AAA---------- ---------AAA--AAA----------- -----------AAAAAA----------- ------------AAAA------------ ---------------------------- 
---------------------------- ---------------------------- ----C----------------------- ---------------------------- ---CC----------------------- -C-CC----------------------- -B-C------------------------ -B-B------------------------ -BBC------------------------ BBBB------------------------ CBBB------------------------ BBBB---------------------AA- -BAB---------------------AAA -BABB---------------------AA --ABB--------------------AA- --BBBB------------------AAA- ---AAA---------------AAAAA-- ---AAA--------------AAAA---- ----AA------------AAAA------ -----AA----------AAAA------- ------B---------AAA--------- ------AA-------AAA---------- -------AAA--AAAAAA---------- --------AAAAAAAAA----------- ----------AAAAAA------------ -----------AAAAA------------ -------------AA------------- ---------------------------- 
---------------------------- ---------------------------- ---------------------------- ----C----------------------- ----C----------------------- ----C----------------------- ---CC----------------------- -CBB------------------------ -CBB------------------------ -BBB------------------------ BBBB------------------------ BABB---------------------A-- -AAB--------------------AA-- --AB-------------A---B-AAAA- --AB------------A-B-A-AAAAA- --BBBB----------A-AAAAAAAA-- ---BAA---------A-AAAAAAAA--- ---AAAA------A--AAAAAA------ ---AAAA-------A-AAAAAA------ ----BAA--A-A-AAAAAAA-------- -----AAA----AAAAAA---------- ------AAA-AAAAAA------------ -------AAAAAAAA------------- ---------AAAAAA------------- ------------A-A------------- ---------------------------- ---------------------------- ---------------------------- 
---------------------------- ---------------------------- ---------------------------- ---------------------------- ----C----------------------- ----C----------------------- ---CCC---------------------- ---BC----------------------- ---BB----------------------- -CBBB----------------------- -BBBB----------B------------ -BBBBB--------B--------AA--- -BBBB----------B-------AA--- --ABB---------BAAAAAAAAAAA-- --ABBB---------AAAAAAAAAA--- --ABBBB-----A-AAAAAAAAAA---- ---AAAB----A-AAAAAAAAAA----- ---AAAA--A--AAAAAAAAAA------ ---AAA--A-A-AAAAAAAAA------- ----AAAA-AAAAAAAAAAA-------- -----AAA-AAAAAAAAA---------- -------AAAAAAAAA------------ ----------AAAAA------------- -----------A---------------- ---------------------------- ---------------------------- ---------------------------- ---------------------------- 
---------------------------- ---------------------------- -----C---------------------- ---------------------------- ---------------------------- ----C----------------------- ----CC---------------------- ----CB---------------------- ---BB---------B------------- --BBB---------BA------------ --BBBB--------BA------------ --BABB--------AA-----A------ --BABB--------AAABB-BAA----- --BABBB----A-AAAAAAAAAAA---- --AABBB---BAAAAAAAAAAAAA---- ---AAAAA-AAAAAAAAAAAAA------ ----AAAAAAAAAAAAAAAAAAA----- -----AABAAAAAAAAAAAAA------- ------AAAAAAAAAA--AAA------- ------AAAAAAA------A-------- -------AAAAA---------------- --------AAAA---------------- ---------------------------- ---------------------------- ---------------------------- ---------------------------- ---------------------------- ---------------------------- 
---------------------------- ---------------------------- ---------------------------- -----C---------------------- -----C---------------------- -----CC--------------------- ----BB---------------------- ----BB-----C---------------- ----C---------B------------- ---BBB-B----BBBB------------ ---BBB---B-B-BBBB----------- ---ABBB---B-BAABAB-B-------- ---ABBB-B-BAAABAAABAAA------ ---ABBB-BAAAAAAABAAAAA------ ---ABBBBBAAAAAAAAAAAAAA----- ----AAAAAAAAAAAAAAA-AA------ ----AAAAAAAAAAAA--A--------- -----AAAAAAAAAAA--A--------- ------AAAAAAA--------------- -------AAAAAA--------------- ---------------------------- ---------------------------- ---------------------------- ---------------------------- ---------------------------- ---------------------------- ---------------------------- ---------------------------- 
---------------------------- ---------------------------- ---------------------------- ---------------------------- ---------------------------- -----BCB-------------------- -----CBC----B--------------- -----BC----BB--------------- -----BBBB-BBB--------------- ----ABBBBBBBBB-------------- ----ABBBBAAABA-------------- -----ABBABBAAA-------------- -----ABBABBAA--------------- ----AAAAAAAAA--------------- -----AAAAAAAA--------------- -----AAAAAAAA--------------- ------AAAAAAA--------------- ------AAAAAAA--------------- ---------------------------- ---------------------------- ---------------------------- ---------------------------- ---------------------------- ---------------------------- ---------------------------- ---------------------------- ---------------------------- ---------------------------- 
---------------------------- ---------------------------- ---------------------------- -------C-------------------- -------C-C------------------ -------B-C-B---------------- -------BBBCB---------------- ------CBBCBBB--------------- ------BBABBBB--------------- ------BBABBBB--------------- ------BAABBBB--------------- ------BAAABBB--------------- ------ABAABBA--------------- ------BAAAABA--------------- ------AAAAAAA--------------- ------AAAABAA--------------- ---------------------------- ---------------------------- ---------------------------- ---------------------------- ---------------------------- ---------------------------- ---------------------------- ---------------------------- ---------------------------- ---------------------------- ---------------------------- ---------------------------- 
