model
size = 23 30 29, scale = 0.05, origin = -y
material 
  colors = A:#111 B:#E83015 C:#444 D:#C62020 E:#888 F:#777 G:#EEE
voxels
----------------------- ----------------------- ----------------------- ----------------------- ----------------------- ----------------------- ----------------------- ----------------------- ----------------------- ----------------------- ----------------------- ----------------------- ----------------------- ----------------------- ----------------------- ----------------------- ----------------------- ----------------------- -------BBBBBBBBB------- -------BBBBBBBBB------- ----------------------- ----------------------- ----------------------- ----------------------- ----------------------- ----------------------- ----------------------- ----------------------- ----------------------- ----------------------- 
----------------------- ----------------------- ----------------------- ----------------------- ----------------------- ----------------------- ----------------------- ----------------------- ----------------------- ----------------------- ----------------------- ----------------------- ----------------------- ----------------------- ----------------------- ----------------------- ----------------------- ----------------------- ------BBEFFFFFEBB------ ------BBBDDDDDBBB------ ----------------------- ----------------------- ----------------------- ----------------------- ----------------------- ----------------------- ----------------------- ----------------------- ----------------------- ----------------------- 
----------------------- ----------------------- ----------------------- ----------------------- ----------------------- ----------------------- ----------------------- ----------------------- ----------------------- ----------------------- ----------------------- ----------------------- ----------------------- ----------------------- ----------------------- ----------------------- ----------------------- ----------------------- -----BEEFEEEEEFEEB----- -----BBBDBBBBBDBBB----- ----------------------- ----------------------- ----------------------- ----------------------- ----------------------- ----------------------- ----------------------- ----------------------- ----------------------- ----------------------- 
----------------------- ----------------------- ----------------------- ----------------------- ----------------------- ----------------------- ----------------------- ----------------------- ----------------------- ----------------------- ----------------------- ----------------------- ----------------------- ----------------------- ----------------------- ----------------------- ----------------------- ----------------------- ----BEEFEFFFFFEFEEB---- ----BBBDBDDDDDBDBBB---- ----------------------- ----------------------- ----------------------- ----------------------- ----------------------- ----------------------- ----------------------- ----------------------- ----------------------- ----------------------- 
----------------------- ----------------------- ----------------------- ----------------------- ----------------------- ----------------------- ----------------------- ----------------------- ----------------------- ----------------------- ----------------------- ----------------------- ----------------------- ----------------------- ----------------------- ----------------------- ----------------------- ----------------------- ---BEEFEFEEEEEFEFEEB--- ---BBBDBDBBBBBDBDBBB--- ----------------------- ----------------------- ----------------------- ----------------------- ----------------------- ----------------------- ----------------------- ----------------------- ----------------------- ----------------------- 
----------------------- ----------------------- ----------------------- ----------------------- ----------------------- ----------------------- ----------------------- ----------------------- ----------------------- ----------------------- ----------------------- ----------------------- ----------------------- ----------------------- ----------------------- ----------------------- ----------------------- ----------------------- ---BEFEFEFFFFFEFEFEB--- ---BBDBDBDDDDDBDBDBB--- ----------------------- ----------------------- ----------------------- ----------------------- ----------------------- ----------------------- ----------------------- ----------------------- ----------------------- ----------------------- 
----------------------- ----------------------- ----------------------- ----------------------- ----------------------- ----------------------- ----------------------- ----------------------- ----------------------- ----------------------- ----------------------- ----------------------- ----------------------- ----------------------- ----------------------- ----------------------- ----------------------- ----------------------- --BEFEFEFEEEEEFEFEFEB-- --BBDBDBDBBBBBDBDBDBB-- ----------------------- ----------------------- ----------------------- ----------------------- ----------------------- ----------------------- ----------------------- ----------------------- ----------------------- ----------------------- 
----------------------- ----------------------- ----------------------- ----------------------- ----------------------- ----------------------- ----------------------- ----------------------- ----------------------- ----------------------- ----------------------- ----------------------- ----------------------- ----------------------- ----------------------- ----------------------- ----------------------- ----------------------- --BFEFEFEEFFFEEFEFEFB-- --BDBDBDBBBBBBBDBDBDB-- ----------G-G---------- ---------GGGGG--------- ----------G-G---------- ---------GGGGG--------- ----------G-G---------- ----------------------- ----------------------- ----------------------- ----------------------- ----------------------- 
----------------------- ----------------------- ----------------------- ----------------------- ----------------------- ----------------------- ----------------------- ----------------------- ----------------------- ----------------------- ----------------------- ----------------------- ----------------------- ----------------------- ----------------------- ----------------------- ----------------------- ----------------------- --BFEFEFEFEEEFEFEFEFB-- --BDBDBAAAAAAAAABDBDB-- ------AAAAAAAAAAA------ ------AAAAAAAAAAA------ ------AAAAAAAAAAA------ ------AAAAAAAAAAA------ -------AAAAAAAAA------- -------AAAAAAAAA------- ----------------------- ----------------------- ----------------------- ----------------------- 
----------------------- ----------------------- ----------------------- ----------------------- ----------------------- ----------------------- ----------------------- ----------------------- ----------------------- ----------------------- ----------------------- ----------------------- ----------------------- ----------------------- ----------------------- ----------------------- ----------------------- ----------------------- --BFEFECCCCCCCCCEFEFB-- --BDAAACCCCCCCCCAAADB-- ----AAA----C----AAA---- ----AAA----C----AAA---- -----AA----C----AA----- -----AA----C----AA----- -----AA----C----AA----- ------AAAAAAAAAAA------ --------AAAAAAA-------- ----------------------- ----------------------- ----------------------- 
----------------------- ----------------------- ----------------------- ----------------------- ----------------------- ----------------------- ----------------------- ----------------------- ----------------------- ----------------------- ----------------------- ----------------------- ----------------------- ----------------------- ----------------------- ----------------------- ----------------------- ----------------------- --BFECC---------CCEFB-- --BAACC---------CCAAB-- ---AAA-----------AAA--- ---AAA-----------AAA--- ----AA-----------AA---- -----A-----------A----- -----AA---------AA----- ------AAAAACAAAAA------ -------AAAAAAAAA------- ----------------------- ----------------------- ----------------------- 
----------------------- ----------------------- ----------------------- ----------------------- ----------------------- ----------------------- ----------------------- ----------------------- ----------------------- ----------------------- ----------------------- ----------------------- ----------------------- --A-----------------A-- --A-----------------A-- --A-----------------A-- --A-----------------A-- --A-----------------A-- --ACCC-----------CCCA-- --AACC-----------CCAA-- --AAAC-----------CAAA-- --AAAC-----------CAAA-- ---AAC-----------CAA--- ----AC-----------CA---- -----AA---------AA----- -----AA---------AA----- -------AAAACAAAA------- ----------AAA---------- ----------------------- ----------------------- 
----------------------- ----------------------- ----------------------- ----------------------- ----------------------- ----------------------- ----------------------- ----------------------- ----------------------- --A-----------------A-- --A-----------------A-- --A-----------------A-- --A-----------------A-- --A-----------------A-- --A-----------------A-- --A-----------------A-- --A-----------------A-- --A-----------------A-- --AC---------------CA-- --AC---------------CA-- --A-----------------A-- --A-----------------A-- --AA---------------AA-- ---A---------------A--- ----AAC---------CAA---- ----AAC---------CAA---- ------AAAAACAAAAA------ --------AAAAAAA-------- ----------------------- ----------------------- 
----------------------- ----------------------- ----------------------- ----------------------- ----------------------- ----------------------- ----------------------- ----------------------- -AA-----------------AA- -AD-----------------DA- -AB-----------------BA- -AB-----------------BA- -AB-----------------BA- -AD-----------------DA- -AB-----------------BA- -AB-----------------BA- -AB-----------------BA- -AD-----------------DA- -AAC---------------CAA- -AAC---------------CAA- -AA-----------------AA- -AA-----------------AA- --AA---------------AA-- --AA---------------AA-- ---A---------------A--- ---AAA-----------AAA--- -----AACAAACAAACAA----- -------AAAAAAAAA------- ----------------------- ----------------------- 
----------------------- ----------------------- ----------------------- ----------------------- ----------------------- ----------------------- ----------------------- AA--------------------- AD-------------------AA AB-------------------BA AD-------------------DA AB-------------------BA AD-------------------DA AB-------------------BA AD-------------------BA AB-------------------BA AD-------------------DA AB-------------------BA AAC-----------------CAA -AC-----------------CA- -A-------------------A- -A-------------------A- --A-----------------A-- --A-----------------A-- ---A---------------A--- ---AAA-----------AAA--- -----AAAC-----CAAA----- -------AAAACAAAA------- ----------AAA---------- ----------------------- 
----------------------- ----------------------- ----------------------- ----------------------- ----------------------- ----------------------- ----------------------- AA-------------------AA AB-------------------BA AB-------------------BA AB-------------------BA AD-------------------DA AB-------------------BA AB-------------------BA AB-------------------BA AD-------------------DA AB-------------------BA AB-------------------BA AAC-----------------CAA AAC-----------------CAA AA-------------------AA -A-------------------A- -AA-----------------AA- --A-----------------A-- --AA---------------AA-- ---AAA-----------AAA--- ----AAAA-------AAAA---- ------AAACACACAAA------ ---------AAAAA--------- ----------------------- 
----------------------- ----------------------- ----------------------- ----------------------- ----------------------- ----------------------- A---------------------A AA-------------------AA AD-------------------DA AB-------------------BA AD-------------------DA AB-------------------BA AD-------------------DA AB-------------------BA AD-------------------DA AB-------------------BA AD-------------------BA AB-------------------BA AC-------------------CA AC-------------------CA AA-------------------AA AA-------------------AA -AA-----------------AA- -AA-----------------AA- --AA---------------AA-- --AAAA-----------AAAA-- ----AAAA-------AAAA---- ------AAAACCCAAAA------ --------AAAAAAA-------- ----------BBB---------- 
B---------------------B B---------------------B B---------------------B B---------------------B B---------------------B B---------------------B B---------------------B BA-------------------AB AB-------------------BA AD-------------------DA AB-------------------BA AB-------------------BA AB-------------------BA AD-------------------DA AB-------------------BA AB-------------------BA AB-------------------BA AD-------------------DA AC-------------------CA AC-------------------CA AC-------------------CA AC-------------------CA -AC-----------------CA- -AC-----------------CA- --AC---------------CA-- --AACC-----------CCAA-- ----AACC-------CCAA---- ------AACCCCCCCAA------ --------AAABAAA-------- ----------BBB---------- 
B---------------------B B---------------------B B---------------------B B---------------------B B---------------------B B---------------------B B---------------------B BA-------------------AB AD-------------------DA AB-------------------BA AD-------------------DA AB-------------------BA AD-------------------DA AB-------------------BA AD-------------------DA AB-------------------BA AD-------------------DA AB-------------------BA AC-------------------CA AC-------------------CA AA-------------------AA AA-------------------AA -AA-----------------AA- -AA-----------------AA- --AA---------------AA-- --AAAA-----------AAAA-- ----AAAA-------AAAA---- ------AAAACCCAAAA------ --------AAAAAAA-------- ----------BBB---------- 
----------------------- ----------------------- ----------------------- ----------------------- ----------------------- ----------------------- A---------------------A AA-------------------AA AB-------------------BA AB-------------------BA AB-------------------BA AD-------------------DA AB-------------------BA AB-------------------BA AB-------------------BA AD-------------------DA AB-------------------BA AB-------------------BA AC-------------------CA AC-------------------CA AA-------------------AA AA-------------------AA -AA-----------------AA- -AA-----------------AA- --AA---------------AA-- --AAAA-----------AAAA-- ----AAAAAC---CAAAAA---- ------AAACACACAAA------ ---------AAAAA--------- ----------------------- 
----------------------- ----------------------- ----------------------- ----------------------- ----------------------- ----------------------- ----------------------- AA-------------------AA AD-------------------DA AB-------------------BA AD-------------------DA AB-------------------BA AD-------------------DA AB-------------------BA AD-------------------DA AB-------------------BA AD-------------------DA AB-------------------BA AC-------------------CA AC-------------------CA AA-------------------AA -A-------------------A- -AA-----------------AA- --A-----------------A-- --AA---------------AA-- ---AAA-----------AAA--- -----AAACA---ACAAA----- -------AAAACAAAA------- ----------AAA---------- ----------------------- 
----------------------- ----------------------- ----------------------- ----------------------- ----------------------- ----------------------- ----------------------- ----------------------- AA-------------------AA AD-------------------DA AB-------------------BA AB-------------------BA AB-------------------BA AD-------------------DA AB-------------------BA AB-------------------BA AB-------------------BA AD-------------------DA AAC-----------------CAA AAC-----------------CAA -A-------------------A- -A-------------------A- --A-----------------A-- --A-----------------A-- ---A---------------A--- ---AAAAC-------CAAAA--- -----AAAAAACAAACAA----- -------AAAAAAAAA------- ----------------------- ----------------------- 
----------------------- ----------------------- ----------------------- ----------------------- ----------------------- ----------------------- ----------------------- ----------------------- -A-------------------A- -AB-----------------BA- -AD-----------------DA- -AB-----------------BA- -AD-----------------DA- -AB-----------------BA- -AD-----------------DA- -AB-----------------BA- -AD-----------------DA- -AB-----------------BA- -AC-----------------CA- -AC-----------------CA- -A-------------------A- -A-------------------A- --A-----------------A-- --A-----------------A-- ---AAAC---------CAAA--- ---AAACA-------ACAAA--- -----AAAAAACAAAAAA----- -------AAAAAAAAA------- ----------------------- ----------------------- 
----------------------- ----------------------- ----------------------- ----------------------- ----------------------- ----------------------- ----------------------- ----------------------- --A-----------------AA- -AD-----------------BA- -AB-----------------BA- -AD-----------------DA- -AB-----------------BA- -AB-----------------BA- -AB-----------------BA- -AD-----------------DA- -AB-----------------BA- -AB-----------------BA- -AAC---------------CAA- -AAC---------------CAA- -AA-----------------AA- --A-----------------A-- --A-----------------A-- ---AAC-----------CAA--- ---AACA---------ACAA--- ----AAAA-------AAAA---- ------AAAAACAAAAA------ ---------AAAAA--------- ----------------------- ----------------------- 
----------------------- ----------------------- ----------------------- ----------------------- ----------------------- ----------------------- ----------------------- ----------------------- --A-----------------A-- --A-----------------A-- --A-----------------A-- --AB----------------A-- --AD---------------DA-- --AB---------------BA-- --AD---------------DA-- --AB---------------BA-- --AD---------------DA-- --AB---------------BA-- --ACC-------------CCA-- --ACC-------------CCA-- --AAC-------------CAA-- --AAC-------------CAA-- ---AC-------------CA--- ---ACA-----------ACA--- ----AAA---------AAA---- -----AAAAAACAAAAAA----- -------AAAAAAAAA------- ----------------------- ----------------------- ----------------------- 
----------------------- ----------------------- ----------------------- ----------------------- ----------------------- ----------------------- ----------------------- ----------------------- ----------------------- --A-----------------A-- --AA---------------AA-- --AD---------------AA-- --AB---------------BA-- --AD---------------DA-- --AB---------------BA-- --AB---------------BA-- --AB---------------BA-- --AD---------------DA-- --AAC-------------CAA-- --AAC-------------CAA-- --AAA-------------AAA-- ---AA-------------AA--- ----A-------------A---- ----AA-----------AA---- -----AA---------AA----- -------AAAACAAAA------- ---------AAAAA--------- ----------------------- ----------------------- ----------------------- 
----------------------- ----------------------- ----------------------- ----------------------- ----------------------- ----------------------- ----------------------- ----------------------- ----------------------- ----------------------- ---AA-------------AA--- ---AA-------------AA--- ---AD-------------AA--- ---AB-------------BA--- ---AD-------------DA--- ---ABD-----------DBA--- ---ADB-----------BDA--- ---ABB-----------BBA--- ---AACC---------CCAA--- ---AACC---------CCAA--- ---AAA-----------AAA--- ----AA-----------AA---- -----A-----------A----- -----A-----------A----- ------AAAAACAAAAA------ ---------AAAAA--------- ----------------------- ----------------------- ----------------------- ----------------------- 
----------------------- ----------------------- ----------------------- ----------------------- ----------------------- ----------------------- ----------------------- ----------------------- ----------------------- ----------------------- ----------------------- ----A-------------A---- ----AA-----------AA---- ----AAA---------AAA---- ----AAAAAAAAAAAAAAA---- ----AABBBDBBBDBBBAA---- ----AADBDBDBDBDBDAA---- ----AABDBBBDBBBDBAA---- ----AAACCCCCCCCCAAA---- ----AAACCCCCCCCCAAA---- ----AAAAAAACAAAAAAA---- -----AAAAAACAAAAAA----- ------AAAAACAAAAA------ ------AAAAACAAAAA------ ---------AAAAA--------- ----------------------- ----------------------- ----------------------- ----------------------- ----------------------- 
----------------------- ----------------------- ----------------------- ----------------------- ----------------------- ----------------------- ----------------------- ----------------------- ----------------------- ----------------------- ----------------------- ----------------------- ----------------------- ----------------------- -------AAAAAAAAA------- ------AAAAAAAAAAA------ ------AAAAAAAAAAA------ ------AAAAAAAAAAA------ ------AAAAAAAAAAA------ ------AAAAAAAAAAA------ ------AAAAAAAAAAA------ -------AAAAAAAAA------- --------AAAAAAA-------- ---------AAAAA--------- ----------------------- ----------------------- ----------------------- ----------------------- ----------------------- ----------------------- 
