model
size = 28 28 9, scale = 0.05, origin = -y
material 
  colors = A:#222 B:#777 C:#444 D:#30C E:#111 F:#E00 G:#EEE H:#39C
voxels
---------------------------- ---------------------------- ------AA-------------------- -----AAA-------------AA----- -----AAA-------------AAA---- ----AAAA-------------AAA---- ----AAAA-------------AAA---- ----AAA--------------AAA---- ----AAA--------------AAA---- ---AAAA--------------AAAA--- ---AAAA--------------AAAA--- -----AA---------------AA---- ---------------------------- ---------------------------- ---------------------------- ---------------------------- ---------------------------- ---------------------------- ---------------------------- ---------------------------- ---------------------------- ---------------------------- ---------------------------- ---------------------------- ---------------------------- ---------------------------- ---------------------------- ---------------------------- 
---------------------------- ------CC-------------------- -----CCCA-----------ACC----- ----CCCAA-----------ACCCC--- ----CCAAA-----------ACCCC--- ---CCAAAA-----------ACCCC--- ---CCAAAA-----------ACCCC--- ---CCAAA------------ACCCC--- ---CCAAA------------ACCCCC-- --CCCAAA------------ACCCCC-- -CCCCAAA-------------CCCCC-- --CCCCAA-------------CCCC--- -----CC--------------CCC---- ---------------------------- ---------------------------- ---------------------------- ---------------------------- ---------------------------- ---------------------------- ---------------------------- ---------------------------- ---------------------------- ---------------------------- ---------------------------- ---------------------------- ---------------------------- ---------------------------- ---------------------------- 
---------------------------- -----EEEEB---------BBBB----- ---BBEEE-------------EBBB--- ---BBEE---------------EBBB-- --BBBE-----------------EBB-- --BBE------------------EBB-- --BBE------------------EBB-- --BBE------------------EBBB- HBBBE------------------EBBBH HBBBE------------------EBBB- BBBBE-----------------EEBBB- -BBBBE----------------BBB--- -BBBBBB-------------BBBBB--- ----BBBB-------------BBBB--- ---------------------------- ---------------------------- ---------------------------- -GG-----------------------G- ---------------------------- ---------------------------- ---------------------------- ---------------------------- ---------------------------- ---------------------------- ---------------------------- ---------------------------- ---------------------------- ---------------------------- 
-------G-------------G------ -----EEEEA---------AAAA----- ---AAEEE-------------EAAA--- ---AAEE---------------EAAA-- --AAAE-----------------EAA-- --AAE------------------EAA-- --AAE------------------EAAA- --AAE------------------EAAA- HAAAE------------------EAAAH HAAAE------------------EAAAH AAAAE-----------------EEAAAA -AAAAE----------------AAA--A -AAAAAA-------------AAAAA-AA -AA-AAAA-------------AAA--AA -A------------------------AA -A------------------------AA -A------------------------AA GAAG---------------------GAG -AA----------------------AA- -AAA---------------------AA- --AA--------------------AAA- --AAA------------------AAA-- ---AAA----------------AAA--- ----AAAAAA--------AAAAAA---- -----AAAAAAAAAAAAAAAAAA----- -------AAAAAAAAAAAAAAA------ ---------AAAAAAAAAAA-------- ------------AAAA------------ 
-------G-------------G------ -----EEEED---------DDFD----- ---DDEEE-------------EFDD--- ---DFEE---------------EFFD-- --DFFE-----------------EFD-- --DFE------------------EFD-- --DFE------------------EFFD- --DFE------------------EFFD- HDFFE------------------EFFDH HDFFE------------------EFFFH DFFFE-----------------EEFDDD -DFFFE----------------DFD--D -DFDFFD-------------DDFFD-DD -DD-DDDD-------------DDD--DD -D------------------------DD -D------------------------DD -D------------------------DD GDDG---------------------GDG -DD----------------------DD- -DDD---------------------DD- --DD--------------------DDD- --DDD------------------DDD-- ---DDD----------------DDD--- ----DDDDDD--------DDDDDD---- -----DDDDDDDDGGDDDDDDDD----- -------DDDDDDGGDDDDDDD------ ---------DDDDGGDDDDD-------- ------------DHHD------------ 
---------------------------- -----EEEEB---------BBBB----- ---BBEEE-------------EBBB--- ---BBEE---------------EBBB-- --BBBE----------------EEBB-- --BBE-----------------EEBB-- --BBE-----------------EEBBB- --BBE-----------------EEBBB- HBBBE-----------------EEBBBH HBBBE-----------------EEBBBH BBBBE-----------------EEBBBB -BBBBE----------------BBB--- -BBBBBB-------------BBBBB--- -BBBBBBB-------------BBB---- ---------------------------- ---------------------------- ---------------------------- -GG-----------------------G- ---------------------------- ---------------------------- ---------------------------- ---------------------------- ---------------------------- ---------------------------- ---------------------------- ---------------------------- ---------------------------- ---------------------------- 
---------------------------- -------C-------------------- ------CCA-----------AC------ ----CCCAA-----------AACCC--- ----CCAAA-----------AACCC--- ---CCAAAA-----------AACCC--- ---CCAAAA-----------AACCC--- ---CCAAA------------AACCCC-- ---CCAAA------------AACCCC-- --CCCAAA------------AACCCCC- --CCCAAA-------------ACCCC-- --CCCCAA-------------ACC---- --CCCCC--------------CCC---- ---------------------------- ---------------------------- ---------------------------- ---------------------------- ---------------------------- ---------------------------- ---------------------------- ---------------------------- ---------------------------- ---------------------------- ---------------------------- ---------------------------- ---------------------------- ---------------------------- ---------------------------- 
---------------------------- ---------------------------- -------A-------------------- ------AA------------A------- -----AAA------------AAAA---- ----AAAA------------AAAA---- ----AAAA-------------AAA---- ----AAA--------------AAA---- ----AAA--------------AAAA--- ----AAA--------------AAAA--- ---AAAA---------------A----- ---AAAA---------------A----- ---------------------------- ---------------------------- ---------------------------- ---------------------------- ---------------------------- ---------------------------- ---------------------------- ---------------------------- ---------------------------- ---------------------------- ---------------------------- ---------------------------- ---------------------------- ---------------------------- ---------------------------- ---------------------------- 
---------------------------- ---------------------------- ---------------------------- ---------------------------- ---------------------------- ---------------------AA----- ---------------------AA----- ---------------------AA----- ---------------------AA----- ---------------------AA----- ---------------------------- ---------------------------- ---------------------------- ---------------------------- ---------------------------- ---------------------------- ---------------------------- ---------------------------- ---------------------------- ---------------------------- ---------------------------- ---------------------------- ---------------------------- ---------------------------- ---------------------------- ---------------------------- ---------------------------- ---------------------------- 
