model
size = 7 29 14, scale = 0.05, origin = -y
material 
  colors = A:#E00 B:#DDD C:#100 D:#500 E:#400 F:#002 G:#020
voxels
------- ------- ------- ------- ------- ------- ------- ------- ------- ------- ------- ------- ------- A------ A------ AA----- FD----- FC----- CC----- CC----- CA----- AA----- EA----- FA----- DE----- ------- ------- ------- ------- 
------- ------- ------- ------- ------- ------- -CA---- -DA---- -FC---- -BC---- -DA---- -AA---- -AE---- -AE---- -DA---- -FA---- -FA---- -CC---- -CC---- -FA---- -CA---- -CF---- -DF---- -BA---- -BA---- -AA---- ------- ------- ------- 
------- ------- ------- ------- --EF--- --BE--- --DD--- --DA--- --FA--- --AA--- --BE--- --AE--- --AE--- --DE--- --DE--- --DE--- --CB--- --CA--- --BA--- --CA--- --CC--- --BC--- --BC--- --BF--- --CA--- --FA--- -DDA--- ------- ------- 
------- ------- ------- ---D--- ---D--- ---DE-- ---DA-- ---DA-- ---AA-- ---AA-- ---BA-- ---BE-- ---DE-- ---DE-- ---CA-- ---CB-- ---CA-- ---CA-- ---CA-- ---BA-- ---BB-- ---BA-- ---CA-- ---CA-- ---A--- --BA--- -BBD--- CCFE--- --CC--- 
------- ------- ------- ----A-- ----A-- ----A-- ----A-- ----A-- ----A-- ----A-- ----A-- ----B-- ----B-- ----A-- ----E-- ----B-- ----A-- ----B-- ----B-- ----B-- ----D-- ----F-- ----A-- ----C-- ---CA-- --DBA-- -BBBA-- -FBGA-- ---A--- 
------- ------- -----A- -----A- -----A- -----A- -----A- -----A- -----E- -----E- -----A- -----A- -----B- -----B- -----A- -----A- -----B- -----B- -----E- -----B- -----A- -----E- -----A- ----FA- ---CBA- --CBBD- --BBBA- --FGC-- ---FE-- 
-----A- -----A- -----A- -----A- -----CA -----AC -----CE -----DE -----DE -----AA -----AA -----BD -----BA -----BB -----BB -----BA -----BD -----DD -----DD -----DB -----DA -----DA -----BE ----DBA ---FCCA --CCDBA --CCCC- --BDBA- ----E-- 
-----A- -----A- -----A- -----A- -----CA -----AC -----CE -----DE -----DE -----AA -----AA -----BD -----BA -----BB -----BB -----BA -----BD -----DD -----DD -----DB -----DA -----DA -----BE ----DBA ---FCCA --CCDBA --CCCC- --BDBA- ----E-- 
------- ------- -----A- -----A- -----A- -----A- -----A- -----A- -----E- -----E- -----A- -----A- -----B- -----B- -----A- -----B- -----B- -----B- -----E- -----B- -----A- -----E- -----A- ----FA- ---CBA- --CBBD- --BBBA- --FGC-- ---FE-- 
------- ------- ------- ----A-- ----A-- ----A-- ----A-- ----A-- ----A-- ----A-- ----A-- ----B-- ----B-- ----A-- ----E-- ----B-- ----A-- ----B-- ----B-- ----B-- ----D-- ----F-- ----A-- ----C-- ---CA-- --DBA-- -BBBA-- -FBGA-- ---A--- 
------- ------- ------- ---D--- ---D--- ---DE-- ---DA-- ---DA-- ---AA-- ---AA-- ---BA-- ---BE-- ---DE-- ---DE-- ---CA-- ---CB-- ---CA-- ---CA-- ---CA-- ---BA-- ---BB-- ---BA-- ---CA-- ---CA-- ---A--- --BA--- -BBD--- CCFE--- --CC--- 
------- ------- ------- ------- --EF--- --BE--- --DD--- --DA--- --FA--- --AA--- --BE--- --AE--- --AE--- --DE--- --DE--- --DE--- --CB--- --CA--- --BA--- --CA--- --CC--- --BC--- --BC--- --BF--- --CA--- --FA--- -DDA--- ------- ------- 
------- ------- ------- ------- ------- ------- -CA---- -DA---- -FC---- -BC---- -DA---- -AA---- -AE---- -AE---- -DA---- -FA---- -FA---- -CC---- -CC---- -FA---- -CA---- -CF---- -DF---- -BA---- -BA---- -AA---- ------- ------- ------- 
------- ------- ------- ------- ------- ------- ------- ------- ------- ------- ------- ------- ------- A------ A------ AA----- FD----- FC----- CC----- CC----- CA----- AA----- EA----- FA----- DE----- ------- ------- ------- ------- 
