model
size = 28 28 9, scale = 0.05, origin = -y
material 
  colors = A:#222 B:#F9F C:#CF9 D:#111 E:#CFC F:#CF6 G:#777 H:#444 I:#E00 J:#EEE K:#39C L:#30C
voxels
---------------------------- ---------------------------- ------FF-------------------- -----FFF-------------FF----- -----FFF-------------FFF---- ----FFFF-------------FFF---- ----FFFF-------------FFF---- ----FFF--------------FFF---- ----FFF--------------FFF---- ---FFFF--------------FFFF--- ---FFFF--------------FFFF--- -----FF---------------FF---- ---------------------------- ---------------------------- ---------------------------- ---------------------------- ---------------------------- ---------------------------- ---------------------------- ---------------------------- ---------------------------- ---------------------------- ---------------------------- ---------------------------- ---------------------------- ---------------------------- ---------------------------- ---------------------------- 
---------------------------- ------CC-------------------- -----CHHC-----------CCC----- ----CHHAC-----------CHHCC--- ----CHAAC-----------CHHHC--- ---CHAAAC-----------CHHHC--- ---CHAAAC-----------CHHHC--- ---CHAAC------------CHHHC--- ---CHAAC------------CHHHCC-- --CHHAAC------------CHHHHC-- -CCHHAAC-------------HHHHC-- --CCCHAC-------------CHHC--- -----CC--------------CCC---- ---------------------------- ---------------------------- ---------------------------- ---------------------------- ---------------------------- ---------------------------- ---------------------------- ---------------------------- ---------------------------- ---------------------------- ---------------------------- ---------------------------- ---------------------------- ---------------------------- ---------------------------- 
---------------------------- -----DDDDE---------EEEE----- ---EEDDD-------------DGEE--- ---EGDD---------------DGGE-- --EEGD-----------------DGE-- --EGD------------------DGE-- --EGD------------------DGE-- --EGD------------------DGEE- KEEGD------------------DGGEK KEGGD------------------DGGE- EGGGD-----------------DDGGE- -EGGGD----------------GGG--- -EEEEGE-------------EGGGE--- ----EEEE-------------EEEE--- ---------------------------- ---------------------------- ---------------------------- -JJ-----------------------J- ---------------------------- ---------------------------- ---------------------------- ---------------------------- ---------------------------- ---------------------------- ---------------------------- ---------------------------- ---------------------------- ---------------------------- 
-------J-------------J------ -----DDDDA---------AAAA----- ---AADDD-------------DAAA--- ---AADD---------------DAAA-- --AAAD-----------------DAA-- --AAD------------------DAA-- --AAD------------------DAAA- --AAD------------------DAAA- KAAAD------------------DAAAK KAAAD------------------DAAAK AAAAD-----------------DDAAAA -AAAAD----------------AAA--A -AAAAAA-------------AAAAA-AA -AA-AAAA-------------AAA--AA -A------------------------AA -A------------------------AA -A------------------------AA JAAJ---------------------JAJ -AA----------------------AA- -AAA---------------------AA- --AA--------------------AAA- --AAA------------------AAA-- ---AAA----------------AAA--- ----AAAAAA--------AAAAAA---- -----AAAAAAAAAAAAAAAAAA----- -------AAAAAAAAAAAAAAA------ ---------AAAAAAAAAAA-------- ------------AAAA------------ 
-------J-------------J------ -----DDDDB---------BBIB----- ---BBDDD-------------DIBB--- ---BIDD---------------DIIB-- --BIID-----------------DIB-- --BID------------------DIB-- --BID------------------DIIB- --BID------------------DIIB- KBIID------------------DIILK KLIID------------------DIIIK BIIID-----------------DDIBBB -BIIID----------------BIB--B -BIBIIB-------------BBIIB-BB -BB-BBBB-------------BBB--BB -B------------------------BB -B------------------------BB -B------------------------BB JLBJ---------------------JLJ -BB----------------------BB- -BBB---------------------BB- --BB--------------------BBB- --BBB------------------BBB-- ---BBB----------------BBB--- ----BBBBBB--------BBBBBB---- -----BBBBBBBBJJBBBBBBBB----- -------BBBBBBJJBBBBBBB------ ---------BBBBJJBBBBB-------- ------------BKKB------------ 
---------------------------- -----EEEEE---------EGGG----- ---EEEDD-------------DGGG--- ---EGDD---------------DGGE-- --EEGD----------------DDGE-- --EGD-----------------DDGE-- --EGD-----------------DDGEE- --EGD-----------------DDGGE- KEEGD-----------------DDGGEK KEGGD-----------------DDGGGK EEGGD-----------------DDGEEE -EGGGD----------------GGE--- -EGGGGE-------------EGGGE--- -EEEEEEE-------------EEE---- ---------------------------- ---------------------------- ---------------------------- -JJ-----------------------J- ---------------------------- ---------------------------- ---------------------------- ---------------------------- ---------------------------- ---------------------------- ---------------------------- ---------------------------- ---------------------------- ---------------------------- 
---------------------------- -------C-------------------- ------CHC-----------CE------ ----CCHAC-----------CCEEE--- ----CHAAC-----------CAHHE--- ---CHAAAC-----------CAHHE--- ---CHAAAC-----------CAHHE--- ---CHAAC------------CAHHEE-- ---CHAAC------------CAHHHE-- --CCHAAC------------CAHHHEE- --CHHAAC-------------CHEEE-- --CHHHAC-------------CHE---- --CCCCC--------------EEE---- ---------------------------- ---------------------------- ---------------------------- ---------------------------- ---------------------------- ---------------------------- ---------------------------- ---------------------------- ---------------------------- ---------------------------- ---------------------------- ---------------------------- ---------------------------- ---------------------------- ---------------------------- 
---------------------------- ---------------------------- -------F-------------------- ------FF------------C------- -----FFF------------CCCC---- ----FFFF------------CAAC---- ----FFFF-------------CAC---- ----FFF--------------CAC---- ----FFF--------------CACC--- ----FFF--------------CACC--- ---FFFF---------------C----- ---FFFF---------------C----- ---------------------------- ---------------------------- ---------------------------- ---------------------------- ---------------------------- ---------------------------- ---------------------------- ---------------------------- ---------------------------- ---------------------------- ---------------------------- ---------------------------- ---------------------------- ---------------------------- ---------------------------- ---------------------------- 
---------------------------- ---------------------------- ---------------------------- ---------------------------- ---------------------------- ---------------------FF----- ---------------------FF----- ---------------------FF----- ---------------------FF----- ---------------------FF----- ---------------------------- ---------------------------- ---------------------------- ---------------------------- ---------------------------- ---------------------------- ---------------------------- ---------------------------- ---------------------------- ---------------------------- ---------------------------- ---------------------------- ---------------------------- ---------------------------- ---------------------------- ---------------------------- ---------------------------- ---------------------------- 
