model
size = 22 32 7, scale = 0.05, origin = -y
material 
  colors = A:#444 B:#222 C:#FC6 D:#888 E:#777 F:#BBB G:#EEE H:#FFF
voxels
224-3B18-3(5B17-5A17-)5B18-3B460-D20-3D40-5A16-3(B5AB15-7A15-)B5AB16-5A39-19B3-19B12-A5-A5(15-C5-C)15-A5-A41-6B5-12B98-D21-D20-3D19-DAD18-D3ED38-2(B5AB15-)3(7A15-B5AB15-)B5AB38-19BC2-B3A4B3A3B3A2B4-3E4-3A3-3A2(6-3F4-CAC3-CAC)6-3E4-3(CAC3-CAC13-)3A3-3A40-6B2-C2-12B10-H3(21-G)20-2(DAD19-)DAD18-D3AD17-DEAED19-G18-2(B5AB15-)3(7A15-B5AB15-)B5AB18-G16-C2-2BA16BCGEB3A3B11ABC3-EAE3-5A-5A2(5-FAF3-C3AC-C3AC)5-EAE3-3(C3AC-C3AC6-G4-)5A-5A2(6-G)5-G8-E6-E3-6B2-CGE12B98-D21-D20-3D19-DAD18-D3ED38-2(B5AB15-)3(7A15-B5AB15-)B5AB38-19BC2-B3A4B3A3B3A2B4-3E4-3A3-3A2(6-3F4-CAC3-CAC)6-3E4-3(CAC3-CAC13-)3A3-3A40-6B2-C2-12B164-D20-3D40-5A16-3(B5AB15-7A15-)B5AB16-5A39-19B3-19B12-A5-A5(15-C5-C)15-A5-A41-6B5-12B229-3B18-3(5B17-5A17-)5B18-3B301-
