model
size = 32, scale = 0.05, origin = -y
material 
  colors = A:#F3F B:#F39 C:#FFF D:#FF3 E:#FC3 F:#F63 G:#CC3 H:#FF6 I:#FFC J:#FC6 K:#FCF L:#F30 M:#FCC N:#CFC O:#FF9 P:#F66 Q:#F0C R:#F6C S:#F9C T:#FC9 U:#FC0 V:#CC0 W:#F33 X:#F69 Y:#F90 Z:#CF0 Aa:#CF6 Ab:#FF0 Ac:#F09 Ad:#CFF Ae:#CC9 Af:#CCC Ag:#F96 Ah:#F6F Ai:#F60 Aj:#F03 Ak:#CF3 Al:#F0F Am:#F36 An:#F9F Ao:#F93 Ap:#F00 Aq:#F06 Ar:#CC6 As:#F99 At:#CCF Au:#CF9 Av:#F3C Aw:#E00
voxels
13-6B986-6C23-12B21-2B6ABA24-6A858-2A2C2A24-4A2C3AB21-12C12-8BQ10BF8B11-BA10D2A19-3A6D3A21-10A23-8A24-A5-2A3(24-8A)18-4(D5-8A5-D12-)D6-6A6-D12-D7-4A7-D12-D4-D8AD4-D17-2Aw6A2Aw23-5(8A24-)8A25-6A122-2A2C2A24-4A2C4A21-3A6-3A19-2A10-2A17-16C9-30B2-8B14D8B2-9B12D2A7B9-3A10D3A16-5A6D5A16-5A5-6A16-4A-6A-4A14-3(D-4A8-4A-D12-)2(D-4A-D6-4A-D12-)D-5A2-2A3-4A-D12-D-4A5-A2-2(4A-D12-D-4A8-)4A-D12-D-4A7-5A-D12-D-4A8-4A-D14-2(4A8-4A16-)4A8-4A17-3A8-3A18-3A4-D3-3A18-4A2-3D-4A19-5A2C5A21-4A2C4A23-3A2C3A22-3A2-2A2-3A19-2A10-2A17-2A12-2A15-2A14-2A13-20C6-BX11B6-B-10B-BQ4BA5D14A3BMQ-7B4AD13A4BAoAaAc6BA-16A-13BA-16A-7B3-3BA2-4A5-5A2-4A8-BA3-12A3-4A9-A4-D8A5-4A9-A7-4A7-A-2(A10-)A7-A-A10-A4-A13-A-A10-5(A18-A12-)A18-A8-A2-2A18-A11-4A14-3A2(11-3A16-2A)11-4A14-3A12-3A14-2A12-A-2A6-3A5-2A14-3A2-A-6A2-3A15-5A6-6A16-3A8-4A16-7A2-7A16-A2-10A2-C15-A6-2A-A6-C13-A18-A11-4C15-3C5-BAi9B10-12BS2B-A20-A-2BAj2BAn2B2-A18-A3-AnZ2BAd2B2-2A16-2A3-RAo2BM4B-A16-A-2A-NT7B2-A14-2(A2-)7B-B3-A12-A3-3A3B3-3A4-12A4-4A4-AB3A4-10A5-A-A5-4A7-7A6-A-A5-2(4A8-)3(3A5-4A20-)3A5-4A19-2A7-4A20-A8-3A19-2A7-4A19-2A2(8-2A21-A)8-3A20-A8-3A10-2A8-A8-4A5-2A-5A5-2A9-3A5-2A4-2A5-2A11-A4-A8-A4-A12-2A16-2A13-2A15-2A13-3A12-A-2A12-2A-2A10-2A-CA12-A3-4A4-2A-A3-A11-A20-A9-4CM16-3C4-BX9B12-2B2-6BD2BA23-BJAb2BS2B-A23-AqAk2BK2B-A23-FD2BL3B2A19-AB-AaK5B2-2A16-5A7B2-3A14-2A-A3-6B4-2A13-A4-6BA2-BA2-2A14-5B-B2-2A-A21-3AB3-2A-2A11-2A7-3AB3-2A-A6-A5-2A7-3AB3-2A12-A8-A-3AB3-2ABA19-5A2(B3-2A23-3A)B3-2A23-2(4A3-2AB22-)4A3-3A22-4A3-2A23-4A4-2A8-2(A6-)4A4-2A5-2A15-3A6-B5-A10-3A3-2A7-BA3-A12-2A2-3A8-B-2A14-CA-3A8-2BA16-4A10-2A16-4A9-A-2A14-2A-A10-A17-2ABA9-A19-A2-A7-5C17-4C3-8B19-8BA24-AAsX5BA22-B-UL5B-A21-B-ApAk5B-A23-V2Am4B2-A22-7BA-A22-7B27-2B31-B2A2-B20-B3-B-BA3-B20-B3-B-B2A2(27-B-BAB)27-B-BA2B26-B-B2A27-B-B2A26-2B-B2A25-A2(-B)2A27-B3-A26-AB3-B26-AB30-BA4-A5-A19-BA4-A25-2A4-B3-A16-A4-A5-2B-A18-A2-B7-B-A18-A-B8-BA20-AB9-2A18-BA9-A20-B-A7-A24-A6-2C22-2C3-8B19-8BA24-A6BA24-A2(7BA22-A-)7B-A23-7B2-A22-7B2-A21-5B5-AB24-2B30-2(B31-)3(B29-B-)2B30-BAB27-B-2B28-B-2B30-BA28-B-2B2(28-B2-B)28-B3-B26-B4-B3-A18-A3-B4-B3-A18-2(A-)B5-B-A20-2AB6-BA22-AB7-A22-A7-A22-B-2(A31-)2C2-2(2BX)2B19-7BAD24-2A5BA24-A6BA24-A7BA22-A-7BA22-B-7B-2A22-B2-3B3-A24-2B5-A25-B31-B2(30-2B)31-B-B2(29-2B)30-3B28-4B28-3B3(31-B)64-B4-A23-B2-B27-2B2-B3-A23-AB3-B-A22-A-B4-2BA22-2AB5-A23-2A6-A23-BA5-C24-A-A5-C25-C3-6BO19-6BRGAk24-AdA3BNTAm25-A2-2BHA30-B25-B30-B31-B484-B5-A25-B5-A30-A27-B2-A22-A5-BA24-A6-2(2A24-A5-)C26-A4-CA25-A5-C25-C3-6BZ19-G4B-BJAr24-GD3BAtVAc25-B2-BAeCH30-B573-N5-I25-C4-I26-P58-A8-Ab22-A5-H26-A5-Q26-A4-C30-C-U29-C-C28-7BX20-F3B-B2D25-5BAD28-2BAD30-B606-AcAr30-Av2-F22-A5-Y2-Al28-WAaV24-A5-Al30-AfX30-CL30-CAk30-C31-5BAfAj19-BAp3B-B2D25-2B2-B2D28-2BAD30-B578-B27-AgG2-K27-AsAh-Q28-U-Ak29-ApAnAm29-2V26-A4-Ap30-CAh30-C63-5BTB19-OAt4-B2D22-3BD2B-BDB22-B2-B31-B583-Ab27-AvAr-P28-YW24-A5-W26-C4-AdQ30-AfAa31-B30-CP30-2(C31-)5BAlK21-BMB2-BD25-D2B2-BD25-B5-B25-A31-B579-OAj24-C5-ZX-An28-MAeY29-AqAgW30-Au31-X30-CD30-C31-C28-2CBWJ2BOKW19-BAkIAiB-BFA25-3B-BAlAt30-BAm606-Z2-U27-AlAh-I28-PAv24-A5-GTU24-C5-D31-Aa30-NAj30-CX30-C28-A31-2C-BT2BJApE20-AnSE2BRVAc25-H3BAvUB25-2(B31-)B605-Q5-AjP30-XAi30-AeTAd29-AgT26-C3-CO26-A3-CAe27-C2-C-C59-C2-BAlBAvRN19-AeAcE4-BS24-YAbAeB-BQK25-EB-4B25-B643-AvC30-AjAa25-J5-Ap30-WAg26-A3-CN26-A4-C27-C31-C32-C2-BAk2BIP22-B3-BP25-VB2-BAnAp28-BK607-Ar31-Ab32-R-C94-H30-C91-C31-C3-AsAgLBTD20-BAnB3-QAj25-RV2-QYN25-NB30-AuAbB28-RWOK27-P-JZY27-Ap-AeM29-AsZAqAg27-AcQMAe30-GAd30-Ab387-WAh31-I31-Aq24-B2-A3-S-As25-VC2-CAj24-AuAAoC-CAl26-AEC2-2C25-3C2-C27-C35-DAjAa22-AjZKB3-KE24-AoLB30-AtB29-BHG29-KAoT28-K-D31-Av30-UAjC29-AjEP29-O30-OI356-DAa3-Ah25-ApKAj29-AgVC29-NKAe-C25-U2-AsAr27-AkC-UAcAa24-AgIAmC-CHAl24-2CAC-CAlXC24-CXC-CAhC25-2C3-C27-C62-K30-AcDB29-AvMH28-H-ANP29-AtCG29-AmPT28-AfCE28-AsAoB30-Z389-D30-AmS29-AFC29-A2L27-Ap3-Ak-U22-Ap2-Am2-WAd-I22-AhAqEC-CAdAnAe23-CAqYC2-CAcAdF23-CAuOC2-2C25-C37-ZAgM21-OAiB5-Af24-AfB30-WAi5-Ag25-TAc30-TH30-OAl30-Ae2-A2-V24-SE30-2R31-F324-V31-U30-HI30-NC30-CF30-PQ27-M3-Aa30-MS-E22-VLMD2-CR-Ai23-AkAlC3-CAtG23-CPA4-CKC22-CG-C29-C6-AhJHAb20-LB5-Aq24-Ak2(B31-)2P3-J26-AiEAg-AgAsJ26-AiY30-GI29-CKA29-Am30-Au325-R31-Av30-TO30-HAr29-UNQ31-D27-J2-PF27-Af2-GAa25-NAj-F28-AuOC4-CLX21-CWIC4-CJ22-CJC-C3-C23-AkC27-O2-JAaL29-V2B7-Aa23-Ab28-Ac2-UH3-HAd21-Q4-F28-ATAfAlAd29-WAgM28-AeJAjAo26-AfAeEAqNZ26-Ao203-Ap31-S31-JN29-WVB30-C31-AbR30-ON58-Aa31-B31-Ac4-U52-JYFS2-C2-Ae20-2CAsAcLC3-CQAd20-CAiVAkC4-CAaMC19-CAfUC6-C21-3C8-AhArAe8-EF2-GEApCSAt12-AlE14-UA2-Ad2-B8-AhRX17-UP10-R19-AjG10-L22-VU3-AgC-Af19-VIH-U5-F22-GNCIVX3-QI21-AhCBCAoD4-G21-CPAbFE27-AnE-Q59-Aq3-M25-A46-S31-An31-AdR31-OE28-AkAoAnAu26-ArAfAdZAsH25-DQJAnAfQF26-DAsAcAtYAl26-KVRAgAc4-DAeF20-AsUAvApAk26-AeAtIOSAj27-AeCArJZX26-DAgAtSLZ25-ApSCHK-Af15-ALYAaAfNA4-KNAoL2-C12-K-AtJAuAlJ2A4-CXDAtC13-LY-AmAbCX2C6-2CH14-O3CU3C28-3C18-P2AhOAqIB5-Aq12-AqMAa-MAbHAi-CIAkG-BAnPMO13-AqAoAlAr6-GArAh2-Am15-SAkZXAl15-AfH10-K6-P11-RJNV6-AiTPL4-T13-FAsCAoC6-DAiAt-AgAm-H-Ai10-KLVPE6-TAaTH7-R11-UEYFK5-AjT10-A9-IAiAuLY27-CG29-AiFK30-Q27-ArDY-N9-XF16-AbMI11-DLAm14-Ag2-A13-Ab14-NAa15-E7-J-C19-LUAuPAe5-Aq-F18-AfAtAiHAiAd5-F3-Af2-R13-WHAfFAuMO4-AaAt2-C2-N12-IJAoWAlAfAl2-B-AmSAgMF17-AqDJAgC2-ZAb-URApEQFN5-As10-AvAqAjAmG3-AkPOSCNLM16-AjFNFT2-GAmAp3-COEO3-Ah10-SEAaXLHNAgAn3-V-CAs-AnZ3-AcQ7-WRWSAgON3-XAc4-Aa6-AkDApJ5-AeAgJNUAmFAAt-AvAl2C5-OAt2-AqULD6-AuAsCIALAHAbYAhJV-P3-IAgSCFApJKA5-XVPCXJH-2CRVAp4-HGApArBAaCAbV8-CF3C-4C-Av-I-FAhSAlAbC-C10-C2-3C5-2C2-CJCAsC12-C18-2C17-AbMR6-AbPAo-Av14-YSApIUAqOFAaAkAnAdQOEZ16-AcRUCAiAeAnLSAdVMBZAiAh15-AoAkOAcFAfAdAs-RAn3-MG-C-AuAc11-EAjAnJQWMQ-OAc-Z-AqKTAn-2H10-ArYZAsAqNJAl2-AnR-AfAuAe-DVAbFAlH8-MAcAuAoQAqMAqPAcAi8-ApEAlAh8-AsAlHArTYAkE-GAkAf-O6-AhAuAgAiAc-Ac5-AtPAlWB-Ar-AaTAjWY3-AmAlAtXIHAjSHRAv5-AeG-At6-Z-AcQ4-Am2-FNAnAlN-A13-NAo-Ak4-GC3-XAd16-OCT-Aj-As-OTB23-B-Z2-C-HAbX2-As9-Ah9-K-Ao4-NAs-J10-NR2-Ai4-QAi4-IO-CG13-LE-TI3-YG-OB-CZ-PAnK24-KArF3-AmL12-AGAf-AhAd3-DAjAsIAlQ-B-UAt11-AkHKAtAeCUXDAjMOQAdAh-AeAnGPHC10-AdArDAgEAnAj2-ZAIYURMAdRKAp-F10-AnAcMApRVOBAsAoAtGAcAjLEM-DU-QAo10-HASFApIPAtTAmAhAkOASAlAu-Ac-NE11-AtJLAhGAiAeB2CAjIAAkPWA2-MY10-AhAmVJIAhAuSKBAnZGHAdGJAt-2E10-OAi2CAbAqCAfArIAbVAoAhArAnTAeAmAqWSAr9-ArSBAbUHAn2CAdAsApT2CAcHZCAkAmAkW-MC6-MAgAjBGAq2CLAkBCAd2CAcQXAcAqETGJU8-YXAnKFAg2CArKD4CAaQAvAeWOAhAeAjAt8-AeRDAaYCHAbIAvAcN2C-BYAdAmAeCZ-Am9-CMSIEAoTAdCRMCAq2PWMAb2C13-5C-C2-C4-AdAlERC27-4C22-BO2ZApL22-AvAAvEKI2MVJAi21-YXAjYI2GAqAo22-ArWQEAuAdAhAbAeE-Af17-2AuWAbAdBWArUCAkAdY4-Z-Av10-L-XWAdTAfPAmWAjAnDMAu-AmAv-Af-AgAi10-JDJAfAaAoAiAbAtOVKAlAr-FYG2-YG10-AqSAeAoAlZAuEQIApVP-JLW5-Af8-AAqK2ZXAhAfAuAaGAhKG3-Ad3-ADW7-Z-AkL3-AvC-BAhIYT-F7-J15-AmFPCAqAv-3Aa22-FAlAiAnHAg-B25-AgT31-TApAf18-LM7-AsNO30-X2-AsAc30-VAv4-AaY12-GAmAk8-HU6-I12-TFAm7-F2I18-AfHLAAbAg4-ApLAf-Ad3-WAeAc15-EY9-A3-Ag15-QAu-S-K-Ao3-AoAtLZ2-Y13-AaBH-K-LNE2-NZAmJAoZ13-FE7-AuY-UMAhCAbTM2-G10-AaAiAgAi8-IEAvBUBGSAf11-SGNAu11-AbAiK-K13-AjGRQ10-CVTAqArAo-As13-BAhC4-C5-Aa-QEBAaRJ13-2(C-)4C3-CID-PApN13-2C2-AoCR4C-4C17-L-C5-Ar2(C-)3C17-C10-3C19-L-Q30-EAa3-G-Am24-RB2-Ad-O24-Ao-P5-X21-KFD-Ai2-Ac26-Av-T2-RV8-J11-AvVXK2-Ab14-Ag9-AcYCAeYMEU24-RWAbAg-EWAi-CAjArI9-NG13-S-Af2-XQ11-Ah14-AbW2-AeD23-DIAdEJFAi30-L98-S191-A2-AnAr27-A3-Q27-HE2-D28-SNAu31-W32-L-Z23-C12-S25-C51-C35-C-5C342-An33-Ak124-A534-
