model
size = 25 31 32, scale = 0.05, origin = -y
material 
  colors = A:#EEE B:#001 C:#D00 D:#555 E:#050 F:#0E0 G:#0A0 H:#E00 I:#630
voxels
258-2C22-5(4C21-)4C22-3C572-3C24-2C19-2(C4-2C18-)C4A2C19-C3A2(2C18-C4A)2C18-2C3A2C19-5C21-3C496-5C19-2C3-2C17-2C5-2C16-C7-C16-C-5A-C16-C7AC16-2C6A3(C16-C7A)C16-2C5A2C17-2C3A2C19-5C369-6A18-7A18-8A16-10A15-11A13-5A3C4A13-4A5C3A13-13A11-15A10-16A9-15A10-4(17A8-)16A9-16A10-14A12-12A-A13-8A291-8A16-12A12-14A11-14A10-8A5-3A8-7A2-9A7-BAD15A7-BAD14A8-B-DAB13A7-B-DB15A6-6(B-DB16A5-)B-DAB14A7-18A7-5A-10A11-3A-9A15-10A262-11A13-13A12-2AB12A9-A3B3A7-2A8-BA3B2A-7A-2A7-BA9B5A-A7-C2D8B6A8-C-D8B7A7-C-D8B8A6-C3-7B9A5-5(C3-7B10A4-)C3-8B2(9A4-B-D9B)8A6-17A9-4A-10A13-11A17-7A238-12A12-2AB11A9-B7A7-2A8-B-5A-7A-2A7-C4A6B5A-A7-C4A6B6A8-C-5D-DB-B7A6-C2-7B-B7A6-C10-B8A5-C10-B9A4-7(C10-B10A3-)B-D8-B9A4-B-D-7B8A7-2AD15A9-3A-10A15-9A17-7A212-14A10-3AB4A6-2A8-B6A2-6A-2A7-C15A-A7-C16A8-C4A6-8A6-C-D7B-2(B8A5-C10-)B9A4-C6-A3-B10A3-2(C4-4A2-B11A2-C4-4AB-B11A2-)2(C10-B11A2-)2(C10-B10A3-)B-D-7B9A6-2AD16A8-16A13-10A15-9A18-6A187-15A9-10A5-2A7-B-14A-A7-C-15A8-C18A6-C4A6-9A5-C-D7B-B9A3-FC6-2A2-B9A3-GC4-4A2-B10A3-C3-5A3B11A2-C4-4A2B-2(11A2-C3-5A3B)11A2-C2-6A3B11A2-C3-4A-3B11A2-C7-4B11A2-C7-2B-B11A2-C-D8-B11A2-B-D8-B9A5-2AD8B9A7-17A10-14A13-10A15-9A20-2A164-A-6AB7A7-B-9A6-A7-C-15A8-C-16A7-C18A6-C3A7-9A5-C-D7B-B9A3-GC4-4A2-B10A2-GC2-6A2-B11A-FC2-6A3B11A-EC2-6A2B-11A-G3(C2-6A3B11A2-)C2-5A-3B11A2-C3-4A4B11A2-C-D5-2B-B11A2-C-D8-B11A2-B-D8-B10A4-2AD8B9A6-18A10-14A12-12A14-10A16-7A161-9A4-4A7-B-12A11-C-16A7-C-17A6-C-18A5-C3A7-10A4-C-D7B-B10A2-EC4-4A2-B11A-FC3-5A2-B11A-EC2-6A3B11A-GC2-6A2B-11A-FC2-6A3B12AEC2-6A3B12AGC2-6A3B12AFC2-5A-3B12A-C4-2A-4B11A2-C7-2B-B11A2-C-D8-B11A2-B-D8-B11A3-2AD8B10A4-20A8-16A10-14A12-12A14-9A19-4A137-6A9-2A7-B-14A9-C-17A6-C-18A5-C-19A4-C3A7-11A2-IC-D7B-B11A-FC6-A3-B11A-EC4-4A2-B11A-EC3-5A3B12AFC3-5A3B12AEC2-6A2B-12AGC2-6A3B12AFC3-5A3B12AEC6-A-3B12AEC7-B2-B12AG2(C10-B12A-)B-D8-B11A2-3AD8B11A3-21A6-18A8-16A10-14A13-10A15-9A42-2(5A20-)5A19-6A12-4A2-A9-2A7-B-14A9-C-18A5-C-19A4-C-20A3-C3A7-12A2-C-D7B-B11A-EC10-B11A-EC7-A2-B11A-FC5-3A2(2-B12AEC4-4A)B-B12AFC5-A-AB-B12AEC5-3AB-B12AG4(C10-B12A-)B-D8-B11A2-3AD8B11A3-22A4-20A6-18A8-16A11-12A14-9A18-6A17-3(7A18-)7A11-7A10-A7-B-15A8-C-18A4-AC-19A4-C-20A3-C3A7-12A2-C-D7B-B11A-EC10-B11A-FC10-B12AE2(C10-B12AG)7(C10-B12A-)B-D8-B11A2-3AD8B11A3-22A4-20A6-18A8-16A11-12A14-10A16-7A17-3(7A18-)7A11-7A10-A7-B-15A8-C-18A4-HC-19A4-C-20A3-C2A8-12A2-C-D7B-B11A-FC-D8-B11A-E10(C10-B12A-)B-D8-B11A2-3AD8B11A3-22A4-20A6-18A8-16A10-14A13-10A16-7A17-3(7A18-)7A11-7A10-A7-B-15A8-C-18A4-AC-8AB10A4-C-20A3-C3A7B12A2-C10-B11A2-C-D8-B11A2-C-B8-9(B12A-C10-)B12A-B-D6-2B12A2-3AD6B13A3-22A4-20A6-18A8-16A10-14A13-10A16-7A17-3(7A18-)7A11-7A10-A7-B-15A8-C-18A4-HC-19A4-C-20A3-C3A7B12A2-C10-B11A2-C-D8-B11A2-C-B8-9(B12A-C10-)B12A-B-D6-3B11A2-3AD7B12A3-22A4-20A6-18A8-16A10-14A13-10A16-7A17-3(7A18-)7A11-7A10-A7-B-15A8-C-18A4-AC-19A4-C-20A3-C2A8-12A2-C-D7B-B11A-FC-D8-B11A-G10(C10-B12A-)B-D8-B11A2-3AD8B11A3-22A4-20A6-18A8-16A10-14A13-10A16-7A17-3(7A18-)7A11-7A10-A7-B-15A8-C-18A4-HC-19A4-C-20A2-HC3A7-12A2-C-D7B-2(B11A-GC10-)B12AFC10-B12AEC10-B12AG7(C10-B12A-)B-D8-B11A2-3AD8B11A3-22A4-20A6-18A8-16A11-12A14-10A16-7A18-2(5A20-)5A19-6A12-4A2-A9-2A7-B-14A9-C-18A5-C-19A3-AC-20A3-C3A7-12A2-C-D7B-B11A-EC10-B11A-FC7-A2-B11A-EC5-3A2-B12AGC4-4A2-B12AFC4-4AB-B12AEC5-A-AB-B12AGC5-3AB-B12AF4(C10-B12A-)B-D8-B11A2-3AD8B11A3-22A4-20A6-18A8-16A11-12A14-9A18-6A111-6A9-2A7-B-14A9-C-17A6-C-18A5-C-19A4-C3A7-11A2-IC-D7B-B11A-FC6-A3-B11A-EC4-4A2-B11A-EC3-5A3B12AFC3-5A3B12AEC2-6A2B-12AGC2-6A3B12AFC3-5A3B12AEC6-A-3B12AEC7-B2-B12AG2(C10-B12A-)B-D8-B11A2-3AD8B11A3-21A6-18A8-16A10-14A13-10A15-9A135-9A4-4A7-B-12A11-C-16A7-C-17A6-C-18A5-C3A7-10A4-C-D7B-B10A2-EC4-4A2-B11A-EC3-5A2-B11A-FC2-6A3B11A-EC2-6A2B-11A-EC2-6A3B12AFC2-6A3B12AEC2-6A3B12AGC2-5A-3B12A-C4-2A-4B11A2-C7-2B-B11A2-C-D8-B11A2-B-D8-B11A3-2AD8B10A4-20A8-16A10-14A12-12A14-9A19-4A138-A-6AB7A7-B-9A6-A7-C-15A8-C-16A7-C18A6-C3A7-9A5-C-D7B-B9A3-EC4-4A2-B10A2-FC2-6A2-B11A-EC2-6A3B11A-GC2-6A2B-11A-G3(C2-6A3B11A2-)C2-5A-3B11A2-C3-4A4B11A2-C-D5-2B-B11A2-C-D8-B11A2-B-D8-B10A4-2AD8B9A6-18A10-14A12-12A14-10A16-7A162-15A9-10A5-2A7-B-14A-A7-C-15A8-C18A6-C4A6-9A5-C-D7B-B9A3-FC6-2A2-B9A3-EC4-4A2-B10A3-C3-5A3B11A2-C4-4A2B-2(11A2-C3-5A3B)11A2-C2-6A3B11A2-C3-4A-3B11A2-C7-4B11A2-C7-2B-B11A2-C-D8-B11A2-B-D8-B9A5-2AD8B9A7-17A10-14A13-10A15-9A20-2A164-14A10-3AB4A6-2A8-B6A2-6A-2A7-C15A-A7-C16A8-C4A6-8A6-C-D7B-2(B8A5-C10-)B9A4-C6-A3-B10A3-2(C4-4A2-B11A2-C4-4AB-B11A2-)2(C10-B11A2-)2(C10-B10A3-)B-D-7B9A6-2AD16A8-16A13-10A15-9A18-6A188-12A12-2AB11A9-B7A7-2A8-B-5A-7A-2A7-C4A6B5A-A7-C4A6B6A8-C-5D-DB-B7A6-C2-7B-B7A6-C10-B8A5-C10-B9A4-7(C10-B10A3-)B-D8-B9A4-B-D-7B8A7-2AD15A9-3A-10A15-9A17-7A213-11A13-13A12-2AB12A9-A3B3A7-2A8-BA3B2A-7A-2A7-BA9B5A-A7-C2D8B6A8-C-D8B7A7-C-D8B8A6-C3-7B9A5-5(C3-7B10A4-)C3-8B2(9A4-B-D9B)8A6-17A9-4A-10A13-11A17-7A239-8A16-12A12-14A11-14A10-8A5-3A8-7A2-9A7-BAD15A7-BAD14A8-B-DAB13A7-B-DB15A6-6(B-DB16A5-)B-DAB14A7-18A7-5A-10A11-3A-9A15-10A264-6A18-7A18-8A16-10A15-11A13-5A3C4A13-4A3C5A13-5A3C5A11-15A10-16A9-15A10-4(17A8-)16A9-16A10-14A12-12A-A13-8A393-5C19-2C3-2C17-2C5-2C16-C7-C16-C-A3CA-C16-C7AC16-2C6A3(C16-C7A)C16-2C5A2C17-2C3A2C19-5C496-3C24-2C19-2(C4-2C18-)C4A2C19-C3A2(2C18-C4A)2C18-2C3A2C19-5C21-3C547-2C22-5(4C21-)4C22-3C339-
