model
size = 30 28 16, scale = 0.05, origin = -y
material 
  colors = A:#EEE B:#111 C:#E00 D:#800 E:#F60
voxels
------------------------------ ------------------------------ ------------------------------ ------------------------------ ------------------------------ ------------------------------ ------------------------------ -------------BBB-------------- ------------------------------ ------------------------------ ------------------------------ ------------------------------ ------------------------------ ------------------------------ ------------------------------ ------------------------------ ------------------------------ ------------------------------ ------------------------------ ------------------------------ ------------------------------ ------------------------------ ------------------------------ ------------------------------ ------------------------------ ------------------------------ ------------------------------ ------------------------------ 
------------------------------ ------------------------------ ------------------------------ -------------BBB-------------- ------------------------------ -------------AAA-------------- ------------AAAAA------------- ---------D--AAAAA------------- ---------C--AAAAA------------- ----------D--AAA-------------- -----------D------------------ -----------CDBBB-------------- ------------------------------ ------------------------------ ------------------------------ ------------------------------ ------------------------------ --------------E--------------- ------------------------------ ------------------------------ ------------------------------ ------------------------------ ------------------------------ ------------------------------ ------------------------------ ------------------------------ ------------------------------ ------------------------------ 
------------------------------ ------------------------------ ------------------------------ ------------AAAAA------------- -----------AAAAAAA------------ ----------AAAAAAAAA----------- ----------AAAAAAAAA----------- ---------CAAAAAAAAA----------- ---------CAAAAAAAAA----------- ---------CCAAAAAAAA----------- ----------CCAAAAAA------------ -----------CCAAAA------------- ------------DCCCD------------- ------------------------------ ------------------------------ ------------------------------ ------------------------------ --------------E--------------- --------------E--------------- ------------------------------ ------------------------------ -------------BB--------------- ------------------------------ ------------------------------ ------------------------------ ------------------------------ ------------------------------ ------------------------------ 
------------------------------ ------------------------------ ------------AAAAA------------- -----------AAAAAAA------------ ----------AAAAAAAAA----------- ---------AAAAAAAAAAA---------- ---------AAAAAAAAAAA---------- ----------AAAAAAAAAA---------- ---------CAAAAAAAAAA---------- ---------CAAAAAAAAAA---------- ---------CCAAAAAAAA----------- ----------CCAAAAAA------------ ------------CCCCC------------- -----------DDCCCD------------- ------------------------------ ------------------------------ ------------------------------ --------------E--------------- --------------E--------------- ------------------------------ ------------------------------ ------------BBBB-------------- -------------BBBB------------- ---------------B-------------- ------------------------------ ------------------------------ ------------------------------ ------------------------------ 
------------------------------ ------------AAAAA------------- -----------AAAAAAA------------ ----------AAAAAAAAA----------- ---------AAAAAAAAAAA---------- --------AAAAAAAAAAAAA--------- --------AAAAAAAAAAAAA--------- --------AAAAAAAAAAAAA--------- --------AAAAAAAAAAAAA--------- --------AAAAAAAAAAAAA--------- ---------CAAAAAAAAAA---------- ----------CAAAAAAAA----------- -----------AAAAAAAD----------- -----------DCCCCCD------------ -----------DC----C------------ -------------BBB-------------- -----------------B------------ -------------AAA-------------- --------------A--------------- ----------------B------------- ------------------------------ -----------BBBBBBBBB---------- ------------BBBBBB------------ --------------BB-------------- ------------------------------ ------------------------------ ------------------------------ ------------------------------ 
------------------------------ -----------AAAAAAA------------ ----------AAAAAAAAA----------- ---------AAAAAAAAAAA---------- --------AAAAAAAAAAAAA--------- --------AAAAAAAAAAAAA--------- --------AAAAAAAAAAAAA--------- --------AAAAAAAAAAAAA--------- --------AAAAAAAAAAAAA--------- --------AAAAAAAAAAAAA--------- --------AAAAAAAAAAAAA--------- ---------AAAAAAAAAAA---------- ----------AAAAAAAACDC--------- ----------DCCAAAACDD---------- -----------CC----C------------ ------------BAAAB------------- -----------BAAAAAA------------ ------------AAAAAA------------ ------------AAAAAA------------ ------------BAAAA------------- -------------AAA-------------- ----------BBBBBBBBBBB--------- -----------BBBBBBB------------ -------------BBBB------------- --------------BBB------------- --------------BBB------------- --------------BBB------------- -------------BBBBB------------ 
-------------AAA-------------- ----------AAAAAAAAA----------- ---------AAAAAAAAAAA---------- --------AAAAAAAAAAAAA--------- --------AAAAAAAAAAAAA--------- --------AAAAAAAAAAAAA--------- -------AAAAAAAAAAAAAAA-------- -------AAAAAAAAAAAAAAA-------- -------AAAAAAAAAAAAAAA-------- --------AAAAAAAAAAAAA--------- --------AAAAAAAAAAAAA--------- --------BAAAAAAAAAAAA--------- --------BAAAAAAAAAACC--------- -------B-CCCAAAAAACD---------- ------B----C-AAAA-D----------- -----B------AAAAAA------------ ----B------AAAAAAAA----------- -----------AAAAAAAA-------BBB- -----------AAAAAAAA--------B-- ------------AAAAAA----------B- ------------AAAAAA-----------B ---------BBBBBBBBBBBB--------- -----------BBBBBBBBB---------- -------------BBBBB------------ -------------BBBBB------------ -------------BBBBB------------ ------------BBBBBBB----------- ------------BBBBBBB----------- 
------------AAAAA------------- ----------AAAAAAAAA----------- ---------AAAAAAAAAAA---------- --------AAAAAAAAAAAAA--------- --------AAAAAAAAAAAAA--------- -------AAAAAAAAAAAAAAA-------- -------AAAAAAAAAAAAAAA-------- -------AAAAAAAAAAAAAAA-------- -------AAAAAAAAAAAAAAA-------- -------AAAAAAAAAAAAAAA-------- --------AAAAAAAAAAAAA--------- --------BAAAAAAAAAAAAB-------- --------BAAAAAAAAAACCB-------- -------B-CCAAAAAAACD--B------- ------B---CCAAAAAAD----B------ -----B-----AAAAAAAA-----B----- ----B------AAAAAAAA------B---- --BB------AAAAAAAAA-------BB-- --B-------AAAAAAAAA--------B-- -BB--------AAAAAAAA--------BB- B-B--------AAAAAAAA--------B-B --B------BBBBBBBBBBBB------B-- -----------BBBBBBBBB---------- -------------BBBBB------------ ------------BBBBBBB----------- ------------BBBBBBB----------- -----------BBBBBBBBB---------- -----------BBBBBBBBB---------- 
------------AAAAA------------- ----------AAAAAAAAA----------- ---------AAAAAAAAAAA---------- --------AAAAAAAAAAAAA--------- --------AAAAAAAAAAAAA--------- -------AAAAAAAAAAAAAAA-------- -------AAAAAAAAAAAAAAA-------- -------AAAAAAAAAAAAAAA-------- -------AAAAAAAAAAAAAAA-------- -------AAAAAAAAAAAAAAA-------- --------AAAAAAAAAAAAA--------- --------AAAAAAAAAAAAAB-------- ---------AAAAAAAAAACCB-------- ---------CCAAAAAAACC--B------- ---------CCCAAAAAAC----B------ -----------AAAAAAAA-----B----- ----------AAAAAAAAAA-----B---- -BBB------AAAAAAAAAA---------- --B-------AAAAAAAAAA---------- -B---------AAAAAAAA----------- B----------AABABAAA----------- ---------BBBBBBBBBBBBB-------- -----------BBBBBBBBB---------- ------------BBBBBBB----------- ------------BBBBBBB----------- ------------BBBBBBB----------- -----------BBBBBBBBB---------- -----------BBBBBBBBB---------- 
------------AAAAA------------- ----------AAAAAAAAA----------- ---------AAAAAAAAAAA---------- --------AAAAAAAAAAAAA--------- --------AAAAAAAAAAAAA--------- -------AAAAAAAAAAAAAAA-------- -------AAAAAAAAAAAAAAA-------- -------AAAAAAAAAAAAAAA-------- -------AAAAAAAAAAAAAAA-------- -------AAAAAAAAAAAAAAA-------- --------AAAAAAAAAAAAA--------- --------AAAAAAAAAAAAA--------- ---------AAAAAAAAAAAC--------- ---------CCAAAAAAACC---------- ---------CCCAAAAAAC----------- -----------AAAAAAAA----------- ----------AAAAAAAAAA---------- ----------AAAAAAAAAA---------- ----------AAAAAAAAAA---------- -----------AAAAAAAA----------- -----------AABABBAA----------- ----------BBBBBBBBBBBB-------- -----------BBBBBBBBB---------- ------------BBBBBBB----------- ------------BBBBBBB----------- ------------BBBBBBB----------- -----------BBBBBBBBB---------- -------------BBBBB------------ 
-------------AAA-------------- ----------AAAAAAAAA----------- ---------AAAAAAAAAAA---------- --------AAAAAAAAAAAAA--------- --------AAAAAAAAAAAAA--------- --------AAAAAAAAAAAAAA-------- -------AAAAAAAAAAAAAAA-------- -------AAAAAAAAAAAAAAA-------- -------AAAAAAAAAAAAAAA-------- --------AAAAAAAAAAAAAA-------- --------AAAAAAAAAAAAA--------- --------AAAAAAAAAAAAA--------- ---------AAAAAAAAAAA---------- ---------CCAAAAAAACC---------- -----------CCAAAAAC----------- ------------AAAAAAA----------- -----------AAAAAAAA----------- -----------AAAAAAAAA---------- -----------AAAAAAAAA---------- -----------AAAAAAAA----------- ------------BBABBAA----------- ------------BBBBBBBBB--------- -----------BBBBBBB-B---------- -------------BBBBB------------ ------------BBBBBBB----------- -----------BBBBBBBBB---------- -----------BBBBBBBBB---------- -------------BBBBB------------ 
------------------------------ -----------AAAAAAA------------ ----------AAAAAAAAA----------- ---------AAAAAAAAAAA---------- --------AAAAAAAAAAAAA--------- --------AAAAAAAAAAAAA--------- --------AAAAAAAAAAAAA--------- --------AAAAAAAAAAAAA--------- --------AAAAAAAAAAAAA--------- --------AAAAAAAAAAAAA--------- --------AAAAAAAAAAAAA--------- ---------AAAAAAAAAAA---------- ----------AAAAAAAAA----------- ----------CCAAAAACC----------- -------------AAA-C------------ ------------AAAAAA------------ -----------AAAAAAAA----------- -----------AAAAAAAA----------- -----------AAAAAAAA----------- ------------AAAAAA------------ ------------BBBBBA------------ -----------BBBBBBBBB---------- -----------BBBBBBB------------ -------------BBBBB------------ ------------BBBBBB------------ -----------BBBBBBBBB---------- -----------BBBBBBBBB---------- -------------BBBBB------------ 
------------------------------ ------------AAAAA------------- -----------AAAAAAA------------ ----------AAAAAAAAA----------- ---------AAAAAAAAAAA---------- --------AAAAAAAAAAAAA--------- --------AAAAAAAAAAAAA--------- --------AAAAAAAAAAAAA--------- --------AAAAAAAAAAAAA--------- --------AAAAAAAAAAAAA--------- ---------AAAAAAAAAAA---------- ----------AAAAAAAAA----------- -----------AAAAAAA------------ -----------CCCCCCC------------ ------------------------------ -------------AAA-------------- ------------AAAAAA------------ ------------AAAAAA------------ ------------AAAAAA------------ -------------AAAA------------- -------------BBA-B------------ --------------BBBBBB---------- --------------BB-------------- --------------BBB------------- ------------BBBBB------------- ------------BBBBBBB----------- ------------BBBBBBB----------- -------------BB-BB------------ 
------------------------------ ------------------------------ ------------AAAAA------------- -----------AAAAAAA------------ ----------AAAAAAAAA----------- ---------AAAAAAAAAAA---------- ---------AAAAAAAAAAA---------- ---------AAAAAAAAAAA---------- ---------AAAAAAAAAAA---------- ---------AAAAAAAAAAA---------- ----------AAAAAAAAA----------- -----------AAAAAAA------------ ------------AAAAA------------- ------------CCCCC------------- ------------------------------ ------------------------------ ------------------------------ ------------------------------ ------------------------------ ------------------------------ -------------BBB-------------- --------------BBBBBB---------- ----------------B------------- --------------BB-------------- -------------BBBB------------- ------------BBBBBBB----------- -------------BBBBB------------ -------------BB-BB------------ 
------------------------------ ------------------------------ ------------------------------ ------------AAAAA------------- -----------AAAAAAA------------ ----------AAAAAAAAA----------- ----------AAAAAAAAA----------- ----------AAAAAAAAA----------- ----------AAAAAAAAA----------- ----------AAAAAAAAA----------- -----------AAAAAAA------------ ------------AAAAA------------- ------------------------------ ------------------------------ ------------------------------ ------------------------------ ------------------------------ ------------------------------ ------------------------------ ------------------------------ ------------------------------ ------------------------------ ------------------------------ ------------------------------ ------------------------------ -------------BBBBB------------ --------------BBB------------- ------------------------------ 
------------------------------ ------------------------------ ------------------------------ ------------------------------ ------------------------------ -------------AAA-------------- ------------AAAAA------------- ------------AAAAA------------- ------------AAAAA------------- -------------AAA-------------- ------------------------------ ------------------------------ ------------------------------ ------------------------------ ------------------------------ ------------------------------ ------------------------------ ------------------------------ ------------------------------ ------------------------------ ------------------------------ ------------------------------ ------------------------------ ------------------------------ ------------------------------ ------------------------------ ------------------------------ ------------------------------ 
