model
size = 32 32 8, scale = 0.05, origin = -y
material 
  colors = A:#E00 B:#B00 C:#800 D:#D00 E:#A00 F:#700
voxels
7-C-B12-B-C15-C14-C15-B16-B14-B16-B13-B18-B12-C18-C11-A20-A10-A20-A9-C22-C8-BA20-AB8-A22-A9-B20-B10-A20-A10-C20-C11-A18-A12-A18-A13-B16-B14-B16-B462-E-A12-A-E12-C3ABA10-AB3AC10-C2AB3A8-3AB2AC9-2AB4A10-4AB2A8-AB3A14-3ABA8-B3AC14-C3AB7-B3AC16-C3AB6-4AB16-B4A6-C2AB18-B2AC5-C2(BA)18-2(AB)C3-B3AB2A16-2AB3AB4-AB2A18-2ABA6-B4A16-4AB7-C2AC16-C2AC9-C2A16-2AC10-D2AB14-B2AD11-DAB14-BAD12-D2A14-2AD13-B2A12-2AB14-DA14-AD15-D2A10-2AD17-A12-A18-A12-A19-B10-B20-C10-C20-AC8-CA20-2A8-2A21-A8-A144-B4-E10-E4-B9-B6AE8-E6AB8-C7A8-7AC7-C7AE8-E7AC6-6AB12-B6A6-B4AC14-C4AB5-B5A16-5AB4-B4AB16-B4AB4-5AB16-B5A3-C5A18-5AC2-B5A18-5AB3-B3AC18-C3AB4-5AC16-C5A5-B4A16-4AB7-C3AB14-B3AC8-5A14-5A9-4AB12-B4A10-D3AB12-B3AD11-DAC14-CAD12-DAC14-CAD13-3A12-3A15-CA12-AC16-AB12-BA17-AB10-BA18-2A10-2A19-C10-C2(20-2A8-2A)21-A8-A22-A8-A80-A20-A9-2A-A-3A8-3A-A-2A7-B7AE8-E7AB6-B8A8-8AB6-C5ACA10-AC5AC5-B5AC14-C5AB4-6A16-6A4-5AB16-B5A3-6AB16-B6A-C5AB18-B5AC-C4AC18-C4AC2-B5AC16-C5AB3-B4AB16-B4AB5-5AB14-B5A6-D5AB12-B5AD7-C3AB14-B3AC8-D3AB14-B3AD9-D2AC14-C2AD10-D3A14-3AD11-B3AC10-C3AB13-B2A12-2AB14-BAB12-BAB15-CAB10-BAC16-B2AD8-D2AB17-BC10-CB18-B2A8-2AB19-C2A6-2AC20-3A6-3A20-BAB6-BAB21-B8-B2(22-A8-A)16-E4-A10-A4-E9-3A-A-2A8-2A-A-3A7-7ABE8-EB7A6-6AB2A8-2AB6A6-C5ABC10-CB5AC5-6AB14-B6A4-B4AB16-B4AB4-B5A16-5AB3-B5AB16-B5AB2-6A18-6A-C5AC18-C5AC-C6A16-6AC3-B5A16-5AB5-B4AB14-B4AB6-B5AB12-B5AB7-D4A14-4AD8-C3AC14-C3AC9-B3A14-3AB10-B3A14-3AB11-B3A12-3AB13-3AB10-B3A14-B2A12-2AB15-2ACD8-DC2A16-CAD10-DAC17-2A10-2A18-BAB8-BAB19-CAE6-EAC20-BAF6-FAB20-B2A6-2AB21-A8-A2(22-B8-B)16-A20-A9-7AE8-E7A8-B7A8-7AB7-B5ABAC8-CAB5AB6-B5AB12-B5AB6-C4AB14-B4AC5-2(5AB16-B5A4-)B4AC16-C4AB3-B4AC18-C4AB2-6A18-6A3-C4A18-4AC4-C5A16-5AC5-5A16-5A7-D3AB14-B3AD8-4AC14-C4A9-C3AC12-C3AC10-C4A12-4AC11-2AB14-B2A12-2AB14-B2A13-B2A12-2AB15-AC12-CA16-2A12-2A17-CA10-AC18-CA10-AC19-B10-B20-2A8-2A20-CA8-AC21-A8-A22-A8-A82-E-EA10-AE-E12-2(B4AB10-)B3ABAC8-CAB3AB9-B3ABAC10-CAB3AB8-3ABA14-AB3A8-CB3A14-3ABC7-AB2AB16-B2ABA6-B2ABC16-CB2AB6-B2AB18-B2AB5-B3AB18-B3AB3-B3AB2A16-2AB3AB4-4A18-4A6-CB3A16-3ABC7-DA2C16-2CAD9-DAC16-CAD10-3AC14-C3A11-2AB14-B2A12-C2B14-2BC13-CAB12-BAC14-BA14-AB15-2AC10-C2A17-A12-A18-B12-B19-B10-B20-C10-C2(20-2A8-2A)21-A8-A146-A-A12-A-A15-C14-C15-A16-A14-B16-B13-B18-B12-C18-C11-C20-C10-A20-A9-A22-A8-AB20-BA8-A22-A9-B20-B2(10-D20-D)11-A18-A12-A18-A13-A16-A14-B16-B455-
