model
size = 32 13 6, scale = 0.05, origin = -y
material 
  colors = A:#111 B:#888 C:#555 D:#222 E:#0A0 F:#0B0 G:#0D0 H:#444 I:#C03 J:#3CF K:#0E0 L:#050 M:#6FF N:#AAA O:#F03 P:#070
voxels
66-J25-2I3-J-J23-4I3-J24-4I29-2I4-2J29-4J24-I3-4J23-I-I3-2J25-I99-30A-7A18-9AM4A18-3A2D3AMAM3A18-2AB3D3AM4A18-2AB3D8A18-3A2D4A2B3A18-8A4B2A18-4AO3A4B2A18-3AOAO3A2B3A18-4AO9A18-7A-30A34-13A3C14A-A5B19CH5B2A5BHCKGK2G4F3GFKGKCH5B2A5BHCG2LPELGL2PL4EKCH5B2A5BHCFGF6E2FEF2EGCH5B2A5BHCG3L2PL2FE2F2E2FCH5B2A5BHCG2FEF5EF3EGKCH5B2A5BHCGLPLE2(F4E)KCH5B2A5BHCKFGE2GEF5EGEGCH5B2A5BHC2KGF2K2F4GF2KGCH5B2A5BH18CH4BNAC3B3A3D10A2(-A)-3A3NC-3C24-3C2-13A3-14A-6A5-9A5-20A2DA2D26A3D2(AD)24A4DAD2AD23A2D2(AD)3(2AD23A4DAD)2AD13AM10A3D2(AD)11AO2A2M10A2DA2D11AONA-30A289-A30-3A28-3AMA26-ANAC2B2A22-2A2NC-3C24-3C289-A30-3A28-2A-3A24-3A33-
