model
size = 32 13 6, scale = 0.05, origin = -y
material 
  colors = A:#BBB B:#888 C:#111 D:#FFF E:#777 F:#00F G:#444 H:#C03 I:#3CF J:#222 K:#EEE L:#AAA M:#6FF N:#F03 O:#DDD P:#03F
voxels
66-I25-2H3-I-I23-4H3-I24-4H29-2H4-2I29-4I24-H3-4I23-H-H3-2I25-H99-30A-7A18-9AM4A18-3A2J3AMAM3A18-2AB3J3AM4A18-2AB3J8A18-3A2J4A2B3A18-8A4B2A18-4AN3A4B2A18-3ANAN3A2B3A18-4AN9A18-7A-30A34-13A3E14A-A5B19EG5B2A5BGE3F11COAEG5B2A5BGEF13CLCEG5B2A5BGE6F7CK2CEG5B2A5BGE7F5CA3CEG5B2A5BGEF8CA2(CK)2CEG5B2A5BGE8FKPK3COCEG5B2A5BGEF6CK5CK2CEG5B2A5BGE12F4CEG5B2A5BG18EG4BLAK3B3A3J10A2(-A)-3A3LK-3D24-3D2-13A3-14A-6A5-9A5-20A2DA2D26A3D2(AD)24A4DAD2AD23A2D2(AD)2AD23A4DAD2AD23A4DA2DAD23A4DAD2AD13AM10A3D2(AD)11AN2A2M10A2DA2D11ANLA-30A289-A30-3A28-3AMA26-ALAK2B2A22-2A2LK-3D24-3D289-A30-3A28-2A-3A24-3A33-
