model
size = 24 26 32, scale = 0.05, origin = -y
material 
  colors = A:#3F9 B:#700 C:#AAA D:#001 E:#444 F:#BBB G:#DDD H:#00E I:#A00 J:#E00 K:#CF3
voxels
181-3J188-5B21-2(F23-)F22-3F333-3J20-5G18-2(G2H)G17-4GH2G17-G2HGH2G17-4GH2G17-G5HG18-5G19-5B381-D22-D-2(D22-)D-D22-D141-B3-B247-B132-4(CAC21-)3C21-D-D116-B3-B332-D-D21-CAC2(45-3A)45-3C22-D93-B3-B309-D22-CAC2(45-3A21-3A)45-3C21-D-D68-B3-B284-D-D21-CAC4(45-3A)45-3C22-D45-2B-2B285-D22-CAC3(21-3A)2(45-3A)2(21-3A)21-3C21-D-D45-B-B141-3E21-3E22-E94-D-D21-CAC93-3A20-5B20-3A93-CAC22-D46-3B117-3E20-5E18-E5-E116-D22-CAC3(21-3A)45-3A19-B5-2(B19-3A-)B19-3A21-3C21-D-D45-3B22-4(F23-)F21-5E18-E5-E115-D-D21-CAC2(45-3A)43-2(B-3A-B17-B5-B17-)B-CAC-B17-B2-D2-B17-2B3-2B18-5B139-5E24-E140-D22-CAC45-3A21-3A43-B-3A-B19-3A19-B5-B17-B-CAC-B20-D71-B142-3E189-D-D21-CAC45-3A43-B-3A-B43-CAC21-D-D19-B5-B17-B2-D2-B17-B5-B20-B142-3E214-D22-2(CAC21-)CAC19-B-CAC-B19-CAC22-D116-7B140-E238-D-2(D22-)D-D19-B2-D2-B19-D-D142-B143-E206-2DKD98-B5-B98-DK2D62-B143-E206-4D4(F23-)2F7B2F18-I4-3(F23-)F4D62-B350-2DKD125-I23-I53-DK2D62-B23-B479-I23-I119-B23-F23-E311-D22-D-2(D22-)D-D22-D47-I23-I95-B358-4(CAC21-)3C21-D-D46-I23-I71-B23-B286-D-D21-CAC2(45-3A)45-3C22-D47-I23-I71-B263-D22-CAC2(45-3A21-3A)45-3C21-D-D46-I23-I47-B47-5(F23-)F15-3E11F3E38-D-D21-CAC3(45-3A)19-B5-B17-B-3A-B17-B5-B17-B-3C-B17-B2-D2-B17-B5-B18-B3-B20-B-B22-B2(23-F)191-D22-CAC3(21-3A)45-3A19-B5-B19-3(3A21-)3C21-D-D94-B238-D-D21-CAC93-3A20-5B20-3A93-CAC118-B217-B21-D22-CAC3(21-3A)2(45-3A)2(21-3A)21-3C21-D-D92-5B236-D-D21-CAC4(45-3A)45-CAC22-D93-B3-B261-D22-CAC2(45-3A21-3A)45-CAC22-D117-B3-B284-D-D21-CAC2(45-3A)45-CAC21-D-D140-B3-B309-D22-4(CAC21-)CAC22-D165-B3-B332-2(D-2(D22-))D-D188-5B199-
