model
size = 29 11 32, scale = 0.05, origin = -y
material 
  colors = A:#3D0000 B:#321414 C:#B01010 D:#4B0C0C E:#D15656
voxels
99-3(8A21-)8A192-3A26-4(3A8-3A15-)3A169-2A27-2A14-2A11-2A14-2A27-2A11-2A14-2A11-2A161-D9-A17-C2(D9-A16-2C)D26-2CD9-A16-2CD9-A17-C2D142-2CD3(7-A20-B)28-2(B7-A20-)B26-2CD28-D84-2CD3(6-A21-B)28-2(B6-A21-)B28-B26-2CD56-2CD28-3(B4-A23-)B28-2(B4-A23-)2(B28-)B2(26-2CD)2(28-B3-A24-B)2(3-A24-B28-B)28-B2(26-2CD)2(28-B3-A24-B)3-A24-B28-B3-A24-A2(28-B)2(26-2CD)2(2-A25-B)2(28-2(B2-A25-)B)28-B2(26-2CD)2(2-A25-B)28-2(B2-A25-)A28-2(B2-A25-)B28-B26-2CD31-A23-2CD2-A25-2(B28-2(B2-A25-))B26-2CD59-A53-2CD28-B-A26-2(B28-)B-A26-B-A24-2CD88-A83-CD-A25-2(CD27-)CD-A25-CD-4(A115-A86-A56-E28-EA28-)A115-A83-CD-A25-2(CD27-)CD-A25-CD-A115-A53-2CD28-B-A26-2(B28-)B-A26-B-A24-2CD89-A23-2CD2-A25-2(B28-2(B2-A25-))B26-2CD55-2CD2(2(2-A25-B)2(28-2(B2-A25-)B)28-B2(26-2CD))2(28-B3-A24-B)3-A24-B28-B3-A24-A2(28-B)2(26-2CD)2(28-B3-A24-B)2(3-A24-B28-B)28-B2(26-2CD)28-3(B4-A23-)B28-A2(4-A23-B)2(28-B)26-2CD54-2CD3(6-A21-B)28-2(B6-A21-)B28-B26-2CD84-2CD3(7-A20-B)28-2(B7-A20-)B26-2CD28-D85-D9-A17-C2(D9-A16-2C)D26-2CD9-A16-2CD9-A17-C2D154-2A27-2A14-2A11-2A14-2A27-2A11-2A14-2A11-2A174-3A26-4(3A8-3A15-)3A203-3(8A21-)8A125-
