model
size = 15 32 15, scale = 0.05, origin = -y
material 
  colors = A:#111 B:#FFF C:#F6F D:#C0F E:#F93 F:#09F G:#66F H:#DDD I:#FCF J:#BBB K:#03F L:#E00 M:#0F6 N:#FF3 O:#06F P:#6FF Q:#FF0 R:#F06
voxels
5-5B370-5B98-9B8-2(5J10-)2(5I10-)2(5C10-)2(5D10-)2(5G10-)2(5K10-)2(5F10-)2A3P10-PA3P10-MAM2A10-2AMAM10-QA2QA10-2A3Q2(10-5E)2(10-5L)8-9B8-5H82-11B5-2(9J6-)2(9I6-)2(9C6-)2(9D6-)2(9G6-)2(9K6-)2(9F6-)PA2B3OAP6-PA5OAP6-2M3O2B2A6-MABA3OAM6-QA5OAQ6-QA2B3OAQ2(6-9E)6-2L4O3L6-9L5-11B5-9H8-5A66-13B3-2(8JR2J4-)2(11I4-)2(11C4-)2(11D4-)2(11G4-)2(11K4-)2(11F4-)2(P9OP4-)2M8OM4-2MB6O2M2(4-2QB6O2Q)2(4-11E)4-3L4O4L4-11L3-13B3-11H6-7A9-5A51-13B3-2(8JR2J4-)2(11I4-)2(11C4-)2(11D4-)2(11G4-)2(11K4-)2(F7A3F4-)2(P9AP4-)2M8AM4-2MB6A2M2(4-2QB6A2Q)2(4-E9AE)4-L9AL4-11L3-13B3-11H5-9A7-7A49-15B-2(9JR3J2-)2(13I2-)2(13C2-)2(13D2-)2(13G2-)2(13K2-)2(13F2-)2(P11OP2-)5M6O2M2-5M5O3M2(2-N2Q5O5N)2(2-13E)2(2-13L)-15B-13H3-11A5-9A9-3H36-15B-J9H3J2-J9A3J2(2-2I8A3I)2(2-13C)2(2-13D)2(2-3G9AG)2(2-K10A2K)2(2-3FA9F)2(2-P11AP)2-5M6A2M2-5M5A3M2(2-2N6A5N)2(2-13E)2(2-2L9A2L)-15B-13H3-11A5-9A8-5H11-3B12-BAB2(6-15B-J9H3J2-J9A3J2(2-2I8A3I)2(2-13C)2(2-13D)2(2-3G9AG)2(2-K10A2K)2(2-3FA9F)2(2-P11AP)2(2-5M6A2M)2(2-2N6A5N)2(2-13E)2(2-2L9A2L)-15B-13H3-11A5-9A8-5H11-3B12-3B)6-15B-4J6H3J2-4J6A3J2(2-2I8A3I)2(2-13C)2(2-13D)2(2-3GA9G)2(2-4K7A2K)2(2-3FA9F)2(2-P11AP)2(2-13M)2(2-2N6A5N)2(2-13E)2(2-2L9A2L)-15B-13H3-11A5-9A9-3H37-13B3-3J7HJ4-3J7AJ2(4-I8A2I)2(4-11C)2(4-11D)2(4-2GA8G)2(4-3K7AK)2(4-2FA8F)2(4-P9AP)2(4-11M)2(4-N6A4N)2(4-11E)2(4-11L)3-13B3-11H5-9A7-7A50-13B3-2(11J4-)2(11I4-)2(11C4-)2(11D4-)2(2GA8G4-)2(11K4-)2(2FA8F4-)2(P9AP4-)2(11M4-)2(11N4-)2(11E4-)11L4-11L3-13B3-11H6-7A9-5A52-11B5-2(9J6-)2(9I6-)2(9C6-)2(9D6-)2(9G6-)2(9K6-)2(9F6-)2(2P5A2P6-)2(9M6-)2(9N6-)2(9E6-)9L6-9L5-11B5-9H8-5A68-9B8-2(5J10-)2(5I10-)2(5C10-)2(5D10-)2(5G10-)2(5K10-)2(5F10-)2(5P10-)2(5M10-)2(5N10-)2(5E10-)5L10-5L8-9B8-5H85-5B370-5B95-
