model
size = 26 15 26, scale = 0.05, origin = -y
material 
  colors = A:#252525 B:#717171
voxels
--------AAAAAAAAAA-------- --------AAAAAAAAAA-------- --------AAAAAAAAAA-------- -------------------------- -------------------------- -------------------------- -------------------------- -------------------------- -------------------------- -------------------------- -------------------------- -------------------------- -------------------------- -------------------------- -------------------------- 
-------AAAAAAAAAAAA------- -------AAAAAAAAAAAA------- -------AAAAAAAAAAAA------- --------AAAAAAAAAA-------- --------AAAAAAAAAA-------- ----------AAAAAA---------- -------------------------- -------------------------- -------------------------- -------------------------- -------------------------- -------------------------- -------------------------- -------------------------- -------------------------- 
-----AAAA--------AAAA----- -----AAAA--------AAAA----- -----AAAA--------AAAA----- -------AAAAAAAAAAAA------- -------AAAAAAAAAAAA------- -------AAAAAAAAAAAA------- --------AAAAAAAAAA-------- --------AAAAAAAAAA-------- -------------------------- -------------------------- -------------------------- -------------------------- -------------------------- -------------------------- -------------------------- 
----AAA------------AAA---- ----AAA------------AAA---- ----AAA------------AAA---- -----AAAA--------AAAA----- -----AAAA--------AAAA----- -----AAAAAAAAAAAAAAAA----- ------AAAAAAAAAAAAAA------ -------AAAAAAAAAAAA------- --------AAAAAAAAAA-------- ---------AAAAAAAA--------- -------------------------- -------------------------- -------------------------- -------------------------- -------------------------- 
---AA----------------AA--- ---AA----------------AA--- ---AA----------------AA--- ----AAA------------AAA---- ----AAA------------AAA---- ----AAAAA--------AAAAA---- ----AAAAA--------AAAAA---- -----AAAAAAAAAAAAAAAA----- ------AAAAAA--AAAAAA------ -------AAAAAAAAAAAA------- ---------AAAAAAAA--------- ----------AAAAAA---------- -------------------------- -------------------------- -------------------------- 
--AA------------------AA-- --AA------------------AA-- --AA------------------AA-- ---AA----------------AA--- ---AA----------------AA--- ---AAA--------------AAA--- ----AA--------------AA---- ----AAAA----------AAAA---- -----AAA----------AAA----- ------AAAA------AAAA------ -------AAAAAAAAAAAA------- --------AAAAAAAAAA-------- -------------------------- -------------------------- -------------------------- 
--A--------------------A-- --A--------------------A-- --A--------------------A-- ---A------------------A--- ---A------------------A--- ---AA----------------AA--- ----A----------------A---- ----AA--------------AA---- ----AA--------------AA---- -----AAA----------AAA----- ------AAAA------AAAA------ -------AAAAAAAAAAAA------- ----------AAAAAA---------- -------------------------- -------------------------- 
-A----------------------A- -A----------------------A- -A----------------------A- --A--------------------A-- --A--------------------A-- --AA------------------AB-- ---B------------------B--- ----AA--------------AA---- ----AA--------------AA---- ----AAA------------AAA---- -----AAA----------AAA----- ------AAAA------AAAA------ --------AAAAAAAAAA-------- ----------AAAAAA---------- -------------------------- 
-A----------------------A- -A----------------------A- -A----------------------A- --A--------------------A-- --A--------------------A-- --BA------------------AB-- ---B------------------A--- ---AA----------------AA--- ----A----------------A---- ----AA--------------AA---- ----AAA------------AAA---- -----AAAA--------AAAA----- -------AAA------AAA------- ---------AAAAAAAA--------- -------------------------- 
A------------------------A A------------------------A A------------------------A -A----------------------A- -B----------------------B- --A--------------------A-- --A--------------------A-- ---AA----------------AA--- ---AA----------------AA--- ----AA--------------AA---- ----AAA------------AAA---- -----AAA----------AAA----- -------AA--------AA------- --------AAAAAAAAAA-------- -------------------------- 
A------------------------A A------------------------A A------------------------A -A----------------------A- -B----------------------B- --A--------------------A-- --B--------------------B-- --BA------------------AB-- ---A------------------A--- ---AA----------------AA--- ----AA--------------AA---- ----AAA------------AAA---- ------AA----------AA------ -------AAAA----AAAA------- -----------AAAA----------- 
A------------------------A A------------------------A A------------------------A -A----------------------A- -B----------------------B- -AA--------------------AA- --A--------------------A-- --BA------------------AB-- --AA------------------AA-- ---AA----------------AA--- ---AAA--------------AAA--- ----AAA------------AAA---- ------AA----------AA------ -------AAA------AAA------- ----------AAAAAA---------- 
A------------------------A A------------------------A A------------------------A -A----------------------A- -B----------------------B- -AA--------------------AA- --A--------------------A-- --AA------------------AA-- --AA------------------AA-- --AAA----------------AAA-- ---AAA--------------AAA--- ----AAA------------AAA---- ------AA----------AA------ -------AAA------AAA------- ----------AAAAAA---------- 
A------------------------A A------------------------A A------------------------A -A----------------------A- -B----------------------B- -BA--------------------AB- --B--------------------B-- --AA------------------AA-- --AA------------------AA-- --AAA----------------AAA-- ---AAA--------------AAA--- ----AAA------------AAA---- ------AA----------AA------ -------AAA------AAA------- ----------AAAAAA---------- 
A------------------------A A------------------------A A------------------------A -A----------------------A- -B----------------------B- -AA--------------------AA- --B--------------------B-- --AA------------------AA-- --AA------------------AA-- ---AA----------------AA--- ---AAA--------------AAA--- ----AAA------------AAA---- ------AA----------AA------ -------AAA------AAA------- ----------AAAAAA---------- 
A------------------------A A------------------------A A------------------------A -A----------------------A- -B----------------------B- --A--------------------A-- --A--------------------A-- --AA------------------AA-- ---A------------------A--- ---AA----------------AA--- ----AA--------------AA---- ----AAA------------AAA---- ------AA----------AA------ -------AAAA----AAAA------- -----------AAAA----------- 
A------------------------A A------------------------A A------------------------A -B----------------------B- -A----------------------A- --A--------------------A-- --A--------------------A-- ---AA----------------AA--- ---AA----------------AA--- ----AA--------------AA---- ----AAA------------AAA---- -----AAA----------AAA----- -------AA--------AA------- --------AAAAAAAAAA-------- -------------------------- 
-A----------------------A- -A----------------------A- -A----------------------A- --A--------------------A-- --A--------------------A-- --AA------------------AA-- ---A------------------A--- ---AA----------------AA--- ----A----------------A---- ----AA--------------AA---- ----AAA------------AAA---- -----AAAA--------AAAA----- -------AAA------AAA------- ---------AAAAAAAA--------- -------------------------- 
-A----------------------A- -A----------------------A- -A----------------------A- --A--------------------A-- --A--------------------A-- --AA------------------AA-- ---A------------------A--- ----AA--------------AA---- ----AA--------------AA---- ----AAA------------AAA---- -----AAA----------AAA----- ------AAAA------AAAA------ --------AAAAAAAAAA-------- ----------AAAAAA---------- -------------------------- 
-AA--------------------AA- --A--------------------A-- --A--------------------A-- ---A------------------A--- ---A------------------A--- ---AA----------------AA--- ----A----------------A---- ----AA--------------AA---- ----AA--------------AA---- -----AAA----------AAA----- ------AAAA------AAAA------ -------AAAAAAAAAAAA------- ----------AAAAAA---------- -------------------------- -------------------------- 
-AA--------------------AA- --A--------------------A-- --A--------------------A-- ---AA----------------AA--- ---AA----------------AA--- ---AAA--------------AAA--- ----AA--------------AA---- ----AAAA----------AAAA---- -----AAA----------AAA----- ------AAAA------AAAA------ -------AAAAAAAAAAAA------- --------AAAAAAAAAA-------- -------------------------- -------------------------- -------------------------- 
---A------------------A--- ---A------------------A--- ---A------------------A--- ----AA--------------AA---- ----AA--------------AA---- ----AAA------------AAA---- ----AAA------------AAA---- -----AAAAA------AAAAA----- ------AAAA------AAAA------ -------AAAAAAAAAAAA------- ---------AAAAAAAA--------- ----------AAAAAA---------- -------------------------- -------------------------- -------------------------- 
----A----------------A---- ----A----------------A---- ----A----------------A---- -----AA------------AA----- -----AA------------AA----- -----AAAA--------AAAA----- ------AAA--------AAA------ --------AAAAAAAAAA-------- --------AAAAAAAAAA-------- ---------AAAAAAAA--------- -------------------------- -------------------------- -------------------------- -------------------------- -------------------------- 
-----AA------------AA----- -----AA------------AA----- -----AA------------AA----- -------AA--------AA------- -------AA--------AA------- -------AAAAAAAAAAAA------- -------AAAAAAAAAAAA------- ----------AAAAAA---------- -------------------------- -------------------------- -------------------------- -------------------------- -------------------------- -------------------------- -------------------------- 
-------AA--------AA------- -------AA--------AA------- -------AA--------AA------- ---------AAAAAAAA--------- ---------AAAAAAAA--------- ---------AAAAAAAA--------- ----------AAAAAA---------- -------------------------- -------------------------- -------------------------- -------------------------- -------------------------- -------------------------- -------------------------- -------------------------- 
---------AAAAAAAA--------- ---------AAAAAAAA--------- ---------AAAAAAAA--------- ----------AAAAAA---------- -------------------------- -------------------------- -------------------------- -------------------------- -------------------------- -------------------------- -------------------------- -------------------------- -------------------------- -------------------------- -------------------------- 
