model
size = 3 32 24, scale = 0.05, origin = -y
material 
  colors = A:#EABB00
voxels
60A39-63A36-66A33-66A30-48A6-18A24-48A6-21A21-48A6-24A18-48A6-27A15-3(84A12-)2(87A9-)3(84A12-)48A6-27A15-48A6-24A18-48A6-21A21-48A6-18A24-2(66A27-)63A30-60A36-
