model
size = 11 5 31, scale = 0.05, origin = -y
material 
  colors = A:#047CD2 B:#2D2D2D C:#151515 D:#1B4361 E:#141515 F:#0C4670 G:#141617 H:#141719 I:#14171A J:#0C4974 K:#131D24 L:#0E3957 M:#131D23 N:#12212C O:#131B20 P:#14191C
voxels
AADAAAAADAA ----------- ----------- ----------- ----------- 
AADAAAAADAA ----------- ----------- ----------- ----------- 
AADAAAAADAA ----------- ----------- ----------- ----------- 
AADAAAAADAA ----------- ----------- ----------- ----------- 
AADAAAAADAA ----------- ----------- ----------- ----------- 
AADAAAAADAA ----------- ----------- ----------- ----------- 
AADAAAAADAA ----------- ----------- ----------- ----------- 
AADAAAAADAA ----------- ----------- ----------- ----------- 
AAAAAAAAAAA ----------- ----------- ----------- ----------- 
AAAAAAAAAAA ----------- ----------- ----------- ----------- 
AAAAAAAAAAA ----------- ----------- ----------- ----------- 
AAAAAAAAAA- ----------- ----------- ----------- ----------- 
-AAAAAAAAA- ----------- ----------- ----------- ----------- 
-AAAAAAAAA- ----------- ----------- ----------- ----------- 
-AAAAAAAAA- ----------- ----------- ----------- ----------- 
-AAAAAAAAA- ----------- ----------- ----------- ----------- 
-AAAAAAAAA- ----------- ----------- ----------- ----------- 
-AAAAAAAA-- ----------- ----------- ----------- ----------- 
--AAAAAAA-- --B-----B-- --B-----B-- ---BBBBB--- ----------- 
--AAAAAAA-- --B-----B-- --B-----B-- ---BBBBB--- ----------- 
--AAAAAAA-- --B-----B-- --B-----B-- ---BBBBB--- ----------- 
--AAAAAAA-- --BBBBBBB-- --B-----B-- ---B---B--- ----BBB---- 
--AAAAAAA-- --BFGHIJB-- --BB---BB-- --B----BB-- ---BBBBB--- 
--BBBBBBB-- --BKCCCLB-- --BB---BB-- --B-----B-- ---BBBBB--- 
--BBBBBBB-- --BMCCCNB-- --BB---BB-- --B-----B-- ---BBBBB--- 
--BBBBBBB-- --BOCCCPB-- --BB---BB-- --B-----B-- ---BBBBB--- 
--BBBBBBB-- --BECCCEB-- --B-----B-- --B-----B-- --B-----B-- 
--BBBBBBB-- --BECCCCB-- --B-----B-- --B-----B-- --B-----B-- 
--BBBBBBB-- --BCCCCCB-- --B-----B-- --B-----B-- --B-----B-- 
--BBBBBBB-- --BCCCCCB-- --B-----B-- --B-----B-- --B-----B-- 
---BBBBB--- ---BBBBB--- ---BBBBB--- ---BBBBB--- ---BBBBB--- 
