model
size = 11 5 31, scale = 0.05, origin = -y
material 
  colors = A:#047CD2 B:#2D2D2D C:#151515 D:#1B4361 E:#141515 F:#131D23 G:#14171A H:#141719 I:#141617
voxels
AADAAAAADAA ----------- ----------- ----------- ----------- 
AADAAAAADAA ----------- ----------- ----------- ----------- 
AADAAAAADAA ----------- ----------- ----------- ----------- 
AADAAAAADAA ----------- ----------- ----------- ----------- 
AADAAAAADAA ----------- ----------- ----------- ----------- 
AADAAAAADAA ----------- ----------- ----------- ----------- 
AADAAAAADAA ----------- ----------- ----------- ----------- 
AADAAAAADAA ----------- ----------- ----------- ----------- 
AAAAAAAAAAA ----------- ----------- ----------- ----------- 
AAAAAAAAAAA ----------- ----------- ----------- ----------- 
AAAAAAAAAAA ----------- ----------- ----------- ----------- 
-AAAAAAAAAA ----------- ----------- ----------- ----------- 
-AAAAAAAAA- ----------- ----------- ----------- ----------- 
-AAAAAAAAA- ----------- ----------- ----------- ----------- 
-AAAAAAAAA- ----------- ----------- ----------- ----------- 
-AAAAAAAAA- ----------- ----------- ----------- ----------- 
-AAAAAAAAA- ----------- ----------- ----------- ----------- 
--AAAAAAAA- ----------- ----------- ----------- ----------- 
--AAAAAAA-- --B-----B-- --B-----B-- ---BBBBB--- ----------- 
--AAAAAAA-- --B-----B-- --B-----B-- ---BBBBB--- ----------- 
--AAAAAAA-- --B-----B-- --B-----B-- ---BBBBB--- ----------- 
--AAAAAAA-- --BBBBBBB-- --B-----B-- ---B---B--- ----BBB---- 
--AAAAAAA-- --BCIHGCB-- --B-----B-- --B----BB-- ---BBBBB--- 
--BBBBBBB-- --BCCCCCB-- --B-----B-- --B-----B-- ---BBBBB--- 
--BBBBBBB-- --BFCCCCB-- --BB---BB-- --B-----B-- ---BBBBB--- 
--BBBBBBB-- --BCCCCCB-- --B-----B-- --B-----B-- ---BBBBB--- 
--BBBBBBB-- --BECCCEB-- --B-----B-- --B-----B-- --B-----B-- 
--BBBBBBB-- --BECCCCB-- --B-----B-- --B-----B-- --B-----B-- 
--BBBBBBB-- --BCCCCCB-- --B-----B-- --B-----B-- --B-----B-- 
--BBBBBBB-- --BCCCCCB-- --B-----B-- --B-----B-- --B-----B-- 
---BBBBB--- ---BBBBB--- ---BBBBB--- ---BBBBB--- ---BBBBB--- 
