model
size = 21 31 29, scale = 0.05, origin = -y
material 
  colors = A:#963 B:#111 C:#960 D:#222
voxels
--------------------- --------------------- --------------------- --------------------- --------------------- --------------------- --------------------- --------------------- --------------------- --------------------- --------------------- --------------------- --------------------- --------------------- --------------------- --------------------- --------------------- --------------------- --------------------- --------------------- --------------------- --------------------- --------------------- --------------------- ------------------B-- ------------------B-- ------------------B-- ------------------B-- ------------------B-- ------------------B-- ------------------B-- 
--------------------- --------------------- --------------------- --------------------- --------------------- --------------------- --------------------- --------------------- --------------------- --------------------- --------------------- --------------------- --------------------- --------------------- --------------------- --------------------- --------------------- --------------------- --------------------- --------------------- --------------------- --------------------- --------------------- ------------------B-- ------------------B-- ------------------B-- ------------------B-- ------------------B-- --------------------- --------------------- ------------------B-- 
--------------------- --------------------- --------------------- --------------------- --------------------- --------------------- --------------------- --------------------- --------------------- --------------------- --------------------- --------------------- --------------------- --------------------- --------------------- --------------------- --------------------- --------------------- --------------------- --------------------- --------------------- --------------------- --------------------- ------------------B-- ------------------B-- ------------------B-- ------------------B-- ------------------B-- --------------------- --------------------- ------------------B-- 
--------------------- --------------------- --------------------- --------------------- --------------------- --------------------- --------------------- --------------------- --------------------- --------------------- --------------------- --------------------- --------------------- --------------------- --------------------- --------------------- --------------------- --------------------- --------------------- --------------------- --------------------- --------------------- --------------------- ------------------B-- ------------------B-- ------------------D-- ------------------D-- ------------------B-- --------------------- --------------------- ------------------B-- 
--------------------- --------------------- --------------------- --------------------- --------------------- --------------------- --------------------- --------------------- --------------------- --------------------- --------------------- --------------------- --------------------- --------------------- --------------------- --------------------- --------------------- --------------------- --------------------- --------------------- --------------------- --------------------- --------------------- --------------------- ------------------B-- ------------------B-- ------------------B-- --------------------- --------------------- --------------------- ------------------B-- 
--------------------- --------------------- --------------------- --------------------- --------------------- --------------------- --------------------- --------------------- --------------------- --------------------- --------------------- --------------------- --------------------- --------------------- --------------------- --------------------- --------------------- --------------------- --------------------- --------------------- --------------------- --------------------- --------------------- --------------------- --------------------- --------------------- --------------------- --------------------- --------------------- --------------------- ------------------B-- 
--------------------- --------------------- --------------------- --------------------- --------------------- --------------------- --------------------- --------------------- --------------------- --------------------- --------------------- --------------------- --------------------- --------------------- --------------------- --------------------- --------------------- --------------------- --------------------- --------------------- --------------------- --------------------- --------------------- --------------------- ------------------B-- ------------------B-- ------------------B-- ------------------B-- ------------------B-- ------------------B-- ------------------B-- 
--------------------- --------------------- --------------------- --------------------- --------------------- --------------------- --------------------- --------------------- --------------------- --------------------- --------------------- --------------------- --------------------- --------------------- --------------------- --------------------- --------------------- --------------------- --------------------- --------------------- --------------------- --------------------- --------------------- ------------------B-- ------------------B-- ------------------B-- ------------------B-- ------------------B-- --------------------- --------------------- --------------------- 
--------------------- --------------------- --------------------- --------------------- --------------------- --------------------- --------------------- --------------------- --------------------- --------------------- --------------------- --------------------- --------------------- --------------------- --------------------- --------------------- --------------------- --------------------- --------------------- --------------------- --------------------- --------------------- --------------------- ------------------B-- ------------------B-- ------------------B-- ------------------B-- ------------------B-- --------------------- --------------------- --------------------- 
--------------------- --------------------- --------------------- --------------------- --------------------- --------------------- --------------------- --------------------- --------------------- --------------------- --------------------- ---------------B----- --------------B------ --------------------- --------------------- --------------------- --------------------- ------------B-------- --------------------- --------------------- --------------------- --------------------- --------------------- ------------------B-- ------------------B-- ------------------D-- ------------------D-- ------------------B-- --------------------- --------------------- --------------------- 
--------------------- --------------------- --------------------- --------------------- --------------------- --------------------- --------------------- --------------------- --------------------- --------------------- --------------------- ---------------B----- --------------B------ --------------------- --------------------- ----------B--B------- --------B-----B------ ------------B-B------ --------------B------ ---BB----B--B-------- ----B------B--------- --------------------- --------------------- --------------------- ------------------B-- ------------------B-- ------------------B-- --------------------- --------------------- --------------------- --------------------- 
--------------------- --------------------- --------------------- --------------------- --------------------- --------------------- --------------------- --------------------- --------------------- -----------A--------- -----------A--B------ ----------AA---B----- --------BAAA--BBD---- ---------BAC--BBB---- --------BBBD---B----- ---------BB--B------- -----B--B----BBB----- -------BB-BBBBB-B---- ----B---BBB-B-B------ ----B---BB--B-------- --------B--B--------- --------BB----------- -------------B------- --------------------- --------------------- --------------------- --------------------- --------------------- --------------------- --------------------- --------------------- 
--------------------- --------------------- --------------------- --------------------- --------------------- --------------------- --------------------- --------------------- --------------------- -----------AA--BB---- -----------AA-BB----- ---------CAAABBBB---- --------BAAAABBBBB--- -------BBBAABBBBB---- ------BBBBAABBBB----- ------BBBBBBBBDB-B--- -----BBBBBBBBBBB----- ------BBBBBBBBBBB---- ---BB--BBBBBBBBB----- ----B--BBBBBBBB------ -------BBBBBB-------- -------BBBBB--------- -----------B-B------- -------------B------- --------------------- --------------------- --------------------- --------------------- --------------------- --------------------- --------------------- 
--------------------- --------------------- --------------------- --------------------- --------CCCCAA------- -------CCCCCAAA------ -------CCCCAAAA------ ------CCCCAAAAAAB---- ------CCCCAAAAAAB---- ------CCCCAAAAAABBB-- ------ACCCAAAAAABB--- ------AAAAAA-AAABDB-- ------AAAAAA-AACB---- ------AAAAAAAAAAB---- ------AAAAAAAAAABBBB- ------AAAAAAAAAABB--- -----BAAAAAAAAAAB-B-- -----BAAAAAAAACCB-B-- -----BBBACAAAAABB-BB- ---BBBBBAAAAAAABB-B-- ---BBBBBBAAAABBB----- -------BBBBBBBBB----- -------BBBBBBBB------ --------BBB--B------- --------------------- --------------------- --------------------- --------------------- --------------------- --------------------- --------------------- 
--------------------- --------------------- --------------------- ----------CCAA------- -----C-CCCAAAAAAB---- ----CCCAAAAAAAAAB---- ----CCCAAAAAAAAABB--- ----CCAAAAAAAAAAB---- ----CAAAAAAAAAAABB--- ----AAAAAAAAAAAABB--- ----AAAAAAAAAAAABB--- ----AAAAAAAAAAAABB--- ----AAAAAAAAAAAABBB-- ----AAAAAAAAAAAABBBB- ----AAAAAAAAAAAABBBB- ----AAAAAAAAAAAABBBB- ----AAAAAAAAAAAABBB-- ----AAAAAAAAAAAABBB-- ----AAAAAAAAAAAAB-BB- ---BAAAAAAAAAAABB-B-- --BBAAAAAAAAAAAB----- ---BBBBAAAAAAABB----- ------BBAAAAABBB----- -------BBBBBB-------- --------BBB---BBB---- ---------------B----- --------------------- --------------------- --------------------- --------------------- --------------------- 
--------------------- --------------------- --------------------- --------CCAAA-A------ ----CCCCAAAAAAAA----- ----AAAAAAAAAAAA----- ----AAAAAAAAAAAABB--- ----AAAAAAAAAAAAB---- ----AAAAAAAAAAAAB---- ----AAAAAAAAAAAABB--- ----AAAAAAAAAAAAB-B-- ----AAAAAAAAAAAABBBB- ----AAAAAAAAAAAABBBB- ----AAAAAAAAAAAAB---- ----AAAAAAAAAAAABBB-- ---CAAAAAAAAAAAAB---- ----AAAAAAAAAAAABBB-- ----AAAAAAAAAAAABBB-- ----AAAAAAAAAAAABBBB- ----AAAAAAAAAAAAB-BB- --BBAAAAAAAAAAAABB--- --BBBBAAAAAAAAAB-BB-- ------BCAAAAAABBB---- ------BBBAACBBBBB---- --------BBBB--BBB---- ----------B---B------ ----------B---------- --------------------- --------------------- --------------------- --------------------- 
--------------------- --------------------- --------------------- -------CCCCAA-------- ----CCCAAAAAAAAAB---- ----AAAAAAAAAAAA----- ----AAAAAAAAAAAAD---- ----AAAAAAAAAAAABB--- ----AAAAAAAAAAAABD--- ----AAAAAAAAAAAABB--- ----AAAAAAAAAAAABBBB- ----AAAAAAAAAAAABBBB- ----AAAAAAAAAAAABBBB- ----AAAAAAAAAAAABB-B- ---BAAAAAAAAAAAABBBB- ---CAAAAAAAAAAAAB-B-- ----AAAAAAAAAAAABBBB- ----AAAAAAAAAAAABBB-- ----AAAAAAAAAAAABBBB- ---BAAAAAAAAAAAAB-B-- --BBAAAAAAAAAAAABB--- --BBAAAAAAAAAAAABBB-- --BBBBACAAAAAAABB---- ------BBAAAABBBB----- -------BBBBBB--BB---- ----------BBBB-B----- --------------------- --------------------- --------------------- --------------------- --------------------- 
-------------AAA----- -------------AAA----- ----------CA-ADC----- ------CCCCAAAADA----- ----CCAAAAAAAAAA----- ----AAAAAAAAAAAABBB-- ----BAAAAAAAAAAABD--- ----AAAAAAAAAAAABB--- ----AAAAAAAAAAAABB--- ----AAAAAAAAAAAABBB-- ----AAAAAAAAAAAABBBB- ----AAAAAAAAAAAABBBB- ----AAAAAAAAAAAABBBB- ----AAAAAAAAAAAABB--- ---BAAAAAAAAAAAABBB-- ---CAAAAAAAAAAAAB-BB- ----AAAAAAAAAAAABBB-- ----AAAAAAAAAAAABB--- ----AAAAAAAAAAAABBBB- ----AAAAAAAAAAAABBB-- ---BAAAAAAAAAAAABB--- --BBAAAAAAAAAAAABBB-- ---BBAAAAAAAAAAABBB-- -----BBAAAACAABBBB--- ------BBBBBBBBBBB---- ------BBBB---BB------ --------------------- --------------------- --------------------- --------------------- --------------------- 
-------------AAA----- -------------AAA----- --------CCAAAAAA----- ------CCAAAAAAAA----- ----CCAAAAAAAAAA----- ----AAAAAAAAAAAAB---- ----BAAAAAAAAAAABBBD- ----AAAAAAAAAAAABBB-- ----AAAAAAAAAAAAB---- ----AAAAAAAAAAAABBBB- ----BAAAAAAAAAAABB--- ----AAAAAAAAAAAABBBB- ----AAAAAAAAAAAABBBB- ----AAAAAAAAAAAABBB-- ----AAAAAAAAAAAABB--- ----AAAAAAAAAAAABBBB- ----AAAAAAAAAAAABBBB- ----AAAAAAAAAAAABB-B- B---AAAAAAAAAAAABB--- -BBBAAAAAAAAAAAAB---- --BBAAAAAAAAAAAABBB-- --BBAAAAAAAAAAAABB--- ----BAAAAAAAAAAAB---- -----BCAAAAAAABBB---- -----BBBBBBBBBB------ -------BBB--B-B------ -------B------------- --------------------- --------------------- --------------------- --------------------- 
------------AAAA----- ------------AAAA----- --------CCAAAAAA----- ------CCAAAAAAAA----- ----CCAAAAAAAAAA----- ----AAAAAAAAAAAA----- ----BAAAAAAAAAAAB---- ----AAAAAAAAAAAAB---- ----AAAAAAAAAAAABD--- ----AAAAAAAAAAAAD---- ----BAAAAAAAAAAABBB-- ----AAAAAAAAAAAABBD-- ----AAAAAAAAAAAA-BB-- ----AAAAAAAAAAAABBB-- ----AAAAAAAAAAAABBB-- ----AAAAAAAAAAAABBB-- ----AAAAAAAAAAAABBBB- ----AAAAAAAAAAAABBB-- ----AAAAAAAAAAAABB--- ----AAAAAAAAAAAABB--- --BBAAAAAAAAAAAABBB-- --BBAAAAAAAAAAAABBB-- ----BAAAAAAAAAAABBB-- ----BBAAAAAAAABBB---- -----BBBBBBBBBBB----- --------BB--B-------- --------------------- --------------------- --------------------- --------------------- --------------------- 
-------------AAA----- -------------AAA----- ----------AA-AAA----- ------CCCCAAAAAA----- ----CCAAAAAAAAAA----- ----AAAAAAAAAAAABB--- ----BAAAAAAAAAAABB--- ----AAAAAAAAAAAABB--- ----AAAAAAAAAAAABBB-- ----AAAAAAAAAAAAD---- ----AAAAAAAAAAAABBBD- ----AAAAAAAAAAAABBB-- ----AAAAAAAAAAAABBB-- ----AAAAAAAAAAAABBB-- ----AAAAAAAAAAAABBB-- ---CAAAAAAAAAAAABBBB- ----AAAAAAAAAAAABBBB- ----AAAAAAAAAAAABBB-- ----AAAAAAAAAAAAB---- ----AAAAAAAAAAAABB--- ---BAAAAAAAAAAAABBB-- --BBAAAAAAAAAAAABB--- ---BBAAAAAAAAAAAB---- ----BBBAACAAAABB----- -----BBBBBBBBB------- ----------B-B-------- --------------------- --------------------- --------------------- --------------------- --------------------- 
--------------------- --------------------- --------------------- -------CCCAAA-------- ----CCCAAAAAAAAA----- ----AAAAAAAAAAAAB---- ----AAAAAAAAAAAAB---- ----AAAAAAAAAAAAB---- ----AAAAAAAAAAAABB--- ----AAAAAAAAAAAAB---- ----AAAAAAAAAAAABBBBB ----AAAAAAAAAAAAB-B-- ----AAAAAAAAAAAABBBB- ----AAAAAAAAAAAAB---- ---BAAAAAAAAAAAABB--- ---CAAAAAAAAAAAABB--- ----AAAAAAAAAAAABB--- ----AAAAAAAAAAAABB--- ----AAAAAAAAAAAABB--- --BBAAAAAAAAAAAABBBB- ---BAAAAAAAAAAAAB---- ---BAAAAAAAAAAAAB---- ---BBBAAAAAAAAABB---- -----DBBAAAABBBBBB--- -------BBBBBB---B---- ----------B-B-------- --------------------- --------------------- --------------------- --------------------- --------------------- 
--------------------- --------------------- --------------------- ----------AAAA------- ----CC-CACAAAAAABB--- ----AAAAAAAAAAAAB---- ----AAAAAAAAAAAAD---- ----AAAAAAAAAAAAB---- ----AAAAAAAAAAAAB---- ----AAAAAAAAAAAABD--- ----AAAAAAAAAAAABBBB- ----AAAAAAAAAAAABB--- ----AAAAAAAAAAAAB---- ----AAAAAAAAAAAAB-B-- ---BAAAAAAAAAAAABB--- ---CAAAAAAAAAAAAB-B-- ----AAAAAAAAAAAABB--- ----AAAAAAAAAAAABB--- --BBAAAAAAAAAAAABB--- ---BAAAAAAAAAAABB---- -BBBAAAAAAAAAAABB---- ----BBBAAAAAAABBBB--- ---BBBBBAAAAABB------ ------BBBBBBBBB------ -------B--BB--------- -----------B--------- --------------------- --------------------- --------------------- --------------------- --------------------- 
--------------------- --------------------- --------------------- ------------A-------- -----CCCCCAAAAA------ ----CCCAAAAAAAAA----- ----CCCAAAAAAAAA----- ----CCAAAAAAAAAABB--- ----ACAAAAAAAAAABB--- ----ACAAAAAAAAAABBBB- ----AAAAAAAAAAAABB--- ----AAAAAAAAAAAABB--- ----AAAAAAAAAAAABBBBB ----AAAAAAAAAAAABBB-- ----AAAAAAAAAAAAB---- ----AAAAAAAAAAAABBBB- ----AAAAAAAAAAAABB--- ----AAAAAAAAAAAABB--- ----AAAAAAAAAAAABB--- B--BAAAAAAAAAAABB---- -B-BBBBBAAAAABB-B---- ---BBBBBAAAABBB------ ----B--BBBBBBBB------ ---------BBB--------- -------B------------- --------------------- --------------------- --------------------- --------------------- --------------------- --------------------- 
--------------------- --------------------- --------------------- --------------------- --------CCAAAA------- -------CCCAAAAA------ -------CCAAAAAA------ ------CCCCAAAAAA----- ------CCCAAAAAAABB--- ------CCCCAAAAAAD---- ------ACCAAAAAAABB--- ------AAAAAA-AAABD--- ------AAAAAA-AAABBB-- ------AAAAAAAAAABB--- ------AAAAAAAAAAB---- -----BAAAAAAAAAABB--- -----BAAAAAAAAAABBBB- -----DAAAAAAAAAABB--- ----DBBBAAAAAAABBB--- ----BBBBAAAAAAAB----- ----B-BBBAAAABB-B---- ------BBBBBBBB------- --------BBBB-BB------ ----------B--B------- --------------------- --------------------- --------------------- --------------------- --------------------- --------------------- --------------------- 
--------------------- --------------------- --------------------- --------------------- --------------------- --------------------- --------------------- --------------------- ---------------B----- -----------AA-BBD---- ----------AAA-BBD---- ---------CAAABBBDB--- -------B-AAAABBBBB--- -------BBBAA-BBBBB--- ------BBBBAABBBBB---- ------BBBBBBBBBBBB--- ------BDBBBBBBBBB---- ------BBBBBBBBBB----- ------BBBBBBBBBBBBB-- -----BBBBBBBBBBBB---- -------B-BBBBBB------ -------BBBBBBB------- ---------B--BBB------ ---------B--B-------- --------------------- --------------------- --------------------- --------------------- --------------------- --------------------- --------------------- 
--------------------- --------------------- --------------------- --------------------- --------------------- --------------------- --------------------- --------------------- --------------------- -----------A---B----- -----------A--BB----- ----------AA--B------ -------B--BB---BB---- --------BBAC--BB----- ---------BDB-DBB----- --------B---BB------- ------B-BBBBB-BBB---- ------BB--BBBBB------ -------BBBBBBB-BB---- ------BBBBBBBBBBB---- -------B-BBBBB------- --------BBBB-B------- -------------B------- --------------------- --------------------- --------------------- --------------------- --------------------- --------------------- --------------------- --------------------- 
--------------------- --------------------- --------------------- --------------------- --------------------- --------------------- --------------------- --------------------- --------------------- --------------------- ---------------B----- --------------------- ---------------B----- --------------------- -------------BB------ --------------------- --------B--B---B----- -----------BBB------- --------B--BBB------- -------B--BBBB------- ----------BB--------- --------------------- --------------------- --------------------- --------------------- --------------------- --------------------- --------------------- --------------------- --------------------- --------------------- 
--------------------- --------------------- --------------------- --------------------- --------------------- --------------------- --------------------- --------------------- --------------------- --------------------- --------------------- --------------------- --------------------- --------------------- --------------------- --------------------- --------------------- --------------------- ------------B-------- ------------BB------- ------------B-------- --------------------- --------------------- --------------------- --------------------- --------------------- --------------------- --------------------- --------------------- --------------------- --------------------- 
