model
size = 23 32 26, scale = 0.05, origin = -y
material 
  colors = A:#000 B:#141414 C:#222 D:#EEE E:#BBB
voxels
336-2A20-3A2(21-2A)17-3A555-2C21-3B14-3BC2BCAB13-3C2B2C2BC12-2CB3C2A3B12-B4C3ACB13-2BC3B2A2C13-C2B3C2ABC14-B3ACB455-6A16-9A14-3(9A13-B)10A12-C10AC11-C2(10AB11-B)10AC11-C2(10A12-B)7A17-2BC390-CB20-2(CB)C16-7AB2C12-B9ACBC10-C9AB2C10-B9AB2C9-C10A3C9-B11A2C9-C12AC9-C11AB10-C11AC10-B11A2(C11-B10A)12-B7A16-3CB2C295-4A19-4A18-6A16-10A13-11AB10-B11AB10-C11AC10-B11AC2(9-B12AB)9-C12AC9-B2(12AB9-C)12AC9-B11AB10-C11AC10-B11AB10-B11A12-B8A15-4C2BC292-11AC11-11AB3(10-B11AC)10-C11A2(C9-13A)C8-C13AB8-B14AC7-B13AC8-C13AC8-B13AB8-C13AB9-B12AC9-2(C11AB10-)C11A12-B9A14-C3ACBC17-BCB270-B12AB9-B12AC9-B12AB8-B13AC8-B13AB8-C13AC8-B14AC7-C2(14AB7-B)14AC6-16AB7-B14AB7-B13AC2(8-B13AB)8-C12AB9-C12AB10-B11AB11-B9A13-B5A3C15-CB2CB268-C2(14AB7-B)14AC7-C14AC7-B14AB7-B14A2(C6-16A)5(B6-16A)C6-15AB8-C13AB8-B12AB9-C12AB10-B11AC11-C9A13-C6ABC14-BCBA3B19-A247-B14AC7-B14AB7-B14A2(-C5-16A)2(-B5-16A)-C5-16AB6-16AB5-17AC5-17AB6-16AC6-16AB6-15AC7-15AC8-C13AB8-B12AC9-C12AB10-C8-2A13-B4-3A2B13-C4ACBC15-C4A81-D3-BC17-D2-C2B21-2B20-2C90-16A-C5-16A-B5(5-16A-C)2(4-17A-B4-17A-C)4-17AC6-16AB6-15AB7-15AC8-B13AC8-C12AC9-B12AB10-B10A12-C9AC12-C2A2-2A3B14-C5A13-3B2-B2C15-4C2-B13-D-B4CB15-DA2BC2ABC14-DEBC3A3C13-D-2CB2AC2B15-2B2A2BC16-3B3CB64-16A-B5-16A-C2(5-16A-B)2(4-17A-C2(4-17A-B))4-17A-B4-17AB2(5-17AC)6-15AB7-15AC7-14AC9-C12AB10-B10A12-C9AB8-2A2-B8AC8-14A8-12A11-E9A12-D10AC2(11-D10AB)11-DAE8AB12-E9AB13-9A15-7A18-3A19-17A-B4-17A-B5-16A3(-C4-17A-B4-17A)3(-C4-17A)B5-17AC6-16AC6-15AC6-16AB7-14AC9-C12AC10-B10A8-2A2-B9AB7-4A-C8AC7-15A8-12A11-10AB12-10AB11-D11AC10-D11AB11-11AC11-10AC12-10AC14-7AB16-5A18-17A-C4-17A-C5-16A-C2(4-17A-B)2(4-17A-C4-17A-B)4-17A-B2(4-17A-C)4-17AB5-17AC5-16AB6-16AB7-14AC9-B12AB9-C11A7-3A2-C9AB7-4A-B8AB7-15A8-12A11-10AC12-3(11AB11-)11AC11-11AB11-10AC14-7AB16-5A18-17A-B4-17A-B5-16A-C3(4-17A-B)5(4-17A-C)4-17A-B4-17AC5-17AB5-16AC6-16AB7-14AB9-B12AB10-C10A7-3A2-B9AB7-14AC7-15A8-12A11-10AC12-11AC11-11AB2(11-11AC)11-11AB11-10AB14-7AB16-5A18-17A-C4-17A-C5-16A2(2(-C4-17A)2(-B4-17A))-C4-17A-B4-17AC6-16AB6-15AB6-16AB7-14AC9-B12AC10-C10A8-2A2-C9AB7-4A-C8AB7-15A8-12A11-10AB12-10AC11-D11AC10-D11AB11-11AC11-10AC12-10AC14-7AB16-5A19-16A-B5-16A-C2(5-16A-B)4-17A-B2(4-17A-C2(4-17A-B))4-17A-C4-17AC5-16AC7-15AB7-15AC7-14AB9-B12AC10-C10A12-B9AC8-3A-C8AB8-14A8-12A11-E9A12-2(D10AB11-)D10AC11-DAE8AB12-E9AB13-9A15-7A18-3A20-4(16A-B5-)2(16A-C5-)16A2(-B4-17A)2(-C4-17A)-B4-17AB6-16AB6-15AC7-15AC8-C13AC8-C12AB9-B12AC10-B10A12-C9AC12-B7ACB14-7A12-3B3-2B15-3CB16-D-C5B15-D-2CB2A2B14-DEBC3ABCB13-D-2CB2AC2B15-2C2ABCB16-2CBC3B65-B2(14AC7-C)14A2(-B5-16A-C5-16A)-B5-16AC2(6-16AB)2(6-16AC)6-15AB2(7-15AC)8-B12AB9-C12AC9-B12AC10-C10A13-B7A2B13-C5A2B16-5A80-D3-BC17-D2-2BC21-2B20-2C91-B13AB8-B14AB7-C14AC7-C14AB7-B14AB7-C14AB5(6-16AC)6-2(15AC7-)15AB8-C13AC8-C12AC9-B12AB10-B11AB11-B9A13-C7AB14-3C2AB2C18-2A247-B12AC9-C12AB9-B12A2(C8-B13A)C8-B14AB2(7-B14AC)7-C14AB7-B14AB6-15A2(B8-C13A)C8-C13AB8-2(C12AC9-)B12AC10-B11AC11-B9A13-C7AB15-2B2CBCB269-10A13-2(11AB10-C)2(11AC10-C)11AB9-13AC9-13AB8-B13AB8-C13AC8-B13AC2(8-C13AB)8-B13AC9-B11AC10-C11AB10-B11AC10-C11A12-C9A14-C6AC16-2B2C2B271-4A19-4A18-6A16-10A13-2(11AB10-C)11AC10-C11AB9-C2(12AC9-B)12AB9-C12AC9-2(B11AC10-)C2(11AB10-B)11AC10-B11A12-C9A14-2CB2C3B386-2A20-5A16-10A12-C11AB10-B11AC10-C11AB9-B2(11AC10-C)3(11AC10-B)11AB11-C10AB11-B10A12-C8A15-2C2BCBC430-C2(B2C)16-C3B3C2B14-CB2C5B13-BC5B2CB13-C3B4C2A13-2BCBC2BC3A12-BC9AC2(11-C10AB)11-B10AB11-B10A12-C10A12-B8A16-3B3C529-2B21-3C14-2B2(CB)ACB13-CB2CBC4B12-3CB2C2A2BC12-2CB2C3A2C13-B2C3B2A2B13-2C2B2C2A2C14-B6AC18-CBC620-2A20-3A2(21-2A)17-4A-A306-
