model
size = 9 30 21, scale = 0.05, origin = -y
material 
  colors = A:#222 B:#000 C:#444
voxels
--------- --BBBBB-- ---BBB--- --------- --------- --------- --------- --------- --------- --------- --------- --------- --------- --------- --------- --------- --------- --------- --------- --------- --------- --------- --------- --------- --------- --------- --------- --------- --------- --------- 
---BBB--- --BCAAB-- --BCCB--- ---BBB--- --------- --------- --------- --------- --------- --------- --------- --------- --------- --------- --------- --------- --------- --------- --------- --------- --------- --------- --------- --------- --------- --------- --------- --------- --------- --------- 
--BACAB-- --BACAB-- --BA-B--- --BBBB--- --------- --------- --------- --------- --------- --------- --------- --------- --------- --------- --------- --------- --------- --------- --------- --------- --------- --------- --------- --------- --------- --------- --------- --------- --------- --------- 
-BACACB-- -BCACCB-- --B--AB-- --BBBBB-- --------- --------- --------- --------- --------- --------- --------- --------- --------- --------- --------- --------- --------- --------- --------- --------- --------- --------- --------- --------- --------- --------- --------- --------- --------- --------- 
-BACCCAB- -BC---CB- --B---B-- --BBBBB-- --------- --------- --------- --------- --------- --------- --------- --------- --------- --------- --------- --------- --------- --------- --------- --------- --------- --------- --------- --------- --------- --------- --------- --------- --------- --------- 
-BCACCAB- -BA---AB- -BC---B-- --BBBBB-- --------- --------- --------- --------- --------- --------- --------- --------- --------- --------- --------- --------- --------- --------- --------- --------- --------- --------- --------- --------- --------- --------- --------- --------- --------- --------- 
-BCAAAAB- -B----CB- -BA---AB- --BCAAB-- ---BBB--- --------- --------- --------- --------- --------- --------- --------- --------- --------- --------- --------- --------- --------- --------- --------- --------- --------- --------- --------- --------- --------- --------- --------- --------- --------- 
-BAACCAB- -B-----B- -BC---AB- -BAC-CCB- --BBBBB-- --------- --------- --------- --------- --------- --------- --------- --------- --------- --------- --------- --------- --------- --------- --------- --------- --------- --------- --------- --------- --------- --------- --------- --------- --------- 
-BACCACAB -B-----B- -B-----B- -BC---AB- --BAAAB-- --BBBB--- --------- --------- --------- --------- --------- --------- --------- --------- --------- --------- --------- --------- --------- --------- --------- --------- --------- --------- --------- --------- --------- --------- --------- --------- 
-BACCCCAB -B-----B- -B-----B- -BA---CB- -BA--AAB- --BACAB-- ---BBB--- ----B---- --------- --------- --------- --------- --------- --------- --------- --------- --------- --------- --------- --------- --------- --------- ----A---- ----C---- ---CAC--- ---CAA--- ---CAA--- --AACAC-- --CACAC-- --AAAAA-- 
-BCACCAB- -BCACACB- -B-----B- -B-----B- -BA---AB- --BC-CB-- --BAAAB-- --BBABB-- ---CAA--- ----A---- ----A---- ----C---- --------- --------- ----AA--- ----CA--- ----CC--- ----AC--- ----AC--- ----AC--- ---ACC--- ---CAA--- ---CCCA-- --CCCAC-- --ACCAC-- --AACAA-- --CCAACB- -BAAAAAB- -AAC--CB- -AAA--AB- 
--------- -BAACCCB- -B-----B- -B-----B- -BC---AB- -BA---CB- -BAA-CAB- --ACACC-- --CCCAC-- --CCACA-- --AAAAA-- --CACCA-- --ACAAA-- --CCCCC-- --CCCCC-- --AACAA-- --ACACA-- --CCCCCB- --ACACCB- --ACAAAB- --CAAAC-- --CC-CA-- --CA-CAB- -BCC--CB- -BC---AB- -BA---CB- -BC---CB- -BA----B- AA-----B- AA-----B- 
--------- -BCCACCB- -BAAACCB- -BC----B- -BA---AB- -BC---AB- -BC---CB- -BAA-CAB- -BCCAACB- --CC--CB- -BCC--CB- -BCA--C-- --AC--AB- --AA--AB- --CA--CB- --AA--AB- -BA---AB- -BA---CB- -BA----B- -BA---CB- -BA---CB- -BC---CB- -BA---AB- -BA----B- CA-----B- CA-----B- AA-----B- CA-----B- AC-----B- A------AA 
--------- --------- -BACAACB- -BC---CB- -BA---AB- -BC---AB- -BC---CB- -BC--CCB- -BC--AAB- -BA----B- -BA---CB- -BC---CB- -BA---AB- -BA----B- -BC----B- -BC----B- -BC----B- -B-----B- -B-----B- -B-----B- -BA----B- -BC----B- AA-----B- CA-----B- CC-----B- C------B- C------CA A------AA A------CC A------AA 
-BCCCACB- -BCCCCAB- -BCCAACB- -BA---AB- -BC---CB- -BA---AB- BAC---AAB BAA---ACB CC-----CA AC-----AC AC-----A- CC-----B- CC-----B- CA-----C- CC-----C- -B-----A- -B-----A- -B-----C- CA-----CC CA-----AA AA-----CC AC-----AA CA-----AC C------CA A------AC A------CA C------CA A------CA A------AC A------AA 
-BACCCCB- -BCCAACB- -B-----B- -BA---CB- -BA---AB- -BC---CB- BCC---CCB CAA---AAC CA-----CA AA-----CA AA-----C- CA-----B- CA-----B- AC-----A- CA-----C- -B-----A- -B-----AA -B-----CA AA-----CC AA-----B- AC-----B- AC-----B- AC-----B- CA-----B- A------B- C------B- A------B- A------B- A------B- A------AA 
-BACCAAB- -BACAAAB- -B----AB- -B----CB- -B----AB- -BA---CB- -BC---CB- -BC---CB- -B-----B- -B-----B- -B-----B- -B-----B- -B-----B- -B-----B- -B-----B- -B-----B- -B-----B- -B-----B- -B-----B- -B-----B- -B-----B- -B-----B- -B-----B- AC-----B- AA-----B- C------B- C------B- A------B- A------B- A------B- 
-BCCAACB- -BAACACB- -B----B-- -BA---B-- -BC---CB- -BC---AB- -BA---CB- -B----AB- -B----CB- -BA---CB- -BA----B- -BC---CB- -BC---CB- -B----CB- -B----AB- -B----AB- -B----CB- -B----CB- -B-----B- -B-----B- -BA----B- -BA---AB- -B----CB- -B----AB- AC----CB- AA----AB- CC----CB- CA----AB- AC----AB- AA---AAB- 
-BACCCAB- -BAAAACB- -BC---B-- -BA--AB-- -BA--CB-- -BC--AC-- -BC--CC-- -BC--AAB- -BC--AA-- -BC--ACB- --AA-CAB- --CC-CCB- -BAC-AC-- -BAA-CA-- -BA--AA-- -BA--CC-- -BAA-CC-- -BAC--AB- -BCA--CB- -BAC--AB- -BA---AB- -BC---CB- -BA--CA-- -BA--CA-- -BA--CA-- -BC-CCA-- -BC-CCA-- -BCCAAC-- -BAAACA-- -BAAAAA-- 
--BAAAAB- --BCACAB- --BCCCB-- --BCCAB-- -BCAACA-- -BACCAA-- --CACAC-- --CCACC-- --CACA--- --ACAA--- --CCCAA-- ---AAA--- ---CCA--- --ACAC--- --ACAA--- --AAAC--- --CACAC-- ---CCAA-- ---CAAA-- --AACCC-- --CCACA-- --CCCAA-- --AACCC-- --CCAA--- --AAAC--- --CCCC--- --AAA---- --CCA---- ---AC---- ---AA---- 
---BBBB-- ---BBBB-- ---BBBB-- ---CA---- ---CA---- ---AA---- ---CC---- ----C---- --------- --------- --------- --------- --------- --------- ----A---- ----C---- ----A---- ---CA---- ---CC---- ---CC---- ---AC---- ---CC---- ---AC---- ---A----- --------- --------- --------- --------- --------- --------- 
