model
size = 7 20 25, scale = 0.05, origin = -y
material 
  colors = A:#111 B:#222 C:#E83015 D:#0F4C3A E:#FFC408 F:#444
voxels
EAAAAAE AAAAAAA AAAAAAA AAAAAAA AAAAAAA AAAAAAA AAAAAAA AAAAAAA AAAAAAA AAAAAAA AAAAAAA AAAAAAA AAAAAAA AAAAAAA AAAAAAA AAAAAAA EAAAAAE ------- ------- ------- 
AAAAAAA BAAAAAB BAAAAAB BAAAAAB BAAAAAB BAAAAAB BAAAAAB BAAAAAB BAAAAAB BAAAAAB BAAAAAB BAAAAAB BAAAAAB BAAAAAB BAAAAAB BAAAAAB AAAAAAA ------- ------- ------- 
AAAAAAA BAAAAAB BAAAAAB BAAAAAB BAAAAAB BAAAAAB BAAAAAB BAAAAAB BAAAAAB BAAAAAB BAAAAAB BAAAAAB BAAAAAF BAAAAAF BAAAAAF BAAAAAB AAAAAAA ------- ------- ------- 
AAAAAAA BAAAAAB BAAAAAB BAAAAAB BAAAAAB BAAAAAB BAAAAAB BAAAAAB BAAAAAB BAAAAAB BAAAAAB BAAAAAB BAAAAAF BAAAAAB BAAAAAB BAAAAAB AAAAAAA ------- ------- ------- 
AAAAAAA BAAAAAB BAAAAAB BAAAAAB BAAAAAB BAAAAAB BAAAAAB BAAAAAB BAAAAAB BAAAAAB BAAAAAF BAAAAAF BAAAAAB BAAAAAB BAAAAAB BAAAAAB AAAAAAA ------- ------- ------- 
AAAAAAA BAAAAAB BAAAAAB BAAAAAB BAAAAAB BAAAAAB BAAAAAB BAAAAAB BAAAAAB BAAAAAF BAAAAAB BAAAAAB BAAAAAB BAAAAAB BAAAAAB BAAAAAB AAAAAAA ------- ------- ------- 
AAAAAAA BAAAAAB BAAAAAB BAAAAAB BAAAAAB BAAAAAB BAAAAAB BAAAAAB BAAAAAB BAAAAAB BAAAAAF BAAAAAF BAAAAAB BAAAAAB BAAAAAB BAAAAAB AAEEEAA ---E--- ---E--- ---E--- 
AAAAAAA BAAAAAB BAAAAAB BAAAAAB BAAAAAB BAAAAAB BAAAAAB BAAAAAB BAAAAAB BAAAAAB BAAAAAB BAAAAAB BAAAAAB BAAAAAB BAAAAAB BAAAAAB AAAAAAA ------- ------- ---E--- 
AAAAAAA BAAAAAB BAAAAAB BAAAAAB BAAAAAB BAAAAAB BAAAAAB BAAAAAB BAAAAAB BAAAAAB BAAAAAB BAAAAAB BAAAAAB BAAAAAB BAAAAAB BAAAAAB AAAAAAA ------- ------- ---E--- 
AAAAAAA AAAAAAA AAAAAAA AAAAAAA AAAAAAA AAAAAAA AAAAAAA AAAAAAA AAAAAAA AAAAAAA AAAAAAA AAAAAAA AAAAAAA AAAAAAA AAAAAAA AAAAAAA AAAAAAA ------- ------- ---E--- 
DDDDDDD DAAAAAD DAAAAAD DAAAAAD DAAAAAD DAAAAAD DAAAAAD DAAAAAD DAAAAAD DAAAAAD DAAAAAD DAAAAAD DAAAAAD EAAAAAE EAAAAAE DAAAAAD DDDDDDD ------- ------- ---E--- 
CCCCCCC CAAAAAC CAAAAAC CAAAAAC CAAAAAC CAAAAAC CAAAAAC CAAAAAC CAAAAAC CAAAAAC CAAAAAC CAAAAAC CAAAAAC EAAAAAE EAAAAAE CAAAAAC CCCCCCC ------- ------- ---E--- 
CCCCCCC CAAAAAC CAAAAAC CAAAAAC CAAAAAC CAAAAAC CAAAAAC CAAAAAC CAAAAAC CAAAAAC CAAAAAC CAAAAAC CAAAAAC EAAAAAE EAAAAAE CAAAAAC CCCCCCC ------- ------- ---E--- 
CCCCCCC CAAAAAC CAAAAAC CAAAAAC CAAAAAC CAAAAAC CAAAAAC CAAAAAC CAAAAAC CAAAAAC CAAAAAC CAAAAAC CAAAAAC EAAAAAE EAAAAAE CAAAAAC CCCCCCC ------- ------- ---E--- 
DDDDDDD DAAAAAD DAAAAAD DAAAAAD DAAAAAD DAAAAAD DAAAAAD DAAAAAD DAAAAAD DAAAAAD DAAAAAD DAAAAAD DAAAAAD EAAAAAE EAAAAAE DAAAAAD DDDDDDD ------- ------- ---E--- 
AAAAAAA AAAAAAA AAAAAAA AAAAAAA AAAAAAA AAAAAAA AAAAAAA AAAAAAA AAAAAAA AAAAAAA AAAAAAA AAAAAAA AAAAAAA AAAAAAA AAAAAAA AAAAAAA AAAAAAA ------- ------- ---E--- 
AAAAAAA BAAAAAB BAAAAAB BAAAAAB BAAAAAB BAAAAAB BAAAAAB BAAAAAB BAAAAAB BAAAAAB BAAAAAB BAAAAAB BAAAAAB BAAAAAB BAAAAAB BAAAAAB AAAAAAA ------- ------- ---E--- 
AAAAAAA BAAAAAB BAAAAAB BAAAAAB BAAAAAB BAAAAAB BAAAAAB BAAAAAB BAAAAAB BAAAAAB BAAAAAB BAAAAAB BAAAAAB BAAAAAB BAAAAAB BAAAAAB AAEEEAA ---E--- ---E--- ---E--- 
AAAAAAA BAAAAAB BAAAAAB BAAAAAB BAAAAAB BAAAAAB BAAAAAB BAAAAAB BAAAAAB BAAAAAB FAAAAAB FAAAAAB BAAAAAB BAAAAAB BAAAAAB BAAAAAB AAAAAAA ------- ------- ------- 
AAAAAAA BAAAAAB BAAAAAB BAAAAAB BAAAAAB BAAAAAB BAAAAAB BAAAAAB BAAAAAB FAAAAAB BAAAAAB BAAAAAB BAAAAAB BAAAAAB BAAAAAB BAAAAAB AAAAAAA ------- ------- ------- 
AAAAAAA BAAAAAB BAAAAAB BAAAAAB BAAAAAB BAAAAAB BAAAAAB BAAAAAB BAAAAAB BAAAAAB FAAAAAB FAAAAAB BAAAAAB BAAAAAB BAAAAAB BAAAAAB AAAAAAA ------- ------- ------- 
AAAAAAA BAAAAAB BAAAAAB BAAAAAB BAAAAAB BAAAAAB BAAAAAB BAAAAAB BAAAAAB BAAAAAB BAAAAAB BAAAAAB FAAAAAB BAAAAAB BAAAAAB BAAAAAB AAAAAAA ------- ------- ------- 
AAAAAAA BAAAAAB BAAAAAB BAAAAAB BAAAAAB BAAAAAB BAAAAAB BAAAAAB BAAAAAB BAAAAAB BAAAAAB BAAAAAB FAAAAAB FAAAAAB FAAAAAB BAAAAAB AAAAAAA ------- ------- ------- 
AAAAAAA BAAAAAB BAAAAAB BAAAAAB BAAAAAB BAAAAAB BAAAAAB BAAAAAB BAAAAAB BAAAAAB BAAAAAB BAAAAAB BAAAAAB BAAAAAB BAAAAAB BAAAAAB AAAAAAA ------- ------- ------- 
EAAAAAE AAAAAAA AAAAAAA AAAAAAA AAAAAAA AAAAAAA AAAAAAA AAAAAAA AAAAAAA AAAAAAA AAAAAAA AAAAAAA AAAAAAA AAAAAAA AAAAAAA AAAAAAA EAAAAAE ------- ------- ------- 
