model
size = 7 20 25, scale = 0.05, origin = -y
material 
  colors = A:#43341B B:#CAAD5F C:#E83015 D:#0F4C3A E:#FFC408
voxels
EAAAAAE AAAAAAA AAAAAAA AAAAAAA AAAAAAA AAAAAAA AAAAAAA AAAAAAA AAAAAAA AAAAAAA AAAAAAA AAAAAAA AAAAAAA AAAAAAA AAAAAAA AAAAAAA EAAAAAE ------- ------- ------- 
AAAAAAA BAAAAAB BAAAAAB BAAAAAB BAAAAAB BAAAAAB BAAAAAB BAAAAAB BAAAAAB BAAAAAB BAAAAAB BAAAAAB BAAAAAB BAAAAAB BAAAAAB BAAAAAB AAAAAAA ------- ------- ------- 
AAAAAAA BAAAAAB BAAAAAB BAAAAAB BAAAAAB BAAAAAB BAAAAAB BAAAAAB BAAAAAB BAAAAAB BAAAAAB BAAAAAB BAAAAAA BAAAAAA BAAAAAA BAAAAAB AAAAAAA ------- ------- ------- 
AAAAAAA BAAAAAB BAAAAAB BAAAAAB BAAAAAB BAAAAAB BAAAAAB BAAAAAB BAAAAAB BAAAAAB BAAAAAB BAAAAAB BAAAAAA BAAAAAB BAAAAAB BAAAAAB AAAAAAA ------- ------- ------- 
AAAAAAA BAAAAAB BAAAAAB BAAAAAB BAAAAAB BAAAAAB BAAAAAB BAAAAAB BAAAAAB BAAAAAB BAAAAAA BAAAAAA BAAAAAB BAAAAAB BAAAAAB BAAAAAB AAAAAAA ------- ------- ------- 
AAAAAAA BAAAAAB BAAAAAB BAAAAAB BAAAAAB BAAAAAB BAAAAAB BAAAAAB BAAAAAB BAAAAAA BAAAAAB BAAAAAB BAAAAAB BAAAAAB BAAAAAB BAAAAAB AAAAAAA ------- ------- ------- 
AAAAAAA BAAAAAB BAAAAAB BAAAAAB BAAAAAB BAAAAAB BAAAAAB BAAAAAB BAAAAAB BAAAAAB BAAAAAA BAAAAAA BAAAAAB BAAAAAB BAAAAAB BAAAAAB AAEEEAA ---E--- ---E--- ---E--- 
AAAAAAA BAAAAAB BAAAAAB BAAAAAB BAAAAAB BAAAAAB BAAAAAB BAAAAAB BAAAAAB BAAAAAB BAAAAAB BAAAAAB BAAAAAB BAAAAAB BAAAAAB BAAAAAB AAAAAAA ------- ------- ---E--- 
AAAAAAA BAAAAAB BAAAAAB BAAAAAB BAAAAAB BAAAAAB BAAAAAB BAAAAAB BAAAAAB BAAAAAB BAAAAAB BAAAAAB BAAAAAB BAAAAAB BAAAAAB BAAAAAB AAAAAAA ------- ------- ---E--- 
AAAAAAA AAAAAAA AAAAAAA AAAAAAA AAAAAAA AAAAAAA AAAAAAA AAAAAAA AAAAAAA AAAAAAA AAAAAAA AAAAAAA AAAAAAA AAAAAAA AAAAAAA AAAAAAA AAAAAAA ------- ------- ---E--- 
DDDDDDD DAAAAAD DAAAAAD DAAAAAD DAAAAAD DAAAAAD DAAAAAD DAAAAAD DAAAAAD DAAAAAD DAAAAAD DAAAAAD DAAAAAD EAAAAAE EAAAAAE DAAAAAD DDDDDDD ------- ------- ---E--- 
CCCCCCC CAAAAAC CAAAAAC CAAAAAC CAAAAAC CAAAAAC CAAAAAC CAAAAAC CAAAAAC CAAAAAC CAAAAAC CAAAAAC CAAAAAC EAAAAAE EAAAAAE CAAAAAC CCCCCCC ------- ------- ---E--- 
CCCCCCC CAAAAAC CAAAAAC CAAAAAC CAAAAAC CAAAAAC CAAAAAC CAAAAAC CAAAAAC CAAAAAC CAAAAAC CAAAAAC CAAAAAC EAAAAAE EAAAAAE CAAAAAC CCCCCCC ------- ------- ---E--- 
CCCCCCC CAAAAAC CAAAAAC CAAAAAC CAAAAAC CAAAAAC CAAAAAC CAAAAAC CAAAAAC CAAAAAC CAAAAAC CAAAAAC CAAAAAC EAAAAAE EAAAAAE CAAAAAC CCCCCCC ------- ------- ---E--- 
DDDDDDD DAAAAAD DAAAAAD DAAAAAD DAAAAAD DAAAAAD DAAAAAD DAAAAAD DAAAAAD DAAAAAD DAAAAAD DAAAAAD DAAAAAD EAAAAAE EAAAAAE DAAAAAD DDDDDDD ------- ------- ---E--- 
AAAAAAA AAAAAAA AAAAAAA AAAAAAA AAAAAAA AAAAAAA AAAAAAA AAAAAAA AAAAAAA AAAAAAA AAAAAAA AAAAAAA AAAAAAA AAAAAAA AAAAAAA AAAAAAA AAAAAAA ------- ------- ---E--- 
AAAAAAA BAAAAAB BAAAAAB BAAAAAB BAAAAAB BAAAAAB BAAAAAB BAAAAAB BAAAAAB BAAAAAB BAAAAAB BAAAAAB BAAAAAB BAAAAAB BAAAAAB BAAAAAB AAAAAAA ------- ------- ---E--- 
AAAAAAA BAAAAAB BAAAAAB BAAAAAB BAAAAAB BAAAAAB BAAAAAB BAAAAAB BAAAAAB BAAAAAB BAAAAAB BAAAAAB BAAAAAB BAAAAAB BAAAAAB BAAAAAB AAEEEAA ---E--- ---E--- ---E--- 
AAAAAAA BAAAAAB BAAAAAB BAAAAAB BAAAAAB BAAAAAB BAAAAAB BAAAAAB BAAAAAB BAAAAAB AAAAAAB AAAAAAB BAAAAAB BAAAAAB BAAAAAB BAAAAAB AAAAAAA ------- ------- ------- 
AAAAAAA BAAAAAB BAAAAAB BAAAAAB BAAAAAB BAAAAAB BAAAAAB BAAAAAB BAAAAAB AAAAAAB BAAAAAB BAAAAAB BAAAAAB BAAAAAB BAAAAAB BAAAAAB AAAAAAA ------- ------- ------- 
AAAAAAA BAAAAAB BAAAAAB BAAAAAB BAAAAAB BAAAAAB BAAAAAB BAAAAAB BAAAAAB BAAAAAB AAAAAAB AAAAAAB BAAAAAB BAAAAAB BAAAAAB BAAAAAB AAAAAAA ------- ------- ------- 
AAAAAAA BAAAAAB BAAAAAB BAAAAAB BAAAAAB BAAAAAB BAAAAAB BAAAAAB BAAAAAB BAAAAAB BAAAAAB BAAAAAB AAAAAAB BAAAAAB BAAAAAB BAAAAAB AAAAAAA ------- ------- ------- 
AAAAAAA BAAAAAB BAAAAAB BAAAAAB BAAAAAB BAAAAAB BAAAAAB BAAAAAB BAAAAAB BAAAAAB BAAAAAB BAAAAAB AAAAAAB AAAAAAB AAAAAAB BAAAAAB AAAAAAA ------- ------- ------- 
AAAAAAA BAAAAAB BAAAAAB BAAAAAB BAAAAAB BAAAAAB BAAAAAB BAAAAAB BAAAAAB BAAAAAB BAAAAAB BAAAAAB BAAAAAB BAAAAAB BAAAAAB BAAAAAB AAAAAAA ------- ------- ------- 
EAAAAAE AAAAAAA AAAAAAA AAAAAAA AAAAAAA AAAAAAA AAAAAAA AAAAAAA AAAAAAA AAAAAAA AAAAAAA AAAAAAA AAAAAAA AAAAAAA AAAAAAA AAAAAAA EAAAAAE ------- ------- ------- 
