model
size = 31 26 26, scale = 0.05, origin = -y
material 
  colors = A:#E00 B:#C93 C:#C90 D:#C60 E:#400
voxels
------------------------------- ------------------------------- ------------------------------- ------------------------------- ------------------------------- ------------------------------- ------------------------------- ------------------------------- ------------B---C-------------- -----------CB---B-------------- ------------C---B-------------- ------------------------------- ------------------------------- ------------------------------- ------------------------------- ------------B---B-------------- -----------AA---A-------------- ------------C---C-------------- ------------------------------- ------------------------------- ------------------------------- ------------------------------- ------------------------------- ------------------------------- ------------------------------- ------------------------------- 
------------------------------- ------------------------------- ------------------------------- ------------------------------- ------------------------------- ------------------------------- ------------------------------- ------------------------------- ------------C---BB------------- -----------AA---AAA------------ ------------A---AA------------- ------------B---BA------------- ------------B---BA------------- ------------B---BA------------- ------------B---BA------------- ------------A---AA------------- -----------AA---AAA------------ ------------C---BB------------- ------------------------------- ------------------------------- ------------------------------- ------------------------------- ------------------------------- ------------------------------- ------------------------------- ------------------------------- 
------------------------------- ------------------------------- ------------------------------- ------------------------------- ------------------------------- ------------------------------- ------------------------------- ------------------------------- -----------CCBBBC-A------------ ----------AAABBBBAAA----------- -----------AABBBBAA------------ -----------ABBBBBAA------------ -----------ABBBBBA------------- -----------ABBBBBAA------------ -----------ABBBBBAA------------ -----------AABBBBAA------------ ----------AAABBBBAAA----------- -----------CBBBBC-A------------ ------------------------------- ------------------------------- ------------------------------- ------------------------------- ------------------------------- ------------------------------- ------------------------------- ------------------------------- 
------------------------------- ------------------------------- ------------------------------- ------------------------------- ------------------------------- ---------A----------A---------- ---------A----------A---------- ---------AA--------AA---------- ----------ACBBBBC-AA----------- ----------AABBBBBAAA----------- ----------AABBBBBBAA----------- ----------AEBBBBBEA------------ ----------A-BBBBB-A------------ ----------A-BBBBB-A------------ ----------AEBBBBBEAA----------- ----------AABBBBBEAA----------- ----------AABBBBBEAA----------- ----------ACCBBBC-AA----------- ---------AA--------AA---------- ---------A----------A---------- ---------A----------A---------- ------------------------------- ------------------------------- ------------------------------- ------------------------------- ------------------------------- 
------------------------------- ------------------------------- ------------------------------- ------------------------------- --------A------------A--------- --------A------------A--------- --------AC----------AA--------- ---------B----------B---------- ---------A-BCCCBCB--B---------- ---------AAEBBBBBE-AA---------- ---------AAEBBBBBE-AA---------- ---------AA-BBBBB--AA---------- ----------A-BBBBB--A----------- ----------A-BBBBB--A----------- ---------AA-BBBBB--AA---------- ---------AAEBBBBB--AA---------- ---------AAEBBBBB--AA---------- ---------A-BCCCCBB--B---------- ---------B----------B---------- --------AC----------AA--------- --------A------------A--------- --------A------------A--------- ------------------------------- ------------------------------- ------------------------------- ------------------------------- 
------------------------------- ------------------------------- ------------------------------- ------------------------------- -------A--------------A-------- -------AC------------CA-------- -------AB------------CA-------- --------B------------B--------- --------B----CBB-----B--------- --------AB--BBBBB---BA--------- --------AA--BBBBC---AA--------- ---------A--CCBCB---A---------- ------------BCCCB---A---------- ---------A--CBBBB-------------- ---------A--CBCBC---A---------- --------AA--BBBBC---AA--------- --------AB--CBBBB---BA--------- --------B----CCB-----B--------- --------B------------B--------- -------AB------------CA-------- -------AC------------CA-------- -------A--------------A-------- ------------------------------- ------------------------------- ------------------------------- ------------------------------- 
------------------------------- ------------------------------- ------------------------------- ------A----------------A------- ------A----------------C------- ------AC--------------CA------- -------B--------------B-------- -------B--------------B-------- -------AB------------BA-------- -------AB----BBB-----BA-------- --------AB---BBC----BA--------- --------AB----------BA--------- ---------A----------A---------- --------AA----------A---------- --------AB----------BA--------- --------AB---CBB----BA--------- -------AB----CBB-----BA-------- -------AB------------BA-------- -------B--------------B-------- -------B--------------B-------- ------AC--------------CA------- ------A----------------C------- ------A----------------A------- ------------------------------- ------------------------------- ------------------------------- 
------------------------------- ------------------------------- ------------------------------- -----A------------------A------ -----AC----------------CA------ -----AC----------------CA------ ------B----------------B------- ------B----------------B------- ------AB--------------BA------- -------B--------------B-------- -------AB------------BA-------- -------AA------------BA-------- --------A---------------------- --------A---------------------- -------AA------------BA-------- -------AB------------BA-------- -------B--------------B-------- ------AB--------------BA------- ------B----------------B------- ------B----------------B------- -----AC----------------CA------ -----AC----------------CA------ -----A------------------A------ ------------------------------- ------------------------------- ------------------------------- 
------------------------------- ------------------------------- ----A--------------------A----- ----A--------------------C----- ----AC------------------CA----- -----C------------------B------ -----B------------------B------ -----AB----------------BA------ ------B----------------B------- ------B----------------B------- ------AB--------------BA------- ------AA--------------AA------- ------------------------------- ------------------------------- ------AA--------------AA------- ------AB--------------BA------- ------B----------------B------- ------B----------------B------- -----AB----------------BA------ -----B------------------B------ -----C------------------B------ ----AC------------------CA----- ----A--------------------C----- ----A--------------------A----- ------------------------------- ------------------------------- 
------------------------------- ------------------------------- ---A----------------------A---- ---AA--------------------CA---- ----C--------------------B----- ----C--------------------B----- ----B--------------------B----- ----AB------------------BA----- -----B------------------B------ -----B------------------A------ -----AA----------------AA------ ------A------------------------ ------------------------------- ------------------------------- ------A------------------------ -----AA----------------AA------ -----B------------------A------ -----B------------------B------ ----AB------------------BA----- ----B--------------------B----- ----C--------------------B----- ----C--------------------B----- ---AA--------------------CA---- ---A----------------------A---- ------------------------------- ------------------------------- 
------------------------------- ------------------------------- ------------------------------- ---A----------------------B---- ---C----------------------B---- ---B----------------------B---- ---AB--------------------BA---- ----B--------------------B----- ----B--------------------A----- ----AA------------------A------ ----AA------------------------- ------------------------------- ------------------------------- ------------------------------- ------------------------------- ----AA------------------------- ----AA-----AA-----------A------ ----B--------------------A----- ----B----AA--------------B----- ---AB----A---------------BA---- ---B-----A----------------B---- ---C----------------------B---- ---A----------------------B---- ------------------------------- ------------------------------- ------------------------------- 
------------------------------- ------------------------------- ------------------------------- --A------------------------B--- --C-----A------------------B--- --B------------------------B--- ---B----------------------B---- ---B----------------------A---- ---A--------------------------- ---AA-------------------------- ------------------------------- ------------------------------- ------------------------------- ------------------------------- ------------------------------- ------------------------------- ---AA-------------------------- ---A--------------------------- ---B---------------AA-----A---- ---B----A-----------A-----B---- --B-----A-----------A------B--- --C-----A------------------B--- --A------------------------B--- ------------------------------- ------------------------------- ------------------------------- 
------------------------------- ------------------------------- ------------------------------- -A----------------------------- -A--------------------------B-- --B------------------------A--- --A------------------------A--- --A---------------------------- --AA--------------------------- ------------------------------- ------------------------------- ------------------------------- ------------------------------- ------------------------------- ------------------------------- ------------------------------- ------------------------------- --AA--------------------------- --A---------------------------- --A------------------------A--- --B------------------------A--- -A--------------------------B-- -A----------------------------- ------------------------------- ------------------------------- ------------------------------- 
------------------------------- ------------------------------- ------------------------------- ------------------------------- A------------------------------ --------------------A---------- -A------------------A-------A-- ------------------------------- ------------------------------- ------------------------------- ------------------------------- ------------------------------- ------------------------------- ------------------------------- ------------------------------- ------------------------------- ----------------A-------------- ------------------------------- ------------------------------- -A--------------------------A-- ------------------------------- A------------------------------ ------------------------------- ------------------------------- ------------------------------- ------------------------------- 
------------------------------- ------------------------------- ------------------------------- ------------------------------- ---------------------A--------- ------------------------------- ------------------------------- ------------------------------- ------------------------------- ------------------------------- ------------------------------- ------------------------------- ------------------------------- ------------------------------- ------------------------------- ------------------------------- ------------------------------- ------------------------------- ------------------------------- ------------------------------- ------------------------------- ---A--------------------------- ---A--------------------------- ---A--------------------------- ------------------------------- ------------------------------- 
------------------------------- ------------------------------- ------------------------------- ------------------------------- -------A--------------A-------- ------------------------------- ------------------------------- ------------------------------- ------------------------------- ------------------------------- ------------------------------- ------------------------------- ------------------------------- ------------------------------- ------------------------------- ------------------------------- ------------------------------- ------------------------------- ------------------------------- ------------------------------- ------------------------------- ------------------------------- --------------------------A---- --A-----------------------A---- ------------------------------- ------------------------------- 
------------------------------- ------------------------------- ------D------------------------ -----------------------A------- ------------------------------- -----------------------A------- ------------------------------- ------------------------------- ------------------------------- ------------------------------- ------------------------------- ------------------------------- ------------------------------- ------------------------------- ------------------------------- ------------------------------- ------------------------------- ------------------------------- ------------------------------- ------------------------------- ------------------------------- ------------------------------- ---------------------------A--- ------------------------------- ---------------------------A--- ------------------------------- 
------------------------------- -----D------------------------- -----D------------------------- ------------------------A------ ------------------------D------ ------------------------A------ ------------------------------- ------------------------------- ------------------------------- ------------------------------- ------------------------------- ------------------------------- ------------------------------- ------------------------------- ------------------------------- ------------------------------- ------------------------------- ------------------------------- ------------------------------- ------------------------------- ------------------------------- ------------------------------- ----------------------------D-- ----------------------------D-- ----------------------------A-- ------------------------------- 
-------------------------A----- ----D-------------------------- -------------------------A----- ------------------------------- ------------------------------- ------------------------A------ ------------------------------- ------------------------------- ------------------------------- ------------------------------- ------------------------------- ------------------------------- ------------------------------- ------------------------------- ------------------------------- ------------------------------- ------------------------------- ------------------------------- ------------------------A------ ------------------------------- ------------------------------- ------------------------------- ------------------------------- -----------------------------D- ------------------------------- -----------------------------A- 
---D----------------------A---- ---AA---------------------A---- ------------------------------- ------------------------------- ------------------------------- -------------------------A----- ------------------------------- ------------------------------- ------------------------------- ------------------------------- ------------------------------- ------------------------------- ------------------------------- ------------------------------- ------------------------------- ------------------------------- ------------------------------- ------------------------------- -------------------------A----- ------------------------------- ------------------------------- ------------------------------- ------------------------------- ------------------------------- ------------------------------D ------------------------------A 
------------------------------- ------------------------------- ------------------------------- ------------------------------- --------------------------D---- ------------------------------- ------------------------------- ------------------------------- ------------------------------- ------------------------------- ------------------------------- ------------------------------- ------------------------------- ------------------------------- ------------------------------- ------------------------------- ------------------------------- ------------------------------- ------------------------------- ---A----------------------A---- ------------------------------- ------------------------------- ------------------------------- ------------------------------- ------------------------------- ------------------------------- 
------------------------------- ------------------------------- ------------------------------- ------------------------------- ------------------------------- ------------------------------- ------------------------------- ------------------------------- ------------------------------- ------------------------------- ------------------------------- ------------------------------- ------------------------------- ------------------------------- ------------------------------- ------------------------------- ------------------------------- ------------------------------- --------------------------A---- ------------------------------- ------------------------------- ------------------------------- ------------------------------- ------------------------------- ------------------------------- ------------------------------- 
------------------------------- ---A--------------------------- ------------------------------- ------------------------------- ------------------------------- ------------------------------- ------------------------------- ------------------------------- ------------------------------- ------------------------------- ------------------------------- ------------------------------- ------------------------------- ------------------------------- ------------------------------- ------------------------------- ------------------------------- --A---------------------------- --D---------------------------- --A------------------------D--- ---------------------------A--- ------------------------------- ------------------------------- ------------------------------- ------------------------------- ------------------------------- 
------------------------------- --A---------------------------- ------------------------------- ------------------------------- ------------------------------- --------------------------A---- ------------------------------- ------------------------------- ------------------------------- ------------------------------- ------------------------------- ------------------------------- ------------------------------- ------------------------------- ------------------------------- ------------------------------- ------------------------------- ------------------------------- ------------------------------- -A--------------------------D-- ------------------------------- ------------------------------- ------------------------------- ------------------------------- ------------------------------- ------------------------------- 
------------------------------- -A----------------------------- ------------------------------- ---------------------------A--- ---------------------------D--- ------------------------------- ------------------------------- ------------------------------- ------------------------------- ------------------------------- ------------------------------- ------------------------------- ------------------------------- ------------------------------- ------------------------------- ------------------------------- ------------------------------- ------------------------------- ------------------------------- ------------------------------- ------------------------------- ------------------------------- ------------------------------- ------------------------------- ------------------------------- ------------------------------- 
------------------------------- ------------------------------- ------------------------------- ------------------------------- ----------------------------D-- ------------------------------- ------------------------------- ------------------------------- ------------------------------- ------------------------------- ------------------------------- ------------------------------- ------------------------------- ------------------------------- ------------------------------- ------------------------------- ------------------------------- ------------------------------- ------------------------------- ------------------------------- ------------------------------- ------------------------------- ------------------------------- ------------------------------- ------------------------------- ------------------------------- 
