model
size = 32, scale = 0.05, origin = -y
material 
  colors = A:#FF3 B:#FFC C:#F3C D:#CF3 E:#F69 F:#F99 G:#F96 H:#CF9 I:#F93 J:#F6C K:#CF6 L:#FF6 M:#FCF N:#FF9 O:#F30 P:#CC6 Q:#F0C R:#F9F S:#CFC T:#F03 U:#FC9 V:#FF0 W:#F90 X:#CC9 Y:#F0F Z:#F36 Aa:#FCC Ab:#F63 Ac:#F39 Ad:#F00 Ae:#F09 Af:#CCC Ag:#F9C Ah:#CF0 Ai:#FC6 Aj:#CFF Ak:#FC3 Al:#EEE Am:#F06 An:#F66 Ao:#CC0 Ap:#CCF Aq:#F60 Ar:#F33 As:#F6F At:#CC3 Au:#FFF Av:#F3F
voxels
12-2(3(AB)A25-)3(AB)A441-Al32-HAsAkRAa27-ArCJ30-UAbJ28-XAO-D27-AhKAi-Aj26-AiAaTV33-B122-3(AB)154-2(7A25-)7A441-A31-C5A26-CAC2AI25-DCAC2AI25-2(AC)AIAAl25-C2(AI)A26-5CA31-A121-8A152-2(B6A2B23-)B6A2B374-HODUECAaJVAm22-AfNAjAONAtNAkAm22-AuFRKDPVRHD22-ZKAeTZQDFLP22-AbAdJEAv2AQAbV22-OGCXE2MWYU22-NSNGQFAoAeGK22-FAcPHAcApMDTY22-KRQEAnXWTSE22-AdJ2AAqAgCAhEO22-GSMAgHPGIGD22-SHFMAfYWUFZ54-2B6A2B148-2(4A6B5A17-)4A6B5A19-7(2A2B2-2B3A21-)2A4(2B2-2B3A20-3A)14(6B3A20-3A)2B2-2B3A21-2A2B2-2B2A23-A2B2-2BA25-2B2-2B21-2(B14AB3A13-)B14AB3A15-28(13A19-)13A15-ABLA2(13-B4A10-AB2A)13-B4A13-8(A13-B17-)2A10-A-15(B17-A13-)B17-2A10-A-4(B17-A13-)B13-2(3AB15-5A8-)3AB15-5A10-8(AB15-2A13-)AB-A10-A2-15(2A13-AB15-)2A13-AB-A10-A2-4(2A13-AB15-)2A10-2(3A19-4A6-)3A19-4A8-8(A19-A11-)A3-A10-A4-15(A11-A19-)A11-A3-A10-A4-4(A11-A19-)A8-2(B3A19-4AB4-)B3A19-4AB7-8(A19-A11-)A3-A10-A4-15(A11-A19-)A11-A3-A10-A4-4(A11-A19-)A7-2(4A21-AB3A2-)4A21-AB3A5-8(A21-AB8-)A4-A10-A5-15(AB8-A21-)AB8-A4-A10-A5-4(AB8-A21-)AB4-2(3AB23-4A-)3AB23-4A4-8(B23-A7-)B5-A10-A6-15(A7-B23-)A7-B5-A10-A6-4(A7-B23-)A4-2(4A2(24-8A)24-4A3-8(A24-A6-)A5-A10-A7-15(A6-A24-)A6-A5-A10-A7-4(A6-A24-)A3-)3A2(25-7A)25-4A2-8(A25-A5-)A6-A10-A7-15(A5-A25-)A5-A6-A10-A7-4(A5-A25-)A3-3A2(26-6A)26-3A2-8(A31-)A6-A10-A13-15(A31-)A6-A10-A13-3(A31-)A29-6(2A2(27-5A)27-3A265-A10-A500-A10-A139-)3(B2A25-4A)265-A10-A500-A10-A140-2(2A25-3AB-)2A25-3AB265-A10-A500-A10-A140-2(2A25-3A2-)2A25-3A266-A10-A500-A10-A141-2(2A23-3A4-)2A23-3A267-A10-A500-A10-A141-2(3A21-4A4-)3A21-4A267-A10-A500-A10-A142-2(2A21-3A6-)2A21-3A268-A10-A500-A10-A142-2(3A19-3AB6-)3A19-3AB268-A10-A500-A10-A143-B2AL2(15-5A8-B3A)15-5A269-A10-A500-A10-A145-ALA2(13-4A12-3A)13-4A271-A10-A500-A10-A146-L4A2(7-6A14-5A)7-6A272-A10-A500-A10-A147-2(AB4AB5ABA18-)AB4AB5ABA24-7(BA30-)BA25-B4AB5AB23-14(2AB3A26-)2AB3A23-B4AB5AB139-
