model
size = 29 23 31, scale = 0.05, origin = -y
material 
  colors = A:#FF3 B:#777 C:#F09 D:#CFF E:#FFF F:#CCC G:#F99 H:#F60 I:#FC0 J:#FCC K:#CC0 L:#CF9 M:#CC6 N:#CC9 O:#F96 P:#F3F Q:#FFC R:#F6F S:#CF6 T:#F30 U:#F6C V:#F69 W:#FF9 X:#CC3 Y:#FCF Z:#FC3 Aa:#FF6 Ab:#CF3 Ac:#F9F Ad:#F33 Ae:#FC9 Af:#F36 Ag:#F66 Ah:#CCF Ai:#FC6 Aj:#F03 Ak:#FF0 Al:#F00 Am:#F3C An:#F06 Ao:#CF0 Ap:#F0F Aq:#F9C Ar:#F93 As:#F39 At:#CFC Au:#F0C Av:#F63 Aw:#F90
voxels
- AmK - - - - - - - - - - - - - - - - - - - - - - - - AoW   - AeAl- - - - - - - - - - - - - - - - - - - - - - - AnR -   - - R Z - - - - - - - - - - - - - - - - - - - S Y X AnAm-   - - Q U AsJ Ab- - - - - - - - - - - - - - AkAaAsQ - - - -   - - - - AgArAjI P - - - - - - - - - - AcArAbAr- - - - - -   - - - - - - - AjAaAqF M AiX AhU M W V U Z A - - - - - - -   - - - - - - - - - - - - - - - - - - - - - - - - - - - - -   - - - - - - - - - - - - - - - - - - - - - - - - - - - - -   - - - - - - - - - - - - - - - - - - - - - - - - - - - - -   - - - - - - - - - - - - - - - - - - - - - - - - - - - - -   - - - - - - - - - - - - - - - - - - - - - - - - - - - - -   - - - - - - - - - - - - - - - - - - - - - - - - - - - - -   - - - - - - - - - - - - - - - - - - - - - - - - - - - - -   - - - - - - - - - - - - - - - - - - - - - - - - - - - - -   - - - - - - - - - - - - - - - - - - - - - - - - - - - - -   - - - - - - - - - - - - - - - - - - - - - - - - - - - - -   - - - - - - - - - - - - - - - - - - - - - - - - - - - - -   - - - - - - - - - - - - - - - - - - - - - - - - - - - - -   - - - - - - - - - - - - - - - - - - - - - - - - - - - - -   - - - - - - - - - - - - - - - - - - - - - - - - - - - - -   - - - - - - - - - - - - - - - - - - - - - - - - - - - - -   - - - - - - - - - - - - - - - - - - - - - - - - - - - - -   - - - - - - - - - - - - - - - - - - - - - - - - - - - - -   
- E Aw- - - - - - - - - - - - - - - - - - - - - - - - P An  - AsAd- - - - - - - - - - - - - - - - - - - - - - - U Aa-   - - D Af- - - - - - - - - - - - - - - - - - - A AlAaAmM -   - - F I C K Y - - - - - - - - - - - - - - AuG A R - - - -   - - - - AmE A AtAf- - - - - - - - - - H AqAwK - - - - - -   - - - - - - - J AkW Q W U V S X K O AdX M C - - - - - - -   - - - - - - - - - - - - - - - - - - - - - - - - - - - - -   - - - - - - - - - - - - - - - - - - - - - - - - - - - - -   - - - - - - - - - - - - - - - - - - - - - - - - - - - - -   - - - - - - - - - - - - - - - - - - - - - - - - - - - - -   - - - - - - - - - - - - - - - - - - - - - - - - - - - - -   - - - - - - - - - - - - - - - - - - - - - - - - - - - - -   - - - - - - - - - - - - - - - - - - - - - - - - - - - - -   - - - - - - - - - - - - - - - - - - - - - - - - - - - - -   - - - - - - - - - - - - - - - - - - - - - - - - - - - - -   - - - - - - - - - - - - - - - - - - - - - - - - - - - - -   - - - - - - - - - - - - - - - - - - - - - - - - - - - - -   - - - - - - - - - - - - - - - - - - - - - - - - - - - - -   - - - - - - - - - - - - - - - - - - - - - - - - - - - - -   - - - - - - - - - - - - - - - - - - - - - - - - - - - - -   - - - - - - - - - - - - - - - - - - - - - - - - - - - - -   - - - - - - - - - - - - - - - - - - - - - - - - - - - - -   - - - - - - - - - - - - - - - - - - - - - - - - - - - - -   
- V F - - - - - - - - - - - - - - - - - - - - - - - - AeX   - AuAi- - - - - - - - - - - - - - - - - - - - - - - Q A -   - - G Aj- - - - - - - - - - - - - - - - - - - A U L E S -   - - K AoX P Ag- - - - - - - - - - - - - - J AbAeAt- - - -   - - - - R AhH AeAl- - - - - - - - - - AtG ApAf- - - - - -   - - - - - - - AsAqE O O X AuAtF C O K V K Ag- - - - - - -   - - - - - - - - - - - - - - - - - - - - - - - - - - - - -   - - - - - - - - - - - - - - - - - - - - - - - - - - - - -   - - - - - - - - - - - - - - - - - - - - - - - - - - - - -   - - - - - - - - - - - - - - - - - - - - - - - - - - - - -   - - - - - - - - - - - - - - - - - - - - - - - - - - - - -   - - - - - - - - - - - - - - - - - - - - - - - - - - - - -   - - - - - - - - - - - - - - - - - - - - - - - - - - - - -   - - - - - - - - - - - - - - - - - - - - - - - - - - - - -   - - - - - - - - - - - - - - - - - - - - - - - - - - - - -   - - - - - - - - - - - - - - - - - - - - - - - - - - - - -   - - - - - - - - - - - - - - - - - - - - - - - - - - - - -   - - - - - - - - - - - - - - - - - - - - - - - - - - - - -   - - - - - - - - - - - - - - - - - - - - - - - - - - - - -   - - - - - - - - - - - - - - - - - - - - - - - - - - - - -   - - - - - - - - - - - - - - - - - - - - - - - - - - - - -   - - - - - - - - - - - - - - - - - - - - - - - - - - - - -   - - - - - - - - - - - - - - - - - - - - - - - - - - - - -   
- A R - - - - - - - - - - - - - - - - - - - - - - - - T An  - Y Am- - - - - - - - - - - - - - - - - - - - - - - Q Ai-   - - AeE - - - - - - - - - - - - - - - - - - - A Q X X Ak-   - - A AsX W D - - - - - - - - - - - - - - J N AcF - - - -   - - - - AcN J X Ad- - - - - - - - - - G AcP Z - - - - - -   - - - - - - - R AhL AbAvF Y K Q AgAvD AuC Ah- - - - - - -   - - - - - - - - - - - - - - - - - - - - - - - - - - - - -   - - - - - - - - - - - - - - - - - - - - - - - - - - - - -   - - - - - - - - - - - - - - - - - - - - - - - - - - - - -   - - - - - - - - - - - - - - - - - - - - - - - - - - - - -   - - - - - - - - - - - - - - - - - - - - - - - - - - - - -   - - - - - - - - - - - - - - - - - - - - - - - - - - - - -   - - - - - - - - - - - - - - - - - - - - - - - - - - - - -   - - - - - - - - - - - - - - - - - - - - - - - - - - - - -   - - - - - - - - - - - - - - - - - - - - - - - - - - - - -   - - - - - - - - - - - - - - - - - - - - - - - - - - - - -   - - - - - - - - - - - - - - - - - - - - - - - - - - - - -   - - - - - - - - - - - - - - - - - - - - - - - - - - - - -   - - - - - - - - - - - - - - - - - - - - - - - - - - - - -   - - - - - - - - - - - - - - - - - - - - - - - - - - - - -   - - - - - - - - - - - - - - - - - - - - - - - - - - - - -   - - - - - - - - - - - - - - - - - - - - - - - - - - - - -   - - - - - - - - - - - - - - - - - - - - - - - - - - - - -   
- O R - - - - - - - - - - - - - - - - - - - - - - - - AqAp  - AwE - - - - - - - - - - - - - - - - - - - - - - - AeAb-   - - AcAn- - - - - - - - - - - - - - - - - - - A C G AaD -   - - K AvD AeS - - - - - - - - - - - - - - AkAiL Ai- - - -   - - - - J W AjAvF - - - - - - - - - - K I AeAn- - - - - -   - - - - - - - S ArAiQ G Q D AkO AdR AuY AgS - - - - - - -   - - - - - - - - - - - - - - - - - - - - - - - - - - - - -   - - - - - - - - - - - - - - - - - - - - - - - - - - - - -   - - - - - - - - - - - - - - - - - - - - - - - - - - - - -   - - - - - - - - - - - - - - - - - - - - - - - - - - - - -   - - - - - - - - - - - - - - - - - - - - - - - - - - - - -   - - - - - - - - - - - - - - - - - - - - - - - - - - - - -   - - - - - - - - - - - - - - - - - - - - - - - - - - - - -   - - - - - - - - - - - - - - - - - - - - - - - - - - - - -   - - - - - - - - - - - - - - - - - - - - - - - - - - - - -   - - - - - - - - - - - - - - - - - - - - - - - - - - - - -   - - - - - - - - - - - - - - - - - - - - - - - - - - - - -   - - - - - - - - - - - - - - - - - - - - - - - - - - - - -   - - - - - - - - - - - - - - - - - - - - - - - - - - - - -   - - - - - - - - - - - - - - - - - - - - - - - - - - - - -   - - - - - - - - - - - - - - - - - - - - - - - - - - - - -   - - - - - - - - - - - - - - - - - - - - - - - - - - - - -   - - - - - - - - - - - - - - - - - - - - - - - - - - - - -   
- AjF - - - - - - - - - - - - - - - - - - - - - - - - P V   - Z Ar- - - - - - - - - - - - - - - - - - - - - - - O P -   - - AoJ - - - - - - - - - - - - - - - - - - - A AvD L Aa-   - - R ApL AgG - - - - - - - - - - - - - - AeQ Y T - - - -   - - - - V AlX Z E - - - - - - - - - - AdAwAaF - - - - - -   - - - - - - - AdAfAbN AmO H A AbY G AcD AdAt- - - - - - -   - - - - - - - - - - - - - - - - - - - - - - - - - - - - -   - - - - - - - - - - - - - - - - - - - - - - - - - - - - -   - - - - - - - - - - - - - - - - - - - - - - - - - - - - -   - - - - - - - - - - - - - - - - - - - - - - - - - - - - -   - - - - - - - - - - - - - - - - - - - - - - - - - - - - -   - - - - - - - - - - - - - - - - - - - - - - - - - - - - -   - - - - - - - - - - - - - - - - - - - - - - - - - - - - -   - - - - - - - - - - - - - - - - - - - - - - - - - - - - -   - - - - - - - - - - - - - - - - - - - - - - - - - - - - -   - - - - - - - - - - - - - - - - - - - - - - - - - - - - -   - - - - - - - - - - - - - - - - - - - - - - - - - - - - -   - - - - - - - - - - - - - - - - - - - - - - - - - - - - -   - - - - - - - - - - - - - - - - - - - - - - - - - - - - -   - - - - - - - - - - - - - - - - - - - - - - - - - - - - -   - - - - - - - - - - - - - - - - - - - - - - - - - - - - -   - - - - - - - - - - - - - - - - - - - - - - - - - - - - -   - - - - - - - - - - - - - - - - - - - - - - - - - - - - -   
- J Ak- - - - - - - - - - - - - - - - - - - - - - - - AhAi  - P I - - - - - - - - - - - - - - - - - - - - - - - J Aa-   - - H T - - - - - - - - - - - - - - - - - - - A AfA X Ar-   - - F P AeR Ag- - - - - - - - - - - - - - I Q E P - - - -   - - - - A U H AjAs- - - - - - - - - - AgA AlAn- - - - - -   - - - - - - - Z AgF T AeAbAwD Q AoAnM H Y K - - - - - - -   - - - - - - - - - - - - - - - - - - - - - - - - - - - - -   - - - - - - - - - - - - - - - - - - - - - - - - - - - - -   - - - - - - - - - - - - - - - - - - - - - - - - - - - - -   - - - - - - - - - - - - - - - - - - - - - - - - - - - - -   - - - - - - - - - - - - - - - - - - - - - - - - - - - - -   - - - - - - - - - - - - - - - - - - - - - - - - - - - - -   - - - - - - - - - - - - - - - - - - - - - - - - - - - - -   - - - - - - - - - - - - - - - - - - - - - - - - - - - - -   - - - - - - - - - - - - - - - - - - - - - - - - - - - - -   - - - - - - - - - - - - - - - - - - - - - - - - - - - - -   - - - - - - - - - - - - - - - - - - - - - - - - - - - - -   - - - - - - - - - - - - - - - - - - - - - - - - - - - - -   - - - - - - - - - - - - - - - - - - - - - - - - - - - - -   - - - - - - - - - - - - - - - - - - - - - - - - - - - - -   - - - - - - - - - - - - - - - - - - - - - - - - - - - - -   - - - - - - - - - - - - - - - - - - - - - - - - - - - - -   - - - - - - - - - - - - - - - - - - - - - - - - - - - - -   
- D Ai- - - - - - - - - - - - - - - - - - - - - - - - AeU   - J An- - - - - - - - - - - - - - - - - - - - - - - AcS -   - - AvZ - - - - - - - - - - - - - - - - - - - A O M G Ap-   - - S AdC O Ah- - - - - - - - - - - - - - J F AoAt- - - -   - - - - AaAtN S Ae- - - - - - - - - - AmArX Ar- - - - - -   - - - - - - - ApA AcL ArQ E T N AkO G AwAoAk- - - - - - -   - - - - - - - - - - - - - - - - - - - - - - - - - - - - -   - - - - - - - - - - - - - - - - - - - - - - - - - - - - -   - - - - - - - - - - - - - - - - - - - - - - - - - - - - -   - - - - - - - - - - - - - - - - - - - - - - - - - - - - -   - - - - - - - - - - - - - - - - - - - - - - - - - - - - -   - - - - - - - - - - - - - - - - - - - - - - - - - - - - -   - - - - - - - - - - - - - - - - - - - - - - - - - - - - -   - - - - - - - - - - - - - - - - - - - - - - - - - - - - -   - - - - - - - - - - - - - - - - - - - - - - - - - - - - -   - - - - - - - - - - - - - - - - - - - - - - - - - - - - -   - - - - - - - - - - - - - - - - - - - - - - - - - - - - -   - - - - - - - - - - - - - - - - - - - - - - - - - - - - -   - - - - - - - - - - - - - - - - - - - - - - - - - - - - -   - - - - - - - - - - - - - - - - - - - - - - - - - - - - -   - - - - - - - - - - - - - - - - - - - - - - - - - - - - -   - - - - - - - - - - - - - - - - - - - - - - - - - - - - -   - - - - - - - - - - - - - - - - - - - - - - - - - - - - -   
- M Ad- - - - - - - - - - - - - - - - - - - - - - - - AlAp  - ApAi- - - - - - - - - - - - - - - - - - - - - - - N R -   - - N Ah- - - - - - - - - - - - - - - - - - - A AfX D Q -   - - AoO AjC P - - - - - - - - - - - - - - M K AhE - - - -   - - - - V AbC I Z - - - - - - - - - - R E AuI - - - - - -   - - - - - - - H H H J AmN AfZ T AfAtF E AkA - - - - - - -   - - - - - - - - - - - - - - - - - - - - - - - - - - - - -   - - - - - - - - - - - - - - - - - - - - - - - - - - - - -   - - - - - - - - - - - - - - - - - - - - - - - - - - - - -   - - - - - - - - - - - - - - - - - - - - - - - - - - - - -   - - - - - - - - - - - - - - - - - - - - - - - - - - - - -   - - - - - - - - - - - - - - - - - - - - - - - - - - - - -   - - - - - - - - - - - - - - - - - - - - - - - - - - - - -   - - - - - - - - - - - - - - - - - - - - - - - - - - - - -   - - - - - - - - - - - - - - - - - - - - - - - - - - - - -   - - - - - - - - - - - - - - - - - - - - - - - - - - - - -   - - - - - - - - - - - - - - - - - - - - - - - - - - - - -   - - - - - - - - - - - - - - - - - - - - - - - - - - - - -   - - - - - - - - - - - - - - - - - - - - - - - - - - - - -   - - - - - - - - - - - - - - - - - - - - - - - - - - - - -   - - - - - - - - - - - - - - - - - - - - - - - - - - - - -   - - - - - - - - - - - - - - - - - - - - - - - - - - - - -   - - - - - - - - - - - - - - - - - - - - - - - - - - - - -   
- M Au- - - - - - - - - - - - - - - - - - - - - - - - AhL   - AdAs- - - - - - - - - - - - - - - - - - - - - - - Y N -   - - AgL - - - - - - - - - - - - - - - - - - - A V G A Aq-   - - H M I S Af- - - - - - - - - - - - - - AqA AsT - - - -   - - - - H AsAkAkW - - - - - - - - - - AcAhAcS - - - - - -   - - - - - - - AeAcP W A T ArApL Z E A AfAfD - - - - - - -   - - - - - - - - - - - - - - - - - - - - - - - - - - - - -   - - - - - - - - - - - - - - - - - - - - - - - - - - - - -   - - - - - - - - - - - - - - - - - - - - - - - - - - - - -   - - - - - - - - - - - - - - - - - - - - - - - - - - - - -   - - - - - - - - - - - - - - - - - - - - - - - - - - - - -   - - - - - - - - - - - - - - - - - - - - - - - - - - - - -   - - - - - - - - - - - - - - - - - - - - - - - - - - - - -   - - - - - - - - - - - - - - - - - - - - - - - - - - - - -   - - - - - - - - - - - - - - - - - - - - - - - - - - - - -   - - - - - - - - - - - - - - - - - - - - - - - - - - - - -   - - - - - - - - - - - - - - - - - - - - - - - - - - - - -   - - - - - - - - - - - - - - - - - - - - - - - - - - - - -   - - - - - - - - - - - - - - - - - - - - - - - - - - - - -   - - - - - - - - - - - - - - - - - - - - - - - - - - - - -   - - - - - - - - - - - - - - - - - - - - - - - - - - - - -   - - - - - - - - - - - - - - - - - - - - - - - - - - - - -   - - - - - - - - - - - - - - - - - - - - - - - - - - - - -   
- AvE - - - - - - - - - - - - - - - - - - - - - - - - AuE   - T Ac- - - - - - - - - - - - - - - - - - - - - - - AbA -   - - K Ad- - - - - - - - - - - - - - - - - - - A L AoM Y -   - - AlD AcZ Af- - - - - - - - - - - - - - AfK O Aa- - - -   - - - - C U E R T - - - - - - - - - - J N AvAl- - - - - -   - - - - - - - U AiY P I L A AlJ N V AvArZ T - - - - - - -   - - - - - - - - - - - - - - - - - - - - - - - - - - - - -   - - - - - - - - - - - - - - - - - - - - - - - - - - - - -   - - - - - - - - - - - - - - - - - - - - - - - - - - - - -   - - - - - - - - - - - - - - - - - - - - - - - - - - - - -   - - - - - - - - - - - - - - - - - - - - - - - - - - - - -   - - - - - - - - - - - - - - - - - - - - - - - - - - - - -   - - - - - - - - - - - - - - - - - - - - - - - - - - - - -   - - - - - - - - - - - - - - - - - - - - - - - - - - - - -   - - - - - - - - - - - - - - - - - - - - - - - - - - - - -   - - - - - - - - - - - - - - - - - - - - - - - - - - - - -   - - - - - - - - - - - - - - - - - - - - - - - - - - - - -   - - - - - - - - - - - - - - - - - - - - - - - - - - - - -   - - - - - - - - - - - - - - - - - - - - - - - - - - - - -   - - - - - - - - - - - - - - - - - - - - - - - - - - - - -   - - - - - - - - - - - - - - - - - - - - - - - - - - - - -   - - - - - - - - - - - - - - - - - - - - - - - - - - - - -   - - - - - - - - - - - - - - - - - - - - - - - - - - - - -   
- C A - - - - - - - - - - - - - - - - - - - - - - - - I G   - AiS - - - - - - - - - - - - - - - - - - - - - - - AgH -   - - AjL - - - - - - - - - - - - - - - - - - - A I W X F -   - - V F M AkAo- - - - - - - - - - - - - - AtR Q Al- - - -   - - - - C G F Z G - - - - - - - - - - V W J Am- - - - - -   - - - - - - - L AhI H P J S W W I AbAoA N Z - - - - - - -   - - - - - - B A A A A A A A A A A A A A A A B - - - - - -   - - - - - - - - - - - - - - - - - - - - - - - - - - - - -   - - - - - - - - - - - - - - - - - - - - - - - - - - - - -   - - - - - - - - - - - - - - - - - - - - - - - - - - - - -   - - - - - - - - - - - - - - - - - - - - - - - - - - - - -   - - - - - - - - - - - - - - - - - - - - - - - - - - - - -   - - - - - - - - - - - - - - - - - - - - - - - - - - - - -   - - - - - - - - - - - - - - - - - - - - - - - - - - - - -   - - - - - - - - - - - - - - - - - - - - - - - - - - - - -   - - - - - - - - - - - - - - - - - - - - - - - - - - - - -   - - - - - - - - - - - - - - - - - - - - - - - - - - - - -   - - - - - - - - - - - - - - - - - - - - - - - - - - - - -   - - - - - - - - - - - - - - - - - - - - - - - - - - - - -   - - - - - - - - - - - - - - - - - - - - - - - - - - - - -   - - - - - - - - - - - - - - - - - - - - - - - - - - - - -   - - - - - - - - - - - - - - - - - - - - - - - - - - - - -   - - - - - - - - - - - - - - - - - - - - - - - - - - - - -   
- F Ac- - - - - - - - - - - - - - - - - - - - - - - - U At  - E G - - - - - - - - - - - - - - - - - - - - - - - O Av-   - - AuV - - - - - - - - - - - - - - - - - - - A K H G T -   - - AwAuA A U - - - - - - - - - - - - - - AqA A Ar- - - -   - - - - AmAqT L O - - - - - - - - - - A AlM A - - - - - -   - - - - - - - AaL AiAdU W ApD P T AsE S I Ap- - - - - - -   - - - - - - B A A A A A A A A A A A A A A A B - - - - - -   - - - - - A A A A A A A A A A A A A A A A A A A A - - - -   - - - - A A A A A A A A A A A A A A A A A A A A A A - - -   - - - - - - - - - - - - - - - - - - - - - - - - - - - - -   - - - - - - - - - - - - - - - - - - - - - - - - - - - - -   - - - - - - - - - - - - - - - - - - - - - - - - - - - - -   - - - - - - - - - - - - - - - - - - - - - - - - - - - - -   - - - - - - - - - - - - - - - - - - - - - - - - - - - - -   - - - - - - - - - - - - - - - - - - - - - - - - - - - - -   - - - - - - - - - - - - - - - - - - - - - - - - - - - - -   - - - - - - - - - - - - - - - - - - - - - - - - - - - - -   - - - - - - - - - - - - - - - - - - - - - - - - - - - - -   - - - - - - - - - - - - - - - - - - - - - - - - - - - - -   - - - - - - - - - - - - - - - - - - - - - - - - - - - - -   - - - - - - - - - - - - - - - - - - - - - - - - - - - - -   - - - - - - - - - - - - - - - - - - - - - - - - - - - - -   - - - - - - - - - - - - - - - - - - - - - - - - - - - - -   
- Y Q - - - - - - - - - - - - - - - - - - - - - - - - L Y   - K D - - - - - - - - - - - - - - - - - - - - - - - N M -   - - I R - - - - - - - - - - - - - - - - - - - A N E AoAd-   - - AjAmV T Au- - - - - - - - - - - - - - G A A O - - - -   - - - - T AhS Y D - - - - - - - - - - AaU I Q - - - - - -   - - - - - - - K F D AnAvP N AhH AsM S ApT Al- - - - - - -   - - - - - - B - - - - - - - - - A A A A A A B - - - - - -   - - - - - A A A A A A A A A A A A A A A A A A A A - - - -   - - - - A A A A A A A A A A A A A A A A A A A A A A - - -   - - - A A A A A A A A A A A A A A A A A A A A A A A A - -   - - - - - - - - - - - - - - - - - - - - - - - - - - - - -   - - - - - - - - - - - - - - - - - - - - - - - - - - - - -   - - - - - - - - - - - - - - - - - - - - - - - - - - - - -   - - - - - - - - - - - - - - - - - - - - - - - - - - - - -   - - - - - - - - - - - - - - - - - - - - - - - - - - - - -   - - - - - - - - - - - - - - - - - - - - - - - - - - - - -   - - - - - - - - - - - - - - - - - - - - - - - - - - - - -   - - - - - - - - - - - - - - - - - - - - - - - - - - - - -   - - - - - - - - - - - - - - - - - - - - - - - - - - - - -   - - - - - - - - - - - - - - - - - - - - - - - - - - - - -   - - - - - - - - - - - - - - - - - - - - - - - - - - - - -   - - - - - - - - - - - - - - - - - - - - - - - - - - - - -   - - - - - - - - - - - - - - - - - - - - - - - - - - - - -   
- G Ak- - - - - - - - - - - - - - - - - - - - - - - - AbAt  - K W - - - - - - - - - - - - - - - - - - - - - - - AmD -   - - AoE - - - - - - - - - - - - - - - - - - - A AwAuW Ac-   - - J AgAnR G - - - - - - - - - - - - - - I A A L - - - -   - - - - AaH S Y D - - - - - - - - - - V AtAjAp- - - - - -   - - - - - - - G J K O AiH F P AdAjC Z N AsW - - - - - - -   - - - - - - B A A A A A A A A A A A A A A A B - - - - - -   - - - - - A A A A A A A A A A A A A A A A A A A A - - - -   - - - - A A A A A A A A A A A A A A A A A A A A A A - - -   - - - A A A A A A A A A A A A A A A A A A A A A A A A - -   - - A A A A A A A A A A A A A A A A A A A A A A A A A A -   - A A A A A A A A A A A A A A A A A A A A A A A A A A A -   - A A A A A A A A A A A - A A A A A A A A A A A A A A A A   A A A A A A A A A - - - - A A A - A A - - - A A A A A A A   A A A A A A A A A A - A A - A A - A A - A A A A A A A A A   A A A A A A A A A A - A - A A A - A A - A A A A A A A A A   A A A A A A A A A A - A A - A A - A A - A A A A A A A A A   A A A A A A A A - - - - - A A - - - A - - - A A A A A A A   - A A A A A A A A A A A A A A A A A A A A A A A A A A A -   - - - - - - - - - - - - - - - - - - - - - - - - - - - - -   - - - - - - - - - - - - - - - - - - - - - - - - - - - - -   - - - - - - - - - - - - - - - - - - - - - - - - - - - - -   - - - - - - - - - - - - - - - - - - - - - - - - - - - - -   
- E L - - - - - - - - - - - - - - - - - - - - - - - - D V   - AfV - - - - - - - - - - - - - - - - - - - - - - - R I -   - - A Aq- - - - - - - - - - - - - - - - - - - A AlN H Aj-   - - AqU M AaAn- - - - - - - - - - - - - - AqA A Aq- - - -   - - - - ApM AbD P - - - - - - - - - - H AbAbA - - - - - -   - - - - - - - J C AmI AaAdU E AnAgAoY F AjD - - - - - - -   - - - - - - B A A A A A A A A A A A A A A A B - - - - - -   - - - - - A A A A A A A A A A A A A A A A A A A A - - - -   - - - - A A A A A A A A A A A A A A A A A A A A A A - - -   - - - A A A A A A A A A A A A A A A A A A A A A A A A - -   - - A A A A A A A A A A A A A A A A A A A A A A A A A A -   - A A A A A A A A A A A A A A A A A A A A A A A A A A A B   B C C C C C C C C C C C C C C C C C C C C C C C C C C C A   A C C C C C C C C C - C C C C C C C C C C C C C C C C C A   A C C C C C C C C C C C C C C C - C C C C C C C C C C C A   A C C C C C C C C C C C C C C C C C C C C C C C C C C C A   A C C C C C C C C C C C C C C C C C C C C C C C C C C C A   A C C C C C C C C C C C C C C C - C C C C C C C C C C C A   B A A A A A A A A A A A A A A A C A A A A A A A A A A A B   - B B B B B B B B B B B B B B B B B B B B B B B B B B B -   - - - - - - - - - - - - - - - - - - - - - - - - - - - - -   - - - - - - - - - - - - - - - - - - - - - - - - - - - - -   - - - - - - - - - - - - - - - - - - - - - - - - - - - - -   
- A A - - - - - - - - - - - - - - - - - - - - - - - - A A   - A A - - - - - - - - - - - - - - - - - - - - - - - A A -   - - A A - - - - - - - - - - - - - - - - - - - A A A A A -   - - A A A A A - - - - - - - - - - - - - - A A A A - - - -   - - - - A A A A A - - - - - - - - - - A A A A - - - - - -   - - - - - - - A A A A A A A A A A A A A A A - - - - - - -   - - - - - - B A A A A A A A A A A A A A A A B - - - - - -   - - - - - A A A A A A A A A A A A A A A A A A A A - - - -   - - - - A A A A A A A A A A A A A A A A A A A A A A - - -   - - - A A A A A A A A A A A A A A A A A A A A A A A A - -   - - A A A A A A A A A A A A A A A A A A A A A A A A A A -   - A A A A A A A A A A A A A A A A A A A A A A A A A A A B   B A A A A A A A A A A A A A A A A A A A A A A A A A A A A   A C C C C C C C C C C C C C C C C C C C C C C C C C C C A   A C C C C C C C C C C C C C C C C C C C C C C C C C C C A   A A A A A A A A A A A A A A A A A A A A A A A A A A A A A   A A A A A A A A A A A A A A A A A A A A A A A A A A A A A   A A A A A A A A A A A A A A A A - A A A A A A A A A A A A   B A A A A A A A A A A A A A A A C A A A A A A A A A A A B   - B B B B B B B B B B B B B B B B B B B B B B B B B B B -   - - B B B B B B B B B B B B B B B B B B B B B B B B B B -   - - - - - - - - - - - - - - - - - - - - - - - - - - - - -   - - - - - - - - - - - - - - - - - - - - - - - - - - - - -   
- A A - - - - - - - - - - - - - - - - - - - - - - - - A A   - A A - - - - - - - - - - - - - - - - - - - - - - - A A -   - - A A - - - - - - - - - - - - - - - - - - - A A A A A -   - - A A A A A - - - - - - - - - - - - - - A A A A - - - -   - - - - A A A A A - - - - - - - - - - A A A A - - - - - -   - - - - - - - A A A A A A A A A A A A A A A - - - - - - -   - - - - - - B A A A A A A A A A A A A A A A B - - - - - -   - - - - - A A A A A A A A A A A A A A A A A A A A - - - -   - - - - A A A A A A A A A A A A A A A A A A A A A A - - -   - - - A A A A A A A A A A A A A A A A A A A A A A A A - -   - - A A A A A A A A A A A A A A A A A A A A A A A A A A -   - A A A A A A A A A A A A A A A A A A A A A A A A A A A B   B A A A A A A A A A A A A A A A A A A A A A A A A A A A A   A A A A A A A A A A A A A A A A A A A A A A A A A A A A A   A A A A A A A A A A A A A A A A A A A A A A A A A A A A A   A A A A A A A A A A A A A A A A A A A A A A A A A A A A A   A A A A A A A A A A A A A A A A A A A A A A A A A A A A A   A C C C C C C C C C C C C C C C C C C C C C C C C C C C A   B A A A A A A A A A A A A A A A A A A A A A A A A A A A B   - B B B B B B B B B B B B B B B B B B B B B B B B B B B -   - - B B B B B B B B B B B B B B B B B B B B B B B B B B -   - - - B B B B B B B B B B B B B B B B B B B B B B B B - -   - - - - - - - - - - - - - - - - - - - - - - - - - - - - -   
- A A - - - - - - - - - - - - - - - - - - - - - - - - A A   - A A - - - - - - - - - - - - - - - - - - - - - - - A A -   - - A A - - - - - - - - - - - - - - - - - - - A A A A A -   - - A A A A A - - - - - - - - - - - - - - A A A A - - - -   - - - - A A A A A - - - - - - - - - - A A A A - - - - - -   - - - - - - - A A A A A A A A A A A A A A A - - - - - - -   - - - - - - B A A A A A A A A A A A A A A A B - - - - - -   - - - - - A A A A A A A A A A A A A A A A A A A A - - - -   - - - - A A A A A A A A A A A A A A A A A A A A A A - - -   - - - A A A A A A A A A A A A A A A A A A A A A A A A - -   - - A A A A A A A A A A A A A A A A A A A A A A A A A A -   - A A A A A A A A A A A A A A A A A A A A A A A A A A A B   B A A A A A A A A A A A A A A A A A A A A A A A A A A A A   A A A A A A A A A A A A A A A A A A A A A A A A A A A A A   A A A A A A A A A A A A A A A A A A A A A A A A A A A A A   A A A A A A A A A A A A A A A A A A A A A A A A A A A A A   A A A A A A A A A A A A A A A A A A A A A A A A A A A A A   A A A A A A A A A A A A A A A A A A A A A A A A A A A A A   B A A A A A A A A A A A A A A A A A A A A A A A A A A A B   - B B B B B B B B B B B B B B B B B B B B B B B B B B B -   - - B B B B B B B B B B B B B B B B B B B B B B B B B B -   - - - B B B B B B B B B B B B B B B B B B B B B B B B - -   - - - - B B B B B B B B B B B B B B B B B B B B B B - - -   
- A A - - - - - - - - - - - - - - - - - - - - - - - - A A   - A A - - - - - - - - - - - - - - - - - - - - - - - A A -   - - A A - - - - - - - - - - - - - - - - - - - A A A A A -   - - A A A A A - - - - - - - - - - - - - - A A A A - - - -   - - - - A A A A A - - - - - - - - - - A A A A - - - - - -   - - - - - - - A A A A A A A A A A A A A A A - - - - - - -   - - - - - - B A A A A A A A A A A A A A A A B - - - - - -   - - - - - A A A A A A A A A A A A A A A A A A A A - - - -   - - - - A A A A A A A A A A A A A A A A A A A A A A - - -   - - - A A A A A A A A A A A A A A A A A A A A A A A A - -   - - A A A A A A A A A A A A A A A A A A A A A A A A A A -   - A A A A A A A A A A A A A A A A A A A A A A A A A A A B   B A A A A A A A A A A A A A A A A A A A A A A A A A A A A   A A A A A A A A A A A A A A A A A A A A A A A A A A A A A   A A A A A A A A A A A A A A A A A A A A A A A A A A A A A   A A A A A A A A A A A A A A A A A A A A A A A A A A A A A   A A A A A A A A A A A A A A A A A A A A A A A A A A A A A   A A A A A A A A A A A A A A A A A A A A A A A A A A A A A   B A A A A A A A A A A A A A A A A A A A A A A A A A A A B   - B B B B B B B B B B B B B B B B B B B B B B B B B B B -   - - B B B B B B B B B B B B B B B B B B B B B B B B B B -   - - - B B B B B B B B B B B B B B B B B B B B B B B B - -   - - - - B B B B B B B B B B B B B B B B B B B B B B - - -   
- A A - - - - - - - - - - - - - - - - - - - - - - - - A A   - A A - - - - - - - - - - - - - - - - - - - - - - - A A -   - - A A - - - - - - - - - - - - - - - - - - - A A A A A -   - - A A A A A - - - - - - - - - - - - - - A A A A - - - -   - - - - A A A A A - - - - - - - - - - A A A A - - - - - -   - - - - - - - A A A A A A A A A A A A A A A - - - - - - -   - - - - - - B A A A A A A A A A A A A A A A B - - - - - -   - - - - - A A A A A A A A A A A A A A A A A A A A - - - -   - - - - A A A A A A A A A A A A A A A A A A A A A A - - -   - - - A A A A A A A A A A A A A A A A A A A A A A A A - -   - - A A A A A A A A A A A A A A A A A A A A A A A A A A -   - A A A A A A A A A A A A A A A A A A A A A A A A A A A B   B A A A A A A A A A A A A A A A A A A A A A A A A A A A A   A A A A A A A A A A A A A A A A A A A A A A A A A A A A A   A A A A A A A A A A A A A A A A A A A A A A A A A A A A A   A A A A A A A A A A A A A A A A A A A A A A A A A A A A A   A A A A A A A A A A A A A A A A A A A A A A A A A A A A A   A A A A A A A A A A A A A A A A A A A A A A A A A A A A A   B A A A A A A A A A A A A A A A A A A A A A A A A A A A B   - B B B B B B B B B B B B B B B B B B B B B B B B B B B -   - - B B B B B B B B B B B B B B B B B B B B B B B B B B -   - - - B B B B B B B B B B B B B B B B B B B B B B B B - -   - - - - B B B B B B B B B B B B B B B B B B B B B B - - -   
- A A - - - - - - - - - - - - - - - - - - - - - - - - A A   - A A - - - - - - - - - - - - - - - - - - - - - - - A A -   - - A A - - - - - - - - - - - - - - - - - - - A A A A A -   - - A A A A A - - - - - - - - - - - - - - A A A A - - - -   - - - - A A A A A - - - - - - - - - - A A A A - - - - - -   - - - - - - - A A A A A A A A A A A A A A A - - - - - - -   - - - - - - B A A A A A A A A A A A A A A A B - - - - - -   - - - - - A A A A A A A A A A A A A A A A A A A A - - - -   - - - - A A A A A A A A A A A A A A A A A A A A A A - - -   - - - A A A A A A A A A A A A A A A A A A A A A A A A - -   - - A A A A A A A A A A A A A A A A A A A A A A A A A A -   - A A A A A A A A A A A A A A A A A A A A A A A A A A A B   B A A A A A A A A A A A A A A A A A A A A A A A A A A A A   A A A A A A A A A A A A A A A A A A A A A A A A A A A A A   A A A A A A A A A A A A A A A A A A A A A A A A A A A A A   A A A A A A A A A A A A A A A A A A A A A A A A A A A A A   A A A A A A A A A A A A A A A A A A A A A A A A A A A A A   A A A A A A A A A A A A A A A A A A A A A A A A A A A A A   B A A A A A A A A A A A A A A A A A A A A A A A A A A A B   - B B B B B B B B B B B B B B B B B B B B B B B B B B B -   - - B B B B B B B B B B B B B B B B B B B B B B B B B B -   - - - B B B B B B B B B B B B B B B B B B B B B B B B - -   - - - - B B B B B B B B B B B B B B B B B B B B B B - - -   
- A A - - - - - - - - - - - - - - - - - - - - - - - - A A   - A A - - - - - - - - - - - - - - - - - - - - - - - A A -   - - A A - - - - - - - - - - - - - - - - - - - A A A A A -   - - A A A A A - - - - - - - - - - - - - - A A A A - - - -   - - - - A A A A A - - - - - - - - - - A A A A - - - - - -   - - - - - - - A A A A A A A A A A A A A A A - - - - - - -   - - - - - - B A A A A A A A A A A A A A A A B - - - - - -   - - - - - A A A A A A A A A A A A A A A A A A A A - - - -   - - - - A A A A A A A A A A A A A A A A A A A A A A - - -   - - - A A A A A A A A A A A A A A A A A A A A A A A A - -   - - A A A A A A A A A A A A A A A A A A A A A A A A A A -   - A A A A A A A A A A A A A A A A A A A A A A A A A A A B   B A A A A A A A A A A A A A A A A A A A A A A A A A A A A   A A A A A A A A A A A A A A A A A A A A A A A A A A A A A   A A A A A A A A A A A A A A A A A A A A A A A A A A A A A   A A A A A A A A A A A A A A A A A A A A A A A A A A A A A   A A A A A A A A A A A A A A A A A A A A A A A A A A A A A   A A A A A A A A A A A A A A A A A A A A A A A A A A A A A   B A A A A A A A A A A A A A A A A A A A A A A A A A A A B   - B B B B B B B B B B B B B B B B B B B B B B B B B B B -   - - B B B B B B B B B B B B B B B B B B B B B B B B B B -   - - - B B B B B B B B B B B B B B B B B B B B B B B B - -   - - - - B B B B B B B B B B B B B B B B B B B B B B - - -   
- A A - - - - - - - - - - - - - - - - - - - - - - - - A A   - A A - - - - - - - - - - - - - - - - - - - - - - - A A -   - - A A - - - - - - - - - - - - - - - - - - - A A A A A -   - - A A A A A - - - - - - - - - - - - - - A A A A - - - -   - - - - A A A A A - - - - - - - - - - A A A A - - - - - -   - - - - - - - A A A A A A A A A A A A A A A - - - - - - -   - - - - - - B A A A A A A A A A A A A A A A B - - - - - -   - - - - - A A A A A A A A A A A A A A A A A A A A - - - -   - - - - A A A A A A A A A A A A A A A A A A A A A A - - -   - - - A A A A A A A A A A A A A A A A A A A A A A A A - -   - - A A A A A A A A A A A A A A A A A A A A A A A A A A -   - A A A A A A A A A A A A A A A A A A A A A A A A A A A B   B A A A A A A A A A A A A A A A A A A A A A A A A A A A A   A A A A A A A A A A A A A A A A A A A A A A A A A A A A A   A A A A A A A A A A A A A A A A A A A A A A A A A A A A A   A A A A A A A A A A A A A A A A A A A A A A A A A A A A A   A A A A A A A A A A A A A A A A A A A A A A A A A A A A A   A A A A A A A A A A A A A A A A A A A A A A A A A A A A A   B A A A A A A A A A A A A A A A A A A A A A A A A A A A B   - B B B B B B B B B B B B B B B B B B B B B B B B B B B -   - - B B B B B B B B B B B B B B B B B B B B B B B B B B -   - - - B B B B B B B B B B B B B B B B B B B B B B B B - -   - - - - - - - - - - - - - - - - - - - - - - - - - - - - -   
- A A - - - - - - - - - - - - - - - - - - - - - - - - A A   - A A - - - - - - - - - - - - - - - - - - - - - - - A A -   - - A A - - - - - - - - - - - - - - - - - - - A A A A A -   - - A A A A A - - - - - - - - - - - - - - A A A A - - - -   - - - - A A A A A - - - - - - - - - - A A A A - - - - - -   - - - - - - - A A A A A A A A A A A A A A A - - - - - - -   - - - - - - B A A A A A A A A A A A A A A A B - - - - - -   - - - - - A A A A A A A A A A A A A A A A A A A A - - - -   - - - - A A A A A A A A A A A A A A A A A A A A A A - - -   - - - A A A A A A A A A A A A A A A A A A A A A A A A - -   - - A A A A A A A A A A A A A A A A A A A A A A A A A A -   - A A A A A A A A A A A A A A A A A A A A A A A A A A A B   B A A A A A A A A A A A A A A A A A A A A A A A A A A A A   A A A A A A A A A A A A A A A A A A A A A A A A A A A A A   A A A A A A A A A A A A A A A A A A A A A A A A A A A A A   A A A A A A A A A A A A A A A A A A A A A A A A A A A A A   A A A A A A A A A A A A A A A A A A A A A A A A A A A A A   A A A A A A A A A A A A A A A A A A A A A A A A A A A A A   B A A A A A A A A A A A A A A A A A A A A A A A A A A A B   - B B B B B B B B B B B B B B B B B B B B B B B B B B B -   - - B B B B B B B B B B B B B B B B B B B B B B B B B B -   - - - - - - - - - - - - - - - - - - - - - - - - - - - - -   - - - - - - - - - - - - - - - - - - - - - - - - - - - - -   
- A A - - - - - - - - - - - - - - - - - - - - - - - - A A   - A A - - - - - - - - - - - - - - - - - - - - - - - A A -   - - A A - - - - - - - - - - - - - - - - - - - A A A A A -   - - A A A A A - - - - - - - - - - - - - - A A A A - - - -   - - - - A A A A A - - - - - - - - - - A A A A - - - - - -   - - - - - - - A A A A A A A A A A A A A A A - - - - - - -   - - - - - - B A A A A A A A A A A A A A A A B - - - - - -   - - - - - A A A A A A A A A A A A A A A A A A A A - - - -   - - - - A A A A A A A A A A A A A A A A A A A A A A - - -   - - - A A A A A A A A A A A A A A A A A A A A A A A A - -   - - A A A A A A A A A A A A A A A A A A A A A A A A A A -   - A A A A A A A A A A A A A A A A A A A A A A A A A A A B   B A A A A A A A A A A A A A A A A A A A A A A A A A A A A   A A A A A A A A A A A A A A A A A A A A A A A A A A A A A   A A A A A A A A A A A A A A A A A A A A A A A A A A A A A   A A A A A A A A A A A A A A A A A A A A A A A A A A A A A   A A A A A A A A A A A A A A A A A A A A A A A A A A A A A   A A A A A A A A A A A A A A A A A A A A A A A A A A A A A   B A A A A A A A A A A A A A A A A A A A A A A A A A A A B   - B B B B B B B B B B B B B B B B B B B B B B B B B B B -   - - B B B B B B B B B B B B B B B B B B B B B B B B B B -   - - - - - - - - - - - - - - - - - - - - - - - - - - - - -   - - - - - - - - - - - - - - - - - - - - - - - - - - - - -   
- A A - - - - - - - - - - - - - - - - - - - - - - - - A A   - A A - - - - - - - - - - - - - - - - - - - - - - - A A -   - - A A - - - - - - - - - - - - - - - - - - - A A A A A -   - - A A A A A - - - - - - - - - - - - - - A A A A - - - -   - - - - A A A A A - - - - - - - - - - A A A A - - - - - -   - - - - - - - A A A A A A A A A A A A A A A - - - - - - -   - - - - - - B A A A A A A A A A A A A A A A B - - - - - -   - - - - - A A A A A A A A A A A A A A A A A A A A - - - -   - - - - A A A A A A A A A A A A A A A A A A A A A A - - -   - - - A A A A A A A A A A A A A A A A A A A A A A A A - -   - - A A A A A A A A A A A A A A A A A A A A A A A A A A -   - A A A A A A A A A A A A A A A A A A A A A A A A A A A B   B A A A A A A A A A A A A A A A A A A A A A A A A A A A A   A A A A A A A A A A A A A A A A A A A A A A A A A A A A A   A A A A A A A A A A A A A A A A A A A A A A A A A A A A A   A A A A A A A A A A A A A A A A A A A A A A A A A A A A A   A A A A A A A A A A A A A A A A A A A A A A A A A A A A A   A A A A A A A A A A A A A A A A A A A A A A A A A A A A A   B A A A A A A A A A A A A A A A A A A A A A A A A A A A B   - B B B B B B B B B B B B B B B B B B B B B B B B B B B -   - - - - - - - - - - - - - - - - - - - - - - - - - - - - -   - - - - - - - - - - - - - - - - - - - - - - - - - - - - -   - - - - - - - - - - - - - - - - - - - - - - - - - - - - -   
- B B - - - - - - - - - - - - - - - - - - - - - - - - B B   - A A - - - - - - - - - - - - - - - - - - - - - - - A A -   - - A A - - - - - - - - - - - - - - - - - - - A A A A A -   - - A A A A - - - - - - - - - - - - - - - A A A A - - - -   - - - - A A A A A - - - - - - - - - - A A A A - - - - - -   - - - - - - - A A A A A A A A A A A A A A A - - - - - - -   - - - - - - - A A A A A A A A A A A A A A A B - - - - - -   - - - - - A - A A A A A A A A A A A A A A A A A A - - - -   - - - - A A - A A A A A A A A A A A A A A A A A A A - - -   - - - A A A - A A A A A A A A A A A A A A A A A A A A - -   - - A A A A - A A A A A A A A A A A A A A A A A A A A A -   - A A A A A - A A A A A A A A A A A A A A A A A A A A A B   B A A A A A - A A A A A A A A A A A A A A A A A A A A A A   A A A A A A - A A A A A A A A A A A A A A A A A A A A A A   A A A A A A - A A A A A A A A A A A A A A A A A A A A A A   A A A A A A - A A A A A A A A A A A A A A A A A A A A A A   A A A A A A - A A A A A A A A A A A A A A A A A A A A A A   A A A A A A - A A A A A A A A A A A A A A A A A A A A A A   - A A A A A A A A A A A A A A A A A A A A A A A A A A A -   - - - - - - - - - - - - - - - - - - - - - - - - - - - - -   - - - - - - - - - - - - - - - - - - - - - - - - - - - - -   - - - - - - - - - - - - - - - - - - - - - - - - - - - - -   - - - - - - - - - - - - - - - - - - - - - - - - - - - - -   
- - - - - - - - - - - - - - - - - - - - - - - - - - - - -   - A A - - - - - - - - - - - - - - - - - - - - - - - A A -   - - A A - - - - - - - - - - - - - - - - - - - A A A A A -   - - A A A A A - - - - - - - - - - - - - - A A A A - - - -   - - - - A A A A A - - - - - - - - - - A A A A - - - - - -   - - - - - - - A A A A A A A A A A A A A A A - - - - - - -   - - - - - - - - - - - - - - - - - - - - - - - - - - - - -   - - - - - A A A A A A A A A A A A A A A A A A A A - - - -   - - - - A A A A A A A A A A A A A A A A A A A A A A - - -   - - - A A A A A A A A A A A A A A A A A A A A A A A A - -   - - A A A A A A A A A A A A A A A A A A A A A A A A A A -   - A A A A A A A A A A A A A A A A A A A A A A A A A A A B   B A A A A A A A A A A A A A A A A A A A A A A A A A A A A   A A A A A A A A A A A A A A A A A A A A A A A A A A A A A   A A A A A A A A A A A A A A A A A A A A A A A A A A A A A   A A A A A A A A A A A A A A A A A A A A A A A A A A A A A   A A A A A A A A A A A A A A A A A A A A A A A A A A A A A   A A A A A A A A A A A A A A A A A A A A A A A A A A A A A   - - - - - - - - - - - - - - - - - - - - - - - - - - - - -   - - - - - - - - - - - - - - - - - - - - - - - - - - - - -   - - - - - - - - - - - - - - - - - - - - - - - - - - - - -   - - - - - - - - - - - - - - - - - - - - - - - - - - - - -   - - - - - - - - - - - - - - - - - - - - - - - - - - - - -   
- - - - - - - - - - - - - - - - - - - - - - - - - - - - -   - - - - - - - - - - - - - - - - - - - - - - - - - - - - -   - - A A - - - - - - - - - - - - - - - - - - - A A A A A -   - - A A A A A - - - - - - - - - - - - - - A A A A - - - -   - - - - A A A A A - - - - - - - - - - A A A A - - - - - -   - - - - - - - A A A A A A A A A A A A A A A - - - - - - -   - - - - - - - - - - - - - - - - - - - - - - - - - - - - -   - - - - - - - - - - - - - - - - - - - - - - - - - - - - -   - - - - A A A A A A A A A A A A A A A A A A A A A A - - -   - - - A A A A A A A A A A A A A A A A A A A A A A A A - -   - - A A A A A A A A A A A A A A A A A A A A A A A A A A -   - - - - - - - - - - - - - - - - - - - - - - - - - - - - -   - A A A A A A A A A A A A A A A A A A A A A A A A A A A A   B B B B B B B B B B B B B B B B B B B B B B B B B B B B B   B B B B B B B B B B B B B B B B B B B B B B B B B B B B B   A A A A A A A A A A A A A A A A A A A A A A A A A A A A A   A A A A A A A A A A A A A A A A A A A A A A A A A A A A A   - - - - - - - - - - - - - - - - - - - - - - - - - - - - -   - - - - - - - - - - - - - - - - - - - - - - - - - - - - -   - - - - - - - - - - - - - - - - - - - - - - - - - - - - -   - - - - - - - - - - - - - - - - - - - - - - - - - - - - -   - - - - - - - - - - - - - - - - - - - - - - - - - - - - -   - - - - - - - - - - - - - - - - - - - - - - - - - - - - -   
- - - - - - - - - - - - - - - - - - - - - - - - - - - - -   - - - - - - - - - - - - - - - - - - - - - - - - - - - - -   - - - - - - - - - - - - - - - - - - - - - - - - - - - - -   - - B B B B B - - - - - - - - - - - - - - B B B B - - - -   - - - - - - - - - - - - - - - - - - - - - - - - - - - - -   - - - - - - - - - - - - - - - - - - - - - - - - - - - - -   - - - - - - - - - - - - - - - - - - - - - - - - - - - - -   - - - - - - - - - - - - - - - - - - - - - - - - - - - - -   - - - - - - - - - - - - - - - - - - - - - - - - - - - - -   - - - A A A A A A A A A A A A A A A A A A A A A A A A - -   - - - - - - - - - - - - - - - - - - - - - - - - - - - - -   - - - - - - - - - - - - - - - - - - - - - - - - - - - - -   - - - - - - - - - - - - - - - - - - - - - - - - - - - - -   - - - - - - - - - - - - - - - - - - - - - - - - - - - - -   - - - - - - - - - - - - - - - - - - - - - - - - - - - - -   - - - - - - - - - - - - - - - - - - - - - - - - - - - - -   - - - - - - - - - - - - - - - - - - - - - - - - - - - - -   - - - - - - - - - - - - - - - - - - - - - - - - - - - - -   - - - - - - - - - - - - - - - - - - - - - - - - - - - - -   - - - - - - - - - - - - - - - - - - - - - - - - - - - - -   - - - - - - - - - - - - - - - - - - - - - - - - - - - - -   - - - - - - - - - - - - - - - - - - - - - - - - - - - - -   - - - - - - - - - - - - - - - - - - - - - - - - - - - - -   
