model
size = 29 23 31, scale = 0.05, origin = -y
material 
  colors = A:#FF3 B:#F90 C:#F09 D:#FFC E:#F99 F:#FCC G:#FCF H:#FC0 I:#F96 J:#F60 K:#FF9 L:#CC0 M:#FFF N:#CC6 O:#CCC P:#CFF Q:#CF3 R:#CC3 S:#F0C T:#F30 U:#CF9 V:#F00 W:#F93 X:#FC9 Y:#F66 Z:#CF6 Aa:#FF6 Ab:#CF0 Ac:#F33 Ad:#F63 Ae:#F9F Af:#FF0 Ag:#F6F Ah:#FC3 Ai:#FC6 Aj:#F9C Ak:#F03 Al:#F6C Am:#F0F An:#CFC Ao:#CC9 Ap:#F69 Aq:#F39 Ar:#F06 As:#F36 At:#F3F Au:#CCF Av:#F3C
voxels
- AvL - - - - - - - - - - - - - - - - - - - - - - - - AbK   - X V - - - - - - - - - - - - - - - - - - - - - - - ArAg-   - - AgAh- - - - - - - - - - - - - - - - - - - Z G R ArAv-   - - D AlAqF Q - - - - - - - - - - - - - - AfAaAqD - - - -   - - - - Y W AkH At- - - - - - - - - - AeW Q W - - - - - -   - - - - - - - AkAaAjO N AiR AuAlN K ApAlAhA - - - - - - -   - - - - - - - - - - - - - - - - - - - - - - - - - - - - -   - - - - - - - - - - - - - - - - - - - - - - - - - - - - -   - - - - - - - - - - - - - - - - - - - - - - - - - - - - -   - - - - - - - - - - - - - - - - - - - - - - - - - - - - -   - - - - - - - - - - - - - - - - - - - - - - - - - - - - -   - - - - - - - - - - - - - - - - - - - - - - - - - - - - -   - - - - - - - - - - - - - - - - - - - - - - - - - - - - -   - - - - - - - - - - - - - - - - - - - - - - - - - - - - -   - - - - - - - - - - - - - - - - - - - - - - - - - - - - -   - - - - - - - - - - - - - - - - - - - - - - - - - - - - -   - - - - - - - - - - - - - - - - - - - - - - - - - - - - -   - - - - - - - - - - - - - - - - - - - - - - - - - - - - -   - - - - - - - - - - - - - - - - - - - - - - - - - - - - -   - - - - - - - - - - - - - - - - - - - - - - - - - - - - -   - - - - - - - - - - - - - - - - - - - - - - - - - - - - -   - - - - - - - - - - - - - - - - - - - - - - - - - - - - -   - - - - - - - - - - - - - - - - - - - - - - - - - - - - -   
- M B - - - - - - - - - - - - - - - - - - - - - - - - AtAr  - AqAc- - - - - - - - - - - - - - - - - - - - - - - AlAa-   - - P As- - - - - - - - - - - - - - - - - - - J V AaAvN -   - - O H C L G - - - - - - - - - - - - - - S E A Ag- - - -   - - - - AvM A AnAs- - - - - - - - - - J AjB L - - - - - -   - - - - - - - F AfK D K AlApZ R L I AcR N C - - - - - - -   - - - - - - - - - - - - - - - - - - - - - - - - - - - - -   - - - - - - - - - - - - - - - - - - - - - - - - - - - - -   - - - - - - - - - - - - - - - - - - - - - - - - - - - - -   - - - - - - - - - - - - - - - - - - - - - - - - - - - - -   - - - - - - - - - - - - - - - - - - - - - - - - - - - - -   - - - - - - - - - - - - - - - - - - - - - - - - - - - - -   - - - - - - - - - - - - - - - - - - - - - - - - - - - - -   - - - - - - - - - - - - - - - - - - - - - - - - - - - - -   - - - - - - - - - - - - - - - - - - - - - - - - - - - - -   - - - - - - - - - - - - - - - - - - - - - - - - - - - - -   - - - - - - - - - - - - - - - - - - - - - - - - - - - - -   - - - - - - - - - - - - - - - - - - - - - - - - - - - - -   - - - - - - - - - - - - - - - - - - - - - - - - - - - - -   - - - - - - - - - - - - - - - - - - - - - - - - - - - - -   - - - - - - - - - - - - - - - - - - - - - - - - - - - - -   - - - - - - - - - - - - - - - - - - - - - - - - - - - - -   - - - - - - - - - - - - - - - - - - - - - - - - - - - - -   
- ApO - - - - - - - - - - - - - - - - - - - - - - - - X R   - S Ai- - - - - - - - - - - - - - - - - - - - - - - D A -   - - E Ak- - - - - - - - - - - - - - - - - - - S AlU M Z -   - - L AbR AtY - - - - - - - - - - - - - - F Q X An- - - -   - - - - AgAuJ X V - - - - - - - - - - AnE AmAs- - - - - -   - - - - - - - AqAjM I I R S AnO C I L ApL Y - - - - - - -   - - - - - - - - - - - - - - - - - - - - - - - - - - - - -   - - - - - - - - - - - - - - - - - - - - - - - - - - - - -   - - - - - - - - - - - - - - - - - - - - - - - - - - - - -   - - - - - - - - - - - - - - - - - - - - - - - - - - - - -   - - - - - - - - - - - - - - - - - - - - - - - - - - - - -   - - - - - - - - - - - - - - - - - - - - - - - - - - - - -   - - - - - - - - - - - - - - - - - - - - - - - - - - - - -   - - - - - - - - - - - - - - - - - - - - - - - - - - - - -   - - - - - - - - - - - - - - - - - - - - - - - - - - - - -   - - - - - - - - - - - - - - - - - - - - - - - - - - - - -   - - - - - - - - - - - - - - - - - - - - - - - - - - - - -   - - - - - - - - - - - - - - - - - - - - - - - - - - - - -   - - - - - - - - - - - - - - - - - - - - - - - - - - - - -   - - - - - - - - - - - - - - - - - - - - - - - - - - - - -   - - - - - - - - - - - - - - - - - - - - - - - - - - - - -   - - - - - - - - - - - - - - - - - - - - - - - - - - - - -   - - - - - - - - - - - - - - - - - - - - - - - - - - - - -   
- A Ag- - - - - - - - - - - - - - - - - - - - - - - - T Ar  - G Av- - - - - - - - - - - - - - - - - - - - - - - D Ai-   - - X M - - - - - - - - - - - - - - - - - - - AeD R R Af-   - - A AqR K P - - - - - - - - - - - - - - F AoAeO - - - -   - - - - AeAoF R Ac- - - - - - - - - - E AeAtAh- - - - - -   - - - - - - - AgAuU Q AdO G L D Y AdP S C Au- - - - - - -   - - - - - - - - - - - - - - - - - - - - - - - - - - - - -   - - - - - - - - - - - - - - - - - - - - - - - - - - - - -   - - - - - - - - - - - - - - - - - - - - - - - - - - - - -   - - - - - - - - - - - - - - - - - - - - - - - - - - - - -   - - - - - - - - - - - - - - - - - - - - - - - - - - - - -   - - - - - - - - - - - - - - - - - - - - - - - - - - - - -   - - - - - - - - - - - - - - - - - - - - - - - - - - - - -   - - - - - - - - - - - - - - - - - - - - - - - - - - - - -   - - - - - - - - - - - - - - - - - - - - - - - - - - - - -   - - - - - - - - - - - - - - - - - - - - - - - - - - - - -   - - - - - - - - - - - - - - - - - - - - - - - - - - - - -   - - - - - - - - - - - - - - - - - - - - - - - - - - - - -   - - - - - - - - - - - - - - - - - - - - - - - - - - - - -   - - - - - - - - - - - - - - - - - - - - - - - - - - - - -   - - - - - - - - - - - - - - - - - - - - - - - - - - - - -   - - - - - - - - - - - - - - - - - - - - - - - - - - - - -   - - - - - - - - - - - - - - - - - - - - - - - - - - - - -   
- I Ag- - - - - - - - - - - - - - - - - - - - - - - - AjAm  - B M - - - - - - - - - - - - - - - - - - - - - - - X Q -   - - AeAr- - - - - - - - - - - - - - - - - - - AkC E AaP -   - - L AdP X Z - - - - - - - - - - - - - - AfAiU Ai- - - -   - - - - F K AkAdO - - - - - - - - - - L H X Ar- - - - - -   - - - - - - - Z W AiD E D P AfI AcAgS G Y Z - - - - - - -   - - - - - - - - - - - - - - - - - - - - - - - - - - - - -   - - - - - - - - - - - - - - - - - - - - - - - - - - - - -   - - - - - - - - - - - - - - - - - - - - - - - - - - - - -   - - - - - - - - - - - - - - - - - - - - - - - - - - - - -   - - - - - - - - - - - - - - - - - - - - - - - - - - - - -   - - - - - - - - - - - - - - - - - - - - - - - - - - - - -   - - - - - - - - - - - - - - - - - - - - - - - - - - - - -   - - - - - - - - - - - - - - - - - - - - - - - - - - - - -   - - - - - - - - - - - - - - - - - - - - - - - - - - - - -   - - - - - - - - - - - - - - - - - - - - - - - - - - - - -   - - - - - - - - - - - - - - - - - - - - - - - - - - - - -   - - - - - - - - - - - - - - - - - - - - - - - - - - - - -   - - - - - - - - - - - - - - - - - - - - - - - - - - - - -   - - - - - - - - - - - - - - - - - - - - - - - - - - - - -   - - - - - - - - - - - - - - - - - - - - - - - - - - - - -   - - - - - - - - - - - - - - - - - - - - - - - - - - - - -   - - - - - - - - - - - - - - - - - - - - - - - - - - - - -   
- AkO - - - - - - - - - - - - - - - - - - - - - - - - AtAp  - AhW - - - - - - - - - - - - - - - - - - - - - - - I At-   - - AbF - - - - - - - - - - - - - - - - - - - ArAdP U Aa-   - - AgAmU Y E - - - - - - - - - - - - - - X D G T - - - -   - - - - ApV R AhM - - - - - - - - - - AcB AaO - - - - - -   - - - - - - - AcAsQ AoAvI J A Q G E AeP AcAn- - - - - - -   - - - - - - - - - - - - - - - - - - - - - - - - - - - - -   - - - - - - - - - - - - - - - - - - - - - - - - - - - - -   - - - - - - - - - - - - - - - - - - - - - - - - - - - - -   - - - - - - - - - - - - - - - - - - - - - - - - - - - - -   - - - - - - - - - - - - - - - - - - - - - - - - - - - - -   - - - - - - - - - - - - - - - - - - - - - - - - - - - - -   - - - - - - - - - - - - - - - - - - - - - - - - - - - - -   - - - - - - - - - - - - - - - - - - - - - - - - - - - - -   - - - - - - - - - - - - - - - - - - - - - - - - - - - - -   - - - - - - - - - - - - - - - - - - - - - - - - - - - - -   - - - - - - - - - - - - - - - - - - - - - - - - - - - - -   - - - - - - - - - - - - - - - - - - - - - - - - - - - - -   - - - - - - - - - - - - - - - - - - - - - - - - - - - - -   - - - - - - - - - - - - - - - - - - - - - - - - - - - - -   - - - - - - - - - - - - - - - - - - - - - - - - - - - - -   - - - - - - - - - - - - - - - - - - - - - - - - - - - - -   - - - - - - - - - - - - - - - - - - - - - - - - - - - - -   
- F Af- - - - - - - - - - - - - - - - - - - - - - - - AuAi  - AtH - - - - - - - - - - - - - - - - - - - - - - - F Aa-   - - J T - - - - - - - - - - - - - - - - - - - I AsA R W -   - - O AtX AgY - - - - - - - - - - - - - - H D M At- - - -   - - - - A AlJ AkAq- - - - - - - - - - Y A V Ar- - - - - -   - - - - - - - AhY O T X Q B P D AbArN J G L - - - - - - -   - - - - - - - - - - - - - - - - - - - - - - - - - - - - -   - - - - - - - - - - - - - - - - - - - - - - - - - - - - -   - - - - - - - - - - - - - - - - - - - - - - - - - - - - -   - - - - - - - - - - - - - - - - - - - - - - - - - - - - -   - - - - - - - - - - - - - - - - - - - - - - - - - - - - -   - - - - - - - - - - - - - - - - - - - - - - - - - - - - -   - - - - - - - - - - - - - - - - - - - - - - - - - - - - -   - - - - - - - - - - - - - - - - - - - - - - - - - - - - -   - - - - - - - - - - - - - - - - - - - - - - - - - - - - -   - - - - - - - - - - - - - - - - - - - - - - - - - - - - -   - - - - - - - - - - - - - - - - - - - - - - - - - - - - -   - - - - - - - - - - - - - - - - - - - - - - - - - - - - -   - - - - - - - - - - - - - - - - - - - - - - - - - - - - -   - - - - - - - - - - - - - - - - - - - - - - - - - - - - -   - - - - - - - - - - - - - - - - - - - - - - - - - - - - -   - - - - - - - - - - - - - - - - - - - - - - - - - - - - -   - - - - - - - - - - - - - - - - - - - - - - - - - - - - -   
- P Ai- - - - - - - - - - - - - - - - - - - - - - - - X Al  - F Ar- - - - - - - - - - - - - - - - - - - - - - - AeZ -   - - AdAh- - - - - - - - - - - - - - - - - - - N I N E Am-   - - Z AcC I Au- - - - - - - - - - - - - - F O AbAn- - - -   - - - - AaAnAoZ X - - - - - - - - - - AvW R W - - - - - -   - - - - - - - AmA AeU W D M T AoAfI E B AbAf- - - - - - -   - - - - - - - - - - - - - - - - - - - - - - - - - - - - -   - - - - - - - - - - - - - - - - - - - - - - - - - - - - -   - - - - - - - - - - - - - - - - - - - - - - - - - - - - -   - - - - - - - - - - - - - - - - - - - - - - - - - - - - -   - - - - - - - - - - - - - - - - - - - - - - - - - - - - -   - - - - - - - - - - - - - - - - - - - - - - - - - - - - -   - - - - - - - - - - - - - - - - - - - - - - - - - - - - -   - - - - - - - - - - - - - - - - - - - - - - - - - - - - -   - - - - - - - - - - - - - - - - - - - - - - - - - - - - -   - - - - - - - - - - - - - - - - - - - - - - - - - - - - -   - - - - - - - - - - - - - - - - - - - - - - - - - - - - -   - - - - - - - - - - - - - - - - - - - - - - - - - - - - -   - - - - - - - - - - - - - - - - - - - - - - - - - - - - -   - - - - - - - - - - - - - - - - - - - - - - - - - - - - -   - - - - - - - - - - - - - - - - - - - - - - - - - - - - -   - - - - - - - - - - - - - - - - - - - - - - - - - - - - -   - - - - - - - - - - - - - - - - - - - - - - - - - - - - -   
- N Ac- - - - - - - - - - - - - - - - - - - - - - - - V Am  - AmAi- - - - - - - - - - - - - - - - - - - - - - - AoAg-   - - AoAu- - - - - - - - - - - - - - - - - - - AlAsR P D -   - - AbI AkC At- - - - - - - - - - - - - - N L AuM - - - -   - - - - ApQ C H Ah- - - - - - - - - - AgM S H - - - - - -   - - - - - - - J J J F AvAoAsAhT AsAnO M AfA - - - - - - -   - - - - - - - - - - - - - - - - - - - - - - - - - - - - -   - - - - - - - - - - - - - - - - - - - - - - - - - - - - -   - - - - - - - - - - - - - - - - - - - - - - - - - - - - -   - - - - - - - - - - - - - - - - - - - - - - - - - - - - -   - - - - - - - - - - - - - - - - - - - - - - - - - - - - -   - - - - - - - - - - - - - - - - - - - - - - - - - - - - -   - - - - - - - - - - - - - - - - - - - - - - - - - - - - -   - - - - - - - - - - - - - - - - - - - - - - - - - - - - -   - - - - - - - - - - - - - - - - - - - - - - - - - - - - -   - - - - - - - - - - - - - - - - - - - - - - - - - - - - -   - - - - - - - - - - - - - - - - - - - - - - - - - - - - -   - - - - - - - - - - - - - - - - - - - - - - - - - - - - -   - - - - - - - - - - - - - - - - - - - - - - - - - - - - -   - - - - - - - - - - - - - - - - - - - - - - - - - - - - -   - - - - - - - - - - - - - - - - - - - - - - - - - - - - -   - - - - - - - - - - - - - - - - - - - - - - - - - - - - -   - - - - - - - - - - - - - - - - - - - - - - - - - - - - -   
- N S - - - - - - - - - - - - - - - - - - - - - - - - AuU   - AcAq- - - - - - - - - - - - - - - - - - - - - - - G Ao-   - - Y U - - - - - - - - - - - - - - - - - - - M ApE A Aj-   - - J N H Z As- - - - - - - - - - - - - - AjA AqT - - - -   - - - - J AqAfAfK - - - - - - - - - - AeAuAeZ - - - - - -   - - - - - - - X AeAtK A T W AmU AhM A AsAsP - - - - - - -   - - - - - - - - - - - - - - - - - - - - - - - - - - - - -   - - - - - - - - - - - - - - - - - - - - - - - - - - - - -   - - - - - - - - - - - - - - - - - - - - - - - - - - - - -   - - - - - - - - - - - - - A - A - - - - - - - - - - - - -   - - - - - - - - - - A A A A A A A - - - - - - - - - - - -   - - - - - - - - - - - - A - - - - A - - - - - - - - - - -   - - - - - - - - - - - - A - - - - A - - - - - - - - - - -   - - - - - - - - - - - - A A A A A - - - - - - - - - - - -   - - - - - - - - - - - - A - - - - A - - - - - - - - - - -   - - - - - - - - - - - - A - - - - A - - - - - - - - - - -   - - - - - - - - - - A A A A A A A - - - - - - - - - - - -   - - - - - - - - - - - - - A - A - - - - - - - - - - - - -   - - - - - - - - - - - - - A - A - - - - - - - - - - - - -   - - - - - - - - - - - - - - - - - - - - - - - - - - - - -   - - - - - - - - - - - - - - - - - - - - - - - - - - - - -   - - - - - - - - - - - - - - - - - - - - - - - - - - - - -   - - - - - - - - - - - - - - - - - - - - - - - - - - - - -   
- AdM - - - - - - - - - - - - - - - - - - - - - - - - S M   - T Ae- - - - - - - - - - - - - - - - - - - - - - - Q A -   - - L Ac- - - - - - - - - - - - - - - - - - - K U AbN G -   - - V P AeAhAs- - - - - - - - - - - - - - AsL I Aa- - - -   - - - - C AlM AgT - - - - - - - - - - F AoAdV - - - - - -   - - - - - - - AlAiG AtH U A V F AoApAdW AhT - - - - - - -   - - - - - - - - - - - - - - - - - - - - - - - - - - - - -   - - - - - - - - - - - - B B B B B - - - - - - - - - - - -   - - - - - - - - - - - B - - - - - B - - - - - - - - - - -   - - - - - - - - - - B - B B B B B - B - - - - - - - - - -   - - - - - - - - - B A B B B B B B B - B - - - - - - - - -   - - - - - - - - B - B B B B B B B B B - B - - - - - - - -   - - - - - - - B - B B B B B B B B B B B - B - - - - - - -   - - - - - - B - B B B B B B B B B B B B B - B - - - - - -   - - - - - - B - B B B B B B B B B B B B B - B - - - - - -   - - - - - - - B - B B B B B B B B B B B - B - - - - - - -   - - - - - - - - B - B B B B B B B B B - B - - - - - - - -   - - - - - - - - - B - B B B B B B B - B - - - - - - - - -   - - - - - - - - - - B - B B B B B - B - - - - - - - - - -   - - - - - - - - - - - B - - - - - B - - - - - - - - - - -   - - - - - - - - - - - - B B B B B - - - - - - - - - - - -   - - - - - - - - - - - - - - - - - - - - - - - - - - - - -   - - - - - - - - - - - - - - - - - - - - - - - - - - - - -   
- C A - - - - - - - - - - - - - - - - - - - - - - - - H E   - AiZ - - - - - - - - - - - - - - - - - - - - - - - Y J -   - - AkU - - - - - - - - - - - - - - - - - - - C H K R O -   - - ApO N AfAb- - - - - - - - - - - - - - AnAgD V - - - -   - - - - C E O AhE - - - - - - - - - - ApK F Av- - - - - -   - - - - - - - U AuH J AtF Z K K H Q AbA AoAh- - - - - - -   - - - - - - - - - - - - - - - - - - - - - - - - - - - - -   - - - - - - - - - - - - - - B - - - - - - - - - - - - - -   - - - - - A A A A A A A A A A A A A A A A A A A - - - - -   - - - - A A A A A A A A A A A A A A A A A A A A A - - - -   - - - A A A A A A A A A A A A A A A A A A A A A A A - - -   - - - A A A A A A A A A A A A A A A A A A A A A A A - - -   - - - A A A A A A A A A A A A A A A A A A A A A A A - - -   - - - A A A A A A A A A A A A A A A A A A - A A A A - - -   - - - A A A A A A A A A A A A A A A A A A A A A A A - - -   - - - A A A A A A A A A A A A A A A A A A A A A A A - - -   - - - A A A A A A A A A A A A A A A A A A A A A A A - - -   - - - - A A A A A A A A A A A A A A A A A A A A A - - - -   - - - - - - - - - - - - A A A A A - - - - - - - - - - - -   - - - - - - - - - - - - - - - - - - - - - - - - - - - - -   - - - - - - - - - - - - - - - - - - - - - - - - - - - - -   - - - - - - - - - - - - - - - - - - - - - - - - - - - - -   - - - - - - - - - - - - - - - - - - - - - - - - - - - - -   
- O Ae- - - - - - - - - - - - - - - - - - - - - - - - AlAn  - M E - - - - - - - - - - - - - - - - - - - - - - - I Ad-   - - S Ap- - - - - - - - - - - - - - - - - - - W L J E T -   - - B S A A Al- - - - - - - - - - - - - - AjO A W - - - -   - - - - AvAjT U I - - - - - - - - - - A V N A - - - - - -   - - - - - - - AaU AiAcAlK AmP AtT AqM Z H Am- - - - - - -   - - - - - - B B B B B B B B B B B B B B B B B - - - - - -   - - - - - A A A A A A A A A A A A A A A A A A A - - - - -   - - - - A A A A A A A A A A A A A A A A A A A A A A - - -   - - - A A A A A A A A A A A A A A A A A A A A A A A A - -   - - - A A A A A A A A A A A A A A A A A A A A A A A A - -   - - A A A A A A A A A A A A A A A A A A A A A A A A A - -   - - A A A A A A A A A A A A A A A A A A A A A A A A A - -   - - A A A A A A A A A A A A A A A A A A A A A A A A A - -   - - A A A A A A A A A A A A A A A A A A A A A A A A A - -   - - A A A A A A A A A A A A A A A A A A A A A A A A A - -   - - A A A A A A A A A A A A A A A A A A A A A A A A A - -   - - A A A A A A A A A A A A A A A A A A A A A A A A A - -   - - - A A A A A A A A A A A A A A A A A A A A A A A - - -   - - - - - - - - - - - - - - - - - - - - - - - - - - - - -   - - - - - - - - - - - - - - - - - - - - - - - - - - - - -   - - - - - - - - - - - - - - - - - - - - - - - - - - - - -   - - - - - - - - - - - - - - - - - - - - - - - - - - - - -   
- G D - - - - - - - - - - - - - - - - - - - - - - - - U G   - L P - - - - - - - - - - - - - - - - - - - - - - - AoN -   - - H Ag- - - - - - - - - - - - - - - - - - - B AoM AbAc-   - - AkAvApT S - - - - - - - - - - - - - - E Z A I - - - -   - - - - T AuZ G P - - - - - - - - - - AaAlH D - - - - - -   - - - - - - - L O P ArAdAtAoAuJ AqN Z AmT V - - - - - - -   - - - - - - B - - - - - - - - - B B B B B B B - - - - - -   - - - - - A A A A A A A A A A A A A A A A A A A - - - - -   - - - - A A A A A A A A A A A A A A A A A A A A A A - - -   - - - A A A A A A A A A A A A A A A A A A A A A A A A - -   - - A A A A A A A A A A A A A A A A A A A A A A A A A A -   - A A A A A A A A A A A A A A A A A A A A A A A A A A A -   - A A A A A A A A A A A A A A A A A A A A A A A A A A A -   - A A A A A A A A A A A A A A A A A A A A A A A A A A A -   - A A A A A A A A A A A A A A A A A A A A A A A A A A A -   - A A A A A A A A A A A A A A A A A A A A A A A A A A A -   - A A A A A A A A A A A A A A A A A A A A A A A A A A A -   - A A A A A A A A A A A A A A A A A A A A A A A A A A A -   - - A A A A A A A A A A A A A A A A A A A A A A A A A A -   - - - A A A A A A A A A A A A A A A A A A A A A A A A - -   - - - - - - - - - - - - - - - - - - - - - - - - - - - - -   - - - - - - - - - - - - - - - - - - - - - - - - - - - - -   - - - - - - - - - - - - - - - - - - - - - - - - - - - - -   
- E Af- - - - - - - - - - - - - - - - - - - - - - - - Q An  - L K - - - - - - - - - - - - - - - - - - - - - - - AvP -   - - AbM - - - - - - - - - - - - - - - - - - - I B S K Ae-   - - F Y ArAgE - - - - - - - - - - - - - - H AbA U - - - -   - - - - AaJ Z G P - - - - - - - - - - ApAnAkAm- - - - - -   - - - - - - - E F L I AiJ O AtAcAkC AhAoAqK - - - - - - -   - - - - - - B B B B B B B B B B B B B B B B B - - - - - -   - - - - - A A A A A A A A A A A A A A A A A A A - - - - -   - - - - A A A A A A A A A A A A A A A A A A A A A A - - -   - - - A A A A A A A A A A A A A A A A A A A A A A A A - -   - - A A A A A A A A A A A A A A A A A A A A A A A A A A -   - A A A A A A A A A A A A A A A A A A A A A A A A A A A -   - A A A A A A A A A A A A A A A A A A A A A A A A A A A -   - A A A A A A A A A A A A A A A A A A A A A A A A A A A -   - A A A A A A A A A A A A A A A A A A A A A A A A A A A -   - A A A A A A A A A A A A A A A A A A A A A A A A A A A -   - A A A A A A A A A A A A A A A A A A A A A A A A A A A -   - A A A A A A A A A A A A A A A A A A A A A A A A A A A -   - A A A A A A A A A A A A A A A A A A A A A A A A A A A -   - - A A A A A A A A A A A A A A A A A A A A A A A A A - -   - - - - - - - - - - - - - - - - - - - - - - - - - - - - -   - - - - - - - - - - - - - - - - - - - - - - - - - - - - -   - - - - - - - - - - - - - - - - - - - - - - - - - - - - -   
- M U - - - - - - - - - - - - - - - - - - - - - - - - P Ap  - AsAp- - - - - - - - - - - - - - - - - - - - - - - AgH -   - - A Aj- - - - - - - - - - - - - - - - - - - F V AoJ Ak-   - - AjAlN AaAr- - - - - - - - - - - - - - AjA A Aj- - - -   - - - - AmN Q P At- - - - - - - - - - J Q Q A - - - - - -   - - - - - - - F C AvH AaAcAlM ArY AbG O AkP - - - - - - -   - - - - - - B B B B B B B B B B B B B B B B B - - - - - -   - - - - - A A A A A A A A A A A A A A A A A A A - - - - -   - - - - A A A A A A A A A A A A A A A A A A A A A A - - -   - - - A A A A A A A A A A A A A A A A A A A A A A A A - -   - - A A A A A A A A A A A A A A A A A A A A A A A A A A -   B B B B B B B B B B B B B B B B B B B B B B B B B B B B B   B B B B B B B B B B B B B B B B B B B B B B B B B B B B B   A C C C C C C C A A - A A A A A A C C A A A C C C C C C A   A C C C C C C C A A A A A A A A - C C A A A C C C C C C A   A C C C C C C C A A A A A A A A A C C A A A C C C C C C A   A C C C C C C C A A A A A A A A A C C A A A C C C C C C A   A C C C C C C C A A A A A A A A - A C A A A C C C C C C A   B B B B B B B B B B B B B B B B B B B B B B B B B B B B B   - - B B B B B B B B B B B B B B B B B B B B B B B B B B -   - - - B B B B B B B B B B B B B B B B B B B B B B B - - -   - - - - - - - - - - - - - - - - - - - - - - - - - - - - -   - - - - - - - - - - - - - - - - - - - - - - - - - - - - -   
- N S - - - - - - - - - - - - - - - - - - - - - - - - Y E   - D AdR - - - - - - - - - - - - - - - - - - - - - - AbW -   - - Z X - - - - - - - - - - - - - - - - - - - T N V F A -   - - AjAaB K S - - - - - - - - - - - - - - F S AiC - - - -   - - - - AcD A AmW - - - - - - - - - - M AmR A - - - - - -   - - - - - - - AgAbAkAnQ H AgG Q AgAeY A A A - - - - - - -   - - - - - - B B B B B B B B B B B B B B B B B - - - - - -   - - - - - A A A A A A A A A A A A A A A A A A A - - - - -   - - - - A A A A A A A A A A A A A A A A A A A A A A - - -   - - - A A A A A A A A A A A A A A A A A A A A A A A A - -   - - A A A A A A A A A A A A A A A A A A A A A A A A A A -   B B B B B B B B B B B B B B B B B B B B B B B B B B B B B   B B B B B B B B B B B B B B B B B B B B B B B B B B B B B   A C C C C C C C C C A C C C C C C C C C C C C C C C C C A   A C C C C C C C C C C C C C C C A A C C C C C C C C C C A   A A A A A A A A A A A A A A A A A A A A A A A A A A A A A   A A A A A A A A A A A A A A A A A A A A A A A A A A A A A   A A A A A A A A A A A A A A A A - A A A A A A A A A A A A   B B B B B B B B B B B B B B B B B B B B B B B B B B B B B   - B B B B B B B B B B B B B B B B B B B B B B B B B B B -   - - B B B B B B B B B B B B B B B B B B B B B B B B B B -   - - - - - - - - - - - - - - - - - - - - - - - - - - - - -   - - - - - - - - - - - - - - - - - - - - - - - - - - - - -   
- X F - - - - - - - - - - - - - - - - - - - - - - - - V R   - AeAdAk- - - - - - - - - - - - - - - - - - - - - - S Aa-   - - T Ab- - - - - - - - - - - - - - - - - - - O AsH AnW -   - - K W X K Ab- - - - - - - - - - - - - - L AqW Ad- - - -   - - - - A N W AdS - - - - - - - - - - AsB G Af- - - - - -   - - - - - - - T B E F L AmH S H AsM G A A A - - - - - - -   - - - - - - B B B B B B B B B B B B B B B B B - - - - - -   - - - - - A A A A A A A A A A A A A A A A A A A - - - - -   - - - - A A A A A A A A A A A A A A A A A A A A A A - - -   - - - A A A A A A A A A A A A A A A A A A A A A A A A - -   - - A A A A A A A A A A A A A A A A A A A A A A A A A A -   B B B B B B B B B B B B B B B B B B B B B B B B B B B B B   B B B B B B B B B B B B B B B B B B B B B B B B B B B B B   A A A A A A A A A A A A A A A A A A A A A A A A A A A A A   A A A A A A A A A A A A A A A A A A A A A A A A A A A A A   A A A A A A A A A A A A A A A A A A A A A A A A A A A A A   A A A A A A A A A A A A A A A A A A A A A A A A A A A A A   A C C C C C C C C C C C C C C C A C C C C C C C C C C C A   B B B B B B B B B B B B B B B B B B B B B B B B B B B B B   - B B B B B B B B B B B B B B B B B B B B B B B B B B B -   - - B B B B B B B B B B B B B B B B B B B B B B B B B B -   - - - B B B B B B B B B B B B B B B B B B B B B B B B - -   - - - - - - - - - - - - - - - - - - - - - - - - - - - - -   
- AbM - - - - - - - - - - - - - - - - - - - - - - - - AnI   - F R D - - - - - - - - - - - - - - - - - - - - - - A E -   - - AfR - - - - - - - - - - - - - - - - - - - C AeAaG Au-   - - Q AgT AcE - - - - - - - - - - - - - - AaM AvAl- - - -   - - - - Q AsZ AgN - - - - - - - - - - AhAgAnY - - - - - -   - - - - - - - D AcL U F I AmAbAjJ V S A A A - - - - - - -   - - - - - - B B B B B B B B B B B B B B B B B - - - - - -   - - - - - A A A A A A A A A A A A A A A A A A A - - - - -   - - - - A A A A A A A A A A A A A A A A A A A A A A - - -   - - - A A A A A A A A A A A A A A A A A A A A A A A A - -   - - A A A A A A A A A A A A A A A A A A A A A A A A A A -   B B B B B B B B B B B B B B B B B B B B B B B B B B B B B   B B B B B B B B B B B B B B B B B B B B B B B B B B B B B   A A A A A A A A A A A A A A A A A A A A A A A A A A A A A   A A A A A A A A A A A A A A A A A A A A A A A A A A A A A   A A A A A A A A A A A A A A A A A A A A A A A A A A A A A   A A A A A A A A A A A A A A A A A A A A A A A A A A A A A   A A A A A A A A A A A A A A A A A A A A A A A A A A A A A   B B B B B B B B B B B B B B B B B B B B B B B B B B B B B   - B B B B B B B B B B B B B B B B B B B B B B B B B B B -   - - B B B B B B B B B B B B B B B B B B B B B B B B B B -   - - - B B B B B B B B B B B B B B B B B B B B B B B B - -   - - - - B B B B B B B B B B B B B B B B B B B B B B - - -   
- O Af- - - - - - - - - - - - - - - - - - - - - - - - AkI   - N J Y - - - - - - - - - - - - - - - - - - - - - - B V -   - - AjJ - - - - - - - - - - - - - - - - - - - F AnH C L -   - - AeX Y B A - - - - - - - - - - - - - - F W R U - - - -   - - - - J D Z AaP - - - - - - - - - - T E AmX - - - - - -   - - - - - - - AnH AnY M AdI AhN T ArAbA A A - - - - - - -   - - - - - - B B B B B B B B B B B B B B B B B - - - - - -   - - - - - A A A A A A A A A A A A A A A A A A A - - - - -   - - - - A A A A A A A A A A A A A A A A A A A A A A - - -   - - - A A A A A A A A A A A A A A A A A A A A A A A A - -   - - A A A A A A A A A A A A A A A A A A A A A A A A A A -   B B B B B B B B B B B B B B B B B B B B B B B B B B B B B   B B B B B B B B B B B B B B B B B B B B B B B B B B B B B   A A A A A A A A A A A A A A A A A A A A A A A A A A A A A   A A A A A A A A A A A A A A A A A A A A A A A A A A A A A   A A A A A A A A A A A A A A A A A A A A A A A A A A A A A   A A A A A A A A A A A A A A A A A A A A A A A A A A A A A   A A A A A A A A A A A A A A A A A A A A A A A A A A A A A   B B B B B B B B B B B B B B B B B B B B B B B B B B B B B   - B B B B B B B B B B B B B B B B B B B B B B B B B B B -   - - B B B B B B B B B B B B B B B B B B B B B B B B B B -   - - - B B B B B B B B B B B B B B B B B B B B B B B B - -   - - - - B B B B B B B B B B B B B B B B B B B B B B - - -   
- AsC - - - - - - - - - - - - - - - - - - - - - - - - AmS   - AkC Ak- - - - - - - - - - - - - - - - - - - - - - ArAj-   - - AiK - - - - - - - - - - - - - - - - - - - J Q - ArQ -   - - ArD C U Ap- - - - - - - - - - - - - - D D X N - - - -   - - - - AaAcI E Ac- - - - - - - - - - D AnAtR - - - - - -   - - - - - - - H AuF I AfO AdAoAeZ AvAhA A A - - - - - - -   - - - - - - B B B B B B B B B B B B B B B B B - - - - - -   - - - - - A A A A A A A A A A A A A A A A A A A - - - - -   - - - - A A A A A A A A A A A A A A A A A A A A A A - - -   - - - A A A A A A A A A A A A A A A A A A A A A A A A - -   - - A A A A A A A A A A A A A A A A A A A A A A A A A A -   B B B B B B B B B B B B B B B B B B B B B B B B B B B B B   B B B B B B B B B B B B B B B B B B B B B B B B B B B B B   A A A A A A A A A A A A A A A A A A A A A A A A A A A A A   A A A A A A A A A A A A A A A A A A A A A A A A A A A A A   A A A A A A A A A A A A A A A A A A A A A A A A A A A A A   A A A A A A A A A A A A A A A A A A A A A A A A A A A A A   A A A A A A A A A A A A A A A A A A A A A A A A A A A A A   B B B B B B B B B B B B B B B B B B B B B B B B B B B B B   - B B B B B B B B B B B B B B B B B B B B B B B B B B B -   - - B B B B B B B B B B B B B B B B B B B B B B B B B B -   - - - B B B B B B B B B B B B B B B B B B B B B B B B - -   - - - - B B B B B B B B B B B B B B B B B B B B B B - - -   
- AdG - - - - - - - - - - - - - - - - - - - - - - - - X F   - AuE E - - - - - - - - - - - - - - - - - - - - - - K Aq-   - - Z R - - - - - - - - - - - - - - - - - - - AhAi- D G -   - - V AeAmAjAc- - - - - - - - - - - - - - A AjAc- - - - -   - - - - AgAeP AuS - - - - - - - - - - AoAsG Q - - - - - -   - - - - - - - AoAqU AbC Q O AhZ ApAsAoA A A - - - - - - -   - - - - - - B B B B B B B B B B B B B B B B B - - - - - -   - - - - - A A A A A A A A A A A A A A A A A A A - - - - -   - - - - A A A A A A A A A A A A A A A A A A A A A A - - -   - - - A A A A A A A A A A A A A A A A A A A A A A A A - -   - - A A A A A A A A A A A A A A A A A A A A A A A A A A -   B B B B B B B B B B B B B B B B B B B B B B B B B B B B B   B B B B B B B B B B B B B B B B B B B B B B B B B B B B B   A A A A A A A A A A A A A A A A A A A A A A A A A A A A A   A A A A A A A A A A A A A A A A A A A A A A A A A A A A A   A A A A A A A A A A A A A A A A A A A A A A A A A A A A A   A A A A A A A A A A A A A A A A A A A A A A A A A A A A A   A A A A A A A A A A A A A A A A A A A A A A A A A A A A A   B B B B B B B B B B B B B B B B B B B B B B B B B B B B B   - B B B B B B B B B B B B B B B B B B B B B B B B B B B -   - - B B B B B B B B B B B B B B B B B B B B B B B B B B -   - - - B B B B B B B B B B B B B B B B B B B B B B B B - -   - - - - B B B B B B B B B B B B B B B B B B B B B B - - -   
- P O - - - - - - - - - - - - - - - - - - - - - - - - AjM   - U K Ah- - - - - - - - - - - - - - - - - - - - - - H G -   - - N U - - - - - - - - - - - - - - - - - - - T H Y D E -   - - S AaI H Y - - - - - - - - - - - - - - G AvQ Ak- - - -   - - - - B J R AcAs- - - - - - - - - - D W T I - - - - - -   - - - - - - - AiAdY N S L Q U O A N AhA A A - - - - - - -   - - - - - - B B B B B B B B B B B B B B B B B - - - - - -   - - - - - A A A A A A A A A A A A A A A A A A A - - - - -   - - - - A A A A A A A A A A A A A A A A A A A A A A - - -   - - - A A A A A A A A A A A A A A A A A A A A A A A A - -   - - A A A A A A A A A A A A A A A A A A A A A A A A A A -   B B B B B B B B B B B B B B B B B B B B B B B B B B B B B   B B B B B B B B B B B B B B B B B B B B B B B B B B B B B   A A A A A A A A A A A A A A A A A A A A A A A A A A A A A   A A A A A A A A A A A A A A A A A A A A A A A A A A A A A   A A A A A A A A A A A A A A A A A A A A A A A A A A A A A   A A A A A A A A A A A A A A A A A A A A A A A A A A A A A   A A A A A A A A A A A A A A A A A A A A A A A A A A A A A   B B B B B B B B B B B B B B B B B B B B B B B B B B B B B   - B B B B B B B B B B B B B B B B B B B B B B B B B B B -   - - B B B B B B B B B B B B B B B B B B B B B B B B B B -   - - - B B B B B B B B B B B B B B B B B B B B B B B B - -   - - - - B B B B B B B B B B B B B B B B B B B B B B - - -   
- AvR - - - - - - - - - - - - - - - - - - - - - - - - D Af  - N L L - - - - - - - - - - - - - - - - - - - - - - O G -   - - G G - - - - - - - - - - - - - - - - - - - U L P AcD -   - - B B AaV J - - - - - - - - - - - - - - C B AaV - - - -   - - - - W L O A Ah- - - - - - - - - - Z AiAlAv- - - - - -   - - - - - - - AjAlI B Q F L A AkY AqU A A A - - - - - - -   - - - - - - B B B B B B B B B B B B B B B B B - - - - - -   - - - - - A A A A A A A A A A A A A A A A A A A - - - - -   - - - - A A A A A A A A A A A A A A A A A A A A A A - - -   - - - A A A A A A A A A A A A A A A A A A A A A A A A - -   - - A A A A A A A A A A A A A A A A A A A A A A A A A A -   B B B B B B B B B B B B B B B B B B B B B B B B B B B B B   B B B B B B B B B B B B B B B B B B B B B B B B B B B B B   A A A A A A A A A A A A A A A A A A A A A A A A A A A A A   A A A A A A A A A A A A A A A A A A A A A A A A A A A A A   A A A A A A A A A A A A A A A A A A A A A A A A A A A A A   A A A A A A A A A A A A A A A A A A A A A A A A A A A A A   A A A A A A A A A A A A A A A A A A A A A A A A A A A A A   B B B B B B B B B B B B B B B B B B B B B B B B B B B B B   - B B B B B B B B B B B B B B B B B B B B B B B B B B B -   - - B B B B B B B B B B B B B B B B B B B B B B B B B B -   - - - B B B B B B B B B B B B B B B B B B B B B B B B - -   - - - - - - - - - - - - - - - - - - - - - - - - - - - - -   
- O Aq- - - - - - - - - - - - - - - - - - - - - - - - AaC   - P J L - - - - - - - - - - - - - - - - - - - - - - P C -   - - U H - - - - - - - - - - - - - - - - - - - T AhAdH Av-   - - O D A T N - - - - - - - - - - - - - - AvG K B - - - -   - - - - G AiAmAqAj- - - - - - - - - - M AmX E - - - - - -   - - - - - - - Y AlAbJ AnM F AtM AhArA A A A - - - - - - -   - - - - - - B B B B B B B B B B B B B B B B B - - - - - -   - - - - - A A A A A A A A A A A A A A A A A A A - - - - -   - - - - A A A A A A A A A A A A A A A A A A A A A A - - -   - - - A A A A A A A A A A A A A A A A A A A A A A A A - -   - - A A A A A A A A A A A A A A A A A A A A A A A A A A -   B B B B B B B B B B B B B B B B B B B B B B B B B B B B B   B B B B B B B B B B B B B B B B B B B B B B B B B B B B B   A A A A A A A A A A A A A A A A A A A A A A A A A A A A A   A A A A A A A A A A A A A A A A A A A A A A A A A A A A A   A A A A A A A A A A A A A A A A A A A A A A A A A A A A A   A A A A A A A A A A A A A A A A A A A A A A A A A A A A A   A A A A A A A A A A A A A A A A A A A A A A A A A A A A A   B B B B B B B B B B B B B B B B B B B B B B B B B B B B B   - B B B B B B B B B B B B B B B B B B B B B B B B B B B -   - - B B B B B B B B B B B B B B B B B B B B B B B B B B -   - - - - - - - - - - - - - - - - - - - - - - - - - - - - -   - - - - - - - - - - - - - - - - - - - - - - - - - - - - -   
- AgE - - - - - - - - - - - - - - - - - - - - - - - - ArG   - AeI D - - - - - - - - - - - - - - - - - - - - - - F Ab-   - - V Ar- - - - - - - - - - - - - - - - - - - AlZ ArAmAg-   - - AjAaW G Al- - - - - - - - - - - - - - AaAiAnAq- - - -   - - - - AbD AdV B - - - - - - - - - - I V D Ar- - - - - -   - - - - - - - L AcN V AnAfM Q W K K AtA A A - - - - - - -   - - - - - - B B B B B B B B B B B B B B B B B - - - - - -   - - - - - A A A A A A A A A A A A A A A A A A A - - - - -   - - - - A A A A A A A A A A A A A A A A A A A A A A - - -   - - - A A A A A A A A A A A A A A A A A A A A A A A A - -   - - A A A A A A A A A A A A A A A A A A A A A A A A A A -   B B B B B B B B B B B B B B B B B B B B B B B B B B B B B   B B B B B B B B B B B B B B B B B B B B B B B B B B B B B   A A A A A A A A A A A A A A A A A A A A A A A A A A A A A   A A A A A A A A A A A A A A A A A A A A A A A A A A A A A   A A A A A A A A A A A A A A A A A A A A A A A A A A A A A   A A A A A A A A A A A A A A A A A A A A A A A A A A A A A   A A A A A A A A A A A A A A A A A A A A A A A A A A A A A   B B B B B B B B B B B B B B B B B B B B B B B B B B B B B   - B B B B B B B B B B B B B B B B B B B B B B B B B B B -   - - B B B B B B B B B B B B B B B B B B B B B B B B B B -   - - - - - - - - - - - - - - - - - - - - - - - - - - - - -   - - - - - - - - - - - - - - - - - - - - - - - - - - - - -   
- L K - - - - - - - - - - - - - - - - - - - - - - - - AoO   - E AfAb- - - - - - - - - - - - - - - - - - - - - - J L -   - - K F - - - - - - - - - - - - - - - - - - - AfAcI R V -   - - AbR AhApV - - - - - - - - - - - - - - Z AfH Ai- - - -   - - - - AcT AgJ Aq- - - - - - - - - - AuW AjK - - - - - -   - - - - - - - X Y B AdP C AfE B AtX Q A A A - - - - - - -   - - - - - - B B B B B B B B B B B B B B B B B - - - - - -   - - - - - A A A A A A A A A A A A A A A A A A A - - - - -   - - - - A A A A A A A A A A A A A A A A A A A A A A - - -   - - - A A A A A A A A A A A A A A A A A A A A A A A A - -   - - A A A A A A A A A A A A A A A A A A A A A A A A A A -   B B B B B B B B B B B B B B B B B B B B B B B B B B B B B   B B B B B B B B B B B B B B B B B B B B B B B B B B B B B   A A A A A A A A A A A A A A A A A A A A A A A A A A A A A   A A A A A A A A A A A A A A A A A A A A A A A A A A A A A   A A A A A A A A A A A A A A A A A A A A A A A A A A A A A   A A A A A A A A A A A A A A A A A A A A A A A A A A A A A   A A A A A A A A A A A A A A A A A A A A A A A A A A A A A   B B B B B B B B B B B B B B B B B B B B B B B B B B B B B   - B B B B B B B B B B B B B B B B B B B B B B B B B B B -   - - - - - - - - - - - - - - - - - - - - - - - - - - - - -   - - - - - - - - - - - - - - - - - - - - - - - - - - - - -   - - - - - - - - - - - - - - - - - - - - - - - - - - - - -   
- D Ak- - - - - - - - - - - - - - - - - - - - - - - - T R   - AiH D - - - - - - - - - - - - - - - - - - - - - - G Ad-   - - AkO - - - - - - - - - - - - - - - - - - - E V AkA S -   - - K AiAfAiX - - - - - - - - - - - - - - J ApH I - - - -   - - - - H AfAaAdQ - - - - - - - - - - H A U A - - - - - -   - - - - - - - T N J X K S C B W Y V E A A A - - - - - - -   - - - - - - - B B B B B B B B B B B B B B B B - - - - - -   - - - - - A - A A A A A A A A A A A A A A A A A - - - - -   - - - - A A - A A A A A A A A A A A A A A A A A A A - - -   - - - A A A - A A A A A A A A A A A A A A A A A A A A - -   - - A A A A - A A A A A A A A A A A A A A A A A A A A A -   B B B B B B - B B B B B B B B B B B B B B B B B B B B B B   B B B B B B - B B B B B B B B B B B B B B B B B B B B B B   A A A A A A - A A A A A A A A A A A A A A A A A A A A A A   A A A A A A - A A A A A A A A A A A A A A A A A A A A A A   A A A A A A - A A A A A A A A A A A A A A A A A A A A A A   A A A A A A - A A A A A A A A A A A A A A A A A A A A A A   A A A A A A - A A A A A A A A A A A A A A A A A A A A A A   - A A A A A A A A A A A A A A A A A A A A A A A A A A A -   - - - - - - - - - - - - - - - - - - - - - - - - - - - - -   - - - - - - - - - - - - - - - - - - - - - - - - - - - - -   - - - - - - - - - - - - - - - - - - - - - - - - - - - - -   - - - - - - - - - - - - - - - - - - - - - - - - - - - - -   
- - - - - - - - - - - - - - - - - - - - - - - - - - - - -   - AlX M - - - - - - - - - - - - - - - - - - - - - - P Ap-   - - AqAf- - - - - - - - - - - - - - - - - - - AqW AeF I -   - - G K AjQ I - - - - - - - - - - - - - - P Q Y X - - - -   - - - - G P E ApL - - - - - - - - - - ApX H A - - - - - -   - - - - - - - I G V D AeQ S AiAcG AfB AkR K - - - - - - -   - - - - - - - - - - - - - - - - - - - - - - - - - - - - -   - - - - - A A A A A A A A A A A A A A A A A A A - - - - -   - - - - A A A A A A A A A A A A A A A A A A A A A A - - -   - - - A A A A A A A A A A A A A A A A A A A A A A A A - -   - - A A A A A A A A A A A A A A A A A A A A A A A A A A -   B B B B B B B B B B B B B B B B B B B B B B B B B B B B B   B B B B B B B B B B B B B B B B B B B B B B B B B B B B B   A A A A A A A A A A A A A A A A A A A A A A A A A A A A A   A A A A A A A A A A A A A A A A A A A A A A A A A A A A A   A A A A A A A A A A A A A A A A A A A A A A A A A A A A A   A A A A A A A A A A A A A A A A A A A A A A A A A A A A A   A A A A A A A A A A A A A A A A A A A A A A A A A A A A A   - - - - - - - - - - - - - - - - - - - - - - - - - - - - -   - - - - - - - - - - - - - - - - - - - - - - - - - - - - -   - - - - - - - - - - - - - - - - - - - - - - - - - - - - -   - - - - - - - - - - - - - - - - - - - - - - - - - - - - -   - - - - - - - - - - - - - - - - - - - - - - - - - - - - -   
- - - - - - - - - - - - - - - - - - - - - - - - - - - - -   - - P Y - - - - - - - - - - - - - - - - - - - - - - - - -   - - F J - - - - - - - - - - - - - - - - - - - N AdZ H A -   - - AmU K AoE - - - - - - - - - - - - - - AbB S S - - - -   - - - - E I AuR F - - - - - - - - - - AjW F D - - - - - -   - - - - - - - G W AdAuAsAnQ S V S J AiAeAqAd- - - - - - -   - - - - - - - - - - - - - - - - - - - - - - - - - - - - -   - - - - - - - - - - - - - - - - - - - - - - - - - - - - -   - - - - A A A A A A A A A A A A A A A A A A A A A A - - -   - - - A A A A A A A A A A A A A A A A A A A A A A A A - -   - - A A A A A A A A A A A A A A A A A A A A A A A A A A -   - - - - - - - - - - - - - - - - - - - - - - - - - - - - -   - A A A A A A A A A A A A A A A A A A A A A A A A A A A A   B B B B B B B B B B B B B B B B B B B B B B B B B B B B B   B B B B B B B B B B B B B B B B B B B B B B B B B B B B B   A A A A A A A A A A A A A A A A A A A A A A A A A A A A A   A A A A A A A A A A A A A A A A A A A A A A A A A A A A A   - - - - - - - - - - - - - - - - - - - - - - - - - - - - -   - - - - - - - - - - - - - - - - - - - - - - - - - - - - -   - - - - - - - - - - - - - - - - - - - - - - - - - - - - -   - - - - - - - - - - - - - - - - - - - - - - - - - - - - -   - - - - - - - - - - - - - - - - - - - - - - - - - - - - -   - - - - - - - - - - - - - - - - - - - - - - - - - - - - -   
- - - - - - - - - - - - - - - - - - - - - - - - - - - - -   - - - - - - - - - - - - - - - - - - - - - - - - - - - - -   - - - - - - - - - - - - - - - - - - - - - - - - - - - - -   - - B B B B B - - - - - - - - - - - - - - B B B B - - - -   - - - - - - - - - - - - - - - - - - - - - - - - - - - - -   - - - - - - - - - - - - - - - - - - - - - - - - - - - - -   - - - - - - - - - - - - - - - - - - - - - - - - - - - - -   - - - - - - - - - - - - - - - - - - - - - - - - - - - - -   - - - - - - - - - - - - - - - - - - - - - - - - - - - - -   - - - A A A A A A A A A A A A A A A A A A A A A A A A - -   - - - - - - - - - - - - - - - - - - - - - - - - - - - - -   - - - - - - - - - - - - - - - - - - - - - - - - - - - - -   - - - - - - - - - - - - - - - - - - - - - - - - - - - - -   - - - - - - - - - - - - - - - - - - - - - - - - - - - - -   - - - - - - - - - - - - - - - - - - - - - - - - - - - - -   - - - - - - - - - - - - - - - - - - - - - - - - - - - - -   - - - - - - - - - - - - - - - - - - - - - - - - - - - - -   - - - - - - - - - - - - - - - - - - - - - - - - - - - - -   - - - - - - - - - - - - - - - - - - - - - - - - - - - - -   - - - - - - - - - - - - - - - - - - - - - - - - - - - - -   - - - - - - - - - - - - - - - - - - - - - - - - - - - - -   - - - - - - - - - - - - - - - - - - - - - - - - - - - - -   - - - - - - - - - - - - - - - - - - - - - - - - - - - - -   
