model
size = 12 32 32, scale = 0.05, origin = -y
material 
  colors = A:#E00 B:#111 C:#500 D:#EEE E:#C36
voxels
50-8A376-8A2(4-2D)4-D2-2B2-D352-8A6-4D7-6A353-8A4-A-4D-A4-8A5-DB2-BD6-2D2A2D5-3B2-3B6-B2-B306-8A4-2A4D2A4(4-8A)328-5(8A4-)CE4AEC2(4-2C)5-C4-C295-4A6-4(8A4-)8A318-4A6-3(8A4-)8A5-6A319-2(DB)6-D5BDB4-7BD4-D7B4-BD3BDBD7-DB2(10-2B)233-2B8-2B48-24A2-2(8A4-)8A19-3(2B10-)2B209-2A4(8-4A)8-26A-10A3-8A5-6A56-2B10-2B197-2A3(8-4A)8-9AC27AC-9AC3-7AC6-C3A69-2B10-2B224-C3ACA5-C7A2-12AC11A-C9A3-8A6-4A81-2B10-2B201-4A7-6A5-8A2-24A-10A3-8A6-4A93-2B10-2B189-4A7-6A5-7AC2-11AC12A-10A3-AC6A6-2C2A105-2B10-2B177-4A7-6A5-8A2-24A-9AC3-6A2C6-4A117-2B177-4A7-6A5-8A2-2(C11A)-10A3-8A6-4A117-2B177-4A7-6A5-8A2-24A-10A3-8A6-4A117-2B10-2B165-4A7-6A5-7AC2-11AC12A-10A3-6ACA6-2A2C129-2B10-2B125-2B8-2B27-6A3-2C34A-C9A3-C7A6-4A141-2B10-2B113-2A3(8-4A)8-37AC-9AC3-7AC6-4A153-2B10-2B101-2A3(8-4A)8-5A6-27A2-8A4-8A6-4A165-2B10-2B152-6A6-C5A6-6A6-5AC8-2A70-2B106-2B10-2B153-2(4A8-)4A81-2B118-2B10-2B154-2A10-2A82-2A130-2B10-2B154-2A82-CA142-2B10-2B142-AC70-2A10-CA154-2(2B10-)2B118-2A10-2A46-2A10-2A190-2B10-2B118-2A10-AC22-2A10-AC214-2B130-2(2A10-)2A226-2(2B382-)2B5-
