model
size = 32 31 32, scale = 0.05, origin = -y
material 
  colors = A:#111 B:#6FF
voxels
270-4A27-6A25-3(8A24-)8A25-6A27-4A668-4A26-8A23-10A21-12A20-12A19-3(14A18-)14A19-12A20-12A21-10A23-8A26-4A509-2A27-8A22-12A19-14A18-14A17-2(16A16-)16A15-18A14-18A15-2(16A16-)16A17-14A18-14A19-12A22-8A27-2B412-6A24-10A20-14A17-16A16-16A15-18A14-18A13-5(20A12-)20A13-18A14-18A15-16A16-16A17-14A20-10A24-6A345-8A22-12A19-14A17-16A15-18A13-20A12-20A11-7(22A10-)22A11-20A12-20A13-18A15-16A17-14A19-12A22-8A280-8A22-12A19-14A16-18A14-18A13-20A11-22A10-22A9-7(24A8-)24A9-22A10-22A11-20A13-18A14-18A16-14A19-12A22-8A246-12A19-14A16-18A13-20A12-20A11-22A9-2(24A8-)24A7-5(26A6-)26A7-2(24A8-)24A9-22A11-20A12-20A13-18A16-14A19-12A23-6A214-4A7-3A16-6A7-5A13-7A7-6A11-8A7-7A10-8A7-7A9-9A7-8A8-9A7-8A7-3(10A7-9A6-)10A7-9A5-11A7-10A4-11A7-10A5-3(10A7-9A6-)10A2(7-9A)7-8A8-9A7-8A9-22A10-22A11-20A13-2B14A2B16-14A20-10A26-2B183-3A11-2A15-4A11-3A13-5A11-4A11-6A11-5A9-7A11-6A7-2(A7B11-7A6-)A7B11-7A5-4(A8B11-8A4-)3(9A11-8A4-)9A11-8A5-2(8A11-7A6-)8A11-7A7-24A9-22A11-20A13-B16AB15-16A17-14A21-8A179-3A13-2A13-4A13-3A11-5A13-4A9-6A13-5A7-7A13-6A6-A6B13-6A5-6(A7B13-7A4-)5(8A13-7A4-)8A13-7A5-7A13-6A6-26A7-24A9-22A11-20A13-18A15-16A18-12A23-6A147-3A15-2A11-4A15-3A9-5A15-4A8-5A15-4A7-6A15-5A5-7A6(15-6A4-A6B)7(15-6A4-7A)15-6A5-26A7-24A8-24A9-22A11-20A14-16A17-14A20-10A25-4A116-2A17-A11-3A17-2A9-4A17-3A7-5A17-4A6-5A17-4A5-6A6(17-5A4-A5B)7(17-5A4-6A)17-5A5-26A6-26A7-24A9-22A11-20A13-18A16-14A19-12A22-9A26-2B84-3A17-2A9-4A17-3A8-4A17-3A7-5A17-4A5-2(6A17-5A4-)6(A5B17-5A4-)7(6A17-5A4-)28A5-26A7-24A8-24A9-22A12-18A15-16A18-12A21-10A23-8A81-2A19-A9-3A19-2A7-4A19-3A6-4A19-3A5-2(5A19-4A4-)6(A4B19-4A4-)7(5A19-4A4-)28A5-26A6-26A7-24A9-22A11-20A14-16A17-14A20-10A23-8A25-6A50-2A19-A9-3A19-2A7-4A19-3A6-4A19-3A5-2(5A19-4A4-)5(A4B19-4A4-)A4B19-4A3-B5A19-4AB2-B5A19-4AB3-5(5A19-4A4-)28A5-12A2B12A6-12A2B12A7-11A2B11A9-10A2B10A11-9A2B9A14-7A2B7A17-6A2B6A20-4A2B5A22-3A2B3A25-2A2B2A27-4A19-2A19-A9-3A19-2A7-4A19-3A5-3(5A19-4A4-)4(A4B19-4A4-)A4B19-4A3-BA4B19-4AB-2B5A19-4A4B5A19-4A2B-B5A19-4AB3-4(5A19-4A4-)28A4-B12A2B12AB5-12A2B12A7-11A2B11A9-10A2B10A11-9A2B9A13-B7A2B7AB16-6A2B6A20-4A2B5A22-3A2B3A25-2A2B2A27-A2BA19-2A19-A9-3A19-2A7-4A19-3A5-3(5A19-4A4-)4(A4B19-4A4-)A4B19-4A3-BA4B19-4AB-2B5A19-4A4B5A19-4A2B-B5A19-4AB3-4(5A19-4A4-)13A2B13A4-B12A2B12AB5-12A2B12A7-11A2B11A9-10A2B10A11-9A2B9A13-B7A2B7AB16-6A2B6A20-4A2B5A22-3A2B3A25-2A2B2A27-4A19-2A19-A9-3A19-2A7-4A19-3A6-4A19-3A5-2(5A19-4A4-)5(A4B19-4A4-)A4B19-4A3-B5A19-4AB2-B5A19-4AB3-5(5A19-4A4-)28A5-12A2B12A6-12A2B12A7-11A2B11A9-10A2B10A11-9A2B9A14-7A2B7A17-6A2B6A20-4A2B5A22-3A2B3A25-2A2B2A28-2A20-2A19-A9-3A19-2A7-4A19-3A6-4A19-3A5-2(5A19-4A4-)6(A4B19-4A4-)7(5A19-4A4-)28A5-12A2B12A6-12A2B12A7-24A9-22A11-20A14-16A17-13A21-4A2B4A23-3A2B3A26-A2BA29-2B20-2A19-A9-3A19-2A8-3A19-2A7-4A19-3A5-5A19-4A4-5A11(19-3BA4-A4B)19-3BA2(4-5A19-4A)4-28A5-13A12BA7-12A11BA8-24A9-22A12-18A15-16A18-12A21-10A24-6A27-4A52-2A17-A11-3A17-2A9-4A17-3A7-5A17-4A6-5A17-4A5-6A11(17-4BA4-A5B)17-4BA2(4-6A17-5A)5-26A6-A19B6A7-4A15B5A9-22A11-2A15B3A13-2A4B12A16-14A19-12A22-8A25-6A83-2A17-A11-3A17-2A9-4A17-3A8-4A17-3A7-5A17-4A5-6A13(17-4BA4-A5B)17-4BA5-A24BA7-A18B5A8-4A13B7A9-22A11-5A10B5A14-3A2B11A17-2A2B10A20-10A23-8A115-2A15-A13-3A15-2A11-4A15-3A9-5A15-3BA7-6A15-3B2A6-6A15-4BA5-3A4B2(15-4B2A4-A6B)9(15-5BA4-A6B)15-5BA5-A5B15-4BA6-A24BA7-7A12B5A9-6A10B6A11-20A13-4A10B4A15-3A2B11A18-12A21-10A147-2A13-A15-3A13-2A13-3AB13-3A11-4AB13-3BA9-5AB13-4BA7-6AB13-5BA6-2A5B13-5BA6-A6B13-5BA5-2A6B13-5B2A4-A7B13-2B5A4-8A13-5B2A5(4-8A13-B6A)5-2(7A13-B5A6-)7A13-B5A7-6A14B4A9-5A14B3A11-4A11B5A13-18A15-16A17-14A21-8A181-2A11-A16-4A5-9A13-A4B5-10A11-2A4B5-11A10-A5B5-11A9-2A5B5-12A8-A6B5-12A7-2(A7B5-13A6-)A7B5-9B4A6-7AB5-12BA5-8AB5-8B6A4-8AB5-8B6A5-3(7AB5-8B5A6-)7AB5-8B5A7-6AB5-8B4A8-6AB5-8B4A9-5A14B3A10-5A14B3A11-4A14B2A13-18A16-14A20-10A26-2B185-3A7-2A19-14A16-18A13-20A12-20A11-22A9-2(24A8-)24A7-14A8B4A5(6-BA22BAB)7-2(A22BA8-)A22BA9-22B11-20B12-20B13-18B16-14B19-12B23-6B217-8A22-12A19-14A16-18A14-18A13-20A11-22A10-22A9-24A8-13A8B3A6(8-A22BA)9-22B10-22B11-20B13-18B14-18B16-14B19-12B22-8B280-8A22-12A19-14A17-16A15-18A13-20A12-20A11-22A10-12A8B2A6(10-22B)11-20B12-20B13-18B15-16B17-14B19-12B22-8B345-6B24-10B20-14B17-16B16-16B15-18B14-18B13-A18BA5(12-20B)13-18B14-A16BA15-16B16-2A12B2A17-14B20-10B24-6B412-2B27-8B22-12B19-14B18-B12AB17-2(16B16-)16B15-18B14-18B15-2(16B16-)2A12B2A17-14B18-14B19-2A8B2A22-3B2A3B27-2B509-4B26-B6AB23-10A21-A10BA20-12B19-3(14B18-)14B19-12B20-2ABA4BAB2A21-2BA4BA2B23-A6BA26-B2AB668-4B27-6B25-B6AB24-A6BA2(24-BA4BAB)25-A4BA27-4B494-
