model
size = 17 15 29, scale = 0.05, origin = -y
material 
  colors = A:#33C B:#603
voxels
----------------- ----------------- -------AA-------- -------AA-------- -------AA-------- ----------------- ----------------- ----------------- ----------------- ----------------- ----------------- ----------------- ----------------- ----------------- ----------------- 
----------------- ----------------- ------AAAA------- ------A--A------- ----------------- ----------------- ----------------- ----------------- ----------------- ----------------- ----------------- ----------------- ----------------- ----------------- ----------------- 
----------------- -------AA-------- -----AA--AA------ -----AA--AA------ ----------------- ----------------- ----------------- ----------------- ----------------- ----------------- ----------------- ----------------- ----------------- ----------------- ----------------- 
-------AA-------- ------AAAA------- -----AA--AA------ -----A----A------ ----------------- ----------------- ----------------- ----------------- ----------------- ----------------- ----------------- ----------------- ----------------- ----------------- ----------------- 
------A--A------- ------A--A------- ----AA-AA-AA----- ----------------- ----------------- ----------------- ----------------- ----------------- ----------------- ----------------- ----------------- ----------------- ----------------- ----------------- ----------------- 
------A--A------- -----AA--AA------ ----A--AA--A----- ----------------- ----------------- ----------------- ----------------- ----------------- ----------------- ----------------- ----------------- ----------------- ----------------- ----------------- ----------------- 
-----A----A------ -----A----A------ ---AA-AAAA-AA---- -------AA-------- ----------------- ----------------- ----------------- ----------------- ----------------- ----------------- ----------------- ----------------- ----------------- ----------------- ----------------- 
-----A----A------ ----AA----AA----- ---A--A--A--A---- ------AAAA------- -------AA-------- ----------------- ----------------- ----------------- ----------------- ----------------- ----------------- ----------------- ----------------- ----------------- ----------------- 
----A------A----- ----A------A----- --AA-AA--AA-AA--- ------A--A------- ------AAAA------- -------AA-------- ----------------- ----------------- ----------------- ----------------- ----------------- ----------------- ----------------- ----------------- ----------------- 
---AA------AA---- ---AA------AA---- --A--A----A--A--- -----AA--AA------ ------A--A------- ------AAAA------- -------AA-------- ----------------- ----------------- ----------------- ----------------- ----------------- ----------------- ----------------- ----------------- 
---A--------A---- ---A--------A---- -AA-AA----AA-AA-- -----A----A------ -----AA--AA------ ------A--A------- ------AAAA------- -------AA-------- ----------------- ----------------- ----------------- ----------------- ----------------- ----------------- ----------------- 
---A--------A---- --AA--------AA--- -A--A------A--A-- ----AA----AA----- -----A----A------ -----AA--AA------ ------A--A------- ------AAAA------- -------AA-------- ----------------- ----------------- ----------------- ----------------- ----------------- ----------------- 
--A----------A--- --A----------A--- AA-AA------AA-AA- ----A------A----- ----AA----AA----- -----A----A------ -----AA--AA------ ------A--A------- ------AAAA------- -------AA-------- ----------------- ----------------- ----------------- ----------------- ----------------- 
--A----------A--- -AA----------AA-- A--A--------A--A- ---AA------AA---- ----A------A----- ----AA----AA----- -----A----A------ -----AA--AA------ ------A--A------- ------AAAA------- -------AA-------- ----------------- ----------------- ----------------- ----------------- 
-A------------A-- -A------------A-- A-AA--------AA-A- ---A--------A---- ---AA------AA---- ----A------A----- ----AA----AA----- -----A----A------ -----AA--AA------ ------A--A------- ------AAAA------- -------AA-------- ----------------- ----------------- ----------------- 
-A------------A-- -A------------A-- A-AA--------AA-A- ---AA------AA---- ---AA------AA---- ----A------A----- ----AA----AA----- -----A----A------ -----AA--AA------ ------A--A------- ------AAAA------- -------AA-------- ----------------- ----------------- ----------------- 
--A----------A--- -AA----------AA-- A--A--------A--A- ---AA------AA---- ----A------A----- ----AA----AA----- -----A----A------ -----AA--AA------ ------A--A------- ------AAAA------- -------AA-------- ----------------- ----------------- ----------------- ----------------- 
--A----------A--- --A----------A--- AA-AA------AA-AA- ----A------A----- ----AA----AA----- -----A----A------ -----AA--AA------ ------A--A------- ------AAAA------- -------AA-------- ----------------- ----------------- ----------------- ----------------- ----------------- 
---A--------A---- --AA--------AA--- -A--A------AB-A-- ----AA----AAB---- -----A----ABB---- -----AA--AA-B---- ------A--A------- ------AAAA------- -------AA-------- ----------------- ----------------- ----------------- ----------------- ----------------- ----------------- 
---A--------A---- ---A--------A---- -AA-AA----AA-AA-- -----A----AB----- -----AA--AABB---- ------A--A-BBB--- ------AAAA---B--- -------AA-------- ----------------- ----------------- ----------------- ----------------- ----------------- ----------------- ----------------- 
----A------A----- ---AA------AA---- --A--A----A--A--- -----AA--AA------ ------A--A------- ------AAAA--BB--- -------AA---BB--- ------------BB--- -------------B--- ----------------- ----------------- ----------------- ----------------- ----------------- ----------------- 
----A------A----- ----A------A----- --AA-AA--AA-AA--- ------A--A------- ------AAAA------- -------AA-------- ----------------- -------------B--- -------------BB-- --------------B-- --------------B-- ----------------- ----------------- ----------------- ----------------- 
-----A----A------ ----AA----AA----- ---A--A--A--A---- ------AAAA------- -------AA-------- ----------------- ----------------- ----------------- -------------BB-- -------------BB-- --------------BB- --------------BB- ---------------B- ----------------- ----------------- 
-----A----A------ -----A----A------ ---AA-AAAA-AA---- -------AA-------- ----------------- ----------------- ----------------- ----------------- ----------------- ----------------- ----------------- ----------------- ---------------B- ---------------BB ----------------B 
-----AA--AA------ -----AA--AA------ ----A--AA--A----- ----------------- ----------------- ----------------- ----------------- ----------------- ----------------- ----------------- ----------------- ----------------- ----------------- ----------------- ----------------- 
------AAAA------- -----AAAAAA------ ----AA-AA-AA----- ----------------- ----------------- ----------------- ----------------- ----------------- ----------------- ----------------- ----------------- ----------------- ----------------- ----------------- ----------------- 
-------AA-------- ------AAAA------- -----A----A------ -----A----A------ ----------------- ----------------- ----------------- ----------------- ----------------- ----------------- ----------------- ----------------- ----------------- ----------------- ----------------- 
----------------- -------AA-------- -----AAAAAA------ -----AA--AA------ ----------------- ----------------- ----------------- ----------------- ----------------- ----------------- ----------------- ----------------- ----------------- ----------------- ----------------- 
----------------- ----------------- -------AA-------- -------AA-------- -------AA-------- ----------------- ----------------- ----------------- ----------------- ----------------- ----------------- ----------------- ----------------- ----------------- ----------------- 
