model
size = 22 25 5, scale = 0.05, origin = -y
material 
  colors = A:#FC9 B:#EEE C:#B00 D:#111 E:#001 F:#DDD
voxels
---------------------- ---------------------- ---------------------- ---------------------- ---------------------- ---------------------- ---------------------- ----------CC---------- ---------CBBC--------- --------CBBBBC-------- -------CBBBBBBC------- ------CBBBBBBBBC------ -----CBBBBBBBBBBC----- ----CCCCCCCCCCCCCC---- ---------------------- ---------------------- ---------------------- ---------------------- -------E------E------- ------EDE----EDE------ ------DFD----DFD------ -------D------D------- ---------------------- ---------------------- ---------------------- 
---------------------- ---------------------- ---------------------- ---------------------- ---------AAAA--------- -------AAAAAAAA------- -------AAAAAAAA------- ------AAAAAAAAAA------ ------AAAAAAAAAA------ ------AAAAAAAAAA------ ----AAAAAAAAAAAAAA---- ----AAAAAAAAAAAAAA---- ----AAAAAAAAAAAAAA---- ----AAAAAAAAAAAAAA---- ---AAAAAAAAAAAAAAAA--- ---AAAAAAAAAAAAAAAA--- ---AAAAAAAAAAAAAAAA--- ---AAAAAAAAAAAAAAAA--- ---AAAAAAAAAAAAAAAA--- ---AAAAFAAAAAAFAAAA--- ---AAAAAAAAAAAAAAAA--- ---AAAAAAAAAAAAAAAA--- ----AAAAAAAAAAAAAA---- ----AAAAAAAAAAAAAA---- ----AAAAAAAAAAAAAA---- 
---------------------- ---------------------- ---------------------- ---------AAAA--------- -------AAAAAAAA------- -------AAAAAAAA------- -----AAAAAAAAAAAA----- -----AAAAAAAAAAAA----- -----AAAAAAAAAAAA----- ----AAAAAAAAAAAAAA---- ----AAAAAAAAAAAAAA---- ----AAAAAAAAAAAAAA---- ----AAAAAAAAAAAAAA---- ----AAAAAAAAAAAAAA---- ---AAAAAAAAAAAAAAAA--- ---AAAAAAAAAAAAAAAA--- --AAAAAAAAAAAAAAAAAA-- --AAAAAAAAAAAAAAAAAA-- --AAAAAAAAAAAAAAAAAA-- --AAAAAAAAAAAAAAAAAA-- --AAAAAAAAAAAAAAAAAA-- ---AAAAAAAAAAAAAAAA--- ---AAAAAAAAAAAAAAAA--- ----AAAAAAAAAAAAAA---- ----AAAAAAAAAAAAAA---- 
---------------------- ---------------------- ---------AAAA--------- -------AAAAAAAA------- ------AAAAAAAAAA------ ------AAAAAAAAAA------ ----AAAAAAAAAAAAAA---- ----AAAAAAAAAAAAAA---- ----AAAAAAAAAAAAAA---- ---AAAAAAAAAAAAAAAA--- ---AAAAAAAAAAAAAAAA--- ---AAAAAAAAAAAAAAAA--- ---AAAAAAAAAAAAAAAA--- --AAAAAAAAAAAAAAAAAA-- --AAAAAAAAAAAAAAAAAA-- -AAAAAAAAAAAAAAAAAAAA- -AAAAAAAAAAAAAAAAAAAA- -AAAAAAAAAAAAAAAAAAAA- -AAAAAAAAAAAAAAAAAAAA- -AAAAAAAAAAAAAAAAAAAA- -AAAAAAAAAAAAAAAAAAAA- -AAAAAAAAAAAAAAAAAAAA- --AAAAAAAAAAAAAAAAAA-- --AAAAAAAAAAAAAAAAAA-- ---AAAAAAAAAAAAAAAA--- 
----------AA---------- ---------AAAA--------- -------AAAAAAAA------- ------AAAAAAAAAA------ -----AAAAAAAAAAAA----- ----AAAAAAAAAAAAAA---- ----AAAAAAAAAAAAAA---- ---AAAAAAAAAAAAAAAA--- ---AAAAAAAAAAAAAAAA--- --AAAAAAAAAAAAAAAAAA-- --AAAAAAAAAAAAAAAAAA-- -AAAAAAAAAAAAAAAAAAAA- -AAAAAAAAAAAAAAAAAAAA- AAAAAAAAAAAAAAAAAAAAAA AAAAAAAAAAAAAAAAAAAAAA AAAAAAAAAAAAAAAAAAAAAA AAAAAAAAAAAAAAAAAAAAAA AAAAAAAAAAAAAAAAAAAAAA AAAAAAAAAAAAAAAAAAAAAA AAAAAAAAAAAAAAAAAAAAAA AAAAAAAAAAAAAAAAAAAAAA -AAAAAAAAAAAAAAAAAAAA- -AAAAAAAAAAAAAAAAAAAA- --AAAAAAAAAAAAAAAAAA-- --AAAAAAAAAAAAAAAAAA-- 
