model
size = 11 31 11, scale = 0.05, origin = -y
material 
  colors = A:#B00 B:#2D1600 C:#200 D:#603 E:#444
voxels
----------- ----------- ----------- ----------- ----------- ----------- ----------- ----------- ----------- ----------- ----------- ----------- ----------- ----------- ----------- ----------- ----------- ----------- ----------- ----------- ----------- ----------- ----------- --BBBBBBB-- ----------- ----------- ----------- ----------- ----------- ----------- ----------- 
----------- ----------- ----------- ----------- ----------- ----------- ----------- ----------- ----------- ----------- ---AADDA--- ---ADAAA--- ---DAAAA--- ---DAAAA--- ---AAAAA--- ---AAAAA--- ---AAAAA--- ---AAAAA--- ---AAAAA--- ---AAAAA--- ---AAAAA--- ---AAAAA--- ---AAAAD--- -BBBBBBBBB- ---BBBBB--- ---BBBBB--- ---BBBBB--- ----------- ----------- ----------- ----------- 
----------- ----------- ----------- ----------- ----------- ----------- ----------- ----------- ----------- ----------- --AAAAAAA-- --AAAAAAA-- --AAAAAAA-- --AAAAAAA-- --DAAAAAA-- --AAAAAAA-- --AAAAAAA-- --AAAAAAA-- --AAAAAAA-- --AAAAAAA-- --AAAAAAA-- --AAAAAAD-- --AAAAAAA-- BBBBBBBBBBB --BBBBBBB-- --BBBBBBB-- --BBBBBBB-- ---BBBBB--- ----------- ----------- ----------- 
----------- ----------- ----------- ----------- ----------- ----------- ----------- ----------- ----------- ----------- -AAEEEEEAB- -AAAAAAAAA- -AAAAAAAAB- -AAAAAAAAB- -AAAAAAAAA- -DAAAAAAAB- -AAAAAAAAA- -AAAAAAAAA- -AAAAAAAAA- -AAAAAAAAA- -AAAAAAAAD- -AAAAAAAAA- -AAAAAAAAA- BBBBBBBBBBB -BBBBBBBBB- -BBBBBBBBB- -BBBBBBBBB- --BBBBBBB-- ---BBBBB--- ----------- ----------- 
----------- ----------- ----------- ----------- ----------- ----------- ----------- ----------- ----------- ----------- -AAEEEEEAA- -AAAAAAAAA- -AAAAAAAAA- -AAAAAAAAA- -AAAAAAAAA- -AAAAAAAAA- -DAAAAAAAA- -AAAAAAAAA- -AAAAAAAAD- -AAAAAAAAD- -AAAAAAAAA- -AAAAAAAAA- -AAAAAAAAA- BBBBBBBBBBB -BBBBBBBBB- -BBBBBBBBB- -BBBBBBBBB- --BBBBBBB-- ---BBBBB--- ----BBB---- ----BBB---- 
----------- ----------- ----------- ----------- ----------- ----------- ----------- ----------- ----------- ----------- -AAEEEEEAA- -AAAAAAAAA- -AAAAAAAAA- -AAAAAAAAA- -AAAAAAAAA- -AAAAAAAAA- -AAAAAAAAA- -DAAAAAAAD- -AAAAAAAAA- -AAAAAAAAA- -AAAAAAAAA- -AAAAAAAAA- -AAAAAAAAA- BBBBBBBBBBB -BBBBBBBBB- -BBBBBBBBB- -BBBBBBBBB- --BBBBBBB-- ---BBBBB--- ----BBB---- ----BBB---- 
----------- ----------- ----------- ----------- ----------- ----------- ----------- ----------- ----------- ----------- -AAEEEEEAA- -AAAAAAAAA- -AAAAAAAAA- -AAAAAAAAA- -AAAAAAAAA- -AAAAAAAAA- -AAAAAAAAA- -DAAAAAAAD- -AAAAAAAAA- -AAAAAAAAA- -AAAAAAAAA- -AAAAAAAAA- -AAAAAAAAA- BBBBBBBBBBB -BBBBBBBBB- -BBBBBBBBB- -BBBBBBBBB- --BBBBBBB-- ---BBBBB--- ----BBB---- ----BBB---- 
----------- ----------- ----------- ----------- ----------- ----------- ----------- ----------- ----------- ----------- -AAEEEEEAA- -BAAAAAAAA- -AAAAAAAAA- -AAAAAAAAA- -BAAAAAAAA- -AAAAAAAAA- -AAAAAAAAD- -AAAAAAAAA- -DAAAAAAAA- -DAAAAAAAA- -AAAAAAAAA- -AAAAAAAAA- -AAAAAAAAA- BBBBBBBBBBB -BBBBBBBBB- -BBBBBBBBB- -BBBBBBBBB- --BBBBBBB-- ---BBBBB--- ----------- ----------- 
----------- ----------- ----------- ----------- ----------- ----------- ----------- ----------- ----------- ----------- --AAAAAAA-- --AAAAAAA-- --AAAAAAA-- --AAAAAAA-- --AAAAAAA-- --AAAAAAD-- --AAAAAAA-- --AAAAAAA-- --AAAAAAA-- --AAAAAAA-- --DAAAAAA-- --AAAAAAA-- --AAAAAAA-- BBBBBBBBBBB --BBBBBBB-- --BBBBBBB-- --BBBBBBB-- ---BBBBB--- ----------- ----------- ----------- 
----------- ----------- ----------- ----------- ----------- ----------- ----------- ----------- ----------- ----------- ---DAAAA--- ---ADAAA--- ---AADDA--- ---AADDA--- ---AAAAD--- ---AAAAA--- ---AAAAA--- ---AAAAA--- ---AAAAA--- ---AAAAA--- ---AAAAA--- ---DAAAA--- ---ADAAA--- -BBBBBBBBB- ---BBBBB--- ---BBBBB--- ---BBBBB--- ----------- ----------- ----------- ----------- 
----CCC---- ----CCC---- ----CCC---- ----CCC---- ----CCC---- ----CCC---- ----CCC---- ----CCC---- ----CCC---- ----CCC---- ----CCC---- ----CCC---- ----CCC---- ----CCC---- ----CCC---- ----CCC---- ----CCC---- ----CCC---- ----CCC---- ----CCC---- ----CCC---- ----CCC---- ----CCC---- --BBBBBBB-- ----------- ----------- ----------- ----------- ----------- ----------- ----------- 
