model
size = 21 32 21, scale = 0.05, origin = -y
material 
  colors = A:#EEE B:#111 C:#E00 D:#F60 E:#FF3 F:#B00 G:#FF0 H:#D00 I:#F90 J:#A00 K:#FF6
voxels
10-B671-2(B20-)B416-7B206-4(B20-)B372-11B13-5B186-6(B20-)B329-13B10-9B14-5B163-10(5A16-)2CA2C16-2AC2A16-5A2(16-C3AC)3(16-5A)16-C3AC2(16-2(AC)A)16-2AC2A11-5B5A5B7-13B10-9B14-5B140-2(3A3-3A12-)3A3B3A6(12-9A)12-2C5A2C12-9A12-C7AC12-AC5ACA12-9A12-AC5ACA12-C7AC12-9A12-2C5A2C4(12-9A)8-4B9A4B6-13B9-11B11-9B14-5B118-2(2A3-D3-2A10-)2A2B-D-2B2A10-4AJAK4A2(5(10-11A)2(10-C9AC))4(10-11A)7-3B11A3B5-15B7-13B9-11B12-7B15-5B97-2(A-GH-FI-D-A10-)ABGH-FI-DBA10-4AJ2AK3A18(10-11A)6-4B11A4B4-15B7-13B9-11B11-9B13-7B16-3B76-2(2A2-2(E-)F2-2A8-)2AB2(-E)-F-B2A8-3ACAJADAK3A18(8-13A)5-4B12A3B3-17B5-15B7-13B9-11B11-9B14-5B17-3B55-2(A2-D-GF-HE2-A8-)AB-D-GF-HE-BA8-2ACAC2AD2AK2A18(8-13A)5-19B3-17B5-15B7-13B9-11B11-9B13-7B15-5B17-3B30-4BA-H-FHDE2-E-A4B-3BA-H-FHDE2-E-A3B2-3BABH-FHDE2-EBA3B3-2B3AJ4A2C3A2B4-2B13A2B5-B13AB6-B13AB7-14(13A8-)13A5-19B3-17B5-15B7-13B9-11B11-9B13-7B15-5B17-3B19-B14-2(A-E-IE2-2DF-A8-)ABE-IE3-DFBA8-3AJ2A2JK4A18(8-13A)5-19B3-17B5-15B7-13B9-11B11-9B13-7B15-5B17-3B34-2(2A2-DH-FGI-2A8-)2AB-DH-FGIB2A8-3AD2AK6A18(8-13A)5-19B3-17B5-15B7-13B9-11B11-9B14-5B17-3B56-2(A-GH-EDG2-A10-)ABGH-EDG-BA10-4AK3AC2A18(10-11A)6-19B4-15B7-13B9-11B11-9B13-7B16-3B77-2(2A2-G4-2A10-)2A2BG2-2B2A10-5A2C4A10-11A2(2(10-C9AC)5(10-11A))3(10-11A)7-17B5-15B7-13B9-11B12-7B15-5B98-2(3A3-3A12-)3A3B3A2(12-9A)12-2C5A2C12-9A12-C7AC12-AC5ACA12-9A12-AC5ACA12-C7AC12-9A12-2C5A2C8(12-9A)8-17B6-13B9-11B11-9B14-5B121-6(5A16-)2CA2C16-2AC2A16-5A2(16-C3AC)3(16-5A)16-C3AC2(16-2(AC)A)16-2AC2A4(16-5A)11-15B7-13B10-9B14-5B144-6(B20-)B329-13B10-9B14-5B165-4(B20-)B372-11B13-5B186-2(B20-)B416-7B206-B661-
