model
size = 32 26 32, scale = 0.05, origin = -y
material 
  colors = A:#FC9 B:#444 C:#F6C D:#F99
voxels
21-A20-4A5-A23-2A6-3A120-4A27-6A25-2A4B2A24-2B4C2B24-2C4D2C24-8A25-6A27-4A417-A-A21-2A6-3A21-2A6-2A22-2A6-2A23-9A22-10A21-12A20-12A19-14A18-A2B8A2BA18-B2C8A2CB18-C12AC19-12A20-12A21-10A23-D6AD26-4A376-2A8-A22-A8-A20-14A18-14A17-2(16A16-)16A15-18A14-AB14ABA15-C14AC2(16-16A)17-14A18-3D8A3D19-4B4A4B22-2CB2AB2C27-BA347-A27-16A15-18A14-18A13-4(20A12-)AB16ABA12-BC16ACB13-18A14-18A15-16A16-AB12A2B17-D2C8A3C20-3AD2AD3A24-6A339-20A12-20A11-7(22A10-)BD18ADB11-20A12-20A13-18A15-16A17-14A19-12A22-8A208-A56-A39-22A10-22A9-7(24A8-)24A9-21AD10-22A11-20A13-18A14-18A16-14A19-12A22-8A176-2A21-A-A5-2A22-3A6-2A20-2A3(8-24A)7-5(26A6-)26A7-24A8-23AB8-24A9-22A11-20A12-20A13-18A16-14A19-12A23-6A200-2A7-2A20-2A8-24A7-3(26A6-)26A5-28A4-28A5-3(26A6-)26A7-24A8-24A9-22A10-22A11-20A13-18A16-14A20-10A26-2A210-26A6-26A5-7(28A4-)28A5-2(26A6-)26A7-24A9-22A11-20A13-18A15-16A17-14A21-8A206-3(28A4-)28A3-3(30A2-)30A3-3(28A4-)28A5-26A6-26A7-24A9-22A11-20A13-18A15-16A18-12A24-4A176-28A4-28A3-7(30A2-)30A3-2(28A4-)28A5-26A7-24A8-24A9-22A11-20A14-16A17-14A21-8A169-A4-28A3-9(30A2-)30A3-28A4-28A5-26A6-26A7-24A9-22A11-20A13-18A16-14A20-10A73-A-2A27-3A29-2A3-A26-A4-29A3(2-30A)-128A-3(30A2-)30A3-28A4-28A5-26A7-24A8-24A9-22A12-18A15-16A18-12A24-4A47-2A29-2A31-2A26-2A3(2-30A)-192A-2(30A2-)30A3-28A4-28A5-26A6-26A7-24A9-22A11-20A14-16A18-12A23-6A142-30A2-30A-256A-2(30A2-)30A3-28A5-26A6-26A7-24A9-22A11-20A14-16A17-2(14A21-8A141-30A2-30A-256A-2(30A2-)30A3-28A4-28A5-26A7-24A9-22A11-20A13-18A16-)14A21-8A76-A64-30A2-30A-256A-2(30A2-)30A3-28A5-26A6-26A7-24A9-22A11-20A14-16A17-14A21-8A44-A31-A64-2(30A2-)30A-192A-2(30A2-)30A3-28A4-28A5-26A6-26A7-24A9-22A11-20A14-16A18-12A23-6A77-2A31-2A27-A4(2-30A)-128A-3(30A2-)30A3-28A4-28A5-26A7-24A8-24A9-22A12-18A15-16A18-12A24-4A77-A2-A26-3A2-A25-2A3-29A3-9(30A2-)30A3-28A4-28A5-26A6-26A7-24A9-22A11-20A13-18A16-14A20-10A167-2A4-28A3-29A3-7(30A2-)30A3-2(28A4-)28A5-26A7-24A8-24A9-22A11-20A14-16A17-14A21-8A174-3(28A4-)28A3-3(30A2-)30A3-3(28A4-)28A5-26A6-26A7-24A9-22A11-20A13-18A15-16A18-12A24-4A177-26A6-26A5-7(28A4-)28A5-2(26A6-)26A7-24A9-22A11-20A13-18A15-16A17-14A21-8A208-24A7-3(26A6-)26A5-28A4-28A5-3(26A6-)26A7-24A8-24A9-22A10-22A11-20A13-18A16-14A20-10A26-2A115-2A31-A30-2A30-2(24A8-)24A7-5(26A6-)26A7-2(24A8-)24A9-22A11-20A12-20A13-18A16-14A19-12A23-6A145-2A2(31-A)19-A11-22A10-22A9-7(24A8-)24A9-22A10-22A11-20A13-18A14-18A16-14A19-12A22-8A176-A20-A30-2A29-3A12-20A11-21A11-7(22A10-)22A11-20A12-20A13-18A15-16A17-14A19-12A22-8A197-A31-A78-16A15-18A14-18A13-5(20A12-)20A13-18A14-18A15-16A16-16A17-14A20-10A24-6A248-A30-2A31-2A5-2A21-14A18-14A17-2(16A16-)16A15-18A14-18A15-2(16A16-)16A17-14A18-14A19-12A22-8A27-2A282-A6-A23-A6-2A25-A5-A25-8A22-11A21-12A20-12A19-3(14A18-)14A19-12A20-12A21-10A23-8A26-4A320-A31-2A30-A123-4A27-6A25-3(8A24-)8A25-6A27-4A398-
