model
size = 9 32 9, scale = 0.05, origin = -y
material 
  colors = A:#BBB B:#C99
voxels
2-3A240-B43-5A96-5(B8-)4(A8-)A104-7A77-A7-3B5(6-BAB)5(6-3A)103-7A5-7(A8-)A7-3A6-BAB5-5(B3AB4-)4(5A4-)5A101-B7A77-A7-3B5(6-BAB)5(6-3A)104-5A96-5(B8-)4(A8-)A106-3A796-B62-
