model
size = 32, scale = 0.05, origin = -y
material 
  colors = A:#036 B:#006 C:#555 D:#800 E:#3F0 F:#001 G:#0A0 H:#888 I:#B00
voxels
929-F4-F13-2(F4-)F995-C3-C5-F8-C4-C2-C333-2(B5-B25-)B5-B59-3B531-C2-C4-C10-C3-C-C304-3B28-2(B3-B27-)B3-B28-3B564-C-C3-C12-C-3C42-F18-F243-3B28-B3GB27-BGEGB27-B3GB28-3B564-4C-C12-6C42-C18-C243-3B28-5B27-2BE2B27-5B28-3B563-7C12-7C41-C18-C209-7A24-2(9A23-)4AE4A2(23-9A)24-6IA340-20D5(12-D18-D)6-F5CD6CF4-F6CD5CF6-D18-D9-F5CF12-F5CF205-3(9A23-)4AE4A3(23-9A)340-D6-E9-D171-6C12-6C42-C18-C208-9D2(23-D7AD)23-D3AE3A2(D23-D7A)D23-9D340-D6-E9-D171-6C13-4C-C41-C18-C208-3(9A23-)4AE4A3(23-9A)340-D6-E9-D170-C-3C2-C12-4C2-C40-F18-F209-6A25-2(9A23-)4AE4A2(23-9A)24-7A341-D6-E9-D169-C3-C4-C10-C2-C4-C367-E440-D6-E9-D167-FC4-C5-F8-C3-C5-F206-5A26-2(7A25-)7A26-5A27-2(E31-)5(H31-E31-)H31-E24-D6-E9-D173-C13-F4-C85-3B70-ADA28-4(2AD2A17-7A3-)2AD2A17-6A5-ADA42-ADA28-4(2AD2A27-)2AD2A28-ADA223-D6-E9-D173-F18-F89-B27-3B29-3B5-2ADAI19-3B5-5A17-3(7A3-5A3-B13-)7A3-5A17-7A3-2AD2A40-IADA28-3(5A23-B3-)2(5A27-)2AD2A222-D6-E9-D276-B5-B26-B3-B27-B3GB4-2ADAI18-5B4-5A17-3(7A3-5A3B14-)7A3-5A17-7A3-2AD2A40-IAD2A27-3(5A24-3B)2(5A27-)2AD2A222-D6-E9-D276-B5-B26-B3-B27-BGEGB4-2ADAI18-2BE2B4-5A3B14-3(3AE3A3-5ABG15-)3AE3A3-5A3B14-3AE3A3-2AD2A3-B16-H19-IAD2A7-E16-3B5A7-H17-GB5A7-E17-GB5A7-H17-GB5A7-E16-3B5A7-H15-B3-2AD2A7-3(E31-H31-)E22-D6-E-E7-D276-B32-B3-B27-B3GB4-2ADAI18-5B4-5A3B14-7A3-5ABG15-7A-9E15-7A-E-5ABG15-7A-H-5A3B14-7A-E-2AD2I3-B21-H14-IAD2A12-E11-3B5A12-H12-GB5A12-E12-9E10-H12-GB5A-E10-E11-3B5A-2(H10-)B3-2ID2A-3(E10-E20-H10-H20-)E10-E17-D16ED174-F16-F118-3B29-3B5-2ADAI19-3B5-5A3B14-3(7A3-5ABG15-)7A3-5A3B14-7A3-2AD2A3-B36-IAD2A24-3B3(5A25-GB)5A24-3B5A23-B3-2AD2A222-D7-E8-D169-F4-C11-F4-C86-3B69-2ADAI27-5A17-3(7A3-5A3B14-)7A3-5A17-7A3-2AD2A40-IAD2A27-3(5A24-3B)2(5A27-)2AD2A222-D7-E8-D170-C3-C5-F6-F3-C5-F153-ADAI27-5A18-5A4-3(5A3-B13-7A3-)5A18-5A4-2AD2A19-H20-IAD2A6-E20-5A6-H16-B3-5A6-E16-B3-5A6-H16-B3-5A6-E20-5A6-H20-2AD2A6-3(E31-H31-)E23-D7-E8-D171-C2-C4-C8-C2-2C3-C154-ADA28-3(2AD2A27-)2A2(D2A28-A)DA20-E21-ADA28-4(2AD2A27-)2AD2A28-ADA223-D7-E8-D172-4C2-C10-C-2C2-C42-F16-F211-6A25-2(9A23-)4AE4A2(23-9A)24-7A340-D7-E8-D171-7C12-3C-C43-C16-C210-3(9A23-)4AE4A3(23-9A)339-D7-E8-D170-8C10-6C44-C16-C210-9D2(23-D7AD)23-D3AE3A2(D23-D7A)D23-9D339-18D5(14-D16-D)7-F6CD6CF2-F6CD6CF7-D16-D11-F5CF10-F5CF207-3(9A23-)4AE4A3(23-9A)528-7C11-7C42-C16-C211-7A24-2(9A23-)4AE4A2(23-9A)24-2A5I529-7C10-C-3C45-C16-C245-3B28-5B27-2BE2B27-5B28-3B562-C2-4C10-C2-2C-C44-F16-F245-3B28-B3GB27-BGEGB27-B3GB28-3B561-C4-C2-C8-C3-2C2-C306-3B28-2(B3-B27-)B3-B28-3B560-F5-C3-C6-F5-C3-C335-2(B5-B25-)B5-B59-3B534-C4-F11-C4-F1001-F16-F71-
