model
size = 17 21 32, scale = 0.05, origin = -y
material 
  colors = A:#E68888 B:#EEE C:#9CF D:#E14343 E:#E9AAAA F:#777 G:#888 H:#D00 I:#E46565 J:#444 K:#BBB L:#111 M:#222 N:#555
voxels
160-IAI13-I3DI13-3D319-D3AD12-DA3D11-IA-D-AI11-5D199-2(D-)D13-JDJ14-GAG14-3F47-F3AF11-D-A2D-D10-DC3-CD10-DIDADID13-D169-D13-3DIDJD11-JC-CG2(12-F3AF)45-B-3A-B10-F-3A-F10-DCDADC2D8-2D-2AD-D11-5D165-5D11-D-3C-JD9-J2(-C)-J10-F2(A-)AF10-FB3-BF11-B3-B13-A-A13-5A10-F2-B2A2-F8-D2-3A2-D8-L2-B2A2-L9-M-BAD-M11-5D147-7D9-DJC3-CJD8-J-C3-C-J8-F3(A-)AF9-A5-A12-3A11-B2-3A2-B8-B-5A-B8-F2-B2A2-F8-D2-B2A2-D8-M2-B2A2-M9-B-B2A-B10-L-3A-L11-2DH2D114-5G11-D5AD9-DC5-CJD7-NC-3A-CN8-F-5A-F8-A3B2A2BA8-B2-3A2-B11-3A13-5A11-D-B2A-D9-D2-B2A2-D7-J-C-B2A-C-J7-BC-3A-CB9-LC3ACL10-D2CH2CD11-2D-HD96-7G8-GE-A3-A-EG6-D2-5A2-D6-J-3B2A2B-J7-F3B2A2BF9-3B2A2B12-3A14-3A13-5A10-F3B2A2BF8-FC-B2A-CD7-AC-5A-CA6-LC-5A-CL7-LA5-AL8-DA-3C-AD9-D5HD80-3F12-2G3A2G8-GEC5-CEG6-D3G3A3GD6-J-3B2A2B-J7-F3B2A2BF9-3B2A2B11-5A10-B-5A-B8-BA-B2A-AB8-A3B2A2BA8-F3B2A2BF6-DJBC-B2A-CBJD4-EBC-5A-CBE4-IDC2-3A2-CDI6-HA5-AH9-6HD80-3F11-3GA-A3G7-E-C-3A-C-E6-D2-G3AG2-D6-J-2B3A2B-J7-F3B2A2BF8-A3B2A2BA8-4B2A3B9-3B2A2B10-A-B2A-A9-A3B2A2BA8-F3B2A2BF6-EJBC-B2A-CBJD4-EBC-5A-CBE4-I-C-5A-C-I5-DHA5-AHD8-7H79-5F10-2G2A-2A2G7-EA2-3A2-AE5-E-9A-E4-D-A3B2A2BA-E5-D-3B2A2B-D7-F3B2A2BF8-A3B2A2BA9-A-B2A-A9-A3B2A2BA8-F3B2A2BF7-J4B2A3BJ5-D2BC-B2A-C2BI4-EBC-5A-CBE4-ECB-5A-BCE5-DHA5-A2H8-7H79-5F10-2GA3-A2G6-GEA2-3A2-AEG4-EC9ACE4-DC9ACE5-JA-2B2AB-AD7-F3B2A2BF8-4B2A3B9-A-B2A-A9-A3B2A2BA8-F3B2A2BF7-J4B2A3BJ5-EBC3B2A2BCBI4-ECBA-B2A-ABCE4-ECB-5A-BCE5-2H2A3-2A2H8-D6H79-5F10-2GA3-A2G6-2EA-5A-A2E4-EC9ACE4-EC2A5-2ACE4-J-A-5A-A-D5-D-3B2A2B-D7-F-2B2AB-F8-A3B2A2BA8-F3B2A2BF7-J4B2A3BJ6-J4B2A3BJ5-EBC3B2A2BCBD4-ECBA-B2A-ABCE4-E-A-5A-A-E5-D2HA3-A2HD9-5H80-5F10-2GA3-A2G7-EA2-3A2-AE5-KC9ACK4-EC2A5-2ACE4-I-A-5A-A-I4-2F-3B2A2B-2F6-J-2B2AB-J8-J-2B2AB-J7-J4B2A3BJ6-J4B2A3BJ5-J-4B2A3B-J4-DBC3B2A2BCBD4-ECBA-B2A-ABCE5-DA-5A-AD7-2HA3-A2D10-2HC2H14-H65-5F10-2GA3-A2G7-EA7-AE5-KC9ACK4-EC9ACE3-A2-A-2B2AB-2(A2-)I3-3B2A2B3-2(I2-A2F-3B2A2B-2F)2(I2-AF2-3B2A2B2-F)D2-A3-3B2A2B3-D3-EBC-2B2AB-CBE4-ECB7ABCE5-D2A5-2AD7-DH2A-2AHD10-2HC2H14-H65-5F10-2G2A-2A2G7-EA7-AE5-GCA-5A-ACG4-EC2A-B2A-2ACE4-E-A-2B2AB-A-E3-A3-3B2A2B3-A2-D3(-B-3B2A2B-B-A2-A)2B-3B2A2B-2BA3-AB-3B2A2B-BA4-EB-7A-BE4-EBC-5A-CBE5-2DA5-A2D8-DHA-AHD12-DCD15-D16-H64-7G7-G2EC5-C2EG4-GCA7-ACG4-ECA-5A-ACE4-A-9A-A4-E-A-2B2AB-A-E2(4-AB-3B2A2B-BA)4-IB-3B2A2B-BI4-ABC-2B2AB-CBA4-AB-7A-BA5-ECA5-ACE6-E-CA3-AC-E7-DH2C-2CHD10-2DC2D14-3(D16-)D47-7G6-4E3C-3C4E3-ECA7-ACE5-E9-E5-EC3-3A3-CE4-EC-7A-CE4-AB9ABA4-E-9A-E4-A-9A-A4-EC-7A-CE5-ECA-3A-ACE6-ECA5-ACE7-D2C3A2CD9-2DC-C2D12-DCD15-H4(16-D)26-K5-3G5-K2-6E3C6E3-E-2C5A2C-E5-EC7ACE6-EC7ACE5-EC9-CE4-AC3-3A3-CA4-EC3-3A3-CE4-IC3-3A3-CI5-E9-E6-ECA5-ACE7-AC5ACA8-2DC3AC2D10-D3CD13-DCD15-H4(16-D)26-2K11-2K2-E-11E-E3-E2-2C3-2C2-E5-3(EC7ACE6-)2(EA7-AE6-)IA7-AI6-EC7ACE6-E-C5AC-E7-AC5ACA9-D2CA2CD11-2DC2D14-D50-2(D16-)D25-3K11-3K-E-2E-5E-2E-E3-EB-7C-BE6-BC5ACB8-2(B7-)BC7ACB2(6-EC7ACE)2(6-AC7ACA)7-AC5ACA9-AC3ACA10-2DCAC2D12-DHD15-D84-D25-2K13-2KG3E4-E4-3EG2-G2BA5CA2BG6-B-C3AC-2(B8-BC5AC)B8-2(B7-)AC7ACA7-9A8-AC5ACA8-A-C3AC-A9-AC3ACA11-D3CD13-3D126-2K13-2KG2E11-2EG6-5B11-B-3C-B10-BCA-ACB9-BC5ACB2(8-AC5ACA)8-IC5ACI8-AC5ACA9-AC3ACA11-2(AC)A12-2DC2D14-D127-K15-K40-2BC2B11-B-3C-B10-BC3ACB2(10-7A)10-I5AI2(10-AC3ACA)11-I3CI13-3D143-K15-K42-B14-2B2AB11-BAC3AB2(10-AC3ACA)10-IC3ACI10-AC3ACA11-2(AC)A12-2IC2I14-D236-3A13-A3CA12-2(AC)A12-5A12-2(AC)A12-A-C-A13-3I269-3A13-A-C-2(A12-2(AC))A13-3A303-ACA14-3A14-ACA14-3A303-ICI14-3A14-ACA15-I305-B15-ACA14-ACA15-I16-D271-B16-I15-ICI14-ICI15-2(I16-)D237-3(B16-)3(I16-)3(D16-)H93-
