model
size = 28 29 29, scale = 0.05, origin = -y
material 
  colors = A:#FCC B:#EEE C:#BBB D:#DDD E:#AAA F:#777 G:#FFC H:#F69 I:#F3C
voxels
---------------------------- ---------------------------- ---------------------------- ---------------------------- ---------------------------- ---------------------------- ---------------------------- ---------------------------- ---------------------------- ---------------------------- ---------------------------- ---------------------------- ---------------------------- ---------------------------- ---------------------------- ---------------------------- -----------------D-D-------- ---------------------------- ---------------------------- ---------------------------- ---------------------------- ---------------------------- ---------------------------- ---------------------------- ---------------------------- ---------------------------- ---------------------------- ---------------------------- ---------------------------- 
---------------------------- ---------------------------- ---------------------------- ---------------------------- ---------------------------- ---------------------------- ---------------------------- ---------------------------- ---------------------------- ---------------------------- ---------------------------- ---------------------------- ---------------------------- ---------------------------- ---------------------------- ---------------------------- ---------------DDBDBB------- ---------------DBBBBB------- -----------------CC--------- ---------------------------- ---------------------------- ---------------------------- ---------------------------- ---------------------------- ---------------------------- ---------------------------- ---------------------------- ---------------------------- ---------------------------- 
---------------------------- ---------------------------- ---------------------------- ---------------------------- ---------------------------- ---------------------------- ---------------------------- ---------------------------- ---------------------------- ---------------------------- ---------------------------- ---------------------------- ------------------D--------- -----------------D---------- -----------------D--D-D----- -----------------D---------- ---------------DD----------- ----------------DBBBBB------ ------------DD--BBBBB------- -------------D---CC--------- -----------------C-CC------- ----------------C----------- ---------------------------- ---------------------------- ---------------------------- ---------------------------- ---------------------------- ---------------------------- ---------------------------- 
---------------------------- ---------------------------- ---------------------------- ---------------------------- ---------------------------- ---------------------------- ---------------------------- ---------------------------- ---------------------------- ---------------------------- ---------------------------- ---------------------------- ------------------D--------- -----------------DD--------- -----------------DDBBDD----- ----------------DDBBBB------ --------------EDDBBBBB------ ----------------DBBBBBB----- -------------BBDBBBBBBB----- ------------CCBBBBBBBBB----- -------------CBBBBBBBC------ -------------C-CBBCC-------- ---------------CCC---------- ---------------C------------ ---------------------------- ---------------------------- ---------------------------- ---------------------------- ---------------------------- 
---------------------------- ---------------------------- ---------------------------- ---------------------------- ---------------------------- ---------------------------- ---------------------------- ---------------------------- ---------------------------- ---------------------------- --------------------D------- ---------------------------- -----------------DDBB------- ----------------EDBBBB------ ---------------EBDBBBBB----- --------------E-BBBBBBB----- -------------EIBABBBBBBB---- ------------E-BBABBBBBBB---- -------------BAAABBBBBBB---- -------------BAAABBBBBB----- ------------CBAAABBBBB------ ------------CBBBBBBBB------- -------------CBBBBB--------- --------------CCC----------- ---------------------------- ---------------------------- ---------------------------- ---------------------------- ---------------------------- 
---------------------------- ---------------------------- ---------------------------- ---------------------------- ---------------------------- ---------------------------- ---------------------------- ---------------------------- ---------------------------- ---------------------------- -----------------EEBD------- ----------------EBBDDB------ ----------------BBBBBBB----- ----------------BBBBBBBB---- -------------AAABBBBBBBB---- -------------AAAABBBBBBB---- -------------AAAABBBBBBBB--- ------------AAAAABBBBBBBB--- ------------AAAAABBBBBBB---- ------------AAAAABBBBBBB---- -----------CBAAAABBBBBBC---- -----------CBBBBBBBBBBB----- ------------BBBBBBBBBCC----- ------------CBBBBBBCC------- -------------CCC--C--------- ---------------------------- ---------------------------- ---------------------------- ---------------------------- 
---------------------------- ---------------------------- ---------------------------- ---------------------------- ---------------------------- ---------------------------- -------------DDD------------ -------------D-------------- ---------------------E------ ------------------EBBC-D---- ----------------EBBBBBC----- ---------------EBBBBBBBB---- ------------AA--BBBBBBBB---- ------------AAAABBBBBBBB---- ------------AAAABBBBBBBBB--- ------------AAAAABBBBBBBB--- ------------AAAAABBBBBBBBB-- ------------AAAAABBBBBBBBC-- -----------AAAAAABBBBBBBBC-- -----------AAAAAABBBBBBBC--- -----------AAAAAAABBBBBBC--- ----------CBBBBBBBBBBBBB---- -----------CBBBBBBBBBBB----- ------------BBBBBBBBBB------ ------------CCBBBBBB-------- -------------CC-CCC--------- ---------------------------- ---------------------------- ---------------------------- 
---------------------------- ---------------------------- ---------------------------- ---------------------------- -----------D---------------- ------------D--------------- ------------DDDDDDDD-------- -------------D-DDDD--------- --------------------EB-E---- ------------------BBBBBB---- -----------AA---BBBBBBBCC--- -----------AAA--BBBBBBBBC--- ----------AAAAAABBBBBBBBB--- ---------AAAAAAABBBBBBBBBC-- --------AAAAAAAABBBBBBBBBC-- --------AAAAAAAAAAAABBBBBC-- --------AAAAAAAAAAAAABBBBC-- --------AAAAAAAAAAAABBBBBC-- --------AAAAAAAAAAAABBBBBC-- ---------AAAAAAAAAABBBBBBC-- ----------AAAAAAAABBBBBBBC-- ----------ABBBBBBBBBBBBBC--- ----------CBBBBBBBBBBBBC---- -----------CBBBBBBBBBBB----- ------------BBBBBBBBC------- ------------C-BBBCCC-------- ---------------CC----------- ---------------------------- ---------------------------- 
---------------------------- ---------------------------- ---------------------------- ---------D------------------ ---------DD----------------- ----------DD-----BBB-------- -----------DDAAAABBBD------- ------------D-AAA-DD-------- -------------------BBBBB---- ---------AA-----BBBBBBBBB--- ------AAAAAAAA-ABBBBBBBBB--- ------AAAAAAAAAABBBBBBBBBC-- ------AAAAAAAAAABBBBBBBBBC-- ------AAAAAAAAAAAAAAABBBBB-- ------AAAAAAAAAAAAAAABBBBBC- ------AAAAAAAAAAAAAAABBBBBC- ------AAAAAAAAAAAAAAABBBBBC- ------AAAAAAAAAAAAAAABBBBBB- ------GAAAAAAAAAAAAAABBBBBC- -------CAAAAAAAAAAABBBBBBBC- -------AAAAAAAAAAABBBBBBBC-- --------AAABBBBABBBBBBBBBC-- ---------BBBBBBBBBBBBBBBB--- ----------CBBBBBBBBBBBBBC--- -----------CBBBBBBBBBBBC---- -----------CBBBBBBBABCC----- ------------CCC---CCC------- ---------------------------- ---------------------------- 
---------------------------- ---------------------------- -------D-------------------- --------D------------------- ---------D------------------ ----------DA-----BBBB------- ----------DAAAABBBBBB------- ----------AAAAABBBB--------- -------AAAAAAAABBB-BBBBBB--- ------AAAAAAAAABBBBBBBBBBB-- -----AAAAAAAAAAAABBBBBBBBC-- -----AAAAAAAAAAAAAABBBBBBBC- -----AAAAAAAAAAAAAAAAABBBBC- -----AAAAAAAAAAAAAAAAABBBBC- -----AAAAAAAAAAAAAAAAABBBBB- -----AAAAAAAAAAAAAAAAABBBBB- -----AAAAAAAAAAAAAAAAABBBBC- -----AAAAAAAAAAAAAAAAABBBBC- -----GAAAAAAAAAAAAAAAABBBBB- ----CFAAAAAAAAAAAAAAAABBBBB- -----CFAAAAAAAAAAAAAABBBBB-- ------AAAAAAAAAAAAAABBBBBB-- -------ABBBBBABBBBBABBBBBC-- ---------BBBBBBBBBBABBBBBC-- ---------CCBBBBBBBBBBBBBC--- -----------BBBBBBBBBBBB----- ------------CBBBBBBBC------- -------------CCCCCC--------- ---------------------------- 
---------------------------- ---------AAA---------------- -------D--AAAA-------------- --------DD-AAAA------------- ---------AAAAAA------------- ----------AAAAAAABBBBB------ -------AAAAAAAABBBBBB------- ------AAAAAAAAABBBBBB-BBB--- -----AAAAAAAAAABBBBBBBBBBB-- ---BBAAAAAAAAAABBBBBBBBBBB-- ---BBBAAAAAAAAAAAAAAAABBBBC- ----AAAAAAAAAAAAAAAAAABBBBC- ----AAAAAAAAAAAAAAAAAABBBBB- ----AAAAAAAAAAAAAAAAAABBBBC- ----AAAAAAAAAAAAAAAAAABBBBBC -----GAAAAAAAAAAAAAAAAABBBBC -----CAAAAAAAAAAAAAAAAABBBBC -----CAAAAAAAAAAAAAAAAABBBBB ----AAAAAAAAAAAAAAAAAAABBBBB ---FFAAAAAAAAAAAAAAAAAABBBB- ----CFAAAAAAAAAAAAAAAABBBBB- -----CFAAAAAAAAAAAAAABBBBBC- -------ABBBBBAAAAAAABBBBBB-- --------BBBBBBBBBAAABBBBB--- --------CCBBBBBBBBBBBBBBC--- ---------CBBBBBBBBBBBBBBC--- -----------BBBBBBBBBBBCC---- --------------CBBB-C-C------ ---------------------------- 
---------------------------- ------D--AAA---------------- -------D-AAAAA-------------- ---------AAAAAA------------- ---------AAAAAA------------- -------AAAAAAAAAABBBBB------ -----AAAAAAAAAABBBBBBBB----- -----AAAAAAAAAABBBBBBBBBBB-- -----AAAAAAAAAABBBBBBBBBBB-- ----BAAAAAAAAAABBBBBBBBBBBC- --BBAAAAAAAAAAAAAAAAAABBBBB- --BBAAAAAAAAAAAAAAAAAAABBBC- ----AAAAAAAAAAAAAAAAAAABBBBC ----AAAAAAAAAAAAAAAAAAABBBBC ----AAAAAAAAAAAAAAAAAAAABBBC ----AAAAAAAAAAAAAAAAAAAABBBC -----FAAAAAAAAAAAAAAAAAABBBC -----CAAAAAAAAAAAAAAAAAABBBC ----AAAAAAAAAAAAAAAAAAAABBBC ---FFAAAAAAAAAAAAAAAAAABBBC- ---FFAAAAAAAAAAAAAAAAABBBBC- ----CFAAAAAAAAAAAAAAABBBBBC- ------AABBBBAAAAAAAAABBBBBC- -------BBBBBAAAAAAAABBBBBC-- --------BBBBBBBBBBBBBBBBBC-- ---------CBBBBBBBBBBBBBBC--- -----------BBBBBBBBBBBBC---- ------------CCCCCCBBC------- ------------------CC-------- 
-------D-------------------- ------DDDAAA---------------- ---------AAAA--------------- ---------AAAAAA------------- -------GAAAAAAA------------- ----GAAAAAAAAAAAABBBBB------ ----AAAAAAAAAAABBBBBBB------ ----AAAAAAAAAAABBBBBBBABBC-- ----AAAAAAAAAAABBBBBBBABBBC- ----AAAAAAAAAAABBBBAAAABBC-- -BBBAAAAAAAAAAAAAAAAAAABBBCB -BBBAAAAAAAAAAAAAAAAAAABBBBC --AAAAAAAAAAAAAAAAAAAAAABBBC --AAAAAAAAAAAAAAAAAAAAAABBBC ---AAAAAAAAAAAAAAAAAAAAABBBC ----AAAAAAAAAAAAAAAAAAAABBBC -----AAAAAAAAAAAAAAAAAAABBBC -----CAAAAAAAAAAAAAAAAAABBBC ----AAAAAAAAAAAAAAAAAAAABBBC ---FFAAAAAAAAAAAAAAAAAABBBBC ---FFAAAAAAAAAAAAAAAAABBBBBC -----AAAAAAAAAAAAAAAAABBBBBC ------AAAAAAAAAAAAAAABBBBBBC -------BBBBBAAAAAAAABBBBBBC- --------BBBBBBBBBBBBBBBBBC-- --------BBBBBBBBBBBBBBBBB--- --------CBBBBBBBBBBBBBB----- ---------C-CBBBBBBBBBB------ --------------BCCC---------- 
-------D-------------------- -------DDAAA---------------- ---------AAAA--------------- ---------AAAAAA------------- -----GAAAAAAAAA------------- ----AAAAAAAAAAAAABBBBB------ ----AAAAAAAAAAAAABBBBBAC---- ---HAAAAAAAAAAAAABBBBBABBBB- ---HAAAAAAAAAAAAABBBBBABBBB- ---HAAAAAAAAAAAAAAAAAAABBBCC -BBAAAAAAAAAAAAAAAAAAAABBBBB -BBAAAAAAAAAAAAAAAAAAAAABBBB AAAAAAAAAAAAAAAAAAAAAAAABBBC AAAAAAAAAAAAAAAAAAAAAAAABBBB -AAAAAAAAAAAAAAAAAAAAAAABBBC --AAAAAAAAAAAAAAAAAAAAAABBBC ---AAAAAAAAAAAAAAAAAAAAABBBC ----AAAAAAAAAAAAAAAAAAAABBBC ----AAAAAAAAAAAAAAAAAAAABBBB ----AAAAAAAAAAAAAAAAAAABBBBB ----AAAAAAAAAAAAAAAAAAABBBBC ----AAAAAAAAAAAAAAAAAAABBBBC -----AAAAAAAAAAAAAAAABBBBBB- ------ABBBBBAAAAAAAABBBBBB-- -------BBBBBBBABBBBBBBBBBBC- --------BBBBBBBBBBBBBBBBBC-- ---------BBBBBBBBBBBBBBCC--- ---------CBBBBBBBBBCBB------ -------------CCCCC---------- 
-------D-------------------- --------DAAA---------------- ---------AAAA--------------- ---------AAAAAA------------- -----AAAAAAAAAA------------- ----AAAAAAAAAAA------------- ---HAAAAAAAAAAAAAAAAAAAB---- ---HAAAAAAAAAAAAAAAAAAABBBB- ---HAAAAAAAAAAAAAAAAAAABBBB- ---HAAAAAAAAAAAAAAAAAAABBBBC -BBAAAAAAAAAAAAAAAAAAAAABBBC -BAAAAAAAAAAAAAAAAAAAAAABBBC AAAAAAAAAAAAAAAAAAAAAAAABBBC AAAAAAAAAAAAAAAAAAAAAAAABBBC -AAAAAAAAAAAAAAAAAAAAAAABBBC --AAAAAAAAAAAAAAAAAAAAAABBBC --AAAAAAAAAAAAAAAAAAAAAABBBB ---AAAAAAAAAAAAAAAAAAAAABBBB ----AAAAAAAAAAAAAAAAAAAABBBC ----AAAAAAAAAAAAAAAAAAAABBBB ----AAAAAAAAAAAAAAAAAAAABBBB ----AAAAAAAAAAAAAAAAAAABBBB- -----AAAAAAAAAAAAAAAAABBBBC- ------AAAAAAAAAAAAAAABBBBBC- -------ABBBBBBAAAAABBBBBBB-- -------ABBBBBBBBBBBBBBBBBC-- --------BBBBBBBBBBBBBBBBC--- ---------CBBBBBBBBBCBBCC---- ----------CCCCCBB---CC------ 
-------D-------------------- --------DAAA---------------- ---------AAAA--------------- ---------AAAAAA------------- -----GAAAAAAAAA------------- ----AAAAAAAAAAAAAAAAAAAC---- ----AAAAAAAAAAAAAAAAAAA----- ---HAAAAAAAAAAAAAAAAAAABBC-- ---HAAAAAAAAAAAAAAAAAAABBBC- ---HAAAAAAAAAAAAAAAAAAABBBC- -BBAAAAAAAAAAAAAAAAAAAABBBBC -BBAAAAAAAAAAAAAAAAAAAAABBBC AAAAAAAAAAAAAAAAAAAAAAAABBBC AAAAAAAAAAAAAAAAAAAAAAAABBBC -AAAAAAAAAAAAAAAAAAAAAAABBBC --AAAAAAAAAAAAAAAAAAAAAABBBC ---AAAAAAAAAAAAAAAAAAAAABBBC ----AAAAAAAAAAAAAAAAAAAABBBC ----AAAAAAAAAAAAAAAAAAAABBBC ----AAAAAAAAAAAAAAAAAAAABBBC ----AAAAAAAAAAAAAAAAAABBBBBC ----AAAAAAAAAAAAAAAAAABBBBB- -----AAAAAAAAAAAAAAAAABBBBC- ------AAAAAAAAAAAAAABBBBBB-- -------AAAAAAAAABBBBBBBBBB-- -------AAABBBBBBBBBBBBBBB--- -------EAABBBBBBBBBBBBBB---- ----------BBBBBBBBBBBB------ ----------CCCBBBBCCC-------- 
--------D------------------- ---------AAA---------------- ---------AAAAA-------------- ---------AAAAAA------------- ------AAAAAAAAA------------- ----GAAAAAAAAAAAAAAAAAAC---- ----AAAAAAAAAAAAAAAAAAC----- ----AAAAAAAAAAAAAAAAAAABBB-- ----AAAAAAAAAAAAAAAAAAABBBB- ----AAAAAAAAAAAAAAAAAAABBBB- -BBAAAAAAAAAAAAAAAAAAAABBBBC -BBAAAAAAAAAAAAAAAAAAAAABBBB --AAAAAAAAAAAAAAAAAAAAAABBBC --AAAAAAAAAAAAAAAAAAAAAABBBB ---AAAAAAAAAAAAAAAAAAAAABBBC ---AAAAAAAAAAAAAAAAAAAAABBBC ----AAAAAAAAAAAAAAAAAAAABBBC -----CAAAAAAAAAAAAAAAAAABBBC ----AAAAAAAAAAAAAAAAAAABBBBB ----AAAAAAAAAAAAAAAAAAABBBBC ---FFAAAAAAAAAAAAAAAAABBBBBC -----AAAAAAAAAAAAAAAABBBBBC- -----AAAAAAAAAAAAAAAABBBBBB- -------AAAAAAAAAAAAABBBBBBC- -------AAAAAAAABBBBBBBBBBB-- --------AABBBBBBBBBBBBBBB--- --------EABBBBBBBBBBBBBB---- ---------CBBBBBBBBBBBC------ ---------CCCBCCCCCC--------- 
--------D------------------- --------D-AA---------------- ---------AAAAA-------------- ---------AAAAAA------------- ---------AAAAAA------------- -----AAAAAAAAAAAAAAAAAAA---- -----AAAAAAAAAAAAABBBBB----- -----AAAAAAAAAAAAABBBB-BBB-- -----AAAAAAAAAAAAABBBBBBBB-C ----BAAAAAAAAAAAAABBBBBBBBC- --BBAAAAAAAAAAAAAAAAAABBBBB- ---BAAAAAAAAAAAAAAAAAAABBBBB ----AAAAAAAAAAAAAAAAAAABBBBB ----AAAAAAAAAAAAAAAAAAABBBBC ----AAAAAAAAAAAAAAAAAAABBBBC ----AAAAAAAAAAAAAAAAAAABBBBC -----FAAAAAAAAAAAAAAAAABBBBC -----CAAAAAAAAAAAAAAAAABBBBC ----AAAAAAAAAAAAAAAAAAABBBBC ---FFAAAAAAAAAAAAAAAAABBBBBC ---FFAAAAAAAAAAAAAAAAABBBBB- -----AAAAAAAAAAAAAAAABBBBBBC ------AAAAAAAAAAAAAAABBBBB-- -------AAAAAAAAAAAAABBBBBBC- --------AAABBBBBBBBBBBBBBC-- -------EAABBBBBBBBBBBBBBC--- -------ECABBBBBBBBBBBBBC---- --------CCBBBBBBBBBBCB------ ---------CC-CCCCCC---------- 
---------------------------- --------D-AA---------------- --------D-AAAA-------------- ---------AAAAAA------------- ---------AAAAAA------------- -------GAAAAAAA------------- ------AAAAAAAAAAAABBBBB----- -----AAAAAAAAAAAAABBB--BB--- -----AAAAAAAAAAAAABBBBBBBB-- ---BBAAAAAAAAAAAAABBBBBBBBBC ---BBAAAAAAAAAAAAAAABBBBBBB- ----AAAAAAAAAAAAAAAAAABBBBBC ----AAAAAAAAAAAAAAAAAABBBB-- ----AAAAAAAAAAAAAAAAAABBBBBB ----AAAAAAAAAAAAAAAAAAABBBBC -----GAAAAAAAAAAAAAAAAABBBBC -----CAAAAAAAAAAAAAAAAABBBBC -----CAAAAAAAAAAAAAAAAABBBBC ----AAAAAAAAAAAAAAAAAAABBBC- ---FFAAAAAAAAAAAAAAAAABBBBC- ---FFAAAAAAAAAAAAAAAAABBBBC- ----CFAAAAAAAAAAAAAAABBBBBC- ------AAAAAAAAAAAAAAABBBBB-- -------AAAAAAAAABBBBBBBBBCC- -------EAAABBBBBBBBBBBBBBC-- ---------EBBBBBBBBBBBBBBC--- -------EECBBBBBBBBBBBBBC---- -----------BBBBBBBBCCCC----- -----------CBCCCC-----C----- 
---------------------------- --------D-AA---------------- -------DD-AAAA-------------- ---------D-AAAA------------- ----------AAAAA------------- ----------AAAAA------------- ---------AAAAAAAAABBBB------ -------AAAAAAAAAABBB---B---- ------AAAAAAAAAAABBBBBBBBC-- -----AAAAAAAAAAAABBBBBBBBB-C -----AAAAAAAAAAAABBBBBBBBBB- -----AAAAAAAAAAAABBBBBBBBBB- -----AAAAAAAAAAAABBBBBBBBBBC -----AAAAAAAAAAAAAAAAABBBBBC -----AAAAAAAAAAAAAAAAABBBBB- -----AAAAAAAAAAAAAAAAABBBBB- -----AAAAAAAAAAAAAAAAABBBBC- -----AAAAAAAAAAAAAAAAABBBBC- -----GAAAAAAAAAAAAAAAAABBBC- ----FFAAAAAAAAAAAAAAAABBBBB- ----CFAAAAAAAAAAAAAAAABBBBC- ------AAAAAAAAAAAABBBBBBBBC- -------AAAAAAAAAABBBBBBBBC-- --------AAAAAAAABBBBBBBBB--- --------ECABBBBBBBBBBBBBC--- ---------CBBBBBBBBBBBBB----- --------EECBBBBBBBBBBBC----- -----------CBBBBBBBBBC------ ------------C--C-----C------ 
---------------------------- ----------A----------------- ---------D------------------ ---------D------------------ ----------D----------------- -----------AAA-------------- ------------AAA---BB-------- -------------AAAABBD-------- -------AAAAA---AB--BBBBBB--- ------AAAAAAA---DBBBBBBBBB-- -----AAAAAAAAABBBBBBBBBBBBC- -----AAAAAAAAACBBBBBBBBBBB-- -----AAAAAAAAABBBBBBBBBBBB-C -----AAAAAAAAABBBBBBBBBBBBB- -----AAAAAAAAAAAAAAAABBBBBB- -----AAAAAAAAAAAAAAAABBBBBB- ------AAAAAAAAAAAAAAABBBBBB- -----AAAAAAAAAAAAAAAABBBBBBC -----GAAAAAAAAAAAAAAABBBBBC- -----CFAAAAAAAAAAAAAABBBBB-- ------AAAAAAAAAAAAAAABBBBB-- -------AAAAAAAAAAABBBBBBBC-- --------AAAAAAAAABBBBBBBC--- ---------CAAAAAABBBBBBAB---- --------ECCBBBBBBBBBBBBC---- ---------ECBBBBBBBBBBBC----- ----------ECBBBBBBBBB------- -----------EE-BBBCCCC------- ----------------C----------- 
---------------------------- ---------------------------- ---------------------------- ----------D----------------- -----------D---------------- ------------DD-------------- --------------D----DD------- ---------------DDDD-D------- ---------------------EEE---- ------------------BBBBBB---- -----------AA---DBBBBBBBB--- ---------AAAAA-BBBBBBBBBBC-C --------AAAAAACBBBBBBBBBB--- --------AAAAABBBBBBBBBBBBBCC -------AAAAAABBBBBBBBBBBBBC- -------AAAAAABBBBBAAABBBBB-- -------AAAAAABBBBAAAABBBBB-- -------AAAAAABBBBAAABBBBBB-- --------AAAAAAAAAAAABBBBBB-- --------AAAAAAAAAAAABBBBBB-- --------AAAAAAAAAAAABBBBB--- ---------AAAAAAAAABBBBBBB--- ----------CAAAAAABBBBBABC--- ----------CAAAAABBBBBBBC---- ----------ECAAAABBBBBBC----- -----------ECBBBBBBBCC------ --------------EBB----------- ---------------E------------ ---------------------------- 
---------------------------- ---------------------------- ---------------------------- ---------------------------- ---------------------------- --------------D------------- ---------------DDDD--------- ----------------DD---------- -------------------EE------- ------------------EBBB------ -----------------EBBBBBB---- ---------------EDBBBBBBBC--- -----------CAA-BBBBBBBBB---- -----------CABBBBBBBBBBB---- -----------CABBBBBBBBBBBB--- -----------AABBBBBBBBBBBB--- -----------AABBBBBBBBBBBBB-- -----------AABBBBBBBBBBBBB-- -----------AABBBBBBBBBBBB--- ----------EAABBBBBBBBBBBB--- ----------EAABBBBBBBBBBBB--- ----------EAAABBBBBBBBBB---- ---------EEAAAAAABBBBBBC---- -----------EAAAABBBBBBCC---- -----------EABAABBBBCCC----- ------------C-BBBBCC-------- ---------------------------- ---------------------------- ---------------------------- 
---------------------------- ---------------------------- ---------------------------- ---------------------------- ---------------------------- ---------------------------- ----------------D----------- ---------------------------- ---------------------------- -------------------E-------- ------------------BBB------- ----------------EDBBBBB----- --------------EEBBBBBBBB---- -------------BCCBBBBBBBB---- ------------CBBBBBBBBBBB---- -----------CBBBBBBBBBBBBB--- ------------BBBBBBBBBBBBBC-- ------------BBBBBBBBBBBBB--- ----------EAABBBBBBBBBBBB--- ----------EAABBBBBBBBBBB---- -----------EABBBBBBBBBBB---- -----------EAABBBBBBBBBC---- -----------EBAAAAABBBBC----- ------------BBBAABBBCCC----- ------------CDBDDBCC-C------ --------------CDCC---------- ---------------------------- ---------------------------- ---------------------------- 
---------------------------- ---------------------------- ---------------------------- ---------------------------- ---------------------------- ---------------------------- ---------------------------- ---------------------------- ---------------------------- ---------------------------- ---------------------------- -------------------BB------- -----------------DBBBB------ --------------CEBDBBBBB----- -------------ECCBBBBBBBB---- -----------ECCBCBBBBBBBB---- -----------CC-BBBBBBBBBBC--- ----------EECBBBBBBBBBBBC--- ----------EEBBBBBBBBBBBD---- -----------EBBBBBBBBBBBB---- ------------BBBBBBBBBBBC---- ------------BBBBBBBBBBC----- ------------CDBBBBBBCC------ ------------CDCDDCCC-------- -----------------C---------- -----------------C---------- ---------------------------- ---------------------------- ---------------------------- 
---------------------------- ---------------------------- ---------------------------- ---------------------------- ---------------------------- ---------------------------- ---------------------------- ---------------------------- ---------------------------- ---------------------------- ---------------------------- --------------------C------- ------------------C-CC------ ----------------CC-CBC------ --------------EEC-DBBCCC---- ------------EEC-BBDBBB------ -----------CC--CBBBBBDDCC--- ------------CC-CBBBBBBBD---- ------------CCBBBBBBDBB----- ------------CBBBBBBBBB-D---- ------------CCDDBBBBDCC----- ------------C-BBBBBCC------- ------------C-DDDCCC-------- --------------C------------- ---------------------------- ---------------------------- ---------------------------- ---------------------------- ---------------------------- 
---------------------------- ---------------------------- ---------------------------- ---------------------------- ---------------------------- ---------------------------- ---------------------------- ---------------------------- ---------------------------- ---------------------------- ---------------------------- ---------------------------- ---------------------------- --------------------C------- ------------------CCCCC----- -----------------CCD-D------ ------------C---DCCDB------- ------------CC--D-BCDCDD---- ------------C-CDCBC---C----- ------------CC-DCC--DC------ ----------------DCCC-------- ------------C-DCDCCCC------- --------------C-DCC--------- ---------------------------- ---------------------------- ---------------------------- ---------------------------- ---------------------------- ---------------------------- 
---------------------------- ---------------------------- ---------------------------- ---------------------------- ---------------------------- ---------------------------- ---------------------------- ---------------------------- ---------------------------- ---------------------------- ---------------------------- ---------------------------- ---------------------------- ---------------------------- -------------------DC------- ---------------------C------ ------------------DCC------- ------------------D--------- -----------------D---------- ----------------DD---------- ---------------------------- ---------------------------- ---------------------------- ---------------------------- ---------------------------- ---------------------------- ---------------------------- ---------------------------- ---------------------------- 
---------------------------- ---------------------------- ---------------------------- ---------------------------- ---------------------------- ---------------------------- ---------------------------- ---------------------------- ---------------------------- ---------------------------- ---------------------------- ---------------------------- ---------------------------- ---------------------------- ---------------------------- ---------------------C------ ---------------------------- ---------------------------- ---------------------------- ---------------------------- ---------------------------- ---------------------------- ---------------------------- ---------------------------- ---------------------------- ---------------------------- ---------------------------- ---------------------------- ---------------------------- 
