model
size = 24 19 9, scale = 0.05, origin = -y
material 
  colors = A:#777 B:#9CF C:#CF0
voxels
--------AAAAAAAA-------- --------AAAAAAAA-------- --------AAAAAAAA-------- --------AAAAAAAA-------- --------AAAAAAAA-------- --------AAAAAAAA-------- --------AAAAAAAAA------- -------AAAAAAAAAAA------ -------AAAAAAAAAAA------ -------AAAAAAAAAAA------ -------ACCACAACCAAC----- ------CACAAACACACAC----- -----ACACAACAACACAC----- -----CAACCAACACCAACC---- ----AAAAAAAAAAAAAAAA---- ---AAAAAAAAAAAAAAAAAA--- ---AAAAAAAAAAAAAAAAAA--- ----AAAAAAAAAAAAAAAA---- -------AAAAAAAAAAA------ 
--------AAAAAAAAA------- --------AAAAAAAAA------- --------AAAAAAAAA------- --------AAAAAAAAA------- -------AAABBBBBBA------- -------AAABBBBBBA------- -------AAABBBBBBAA------ ------AAAABBBBBBAA------ ------AAAABBBBBBAAA----- ------AAAABBBBBBAAA----- ------CAAABBBBBBAAAC---- -----CAAAABBBBBBBAAA---- ----CAAAAABBBBBBBBAAA--- ----AAAAAABBBBBBBBAAA--- --AAAAAAAABBBBBBBBAAAA-- --AAAAAAAABBBBBBBAAAAAA- --AAAAAAAAAAAAAAAAAAAA-- ---AAAAAAAAAAAAAAAAA---- -------AAAAAAAAAAA------ 
-------AAAAAAAAAA------- -------AAAAAAAAAA------- -------AAAAAAAAAA------- -------AAAAAAAAAA------- -------AAABBBBBBBA------ ------AAAABBBBBBBAA----- -----AAAAABBBBBBBAA----- -----AAAAABBBBBBBAAA---- -----AAAAABBBBBBBAAA---- -----AAAAABBBBBBBAAA---- -----AAAAABBBBBBBBAA---- ----CAAAAABBBBBBBBA----- ----AAAAAABBBBBBAAAA---- ---AAAAAAABBBBBBAAAAAA-- -AAAAAAAAABBBBBBAAAAAAAA -AAAAAAAAABBBBBBAAAAAAA- --AAAAAAAAAAAAAAAAAAAAA- --AAAAAAAAAAAAAAAAAAA--- -------AAAAAAAAAAA------ 
-------AAAAAAAAAAA------ -------AAAAAAAAAAA------ ------AAAAAAAAAAAA------ ------AAAAAAAAAAAAA----- ------AAAABBBBAAAAA----- -----AAAAABBBBAAAAA----- ----AAAAAABBBBAAAAAA---- ----AAAAAABBBBAAAAAA---- ----AAAAAABBBBAAAAAA---- ----AAAAAABBBBAAAAAA---- ----CAAAAABBBBAAAAAA---- ----AAAAAABBBBAAAAAA---- ----AAAAAABBBBAAAAAAA--- ---AAAAAAABBBBAAAAAAAAAA -AAAAAAAAABBBBAAAAAAAAAA -AAAAAAAAABBBBAAAAAAAAAA -AAAAAAAAAAAAAAAAAAAAAA- --AAAAAAAAAAAAAAAAAAAAA- -------AAAAAAAAAAA------ 
-------AAAAAAAAAAA------ -------AAAAAAAAAA------- ------AAAAAAAAAAAA------ ------AAAAAAAAAAAAA----- -----AAAAABBBBAAAAA----- -----AAAAABBBBAAAAA----- ----AAAAAABBBBAAAAAA---- ----AAAAAABBBBAAAAAA---- ----AAAAAABBBBAAAAAA---- ----AAAAAABBBBAAAAAA---- ----AAAAAABBBBAAAAAA---- ----AAAAAABBBBAAAAAA---- ----AAAAAABBBBAAAAAAA--- ---AAAAAAABBBBAAAAAAAAAA -AAAAAAAAABBBBAAAAAAAAAA AAAAAAAAAABBBBAAAAAAAAAA -AAAAAAAAAAAAAAAAAAAAAA- --AAAAAAAAAAAAAAAAAAAAA- -------AAAAAAAAAAA------ 
-------AAAAAAAAAA------- -------AAAAAAAAA-------- -------AAAAAAAAAA------- -------AAAAAAAAAAA------ ------AAAAAAAAAAAAA----- ------AAAAAAAAAAAAA----- -----AAAAAAAAAAAAAAA---- -----AAAAAAAAAAAAAAA---- ----AAAAAAAAAAAAAAAA---- ----AAAAAAAAAAAAAAAA---- ----AAAAAAAAAAAAAAAA---- ----AAAAAAAAAAAAAAAA---- ----AAAAAAAAAAAAAAAAA--- ---AAAAAAAAAAAAAAAAAAAAA -AAAAAAAAAAAAAAAAAAAAAAA AAAAAAAAAAAAAAAAAAAAAAAA -AAAAAAAAAAAAAAAAAAAAAA- --AAAAAAAAAAAAAAAAAAAA-- -------AAAAAAAAAAA------ 
--------AAAAAAAA-------- --------AAAAAAAA-------- --------AAAAAAAAA------- --------AAAAAAAAA------- -------AAAAAAAAAA------- ------AAAAAAAAAAAA------ ------AAAAAAAAAAAAA----- ------AAAAAAAAAAAAA----- -----AAAAAAAAAAAAAA----- -----AAAAAAAAAAAAAA----- ----AAAAAAAAAAAAAAAA---- ----AAAAAAAAAAAAAAAA---- ----AAAAAAAAAAAAAAAAA--- ---AAAAAAAAAAAAAAAAAAAA- -AAAAAAAAAAAAAAAAAAAAAA- -AAAAAAAAAAAAAAAAAAAAAA- ---AAAAAAAAAAAAAAAAAAA-- ---AAAAAAAAAAAAAAAAAAA-- -------AAAAAAAAAAA------ 
----------AAAAA--------- ----------AAAAA--------- ---------AAAAAAA-------- ---------AAAAAAA-------- ---------AAAAAAAA------- -------AAAAAAAAAA------- -------AAAAAAAAAA------- -------AAAAAAAAAAA------ ------AAAAAAAAAAAAA----- ------AAAAAAAAAAAAA----- ------AAAAAAAAAAAAA----- ----AAAAAAAAAAAAAAAA---- ----AAAAAAAAAAAAAAAAA--- ---AAAAAAAAAAAAAAAAAAA-- --AAAAAAAAAAAAAAAAAAAA-- --AAAAAAAAAAAAAAAAAAAA-- ----AAAAAAAAAAAAAAAAA--- ----AAAAAAAAAAAAAAAA---- -------AAAAAAAAAAA------ 
------------------------ ------------------------ -----------AAA---------- -----------AAAA--------- ----------AAAAA--------- ----------AAAAAA-------- ---------AAAAAAA-------- --------AAAAAAAAA------- --------AAAAAAAAA------- -------AAAAAAAAAAA------ -------AAAAAAAAAAAA----- ------AAAAAAAAAAAAA----- -----AAAAAAAAAAAAAAA---- ----AAAAAAAAAAAAAAAAA--- ---AAAAAAAAAAAAAAAAAA--- ----AAAAAAAAAAAAAAAAA--- -----AAAAAAAAAAAAAA----- ------AAAAAAAAAAAA------ -------AAAAAAAAAAA------ 
