model
size = 29 24 31, scale = 0.05, origin = -y
material 
  colors = A:#CFB53B B:#FF3 C:#1AAB9B D:#F09 E:#FFF
voxels
-AA------------------------AA -AA-----------------------AA- --AA-------------------AAAAA- --AAAAA--------------AAAA---- ----AAAAA----------AAAA------ -------AAAAAAAAAAAAAAA------- ----------------------------- ----------------------------- ----------------------------- ----------------------------- ----------------------------- ----------------------------- ----------------------------- ----------------------------- ----------------------------- ----------------------------- ----------------------------- ----------------------------- ----------------------------- ----------------------------- ----------------------------- ----------------------------- ----------------------------- ----------------------------- 
-AA------------------------AA -AA-----------------------AA- --AA-------------------AAAAA- --AAAAA--------------AAAA---- ----AAAAA----------AAAA------ -------AAAAAAAAAAAAAAA------- ----------------------------- ----------------------------- ----------------------------- ----------------------------- ----------------------------- ----------------------------- ----------------------------- ----------------------------- ----------------------------- ----------------------------- ----------------------------- ----------------------------- ----------------------------- ----------------------------- ----------------------------- ----------------------------- ----------------------------- ----------------------------- 
-AA------------------------AA -AA-----------------------AA- --AA-------------------AAAAA- --AAAAA--------------AAAA---- ----AAAAA----------AAAA------ -------AAAAAAAAAAAAAAA------- ----------------------------- ----------------------------- ----------------------------- ----------------------------- ----------------------------- ----------------------------- ----------------------------- ----------------------------- ----------------------------- ----------------------------- ----------------------------- ----------------------------- ----------------------------- ----------------------------- ----------------------------- ----------------------------- ----------------------------- ----------------------------- 
-AA------------------------AA -AA-----------------------AA- --AA-------------------AAAAA- --AAAAA--------------AAAA---- ----AAAAA----------AAAA------ -------AAAAAAAAAAAAAAA------- ----------------------------- ----------------------------- ----------------------------- ----------------------------- ----------------------------- ----------------------------- ----------------------------- ----------------------------- ----------------------------- ----------------------------- ----------------------------- ----------------------------- ----------------------------- ----------------------------- ----------------------------- ----------------------------- ----------------------------- ----------------------------- 
-AA------------------------AA -AA-----------------------AA- --AA-------------------AAAAA- --AAAAA--------------AAAA---- ----AAAAA----------AAAA------ -------AAAAAAAAAAAAAAA------- ----------------------------- ----------------------------- ----------------------------- ----------------------------- ----------------------------- ----------------------------- ----------------------------- ----------------------------- ----------------------------- ----------------------------- ----------------------------- ----------------------------- ----------------------------- ----------------------------- ----------------------------- ----------------------------- ----------------------------- ----------------------------- 
-AA------------------------AA -AA-----------------------AA- --AA-------------------AAAAA- --AAAAA--------------AAAA---- ----AAAAA----------AAAA------ -------AAAAAAAAAAAAAAA------- ----------------------------- ----------------------------- ----------------------------- ----------------------------- ----------------------------- ----------------------------- ----------------------------- ----------------------------- ----------------------------- ----------------------------- ----------------------------- ----------------------------- ----------------------------- ----------------------------- ----------------------------- ----------------------------- ----------------------------- ----------------------------- 
-AA------------------------AA -AA-----------------------AA- --AA-------------------AAAAA- --AAAAA--------------AAAA---- ----AAAAA----------AAAA------ -------AAAAAAAAAAAAAAA------- ----------------------------- ----------------------------- ----------------------------- ----------------------------- ----------------------------- ----------------------------- ----------------------------- ----------------------------- ----------------------------- ----------------------------- ----------------------------- ----------------------------- ----------------------------- ----------------------------- ----------------------------- ----------------------------- ----------------------------- ----------------------------- 
-AA------------------------AA -AA-----------------------AA- --AA-------------------AAAAA- --AAAAA--------------AAAA---- ----AAAAA----------AAAA------ -------AAAAAAAAAAAAAAA------- ----------------------------- ----------------------------- ----------------------------- ----------------------------- ----------------------------- ----------------------------- ----------------------------- ----------------------------- ----------------------------- ----------------------------- ----------------------------- ----------------------------- ----------------------------- ----------------------------- ----------------------------- ----------------------------- ----------------------------- ----------------------------- 
-AA------------------------AA -AA-----------------------AA- --AA-------------------AAAAA- --AAAAA--------------AAAA---- ----AAAAA----------AAAA------ -------AAAAAAAAAAAAAAA------- ----------------------------- ----------------------------- ----------------------------- ----------------------------- ----------------------------- ----------------------------- ----------------------------- ----------------------------- ----------------------------- ----------------------------- ----------------------------- ----------------------------- ----------------------------- ----------------------------- ----------------------------- ----------------------------- ----------------------------- ----------------------------- 
-AA------------------------AA -AA-----------------------AA- --AA-------------------AAAAA- --AAAAA--------------AAAA---- ----AAAAA----------AAAA------ -------AAAAAAAAAAAAAAA------- ----------------------------- ----------------------------- ----------------------------- ----------------------------- ----------------------------- ----------E--E-E--E---------- ----------E--E-E--E---------- ----------E-E---E-E---------- ----------EE-----EE---------- ----------E-------E---------- ----------------------------- ----------------------------- ----------------------------- ----------------------------- ----------------------------- ----------------------------- ----------------------------- ----------------------------- 
-AA------------------------AA -AA-----------------------AA- --AA-------------------AAAAA- --AAAAA--------------AAAA---- ----AAAAA----------AAAA------ -------AAAAAAAAAAAAAAA------- ----------------------------- ------------CCCCC------------ -----------CCCCCCC----------- ----------CCCCCCCCC---------- ---------CCCCCCCCCCC--------- --------CCCCCCCACCACC-------- -------CCCCCCCCACCACCC------- -------CCCCCACCCACACCC------- -------CCCCCCCCCCAACCC------- -------CCCCCCCCCCCACCC------- --------CCCCCCCCCCCCC-------- ---------CCCCCCCCCCC--------- ----------CCCCCCCCC---------- -----------CCCCCCC----------- ------------CCCCC------------ ----------------------------- ----------------------------- ----------------------------- 
-AA------------------------AA -AA-----------------------AA- --AA-------------------AAAAA- --AAAAA--------------AAAA---- ----AAAAA----------AAAA------ -------AAAAAAAAAAAAAAA------- ----------------------------- --------------AA------------- -----AAAAAAAAAAAAAAAAAAA----- ----AAAAAAAAAAAAAAAAAAAAA---- ---AAAAAAAAAAAAAAAAAAAAAAA--- ---AAAAAAAAAAAAAAAAAAAAAAA--- ---AAAAAAAAAAAAAAAAAAAAAAA--- ---AAAAAAAAAAAAAAAAAAAAAAA--- ---AAAAAAAAAAAAAAAAAAAAAAA--- ---AAAAAAAAAAAAAAAAAAAAAAA--- ---AAAAAAAAAAAAAAAAAAAAAAA--- ----AAAAAAAAAAAAAAAAAAAAA---- ------------AAAAA------------ ----------------------------- ----------------------------- ----------------------------- ----------------------------- ----------------------------- 
-AA------------------------AA -AA-----------------------AA- --AA-------------------AAAAA- --AAAAA--------------AAAA---- ----AAAAA----------AAAA------ -------AAAAAAAAAAAAAAA------- ------AAAAAAAAAAAAAAAAA------ -----AAAAAAAAAAAAAAAAAAA----- ----ABBBBBBBBBBBBBBBBBBBAA--- ---ABBBBBBBBBBBBBBBBBBBBBAA-- ---ABBBBBBBBBBBBBBBBBBBBBBA-- --ABBBBBBBBBBBBBBBBBBBBBBBA-- --ABBBBBBBBBBBBBBBBBBBBBBBA-- --ABBBBBBBBBBBBBBBBBBBBBBBA-- --ABBBBBBBBBBBBBBBBBBBBBBBA-- --ABBBBBBBBBBBBBBBBBBBBBBBA-- --ABBBBBBBBBBBBBBBBBBBBBBBA-- --AAAAAAAAAAAAAAAAAAAAAAAAA-- ---AAAAAAAAAAAAAAAAAAAAAAA--- ----------------------------- ----------------------------- ----------------------------- ----------------------------- ----------------------------- 
-AA------------------------AA -AA-----------------------AA- --AA-------------------AAAAA- --AAAAA--------------AAAA---- ----AAAAA----------AAAA------ -------AAAAAAAAAAAAAAA------- ------A---------AAAAAAA------ -----AAAAAAAAAAAAAAAAAAA----- ----ABBBBBBBBBBBBBBBBBBBAA--- ---ABBBBBBBBBBBBBBBBBBBBBAA-- --ABBBBBBBBBBBBBBBBBBBBBBBAA- -AABBBBBBBBBBBBBBBBBBBBBBBAA- -AABBBBBBBBBBBBBBBBBBBBBBBAA- -AAAAAAAAAAAAAAAAAAAAAAAAAAA- -AABBBBBBBBBBBBBBBBBBBBBBBAA- -AABBBBBBBBBBBBBBBBBBBBBBBAA- -AABBBBBBBBBBBBBBBBBBBBBBBAA- -AAAAAAAAAAAAAAAAAAAAAAAAAAA- --AAAAAAAAAAAAAAAAAAAAAAAAAA- ---AAAAAAAAAAAAAAAAAAAAAAAA-- ----------------------------- ----------------------------- ----------------------------- ----------------------------- 
-AA------------------------AA -AA-----------------------AA- --AA-------------------AAAAA- --AAAAA--------------AAAA---- ----AAAAA----------AAAA------ -------AAAAAAAAAAAAAAA------- ------AAAAAAAAAAAAAAAAA------ -----AAAAAAAAAAAAAAAAAAA----- ----ABBBBBBBBBBBBBBBBBBBAA--- ---ABBBBBBBBBBBBBBBBBBBBBAA-- --ABBBBBBBBBBBBBBBBBBBBBBBAA- -AABBBBBBBBBBBBBBBBBBBBBBBAA- -AABBBBBBBBBBBBBBBBBBBBBBBAA- -AABBBBBBBBBBBBBBBBBBBBBBBAA- -AABBBBBBBBBBBBBBBBBBBBBBBAA- -AABBBBBBBBBBBBBBBBBBBBBBBAA- -AABBBBBBBBBBBBBBBBBBBBBBBAA- -ABBBBBBBBBBBBBBBBBBBBBBBBBA- -AAAAAAAAAAAAAAAAAAAAAAAAAAA- --AAAAAAAAAAAAAAAAAAAAAAAAA-- ----------------------------- ----------------------------- ----------------------------- ----------------------------- 
-AA------------------------AA -AA-----------------------AA- --AA-------------------AAAAA- --AAAAA--------------AAAA---- ----AAAAA----------AAAA------ -------AAAAAAAAAAAAAAA------- ------AAAAAAAAAAAAAAAAA------ -----AAAAAAAAAAAAAAAAAAA----- ----ABBBBBBBBBBBBBBBBBBBAA--- ---ABBBBBBBBBBBBBBBBBBBBBAA-- --ABBBBBBBBBBBBBBBBBBBBBBBAA- AAAAAAAAAAAAAAAAAAAAAAAAAAAAA AAAAAAAAAAAAAAAAAAAAAAAAAAAAA AAADDDDDBB-BBBBBBDDBBBDDDDAAA AAADDDDDBBBBBBBB-DDBBBDDDDAAA AAADDDDDBBBBBBBBBDDBBBDDDDAAA AAADDDDDBBBBBBBBBDDBBBDDDDAAA AAAAAAAAAAAAAAAA-AAAAAAAAAAAA AAAAAAAAAAAAAAAAAAAAAAAAAAAAA --AAAAAAAAAAAAAAAAAAAAAAAAAA- ---AAAAAAAAAAAAAAAAAAAAAAA--- ----------------------------- ----------------------------- ----------------------------- 
-AA------------------------AA -AAA----------------------AA- --AA-------------------AAAAA- --AAAAA--------------AAAA---- ----AAAAA----------AAAA------ -------AAAAAAAAAAAAAAA------- ------AAAAAAAAAAAAAAAAA------ -----AAAAAAAAAAAAAAAAAAA----- ----ABBBBBBBBBBBBBBBBBBBAA--- ---ABBBBBBBBBBBBBBBBBBBBBAA-- --ABBBBBBBBBBBBBBBBBBBBBBBAA- AAAAAAAAAAAAAAAAAAAAAAAAAAAAA AAAAAAAAAAAAAAAAAAAAAAAAAAAAA AAADDDDDDDBDDDDDDDDDDDDDDDAAA AAADDDDDDDDDDDDDBBDDDDDDDDAAA AAABBBBBBBBBBBBBBBBBBBBBBBAAA AAABBBBBBBBBBBBBBBBBBBBBBBAAA AABBBBBBBBBBBBBB-BBBBBBBBBBAA AAAAAAAAAAAAAAAAAAAAAAAAAAAAA -AAAAAAAAAAAAAAAAAAAAAAAAAAA- --AAAAAAAAAAAAAAAAAAAAAAAAAA- ----------------------------- ----------------------------- ----------------------------- 
-AA------------------------AA -AAA----------------------AA- --AA-------------------AAAAA- --AAAAA--------------AAAA---- ----AAAAA----------AAAA------ -------AAAAAAAAAAAAAAA------- ------AAAAAAAAAAAAAAAAA------ -----AAAAAAAAAAAAAAAAAAA----- ----ABBBBBBBBBBBBBBBBBBBAA--- ---ABBBBBBBBBBBBBBBBBBBBBAA-- --ABBBBBBBBBBBBBBBBBBBBBBBAA- AAAAAAAAAAAAAAAAAAAAAAAAAAAAA AAAAAAAAAAAAAAAAAAAAAAAAAAAAA AAABBBBBBBBBBBBBBBBBBBBBBBAAA AAABBBBBBBBBBBBBBBBBBBBBBBAAA AAABBBBBBBBBBBBBBBBBBBBBBBAAA AAABBBBBBBBBBBBBBBBBBBBBBBAAA AADDDDDDDDDDDDDDBDDDDDDDDDDAA AAAAAAAAAAAAAAAAAAAAAAAAAAAAA -AAAAAAAAAAAAAAAAAAAAAAAAAAA- --AAAAAAAAAAAAAAAAAAAAAAAAAA- ---AAAAAAAAAAAAAAAAAAAAAAAA-- ----------------------------- ----------------------------- 
-AA------------------------AA -AAA----------------------AA- --AA-------------------AAAAA- --AAAAA--------------AAAA---- ----AAAAA----------AAAA------ -------AAAAAAAAAAAAAAA------- ------AAAAAAAAAAAAAAAAA------ -----AAAAAAAAAAAAAAAAAAA----- ----ABBBBBBBBBBBBBBBBBBBAA--- ---ABBBBBBBBBBBBBBBBBBBBBAA-- --ABBBBBBBBBBBBBBBBBBBBBBBAA- AAAAAAAAAAAAAAAAAAAAAAAAAAAAA AAAAAAAAAAAAAAAAAAAAAAAAAAAAA AAABBBBBBBBBBBBBBBBBBBBBBBAAA AAABBBBBBBBBBBBBBBBBBBBBBBAAA AAABBBBBBBBBBBBBBBBBBBBBBBAAA AAABBBBBBBBBBBBBBBBBBBBBBBAAA AABBBBBBBBBBBBBBBBBBBBBBBBBAA AAAAAAAAAAAAAAAAAAAAAAAAAAAAA -AAAAAAAAAAAAAAAAAAAAAAAAAAA- --AAAAAAAAAAAAAAAAAAAAAAAAAA- ---AAAAAAAAAAAAAAAAAAAAAAAA-- ----AAAAAAAAAAAAAAAAAAAAAA--- ----------------------------- 
-AA------------------------AA -AAA----------------------AA- --AA-------------------AAAAA- --AAAAA--------------AAAA---- ----AAAAA----------AAAA------ -------AAAAAAAAAAAAAAA------- ------AAAAAAAAAAAAAAAAA------ -----AAAAAAAAAAAAAAAAAAA----- ----ABBBBBBBBBBBBBBBBBBBAA--- ---ABBBBBBBBBBBBBBBBBBBBBAA-- --ABBBBBBBBBBBBBBBBBBBBBBBAA- AAAAAAAAAAAAAAAAAAAAAAAAAAAAA AAAAAAAAAAAAAAAAAAAAAAAAAAAAA AAABBBBBBBBBBBBBBBBBBBBBBBAAA AAABBBBBBBBBBBBBBBBBBBBBBBAAA AAABBBBBBBBBBBBBBBBBBBBBBBAAA AAABBBBBBBBBBBBBBBBBBBBBBBAAA AABBBBBBBBBBBBBBBBBBBBBBBBBAA AAAAAAAAAAAAAAAAAAAAAAAAAAAAA -AAAAAAAAAAAAAAAAAAAAAAAAAAA- --AAAAAAAAAAAAAAAAAAAAAAAAAA- ---AAAAAAAAAAAAAAAAAAAAAAAA-- ----AAAAAAAAAAAAAAAAAAAAAA--- -------------EC-------------- 
-AA------------------------AA -AAA----------------------AA- --AA-------------------AAAAA- --AAAAA--------------AAAA---- ----AAAAA----------AAAA------ -------AAAAAAAAAAAAAAA------- ------AAAAAAAAAAAAAAAAA------ -----AAAAAAAAAAAAAAAAAAA----- ----ABBBBBBBBBBBBBBBBBBBAA--- ---ABBBBBBBBBBBBBBBBBBBBBAA-- --ABBBBBBBBBBBBBBBBBBBBBBBAA- AAAAAAAAAAAAAAAAAAAAAAAAAAAAA AAAAAAAAAAAAAAAAAAAAAAAAAAAAA AAABBBBBBBBBBBBBBBBBBBBBBBAAA AAABBBBBBBBBBBBBBBBBBBBBBBAAA AAABBBBBBBBBBBBBBBBBBBBBBBAAA AAABBBBBBBBBBBBBBBBBBBBBBBAAA AABBBBBBBBBBBBBBBBBBBBBBBBBAA AAAAAAAAAAAAAAAAAAAAAAAAAAAAA -AAAAAAAAAAAAAAAAAAAAAAAAAAA- --AAAAAAAAAAAAAAAAAAAAAAAAAA- ---AAAAAAAAAAAAAAAAAAAAAAAA-- ----AAAAAAAAAAAAAAAAAAAAAA--- -------------CE-------------- 
-AA------------------------AA -AAA----------------------AA- --AA-------------------AAAAA- --AAAAA--------------AAAA---- ----AAAAA----------AAAA------ -------AAAAAAAAAAAAAAA------- ------AAAAAAAAAAAAAAAAA------ -----AAAAAAAAAAAAAAAAAAA----- ----ABBBBBBBBBBBBBBBBBBBAA--- ---ABBBBBBBBBBBBBBBBBBBBBAA-- --ABBBBBBBBBBBBBBBBBBBBBBBAA- AAAAAAAAAAAAAAAAAAAAAAAAAAAAA AAAAAAAAAAAAAAAAAAAAAAAAAAAAA AAABBBBBBBBBBBBBBBBBBBBBBBAAA AAABBBBBBBBBBBBBBBBBBBBBBBAAA AAABBBBBBBBBBBBBBBBBBBBBBBAAA AAABBBBBBBBBBBBBBBBBBBBBBBAAA AABBBBBBBBBBBBBBBBBBBBBBBBBAA AAAAAAAAAAAAAAAAAAAAAAAAAAAAA -AAAAAAAAAAAAAAAAAAAAAAAAAAA- --AAAAAAAAAAAAAAAAAAAAAAAAAA- ---AAAAAAAAAAAAAAAAAAAAAAAA-- ----AAAAAAAAAAAAAAAAAAAAAA--- ----------------------------- 
-AA------------------------AA -AAA----------------------AA- --AA-------------------AAAAA- --AAAAA--------------AAAA---- ----AAAAA----------AAAA------ -------AAAAAAAAAAAAAAA------- ------AAAAAAAAAAAAAAAAA------ -----AAAAAAAAAAAAAAAAAAA----- ----ABBBBBBBBBBBBBBBBBBBAA--- ---ABBBBBBBBBBBBBBBBBBBBBAA-- --ABBBBBBBBBBBBBBBBBBBBBBBAA- AAAAAAAAAAAAAAAAAAAAAAAAAAAAA AAAAAAAAAAAAAAAAAAAAAAAAAAAAA AAABBBBBBBBBBBBBBBBBBBBBBBAAA AAABBBBBBBBBBBBBBBBBBBBBBBAAA AAABBBBBBBBBBBBBBBBBBBBBBBAAA AAABBBBBBBBBBBBBBBBBBBBBBBAAA AABBBBBBBBBBBBBBBBBBBBBBBBBAA AAAAAAAAAAAAAAAAAAAAAAAAAAAAA -AAAAAAAAAAAAAAAAAAAAAAAAAAA- --AAAAAAAAAAAAAAAAAAAAAAAAAA- ---AAAAAAAAAAAAAAAAAAAAAAAA-- ----AAAAAAAAAAAAAAAAAAAAAA--- ----------------------------- 
-AA------------------------AA -AAA----------------------AA- --AA-------------------AAAAA- --AAAAA--------------AAAA---- ----AAAAA----------AAAA------ -------AAAAAAAAAAAAAAA------- ------AAAAAAAAAAAAAAAAA------ -----AAAAAAAAAAAAAAAAAAA----- ----ABBBBBBBBBBBBBBBBBBBAA--- ---ABBBBBBBBBBBBBBBBBBBBBAA-- --ABBBBBBBBBBBBBBBBBBBBBBBAA- AAAAAAAAAAAAAAAAAAAAAAAAAAAAA AAAAAAAAAAAAAAAAAAAAAAAAAAAAA AAABBBBBBBBBBBBBBBBBBBBBBBAAA AAABBBBBBBBBBBBBBBBBBBBBBBAAA AAABBBBBBBBBBBBBBBBBBBBBBBAAA AAABBBBBBBBBBBBBBBBBBBBBBBAAA AABBBBBBBBBBBBBBBBBBBBBBBBBAA AAAAAAAAAAAAAAAAAAAAAAAAAAAAA -AAAAAAAAAAAAAAAAAAAAAAAAAAA- --AAAAAAAAAAAAAAAAAAAAAAAAAA- ---AAAAAAAAAAAAAAAAAAAAAAAA-- ----------------------------- ----------------------------- 
-AA------------------------AA -AAA----------------------AA- --AA-------------------AAAAA- --AAAAA--------------AAAA---- ----AAAAA----------AAAA------ -------AAAAAAAAAAAAAAA------- ------AAAAAAAAAAAAAAAAA------ -----AAAAAAAAAAAAAAAAAAA----- ----ABBBBBBBBBBBBBBBBBBBAA--- ---ABBBBBBBBBBBBBBBBBBBBBAA-- --ABBBBBBBBBBBBBBBBBBBBBBBAA- AAAAAAAAAAAAAAAAAAAAAAAAAAAAA AAAAAAAAAAAAAAAAAAAAAAAAAAAAA AAABBBBBBBBBBBBBBBBBBBBBBBAAA AAABBBBBBBBBBBBBBBBBBBBBBBAAA AAABBBBBBBBBBBBBBBBBBBBBBBAAA AAABBBBBBBBBBBBBBBBBBBBBBBAAA AABBBBBBBBBBBBBBBBBBBBBBBBBAA AAAAAAAAAAAAAAAAAAAAAAAAAAAAA -AAAAAAAAAAAAAAAAAAAAAAAAAAA- --AAAAAAAAAAAAAAAAAAAAAAAAAA- ----------------------------- ----------------------------- ----------------------------- 
-AA------------------------AA -AAA----------------------AA- --AA-------------------AAAAA- --AAAAA--------------AAAA---- ----AAAAA----------AAAA------ -------AAAAAAAAAAAAAAA------- ------AAAAAAAAAAAAAAAAA------ -----AAAAAAAAAAAAAAAAAAA----- ----ABBBBBBBBBBBBBBBBBBBAA--- ---ABBBBBBBBBBBBBBBBBBBBBAA-- --ABBBBBBBBBBBBBBBBBBBBBBBAA- AAAAAAAAAAAAAAAAAAAAAAAAAAAAA AAAAAAAAAAAAAAAAAAAAAAAAAAAAA AAABBBBBBBBBBBBBBBBBBBBBBBAAA AAABBBBBBBBBBBBBBBBBBBBBBBAAA AAABBBBBBBBBBBBBBBBBBBBBBBAAA AAABBBBBBBBBBBBBBBBBBBBBBBAAA AABBBBBBBBBBBBBBBBBBBBBBBBBAA AAAAAAAAAAAAAAAAAAAAAAAAAAAAA -AAAAAAAAAAAAAAAAAAAAAAAAAAA- --AAAAAAAAAAAAAAAAAAAAAAAAAA- ----------------------------- ----------------------------- ----------------------------- 
-AA------------------------AA -AAA----------------------AA- --AA-------------------AAAAA- --AAAAA--------------AAAA---- ----AAAAA----------AAAA------ -------AAAAAAAAAAAAAAA------- ------AAAAAAAAAAAAAAAAA------ -----AAAAAAAAAAAAAAAAAAA----- ----ABBBBBBBBBBBBBBBBBBBAA--- ---ABBBBBBBBBBBBBBBBBBBBBAA-- --ABBBBBBBBBBBBBBBBBBBBBBBAA- AAAAAAAAAAAAAAAAAAAAAAAAAAAAA AAAAAAAAAAAAAAAAAAAAAAAAAAAAA AAABBBBBBBBBBBBBBBBBBBBBBBAAA AAABBBBBBBBBBBBBBBBBBBBBBBAAA AAABBBBBBBBBBBBBBBBBBBBBBBAAA AAABBBBBBBBBBBBBBBBBBBBBBBAAA AABBBBBBBBBBBBBBBBBBBBBBBBBAA AAAAAAAAAAAAAAAAAAAAAAAAAAAAA -AAAAAAAAAAAAAAAAAAAAAAAAAAA- ----------------------------- ----------------------------- ----------------------------- ----------------------------- 
-AA------------------------AA -AAA----------------------AA- --AA-------------------AAAAA- --AAAAA--------------AAAA---- ----AAAAA----------AAAA------ -------AAAAAAAAAAAAAAA------- -------AAAAAAAAAAAAAAAA------ -----A-AAAAAAAAAAAAAAAAA----- ----AB-BBBBBBBBBBBBBBBBBAA--- ---ABB-BBBBBBBBBBBBBBBBBBAA-- --ABBB-BBBBBBBBBBBBBBBBBBBAA- AAAAAA-AAAAAAAAAAAAAAAAAAAAAA AAAAAA-AAAAAAAAAAAAAAAAAAAAAA AAABBB-BBBBBBBBBBBBBBBBBBBAAA AAABBB-BBBBBBBBBBBBBBBBBBBAAA AAABBB-BBBBBBBBBBBBBBBBBBBAAA AAABBB-BBBBBBBBBBBBBBBBBBBAAA AABBBB-BBBBBBBBBBBBBBBBBBBBAA -AAAAAAAAAAAAAAAAAAAAAAAAAAA- ----------------------------- ----------------------------- ----------------------------- ----------------------------- ----------------------------- 
----------------------------- -AAA----------------------AA- --AA-------------------AAAAA- --AAAAA--------------AAAA---- ----AAAAA----------AAAA------ -------AAAAAAAAAAAAAAA------- ----------------------------- -----AAAAAAAAAAAAAAAAAAA----- ----ABBBBBBBBBBBBBBBBBBBAA--- ---ABBBBBBBBBBBBBBBBBBBBBAA-- --ABBBBBBBBBBBBBBBBBBBBBBBAA- AAAAAAAAAAAAAAAAAAAAAAAAAAAAA AAAAAAAAAAAAAAAAAAAAAAAAAAAAA AAABBBBBBBBBBBBBBBBBBBBBBBAAA AAABBBBBBBBBBBBBBBBBBBBBBBAAA AAABBBBBBBBBBBBBBBBBBBBBBBAAA AAABBBBBBBBBBBBBBBBBBBBBBBAAA AAAAAAAAAAAAAAAAAAAAAAAAAAAAA ----------------------------- ----------------------------- ----------------------------- ----------------------------- ----------------------------- ----------------------------- 
----------------------------- --AA------------------------- --AA-------------------AAAAA- --AAAAA--------------AAAA---- ----AAAAA----------AAAA------ -------AAAAAAAAAAAAAAA------- ----------------------------- ----------------------------- ----AAAAAAAAAAAAAAAAAAAAAA--- ---ABBBBBBBBBBBBBBBBBBBBBAA-- --AAAAAAAAAAAAAAAAAAAAAAAAAA- ----------------------------- -AAAAAAAAAAAAAAAAAAAAAAAAAAAA AAAAAAAAAAAAAAAAAAAAAAAAAAAAA AAAAAAAAAAAAAAAAAAAAAAAAAAAAA AAAAAAAAAAAAAAAAAAAAAAAAAAAAA AAAAAAAAAAAAAAAAAAAAAAAAAAAAA ----------------------------- ----------------------------- ----------------------------- ----------------------------- ----------------------------- ----------------------------- ----------------------------- 
----------------------------- ----------------------------- ----------------------------- --AAAAA--------------AAAA---- ----------------------------- ----------------------------- ----------------------------- ----------------------------- ----------------------------- ---AAAAAAAAAAAAAAAAAAAAAAAA-- ----------------------------- ----------------------------- ----------------------------- ----------------------------- ----------------------------- ----------------------------- ----------------------------- ----------------------------- ----------------------------- ----------------------------- ----------------------------- ----------------------------- ----------------------------- ----------------------------- 
