model
size = 29 24 31, scale = 0.05, origin = -y
material 
  colors = A:#1AAB9B B:#FF3 C:#EEE D:#F09
voxels
-AA------------------------AA -AA-----------------------AA- --AA-------------------CCCAA- --AACCC--------------CCCC---- ----CCCCC----------CCCC------ -------CCCCAAAAAAACCCC------- ----------------------------- ----------------------------- ----------------------------- ----------------------------- ----------------------------- ----------------------------- ----------------------------- ----------------------------- ----------------------------- ----------------------------- ----------------------------- ----------------------------- ----------------------------- ----------------------------- ----------------------------- ----------------------------- ----------------------------- ----------------------------- 
-AA------------------------AA -AA-----------------------AA- --AA-------------------CCCAA- --AACCC--------------CCCC---- ----CCCCC----------CCCC------ -------CCCCAAAAAAACCCC------- ----------------------------- ----------------------------- ----------------------------- ----------------------------- ----------------------------- ----------------------------- ----------------------------- ----------------------------- ----------------------------- ----------------------------- ----------------------------- ----------------------------- ----------------------------- ----------------------------- ----------------------------- ----------------------------- ----------------------------- ----------------------------- 
-AA------------------------AA -AA-----------------------AA- --AA-------------------CCCAA- --AACCC--------------CCCC---- ----CCCCC----------CCCC------ -------CCCCAAAAAAACCCC------- ----------------------------- ----------------------------- ----------------------------- ----------------------------- ----------------------------- ----------------------------- ----------------------------- ----------------------------- ----------------------------- ----------------------------- ----------------------------- ----------------------------- ----------------------------- ----------------------------- ----------------------------- ----------------------------- ----------------------------- ----------------------------- 
-AA------------------------AA -AA-----------------------AA- --AA-------------------CCCAA- --AACCC--------------CCCC---- ----CCCCC----------CCCC------ -------CCCCAAAAAAACCCC------- ----------------------------- ----------------------------- ----------------------------- ----------------------------- ----------------------------- ----------------------------- ----------------------------- ----------------------------- ----------------------------- ----------------------------- ----------------------------- ----------------------------- ----------------------------- ----------------------------- ----------------------------- ----------------------------- ----------------------------- ----------------------------- 
-AA------------------------AA -AA-----------------------AA- --AA-------------------CCCAA- --AACCC--------------CCCC---- ----CCCCC----------CCCC------ -------CCCCAAAAAAACCCC------- ----------------------------- ----------------------------- ----------------------------- ----------------------------- ----------------------------- ----------------------------- ----------------------------- ----------------------------- ----------------------------- ----------------------------- ----------------------------- ----------------------------- ----------------------------- ----------------------------- ----------------------------- ----------------------------- ----------------------------- ----------------------------- 
-AA------------------------AA -AA-----------------------AA- --AA-------------------CCCAA- --AACCC--------------CCCC---- ----CCCCC----------CCCC------ -------CCCCAAAAAAACCCC------- ----------------------------- ----------------------------- ----------------------------- ----------------------------- ----------------------------- ----------------------------- ----------------------------- ----------------------------- ----------------------------- ----------------------------- ----------------------------- ----------------------------- ----------------------------- ----------------------------- ----------------------------- ----------------------------- ----------------------------- ----------------------------- 
-AA------------------------AA -AA-----------------------AA- --AA-------------------CCCAA- --AACCC--------------CCCC---- ----CCCCC----------CCCC------ -------CCCCAAAAAAACCCC------- ----------------------------- ----------------------------- ----------------------------- ----------------------------- ----------------------------- ----------------------------- ----------------------------- ----------------------------- ----------------------------- ----------------------------- ----------------------------- ----------------------------- ----------------------------- ----------------------------- ----------------------------- ----------------------------- ----------------------------- ----------------------------- 
-AA------------------------AA -AA-----------------------AA- --AA-------------------CCCAA- --AACCC--------------CCCC---- ----CCCCC----------CCCC------ -------CCCCAAAAAAACCCC------- ----------------------------- ----------------------------- ----------------------------- ----------------------------- ----------------------------- ----------------------------- ----------------------------- ----------------------------- ----------------------------- ----------------------------- ----------------------------- ----------------------------- ----------------------------- ----------------------------- ----------------------------- ----------------------------- ----------------------------- ----------------------------- 
-AA------------------------AA -AA-----------------------AA- --AA-------------------CCCAA- --AACCC--------------CCCC---- ----CCCCC----------CCCC------ -------CCCCAAAAAAACCCC------- ----------------------------- ----------------------------- ----------------------------- ----------------------------- ----------------------------- ----------------------------- ----------------------------- ----------------------------- ----------------------------- ----------------------------- ----------------------------- ----------------------------- ----------------------------- ----------------------------- ----------------------------- ----------------------------- ----------------------------- ----------------------------- 
-AA------------------------AA -AA-----------------------AA- --AA-------------------CCCAA- --AACCC--------------CCCC---- ----CCCCC----------CCCC------ -------CCCCAAAAAAACCCC------- ----------------------------- ----------------------------- ----------------------------- ----------------------------- ----------------------------- ----------C--C-C--C---------- ----------C--C-C--C---------- ----------C-C---C-C---------- ----------CC-----CC---------- ----------C-------C---------- ----------------------------- ----------------------------- ----------------------------- ----------------------------- ----------------------------- ----------------------------- ----------------------------- ----------------------------- 
-AA------------------------AA -AA-----------------------AA- --AA-------------------CCCAA- --AACCC--------------CCCC---- ----CCCCC----------CCCC------ -------CCCCAAAAAAACCCC------- ----------------------------- ------------AAAAA------------ -----------AAAAAAA----------- ----------AAAAAAAAA---------- ---------AAAAAAAAAAA--------- --------AAAAAAAAAAAAA-------- -------AAAAAAAAAAAAAAA------- -------AAAAAAAAAAAAAAA------- -------AAAAAAAAAAAAAAA------- -------AAAAAAAAAAAAAAA------- --------AAAAAAAAAAAAA-------- ---------AAAAAAAAAAA--------- ----------AAAAAAAAA---------- -----------AAAAAAA----------- ------------AAAAA------------ ----------------------------- ----------------------------- ----------------------------- 
-AA------------------------AA -AA-----------------------AA- --AA-------------------CCCAA- --AACCC--------------CCCC---- ----CCCCC----------CCCC------ -------CCCCAAAAAAACCCC------- ----------------------------- --------------AA------------- -----CCCCCCCCCCCCCCCCCCC----- ----CCCCCCCCCCCCCCCCCCCCC---- ---CCCCCCCCCCCCCCCCCCCCCCC--- ---CCCCCCCCCCCCCCCCCCCCCCC--- ---CCCCCCCCCCCCCCCCCCCCCCC--- ---CCCCCCCCCCCCCCCCCCCCCCC--- ---CCCCCCCCCCCCCCCCCCCCCCC--- ---CCCCCCCCCCCCCCCCCCCCCCC--- ---CCCCCCCCCCCCCCCCCCCCCCC--- ----CCCCCCCCCCCCCCCCCCCCC---- ------------AAAAA------------ ----------------------------- ----------------------------- ----------------------------- ----------------------------- ----------------------------- 
-AA------------------------AA -AA-----------------------AA- --AA-------------------CCCAA- --AACCC--------------CCCC---- ----CCCCC----------CCCC------ -------CCCCAAAAAAACCCC------- ------AAAAAAAAAAAAAAAAA------ -----AAAAAAAAAAAAAAAAAAA----- ----ABBBBBBBBBBBBBBBBBBBAA--- ---ABBBBBBBBBBBBBBBBBBBBBAA-- ---ABBBBBBBBBBBBBBBBBBBBBBA-- --ABBBBBBBBBBBBBBBBBBBBBBBA-- --ABBBBBBBBBBBBBBBBBBBBBBBA-- --ABBBBBBBBBBBBBBBBBBBBBBBA-- --ABBBBBBBBBBBBBBBBBBBBBBBA-- --ABBBBBBBBBBBBBBBBBBBBBBBA-- --ABBBBBBBBBBBBBBBBBBBBBBBA-- --ACCCCCCCCCCCCCCCCCCCCCCCA-- ---CCCCCCCCCCCCCCCCCCCCCCC--- ----------------------------- ----------------------------- ----------------------------- ----------------------------- ----------------------------- 
-AA------------------------AA -AA-----------------------AA- --AA-------------------CCCAA- --AACCC--------------CCCC---- ----CCCCC----------CCCC------ -------CCCCAAAAAAACCCC------- ------A---------AAAAAAA------ -----AAAAAAAAAAAAAAAAAAA----- ----ABBBBBBBBBBBBBBBBBBBAA--- ---ABBBBBBBBBBBBBBBBBBBBBAA-- --ABBBBBBBBBBBBBBBBBBBBBBBAA- -AABBBBBBBBBBBBBBBBBBBBBBBAA- -AABBBBBBBBBBBBBBBBBBBBBBBAA- -AAAAAAAAAAAAAAAAAAAAAAAAAAA- -AABBBBBBBBBBBBBBBBBBBBBBBAA- -AABBBBBBBBBBBBBBBBBBBBBBBAA- -AABBBBBBBBBBBBBBBBBBBBBBBAA- -AAAAAAAAAAAAAAAAAAAAAAAAAAA- --ACCCCCCCCCCCCCCCCCCCCCCCAA- ---ACCCCCCCCCCCCCCCCCCCCCAA-- ----------------------------- ----------------------------- ----------------------------- ----------------------------- 
-AA------------------------AA -AA-----------------------AA- --AA-------------------CCCAA- --AACCC--------------CCCC---- ----CCCCC----------CCCC------ -------CCCCAAAAAAACCCC------- ------AAAAAAAAAAAAAAAAA------ -----AAAAAAAAAAAAAAAAAAA----- ----ABBBBBBBBBBBBBBBBBBBAA--- ---ABBBBBBBBBBBBBBBBBBBBBAA-- --ABBBBBBBBBBBBBBBBBBBBBBBAA- -AABBBBBBBBBBBBBBBBBBBBBBBAA- -AABBBBBBBBBBBBBBBBBBBBBBBAA- -AABBBBBBBBBBBBBBBBBBBBBBBAA- -AABBBBBBBBBBBBBBBBBBBBBBBAA- -AABBBBBBBBBBBBBBBBBBBBBBBAA- -AABBBBBBBBBBBBBBBBBBBBBBBAA- -ABBBBBBBBBBBBBBBBBBBBBBBBBA- -ACCCCCCCCCCCCCCCCCCCCCCCCCA- --AAACCCCCCCCCCCCCCCCCCCAAA-- ----------------------------- ----------------------------- ----------------------------- ----------------------------- 
-AA------------------------AA -AA-----------------------AA- --AA-------------------CCCAA- --AACCC--------------CCCC---- ----CCCCC----------CCCC------ -------CCCCAAAAAAACCCC------- ------AAAAAAAAAAAAAAAAA------ -----AAAAAAAAAAAAAAAAAAA----- ----ABBBBBBBBBBBBBBBBBBBAA--- ---ABBBBBBBBBBBBBBBBBBBBBAA-- --ABBBBBBBBBBBBBBBBBBBBBBBAA- AAAAAAAAAAAAAAAAAAAAAAAAAAAAA AAAAAAAAAAAAAAAAAAAAAAAAAAAAA AAADDDDDBB-BBBBBBDDBBBDDDDAAA AAADDDDDBBBBBBBB-DDBBBDDDDAAA AAADDDDDBBBBBBBBBDDBBBDDDDAAA AAADDDDDBBBBBBBBBDDBBBDDDDAAA AAAAAAAAAAAAAAAA-AAAAAAAAAAAA AAAAAAAAAAAAAAAAAAAAAAAAAAAAA --AAAAAAAAAAAAAAAAAAAAAAAAAA- ---AAAAAAAAAAAAAAAAAAAAAAA--- ----------------------------- ----------------------------- ----------------------------- 
-AA------------------------AA -AAA----------------------AA- --AA-------------------CCCAA- --AACCC--------------CCCC---- ----CCCCC----------CCCC------ -------CCCCAAAAAAACCCC------- ------AAAAAAAAAAAAAAAAA------ -----AAAAAAAAAAAAAAAAAAA----- ----ABBBBBBBBBBBBBBBBBBBAA--- ---ABBBBBBBBBBBBBBBBBBBBBAA-- --ABBBBBBBBBBBBBBBBBBBBBBBAA- AAAAAAAAAAAAAAAAAAAAAAAAAAAAA AAAAAAAAAAAAAAAAAAAAAAAAAAAAA AAADDDDDDDBDDDDDDDDDDDDDDDAAA AAADDDDDDDDDDDDDBBDDDDDDDDAAA AAABBBBBBBBBBBBBBBBBBBBBBBAAA AAABBBBBBBBBBBBBBBBBBBBBBBAAA AABBBBBBBBBBBBBB-BBBBBBBBBBAA AAAAAAAAAAAAAAAAAAAAAAAAAAAAA -AAAAAAAAAAAAAAAAAAAAAAAAAAA- --AAAAAAAAAAAAAAAAAAAAAAAAAA- ----------------------------- ----------------------------- ----------------------------- 
-AA------------------------AA -AAA----------------------AA- --AA-------------------CCCAA- --AACCC--------------CCCC---- ----CCCCC----------CCCC------ -------CCCCAAAAAAACCCC------- ------AAAAAAAAAAAAAAAAA------ -----AAAAAAAAAAAAAAAAAAA----- ----ABBBBBBBBBBBBBBBBBBBAA--- ---ABBBBBBBBBBBBBBBBBBBBBAA-- --ABBBBBBBBBBBBBBBBBBBBBBBAA- AAAAAAAAAAAAAAAAAAAAAAAAAAAAA AAAAAAAAAAAAAAAAAAAAAAAAAAAAA AAABBBBBBBBBBBBBBBBBBBBBBBAAA AAABBBBBBBBBBBBBBBBBBBBBBBAAA AAABBBBBBBBBBBBBBBBBBBBBBBAAA AAABBBBBBBBBBBBBBBBBBBBBBBAAA AADDDDDDDDDDDDDDBDDDDDDDDDDAA AAAAAAAAAAAAAAAAAAAAAAAAAAAAA -AAAAAAAAAAAAAAAAAAAAAAAAAAA- --AAAAAAAAAAAAAAAAAAAAAAAAAA- ---AAAAAAAAAAAAAAAAAAAAAAAA-- ----------------------------- ----------------------------- 
-AA------------------------AA -AAA----------------------AA- --AA-------------------CCCAA- --AACCC--------------CCCC---- ----CCCCC----------CCCC------ -------CCCCAAAAAAACCCC------- ------AAAAAAAAAAAAAAAAA------ -----AAAAAAAAAAAAAAAAAAA----- ----ABBBBBBBBBBBBBBBBBBBAA--- ---ABBBBBBBBBBBBBBBBBBBBBAA-- --ABBBBBBBBBBBBBBBBBBBBBBBAA- AAAAAAAAAAAAAAAAAAAAAAAAAAAAA AAAAAAAAAAAAAAAAAAAAAAAAAAAAA AAABBBBBBBBBBBBBBBBBBBBBBBAAA AAABBBBBBBBBBBBBBBBBBBBBBBAAA AAABBBBBBBBBBBBBBBBBBBBBBBAAA AAABBBBBBBBBBBBBBBBBBBBBBBAAA AABBBBBBBBBBBBBBBBBBBBBBBBBAA AAAAAAAAAAAAAAAAAAAAAAAAAAAAA -AAAAAAAAAAAAAAAAAAAAAAAAAAA- --AAAAAAAAAAAAAAAAAAAAAAAAAA- ---AAAAAAAAAAAAAAAAAAAAAAAA-- ----CCCCCCCCCCCCCCCCCCCCCC--- ----------------------------- 
-AA------------------------AA -AAA----------------------AA- --AA-------------------CCCAA- --AACCC--------------CCCC---- ----CCCCC----------CCCC------ -------CCCCAAAAAAACCCC------- ------AAAAAAAAAAAAAAAAA------ -----AAAAAAAAAAAAAAAAAAA----- ----ABBBBBBBBBBBBBBBBBBBAA--- ---ABBBBBBBBBBBBBBBBBBBBBAA-- --ABBBBBBBBBBBBBBBBBBBBBBBAA- AAAAAAAAAAAAAAAAAAAAAAAAAAAAA AAAAAAAAAAAAAAAAAAAAAAAAAAAAA AAABBBBBBBBBBBBBBBBBBBBBBBAAA AAABBBBBBBBBBBBBBBBBBBBBBBAAA AAABBBBBBBBBBBBBBBBBBBBBBBAAA AAABBBBBBBBBBBBBBBBBBBBBBBAAA AABBBBBBBBBBBBBBBBBBBBBBBBBAA AAAAAAAAAAAAAAAAAAAAAAAAAAAAA -AAAAAAAAAAAAAAAAAAAAAAAAAAA- --AAAAAAAAAAAAAAAAAAAAAAAAAA- ---AAAAAAAAAAAAAAAAAAAAAAAA-- ----CCCCCCCCCCCCCCCCCCCCCC--- -------------AA-------------- 
-AA------------------------AA -AAA----------------------AA- --AA-------------------CCCAA- --AACCC--------------CCCC---- ----CCCCC----------CCCC------ -------CCCCAAAAAAACCCC------- ------AAAAAAAAAAAAAAAAA------ -----AAAAAAAAAAAAAAAAAAA----- ----ABBBBBBBBBBBBBBBBBBBAA--- ---ABBBBBBBBBBBBBBBBBBBBBAA-- --ABBBBBBBBBBBBBBBBBBBBBBBAA- AAAAAAAAAAAAAAAAAAAAAAAAAAAAA AAAAAAAAAAAAAAAAAAAAAAAAAAAAA AAABBBBBBBBBBBBBBBBBBBBBBBAAA AAABBBBBBBBBBBBBBBBBBBBBBBAAA AAABBBBBBBBBBBBBBBBBBBBBBBAAA AAABBBBBBBBBBBBBBBBBBBBBBBAAA AABBBBBBBBBBBBBBBBBBBBBBBBBAA AAAAAAAAAAAAAAAAAAAAAAAAAAAAA -AAAAAAAAAAAAAAAAAAAAAAAAAAA- --AAAAAAAAAAAAAAAAAAAAAAAAAA- ---AAAAAAAAAAAAAAAAAAAAAAAA-- ----CCCCCCCCCCCCCCCCCCCCCC--- -------------AA-------------- 
-AA------------------------AA -AAA----------------------AA- --AA-------------------CCCAA- --AACCC--------------CCCC---- ----CCCCC----------CCCC------ -------CCCCAAAAAAACCCC------- ------AAAAAAAAAAAAAAAAA------ -----AAAAAAAAAAAAAAAAAAA----- ----ABBBBBBBBBBBBBBBBBBBAA--- ---ABBBBBBBBBBBBBBBBBBBBBAA-- --ABBBBBBBBBBBBBBBBBBBBBBBAA- AAAAAAAAAAAAAAAAAAAAAAAAAAAAA AAAAAAAAAAAAAAAAAAAAAAAAAAAAA AAABBBBBBBBBBBBBBBBBBBBBBBAAA AAABBBBBBBBBBBBBBBBBBBBBBBAAA AAABBBBBBBBBBBBBBBBBBBBBBBAAA AAABBBBBBBBBBBBBBBBBBBBBBBAAA AABBBBBBBBBBBBBBBBBBBBBBBBBAA AAAAAAAAAAAAAAAAAAAAAAAAAAAAA -AAAAAAAAAAAAAAAAAAAAAAAAAAA- --AAAAAAAAAAAAAAAAAAAAAAAAAA- ---AAAAAAAAAAAAAAAAAAAAAAAA-- ----CCCCCCCCCCCCCCCCCCCCCC--- ----------------------------- 
-AA------------------------AA -AAA----------------------AA- --AA-------------------CCCAA- --AACCC--------------CCCC---- ----CCCCC----------CCCC------ -------CCCCAAAAAAACCCC------- ------AAAAAAAAAAAAAAAAA------ -----AAAAAAAAAAAAAAAAAAA----- ----ABBBBBBBBBBBBBBBBBBBAA--- ---ABBBBBBBBBBBBBBBBBBBBBAA-- --ABBBBBBBBBBBBBBBBBBBBBBBAA- AAAAAAAAAAAAAAAAAAAAAAAAAAAAA AAAAAAAAAAAAAAAAAAAAAAAAAAAAA AAABBBBBBBBBBBBBBBBBBBBBBBAAA AAABBBBBBBBBBBBBBBBBBBBBBBAAA AAABBBBBBBBBBBBBBBBBBBBBBBAAA AAABBBBBBBBBBBBBBBBBBBBBBBAAA AABBBBBBBBBBBBBBBBBBBBBBBBBAA AAAAAAAAAAAAAAAAAAAAAAAAAAAAA -AAAAAAAAAAAAAAAAAAAAAAAAAAA- --AAAAAAAAAAAAAAAAAAAAAAAAAA- ---AAAAAAAAAAAAAAAAAAAAAAAA-- ----CCCCCCCCCCCCCCCCCCCCCC--- ----------------------------- 
-AA------------------------AA -AAA----------------------AA- --AA-------------------CCCAA- --AACCC--------------CCCC---- ----CCCCC----------CCCC------ -------CCCCAAAAAAACCCC------- ------AAAAAAAAAAAAAAAAA------ -----AAAAAAAAAAAAAAAAAAA----- ----ABBBBBBBBBBBBBBBBBBBAA--- ---ABBBBBBBBBBBBBBBBBBBBBAA-- --ABBBBBBBBBBBBBBBBBBBBBBBAA- AAAAAAAAAAAAAAAAAAAAAAAAAAAAA AAAAAAAAAAAAAAAAAAAAAAAAAAAAA AAABBBBBBBBBBBBBBBBBBBBBBBAAA AAABBBBBBBBBBBBBBBBBBBBBBBAAA AAABBBBBBBBBBBBBBBBBBBBBBBAAA AAABBBBBBBBBBBBBBBBBBBBBBBAAA AABBBBBBBBBBBBBBBBBBBBBBBBBAA AAAAAAAAAAAAAAAAAAAAAAAAAAAAA -AAAAAAAAAAAAAAAAAAAAAAAAAAA- --AAAAAAAAAAAAAAAAAAAAAAAAAA- ---AAAAAAAAAAAAAAAAAAAAAAAA-- ----------------------------- ----------------------------- 
-AA------------------------AA -AAA----------------------AA- --AA-------------------CCCAA- --AACCC--------------CCCC---- ----CCCCC----------CCCC------ -------CCCCAAAAAAACCCC------- ------AAAAAAAAAAAAAAAAA------ -----AAAAAAAAAAAAAAAAAAA----- ----ABBBBBBBBBBBBBBBBBBBAA--- ---ABBBBBBBBBBBBBBBBBBBBBAA-- --ABBBBBBBBBBBBBBBBBBBBBBBAA- AAAAAAAAAAAAAAAAAAAAAAAAAAAAA AAAAAAAAAAAAAAAAAAAAAAAAAAAAA AAABBBBBBBBBBBBBBBBBBBBBBBAAA AAABBBBBBBBBBBBBBBBBBBBBBBAAA AAABBBBBBBBBBBBBBBBBBBBBBBAAA AAABBBBBBBBBBBBBBBBBBBBBBBAAA AABBBBBBBBBBBBBBBBBBBBBBBBBAA AAAAAAAAAAAAAAAAAAAAAAAAAAAAA -AAAAAAAAAAAAAAAAAAAAAAAAAAA- --AAAAAAAAAAAAAAAAAAAAAAAAAA- ----------------------------- ----------------------------- ----------------------------- 
-AA------------------------AA -AAA----------------------AA- --AA-------------------CCCAA- --AACCC--------------CCCC---- ----CCCCC----------CCCC------ -------CCCCAAAAAAACCCC------- ------AAAAAAAAAAAAAAAAA------ -----AAAAAAAAAAAAAAAAAAA----- ----ABBBBBBBBBBBBBBBBBBBAA--- ---ABBBBBBBBBBBBBBBBBBBBBAA-- --ABBBBBBBBBBBBBBBBBBBBBBBAA- AAAAAAAAAAAAAAAAAAAAAAAAAAAAA AAAAAAAAAAAAAAAAAAAAAAAAAAAAA AAABBBBBBBBBBBBBBBBBBBBBBBAAA AAABBBBBBBBBBBBBBBBBBBBBBBAAA AAABBBBBBBBBBBBBBBBBBBBBBBAAA AAABBBBBBBBBBBBBBBBBBBBBBBAAA AABBBBBBBBBBBBBBBBBBBBBBBBBAA AAAAAAAAAAAAAAAAAAAAAAAAAAAAA -AAAAAAAAAAAAAAAAAAAAAAAAAAA- --AAAAAAAAAAAAAAAAAAAAAAAAAA- ----------------------------- ----------------------------- ----------------------------- 
-AA------------------------AA -AAA----------------------AA- --AA-------------------CCCAA- --AACCC--------------CCCC---- ----CCCCC----------CCCC------ -------CCCCAAAAAAACCCC------- ------AAAAAAAAAAAAAAAAA------ -----AAAAAAAAAAAAAAAAAAA----- ----ABBBBBBBBBBBBBBBBBBBAA--- ---ABBBBBBBBBBBBBBBBBBBBBAA-- --ABBBBBBBBBBBBBBBBBBBBBBBAA- AAAAAAAAAAAAAAAAAAAAAAAAAAAAA AAAAAAAAAAAAAAAAAAAAAAAAAAAAA AAABBBBBBBBBBBBBBBBBBBBBBBAAA AAABBBBBBBBBBBBBBBBBBBBBBBAAA AAABBBBBBBBBBBBBBBBBBBBBBBAAA AAABBBBBBBBBBBBBBBBBBBBBBBAAA AABBBBBBBBBBBBBBBBBBBBBBBBBAA AAAAAAAAAAAAAAAAAAAAAAAAAAAAA -AAAAAAAAAAAAAAAAAAAAAAAAAAA- ----------------------------- ----------------------------- ----------------------------- ----------------------------- 
-AA------------------------AA -AAA----------------------AA- --AA-------------------CCCAA- --AACCC--------------CCCC---- ----CCCCC----------CCCC------ -------CCCCAAAAAAACCCC------- -------AAAAAAAAAAAAAAAA------ -----A-AAAAAAAAAAAAAAAAA----- ----AB-BBBBBBBBBBBBBBBBBAA--- ---ABB-BBBBBBBBBBBBBBBBBBAA-- --ABBB-BBBBBBBBBBBBBBBBBBBAA- AAAAAA-AAAAAAAAAAAAAAAAAAAAAA AAAAAA-AAAAAAAAAAAAAAAAAAAAAA AAABBB-BBBBBBBBBBBBBBBBBBBAAA AAABBB-BBBBBBBBBBBBBBBBBBBAAA AAABBB-BBBBBBBBBBBBBBBBBBBAAA AAABBB-BBBBBBBBBBBBBBBBBBBAAA AABBBB-BBBBBBBBBBBBBBBBBBBBAA -AAAAAAAAAAAAAAAAAAAAAAAAAAA- ----------------------------- ----------------------------- ----------------------------- ----------------------------- ----------------------------- 
----------------------------- -AAA----------------------AA- --AA-------------------CCCAA- --AACCC--------------CCCC---- ----CCCCC----------CCCC------ -------CCCCAAAAAAACCCC------- ----------------------------- -----AAAAAAAAAAAAAAAAAAA----- ----ABBBBBBBBBBBBBBBBBBBAA--- ---ABBBBBBBBBBBBBBBBBBBBBAA-- --ABBBBBBBBBBBBBBBBBBBBBBBAA- AAAAAAAAAAAAAAAAAAAAAAAAAAAAA AAAAAAAAAAAAAAAAAAAAAAAAAAAAA AAABBBBBBBBBBBBBBBBBBBBBBBAAA AAABBBBBBBBBBBBBBBBBBBBBBBAAA AAABBBBBBBBBBBBBBBBBBBBBBBAAA AAABBBBBBBBBBBBBBBBBBBBBBBAAA AAAAAAAAAAAAAAAAAAAAAAAAAAAAA ----------------------------- ----------------------------- ----------------------------- ----------------------------- ----------------------------- ----------------------------- 
----------------------------- --AA------------------------- --AA-------------------CCCAA- --AACCC--------------CCCC---- ----CCCCC----------CCCC------ -------CCCCAAAAAAACCCC------- ----------------------------- ----------------------------- ----AAAAAAAAAAAAAAAAAAAAAA--- ---ABBBBBBBBBBBBBBBBBBBBBAA-- --AAAAAAAAAAAAAAAAAAAAAAAAAA- ----------------------------- -AAAAAAAAAAAAAAAAAAAAAAAAAAAA AAAAAAAAAAAAAAAAAAAAAAAAAAAAA AAAAAAAAAAAAAAAAAAAAAAAAAAAAA AAAAAAAAAAAAAAAAAAAAAAAAAAAAA AAAAAAAAAAAAAAAAAAAAAAAAAAAAA ----------------------------- ----------------------------- ----------------------------- ----------------------------- ----------------------------- ----------------------------- ----------------------------- 
----------------------------- ----------------------------- ----------------------------- --AACCC--------------CCCC---- ----------------------------- ----------------------------- ----------------------------- ----------------------------- ----------------------------- ---AAAAAAAAAAAAAAAAAAAAAAAA-- ----------------------------- ----------------------------- ----------------------------- ----------------------------- ----------------------------- ----------------------------- ----------------------------- ----------------------------- ----------------------------- ----------------------------- ----------------------------- ----------------------------- ----------------------------- ----------------------------- 
