model
size = 29 24 31, scale = 0.05, origin = -y
material 
  colors = A:#3CF B:#FF3 C:#CFB53B D:#111 E:#F09
voxels
-C-------------------------CC -CC-----------------------CC- --CC-------------------CCCCC- --CCCC---------------CCCC---- ----CCC-------------CCC------ ------CCCCCCCCCCCCCCCC------- ----------------------------- ----------------------------- ----------------------------- ----------------------------- ----------------------------- ----------------------------- ----------------------------- ----------------------------- ----------------------------- ----------------------------- ----------------------------- ----------------------------- ----------------------------- ----------------------------- ----------------------------- ----------------------------- ----------------------------- ----------------------------- 
-CC-----------------------CCC -ACC---------------------CCA- --ACC----------------CCCCDAA- --AACCCC-----------CCDADD---- ----DDACCCCCCCCCCCCCDDA------ -------DDDDAAAAAAADDDD------- ----------------------------- ----------------------------- ----------------------------- ----------------------------- ----------------------------- ----------------------------- ----------------------------- ----------------------------- ----------------------------- ----------------------------- ----------------------------- ----------------------------- ----------------------------- ----------------------------- ----------------------------- ----------------------------- ----------------------------- ----------------------------- 
-CC-----------------------CCC -ACC---------------------CCA- --ACC----------------CCCCDAA- --AACCCC-----------CCDADD---- ----DDACCCCCCCCCCCCDDDA------ -------DDDDAAAAAAADDDD------- ----------------------------- ----------------------------- ----------------------------- ----------------------------- ----------------------------- ----------------------------- ----------------------------- ----------------------------- ----------------------------- ----------------------------- ----------------------------- ----------------------------- ----------------------------- ----------------------------- ----------------------------- ----------------------------- ----------------------------- ----------------------------- 
-CC-----------------------CCC -ACC---------------------CCA- --ACC----------------CCCCDAA- --AACCCC-----------CCDADD---- ----DDACCCCCCCCCCCCDDDA------ -------DDDDAAAAAAADDDD------- ----------------------------- ----------------------------- ----------------------------- ----------------------------- ----------------------------- ----------------------------- ----------------------------- ----------------------------- ----------------------------- ----------------------------- ----------------------------- ----------------------------- ----------------------------- ----------------------------- ----------------------------- ----------------------------- ----------------------------- ----------------------------- 
-CC-----------------------CCC -ACC---------------------CCA- --ACC----------------CCCCDAA- --AACCCC-----------CCDADD---- ----DDACCCCCCCCCCCCDDDA------ -------DDDDAAAAAAADDDD------- ----------------------------- ----------------------------- ----------------------------- ----------------------------- ----------------------------- ----------------------------- ----------------------------- ----------------------------- ----------------------------- ----------------------------- ----------------------------- ----------------------------- ----------------------------- ----------------------------- ----------------------------- ----------------------------- ----------------------------- ----------------------------- 
-CC-----------------------CCC -ACC---------------------CCA- --ACC----------------CCCCDAA- --AACCCC-----------CCDADD---- ----DDACCCCCCCCCCCCDDDA------ -------DDDDAAAAAAADDDD------- ----------------------------- ----------------------------- ----------------------------- ----------------------------- ----------------------------- ----------------------------- ----------------------------- ----------------------------- ----------------------------- ----------------------------- ----------------------------- ----------------------------- ----------------------------- ----------------------------- ----------------------------- ----------------------------- ----------------------------- ----------------------------- 
-CC-----------------------CCC -ACC---------------------CCA- --ACC----------------CCCCDAA- --AACCCC-----------CCDADD---- ----DDACCCCCCCCCCCCDDDA------ -------DDDDAAAAAAADDDD------- ----------------------------- ----------------------------- ----------------------------- ----------------------------- ----------------------------- ----------------------------- ----------------------------- ----------------------------- ----------------------------- ----------------------------- ----------------------------- ----------------------------- ----------------------------- ----------------------------- ----------------------------- ----------------------------- ----------------------------- ----------------------------- 
-CC-----------------------CCC -ACC---------------------CCA- --ACC----------------CCCCDAA- --AACCCC-----------CCDADD---- ----DDACCCCCCCCCCCCDDDA------ -------DDDDAAAAAAADDDD------- ----------------------------- ----------------------------- ----------------------------- ----------------------------- ----------------------------- ----------------------------- ----------------------------- ----------------------------- ----------------------------- ----------------------------- ----------------------------- ----------------------------- ----------------------------- ----------------------------- ----------------------------- ----------------------------- ----------------------------- ----------------------------- 
-CC-----------------------CCC -ACC---------------------CCA- --ACC----------------CCCCDAA- --AACCCC-----------CCDADD---- ----DDACCCCCCCCCCCCDDDA------ -------DDDDAAAAAAADDDD------- ----------------------------- ----------------------------- ----------------------------- ----------------------------- ----------------------------- ----------------------------- ----------------------------- ----------------------------- ----------------------------- ----------------------------- ----------------------------- ----------------------------- ----------------------------- ----------------------------- ----------------------------- ----------------------------- ----------------------------- ----------------------------- 
-CC-----------------------CCC -ACC---------------------CCA- --ACC----------------CCCCDAA- --AACCCC-----------CCDADD---- ----DDACCCCCCCCCCCCDDDA------ -------DDDDAAAAAAADDDD------- ----------------------------- ----------------------------- ----------------------------- ----------------------------- ----------------------------- ----------------------------- ----------------------------- ----------------------------- ----------------------------- ----------------------------- ----------------------------- ----------------------------- ----------------------------- ----------------------------- ----------------------------- ----------------------------- ----------------------------- ----------------------------- 
-CC-----------------------CCC -ACC---------------------CCA- --ACC----------------CCCCDAA- --AACCCC-----------CCDADD---- ----DDACCCCCCCCCCCCDDDA------ -------DDDDAAAAAAADDDD------- ----------------------------- ----------------------------- ----------------------------- ----------------------------- ----------------------------- ----------------------------- --------------C-------------- ---------D---C-C-----D------- ---------D--C---C------------ ---------D-C--C--C----------- ---------DC--CCC--C---------- ---------CC-CCCCC-CC--------- ----------------------------- ----------------------------- ----------------------------- ----------------------------- ----------------------------- ----------------------------- 
-CC-----------------------CCC -ACC---------------------CCA- --ACC----------------CCCCDAA- --AACCCC-----------CCDADD---- ----DDACCCCCCCCCCCCDDDA------ -------DDDDAAAAAAADDDD------- ----------------------------- ----------------------------- -----DDDDDDDDDDDDDDDDDDD----- ----DDDDDDDDDDDDDDDDDDDDD---- ---DDDDDDDDDDDDDDDDDDDDDDD--- ---DDDDDDDDDDDDDDDDDDDDDDD--- ---DDDDDDDDDDDDDDDDDDDDDDD--- ---DDDDDDDDDDDDDDDDDDDDDDD--- ---DDDDDDDDDDDDDDDDDDDDDDD--- ---DDDDDDDDDDDDDDDDDDDDDDD--- ---DDDDDDDDDDDDDDDDDDDDDDD--- ----DDDDDDDDDDDDDDDDDDDDD---- ----------------------------- ----------------------------- ----------------------------- ----------------------------- ----------------------------- ----------------------------- 
-CC-----------------------CCC -ACC---------------------CCA- --ACC----------------CCCCDAA- --AACCCC-----------CCDADD---- ----DDACCCCCCCCCCCCDDDA------ -------DDDDAAAAAAADDDD------- ------AAAAAAAAAAAAAAAAA------ -----AAAAAAAAAAAAAAAAAAA----- ----ABBBBBBBBBBBBBBBBBBBAA--- ---ABBBBBBBBBBBBBBBBBBBBBAA-- ---ABBBBBBBBBBBBBBBBBBBBBBA-- --ABBBBBBBBBBBBBBBBBBBBBBBA-- --ABBBBBBBBBBBBBBBBBBBBBBBA-- --ABBBBBBBBBBBBBBBBBBBBBBBA-- --ABBBBBBBBBBBBBBBBBBBBBBBA-- --ABBBBBBBBBBBBBBBBBBBBBBBA-- --ABBBBBBBBBBBBBBBBBBBBBBBA-- --ADDDDDDDDDDDDDDDDDDDDDDDA-- ---DDDDDDDDDDDDDDDDDDDDDDD--- ----------------------------- ----------------------------- ----------------------------- ----------------------------- ----------------------------- 
-CC-----------------------CCC -ACC---------------------CCA- --ACC----------------CCCCDAA- --AACCCC-----------CCDADD---- ----DDACCCCCCCCCCCCDDDA------ -------DDDDAAAAAAADDDD------- ------A---------AAAAAAA------ -----AAAAAAAAAAAAAAAAAAA----- ----ABBBBBBBBBBBBBBBBBBBAA--- ---ABBBBBBBBBBBBBBBBBBBBBAA-- --ABBBBBBBBBBBBBBBBBBBBBBBAA- -AABBBBBBBBBBBBBBBBBBBBBBBAA- -AABBBBBBBBBBBBBBBBBBBBBBBAA- -AAAAAAAAAAAAAAAAAAAAAAAAAAA- -AABBBBBBBBBBBBBBBBBBBBBBBAA- -AABBBBBBBBBBBBBBBBBBBBBBBAA- -AABBBBBBBBBBBBBBBBBBBBBBBAA- -AAAAAAAAAAAAAAAAAAAAAAAAAAA- --ADDDDDDDDDDDDDDDDDDDDDDDAA- ---ADDDDDDDDDDDDDDDDDDDDDAA-- ----------------------------- ----------------------------- ----------------------------- ----------------------------- 
-CC-----------------------CCC -ACC---------------------CCA- --ACC----------------CCCCDAA- --AACCCC-----------CCDADD---- ----DDACCCCCCCCCCCCDDDA------ -------DDDDAAAAAAADDDD------- ------AAAAAAAAAAAAAAAAA------ -----AAAAAAAAAAAAAAAAAAA----- ----ABBBBBBBBBBBBBBBBBBBAA--- ---ABBBBBBBBBBBBBBBBBBBBBAA-- --ABBBBBBBBBBBBBBBBBBBBBBBAA- -AABBBBBBBBBBBBBBBBBBBBBBBAA- -AABBBBBBBBBBBBBBBBBBBBBBBAA- -AABBBBBBBBBBBBBBBBBBBBBBBAA- -AABBBBBBBBBBBBBBBBBBBBBBBAA- -AABBBBBBBBBBBBBBBBBBBBBBBAA- -AABBBBBBBBBBBBBBBBBBBBBBBAA- -ABBBBBBBBBBBBBBBBBBBBBBBBBA- -ADDDDDDDDDDDDDDDDDDDDDDDDDA- --AAADDDDDDDDDDDDDDDDDDDAAA-- ----------------------------- ----------------------------- ----------------------------- ----------------------------- 
-CC-----------------------CCC -ACC---------------------CCA- --ACC----------------CCCCDAA- --AACCCC-----------CCDADD---- ----DDACCCCCCCCCCCCDDDA------ -------DDDDAAAAAAADDDD------- ------AAAAAAAAAAAAAAAAA------ -----AAAAAAAAAAAAAAAAAAA----- ----ABBBBBBBBBBBBBBBBBBBAA--- ---ABBBBBBBBBBBBBBBBBBBBBAA-- --ABBBBBBBBBBBBBBBBBBBBBBBAA- AAAAAAAAAAAAAAAAAAAAAAAAAAAAA AAAAAAAAAAAAAAAAAAAAAAAAAAAAA AAAEEEEEBB-BBBBBBEEBBBEEEEAAA AAAEEEEEBBBBBBBB-EEBBBEEEEAAA AAAEEEEEBBBBBBBBBEEBBBEEEEAAA AAAEEEEEBBBBBBBBBEEBBBEEEEAAA AAAAAAAAAAAAAAAA-AAAAAAAAAAAA AAAAAAAAAAAAAAAAAAAAAAAAAAAAA --AAAAAAAAAAAAAAAAAAAAAAAAAA- ---AAAAAAAAAAAAAAAAAAAAAAA--- ----------------------------- ----------------------------- ----------------------------- 
-CC-----------------------CCC -ACC---------------------CCA- --ACC----------------CCCCDAA- --AACCCC-----------CCDADD---- ----DDACCCCCCCCCCCCDDDA------ -------DDDDAAAAAAADDDD------- ------AAAAAAAAAAAAAAAAA------ -----AAAAAAAAAAAAAAAAAAA----- ----ABBBBBBBBBBBBBBBBBBBAA--- ---ABBBBBBBBBBBBBBBBBBBBBAA-- --ABBBBBBBBBBBBBBBBBBBBBBBAA- AAAAAAAAAAAAAAAAAAAAAAAAAAAAA AAAAAAAAAAAAAAAAAAAAAAAAAAAAA AAAEEEEEEEBEEEEEEEEEEEEEEEAAA AAAEEEEEEEEEEEEEBBEEEEEEEEAAA AAABBBBBBBBBBBBBBBBBBBBBBBAAA AAABBBBBBBBBBBBBBBBBBBBBBBAAA AABBBBBBBBBBBBBB-BBBBBBBBBBAA AAAAAAAAAAAAAAAAAAAAAAAAAAAAA -AAAAAAAAAAAAAAAAAAAAAAAAAAA- --AAAAAAAAAAAAAAAAAAAAAAAAAA- ----------------------------- ----------------------------- ----------------------------- 
-CC-----------------------CCC -ACC---------------------CCA- --ACC----------------CCCCDAA- --AACCCC-----------CCDADD---- ----DDACCCCCCCCCCCCDDDA------ -------DDDDAAAAAAADDDD------- ------AAAAAAAAAAAAAAAAA------ -----AAAAAAAAAAAAAAAAAAA----- ----ABBBBBBBBBBBBBBBBBBBAA--- ---ABBBBBBBBBBBBBBBBBBBBBAA-- --ABBBBBBBBBBBBBBBBBBBBBBBAA- AAAAAAAAAAAAAAAAAAAAAAAAAAAAA AAAAAAAAAAAAAAAAAAAAAAAAAAAAA AAABBBBBBBBBBBBBBBBBBBBBBBAAA AAABBBBBBBBBBBBBBBBBBBBBBBAAA AAABBBBBBBBBBBBBBBBBBBBBBBAAA AAABBBBBBBBBBBBBBBBBBBBBBBAAA AAEEEEEEEEEEEEEEBEEEEEEEEEEAA AAAAAAAAAAAAAAAAAAAAAAAAAAAAA -AAAAAAAAAAAAAAAAAAAAAAAAAAA- --AAAAAAAAAAAAAAAAAAAAAAAAAA- ---CCCCCCCCCCCCCCCCCCCCCCCC-- ----------------------------- ----------------------------- 
-CC-----------------------CCC -ACC---------------------CCA- --ACC----------------CCCCDAA- --AACCCC-----------CCDADD---- ----DDACCCCCCCCCCCCDDDA------ -------DDDDAAAAAAADDDD------- ------AAAAAAAAAAAAAAAAA------ -----AAAAAAAAAAAAAAAAAAA----- ----ABBBBBBBBBBBBBBBBBBBAA--- ---ABBBBBBBBBBBBBBBBBBBBBAA-- --ABBBBBBBBBBBBBBBBBBBBBBBAA- AAAAAAAAAAAAAAAAAAAAAAAAAAAAA AAAAAAAAAAAAAAAAAAAAAAAAAAAAA AAABBBBBBBBBBBBBBBBBBBBBBBAAA AAABBBBBBBBBBBBBBBBBBBBBBBAAA AAABBBBBBBBBBBBBBBBBBBBBBBAAA AAABBBBBBBBBBBBBBBBBBBBBBBAAA AABBBBBBBBBBBBBBBBBBBBBBBBBAA AAAAAAAAAAAAAAAAAAAAAAAAAAAAA -AAAAAAAAAAAAAAAAAAAAAAAAAAA- --AAAAAAAAAAAAAAAAAAAAAAAAAA- ---CAAAAAAAAAAAAAAAAAAAAAAC-- ----DDDDDDDDDDDDDDDDDDDDDD--- ----------------------------- 
-CC-----------------------CCC -ACC---------------------CCA- --ACC----------------CCCCDAA- --AACCCC-----------CCDADD---- ----DDACCCCCCCCCCCCDDDA------ -------DDDDAAAAAAADDDD------- ------AAAAAAAAAAAAAAAAA------ -----AAAAAAAAAAAAAAAAAAA----- ----ABBBBBBBBBBBBBBBBBBBAA--- ---ABBBBBBBBBBBBBBBBBBBBBAA-- --ABBBBBBBBBBBBBBBBBBBBBBBAA- AAAAAAAAAAAAAAAAAAAAAAAAAAAAA AAAAAAAAAAAAAAAAAAAAAAAAAAAAA AAABBBBBBBBBBBBBBBBBBBBBBBAAA AAABBBBBBBBBBBBBBBBBBBBBBBAAA AAABBBBBBBBBBBBBBBBBBBBBBBAAA AAABBBBBBBBBBBBBBBBBBBBBBBAAA AABBBBBBBBBBBBBBBBBBBBBBBBBAA AAAAAAAAAAAAAAAAAAAAAAAAAAAAA -AAAAAAAAAAAAAAAAAAAAAAAAAAA- --AAAAAAAAAAAAAAAAAAAAAAAAAA- ---CAAAAAAAAAAAAAAAAAAAAAAC-- ----DDDDDDDDDDDDDDDDDDDDDD--- -------------CC-------------- 
-CC-----------------------CCC -ACC---------------------CCA- --ACC----------------CCCCDAA- --AACCCC-----------CCDADD---- ----DDACCCCCCCCCCCCDDDA------ -------DDDDAAAAAAADDDD------- ------AAAAAAAAAAAAAAAAA------ -----AAAAAAAAAAAAAAAAAAA----- ----ABBBBBBBBBBBBBBBBBBBAA--- ---ABBBBBBBBBBBBBBBBBBBBBAA-- --ABBBBBBBBBBBBBBBBBBBBBBBAA- AAAAAAAAAAAAAAAAAAAAAAAAAAAAA AAAAAAAAAAAAAAAAAAAAAAAAAAAAA AAABBBBBBBBBBBBBBBBBBBBBBBAAA AAABBBBBBBBBBBBBBBBBBBBBBBAAA AAABBBBBBBBBBBBBBBBBBBBBBBAAA AAABBBBBBBBBBBBBBBBBBBBBBBAAA AABBBBBBBBBBBBBBBBBBBBBBBBBAA AAAAAAAAAAAAAAAAAAAAAAAAAAAAA -AAAAAAAAAAAAAAAAAAAAAAAAAAA- --AAAAAAAAAAAAAAAAAAAAAAAAAA- ---CAAAAAAAAAAAAAAAAAAAAAAC-- ----DDDDDDDDDDDDDDDDDDDDDD--- -------------CC-------------- 
-CC-----------------------CCC -ACC---------------------CCA- --ACC----------------CCCCDAA- --AACCCC-----------CCDADD---- ----DDACCCCCCCCCCCCDDDA------ -------DDDDAAAAAAADDDD------- ------AAAAAAAAAAAAAAAAA------ -----AAAAAAAAAAAAAAAAAAA----- ----ABBBBBBBBBBBBBBBBBBBAA--- ---ABBBBBBBBBBBBBBBBBBBBBAA-- --ABBBBBBBBBBBBBBBBBBBBBBBAA- AAAAAAAAAAAAAAAAAAAAAAAAAAAAA AAAAAAAAAAAAAAAAAAAAAAAAAAAAA AAABBBBBBBBBBBBBBBBBBBBBBBAAA AAABBBBBBBBBBBBBBBBBBBBBBBAAA AAABBBBBBBBBBBBBBBBBBBBBBBAAA AAABBBBBBBBBBBBBBBBBBBBBBBAAA AABBBBBBBBBBBBBBBBBBBBBBBBBAA AAAAAAAAAAAAAAAAAAAAAAAAAAAAA -AAAAAAAAAAAAAAAAAAAAAAAAAAA- --AAAAAAAAAAAAAAAAAAAAAAAAAA- ---CAAAAAAAAAAAAAAAAAAAAAAC-- ----DDDDDDDDDDDDDDDDDDDDDD--- ----------------------------- 
-CC-----------------------CCC -ACC---------------------CCA- --ACC----------------CCCCDAA- --AACCCC-----------CCDADD---- ----DDACCCCCCCCCCCCDDDA------ -------DDDDAAAAAAADDDD------- ------AAAAAAAAAAAAAAAAA------ -----AAAAAAAAAAAAAAAAAAA----- ----ABBBBBBBBBBBBBBBBBBBAA--- ---ABBBBBBBBBBBBBBBBBBBBBAA-- --ABBBBBBBBBBBBBBBBBBBBBBBAA- AAAAAAAAAAAAAAAAAAAAAAAAAAAAA AAAAAAAAAAAAAAAAAAAAAAAAAAAAA AAABBBBBBBBBBBBBBBBBBBBBBBAAA AAABBBBBBBBBBBBBBBBBBBBBBBAAA AAABBBBBBBBBBBBBBBBBBBBBBBAAA AAABBBBBBBBBBBBBBBBBBBBBBBAAA AABBBBBBBBBBBBBBBBBBBBBBBBBAA AAAAAAAAAAAAAAAAAAAAAAAAAAAAA -AAAAAAAAAAAAAAAAAAAAAAAAAAA- --AAAAAAAAAAAAAAAAAAAAAAAAAA- ---CAAAAAAAAAAAAAAAAAAAAAAC-- ----DDDDDDDDDDDDDDDDDDDDDD--- ----------------------------- 
-CC-----------------------CCC -ACC---------------------CCA- --ACC----------------CCCCDAA- --AACCCC-----------CCDADD---- ----DDACCCCCCCCCCCCDDDA------ -------DDDDAAAAAAADDDD------- ------AAAAAAAAAAAAAAAAA------ -----AAAAAAAAAAAAAAAAAAA----- ----ABBBBBBBBBBBBBBBBBBBAA--- ---ABBBBBBBBBBBBBBBBBBBBBAA-- --ABBBBBBBBBBBBBBBBBBBBBBBAA- AAAAAAAAAAAAAAAAAAAAAAAAAAAAA AAAAAAAAAAAAAAAAAAAAAAAAAAAAA AAABBBBBBBBBBBBBBBBBBBBBBBAAA AAABBBBBBBBBBBBBBBBBBBBBBBAAA AAABBBBBBBBBBBBBBBBBBBBBBBAAA AAABBBBBBBBBBBBBBBBBBBBBBBAAA AABBBBBBBBBBBBBBBBBBBBBBBBBAA AAAAAAAAAAAAAAAAAAAAAAAAAAAAA -AAAAAAAAAAAAAAAAAAAAAAAAAAA- --AAAAAAAAAAAAAAAAAAAAAAAAAA- ---CCCCCCCCCCCCCCCCCCCCCCCC-- ----------------------------- ----------------------------- 
-CC-----------------------CCC -ACC---------------------CCA- --ACC----------------CCCCDAA- --AACCCC-----------CCDADD---- ----DDACCCCCCCCCCCCDDDA------ -------DDDDAAAAAAADDDD------- ------AAAAAAAAAAAAAAAAA------ -----AAAAAAAAAAAAAAAAAAA----- ----ABBBBBBBBBBBBBBBBBBBAA--- ---ABBBBBBBBBBBBBBBBBBBBBAA-- --ABBBBBBBBBBBBBBBBBBBBBBBAA- AAAAAAAAAAAAAAAAAAAAAAAAAAAAA AAAAAAAAAAAAAAAAAAAAAAAAAAAAA AAABBBBBBBBBBBBBBBBBBBBBBBAAA AAABBBBBBBBBBBBBBBBBBBBBBBAAA AAABBBBBBBBBBBBBBBBBBBBBBBAAA AAABBBBBBBBBBBBBBBBBBBBBBBAAA AABBBBBBBBBBBBBBBBBBBBBBBBBAA AAAAAAAAAAAAAAAAAAAAAAAAAAAAA -AAAAAAAAAAAAAAAAAAAAAAAAAAA- --AAAAAAAAAAAAAAAAAAAAAAAAAA- ----------------------------- ----------------------------- ----------------------------- 
-CC-----------------------CCC -ACC---------------------CCA- --ACC----------------CCCCDAA- --AACCCC-----------CCDADD---- ----DDACCCCCCCCCCCCDDDA------ -------DDDDAAAAAAADDDD------- ------AAAAAAAAAAAAAAAAA------ -----AAAAAAAAAAAAAAAAAAA----- ----ABBBBBBBBBBBBBBBBBBBAA--- ---ABBBBBBBBBBBBBBBBBBBBBAA-- --ABBBBBBBBBBBBBBBBBBBBBBBAA- AAAAAAAAAAAAAAAAAAAAAAAAAAAAA AAAAAAAAAAAAAAAAAAAAAAAAAAAAA AAABBBBBBBBBBBBBBBBBBBBBBBAAA AAABBBBBBBBBBBBBBBBBBBBBBBAAA AAABBBBBBBBBBBBBBBBBBBBBBBAAA AAABBBBBBBBBBBBBBBBBBBBBBBAAA AABBBBBBBBBBBBBBBBBBBBBBBBBAA AAAAAAAAAAAAAAAAAAAAAAAAAAAAA -AAAAAAAAAAAAAAAAAAAAAAAAAAA- --AAAAAAAAAAAAAAAAAAAAAAAAAA- ----------------------------- ----------------------------- ----------------------------- 
-CC-----------------------CCC -ACC---------------------CCA- --ACC----------------CCCCDAA- --AACCCC-----------CCDADD---- ----DDACCCCCCCCCCCCDDDA------ -------DDDDAAAAAAADDDD------- ------AAAAAAAAAAAAAAAAA------ -----AAAAAAAAAAAAAAAAAAA----- ----ABBBBBBBBBBBBBBBBBBBAA--- ---ABBBBBBBBBBBBBBBBBBBBBAA-- --ABBBBBBBBBBBBBBBBBBBBBBBAA- AAAAAAAAAAAAAAAAAAAAAAAAAAAAA AAAAAAAAAAAAAAAAAAAAAAAAAAAAA AAABBBBBBBBBBBBBBBBBBBBBBBAAA AAABBBBBBBBBBBBBBBBBBBBBBBAAA AAABBBBBBBBBBBBBBBBBBBBBBBAAA AAABBBBBBBBBBBBBBBBBBBBBBBAAA AABBBBBBBBBBBBBBBBBBBBBBBBBAA AAAAAAAAAAAAAAAAAAAAAAAAAAAAA -AAAAAAAAAAAAAAAAAAAAAAAAAAA- ----------------------------- ----------------------------- ----------------------------- ----------------------------- 
-CC-----------------------CCC -AAC---------------------CCA- --ACC----------------CCCCDAA- --AACCCC-----------CCDADD---- ----DDACCCCCCCCCCCCDDDA------ -------DDDDAAAAAAADDDD------- -------AAAAAAAAAAAAAAAA------ -----A-AAAAAAAAAAAAAAAAA----- ----AB-BBBBBBBBBBBBBBBBBAA--- ---ABB-BBBBBBBBBBBBBBBBBBAA-- --ABBB-BBBBBBBBBBBBBBBBBBBAA- AAAAAA-AAAAAAAAAAAAAAAAAAAAAA AAAAAA-AAAAAAAAAAAAAAAAAAAAAA AAABBB-BBBBBBBBBBBBBBBBBBBAAA AAABBB-BBBBBBBBBBBBBBBBBBBAAA AAABBB-BBBBBBBBBBBBBBBBBBBAAA AAABBB-BBBBBBBBBBBBBBBBBBBAAA AABBBB-BBBBBBBBBBBBBBBBBBBBAA -AAAAAAAAAAAAAAAAAAAAAAAAAAA- ----------------------------- ----------------------------- ----------------------------- ----------------------------- ----------------------------- 
----------------------------- -CCC---------------------CCC- --ACC----------------CCCCDAA- --AACCCC-----------CCDADD---- ----DDACCCCCCCCCCCCDDDA------ -------DDDDAAAAAAADDDD------- ----------------------------- -----AAAAAAAAAAAAAAAAAAA----- ----ABBBBBBBBBBBBBBBBBBBAA--- ---ABBBBBBBBBBBBBBBBBBBBBAA-- --ABBBBBBBBBBBBBBBBBBBBBBBAA- AAAAAAAAAAAAAAAAAAAAAAAAAAAAA AAAAAAAAAAAAAAAAAAAAAAAAAAAAA AAABBBBBBBBBBBBBBBBBBBBBBBAAA AAABBBBBBBBBBBBBBBBBBBBBBBAAA AAABBBBBBBBBBBBBBBBBBBBBBBAAA AAABBBBBBBBBBBBBBBBBBBBBBBAAA AAAAAAAAAAAAAAAAAAAAAAAAAAAAA ----------------------------- ----------------------------- ----------------------------- ----------------------------- ----------------------------- ----------------------------- 
----------------------------- ----------------------------- --CCC------------------CCCCC- --CCCCCC-------------CCDD---- ----CCCCC----------CCCC------ -------CCCCCCCCCCCCCCC------- ----------------------------- ----------------------------- ----AAAAAAAAAAAAAAAAAAAAAA--- ---ABBBBBBBBBBBBBBBBBBBBBAA-- --AAAAAAAAAAAAAAAAAAAAAAAAAA- ----------------------------- -AAAAAAAAAAAAAAAAAAAAAAAAAAAA AAAAAAAAAAAAAAAAAAAAAAAAAAAAA AAAAAAAAAAAAAAAAAAAAAAAAAAAAA AAAAAAAAAAAAAAAAAAAAAAAAAAAAA AAAAAAAAAAAAAAAAAAAAAAAAAAAAA ----------------------------- ----------------------------- ----------------------------- ----------------------------- ----------------------------- ----------------------------- ----------------------------- 
----------------------------- ----------------------------- ----C------------------------ --CCCCC--------------CCCC---- ----------------------------- ----------------------------- ----------------------------- ----------------------------- ----------------------------- ---AAAAAAAAAAAAAAAAAAAAAAAA-- ----------------------------- ----------------------------- ----------------------------- ----------------------------- ----------------------------- ----------------------------- ----------------------------- ----------------------------- ----------------------------- ----------------------------- ----------------------------- ----------------------------- ----------------------------- ----------------------------- 
