model
size = 29 24 31, scale = 0.05, origin = -y
material 
  colors = A:#3CF B:#FF3 C:#111 D:#F09
voxels
-AA------------------------AA -AA-----------------------AA- --AA-------------------CCCAA- --AACCA--------------CACC---- ----CCACC----------CCCA------ -------CCCCAAAAAAACCCC------- ----------------------------- ----------------------------- ----------------------------- ----------------------------- ----------------------------- ----------------------------- ----------------------------- ----------------------------- ----------------------------- ----------------------------- ----------------------------- ----------------------------- ----------------------------- ----------------------------- ----------------------------- ----------------------------- ----------------------------- ----------------------------- 
-AA------------------------AA -AA-----------------------AA- --AA-------------------CCCAA- --AACCA--------------CACC---- ----CCACC----------CCCA------ -------CCCCAAAAAAACCCC------- ----------------------------- ----------------------------- ----------------------------- ----------------------------- ----------------------------- ----------------------------- ----------------------------- ----------------------------- ----------------------------- ----------------------------- ----------------------------- ----------------------------- ----------------------------- ----------------------------- ----------------------------- ----------------------------- ----------------------------- ----------------------------- 
-AA------------------------AA -AA-----------------------AA- --AA-------------------CCCAA- --AACCA--------------CACC---- ----CCACC----------CCCA------ -------CCCCAAAAAAACCCC------- ----------------------------- ----------------------------- ----------------------------- ----------------------------- ----------------------------- ----------------------------- ----------------------------- ----------------------------- ----------------------------- ----------------------------- ----------------------------- ----------------------------- ----------------------------- ----------------------------- ----------------------------- ----------------------------- ----------------------------- ----------------------------- 
-AA------------------------AA -AA-----------------------AA- --AA-------------------CCCAA- --AACCA--------------CACC---- ----CCACC----------CCCA------ -------CCCCAAAAAAACCCC------- ----------------------------- ----------------------------- ----------------------------- ----------------------------- ----------------------------- ----------------------------- ----------------------------- ----------------------------- ----------------------------- ----------------------------- ----------------------------- ----------------------------- ----------------------------- ----------------------------- ----------------------------- ----------------------------- ----------------------------- ----------------------------- 
-AA------------------------AA -AA-----------------------AA- --AA-------------------CCCAA- --AACCA--------------CACC---- ----CCACC----------CCCA------ -------CCCCAAAAAAACCCC------- ----------------------------- ----------------------------- ----------------------------- ----------------------------- ----------------------------- ----------------------------- ----------------------------- ----------------------------- ----------------------------- ----------------------------- ----------------------------- ----------------------------- ----------------------------- ----------------------------- ----------------------------- ----------------------------- ----------------------------- ----------------------------- 
-AA------------------------AA -AA-----------------------AA- --AA-------------------CCCAA- --AACCA--------------CACC---- ----CCACC----------CCCA------ -------CCCCAAAAAAACCCC------- ----------------------------- ----------------------------- ----------------------------- ----------------------------- ----------------------------- ----------------------------- ----------------------------- ----------------------------- ----------------------------- ----------------------------- ----------------------------- ----------------------------- ----------------------------- ----------------------------- ----------------------------- ----------------------------- ----------------------------- ----------------------------- 
-AA------------------------AA -AA-----------------------AA- --AA-------------------CCCAA- --AACCA--------------CACC---- ----CCACC----------CCCA------ -------CCCCAAAAAAACCCC------- ----------------------------- ----------------------------- ----------------------------- ----------------------------- ----------------------------- ----------------------------- ----------------------------- ----------------------------- ----------------------------- ----------------------------- ----------------------------- ----------------------------- ----------------------------- ----------------------------- ----------------------------- ----------------------------- ----------------------------- ----------------------------- 
-AA------------------------AA -AA-----------------------AA- --AA-------------------CCCAA- --AACCA--------------CACC---- ----CCACC----------CCCA------ -------CCCCAAAAAAACCCC------- ----------------------------- ----------------------------- ----------------------------- ----------------------------- ----------------------------- ----------------------------- ----------------------------- ----------------------------- ----------------------------- ----------------------------- ----------------------------- ----------------------------- ----------------------------- ----------------------------- ----------------------------- ----------------------------- ----------------------------- ----------------------------- 
-AA------------------------AA -AA-----------------------AA- --AA-------------------CCCAA- --AACCA--------------CACC---- ----CCACC----------CCCA------ -------CCCCAAAAAAACCCC------- ----------------------------- ----------------------------- ----------------------------- ----------------------------- ----------------------------- ----------------------------- ----------------------------- ----------------------------- ----------------------------- ----------------------------- ----------------------------- ----------------------------- ----------------------------- ----------------------------- ----------------------------- ----------------------------- ----------------------------- ----------------------------- 
-AA------------------------AA -AA-----------------------AA- --AA-------------------CCCAA- --AACCA--------------CACC---- ----CCACC----------CCCA------ -------CCCCAAAAAAACCCC------- ----------------------------- ----------------------------- ----------------------------- ----------------------------- ----------------------------- ----------------------------- ----------------------------- ----------------------------- ----------------------------- ----------------------------- ----------------------------- ----------------------------- ----------------------------- ----------------------------- ----------------------------- ----------------------------- ----------------------------- ----------------------------- 
-AA------------------------AA -AA-----------------------AA- --AA-------------------CCCAA- --AACCA--------------CACC---- ----CCACC----------CCCA------ -------CCCCAAAAAAACCCC------- ----------------------------- ----------------------------- ----------------------------- ----------------------------- ----------------------------- ----------------------------- --------------A-------------- ---------C---A-A-----C------- ---------C--A---A------------ ---------C-A--A--A----------- ---------CA--AAA--A---------- ---------AA-AAAAA-AA--------- ----------------------------- ----------------------------- ----------------------------- ----------------------------- ----------------------------- ----------------------------- 
-AA------------------------AA -AA-----------------------AA- --AA-------------------CCCAA- --AACCA--------------CACC---- ----CCACC----------CCCA------ -------CCCCAAAAAAACCCC------- ----------------------------- ----------------------------- -----CCCCCCCCCCCCCCCCCCC----- ----CCCCCCCCCCCCCCCCCCCCC---- ---CCCCCCCCCCCCCCCCCCCCCCC--- ---CCCCCCCCCCCCCCCCCCCCCCC--- ---CCCCCCCCCCCCCCCCCCCCCCC--- ---CCCCCCCCCCCCCCCCCCCCCCC--- ---CCCCCCCCCCCCCCCCCCCCCCC--- ---CCCCCCCCCCCCCCCCCCCCCCC--- ---CCCCCCCCCCCCCCCCCCCCCCC--- ----CCCCCCCCCCCCCCCCCCCCC---- ----------------------------- ----------------------------- ----------------------------- ----------------------------- ----------------------------- ----------------------------- 
-AA------------------------AA -AA-----------------------AA- --AA-------------------CCCAA- --AACCA--------------CACC---- ----CCACC----------CCCA------ -------CCCCAAAAAAACCCC------- ------AAAAAAAAAAAAAAAAA------ -----AAAAAAAAAAAAAAAAAAA----- ----ABBBBBBBBBBBBBBBBBBBAA--- ---ABBBBBBBBBBBBBBBBBBBBBAA-- ---BBBBBBBBBBBBBBBBBBBBBBBA-- --ABBBBBBBBBBBBBBBBBBBBBBBA-- --ABBBBBBBBBBBBBBBBBBBBBBBA-- --ABBBBBBBBBBBBBBBBBBBBBBBA-- --ABBBBBBBBBBBBBBBBBBBBBBBA-- --ABBBBBBBBBBBBBBBBBBBBBBBA-- --ABBBBBBBBBBBBBBBBBBBBBBBA-- --ACCCCCCCCCCCCCCCCCCCCCCCA-- ---CCCCCCCCCCCCCCCCCCCCCCC--- ----------------------------- ----------------------------- ----------------------------- ----------------------------- ----------------------------- 
-AA------------------------AA -AA-----------------------AA- --AA-------------------CCCAA- --AACCA--------------CACC---- ----CCACC----------CCCA------ -------CCCCAAAAAAACCCC------- ------A---------AAAAAAA------ -----AAAAAAAAAAAAAAAAAAA----- ----ABBBBBBBBBBBBBBBBBBBAA--- ---ABBBBBBBBBBBBBBBBBBBBBAA-- --ABBBBBBBBBBBBBBBBBBBBBBBAA- -AABBBBBBBBBBBBBBBBBBBBBBBAA- -AABBBBBBBBBBBBBBBBBBBBBBBAA- -AAAAAAAAAAAAAAAAAAAAAAAAAAA- -AABBBBBBBBBBBBBBBBBBBBBBBAA- -AABBBBBBBBBBBBBBBBBBBBBBBAA- -AABBBBBBBBBBBBBBBBBBBBBBBAA- -AAAAAAAAAAAAAAAAAAAAAAAAAAA- --ACCCCCCCCCCCCCCCCCCCCCCCAA- ---ACCCCCCCCCCCCCCCCCCCCCAA-- ----------------------------- ----------------------------- ----------------------------- ----------------------------- 
-AA------------------------AA -AA-----------------------AA- --AA-------------------CCCAA- --AACCA--------------CACC---- ----CCACC----------CCCA------ -------CCCCAAAAAAACCCC------- ------AAAAAAAAAAAAAAAAA------ -----AAAAAAAAAAAAAAAAAAA----- ----ABBBBBBBBBBBBBBBBBBBAA--- ---ABBBBBBBBBBBBBBBBBBBBBAA-- --ABBBBBBBBBBBBBBBBBBBBBBBAA- -AABBBBBBBBBBBBBBBBBBBBBBBAA- -AABBBBBBBBBBBBBBBBBBBBBBBAA- -AABBBBBBBBBBBBBBBBBBBBBBBAA- -AABBBBBBBBBBBBBBBBBBBBBBBAA- -AABBBBBBBBBBBBBBBBBBBBBBBAA- -AABBBBBBBBBBBBBBBBBBBBBBBAA- -ABBBBBBBBBBBBBBBBBBBBBBBBBA- -ACCCCCCCCCCCCCCCCCCCCCCCCCA- --AAACCCCCCCCCCCCCCCCCCCAAA-- ----------------------------- ----------------------------- ----------------------------- ----------------------------- 
-AA------------------------AA -AA-----------------------AA- --AA-------------------CCCAA- --AACCA--------------CACC---- ----CCACC----------CCCA------ -------CCCCAAAAAAACCCC------- ------AAAAAAAAAAAAAAAAA------ -----AAAAAAAAAAAAAAAAAAA----- ----ABBBBBBBBBBBBBBBBBBBAA--- ---ABBBBBBBBBBBBBBBBBBBBBAA-- --ABBBBBBBBBBBBBBBBBBBBBBBAA- AAAAAAAAAAAAAAAAAAAAAAAAAAAAA AAAAAAAAAAAAAAAAAAAAAAAAAAAAA AAADDDDDBB-BBBBBBDDBBBDDDDAAA AAADDDDDBBBBBBBB-DDBBBDDDDAAA AAADDDDDBBBBBBBBBDDBBBDDDDAAA AAADDDDDBBBBBBBBBDDBBBDDDDAAA AAAAAAAAAAAAAAAA-AAAAAAAAAAAA AAAAAAAAAAAAAAAAAAAAAAAAAAAAA --AAAAAAAAAAAAAAAAAAAAAAAAAA- ---AAAAAAAAAAAAAAAAAAAAAAA--- ----------------------------- ----------------------------- ----------------------------- 
-AA------------------------AA -AAA----------------------AA- --AA-------------------CCCAA- --AACCA--------------CACC---- ----CCACC----------CCCA------ -------CCCCAAAAAAACCCC------- ------AAAAAAAAAAAAAAAAA------ -----AAAAAAAAAAAAAAAAAAA----- ----ABBBBBBBBBBBBBBBBBBBAA--- ---ABBBBBBBBBBBBBBBBBBBBBAA-- --ABBBBBBBBBBBBBBBBBBBBBBBAA- AAAAAAAAAAAAAAAAAAAAAAAAAAAAA AAAAAAAAAAAAAAAAAAAAAAAAAAAAA AAADDDDDDDBDDDDDDDDDDDDDDDAAA AAADDDDDDDDDDDDDBBDDDDDDDDAAA AAABBBBBBBBBBBBBBBBBBBBBBBAAA AAABBBBBBBBBBBBBBBBBBBBBBBAAA AABBBBBBBBBBBBBB-BBBBBBBBBBAA AAAAAAAAAAAAAAAAAAAAAAAAAAAAA -AAAAAAAAAAAAAAAAAAAAAAAAAAA- --AAAAAAAAAAAAAAAAAAAAAAAAAA- ----------------------------- ----------------------------- ----------------------------- 
-AA------------------------AA -AAA----------------------AA- --AA-------------------CCCAA- --AACCA--------------CACC---- ----CCACC----------CCCA------ -------CCCCAAAAAAACCCC------- ------AAAAAAAAAAAAAAAAA------ -----AAAAAAAAAAAAAAAAAAA----- ----ABBBBBBBBBBBBBBBBBBBAA--- ---ABBBBBBBBBBBBBBBBBBBBBAA-- --ABBBBBBBBBBBBBBBBBBBBBBBAA- AAAAAAAAAAAAAAAAAAAAAAAAAAAAA AAAAAAAAAAAAAAAAAAAAAAAAAAAAA AAABBBBBBBBBBBBBBBBBBBBBBBAAA AAABBBBBBBBBBBBBBBBBBBBBBBAAA AAABBBBBBBBBBBBBBBBBBBBBBBAAA AAABBBBBBBBBBBBBBBBBBBBBBBAAA AADDDDDDDDDDDDDDBDDDDDDDDDDAA AAAAAAAAAAAAAAAAAAAAAAAAAAAAA -AAAAAAAAAAAAAAAAAAAAAAAAAAA- --AAAAAAAAAAAAAAAAAAAAAAAAAA- ---AAAAAAAAAAAAAAAAAAAAAAAA-- ----------------------------- ----------------------------- 
-AA------------------------AA -AAA----------------------AA- --AA-------------------CCCAA- --AACCA--------------CACC---- ----CCACC----------CCCA------ -------CCCCAAAAAAACCCC------- ------AAAAAAAAAAAAAAAAA------ -----AAAAAAAAAAAAAAAAAAA----- ----ABBBBBBBBBBBBBBBBBBBAA--- ---ABBBBBBBBBBBBBBBBBBBBBAA-- --ABBBBBBBBBBBBBBBBBBBBBBBAA- AAAAAAAAAAAAAAAAAAAAAAAAAAAAA AAAAAAAAAAAAAAAAAAAAAAAAAAAAA AAABBBBBBBBBBBBBBBBBBBBBBBAAA AAABBBBBBBBBBBBBBBBBBBBBBBAAA AAABBBBBBBBBBBBBBBBBBBBBBBAAA AAABBBBBBBBBBBBBBBBBBBBBBBAAA AABBBBBBBBBBBBBBBBBBBBBBBBBAA AAAAAAAAAAAAAAAAAAAAAAAAAAAAA -AAAAAAAAAAAAAAAAAAAAAAAAAAA- --AAAAAAAAAAAAAAAAAAAAAAAAAA- ---AAAAAAAAAAAAAAAAAAAAAAAA-- ----CCCCCCCCCCCCCCCCCCCCCC--- ----------------------------- 
-AA------------------------AA -AAA----------------------AA- --AA-------------------CCCAA- --AACCA--------------CACC---- ----CCACC----------CCCA------ -------CCCCAAAAAAACCCC------- ------AAAAAAAAAAAAAAAAA------ -----AAAAAAAAAAAAAAAAAAA----- ----ABBBBBBBBBBBBBBBBBBBAA--- ---ABBBBBBBBBBBBBBBBBBBBBAA-- --ABBBBBBBBBBBBBBBBBBBBBBBAA- AAAAAAAAAAAAAAAAAAAAAAAAAAAAA AAAAAAAAAAAAAAAAAAAAAAAAAAAAA AAABBBBBBBBBBBBBBBBBBBBBBBAAA AAABBBBBBBBBBBBBBBBBBBBBBBAAA AAABBBBBBBBBBBBBBBBBBBBBBBAAA AAABBBBBBBBBBBBBBBBBBBBBBBAAA AABBBBBBBBBBBBBBBBBBBBBBBBBAA AAAAAAAAAAAAAAAAAAAAAAAAAAAAA -AAAAAAAAAAAAAAAAAAAAAAAAAAA- --AAAAAAAAAAAAAAAAAAAAAAAAAA- ---AAAAAAAAAAAAAAAAAAAAAAAA-- ----CCCCCCCCCCCCCCCCCCCCCC--- -------------AA-------------- 
-AA------------------------AA -AAA----------------------AA- --AA-------------------CC-AA- --AACCA--------------CACC---- ----CCACC----------CCCA------ -------CCCCAAAAAAACCCC------- ------AAAAAAAAAAAAAAAAA------ -----AAAAAAAAAAAAAAAAAAA----- ----ABBBBBBBBBBBBBBBBBBBAA--- ---ABBBBBBBBBBBBBBBBBBBBBAA-- --ABBBBBBBBBBBBBBBBBBBBBBBAA- AAAAAAAAAAAAAAAAAAAAAAAAAAAAA AAAAAAAAAAAAAAAAAAAAAAAAAAAAA AAABBBBBBBBBBBBBBBBBBBBBBBAAA AAABBBBBBBBBBBBBBBBBBBBBBBAAA AAABBBBBBBBBBBBBBBBBBBBBBBAAA AAABBBBBBBBBBBBBBBBBBBBBBBAAA AABBBBBBBBBBBBBBBBBBBBBBBBBAA AAAAAAAAAAAAAAAAAAAAAAAAAAAAA -AAAAAAAAAAAAAAAAAAAAAAAAAAA- --AAAAAAAAAAAAAAAAAAAAAAAAAA- ---AAAAAAAAAAAAAAAAAAAAAAAA-- ----CCCCCCCCCCCCCCCCCCCCCC--- -------------AA-------------- 
-AA------------------------AA -AAA----------------------AA- --AA-------------------CC-AA- --AACCA--------------CAC----- ----CCACC----------CCCA------ -------CCCCAAAAAAACCCC------- ------AAAAAAAAAAAAAAAAA------ -----AAAAAAAAAAAAAAAAAAA----- ----ABBBBBBBBBBBBBBBBBBBAA--- ---ABBBBBBBBBBBBBBBBBBBBBAA-- --ABBBBBBBBBBBBBBBBBBBBBBBAA- AAAAAAAAAAAAAAAAAAAAAAAAAAAAA AAAAAAAAAAAAAAAAAAAAAAAAAAAAA AAABBBBBBBBBBBBBBBBBBBBBBBAAA AAABBBBBBBBBBBBBBBBBBBBBBBAAA AAABBBBBBBBBBBBBBBBBBBBBBBAAA AAABBBBBBBBBBBBBBBBBBBBBBBAAA AABBBBBBBBBBBBBBBBBBBBBBBBBAA AAAAAAAAAAAAAAAAAAAAAAAAAAAAA -AAAAAAAAAAAAAAAAAAAAAAAAAAA- --AAAAAAAAAAAAAAAAAAAAAAAAAA- ---AAAAAAAAAAAAAAAAAAAAAAAA-- ----CCCCCCCCCCCCCCCCCCCCCC--- ----------------------------- 
-AA------------------------AA -AAA----------------------AA- --AA-------------------CCCAA- --AACCA--------------CACC---- ----CCACC----------CCCA------ -------CCCCAAAAAAACCCC------- ------AAAAAAAAAAAAAAAAA------ -----AAAAAAAAAAAAAAAAAAA----- ----ABBBBBBBBBBBBBBBBBBBAA--- ---ABBBBBBBBBBBBBBBBBBBBBAA-- --ABBBBBBBBBBBBBBBBBBBBBBBAA- AAAAAAAAAAAAAAAAAAAAAAAAAAAAA AAAAAAAAAAAAAAAAAAAAAAAAAAAAA AAABBBBBBBBBBBBBBBBBBBBBBBAAA AAABBBBBBBBBBBBBBBBBBBBBBBAAA AAABBBBBBBBBBBBBBBBBBBBBBBAAA AAABBBBBBBBBBBBBBBBBBBBBBBAAA AABBBBBBBBBBBBBBBBBBBBBBBBBAA AAAAAAAAAAAAAAAAAAAAAAAAAAAAA -AAAAAAAAAAAAAAAAAAAAAAAAAAA- --AAAAAAAAAAAAAAAAAAAAAAAAAA- ---AAAAAAAAAAAAAAAAAAAAAAAA-- ----CCCCCCCCCCCCCCCCCCCCCC--- ----------------------------- 
-AA------------------------AA -AAA----------------------AA- --AA-------------------CCCAA- --AACCA--------------CACC---- ----CCACC----------CCCA------ -------CCCCAAAAAAACCCC------- ------AAAAAAAAAAAAAAAAA------ -----AAAAAAAAAAAAAAAAAAA----- ----ABBBBBBBBBBBBBBBBBBBAA--- ---ABBBBBBBBBBBBBBBBBBBBBAA-- --ABBBBBBBBBBBBBBBBBBBBBBBAA- AAAAAAAAAAAAAAAAAAAAAAAAAAAAA AAAAAAAAAAAAAAAAAAAAAAAAAAAAA AAABBBBBBBBBBBBBBBBBBBBBBBAAA AAABBBBBBBBBBBBBBBBBBBBBBBAAA AAABBBBBBBBBBBBBBBBBBBBBBBAAA AAABBBBBBBBBBBBBBBBBBBBBBBAAA AABBBBBBBBBBBBBBBBBBBBBBBBBAA AAAAAAAAAAAAAAAAAAAAAAAAAAAAA -AAAAAAAAAAAAAAAAAAAAAAAAAAA- --AAAAAAAAAAAAAAAAAAAAAAAAAA- ---AAAAAAAAAAAAAAAAAAAAAAAA-- ----------------------------- ----------------------------- 
-AA------------------------AA -AAA----------------------AA- --AA-------------------CCCAA- --AACCA--------------CACC---- ----CCACC----------CCCA------ -------CCCCAAAAAAACCCC------- ------AAAAAAAAAAAAAAAAA------ -----AAAAAAAAAAAAAAAAAAA----- ----ABBBBBBBBBBBBBBBBBBBAA--- ---ABBBBBBBBBBBBBBBBBBBBBAA-- --ABBBBBBBBBBBBBBBBBBBBBBBAA- AAAAAAAAAAAAAAAAAAAAAAAAAAAAA AAAAAAAAAAAAAAAAAAAAAAAAAAAAA AAABBBBBBBBBBBBBBBBBBBBBBBAAA AAABBBBBBBBBBBBBBBBBBBBBBBAAA AAABBBBBBBBBBBBBBBBBBBBBBBAAA AAABBBBBBBBBBBBBBBBBBBBBBBAAA AABBBBBBBBBBBBBBBBBBBBBBBBBAA AAAAAAAAAAAAAAAAAAAAAAAAAAAAA -AAAAAAAAAAAAAAAAAAAAAAAAAAA- --AAAAAAAAAAAAAAAAAAAAAAAAAA- ----------------------------- ----------------------------- ----------------------------- 
-AA------------------------AA -AAA----------------------AA- --AA-------------------CCCAA- --AACCA--------------CACC---- ----CCACC----------CCCA------ -------CCCCAAAAAAACCCC------- ------AAAAAAAAAAAAAAAAA------ -----AAAAAAAAAAAAAAAAAAA----- ----ABBBBBBBBBBBBBBBBBBBAA--- ---ABBBBBBBBBBBBBBBBBBBBBAA-- --ABBBBBBBBBBBBBBBBBBBBBBBAA- AAAAAAAAAAAAAAAAAAAAAAAAAAAAA AAAAAAAAAAAAAAAAAAAAAAAAAAAAA AAABBBBBBBBBBBBBBBBBBBBBBBAAA AAABBBBBBBBBBBBBBBBBBBBBBBAAA AAABBBBBBBBBBBBBBBBBBBBBBBAAA AAABBBBBBBBBBBBBBBBBBBBBBBAAA AABBBBBBBBBBBBBBBBBBBBBBBBBAA AAAAAAAAAAAAAAAAAAAAAAAAAAAAA -AAAAAAAAAAAAAAAAAAAAAAAAAAA- --AAAAAAAAAAAAAAAAAAAAAAAAAA- ----------------------------- ----------------------------- ----------------------------- 
-AA------------------------AA -AAA----------------------AA- --AA-------------------CCCAA- --AACCA--------------CACC---- ----CCACC----------CCCA------ -------CCCCAAAAAAACCCC------- ------AAAAAAAAAAAAAAAAA------ -----AAAAAAAAAAAAAAAAAAA----- ----ABBBBBBBBBBBBBBBBBBBAA--- ---ABBBBBBBBBBBBBBBBBBBBBAA-- --ABBBBBBBBBBBBBBBBBBBBBBBAA- AAAAAAAAAAAAAAAAAAAAAAAAAAAAA AAAAAAAAAAAAAAAAAAAAAAAAAAAAA AAABBBBBBBBBBBBBBBBBBBBBBBAAA AAABBBBBBBBBBBBBBBBBBBBBBBAAA AAABBBBBBBBBBBBBBBBBBBBBBBAAA AAABBBBBBBBBBBBBBBBBBBBBBBAAA AABBBBBBBBBBBBBBBBBBBBBBBBBAA AAAAAAAAAAAAAAAAAAAAAAAAAAAAA -AAAAAAAAAAAAAAAAAAAAAAAAAAA- ----------------------------- ----------------------------- ----------------------------- ----------------------------- 
-AA------------------------AA -AAA----------------------AA- --AA-------------------CCCAA- --AACCA--------------CACC---- ----CCACC----------CCCA------ -------CCCCAAAAAAACCCC------- -------AAAAAAAAAAAAAAAA------ -----A-AAAAAAAAAAAAAAAAA----- ----AB-BBBBBBBBBBBBBBBBBAA--- ---ABB-BBBBBBBBBBBBBBBBBBAA-- --ABBB-BBBBBBBBBBBBBBBBBBBAA- AAAAAA-AAAAAAAAAAAAAAAAAAAAAA AAAAAA-AAAAAAAAAAAAAAAAAAAAAA AAABBB-BBBBBBBBBBBBBBBBBBBAAA AAABBB-BBBBBBBBBBBBBBBBBBBAAA AAABBB-BBBBBBBBBBBBBBBBBBBAAA AAABBB-BBBBBBBBBBBBBBBBBBBAAA AABBBB-BBBBBBBBBBBBBBBBBBBBAA -AAAAAAAAAAAAAAAAAAAAAAAAAAA- ----------------------------- ----------------------------- ----------------------------- ----------------------------- ----------------------------- 
----------------------------- -AAA----------------------AA- --AA-------------------CCCAA- --AACCA--------------CACC---- ----CCACC----------CCCA------ -------CCCCAAAAAAACCCC------- ----------------------------- -----AAAAAAAAAAAAAAAAAAA----- ----ABBBBBBBBBBBBBBBBBBBAA--- ---ABBBBBBBBBBBBBBBBBBBBBAA-- --ABBBBBBBBBBBBBBBBBBBBBBBAA- AAAAAAAAAAAAAAAAAAAAAAAAAAAAA AAAAAAAAAAAAAAAAAAAAAAAAAAAAA AAABBBBBBBBBBBBBBBBBBBBBBBAAA AAABBBBBBBBBBBBBBBBBBBBBBBAAA AAABBBBBBBBBBBBBBBBBBBBBBBAAA AAABBBBBBBBBBBBBBBBBBBBBBBAAA AAAAAAAAAAAAAAAAAAAAAAAAAAAAA ----------------------------- ----------------------------- ----------------------------- ----------------------------- ----------------------------- ----------------------------- 
----------------------------- --AA------------------------- --AA-------------------CCCAA- --AACCA--------------CACC---- ----CCACC----------CCCA------ -------CCCCAAAAAAACCCC------- ----------------------------- ----------------------------- ----AAAAAAAAAAAAAAAAAAAAAA--- ---ABBBBBBBBBBBBBBBBBBBBBAA-- --AAAAAAAAAAAAAAAAAAAAAAAAAA- ----------------------------- -AAAAAAAAAAAAAAAAAAAAAAAAAAAA AAAAAAAAAAAAAAAAAAAAAAAAAAAAA AAAAAAAAAAAAAAAAAAAAAAAAAAAAA AAAAAAAAAAAAAAAAAAAAAAAAAAAAA AAAAAAAAAAAAAAAAAAAAAAAAAAAAA ----------------------------- ----------------------------- ----------------------------- ----------------------------- ----------------------------- ----------------------------- ----------------------------- 
----------------------------- ----------------------------- ----------------------------- --AACCA--------------CACC---- ----------------------------- ----------------------------- ----------------------------- ----------------------------- ----------------------------- ---AAAAAAAAAAAAAAAAAAAAAAAA-- ----------------------------- ----------------------------- ----------------------------- ----------------------------- ----------------------------- ----------------------------- ----------------------------- ----------------------------- ----------------------------- ----------------------------- ----------------------------- ----------------------------- ----------------------------- ----------------------------- 
