model
size = 19 26 32, scale = 0.05, origin = -y
material 
  colors = A:#00E B:#F0C C:#AAA D:#001 E:#444 F:#BBB G:#DDD H:#F36 I:#E00 J:#CF3
voxels
141-3I148-5B16-2(F18-)F17-3F263-3I15-5G13-2(G2A)G12-4GA2G12-G2AGA2G12-4GA2G12-G5AG13-5G14-5B301-D17-D-2(D17-)D-D17-D111-B3-B300-4(CAC16-)3C16-D-D91-B3-B262-D-D16-CAC2(35-3A)35-3C17-D73-B3-B244-D17-CAC2(35-3A16-3A)35-3C16-D-D53-B3-B224-D-D16-CAC4(35-3A)35-3C17-D35-2B-2B225-D17-CAC3(16-3A)2(35-3A)2(16-3A)16-3C16-D-D35-B-B111-3E16-3E17-E74-D-D16-CAC73-3A15-5B15-3A73-CAC17-D36-3B92-3E15-5E13-E5-E91-D17-CAC3(16-3A)35-3A14-B5-2(B14-3A-)B14-3A16-3C16-D-D35-3B17-4(F18-)F16-5E13-E5-E90-D-D16-CAC2(35-3A)33-2(B-3A-B12-B5-B12-)B-CAC-B12-B2-D2-B12-2B3-2B13-5B109-5E19-E110-D17-CAC35-3A16-3A33-B-3A-B14-3A14-B5-B12-B-CAC-B15-D56-B112-3E149-D-D16-CAC35-3A33-B-3A-B33-CAC16-D-D14-B5-B12-B2-D2-B12-B5-B15-B112-3E169-D17-2(CAC16-)CAC14-B-CAC-B14-CAC17-D91-7B110-E188-D-2(D17-)D-D14-B2-D2-B14-D-D112-B113-E161-2DJD78-B5-B78-DJ2D47-B113-E161-4D4(F18-)2F7B2F13-H4-3(F18-)F4D47-B275-2DJD100-H18-H43-DJ2D47-B18-B379-H18-H94-B18-F18-E246-D17-D-2(D17-)D-D17-D37-H18-H75-B283-4(CAC16-)3C16-D-D36-H18-H56-B18-B226-D-D16-CAC2(35-3A)35-3C17-D37-H18-H56-B208-D17-CAC2(35-3A16-3A)35-3C16-D-D36-H18-H37-B37-5(F18-)F10-3E11F3E28-D-D16-CAC3(35-3A)14-B5-B12-B-3A-B12-B5-B12-B-3C-B12-B2-D2-B12-B5-B13-B3-B15-B-B17-B2(18-F)151-D17-CAC3(16-3A)35-3A14-B5-B14-3(3A16-)3C16-D-D74-B188-D-D16-CAC73-3A15-5B15-3A73-CAC93-B172-B16-D17-CAC3(16-3A)2(35-3A)2(16-3A)16-3C16-D-D72-5B186-D-D16-CAC4(35-3A)35-CAC17-D73-B3-B206-D17-CAC2(35-3A16-3A)35-CAC17-D92-B3-B224-D-D16-CAC2(35-3A)35-CAC16-D-D110-B3-B244-D17-4(CAC16-)CAC17-D130-B3-B262-2(D-2(D17-))D-D148-5B159-
