model
size = 32, scale = 0.05, origin = -y
material 
  colors = A:#E00 B:#3CF C:#CC3 D:#FF3 E:#F00 F:#F69 G:#CF0 H:#F96 I:#F33 J:#F03 K:#F63 L:#F06 M:#CF6 N:#F9F O:#F93 P:#F6F Q:#CC0 R:#CF9 S:#F0C T:#CFF U:#F60 V:#CF3 W:#F6C X:#F36 Y:#F09 Z:#CCC Aa:#F66 Ab:#FCF Ac:#FCC Ad:#F90 Ae:#FC3 Af:#FC0 Ag:#CFC Ah:#FFC Ai:#F30 Aj:#FF0 Ak:#F9C Al:#FF6 Am:#F3C An:#FC6 Ao:#F99 Ap:#CC9 Aq:#FF9 Ar:#CCF As:#FC9
voxels
33C29(30-2C)30-34C9-12B9-C11-2B6A2B24-6A301-B30-BA30-A128-A30-AB30-BA30-A269-2A2B2A24-4A2B4A11-C3AAmBFAlAaTSHEAiNMAYAk2AZAAiDVO4A2C-28B-C9-BA10DAB19-3A6D3A21-10A23-8A24-A6-A3(24-8A)18-2(D5-8A5-D12-)D5-8A5-D6-A5-D5-8A5-D5-2A5-D6-6A6-D5-A6-D7-4A7-D12-D4-D8AD4-D17-10A23-8A12-A11-8A11-AB11-8A11-BA11-8A11-A12-8A24-8A25-6A122-2A2B2A24-4A2B4A21-3A6-3A19-2A10-2A9-CAPAhYXYAAcAFAMALAUAnAAiAEAKGE2AVAoA2C29B-C-8B14D8B2-9B12D9B2-A6-3A10D3A9-A6-5A6D5A9-A2(6-5A)9-A6-4A-6A-4A9-3(A4-D-4A8-4A-D7-)A2(4-D-4A-D)7-A2(4-D-4A-D)6-2A4-D-5A2-2A2-5A-D5-3A4-D-4A8-4A-D5-A-3(A4-D-4A8-4A-D7-)A4-D-4A8-4A-D6-2A6-4A8-4A7-ABA6-4A8-4A7-B2A6-4A8-4A7-A-2(A7-3A8-3A10-)A7-4A2-2D2-4A10-A8-5A2B5A11-A9-4A2B4A12-A10-3A2B3A13-A8-3A2-2A2-3A11-A7-2(2A10-)A6-2A12-2A9-A5-2A14-2A7-CAHBRO2AWOAnAiAF3AAdXAU5AWANBAg2C12B6-11B-CBS4BA5D8A5DA4BS8B4AD8AD4A13BA-16A-A12BA-16A-A6B3-3BA2-4A6-4A2-A3B8-BA3-12A3-AB11-A4-D8AD4-A12-A7-4A7-A12-A18-A12-A4-A8-A4-A12-A18-A6-A5-A18-A5-2A5-A18-A5-A6-2(A18-A12-)A18-A8-A2-2A18-2A2(2-A)4-4A14-4A4-AB4-3A16-3A4-BA4-3A16-3A4-A5-4A14-4A11-3A14-3A11-A-2(2A6-)2A-A12-3A2-A-4A-A2-3A15-5A6-5A17-3A8-3A17-7A2-7A16-A2-10A2-A15-A6-4A6-A13-A18-A6-CDAQAGJAX2AAdAAeJFJAeAF3APM3ALEO2C10B10-9B-CBAk2B-A20-A-2BAk2BN2B2-A18-A2-2BN2BT2B2-2A16-2A2-2BT2BA4B-A16-A-4BA7B2-A14-A2-10B-B3-A12-A3-B-4B3-3A4-12A4-3A5-5A4-10A4-5A4-4A7-6A7-4A4-2(4A8-)4A4-4A20-4A2-A-4A20-4A-2A-4A20-4A-A2-4A20-4A4-4A20-4A5-3A20-3A5-4A20-4A2-A2-2A22-2A2-AB2-2A22-2A2-BA2-3A20-3A2-A3-3A20-3A6-4A5-2(2A-)2A5-4A7-3A5-2A4-2A5-3A10-A4-A8-A4-A12-2A16-2A13-2(2A14-)3A12-3A13-2A-2A10-2A-2A12-A3-4A4-4A3-A11-A20-A5-CUAlAfAKUM3AIFAGAnHLPAeJL2AT2EAcZPA2C10B10-9B-CBD2BA22-A2BD2BAk2B-A20-A-2BAk2BAb2B-A20-A-2BAb2BA3B2A18-2A3BA5B2-2A16-2A2-8B2-3A14-3A2-8B4-2A12-2A4-6BA2-BA2-2A10-2A2-AB2-A2B2-2A-A20-A-2A4-2A-2A18-2A-2A4-2A-3(A6-)A-2A2-A-2A24-2(2A-)2ABA20-AB2A-A2-3(2A24-2A4-)2AB22-B2A2-A-2AB22-B2A-AB-3A22-3A-BA-2A24-2A-A3-2A8-A4-A8-2A6-2A5-2A8-2A5-2A7-B5-A10-A5-B8-BA3-A12-A3-AB9-B-2A14-2A-B10-2BA16-A2B11-2A16-2A11-A-2A14-2A-A10-A20-A9-A22-A4-CFCL2ADAAjAOYAn3AAeAMAH3AAc3AJAfW2C7B16-6B-C3BA24-A7BA22-A2(8B-A20-A-)8B2-A18-A2-8BA-A18-A-A8B24-5B30-2B2A2-B20-B2-2A2BA3-B20-B3-A2B2A26-2(2AB)26-BAB2AB26-B2ABA2B24-2BA4(2B2A26-2A)2B-A26-2(A-B)26-B-A35-A5-A12-A5-A6-A24-A6-B3-A16-A3-B6-2B-A18-A-2B7-B-A18-A-B8-BA20-AB9-2A18-2A9-A22-A7-A24-A3-2CEAaAAdAWKAK2AY3AAeAjAAeJAjRI2AIGNV2C7B16-6B-C3BA24-A6BA24-A7B2(A22-A8B)-A20-A-2(8B2-A18-A2-)5B5-AB16-BA5-3B28-3B30-2B2(30-BA)30-AB30-3B28-3BAB26-BA3B28-4B28-3BA28-2(AB)28-2B-B28-B2-B28-B3-B26-2(B4-B3-A18-A3-)B5-B-A20-A-B6-BA22-AB7-A22-A7-A24-A35-CGM3ADJAjAd3ARAOXAUYAGPDALEAAgNE2C7B16-6B-C2B2A24-2A5B2A23-A6B3A22-A7B2(A22-A8B)-2A18-2A-7B3-A18-A3-4B5-A18-A5-3(2B30-)BA30-BA-B26-B-A2B28-3B30-3B28-4B28-3B30-2B30-BA30-2B30-B33-B4-A18-A4-B2-B28-B2-B3-A20-A2(3-B)-A22-A-B4-2BA22-A2B5-A24-A6-A24-A5-B26-B2-CAoAbW2AU2AAiJAO2AKOLARXAHAAn3AAmTAp2C7B16-6B-CBWCB24-BCW2BAgAsB24-BAsAg3BAlB24-BAl2B2-B26-B226-A30-2A30-A128-A30-AB30-BA30-A32-B5-A18-A5-2B5-A18-A5-B5-A20-A6-B2-A22-A2(2-B)A26-AB3-2(2A24-2A4-)B26-B4-BA24-AB2-CASX2AFAjAK2AKAUA2G2AO2AKAJAEARZ2C7B16-6B-C-BAB24-BA3BArQB24-BQAr5B24-4B2-B26-B226-A30-2A30-A128-A30-AB30-BA30-A32-Ag5-Ah18-Ah5-AgB4-Ah20-Ah4-BAa30-Aa36-A22-A5-Al28-Al3-S26-S4-B26-B3-B-Af24-Af-B-CHFAbAcACAHAC4AJKEAjAG2AAcIGLPQAqE2C7B16-6B-C-BDB24-BD2(4BAB24-BA)2B2-B26-B226-A30-2A30-A128-A30-AB30-BA30-A65-YA26-AY2-Am2-K22-K2-Am2(2-A)22-2(A2-)IMQ24-QMI3-A26-A3-ZF26-FZ2-BA26-AB2-BV26-VB-CH4AGAHP2AJ4AC2AKACDL3AUWV2C7B16-6B-C-BDB24-BDB2-BDB24-BDB-4B24-4B2-B26-B226-A30-2A30-A128-A30-AB30-BA30-A37-B20-B6-HC2-Ab20-Ab2-CH2-AoP-S22-S-PAo2-Af-V24-V-Af2-ENX24-XNE2-2Q26-2Q3-E26-E3-BP26-PB2-B28-B-CAbVKIAdARIAC3AAeCAdAc3AUEG2AJAAkAN2C7B16-6B-C-BDB24-BDB2-3B24-3B289-A30-2A30-A128-A30-AB30-BA30-A37-A20-A6-AmA-Aa22-Aa-AAm2-AI26-IA2-I28-I2-TS26-ST2-ZM26-MZ3-B26-B3-BAa26-AaB2-B28-B-CAN9ACAAc2AAi2AAdAM3AG3AL2C7B16-6B-C2-2B24-3B3-2B24-3B4-B284-A30-2A30-A128-A30-AB30-BA30-A65-AqJ26-JAq2-GF-N22-N-FG2-AApA24-AApA2-LHI24-IHL3-R26-R4-F26-F3-BD26-DB2-B28-B-CAOAhATHAOR4AWC7AM3AT2AZ2C7B16-6B-C2-2B24-3B3-2B24-3B4-B284-A30-2A30-A128-A30-AB30-BA30-A65-AqJ26-JAq2-GF-N22-N-FG2-AApA24-AApA2-LHI24-IHL3-R26-R4-F26-F3-BD26-DB2-B28-B-CAOAhATHAOR4AWC7AM3AT2AZ2C7B16-6B-C-BDB26-B2-3B24-3B289-A30-2A30-A128-A30-AB30-BA30-A37-A20-A6-AmA-Aa22-Aa-AAm2-AI26-IA2-I28-I2-TS26-ST2-ZM26-MZ3-B26-B3-BAa26-AaB2-B28-B-CAN9ACAAc2AAi2AAdAM3AG3AL2C7B16-6B-C-BDB25-2B2-BDB24-BDB-4B24-4B2-B26-B226-A30-2A30-A128-A30-AB30-BA30-A37-B20-B6-HC2-Ab20-Ab2-CH2-AoP-S22-S-PAo2-Af-V24-V-Af2-ENX24-XNE2-2Q26-2Q3-E26-E3-BP26-PB2-B28-B-CAbVKIAdARIAC3AAeCAdAc3AUEG2AJAAkAN2C7B16-6B-C-BDB27-3BAB24-BA4BAB24-4B2-B26-B226-A30-2A30-A128-A30-AB30-BA30-A65-YA26-AY2-Am2-K22-K2-Am2(2-A)22-2(A2-)IMQ24-QMI3-A26-A3-ZF26-FZ2-BA26-AB2-BV26-VB-CH4AGAHP2AJ4AC2AKACDL3AUWV2C7B16-6B-C-BAB27-2BArQB24-BQAr5B24-4B2-B26-B226-A30-2A30-A128-A30-AB30-BA30-A32-Ag5-Ah18-Ah5-AgB4-Ah20-Ah4-BAa30-Aa36-A22-A5-Al28-Al3-S26-S4-B26-B3-B-Af24-Af-B-CHFAbAcACAHAC4AJKEAjAG2AAcIGLPQAqE2C7B16-6B-CBWCB27-2BAgAsB24-BAsAg3BAlB24-BAl2B2-B26-B226-A30-2A30-A128-A30-AB30-BA30-A32-B5-A18-A5-2B5-A18-A5-B5-A20-A6-B2-A22-A2(2-B)A26-AB3-2(2A24-2A4-)B26-B4-BA24-AB2-CASX2AFAjAK2AKAUA2G2AO2AKAJAEARZ2C7B16-6B-C2B2A27-4BA24-A6BA24-A7B2(A22-A8B)-2A18-2A-7B3-A18-A3-4B5-A18-A5-3(2B30-)BA30-BA-B26-B-A2B28-3B30-3B28-4B28-3B30-2B30-BA30-2B30-B33-B4-A18-A4-B2-B28-B2-B3-A20-A2(3-B)-A22-A-B4-2BA22-A2B5-A24-A6-A24-A5-B26-B2-CAoAbW2AU2AAiJAO2AKOLARXAHAAn3AAmTAp2C7B16-6B-C3BA27-4BA24-A7B2(A22-A8B)-A20-A-2(8B2-A18-A2-)5B5-AB16-BA5-3B28-3B30-2B2(30-BA)30-AB30-3B28-3BAB26-BA3B28-4B28-3BA28-2(AB)28-2B-B28-B2-B28-B3-B26-2(B4-B3-A18-A3-)B5-B-A20-A-B6-BA22-AB7-A22-A7-A24-A35-CGM3ADJAjAd3ARAOXAUYAGPDALEAAgNE2C7B16-6B-C3BA27-5BA22-A2(8B-A20-A-)8B2-A18-A2-8BA-A18-A-A8B24-5B30-2B2A2-B20-B2-2A2BA3-B20-B3-A2B2A26-2(2AB)26-BAB2AB26-B2ABA2B24-2BA4(2B2A26-2A)2B-A26-2(A-B)26-B-A35-A5-A12-A5-A6-A24-A6-B3-A16-A3-B6-2B-A18-A-2B7-B-A18-A-B8-BA20-AB9-2A18-2A9-A22-A7-A24-A3-2CEAaAAdAWKAK2AY3AAeAjAAeJAjRI2AIGNV2C10B10-9B-CBD2BA26-2BAk2B-A20-A-2BAk2BAb2B-A20-A-2BAb2BA3B2A18-2A3BA5B2-2A16-2A2-8B2-3A14-3A2-8B4-2A12-2A4-6BA2-BA2-2A10-2A2-AB2-A2B2-2A-A20-A-2A4-2A-2A18-2A-2A4-2A-3(A6-)A-2A2-A-2A24-2(2A-)2ABA20-AB2A-A2-3(2A24-2A4-)2AB22-B2A2-A-2AB22-B2A-AB-3A22-3A-BA-2A24-2A-A3-2A8-A4-A8-2A6-2A5-2A8-2A5-2A7-B5-A10-A5-B8-BA3-A12-A3-AB9-B-2A14-2A-B10-2BA16-A2B11-2A16-2A11-A-2A14-2A-A10-A20-A9-A22-A4-CFCL2ADAAjAOYAn3AAeAMAH3AAc3AJAfW2C10B10-9B-CBAk2B-A25-2BN2B2-A18-A2-2BN2BT2B2-2A16-2A2-2BT2BA4B-A16-A-4BA7B2-A14-A2-10B-B3-A12-A3-B-4B3-3A4-12A4-3A5-5A4-10A4-5A4-4A7-6A7-4A4-2(4A8-)4A4-4A20-4A2-A-4A20-4A-2A-4A20-4A-A2-4A20-4A4-4A20-4A5-3A20-3A5-4A20-4A2-A2-2A22-2A2-AB2-2A22-2A2-BA2-3A20-3A2-A3-3A20-3A6-4A5-2(2A-)2A5-4A7-3A5-2A4-2A5-3A10-A4-A8-A4-A12-2A16-2A13-2(2A14-)3A12-3A13-2A-2A10-2A-2A12-A3-4A4-4A3-A11-A20-A5-CUAlAfAKUM3AIFAGAnHLPAeJL2AT2EAcZPA2C12B6-11B-CBS4BA5D8A5D6-8B4AD8AD4A13BA-16A-A12BA-16A-A6B3-3BA2-4A6-4A2-A3B8-BA3-12A3-AB11-A4-D8AD4-A12-A7-4A7-A12-A18-A12-A4-A8-A4-A12-A18-A6-A5-A18-A5-2A5-A18-A5-A6-2(A18-A12-)A18-A8-A2-2A18-2A2(2-A)4-4A14-4A4-AB4-3A16-3A4-BA4-3A16-3A4-A5-4A14-4A11-3A14-3A11-A-2(2A6-)2A-A12-3A2-A-4A-A2-3A15-5A6-5A17-3A8-3A17-7A2-7A16-A2-10A2-A15-A6-4A6-A13-A18-A6-CDAQAGJAX2AAdAAeJFJAeAF3APM3ALEO2C29B-C-8B14D2B8-9B12D9B9-3A10D3A16-5A6D5A16-5A6-5A16-4A-6A-4A14-3(D-4A8-4A-D12-)D-4A-D4-D-4A-D12-D-4A-D4-D-4A-D6-A5-D-5A2-2A2-5A-D5-2A5-D-4A8-4A-D5-A6-3(D-4A8-4A-D12-)D-4A8-4A-D6-A7-4A8-4A7-AB7-4A8-4A7-BA7-4A8-4A7-A9-2(3A8-3A18-)4A2-2D2-4A19-5A2B5A21-4A2B4A23-3A2B3A22-3A2-2A2-3A19-2A10-2A17-2A12-2A15-2A14-2A7-CAkHBRO2AWOAnAiAF3AAdXAU5AWANBAg2CA28BAC-A7-BA10DAB7-A2-A8-3A6D3A8-A2-A9-10A9-A2-A10-8A10-A2-A10-A6-A3(10-A2-A10-8A)10-3(A2-A4-D5-8A5-D4-)A-2A4-D5-8A5-D4-4A4-D6-6A6-D4-2A-A4-D7-4A7-D4-A2-A2(4-D)8A2(D4-)A2-A9-10A9-A2-A10-8A10-A-2A10-8A10-2ABA10-8A10-AB2A10-8A10-2A-2(A10-8A10-A2-)A11-6A11-3(A2-A28-)A2-A11-2A2B2A11-A2-A9-4A2B4A9-A2-A8-3A6-3A8-A2-A7-2A10-2A7-A-CAPAhYXYAAcAFAMALAUAnAAiAEAKGE2AVAoA2C3A6-12B6-3AC-3A7-2B6A2B7-3A2-3A9-6A9-9(3A2-3A24-)3A-B3A24-3AB4A24-4A-3(3A24-3A2-)3A24-3A-4A24-4AB3A24-3AB4A24-4A-8(3A24-3A2-)3A9-2A2B2A9-3A2-3A7-4A2B4A7-3A-C5AF2ATAHEAiAMAY2AAn2AAiDAO4A34C29(30-2C)30-33C
