model
size = 32, scale = 0.05, origin = -y
material 
  colors = A:#F3F B:#F39 C:#FFF D:#FF3 E:#C0F F:#F9F G:#CF3 H:#F00 I:#CCC J:#CC0 K:#F0F L:#F99 M:#CC6 N:#F0C O:#FCF P:#F9C Q:#CFC R:#F96 S:#F90 T:#F69 U:#CF0 V:#FC0 W:#CC3 X:#FC6 Y:#FF6 Z:#F33 Aa:#F3C Ab:#F03 Ac:#F06 Ad:#FCC Ae:#F6F Af:#F63 Ag:#F66 Ah:#FF9 Ai:#CF6 Aj:#CFF Ak:#FF0 Al:#FFC Am:#F6C An:#CF9 Ao:#CC9 Ap:#F30 Aq:#F93 Ar:#F60 As:#FC9 At:#F09 Au:#FC3 Av:#F36 Aw:#CCF
voxels
13-6C365-C30-C192-C389-JAuAcAtORWAsGHXAeLAjXAoMSAdAm16-4C4B4C21-2C6A2C24-6A301-C30-CE30-E128-E30-EC30-CE30-E269-2A2C2A24-4A2C4A15-AaCTYAgAjNRHApFAiMAtPAsXIKApDGAqK6-12C7B9C11-CA10DAC19-3A6D3A21-10A23-8A24-A6-A3(24-8A)18-2(D5-8A5-D12-)D5-8A5-D6-E5-D5-8A5-D5-2E5-D6-6A6-D5-E6-D7-4A7-D12-D4-D8AD4-D17-10A23-8A12-E11-8A11-EC11-8A11-CE11-8A11-E12-8A24-8A25-6A122-2A2C2A24-4A2C4A21-3A6-3A19-2A10-2A11-AeAlAtAvAtCAdJTOAiYAcOArXAwApMHAoAfUHAQGL3-2C26B2C2-8B14D8B2-9B12D9B9-3A10D3A16-5A6D5A16-5A6-5A16-4A-6A-4A14-3(D-4A8-4A-D12-)D-4A-D4-D-4A-D12-D-4A-D4-D-4A-D6-E5-D-5A2-2A2-5A-D5-2E5-D-4A8-4A-D5-E6-3(D-4A8-4A-D12-)D-4A8-4A-D6-E7-4A8-4A7-EC7-4A8-4A7-CE7-4A8-4A7-E9-2(3A8-3A18-)4A2-2D2-4A19-5A2C5A21-4A2C4A23-3A2C3A22-3A2-2A2-3A19-2A10-2A17-2A12-2A15-2A14-2A9-RBAnAqAgFAmAqXApOTINCSAvYArGAsIPAoAmAhFCQ-2C11B6-11B2CBN4BA5D8A5DA4BN8B4AD8AD4A13BA-16A-A12BA-16A-A6B3-3BA2-4A6-4A2-A3B8-BA3-12A3-AB11-A4-D8AD4-A12-A7-4A7-A12-A18-A12-A4-A8-A4-A12-A18-A6-E5-A18-A5-2E5-A18-A5-E6-2(A18-A12-)A18-A8-A2-2A18-2A2-A2-E4-4A14-4A4-EC4-3A16-3A4-CE4-3A16-3A4-E5-4A14-4A11-3A14-3A11-A-2(2A6-)2A-A12-3A2-A-4A-A2-3A15-5A6-5A17-3A8-3A17-7A2-7A16-A2-10A2-A15-A6-4A6-A13-A18-A7-DMJAgUAbFAvAGSNAuAbTAbAuATCFCAeAiIGPAcHAq-2C9B10-9B2CBP2B-A20-A-2BP2BF2B2-A18-A2-2BF2BAj2B2-2A16-2A2-2BAj2BAd4B-A16-A-4BAd7B2-A14-A2-10B-B3-A12-A3-B-4B3-3A4-12A4-3A5-5A4-10A4-5A4-4A7-6A7-4A4-2(4A8-)4A4-4A20-4A2-E-4A20-4A-2E-4A20-4A-E2-4A20-4A4-4A20-4A5-3A20-3A5-4A20-4A2-E2-2A22-2A2-EC2-2A22-2A2-CE2-3A20-3A2-E3-3A20-3A6-4A5-2(2A-)2A5-4A7-3A5-2A4-2A5-3A10-A4-A8-A4-A12-2A16-2A13-2(2A14-)3A12-3A13-2A-2A10-2A-2A12-A3-4A4-4A3-A11-A20-A6-ArY2VAfArAiOYFZTGUXRAcAeAuAbAcAoQAj2HAdIAeAL2C9B10-9B2CBD2BA22-A2BD2BP2B-A20-A-2BP2BO2B-A20-A-2BO2BAp3B2A18-2A3BAp5B2-2A16-2A2-8B2-3A14-3A2-8B4-2A12-2A4-6BA2-BA2-2A10-2A2-AB2-A2B2-2A-A20-A-2A4-2A-2A18-2A-2A4-2A-3(A6-)A-2A2-E-2A24-2A-2E-2ABA20-AB2A-E2-3(2A24-2A4-)2AB22-B2A2-E-2AB22-B2A-EC-3A22-3A-CE-2A24-2A-E3-2A8-A4-A8-2A6-2A5-2A8-2A5-2A7-B5-A10-A5-B8-BA3-A12-A3-AB9-B-2A14-2A-B10-2BA16-A2B11-2A16-2A11-A-2A14-2A-A10-A20-A9-A22-A4-FTWAcKAhDNAkAwAqAtXAaQGAuLAiGRIOAaAdGAoAwAbVAm3C6B16-6B2C3BA24-A7BA22-A2(8B-A20-A-)8B2-A18-A2-8BA-A18-A-A8B24-5B30-2B2A2-B20-B2-2A2BA3-B20-B3-A2B2A26-2A2(BEAB26-BA)EBA2B24-2BA4(2B2A26-2A)BC-A26-A-CE-B26-B-E35-A5-A12-A5-A6-A24-A6-B3-A16-A3-B6-2B-A18-A-2B7-B-A18-A-B8-BA20-AB9-2A18-2A9-A22-A7-A24-A3-FWHAgKSPAmAfYAfVGAtAaFCAuAkAaAuAbAkAnZFIZUFGH2C6B16-6B2C3BA24-A6BA24-A7B2(A22-A8B)-A20-A-2(8B2-A18-A2-)5B5-AB16-BA5-3B28-3B30-2B2(30-BE)30-EB30-3B28-3BAB26-BA3B28-4B28-2BCA28-ACEB28-2B-B28-B2-B28-B3-B26-2(B4-B3-A18-A3-)B5-B-A20-A-B6-BA22-AB7-A22-A7-A24-A35-AjUAiAdQLDAbAkSLPFAnMAqAvAaArAtCUAeDNAcHLQFHAe2C6B16-6B2C2B2A24-2A5B2A23-A6B3A22-A7B2(A22-A8B)-2A18-2A-7B3-A18-A3-4B5-A18-A5-3(2B30-)BE30-BE-B26-B-E2B28-3B30-3B28-4B28-3B30-BC30-CE30-2B30-B33-B4-A18-A4-B2-B28-B2-B3-A20-A2(3-B)-A22-A-B4-2BA22-A2B5-A24-A6-A24-A5-C26-C2-AnLOAmAhNArBAlApAbMAqAgJAfAqAcKAnAvQRNXIGCAaAjAoV-C6B16-6B2CBAmWB24-BWAm2BQAsB24-BAsQ3BYB24-BY2B2-B26-B226-E30-2E30-E128-E30-EC30-CE30-E32-B5-A18-A5-2B5-A18-A5-B5-A20-A6-B2-A22-A2(2-B)A26-AB3-2(2A24-2A4-)C26-C4-CA24-AC2-AhANAvPBTAkAlAfYKAfVArL2UAhAgAqAaMAfAoAbFHMAnIF-C6B16-6B2C-BXB24-BX3BAwJB24-BJAw3BCB24-BC2B2-B26-B226-E30-2E30-E128-E30-EC30-CE30-E32-Q5-Al18-Al5-QC4-Al20-Al4-CAg30-Ag36-Ak22-Ak5-Y28-Y3-N26-N4-C26-C3-C-V24-V-C-AmRTOAdAgWAsRIWAoLKPAbAfHAkVUMYAdZUAcAeJAhHF-C6B16-6B2C-BDB24-BD2(4BAB24-BA)2B2-B26-B226-E30-2E30-E128-E30-EC30-CE30-E65-AtM26-MAt2-Aa2-Af22-Af2-Aa2-S2-K22-K2-S2-ZAiJ24-JAiZ3-K26-K3-IT26-TI2-CAp26-ApC2-CG26-GC-XRXAkAwJUAsRAeAlAsAb2KYAhWAKAfJWDAcQIVArAmGAj-C6B16-6BC2(2-BDB24-BDB)-4B24-4B2-B26-B226-E30-2E30-E128-E30-EC30-CE30-E37-B20-B6-RW2-O20-O2-WR2-LAe-N22-N-AeL2-V-G24-G-V2-HFAv24-AvFH2-2J26-2J3-H26-H3-CAe26-AeC2-C28-C-XOGAfZSLAnZQWCYQAuWSAdAlKAhArHULAaAbFPXFAn-C6B16-5B2C2-BDB24-BDB2-3B24-3B289-E30-2E30-E128-E30-EC30-CE30-E37-Ak20-Ak6-AaM-Ag22-Ag-MAa2-SZ26-ZS2-Z28-Z2-AjN26-NAj2-IAi26-AiI3-B26-B3-CAg26-AgC2-C28-C-MApFAkLAsAAwCAaOAoWAhAdAlLApMQSPAi2PMUFKXAcAh-C6B16-5B2C2(3-2B24-3B)4-B284-E30-2E30-E128-E30-EC30-CE30-E65-AhAb26-AbAh2-UT-F22-F-TU2-AdAoS24-SAoAd2-AcRZ24-ZRAc3-An26-An4-T26-T3-CD26-DC2-C28-C-ArSAqAlCAjRVAqAnVOAlPAmWNJIAhLKOAiAwJQAjAuMIAm-C6B16-5B2C2(3-2B24-3B)4-B284-E30-2E30-E128-E30-EC30-CE30-E65-AhAb26-AbAh2-UT-F22-F-TU2-AdAoS24-SAoAd2-AcRZ24-ZRAc3-An26-An4-T26-T3-CD26-DC2-C28-C-ArSAqAlCAjRVAqAnVOAlPAmWNJIAhLKOAiAwJQAjAuMIAm-C6B16-5B2C2-BDB26-B2-3B24-3B289-E30-2E30-E128-E30-EC30-CE30-E37-Ak20-Ak6-AaM-Ag22-Ag-MAa2-SZ26-ZS2-Z28-Z2-AjN26-NAj2-IAi26-AiI3-B26-B3-CAg26-AgC2-C28-C-MApFAkLAsAAwCAaOAoWAhAdAlLApMQSPAi2PMUFKXAcAh-C6B16-5B2C2-BDB25-2B2-BDB24-BDB-4B24-4B2-B26-B226-E30-2E30-E128-E30-EC30-CE30-E37-B20-B6-RW2-O20-O2-WR2-LAe-N22-N-AeL2-V-G24-G-V2-HFAv24-AvFH2-2J26-2J3-H26-H3-CAe26-AeC2-C28-C-XOGAfZSLAnZQWCYQAuWSAdAlKAhArHULAaAbFPXFAn-C6B16-5B3C-BDB27-3BAB24-BA4BAB24-4B2-B26-B226-E30-2E30-E128-E30-EC30-CE30-E65-AtM26-MAt2-Aa2-Af22-Af2-Aa2-S2-K22-K2-S2-ZAiJ24-JAiZ3-K26-K3-IT26-TI2-CAp26-ApC2-CG26-GC-XRXAkAwJUAsRAeAlAsAb2KYAhWAKAfJWDAcQIVArAmGAj-C6B16-5B3C-BXB27-2BAwJB24-BJAw3BCB24-BC2B2-B26-B226-E30-2E30-E128-E30-EC30-CE30-E32-Q5-Al18-Al5-QC4-Al20-Al4-CAg30-Ag36-Ak22-Ak5-Y28-Y3-N26-N4-C26-C3-C-V24-V-C-AmRTOAdAgWAsRIWAoLKPAbAfHAkVUMYAdZUAcAeJAhHF-C6B16-5B3CBAmWB27-2BQAsB24-BAsQ3BYB24-BY2B2-B26-B226-E30-2E30-E128-E30-EC30-CE30-E32-B5-A18-A5-2B5-A18-A5-B5-A20-A6-B2-A22-A2(2-B)A26-AB3-2(2A24-2A4-)C26-C4-CA24-AC2-AhANAvPBTAkAlAfYKAfVArL2UAhAgAqAaMAfAoAbFHMAnIF2C6B16-5B3C2B2A27-4BA24-A6BA24-A7B2(A22-A8B)-2A18-2A-7B3-A18-A3-4B5-A18-A5-3(2B30-)BE30-BE-B26-B-E2B28-3B30-3B28-4B28-3B30-BC30-CE30-2B30-B33-B4-A18-A4-B2-B28-B2-B3-A20-A2(3-B)-A22-A-B4-2BA22-A2B5-A24-A6-A24-A5-C26-C2-AnLOAmAhNArBAlApAbMAqAgJAfAqAcKAnAvQRNXIGCAaAjAoV2C6B16-5B3C3BA27-4BA24-A7B2(A22-A8B)-A20-A-2(8B2-A18-A2-)5B5-AB16-BA5-3B28-3B30-2B2(30-BE)30-EB30-3B28-3BAB26-BA3B28-4B28-2BCA28-ACEB28-2B-B28-B2-B28-B3-B26-2(B4-B3-A18-A3-)B5-B-A20-A-B6-BA22-AB7-A22-A7-A24-A35-AjUAiAdQLDAbAkSLPFAnMAqAvAaArAtCUAeDNAcHLQFHAe2C6B16-5B3C3BA27-5BA22-A2(8B-A20-A-)8B2-A18-A2-8BA-A18-A-A8B24-5B30-2B2A2-B20-B2-2A2BA3-B20-B3-A2B2A26-2A2(BEAB26-BA)EBA2B24-2BA4(2B2A26-2A)BC-A26-A-CE-B26-B-E35-A5-A12-A5-A6-A24-A6-B3-A16-A3-B6-2B-A18-A-2B7-B-A18-A-B8-BA20-AB9-2A18-2A9-A22-A7-A24-A3-FWHAgKSPAmAfYAfVGAtAaFCAuAkAaAuAbAkAnZFIZUFGH2C9B10-8B3CBD2BA26-2BP2B-A20-A-2BP2BO2B-A20-A-2BO2BAp3B2A18-2A3BAp5B2-2A16-2A2-8B2-3A14-3A2-8B4-2A12-2A4-6BA2-BA2-2A10-2A2-AB2-A2B2-2A-A20-A-2A4-2A-2A18-2A-2A4-2A-3(A6-)A-2A2-E-2A24-2A-2E-2ABA20-AB2A-E2-3(2A24-2A4-)2AB22-B2A2-E-2AB22-B2A-EC-3A22-3A-CE-2A24-2A-E3-2A8-A4-A8-2A6-2A5-2A8-2A5-2A7-B5-A10-A5-B8-BA3-A12-A3-AB9-B-2A14-2A-B10-2BA16-A2B11-2A16-2A11-A-2A14-2A-A10-A20-A9-A22-A4-FTWAcKAhDNAkAwAqAtXAaQGAuLAiGRIOAaAdGAoAwAbVAm3C9B10-8B3CBP2B-A25-2BF2B2-A18-A2-2BF2BAj2B2-2A16-2A2-2BAj2BAd4B-A16-A-4BAd7B2-A14-A2-10B-B3-A12-A3-B-4B3-3A4-12A4-3A5-5A4-10A4-5A4-4A7-6A7-4A4-2(4A8-)4A4-4A20-4A2-E-4A20-4A-2E-4A20-4A-E2-4A20-4A4-4A20-4A5-3A20-3A5-4A20-4A2-E2-2A22-2A2-EC2-2A22-2A2-CE2-3A20-3A2-E3-3A20-3A6-4A5-2(2A-)2A5-4A7-3A5-2A4-2A5-3A10-A4-A8-A4-A12-2A16-2A13-2(2A14-)3A12-3A13-2A-2A10-2A-2A12-A3-4A4-4A3-A11-A20-A5-VArY2VAfArAiOYFZTGUXRAcAeAuAbAcAoQAj2HAdIAeAL2C11B6-10B3CBN4BA5D8A5D6-8B4AD8AD4A13BA-16A-A12BA-16A-A6B3-3BA2-4A6-4A2-A3B8-BA3-12A3-AB11-A4-D8AD4-A12-A7-4A7-A12-A18-A12-A4-A8-A4-A12-A18-A6-E5-A18-A5-2E5-A18-A5-E6-2(A18-A12-)A18-A8-A2-2A18-2A2-A2-E4-4A14-4A4-EC4-3A16-3A4-CE4-3A16-3A4-E5-4A14-4A11-3A14-3A11-A-2(2A6-)2A-A12-3A2-A-4A-A2-3A15-5A6-5A17-3A8-3A17-7A2-7A16-A2-10A2-A15-A6-4A6-A13-A18-A7-DMJAgUAbFAvAGSNAuAbTAbAuATCFCAeAiIGPAcHAq2-C27BC3-8B14D2B8-9B12D9B9-3A10D3A16-5A6D5A16-5A6-5A16-4A-6A-4A14-3(D-4A8-4A-D12-)D-4A-D4-D-4A-D12-D-4A-D4-D-4A-D6-E5-D-5A2-2A2-5A-D5-2E5-D-4A8-4A-D5-E6-3(D-4A8-4A-D12-)D-4A8-4A-D6-E7-4A8-4A7-EC7-4A8-4A7-CE7-4A8-4A7-E9-2(3A8-3A18-)4A2-2D2-4A19-5A2C5A21-4A2C4A23-3A2C3A22-3A2-2A2-3A19-2A10-2A17-2A12-2A15-2A14-2A8-PRBAnAqAgFAmAqXApOTINCSAvYArGAsIPAoAmAhFCQ3-9C10B9C11-CA10DAC19-3A6D3A21-10A23-8A24-A6-A3(24-8A)18-2(D5-8A5-D12-)D5-8A5-D6-E5-D5-8A5-D5-2E5-D6-6A6-D5-E6-D7-4A7-D12-D4-D8AD4-D17-10A23-8A12-E11-8A11-EC11-8A11-CE11-8A11-E12-8A24-8A25-6A122-2A2C2A24-4A2C4A21-3A6-3A19-2A10-2A11-AeAlAtAvAtCAdJTOAiYAcOArXAwApMHAoAfUHAQGL12-4C5B3C21-2C6A2C24-6A301-C30-CE30-E128-E30-EC30-CE30-E269-2A2C2A24-4A2C4A15-AaCTYAgAjNRHApFAiMAtPAsXIKApDGAqK17-6C365-C30-C160-E31-C30-C358-JAuAcAtORWAsGHXAeLAjXAoMSAdAm6-
