model
size = 32 11 11, scale = 0.05, origin = -y
material 
  colors = A:#EEE B:#BBB C:#444 D:#DDD E:#B00 F:#777 G:#D00 H:#888 I:#800 J:#111 K:#0C0 L:#FC3
voxels
123-2CHEC27-CHCEC26-JG2CEH27-CHCEC27-2C2FC187-CHCFI18-2A6B4AEC18-2AB4A2B3AEG17-BD2BD8AEI18-2BAD8AEC18-6D3J3AEF27-CFC2F123-3C2F18-8AJ3AEC18-12AEG12-3B15AEC11-D2A2B14AEF12-2AD3B12AEF18-D11AEC18-2D3A3D4AEI27-CFGHC59-CGCFC18-6B3J3AEG18-12AEC2(2-2A)2-21AI4A2D2-2B2-B18AG4ADB2-BD-B19AF4ADA2-2A2-19AL2(2-2A)2-B20AG18-13AC18-6A2BJ4AC27-CFI2C27-2CHFC18-4B2AD5AEC12-6B12AEI4A2(2D2-)B18AG5-K4A2B19AH5-KDB2AB20AG5-K2B2ADB19AC4ADA2-2A2-19AG12-D5B13AI18-2A3D2B6AG27-CGC2F26-CG2CFC17-2B2DB2D2B4AEG12-2D3B13AEC4ADA2-AB-B19AG5-K2D2AB20AL5-K25AG5-KAD2ADB19AG4ADA2-2D2-19AL11-3B2D15AC17-3BD2ABD6AG26-3C3F27-CHCEC18-3AB2AB5AEF12-3A3B12AEF4ADA2-AB2-19AI5-K25AG5-KB24AC5-KAB2A2D19AL4ADA2-2B2-19AI12-3AD2B13AF18-6BD6AH27-CHICI27-CHFEG18-3A4B5AEC18-12AEF2(2-2A)2-B20AF4ADA2-2B-B18AEL4A2B-2BA2-18AEFAB2ABA2-BD2-B17AEC2-2A2-AB2-2B3A2B13AEC18-12AEC18-B11AEC27-CFCHC59-C4F18-4A3B5AEC18-12AEG12-2A4B12AEF12-3B2D13AEI12-3B15AEF18-12AEF18-B3A5B3AEC27-BGCFH123-3CFC18-7A2J3AEC18-12AEC17-2B5AB5AEC18-2BA3DB5AEC18-7B2J3AEC27-CGCEC187-2(CH)G27-2CI2C26-2CGFHC27-4CG27-C2GCG96-
