model
size = 11 31 30, scale = 0.05, origin = -y
material 
  colors = A:#00E B:#FF0 C:#E00 D:#F09 E:#EEE
voxels
----------- ----------- ----------- ----------- ----------- ----------- ----------- ----------- ----------- ----------- ----------- ----------- ----------- ----------- ----------- ----------- ----------- ----------- ----AAAA--- ----AAAA--- ----AAAA--- ----AAAA--- ----------- ----------- ----------- ----------- ----------- ----------- ----------- ----------- ----------- 
----------- ----------- ----------- ----------- ----------- ----------- ----------- ----------- ----------- ----------- ----------- ----------- ----------- ----------- ----------- ----------- -----AA---- ---AAAAAA-- ---AAAAAA-- --AAAAAAAA- --AAAAAAAA- ---AAAAAA-- ---AAAAAA-- -----AA---- ----------- ----------- ----------- ----------- ----------- ----------- ----------- 
----------- ----------- ----------- ----------- ----------- ----------- ----------- ----------- ----------- ----------- ----------- ----------- ----------- ----------- ----------- ----------- ---AAAAAA-- --AAAAAAAA- --AAAAAAAA- --AAAAAAAA- --AAAAAAAA- --AAAAAAAA- --AAAAAAAA- ---AAAAAA-- ----------- ----------- ----------- ----------- ----------- ----------- ----------- 
----------- ----------- ----------- ----------- ----------- ----------- ----------- ----------- ----------- ----------- ----------- ----------- ----------- ----------- ----------- ----AAAA--- ---AAAAAA-- --AAAAAAAA- -AAAAAAAAAA -AAAAAAAAAA -AAAAAAAAAA -AAAAAAAAAA --AAAAAAAA- ---AAAAAA-- ----AAAA--- ----------- ----------- ----------- ----------- ----------- ----------- 
----------- ----------- ----------- ----------- ----------- ----------- ----------- ----------- ----------- ----------- ----------- ----------- ----------- ----------- ------AA--- ----AAAA--- --AAAAAAAA- --AAAAAAAA- -AAAAAAAAAA -AAAAAAAAAA -AAAAAAAAAA -AAAAAAAAAA --AAAAAAAA- --AAAAAAAA- ----AAAA--- ----------- ----------- ----------- ----------- ----------- ----------- 
----------- ----------- ----------- ----------- ----------- ----------- ----------- ----------- ----------- ----------- ----------- ----------- ----------- ----------- ------A---- ----AAAA--- --AAAAAAAA- --AAAAAAAA- -AAAAAAAAAA -AAAAAAAAAA -AAAAAAAAAA -AAAAAAAAAA --AAAAAAAA- --AAAAAAAA- ----AAAA--- ----------- ----------- ----------- ----------- ----------- ----------- 
----------- ----------- ----------- ----------- ----------- ----------- ----------- ----------- ----------- ----------- ----------- ----------- ----------- ------E---- ----------- ----AAAA--- ---AAAAAA-- --AAAAAAAA- -AAAAAAAAAA -AAAAAAAAAA -AAAAAAAAAA -AAAAAAAAAA --AAAAAAAA- ---AAAAAA-- ----AAAA--- ----------- ----------- ----------- ----------- ----------- ----------- 
----------- ----------- ----------- ----------- ----------- ----------- ----------- ----------- ----------- ----------- ----------- ----------- ----------- ------E---- ----------- ----------- ---AAAAAA-- --AAAAAAAA- --AAAAAAAA- --AAAAAAAA- --AAAAAAAA- --AAAAAAAA- --AAAAAAAA- ---AAAAAA-- ----------- ----------- ----------- ----------- ----------- ----------- ----------- 
----------- ----------- ----------- ----------- ----------- ----------- ----------- ----------- ----------- ----------- ----------- ----------- ------E---- ----------- ----------- ----------- -----AA---- ---AAAAAA-- ---AAAAAA-- --AAAAAAAA- --AAAAAAAA- ---AAAAAA-- ---AAAAAA-- -----AA---- ----------- ----------- ----------- ----------- ----------- ----------- ----------- 
----------- ----------- ----------- ----------- ----------- ----------- ----------- ----------- ----------- ----------- ----------- ----------- -------E--- ----------- ----------- ----------- ----------- ----------- ----AAAA--- ----AAAA--- ----AAAA--- ----AAAA--- ----------- ----------- ----------- ---BB------ --BBBB----- --BBBB----- ---BB------ ----------- ----------- 
----------- ----------- ----------- ----------- ----------- ----------- ----------- ----------- ----------- ----------- ----------- -------E--- ----------- ----------- ----------- ----------- ----------- ----------- ----------- ----------- ----------- ----------- ----------- ----------- --BBBB----- -BBBBBB---- -BBBBBB---- -BBBBBB---- -BBBBBB---- --BBBB----- ----------- 
----------- ----------- ----------- ----------- ----------- ----------- ----------- ----------- ----------- ----------- -------E--- ----------- ----------- ----------- ----------- ----------- ----------- ----------- ----------- ----------- ----------- ----------- ----------- ----------- -BBBBBB---- -BBBBBB---- BBBBBBBB--- BBBBBBBB--- -BBBBBB---- -BBBBBB---- ---BB------ 
----------- ----------- ----------- ----------- ----------- ----------- ----------- ----------- ----------- ----------- -------E--- ----------- ----------- ----------- ----------- ----------- ----------- ---DD------ --DDDD----- --DDDD----- ---DD------ ----------- ----------- --BBBB----- -BBBBBB---- BBBBBBBB--- BBBBBBBB--- BBBBBBBB--- BBBBBBBB--- -BBBBBB---- --BBBB----- 
----------- ----------- ----------- ----------- ----------- ----------- ----------- ----------- ----------- -------E--- ----------- ----------- ----------- ----------- ----------- ----------- --DDDD----- -DDDDDD---- -DDDDDD---- -DDDDDD---- -DDBDDD---- --DDDD----- ----------- --BBBB----- -BBBBBB---- BBBBBBBB--- BBBBBBBB--- BBBBBBBB--- BBBBBBBB--- -BBBBBB---- --BBBB----- 
----------- ----------- ----------- ----------- ----------- ----------- ----------- ----------- -------E--- ----------- ----------- ----------- ----------- ----------- ----------- ---DD------ -DDDDDD---- -DDDDDD---- DDDDDDDD--- DBDDDDDD--- -DBDDDD---- -DDBDDD---- ---EB------ ---BB------ -BBBBBB---- -BBBBBB---- BBBBBBBB--- BBBBBBBB--- -BBBBBB---- -BBBBBB---- ---BB------ 
----------- ----------- ----------- ----------- ----------- ----------- ----------- ----------- --------E-- ----------- ----------- ----------- ----------- ----------- ---D------- --DEED----- -DEEEED---- DDDDDDDD--- DDDDDDDD--- DBDDDDDD--- DBBDDDDD--- -DBBDDD---- --DDDD----- ----------- --BBBB----- -BBBBBB---- -BBBBBB---- -BBBBBB---- -BBBBBB---- --BBBB----- ----------- 
----------- ----------- ----------- ----------- ----------- ----------- ----------- --------E-- ----------- ----------- ----------- ----------- ----------- ----D------ ---DD------ --DEED----- -DEEEED---- DDDDDDDD--- DDDDDDDD--- DBDDDDDD--- DBBDDDDD--- -DBBDDD---- --DDDD----- ----------- ----------- ---BB------ --BBBB----- --BBBB----- ---BB------ ----------- ----------- 
----------- ----------- ----------- ----------- ----------- ----------- ----------- --------E-- ----------- ----------- ----------- ----------- ----E------ ----------- ----------- ---DD------ -DDEEDD---- -DDDDDD---- DDDDDDDD--- DBBDDDDD--- -DBDDDD---- -DDBDDD---- ---DD------ ----------- ----------- ----------- ----------- ----------- ----------- ----------- ----------- 
----------- ----------- ----------- ----------- ----------- ----------- --------E-- ----------- ----------- ----------- ----------- -----E----- ----------- ----------- ----------- ----------- --DDDD----- -DDDDDD---- -DBDDDD---- -DBBDDD---- -DDBDDD---- --DDDD----- ----------- ---CC------ --CCCC----- --CCCC----- ---CC------ ----------- ----------- ----------- ----------- 
----------- ----------- ----------- ----------- ----------- --------E-- ----------- ----------- ----------- ----------- -----E----- ----------- ----------- ----------- ----------- ----------- ----------- ---DD------ --DDDD----- --DDDD----- ---DD------ ----------- --CCCC----- -CCCCCC---- -CCCCCC---- -CCCCCC---- -CCCCCC---- --CCCC----- ----------- ----------- ----------- 
----------- ----------- ----------- ----------- ----------- --------E-- ----------- ----------- ----------- ------E---- ----------- ----------- ----------- ----------- ----------- ----------- ----------- ----------- ----------- ----------- ----------- ---CC------ -CCCCCC---- -CCCCCC---- CCCCCCCC--- CCCCCCCC--- -CCCCCC---- -CCCCCC---- ---CC------ ----------- ----------- 
----------- ----------- ----------- ----------- ---------E- ----------- ----------- ----------- ------E---- ----------- ----------- ----------- ----------- ----------- ----------- ----------- ----------- ----------- ----------- ----C------ ----C------ --CCCC----- -CCCCCC---- CCCCCCCC--- CCCCCCCC--- CCCCCCCC--- CCCCCCCC--- -CCCCCC---- --CCCC----- ----------- ----------- 
----------- ----------- ----------- ---------E- ----------- ----------- ----------- -------E--- ----------- ----------- ----------- ----------- ----------- ----------- ----------- ----------- ----------- -----E----- -----E----- ----------- ----C------ --CCCC----- -CCCCCC---- CCCCCCCC--- CCCCCCCC--- CCCCCCCC--- CCCCCCCC--- -CCCCCC---- --CCCC----- ----------- ----------- 
----------- ----------- ----------- ---------E- ----------- ----------- -------E--- ----------- ----------- ----------- ----------- ----------- ----------- ----------- ------E---- ------E---- -----E----- ----------- ----------- ----------- ----------- ---CC------ -CCCCCC---- -CCCCCC---- CCCCCCCC--- CCCCCCCC--- -CCCCCC---- -CCCCCC---- ---CC------ ----------- ----------- 
----------- ----------- ---------E- ----------- ----------- --------E-- ----------- ----------- ----------- ----------- ----------- ----------- -------E--- ------E---- ----------- ----------- ----------- ----------- ----------- ----------- ----------- ----------- --CCCC----- -CCCCCC---- -CCCCCC---- -CCCCCC---- -CCCCCC---- --CCCC----- ----------- ----------- ----------- 
----------- ----------- ---------E- ----------- --------E-- ----------- ----------- ----------- ----------- --------E-- -------E--- -------E--- ----------- ----------- ----------- ----------- ----------- ----------- ----------- ----------- ----------- ----------- ----------- ---CC------ --CCCC----- --CCCC----- ---CC------ ----------- ----------- ----------- ----------- 
----------- ----------- ----------- ---------E- ----------- ----------- ----------- ---------E- --------E-- ----------- ----------- ----------- ----------- ----------- ----------- ----------- ----------- ----------- ----------- ----------- ----------- ----------- ----------- ----------- ----------- ----------- ----------- ----------- ----------- ----------- ----------- 
----------- ----------- ---------E- ----------E ----------E ---------E- ---------E- ----------- ----------- ----------- ----------- ----------- ----------- ----------- ----------- ----------- ----------- ----------- ----------- ----------- ----------- ----------- ----------- ----------- ----------- ----------- ----------- ----------- ----------- ----------- ----------- 
----------- ----------E ----------E ----------- ----------- ----------- ----------- ----------- ----------- ----------- ----------- ----------- ----------- ----------- ----------- ----------- ----------- ----------- ----------- ----------- ----------- ----------- ----------- ----------- ----------- ----------- ----------- ----------- ----------- ----------- ----------- 
----------E ----------- ----------- ----------- ----------- ----------- ----------- ----------- ----------- ----------- ----------- ----------- ----------- ----------- ----------- ----------- ----------- ----------- ----------- ----------- ----------- ----------- ----------- ----------- ----------- ----------- ----------- ----------- ----------- ----------- ----------- 
