model
size = 30 27 9, scale = 0.05, origin = -y
material 
  colors = A:#FFF B:#050000 C:#000 D:#9BADB7 E:#FBF236 F:#080808 G:#F3ECEC
voxels
BBBBBBBBBBBBBBBBBBBBBBBBBBBBBB BBBBBBBBBBBBBBBBBBBBBBBBBBBBBB BBBBBBBBBBBBBBBBBBBBBBBBBBBBBB BBBBBBBBBBBBBBBBBBBBBBBBBBBBBB BBBBBBBBBBBBBBBBBBBBBBBBBBBBBB BBBBBBBBBBBBBBBBBBBBBBBBBBBBBB BBBBBBBBBBBBBBBBBBBBBBBBBBBBBB BBBBBBBBBBBBBBBBBBBBBBBBBBBBBB BBBBBBBBBBBBBBBBBBBBBBBBBBBBBB BBBBBBBBBBBBBBBBBBBBBBBBBBBBBB BBBBBBBBBBBBBBBBBBBBBBBBBBBBBB BBBBBBBBBBBBBBBBBBBBBBBBBBBBBB BBBBBBBBBBBBBBBBBBBBBBBBBBBBBB BBBBBBBBBBBBBBBBBBBBBBBBBBBBBB BBBBBBBBBBBBBBBBBBBBBBBBBBBBBB BBBBBBBBBBBBBBBBBBBBBBBBBBBBBB BBBBBBBBBBBBBBBBBBBBBBBBBBBBBB BBBBBBBBBBBBBBBBBBBBBBBBBBBBBB BBBBBBBBBBBBBBBBBBBBBBBBBBBBBB BBBBBBBBBBBBBBBBBBBBBBBBBBBBBB BBBBBBBBBBBBBBCCBBBBBCCCBBBBBB ------------------------------ ------------------------------ ------------------------------ ------------------------------ ------------------------------ ------------------------------ 
BBBBBBBBBBBBBBBBBBBBBBBBBBBBBB BAAAAAAAAAAAAAABABAAAAAAAAAAAB BAAAAAAAAAAAAAAAAAAAAAAAAABAAB BAAAAAAAAAAAAAAAAAAAAAAAAAAAAB BAAAAAAAAAAAAAAAAAAAAAAAAAAAAB BAAAAAAAAAAAAAAAAAAAAAAAAAAAAB BAAAAAAAAAAAAAAAAAAAAAAAAAAAAB BAAAAAAAAAAAAAAAAAAAAAAAAAAAAB BAAAAAAAAAAAAAAAAAAAAAAAAAAAAB BAAAAAAAAAAAAAAAAAAAAAAAAAAAAB BAAAAAAAAAAAAAAAAAAAAAAAAAAAAB BAAAAAAAAAAAAAAAAAAAAAAAAAAAAB BAAAAAAAAAAAAAAAAAAAAAAAAAAAAB BAAAAAAAAAAAAAAAAAAAAAAAAAAAAB BAAAAAAAAAAAAAAAAAAAAAAAAAAAAB BAAAAAAAAAAAAAAAAAAAAAAAAAAAAB BAAAAAAAAAAAAAAAAAAAAAAAAAAAAB BAAAAAAAAAAAAAAAAAAAAAAAAAAAAB BAAAAAAAAAAAAAAAAAAAAAAAAAAAAB BBAAABAAAAAAAAAAAAAAAAAAAAAAAB BBBBBBBBBBBBCCBBBBBBBBCCBBBBBB ------------------------------ ------------------------------ ------------------------------ ------------------------------ ------------------------------ ------------------------------ 
BBBBBBBBBBBBBBBBBBBBBBBBBBBBBB BAAAAAAAAAAAAAABABAAAAAAAABAAB BAAAAAAAAAAAAAAAAAAAAAAAAAAAAB BAAAAAAAAAAAAAAAAAAAAAAAAAAAAB BAAAAAAAAAAAAAAAAAAAAAAAAAAAAB BAAAAAAAAAAAAAAAAAAAAAAAAAAAAB BAAAAAAAAAAAAAAAAAAAAAAAAAAAAB BAAAAAAAAAAAAAAAAAAAAAAAAAAAAB BAAAAAAAAAAAAAAAAAAAAAAAAAAAAB BAAAAAAAAAAAAAAAAAAAAAAAAAAAAB BAAAAAAAAAAAAAAAAAAAAAAAAAAAAB BAAAAAAAAAAAAAAAAAAAAAAAAAAAAB BAAAAAAAAAAAAAAAAAAAAAAAAAAAAB BAAAAAAAAAAAAAAAAAAAAAAAAAAAAB BAAAAAAAAAAAAAAAAAAAAAAAAAAAAB BAAAAAAAAAAAAAAAAAAAAAAAAAAAAB BAAAAAAAAAAAAAAAAAAAAAAAAAAAAB BAAAAAAAAAAAAAAAAAAAAAAAAAAAAB BAAAAAAAAAAAAAAAAAAAAAAAAAAAAB BBAAABAAAAAAAAAAAAAAAAAAAAAAAB BBBBBBCFBBBBBBBBBBBBBCCCCBBBBB ------------------------------ ------------------------------ ------------------------------ ------------------------------ ------------------------------ ------------------------------ 
BBBBBBBBBBBBBBBBBBBBBBBBBBBBBB BAAAAAAAAAAAAAAAAAAAAAAAAABAAB BAAAAAAAAAAAAAAAAAAAAAAAAAAAAB BAAAAAAAAAAAAAAAAAAAAAAAAAAAAB BAAAAAAAAAAAAAAAAAAAAAAAAAAAAB BAAAAAAAAAAAAAAAAAAAAAAAAAAAAB BAAAAAAAAAAAAAAAAAAAAAAAAAAAAB BAAAAAAAAAAAAAAAAAAAAAAAAAAAAB CAAAAAAAAAAAAAAAAAAAAAAAAAAAAB CAAAAAAAAAAAAAAAAAAAAAAAAAAAAB BAAAAAAAAAAAAAAAAAAAAAAAAAAAAB BAAAAAAAAAAAAAAAAAAAAAAAAAAAAB BAAAAAAAAAAAAAAAAAAAAAAAAAAAAB BAAAAAAAAAAAAAAAAAAAAAAAAAAAAB BAAAAAAAAAAAAAAAAAAAAAAAAAAAAB BAAAAAAAAAAAAAAAAAAAAAAAAAAAAB BAAAAAAAAAAAAAAAAAAAAAAAAAAAAB BAAAAAAAAAAAAAAAAAAAAAAAAAAAAB BAAAAAAAAAAAAAAAAAAAAAAAAAAAAB BBAAAAAAAAAAAAAAAAAAAAAAAAAAAB BBBBBBCAABBBBBBBBBBBBACCCBBBBB ------EEEEE--------EEEEE------ -------ECE----------ECE------- -------CCC----------CCC------- -------CBC----------CBC------- -------CBFCCCCCCCCCCFBC------- --------CCBBBBBBBBBBFC-------- 
BBBBBBBBBBBBBBBBBBBBBBBBBBBBBC CAAAAAAAAAAAAAAAAAAAAAAAAABAAC CAAAAAAAAAAAAAAAAAAAAAAAAAAAAC CAAAAAAAAAAAAAAAAAAAAAAAAAAAAC CAAAAAAAAAAAAAAAAAAAAAAAAAAAAC CAAAAAAAAAAAAAAAAAAAAAAAAAAAAC CAAAAAAAAAAAAAAAAAAAAAAAAAAAAC CAAAAAAAAAAAAAAAAAAAAAAAAAAAAC CAAAAAAAAAAAAAAAAAAAAAAAAAAAAC CAAAAAAAAAAAAAAAAAAAAAAAAAAAAC CAAAAAAAAAAAAAAAAAAAAAAAAAAAAC CAAAAAAAAAAAAAAAAAAAAAAAAAAAAC CAAAAAAAAAAAAAAAAAAAAAAAAAAAAC CAAAAAAAAAAAAAAAAAAAAAAAAAAAAC CAAAAAAAAAAAAAAAAAAAAAAAAAAAAC CAAAAAAAAAAAAAAAAAAAAAAAAAAAAC CAAAAAAAAAAAAAAAAAAAAAAAAAAAAC CAAAAAAAAAAAAAAAAAAAAAAAAAAAAC CAAAAAAAAAAAAAAAAAAAAAAAAAAAAC CBAAAAAAAAAAAAAAAAAAAAAAAAAAAC CCCCCCCAABBCCCCCCCCCBACCCCCCCC ------ECBCE--------ECBCE------ -------EEE----------EEE------- -------CCC----------CCC------- -------CBC----------CBC------- -------CBGCCCCCCCCCCGBC------- --------CBCBBBBBBBBBCC-------- 
BBBBBBBBBBBBBBBBBBBBBBBBBBBBBB BAAAAAAAABAAAAABAAAAAAAAAAAAAB BAAAAAAAAAAAAAAAAAAAAAAAAAAAAB BAAAAAAAAAAAAAAAAAAAAAAAAAAAAB BAAAAAAAAAAAAAAAAAAAAAAAAAAAAB BAAAAAAAAAAAAAAAAAAAAAAAAAAAAB BAAAAAAAAAAAAAAAAAAAAAAAAAAAAB BAAAAAAAAAAAAAAAAAAAAAAAAAAAAB BAAAAAAAAAAAAAAAAAAAAAAAAAAAAB CAAAAAAAAAAAAAAAAAAAAAAAAAAAAB CAAAAAAAAAAAAAAAAAAAAAAAAAAAAB BAAAAAAAAAAAAAAAAAAAAAAAAAAAAB BAAAAAAAAAAAAAAAAAAAAAAAAAAAAB BAAAAAAAAAAAAAAAAAAAAAAAAAAAAB BAAAAAAAAAAAAAAAAAAAAAAAAAAAAB BAAAAAAAAAAAAAAAAAAAAAAAAAAAAB BAAAAAAAAAAAAAAAAAAAAAAAAAAAAB BAAAAAAAAAAAAAAAAAAAAAAAAAAAAB BAAAAAAAAAAAAAAAAAAAAAAAAAAAAB BAABAAAAAAAAAAAAAAAAAAAAAAAAAB BBBBBBCAABBBBBBBBBBCBAABCCBBBB --EE--EEEEE--------EEEEE--EE-- -------ECE----------ECE------- -------CCC----------CCC------- -------CBC----------CBC------- -------CBFCCCCCCCCCCFBC------- --------CBBCBBBBBBBBCC-------- 
BBBBBBBBBBBBBBBBBBBBBBBBBBBBBB DAAAAAAAAABAAAABBAAAAAAAAAAAAD DAAAAAAAAAAAAAAAAAAAAAAAAAAAAD DAAAAAAAAAAAAAAAAAAAAAAAAAAAAD DAAAAAAAAAAAAAAAAAAAAAAAAAAAAD DAAAAAAAAAAAAAAAAAAAAAAAAAAAAD DAAAAAAAAAAAAAAAAAAAAAAAAAAAAD DAAAAAAAAAAAAAAAAAAAAAAAAAAAAD DAAAAAAAAAAAAAAAAAAAAAAAAAAAAD DAAAAAAAAAAAAAAAAAAAAAAAAAAAAD DAAAAAAAAAAAAAAAAAAAAAAAAAAAAD DAAAAAAAAAAAAAAAAAAAAAAAAAAAAD DAAAAAAAAAAAAAAAAAAAAAAAAAAAAD DAAAAAAAAAAAAAAAAAAAAAAAAAAAAD DAAAAAAAAAAAAAAAAAAAAAAAAAAAAD DAAAAAAAAAAAAAAAAAAAAAAAAAAAAD DAAAAAAAAAAAAAAAAAAAAAAAAAAAAD DAAAAAAAAAAAAAAAAAAAAAAAAAAAAD DAAAAAAAAAAAAAAAAAAAAAAAAAAAAD DBAABAAAAAAAAAAAAAAAAAAAAAAAAD DDDDDDDDDDDDDDDDDDDDDDDDDDDDDD --EE----------------------EE-- ------------------------------ ------------------------------ ------------------------------ ------------------------------ ------------------------------ 
BBBBBBBBBBBBBBBBBBBBBBBBBBBBBB BAAAAAAAAAABAAAABBBAAAAAAAAAAB BAAAAAAAAAABAAAABBAAAAAAAAAAAB BAAAAAAAAAAAAAAAAAAAAAAAAAAAAB BAAAAAAAAAAAAAAAAAAAAAAAAAAAAB BAAAAAAAAAAAAAAAAAAAAAAAAAAAAB BAAAAAAAAAAAAAAAAAAAAAAAAAAABB BAAAAAAAAAAAAAAAAAAAAAAAAAAAAB BAAAAAAAAAAAAAAAAAAAAAAAAAAAAB BAAAAAAAAAAAAAAAAAAAAAAAAAAAAB BAAAAAAAAAAAAAAAAAAAAAAAAAAAAB BAAAAAAAAAAAAAAAAAAAAAAAAAAAAB BAAAAAAAAAAAAAAAAAAAAAAAAAAAAB BAAAAAAAAAAAAAAAAAAAAAAAAAAAAB BAAAAAAAAAAAAAAAAAAAAAAAAAAAAB BAAAAAAAAAAAAAAAAAAAAAAAAAAAAB BAAAAAAAAAAAAAAAAAAAAAAAAAAAAB BAAAAAAAAAAAAAAAAAAAAAAAAAAAAB BAAAAAAAAAAAAAAAAAAAAAAAAAAAAB BABAABAAAAAAAAAAAAAAAAAABBAAAB BBBBBBCBBBBBBBBBBBBBBBBBBBCBBB --EE----------------------EE-- ------------------------------ ------------------------------ ------------------------------ ------------------------------ ------------------------------ 
BBBBBBBBBBBBBBBBBBBBBBBBBBBBBB BBBBBBBBBBBBBCCCBBBBBBBBBBBBBB BBBBBBBBBBBBCCCCCBBBBBBBBBBBBB BBBBBBBBBBCCCCCCCCCBBBBBBBBBBB BBBBBBBBBBCCCCCCCCCBBBBBBBBBBB BBBBBBBBBCCCCCCCCCCCCBBBBBBBBB BBBBBBBBCCCCCCCCCCCCCBBBBBBBBB BBBBBBBCCCCCCCCCCCCCCCCBBBBBBB BBBBBBCCCCCCCCCCCCCCCCCBBBBBBB BBBBBBCCCCCCCCCCCCCCCCCBBBBBBB BBBBBBCCCCCCCCCCCCCCCCCBBBBBBB BBBBBBCCCCCCCCCCCCCCCCCBBBBBBB BBBBBBCCCCCCCCCCCCCCCCCBBBBBBB BBBBBBBCCCCCCCCCCCCCCCBBBBBBBB BBBBBBBCCCCCCCCCCCCCCCBBBBBBBB BBBBBBBBBCCCCCCCCCCCBBBBBBBBBB BBBBBBBBBCBCCCCCCCCCBBBBBBBBBB BBBBBBBBBBBBCCCCCCCBBBBBBBBBBB BBBBBBBBBBBBCCCCCCBBBBBBBBBBBB BBBBBBBBBBBBBCCCCBBBBBBBBBBBBB BBBBBBCBBBBBBBCCBBBBBBBBBBBBBB ------------------------------ ------------------------------ ------------------------------ ------------------------------ ------------------------------ ------------------------------ 
