model
size = 31 5 31, scale = 0.05, origin = -y
material 
  colors = A:#C00 B:#001 C:#6F6
voxels
-------------AAA-AA------------ -------------A-A-A------------- -------------A-A-AA------------ -------------A-A-A------------- -------------AAA-AA------------ 
---------BBB-------A-A--------- -----------B-------A-A--------- ---------BBB---------A--------- ---------B---------A-A--------- ---------BBB-------A-A--------- 
-------B--------------AA------- -------B----------------------- -------B--------------AA------- -------B----------------------- -------B--------------AA------- 
------------------------------- ------------------------------- ------------------------------- ------------------------------- ------------------------------- 
------------------------------- -----B------------------------- -----B-------------------A----- -----B-------------------A----- -------------------------A----- 
----B---------------------A---- --------------------------A---- --------------------------A---- ------------------------------- ----B-------------------------- 
---B--------------------------- ---B--------------------------- ---B-----------------------A--- ---B-----------------------A--- ---B-----------------------A--- 
------------------------------- ------------------------------- ------------------------------- ------------------------------- ------------------------------- 
------------------------------- ------------------------------- --C-------------------------C-- ------------------------------- ------------------------------- 
------------------------------- ------------------------------- ------------------------------- ------------------------------- ------------------------------- 
-----------------------------B- -----------------------------B- -A---------------------------B- -A---------------------------B- -A---------------------------B- 
-A---------------------------B- -A----------------------------- -A----------------------------- ------------------------------- -----------------------------B- 
------------------------------- ------------------------------B A-----------------------------B A-----------------------------B A------------------------------ 
------------------------------- ------------------------------- ------------------------------- ------------------------------- ------------------------------- 
A-----------------------------B ------------------------------B A-----------------------------B ------------------------------B A-----------------------------B 
A------------------------------ ------------------------------- A------------------------------ ------------------------------- A------------------------------ 
A-----------------------------B A------------------------------ A-----------------------------B A-----------------------------B A-----------------------------B 
------------------------------B ------------------------------- ------------------------------B ------------------------------- ------------------------------B 
A-----------------------------B A-----------------------------B ------------------------------B A------------------------------ A-----------------------------B 
-A----------------------------- ------------------------------- -A----------------------------- ------------------------------- -A----------------------------- 
-A---------------------------A- -A---------------------------A- -A---------------------------A- -A---------------------------A- -A---------------------------A- 
-----------------------------A- ------------------------------- ------------------------------- ------------------------------- -----------------------------A- 
--A-------------------------A-- --A-------------------------A-- --A-------------------------A-- --A-------------------------A-- --A-------------------------A-- 
--A---------------------------- ------------------------------- ------------------------------- ------------------------------- --A---------------------------- 
---A-----------------------A--- ---A-----------------------A--- ---A-----------------------A--- ---A-----------------------A--- ---A-----------------------A--- 
--------------------------A---- ------------------------------- --------------------------A---- ------------------------------- --------------------------A---- 
-----B-------------------A----- -----B-------------------A----- -----B------------------------- -------------------------A----- -----B-------------------A----- 
------B------------------------ ------------------------------- ------B------------------------ ------------------------------- ------B------------------------ 
-------B--------------AA------- -----------------------A------- -------B--------------AA------- -------B---------------A------- -------B--------------AA------- 
---------B-----------A--------- ---------B-B------------------- ---------B-B-------A-A--------- ---------B-B-------A----------- ---------B---------A-A--------- 
------------BB----A------------ -------------B----A------------ -------------B-C-AA------------ -------------B---A------------- ------------BB---A------------- 
