model
size = 27 28 21, scale = 0.05, origin = -y
material 
  colors = A:#316A4D B:#25AA23 C:#3C3C8B D:#0A0A0A E:#007
voxels
--------------------------- --------------------------- --------------------------- --------------------------- --------------------------- --------------------------- --------------------------- --------------------------- --------------------------- --------------------------- -------------------------BB -------------------------BB -------------------------DD -------------------------DD -------------------------BB -------------------------BB -------------------------DD -------------------------DD -------------------------BB --------------------------- --------------------------- --------------------------- --------------------------- --------------------------- --------------------------- --------------------------- --------------------------- --------------------------- 
--------------------------- --------------------------- --------------------------- --------------------------- --------------------------- --------------------------- --------------------------- --------------------------- --------------------------- -------------------------BB -------------------------BB ------------------------BBB ------------------------BBB ------------------------BBB ------------------------BBB ------------------------BBB ------------------------BBB ------------------------BBB -------------------------BB -------------------------BB --------------------------- --------------------------- --------------------------- --------------------------- --------------------------- --------------------------- --------------------------- --------------------------- 
--------------------------- --------------------------- --------------------------- --------------------------- --------------------------- --------------------------- --------------------------- --------------------------- -------------------------BB ------------------------AB- ------------------------AB- ------------------------AB- -----------------------BAB- -----------------------BAB- -----------------------BAB- -----------------------BAB- -----------------------BAB- ------------------------AB- ------------------------AB- -------------------------BB -------------------------BB --------------------------- --------------------------- --------------------------- --------------------------- --------------------------- --------------------------- --------------------------- 
--------------------------- --------------------------- --------------------------- --------------------------- --------------------------- --------------------------- --------------------------- -------------------------BB ------------------------ABB ------------------------AB- -----------------------BAAA -----------------------BAAA -----------------------BAAA -----------------------BAB- -----------------------BAAA -----------------------BAAA -----------------------BAAA -----------------------BAAA -----------------------BAAA ------------------------AB- ------------------------ABB -------------------------BB --------------------------- --------------------------- --------------------------- --------------------------- --------------------------- --------------------------- 
---------BBBBBBBB---------- -------BB--------BBB------- -----BB-------------BB----- ----B-----------------B---- ---B-------------------BB-- --B---------------------BB- -B-----------------------BB -B----------------------ABB BB----------------------AB- BA---------------------BAB- BA---------------------BAAA BA---------------------BAC- BA--------------------AAAAA BA--------------------AAAB- BA--------------------AAAAA BA--------------------AAACC BA--------------------AAAB- BA---------------------BACC BA---------------------BAB- BB---------------------BAAA -B----------------------AB- -B----------------------ABB --B----------------------BB ---B-------------------ABAB ----B-----------------B---- -----BB-------------BB----- -------BB--------BBB------- ---------BBBBBBBB---------- 
---------AAAAAAAA---------- -------AA--------AAA------- -----AA-------------AA----- ----A-----------------A---- ---A-------------------AA-- --A---------------------BAB -A----------------------ABB -A----------------------AB- AA---------------------BAB- AA---------------------BAB- A----------------------BAAA AA--------------------AAAAA A---------------------AAAAA AA---------------------EAB- A---------------------AAAAA AA---------------------EAB- A---------------------AAACC AA--------------------AAAB- AA---------------------BAB- AA---------------------BAB- -A---------------------BAAA -A----------------------AB- --A---------------------ABB ---A-------------------AABB ----A-----------------A---- -----AA-------------AA----- -------AA--------AAA------- ---------AAAAAAAA---------- 
---------BBBBBBBB---------- -------BA--------ABB------- -----BA-------------BA----- ----A-----------------B---- ---B-------------------AB-- --A---------------------BBB -B----------------------AAB -A----------------------AB- AB---------------------BAB- BA---------------------BAB- BA--------------------AAAB- BA--------------------AAAB- BA--------------------AAAB- BA--------------------AAAB- BA--------------------AAAAA BA--------------------AAACC BA--------------------AAAB- BA--------------------AAACC BB--------------------AAAB- AB---------------------BAB- -A---------------------BAAA -B----------------------AB- --A---------------------ABB ---B-------------------ABAB ----A-----------------B---- -----BA-------------BA----- -------BA--------BAB------- ---------BABBBBAB---------- 
---------BBBBBBBB---------- -------BA--------ABB------- -----BA-------------BA----- ----A-----------------B---- ---B-------------------AB-- --A---------------------ABB -B----------------------ABB -A---------------------BAB- AB---------------------BAB- AA--------------------AAAAA AA--------------------AAAAA A---------------------AAAAA AA--------------------AAAB- A---------------------AAAB- AA--------------------AAAAA A---------------------AAAB- AA--------------------AAACC AA--------------------AAAB- AB--------------------AAAB- AB--------------------AAAB- -A---------------------BAAA -B---------------------BAB- --A---------------------ABB ---B-------------------AABB ----A-----------------B---- -----BA-------------BA----- -------BA--------BAB------- ---------BABBBBAB---------- 
---------AAAAAAAA---------- -------AA--------AAA------- -----AA-------------AA----- ----A-----------------A---- ---A-------------------AA-- --A---------------------AAB -A----------------------AAB -A---------------------BAB- AA---------------------BAAA BB--------------------AAAC- AA--------------------AAAAA BA---------------------EAAA BA--------------------AAAAA BA---------------------EAB- BA--------------------AAAAA BA---------------------EAAA BA--------------------AAAAA AB---------------------EAAA BA--------------------AAAAA AA--------------------AAAAA -A---------------------BAAA -A---------------------BAB- --A---------------------ABB ---A-------------------ABAB ----A-----------------A---- -----AA-------------AA----- -------AA--------AAA------- ---------AAAAAAAA---------- 
---------BBBBBBBB---------- -------BB--------BBB------- -----BB-------------BB----- ----B-----------------B---- ---B-------------------BB-- --B---------------------ABB -B----------------------ABB -B---------------------BAB- BA---------------------BAAA BA--------------------AAAAA BB--------------------AAAC- BB--------------------AAAAA -A--------------------AAAAA BB--------------------AAAB- -A--------------------AAAB- BB--------------------AAAB- -A--------------------AAAB- BA--------------------AAAB- BA--------------------AAAB- BA--------------------AAAB- -B---------------------BAB- -B---------------------BAB- --B---------------------ABB ---B-------------------BABB ----B-----------------B---- -----BB-------------BB----- -------BB--------BBB------- ---------BBBBBBBB---------- 
---------AAAAAAAA---------- -------AA--------AAA------- -----AA-------------AA----- ----A-----------------A---- ---A-------------------AA-- --A---------------------BAB -A----------------------BAB -A---------------------BBB- AA---------------------BBAA BB--------------------AABAA AA--------------------AABAA BA--------------------AABAA BA--------------------AABAA BA--------------------AABB- BA--------------------AAC-- BA--------------------AABB- BA--------------------AABB- AB--------------------AABB- BA--------------------AABB- AA--------------------AABB- -A---------------------BC-- -A---------------------BC-- --A---------------------BBB ---A-------------------ABAB ----A-----------------A---- -----AA-------------AA----- -------AA--------AAA------- ---------AAAAAAAA---------- 
---------BBBBBBBB---------- -------BA--------ABB------- -----BA-------------BA----- ----A-----------------B---- ---B-------------------AB-- --A---------------------ABB -B----------------------ABB -A---------------------BAB- AB---------------------BAB- AA--------------------AAAAA AA--------------------AAAAA A----------------------EAAA AA--------------------AAAB- A----------------------EAB- AA--------------------AAAB- A----------------------EAB- AA--------------------AAAAA AA---------------------EAAA AB--------------------AAAAA AB--------------------AAAB- -A---------------------BAB- -B---------------------BC-- --A---------------------ABB ---B-------------------AABB ----A-----------------B---- -----BA-------------BA----- -------BA--------BAB------- ---------BABBBBAB---------- 
---------BBBBBBBB---------- -------BA--------ABB------- -----BA-------------BA----- ----A-----------------B---- ---B-------------------AB-- --A---------------------ABB -B----------------------AAB -A---------------------BAB- AB---------------------BAB- BA--------------------AAAB- BA--------------------AAAB- BA--------------------AAAB- BA--------------------AAAB- BA--------------------AAAB- BA--------------------AAAB- BA--------------------AAAAA BA--------------------AAAAA BA--------------------AAAAA BB--------------------AAAAA AB--------------------AAAAA -A---------------------BAB- -B---------------------BAB- --A---------------------ABB ---B-------------------ABAB ----A-----------------B---- -----BA-------------BA----- -------BA--------BAB------- ---------BABBBBAB---------- 
---------AAAAAAAA---------- -------AA--------AAA------- -----AA-------------AA----- ----A-----------------A---- ---A-------------------AA-- --A---------------------AAB -A----------------------ABB -A----------------------AB- AA---------------------BAB- AA---------------------B-AA A---------------------AAAAA AA--------------------AAAAA A---------------------AAAB- AA--------------------AAAB- A---------------------AAAAA AA--------------------AAAAA A---------------------AAAAA AA--------------------AAAAA AA--------------------AAAC- AA---------------------BAAA -A---------------------BAAA -A----------------------AB- --A---------------------ABB ---A-------------------AABB ----A-----------------A---- -----AA-------------AA----- -------AA--------AAA------- ---------AAAAAAAA---------- 
---------BBBBBBBB---------- -------BB--------BBB------- -----BB-------------BB----- ----B-----------------B---- ---B-------------------BB-- --B---------------------BBB -B----------------------AAB -B----------------------AB- BB---------------------BAAA BA---------------------B-AA BA---------------------BAAA BA--------------------AAAAA BA--------------------AAAAA BA---------------------EAB- BA--------------------AAAAA BA---------------------EAC- BA--------------------AAAC- BA--------------------AAAC- BA---------------------BAAA BB---------------------BAAA -B---------------------BAAA -B----------------------AB- --B---------------------ABB ---B-------------------ABAB ----B-----------------B---- -----BB-------------BB----- -------BB--------BBB------- ---------BBBBBBBB---------- 
--------------------------- --------------------------- --------------------------- --------------------------- --------------------------- --------------------------- ------------------------ABB ------------------------ABB ------------------------AAA -----------------------BAAA -----------------------BAC- -----------------------BAAA ----------------------AAAAA ----------------------AAAB- ----------------------AAAAA ----------------------AAAAA ----------------------AAAAA -----------------------BAAA -----------------------BAAA -----------------------BAAA ------------------------AAA ------------------------AB- ------------------------ABB --------------------------- --------------------------- --------------------------- --------------------------- --------------------------- 
--------------------------- --------------------------- --------------------------- --------------------------- --------------------------- --------------------------- --------------------------- ------------------------ABB ------------------------AAB ------------------------AC- -----------------------BAAA -----------------------BAAA -----------------------BAAA -----------------------BAB- -----------------------BAB- -----------------------BAAA -----------------------BAAA -----------------------BAAA -----------------------BAAA ------------------------AAA ------------------------AB- ------------------------ABB --------------------------- --------------------------- --------------------------- --------------------------- --------------------------- --------------------------- 
--------------------------- --------------------------- --------------------------- --------------------------- --------------------------- --------------------------- --------------------------- --------------------------- ------------------------ABB ------------------------AAB ------------------------AAB ------------------------BAA -----------------------BBB- -----------------------BBB- -----------------------BBB- -----------------------BBB- -----------------------BBAA ------------------------BAA ------------------------AAA ------------------------AB- ------------------------ABB --------------------------- --------------------------- --------------------------- --------------------------- --------------------------- --------------------------- --------------------------- 
--------------------------- --------------------------- --------------------------- --------------------------- --------------------------- --------------------------- --------------------------- --------------------------- --------------------------- ------------------------ABB ------------------------ABB ------------------------ABB ------------------------BB- ------------------------BB- ------------------------BB- ------------------------BB- ------------------------BB- ------------------------AB- ------------------------ABB ------------------------ABB --------------------------- --------------------------- --------------------------- --------------------------- --------------------------- --------------------------- --------------------------- --------------------------- 
--------------------------- --------------------------- --------------------------- --------------------------- --------------------------- --------------------------- --------------------------- --------------------------- --------------------------- --------------------------- --------------------------- ------------------------ABB ------------------------ABB ------------------------ABB ------------------------ABB ------------------------ABB ------------------------ABB ------------------------ABB --------------------------- --------------------------- --------------------------- --------------------------- --------------------------- --------------------------- --------------------------- --------------------------- --------------------------- --------------------------- 
--------------------------- --------------------------- --------------------------- --------------------------- --------------------------- --------------------------- --------------------------- --------------------------- --------------------------- --------------------------- --------------------------- --------------------------- --------------------------- -------------------------D- ------------------------DDD -------------------------D- --------------------------- --------------------------- --------------------------- --------------------------- --------------------------- --------------------------- --------------------------- --------------------------- --------------------------- --------------------------- --------------------------- --------------------------- 
