model
size = 26 28 21, scale = 0.05, origin = -y
material 
  colors = A:#0A0A0A B:#000 C:#001 D:#007
voxels
-------------------------- -------------------------- -------------------------- -------------------------- -------------------------- -------------------------- -------------------------- -------------------------- -------------------------- -------------------------- -------------------------- -------------------------B -------------------------C -------------------------C -------------------------- -------------------------B -------------------------C -------------------------C -------------------------- -------------------------- -------------------------- -------------------------- -------------------------- -------------------------- -------------------------- -------------------------- -------------------------- -------------------------- 
-------------------------- -------------------------- -------------------------- -------------------------- -------------------------- -------------------------- -------------------------- -------------------------- -------------------------- -------------------------B -------------------------B ------------------------BB ------------------------BB ------------------------BB ------------------------BB ------------------------BB ------------------------BB ------------------------BB -------------------------B -------------------------B -------------------------- -------------------------- -------------------------- -------------------------- -------------------------- -------------------------- -------------------------- -------------------------- 
-------------------------- -------------------------- -------------------------- -------------------------- -------------------------- -------------------------- -------------------------- -------------------------- -------------------------B ------------------------AB ------------------------AB ------------------------AB -----------------------BAB -----------------------BAB -----------------------BAB -----------------------BAB -----------------------BAB ------------------------AB ------------------------AB -------------------------B -------------------------B -------------------------- -------------------------- -------------------------- -------------------------- -------------------------- -------------------------- -------------------------- 
-------------------------- -------------------------- -------------------------- -------------------------- -------------------------- -------------------------- -------------------------- -------------------------B ------------------------AB ------------------------AB -----------------------BAA -----------------------BAA -----------------------BAA -----------------------BAB -----------------------BAA -----------------------BAA -----------------------BAA -----------------------BAA -----------------------BAA ------------------------AB ------------------------AB -------------------------B -------------------------- -------------------------- -------------------------- -------------------------- -------------------------- -------------------------- 
-------------------------- -------------------------- -------------------------- -------------------------- -------------------------- -------------------------- -------------------------B ------------------------AB ------------------------AB -----------------------BAB -----------------------BAA -----------------------BAC ----------------------AAAA ----------------------AAAB ----------------------AAAA ----------------------AAAC ----------------------AAAB -----------------------BAC -----------------------BAB -----------------------BAA ------------------------AB ------------------------AB -------------------------B -------------------------- -------------------------- -------------------------- -------------------------- -------------------------- 
---------BBBBBBBB--------- -------BB--------BBB------ -----BB-------------BB---- ----B-----------------B--- ---B-------------------BB- --B---------------------B- -B----------------------AB -B----------------------AB BB---------------------BAC BA---------------------BAB BA---------------------BAA BA--------------------AAAA BA--------------------AAAA BA---------------------DAB BA--------------------AAAA BA---------------------DAB BA--------------------AAAC BA--------------------AAAB BA---------------------BAB BB---------------------BAB -B---------------------BAA -B----------------------AB --B---------------------AB ---B-------------------BB- ----B-----------------B--- -----BB-------------BB---- -------BB--------BBB------ ---------BBBBBBBB--------- 
---------AAAAAAAA--------- -------AA--------AAA------ -----AA-------------AA---- ----A-----------------A--- ---A-------------------AA- --A---------------------BB -A----------------------AA -A----------------------AB AA---------------------BAB AA---------------------BAB A---------------------AAAB AA--------------------AAAB A---------------------AAAB AA--------------------AAAB A---------------------AAAA AA--------------------AAAC A---------------------AAAB AA--------------------AAAC AA--------------------AAAB AA---------------------BAB -A---------------------BAA -A----------------------AB --A---------------------AB ---A-------------------ABA ----A-----------------A--- -----AA-------------AA---- -------AA--------AAA------ ---------AAAAAAAA--------- 
---------BBBBBBBB--------- -------BA--------ABB------ -----BA-------------BA---- ----A-----------------B--- ---B-------------------AB- --A---------------------AB -B----------------------AB -A---------------------BAB AB---------------------BAB BA--------------------AAAA BA--------------------AAAA BA--------------------AAAA BA--------------------AAAB BA--------------------AAAB BA--------------------AAAA BA--------------------AAAB BA--------------------AAAC BA--------------------AAAB BB--------------------AAAB AB--------------------AAAB -A---------------------BAA -B---------------------BAB --A---------------------AB ---B-------------------AAB ----A-----------------B--- -----BA-------------BA---- -------BA--------BAB------ ---------BABBBBAB--------- 
---------BBBBBBBB--------- -------BA--------ABB------ -----BA-------------BA---- ----A-----------------B--- ---B-------------------AB- --A---------------------AB -B----------------------AA -A---------------------BAB AB---------------------BAA AA--------------------AAAC AA--------------------AAAA A----------------------DAA AA--------------------AAAA A----------------------DAB AA--------------------AAAA A----------------------DAA AA--------------------AAAA AA---------------------DAA AB--------------------AAAA AB--------------------AAAA -A---------------------BAA -B---------------------BAB --A---------------------AB ---B-------------------ABA ----A-----------------B--- -----BA-------------BA---- -------BA--------BAB------ ---------BABBBBAB--------- 
---------AAAAAAAA--------- -------AA--------AAA------ -----AA-------------AA---- ----A-----------------A--- ---A-------------------AA- --A---------------------AB -A----------------------AB -A---------------------BAB AA---------------------BAA BB--------------------AAAA AA--------------------AAAC BA--------------------AAAA BA--------------------AAAA BA--------------------AAAB BA--------------------AAAB BA--------------------AAAB BA--------------------AAAB AB--------------------AAAB BA--------------------AAAB AA--------------------AAAB -A---------------------BAB -A---------------------BAB --A---------------------AB ---A-------------------AAB ----A-----------------A--- -----AA-------------AA---- -------AA--------AAA------ ---------AAAAAAAA--------- 
---------BBBBBBBB--------- -------BB--------BBB------ -----BB-------------BB---- ----B-----------------B--- ---B-------------------BB- --B---------------------BB -B----------------------BA -B---------------------BBB BA---------------------BBA BA--------------------AABA BB--------------------AABA BB--------------------AABA -B--------------------AABA BB--------------------AABB -B--------------------AAC- BB--------------------AABB -B--------------------AABB BA--------------------AABB BA--------------------AABB BA--------------------AABB -B---------------------BBC -B---------------------BBC --B---------------------BB ---B-------------------BBA ----B-----------------B--- -----BB-------------BB---- -------BB--------BBB------ ---------BBBBBBBB--------- 
---------AAAAAAAA--------- -------AA--------AAA------ -----AA-------------AA---- ----A-----------------A--- ---A-------------------AA- --A---------------------AB -A----------------------AB -A---------------------BAB AA---------------------BAB BB--------------------AAAA AA--------------------AAAA BA---------------------DAA BA--------------------AAAB BA---------------------DAB BA--------------------AAAB BA---------------------DAB BA--------------------AAAA AB---------------------DAA BA--------------------AAAA AA--------------------AAAB -A---------------------BAB -A---------------------BAC --A---------------------AB ---A-------------------AAB ----A-----------------A--- -----AA-------------AA---- -------AA--------AAA------ ---------AAAAAAAA--------- 
---------BBBBBBBB--------- -------BA--------ABB------ -----BA-------------BA---- ----A-----------------B--- ---B-------------------AB- --A---------------------AB -B----------------------AA -A---------------------BAB AB---------------------BAB AA--------------------AAAB AA--------------------AAAB A---------------------AAAB AA--------------------AAAB A---------------------AAAB AA--------------------AAAB A---------------------AAAA AA--------------------AAAA AA--------------------AAAA AB--------------------AAAA AB--------------------AAAA -A---------------------BAB -B---------------------BAB --A---------------------AB ---B-------------------ABA ----A-----------------B--- -----BA-------------BA---- -------BA--------BAB------ ---------BABBBBAB--------- 
---------BBBBBBBB--------- -------BA--------ABB------ -----BA-------------BA---- ----A-----------------B--- ---B-------------------AB- --A---------------------AB -B----------------------AB -A----------------------AB AB---------------------BAB BA---------------------B-A BA--------------------AAAA BA--------------------AAAA BA--------------------AAAB BA--------------------AAAB BA--------------------AAAA BA--------------------AAAA BA--------------------AAAA BA--------------------AAAA BB--------------------AAAC AB---------------------BAA -A---------------------BAA -B----------------------AB --A---------------------AB ---B-------------------AAB ----A-----------------B--- -----BA-------------BA---- -------BA--------BAB------ ---------BABBBBAB--------- 
---------AAAAAAAA--------- -------AA--------AAA------ -----AA-------------AA---- ----A-----------------A--- ---A-------------------AA- --A---------------------BB -A----------------------AA -A----------------------AB AA---------------------BAA AA---------------------B-A A----------------------BAA AA--------------------AAAA A---------------------AAAA AA---------------------DAB A---------------------AAAA AA---------------------DAC A---------------------AAAC AA--------------------AAAC AA---------------------BAA AA---------------------BAA -A---------------------BAA -A----------------------AB --A---------------------AB ---A-------------------ABA ----A-----------------A--- -----AA-------------AA---- -------AA--------AAA------ ---------AAAAAAAA--------- 
---------BBBBBBBB--------- -------BB--------BBB------ -----BB-------------BB---- ----B-----------------B--- ---B-------------------BB- --B---------------------B- -B----------------------AB -B----------------------AB BB----------------------AA BA---------------------BAA BA---------------------BAC BA---------------------BAA BA--------------------AAAA BA--------------------AAAB BA--------------------AAAA BA--------------------AAAA BA--------------------AAAA BA---------------------BAA BA---------------------BAA BB---------------------BAA -B----------------------AA -B----------------------AB --B---------------------AB ---B-------------------BB- ----B-----------------B--- -----BB-------------BB---- -------BB--------BBB------ ---------BBBBBBBB--------- 
-------------------------- -------------------------- -------------------------- -------------------------- -------------------------- -------------------------- -------------------------- ------------------------AB ------------------------AA ------------------------AC -----------------------BAA -----------------------BAA -----------------------BAA -----------------------BAB -----------------------BAB -----------------------BAA -----------------------BAA -----------------------BAA -----------------------BAA ------------------------AA ------------------------AB ------------------------AB -------------------------- -------------------------- -------------------------- -------------------------- -------------------------- -------------------------- 
-------------------------- -------------------------- -------------------------- -------------------------- -------------------------- -------------------------- -------------------------- -------------------------- ------------------------AB ------------------------AA ------------------------AA ------------------------BA -----------------------BBB -----------------------BBB -----------------------BBB -----------------------BBB -----------------------BBA ------------------------BA ------------------------AA ------------------------AB ------------------------AB -------------------------- -------------------------- -------------------------- -------------------------- -------------------------- -------------------------- -------------------------- 
-------------------------- -------------------------- -------------------------- -------------------------- -------------------------- -------------------------- -------------------------- -------------------------- -------------------------- ------------------------AB ------------------------AB ------------------------AB ------------------------BB ------------------------BA ------------------------BA ------------------------BB ------------------------BB ------------------------AB ------------------------AB ------------------------AB -------------------------- -------------------------- -------------------------- -------------------------- -------------------------- -------------------------- -------------------------- -------------------------- 
-------------------------- -------------------------- -------------------------- -------------------------- -------------------------- -------------------------- -------------------------- -------------------------- -------------------------- -------------------------- -------------------------- ------------------------AB ------------------------AB ------------------------BB ------------------------BB ------------------------BB ------------------------AB ------------------------AB -------------------------- -------------------------- -------------------------- -------------------------- -------------------------- -------------------------- -------------------------- -------------------------- -------------------------- -------------------------- 
-------------------------- -------------------------- -------------------------- -------------------------- -------------------------- -------------------------- -------------------------- -------------------------- -------------------------- -------------------------- -------------------------- -------------------------- -------------------------- ------------------------BB ------------------------CC ------------------------BB -------------------------- -------------------------- -------------------------- -------------------------- -------------------------- -------------------------- -------------------------- -------------------------- -------------------------- -------------------------- -------------------------- -------------------------- 
