model
size = 15 32 15, scale = 0.05, origin = -y
material 
  colors = A:#111 B:#0F6 C:#06F D:#FFF E:#DDD
voxels
5-5D370-5D98-9D8-5E13(10-5B)10-2A2(3B10-BA)B2A10-2ABAB10-BA2BA10-2A3B4(10-5B)8-9D8-5E82-11D5-9E13(6-2B5C2B)6-BA2D3CAB6-BA5CAB6-2B3C2D2A6-BADA3CAB6-BA5CAB6-BA2D3CAB4(6-2B5C2B)5-11D5-9E8-5B66-13D3-11E23(4-B9CB)3-13D3-11E6-B5AB9-5B51-13D3-11E23(4-B9AB)3-13D3-11E5-B7AB7-7B49-15D-13E23(2-B11CB)-15D-13E3-B9AB5-3B3A3B9-3E36-15D-13E23(2-B11AB)-15D-13E3-B9AB5-2B5A2B8-5E11-3D12-DBD2(6-15D-13E23(2-B11AB)-15D-13E3-B9AB5-2B5A2B8-5E11-3D12-3D)6-15D-13E23(2-B11AB)-15D-13E3-B9AB5-3B3A3B9-3E37-13D3-11E23(4-B9AB)3-13D3-11E5-B7AB7-7B50-13D3-11E23(4-B9AB)3-13D3-11E6-B5AB9-5B52-11D5-9E23(6-2B5A2B)5-11D5-9E8-5B68-9D8-5E23(10-5B)8-9D8-5E85-5D370-5D95-
