model
size = 22 26 3, scale = 0.05, origin = -y
material 
  colors = A:#EEE B:#F596AA C:#DB4D6D
voxels
-------A------A------- ------AA------AA------ ------AA------AA------ -----AAA------AAA----- ---AAAAA------AAAAA--- ---AA--A------A--AA--- ---A---A------A---A--- --AA---A------A---AA-- --AA---A------A---AA-- --A----A------A----A-- -AA----A------A----AA- -AA----A------A----AA- -A-----A------A-----A- -A-----A------A-----A- -A-----A------A-----A- -A-----A------A-----A- -A----AA------AA----A- -A----A--------A----A- -AA--AA--------AA--AA- --A--A----------A--A-- --AAAA----------AAAA-- ---AA------------AA--- ----A------------A---- ----A------------A---- ---------------------- ---------------------- 
-----AAA------AAA----- -----AAA------AAA----- ----AAAA------AAAA---- ---AAAAA------AAAAA--- ---AAAAA------AAAAA--- --AAACCA------ACCAAA-- --AACCCA------ACCCAA-- --AACCCA------ACCCAA-- -AAACCCA------ACCCAAA- -AABCCCA------ACCCBAA- -AABBCCA------ACCBBAA- -AABBCCA------ACCBBAA- AABBBBCA------ACBBBBAA AABBBBBA------ABBBBBAA AABBBBBA------ABBBBBAA AABBBBBA------ABBBBBAA AABBBBAA------AABBBBAA -ABBBBAA------AABBBBA- -AABBAAA------AAABBAA- -AABBAA--------AABBAA- -AAAAAA--------AAAAAA- --AAAA----------AAAA-- --AAA------------AAA-- ---AA------------AA--- ---AA------------AA--- ---A--------------A--- 
-----AAA------AAA----- -----AAA------AAA----- ----AAAA------AAAA---- ---AAAAA------AAAAA--- --AAAAAA------AAAAAA-- --AAAAAA------AAAAAA-- -AAAAAAA------AAAAAAA- -AAAAAAA------AAAAAAA- -AAAAAAA------AAAAAAA- AAAAAAAA------AAAAAAAA AAAAAAAA------AAAAAAAA AAAAAAAA------AAAAAAAA AAAAAAAA------AAAAAAAA AAAAAAAA------AAAAAAAA AAAAAAAA------AAAAAAAA AAAAAAAA------AAAAAAAA AAAAAAAA------AAAAAAAA AAAAAAAA------AAAAAAAA AAAAAAAA------AAAAAAAA AAAAAAAA------AAAAAAAA -AAAAAAA------AAAAAAA- -AAAAAA--------AAAAAA- --AAAA----------AAAA-- --AAAA----------AAAA-- ---AA------------AA--- ---A--------------A--- 
