model
size = 32 31 31, scale = 0.05, origin = -y
material 
  colors = A:#9CF B:#444 C:#EEE D:#A4CCCC E:#111 F:#555 G:#BBB H:#400 I:#FF3 J:#777 K:#222 L:#909 M:#660 N:#0B0 O:#E00 P:#960 Q:#FF0 R:#F60 S:#690 T:#036 U:#600 V:#D00 W:#6C3 X:#00D Y:#070 Z:#933 Aa:#633 Ab:#888 Ac:#C00
voxels
130B28-4B5-D3-D8-D9-4B16-D11-4B12-D15-2(4B28-)4B25-D2-4B12-D15-4B14-4D10-3B19-D9-3B4-D17-D6-3B19-2(D4-)3B29-3B21-D7-4B-D18-D-D5-4B20-D7-4B2-D25-4B28-4B3-D24-4B7-D20-4B8-D19-4B11-D16-2(4B28-)66B32-33B2(30A2B)A29C2(2BC28DC)2BC4D-5D-9D5-3DC2BC3D3-2D4-8D5-3DC2BC3D10-5D5-5DC2BC2D4-D6-5D6-4DC2BC3D2-3D-D2-6D6-4DC2BC3D-5D-9D5-4DC2BC5D8-10D-4D3(C2B-5D13-10D)2(C2B-3D17-8D)3(C2BC3D17-8D)C2BC4D16-5D-2DC2BCD-2D16-4D-3DC2BCD2-6D7-6D2-4DC2BCD5-6D-D3-4D4-3DC2BC5-8D3-5D4-3DC2BC4-11D-4D6-2DC2BC2D-11D-6D-D-4DC2BA28CA33B32-33B2(30A2B)A29C24(2BC28-C)2BA28CA25BK7B32-33B30A2B30ABHA29C3(BHC28-C)2BC28-CBH11(C28-C2B)2(C28-CEBC28-2CB)2(C28-2CB)3(C28-C2B)A28CA24BKHK6B32-33B30A2B30ABHA29C2(BHC28-C)2(EHC28-C)3(EBC28-C)2(2BC28-CEBC28-C)2(EBC28-C)2(2BC28-C)2B2(C28-2C2(BC28-CE)B)2(C28-C2B)CM27-C2BA28CA20BKB4K7B32-33B30A2B30ABHA3CZU24C4(BHC28-C)2(EBC28-C2BC28-C)3(EBC28-C)2BC28-CEB3(C28-C2B)2(C28-2CB)3(C28-2CH)C28-CEH2(C28-C2B)CM27-C2BA28CA19BKH5K7B32-33B30A2B30ABHA3CAcZ24CBHC28-CBHC12-5G11-CBH6(C28-C2B)2(C28-CBHC28-C2B)3(C28-C2B)C28-CEBC28-2CB2(C28-CEH)2(C28-2CB)C28-C2BCM27-C2BCS27-C2BACMSP24CA18B4K11B32-33B2(30A2B)A3C3U23C2BC13-3G12-C2BC11-2G3-2G10-2(CEBC28-)2(C2BC28-)CEBC28-C2B2(C28-CEB)3(C28-CBH)3(C28-C2B)3(C28-2CB)C28-CEH2(C28-2CB)C28-C2BCS27-C2BCW3-M23-C2BACSPS24CA18BKHK12B32-33B2(30A2B)A3CPCAaU22C2BC12-5G11-C2BC10-2G5-2G9-7(C2BC28-)CEB2(C28-CEH)3(C28-CBH)C28-C2B2(C28-CEB)C28-2C2(BC28-CE)BC28-2CBCS3-M9-I13-C2BCW3-M8-3I12-C2BCW3-M23-C2BACPMS24CA33B6-9B6KH4K6-33B30A2B15A-14A2BA2CPCAa8C3G13C2BC11-2G3-2G10-C2BC10-G7-G9-5(CEBC28-)2(C2BC28-)CEBC28-CB2(HC28-CE)4(HC28-CB)H3(C28-C2B)C14-I13-C2BC13-3I12-C2BCM12-3I12-C2BCP11-5I11-C2BCW12-3G12-C2BACSMCP23CA33B6-10B3K2B5K3-2T-33B30A2B15A-14A2BA13C3G13C2BC11-2G3-2G10-C2BC10-G7-G9-2(C2BC28-)2(CEBC28-C2BC28-)C2B3(C28-CEB)5(C28-CBH)2(C28-C2B)C14-I13-2(C2BC13-3I12-)C2BCP11-2IAb2I11-C2BCS11-2IAb2I11-C2BCP12-3G12-C2BACM26CA33B6-20B2-T3-33B30A2B15A-14A2BA13C3G13C2BC11-2G3-2G10-C2BC10-G7-G9-2(CEBC28-)C2BC28-CEB2(C28-C2B)2(C28-CEB)2(C28-C2B)4(C28-CBH)2(C28-C2B)C28-N2BC28-Q2BC14-I13-N2(2BC13-3I12-L)2BCM11-5I10-RC2BCM12-3G12-C2BA28CA33B6-8B-2B-8B-T4-33B2(30A2B)A29C2BC12-5G11-C2BC10-2G5-2G9-12(C2BC28-)2(CBHC28-)C2BC28-N2BC28-Q2BC28-R2BC28-Q2BC28-L2BC14-I13-L2BC13-3I11-OC2BC27-RC2BA25C2LCA33B6-5B3(-2B)-5B-TVT2-33B2(30A2B)A29C2BC13-3G12-C2BC11-2G3-2G10-CEB2(C28-C2B3(C28-CEB))2(C28-CEB)C28-C2B2(C28-CBH)C28-C2BC28-N2BC28-A2(2BC28-R)2BC28-O2BC28-L2BC27-QC2BC25-N-RC2BA26CLCA33B6-6(2B-)2B2-TV2-33B2(30A2B)A29C2BC28-C2BC12-5G11-3(CEBC28-)C2BC28-CEB3(C28-C2B)2(C28-CEBC28-C2B)4(C28-C2B)C28-N2BC28-Q2(2BC28-O)2BC28-A2BC27-OC2BC27-QC2BA25C2LCA33B6-6(2B-)2B3-V2-33B2(30A2B)A29C3(2BC28-C)4(BJ2(C28-C2B)C28-C)2(2BC28-C)2BC28-N2BC28-A2BC28-Q2BC28-N2BC28-L2BC27-QC2BC25-N-OC2BA26CLCA33B6-6(2B-)2B3-V2-33B2(30A2B)A29C3(2BC28-C)BJ2(C28-C2B)C28-CEJC28-C2BC28-CEBC28-CEJ2(C28-CEB)C28-CEJ6(C28-C2B)C28-L2BC28-N2BC28-L2BC27-OC2BC27-RC2BC25-N-RC2BA26CLCA33B6-6(2B-)2B6-33B2(30A2B)A29C2(2BC28-C)EBC28-CEJ2(C28-CEB)C28-CEJC28-C2BC28-CEBC28-CBJC28-CEBC28-C2BC28-CEJ10(C28-C2B)C27-RC2BC26-NQC2BA28CA33B6-6(2B-)2B6-33B2(30A2B)A29C3(2BC28-C)BJ2(C28-C2B)C28-CE2(J2(C28-C2B)C28-CB)J12(C28-C2B)A28CA33B6-6(2B-)2B6-33B2(30A2B)A29C3(2BC28-C)3(BJ2(C28-C2B)C28-C)EJ12(C28-C2B)A28CA33B6-6(2B-)2B6-33B2(30A2B)A29C3(2BC28-C)BJ2(C28-C2B)C28-CBJC28-C2BC28-CEBC28-CEJ2(C28-CEB)C28-CEJ12(C28-C2B)A28CA33B6-6(2B-)2B6-33B2(30A2B)A29C3(2BC28-C)3(BJ2(C28-C2B)C28-C)EJ2(C28-C2B)C28-CEBC28-C2B3(C28-CEB)5(C28-C2B)A28CA33B6-5B3(-2B)-5B6-33B3(30A2B)4(2(A29C2B)A29CBJ)A29C2B2(A29CEB)2(A29C2BA29CEB)A29CEB4(A29C2B)30A33B6-8B-2B-8B6-33B5(30A2B)3(30ABJ2(30A2B))30AEJ2(30A2B)3(30AEB)30A2B30AEB5(30A2B)30A33B6-11BO8B6-33B5(30A2B)2(30ABJ2(30A2B))30ABJ30A2B30AEB30ABJ12(30A2B)30A33B6-10BYX8B6-33B5(30A2B)30ABJ2(30A2B)30ABJ30A2B30AEB30AEJ2(30AEB)30ABJ12(30A2B)30A33B6-10BOY8B6-33B13(30A2B)30AEB3(30A2B)30AEB30A2B3(30AEB)5(30A2B)30A33B6-10BOXO7B6-33B14(30A2B)30AEB30A2B2(30AEB)2(30A2B30AEB)30AEB4(30A2B)30A33B32-33B17(30A2B)3(30AEB)30A2B30AEB5(30A2B)30A33B32-33B27(30A2B)30A33B32-275B11F21BFK7FKF6(21B11F)21BFK9F21B9FKF21B11F354B32-
