model
size = 29 27 27, scale = 0.05, origin = -y
material 
  colors = A:#111 B:#FC6 C:#222 D:#F4C874 E:#DAAF57 F:#888 G:#AAA H:#B69248 I:#EEE J:#777 K:#BBB L:#92763A M:#4A3D1D N:#D3BDA0 O:#DDD P:#633 Q:#26200E R:#996
voxels
----------------------------- ----------------------------- ----------------------------- ----------------------------- ----------------------------- ----------------------------- ----------------------------- ----------------------------- ----------------------------- ----------------------------- ----------------------------- ----------------------------- ----------------------------- ----------------------------- -----------------A-AA-------- ----------------GACAA-------- -----------------AA---------- ----------------------------- ----------------------------- ----------------------------- ----------------------------- ----------------------------- ----------------------------- ----------------------------- ----------------------------- ----------------------------- ----------------------------- 
----------------------------- ----------------------------- ----------------------------- ----------------------------- ----------------------------- ----------------------------- ----------------------------- ----------------------------- ----------------------------- ----------------------------- ----------------------------- ----------------------------- ----------------------------- ----------------------------- -------------------AC-------- -----------------AAAAC------- ----------------CACAA-------- -----------------AAA--------- -----------------A-AC-------- ----------------A------------ ----------------------------- ----------------------------- ----------------------------- ----------------------------- ----------------------------- ----------------------------- ----------------------------- 
----------------------------- ----------------------------- ----------------------------- ----------------------------- ----------------------------- ----------------------------- ----------------------------- ----------------------------- ----------------------------- ----------------------------- ----------------------------- ----------------------------- ------------------AAA-------- -----------------CAACAA------ -----------------CAAAAA------ ----------------GACACAAA----- -------------FFFAACAAAAA----- ------------FCFAAAACACA------ -------------FAACACCAAC------ -------------CCAAAAAAA------- ---------------AAAA---------- ---------------A------------- ----------------------------- ----------------------------- ----------------------------- ----------------------------- ----------------------------- 
----------------------------- ----------------------------- ----------------------------- ----------------------------- ----------------------------- ----------------------------- ----------------------------- ----------------------------- ----------------------------- ----------------------------- -------------------CC-------- -------------A----AACAC------ -------------AA-GCAAAAA------ ----------------FCAACCA------ ---------------FFAAAAAAA----- --------------FGCAAAAAAAC---- -------------AAAAAAAACAAC---- -------------C-ACCAAAAAC----- ------------FA-CAAACAAAA----- ------------ACACAAAAAAA------ -------------ACAAAAAAA------- --------------CAAAA---------- ----------------------------- ----------------------------- ----------------------------- ----------------------------- ----------------------------- 
----------------------------- ----------------------------- ----------------------------- ----------------------------- ----------------------------- ----------------------------- ----------------------------- ----------------------------- -------------------C--------- -----------------ACAAA------- -------------A-AAAAAAAA------ -------------DB-AAAAAAAA----- -------------DAACAAAAACA----- ------------DCBCAAAAACAAA---- ------------IGGAAAACCCACC---- --------------AACAAAAACAA---- -------------ICAAAAAAAAAA---- ------------C-ACACACACAAA---- -----------AA-CACAAAAACAA---- -----------AACCAAAACAACAA---- ------------AACCCCACAAAC----- ------------CAAAACAAAAA------ -------------AACAAA---------- ----------------------------- ----------------------------- ----------------------------- ----------------------------- 
----------------------------- ----------------------------- ----------------------------- ----------------------------- ----------------------------- ----------------------------- ----------------------------- -------------------CAC------- -----------A-----AAACAC------ ----------AAAA--AAAAAAAC----- ----------A-BBB-ACCAAAAA----- ---------IA-DACAAAAACCCCC---- ---------I--BDDCAAACACCAA---- -----------FBBBBBAAAAAAAAA--- -----------FCAACACAAAAAAAA--- -------------FAAAAAAAAACAC--- ----------I--CCCAACAACAAAA--- ----------IIIAAACCCACAAAAA--- ---------IFA-AAACCACAAACCC--- ----------FAAACAAAAACACAA---- -----------AAAACAAAAAAACA---- ------------AAAAAACCAAAA----- ------------CAAACCAAAA------- -------------AACAAA---------- ----------------------------- ----------------------------- ----------------------------- 
----------------------------- ----------------------------- ----------------------------- ----------------------------- ----------------------------- ----------------------------- -----------------A---C------- ------------A-----AAAAAA----- ----------AAACA-CCAAAACAA---- ----------ABCBA-ACAAACAAC---- ---------IBABB-CCAACAAACA---- ----------AADBBAAAACAAAAAA--- ---------CADBDDCAAAAACAAAA--- -----KKKKKCBDDDBBDBBAAACAA--- ---------AKBDBBAAACAAACACAA-- ---------CFAFAACAAAACAAAAAA-- ---------FBCFAAACAACCACAAAC-- ---------FDAAAAAACAAAACAAAA-- --------IGBAAACAAAAAACAAAC--- --------IIGAACAAACACAAACCA--- ----------FACAACCAAAAAAAA---- -----------FACACACAACAAAA---- ------------AAAAAACCAAA------ ------------CAAACAACA-------- ---------------AAAA---------- ----------------------------- ----------------------------- 
----------------------------- ----------------------------- ----------------------------- -----------------AAA--------- -----------------CCA--------- ----------------------------- ------------C--AA--AACAC----- --------EED-A-A-CAACCAAAA---- -------EEBDBABBAACCAAACCAA--- -------BBDBBBABAAAACAAAACA--- ------BDBBDBBBBBAAACAAAAAC--- -----EBBBBBBBDDBCCCAACACAA--- ------BDBBBBDBBDCAAACACACCA-- ----KDBDBDBBBBBBDBBBBAACCAA-- -------BDBDDDBDBBBBBBAACAAA-- -------BBDCCAAAAAAAAACCAAAA-- -------BDDAAACCACACAAAAAACA-- -------CBBBCCAAAACAAAAACAAA-- -------CBBDAAAAACACAAAAAAAA-- -------FGGBACCCACACAAAAAAAA-- --------IFCACAAAACACAAAAAA--- ----------FCCCAACCAAAACAA---- ----------CCACAAAACACAAA----- -----------AAAACACC-AAA------ ------------AAA---ACA-------- ----------------------------- ----------------------------- 
----------------------------- ------------EDBBBBD-B-------- -------------EBBBBBBB-------- ----------------DAAAC-------- ----BDBD-------AAAAAA-------- ----EBDBDBBE---CACA-----A---- ----HBDBBBDBBACAAACAAAAAA---- ----HBBBBDBDBAACAAACAAAAAA--- ----EBEDDDDBDBDBAAAAAAAAAC--- ----EDEBDBDDDDBBACAAACCCACA-- -----HBBBBBBDDDBAAAAAAAAAAA-- -F---BBBBBBBBBBBAAAAAAAACCA-- -K---KBBBDBBBDDBAAAAAAAAAAA-- -OKK-BDDDBBBDBBBBDDBBDCAAAA-- ----HBBBDBBBBBBDDBBDACACACAC- ----DBBDBBAAAAACCACAACAAAAAA- -----BBDBDACAAACAAAAAACCAAAA- ----A-DBBDBAACAAAAAAAAAAACA-- -----ABBDBBAAAACCCACCAACAC--- -----JDBBBBCACAAAAAAACCAAAA-- ------IBCAACAAACCAAAAAAACC--- -------IFFAAACAACCAAAACACA--- ---------FAAAACCACAACAAAA---- -----------CCAACAACACACA----- -----------CAAAAACAAAAA------ -------------AACAACC--------- ----------------------------- 
------------D-----D---------- ----------HDBDDDDDBBD-------- ----------HHHDBDBBBDB-------- ---BB--BBBDDHHBBDAACCA------- ---LBBDBBDBEBBBAAAAAA-------- ---HBDBBDDDBDEDAACAAA-CAC---- ---LBBBDBBDBBDBCACACAAAAAA--- ----LBDDBBBBDDBAAACAACAACCA-- ----HDDBDDBBBBBDAAACAACAAAA-- ----EBBDBBBBDBBBAACCCAACCAC-- -J--BBBBDBBBDBBDAAAAAAAACCA-- --B-BDBBBBBBBDBDAAAAAACAAAAA- --MDBBBBBBBBBBBDAACAAACCACAA- -BBBDBDDDDDDDBBBBDDBBBBAAAAA- --NDDADDDBBBBBDBDDBDCACAAAAC- ---HBABDDBCAAACACAAAAAAACACA- ---DDDBBBBAACAAAAAAAAACCAACA- ----BBDDBBACAACAAAAAAAACCAAAA ----ABBBDBBAAACCAAAAAACCAAAAA -----ADBDBDAAAACACCCAAAACCC-- -----JBDCACCAAAAAAAAAAAAAA--- ------IDAAAAACACAAAAAAAACA--- -------IACCAAACACACAACCCC---- --------IGAACACCACACAACAA---- -----------AAAAAACAAAAAA----- -----------A--AAAA-C-AC------ -------------ACAAAC---------- 
-----------DDDBBBDDDD-------- ---------HBBBBDDBDBBBB------- ---EDB--BBDBBBDBBBBBD-------- --EDDDDBDBDBBBBBBAAAAA------- --EBBDDDBDDBBDBAACAAAAA------ --EDDBDBBDBBDBBAAACAAAACAA--- ---LBBBBBDBBBDBACACACAAAAAA-- ---HBBDBBBDBDDDACAAAACACCAA-- ----EBDDBBDDDBDBAAAACCCAACAA- ----DBDDBDBBBBBBCAACCCAACAAC- -J-DDBBBBDBDBBBBAAAAAAAAAAAA- -BDBDBBBDDBBBDDBAAACAACAAAAA- -EBBBDDBDDBBBBBBCAAAACAAAAAA- -MBDDBDBBBDDBBDBBBDBDBBDAAAAA -NBDBDBDBDDBBBBDBBBDAAAACCAAA --QDBABBBDAAACAACACAAACCAAAA- ---DDBBDBDACACCAAAAACCACAACC- ---BDDBBDBAAAAAACAAAACCAAAA-- ----BBDBBBAACAAAAACAACAAAAACA ----BBDDBDDAACAAAAAAACAAAAAAC -----DBBAAAACAAAAAACCAACCAA-- -----JBAACACACAAAACAAACCACA-- ------IBAAAAAAAAAAAAAAAAAA--- -------IBAAAACAACACAACAAA---- --------I--ACAAAAAACAAACC---- ------------CAACAACAA-CA----- ------------AA----ACC-------- 
----------HDBBDBBBBBBB------- ---ED---HHBBBDDBBBBDBBD------ ---BBDDDBBDBBBBBBBBBB-------- ---EBBDBBDDBBBBDBAAAAC------- --LPBBDDDBDBBBBCAAAAAA---A--- --EDBBDBDDDDBBDAAAAAAA-AAA--- --EDBDDBDBBBBBBCAACCAAACAAC-- ---LBBBDBBDBDBBAAAACAAAAAA--- ---EDBDDBDDBBBDBAAAAAAACAACA- ---HBDDDDDDBDBDDAAAAACAAACCA- -J-BDDDBBDBBBDDBAAAAAACAAAAA- -BBBBDBBDBBBDBDBACACAAAAACAAA -EDDBDBDDBDBBDBBCAAACBBDCAAAA -MBBBBDDBDDDDBBBBDDDBBBBCCACC -NDBBBDDBDBBBDBBDBDBAACAAAAAA --QBBABDDDBDBBBBBDBDAAACAAACC --HBDBBBBDAAACAAAAAAACAAAACCA ---BDDBDBBAACAAAACAAAACACAAAC ---BDDBDBDACAAACAAAAACAAAACA- ----BBDDBDACAACCCACAAAACACAAA ----BDDBDDBAAAAAAAAAAACAAAAA- ----DBBCAAAAAAACCAAACAAAAAA-- -----IBDAAAAAAAACACCACACAA--- ------I-ACAAACACAAAAAACAAC--- --------CAACAAAAAACAAAA-A---- ---------A-AACCACAAACA-C----- -----------A--ACAA---A------- 
---------HDBDBBBDBBDBB------- --EDDD--BBBBBBDDDBBBDBD------ --EBDDBBBBBBDBBBDBDBBD------- --EBDBBBDBDBBBBDBAACAA------- --DDBBDDBBDBBBBBAAAACA-C----- --LPBDBBDDDBBBDBAAAACC-CAAA-- --EBBBBBDDDBBBBBCACAAAAACCA-- --EBBBDBBBBDDBDBACAACAAAAAAC- ---BDBBBBDDBBDDBCAAAACAAAAAA- ---HDBBDBBDBDBBBAAAAAAAAACAA- -JDDBDBBDBDBBDBBAAACCCCAAAACC -GDDDBBBBBBBDBBBAAAAAACCACCAA -FDBBBDBBDBBDDDBDDBBBDBBAAAC- -OBDBBBDDBDDBBBDBBDBBBDBCAAA- --HBBBBBDBDDBDBBBDBBDACCACAC- --HBDBBBDBBBDBBBDBBBCAACAAAAA --ABDBDBDBAAAACAACCCAAAAAACAA ---DDBBDBBAAACAAAAAACAAACCACA ---BBDBBBBAAAAAACAAAAAAACAAA- ----DBBBBBCAAAAAACCAAAAAAACA- ----BDDBBBAAACAAAAACACAAACAA- -----BBACAAAACACCAAACAAAAA--- -----GBAAAAAACACAAACAACCAAA-- -----C-GAACAAAAAAAAAAACAAA--- ---------AAACAAAAAAAACAAC---- ---------ACAACACAAAAAC-A----- -------------CAACA---A------- 
---------BBBDDBDBBBBBD------- --EDDD--BBDBBBDBDBBDBBD------ --EDDDDBDBBDDBBBBDBBBB------- --DBDDBBBBBDBBDBBBBBB-------- --DDBBDDBDDBBDBBAAACC--A----- --LPDBBBBBBDBBBBAACAA--CAAC-- --BDBBBBBBBBBBBBAAAAAAAACAA-- --EBBDBBDBDBBBBBACAACAACAAAA- ---DBBBDBBBBBBDDAAAAACAACAAC- --BBDBDBDBBDBDBBAAAAAACCACCA- BBDBBDBDDDBDBBDDAAAAACACCAAAA BBBBBDDDBDBDBDBBAAACACCACCAC- --BBBDBBBBDBDDDBBBBBDDBDACAA- --JBBDDBBDBDBBDDBBBBBBBDAAAA- --BBBBDBBBBBBBBBDBBBBACAAAAA- --BBBBBDBBBBBBBBDDBBDCACAAAA- --BBBBBBBBAACAAAAAACAAAAAACA- ---BBBDBDDACAACCAAAAAACAAAAAA ---DBDBBBBCAACAAAAAAACAACAAAA ---BBDDBBBAAAAAAAACCCAAAAAC-- ----DBDBBBCCACAAACCAAAAACAAA- -----DBBDBAAAACCAAACACCAACA-- ----R-BBACCCCAACCAAAAACACA--- -----F--CAACCAAACAACCAAAAA--- ------A-AACAAAACCACCAAAAA---- -------AACAACCAAAAAAAACC----- ---------AAACAACA---CA------- 
---------BBBDBDDBBDBBB------- --EBDD--BBBBBBBBBBDDBDD------ --EDDDBDBDDBBBBBBBDDBB------- --DDBDDDBBBBDBDBDBDBB--A----- --DBDBBDBDDBBBDBAAACCC------- --LPDBBDBBBBBDDDAAAAA--AAA--- --BBBBBBBDBBDBDBACACCCCCAAA-- --EBBDBBDBBBBDBBAAAAAACCAAAC- ---DDBBBBDBDBBBBAAAACAAAAAAA- --BBBBBBDBDBBDBBAAAACACAAACC- BBDBDBBDBBBDBBBBACACAAAAAACAA BDDDDBDDBBDBDDDBACAACAACAAAAA --DBBBBBDBBBBBDBBBBDBDDDCCAAA --JDBBDDBBDBBBBDBBBBBDBDAAACA --BBBBBBBBDBBBDBBDBBDAACAACCC --BBDBBBDBBBDBBDBBDDBAAAACAAA --DDBDDBBBAAAAACAAACACCACAAAC ---DBBBDBBAAAAACCACAACACACAA- ---DDDBDBDAAAAAAACAAAAAACAAC- ---BDBDDBBCAAAAACCAAACAACAA-- ----DDBBDBACAAACCCAAAACAAAAA- ---G-BBDBBCACAAAAACAACACCCA-- ----AGBBBBCAAACAAAAAAACAAA--- ------IFGGAAAAAAACAAACAAAA--- -----F----GAACCCAACAACCAA---- ----------AAAACCAAAAAA-A----- ----------AAAAAAACAC-C------- 
----------BDDBDBBBBBDD------- --EDED--BBBDDDDBDBBBDBD------ --EBBBBBDDBDBDBBBDDDDB------- --EBBBBBBDDDDBBBDDDDB--A----- --EBDDDBBBBBDBBBCCCAAAA------ --LPDBDBBBBBDDBBAAACC--AAA--- --EBDBBDBBBBBBDBAAAAAAACAAC-- --EDDBBDBBBBBDBDAACAAACAAAA-- ---DBBBBBDBDDBDBCAACAAAAACAC- ---DDBDBBBBDDBBBAACACAACAAAA- -JBBDBDDBBBBBBBBAAAAAAAAACCA- -FBBDBBBBDDDBBDBACCCAACAAAAA- -KBDBBBDBBBBBDBBBDBDDBDBAAAAC -KBBBBBBDDDBBBBDDBBDBAAACCAAA --HDDBDBBBBBDDBDBDBDBACCAAAAA --HDDABBDBBDDBBBBBBBDCAAAAAAA --ABBBBBBDDDBDDAACACAACAAAACA ---BBDBDBDCAACAAAAAAACCCAACC- ---DBBDBBDAAAACCCAAACAAAAAAA- ----BBDDBBCCCAAAACCAAAACAAAA- ----DBBBBBCCAAAAAAAAAACACAA-- ---FFBBDDDCCAAAAAACAAAACCAC-- -----GGDDDAAAACAAACAAAAAAA--- -------IGDCAAAACACAAAAACCA--- -----F----GAAAAAAAAAAAAAA---- -----G-AAAACCAAACCAACA-A----- -------A-AACAAAAAAA--A------- 
-----------BBBBBDDDBBB------- ---EDD--DDDBDBBBBBBBDD------- ---E-BDDBBBDBBDDBBDDB-------- ---EBBBDDBBDBBBDBDBBB-------- --LPBDBBBBDBBDDBAAAAACAA----- --EDDBDBDBDDBBDDAAACAACAAA--- --EBBDBDDBBBBDBBAAAACCCAAA-A- ---L-BBDBDBBDBBBCCAAAAAAAAC-- ---EBBDDBDBBDDBBAAAACCAAAAA-- ---HDDBDDDDDBDDDCCACAAACAAAA- -J-BBBBBBBDBDBBDAAAAAAAACAAA- -HBBDBBDDBBBBBBDCAAACCCAAAAC- -EBDDDBDDDBBBDDBBDBDBBDCAAAC- -MBBBBDDBBBBBBDDDBBBBAACAACAC -NBBBBBBBDDBDDDBBDBBDCAACAACC --QBBABBBDBBBDDBBDDBDAACCCAA- --BDDBBDDBBBBBBDDBBBBAAAAAAA- ---BBDDDBBCAAAAACAAACAAAAAAA- ----BBBBBDCCAAAAACCCCACAAAC-- ----BBBBDBAAACCAAAAAAAAAACAA- ---F-BBBDBCAACCCACAAAAAAACC-- ----IFDBDBACAAAAAAAACCCACAA-- ---IGA-FDBAACCAAAAAACAACCA--- --------FGCACACAAACAAACAC---- -------FC-AAAAAAAAAAAAAA----- -------AAAAAAAAAAACAAA------- ---------CAAAACAAA---C------- 
------------BBBBDBDDB-------- ----------HEDBBBBDDBBD------- ---DDDB--DDDBBBBBBBBB-------- --EDDBDDBBBBBBDBBBBBD-------- --EDDDDBAABDBDBBAACACAA------ --EBBBBDDDDDBBBBCAAAA--AA---- ---HBDBBDBBBDBDBA-CCCCCACA--- ---HDBBDDBBBBBBBCCAAAACAAAAA- ----HBDBDBDDDBDDAAAAACAAAAA-- ----HBDBBBBBBBBBACACCCACAACC- -J--BDBBBBBDDBBDAACAAAAAAA-C- -HB-BBBBBBBDDBDBAAAAACACCACA- -ED-BBBBBDBBBDDBBDBBBDBAAAAC- -MBDBBDBDBDBBDDBDDBDBCCAAAAA- -NBBDABBDBBBDBBBBBDBBAAAAAAA- --ABBCBBBBBDBBBBDDDBBAAAAAAC- ---BDBBBDDBBDBDDBBBBBACCACAA- ----BBDDBBCCCACCCACACAAACAAA- ----DDDBBDAAAAAAAAAAAAAAAAC-- ---IABBBBDAACCACACAACCCACAA-- ----CFBBDBCCAAAAAACAAAACAA--- ---FAGFGDBACAACAAAACCAACACA-- -----G--GBAAAAACACAAAACAAA--- ----G-----AAAAAACACAAAAAC---- ----F-C--ACAAAAAAAAAAAAA----- -------CC--AAAAACAACAAA------ -----------CCAAAA---A-A------ 
----------------------------- ------------EBBDBBBBD-------- -------------HDDBBBDB-------- -----H-----HBBDDBBBB--------- ---HDDBBBDDABB-AACACAAA------ ---HBDDDBBAADDBC-CCA---A----- ---LDBBBDBBLDDD--AAAAACACA--- ----LBBDDDBDBBBBAAAAACCCAA-A- ----HBDBBBDBBBDD-AAAAAAAAAC-- ----HDDBBDDDDBDDAAACCCAAAAA-- -J-BHHBDBDBDBBBBCAAAAAACAAAA- ---BBBBBDBBDDDBDBBDBBBAAACAC- --M-BBBBDBBBBBBBBBDBBDCAAAA-- --B-BBBBBDDBBBDBDBBBDDAAACAA- --NBBBDBBBBDBDBBDBBBBDAAACAA- ---HQDBDBBBDBBBDBBBBBBACACCA- ----BBBBDBBBDDDDDDDDBBCACAAA- -----DDBBBACAACAAAAAAAACAACA- ----ABBBBDAACAAAAACCAAACACA-- ---R-FDBBBCACCACACACAACCAAA-- --IGG--BDBCAAAAAAAAAACAAAA--- --IFG--ADBACAAAACACCAAACC---- ----G---JACCAAAAACCACAACC---- -----F---AAACCAAAACAAAAA----- ------A---AAAAAACACCACA------ ------A----AAAAAAAAAAA------- ------------A-AA-AAA-A------- 
----------------------------- ----------------EDBBB-------- --------------EDDBBB--------- ------------H-BDDB----------- ------------A-----CC-A------- ------------AAA--ACA--------- ----EBDEEEL-A-AAAC-AACAAA---- ----HBDBEBBBB--A-CCAAAACCC--- ----HDBBAEDBADACACAAAAAACAA-- -----HBDBDDDBBAAAAAACACAAA--- ------DDBBBBBDACCAAAACAAAA-A- -J----BBBBBDBBAAAACAACAACAA-- -K----DBDBBDBDBBBBBBBAAAAAA-- -OOOKOBBBBBBDBBBDBBBDACACCA-- ------HDBBDBBBBBBBDDBCAAAAA-- ------DDDBBBDBDBBBBDBAAAAAAA- ------DBDBBDBBDBDBDBDACAAAA-- -----C-BDBAAACACACACAAACCAA-- -----GGBDGAAAAAAAAAACACACA--- ------FDFBAAAAACCACAAACAAC--- --IF-GC-BDAAAACCCAAAAAACCA--- ----GAJ-FAAAAAAACAACCCAAA---- ----GG---AAACCCAAACCAAAC----- ------G---AAAACCAAAAAAC------ ------A----AACCAAAAACA------- --------------ACCACAA-------- ----------------C------------ 
----------------------------- ----------------------------- ----------------------------- ----------------------------- --------------A----AA-------- -------------A--------------- -----------------A----------- -----------AA-----AAACAA----- ----------ABB----ACAAACAA---- ---------DBDCC-AAAACAAAAAC-C- --------BBCADBCCAACAACCAA---- --------DABBBACCACCAACAAAAAA- --------ABDBDCAAAAACAAAAAAA-- ------KKKKGBDACAAABBDACCAAA-- --------HBBDBCCCABBDBAAAACC-- --------DDDBBAAAADBDAACAAAA-- --------CGGDBDDBDDBDAAAAACA-- -------GCBFBFBBBDBBBCCAAAA--- ------IAG-GACCCCAAACAAACCA--- -------FIACACAAAACAACACAAC--- -----GFCAAA-AAACAAAAAAAAA---- ----GIIJIIA---AAACAAACCAA---- ----I------AA---ACAAAAA------ -------F----AAAAAAAAAA------- ---------------AA-AA--------- ----------------C------------ ----------------------------- 
----------------------------- ----------------------------- ----------------------------- ----------------------------- ----------------------------- ----------------------------- ----------------------------- -----------JJ------AAA------- -----------C------CAAAAA----- ----------CAD----CACAAAAC---- ---------BCCBB-AAAAAAAAAA---- ----------AGAAACAAAAAACA----- ----------AFAACAACAAAAAAC---- ----------AFBAAAACCAAAACA---- ---------CCFBAAAAAAAAACAAC--- ---------GGFGACCCAAAAAAAAA--- -----------A-AAAACCAAAAAAA--- ---------G-C-GCAAAACACACAA--- -----------A-FAACAAAACACAA--- ---------I-G--CAACAAAAAAA---- -------II--F--AAAAAACCCAC---- ---------------GAACCAAAA----- -------------F--GAACCCC------ ------------CCCACCAA--------- ----------------GA----------- ----------------------------- ----------------------------- 
----------------------------- ----------------------------- ----------------------------- ----------------------------- ----------------------------- ----------------------------- ----------------------------- ------------------C---------- ------------------CAA-------- ------------------CAAAC------ -------------DD-AAAAAAAC----- ------------BCAAAAAAACAA----- ------------AACACAACAACAA---- -----------AACAAAAAACAACA---- -----------FAAAAACAAAAAAAA--- ---------A-IAAAAAAACACCAC---- ---------I--CACCACAAACACA---- ----------IA-ACAAAAACAAAC---- -------------CACCAAACAACC---- --------------CACACAAAAAA---- ------------A--AAAACCCAC----- ------------CCC-CAAAAAA------ ------------ACA--ACA-C------- --------------A-AA----------- ----------------------------- ----------------------------- ----------------------------- 
----------------------------- ----------------------------- ----------------------------- ----------------------------- ----------------------------- ----------------------------- ----------------------------- ----------------------------- -------------------A--------- -------------------AA-------- -------------AA---AAAA------- --------------C-CAACAAA------ --------------AAAAAAAAAC----- ------------ACCAAAACACCA----- -----------AA-AACACAAAAAC---- ---------I--CAAAAAAAACAAC---- ------------AAACAAACAACCA---- ------------AACCAACAAAAA----- ------------AACAACACCCCC----- ------------CAAAAAAAAAAC----- ------------A-CAAACAAA------- ------------AAA--CAC--------- -----------------A----------- -----------------A----------- ----------------------------- ----------------------------- ----------------------------- 
----------------------------- ----------------------------- ----------------------------- ----------------------------- ----------------------------- ----------------------------- ----------------------------- ----------------------------- ----------------------------- --------------------A-------- ------------------A-AC------- ----------------AA-AAA------- ----------------A--AACCA----- --------------A-ACAAAA------- -----------AA--CCAAAAAAAA---- ------------CA-AACAAAAA------ ------------CAAAAAAC-AC------ ------------CAACAACCAAC------ ------------AAC-ACAA-AA------ ------------C-AACAAAA-------- ------------A--C-CCA--------- --------------C-------------- ----------------------------- ----------------------------- ----------------------------- ----------------------------- ----------------------------- 
----------------------------- ----------------------------- ----------------------------- ----------------------------- ----------------------------- ----------------------------- ----------------------------- ----------------------------- ----------------------------- ----------------------------- ----------------------------- --------------------C-------- ------------------CAAAA------ -----------------AA---------- ------------C----AA-A-------- ------------AA----AA-C------- ------------C-A-CAC---C------ ------------AA--AA---A------- -----------------AAA--------- ------------A--A-AAAC-------- --------------A--AA---------- ----------------------------- ----------------------------- ----------------------------- ----------------------------- ----------------------------- ----------------------------- 
----------------------------- ----------------------------- ----------------------------- ----------------------------- ----------------------------- ----------------------------- ----------------------------- ----------------------------- ----------------------------- ----------------------------- ----------------------------- ----------------------------- --------------------A-------- ---------------------A------- -------------------AA-------- ----------------------------- ----------------------------- ----------------------------- ----------------------------- ----------------------------- ----------------------------- ----------------------------- ----------------------------- ----------------------------- ----------------------------- ----------------------------- ----------------------------- 
