model
size = 29 27 28, scale = 0.05, origin = -y
material 
  colors = A:#111 B:#FC6 C:#222 D:#F4C874 E:#888 F:#AAA G:#EEE H:#DAAF57 I:#202424 J:#B69248 K:#000 L:#404848 M:#BBB N:#777 O:#819191 P:#600 Q:#E00 R:#92763A S:#DDD T:#D3BDA0 U:#996 V:#26200E W:#A2B6B6
voxels
----------------------------- ----------------------------- ----------------------------- ----------------------------- ----------------------------- ----------------------------- ----------------------------- ----------------------------- ----------------------------- ----------------------------- ----------------------------- ----------------------------- ----------------------------- ----------------------------- -----------------A-AA-------- ----------------FACAA-------- -----------------AA---------- ----------------------------- ----------------------------- ----------------------------- ----------------------------- ----------------------------- ----------------------------- ----------------------------- ----------------------------- ----------------------------- ----------------------------- 
----------------------------- ----------------------------- ----------------------------- ----------------------------- ----------------------------- ----------------------------- ----------------------------- ----------------------------- ----------------------------- ----------------------------- ----------------------------- ----------------------------- ----------------------------- ----------------------------- -------------------AC-------- -----------------AAAAC------- ----------------CACAA-------- -----------------AAA--------- -----------------A-AC-------- ----------------A------------ ----------------------------- ----------------------------- ----------------------------- ----------------------------- ----------------------------- ----------------------------- ----------------------------- 
----------------------------- ----------------------------- ----------------------------- ----------------------------- ----------------------------- ----------------------------- ----------------------------- ----------------------------- ----------------------------- ----------------------------- ----------------------------- ----------------------------- ------------------AAA-------- -----------------CAACAA------ -----------------CAAAAA------ ----------------FACACAAA----- -------------EEEAACAAAAA----- ------------ECEAAAACACA------ -------------EAACACCAAC------ -------------CCAAAAAAA------- ---------------AAAA---------- ---------------A------------- ----------------------------- ----------------------------- ----------------------------- ----------------------------- ----------------------------- 
----------------------------- ----------------------------- ----------------------------- ----------------------------- ----------------------------- ----------------------------- ----------------------------- ----------------------------- ----------------------------- ----------------------------- -------------------CC-------- -------------A----AACAC------ -------------AA-FCAAAAA------ ----------------ECAACCA------ ---------------EEAAAAAAA----- --------------EFCAAAAAAAC---- -------------AAAAAAAACAAC---- -------------C-ACCAAAAAC----- ------------EA-CAAACAAAA----- ------------ACACAAAAAAA------ -------------ACAAAAAAA------- --------------CAAAA---------- ----------------------------- ----------------------------- ----------------------------- ----------------------------- ----------------------------- 
----------------------------- ----------------------------- ----------------------------- ----------------------------- ----------------------------- ----------------------------- ----------------------------- ----------------------------- -------------------C--------- -----------------ACAAA------- -------------A-AAAAAAAA------ -------------DA-AAAAAAAA----- -------------DAACAAAAACA----- ------------DCACAAAAACAAA---- ------------GFFAAAACCCACC---- --------------AACAAAAACAA---- -------------GCAAAAAAAAAA---- ------------C-ACACACACAAA---- -----------AA-CACAAAAACAA---- -----------AACCAAAACAACAA---- ------------AACCCCACAAAC----- ------------CAAAACAAAAA------ -------------AACAAA---------- ----------------------------- ----------------------------- ----------------------------- ----------------------------- 
----------------------------- ----------------------------- ----------------------------- ----------------------------- ----------------------------- ----------------------------- ----------------------------- -------------------CAC------- -----------A-----AAACAC------ ----------AAAA--AAAAAAAC----- ----------A-BBA-ACCAAAAA----- ---------GA-DACAAAAACCCCC---- ---------G--BDDCAAACACCAA---- -----------EBBBBBAAAAAAAAA--- -----------ECAACACAAAAAAAA--- -------------EAAAAAAAAACAC--- ----------G--CCCAACAACAAAA--- ----------GGGAAACCCACAAAAA--- ---------GEA-AAACCACAAACCC--- ----------EAAACAAAAACACAA---- -----------AAAACAAAAAAACA---- ------------AAAAAACCAAAA----- ------------CAAACCAAAA------- -------------AACAAA---------- ----------------------------- ----------------------------- ----------------------------- 
----------------------------- ----------------------------- ----------------------------- ----------------------------- ----------------------------- ----------------------------- -----------------A---C------- ------------A-----AAAAAA----- ----------AAACA-CCAAAACAA---- ----------ABCBA-ACAAACAAC---- ---------GBABB-CCAACAAACA---- ----------AADBBAAAACAAAAAA--- ---------CADBDDCAAAAACAAAA--- -----MMMMMCBDDDBBDBBAAACAA--- ---------AMBDBBAAACAAACACAA-- ---------CEAEAACAAAACAAAAAA-- ---------EBCEAAACAACCACAAAC-- ---------EDAAAAAACAAAACAAAA-- --------GFBAAACAAAAAACAAAC--- --------GGFAACAAACACAAACCA--- ----------EACAACCAAAAAAAA---- -----------EACACACAACAAAA---- ------------AAAAAACCAAA------ ------------CAAACAACA-------- ---------------AAAA---------- ----------------------------- ----------------------------- 
----------------------------- ----------------------------- ----------------------------- -----------------AAA--------- -----------------CCA--------- ----------------------------- ------H-----C--AA--AACAC----- --------HHD-A-A-CAACCAAAA---- -------HHBDBABBAACCAAACCAA--- -------BBDBBBABAAAACAAAACA--- ------KDBBDBBBBBAAACAAAAAC--- ------KBBBBBBDDBCCCAACACAA--- ------KDBBBBDBBDCAAACACACCA-- ----MDBDBDBBBBBBDBBBBAACCAA-- -------KDBDDDBDBBBBBBAACAAA-- -------KBDCCAAAAAAAAACCAAAA-- --------DDAAACCACACAAAAAACA-- -------KBBBCCAAAACAAAAACAAA-- -------CBBDAAAAACACAAAAAAAA-- -------EFFBACCCACACAAAAAAAA-- --------GECACAAAACACAAAAAA--- ----------ECCCAACCAAAACAA---- ----------CCACAAAACACAAA----- -----------AAAACACC-AAA------ ------------AAA---ACA-------- ----------------------------- ----------------------------- 
----------------------------- ------------HDBBBBD-B-------- -------------HBBBBBBB-------- ----------------DAAAC-------- ----KDBD-------AAAAAA-------- ----IKDBDBBH---CACA-----A---- ----IKDBBBDBBACAAACAAAAAA---- ----IKKBBDBDBAACAAACAAAAAA--- ----IIKDDDDBDBDBAAAAAAAAAC--- -----IKBDBDDDDBBACAAACCCACA-- -----IBBBBBBDDDBAAAAAAAAAAA-- -N---IBBBBBBBBBBAAAAAAAACCA-- -L---IBBBDBBBDDBAAAAAAAAAAA-- -LMM-BDDDBBBDBBBBDDBBDCAAAA-- ----IIIBDBBBBBBDDBBDACACACAC- ----IIIDBBAAAAACCACAACAAAAAA- -----IIKBDACAAACAAAAAACCAAAA- ----I-KBBDBAACAAAAAAAAAAACA-- -----KBBDBBAAAACCCACCAACAC--- -----NDBBBBCACAAAAAAACCAAAA-- ------GBCAACAAACCAAAAAAACC--- -------GEEAAACAACCAAAACACA--- ---------EAAAACCACAACAAAA---- -----------CCAACAACACACA----- -----------CAAAAACAAAAA------ -------------AACAACC--------- ----------------------------- 
------------D-----D---------- ----------JDBDDDDDBBD-------- ----------JJJDBDBBBDB-------- ----B---BBDDJJBBDAACCA------- ---KBBDBBDBHBBBAAAAAA-------- ---IBDBBDDDBDHDAACAAA-CAC---- ----IBBDBBDBBDBCACACAAAAAA--- ----LBDDBBBBDDBAAACAACAACCA-- ---OLDDBDDBBBBBDAAACAACAAAA-- ---OLBBDBBBBDBBBAACCCAACCAC-- ----WBBBDBBBDBBDAAAAAAAACCA-- -OO-ODBBBBBBBDBDAAAAAACAAAAA- --LLIBBBBBBBBBBDAACAAACCACAA- ---QDBDDDDDDDBBBBDDBBBBAAAAA- -LIIDADDDBBBBBDBDDBDCACAAAAC- ---IBABDDBCAAACACAAAAAAACACA- ---KKDBBBBAACAAAAAAAAACCAACA- ----KIDDBBACAACAAAAAAAACCAAAA ----IBBBDBBAAACCAAAAAACCAAAAA -----KDBDBDAAAACACCCAAAACCC-- -----NBDCACCAAAAAAAAAAAAAA--- ------GDAAAAACACAAAAAAAACA--- -------GACCAAACACACAACCCC---- --------GFAACACCACACAACAA---- -----------AAAAAACAAAAAA----- -----------A--AAAA-C-AC------ -------------ACAAAC---------- 
-----------DDDBBBDDDD-------- ---------JBBBBDDBDBBBB------- ---RDB--BBDBBBDBBBBBD-------- --HDD-DBDBDBBBBBBAAAAA------- --HBBDDDBDDBBDBAACAAAAA------ --HDDBDBBDBBDBBAAACAAAACAA--- ---KBBBBBDBBBDBACACACAAAAAA-- ---IBBDBBBDBDDDACAAAACACCAA-- ----IBDDBBDDDBDBAAAACCCAACAA- ---OLBDDBDBBBBBBCAACCCAACAAC- ---ODBBBBDBDBBBBAAAAAAAAAAAA- -LOODBBBDDBBBDDBAAACAACAAAAA- --LBBDDBDDBBBBBBCAAAACAAAAAA- ---QDBDBBBDDBBDBBBDBDBBDAAAAA -LBDBDBDBDDBBBBDBBBDAAAACCAAA --LDBABBBDAAACAACACAAACCAAAA- ---IDBBDBDACACCAAAAACCACAACC- ---KDDBBDBAAAAAACAAAACCAAAA-- ----IBDBBBAACAAAAACAACAAAAACA ----BBDDBDDAACAAAAAAACAAAAAAC -----DBBAAAACAAAAAACCAACCAA-- -----NBAACACACAAAACAAACCACA-- ------GBAAAAAAAAAAAAAAAAAA--- -------GBAAAACAACACAACAAA---- --------G--ACAAAAAACAAACC---- ------------CAACAACAA-CA----- ------------AA----ACC-------- 
----------JDBBDBBBBBBB------- ---HD---JJBBBDDBBBBDBBD------ ---BBDDDBBDBBBBBBBBBB-------- ---PBBDBBDDBBBBDBAAAAC------- ---PBBDDDBDBBBBCAAAAAA---A--- --HDBBDBDDDDBBDAAAAAAA-AAA--- --HDBDDBDBBBBBBCAACCAAACAAC-- ---KBBBDBBDBDBBAAAACAAAAAA--- ---KDBDDBDDBBBDBAAAAAAACAACA- ---KBDDDDDDBDBDDAAAAACAAACCA- ---ODDDBBDBBBDDBAAAAAACAAAAA- -L-OBDBBDBBBDBDBACACAAAAACAAA --LDBDBDDBDBBDBBCAAACBBDCAAAA ---QBBDDBDDDDBBBBDDDBBBBCCACC -LDBBBDDBDBBBDBBDBDBAACAAAAAA --LBBABDDDBDBBBBBDBDAAACAAACC --IBDBBBBDAAACAAAAAAACAAAACCA ---LDDBDBBAACAAAACAAAACACAAAC ---IDDBDBDACAAACAAAAACAAAACA- ----BBDDBDACAACCCACAAAACACAAA ----BDDBDDBAAAAAAAAAAACAAAAA- ----DBBCAAAAAAACCAAACAAAAAA-- -----GBDAAAAAAAACACCACACAA--- ------G-ACAAACACAAAAAACAAC--- --------CAACAAAAAACAAAA-A---- ---------A-AACCACAAACA-C----- -----------A--ACAA---A------- 
---------JDBDBBBDBBDBB------- --HDDD--BBBBBBDDDBBBDBD------ --HBDDBBBBBBDBBBDBDBBD------- --HBDBBBDBDBBBBDBAACAA------- ----PBDDBBDBBBBBAAAACA-C----- ---PBDBBDDDBBBDBAAAACC-CAAA-- --DBBBBBDDDBBBBBCACAAAAACCA-- ----BBDBBBBDDBDBACAACAAAAAAC- ---BDBBBBDDBBDDBCAAAACAAAAAA- ---KDBBDBBDBDBBBAAAAAAAAACAA- ---OBDBBDBDBBDBBAAACCCCAAAACC -IODDBBBBBBBDBBBAAAAAACCACCAA --LBBBDBBDBBDDDBDDBBBDBBAAAC- ---QBBBDDBDDBBBDBBDBBBDBCAAA- --LBBBBBDBDDBDBBBDBBDACCACAC- --LBDBBBDBBBDBBBDBBBCAACAAAAA --IBDBDBDBAAAACAACCCAAAAAACAA ---KDBBDBBAAACAAAAAACAAACCACA ---IBDBBBBAAAAAACAAAAAAACAAA- ----IBBBBBCAAAAAACCAAAAAAACA- ----BDDBBBAAACAAAAACACAAACAA- -----BBACAAAACACCAAACAAAAA--- -----FBAAAAAACACAAACAACCAAA-- -----C-FAACAAAAAAAAAAACAAA--- ---------AAACAAAAAAAACAAC---- ---------ACAACACAAAAAC-A----- -------------CAACA---A------- 
---------BBBDDBDBBBBBD------- --DDDD--BBDBBBDBDBBDBBD------ --DDDDDBDBBDDBBBBDBBBB------- --BBDDBBBBBDBBDBBBBBB-------- ----PBDDBDDBBDBBAAACC--A----- ---PDBBBBBBDBBBBAACAA--CAAC-- --BDBBBBBBBBBBBBAAAAAAAACAA-- ---BBDBBDBDBBBBBACAACAACAAAA- ---DBBBDBBBBBBDDAAAAACAACAAC- --BBDBDBDBBDBDBBAAAAAACCACCA- BBDBBDBDDDBDBBDDAAAAACACCAAAA BBBBBDDDBDBDBDBBAAACACCACCAC- --KBBDBBBBDBDDDBBBBBDDBDACAA- --KBBDDBBDBDBBDDBBBBBBBDAAAA- --IBBBDBBBBBBBBBDBBBBACAAAAA- --KBBBBDBBBBBBBBDDBBDCACAAAA- --KBBBBBBBAACAAAAAACAAAAAACA- ---IBBDBDDACAACCAAAAAACAAAAAA ---KBDBBBBCAACAAAAAAACAACAAAA ----IDDBBBAAAAAAAACCCAAAAAC-- ----DBDBBBCCACAAACCAAAAACAAA- -----DBBDBAAAACCAAACACCAACA-- ----U-BBACCCCAACCAAAAACACA--- -----E--CAACCAAACAACCAAAAA--- ------A-AACAAAACCACCAAAAA---- -------AACAACCAAAAAAAACC----- ---------AAACAACA---CA------- 
---------BBBDBDDBBDBBB------- --DBDD--BBBBBBBBBBDDBDD------ --DDDDBDBDDBBBBBBBDDBB------- --DDBDDDBBBBDBDBDBDBB--A----- ----PBBDBDDBBBDBAAACCC------- ---PDBBDBBBBBDDDAAAAA--AAA--- --BBBBBBBDBBDBDBACACCCCCAAA-- ---BBDBBDBBBBDBBAAAAAACCAAAC- ---DDBBBBDBDBBBBAAAACAAAAAAA- --BBBBBBDBDBBDBBAAAACACAAACC- BBDBDBBDBBBDBBBBACACAAAAAACAA BDDDDBDDBBDBDDDBACAACAACAAAAA --LBBBBBDBBBBBDBBBBDBDDDCCAAA --LDBBDDBBDBBBBDBBBBBDBDAAACA --BBBBBBBBDBBBDBBDBBDAACAACCC --BBDBBBDBBBDBBDBBDDBAAAACAAA --DDBDDBBBAAAAACAAACACCACAAAC ---DBBBDBBAAAAACCACAACACACAA- ---KDDBDBDAAAAAAACAAAAAACAAC- ---IDBDDBBCAAAAACCAAACAACAA-- ----DDBBDBACAAACCCAAAACAAAAA- ---F-BBDBBCACAAAAACAACACCCA-- ----AFBBBBCAAACAAAAAAACAAA--- ------GEFFAAAAAAACAAACAAAA--- -----E----FAACCCAACAACCAA---- ----------AAAACCAAAAAA-A----- ----------AAAAAAACAC-C------- 
----------BDDBDBBBBBDD------- --HDHD--BBBDDDDBDBBBDBD------ --DBBBBBDDBDBDBBBDDDDB------- --HBBBBBBDDDDBBBDDDDB--A----- ----PDDBBBBBDBBBCCCAAAA------ ---PDBDBBBBBDDBBAAACC--AAA--- --BBDBBDBBBBBBDBAAAAAAACAAC-- ---DDBBDBBBBBDBDAACAAACAAAA-- ---DBBBBBDBDDBDBCAACAAAAACAC- ---DDBDBBBBDDBBBAACACAACAAAA- -NBBDBDDBBBBBBBBAAAAAAAAACCA- -EBBDBBBBDDDBBDBACCCAACAAAAA- -MBDBBBDBBBBBDBBBDBDDBDBAAAAC ----QBBBDDDBBBBDDBBDBAAACCAAA -LJDDBDBBBBBDDBDBDBDBACCAAAAA --JDDABBDBBDDBBBBBBBDCAAAAAAA --ABBBBBBDDDBDDAACACAACAAAACA ---BBDBDBDCAACAAAAAAACCCAACC- ---DBBDBBDAAAACCCAAACAAAAAAA- ----BBDDBBCCCAAAACCAAAACAAAA- ----DBBBBBCCAAAAAAAAAACACAA-- ---EEBBDDDCCAAAAAACAAAACCAC-- -----FFDDDAAAACAAACAAAAAAA--- -------GFDCAAAACACAAAAACCA--- -----E----FAAAAAAAAAAAAAA---- -----F-AAAACCAAACCAACA-A----- -------A-AACAAAAAAA--A------- 
-----------BBBBBDDDBBB------- ---HDD--DDDBDBBBBBBBDD------- ---H-BDDBBBDBBDDBBDDB-------- ---PBBBDDBBDBBBDBDBBB-------- ---PBDBBBBDBBDDBAAAAACAA----- --HDDBDBDBDDBBDDAAACAACAAA--- --HBBDBDDBBBBDBBAAAACCCAAA-A- ---R-BBDBDBBDBBBCCAAAAAAAAC-- ---HBBDDBDBBDDBBAAAACCAAAAA-- ---JDDBDDDDDBDDDCCACAAACAAAA- -N-BBBBBBBDBDBBDAAAAAAAACAAA- -JBBDBBDDBBBBBBDCAAACCCAAAAC- --BDDDBDDDBBBDDBBDBDBBDCAAAC- ----QBDDBBBBBBDDDBBBBAACAACAC -TBBBBBBBDDBDDDBBDBBDCAACAACC --VBBABBBDBBBDDBBDDBDAACCCAA- --BDDBBDDBBBBBBDDBBBBAAAAAAA- ---BBDDDBBCAAAAACAAACAAAAAAA- ----BBBBBDCCAAAAACCCCACAAAC-- ----BBBBDBAAACCAAAAAAAAAACAA- ---E-BBBDBCAACCCACAAAAAAACC-- ----GEDBDBACAAAAAAAACCCACAA-- ---GFA-EDBAACCAAAAAACAACCA--- --------EFCACACAAACAAACAC---- -------EC-AAAAAAAAAAAAAA----- -------AAAAAAAAAAACAAA------- ---------CAAAACAAA---C------- 
------------BBBBDBDDB-------- ----------JHDBBBBDDBBD------- ---D-DB--DDDBBBBBBBBB-------- --HDDBDDBBBBBBDBBBBBD-------- --HDDBDBAABDBDBBAACACAA------ --HBBBBDDDDDBBBBCAAAA--AA---- ---JBDBBDBBBDBDBA-CCCCCACA--- ---JDBBDDBBBBBBBCCAAAACAAAAA- ----JBDBDBDDDBDDAAAAACAAAAA-- ----JBDBBBBBBBBBACACCCACAACC- -N--BDBBBBBDDBBDAACAAAAAAA-C- -JB-BBBBBBBDDBDBAAAAACACCACA- --D-BBBBBDBBBDDBBDBBBDBAAAAC- ----QBDBDBDBBDDBDDBDBCCAAAAA- -TBBDABBDBBBDBBBBBDBBAAAAAAA- --ABBCBBBBBDBBBBDDDBBAAAAAAC- ---BDBBBDDBBDBDDBBBBBACCACAA- ----BBDDBBCCCACCCACACAAACAAA- ----DDDBBDAAAAAAAAAAAAAAAAC-- ---GABBBBDAACCACACAACCCACAA-- ----CEBBDBCCAAAAAACAAAACAA--- ---EAFEFDBACAACAAAACCAACACA-- -----F--FBAAAAACACAAAACAAA--- ----F-----AAAAAACACAAAAAC---- ----E-C--ACAAAAAAAAAAAAA----- -------CC--AAAAACAACAAA------ -----------CCAAAA---A-A------ 
----------------------------- ------------HBBDBBBBD-------- -------------JDDBBBDB-------- -----J-----JBBDDBBBB--------- ---J--BBBDDABB-AACACAAA------ ---JBD-DBBAADDBC-CCA---A----- ---RDBBBDBBRDDD--AAAAACACA--- ----RBBDDDBDBBBBAAAAACCCAA-A- ----JBDBBBDBBBDD-AAAAAAAAAC-- ----JDDBBDDDDBDDAAACCCAAAAA-- -N-BJJBDBDBDBBBBCAAAAAACAAAA- ---BBBBBDBBDDDBDBBDBBBAAACAC- ----BBBBDBBBBBBBBBDBBDCAAAA-- ----QQBBBDDBBBDBDBBBDDAAACAA- --TBBBDBBBBDBDBBDBBBBDAAACAA- ---JVDBDBBBDBBBDBBBBBBACACCA- ----BBBBDBBBDDDDDDDDBBCACAAA- -----GDBBBACAACAAAAAAAACAACA- ---GABBBBDAACAAAAACCAAACACA-- --GU-EDBBBCACCACACACAACCAAA-- --GFF--BDBCAAAAAAAAAACAAAA--- --GEF--ADBACAAAACACCAAACC---- ----F---NACCAAAAACCACAACC---- -----E---AAACCAAAACAAAAA----- ------A---AAAAAACACCACA------ ------A----AAAAAAAAAAA------- ------------A-AA-AAA-A------- 
----------------------------- ----------------HDBBB-------- --------------HDDBBB--------- ------------J-BDDB----------- ------------A-----CC-A------- -------B----AAA--ACA--------- ----HB-HHHR-A-AAAC-AACAAA---- ----JBDBHBBBB--A-CCAAAACCC--- ----JDBBAHDBADACACAAAAAACAA-- -----JBDBDDDBBAAAAAACACAAA--- ------DDBBBBBDACCAAAACAAAA-A- -N----BBBBBDBBAAAACAACAACAA-- -M----DBDBBDBDBBBBBBBAAAAAA-- -SSSMSBBBBBBDBBBDBBBDACACCA-- ------JDBBDBBBBBBBDDBCAAAAA-- ------DDDBBBDBDBBBBDBAAAAAAA- ------DBDBBDBBDBDBDBDACAAAA-- -----C-BDBAAACACACACAAACCAA-- -----FFBDFAAAAAAAAAACACACA--- ------EDEBAAAAACCACAAACAAC--- --GE-FC-BDAAAACCCAAAAAACCA--- ----FAN-EAAAAAAACAACCCAAA---- ----FF---AAACCCAAACCAAAC----- ------F---AAAACCAAAAAAC------ ------A----AACCAAAAACA------- --------------ACCACAA-------- ----------------C------------ 
----------------------------- ----------------------------- ----------------------------- ----------------------------- --------------A----AA-------- -------------A--------------- -----------------A----------- -----------AA-----AAACAA----- ----------ABB----ACAAACAA---- ---------DBDCC-AAAACAAAAAC-C- --------BBCADBCCAACAACCAA---- --------DABBBACCACCAACAAAAAA- --------ABDBDCAAAAACAAAAAAA-- ------MMMMFBDACAAABBDACCAAA-- --------JBBDBCCCABBDBAAAACC-- --------DDDBBAAAADBDAACAAAA-- --------CFFDBDDBDDBDAAAAACA-- -------FCBEBEBBBDBBBCCAAAA--- ------GAF-FACCCCAAACAAACCA--- -------EGACACAAAACAACACAAC--- -----FECAAA-AAACAAAAAAAAA---- ----FGGNGGA---AAACAAACCAA---- ----G------AA---ACAAAAA------ -------E----AAAAAAAAAA------- ---------------AA-AA--------- ----------------C------------ ----------------------------- 
----------------------------- ----------------------------- ----------------------------- ----------------------------- ----------------------------- ----------------------------- ----------------------------- -----------NN------AAA------- -----------C------CAAAAA----- ----------CAD----CACAAAAC---- ---------BCCBB-AAAAAAAAAA---- ----------AFAAACAAAAAACA----- ----------AEAACAACAAAAAAC---- ----------AEBAAAACCAAAACA---- ---------CCEBAAAAAAAAACAAC--- ---------FFEFACCCAAAAAAAAA--- -----------A-AAAACCAAAAAAA--- ---------F-C-FCAAAACACACAA--- -----------A-EAACAAAACACAA--- ---------G-F--CAACAAAAAAA---- -------GG--E--AAAAAACCCAC---- ---------------FAACCAAAA----- -------------E--FAACCCC------ ------------CCCACCAA--------- ----------------FA----------- ----------------------------- ----------------------------- 
----------------------------- ----------------------------- ----------------------------- ----------------------------- ----------------------------- ----------------------------- ----------------------------- ------------------C---------- ------------------CAA-------- ------------------CAAAC------ -------------DD-AAAAAAAC----- ------------BCAAAAAAACAA----- ------------AACACAACAACAA---- -----------AACAAAAAACAACA---- -----------EAAAAACAAAAAAAA--- ---------A-GAAAAAAACACCAC---- ---------G--CACCACAAACACA---- ----------GA-ACAAAAACAAAC---- -------------CACCAAACAACC---- --------------CACACAAAAAA---- ------------A--AAAACCCAC----- ------------CCC-CAAAAAA------ ------------ACA--ACA-C------- --------------A-AA----------- ----------------------------- ----------------------------- ----------------------------- 
----------------------------- ----------------------------- ----------------------------- ----------------------------- ----------------------------- ----------------------------- ----------------------------- ----------------------------- -------------------A--------- -------------------AA-------- -------------AA---AAAA------- --------------C-CAACAAA------ --------------AAAAAAAAAC----- ------------ACCAAAACACCA----- -----------AA-AACACAAAAAC---- ---------G--CAAAAAAAACAAC---- ------------AAACAAACAACCA---- ------------AACCAACAAAAA----- ------------AACAACACCCCC----- ------------CAAAAAAAAAAC----- ------------A-CAAACAAA------- ------------AAA--CAC--------- -----------------A----------- -----------------A----------- ----------------------------- ----------------------------- ----------------------------- 
----------------------------- ----------------------------- ----------------------------- ----------------------------- ----------------------------- ----------------------------- ----------------------------- ----------------------------- ----------------------------- --------------------A-------- ------------------A-AC------- ----------------AA-AAA------- ----------------A--AACCA----- --------------A-ACAAAA------- -----------AA--CCAAAAAAAA---- ------------CA-AACAAAAA------ ------------CAAAAAAC-AC------ ------------CAACAACCAAC------ ------------AAC-ACAA-AA------ ------------C-AACAAAA-------- ------------A--C-CCA--------- --------------C-------------- ----------------------------- ----------------------------- ----------------------------- ----------------------------- ----------------------------- 
----------------------------- ----------------------------- ----------------------------- ----------------------------- ----------------------------- ----------------------------- ----------------------------- ----------------------------- ----------------------------- ----------------------------- ----------------------------- --------------------C-------- ------------------CAAAA------ -----------------AA---------- ------------C----AA-A-------- ------------AA----AA-C------- ------------C-A-CAC---C------ ------------AA--AA---A------- -----------------AAA--------- ------------A--A-AAAC-------- --------------A--AA---------- ----------------------------- ----------------------------- ----------------------------- ----------------------------- ----------------------------- ----------------------------- 
----------------------------- ----------------------------- ----------------------------- ----------------------------- ----------------------------- ----------------------------- ----------------------------- ----------------------------- ----------------------------- ----------------------------- ----------------------------- ----------------------------- --------------------A-------- ---------------------A------- -------------------AA-------- ----------------------------- ----------------------------- ----------------------------- ----------------------------- ----------------------------- ----------------------------- ----------------------------- ----------------------------- ----------------------------- ----------------------------- ----------------------------- ----------------------------- 
----------------------------- ----------------------------- ----------------------------- ----------------------------- ----------------------------- ----------------------------- ----------------------------- ----------------------------- ----------------------------- ----------------------------- ----------------------------- ----------------------------- ----------------------------- ---------------------C------- ----------------------------- ----------------------------- ----------------------------- ----------------------------- ----------------------------- ----------------------------- ----------------------------- ----------------------------- ----------------------------- ----------------------------- ----------------------------- ----------------------------- ----------------------------- 
