model
size = 24 24 18, scale = 0.05, origin = -y
material 
  colors = A:#202020 B:#FFD319 C:#FF901F D:#FF2975 E:#F222FF F:#8C20FF G:#01CDFE H:#6498CC
voxels
---FFFFFFFFFFFFFFFFFF--- ---EEEEEEEEEEEEEEEEEE--- ---EEEEEEEEEEEEEEEEEE--- ---DDDDDDDDDDDDDDDDDD--- ---DDDDDDDDDDDDDDDDDD--- ---CCCCCCCCCCCCCCCCCC--- ---CCCCCCCCCCCCCCCCCC--- ---BBBBBBBBBBBBBBBBBB--- ---BBBBBBBBBBBBBBBBBB--- ------------------------ ------------------------ ------------------------ ------------------------ ------------------------ ------------------------ ------------------------ ------------------------ ------------------------ ------------------------ ------------------------ ------------------------ ------------------------ ------------------------ ------------------------ 
---FFFFFFFFFFFFFFFFFF--- ---EFFHHHHHHHHHHHHHHE--- ---EBBBBBBBBBBBBBBBBE--- ---DGGGGGGGGGGGGGGGGD--- ---DGGGGGGGGGGGGGGGGD--- ---CCCCCCCCCCCCCCCCCC--- ---CGGGGGGGGGGGGGGGGC--- ---BBBBBBBBBBBBBBBBBB--- ---BBBBBBBBBBBBBBBBBB--- ------------------------ ------------------------ ------------------------ ------------------------ ------------------------ ------------------------ ------------------------ ------------------------ ------------------------ ------------------------ ------------------------ ------------------------ ------------------------ ------------------------ ------------------------ 
---FFFFFFFFFFFFFFFFFF--- ---EEEEEEEEEEEEEEEEEE--- ---EEEEEEEEEEEEEEEEEE--- ---DDDDDDDDDDDDDDDDDD--- ---DDDDDDDDDDDDDDDDDD--- ---CCCCCCCCCCCCCCCCCC--- ---CCCCCCCCCCCCCCCCCC--- ---BBBBBBBBBBBBBBBBBB--- ---BBBBBBBBBBBBBBBBBB--- ------------------------ ------------------------ ------------------------ ------------------------ ------------------------ ------------------------ ------------------------ ------------------------ ------------------------ ------------------------ ------------------------ ------------------------ ------------------------ ------------------------ ------------------------ 
AAA------------------AAA AAA------------------AAA AAA------------------AAA AAA------------------AAA AAA------------------AAA AAA------------------AAA AAA------------------AAA AAA------------------AAA AAA------------------AAA AAAAAAAAAAAAAAAAAAAAAAAA AAAAAAAAAAAAAAAAAAAAAAAA AAAAAAAAAAAAAAAAAAAAAAAA ---AAAAAAAAAAAAAAAAAA--- ---AAAAAAAAAAAAAAAAAA--- ---AAAAAAAAAAAAAAAAAA--- ------------------------ ------------------------ ------------------------ ------------------------ ------------------------ ------------------------ ------------------------ ------------------------ ------------------------ 
AAA------------------AAA AAA------------------AAA AAA------------------AAA AAA------------------AAA AAA------------------AAA AAA------------------AAA AAA------------------AAA AAA------------------AAA AAA------------------AAA AAAAAAAAAAAAAAAAAAAAAAAA AAAAAAAAAAAAAAAAAAAAAAAA AAAAAAAAAAAAAAAAAAAAAAAA ---AAAAAAAAAAAAAAAAAA--- ---AAAAAAAAAAAAAAAAAA--- ---AAAAAAAAAAAAAAAAAA--- ------------------------ ------------------------ ------------------------ ------------------------ ------------------------ ------------------------ ------------------------ ------------------------ ------------------------ 
AAA------------------AAA AAA------------------AAA AAA------------------AAA AAA------------------AAA AAA------------------AAA AAA------------------AAA AAA------------------AAA AAA------------------AAA AAA------------------AAA AAAAAAAAAAAAAAAAAAAAAAAA AAAAAAAAAAAAAAAAAAAAAAAA AAAAAAAAAAAAAAAAAAAAAAAA ---AAAAAAAAAAAAAAAAAA--- ---AAAAAAAAAAAAAAAAAA--- ---AAAAAAAAAAAAAAAAAA--- ------------------------ ------------------------ ------------------------ ------------------------ ------------------------ ------------------------ ------------------------ ------------------------ ------------------------ 
AAA------------------AAA AAA------------------AAA AAA------------------AAA AAA------------------AAA AAA------------------AAA AAA------------------AAA AAA------------------AAA AAA------------------AAA AAA------------------AAA AAAAAAAAAAAAAAAAAAAAAAAA AAAAAAAAAAAAAAAAAAAAAAAA AAAAAAAAAAAAAAAAAAAAAAAA ---AAAAAAAAAAAAAAAAAA--- ---AAAAAAAAAAAAAAAAAA--- ---AAAAAAAAAAAAAAAAAA--- ------------------------ ------------------------ ------------------------ ------------------------ ------------------------ ------------------------ ------------------------ ------------------------ ------------------------ 
AAA------------------AAA AAA------------------AAA AAA------------------AAA AAA------------------AAA AAA------------------AAA AAA------------------AAA AAA------------------AAA AAA------------------AAA AAA------------------AAA AAAAAAAAAAAAAAAAAAAAAAAA AAAAAAAAAAAAAAAAAAAAAAAA AAAAAAAAAAAAAAAAAAAAAAAA -A-AAAAAAAAAAAAAAAAAA-A- -A-AAAAAAAAAAAAAAAAAA-A- -D-AAAAAAAAAAAAAAAAAA-D- -C--------------------C- -B--------------------B- ------------------------ ------------------------ ------------------------ ------------------------ ------------------------ ------------------------ ------------------------ 
AAA------------------AAA AAA------------------AAA AAA------------------AAA AAA------------------AAA AAA------------------AAA AAA------------------AAA AAA------------------AAA AAA------------------AAA AAA------------------AAA AAAAAAAAAAAAAAAAAAAAAAAA AAAAAAAAAAAAAAAAAAAAAAAA AAAAAAAAAAAAAAAAAAAAAAAA AABAAAAAAAAAAAAAAAAAABAA AAFAAAAAAAAAAAAAAAAAAFAA AACAAAAAAAAAAAAAAAAAACAA AA--------------------AA AA--------------------AA AA--------------------AA AA--------------------AA AA--------------------AA A----------------------A D----------------------D C----------------------C B----------------------B 
AAA------------------AAA AAA------------------AAA AAA------------------AAA AAA------------------AAA AAA------------------AAA AAA------------------AAA AAA------------------AAA AAA------------------AAA AAA------------------AAA AAAAAAAAAAAAAAAAAAAAAAAA AAAAAAAAAAAAAAAAAAAAAAAA AAAAAAAAAAAAAAAAAAAAAAAA AABAAAAAAAAAAAAAAAAAABAA AAFAAAAAAAAAAAAAAAAAAFAA AACAAAAAAAAAAAAAAAAAACAA AA--------------------AA AA--------------------AA AA--------------------AA AA--------------------AA AA--------------------AA A----------------------A D----------------------D C----------------------C ------------------------ 
AAA------------------AAA AAA------------------AAA AAA------------------AAA AAA------------------AAA AAA------------------AAA AAA------------------AAA AAA------------------AAA AAA------------------AAA AAA------------------AAA AAAAAAAAAAAAAAAAAAAAAAAA AAAAAAAAAAAAAAAAAAAAAAAA AAAAAAAAAAAAAAAAAAAAAAAA -A-AAAAAAAAAAAAAAAAAA-A- -A-AAAAAAAAAAAAAAAAAA-A- -D-AAAAAAAAAAAAAAAAAA-D- -C--------------------C- -B--------------------B- ------------------------ ------------------------ ------------------------ ------------------------ ------------------------ ------------------------ ------------------------ 
AAA------------------AAA AAA------------------AAA AAA------------------AAA AAA------------------AAA AAA------------------AAA AAA------------------AAA AAA------------------AAA AAA------------------AAA AAA------------------AAA AAAAAAAAAAAAAAAAAAAAAAAA AAAAAAAAAAAAAAAAAAAAAAAA AAAAAAAAAAAAAAAAAAAAAAAA ---AAAAAAAAAAAAAAAAAA--- ---AAAAAAAAAAAAAAAAAA--- ---AAAAAAAAAAAAAAAAAA--- ------------------------ ------------------------ ------------------------ ------------------------ ------------------------ ------------------------ ------------------------ ------------------------ ------------------------ 
---AAA------------AAA--- ---AAA------------AAA--- ---AAA------------AAA--- ---AAA------------AAA--- ---AAA------------AAA--- ---AAA------------AAA--- ---AAA------------AAA--- ---AAA------------AAA--- ---AAA------------AAA--- ---AAAAAAAAAAAAAAAAAA--- ---AAAAAAAAAAAAAAAAAA--- ---AAAAAAAAAAAAAAAAAA--- ------AAAAAAAAAAAA------ ------AAAAAAAAAAAA------ ------AAAAAAAAAAAA------ ------------------------ ------------------------ ------------------------ ------------------------ ------------------------ ------------------------ ------------------------ ------------------------ ------------------------ 
---AAA------------AAA--- ---AAA------------AAA--- ---AAA------------AAA--- ---AAA------------AAA--- ---AAA------------AAA--- ---AAA------------AAA--- ---AAA------------AAA--- ---AAA------------AAA--- ---AAA------------AAA--- ---AAAAAAAAAAAAAAAAAA--- ---AAAAAAAAAAAAAAAAAA--- ---AAAAAAAAAAAAAAAAAA--- ------AAAAAAAAAAAA------ ------AAAAAAAAAAAA------ ------AAAAAAAAAAAA------ ------------------------ ------------------------ ------------------------ ------------------------ ------------------------ ------------------------ ------------------------ ------------------------ ------------------------ 
---AAA------------AAA--- ---AAA------------AAA--- ---AAA------------AAA--- ---AAA------------AAA--- ---AAA------------AAA--- ---AAA------------AAA--- ---AAA------------AAA--- ---AAA------------AAA--- ---AAA------------AAA--- ---AAAAAAAAAAAAAAAAAA--- ---AAAAAAAAAAAAAAAAAA--- ---AAAAAAAAAAAAAAAAAA--- ------AAAAAAAAAAAA------ ------AAAAAAAAAAAA------ ------AAAAAAAAAAAA------ ------------------------ ------------------------ ------------------------ ------------------------ ------------------------ ------------------------ ------------------------ ------------------------ ------------------------ 
------AAAAAAAAAAAA------ ------AAAAAAAAAAAA------ ------AAAAAAAAAAAA------ ------AAAAAAAAAAAA------ ------AAAAAAAAAAAA------ ------AAAAAAAAAAAA------ ------AAAAAAAAAAAA------ ------AAAAAAAAAAAA------ ------AAAAAAAAAAAA------ ------AAAAAAAAAAAA------ ------AAAAAAAAAAAA------ ------AAAAAAAAAAAA------ ------------------------ ------------------------ ------------------------ ------------------------ ------------------------ ------------------------ ------------------------ ------------------------ ------------------------ ------------------------ ------------------------ ------------------------ 
------AAAAAAAAAAAA------ ------AAAAAAAAAAAA------ ------AAAAAAAAAAAA------ ------AAAAAAAAAAAA------ ------AAAAAAAAAAAA------ ------AAAAAAAAAAAA------ ------AAAAAAAAAAAA------ ------AAAAAAAAAAAA------ ------AAAAAAAAAAAA------ ------AAAAAAAAAAAA------ ------AAAAAAAAAAAA------ ------AAAAAAAAAAAA------ ------------------------ ------------------------ ------------------------ ------------------------ ------------------------ ------------------------ ------------------------ ------------------------ ------------------------ ------------------------ ------------------------ ------------------------ 
------AAAAAAAAAAAA------ ------AAAAAAAAAAAA------ ------AAAAAAAAAAAA------ ------AAAAFFFFAAAA------ ------AAAAEAAEAAAA------ ------AAAADAADAAAA------ ------AAAACAACAAAA------ ------AAAABBBBAAAA------ ------AAAAAAAAAAAA------ ------AAAAAAAAAAAA------ ------AAAAAAAAAAAA------ ------AAAAAAAAAAAA------ ------------------------ ------------------------ ------------------------ ------------------------ ------------------------ ------------------------ ------------------------ ------------------------ ------------------------ ------------------------ ------------------------ ------------------------ 
