model
size = 10, scale = 0.05, origin = -y
material 
  colors = A:#339 B:#336 C:#DDD D:#100 E:#6FC F:#555 G:#C90
voxels
---------- ----CC---- ECECEECECE ---------- -ECECCECE- ----CC---- C--CCCC--C CCCCGGCCCC ---CCCC--- ---------- 
-B------B- BBBBAABBBB AAAAAAAAAA A--------A -AAAAAAAA- A--AAAA--A A--AAAA--A AAAAAAAAAA -AAAAAAAA- ----CC---- 
-BBBBBBBB- BAAAAAAAAB AAAAAAAAAA ADFDFFDFDA AAAAAAAAAA ADDAAAADDA ADDAAAADDA AAAAAAAAAA -AAAAAAAA- --CCCCCC-- 
-B------B- BABBBBBBAB AAAAAAAAAA AAAAAAAAAA AAAAAAAAAA AAAAAAAAAA AAAAAAAAAA AAAAAAAAAA AAAAAAAAAA --CCCCCC-- 
-B------B- BAB----BAB AAABBBBAAA AAAAAAAAAA AAAAAAAAAA AAAAAAAAAA AAAAAAAAAA AAAAAAAAAA AAAAAAAAAA -CCCCCCCC- 
-B------B- BAB----BAB AAABBBBAAA BAAAAAAAAB AAAAAAAAAA AAAAAAAAAA AAAAAAAAAA AAAAAAAAAA AABAAAABAA -C-CCCC-C- 
-B------B- BAB----BAB AAABBBBAAA AAAAAAAAAA AAAAAAAAAA AAAAAAAAAA AAAAAAAAAA AAAAAAAAAA AAAAAAAAAA -CCCCCCCC- 
-B------B- BABBBBBBAB AAAAAAAAAA BAAAAAAAAB AAAAAAAAAA AAAAAAAAAA AAAAAAAAAA AAAAAAAAAA AAAABBAAAA -CCC--CCC- 
-BBBBBBBB- BAAAAAAAAB AAAAAAAAAA AAAAAAAAAA AAAAAAAAAA AAAAAAAAAA AAAAAAAAAA AAAAAAAAAA AAAABBAAAA -CCC--CCC- 
---------- BBBBBBBBBB AAAAAAAAAA BABABBABAB AAAAAAAAAA BAAABBAAAB AAAABBAAAA AAAAAAAAAA -AAABBAAA- --CC--CC-- 
