model
size = 17 28 15, scale = 0.05, origin = -y
material 
  colors = A:#369 B:#AAA C:#39C D:#444 E:#F90 F:#DDD G:#111
voxels
----------------- ----------------- ----------------- ----------------- ----------------- ----------------- ----------------- ----------------- ----------------- ----------------- ----------------- ----------------- ----------------- ----------------- ----------------- ----------------- ----------------- ----------------- ----------------- ----------------- ----------------- ----------------- ----------------- ------EEEEE------ ------EEEEE------ ----------------- ----------------- ----------------- 
----------------- ----------------- ----------------- ----------------- ----------------- ----------------- ----------------- ----------------- ----------------- ----------------- ----------------- ----------------- ----------------- ----------------- ----------------- ----------------- ----------------- ----------------- ----------------- ----------------- ----------------- ----------------- ----------------- ------EEEEE------ ------EEEEE------ ----------------- ----------------- ----------------- 
----------------- ----------------- ----------------- ----------------- ----------------- ----------------- ----------------- ----------------- ----------------- ----------------- ----------------- ----------------- ----------------- ----------------- ----------------- ----------------- ----------------- ----------------- ----------------- ----------------- ----------------- ----------------- ----------------- ------EEEEE------ ------EEEEE------ ----------------- ----------------- ----------------- 
---EEEEE-EEEEE--- ----------------- ---BBBBBBBBBBB--- ---BBBBBBBBBBB--- ---BBBBBBBBBBB--- ---BBBBBBBBBBB--- ---BBBBBBBBBBB--- ---BBBBBBBBBBB--- ---BBBBBBBBBBB--- ---BBBBBBBBBBB--- ---BBBBBBBBBBB--- ---BBBBBBBBBBB--- ---BBBBBBBBBBB--- ---BBBBBBBBBBB--- ---BBBBBBBBBBB--- ---BBBBBBBBBBB--- ---BBBBBBBBBBB--- ---BBBBBBBBBBB--- ---BBBBBBBBBBB--- ---BBBBBBBBBBB--- ---BBBBBBBBBBB--- ---FFFFFFFFFFF--- ---AAAAAAAAAAA--- ---AAAAAAAAAAA--- ---AAAAAAAAAAA--- ---AAAACCCAAAA--- ---AAAACCCAAAA--- ---CCCCCCCCCCC--- 
---EEEEE-EEEEE--- ----------------- ---BBBBBBBBBBB--- ---BBBBBBBBBBB--- ---BBBBBBBBBBB--- ---BBBBBBBBBBB--- ---BBBBBBBBBBB--- ---BBBBBBBBBBB--- ---BBBBBBBBBBB--- ---BBBBBBBBBBB--- ---BBBBBBBBBBB--- ---BBBBBBBBBBB--- ---BBBBBBBBBBB--- ---BBBBBBBBBBB--- ---BBBBBBBBBBB--- ---BBBBBBBBBBB--- ---BBBBBBBBBBB--- ---BBBBBBBBBBB--- ---BBBBBBBBBBB--- ---BBBBBBBBBBB--- ---BBBBBBBBBBB--- ---FFFFFFFFFFF--- ---AAAAAAAAAAA--- --GAAAAAAAAAAAG-- --GAAAAAAAAAAAG-- --GAAAAAAAAAAAG-- --FAAAAAAAAAAAF-- ---CCCCCCCCCCC--- 
---EEEEE-EEEEE--- ----------------- ---BBBBBBBBBBB--- ---BBBBBBBBBBB--- ---BBBBBBBBBBB--- ---BBBBBBBBBBB--- ---BBBBBBBBBBB--- ---BBBBBBBBBBB--- ---BBBBBBBBBBB--- ---BBBBBBBBBBB--- ---BBBBBBBBBBB--- ---BBBBBBBBBBB--- ---BBBBBBBBBBB--- ---BBBBBBBBBBB--- ---BBBBBBBBBBB--- ---BBBBBBBBBBB--- ---BBBBBBBBBBB--- ---BBBBBBBBBBB--- ---BBBBBBBBBBB--- ---BBBBBBBBBBB--- ---BBBBBBBBBBB--- ---FFFFFFFFFFF--- ---AAAAAAAAAAA--- --GAAAAAAAAAAAG-- --GAAAAAAAAAAAG-- --GAAAAAAAAAAAG-- --GAAAAAAAAAAAG-- ---CCCCCCCCCCC--- 
---EEEEE-EEEEE--- -----E-----E----- ---BBBBBBBBBBB--- ---BBBBBBBBBBB--- ---BBBBBBBBBBB--- ---BBBBBBBBBBB--- ---BBBBBBBBBBB--- ---BBBBBBBBBBB--- ---BBBBBBBBBBB--- ---BBBBBBBBBBB--- ---BBBBBBBBBBB--- ---BBBBBBBBBBB--- ---BBBBBBBBBBB--- ---BBBBBBBBBBB--- ---BBBBBBBBBBB--- ---BBBBBBBBBBB--- ---BBBBBBBBBBB--- ---BBBBBBBBBBB--- ---BBBBBBBBBBB--- ---BBBBBBBBBBB--- ---BBBBBBBBBBB--- ---FFFFFFFFFFF--- ---AAAAAAAAAAA--- --GAAAAAAAAAAAG-- --GAAAAAAAAAAAG-- --GAAAAAAAAAAAG-- --GAAAAAAAAAAAG-- ---CCCCCCCCCCC--- 
---EEEEE-EEEEE--- -----E-----E----- ---BBBBBBBBBBB--- ---BBBBBBBBBBB--- ---BBBBBBBBBBB--- ---BBBBBBBBBBB--- ---BBBBBBBBBBB--- -DDBBBBBBBBBBBDD- -DDBBBBBBBBBBBDD- -DDBBBBBBBBBBBDD- -DDBBBBBBBBBBBDD- -DDBBBBBBBBBBBDD- -DDBBBBBBBBBBBDD- -DDBBBBBBBBBBBDD- -DDBBBBBBBBBBBDD- -DDBBBBBBBBBBBDD- -DDBBBBBBBBBBBDD- -DDBBBBBBBBBBBDD- -DDBBBBBBBBBBBDD- -DDBBBBBBBBBBBDD- ---BBBBBBBBBBB--- ---FFFFFFFFFFF--- ---AAAAAAAAAAA--- --GAAAAAAAAAAAG-- --GAAAAAAAAAAAG-- --GAAAAAAAAAAAG-- --GAAAAAAAAAAAG-- ---CCCCCCCCCCC--- 
---EEEEE-EEEEE--- ----------------- ---AAAAAAAAAAA--- ---AAAAAAAAAAA--- ---AAAAAAAAAAA--- ---AAAAAAAAAAA--- ---AAAAAAAAAAA--- DDDAAAAAAAAAACDDD DDDAAAAAAAAAACDDD DDDAAAAAAAAAACDDD -DDAAAAAAAAAACDD- -DDAAAAAAAAAACDD- -DDAAAAAAAAAACDD- -DDAAAAAAAAAACDD- -DDAAAAAAAAAACDD- -DDAAAAAAAAAACDD- -DDAAAAAAAAAACDD- -DDAAAAAAAAAACDD- -DDAAAAAAAAAACDD- -DDAAAAAAAAAACDD- ---AAAAAAAAAAA--- ---AAAAAAAAAAA--- ---AAAAAAAAAAA--- ---AAAAAAAAAAA--- ---AAAAAAAAAAA--- ---AAAAAAAAAAA--- ---AAAAAAAAAAA--- ---CCCCCCCCCCC--- 
----------------- ----------------- ---AAAAAAAAAAA--- ---AAAAAAAAAAA--- ---AAAAAAAAAAA--- ---AAAAAAAAAAA--- ---AAAAAAAAAAA--- DDDAAAAAAAAAACDDD DDDAAAAAAAAAACDDD DDDAAAAAAAAAACDDD -DDAAAAAAAAAACDD- -DDAAAAAAAAAACDD- -DDAAAAAAAAAACDD- -DDAAAAAAAAAACDD- -DDAAAAAAAAAACDD- -DDAAAAAAAAAACDD- -DDAAAAAAAAAACDD- -DDAAAAAAAAAACDD- -DDAAAAAAAAAACDD- -DDAAAAAAAAAACDD- ---AAAAAAAAAAA--- ---AAAAAAAAAAA--- ---AAAAAAAAAAA--- ---AAAAAAAAAAA--- ---CCCCCCCCCCC--- ---CCCCCCCCCCC--- ---CCCCCCCCCCC--- ---CCCCCCCCCCC--- 
----------------- ----------------- ---AAAAAAAAAAA--- ---AAAAAAAAAAA--- ---AAAAAAAAAAA--- ---AAAAAAAAAAA--- ---AAAAAAAAAAA--- DDDAAAAAAAAAACDDD DDDAAAAAAAAAACDDD DDDAAAAAAAAAACDDD -DDAAAAAAAAAACDD- -DDAAAAAAAAAACDD- -DDAAAAAAAAAACDD- -DDAAAAAAAAAACDD- -DDAAAAAAAAAACDD- -DDAAAAAAAAAACDD- -DDAAAAAAAAAACDD- -DDAAAAAAAAAACDD- -DDAAAAAAAAAACDD- -DDAAAAAAAAAACDD- ---AAAAAAAAAAA--- ---AAAAAAAAAAA--- ---AAAAAAAAAAA--- ---AAAAAAAAAAA--- ---CCCCCCCCCCC--- ---CCCCCCCCCCC--- ---CCCCCCCCCCC--- ---CCCCCCCCCCC--- 
----------------- ----------------- ---AAAAAAAAAAA--- ---AAAAAAAAAAA--- ---AAAAAAAAAAA--- ---AAAAAAAAAAA--- ---AAAAAAAAAAA--- DDDAAAAAAAAAACDDD DDDAAAAAAAAAACDDD DDDAAAAAAAAAACDDD -DDAAAAAAAAAACDD- -DDAAAAAAAAAACDD- -DDAAAAAAAAAACDD- -DDAAAAAAAAAACDD- -DDAAAAAAAAAACDD- -DDAAAAAAAAAACDD- -DDAAAAAAAAAACDD- -DDAAAAAAAAAACDD- -DDAAAAAAAAAACDD- -DDAAAAAAAAAACDD- ---AAAAAAAAAAA--- ---AAAAAAAAAAA--- ---AAAAAAAAAAA--- ---AAAAAAAAAAA--- ---CCCCCCCCCCC--- ---CCCCCCCCCCC--- ---CCCCCCCCCCC--- ---CCCCCCCCCCC--- 
----------------- ----------------- ---AAAAAAAAAAA--- ---AAAAAAAAAAA--- ---AAAAAAAAAAA--- ---AAAAAAAAAAA--- ---AAAAAAAAAAA--- DDDAAAAAAAAAAADDD DDDAAAAAAAAAAADDD DDDAAAAAAAAAAADDD ---AAAAAAAAAAA--- ---AAAAAAAAAAA--- ---AAAAAAAAAAA--- ---AAAAAAAAAAA--- ---AAAAAAAAAAA--- ---AAAAAAAAAAA--- ---AAAAAAAAAAA--- ---AAAAAAAAAAA--- ---AAAAAAAAAAA--- ---AAAAAAAAAAA--- ---AAAAAAAAAAA--- ---AAAAAAAAAAA--- ---AAAAAAAAAAA--- ---AAAAAAAAAAA--- ---CCCCCCCCCCC--- ---CCCCCCCCCCC--- ---CCCCCCCCCCC--- ---CCCCCCCCCCC--- 
----------------- ----------------- ---AAAAAAAAAAA--- ---AAAAAAAAAAA--- ---AAAAAAAAAAA--- ---AAAAAAAAAAA--- ---AAAAAAAAAAA--- ---AAAAAAAAAAA--- ---AAAAAAAAAAA--- ---AAAAAAAAAAA--- ---AAAAAAAAAAA--- ---AAAAAAAAAAA--- ---AAAAAAAAAAA--- ---AAAAAAAAAAA--- ---AAAAAAAAAAA--- ---AAAAAAAAAAA--- ---AAAAAAAAAAA--- ---AAAAAAAAAAA--- ---AAAAAAAAAAA--- ---AAAAAAAAAAA--- ---AAAAAAAAAAA--- ---AAAAAAAAAAA--- ---AAAAAAAAAAA--- ---AAAAAAAAAAA--- ---CCCCCCCCCCC--- ---CCCCCCCCCCC--- ---CCCCCCCCCCC--- ---CCCCCCCCCCC--- 
----------------- ----------------- ---AAAAAAAAAAA--- ---AAAAAAAAAAA--- ---AAAAAAAAAAA--- ---AAAAAAAAAAA--- ---AAAAAAAAAAA--- ---AAAAAAAAAAA--- ---AAAAAAAAAAA--- ----------------- ----------------- ----------------- ----------------- ----------------- ----------------- ----------------- ----------------- ----------------- ----------------- ----------------- ----------------- ----------------- ----------------- ----------------- ----------------- ----------------- ----------------- ----------------- 
