model
size = 17 28 14, scale = 0.05, origin = -y
material 
  colors = A:#369 B:#DDD C:#39C D:#F90 E:#CF0 F:#111
voxels
----------------- ----------------- ----------------- ----------------- ----------------- ----------------- ----------------- ----------------- ----------------- ----------------- ----------------- ----------------- ----------------- ----------------- ----------------- ----------------- ----------------- ----------------- ----------------- ----------------- ----------------- ----------------- ----------------- ------DDDDD------ ------DDDDD------ ----------------- ----------------- ----------------- 
----------------- ----------------- ----------------- ----------------- ----------------- ----------------- ----------------- ----------------- ----------------- ----------------- ----------------- ----------------- ----------------- ----------------- ----------------- ----------------- ----------------- ----------------- ----------------- ----------------- ----------------- ----------------- ----------------- ------DDDDD------ ------DDDDD------ ----------------- ----------------- ----------------- 
----------------- ----------------- ----------------- ----------------- ----------------- ----------------- ----------------- ----------------- ----------------- ----------------- ----------------- ----------------- ----------------- ----------------- ----------------- ----------------- ----------------- ----------------- ----------------- ----------------- ----------------- ----------------- ----------------- ------DDDDD------ ------DDDDD------ ----------------- ----------------- ----------------- 
---DDDDD-DDDDD--- ----------------- ---BBBBBBBBBBB--- ---BBBBBBBBBBB--- ---BBBBBBBBBBB--- ---BBBBBBBBBBB--- ---BBBBBBBBBBB--- ---BBBBBBBBBBB--- ---BBBBBBBBBBB--- ---BBBBBBBBBBB--- ---BBBBBBBBBBB--- ---BBBBBBBBBBB--- ---BBBBBBBBBBB--- ---BBBBBBBBBBB--- ---BBBBBBBBBBB--- ---BBBBBBBBBBB--- ---BBBBBBBBBBB--- ---BBBBBBBBBBB--- ---BBBBBBBBBBB--- ---BBBBBBBBBBB--- ---BBBBBBBBBBB--- ---EEEEEEEEEEE--- ---AAAAAAAAAAA--- ---AAAAAAAAAAA--- ---AAAAAAAAAAA--- ---AAAAAAAAAAA--- ---AAAAAAAAAAA--- ---AAAAAAAAAAA--- 
---DDDDD-DDDDD--- ----------------- ---BBBBBBBBBBB--- ---BBBBAAAAAAB--- ---BBBBAAAAAAB--- ---BBBBAAAAAAB--- ---BBBBAAAAAAB--- ---BBBBAAAAAAB--- ---BBBBAAAAAAB--- ---BBBBAAAAAAB--- ---BBBBAAAAAAB--- ---BBBBAAAAAAB--- ---BBBBAAAAAAB--- ---BBBBAAAAAAB--- ---BBBBAAAAAAB--- ---BBBBAAAAAAB--- ---BBBBAAAAAAB--- ---BBBBAAAAAAB--- ---BBBBAAAAAAB--- ---BBBBAAAAAAB--- ---BBBBAAAAAAB--- ---EEEEEEEEEEE--- ---AAAAAAAAAAA--- --FAAAAAAAAAAAF-- --FAAAAAAAAAAAF-- --FAAAAAAAAAAAF-- --BAAAAAAAAAAAB-- ---AAAAAAAAAAA--- 
---DDDDD-DDDDD--- ----------------- ---BBBBBBBBBBB--- ---BBBBAAAAAAB--- ---BBBBAAAAAAB--- ---BBBBAAAAAAB--- ---BBBBAAAAAAB--- ---BBBBAAAAAAB--- ---BBBBAAAAAAB--- ---BBBBAAAAAAB--- ---BBBBAAAAAAB--- ---BBBBAAAAAAB--- ---BBBBAAAAAAB--- ---BBBBAAAAAAB--- ---BBBBAAAAAAB--- ---BBBBAAAAAAB--- ---BBBBAAAAAAB--- ---BBBBAAAAAAB--- ---BBBBAAAAAAB--- ---BBBBAAAAAAB--- ---BBBBAAAAAAB--- ---EEEEEEEEEEE--- ---AAAAAAAAAAA--- --FAAAAAAAAAAAF-- --FAAAAAAAAAAAF-- --FAAAAAAAAAAAF-- --FAAAAAAAAAAAF-- ---AAAAAAAAAAA--- 
---DDDDD-DDDDD--- -----D-----D----- ---BBBBBBBBBBB--- ---BBBBAAAAAAB--- ---BBBBAAAAAAB--- ---BBBBAAAAAAB--- ---BBBBAAAAAAB--- ---BBBBAAAAAAB--- ---BBBBAAAAAAB--- ---BBBBAAAAAAB--- ---BBBBAAAAAAB--- ---BBBBAAAAAAB--- ---BBBBAAAAAAB--- ---BBBBAAAAAAB--- ---BBBBAAAAAAB--- ---BBBBAAAAAAB--- ---BBBBAAAAAAB--- ---BBBBAAAAAAB--- ---BBBBAAAAAAB--- ---BBBBAAAAAAB--- ---BBBBAAAAAAB--- ---EEEEEEEEEEE--- ---AAAAAAAAAAA--- --FAAAAAAAAAAAF-- --FAAAAAAAAAAAF-- --FAAAAAAAAAAAF-- --FAAAAAAAAAAAF-- ---AAAAAAAAAAA--- 
---DDDDD-DDDDD--- -----D-----D----- ---BBBBBBBBBBB--- ---BBBBAAAAAAB--- ---BBBBAAAAAAB--- ---BBBBAAAAAAB--- ---BBBBAAAAAAB--- -CCBBBBAAAAAABCC- -CCBBBBAAAAAABCC- -CCBBBBAAAAAABCC- -CCBBBBAAAAAABCC- -CCBBBBAAAAAABCC- -CCBBBBAAAAAABCC- -CCBBBBAAAAAABCC- -CCBBBBAAAAAABCC- -CCBBBBAAAAAABCC- -CCBBBBAAAAAABCC- -CCBBBBAAAAAABCC- -CCBBBBAAAAAABCC- -CCBBBBAAAAAABCC- ---BBBBAAAAAAB--- ---EEEEEEEEEEE--- ---AAAAAAAAAAA--- --FAAAAAAAAAAAF-- --FAAAAAAAAAAAF-- --FAAAAAAAAAAAF-- --FAAAAAAAAAAAF-- ---AAAAAAAAAAA--- 
---DDDDD-DDDDD--- ----------------- ---AAAAAAAAAAA--- ---AAAAAAAAAAA--- ---AAAAAAAAAAA--- ---AAAAAAAAAAA--- ---AAAAAAAAAAA--- CCCAAAAAAAAAACCCC CCCAAAAAAAAAACCCC CCCAAAAAAAAAACCCC -CCAAAAAAAAAACCC- -CCAAAAAAAAAACCC- -CCAAAAAAAAAACCC- -CCAAAAAAAAAACCC- -CCAAAAAAAAAACCC- -CCAAAAAAAAAACCC- -CCAAAAAAAAAACCC- -CCAAAAAAAAAACCC- -CCAAAAAAAAAACCC- -CCAAAAAAAAAACCC- ---AAAAAAAAAAA--- ---AAAAAAAAAAA--- ---AAAAAAAAAAA--- ---AAAAAAAAAAA--- ---AAAAAAAAAAA--- ---AAAAAAAAAAA--- ---AAAAAAAAAAA--- ---AAAAAAAAAAA--- 
----------------- ----------------- ---AAAAAAAAAAA--- ---AAAAAAAAAAA--- ---AAAAAAAAAAA--- ---AAAAAAAAAAA--- ---AAAAAAAAAAA--- CCCAAAAAAAAAACCCC CCCAAAAAAAAAACCCC CCCAAAAAAAAAACCCC -CCAAAAAAAAAACCC- -CCAAAAAAAAAACCC- -CCAAAAAAAAAACCC- -CCAAAAAAAAAACCC- -CCAAAAAAAAAACCC- -CCAAAAAAAAAACCC- -CCAAAAAAAAAACCC- -CCAAAAAAAAAACCC- -CCAAAAAAAAAACCC- -CCAAAAAAAAAACCC- ---AAAAAAAAAAA--- ---AAAAAAAAAAA--- ---AAAAAAAAAAA--- ---AAAAAAAAAAA--- ---AAAAAAAAAAA--- ---AAAAAAAAAAA--- ---AAAAAAAAAAA--- ---AAAAAAAAAAA--- 
----------------- ----------------- ---AAAAAAAAAAA--- ---AAAAAAAAAAA--- ---AAAAAAAAAAA--- ---AAAAAAAAAAA--- ---AAAAAAAAAAA--- CCCAAAAAAAAAACCCC CCCAAAAAAAAAACCCC CCCAAAAAAAAAACCCC -CCAAAAAAAAAACCC- -CCAAAAAAAAAACCC- -CCAAAAAAAAAACCC- -CCAAAAAAAAAACCC- -CCAAAAAAAAAACCC- -CCAAAAAAAAAACCC- -CCAAAAAAAAAACCC- -CCAAAAAAAAAACCC- -CCAAAAAAAAAACCC- -CCAAAAAAAAAACCC- ---AAAAAAAAAAA--- ---AAAAAAAAAAA--- ---AAAAAAAAAAA--- ---AAAAAAAAAAA--- ---AAAAAAAAAAA--- ---AAAAAAAAAAA--- ---AAAAAAAAAAA--- ---AAAAAAAAAAA--- 
----------------- ----------------- ---AAAAAAAAAAA--- ---AAAAAAAAAAA--- ---AAAAAAAAAAA--- ---AAAAAAAAAAA--- ---AAAAAAAAAAA--- CCCAAAAAAAAAACCCC CCCAAAAAAAAAACCCC CCCAAAAAAAAAACCCC -CCAAAAAAAAAACCC- -CCAAAAAAAAAACCC- -CCAAAAAAAAAACCC- -CCAAAAAAAAAACCC- -CCAAAAAAAAAACCC- -CCAAAAAAAAAACCC- -CCAAAAAAAAAACCC- -CCAAAAAAAAAACCC- -CCAAAAAAAAAACCC- -CCAAAAAAAAAACCC- ---AAAAAAAAAAA--- ---AAAAAAAAAAA--- ---AAAAAAAAAAA--- ---AAAAAAAAAAA--- ---AAAAAAAAAAA--- ---AAAAAAAAAAA--- ---AAAAAAAAAAA--- ---AAAAAAAAAAA--- 
----------------- ----------------- ---AAAAAAAAAAA--- ---AAAAAAAAAAA--- ---AAAAAAAAAAA--- ---AAAAAAAAAAA--- ---AAAAAAAAAAA--- CCCAAAAAAAAAAACCC CCCAAAAAAAAAAACCC CCCAAAAAAAAAAACCC ---AAAAAAAAAAA--- ---AAAAAAAAAAA--- ---AAAAAAAAAAA--- ---AAAAAAAAAAA--- ---AAAAAAAAAAA--- ---AAAAAAAAAAA--- ---AAAAAAAAAAA--- ---AAAAAAAAAAA--- ---AAAAAAAAAAA--- ---AAAAAAAAAAA--- ---AAAAAAAAAAA--- ---AAAAAAAAAAA--- ---AAAAAAAAAAA--- ---AAAAAAAAAAA--- ---AAAAAAAAAAA--- ---AAAAAAAAAAA--- ---AAAAAAAAAAA--- ---AAAAAAAAAAA--- 
----------------- ----------------- ---AAAAAAAAAAA--- ---AAAAAAAAAAA--- ---AAAAAAAAAAA--- ---AAAAAAAAAAA--- ---AAAAAAAAAAA--- ---AAAAAAAAAAA--- ---AAAAAAAAAAA--- ---AAAAAAAAAAA--- ---AAAAAAAAAAA--- ---AAAAAAAAAAA--- ---AAAAAAAAAAA--- ---AAAAAAAAAAA--- ---AAAAAAAAAAA--- ---AAAAAAAAAAA--- ---AAAAAAAAAAA--- ---AAAAAAAAAAA--- ---AAAAAAAAAAA--- ---AAAAAAAAAAA--- ---AAAAAAAAAAA--- ---AAAAAAAAAAA--- ---AAAAAAAAAAA--- ---AAAAAAAAAAA--- ---AAAAAAAAAAA--- ---AAAAAAAAAAA--- ---AAAAAAAAAAA--- ---AAAAAAAAAAA--- 
