model
size = 32, scale = 0.05, origin = -y
material 
  colors = A:#7BA23F B:#DDD23B C:#A8497A D:#EFBB24 E:#D0104C F:#E03C8A G:#734338 H:#E83015 I:#CA7A2C J:#36563C K:#C78550 L:#91B493 M:#0089A7 N:#F0A986
voxels
3C2(2-4C)3-3CB2-4C2-2A2GD2-4B2-3BG3-3CB2-4C2-2A2D4-3B2-B2-G3-C2-B2-3C4-A64-2G6-2(B2-)G3-C2-B2-C6-A3G5-B2-3BG3-3CB2-C5-2A3G5-D2-3BG3-3CB2-C5-2A3G2-3BD2-3BG3-3CB2-4C2-2A20-2F42-3G2-4G-F13-4C2-2A2G4-3G2-2F11-3C4-A2G4-3G4-2F7-F-3C4-A3G2-4GF5-2F4-F2-4C2-2A9-F7-2F-D19-F10-2F19-F11-3F16-FG10-F4-4C2-2A7-FG10-F4-3C4-A6-F-G9-F5-3C4-A6-F-G15-4C2-2A5-F64-2IG2-4G3-3CB2-4C2-2A4-2I-IG2-4G3-3AB2-A5-2A8-G2-2G10-5I4-2G6-G2-G84-2G4-3G23-3G2-4G9-2(4A2-)2A2(2C-)3C-2C2-2C-2C2-2B-3C-2A-A2C-2D-3B-2B2-2C-2C2-2B-3C-2A-A32-2D4-3B2-B2-C3-C2-B2-3C4-A2D4-2F2(B2-)C3-C2-B2-C6-A32-2C-C4-B-2B2-C3-C2-2B-C4-A-A2C-C4-D-2B2-C3-C2-2B-C4-A-A2(2E-)3E2(-2E2-2E)-3E-2A-A32-2E4-3E2(2-E)3-2(E2-)3E4-A2(2E-)3E-E7-E3-E-3E-2A-A64-2(2E-)3E-E11-E-3E-2A-A7-2E15-E6-A8-E11-E19-E15-E6-A8-E-E11-E-3E-2A-A72-C-C11-B-3C-2A-A8-2(C2-)C3-C2-B2-3C4-A40-C-2C2-2C-2C2-2B-3C-2A-A8-A-2A2-A3-A2-2B-A4-A-A7-IA-2A12-I39-2A6-A2-A20-2A4-3A2-A52-2(2A-)3A2(-2A2-2A)-3A-2A-22A3B13A9B7A3B2A5GADA-2A-3BF2B2-2A-2A2-2B-2AG-2G-4A2-4B2-3BA3-3AB2-2A2G2-G4A5-B2-3BA3-3AB2-A5-GADA-A4-B-2B2-A3-A-F2B-A4-G-5A4-D5BA3-3A3BA4-2G5A4-6BA3-3A3BA4-2GA27E2G6E3-3E-2E2-E3-2(E2-)3E4-2(4E2-)4E3-4E2-3EG2-13E7-E3-5E2G5E-2E-5E11-E-3E-GE-3E-2E-3E-E10-2E-3E-GE-12E11-5E2G3E7-2E15-E5-2E8-E15-E6-E8-E15-E5-2E8-3E10-6E2G3E2(8-E-E11-E-3E-GE-E)8-3A10-F2B2A3G3E8-A2-4A3-3AB2-2A2G2-2E8-2(A2-)A3-A2-B2-2AG4-E8-13A3B2A5GA8-7A3I3A3BA4-2GA7-I5AI18-2A-A4-AI2A20-3AI4-A2-2A19-3A2-4A2-2A19-2(2A-)3A-2A20-63AE8H23AE8-F12-F7-A-E8-F21-AE20-2F8-AE29-A-2(E19-F9-2A)E19-F9-3E18-F12-E2-F15-F11-2E-F7-F19-3EF7-F-F11-F6-E-E8-F13-D6-E-E7-F21-3E30-2E31-E30-2E22-F6-3E2(29-E-E)22-3F4-3E30-2E31-E18-I10-3A13-2I3-I10-3A9-4I16-3A3-I3-6I16-A-A3I27-2AF29-2A29-A-A29-34AE8H23AE29-A-2(E30-A)E29-A-2(E29-2A)E29-3E31-E30-2E29-3E2(29-E-E)29-3E30-2E31-E30-2E29-3E28-F2(E-E29-)3E29-3E30-2E29-3J29-3A12-I16-3A8-I-2I17-A-AF29-2A30-2A29-A-A29-5A-2A-3A2(-2A2-2A)-3A-2A-E2(2H-)2HA2(-2A2-2A)-3A-2A-E32-2H4-2HA2(2-D)3-2(D2-)3D4-E2A6-2(D2-)D3-2(D2-)D6-E32-2D-A4-A-2D2-D3-D2-2D-D4-A-E2A-A4-A-AD2-D3-D2-2D-D4-A-E2A-2AF3A-AD2-2DF2D2-2D-3D-AE-E6-F25-2A4-3A2(2-D)3-2(D2-)3D4-E2AF2A-3A-A11-D-3D-AE-E2(3-F)56-2(2A-)3A-A11-D-3D-AE-E2A4-F-A15-D6-E32-2A6-A15-D6-E10-A10-FD-3D-AE-E73-FA11-D-3D-AE-E10-2(F2(D2-))3D3-2E25-2I14-FAD2-2D-2D2-DJ-3J-2J-J9-IAD2-D3-D2-2D-D4-A-A9-IA2(D2-)ID2-2D-D4-A-A18-I31-2(D2-)D6-A18-2(D2-)3D4-A49-2D2-2D-3D-2A-2(4A2-)4A3-3AB2-4A2-AE3H2-3HA2-4A3-3AB2-4A2-AE2H4-2HA2(2-D)3-D2-B2-3D4-E64-2A6-A2(2-D)3-D2-B2-D6-E3A5-A2-4D3-3DB2-D5-AED2A5-A2-4D3-3DB2-D5-AE3AF-4A2-4D2-F3DB2-4D2-2E6-F-F37-F17-3AF-4A15-4D2-2E2AF3-3A15-3D4-E-F4-2F16-3D4-EF5-F17-4D2-2E120-4D2-2E2(24-3D4-E)10-F11-F-4D2-2E25-2I47-F4D3-3DB2-4J2-2J10-I4D3-3DB2-D5-2A11-3D29-2(D2-)ID2-B2-D6-A14-I67-2(D2-)3D4-A18-2(4D2-)5A5-A2-4A3-3AB2-A5-AE3H5-B2-3BA3-3AB2-A5-AE2H6-2(B2-)D3-D2-B2-D6-E11-F148-3K3-2FB2-3BD3-3DB2-D5-2E-2IF3-2F55-3K4-FK15-D5-2E2A4-F-A15-2(D6-E24-)D5-2E120-D5-2E2(24-D6-E)24-D5-2E73-FI4D3-3DB2-J5-2J82-I127-4D2-D5-4A-A4-A-2A2-A3-A2-2B-A4-A-E2H-H4-B-2B2-A3-A2-2B-A4-A-E32-2H6-2(B2-)D3-D2-B2-D6-E128-DKFK3-FB-2B2-D3-D2-2B-D4-E4-F5-F23-2K6-2(B2-)D3-2(D2-)D7-2K-K4-K-A11-B-D4-E76-A11-B-D4-E12-F95-A11-B-D4-E76-A11-B-D4-E13-D-FD3-D2-B2-D47-FIAD2-D3-D2-2B-J4-J-J210-D2-2D-D4-A-5A4-7A3-3A3BA4-2AE4H4-6BA3-3A3BA4-2AE2H-H4-B-2B2-D3-D2-2B-D4-A-E3H5-B2-D2BD3-3DB2-D5-AE128-4K4-6BD3-3D3BD4-E2-DKF4-F2(B2-)D3-2(D2-)D7-3K5-B2-3BH3-3HB2-H7-4K4-2KA11-2BD4-E2-2A-A4-AFA11-B-D4-E11-FAF10-B-D4-E11-FA11-2BD4-E12-F95-A11-2BD4-E12-A11-B-D4-E12-A10-IB-D4-E12-A11-2BD4-E13-4D3-3DB2-D16-FID2-D3-D2-B2-D17-A4D3-3D3BJ4-3J200-IA8-7D2(4-7A)3-3A3BA4-2AE4H4-6BA3-3A3BA4-2AE2H-H4-B-2B2-D3-D2-2B-D4-A-E3H5-B2-3BD3-3DB2-D5-AE128-4K4-6BD3-3D3BD4-E2-2K6-2(B2-)D3-D2-B2-D7-D2K4-FB-F3BH3-3HB2-H7-4K4-2KF11-2BD4-E2-2A-A4-A2F11-B-D4-E2-2I8-F11-B-D4-E24-2BD4-E120-2BD4-E24-B-D4-E23-IB-D4-E24-2BD4-E13-4D3-3DB2-D16-FID2-D3-D2-B2-D18-4D3-3D3BJ4-3J20-M180-A8-7D4-24A3B7AE5H9B7A3B7AE2(2H-)3B-2B2-2D-2D2-2B-3D-2A-E3H2-4B2-3BD3-3DB2-4D2-AE3N5-B2-2BDN3-3NB2-D5-AE2K-K4-D-2B2-N3-N2-2B-2(D4-A2-4K4-6BN3-3N3B)D4-A2-5K9B7D3B4DAE-E2K3-F3B2-B2-D3-D2-B-I3D2-E2-D2K2F4B2-3BH2-I3HB-I4H4-10K4-2(I3-)2B4DAE2-2(2AI)3A13-B-3D-AE5-2IFI-F13-B-3D-AE5-F18-2B4DAE26-2(D31-)D29-2B4DAE22-FIBF3D-AE23-FB-3D-AE24-2B4DAE12-I4D3-3DB2-4D14-FD2-D3-D2-B2-3D16-10D3B8J11-4D3-3D3BD4-3A11-2D30-D125-A6-I11D6A4-3A2(2-A)3-A2-B2-3A4-E2H4-3B2-B2-A3-A2-B2-3A4-E128-2(2K6-2(B2-)N3-N2-B2-D7-)2K3-F3B2-B2-D3-D2-B2-3D2IE-E6-F16-F3I7-F-2F7-2I3-4I-FI7-DK2-F-3KI14-3D9-F-3I26-F2-3F47-3D124-I3D26-FIF2I28-F-F31-3D18-2F28-F31-D2-D3-D2-B2-3J4-J11-D2-D3-D2-B2-D6-A11-D165-I2(D2-)3D4-2(4A2-)4A3-3AB2-4A2-AE3H2-4B2-3BA3-3AB2-4A2-AE2H4-3B2-B2-D2-FD2-B2-3D4-E64-2K6-2(B2-)N3-D2-2(B2-D7-3K5-B2-3BN3-3N)B2-D7-3K-F4B2-3BD3-3DB-F4D9-F5-2F11-F38-E3K-F4K13-FI4D4-DA3-F3A15-3D12-3F14-3D29-4D67-E31-E23-I4D26-2F2(3D29-)4D79-4D3-3DB2-4J2-2J11-4D3-3DB2-D5-2A11-2D30-D31-M102-2(4D2-)13A9-F-2B7AE5H6B8-F2-2B7AE2(2H-)3B-B7-F3-B-3D-2A-E3H2-4B15-4D2-AE3N5-B15-D5-AE2K-K4-B-B11-B-D4-A2-4K4-3B3-F7-2BD4-A2-4K4-3B2-F8-2BD4-A2-5K6B-F8-F2B4DAE2-2K3-F3B13-2F3D5-3KF-4B15-4H9-F19-3I3-E6-3F31-F86-E63-E26-2F25-2F-2F94-4D28-3D19-F7-2B8J14-F7-2BD4-3A71-5M28-2M31-I12-10I8-IA11-I6D6A-2A-3A-A10-FB-3A-2A-E2(2H-)3B-B11-B-3A-2A-E32-2H4-3B14-F3A4-E2N6-B15-A6-E32-2K-K4-B-B11-B-A4-A2-2K-K4-B-B10-FB-A4-A2-2(2K-)3B-B10-MB-3J-JE6-F27-2KFM2-3B15-3H8-M59-E62-2E3(31-E)52-3F97-3A47-A3-F7-B-3J-2J-J8-2FA11-B-A4-A-A10-A58-5M29-2M22-I39-3M12-A2(-3A-2A)-3A-A11-B-3A-2A-E2(2H-)3B-B10-FBF3A-2A-E24-F7-2H4-3B15-3A4-E2N6-B15-A6-E32-2N-N4-B-B10-FB-A4-A2-2N-N4-B-BM10-B-A4-A-E2A-2J-3B-B11-B-3J-JE-E31-E2H4-3B15-3H4-E31-E30-2E31-E29-3E30-2E63-E52-2F98-3A46-FA3-F7-B-3J-2J-J6-3F-A11-B-A4-A-A10-A84-I71-M14-A-3A-2A-12A11-2B7AE5H6B11-2B7AE2(2H-)3B-B9-2FB-3A-2A-E3H2-4B12-2F-4A2-AE3A5-B15-A5-AE2A-A4-B-B11-B-A4-A2-4A4-3B11-2BA4-A2-4A4-3BM10-2BA4-A2-2A3J6B11-2B5JE2-2A4-3B14-F3J5-3H2-4B14-F4H6-F21-4F35-E30-2E28-F3E63-E83-2F98-F4A28-3A15-A3-F6-F2B8J5-2F3-A9-FI2BA4-3A5-F3-IA10-F19-IA126-A12-13A5-A12-3FA5-AE3H5-B12-3FA5-AE2H6-B12-3FA6-E24-F31-D31-F30-F19-M11-F8-2AJ5-B2-2M10-FJ7-F32-2F28-2(E31-E63-)E238-F8-IJ4-I2J22-3I4-3I3-3F178-A5-4A6-A6-7F-FA6-E2H6-B11-F-2FA6-E192-2A6-B3-2M10-J6-E31-EF126-E63-E31-E191-E31-E24-J6-J33-3F180-A6-4A5-A2-4F5-F3-A5-AE3H5-B14-FA5-AE2H6-B15-A6-E159-E13-2M9-J20-M113-E126-2E127-E31-E88-J5-2J32-2F182-A5-13A7-2F2-2B8A5H6B11-2B8A2(2H-)3B-B11-BF3A-2A-A3H2-4B14-F4A2-2A5-4F15-A5-2A21-FB-3(A4-A24-2B)5JE26-3J28-F4J28-2F37-E127-3(E31-)E88-4A28-3A26-F2B8J22-2BA4-3AF181-12A-2A-3A-A5-2F4-B-3A-2A-A2(2H-)3B-B11-B-3A-2A-A32-2H4-3B14-F3A4-A24-A6-A53-F2(B-A4-A24-)BF3J-JE26-2F29-F3J36-E159-E31-E30-2E119-F3A29-3F27-B-3J-2J-J22-B-A4-A-A182-A2(-3A-2A)-3A-A3-MF6-B-3A-2A-A2(2H-)3B-B11-B-3A-2A-A32-2H4-3B15-3A4-A24-A6-A54-2(B-A4-A23-F)BF3A-AE24-F33-3A36-E88-2F68-2E63-E30-2E31-E56-3A4-E54-B-3J-2J-J22-B-A4-A-A182-A-3A-2A-A11C11-2B4C4A5H6B11-2B4C4A2(2H-)3B-BF10-B-3C-2A-A3H2-4B-F13-4C2-2A7-2F15-C5-2A18-F3-B-C4-A21-2F-2BC4-A23-F2BC4-A22-2F2B4CAE23-3F3C27-2F4C3-E24-F3I29-3F60-4I2-2E25-3F2-2E30-2E31-E95-E55-I4C28-3C27-2B8J22-2BA4-3A182-10A3C2(2-4C)2-F3CB2-4C2-2A3H2-4B2-3BC2-F3CB2-4C2-2A2H4-3B2-B-FL2-FL-FB2-3C4-A14-F3-F2-F59-FL2-3(B2-C25-3L)B2-4C67-E23-I4C3-E23-I3C28-I3C4-E23-I4C35-E88-4C28-2(3C29-)4C3-E78-I2-I3CB2-4J2-2J11-I2-I3-3AB2-A5-2A178-2(4A2-)2A2C4-3C2(2-C)3-C2-B2-3C4-A2C4-3B2-B2-C3-C-FB2-3C4-A21-F106-2C6-2(B2-)L3-L2-B2-C7-2C6-2(B2-)L3-L2-B-FC7-2C4-3B2-B2-L3-L2-BF-3C26-F31-F2-I7-2C-3I3C11-F-2I3C5-2I4-3I15-3I61-3C36-E56-F31-3C47-F45-3C36-E43-2(C2-)IC2-B2-3J4-J10-IA-IA3-A2-B2-A6-A10-IA23-I130-3A9-2(A2-)3A4-A21C3B4C4A5C9B7C3B4C4A2(2C-)3B-2B2-2LM2L2-2B-3C-2A-A3C2-4B2-3BL3-3LB2-4C2-2A3C5-B2-3BL3-3LB2-C5-2A2C-C4-B-2B2-L3-L2-2B-2(C4-A2-4C4-6BL3-3L3B)C4-A2-5C9B7L3B4CAE2-2C4-3B2-B2-L3-L2-BF-3C5-3C2-4B2-3BL2-I3LB-I4C4-11C-3I3-4I2B4CAE2-2CI2C-3C-C9-F-B-3C-AE4-F7-C11-B-3C-AE12-D11-2B4CAE26-C6-E24-C30-FC17-C11-2B4CAE12-C11-B-3C-AE11-FC11-B-3C-AE12-C11-2B4CAE12-F4L3-3LB2-4C15-C2-C3-C2-B2-3C4-E10-11C3B8J10-5A3-3A3BA4-3A9-I3A21-IA3-IA-2A28-A28-4A25-F2A-3A26-7A7-15A4C4-7C3-3C3BC4-3A4C4-6BC3-3C3BC4-3A2C-C4-B-2B2-C-M-C2-2B-C4-A-A3C5-B2-3BC3-3CB2-C5-2A18-M109-4C4-6BC3-3C3BC4-E2-2C6-2(B2-)C3-C2-B2-C7-3C5-B2-3BC3-3CB2-C7-4C4-3C7-M3-2BC4-E2-2C-C4-C-2(C11-B-C4-E12-)C11-2BC4-E33-E74-C11-2B2(C4-E12-C11-B-)C4-E12-C11-2BC4-E13-4C3-3CB2-C18-C2-C3-C2-B2-C17-5C3-3C3BJ4-3J13-F122-A26-A4-A25-FA4-2A8-7A4-3A4C4-7C3-3C3BC4-3A4G4-6BG3-3C3BC4-3A2G-G4-B-2B2-G-2MC2-2B-C4-A-A3G5-B2-3BG2-M3CB2-C5-2A128-4G4-6BG3-3C3BC4-E2-2G6-2(B2-)G3-C2MB2-C7-3G5-B2-3BG3-3CB2-C7-4G4-3G8-M2-2BC4-E2-2G-G4-G-2(G11-B-C4-E12-)G11-2BC4-E108-GF10-2B2(C4-E12-G11-B-)C4-E12-G11-2BC4-E13-4G3-3CB2-C18-G2-G3-C2-B2-C17-5G3-3C3BJ4-3J131-I3-I2(G26-G4-)2G8-7A4-3A2C-C4-C-2C2-C3-C2-2B-C4-A-A2G-G4-B-2B2-G3-C2-2B-C4-A-A32-2G6-2(B2-)G2-MC2-B2-C6-A17-M110-2G-G4-B-2B2-G3-C2-2B-C4-E34-2G6-2(B2-)G3-C2-B2-C7-2G-G4-G-G11-B-C4-E76-G11-B-C4-E-E106-GF10-B-C4-E76-G11-B-C4-E13-G2-G3-C2-B2-C21-F27-2G2-G3-C2-2B-J4-J-J129-G5-IG55-2G-G4-G9-A2-2A-A4-A-A3C5-C2-4C3-3CB2-C5-2A3G5-B2-3BG3-3CB2-C5-2A2G6-2(B2-)G3-C2-B2-C6-A49-2M109-3G5-B2-3BG3-3CB2-C71-3G5-G15-C7-2G6-G15-2(C31-)C4-3F26-3F77-F13-3(C31-)C21-F60-4G3-3CB2-C5-2A120-3I25-4I9-G6-G4-2I17-3G5-G9-4A2-A5-2A
