model
size = 24 31 13, scale = 0.05, origin = -y
material 
  colors = A:#002 B:#00A C:#3F6 D:#001
voxels
--BBBBBBBBBBBBBBBBBBBB-- --AAAAAAACCCCCAAAAAAAA-- --AAAAACCCCCCCCCAAAAAA-- --AAACCCCCCCCCCCCCAAAA-- --AAACCCCDDDCCCCCCAAAA-- --AACCDCDCCCDCDCCCCAAA-- --AACCCDCCCCCDCCCCCAAA-- --ACCCCCCCCCCCCCCCCCAA-- --ACCCCCCCCCCCCCCCCCAA-- --ACCCCCCCCCCCCCCCCCAA-- --ACCCCDDCCCCCCCCCCCAA-- --ACCCCDDCCCCDDCCCCCAA-- --AACCCCCCCCCCCCCCCAAA-- --AACCDDDCCCCDDDCCCAAA-- --AAACCCCCCCCCCCCCAAAA-- --AAACCCCCCCCCCCCCAAAA-- --AAAAACCCCCCCCCAAAAAA-- --AAAAAAACCCCCAAAAAAAA-- --AAAAAAAABBBAAAAAAAAA-- --AAAAAABB---BBBAAAAAA-- --BBBBBB--------BBBBBB-- --BBABAB--------BABABB-- ---BABAB--------BABAB--- ---BABAB--------BABAB--- ---BABAB--------BABAB--- ---BABAB--------BABAB--- ---BABAB--------BABAB--- ------------------------ ------------------------ ------------------------ ------------------------ 
-B--------------------B- -AA------------------AA- -AA------------------AA- -AA------------------AA- -AA------------------AA- -AA------------------AA- -AA------------------AA- -AA------------------AA- -AA------------------AA- -AA------------------AA- -AA------------------AA- -AA------------------AA- -AA------------------AA- -AA------------------AA- -AA------------------AA- -AA------------------AA- -AA------------------AA- -AA------------------AA- -AA------------------AA- -AA------------------AA- -B--------------------B- ------------------------ ------------------------ ------------------------ ------------------------ ------------------------ ------------------------ ---BABAB--------BABAB--- ------------------------ ------------------------ ------------------------ 
BB---------------------B AA--------------------BA AA--------------------AA AA--------------------AA AA--------------------AA AA--------------------AA AA--------------------AA AA--------------------AA AA--------------------AA AA--------------------AA AA--------------------AA AA--------------------AA AA--------------------AA AA--------------------AA AA--------------------AA AA--------------------AA AA--------------------AA AA--------------------AA AA--------------------AA BA--------------------AB ------------------------ ------------------------ ------------------------ ------------------------ ------------------------ ------------------------ ------------------------ ------------------------ ---BABAB--------BABAB--- ------------------------ ------------------------ 
------------------------ B----------------------B A----------------------A A----------------------A A----------------------A A----------------------A A----------------------A A----------------------A A----------------------A A----------------------A A----------------------A A----------------------A A----------------------A A----------------------A A----------------------A A----------------------A A----------------------A A----------------------A A----------------------A B----------------------B ------------------------ ------------------------ ------------------------ ------------------------ ------------------------ ------------------------ ------------------------ ------------------------ ------------------------ ---BABAB--------BABAB--- ------------------------ 
------------------------ B----------------------B B----------------------B B----------------------B B----------------------B B----------------------B B----------------------B B----------------------B B----------------------B B----------------------B B----------------------B B----------------------B B----------------------B B----------------------B B----------------------B B----------------------B B----------------------B B----------------------B B----------------------B B----------------------B ------------------------ ------------------------ ------------------------ ------------------------ ------------------------ ------------------------ ------------------------ ------------------------ ------------------------ ------------------------ ---BABAB--------BABAB--- 
------------------------ B----------------------B A----------------------A A----------------------A A----------------------A A----------------------A A----------------------A A----------------------A A----------------------A A----------------------A A----------------------A A----------------------A A----------------------A A----------------------A A----------------------A A----------------------A A----------------------A A----------------------A A----------------------A B----------------------B ------------------------ ------------------------ ------------------------ ------------------------ ------------------------ ------------------------ ------------------------ ------------------------ ------------------------ ------------------------ ---BABAB--------BABAB--- 
------------------------ B----------------------B B----------------------B B----------------------B B----------------------B B----------------------B B----------------------B B----------------------B B----------------------B B----------------------B B----------------------B B----------------------B B----------------------B B----------------------B B----------------------B B----------------------B B----------------------B B----------------------B B----------------------B B----------------------B ------------------------ ------------------------ ------------------------ ------------------------ ------------------------ ------------------------ ------------------------ ------------------------ ------------------------ ------------------------ ---BABAB--------BABAB--- 
------------------------ B----------------------B A----------------------A A----------------------A A----------------------A A----------------------A A----------------------A A----------------------A A----------------------A A----------------------A A----------------------A A----------------------A A----------------------A A----------------------A A----------------------A A----------------------A A----------------------A A----------------------A A----------------------A B----------------------B ------------------------ ------------------------ ------------------------ ------------------------ ------------------------ ------------------------ ------------------------ ------------------------ ------------------------ ------------------------ ---BABAB--------BABAB--- 
------------------------ B----------------------B B----------------------B B----------------------B B----------------------B B----------------------B B----------------------B B----------------------B B----------------------B B----------------------B B----------------------B B----------------------B B----------------------B B----------------------B B----------------------B B----------------------B B----------------------B B----------------------B B----------------------B B----------------------B ------------------------ ------------------------ ------------------------ ------------------------ ------------------------ ------------------------ ------------------------ ------------------------ ------------------------ ------------------------ ---BABAB--------BABAB--- 
------------------------ B----------------------B A----------------------A A----------------------A A----------------------A A----------------------A A----------------------A A----------------------A A----------------------A A----------------------A A----------------------A A----------------------A A----------------------A A----------------------A A----------------------A A----------------------A A----------------------A A----------------------A A----------------------A B----------------------B ------------------------ ------------------------ ------------------------ ------------------------ ------------------------ ------------------------ ------------------------ ------------------------ ------------------------ ---BABAB--------BABAB--- ------------------------ 
BB--------------------BB BB--------------------BB BA--------------------AB BA--------------------AB BA--------------------AB BA--------------------AB BA--------------------AB BA--------------------AB BA--------------------AB BA--------------------AB BA--------------------AB BA--------------------AB BA--------------------AB BA--------------------AB BA--------------------AB BA--------------------AB BA--------------------AB BA--------------------AB BA--------------------AB BA--------------------AB ------------------------ ------------------------ ------------------------ ------------------------ ------------------------ ------------------------ ------------------------ ------------------------ ---BABAB--------BABAB--- ------------------------ ------------------------ 
-BB------------------BB- -AA------------------AA- -AA------------------AA- -AA------------------AA- -AA------------------AA- -AA------------------AA- -AA------------------AA- -AA------------------AA- -AA------------------AA- -AA------------------AA- -AA------------------AA- -AA------------------AA- -AA------------------AA- -AA------------------AA- -AA------------------AA- -AA------------------AA- -AA------------------AA- -AA------------------AA- -AA------------------AA- -AA------------------AA- -B--------------------B- ------------------------ ------------------------ ------------------------ ------------------------ ------------------------ ------------------------ ---BABAB--------BABAB--- ------------------------ ------------------------ ------------------------ 
--BBBBBBBBBBBBBBBBBBBB-- --AAAAAAAAAAAAAAAAAAAA-- --AAAAAAAACCCCCAAAAAAA-- --AAAAAACCCCCCCCCAAAAA-- --AAAACCCCCCCCCCCCCAAA-- --AAAACCCCCCCCCCCCCCAA-- --AAACCCCCCCCCCCCCCCAA-- --AAACCCCCCCCCCCCAAAAA-- --AACCCCCCCCCCAAAAAAAA-- --AACCCCCCCCAAAAAAAAAA-- --AACCCCCCCCAAAAAAAAAA-- --AACCCCCCCCCCAAAAAAAA-- --AACCCCCCCCCCCCAAAAAA-- --AAACCCCCCCCCCCCCCAAA-- --AAACCCCCCCCCCCCCCCAA-- --AAAACCCCDDCCCCCCCAAA-- --AAAACCCCDDCCCCCCCAAA-- --AAAAAACCCCCCCCCAAAAA-- --AAAAAAAACCCCCAAAAAAA-- --AAAAAABBBBBBBBAAAAAA-- --BBBBBB--------BBBBBB-- ---BABAB--------BABAB--- ---BABAB--------BABAB--- ---BABAB--------BABAB--- ---BABAB--------BABAB--- ---BABAB--------BABAB--- ---BABAB--------BABAB--- ------------------------ ------------------------ ------------------------ ------------------------ 
