model
size = 9 31 17, scale = 0.05, origin = -y
material 
  colors = A:#4E2B0F B:#000 C:#341800 D:#EEE
voxels
--------- --------- --------- --------- --------- --------- --------- --------- --------- --------- --------- --------- --------- --------- --------- --------- --------- --------- --------- --------- --------- --------- --------- ---BBB--- --BBBBB-- -BBBBBBB- -BBBBBBB- -BBBBBBB- --BBBBB-- ---BBB--- --------- 
--------- --------- --------- --------- --------- --------- --------- --------- --------- --------- --------- --------- --------- --------- --------- --------- --------- --------- --------- --------- --------- --------- --AAAAA-- -AAAAAAA- AAAAAAAAA AAAAAAAAA AAAAAAAAA AAAAAAAAA AAAAAAAAA -AAAAAAA- --AAAAA-- 
--------- --------- --------- --------- --------- --------- --------- --------- --------- --------- --------- --------- --------- --------- --------- --------- --------- --------- --------- --------- --------- --------- --AAAAA-- -AAAAAAA- AAAAAAAAA AAAAAAAAA AAAAAAAAA AAAAAAAAA AAAAAAAAA -AAAAAAA- --AAAAA-- 
--------- --------- --------- --------- --------- --------- --------- --------- --------- --------- --------- --------- --------- --------- --------- --------- --------- --------- --------- --------- --------- --------- --------- ----C---- ---CCC--- --CCCCC-- -CCCCCCC- --CCCCC-- ---CCC--- ----C---- --------- 
--------- --------- --------- --------- --------- --------- --------- --------- --------- --------- --------- --------- --------- --------- --------- --------- --------- --------- --------- --------- --------- --------- --------- ---AAA--- --AAAAA-- -AAAAAAA- -AAAAAAA- -AAAAAAA- --AAAAA-- ---AAA--- --------- 
--------- --------- --------- --------- --------- --------- --------- --------- --------- --------- --------- --------- --------- --------- --------- --------- --------- --------- --------- --------- --------- --------- --------- ---AAA--- --AAAAA-- -AAAAAAA- -AAAAAAA- -AAAAAAA- --AAAAA-- ---AAA--- --------- 
---BBB--- ----C---- --------- --------- --------- --------- --------- --------- --------- --------- --------- --------- --------- --------- --------- --------- --------- --------- --------- --------- --------- --------- ----A---- ---AAA--- --AAAAA-- -AAAAAAA- -AAAAAAA- -AAAAAAA- --AAAAA-- ---AAA--- --------- 
--BDDDB-- ---AAA--- ----AC--- ----A---- ----A---- ---CC---- ----CC--- ----A---- ----A---- ---CC---- ----CC--- ----A---- ----A---- ----A---- ----A---- ----A---- ----A---- ----A---- ----A---- ----A---- ----A---- ---BAB--- ---AAA--- ---AAA--- --AAAAA-- -AAAAAAA- -AAAAAAA- -AAAAAAA- --AAAAA-- ---AAA--- --------- 
--BDBDB-- --CAAAC-- ---AAC--- ---AAC--- ---CAA--- ---CAA--- ---AAC--- ---AAC--- ---CAA--- ---CAA--- ---AAC--- ---AAC--- ---AAA--- ---AAA--- ---AAA--- ---AAA--- ---AAA--- ---AAA--- ---AAA--- ---AAA--- ---AAA--- ---AAA--- ---AAA--- ---AAA--- --AAAAA-- -AAAAAAA- -AAAAAAA- -AAAAAAA- --AAAAA-- ---AAA--- --------- 
--BDBDB-- ---AAA--- ----A---- ----CC--- ---CC---- ----A---- ----A---- ----CC--- ---CC---- ----A---- ----A---- ----AC--- ----A---- ----A---- ----A---- ----A---- ----A---- ----A---- ----A---- ----A---- ----A---- ---BAB--- ---AAA--- ---AAA--- --AAAAA-- -AAAAAAA- -AAAAAAA- -AAAAAAA- --AAAAA-- ---AAA--- --------- 
---BBB--- ----C---- --------- --------- --------- --------- --------- --------- --------- --------- --------- --------- --------- --------- --------- --------- --------- --------- --------- --------- --------- --------- ----A---- ---AAA--- --AAAAA-- -AAAAAAA- -AAAAAAA- -AAAAAAA- --AAAAA-- ---AAA--- --------- 
--------- --------- --------- --------- --------- --------- --------- --------- --------- --------- --------- --------- --------- --------- --------- --------- --------- --------- --------- --------- --------- --------- --------- ---AAA--- --AAAAA-- -AAAAAAA- -AAAAAAA- -AAAAAAA- --AAAAA-- ---AAA--- --------- 
--------- --------- --------- --------- --------- --------- --------- --------- --------- --------- --------- --------- --------- --------- --------- --------- --------- --------- --------- --------- --------- --------- --------- ---AAA--- --AAAAA-- -AAAAAAA- -AAAAAAA- -AAAAAAA- --AAAAA-- ---AAA--- --------- 
--------- --------- --------- --------- --------- --------- --------- --------- --------- --------- --------- --------- --------- --------- --------- --------- --------- --------- --------- --------- --------- --------- --------- ----C---- ---CCC--- --CCCCC-- -CCCCCCC- --CCCCC-- ---CCC--- ----C---- --------- 
--------- --------- --------- --------- --------- --------- --------- --------- --------- --------- --------- --------- --------- --------- --------- --------- --------- --------- --------- --------- --------- --------- --AAAAA-- -AAAAAAA- AAAAAAAAA AAAAAAAAA AAAAAAAAA AAAAAAAAA AAAAAAAAA -AAAAAAA- --AAAAA-- 
--------- --------- --------- --------- --------- --------- --------- --------- --------- --------- --------- --------- --------- --------- --------- --------- --------- --------- --------- --------- --------- --------- --AAAAA-- -AAAAAAA- AAAAAAAAA AAAAAAAAA AAAAAAAAA AAAAAAAAA AAAAAAAAA -AAAAAAA- --AAAAA-- 
--------- --------- --------- --------- --------- --------- --------- --------- --------- --------- --------- --------- --------- --------- --------- --------- --------- --------- --------- --------- --------- --------- --------- ---BBB--- --BBBBB-- -BBBBBBB- -BBBBBBB- -BBBBBBB- --BBBBB-- ---BBB--- --------- 
