model
size = 31, scale = 0.05, origin = -y
material 
  colors = A:#080 B:#0B0 C:#0D0 D:#C36 E:#C00 F:#DDD G:#A00 H:#D00 I:#700
voxels
------------------------------- ------------------------------- ------------------------------- ------------------------------- ------------------------------- ------------------------------- ------------------------------- --------------B-B-------------- --------------BBB-------------- ------------BBBBBBB------------ -------------FFFFF------------- -------------F---F------------- -------------F---F------------- ------------------------------- ------------------------------- ------------------------------- ------------------------------- ------------------------------- ------------------------------- ------------------------------- ------------------------------- ------------------------------- ------------------------------- ------------------------------- ------------------------------- ------------------------------- ------------------------------- ------------------------------- ------------------------------- ------------------------------- ------------------------------- 
------------------------------- ------------------------------- ------------------------------- ------------------------------- ------------------------------- ------------------------------- --------------B-B-------------- --------------BBB-------------- ------------BBBBB-B------------ -----------BBBBBBBB------------ ------------FBBBBBF------------ ------------FBFFFBB------------ -------------FBBBF------------- ------------F--B--F------------ ------------F-----F------------ ------------F-----F------------ ------------------------------- ------------------------------- ------------------------------- ------------------------------- ------------------------------- ------------------------------- ------------------------------- ------------------------------- ------------------------------- ------------------------------- ------------------------------- ------------------------------- ------------------------------- ------------------------------- ------------------------------- 
------------------------------- ------------------------------- ------------------------------- ------------------------------- ------------------------------- ------------------------------- --------------B-B-------------- --------------BBBB------------- -------------BBBBBB------------ -----------BBBBBBBB------------ ------------FBBBBBF------------ ------------BB---BB------------ -------------FBBBF------------- ---------------B--------------- ------------------------------- ------------------------------- ------------------------------- ------------------------------- ------------------------------- ------------------------------- ------------------------------- ------------------------------- ------------------------------- ------------------------------- ------------------------------- ------------------------------- ------------------------------- ------------------------------- ------------------------------- ------------------------------- ------------------------------- 
------------------------------- ------------------------------- ------------------------------- ------------------------------- ------------------------------- ------------------------------- ---------------B-B------------- --------------BB-B------------- -------------BBBBB------------- -----------BBBBBBBB------------ ------------FBBBBBF------------ ------------BB---BB------------ ------------BBBBBBB------------ ---------------B--------------- ---------------B--------------- ------------------------------- ------------------------------- ------------------------------- ------------------------------- ------------------------------- ------------------------------- ------------------------------- ------------------------------- ------------------------------- ------------------------------- ------------------------------- ------------------------------- ------------------------------- ------------------------------- ------------------------------- ------------------------------- 
------------------------------- ------------------------------- ------------------------------- ------------------------------- ------------------------------- ------------------------------- ---------------B-B------------- ------------BB-B-B------------- -------------BBBBB------------- -----------BBBBBBBB------------ ------------BBBBBBB------------ -----------BBBBBBBBB----------- -----------BBBBBBBBB----------- ------------BBB-BBBB----------- ------------------------------- ------------------------------- ------------------------------- ------------------------------- ------------------------------- ------------------------------- ------------------------------- ------------------------------- ------------------------------- ------------------------------- ------------------------------- ------------------------------- ------------------------------- ------------------------------- ------------------------------- ------------------------------- ------------------------------- 
------------------------------- ------------------------------- ------------------------------- ------------------------------- ------------------------------- ------------------------------- -------------B----------------- -------------B-B--------------- -------------BBB-B------------- -------------BCCCBB------------ -------------CCCCC------------- -----------BCCCCCCCB----------- -----------CCCCCCCCC----------- -----------BCCCCCCCC----------- -------------BBBBB------------- ---------------B--------------- ------------------------------- ------------------------------- ------------------------------- ------------------------------- ------------------------------- ------------------------------- ------------------------------- ------------------------------- ------------------------------- ------------------------------- ------------------------------- ------------------------------- ------------------------------- ------------------------------- ------------------------------- 
------------------------------- ------------------------------- ------------------------------- ------------------------------- ------------------------------- ------------------------------- -------------B--BB------------- -------------BBBBBB------------ -------------BBBBBB------------ -------------BCCCBB------------ ------------BCCCCC------------- -----------CCCCCCCCC----------- -----------CCCCCCCCC----------- -----------CCCCCCCCC----------- ------------BBBBBBB------------ -------------BBBBB------------- ---------------B--------------- ------------------------------- ------------------------------- ------------------------------- ------------------------------- ------------------------------- ------------------------------- ------------------------------- ------------------------------- ------------------------------- ------------------------------- ------------------------------- ------------------------------- ------------------------------- ------------------------------- 
------------------------------- ------------------------------- ------------------------------- ------------------------------- ------------------------------- -------------BB--B------------- -------------BBB-B------------- -------------BBBBBB------------ ------------BBBB-BB------------ -------------BCCCBB------------ ------------BCCCCC------------- -----------CCCCCCCCC----------- -----------CCCCCCCCC----------- -----------CCCCCCCCC----------- ------------BCCCCCB------------ -------------CCCCC------------- --------------CBC-------------- ---------------B--------------- ------------------------------- ------------------------------- ------------------------------- ------------------------------- ------------------------------- ------------------------------- ------------------------------- ------------------------------- ------------------------------- ------------------------------- ------------------------------- ------------------------------- ------------------------------- 
------------------------------- ------------------------------- ------------------------------- ------------------------------- ------------------------------- -------------BB---------------- -------------BB--BB------------ -------------BBBBBB------------ -------------BBB-BB------------ -------------BCCCBB------------ ------------BCCCCC------------- -----------CCCCCCCCC----------- -----------CCCCCCCCC----------- -----------CCCCCCCCB----------- ------------BCCCCCB------------ -------------CCCCC------------- --------------CCC-------------- --------------CCC-------------- --------------CBC-------------- ------------------------------- ------------------------------- ------------------------------- ------------------------------- ------------------------------- ------------------------------- ------------------------------- ------------------------------- ------------------------------- ------------------------------- ------------------------------- ------------------------------- 
------------------------------- ------------------------------- ------------------------------- ------------------------------- ------------------------------- -------------BB---------------- -------------BB--B------------- -------------BBBBBB------------ --------------BBBBB------------ ------------BBCCCBB------------ ------------BCCCCC------------- -----------BCCCCCCCB----------- -----------CCCCCCCCC----------- ---------B-BCCCCCCCA----------- ------------BCCCCCB------------ -------------CCCCC------------- --------------CCC-------------- --------------CCC-------------- --------------CCC-------------- --------------B-B-------------- ----------BBBB---BBBB---------- ------------------------------- ------------------------------- ------------------------------- ------------------------------- ------------------------------- ------------------------------- ------------------------------- ------------------------------- ------------------------------- ------------------------------- 
------------------------------- ------------------------------- ------------------------------- ------------------------------- --------------B---------------- -------------BBB--B------------ -------------BBB--B------------ ------------BBBBBBB------------ -----------BBAAAABB------------ -----------BAACCCA------------- ----------AAACCCCCAAA---------- ----------AACCCCCCCCA---------- -------B-AAACCCCCCCCA---------- ---------AAACCCCCCCCA---------- ---------AAAACCCCCAAA---------- ---------AAAACCCCCAAA---------- ---------AAAAACCCAAAAB--------- ---------AAAAAAAAAAAA---------- ---------AAHIHAAAHIHA---------- ----------AHHHAAAHHHA---------- ----------AAAAAAAAAAA---------- ------------AAAAAA------------- -------------AAAA-------------- ------------------------------- ------------------------------- ------------------------------- ------------------------------- ------------------------------- ------------------------------- ------------------------------- ------------------------------- 
------------------------------- ------------------------------- ------------------------------- ------------------------------- ------------------------------- -------------BBB--B------------ ------------BBBBB-B------------ -----------BBBBBBBB------------ -----------AAAAAAAAA----------- ----------AAAACCCAAAAB--------- ---------AAAACCCCCAAAA--------- -------AAAAACCCCCCCCAA-B------- -------AAAAACCCACCCCAA--------- -------AAAAACCCCCCCCAA--------- -------AAAAAACCCCCAAAA--------- -------AAAAAACCCCCAAAA--------- -------AAAAAAACCCAAAAA--------- ------BAAAAAAAAAAAAAAA--------- -------AAAAAAAAAAAAAAA--------- -------AAAAAAAAAAAAAAA--------- -------BBAAAAAAAAAAAAA--------- ----------AAAAAAAAAAA---------- -----------AAAAAAAAA----------- ------------------------------- ------------------------------- ------------------------------- ------------------------------- ------------------------------- ------------------------------- ------------------------------- ------------------------------- 
------------------------------- ------------------------------- ------------------------------- -------------B----------------- -------------BB---------------- ------------BBBBBBB------------ -----------BBAAAABBB----------- -----------AAAAAAAAA----------- ---------AAAAAAAAAAAAA--------- -------AAAAAAAAAAAAAAAA-------- -------AAAAAAAAAAAAAAAA-------- -------AAAAAAAAAAAAAAAAA------- -------AAAAAAAAAAAAAAAA-------- -------AAAAAAAAAAAAAAAA-------- -------AAAAAAAAAAAAAAAA-------- -------AAAAAAAAAAAAAAAA-------- -------AAAAAAAAAAAAAAAA-------- -------AAAAAAAAAAAAAAAA-------- -------AAAAAAAAAAAAAAAA-------- -------AAAAAAAAAAAAAAAA-------- -------AAAAAAAAAAAAAAAAB------- -------AAAAAAAAAAAAAAAA-------- ---------AAAAAAAAAAAAA--------- -----------AAAAAAAAA----------- -------------AAAA-------------- -------------D-DDE------------- ----------------E-------------- ------------------------------- ------------------------------- ------------------------------- ------------------------------- 
-------------AAAAA------------- -------------AAAAAB------------ -------------AAAAA------------- ------------BAAAAA------------- ------------BABAAB------------- ------------BBBB-BB------------ -----------BAAAAAABB----------- ----------AAAAAAAAAAA---------- -------AAAAAAAAAAAAAAAA-------- -------AAAAAAAAAAAAAAAA-------- -------AAAAAAAAAAAAAAAAA------- -------AAAAAAAAAAAAAAAAA------- -------AAAAAAAAAAAAAAAAA------- -------AAAAAAAAAAAAAAAAA------- -------AAAAAAAAAAAAAAAAA------- -------AAAAAAAAAAAAAAAAA------- -------AAAAAAAAAAAAAAAAA------- -------AAAAAAAAAAAAAAAAA------- -------AAAAAAAAAAAAAAAAA------- -------AAAAAAAAAAAAAAAAA------- -------AAAAAAAAAAAAAAAAA------- -------AAAAAAAAAAAAAAAA-------- -------AAAAAAAAAAAAAAAA-------- ----------AAAAAAAAAAA---------- ------------AAAAAA--B---------- -------------D-DDD------------- --------------D-EE------------- ---------------D--------------- ------------------------------- ------------------------------- ------------------------------- 
----------BAAAAAAAAA----------- -----------AAAAAAAAA----------- -----------AAAAAAAAA----------- -----------AAAAAAAAA----------- -----------AAABBABAA----------- ------------BBAA-B-B----------- ----------AAAAAAAAAAA---------- --------BAAAAAAAAAAAAA--------- -------AAAAAAAAAAAAAAAA-------- -------AAAAAAAAAAAAAAAAA------- -------AAAAAAAAAAAAAAAAA------- -------AAAAAAAAAAAAAAAAA------- -------AAAAAAAAAAAAAAAAA------- ------BAAAAAAAAAAAAAAAAA------- -------AAAAAAAAAAAAAAAAA------- -------AAAAAAAAAAAAAAAAA------- -------AAAAAAAAAAAAAAAAA------- -------AAAAAAAAAAAAAAAAA------- -------AAAAAAAAAAAAAAAAA------- -------AAAAAAAAAAAAAAAAA------- ------BAAAAAAAAAAAAAAAAA------- -------AAAAAAAAAAAAAAAAA------- -------AAAAAAAAAAAAAAAA-------- ---------AAAAAAAAAAAAA--------- ----------AAAAAAAAAAA---------- --------------AAD-------------- --------------DDD-------------- --------------DDE-------------- ---------------D--------------- ------------------------------- ------------------------------- 
----------AAAAAAAAAAA---------- ----------AAAAAAAAAAA---------- ----------AAAAAAAAAAA---------- ----------AAAABAAAAAAB--------- ----------AAABBAABAAA---------- ----------ABAAAAAA-BA---------- ----------AAAAAAAAAAA---------- -------AAAAAAAAAAAAAAAA-------- -------AAAAAAAAAAAAAAAAA------- -------AAAAAAAAAAAAAAAAA------- -------AAAAAAAAAAAAAAAAA------- -------AAAAAAAAAAAAAAAAA------- -------AAAAAAAAAAAAAAAAA------- -------AAAAAAAAAAAAAAAAA------- -------AAAAAAAAAAAAAAAAAB------ -------AAAAAAAAAAAAAAAAA------- -------AAAAAAAAAAAAAAAAA------- -------AAAAAAAAAAAAAAAAA------- -------AAAAAAAAAAAAAAAAA------- -------AAAAAAAAAAAAAAAAA------- -------AAAAAAAAAAAAAAAAA------- -------AAAAAAAAAAAAAAAAA------- -------AAAAAAAAAAAAAAAAA------- -------AAAAAAAAAAAAAAAA-------- ----------AAAAAAAAAAA---------- ------------AAAAAA------------- ------------DDDDDD------------- ------------EE-D-E------------- -------------E-DE-------------- ------------------------------- ------------------------------- 
---------AAAAAAAAAAAAA--------- ---------AAAAAAAAAAAAA--------- ---------AAAAAAAAAAAAA--------- --------BAAAAAAAAAAAAA--------- ---------AAAABAAABAAAA--------- ---------AAAAAAAAAAAAA--------- ---------AAAAAAAAAAAAA--------- -------AAAAAAAAAAAAAAAA-------- -------AAAAAAAAAAAAAAAAA------- -------AAAAAAAAAAAAAAAAA------- -------AAAAAAAAAAAAAAAAA------- -------AAAAAAAAAAAAAAAAA------- -------AAAAAAAAAAAAAAAAA------- -------AAAAAAAAAAAAAAAAA------- -------AAAAAAAAAAAAAAAAA------- -------AAAAAAAAAAAAAAAAA------- -------AAAAAAAAAAAAAAAAA------- -------AAAAAAAAAAAAAAAAA------- -------AAAAAAAAAAAAAAAAA------- -------AAAAAAAAAAAAAAAAA------- -------AAAAAAAAAAAAAAAAA------- -------AAAAAAAAAAAAAAAAA------- -------AAAAAAAAAAAAAAAAA------- -------AAAAAAAAAAAAAAAA-------- ---------AAAAAAAAAAAAA--------- -----------AAAAAAAAA----------- ------------DDBDDD------------- ------------EEDDD-------------- -------------EDDE-------------- --------------D-E-------------- ------------------------------- 
---------AAAAAAAAAAAAA--------- ---------AAAAAAAAAAAAA--------- ---------AAAAAAAAAAAAA--------- ---------AAAABAAAAAAAA--------- ---------AAAA-AAAAAAAA--------- ---------AAAAAAAAAAAAA--------- ---------AAAAAAAAAAAAA--------- -------AAAAAAAAAAAAAAAA-------- -------AAAAAAAAAAAAAAAAAB------ -------AAAAAAAAAAAAAAAAA------- -------AAAAAAAAAAAAAAAAA------- -------AAAAAAAAAAAAAAAAA------- -------AAAAAAAAAAAAAAAAA------- -------AAAAAAAAAAAAAAAAA------- -------AAAAAAAAAAAAAAAAA------- -------AAAAAAAAAAAAAAAAA------- -------AAAAAAAAAAAAAAAAA------- -------AAAAAAAAAAAAAAAAA------- -------AAAAAAAAAAAAAAAAA------- -------AAAAAAAAAAAAAAAAAB------ -------AAAAAAAAAAAAAAAAA------- -------AAAAAAAAAAAAAAAAA------- -------AAAAAAAAAAAAAAAAA------- -------AAAAAAAAAAAAAAAA-------- ---------AAAAAAAAAAAAA--------- ----------BAAAAAAAAA----------- ------------DDDDDD------------- ------------EDDDD-------------- -------------EDDE-------------- -------------EEEE-------------- -------------E----------------- 
--------AAAAAAAAAAAAAAA-------- --------AAAAAAAAAAAAAAA-------- --------AAAAAAAAAAAAAAA-------- --------AAAAAAAAAAAAAAA-------- --------AAAAAAAAAAAAAAA-------- --------AAAAAAAAAAAAAAA-------- -------AAAAAAAAAAAAAAAA-------- -------AAAAAAAAAAAAAAAA-------- ------BAAAAAAAAAAAAAAAAA------- -------AAAAAAAAAAAAAAAAA------- -------AAAAAAAAAAAAAAAAA------- -------AAAAAAAAAAAAAAAAA------- -------AAAAAAAAAAAAAAAAA------- -------AAAAAAAAAAAAAAAAA------- -------AAAAAAAAAAAAAAAAA------- -------AAAAAAAAAAAAAAAAA------- -------AAAAAAAAAAAAAAAAA------- -------AAAAAAAAAAAAAAAAA------- -------AAAAAAAAAAAAAAAAA------- -------AAAAAAAAAAAAAAAAA------- -------AAAAAAAAAAAAAAAAA------- -------AAAAAAAAAAAAAAAAA------- -------AAAAAAAAAAAAAAAAA------- -------AAAAAAAAAAAAAAAA-------- -------AAAAAAAAAAAAAAAA-------- -----------AAAAAAAAABB--------- ------------DDDDDD------------- ------------EDDDD-------------- -------------EDDDE------------- -------------EEEEE------------- ------------------------------- 
--------AAAAAAAAAAAAAAA-------- --------AAAAAAAAAAAAAAA-------- --------AAAAAAAAAAAAAAA-------- --------AAAAAAAAAAAAAAA-------- --------AAAAAAAAAAAAAAA-------- --------AAAAAAAAAAAAAAA-------- -------AAAAAAAAAAAAAAAA-------- -------AAAAAAAAAAAAAAAA-------- -------AAAAAAAAAAAAAAAAA------- -------AAAAAAAAAAAAAAAAA------- -------AAAAAAAAAAAAAAAAA------- ------BAAAAAAAAAAAAAAAAAB------ -----BBAAAAAAAAAAAAAAAAABB----- ----BBBAAAAAAAAAAAAAAAAABBB---- ---BBBBAAAAAAAAAAAAAAAAABBBB--- ---BB-BAAAAAAAAAAAAAAAAAB--B--- --BB--BAAAAAAAAAAAAAAAAAB--BB-- --B---BAAAAAAAAAAAAAAAAAB---B-- -BB---BAAAAAAAAAAAAAAAAAB----B- BB---BBAAAAAAAAAAAAAAAAABB---BB B----B-AAAAAAAAAAAAAAAAA-B----B B---BB-AAAAAAAAAAAAAAAAA-BB---B BB-BB--AAAAAAAAAAAAAAAAA--BB--B BBBB---AAAAAAAAAAAAAAAA----B-BB -BBB---AAAAAAAAAAAAAAAA----BBB- --B------BAAAAAAAAAAA-------B-- -----------DDDEDDD------------- ------------EDEDD-------------- -------------EEDDE------------- -------------E-EEE------------- ------------------------------- 
--------AAAAAAA-AAAAAAA-------- --------AAAAAAA-AAAAAAA-------- --------AAAAAAA-AAAAAAA-------- --------AAAAAAAAAAAAAAA-------- --------AAAAAAAAAAAAAAA-------- --------AAAAAAAAAAAAAAAB------- -------AAAAAAAAAAAAAAAA-------- -------AAAAAAAAAAAAAAAA-------- -------AAAAAAAAAAAAAAAAA------- -------AAAAAAAAAAAAAAAAA------- -------AAAAAAAAAAAAAAAAA------- ------BAAAAAAAAAAAAAAAAAB------ -----BBAAAAAAAAAAAAAAAAABB----- ----BBBAAAAAAAAAAAAAAAAABBB---- ---BBBBAAAAAAAAAAAAAAAAABBBB--- ---BBBBAAAAAAAAAAAAAAAAABBBB--- --BBGGBAAAAAAAAAAAAAAAAABBBBB-- --BBGBBAAAAAAAAAAAAAAAAABBGBB-- -BBGGBBAAAAAAAAAAAAAAAAABBGGBB- BBBGGBBAAAAAAAAAAAAAAAAABBBGGBB BBGGBB-AAAAAAAAAAAAAAAAA-BBBGBB BBBBBB-AAAAAAAAAAAAAAAAA-BBBGBB BBBBB--AAAAAAAAAAAAAAAAA--BBBBB BBBB---AAAAAAAAAAAAAAAA----BBBB -BBB---AAAAAAAAAAAAAAAA----BBB- --B-------AAAAAAAAAAA-------B-- -----------DEDDDDD------------- ------------EDEDD-------------- -------------E-DD-------------- -------------E-EE-------------- ------------------------------- 
--------AAAAAAAAAAAAAAA-------- --------AAAAAAAAAAAAAAA-------- --------AAAAAAAAAAAAAAA-------- --------AAAAAAAAAAAAAAA-------- --------AAAAAAAAAAAAAAA-------- --------AAAAAAAAAAAAAAA-------- -------AAAAAAAAAAAAAAAA-------- -------AAAAAAAAAAAAAAAA-------- -------AAAAAAAAAAAAAAAAA------- -------AAAAAAAAAAAAAAAAA------- -------AAAAAAAAAAAAAAAAA------- -------AAAAAAAAAAAAAAAAA------- -------AAAAAAAAAAAAAAAAA------- -------AAAAAAAAAAAAAAAAA------- -------AAAAAAAAAAAAAAAAA------- -------AAAAAAAAAAAAAAAAA------- -------AAAAAAAAAAAAAAAAAB------ -------AAAAAAAAAAAAAAAAA------- ----B--AAAAAAAAAAAAAAAAA------- -------AAAAAAAAAAAAAAAAA--B---- -------AAAAAAAAAAAAAAAAA------- -------AAAAAAAAAAAAAAAAA----B-- -------AAAAAAAAAAAAAAAAA------- --B----AAAAAAAAAAAAAAAA-------- -------AAAAAAAAAAAAAAAA-------- ----------DAAAAAAAAA----------- -----------DEDDDDD------------- ------------EEDDDD------------- -------------E-DDD------------- ---------------EDE------------- ---------------EEE------------- 
--------AAAAAAAAAAAAAAA-------- --------AAAAAAAAAAAAAAA-------- --------AAAAAAAAAAAAAAA-------- --------AAAAAAAAAAAAAAA-------- --------AAAAAAAAAAAAAAA-------- --------AAAAAAAAAAAAAAA-------- ---------AAAAAAAAAAAAA--------- -------AAAAAAAAAAAAAAAA-------- -------AAAAAAAAAAAAAAAAA------- -------AAAAAAAAAAAAAAAAA------- -------AAAAAAAAAAAAAAAAA------- -------AAAAAAAAAAAAAAAAA------- -------AAAAAAAAAAAAAAAAA------- -------AAAAAAAAAAAAAAAAA------- -------AAAAAAAAAAAAAAAAA------- -------AAAAAAAAAAAAAAAAA------- -------AAAAAAAAAAAAAAAAA------- -------AAAAAAAAAAAAAAAAA------- -------AAAAAAAAAAAAAAAAA------- -------AAAAAAAAAAAAAAAAA------- -------AAAAAAAAAAAAAAAAA------- -------AAAAAAAAAAAAAAAAA------- -------AAAAAAAAAAAAAAAAA------- -------AAAAAAAAAAAAAAAA-------- ---------AAAAAAAAAAAAA--------- ----------DAAAAAAAAA----------- -----------DEEDDDD------------- ------------EEDDDE------------- ---------------DDE------------- ---------------EEE------------- ---------------E--------------- 
---------AAAAAAAAAAAAAB-------- ---------AAAAAAAAAAAAA--------- ---------AAAAAAAAAAAAA--------- ---------AAAAAAAAAAAAA--------- ---------AAAAAAAAAAAAA--------- ---------AAAAAAAAAAAAA--------- ----------AAAAAAAAAAA---------- -------AAAAAAAAAAAAAAAA-------- -------AAAAAAAAAAAAAAAAA------- -------AAAAAAAAAAAAAAAAA------- -------AAAAAAAAAAAAAAAAA------- -------AAAAAAAAAAAAAAAAA------- -------AAAAAAAAAAAAAAAAA------- -------AAAAAAAAAAAAAAAAA------- -------AAAAAAAAAAAAAAAAA------- -------AAAAAAAAAAAAAAAAA------- -------AAAAAAAAAAAAAAAAA------- -------AAAAAAAAAAAAAAAAA------- -------AAAAAAAAAAAAAAAAA------- -------AAAAAAAAAAAAAAAAA------- -------AAAAAAAAAAAAAAAAA------- -------AAAAAAAAAAAAAAAAA------- -------AAAAAAAAAAAAAAAAA------- -------AAAAAAAAAAAAAAAA-------- ----------AAAAAAAAAAA---------- -----------DAAAAAA------------- ------------EEDDDD------------- ------------E-DDDD------------- ---------------DDE------------- ---------------EEE------------- ---------------E--------------- 
---------AAAAAAAAAAAAA--------- ---------AAAAAAAAAAAAA--------- ---------AAAAAAAAAAAAA--------- --------BAAAAAAAAAAAAA--------- ---------AAAAAAAAAAAAA--------- ---------AAAAAAAABAAAA--------- ----------AAAAAAAAAAA---------- ---------AAAAAAAAAAAAA--------- -------AAAAAAAAAAAAAAAA-------- -------AAAAAAAAAAAAAAAAA------- -------AAAAAAAAAAAAAAAAA------- -------AAAAAAAAAAAAAAAAA------- -------AAAAAAAAAAAAAAAAA------- -------AAAAAAAAAAAAAAAAA------- -------AAAAAAAAAAAAAAAAA------- -------AAAAAAAAAAAAAAAAA------- -------AAAAAAAAAAAAAAAAA------- -------AAAAAAAAAAAAAAAAA------- -------AAAAAAAAAAAAAAAAA------- -------AAAAAAAAAAAAAAAAA------- -------AAAAAAAAAAAAAAAAA------- -------AAAAAAAAAAAAAAAAAB------ -------AAAAAAAAAAAAAAAA-------- ---------AAAAAAAAAAAAA--------- ----------AAAAAAAAAAA---------- ------------DDAADD------------- ------------E-DDD-------------- --------------DDDE------------- --------------EDEE------------- ---------------EE-------------- ---------------E--------------- 
----------AAAAAAAAAAA---------- ----------AAAAAAAAAAA---------- ----------AAAAAAAAAAA---------- ----------AAAAAAAAAAA---------- ----------AAAAAAAAAAA---------- ----------AAAAAAAAAAAB--------- ------------AAAAAA------------- --------B-AAAAAAAAAAA---------- -------AAAAAAAAAAAAAAAA-------- -------AAAAAAAAAAAAAAAA-------- -------AAAAAAAAAAAAAAAAA------- -------AAAAAAAAAAAAAAAAA------- -------AAAAAAAAAAAAAAAAA------- -------AAAAAAAAAAAAAAAAA------- -------AAAAAAAAAAAAAAAAA------- ------BAAAAAAAAAAAAAAAAA------- -------AAAAAAAAAAAAAAAAA------- -------AAAAAAAAAAAAAAAAA------- -------AAAAAAAAAAAAAAAAA------- -------AAAAAAAAAAAAAAAAA------- -------AAAAAAAAAAAAAAAAA------- -------AAAAAAAAAAAAAAAA-------- -------AAAAAAAAAAAAAAAA-------- ---------BAAAAAAAAAAA---------- ------------AAAAAA------------- ------------DDDDDD------------- ------------EDDDD-------------- -------------E-DEE------------- -------------EEDE-------------- -------------E-EE-------------- ------------------------------- 
-----------AAAAAAAAA----------- -----------AAAAAAAAA----------- -----------AAAAAAAAA----------- -----------AAAAAAAAA----------- -----------AAAAAAAAA----------- -----------AAAAAAAAA----------- -------------AAAA-------------- -----------AAAAAAAAA----------- ---------AAAAAAAAAAAAA--------- -------AAAAAAAAAAAAAAAA-------- -------AAAAAAAAAAAAAAAA-------- -------AAAAAAAAAAAAAAAAA------- -------AAAAAAAAAAAAAAAAA------- -------AAAAAAAAAAAAAAAAA------- -------AAAAAAAAAAAAAAAAA------- -------AAAAAAAAAAAAAAAAA------- -------AAAAAAAAAAAAAAAAAB------ -------AAAAAAAAAAAAAAAAA------- -------AAAAAAAAAAAAAAAAA------- -------AAAAAAAAAAAAAAAAA------- ------BAAAAAAAAAAAAAAAA-------- -------AAAAAAAAAAAAAAAA-------- ---------AAAAAAAAAAAAA--------- -----------AAAAAAAAA----------- ------------DAAAAD------------- -------------DDDDD------------- -------------D-DDD------------- -------------EEDEE------------- -------------E-EEE------------- -------------E----------------- ------------------------------- 
-------------AAAAA------------- -------------AAAAAB------------ -------------AAAAA------------- -------------AAAAA------------- -------------AAAAA------------- -------------AAAAA------------- ------------------------------- ---------------B--------------- -----------AAAAAAAAAB---------- ----------AAAAAAAAAAA---------- ---------AAAAAAAAAAAAA--------- -------AAAAAAAAAAAAAAAA-------- -------AAAAAAAAAAAAAAAA-------- -------AAAAAAAAAAAAAAAA-------- -------AAAAAAAAAAAAAAAA-------- -------AAAAAAAAAAAAAAAA-------- -------AAAAAAAAAAAAAAAA-------- -------AAAAAAAAAAAAAAAA-------- -------AAAAAAAAAAAAAAAA-------- -------AAAAAAAAAAAAAAAA-------- ---------AAAAAAAAAAAAA--------- ----------AAAAAAAAAAA---------- -----------AAAAAAAAA----------- ------------DDDD-D------------- ------------DDDDDD------------- -------------D-DDE------------- -------------E-DEE------------- -------------EEDEE------------- ---------------EE-------------- ----------------E-------------- ------------------------------- 
------------------------------- ------------------------------- -------------B----------------- -------------B----------------- -------------D----------------- ------------------------------- ------------------------------- ------------------------------- -----------AAAAAAAAA----------- ----------AAAAAAAAAAA---------- ---------AAAAAAAAAAAAA--------- -------AAAAAAAAAAAAAAAA-------- -------AAAAAAAAAAAAAAAA-------- -------AAAAAAAAAAAAAAAA-------- -------AAAAAAAAAAAAAAAA-------- -------AAAAAAAAAAAAAAAA-------- -------AAAAAAAAAAAAAAAA-------- -------AAAAAAAAAAAAAAAA-------- -------AAAAAAAAAAAAAAAA-------- -------AAAAAAAAAAAAAAAA-------- ---------AAAAAAAAAAAAA--------- ----------AAAAAAAAAAA---------- -----------AAAAAAAAA----------- ------------DDDD-D------------- ------------DD-DDD------------- -------------E-DEE------------- -------------EEDEE------------- ---------------EE-------------- ----------------E-------------- ----------------E-------------- ------------------------------- 
------------------------------- ------------------------------- ------------------------------- -------------D----------------- ------------------------------- ------------------------------- ------------------------------- ------------------------------- -------------AAAA-------------- ------------AAAAAA------------- ----------AAAAAAAAAAA---------- ----------AAAAAAAAAAAB--------- ---------AAAAAAAAAAAAA--------- -------AAAAAAAAAAAAAAAA-------- -------AAAAAAAAAAAAAAAA-------- -------AAAAAAAAAAAAAAAA-------- -------AAAAAAAAAAAAAAAA-------- -------AAAAAAAAAAAAAAAA-------- ---------AAAAAAAAAAAAA--------- ----------AAAAAAAAAAA---------- ----------AAAAAAAAAAA---------- -----------DAAAAAA------------- ------------DAAAAD------------- ------------DDDDD-------------- ------------DE-DDE------------- -------------EEDE-------------- -------------E-EE-------------- ------------------------------- ------------------------------- ------------------------------- ------------------------------- 
------------------------------- ------------------------------- ------------------------------- ------------------------------- ------------------------------- ------------------------------- ------------------------------- ------------------------------- -------------DD---------------- ------------DDD---------------- -----------DDDDE--------------- -----------DDDE-D-------------- -----------D--E-D-------------- ---------B-D-DBED-------------- -----------DDDDED-------------- -----------DDDDED-------------- -----------DDDDED-------------- ------------EDDDD-------------- -----------DEDDD-D------------- -----------DBDDD-D------------- -----------DDDDBDD------------- ------------DDDBDD------------- ------------EDDDD-------------- -------------EDDE-------------- -------------E-DEE------------- ---------------DE-------------- ---------------E--------------- ------------------------------- ------------------------------- ------------------------------- ------------------------------- 
