model
size = 32, scale = 0.05, origin = -y
material 
  colors = A:#555 B:#111 C:#999 D:#3D3D3D E:#1C0000 F:#100 G:#FF0400 H:#4E0000 I:#222 J:#D70000 K:#C03 L:#444 M:#0E0 N:#F60
voxels
206-D2-D28-D2-D26-3D2-3D23-4A2-4A22-A8C5(A22-AC3(IB)C)A22-A8CA22-10A26-2B24-J12-J18-G12-G18-J12-J137-C30-C34-C26-C81-2G156-2(DA2-AD26-)DA2-AD24-2ADA2-AD2A21-3D2A2-2A3D20-5A2-5A20-5A2H5A20-12A16-G3-12A3-G12-J3-12A3-J12-GJG-12A-GJG14-J-12A-J16-G-12A-G16-J-12A-J16-GJ12AJG17-G5-2B5-G24-2B24-2GJG2-2B2-GJ2G21-JGJ2-JGJ26-G2-G78-2C28-2C34-C26-C81-2G125-A2-A26-ADA2-ADA24-ADA2-ADA22-2(3ADA2-AD3A20-)3D2A2-2A3D20-5A2-5A20-5A2H5A20-12A15-GJ3-12A3-JG15-7(12A20-)12A25-2B61-J2-J78-2C28-2C34-C26-C81-2H93-A2-A26-2(ADA2-ADA24-)ADA2-ADA22-3ADA2-AD3A19-4ADA2-AD4A17-5D2A2-2A5D16-D6A2-6AD16-D6A2G6AD16-D14AD13-J2-D14AD2-J13-6(16A16-)16A17-14A19-12A23-6B27-G2-G29-2B30-2B15-2C28-2C34-2C24-2C81-2H62-2E29-A2EA28-A2EA25-2ADA2-AD2A22-2ADA2-AD2A19-5ADA2-AD5A15-6ADA2-AD6A14-8A2-8A14-2A6-2G6-4(2A14-)2A10-GJG-DA14-AD-GJG6-J3-2A14-2A3-J10-11(2A14-)2A15-16A16-16A17-14A22-6B26-6B28-2B15-2C13-2B13-2C34-2C24-2C81-2H22-18B21-D2ED2(28-A2EA)22-5A2-2H2-5A15-6A2-2H2-6A2(14-2A6-2H6-2A)14-MA6-2H6-AB14-2A6-2G6-AL14-NA14-AL2(14-2A)14-DA14-AD10-G3-2A14-2A3-G10-12(2A14-)A16-A15-16A16-16A17-14A23-4B28-4B14-2C13-2B13-2C15-2B17-2C24-2C81-2E21-20B16-D2-2D2H2D2-D20-A2-DA2HAD2-A2(20-3ADA2HAD3A)17-3(A2-3ADA2HAD3A2-A14-)A2-5A2H2(5A2-A14-A2-5A2G)5A2-A14-A16-A14-D16-D10-J3-A16-A3-J6-G3-A16-A3-G10-6(A16-A14-)A16-A15-16A16-2A12-2A17-14A10-C-C10-4B10-2(C-)4C10-4B10-4C-3C11-2B11-3C3-2C11-2F11-2C49-2F30-2E20-2B18-2B11-9D2A9D2(12-D18AD)12-D2A-12A-2A2(D12-DA2-12A2-A)D11-4(ADA2-12A2-ADA10-)ADA16-ADA10-3D16-3D10-3A16-3A8-J-3A16-3A-J7-4A16-4A8-4A16-4A9-3A16-3A9-4A16-4A9-3A16-3A11-2A16-2A12-2A16-2A13-A16-A15-A14-A11-C5-A12-A5-C4-3C5-14A5-3C-4C10-4B10-4C-3C11-2B11-3C3-2C11-2B11-2C49-2F30-2E19-2B20-2B9-D20-D10-A20-8(A10-A4-12A4-)A10-A20-A10-D20-D10-A20-A8-GA22-AG6-JA22-AJ7-A22-A9-A20-A9-2A20-2A8-2A20-2A9-C20-C11-3A14-3A13-2A14-2A15-A14-A11-2C4-A12-A4-2C4-3C6-12A6-3C-4C10-4B10-4C-3C10-4B10-3C3-2C11-2B11-2C17-2(2F30-)2E18-2B22-2B7-D22-D8-A22-8(A8-A5-12A5-)A8-A22-A8-D22-D9-A20-A9-A22-A7-GA22-AG7-A22-A9-A20-A9-2A20-2A8-2A20-2A9-C20-C11-C2A14-2AC9-5C2A12-2A5C6-4C-2A12-2A-4C5-3C4-2A10-2A4-3C3-3C6-12A6-3C-4C6-12A6-4C-3C10-4B10-3C3-2C11-2B11-2C17-2(2F30-)2E17-2B24-2B5-D24-D6-A24-2(A6-)7(12A2(6-A)6-)12A2(6-A)24-A7-D22-D9-A20-A8-2(BA22-AB6-)BA22-AB8-A20-A9-2(2A20-2A8-)CA20-AC7-3C3A14-3A3C6-2CA2C2A12-2A2CA2C6-4C-2A12-2A-4C5-3C4-2A10-2A4-3C3-3C6-12A6-3C-CA2C6-12A6-2CAC-3C10-4B10-3C3-C11-4B11-C17-2(2F30-)2E16-2B26-2B4-D24-D6-C24-2(C6-)3(12A2(6-C)6-)12A6-C2(6-A6-12A6-A6-D6-12A6-D)6-A24-A7-D22-D7-2BA20-A2B6-BA22-AB7-E22-E7-B2A20-2AB6-2BA20-A2B2(6-ACA20-ACA)7-CA20-AC7-2C4A14-4A2C6-2CA2C2A12-2A2CA2C6-4C-2A12-2A-4C5-3C4-2A10-2A4-3C3-3C6-A10-A6-3C-CA2C6-2A8-2A6-2CAC-3C8-8A8-3C15-4B29-2(2F30-)2E16-2B26-2B4-D24-D6-C24-C6-B2(6-12A2(6-B))6-12A6-B6-C6-12A6-C2(6-A6-12A6-A6-D6-12A6-D)6-A24-A6-BA22-AB6-2BA20-A2B7-E22-E8-H22-H8-EA20-AE8-BA20-AB7-B2A20-2AB6-ACA20-ACA7-CA20-AC7-2C4A14-4A2C6-2CA2C2A12-2A2CA2C6-4C-2A12-2A-4C5-3C4-2A10-2A4-3C3-3C6-A10-A6-3C-4C6-2A8-2A6-4C11-10A25-4B29-2(2F30-)2E16-2B26-2B4-D24-D6-C24-C6-I2(6-12A2(6-I))6-12A6-I6-C6-12A6-C2(6-A6-12A6-A6-D6-12A6-D)6-A24-A6-BA22-AB7-EA20-AE8-H22-H8-G22-G8-HA20-AH9-E20-E8-B2A20-2AB7-2(CA20-AC8-)2C3A14-3A2C7-5C2A12-2A5C6-4C-2A12-2A-4C5-3C4-2A10-2A4-3C12-A10-A20-2A8-2A21-10A25-4B29-2(2F30-)2E16-2B26-2B4-D24-D6-C24-C6-B2(6-12A2(6-B))6-12A6-B6-C6-D10AD6-C2(6-A6-12A6-A6-D6-12A6-D)6-A24-A6-BA22-AB6-2BA20-A2B7-E22-E8-H22-H8-EA20-AE8-BA20-AB7-BKA20-AKB6-ACA20-ACA7-CA20-AC8-2C3A14-3A2C9-3C2A12-2A3C11-C-2A12-2A-C15-2A10-2A19-A10-A20-2A8-2A21-10A25-4B29-2(2F30-)2E16-2B26-2B4-D24-D6-C24-C6-I2(6-12A2(6-I))6-12A6-I6-C6-12A6-C2(6-A6-12A6-A6-D6-12A6-D)6-A24-A7-D22-D7-2BA20-A2B6-BA22-AB7-E22-E7-B2A20-2AB6-2BA20-A2B7-2(2A20-2A8-)CA20-AC9-C3A14-3AC11-2C2A12-2A2C14-2A12-2A17-2A10-2A19-A10-A20-2A8-2A21-10A25-4B29-2(2F30-)2E16-2B26-2B4-D24-D6-C24-C6-B2(6-12A2(6-B))6-12A6-B6-C6-12A6-C6-A6-12A6-A6-D6-12A6-D6-A6-12A6-A2(6-D)10A2(D6-)A24-A7-D22-D9-A20-A8-2(BA22-AB6-)B2A20-2AB8-A20-A9-2(2A20-2A8-)CA20-AC9-C3A14-3AC11-2C2A12-2A2C14-2A12-2A17-2A10-2A19-A10-A20-2A8-2A21-10A25-4B29-2(2F30-)2E16-2B26-2B4-D24-D6-C24-C6-I2(6-12A2(6-I))6-12A6-I6-C6-12A6-C6-A6-12A6-A6-D6-12A6-D6-A6-12A6-A2(6-D)10A2(D6-)A24-A7-D22-D9-A20-A9-2A20-2A8-A22-A8-2A20-2A9-A20-A9-KA20-AK8-2A20-2A8-CA20-AC9-2C2A14-2A2C12-C2A12-2AC15-2A12-2A17-A12-A19-3A6-3A20-2A8-2A21-10A25-4B29-2(2F30-)2E16-2B26-2B4-D24-D6-C24-C6-B2(6-12A2(6-B))6-12A6-B6-C6-12A6-C6-A6-12A6-A6-D6-12A6-D6-A6-12A6-A2(6-D)10A2(D6-)A24-A7-D22-D9-A20-A3(10-B20-B)2(10-A20-A)9-2A20-2A8-2C20-2C10-C2A14-2AC13-3A12-3A15-2A12-2A17-A12-A19-4A4-4A20-4A4-4A21-10A25-4B29-2(2F30-)2E16-2B26-2B4-D24-D6-C24-C6-I2(6-12A2(6-I))6-12A6-I6-C6-12A6-C6-A6-12A6-A6-D6-12A6-D6-A6-12A6-A2(6-D)10A2(D6-)AD22-DA7-D22-D9-2(B20-B10-)E20-E2(10-B20-B)10-A20-A9-2A20-2A8-2C20-2C10-3A14-3A13-3A12-3A15-2A12-2A17-14A19-12A20-4A4-4A21-10A25-4B29-2(2F30-)2E16-2B26-2B4-D24-D6-C24-C6-B2(6-12A2(6-B))6-12A6-B6-C6-12A6-C6-A3(6-12A2(6-A))6-D10AD2(6-A)2D20-2DA7-D22-D9-B20-B10-E20-E10-H20-H10-E20-E2(10-B20-B)9-2A20-2A8-2C20-2C10-3A14-3A13-2A14-2A15-A14-A17-14A19-12A21-10A23-8A26-4B29-2(2F30-)2E16-2B26-2B4-D24-D6-C24-C6-I2(6-12A2(6-I))6-12A6-I6-C6-12A6-C6-A6-12A2(6-A)6-12A6-A6-DA5-12A5-AD6-D2A4-12A4-2AD6-2DA20-A2D8-B20-B10-E20-E10-H20-H10-G20-G10-H20-H10-E20-E10-BE18-EB10-2B18-2B10-CA18-AC11-3A14-3A13-2A14-2A15-3A10-3A17-14A20-10A23-8A26-4B28-4B29-2(2F30-)2E16-2B26-2B4-D24-D6-C24-2(C6-)3(12A2(6-C)6-)12A6-C6-A6-12A6-A6-DA5-12A5-AD7-2A4-12A4-2A9-DA3-12A3-AD10-DA18-AD11-B18-B12-E18-E12-H18-H12-G18-G12-H18-H12-EH16-HE12-2E16-2E11-3B16-3B11-CA16-AC13-2A14-2A15-2A12-2A17-3A8-3A20-10A23-8A25-6A27-4B28-4B29-2F30-2F49-2B24-2B5-2(D24-D6-)D4(6-12A2(6-D))6-12A6-D7-2A4-12A4-2A9-2A3-12A3-2A11-DA2-12A2-AD12-2A16-2A13-B16-B14-E16-E14-H16-H2(14-G16-G)15-H14-H15-2E14-2E12-4B14-4B12-2A14-2A15-2A12-2A17-4A6-4A19-3A6-3A22-8A25-6A27-B2FB28-B2FB29-2(2F30-)2F50-2B22-2B7-D22-D8-A22-5(A8-A5-12A5-)A9-2A3-12A3-2A11-DA2-12A2-AD13-DA-12A-AD2(14-2A)15-B14-B16-E14-E16-H14-H2(16-G14-G)17-H12-H17-2E12-2E14-4B12-4B14-2A12-2A17-2A10-2A19-3A6-3A21-10A24-6A27-4B28-B2FB29-2F30-2F115-2B20-2B9-D20-D9-CA20-A3(C8-CB4-12A4-B)C8-CA4-12A4-AC9-A4-12A4-A11-DA2-12A2-AD13-2A-12A-2A15-D14AD16-2A12-2A17-B12-B18-E12-E18-H12-H2(18-G12-G)19-H10-H19-2E10-2E16-4B10-4B16-2A10-2A19-3A6-3A21-10A24-6A28-2B29-4B28-B2FB29-2F30-2F116-2B18-2B11-D18-D11-CA18-AC11-2(I3-12A3-I12-)I3-12A3-I11-CA3-12A3-AC11-A3-12A3-A13-2A-12A-2A15-D14AD17-14A18-3A8-3A19-2B8-2B20-2E8-2E20-12H2(20-12G)21-10H21-12E18-16B18-3A6-3A21-10A24-6A28-2(2F30-)2B2(30-2F)149-2B16-2B13-D16-D13-CA16-AC13-2(B2-12A2-B14-)B2-12A2-B13-CA2-12A2-AC13-A2-12A2-A15-D14AD17-14A19-12A20-D2A6-2AD22-B6-B24-8E151-10E20-14B20-10A24-6A60-2(2E30-)2F214-2B14-2B15-D14-D15-CA14-AC15-2(I14-I16-)I14-I15-CA14-AC15-D14-D17-DA10-AD19-DA8-AD20-D10AD20-2D8A2D22-8B214-12B23-6A373-2B12-2B17-A12-A17-4(CA12-AC16-)CA12-AC17-A12-A19-A10-A21-10A23-8A24-8D247-10B404-2B10-2B19-7(A10-A20-)12A21-10A25-4C282-8B406-12B21-10C3(22-C8BC22-C8IC)22-C8BC23-2C4I2C314-4B398-
