model
size = 32 28 12, scale = 0.05, origin = -y
material 
  colors = A:#960 B:#963 C:#444 D:#A57921 E:#B18C43 F:#C3C G:#DDD H:#888 I:#111
voxels
613-2(A31-)A68-C457-2(A31-)A32-2A31-A15-A31-BA30-AB4A25-7A26-5AB25-G4ABA2-C22-GAB3AB2-C22-G6A2-C21-3A-2AC2-C27-2D-C29-2C24-2(BA)27-2A30-BA302-A31-2A11-A5-A12-2A12-3A2-A13-A14-3A13-4A14-2A11-3ABA14-2A2E8-6A14-3A3E6-7A13-4AB2AE3-B5ABA12-6ABAE3-3AB4A13-G6A2E2-2C-AB-C13-2I3AB2A3E-C5-C13-2I6A4E2(C-)C16-GB5A3E2(-C)16-2ABAB2ABA2BC-C19-C2-2A4D3C22-3A4C23-4A2(-C)23-C2A30-C269-2D13-4A12-2DA17-AB10-2DA12-A2H3-HA8-B2D2A11-4A2-HB8-4DA11-AB3AB3D7-3D3A11-6A3D5-2DB5A12-6A3D-4DB5A12-5AB2A6D6A12-9AB3D8A12-2(3AB)A3D4AB3A13-GAB6A5D2A4D11-IB3AB5A9D12-I3AB7ADB3D2C13-G4ABAB2A2(BA)B2C14-4A2B2AB5A-C17-C3AB6ABC20-C2AB3AD3C22-3A2BAC25-C-4C230-A31-A14-3A2B11-3A13-4F2A9-4A17-HA9-4A12-AH2F2-F9-2AB2A11-4AF-F9-5A12-3A2B3A6-2ABA2BA10-6AB3A4-9A11-21A11-4AB8AB4A2BA12-2AB4AB11ABA11-AB19A12-G2(6AB)AB4A11-G2A2B5AB8A2D11-GB3ABAB8A3D12-7AB3ABAB3A-C14-13A2DC16-C12A2C17-C6AB2D3C20-2CAB3A2C25-6C81-2A29-3A28-4A27-5A17-A8-5A18-B7-5A19-BA5-5A3-5A12-3A3-5A4-4F2A10-4A-6A9-FBA9-AB2A-5A6-A2HF-FA9-9A7-5A-F9-8A8-BAB2A2B2A5-8A10-7A2BA4-3ABAB2A11-19AB2A11-AB7AB11A11-9AB7A3BAB10-3AB10AB7A11-4A2B16A10-BAB16A2BD10-AB6AB9A2DC12-9AB4AB2A2C13-9A3B2ABAC15-15AC17-4A2B2A3D3C17-2C6AB3C21-8C81-2A29-3A28-4A27-5A17-A8-5A18-A7-5A19-2A5-5A3-2AB2A12-B2A3-5A4-4F2A10-4A-6A9-F2A9-4A-5A6-B2HF-FA9-9A7-AB3A-F9-3AB4A8-5AB2AB5-8A10-A2B7A4-2AB3ABA11-7ABA2B11A11-4A2B12AB2A11-3AB8AB2AB5AB10-10AB2A2B5ABA11-3A2B3AB13A10-2AB11AB5ABD10-AB16A2DC12-6A2B9A2C13-B12AB2AC15-6AB8AC16-C8A3D3C18-CB3AB2A3C22-7C26-2C201-A31-A13-B5A11-3A12-5F2A9-2ABA17-HA9-AB2A12-AH2F2-F9-5A11-4AF-F9-5A12-2AB4AB6-7A10-B9A4-AB6AB11-AB3A2B14A11-3AB5AB11A12-3AB7AB9A11-2B3AB2AB4ABA2(B2A)12-G20A11-G4AB2ABAB8A2D11-G3AB7AB3A3D12-AB5A3B7A2C14-A2B2(2AB)4A2DC16-C12A2C17-C7A2D3C21-C2A3B2C24-2C-3C31-C262-2D13-4A12-2DA17-AB10-BDA12-A2H3-HE8-3DBA11-AB2A2-HE8-4DA11-6A3E7-B2D3A12-5AEBA5-3D4AB12-2AB4ABD-4D6A12-4AB3A6D3AB2A12-3AB6A3D5AB2A12-8AB2DB8A13-G2(2AB)2A5D2A2DBA11-I3AB6A9D12-I6AB3AB3DBDC14-G9A3B2D2C14-5AB8A2C17-C3AB2ABA2BA2C19-C2AB3ADC-C21-CAB4AC358-A31-2A11-B5-A12-AB12-3A2-A13-B14-2AB13-2ABA14-2A11-2AB2A14-2A2E8-6A14-3A3E6-5ABA13-5AB2A3-A2B5A12-9A3-6ABA13-G6ABE4-C2A2C13-2I6A3EC3-C-C14-2I3A2BA4EC-2C17-G6A3E-3C16-3AB3A3EB-3C19-C-2A3DBC-C22-3A3-C23-4A28-2A366-A31-B31-A32-2A31-B15-A31-2A30-6A6-C18-2BA2B2A6-C19-6A7-C17-G3AB2A25-G2AB3A3-C21-G6A24-3A-2A2(-C)23-C3-2D2C55-4A27-2A30-BA640-A31-B31-A218-
