model
size = 32 26 28, scale = 0.05, origin = -y
material 
  colors = A:#111 B:#800 C:#400 D:#F60 E:#FFF
voxels
78-2(D2AD28-)D2AD29-2A30-2A668-BD2ADB26-B4AB26-BA2-AB26-B4AB26-BD2ADB27-D2AD28-D2AD29-2A572-BD2-DB26-6A2(26-A4-A)25-2A4-2A24-3A2-3A24-2BA2-A2B25-B4AB26-BD2ADB27-D2AD28-D2AD507-BD2ADB26-6A2(26-A4-A)25-2(2A4-2A24-)BA4-AB24-2A4-2A24-B2A2-2AB25-BA2-AB26-B4AB27-D2AD29-2A444-BD2ADB26-6A3(26-2A2-2A)25-3A2-3A23-B3A2-3AB22-2A6-2A22-B2A4-2AB23-2A4-2A24-3A2-3A25-B4AB27-D2AD28-D2AD29-2A382-2A29-4(4A28-)4A26-B6AB22-2B3A2-3A2B20-B2A6-2AB20-3A6-3A21-3A4-3A23-3A2-3A24-ABA2-ABA25-B4AB26-BD2ADB27-D2AD509-2A29-4A23-B5A2-5AB18-BA-3A2-3A-AB18-3A8-3A19-4A4-4A21-3A4-3A2(22-E2A4-2AE)23-3A2-3A25-B4AB27-D2AD477-2A29-4A22-B6A2-6AB16-2A-4A2-4A-2A16-3A2-A4-A2-3A17-2(4A6-4A18-)2EA8-A2E19-E2A6-2AE20-E3A4-3AE21-4A2-4A23-ABD2ADBA475-2A22-2B5-4A5-2B13-2B2(4A2-)4A2B13-2A2(2-4A)2-2A14-3(3A2-)3A14-3A12-3A15-2A12-2A16-3A10-3A17-EA10-AE18-E2A8-2AE19-3A6-3A21-10A23-ABD2ADBA24-AB4-BA411-2A20-2B4A4-2A4-4A2B10-B6A2-4A2-6AB10-B2A3-10A3-2AB11-3(2A4-)2A2(12-3A14-3A)13-3A12-3A15-2A12-2A17-2A10-2A19-3A6-3A21-2A6-2A23-2(2AD)2A23-2AB4-B2A22-2AB4-B2A400-B5A10-5AB10-B3-3A2-4A2-3A3-B10-2A3-12A3-2A10-2A5-2(2A-)2A5-2A10-2A18-2A11-2A16-2A13-2(2A14-)3A12-3A15-3A10-3A18-4A4-4A22-3A2-3A24-ABD2ADBA24-AB-2A-BA23-2AB4-B2A22-2A6-2A23-A6-A337-B5A2-A4-A2-5AB10-BA2(2-6A)2-AB10-A5-10A5-A10-2(2A8-)2A10-2A18-2A11-2(2A16-2A12-)3A14-3A13-4A10-4A16-5A4-5A19-2A-BA2-AB-2A24-D2AD28-D2AD26-A6-A23-2A6-2A23-A6-A338-B7A4-7AB11-BA3-5A2-5A3-AB10-2A7-4A7-2A10-2(2A8-)2A11-A18-A12-A18-A11-2A18-2A10-3A16-3A10-5A12-5A14-6A2-6A18-3A-BA2-AB-3A23-D2-D28-D2AD29-2A377-3A6-3A16-B7A4-7AB11-BA6-2A2-2A6-AB10-2A7-4A7-2A11-A8-2A8-A2(12-2A16-2A)11-2A18-2A9-2A20-2A8-9A6-9A13-2(4AB)4A18-3A2-D2AD2-3A18-2A3-D2AD3-2A23-D2AD28-D2AD374-5A6-5A14-B4A-2A4-2A-4AB12-A6-6A6-A12-A7-4A7-A12-2A16-2A2(12-3A14-3A)10-4A16-4A8-2A2-4A8-4A2-2A7-C10A4-10AC7-2C3-2A-AB4ABA-2A3-2C13-2(2A4-)2A18-2A3-D2AD3-2A23-D2AD28-D2AD29-2A313-2A8-2A17-B6A4-6AB13-B2A3-3A2-3A3-2AB12-A6-6A6-A2(12-2A16-2A)13-2(2A14-)3A12-3A11-7A10-7A7-9A8-9A6-6A2-2A-4A-2A2-6A6-4C5-8A5-4C12-2A-AB4-BA-2A18-2A10-2A23-D2AD28-D2AD29-2A311-B3A8-3AB15-7A4-7A13-2A5-6A5-2A12-2A6-4A6-2A12-2A16-2A13-2(2A14-)3A12-3A15-3A10-3A17-3A8-3A12-4A3-3A6-3A3-4A6-3AC4-10A4-C3A6-2AC6-8A6-C2A6-2C7-BA4-AB7-2C50-2A2(30-2D)30-2A279-B4A6-4AB15-2A2(2-4A)2-2A14-A5-6A5-A14-A16-A2(14-2A)14-3A12-3A15-2A12-2A17-2A10-2A18-3A8-3A18-6A2-6A12-2AC3-14A3-C2A5-C2AC5-2A6-2A5-C2AC4-3C22-3C81-2A2(30-2D)30-2A247-B4A6-4AB15-2A3-8A3-2A14-2A5-4A5-3(2A14-)3A12-3A15-2A12-2A17-2(A12-A18-)3A8-3A18-14A18-2(4A-)4A11-2AC2(6-2A)6-C2A4-2AC22-C2A4-2C24-2C81-2A30-2D30-2A247-B4A6-4AB16-2A2-8A2-3(2A16-2A12-)2A17-2A10-2A18-3A8-3A18-4A6-4A18-5A-2A-5A20-10A45-2A24-2A4-2AC22-C2A4-2C24-2C113-2A30-2D30-2A216-B4A4-4AB17-3A-8A-3A16-3A10-3A17-2A10-2A18-3A8-3A18-4A6-4A19-4A4-4A21-10A23-8A25-6A79-2A24-2A4-AC24-CA4-2C24-2C113-2(2A30-)2A185-3B6-3B20-12A2(20-3A6-3A)20-5A2-5A21-10A23-8A25-2(6A26-)2A2-2A111-AC24-CA3-CAC24-CAC3-C26-C145-2A30-2A187-3(8A24-)8A26-4A59-2A2-2A26-6A143-A26-A3-2AC24-C2A2-2C26-2C770-2(AC26-CA2-)C28-C770-2A26-2A2-2C26-2C770-A28-A-2C28-4C28-2C768-AC28-CA2C28-2C800-C30-C128-
