model
size = 10 32 24, scale = 0.05, origin = -y
material 
  colors = A:#FC0
voxels
132-6A305-4A5-7A2-4A-3A235-3A7-3A6-4A3(4-6A)5-6A4-7A-4A2-4A202-A-3A5-5A5-6A4-6A2(3-4A-2A)3(3-3A2-2A)4-2A2-2A3-2A4-2A-3A4-5A6-2A172-2A8-5A5-6A3-4A-2A3-3A2-2A6(3-3A3-A)3-3A3-2A2-2A4-2A-3A4-6A5-2A162-A9-5A5-6A4-2A2-2A4-2A4(3-A3-3A)3-A4-2A3(3-A3-3A)3-2A2-2A4-2A2-2A5-A-3A4-5A6-2A152-4A6-6A4-2A2-2A4-2A3-A3-3A3-A4-2A3-A6(3-3A2-2A)4-2A2-2A4-2A2(2-3A)3-2A2-3A3-7A3-3A152-5A5-6A2(3-3A3-A)3-3A2-2A2(3-7A)3-6A5(6-4A)6-5A4-6A4-7A2-8A2(2-3A)143-5A5-2A2-2A4-2A3-A4-2A2-2A4-6A5-4A7-2A88-3A5-6A4-6A144-5A4-4A-2A3-3A3-A4-3A-2A4-5A6-2(3A7-)3A2(8-2A)7-3A6(8-2A)8-2(3A7-)3A8-2A8-A108-3A4-7A3-3A2-2A4-2A2-2A4-6A4-11(5A5-)5A2(6-4A)7-3A6-4A6(7-3A)7-2A48-2A7-4A6-2A-2A5-A2-2A4-3A-2A4-6A4-5A6-4A5(5-5A)12(6-4A)6-3A2(8-2A)7-4A6-4A7-3A27-3A6-4A3(5-5A)5-3A-A5-2A-2A5-5A5-3A-A2(5-5A)5-3A-A12(6-4A)6-3A8-2A7-3A7-4A2(7-3A)47-2A8-3A4(6-4A)5(7-3A)7-5(2A8-)2A3(9-A)29-A9-A5(8-2A)2(298-2A8-2A9-A)298-3(2A8-2A308-)2(2(3A7-)2A298-)2(2A8-2A308-)2A8-2A14-
