model
size = 24 32 13, scale = 0.05, origin = -y
material 
  colors = A:#111 B:#B00 C:#C90
voxels
610-B2-B19-2B2-2B17-2B4-2B15-2B6-2B13-2B8-2B58-2A12-2A9-A12-A11-2(A10-A12-)2A8-2A38-A6-A16-2A4-2A3(16-2AC2-C2A2(16-3A2-3A))16-2AC2-C2A16-3A2-3A15-4A2-4A2(14-3AC2-C3A2(14-4A2-4A))2(14-4A2-4A)14-3A4-3A13-B2A6-2AB14-A6-A35-2A-A10-A-2A7-3A10-3A8-3A10-3A9-2(2A10-)3A8-3A11-3C6-3C11-4A6-4A2(10-3A8-3A)7(10-4A6-4A)10-3A8-3A2(10-4A6-4A)4(10-2A)2(10-3A8-3A)9-C3A8-3AC8-C3A8-3AC7-C4A8-4AC5-C5A8-5AC4-5A10-5A7-2(2A10-)5A4-5A11-B2A6-2AB32-2A2-A10-A2-2A5-2A14-2A7-2A12-2A2(8-4A)8-A-A10-A-A8-2C2A8-2A2C3(8-3A10-3A)6(8-2A12-2A)2(8-3A10-3A)8-2(A-A10-)2(A10-)3A10-3A8-A-A10-A-A8-3A10-3A2(8-C14-C)8-A14-A7-2A14-2A6-2A14-2A4-C3A14-3AC-C4A14-4AC5-4A6-4A10-2B2A6-2A2B13-A6-A9-2A18-2A3-A18-A4-3A14-3A5-2(2A14-2A6-)C3A10-3AC7(6-2A14-2A)6-A16-A6-2A14-2A2(6-3A12-3A)6-2A14-2A6-3A12-3A7-3(A14-A8-)C14-C125-4A14-4A-C8A6-8AC5-B-2A6-2A-B13-A6-A9-2A18-2A3-A18-A4-2A16-2A5-2(A16-A6-)C16-C3(6-A16-A)5(6-2A14-2A)2(6-3A12-3A)5(6-A16-A)2(6-C16-C)147-C8A6-8AC5-B-2A6-2A-B13-A6-A9-2A18-2A3-2A16-2A5-3(2A14-2A6-)C16-C2(6-A16-A)6-2A14-2A5(6-3A12-3A)4(6-A16-A)6-A-A12-A-2(A6-A16-)A2(6-C16-C)147-C8A6-8AC5-B-2A6-2A-B13-A6-A10-2A16-2A5-2A14-2A7-3(2A12-2A8-)CA12-AC3(7-3A12-2A)8-2A12-2A8(8-A14-A)8-2A12-2A2(8-A14-A)8-A-A10-A-A8-C14-C125-4A14-4A-C8A6-8AC5-B-2A6-2A-B13-A6-A11-2A2(2-4A)2-2A7-2(2A-)4A2(-2A)9-5A-2A-5A10-5A4-5A10-3A8-3A10-C2A8-2AC9-2(3A10-3A8-2A12-2A8-)3(2A12-2A8-)3A10-3A8-2A12-2A8-A-A10-A-A2(8-3A10-3A)8-A-A10-A-A8-3A10-3A8-A-2A8-2A-A2(8-4A)2(8-C14-C)7-CA14-AC5-C2(2A6-)2AC4-C2A2-A8-A2-2AC3-C3A14-3AC-C4A14-4AC5-5A4-5A10-2B2A6-2A2B13-A6-A12-16A9-2A3-4A3-2A11-12A12-3A2-2A2-3A12-3A6-3A12-2C3A2-3A2C11-4A6-4A2(10-3A8-3A)14(10-2A)10-3A8-3A2(2(10-2A)2(10-3A8-3A))2(10-3A8-3A)8-5A2-4A2-5A6-5A8-5A5-6A8-6A7-3(2A2-)2A10-14A10-2B10A2B14-6A15-12A13-10A15-3(8A16-)8C14-17(12A12-)12A11-14A10-14A9-16A10-2(12A12-)12A13-3B4-3B38-10A15-3(8A16-)8A19-2B19-8A15-21(10A14-)10A15-8A17-6B44-4(2B22-)2B46-3(2B22-)2B21-4B20-B2-B19-2B2-2B8(18-B4-B)18-2B2-2B19-4B21-7(2B22-)2B35-
