model
size = 20 32 13, scale = 0.05, origin = -y
material 
  colors = A:#D00 B:#0FF C:#300 D:#C09 E:#C60 F:#FF3 G:#99F H:#F6C I:#00C J:#FF6 K:#C93 L:#C0C M:#00F N:#0B0 O:#006 P:#06F Q:#6CF R:#693 S:#900 T:#0C9 U:#966 V:#699 W:#6CC X:#36C Y:#60C Z:#F03 Aa:#033 Ab:#339 Ac:#C06 Ad:#FF9 Ae:#0F6
voxels
565-Aa8-Aa67-2J12-2A5-J12-H7-2(J10-H8-)2J8-2H88-Ad10-Ad70-L6-H111-2(F8-V10-)2(2F6-2S10-)2F6-SK10-2F6-2K8-Ab-2F6-2K-Ab8-2(2F6-2K10-)2F6-KA10-2F6-KA11-F6-A27-2J-J10-A-2A3-3J10-3H4-3J10-3H5-2J10-2H6-3J8-3H7-3J6-2HP7-4J6-H3A6-J2L8-A2H6-3L8-3H6-4L6-A3H5-Ac3LA6-4HAc5-3(4L6-4H6-)3LS6-3HR6-3LS6-2HRG6-3L8-2RG6-2LSA6-R2QG6-2F2A6-3QG2(6-2F10-2Q)6-3F8-2SA6-3F8-3S5-2FNA8-3KS4-3NA8-4K3-P4N8-5K-P5N8-6K5N10-5K3-NF10-AK6-4FA4-5A8-2F6-2A26-J2-J10-2(A2-)2J14-2H3-2A12-2H4-2J2A8-A3H4-J-J10-A-H4-3JA8-2A2P4-2JA10-3A4-2LA10-A2H4-2LA10-3H4-LA3(12-2H4-2A)2(12-2R4-2A)12-2R4-3A10-ARG4-3A10-A2G4-A-A10-A-G6-A10-Q6-3A10-3Q4-A-A10-A-Q4-3A10-3A3-ZP14-PZ3-P14-P4-A14-A3-2A14-2A2-2N14-2K-2(3N14-3K)3-4F6-3AK8-2F6-2A11-F6-A47-EA2(14-HD2-EJ)14-AD2-E3A10-3AD2-E2(L14-HD2-B)2(A14-HD2-B)A14-H2(D2-IA14-R)D2-A16-D2-2A14-RG2-3A12-AQG2-O2A12-Q2G2-OA14-2G2-O2A12-2QG3-A14-Q2(4-A14-A)4-P14-P102-2NA14-3A2N-2A2F6-4A-2A5-2F6-2A11-F6-A47-4(E16-D2-)E16-D-UB16-DU-B16-D2-2B14-MD2-BI2(14-MD2-IA)14-MD2-2I14-2G2-AIA12-A2G2-AOA12-ATG2-O16-G-YO16-GY-O16-G2(2-O16-T)2-P16-P2-C16-P121-2A-3FA6-4A-2A5-2F6-2A11-F6-A27-E16-D3(2-2E14-2D)3(2-E16-D)2-2B14-2(MD2-2BA12-A)2(MD2-IBA12-A)2G2-2IA12-3G2-I4(16-G2-O)-A12-D-D2-O16-D2-A16-D2-P16-D2-C16-P121-2A-3FA6-4A-2AAe4-2F6-2A4-Ae2(6-A)6-2E16-2A-2E14-DA3-3(2E12-2D4-)2E12-2D3-3E12-2M3-2EA12-AM3-3B12-AM4-2B12-AM3-UB14-MU3-3(B14-G4-)2(O14-G4-)2(O14-T4-)AI12-AD4-A2(14-D4-C)-A10-A-D4-C14-D103-2A14-2B4-3FA6-4A8-2F6-2A11-A6-A7-2E2-3J4-3H2-2A3-2E-2J6-DA-DA5-2EJEA4-A4D6-2EAEA4-2A3D6-2EA8-A2D6-2EA8-2AP5-3E10-2AM4-2E12-AM4-3B10-2AM4-2B12-AM3(4-2B12-2G)4-3B10-3G4-2B12-2G4-O-B10-A-T4-2OA10-2AT4-OIA10-3A4-I-A10-A-A4-A2I10-2AD4-C-IA8-2A-D4-3CA8-A3D2(4-C14-D)3-CA14-AP2-CA2(6-2A)2-CA2-A8-A2-2B2-2C14-2B2-2A14-2B4-3F2A4-3AMB8-2F6-2A11-A6-A8-3E2A6-2D3A5-2E10-DA7-3E2A2-A4D8-3E2-2A2-3D8-3E6-A2D8-2EO2A2-3A2P7-2E2O6-4A6-2EA8-T2A6-2EB8-2GA6-EB5(10-2G6-2B)10-2M6-2B10-2A6-O2B8-3A6-2I10-2A2(6-2IA8-3A)6-2C10-2D3(6-3C8-3D)6-3A8-A2D4-2CB2A2-4A2-5A2-3CBA8-A2B2A2-4CA8-4BA4-2(2C2-)KA2-2B6-3F6C3A2B8-2F5C3A12-4C2A11-9AD2A9-AE6ADA11-E6AD12-E2B2I2AD12-E3B2ITA12-4B2I2P10-2O3B2I3ATA8-2B8A2G3(8-2B7A3G)8-2B8A2G8-2B7A2MG8-2B7A3M8-2B8A2M8-2B8AMA2(8-2B10A)8-IB10A8-2I10A8-2C8A2D7-W2C7A3DW7-2C7A3D8-2C7A3D7-2BC8A2DA6-3B8A2BA5-3B8A4BA6-3C6A3B8-3C5A2M2B8-2F5CA4M49-4E5DA11-3EI4D12-3EBI3D12-2E2B2I2D12-E3B2I2T32-3B3I2G11-4B4I2G10-5B3I2G10-6B2I2G10-6BI2CG6(10-6B4C)10-5BM4C10-4B2M4C10-4B2D4C10-C4B5C3(10-9CD)10-9CB10-2I2A5CB10-A8CB10-9CB10-8C2B11-6CAM332-F6-F173-X4-X167-
