model
size = 21 30 3, scale = 0.05, origin = -y
material 
  colors = A:#111 B:#EEE C:#E00
voxels
---AAAAAAAAAAAAAAA--- ---ABBBBBBBBBBBBBA--- ---ABAAAAAAAAAAABA--- ---ABAACCAACACAABA--- --AABACAAACACACABA--- -AABAACAAACACACABA--- -ABAAAACCACAAACAABA-- AABAAAAAAAAAAAAAAABA- ABAAABBBAAAAAAAAAABA- ABAABAAABBBAAAAAAAABA ABABAAABAAABBAAAAAABA ABAAAABAAABAABAAAAABA ABAAABAAABAAABAAAAABA ABAABAAABAAABABAAAABA ABAAAAABAABBBBAAAAABA AABAAAAAABAAAAAAAABAA -AABBAAAABBAAAAABBAA- --AAABBAAAABBBBBAAA-- ----AAABBBAAAABA----- ------AAAABAAABA----- ---------ABAAABA----- ---------ABAAABA----- ---------ABAAABA----- ---------ABAAABA----- ---------ABAAABA----- ---------ABAAABA----- ---------ABAAABA----- ---------ABAAABA----- ---------AABBBAA----- ----------AAAAA------ 
---AAA---------AAA--- ---AAA---------AAA--- ---AAA---------AAA--- ---AAA---------AAA--- --AAAA---------AAA--- -AAAAA---------AAA--- -AAAAA---------AAAA-- AAAAAA---------AAAAA- AAAAAA---------AAAAA- AAAAAA---------AAAAAA AAAAAA---------AAAAAA AAAAAA---------AAAAAA AAAAAA---------AAAAAA AAAAAA---------AAAAAA AAAAAA---------AAAAAA AAAAAA---------AAAAAA -AAAAA---------AAAAA- --AAAAAAAAAAAAAAAAA-- ----AAAAAAAAAAAA----- ------AAAAAAAAAA----- ---------AAAAAAA----- ---------AAAAAAA----- ---------AAAAAAA----- ---------AAAAAAA----- ---------AAAAAAA----- ---------AAAAAAA----- ---------AAAAAAA----- ---------AAAAAAA----- ---------AAAAAAA----- ----------AAAAA------ 
---AAAAAAAAAAAAAAA--- ---ABBBBBBBBBBBBBA--- ---ABAAAAAAAAAAABA--- ---ABACCCAACACAABA--- --AABAACAACCCCCABA--- -AABAAACAAACACAABA--- -ABAAAACAACCCCCABAA-- AABAAAACCAACACAAABAA- ABAAABBBAAAAAAAAAABA- ABAABAAABBBAAAAAAABAA ABABAAABAAABBAAAAAABA ABAAAABAAABAABAAAAABA ABAAABAAABAAABBAAAABA ABAAAAAABAAABABAAAABA ABAAAAABAABBBBAAAAABA AABAAAAAABAAAAAAAABAA -AABBAAAABBAAAAABBAA- --AAABBAAAABBBBBAAA-- ----AAABBBAAAABA----- ------AAAABAAABA----- ---------ABAAABA----- ---------ABAAABA----- ---------ABAAABA----- ---------ABAAABA----- ---------ABAAABA----- ---------ABAAABA----- ---------ABAAABA----- ---------ABAAABA----- ---------AABBBAA----- ----------AAAAA------ 
