model
size = 30 32 7, scale = 0.05, origin = -y
material 
  colors = A:#B00 B:#001A61
voxels
814-2A18-2A7-2A20-2A907-2A18-2A7-2A20-2A103-A2-4A2-A11-3A6-3(A2-)A6-3A2-A-2A4-A2(2-2A)2-A4-2A2(-A)3-2(A4-A2-)A4-A3-2A4-A3-A2(2-2A)2-A3-A2(4-2A)-A4-A2-A4-A-2A4-2A5-A-A4-4A4-A-A5-2A5-2(A-)10A2(-A)5-2A5-18A5-2A6-A4-A-2A-A4-A6-A-A5-A4-A-2A-A4-A5-A3-2A3-A4-6A4-A3-2A5-A3-A4-6A4-A3-A6-2A2-A5-4A5-A2-2A7-2(A2-)10A2(2-A)8-2A-A2-A-6A-A2-A-2A9-A-A2-10A2-A-A10-4A2(2-A-A)2-4A11-6A-A2-A-6A12-8A2-8A13-7A2-7A14-A2-10A2-A14-2A2-8A2-2A15-2A-3A2-3A-2A17-12A19-10A16-18A10-2A4-3(A2-)A4-2A7-2A5-3A4-3A5-2A14-A6-A71-10BA2B4A2BA11B3A6B3(A2B)A6B3A2BAB2A4BA2(2B2A)2BA4B2A2(BA)3B2(A4BA2B)A4BA3B2A4BA3BA2(2B2A)2BA3BA2(4B2A)BA4BA2BA4BAB2A4B2A5BABA4B4A4BABA5B2A5B2(AB)10A2(BA)5B2A5B18A5B2A6BA4BAB2ABA4BA6BABA5BA4BAB2ABA4BA5BA3B2A3BA4B6A4BA3B2A5BA3BA4B6A4BA3BA6B2A2BA5B4A5BA2B2A7B2(A2B)10A2(2BA)8B2ABA2BAB6ABA2BAB2A9BABA2B10A2BABA10B4A2(2BABA)2B4A11B6ABA2BAB6A12B8A2B8A13B7A2B7A14BA2B10A2BA14B2A2B8A2B2A15B2AB3A2B3AB2A17B3AB4AB3A19B10A16B18A10B2A4B3(A2B)A4B2A7B2A5B3A4B3A5B2A14BA6BA71B10-A2-4A2-A11-3A6-3(A2-)A6-3A2-A-2A4-A2(2-2A)2-A4-2A2(-A)3-2(A4-A2-)A4-A3-2A4-A3-A2(2-2A)2-A3-A2(4-2A)-A4-A2-A4-A-2A4-2A5-A-A4-4A4-A-A5-2A5-2(A-)10A2(-A)5-2A5-18A5-2A6-A4-A-2A-A4-A6-A-A5-A4-A-2A-A4-A5-A3-2A3-A4-6A4-A3-2A5-A3-A4-6A4-A3-A6-2A2-A5-4A5-A2-2A7-2(A2-)10A2(2-A)8-2A-A2-A-6A-A2-A-2A9-A-A2-10A2-A-A10-4A2(2-A-A)2-4A11-6A-A2-A-6A12-8A2-8A13-7A2-7A14-A2-10A2-A14-2A2-8A2-2A15-2A-3A2-3A-2A17-3A-4A-3A19-10A16-18A10-2A4-3(A2-)A4-2A7-2A5-3A4-3A5-2A14-A6-A885-2A18-2A7-2A20-2A907-2A18-2A7-2A20-2A93-
