model
size = 11 7 9, scale = 0.05, origin = -y
material 
  colors = A:#444 B:#777 C:#111 D:#FF3
voxels
C---------- C---------- ----------- ----------- ----------- ----------- ----------- 
----------C C---------C ----------- ----------- ----------- ----------- ----------- 
----------- C---------C ----------- ----------- ----------- ----------- ----------- 
----------- C---------C ----------- ----------- ----------- ----------- ----------- 
----------- C---------C ----------- ----------- ----------- ----------- ----------- 
----------- C---------C ----------- ----------- ----------- ----------- ----------- 
----------- C---------C ----------- ----------- ----------- ----------- ----------- 
----------- C---------C ----------- ----------- ----------- ----------- ----------- 
----------- AAAAA-AAAAA ABBBB-BBBBA ABBBA-ABBBA ABBBA-ABBBA AAAAA-AAAAA DDDDD-DDDDD 
