model
size = 16 25 3, scale = 0.05, origin = -y
material 
  colors = A:#111 B:#E00 C:#B00
voxels
------AAAA------ ---------------- ---------------- ---------------- ---------------- ---------------- ---------------- ---------------- ---------------- ---------------- ---------------- ---------------- ---------------- ---------------- ---------------- ---------------- ---------------- ---------------- ---------------- ---------------- ---------------- ---------------- ---------------- ---------------- ---------------- 
------A--A------ -------CC------- ---------------- ---------------- ---------------- ---------------- ---------------- ---------------- ---------------- ---------------- ---------------- ---------------- ---------------- ---------------- ---------------- -C-----BB-----C- -C-----BB-----C- A-----A--------- ---------------- ---------------- ---------------- ---------------- ---------------- -------CC------- ---------------- 
------ABBA------ ------ABBA------ ------ABBA------ ------ABBA------ ------ABBA------ ------ABBA------ ------ABBA------ ------ABBA------ ------ABBA------ ------ABBA------ ------ABBA------ ------ABBA------ ------ABBA------ ------ABBA------ AAAAAAABBAAAAAAA ABBBBBBBBBBBBBBA ABBBBBBBBBBBBBBA AAAAAAABBAAAAAAA ------ABBA------ ------ABBA------ ------ABBA------ ------ABBA------ ------ABBA------ ------ABBA------ ------AAAA------ 
