model
size = 16 8 26, scale = 0.05, origin = -y
material 
  colors = A:#6C2B00 B:#FFF C:#CC9 D:#222 E:#E00
voxels
---EEE---------- ---------------- ---------------- ---------------- ---------------- ---------------- ---------------- ---------------- 
---EEE---------- ---------------- ---------------- ---------------- ---------------- ---------------- ---------------- ---------------- 
---------------- ---EEE---------- ---------------- ---------------- ---------------- ---------------- ---------------- ---------------- 
---AAAAAAAAAAAAA --AA------------ -AAEEE---------- -A-------------- -A-------------- -AA------------- --AA------------ ---AAAAAAAAAAAAA 
--AACCCCCCCCCCAA -AABBBBBBBBBBBB- -AABBBBBBBBBBBB- AABEEEBBBBBBBBB- AABBBBBBBBBBBBB- -AABBBBBBBBBBBB- -AABBBBBBBBBBBB- --AACCCCCCCCCCAA 
--ACCAAAAAAAACCA -AAAAAAAAAAAAAB- AAAAAAAAAAAAAAB- AAAAAAAAAAAAAAB- AAAAAAAAAAAAAAB- AAAAAAAAAAAAAAB- -AAAAAAAAAAAAAB- --ACCAAAAAAAACCA 
--ACAAAAAAAAAACA -AAAAAAAAAAAAAB- AAAAAAAAAAAAAAB- AAAAAAAAAAAAAAB- AAAAAAAAAAAAAAB- AAAAAAAAAAAAAAB- -AAAAAAAAAAAAAB- --ACAAAAAAAAAACA 
--ACAAAAAAAAAACA -AAAAAAAAAAAAAB- AAAAAAAAAAAAAAB- AAAAAAAAAAAAAAB- AAAAAAAAAAAAAAB- AAAAAAAAAAAAAAB- -AAAAAAAAAAAAAB- --ACAAAAAAAAAACA 
--ACAAAAAAAAAACA -AAAAAAAAAAAAAB- AAAAAAAAAAAAAAB- AAAAAAAAAAAAAAB- AAAAAAAAAAAAAAB- AAAAAAAAAAAAAAB- -AAAAAAAAAAAAAB- --ACADAADAADAACA 
--ACAAAAAAAAAACA -AAAAAAAAAAAAAB- AAAAAAAAAAAAAAB- AAAAAAAAAAAAAAB- AAAAAAAAAAAAAAB- AAAAAAAAAAAAAAB- -AAAAAAAAAAAAAB- --ACADAADADDAACA 
--ACAAAAAAAAAACA -AAAAAAAAAAAAAB- AAAAAAAAAAAAAAB- AAAAAAAAAAAAAAB- AAAAAAAAAAAAAAB- AAAAAAAAAAAAAAB- -AAAAAAAAAAAAAB- --ACADAADDADAACA 
--ACAAAAAAAAAACA -AAAAAAAAAAAAAB- AAAAAAAAAAAAAAB- AAAAAAAAAAAAAAB- AAAAAAAAAAAAAAB- AAAAAAAAAAAAAAB- -AAAAAAAAAAAAAB- --ACADAADAADAACA 
--ACAAAAAAAAAACA -AAAAAAAAAAAAAB- AAAAAAAAAAAAAAB- AAAAAAAAAAAAAAB- AAAAAAAAAAAAAAB- AAAAAAAAAAAAAAB- -AAAAAAAAAAAAAB- --ACAAAAAAAAAACA 
--ACAAAAAAAAAACA -AAAAAAAAAAAAAB- AAAAAAAAAAAAAAB- AAAAAAAAAAAAAAB- AAAAAAAAAAAAAAB- AAAAAAAAAAAAAAB- -AAAAAAAAAAAAAB- --ACADAAADAAAACA 
--ACAAAAAAAAAACA -AAAAAAAAAAAAAB- AAAAAAAAAAAAAAB- AAAAAAAAAAAAAAB- AAAAAAAAAAAAAAB- AAAAAAAAAAAAAAB- -AAAAAAAAAAAAAB- --ACADDAADDAAACA 
--ACAAAAAAAAAACA -AAAAAAAAAAAAAB- AAAAAAAAAAAAAAB- AAAAAAAAAAAAAAB- AAAAAAAAAAAAAAB- AAAAAAAAAAAAAAB- -AAAAAAAAAAAAAB- --ACADAAADAAAACA 
--ACAAAAAAAAAACA -AAAAAAAAAAAAAB- AAAAAAAAAAAAAAB- AAAAAAAAAAAAAAB- AAAAAAAAAAAAAAB- AAAAAAAAAAAAAAB- -AAAAAAAAAAAAAB- --ACADDDADDDAACA 
--ACAAAAAAAAAACA -AAAAAAAAAAAAAB- AAAAAAAAAAAAAAB- AAAAAAAAAAAAAAB- AAAAAAAAAAAAAAB- AAAAAAA-AAAAAAB- -AAAAAAAAAAAAAB- --ACAAAAAAAAAACA 
--ACAAAAAAAAAACA -AAAAAAAAAAAAAB- AAAAAAAAAAAAAAB- AAAAAAAAAAAAAAB- AAAAAAAAAAAAAAB- AAAAAAAAAAAAAAB- -AAAAAAAAAAAAAB- --ACADAAADDDAACA 
--ACAAAAAAAAAACA -AAAAAAAAAAAAAB- AAAAAAAAAAAAAAB- AAAAAAAAAAAAAAB- AAAAAAAAAAAAAAB- AAAAAAAAAAAAAAB- -AAAAAAAAAAAAAB- --ACADDDADADAACA 
--ACAAAAAAAAAACA -AAAAAAAAAAAAAB- AAAAAAAAAAAAAAB- AAAAAAAAAAAAAAB- AAAAAAAAAAAAAAB- AAAAAAAAAAAAAAB- -AAAAAAAAAAAAAB- --ACADADADADAACA 
--ACAAAAAAAAAACA -AAAAAAAAAAAAAB- AAAAAAAAAAAAAAB- AAAAAAAAAAAAAAB- AAAAAAAAAAAAAAB- AAAAAAAAAAAAAAB- -AAAAAAAAAAAAAB- --ACADDDADADAACA 
--ACAAAAAAAAAACA -AAAAAAAAAAAAAB- AAAAAAAAAAAAAAB- AAAAAAAAAAAAAAB- AAAAAAAAAAAAAAB- AAAAAAAAAAAA-AB- -AAAAAAAAAAAAAB- --ACAAAAAAAAAACA 
--ACCAAAAAAAACCA -AAAAAAAAAAAAAB- AAAAAAAAAAAAAAB- AAAAAAAAAAAAAAB- AAAAAAAAAAAAAAB- AAAAAAAAAAAAAAB- -AAAAAAAAAAAAAB- --ACCAAAAAAAACCA 
--AACCCCCCCCCCAA -AABBBBBBBBBBBB- -AABBBBBBBBBBBB- AABEEEBBBBBBBBB- AABBBBBBBBBBBBB- -AABBBBBBBBBBBB- -AABBBBBBBBBBBB- --AACCCCCCCCCCAA 
---AAAAAAAAAAAAA --AEEE---------- -AAEEE---------- -A-------------- -A-------------- -AA------------- --AA------------ ---AAAAAAAAAAAAA 
