model
size = 3 31 25, scale = 0.05, origin = -y
material 
  colors = A:#F80 B:#EEE C:#555 D:#888
voxels
--- --- --- --- --- --- --- --- --- -A- -A- -A- -A- -A- -A- -A- --- --- --- --- --- --- --- --- --- --- --- --- --- --- --- 
--- --- --- --- --- --- --- -A- AAA AAA AAA AAA AAA AAA AAA AAA AAA -A- --- --- --- --- --- --- --- --- --- --- --- --- --- 
--- --- --- --- --- -A- AAA AAA AAA -A- -A- -A- -A- -A- -A- -A- AAA AAA AAA -A- --- --- --- --- --- --- --- --- --- --- --- 
--- --- --- --- -A- AAA AAA -A- -A- -B- -B- -B- -B- -B- -B- -B- -A- -A- AAA AAA -A- --- --- --- --- --- --- --- --- --- --- 
--- --- --- -A- AAA AAA -A- -B- -B- -B- -B- -B- -B- -B- -B- -B- -B- -B- -A- AAA AAA -A- --- --- --- --- --- --- --- --- --- 
--- --- -A- AAA AAA -A- -B- -B- -B- -B- -B- -B- -B- -B- -B- -B- -B- -B- -B- -A- AAA AAA -A- --- --- --- --- --- --- --- --- 
--- --- AAA AAA -A- -B- -B- -B- -B- -B- -B- -B- -B- -B- -B- -B- -B- -B- -B- -B- -A- AAA AAA --- --- --- --- --- --- --- --- 
--- -A- AAA -A- -B- -B- -B- -B- -B- -B- -B- -B- -B- -B- -B- -B- -B- -B- -B- -B- -B- -A- AAA -A- --- --- --- --- --- --- --- 
--- AAA AAA -A- -B- -B- -B- -C- -C- -C- -C- -C- -C- -C- -C- -C- -C- -C- -B- -B- -B- -A- AAA AAA --- --- --- --- --- --- --- 
-A- AAA -A- -B- -B- -B- -C- -C- -C- -C- -C- -C- -C- -C- -C- -C- -C- -C- -C- -B- -B- -B- -A- AAA -A- --- --- --- --- --- --- 
-A- AAA -A- -C- -C- -C- -C- -C- -B- -B- -B- -B- -C- -C- -B- -B- -B- -C- -C- -C- -C- -C- -A- AAA -A- --- --- --- --- --- --- 
-A- AAA -A- -C- -C- -C- -C- -C- -B- -B- -B- -B- -C- -C- -B- -B- -B- -C- -C- -C- -C- -C- -A- AAA -A- --- --- -D- -D- --- --- 
-A- AAA -A- -B- -B- -B- -C- -C- -B- -B- -B- -B- -C- -C- -B- -B- -B- -C- -C- -B- -B- -B- -D- DAD DDD -D- -D- DDD DDD -D- -D- 
-A- AAA -A- -C- -C- -C- -C- -C- -B- -B- -B- -B- -C- -C- -B- -B- -B- -C- -C- -C- -C- -C- -A- AAA -A- --- --- -D- -D- --- --- 
-A- AAA -A- -C- -C- -C- -C- -C- -B- -B- -B- -B- -C- -C- -B- -B- -B- -C- -C- -C- -C- -C- -A- AAA -A- --- --- --- --- --- --- 
-A- AAA -A- -B- -B- -B- -C- -C- -B- -B- -B- -C- -C- -C- -C- -C- -C- -C- -C- -B- -B- -B- -A- AAA -A- --- --- --- --- --- --- 
--- AAA AAA -A- -B- -B- -B- -C- -C- -C- -C- -C- -C- -B- -C- -C- -C- -C- -B- -B- -B- -A- AAA AAA --- --- --- --- --- --- --- 
--- -A- AAA -A- -B- -B- -B- -B- -C- -C- -C- -C- -B- -B- -B- -B- -B- -B- -B- -B- -B- -A- AAA -A- --- --- --- --- --- --- --- 
--- --- AAA AAA -A- -B- -B- -B- -B- -B- -B- -B- -B- -B- -B- -B- -B- -B- -B- -B- -A- AAA AAA --- --- --- --- --- --- --- --- 
--- --- -A- AAA AAA -A- -B- -B- -B- -B- -B- -B- -B- -B- -B- -B- -B- -B- -B- -A- AAA AAA -A- --- --- --- --- --- --- --- --- 
--- --- --- -A- AAA AAA -A- -B- -B- -B- -B- -B- -B- -B- -B- -B- -B- -B- -A- AAA AAA -A- --- --- --- --- --- --- --- --- --- 
--- --- --- --- -A- AAA AAA -A- -A- -B- -B- -B- -B- -B- -B- -B- -A- -A- AAA AAA -A- --- --- --- --- --- --- --- --- --- --- 
--- --- --- --- --- -A- -A- AAA AAA -A- -A- -A- -A- -A- -A- -A- AAA AAA AAA -A- --- --- --- --- --- --- --- --- --- --- --- 
--- --- --- --- --- --- --- -A- AAA AAA AAA AAA AAA AAA AAA AAA AAA -A- --- --- --- --- --- --- --- --- --- --- --- --- --- 
--- --- --- --- --- --- --- --- --- -A- -A- -A- -A- -A- -A- -A- --- --- --- --- --- --- --- --- --- --- --- --- --- --- --- 
