model
size = 11 32 19, scale = 0.05, origin = -y
material 
  colors = A:#232323 B:#1E1E1E C:#090909 D:#1E0E04 E:#1C0B00 F:#E00
voxels
255-7A3-AC5BC4(A2-A7B)A2-AC5BCA3-7A257-7A3-B7AB-66A-B6A2B3-7A245-AC5BCA-11AC9ACB3(9A2B)9ABC9AC11A-AC5BC4(A244-A7BA-11AB5(9A2B)9AB11A-A7B)A5-3C9-E109-E9-3C97-B6-2(A3B)A-11AB5(9A2B)9AB11A-A7BA4-C3FC7-3D9-DE2(9-D10-D9-2E10-2E)8-DBD7-CBDBC7-BAB9-5(A10-)A9-ABA8-CBC5-A2B3A2BA-11AB5(9A2B)9AB11A-A7BA4-2(CF)C6-E3DE7-2(2(2DE8-)2(E2D8-))2DE7-EBDBE6-C3DC7-7(3A8-)BAB7-5B4-AB5ABA-11AB5(9A2B)9AB11A-A7BA4-C3FC7-3D9-D2(10-2E8-2E2(10-D))9-DBD7-CBDBC7-BAB9-5(A10-)A9-ABA8-CBC5-A2B3A2BA-11AB5(9A2B)9AB11A-A7BA5-3C9-E109-E9-3C97-B6-2(A3B)4(A-11AB5(9A2B)9AB11A-A7BA244-A7B)A-11AB5(9A2B)9AB11A-A7BA244-AC5BCA-11AC9ACB3(9A2B)9ABC9AC11A-AC5BCA245-7A3-B7AB-66A-B7AB3-7A257-7A3-AC5BC4(A2-A7B)A2-AC5BCA3-7A13-
