model
size = 24 18 19, scale = 0.05, origin = -y
material 
  colors = A:#200 B:#111 C:#EEE
voxels
------AAAAAAA----------- ------------------------ ------------------------ ------------------------ ------------------------ ------------------------ ------------------------ ------------------------ ------------------------ ------------------------ ------------------------ ------------------------ ------------------------ ------------------------ ------------------------ ------------------------ ------------------------ ------------------------ 
----AAAAAAAAAAA--------- -------AAAAA------------ ------------------------ ------------------------ ------------------------ ------------------------ ------------------------ ------------------------ ------------------------ ------------------------ ------------------------ ------------------------ ------------------------ ------------------------ ------------------------ ------------------------ ------------------------ ------A----------------- 
---AAAAAAAAAAAAA-------- -----AAAAAAAAA---------- ------------------------ ------------------------ -------AAAAA------------ ------------------------ ------------------------ ------------------------ ------------------------ ------------------------ ------------------------ ------------------------ ------------------------ ------------------------ ------------------------ ------------------------ ------A----------------- ------A----------------- 
--AAAAAAAAAAAAAA-------- ---AAAAAAAAAAAAA-------- -------AAAAA------------ ------AAAAA------------- -----AAAAAAAAA---------- ------------------------ ------------------------ ------------------------ ------------------------ ------------------------ ------------------------ ------------------------ ------------------------ ------------------------ ------------------------ ------A----------------- ------A----------------- ------------------------ 
-AAAAAAAAAAAAAAAAA------ ---AAAAAAAAAAAAA-------- -----AAAAAAAAA---------- ----AAAAAAAAA----------- ----AAAAAAAAAAA--------- -------AAAAA------------ -------AAAAA------------ ------AAAAA------------- ------------------------ ------------------------ ------------------------ ------------------------ ------------------------ ------------------------ ------------------------ ------A----------------- ------A----------------- ------------------------ 
-AAAAAAAAAAAAAAAAA------ --AAAAAAAAAAAAAA-------- ----AAAAAAAAAAA--------- ---AAAAAAAAAAA---------- ---AAAAAAAAAAAAA-------- -----AAAAAAAAA---------- ------AAAAAAA----------- -----AAAAAAA------------ -------AAAAA------------ ------AAAAA------------- ------------------------ ------------------------ ------------------------ -------AAAAA------------ ------AAAAA------------- -----AAAAA-------------- ------A----------------- ------------------------ 
AAAAAAAAAAAAAAAAA------- --AAAAAAAAAAAAAA-------- ----AAAAAAAAAAA--------- ---AAAAAAAAAAA---------- ---AAAAAAAAAAAAA-------- ----AAAAAAAAAAA--------- -----AAAAAAAAA---------- ----AAAAAAAAA----------- ------AAAAAAA----------- -----AAAAAAA------------ --------AAA------------- ------------------------ ------AAA--------------- ------AAAAAAA----------- -----AAAAAAA------------ ----AAAAAAA------------- -----AAA---------------- ------------B----------- 
AAAAAAAAAAAAAAAAA------- -AAAAAAAAAAAAAAA-------- ---AAAAAAAAAAAA--------- --AAAAAAAAAAAAA--------- --AAAAAAAAAAAAAAA------- ----AAAAAAAAAAA-AAABB--- ----AAAAAAAAAAA-----C--- ---AAAAAAAAAAA---------- -----AAAAAAAAA---------- ----AAAAAAAAAAAA-----CB- -------AAAAA-AAAA--AAB-- -------AAA-------------- -----AAAAA-------------- -----AAAAAAAAA---------- ----AAAAAAAAA----------- ---AAAAAAAAA------------ ----AAAAA---B----------- ----AAAA----B----------- 
AAAAAAAAAAAAAAAAAA------ -AAAAAAAAAAAAAAA-------- ---AAAAAAAAAAAA--------- --AAAAAAAAAAAAA--------- --AAAAAAAAAAAAAAA----AB- ---AAAAAAAAAAAAAAAAAAAC- ----AAAAAAAAAAA--------- ---AAAAAAAAAAA---------- -----AAAAAAAAA-------C-- ----AAAAAAAAABBB-----AAB ------AAAAAAAAAAA--AAAA- ------AAAAAAAAAAAAAAAA-- ----AAAAAAAAAAAAAAAAAB-- -----AAAAAAAAAAAAAAAAA-- ----AAAAAAAAA----------- ---AAAAAAAAAC----------- ---AAAAAAA--B----------- ---AAAAAA--------------- 
AAAAAAAAAAAAAAAAAA------ -AAAAAAAAAAAAAAA-------- ---AAAAAAAAAAAA--------- --AAAAAAAAAAAAA--------- --AAAAAAAAAAAAAAA----AB- ---AAAAAAAAAAAAAAAAAAA-- ----AAAAA-AAAAA--------- ---AAAAA-AAAAA---------- -----AAAA-AAAA---------- ----AAAA-AAAABBB-----BAB ------AAA-AAAAAAA--AAAA- ------AA-AAAAAAAAAAAAA-- ----AAA-AAAAAAAAAAAA-B-- -----AAAA-AAAAAAAAAAAB-- ----AAAA-AAAA----------- ---AAAA-AAAA------------ ---AAAAAAA-------------- ---AAAAAAA-------------- 
AAAAAAAAAAAAAAAAAA------ -AAAAAAAAAAAAAAA-------- ---AAAAAAAAAAAA--------- --AAAAAAAAAAAAA--------- --AAAAAAAAAAAAAAA----AB- ---AAAAAA-AAAAAAAAAAAAC- ----AAAAAAAAAAA--------- ---AAAAAAAAAAA---------- -----AAAAAAAAA-------C-- ----AAAAAAAAABBB-----AAB ------AAAAAAAAAAA--AAAA- ------AAAAAAAAAAAAAAAA-- ----AAAAAAAAAAAAAAAAAB-- -----AAAAAAAAAAAAAAAAA-- ----AAAAAAAAA----------- ---AAAAAAAAAC----------- ---AAAAAAA--B----------- ---AAAAAA--------------- 
AAAAAAAAAAAAAAAAAA------ -AAAAAAAAAAAAAAA-------- ---AAAAAAAAAAAA--------- --AAAAAAAAAAAAA--------- --AAAAAAAAAAAAAAA------- ---AAAAAAAAAAAAAAAAAB--- ----AAAAAAAAAAA-----C--- ---AAAAAAAAAAA---------- -----AAAAAAAAA---------- ----AAAAAAAAAAAA-----CB- -------AAAAA-AAAA--AAB-- -------AAA-------------- -----AAAAA-------------- -----AAAAAAAAA---------- ----AAAAAAAAA----------- ---AAAAAAAAA------------ ----AAAAA---B----------- ----AAAA----B----------- 
AAAAAAAAAAAAAAAAAA------ --AAAAAAAAAAAAAA-------- ----AAAAAAAAAAA--------- ---AAAAAAAAAAA---------- ---AAAAAAAAAAAAA-------- ---AAAAAAAAAAAAA-------- -----AAAAAAAAA---------- ----AAAAAAAAA----------- ------AAAAAAA----------- -----AAAAAAA------------ --------AAA------------- ------------------------ ------AAA--------------- ------AAAAAAA----------- -----AAAAAAA------------ ----AAAAAAA------------- -----AAA---------------- ------------B----------- 
-AAAAAAAAAAAAAAAAA------ --AAAAAAAAAAAAAA-------- ----AAAAAAAAAAA--------- ---AAAAAAAAAAA---------- ---AAAAAAAAAAAAA-------- ----AAAAAAAAAAA--------- ------AAAAAAA----------- -----AAAAAAA------------ -------AAAAA------------ ------AAAAA------------- ------------------------ ------------------------ ------------------------ -------AAAAA------------ ------AAAAA------------- -----AAAAA-------------- ------A----------------- ------------------------ 
-AAAAAAAAAAAAAAAAA------ ---AAAAAAAAAAAAA-------- -----AAAAAAAAA---------- ----AAAAAAAAA----------- ----AAAAAAAAAAA--------- ----AAAAAAAAAAA--------- -------AAAAA------------ ------AAAAA------------- ------------------------ ------------------------ ------------------------ ------------------------ ------------------------ ------------------------ ------------------------ ------A----------------- ------A----------------- ------------------------ 
--AAAAAAAAAAAAAAA------- ---AAAAAAAAAAAAA-------- -------AAAAA------------ ------AAAAA------------- -----AAAAAAAAA---------- -----AAAAAAAAA---------- ------------------------ ------------------------ ------------------------ ------------------------ ------------------------ ------------------------ ------------------------ ------------------------ ------------------------ ------A----------------- ------A----------------- ------------------------ 
---AAAAAAAAAAAAA-------- -----AAAAAAAAA---------- ------------------------ ------------------------ -------AAAAA------------ -------AAAAA------------ ------------------------ ------------------------ ------------------------ ------------------------ ------------------------ ------------------------ ------------------------ ------------------------ ------------------------ ------------------------ ------A----------------- ------A----------------- 
----AAAAAAAAAAA--------- -------AAAAA------------ ------------------------ ------------------------ ------------------------ ------------------------ ------------------------ ------------------------ ------------------------ ------------------------ ------------------------ ------------------------ ------------------------ ------------------------ ------------------------ ------------------------ ------------------------ ------A----------------- 
------AAAAAAA----------- ------------------------ ------------------------ ------------------------ ------------------------ ------------------------ ------------------------ ------------------------ ------------------------ ------------------------ ------------------------ ------------------------ ------------------------ ------------------------ ------------------------ ------------------------ ------------------------ ------------------------ 
