model
size = 24 31 21, scale = 0.05, origin = -y
material 
  colors = A:#396 B:#500 C:#111 D:#EEE
voxels
--BBBBBBBBBBBBBBBBBBBB-- --AAAAAAAAAAAAAAAAAAAA-- --AABBBBBBBBBBBBBBBBAA-- --ABAAAAAAAAAAAAAAAABA-- --BAAABBBBBBBBBBBAAAAB-- --AAABAAAAAAAAAAABAAAA-- --AABAAAACACCAAAAABAAA-- --ABAAAAACACACAAAAABAA-- --BAAAAAACACAAAAAAAABA-- --AAAAACACACAAAAAAAAAB-- --AAAAAACCCCCAAAAAAAAA-- --ABAAAAAAAAAAAAAAAAAA-- --BAAAAAAAAAAAAAAAAABA-- --AAAACACCCCACCCCAAAAB-- --AAACAACAACACAAAAAAAA-- --ABACAACAACAACAAAAAAA-- --BAACAACCCCAAACAAAABA-- --AAACAACAACAACAAAAAAB-- --AAAAAACAACACAAAAAAAA-- --AAACAACCCCACCCCAAAAA-- --AAAAAAAAAAAAAAAAAAAA-- --AAAAAAAABBBBAAAAAAAA-- --AAAAAAAB----BAAAAAAA-- --BABABAB------BABABAB-- ---BABAB--------BABAB--- ---BABAB--------BABAB--- ------------------------ ------------------------ ------------------------ ------------------------ ------------------------ 
-B--------------------B- -A--------------------A- -A--------------------A- -A--------------------A- -B--------------------A- -A--------------------B- -A--------------------A- -A--------------------A- -B--------------------A- -A--------------------B- -A--------------------A- -A--------------------A- -B--------------------A- -A--------------------B- -A--------------------A- -A--------------------A- -B--------------------A- -A--------------------B- -A--------------------A- -A--------------------A- -A--------------------A- -A--------------------A- -B--------------------B- ------------------------ ------------------------ ------------------------ ---BABAB--------BABAB--- ------------------------ ------------------------ ------------------------ ------------------------ 
-B--------------------B- -A--------------------A- -A--------------------A- -B--------------------A- -A--------------------B- -B--------------------A- -A--------------------B- -A--------------------A- -A--------------------A- -B--------------------A- -A--------------------B- -A--------------------A- -A--------------------A- -B--------------------A- -A--------------------B- -A--------------------A- -A--------------------A- -B--------------------A- -A--------------------B- -A--------------------A- -A--------------------A- -B--------------------A- -B--------------------B- ------------------------ ------------------------ ------------------------ ------------------------ ---BABAB--------BABAB--- ------------------------ ------------------------ ------------------------ 
B----------------------B A----------------------A B----------------------A A----------------------B B----------------------A A----------------------B B----------------------A A----------------------B A----------------------A A----------------------A B----------------------A A----------------------B A----------------------A A----------------------A B----------------------A A----------------------B A----------------------A A----------------------A B----------------------A A----------------------B B----------------------A B----------------------B ------------------------ ------------------------ ------------------------ ------------------------ ------------------------ ------------------------ ---BABAB--------BABAB--- ------------------------ ------------------------ 
B----------------------B B----------------------A A----------------------B A----------------------A B----------------------A A----------------------B A----------------------A B----------------------A A----------------------B A----------------------A A----------------------A B----------------------A A----------------------B A----------------------A A----------------------A B----------------------A A----------------------B A----------------------A A----------------------A B----------------------A B----------------------B ------------------------ ------------------------ ------------------------ ------------------------ ------------------------ ------------------------ ------------------------ ------------------------ ---BABAB--------BABAB--- ------------------------ 
B----------------------B A----------------------B A----------------------A A----------------------A B----------------------A A----------------------B A----------------------A A----------------------A B----------------------A A----------------------B A----------------------A A----------------------A B----------------------A A----------------------B A----------------------A A----------------------A B----------------------A A----------------------B B----------------------A B----------------------B ------------------------ ------------------------ ------------------------ ------------------------ ------------------------ ------------------------ ------------------------ ------------------------ ------------------------ ---BABAB--------BABAB--- ------------------------ 
B----------------------B A----------------------A A----------------------A A----------------------A B----------------------B A----------------------B A----------------------B A----------------------A A----------------------A B----------------------A A----------------------B A----------------------A A----------------------A B----------------------A A----------------------B A----------------------A A----------------------A B----------------------A B----------------------B ------------------------ ------------------------ ------------------------ ------------------------ ------------------------ ------------------------ ------------------------ ------------------------ ------------------------ ------------------------ ------------------------ ---BABAB--------BABAB--- 
B----------------------B A----------------------A A----------------------A B----------------------B B----------------------A B----------------------B A----------------------A A----------------------B A----------------------A A----------------------A B----------------------A A----------------------B A----------------------A A----------------------A B----------------------A A----------------------B B----------------------A B----------------------B ------------------------ ------------------------ ------------------------ ------------------------ ------------------------ ------------------------ ------------------------ ------------------------ ------------------------ ------------------------ ------------------------ ------------------------ ---BABAB--------BABAB--- 
B----------------------B A----------------------A B----------------------B A----------------------A B----------------------A A----------------------B B----------------------A A----------------------A A----------------------B A----------------------A A----------------------A B----------------------A A----------------------B A----------------------A A----------------------A B----------------------A B----------------------B ------------------------ ------------------------ ------------------------ ------------------------ ------------------------ ------------------------ ------------------------ ------------------------ ------------------------ ------------------------ ------------------------ ------------------------ ------------------------ ---BABAB--------BABAB--- 
B----------------------B B----------------------B A----------------------A A----------------------A B----------------------A A----------------------B A----------------------A B----------------------A A----------------------A A----------------------B A----------------------A A----------------------A B----------------------A A----------------------B B----------------------A -----------------------B ------------------------ ------------------------ ------------------------ ------------------------ ------------------------ ------------------------ ------------------------ ------------------------ ------------------------ ------------------------ ------------------------ ------------------------ ------------------------ ------------------------ ---BABAB--------BABAB--- 
B----------------------B B----------------------B B----------------------B B----------------------B B----------------------B B----------------------B B----------------------B B----------------------B B----------------------B B----------------------B B----------------------B B----------------------B B----------------------B B----------------------B B----------------------B -----------------------B ------------------------ ------------------------ ------------------------ ------------------------ ------------------------ ------------------------ ------------------------ ------------------------ ------------------------ ------------------------ ------------------------ ------------------------ ------------------------ ------------------------ ---BABAB--------BABAB--- 
B----------------------B B----------------------B A----------------------A A----------------------A B----------------------A A----------------------B A----------------------A B----------------------A A----------------------A A----------------------B A----------------------A A----------------------A B----------------------A A----------------------B B----------------------A -----------------------B ------------------------ ------------------------ ------------------------ ------------------------ ------------------------ ------------------------ ------------------------ ------------------------ ------------------------ ------------------------ ------------------------ ------------------------ ------------------------ ------------------------ ---BABAB--------BABAB--- 
B----------------------B A----------------------A B----------------------B A----------------------A B----------------------A A----------------------B B----------------------A A----------------------A A----------------------B A----------------------A A----------------------A B----------------------A A----------------------B A----------------------A A----------------------A B----------------------A B----------------------B ------------------------ ------------------------ ------------------------ ------------------------ ------------------------ ------------------------ ------------------------ ------------------------ ------------------------ ------------------------ ------------------------ ------------------------ ------------------------ ---BABAB--------BABAB--- 
B----------------------B A----------------------A A----------------------A B----------------------B B----------------------A B----------------------B A----------------------A A----------------------B A----------------------A A----------------------A B----------------------A A----------------------B A----------------------A A----------------------A B----------------------A A----------------------B B----------------------A B----------------------B ------------------------ ------------------------ ------------------------ ------------------------ ------------------------ ------------------------ ------------------------ ------------------------ ------------------------ ------------------------ ------------------------ ------------------------ ---BABAB--------BABAB--- 
B----------------------B A----------------------A A----------------------A A----------------------A B----------------------B A----------------------B A----------------------B A----------------------A A----------------------A B----------------------A A----------------------B A----------------------A A----------------------A B----------------------A A----------------------B A----------------------A A----------------------A B----------------------A B----------------------B ------------------------ ------------------------ ------------------------ ------------------------ ------------------------ ------------------------ ------------------------ ------------------------ ------------------------ ------------------------ ------------------------ ---BABAB--------BABAB--- 
B----------------------B A----------------------B A----------------------A A----------------------A B----------------------A A----------------------B A----------------------A A----------------------A B----------------------A A----------------------B A----------------------A A----------------------A B----------------------A A----------------------B A----------------------A A----------------------A B----------------------A A----------------------B B----------------------A B----------------------B ------------------------ ------------------------ ------------------------ ------------------------ ------------------------ ------------------------ ------------------------ ------------------------ ------------------------ ---BABAB--------BABAB--- ------------------------ 
B----------------------B B----------------------A A----------------------B A----------------------A B----------------------A A----------------------B A----------------------A B----------------------A A----------------------B A----------------------A A----------------------A B----------------------A A----------------------B A----------------------A A----------------------A B----------------------A A----------------------B A----------------------A A----------------------A B----------------------A B----------------------B ------------------------ ------------------------ ------------------------ ------------------------ ------------------------ ------------------------ ------------------------ ------------------------ ---BABAB--------BABAB--- ------------------------ 
B----------------------B A----------------------A B----------------------A A----------------------B B----------------------A A----------------------B B----------------------A A----------------------B A----------------------A A----------------------A B----------------------A A----------------------B A----------------------A A----------------------A B----------------------A A----------------------B A----------------------A A----------------------A B----------------------A A----------------------B B----------------------A B----------------------B ------------------------ ------------------------ ------------------------ ------------------------ ------------------------ ------------------------ ---BABAB--------BABAB--- ------------------------ ------------------------ 
B---------------------B- A---------------------A- A---------------------A- B---------------------A- A---------------------B- B---------------------A- A---------------------B- A---------------------A- A---------------------A- B---------------------A- A---------------------B- A---------------------A- A---------------------A- B---------------------A- A---------------------B- A---------------------A- A---------------------A- B---------------------A- A---------------------B- A---------------------A- A---------------------A- B---------------------A- B---------------------B- ------------------------ ------------------------ ------------------------ ------------------------ ---BABAB--------BABAB--- ------------------------ ------------------------ ------------------------ 
-B--------------------B- -A--------------------A- -A--------------------A- -A--------------------A- -B--------------------A- -A--------------------B- -A--------------------A- -A--------------------A- -B--------------------A- -A--------------------B- -A--------------------A- -A--------------------A- -B--------------------A- -A--------------------B- -A--------------------A- -A--------------------A- -B--------------------A- -A--------------------B- -A--------------------A- -A--------------------A- -A--------------------A- -A--------------------A- -B--------------------B- ------------------------ ------------------------ ------------------------ ---BABAB--------BABAB--- ------------------------ ------------------------ ------------------------ ------------------------ 
--BBBBBBBBBBBBBBBBBBBB-- --AAAABAAAAAAAAAABAAAA-- --AAABAAAAAAAAAAAABAAA-- --AABAAABBBBBBBBAAABAA-- --BBAAABAAAAAAAABAAABA-- --AAAAAAAACCACAAAABAAB-- --AAABAAACACACAAAAAAAA-- --AABAAAAAACACAAAAABAA-- --BBAAAAAAACACACAAAABA-- --AAAAAAAACCCCCAAAAAAB-- --AAABAADAAADAAAAAAAAA-- --AABAAADAAADAAAAAABAA-- --BBAACCCCACCCCACAAABA-- --AAAAAAACACAACAACAAAB-- --AAAAAACAACAACAACAAAA-- --AAAAACAAACCCCAACAAAA-- --AAAAAACAACAACAACAAAA-- --BAAAAAACACAACAAAAAAB-- --ABAACCCCACCCCAACAABA-- --AABAAAAAAAAAAAAAABAA-- --AAABAAAAAAAAAAAABAAA-- --AAAAAAAAAAAAAAABAAAA-- --AAAAABAAAAAAAABAAAAA-- --BAAAAABABBBBABAAAAAB-- ---BAAAAAB----BAAAAAB--- ---BABABB------BBABAB--- ------------------------ ------------------------ ------------------------ ------------------------ ------------------------ 
