model
size = 22 30 19, scale = 0.05, origin = -y
material 
  colors = A:#252525 B:#212121 C:#282828 D:#191919 E:#1D1D1D F:#FF0 G:#FFF H:#DADADA I:#A00 J:#000 K:#EAEA2C
voxels
--------D----D-------- --------D----D-------- --------D----D-------- --------D----D-------- --------D----D-------- --------D----D-------- --------D----D-------- --------D----D-------- --------D----D-------- --------D----D-------- --------D----D-------- --------D----D-------- --------D----D-------- --------D----D-------- --------D----D-------- --------D----D-------- --------D----D-------- --------D----D-------- --------D----D-------- --------D----D-------- ---------------------- ---------------------- ---------------------- ---------------------- ---------------------- ---------------------- ---------------------- ---------------------- ---------------------- ---------------------- 
-----DDD------DDD----- -----CCA------ACA----- -----ACC------CAA----- -----AAA------CAE----- -----IAA------CAA----- -----IAA------CAA----- -----IAA------AHH----- -----CCA------ABB----- -----AAA------CHH----- -----IAA------ABB----- -----ACA------AHH----- -----AAA------AAA----- -----IAA------AAF----- -----ACA------CAA----- -----AAA------CAA----- -----HCA------ACF----- -----AHA------CAA----- -----ACA------ACC----- -----FAC------CAA----- -----AAA------AHA----- -----AHAD----DAAH----- -----HAAD----DCAA----- -----ACAD----DACC----- ---------------------- ---------------------- ---------------------- ---------------------- ---------------------- ---------------------- ---------------------- 
---BD------------DD--- ---CA------------AE--- ---AA------------AE--- ---AI------------EA--- ---IA------------CA--- ---IA------------AA--- ---IA------------HH--- ---AA------------BB--- ---AA------------HH--- ---II------------BB--- ---IA------------HH--- ---IA------------AA--- ---II------------FF--- ---AA------------FC--- ---AA------------FA--- ---HH------------FA--- ---AA------------FA--- ---AF------------AB--- ---FK------------CC--- ---AF------------AA--- ---AA------------HH--- ---HH------------AA--- ---AA------------AC--- ---DAABAD----DAACCA--- ---------------------- ---------------------- ---------------------- ---------------------- ---------------------- ---------------------- 
--D----------------D-- --B----------------A-- --A----------------B-- --A----------------C-- --A----------------A-- --A----------------A-- --A----------------A-- --A----------------C-- --A----------------C-- --A----------------A-- --A----------------H-- --A----------------A-- --A----------------C-- --A----------------C-- --A----------------C-- --A----------------C-- --H----------------B-- --A----------------B-- --A----------------A-- --A----------------H-- --H----------------A-- --A----------------B-- --A----------------B-- --B----------------A-- ---BAEAAD----DAAEEE--- ---------------------- ---------------------- ---------------------- ---------------------- ---------------------- 
-D------------------D- -B------------------A- -C------------------B- -A------------------B- -A------------------C- -E------------------A- -E------------------E- -C------------------A- -A------------------E- -A------------------A- -A------------------A- -A------------------A- -C------------------A- -A------------------B- -C------------------B- -A------------------E- -A------------------B- -A------------------B- -C------------------A- -A------------------A- -A------------------B- -C------------------C- -A------------------C- -A------------------C- --EB--------------AC-- ----EACD------DABC---- -----B----------A----- ---------------------- ---------------------- ---------------------- 
-D------------------D- -A------------------B- -A------------------A- -A------------------B- -A------------------E- -A------------------B- -C------------------B- -A------------------B- -C------------------B- -A------------------A- -C------------------E- -C------------------C- -E------------------A- -E------------------C- -A------------------E- -A------------------B- -C------------------B- -C------------------A- -C------------------B- -A------------------C- -D------------------D- -D------------------D- -D------------------D- -D------------------D- -DAA--------------AAD- ---C--------------A--- ----CAAD------DAAB---- ------D--------D------ ---------------------- ---------------------- 
D--------------------D B--------------------A A--------------------A E--------------------E E--------------------B E--------------------E E--------------------B E--------------------B A--------------------E B--------------------C C--------------------B B--------------------C B--------------------B A--------------------E C--------------------A B--------------------A E--------------------B A--------------------C A--------------------A D--------------------D ---------------------- ---------------------- ---------------------- ---------------------- ---------------------- --DA--------------AD-- ---BA------------BB--- -----A-D------D-B----- ------D--------D------ ---------------------- 
D--------------------D C--------------------A B--------------------E B--------------------C B--------------------B A--------------------B B--------------------C B--------------------C E--------------------C B--------------------C C--------------------C E--------------------B E--------------------C E--------------------E C--------------------E B--------------------A E--------------------E A--------------------A D--------------------D ---------------------- ---------------------- ---------------------- ---------------------- ---------------------- ---------------------- ---------------------- ---D--------------D--- ----AA----------AC---- ------D--------D------ ---------------------- 
D--------------------D B--------------------A B--------------------A A--------------------A B--------------------E B--------------------B B--------------------E E--------------------B B--------------------C C--------------------E A--------------------B B--------------------C B--------------------C E--------------------B E--------------------B B--------------------A A--------------------E A--------------------A D--------------------D ---------------------- ---------------------- ---------------------- ---------------------- ---------------------- ---------------------- ---------------------- ---D--------------D--- ----A------------A---- -----D----------D----- ---------------------- 
D--------------------D A--------------------E C--------------------E B--------------------C A--------------------A B--------------------A B--------------------B B--------------------B A--------------------C B--------------------B B--------------------C E--------------------E B--------------------E C--------------------A B--------------------B A--------------------E E--------------------B A--------------------A D--------------------D ---------------------- ---------------------- ---------------------- ---------------------- ---------------------- ---------------------- ---------------------- ---D--------------D--- ----A------------A---- -----D----------D----- ---------------------- 
D--------------------D A--------------------A A--------------------C A--------------------A C--------------------E B--------------------A E--------------------A E--------------------E B--------------------A C--------------------A B--------------------A B--------------------A A--------------------E A--------------------A B--------------------A B--------------------A C--------------------B A--------------------C D--------------------D ---------------------- ---------------------- ---------------------- ---------------------- ---------------------- ---------------------- ---------------------- ---D--------------D--- ----A------------A---- -----D----------D----- ---------------------- 
D--------------------D B--------------------A C--------------------A A--------------------A E--------------------E E--------------------E A--------------------C B--------------------B C--------------------A B--------------------E B--------------------A E--------------------E B--------------------A B--------------------C B--------------------C B--------------------E C--------------------C A--------------------A D--------------------D ---------------------- ---------------------- ---------------------- ---------------------- ---------------------- ---------------------- ---------------------- ---D--------------D--- ----A------------C---- -----D----------D----- ---------------------- 
D--------------------D A--------------------E A--------------------A B--------------------E B--------------------A B--------------------C C--------------------B B--------------------A E--------------------A E--------------------C E--------------------A B--------------------C A--------------------A C--------------------E E--------------------B E--------------------B B--------------------E C--------------------A A--------------------A D--------------------D ---------------------- ---------------------- ---------------------- ---------------------- ---------------------- --D----------------D-- ---A--------------E--- ----A------------B---- -----D----------D----- ------D--------D------ 
-D------------------D- -E------------------A- -A------------------C- -B------------------A- -E------------------C- -E------------------A- -A------------------A- -A------------------A- -B------------------A- -A------------------A- -B------------------C- -C------------------B- -C------------------B- -A------------------B- -C------------------B- -A------------------A- -A------------------A- -A------------------A- -A------------------E- -A------------------A- -D------------------D- -D------------------D- -D------------------D- -D------------------D- -D------------------D- --A----------------A-- ---B--------------A--- ----A------------C---- -----AD--------DA----- ------D--------D------ 
-D------------------D- -A------------------A- -E------------------A- -C------------------B- -A------------------C- -A------------------E- -B------------------A- -B------------------E- -C------------------C- -B------------------C- -A------------------E- -B------------------A- -E------------------C- -A------------------C- -A------------------E- -C------------------A- -A------------------A- -E------------------B- -E------------------B- -C------------------C- -A------------------A- -C------------------A- -A------------------E- -A------------------A- -A------------------A- --A----------------E-- ---B--------------B--- ----AA----------BB---- ------AC------AC------ -------D------D------- 
--D----------------D-- --A----------------A-- --B----------------E-- --A----------------E-- --B----------------C-- --A----------------C-- --A----------------C-- --A----------------C-- --A----------------B-- --E----------------B-- --A----------------C-- --A----------------E-- --E----------------C-- --A----------------E-- --B----------------C-- --E----------------E-- --B----------------A-- --A----------------B-- --C----------------B-- --A----------------B-- --E----------------A-- --A----------------E-- --A----------------E-- --C----------------C-- --C----------------A-- ---A--------------E--- ----EA----------AC---- -----EABCCABABECB----- -------ABABECAB------- --------DDDDDD-------- 
---DD------------DD--- ---AA------------AA--- ---BF------------FE--- ---AF------------FB--- ---AF------------FA--- ---AF------------FB--- ---BF------------FA--- ---AF------------FA--- ---AF------------FA--- ---AA------------AB--- ---CA------------AE--- ---CB------------BA--- ---EA------------AA--- ---CB------------BA--- ---AC------------AE--- ---AB------------AA--- ---BA------------BC--- ---EB------------AB--- ---BA------------BE--- ---AA------------AA--- ---AE------------AA--- ---BA------------AC--- ---EA------------AA--- ---EA------------AC--- ---EC------------AB--- ----CA----------EE---- -----ECEAEAAAAABE----- ------EEEECBBBBE------ ---------------------- ---------------------- 
-----DDDDDDDDDDDD----- -----FFFFFFFFFFFF----- -----FAAAAAAAAAAF----- -----AAAAAAAAAAAA----- -----AAAAAAAAAAAA----- -----AAAAAAAAAAAA----- -----AAAAAAAAAAAA----- -----AAAAAAAAAAAA----- -----FAAAAAAAAAAF----- -----FFFFFFFFFFFF----- -----AAAAABEAAAAB----- -----AABAAAEAEAAA----- ----BABBEABACCEAAA---- ----BABACCBBACBCAE---- ----CACBABCECCECAC---- ----BACABBABBCBAEA---- ----BAACBEBBCAEAAB---- ----CBAEBCBCAACACC---- ----BAECBBCEBBCCBC---- ----AABBBCABACCEAA---- ----BAEACAECCCEBAC---- ----CABAAAEAEEBAEC---- ----EAAECEBCEEAABA---- ----EBCEAAAACCEBAC---- -----BAACABBAAAAE----- ------AABAEAEEAA------ -------BAABEACC------- ---------------------- ---------------------- ---------------------- 
---------------------- ------FFFFFFFFFF------ ------AAAAAAAAAA------ ------FFFFAFAAAF------ ------AAAFAFAFAF------ ------AAAFAFAFAF------ ------AAAFAFFAFF------ ------FFFFAFAAAF------ ------AAAAAAAAAA------ ------FFFFFFFFFF------ ------AAAAAAAAAE------ ------EBBEEBBEBA------ ------EEAEAAAEEB------ ------BAAAGGAAAA------ ------EAGBGGBGAE------ ------AAGAGGAGAB------ ------AAGGGGGGAA------ ------AGGGGGGGGA------ ------AGJJGGJJGA------ ------AGJJGGJJGB------ ------EGGGGGGGGA------ ------AAGGGGGGAA------ ------BAAGGGGAEA------ ------BBABAAAABE------ ------BEEABBAEAA------ -------BCABEECA------- ---------------------- ---------------------- ---------------------- ---------------------- 
