model
size = 20 9 5, scale = 0.05, origin = -y
material 
  colors = A:#EEE B:#0E0 C:#222
voxels
-------------------- -------------------- -------------------- ----C----------C---- ---CCC--------CCC--- ----C----------C---- -------------------- -------------------- -------------------- 
-------------------- --BBBBB------BBBBB-- -BBBCBBB----BBBCBBB- -BBCCCBB----BBCCCBB- -BCCCCCB----BCCCCCB- -BBCCCBB----BBCCCBB- -BBBCBBB----BBBCBBB- --BBBBB------BBBBB-- -------------------- 
--AAAAA------AAAAA-- -AAAAAAA----AAAAAAA- AAAAAAAAA--AAAAAAAAA AAAAAAAAA--AAAAAAAAA AAAAAAAAA--AAAAAAAAA AAAAAAAAA--AAAAAAAAA AAAAAAAAA--AAAAAAAAA -AAAAAAA----AAAAAAA- --AAAAA------AAAAA-- 
--AAAAA------AAAAA-- -AAAAAAA----AAAAAAA- AAAAAAAAA--AAAAAAAAA AAAAAAAAA--AAAAAAAAA AAAAAAAAA--AAAAAAAAA AAAAAAAAA--AAAAAAAAA AAAAAAAAA--AAAAAAAAA -AAAAAAA----AAAAAAA- --AAAAA------AAAAA-- 
--AAAAA------AAAAA-- -AAAAAAA----AAAAAAA- AAAAAAAAA--AAAAAAAAA AAAAAAAAA--AAAAAAAAA AAAAAAAAA--AAAAAAAAA AAAAAAAAA--AAAAAAAAA AAAAAAAAA--AAAAAAAAA -AAAAAAA----AAAAAAA- --AAAAA------AAAAA-- 
