model
size = 16 18 32, scale = 0.05, origin = -y
material 
  colors = A:#FF3 B:#F90 C:#900 D:#FC0 E:#A00 F:#700 G:#C60 H:#800 I:#500 J:#400 K:#600 L:#C90 M:#B00 N:#FC3 O:#FF0 P:#CC0
voxels
76-KA14-CD13-EG14-EK255-CA14-LD13-BK14-EG255-BA14-PD13-EA14-EK239-DA14-DA13-BD14-2C14-C46-F177-DA14-2A14-D14-2G14-2F14-C30-E15-F161-LA14-2A13-2A14-2D14-2E13-2C30-D14-ED14-2F145-CA14-DA13-2A14-2D14-L14-2F14-2M14-G14-2D14-FD145-H2(D14-)2A14-2A13-2D14-2C14-2F13-2C2(14-2D)14-F99-FB13-FK14-KD14-G14-2N14-A14-2D14-2L14-H14-2M14-2G14-D15-E14-2F67-2B14-FB13-FK14-HK13-2E14-2D14-A14-2A14-2D13-2G14-2F14-C2(15-D)14-EF67-BA14-BA13-HB14-FK13-2K14-2G13-2N14-2A14-D14-2B14-2C14-E15-G14-2D14-E53-B14-BA13-BA14-IB14-M14-2K14-2E13-2D14-2A14-A14-2D14-2G14-H15-C14-E15-E37-BA13-2A14-2A13-GA14-M2(B14-)2C14-2I13-2G14-2D14-A14-2D14-2B14-E15-M14-E37-2(2A14-2A13-)2(BA14-)D14-2B14-K14-2C14-2D14-A14-2A14-2D14-G15-H14-C37-2A14-2A13-2A14-3(A14-D)14-2B14-C14-2I14-2C14-D14-2A14-2D14-B15-H14-C37-AD13-2(2A14-)A2(14-2A)14-A14-2D14-B14-2F14-2K14-L2(14-2D)14-B14-2M14-E37-B2(2(14-2A)14-A)14-2A14-A14-2G14-2J14-H14-2L14-2O14-D14-2C14-C37-B14-2B14-AB14-A2(14-2A)13-2(2A14-)A14-2D14-2H13-2J14-2E14-D14-2D14-2C14-H52-2B14-B15-B14-AB2(14-2A13-2A)14-2D14-G2(14-2I)13-2E14-2G14-2M13-2H52-K2(15-B)14-DB14-AB13-AB14-2A13-2A14-2A13-2B14-2C13-2J14-2I14-2K13-2C14-2C68-K15-K14-HK13-2G14-DB13-AB14-AB13-AB14-2D13-3C13-2K14-2J13-2F14-2C14-M69-B14-2E14-HE13-2K14-2E13-2G13-2DB13-DB14-2D13-GB14-2F13-2J14-2H14-2C13-FG69-B14-B2(E13-2C)13-2H14-2I13-2F14-2E13-2C14-2H13-2I14-2J13-3E13-2C14-F85-2(2B13-)3L2(13-2C)14-2F13-2I14-2J13-2J14-2I13-2I14-2E14-2C99-2B14-2(2B13-)3B13-2L13-3C13-2M13-2F14-2I13-2J14-2H14-2C115-2C13-3G2(13-2B)2(13-3B13-2B)14-2C13-2J14-2E131-I14-2I13-3H13-2E13-2C14-2G13-2G14-2C13-2I14-2K147-C14-2E13-2F14-2I13-2(2J14-J14-)2J177-2C14-2C13-2E13-3C13-2C13-2I14-2J209-G14-2B13-2B14-2B13-2I206-B14-3B13-3B12-5G10-5H11-J3-J10-2I3-I10-E194-2C14-2F13-3K12-4C12-4F11-5H11-5F10-5H10-4L76-
