model
size = 15 18 31, scale = 0.05, origin = -y
material 
  colors = A:#FF3 B:#F90 C:#FC0 D:#900 E:#A00 F:#C60 G:#700 H:#500 I:#400 J:#800 K:#600 L:#B00 M:#C90 N:#FC3 O:#FF0 P:#CC0
voxels
--------------- --------------- --------------- --------------- -----B--------- ----BBB-------- ----BBB-------- ---BBFFF------- --CCCJJ-------- --EEE-I-------- -DDDD-H-------- -EEE----------- FF------------- --------------- --------------- --------------- --------------- --------------- 
--------------- --------------- --------------- --------------- --------------- --------F------ -------BB------ ------BB------- ------BB------- -----HH-------- --------------- --------------- --------------- --------------- --------------- --------------- --------------- --------------- 
--------------- --------------- --------------- --------------- --------DD----- --------DD----- -------EE------ ------DDD------ ------DD------- -----HH-------- -----II-------- --------------- --------------- --------------- --------------- --------------- --------------- --------------- 
--------------- --------------- --------------- ----------D---- ---------EE---- --------GG----- --------HH----- -------II------ -------I------- ------II------- ------I-------- -----II-------- --------------- --------------- --------------- --------------- --------------- --------------- 
--------------- --------------- --------------- ----------H---- ---------HH---- --------JJJ---- --------EE----- -------DD------ -------FF------ ------FF------- ------DD------- -----HH-------- -----KK-------- --------------- --------------- --------------- --------------- --------------- 
--------------- --------------- --------------- ----------DD--- ---------FFF--- ---------BB---- --------BB----- -------BBB----- -------BB------ ------BBB------ ------BB------- ------DD------- -----II-------- -----EE-------- --------------- --------------- --------------- --------------- 
--------------- --------------- --------------- ----------BB--- ----------BB--- ---------BB---- --------BBB---- --------MM----- -------DDD----- -------LL------ ------GG------- ------HH------- -----II-------- -----JJ-------- -----DD-------- --------------- --------------- --------------- 
--------------- --------------- --------------- -----------BB-- ----------BB--- ---------MMM--- ---------DD---- --------DD----- --------GG----- -------HH------ -------II------ ------II------- ------HH------- -----HH-------- -----EE-------- -----DD-------- --------------- --------------- 
--------------- --------------- ------------B-- -----------BE-- ----------DDE-- ----------DD--- ---------JJ---- ---------HH---- --------GG----- --------EE----- -------DD------ -------JJ------ ------HH------- ------II------- -----EEE------- -----DD-------- -----G--------- --------------- 
--------------- --------------- ------------B-- -----------EE-- -----------JE-- ----------KK--- ----------EE--- ---------FF---- --------CCB---- --------CB----- --------CC----- -------FB------ -------GG------ ------II------- ------JJ------- ------DD------- -----GF-------- --------------- 
--------------- --------------- ------------K-- ------------K-- -----------JK-- ----------FF--- ----------CB--- ---------AB---- ---------AB---- --------AB----- --------CC----- -------DDD----- -------KK------ -------II------ ------GG------- ------DD------- ------L-------- --------------- 
--------------- ------------K-- ------------B-- ------------B-- -----------CB-- -----------AB-- ----------AB--- ----------AA--- ---------AA---- ---------AA---- --------BB----- --------DD----- -------II------ -------HH------ -------KK------ ------DD------- ------DD------- --------------- 
--------------- ------------BB- ------------B-- ------------B-- -----------AB-- -----------AA-- ----------AA--- ----------AA--- ---------AA---- ---------CC---- ---------F----- --------HH----- --------HH----- -------EE------ -------FF------ -------LL------ ------JJ------- --------------- 
-------------B- ------------BB- ------------AB- ------------A-- -----------AA-- -----------AA-- ----------AA--- ----------AA--- ----------A---- ---------CC---- ---------JJ---- --------II----- --------EE----- --------C------ -------CC------ -------DD------ -------J------- --------------- 
-------------B- ------------AA- ------------AA- ------------A-- -----------AA-- -----------AA-- -----------A--- ----------AA--- ----------A---- ---------FF---- ---------II---- ---------J----- --------MM----- --------OO----- --------C------ -------DD------ -------D------- --------------- 
-------------AC ------------AA- ------------AA- ------------A-- -----------AA-- -----------AA-- -----------A--- ----------CC--- ----------B---- ---------GG---- ---------KK---- ---------M----- --------CC----- --------CC----- --------B------ -------LL------ -------E------- --------------- 
-------------AA -------------AA ------------AA- ------------A-- -----------CA-- -----------CA-- -----------C--- ----------BB--- ----------D---- ---------HH---- ---------DD---- ---------C----- --------AA----- --------CC----- --------B------ --------J------ -------D------- --------------- 
-------------AA -------------AA ------------AA- ------------AA- -----------BA-- -----------BA-- -----------C--- ----------BB--- ----------K---- ---------DD---- ---------CC---- ---------A----- --------AA----- --------CC----- --------F------ --------J------ -------D------- --------------- 
--------------- -------------BA ------------AA- ------------AA- -----------FA-- -----------LB-- -----------B--- ----------DD--- ----------HH--- ---------FF---- ---------CC---- ---------A----- --------CC----- --------BB----- --------E------ --------L------ -------E------- --------------- 
--------------- --------------- -------------B- ------------BA- -----------BA-- -----------HB-- -----------L--- ----------KK--- ----------EE--- ---------CC---- ---------AA---- ---------A----- --------CC----- --------FF----- --------J------ --------D------ -------E------- -------E------- 
--------------- --------------- --------------- ------------BA- ------------BA- -----------JB-- -----------GK-- ----------KK--- ----------FF--- ---------NN---- ---------AA---- ---------C----- --------BB----- --------DD----- --------E------ --------F------ -------CC------ -------E------- 
--------------- --------------- --------------- ------------BB- ------------GB- -----------GK-- -----------JK-- ----------EE--- ----------CC--- ----------A---- ---------AA---- ---------CC---- --------FF----- --------GG----- --------D------ --------C------ --------C------ -------EG------ 
--------------- --------------- --------------- --------------- ------------GB- -----------GK-- -----------KC-- -----------F--- ----------NN--- ----------A---- ---------CC---- ---------MM---- ---------J----- --------LL----- --------FF----- --------C------ --------E------ -------GG------ 
--------------- --------------- --------------- --------------- --------------- --------------- -----------JC-- -----------C--- ----------AA--- ----------AA--- ---------CC---- ---------DD---- ---------GG---- --------DD----- --------CC----- --------CC----- --------G------ --------------- 
--------------- --------------- --------------- --------------- --------------- --------------- -----------DA-- -----------CA-- ----------AA--- ----------CC--- ----------M---- ---------GG---- ---------LL---- ---------F----- --------CC----- --------GC----- --------------- --------------- 
--------------- --------------- --------------- --------------- --------------- --------------- -----------MA-- -----------AA-- ----------AA--- ----------CC--- ----------EE--- ---------DD---- --------------- ---------C----- --------EC----- --------GG----- --------------- --------------- 
--------------- --------------- --------------- --------------- --------------- --------------- -----------CA-- -----------AA-- -----------C--- ----------FF--- ----------GG--- ----------D---- --------------- ---------E----- ---------G----- --------------- --------------- --------------- 
--------------- --------------- --------------- --------------- --------------- --------------- -----------CA-- -----------CA-- ----------BC--- ----------DD--- ----------D---- --------------- --------------- ---------G----- --------------- --------------- --------------- --------------- 
--------------- --------------- --------------- --------------- --------------- --------------- -----------BA-- -----------PC-- ----------EA--- ----------EK--- --------------- --------------- --------------- --------------- --------------- --------------- --------------- --------------- 
--------------- --------------- --------------- --------------- --------------- -----------DA-- -----------MC-- ----------BK--- ----------EF--- --------------- --------------- --------------- --------------- --------------- --------------- --------------- --------------- --------------- 
--------------- --------------- --------------- --------------- -----------KA-- -----------DC-- ----------EF--- ----------EK--- --------------- --------------- --------------- --------------- --------------- --------------- --------------- --------------- --------------- --------------- 
