model
size = 14 15 32, scale = 0.05, origin = -y
material 
  colors = A:#EEE B:#001 C:#222 D:#BBB E:#FF3 F:#555 G:#3C0 H:#3CC I:#C0C J:#900 K:#306 L:#C33 M:#69F N:#00D O:#F39 P:#800 Q:#9FC R:#6CF
voxels
4-3(6A8-)2(6B8-)6B7-2(8B6-)8B7-6B77-3(8A6-)2(2B4-2B6-)3(8B6-)8B7-6B9-4B10-4B49-3(10A4-)2(2(2B2-)2B4-)3B-2B-3B5-2(8B6-)8B7-3(6B8-)6B10-2B22-3(11A3-)2B-4B-2BA3-B2-4B2-B4-2B-4B-2B3(4-10B)5-8B6-8B7-6B8-6B34-2(11A3-)11A2-2B-B4AB-2B3-2(B-B4-)B-6B-B3(4-10B)5-8B6-8B7-6B8-2B2-2B34-2(11A3-)11A2-2B-B4AB-2B2(2-B)4-3(B2-)B4-B2-B3-5(3B4-)3B5-2B4-2B7-B4-B62-2(11A3-)11A2-2B-BA2-AB-2B2-B-B6-B-B2-B-2B4-2B-2(B2-)B4-2(B2-)4B4-4B3-2(3B4-)2B6-2B74-2(11A3-)11A2-3BA3-2A3B3(2-B-B6-B-B)2(2-3B6-3B)3-2B6-2B75-10A2(3-11A)2-B2EA3-2A2EB2-3M6-3M2-J-J6-J-J2-B-B6-B-B2-3L6-3L2-R2B6-2BR88-10A2(3-11A)2-3BA3-2A3B2-3E6-3E2-3B6-3B2-P-E6-E-E2-3B6-3B2-Q2B6-2BQ88-10A4-10A3-11A2-3BA4-A3B2-3E6-3E2-3B6-3B2-P2E6-3E2-3B6-3B2-L2B6-2BL2-B10-B18-BC4-CB7-6C35-10A4-10A3-11A2-3BA5-2B-A-3E6-3E2-3H6-3H2-3B6-3B2(2-3J6-3J)2-B10-B3-2B6-2B4-2B6C2B5-F6CF7-6C21-2(10A4-)11A-3BA5-2B-A-3E6-3E2-3K6-3K2-3G6-3G2-2O8-2O2-2G8-2G2-2B8-2B2-3B6-3B3-2B6C2B5-F6CF6-F6CF20-10A4-10A3-12A-3BA5-2B-A-3E6-3E2-3H6-3H2-3B6-3B2(2-3G6-3G)2-3B6-2(3B2-3B6C)3B4-F6C8-F4CF9-4F8-11A3-11A2-12A-3BA5-2B-A-3E6-3E2-3B6-3B2-P2E6-3E2-3B6-3B2-3I6-3I2-3B6-3B2-3B6C3B2-2BA6CA2B4-F6CF7-F4CF20-12A2-12A-13A-3BA5-3BA-3E6-3E2-3B6-3B2-P2E6-3E2-3B6-3B2-3IC4-C3I3(2-3B6C3B)5-6C9-4F21-12A2(-13A)-B2EA5-3EA-3H6-3H2-3K6-3K2-3B6-3B2-3N6-3N2-3I6C3I2(2-3B6C3B)3-BF6CFB5-8F32-13A-28A2B2A5-A2BA-2(2B8-2B2-)3B6-3(3B2-3B6C)3B3-2B6C2B6-6C47-42AB3A5-2ABA-B10-B2-2B8-2B4(2-3B6C3B)3-BA6CAB5-8F45-43AB3A5-2ABA-B10-B2-2B8-2B3(2-3B6C3B)3-2B6C2B5-B6CB7-6C46-43AB2A6-2ABA-2(B10-B2-)3B6C3B2-3BC4-C3B3-2B6C2B4-2B6C2B5-F6CF6-8F45-43AB2A5-3ABA-B10-B2-3B6C3B2-3B6-3B3-2BC-2C-C2B4-2B6C2B6-6C8-6C60-43AB2A5-3ABA-2B8-2B2-3B6C3B2-3B6-3B3-2B6C2B5-B6CB7-C4-C74-43AB2A5-2A-BA-B8-2DB3-D7-2D3-11D3-10D5-9D6-7D74-43AB2A4-3A-BA2-A7-2D3-2D8-D3-11D4-9D5-9D87-3(13A-)4A4-3A-2A-D8-3D2-2D-8D3-11D4-9D5-9D88-12A2-12A-13A2-4A3-5A2-2D7-3D2-11D4-10D4-8D7-7D89-3(12A2-)9A-2A2-11D3-8D-2(2D4-)A2D7-4D105-3(11A3-)9A-2A2-11D4-2D6-D5-3D2-4D7-4D105-2(10A4-)10A5-A-4A2-A3(5-2D)4-2D7-6D119-3(8A6-)8A7-6D9-4D11-2D122-6A7-8A6-8A8-4A160-
