model
size = 15 32 15, scale = 0.05, origin = -y
material 
  colors = A:#111 B:#06F C:#FFF D:#DDD E:#EEE
voxels
5-5C370-5C98-9C8-5D13(10-5B)10-2C2(3B10-BC)B2E10-2CBEB10-BC2BC10-2C3B4(10-5B)8-9C8-5D82-11C5-9D13(6-9B)6-BC2A3BEB6-BC5BEB6-5B2A2E6-BC2A3BEB6-BC5BEB6-B2CA3BCB4(6-9B)5-11C5-9D8-5B66-13C3-11D23(4-11B)3-13C3-11D6-B5AB9-5B51-13C3-11D23(4-B9AB)3-13C3-11D5-B7AB7-7B49-15C-13D23(2-13B)-15C-13D3-B9AB5-3B3A3B9-3D36-15C-13D23(2-B11AB)-15C-13D3-B9AB5-2B5A2B8-5D11-3C12-CBC2(6-15C-13D23(2-B11AB)-15C-13D3-B9AB5-2B5A2B8-5D11-3C12-3C)6-15C-13D23(2-B11AB)-15C-13D3-B9AB5-3B3A3B9-3D37-13C3-11D23(4-B9AB)3-13C3-11D5-B7AB7-7B50-13C3-11D23(4-B9AB)3-13C3-11D6-B5AB9-5B52-11C5-9D23(6-2B5A2B)5-11C5-9D8-5B68-9C8-5D23(10-5B)8-9C8-5D85-5C370-5C95-
