model
size = 16 31 21, scale = 0.05, origin = -y
material 
  colors = A:#111 B:#C30 C:#930 D:#F30 E:#999 F:#4C2603 G:#630 H:#F60 I:#AAA J:#633 K:#996 L:#777 M:#400 N:#300 O:#592C01 P:#963 Q:#FCC R:#FFC S:#BBB T:#888 U:#444 V:#966 W:#C96 X:#C63 Y:#C99 Z:#800 Aa:#333 Ab:#555 Ac:#FC9 Ad:#222 Ae:#C60 Af:#CCB615 Ag:#CCAE1D Ah:#500 Ai:#700 Aj:#A00 Ak:#3F1F05 Al:#600
voxels
- - - - A A A A A A A - - - - -   - - - - - A A A A A A - - - - -   - - - - - A A A A A - - - - - -   - - - - - A A A A A A - - - - -   - - - - - A A A A A A - - - - -   - - - - - A A A A A A - - - - -   - - - - - - A A A A A - - - - -   - - - - - - A A A A A - - - - -   - - - - - - - A A A A - - - - -   - - - - - - - - - - - - - - - -   - - - - - - - - - - - - - - - -   - - - - - - - - - - - - - - - -   - - - - - - - - - - - - - - - -   - - - - - - - - - - - - A - - -   - - - - - A - - - - - - - A A -   - - - - - - - - - - - - - A A -   - - - - - - - - - - - - - A A -   - - - - - - - - - - - - - A A -   - - - - - - - - - - - - - - A -   - - - - - - - - - - - - - - A -   - - - - - - - - - - - - - - A -   - - - - - - - - - - - - - - A -   - - - - - - - - - - - - - - A -   - - - - - - - - - - - - - - A -   - - - - - - - - - - - - - - A -   - - - - - - - - - - - - - A A -   - - - - - - - - - - - - A A A -   - - - - - - - - - A A A A A - -   - - - - - - - - - A A A A - - -   - - - - - - - - - - - - - - - -   - - - - - - - - - - - - - - - -   
- - A A A A A A A A A A A - - -   - - - A A - - - - - - A A - - -   - - - A A - - - - - A A - - - -   - - - A A - - - - - - A A - - -   - - - A A - - - - - - A A - - -   - - - A A - - - - - - A A - - -   - - - - A A - - - - - A A - - -   - - - - A A - - - - - A A - - -   - - - - I A A - - - - A A A A -   - - - - L A A A A A A A A A A -   - - - - E A A A A A A A A A A -   - - - - - A A A A A A A A A A -   - - - - E A A - - - - - A A A -   - - - - E A - - - - - - - A A -   - - - - E - - - - - - - - - A -   - - - E A - - - - - - - - - A -   - - - E A - - - - - - - - - A -   - - E E A - - - - - - - - - A -   - - E E A - - - - - - - - - - A   - - E E A - - - - - - - - - - A   - - E E A - - - - - - - - - - A   - - S A A - - - - - - - - - - A   - - AgA A - - - - - - - - - - A   - - - A A - - - - - - - - - - A   - - - A A - - - - - - - - - - A   - - - - A A - - - - - - - - A -   - - - - A A - - - - - - - - A -   - - - - - A A A A - - - - - - -   - - - - - - A A A - - A A - - -   - - - - - - - - A A A - - - - -   - - - - - - - - - - - - - - - -   
- - A A A A A A A A A A A A A -   - - A - - - - - - - - - - A A -   - - A - - - - - - - - - A - - -   - - A - - - - - - - - - - A A -   - - A - - - - - - - - - - A A -   - - A - - - - - - - - - - A A -   - - A A - - - - - - - - - A A -   - - E E - - - - - - - - - A A -   - - L L - - - - - - - - - - A -   - - I E - - - - - - - - - - A -   - - A E - - - - - - - - - - A -   - - A E E - - - - - - - - - A -   - - - E - - - - - - - - - - A -   - - A E - - - - - - - - - - A -   - - A E - - - - - - - - - - A -   - - A - - - - - - - - - - - - A   - A A - - - - - - - - - - - - A   A A - - - - - - - - - - - - - A   A A - - - - - - - - - - - - - A   A A - - - - - - - - - - - - - A   A A - - - - - - - - - - - - - A   - I - - - - - - - - - - - - - A   - Ag- - - - - - - - - - - - - A   - - A - - - - - - - - - - - - A   - - A - - - - - - - - - - - - A   - - - A - - - - - - - - - - - A   - - - - A - - - - - - - - - A -   - - - - A A - - - - - - - A - -   - - - - - - A - - - - - A A - -   - - - - - - - A A A A A - - - -   - - - - - - - - - - - - - - - -   
- A A A A A A A A A A A A A A -   - A - - - - - A - - - - - - A -   - A - - - - - A - - - - - A A -   - A - - - - - - - - - - - - A -   - A - - - - - - - - - - - - A -   - A - - - - - - - - - - - - A -   - A - - - - - - - - - - - - A -   - E - - - - - - - - - - - - A -   - Ab- - - - - - - - - - - - A -   - A - - - - - - - - - - - - A -   - A - - - - - - - - - - - - A -   A A - - - - - - - - - - - - A -   A A A - - - - - - - - - - - A -   A A - - - - - - - - - - - - - A   A A - - - - - - - - - - - - - A   A A - - - - - - - - - - - - - A   A - - - - - - - - - - - - - - A   A - - - - - - - - - - - - - - A   A - - - - - - - - - - - - - - A   A - - - - - - - - - - - - - - A   A - - - - - - - - - - - - - - A   Ag- - - - - - - - - - - - - - A   - I - - - - - - - - - - - - - A   - A - - - - - - - - - - - - - A   - - A - - - - - - - - - - - - A   - - - A - - - - - - - - - - - A   - - - A - - - - - - - - - - A -   - - - - A - - - - - - - - A - -   - - - - - A A - - - - - - A - -   - - - - - - - A A A A A A - - -   - - - - - - - - - - - - - - - -   
A A A A A A A - A A A A A A A A   A - - - - A A - A - - - - - A -   A - - - - A A - A - - - - - A -   A - - - - A - A - - - - - - A -   A - - - - A - - - - - - - - - A   A - - - - - - - - - - - - - A -   A - - - - - - - - - - - - - - A   I - - - - - - - - - - - - - - A   O - - - - - - - - - - - - - - A   A - - - - - - - - - - - - - - A   A - - - - - - - - - - - - - - A   A - - - - - - - - - - - - - - A   A - - - - - - - - - - - - - - A   A - - - - - - - - - - - - - - A   A - - - - - - - - - - - - - - A   A - - - - - - - - - - - - - - A   A - - - - - - - - - - - - - - A   A - - - - - - - - - - - - - - A   A - - - - - - - - - - - - - - A   A - - - - - - - - - - - - - - A   A - - - - - - - - - - - - - - A   I - - - - - - - - - - - - - - A   I - - - - - - - - - - - - - - A   - A - - - - - - - - - - - - - A   - - A - - - - - - - - - - - - A   - - A - - - - - - - - - - - A A   - - - A - - - - - A - - - - - -   - - - - A - - - - - - - - - - -   - - - - - A - - - - - - - A - -   - - - - - - A - - - - - A - - -   - - - - - - - A A A A A - - - -   
A A A A A - A - - A A A A A A A   A - - - A - A - A A - - - - - A   A - - - A - A - A - - - - - A -   A - - - A - A - A - - - - - - A   A - - - A - A A A - - - - - - A   A - - - - A A A A - - - - - A -   A - - - - - - A A - - - - - A -   E - - - - - - E E - - - - - - A   T - - - - - - T T - - - - - - A   O - - - - - - O O - - - - - - A   I - - - - - - I I - - - - - - A   S - - - - - S S S S - - - - - A   I - - - - - I - - - - - - - - A   S - - - - - - - - - - - - - - A   I - - - - - - - - - - - - - - A   I - - - - - - - - - - - - - - A   S - - - - - - - - - - - - - - A   I - - - - - - - - - - - - - - A   S - - - - - - - - - - - - - - A   I - - - - - - - - - - - - - - A   Ab- - - - - - - - - - - - - - A   Y - - - - - - - - - - - - - - A   E - - - - - - - - - - - - - - A   L - - - - - - - - - - - - - - A   - E - - - - - - - - - - - - - A   - - I - - - - - - - - - - - - A   - - S - - - - - - A - - - - A -   - - - A - - - - - - - - - - A -   - - - - A - - - - - - - - A - -   - - - - - A A A A A - - A - - -   - - - - - - - A A A A A - - - -   
A A A A A A - - - - A A A A A A   A - - - - A - - - - A - - - - A   O - - - - O - - - O - - - - - A   A - - - - A - - - A - - - - - A   Aa- - - - Aa- - - Aa- - - - A -   G - - - - G - - - G - - - - A -   N - - - - - N - - N - - - - - A   N - - - - - N - - N - - - - - A   M - - - - - M - - M - - - - - A   M - - - - - M - - M - - - - - A   N - - - - N N - - N - - - - - A   N - - - - N - - - - A - - - - A   M - - - M M - - - - - - - - - A   M - - - - M - - - - - - - - - A   M - - - - M - - - - - - - - - A   M - - - - - - - - - - - A - - A   Ah- - - - - - - - - - - - - - A   Al- - - - - - - - - - - - - - A   Ah- - - Ah- - - - - - - - - - A   F - - - F - - - - - - - - - - A   Y - - - Y - - - - - - - - A - A   Y - - - - - - - - - - - - A - A   Af- - - - - - - - - - - - - - A   Af- - - - - - - - - - - - - - A   - Af- - - - - - - - - - - - - A   - - Af- - - - - - - - - - - - A   - - I - - - - - - A - - - - A -   - - - Y - - - - - - - - - - A -   - - - - A A A A A A - - - A - -   - - - - - - - - - - A - A - - -   - - - - - - - - - - - A A - - -   
A A A A A - - - - - - A A A A A   A - - - A - - - - - A - - - - A   F - - - F - - - - - A - - - - A   F - - - F - - - - - A - - - - A   Ad- - - Ad- - - - - A - - - A -   Ak- - - Ak- - - - - A - - - A -   C - - - - C - - - - A - - - - A   C - - - - C - - - - A - - - - A   C - - - - C - - - - A A - - - A   C - - - - C - - - - A A - - - A   C - - - C - - - - - A A - - - A   B - - - B - - - - - - A - - - A   C - - C - - - - - - - A - - - A   C - - - C - - - - - - - A - - A   C - - - C - - - - - - - A - - A   C - - - C - - - - - - - A - - A   C - - - C - - - - - - - - - - A   C - - - C - - - - - - - - A - A   B - - B - - - - - - - - - A - A   X - - X - - - - - - - - - A - A   Ac- - - Ac- - - - - - - - A - A   R - - - R - - - - - - - - A - A   Q - - - - - - - - - - - - - - A   R - - - - - - - - - - - - - - A   - R - - - - - - - - - - - - - A   - - R - - - - - - - - - - - - A   - - R - - - - - - A - - - - A -   - - - Y - - - - - - - - - - A -   - - - - A A A A A A A - - A - -   - - - - - - - - - - - A - A - -   - - - - - - - - - - - - A - - -   
A A A A A - - - - - - A A A A A   L - - - L - - - - - - A - - - A   U - - - U - - - - - A - - - - A   U - - - U - - - - - A - - - - A   Aa- - - Aa- - - - - A - - - A -   C - - - C - - - - - A - - - - A   B - - - B - - - - - A - - - - A   B - - - B - - - - - - A - - - A   B - - - B - - - - - - - A - - A   B - - - B - - - - - - - A - - A   B - - B - - - - - - - - A - - A   H - - H - - - - - - - - A - - A   B - - B - - - - - - - - A - - A   B - - B - - - - - - - - A - - A   B - - B - - - - - - - - - A - A   B - - B - - - - - - - - - A - A   D - - D - - - - - - - - - A - A   D - - D - - - - - - - - - A - A   B - - B - - - - - - - - - A - A   X - - X - - - - - - - - - A - A   Ac- - Ac- - - - - - - - - A - A   Q - - - Q - - - - - - - - A - A   Q - - - - - - - - - - - - - - A   R - - - - - - - - - - - - - - A   - R - - - - - - - - - - - - - A   - - R - - - - - - - - - - - - A   - - R - - - - - A A A - - - A -   - - - Y - - - - - - - - - - A -   - - - - AgA A A A A A - - A - -   - - - - - - - - - - - A - A - -   - - - - - - - - - - - - A - - -   
A A A A - - - - - - - A A A A A   T - - T - - - - - - - A - - - A   L - - L - - - - - - A - - - - A   U - - U - - - - - - A - - - - A   J - - J - - - - - - A - - - A -   Ai- - Ai- - - - - - A - - - - A   C - - C - - - - - - A - - - - A   C - - C - - - - - - - A - - - A   B - - B - - - - - - - - A - - A   B - - B - - - - - - - - A - - A   B - B - - - - - - - - - - A - A   B - B - - - - - - - - - - A - A   H - H - - - - - - - - - - A - A   B - B - - - - - - - - - - A - A   D - D - - - - - - - - - - A - A   D - D - - - - - - - - - - A - A   H - H - - - - - - - - - - A - A   H - H - - - - - - - - - - A - A   B - B - - - - - - - - - - A - A   X - - X - - - - - - - - - A - A   Af- - Af- - - - - - - - - A - A   Ac- - - Ac- - - - - - - - - - A   Q - - - Q - - - - - - - - - - A   Q - - - - - - - - - - - - - - A   - Q - - - - - - - - - - - - - A   - - Q - - - - - - - - - - - - A   - - Q - - - - - A - A - - - A -   - - - W - - - A A A - - - - A -   - - - - I A A - - - A - - A - -   - - - - - - - - - - - A - A - -   - - - - - - - - - - - - A - - -   
A A A A - - - - - - - A A A A A   I - - I - - - - - - - A - - - A   L - - L - - - - - - A - - - - A   T - - T - - - - - - A - - - A -   G - - G - - - - - - A - - - A -   Z - - Z - - - - - - A - - - - A   B - - B - - - - - - - A - - - A   B - - B - - - - - - - - A - - A   B - - B - - - - - - - - A - - A   B - - B - - - - - - - - A - - A   B - B - - - - - - - - - - A - A   H - H - - - - - - - - - - A - A   H - H - - - - - - - - - - A - A   B - B - - - - - - - - - - A - A   B - B - - - - - - - - - - A - A   D - D - - - - - - - - - - A - A   D - D - - - - - - - - - - A - A   D - D - - - - - - - - - - A - A   D - D - - - - - - - - - - A - A   X - - X - - - - - - - - - A - A   K - - K - - - - - - - - - A - A   W - - - W - - - - - - - - - - A   W - - - W - - - - - - - - - - A   W - - - - - - - - - - - - - - A   - W - - - - - - - - - - - - - A   - - W - - - - - - - - - - - - A   - - W - - - - A - - A - - - A -   - - - K - - - A - - A - - - A -   - - - - E A A - - - A - - A - -   - - - - - - - - - - - A - A - -   - - - - - - - - - - - - A - - -   
A A A A - - - - - - - A A A A A   I - - I - - - - - - - A - - - A   L - - L - - - - - - - A - - - A   K - - K - - - - - - - A - - A -   C - - C - - - - - - - A - - A -   C - - C - - - - - - - A - - - A   B - - B - - - - - - - A - - - A   B - - B - - - - - - - - A - - A   B - - B - - - - - - - - A - - A   B - - B - - - - - - - - A - - A   D - - D - - - - - - - - - A - A   H - - H - - - - - - - - - A - A   D - - D - - - - - - - - - A - A   D - - D - - - - - - - - - A - A   D - - D - - - - - - - - - A - A   D - - D - - - - - - - - - A - A   D - D - - - - - - - - - - A - A   B - B - - - - - - - - - - A - A   B - B - - - - - - - - - - A - A   C - - C - - - - - - - - - A - A   P - - P - - - - - - - - - A - A   K - - - K - - - - - - - - - - A   K - - - K - - - - - - - - - - A   K - - - - - - - - - - - - - - A   - K - - - - - - - - - - - - - A   - - K - - - A - - - - - - - - A   - - V - - - - - - - A - - - A -   - - - V - - - A - - A - - - A -   - - - - E A A - - - A - - A - -   - - - - - - - - - - - A - A - -   - - - - - - - - - - - - A - - -   
A A A A - - - - - - - A A A A A   E - - E - - - - - - - A - - - A   O - - O - - - - - - - A - - - A   L - - L - - - - - - - A - - A -   C - - C - - - - - - - A - - A -   Aj- - Aj- - - - - - - A - - - A   B - - B - - - - - - - A - - - A   B - - B - - - - - - - - A - - A   D - - D - - - - - - - - A - - A   D - - D - - - - - - - - A - - A   D - - D - - - - - - - - A - - A   H - - H - - - - - - - - A - - A   B - - B - - - - - - - - A - - A   D - - D - - - - - - - - A - - A   D - - D - - - - - - - - A - - A   D - - D - - - - - - - - - - - A   D - D - - - - - - - - - - - - A   D - D - - - - - - - - - - A - A   D - D - - - - - - - - - - A - A   C - - C - - - - - - - - - A - A   F - - F - - - - - - - - - A - A   P - - - P - - - - - - - - - - A   P - - - P - - - - - - - - - - A   P - - - - - - - - - - - - - - A   - P - - - - - - - - - - - - - A   - - P - - - - - - - - - - - - A   - - P - - - - - - - A - - - A -   - - - F - - - A A A - - - - A -   - - - - E A A - - - A - - A - -   - - - - - - - - - - - A - A - -   - - - - - - - - - - - - A - - -   
A A A A A - - - - - - A A A A -   I - - - I - - - - - A - - - - A   Ab- - - Ab- - - - - A - - - - A   V - - - V - - - - - A - - - A -   G - - - G - - - - - A - - - A -   Z - - - Z - - - - - - A - - - A   B - - - B - - - - - - A - - - A   B - - - B - - - - - - A - - - A   B - - - B - - - - - - A - - - A   B - - - B - - - - - - A - - - A   B - - B - - - - - - - A - - - A   H - - H - - - - - - - A - - - A   D - - D - - - - - - - A - - - A   B - - B - - - - - - - - A - - A   B - - B - - - - - - - - - - - A   D - - D - - - - - - - - - - - A   D - - D - - - - - - - - - - - A   D - - D - - - - - - - - - - - A   D - - D - - - - - - - - - A - A   C - - C - - - - - - - - - A - A   J - - J - - - - - - - - - A - A   F - - - F - - - - - - - - A - A   F - - - - - - - - - - - - - - A   F - - - - - - - - - - - - - - A   - F - - - - - - - - - - - - - A   - - F - - - - - - - - - - - - A   - - F - - - - - - A - - - - A -   - - - F - - - - - - - - - - A -   - - - - T A A A A A A - - A - -   - - - - - - - - - - - A - A - -   - - - - - - - - - - - - A - - -   
A A A A A - - - - - A A A A A -   K - - - K - - - - - A - - - - A   Aa- - - Aa- - - - - A - - - - A   M - - - M - - - - - A - - - A -   F - - - F - - - - - A - - - A -   Z - - - Z - - - - - A - - - - A   B - - - B - - - - - A - - - - A   B - - - B - - - - - A - - - - A   B - - - B - - - - - A - - - - A   B - - - B - - - - - A - - - - A   B - - - B - - - - - - A - - - A   D - - - D - - - - - - A - - - A   H - - - H - - - - - - A - - - A   B - - - B - - - - - - - A - - A   B - - - B - - - - - - - - - - A   B - - - B - - - - - - - - - - A   B - - - B - - - - - - - - - - A   D - - - D - - - - - - - - - - A   D - - D - - - - - - - - - - - A   C - - C - - - - - - - - - - - A   G - - - G - - - - - - - - - - A   J - - - J - - - - - - - - - - A   F - - - - - - - - - - - - - - A   J - - - - - - - - - - - - - - A   - J - - - - - - - - - - - - - A   - - J - - - - - - - - - - - - A   - - J - - - - - - A - - - - A -   - - - J - - - - - - - - - - A -   - - - - A A A A A A A - - A - -   - - - - - - - - - - - A - A - -   - - - - - - - - - - - - A - - -   
A A A A A A - - - - A A A A A -   L - - - - L - - - L - - - - - A   F - - - - F - - - F - - - - - A   U - - - - U - - - U - - - - - A   N - - - - N - - - N - - - - A -   C - - - - C - - - C - - - - A -   B - - - - B - - - B - - - - - A   B - - - - B - - - B - - - - - A   Ae- - - - Ae- - - Ae- - - - - A   Ae- - - - AeAe- - - A - - - - A   H - - - - H H - - - A - - - - A   H - - - - H H - - - - A - - - A   B - - - - B B - - - - A - - - A   B - - - - B B - - - - A - - - A   B - - - - B - - - - - - - - - A   B - - - - B - - - - - - - - - A   B - - - - B - - - - - - - - - A   B - - - - - - - - - - - - - - A   D - - - D - - - - - - - - - - A   C - - - C - - - - - - - - - - A   J - - - J - - - - - - - - - - A   F - - - - - - - - - - - - - - A   F - - - - - - - - - - - - - - A   F - - - - - - - - - - - - - - A   - F - - - - - - - - - - - - - A   - - F - - - - - - - - - - - - A   - - F - - - - - - - - - - - A -   - - - J - - - - - - - - - - A -   - - - - A A A A A A - - - A - -   - - - - - - - - - - A - A - - -   - - - - - - - - - - - A A - - -   
- A A A A A A - A A A A A A A -   - O - - - - O - O - - - - - A A   Ab- - - - - Ab- Ab- - - - - A A   J - - - - - J J J - - - - - A -   Ad- - - - - AdAdAd- - - - - A -   G - - - - - G G G - - - - - A -   G - - - - - G G G - - - - - A -   G - - - - - G G G - - - - - A -   G - - - - - G G G - - - - - A -   C - - - - - - C C C - - - - A -   C - - - - - - C C C - - - - - A   C - - - - - - C C A A - - - - A   C - - - - - - C C A A - - - - A   C - - - - - - - - - - - - - - A   C - - - - - - - - - - - - - - A   C - - - - - - - - - - - - - - A   C - - - - - - - - - - - - - - A   B - - - - - - - - - - - - - - A   C - - - - - - - - - - - - - - A   P - - - - - - - - - - - - - - A   V - - - - - - - - - - - - - - A   V - - - - - - - - - - - - - - A   V - - - - - - - - - - - - - - A   V V - - - - - - - - - - - - - A   - - K - - - - - - - - - - - - A   - - K - - - - - - - - - - - - A   - - - K - - - - - - - - - - A -   - - - - A - - - - - - - - - A -   - - - - - A - - - - - - - A - -   - - - - - - A A A A - - A - - -   - - - - - - - A A A A A - - - -   
- A A A A A A A A A A A A A - -   - A - - - - - A - - - - - A - -   - T - - - - - T - - - - - A - -   - K - - - - - - - - - - - - A -   - K - - - - - - - - - - - - A -   - U - - - - - - - - - - - A - -   - Ah- - - - - - - - - - - A - -   - G - - - - - - - - - - - A - -   - G - - - - - - - - - - - A - -   - G - - - - - - - - - - - - A -   - G - - - - - - - - - - - - A -   - G - - - - - - - - - - - - - A   - AiAi- - - - - - - - - - - A -   - Z - - - - - - - - - - - - - A   - C - - - - - - - - - - - - - A   C - - - - - - - - - - - - - - A   C - - - - - - - - - - - - - - A   C - - - - - - - - - - - - - - A   C - - - - - - - - - - - - - - A   C - - - - - - - - - - - - - - A   J - - - - - - - - - - - - - - A   J - - - - - - - - - - - - - - A   F - - - - - - - - - - - - - - A   - F - - - - - - - - - - - - - A   - - F - - - - - - - - - - - - A   - - - F - - - - - - - - - - - A   - - - O - - - - - - - - - - A -   - - - - A - - - - - - - - A - -   - - - - - A A - - - - - - A - -   - - - - - - - A A A A A A - - -   - - - - - - - - - - - - - - - -   
- - A A A A A A A A A A A A - -   - - A - - - - - - - - - - A - -   - - A - - - - - - - - - A - - -   - - A - - - - - - - - - - A - -   - - A - - - - - - - - - - A - -   - - A - - - - - - - - - - A - -   - - A A - - - - - - - - - A - -   - - A A - - - - - - - - - A - -   - - A A - - - - - - - - - A - -   - - A A - - - - - - - - - - A -   - - A A - - - - - - - - - - A -   - - A A A - - - - - - - - - A -   - - - A - - - - - - - - - - A -   - - A A - - - - - - - - - - A -   - A A - - - - - - - - - - - A -   - A A - - - - - - - - - - - - A   - A A - - - - - - - - - - - - A   - A - - - - - - - - - - - - - A   - A - - - - - - - - - - - - - A   - A - - - - - - - - - - - - - A   - A - - - - - - - - - - - - - A   - A - - - - - - - - - - - - - A   - A - - - - - - - - - - - - - A   - - A - - - - - - - - - - - - A   - - A - - - - - - - - - - - - A   - - - A - - - - - - - - - - - A   - - - - - - - - - - - - - - A -   - - - - A A - - - - - - - A - -   - - - - - - A - - - - - A A - -   - - - - - - - A A A A A - - - -   - - - - - - - - - - - - - - - -   
- - A A A A A A A A A A A - - -   - - - A A - - - - - - A A - - -   - - - A A - - - - - A A - - - -   - - - A A - - - - - - A A - - -   - - - A A - - - - - - A A - - -   - - - A A - - - - - - A A - - -   - - - - A A - - - - - A A - - -   - - - - A A - - - - - A A - - -   - - - - A A A - - - - A A A - -   - - - - A A A A A A A A A A - -   - - - - A A A A A A A A A A - -   - - - - - A A A A A A A A A - -   - - - - A A A A A A A A A A - -   - - - - A A - - - - - - - - - -   - - - A A - - - - - - - - - - -   - - - A A - - - - - - - - - A -   - - - A A - - - - - - - - - A -   - - A A A - - - - - - - - - A -   - - A A - - - - - - - - - - - A   - - A A - - - - - - - - - - - A   - - A A - - - - - - - - - - - A   - - A A - - - - - - - - - - - A   - - A A - - - - - - - - - - - A   - - - A - - - - - - - - - - - A   - - - A A - - - - - - - - - - A   - - - - A A - - - - - - - - A -   - - - - A A - - - - - - - - A -   - - - - - A A A - - - - - A - -   - - - - - - A A A A A A A - - -   - - - - - - - - A A A - - - - -   - - - - - - - - - - - - - - - -   
- - - - A A A A A A A - - - - -   - - - - - A A A A A A - - - - -   - - - - - A A A A A - - - - - -   - - - - - A A A A A A - - - - -   - - - - - A A A A A A - - - - -   - - - - - A A A A A A - - - - -   - - - - - - A A A A A - - - - -   - - - - - - A A A A A - - - - -   - - - - - - - A A A A - - - - -   - - - - - - - - - - - - - - - -   - - - - - - - - - - - - - - - -   - - - - - - - - - - - - - - - -   - - - - - - - - - - - - - - - -   - - - - - - - - - - - - - - - -   - - - - - A - - - - - - - - - -   - - - - - A - - - - - - - - - -   - - - - - A - - - - - - - - - -   - - - - - - - - - - - - - - - -   - - - - - - - - - - - - - - A -   - - - - - - - - - - - - - - A -   - - - - - - - - - - - - - - A -   - - - - - - - - - - - - - - A -   - - - - - - - - - - - - - - A -   - - - - - - - - - - - - - - A -   - - - - - - - - - - - - - - A -   - - - - - - - - - - - - - - A -   - - - - - - - - - - - - - - A -   - - - - - - - - - - - A A A - -   - - - - - - - - - - - A A - - -   - - - - - - - - - - - - - - - -   - - - - - - - - - - - - - - - -   
