model
size = 15 32 21, scale = 0.05, origin = -y
material 
  colors = A:#BBB B:#DDD C:#000 D:#AAA E:#999 F:#444 G:#666 H:#888 I:#333 J:#555 K:#111 L:#222 M:#CCC N:#010 O:#100
voxels
3-A4BA6B3-2(B5A)3-A2(B4A)B4-2B2A3B2A6-2A2B5A6-2AB3AB2A6-B4A2BAB6-2A3B2ABA6-6AB2A8-2B3A9-A3BABA8-B4A2B54-3B3AB7-B3A4-A6-AB6-A5-AB7-A5-A8-B4-A9-A3-2BA8-2B2-BAB8-BA2-ABA8-2B3-BA7-AB4-AB7-2A5-A7-B6-2A5-BA6-A2B3A3B7-2BABA2B35-5A2B3A3B2-2B5ABA4B2-3B3ABA2B3A2-A2B2A4BA3B2-2(BA)B8A2-2A2BA3BA2BAB2-3B2(3A2B)2-2B3A2BA3B2A2-2(A2B)ABA2BAB3-2A3BA2B3AB3-B5A2B2(AB)3-B3AB2A3BAB2-D3(BA)5BA2-DB2ABA2B5A2-B2A3(BA)4B2-6B2ABAB2A2-B3AB2A4-2A2-ABA2B6-2A-A3BA7-BA-2B2A8-BA-2(BA)8-2A-3BA8-2B-A3B8-2A-BA2B8-BA2-BAB8-BA2-B2A7-BAB3-B2A6-BA4-A2B6-2B5-2(BA)B2-2A7-2(BA)3B34-2(AB)5A2BA2B-BAB3A2B3ABAB-ABA2BAB2ABAB2A-2(2AB)3A2B3A-BA2BA2(B2A)2BA-A3B3AB2A2B2A-2(BA)B2A3BA2BA-AB3A2B2A2BA2B-2BABA3B4ABA2-2BAB4A2BABA2-4ABA2BAB3A-2(2BA)3B4AB-2A3BAB2ABA2BA-2A2BAB2AB5A-2A3BA2B5AB-2A2BAB2A3(BA)2-AB2(A2B)A4B2-BA3B4-2A2B-AB3A6-ABA-2ABA7-3B-2ABA8-2A-2D2A9-B-2E2A9-B-2DBA9-A-2E2B8-AB2-D2A8-2A2-E2A7-2BA3-2BA6-2B5-AB2AB3-A7-4BA2B9-5B20-B2A10-A-BA2(11-B-AB)A9-2A-B2A9-2B-B2A9-BA-A2B9-2B-2AB9-BA-2BA9-2B-2(AB)A5-2(AB)-B2AB7-B2A-2(BA)7-A2B-ABA3BAB2(A2B)-A2BA5B2ABAB-2DB6A3B2A-2E3B5-2A2B-2EBA-2A4-3B-2H2AB6-BAB-2DA-A7-2A-2GBA8-2B-2J-A9-A-F-A10-B-I-B10-A-J-B10-B-2GB10-B-2DBA9-A2-HBA8-2B2-EAB8-A4-A2B2-B3-B6-3A2(BA)B9-3BAB19-BAB11-2BA2(12-3A)12-3B12-BAB2(12-B2A)12-BAB12-2ABA11-3AB11-B3M11-B2M2(12-3A)12-B2E12-B3G11-A3I2-A8-A2K3-B8-B2K2-A9-A2K2-B9-B2K-B10-B2G-B10-A-D-A10-A-G-B10-B-2FA10-B2-DA10-A2-ABA8-A4-A2B2-A3-A6-4A3-B9-5A19-AB12-3(BA13-)2B2(13-2A)13-BA13-AB13-A2B12-B2A12-BD13-BH13-BD13-BF13-AI13-A2K12-B2C12-B2(C13-A)K3-B9-BK2-B10-BD2-A10-A-K-B10-A-C-B10-B-K-B10-A2-IA10-B2-D-A9-B3-B-A2-A4-A5-2BAB3-2B8-BA3B19-B2(13-BA)13-2A13-BA13-2A13-AB13-BA2(13-2A)13-AB13-AD13-AE13-BG13-AF13-BK2(13-AC)13-AK2(13-BI)3-B9-AL2-B10-BE2-B10-AC-CA10-B-2CB10-B-C-B10-A2-C8-B2-A2-GA6-A3-B3-2A4-B3-A5-A2BAB3-B7-A5-B9-2B2AB4-A13-BA2(13-2B)2(13-BA)2(13-AB)13-BA13-2B13-AG13-AF13-BL13-BN2(13-AC)13-BC13-A2(F13-B)H13-AH3-A9-AI2-B10-BD2-A10-BC2-B10-A3CB10-B-C-A10-A-2C8-2(A2-)JB6-A2(3-B)A4-A3-B5-2A2-A3-A7-BA2B-BA9-2B2(AB)3-A13-AB2(13-BA)13-2A3(13-BA)13-AB13-BA13-BD13-BF13-AI13-BN13-AC13-BC13-AC13-BJ13-BD13-AG13-BD3-B9-BH2-B10-BD2-B10-AF2-A10-AC2-B10-B-C-B10-B-2C8-2(A2-)HB6-A3-B2-M-A9-B3-2BA7-A12-AB13-BA2-B2(13-BA)13-2B13-2A13-BA13-BE13-AH13-BD13-BJ13-AI13-BK2(13-BC)3(13-AC)13-AG13-AD13-BH13-AD3-A9-AC2-B10-AL2-A10-BG2-B10-AF2-A10-A-J-B10-B-2I8-2(A2-)E8-A2-B2-AB10-B3-2A8-A12-BA13-AB2-A13-AB13-2B2(13-BA)13-AB13-BJ2(13-BF)13-AI13-BK13-AO13-BC13-A2(C13-B)C13-AC13-BJ13-BH13-B2(D13-A)F13-2(BC2-B10-)AG2-A10-B-D-B10-B-2J11-A2-D8-2(B2-)AB10-A3-AB8-A12-2A13-2B2-B13-2A13-AB13-BA2(13-AB)13-BE13-AE13-BH13-BJ13-AI13-BK13-AN2(13-BC)13-AC13-BC13-AI13-AG13-BH13-AD13-BC13-AC2-A10-BG2-B10-AL2-A10-B-F-A10-B-2K11-A2-E8-2(A2-)MA10-A3-2B8-A12-2A13-AB2-A13-2B13-AB13-2B13-BA13-AB13-BA13-2B13-BD13-AG13-AJ13-BF13-BL13-AO2(13-BC)13-AC13-BF13-AG13-BG13-AE13-BH13-AF2-B10-AF2-A10-AL-LB10-B-C-A10-B-2C11-A2-LB10-B2-M-A9-A3-B2A7-A12-2B13-2A2-A13-2A13-BA3(13-AB)2(13-2A)13-AG13-BJ13-AL13-AO13-A2(C13-B)3(C13-A)C13-BJ13-AF13-BH13-BG13-BJ2-A10-BG2-B10-A2C-A10-A-C-B10-B-2C11-A2-LA6-B3-A3-2A4-A3-B5-2A2-B3-B7-2AB3-B9-BA2BAB3-B13-2A13-2B13-2A13-AB13-BA13-AB13-2B2(13-BA)13-AM13-BA13-AD13-AH13-AG13-AF13-AL13-BK13-BC13-AI13-AF3-B9-BF2-B10-BF2-A10-AG2-B10-B-2CA10-A-C-A10-B2-C8-2(A2-)GA6-A3-B3-AB4-A3-B5-2A3B3-B7-A5-A9-A2BAB4-2B12-AB13-2B13-2A4(13-2B)13-2A13-A2B12-B2A12-2A13-A2(D13-B)E13-BD13-B2J4-BA6-B2I3-B2-B5-AC4-A8-A2(C3-B9-B)J2-A10-AF2-B10-A-J-B10-B-I-A10-B-L-A10-A2-LA10-A2-E-B9-B3-A-B2-B4-B5-A3B3-2B8-2A2BA19-2AB11-2(A2B12-)B2A12-2BA12-3A12-BAB12-ABA12-2AB12-4B11-2ABA11-4B11-2(B2A12-)A2D12-B2D12-A3E3-2B6-A3E2(2-A)5-A2D3-A8-A2J2-B9-A2F2-A9-B2F-B10-B2I-B10-A-I-A10-A-D-A10-B-2H11-B2-HA10-A2-EBA8-2B3-3B2-B3-2A5-3AB3-2A8-2ABAB19-2ABA10-B2AB11-2(BA)11-BA2BA8-2BABA2B8-2(AB)3A8-3BA2BA8-2ABA3B8-2B2(AB)A7-2(2A3B)5-2B2(AB)2AB7-2(AB)2A2B7-A2BAB3A2B9A3(BA)9BA3B5A4BA3D2AB5-2A2B5A-2A4-B6ABA2-A3-7A-A7-5A2B8-AB3D-B9-B2D-A10-A-E-A10-B-H-B10-A-2HB10-B-2HAB9-B2-HB9-2A2-H2A8-2A3-A2B2-B3-2B5-B5ABAB8-A2B2A20-4(AB)3A2BA-ABA5B2A4B-B5A6B2A-2ABA2B2A2BA3B-A2BAB2(A2B)2AB-ABA2B3AB2A2BA-5ABAB2ABA2B-ABA2BA6B2A-4BAB3ABAB2A2-2ABA5B2A2B2-3BA4BA2B2A-2AB3A2B3(AB)-A2B2ABA3BA2BA-2A3BABA6B-2B2AB3A3BABA-2E5AB2ABA2B2-E2B4A6B2-DA2B3A2-B3A-2DA3B5-ABA-2D2BA6-3A-2D3B7-2A2(-2DBA9-B)-2E2B9-A-2EAB8-2A2-E2A8-2B2-EBA7-2AB3-3B6-BA5-2BABA3-B7-2B2ABAB9-2B3A21-3A3BA3B3A2-3BA2BA5BA2-B2AB3A3B2AB2-3B2(2AB)A3B2-A4B5ABAB2-B3A2BA3BA2B2-BA2BA3B4AB2-2(BA)B5AB2A2-BAB10A3-B2A4B2A3B3-3B3AB3A2B3-A4B4AB2A2-2(BA)B3A4BA2-2BABA3B2ABAB2-A2BA3B4A2B2-B2A6BA2BA2-5B2ABA2B2A2-B4ABA2-B2AB-3(AB)4-A2BA-2A3B6-BAB-B4A7-AB-A3B2(8-BA-BA2B)8-2B2-3A8-2B2-ABA7-ABA3-A2B6-2A4-ABA6-AB5-AB3A2-2A7-2(AB)A2B36-B2ABAB4A2B3-7A3BAB3-2(2B2ABA)4-2(2BA)2B7-2AB4AB7-3B2A2BA7-3A4BA7-BA5BA7-B3A3B10-4BA9-2BABA2B8-7A54-AB2AB9-A2BA3B8-ABA3-A7-3B4-AB6-2A6-2(B7-)2(A5-A8-)B5-A8-B5-A7-AB5-2A6-AB5-A2(B6-)2B6-B6-2A5-2A7-3BAB2A33-
