model
size = 29 32 15, scale = 0.05, origin = -y
material 
  colors = A:#010 B:#001 C:#FF3 D:#C0C E:#3C0 F:#69F G:#C96 H:#9FC I:#00D J:#900 K:#3CC L:#F39 M:#306 N:#C33 O:#969 P:#6CF
voxels
9-10(11A18-)3A5B3A18-3ABIHDB3A18-2ABIFBFGB2A18-ABLH3BOGBA18-ABF5BGBA18-AB7CBA18-BC7BCB18-BK7CFB18-BM2BKMK2BJB18-2B2CBEB2C2B18-BI2BELJ2BNB18-B3D2EJNHPB18-11B19-9B20-9B221-2A9-2A8(16-A11-A)17-A9-A18-A9-A17-4(A11-A16-)A11-A17-A9-A18-A9-A16-3(2A11-2A14-)2(AB11-BA14-)3A9-3A15-2A9-2A17-2A7B2A20-7A163-2A11-2A8(14-A13-A)15-2(A11-A16-)A11-A15-4(A13-A14-)2(2A11-2A14-)2(A13-A14-)2(A13-)2(A15-A12-)A15-2(A13-)A14-2A11-2A15-13A17-11A21-5A105-2A13-2A2(12-A15-A)2(13-A)16(14-A13-A)11-3A15-3A3(8-2A-15A-2A)9-19A11-A-13A-A13-3A9-3A14-2A-3A3-3A-2A16-2(3A-)3A21-5A76-8(A15-A12-)A15-2(A13-)8(A14-A13-)A13-A15-A8-25A4-2A3-15A3-2A5-3(A2-A15-A2-A6-)4A15-4A6-5A13-5A7-4A13-4A2(9-5A)11-3A-3A3-3A-3A15-11A73-8(A15-A12-)A15-3(A13-)A15-A12-A15-2(A13-)3(A14-A13-)A13-A15-A12-17A7-5A-15A-5A3(2-6A15-6A)3-2(4A17-4A4-)3A19-3A4-A-A19-A-A5-3A17-3A6-4A15-4A7-2A-3A9-3A-2A10-7A3-7A16-2A5-2A45-2(11(A15-A12-)A15-2(A13-)2(A14-A13-)A13-A15-A12-17A12-A15-A7-A3-2A15-2A3-A-2A4-A15-A4-4A4-A15-A4-2A-2A3-A15-A3-2(2A2-2A23-)2A3-A23-A2(4-2A21-2A)5-2A19-2A6-4A15-4A8-6A7-6A13-2A-A5-A-2A18-2A5-2A16-)11(A15-A12-)A15-2(A13-)2(A14-A13-)A13-A15-A12-A15-A13-15A9-3A2-15A2-3A2-A-5A15-5A-2A-5A15-5A2(-A)-4A15-4A2(-A2-A-3A17-3A)-A3-3A19-3A4-A-A19-A-A4-A-2A17-2A-A5-A-2A15-2A-A6-2A2-3A9-3A2-2A8-3A2-2A5-2A2-3A13-2A7-A-2A18-2A5-2A16-11(A15-A12-)A15-2(A13-)2(A14-A13-)A13-A15-A12-A15-A64-A6-15A6-2A6-15A6-A-2(A4-A15-A4-A2-)A4-A15-A4-A3-A2-2A15-2A2-A4-A2-3A13-3A2-A4-A3-2A13-2A3-A5-A3-3A9-3A3-A6-3(2A5-)2A8-2(3A13-)2A9-2A18-2A5-2A16-11(A15-A12-)A15-2(A13-)2(A14-A13-)A13-A15-A12-A15-A64-A27-2A27-A-2(A5-15A5-A2-)A5-15A5-A3-A4-15A2(4-A)5-13A5-A4-A5-2A9-2A2(5-A)6-2A4-3A6-A6-2A19-2A8-2(3A13-)2A7-A-2A18-2A5-2A16-7(A15-A12-)A15-A13-A14-3(A13-)A15-A12-A15-2(A13-)3(A14-A13-)A13-A15-A12-A15-A7-5A17-5A2(2-A25-A)2-2A23-2A3-3(A23-A4-)A23-A5-A6-9A6-A6-2A8-3A8-2A7-2A17-2A10-4A9-4A16-2A-6A21-7A17-2(A15-A12-)A15-6(A13-A14-)2(A13-)8(A14-A13-)A13-A15-A8-5A15-5A4-2A21-2A5-3(A21-A6-)2A19-2A6-3A17-3A7-3A15-3A9-2A15-2A2(11-3A)15-3A5-3A21-5A24-5A18-2(A15-A12-)A15-2(A13-)16(A14-A13-)A11-3A15-3A3(8-2A17-2A)9-2A15-2A11-A15-2(A13-)A14-2A11-2A16-3A5-3A21-5A76-2(17A12-)17A13-17(15A14-)15A13-2(17A12-)17A13-15A14-15A15-13A17-11A21-5A99-
