model
size = 15 32 32, scale = 0.05, origin = -y
material 
  colors = A:#47D9D9 B:#23D2D2 C:#000 D:#CCC E:#996 F:#200 G:#400 H:#630 I:#963 J:#B3B3B3 K:#002 L:#633 M:#036 N:#666 O:#777 P:#003 Q:#100 R:#005 S:#00606F T:#330 U:#966 V:#FFF W:#969696 X:#663 Y:#555 Z:#069 Aa:#222 Ab:#797979 Ac:#999 Ad:#5C5C5C Ae:#F99 Af:#DDD Ag:#960 Ah:#333
voxels
291-4AB10-AB3A444-2AB4A8-3A2B2A8-5ABA8-3A2B2A9-3ABA10-AB3A399-7A7-A2B6A6-BA2B2ABAB7-5A2B8-4ABAB8-AB5A8-2AB4A8-5ABA9-AB2AB354-7A7-AB3A2-2A6-2AB2A2-2A6-9A6-2AB3A3B6-2AB3AB2A6-2(3AB)A6-2AB3AB2A7-5ABA8-B6A9-2B3A324-S5-A7-2A2-A3-A5-ABA2-A3-2A4-2(2AB)2-A2B4-4ABA2-ABA4-6A2-ABA5-2AB5AB6-7ABA6-5AB3A7-7A8-5A2B323-2AB3-A7-AB2-B3-A5-3(3A2-A3-2A4-)BAB2-B3-AB4-3A2-2A2-AB5-2(B2A)2-A6-3A2B2-BA6-B2A2B2ABA7-BA2B3A9-BAB2A37-6A2B4A3-2(BA)B5ABA3-4B2ABAB2AB4-4AB3A7-3AB4A7-2(2AB)AB7-7AB7-4AB3A7-2ABA3B10-4AB9-5ABA8-2AB3AB54-B4A9-3AB3A8-3A3-A7-2ABA3-2A6-AB3A3-A5-A-3AB4-B3-AB6A3-AB2-3BA2-2A3-2A2-2A2B2-2(2A3-)3A2(2-AB)4-3A2(2-2A)5-BA2-AB2-A6-5A2-AB6-5AB3A7-B3ABAB35-3ABAB7A2-2A2B9A2-A2B6A2B2A2-SAS2AB2A2B3A2-A3M6AB2A2-RA2RB2AB3A2B2-A3R5AB3A2-A3KAB7A2-A3C2B7A3-2C5AB4A3-3C2AB6A3-CAC9A2-2C3ABAB5A2-3V10A2-2V2ABA2B3A2B2-2C3AM7A2-2CAC2A4BABA2-2CACABA2-B3A-5CA2B2-4A-5C2ABA2-B2A-5CB2AB3-BA-5C2B2AB2-BA-5P2-B2A2-2A-3ABA2-3A2-BA2-3A4-BA2(2-2A)B4-A2-A2B3-2AB2(2-BA)4-A2B2(2-2A)5-B4A2-2B7-B3ABAB34-4A2BAB5AB-3B2(4AB)A-A3C4ABA2B2A-A3C2AB6AB-A3C3AB6A-4C2AB3A2B2A-4CA2BAB2A2BA-4C2AB7A-5C5A3BA2(2-4CB8A)-5C2BA2(B2A)-5C5AB2AB-5F4A2B3A-5C2B2AB4A-5C3A2B3AB2-4CA2B6A2-4CABA2-B3A-5CABA3-3A-5C4A2-3A-5C4A3-BA-5C2(AB)A3-B-4C4-AB3-A-4C4-2A3-A-4C4-AB2-2A2-ABA4-AB2-2B2-B2A4-2A-B2A3-3A2(2-2A)5-5A3-A7-2(2AB)A9-4AB19-2ABA10-3AB11-2A2C11-A4C8-3A4I8-ABA4E8-3A4C8-B2A4C8-ABA4C7-2ABA5CB5-3AB5C7-B2A5C7-2BA6HA2B6A6C9A6CAB2A3B2A6C5-4A5C-BA4-3A6C2-A3-3B4C-C2-A4-BA5C4-A3-2A3C-C4-B4-A2C-C6-A3-A2(-D)6-A3-B2(-D)6-A3-A-3J6-A3-A-4C4-2A3-A2-3Z4-2(AB2-)3A4-A3-AB3-2AB2-B3-2A5-7ABA8-B4A19-3A11-ABA12-A2C12-A2E12-B2E12-A2L12-B3(2C12-A)3C2(11-A3F)11-B2(2C12-A)2T12-A2C12-B3C3-2A6-A3C2-C2-A5-A2C3-C2-A5-B2C2-C2(4-A)2C2-C4-B4-A2C-C6-A3-B2J-J2(6-A3-A2(-D))6-B3-A-3J6-A3-B2-2C6-A3-B2-3A4-A3-2A3-3A2-B3-2A5-2ABA3-2A8-5A19-2A12-2A13-AC13-AH13-AC13-AF2(13-AC)13-AG13-2(A2E12-)AC13-AU13-AE13-BE13-AT13-A2C4-2A6-A2U3-A2-A5-AC4-C2-A5-AC3-C4-A4-BC3-C4-B4-AC2-C6-A3-AN2-N3(6-A3-B2(-D))6-B3-A2-2N6-A3-B2-K-K2(4-A)3-A-A2-A4-A5-3AB3-BA8-5A19-A13-2A13-B5(C13-A)C13-B3(E13-A)C2(13-AE)13-BX13-AO13-AC5-2A6-AT2(4-B2-A5-AC)3-C4-A4-BC3-C2(4-B)2(C2-C6-A3-A)D2-D6-A3-A-3D6-B3-B2(-D)6-A3-A2-D8-2(A2-)2C6-B3-A3-2P4-A3-B5-2A2BA3-A7-A5-B9-5A4-B13-2A13-AC2(13-AQ)13-AC13-BAg13-AC3(13-AE)13-BC13-AI13-BE3(13-AC)5-2A6-BQ4-A2-A5-AC4-A2-B5-AC3-C4-B4-AC3-C2(4-A)C2-C6-A3-AC2-C6-B3-BD2-D6-B3-A2D-D6-A3-A2(-D)6-A3-A-2D8-2(A2-)2C6-B3-A3-2C4-A3-A5-2A2-B3-A7-ABA3-A9-5AB3-A13-2A13-BW13-AF13-AE13-AQ13-AC13-AF13-AH13-AF13-BX13-BU13-AC13-BE13-BW13-AAa13-AC5-2A6-AL4-A2-A5-AC4-B2-A5-BC3-C2(4-A)C3-C4-A4-B2(C2-C6-A3-A)D2-D6-A3-AD-2D6-B3-A2(-D)6-A3-A-2D8-2(A2-)2W10-A2-C-C9-A3-3A7-A12-2A13-2A2-A13-2A13-BA13-2A3(13-AC)13-BI13-AQ13-BAe13-AG13-BE13-AL3(13-AC)13-AF5-2A6-BE4-B2-A5-AC4-A2-A5-AC3-C2(4-A)C3-C4-A4-B2(C2-C6-A3-A)O2-O6-A3-BD2-D6-A3-A2(-D)6-A3-B-2D8-B2-A2-D8-2(A2-)2C10-B3-AB8-A12-BA13-2A2-A13-2A13-2B13-AY13-AG13-B2(C13-A)E13-AG13-AI13-AG13-BU2(13-AE)13-AL13-AC13-AG5-2A6-AE4-B2-A5-AC4-A2-A5-AC3-C4-A4-BC3-C2(4-A)C2-C6-B3-BC2-C6-A3-AN2-N6-A3-AD2-D6-A3-A2(-D)6-A3-B-2D8-A2-B2-D8-B2-A2-2C10-B3-2B8-B12-2A13-2A2-A2(13-2A)13-B3(C13-A)Aa13-BE13-AG13-AI13-BG13-AT13-AH13-AF2(13-AC)13-AG5-BA6-BE2(4-A2-A5-AC)3-C4-A4-BC3-C2(4-A)C2-C6-A3-AC2-C6-A3-BN2-N6-A3-AD2-D6-A3-A2(-D)6-B3-A-2D8-B2-A2-D8-2(A2-)2C10-A3-2A8-B12-2B13-AB2-B3(13-2A)2(13-BC)13-AC13-AI13-AQ13-AI13-AG13-BE13-AG2(13-BC)2(13-AC)5-AB6-AE2(4-A2-A5-AC)3-C2(4-A)C3-C2(4-B)2(C2-C6-A3-A)O2-O6-B3-AD2-D6-A3-A2(-D)6-A3-A-2D8-2(A2-)2D6-B3-B2-C-C9-A3-A2B7-A12-2A13-2A2-A13-BA13-AAf13-AAd13-AT2(13-AC)13-AQ13-AL13-BF13-AX13-BI13-AC2(13-BE)13-AAh13-AC5-BA6-AG2(4-A2-A5-AC)3-C4-A4-BC3-C2(4-A)C2-C6-A3-AC2-C6-A3-BAb2-Ab6-A3-B4D6-A3-A2(-D)6-A3-A-2D8-2(A2-)2D6-2(A3-)2C4-B3-A5-BA2-A3-B7-4A-2A9-4ABA3-A13-2A13-AO13-AC13-BL13-AC13-AH13-AC13-A2(E13-B)E13-AC13-AU13-BE13-B2(C13-A)C5-2A6-AF4-A2-A5-AC4-A2-A5-B2(C3-C2(4-A))C2-C6-A3-AC2-C6-B3-AY-2Y6-B3-A-3D6-A3-B2(-D)6-B3-A2-D8-A2-B2-2Ac6-B3-A3-2C4-A3-A5-5A3-B7-A5-A9-2(AB)A4-2A12-2A13-AB13-BAd13-B2(G13-A)2(C13-A)E13-B2(2E12-A)C2(13-BE)13-AX13-BO13-A2C4-2A6-A2H3-B2-A5-AC4-B2-A5-AC3-C2(4-A)C3-C4-B4-AC2-C6-A3-BC2-C6-B3-A2(-C)6-B3-A2(-D)6-B3-B2(-D)6-B3-A2-2J6-A3-A2-C-C4-A4-B3-A-B2-B4-A5-3AB3-2A8-A3BA19-2AB11-3B12-A2H12-B5(2C12-A)2F12-2(A3E11-)A3C11-A2I12-B2(2E12-A)2G12-A3C3-BA6-A3E2-B2-A5-B2C3-A2-A5-A2(2C2-C2(4-A))2C-C6-B3-A2C-C2(6-A3-B2(-C))6-A3-A-3C6-B3-A2-2C6-B3-A2-3S4-B3-A4-3A2-A3-B6-2(AB)3-A9-2ABAB19-AB2A10-AB2A11-A3C11-B4C9-AB4C9-2A4C9-BA4C9-2B2(4C9-2A)4C2A5-4A4CA7-3A4FB7-3A4C2AB3AB4A4CAB2AB5AB4C2A5B4A4C2A5-2ABA4CA-AB4-ABA4CBA2-A3-2AB4C-A2-A4-2A4CB4-A3-BA3C-C2(4-A)2C-C6-B2(3-A2(-C)6-A)3-A-3C6-A3-B-4C4-AB3-A2-3M4-2(AB2-)B2A4-A3-A4-A2B2-A3-A6-5AB2A9-2B2AB20-B10AB2A-AB2AB5A2BAB-3C3AB6AB-3C5ABA2B2A-3CB2AB5ABA-3C2(AB)2A2B2AB-3CA2BAB6A-3CAB7ABA-3C2(AB)7A2-2CB2AB3A2B2A2-2CAB3ABAB3A-3C2A2(B3A)B-3L11A-3F4ABAB4A-3C4AB2AB2MB-3C2(4AB)A2-2C8A3B2-2C2B3A2-2ABA-3C2AB2A3-B2A-3C6A2-3A-3C2A2(BA)3-AB-3CBAB2ABA3-A-3CB4-BA3-A-3CA4-2A3-A-4C4-BA2-2A2-3K4-2(2A2-)2AB4-2A-3A3-3A2-AB2-BA5-5A3-B7-7A9-BA3B21-5A2B3A2BA2-BAB6AB3A2-2C2B3A2(B2A)2-2CA2B2A4B2A2-2CB6AB3A2-2C11A2-2CB6A2(BA)2-2C5A2B4A2-2C7AB3A3-C11A3-C5ABAB3A3-C2AB8A2-E3AB2A2B4A2-7AB3A2B2-3AB4A2B3A2-2C2AB6ABA2-2CB2(A2B)4A2-2CAB3A2-A2BA-3C3ABA2-4A-3C2A2(BA)2-3A-3C2A2B2A3-2A-3C2(AB)3A2-BA-3CAB2-2BA2-AB-3C2A2-3A2-2A2-2KA4-2(AB2-)A2B4-A2-2BA3-3A2-2A2-AB4-B2(2A2-)BA5-2(AB)A2-2A7-AB4AB36-B11A3-3AB2AB5A3-4AB7A4-4A2B2AB6-5AB3A6-7A2B2(6-9A)6-5A2B2A8-2AB2A9-AB3ABA8-7A54-AB2AB9-5ABA8-3A3-A7-AB2A3-BA6-5A3-A5-C-2(BA)4-A3-2C6A3-2A2-AC2B2-2A3-2A2-4A2-2A3-BA3-B2A2(2-BA)4-B2A2-2B2-BA5-2(2A2-)A6-2B2AB2-2B6-2A2BAB3A7-B5AB308-3A3-B7-BA2-A3-A5-2(3A2-A3-2A4-)2AB2-A3-AB4-3A2-B3-2A4-3A2(2-2A)5-4ABA2-A6-4AB2-2A6-3A3(BA)7-AB4AB9-ABA2B309-A5-A7-AB2-B3-A5-ABA2-A3-AB4-AB4A2-3A4-2A3BA2-3A4-4ABA2-3A5-2(BA)B4A6-2BA2(B2A)6-A2B2AB3A7-A2B2(AB)8-B6A323-3AB3A7-B2ABA2-2A6-BAB2A2-BA6-AB4ABAB6-B4AB2AB6-9A6-3B6A6-BA2B2(AB)A7-5A2B8-2B2A2BA9-5A324-7A7-3(AB)3A6-9A7-3ABA2B8-AB5A8-2A2B3A8-5A2B8-ABA2BAB9-3ABA354-2(AB)3A8-A2B2ABA8-7A8-2B3A2B9-5A10-4AB124-
