model
size = 24 27 29, scale = 0.05, origin = -y
material 
  colors = A:#F00 B:#000 C:#DE2400 D:#BE4800 E:#DA0107 F:#920316 G:#9E6D00 H:#B6020F I:#6E041E J:#7D9100 K:#BBB L:#4A0525 M:#020835 N:#EEE O:#3DDA00 P:#5DB600 Q:#119613 R:#1DFF00 S:#26062D T:#052C2B
voxels
-----------KKK---------- -----------AAA---------- -----------AAA---------- -----------AAA---------- -----------AAA---------- -----------AAA---------- -----------CCC---------- -----------CCC---------- -----------DDD---------- -----------DDD---------- -----------DDD---------- -----------DDD---------- -----------DDD---------- -----------DDD---------- -----------DDD---------- -----------DDD---------- -----------DDD---------- -----------GGG---------- -----------GGG---------- -----------GGG---------- -----------GGG-GG------- -----------GGG-GG------- -----------JJJ-JJ------- -----------JJJ---------- -----------BBB-BB------- -----------BBB-BB------- -----------BBB---------- 
-----------KKK---------- -----------AAA---------- -----------AAA---------- -----------AAA---------- -----------AAA---------- -----------AAA---------- -----------CCC---------- -----------CCC---------- -----------CCC---------- -----------DDD---------- -----------DDD---------- -----------DDD---------- -----------DDD---------- -----------DDD---------- -----------DDD---------- -----------DDD---------- -----------DDD---------- -----------DDD---------- -----------GGG---------- -----------GGG---------- -----------GGG-GG------- -----------GGG-GG------- -----------JJJ-JJ------- -----------JJJ---------- -----------BBB-BB------- -----------BBB-BB------- -----------BBB---------- 
--------KKKKKK-KK------- --------AAAAAA-AA------- --------AAAAAA-AA------- --------AAAAAA-AA------- --------AAAAAA-AA------- --------AAAAAAAAA------- --------CCCCCCCCC------- --------CCCCCCCCC------- --------CCCCCCCCC------- --------CCCCCCCCC------- --------DDDDDDDDD------- --------DDDDDDDDD------- --------DDDDDDDDD------- --------DDDDDDDDD------- --------DDDDDDDDD------- --------DDDDDDDDD------- --------DDDDDDDDD------- ------DDDDDDDDDDD---D--- ------GGGGGGGGGGG---G--- ------GGGGGGGGGGG---G--- ------GGGGGGGGGGG---G--- --------GGGGGGGGG---G--- --------JJJJJJJJJ---J--- --------JJJJBBJJJ---J--- --------BBBBBBBBB-BB---- --------BBBBBBBBB-BB---- --------BBBBBBBBB-BB---- 
-------KKKKKKKKKKK------ -------AAAAAAAAAAA------ ------AAAAAAAAAAAA------ ------AAAAAAAAAAAA------ ------AAAAAAAAAAAA------ ------AAAAAAAAAAAA------ ------CCCCCCCCCCCC------ ------CCCCCCCCCCCC------ ------CCCCCCCCCCCC------ ------CCCCCCCCCCCC------ ------CCCCCCCCCCCC------ ------DDDDDDDDDDDD------ ------DDDDDDDDDDDDDD---- ------DDDDDDDDDDDDDD---- ------DDDDDDDDDDDDDD---- --------DDDDDDDDDD--D--- --------DDDDDDDDDD--D--- -----DDDDDDDDDDDDD--D--- -----GGGGGGGGGGGGG--G--- -----GGGGGGGGGGGGG--G--- ------GGGGGGGGGGGGGGG--- ------GGGGGGGGGGGGGGG--- ------JJJJJJJJJJJJJJJ--- ------JJJJJJBBBBBJJJJ--- ------BBBBBBBBBBBBBBB--- ------BBBBBBBBBBBBBBB--- ------BBBBBBBBBBBBBBB--- 
------KKKKKKKKKKKK------ ------AAAAAAAAAAAA------ ------AAAAAAAAAAAA------ ------AAAAAAAAAAAA------ ------AAAAAAAAAAAA------ ------AAAAAAAAAAAA------ ------CCCCCCCCCCCC------ ------CCCCCCCCCCCC------ ------CCCCCCCCCCCC------ ------CCCCCCCCCCCC------ ------CCCCCCCCCCCC------ ------CCCCCCCCCCCC------ ------DDDDDDDDDDDDDD---- ------DDDDDDDDDDDDDD---- ------DDDDDDDDDDDDDD---- --------DDDDDDDDDD--D--- --------DDDDDDDDDD--D--- -----DDDDDDDDDDDDD--D--- -----GGGGGGGGGGGGG--G--- -----GGGGGGGGGGGGG--G--- ------GGGGGGGGGGGGGGG--- ------GGGGGGGGGGGGGGG--- ------JJJJJJJJJJJJJJJ--- ------JJJJJJBBBBBJJJJ--- ------BBBBBBBBBBBBBBB--- ------BBBBBBBBBBBBBBB--- ------BBBBBBBBBBBBBBB--- 
------KKKKKKKKKKKK------ ------AAAAAAAAAAAA------ -----AAAAAAAAAAAAA------ -----AAAAAAAAAAAAA------ -----AAAAAAAAAAAAA------ -----AAAAAAAAAAAAA------ -----CCCCCCCCCCCCCCC---- -----CCCCCCCCCCCCCCC---- -----CCCCCCCCCCCCCCC---- -----CCCCCCCCCCCCCCC---- -----CCCCCCCCCCCCCCC---- -----CCCCCCCCCCCCCCC---- -----CCCCCCCCCCCCCCC---- -----DDDDDDDDDDDDDDD---- -----DDDDDDDDDDDDDDDD--- -----DDDDDDDDDDDDDDD-DD- -----DDDDDDDDDDDDDDD-DD- -----DDDDDDDDDDDDDDD-DD- -----DDDDDDDDDDDDDDD-DD- -----GGGGGGGGGGGGGGG-GG- -----GGGGGGGGGGGGGGGGGG- ---GGGGGGGGGGGGGGGGGGGG- ---JJJJJJJJJJJJJJJJJJJJ- ---JJJJJJJJJBBBBBBBBBJJ- -----BBBBBBBBBBBBBBBBBB- -----BBBBBBBBBBBBBBBBBB- -----BBBBBBBBBBBBBBBBBB- 
------KKKKKKKKKKKK------ ------AAAAAAAAAAAA------ -----AAAAAAAAAAAAA------ -----AAAAAAAAAAAAA------ -----AAAAAAAAAAAAA------ -----AAAAAAAAAAAAAAA---- -----CCCCCCCCCCCCCCC---- -----CCCCCCCCCCCCCCC---- -----CCCCCCCCCCCCCCC---- -----CCCCCCCCCCCCCCC---- -----CCCCCCCCCCCCCCC---- -----CCCCCCCCCCCCCCC---- -----CCCCCCCCCCCCCCCC--- -----DDDDDDDDDDDDDDDD--- -----DDDDDDDDDDDDDDD-DD- -----DDDDDDDDDDDDDDD-DD- -----DDDDDDDDDDDDDDD-DD- -----DDDDDDDDDDDDDDDDDD- -----DDDDDDDDDDDDDDDDDDD -----GGGGGGGGGGGGGGGGGGG ---GGGGGGGGGGGGGGGGGGGGG ---GGGGGGGGGGGGGGGGGGGGG ---JJJJJJJJJJJJJJJJJJJJJ ---JJJJJJJJJBBBBBBBBBJJ- ---BBBBBBBBBBBBBBBBBBBB- ---BBBBBBBBBBBBBBBBBBBB- ---BBBBBBBBBBBBBBBBBBBB- 
------KKKKKKKKKKKK------ ------AAAAAAAAAAAA------ -----AAAAAAAAAAAAA------ -----AAAAAAAAAAAAA------ -----AAAAAAAAAAAAA------ -----AAAAAAAAAAAAAAA---- -----CCCCCCCCCCCCCCC---- -----CCCCCCCCCCCCCCC---- -----CCCCCCCCCCCCCCC---- -----CCCCCCCCCCCCCCC---- -----CCCCCCCCCCCCCCC---- -----CCCCCCCCCCCCCCC---- -----CCCCCCCCCCCCCCCC--- -----CCCCCCCCCCCCCCCC--- -----DDDDDDDDDDDDDDD-DD- -----DDDDDDDDDDDDDDD-DD- -----DDDDDDDDDDDDDDD-DD- -----DDDDDDDDDDDDDDDDDD- -----DDDDDDDDDDDDDDDDDDD -----GGGGGGGGGGGGGGGGGGG ---GGGGGGGGGGGGGGGGGGGGG ---GGGGGGGGGGGGGGGGGGGGG ---JJJJJJJJJJJJJJJJJJJJJ ---JJJJJJJJJBBBBBBBBBJJ- ---BBBBBBBBBBBBBBBBBBBB- ---BBBBBBBBBBBBBBBBBBBB- ---BBBBBBBBBBBBBBBBBBBB- 
------KKKKKKKKKKKK------ ------AAAAAAAAAAAA------ -----AAAAAAAAAAAAA------ -----AAAAAAAAAAAAA------ -----AAAAAAAAAAAAA------ -----AAAAAAAAAAAAAAA---- -----AAAAAAAAAAAAAAA---- -----AAAAAAAAAAAAAAA---- -----CCCCCCCCCCCCCCC---- -----CCCCCCCCCCCCCCC---- -----CCCCCCCCCCCCCCC---- -----CCCCCCCCCCCCCCCC--- -----CCCCCCCCCCCCCCCC--- -----CCCCCCCCCCCCCCCC--- -----CCCCCCCCCCCCCCC-CC- -----DDDDDDDDDDDDDDD-DD- -----DDDDDDDDDDDDDDD-DD- -----DDDDDDDDDDDDDDDDDD- --DDDDDDDDDDDDDDDDDDDDDD --DDDDDDDDDDDDDDDDDDDDDD --GGGGGGGGGGGGGGGGGGGGGG ---GGGGGGGGGGGGGGGGGGGGG ---JJJJJJJJJJJJJJJJJJJJJ ---JJJJJJJJJBBBBBBBBBJJ- ---BBBBBBBBBBBBBBBBBBBB- ---BBBBBBBBBBBBBBBBBBBB- ---BBBBBBBBBBBBBBBBBBBB- 
-------KKKKKKKKKK------- -------AAAAAAAAAA------- ------AAAAAAAAAAAA------ ------AAAAAAAAAAAA------ ------AAAAAAAAAAAA------ ------AAAAAAAAAAAA------ ------AAAAAAAAAAAAAA---- ------AAAAAAAAAAAAAA---- ------AAAAAAAAAAAAAA---- ------AAAAAAAAAAAAAA---- ------AAAAAAAAAAAAAA---- ------CCCCCCCCCCCCCCC--- ------CCCCCCCCCCCCCCC--- ------CCCCCCCCCCCCCCC--- ------CCCCCCCCCCCCCCCCC- -----CCCCCCCCCCCCCCCCCC- -----DDDDDDDDDDDDDDDDDD- --D--DDDDDDDDDDDDDDDDDD- --D--DDDDDDDDDDDDDDDDDDD --D--DDDDDDDDDDDDDDDDDDD --GGGGGGGGGGGGGGGGGGGGGG --GGGGGGGGGGGGGGGGGGGGGG --JJJJJJJJJJJJJJJJJJJJJJ --NPPPPPPPPPBBBBBBBBBPP- ---BBBBBBBBBBBBBBBBBBBB- ---BBBBBBBBBBBBBBBBBBBB- --NBBBBBBBBBBBBBBBBBBBB- 
--------KKKKKKKKK------- --------AAAAAAAAA------- ------AAAAAAAAAAAA------ ------AAAAAAAAAAAA------ ------AAAAAAAAAAAA------ ------AAAAAAAAAAAA------ ------AAAAAAAAAAAAAA---- ------AAAAAAAAAAAAAA---- ------AAAAAAAAAAAAAA---- ------AAAAAAAAAAAAAA---- ------AAAAAAAAAAAAAA---- ------AAAAAAAAAAAAAAA--- ------AAAAAAAAAAAAAAA--- ------CCCCCCCCCCCCCCC--- ------CCCCCCCCCCCCCCCCC- -----CCCCCCCCCCCCCCCCCC- -----CCCCCCCCCCCCCCCCCC- --C--CCCCCCCCCCCCCCCCCC- --D--DDDDDDDDDDDDDDDDDDD --D--DDDDDDDDDDDDDDDDDDD --DDDDDDDDDDDDDDDDDDDDDD --GGGGGGGGGGGGGGGGGGGGGG --JJJJJJJJJJJJJJJJJJJJJJ --NPPPPPPPPPBBBBBBBBBPP- ---BBBBBBBBBBBBBBBBBBBB- ---BBBBBBBBBBBBBBBBBBBB- --NBBBBBBBBBBBBBBBBBBBB- 
---------KKKKK---------- ---------AAAAA---------- --------AAAAAA---------- ------AAAAAAAAA--------- ------AAAAAAAAA--------- ------AAAAAAAAA--------- ------AAAAAAAAAAA------- ------AAAAAAAAAAA------- ------AAAAAAAAAAA------- ------AAAAAAAAAAA------- ------AAAAAAAAAAA------- ------AAAAAAAAAAA------- ------AAAAAAAAAAAAAA---- ------AAAAAAAAAAAAAA---- ---AAAAAAAAAAAAAAAAAA--- --AAAAAAAAAAAAAAAAAAA--- --CCCCCCCCCCCCCCCCCCC--- --C--CCCCCCCCCCCCCCCCCC- --C---CCCCCCCCCCCCCCCCC- --D---DDDDDDDDDDDDDDDDD- --D--DDDDDDDDDDDDDDDDDD- --G--GGGGGGGGGGGGGGGGGG- --P--PPPPPPPPPPPPPPPPPP- NNB--OOOOOOOBBBBBBBBBOO- NNBBBBBBBBBBBBBBBBBBBBB- NNBBBBBBBBBBBBBBBBBBBBB- NNBBBBBBBBBBBBBBBBBBBBB- 
------------------------ ------------------------ ------------------------ ------------AA---------- ------------AA---------- ------AAA---AA---------- ------AAAAAAAA---------- ------AAAAAAAA---------- ------AAAAA-AA---------- -----AAAA--------------- -----AAAA--------------- ---AAAAAA--AAA---------- ---AAAAAAAAAAAA--------- ---AAAAAAAAAAAA--------- --AAAAAAAAAAAAA--------- --AAAAAAAAAAAAAAAAAA---- --AAAAAAAAAAAAAAAAAA---- --CCCCCCCCCCCCCCCCCCCCC- --CCCCCCCCCCCCCCCCCCCCC- --CCCCCCCCCCCCCCCCCCCCC- --D--DDDDDDDDDDDDDDDDDD- --G--GGGGGGGGGGGGGGGGGG- --O--OOOOOOOOOOOOOOOOOO- --B--RRRRRRRBBBBBBBBBRR- NNBBBBBBBBBBBBBBBBBBBBB- NNBBBBBBBBBBBBBBBBBBBBB- --BBBBBBBBBBBBBBBBBBBBB- 
------------------------ ------------------------ ------------------------ ------------AA---------- ------------AA---------- ------AAA---AA---------- ------AAAAAAAA---------- ------AAAAAAAA---------- ------AAAAA-AA---------- -----AAAA--------------- -----AAAA--------------- ---AAAAAA--AAA---------- ---AAAAAAAAAAAA--------- ---AAAAAAAAAAAA--------- --AAAAAAAAAAAAA--------- --AAAAAAAAAAAAAAAAAA---- --AAAAAAAAAAAAAAAAAA---- --AAAAAAAAAAAAAAAAAAAAA- --AAAAAAAAAAAAAAAAAAAAA- --CCCCCCCCCCCCCCCCCCCCC- --D--DDDDDDDDDDDDDDDDDD- --G--GGGGGGGGGGGGGGGGGG- --O--OOOOOOOOOOOOOOOOOO- --B--RRRRRRRBBBBBBBBBRR- NNBBBBBBBBBBBBBBBBBBBBB- NNBBBBBBBBBBBBBBBBBBBBB- --BBBBBBBBBBBBBBBBBBBBB- 
------------------------ ------------------------ ------------------------ ------------------------ ------------------------ ------------------------ ------AA---------------- ------AA---------------- ------AAAAA------------- ---AAAAAA--------------- ---AAAAAA--------------- ---AAAAAAAAAAAAAA------- --AAAAAAAAAAAAA--------- --AAAAAAAAAAAAA--------- --AAAAAAAAAAAAA--------- --AAAAAAAAAAAAAAAAAA---- --AAAAAAAAAAAAAAAAAA---- --AAAAAAAAAAAAAAAAAAAAA- --A---AAAAAAAAAAAAAAAAA- --A---AAAAAAAAAAAAAAAAA- --A--AAAAAAAAAAAAAAAAAA- --A--AAAAAAAAAAAAAAAAAA- --Q--QQQQQQQQQQQQQQQQQQ- --B--QQQQQQQBBBBBBBBBQQ- NNBBBBBBBBBBBBBBBBBBBBB- NNBBBBBBBBBBBBBBBBBBBBB- --BBBBBBBBBBBBBBBBBBBBB- 
-----------KKKK--------- -----------AAAA--------- ---------AAAAAA--------- --------AAAAAAA--------- --------AAAAAAA--------- ------AAAAAAAAA--------- ------AAAAAA------------ ------AAAAAA------------ ------AAAAAAAAAAA------- -----AAAAAAAAAAAA------- -----AAAAAAAAAAAA------- ---AA-AAAAAAAAAAA-AA---- ---AA-AAA--AAAAAAAAA---- ---AA-AAA--AAAAAAAAA---- --A--AAAAAAAAAAAAAAA---- --AAA-AAAAAAAAAAAAAAAAA- --AAA-AAAAAAAAAAAAAAAAA- --A---AAAAAAAAAAAAAAAAA- --A--AAAAAAAAAAAAAAAAAA- --E--EEEEEEEEEEEEEEEEEE- --E--EEEEEEEEEEEEEEEEEE- --A--AAAAAAAAAAAAAAAAAA- --M--MMMMMMMMMMMMMMMMMM- --BTTTTTTTTTBBBBBBBBBTT- NNBBBBBBBBBBBBBBBBBBBBB- NNBBBBBBBBBBBBBBBBBBBBB- --BBBBBBBBBBBBBBBBBBBBB- 
-----------KKKK--------- -----------AAAA--------- ---------AAAAAA--------- --------AAAAAAA--------- --------AAAAAAA--------- ------AAAAAAAAA--------- ------AAAAAA------------ ------AAAAAA------------ ------AAAAAAAAAAA------- -----AAAAAAAAAAAA------- -----AAAAAAAAAAAA------- ---AA-AAAAAAAAAAA-AA---- ---AA-AAA--AAAAAAAAA---- ---AA-AAA--AAAAAAAAA---- --A--AAAAAAAAAAAAAAA---- --AAA-AAAAAAAAAAAAAAAAA- --EEE-EEEEEEEEEEEEEEEEE- --E---EEEEEEEEEEEEEEEEE- --E--EEEEEEEEEEEEEEEEEE- --H--HHHHHHHHHHHHHHHHHH- --H--HHHHHHHHHHHHHHHHHH- --I--IIIIIIIIIIIIIIIIII- --M--MMMMMMMMMMMMMMMMMM- --BMMMMMMMMMBBBBBBBBBMM- NNBBBBBBBBBBBBBBBBBBBBB- NNBBBBBBBBBBBBBBBBBBBBB- --BBBBBBBBBBBBBBBBBBBBB- 
------KKKKKKKKKKKKKKK--- ------AAAAAAAAAAAAAAA--- ------AAAAAAAAAAAAAAA--- ------AAAAAAAAAAAAAAA--- ------AAAAAAAAAAAAAAA--- ------AAAAAAAAAAAAAAA--- ------AAAAAAAAAAAAAAA--- ------AAAAAAAAAAAAAAA--- ------AAAAAAAAAAAAAAA--- ------AAAAAAAAAAAAAAA--- ------AAAAAAAAAAAAAAA--- ------AAAAAAAAAAAAAAA--- ------AAAAAAAAAAAAAAA--- ------AAAAAAAAAAAAAAA--- ------EEEEEEEEEEEEEEEEE- -----EEEEEEEEEEEEEEEEEE- -----EEEEEEEEEEEEEEEEEE- --E--EEEEEEEEEEEEEEEEEE- --HHHHHHHHHHHHHHHHHHHHH- --HHHHHHHHHHHHHHHHHHHHH- --FFFFFFFFFFFFFFFFFFFFF- --IIIIIIIIIIIIIIIIIIIII- --LLLLLLLLLLLLLLLLLLLLL- NNNMMMMMMMMMBBBBBBBBBMM- NNNBBBBBBBBBBBBBBBBBBBB- NNNBBBBBBBBBBBBBBBBBBBB- NNNBBBBBBBBBBBBBBBBBBBB- 
------KKKKKKKKKKKKKK---- ------AAAAAAAAAAAAAA---- ------AAAAAAAAAAAAAA---- ------AAAAAAAAAAAAAA---- ------AAAAAAAAAAAAAA---- ------AAAAAAAAAAAAAA---- ------AAAAAAAAAAAAAA---- ------AAAAAAAAAAAAAA---- -----AAAAAAAAAAAAAAA---- -----AAAAAAAAAAAAAAA---- -----AAAAAAAAAAAAAAA---- -----EEEEEEEEEEEEEEEE--- -----EEEEEEEEEEEEEEEE--- -----EEEEEEEEEEEEEEEE--- -----EEEEEEEEEEEEEEEEEE- ---EEEEEEEEEEEEEEEEEEEE- ---EEEEEEEEEEEEEEEEEEEE- ---HHHHHHHHHHHHHHHHHHHH- --HHHHHHHHHHHHHHHHHHHHH- --FFFFFFFFFFFFFFFFFFFFF- --FFFFFFFFFFFFFFFFFFFFF- ---IIIIIIIIIIIIIIIIIIII- ---LLLLLLLLLLLLLLLLLLLL- --NSSSSSSSSSBBBBBBBBBSS- ---BBBBBBBBBBBBBBBBBBBB- ---BBBBBBBBBBBBBBBBBBBB- --NBBBBBBBBBBBBBBBBBBBB- 
------KKKKKKKKKKKKKK---- ------AAAAAAAAAAAAAA---- ------AAAAAAAAAAAAAA---- ------AAAAAAAAAAAAAA---- ------AAAAAAAAAAAAAA---- ------AAAAAAAAAAAAAA---- ------AAAAAAAAAAAAAA---- ------AAAAAAAAAAAAAA---- -----EEEEEEEEEEEEEEE---- -----EEEEEEEEEEEEEEE---- -----EEEEEEEEEEEEEEE---- -----EEEEEEEEEEEEEEEE--- -----EEEEEEEEEEEEEEEE--- -----EEEEEEEEEEEEEEEE--- -----EEEEEEEEEEEEEEEEEE- ---EEEEEEEEEEEEEEEEEEEE- ---HHHHHHHHHHHHHHHHHHHH- ---HHHHHHHHHHHHHHHHHHHH- --FFFFFFFFFFFFFFFFFFFFF- --FFFFFFFFFFFFFFFFFFFFF- --FFFFFFFFFFFFFFFFFFFFF- ---IIIIIIIIIIIIIIIIIIII- ---IIIIIIIIIIIIIIIIIIII- --NLLLLLLLLLBBBBBBBBBLL- ---BBBBBBBBBBBBBBBBBBBB- ---BBBBBBBBBBBBBBBBBBBB- --NBBBBBBBBBBBBBBBBBBBB- 
------KKKKKKKKKKKKKK---- ------AAAAAAAAAAAAAA---- ------AAAAAAAAAAAAAA---- ------AAAAAAAAAAAAAA---- ------AAAAAAAAAAAAAA---- -----AAAAAAAAAAAAAAA---- -----EEEEEEEEEEEEEEE---- -----EEEEEEEEEEEEEEE---- -----EEEEEEEEEEEEEEE---- -----EEEEEEEEEEEEEEE---- -----EEEEEEEEEEEEEEE---- -----EEEEEEEEEEEEEEE---- -----EEEEEEEEEEEEEEE---- -----EEEEEEEEEEEEEEE---- -----HHHHHHHHHHHHHHHH--- ---HHHHHHHHHHHHHHHHH-HH- ---HHHHHHHHHHHHHHHHH-HH- ---FFFFFFFFFFFFFFFFF-FF- ---FFFFFFFFFFFFFFFFFFFF- ---FFFFFFFFFFFFFFFFFFFF- ---FFFFFFFFFFFFFFFFFFFF- ---IIIIIIIIIIIIIIIIIIII- ---IIIIIIIIIIIIIIIIIIII- ---LLLLLLLLBBBBBBBBBBLL- ---BBBBBBBBBBBBBBBBBBBB- ---BBBBBBBBBBBBBBBBBBBB- ---BBBBBBBBBBBBBBBBBBBB- 
------KKKKKKKKKKKKKK---- ------AAAAAAAAAAAAAA---- ------AAAAAAAAAAAAAA---- ------AAAAAAAAAAAAAA---- ------AAAAAAAAAAAAAA---- ------AAAAAAAAAAAAAA---- ------EEEEEEEEEEEEEE---- ------EEEEEEEEEEEEEE---- ------EEEEEEEEEEEEEE---- ------EEEEEEEEEEEEEE---- ------EEEEEEEEEEEEEE---- ------EEEEEEEEEEEEEE---- ------EEEEEEEEEEEEEE---- ------HHHHHHHHHHHHHH---- -----HHHHHHHHHHHHHHH---- -----HHHHHHHHHHHHHHH-HH- -----HHHHHHHHHHHHHHH-HH- -----FFFFFFFFFFFFFFF-FF- -----FFFFFFFFFFFFFFF-FF- -----FFFFFFFFFFFFFFF-FF- -----FFFFFFFFFFFFFFF-FF- -----IIIIIIIIIIIIIII-II- -----IIIIIIIIIIIIIII-II- -----LLLLLLBBBBBBBBBBLL- -----BBBBBBBBBBBBBBBBBB- -----BBBBBBBBBBBBBBBBBB- -----BBBBBBBBBBBBBBBBBB- 
------KKKKKKKKKKKKKK---- ------AAAAAAAAAAAAAA---- ------AAAAAAAAAAAAAA---- ------AAAAAAAAAAAAAA---- ------AAAAAAAAAAAAAA---- ------AAAAAAAAAAAAAA---- ------EEEEEEEEEEEEEE---- ------EEEEEEEEEEEEEE---- ------EEEEEEEEEEEEEE---- ------EEEEEEEEEEEEEE---- ------EEEEEEEEEEEEEE---- ------EEEEEEEEEEEEEE---- ------HHHHHHHHHHHHHH---- ------HHHHHHHHHHHHHH---- -----HHHHHHHHHHHHHHH---- -----HHHHHHHHHHHHHHH-HH- -----FFFFFFFFFFFFFFF-FF- -----FFFFFFFFFFFFFFF-FF- -----FFFFFFFFFFFFFFF-FF- -----FFFFFFFFFFFFFFF-FF- -----FFFFFFFFFFFFFFF-FF- -----IIIIIIIIIIIIIII-II- -----IIIIIIIIIIIIIII-II- -----IIIIIIBBBBBBBBBBII- -----BBBBBBBBBBBBBBBBBB- -----BBBBBBBBBBBBBBBBBB- -----BBBBBBBBBBBBBBBBBB- 
--------KKKKKKKKKK------ --------AAAAAAAAAA------ --------AAAAAAAAAA------ --------AAAAAAAAAA------ --------AAAAAAAAAA------ --------AAAAAAAAAA------ --------EEEEEEEEEE------ --------EEEEEEEEEE------ --------EEEEEEEEEE------ --------EEEEEEEEEE------ --------EEEEEEEEEE------ --------HHHHHHHHHH------ --------HHHHHHHHHH------ --------HHHHHHHHHH------ --------HHHHHHHHHH------ --------FFFFFFFFFF------ --------FFFFFFFFFF------ ------FFFFFFFFFFFF--FFF- ------FFFFFFFFFFFF--F--- ------FFFFFFFFFFFF--F--- ------FFFFFFFFFFFF--F--- ------IIIIIIIIIIII--I--- ------IIIIIIIIIIII--I--- ------IIIIIBBBBBBBBBI--- ------BBBBBBBBBBBBBBB--- ------BBBBBBBBBBBBBBB--- ------BBBBBBBBBBBBBBB--- 
---------KKKKKK--------- ---------AAAAAA--------- ---------AAAAAA--------- ---------AAAAAA--------- ---------AAAAAA--------- --------AAAAAAAAA------- --------EEEEEEEEE------- --------EEEEEEEEE------- --------EEEEEEEEE------- --------HHHHHHHHH------- --------HHHHHHHHH------- --------HHHHHHHHH------- --------HHHHHHHHH------- --------HHHHHHHHH------- --------HHHHHHHHH------- --------FFFFFFF--------- --------FFFFFFF--------- --------FFFFFFF-----F--- --------FFFFFFF-----F--- --------FFFFFFF-----F--- --------FFFFFFF---FFF--- --------IIIIIII---II---- --------IIIIIII---II---- --------IIIBBBB---II---- --------BBBBBBB--BBB---- --------BBBBBBB--BBB---- --------BBBBBBBBBBBB---- 
---------KKKKKK--------- ---------AAAAAA--------- ---------AAAAAA--------- ---------AAAAAA--------- ---------AAAAAA--------- --------AAAAAAAAA------- --------EEEEEEEEE------- --------EEEEEEEEE------- --------HHHHHHHHH------- --------HHHHHHHHH------- --------HHHHHHHHH------- --------HHHHHHHHH------- --------HHHHHHHHH------- --------HHHHHHHHH------- --------FFFFFFFFF------- --------FFFFFFF--------- --------FFFFFFF--------- --------FFFFFFF-----F--- --------FFFFFFF-----F--- --------FFFFFFF-----F--- --------FFFFFFF---FFF--- --------IIIIIII---II---- --------IIIIIII---II---- --------IIIBBBB---II---- --------BBBBBBB--BBB---- --------BBBBBBB--BBB---- --------BBBBBBBBBBBB---- 
------------KK---------- ------------AA---------- ------------AA---------- ------------AA---------- ------------AA---------- ------------AA---------- -----------EEE---------- -----------HHH---------- -----------HHH---------- -----------HHH---------- -----------HHH---------- -----------HHH---------- -----------HHH---------- -----------FFF---------- -----------FFF---------- -----------FFF---------- -----------FFF---------- --------FFFFFF-FFFFF---- --------FFFFFFFFFFFF---- --------FFFFFFFFFFFF---- ---------FFFFFFFFFFF---- ---------IIIIIIIIIII---- ---------IIIIIIIIIII---- ---------IIIIIBIIIII---- ---------BBBBBBBBB------ ---------BBBBBBBBB------ -----------BBBBBBB------ 
------------------------ ------------------------ ------------------------ ------------------------ ------------------------ ------------------------ ------------------------ ------------------------ ------------------------ ------------------------ ------------------------ ------------------------ ------------------------ ------------------------ ------------------------ ------------------------ ------------------------ --------------FFF------- --------------F--------- --------------F--------- --------------F--------- --------------I--------- --------------I--------- --------------I--------- ------------------------ ------------------------ ------------------------ 
------------------------ ------------------------ ------------------------ ------------------------ ------------------------ ------------------------ ------------------------ ------------------------ ------------------------ ------------------------ ------------------------ ------------------------ ------------------------ ------------------------ ------------------------ ------------------------ ------------------------ --------------FFF------- --------------F--------- --------------F--------- --------------F--------- --------------I--------- --------------I--------- --------------I--------- ------------------------ ------------------------ ------------------------ 
