model
size = 29 32 15, scale = 0.05, origin = -y
material 
  colors = A:#F00 B:#DA0107 C:#DE2400 D:#920316 E:#9E6D00 F:#6E041E G:#BE4800 H:#4A0525 I:#3DDA00 J:#B6020F K:#7D9100 L:#020835 M:#052C2B N:#19DC06 O:#1DFF00 P:#5DB600 Q:#26062D R:#119613 S:#15B90D T:#095021 U:#AAA V:#EEE W:#BBB X:#0D731A Y:#DDD
voxels
9-2(B10A18-)3(2B9A18-)3B8A2(18-11A)3(18-B10A)2(18-2B8AC)18-2B7A2(2C18-3B6A)2C18-J3B4A2CG18-5UA5U18-4W3A4W18-D3YBAC3YG18-D3VBAG3VE18-F9VE18-F3VLRI3VK19-3WMRO3W20-4UR4U221-2B9-2A4(16-B11-A)16-B11-C2(16-B11-A)16-B11-C17-B9-A18-B9-C17-3(B11-C16-)J11-C16-J11-G17-J9-G18-V9-V16-2D11-2G14-2D11-GE14-2D2(11-2E14-2F)11-2K14-2HW9-W2K15-2U9-2U17-Q2LMTRSNO2I20-2MTRS2N163-2B11-2A14-B13-A7(14-B13-C)15-2(B11-C16-)B11-C15-B2(13-C14-J)13-G14-J13-G14-2J11-2G14-2U11-2U14-D13-G2(14-D13-E)13-F15-E2(12-F15-K)2(13-U)14-HQ11-2I15-Q2L2MTRS2N2OI17-L3MTRS3NO21-TX2RS105-2B13-A2(C12-B15-)C13-10(B13-C14-)J13-C3(14-J13-G)2(14-D13-G)14-D13-E11-3D15-3E8-2F-6F2A7E-2E8-2F-3F2H2LR2IP4K-2K8-2F-3HQ2LMR2OI2P2K-2K9-3H2Q2LMTR3O2I4P11-H-2Q2LMTRSNO3I-P13-2QL9-O2I14-QL-3M3-3N-OI16-L2M-X2R-3N21-TX2RS76-5(B15-C12-)J3(15-C12-B)15-C13-4(B13-C14-)J13-C3(14-J13-G)14-D13-G13-D15-G8-9D2JBA2C4G6E4-2D3-5DJBA4G3E3-2E5-F2-F15-E2-E2(6-F2-F15-K2-K)6-F3H15-2P2K6-5H13-I4P7-3HQ13-3IP9-3Q2L9-2O3I11-Q2L-2MT3-S2N-2OI15-3MTX2R2S2N73-5(B15-C12-)J3(15-C12-B)15-C13-B13-C13-B15-C12-B15-C13-B2(13-C14-J)13-G14-J13-G13-D15-G12-3D2J2B3A3C4G7-5D-3D2JB3A2C4G-G4E2(2-6D15-6E)2-6F15-6E3-2(4F17-4K4-)2FH19-3K4-H-H19-P-P5-3H17-I2P6-2H2Q15-4I7-2Q-3L9-N2O-2I10-3L3MT3-2S3N2O16-MT5-SN45-2(5(B15-C12-)J6(15-C12-B)15-C13-B2(13-C14-J)13-G13-J15-G12-D3J3B4A2C4G12-D15-G7-D3-2D15-2G3-E-2(2D4-D15-E4-2E)-2F3-F15-E3-2E2(2-2F23-2K)3-F23-K2(4-2H21-2P)5-2H19-2I6-H3Q15-4I8-Q3L2M7-3N3O13-2M-T5-S-2N18-MT5-SN16-)5(B15-C12-)J6(15-C12-B)15-C13-B2(13-C14-J)13-G13-J15-G12-D15-G13-2D2J2B3A3C3G8-D5-3D2JB3A2C4G5-E-D-3D-D15-5E-ED-5D15-5E-E-F-4F15-4E-E2(2-F-3F17-3K-K)3-2FH19-3K4-H-H19-P-P4-H-2H17-IP-P5-H-2Q15-2I-I6-HQ2-3L9-N2O2-2I8-Q2L2-2M5-SN2-3O13-2M7-S-2N18-MT5-SN16-5(B15-C12-)J6(15-C12-B)15-C13-B2(13-C14-J)13-G13-J15-G12-D15-G36-D25-E-D6-4D2JBA2C4GE6-ED6-5DJBA4G3E6-E-F4-F15-E4-E2(2-F4-F15-K4-K)3-F2-2H15-2P2-K4-H2-3H13-I2P2-P4-H3-HQ13-2I3-P5-H3-Q2L9-2OI3-I6-HQ5-2M5-2N5-2I8-Q2L13-3O13-2M9-2N18-MT5-SN16-5(B15-C12-)J6(15-C12-B)15-C13-B2(13-C14-J)13-G13-J15-G12-D15-G36-D25-E-2(D27-E)-F5-6F2A7E5-E2-F5-3F2H2LR2IP4K5-K2-F5-3HQ2LMR2OI2P2K5-K3-F4-H2Q2LMTR3O2I2P4-K4-H5-2Q2LMTRSNO3I5-P4-H5-QL9-OI5-P5-H6-2M4-3N6-I6-HQ19-2I8-Q2L13-3O13-2M7-S-2N18-MT5-SN16-5(B15-C12-)J2(15-C12-B)15-C13-B14-C13-B13-C13-B15-C12-B15-C13-B2(13-C14-J)13-G14-J13-G13-D15-G12-D15-G7-5D17-G4E2(2-D25-E)2-2F23-2E3-3(F23-K4-)H23-P5-H6-L2MTRS2NO6-P6-2H8-TRS8-2I7-2Q17-2I10-3LM9-2N2O16-M2TX2R2SN21-T2X2R2S17-2(B15-C12-)B15-6(C13-B14-)C13-4(B13-C14-)J13-C3(14-J13-G)14-D13-G13-D15-G8-5D15-5E4-2D21-2E5-F21-E2(6-F21-K)6-FH19-2K6-3H17-3P7-3H15-2IP9-2Q15-2I11-Q2L11-2OI15-3M5-S2N21-TX2RS24-2X2RS18-2(B15-C12-)B15-C13-10(B13-C14-)J13-C3(14-J13-G)2(14-D13-G)14-D13-E11-3D15-3E8-2F17-2E2(8-2F17-2K)9-2H15-2P11-H15-P13-Q13-I14-QL11-OI16-L2M5-3N21-TX2RS76-2(4B12AC12-)5B10A2C13-2(4B10AC14-)5B8A2C2(14-2B12AC)3(14-3B10A2C)2(14-4B8A3C)14-J3B7A4C14-2J3B6A3CG14-2J3B6A2C2G14-3J3B4A2C3G14-2D2J2B3A3C3G14-3D2JB3A2C4G14-4D2JBA2C4GE14-5DJBA4G3E13-7F2A8E12-4F2H2LR2IP5K12-F3HQ2LMR2OI2P3K13-H2Q2LMTR3O2I2P14-H2Q2LMTRSNO4I15-Q2L2MTRS2N2OI17-L3MTRS3NO21-TX2RS99-
