model
size = 7 29 14, scale = 0.05, origin = -y
material 
  colors = A:#FBE251 B:#D19826 C:#FFC408 D:#FFB11B E:#DDD23B F:#FAD689 G:#EEE H:#FCFAF2
voxels
------- ------- ------- ------- ------- ------- ------- ------- ------- ------- ------- ------- ------- A------ A------ AA----- FD----- FB----- BB----- BB----- BA----- AA----- EA----- FA----- DE----- ------- ------- ------- ------- 
------- ------- ------- ------- ------- ------- -BA---- -DA---- -FB---- -CB---- -DA---- -AA---- -AE---- -AE---- -DA---- -FA---- -FA---- -BB---- -BB---- -FA---- -BA---- -BF---- -DF---- -CA---- -CA---- -AA---- ------- ------- ------- 
------- ------- ------- ------- --EF--- --CE--- --DD--- --DA--- --FA--- --AA--- --CE--- --AE--- --AE--- --DE--- --DE--- --DE--- --BA--- --BA--- --CA--- --BA--- --BB--- --CB--- --CB--- --CF--- --BA--- --FA--- -DDA--- ------- ------- 
------- ------- ------- ---D--- ---D--- ---DE-- ---DA-- ---DA-- ---AA-- ---AA-- ---CA-- ---CE-- ---DE-- ---DE-- ---BA-- ---BA-- ---BA-- ---BA-- ---BA-- ---CA-- ---CA-- ---CA-- ---BA-- ---BA-- ---A--- --CA--- -CGD--- BBFE--- --BB--- 
------- ------- ------- ----A-- ----A-- ----A-- ----A-- ----A-- ----A-- ----A-- ----A-- ----C-- ----C-- ----A-- ----E-- ----A-- ----A-- ----C-- ----C-- ----C-- ----D-- ----F-- ----A-- ----B-- ---BA-- --DGA-- -CGGA-- -FCHA-- ---A--- 
------- ------- -----C- -----B- -----A- -----A- -----A- -----A- -----E- -----E- -----A- -----A- -----C- -----C- -----A- -----A- -----C- -----C- -----E- -----A- -----A- -----E- -----A- ----FA- ---BGA- --BGGD- --GGGA- --FHB-- ---FE-- 
-----B- -----B- -----B- -----B- -----BA -----AB -----BE -----DE -----DE -----AA -----AA -----CD -----CA -----CC -----CC -----CA -----CD -----DD -----DD -----DE -----DA -----DA -----CE ----DCA ---FBBA --BBDCA --BBBB- --CDCA- ----E-- 
-----B- -----B- -----B- -----B- -----BA -----AB -----BE -----DE -----DE -----AA -----AA -----CD -----CA -----CC -----CC -----CA -----CD -----DD -----DD -----DE -----DA -----DA -----CE ----DCA ---FBBA --BBDCA --BBBB- --CDCA- ----E-- 
------- ------- -----C- -----B- -----A- -----A- -----A- -----A- -----E- -----E- -----A- -----A- -----C- -----C- -----A- -----A- -----C- -----C- -----E- -----A- -----A- -----E- -----A- ----FA- ---BGA- --BGGD- --GGGA- --FHB-- ---FE-- 
------- ------- ------- ----A-- ----A-- ----A-- ----A-- ----A-- ----A-- ----A-- ----A-- ----C-- ----C-- ----A-- ----E-- ----A-- ----A-- ----C-- ----C-- ----C-- ----D-- ----F-- ----A-- ----B-- ---BA-- --DGA-- -CGGA-- -FCHA-- ---A--- 
------- ------- ------- ---D--- ---D--- ---DE-- ---DA-- ---DA-- ---AA-- ---AA-- ---CA-- ---CE-- ---DE-- ---DE-- ---BA-- ---BA-- ---BA-- ---BA-- ---BA-- ---CA-- ---CA-- ---CA-- ---BA-- ---BA-- ---A--- --CA--- -CGD--- BBFE--- --BB--- 
------- ------- ------- ------- --EF--- --CE--- --DD--- --DA--- --FA--- --AA--- --CE--- --AE--- --AE--- --DE--- --DE--- --DE--- --BA--- --BA--- --CA--- --BA--- --BB--- --CB--- --CB--- --CF--- --BA--- --FA--- -DDA--- ------- ------- 
------- ------- ------- ------- ------- ------- -BA---- -DA---- -FB---- -CB---- -DA---- -AA---- -AE---- -AE---- -DA---- -FA---- -FA---- -BB---- -BB---- -FA---- -BA---- -BF---- -DF---- -CA---- -CA---- -AA---- ------- ------- ------- 
------- ------- ------- ------- ------- ------- ------- ------- ------- ------- ------- ------- ------- A------ A------ AA----- FD----- FB----- BB----- BB----- BA----- AA----- EA----- FA----- DE----- ------- ------- ------- ------- 
