model
size = 27 17 24, scale = 0.05, origin = -y
material 
  colors = A:#222 B:#111 C:#004 D:#002 E:#555 F:#BBB G:#E00 H:#888 I:#DDD J:#0B0 K:#CF0 L:#008 M:#070
voxels
--------------------------- --------------------------- --------------------------- --------------------------- --------------------------- -----------------A--------- -----------------A--------- -----------------A--------- -----------------A--------- -----------------A--------- -----------------A--------- --------------------------- --------------------------- --------------------------- --------------------------- --------------------------- --------------------------- 
--------------------------- --------------------------- --------------------------- --------------------------- -----------------A--------- -----------------CA-------- -----------------CA-------- -----------------CA-------- -----------------CA-------- -----------------CA-------- -----------------CA-------- -----------------A--------- --------------------------- --------------------------- --------------------------- --------------------------- --------------------------- 
--------------------------- --------------------------- --------------------------- --------------------------- -----------------A--------- -----------------CA-------- -----------------CA-------- -----------------CA-------- -----------------CA-------- -----------------CA-------- -----------------CA-------- -----------------A--------- --------------------------- --------------------------- --------------------------- --------------------------- --------------------------- 
--------------------------- --------------------------- --------------------------- --------------------------- -----------------A--------- -----------------CA-------- -----------------CA-------- -----------------CA-------- -----------------CA-------- -----------------CA-------- -----------------CA-------- -----------------A--------- --------------------------- --------------------------- --------------------------- --------------------------- --------------------------- 
--------------------------- --------------------------- --------------------------- --------------------------- -----------------A--------- -----------------CA-------- -----------------CA-------- -----------------CA-------- -----------------CA-------- -----------------CA-------- -----------------CA-------- -----------------A--------- --------------------------- --------------------------- --------------------------- --------------------------- --------------------------- 
--------------------------- --------------------------- --------------------------- --------------------------- -----------------A--------- -----------------CA-------- -----------------CA-------- -----------------CA-------- -----------------CA-------- -----------------CA-------- -----------------CA-------- -----------------A--------- --------------------------- --------------------------- --------------------------- --------------------------- --------------------------- 
--------------------------- --------------------------- --------------------------- --------------------------- -----------------A--------- -----------------CA-------- -----------------CA-------- -----------------CA-------- -----------------CA-------- -----------------CA-------- -----------------CA-------- -----------------A--------- --------------------------- --------------------------- --------------------------- --------------------------- --------------------------- 
--------------------------- --------------------------- --------------------------- --------------------------- --------------------------- -----------------A--------- -----------------A--------- -----------------A--------- -----------------A--------- -----------------A--------- -----------------A--------- --------------------------- --------------------------- --------------------------- --------------------------- --------------------------- --------------------------- 
--------------------------A --------------------------A --------------------------A --------------------------A --------------------------A --------------------------A --------------------------A --------------------------A -----------------A--------A -----------------A--------A --------------------------A --------------------------A --------------------------A --------------------------A --------------------------A --------------------------- --------------------------- 
--------------------------A -------------------------A- -------------------------A- ----AAAAAAAAAAAAAAAAA----A- ----AAAAA------AAAAAA----A- ----AAAA--------AAAAA----A- ----AAAA--------AAAAA----A- ----AAAA--------AAAAA----A- ----AAAA--------AAAAA----A- ----AAAA--------AAAAA----A- ----AAAA--------AAAAA----A- ----AAAAA------AAAAAA----A- -------------------------A- -------------------------A- --------------------------A --------------------------- --------------------------- 
--------------------------A -------------------------A- ----AAAAAAAAAAAAAAAAA---A-- ----AAAAAAAAAAAAAAAAA---A-- ----AAAAAAAAAAAAAAAAA---A-- ----AAAAAAAAAAAAAAAAA---A-- ----AAAAAAAAAAAAAAAAA---A-- A---AAAAAAFAFAAAAAAAA---A-- A---AAAAAAAAAAAAAAAAA---A-- A---AAAAAAFAFAAAAAAAA---A-- A---AAAAAAAAAAAAAAAAA---A-- ----AAAAAAAAAAAAAAAAA---A-- ----AAAAAAAAAAAAAAAAA---A-- -------------------------A- --------------------------A --------------------------- --------------------------- 
--------------------------A ----AAAAAAAAAAAAAAAAA----A- ----AAAAAAAAAAAAAAAAA---A-- ----AAAAAAAAAAAAAAAAAA-A--- ----BAAAAAAAAAAAAAAAAABA--- ---ABBAAAAAAAAAAAAAAAABA--- A-AABBAAAAAAAAAAAAAAAABA--- CAAABBAAAAAAAAAAAAAAAABA--- CAAABBAAAAAAAAAAAAAAAABA--- CAA-BAAAAAAAAAAAAAAAAABA--- CA--AAAAAAAAAAAAAAAAAABA--- A---AAAAAAAAAAAAAAAAAAEA--- ----AAAAAAAAAAAAAAAAA-E-A-- ----AAAAAAAAAAAAAAAAA-E--A- ----------------EEE--E----A -------------------EE------ --------------------------- 
--------------------------A ----AAAAAAAAAAAAAAAAA----A- ----AAAAAAAAAAAAAAAAA---A-- ----AAAAAAAAAAAAAAAAAABA--- ---ABAAAAAAAAAAAAAAAAAD---- A-AABAAAAAAAAAAAAAAAAAD---- MAAABAAAAAAAAAAAAAAAAAD---- CAAABAAAAAAAAAAAAAAAAAD---- CAAABAAAAAAAAAAAAAAAAAD---- CAAABAAAAAAAAAAAAAAAAAD---- CAA-AAAAAAAAAAAAAAAAAAD---- AA-FAAAAAAAAAAAAAAAAAABA--- F---AAAAAAAAAAAAAAAAA---A-- ----AAAAAAAAAAAAAAAAA----A- ---------------E----------A --------------------------- --------------------------- 
--------------------------A ----AAAAAAAAAAAAAAAAA----A- ----AAAAAAAAAAAAAAAAA---A-- ----AAAAAAAAAAAAAAAAAABA--- ---ABAAAAAAAAAAAAAAAAAD---- A-AABAAAAAAAAAAAAAAAAAD---- AAAABAAAAAAAAAAAAAAAAAD---- CAAABAAAAAAAAAAAAAAAAAD---- CAAABAAAAAAAAAAAAAAAAAD---- CAAABAAAAAAAAAAAAAAAAAD---- CAA-AAAAAAAAAAAAAAAAAAD---- AA-FAAAAAAAAAAAAAAAAAABA--- A---AAAAAAAAAAAAAAAAA---A-- ----AAAAAAAAAAABAAAAA----A- ---------------B----------A --------------------------- --------------------------- 
--------------------------A ----AAAAAAAAAAAAAAAAA----A- ----AAAAAAAAAAAAAAAAA---A-- ----AAAAAAAAAAAAAAAAAABA--- ---ABAAAAAAAAAAAAAAAAAD---- A-AABAAAAAAAAAAAAAAAAAD---- AAAABAAAAAAAAAAAAAAAAAD---- CAAABAAAAAAAAAAAAAAAAAD---- CAAABAAAAAAAAAAAAAAAAAD---- CAAABAAAAAAAAAAAAAAAAAD---- CAA-AAAAAAAAAAAAAAAAAAD---- AA--AAAAAAAAAAAAAAAAAABA--- A---AAAAAAAAAAAAAAAAA---A-- ----AAAAAAAAAAAAAAAAA----A- --------------------------A --------------------------- --------------------------- 
--------------------------A ----AAAAAAAAAAAAAAAAA----A- ----AAAAAAAAAAAAAAAAA---A-- ----AAAAAAAAAAAAAAAAAABA--- ---ABAAAAAAAAAAAAAAAAAD---- A-AABAAAAAAAAAAAAAAAAAD---- AAAABAAAAAAAAAAAAAAAAAD---- CAAABAAAAAAAAAAAAAAAAAD---- CAAABAAAAAAAAAAAAAAAAAD---- CAAABAAAAAAAAAAAAAAAAAD---- CAA-AAAAAAAAAAAAAAAAAAD---- AA--AAAAAAAAAAAAAAAAABBA--- F---AAAAAAAAAAAAAAAAAB--A-- ----BAAAAAAAAAAAAAAABB---A- ----BBB------------BB-----A ------BBBBBBBBBBBBBBB------ -------BBBBBBBBBBBBB------- 
--------------------------A ----AAAAAAAAAAAAAAAAA----A- ----AAAAAAAAAAAAAAAAA---A-- ----AAAAAAAAAAAAAAAAAABA--- ----BAAAAAAAAAAAAAAAAAD---- ---ABAAAAAAAAAAAAAAAAAD---- A-AABAAAAAAAAAAAAAAAAAD---- CAAABAAAAAAAAAAAAAAAAAD---- CAAABAAAAAAAAAAAAAAAAAD---- CAA-BAAAAAAAAAAAAAAAAAD---- CA--AAAAAAAAAAAAAAAAAAD---- A---AAAAAAAAAAAAAAAAABBA--- ----AAAAAAAAAAAAAAAAAB--A-- ----BAAAAAAAAAAAAAAABB---A- ----BBB------------BB-----A ------BBBBBBBBBBBBBBB------ -------BBBBBBBBBBBBB------- 
--------------------------A ----AAAAAAAAAAAAAAAAA----A- ----AAAAAAAAAAAAAAAAA---A-- ----AAAAAAAAAAAAAAAAAABA--- ----AAAAAAAAAAAAAAAAAAD---- ----AAAAAAAAAAAAAAAAAAD---- ----AAAAAAAAAAAAAAAAAAD---- A---AAAAAAAAAAAAAAAAAAD---- A---AAAAAAAAAAAAAAAAAAD---- A---AAAAAAAAAAAAAAAAAAD---- A---AAAAAAAAAAAAAAAAAAD---- ----AAAAAAAAAAAAAAAAAABA--- ----AAAAAAAAAAAAAAAAA---A-- ----AAAAAAAAAAAAAAAAA----A- --------------------------A --------------------------- --------------------------- 
--------------------------A ----AAAAAAAAAAAAAAAAA----A- ----AAAAAAAAAAAAAAAAA---A-- ----AAAAAAAAAAAAAAAAAABA--- ----AAAAAAAAAAAAAAAAAAD---- ----AAAAAAAAAAAAAAAAAAD---- ----AAAAAAAAAAAAAAAAAAD---- ----HAAAAAAAAAAAAAAAAAD---- ----AAAAAAAAAAAAAAAAAAD---- ----GAAAAAAAAAAAAAAAAAD---- ----AAAAAAAAAAAAAAAAAAD---- ----GAAAAAAAAAAAAAAAAABA--- ----AAAAAAAAAAAAAAAAA---A-- ----AAAAAAAAAAAAAAAAA----A- --------------------------A --------------------------- --------------------------- 
--------------------------A ----AAAAAAAAAAAAAAAAA----A- ----AAAAAAAAAAAAAAAAA---A-- ----AAAAAAAAAAAAAAAAAABA--- ----AAAAAAAAAAAAAAAAAAD---- ----AAAAAAAAAAAAAAAAAAD---- ----AAAAAAAAAAAAAAAAAAD---- ----AAAAAAAAAAAAAAAAAAD---- ----AAAAAAAAAAAAAAAAAAD---- ----AAAAAAAAAAAAAAAAAAD---- ----AAAAAAAAAAAAAAAAAAD---- ----AAAAAAAAAAAAAAAAAABA--- ----AAAAAAAAAAAAAAAAA---A-- ----AAAAAAAAAAAAAAAAA----A- --------------------------A --------------------------- --------------------------- 
--------------------------A ----AAAAAAAAAAAAAAAAA----A- ----AAAAAAAAAAAAAAAAA---A-- ----AAAAAAAAAAAAAAAAAA-A--- ----AAAAAAAAAAAAAAAAAABA--- ----AAAAAAAAAAAAAAAAAABA--- ----AAAAAAAAAAAAAAAAAABA--- ----HAAAAAAAAAAAAAAAAABA--- ----AAAAAAAAAAAAAAAAAABA--- ----HAAAAAAAAAAAAAAAAABA--- ----AAAAAAAAAAAAAAAAAABA--- ----HAAAAAAAAAAAAAAAAA-A--- ----AAAAAAAAAAAAAAAAA---A-- ----AAAAAAAAAAAAAAAAA----A- --------------------------A --------------------------- --------------------------- 
--------------------------A -------------------------A- ----AAAAAAAAAAAAAAAAA---A-- ----AAAAAAAAAAAAAAAAA---A-- ----AAAAAAAAAAAAAAAAA---A-- ----AAAAAAAAAAAAAAAAA---A-- ----AAAAAAAAAAAAAAAAA---A-- ----AAAAAAAAAAAAAAAAA---A-- ----AAAAAAAAAAAAAAAAA---A-- ----AAAAAAAAAAAAAAAAA---A-- ----AAAAAAAAAAAAAAAAA---A-- ----AAAAAAAAAAAAAAAAA---A-- ----AAAAAAAAAAAAAAAAA---A-- -------------------------A- --------------------------A --------------------------- --------------------------- 
--------------------------A -------------------------A- -------------------------A- ----AAAAAAAAAAAAAAAAA----A- ----AAAAAAAAAAAAAAAAA----A- ----AAAAAAAAAAAAAAAAA----A- ----AAAAAAAAAAABBBBAA----A- ----AAAAAAAAAAAAAAAAA----A- ----AAAAAAAAAAAAAAAAA----A- ----AAAAAAAAAAAAAAAAA----A- ----AAAAAAAAAAABBBBAA----A- ----AAAAAAAAAAA----AA----A- -------------------------A- -------------------------A- --------------------------A --------------------------- --------------------------- 
--------------------------A --------------------------A --------------------------A --------------------------A --------------------------A --------------------------A --------------------------A ---------------BBBB-------A ------K--------BBBI-------A -----J-I--G----BIBB-------A ------L---G---------------A --------------------------A --------------------------A --------------------------A --------------------------A --------------------------- --------------------------- 
