model
size = 21 12 28, scale = 0.05, origin = -y
material 
  colors = A:#050 B:#7A4F38 C:#3B2F2F D:#DDD
voxels
--------------------- --------------------- --------------------- --------------------- --------------------- --------------------- --------------------- ----------A---------- ---------AAA--------- ---------AAA--------- -------AAAAAAA------- -------AAAAAAA------- 
--------------------- --------------------- --------------------- --------------------- --------------------- -------AAAAAAA------- -------AAAAAAA------- -------AAAAAAA------- -------AAAAAAA------- -------AAAAAAA------- -----AAADDDDDAAA----- -----AAAAAAAAAAA----- 
--------------------- --------------------- --------------------- --------------------- --------AAAAA-------- -----AAAAAAAAAAA----- -----AAAAAAAAAAA----- -----AAAAAAAAAAA----- -----AAAAAAAAAAA----- -----AAABBBBBAAA----- ----AADD-----DDAA---- ----AAAA-----AAAA---- 
--------------------- --------------------- --------------------- --------AAAAA-------- ------AAAAAAAAA------ ----AAAAAAAAAAAAA---- ----AAAAAAAAAAAAA---- ----AAAAAAAAAAAAA---- ----AAAAAAAAAAAAA---- ----AABBBBBBBBBAA---- ---ADD---------DDA--- ---AAA---------AAA--- 
--------------------- --------------------- --------AAAAA-------- ------AAAAAAAAA------ ----AAAAAAAAAAAAA---- ---AAAAAAAAAAAAAAA--- ---AAAAAAAAAAAAAAA--- ---AAAAAAAAAAAAAAA--- ---AAAAAAAAAAAAAAA--- ---ABBBBBBBBBBBBBA--- --AD-------------DA-- --AA-------------AA-- 
--------------------- --------AAAAA-------- ------AAAAAAAAA------ -----AAAAAAAAAAA----- ----AAAAAAAAAAAAA---- --AAAAAAAAAAAAAAAAA-- --AAAAAAAAAAAAAAAAA-- --AAAAAAAAAAAAAAAAA-- --AAAAAAAAAAAAAAAAA-- --AABBBBBCCCCCBBBAA-- -AAD-------------DAA- -AAA-------------AAA- 
--------AAAAA-------- -------AAAAAAA------- -----AAAAAAAAAAA----- ----AAAAAAAAAAAAA---- ---AAAAAAAAAAAAAAA--- --AAAAAAAAAAAAAAAAA-- --AAAAAAAAAAAAAAAAA-- --AAAAAAAAAAAAAAAAA-- --AAAAAAAAAAAAAAAAA-- --ABBBBBCCCCCCCBBBA-- -AD---------------DA- -AA---------------AA- 
-------AAAAAAA------- ------AAAAAAAAA------ -----AAAAAAAAAAA----- ----AAAAAAAAAAAAA---- ---AAAAAAAAAAAAAAA--- -AAAAAAAAAAAAAAAAAAA- -AAAAAAAAAAAAAAAAAAA- -AAAAAAAAAAAAAAAAAAA- -AAAAAAAAAAAAAAAAAAA- -AABBBBCCCCCCCCCBBAA- AAD---------------DAA AAA---------------AAA 
------AAAAAAAAA------ -----AAAAAAAAAAA----- ----AAAAAAAAAAAAA---- ---AAAAAAAAAAAAAAA--- --AAAAAAAAAAAAAAAAA-- -AAAAAAAAAAAAAAAAAAA- -AAAAAAAAAAAAAAAAAAA- -AAAAAAAAAAAAAAAAAAA- -AAAAAAAAAAAAAAAAAAA- -ABBBBCCCCCCCCCCCBBA- AD-----------------DA AA-----------------AA 
------AAAAAAAAA------ -----AAAAAAAAAAA----- ----AAAAAAAAAAAAA---- ---AAAAAAAAAAAAAAA--- --AAAAAAAAAAAAAAAAA-- -AAAAAAAAAAAAAAAAAAA- -AAAAAAAAAAAAAAAAAAA- -AAAAAAAAAAAAAAAAAAA- AAAAAAAAAAAAAAAAAAAAA AABBBBCCCCCCCCCCCBBAA AD-----------------DA AA-----------------AA 
------AAAAAAAAA------ -----AAAAAAAAAAA----- ----AAAAAAAAAAAAA---- ---AAAAAAAAAAAAAAA--- --AAAAAAAAAAAAAAAAA-- -AAAAAAAAAAAAAAAAAAA- -AAAAAAAAAAAAAAAAAAA- AAAAAAAAAAAAAAAAAAAAA AAAAAAAAAAAAAAAAAAAAA AABBBBCCCCCCCCCCCBBAA AD-----------------DA AA-----------------AA 
------AAAAAAAAA------ -----AAAAAAAAAAA----- ----AAAAAAAAAAAAA---- ---AAAAAAAAAAAAAAA--- --AAAAAAAAAAAAAAAAA-- -AAAAAAAAAAAAAAAAAAA- -AAAAAAAAAAAAAAAAAAA- -AAAAAAAAAAAAAAAAAAA- AAAAAAAAAAAAAAAAAAAAA AABBBBCCCCCCCCCCCBBAA AD-----------------DA AA-----------------AA 
------AAAAAAAAA------ -----AAAAAAAAAAA----- ----AAAAAAAAAAAAA---- ---AAAAAAAAAAAAAAA--- --AAAAAAAAAAAAAAAAA-- -AAAAAAAAAAAAAAAAAAA- -AAAAAAAAAAAAAAAAAAA- -AAAAAAAAAAAAAAAAAAA- -AAAAAAAAAAAAAAAAAAA- -ABBBBCCCCCCCCCCCBBA- AD-----------------DA AA-----------------AA 
-------AAAAAAA------- ------AAAAAAAAA------ -----AAAAAAAAAAA----- ----AAAAAAAAAAAAA---- ---AAAAAAAAAAAAAAA--- -AAAAAAAAAAAAAAAAAAA- -AAAAAAAAAAAAAAAAAAA- -AAAAAAAAAAAAAAAAAAA- -AAAAAAAAAAAAAAAAAAA- -AABBBBCCCCCCCCCBBAA- AAD---------------DAA AAA---------------AAA 
--------AAAAA-------- -------AAAAAAA------- -----AAAAAAAAAAA----- ----AAAAAAAAAAAAA---- ---AAAAAAAAAAAAAAA--- --AAAAAAAAAAAAAAAAA-- --AAAAAAAAAAAAAAAAA-- --AAAAAAAAAAAAAAAAA-- --AAAAAAAAAAAAAAAAA-- --ABBBBBCCCCCCCBBBA-- -AD---------------DA- -AA---------------AA- 
--------------------- --------AAAAA-------- ------AAAAAAAAA------ -----AAAAAAAAAAA----- ----AAAAAAAAAAAAA---- --AAAAAAAAAAAAAAAAA-- --AAAAAAAAAAAAAAAAA-- --AAAAAAAAAAAAAAAAA-- --AAAAAAAAAAAAAAAAA-- --AABBBBBCCCCCBBBAA-- -AAD-------------DAA- -AAA-------------AAA- 
--------------------- ---------AAA--------- --------AAAAA-------- ------AAAAAAAAA------ ----AAAAAAAAAAAAA---- ---AAAAAAAAAAAAAAA--- ---AAAAAAAAAAAAAAA--- ---AAAAAAAAAAAAAAA--- ---AAAAAAAAAAAAAAA--- ---ABBBBBBBBBBBBBA--- --AD-------------DA-- --AA-------------AA-- 
--------------------- ---------AAA--------- --------------------- --------AAAAA-------- ------AAAAAAAAA------ ----AAAAAAAAAAAAA---- ----AAAAAAAAAAAAA---- ----AAAAAAAAAAAAA---- ----AAAAAAAAAAAAA---- ----AABBBBBBBBBAA---- ---ADD---------DDA--- ---AAA---------AAA--- 
--------------------- ---------AAA--------- --------------------- --------------------- --------AAAAA-------- -----AAAAAAAAAAA----- -----AAAAAAAAAAA----- -----AAAAAAAAAAA----- -----AAAAAAAAAAA----- -----AAABBBBBAAA----- ----AADD-----DDAA---- ----AAAA-----AAAA---- 
--------------------- ---------AAA--------- ---------AAA--------- --------------------- --------------------- -------AAAAAAA------- -------AAAAAAA------- -------AAAAAAA------- -------AAAAAAA------- -------AAAAAAA------- -----AAADDDDDAAA----- -----AAAAAAAAAAA----- 
--------------------- --------------------- ---------AAA--------- --------------------- --------------------- --------------------- --------------------- ----------A---------- ---------AAA--------- ---------AAA--------- -------AAAAAAA------- -------AAAAAAA------- 
--------------------- --------------------- ---------AAA--------- ---------AAA--------- --------------------- --------------------- --------------------- --------------------- --------------------- ---------AAA--------- --------------------- --------------------- 
--------------------- --------------------- --------------------- ---------AAA--------- --------------------- --------------------- --------------------- --------------------- --------------------- ---------AAA--------- ---------AAA--------- --------------------- 
--------------------- --------------------- --------------------- ---------AAA--------- ---------AAA--------- --------------------- --------------------- --------------------- --------------------- --------------------- ---------AAA--------- ---------AAA--------- 
--------------------- --------------------- --------------------- --------------------- ---------AAA--------- --------------------- --------------------- --------------------- --------------------- --------------------- --------------------- ---------AAA--------- 
--------------------- --------------------- --------------------- --------------------- ---------AAA--------- ---------AAA--------- --------------------- --------------------- --------------------- --------------------- ---------AAA--------- ---------AAA--------- 
--------------------- --------------------- --------------------- --------------------- --------------------- ---------AAA--------- ---------AAA--------- --------------------- --------------------- ---------AAA--------- ---------AAA--------- --------------------- 
--------------------- --------------------- --------------------- --------------------- --------------------- --------------------- ---------AAA--------- ---------AAA--------- ---------AAA--------- ---------AAA--------- --------------------- --------------------- 
