model
size = 21 12 28, scale = 0.05, origin = -y
material 
  colors = A:#222 B:#050 C:#7A4F38 D:#3B2F2F
voxels
--------------------- --------------------- --------------------- --------------------- --------------------- --------------------- --------------------- ----------A---------- ---------AAA--------- ---------AAA--------- -------AAAAAAA------- -------AAAAAAA------- 
--------------------- --------------------- --------------------- --------------------- --------------------- -------AAAAAAA------- -------AAAAAAA------- -------AAAAAAA------- -------AAAAAAA------- -------AAAAAAA------- -----AAAAAAAAAAA----- -----AAAAAAAAAAA----- 
--------------------- --------------------- --------------------- --------------------- --------AAAAA-------- -----AAAAAAAAAAA----- -----AABBAAAAAAA----- -----AABBAAAAAAA----- -----AABBAAAAAAA----- -----AABCCCCCAAA----- ----AAAA-----AABA---- ----AAAA-----AAAA---- 
--------------------- --------------------- --------------------- --------AAAAA-------- ------AAAAAAAAA------ ----AAAAAAAAAAAAA---- ----AAABBBBBBBBAA---- ----AAABBBBBBBAAA---- ----AAABBBBBBAAAA---- ----AACCCCCCCCCAA---- ---AAA---------AAA--- ---AAA---------AAA--- 
--------------------- --------------------- --------AAAAA-------- ------AAAAAAAAA------ ----AAAAAAAAAAAAA---- ---AAAAAAAAAAAAAAA--- ---AAAABBBBBBAAAAA--- ---AAAABBBBBBAAAAA--- ---AAAABBBBBBAAAAA--- ---ACCCCCCCCCCCCCA--- --AA-------------AA-- --AA-------------AA-- 
--------------------- --------AAAAA-------- ------AAAAAAAAA------ -----AAAAAAAAAAA----- ----AAAAAAAAAAAAA---- --AAAAAAAAAAAAAAAAA-- --AAAAABBBBBBBBBBBA-- --AAAAABBBBBBBBAAAA-- --AAAAABBBBBBBBBBBA-- --AACCCCCDDDDDCCCBA-- -AAA-------------AAA- -AAA-------------AAA- 
--------AAAAA-------- -------AAAAAAA------- -----AAAAAAAAAAA----- ----AAAAAAAAAAAAA---- ---AAAAAAAAAAAAAAA--- --AAAAAAAAAAAAAAAAA-- --AAAAABBBBBBBBBBBA-- --AAAAABBBBBBBAAAAA-- --AAAAABBBBBBBBBBBA-- --ACCCCCDDDDDDDCCCA-- -AA---------------AA- -AA---------------AA- 
-------AAAAAAA------- ------AAAAAAAAA------ -----AAAAAAAAAAA----- ----AAAAAAAAAAAAA---- ---AAAAAAAAAAAAAAA--- -AAAAAAAAAAAAAAAAAAA- -AAAAAABBBBBBBBBBBBA- -AAAAAABBBBBBBAAAAAA- -AAAAAABBBBBBBBBBBAA- -ACCCCCDDDDDDDDDCCAA- AAA---------------AAA AAA---------------AAA 
------AAAAAAAAA------ -----AAAAAAAAAAA----- ----AAAAAAAAAAAAA---- ---AAAAAAAAAAAAAAA--- --AAAAAAAAAAAAAAAAA-- -AAAAAAAAAAAAAAAAAAA- -AAAAAABBBBBBBBBBBBA- -AAAAAABBBBBBAAAAAAA- -AAAAAABBBBBBBBBBBAA- -ACCCCCDDDDDDDDDDCCA- AA-----------------AA AA-----------------AA 
------AAAAAAAAA------ -----AAAAAAAAAAA----- ----AAAAAAAAAAAAA---- ---AAAAAAAAAAAAAAA--- --AAAAAAAAAAAAAAAAA-- -AAAAAAAAAAAAAAAAAAA- -AAAAAABBBBBBBBBBBBA- -AAAAAABBBBBBAAAAAAA- AAAAAAABBBBBBBBBBBBAA AACCCCCDDDDDDDDDDCCAA AA-----------------AA AA-----------------AA 
------AAAAAAAAA------ -----AAAAAAAAAAA----- ----AAAAAAAAAAAAA---- ---AAAAAAAAAAAAAAA--- --AAAAAAAAAAAAAAAAA-- -AAAAAAAAAAAAAAAAAAA- -AAAAAABBBBBBBBBBBBA- AAAAAAABBBBBBAAAAAAAA AAAAAAABBBBBBBBBBBBAA AACCCCCDDDDDDDDDDCCAA AA-----------------AA AA-----------------AA 
------AAAAAAAAA------ -----AAAAAAAAAAA----- ----AAAAAAAAAAAAA---- ---AAAAAAAAAAAAAAA--- --AAAAAAAAAAAAAAAAA-- -AAAAAAAAAAAAAAAAAAA- -AAAAAABBBBBBBBBBBBA- -AAAAAABBBBBBAAAAAAA- AAAAAAABBBBBBBBBBBBAA AACCCCCDDDDDDDDDDCCAA AA-----------------AA AA-----------------AA 
------AAAAAAAAA------ -----AAAAAAAAAAA----- ----AAAAAAAAAAAAA---- ---AAAAAAAAAAAAAAA--- --AAAAAAAAAAAAAAAAA-- -AAAAAAAAAAAAAAAAAAA- -AAAAAABBBBBBBBBBBBA- -AAAAAABBBBBBAAAAAAA- -AAAAAABBBBBBBBBBBBA- -ACCCCCDDDDDDDDDDCCA- AA-----------------AA AA-----------------AA 
-------AAAAAAA------- ------AAAAAAAAA------ -----AAAAAAAAAAA----- ----AAAAAAAAAAAAA---- ---AAAAAAAAAAAAAAA--- -AAAAAAAAAAAAAAAAAAA- -AABBBBBBBBBBBBBBBBA- -AABBBBBBBBBBBAAAAAA- -AABBBBBBBBBBBBBBBBA- -AACCCCDDDDDDDDDCCBA- AAA---------------AAA AAA---------------AAA 
--------AAAAA-------- -------AAAAAAA------- -----AAAAAAAAAAA----- ----AAAAAAAAAAAAA---- ---AAAAAAAAAAAAAAA--- --AAAAAAAAAAAAAAAAA-- --ABBBBBBBBBBBBBBBA-- --ABBBBBBBBBBBAAAAA-- --ABBBBBBBBBBBBBBBA-- --ACCCCCDDDDDDDCCCA-- -AA---------------AA- -AA---------------AA- 
--------------------- --------AAAAA-------- ------AAAAAAAAA------ -----AAAAAAAAAAA----- ----AAAAAAAAAAAAA---- --AAAAAAAAAAAAAAAAA-- --ABBBBBBBBBBBBBBBA-- --ABBBBBBBBBBBBAAAA-- --AAABBBBBBBBBBBBBA-- --AACCCCCDDDDDCCCBA-- -AAA-------------AAA- -AAA-------------AAA- 
--------------------- ---------AAA--------- --------AAAAA-------- ------AAAAAAAAA------ ----AAAAAAAAAAAAA---- ---AAAAAAAAAAAAAAA--- ---AABBBBBBBBBBBBA--- ---AABBBBBBBBBBBAA--- ---AABBBBBBBBBBBBA--- ---ACCCCCCCCCCCCCA--- --AA-------------AA-- --AA-------------AA-- 
--------------------- ---------AAA--------- --------------------- --------AAAAA-------- ------AAAAAAAAA------ ----AAAAAAAAAAAAA---- ----ABBBBBBBBBBBA---- ----ABBBBBBBBBBBA---- ----ABBBBBBBBBBBA---- ----AACCCCCCCCCBA---- ---AAA---------AAA--- ---AAA---------AAA--- 
--------------------- ---------AAA--------- --------------------- --------------------- --------AAAAA-------- -----AAAAAAAAAAA----- -----AABBBBBAAAA----- -----AABBBBBAAAA----- -----AABBBBBAAAA----- -----AABCCCCCAAA----- ----AAAA-----AAAA---- ----AAAA-----AAAA---- 
--------------------- ---------AAA--------- ---------AAA--------- --------------------- --------------------- -------AAAAAAA------- -------AAAAAAA------- -------AAAAAAA------- -------AAAAAAA------- -------AAAAAAA------- -----AAAAAAAAAAA----- -----AAAAAAAAAAA----- 
--------------------- --------------------- ---------AAA--------- --------------------- --------------------- --------------------- --------------------- ----------A---------- ---------AAA--------- ---------AAA--------- -------AAAAAAA------- -------AAAAAAA------- 
--------------------- --------------------- ---------AAA--------- ---------AAA--------- --------------------- --------------------- --------------------- --------------------- --------------------- ---------AAA--------- --------------------- --------------------- 
--------------------- --------------------- --------------------- ---------AAA--------- --------------------- --------------------- --------------------- --------------------- --------------------- ---------AAA--------- ---------AAA--------- --------------------- 
--------------------- --------------------- --------------------- ---------AAA--------- ---------AAA--------- --------------------- --------------------- --------------------- --------------------- --------------------- ---------AAA--------- ---------AAA--------- 
--------------------- --------------------- --------------------- --------------------- ---------AAA--------- --------------------- --------------------- --------------------- --------------------- --------------------- --------------------- ---------AAA--------- 
--------------------- --------------------- --------------------- --------------------- ---------AAA--------- ---------AAA--------- --------------------- --------------------- --------------------- --------------------- ---------AAA--------- ---------AAA--------- 
--------------------- --------------------- --------------------- --------------------- --------------------- ---------AAA--------- ---------AAA--------- --------------------- --------------------- ---------AAA--------- ---------AAA--------- --------------------- 
--------------------- --------------------- --------------------- --------------------- --------------------- --------------------- ---------AAA--------- ---------AAA--------- ---------AAA--------- ---------AAA--------- --------------------- --------------------- 
