model
size = 32, scale = 0.05, origin = -y
material 
  colors = A:#FCFAF2 B:#E83015 C:#111
voxels
398-4A27-6A154-6B27-4B700-4A26-8A23-10A21-12A20-12A22-3(8C24-)8C22-12B20-12B21-10B23-8B26-4B541-2A27-8A22-12A19-14A18-14A17-16A16-16A17-3(14C18-)14C17-16B16-16B17-14B18-14B19-12B22-8B27-2B444-6A24-10A20-14A17-16A16-16A15-18A14-18A13-20A14-16C15-18C14-18C15-16C14-20B13-18B14-18B15-16B16-16B17-14B20-10B24-6B377-8A22-12A19-14A17-16A15-18A13-20A12-20A11-22A10-22A11-3(20C12-)20C11-22B10-22B11-20B12-20B13-18B15-16B17-14B19-12B22-8B312-8A22-12A19-14A16-18A14-18A13-20A11-22A10-22A9-24A8-24A9-3(22C10-)22C9-24B8-24B9-22B10-22B11-20B13-18B14-18B16-14B19-12B22-8B249-6A23-12A19-14A16-18A13-20A12-20A11-22A9-2(24A8-)24A7-26A7-3(24C8-)24C7-26B7-2(24B8-)24B9-22B11-20B12-20B13-18B16-14B19-12B23-6B188-2A26-10A20-14A16-18A13-20A11-22A10-22A9-24A8-24A7-3(26A6-)4(26C6-)2(26B6-)26B7-24B8-24B9-22B10-22B11-20B13-18B16-14B20-10B26-2B155-8A21-14A17-16A15-18A13-20A11-22A9-24A7-2(26A6-)26A5-28A4-28A5-26C5-28C4-28C5-26C5-28B4-28B5-2(26B6-)26B7-24B9-22B11-20B13-18B15-16B17-14B21-8B122-4A24-12A18-16A15-18A13-20A11-22A9-24A7-26A6-26A5-4(28A4-)4(28C4-)3(28B4-)28B5-26B6-26B7-24B9-22B11-20B13-18B15-16B18-12B24-4B90-8A21-14A17-16A14-20A11-22A9-24A8-24A7-26A5-2(28A4-)28A3-2(30A2-)4(30C2-)30B2-30B3-2(28B4-)28B5-26B7-24B8-24B9-22B11-20B14-16B17-14B21-8B87-10A20-14A16-18A13-20A11-22A9-24A7-26A6-26A5-28A4-28A3-3(30A2-)4(30C2-)2(30B2-)30B3-28B4-28B5-26B6-26B7-24B9-22B11-20B13-18B16-14B20-10B57-4A24-12A18-16A15-18A12-22A9-24A8-24A7-26A5-28A4-28A3-3(30A2-)6(30C2-)2(30B2-)30B3-28B4-28B5-26B7-24B8-24B9-22B12-18B15-16B18-12B24-4B27-6A23-12A18-16A14-20A11-22A9-24A7-26A6-26A5-28A4-28A3-2(30A2-)2(30C2-)30C-64A-C28AC2-C28BC2-30C2(2-30B)3-28B4-28B5-26B6-26B7-24B9-22B11-20B14-16B18-12B23-6B25-8A21-14A17-16A14-20A11-22A9-24A7-26A6-26A5-28A3-3(30A2-)30C2-30C-128A-C28BC2-16C13BC2-B15C14B2(2-30B)3-28B5-26B6-26B7-24B9-22B11-20B14-16B17-2(14B21-8B24-8A21-14A16-18A13-20A11-22A9-24A7-26A5-28A4-28A3-2(30A2-)30C2-30C-161A30BA-2(30C2-)30B2-30B3-28B4-28B5-26B7-24B9-22B11-20B13-18B16-)14B21-8B24-8A21-14A17-16A14-20A11-22A9-24A7-26A6-26A5-28A3-3(30A2-)30C2-30C-128A-2(30C2-)2(30B2-)30B3-28B5-26B6-26B7-24B9-22B11-20B14-16B17-14B21-8B25-6A23-12A18-16A14-20A11-22A9-24A7-26A6-26A5-28A4-28A3-2(30A2-)C12A17C2(2-30C)-64A-C28AC2(2-30C)2(2-30B)3-28B4-28B5-26B6-26B7-24B9-22B11-20B14-16B18-12B23-6B27-4A24-12A18-16A15-18A12-22A9-24A8-24A7-26A5-28A4-28A3-3(30A2-)C3A26C5(2-30C)3(2-30B)3-28B4-28B5-26B7-24B8-24B9-22B12-18B15-16B18-12B24-4B57-10A20-14A16-18A13-20A11-22A9-24A7-26A6-26A5-28A4-28A3-3(30A2-)4(30C2-)2(30B2-)30B3-28B4-28B5-26B6-26B7-24B9-22B11-20B13-18B16-14B20-10B87-8A21-14A17-16A14-20A11-22A9-24A8-24A7-26A5-2(28A4-)28A3-2(30A2-)4(30C2-)30B2-30B3-2(28B4-)28B5-26B7-24B8-24B9-22B11-20B14-16B17-14B21-8B90-4A24-12A18-16A15-18A13-20A11-22A9-24A7-26A6-26A5-4(28A4-)4(28C4-)3(28B4-)28B5-26B6-26B7-24B9-22B11-20B13-18B15-16B18-12B24-4B122-8A21-14A17-16A15-18A13-20A11-22A9-24A7-2(26A6-)26A5-28A4-28A5-26C5-28C4-28C5-26C5-28B4-28B5-2(26B6-)26B7-24B9-22B11-20B13-18B15-16B17-14B21-8B155-2A26-10A20-14A16-18A13-20A11-22A10-22A9-24A8-24A7-3(26A6-)4(26C6-)2(26B6-)26B7-24B8-24B9-22B10-22B11-20B13-18B16-14B20-10B26-2B188-6A23-12A19-14A16-18A13-20A12-20A11-22A9-2(24A8-)24A7-26A7-3(24C8-)24C7-26B7-2(24B8-)24B9-22B11-20B12-20B13-18B16-14B19-12B23-6B249-8A22-12A19-14A16-18A14-18A13-20A11-22A10-22A9-24A8-24A9-3(22C10-)22C9-24B8-24B9-22B10-22B11-20B13-18B14-18B16-14B19-12B22-8B312-8A22-12A19-14A17-16A15-18A13-20A12-20A11-22A10-22A11-3(20C12-)20C11-22B10-22B11-20B12-20B13-18B15-16B17-14B19-12B22-8B377-6A24-10A20-14A17-16A16-16A15-18A14-18A13-20A14-16C15-18C14-18C15-16C14-20B13-18B14-18B15-16B16-16B17-14B20-10B24-6B444-2A27-8A22-12A19-14A18-14A17-16A16-16A17-3(14C18-)14C17-16B16-16B17-14B18-14B19-12B22-8B27-2B541-4A26-8A23-10A21-12A20-12A22-3(8C24-)8C22-12B20-12B21-10B23-8B26-4B700-4A27-6A154-6B27-4B398-
