model
size = 27 30 27, scale = 0.05, origin = -y
material 
  colors = A:#040 B:#050 C:#030 D:#696 E:#930 F:#700 G:#FF3 H:#3C6 I:#500
voxels
--------------------------- --------------------------- --------------------------- --------------------------- --------------------------- --------------------------- --------------------------- --------------------------- --------------------------- --------------------------- --------------------------- --------------------------- --------------------------- --------------------------- --------------------------- --------------------------- --------------------------- ----------GBBBBBB---------- --------------------------- --------------------------- --------------------------- --------------------------- --------------------------- --------------------------- --------------------------- --------------------------- --------------------------- --------------------------- --------------------------- --------------------------- 
--------------------------- --------------------------- --------------------------- --------------------------- --------------------------- --------------------------- --------------------------- --------------------------- --------------------------- --------------------------- --------------------------- --------------------------- --------------------------- --------------------------- --------------------------- --------------------------- ----------AAAAGAA---------- -------BBBBBBBBBBBGB------- --------------------------- --------------------------- --------------------------- --------------------------- --------------------------- --------------------------- --------------------------- --------------------------- --------------------------- --------------------------- --------------------------- --------------------------- 
--------------------------- --------------------------- --------------------------- --------------------------- --------------------------- --------------------------- --------------------------- --------------------------- --------------------------- --------------------------- --------------------------- --------------------------- --------------------------- --------------------------- --------------------------- ----------CCCCCCC---------- --------AAAAAAAAAAA-------- ------BBBBBBBBBBBBBBB------ ----------AAAAAAA---------- --------------------------- --------------------------- --------------------------- --------------------------- --------------------------- --------------------------- --------------------------- --------------------------- --------------------------- --------------------------- --------------------------- 
--------------------------- --------------------------- --------------------------- --------------------------- --------------------------- --------------------------- --------------------------- --------------------------- --------------------------- --------------------------- --------------------------- --------------------------- --------------------------- --------------------------- --------------------------- --------CCCCCCCCCCC-------- ------AAAAAAAAAAAAAAA------ ----BBBBBBBBBBBBBBBBBBB---- --------AAAAAAAAAAA-------- --------------------------- --------------------------- --------------------------- --------------------------- --------------------------- --------------------------- --------------------------- --------------------------- --------------------------- --------------------------- --------------------------- 
--------------------------- --------------------------- --------------------------- --------------------------- --------------------------- --------------------------- --------------------------- --------------------------- --------------------------- --------------------------- --------------------------- --------------------------- --------------------------- --------------------------- --------------------------- ------GCCCCCCCCCCCCCG------ -----AAAAAAAAAAAAAAAAA----- ---BBBBBBBBBBBBBBBBBBBBB--- ------AAAAAAAAAAAAAAA------ ----------BBBGBBB---------- --------------------------- --------------------------- --------------------------- --------------------------- --------------------------- --------------------------- --------------------------- --------------------------- --------------------------- --------------------------- 
--------------------------- --------------------------- --------------------------- --------------------------- --------------------------- --------------------------- --------------------------- --------------------------- --------------------------- --------------------------- --------------------------- --------------------------- --------------------------- --------------------------- --------------------------- -----CCCCCCCCCCCCCCCCC----- ----AAAAAAAAAAAAAAAAAAA---- ---BBBBBBBBBBBBBBBBBBBBG--- -----AAAAAAAAAAAAAAAAA----- --------BBBBBBBBBBB-------- -----------AAAAA----------- --------------------------- --------------------------- --------------------------- --------------------------- --------------------------- --------------------------- --------------------------- --------------------------- --------------------------- 
-----------HDDDD----------- -----------HHDDD----------- ------------HDD------------ --------------------------- --------------------------- --------------------------- --------------------------- --------------------------- --------------------------- --------------------------- --------------------------- --------------------------- --------------------------- --------------------------- --------------------------- ----CCCCCCCCCCCCCCCCCCC---- ---AAAAAAAAAAAAAAAAAAAAA--- --BBBBBBBBBBBBBBBBBBBBBBB-- ----AAAAAAAAAAAAAAAAAAA---- -------GBBBBBBBBBBBB------- ---------AAAAAAAGA--------- -----------AAAAA----------- --------------------------- --------------------------- --------------------------- --------------------------- --------------------------- --------------------------- --------------------------- --------------------------- 
---------DD-----DH--------- ---------DD-----DD--------- ---------HDD---DDH--------- ----------DDDDHDD---------- -----------DHDDD----------- --------------------------- --------------------------- --------------------------- --------------------------- --------------------------- --------------------------- --------------------------- --------------------------- --------------------------- --------------------------- ----CCCCCCCCCCCCCCCCCCC---- ---AAAAAAAAAAAAAAAAAAAAA--- -BBBBBBBBBBBBBBBBBBBBBBBBB- ----AAAAAAAAAAAAAAAAAAA---- ------BBBBBBBBBBBBBBB------ -------AAAAAAAAAAAAA------- ---------AAAAAAAAA--------- -----------BBBBB----------- --------------------------- --------------------------- --------------------------- --------------------------- --------------------------- --------------------------- --------------------------- 
--------D---------D-------- --------DD-------DD-------- --------DDD-----HHD-------- ---------DDD---HDH--------- ----------HDDDDDD---------- -----------DDHDD----------- --------------------------- --------------------------- --------------------------- --------------------------- --------------------------- --------------------------- --------------------------- --------------------------- --------------------------- ---CCCCCCCCCCCCCCCCCCCCC--- --AAAAAAAAAAAAAAAAAAAAAAA-- -BBBBBBBBBBBBBBBBBBBBBBBBB- ---AAAAAAAAAAAAAAAAAAAAA--- -----BBBBBBBBBBBBBBBBB----- -------AAAAAAAAAAAAA------- --------AAAAAAAAAAA-------- ---------BBBBBBBBB--------- -----------AAGAA----------- --------------------------- --------------------------- --------------------------- --------------------------- --------------------------- --------------------------- 
-------DD---------HD------- -------DD---------DD------- -------DDD-------DDH------- --------DDD-----DDD-------- ---------DDD---DDD--------- ----------DDDDDDH---------- -----------DDDDD----------- --------------------------- --------------------------- --------------------------- --------------------------- --------------------------- --------------------------- --------------------------- --------------------------- ---CCCCCCCCCCCCCCCCCCCCC--- --AAAAAAAAAAAAAAAAAAAAAAA-- -BBBBBBBBBBBBBBBBBBBBBBBBB- ---AAAAAAAAAAAAAAAAAAAAA--- -----BBBBBBBBBBBBBBBBB----- ------AAAAAAAAAAAAAAA------ -------AAAAAAAAAAAAA------- --------BBBBBBBBBBB-------- ----------AAAAAAA---------- -----------BBBBB----------- --------------------------- --------------------------- --------------------------- --------------------------- --------------------------- 
-------D-----------D------- -------D-----------D------- -------HD---------DD------- -------DDD-------DDD------- --------DDD-----DDD-------- ---------DDD---DDD--------- ----------HDDDDDD---------- --------------------------- --------------------------- --------------------------- --------------------------- --------------------------- --------------------------- --------------------------- --------------------------- --CCCCCCCCCCCCCCCCCCCCCCC-- -GAAAAAAAAAAAAAAAAAAAAAAAA- BBBBBBBBBBBBBBBBBBBBBBBBBBB --AAAAAAAAAAAAAAAAAAAAAAA-- ----GBBBBBBBBBBBBBBBBBB---- ------AAAAAAAAAAAAAAA------ -------AAAAAAAAAAAAA------- --------BBBBBBBBBBB-------- ---------AAAAAAAAG--------- ----------BBBBBBB---------- ------------AAG------------ --------------------------- --------------------------- --------------------------- --------------------------- 
------DD-----------DD------ ------DD-----------DD------ -------DD---------DD------- -------DDD-------DDD------- -------DDDD-----DDDD------- --------DDDD---DDDD-------- ---------DDDDDDDDD--------- ------------EFF------------ ------------FFF------------ ------------FEF------------ ------------EIF------------ ------------FFE------------ ------------FIF------------ ------------IFI------------ ------------IIF------------ --CCCCCCCCCCCCCCCCCCCCCCC-- -AAAAAAAAAAAAAAAAAAAAAAAAA- BBBBBBBBBBBBBBBBBBBBBBBBBBB --AAAAAAAAAAAAAAAAAAAAAAA-- ----BBBBBBBBBBBBBBBBBBB---- -----AAAAAAAAAAAAAAAAA----- ------AAAAAAAAAAAAAAA------ -------BBBBBBBBBBBBB------- --------AAAAAAAAAAA-------- ---------BBBBBBBBB--------- -----------AAAAA----------- ------------BBB------------ --------------------------- --------------------------- --------------------------- 
------DD-----------DD------ ------DD-----------DD------ ------DDD---------DDD------ -------DDD-------DDH------- -------DDDD-----DDDD------- --------DDDD---DDDD-------- ---------DDDDDDDDD--------- -----------EEEFE----------- -----------FFEFF----------- -----------EEEFI----------- -----------FEEFF----------- -----------IEEEE----------- -----------FEFFI----------- -----------IEFFI----------- -----------FEFFF----------- --CCCCCCCCCCCCCCCCCCCCCCC-- -AAAAAAAAAAAAAAAAAAAAAAAAA- BBBBBBBBBBBBBBBBBBBBBBBBBBB --AAAAAAAAAAAAAAAAAAAAAAA-- ----BBBBBBBBBBBBBBBBBBG---- -----AAAAAAAAAAAAAAAAA----- ------AAAAAAAAAAAAAAA------ -------BBBBBBBBBBBBB------- --------GAAAAAAAAAA-------- ---------BBBBBBBBB--------- ----------AAAAAAA---------- -----------GBBBB----------- ------------AAA------------ -------------B------------- --------------------------- 
------HD-----------DD------ ------DD-----------DD------ ------DDD---------DDD------ -------DDD-------DDD------- -------HDDD-----DDDD------- --------DDDD---DDDH-------- ---------DDDDDDDDD--------- -----------FEEEF----------- -----------FEEFF----------- -----------FEEEE----------- -----------EEEEF----------- -----------EEEEF----------- -----------IEEEF----------- -----------IEEEF----------- -----------EEEEI----------- --CCCCCCCCCCCCCCCCCCCCCCC-- -AAAAAAAAAAAAAAAAAAAAAAAAA- BBBBBBBBBBBBBBBBBBBBBBBBBBB --GAAAAAAAAAAAAAAAAAAAAAA-- ----BBBBBBBBBBBBBBBBBBB---- -----AAAAAAAAAAAAAAAAA----- ------AAAAAAAAAAAAAAG------ -------BBBBBBBBBBBBB------- --------AAAAAAAAAAA-------- ---------BBBBBBBBG--------- ----------AAAAAAA---------- -----------BBBBB----------- ------------AAA------------ ------------BBB------------ -------------B------------- 
------DD-----------DD------ ------DD-----------DD------ ------HDD---------DDH------ -------DDD-------DDD------- -------DDDD-----DDDD------- --------DDDD---DDDD-------- ---------DDDDDDDDD--------- -----------FEEEE----------- -----------EEEEF----------- -----------IEEEF----------- -----------FEEEI----------- -----------EEEEI----------- -----------IEEEE----------- -----------FEEEI----------- -----------IEEEE----------- --GCCCCCCCCCCCCCCCCCCCCCC-- -AAAAAAAAAAAAAAAAAAAAAAAAA- BBBBBBBBBBBBBBBBBBBBBBBBBBB --AAAAAAAAAAAAAAAAAAAAAAA-- ----BBBBBBBBBBBBBBBBBBB---- -----AAAAAAAAAAAAAAAAA----- ------GAAAAAAAAAAAAAA------ -------BBBBBBBBBBBBB------- --------AAAAAAAAAAA-------- ---------BBBBBBBBB--------- ----------AAAAAAA---------- -----------BBBBB----------- ------------AAA------------ -------------B------------- --------------------------- 
------DD-----------DD------ ------DD-----------DD------ -------DD---------DD------- -------DDD-------DDD------- -------DDDD-----DDDH------- --------HDDD---DDDD-------- ---------DDDDDDDDD--------- ------------EFF------------ ------------FEF------------ ------------EII------------ ------------FEI------------ ------------FFI------------ ------------IFF------------ ------------III------------ ------------FII------------ --CCCCCCCCCCCCCCCCCCCCCCC-- -AAAAAAAAAAAAAAAAAAAAAAAAA- BBBBBBBBBBBBBBBBBBBBBBBBBBB --AAAAAAAAAAAAAAAAAAAAAAA-- ----BBBBBBBBBBBBBBBBBBB---- -----AAAAAAAAAAAAAAAAA----- ------AAAAAAAAAAAAAAA------ -------BBBBBBBBBBBBB------- --------AAAAAAAAAAA-------- ---------GBBBBBBBB--------- -----------AAAAA----------- ------------BBB------------ --------------------------- --------------------------- --------------------------- 
-------D-----------D------- -------D-----------D------- -------DD---------DD------- -------DDD-------DDD------- --------DDD-----DDD-------- ---------DDD---DDH--------- ----------DDDDDDD---------- --------------------------- --------------------------- --------------------------- --------------------------- --------------------------- --------------------------- --------------------------- --------------------------- --CCCCCCCCCCCCCCCCCCCCCCG-- -AAAAAAAAAAAAAAAAAAAAAAAAA- BBBBBBBBBBBBBBBBBBBBBBBBBBB --AAAAAAAAAAAAAAAAAAAAAAG-- ----BBBBBBBBBBBBBBBBBBB---- ------AAAAAAAAAAAAAAA------ -------AAAAAAAAAAAAA------- --------BBBBBBBBBBB-------- ---------AAAAAAAAG--------- ----------BBBBBBB---------- ------------AAA------------ --------------------------- --------------------------- --------------------------- --------------------------- 
-------D-----------D------- -------D-----------D------- -------DD---------HD------- --------DD-------DH-------- ---------HD-----DD--------- ----------DD---DD---------- -----------DDDDD----------- --------------------------- --------------------------- --------------------------- --------------------------- --------------------------- --------------------------- --------------------------- --------------------------- ---CCCCCCCCCCCCCCCCCCCCC--- --AAAAAAAAAAAAAAAAAAAAAAA-- -BBBBBBBBBBBBBBBBBBBBBBBBB- ---AAAAAAAAAAAAAAAAAAAAA--- -----BBBBBBBBBBBBBBBBB----- ------AAAAAAAAAAAAAAA------ -------AAAAAAAAAAAAA------- --------BBBBBBBBBBB-------- ----------AAAAAAA---------- -----------BBBBB----------- --------------------------- --------------------------- --------------------------- --------------------------- --------------------------- 
--------------------------- --------------------------- --------------------------- --------------------------- --------------------------- --------------------------- --------------------------- --------------------------- --------------------------- --------------------------- --------------------------- --------------------------- --------------------------- --------------------------- --------------------------- ---CCCCCCCCCCCCCCCCCCCCC--- --AAAAAAAAAAAAAAAAAAAAAAA-- -BBBBBBBBBBBBBBBBBBBBBBBBB- ---AAAAAAAAAAAAAAAAAAAAA--- -----BBBBBBBBBBBBBBBBB----- -------AAAAAAAAAAAAA------- --------AAAAAAAAAAA-------- ---------BBBBBBBBB--------- -----------AAAAA----------- --------------------------- --------------------------- --------------------------- --------------------------- --------------------------- --------------------------- 
--------------------------- --------------------------- --------------------------- --------------------------- --------------------------- --------------------------- --------------------------- --------------------------- --------------------------- --------------------------- --------------------------- --------------------------- --------------------------- --------------------------- --------------------------- ----CCCCCCCCCCCCCCCCCCC---- ---AAAAAAAAAAAAAAAAAAAAA--- -GBBBBBBBBBBBBBBBBBBBBBBBB- ----AAAAAAAAAAAAAAAAAAA---- ------BBBBBBBBBBBBBBG------ -------AAAAAAAAAAAAA------- ---------AAAAAAAAA--------- -----------BBBBB----------- --------------------------- --------------------------- --------------------------- --------------------------- --------------------------- --------------------------- --------------------------- 
--------------------------- --------------------------- --------------------------- --------------------------- --------------------------- --------------------------- --------------------------- --------------------------- --------------------------- --------------------------- --------------------------- --------------------------- --------------------------- --------------------------- --------------------------- ----CCCCCCCCCCCCCCCCCCC---- ---AAAAAAAAAAAAAAAAAAAAA--- --BBBBBBBBBBBBBBBBBBBBBBB-- ----AAAAAAAAAAAAAAAAAAA---- -------BBBBBBBBBBBBB------- ---------GAAAAAAAA--------- -----------AGAAA----------- --------------------------- --------------------------- --------------------------- --------------------------- --------------------------- --------------------------- --------------------------- --------------------------- 
--------------------------- --------------------------- --------------------------- --------------------------- --------------------------- --------------------------- --------------------------- --------------------------- --------------------------- --------------------------- --------------------------- --------------------------- --------------------------- --------------------------- --------------------------- -----GCCCCCCCCCCCCCCCC----- ----AAAAAAAAAAAAAAAAAAA---- ---BBBBBBBBBBBBBBBBBBBBB--- -----AAAAAAAAAAAAAAAAA----- --------BBBBBBBBBBB-------- -----------AAAAA----------- --------------------------- --------------------------- --------------------------- --------------------------- --------------------------- --------------------------- --------------------------- --------------------------- --------------------------- 
--------------------------- --------------------------- --------------------------- --------------------------- --------------------------- --------------------------- --------------------------- --------------------------- --------------------------- --------------------------- --------------------------- --------------------------- --------------------------- --------------------------- --------------------------- ------CCCCCCCCCCCCCCC------ -----AAAAAAAAAAAAAAAAA----- ---BBBBBBBBBBBBBBBBBBBBB--- ------AAAAAAAAAAAAAAA------ ----------BBBBBBB---------- --------------------------- --------------------------- --------------------------- --------------------------- --------------------------- --------------------------- --------------------------- --------------------------- --------------------------- --------------------------- 
--------------------------- --------------------------- --------------------------- --------------------------- --------------------------- --------------------------- --------------------------- --------------------------- --------------------------- --------------------------- --------------------------- --------------------------- --------------------------- --------------------------- --------------------------- --------CCCCCCCCCGC-------- ------AAAAAAAAAAAAAAA------ ----BBBBBBBBBBBBBBBBBBB---- --------AAAAAAAAAAA-------- --------------------------- --------------------------- --------------------------- --------------------------- --------------------------- --------------------------- --------------------------- --------------------------- --------------------------- --------------------------- --------------------------- 
--------------------------- --------------------------- --------------------------- --------------------------- --------------------------- --------------------------- --------------------------- --------------------------- --------------------------- --------------------------- --------------------------- --------------------------- --------------------------- --------------------------- --------------------------- ----------CCCCCCC---------- --------AAAAAAAAAAA-------- ------BBBBBBBBBBBBBBB------ ----------AAAAAAA---------- --------------------------- --------------------------- --------------------------- --------------------------- --------------------------- --------------------------- --------------------------- --------------------------- --------------------------- --------------------------- --------------------------- 
--------------------------- --------------------------- --------------------------- --------------------------- --------------------------- --------------------------- --------------------------- --------------------------- --------------------------- --------------------------- --------------------------- --------------------------- --------------------------- --------------------------- --------------------------- --------------------------- ----------AAAAAAA---------- -------BBBBBBBBBBBBB------- --------------------------- --------------------------- --------------------------- --------------------------- --------------------------- --------------------------- --------------------------- --------------------------- --------------------------- --------------------------- --------------------------- --------------------------- 
--------------------------- --------------------------- --------------------------- --------------------------- --------------------------- --------------------------- --------------------------- --------------------------- --------------------------- --------------------------- --------------------------- --------------------------- --------------------------- --------------------------- --------------------------- --------------------------- --------------------------- ----------BBBBBBB---------- --------------------------- --------------------------- --------------------------- --------------------------- --------------------------- --------------------------- --------------------------- --------------------------- --------------------------- --------------------------- --------------------------- --------------------------- 
