model
size = 32, scale = 0.05, origin = -y
material 
  colors = A:#AAA B:#33C C:#CC9 D:#3CF E:#0CF F:#6FF G:#0FF H:#EEE I:#F63 J:#FC9 K:#FC0 L:#111
voxels
32BA12-9C-2(C3-)5(2A22-F3-D3-)2(2A22-H2(3-D3-2A22-F)3-D3-)2A26-D3-2A26-H3-2A26-D3-15(2A30-)33A32B10-15C2-C4(23-E3-F3-D)6(27-F3-D)27-E3-D27-F3-F3(31-D)452-32A32B8-20C4(23-E3-F3-D)23-H3-F3-D23-E3-7(F3-D27-)F3-3(D31-)D420-32A32B7-21C3(20-G2-E3-F3-D)5(23-E3-F3-D)5(27-F3-D)27-F3-F31-H31-D31-H388-32A32B6-23C19-4(G2-E3-F3-D20-)H2-E3-F3-D20-E2-E3-F3-D23-H3(3-F3-D23-E)3-2(F3-D27-)H3(3-D27-F)3-3(D31-)D356-32A32B5-25C18-7(G2-E3-F3-D20-)G2-E3-F3-D23-G3-F3-D23-E3-F3-D23-G3-4(F3-D27-)H3-D27-F3-2(D31-)F31-D324-32A32B4-27C13-2(E3-G2-E3-F3-D16-)E3-5(G2-E3-F3-D20-)E2-E3-F3-D20-G2-3(E3-F3-D23-)E3-2(F3-D27-)H2(3-D27-F)3-D31-H2(31-D)324-32A32B3-29C12-4(E3-G2-E3-F3-D16-)E3-5(G2-E3-F3-D20-)H2-3(E3-F3-D23-)2(E3-)4(D27-F3-)3(D31-)D292-32A32B2-30C12-2(E3-G2-E3-F3-D16-)G3(3-G2-E3-F3-D16-E)3-G2-E3-F3-D16-H3-4(G2-E3-F3-D20-)G2-2(E3-F3-D23-)E3-4(F3-D27-)F3-D31-F31-H31-D292-32A32B2-30C12-3(E3-G2-E3-F3-D16-)E3-G2-G3-F3-D16-H3(3-G2-E3-F3-D16-E)3-4(G2-E3-F3-D20-)G2-2(E3-F3-D23-)E3-2(F3-D27-)E2(3-D27-F)3-3(D31-)D260-32A32B-31C12-8(E3-G2-E3-F3-D16-)E3-G2-E3-F3-D20-G2-2(E3-)D20-H2-E3-F3-D20-G2-G2(3-F3-D23-E)3-4(F3-D27-)F3-3(D31-)F260-32A32B-31C12-8(E3-G2-E3-F3-D16-)E3-3(G2-E3-F3-D20-)E2-E3-F3-D20-G2-2(E3-F3-D23-)H3-3(F3-D27-)F3-3(D31-)D260-32A32B-31C12-2(E3-G2-E3-F3-D16-)G6(3-G2-E3-F3-D16-E)3-G2-E3-F3-D16-H3-3(G2-E3-F3-D20-)H2-2(E3-F3-D23-)E3-3(F3-D27-)H3-D27-F3-2(D31-)D260-32A32B32C12-3(E3-G2-E3-F3-D16-)E3-G2-E3-F3-D11-H4-E3-G2-E3-F3-D10-3G3-E3-G2-E3-F3-D11-H4-E3-G2-E3-F3-D16-E3-G2-2(E3-)D16-E3-G2-E3-F3-D16-E3-G2-G2(3-F3-D20-G2-E)3-F3-D20-G2-H3(3-F3-D23-E)3-F3-D27-H2(3-D27-F)3-D31-H31-D31-H228-32A32B32C12-3(E3-G2-E3-F3-D16-)E3-G2-E3-F3-D10-GAG3-E3-G2-E3-F3-D5-3IJ-GAG3-E3-G2-E3-F3-D10-3G3-4(E3-G2-E3-F3-D16-)E3-G2-E3-F3-D20-H2(2-E3-F3-D20-G)2-2(E3-F3-D23-)E3-3(F3-D27-)F3-3(D31-)D228-32A32B32C12-3(E3-G2-E3-F3-D16-)E3-G2-E3-F3-D11-H4-E3-G2-E3-F3-D5-I4-3G3-E3-G2-E3-F3-D11-H4-4(E3-G2-E3-F3-D16-)E3-3(G2-E3-F3-D20-)H2-2(E3-F3-D23-)H3-3(F3-D27-)E3-3(D31-)F228-32A32B23C-8CL2(11-E3-G2-E3-F3-D4-I)11-2(E3-G2-E3-F3-D5-I10-)E3-G2-E3-F3-D5-2I9-E3-G2-E3-F3-D5-I10-E3-G2-E3-F3-D5-KJ9-3(E3-G2-E3-F3-D16-)E3-3(G2-E3-F3-D20-)G2-2(E3-F3-D23-)E2(3-F)3(27-F3-D)3(31-D)228-32A32B19C-7C-4C12-2(E3-G2-E3-F3-D16-)3(E3-G2-E3-F3-D5-2I9-)E3-G2-E3-F3-D5-I10-E3-G2-E3-F3-D5-KJ9-3(E3-G2-E3-F3-D16-)H3-3(G2-E3-F3-D20-)H2-2(E3-F3-D23-)E3-3(F3-D27-)H3-2(D31-)F31-D228-32A32B12C-19C3-L3(8-E3-G2-E3-F3-D7-I)8-E3-G2-E3-F3-D16-E3-G2-E3-F3-D4-2I10-5(E3-G2-E3-F3-D16-)E3-3(G2-E3-F3-D20-)G2-2(E3-F3-D23-)G3-2(F3-D27-)E3-D27-F3-3(D31-)H228-32A32B32C12-4(E3-G2-E3-F3-D16-)E3-G2-E3-F3-D4-I11-5(E3-G2-E3-F3-D16-)H3-2(G2-E3-F3-D20-)E2-E3-F3-D20-G2-2(E3-F3-D23-)E3-3(F3-D27-)F3-3(D31-)D228-32A32B32C12-4(E3-G2-E3-F3-D16-)E3-G2-E3-F3-D4-I11-E3-G2-E3-F3-D16-E3-G2-G3-F3-D16-G3-G2-E2(3-F)16-E3-G2-E3-F3-D16-E3-E2-E3-F3-D16-H3-2(G2-E3-F3-D20-)G2-2(E3-)D20-H2-2(E3-F3-D23-)H3-3(F3-D27-)F3-2(D31-)H31-D228-32A32B32C12-4(E3-G2-E3-F3-D16-)E3-G2-E3-F3-D4-J11-4(E3-G2-E3-F3-D16-)E3-3(G2-E3-F3-D20-)G2-3(E3-F3-D23-)E3-2(F3-D27-)F3-4(D31-)H228-32A32B-31C12-9(E3-G2-E3-F3-D16-)E3-3(G2-E3-F3-D20-)G2-H3-F3-D23-E3-F3-D23-H3-2(F3-D27-)H3-D27-F3-2(D31-)F31-D260-32A32B-31C12-5(E3-G2-E3-F3-D16-)E3-E2-E3-F3-D16-H2(3-G2-E3-F3-D16-E)3-3(G2-E3-F3-D20-)G2-G3-F3-D20-G2-2(E3-F3-D23-)E3-3(F3-D27-)F3-D31-H2(31-D)260-32A32B-31C12-3(E3-G2-E3-F3-D16-)G5(3-G2-E3-F3-D16-E)3-G2-E3-F3-D20-E2(2-E3-F3-D20-G)2-E3-F3-D23-2(E3-)D23-H3-2(F3-D27-)F3-F27-F3-4(D31-)D260-32A32B2-30C12-2(E3-G2-E3-F3-D16-)E3-G2-G4(3-F3-D16-E3-G2-E)3-F3-D16-H3-G2-G3-F3-D20-G2-2(E3-)2(D20-G2-E3-F3-)D20-H2-2(E3-F3-D23-)E3-2(F3-D27-)F3-F27-H3-2(D31-)F2(31-D)260-32A32B2-30C12-6(E3-G2-E3-F3-D16-)E3-4(G2-E3-F3-D20-)H2-2(E3-F3-D23-)E3-F3-D27-H2(3-D27-F)3-4(D31-)H292-32A32B3-29C12-E3-G2-E2(3-F)16-E3-G2-E3-F3-D16-E3-E2(2-E3-F3-D16-E3-G)5(2-E3-F3-D20-G)2-2(E3-F3-D23-)H3-F3-D23-E3-3(F3-D27-)F3-4(D31-)D292-32A32B4-27C13-2(E3-G2-E3-F3-D16-)H3-G2-E3-F3-D20-G2-2(E3-)D20-G2-E3-F3-D20-E2-E3-F3-D20-H2(2-E3-F3-D20-G)2-2(E3-F3-D23-)H3-F3-D23-E3-3(F3-D27-)F3-4(D31-)D324-32A32B5-25C18-G2-2(E3-)D20-G2-G6(3-F3-D20-G2-E)3(3-F3-D23-E)3-F3-D27-E2(3-D27-F)3-4(D31-)H31-D324-32A32B6-23C19-5(G2-E3-F3-D20-)G2-4(E3-F3-D23-)E3-3(F3-D27-)F3-D31-F31-H3(31-D)356-32A32BA6-21C3(3-2A15-G2-E3-F3-D)3(3-2A18-E3-F3-D)3-2A18-E2(3-F)3-2A18-E3-4(F3-D3-2A22-)H3-5(D3-2A26-)H3-12(2A30-)33A
