model
size = 15 8 16, scale = 0.05, origin = -y
material 
  colors = A:#111 B:#EEE C:#0CF
voxels
--------------- ----CA---CA---- ----CC---CC---- --------------- --------------- --------------- --------------- --------------- 
----BB---BB---- ---BBBB-BBBB--- ---BBBB-BBBB--- ----BB---BB---- --------------- --------------- --------------- --------------- 
----BB---BB---- ---BBBB-BBBB--- ---BBBB-BBBB--- ----BB---BB---- --------------- --------------- --------------- --------------- 
--------------- ----BB---BB---- ----BB---BB---- --------------- --------------- --------------- --------------- --------------- 
--------------- --------------- --------------- --------------- --------------- --------------- --------------- --------------- 
--AAAAA-AAAAA-- --A----A----A-- --A----A----A-- --AAAAA-AAAAA-- --------------- AA---AA-AA---AA -AA-AA---AA-AA- --AAA-----AAA-- 
--------------- --------------- --------------- --A---------A-- --------------- --------------- --------------- --------------- 
--------------- --------------- --------------- --A---------A-- --------------- --------------- --------------- --------------- 
--------------- --------------- --------------- --A---------A-- --------------- --------------- --------------- --------------- 
--------------- --------------- --------------- --A---------A-- --------------- --------------- --------------- --------------- 
--------------- --------------- --------------- --A---------A-- --------------- --------------- --------------- --------------- 
--------------- --------------- --------------- --A---------A-- --------------- --------------- --------------- --------------- 
--------------- --------------- --A---------A-- --A---------A-- --------------- --------------- --------------- --------------- 
--------------- --A---------A-- --A---------A-- --------------- --------------- --------------- --------------- --------------- 
--A---------A-- --A---------A-- --------------- --------------- --------------- --------------- --------------- --------------- 
--A---------A-- --------------- --------------- --------------- --------------- --------------- --------------- --------------- 
