model
size = 17 5 8, scale = 0.05, origin = -y
material 
  colors = A:#EEE B:#DDD C:#777 D:#D00 E:#111 F:#F90 G:#C60 H:#930 I:#FC0 J:#BBB K:#E00 L:#0CF
voxels
----------------- ----------------- ----------------- --------AI------- --------EE------- 
BBBB------------- -K-K----AA------- --------DD------- -------DFGD------ -------E--E------ 
BBBB----AA----CCC -K-K---AAAA---CCC -------D--D---CCC ------DGFGFD----- ------E----E----- 
BBBB---AAAA---CCC -H-H--AA--AA--C-C ------D----D--CLC -----IFBBGFGA---- -----E------E---- 
BBBB---AAAA---CCC -H-H--AA--AA--CCC ------D----D--CCC -----AFBIGFGI---- -----E------E---- 
JJJJ----AA------- -H-H---AAAA------ -------D--D------ ------DGFGFD----- ------E----E----- 
BBBB------------- -H-H----AA------- --------DD------- -------DFGD------ -------E--E------ 
BBBB------------- -H-H------------- ----------------- --------IA------- --------EE------- 
