model
size = 28 29 30, scale = 0.05, origin = -y
material 
  colors = A:#F03 B:#F99 C:#BBB D:#FF3 E:#FFF F:#F66 G:#F90 H:#FCF
voxels
---------------------------- ---------------------------- ---------------------------- ---------------------------- ---------------------------- ---------------------------- ---------------------------- ---------------------------- ---------------------------- ---------------------------- ---------------------------- ---------------------------- ---------------------------- ---------------------------- ---------------------------- ---------------------------- ---------------------------- ---------------------------- ---------------------------- ---------------------------- ---------------------------- ---------------------------- -----------BBBBBB----------- ---------BBBBBBBBBB--------- ---------------------------- ---------------------------- ---------------------------- ---------------------------- ---------------------------- 
---------------------------- ---------------------------- ---------------------------- ---------------------------- ---------------------------- ---------------------------- ---------------------------- ---------------------------- ---------------------------- ---------------------------- ---------------------------- ---------------------------- ---------------------------- ---------------------------- ---------------------------- ---------------------------- ---------------------------- ---------------------------- ---------------------------- ---------------------------- -----------AAAAAA----------- ----------AAAAAAAA---------- --------BBB------BBB-------- -------BBB--------BBB------- ---------------------------- ---------------------------- ---------------------------- ---------------------------- ---------------------------- 
---------------------------- ---------------------------- ---------------------------- ---------------------------- ---------------------------- ---------------------------- ---------------------------- ---------------------------- ---------------------------- ---------------------------- ---------------------------- ---------------------------- ---------------------------- ---------------------------- ---------------------------- ---------------------------- ---------------------------- ---------------------------- ------------AAAA------------ ----------AAAAAAAA---------- --------AAAAAAAAAAAA-------- -------AAAAAAAAAAAAAA------- ------BB------------BB------ ------BB------------BB------ ---------------------------- ---------------------------- ---------------------------- ---------------------------- ---------------------------- 
---------------------------- ---------------------------- ---------------------------- ---------------------------- ---------------------------- ---------------------------- ---------------------------- ---------------------------- ---------------------------- ---------------------------- ---------------------------- ---------------------------- ---------------------------- ---------------------------- ---------------------------- ---------------------------- ------------AAAA------------ ----------AAAAAAAA---------- ---------AAAAAAAAAA--------- --------AAAAAAAAAAAA-------- -------AAAAAAAAAAAAAA------- ------AAAAAAAAAAAAAAAA------ -----BB--------------BB----- ----BBB--------------BBB---- ---------------------------- ---------------------------- ---------------------------- ---------------------------- ---------------------------- 
---------------------------- ---------------------------- ---------------------------- ---------------------------- ---------------------------- ---------------------------- ---------------------------- ---------------------------- ---------------------------- ---------------------------- ---------------------------- ---------------------------- ---------------------------- ---------------------------- ------------AAAA------------ ----------AAAAAAAA---------- ---------AAAAAAAAAA--------- --------AAAAAAAAAAAA-------- -------AAAAAAAAAAAAAA------- ------AAAAAAAAAAAAAAAA------ -----AAAAAAAAAAAAAAAAAA----- -----AAAAAAAAAAAAAAAAAA----- ----B------------------B---- ---BB------------------BB--- ---------------------------- ---------------------------- ---------------------------- ---------------------------- ---------------------------- 
---------------------------- ---------------------------- ---------------------------- ---------------------------- ---------------------------- ---------------------------- ---------------------------- ---------------------------- ---------------------------- ---------------------------- ---------------------------- ---------------------------- ------------AAAA------------ ----------AAAAAAAA---------- ---------AAAAAAAAAA--------- --------AAAAAAAAAAAA-------- -------AAAAAAAAAAAAAA------- -------AAAAAAAAAAAAAA------- ------AAAAAAAAAAAAAAAA------ -----AAAAAAAAAAAAAAAAAA----- ----AAAAAAAAAAAAAAAAAAAA---- ----AAAAAAAAAAAAAAAAAAAA---- ---B--------------------B--- ---B--------------------B--- ---------------------------- ---------------------------- ---------------------------- ---------------------------- ---------------------------- 
---------------------------- ---------------------------- ---------------------------- ---------------------------- ---------------------------- ---------------------------- ---------------------------- ---------------------------- ---------------------------- ---------------------------- ------------AAAA------------ -----------AAAAAA----------- ---------AAAAAAAAAA--------- ---------AAAAAAAAAA--------- --------AAAAAAAAAAAA-------- -------AAAAAAAAAAAAAA------- ------AAAAAAAAAAAAAAAA------ ------AAAAAAAAAAAAAAAA------ -----AAAAAAAAAAAAAAAAAA----- ----AAAAAAAAAAAAAAAAAAAA---- ----AAAAAAAAAAAAAAAAAAAA---- ---AAAAAAAAAAAAAAAAAAAAAA--- --BB--------------------BB-- --BB--------------------BB-- ---------------------------- ---------------------------- ---------------------------- ---------------------------- ---------------------------- 
---------------------------- ---------------------------- ---------------------------- ---------------------------- ---------------------------- ---------------------------- ---------------------------- ---------------------------- ------------AAAA------------ -----------AAAAAA----------- ----------AAAAAAAA---------- ---------AAAAAAAAAA--------- --------AAAAAAAAAAAA-------- -------AAAAAAAAAAAAAA------- -------AAAAAAAAAAAAAA------- ------AAAAAAAAAAAAAAAA------ -----AAAAAAAAAAAAAAAAAA----- -----AAAAAAAAAAAAAAAAAA----- ----AAAAAAAAAAAAAAAAAAAA---- ----AAAAAAAAAAAAAAAAAAAA---- ---AAAAAAAAAAAAAAAAAAAAAA--- --AAAAAAAAAAAAAAAAAAAAAAAA-- --B----------------------B-- -BB----------------------BB- ---------------------------- ---------------------------- ---------------------------- ---------------------------- ---------------------------- 
------------BBBB------------ ------------BBBB------------ ------------EEEE------------ ------------FFFF------------ ------------AAAA------------ ------------AAAA------------ ------------AAAA------------ -----------AAAAAA----------- ----------AAAAAAAA---------- ---------AAAAAAAAAA--------- ---------AAAAAAAAAA--------- --------AAAAAAAAAAAA-------- -------AAAAAAAAAAAAAA------- -------AAAAAAAAAAAAAA------- ------AAAAAAAAAAAAAAAA------ -----AAAAAAAAAAAAAAAAAA----- -----AAAAAAAAAAAAAAAAAA----- ----AAAAAAAAAAAAAAAAAAAA---- ----AAAAAAAAAAAAAAAAAAAA---- ---AAAAAAAAAAAAAAAAAAAAAA--- --AAAAAAAAAAAAAAAAAAAAAAAA-- --AAAAAAAAAAAAAAAAAAAAAAAA-- -B----------------CCCCC---B- -B------------------------B- ---------------------------- ---------------------------- ---------------------------- ---------------------------- ---------------------------- 
----------BBBBBBBB---------- ----------BBBBBBBB---------- ----------EEAAAAEE---------- ----------FFAAAAFF---------- ----------AAAAAAAA---------- ----------AAAAAAAA---------- ----------AAAAAAAA---------- ----------AAAAAAAA---------- ---------AAAAAAAAAA--------- --------AAAAAAAAAAAA-------- --------AAAAAAAAAAAA-------- -------AAAAAAAAAAAAAA------- ------AAAAAAAAAAAAAAAA------ ------AAAAAAAAAAAAAAAA------ -----AAAAAAAAAAAAAAAAAA----- -----AAAAAAAAAAAAAAAAAA----- ----AAAAAAAAAAAAAAAAAAAA---- ----AAAAAAAAAAAAAAAAAAAA---- ---AAAAAAAAAAAAAAAAAAAAAA--- ---AAAAAAAAAAAAAAAAAAAAAA--- --AAAAAAAAAAAAAAAAAAAAAAAA-- --AAAAAAAAAAAAAAAAAAAAAAAA-- -B---------------HCCCCC---B- BB------------------------BB ---------------------------- ---------------------------- ---------------------------- ---------------------------- ---------------------------- 
---------BBBBBBBBBB--------- ---------BBBBBBBBBB--------- ---------EAAAAAAAAE--------- ---------FAAAAAAAAF--------- ---------AAAAAAAAAA--------- ---------AAAAAAAAAA--------- ---------AAAAAAAAAA--------- ---------AAAAAAAAAA--------- --------AAAAAAAAAAAA-------- --------AAAAAAAAAAAA-------- -------AAAAAAAAAAAAAA------- -------AAAAAAAAAAAAAA------- ------AAAAAAAAAAAAAAAA------ -----AAAAAAAAAAAAAAAAAA----- -----AAAAAAAAAAAAAAAAAA----- ----AAAAAAAAAAAAAAAAAAAA---- ----AAAAAAAAAAAAAAAAAAAA---- ---AAAAAAAAAAAAAAAAAAAAAA--- ---AAAAAAAAAAAAAAAAAAAAAA--- --AAAAAAAAAAAAAAAAAAAAAAAA-- --AAAAAAAAAAAAAAAAAAAAAAAA-- -AAAAAAAAAAAAAAAAAAAAAAAAAA- -B---------------HCCCCC---B- B--------------------------B ---------------------------- ---------------------------- ---------------------------- ---------------------------- ---------------------------- 
---------BBBBBBBBBB--------- ---------BBBBBBBBBB--------- ---------EAAAAAAAAE--------- ---------FAAAAAAAAF--------- ---------AAAAAAAAAA--------- ---------AAAAAAAAAA--------- ---------AAAAAAAAAA--------- --------AAAAAAAAAAAA-------- --------AAAAAAAAAAAA-------- -------AAAAAAAAAAAAAA------- -------AAAAAAAAAAAAAA------- ------AAAAAAAAAAAAAAAA------ ------AAAAAAAAAAAAAAAA------ -----AAAAAAAAAAAAAAAAAA----- -----AAAAAAAAAAAAAAAAAA----- ----AAAAAAAAAAAAAAAAAAAA---- ----AAAAAAAAAAAAAAAAAAAA---- ---AAAAAAAAAAAAAAAAAAAAAA--- ---AAAAAAAAAAAAAAAAAAAAAA--- --AAAAAAAAAAAAAAAAAAAAAAAA-- -AAAAAAAAAAAAAAAAAAAAAAAAAA- -AAAAAAAAAAAAAAAAAAAAAAAAAA- B----------------HCCCCC----B B--------------------------B ---------------------------- ---------------------------- ---------------------------- ---------------------------- ---------------------------- 
--------BBBBBBBBBBBB-------- --------BBBBBBBBBBBB-------- --------EAAAAAAAAAAE-------- --------FAAAAAAAAAAF-------- --------AAAAAAAAAAAA-------- --------AAAAAAAAAAAA-------- --------AAAAAAAAAAAA-------- --------AAAAAAAAAAAA-------- -------AAAAAAAAAAAAAA------- -------AAAAAAAAAAAAAA------- ------AAAAAAAAAAAAAAAA------ ------AAAAAAAAAAAAAAAA------ -----AAAAAAAAAAAAAAAAAA----- -----AAAAAAAAAAAAAAAAAA----- ----AAAAAAAAAAAAAAAAAAAA---- ----AAAAAAAAAAAAAAAAAAAA---- ---AAAAAAAAAAAAAAAAAAAAAA--- ---AAAAAAAAAAAAAAAAAAAAAA--- --AAAAAAAAAAAAAAAAAAAAAAAA-- --AAAAAAAAAAAAAAAAAAAAAAAA-- -AAAAAAAAAAAAAAAAAAAAAAAAAA- -AAAAAAAAAAAAAAAAAAAAAAAAAA- B----------------HCCCCC----B B--------------------------B ---------------------------- ---------------------------- ---------------------------- ---------------------------- ---------------------------- 
--------BBBBBBBBBBBB-------- --------BBBBBBBBBBBB-------- --------EAAAAAAAAAAE-------- --------FAAAAAAAAAAF-------- --------AAAAAAAAAAAA-------- --------AAAAAAAAAAAA-------- --------AAAAAAAAAAAA-------- --------AAAAAAAAAAAA-------- -------AAAAAAAAAAAAAA------- -------AAAAAAAAAAAAAA------- ------AAAAAAAAAAAAAAAA------ ------AAAAAAAAAAAAAAAA------ -----AAAAAAAAAAAAAAAAAA----- -----AAAAAAAAAAAAAAAAAA----- ----AAAAAAAAAAAAAAAAAAAA---- ----AAAAAAAAAAAAAAAAAAAA---- ---AAAAAAAAAAAAAAAAAAAAAA--- ---AAAAAAAAAAAAAAAAAAAAAA--- --AAAAAAAAAAAAAAAAAAAAAAAA-- --AAAAAAAAAAAAAAAAAAAAAAAA-- -AAAAAAAAAAAAAAAAAAAAAAAAAA- -AAAAAAAAAAAAAAAAAAAAAAAAAA- B-----CCCCC------CCCCC-----B B--------------------------B ---------------------------- ---------------------------- ---------------------------- ---------------------------- ---------------------------- 
--------BBBBBBBBBBBB-------- --------BBBBBBBBBBBB-------- --------EAAAAAAAAAAE-------- --------FAAAAAAAAAAF-------- --------AAAAAAAAAAAA-------- --------AAAAAAAAAAAA-------- --------AAAAAAAAAAAA-------- --------AAAAAAAAAAAA-------- -------AAAAAAAAAAAAAA------- -------AAAAAAAAAAAAAA------- ------AAAAAAAAAAAAAAAA------ ------AAAAAAAAAAAAAAAA------ -----AAAAAAAAAAAAAAAAAA----- -----AAAAAAAAAAAAAAAAAA----- ----AAAAAAAAAAAAAAAAAAAA---- ----AAAAAAAAAAAAAAAAAAAA---- ---AAAAAAAAAAAAAAAAAAAAAA--- ---AAAAAAAAAAAAAAAAAAAAAA--- --AAAAAAAAAAAAAAAAAAAAAAAA-- --AAAAAAAAAAAAAAAAAAAAAAAA-- -AAAAAAAAAAAAAAAAAAAAAAAAAA- -AAAAAAAAAAAAAAAAAAAAAAAAAA- B----HCCCCC---G------------B B-------------G------------B ---------------------------- ---------------------------- ---------------------------- ---------------------------- ---------------------------- 
--------BBBBBBBBBBBB-------- --------BBBBBBBBBBBB-------- --------EAAAAAAAAAAE-------- --------FAAAAAAAAAAF-------- --------AAAAAAAAAAAA-------- --------AAAAAAAAAAAA-------- --------AAAAAAAAAAAA-------- --------AAAAAAAAAAAA-------- -------AAAAAAAAAAAAAA------- -------AAAAAAAAAAAAAA------- ------AAAAAAAAAAAAAAAA------ ------AAAAAAAAAAAAAAAA------ -----AAAAAAAAAAAAAAAAAA----- -----AAAAAAAAAAAAAAAAAA----- ----AAAAAAAAAAAAAAAAAAAA---- ----AAAAAAAAAAAAAAAAAAAA---- ---AAAAAAAAAAAAAAAAAAAAAA--- ---AAAAAAAAAAAAAAAAAAAAAA--- --AAAAAAAAAAAAAAAAAAAAAAAA-- --AAAAAAAAAAAAAAAAAAAAAAAA-- -AAAAAAAAAAAAAAAAAAAAAAAAAA- -AAAAAAAAAAAAAAAAAAAAAAAAAA- B----HCCCCC---D------------B B-------------D------------B --------------G------------- --------------G------------- ---------------------------- ---------------------------- ---------------------------- 
---------BBBBBBBBBB--------- ---------BBBBBBBBBB--------- ---------EAAAAAAAAE--------- ---------FAAAAAAAAF--------- ---------AAAAAAAAAA--------- ---------AAAAAAAAAA--------- ---------AAAAAAAAAA--------- --------AAAAAAAAAAAA-------- --------AAAAAAAAAAAA-------- -------AAAAAAAAAAAAAA------- -------AAAAAAAAAAAAAA------- ------AAAAAAAAAAAAAAAA------ ------AAAAAAAAAAAAAAAA------ -----AAAAAAAAAAAAAAAAAA----- -----AAAAAAAAAAAAAAAAAA----- ----AAAAAAAAAAAAAAAAAAAA---- ----AAAAAAAAAAAAAAAAAAAA---- ---AAAAAAAAAAAAAAAAAAAAAA--- ---AAAAAAAAAAAAAAAAAAAAAA--- --AAAAAAAAAAAAAAAAAAAAAAAA-- -AAAAAAAAAAAAAAAAAAAAAAAAAA- -AAAAAAAAAAAAAAAAAAAAAAAAAA- B----HCCCCC---D------------B B-------------D------------B --------------D------------- --------------G------------- --------------G------------- ---------------------------- ---------------------------- 
---------BBBBBBBBBB--------- ---------BBBBBBBBBB--------- ---------EAAAAAAAAE--------- ---------FAAAAAAAAF--------- ---------AAAAAAAAAA--------- ---------AAAAAAAAAA--------- ---------AAAAAAAAAA--------- ---------AAAAAAAAAA--------- --------AAAAAAAAAAAA-------- --------AAAAAAAAAAAA-------- -------AAAAAAAAAAAAAA------- -------AAAAAAAAAAAAAA------- ------AAAAAAAAAAAAAAAA------ -----AAAAAAAAAAAAAAAAAA----- -----AAAAAAAAAAAAAAAAAA----- ----AAAAAAAAAAAAAAAAAAAA---- ----AAAAAAAAAAAAAAAAAAAA---- ---AAAAAAAAAAAAAAAAAAAAAA--- ---AAAAAAAAAAAAAAAAAAAAAA--- --AAAAAAAAAAAAAAAAAAAAAAAA-- --AAAAAAAAAAAAAAAAAAAAAAAA-- -AAAAAAAAAAAAAAAAAAAAAAAAAA- -B---HCCCCC---D-----------B- B-------------D------------B --------------D------------- --------------D------------- --------------G------------- ---------------------------- ---------------------------- 
----------BBBBBBBB---------- ----------BBBBBBBB---------- ----------EEAAAAEE---------- ----------FFAAAAFF---------- ----------AAAAAAAA---------- ----------AAAAAAAA---------- ----------AAAAAAAA---------- ----------AAAAAAAA---------- ---------AAAAAAAAAA--------- --------AAAAAAAAAAAA-------- --------AAAAAAAAAAAA-------- -------AAAAAAAAAAAAAA------- ------AAAAAAAAAAAAAAAA------ ------AAAAAAAAAAAAAAAA------ -----AAAAAAAAAAAAAAAAAA----- -----AAAAAAAAAAAAAAAAAA----- ----AAAAAAAAAAAAAAAAAAAA---- ----AAAAAAAAAAAAAAAAAAAA---- ---AAAAAAAAAAAAAAAAAAAAAA--- ---AAAAAAAAAAAAAAAAAAAAAA--- --AAAAAAAAAAAAAAAAAAAAAAAA-- --AAAAAAAAAAAAAAAAAAAAAAAA-- -B---CCCCC----D-----------B- BB------------D-----------BB --------------D------------- --------------D------------- --------------D------------- --------------G------------- ---------------------------- 
------------BBBB------------ ------------BBBB------------ ------------EEEE------------ ------------FFFF------------ ------------AAAA------------ ------------AAAA------------ ------------AAAA------------ -----------AAAAAA----------- ----------AAAAAAAA---------- ---------AAAAAAAAAA--------- ---------AAAAAAAAAA--------- --------AAAAAAAAAAAA-------- -------AAAAAAAAAAAAAA------- -------AAAAAAAAAAAAAA------- ------AAAAAAAAAAAAAAAA------ -----AAAAAAAAAAAAAAAAAA----- -----AAAAAAAAAAAAAAAAAA----- ----AAAAAAAAAAAAAAAAAAAA---- ----AAAAAAAAAAAAAAAAAAAA---- ---AAAAAAAAAAAAAAAAAAAAAA--- --AAAAAAAAAAAAAAAAAAAAAAAA-- --AAAAAAAAAAAAAAAAAAAAAAAA-- -B------------D-----------B- -B------------D-----------B- --------------D------------- --------------D------------- --------------D------------- --------------G------------- ---------------------------- 
---------------------------- ---------------------------- ---------------------------- ---------------------------- ---------------------------- ---------------------------- ---------------------------- ---------------------------- ------------AAAA------------ -----------AAAAAA----------- ----------AAAAAAAA---------- ---------AAAAAAAAAA--------- --------AAAAAAAAAAAA-------- -------AAAAAAAAAAAAAA------- -------AAAAAAAAAAAAAA------- ------AAAAAAAAAAAAAAAA------ -----AAAAAAAAAAAAAAAAAA----- -----AAAAAAAAAAAAAAAAAA----- ----AAAAAAAAAAAAAAAAAAAA---- ----AAAAAAAAAAAAAAAAAAAA---- ---AAAAAAAAAAAAAAAAAAAAAA--- --AAAAAAAAAAAAAAAAAAAAAAAA-- --B-----------D----------B-- -BB-----------D----------BB- --------------D------------- --------------D------------- --------------D------------- --------------D------------- --------------G------------- 
---------------------------- ---------------------------- ---------------------------- ---------------------------- ---------------------------- ---------------------------- ---------------------------- ---------------------------- ---------------------------- ---------------------------- ------------AAAA------------ -----------AAAAAA----------- ---------AAAAAAAAAA--------- ---------AAAAAAAAAA--------- --------AAAAAAAAAAAA-------- -------AAAAAAAAAAAAAA------- ------AAAAAAAAAAAAAAAA------ ------AAAAAAAAAAAAAAAA------ -----AAAAAAAAAAAAAAAAAA----- ----AAAAAAAAAAAAAAAAAAAA---- ----AAAAAAAAAAAAAAAAAAAA---- ---AAAAAAAAAAAAAAAAAAAAAA--- --BB----------D---------BB-- --BB----------D---------BB-- --------------D------------- --------------D------------- --------------D------------- --------------D------------- --------------G------------- 
---------------------------- ---------------------------- ---------------------------- ---------------------------- ---------------------------- ---------------------------- ---------------------------- ---------------------------- ---------------------------- ---------------------------- ---------------------------- ---------------------------- ------------AAAA------------ ----------AAAAAAAA---------- ---------AAAAAAAAAA--------- --------AAAAAAAAAAAA-------- -------AAAAAAAAAAAAAA------- -------AAAAAAAAAAAAAA------- ------AAAAAAAAAAAAAAAA------ -----AAAAAAAAAAAAAAAAAA----- ----AAAAAAAAAAAAAAAAAAAA---- ----AAAAAAAAAAAAAAAAAAAA---- ---B----------D---------B--- ---B----------D---------B--- --------------D------------- --------------D------------- --------------D------------- --------------D------------- --------------G------------- 
---------------------------- ---------------------------- ---------------------------- ---------------------------- ---------------------------- ---------------------------- ---------------------------- ---------------------------- ---------------------------- ---------------------------- ---------------------------- ---------------------------- ---------------------------- ---------------------------- ------------AAAA------------ ----------AAAAAAAA---------- ---------AAAAAAAAAA--------- --------AAAAAAAAAAAA-------- -------AAAAAAAAAAAAAA------- ------AAAAAAAAAAAAAAAA------ -----AAAAAAAAAAAAAAAAAA----- -----AAAAAAAAAAAAAAAAAA----- ----B---------D--------B---- ---BB---------D--------BB--- --------------D------------- --------------D------------- --------------D------------- --------------D------------- --------------G------------- 
---------------------------- ---------------------------- ---------------------------- ---------------------------- ---------------------------- ---------------------------- ---------------------------- ---------------------------- ---------------------------- ---------------------------- ---------------------------- ---------------------------- ---------------------------- ---------------------------- ---------------------------- ---------------------------- ------------AAAA------------ ----------AAAAAAAA---------- ---------AAAAAAAAAA--------- --------AAAAAAAAAAAA-------- -------AAAAAAAAAAAAAA------- ------AAAAAAAAAAAAAAAA------ -----BB-------D------BB----- ----BBB-------D------BBB---- --------------D------------- --------------D------------- --------------D------------- --------------G------------- ---------------------------- 
---------------------------- ---------------------------- ---------------------------- ---------------------------- ---------------------------- ---------------------------- ---------------------------- ---------------------------- ---------------------------- ---------------------------- ---------------------------- ---------------------------- ---------------------------- ---------------------------- ---------------------------- ---------------------------- ---------------------------- ---------------------------- ------------AAAA------------ ----------AAAAAAAA---------- --------AAAAAAAAAAAA-------- -------AAAAAAAAAAAAAA------- ------BB------D-----BB------ ------BB------D-----BB------ --------------D------------- --------------D------------- --------------D------------- --------------G------------- ---------------------------- 
---------------------------- ---------------------------- ---------------------------- ---------------------------- ---------------------------- ---------------------------- ---------------------------- ---------------------------- ---------------------------- ---------------------------- ---------------------------- ---------------------------- ---------------------------- ---------------------------- ---------------------------- ---------------------------- ---------------------------- ---------------------------- ---------------------------- ---------------------------- -----------AAAAAA----------- ----------AAAAAAAA---------- --------BBB---D--BBB-------- -------BBB----D---BBB------- --------------D------------- --------------D------------- --------------G------------- ---------------------------- ---------------------------- 
---------------------------- ---------------------------- ---------------------------- ---------------------------- ---------------------------- ---------------------------- ---------------------------- ---------------------------- ---------------------------- ---------------------------- ---------------------------- ---------------------------- ---------------------------- ---------------------------- ---------------------------- ---------------------------- ---------------------------- ---------------------------- ---------------------------- ---------------------------- ---------------------------- --------------D------------- -----------BBBCBB----------- ---------BBBBBCBBBB--------- --------------D------------- --------------G------------- --------------G------------- ---------------------------- ---------------------------- 
---------------------------- ---------------------------- ---------------------------- ---------------------------- ---------------------------- ---------------------------- ---------------------------- ---------------------------- ---------------------------- ---------------------------- ---------------------------- ---------------------------- ---------------------------- ---------------------------- ---------------------------- ---------------------------- ---------------------------- ---------------------------- ---------------------------- ---------------------------- ---------------------------- --------------D------------- --------------D------------- --------------D------------- --------------G------------- --------------G------------- ---------------------------- ---------------------------- ---------------------------- 
---------------------------- ---------------------------- ---------------------------- ---------------------------- ---------------------------- ---------------------------- ---------------------------- ---------------------------- ---------------------------- ---------------------------- ---------------------------- ---------------------------- ---------------------------- ---------------------------- ---------------------------- ---------------------------- ---------------------------- ---------------------------- ---------------------------- ---------------------------- ---------------------------- --------------G------------- --------------G------------- --------------G------------- ---------------------------- ---------------------------- ---------------------------- ---------------------------- ---------------------------- 
