model
size = 17 31 17, scale = 0.05, origin = -y
material 
  colors = A:#DDD586 B:#C5D1D4
voxels
----------------- ----------------- ----------------- ----------------- ----------------- ----------------- ----------------- ----------------- ----------------- ----------------- ----------------- ----------------- ----------------- ----------------- ----------------- ----------------- ----------------- ----------------- ------AAAAA------ ------AAAAA------ ------AAAAA------ ------AAAAA------ ------AAAAA------ ------BBBBB------ ------BBBBB------ ----------------- ----------------- ----------------- ----------------- ----------------- ----------------- 
----------------- ----------------- ----------------- ----------------- ----------------- ----------------- ----------------- ----------------- ----------------- ----------------- ----------------- ----------------- ----------------- ----------------- ----------------- ----------------- ----------------- ------AAAAA------ ----AAAAAAAAA---- ----AAAAAAAAA---- ----AAAAAAAAA---- ----AAAAAAAAA---- ----AAAAAAAAA---- ----BB-----BB---- ----BB-----BB---- ------BBBBB------ ------BBBBB------ ----------------- ----------------- ----------------- ----------------- 
----------------- ----------------- ----------------- ----------------- ----------------- ----------------- ----------------- ----------------- ----------------- ----------------- ----------------- ----------------- ----------------- ----------------- ----------------- ----------------- ----------------- ----AAAAAAAAA---- --AAAAAAAAAAAAA-- --AAAAAAAAAAAAA-- --AAAAAAAAAAAAA-- --AAAAAAAAAAAAA-- --AAAAAAAAAAAAA-- --BB---------BB-- --BB---------BB-- ----BB-----BB---- ----BB-----BB---- ------BBBBB------ ------BBBBB------ ----------------- ----------------- 
------BBBBB------ ----------------- ----------------- ----------------- ----------------- ----------------- ----------------- ----------------- ----------------- ----------------- ----------------- ----------------- ----------------- ----------------- ----------------- ----------------- ------AAAAA------ ---AAAAAAAAAAA--- --AAAAAAAAAAAAA-- --AAAAAAAAAAAAA-- --AAAAAAAAAAAAA-- --AAAAAAAAAAAAA-- --AAAAAAAAAAAAA-- --B-----------B-- --B-----------B-- ---B---------B--- ---B---------B--- ----BB-----BB---- ----BB-----BB---- ------BBBBB------ ------BBBBB------ 
-----BBBBBBB----- ----------------- ----------------- ----------------- ----------------- ----------------- ----------------- ----------------- ----------------- ----------------- ----------------- ----------------- ----------------- ----------------- ----------------- ------AAAAA------ -----AAAAAAA----- --AAAAAAAAAAAAA-- -AAAAAAAAAAAAAAA- -AAAAAAAAAAAAAAA- -AAAAAAAAAAAAAAA- -AAAAAAAAAAAAAAA- -AAAAAAAAAAAAAAA- -B-------------B- -B-------------B- --B-----------B-- --B-----------B-- ---BB-------BB--- ---BB-------BB--- -----B-----B----- -----B-----B----- 
----BBBBBBBBB---- ----------------- ----------------- ----------------- ----------------- ----------------- ----------------- ----------------- ----------------- ----------------- ----------------- ----------------- ----------------- ----------------- ----------------- -----AAAAAAA----- ----AAAAAAAAA---- --AAAAAAAAAAAAA-- -AAAAAAAAAAAAAAA- -AAAAAAAAAAAAAAA- -AAAAAAAAAAAAAAA- -AAAAAAAAAAAAAAA- -AAAAAAAAAAAAAAA- -B-------------B- -B-------------B- --B-----------B-- --B-----------B-- ---B---------B--- ---B---------B--- ----B-------B---- ----B-------B---- 
---BBBBBBBBBBB--- -------BBB------- ----------------- ----------------- ----------------- ----------------- ----------------- ----------------- ----------------- ----------------- ----------------- ----------------- ----------------- ----------------- -------AAA------- ----AAAAAAAAA---- ---AAAAAAAAAAA--- -AAAAAAAAAAAAAAA- AAAAAAAAAAAAAAAAA AAAAAAAAAAAAAAAAA AAAAAAAAAAAAAAAAA AAAAAAAAAAAAAAAAA AAAAAAAAAAAAAAAAA B---------------B B---------------B -B-------------B- -B-------------B- --B-----------B-- --B-----------B-- ---B---------B--- ---B---------B--- 
---BBBBBBBBBBB--- ------BBBBB------ -------BBB------- --------B-------- --------B-------- --------B-------- --------B-------- --------B-------- --------B-------- --------B-------- --------B-------- --------B-------- --------B-------- -------BBB------- ------AAAAA------ ----AAAAAAAAA---- ---AAAAAAAAAAA--- -AAAAAAAAAAAAAAA- AAAAAAAAAAAAAAAAA AAAAAAAAAAAAAAAAA AAAAAAAAAAAAAAAAA AAAAAAAAAAAAAAAAA AAAAAAAAAAAAAAAAA B---------------B B---------------B -B-------------B- -B-------------B- --B-----------B-- --B-----------B-- ---B---------B--- ---B---------B--- 
---BBBBBBBBBBB--- ------BBBBB------ -------BBB------- -------BBB------- -------BBB------- -------BBB------- -------BBB------- -------BBB------- -------BBB------- -------BBB------- -------BBB------- -------BBB------- -------BBB------- -------BBB------- ------AAAAA------ ----AAAAAAAAA---- ---AAAAAAAAAAA--- -AAAAAAAAAAAAAAA- AAAAAAAAAAAAAAAAA AAAAAAAAAAAAAAAAA AAAAAAAAAAAAAAAAA AAAAAAAAAAAAAAAAA AAAAAAAAAAAAAAAAA B---------------B B---------------B -B-------------B- -B-------------B- --B-----------B-- --B-----------B-- ---B---------B--- ---B---------B--- 
---BBBBBBBBBBB--- ------BBBBB------ -------BBB------- --------B-------- --------B-------- --------B-------- --------B-------- --------B-------- --------B-------- --------B-------- --------B-------- --------B-------- --------B-------- -------BBB------- ------AAAAA------ ----AAAAAAAAA---- ---AAAAAAAAAAA--- -AAAAAAAAAAAAAAA- AAAAAAAAAAAAAAAAA AAAAAAAAAAAAAAAAA AAAAAAAAAAAAAAAAA AAAAAAAAAAAAAAAAA AAAAAAAAAAAAAAAAA B---------------B B---------------B -B-------------B- -B-------------B- --B-----------B-- --B-----------B-- ---B---------B--- ---B---------B--- 
---BBBBBBBBBBB--- -------BBB------- ----------------- ----------------- ----------------- ----------------- ----------------- ----------------- ----------------- ----------------- ----------------- ----------------- ----------------- ----------------- -------AAA------- ----AAAAAAAAA---- ---AAAAAAAAAAA--- -AAAAAAAAAAAAAAA- AAAAAAAAAAAAAAAAA AAAAAAAAAAAAAAAAA AAAAAAAAAAAAAAAAA AAAAAAAAAAAAAAAAA AAAAAAAAAAAAAAAAA B---------------B B---------------B -B-------------B- -B-------------B- --B-----------B-- --B-----------B-- ---B---------B--- ---B---------B--- 
----BBBBBBBBB---- ----------------- ----------------- ----------------- ----------------- ----------------- ----------------- ----------------- ----------------- ----------------- ----------------- ----------------- ----------------- ----------------- ----------------- -----AAAAAAA----- ----AAAAAAAAA---- --AAAAAAAAAAAAA-- -AAAAAAAAAAAAAAA- -AAAAAAAAAAAAAAA- -AAAAAAAAAAAAAAA- -AAAAAAAAAAAAAAA- -AAAAAAAAAAAAAAA- -B-------------B- -B-------------B- --B-----------B-- --B-----------B-- ---B---------B--- ---B---------B--- ----B-------B---- ----B-------B---- 
-----BBBBBBB----- ----------------- ----------------- ----------------- ----------------- ----------------- ----------------- ----------------- ----------------- ----------------- ----------------- ----------------- ----------------- ----------------- ----------------- ------AAAAA------ -----AAAAAAA----- --AAAAAAAAAAAAA-- -AAAAAAAAAAAAAAA- -AAAAAAAAAAAAAAA- -AAAAAAAAAAAAAAA- -AAAAAAAAAAAAAAA- -AAAAAAAAAAAAAAA- -B-------------B- -B-------------B- --B-----------B-- --B-----------B-- ---BB-------BB--- ---BB-------BB--- -----B-----B----- -----B-----B----- 
------BBBBB------ ----------------- ----------------- ----------------- ----------------- ----------------- ----------------- ----------------- ----------------- ----------------- ----------------- ----------------- ----------------- ----------------- ----------------- ----------------- ------AAAAA------ ---AAAAAAAAAAA--- --AAAAAAAAAAAAA-- --AAAAAAAAAAAAA-- --AAAAAAAAAAAAA-- --AAAAAAAAAAAAA-- --AAAAAAAAAAAAA-- --B-----------B-- --B-----------B-- ---B---------B--- ---B---------B--- ----BB-----BB---- ----BB-----BB---- ------BBBBB------ ------BBBBB------ 
----------------- ----------------- ----------------- ----------------- ----------------- ----------------- ----------------- ----------------- ----------------- ----------------- ----------------- ----------------- ----------------- ----------------- ----------------- ----------------- ----------------- ----AAAAAAAAA---- --AAAAAAAAAAAAA-- --AAAAAAAAAAAAA-- --AAAAAAAAAAAAA-- --AAAAAAAAAAAAA-- --AAAAAAAAAAAAA-- --BB---------BB-- --BB---------BB-- ----BB-----BB---- ----BB-----BB---- ------BBBBB------ ------BBBBB------ ----------------- ----------------- 
----------------- ----------------- ----------------- ----------------- ----------------- ----------------- ----------------- ----------------- ----------------- ----------------- ----------------- ----------------- ----------------- ----------------- ----------------- ----------------- ----------------- ------AAAAA------ ----AAAAAAAAA---- ----AAAAAAAAA---- ----AAAAAAAAA---- ----AAAAAAAAA---- ----AAAAAAAAA---- ----BB-----BB---- ----BB-----BB---- ------BBBBB------ ------BBBBB------ ----------------- ----------------- ----------------- ----------------- 
----------------- ----------------- ----------------- ----------------- ----------------- ----------------- ----------------- ----------------- ----------------- ----------------- ----------------- ----------------- ----------------- ----------------- ----------------- ----------------- ----------------- ----------------- ------AAAAA------ ------AAAAA------ ------AAAAA------ ------AAAAA------ ------AAAAA------ ------BBBBB------ ------BBBBB------ ----------------- ----------------- ----------------- ----------------- ----------------- ----------------- 
