model
size = 11 32 11, scale = 0.05, origin = -y
material 
  colors = A:#967249 B:#004383 C:#EEE D:#FFC408 E:#222
voxels
26-3A7-5A12(6-4AC)2(6-5A)7-3A8-3A9-A10-A129-5A5-2(7A4-)6AC10(4-6AB)4-6AC3(4-7A)5-5A6-5A7-3A8-3A9-C97-3A6-7A3-2(9A2-)C6A2C2-C6A2B3(2-C6ABC)2(2-C6A2B)2(2-C6ABD2-C6A2B)2-C6A2C3(2-9A)3-7A4-7A5-5A6-5A7-CAC9-B85-A3-A4-9A2-9A-11A2C6A3CEC6A4B4(C6A2BCB)C6A4BC6ABD2BC6AB2DBC6ABD2BC6A3B2C6A3C22A-2(9A2-)9A3-7A4-6AC5-4AC6-ACA2B7-C2B9-C42-3A8-3A6-A5-A3-9A-22A2C6A3CE2(C6A4B)C2(6A2BCBC6A2B3C)2(6A4BC6A3B2C)6A3C44A-2(9A2-)8AC3-6AB5-4AD6-4AB7-2AC3(8-3A)7-A3-A6-A3-2(A5-)A3-9A-22A2C6A3CB3(C6A4B)C6A2B3C3(6A2BCBC)6A3B2C6A4BC6A3B2C6A3C38A2(-10A)-4AC-4A-3AB2-4A-3AB3-3A-2AC5-2A-AB6-2A-AC7-2(A-A8-)A-A7-A3-A6-A3-2(A5-)A3-9A-22A2C6A3CDC6A4BC6A2BDBC6A4BC6A3B2C6A4BC6A2B3C6A2BCBC6A2B3C6A4BC6A3B2C6A3C44A-2(9A2-)8AC3-6AB5-4AC6-4AB7-2AC3(8-3A)7-2(A3-A6-)A3-A4-9A2-9A-11A2C6A3CB2(C6A4B)2(C6A2BCB)C6A4BC6A3B2C6A2BCBC6A2B3C6A2BCBC6A3B2C6A3C22A-2(9A2-)9A3-7A4-6AC5-4AC6-ACA2B7-C2B9-C42-2(3A8-)3A6-7A3-2(9A2-)C6A2C2(2(2-C6A2B)2(2-C6ABC))2-C6ABC2-C6A2B2-C6A2C3(2-9A)3-7A4-7A5-5A6-5A7-CAC9-B96-5A5-2(7A4-)6AC2(4-6AB)2(4-6AC)6(4-6AB)4-6AC3(4-7A)5-5A6-5A7-3A8-3A9-C119-3A7-5A12(6-4AC)2(6-5A)7-3A8-3A9-A10-A115-
