model
size = 11 32 11, scale = 0.05, origin = -y
material 
  colors = A:#5D7C30 B:#F7D94C C:#004383 D:#EEE E:#65924D F:#FFC408
voxels
26-3A7-6(5A6-)4(5B6-)4(5A6-)5A7-3A8-3A9-A10-A129-5A5-5(7A4-)2(B5AB4-)2B3ABA4-2B4AB4-AB5A4-2B4A2(B4-B5A)B4(4-7A)5-5A6-5A7-3A8-3A9-A97-3A6-7A3-2(9A2-)7ADA2-AC5ACA2(2-BC5ACB)2-EC5ACE2-3B3A3B2-AC5ACA2(2-BC5ACB)2-EC5ACE2-BC5ACB2-BD5ADB2-B7AB2(2-9A)3-7A4-7A5-5A6-5A7-3A9-A85-A3-A4-9A2-9A-12AD6A2DAB2(2C5A2C2B)2C5A2CBE2C5A2CE4B3A2BCBA2C5A2CBA2C5ACFAB2C5ACFBE2C5ACF2E2C5A2CEB2D5A2D2(2B9A)B-2(9A2-)9A3-7A4-7A5-5A6-5A7-3A9-A42-3A8-3A6-A5-A3-9A-22ABD6A2D2(2B2C5A2C)BE2C5A2CED2C5A2CD4B3A2BC2B2C5A2C2A2C5A2C2B2C5A2CBE2(2C5A2C2E)2D5A2DEB2(9A2B)9AB11A-2(9A2-)9A3-7A5-5A6-5A7-3A2(8-3B)8-3A7-A3-A6-A3-2(A5-)A3-9A-22ABD6A2D2B2C5A2CBE2C5A2C2E2C5A2CED2C5A2CD4B3A4BA2C5A2CAB2C5A2C2B2C5A2CBE2(2C5A2C2E)2D5A2DEB2(9A2B)9AB5A2(-10A)-5A2(-4A)2-4A-4A3-3A-3A5-2A-2A6-2A-2A7-2(B-B8-)A-A7-A3-A6-A3-2(A5-)A3-9A-22ABD6A2D2(2B2C5A2C)BE2C5A2CED2C5A2CDBC2B3A4BA2C5A2C2B2C5A2CAB2C5A2CBE2(2C5A2C2E)2D5A2DEB2(9A2B)9AB11A-2(9A2-)9A3-7A5-5A6-5A7-3A2(8-3B)8-3A7-2(A3-A6-)A3-A4-9A2-9A-12AD6A2DAB2(2C5A2C2B)2C5A2CBE2C5A2CEBC2B3A5B2C5A2C2AFC5A2CABFC5A2CBEFC5A2C2E2C5A2CEB2D5A2D2(2B9A)B-2(9A2-)9A3-7A4-7A5-5A6-5A7-3A9-A42-2(3A8-)3A6-7A3-2(9A2-)7ADA2-AC5ACA2(2-BC5ACB)2-EC5ACE2-3B3A3B2-AC5ACA2(2-BC5ACB)2-EC5ACE2-BC5ACB2-BD5ADB2-B7AB2(2-9A)3-7A4-7A5-5A6-5A7-3A9-A96-5A5-5(7A4-)2(B5AB4-)AB3A2B4-B4A2B4-5ABA4-B4A2B2(4-B5AB)4(4-7A)5-5A6-5A7-3A8-3A9-A119-3A7-6(5A6-)4(5B6-)4(5A6-)5A7-3A8-3A9-A10-A115-
