model
size = 11 28 11, scale = 0.05, origin = -y
material 
  colors = A:#CAAD5F B:#FFD724 C:#004383 D:#AAA E:#65924D F:#BBB G:#EEE
voxels
----------- ----------- ----BBB---- ---BBBBB--- ---BBBBB--- ---BBBBB--- ---BBBBB--- ---BBBBB--- ---BBBBB--- ---BBBBB--- ---BBBBB--- ---BBBBB--- ---BBBBB--- ---EEEBB--- ---BBEBB--- ---BBEBB--- ---BBEBB--- ---EEEBB--- ---BBBBB--- ---BBBBB--- ---BBBBB--- ---BBBBB--- ---BBBBB--- ---BBBBB--- ---BBBBB--- ---BBBBB--- ----DDD---- ----------- 
----------- ---DDDDD--- --BBAAABB-- --BBAAABB-- --BBAAABB-- --BBAAABB-- --BBAAABB-- --BBAAABB-- --BBAAABB-- --BBAAABB-- --EBAAABB-- --EBAAABB-- --EBAAABB-- --BBAAABB-- --BBAAABB-- --BBAAABB-- --EBAAABB-- --BBAAABB-- --EBAAABB-- --EBAAABB-- --EBAAABB-- --BBAAABB-- --BBAAABB-- --BBAAABB-- --BBAAABB-- --BB---BB-- ---DBBBD--- ----DDD---- 
----FFF---- --DDBBBDD-- -BBAAAAABB- -BBAAAAABB- -BBAAAAAGB- -BBAAAAACB- -BBAAAAACB- -BCAAAAACB- -BCAAAAACB- -ECAAAAABB- -BCAAAAABB- -BBAAAAABB- -BBAAAAAGB- -BBAAAAACB- -BGAAAAACB- -BCAAAAACB- -BCAAAAACB- -BCAAAAACB- -BBAAAAABB- -BCAAAAACB- -BCAAAAACB- -ECAAAAACB- -BCAAAAACB- -BGAAAAABB- -BBAAAAABB- -BB-----BB- --DBFFFBD-- ---D---D--- 
---F---F--- -DDBDDDBDD- -BAAAAAAAB- BBAAAAAAABB BAAAAAAAAGB BAAAAAAAACB BAAAAAAAACB BCAAAAAAACB ECAAAAAAACB BCAAAAAAACB BCAAAAAAABB EBAAAAAAABB EBBAAAAAAGB BBAAAAAAACB BGAAAAAAACB ECAAAAAAACB EBAAAAAAACB BCAAAAAAACB BCAAAAAAABB ECAAAAAAACB BCAAAAAAACB BCAAAAAAACB ECAAAAAAACB BGAAAAAAAGB BBAAAAAAABB BB-------BB -DBFFFFFBD- --D-----D-- 
--F-----F-- -DBDDDDDBD- BBAAAAAAABB BBAAAAAAABB BAAAAAAAAGB BAAAAAAAACB BAAAAAAAACB ECAAAAAAACB BCAAAAAAACB BCAAAAAAACB ECAAAAAAABB EBAAAAAAABB GBBAAAAAAGB BBAAAAAAACB BGAAAAAAACB BCAAAAAAACB BCAAAAAAACB BCAAAAAAACB BCAAAAAAABB ECAAAAAAACB ECAAAAAAACB BCAAAAAAACB BCAAAAAAACB EGAAAAAAAGB BBAAAAAAABB BB-------BB DBF--FFFFBD -D---FFFFFF 
--F-----F-- -DBDDDDDBD- BBAAAAAAABB BBAAAAAAABB BAAAAAAAAGB BAAAAAAAACB BAAAAAAAACB ECAAAAAAACB BCAAAAAAACB BCAAAAAAABB ECAAAAAAABB EBAAAAAAABB GBBAAAAAAGB BBAAAAAAACB BGAAAAAAACB BCAAAAAAACB ECAAAAAAACB BCAAAAAAACB BBAAAAAAABB ECAAAAAAACB ECAAAAAAACB ECAAAAAAACB BCAAAAAAACB EGAAAAAAAGB BBAAAAAAABB BB-------BB DBF--FFFFFD -D---F-F--F 
--F-----F-- -DBDDDDDBD- BBAAAAAAABB BBAAAAAAABB BAAAAAAAAGB BAAAAAAAACB BAAAAAAAACB ECAAAAAAACB BCAAAAAAACB BCAAAAAAABB ECAAAAAAABB ECAAAAAAABB GBBAAAAAAGB BBAAAAAAACB BGAAAAAAACB BCAAAAAAACB ECAAAAAAACB BCAAAAAAACB BBAAAAAAACB ECAAAAAAACB ECAAAAAAACB BCAAAAAAACB BCAAAAAAACB EGAAAAAAAGB BBAAAAAAABB BB-------BB DBF--FFFFBD -D---FFFFFF 
---F---F--- -DDBDDDBDD- -BAAAAAAAB- BBAAAAAAABB BAAAAAAAAGB BAAAAAAAACB BAAAAAAAACB BCAAAAAAACB ECAAAAAAACB BCAAAAAAABB BCAAAAAAABB ECAAAAAAABB EBBAAAAAAGB BBAAAAAAACB BGAAAAAAABB BCAAAAAAABB BCAAAAAAABB BCAAAAAAACB BBAAAAAAACB ECAAAAAAACB BCAAAAAAACB BCAAAAAAACB ECAAAAAAACB BGAAAAAAAGB BBAAAAAAABB BB-------BB -DBFFFFFBD- --D-----D-- 
----FFF---- --DDBBBDD-- -BBAAAAABB- -BBAAAAABB- -BBAAAAAGB- -BBAAAAACB- -BBAAAAACB- -BCAAAAACB- -BCAAAAACB- -ECAAAAABB- -BCAAAAABB- -BBAAAAABB- -BBAAAAAGB- -BBAAAAACB- -BGAAAAACB- -BCAAAAACB- -ECAAAAACB- -BCAAAAACB- -BBAAAAABB- -BCAAAAACB- -BCAAAAACB- -ECAAAAACB- -BCAAAAACB- -BGAAAAABB- -BBAAAAABB- -BB-----BB- --DBFFFBD-- ---D---D--- 
----------- ---DDDDD--- --BBAAABB-- --BBAAABB-- --BBAAABB-- --BBAAABB-- --BBAAABB-- --BBAAABB-- --BBAAABB-- --BBAAABB-- --EBAAABB-- --EBAAABB-- --EBAAABB-- --BBAAABB-- --BBAAABB-- --EBAAABB-- --BBAAABB-- --BBAAABB-- --EBAAABB-- --EBAAABB-- --EBAAABB-- --BBAAABB-- --BBAAABB-- --BBAAABB-- --BBAAABB-- --BB---BB-- ---DBBBD--- ----DDD---- 
----------- ----------- ----BBB---- ---BBBBB--- ---BBBBB--- ---BBBBB--- ---BBBBB--- ---BBBBB--- ---BBBBB--- ---BBBBB--- ---BBBBB--- ---BBBBB--- ---BBBBB--- ---EEEBB--- ---BBEBB--- ---BBEBB--- ---BBEBB--- ---EEEBB--- ---BBBBB--- ---BBBBB--- ---BBBBB--- ---BBBBB--- ---BBBBB--- ---BBBBB--- ---BBBBB--- ---BBBBB--- ----DDD---- ----------- 
