model
size = 28 30 28, scale = 0.05, origin = -y
material 
  colors = A:#EEE B:#CC6 C:#993 D:#555 E:#3CF F:#F06 G:#FC9 H:#FF3 I:#F63 J:#CFF K:#CCC L:#F9F M:#CC9 N:#FF6 O:#F9C P:#F3F Q:#FF0 R:#F30 S:#FCF T:#F90 U:#FFC V:#FC0 W:#F99 X:#CCF Y:#FC3 Z:#F0F Aa:#CF3 Ab:#F66 Ac:#CFC Ad:#F39 Ae:#CC0 Af:#FF9 Ag:#F36 Ah:#F6C Ai:#F03 Aj:#FFF Ak:#F09 Al:#F96 Am:#F69 An:#F60 Ao:#F00 Ap:#F3C Aq:#F33 Ar:#CF6 As:#CC3 At:#CF9 Au:#F93 Av:#FCC Aw:#CF0 Ax:#FC6 Ay:#F0C Az:#F6F
voxels
D D D D D D D D D D D D D D D D D D D D D D D D D D D D   D A A A A A A A A A A A A A A A A A A A A A A A A A A D   D A A A A A A A A A A A A A A A A A A A A A A A A A A D   D A A A A A A A A A A A A A A A A A A A A A A A A A A D   D A A A A A A A A A A A A A A A A A A A A A A A A A A D   D A A A A A A A A A A A A A A A A A A A A A A A A A A D   D A A A A A A A A A A A A A A A A A A A A A A A A A A D   D A A A A A A A A A A A A A A A A A A A A A A A A A A D   D A A A A A A A A A A A A A A A A A A A A A A A A A A D   D A A A A A A A A A A A A A A A A A A A A A A A A A A D   D A A A A A A A A A A A A A A A A A A A A A A A A A A D   D A A A A A A A A A A A A A A A A A A A A A A A A A A D   D A A A A A A A A A A A A A A A A A A A A A A A A A A D   D A A A A A A A A A A A A A A A A A A A A A A A A A A D   D A A A A A A A A A A A A A A A A A A A A A A A A A A D   D A A A A A A A A A A A A A A A A A A A A A A A A A A D   D A A A A A A A A A A A A A A A A A A A A A A A A A A D   D A A A A A A A A A A A A A A A A A A A A A A A A A A D   D A A A A A A A A A A A A A A A A A A A A A A A A A A D   D A A A A A A A A A A A A A A A A A A A A A A A A A A D   D A A A A A A A A A A A A A A A A A A A A A A A A A A D   D A A A A A A A A A A A A A A A A A A A A A A A A A A D   D A A A A A A A A A A A A A A A A A A A A A A A A A A D   D A A A A A A A A A A A A A A A A A A A A A A A A A A D   D A A A A A A A A A A A A A A A A A A A A A A A A A A D   D A A A A A A A A A A A A A A A A A A A A A A A A A A D   D A A A A A A A A A A A A A A A A A A A A A A A A A A D   D D D D D D D D D D D D D D D D D D D D D D D D D D D D   - - - - - - - - - - - - - - - - - - - - - - - - - - - -   - - - - - - - - - - - - - - - - - - - - - - - - - - - -   
D A A A A A A A A A A A A A A A A A A A A A A A A A A D   A A A A A A A A A A A A A A A A A A A A A A A A A A A A   A A A A A A A A A A A A A A A A A A A A A A A A A A A A   A A A A A A A A A A A A A A A A A A A A A A A A A A A A   A A A A A A A A A A A A A A A A A A A A A A A A A A A A   A A A A A A A A A A A A A A A A A A A A A A A A A A A A   A A A A A A A A A A A A A A A A A A A A A A A A A A A A   A A A A A A A A A A A A A A A A A A A A A A A A A A A A   A A A A A A A A A A A A A A A A A A A A A A A A A A A A   A A A A A A A A A A A A A A A A A A A A A A A A A A A A   A A A A A A A A A A A A A A A A A A A A A A A A A A A A   A A A A A A A A A A A A A A A A A A A A A A A A A A A A   A A A A A A A A A A A A A A A A A A A A A A A A A A A A   A A A A A A A A A A A A A A A A A A A A A A A A A A A A   A A A A A A A A A A A A A A A A A A A A A A A A A A A A   A A A A A A A A A A A A A A A A A A A A A A A A A A A A   A A A A A A A A A A A A A A A A A A A A A A A A A A A A   A A A A A A A A A A A A A A A A A A A A A A A A A A A A   A A A A A A A A A A A A A A A A A A A A A A A A A A A A   A A A A A A A A A A A A A A A A A A A A A A A A A A A A   A A A A A A A A A A A A A A A A A A A A A A A A A A A A   A A A A A A A A A A A A A A A A A A A A A A A A A A A A   A A A A A A A A A A A A A A A A A A A A A A A A A A A A   A A A A A A A A A A A A A A A A A A A A A A A A A A A A   A A A A A A A A A A A A A A A A A A A A A A A A A A A A   A A A A A A A A A A A A A A A A A A A A A A A A A A A A   A A A A A A A A A A A A A A A A A A A A A A A A A A A A   D A A A A A A A A A A A A A A A A A A A A A A A A A A D   - - - - - - - - - - - - - - - - - - - - - - - - - - - -   - - - - - - - - - - - - - - - - - - - - - - - - - - - -   
D A A A A A A A A A A A A A A A A A A A A A A A A A A D   A A A A A A A A A A A A A A A A A A A A A A A A A A A A   A A A A A A A A A A A A A A A A A A A A A A A A A A A A   A A A A A A A A A A A A A A A A A A A A A A A A A A A A   A A A A A A A A A A A A A A A A A A A A A A A A A A A A   A A A A A A A A A A A A A A A A A A A A A A A A A A A A   A A A A A A A A A A A A A A A A A A A A A A A A A A A A   A A A A A A A A A A A A A A A A A A A A A A A A A A A A   A A A A A A A A A A A A A A A A A A A A A A A A A A A A   A A A A A A A A A A A A A A A A A A A A A A A A A A A A   A A A A A A A A A A A A A A A A A A A A A A A A A A A A   A A A A A A A A A A A A A A A A A A A A A A A A A A A A   A A A A A A A A A A A A A A A A A A A A A A A A A A A A   A A A A A A A A A A A A A A A A A A A A A A A A A A A A   A A A A A A A A A A A A A A A A A A A A A A A A A A A A   A A A A A A A A A A A A A A A A A A A A A A A A A C - -   A A A A A A A A A A A A A A A A A A A A A A A A A C - -   A A A A A A A A A A A A A A A A A A A A A A A A A C - -   A A A A A A A A A A A A A A A A A A A A A A A A A C - -   A A A A A A A A A A A A A A A A A A A A A A A A A C - -   A A A A A A A A A A A A A A A A A A A A A A A A A C - -   A A A A A A A A A A A A A A A A A A A A A A A A A C - -   A A A A A A A A A A A A A A A A A A A A A A A A A C - -   A A A A A A A A A A A A A A A A A A A A A A A A A C - -   A A A A A A A A A A A A A A A A A A A A A A A A A A A A   A A A A A A A A A A A A A A A A A A A A A A A A A A A A   A A A A A A A A A A A A A A A A A A A A A A A A A A A A   D A A A A A A A A A A A A A A A A A A A A A A A A A A D   - - - - - - - - - - - - - - - - - - - - - - - - - - - -   - - - - - - - - - - - - - - - - - - - - - - - - - - - -   
D A A A A A A A A A A A A A A A A A A A A A A A A A A D   A A A A B B B B B B B B B B B B B B B B B B B B A A A A   A A A A B B B B B B B B B B B B B B B B B B B B A A A A   A A A A B B B B B B B B B B B B B B B B B B B B A A A A   A A A A B B B B B B B B B B B B B B B B B B B B A A A A   A A A A B B B B B B B B B B B B B B B B B B B B A A A A   A A A A B B B B B B B B B B B B B B B B B B B B A A A A   A A A A B B B B B B B B B B B B B B B B B B B B A A A A   A A A A B B B B B B B B B B B B B B B B B B B B A A A A   A A A A B B B B B B B B B B B B B B B B B B B B A A A A   A A A A B B B B B B B B B B B B B B B B B B B B A A A A   A A A A B B B B B B B B B B B B B B B B B B B B A A A A   A A A A B B B B B B B B B B B B B B B B B B B B A A A A   A A A A B B B B B B B B B B B B B B B B B B B B A A A A   A A A A B B B B B B B B B B B B B B B B B B B B A C - -   A A A A B B B B B B B B B B B B B B B B B B B B A C - -   A A A A B B B B B B B B B B B B B B B B B B B B A C - -   A A A A B B B B B B B B B B B B B B B B B B B B A C - -   A A A A A A A A A A A A A A A A A A A A A A A A A C - -   A A A A A A A A A A A A A A A A A A A A A A A A A C - -   A A A A A A A A A A A A A A A A A A A A A A A A A C - -   A A A A A A A A A A A A A A A A A A A A A A A A A C - -   A A A A A A A A A A A A A A A A A A A A A A A A A C - -   A A A A A A A A A A A A A A A A A A A A A A A A A C - -   A A A A A A A A A A A A A A A A A A A A A A A A A C - -   A A A A A A A A A A A A A A A A A A A A A A A A A A A A   A A A A A A A A A A A A A A A A A A A A A A A A A A A A   D A A A A A A A A A A A A A A A A A A A A A A A A A A D   - - - - - - - - - - - - - - - - - - - - - - - - - - - -   - - - - - - - - - - - - - - - - - - - - - - - - - - - -   
D A A A - - - - - - - - - - - - - - - - - - - - A A A D   A A A B - - - - - - - - - - - - - - - - - - - - B A C -   A A A B - - - - - - - - - - - - - - - - - - - - B A C -   A A A B - - - - - - - - - - - - - - - - - - - - B A C -   A A A B - - - - - - - - - - - - - - - - - - - - B A C -   A A A B - - - - - - - - - - - - - - - - - - - - B A C -   A A A B - - - - - - - - - - - - - - - - - - - - B A C -   A A A B - - - - - - - - - - - - - - - - - - - - B A C -   A A A B - - - - - - - - - - - - - - - - - - - - B A A A   A A A B - - - - - - - - - - - - - - - - - - - - B A A A   A A A B - - - - - - - - - - - - - - - - - - - - B A A A   A A A B - - - - - - - - - - - - - - - - - - - - B A A A   A A A B - - - - - - - - - - - - - - - - - - - - B A A A   A A A B - - - - - - - - - - - - - - - - - - - - B C - -   A A A B - - - - - - - - - - - - - - - - - - - - B C - -   A A A B - - - - - - - - - - - - - - - - - - - - B C - -   A A A B - - - - - - - - - - - - - - - - - - - - B C - -   A A A B - - - - - - - - - - - - - - - - - - - - B C - -   A A A A W AvP H O AqZ Q AnX J AhV Z R G I G G AcA C - -   A A A A A A A A A A A A A A A A A A A A A A A A A C - -   A A A A A A A A A A A A A A A A A A A A A A A A A C - -   A A A A A A A A A A A A A A A A A A A A A A A A A C - -   A A A A A A A A A A A A A A A A A A A A A A A A A C - -   A A A A A A A A A A A A A A A A A A A A A A A A A C - -   A A A A A A A A A A A A A A A A A A A A A A A A A C - -   A A A A A A A A A A A A A A A A A A A A A A A A A C - -   A A A A A A A A A A A A A A A A A A A A A A A A A A A A   D A A A A A A A A A A A A A A A A A A A A A A A A A A D   - - - - - - - - - - - - - - - - - - - - - - - - - - - -   - - - - - - - - - - - - - - - - - - - - - - - - - - - -   
D A A A - - - - - - - - - - - - - - - - - - - - A A A D   A A A B - - - - - - - - - - - - - - - - - - - - B A A A   A A A B - - - - - - - - - - - - - - - - - - - - B A A A   A A A B - - - - - - - - - - - - - - - - - - - - B A A A   A A A B - - - - - - - - - - - - - - - - - - - - B A A A   A A A B - - - - - - - - - - - - - - - - - - - - B A A A   A A A B - - - - - - - - - - - - - - - - - - - - B A A A   A A A B - - - - - - - - - - - - - - - - - - - - B A C -   A A A B - - - - - - - - - - - - - - - - - - - - B A A A   A A A B - - - - - - - - - - - - - - - - - - - - B A A A   A A A B - - - - - - - - - - - - - - - - - - - - B A A A   A A A B - - - - - - - - - - - - - - - - - - - - B A A A   A A A B - - - - - - - - - - - - - - - - - - - - B A A A   A A A B - - - - - - - - - - - - - - - - - - - - B C - -   A A A B - - - - - - - - - - - - - - - - - - - - B C - -   A A A B - - - - - - - - - - - - - - - - - - - - B C - -   A A A B - - - - - - - - - - - - - - - - - - - - B C - -   A A A B - - - - - - - - - - - - - - - - - - - - B C - -   A A A A H N W M T AzS AvO I AsT AlH AzI I Q ArAoA C - -   A A A A A A A A A A A A A A A A A A A A A A A A A C - -   A A A A A A A A A A A A A A A A A A A A A A A A A C - -   A A A A A A A A A A A A A A A A A A A A A A A A A C - -   A A A A A A A A A A A A A A A A A A A A A A A A A C - -   A A A A A A A A A A A A A A A A A A A A A A A A A C - -   A A A A A A A A A A A A A A A A A A A A A A A A A C - -   A A A A A A A A A A A A A A A A A A A A A A A A A C - -   A A A A A A A A A A A A A A A A A A A A A A A A A A A A   D A A A A A A A A A A A A A A A A A A A A A A A A A A D   - - - - - - - - - - - - - - - - - - - - - - - - - - - -   - - - - - - - - - - - - - - - - - - - - - - - - - - - -   
D A A A - - - - - - - - - - - - - - - - - - - - A A A D   A A A B - - - - - - - - - - - - - - - - - - - - B A A A   A A A B - - - - - - - - - - - - - - - - - - - - B A A A   A A A B - - - - - - - - - - - - - - - - - - - - B A A A   A A A B - - - - - - - - - - - - - - - - - - - - B A A A   A A A B - - - - - - - - - - - - - - - - - - - - B A A A   A A A B - - - - - - - - - - - - - - - - - - - - B A A A   A A A B - - - - - - - - - - - - - - - - - - - - B A C -   A A A B - - - - - - - - - - - - - - - - - - - - B A A A   A A A B - - - - - - - - - - - - - - - - - - - - B A A A   A A A B - - - - - - - - - - - - - - - - - - - - B A A A   A A A B - - - - - - - - - - - - - - - - - - - - B A A A   A A A B - - - - - - - - - - - - - - - - - - - - B A A A   A A A B - - - - - - - - - - - - - - - - - - - - B C - -   A A A B - - - - - - - - - - - - - - - - - - - - B C - -   A A A B - - - - - - - - - - - - - - - - - - - - B C - -   A A A B - - - - - - - - - - - - - - - - - - - - B C - -   A A A B - - - - - - - - - - - - - - - - - - - - B C - -   A A A A M S AeU F AtAkN T I AwH AqAhO N P K AbJ A C - -   A A A A A A A A A A A A A A A A A A A A A A A A A C - -   A A A A A A A A A A A A A A A A A A A A A A A A A C - -   A A A A A A A A A A A A A A A A A A A A A A A A A C - -   A A A A A A A A A A A A A A A A A A A A A A A A A C - -   A A A A A A A A A A A A A A A A A A A A A A A A A C - -   A A A A A A A A A A A A A A A A A A A A A A A A A C - -   A A A A A A A A A A A A A A A A A A A A A A A A A C - -   A A A A A A A A A A A A A A A A A A A A A A A A A A A A   D A A A A A A A A A A A A A A A A A A A A A A A A A A D   - - - - - - - - - - - - - - - - - - - - - - - - - - - -   - - - - - - - - - - - - - - - - - - - - - - - - - - - -   
D A A A - - - - - - - - - - - - - - - - - - - - A A A D   A A A B - - - - - - - - - - - - - - - - - - - - B A A A   A A A B - - - - - - - - - - - - - - - - - - - - B A A A   A A A B - - - - - - - - - - - - - - - - - - - - B A A A   A A A B - - - - - - - - - - - - - - - - - - - - B A A A   A A A B - - - - - - - - - - - - - - - - - - - - B A A A   A A A B - - - - - - - - - - - - - - - - - - - - B A A A   A A A B - - - - - - - - - - - - - - - - - - - - B A C -   A A A B - - - - - - - - - - - - - - - - - - - - B A A A   A A A B - - - - - - - - - - - - - - - - - - - - B A A A   A A A B - - - - - - - - - - - - - - - - - - - - B A A A   A A A B - - - - - - - - - - - - - - - - - - - - B A A A   A A A B - - - - - - - - - - - - - - - - - - - - B A A A   A A A B - - - - - - - - - - - - - - - - - - - - B C - -   A A A B - - - - - - - - - - - - - - - - - - - - B C - -   A A A B - - - - - - - - - - - - - - - - - - - - B C - -   A A A B - - - - - - - - - - - - - - - - - - - - B C - -   A A A B - - - - - - - - - - - - - - - - - - - - B C - -   A A A A U AkM AgO N L S F P AvAgAsX Z AcW S R G A C - -   A A A A A A A A A A A A A A A A A A A A A A A A A C E -   A A A A A A A A A A A A A A A A A A A A A A A A A C E -   A A A A A A A A A A A A A A A A A A A A A A A A A C - -   A A A A A A A A A A A A A A A A A A A A A A A A A C - -   A A A A A A A A A A A A A A A A A A A A A A A A A C - -   A A A A A A A A A A A A A A A A A A A A A A A A A C - -   A A A A A A A A A A A A A A A A A A A A A A A A A C - -   A A A A A A A A A A A A A A A A A A A A A A A A A A A A   D A A A A A A A A A A A A A A A A A A A A A A A A A A D   - - - - - - - - - - - - - - - - - - - - - - - - - - - -   - - - - - - - - - - - - - - - - - - - - - - - - - - - -   
D A A A - - - - - - - - - - - - - - - - - - - - A A A D   A A A B - - - - - - - - - - - - - - - - - - - - B A A A   A A A B - - - - - - - - - - - - - - - - - - - - B A A A   A A A B - - - - - - - - - - - - - - - - - - - - B A A A   A A A B - - - - - - - - - - - - - - - - - - - - B A A A   A A A B - - - - - - - - - - - - - - - - - - - - B A A A   A A A B - - - - - - - - - - - - - - - - - - - - B A A A   A A A B - - - - - - - - - - - - - - - - - - - - B A C -   A A A B - - - - - - - - - - - - - - - - - - - - B A A A   A A A B - - - - - - - - - - - - - - - - - - - - B A A A   A A A B - - - - - - - - - - - - - - - - - - - - B A A A   A A A B - - - - - - - - - - - - - - - - - - - - B A A A   A A A B - - - - - - - - - - - - - - - - - - - - B A A A   A A A B - - - - - - - - - - - - - - - - - - - - B C - -   A A A B - - - - - - - - - - - - - - - - - - - - B C - -   A A A B - - - - - - - - - - - - - - - - - - - - B C - -   A A A B - - - - - - - - - - - - - - - - - - - - B C - -   A A A B - - - - - - - - - - - - - - - - - - - - B C - -   A A A A AgAwF AjAaB V AkO W AkAuAdI H AoAeB AzQ A C E -   A A A A A A A A A A A A A A A A A A A A A A A A A C E -   A A A A A A A A A A A A A A A A A A A A A A A A A C E -   A A A A A A A A A A A A A A A A A A A A A A A A A C E -   A A A A A A A A A A A A A A A A A A A A A A A A A C - -   A A A A A A A A A A A A A A A A A A A A A A A A A C - -   A A A A A A A A A A A A A A A A A A A A A A A A A C - -   A A A A A A A A A A A A A A A A A A A A A A A A A C - -   A A A A A A A A A A A A A A A A A A A A A A A A A A A A   D A A A A A A A A A A A A A A A A A A A A A A A A A A D   - - - - - - - - - - - - - - - - - - - - - - - - - - - -   - - - - - - - - - - - - - - - - - - - - - - - - - - - -   
D A A A - - - - - - - - - - - - - - - - - - - - A A A D   A A A B - - - - - - - - - - - - - - - - - - - - B A C -   A A A B - - - - - - - - - - - - - - - - - - - - B A C -   A A A B - - - - - - - - - - - - - - - - - - - - B A C -   A A A B - - - - - - - - - - - - - - - - - - - - B A C -   A A A B - - - - - - - - - - - - - - - - - - - - B A C -   A A A B - - - - - - - - - - - - - - - - - - - - B A C -   A A A B - - - - - - - - - - - - - - - - - - - - B A C -   A A A B - - - - - - - - - - - - - - - - - - - - B A A A   A A A B - - - - - - - - - - - - - - - - - - - - B A A A   A A A B - - - - - - - - - - - - - - - - - - - - B A A A   A A A B - - - - - - - - - - - - - - - - - - - - B A A A   A A A B - - - - - - - - - - - - - - - - - - - - B A A A   A A A B - - - - - - - - - - - - - - - - - - - - B C - -   A A A B - - - - - - - - - - - - - - - - - - - - B C - -   A A A B - - - - - - - - - - - - - - - - - - - - B C - -   A A A B - - - - - - - - - - - - - - - - - - - - B C - -   A A A B - - - - - - - - - - - - - - - - - - - - B C E -   A A A A AjY L AhAgAfF AwAaAeI AtB I AhJ M AdO K A C E -   A A A A A A A A A A A A A A A A A A A A A A A A A C E -   A A A A A A A A A A A A A A A A A A A A A A A A A C E -   A A A A A A A A A A A A A A A A A A A A A A A A A C E -   A A A A A A A A A A A A A A A A A A A A A A A A A C E -   A A A A A A A A A A A A A A A A A A A A A A A A A C - -   A A A A A A A A A A A A A A A A A A A A A A A A A C - -   A A A A A A A A A A A A A A A A A A A A A A A A A C - -   A A A A A A A A A A A A A A A A A A A A A A A A A A A A   D A A A A A A A A A A A A A A A A A A A A A A A A A A D   - - - - - - - - - - - - - - - - - - - - - - - - - - - -   - - - - - - - - - - - - - - - - - - - - - - - - - - - -   
D A A A - - - - - - - - - - - - - - - - - - - - A A A D   A A A B - - - - - - - - - - - - - - - - - - - - B A C -   A A A B - - - - - - - - - - - - - - - - - - - - B A C -   A A A B - - - - - - - - - - - - - - - - - - - - B A C -   A A A B - - - - - - - - - - - - - - - - - - - - B A C -   A A A B - - - - - - - - - - - - - - - - - - - - B A C -   A A A B - - - - - - - - - - - - - - - - - - - - B A C -   A A A B - - - - - - - - - - - - - - - - - - - - B A C -   A A A B - - - - - - - - - - - - - - - - - - - - B A A A   A A A B - - - - - - - - - - - - - - - - - - - - B A A A   A A A B - - - - - - - - - - - - - - - - - - - - B A A A   A A A B - - - - - - - - - - - - - - - - - - - - B A A A   A A A B - - - - - - - - - - - - - - - - - - - - B A A A   A A A B - - - - - - - - - - - - - - - - - - - - B C - -   A A A B - - - - - - - - - - - - - - - - - - - - B C - -   A A A B - - - - - - - - - - - - - - - - - - - - B C - -   A A A B - - - - - - - - - - - - - - - - - - - - B C - -   A A A B - - - - - - - - - - - - - - - - - - - - B C E -   A A A A AhAdApB AmW AoY AgM U U N P X G F X Z S A C E -   A A A A A A A A A A A A A A A A A A A A A A A A A C E -   A A A A A A A A A A A A A A A A A A A A A A A A A C E -   A A A A A A A A A A A A A A A A A A A A A A A A A C E -   A A A A A A A A A A A A A A A A A A A A A A A A A C E -   A A A A A A A A A A A A A A A A A A A A A A A A A C - -   A A A A A A A A A A A A A A A A A A A A A A A A A C - -   A A A A A A A A A A A A A A A A A A A A A A A A A C - -   A A A A A A A A A A A A A A A A A A A A A A A A A A A A   D A A A A A A A A A A A A A A A A A A A A A A A A A A D   - - - - - - - - - - - - - - - - - - - - - - - - - - - -   - - - - - - - - - - - - - - - - - - - - - - - - - - - -   
D A A A - - - - - - - - - - - - - - - - - - - - A A A D   A A A B - - - - - - - - - - - - - - - - - - - - B A A A   A A A B - - - - - - - - - - - - - - - - - - - - B A A A   A A A B - - - - - - - - - - - - - - - - - - - - B A A A   A A A B - - - - - - - - - - - - - - - - - - - - B A A A   A A A B - - - - - - - - - - - - - - - - - - - - B A A A   A A A B - - - - - - - - - - - - - - - - - - - - B A A A   A A A B - - - - - - - - - - - - - - - - - - - - B A C -   A A A B - - - - - - - - - - - - - - - - - - - - B A A A   A A A B - - - - - - - - - - - - - - - - - - - - B A A A   A A A B - - - - - - - - - - - - - - - - - - - - B A A A   A A A B - - - - - - - - - - - - - - - - - - - - B A A A   A A A B - - - - - - - - - - - - - - - - - - - - B A A A   A A A B - - - - - - - - - - - - - - - - - - - - B C - -   A A A B - - - - - - - - - - - - - - - - - - - - B C - -   A A A B - - - - - - - - - - - - - - - - - - - - B C - -   A A A B - - - - - - - - - - - - - - - - - - - - B C - -   A A A B - - - - - - - - - - - - - - - - - - - - B C - -   A A A A B AfJ AkV AtAfAdAmF AyR K W I Q L H H B A C E -   A A A A A A A A A A A A A A A A A A A A A A A A A C E -   A A A A A A A A A A A A A A A A A A A A A A A A A C E -   A A A A A A A A A A A A A A A A A A A A A A A A A C E -   A A A A A A A A A A A A A A A A A A A A A A A A A C - -   A A A A A A A A A A A A A A A A A A A A A A A A A C - -   A A A A A A A A A A A A A A A A A A A A A A A A A C - -   A A A A A A A A A A A A A A A A A A A A A A A A A C - -   A A A A A A A A A A A A A A A A A A A A A A A A A A A A   D A A A A A A A A A A A A A A A A A A A A A A A A A A D   - - - - - - - - - - - - - D - - - - - - - - - - - - - -   - - - - - - - - - - - - - D - - - - - - - - - - - - - -   
D A A A - - - - - - - - - - - - - - - - - - - - A A A D   A A A B - - - - - - - - - - - - - - - - - - - - B A A A   A A A B - - - - - - - - - - - - - - - - - - - - B A A A   A A A B - - - - - - - - - - - - - - - - - - - - B A A A   A A A B - - - - - - - - - - - - - - - - - - - - B A A A   A A A B - - - - - - - - - - - - - - - - - - - - B A A A   A A A B - - - - - - - - - - - - - - - - - - - - B A A A   A A A B - - - - - - - - - - - - - - - - - - - - B A C -   A A A B - - - - - - - - - - - - - - - - - - - - B A A A   A A A B - - - - - - - - - - - - - - - - - - - - B A A A   A A A B - - - - - - - - - - - - - - - - - - - - B A A A   A A A B - - - - - - - - - - - - - - - - - - - - B A A A   A A A B - - - - - - - - - - - - - - - - - - - - B A A A   A A A B - - - - - - - - - - - - - - - - - - - - B C - -   A A A B - - - - - - - - - - - - - - - - - - - - B C - -   A A A B - - - - - - - - - - - - - - - - - - - - B C - -   A A A B - - - - - - - - - - - - - - - - - - - - B C - -   A A A B - - - - - - - - - - - - - - - - - - - - B C - -   A A A A AkAlAiAmJ P AnAfV L AjL Y AeI K ApG AhAdA C - -   A A A A A A A A A A A A A A A A A A A A A A A A A C E -   A A A A A A A A A A A A A A A A A A A A A A A A A C E -   A A A A A A A A A A A A A A A A A A A A A A A A A C - -   A A A A A A A A A A A A A A A A A A A A A A A A A C - -   A A A A A A A A A A A A A A A A A A A A A A A A A C - -   A A A A A A A A A A A A A A A A A A A A A A A A A C - -   A A A A A A A A A A A A A A A A A A A A A A A A A C - -   A A A A A A A A A A A A A A A A A A A A A A A A A A A A   D A A A A A A A A A A A A A A A A A A A A A A A A A A D   - - - - - - - - - - - - - - - - - - - - - - - - - - - -   - - - - - - - - - - - - - D - - - - - - - - - - - - - -   
D A A A - - - - - - - - - - - - - - - - - - - - A A A D   A A A B - - - - - - - - - - - - - - - - - - - - B A A A   A A A B - - - - - - - - - - - - - - - - - - - - B A A A   A A A B - - - - - - - - - - - - - - - - - - - - B A A A   A A A B - - - - - - - - - - - - - - - - - - - - B A A A   A A A B - - - - - - - - - - - - - - - - - - - - B A A A   A A A B - - - - - - - - - - - - - - - - - - - - B A A A   A A A B - - - - - - - - - - - - - - - - - - - - B A C -   A A A B - - - - - - - - - - - - - - - - - - - - B A A A   A A A B - - - - - - - - - - - - - - - - - - - - B A A A   A A A B - - - - - - - - - - - - - - - - - - - - B A A A   A A A B - - - - - - - - - - - - - - - - - - - - B A A A   A A A B - - - - - - - - - - - - - - - - - - - - B A A A   A A A B - - - - - - - - - - - - - - - - - - - - B C - -   A A A B - - - - - - - - - - - - - - - - - - - - B C - -   A A A B - - - - - - - - - - - - - - - - - - - - B C - -   A A A B - - - - - - - - - - - - - - - - - - - - B C - -   A A A B - - - - - - - - - - - - - - - - - - - - B C - -   A A A A AmAuAbK AfAwZ AlJ ApAlAbN M P S J H X X A C - -   A A A A A A A A A A A A A A A A A A A A A A A A A C - -   A A A A A A A A A A A A A A A A A A A A A A A A A C - -   A A A A A A A A A A A A A A A A A A A A A A A A A C - -   A A A A A A A A A A A A A A A A A A A A A A A A A C - -   A A A A A A A A A A A A A A A A A A A A A A A A A C - -   A A A A A A A A A A A A A A A A A A A A A A A A A C - -   A A A A A A A A A A A A A A A A A A A A A A A A A C - -   A A A A A A A A A A A A A A A A A A A A A A A A A A A A   D A A A A A A A A A A A A A A A A A A A A A A A A A A D   - - - - - - - - - - - - - - - - - - - - - - - - - - - -   - - - - - - - - - - - - - D - - - - - - - - - - - - - -   
D A A A - - - - - - - - - - - - - - - - - - - - A A A D   A A A B - - - - - - - - - - - - - - - - - - - - B A A A   A A A B - - - - - - - - - - - - - - - - - - - - B A A A   A A A B - - - - - - - - - - - - - - - - - - - - B A A A   A A A B - - - - - - - - - - - - - - - - - - - - B A A A   A A A B - - - - - - - - - - - - - - - - - - - - B A A A   A A A B - - - - - - - - - - - - - - - - - - - - B A A A   A A A B - - - - - - - - - - - - - - - - - - - - B A C -   A A A B - - - - - - - - - - - - - - - - - - - - B A A A   A A A B - - - - - - - - - - - - - - - - - - - - B A A A   A A A B - - - - - - - - - - - - - - - - - - - - B A A A   A A A B - - - - - - - - - - - - - - - - - - - - B A A A   A A A B - - - - - - - - - - - - - - - - - - - - B A A A   A A A B - - - - - - - - - - - - - - - - - - - - B C - -   A A A B - - - - - - - - - - - - - - - - - - - - B C - -   A A A B - - - - - - - - - - - - - - - - - - - - B C - -   A A A B - - - - - - - - - - - - - - - - - - - - B C - -   A A A B - - - - - - - - - - - - - - - - - - - - B C - -   A A A A K V K F Q AwO AuAfJ AnAxAaF W B AiArI H A C - -   A A A A A A A A A A A A A A A A A A A A A A A A A C - -   A A A A A A A A A A A A A A A A A A A A A A A A A C - -   A A A A A A A A A A A A A A A A A A A A A A A A A C - -   A A A A A A A A A A A A A A A A A A A A A A A A A C - -   A A A A A A A A A A A A A A A A A A A A A A A A A C - -   A A A A A A A A A A A A A A A A A A A A A A A A A C - -   A A A A A A A A A A A A A A A A A A A A A A A A A C - -   A A A A A A A A A A A A A A A A A A A A A A A A A A A A   D A A A A A A A A A A A A A A A A A A A A A A A A A A D   - - - - - - - - - - - - - - - - - - - - - - - - - - - -   - - - - - - - - - - - - - D - - - - - - - - - - - - - -   
D A A A - - - - - - - - - - - - - - - - - - - - A A A D   A A A B - - - - - - - - - - - - - - - - - - - - B A A A   A A A B - - - - - - - - - - - - - - - - - - - - B A A A   A A A B - - - - - - - - - - - - - - - - - - - - B A A A   A A A B - - - - - - - - - - - - - - - - - - - - B A A A   A A A B - - - - - - - - - - - - - - - - - - - - B A A A   A A A B - - - - - - - - - - - - - - - - - - - - B A A A   A A A B - - - - - - - - - - - - - - - - - - - - B A C -   A A A B - - - - - - - - - - - - - - - - - - - - B A A A   A A A B - - - - - - - - - - - - - - - - - - - - B A A A   A A A B - - - - - - - - - - - - - - - - - - - - B A A A   A A A B - - - - - - - - - - - - - - - - - - - - B A A A   A A A B - - - - - - - - - - - - - - - - - - - - B A A A   A A A B - - - - - - - - - - - - - - - - - - - - B C - -   A A A B - - - - - - - - - - - - - - - - - - - - B C - -   A A A B - - - - - - - - - - - - - - - - - - - - B C - -   A A A B - - - - - - - - - - - - - - - - - - - - B C - -   A A A B - - - - - - - - - - - - - - - - - - - - B C - -   A A A A F G AaP AmS V V Q AiX V AdL AeAdAbT I G A C - -   A A A A A A A A A A A A A A A A A A A A A A A A A C E -   A A A A A A A A A A A A A A A A A A A A A A A A A C E -   A A A A A A A A A A A A A A A A A A A A A A A A A C - -   A A A A A A A A A A A A A A A A A A A A A A A A A C - -   A A A A A A A A A A A A A A A A A A A A A A A A A C - -   A A A A A A A A A A A A A A A A A A A A A A A A A C - -   A A A A A A A A A A A A A A A A A A A A A A A A A C - -   A A A A A A A A A A A A A A A A A A A A A A A A A A A A   D A A A A A A A A A A A A A A A A A A A A A A A A A A D   - - - - - - - - - - - - - - - - - - - - - - - - - - - -   - - - - - - - - - - - - - D - - - - - - - - - - - - - -   
D A A A - - - - - - - - - - - - - - - - - - - - A A A D   A A A B - - - - - - - - - - - - - - - - - - - - B A A A   A A A B - - - - - - - - - - - - - - - - - - - - B A A A   A A A B - - - - - - - - - - - - - - - - - - - - B A A A   A A A B - - - - - - - - - - - - - - - - - - - - B A A A   A A A B - - - - - - - - - - - - - - - - - - - - B A A A   A A A B - - - - - - - - - - - - - - - - - - - - B A A A   A A A B - - - - - - - - - - - - - - - - - - - - B A C -   A A A B - - - - - - - - - - - - - - - - - - - - B A A A   A A A B - - - - - - - - - - - - - - - - - - - - B A A A   A A A B - - - - - - - - - - - - - - - - - - - - B A A A   A A A B - - - - - - - - - - - - - - - - - - - - B A A A   A A A B - - - - - - - - - - - - - - - - - - - - B A A A   A A A B - - - - - - - - - - - - - - - - - - - - B C - -   A A A B - - - - - - - - - - - - - - - - - - - - B C - -   A A A B - - - - - - - - - - - - - - - - - - - - B C - -   A A A B - - - - - - - - - - - - - - - - - - - - B C - -   A A A B - - - - - - - - - - - - - - - - - - - - B C - -   A A A A P I U F AvX AcG AmAbW AlP ApM X K AyP H A C E -   A A A A A A A A A A A A A A A A A A A A A A A A A C E -   A A A A A A A A A A A A A A A A A A A A A A A A A C E -   A A A A A A A A A A A A A A A A A A A A A A A A A C E -   A A A A A A A A A A A A A A A A A A A A A A A A A C - -   A A A A A A A A A A A A A A A A A A A A A A A A A C - -   A A A A A A A A A A A A A A A A A A A A A A A A A C - -   A A A A A A A A A A A A A A A A A A A A A A A A A C - -   A A A A A A A A A A A A A A A A A A A A A A A A A A A A   D A A A A A A A A A A A A A A A A A A A A A A A A A A D   - - - - - - - - - - - - - D - - - - - - - - - - - - - -   - - - - - - - - - - - - - D - - - - - - - - - - - - - -   
D A A A - - - - - - - - - - - - - - - - - - - - A A A D   A A A B - - - - - - - - - - - - - - - - - - - - B A C -   A A A B - - - - - - - - - - - - - - - - - - - - B A C -   A A A B - - - - - - - - - - - - - - - - - - - - B A C -   A A A B - - - - - - - - - - - - - - - - - - - - B A C -   A A A B - - - - - - - - - - - - - - - - - - - - B A C -   A A A B - - - - - - - - - - - - - - - - - - - - B A C -   A A A B - - - - - - - - - - - - - - - - - - - - B A C -   A A A B - - - - - - - - - - - - - - - - - - - - B A A A   A A A B - - - - - - - - - - - - - - - - - - - - B A A A   A A A B - - - - - - - - - - - - - - - - - - - - B A A A   A A A B - - - - - - - - - - - - - - - - - - - - B A A A   A A A B - - - - - - - - - - - - - - - - - - - - B A A A   A A A B - - - - - - - - - - - - - - - - - - - - B C - -   A A A B - - - - - - - - - - - - - - - - - - - - B C - -   A A A B - - - - - - - - - - - - - - - - - - - - B C - -   A A A B - - - - - - - - - - - - - - - - - - - - B C - -   A A A B - - - - - - - - - - - - - - - - - - - - B C E -   A A A A F N L AfAuAmG I AvK H AqZ J F H AaAnW ArA C E -   A A A A A A A A A A A A A A A A A A A A A A A A A C E -   A A A A A A A A A A A A A A A A A A A A A A A A A C E -   A A A A A A A A A A A A A A A A A A A A A A A A A C E -   A A A A A A A A A A A A A A A A A A A A A A A A A C E -   A A A A A A A A A A A A A A A A A A A A A A A A A C - -   A A A A A A A A A A A A A A A A A A A A A A A A A C - -   A A A A A A A A A A A A A A A A A A A A A A A A A C - -   A A A A A A A A A A A A A A A A A A A A A A A A A A A A   D A A A A A A A A A A A A A A A A A A A A A A A A A A D   - - - - - - - - - - - - - - - - - - - - - - - - - - - -   - - - - - - - - - - - - - - - - - - - - - - - - - - - -   
D A A A - - - - - - - - - - - - - - - - - - - - A A A D   A A A B - - - - - - - - - - - - - - - - - - - - B A C -   A A A B - - - - - - - - - - - - - - - - - - - - B A C -   A A A B - - - - - - - - - - - - - - - - - - - - B A C -   A A A B - - - - - - - - - - - - - - - - - - - - B A C -   A A A B - - - - - - - - - - - - - - - - - - - - B A C -   A A A B - - - - - - - - - - - - - - - - - - - - B A C -   A A A B - - - - - - - - - - - - - - - - - - - - B A C -   A A A B - - - - - - - - - - - - - - - - - - - - B A A A   A A A B - - - - - - - - - - - - - - - - - - - - B A A A   A A A B - - - - - - - - - - - - - - - - - - - - B A A A   A A A B - - - - - - - - - - - - - - - - - - - - B A A A   A A A B - - - - - - - - - - - - - - - - - - - - B A A A   A A A B - - - - - - - - - - - - - - - - - - - - B C - -   A A A B - - - - - - - - - - - - - - - - - - - - B C - -   A A A B - - - - - - - - - - - - - - - - - - - - B C - -   A A A B - - - - - - - - - - - - - - - - - - - - B C - -   A A A B - - - - - - - - - - - - - - - - - - - - B C E -   A A A A AfAcAjAeAlAcAzN AuAaM AsS AiL G U O AeT A C E -   A A A A A A A A A A A A A A A A A A A A A A A A A C E -   A A A A A A A A A A A A A A A A A A A A A A A A A C E -   A A A A A A A A A A A A A A A A A A A A A A A A A C E -   A A A A A A A A A A A A A A A A A A A A A A A A A C E -   A A A A A A A A A A A A A A A A A A A A A A A A A C - -   A A A A A A A A A A A A A A A A A A A A A A A A A C - -   A A A A A A A A A A A A A A A A A A A A A A A A A C - -   A A A A A A A A A A A A A A A A A A A A A A A A A A A A   D A A A A A A A A A A A A A A A A A A A A A A A A A A D   - - - - - - - - - - - - - - - - - - - - - - - - - - - -   - - - - - - - - - - - - - - - - - - - - - - - - - - - -   
D A A A - - - - - - - - - - - - - - - - - - - - A A A D   A A A B - - - - - - - - - - - - - - - - - - - - B A A A   A A A B - - - - - - - - - - - - - - - - - - - - B A A A   A A A B - - - - - - - - - - - - - - - - - - - - B A A A   A A A B - - - - - - - - - - - - - - - - - - - - B A A A   A A A B - - - - - - - - - - - - - - - - - - - - B A A A   A A A B - - - - - - - - - - - - - - - - - - - - B A A A   A A A B - - - - - - - - - - - - - - - - - - - - B A C -   A A A B - - - - - - - - - - - - - - - - - - - - B A A A   A A A B - - - - - - - - - - - - - - - - - - - - B A A A   A A A B - - - - - - - - - - - - - - - - - - - - B A A A   A A A B - - - - - - - - - - - - - - - - - - - - B A A A   A A A B - - - - - - - - - - - - - - - - - - - - B A A A   A A A B - - - - - - - - - - - - - - - - - - - - B C - -   A A A B - - - - - - - - - - - - - - - - - - - - B C - -   A A A B - - - - - - - - - - - - - - - - - - - - B C - -   A A A B - - - - - - - - - - - - - - - - - - - - B C - -   A A A B - - - - - - - - - - - - - - - - - - - - B C - -   A A A A AeAoAqAiAtAxAsAcAlU U AdAkAbApH L T M AyA C E -   A A A A A A A A A A A A A A A A A A A A A A A A A C E -   A A A A A A A A A A A A A A A A A A A A A A A A A C E -   A A A A A A A A A A A A A A A A A A A A A A A A A C E -   A A A A A A A A A A A A A A A A A A A A A A A A A C - -   A A A A A A A A A A A A A A A A A A A A A A A A A C - -   A A A A A A A A A A A A A A A A A A A A A A A A A C - -   A A A A A A A A A A A A A A A A A A A A A A A A A C - -   A A A A A A A A A A A A A A A A A A A A A A A A A A A A   D A A A A A A A A A A A A A A A A A A A A A A A A A A D   - - - - - - - - - - - - - - - - - - - - - - - - - - - -   - - - - - - - - - - - - - - - - - - - - - - - - - - - -   
D A A A - - - - - - - - - - - - - - - - - - - - A A A D   A A A B - - - - - - - - - - - - - - - - - - - - B A A A   A A A B - - - - - - - - - - - - - - - - - - - - B A A A   A A A B - - - - - - - - - - - - - - - - - - - - B A A A   A A A B - - - - - - - - - - - - - - - - - - - - B A A A   A A A B - - - - - - - - - - - - - - - - - - - - B A A A   A A A B - - - - - - - - - - - - - - - - - - - - B A A A   A A A B - - - - - - - - - - - - - - - - - - - - B A C -   A A A B - - - - - - - - - - - - - - - - - - - - B A A A   A A A B - - - - - - - - - - - - - - - - - - - - B A A A   A A A B - - - - - - - - - - - - - - - - - - - - B A A A   A A A B - - - - - - - - - - - - - - - - - - - - B A A A   A A A B - - - - - - - - - - - - - - - - - - - - B A A A   A A A B - - - - - - - - - - - - - - - - - - - - B C - -   A A A B - - - - - - - - - - - - - - - - - - - - B C - -   A A A B - - - - - - - - - - - - - - - - - - - - B C - -   A A A B - - - - - - - - - - - - - - - - - - - - B C - -   A A A B - - - - - - - - - - - - - - - - - - - - B C - -   A A A A AiJ Y N AcArG AoAtL AgB L K J ArAjF F AnA C - -   A A A A A A A A A A A A A A A A A A A A A A A A A C E -   A A A A A A A A A A A A A A A A A A A A A A A A A C E -   A A A A A A A A A A A A A A A A A A A A A A A A A C - -   A A A A A A A A A A A A A A A A A A A A A A A A A C - -   A A A A A A A A A A A A A A A A A A A A A A A A A C - -   A A A A A A A A A A A A A A A A A A A A A A A A A C - -   A A A A A A A A A A A A A A A A A A A A A A A A A C - -   A A A A A A A A A A A A A A A A A A A A A A A A A A A A   D A A A A A A A A A A A A A A A A A A A A A A A A A A D   - - - - - - - - - - - - - - - - - - - - - - - - - - - -   - - - - - - - - - - - - - - - - - - - - - - - - - - - -   
D A A A - - - - - - - - - - - - - - - - - - - - A A A D   A A A B - - - - - - - - - - - - - - - - - - - - B A A A   A A A B - - - - - - - - - - - - - - - - - - - - B A A A   A A A B - - - - - - - - - - - - - - - - - - - - B A A A   A A A B - - - - - - - - - - - - - - - - - - - - B A A A   A A A B - - - - - - - - - - - - - - - - - - - - B A A A   A A A B - - - - - - - - - - - - - - - - - - - - B A A A   A A A B - - - - - - - - - - - - - - - - - - - - B A C -   A A A B - - - - - - - - - - - - - - - - - - - - B A A A   A A A B - - - - - - - - - - - - - - - - - - - - B A A A   A A A B - - - - - - - - - - - - - - - - - - - - B A A A   A A A B - - - - - - - - - - - - - - - - - - - - B A A A   A A A B - - - - - - - - - - - - - - - - - - - - B A A A   A A A B - - - - - - - - - - - - - - - - - - - - B C - -   A A A B - - - - - - - - - - - - - - - - - - - - B C - -   A A A B - - - - - - - - - - - - - - - - - - - - B C - -   A A A B - - - - - - - - - - - - - - - - - - - - B C - -   A A A B - - - - - - - - - - - - - - - - - - - - B C - -   A A A A N G AxM R T ArJ AcAjAjN V AaAiT AqO L O A C - -   A A A A A A A A A A A A A A A A A A A A A A A A A C - -   A A A A A A A A A A A A A A A A A A A A A A A A A C - -   A A A A A A A A A A A A A A A A A A A A A A A A A C - -   A A A A A A A A A A A A A A A A A A A A A A A A A C - -   A A A A A A A A A A A A A A A A A A A A A A A A A C - -   A A A A A A A A A A A A A A A A A A A A A A A A A C - -   A A A A A A A A A A A A A A A A A A A A A A A A A C - -   A A A A A A A A A A A A A A A A A A A A A A A A A A A A   D A A A A A A A A A A A A A A A A A A A A A A A A A A D   - - - - - - - - - - - - - - - - - - - - - - - - - - - -   - - - - - - - - - - - - - - - - - - - - - - - - - - - -   
D A A A - - - - - - - - - - - - - - - - - - - - A A A D   A A A B - - - - - - - - - - - - - - - - - - - - B A A A   A A A B - - - - - - - - - - - - - - - - - - - - B A A A   A A A B - - - - - - - - - - - - - - - - - - - - B A A A   A A A B - - - - - - - - - - - - - - - - - - - - B A A A   A A A B - - - - - - - - - - - - - - - - - - - - B A A A   A A A B - - - - - - - - - - - - - - - - - - - - B A A A   A A A B - - - - - - - - - - - - - - - - - - - - B A C -   A A A B - - - - - - - - - - - - - - - - - - - - B A A A   A A A B - - - - - - - - - - - - - - - - - - - - B A A A   A A A B - - - - - - - - - - - - - - - - - - - - B A A A   A A A B - - - - - - - - - - - - - - - - - - - - B A A A   A A A B - - - - - - - - - - - - - - - - - - - - B A A A   A A A B - - - - - - - - - - - - - - - - - - - - B C - -   A A A B - - - - - - - - - - - - - - - - - - - - B C - -   A A A B - - - - - - - - - - - - - - - - - - - - B C - -   A A A B - - - - - - - - - - - - - - - - - - - - B C - -   A A A B - - - - - - - - - - - - - - - - - - - - B C - -   A A A A M Q H R Z R AbG R AqAhK F U AbAyY AaApT A C - -   A A A A A A A A A A A A A A A A A A A A A A A A A C - -   A A A A A A A A A A A A A A A A A A A A A A A A A C - -   A A A A A A A A A A A A A A A A A A A A A A A A A C - -   A A A A A A A A A A A A A A A A A A A A A A A A A C - -   A A A A A A A A A A A A A A A A A A A A A A A A A C - -   A A A A A A A A A A A A A A A A A A A A A A A A A C - -   A A A A A A A A A A A A A A A A A A A A A A A A A C - -   A A A A A A A A A A A A A A A A A A A A A A A A A A A A   D A A A A A A A A A A A A A A A A A A A A A A A A A A D   - - - - - - - - - - - - - - - - - - - - - - - - - - - -   - - - - - - - - - - - - - - - - - - - - - - - - - - - -   
D A A A - - - - - - - - - - - - - - - - - - - - A A A D   A A A B - - - - - - - - - - - - - - - - - - - - B A C -   A A A B - - - - - - - - - - - - - - - - - - - - B A C -   A A A B - - - - - - - - - - - - - - - - - - - - B A C -   A A A B - - - - - - - - - - - - - - - - - - - - B A C -   A A A B - - - - - - - - - - - - - - - - - - - - B A C -   A A A B - - - - - - - - - - - - - - - - - - - - B A C -   A A A B - - - - - - - - - - - - - - - - - - - - B A C -   A A A B - - - - - - - - - - - - - - - - - - - - B A A A   A A A B - - - - - - - - - - - - - - - - - - - - B A A A   A A A B - - - - - - - - - - - - - - - - - - - - B A A A   A A A B - - - - - - - - - - - - - - - - - - - - B A A A   A A A B - - - - - - - - - - - - - - - - - - - - B A A A   A A A B - - - - - - - - - - - - - - - - - - - - B C - -   A A A B - - - - - - - - - - - - - - - - - - - - B C - -   A A A B - - - - - - - - - - - - - - - - - - - - B C - -   A A A B - - - - - - - - - - - - - - - - - - - - B C - -   A A A B - - - - - - - - - - - - - - - - - - - - B C - -   A A A A R K Q Y AsS R Q Z Y B Y AoL K AnAxAgJ F A C - -   A A A A A A A A A A A A A A A A A A A A A A A A A C - -   A A A A A A A A A A A A A A A A A A A A A A A A A C - -   A A A A A A A A A A A A A A A A A A A A A A A A A C - -   A A A A A A A A A A A A A A A A A A A A A A A A A C - -   A A A A A A A A A A A A A A A A A A A A A A A A A C - -   A A A A A A A A A A A A A A A A A A A A A A A A A C - -   A A A A A A A A A A A A A A A A A A A A A A A A A C - -   A A A A A A A A A A A A A A A A A A A A A A A A A A A A   D A A A A A A A A A A A A A A A A A A A A A A A A A A D   - - - - - - - - - - - - - - - - - - - - - - - - - - - -   - - - - - - - - - - - - - - - - - - - - - - - - - - - -   
D A A A A A A A A A A A A A A A A A A A A A A A A A A D   A A A A B B B B B B B B B B B B B B B B B B B B A A A A   A A A A B B B B B B B B B B B B B B B B B B B B A A A A   A A A A B B B B B B B B B B B B B B B B B B B B A A A A   A A A A B B B B B B B B B B B B B B B B B B B B A A A A   A A A A B B B B B B B B B B B B B B B B B B B B A A A A   A A A A B B B B B B B B B B B B B B B B B B B B A A A A   A A A A B B B B B B B B B B B B B B B B B B B B A A A A   A A A A B B B B B B B B B B B B B B B B B B B B A A A A   A A A A B B B B B B B B B B B B B B B B B B B B A A A A   A A A A B B B B B B B B B B B B B B B B B B B B A A A A   A A A A B B B B B B B B B B B B B B B B B B B B A A A A   A A A A B B B B B B B B B B B B B B B B B B B B A A A A   A A A A B B B B B B B B B B B B B B B B B B B B A A A A   A A A A B B B B B B B B B B B B B B B B B B B B A C - -   A A A A B B B B B B B B B B B B B B B B B B B B A C - -   A A A A B B B B B B B B B B B B B B B B B B B B A C - -   A A A A B B B B B B B B B B B B B B B B B B B B A C - -   A A A A A A A A A A A A A A A A A A A A A A A A A C - -   A A A A A A A A A A A A A A A A A A A A A A A A A C - -   A A A A A A A A A A A A A A A A A A A A A A A A A C - -   A A A A A A A A A A A A A A A A A A A A A A A A A C - -   A A A A A A A A A A A A A A A A A A A A A A A A A C - -   A A A A A A A A A A A A A A A A A A A A A A A A A C - -   A A A A A A A A A A A A A A A A A A A A A A A A A C - -   A A A A A A A A A A A A A A A A A A A A A A A A A A A A   A A A A A A A A A A A A A A A A A A A A A A A A A A A A   D A A A A A A A A A A A A A A A A A A A A A A A A A A D   - - - - - - - - - - - - - - - - - - - - - - - - - - - -   - - - - - - - - - - - - - - - - - - - - - - - - - - - -   
D A A A A A A A A A A A A A A A A A A A A A A A A A A D   A A A A A A A A A A A A A A A A A A A A A A A A A A A A   A A A A A A A A A A A A A A A A A A A A A A A A A A A A   A A A A A A A A A A A A A A A A A A A A A A A A A A A A   A A A A A A A A A A A A A A A A A A A A A A A A A A A A   A A A A A A A A A A A A A A A A A A A A A A A A A A A A   A A A A A A A A A A A A A A A A A A A A A A A A A A A A   A A A A A A A A A A A A A A A A A A A A A A A A A A A A   A A A A A A A A A A A A A A A A A A A A A A A A A A A A   A A A A A A A A A A A A A A A A A A A A A A A A A A A A   A A A A A A A A A A A A A A A A A A A A A A A A A A A A   A A A A A A A A A A A A A A A A A A A A A A A A A A A A   A A A A A A A A A A A A A A A A A A A A A A A A A A A A   A A A A A A A A A A A A A A A A A A A A A A A A A A A A   A A A A A A A A A A A A A A A A A A A A A A A A A A A A   A A A A A A A A A A A A A A A A A A A A A A A A A C - -   A A A A A A A A A A A A A A A A A A A A A A A A A C - -   A A A A A A A A A A A A A A A A A A A A A A A A A C - -   A A A A A A A A A A A A A A A A A A A A A A A A A C - -   A A A A A A A A A A A A A A A A A A A A A A A A A C - -   A A A A A A A A A A A A A A A A A A A A A A A A A C - -   A A A A A A A A A A A A A A A A A A A A A A A A A C - -   A A A A A A A A A A A A A A A A A A A A A A A A A C - -   A A A A A A A A A A A A A A A A A A A A A A A A A C - -   A A A A A A A A A A A A A A A A A A A A A A A A A A A A   A A A A A A A A A A A A A A A A A A A A A A A A A A A A   A A A A A A A A A A A A A A A A A A A A A A A A A A A A   D A A A A A A A A A A A A A A A A A A A A A A A A A A D   - - - - - - - - - - - - - - - - - - - - - - - - - - - -   - - - - - - - - - - - - - - - - - - - - - - - - - - - -   
D A A A A A A A A A A A A A A A A A A A A A A A A A A D   A A A A A A A A A A A A A A A A A A A A A A A A A A A A   A A A A A A A A A A A A A A A A A A A A A A A A A A A A   A A A A A A A A A A A A A A A A A A A A A A A A A A A A   A A A A A A A A A A A A A A A A A A A A A A A A A A A A   A A A A A A A A A A A A A A A A A A A A A A A A A A A A   A A A A A A A A A A A A A A A A A A A A A A A A A A A A   A A A A A A A A A A A A A A A A A A A A A A A A A A A A   A A A A A A A A A A A A A A A A A A A A A A A A A A A A   A A A A A A A A A A A A A A A A A A A A A A A A A A A A   A A A A A A A A A A A A A A A A A A A A A A A A A A A A   A A A A A A A A A A A A A A A A A A A A A A A A A A A A   A A A A A A A A A A A A A A A A A A A A A A A A A A A A   A A A A A A A A A A A A A A A A A A A A A A A A A A A A   A A A A A A A A A A A A A A A A A A A A A A A A A A A A   A A A A A A A A A A A A A A A A A A A A A A A A A A A A   A A A A A A A A A A A A A A A A A A A A A A A A A A A A   A A A A A A A A A A A A A A A A A A A A A A A A A A A A   A A A A A A A A A A A A A A A A A A A A A A A A A A A A   A A A A A A A A A A A A A A A A A A A A A A A A A A A A   A A A A A A A A A A A A A A A A A A A A A A A A A A A A   A A A A A A A A A A A A A A A A A A A A A A A A A A A A   A A A A A A A A A A A A A A A A A A A A A A A A A A A A   A A A A A A A A A A A A A A A A A A A A A A A A A A A A   A A A A A A A A A A A A A A A A A A A A A A A A A A A A   A A A A A A A A A A A A A A A A A A A A A A A A A A A A   A A A A A A A A A A A A A A A A A A A A A A A A A A A A   D A A A A A A A A A A A A A A A A A A A A A A A A A A D   - - - - - - - - - - - - - - - - - - - - - - - - - - - -   - - - - - - - - - - - - - - - - - - - - - - - - - - - -   
D D D D D D D D D D D D D D D D D D D D D D D D D D D D   D A A A A A A A A A A A A A A A A A A A A A A A A A A D   D A A A A A A A A A A A A A A A A A A A A A A A A A A D   D A A A A A A A A A A A A A A A A A A A A A A A A A A D   D A A A A A A A A A A A A A A A A A A A A A A A A A A D   D A A A A A A A A A A A A A A A A A A A A A A A A A A D   D A A A A A A A A A A A A A A A A A A A A A A A A A A D   D A A A A A A A A A A A A A A A A A A A A A A A A A A D   D A A A A A A A A A A A A A A A A A A A A A A A A A A D   D A A A A A A A A A A A A A A A A A A A A A A A A A A D   D A A A A A A A A A A A A A A A A A A A A A A A A A A D   D A A A A A A A A A A A A A A A A A A A A A A A A A A D   D A A A A A A A A A A A A A A A A A A A A A A A A A A D   D A A A A A A A A A A A A A A A A A A A A A A A A A A D   D A A A A A A A A A A A A A A A A A A A A A A A A A A D   D A A A A A A A A A A A A A A A A A A A A A A A A A A D   D A A A A A A A A A A A A A A A A A A A A A A A A A A D   D A A A A A A A A A A A A A A A A A A A A A A A A A A D   D A A A A A A A A A A A A A A A A A A A A A A A A A A D   D A A A A A A A A A A A A A A A A A A A A A A A A A A D   D A A A A A A A A A A A A A A A A A A A A A A A A A A D   D A A A A A A A A A A A A A A A A A A A A A A A A A A D   D A A A A A A A A A A A A A A A A A A A A A A A A A A D   D A A A A A A A A A A A A A A A A A A A A A A A A A A D   D A A A A A A A A A A A A A A A A A A A A A A A A A A D   D A A A A A A A A A A A A A A A A A A A A A A A A A A D   D A A A A A A A A A A A A A A A A A A A A A A A A A A D   D D D D D D D D D D D D D D D D D D D D D D D D D D D D   - - - - - - - - - - - - - - - - - - - - - - - - - - - -   - - - - - - - - - - - - - - - - - - - - - - - - - - - -   
