model
size = 27 28 23, scale = 0.05, origin = -y
material 
  colors = A:#09C B:#06C C:#005 D:#009 E:#002 F:#35008B G:#000
voxels
--------------------------- --------------------------- --------------------------- --------------------------- --------------------------- --------------------------- --------------------------- --------------------------- --------------------------- --------------------------- --------------------------- --------------------------- -------------------------CC -------------------------CC --------------------------- -------------------------CC -------------------------CC --------------------------- --------------------------- --------------------------- --------------------------- --------------------------- --------------------------- --------------------------- --------------------------- --------------------------- --------------------------- --------------------------- 
--------------------------- --------------------------- --------------------------- --------------------------- --------------------------- --------------------------- --------------------------- --------------------------- --------------------------- --------------------------- -------------------------AA ------------------------BAA ------------------------BAA ------------------------BAA ------------------------BAA ------------------------BAA ------------------------BAA ------------------------BAA -------------------------AA --------------------------- --------------------------- --------------------------- --------------------------- --------------------------- --------------------------- --------------------------- --------------------------- --------------------------- 
--------------------------- --------------------------- --------------------------- --------------------------- --------------------------- --------------------------- --------------------------- --------------------------- --------------------------- ------------------------BAA ------------------------BA- ------------------------BA- ------------------------BA- ------------------------BA- ------------------------BA- ------------------------BA- ------------------------BA- ------------------------BA- ------------------------BA- ------------------------BAA --------------------------- --------------------------- --------------------------- --------------------------- --------------------------- --------------------------- --------------------------- --------------------------- 
--------------------------- --------------------------- --------------------------- --------------------------- --------------------------- --------------------------- --------------------------- --------------------------- ------------------------BAA ------------------------BBA ------------------------BB- ------------------------BB- -----------------------AAA- -----------------------AAA- -----------------------AAA- -----------------------AAA- -----------------------AAB- ------------------------BB- ------------------------BB- ------------------------BAA ------------------------BAA --------------------------- --------------------------- --------------------------- --------------------------- --------------------------- --------------------------- --------------------------- 
--------------------------- --------------------------- --------------------------- --------------------------- --------------------------- --------------------------- --------------------------- ------------------------BAA ------------------------BBA ------------------------BB- -----------------------ABB- -----------------------ABB- -----------------------ABB- -----------------------ABA- -----------------------ABA- -----------------------ABB- -----------------------ABB- -----------------------ABB- -----------------------ABB- ------------------------BB- ------------------------BAA ------------------------BAA --------------------------- --------------------------- --------------------------- --------------------------- --------------------------- --------------------------- 
---------AAAAAAAA---------- -------AA--------AAA------- -----AA-------------AA----- ----A-----------------A---- ---A-------------------AA-- --A---------------------AA- -A----------------------BAA -A----------------------BAA AA----------------------BB- AA---------------------ABB- AA---------------------ABG- AA---------------------ABB- AA---------------------BBB- AA---------------------BBA- AA---------------------BBB- AA---------------------BBB- AA---------------------BBE- AA---------------------ABB- AA---------------------ABB- AA---------------------ABB- -A----------------------BB- -A----------------------BAA --A---------------------BAA ---A-------------------ABA- ----A-----------------A---- -----AA-------------AA----- -------AA--------AAA------- ---------AAAAAAAA---------- 
---------BBBBBBBB---------- -------BB--------BBB------- -----BB-------------BB----- ----B-----------------B---- ---B-------------------BB-- --B---------------------BBA -B----------------------BBA -B----------------------BA- BB---------------------ABB- BB---------------------ABB- BB---------------------ABB- BA---------------------BBE- BA---------------------BBB- B-----------------------DA- BA---------------------BBB- B-----------------------DB- BA---------------------BBB- BB---------------------BBG- BB---------------------ABE- BB---------------------ABE- -B---------------------ABB- -B----------------------BA- --B---------------------BAA ---B-------------------AAAA ----B-----------------B---- -----BB-------------BB----- -------BB--------BBB------- ---------BBBBBBBB---------- 
---------AAAAAAAA---------- -------AB--------BAA------- -----AB-------------AB----- ----B-----------------A---- ---A-------------------BA-- --B---------------------BBA -A----------------------BAA -B----------------------BA- BA---------------------ABA- AA---------------------ABB- AA---------------------BBB- AB---------------------BBB- AA---------------------BBA- BA---------------------BBA- BA---------------------BBB- AA---------------------BBB- AA---------------------BBB- AB---------------------BBB- AA---------------------BBB- BA---------------------ABB- -B---------------------ABB- -A----------------------BA- --B---------------------BAA ---A-------------------ABAA ----B-----------------A---- -----AB-------------AB----- -------AB--------ABA------- ---------ABAAAABA---------- 
---------AAAAAAAA---------- -------AB--------BAA------- -----AB-------------AB----- ----B-----------------A---- ---A-------------------BA-- --B---------------------BBA -A----------------------BBA -B---------------------ABA- BA---------------------ABA- AA---------------------BBA- AA---------------------BBA- AA---------------------BBA- AB---------------------BBA- BA---------------------BBA- BA---------------------BBA- AA---------------------BBB- AB---------------------BBB- AA---------------------BBB- AA---------------------BBB- BA---------------------BBB- -B---------------------ABA- -A---------------------ABA- --B---------------------BAA ---A-------------------ABAA ----B-----------------A---- -----AB-------------AB----- -------AB--------ABA------- ---------ABAAAABA---------- 
---------BBBBBBBB---------- -------BB--------BBB------- -----BB-------------BB----- ----B-----------------B---- ---B-------------------BB-- --B---------------------BBA -B----------------------BAA -B---------------------ABA- BB---------------------ABA- BB---------------------BBA- BB---------------------BBA- BB----------------------DA- BA---------------------BBA- BB----------------------DA- BA---------------------BBA- BB----------------------DA- BA---------------------BBB- BB----------------------DB- BB---------------------BBB- BB---------------------BBA- -B---------------------ABA- -B---------------------AFA- --B---------------------BAA ---B-------------------AAAA ----B-----------------B---- -----BB-------------BB----- -------BB--------BBB------- ---------BBBBBBBB---------- 
---------AAAAAAAA---------- -------AA--------AAA------- -----AA-------------AA----- ----A-----------------A---- ---A-------------------AA-- --A---------------------AAA -A----------------------BBA -A---------------------AAA- AA---------------------AAA- AA---------------------BAB- AA---------------------BAB- AA---------------------BAB- AA---------------------BAA- AA---------------------BAA- AB---------------------BFA- AA---------------------BAA- AA---------------------BAA- AA---------------------BAA- AA---------------------BAA- AA---------------------BAA- -A---------------------AFC- -A---------------------AFA- --A---------------------BAA ---A-------------------ABAA ----A-----------------A---- -----AA-------------AA----- -------AA--------AAA------- ---------AAAAAAAA---------- 
---------AAAAAAAA---------- -------AA--------AAA------- -----AA-------------AA----- ----A-----------------A---- ---A-------------------AA-- --A---------------------AAA -A----------------------BAA -A---------------------A-A- AA---------------------A-A- AA---------------------BBB- AA---------------------BBC- AA---------------------BBB- AA---------------------BBA- AA---------------------BBA- AB---------------------BBA- AA---------------------BAA- AA---------------------BBA- AA---------------------BBA- AA---------------------BBA- AA---------------------BBC- -A---------------------AAC- -A---------------------AAA- --A---------------------B-A ---A-------------------ABAA ----A-----------------A---- -----AA-------------AA----- -------AA--------AAA------- ---------AAAAAAAA---------- 
---------BBBBBBBB---------- -------BB--------BBB------- -----BB-------------BB----- ----B-----------------B---- ---B-------------------BB-- --B---------------------BBA -B----------------------BAA -B---------------------ABA- BB---------------------ABA- BB---------------------BBB- BB---------------------BBB- BB---------------------BBB- BA---------------------BBA- BB---------------------BBA- BA---------------------BBA- BB---------------------BBA- BA---------------------BBA- BB---------------------BBA- BB---------------------BBA- BB---------------------BBA- -B---------------------AFC- -B---------------------ABA- --B---------------------BAA ---B-------------------AAAA ----B-----------------B---- -----BB-------------BB----- -------BB--------BBB------- ---------BBBBBBBB---------- 
---------AAAAAAAA---------- -------AB--------BAA------- -----AB-------------AB----- ----B-----------------A---- ---A-------------------BA-- --B---------------------BBA -A----------------------BAA -B---------------------ABA- BA---------------------ABA- AA---------------------BBA- AA---------------------BBA- AA----------------------DA- AB---------------------BBA- BA----------------------DA- BA---------------------BBA- AA----------------------DA- AB---------------------BBB- AA----------------------DB- AA---------------------BBB- BA---------------------BBA- -B---------------------ABA- -A---------------------AFA- --B---------------------BAA ---A-------------------ABAA ----B-----------------A---- -----AB-------------AB----- -------AB--------ABA------- ---------ABAAAABA---------- 
---------AAAAAAAA---------- -------AB--------BAA------- -----AB-------------AB----- ----B-----------------A---- ---A-------------------BA-- --B---------------------BBA -A----------------------BBA -B---------------------ABA- BA---------------------ABA- AA---------------------BBA- AA---------------------BBA- AB---------------------BBA- AA---------------------BBA- BA---------------------BBA- BA---------------------BBA- AA---------------------BBB- AA---------------------BBB- AB---------------------BBB- AA---------------------BBB- BA---------------------BBB- -B---------------------ABA- -A---------------------ABA- --B---------------------BAA ---A-------------------ABAA ----B-----------------A---- -----AB-------------AB----- -------AB--------ABA------- ---------ABAAAABA---------- 
---------BBBBBBBB---------- -------BB--------BBB------- -----BB-------------BB----- ----B-----------------B---- ---B-------------------BB-- --B---------------------BBA -B----------------------BAA -B----------------------BA- BB---------------------ABA- BB---------------------A-B- BB---------------------BBB- BA---------------------BBB- BA---------------------BBA- B----------------------BBA- BA---------------------BBB- B----------------------BBB- BA---------------------BBB- BB---------------------BBB- BB---------------------BBE- BB---------------------ABB- -B---------------------ABB- -B----------------------BA- --B---------------------BAA ---B-------------------AAAA ----B-----------------B---- -----BB-------------BB----- -------BB--------BBB------- ---------BBBBBBBB---------- 
---------AAAAAAAA---------- -------AA--------AAA------- -----AA-------------AA----- ----A-----------------A---- ---A-------------------AA-- --A---------------------AAA -A----------------------BBA -A----------------------BA- AA---------------------ABB- AA---------------------A-E- AA---------------------ABB- AA---------------------BBB- AA---------------------BBB- AA----------------------DA- AA---------------------BBB- AA----------------------DB- AA---------------------BBB- AA---------------------BBG- AA---------------------ABB- AA---------------------ABB- -A---------------------ABB- -A----------------------BA- --A---------------------BAA ---A-------------------ABAA ----A-----------------A---- -----AA-------------AA----- -------AA--------AAA------- ---------AAAAAAAA---------- 
--------------------------- --------------------------- --------------------------- --------------------------- --------------------------- --------------------------- ------------------------BAA ------------------------BAA ------------------------BB- -----------------------ABB- -----------------------ABG- -----------------------ABB- -----------------------BBB- -----------------------BBA- -----------------------BBB- -----------------------BBB- -----------------------BBB- -----------------------ABE- -----------------------ABB- -----------------------ABB- ------------------------BB- ------------------------BA- ------------------------BAA --------------------------- --------------------------- --------------------------- --------------------------- --------------------------- 
--------------------------- --------------------------- --------------------------- --------------------------- --------------------------- --------------------------- --------------------------- ------------------------BAA ------------------------BB- ------------------------BB- -----------------------ABB- -----------------------ABB- -----------------------ABB- -----------------------ABA- -----------------------ABA- -----------------------ABB- -----------------------ABB- -----------------------ABE- -----------------------ABB- ------------------------BB- ------------------------BA- ------------------------BAA --------------------------- --------------------------- --------------------------- --------------------------- --------------------------- --------------------------- 
--------------------------- --------------------------- --------------------------- --------------------------- --------------------------- --------------------------- --------------------------- --------------------------- ------------------------BAA ------------------------BB- ------------------------BB- ------------------------BB- -----------------------AAA- -----------------------AAA- -----------------------AAA- -----------------------AAA- -----------------------AAB- ------------------------BB- ------------------------BB- ------------------------BA- ------------------------BAA --------------------------- --------------------------- --------------------------- --------------------------- --------------------------- --------------------------- --------------------------- 
--------------------------- --------------------------- --------------------------- --------------------------- --------------------------- --------------------------- --------------------------- --------------------------- --------------------------- ------------------------BAA ------------------------BAA ------------------------BA- ------------------------BA- ------------------------BA- ------------------------BA- ------------------------BA- ------------------------BA- ------------------------BA- ------------------------BAA ------------------------BAA --------------------------- --------------------------- --------------------------- --------------------------- --------------------------- --------------------------- --------------------------- --------------------------- 
--------------------------- --------------------------- --------------------------- --------------------------- --------------------------- --------------------------- --------------------------- --------------------------- --------------------------- --------------------------- --------------------------- ------------------------BAA ------------------------BAA ------------------------BAA ------------------------BAA ------------------------BAA ------------------------BAA ------------------------BAA --------------------------- --------------------------- --------------------------- --------------------------- --------------------------- --------------------------- --------------------------- --------------------------- --------------------------- --------------------------- 
--------------------------- --------------------------- --------------------------- --------------------------- --------------------------- --------------------------- --------------------------- --------------------------- --------------------------- --------------------------- --------------------------- --------------------------- --------------------------- -------------------------C- ------------------------CCC -------------------------C- --------------------------- --------------------------- --------------------------- --------------------------- --------------------------- --------------------------- --------------------------- --------------------------- --------------------------- --------------------------- --------------------------- --------------------------- 
