model
size = 28 28 19, scale = 0.05, origin = -y
material 
  colors = A:#030 B:#000100 C:#004044 D:#001A0D E:#009 F:#35008B
voxels
---------------------------- ---------------------------- ---------------------------- ---------------------------- ---------------------------- ---------------------------- ---------------------------- ---------------------------- ---------------------------- ---------------------------- ---------------------------- -------------------------AAA -------------------------AAA -------------------------AAA -------------------------AAA -------------------------AAA -------------------------AAA -------------------------AAA ---------------------------- ---------------------------- ---------------------------- ---------------------------- ---------------------------- ---------------------------- ---------------------------- ---------------------------- ---------------------------- ---------------------------- 
---------------------------- ---------------------------- ---------------------------- ---------------------------- ---------------------------- ---------------------------- ---------------------------- ---------------------------- ---------------------------- -------------------------AAA -------------------------AAA -------------------------AAA ------------------------BAD- ------------------------BAC- ------------------------BAC- ------------------------BAC- ------------------------BAA- -------------------------AAA -------------------------AAA -------------------------AAA ---------------------------- ---------------------------- ---------------------------- ---------------------------- ---------------------------- ---------------------------- ---------------------------- ---------------------------- 
---------------------------- ---------------------------- ---------------------------- ---------------------------- ---------------------------- ---------------------------- ---------------------------- ---------------------------- -------------------------AAA -------------------------AAA ------------------------BAA- ------------------------BAD- ------------------------BAC- ------------------------BAC- ------------------------BAC- ------------------------BAC- ------------------------BAC- ------------------------BAD- ------------------------BAA- -------------------------AAA -------------------------AAA ---------------------------- ---------------------------- ---------------------------- ---------------------------- ---------------------------- ---------------------------- ---------------------------- 
---------------------------- ---------------------------- ---------------------------- ---------------------------- ---------------------------- ---------------------------- ---------------------------- -------------------------AAA -------------------------AD- ------------------------BAA- ------------------------BAD- ------------------------BAC- ------------------------BAC- ------------------------BAC- ------------------------BAC- ------------------------BAC- ------------------------BAC- ------------------------BAC- ------------------------BAD- ------------------------BAA- -------------------------AD- -------------------------AAA ---------------------------- ---------------------------- ---------------------------- ---------------------------- ---------------------------- ---------------------------- 
----------AAAAAAAA---------- --------AA--------AAA------- ------AA-------------AA----- -----A-----------------A---- ----A-------------------A--- ---A---------------------A-- --A----------------------AAA -A-----------------------AAA AA----------------------BAA- AA----------------------BAA- AA----------------------BAD- AA----------------------BAC- AA----------------------BAC- AA-----------------------EB- AA----------------------BAB- AA-----------------------EB- AA----------------------BAC- AA----------------------BAC- AA----------------------BAD- AA----------------------BAA- -A----------------------BAA- --A----------------------AAA ---A---------------------AAA ----A-------------------A--- -----A-----------------A---- ------AA-------------AA----- --------AA--------AAA------- ----------AAAAAAAA---------- 
----------BBBBBBBB---------- --------BB--------BBB------- ------BB-------------BB----- -----B-----------------B---- ----B-------------------B--- ---B---------------------B-- --B----------------------AAA -B-----------------------AD- BB----------------------BAD- BA----------------------BAD- BB----------------------BAA- BB----------------------BAC- BA----------------------BAC- BB----------------------BAC- BA----------------------BAC- BB----------------------BAC- BB----------------------BAC- BA----------------------BAC- BB----------------------BAD- BB----------------------BAD- -B----------------------BAD- --B----------------------AD- ---B---------------------AAA ----B-------------------B--- -----B-----------------B---- ------BB-------------BB----- --------BB--------BBB------- ----------BBBBBBBB---------- 
----------AAAAAAAA---------- --------AA--------AAA------- ------AA-------------AA----- -----A-----------------A---- ----A-------------------A--- ---A---------------------AAA --A----------------------AAA -A----------------------BAC- AA----------------------BAC- AB----------------------BAC- AA----------------------BAD- AA----------------------BAD- AB----------------------BAC- AA----------------------BAC- AB----------------------BAC- AA----------------------BAC- AA----------------------BAC- AB----------------------BAD- AA----------------------BAA- AA----------------------BAC- -A----------------------BAC- --A---------------------BAC- ---A---------------------AAA ----A-------------------AAAA -----A-----------------A---- ------AA-------------AA----- --------AA--------AAA------- ----------AAAAAAAA---------- 
----------BABABABA---------- --------BA--------ABA------- ------AB-------------BB----- -----B-----------------A---- ----B-------------------B--- ---B---------------------AAA --A----------------------AC- -B----------------------BAC- BA----------------------BAC- AA----------------------BAC- BA----------------------BAC- B------------------------ED- AA----------------------BAD- B------------------------EC- AA----------------------BAC- B------------------------EC- BA----------------------BAD- AA-----------------------EA- AA----------------------BAC- AA----------------------BAC- -A----------------------BAC- --A---------------------BFC- ---A---------------------AC- ----A-------------------AAAA -----A-----------------B---- ------BB-------------AA----- --------BA--------BAB------- ----------BABABABA---------- 
----------ABABABAB---------- --------AB--------BAB------- ------BA-------------AA----- -----A-----------------B---- ----A-------------------A--- ---A---------------------AAA --B----------------------AC- -A----------------------BAC- AA----------------------BAC- BA----------------------BAB- AA----------------------BAC- AA----------------------BAC- BA----------------------BAD- AA----------------------BAA- BA----------------------BFA- AA----------------------BAA- AA----------------------BAA- BA----------------------BAC- AA----------------------BAC- BB----------------------BAB- -B----------------------BFC- --B---------------------BFC- ---B---------------------AC- ----A-------------------AAAA -----B-----------------A---- ------AA-------------AB----- --------AB--------ABA------- ----------ABABABAB---------- 
----------BABABABA---------- --------BA--------ABA------- ------AB-------------BB----- -----B-----------------A---- ----B-------------------B--- ---B---------------------AAA --A----------------------AC- -B----------------------B-C- BB----------------------B-B- BB----------------------BAC- BB----------------------BAC- BB----------------------BAC- BB----------------------BAD- BB----------------------BAA- BB----------------------BD-- BB----------------------BAA- BB----------------------BAA- BB----------------------BAC- BB----------------------BAC- AA----------------------BAC- -A----------------------BAB- --A---------------------BAC- ---A---------------------AC- ----B-------------------AAAA -----A-----------------B---- ------AB-------------BA----- --------AA--------BAB------- ----------BABABABA---------- 
----------ABABABAB---------- --------AB--------BAB------- ------BA-------------AA----- -----A-----------------B---- ----A-------------------A--- ---A---------------------AAA --B----------------------AC- -A----------------------BAC- AA----------------------BAC- BA----------------------BAB- AA----------------------BAC- AA----------------------BAC- BA----------------------BAD- AA----------------------BAA- BA----------------------BAA- AA----------------------BAA- AA----------------------BAA- BA----------------------BAC- AA----------------------BAC- BB----------------------BAB- -B----------------------BFC- --B---------------------BAC- ---B---------------------AC- ----A-------------------AAAA -----B-----------------A---- ------AA-------------AB----- --------AB--------ABA------- ----------ABABABAB---------- 
----------BABABABA---------- --------BA--------ABA------- ------AB-------------BB----- -----B-----------------A---- ----B-------------------B--- ---B---------------------AAA --A----------------------AC- -B----------------------BAC- BA----------------------BAC- AA----------------------BAC- BA----------------------BAC- B------------------------ED- AA----------------------BAD- B------------------------EC- AA----------------------BAC- B------------------------EC- BA----------------------BAD- AA-----------------------EA- AA----------------------BAC- AA----------------------BAC- -A----------------------BAC- --A---------------------BFC- ---A---------------------AC- ----A-------------------AAAA -----A-----------------B---- ------BB-------------AA----- --------BA--------BAB------- ----------BABABABA---------- 
----------AAAAAAAA---------- --------AA--------AAA------- ------AA-------------AA----- -----A-----------------A---- ----A-------------------A--- ---A---------------------AAA --A----------------------AAA -A----------------------BAC- AA----------------------BAC- AB----------------------BAC- AA----------------------BAD- AA----------------------BAD- AB----------------------BAC- AA----------------------BAC- AB----------------------BAC- AA----------------------BAC- AA----------------------BAC- AB----------------------BAD- AA----------------------BAA- AA----------------------BAC- -A----------------------BAC- --A---------------------BAC- ---A---------------------AAA ----A-------------------AAAA -----A-----------------A---- ------AA-------------AA----- --------AA--------AAA------- ----------AAAAAAAA---------- 
----------BBBBBBBB---------- --------BB--------BBB------- ------BB-------------BB----- -----B-----------------B---- ----B-------------------B--- ---B---------------------B-- --B----------------------AAA -B-----------------------AD- BB----------------------BAD- BA----------------------B-D- BB----------------------BAA- BB----------------------BAC- BA----------------------BAC- BB----------------------BAC- BA----------------------BAC- BB----------------------BAC- BB----------------------BAC- BA----------------------BAC- BB----------------------BAD- BB----------------------BAD- -B----------------------BAD- --B----------------------AD- ---B---------------------AAA ----B-------------------B--- -----B-----------------B---- ------BB-------------BB----- --------BB--------BBB------- ----------BBBBBBBB---------- 
----------AAAAAAAA---------- --------AA--------AAA------- ------AA-------------AA----- -----A-----------------A---- ----A-------------------A--- ---A---------------------A-- --A----------------------AAA -A-----------------------AAA AA----------------------BAA- AA----------------------B-A- AA----------------------BAD- AA----------------------BAC- AA----------------------BAC- AA-----------------------EB- AA----------------------BAB- AA-----------------------EB- AA----------------------BAC- AA----------------------BAC- AA----------------------BAD- AA----------------------BAA- -A----------------------BAA- --A----------------------AAA ---A---------------------AAA ----A-------------------A--- -----A-----------------A---- ------AA-------------AA----- --------AA--------AAA------- ----------AAAAAAAA---------- 
---------------------------- ---------------------------- ---------------------------- ---------------------------- ---------------------------- ---------------------------- ---------------------------- -------------------------AAA -------------------------AD- ------------------------BAA- ------------------------BAD- ------------------------BAC- ------------------------BAC- ------------------------BAC- ------------------------BAC- ------------------------BAC- ------------------------BAC- ------------------------BAC- ------------------------BAD- ------------------------BAA- -------------------------AD- -------------------------AAA ---------------------------- ---------------------------- ---------------------------- ---------------------------- ---------------------------- ---------------------------- 
---------------------------- ---------------------------- ---------------------------- ---------------------------- ---------------------------- ---------------------------- ---------------------------- ---------------------------- -------------------------AAA -------------------------AAA ------------------------BAA- ------------------------BAD- ------------------------BAC- ------------------------BAC- ------------------------BAC- ------------------------BAC- ------------------------BAC- ------------------------BAD- ------------------------BAA- -------------------------AAA -------------------------AAA ---------------------------- ---------------------------- ---------------------------- ---------------------------- ---------------------------- ---------------------------- ---------------------------- 
---------------------------- ---------------------------- ---------------------------- ---------------------------- ---------------------------- ---------------------------- ---------------------------- ---------------------------- ---------------------------- -------------------------AAA -------------------------AAA -------------------------AAA ------------------------BAD- ------------------------BAC- ------------------------BAC- ------------------------BAC- ------------------------BAD- -------------------------AAA -------------------------AAA -------------------------AAA ---------------------------- ---------------------------- ---------------------------- ---------------------------- ---------------------------- ---------------------------- ---------------------------- ---------------------------- 
---------------------------- ---------------------------- ---------------------------- ---------------------------- ---------------------------- ---------------------------- ---------------------------- ---------------------------- ---------------------------- ---------------------------- ---------------------------- -------------------------AAA -------------------------AAA -------------------------AAA -------------------------AAA -------------------------AAA -------------------------AAA -------------------------AAA ---------------------------- ---------------------------- ---------------------------- ---------------------------- ---------------------------- ---------------------------- ---------------------------- ---------------------------- ---------------------------- ---------------------------- 
