model
size = 14 32 28, scale = 0.05, origin = -y
material 
  colors = A:#111 B:#D00 C:#222 D:#800 E:#E00 F:#500 G:#700 H:#001 I:#E91D1C J:#002 K:#DF5756 L:#DA7474 M:#400 N:#E43A39
voxels
181-A2(13-C)27-3(A13-C13-)C3(13-A)41-A2(13-C)13-A180-2(C13-)A13-K13-D3(13-A)13-F13-D3(13-A)13-C2(13-A)2(13-C13-A)123-2(A13-)C28-A13-E4(13-B)13-C13-E2(13-B)13-E13-G2(13-B)13-C3(13-A)13-C13-A95-A3(13-C)2(13-A)14-C13-G4(13-B)13-A13-L2(13-B)13-K13-G2(13-B)13-J3(13-A)13-C13-A67-3(A13-)2(C13-)A13-J13-E14-C13-F4(13-B)13-N13-L2(13-B)13-K13-G13-B13-D13-H3(13-A)13-C39-2(A13-)2(C2(13-A)13-)G2(13-F)14-F13-J4(13-B)2(13-K)2(13-B)13-K13-E13-D13-M13-C3(13-A)53-A3(13-C)13-A13-F13-J13-I13-A13-D13-A14-E13-J4(13-B)13-K13-G2(13-B)13-K2(13-A)13-L13-E13-C13-A53-2(A13-C13-)2(A13-)2(D13-)A13-J13-L13-G14-E13-H5(13-B)13-F2(13-B)2(13-F)13-E13-D13-G2(13-A)53-H2(13-C)6(13-A)13-F13-A13-D14-2(A13-)D4(13-B)13-A13-D13-A13-G13-E13-L13-E2(13-A)81-2(A13-C13-)C13-M2(13-E)13-A13-D2(13-I)13-D14-A4(13-B)2(13-A)2(13-E)13-D13-J137-3(A13-)G13-M13-F13-A13-J3(13-I)13-B14-A13-I3(13-B)13-A2(13-E)13-D13-J179-H13-M2(13-D)13-I13-L13-A2(13-I)13-B14-M13-F3(13-B)13-A13-E13-F13-H235-D3(13-F)13-A13-H13-L14-I13-A13-E13-B13-G2(292-7(D13-)4(DH12-)DH)292-D3(13-F)13-A13-H13-L14-I13-A13-E13-B13-G251-H13-M2(13-D)13-I13-L13-A2(13-I)13-B14-M13-F3(13-B)13-A13-E13-F13-H167-3(A13-)G13-M13-F13-A13-J3(13-I)13-B14-A13-I3(13-B)13-A2(13-E)13-D13-J139-2(A13-C13-)C13-M2(13-E)13-A13-D2(13-I)13-D14-A4(13-B)2(13-A)2(13-E)13-D13-J111-H2(13-C)6(13-A)13-F13-A13-D14-2(A13-)D4(13-B)13-A13-D13-A13-G13-E13-L13-E2(13-A)69-2(A13-C13-)2(A13-)2(D13-)A13-J13-L13-G14-E13-H5(13-B)13-F2(13-B)2(13-F)13-E13-D13-G2(13-A)69-A3(13-C)13-A13-F13-J13-I13-A13-D13-A14-E13-J4(13-B)13-K13-G2(13-B)13-K2(13-A)13-L13-E13-C13-A69-2(A13-)2(C2(13-A)13-)G2(13-F)14-F13-J4(13-B)2(13-K)2(13-B)13-K13-E13-D13-M13-C3(13-A)97-3(A13-)2(C13-)A13-J13-E14-C13-F4(13-B)13-N13-L2(13-B)13-K13-G13-B13-D13-H3(13-A)13-C111-A3(13-C)2(13-A)14-C13-G4(13-B)13-A13-L2(13-B)13-K13-G2(13-B)13-J3(13-A)13-C13-A125-2(A13-)C28-A13-E4(13-B)13-C13-E2(13-B)13-E13-G2(13-B)13-C3(13-A)13-C13-A182-2(C13-)A13-K13-D3(13-A)13-F13-D3(13-A)13-C2(13-A)2(13-C13-A)182-A2(13-C)27-3(A13-C13-)C3(13-A)41-A2(13-C)13-A
