model
size = 17 23 23, scale = 0.05, origin = -y
material 
  colors = A:#E00 B:#D00 C:#100 D:#222 E:#800
voxels
-----AAAAAAA----- -----ADDADDA----- -----ADDADDA----- -----AAAAAAA----- ----------------- ----------------- ----------------- ----------------- ----------------- ----------------- ----------------- ----------------- ----------------- ----------------- ----------------- ----------------- ----------------- ----------------- ----------------- ----------------- ----------------- ----------------- ----------------- 
-------AAA------- -----AAAAAAA----- -----AAAAAAA----- -----AAAAAAA----- ----------------- ----------------- ----------------- ----------------- ----------------- ----------------- ----------------- ----------------- ----------------- ----------------- ----------------- ----------------- ----------------- ----------------- ----------------- ----------------- ----------------- ----------------- ----------------- 
----------------- ------AAAAA------ -------AAAA------ -----AAAAAAA----- -------AAA------- ----------------- ----------------- ----------------- ----------------- ----------------- ----------------- ----------------- ----------------- ----------------- ----------------- ----------------- ----------------- ----------------- ----------------- ----------------- ----------------- ----------------- ----------------- 
----------------- ------AAAAA------ ------AAAAA------ -----AAAAAAA----- ------BAAAB------ -------AAA------- ----------------- ----------------- ----------------- ----------------- ----------------- ----------------- ----------------- ----------------- ----------------- ----------------- ----------------- ----------------- ----------------- ----------------- ----------------- ----------------- ----------------- 
----------------- ------AAAAA------ ------AAAAA------ ------AAAAA------ ------AAAAA------ -------AAA------- -------AAA------- ----------------- ----------------- ----------------- ----------------- ----------------- ----------------- ----------------- ----------------- ----------------- ----------------- ----------------- ----------------- ----------------- ----------------- ----------------- ----------------- 
----------------- ------AAAAA------ ------AAAAA------ ------AAAAA------ ------AAAAA------ -------AAA------- -------AAA------- -------AAA------- ----------------- ----------------- ----------------- ----------------- ----------------- ----------------- ----------------- ----------------- ----------------- ----------------- ----------------- ----------------- ----------------- ----------------- ----------------- 
----------------- ------AAAAA------ ------AAAAA------ ------AAAAA------ ------AAAAA------ ------AAAAA------ -------AAA------- -------AAA------- -------AAA------- ----------------- ----------------- ----------------- ----------------- ----------------- ----------------- ----------------- ----------------- ----------------- ----------------- ----------------- ----------------- ----------------- ----------------- 
----------------- ------AAAAA------ ------AAAAA------ ------AAAAA------ ------AAAAA------ ------AAAAA------ ------BAAAB------ -------AAA------- -------AAA------- -------AAA------- ----------------- ----------------- ----------------- ----------------- ----------------- ----------------- ----------------- ----------------- ----------------- ----------------- ----------------- ----------------- ----------------- 
----------------- ------AAAAA------ ------AAAAA------ ------AAAAA------ ------AAAAA------ ------AAAAA------ -----BBAAABB----- -------AAA------- -------AAA------- -------AAA------- -------AAA------- -------AAA------- ----------------- ----------------- ----------------- ----------------- ----------------- ----------------- ----------------- ----------------- ----------------- ----------------- ----------------- 
----------------- ----------------- ------AAAAA------ -------AAA------- -------AAA------- -------AAA------- -----BBBAAAB----- -----BBBABBB----- ------BBAAB------ ------BBAAB------ ------AAAAA------ ------CAAAC------ ------EAAAE------ -----EAAAAAE----- ----------------- ----------------- ----------------- ----------------- ----------------- ----------------- ----------------- ----------------- ----------------- 
----------------- ------AAAAA------ ----AAAAAAAAA---- ------AAAAA------ ------AAAAA------ ------AAAAA------ -----BBBAA------- ----BBBBAABBB---- ----BBAAAABBB---- ------AAAAA------ -----AAAAAAA----- -----AAAAAAA----- -----AAAAAAA----- -----AAAAAAA----- -----AAAAAAA----- ----------------- ----------------- ----------------- ----------------- ----------------- ----------------- ----------------- ----------------- 
----------------- ----AAAAAAAAA---- ---AAAAAAAAAAA--- -----AAAAAAA----- -----AAAAAAA----- -----AAAAAAA----- ------ABAAA------ ----BBBBAABBB---- ----BBAAAABBB---- -----BAAAAAB----- ----ABAAAAABA---- ----ABAAAAABA---- ----ABAAAAABA---- ----ABAAAAABA---- -----BAAAAAB----- ---CCCAAAAACCC--- -CCCCC-----CCCCC- -CCC---------CCC- CC-------------CC CC-------------CC C---------------C ----------------- ----------------- 
----------------- ---AAAAAAAAAAA--- ---AAAAAAAAAAA--- ----AAAAAAAAA---- ----AAAAAAAAA---- ----AAAAAAAAA---- -----AAAAAAA----- ----BBBBAAAA----- ----BBAAAAA------ ----AAAAAAAAA---- ----AAAAAAAAA---- ----AAAAAAAAA---- ----AAAAAAAAA---- ----AAAAAAAAA---- -----AAAAAAA----- ---CCCAAAAACCC--- -CCCCCAAAAACCCCC- -CCC---------CCC- CC-------------CC CC-------------CC C---------------C C---------------C C---------------C 
----------------- ---AAAAAAAAAAA--- --AAAAAAAAAAAAA-- ---AAAAAAAAAAA--- ---AAAAAAAAAAA--- ---AAAAAAAAAAA--- ----AAAAAAAAA---- ----AAAAAAAAA---- ------AAAAA------ ------AAAAA------ ------AAAAA------ ------AAAAA------ ------AAAAA------ ------AAAAA------ ------AAAAA------ ------AAAAA------ ------AAAAA------ ------AAAAA------ ----------------- ----------------- ----------------- ----------------- ----------------- 
----------------- --AAAAAAAAAAAAA-- --AAAAAAAAAAAAA-- ---AAAAAAAAAAA--- ---AAAAAAAAAAA--- ---AAAAAAAAAAA--- ----AAAAAAAAA---- ----AAAAAAAAA---- -----AAAAAAA----- ------AAAAA------ ------AAAAA------ ------AAAAA------ ---AAAAAAAAAAA--- --ABBBAAAAABBBA-- ------AAAAA------ ------AAAAA------ ------AAAAA------ ------AAAAA------ -------AAA------- ----------------- ----------------- ----------------- ----------------- 
----------------- --AAAAAAAAAAAAA-- --AAAAAAAAAAAAA-- ---AAAAAAAAAAA--- ---AAAAAAAAAAA--- ---AAAAAAAAAAA--- ----AAAAAAAAA---- ----AAAAAAAAA---- -----AAA-AAA----- ------AAAAA------ ------AAAAA------ ------AAAAA------ ------AAAAA------ ------AAAAA------ ------AAAAAB----- ------AAAAA------ ------AAAAA------ ------AAAAA------ ----------------- ----------------- ----------------- ----------------- ----------------- 
----------------- --AAAAAAAAAAAAA-- --AAAAAAAAAAAAA-- ---AAAAAAAAAAA--- ---AAAAAAAAAAA--- ---AAAAAAAAAAA--- ----AAAAAAAAA---- ----AAAAAAAAA---- -----AAAAAAA----- -------AAA------- -------AAA------- -------AAA------- -------AAA------- --------A-------- ------AAAAA------ ------AAAAA------ ------AAAAA------ ----------------- ----------------- ----------------- ----------------- ----------------- ----------------- 
----------------- --AAAAAAAAAAAAA-- --AAAAAAAAAAAAA-- ---AAAAAAAAAAA--- ---AAAAAAAAAAA--- ---AAAAAAAAAAA--- ----AAAAAAAAA---- ----AAAAAAAAA---- ------AAAAA------ ----------------- ----------------- ----------------- ----------------- --------A-------- --------A-------- --------A-------- ----------------- ----------------- ----------------- ----------------- ----------------- ----------------- ----------------- 
----------------- --AAAAAAAAAAAAA-- ---AAAAAAAAAAA--- ----AAAAAAAAA---- ----AAAAAAAAA---- ----AAAAAAAAA---- -----AAAAAAA----- -----AAAAAAA----- -------AAA------- ----------------- ----------------- ----------------- ----------------- ----------------- ----------------- ----------------- ----------------- ----------------- ----------------- ----------------- ----------------- ----------------- ----------------- 
----------------- ---AAAAAAAAAAA--- ---AAAAAAAAAAA--- -----AAAAAAA----- -----AAAAAAA----- -----AAAAAAA----- ------AAAAA------ ------AAAAA------ ----------------- ----------------- ----------------- ----------------- ----------------- ----------------- ----------------- ----------------- ----------------- ----------------- ----------------- ----------------- ----------------- ----------------- ----------------- 
----------------- ---AAAAAAAAAAA--- ----AAAAAAAAA---- ------AAAAA------ ------AAAAA------ ------AAAAA------ ----------------- ----------------- ----------------- ----------------- ----------------- ----------------- ----------------- ----------------- ----------------- ----------------- ----------------- ----------------- ----------------- ----------------- ----------------- ----------------- ----------------- 
----------------- ----AAAAAAAAA---- ------AAAAA------ ----------------- ----------------- ----------------- ----------------- ----------------- ----------------- ----------------- ----------------- ----------------- ----------------- ----------------- ----------------- ----------------- ----------------- ----------------- ----------------- ----------------- ----------------- ----------------- ----------------- 
----------------- ------AAAAA------ ----------------- ----------------- ----------------- ----------------- ----------------- ----------------- ----------------- ----------------- ----------------- ----------------- ----------------- ----------------- ----------------- ----------------- ----------------- ----------------- ----------------- ----------------- ----------------- ----------------- ----------------- 
