model
size = 16 28 19, scale = 0.05, origin = -y
material 
  colors = A:#C30 B:#F30 C:#EEE D:#C96 E:#996 F:#FFC G:#930 H:#FCC I:#CC9 J:#F60 K:#888 L:#963 M:#AAA N:#663 O:#FC9 P:#C99 Q:#966 R:#CCC S:#400 T:#444 U:#777 V:#999 W:#300 X:#BBB Y:#630 Z:#633 Aa:#800 Ab:#111 Ac:#555 Ad:#500 Ae:#600 Af:#A00 Ag:#700 Ah:#660 Ai:#C63 Aj:#666 Ak:#333 Al:#222
voxels
- - - - - - - - - - - - - - - -   - - - - - - - - - - - - - - - -   - - - - - - - - - - - - - - - -   - - - - - - - - - - - - - - - -   - - - - - - - - - - - - - - - -   - - - - - - - - - - - - - - - -   - - - - - - - - - - - - - - - -   - - - - - - - - - - - - - - - -   - - - - - - - - - - - - - - - -   - - - - - - - - - - - - - - - -   - - - - - - - - - - - - - - - -   - - - - - - - - - - - - - - - -   - - - - - - - - - - - - - - - -   - - - - - - - - - - - - - - - -   - - - - - - - - - - - - - - - -   - - - - - - C - - - - - - - - -   - - - - - C C C - C - - - - - -   - - - - - - - - - - - - - - - -   - - - - - - - - - C - - - - - -   - - - - - - - - - C - - - - - -   - - - - - - - - C C - - - - - -   - - - - - - - C C C - - - - - -   - - - - - - - C C C - - - - - -   - - - - - - - C C C - - - - - -   - - - - - - - C C C - - - - - -   - - - - - - - - - - - - - - - -   - - - - - - - - - - - - - - - -   - - - - - - - - - - - - - - - -   
- - - - - G G Y Y Z - - - - - -   - - - - - G G Y Y Z - - - - - -   - - - - - - - - - - - - - - - -   - - - - - - - - - - - - - - - -   - - - - - - - - - - - - - - - -   - - - - - - - - - - - - - - - -   - - - - - - - - - - - - - - - -   - - - - - - - - - - - - - - - -   - - - - - - - - - - - - - - - -   - - - - - - - - - - - - - - - -   - - - - - - - - - - - - - - - -   - - - - - - - - - - - - - - - -   - - - - - - - - - - - - - - - -   - - - - - - - - - - - - - - - -   - - - - - - - - D - - - - - - -   - - - - - - D D D D - - - - - -   - - - - C O D C C C - - - - - -   - - - - D O O C C O - - - - - -   - - - - D K F C C H C - - - - -   - - - - - C C C C H F - - - - -   - - - - C F F C C H F - - - - -   - - - - C F F I I H F - - - - -   - - - C C F F I I H F - - - - -   - - - - C F F I I H C - - - - -   - - - - - - F M M D C - - - - -   - - - - - C C C C C - - - - - -   - - - - - - K M - - - - - - - -   - - - - - - - - - - - - - - - -   
- - - - Q G G Y Y Z Ak- - - - -   - - - - Q G G Y Y Z Ak- - - - -   - - - - - A A A G A - - - - - -   - - - - - A A A G A - - - - - -   - - - - - B A A A A - - - - - -   - - - - - B A A A A - - - - - -   - - - - - B B A A A - - - - - -   - - - - - J J J A J - - - - - -   - - - - - A B J J A - - - - - -   - - - - - B B A A A - - - - - -   - - - - - B B A B A - - - - - -   - - - - - B B B B A - - - - - -   - - - - - A B B J B - - - - - -   - - - - - B A B J B - - - - - -   - - - - - B A B A A - - - - - -   - - - - - A G AiAiAiD - - - - -   - - - - D O O D D O - - - - - -   - - - C D O O D D O H - - - - -   - - - - C H F D D H H - - - - -   - - - - C H H D D H F - - - - -   - - - - C F F D D H F - - - - -   - - - C C F F I I H F - - - - -   - - - C C F F I I H F - - - - -   - - - C C F F I I H F - - - - -   - - - - C F F M M D P - - - - -   - - - - C K P P P M R - - - - -   - - - - C R M M M M - - - - - -   - - - - - - - - - - - - - - - -   
- - - Q Y G G Y Y Z AkAl- - - -   - - - Q Y G G Y Y Z AkAl- - - -   - - - - A A A A G A G - - - - -   - - - - A A A A G A G - - - - -   - - - - A B A A A A G - - - - -   - - - - A B A A A A G - - - - -   - - - - A B B A A A G - - - - -   - - - - J J J J A J A - - - - -   - - - - B A B J J A G - - - - -   - - - - A B B A A A G - - - - -   - - - - A B B A B A G - - - - -   - - - - B B B B B A G - - - - -   - - - - B B B B J B G - - - - -   - - - - J B A B J B B - - - - -   - - - - J B A B A A B - - - - -   - - - - A G G AiAiA A D D - - -   - - - - I O E D D O I O - - - -   - - C D I O E D D O I O - - - -   - - C C O H E D D D O H - - - -   - - - C H H E D D D H H - - - -   - C - C H F E E E D H F - - - -   - C C C H F E E E D H F - - - -   - - C C H F F E E D H F - - - -   - K - C H F F E E D H F - - - -   - - - C H F F Q Q D H F - - - -   - - - C D P P Q Q E D P - - - -   - - - C M R C C C C M R - - - -   - - - - - - - - C - - - - - - -   
- - Q Q Q Q Q Q Q Q Q Q Q - - -   - - Q Q Q Q Q Q Q Q Q Q Q - - -   - - - AaAaAaAaAaAaAaAaAa- - - -   - - - A A A A A A A A A - - - -   - - - A A A A A A A A A - - - -   - - - A A A A A A A A A - - - -   - - - A A A A A A A A A - - - -   - - - A A A A A A A A A - - - -   - - - J J J J J J J J J - - - -   - - - B B B B B B B B B - - - -   - - - A A A A A A A A A - - - -   - - - A A A A A A A A A - - - -   - - - B B B B B B B B B - - - -   - - - B B B B B B B B B - - - -   - - - B B B B B B B B B C - - -   - - - B B B B B B B B A D C - -   - - C E Z Z Z Z Z Z Z O O - - -   - C C E Z Z Z Z Z Z Z O O - - -   - - C D O N N N N N N H F - - -   - C C D H N N N N N N H H - - -   I K C D H N N N N N H F F - - -   - C C D H N N N N N H F F - - -   - C C D H F N N N D H F F - - -   C C C D H F N N N D H F F - - -   - C C D H F N N N D H F F C - -   - - C C D P N N N E D P P C - -   - - - C M R K C C C M R K C - -   - - - - - - - - C C - - - - - -   
- U U U U U U U U U U U U U - -   - U U U U U U U U U U U U U - -   - - AfAfAfAfAfAfAfAfAfAfAf- - -   - - A A A A A A A A A A A - - -   - - A A A A A A A A A A A - - -   - - B B B B B B B B B B B - - -   - - B B B B B B B B B B B - - -   - - B B B B B B B B B B B - - -   - - J J J J J J J J J J J - - -   - - A A A A A A A A A A A - - -   - - B B B B B B B B B B B - - -   - - B B B B B B B B B B B - - -   - - B B B B B B B B B B B - - -   - - B B B B B B B B B B B - - -   - - A B B B B B B B B B B - - -   - - A B B B B B B B B B B C - -   - - L N N N N N N N N N D D C -   C L L N N N N N N N N N N P - -   - I E D L L L L L L L L C C - -   C E E D L L L L L L L L H I - -   C E E D L L L L L L L L F I - -   C E E D L L L L L L L L F I - -   C E E D L L L L L L L F F I - -   C C K D L L L L L L L F F I - -   - C Q D H L L L L L L F F M C -   - C Q E D N N N N N D P P P C -   - - C C M C C C C C M - C C - -   - - - - - - - - - - - - - - - -   
- E E E E E E E E E E E E E - -   - E E E E E E E E E E E E E - -   - - G G G G G G G G G G G - - -   - - A A A A A A A A A A A - - -   - - A A A A A A A A A A A - - -   - - A A A A A A A A A A A - - -   - - A A A A A A A A A A A - - -   - - B B B B B B B B B B B - - -   - - J J J J J J J J J J J - - -   - - B B B B B B B B B B B - - -   - - B B B B B B B B B B B - - -   - - B B B B B B B B B B B - - -   - - B B B B B B B B B B B - - -   - - B B B B B B B B B B B - - -   - - A A A A A A A A A A A - - -   - - A A A A A A A A A A A - - -   - L L L L L L L L L L L L L C -   I L L L L L L L L L L L L L C -   I E E E E E E E E E E E E C - -   C E E E E E E E E E E E E C - -   C E E E E E E E E E E E K I - -   C E E E E E E E E E E E E I - -   C E E E E E E E E E E E E I C -   C E E E E E E E E E E E E I C -   I Q Q D Q Q Q Q Q Q Q Q Q M C -   C Q Q E Q Q Q Q Q Q Q Q P P C -   - C C C C C C C C C I C - C - -   - - - - - - - - - - - - - - - -   
- K K K K K K K K K K K K K - -   - K K K K K K K K K K K K K - -   - - AaAaAaAaAaAaAaAaAaAaAa- - -   - - A A A A A A A A A A A - - -   - - A A A A A A A A A A A - - -   - - A A A A A A A A A A A - - -   - - A A A A A A A A A A A - - -   - - A A A A A A A A A A A - - -   - - J J J J J J J J J J J - - -   - - J J J J J J J J J J J - - -   - - A A A A A A A A A A A - - -   - - A A A A A A A A A A A - - -   - - B B B B B B B B B B B - - -   - - B B B B B B B B B B B - - -   - - B B B B B B B B B B B - - -   - - B B B B B B B B B B B - - -   - E E E E E E E E E E E E E D -   - E E E E E E E E E E E E D C -   - C D D D D D D D D D D D D C -   - C D D D D D D D D D D D C - -   - C D D D D D D D D D D C C - -   - C D D D D D D D D D D D D C -   C C D D D D D D D D D D D D C -   - C D D D D D D D D D D D C C -   C C D D D D D D D D D D D C K C   C Q Q E E E E E E E E E E K I -   - C C C C C C C C C C C C - - -   - - - - - - - - - - - - - - - -   
- K K K K K K K K K K K K K - -   - K K K K K K K K K K K K K - -   - - - AgAgAgAgAgAgAgAgAgAg- - -   - - - G G G G G G G G G G - - -   - - G G G G G G G G G G G - - -   - - A A A A A A A A A A A - - -   - - A A A A A A A A A A A - - -   - - A A A A A A A A A A A - - -   - - A A A A A A A A A A A - - -   - - J J J J J J J J J J J - - -   - - A A A A A A A A A A A - - -   - - B B B B B B B B B B B - - -   - - B B B B B B B B B B B - - -   - - J J J J J J J J J J J - - -   - - J J J J J J J J J J J - - -   - - A A A A A A A A A A A - - -   - E E E E E E E E E E E E D D -   - E E E E E E E E E E E E E C -   - C D D D D D D D D D D D D C -   - C D D D D D D D D D D D C - -   - C D D D D D D D D D D D D C -   - C D D D D D D D D D D K C C C   - C D D D D D D D D D D C C C -   - C D D D D D D D D D D D C C -   I I D D D D D D D D D D D C K C   C Q Q E E E E E E E E E E C I -   C C C C C C C C C C C C C - - -   - - - C - C - - - - - - - - - -   
- T T T T T T T T T T T T T - -   - - T T T T T T T T T T T T - -   - - - G G G G G G G G G G - - -   - - A A A A A A A A A A A - - -   - - A A A A A A A A A A A - - -   - - A A A A A A A A A A A - - -   - - A A A A A A A A A A A - - -   - - A A A A A A A A A A A - - -   - - J J J J J J J J J J J - - -   - - A A A A A A A A A A A - - -   - - A A A A A A A A A A A - - -   - - A A A A A A A A A A A - - -   - - A A A A A A A A A A A - - -   - - B B B B B B B B B B B - - -   - - B B B B B B B B B B B - - -   - - A A A A A A A A A A A - - -   - I I I I I I I I I I I I - - -   - I I I I I I I I I I I I I - -   - O O O O O O O O O O O K D C -   C H H H H H H H H H H H H C - -   - H H H H H H H H H H H H H C -   - H H H H H H H H H H H H H C -   I H H H H H H H H H H H H C C -   C H H H H H H H H H H H H H C -   C I H H H H H H H H H H H H C -   C D D D D D D D D D D D D C - -   C C C M M M M M M M M M M C - -   - - C - - - - - - - - I - - - -   
- - - T T T T T T T T T T - - -   - - - T T T T T T T T T T - - -   - - - AhAhAhAhAhAhAhAhAh- - - -   - - - G G G G G G G G G - - - -   - - - G G G G G G G G G - - - -   - - - G G G G G G G G G - - - -   - - - G G G G G G G G G - - - -   - - - G G G G G G G G G - - - -   - - - A A A A A A A A A - - - -   - - - G G G G G G G G G - - - -   - - - G G G G G G G G G - - - -   - - - G G G G G G G G G - - - -   - - - G G G G G G G G G - - - -   - - - G G G G G G G G G - - - -   - - - G G G G G G G G G - - - -   - - - A A A A A A A A A - - - -   - O O O O O O O O O O O O - - -   - O O O O O O O O O O O O O - -   - - H H H H H H H H H H H H - -   - H H H H H H H H H H H C - - -   - F F F F F F F F F F F F F - -   - - F F F F F F F F F F F F - -   - F F F F F F F F F F F F C - -   - F F F F F F F F F F F F F C -   - - C F F F F F F F F F F F C -   C C C P P P P P P P P P P P C -   - - C R R R R R R R R R R C - -   - - - - - - - - - - - I I - - -   
- - - N N N N N N N N N - - - -   - - - N N N N N N N N N - - - -   - - - - Y Y Y Y Y Y Y - - - - -   - - - - W W W W W W W - - - - -   - - - - W W W W W W W - - - - -   - - - - S S S S S S S - - - - -   - - - - S S S S S S S - - - - -   - - - - W W W W W W W - - - - -   - - - - W W W W W W W - - - - -   - - - - S S S S S S S - - - - -   - - - - S S S S S S S - - - - -   - - - - S S S S S S S - - - - -   - - - - S S S S S S S - - - - -   - - - - AdAdAdAdAdAdAd- - - - -   - - - - AeAeAeAeAeAeAe- - - - -   - - - - AdAdAdAdAdAdAd- - - - -   - - - O O O O O O O O C - - - -   - - - O O O O O O O O O C - - -   - - - F F F F F F F F F C - - -   - - - H H H H H H H H H C - - -   - - - F F F F F F F F F F - - -   - - - F F F F F F F F F F - - -   - - - F F F F F F F F F F - - -   - - C F F F F F F F F F C - - -   - - C F F F F F F F F F F - - -   C C C C P P P P P P P P P C C -   - - C R R R R R R R R R R C - -   - - - - - - - I I I - I - - - -   
- - - - AbAbAbAbAbAbAbAb- - - -   - - - - AbAbAbAbAbAbAbAb- - - -   - - - - - - - - - - - - - - - -   - - - - - - - - - - - - - - - -   - - - - - - V V V W - - - - - -   - - - - - K K K K W - - - - - -   - - - - - W AjAjAjS - - - - - -   - - - - - W M M M S - - - - - -   - - - - - W X X X S - - - - - -   - - - - - W M M M S - - - - - -   - - - - - AeX X X W - - - - - -   - - - - - AeM M M W - - - - - -   - - - - - AeM M M W - - - - - -   - - - - - AeX X X S - - - - - -   - - - - - AeM M M S - - - - - -   - - - - - X X X X S - - - - - -   - - - C P P P P P P P - - - - -   - - - C P P P P P P P C - - - -   - - - C P P P P P P P C - - - -   - - - C I I I I I I I I - - - -   - - - - I I I I I I I I - - - -   - - - - I I I I I I I I - - - -   - - - - I I I I I I I I - - - -   - - - - I I I I I I I I - - - -   - - - C M M M M M C M C - - - -   - - - I P P P P C P P P I I - -   - - - C R R R R R R R R - - - -   - - - - - - - - - - - - - - - -   
- - - - - - - - - - - - - - - -   - - - - - - - - - - - - - - - -   - - - - - - - - - - - - - - - -   - - - - - - - - - - - - - - - -   - - - - - - - M - - - - - - - -   - - - - - - - Aj- - - - - - - -   - - - - - - - - - - - - - - - -   - - - - - - - - - - - - - - - -   - - - - - - - - - - - - - - - -   - - - - - - - - - - - - - - - -   - - - - - - - - - - - - - - - -   - - - - - - - - - - - - - - - -   - - - - - - - - - - - - - - - -   - - - - - - - - - - - - - - - -   - - - - - - - - - - - - - - - -   - - - - - - - - - - - - - - - -   - - - - C AcAcAcAcAcAc- - - - -   - - - - C AcAcAcAcAcAc- - - - -   - - - - C P P P P P C - - - - -   - - - - C V V V V V C - - - - -   - - - - I U U U U U C - - - - -   - - - - I V V V V V I - - - - -   - - - - I M M M C I I C - - - -   - - - - I M C C M I C - - - - -   - - - - I I X C C - C - - - - -   - - - - I R I C - C - - - - - -   - - - - - - - - - - - - - - - -   - - - - - - - - - - - - - - - -   
- - - - - - - - - - - - - - - -   - - - - - - - - - - - - - - - -   - - - - - - - - - - - - - - - -   - - - - - - - - - - - - - - - -   - - - - - - V V V - - - - - - -   - - - - - - AcAcAc- - - - - - -   - - - - - - - - - - - - - - - -   - - - - - - - - - - - - - - - -   - - - - - - - - - - - - - - - -   - - - - - - - - - - - - - - - -   - - - - - - - - - - - - - - - -   - - - - - - - - - - - - - - - -   - - - - - - - - - - - - - - - -   - - - - - - - - - - - - - - - -   - - - - - - - - - - - - - - - -   - - - - - - - - - - - - - - - -   - - - - - - - - - - - - - - - -   - - - - - I - - - - - - - - - -   - - - - - I R R R - - - - - - -   - - - - - I M M M - - - - - - -   - - - - - I I - - - - - - - - -   - - - - - I - - - - - - - - - -   - - - - I I - C - - C - - - - -   - - - - I C C C C C C - - - - -   - - - - - I I - - - - - - - - -   - - - - - - - - - - - - - - - -   - - - - - - - - - - - - - - - -   - - - - - - - - - - - - - - - -   
- - - - - - - - - - - - - - - -   - - - - - - - - - - - - - - - -   - - - - - - - - - - - - - - - -   - - - - - - - - - - - - - - - -   - - - - - - V V V - - - - - - -   - - - - - - U U U - - - - - - -   - - - - - - M M M - - - - - - -   - - - - - - - - - - - - - - - -   - - - - - - - - - - - - - - - -   - - - - - - - - - - - - - - - -   - - - - - - - - - - - - - - - -   - - - - - - - - - - - - - - - -   - - - - - - - - - - - - - - - -   - - - - - - - - - - - - - - - -   - - - - - - - - - - - - - - - -   - - - - - - - - - - - - - - - -   - - - - - - - - - - - - - - - -   - - - - - - - - - - - - - - - -   - - - - - I M M M - - - - - - -   - - - - - - R R R - - - - - - -   - - - - - I V V V - - - - - - -   - - - - - I - - - - - - - - - -   - - - - - - - - - - - - - - - -   - - - - - - - - - - - - - - - -   - - - - - - - - - - - - - - - -   - - - - - - - - - - - - - - - -   - - - - - - - - - - - - - - - -   - - - - - - - - - - - - - - - -   
- - - - - - - - - - - - - - - -   - - - - - - - - - - - - - - - -   - - - - - - - - - - - - - - - -   - - - - - - - - - - - - - - - -   - - - - - - - M - - - - - - - -   - - - - - - M M M - - - - - - -   - - - - - - U U U - - - - - - -   - - - - - - U U U - - - - - - -   - - - - - - M M M - - - - - - -   - - - - - - X X X - - - - - - -   - - - - - - - - - - - - - - - -   - - - - - - - - - - - - - - - -   - - - - - - - - - - - - - - - -   - - - - - - - - - - - - - - - -   - - - - - - - - - - - - - - - -   - - - - - - - - - - - - - - - -   - - - - - - - - - - - - - - - -   - - - - - - V V V - - - - - - -   - - - - - - X X X - - - - - - -   - - - - - - R R R - - - - - - -   - - - - - I K K K - - - - - - -   - - - - - - - - - - - - - - - -   - - - - - - - - - - - - - - - -   - - - - - - - - - - - - - - - -   - - - - - - - - - - - - - - - -   - - - - - - - - - - - - - - - -   - - - - - - - - - - - - - - - -   - - - - - - - - - - - - - - - -   
- - - - - - - - - - - - - - - -   - - - - - - - - - - - - - - - -   - - - - - - - - - - - - - - - -   - - - - - - - - - - - - - - - -   - - - - - - - - - - - - - - - -   - - - - - - - R - - - - - - - -   - - - - - - R R R - - - - - - -   - - - - - - M M M - - - - - - -   - - - - - - V V V - - - - - - -   - - - - - - V V V - - - - - - -   - - - - - - K K K - - - - - - -   - - - - - - U U U - - - - - - -   - - - - - - K K K - - - - - - -   - - - - - - K K K - - - - - - -   - - - - - - K K K - - - - - - -   - - - - - - K K K - - - - - - -   - - - - - - M M M - - - - - - -   - - - - - - X X X - - - - - - -   - - - - - - M M M - - - - - - -   - - - - - - - X - - - - - - - -   - - - - - - - - - - - - - - - -   - - - - - - - - - - - - - - - -   - - - - - - - - - - - - - - - -   - - - - - - - - - - - - - - - -   - - - - - - - - - - - - - - - -   - - - - - - - - - - - - - - - -   - - - - - - - - - - - - - - - -   - - - - - - - - - - - - - - - -   
- - - - - - - - - - - - - - - -   - - - - - - - - - - - - - - - -   - - - - - - - - - - - - - - - -   - - - - - - - - - - - - - - - -   - - - - - - - - - - - - - - - -   - - - - - - - - - - - - - - - -   - - - - - - - - - - - - - - - -   - - - - - - - - - - - - - - - -   - - - - - - - - - - - - - - - -   - - - - - - - X - - - - - - - -   - - - - - - R R R - - - - - - -   - - - - - - X X X - - - - - - -   - - - - - - V V V - - - - - - -   - - - - - - V V V - - - - - - -   - - - - - - V V V - - - - - - -   - - - - - - X X X - - - - - - -   - - - - - - - X - - - - - - - -   - - - - - - - - - - - - - - - -   - - - - - - - - - - - - - - - -   - - - - - - - - - - - - - - - -   - - - - - - - - - - - - - - - -   - - - - - - - - - - - - - - - -   - - - - - - - - - - - - - - - -   - - - - - - - - - - - - - - - -   - - - - - - - - - - - - - - - -   - - - - - - - - - - - - - - - -   - - - - - - - - - - - - - - - -   - - - - - - - - - - - - - - - -   
