model
size = 32 15 32, scale = 0.05, origin = -y
material 
  colors = A:#C90 B:#C93 C:#E00 D:#C30
voxels
399-2(2D30-)2D59-9C119-8C154-4A28-AB2A29-2(2D30-)2D29-BA2B23-3CAB2ABA2B3C21-3ABA3B26-2B2A28-2(AB)23-3CB2(A2B)A3C21-A2BAB3A25-2AB3A26-2ABA2B26-2A2BAB27-B2AB28-2A2B29-2(2D30-)2D25-AB2A2BA3BAB18-CA4B2A2(BA)2BAC18-3B2A2B2AB2A20-7AB4A20-BA3B6AB18-C4A2B2AB2A2BAC18-4AB2A2BABA20-AB3A2-3ABA22-BAB2-ABA25-B4-A181-AB2A8-A2BA15-CB3A8-2BABC15-A2BA8-4A16-3BA8-A3B16-3AB8-2(AB)15-C2ABA8-3BAC15-3AB8-B3A16-AB2A8-4A16-2A12-2B16-A14-A108-3D18-3D8-3D18-3D11-B2A12-B2A13-CABA12-BABC13-2BA12-B2A14-BAB12-ABA14-2AB12-2AB13-CABA12-BABC13-2AB12-BAB13-B3A12-2A2B12-4A12-3AB12-3A14-2AB11-3B16-3A10-ABA16-A2B10-AB18-BA9-3D18-3D8-3D18-3D10-2AB14-2AB11-CABA14-ABAC11-A2B14-3A12-BA16-AB12-B2A14-3A11-CA2B14-2BAC11-BA16-BA11-BAB16-BAB10-3A16-ABA10-3A16-BAB10-AB18-2A10-2A18-AB10-2A18-2A9-3D18-3D8-3D18-3D9-AB18-2A9-C2A18-2BC9-2A18-2A10-2A18-BA10-AB18-BA9-C2A18-2AC9-2A18-2A10-BA18-2A10-AB18-BA10-BA18-2A10-A20-A10-A20-B105-2AB18-3A7-CB2A18-3AC7-3A18-3A8-BA20-AB8-ABA18-3A7-C3B18-3AC7-BA20-AB8-2A20-2A8-2A20-AB8-BA20-BA168-BA20-2A6-C3A20-A2BC6-BA20-2A8-2A20-2A8-BA20-2B6-CB2A20-A2BC6-2A20-AB8-AB20-2A8-AB20-BA199-BA22-2A5-C2A22-ABC5-2B22-2A6-2A22-2A6-BA22-2A5-CBA22-2AC5-2A22-AB6-2A22-BA230-BA22-2A5-C2A22-2BC5-AB22-2A6-BA22-BA6-AB22-AB5-CBA22-2BC5-BA22-2A6-AB22-2A230-A24-B4-CBA24-2AC3-2B24-2A5-A24-A6-B24-A4-CBA24-BAC3-AB24-2A5-A24-B6-B24-A198-A24-A4-CAB24-2AC3-BA24-2A5-B24-B6-B24-A4-C2A24-ABC3-2A24-2A4-2B24-BA4-2A24-2A4-2A24-BA164-AB24-BA3-C2A24-2AC3-2(2A24-BA4-)2A24-2A3-C2A24-2AC3-BA24-2A4-2A24-2A4-2B24-2A4-A26-A3-2A26-BA2-2A26-AB99-AB24-2A3-C2A24-2BC3-AB24-2B4-BA24-2A4-2A24-2A3-CAB24-BAC3-2A24-AB2(4-A26-A)4-A26-B3-2A26-BA2-2A26-BA-3D2(26-6D)26-3D2-BA24-BA3-C2A24-ABC3-2A24-2A4-AB24-AB4-2B24-2A3-C2A24-ABC3-2A24-AB2(4-A26-A)4-A26-B3-2A26-AB2-2A26-BA-3D2(26-6D)26-3D2-BA24-2B3-CAB24-2AC3-AB24-AB4-2A24-2A4-BA24-AB3-CBA24-2AC3-AB2(24-2A4-2A)24-2A4-A26-A3-2B26-AB2-BA26-AB100-A24-A4-CBA24-2AC3-2A24-2B5-B24-B6-A24-B4-C2A24-2AC3-2A24-2A3(4-2A24-BA)165-A24-A4-C2A24-2AC3-BA24-2B5-B24-B6-A24-A4-CAB24-2AC3-BA24-BA5-A24-A6-B24-B198-2A22-AB5-C2A22-2BC5-2A22-BA6-AB22-BA6-BA22-BA5-C2A22-ABC5-BA22-2A6-2A22-2A230-AB22-BA5-CBA22-2BC5-2B22-AB6-BA22-2A6-2A22-BA5-C2B22-2AC5-2A22-BA7-A22-AB231-AB20-2A6-C3B20-2BAC6-2(2A20-2A8-)AB20-2A6-CABA20-3AC6-2A20-2A2(8-2A20-AB)200-ABA18-ABA7-C2BA18-3AC7-3A18-B2A8-2A20-AB8-3A18-3A7-CABA18-ABAC7-BA20-BA8-2A20-AB8-AB20-2B8-AB20-2A169-2B18-2A9-C2A18-ABC9-AB18-AB10-2A18-AB10-BA18-AB9-CAB18-BAC9-BA18-AB10-BA18-2B10-2A18-AB10-2A18-2A10-A20-A10-B20-B107-3A14-2BA11-C3B14-B2AC11-ABA14-3A12-AB16-BA12-3A14-2AB11-CB2A14-2ABC11-AB16-2B11-2AB16-3A10-B2A16-3A10-3A16-A2B10-AB18-AB10-2A18-BA10-2D18-2B9-3D18-3D8-3D18-3D11-3A12-3A13-CA2B12-3BC13-B2A12-3A14-2BA12-3A14-2AB12-3A13-C2AB12-A2BC13-ABA12-B2A13-4A12-2(AB)12-AB2A12-2BAB12-3A14-3A11-B2A16-ABA10-BAB16-2AB10-2D18-2A9-3D18-3D8-3D18-3D12-A2BA8-4A15-CB3A8-2ABAC15-2ABA8-3AB16-2(BA)8-4A16-B2AB8-3AB15-CAB2A8-2BABC15-2ABA8-2ABA16-2(AB)8-2B2A16-2A12-2A16-A14-B108-3D18-3D8-3D18-3D14-2A3B5ABA18-CAB4AB3AB2ABC18-A2B3(AB)3A20-B2A2B4A2BA20-3AB5A3B18-C4AB2A2(BA)2BAC18-B3A2BAB2A2B20-BAB2A2-A2B2A22-A2B2-B2A25-B4-A134-3D29-3D18-4A23-3C2A2BAB2A3C21-AB2AB3A26-4B28-3AB23-3C4ABA2B3C21-2A2B4A25-2B4A26-2B2ABA26-3AB2A27-2ABA28-4B29-2(2D30-)2D59-8C120-8C154-3AB28-4B29-2(2D30-)2D414-2(2D30-)2D15-
