model
size = 25 22 18, scale = 0.05, origin = -y
material 
  colors = A:#F08E00 B:#F5B200 C:#060808 D:#00D E:#9C0 F:#0D1111 G:#CF3 H:#9C3 I:#E64700 J:#020 K:#090D0D L:#918E00 M:#000 N:#050 O:#DAD600 P:#101616 Q:#99C R:#9E6D00 S:#FFFA00 T:#999 U:#6D6B00 V:#040 W:#484700 X:#0F9
voxels
------------------------- ------------------------- ------------------------- ------------------------- ------------------------- ------------------------- ------------------------- ------------------------- ------------------------- ------------R------------ -----------BRB----------- -----------BBB----------- -----------BBB----------- ------------------------- ------------------------- ------------------------- ------------------------- ------------------------- ------------------------- ------------------------- ------------------------- ------------------------- 
------------------------- ------------------------- ------------------------- ------------------------- ------------------------- ------------------------- ----------GGGGG---------- ------------------------- ----------BBBBB---------- ---------BBVAVBB--------- ---------BBAAABB--------- ---------BBAAABB--------- ---------BBAAABB--------- ----------BBBBB---------- ----------BBABB---------- ------------A------------ ------------------------- ------------------------- ------------------------- ------------------------- ------------------------- ------------------------- 
------------------------- ------------------------- ------------------------- ------------------------- ------------------------- ----------GGGGG---------- ----------G---G---------- ---------LGTTTGL--------- --------UBAAAAABU-------- --------RAAAAAAAR-------- --------BAAAAAAAB-------- --------BAAAAAAAB-------- --------BAAAAAAAB-------- --------BBAAAAABB-------- ---------BAAAAAB--------- ----------BAAAB---------- -----------BAB----------- ------------------------- ------------------------- ------------------------- ------------------------- ------------------------- 
------------------------- ------------------------- ------------------------- ------------------------- ----------GGGGG---------- ---------B-----B--------- ---------LAAAAAL--------- --------BAAAAAAAB-------- -------MAAAAAAAAAM------- -------MAAAAAAAAAM------- -------JAAAAAAAAAJ------- -------BAAAAAAAAAB------- -------BAAAAAAAAAB------- -------BAAAAAAAAAB------- --------BAAAAAAAB-------- --------BBAAAAABB-------- ----------BBABB---------- ------------H------------ ------------------------- ------------------------- ------------------------- ------------------------- 
------------------------- ------------------------- ------------------------- ------------------------- ----------BBBBB---------- ---------B-AAA-B--------- --------BAAAAAAAB-------- -------NAAAAAAAAAN------- -------MAAAAAAAAAM------- -------MAAAAAAAAAM------- ------JAAAAAAAAAAAJ------ ------BAAAAAAAAAAAB------ ------BAAAAAAAAAAAB------ -------BAAAAAAAAAB------- -------BAAAAAAAAAB------- --------BAAAAAAAB-------- ---------BAAAAAB--------- ----------ABHBA---------- ------------------------- ------------------------- ------------------------- ------------------------- 
------------------------- ------------------------- ------------------------- ------------------------- ----------EBBBE---------- --------BBAAAAABB-------- -------BAAAAAAAAAB------- -------NAAAAAAAAAN------- ------QAAAAAAAAAAAQ------ ------QAAAAAAAAAAAQ------ ------JAAAAAAAAAAAJ------ ------BAAAAAAAAAAAB------ ------BAAAAAAAAAAAB------ ------BAAAAAAAAAAAB------ ------BAAAAAAAAAAAB------ -------AAAAAAAAAAA------- --------AAAAAAAAA-------- ---------IABHBAI--------- ------------------------- ------------------------- ------------------------- ------------------------- 
------------------------- ------------------------- ---A-----------------A--- ---AA---------------AA--- ---------HEAABEH--------- --------BAAAAAAAB-------- -------BAAAAAAAAAB------- ------NAAAAAAAAAAAN------ ------NAAAAAAAAAAAN------ ------JAAAAAAAAAAAJ------ -----JAAAAAAAAAAAAAJ----- -----EAAAAAAAAAAAAAE----- ------BAAAAAAAAAAAB------ ------BAAAAAAAAAAAB------ ------BAAAAAAAAAAAB------ -------AAAAAAAAAAA------- ------CCAAAAAAAAACC------ -----KCC-IABHBAI-CCK----- -----FKKC-------CKKF----- -----FFF---------FFF----- ------F-----------F------ ------------------------- 
------------------------- ------------------------- ------------------------- ---AAO-------------OAA--- ----BBOOEHEAAAEHEOOBB---- -----WBBAAAAAAAAABBW----- ------BAAAAAAAAAAAB------ ------AAAAAAAAAAAAA------ ----EAAAAAAAAAAAAAAAE---- ----AAAAAAAAAAAAAAAAA---- -----AAAAAAAAAAAAAAA----- -----EAAAAAAAAAAAAAE----- -----EAAAAAAAAAAAAAE----- -----AAAAAAAAAAAAAAA----- ------BAAAAAAAAAAAB------ ------CAAAAAAAAAAAC------ -----CAAAAAAAAAAAAAC----- -----FAACAABHBAACAAF----- -----FAACP-----PCAAF----- -----FAF---------FAF----- -----PC-----------CP----- ------C-----------C------ 
------------------------- ------------------------- ------------------------- ---A-----------------A--- ---------HEAAAEH--------- --------BAAAAAAAB-------- -------BAAAAAAAAAB------- -------AAAAAAAAAAAA------ ------BAAAAAAAAAAAB------ -----AAAAAAAAAAAAAAA----- -----AAAAAAAAAAAAAAA----- -----EAAAAAAAAAAAAAE----- -----EAAAAAAAAAAAAAE----- ------BAAAAAAAAAAAB------ ------BAAAAAAAAAAAB------ ------CAAAAAAAAAAAC------ -----CCAAAAAAAAAAACC----- -----KCCAIABHBAIACCK----- -----FFCC-------CCFF----- -----FFF---------FFF----- ------C-----------C------ ------C-----------C------ 
------------------------- ------------------------- ------------------------- ------------------------- ---------HEAAAEH--------- --------BAAAAAAAB-------- -------BAAAAAAAAAB------- ------AAAAAAAAAAAAA------ ------AAAAAAAAAAAAA------ -----AAAAAAAAAAAAAAA----- -----AAAAAAAAAAAAAAA----- -----EAAAAAAAAAAAAAE----- -----EAAAAAAAAAAAAAE----- ------BAAAAAAAAAAAB------ ------BAAAAAAAAAAAB------ -------AAAAAAAAAAA------- -------CAAAAAAAAAC------- --------CIABHBAIC-------- ------------------------- ------------------------- ------------------------- ------------------------- 
------------------------- ------------------------- ------------------------- ------------------------- ----------EAAAE---------- --------BBAAAAABB-------- -------BAAAAAAAAAB------- ------AAAAAAAAAAAAA------ ------AAAAAAAAAAAAA------ -DDDS-AAAAAAAAAAAAA-SDDD- --DD--BAAAAAAAAAAAB--DD-- ------BAAAAAAAAAAAB------ ------BAAAAAAAAAAAB------ ------BAAAAAAAAAAAB------ ------BAAAAAAAAAAAB------ -------AAAAAAAAAAA------- --------AAAAAAAAA-------- ---------IABHBAI--------- ------------------------- ------------------------- ------------------------- ------------------------- 
------------------------- ------------------------- ------------------------- ------------------------- ----------EAAAE---------- ---------BAAAAAB--------- --------BAAAAAAAB-------- -------AAAAAAAAAAA------- ------AAAAAAAAAAAAA------ XDDDDDAAAAAAAAAAAAADDDDDX --DDDDBAAAAAAAAAAABDDDD-- ------BAAAAAAAAAAAB------ ------BAAAAAAAAAAAB------ ------BAAAAAAAAAAAB------ -------BAAAAAAAAAB------- -------AAAAAAAAAAA------- --------AAAAAAAAA-------- ---------IABHBAI--------- ------------------------- ------------------------- ------------------------- ------------------------- 
------------------------- ------------------------- ------------------------- ------------------------- ------------------------- ----------BABBB---------- --------BLAAAAALB-------- --------BAAAAAAAB-------- -------AAAAAAAAAAA------- -DDDS--AAAAAAAAAAA--SDDD- --DD---AAAAAAAAAAA---DD-- ------BAAAAAAAAAAAB------ -------BAAAAAAAAAB------- -------BAAAAAAAAAB------- -------BAAAAAAAAAB------- --------BAAAAAAAB-------- ---------BBAAABB--------- -----------BHB----------- ------------------------- ------------------------- ------------------------- ------------------------- 
------------------------- ------------------------- ------------------------- ------------------------- ------------------------- -----------BBB----------- ----------BAABB---------- ---------LAAAAAL--------- --------BAAAAAAAB-------- -------BBAAAAAAABB------- -------AAAAAAAAAAA------- -------BAAAAAAAAAB------- -------BAAAAAAAAAB------- --------BAAAAAAAB-------- --------BAAAAAAAB-------- ---------BBAAABB--------- ----------BBBBB---------- ------------------------- ------------------------- ------------------------- ------------------------- ------------------------- 
------------------------- ------------------------- ------------------------- ------------------------- ------------------------- ------------B------------ -----------BBB----------- ----------BBBBB---------- ---------BBAAABB--------- ---------BAAAAAB--------- --------BBAAAAABB-------- --------BBAAAAABB-------- --------BBAAAAABB-------- ---------BBAAABB--------- ---------BBAABBB--------- -----------BBA----------- ------------------------- ------------------------- ------------------------- ------------------------- ------------------------- ------------------------- 
--------A---------------- --------AA--------------- ---------B--------------- ------------------------- ------------------------- ------------B------------ ------------------------- ------------------------- -----------BBB----------- ----------BBBBB---------- ----------BBBBB---------- ----------BBBBB---------- ----------BBBBB---------- -----------BBB----------- -----------AAA----------- ------------------------- ------------------------- ------------------------- ------------------------- ------------------------- ------------------------- ------------------------- 
------------------------- ------------------------- ------------------------- ----------BB------------- ------------------------- ------------------------- -----------B------------- ------------------------- ------------------------- ------------------------- ------------------------- ------------------------- ------------------------- ------------------------- ------------------------- ------------------------- ------------------------- ------------------------- ------------------------- ------------------------- ------------------------- ------------------------- 
------------------------- ------------------------- ------------------------- ------------------------- -----------B------------- ----------BB------------- ------------------------- ------------------------- ------------------------- ------------------------- ------------------------- ------------------------- ------------------------- ------------------------- ------------------------- ------------------------- ------------------------- ------------------------- ------------------------- ------------------------- ------------------------- ------------------------- 
