model
size = 18 22 25, scale = 0.05, origin = -y
material 
  colors = A:#800 B:#E00 C:#060808 D:#C63 E:#200 F:#0D1111 G:#EEE H:#500 I:#400 J:#888 K:#000 L:#090D0D M:#BBB N:#08B600 O:#000124 P:#F6F Q:#C30 R:#101616 S:#99C T:#A00 U:#F3C V:#444 W:#FC0 X:#484700
voxels
------------------ ------------------ ------------------ ------------------ ------------------ ------------------ ------------------ ------------------ ------------------ -----------Q------ ------------------ ------------------ ------------------ ------------------ ------------------ ------------------ ------------------ ------------------ ------------------ ------------------ ------------------ ------------------ 
------------------ ------------------ ------------------ ------------------ ------------------ ------------------ ------------------ ------------------ ------------------ ----------DDD----- ------------------ ------------------ ------------------ ------------------ ------------------ ------------------ ------------------ ------------------ ------------------ ------------------ ------------------ ------------------ 
------------------ ------------------ ------------------ ------------------ ------------------ ------------------ ------------------ ------------------ ------------------ ----------DDD----- ----------DDD----- ------------------ ------------------ ------------------ ------------------ ------------------ ------------------ ------------------ ------------------ ------------------ ------------------ ------------------ 
------------------ ------------------ ------A----------- ------AAA--------- ------------------ ------------------ ------------------ ------------------ ------------------ ----------DDD----- ----------DDD----- ------------------ ------------------ ------------------ ------------------ ------------------ ------------------ ------------------ ------------------ ------------------ ------------------ ------------------ 
------------------ ------------------ ------------------ ------AA---------- -------B---------- ------------------ ------------------ ------------------ -------E---------- -------A--QDQ----- -----------D------ ------------------ ------------------ ------------------ ------------------ ------------------ ------------------ ------------------ ------------------ ------------------ ------------------ ------------------ 
------------------ ------------------ ------------------ -------P---------- -------B---------- -------X---------- ------------------ ------------------ -------A---------- -------AAA-D------ ------KAAA-D------ ------EEEE-------- -------EEE-------- -------A---------- ------------------ ------------------ -------CC--------- ------LFL--------- ------FFF--------- ------FFF--------- -------R---------- ------------------ 
------------------ ------------------ ------------------ ------------------ -------P---------- -------B---------- -------B---------- ------OAAAA------- -----SOABAAA------ -----SKAAAAA------ ----KKAAAABB------ ----BBAAAABBB----- ----BBBAAABB------ -----BBABBBB------ -----BBBBBB------- -------CC--------- ------CAC--------- ------CAC--------- ------LAF--------- ------FAF--------- ------FCC--------- -------CC--------- 
------------------ ------------------ ------------------ ------------------ -------P---------- -------B---------- -----BBABBB------- ----OOAAAAAA------ ---NNAAAAAAAA----- ---NNAAAAAAAAB---- ---KAAAAAAAAAA---- ---BAAAAAAAAAB---- ---BAAAAAAAABB---- ---BBAAAAAAAB----- ----BAAAAAABB----- -----AAAAAAA------ ------CAAC-------- ------CAC--------- ------LAC--------- ------FFF--------- ------------------ ------------------ 
------------------ ------------------ ------------------ ------------------ -------E---------- -----BBABBB------- ----BAAAAAABB----- ---BAAAAAAAAB----- --JAAAAAAAAAAB---- --TAAAAAAAAAAB---- --BAAAAAAAAAAAB--- --BAAAAAAAAAAAB--- --BAAAAAAAAAAAB--- --BAAAAAAAAAAB---- ---BAAAAAAAAAB---- ---BBAAAAAAAB----- -----AAAAAAA------ -------CAC-------- ------CCC--------- ------------------ ------------------ ------------------ 
------------------ ------------------ ------------------ ------------------ ------HHHH-------- ---BBBAAAABB------ ---MAAAAAAAAM----- --MAAAAAAAAAAM---- --BAAAAAAAAAAAB--- -BAAAAAAAAAAAAB--- -BAAAAAAAAAAAAB--- -BAAAAAAAAAAAAB--- -BAAAAAAAAAAAAB--- --BAAAAAAAAAAAB--- --BAAAAAAAAAAAB--- ---BAAAAAAAAAB---- ----BAAAAAAAB----- -----IIAIIII------ -------R---------- ------------------ ------------------ ------------------ 
------------------ ------------------ ------------------ ------------------ ---GBEEEEEEE------ --G--AAAAAAAB----- -GGAAAAAAAAAAB---- --GAAAAAAAAAAAB--- -BAAAAAAAAAAAAB--- -BAAAAAAAAAAAAAB-- -BAAAAAAAAAAAAAB-- -BAAAAAAAAAAAAAB-- -BAAAAAAAAAAAAAB-- -BAAAAAAAAAAAAB--- -BAAAAAAAAAAAAB--- --BAAAAAAAAAAB---- ---BAAAAAAAABB---- ----AAAAAAAA------ ------------------ ------------------ ------------------ ------------------ 
------------------ ------------------ ------------------ ------------------ ---GBBAAAAAA------ --G-AAAAAAAABB---- -G-AAAAAAAAAABB--- --UAAAAAAAAAAAB--- -BAAAAAAAAAAAAAB-- -WAAAAAAAAAAAAAB-- BAAAAAAAAAAAAAAB-- BAAAAAAAAAAAAAAB-- BAAAAAAAAAAAAAAB-- -BAAAAAAAAAAAAAB-- -BAAAAAAAAAAAABA-- --AAAAAAAAAAAAA--- --BBAAAAAAAAAB---- ----BBBBBBBBB----- ------------------ ------------------ ------------------ ------------------ 
------------------ ------------------ ------------------ ------------------ ---GBBAAAAAA------ --G-AAAAAAAABBBJ-- -G-AAAAAAAAAAAB--- --UAAAAAAAAAAAB--- -BAAAAAAAAAAAAAB-- TAAAAAAAAAAAAAAB-- TAAAAAAAAAAAAAAB-- BAAAAAAAAAAAAAAB-- BAAAAAAAAAAAAAAB-- -BAAAAAAAAAAAAAB-- -AAAAAAAAAAAAAAA-- -AAAAAAAAAAAAAB--- --AAAAAAAAAAAB---- ---HHHHHHHHHH----- ------------------ ------------------ ------------------ ------------------ 
------------------ ------------------ ------------------ ----------------J- ---GBBAAAAAA-----J --G-AAAAAAAAAB---J -G-AAAAAAAAAAAB-J- --UAAAAAAAAAAAB--- -BAAAAAAAAAAAAAB-- -WAAAAAAAAAAAAAB-- BAAAAAAAAAAAAAAB-- BAAAAAAAAAAAAAAB-- BAAAAAAAAAAAAAAB-- -BAAAAAAAAAAAAAB-- -BAAAAAAAAAAAAAA-- --AAAAAAAAAAAAB--- --BBAAAAAAAAAB---- ----BBBBBBBBB----- ------------------ ------------------ ------------------ ------------------ 
------------------ ------------------ ------------------ ----------------J- ---GBEEEEEEE------ --G--AAAAAAAB----J -GGAAAAAAAAAAB---- --GAAAAAAAAAAAB--- -BAAAAAAAAAAAAB--- -BAAAAAAAAAAAAAB-- -BAAAAAAAAAAAAAB-- -BAAAAAAAAAAAAAB-- -BAAAAAAAAAAAAAB-- -BAAAAAAAAAAAAB--- -BAAAAAAAAAAAAB--- --BAAAAAAAAAAB---- ---BAAAAAAAABB---- ----AAAAAAAA------ ------------------ ------------------ ------------------ ------------------ 
------------------ ---------------V-- ---------------J-- ------------------ ------HHHH-------- ---BBBAAAABB------ ---MAAAAAAAAM----- --MAAAAAAAAAAM---- --BAAAAAAAAAAAB--- -BAAAAAAAAAAAAB--- -BAAAAAAAAAAAAB--- -BAAAAAAAAAAAAB--- -BAAAAAAAAAAAAB--- --BAAAAAAAAAAAB--- --BAAAAAAAAAAAB--- ---BAAAAAAAAAB---- ----BAAAAAAAB----- -----IIAIIII------ -------R---------- ------------------ ------------------ ------------------ 
---------------V-- ---------------V-- ------------------ ------------------ -------E---------- -----BBABBB------- ----BAAAAAABB----- ---BAAAAAAAAB----- --JAAAAAAAAAAB---- --TAAAAAAAAAAB---- --BAAAAAAAAAAAB--- --BAAAAAAAAAAAB--- --BAAAAAAAAAAAB--- --BAAAAAAAAAAB---- ---BAAAAAAAAAB---- ---BBAAAAAAAB----- -----AAAAAAA------ -------CAC-------- ------CCC--------- ------------------ ------------------ ------------------ 
------------------ ------------------ ------------------ ------------------ -------P---------- -------B---------- -----BBABBB------- ----OOAAAAAA------ ---NNAAAAAAAA----- ---NNAAAAAAAAB---- ---KAAAAAAAAAA---- ---BAAAAAAAAAB---- ---BAAAAAAAABB---- ---BBAAAAAAAB----- ----BAAAAAABB----- -----AAAAAAA------ ------CAAC-------- ------CAC--------- ------LAC--------- ------FFF--------- ------------------ ------------------ 
------------------ ------------------ ------------------ ------------------ -------P---------- -------B---------- -------B---------- ------OA-AA------- -----SOABAAA------ -----SKAAAAA------ ----KKAAAABB------ ----BBAAAABBB----- ----BBBAAABB------ -----BBABBBB------ -----BBBBBB------- -------CC--------- ------CAC--------- ------CAC--------- ------LAF--------- ------FAF--------- ------FCC--------- -------CC--------- 
------------------ ------------------ ------------------ -------P---------- -------B---------- -------X---------- ------------------ ------------------ -------A---------- -------AAA-D------ ------KAAA-D------ ------EEEE-------- -------EEE-------- -------A---------- ------------------ ------------------ -------CC--------- ------LFL--------- ------FFF--------- ------FFF--------- -------R---------- ------------------ 
------------------ ------------------ ------------------ ------AA---------- -------B---------- ------------------ ------------------ ------------------ -------E---------- -------A--QDQ----- -----------D------ ------------------ ------------------ ------------------ ------------------ ------------------ ------------------ ------------------ ------------------ ------------------ ------------------ ------------------ 
------------------ ------------------ ------A----------- ------AAA--------- ------------------ ------------------ ------------------ ------------------ ------------------ ----------DDD----- ----------DDD----- ------------------ ------------------ ------------------ ------------------ ------------------ ------------------ ------------------ ------------------ ------------------ ------------------ ------------------ 
------------------ ------------------ ------------------ ------------------ ------------------ ------------------ ------------------ ------------------ ------------------ ----------DDD----- ----------DDD----- ------------------ ------------------ ------------------ ------------------ ------------------ ------------------ ------------------ ------------------ ------------------ ------------------ ------------------ 
------------------ ------------------ ------------------ ------------------ ------------------ ------------------ ------------------ ------------------ ------------------ ----------DDD----- ------------------ ------------------ ------------------ ------------------ ------------------ ------------------ ------------------ ------------------ ------------------ ------------------ ------------------ ------------------ 
------------------ ------------------ ------------------ ------------------ ------------------ ------------------ ------------------ ------------------ ------------------ -----------Q------ ------------------ ------------------ ------------------ ------------------ ------------------ ------------------ ------------------ ------------------ ------------------ ------------------ ------------------ ------------------ 
