model
size = 18 22 25, scale = 0.05, origin = -y
material 
  colors = A:#15B90D B:#19DC06 C:#010 D:#C0C E:#119613 F:#393 G:#012400 H:#CF3 I:#050 J:#034800 K:#1DFF00 L:#000 M:#6C3 N:#060808 O:#CC9 P:#6F3 Q:#996 R:#303 S:#909 T:#F5B200 U:#101616 V:#070 W:#060 X:#040 Y:#3DDA00 Z:#4A0525
voxels
------------------ ------------------ ------------------ ------------------ ------------------ ------------------ ------------------ ------------------ ------------------ -----------Z------ ------------------ ------------------ ------------------ ------------------ ------------------ ------------------ ------------------ ------------------ ------------------ ------------------ ------------------ ------------------ 
------------------ ------------------ ------------------ ------------------ ------------------ ------------------ ------------------ ------------------ ------------------ ----------DDD----- ------------------ ------------------ ------------------ ------------------ ------------------ ------------------ ------------------ ------------------ ------------------ ------------------ ------------------ ------------------ 
------------------ ------------------ ------------------ ------------------ ------------------ ------------------ ------------------ ------------------ ------------------ ----------DDD----- ----------DDD----- ------------------ ------------------ ------------------ ------------------ ------------------ ------------------ ------------------ ------------------ ------------------ ------------------ ------------------ 
------------------ ------------------ ------------------ ------AAA--------- ------------------ ------------------ ------------------ ------------------ ------------------ ----------DDD----- ----------DDD----- ------------------ ------------------ ------------------ ------------------ ------------------ ------------------ ------------------ ------------------ ------------------ ------------------ ------------------ 
------------------ ------------------ ------------------ ------AA---------- -------B---------- ------------------ ------------------ ------------------ -------F---------- -------A--SDS----- -----------D------ ------------------ ------------------ ------------------ ------------------ ------------------ ------------------ ------------------ ------------------ ------------------ ------------------ ------------------ 
------------------ ------------------ ------------------ -------M---------- -------B---------- -------X---------- ------------------ -------E---------- -------A---------- -------AAA-D------ ------AAAA-D------ ------FFFF-------- -------FFF-------- -------A---------- ------------------ ------------------ -------CC--------- ------JGJ--------- ------GGG--------- ------GGG--------- -------U---------- ------------------ 
------------------ ------------------ ------------------ ------------------ -------M---------- -------B---------- -------B---------- ------OAAAA------- -----QQABAAA------ -----AAAAAAA------ ----BBAAAABB------ ----BBAAAABBB----- ----BBBAAABB------ -----BBABBBB------ -----EEEEEE------- -------CC--------- ------CAC--------- ------CAC--------- ------JAG--------- ------GAG--------- ------GCC--------- -------CC--------- 
------------------ ------------------ ------------------ ------------------ -------M---------- -------B---------- -----BBABBB------- ----OOAAAAAA------ ---LLAAAAAAAA----- ---LLAAAAAAAAB---- ---AAAAAAAAAAA---- ---BAAAAAAAAAB---- ---BAAAAAAAABB---- ---BBAAAAAAAB----- ----BAAAAAABB----- -----AAAAAAA------ ------CAAC-------- ------CAC--------- ------JAC--------- ------GGG--------- ------------------ ------------------ 
------------------ ------------------ ------------------ ------------------ -------F---------- -----BBABBB------- ----BAAAAAABB----- ---BAAAAAAAAB----- --VAAAAAAAAAAB---- --WAAAAAAAAAAB---- --BAAAAAAAAAAAB--- --BAAAAAAAAAAAB--- --BAAAAAAAAAAAB--- --BAAAAAAAAAAB---- ---BAAAAAAAAAB---- ---BBAAAAAAAB----- -----AAAAAAA------ -------CAC-------- ------NNN--------- ------------------ ------------------ ------------------ 
------------------ ------------------ ------------------ ------------------ ------EEEE-------- ---BBBAAAABB------ ---KAAAAAAAAK----- --KAAAAAAAAAAK---- --BAAAAAAAAAAAB--- -BAAAAAAAAAAAAB--- -BAAAAAAAAAAAAB--- -BAAAAAAAAAAAAB--- -BAAAAAAAAAAAAB--- --BAAAAAAAAAAAB--- --BAAAAAAAAAAAB--- ---BAAAAAAAAAB---- ----BAAAAAAAB----- -----IIAIIII------ -------R---------- ------------------ ------------------ ------------------ 
------------------ ------------------ ------------------ ------------------ ---HBFFFFFFF------ --H--AAAAAAAB----- -HHAAAAAAAAAAB---- --HAAAAAAAAAAAB--- -PAAAAAAAAAAAAB--- -PAAAAAAAAAAAAAB-- -BAAAAAAAAAAAAAB-- -BAAAAAAAAAAAAAB-- -BAAAAAAAAAAAAAB-- -BAAAAAAAAAAAAB--- -BAAAAAAAAAAAAB--- --BAAAAAAAAAAB---- ---BAAAAAAAABB---- ----AAAAAAAA------ ------------------ ------------------ ------------------ ------------------ 
------------------ ------------------ ------------------ ------------------ ---HBBBAAAAA------ --H-AAAAAAAABB---- -H-AAAAAAAAAABB--- --TAAAAAAAAAAAB--- -PAAAAAAAAAAAAAB-- -RAAAAAAAAAAAAAB-- BAAAAAAAAAAAAAAB-- BAAAAAAAAAAAAAAB-- BAAAAAAAAAAAAAAB-- -BAAAAAAAAAAAAAB-- -BAAAAAAAAAAAABA-- --AAAAAAAAAAAAA--- --BBAAAAAAAAAB---- ----BBBBBBBBB----- ------------------ ------------------ ------------------ ------------------ 
------------------ ------------------ ------------------ ------------------ ---HBBAAAAAA------ --H-AAAAAAAABBBBB- -H-AAAAAAAAAAAB--- --TAAAAAAAAAAAB--- -QAAAAAAAAAAAAAB-- YAAAAAAAAAAAAAAB-- YAAAAAAAAAAAAAAB-- BAAAAAAAAAAAAAAB-- BAAAAAAAAAAAAAAB-- -BAAAAAAAAAAAAAB-- -AAAAAAAAAAAAAAA-- -AAAAAAAAAAAAAB--- --AAAAAAAAAAAB---- ---EEEEEEEEEE----- ------------------ ------------------ ------------------ ------------------ 
------------------ ------------------ ------------------ ------------------ ---HBBAAAAAA----B- --H-AAAAAAAAAB---- -H-AAAAAAAAAAAB--- --TAAAAAAAAAAAB--- -PAAAAAAAAAAAAAB-- -RAAAAAAAAAAAAAB-- BAAAAAAAAAAAAAAB-- BAAAAAAAAAAAAAAB-- BAAAAAAAAAAAAAAB-- -BAAAAAAAAAAAAAB-- -BAAAAAAAAAAAAAA-- --AAAAAAAAAAAAB--- --BBAAAAAAAAAB---- ----AAAAAAAAA----- ------------------ ------------------ ------------------ ------------------ 
------------------ ------------------ ----------------B- ---------------B-- ---HBFFFFFFF------ --H--AAAAAAAB----- -HHAAAAAAAAAAB---- --HAAAAAAAAAAAB--- -PAAAAAAAAAAAAB--- -PAAAAAAAAAAAAAB-- -BAAAAAAAAAAAAAB-- -BAAAAAAAAAAAAAB-- -BAAAAAAAAAAAAAB-- -BAAAAAAAAAAAAB--- -BAAAAAAAAAAAAB--- --BAAAAAAAAAAB---- ---BAAAAAAAABB---- ----AAAAAAAA------ ------------------ ------------------ ------------------ ------------------ 
------------------ ----------------B- ----------------B- ------------------ ------EEEE-------- ---BBBAAAABB------ ---KAAAAAAAAK----- --KAAAAAAAAAAK---- --BAAAAAAAAAAAB--- -BAAAAAAAAAAAAB--- -BAAAAAAAAAAAAB--- -BAAAAAAAAAAAAB--- -BAAAAAAAAAAAAB--- --BAAAAAAAAAAAB--- --BAAAAAAAAAAAB--- ---BAAAAAAAAAB---- ----BAAAAAAAB----- -----IIAIIII------ -------R---------- ------------------ ------------------ ------------------ 
-----------------B ----------------B- ------------------ ------------------ -------F---------- -----BBABBB------- ----BAAAAAABB----- ---BAAAAAAAAB----- --VAAAAAAAAAAB---- --WAAAAAAAAAAB---- --BAAAAAAAAAAAB--- --BAAAAAAAAAAAB--- --BAAAAAAAAAAAB--- --BAAAAAAAAAAB---- ---BAAAAAAAAAB---- ---BBAAAAAAAB----- -----AAAAAAA------ -------CAC-------- ------NNN--------- ------------------ ------------------ ------------------ 
------------------ ------------------ ------------------ ------------------ -------M---------- -------B---------- -----BBABBB------- ----OOAAAAAA------ ---LLAAAAAAAA----- ---LLAAAAAAAAB---- ---AAAAAAAAAAA---- ---BAAAAAAAAAB---- ---BAAAAAAAABB---- ---BBAAAAAAAB----- ----BAAAAAABB----- -----AAAAAAA------ ------CAAC-------- ------CAC--------- ------JAC--------- ------GGG--------- ------------------ ------------------ 
------------------ ------------------ ------------------ ------------------ -------M---------- -------B---------- -------B---------- ------OAAAA------- -----QQABAAA------ -----AAAAAAA------ ----BBAAAABB------ ----BBAAAABBB----- ----BBBAAABB------ -----BBABBBB------ -----EEEEEE------- -------CC--------- ------CAC--------- ------CAC--------- ------JAG--------- ------GAG--------- ------GCC--------- -------CC--------- 
------------------ ------------------ ------------------ -------M---------- -------B---------- -------X---------- ------------------ -------E---------- -------A---------- -------AAA-D------ ------AAAA-D------ ------FFFF-------- -------FFF-------- -------A---------- ------------------ ------------------ -------CC--------- ------JGJ--------- ------GGG--------- ------GGG--------- -------U---------- ------------------ 
------------------ ------------------ ------------------ ------AA---------- -------B---------- ------------------ ------------------ ------------------ -------F---------- -------A--SDS----- -----------D------ ------------------ ------------------ ------------------ ------------------ ------------------ ------------------ ------------------ ------------------ ------------------ ------------------ ------------------ 
------------------ ------------------ ------------------ ------AAA--------- ------------------ ------------------ ------------------ ------------------ ------------------ ----------DDD----- ----------DDD----- ------------------ ------------------ ------------------ ------------------ ------------------ ------------------ ------------------ ------------------ ------------------ ------------------ ------------------ 
------------------ ------------------ ------------------ ------------------ ------------------ ------------------ ------------------ ------------------ ------------------ ----------DDD----- ----------DDD----- ------------------ ------------------ ------------------ ------------------ ------------------ ------------------ ------------------ ------------------ ------------------ ------------------ ------------------ 
------------------ ------------------ ------------------ ------------------ ------------------ ------------------ ------------------ ------------------ ------------------ ----------DDD----- ------------------ ------------------ ------------------ ------------------ ------------------ ------------------ ------------------ ------------------ ------------------ ------------------ ------------------ ------------------ 
------------------ ------------------ ------------------ ------------------ ------------------ ------------------ ------------------ ------------------ ------------------ -----------Z------ ------------------ ------------------ ------------------ ------------------ ------------------ ------------------ ------------------ ------------------ ------------------ ------------------ ------------------ ------------------ 
