model
size = 15 15 32, scale = 0.05, origin = -y
material 
  colors = A:#EEE B:#69C C:#9CF D:#99C E:#CCF F:#99F G:#66C H:#100 I:#669 J:#BBB K:#CFF L:#222 M:#111 N:#9CC O:#FFF P:#001 Q:#CCC R:#336 S:#555 T:#333
voxels
96-2EA12-2E2A11-2E2A12-EA146-3K2A9-4C3A8-4C4A7-4G2(4A7-4B)4A8-3B3A10-2C2A87-2A10-4E3A7-5E4A6-5B5A5-5C5A4-6G5A4-6B5A5-5G5A5-5B4A7-4F4A8-3C2A69-4E3A7-5C4A5-6C5A4-2(6B6A3-)6G6A3-6N6A3-6F6A3-6B5A5-5B5A6-4B4A8-3E2A40-5A8-5E4A5-6B5A4-6C6A2-7B6A2-7I6A2-14A-13A2-7B2(6A3-6B)5A5-5D5A6-4C3A11-A26-4E3A7-5D5A4-6B6A2-7B6A2-7I7A-7B2(7A-7I)7A-7B7A-7D6A3-6E6A3-6G5A5-5C4A8-3E2A11-3A10-4E4A6-5F5A4-6F6A2-7D6A2-7B7A8L2(7A8H)7A-7T7A-7C7A-7E6A3-6C5A5-5F4A8-3E3A10-4A9-4E4A5-6B5A4-6B6A2-7G7A-7D3(7A8H)7A8P7A-7F7A-7C6A3-6C6A4-5F5A6-4D3A10-4A9-4J4A5-6G5A4-6D6A2-7F6A2-7B7A8M3(7A8H)7A-7F7A-7E6A3-6B6A4-5D5A7-3E3A11-2A10-4O4A6-5B5A4-6G6A2-7B6A2-7C7A-7B2(7A8L)7A-7B2(7A-7C)6A3-6C5A5-5C4A8-3O3A24-6A7-5D4A5-6I5A4-6F2(6A2-7B)7A-7B7A-7F7A-7C7A-7K6A3-6D6A4-5E5A6-4E4A9-4A26-4A9-4E4A6-5C5A4-6C5A4-6B6A2-7I6A2-7D6A2-7C6A2-7G6A3-6D6A3-6C5A5-5D4A8-3E3A54-5A9-4J4A6-5F5A4-6F2(5A4-6B)6A3-6C6A3-6B5A5-5G5A5-5C4A7-4Q3A11-2A71-5A9-4Q3A7-5J4A6-5N4A6-2(5D5A5-)5I4A7-4D4A8-3J3A11-2A103-A12-5A10-3O3A8-4J3A9-3J3A9-3Q3A10-4A582-O12-3E2A10-3E3A8-4B3A9-3F3A9-3E3A10-2E2A115-3E2A9-4K3A7-5F4A6-5C4A6-5I5A5-5B5A5-5G4A7-4B4A8-3D3A11-EA71-3E2A9-4E4A6-5C5A4-6G5A4-6C5A4-6G6A3-6D6A3-6B2(5A5-5B)4A7-4F3A11-EA42-4A9-4K4A6-5C5A4-6C5A4-6D6A2-7I6A2-7B2(6A2-7D)6A3-6F6A3-6G5A5-5B4A8-3E3A39-6A7-5C4A5-6G5A4-6I6A2-7G6A2-7B7A-7E7A-7C2(7A-7B)6A3-6B6A4-5D5A6-4B4A9-2O2A12-2A10-4E4A6-5B5A4-6B6A2-7I6A2-7B7A-7S2(7A8M)7A-7I7A-7D7A-7C6A3-6D5A5-5D4A8-3Q3A10-4A9-4E4A5-6C5A4-6B6A2-7F6A2-7B4(7A8H)7A-7F7A-7K6A3-6C6A4-5F5A7-3J3A10-4A9-4J4A5-6D5A4-6D6A2-7B7A-7G4(7A8H)7A-7D7A-7C6A3-6N6A4-5F5A6-4J2(3A10-)4E4A6-5B5A4-6B6A2-7D6A2-7F7A8R7A8H7A8P7A-7L7A-7C7A-7E6A3-6E5A5-5C4A8-3E3A23-7A7-5D5A4-6I2(6A2-7C)7A-7D2(7A-7B)7A-7F7A-7K6A3-6D6A3-6K5A5-5E4A8-5A25-5A8-5J4A5-6G5A4-6C6A2-7B6A2-7D6A2-7G7A-7E6A2-7G6A3-6E6A3-6C5A5-5C5A6-4E3A11-A41-7A7-5D4A5-6D5A4-3(6B6A3-)6C2(6A3-6G)5A5-5C5A6-4D4A8-5A57-2A10-7A7-5E4A6-5F5A5-5D5A4-6D5A4-6F5A5-5G5A5-5D4A7-4J4A8-3O2A100-5A9-4J3A8-3(4D4A7-)4D4A8-3J3A10-4A146-3A12-4A11-4A12-2A81-
