model
size = 15 15 29, scale = 0.05, origin = -y
material 
  colors = A:#EEE B:#633 C:#963 D:#996 E:#100 F:#222 G:#663 H:#966 I:#333 J:#BBB K:#111 L:#999 M:#555 N:#C99 O:#CCC P:#C96 Q:#330 R:#444 S:#CC9 T:#888 U:#010 V:#FFF W:#993 X:#300 Y:#666 Z:#AAA
voxels
--------------- --------------- --------------- --------------- -------A------- -----AAAAA----- -----VVVVAA---- ----JJJJJAA---- -----JJJJAA---- -----OOOOAA---- ------AAAA----- --------------- --------------- --------------- --------------- 
--------------- --------------- --------------- -----AAAAA----- ----JJJJJAA---- ---MMMMMMAAA--- ---XXXXXXAAA--- ---BBBBBBAAAA-- ---IIIIIIAAAA-- ---BBBBBBAAA--- ----FFFFAAAA--- -----TTTAAA---- -------AA------ --------------- --------------- 
--------------- --------------- -----AAAAA----- ----LLLLAAAA--- ---FFFFFAAAAA-- --CCCCCCAAAAA-- --BBBBBBAAAAA-- --BBBBBBAAAAAA- --BBBBBBAAAAAA- --GGGGGGAAAAA-- ---BBBBBAAAAA-- ---BBBBBAAAA--- ----MMMMAAA---- -------AA------ --------------- 
--------------- ------AAAA----- ----JJJJAAAA--- ---FFFFFAAAAA-- --GGGGGGAAAAA-- --DDDDDDAAAAAA- -PPPPPPPAAAAAA- -GGGGGGGAAAAAA- -BBBBBBBAAAAAA- -BBBBBBBAAAAAA- --BBBBBBAAAAAA- --GGGGGGAAAAA-- ---BBBBBAAAA--- -----MMMAAA---- --------------- 
--------------- -----AAAAAA---- ---IIIIIAAAA--- --HHHHHHAAAAA-- --HHHHHHAAAAAA- -NNNNNNNAAAAAA- -DDDDDDDAAAAAAA -DDDDDDDAAAAAAA -CCCCCCCAAAAAAA -CCCCCCCAAAAAAA -CCCCCCCAAAAAA- --BBBBBBAAAAAA- ---BBBBBAAAAA-- ----KKKKAAAA--- ------JJAA----- 
-------AA------ ----VVVVAAAA--- ---FFFFFAAAAA-- --HHHHHHAAAAAA- -LLLLLLLAAAAAA- -PPPPPPPAAAAAAA -PPPPPPPAAAAAAA BBBBBBBBAAAAAAA QQQQQQQQAAAAAAA -OOOOOOOAAAAAAA -SSSSSSSAAAAAAA -CCCCCCCAAAAAA- --BBBBBBAAAAA-- ---FFFFFAAAA--- -----YYYAAA---- 
------AAAA----- ----LLLLAAAA--- --GGGGGGAAAAA-- --DDDDDDAAAAAA- -NNNNNNNAAAAAA- -DDDDDDDAAAAAAA QQQQQQQQAAAAAAA EEEEEEEEAAAAAAA EEEEEEEEAAAAAAA MMMMMMMMAAAAAAA -CCCCCCCAAAAAAA -CCCCCCCAAAAAA- --BBBBBBAAAAAA- ---BBBBBAAAAA-- -----RRRAAA---- 
------AAAA----- ----LLLLAAAA--- --CCCCCCAAAAA-- --DDDDDDAAAAAA- -NNNNNNNAAAAAAA -DDDDDDDAAAAAAA EEEEEEEEAAAAAAA EEEEEEEEAAAAAAA EEEEEEEEAAAAAAA MMMMMMMMAAAAAAA -OOOOOOOAAAAAAA -JJJJJJJAAAAAA- --HHHHHHAAAAAA- ---BBBBBAAAAA-- ----IIIIAAA---- 
------AAA------ ----ZZZZAAAA--- ---BBBBBAAAAA-- --DDDDDDAAAAAA- -SSSSSSSAAAAAA- -DDDDDDDAAAAAAA BBBBBBBBAAAAAAA UUUUUUUUAAAAAAA EEEEEEEEAAAAAAA -LLLLLLLAAAAAAA -AAAAAAAAAAAAAA -AAAAAAAAAAAAA- --DDDDDDAAAAA-- ---IIIIIAAAA--- -----RRRAAA---- 
--------------- ----AAAAAAA---- ---FFFFFAAAAA-- --HHHHHHAAAAAA- -NNNNNNNAAAAAA- -DDDDDDDAAAAAAA -WWWWWWWAAAAAAA -GGGGGGGAAAAAAA -CCCCCCCAAAAAAA -CCCCCCCAAAAAAA -JJJJJJJAAAAAA- --OOOOOOAAAAAA- --IIIIIIAAAAA-- ---KKKKKAAAA--- -----YYYAA----- 
--------------- -----AAAAA----- ---RRRRRAAAA--- --BBBBBBAAAAA-- --HHHHHHAAAAAA- -HHHHHHHAAAAAA- -CCCCCCCAAAAAA- -CCCCCCCAAAAAAA -CCCCCCCAAAAAA- -GGGGGGGAAAAAA- --GGGGGGAAAAAA- --BBBBBBAAAAA-- ---KKKKKAAAAA-- ----EEEEAAA---- -------V------- 
--------------- --------------- ----AAAAAAA---- ---FFFFFAAAA--- --BBBBBBAAAAA-- --BBBBBBAAAAAA- --FFFFFFAAAAAA- --BBBBBBAAAAAA- --BBBBBBAAAAAA- --BBBBBBAAAAAA- --BBBBBBAAAAA-- ---FFFFFAAAAA-- ----EEEEAAAA--- -----TTTAA----- --------------- 
--------------- --------------- -------AA------ ----AAAAAAA---- ---FFFFFAAAA--- ---FFFFFAAAAA-- ---BBBBBAAAAA-- --BBBBBBAAAAA-- --IIIIIIAAAAA-- ---FFFFFAAAAA-- ---KKKKKAAAA--- ----EEEEAAAA--- -----TTTAA----- --------------- --------------- 
--------------- --------------- --------------- --------------- -----AAAAA----- ----LLLLAAA---- ----KKKKAAAA--- ----KKKKAAAA--- ----KKKKAAAA--- ----EEEEAAAA--- -----RRRAAA---- ------AAAA----- --------------- --------------- --------------- 
--------------- --------------- --------------- --------------- -------A------- -----AAAAA----- -----VAAAAA---- ----JJAAAAA---- -----JAAAAA---- -----OOAAAA---- ------AAAA----- --------------- --------------- --------------- --------------- 
--------------- --------------- --------------- -----AAAAA----- ----JJJJJAA---- ---MMMMMMAAA--- ---XXXXXXAAA--- ---BBBBBBAAAA-- ---IIIIIIAAAA-- ---BBBBBBAAA--- ----FFFFAAAA--- -----TTTAAA---- -------AA------ --------------- --------------- 
--------------- --------------- -----AAAAA----- ----LLLLAAAA--- ---FFFFFAAAAA-- --CCCCCCAAAAA-- --BBBBBBAAAAA-- --BBBBBBAAAAAA- --BBBBBBAAAAAA- --GGGGGGAAAAA-- ---BBBBBAAAAA-- ---BBBBBAAAA--- ----MMMMAAA---- -------AA------ --------------- 
--------------- ------AAAA----- ----JJJJAAAA--- ---FFFFFAAAAA-- --GGGGGGAAAAA-- --DDDDDDAAAAAA- -PPPPPPPAAAAAA- -GGGGGGGAAAAAA- -BBBBBBBAAAAAA- -BBBBBBBAAAAAA- --BBBBBBAAAAAA- --GGGGGGAAAAA-- ---BBBBBAAAA--- -----MMMAAA---- --------------- 
--------------- -----AAAAAA---- ---IIIIIAAAA--- --HHHHHHAAAAA-- --HHHHHHAAAAAA- -NNNNNNNAAAAAA- -DDDDDDDAAAAAAA -DDDDDDDAAAAAAA -CCCCCCCAAAAAAA -CCCCCCCAAAAAAA -CCCCCCCAAAAAA- --BBBBBBAAAAAA- ---BBBBBAAAAA-- ----KKKKAAAA--- ------JJAA----- 
-------AA------ ----VVVVAAAA--- ---FFFFFAAAAA-- --HHHHHHAAAAAA- -LLLLLLLAAAAAA- -PPPPPPPAAAAAAA -PPPPPPPAAAAAAA BBBBBBBBAAAAAAA QQQQQQQQAAAAAAA -OOOOOOOAAAAAAA -SSSSSSSAAAAAAA -CCCCCCCAAAAAA- --BBBBBBAAAAA-- ---FFFFFAAAA--- -----YYYAAA---- 
------AAAA----- ----LLLLAAAA--- --GGGGGGAAAAA-- --DDDDDDAAAAAA- -NNNNNNNAAAAAA- -DDDDDDDAAAAAAA QQQQQQQQAAAAAAA EEEEEEEEAAAAAAA EEEEEEEEAAAAAAA MMMMMMMMAAAAAAA -CCCCCCCAAAAAAA -CCCCCCCAAAAAA- --BBBBBBAAAAAA- ---BBBBBAAAAA-- -----RRRAAA---- 
------AAAA----- ----LLLLAAAA--- --CCCCCCAAAAA-- --DDDDDDAAAAAA- -NNNNNNNAAAAAAA -DDDDDDDAAAAAAA EEEEEEEEAAAAAAA EEEEEEEEAAAAAAA EEEEEEEEAAAAAAA MMMMMMMMAAAAAAA -OOOOOOOAAAAAAA -JJJJJJJAAAAAA- --HHHHHHAAAAAA- ---BBBBBAAAAA-- ----IIIIAAA---- 
------AAA------ ----ZZZZAAAA--- ---BBBBBAAAAA-- --DDDDDDAAAAAA- -SSSSSSSAAAAAA- -DDDDDDDAAAAAAA BBBBBBBBAAAAAAA UUUUUUUUAAAAAAA EEEEEEEEAAAAAAA -LLLLLLLAAAAAAA -AAAAAAAAAAAAAA -AAAAAAAAAAAAA- --DDDDDDAAAAA-- ---IIIIIAAAA--- -----RRRAAA---- 
--------------- ----AAAAAAA---- ---FFFFFAAAAA-- --HHHHHHAAAAAA- -NNNNNNNAAAAAA- -DDDDDDDAAAAAAA -WWWWWWWAAAAAAA -GGGGGGGAAAAAAA -CCCCCCCAAAAAAA -CCCCCCCAAAAAAA -JJJJJJJAAAAAA- --OOOOOOAAAAAA- --IIIIIIAAAAA-- ---KKKKKAAAA--- -----YYYAA----- 
--------------- -----AAAAA----- ---RRRRRAAAA--- --BBBBBBAAAAA-- --HHHHHHAAAAAA- -HHHHHHHAAAAAA- -CCCCCCCAAAAAA- -CCCCCCCAAAAAAA -CCCCCCCAAAAAA- -GGGGGGGAAAAAA- --GGGGGGAAAAAA- --BBBBBBAAAAA-- ---KKKKKAAAAA-- ----EEEEAAA---- -------V------- 
--------------- --------------- ----AAAAAAA---- ---FFFFFAAAA--- --BBBBBBAAAAA-- --BBBBBBAAAAAA- --FFFFFFAAAAAA- --BBBBBBAAAAAA- --BBBBBBAAAAAA- --BBBBBBAAAAAA- --BBBBBBAAAAA-- ---FFFFFAAAAA-- ----EEEEAAAA--- -----TTTAA----- --------------- 
--------------- --------------- -------AA------ ----AAAAAAA---- ---FFFFFAAAA--- ---FFFFFAAAAA-- ---BBBBBAAAAA-- --BBBBBBAAAAA-- --IIIIIIAAAAA-- ---FFFFFAAAAA-- ---KKKKKAAAA--- ----EEEEAAAA--- -----TTTAA----- --------------- --------------- 
--------------- --------------- --------------- --------------- -----AAAAA----- ----LLLLAAA---- ----KKKKAAAA--- ----KKKKAAAA--- ----KKKKAAAA--- ----EEEEAAAA--- -----RRRAAA---- ------AAAA----- --------------- --------------- --------------- 
--------------- --------------- --------------- --------------- --------------- --------------- ------AAA------ ------AAAA----- ------AAAA----- -------AA------ --------------- --------------- --------------- --------------- --------------- 
