model
size = 15 15 30, scale = 0.05, origin = -y
material 
  colors = A:#EEE B:#336 C:#100 D:#369 E:#001 F:#96C G:#6CC H:#222 I:#639 J:#39C K:#969 L:#99C M:#333 N:#3CC O:#36C P:#555 Q:#939 R:#111 S:#9CC T:#004 U:#366 V:#69C W:#999 X:#777 Y:#339 Z:#636 Aa:#C9C Ab:#66C Ac:#033 Ad:#CCC Ae:#6FF Af:#444 Ag:#FFF Ah:#CCF Ai:#036 Aj:#6CF Ak:#888 Al:#002 Am:#303 An:#003 Ao:#039 Ap:#669 Aq:#63C Ar:#BBB
voxels
- - - - - - - - - - - - - - -   - - - - - - - - - - - - - - -   - - - - - - - - - - - - - - -   - - - - - - - - - - - - - - -   - - - - - - - A - - - - - - -   - - - - - X X A A A - - - - -   - - - - - H H A A A A - - - -   - - - - R R R A A A A - - - -   - - - - - R R A A A A - - - -   - - - - - H H A A A A - - - -   - - - - - - ArA A A - - - - -   - - - - - - - - - - - - - - -   - - - - - - - - - - - - - - -   - - - - - - - - - - - - - - -   - - - - - - - - - - - - - - -   
- - - - - - - - - - - - - - -   - - - - - - - - - - - - - - -   - - - - - - - - - - - - - - -   - - - - - W W A A A - - - - -   - - - - H H H A A A A - - - -   - - - B B B B A A A A A - - -   - - - B B B B A A A A A - - -   - - - T T T T A A A A A A - -   - - - AnAnAnAnA A A A A A - -   - - - H H H H A A A A A - - -   - - - - B B B A A A A A - - -   - - - - - M M A A A A - - - -   - - - - - - - A A - - - - - -   - - - - - - - - - - - - - - -   - - - - - - - - - - - - - - -   
- - - - - - - - - - - - - - -   - - - - - - - - - - - - - - -   - - - - - X X A A A - - - - -   - - - - B B B A A A A A - - -   - - - Y Y Y Y A A A A A A - -   - - J J J J J A A A A A A - -   - - O O O O O A A A A A A - -   - - Y Y Y Y Y A A A A A A A -   - - B B B B B A A A A A A A -   - - B B B B B A A A A A A - -   - - - Y Y Y Y A A A A A A - -   - - - B B B B A A A A A - - -   - - - - AcAcAcA A A A - - - -   - - - - - - - A A - - - - - -   - - - - - - - - - - - - - - -   
- - - - - - - - - - - - - - -   - - - - - - AgA A A - - - - -   - - - - B B B A A A A A - - -   - - - D D D D A A A A A A - -   - - J J J J J A A A A A A - -   - - N N N N N A A A A A A A -   - V V V V V V A A A A A A A -   - K K K K K K A A A A A A A -   - Z Z Z Z Z Z A A A A A A A -   - I I I I I I A A A A A A A -   - - AbAbAbAbAbA A A A A A A -   - - O O O O O A A A A A A - -   - - - AoAoAoAoA A A A A - - -   - - - - - T T A A A A - - - -   - - - - - - - - - - - - - - -   
- - - - - - - - - - - - - - -   - - - - - H H A A A A - - - -   - - - B B B B A A A A A - - -   - - J J J J J A A A A A A - -   - - AjAjAjAjAjA A A A A A A -   - N N N N N N A A A A A A A -   - I I I I I I A A A A A A A A   - Z Z Z Z Z Z A A A A A A A A   - W W W W W W A A A A A A A A   - Q Q Q Q Q Q A A A A A A A A   - F F F F F F A A A A A A A -   - - V V V V V A A A A A A A -   - - - O O O O A A A A A A - -   - - - - B B B A A A A A - - -   - - - - - - AdA A A - - - - -   
- - - - - - - A A - - - - - -   - - - - B B B A A A A A - - -   - - - D D D D A A A A A A - -   - - N N N N N A A A A A A A -   - AeAeAeAeAeAeA A A A A A A -   - D D D D D D A A A A A A A A   - R R R R R R A A A A A A A A   E E E E E E E A A A A A A A A   C C C C C C C A A A A A A A A   - M M M M M M A A A A A A A A   - K K K K K K A A A A A A A A   - AaAaAaAaAaAaA A A A A A A -   - - F F F F F A A A A A A - -   - - - I I I I A A A A A - - -   - - - - - H H A A A A - - - -   
- - - - - - AgA A A - - - - -   - - - - B B B A A A A A - - -   - - D D D D D A A A A A A - -   - - G G G G G A A A A A A A -   - G G G G G G A A A A A A A -   - B B B B B B A A A A A A A A   E E E E E E E A A A A A A A A   C C C C C C C A A A A A A A A   C C C C C C C A A A A A A A A   C C C C C C C A A A A A A A A   - B B B B B B A A A A A A A A   - S S S S S S A A A A A A A -   - - L L L L L A A A A A A A -   - - - AqAqAqAqA A A A A A - -   - - - - - H H A A A A - - - -   
- - - - - - AgA A A - - - - -   - - - - B B B A A A A A - - -   - - F F F F F A A A A A A - -   - - AhAhAhAhAhA A A A A A A -   - S S S S S S A A A A A A A A   - M M M M M M A A A A A A A A   E E E E E E E A A A A A A A A   C C C C C C C A A A A A A A A   C C C C C C C A A A A A A A A   C C C C C C C A A A A A A A A   - B B B B B B A A A A A A A A   - G G G G G G A A A A A A A -   - - S S S S S A A A A A A A -   - - - ApApApApA A A A A A - -   - - - - B B B A A A A - - - -   
- - - - - - A A A - - - - - -   - - - - B B B A A A A A - - -   - - - F F F F A A A A A A - -   - - AaAaAaAaAaA A A A A A A -   - L L L L L L A A A A A A A -   - P P P P P P A A A A A A A A   C C C C C C C A A A A A A A A   E E E E E E E A A A A A A A A   C C C C C C C A A A A A A A A   - C C C C C C A A A A A A A A   - B B B B B B A A A A A A A A   - G G G G G G A A A A A A A -   - - G G G G G A A A A A A - -   - - - D D D D A A A A A - - -   - - - - - H H A A A A - - - -   
- - - - - - - - - - - - - - -   - - - - H H H A A A A - - - -   - - - I I I I A A A A A A - -   - - F F F F F A A A A A A A -   - L L L L L L A A A A A A A -   - F F F F F F A A A A A A A A   - AfAfAfAfAfAfA A A A A A A A   - X X X X X X A A A A A A A A   - P P P P P P A A A A A A A A   - B B B B B B A A A A A A A A   - D D D D D D A A A A A A A -   - - N N N N N A A A A A A A -   - - J J J J J A A A A A A - -   - - - B B B B A A A A A - - -   - - - - - AkAkA A A - - - - -   
- - - - - - - - - - - - - - -   - - - - - W W A A A - - - - -   - - - B B B B A A A A A - - -   - - O O O O O A A A A A A - -   - - V V V V V A A A A A A A -   - L L L L L L A A A A A A A -   - Q Q Q Q Q Q A A A A A A A -   - K K K K K K A A A A A A A A   - K K K K K K A A A A A A A -   - P P P P P P A A A A A A A -   - - U U U U U A A A A A A A -   - - J J J J J A A A A A A - -   - - - D D D D A A A A A A - -   - - - - B B B A A A A - - - -   - - - - - - - A - - - - - - -   
- - - - - - - - - - - - - - -   - - - - - - - - - - - - - - -   - - - - AcAcAcAcA A A - - - -   - - - AiAiAiAiAiA A A A - - -   - - D D D D D D A A A A A - -   - - AbAbAbAbAbAbA A A A A A -   - - Q Q Q Q Q Q A A A A A A -   - - I I I I I I A A A A A A -   - - D D D D D D A A A A A A -   - - U U U U U U A A A A A A -   - - U U U U U U A A A A A - -   - - - D D D D D A A A A A - -   - - - - B B B B A A A A - - -   - - - - - W W W A A - - - - -   - - - - - - - - - - - - - - -   
- - - - - - - - - - - - - - -   - - - - - - - - - - - - - - -   - - - - - - - A A - - - - - -   - - - - M M M M A A A - - - -   - - - B B B B B A A A A - - -   - - - B B B B B A A A A A - -   - - - B B B B B A A A A A - -   - - B B B B B B A A A A A - -   - - T T T T T T A A A A A - -   - - - AlAlAlAlAlA A A A A - -   - - - T T T T T A A A A - - -   - - - - H H H H A A A A - - -   - - - - - X X X A A - - - - -   - - - - - - - - - - - - - - -   - - - - - - - - - - - - - - -   
- - - - - - - - - - - - - - -   - - - - - - - - - - - - - - -   - - - - - - - - - - - - - - -   - - - - - - - - - - - - - - -   - - - - - AkAkAkA A - - - - -   - - - - M M M M A A A - - - -   - - - - AmAmAmAmA A A A - - -   - - - - R R R R A A A A - - -   - - - - E E E E A A A A - - -   - - - - E E E E A A A A - - -   - - - - - R R R A A A - - - -   - - - - - - AdAdA A - - - - -   - - - - - - - - - - - - - - -   - - - - - - - - - - - - - - -   - - - - - - - - - - - - - - -   
- - - - - - - - - - - - - - -   - - - - - - - - - - - - - - -   - - - - - - - - - - - - - - -   - - - - - - - - - - - - - - -   - - - - - - - - - - - - - - -   - - - - - - - - - - - - - - -   - - - - - - AgAgA - - - - - -   - - - - - - AdAdA A - - - - -   - - - - - - AdAdA A - - - - -   - - - - - - - A A - - - - - -   - - - - - - - - - - - - - - -   - - - - - - - - - - - - - - -   - - - - - - - - - - - - - - -   - - - - - - - - - - - - - - -   - - - - - - - - - - - - - - -   
- - - - - - - - - - - - - - -   - - - - - - - - - - - - - - -   - - - - - - - - - - - - - - -   - - - - - - - - - - - - - - -   - - - - - - - A - - - - - - -   - - - - - X X A A A - - - - -   - - - - - H H A A A A - - - -   - - - - R R R A A A A - - - -   - - - - - R R A A A A - - - -   - - - - - H H A A A A - - - -   - - - - - - ArA A A - - - - -   - - - - - - - - - - - - - - -   - - - - - - - - - - - - - - -   - - - - - - - - - - - - - - -   - - - - - - - - - - - - - - -   
- - - - - - - - - - - - - - -   - - - - - - - - - - - - - - -   - - - - - - - - - - - - - - -   - - - - - W W A A A - - - - -   - - - - H H H A A A A - - - -   - - - B B B B A A A A A - - -   - - - B B B B A A A A A - - -   - - - T T T T A A A A A A - -   - - - AnAnAnAnA A A A A A - -   - - - H H H H A A A A A - - -   - - - - B B B A A A A A - - -   - - - - - M M A A A A - - - -   - - - - - - - A A - - - - - -   - - - - - - - - - - - - - - -   - - - - - - - - - - - - - - -   
- - - - - - - - - - - - - - -   - - - - - - - - - - - - - - -   - - - - - X X A A A - - - - -   - - - - B B B A A A A A - - -   - - - Y Y Y Y A A A A A A - -   - - J J J J J A A A A A A - -   - - O O O O O A A A A A A - -   - - Y Y Y Y Y A A A A A A A -   - - B B B B B A A A A A A A -   - - B B B B B A A A A A A - -   - - - Y Y Y Y A A A A A A - -   - - - B B B B A A A A A - - -   - - - - AcAcAcA A A A - - - -   - - - - - - - A A - - - - - -   - - - - - - - - - - - - - - -   
- - - - - - - - - - - - - - -   - - - - - - AgA A A - - - - -   - - - - B B B A A A A A - - -   - - - D D D D A A A A A A - -   - - J J J J J A A A A A A - -   - - N N N N N A A A A A A A -   - V V V V V V A A A A A A A -   - K K K K K K A A A A A A A -   - Z Z Z Z Z Z A A A A A A A -   - I I I I I I A A A A A A A -   - - AbAbAbAbAbA A A A A A A -   - - O O O O O A A A A A A - -   - - - AoAoAoAoA A A A A - - -   - - - - - T T A A A A - - - -   - - - - - - - - - - - - - - -   
- - - - - - - - - - - - - - -   - - - - - H H A A A A - - - -   - - - B B B B A A A A A - - -   - - J J J J J A A A A A A - -   - - AjAjAjAjAjA A A A A A A -   - N N N N N N A A A A A A A -   - I I I I I I A A A A A A A A   - Z Z Z Z Z Z A A A A A A A A   - W W W W W W A A A A A A A A   - Q Q Q Q Q Q A A A A A A A A   - F F F F F F A A A A A A A -   - - V V V V V A A A A A A A -   - - - O O O O A A A A A A - -   - - - - B B B A A A A A - - -   - - - - - - AdA A A - - - - -   
- - - - - - - A A - - - - - -   - - - - B B B A A A A A - - -   - - - D D D D A A A A A A - -   - - N N N N N A A A A A A A -   - AeAeAeAeAeAeA A A A A A A -   - D D D D D D A A A A A A A A   - R R R R R R A A A A A A A A   E E E E E E E A A A A A A A A   C C C C C C C A A A A A A A A   - M M M M M M A A A A A A A A   - K K K K K K A A A A A A A A   - AaAaAaAaAaAaA A A A A A A -   - - F F F F F A A A A A A - -   - - - I I I I A A A A A - - -   - - - - - H H A A A A - - - -   
- - - - - - AgA A A - - - - -   - - - - B B B A A A A A - - -   - - D D D D D A A A A A A - -   - - G G G G G A A A A A A A -   - G G G G G G A A A A A A A -   - B B B B B B A A A A A A A A   E E E E E E E A A A A A A A A   C C C C C C C A A A A A A A A   C C C C C C C A A A A A A A A   C C C C C C C A A A A A A A A   - B B B B B B A A A A A A A A   - S S S S S S A A A A A A A -   - - L L L L L A A A A A A A -   - - - AqAqAqAqA A A A A A - -   - - - - - H H A A A A - - - -   
- - - - - - AgA A A - - - - -   - - - - B B B A A A A A - - -   - - F F F F F A A A A A A - -   - - AhAhAhAhAhA A A A A A A -   - S S S S S S A A A A A A A A   - M M M M M M A A A A A A A A   E E E E E E E A A A A A A A A   C C C C C C C A A A A A A A A   C C C C C C C A A A A A A A A   C C C C C C C A A A A A A A A   - B B B B B B A A A A A A A A   - G G G G G G A A A A A A A -   - - S S S S S A A A A A A A -   - - - ApApApApA A A A A A - -   - - - - B B B A A A A - - - -   
- - - - - - A A A - - - - - -   - - - - B B B A A A A A - - -   - - - F F F F A A A A A A - -   - - AaAaAaAaAaA A A A A A A -   - L L L L L L A A A A A A A -   - P P P P P P A A A A A A A A   C C C C C C C A A A A A A A A   E E E E E E E A A A A A A A A   C C C C C C C A A A A A A A A   - C C C C C C A A A A A A A A   - B B B B B B A A A A A A A A   - G G G G G G A A A A A A A -   - - G G G G G A A A A A A - -   - - - D D D D A A A A A - - -   - - - - - H H A A A A - - - -   
- - - - - - - - - - - - - - -   - - - - H H H A A A A - - - -   - - - I I I I A A A A A A - -   - - F F F F F A A A A A A A -   - L L L L L L A A A A A A A -   - F F F F F F A A A A A A A A   - AfAfAfAfAfAfA A A A A A A A   - X X X X X X A A A A A A A A   - P P P P P P A A A A A A A A   - B B B B B B A A A A A A A A   - D D D D D D A A A A A A A -   - - N N N N N A A A A A A A -   - - J J J J J A A A A A A - -   - - - B B B B A A A A A - - -   - - - - - AkAkA A A - - - - -   
- - - - - - - - - - - - - - -   - - - - - W W A A A - - - - -   - - - B B B B A A A A A - - -   - - O O O O O A A A A A A - -   - - V V V V V A A A A A A A -   - L L L L L L A A A A A A A -   - Q Q Q Q Q Q A A A A A A A -   - K K K K K K A A A A A A A A   - K K K K K K A A A A A A A -   - P P P P P P A A A A A A A -   - - U U U U U A A A A A A A -   - - J J J J J A A A A A A - -   - - - D D D D A A A A A A - -   - - - - B B B A A A A - - - -   - - - - - - - A - - - - - - -   
- - - - - - - - - - - - - - -   - - - - - - - - - - - - - - -   - - - - AcAcAcAcA A A - - - -   - - - AiAiAiAiAiA A A A - - -   - - D D D D D D A A A A A - -   - - AbAbAbAbAbAbA A A A A A -   - - Q Q Q Q Q Q A A A A A A -   - - I I I I I I A A A A A A -   - - D D D D D D A A A A A A -   - - U U U U U U A A A A A A -   - - U U U U U U A A A A A - -   - - - D D D D D A A A A A - -   - - - - B B B B A A A A - - -   - - - - - W W W A A - - - - -   - - - - - - - - - - - - - - -   
- - - - - - - - - - - - - - -   - - - - - - - - - - - - - - -   - - - - - - - A A - - - - - -   - - - - M M M M A A A - - - -   - - - B B B B B A A A A - - -   - - - B B B B B A A A A A - -   - - - B B B B B A A A A A - -   - - B B B B B B A A A A A - -   - - T T T T T T A A A A A - -   - - - AlAlAlAlAlA A A A A - -   - - - T T T T T A A A A - - -   - - - - H H H H A A A A - - -   - - - - - X X X A A - - - - -   - - - - - - - - - - - - - - -   - - - - - - - - - - - - - - -   
- - - - - - - - - - - - - - -   - - - - - - - - - - - - - - -   - - - - - - - - - - - - - - -   - - - - - - - - - - - - - - -   - - - - - AkAkAkA A - - - - -   - - - - M M M M A A A - - - -   - - - - AmAmAmAmA A A A - - -   - - - - R R R R A A A A - - -   - - - - E E E E A A A A - - -   - - - - E E E E A A A A - - -   - - - - - R R R A A A - - - -   - - - - - - AdAdA A - - - - -   - - - - - - - - - - - - - - -   - - - - - - - - - - - - - - -   - - - - - - - - - - - - - - -   
- - - - - - - - - - - - - - -   - - - - - - - - - - - - - - -   - - - - - - - - - - - - - - -   - - - - - - - - - - - - - - -   - - - - - - - - - - - - - - -   - - - - - - - - - - - - - - -   - - - - - - AgAgA - - - - - -   - - - - - - AdAdA A - - - - -   - - - - - - AdAdA A - - - - -   - - - - - - - A A - - - - - -   - - - - - - - - - - - - - - -   - - - - - - - - - - - - - - -   - - - - - - - - - - - - - - -   - - - - - - - - - - - - - - -   - - - - - - - - - - - - - - -   
