model
size = 23 23 30, scale = 0.05, origin = -y
material 
  colors = A:#111 B:#000 C:#555 D:#222
voxels
----------------------- ----------------------- ----------------------- ----------------------- ----------------------- ----------------------- ----------------------- ----------------------- ----------------------- -----------C----------- -----------C----------- ---------CC------------ ----------------------- ----------------------- ----------------------- ----------------------- ----------------------- ----------------------- ----------------------- ----------------------- ----------------------- ----------------------- ----------------------- 
----------------------- ----------------------- ----------------------- ----------------------- ----------------------- ----------------------- ----------------------- ----------------------- ----------------------- -----------C----------- -----------C----------- ---------CC------------ ----------------------- ----------------------- ----------------------- ----------------------- ----------------------- ----------------------- ----------------------- ----------------------- ----------------------- ----------------------- ----------------------- 
---------AAA----------- ---------AAA----------- ---------AAA----------- ---------AAA----------- ---------AAA----------- ---------AAA----------- ---------AAA----------- ---------AAA----------- ---------AAA----------- ---------AAACCC-------- ---------AAACCC-------- ------CCCAAA----------- -----C---AAA------CC--- -----C---AAA------CC--- ---------AAA----------- ---------AAA--A-------- ---------AAA--A-------- ---------AAA--A-------- ---------AAA----------- ---------AAA----------- ---------BBB--B-------- ---------BBB----------- ---------BBB----------- 
------AAAAAAAAA-------- ------AAAAAAAAA-------- ------AAAAAAAAA-------- ------AAAAAAAAA-------- ------AAAAAAAAA-------- ------AAAAAAAAA-------- ------AAAAAAAAA-------- ------AAAAAAAAA-------- ------AAAAAAAAA-------- ------AAAAAAAAA-------- ------AAAAAAAAA-------- ------AAAAAAAAACCC----- -----AAAAAAAAAA---AAC-- -----AAAAAAAAAA---AAC-- ---CCAAAAAAAAAA---AAC-- -----AAAAAAAAAA---AA--- -----AAAAAAAAAA---AA--- ------AAAAAAAAA---AA--- ------AAAAABAAA---AA--- ------AAAAABAAA---AA--- ------BBBBBBBBB--B----- ------BBBBBBBBB--B----- ------BBBBBBBBB--B----- 
------AAAAAAAAA-------- ------AAAAAAAAA-------- ------AAAAAAAAA-------- ------AAAAAAAAA-------- ------AAAAAAAAA-------- ------AAAAAAAAA-------- ------AAAAAAAAA-------- ------AAAAAAAAA-------- ------AAAAAAAAA-------- ------AAAAAAAAA-------- ------AAAAAAAAA-------- ------AAAAAAAAACCC----- -----AAAAAAAAAA---AAC-- -----AAAAAAAAAA---AAC-- ---CCAAAAAAAAAA---AAC-- -----AAAAAAAAAA---AA--- -----AAAAAAAAAA---AA--- ------AAAAAAAAA---AA--- ------AAAAABAAA---AA--- ------AAAAABAAA---AA--- ------BBBBBBBBB--B----- ------BBBBBBBBB--B----- ------BBBBBBBBB--B----- 
-----AAAAAAAAAAAA------ -----AAAAAAAAAAAA------ -----AAAAAAAAAAAA------ -----AAAAAAAAAAAA------ -----AAAAAAAAAAAA------ -----AAAAAAAAAAAA------ -----AAAAAAAAAAAA------ -----AAAAAAAAAAAA------ -----AAAAAAAAAAAAA----- -----AAAAAAAAAAAAA----- -----AAAAAAAAAAAAA----- ------AAAAAAAAAAACAA--- ---AAAAAAAAAAAAAA-AA--- ---AAAAAAAAAAAAAA-AA--- --CAAAAAAAAAAAAAA-AAC-- -----AAAAAAAAAAAAAAAC-- -----AAAAAAAAAAAAAAAC-- -----AAAAAAAAAAAAAAA--- -----AAAAAABBBBAAAAA--- -----AAAAAABBBBAAAAA--- -----BBBBBBBBBBBBBBB--- -----BBBBBBBBBBBBBBB--- -----BBBBBBBBBBBBBBB--- 
---AAAAAAAAAAAAAA------ ---AAAAAAAAAAAAAA------ ---AAAAAAAAAAAAAAA----- ---AAAAAAAAAAAAAAA----- ---AAAAAAAAAAAAAAA----- ---AAAAAAAAAAAAAAA----- ---AAAAAAAAAAAAAAA----- ---AAAAAAAAAAAAAAA----- ---AAAAAAAAAAAAAAA----- ---AAAAAAAAAAAAAAAAA--- ---AAAAAAAAAAAAAAAAA--- ---AAAAAAAAAAAAAAA--A-- ---AAAAAAAAAAAAAAA--A-- ---AAAAAAAAAAAAAAA--A-- ---AAAAAAAAAAAAAAA--A-- --CAAAAAAAAAAAAAAAAAA-- --CAAAAAAAAAAAAAAAAAA-- CCAAAAAAAAAAAAAAAAAAACC CCAAAAAAAAABBBBBBBBBA-- CCAAAAAAAAABBBBBBBBBA-- ---BBBBBBBBBBBBBBBBBB-- ---BBBBBBBBBBBBBBBBBB-- ---BBBBBBBBBBBBBBBBBB-- 
---AAAAAAAAAAAAAA------ ---AAAAAAAAAAAAAA------ ---AAAAAAAAAAAAAAA----- ---AAAAAAAAAAAAAAA----- ---AAAAAAAAAAAAAAA----- ---AAAAAAAAAAAAAAA----- ---AAAAAAAAAAAAAAA----- ---AAAAAAAAAAAAAAA----- ---AAAAAAAAAAAAAAA----- ---AAAAAAAAAAAAAAAAA--- ---AAAAAAAAAAAAAAAAA--- ---AAAAAAAAAAAAAAA--A-- ---AAAAAAAAAAAAAAA--A-- ---AAAAAAAAAAAAAAA--A-- ---AAAAAAAAAAAAAAA--A-- --CAAAAAAAAAAAAAAAAAA-- --CAAAAAAAAAAAAAAAAAA-- CCAAAAAAAAAAAAAAAAAAACC CCAAAAAAAAABBBBBBBBBA-- CCAAAAAAAAABBBBBBBBBA-- ---BBBBBBBBBBBBBBBBBB-- ---BBBBBBBBBBBBBBBBBB-- ---BBBBBBBBBBBBBBBBBB-- 
---AAAAAAAAAAAAAAA----- ---AAAAAAAAAAAAAAA----- ---AAAAAAAAAAAAAAA----- ---AAAAAAAAAAAAAAA----- ---AAAAAAAAAAAAAAA----- ---AAAAAAAAAAAAAAA----- ---AAAAAAAAAAAAAAA----- ---AAAAAAAAAAAAAAA----- ---AAAAAAAAAAAAAAAAA--- ---AAAAAAAAAAAAAAA--A-- ---AAAAAAAAAAAAAAA--A-- ---AAAAAAAAAAAAAAA--A-- ---AAAAAAAAAAAAAAAAAA-- ---AAAAAAAAAAAAAAAAAA-- ---AAAAAAAAAAAAAAAAAAAA --AAAAAAAAAAAAAAAAAAAAA --AAAAAAAAAAAAAAAAAAAAA --AAAAAAAAAAAAAAAAAAAAA --AAAAAAAAABBBBBBBBBACC --AAAAAAAAABBBBBBBBBACC --BBBBBBBBBBBBBBBBBBB-- --BBBBBBBBBBBBBBBBBBB-- --BBBBBBBBBBBBBBBBBBB-- 
---AAAAAAAAAAAAAAA----- ---AAAAAAAAAAAAAAA----- ---AAAAAAAAAAAAAAA----- ---AAAAAAAAAAAAAAA----- ---AAAAAAAAAAAAAAA----- ---AAAAAAAAAAAAAAA----- ---AAAAAAAAAAAAAAAAA--- ---AAAAAAAAAAAAAAAAA--- ---AAAAAAAAAAAAAAAAA--- ---AAAAAAAAAAAAAAA--A-- ---AAAAAAAAAAAAAAA--A-- ---AAAAAAAAAAAAAAA--A-- ---AAAAAAAAAAAAAAAAAA-- ---AAAAAAAAAAAAAAAAAA-- AAAAAAAAAAAAAAAAAAAAAAA AAAAAAAAAAAAAAAAAAAAAAA AAAAAAAAAAAAAAAAAAAAAAA --AAAAAAAAAAAAAAAAAAAAA --AAAAAAAAABBBBBBBBBA-- --AAAAAAAAABBBBBBBBBA-- --BBBBBBBBBBBBBBBBBBB-- --BBBBBBBBBBBBBBBBBBB-- --BBBBBBBBBBBBBBBBBBB-- 
---AAAAAAAAAAAAAAA----- ---AAAAAAAAAAAAAAA----- ---AAAAAAAAAAAAAAA----- ---AAAAAAAAAAAAAAA----- ---AAAAAAAAAAAAAAA----- ---AAAAAAAAAAAAAAA----- ---AAAAAAAAAAAAAAAAA--- ---AAAAAAAAAAAAAAAAA--- ---AAAAAAAAAAAAAAAAA--- ---AAAAAAAAAAAAAAA--A-- ---AAAAAAAAAAAAAAA--A-- ---AAAAAAAAAAAAAAA--A-- ---AAAAAAAAAAAAAAAAAA-- ---AAAAAAAAAAAAAAAAAA-- AAAAAAAAAAAAAAAAAAAAAAA AAAAAAAAAAAAAAAAAAAAAAA AAAAAAAAAAAAAAAAAAAAAAA --AAAAAAAAAAAAAAAAAAAAA --AAAAAAAAABBBBBBBBBA-- --AAAAAAAAABBBBBBBBBA-- --BBBBBBBBBBBBBBBBBBB-- --BBBBBBBBBBBBBBBBBBB-- --BBBBBBBBBBBBBBBBBBB-- 
-----AAAAAAAAAAAA------ -----AAAAAAAAAAAA------ -----AAAAAAAAAAAAA----- -----AAAAAAAAAAAAA----- -----AAAAAAAAAAAAA----- -----AAAAAAAAAAAAA----- -----AAAAAAAAAAAAAAA--- -----AAAAAAAAAAAAAAA--- -----AAAAAAAAAAAAAAA--- -----AAAAAAAAAAAAAAAA-- -----AAAAAAAAAAAAAAAA-- ---AAAAAAAAAAAAAAAAAA-- AA-AAAAAAAAAAAAAAAAAA-- AA-AAAAAAAAAAAAAAAAAA-- AA-AAAAAAAAAAAAAAAAAAAA AAAAAAAAAAAAAAAAAAAAAAA AAAAAAAAAAAAAAAAAAAAAAA AAAAAAAAAAAAAAAAAAAAAAA --AAAAAAAAABBBBBBBBBA-- --AAAAAAAAABBBBBBBBBA-- BBBBBBBBBBBBBBBBBBBBB-- --DBBBBBBBBBBBBBBBBBB-- --DBBBBBBBBBBBBBBBBBB-- 
-----AAAAAAAAA--------- -----AAAAAAAAA--------- -----AAAAAAAAAA-------- -----AAAAAAAAAA-------- -----AAAAAAAAAA-------- -----AAAAAAAAAA-------- -----AAAAAAAAAA-------- -----AAAAAAAAAA-------- -----AAAAAAAAAAAAA----- --AAAAAAAAAAAAAAAAAA--- --AAAAAAAAAAAAAAAAAA--- AAAAAAAAAAAAAAAAAAAA--- AA-AAAAAAAAAAAAAAAAAA-- AA-AAAAAAAAAAAAAAAAAA-- AA---AAAAAAAAAAAAAAAA-- AA-AAAAAAAAAAAAAAAAAA-- AA-AAAAAAAAAAAAAAAAAA-- AA-AAAAAAAAAAAAAAAAAA-- DD-AAAAAAAABBBBBBBBBA-- DD-AAAAAAAABBBBBBBBBA-- DDBBBBBBBBBBBBBBBBBBB-- DDBBBBBBBBBBBBBBBBBBB-- DDBBBBBBBBBBBBBBBBBBB-- 
-----AAAAAAAAA--------- -----AAAAAAAAA--------- -----AAAAAAAAAA-------- -----AAAAAAAAAA-------- -----AAAAAAAAAA-------- -----AAAAAAAAAA-------- -----AAAAAAAAAA-------- -----AAAAAAAAAA-------- -----AAAAAAAAAAAAA----- --AAAAAAAAAAAAAAAAAA--- --AAAAAAAAAAAAAAAAAA--- AAAAAAAAAAAAAAAAAAAA--- AA-AAAAAAAAAAAAAAAAAA-- AA-AAAAAAAAAAAAAAAAAA-- AA---AAAAAAAAAAAAAAAA-- AA-AAAAAAAAAAAAAAAAAA-- AA-AAAAAAAAAAAAAAAAAA-- AA-AAAAAAAAAAAAAAAAAA-- DD-AAAAAAAABBBBBBBBBA-- DD-AAAAAAAABBBBBBBBBA-- DDBBBBBBBBBBBBBBBBBBB-- DDBBBBBBBBBBBBBBBBBBB-- DDBBBBBBBBBBBBBBBBBBB-- 
-----AAA---A----------- -----AAA---A----------- -----AAAAAAA----------- -----AAAA--A----------- -----AAAA--A----------- ---AAAAA--------------- --AAAAAA-AAA----------- --AAAAAA-AAA----------- --AAAAAAAAAAAA--------- AAAAAAAAAAAAAA--------- AAAAAAAAAAAAAA--------- AAAAAAAAAAAAAAAAAA----- AAAAAAAAAAAAAAAAAAAAA-- AAAAAAAAAAAAAAAAAAAAA-- AAAAAAAAAAAAAAAAAAAAA-- AA-AAAAAAAAAAAAAAAAAA-- AA-AAAAAAAAAAAAAAAAAA-- AA-AAAAAAAAAAAAAAAAAA-- DD-AAAAAAAABBBBBBBBBA-- DD-AAAAAAAABBBBBBBBBA-- BBBBBBBBBBBBBBBBBBBBB-- DDBBBBBBBBBBBBBBBBBBB-- DDBBBBBBBBBBBBBBBBBBB-- 
----------------------- ----------------------- -----A----------------- -----AAAA-------------- -----AAAA-------------- --AAAAAA--------------- --AAAAAAAAAAAAA-------- --AAAAAAAAAAAAA-------- AAAAAAAAAAAAAA--------- AAAAAAAAAAAAAA--------- AAAAAAAAAAAAAA--------- AAAAAAAAAAAAAAAAAA----- AAAAAAAAAAAAAAAAAAAAA-- AAAAAAAAAAAAAAAAAAAAA-- AA---AAAAAAAAAAAAAAAA-- AA-AAAAAAAAAAAAAAAAAA-- AA-AAAAAAAAAAAAAAAAAA-- AA-AAAAAAAAAAAAAAAAAA-- DD-AAAAAAAABBBBBBBBBA-- DD-AAAAAAAABBBBBBBBBA-- BBBBBBBBBBBBBBBBBBBBB-- DDBBBBBBBBBBBBBBBBBBB-- DDBBBBBBBBBBBBBBBBBBB-- 
----------------------- ----------------------- -----A----------------- -----AAAA-------------- -----AAAA-------------- --AAAAAA--------------- --AAAAAAAAAAAAA-------- --AAAAAAAAAAAAA-------- AAAAAAAAAAAAAA--------- AAAAAAAAAAAAAA--------- AAAAAAAAAAAAAA--------- AAAAAAAAAAAAAAAAAA----- AAAAAAAAAAAAAAAAAAAAA-- AAAAAAAAAAAAAAAAAAAAA-- AA---AAAAAAAAAAAAAAAA-- AA-AAAAAAAAAAAAAAAAAA-- AA-AAAAAAAAAAAAAAAAAA-- AA-AAAAAAAAAAAAAAAAAA-- DD-AAAAAAAABBBBBBBBBA-- DD-AAAAAAAABBBBBBBBBA-- BBBBBBBBBBBBBBBBBBBBB-- DDBBBBBBBBBBBBBBBBBBB-- DDBBBBBBBBBBBBBBBBBBB-- 
-----AAAAAAAAA--------- -----AAAAAAAAA--------- -----AAAAAA------------ -----AAAAAAAAAA-------- -----AAAAAAAAAA-------- ---AAAAAAAAAAAA-------- --A--AAAAAAAAAA--A----- --A--AAAAAAAAAA--A----- --A--AAA-AAAAAAAAA----- AA-AAAAAAAAAAAAAAA----- AA-AAAAAAAAAAAAAAA----- AAA--AAAAAAAAAAAAAAAA-- AA---AAAAAAAAAAAAAAAA-- AA---AAAAAAAAAAAAAAAA-- AA-AAAAAAAAAAAAAAAAAA-- AA-AAAAAAAAAAAAAAAAAA-- AA-AAAAAAAAAAAAAAAAAA-- AA-AAAAAAAAAAAAAAAAAA-- DDAAAAAAAAABBBBBBBBBA-- DDAAAAAAAAABBBBBBBBBA-- DDBBBBBBBBBBBBBBBBBBB-- DDBBBBBBBBBBBBBBBBBBB-- DDBBBBBBBBBBBBBBBBBBB-- 
-----AAAAAAAAAAAAAAA--- -----AAAAAAAAAAAAAAA--- -----AAAAAAAAAAAAAAA--- -----AAAAAAAAAAAAAAA--- -----AAAAAAAAAAAAAAA--- -----AAAAAAAAAAAAAAA--- -----AAAAAAAAAAAAAAA--- -----AAAAAAAAAAAAAAA--- -----AAAAAAAAAAAAAAA--- -----AAAAAAAAAAAAAAAA-- -----AAAAAAAAAAAAAAAA-- ---AAAAAAAAAAAAAAAAAA-- AA-AAAAAAAAAAAAAAAAAA-- AA-AAAAAAAAAAAAAAAAAA-- AAAAAAAAAAAAAAAAAAAAA-- AAAAAAAAAAAAAAAAAAAAA-- AAAAAAAAAAAAAAAAAAAAA-- AAAAAAAAAAAAAAAAAAAAA-- --AAAAAAAAABBBBBBBBBA-- --AAAAAAAAABBBBBBBBBA-- --BBBBBBBBBBBBBBBBBBB-- --DBBBBBBBBBBBBBBBBBB-- --DBBBBBBBBBBBBBBBBBB-- 
-----AAAAAAAAAAAAAAA--- -----AAAAAAAAAAAAAAA--- -----AAAAAAAAAAAAAAA--- -----AAAAAAAAAAAAAAA--- -----AAAAAAAAAAAAAAA--- -----AAAAAAAAAAAAAAA--- -----AAAAAAAAAAAAAAA--- -----AAAAAAAAAAAAAAA--- -----AAAAAAAAAAAAAAA--- -----AAAAAAAAAAAAAAAA-- -----AAAAAAAAAAAAAAAA-- ---AAAAAAAAAAAAAAAAAA-- AA-AAAAAAAAAAAAAAAAAA-- AA-AAAAAAAAAAAAAAAAAA-- AAAAAAAAAAAAAAAAAAAAA-- AAAAAAAAAAAAAAAAAAAAA-- AAAAAAAAAAAAAAAAAAAAA-- AAAAAAAAAAAAAAAAAAAAA-- --AAAAAAAAABBBBBBBBBA-- --AAAAAAAAABBBBBBBBBA-- --BBBBBBBBBBBBBBBBBBB-- --DBBBBBBBBBBBBBBBBBB-- --DBBBBBBBBBBBBBBBBBB-- 
-----AAAAAAAAAAAAA----- -----AAAAAAAAAAAAA----- -----AAAAAAAAAAAAA----- ---AAAAAAAAAAAAAAA----- ---AAAAAAAAAAAAAAA----- ---AAAAAAAAAAAAAAA----- ---AAAAAAAAAAAAAAAAA--- ---AAAAAAAAAAAAAAAAA--- ---AAAAAAAAAAAAAAAAA--- ---AAAAAAAAAAAAAAAAAA-- ---AAAAAAAAAAAAAAAAAA-- --AAAAAAAAAAAAAAAAAAA-- --AAAAAAAAAAAAAAAAAAA-- --AAAAAAAAAAAAAAAAAAA-- AAAAAAAAAAAAAAAAAAAAA-- AAAAAAAAAAAAAAAAAAAAA-- AAAAAAAAAAAAAAAAAAAAA-- --AAAAAAAAAAAAAAAAAAA-- --AAAAAAAAABBBBBBBBBA-- --AAAAAAAAABBBBBBBBBA-- --BBBBBBBBBBBBBBBBBBB-- --BBBBBBBBBBBBBBBBBBB-- --BBBBBBBBBBBBBBBBBBB-- 
---AAAAAAAAAAAAAAA----- ---AAAAAAAAAAAAAAA----- ---AAAAAAAAAAAAAAA----- ---AAAAAAAAAAAAAAA----- ---AAAAAAAAAAAAAAA----- ---AAAAAAAAAAAAAAA----- ---AAAAAAAAAAAAAAA----- ---AAAAAAAAAAAAAAA----- ---AAAAAAAAAAAAAAA----- ---AAAAAAAAAAAAAAAAA--- ---AAAAAAAAAAAAAAAAA--- --AAAAAAAAAAAAAAAA--A-- --AAAAAAAAAAAAAAAA--A-- --AAAAAAAAAAAAAAAA--A-- --AAAAAAAAAAAAAAAAAAA-- --AAAAAAAAAAAAAAAAAAA-- --AAAAAAAAAAAAAAAAAAA-- --AAAAAAAAAAAAAAAAAAA-- --AAAAAAABBBBBBBBBBBA-- --AAAAAAABBBBBBBBBBBA-- --BBBBBBBBBBBBBBBBBBB-- --BBBBBBBBBBBBBBBBBBB-- --BBBBBBBBBBBBBBBBBBB-- 
---AAAAAAAAAAAAAAA----- ---AAAAAAAAAAAAAAA----- ---AAAAAAAAAAAAAAA----- ---AAAAAAAAAAAAAAA----- ---AAAAAAAAAAAAAAA----- ---AAAAAAAAAAAAAAA----- ---AAAAAAAAAAAAAAA----- ---AAAAAAAAAAAAAAA----- ---AAAAAAAAAAAAAAA----- ---AAAAAAAAAAAAAAAAA--- ---AAAAAAAAAAAAAAAAA--- --AAAAAAAAAAAAAAAA--A-- --AAAAAAAAAAAAAAAA--A-- --AAAAAAAAAAAAAAAA--A-- --AAAAAAAAAAAAAAAAAAA-- --AAAAAAAAAAAAAAAAAAA-- --AAAAAAAAAAAAAAAAAAA-- --AAAAAAAAAAAAAAAAAAA-- --AAAAAAABBBBBBBBBBBA-- --AAAAAAABBBBBBBBBBBA-- --BBBBBBBBBBBBBBBBBBB-- --BBBBBBBBBBBBBBBBBBB-- --BBBBBBBBBBBBBBBBBBB-- 
-----AAAAAAAAAAAAA----- -----AAAAAAAAAAAAA----- -----AAAAAAAAAAAAA----- -----AAAAAAAAAAAAA----- -----AAAAAAAAAAAAA----- -----AAAAAAAAAAAAA----- -----AAAAAAAAAAAAA----- -----AAAAAAAAAAAAA----- -----AAAAAAAAAAAAA----- ---AAAAAAAAAAAAAAA----- ---AAAAAAAAAAAAAAA----- ---AAAAAAAAAAAAAAA--A-- ---AAAAAAAAAAAAAAA--A-- ---AAAAAAAAAAAAAAA--A-- ---AAAAAAAAAAAAAAA--A-- ---AAAAAAAAAAAAAAA--A-- ---AAAAAAAAAAAAAAA--A-- ---AAAAAAAAAAAAAAA--A-- ---AAAAAABBBBBBBBBBBA-- ---AAAAAABBBBBBBBBBBA-- ---BBBBBBBBBBBBBBBBBB-- ---BBBBBBBBBBBBBBBBBB-- ---BBBBBBBBBBBBBBBBBB-- 
------AAAAAAAAAAA------ ------AAAAAAAAAAA------ ------AAAAAAAAAAA------ ------AAAAAAAAAAA------ ------AAAAAAAAAAA------ ------AAAAAAAAAAA------ ------AAAAAAAAAAA------ ------AAAAAAAAAAA------ ------AAAAAAAAAAA------ ------AAAAAAAAAAA------ ------AAAAAAAAAAA------ ------AAAAAAAAAAA------ -----AAAAAAAAAAAA-AAA-- -----AAAAAAAAAAAA-AAA-- -----AAAAAAAAAAAA-AA--- -----AAAAAAAAAAAA-AA--- -----AAAAAAAAAAAA-AA--- -----AAAAAAAAAAAA-AA--- -----AAAABBBBBBBBBAA--- -----AAAABBBBBBBBBAA--- -----BBBBBBBBBBBBBBB--- -----BBBBBBBBBBBBBBB--- -----BBBBBBBBBBBBBBB--- 
------AAAAAAAAAAA------ ------AAAAAAAAAAA------ ------AAAAAAAAAAA------ ------AAAAAAAAAAA------ ------AAAAAAAAAAA------ ------AAAAAAAAAAA------ ------AAAAAAAAAAA------ ------AAAAAAAAAAA------ ------AAAAAAAAAAA------ ------AAAAAAAAAAA------ ------AAAAAAAAAAA------ ------AAAAAAAAAAA------ -----AAAAAAAAAAAA-AAA-- -----AAAAAAAAAAAA-AAA-- -----AAAAAAAAAAAA-AA--- -----AAAAAAAAAAAA-AA--- -----AAAAAAAAAAAA-AA--- -----AAAAAAAAAAAA-AA--- -----AAAABBBBBBBBBAA--- -----AAAABBBBBBBBBAA--- -----BBBBBBBBBBBBBBB--- -----BBBBBBBBBBBBBBB--- -----BBBBBBBBBBBBBBB--- 
------AAAAAAAAA-------- ------AAAAAAAAA-------- ------AAAAAAAAA-------- ------AAAAAAAAA-------- ------AAAAAAAAA-------- ------AAAAAAAAA-------- ------AAAAAAAAA-------- ------AAAAAAAAA-------- ------AAAAAAAAA-------- ------AAAAAAAAA-------- ------AAAAAAAAA-------- ------AAAAAAAA--------- ------AAAAAAAA----AA--- ------AAAAAAAA----AA--- ------AAAAAAAA----AA--- ------AAAAAAAA---AAA--- ------AAAAAAAA---AAA--- ------AAAAAAAA---A----- ------AAABBBBB---A----- ------AAABBBBB---A----- ------BBBBBBBB-BBB----- ------BBBBBBBBBBBB----- ------BBBBBBBBBBBB----- 
-----------A----------- -----------A----------- ---------AAA----------- ---------AAA----------- ---------AAA----------- ---------AAA----------- ---------AAA----------- ---------AAA----------- ---------AAA----------- ---------AAA----------- ---------AAA----------- ---------AAA----------- ------AAAAAA--AAAA----- ------AAAAAA--AAAA----- ------AAAAAAAAAAAA----- --------AAAAAAAAAA----- --------AAAAAAAAAA----- --------AAAAAAAAAA----- --------AAAABBAAAA----- --------AAAABBAAAA----- --------BBBBBBBBB------ ---------BBBBBBBB------ ---------BBBBBBBB------ 
-----------A----------- -----------A----------- ---------AAA----------- ---------AAA----------- ---------AAA----------- ---------AAA----------- ---------AAA----------- ---------AAA----------- ---------AAA----------- ---------AAA----------- ---------AAA----------- ---------AAA----------- ------AAAAAA--AAAA----- ------AAAAAA--AAAA----- ------AAAAAAAAAAAA----- --------AAAAAAAAAA----- --------AAAAAAAAAA----- --------AAAAAAAAAA----- --------AAAABBAAAA----- --------AAAABBAAAA----- --------BBBBBBBBB------ ---------BBBBBBBB------ ---------BBBBBBBB------ 
----------------------- ----------------------- ----------------------- ----------------------- ----------------------- ----------------------- ----------------------- ----------------------- ----------------------- ----------------------- ----------------------- ----------------------- ------------AAA-------- ------------AAA-------- ------------AA--------- ------------AA--------- ------------AA--------- ------------AA--------- ------------AA--------- ------------AA--------- ----------------------- ----------------------- ----------------------- 
