model
size = 24 23 20, scale = 0.05, origin = -y
material 
  colors = A:#F33 B:#C33 C:#700 D:#933 E:#100 F:#D00 G:#800 H:#900 I:#C00 J:#A00 K:#500 L:#600 M:#300 N:#B00 O:#400 P:#200 Q:#C30 R:#870E1D S:#F9F
voxels
------------------------ ------------------------ ------------------------ ------------------------ ------------------------ ------------------------ ------------------------ ------------------------ ------------------------ ---------AAAA----------- --------AAAAAA---------- --------AAAAAA---------- --------AAAAAA---------- --------AAAAAA---------- ---------BBBB----------- ----C------------------- ----AA------------------ ----AA------------------ ----AA------------------ ----CA------------------ ----CB------------------ ------------------------ ------------------------ 
------EE-----EE--------- ------BB-----BB--------- ------AA-----AA--------- ------AA-----BB--------- ------AA-----AA--------- ------AA-----AA--------- ------------------------ --------AAAAAA---------- -------BBBBBBBB--------- ------QQQQQQQQQQ-------- ------BBBBBBBBBA-------- ------BBBBBBBBBA-------- ------AAAAAAAAAA-------- ------BBBBBBBBBA-------- ----CCBBBCCCCBBA-------- ----AAAAAAAAAAA--------- ----AAA-AAAAAA---------- ----AAAA---------------- ----AA------------------ ----AA------------------ ----AA------------------ ----CD------------------ ------------------------ 
------EE-----EE--------- ------RR-----RR--------- ------AA-----AA--------- ------AA-----BB--------- ------BB-----BB--------- ------AA--AA-AA--------- -------AAAAAAAA--------- ------AAAAAAAAAA-------- -----BBBBBBBBBBAA------- -----FFFFFFFFFFAA------- -----JJJJJJJJJJAA------- ----KKKKKKKKKKKAAA------ ----BBBBBBBBBBBAAA------ -----AAAAAAAAAAAA------- ----CCCCCCCCCCCAA------- ----AAAAAAAAAAAAA------- ----AAAAAAAAAAAA-------- ----AAAAAAAAAAA--------- ----AA----AA------------ ----AA------------------ ----AA------------------ ----AA------------------ ------------------------ 
------EE-----EE--------- ------BB-----BB--------- ------AA-----AA--------- ------AA-----DD--------- ------BB--BB-BB--------- ------AAAAAAAAA--------- ------AAAAAAAAAA-------- -----AAAAAAAAAAAA------- ----AAAAAAAAAAAAAA------ ----BBBBBBBBBBBAAA------ ----SEEEEEEEEEEAAA------ ---EEEEEEEEEEEEAAAA----- ---MMMMMMMMMMMMAAAA----- ----AAAAAAAAAAAAAA------ ----AAAAAAAAAAAAAA------ ----DDDDDDDDDDDDDA------ ----BBBBBBBBBBBAA------- ----BBBBBBBBBBBA-------- ----AAAAAAAAAAA--------- ----AA----AA------------ ----AA------------------ ----A------------------- ----C------------------- 
------------------------ ------------------------ ------------------------ ------AA-----JA--------- ------AAAAAAAAA--------- ------AAAAAAAAAA-------- -----AAAAAAAAAAAA------- ----AAAAAAAAAAAAAA------ ---AAAAAAAAAAAAAAAA----- ---AAAAAAAAAAAAAAAA----- ---SMMMMMMMMMMMAAAA----- ---EEEEEEEEEEEEAAAA----- ---CCCCCCCCCCCCAAAA----- ---AAAAAAAAAAAAAAAA----- ---BBBBBBBBBBBBAAAA----- ---BBBBBBBBBBBBAAAA----- ----DDDDDDDDDDDDDD------ ----DDDDDDDDDDDDD------- ----CCCCCCCCCCCA-------- ----CC-AAAAAAAA--------- ----CC------------------ ----KK------------------ ------------------------ 
------------------------ ------------------------ ------------------------ ------AAAAAAAAA--------- ------AAAAAAAAAA-------- -----AAAAAAAAAAAA------- ----AAAAAAAAAAAAAA------ ---AAAAAAAAAAAAAAAA----- ---AAAAAAAAAAAAAAAA----- --AAAAAAAAAAAAAAAAAA---- --BBBBBBBBBBBBBBAAAA---- --BBBBBBBBBBBBBAAAAA---- --AAAAAAAAAAAAAAAAAA---- --AAAAAAAAAAAAAAAAAA---- --AAAAAAAAAAAAAAAAAA---- ---AAAAAAAAAAAAAAAA----- ---AAAAAAAAAAAAAAAA----- ----AAAAAAAAAAAAAA------ -----AAAAAAAAAAAA------- ------AAAAAAAAAA-------- --------AAAAAA---------- ------------------------ ------------------------ 
------------------------ ------------------------ ------------------------ ------AAAAAAAAA--------- ----AAAAAAAAAAAAA------- ---AAAAAAAAAAAAAAA------ ---BBBBBBBBBBBBBAAA----- ---DDDDDDDDDDDDDDDA----- --BBBBBBBBBBBBBBAAAA---- --BBBBBBBBBBBBBBAAAA---- --AAAAAAAAAAAAAAAAAA---- --AAAAAAAAAAAAAAAAAA---- --AAAAAAAAAAAAAAAAAA---- --AAAAAAAAAAAAAAAAAA---- --AAAAAAAAAAAAAAAAAA---- --AAAAAAAAAAAAAAAAAA---- ---AAAAAAAAAAAAAAAA----- ---AAAAAAAAAAAAAAAA----- ----AAAAAAAAAAAAAA------ -----AAAAAAAAAAAA------- -------AAAAAAAA--------- ------------------------ ------------------------ 
------------------------ ------------------------ ---------AAAA----------- ------AAAAAAAAAA-------- ---AAAAAAAAAAAAAA------- --BBBBBBBBBBBBAAAA------ -CCCCCCCCCCCCCCCAAA----- NNNNNNNNNNNNNNNNAAAA---- HHHHHHHHHHHHHHHHHHHA---- LLLLLLLLLLLLLLLLLLLA---- -BBBBBBBBBBBBBBBAAAAA--- -AAAAAAAAAAAAAAAAAAAA--- -AAAAAAAAAAAAAAAAAAAA--- -AAAAAAAAAAAAAAAAAAAA--- --AAAAAAAAAAAAAAAAAA---- --AAAAAAAAAAAAAAAAAA---- --AAAAAAAAAAAAAAAAAA---- ---AAAAAAAAAAAAAAAA----- ----AAAAAAAAAAAAAA------ -----AAAAAAAAAAAA------- ------AAAAAAAAAA-------- ---------AAAA----------- ------------------------ 
------------------------ ------------------------ --------AAAAAA---------- ------AAAAAAAAAA-------- ---AAAAAAAAAAAAAA------- --DDDDDDDDDDDDAAAA------ IIIIIIIIIIIIIIIIAAA----- -KKKKKKKKKKKKKKKAAAA---- -EEEEEEEEEEEEEEEAAAA---- IIIIIIIIIIIIIIIIAAAAA--- GGGGGGGGGGGGGGGGAAAAA--- -AAAAAAAAAAAAAAAAAAAA--- -AAAAAAAAAAAAAAAAAAAA--- -AAAAAAAAAAAAAAAAAAAA--- -AAAAAAAAAAAAAAAAAAAA--- --AAAAAAAAAAAAAAAAAA---- --AAAAAAAAAAAAAAAAAA---- ---AAAAAAAAAAAAAAAA----- ----AAAAAAAAAAAAAA------ -----AAAAAAAAAAAA------- ------AAAAAAAAAA-------- --------AAAAAA---------- ------------------------ 
------------------------ ------------------------ --------AAAAAA---------- ------AAAAAAAAAA-------- --AAAAAAAAAAAAAAAA------ GGGGGGGGGGGGGGAAAAA----- IIIIIIIIIIIIIIIIAAA----- JJJJJJJJJJJJJJJJAAAA---- GGGGGGGGGGGGGGGGAAAA---- FFFFFFFFFFFFFFFFAAAAA--- GGGGGGGGGGGGGGGGAAAAA--- -AAAAAAAAAAAAAAAAAAAA--- -AAAAAAAAAAAAAAAAAAAA--- -AAAAAAAAAAAAAAAAAAAARRR -AAAAAAAAAAAAAAAAAAAA--R --AAAAAAAAAAAAAAAAAA---R --AAAAAAAAAAAAAAAAAA---- ---AAAAAAAAAAAAAAAA----- ---AAAAAAAAAAAAAAAA----- ----AAAAAAAAAAAAAA------ ------AAAAAAAAAA-------- --------AAAAAA---------- ------------------------ 
------------------------ ------------------------ --------AAAAAA---------- ------AAAAAAAAAA-------- --AAAAAAAAAAAAAAAA------ GGGGGGGGGGGGGGAAAAA----- FFFFFFFFFFFFFFFFAAA----- HHHHHHHHHHHHHHHHHHHA---- OOOOOOOOOOOOOOOOAAAA---- FFFFFFFFFFFFFFFFAAAAA--- CCCCCCCCCCCCCCCCAAAAA--- -AAAAAAAAAAAAAAAAAAAA--- -AAAAAAAAAAAAAAAAAAAA--- -AAAAAAAAAAAAAAAAAAAA--- -AAAAAAAAAAAAAAAAAAAA--- --AAAAAAAAAAAAAAAAAA---- --AAAAAAAAAAAAAAAAAA---- ---AAAAAAAAAAAAAAAA----- ---AAAAAAAAAAAAAAAA----- ----AAAAAAAAAAAAAA------ ------AAAAAAAAAA-------- --------AAAAAA---------- ------------------------ 
------------------------ ------------------------ --------AAAAAA---------- ------AAAAAAAAAA-------- ---AAAAAAAAAAAAAA------- --DDDDDDDDDDDDAAAA------ NNNNNNNNNNNNNNNNAAA----- -CCCCCCCCCCCCCCCAAAA---- -MMMMMMMMMMMMMMMAAAA---- JJJJJJJJJJJJJJJJAAAAA--- JAAAAAAAAAAAAAAAAAAAA--- -AAAAAAAAAAAAAAAAAAAA--- -AAAAAAAAAAAAAAAAAAAA--- -AAAAAAAAAAAAAAAAAAAA--- -AAAAAAAAAAAAAAAAAAAA--- --AAAAAAAAAAAAAAAAAA---- --AAAAAAAAAAAAAAAAAA---- ---AAAAAAAAAAAAAAAA----- ----AAAAAAAAAAAAAA------ -----AAAAAAAAAAAA------- ------AAAAAAAAAA-------- --------AAAAAA---------- ------------------------ 
------------------------ ------------------------ ---------AAAA----------- ------AAAAAAAAAA-------- ---AAAAAAAAAAAAAA------- --BBBBBBBBBBBBAAAA------ -LLLLLLLLLLLLLLLLLA----- HHHHHHHHHHHHHHHHHHHA---- CCCCCCCCCCCCCCCCAAAA---- CCCCCCCCCCCCCCCCAAAA---- -BBBBBBBBBBBBBBBAAAAA--- -AAAAAAAAAAAAAAAAAAAA--- -AAAAAAAAAAAAAAAAAAAA--- -AAAAAAAAAAAAAAAAAAAA--- --AAAAAAAAAAAAAAAAAA---- --AAAAAAAAAAAAAAAAAA---- --AAAAAAAAAAAAAAAAAA---- ---AAAAAAAAAAAAAAAA----- ----AAAAAAAAAAAAAA------ -----AAAAAAAAAAAA------- ------AAAAAAAAAA-------- ---------AAAA----------- ------------------------ 
------------------------ ------------------------ ------------------------ ------AAAAAAAAA--------- ----AAAAAAAAAAAAA------- ---AAAAAAAAAAAAAAA------ ---BBBBBBBBBBBBBAAA----- ---BBBBBBBBBBBBBAAA----- --BBBBBBBBBBBBBBAAAA---- --AAAAAAAAAAAAAAAAAA---- --AAAAAAAAAAAAAAAAAA---- --AAAAAAAAAAAAAAAAAA---- --AAAAAAAAAAAAAAAAAA---- --AAAAAAAAAAAAAAAAAA---- --AAAAAAAAAAAAAAAAAA---- --AAAAAAAAAAAAAAAAAA---- ---AAAAAAAAAAAAAAAA----- ---AAAAAAAAAAAAAAAA----- ----AAAAAAAAAAAAAA------ -----AAAAAAAAAAAA------- -------AAAAAAAA--------- ------------------------ ------------------------ 
------------------------ ------------------------ ------------------------ ------AAAAAAAAA--------- ------AAAAAAAAAA-------- -----AAAAAAAAAAAA------- ----AAAAAAAAAAAAAA------ ---AAAAAAAAAAAAAAAA----- ---AAAAAAAAAAAAAAAA----- --AAAAAAAAAAAAAAAAAA---- --BBBBBBBBBBBBBBAAAA---- --DDDDDDDDDDDDDDDDDB---- --BBBBBBBBBBBBBBAAAA---- --AAAAAAAAAAAAAAAAAA---- --AAAAAAAAAAAAAAAAAA---- ---AAAAAAAAAAAAAAAA----- ---AAAAAAAAAAAAAAAA----- ----AAAAAAAAAAAAAA------ -----AAAAAAAAAAAA------- ------AAAAAAAAAA-------- --------BBBBBB---------- ------------------------ ------------------------ 
------EE-----EE--------- ------AA-----DD--------- ------AA-----AA--------- ------AA-----AA--------- ------BBBBBBBBB--------- ------AAAAAAAAAA-------- -----AAAAAAAAAAAA------- ----AAAAAAAAAAAAAA------ ---AAAAAAAAAAAAAAAA----- ---BBBBBBBBBBBBBAAA----- ---SEEEEEEEEEEEEAAA----- ---EEEEEEEEEEEEEAAB----- ---OOOOOOOOOOOOOAAA----- ---BBBBBBBBBBBBBAAA----- ---BBBBBBBBBBBBBAAA----- ---JAAAAAAAAAAAAAAA----- ----CCCCCCCCCCCCAA------ ----CCCCCCCCCCCCA------- ----CCCCCCCCCCCA-------- ----LLAAAAAAAAA--------- ----CC------------------ ----CC------------------ ------------------------ 
------EE-----EE--------- ------DD-----DD--------- ------AA-----AA--------- ------AA-----AA--------- ------BB--BB-BB--------- ------AAAAAAAAA--------- ------AAAAAAAAAA-------- -----AAAAAAAAAAAA------- ----AAAAAAAAAAAAAA------ ----BBBBBBBBBBBBAA------ ----SPPPPPPPPPPPAA------ ---EEEEEEEEEEEEEAAB----- ---KKKKKKKKKKKKKAAA----- ----BBBBBBBBBBBBAA------ ----CCCCCCCCCCCCAA------ ----BBBBBBBBBBBBAA------ ----BBBBBBBBBBBBA------- ----AAAAAAAAAAAA-------- ----AAAAAAAAAAA--------- ----AA----AA------------ ----AA------------------ ----CB------------------ ------------------------ 
------EE-----EE--------- ------DD-----DD--------- ------AA-----AA--------- ------AA-----AA--------- ------DD-----AA--------- ------AA--AA-AA--------- -------AAAAAAAA--------- ------AAAAAAAAAA-------- -----BBBBBBBBBBBA------- -----FFFFFFFFFFFA------- -----FFFFFFFFFFFA------- ----DDDDDDDDDDDDBB------ ----BBBBBBBBBBBBAA------ -----AAAAAAAAAAAA------- ----CCCCCCCCCCCCA------- ----AAAAAAAAAAAAA------- ----AAAAAAAAAAAA-------- ----AAAAAAAAAAA--------- ----AA----AA------------ ----AA------------------ ----AA------------------ ----CB------------------ ------------------------ 
------------------------ ------------------------ ------------------------ ------------------------ ------------------------ ------------------------ ------------------------ --------AAAAAA---------- -------BBBBBBBB--------- ------BBBBBBBBBB-------- ------BBBBBBBBBB-------- ------AAAAAAAAAA-------- ------AAAAAAAAAA-------- ------AAAAAAAAAA-------- ----CCCBCCCCCAAA-------- ----AA-AAAAAAAA--------- ----AA--AAAAAA---------- ----AA------------------ ----AA------------------ ----AA------------------ ----CA------------------ ------------------------ ------------------------ 
------------------------ ------------------------ ------------------------ ------------------------ ------------------------ ------------------------ ------------------------ ------------------------ ------------------------ ---------AAAA----------- --------BBBBBB---------- --------AAAAAA---------- --------AAAAAA---------- --------ABBBBB---------- ---------BBBB----------- ----BB------------------ ----CA------------------ ----CA------------------ ----CA------------------ ----CA------------------ ------------------------ ------------------------ ------------------------ 
