model
size = 14 12 20, scale = 0.05, origin = -y
material 
  colors = A:#9F6 B:#FF3 C:#111 D:#EEE E:#0FF F:#39C G:#C6F H:#F90 I:#C0C J:#100
voxels
-------------- -------------- -------------- -------------- ----J--------- -------------- -------------- -------------- -------------- -------------- -------------- -------------- 
-------------- -------------- -------------- -------------- ---HHH-------- ---HHH-------- -------------- ---J-J-------- -------------- -J-----J------ -------------- -------------- 
-------------- -------------- -------------- -------------- --DDDDD------- --DDDDD------- --DDDDD------- --DDDDD------- -DD---DD------ -DD---DD------ -------------- -------------- 
-------------- -------------- -------------- ---BBB-------- --BBBBB------- -BBBBBBB------ -BBBBBBB------ -BBBBBBB------ --BBBBB------C ---BBB-------C -------------C -------------- 
--F---F------- -------------- BBBBBBBBB----- BBBBBBBBB----- BBBBBBBBB----- BBBBBBBBB----- BBBBBBBBB----- BBBBBBBBB----C BBBBBBBBB----- BBBBBBBBB----- BBBBBBBBB----- -------------C 
--F---F------- --E---E------- --E---E------- --EGGGE------- --AAAAA------- --AAAAA------- --AAAAA------- --AAAAA------C --CC-CC------C --CCCCCCCCCCCC ---CCC-------- -------------C 
--F---F------- --E---E------- --E---E------- --EGGGE------- --AAAAA------- --AAAAA------- --AAAAA------- --AAAAA------C -------------- -------------- -------------- -------------C 
-------------- -------------- -------------- --AAAAA------- --AAAAA------- --AAAAA------- --AAAAA------- --AAAAA------- -------------C -------------C -------------C -------------- 
-------------- -------------- -------------- --AAAAA------- --AAAAA------- --AAAAA------- --AAAAA------- --AAAAA------- -------------- -------------- -------------- -------------- 
-------------- -------------- -------------- --AAAAA------- --AAAAA------- --AAAAA------- --AAAAA------- --AAAAA------- -------------- -------------- -------------- -------------- 
-------------- -------------- -------------- --AAAAA------- --AAAAA------- --AAAAA------- --AAAAA------- --AAAAA------- -------------- -------------- -------------- -------------- 
-------------- -------------- -------------- --AAAAA------- --AAAAA------- --AAAAA------- --AAAAA------- --AAAAA------- -------------- -------------- -------------- -------------- 
-------------- -------------- -------------- --AAAAA------- --AAAAA------- --AAAAA------- --AAAAA------- --AAAAA------- -------------- -------------- -------------- -------------- 
--F---F------- -------------- -------------- --AAAAA------- --AAAAA------- --AAAAA------- --AAAAA------- --AAAAA------- -------------- -------------- -------------- -------------- 
--F---F------- --E---E------- --E---E------- --EGGGE------- --AAAAA------- --AAAAA------- --AAAAA------- --AAAAA------- -------------- -------------- -------------- -------------- 
--F---F------- --E---E------- --E---E------- --EGGGE------- --AAAAA------- --AAAAA------- --AAAAA------- --AAAAA------- -------------- -------------- -------------- -------------- 
-------------- -------------- -------------- ----I--------- ----I--------- ----I--------- ----I--------- -------------- -------------- -------------- -------------- -------------- 
-------------- -------------- -------------- -------------- -------------- -------------- ----I--------- -------------- -------------- -------------- -------------- -------------- 
-------------- -------------- -------------- -------------- -------------- -------------- ----I--------- -------------- -------------- -------------- -------------- -------------- 
-------------- -------------- -------------- -------------- -------------- -------------- ----C--------- -------------- -------------- -------------- -------------- -------------- 
