model
size = 15 32 32, scale = 0.05, origin = -y
material 
  colors = A:#222 B:#111 C:#033 D:#000 E:#001 F:#FFF G:#002 H:#666 I:#BBB J:#AAA K:#DDD L:#444 M:#888 N:#333 O:#969696 P:#CCC Q:#066 R:#EDEDED S:#010 T:#EEE U:#555 V:#B3B3B3 W:#699 X:#00606F Y:#336 Z:#999 Aa:#036 Ab:#D0D0D0 Ac:#099 Ad:#9CC Ae:#0C9 Af:#0CC Ag:#D6F3F3 Ah:#366 Ai:#797979 Aj:#096
voxels
291-5B10-5B444-7E2(8-7B)8-7C9-5C10-5A399-BABNLAC7-B4A3CA6-5A2C2A7-2A2CBCA8-B3CA2C8-B4CBC8-B3ACAB8-BA4CB9-C2A2C354-BABNLAC7-B4A2-CA6-5A2-2A6-C2A2CBCAC6-AB3CA3C6-2B4CB2C6-2B3ACABC6-2BA4CBC7-AC2A2CA8-A2CBA2C9-AB3A324-B5-C7-BA2-A3-A5-E2A2-A3-2A4-2C2A2C2-A2C4-BAB3C2-3C4-3B3C2-3C5-2B3ACABC6-2BA4CBC6-GAC2A2CAB7-A2CBA2C8-2AB3AC323-BAB3-C7-BA2-A3-A5-E2A2-A3-2A4-2CA2-C3-2C4-BAB2-C3-2C4-3B2-C3-2C4-A2B2-AC2-2C5-2BA3C2-C6-GAC2A2-AB6-2(BA2C)A7-2AB3AC9-ABE2C37-BAB3CA4CA3-A2B4CB3CB3-3B3ACAB3C4-2BA4CB7-GAC2A2CA7-2(BA2C)7-B2AB3AC7-B2ABE3C7-B2CBA2C10-CB2AC9-B2CAEBC8-BAL3BA54-CAaC2A9-2CLCABA8-GBA3-A7-2(AB)3-CA6-B4A3-A5-E-4A4-A3-G2C2A2CB3-2C2-2(AB)2-CA3-2C2-4B2-2C3-CB3-A2B2-AC2-2C4-3B2(2-2C)5-GA2-AC2-B6-BA2CB2-CA6-B2AB3ACA7-2ABE3C35-2BAB3CA4CA2-4B4CB3CB2-2A2B3ACAB3C2-4BA4CB3C2-2SGAC2A2CAB2C2-2S2(BA2C)A2C2-3B2AB3ACABC2-3B2ABE4C2A2-3B2CB2(A2C)B3-2BACB2A4CA3-A2B2CAEBC2BC3-BEBAL3BACBC2-BGEAC2AE2BABE2-BC2BC7AB2-NAG2BCGCA2B2A2-4ACAaC3A2BC2-BCA2CLCAB2ABC2-BABGBAC2-2(AC)-C3(AB)N2-CASC-BC2B4AC2-ASB-BCE5AC3-AB-CG2C2A2CBC2-2C-C2(AB)2-CAC2-2C-C4B2-2CB2-2C2-2AB4-CA2-2C2-3B4-C2-2CA3-BGA2-AC2-BC4-2BA2-BA2-AC5-B2ABA2-CA7-2ABE3C34-3BAB3CA4CA-3A2B4CB3CB-5B3ACAB3C-5BA4CB3C-3BGAC2A2CAB2C-4BA2CB2(A2C)-4B2AB3ACABC-4B2ABE4C2A-4B2CB2(A2C)B2-3BACB2A4CA2-4B2CAEBC2BC-3BEBAL3BACBC-3AGACQCB2ACAE-CBC2BC7AB-11FB2A-11I2BC2-10PABC2-7I2-ICAC-8T3-ASC-2C2B4AC2-ASC-2CE5AC3-AC-AG2C2A2CBC3-A-2ABA4-AC3-A-A3B4-CB3-A-C2AB4-CA2-2C2-3B4-2C2-CA2-2BG4-2C-BCB3-2BA2-BA2-AC5-B2ABA3-A7-2ABE3C9-CBA2C19-4B10-A3B11-4B11-C4A8-3C4B8-B2C4B8-A2C4A8-ABC4S8-C2A4B7-A2CB4EBA5-3CA5B7-2BC4BE7-CBC12FCAE12K2AB12HB2A6D5-D2BC5D-2D4-ABC6D2-D3-CAC4D-D2-D4-SA5J4-J3-SC3F-2(F4-)C2B-C6-C3-B-C-B6-C3-2(C-)B6-B3-C-C2A6-A3-C-A3B4-2C3-A2-2BG4-2C2-CB2-3B4-A3-CB3-2BA2-A3-AB5-B2ABE4C8-CBA2C19-3A11-3A12-B3(2A12-C)2(2B12-C)2S12-A2B12-B3E11-A3E11-C3K11-C2O12-E2D12-B2D12-A2D12-C3D3-2D6-C3D2(2-D)5-C2D3-D2-D5-C2D2-2(D4-)C2J2-2(J4-)A2R-R6-R3-A2C-B6-C3-2(C-)B6-B3-C-N-A6-A3-N-3B6-C3-B2-2B6-C3-B2-3B4-A3-CB3-2BA2-A3-AB5-B2AB3-2C8-CBA2C19-2B12-BA13-BN2(13-CA)3(13-CB)13-AB13-B2E12-A2F12-CL13-CD13-ED13-BD13-AD13-C2Q4-2Q6-C2D3-D2-D5-CD4-D2-D5-CD3-2(D4-)AD3-2(D4-)BH2-H6-H3-CAb2-Ab6-Ab3-C-A-B6-B3-A-B-A6-A3-B-Ah-B6-C3-Ah2-2B6-C3-A2-B-B4-A4-B3-B-A2-A4-B5-B2AB3-2C8-CBA2C19-B2(13-2B)13-BA13-AB13-BA13-2A13-AB13-2B13-BR13-BU2(13-BD)13-ED13-BI13-AI13-CAd5-2Ad6-2(CI4-I2-I5-)CR3-2(R4-)AD3-2(D4-)2(CD2-D6-D3-)CF2-F6-F3-C-C2A6-A3-2(C-)B6-C3-C2-B8-A2-B2-2B6-C3-B3-2B4-A3-B5-B2ABE3-C7-C5-A9-CB2AC4-G13-GB13-BC13-2C13-CA2(13-2A)13-AC13-CF13-AJ2(13-BD)13-GD13-AD13-C2(D13-A)X5-2X6-CM4-M2-M5-CK4-K2-K5-AD3-2(D4-)BD3-2(D4-)2(CD2-D6-D3-)CV2-V6-V3-3C-A6-A3-2(C-)B6-C3-C-2B8-A2-B2-2B6-C3-B3-2B4-A3-B5-BA2-E3-C7-2CB3-A9-CB2A2C3-E13-EG13-GC13-CB13-BA13-AB13-BC13-2C13-CR13-BN4(13-BD)13-AD13-CR13-CAg5-2Ag6-2(CD4-D2-D5-)B2(D3-2(D4-)C)2(D2-D6-D3-C)H2-H6-H3-CF-2F6-F3-2(A-)B6-C3-A-2B8-A2-B2-2B10-B2-B-B9-B3-EBA7-A12-AC13-2C2-E13-EA13-AB3(13-2B)13-BC13-2C13-CZ3(13-AD)2(13-BD)13-AD13-AAi13-AX5-2X6-CP4-P2-P5-AU4-U2-U5-B2(D3-2(D4-)C)D2-D6-D3-CD2-D6-D3-AD2-D6-D3-BJ2-J6-J3-2(C-)B6-C3-C-2B8-A2(2-B)8-C2-B2-2B10-B3-EB8-A12-AC13-2C2-E13-EB13-BE13-EA13-2A13-AC13-2C13-CF13-AU13-C4(D13-B)D2(13-CO)13-CW5-2W6-CO4-O2-O5-BO4-O2-O5-CR3-2(R4-)CD3-2(D4-)CD2-D6-D3-BD2-D6-D3-CD2-D6-D3-BM2-M6-M3-C2(-B)6-C3-B-2E8-A2-E2-B8-C2-B2-2B10-B3-EB8-B12-AC13-2C2-E2(13-2E)13-EB3(13-2B)13-BF13-CU2(13-BD13-AD)13-BD2(13-CW)13-CJ5-2J6-A2(W4-M2-M5-C)Q3-2(Ad4-)CD3-2(D4-)CD2-D6-D3-AD2-D6-D3-BD2-D6-D3-AM2-M6-M3-2(C-)B6-C3-C-2E8-A2(2-E)8-C2-E2-2B10-B3-EB8-B12-AC13-2C2-B13-BE2(13-2E)13-EB13-2B13-BA13-AC13-CZ13-CD13-G2(D13-C)2(D13-A)2(D13-C)M5-2M6-BAc4-Ac2-Ac5-2C4-C2-C5-A2(D3-2(D4-)C)D2-D6-C3-AD2-D6-C3-BD2-D6-B3-EJ2-J6-A3-A-C-B6-C3-C-2B8-A2-B2-CB6-C3-C2-B-B9-B3-EBA7-B12-AC13-2C2-2(E13-2E13-EB13-B)A13-2A13-AV2(13-CD)13-E4(D13-A)Aj13-AM5-2M6-CD4-Ac2-Ac5-CD4-C2-C5-2(AD3-2(D4-))2(AD2-D6-C3-)AH2-H6-B3-A4F6-A3-2(A-)B6-C3-A-2C8-A2(2-C)B6-2(C3-)2B4-A3-A5-BA2-E3-C7-2CBA-CA9-CB2A2C3-E13-EB13-BE13-2E13-EB13-2B13-BC13-CA13-AF13-CJ13-C2(D13-B)4(D13-A)M5-2M6-CQ4-Q2-Q5-CAe4-Ae2-Ae5-CD3-2(D4-)AD3-2(D4-)SD2-D6-C3-AD2-D6-C3-BV-2V6-B3-B-3B6-A3-2(B-)B6-C3-B2-L8-A2-L2-2A6-C3-A3-2B4-A3-B5-B2ABE3-C7-C5-A9-CB2AC4-2B12-2(2B13-)BE13-EB13-2B13-BC13-2C13-CB13-B2R12-A2U12-BD13-AD13-BD13-AQ13-BQ13-N2Z4-2Z6-L2Q3-Q2-Q5-AQ4-Q2-Q5-CAf3-2(Af4-)AD3-2(D4-)SD2-D6-C3-BD2-D6-C3-E2(-F)6-B3-B2(-A)6-A3-A2(-C)6-C3-C2-2C6-C3-C2-B-B4-A4-B3-A-A2-A4-A5-B2AB3-2C8-CBA2C19-3A11-A2B2(12-3B)12-B2A12-A2N12-3N12-N2A12-A2B12-4B11-B3F11-A3L11-B2D12-G2D12-B2D12-A2D12-C3H3-2H6-A3D2(2-D)5-A2D3-D2-D5-A2D2-2(D4-)C2D2-2(D4-)A2H-H6-C3-B2Ab-Ab6-C3-2(B-)B6-B3-2(B-)B6-A3-B-3B6-C3-B2-2B6-C3-B2-3B4-A3-B4-2BA2-A3-A6-B2AB3-C9-CBA2C19-4B10-B3E11-E3B11-B4A9-6A9-2A4Y9-2Y4A9-6A9-2A4B9-7BA5-C3B4CB7-3C5K7-3A10O2A3C10D5C10DA2B2L6D5-AB2C5D-2D4-3A6D2-D3-C2B4D-D2-D4-2A5D4-D3-2A3J-2(J4-)B2R-R6-C3-2(B-)B6-C3-B2(-A)6-B3-A-3B6-A3-B-4B4-2C3-B2-2BG4-2C2-2B2-3B4-A3-B4-2BA2-A3-A6-B2ABE3C9-CBA2C20-3BAB3CA2C3B-5B4CBC3B-2BA2B3ACA4B-2A3BA4CB3A-2ABGAC2A2C4A-4BA2CBA2C3B-4B2AB3AC3B-2BEB2ABE3C3B-4B2CBA2CA3B2-A2BACB2A2C3A2-2A2B2CAEBC3A-2ABEBAL3B4A-9F5A-9K5C-9HAB3Aa-9D2AB2C2-8DB4A2-7D2-AC2A-8D3-3A-9J2-A2B-9F3-2B-3AC2A2CBC3-A-3BA4-AC3-B-3AB4-CB3-A-4B4-CA2-2B2-2EB4-2C2-2E2-2BG4-2C-3B3-2BA2-BA2-AB5-B2ABA3-A7-2ABE3C9-CBA2C21-2BAB3CA2C3B2-4B4CBC3B2-BA2B3ACA4B2-4BA4C4B2-2BGAC2A2CA3B2-A2BA2CBA2C3A2-E2B2AB3AC3E2-AEB2ABE3C3A2-A2B2CBA2C4A3-2BACB2A2C3N3-A2B2CAEBC3A3-BEBAL3BA3G2-BCGACQCB2A3B2-BGC3ACB2C3B2-F4GC2GAB3C2-FGCG4I2AB2G2-PCG5PB2A2C2-IGC4I2-AC2A-2TC5T2-CA2B-4B4AC2-A2B-8AC3-2A-3AC2A2CBC2-2A-3BAB2-CAC2-2B-3A2B2-2CB2-2A2-3B4-CA2-2B2-2EB4-C2-C2E3-EGA2-AC2-BE4-2BA2-BA2-AB5-B2ABA2-CA7-2ABE3C36-BAB3CAC4E3-3B4CB4E3-A2B3ACA4E4-2BA4C2B6-GAC2A2C2B6-BA2CBAC2A6-B2AB5A6-B2ABE4C6-B2CBA2C2A8-CB2AC9-B2CAEBC8-BAL3BA54-GAaC2A9-GCLCABA8-GBA3-A7-2(AB)3-CA6-B4A3-A5-A-4A4-A3-2BC2A2CB3-2B2-2CAB2-CA3-2C2-2C2B2-2(2C3-)A2B2-AC2-CA4-E2B2-2C2-CE5-GA2-AC2-B6-BA2CB2-CA6-B2AB3ACA7-2ABE3C308-BAB3-C7-2A2-A3-A5-2BA2-A3-AB4-2EA2-C3-CE4-3B2-C3-CB4-2AB2-C3-CA4-2AB2-AC2-CA5-ABA3C2-C6-EAC2A2-AB6-2(BA2C)A7-2AB3AC9-ABE2C309-B5-C7-2A2-A3-A5-3A2-A3-2A4-2E2A2C2-ACE4-2EB3C2-2CE4-3B3C2-2CB5-2B3ACABC6-2BA4CBC6-EAC2A2CAB7-A2CBA2C8-2AB3AC323-BABNLAC7-5A2-CA6-B4A2-2A6-E2A2CBCAC6-EB3CA3C6-2B4CB2C6-EB3ACABC6-2BA4CBC7-AC2A2CA8-A2CBA2C9-AB3A324-BABNLAC7-5A3CA6-E4A2C2A7-2A2CBCA8-B3CA2C8-B4CBC8-B3ACAB8-BA4CB9-C2A2C354-BABNLAC8-4A3C8-4A2CA8-2A2CBCA9-3CAC10-4CB124-
