model
size = 30 30 25, scale = 0.05, origin = -y
material 
  colors = A:#000 B:#111 C:#6C5B1F D:#846A24 E:#EEE F:#0D1300
voxels
------------------------------ ------------------------------ ------------------------------ ------------------------------ ------------------------------ ------------------------------ ------------------------------ ------------------------------ ------------------------------ ------------------------------ ------------------------------ ------------------------------ -----------------DD----------- -----------------DCDA--------- -----------------DCCA--------- -------------A---CCCA--------- -----------------AC----------- ---------------B-------------- ---------------B-------------- -----------B------------------ ------------BA--A------------- ------------A----------------- -------------A---------------- -------------A---------------- ------------------------------ ------------------------------ ------------------------------ ------------------------------ ------------------------------ ------------------------------ 
------------------------------ ------------------------------ ------------------------------ ------------------------------ ------------------------------ ------------------------------ ------------------------------ ------------------------------ ------------------------------ ------------------------------ ----------------DC------------ ---------------CCDDA---------- ---------------BDCCA---------- ---------------ADDDCA--------- -------------A-ADDDCA--------- -------------ABDDDDA---------- --------------AAAABB---------- ---------------BBB------------ -----------B---A---A---------- -----------BA-BBB-BA---A------ ----------AABB--BBB--AAA------ --------BBBAAB---B------------ --------AABABB---B-----A------ ---------AAA-A---------------- ----------AA------------------ ------------------------------ ------------------------------ ------------------------------ ------------------------------ ------------------------------ 
------------------------------ ------------------------------ ------------------------------ ------------------------------ ------------------------------ ------------------------------ ------------------------------ ------------------------------ ------------------------------ ---------------CD------------- ---------------DDCA----------- ---------------DCCDAA--------- --------------CDCCCAA--------- -------------CCCCDCA---------- -------------DCCCDCCA--------- -----------AADDDDCCDA--------- ------------BBACDCCBAB-------- ----------BB-A-AAAAABB-A------ ----------ABA-BAAAAAAAAB------ ----------ABA-AABBBBAAAB------ ---------AABBA--BBBBBBAAA----- ---------ABA-B---AAAABBAB----- --------AAABAB---AAAA-AAB----- ---------ABBAA---BB-A-BA------ -----------------AB-B--------- ------------------------------ ------------------------------ ------------------------------ ------------------------------ ------------------------------ 
------------------------------ ------------------------------ ------------------------------ ------------------------------ ------------------------------ ------------------------------ ------------------------------ ------------------------------ ------------------------------ ------------ACACC------------- -----------CCABDC-B----------- ---------DDCCCBCCCDB---------- ---------DCCDCDCDDDBAB-------- ----------CCDDCDCCDDABA------- ------------CCDCCCCCBAAAA----- -------AAAACCDCDCCDCBABAA----- ----------CDCCCCDCCCABAAB----- ----------CCAABAABAABAAAA----- ----------AAAAABBBBABBABA----- ----------ABBBABAAAAAABBA----- ---------AABBABABBABAABAB----- ---------AAAABBABBBBABAA------ -------AABBAABABBBAAABAB------ ------AAAABBBABA-ABBAABB------ -------AAAAB--AB-AABBBAA------ -------------AB---BAA--------- ------------------AA---------- ------------------------------ ------------------------------ ------------------------------ 
------------------------------ ------------------------------ ------------------------------ ------------------------------ ------------------------------ ------------------------------ -----------ABBA--------------- ----------DBBBBBA------------- ----------CCBBADCBB----------- ---------DDCDCCCCCCA---------- --------DDCCDCDDCDDBB--------- -------CCDCCCCDCDCCCAAB------- -------CCCCDDDCDCCDCBBBB------ ---A----DCCCCCCCCCDDBBABBA---- ---AA----DCDCCCCCCDCBAAABA---- ---A-AADCDCDDDDCDDDCBBAAB----- ---------DCCDDCCDCCCBBAABB---- ---------DCCAABAAABBAAAAAA---- ----------DCBAABAAABAABABB---- ---------ABCBAABBBBABAABBAB--- --------ABBCBBAAAABABABABBB--- --------BBADABBABBABAABBAA---- --------AABABAAABABBABBBAA---- ----------BBAAAAABBABABB------ --------ABAAAABABABAABBBB----- ----------ABA-AB-BBBBBBB------ -----------AA--A----A-A------- ------------------------------ ------------------------------ ------------------------------ 
------------------------------ ------------------------------ ------------------------------ -----------A-A---------------- ----------ABAAADA------------- --------DABAAAAADDB----------- -------DCCDDDDDCDDA----------- -------DCDDCDDDCCAAB---------- -------CCCDCCDCDDCCBA--------- ------CDCDCCDDDCDDDCA--------- ------CCCDCDCCCCCDCCABB------- ------DCCCCDCCDCDDCDBABAA----- ---A--CCCCCCDDDDDCCCBABBB----- ------DDDCDCDDCCCDDCABAABB---- ------DDCDDCCCCCDCDCABABBB---- -----DDDCCCCCCCCDDCCBABAABBB-- ---A--FCCCCDCCDDCCDCBBAABBBA-- ------FDCDDCBAABABBBAABBBAA--- ------CCCDDDABBBAABAAAABABB--- -------CDDDCABBBAAAABBAABBA--- -------BBDCCABABABBBBBBBAAB--- -------BACCDBBAAABBAAABBABB--- -------ABBABBAABBBABBAAABB---- --------AABBAAABBAAAABBAAB---- ---------BBBABABABAAAAAABAA--- ---------AABBBBAAAABBBBAAA---- -----------BAABA-AAABBAA------ -------------A------A--------- ------------------------------ ------------------------------ 
------------------------------ ------------------------------ -----------A------------------ ----------AAACC------CA------- ------CCCADCCDDDD----CA------- -----DCCCDDDDCCDDDDDA--------- -----DCDDCDDDCDCCDDDA--------- -----DCCCCDCCDDDDCCDB--------- -----DCDDDCCDCCCCDCCAB-------- -----DCCDDDCCCDCCDCDBAB------- -----DCDCDDDDDDDCDDDBAAB------ ------DCDCDCCDDDCCDDABABB----- ---A-DDCCCCDDCDCCCCCBBBBBBB--- ------CCDDCDCCDCCDCDBBBABAA--- ------EDDDDDCDCDCCCCBAABBBA--- ------EDCDDDDDDCCCCCBBBAAABB-- ---ADDDCCDCCCCDDCCCCBAABBBB--- -----FCCCCCCAAAAAAAAAABBAAAA-- -----DDCCDDCBABABBBABAABBAAB-- ------DDCDDCAABBBABBAAAABBBB-- ------DCCDDDABABAABABBAABAAA-- -------ACCCCAAAAABBABBBBAABB-- -------BABAAABBABBBABAAAAAB--- -------AABAABBBBAABBABABBBA--- -------AABBABBABBBAAABBAAA---- --------AAAAABAABBBBBAAAB----- ------A--ABABBBAAABAAAAB------ ------------BABBBAAB---------- ----------------B------------- ------------------------------ 
------------------------------ ------------------------------ -----B--B--A-CCCDDDCC-A------- ------AABAACCCCCCDCCCDA------- -----CCCCDCCDCDDDCDCCCAA------ -----DDCDCDCCDCCCDCCDAAA------ -----DDCCCDCDCDCCCDDBAB------- -----DDDCCDCCDCDCDDDABB------- -----DDCCCDDCCCDCDCDABBA------ -----DCDDCCCCCCDCCCDBAAA------ -----DDDCCCCDDCCDCCCBBBBA----- -----DCDDCDCDCDDDDCCBBAABA---- ---A-CDCCCDDDCDCDCDCBAAAAB---- ------DCDDDCDDDCCDCCAAABABB--- ------BCDCDDCDCDCDCDAAAABAABA- ------EDDDCDCDDCDCDCBABAABBB-- ---ADDDCCCCCDDDDDCDDBABAABBB-- -----DCDDDDCBBAAAABBABABABAB-- ----FCCCCDCCBBABBAAAABBBBBAA-- -----DCCCDCDBABABABABABBBBABA- -----DDCCCCDABAAAABBAAABAAABA- ------AACCCCBBBBAAAABBABABABB- ------BAABABBABAABBBBBAABABAA- -------BBBBBBBBBAABAAAABABBB-- ------BBABAAAABAABBBBAABABA--- --------BBBBAABBBBAAABBBBB---- -----AB-AAABBBBAABAAABBAA----- ------------BAABBBABAA-BB----- --------------BBBBB----------- ----------------B------------- 
------------------------------ -----A------CDC--------------- -----ABABAACCCCDDDCCC--------- -----DABCCDDDCDDDDCCDDA------- ----DDCDCDCDCDCCDCCDC-CAA----- ------ECCCCCDDDDDCCDCCCCA----- ----FDCDCDCCCCDDCCDBABAA------ -----DCCCCDDCDCDCDCBBBAA------ -----DCCDDDCCDCCCCCAABBB------ -----DCCDCCDCCDCCCCBAABAA----- -----DCCCDCCCCCDDDCBABABB----- -----DCDCCDCDCCDCDCBABBAAB---- ---A-CCDCDDCDCCDCDCBBBBBAB---- ------CDCCCCCCCCDDCBBAAAAAB--- ------EDDCCDDCDDCCDAABABBAAB-- ------EDCCCCCDCCDCDBBBABAABA-- ---ADDDCCCDDCCDDCCDABAABBBA--- -----DCDDCCCAABBBAABABAAABA--- ----FDCDCCDDBBBABABBAABABAB--- -----DCDDCDDAAABBBBBAABBAAB--- -----DDDCCCDAABBBBAAABAAAAA--- -----DAACCCCABBAAAAAAAABBBA--- ------BAAABBBBABBABBBBBAAABA-- -----ABBBAABABABBBAABABAAAA--- ------BAABBBABABBABBAAABAA---- --------ABAABAABABAAABABB----- ------A-BABAAAABABBABABA------ ---------ABAABBABAABBB-B------ -------------BABBBAB---------- --------------B--BB----------- 
-----B------------------------ -----BBAB--CCCDCCDDD---------- ----DCCCBDCCDDCCDDDCDD-------- ----DDDDDDDDDCCDCCCDCA-------- -----ECCDDCCCDCCCCCDCA-A------ ----EECCDDDCCCCCCDDCCCDCA----- ----DBCCCCDCDDDDDDCBAABBA----- ----FDDDCDCDCDDDDDDAAAAB------ ---DCDCDDDCCDCCDCDCBBBABB----- ----DDDDCDDDDCCDCCDBBABAB----- -----DCDCCCDCCDCDDCBABBAA----- -----DCDDCDDCDCCCDDAAAABAB---- ---A-CDCDDDCCDDCDDDABBBABAB--- ------DCDDCCDCCCCCCBBABBAAA--- ------EDDCCDDDCDCCDAAAAABBAB-- -----DDDCCCCCCCDDDDBBBAABBBB-- ---ADDCCCCDDDCCCCDDAAAABAABAA- -----DDCCCCCAABBAABAAAABBBABB- -----DCCCDCCABBBAABBBAAABABB-- ----FDCDDDDCBAAABABBBBBBBBB--- -----DCDDCDCABABBBBAAAAABAA--- -----DBBCCDCAABBABABAABBBAA--- -----DBAAABBBAAAAAAABABAAAA--- ----ABBAABBAABBABBBBABBABBA--- ----BAABBBBBBBAABBBABABAAA---- -----AB-BAAAAAAAAAAABBBBB----- ------AB-BABBBBAAAAAAABA------ ------BB--BAABBBBABBBBA------- ------------AAABBAAAB--------- -------------AB---B----------- 
------AB---------------------- ----AADDD--DCCDDCCDC---------- ----DDDCDCCDCDDCCDDDDD-------- ----DCCCDCDDCCCCDCCDCD-------- -----ECCCDDDCDDCCDCDCCA------- ----EDCCDDDCCDCDCDDABABB------ ----DCDDCCDCCDDDCCCBBAAAA----- ---FFCCDDCDCCCDCCCDABBBA------ --DDCCCDDDDDDCDDDCCAAABBA----- --DDCCDCDCCCCDDCCDCBABBAA----- ---DDCDCDDDCDDDDDCCABBAAA----- ----DCDDCCDDCDCCCCCAABAABA---- ----DDCCCCCCCDCCDDDABBBBABB--- ---ACDCCDCCDCCDCCDCBABABBAB--- ---ACCCCCCDCCDCDCDDBAABBABA--- ---ADDCCDDDCCDDCDDCBBAABBBB--- -----CDDDCDDDDCCDDDBBBABABB--- -----DCCCDCBABBAABBBABBAAAB--- -----CDDCCCBAABBBBBABABBBABBB- -----DCCCDCBAABBAAABBAABABBAB- -----DCCDDDBBABBAAABABBBAABB-- -----DBBCCDAAABBBBABAABAABAA-- -----DBABBBABAABABBAABABBABA-- -----ABABABBBBBBBABBAAABBABB-- -----BBBBAABBABAAAABABAAABB--- -----BAAABBABBBBBBAABAABA----- ---BBBBB-AAABBABABABAAAA------ ---A--AB--BBBBBABABABBB------- ------B-----ABBBBBAAB-A------- ------------AB---------------- 
-----BBB---------------------- ----ACDCDD-CCCDCDCCC---------- ----DCCCCCCCCCCCCCCDC--------- ----DCCCDCCCDCCDCDCDCA-------- -----ECCDDDCCCCDDDCCCA-------- ----EDDDCCDCDDDCDCDAAABA------ ----DDCDDCCDCDCCCDCAABBB------ ---FACCCDCDCCCCCCDCBBBAB------ DDDCCDCDDCDDCCCDDDDAAABBB----- DCCDCCDCCCCCCDDDCCCBABBBB----- -DCCDDDDCCCDDDDCDCDBABBAA----- --DDDCCCCDCDCDCCDCCBABBABB---- --DCDDDCDDDCDCCDDCCBBBBBBAB--- ---DCCDCCCCCCCCCCCDBBBABBBB--- ---ACDCDCDCDDCCDDDCBAABAAAA--- -----CCDCCCCDCDCCDCABBAAAAA--- -----CDDCCCBBABBAABBBABBABAB-- -----DCCDCCBAAABBBABBBBABBAA-- -----CCCDCDBBAAAAAAABBBBBAAA-- -----DCDDCDAAABBBABBBBABABB--- -----DDDDDDABAABBBABBAAAABBA-- -----CABCDDAABBAAABBAABBAAAB-- -----DAABABBAAABBBAABBAABAA--- -----DAABABBABABBAAABABAAAB--- -----BBABBBABBBBBABABBAAAA---- ----BBABBAAAABBABBABAAABA----- ------AABBBAABAABABBAABA------ ------ABA-ABBBBAABBABBB------- -------A---AABBBBBAAB-AB------ ------------AA---A------------ 
-----B------------------------ ----ACBAACDCDCCCCCCD---------- ----DDCCDCDCCDCCCDCCC--------- ----DDCCCDCDCCCDCCCDDDA------- -----ECCCCCDDDCDDCCCDA-------- ----EDDDCCDDCDDCDCCAAAAB------ ----DCCCCCDCDDCCCCCAABAA------ ---FDDCCCDDCDDCCCCDAAABB------ DDDCDDDCDCCDCCCDDCDBABAAA----- DDCCCDCCDCCDDCDCDCCABBAAB----- -DCCCCCCCCDDDDCCCDCBBBBAB----- --DDCCDCDCDDDCCCCDCBAAABAA---- --DDDDDCCDDDCDCDCDCBBAAAAAAB-- ---DDDDDCCDDCDDDCCDBBBBAABAA-- ---ACCDDCDCDDDCCDDCBAAABAABBB- -----CDDDCDDDCCDCCDBABAAABBBB- -----CCCCDDBBABAAAAAAAAABAA--- -----DCCDDDAAABABAABAABBBBA--- -----DDDDDCABAABBAABABBAAAB--- -----DDCDCCBBBBBABBABBBAABA--- -----DCCCDDAABAABABBBABABBA--- -----CAACCDBBABABAABABBBBBB--- -----DBBAAAABAABAABBAAABAAA--- -----BAAAAAABBAAABBABBBBAAB--- ----AAABBBBBAAABAABABABBBB---- -----BAAAAAAAABAABBAAABBB----- -----BB-BAABABABAABBAAAA------ ---------AABBAAABBBBBBBB------ -----------ABBBABAAABABB------ -----------A-A---A------------ 
------B----------------------- ----AACBB-DDDDCCDDCC---------- ----DCCDCCDDCDCCDD-DD--------- ----DDDCCCCCDCDDDCCCCA-------- -----EDCDCCCDDCDDDCBA--------- ----EDCDCDCCCDDCDDDBBABA------ ----DCCDDCCCDDCCDCDBABAA------ ---FACDDCCCDDCDCDCCABAAA------ --DDCDCDCDCDCCDCCDCBAABAA----- --DDCDDCDDCCDCCDDCCBABAAB----- ---DDDCCCCDCDCDDDDDBBABBB----- ----DCCCCDCDCDDCDDCAAAABAB---- ----DCCDDDDCDCCCCCCBAABAABA--- ---ACCDDCCCDCDDDCCCBABAABAB--- ---ACCDCCCDDDDDCDDCABBBBABBB-- ---ADDCDDCDDDDCDDCDBBBBBBAA--- -----CDDDDCABABBBBBAABBABAAA-- -----DCDDCCAAAABABBAABAAAABB-- -----CDDDCDAABBBBAABBAABBBAA-- -----DDCCDDBBABBBABAABBBBABA-- -----DCCCCCBABBBBBBBABAABBBA-- -----CBBDDCAABAABAAABBBBBBAA-- -----DBBABBBABBABBBAAAAABBBB-- ------AABAABBBBBBAABBBAAABBB-- ----AAABABABABABABAAABBBBBB--- ------BABBABABBABABBBABBAA---- -------A-ABBAAAABAABABAABA---- ---------BABBBABABBABABAB----- ---------AAAABBABAABB-B------- ----------A---A---A----------- 
-----B------------------------ -----BBA---DCCCCCCCC---------- ----DDCCA-CCCCDCCC-CC--------- ----DDDCDCCCDDDDDDCDCA-------- -----EDCCDDCCCCDDDCAA--------- ----EECCCDCCDDDDDDDBAAAA------ ----DCDDCCCDCDCCDDCBAABBA----- ----FCDDCDDCCDDCDCCABBBB------ --DDDCCCCCCCDCCDDCCABABAA----- ----DCDDCCCCDDCCDCCBABABB----- -----DDCCCDCDCDDCDCBBBAAB----- -----DCCDDCCCCDDCDDAABBBAA---- ---A-DCCCCDCDCDCCDDBABAAAAB--- ------CDDCCCDCDDCDDABBBABBA--- ------ECCCCDDDCDDDDABBAAABAA-- -----CCCCCCDDCCCDCDBAAABAAAB-- ---ACCCCDCDBBABBBABBABBABAAB-- -----DCCCCDBBBABBBAABBBAABB--- -----CCCCCCABABBABAAAAABBAB--- ----FCCDDCCBBABABBABBBBAABA--- -----DCCCCDBABAABAAABBAABAB--- -----DBACCCABBBAAABBABBBABB--- -----AABAABBAAABBBABBAAABAA--- -----AAAABAABBABBABABAAABAA--- ------BABBAABAAABBABBAAABB---- -------BBABBBBBAAAABBBBBAA---- -------BABAAAAAAAABBBBABA----- --------BABBAABBABABAA-------- ----------AA-ABABBABBA-------- -----------A--B---A----------- 
-----BB----------------------- -----BB-----CDDDDCC----------- -----BDAA--CCCDCCD-C---------- -----DDCC-CDCCCDDDDDA--------- ----DCCDDCDCDCCDDDCB---------- ------ECCCCCCCDDDDDBBABA------ ----FDCCCCCDCDDDDCCAAAAA------ -----DCDCCDDDDDCCCCAAAABB----- -----DDDCDDDCCDCCCCBBBBB------ -----DCCCCCCDCCDCCCBBAAAA----- -----DCDCCDCCDDDDDDABBAAB----- -----DDCCCDDDCDDCDCAABABAA---- ---A-DCCDCCDDDDDCCDBBBBABA---- ------DCCCCDDCCCCDCAABBBBBA--- ------EDDCCDCCCDDCDBABBBAAAB-- ------EDDCDCDCDDCCCBABBABBABA- ---ACDDCCDCBBAABAAAAAABBABBA-- -----DDDDCDABBBAAABBBBABBBABB- ----FDDCDDCAAAAABBAABBBBABBB-- -----DCDCCCAAAABBBAAAABBBBB--- -----CCDDCCAAAAAAABABBBBAABA-- -----CBBCDCBBBBBABABBBAAAAB--- ------AAABAAAABABAAAABBBBBB--- --ABBAABAAABAABAABBBAABABBB--- ---A-AABBABAABBBBAABAAABBAAB-- ------BBABBAAABAAAABAABBBA---- ------ABABBBBAABBAABABAB------ -------BAABAABBBABBBBB-------- ---------A-A--BAAABA---------- -----------A--B--A-A---------- 
------------------------------ ------B-------CDCCD----------- -----AD-A----CDDCDC----------- -----BDAA--CCCCCDCC----------- -----DCCCCCDCDDCDCCA---------- -----DCDCCCDDCDCDCCAABAB------ -----DDCDDCDDDCCCCCABBB------- -----DDDDCDCCDCDCDDBBAB------- -----DDCCCCCDCCCCDDAABBA------ -----DCCCCCDCCDCDDDABBBA------ -----DCCCCDDDDCDCCCABBABB----- -----DDDDDDCCCCCCDCAAAAABB---- ---A-DCCDCCCDCDDDCDBABBABA---- ------CDCCDDCCDCCCCAABBAAAB--- ------BDCCDDCCDCDCDBAAAAABB--- ------EDDCCCDDDDCDDAABABBABB-- ---ADDCDCCCAABAABBBABABABABBA- ----FCCCDCDBBAAABBABAAABBABAB- ----FCCDCCDAABBABABABBBAABABB- -----CDCCDCABBBBBBBABABABBBBA- -----CCDDDCBAAABBBAABBABABBAA- ------CBDCCAAABAABBABABAABABB- ------AABAAAAAABAABBBAAAABBAA- ------BBABABBAABBBBBBBAAAABA-- ------BBBAAAAABBBBBAAAAABBB--- --------BBBAABBBAABBBBBBBB---- ---------AAABBABABABBBABA----- ------------AAABBABBAA-------- ---------AAAA--AAAAB---------- ----------------B--B---------- 
------------------------------ --------------CCCDD----------- ------BA------DDCD------------ -------AB----CCDDC------------ ------DCBADDBCDDDCCB---------- -----DDCCCCCDDDDCCCAA--------- -----DCCCCCDDDDCCCDBA--------- -----DDCCCDCDCDDCDDBA--------- -----DDCCDDCDDCDDDDAAA-------- -----DDDDCDDDDDDCCCAABA------- -----DDCCCDDCDCDCDCABBAA------ ------DCCDCDCCCCCCCAAABBB----- ---A-CCCCDCDDCCDDCDABBAABB---- ------DCCDCCDCCDDCDBBAABABB--- ------ECCCDDCCDDCDDABABABABA-- ------EDDDDCCDCDCDDBBBAAABBA-- ---ADCCCDDDBBAABBBBBBBABAAAB-- -----FDDCDCAAAABBBABBABABAABAA -----CDCDCDBABBABABBAAABBABAAB ------DCCCCBBBABABBBBBABABBAB- ------DCDCDAAAABABBBBAAAAAABA- -------DDDCBBABAABAAABBBBBAAA- -------AABABABABBAABBBBAABBA-- --------BABBABAABABBBABBBBA--- -------BABBBBAAAAAAABBBABB---- --------AABBBABBABBBABBBA----- --------A-BAABBAABABABAA------ ----------AB---BBAAB-B-------- -----------A---A-----B-------- -----------A------------------ 
------------------------------ ------------------------------ ---------------CC------------- --------AAA--CCCD------------- ---------ABD-BCDDAB----------- --------BBABAAADCAB----------- -------CCABBBCCBCCB----------- -------DDCDDCCCDDADB---------- ------DCDCCCDCCCCDDBA--------- ------CCDDCDCDCDDCDBB--------- ------CDCDDCDCDCDCDBAAB------- ------DCCCDCDCDDCDCBBABAB----- ---A--DDDCCDCCCDCCCBBBABB----- ------DCCCCCDDCDDCCABAABAA---- ------CDDCDCCCCCCCDBBBBAAA---- -----CCCCDDCDCCDDCCBBBBABBAAA- ---A--CCCDCBBABBBAAAAAABBABAA- ------FDCCCABABAABBBABABAABBA- ------DDDDCBAABAABABBABABABAB- -------DDCCBBBBABABBBABAABBAAB -------DDDDBBABAABAAAAABABBBAB -------AADCAABABBBAAABBBBBAAB- --------ABBAABBAABBABAAABBAB-- --------AAABABABAABBABABABB--- -------ABBAAABBABAABBBBAA----- --------ABBBABBAAABAABBA------ --------AA-A-BBBBBAABBA------- ---------A-A-------A---------- -----------A-------B---------- ------------------------------ 
------------------------------ ------------------------------ ------------------------------ ------------------------------ -----------A------------------ ---------------B-------------- -------------AB-AB------------ ----------BBBBAAA-B----------- ----------CBABABABDB---------- ---------DCACDCCCBCBA--------- --------DDDCCCCCDDCBB--------- -------DDDCDCDCDDCCBAAB------- -------DDDDDDCCCCDCBABAA------ ---A---DDDDDCDCCCCDAAAAAA----- ---AA----DDDDDCDDDDBBBABB----- ---A-AADCDDDCCCDCCDBAABBB-A--- --------DDDAAAAAAAABBAAAAB---- --------DDDBBBBBAABABBABAABB-- ---------DDAABAAABABBABBAAB--- ---------DBBBAAABABBBAAABBA--- ---------DDABBBBBBBABAAAABABB- --------AAAABBAAAABBAABAAA-A-- --------ABBBAAAABABAABAAAB---- ----------BBAAABBBBABBAAAB---- --------B-AABAAABABBBAABBA---- --------AB-B--BABBAAABB------- -----------A------BB-B-------- ------------------------------ ------------------------------ ------------------------------ 
------------------------------ ------------------------------ ------------------------------ ------------------------------ ------------------------------ ------------------------------ ------------------------------ ------------------------------ ------------------A----------- ------------CCABD-BB---------- -----------CCDDDD-A----------- ---------DCCCDDDDCAA---------- ----------DCDDDDDDBAAA-------- -----------DCDCCCDAABBB------- ------------DCDDDCAABABB------ -------AAAACCCCDDCAAABABB----- -----------AABBBBBBBBBBAA----- -----------BABAABAABBBBBA----- ----------BABBBBAAAABBBBA----- ----------BBAABBBBAAABBBB----- ----------A-BAAABABBABBAB----- ---------AA-BBBBABAAAAAA------ ---------AB-BAABBBBABBBB------ ---------BAB-BBBAAABBBA------- --------AABB--ABABBAAAB------- ----------B---BBB-A--B-------- ------------------------------ ------------------------------ ------------------------------ ------------------------------ 
------------------------------ ------------------------------ ------------------------------ ------------------------------ ------------------------------ ------------------------------ ------------------------------ ------------------------------ ------------------------------ ---------------BDA------------ ---------------ADCAA---------- ---------------DCCBA---------- ---------------DDCB----------- -------------A-CCDB----------- --------------AACDBB---------- -----------AADCCDCAAA--------- ------------AABBBAAABA-------- -------------BBAABBBAB-------- ------------ABABAABAABA------- ------------BBABAAAABBA------- ----------B-ABBBAAABAA-------- ------------BBBABBBAB--------- --------------AAAA-BA--------- ---------AB----BBBBA-B-------- ---------AA-------BB-B-------- ------------------------------ ------------------------------ ------------------------------ ------------------------------ ------------------------------ 
------------------------------ ------------------------------ ------------------------------ ------------------------------ ------------------------------ ------------------------------ ------------------------------ ------------------------------ ------------------------------ ------------------------------ ----------------DA------------ ----------------CCAB---------- ----------------DDA----------- ----------------DDBA---------- ----------------DDAB---------- -------------AAADDA----------- --------------AAAABB---------- -------------ABB----A--------- --------------BA---BA--------- ------------BBABAABAB--------- ------------AAAABA-BB--------- ------------AB-AAA-AA--------- -------------AABAB-B---------- --------------ABBBB----------- --------------BA--A----------- ------------------A----------- ------------------------------ ------------------------------ ------------------------------ ------------------------------ 
------------------------------ ------------------------------ ------------------------------ ------------------------------ ------------------------------ ------------------------------ ------------------------------ ------------------------------ ------------------------------ ------------------------------ ------------------------------ ------------------------------ ------------------A----------- -----------------DAA---------- -----------------DAA---------- ------------------AA---------- -----------------BA----------- -------------BB--------------- -------------AB--------------- -----------BBBBBB------------- --------------ABA------------- ----------------B------------- ----------------BB------------ ---------------B-B------------ ------------------------------ ------------------------------ ------------------------------ ------------------------------ ------------------------------ ------------------------------ 
------------------------------ ------------------------------ ------------------------------ ------------------------------ ------------------------------ ------------------------------ ------------------------------ ------------------------------ ------------------------------ ------------------------------ ------------------------------ ------------------------------ ------------------------------ ------------------------------ ------------------------------ ------------------------------ ------------------------------ ------------------------------ ------------------------------ --------------AA-------------- ------------------------------ ------------------------------ ------------------------------ ------------------------------ ------------------------------ ------------------------------ ------------------------------ ------------------------------ ------------------------------ ------------------------------ 
