model
size = 16 31 31, scale = 0.05, origin = -y
material 
  colors = A:#222 B:#FF3 C:#F90 D:#F93
voxels
---------------- ---------------- ---------------- ---------------- ---------------- ---------------- ---------------- ---------------- ---------------- ---------------- ---------------- ---------------- ---------------- ---------------- ---------------- ---------------- ---------------- ---------------- -------AAAAA---- ------AAAAAA---- ------AAAAAA---- -------AAAA----- ---------------- ---------------- ---------------- ---------------- ---------------- ---------------- ---------------- ---------------- ---------------- 
---------------- ---------------- ---------------- ---------------- ---------------- ---------------- ---------------- ---------------- ---------------- ---------------- ---------------- ---------------- ---------------- ---------------- ---------------- ---------------- ---------------- ---------AAAA--- ------AAAAAAA--- ------AAAAAAA--- ------AAAAAAA--- ------AAAAAAA--- ------AAAAAAA--- ------AAAAAAA--- ------AAAAAA---- ---------------- ---------------- ---------------- ---------------- ---------------- ---------------- 
---------------- ---------------- ---------------- ---------------- ---------------- ---------------- ---------------- ---------------- ---------------- ---------------- ---------------- ---------------- ---------------- ---------------- ---------------- ---------------- ---------------- --------AAAAAA-- -----AAAAAAAAA-- -----AAAAAAAAA-- -----AAAAAAAAA-- -----AAAAAAAAA-- -----AAAAAAAAA-- -----AAAAAAAAA-- -----AAAAAAAAA-- -----AAAAAAAA--- ------AAAAAAA--- ---------------- ---------------- ---------------- ---------------- 
---------------- ---------------- ---------------- ---------------- ---------------- ---------------- ---------------- ---------------- ---------------- ---------------- ---------------- ---------------- ---------------- ---------------- ---------------- ---------------- ---------------- ------AAAAAAA--- -----AAAAAAAAA-- -----AAAAAAAAAA- -----AAAAAAAAAA- -----AAAAAAAAAA- -----AAAAAAAAAA- -----AAAAAAAAAA- -----AAAAAAAAA-- -----AAAAAAAAA-- -----AAAAAAAA--- ------AAAAAAA--- ---------------- ---------------- ---------------- 
---------------- ---------------- ---------------- ---------------- ---------------- ---------------- ---------------- ---------------- ---------------- ---------------- ---------------- ---------------- ---------------- ---------------- ---------------- ---------------- ---------------- -----AAAA-AAA--- -----AAAAAAAAA-- ----AAAAAAAAAAA- ----AAAAAAAAAAA- ----AAAAAAAAAAA- ----AAAAAAAAAAA- -----AAAAAAAAAA- -----AAAAAAAAAA- -----AAAAAAAAAA- -----AAAAAAAAA-- -----AAAAAAAA--- -------AAAAA---- ---------------- ---------------- 
----AAAAAAA----- -----AAAAAA----- -----AAAAA------ -----AAAAAA----- -----AAAAAA----- -----AAAAAA----- ------AAAAA----- ------AAAAA----- -------AAAA----- ---------------- ---------------- ---------------- ---------------- ------AAAAAAA--- -----AAAAAAAAAA- -----AAAAAAAAAA- -----AAAAAAAAAA- -----AAAAAAAAAA- ----AAAAAAAAAAA- ---AAAAAAAAAAAA- ---AAAAAAAAAAAA- ---AAAAAA-AAAAA- ---AAAAAA-AAAAA- ---AAAAAAAAAAAA- ----AAAAAAAAAAA- ----AAAAAAAAAAA- ----AAAAAAAAAAA- -----AAAAAAAAA-- ------AAAAAAA--- ---------------- ---------------- 
---AAAAAAAAAA--- ---AAAAAAAAAA--- ---AAAAAAAAA---- ---AAAAAAAAAA--- ---AAAAAAAAAA--- ---AAAAAAAAAA--- ----AAAAAAAAA--- ----AAAAAAAAA--- ----AAAAAAAAAAA- ----AAAAAAAAAAA- ----AAAAAAAAAAA- -----AAAAAAAAAA- ----AAAAAAAAAAA- ----AAAAAAAAAAA- ----AAAAAAAAAAA- ---AAAAAAAAAAAA- ---AAAAAAAAAAAA- --AAAAAAAAAAAAA- ---AAAAAAAAAAAAA --AAAAAAAAAAAAAA --AAAAAAAAAAAAAA --AAAAAA--AAAAAA --AAAAAA---AAAAA ---AAAAAA-AAAAAA ---AAAAAAAAAAAAA ----AAAAAAAAAAA- ----AAAAAAAAAAA- -----AAAAAAAAA-- ------AAAAAAA--- --------AAA----- ---------------- 
---AAAAAAAAAAAA- --AAAAAAAAAAAAA- --AAAAAAAAAAA--- --AAAAAAAAAAAAA- --AAAAAAAAAAAAA- --AAAAAAAAAAAAA- --AAAAAAAAAAAAA- ---AAAAAAAAAAAA- ---AAAAAAAAAAAA- ---AAAAAAAAAAAA- ---AAAAAAAAAAAA- --AAAAAAAAAAAAA- ---AAAAAAAAAAAA- --AAAAAAAAAAAAA- --AAAAAAAAAAAAA- --AAAAAAAAAAAAAA -AAAAAAAAAAAAAAA -AAAAAAAAAAAAAAA -AAAAAAAAAAAAAAA -AAAAAAAAAAAAAAA -AAAAAAAAAAAAAAA -AAAAAAA--AAAAAA -AAAAAAA---AAAAA --AAAAAA---AAAAA --AAAAAAA-AAAAAA ---AAAAAAAAAAAAA ----AAAAAAAAAAA- ----AAAAAAAAAA-- ------AAAAAAAA-- -------AAAAA---- ---------------- 
--AAAAAAAAAAAAA- -AAAAAAAAAAAAAA- -AAAAAAAAAAAAAA- -AAAAAAAAAAAAAA- -AAAAAAAAAAAAAA- -AAAAAAAAAAAAAA- --AAAAAAAAAAAAA- --AAAAAAAAAAAAA- --AAAAAAAAAAAAA- --AAAAAAAAAAAAA- -AAAAAAAAAAAAAA- -AAAAAAAAAAAAAA- AAAAAAAAAAAAAAA- AAAAAAAAAAAAAAAA AAAAAAAAAAAAAAAA AAAAAAAAAAAAAAAA AAAAAAAAAAAAAAAA AAAAAAAAAAAAAAAA AAAAAAAAAAAAAAAA AAAAAAAAAAAAAAAA AAAAAAAAAAAAAAAA AAAAAAAA---AAAAA -AAAAAAA----AAAA -AAAAAAA---AAAAA --AAAAAAA-AAAAAA ---AAAAAAAAAAAAA ---AAAAAAAAAAAA- ----AAAAAAAAAA-- -----AAAAAAAAA-- -------AAAAAA--- ---------------- 
-AAAAAA-AAAAAAAA AAAAAAA-AAAAAAA- AAAAAAA-AAAAAAA- AAAAAAAAAAAAAAA- AAAAAAAAAAAAAAAA -AAAAAAAAAAAAAA- -BAAAAAAAAAAAAAA -BAAAAAAAAAAAAAA -BAAAAAAAAAAAAAA -BAAAAAAAAAAAAAA BAAAAAAAAAAAAAAA BAAAAAAAAAAAAAAA BAAAAAAAAAAAAAAA BAAAAAAAAAAAAAAA BAAAAAAAAAAAAAAA BAAAAAAAA-AAAAAA BAAAAAAA--AAAAAA BAAAAAAA---AAAAA BAAAAAA----AAAAA BAAAAAAA---AAAAA BAAAAAAA---AAAAA BAAAAAAAAA-AAAAA BAAAAAAAAA-AAAAA -BAAAAAA---AAAAA --BAAAAA---AAAAA --AAAAAAA-AAAAAA ---AAAAAAAAAAA-- ----AAAAAAAAAA-- -----AAAAAAAAA-- ------AAAAAAA--- -------AAAAA---- 
AAAAA-A--AAAAAAA AAAAA-A-AAAAAAAA AAAAA-A-AAAAAAA- AAAAA-A-AAAAAAAA AAAAA-AAAAAAAAAA AAAAAAAAAAAAAAA- BAAAAAAAAAAAAAA- AAAAAAAAAAAAAAAA AAAAAAAAAAAAAAAA AAAAAAAAAAAAAAAA AAAAAAAAAAAAAAAA AAAAAAAAAAAAAAAA AAAAAAAAAAAAAAAA AAAAAAAAAAAAAAAA AAAAAAAAAAAAAAAA AAAAAAAAA-AAAAAA AAAAAAAA--AAAAAA AAAAAAAA---AAAAA AAAAAAA----AAAAA AAAAAAAA----AAAA AAAAAAAA----AAAA AAAAAAAAAA--AAAA AAAAAAAAAA--AAAA AAAAAAAA---AAAAA -BAAAAAA---AAAAA --AAAAAAA-AAAAAA --AAAAAAAAAAAAA- ---AAAAAAAAAAAA- ----AAAAAAAAAA-- -----AAAAAAAA--- -------AAAAA---- 
AAAAAA----AAAAAA AAAAAA----AAAAAA AAAAAA---AAAAAAA AAAAAA---AAAAAAA AAAAAA---AAAAAA- AAAAAA---AAAAAA- BAAAAAA--AAAAAAA AAAAAAA--AAAAAAA AAAAAAA--AAAAAAA AAAAAAA--AAAAAAA AAAAAAA--AAAAAAA AAAAAA----AAAAAA AAAAAA-----AAAAA AAAAAA-----AAAAA AAAAAA-----AAAAA AAAAAA------AAAA AAAAAA------AAAA AAAAAA------AAAA AAAAA-------AAAA AAAAA-------AAAA AAAAA--------AAA AAAAAA-------AAA AAAAAA------AAAA AAAAAAA-----AAAA -BAAAAAA---AAAAA --AAAAAAA-AAAAAA --AAAAAAAAAAAAA- ---AAAAAAAAAAAA- ----AAAAAAAAAA-- ----------AAA--- -----------AA--- 
AAAAA------AAAAA AAAAA-----AAAAAA AAAAA-----AAAAAA AAAAA-----AAAAAA AAAAA-----AAAAA- AAAAA-----AAAAA- BAAAAA----AAAAAA AAAAAA----AAAAAA AAAAAA----AAAAAA AAAAAA----AAAAAA CAAAA-----AAAAAA CAAAA------AAAAA CAAA-------AAAAA DAAAA-------AAAA DAAAA-------AAAA AAAAA-------AAAA AAAAA-------AAAA AAAAA--------AAA AAAA---------AAA AAAA---------AAA AAAAA--------AAA AAAAA--------AAA AAAAAA------AAAA AAAAAAA-----AAAA -BAAAAAA---AAAAA --AAAAAAA-AAAAAA --AAAAAAAAAAAAA- ---AAAAAAAAAAAA- ----AAAAAAAAAA-- -----------AAA-- ------------A--- 
AAAAA------AAAAA AAAAA------AAAAA AAAAA-----AAAAAA AAAAA-----AAAAAA AAAAA-----AAAAA- AAAAA-----AAAAAA BAAAA-----AAAAAA AAAAA------AAAAA AAAAA-------AAAA DAAAA-------AAAA DAAA--------AAAA CAAA--------AAAA DAAA--------AAAA CAAA--------AAAA CAAA---------AAA CAAA---------AAA AAAA---------AAA CAAA---------AAA DAAA---------AAA DAAA---------AAA CAAA---------AAA AAAAA--------AAA AAAAAA------AAAA AAAAAA------AAAA -BAAAAA----AAAAA --AAAAAA---AAAAA --AAAAAAAAAAAAA- ---AAAAAAAAAAAA- ----AAAAAAAAAA-- -----------AAA-- ------------A--- 
AAAA-------AAAAA AAAA-------AAAAA AAAA------AAAAAA AAAA------AAAAAA AAAA------AAAAA- AAAA------AAAAAA BAAA------AAAAAA AAAA-------AAAAA AAAA--------AAAA DAAA--------AAAA CAA----------AAA AAA----------AAA AAA----------AAA AAA----------AAA CAA----------AAA CAA----------AAA CAA----------AAA CAA----------AAA CAA----------AAA DAAA---------AAA DAAA---------AAA CAAAA-------AAAA AAAAA-------AAAA AAAAAA------AAAA -BAAAAA----AAAAA --AAAAAA---AAAAA --AAAAAAA-AAAAA- ---AAAAAAAAAAAA- ----AAA---AAAA-- -----------AAA-- ------------A--- 
AAAA-------AAAAA AAAA-------AAAAA AAAA------AAAAAA AAAA------AAAAA- AAAA------AAAAA- AAAA------AAAAAA BAAA-------AAAAA AAAA--------AAAA CAAA--------AAAA DAAA--------AAAA AAA----------AAA AAA----------AAA AAA----------AAA AAA----------AAA AAA----------AAA DAA----------AAA CAA----------AAA CAA----------AAA AAA----------AAA AAAA---------AAA CAAA---------AAA CAAAA-------AAAA DAAAA-------AAAA AAAAAA------AAAA -BAAAA-----AAAAA --AAAAAA---AAAAA --AAAAAA--AAAAA- ---AAAAA--AAAAA- ----AAA---AAAA-- -----------AAA-- ------------A--- 
AAAA-------AAAAA AAAA-------AAAAA AAAA-------AAAAA AAAA-------AAAA- AAAA-------AAAA- AAAA-------AAAAA BAAA-------AAAAA AAAA--------AAAA AAAA--------AAAA DAAA--------AAAA AAAA---------AAA AAAA---------AAA AAAA---------AAA AAAA---------AAA AAAA---------AAA CAAA---------AAA DAA----------AAA AAA----------AAA AAA----------AAA AAAA---------AAA AAAA---------AAA CAAAA-------AAAA AAAAA-------AAAA AAAAAA------AAAA -BAAAA-----AAAAA --AAAAAA---AAAAA --AAAAAA--AAAAA- ---AAAAA--AAAAA- ----AAA---AAAA-- -----------AAA-- ------------A--- 
AAAA-------AAAAA AAAA-------AAAAA AAAA-------AAAAA AAAA-------AAAA- AAAA-------AAAA- AAAA-------AAAAA BAAA-------AAAAA AAAA--------AAAA DAAA--------AAAA DAAA--------AAAA AAAA--------AAAA ADAA--------AAAA ACAA--------AAAA ADAA--------AAAA ADAA--------AAAA CAAA--------AAAA DAA---------AAAA ADA----------AAA ACA----------AAA ACAA---------AAA ADAA---------AAA DAAAA-------AAAA DAAAA-------AAAA AAAAAA------AAAA -BAAAAA----AAAAA --AAAAAA---AAAAA --AAAAAAA-AAAAA- ---AAAAAAAAAAAA- ----AAA---AAAA-- -----------AAA-- ------------A--- 
AAAAA------AAAA- AAAAA-----AAAAAA AAAAA-----AAAAAA AAAAA-----AAAAA- AAAAA-----AAAAA- AAAAA------AAAAA BAAAA------AAAAA AAAAA------AAAAA AAAAA------AAAAA CAAAA------AAAAA DAAA-------AAAAA CAAA-------AAAAA CAAA-------AAAAA DAAA--------AAAA DAAA--------AAAA DAAA--------AAAA DAAA--------AAAA DAAA--------AAAA CAAA---------AAA DAAA---------AAA CAAA---------AAA CAAAA--------AAA AAAAAA------AAAA AAAAAA------AAAA -BAAAAA----AAAAA --AAAAAAA--AAAAA --AAAAAAAAAAAAA- ---AAAAAAAAAAAA- ----AAAAAAAAAA-- -----------AAA-- ------------A--- 
AAAAA-----AAAAA- AAAAA-----AAAAAA AAAAA-----AAAAAA AAAAA-----AAAAA- AAAAA-----AAAAA- AAAAA-----AAAAAA BAAAA-----AAAAAA AAAAA-----AAAAAA AAAAA-----AAAAAA CAAAA-----AAAAAA DAAAA------AAAAA DAAAA------AAAAA DAAAA------AAAAA DAAAA-------AAAA CAAAA-------AAAA CAAAA-------AAAA DAAAA-------AAAA CAAAA-------AAAA CAAA---------AAA CAAA---------AAA CAAAA--------AAA CAAAA--------AAA AAAAAA------AAAA AAAAAAA-----AAAA -BAAAAAA---AAAAA --AAAAAAA-AAAAAA --AAAAAAAAAAAAA- ---AAAAAAAAAAAA- ----AAAAAAAAAA-- -----------AAA-- ------------A--- 
AAAAAA----AAAAA- AAAAAA---AAAAAAA AAAAAA---AAAAAAA AAAAAA---AAAAAAA AAAAAA---AAAAAA- AAAAAA---AAAAAA- BAAAAA---AAAAAAA AAAAAA---AAAAAAA AAAAAA---AAAAAAA AAAAAAA---AAAAAA AAAAAAA---AAAAAA AAAAAAA----AAAAA AAAAAAA----AAAAA AAAAAAA----AAAAA AAAAAA------AAAA AAAAAA------AAAA AAAAAA------AAAA AAAAAA------AAAA AAAAAA------AAAA AAAAA-------AAAA AAAAA--------AAA AAAAAA-------AAA AAAAAA------AAAA AAAAAAA-----AAAA -BAAAAAA---AAAAA --AAAAAAA-AAAAAA --AAAAAAAAAAAAA- ---AAAAAAAAAAAA- ----AAAAAAAAAA-- ----------AAA--- -----------AA--- 
-AAAAAA-AAAAAAA- -AAAAAA-AAAAAAAA AAAAAAA-AAAAAAAA AAAAAAAAAAAAAAA- AAAAAAAAAAAAAAA- AAAAAAAAAAAAAAA- BAAAAAAAAAAAAAA- AAAAAAAAAAAAAAA- AAAAAAAAAAAAAAA- AAAAAAAAAAAAAAA- AAAAAAAAAAAAAAAA AAAAAAAAAAAAAAAA AAAAAAAAAAAAAAAA AAAAAAAAAAAAAAAA AAAAAAAAAAAAAAAA AAAAAAAAA-AAAAAA AAAAAAAA--AAAAAA AAAAAAAA---AAAAA AAAAAAA----AAAAA AAAAAAA----AAAAA AAAAAA------AAAA AAAAAAA-----AAAA AAAAAAA-----AAAA AAAAAAAA---AAAAA --BAAAAA---AAAAA --AAAAAAA-AAAAAA --AAAAAAAAAAAAA- ----AAAAAAAAAAA- -----AAAAAAAAA-- ------AAAAAAA--- -------AAAAA---- 
-AAAAAAAAAAAAA-- -AAAAAAAAAAAAA-- AAAAAAAAAAAAAA-- AAAAAAAAAAAAAAA- AAAAAAAAAAAAAAA- AAAAAAAAAAAAAA-- BAAAAAAAAAAAAA-- BAAAAAAAAAAAAA-- BAAAAAAAAAAAAA-- BAAAAAAAAAAAAAA- BAAAAAAAAAAAAAA- BAAAAAAAAAAAAAAA BAAAAAAAAAAAAAA- BAAAAAAAAAAAAAAA BAAAAAAAAAAAAAAA BAAAAAAAAAAAAAAA BAAAAAAAAAAAAAAA BAAAAAAAAAAAAAAA BAAAAAAAAAAAAAAA BAAAAAAAAAAAAAAA BAAAAAAAAAAAAAAA BAAAAAAA---AAAAA BAAAAAAA----AAAA -BAAAAAA---AAAAA --BAAAAAA-AAAAAA --AAAAAAAAAAAAAA --AAAAAAAAAAAAA- ----AAAAAAAAAA-- -----AAAAAAAAA-- -------AAAAAA--- ---------------- 
--AAAAAAAAAAAA-- --AAAAAAAAAAAA-- -AAAAAAAAAAAA--- AAAAAAAAAAAAAA-- AAAAAAAAAAAAAA-- -AAAAAAAAAAAAA-- -AAAAAAAAAAAAA-- --AAAAAAAAAAAA-- --AAAAAAAAAAAA-- --AAAAAAAAAAAAA- -AAAAAAAAAAAAAA- -AAAAAAAAAAAAAA- AAAAAAAAAAAAAAA- AAAAAAAAAAAAAAA- AAAAAAAAAAAAAAA- AAAAAAAAAAAAAAAA AAAAAAAAAAAAAAAA AAAAAAAAAAAAAAAA AAAAAAAAAAAAAAAA AAAAAAAAAAAAAAAA AAAAAAAAAAAAAAAA AAAAAAAA--AAAAAA AAAAAAAA---AAAAA --AAAAAA---AAAAA --AAAAAAA-AAAAAA --AAAAAAAAAAAAAA ----AAAAAAAAAAA- ----AAAAAAAAAA-- ------AAAAAAAA-- -------AAAAA---- ---------------- 
--AAAAAAAAAAA--- ---AAAAAAAAAA--- ---AAAAAAAAA---- ---AAAAAAAAAA--- ---AAAAAAAAAA--- ---AAAAAAAAAA--- ----AAAAAAAAA--- ----AAAAAAAAA--- ----AAAAAAAAAA-- ----AAAAAAAAAA-- ----AAAAAAAAAA-- ---AAAAAAAAAAA-- -AAAAAAAAAAAAA-- -AAAAAAAAAAAAA-- AAAAAAAAAAAAAA-- AAAAAAAAAAAAAAA- AAAAAAAAAAAAAAA- AAAAAAAAAAAAAAA- AAAAAAAAAAAAAAAA AAAAAAAAAAAAAAAA AAAAAAAAAAAAAAAA -AAAAAAA--AAAAAA --AAAAAA---AAAAA ---AAAAAA-AAAAAA --AAAAAAAAAAAAAA ----AAAAAAAAAAA- ----AAAAAAAAAAA- -----AAAAAAAAA-- ------AAAAAAA--- --------AAA----- ---------------- 
----AAAAAAA----- -----AAAAAA----- -----AAAAA------ -----AAAAAA----- -----AAAAAA----- -----AAAAAA----- ------AAAAA----- ------AAAAA----- -------AAAA----- ---------------- ---------------- ---------------- ---------------- ------AAAAAAA--- -----AAAAAAAAA-- -----AAAAAAAAA-- -----AAAAAAAAA-- -----AAAAAAAAA-- ----AAAAAAAAAAA- ---AAAAAAAAAAAA- ---AAAAAAAAAAAA- ----AAAAA-AAAAA- --AAAAAAA-AAAAA- --AAAAAAAAAAAAA- ----AAAAAAAAAAA- ----AAAAAAAAAAA- ----AAAAAAAAAAA- -----AAAAAAAAA-- ------AAAAAAA--- ---------------- ---------------- 
---------------- ---------------- ---------------- ---------------- ---------------- ---------------- ---------------- ---------------- ---------------- ---------------- ---------------- ---------------- ---------------- ---------------- ---------------- ---------------- ---------------- -----AAAA-AAA--- -----AAAAAAAAA-- ----AAAAAAAAAAA- ----AAAAAAAAAAA- ----AAAAAAAAAAA- ----AAAAAAAAAAA- -----AAAAAAAAAA- -----AAAAAAAAAA- -----AAAAAAAAAA- -----AAAAAAAAA-- -----AAAAAAAA--- -------AAAAA---- ---------------- ---------------- 
---------------- ---------------- ---------------- ---------------- ---------------- ---------------- ---------------- ---------------- ---------------- ---------------- ---------------- ---------------- ---------------- ---------------- ---------------- ---------------- ---------------- ------AAAAAAA--- -----AAAAAAAAA-- -----AAAAAAAAAA- -----AAAAAAAAAA- -----AAAAAAAAAA- -----AAAAAAAAAA- -----AAAAAAAAAA- -----AAAAAAAAA-- -----AAAAAAAAA-- -----AAAAAAAA--- ------AAAAAAA--- ---------------- ---------------- ---------------- 
---------------- ---------------- ---------------- ---------------- ---------------- ---------------- ---------------- ---------------- ---------------- ---------------- ---------------- ---------------- ---------------- ---------------- ---------------- ---------------- ---------------- --------AAAAAA-- -----AAAAAAAAA-- -----AAAAAAAAA-- -----AAAAAAAAA-- -----AAAAAAAAA-- -----AAAAAAAAA-- -----AAAAAAAAA-- -----AAAAAAAAA-- -----AAAAAAAA--- ------AAAAAAA--- ---------------- ---------------- ---------------- ---------------- 
---------------- ---------------- ---------------- ---------------- ---------------- ---------------- ---------------- ---------------- ---------------- ---------------- ---------------- ---------------- ---------------- ---------------- ---------------- ---------------- ---------------- ---------AAAA--- ------AAAAAAA--- ------AAAAAAA--- ------AAAAAAA--- ------AAAAAAA--- ------AAAAAAA--- ------AAAAAAA--- ------AAAAAA---- ---------------- ---------------- ---------------- ---------------- ---------------- ---------------- 
---------------- ---------------- ---------------- ---------------- ---------------- ---------------- ---------------- ---------------- ---------------- ---------------- ---------------- ---------------- ---------------- ---------------- ---------------- ---------------- ---------------- ---------------- -------AAAAA---- ------AAAAAA---- ------AAAAAA---- -------AAAA----- ---------------- ---------------- ---------------- ---------------- ---------------- ---------------- ---------------- ---------------- ---------------- 
