model
size = 15 32 29, scale = 0.05, origin = -y
material 
  colors = A:#EEE B:#000 C:#555 D:#090D0D E:#030404 F:#060808 G:#888 H:#777
voxels
291-5A10-5A444-7A2(8-3A3-A)8-7A9-5A10-5A399-A5-A7-2A2-A3-A6-2A2-A3-A7-3(3A3-A8-)7A8-7A9-5A354-A5-A7-6(2A2-A3-A6-)A-2A4-A7-3A3-A8-7A9-5A324-A5-A7-2A2-A3-A5-3(A-A2-2(A4-))A-A2-A4-A5-2(2A2-A3-A6-)2A2-A3-A7-3A3-A8-7A323-3A3-A7-2A2-A3-A5-4(A-A2-2(A4-))2A4-A3-A5-A4-A2-2(A6-2A2-A3-)A7-3A3-A9-5A37-2(12A3-)12A4-5(9A6-)9A8-5A9-7A8-7A54-5A9-7A8-3A3-A7-A-2A4-A6-5A3-A5-A-4A4-A3-A-6A4-2(A2-A-2(A4-))A3-2A4-A3-A4-2A4-A3-A5-A4-A2-A6-2A2-A3-A6-A-2A4-A7-7A35-2A10-2(A2-A11-)A6(2-2A9-2A)3-3A5-4A2(3-2A7-3A)3(2-13A)2-4A5-4A2-3A-2A4-3A2-4A2-A3-2(3A-)A2-A4-2A-4A4-A3-2(2A-)2(A4-)3(2(A-)A6-A3-)A2-2A6-A3-A2-A-2(A4-)A3-2A4-A3-A4-2A4-A3-A5-2A2-A3-A7-7A34-2A11-8(A-A12-)2(A2-A11-)A-2A11-4(A-A12-)A2-A3-2A6-3(A2-)A5-A-A3-A2-A5-2(A-A2-2(A4-))4(2(A-)A6-A3-)2(A2-2A6-A3-)A3-2A4-A3-A5-2A2-A3-A7-3A3-A9-5A19-2A12-8(2A13-)2(3A12-)5(2A13-)3A4-2A6-3A3-A2-A5-2A4-A2-A5-2(2A3-2(A4-))2(2A2-A6-A3-)3(2(A-)A6-A3-)A2-2A6-A3-A2-A-2(A4-)A3-A-A2-A4-A5-4A3-2A8-5A19-A13-BA9(13-2A)13-AB13-BA4(13-2A)5-2A6-2(2A4-A2-A5-)2(2A3-2(A4-))2A2-A6-A3-AB2-B6-B3-BA2-A6-A3-2A2-A6-A3-2(A-)A6-A3-A2-A8-2(A2-)2A6-2(A3-)2A4-A3-A5-5A3-A7-A5-A9-5A4-2(A13-B)A7(13-2A)13-AC13-CB13-2B13-BA3(13-2A)5-2A6-2(2A4-A2-A5-)2(2A3-2(A4-))AC2-C6-C3-CB2-B6-B3-2B2-B6-B3-BA2-A6-A3-2(A-)A6-A3-A-2A8-2(A2-)2A6-2(A3-)2A4-A3-A5-2A2-A3-A7-4A-2A9-6A3-3(A13-B)A5(13-2A)13-AC13-CF13-FB2(13-2B)13-BA2(13-2A)5-2A6-2(2A4-A2-A5-)2A3-2(A4-)AC3-2(C4-)CF2-F6-F3-FB2(2-B6-B3-2B)2-B6-B3-B2(-A)6-A3-A-2A8-2(A2-)2A6-A3-A2-A-A9-A3-3A7-A12-2A13-2A2-2(A13-B)A13-EA13-BA3(13-2A)13-AC13-CG13-GD13-DB13-2B13-BE13-EB13-BA13-2A5-2A6-2(2A4-A2-A5-)AC3-2(C4-)CG3-2(G4-)GD2-D6-D3-DB2-B6-B3-2B2-B6-B3-BE2-E6-E3-E2(-B)6-B3-B-2A8-2(A2-)A8-2(A2-)2A10-A3-2A8-A12-2A13-2A2-2(A13-B)A13-E2(A13-B)A13-2A13-AC13-CH13-HD13-2D13-DB13-2B13-BE13-EB13-2B13-BA5-2A6-2A4-A2-A5-AC4-C2-C5-CH3-2(H4-)HD3-2(D4-)2D2-D6-D3-DB2-B6-B3-2B2-B6-B3-BE2-E6-E3-E2(-B)6-B3-B-2B8-2(B2-)A8-2(A2-)2A10-A3-2A8-A12-2A13-2A2-2(A13-B)A13-EA13-BA3(13-2A)13-AC13-CG13-GD13-DB13-2B13-BE13-EB13-BA13-2A5-2A6-2(2A4-A2-A5-)AC3-2(C4-)CG3-2(G4-)GD2-D6-D3-DB2-B6-B3-2B2-B6-B3-BE2-E6-E3-E2(-B)6-B3-B-2A8-2(A2-)A8-2(A2-)2A10-A3-2A8-A12-2A13-2A2-3(A13-B)A5(13-2A)13-AC13-CF13-FB2(13-2B)13-BA2(13-2A)5-2A6-2(2A4-A2-A5-)2A3-2(A4-)AC3-2(C4-)CF2-F6-F3-FB2(2-B6-B3-2B)2-B6-B3-B2(-A)6-A3-A-2A8-2(A2-)2A10-A2-A-A9-A3-3A7-A12-2A13-2A2-2(A13-B)A7(13-2A)13-AC13-CB13-2B13-BA3(13-2A)5-2A6-2(2A4-A2-A5-)2(2A3-2(A4-))AC2-C6-C3-CB2-B6-B3-2B2-B6-B3-BA2-A6-A3-2(A-)A6-A3-A-2A8-2(A2-)2A6-2(A3-)2A4-A3-A5-2A2-A3-A7-3A3-A9-6A3-A13-BA9(13-2A)13-AB13-BA4(13-2A)5-2A6-2(2A4-A2-A5-)2(2A3-2(A4-))2A2-A6-A3-AB2-B6-B3-BA2-A6-A3-2A2-A6-A3-2(A-)A6-A3-A2-A8-2(A2-)2A6-2(A3-)2A4-A3-A5-5A3-A7-A5-A9-5A4-2A12-8(2A13-)2(3A12-)5(2A13-)3A4-2A6-3A3-A2-A5-2A4-A2-A5-2(2A3-2(A4-))2(2A2-A6-A3-)3(2(A-)A6-A3-)A2-2A6-A3-A2-A-2(A4-)A3-A-A2-A4-A5-4A3-2A8-5A20-2A11-8(A-A12-)2(A2-A11-)A-2A11-4(A-A12-)A2-A3-2A6-3(A2-)A5-A-A3-A2-A5-2(A-A2-2(A4-))4(2(A-)A6-A3-)2(A2-2A6-A3-)A3-2A4-A3-A5-2A2-A3-A7-3A3-A9-5A21-2A10-2(A2-A11-)A5(2-2A8-3A)2-2A7-4A3-3A5-4A2(3-2A7-3A)3(2-13A)2-4A5-4A2-3A-2A4-3A2-4A2-A3-2(3A-)A2-A4-2A-4A4-A3-2(2A-)2(A4-)3(2(A-)A6-A3-)A2-2A6-A3-A2-A-2(A4-)A3-2A4-A3-A4-2A4-A3-A5-2A2-A3-A7-7A36-2(12A3-)12A4-5(8A7-)7A10-5A9-7A8-7A54-5A9-7A8-3A3-A7-A-2A4-A6-5A3-A5-A-4A4-A3-A-6A4-2(A2-A-2(A4-))A3-2A4-A3-A4-2A4-A3-A5-A4-A2-A6-2A2-A3-A6-A-2A4-A7-7A308-3A3-A7-2A6-A5-4(A-A2-2(A4-))2A4-A3-A5-A4-A2-2(A6-2A2-A3-)A7-3A3-A9-5A309-A5-A7-2A2-A3-A5-3(A-A2-2(A4-))A-A2-A4-A5-2(2A2-A3-A6-)2A2-A3-A7-3A3-A8-7A323-A5-A7-6(2A2-A3-A6-)A-2A4-A7-3A3-A8-7A9-5A324-A5-A7-2A2-A3-A6-2A2-A3-A7-3(3A3-A8-)7A8-7A9-5A354-7A2(8-3A3-A)8-7A9-5A10-5A415-5A10-5A169-
