model
size = 28 31 29, scale = 0.05, origin = -y
material 
  colors = A:#394039 B:#503535 C:#252525 D:#707469 E:#4B4B4B F:#859593 G:#363D34 H:#2D4327 I:#333D31 J:#7C9EB3 K:#2E352D
voxels
---------------------------- ---------------------------- ---------------------------- ---------------------------- ---------------------------- ---------------------------- ---------------------------- ---------------------------- ---------------------------- ---------------------------- ---------------------------- ---------------------------- ---------------------------- ---------------------------- ---------------------------- ---------------------------- ---------AAAAAAAAAA--------- ---------------------------- ---------------------------- ---------------------------- ---------------------------- ---------------------------- ---------------------------- ---------------------------- ---------------------------- ---------------------------- ---------------------------- ---------------------------- ---------------------------- ---------------------------- ---------------------------- 
---------------------------- ---------------------------- ---------------------------- ---------------------------- ---------------------------- ---------------------------- ---------------------------- ---------------------------- ---------------------------- ---------------------------- ---------------------------- ---------------------------- ---------------------------- ---------------------------- ---------------------------- ---------------------------- --------A----------A-------- ---------AAAAAAAAAA--------- ---------------------------- ---------------------------- ---------------------------- ---------------------------- ---------------------------- ---------------------------- ---------------------------- ---------------------------- ---------------------------- ---------------------------- ---------------------------- ---------------------------- ---------------------------- 
---------------------------- ---------------------------- ---------------------------- ---------------------------- ---------------------------- ---------------------------- ---------------------------- ---------------------------- ---------------------------- ---------------------------- ---------------------------- ---------------------------- ---------------------------- ---------------------------- ---------------------------- ---------------------------- ------AA------------AA------ --------A----------A-------- ---------AAAAAAAAAA--------- ---------------------------- ---------------------------- ---------------------------- ---------------------------- ---------------------------- ---------------------------- ---------------------------- ---------------------------- ---------------------------- ---------------------------- ---------------------------- ---------------------------- 
---------------------------- ---------------------------- ---------------------------- ---------------------------- ---------------------------- ---------------------------- ---------------------------- ---------------------------- ---------------------------- ---------------------------- ---------------------------- ---------------------------- ---------------------------- ---------------------------- ---------------------------- ---------------------------- -----A----------------A----- ------AK------------AA------ --------AAAAAAAAAAAA-------- ------CCCCAAAAAAAACCCC------ ------DDDDCAAAAAACDDDD------ -------FFFDCCAACCDFFF------- -----------D----D----------- -----------D----D----------- ---------------------------- ---------------------------- ---------------------------- ---------------------------- ---------------------------- ---------------------------- ---------------------------- 
---------------------------- ---------------------------- ---------------------------- ---------------------------- ---------------------------- ---------------------------- ---------------------------- ---------------------------- ---------------------------- ---------------------------- ---------------------------- ---------------------------- ---------------------------- ---------------------------- ---------------------------- ---------------------------- -----A----------------A----- -----A----------------A----- ------AAAA--------AAAA------ -----CEEEAAAAAAAAAEEEEC----- -----DDDAEAAAAAAAEAADDD----- -----DF-AAEAAAAAAAAA-FD----- -------FFFFDCAACDFFFF------- -------FFJFDCAACDFFFF------- -----------DDDDDD----------- -----------DDDDDD----------- ---------------------------- ---------------------------- ---------------------------- ---------------------------- ---------------------------- 
---------------------------- ---------------------------- ---------------------------- ---------------------------- ---------------------------- ---------------------------- ---------------------------- ---------------------------- ---------------------------- ---------------------------- ---------------------------- ---------------------------- ---------------------------- ---------------------------- ---------------------------- ---------------------------- -----A----------------A----- -----A----------------A----- -----AAA------------AAA----- -----CAAAE-------EAAAAC----- -----CAAAE-------EAAAAC----- -----CAAAAEAAAAAAAAAAAC----- -----DFAAAAEAAAAEAAAAFD----- ----CDF-AHAEAAAAEAHA-JDC---- -------FJFFDAAAADFFFJ------- -------FFFFDCCCCDFFFF------- -----------D----D----------- ---------------------------- ---------------------------- ---------------------------- ---------------------------- 
---------------------------- ---------------------------- ---------------------------- ---------------------------- ---------------------------- ---------------------------- ---------------------------- ---------------------------- ---------------------------- ---------------------------- ---------------------------- ---------------------------- ---------------------------- ---------------------------- ---------------------------- ---------------------------- ----AA----------------AA---- ----AA----------------AA---- ----AA----------------AA---- ----CKAA------------AAKC---- ----CAAA------------AAAC---- ---ECAAAAA--------AAAAAC---- ---ECAAAAA--------AAAAAC---- ----CDAAAAAAAAAAAAAAAG-C---- ----CDFAAAAEA--AEAAAAFDC---- -----DF-AAAEAAAAEAAA-FD----- ------DDDDDCCGACCDDDDD------ -----------CAAGAC----------- ---------------------------- ---------------------------- ---------------------------- 
---------------------------- ---------------------------- ---------------------------- ---------------------------- ---------------------------- ---------------------------- ---------------------------- ---------------------------- ---------------------------- ---------------------------- ---------------------------- ---------------------------- ---------------------------- ---------------------------- ---A------------------------ ---I--------------------I--- ---AA------------------AA--- ---AA------------------AA--- ---AA------------------AA--- ----AA----------------AA---- ----AA----------------AA---- --BEAAA--------------AAAE--- --BECAA--------------AACE--- ---ECCAAA----------AAACC---- ---E-CAAA----------AAAC----- -----CCAAAA------AAAACC----- -----CCCAAEAAAAAAAAACCC----- --------CCCAAAAAACCC-------- ---------------------------- ---------------------------- ---------------------------- 
---------------------------- ---------------------------- ---------------------------- ---------------------------- ---------------------------- ---------------------------- ---------------------------- ---------------------------- ---------------------------- ---------------------------- ---------------------------- ---------------------------- ---------------------------- ---I---------------------A-- ---A---------------------I-- ---A--------------------AA-- ---A--------------------A--- ---A--------------------A--- ---A--------------------A--- ----A------------------A---- -B--A------------------A---- --BEAA----------------AAE--- --BE-A----------------A-E--- --BE-AA--------------AA-E--- --BE-AA--------------AA-E--- ---E-CAAA----------AAAC----- ------CAAAE------AAAAC------ -------CAAAAAAAAAAAAC------- -----------AAAAAA----------- ---------------------------- ---------------------------- 
---------------------------- ---------------------------- ---------------------------- ---------------------------- ---------------------------- ---------------------------- ---------------------------- ---------------------------- ---------------------------- ---------------------------- ---------------------------- --A------------------------- --I----------------------I-- ---A---------------------A-- ---A---------------------A-- --A----------------------A-- --A----------------------A-- --A----------------------A-- --A----------------------A-- ---A--------------------A--- -B-A--------------------AB-- -B-AA------------------AE--- -B--A------------------AE--- --BE-AA--------------AA-E--- -----AA--------------AA-E--- -----GAA------------AAG-E--- ------AAA----------AAA------ -------AAAA------AAAA------- ---------AAAAAAAAAA--------- -----------GAAAHA----------- ---------------------------- 
---------------------------- ---------------------------- ---------------------------- ---------------------------- ---------------------------- ---------------------------- ---------------------------- ---------------------------- ---------------------------- ---------------------------- --I-----------------------A- --A-----------------------A- --A-----------------------A- --A-----------------------A- --A----------------------A-- --A----------------------A-- --A----------------------A-- --A----------------------A-- --A----------------------A-- -B-A--------------------A--- -B-A--------------------AB-- -B-AA------------------AAB-- -B--A------------------A-B-- -B--AA----------------AAE--- -----A----------------A----- -----AA--------------AA----- -----AAA------------AAA----- ------AAAA--------AAAA------ --------AAA------AAA-------- ----------AAAAAAAA---------- ---------------------------- 
---------------------------- ---------------------------- ---------------------------- ---------------------------- ---------------------------- ---------------------------- ---------------------------- ---------------------------- ---------------------------- -A------------------------I- --A-----------------------A- --A-----------------------A- --A-----------------------A- --A-----------------------A- --A----------------------A-- --A----------------------A-- -AA----------------------AA- -AA----------------------AA- -AA----------------------AA- -BGA--------------------AB-- -B-A--------------------AB-- -B-A--------------------AB-- -B-A--------------------AB-- ----AA----------------AA-B-- ----HA----------------AA---- -----AA--------------AA----- -----AAA------------AAA----- ------AAA----------AAA------ --------AA--------AH-------- ---------AGAAAAAAGG--------- ---------------------------- 
---------------------------- ---------------------------- ---------------------------- ---------------------------- ---------------------------- ---------------------------- ---------------------------- I--------------------------- -I------------------------A- -A------------------------A- -A------------------------A- -A------------------------A- -AA-----------------------A- --A-----------------------A- --A----------------------A-- --A----------------------A-- -AA----------------------AG- -AA----------------------AA- -AA----------------------AA- -BA----------------------AB- -BAA--------------------ABB- -B-A--------------------ABB- ---A--------------------AB-- ---AA------------------AA--- ----A------------------A---- ----AA----------------AA---- -----AA--------------AA----- -----AAA------------AAA----- -------AA----------AA------- --------AAAA----AAAA-------- ------------AAAA------------ 
---------------------------- ---------------------------- ---------------------------- ---------------------------- ---------------------------- I--------------------------- A-------------------------I- -A------------------------A- -A------------------------A- -A------------------------A- -A------------------------A- -A------------------------A- -AA----------------------AA- --A-----------------------A- --A----------------------A-- -AA----------------------AA- -AA----------------------AA- -AA----------------------AA- -BA----------------------AB- -BA----------------------AB- -BA----------------------AB- -BAA--------------------AAB- ---A--------------------A--- ---AA------------------AA--- ---AA------------------AG--- ----AA----------------AA---- ----AAH--------------AAA---- -----AAA------------AAA----- -------AA----------AA------- --------AAA------AAA-------- -----------AAAAAA----------- 
D--------------------------- D--------------------------D A--------------------------A A--------------------------A A--------------------------A A--------------------------A A--------------------------A A--------------------------A -A------------------------A- -A------------------------A- -A------------------------A- -A------------------------A- -AA----------------------AA- -AA-----------------------A- -AA----------------------AA- -AA----------------------AA- -AA----------------------AA- -AA----------------------AA- -BA----------------------AB- -BA----------------------AB- -BG----------------------AB- --AA--------------------AH-- ---A--------------------A--- ---HA------------------AA--- ---AA------------------AA--- ---AAA----------------AAA--- ----AAA--------------AAA---- -----AAA------------AAA----- -------AA----------AA------- --------AAA------AAA-------- -----------AAAAAA----------- 
---------------------------D D--------------------------D A--------------------------A A--------------------------A A--------------------------A A--------------------------A A--------------------------A A--------------------------A A-------------------------A- -A------------------------A- -A------------------------A- -A------------------------A- -AA----------------------AA- -A-----------------------AA- --A----------------------AA- -AA----------------------AA- -AA----------------------AA- -BA----------------------AB- -BA----------------------AB- -BA----------------------AB- -BA----------------------AB- --AA--------------------AA-- ---A--------------------A--- ---AA------------------AA--- ---AA------------------AA--- ---AAA----------------AAA--- ----AAA--------------AAA---- -----AAA------------AAA----- -------AA----------AA------- --------AAA------AAA-------- -----------AAGAAA----------- 
---------------------------- ---------------------------- ---------------------------- ---------------------------- ---------------------------- ---------------------------I -I-------------------------A -A------------------------A- -A------------------------A- -A------------------------A- -A------------------------A- -A------------------------A- -AA----------------------AA- -A-----------------------A-- --A----------------------A-- --A----------------------AA- -AA----------------------AA- -BA----------------------AB- -BA----------------------AB- -BA----------------------AB- --A----------------------A-- --AA--------------------AA-- ---A--------------------A--- ---AA------------------AA--- ---AA------------------AA--- ----AA----------------AA---- ----AAA--------------AAA---- -----AAA------------AAA----- -------AA----------AA------- --------AAA------GAA-------- -----------AAAAAA----------- 
---------------------------- ---------------------------- ---------------------------- ---------------------------- ---------------------------- ---------------------------- ---------------------------- ---------------------------I -A------------------------I- -A------------------------A- -A------------------------A- -A------------------------A- -A-----------------------AA- -A-----------------------A-- --A----------------------A-- --A----------------------A-- -AA----------------------AA- -BA----------------------AB- -BA----------------------AB- -BA----------------------AB- --A----------------------A-- ---A--------------------A--- ---A--------------------A--- ---GA------------------AA--- ----A------------------A---- ----AA----------------AA---- -----AA--------------AA----- -----AAA------------AAA----- -------AA----------AA------- --------AAAA----AAAA-------- ------------AAAA------------ 
---------------------------- ---------------------------- ---------------------------- ---------------------------- ---------------------------- ---------------------------- ---------------------------- ---------------------------- ---------------------------- -I------------------------A- -A-----------------------A-- -A-----------------------A-- -A-----------------------A-- -A-----------------------A-- --A----------------------A-- --A----------------------A-- -BA----------------------AB- -BA----------------------AB- -BA----------------------AB- --A----------------------A-- --A----------------------A-- ---A--------------------A--- ---A--------------------A--- ----AA----------------AA---- ----AA----------------AA---- -----AA--------------AA----- -----AAH------------AAA----- ------AAA----------HAA------ --------AA--------AH-------- ---------AAAAAAAAAA--------- ---------------------------- 
---------------------------- ---------------------------- ---------------------------- ---------------------------- ---------------------------- ---------------------------- ---------------------------- ---------------------------- ---------------------------- ---------------------------- -A-----------------------I-- -A-----------------------A-- -A-----------------------A-- -A-----------------------A-- --A----------------------A-- --A----------------------AB- -BA----------------------AB- -BA----------------------AB- -BH----------------------HB- ---A--------------------A--- ---A--------------------A--- ---AA------------------AA--- ----A------------------A---- ----AA----------------AA---- -----A----------------A----- -----AA--------------AA----- -----AAA------------AAA----- ------AAAA--------AAAA------ --------AAA------AAA-------- ----------AAAAAAAG---------- ---------------------------- 
---------------------------- ---------------------------- ---------------------------- ---------------------------- ---------------------------- ---------------------------- ---------------------------- ---------------------------- ---------------------------- ---------------------------- ---------------------------- -------------------------A-- --I----------------------I-- --A---------------------A--- --A---------------------A--- -BA----------------------AB- -BA----------------------AB- -BA----------------------AB- -BA----------------------AB- ---A--------------------A--- ---A--------------------G--- ---AA------------------AA--- ----A------------------A---- -----AA--------------AA----- -----AA--------------AA----- -----AAA------------AAA----- ------AAA----------AAG------ -------AAAA------AAAA------- ---------AAAAAAAAAA--------- -----------AHAAAA----------- ---------------------------- 
---------------------------- ---------------------------- ---------------------------- ---------------------------- ---------------------------- ---------------------------- ---------------------------- ---------------------------- ---------------------------- ---------------------------- ---------------------------- ---------------------------- ---------------------------- --A------------------------- --B---------------------AB-- --B---------------------AB-- --BA--------------------AB-- --BA--------------------AB-- ---A--------------------A--- ----A------------------A---- ----A------------------A---- ----AA----------------AA---- -----A----------------A----- -----AA--------------AA----- -----AA--------------AA----- ------GAA----------AAA------ -------AAAA------AAAA------- --------AAAAAAAAAAAA-------- -----------GAAAAA----------- ---------------------------- ---------------------------- 
---------------------------- ---------------------------- ---------------------------- ---------------------------- ---------------------------- ---------------------------- ---------------------------- ---------------------------- ---------------------------- ---------------------------- ---------------------------- ---------------------------- ---------------------------- --A----------------------A-- --BA--------------------AB-- --BB--------------------BB-- --BA--------------------AB-- --BA--------------------AB-- ---A--------------------A--- ----AA----------------AA---- ----AA----------------AA---- ----AAA--------------AAA---- -----AA--------------AA----- -----AAAA----------AAAH----- ------AAA----------AAA------ -------AAAA------AAAA------- --------AAAHAAAHAAAA-------- ---------AAAAAAAAHA--------- ---------------------------- ---------------------------- ---------------------------- 
---------------------------- ---------------------------- ---------------------------- ---------------------------- ---------------------------- ---------------------------- ---------------------------- ---------------------------- ---------------------------- ---------------------------- ---------------------------- ---------------------------- ---------------------------- ---A--------------------A--- ---BA------------------AB--- ---BA------------------AB--- ---BA------------------AB--- ----A------------------A---- ----A------------------A---- -----AA--------------AA----- -----AA--------------AA----- -----AAA------------AAA----- -----AAA------------AAA----- ------AAAAA------AAAAA------ -------AAAA------AAAA------- --------GAAAAAAAAAAA-------- ----------AAAAAGAA---------- -----------AAAAAA----------- ---------------------------- ---------------------------- ---------------------------- 
---------------------------- ---------------------------- ---------------------------- ---------------------------- ---------------------------- ---------------------------- ---------------------------- ---------------------------- ---------------------------- ---------------------------- ---------------------------- ---------------------------- ---------------------------- ----A------------------A---- ----BA----------------AB---- ----BA----------------AB---- ----BA----------------AB---- -----A----------------H----- -----A----------------G----- ------AA------------AG------ ------GA------------AA------ ------AAAA--------AAAA------ -------AAA--------AAA------- ---------AAAAAAAAAA--------- ---------AAAAAAAAAA--------- ----------AAGAAAAA---------- ---------------------------- ---------------------------- ---------------------------- ---------------------------- ---------------------------- 
---------------------------- ---------------------------- ---------------------------- ---------------------------- ---------------------------- ---------------------------- ---------------------------- ---------------------------- ---------------------------- ---------------------------- ---------------------------- ---------------------------- ---------------------------- -----A----------------A----- -----BAA------------AAB----- -----BAA------------AAB----- -----BAA------------AAB----- ------AH------------AA------ ------AA------------AA------ --------AA--------AA-------- --------AA--------AA-------- --------AAAAAAAAAAAG-------- --------AAAAAAAAAHAA-------- -----------AAAAAA----------- ---------------------------- ---------------------------- ---------------------------- ---------------------------- ---------------------------- ---------------------------- ---------------------------- 
---------------------------- ---------------------------- ---------------------------- ---------------------------- ---------------------------- ---------------------------- ---------------------------- ---------------------------- ---------------------------- ---------------------------- ---------------------------- ---------------------------- ---------------------------- ------AA------------AA------ ------BBAA--------AABB------ ------BBAA--------AABB------ ------BBAA--------AABB------ --------AA--------AA-------- --------AA--------AA-------- ----------AAAAAAAA---------- ----------AAAAAAAA---------- ----------AAAAAAAA---------- -----------AAGAAA----------- ---------------------------- ---------------------------- ---------------------------- ---------------------------- ---------------------------- ---------------------------- ---------------------------- ---------------------------- 
---------------------------- ---------------------------- ---------------------------- ---------------------------- ---------------------------- ---------------------------- ---------------------------- ---------------------------- ---------------------------- ---------------------------- ---------------------------- ---------------------------- ---------------------------- --------AA--------AA-------- --------BBAAAAAAAABB-------- --------BBAAAAAAAABB-------- --------BBAAAAAAABBB-------- ----------AAAAAAAA---------- ----------AAAAAGAA---------- -----------AAAAAA----------- ---------------------------- ---------------------------- ---------------------------- ---------------------------- ---------------------------- ---------------------------- ---------------------------- ---------------------------- ---------------------------- ---------------------------- ---------------------------- 
---------------------------- ---------------------------- ---------------------------- ---------------------------- ---------------------------- ---------------------------- ---------------------------- ---------------------------- ---------------------------- ---------------------------- ---------------------------- ---------------------------- ---------------------------- ----------AAAAAAAA---------- ----------BBBBBBBB---------- ----------BBBBBBBB---------- ----------BBBBBBBB---------- ---------------------------- ---------------------------- ---------------------------- ---------------------------- ---------------------------- ---------------------------- ---------------------------- ---------------------------- ---------------------------- ---------------------------- ---------------------------- ---------------------------- ---------------------------- ---------------------------- 
