model
size = 30 31 23, scale = 0.05, origin = -y
material 
  colors = A:#2A4A5B B:#E3E3E3 C:#959595 D:#46647C E:#5E5E5E F:#BBB
voxels
------------------------------ ------------------------------ ------------------------------ ------------------------------ ------------------------------ ------------------------------ ------------------------------ ------------------------------ ------------------------------ ------------------------------ ------------------------------ ------------------------------ ------------------------------ -------------ABCC------------- -------------BBCC------------- -------------BBCC------------- -------------BBCA------------- -------------BAAA------------- -------------AAAA------------- -------------AAAA------------- -------------AACC------------- -------------AAAA------------- -------------AAAA------------- ------------------------------ ------------------------------ ------------------------------ ------------------------------ ------------------------------ ------------------------------ ------------------------------ ------------------------------ 
------------------------------ ------------------------------ ------------------------------ ------------------------------ ------------------------------ ------------------------------ ------------------------------ ------------------------------ -------------BBAA------------- -------------BBCA------------- -------------BAAA------------- -------------AAAA------------- -------------AAAC------------- ----------AAA----CCC---------- ----------ABB----CCC---------- ----------BBB----CCA---------- ----------BBB----AAA---------- ----------BBB----AAA---------- ----------BBA----AAC---------- ----------AAA----CCC---------- ----------AAA----CCC---------- ----------AAA----AAC---------- ----------BBA----ACC---------- -------------BAAA------------- -------------BBCC------------- -------------BBCC------------- ------------------------------ ------------------------------ ------------------------------ ------------------------------ ------------------------------ 
--------------AA-------------- -------------AAAA------------- -------------AAAA------------- -------------AFEA------------- -------------FBCE------------- -------------BBCC------------- -------------BBAC------------- -------------BBAA------------- ----------BBB----AAA---------- ----------BBB----AAA---------- ----------BBB----AAA---------- ----------BAA----ACC---------- ----------AAA----CCC---------- --------AA----------CC-------- --------AA----------CA-------- --------BB----------AA-------- --------BB----------AA-------- --------BB----------AC-------- --------BB----------CC-------- --------BB----------CC-------- --------BA----------CC-------- --------BB----------CC-------- --------BB----------CC-------- ----------BBB----CCC---------- ----------BBB----CCC---------- ----------FFB----CEE---------- -------------FBCE------------- -------------AFEA------------- -------------AAAA------------- -------------AAAA------------- -------------AAAA------------- 
--------------AA-------------- ------------AAAAAA------------ ----------AAAAAAAAAA---------- ----------AAAA--AAAA---------- ----------AAF----EAA---------- ----------FFB----CEE---------- ----------BBB----CCC---------- ----------BBB----ACC---------- --------BB----------CC-------- --------BB----------AC-------- --------BB----------CC-------- --------BB----------CC-------- --------AA----------CC-------- ----AFAA--------------CAAA---- ----AAAA--------------AAAA---- ----AAAA--------------AAAE---- ----AABB--------------ACCE---- ----BBBB--------------CCCE---- ----BBBB--------------CCCC---- ----BBBB--------------CCCC---- ----BBBB--------------CCCC---- ----BBBB--------------CCCC---- ----FFBB--------------CCEE---- --------BB----------CC-------- --------FF----------EE-------- --------AA----------AA-------- ----------AAF----EAA---------- ----------AAAA--AAAA---------- ----------AAAAAAAAAA---------- ----------AAAAAAAAAA---------- ------------AAAAAA------------ 
------------------------------ ------------A----A------------ ----------AAA----AAA---------- --------AAAAA----AAAAA-------- --------AAAA------AAAA-------- --------AA----------AA-------- --------FF----------EE-------- --------BB----------CC-------- ----AAFB--------------CEAA---- ----AAFB--------------CEAA---- ----AFBB--------------CCEA---- ----AFBB--------------CCEA---- ----AFBB--------------CCEA---- -AAAA---------------------AAA- -AAA----------------------AAA- -AAA----------------------AAA- -AAA----------------------AAA- AAAA----------------------AAAA AAAF----------------------EAAA AAAF----------------------EAAA AAAF----------------------EAAA AAAF----------------------EAAA AAAA----------------------AAAA ----AAFF--------------EEAA---- ----AAAA--------------AAAA---- ----AAAAAA----------AAAAAA---- --------AAAA------AAAA-------- --------AAAAA----AAAAA-------- --------AAAAA----AAAAA-------- ----------AAA----AAA---------- ------------A----A------------ 
------------------------------ ------------------------------ ------------------------------ --------AA----------AA-------- ------AAAA----------AAAA------ ----AAAAAA----------AAAAAA---- ----AAAA--------------AAAA---- ----AAFF--------------EEAA---- ---AAA------------------AAA--- --AAAA------------------AAAA-- --AAA---------------------AA-- --AAA---------------------AA-- --AAA---------------------AA-- -AAA----------------------AAA- -AAA----------------------AAA- -AAA----------------------AAA- -AAA----------------------AAA- AAAA----------------------AAAA AAA------------------------AAA AAA------------------------AAA AAA------------------------AAA AAA------------------------AAA AAAA----------------------AAAA AAAAAA------------------AAAAAA AAAAAAAA--------------AAAAAAAA --AAAAAA--------------AAAAAA-- ----AAAAAA----------AAAAAA---- ------AAAA----------AAAA------ --------AA----------AA-------- ------------------------------ ------------------------------ 
------------------------------ ------------------------------ ------------------------------ ------------------------------ ------AA--------------AA------ ----AAAA--------------AAAA---- ---AAAAA--------------AAAAA--- ---AAA------------------AAA--- ---A----------------------A--- --AA----------------------AA-- --AA----------------------AA-- --AA----------------------AA-- --AA----------------------AA-- --AA----------------------AA-- --AA----------------------AA-- --AA----------------------AA-- --AA----------------------AA-- -AA------------------------AA- -AA------------------------AA- -AA------------------------AA- -AA------------------------AA- -AA------------------------AA- -AA------------------------AA- AAAA----------------------AAAA AAAA----------------------AAAA --AA----------------------AA-- ----AAAA--------------AAAA---- ------AA--------------AA------ ------------------------------ ------------------------------ ------------------------------ 
------------------------------ ------------------------------ ------------------------------ ------------------------------ ------------------------------ ------------------------------ ---A----------------------A--- ---A----------------------A--- ---A----------------------A--- --AA----------------------AA-- --AA----------------------AA-- --AA----------------------AA-- --AA----------------------AA-- --AA----------------------AA-- --AA----------------------AA-- --AA----------------------AA-- --AA----------------------AA-- -AA------------------------AA- -AA------------------------AA- -AA------------------------AA- -AA------------------------AA- -AA------------------------AA- -AA------------------------AA- AAA------------------------AAA AAA------------------------AAA ------------------------------ ------------------------------ ------------------------------ ------------------------------ ------------------------------ ------------------------------ 
------------------------------ ------------------------------ ------------------------------ ------------------------------ ------------------------------ ------------------------------ ---A----------------------A--- ---A----------------------A--- ---A----------------------A--- --AA----------------------AA-- --AA----------------------AA-- --AA----------------------AA-- --AA----------------------AA-- --AA----------------------AA-- --AA----------------------AA-- --AA----------------------AA-- --AA----------------------AA-- -AA------------------------AA- -AA------------------------AA- -AA------------------------AA- -AA------------------------AA- -AA------------------------AA- -AA------------------------AA- AAA------------------------AAA AAA------------------------AAA ------------------------------ ------------------------------ ------------------------------ ------------------------------ ------------------------------ ------------------------------ 
------------------------------ ------------------------------ ------------------------------ ------------------------------ ------------------------------ ------------------------------ ---A----------------------A--- ---A----------------------A--- ---A----------------------A--- --AA----------------------AA-- --AA----------------------AA-- --AA----------------------AA-- --AA----------------------AA-- --AA----------------------AA-- --AA----------------------AA-- --AA----------------------AA-- --AA----------------------AA-- -AA------------------------AA- -AA------------------------AA- -AA------------------------AA- -AA------------------------AA- -AA------------------------AA- -AA------------------------AA- AAA------------------------AAA AAA------------------------AAA ------------------------------ ------------------------------ ------------------------------ ------------------------------ ------------------------------ ------------------------------ 
------------------------------ ------------------------------ ------------------------------ ------------------------------ ------------------------------ ------------------------------ ---A----------------------A--- ---A----------------------A--- ---A----------------------A--- --AA----------------------AA-- --AA----------------------AA-- --AA----------------------AA-- --AA----------------------AA-- --AA----------------------AA-- --AA----------------------AA-- --AA----------------------AA-- --AA----------------------AA-- -AA------------------------AA- -AA------------------------AA- -AA------------------------AA- -AA------------------------AA- -AA------------------------AA- -AA------------------------AA- AAA------------------------AAA AAA------------------------AAA ------------------------------ ------------------------------ ------------------------------ ------------------------------ ------------------------------ ------------------------------ 
------------------------------ ------------------------------ ------------------------------ ------------------------------ ------------------------------ ------------------------------ ------------------------------ ---A----------------------A--- ---A----------------------A--- --AA----------------------AA-- --AA----------------------AA-- --AA----------------------AA-- --AA----------------------AA-- --AA----------------------AA-- --AA----------------------AA-- --AA----------------------AA-- --AA----------------------AA-- -AA------------------------AA- -AA------------------------AA- -AA------------------------AA- -AA------------------------AA- -AA------------------------AA- -AA------------------------AA- AAA------------------------AAA AAA------------------------AAA ------------------------------ ------------------------------ ------------------------------ ------------------------------ ------------------------------ ------------------------------ 
------------------------------ ------------------------------ ------------------------------ ------------------------------ ------------------------------ ------------------------------ ------------------------------ ---A----------------------A--- ---A----------------------A--- --AA----------------------AA-- --AA----------------------AA-- --AA----------------------AA-- --AA----------------------AA-- --AA----------------------AA-- --AA----------------------AA-- --AA----------------------AA-- --AA----------------------AA-- -AA------------------------AA- -AA------------------------AA- -AA------------------------AA- -AA------------------------AA- -AA------------------------AA- -AA------------------------AA- AAA------------------------AAA AAA------------------------AAA ------------------------------ ------------------------------ ------------------------------ ------------------------------ ------------------------------ ------------------------------ 
------------------------------ ------------------------------ ------------------------------ ------------------------------ ------------------------------ ------------------------------ ------------------------------ ---A----------------------A--- ---A----------------------A--- --AA----------------------AA-- --AA----------------------AA-- --AA----------------------AA-- --AA----------------------AA-- --AA----------------------AA-- --AA----------------------AA-- --AA----------------------AA-- --AA----------------------AA-- -AA------------------------AA- -AA------------------------AA- -AA------------------------AA- -AA------------------------AA- -AA------------------------AA- -AA------------------------AA- AAA------------------------AAA AAA------------------------AAA ------------------------------ ------------------------------ ------------------------------ ------------------------------ ------------------------------ ------------------------------ 
------------------------------ ------------------------------ ------------------------------ ------------------------------ ------------------------------ ------------------------------ ------------------------------ ---A----------------------A--- ---A----------------------A--- --AA----------------------AA-- --AA----------------------AA-- --DA----------------------AD-- --DA----------------------AD-- --DA----------------------AD-- --DA----------------------AD-- --AA----------------------AA-- --AA----------------------AA-- -AA------------------------AA- -AA------------------------AA- -DA------------------------AD- -DA------------------------AD- -AA------------------------AA- -AA------------------------AA- AAA------------------------AAA AAA------------------------AAA ------------------------------ ------------------------------ ------------------------------ ------------------------------ ------------------------------ ------------------------------ 
------------------------------ ------------------------------ ------------------------------ ------------------------------ ------------------------------ ------------------------------ ------------------------------ ---A----------------------A--- ---A----------------------A--- --AA----------------------AA-- --DA----------------------AD-- ------------------------------ ------------------------------ ------------------------------ ------------------------------ --DA----------------------AD-- --AA----------------------AA-- -AA------------------------AA- -DA------------------------AD- ------------------------------ ------------------------------ -DA------------------------AD- -AA------------------------AA- AAA------------------------AAA AAA------------------------AAA ------------------------------ ------------------------------ ------------------------------ ------------------------------ ------------------------------ ------------------------------ 
------------------------------ ------------------------------ ------------------------------ ------------------------------ ------------------------------ ------------------------------ ------------------------------ ------------------------------ ---A----------------------A--- --DA----------------------AD-- ------------------------------ ------------------------------ ------------------------------ ------------------------------ ------------------------------ ------------------------------ --DA----------------------AD-- -DA------------------------AD- ------------------------------ ------------------------------ ------------------------------ ------------------------------ -DA------------------------AD- AAA------------------------AAA AAA------------------------AAA ------------------------------ ------------------------------ ------------------------------ ------------------------------ ------------------------------ ------------------------------ 
------------------------------ ------------------------------ ------------------------------ ------------------------------ ------------------------------ ------------------------------ ------------------------------ ------------------------------ ---A----------------------A--- --DA----------------------AD-- ------------------------------ ------------------------------ ------------------------------ ------------------------------ ------------------------------ ------------------------------ --DA----------------------AD-- -DA------------------------AD- ------------------------------ ------------------------------ ------------------------------ ------------------------------ -DA------------------------AD- AAA------------------------AAA AAA------------------------AAA ------------------------------ ------------------------------ ------------------------------ ------------------------------ ------------------------------ ------------------------------ 
------------------------------ ------------------------------ ------------------------------ ------------------------------ ------------------------------ ------------------------------ ------------------------------ ------------------------------ ---A----------------------A--- --DA----------------------AD-- ------------------------------ ------------------------------ ------------------------------ ------------------------------ ------------------------------ ------------------------------ --DA----------------------AD-- -DA------------------------AD- ------------------------------ ------------------------------ ------------------------------ ------------------------------ -DA------------------------AD- AAA------------------------AAA AAA------------------------AAA ------------------------------ ------------------------------ ------------------------------ ------------------------------ ------------------------------ ------------------------------ 
------------------------------ ------------------------------ ------------------------------ ------------------------------ ------------------------------ ------------------------------ ------------------------------ ------------------------------ ---A----------------------A--- --DA----------------------AD-- ------------------------------ ------------------------------ ------------------------------ ------------------------------ ------------------------------ ------------------------------ --DA----------------------AD-- -DA------------------------AD- ------------------------------ ------------------------------ ------------------------------ ------------------------------ -DA------------------------AD- AAA------------------------AAA AAA------------------------AAA ------------------------------ ------------------------------ ------------------------------ ------------------------------ ------------------------------ ------------------------------ 
------------------------------ ------------------------------ ------------------------------ ------------------------------ ------------------------------ ------------------------------ ------------------------------ ------------------------------ ------------------------------ --AA----------------------AA-- --DA----------------------AD-- ------------------------------ ------------------------------ ------------------------------ ------------------------------ --DA----------------------AD-- --AA----------------------AA-- -AA------------------------AA- -DA------------------------AD- ------------------------------ ------------------------------ -DA------------------------AD- -AA------------------------AA- ------------------------------ ------------------------------ ------------------------------ ------------------------------ ------------------------------ ------------------------------ ------------------------------ ------------------------------ 
------------------------------ ------------------------------ ------------------------------ ------------------------------ ------------------------------ ------------------------------ ------------------------------ ------------------------------ ------------------------------ ------------------------------ --AA----------------------AA-- --DA----------------------AD-- --DA----------------------AD-- --DA----------------------AD-- --DA----------------------AD-- --AA----------------------AA-- ------------------------------ ------------------------------ -AA------------------------AA- -DA------------------------AD- -DA------------------------AD- -AA------------------------AA- ------------------------------ ------------------------------ ------------------------------ ------------------------------ ------------------------------ ------------------------------ ------------------------------ ------------------------------ ------------------------------ 
------------------------------ ------------------------------ ------------------------------ ------------------------------ ------------------------------ ------------------------------ ------------------------------ ------------------------------ ------------------------------ ------------------------------ ------------------------------ ------------------------------ ------------------------------ ------------------------------ ------------------------------ ------------------------------ ------------------------------ ------------------------------ ------------------------------ -AA------------------------AA- -AA------------------------AA- ------------------------------ ------------------------------ ------------------------------ ------------------------------ ------------------------------ ------------------------------ ------------------------------ ------------------------------ ------------------------------ ------------------------------ 
