model
size = 30 31 8, scale = 0.05, origin = -y
material 
  colors = A:#2A4A5B B:#E3E3E3 C:#959595 D:#BBB E:#5E5E5E F:#46647C
voxels
--------------AA-------------- ------------AAAAAA------------ ----------AAAAAAAAAA---------- --------AAAAAA--AAAAAA-------- ------AAAAAA------AAAAAA------ ----AAAAAA----------AAAAAA---- ---AAAAA-------A------AAAAA--- ---AAA---------AAA------AAA--- ---AAA---------AAAAA----AAA--- --AAAA----------AAAAA---AAAA-- --AAA---------AAAAAA-----AAA-- --AAA------AAAAAAA-------AAA-- --AAA---AAAAAAAA---------AAA-- -AAAA-AAAAAAAA---------AAAAAA- -AAAAAAAAAA----------AAAAAAAA- -AAAAAAA-----------AAAAAA-AAA- -AAAAA----------AAAAAAA---AAA- AAAA----------AAAAAAA-----AAAA AAA---------AAAAAAA--------AAA AAA-------AAAAAAA----------AAA AAA------AAAAAA------------AAA AAA-------AAAAAAAAA--------AAA AAAA--------AAAAAA--------AAAA AAAAAA--------AAA-------AAAAAA AAAAAAAA--------------AAAAAAAA --AAAAAAAA----------AAAAAAAA-- ----AAAAAAAA------AAAAAAAA---- ------AAAAAAAA--AAAAAAAA------ --------AAAAAAAAAAAAAA-------- ----------AAAAAAAAAA---------- ------------AAAAAA------------ 
--------------AA-------------- ------------AAAAAA------------ ----------AAAAAAAAAA---------- --------AAAAAADEAAAAAA-------- ------AAAAAADDBCEEAAAAAA------ ----AAAAAADDBBBCCCEEAAAAAA---- ---AAAAADDBBBBBCCCCCEEAAAAA--- ---AAADDBBBBBBBCCCCCCCEEAAA--- ---AAADBBBBBBBBBBCCCCCCEAAA--- --AAAADBBBBBBBBCBBCCCCCCAAAA-- --AAADBBBBBBBBBBBBBCCCCCCCAA-- --AAADBBBBBBBBBCCCCCCCCCCCAA-- --AAADBBBBBBBBBBCCCCCCCCCCAA-- -AAAADBBBBBBBBBCCCCCCCCCCCAAA- -AAABBBBBBBBBBBCCCCCCCCCCBAAA- -AAABBBBBBBBBBBCCCCBBBBCCEAAA- -AAABBBBBBBBBBBCBBBBBBBCCEAAA- AAAABBBBBBBBBBBBBBBBBCCCCEAAAA AAADBBBBBBBBBBBBBBBCCCCCCCEAAA AAADBBBBBBBBBBBBBCCCCCCCCCEAAA AAADBBBBBBBBBBBCCCCCCCCCCCEAAA AAADBBBBBBBBBBBBBBBCCCCCCCEAAA AAAADDBBBBBBBBBBBBCCCCCCEEAAAA AAAAAADDBBBBBBBBBCCCCCEEAAAAAA AAAAAAAADDBBBBBCCCCCEEAAAAAAAA --AAAAAAAADDBBBCCCEEAAAAAAAA-- ----AAAAAAAADDBCEEAAAAAAAA---- ------AAAAAAAADEAAAAAAAA------ --------AAAAAAAAAAAAAA-------- ----------AAAAAAAAAA---------- ------------AAAAAA------------ 
--------------AA-------------- ------------AAAAAA------------ ----------AAAAAAAAAA---------- --------AAAAAAAAAAAAAA-------- ------AAAAAAAAAAAAAAAAAA------ ----AAAAAAAAAAAAAAAAAAAAAA---- ---AAAAAAAAAAAAAAAAAAAAAAAA--- ---AAAAAAAAAAAAAAAAAAAAAAAA--- ---AAAAAAAAAAAAAAAAAAAAAAAA--- --AAAAAAAAAAAAAAAAAAAAAAAAAA-- --AAAAAAAAAAAAAAAAAAAAAAAAAA-- --AAAAAAAAAAAAAAAAAAAAAAAAAA-- --AAAAAAAAAAAAAAAAAAAAAAAAAA-- -AAAAAAAAAAAAAAAAAAAAAAAAAAAA- -AAAAAAAAAAAAAAAAAAAAAAAAAAAA- -AAAAAAAAAAAAAAAAAAAAAAAAAAAA- -AAAAAAAAAAAAAAAAAAAAAAAAAAAA- AAAAAAAAAAAAAAAAAAAAAAAAAAAAAA AAAAAAAAAAAAAAAAAAAAAAAAAAAAAA AAAAAAAAAAAAAAAAAAAAAAAAAAAAAA AAAAAAAAAAAAAAAAAAAAAAAAAAAAAA AAAAAAAAAAAAAAAAAAAAAAAAAAAAAA AAAAAAAAAAAAAAAAAAAAAAAAAAAAAA AAAAAAAAAAAAAAAAAAAAAAAAAAAAAA AAAAAAAAAAAAAAAAAAAAAAAAAAAAAA --AAAAAAAAAAAAAAAAAAAAAAAAAA-- ----AAAAAAAAAAAAAAAAAAAAAA---- ------AAAAAAAAAAAAAAAAAA------ --------AAAAAAAAAAAAAA-------- ----------AAAAAAAAAA---------- ------------AAAAAA------------ 
--------------AA-------------- ------------AAAAAA------------ ----------AAAAAAAAAA---------- --------AAAAAAEEAAAAAA-------- ------AAAAAAEECCEEAAAAAA------ ----AAAAAAEEECCDDEEEAAAAAA---- ---AAAAAEECCECCDDECCEEAAAAA--- ---AAAEECCCDECDDDECCCDEEAAA--- ---AAAEECCDDECDDDECCDDEEAAA--- --AAAAEECDDDECDDDECDDDECAAAA-- --AAAECECDDDECDDDECDDDECCCAA-- --AAAECECDDDECDDDECDDDECDCAA-- --AAAECECDDDECDDDECDDDECDCAA-- -AAAAECECDDDECDDDECDDDECDCAAA- -AAAECDECDDDECDDBECDDDECDEAAA- -AAAECDECDDDECDDBECDDDECDEAAA- -AAAECDECDDBECDDBECDDBECDEAAA- AAAAECDECDDBECDDBECDDBECDEAAAA AAAECDBECDDBECDDBECDDBEDDBEAAA AAAECDBECDDBECDDBECDDBEDDBEAAA AAAECDBECDDBECDDBECDDBEDDDEAAA AAAECDDECDDBECDDDECDDBEDDBEAAA AAAAEEBECDDDECDDBECDDDECEEAAAA AAAAAAEECDDBECDDBECDDBEEAAAAAA AAAAAAAAEEDBECDDBECDEEAAAAAAAA --AAAAAAAAEEECDDBEEEAAAAAAAA-- ----AAAAAAAAEEDBEEAAAAAAAA---- ------AAAAAAAAEEAAAAAAAA------ --------AAAAAAAAAAAAAA-------- ----------AAAAAAAAAA---------- ------------AAAAAA------------ 
--------------AA-------------- ------------AAAAAA------------ ----------AAAAAAAAAA---------- --------AAAAAA--AAAAAA-------- ------AAAAAA------AAAAAA------ ----AAAAAA----------AAAAAA---- ---AAAAA--------------AAAAA--- ---AAA------------------AAA--- ---AAA------------------AAA--- --AAAA------------------AAAA-- --AAA--------------------AAA-- --AAA--------------------AAA-- --AAA--------------------AAA-- -AAAA--------------------AAAA- -AAA---EE------------EE---AAA- -AAA---EE------------EE---AAA- -AAA---EE------------EE---AAA- AAAA---EE------------EE---AAAA AAA------------------------AAA AAA------------------------AAA AAA------------------------AAA AAA------------------------AAA AAAA----------------------AAAA AAAAAA------------------AAAAAA AAAAAAAA--------------AAAAAAAA --AAAAAAAA----------AAAAAAAA-- ----AAAAAAAA------AAAAAAAA---- ------AAAAAAAA--AAAAAAAA------ --------AAAAAAAAAAAAAA-------- ----------AAAAAAAAAA---------- ------------AAAAAA------------ 
------------------------------ ------------------------------ ------------------------------ ------------------------------ ------------------------------ ------------------------------ ------------------------------ ------------------------------ ------------------------------ ------------------------------ ------------------------------ ------------------------------ ------------------------------ ------------------------------ --------AA----------AA-------- --------FF----------FF-------- --------FF----------FF-------- --------AA----------AA-------- ------------------------------ ------------------------------ ------------------------------ ------------------------------ ------------------------------ ------------------------------ ------------------------------ ------------------------------ ------------------------------ ------------------------------ ------------------------------ ------------------------------ ------------------------------ 
------------------------------ ------------------------------ ------------------------------ ------------------------------ ------------------------------ ------------------------------ ------------------------------ ------------------------------ ------------------------------ ------------------------------ ------------------------------ ------------------------------ ------------------------------ ------------------------------ ---------AAA------AAA--------- ---------FFF------FFF--------- ---------FFF------FFF--------- ---------AAA------AAA--------- ------------------------------ ------------------------------ ------------------------------ ------------------------------ ------------------------------ ------------------------------ ------------------------------ ------------------------------ ------------------------------ ------------------------------ ------------------------------ ------------------------------ ------------------------------ 
------------------------------ ------------------------------ ------------------------------ ------------------------------ ------------------------------ ------------------------------ ------------------------------ ------------------------------ ------------------------------ ------------------------------ ------------------------------ ------------------------------ ------------------------------ ------------------------------ -----------AAAAAAAA----------- -----------FFFFFFFF----------- -----------FFFFFFFF----------- -----------AAAAAAAA----------- ------------------------------ ------------------------------ ------------------------------ ------------------------------ ------------------------------ ------------------------------ ------------------------------ ------------------------------ ------------------------------ ------------------------------ ------------------------------ ------------------------------ ------------------------------ 
