model
size = 13 5 6, scale = 0.05, origin = -y
material 
  colors = A:#444 B:#111
voxels
--AAA---AAA-- -ABBBA-ABBBA- -ABBBBABBBBA- -ABBBBABBBBA- AAAAAA-AAAAAA 
------------- ------------- ------------- ------------- A-----------A 
------------- ------------- ------------- ------------- A-----------A 
------------- ------------- ------------- ------------- A-----------A 
------------- ------------- ------------- ------------- A-----------A 
------------- ------------- ------------- ------------- A-----------A 
