model
size = 19 18 24, scale = 0.05, origin = -y
material 
  colors = A:#0D0 B:#111 C:#0B0 D:#080 E:#444 F:#100
voxels
------------------- ------------------- ------------------- -------BBBBB------- -----AA-----AA----- ------------------- ------------------- -----A-------A----- ------A-----A------ ------A-AAA-A------ -------A---A------- ------------------- ------------------- ------------------- ------------------- ------------------- ------------------- ------------------- 
------------------- ------------------- ------------------- --------BBB-------- -----AAA---AAA----- -----A-------A----- ------------------- -----A-------A----- ------A-----A------ -------AAAAA------- ------------------- ------------------- ------------------- ------------------- ------------------- ------------------- ------------------- ------------------- 
------------------- ------------------- ------------------- --------BBB-------- ------AA---AA------ ------A-----A------ -----A-------A----- -----AA-----AA----- -------A---A------- -------AAAAA------- ------------------- ------------------- ------------------- ------------------- ------------------- ------------------- ------------------- ------------------- 
------------------- ------------------- ------------------- ---------B--------- ------AAA-AAA------ ------A-----A------ ------A-----A------ ------A-----A------ -------A---A------- -------AA--A------- ---------AA-------- ------------------- ------------------- ------------------- ------------------- ------------------- ------------------- ------------------- 
------------------- ------------------- ------------------- --------BBB-------- ------AA---AA------ ------A-----A------ ------A-----A------ ------A-----A------ -------A---A------- -------A---A------- -------AA--A------- --------AAA-------- --------AAA-------- --------AAA-------- --------AAA-------- ------------------- ------------------- ------------------- 
------------------- ------------------- ------------------- --------BBB-------- ------AA---AA------ ------A-----A------ ------A-----A------ ------A-----A------ -------A---A------- ------A-----A------ ------A-----A------ ------AA---AA------ ------AA---AA------ -------A---A------- -------A---A------- -------AAAAA------- --------AAA-------- ------------------- 
------------------- ------------------- ------------------- ---------B--------- ------AAA-AAA------ ------A-----A------ ------A-----A------ ------A-----A------ ------A-----A------ ------A-----A------ ------A-----A------ -----A-------A----- -----A-------A----- ------A-----A------ -------A---A------- -------A---A------- -------C---C------- --------EEE-------- 
------------------- ------------------- ------------------- ------AAAAAAA------ ------A-----A------ ------A-----A------ -----A-------A----- -----A-------A----- -----A-------A----- -----A-------A----- -----A-------A----- -----A-------A----- -----A-------A----- -----A-------A----- ------A-----A------ ------A-----A------ -------C---C------- --------EFE-------- 
------------------- ------------------- ------------------- ------AAAAAAA------ -----A-------A----- -----A-------A----- ----A---------A---- ----A---------A---- ----A---------A---- ----A---------A---- ----A---------A---- ----A---------A---- ----A---------A---- ----A---------A---- ----AA-------AA---- ------A-----A------ -------C---C------- --------EEE-------- 
------------------- ------------------- -------AAAAAA------ -----AA------A----- ----A---------A---- ----A---------A---- ---A-----------A--- ---A-----------A--- ---A-----------A--- ---A-----------A--- ----A---------A---- ---A-----------A--- ---A-----------A--- ---A-----------A--- ---A-----------A--- ----AA-------AA---- ------CC---CC------ --------EFE-------- 
------------------- -------AAAAA------- -----AA-----AA----- ----A---------A---- ---A-----------A--- ---A-----------A--- --A-------------A-- --A-------------A-- --A-------------A-- --A-------------A-- ---A-----------A--- ---A-----------A--- ---A-----------A--- ---A-----------A--- ---A-----------A--- ---AA---------AA--- -----CCA---AAA----- --------EEE-------- 
------------------- ------AAAAAAA------ ----AA-------AA---- ---A-----------A--- ---A-----------A--- --A-------------A-- --A-------------A-- -A---------------A- --A-------------A-- --A-------------A-- --A-------------A-- --A-------------A-- --A-------------A-- --A-------------A-- --A-------------A-- ---A-----------A--- ----CCBAA-AABAA---- ---------D--------- 
------------------- -----AAAAAAAAA----- ----A---------A---- ---A-----------A--- --A-------------A-- --A-------------A-- -A---------------A- -A---------------A- -A---------------A- --A-------------A-- --A-------------A-- --A-------------A-- --A-------------A-- --A-------------A-- --A-------------A-- ---A-----------A--- ----CBBBA-ABBBA---- ---------D--------- 
-------AAAAA------- -----AA-----AA----- ---AA---------AA--- ---A-----------A--- --A-------------A-- -A---------------A- -A---------------A- -A---------------A- -A---------------A- --A-------------A-- --A-------------A-- --A-------------A-- --A-------------A-- --A-------------A-- --A-------------A-- ---A-----------A--- ----CCBA---ABAA---- --------DDD-------- 
------AAAAAAA------ ----AA-------AA---- ---A-----------A--- --A-------------A-- --A-------------A-- -A---------------A- -A---------------A- B-----------------B B-----------------B -A---------------A- -A---------------A- --A-------------A-- --A-------------A-- --A-------------A-- --A-------------A-- ---AA---------AA--- -----AA-----AA----- -------DDDDD------- 
------AAAAAAA------ ----AA-------AA---- ---A-----------A--- --A-------------A-- --A-------------A-- -A---------------A- -A---------------A- B-----------------B B-----------------B B-----------------B -A---------------A- --A-------------A-- --A-------------A-- --A-------------A-- ---A-----------A--- ---AA---------AA--- -----AA-----AA----- -------DDDDD------- 
------AAAAAAA------ ----AA-------AA---- ---A-----------A--- --A-------------A-- --A-------------A-- -A---------------A- -A---------------A- B-----------------B B-----------------B B-----------------B -A---------------A- --A-------------A-- --A-------------A-- ---A-----------A--- ---A-----------A--- ----A---------A---- -----AAAAAAAAA----- ------------------- 
-------AAAAA------- -----AA-----AAA---- ---AA----------A--- --A-------------A-- --A-------------A-- -A---------------A- -A---------------A- -A---------------A- -A---------------A- -A---------------A- -A---------------A- --A-------------A-- ---A-----------A--- ---A-----------A--- ----A---------A---- ----A---------A---- -----AAAAAAAAA----- ------------------- 
--------AAA-------- -----AAA---AAA----- ----A---------A---- ---A-----------A--- --A-------------A-- --A-------------A-- -A---------------A- -A---------------A- -A---------------A- -A---------------A- -AA-------------AA- ---A-----------A--- ---A-----------A--- ----A---------A---- ----A---------A---- -----A-------A----- ------AAAAAAA------ ------------------- 
------------------- ------AAAAAAA------ ----AA-------AA---- ---A-----------A--- ---A-----------A--- --A-------------A-- --A-------------A-- --A-------------A-- --A-------------A-- --A-------------A-- --A-------------A-- ---A-----------A--- ----A---------A---- ----A---------A---- -----A--------A---- -----AAA---AAA----- --------AAA-------- ------------------- 
------------------- -------AAAAA------- -----AA-----AA----- ----A---------A---- ---A-----------A--- ---A-----------A--- --A-------------A-- --A-------------A-- --A-------------A-- --A-------------A-- ---A-----------A--- ---A-----------A--- ----A---------A---- ----A---------A---- -----A-------A----- ------AAAAAAA------ ------------------- ------------------- 
------------------- ------------------- -------AAAAA------- -----AA-----AA----- ----A---------A---- ----A---------A---- ---A-----------A--- ---A-----------A--- ---A-----------A--- ---A-----------A--- ---A-----------A--- ----A---------A---- ----A---------A---- -----A-------A----- ------AAA-AAA------ ---------A--------- ------------------- ------------------- 
------------------- ------------------- ------------------- -------AAAAA------- -----AAAAAAAAA----- -----AA-----AA----- ----AA-------AA---- ----A---------A---- ----A---------A---- ----A---------A---- ----A---------A---- ----AA-------AA---- -----AA-----AA----- ------AAAAAAA------ --------AAA-------- ------------------- ------------------- ------------------- 
------------------- ------------------- ------------------- ------------------- ------------------- -------AAAAA------- ------AAAAAAA------ -----AAAAAAAAA----- -----AAAAAAAAA----- -----AAAAAAAAA----- -----AAAAAAAAA----- ------AAAAAAA------ -------AAAAA------- ------------------- ------------------- ------------------- ------------------- ------------------- 
