model
size = 20 24 26, scale = 0.05, origin = -y
material 
  colors = A:#050 B:#222 C:#111 D:#040 E:#960 F:#777 G:#888 H:#444 I:#630 J:#E00 K:#EEE L:#FF0
voxels
-------------------- -------------------- -------------------- -------------------- -------------------- ---------AA--------- --------AAAA-------- -------AADDAA------- -------A-DD-A------- -------A-DD-A------- -------A-DD-A------- -------A-DD-A------- -------A-DD-A------- --------AAAA-------- -------------------- -------------------- -------------------- -------------------- -------------------- -------------------- -------------------- -------------------- -------------------- -------------------- 
-------------------- -------------------- ----CC--------CC---- ----CC--------CC---- -------------------- --------CAAC-------- --------AAAA-------- -------AADDAA------- --------ADDA-------- -------AADDAA------- --------ADDA-------- ------LAADDAAL------ --------ADDA-------- -------AAAAAA------- --------ADDA-------- -------------------- -------------------- -------------------- -------------------- -------------------- -------------------- -------------------- -------------------- -------------------- 
-------------------- ----CC--------CC---- -----B--------B----- -----B--------B----- ----CC---FF---CC---- --------AAAA-------- -------AAAAAA------- -------AAAAAA------- --------AAAA-------- -------AAAAAA------- ------DAAAAAAD------ -----DDAAAAAADD----- ------AAAAAAAA------ -------AAAAAA------- --------ADDA-------- -------------------- -------------------- -------------------- -------------------- -------------------- -------------------- -------------------- -------------------- -------------------- 
----CC--------CC---- -----B--------B----- -----GF------FG----- -----GFF----FFG----- -----B-FFFFFF-B----- ----CC-FFFFFF-CC---- -------AAAAAA------- -------AAAAAA------- --------AAAA-------- -------AAAAAA------- --------AAAA-------- -------AAAAAA------- --------AAAA-------- -------AAAAAA------- --------ADDA-------- -------------------- -------------------- -------------------- -------------------- -------------------- -------------------- -------------------- -------------------- -------------------- 
----CC--------CC---- -----B--------B----- -----G--------G----- -----G--------G----- -----B--------B----- ----CC--AAAA--CC---- --------AAAA-------- -------AAAAAA------- -------AAAAAA------- -------AAAAAA------- -------AAAAAA------- -------AAAAAA------- -------AAAAAA------- -------AAAAAA------- --------ADDA-------- -------------------- -------------------- -------------------- -------------------- -------------------- -------------------- -------------------- -------------------- -------------------- 
-------------------- ----CC--------CC---- -----B--------B----- -----B--------B----- ----CC--------CC---- ---------AA--------- --------AAAA-------- -------DAAAAD------- --------AAAA-------- -------DAAAAD------- --------AAAA-------- -------DAAAAD------- --------AAAA-------- -------AAAAAA------- --------ADDA-------- ----------B--------- ----------B--------- ----------B--------- ----------B--------- ----------B--------- ----------B--------- ----------B--------- -------------------- -------------------- 
-------------------- -------------------- ----CC--------CC---- ----CC--------CC---- -------------------- -------------------- ---------AA--------- -------DAAAAD------- --------AAAA-------- -------DAAAAD------- --------AAAA-------- -------DAAAAD------- --------AAAA-------- -------AAAAAA------- --------ADDA-------- -------------------- -------------------- -------------------- -------------------- -------------------- -------------------- -------------------- ----------B--------- -------------------- 
-------------------- -------------------- -------------------- -------------------- -------------------- -------------------- ---------AA--------- -------DAAAAD------- --------AAAA-------- -------DAAAAD------- --------AAAA-------- -------DAAAAD------- --------AAAA-------- -------AAAAAA------- --------ADDA-------- -------------------- -------------------- -------------------- -------------------- -------------------- -------------------- -------------------- -------------------- ----------B--------- 
-------------------- -------------------- -------------------- -------------------- -------------------- -------------------- ---------AA--------- -------DAAAAD------- --------AAAA-------- -------DAAAAD------- --------AAAA-------- -------DAAAAD------- --------AAAA-------- -------AAAAAA------- --------ADDA-------- -------------------- -------------------- -------------------- -------------------- -------------------- -------------------- -------------------- -------------------- -------------------- 
-------------------- -------------------- -------------------- -------------------- -------------------- -------------------- ---------AA--------- -------DAAAAD------- --------AAAA-------- -------DAAAAD------- --------AAAA-------- -------DAAAAD------- --------AAAA-------- -------AAAAAA------- --------ADDA-------- -------------------- -------------------- -------------------- -------------------- -------------------- -------------------- -------------------- -------------------- -------------------- 
-------------------- -------------------- -------------------- -------------------- -------------------- -------------------- ---------AA--------- -------DAAAAD------- --------AAAA-------- -------DAAAAD------- --------AAAA-------- -------DAAAAD------- --------AAAA-------- -------AAAAAA------- --------ADDA-------- -------------------- -------------------- -------------------- -------------------- -------------------- -------------------- -------------------- -------------------- -------------------- 
-------------------- -------------------- -------------------- -------------------- -------------------- -------------------- ---------AA--------- -------DAAAAD------- --------AAAA-------- -------DAAAAD------- --------AAAA-------- -------DAAAAD------- --------AAAA-------- -------AAAAAA------- --------ADDA-------- -------------------- -------------------- -------------------- -------------------- -------------------- -------------------- -------------------- -------------------- -------------------- 
-------------------- -------------------- -------------------- -------------------- -------------------- -------------------- ---------AA--------- -------DAAAAD------- --------AAAA-------- -------DAAAAD------- --------AAAA-------- -------DAAAAD------- --------AAAA-------- -------AAAAAA------- --------ADDA-------- -------------------- -------------------- -------------------- -------------------- -------------------- -------------------- -------------------- -------------------- -------------------- 
-------------------- -------------------- -------------------- -------------------- -------------------- -------------------- ---------AA--------- -------DAAAAD------- --------AAAA-------- -------DAAAAD------- --------AAAA-------- -------DAAAAD------- --------AAAA-------- -------AAAAAA------- --------ADDA-------- -------------------- -------------------- -------------------- -------------------- -------------------- -------------------- -------------------- -------------------- -------------------- 
-------------------- -------------------- -------------------- -------------------- -------------------- -------------------- ---------AA--------- -------DAAAAD------- --------AAAA-------- -------DAAAAD------- --------AAAA-------- -------DAAAAD------- --------AAAA-------- -------AAAAAA------- --------ADDA-------- -------------------- -------------------- -------------------- -------------------- -------------------- -------------------- -------------------- -------------------- -------------------- 
-------------------- -------------------- -------------------- -------------------- -------------------- -------------------- --------AAAA-------- -------AAAAAA------- -------AAAAAA------- -------AAAAAA------- -------AAAAAA------- -------AAAAAA------- -------BAAAAB------- --------BKKB-------- -------------------- -------------------- -------------------- -------------------- -------------------- -------------------- -------------------- -------------------- -------------------- -------------------- 
-------------------- -------------------- -------------------- CCCCCC--------CCCCCC CCCCCC--------CCCCCC CCCCCC---AA---CCCCCC CCCCCC--AAAA--CCCCCC -------AAAAAA------- -------AAAAAA------- -------AAAAAA------- -------AAAAAA------- -------B-CC-B------- -------B-CC-B------- -------------------- -------------------- -------------------- -------------------- -------------------- -------------------- -------------------- -------------------- -------------------- -------------------- -------------------- 
-------------------- -------------------- CCCCCC--------CCCCCC -BBBBB--------BBBBB- -BBBBB--------BBBBB- -BBBBB-AAAAAA-BBBBB- -BBBBB-AAAAAA-BBBBB- CCCCCC-AAAAAA-CCCCCC -------B-HH-B------- -------B----B------- -------B----B------- -------B----B------- -------------------- ---------CC--------- -------------------- -------------------- -------------------- -------------------- -------------------- -------------------- -------------------- -------------------- -------------------- -------------------- 
-------------------- CCCCCC--------CCCCCC -BBBBB--------BCCCB- -BBBBB--------BBBBB- -BBBBB--------BBBBB- -BBBBB-AAAAAA-BBBBB- -BBBBB-AAAAAA-BBBBB- -BBBBB-AAAAAA-BCCCB- CCCCCC--------CCCCCC -------------------- -------------------- ---------II--------- --------I--I-------- --------I--I-------- ---------II--------- -------------------- -------------------- -------------------- -------------------- -------------------- -------------------- -------------------- -------------------- -------------------- 
CCCCCC--------CCCCCC -BBBBB--------BBBBB- -BBBBB--------BBBBB- --HBBB--------BBBH-- -BBBBB--------BBBBB- -BBBBB-AAAAAA-BBBBB- --HBBB-AAAAAA-BBBH-- -BBBBB-AAAAAA-BBBBB- -BBBBB--------BBBBB- CCCCCC--------CCCCCC -------------------- -------------------- -------------------- -------------------- -------------------- -------------------- -------------------- -------------------- -------------------- -------------------- -------------------- -------------------- -------------------- -------------------- 
CCCCCC--------CCCCCC -BBBBB--------BBBBB- -BBBBB--------BBBBB- -BBBBB--------BBBBB- GGBBBBFFFFFFFFBBBBBG GGBBBBFAAAAAAFBBBBBG -BBBBB-AAAAAA-BBBBB- -BBBBB-AAAAAA-BBBBB- -BBBBB-AAAAAA-BBBBB- CCCCCC-EEEEEE-CCCCCC -------E----E------- -------E----E------- -------------------- -------------------- -------------------- -------------------- -------------------- -------------------- -------------------- -------------------- -------------------- -------------------- -------------------- -------------------- 
CCCCCC--------CCCCCC -BBBBB--------BBBBB- -BBBBB--------BBBBB- -BBBBB--------BBBBB- GGBBBBFFFFFFFFBBBBBG GGBBBBFAAAAAAFBBBBBG -BBBBB-AAAAAA-BBBBB- -BBBBB-AAAAAA-BBBBB- -BBBBB-AAAAAA-BBBBB- CCCCCC-EEEEEE-CCCCCC -------E----E------- -------E----E------- -------------------- -------------------- -------------------- -------------------- -------------------- -------------------- -------------------- -------------------- -------------------- -------------------- -------------------- -------------------- 
CCCCCC--------CCCCCC -BBBBB--------BBBBB- -BBBBB--------BBBBB- --HBBB--------BBBH-- -BBBBB--------BBBBB- -BBBBB-AAAAAA-BBBBB- --HBBB-AAAAAA-BBBH-- -BBBBB-AAAAAA-BBBBB- -BBBBB-AAAAAA-BBBBB- CCCCCC-EEEEEE-CCCCCC -------E----E------- -------E----E------- -------------------- -------------------- -------------------- -------------------- -------------------- -------------------- -------------------- -------------------- -------------------- -------------------- -------------------- -------------------- 
-------------------- CCCCCC--------CCCCCC -BCCCB--------BCCCB- -BBBBB--------BBBBB- -BBBBB--------BBBBB- -BBBBB-CAAAAC-BBBBB- -BBBBB-AAAAAA-BBBBB- -BCCCB-AAAAAA-BCCCB- CCCCCC-AAAAAA-CCCCCC -------EAAAAE------- -------EEEEEE------- -------EEEEEE------- --------EEEE-------- --------EEEE-------- -------------------- -------------------- -------------------- -------------------- -------------------- -------------------- -------------------- -------------------- -------------------- -------------------- 
-------------------- -------------------- CCCCCC--------CCCCCC -BBBBB--------BBBBB- -BBBBB--------BBBBB- -BBBBB--AAAA--BBBBB- -BBBBB-AAAAAA-BBBBB- CCCCCC-AAAAAA-CCCCCC -------AAAAAA------- -------AAAAAA------- -------AJAAJA------- -------AAAAAA------- --------AAAA-------- -------------------- -------------------- -------------------- -------------------- -------------------- -------------------- -------------------- -------------------- -------------------- -------------------- -------------------- 
-------------------- -------------------- -------------------- CCCCCC--------CCCCCC CCCCCC--------CCCCCC CCCCCC--AAAA--CCCCCC CCCCCC-AADDAA-CCCCCC -------A-DD-A------- -------A-DD-A------- -------A-DD-A------- -------AJDDJA------- -------AADDAA------- ---------AA--------- -------------------- -------------------- -------------------- -------------------- -------------------- -------------------- -------------------- -------------------- -------------------- -------------------- -------------------- 
