model
size = 21 32 29, scale = 0.05, origin = -y
material 
  colors = A:#555 B:#EEE C:#777 D:#BBB E:#444 F:#AAA G:#500 H:#666 I:#222 J:#111
voxels
320-2B7-2B10-2B7-2B615-2(7B5-7B2-)9B2-8B2-2B-6B2-5B-2(2B2-)3B5-3B2-2B6-2B7-2B467-2B17-BD3B15-2BD4B13-3B2(D8B5-7B)D2B-2B2-3B2(2-2B)-BD5B2-3B2-2B2-4BD6B-3B2-2B-5BD10B2-8BD8B5-7BD4-3B7-3B382-D4(2B15-2B2D)3B13-3B2D-3B11-3B-2D2-5B5-5B2-2D6-3B2-2B6-2D6-7B6-2(2D8-4B7-)2D2-2B2-3B2(2-2B)2-2D4B-2B5-2B-4B2D7B5-7BD3-4B7-4B340-2A15-2A-D2A15-3AD-A15-A2(-AD-2A13-2A)-AD-3A11-3A-AD2-2A11-2A2-AD3-4A5-4A3-AD6-3A2-2A6-AD8-A2BA7-AD9-2B8-AD8-A2BA7-2(AD6-3A2-2A6-)AD3A2-2A5-2A2-4A2(D6A7-7A)2-4A9-4A4-4A9-4A5-3A9-3A46-3(3A13-3A2-)2A15-2A128-3A13-3A-3(D3A13-4A)2(D2-2A11-2A2-A)D3-4A5-4A3-AD3-6A2-5A3-AD6-3A2B2A6-AD8-A2BA7-AD9-2B8-AD8-A2BA7-AD8-A2HA7-AD6-3A2-2A6-2(AD2(5-2A)5-)A2(D2A2-2A7-2A2-3A)D3A-2A7-2A-4A2(D5A9-6A)D4A11-5A-4A11-4A2-A-2A11-2A-A2-3A13-3A2-2A15-2A128-3A13-3A2(2-A-A13-A-A)-DA-2A11-2A-2AD2-2A11-2A2-AD3-A11-A3-AD3-4A5-4A3-AD6-3A2-2A6-AD8-A2BA7-AD9-2B8-AD19-AD9-2B8-AD8-A2HA7-AD6-3A2-2A6-AD6-A5-A6-AD2(5-2A)5-3(AD4-2A7-2A4-)2(AD3-2A9-2A3-)ADA2-A11-A2-2ADA-2A11-2(2A-)A-2A11-2A-A2-3A13-3A2-2A15-2A108-2A13-2A3-3A13-3A2-4A11-4A2-A-2A11-2A-A-DA-2A11-2A-2ADA2-A11-A2-2AD3-2A9-2A3-AD3-4A5-4A3-AD6-3A2-2A6-AD8-A2BA7-AD9-2B8-AD19-AD9-2B8-AD8-A2HA7-AD6-3A2-2A6-2(AD2(5-2A)5-)AD3-3A7-3A3-AD3-2A9-2A3-2(AD2-3A9-3A2-)AD2-2A11-2A2-AD-3A11-3A-AD4A11-5A-3A13-3A2-3A13-3A129-2A13-2A4-2A13-2A3-4A11-4A2(2-A)11-3(A2-)A11-A2-A-DA2-A11-A2-2AD3-2A9-2A3-AD4-3A5-3A4-AD6-3A2-2A6-AD8-A2BA7-2(AD19-)AD9-2B8-AD8-A2HA7-AD6-3A2-2A6-AD2(5-2A)5-AD5-A7-A5-AD3-3A7-3A3-AD3-A11-A3-AD2-2A11-2A2(2-AD2-A13-A)2-AD-2A13-2A-AD2A15-3A-2A15-2A88-2A11-2A6-2A11-2A5-2(3A11-3A4-)3A11-3A3-4A11-4A2(2-A)11-3(A2-)A11-A2-A-2(DA2-2A9-2A2-2A)DA3-3A5-3A3-2AD6-3A2-2A6-AD8-A2BA7-2(AD19-)AD9-2B8-AD8-A2HA7-AD6-3A2-2A6-AD2(5-2A)5-ADA3-2A7-2A3-2AD6A7-7A2(D4A11-5A)3(D3A13-4A)D2A15-3A-2A15-2A68-2(3A7-)4A7-4A6-3A9-3A5-4A9-4A4-3A11-3A4-A-A11-A-A3-2(2A-A11-A-2A2-)2(2A-2A9-2A-2A2-)A3-2A7-2A3-A-DA3-3A5-3A3-2ADA5-3A2B2A5-2AD8-A2BA7-2(AD19-)AD9-2B8-AD8-A2HA7-AD6-3A2-2A6-ADA4-2A5-3A3-2AD6A7-7A-5A9-5A196-2A5-2A10-4A5-4A7-5A5-5A6-A-2A7-2A-A6-3A9-3A5-2(4A9-4A4-)2(A-2A9-2A-A4-)A-2A9-2A-A3-2A2-A9-A3(2-2A)7-2(2A2-)2A3-4A2-3A3-2A-DA5-3A2B2A5-2ADA8-2B7-2A3(D19-A)D8-A2HA7-ADA4-4A2-3A4-2AD7A5-8A-6A8-5A217-4A2B3A10-6A2B5A7-2A-4A2-3A-2A6-5A5-5A6-A-2A7-2A-A6-A-A9-A-A5-2(2A-A9-A-2A4-)3(A2-A9-A2-A4-)A2-2A7-2A2-A3-2A3-4A2-3A3-2A2-2A6-A2BA5-2A-DA8-2B7-2ADA17-2A2(D19-A)DA7-A2HA6-2AD2A3-4A2-3A3-3A-6A7-6A238-9B10-3B2-4B-3B8-C2-7B2-C7-FC-2B5-2B-2C2(6-F-CB7-2B-C)6-F-C9-B-C5-3(IF-C9-B-CF4-)2(IF-CB7-2B-CF4-)IF2-4B2-3B2-CF3-BI6-4B5-FI2-BI7-2B6-BI-DB17-I2(2DB17-B)2D2B6-B2HB5-2BD-B8D2-8D3-5H7-5H239-9B10-4B5-4B8-2C-7B-BC7-FC-4B2-3B-2C6-FC-2B5-2B-2C3(6-F-CB7-2B-C)6-F-C9-B2(-C6-F-CB7-2B)-C6-F2-2B5-2B2-C5-IF2-4B2-3B2-CF4-IF5-4B4-BF3-BIF13-2BI2-BI15-BI2-2B15-BG2-2B15-2B2-9B2H8B3-8D2-7D261-7B12-5B2-4B9-2C3-4B2-BC8-C2-7B2-C7-FC-4B2-3B-2C6-FC-2B5-2B-2C6-FC-B7-B-2C3(6-F-CB7-2B-C)6-F2-B7-B2-C6-F2-2B5-2B2-C6-F3-3B2-2B3-C6-F5-4C4-B5-IF13-2G4-IB13-2G4-B15-G4-2BG11-BGB4-2BG12CGB284-4B13-11B9-2CB7-2BC8-2C3-4B2-BC8-C2-7B2-C8-C-2B5-2B-C7-FC-2B5-2B4(-2C6-FC-B7-B)-2C6-FC-2B5-2B-2C6-FC2-3B2-2B2-2C6-FG4-4C3-BG6-FG11-BG5-IB13-2G4-GB13-2G4-2BG2B3-2C2-C2B2G6-G12C304-9B11-CB7-2B9-2C9-BC8-C2-7B2-C8-C2-3B2-2B2-2(C8-C-2B5-2B-)2(C8-C-B7-B-)C8-C-B6-2B-C8-C-2B5-2B-C8-C2-3B2-2B2-C8-C4-4C3-G7-FG2(11-BG6-2G)B9-2BG6-2G2E8C2EG9-E8C306-9B11-E2B5-3B9-2EB7-3B8-2E3-4B2-BC8-CE-7B-BC8-C2-3B2-2B2-4(C8-C-2B5-2B-)C8-2C2B5-B-BC8-2C-3B2-2B-BC8-2C3-4C2-2(BC8-GC9-)BC8-GCB7-CBC9-2E8CE327-7B13-9B11-EB7-BE10-2(E9-)CE3-4B2-2E8-CE-7B-2E8-CE-3B2-2B4(-2E8-CE-B5-B)-2E9-E-7B-E10-E3-4C2-E10-E9-E10-2E7-CE10-2E8CE11-E8C348-9B11-E2C5-B2C10-EC7-2C10-E4-2B3-C10-E3-4B2-C10-E-C2B2-2B3(-E10-E-C5-B)-E10-E-C2B2-2B-E10-2EC6BCE10-2E3-2C2-CE10-2E7-CE10-2EC5-2CE11-E8C370-3B2F2B13-2C6BC11-E2C5-B2C10-EC7-2C10-E3-4B2-C10-E-C6B3(-E10-E-C2B2-2B)-E10-2EC2B2-2BCE10-2E2-4B-CE11-2(E7-C12-)E8C13-7C392-C6B13-2C2B2-2BC11-2(EC7-2C10-)3(2E2-4B-CE10-)2E2(2-B)-CE10-2E2-4B-CE11-E2-4B-C12-E7-C12-E3C2-3C12-E8C414-4B14-2C2B2-2B2(C12-C7-)2(C12-C3-2B2-)C12-C2-4B-C12-C2(2-B)-C12-C2-4B-C12-C3-2B2-C12-B7-C12-B3C2-3C15-4C416-4B14-2C6BC12-2C5-BC12-C7-2(C12-C3-2B2-)C12-C2-4B-2(C12-2C-5B)C12-2C2-2B-BC12-FC5-2C12-F8C15-4C417-2F16-7F13-3F4B2F12-FC2B2-2B2(C12-FC5-B)2(C12-FC2-2B-B)C13-B2-2B-C14-BCB2-BC14-2D4BD14-7D478-4D15-7D5(14-2D4BD)14-7D16-4D542-4D3(17-D2BD)17-4D606-2(2J19-)2J18-4J428-
