model
size = 18 6 5, scale = 0.05, origin = -y
material 
  colors = A:#E00 B:#DDD C:#100 D:#FFF E:#D00 F:#555
voxels
----------C------- ----------C------- ----------C------- ----------C------- ----------C------- ----------C------- 
----------C------- ------------------ ------------------ ------------------ ------------------ ----------C------- 
---------AAAAAAAAA ---------AAAFFA--A --------FAAAFFA--A ----------AAAAA-AA ----------CAAAAAA- ----------C------- 
---------AAAAAAAAA ---------AAAAAA--A ---------AAAAAA--A ----------AAAAA-AA -----------AAAAAA- ------------------ 
--D-D-D-D-EEEEE--- DBBBBBBBBBAAAAA--- -BBBBBBBBBAAAAA--- -D-D-D-D---------- ------------------ ------------------ 
