model
size = 12 23 11, scale = 0.05, origin = -y
material 
  colors = A:#C6C B:#111 C:#E00 D:#90C E:#0C0 F:#06F G:#C3F H:#888
voxels
AAAAAAAAAAA- AAAAAAAAAAA- AAAAAAAAAAA- AAAAAAAAAAA- AAAAAAAAAAA- AAAAAAAAAAA- AAAAAAAAAAA- AAAAAAAAAAA- AAAAAAAAAAA- AAAAAAAAAAA- AAAAAAAAAAA- AA---------- AA---------- AA---------- AA---------- AA---------- AA---------- AA---------- AA---------- AA---------- AA---------- AA---------- AA---------- 
AAAAAAAAAAA- AAAAAAAAAAA- AAAAAAAAAAA- AAAAAAAAAAA- AAAAAAAAAAA- AAAAAAAAAAA- AAAAAAAAAAA- AAAAAAAAAAA- AAAAAAAAAAA- AAAAAAAAAAA- AAAAAAAAAAA- AB-----EEE-- AB---------- AB---------- AB---------- AB---------- AB---------- AB---------- AB---------- AD---------- AD---------- AA---------- AA---------- 
AAAAAAAAAAA- AAAAAAAAAAA- AAAAAAAAAAA- AAAAAAAAAAA- AAAAAAAAAAA- AAAAAAAAAAA- AAAAAAAAAAA- AAAAAAAAAAA- AAAAAAAAAAA- AAAAAAAAAAA- AAAAAAAAAAA- AB-----EEE-- AB------E--- AB---------- AB---------- AB---------- AB---------- AD---------- AD---------- AB---------- AB---------- AA---------- AA---------- 
AAAAAAAAAAA- AAAAAAAAAAA- AAAAAAAAAAA- AAAAAAAAAAA- AAAAAAAAAAA- AAAAAAAAAAA- AAAAAAAAAAA- AAAAAAAAAAA- AAAAAAAAAAA- AAAAAAAAAAA- AAAAAAAAAAA- AB-----EEE-- AB---------- AB---------- AB---------- AB---------- AB---------- AG---------- AG---------- AD---------- AD---------- AA---------- AA---------- 
AAAAAAAAAAA- AAAAAAAAAAA- AAAAAAAAAAA- AAAAAAAAAAA- AAAAAAAAAAA- AAAAAAAAAAA- AAAAAAAAAAA- AAAAAAAAAAA- AAAAAAAAAAA- AAAAAAAAAAA- AAAAAAAAAAA- AB---------- AB---------- AB---------- AB---------- AB---------- AB---------- AG---------- AB---------- AB---------- AB---------- AA---------- AA---------- 
AAAAAAAAAAA- AAAAAAAAAAA- AAAAAAAAAAA- AAAAAAAAAAA- AAAAAAAAAAA- AAAAAAAAAAA- AAAAAAAAAAA- AAAAAAAAAAA- AAAAAAAAAAA- AAAAAAAAAAA- AAAAAAAAAAA- AB-----FFF-- AB---------- AB---------- AB---------- AB---------- AB---------- AG---------- AG---------- AB---------- AB---------- AA---------- AA---------- 
AAAAAAAAAAA- AAAAAAAAAAA- AAAAAAAAAAA- AAAAAAAAAAA- AAAAAAAAAAA- AAAAAAAAAAA- AAAAAAAAAAA- AAAAAAAAAAA- AAAAAAAAAAA- AAAAAAAAAAA- AAAAAAAAAAA- AB-----FFF-- AB------F--- AB---------- AB---------- AB---------- AB---------- AD---------- AD---------- AD---------- AD---------- AA---------- AA---------- 
AAAAAAAAAAA- AAAAAAAAAAA- AAAAAAAAAAAH AAAAAAAAAAAH AAAAAAAAAAA- AAAAAAAAAAAC AAAAAAAAAAAC AAAAAAAAAAA- AAAAAAAAAAA- AAAAAAAAAAA- AAAAAAAAAAA- AB-----FFF-- AB---------- AB---------- AB---------- AB---------- AB---------- AB---------- AD---------- AB---------- AD---------- AA---------- AA---------- 
AAAAAAAAAAA- AAAAAAAAAAA- AAAAAAAAAAAH AAAAAAAAAA-- AAAAAAAAAAA- AAAAAAAAAAA- AAAAAAAAAAA- AAAAAAAAAAA- AAAAAAAAAAA- AAAAAAAAAAA- AAAAAAAAAAA- AB---------- AB---------- AB------C--- AB-----CCC-- AB------C--- AB---------- AD---------- AB---------- AD---------- AB---------- AA---------- AA---------- 
AAAAAAAAAAA- AAAAAAAAAAA- AAAAAAAAAAAH AAAAAAAAAAAH AAAAAAAAAAA- AAAAAAAAAA-- AAAAAAAAAA-- AAAAAAAAAAA- AAAAAAAAAAA- AAAAAAAAAAA- AAAAAAAAAAA- AB------B--- AB------B--- AB-----CBC-- AB-----CCC-- AB-----CCC-- AB---------- AG---------- AG---------- AB---------- AG---------- AA---------- AA---------- 
AAAAAAAAAAA- AAAAAAAAAAA- AAAAAAAAAAA- AAAAAAAAAAA- AAAAAAAAAAA- AAAAAAAAAAA- AAAAAAAAAAA- AAAAAAAAAAA- AAAAAAAAAAA- AAAAAAAAAAA- AAAAAAAAAAA- AA---------- AA---------- AA------C--- AA-----CCC-- AA------C--- AA---------- AA---------- AA---------- AA---------- AA---------- AA---------- AA---------- 
