model
size = 16 31 31, scale = 0.05, origin = -y
material 
  colors = A:#00E B:#00B C:#EEE
voxels
---------------- ---------------- ---------------- ---------------- ---------------- ---------------- ---------------- ---------------- ---------------- ---------------- ---------------- ---------------- ---------------- ---------------- ---------------- ---------------- ---------------- ---------------- -------AAAAA---- ------AAAABA---- ------AAAAAA---- -------AAAA----- ---------------- ---------------- ---------------- ---------------- ---------------- ---------------- ---------------- ---------------- ---------------- 
---------------- ---------------- ---------------- ---------------- ---------------- ---------------- ---------------- ---------------- ---------------- ---------------- ---------------- ---------------- ---------------- ---------------- ---------------- ---------------- ---------------- ---------AAAB--- ------AAAAAAA--- ------AAAAAAA--- ------AAAAAAA--- ------AAAAAAA--- ------AAAAAAA--- ------AAAAAAA--- ------AAAAAA---- ---------------- ---------------- ---------------- ---------------- ---------------- ---------------- 
---------------- ---------------- ---------------- ---------------- ---------------- ---------------- ---------------- ---------------- ---------------- ---------------- ---------------- ---------------- ---------------- ---------------- ---------------- ---------------- ---------------- --------AAAAAA-- -----AAAAAAAAA-- -----AAAAAABAA-- -----AAAAAAAAA-- -----ABAAABAAA-- -----AAAAAAAAA-- -----AAAAAAAAB-- -----AABAAABAA-- -----ABAAAAAA--- ------AAAAABA--- ---------------- ---------------- ---------------- ---------------- 
---------------- ---------------- ---------------- ---------------- ---------------- ---------------- ---------------- ---------------- ---------------- ---------------- ---------------- ---------------- ---------------- ---------------- ---------------- ---------------- ---------------- ------AAAAAAA--- -----AAAAAAAAA-- -----AAAAAAAAAA- -----AAAAAAAAAA- -----AAAAAAAAAA- -----AAAAAAAAAA- -----AAAAAAAAAA- -----AAAAAAAAA-- -----AAAAAAAAA-- -----AAAAAAAA--- ------AAAAAAA--- ---------------- ---------------- ---------------- 
---------------- ---------------- ---------------- ---------------- ---------------- ---------------- ---------------- ---------------- ---------------- ---------------- ---------------- ---------------- ---------------- ---------------- ---------------- ---------------- ---------------- -----AAAA-AAA--- -----AAAAAAAAA-- ----AAAAAAAAAAA- ----AAAAAAAAAAA- ----AAAAABAAAAA- ----AAAAAAAAAAA- -----AAAAAAAAAA- -----AAAAAAAAAA- -----AAAAAAAAAA- -----AAAAAAAAA-- -----AAAAAAAA--- -------AAAAA---- ---------------- ---------------- 
----AAAAAAA----- -----AAAAAA----- -----AAAAA------ -----AAAAAA----- -----AAABAA----- -----AAAAAA----- ------AAAAA----- ------AAAAA----- -------AAAA----- ---------------- ---------------- ---------------- ---------------- ------AAAAAAA--- -----AAAAAAAAAA- -----AAAAAAAAAA- -----AAAAAAAAAA- -----AAABAAABAA- ----AAAAAAAAAAA- ---AAAAAAAAAAAA- ---AAAAAAAAAAAA- ---AABAAA-AAAAA- ---AAAAAA-AAABA- ---AAAAAAAAAAAA- ----BAAAAAAAAAA- ----AAAAAAAAAAA- ----BAAAAAAAAAA- -----AAAABAAAA-- ------BAAAAAA--- ---------------- ---------------- 
---AAAABAAAAA--- ---AAAAAAAAAA--- ---AAAAAAAAA---- ---AAAAAAAAAA--- ---AAAAAABBAA--- ---AAAAAAAAAA--- ----AAAAAAAAA--- ----AAAAAAAAA--- ----AAAAAAAAAAA- ----AAAAAAAAAAA- ----AAABAAAAAAA- -----AAAAAAAAAA- ----AAAAAAAAAAA- ----AABAAAAAAAA- ----AAAAAAAAAAA- ---AAAAAAABAAAA- ---AAAAAAAAAAAA- --AAAAAAAAAAAAA- ---AAAAAABAAAAAA --AAAAAAAAAAABAA --AAAAAAAAAAAAAA --AAAAAA--AAAAAA --AAABAA---AAAAA ---AAAAAA-AAAAAB ---AAAAAABAAAAAA ----BAABAAAAAAA- ----AAAAAAAAAAA- -----AAAAABAAA-- ------AAAAAAA--- --------AAA----- ---------------- 
---AAAAAAAAAAAA- --ABAAAAAAAAAAA- --AAAAAAAAAAA--- --AAAAAAAAAAAAA- --AABAAAABAAAAA- --AAAAAAAAAAAAA- --AAAAAAAAAAAAA- ---ABAAAAAAAAAA- ---AABAAAAAAAAA- ---AAAAAAAAAAAA- ---AAAAAAAAAAAA- --BAAAAAAAAAAAA- ---AAAAAAAAAAAA- --AAAAAAAAAAAAB- --AAAAAAAAAAAAA- --AAAAAAAAAAAAAA -AAAAAAAAAAAAAAA -AAABAAAAAAAAAAA AAAAAAAAAAAAAAAA -AAAAAABAAAAAAAA -ABAAAAAAAAAAAAA -AAAAAAA--AAAAAA -AAAAAAA---AAAAA --AAAAAA---AAAAA --AAAAAAA-AAAAAA ---AAAAAAAAABAAA ----AAAAAAABAAA- ----AAAAAAABAA-- ------AAAAAAAA-- -------AAAAB---- ---------------- 
--AAAAAAAAAAAAA- -AAAAABAAAAAAAA- -AAAAAAAAAAAAAA- -AAAAAAAAAAAAAA- -AAAAAAAAAAAAAA- -AAAAAAAAAAAAAA- --AAAAAAAABAAAA- --AAAAAAAAAAAAA- --AAAAAAAAAAAAA- --AAAAAAAAAAAAB- -AAAAAAAAAAAAAA- -AAAAAAAAAAAAAA- AAAAAAAAAAAAAAB- CAABAAAAAAAAAAAA CAAAAAAAAAAAAAAA CBAAAAAAAAAAAAAA CAAAAAAAAAABAAAA CAAAAABAAAAAAAAA CAAAAAAABAAAAAAA CAAAAAAAAAAAAAAA AAAAAAAAAAAAAAAA AAAAAAAA---AAAAA -AAAAAAA----AAAA -AAAAAAA---AAAAA --AAAAAAA-AAAAAA ---BAAAAAAAAAAAA ---AAAAAAAAAAAA- ----AAAAAAABAA-- -----AAAAAAAAA-- -------AAAAAA--- ---------------- 
-AABAAA-AAAAAAAA AAAAAAA-ABAAAAA- AAAAAAA-AAAAAAA- AAAAAAAAAAAAAAA- AAAAAAAAAAAAAAAA -AAAAAAAAAABAAA- -AAAAAAAAAAAAAAA -AAAAAAAAAAAAAAA -AAAAAAAAAAAAABA -AAAAAAAAAAAAAAA AAAAABAAAAAAAAAA AAAABAAAAAAAAAAA CAAAAAAAAAAAAAAA AAAAAAAAAABAAAAA AAAAAAAAAAAAAAAA AAAAABAAA-AAAAAA AAAAAAAA--AAAAAA AAAAAAAA---BABAA AAAAAAA----AAAAB AAAAAABA---AAABA CAABAAAA---AAAAA AAAAAAAAAA-AABAA AAAAAAAAAA-AAAAA -AAAAAAA---AAAAA --AABAAA---AAAAA --AAAAAAA-AAAAAA ---AAAAAAAAAAA-- ----AAAAAAAAAA-- -----AAAAAAAAA-- ------AAAAAAA--- -------AAAAA---- 
AAAAA-A--AAAAAAA AAAAA-A-ABAAAAAA AAAAA-A-AAAAAAB- AAAAA-A-AAAAAAAA AAAAA-AAAAAAAABA AAAAAAAAAAAAAAA- AAAAAAAAAAAAAAA- AAAAAAAAAAAAAAAA AAAAAAAAAAAAAAAA AAAAAAAAAAAAAAAA AAAAAAAAAAAABAAA AAAAAAAAAAAAAAAA CAAAAAAAAAAAAAAA CAAAAAAAAAAAAABA CAAAABAAAAAAAAAA CAABAAAAA-AAAAAA CAAAAAAA--AAABAA CAAAAAAA---AAAAA CAAAAAA----AAAAA CAAAAABA----AABA CAAAAABB----AAAA AAAAAAAAAA--AAAA AAAAAAAAAA--ABAA AAAAAAAA---AAAAA -BAAAAAA---AAAAA --AAAAAAA-AAAAAA --AAAAAAABAAAAA- ---AABAAAAAAAAA- ----AAAAAAAAAA-- -----AAAAAAAA--- -------AAAAA---- 
AAAAAA----AAAAAA AAAAAA----AAAAAA AAAAAA---AAAAAAA AAAABA---AABAAAA AAAAAB---AAAAAA- AAAAAA---AAAAAA- AAAAAAA--AAAAABA AAAAAAA--AAAAAAA AAAAAAA--AAAAAAA AAAAAAA--AAAAAAA AAAAAAA--AAAAAAA AAAAAA----AAAAAA AAAAAA-----BAAAA AAAAAA-----AAAAA AAAABA-----AAAAA AAAAAA------AAAA AAAAAA------AAAA AAAAAA------AAAA AAABA-------AAAA AAAAA-------AAAA AAAAA--------AAA AAAAAA-------AAA AAAAAA------AAAA AAAAAAA-----AAAA -AAAAAAA---AAAAA --AAAAAAA-AAAAAA --AAAAAAAAAAAAA- ---BAAAAAAAAAAA- ----AAAAAAAAAA-- ----------AAA--- -----------AA--- 
AAAAA------AAAAA BABAA-----ABAAAA AAAAA-----AAAAAA AAAAA-----AAABAA AAAAA-----AABAA- AAAAA-----AAAAA- AAAAAA----AAAAAA ABAAAA----AAAAAA AAAAAA----AAAABA AAAAAA----AAAAAA AAAAA-----AAAAAA AABAA------AAAAA AAAA-------AAAAA CAAAA-------AAAA CAAAB-------AAAA CAAAA-------AAAA CAAAA-------AAAA CAAAA--------AAA CAAA---------AAA CAAA---------AAA AABAA--------AAA AAAAA--------AAA AAAAAA------AAAA AAAAAAA-----AAAA -AAAAAAA---AAAAA --AAAAAAA-BAAAAA --AABAAAAAAAAAA- ---AAAAAAAAAAAA- ----AAAAAAABAA-- -----------AAA-- ------------A--- 
AAAAA------AAAAA AAAAA------AAAAA AAAAA-----AAAAAA AAAAA-----AAAAAA AAAAA-----AAAAA- AAAAA-----AAABAA AAAAA-----AAAAAA AAAAA------AAAAA AAAAA-------AAAB AAAAB-------AAAA AAAB--------AAAA AAAA--------AAAA CAAA--------AAAA AAAA--------AAAA AAAA---------AAA AAAA---------AAA AAAB---------AAA AABA---------AAA AABA---------AAA AAAA---------AAA CAAA---------AAA AAAAA--------AAA AABAAA------ABAA AAAAAA------AAAA -AAAAAA----BAAAA --AAAAAA---AAAAA --AAAAAAAAAAAAA- ---AAAAAAAAAAAA- ----AAAAAAABAA-- -----------AAA-- ------------A--- 
AABA-------AABAA AAAA-------AAAAA AAAA------AAAAAA AAAA------AAAAAA AAAA------AAAAA- AAAA------BAAAAA AAAA------AAABAA AAAA-------AAAAA AAAA--------AAAA AABA--------AAAA AAA----------AAA AAA----------AAA AAB----------AAA CAA----------AAA CAA----------AAA CAA----------AAA CAA----------AAA CAA----------AAA CAA----------AAA CAAA---------AAA AAAA---------AAA AAAAA-------AAAA AAAAA-------AAAA AAAAAA------AAAA -AAAAAA----AAAAA --AAAAAA---AAAAA --AAAAAAA-AAAAA- ---AAAAAAAAAAAA- ----AAA---AAAA-- -----------AAA-- ------------A--- 
ABAA-------AAAAA AAAA-------AAAAA AAAA------BAAAAA AAAA------AAAAA- AAAA------AAAAA- ABAA------AAAAAA AAAA-------AAAAA AAAB--------AAAA AAAA--------AAAA AAAA--------AAAA AAA----------AAA AAA----------AAA AAA----------AAA AAA----------AAA AAA----------AAA AAA----------AAA AAA----------AAA AAA----------AAA AAA----------AAA AAAA---------AAA AAAA---------AAA AAAAA-------AAAA AAAAA-------AAAB AAAAAA------AAAA -AAABA-----AAAAA --AAAAAA---AAAAA --AAAAAA--AAAAA- ---AAAAA--AAAAA- ----AAA---AAAA-- -----------AAA-- ------------A--- 
AAAA-------AAAAA AAAA-------AAAAA AAAA-------AAAAA AAAA-------AAAA- AAAA-------AAAA- AAAA-------AAAAA AAAA-------BAAAA AAAA--------AAAA AAAA--------AAAA AAAA--------AAAA AAAA---------AAA AAAA---------AAA AAAA---------AAA CABA---------AAA CAAB---------AAA CAAA---------BAA AAA----------ABA AAA----------AAA AAA----------AAA CAAA---------AAA AAAA---------AAA AAAAA-------AABA AAAAA-------AAAA AAAAAA------AAAA -AAAAA-----AAAAA --AAAAAA---AAAAA --AAAAAA--AAAAA- ---AAAAA--AAAAA- ----AAA---AAAA-- -----------AAA-- ------------A--- 
AAAA-------AAAAA AAAA-------AAAAA AAAA-------AAAAA AAAA-------AAAA- AAAA-------AABA- AAAA-------AAAAA AAAA-------AAAAA AAAA--------ABAA AAAA--------AAAA AAAA--------AAAA AAAA--------AAAA AAAA--------AAAA CAAA--------AAAA AAAA--------BAAA AAAA--------ABAA AAAA--------AAAA CAA---------AAAA AAA----------AAB AAA----------AAB AAAA---------AAA CAAA---------AAA AAAAA-------AAAA AAAAA-------AAAA AAAAAA------AAAA -AAAABA----AAAAA --AAAAAA---AAAAA --AAAAAAA-AAABA- ---AAAAAAAAAAAA- ----BAA---AAAA-- -----------AAA-- ------------A--- 
AAAAA------AAAA- AAAAA-----AAABAA AAAAA-----AAAAAA AAAAA-----ABAAA- AAAAA-----AAAAA- AAAAA------AAAAA AAAAA------AAAAA ABAAA------AAAAA AAAAA------AAAAA AAAAA------AAAAA AAAA-------AAAAA AAAA-------AAAAA AAAA-------AAAAA CAAA--------AAAA AAAA--------AAAA AAAA--------AAAA AAAA--------ABBA CAAA--------AAAA CAAA---------AAA CAAA---------AAA AAAA---------AAA AAAAA--------AAA AAAAAA------AAAA AAAAAA------AAAA -AAAAAA----AAAAA --AAAAAAB--AAABA --ABAAAAAAAAAAA- ---AAAAAAAAAAAA- ----AAAAAAAAAA-- -----------AAA-- ------------A--- 
AAAAB-----AAAAA- AAAAA-----AAAAAA AAAAA-----AAAAAA AAAAA-----AAAAA- AAAAA-----AAAAA- BAAAA-----AAAAAA AAAAA-----AAAAAA AAAAA-----AAAAAA AAAAA-----AAAAAA AAAAA-----AAAAAA AAAAA------AAAAA AAAAA------AAAAA AAAAA------AAAAA AAAAA-------AAAA AAAAA-------AAAA AAAAA-------ABAA AAAAA-------AAAA AAAAA-------AAAA AAAA---------AAA AAAA---------AAA AAAAA--------AAA AAABA--------AAA AAAAAA------AABA AAAAAAA-----AAAA -AAAAAAA---AABAA --BAAAAAA-AAAAAA --AAAAAAAAAAAAA- ---AAAAAAAAAAAA- ----AAAAAAAAAA-- -----------AAA-- ------------A--- 
AAAAAA----AAAAA- AAAAAA---AAAAAAA AAAABA---AAAAAAA AAAAAA---AAAAAAA AAAAAA---AAABAB- AAAAAA---AAAAAA- AAAAAA---AAAAAAA AAAABA---ABAAABA AAABAA---AAAAAAA AAAAAAA---AAAAAA AAAAAAA---AAAAAA AAAAAAA----AAAAA AAAAABA----AABAA CAAAAAA----AAAAA CAAAAA------AAAA CAAAAA------AAAA AAAAAA------AAAA CAAAAA------AAAA CAAAAA------AAAA CAAAA-------AAAA AAAAA--------AAA ABAAAA-------AAA AAAAAB------AAAA AAAAAAA-----AAAA -AAAAAAA---AAAAA --AAAAAAA-AAAAAA --AAAAAAAAAAAAA- ---AAAAAAAAAAAA- ----AAAAAAAAAA-- ----------AAA--- -----------AA--- 
-AAAAAA-AAAAAAA- -ABAAAA-AAAAAAAA AAAAAAA-AAAAAAAA AAAAAAAAAAAAAAA- AAAAAAAAAAAAAAA- AAAAAAAAAAAAAAA- AAAAAAAAAAAAABA- AAAAAAAABAAAAAA- AAAAAAAAAAAAAAA- AAAAAAAAAAAAAAA- AAAAAAAAAAAAAAAA AAAAAAAAAAABAAAA CAAAAAAAABBAAAAA AAAAAAAAAAAAAAAA AAAAAAAAAAAAAAAA AAAAAAAAA-AAAAAA CAAAAAAA--AAAAAA AAAAAAAA---AAAAA AAAABAA----AAAAA AAAAAAA----AAAAA CBABAA------AAAA AAAAAAB-----AAAA AAAAAAA-----AAAA AAAAAAAA---AAABA --AAAAAA---AAAAA --AAAAAAA-AAAAAA --AAAAABAAAAAAA- ----AAAAAAAAAAA- -----AAAAAAAAA-- ------AAAAAAA--- -------AAAAA---- 
-AAAAAAAAAAAAA-- -AAAAAAAAAAAAA-- AAAAAAAAAAAAAA-- AAAAAAAAAABAAAA- AAAAAAAAAAAAAAA- AAAAAAAAAAAAAA-- AAAAAAABAAAAAA-- AAAAAAABAAAAAA-- AAAAAAAAAAAAAA-- AAAAAAAAAAAAAAA- AAAAAAAAAAAAAAA- AAAAAAABAAAAAAAA CAAAAAAAAABAAAA- CAAAAAAAAAAAAAAA CAAAAAAAAAAAAAAA CAAAAAAAAAAAAAAA CAAAAAAAAAAAAAAA CAAAAAAAAAAAAAAA CAAAAABAAAAAAAAA CAAAAAAAAAAAAAAA CABAAAAAAAAAAAAA AAAAAAAA---AABAA AAAAAAAA----AAAA -AAAAAAA---AAAAA --AAAAAAA-AAAAAA --AAAAAAAAAAAAAA --AAAAAAABAAAAA- ----AAAAAAAAAA-- -----AAAAAAAAA-- -------AAAABA--- ---------------- 
--AAAABAAAAAAA-- --AAAAAAAAAAAA-- -AABAAAAAABAA--- AAAAAAAAAAAABA-- AAAAAAAAAAAAAA-- -AAAABAAAAAAAA-- -AAAAAAAAAAAAA-- --AAAAAAAAAAAA-- --AAAAAAAAAAAA-- --AAAAAAAAAAAAA- -AAAAAAAAAAAAAA- -AAAAAAAAAAAAAA- AAAAAAAAAAAAAAA- -AAAAAAAAAABBAA- -AAAAAAAAAAAAAA- -AAAAAAABAABAAAA -AAAAAAAAAAAAAAA -AAAAAAAAAAABAAA -AAAAAAABBABAAAA -AAAAAAAAAAAAAAA -AAAAAAAAAAAAAAA -AAAAAAA--AAAAAA -AAAAAAA---AAAAA --AAAAAA---AAAAA --AAAAAAA-AAAAAA --AAAAAAAAAAAAAA ----AAAAAABAAAA- ----AAAAAAAAAA-- ------AAABAAAA-- -------AAAAA---- ---------------- 
--AAAAAAAAAAA--- ---AAAAAAAAAA--- ---AAAAAABAA---- ---AAAAAAAAAA--- ---AAAAAAAAAA--- ---ABAAAAAAAA--- ----AAAAAAAAA--- ----AABAAAAAA--- ----AAAAAAAAAA-- ----AAAAABAAAA-- ----AAAAAAAAAA-- ---AAAAAAAAAAA-- -AAAAAAAAAAAAA-- -AAAAAAAAABAAA-- AAAAAAAAAAAAAA-- AAAAAAAAAAAAAAB- AAAAAAAAAAAAAAA- AAAAAAAAAAAAAAA- AAAAAAAAAAAAAAAB AAAAAAAAAAAAAAAA AAAABAAAAAAAAAAA AAAAAAAA--AABAAA --AAAAAA---AAAAA ---AAAAAA-AAAAAA --AAAAAAAAAAAABA ----AAAAAAAAABA- ----AAAABAAAAAA- -----AAAAAAAAA-- ------AABAAAA--- --------AAA----- ---------------- 
----AAAAAAA----- -----AAAAAA----- -----AAAAA------ -----AAAAAA----- -----AAAAAA----- -----AAAAAA----- ------AAAAA----- ------AAAAA----- -------AAAB----- ---------------- ---------------- ---------------- ---------------- ------AAAAAAA--- -----AAAAAAAAA-- -----AAAAAAAAA-- -----AAAAAAAAA-- -----AAAAAAAAA-- ----AABAAAAAAAA- ---AAAAABAAAAAA- ---AAAAAAAAAAAA- ----AAAAA-AAAAA- --AAABAAA-AAAAA- --AAAAAAAAAAAAA- ----AAAAAAAAAAA- ----AAAAAAAAAAA- ----AAAAAAAAAAA- -----AAAAAAAAA-- ------AAAAAAA--- ---------------- ---------------- 
---------------- ---------------- ---------------- ---------------- ---------------- ---------------- ---------------- ---------------- ---------------- ---------------- ---------------- ---------------- ---------------- ---------------- ---------------- ---------------- ---------------- -----AAAA-AAA--- -----AAAAAAAAA-- ----AAAAAAAAAAB- ----AAAAAAAAAAA- ----AAAAAAAAAAA- ----AAAAAAAAAAA- -----AAAAAAAAAA- -----AAAAABBAAA- -----AAAAAAAAAA- -----AAAAAAAAB-- -----AAAAABAA--- -------AAAAA---- ---------------- ---------------- 
---------------- ---------------- ---------------- ---------------- ---------------- ---------------- ---------------- ---------------- ---------------- ---------------- ---------------- ---------------- ---------------- ---------------- ---------------- ---------------- ---------------- ------AAAAAAA--- -----AAAAAAAAA-- -----AAAAAAAAAA- -----AAAAAAAAAA- -----AAAAAAAAAA- -----AAAAAAAAAA- -----AAAAAAAAAA- -----AAAAAAAAA-- -----AAAAAAAAA-- -----AAAAAAAA--- ------AAAAAAA--- ---------------- ---------------- ---------------- 
---------------- ---------------- ---------------- ---------------- ---------------- ---------------- ---------------- ---------------- ---------------- ---------------- ---------------- ---------------- ---------------- ---------------- ---------------- ---------------- ---------------- --------AAAAAA-- -----AAAAAAAAA-- -----AAAAAAAAA-- -----AAAAAAAAA-- -----AAAAAAAAA-- -----AAAAAAAAA-- -----AAAAAAAAA-- -----AABAAAAAA-- -----AAAAAAAA--- ------AAAAAAA--- ---------------- ---------------- ---------------- ---------------- 
---------------- ---------------- ---------------- ---------------- ---------------- ---------------- ---------------- ---------------- ---------------- ---------------- ---------------- ---------------- ---------------- ---------------- ---------------- ---------------- ---------------- ---------AAAA--- ------AAAAAAA--- ------AAAAAAA--- ------BAAAAAA--- ------AAAAAAA--- ------AAAAAAA--- ------AAAAAAA--- ------AAAAAA---- ---------------- ---------------- ---------------- ---------------- ---------------- ---------------- 
---------------- ---------------- ---------------- ---------------- ---------------- ---------------- ---------------- ---------------- ---------------- ---------------- ---------------- ---------------- ---------------- ---------------- ---------------- ---------------- ---------------- ---------------- -------AAAAA---- ------AAAAAA---- ------AAAAAA---- -------AAAA----- ---------------- ---------------- ---------------- ---------------- ---------------- ---------------- ---------------- ---------------- ---------------- 
