model
size = 16 31 31, scale = 0.05, origin = -y
material 
  colors = A:#EEE B:#797979 C:#5C5C5C D:#3F3F3F E:#B3B3B3 F:#222 G:#D0D0D0 H:#969696 I:#001 J:#A00 K:#700 L:#B00 M:#800
voxels
---------------- ---------------- ---------------- ---------------- ---------------- ---------------- ---------------- ---------------- ---------------- ---------------- ---------------- ---------------- ---------------- ---------------- ---------------- ---------------- ---------------- ---------------- -------AAAAA---- ------AAAAAA---- ------AAAAAA---- -------AAAA----- ---------------- ---------------- ---------------- ---------------- ---------------- ---------------- ---------------- ---------------- ---------------- 
---------------- ---------------- ---------------- ---------------- ---------------- ---------------- ---------------- ---------------- ---------------- ---------------- ---------------- ---------------- ---------------- ---------------- ---------------- ---------------- ---------------- ---------AAAA--- ------AAAAAAA--- ------AAAAAAA--- ------AAAAAAA--- ------AAAAAAA--- ------AAAAAAA--- ------AAAAAAA--- ------AAAAAA---- ---------------- ---------------- ---------------- ---------------- ---------------- ---------------- 
---------------- ---------------- ---------------- ---------------- ---------------- ---------------- ---------------- ---------------- ---------------- ---------------- ---------------- ---------------- ---------------- ---------------- ---------------- ---------------- ---------------- --------AAAAAA-- -----AAAAAAAAA-- -----AAAAAAAAA-- -----AAAAAAAAA-- -----AAAAAAAAA-- -----AAAAAAAAA-- -----AAAAAAAAA-- -----AAAAAAAAA-- -----AAAAAAAA--- ------AAAAAAA--- ---------------- ---------------- ---------------- ---------------- 
---------------- ---------------- ---------------- ---------------- ---------------- ---------------- ---------------- ---------------- ---------------- ---------------- ---------------- ---------------- ---------------- ---------------- ---------------- ---------------- ---------------- ------AAAAAAA--- -----AAAAAAAAA-- -----AAAAAAAAAA- -----AAAAAAAAAA- -----AAAAAAAAAA- -----AAAAAAAAAA- -----AAAAAAAAAA- -----AAAAAAAAA-- -----AAAAAAAAA-- -----AAAAAAAA--- ------AAAAAAA--- ---------------- ---------------- ---------------- 
---------------- ---------------- ---------------- ---------------- ---------------- ---------------- ---------------- ---------------- ---------------- ---------------- ---------------- ---------------- ---------------- ---------------- ---------------- ---------------- ---------------- -----AAAA-AAA--- -----AAAAAAAAA-- ----AAAAAAAAAAA- ----AAAAAAAAAAA- ----AAAAAAAAAAA- ----AAAAAAAAAAA- -----AAAAAAAAAA- -----AAAAAAAAAA- -----AAAAAAAAAA- -----AAAAAAAAA-- -----AAAAAAAA--- -------AAAAA---- ---------------- ---------------- 
----FFFFFFF----- -----FFFFFF----- -----DDDDD------ -----DDDDDD----- -----CCCCCC----- -----CCCCCC----- ------BBBBB----- ------BBBBB----- -------BBBB----- ---------------- ---------------- ---------------- ---------------- ------EEEEEEE--- -----EEEEEEEEEE- -----GGGGGGGGGG- -----GGGGGGGGGG- -----AAAAAAAAAA- ----AAAAAAAAAAA- ---AAAAAAAAAAAA- ---AAAAAAAAAAAA- ---AAAAAA-AAAAA- ---AAAAAA-AAAAA- ---AAAAAAAAAAAA- ----AAAAAAAAAAA- ----AAAAAAAAAAA- ----AAAAAAAAAAA- -----AAAAAAAAA-- ------AAAAAAA--- ---------------- ---------------- 
---FFFFFFFFFF--- ---FFFFFFFFFF--- ---DDDDDDDDD---- ---DDDDDDDDDD--- ---CCCCCCCCCC--- ---CCCCCCCCCC--- ----BBBBBBBBB--- ----BBBBBBBBB--- ----BBBBBBBBBBB- ----BBBBBBBBBBB- ----BBBBBBBBBBB- -----HHHHHHHHHH- ----HHHHHHHHHHH- ----EEEEEEEEEEE- ----EEEEEEEEEEE- ---GGGGGGGGGGGG- ---GGGGGGGGGGGG- --AAAAAAAAAAAAA- ---AAAAAAAAAAAAA --AAAAAAAAAAAAAA --AAAAAAAAAAAAAA --AAAAAA--AAAAAA --AAAAAA---AAAAA ---AAAAAA-AAAAAA ---AAAAAAAAAAAAA ----AAAAAAAAAAA- ----AAAAAAAAAAA- -----AAAAAAAAA-- ------AAAAAAA--- --------AAA----- ---------------- 
---FFFFFFFFFFFF- --FFFFFFFFFFFFF- --DDDDDDDDDDD--- --DDDDDDDDDDDDD- --CCCCCCCCCCCCC- --CCCCCCCCCCCCC- --BBBBBBBBBBBBB- ---BBBBBBBBBBBB- ---BBBBBBBBBBBB- ---BBBBBBBBBBBB- ---BBBBBBBBBBBB- --HHHHHHHHHHHHH- ---HHHHHHHHHHHH- --EEEEEEEEEEEEE- --EEEEEEEEEEEEE- --GGGGGGGGGGGGGG -GGGGGGGGGGGGGGG -AAAAAAAAAAAAAAA -AAAAAAAAAAAAAAA -AAAAAAAAAAAAAAA -AAAAAAAAAAAAAAA -AAAAAAA--AAAAAA -AAAAAAA---AAAAA --AAAAAA---AAAAA --AAAAAAA-AAAAAA ---AAAAAAAAAAAAA ----AAAAAAAAAAA- ----AAAAAAAAAA-- ------AAAAAAAA-- -------AAAAA---- ---------------- 
--FFFFFFFFFFFFF- -FFFFFFFFFFFFFF- -DDDDDDDDDDDDDD- -DDDDDDDDDDDDDD- -CCCCCCCCCCCCCC- -CCCCCCCCCCCCCC- --BBBBBBBBBBBBB- --BBBBBBBBBBBBB- --BBBBBBBBBBBBB- --BBBBBBBBBBBBB- -BBBBBBBBBBBBBB- -HHHHHHHHHHHHHH- HHHHHHHHHHHHHHH- EEEEEEEEEEEEEEEE EEEEEEEEEEEEEEEE GGGGGGGGGGGGGGGG GGGGGGGGGGGGGGGG AAAAAAAAAAAAAAAA AAAAAAAAAAAAAAAA AAAAAAAAAAAAAAAA AAAAAAAAAAAAAAAA AAAAAAAA---AAAAA -AAAAAAA----AAAA -AAAAAAA---AAAAA --AAAAAAA-AAAAAA ---AAAAAAAAAAAAA ---AAAAAAAAAAAA- ----AAAAAAAAAA-- -----AAAAAAAAA-- -------AAAAAA--- ---------------- 
-FFFFFF-FFFFFFFF FFFFFFF-FFFFFFF- DDDDDDD-DDDDDDD- DDDDDDDDDDDDDDD- CCCCCCCCCCCCCCCC -CCCCCCCCCCCCCC- -BBBBBBBBBBBBBBB -BBBBBBBBBBBBBBB -BBBBBBBBBBBBBBB -BBBBBBBBBBBBBBB BBBBBBBBBBBBBBBB HHHHHHHHHHHHHHHH HHHHHHHHHHHHHHHH EEEEEEEEEEEEEEEE EEEEEEEEEEEEEEEE GGGGGGGGG-GGGGGG GGGGGGGG--GGGGGG AAAAAAAA---AAAAA AAAAAAA----AAAAA AAAAAAAA---AAAAA AAAAAAAA---AAAAA AAAAAAAAAA-AAAAA AAAAAAAAAA-AAAAA -AAAAAAA---AAAAA --AAAAAA---AAAAA --AAAAAAA-AAAAAA ---AAAAAAAAAAA-- ----AAAAAAAAAA-- -----AAAAAAAAA-- ------AAAAAAA--- -------AAAAA---- 
FFFFF-F--FFFFFFF FFFFF-F-FFFFFFFF DDDDD-D-DDDDDDD- DDDDD-D-DDDDDDDD CCCCC-CCCCCCCCCC CCCCCCCCCCCCCCC- BBBBBBBBBBBBBBB- BBBBBBBBBBBBBBBB BBBBBBBBBBBBBBBB BBBBBBBBBBBBBBBB BBBBBBBBBBBBBBBB HHHHHHHHHHHHHHHH HHHHHHHHHHHHHHHH KEEEEEEEEEEEEEEE KEEEEEEEEEEEEEEE KGGGGGGGG-GGGGGG KGGGGGGG--GGGGGG MAAAAAAA---AAAAA JAAAAAA----AAAAA JAAAAAAA----AAAA JAAAAAAA----AAAA LAAAAAAAAA--AAAA LAAAAAAAAA--AAAA AAAAAAAA---AAAAA -AAAAAAA---AAAAA --AAAAAAA-AAAAAA --AAAAAAAAAAAAA- ---AAAAAAAAAAAA- ----AAAAAAAAAA-- -----IIAAAAAA--- -------IIIIA---- 
FFFFFF----FFFFFF FFFFFF----FFFFFF DDDDDD---DDDDDDD DDDDDD---DDDDDDD CCCCCC---CCCCCC- CCCCCC---CCCCCC- BBBBBBB--BBBBBBB BBBBBBB--BBBBBBB BBBBBBB--BBBBBBB BBBBBBB--BBBBBBB BBBBBBB--BBBBBBB HHHHHH----HHHHHH HHHHHH-----HHHHH EEEEEE-----EEEEE EEEEEE-----EEEEE GGGGGG------GGGG GGGGGG------GGGG MAAAAA------AAAA AAAAA-------AAAA AAAAA-------AAAA AAAAA--------AAA AAAAAA-------AAA AAAAAA------AAAA AAAAAAA-----AAAA -AAAAAAA---AAAAA --AAAAAAA-AAAAAA --AAAAAAAAAAAAA- ---AAAAAAAAAAAA- ----IAAAAAAAAA-- ----------AAA--- -----------IA--- 
FFFFF------FFFFF FFFFF-----FFFFFF DDDDD-----DDDDDD DDDDD-----DDDDDD CCCCC-----CCCCC- CCCCC-----CCCCC- BBBBBB----BBBBBB BBBBBB----BBBBBB BBBBBB----BBBBBB BBBBBB----BBBBBB BBBBB-----BBBBBB HHHHH------HHHHH HHHH-------HHHHH EEEEE-------EEEE EEEEE-------EEEE GGGGG-------GGGG GGGGG-------GGGG MAAAA--------AAA JAAA---------AAA JAAA---------AAA JAAAA--------AAA LAAAA--------AAA LAAAAA------AAAA AAAAAAA-----AAAA -AAAAAAA---AAAAA --AAAAAAA-AAAAAA --AAAAAAAAAAAAA- ---AAAAAAAAAAAA- ----IAAAAAAAAA-- -----------AAA-- ------------I--- 
FFFFF------FFFFF FFFFF------FFFFF DDDDD-----DDDDDD DDDDD-----DDDDDD CCCCC-----CCCCC- CCCCC-----CCCCCC BBBBB-----BBBBBB BBBBB------BBBBB BBBBB-------BBBB BBBBB-------BBBB BBBB--------BBBB HHHH--------HHHH HHHH--------HHHH EEEE--------EEEE EEEE---------EEE GGGG---------GGG GGGG---------GGG AAAA---------AAA AAAA---------AAA AAAA---------AAA AAAA---------AAA AAAAA--------AAA AAAAAA------AAAA AAAAAA------AAAA -AAAAAA----AAAAA --AAAAAA---AAAAA --AAAAAAAAAAAAA- ---AAAAAAAAAAAA- ----IAAAAAAAAA-- -----------AAA-- ------------I--- 
FFFF-------FFFFF FFFF-------FFFFF DDDD------DDDDDD DDDD------DDDDDD CCCC------CCCCC- CCCC------CCCCCC BBBB------BBBBBB BBBB-------BBBBB BBBB--------BBBB BBBB--------BBBB BBB----------BBB HHH----------HHH HHH----------HHH EEE----------EEE KEE----------EEE KGG----------GGG KGG----------GGG MAA----------AAA JAA----------AAA JAAA---------AAA JAAA---------AAA LAAAA-------AAAA AAAAA-------AAAA AAAAAA------AAAA -AAAAAA----AAAAA --AAAAAA---AAAAA --AAAAAAA-AAAAA- ---AAAAAAAAAAAA- ----IAA---AAAA-- -----------AAA-- ------------I--- 
FFFF-------FFFFF FFFF-------FFFFF DDDD------DDDDDD DDDD------DDDDD- CCCC------CCCCC- CCCC------CCCCCC BBBB-------BBBBB BBBB--------BBBB BBBB--------BBBB BBBB--------BBBB BBB----------BBB HHH----------HHH HHH----------HHH KEE----------EEE EEE----------EEE GGG----------GGG GGG----------GGG AAA----------AAA AAA----------AAA AAAA---------AAA AAAA---------AAA AAAAA-------AAAA LAAAA-------AAAA AAAAAA------AAAA -AAAAA-----AAAAA --AAAAAA---AAAAA --AAAAAA--AAAAA- ---AAAAA--AAAAA- ----IAA---AAAA-- -----------AAA-- ------------I--- 
FFFF-------FFFFF FFFF-------FFFFF DDDD-------DDDDD DDDD-------DDDD- CCCC-------CCCC- CCCC-------CCCCC BBBB-------BBBBB BBBB--------BBBB BBBB--------BBBB BBBB--------BBBB BBBB---------BBB HHHH---------HHH HHHH---------HHH KEEE---------EEE EEEE---------EEE GGGG---------GGG GGG----------GGG AAA----------AAA AAA----------AAA AAAA---------AAA AAAA---------AAA AAAAA-------AAAA LAAAA-------AAAA AAAAAA------AAAA -AAAAA-----AAAAA --AAAAAA---AAAAA --AAAAAA--AAAAA- ---AAAAA--AAAAA- ----IAA---AAAA-- -----------AAA-- ------------I--- 
FFFF-------FFFFF FFFF-------FFFFF DDDD-------DDDDD DDDD-------DDDD- CCCC-------CCCC- CCCC-------CCCCC BBBB-------BBBBB BBBB--------BBBB BBBB--------BBBB BBBB--------BBBB BBBB--------BBBB HHHH--------HHHH HHHH--------HHHH EEEE--------EEEE KEEE--------EEEE KGGG--------GGGG KGG---------GGGG MAA----------AAA JAA----------AAA JAAA---------AAA JAAA---------AAA LAAAA-------AAAA AAAAA-------AAAA AAAAAA------AAAA -AAAAAA----AAAAA --AAAAAA---AAAAA --AAAAAAA-AAAAA- ---AAAAAAAAAAAA- ----IAA---AAAA-- -----------AAA-- ------------I--- 
FFFFF------FFFF- FFFFF-----FFFFFF DDDDD-----DDDDDD DDDDD-----DDDDD- CCCCC-----CCCCC- CCCCC------CCCCC BBBBB------BBBBB BBBBB------BBBBB BBBBB------BBBBB BBBBB------BBBBB BBBB-------BBBBB HHHH-------HHHHH HHHH-------HHHHH EEEE--------EEEE EEEE--------EEEE GGGG--------GGGG GGGG--------GGGG AAAA--------AAAA AAAA---------AAA AAAA---------AAA AAAA---------AAA AAAAA--------AAA AAAAAA------AAAA AAAAAA------AAAA -AAAAAA----AAAAA --AAAAAAA--AAAAA --AAAAAAAAAAAAA- ---AAAAAAAAAAAA- ----IAAAAAAAAA-- -----------AAA-- ------------I--- 
FFFFF-----FFFFF- FFFFF-----FFFFFF DDDDD-----DDDDDD DDDDD-----DDDDD- CCCCC-----CCCCC- CCCCC-----CCCCCC BBBBB-----BBBBBB BBBBB-----BBBBBB BBBBB-----BBBBBB BBBBB-----BBBBBB BBBBB------BBBBB HHHHH------HHHHH HHHHH------HHHHH KEEEE-------EEEE KEEEE-------EEEE KGGGG-------GGGG KGGGG-------GGGG MAAAA-------AAAA JAAA---------AAA JAAA---------AAA JAAAA--------AAA LAAAA--------AAA LAAAAA------AAAA AAAAAAA-----AAAA -AAAAAAA---AAAAA --AAAAAAA-AAAAAA --AAAAAAAAAAAAA- ---AAAAAAAAAAAA- ----IAAAAAAAAA-- -----------AAA-- ------------I--- 
FFFFFF----FFFFF- FFFFFF---FFFFFFF DDDDDD---DDDDDDD DDDDDD---DDDDDDD CCCCCC---CCCCCC- CCCCCC---CCCCCC- BBBBBB---BBBBBBB BBBBBB---BBBBBBB BBBBBB---BBBBBBB BBBBBBB---BBBBBB BBBBBBB---BBBBBB HHHHHHH----HHHHH HHHHHHH----HHHHH EEEEEEE----EEEEE EEEEEE------EEEE GGGGGG------GGGG GGGGGG------GGGG MAAAAA------AAAA AAAAAA------AAAA AAAAA-------AAAA AAAAA--------AAA AAAAAA-------AAA AAAAAA------AAAA AAAAAAA-----AAAA -AAAAAAA---AAAAA --AAAAAAA-AAAAAA --AAAAAAAAAAAAA- ---AAAAAAAAAAAA- ----IIAAAAAAAA-- ----------AAA--- -----------IA--- 
-FFFFFF-FFFFFFF- -FFFFFF-FFFFFFFF DDDDDDD-DDDDDDDD DDDDDDDDDDDDDDD- CCCCCCCCCCCCCCC- CCCCCCCCCCCCCCC- BBBBBBBBBBBBBBB- BBBBBBBBBBBBBBB- BBBBBBBBBBBBBBB- BBBBBBBBBBBBBBB- BBBBBBBBBBBBBBBB HHHHHHHHHHHHHHHH HHHHHHHHHHHHHHHH EEEEEEEEEEEEEEEE EEEEEEEEEEEEEEEE GGGGGGGGG-GGGGGG GGGGGGGG--GGGGGG MAAAAAAA---AAAAA JAAAAAA----AAAAA JAAAAAA----AAAAA JAAAAA------AAAA LAAAAAA-----AAAA LAAAAAA-----AAAA AAAAAAAA---AAAAA --AAAAAA---AAAAA --AAAAAAA-AAAAAA --AAAAAAAAAAAAA- ----AAAAAAAAAAA- -----AAAAAAAAA-- ------IAAAAAA--- -------IIIIA---- 
-FFFFFFFFFFFFF-- -FFFFFFFFFFFFF-- DDDDDDDDDDDDDD-- DDDDDDDDDDDDDDD- CCCCCCCCCCCCCCC- CCCCCCCCCCCCCC-- BBBBBBBBBBBBBB-- BBBBBBBBBBBBBB-- BBBBBBBBBBBBBB-- BBBBBBBBBBBBBBB- BBBBBBBBBBBBBBB- HHHHHHHHHHHHHHHH HHHHHHHHHHHHHHH- EEEEEEEEEEEEEEEE EEEEEEEEEEEEEEEE GGGGGGGGGGGGGGGG GGGGGGGGGGGGGGGG AAAAAAAAAAAAAAAA AAAAAAAAAAAAAAAA AAAAAAAAAAAAAAAA AAAAAAAAAAAAAAAA AAAAAAAA---AAAAA AAAAAAAA----AAAA -AAAAAAA---AAAAA --AAAAAAA-AAAAAA --AAAAAAAAAAAAAA --AAAAAAAAAAAAA- ----AAAAAAAAAA-- -----AAAAAAAAA-- -------AAAAAA--- ---------------- 
--FFFFFFFFFFFF-- --FFFFFFFFFFFF-- -DDDDDDDDDDDD--- DDDDDDDDDDDDDD-- CCCCCCCCCCCCCC-- -CCCCCCCCCCCCC-- -BBBBBBBBBBBBB-- --BBBBBBBBBBBB-- --BBBBBBBBBBBB-- --BBBBBBBBBBBBB- -BBBBBBBBBBBBBB- -HHHHHHHHHHHHHH- HHHHHHHHHHHHHHH- EEEEEEEEEEEEEEE- EEEEEEEEEEEEEEE- GGGGGGGGGGGGGGGG GGGGGGGGGGGGGGGG AAAAAAAAAAAAAAAA AAAAAAAAAAAAAAAA AAAAAAAAAAAAAAAA AAAAAAAAAAAAAAAA AAAAAAAA--AAAAAA -AAAAAAA---AAAAA --AAAAAA---AAAAA --AAAAAAA-AAAAAA --AAAAAAAAAAAAAA ----AAAAAAAAAAA- ----AAAAAAAAAA-- ------AAAAAAAA-- -------AAAAA---- ---------------- 
--FFFFFFFFFFF--- ---FFFFFFFFFF--- ---DDDDDDDDD---- ---DDDDDDDDDD--- ---CCCCCCCCCC--- ---CCCCCCCCCC--- ----BBBBBBBBB--- ----BBBBBBBBB--- ----BBBBBBBBBB-- ----BBBBBBBBBB-- ----BBBBBBBBBB-- ---HHHHHHHHHHH-- -HHHHHHHHHHHHH-- -EEEEEEEEEEEEE-- -EEEEEEEEEEEEE-- -GGGGGGGGGGGGGG- -GGGGGGGGGGGGGG- -AAAAAAAAAAAAAA- -AAAAAAAAAAAAAAA -AAAAAAAAAAAAAAA -AAAAAAAAAAAAAAA -AAAAAAA--AAAAAA --AAAAAA---AAAAA --AAAAAAA-AAAAAA --AAAAAAAAAAAAAA ----AAAAAAAAAAA- ----AAAAAAAAAAA- -----AAAAAAAAA-- ------AAAAAAA--- --------AAA----- ---------------- 
----FFFFFFF----- -----FFFFFF----- -----DDDDD------ -----DDDDDD----- -----CCCCCC----- -----CCCCCC----- ------BBBBB----- ------BBBBB----- -------BBBB----- ---------------- ---------------- ---------------- ---------------- ------EEEEEEE--- -----EEEEEEEEE-- -----GGGGGGGGG-- -----GGGGGGGGG-- -----AAAAAAAAA-- ----AAAAAAAAAAA- ---AAAAAAAAAAAA- ---AAAAAAAAAAAA- ----AAAAA-AAAAA- --AAAAAAA-AAAAA- --AAAAAAAAAAAAA- ----AAAAAAAAAAA- ----AAAAAAAAAAA- ----AAAAAAAAAAA- -----AAAAAAAAA-- ------AAAAAAA--- ---------------- ---------------- 
---------------- ---------------- ---------------- ---------------- ---------------- ---------------- ---------------- ---------------- ---------------- ---------------- ---------------- ---------------- ---------------- ---------------- ---------------- ---------------- ---------------- -----AAAA-AAA--- -----AAAAAAAAA-- ----AAAAAAAAAAA- ----AAAAAAAAAAA- ----AAAAAAAAAAA- ----AAAAAAAAAAA- -----AAAAAAAAAA- -----AAAAAAAAAA- -----AAAAAAAAAA- -----AAAAAAAAA-- -----AAAAAAAA--- -------AAAAA---- ---------------- ---------------- 
---------------- ---------------- ---------------- ---------------- ---------------- ---------------- ---------------- ---------------- ---------------- ---------------- ---------------- ---------------- ---------------- ---------------- ---------------- ---------------- ---------------- ------AAAAAAA--- -----AAAAAAAAA-- -----AAAAAAAAAA- -----AAAAAAAAAA- -----AAAAAAAAAA- -----AAAAAAAAAA- -----AAAAAAAAAA- -----AAAAAAAAA-- -----AAAAAAAAA-- -----AAAAAAAA--- ------AAAAAAA--- ---------------- ---------------- ---------------- 
---------------- ---------------- ---------------- ---------------- ---------------- ---------------- ---------------- ---------------- ---------------- ---------------- ---------------- ---------------- ---------------- ---------------- ---------------- ---------------- ---------------- --------AAAAAA-- -----AAAAAAAAA-- -----AAAAAAAAA-- -----AAAAAAAAA-- -----AAAAAAAAA-- -----AAAAAAAAA-- -----AAAAAAAAA-- -----AAAAAAAAA-- -----AAAAAAAA--- ------AAAAAAA--- ---------------- ---------------- ---------------- ---------------- 
---------------- ---------------- ---------------- ---------------- ---------------- ---------------- ---------------- ---------------- ---------------- ---------------- ---------------- ---------------- ---------------- ---------------- ---------------- ---------------- ---------------- ---------AAAA--- ------AAAAAAA--- ------AAAAAAA--- ------AAAAAAA--- ------AAAAAAA--- ------AAAAAAA--- ------AAAAAAA--- ------AAAAAA---- ---------------- ---------------- ---------------- ---------------- ---------------- ---------------- 
---------------- ---------------- ---------------- ---------------- ---------------- ---------------- ---------------- ---------------- ---------------- ---------------- ---------------- ---------------- ---------------- ---------------- ---------------- ---------------- ---------------- ---------------- -------AAAAA---- ------AAAAAA---- ------AAAAAA---- -------AAAA----- ---------------- ---------------- ---------------- ---------------- ---------------- ---------------- ---------------- ---------------- ---------------- 
