model
size = 29 32 32, scale = 0.05, origin = -y
material 
  colors = A:#F3F B:#888 C:#AAA D:#111 E:#CCF F:#FCF G:#0F3 H:#E00 I:#F30 J:#F39 K:#F36 L:#CC9 M:#F3C N:#CF0 O:#FCC P:#CC0 Q:#F6C R:#CFC S:#FF3 T:#FC0 U:#F09 V:#FF9 W:#F69 X:#F66 Y:#CC6 Z:#F9C Aa:#F33 Ab:#F60 Ac:#FF6 Ad:#F99 Ae:#F96 Af:#F9F Ag:#FC3 Ah:#F93 Ai:#CF6 Aj:#F0C Ak:#CF3 Al:#CCC Am:#F90 An:#CF9 Ao:#CFF Ap:#FFF Aq:#F00 Ar:#F6F As:#FFC At:#F06 Au:#FF0 Av:#CC3 Aw:#FC9 Ax:#F63 Ay:#F03 Az:#FC6 Ba:#F0F
voxels
3-4(A-)7A4(-A)5-11A-A-11A3-3A-19A-3A2-5A17-5A3-A2-A17-A2-2A3-4A17-5A2-3A-A17-A-4A2-26A4-4A15-4A4-27A3-25A5-3A15-4A8-3A13-3A12-16A532-4(A-)7A4(-A)5-11A-A-11A3-3A-A17DA-3A2-4AD17-D4A3-A2-D17-D2-2A3-3AD17-D4A2-3A-D17-D-4A2-4A17D5A4-4A15-4A4-27A3-23ADA5-3A2C11-2CDA2D8-2DA13C2DA13-4D7A4D18-7D507-4(A-)7A4(-A)5-11A-A-11A3-3A-19A-3A2-5AFAMJ2KDHFHD2KJMAF5A3-A2-AFAMJ3IHFH3IJMAFA2-2A3-4AFAMJ3I3F3IJMAF5A2-3A-AFAMJ2K5F2KJMAFA-4A2-26A4-4A15-4A4-27A3-23ADA5-5A11-2ADA2D8-2D13A3DA13-4D7A4D18-6DG507-4(A-)7A4(-A)5-11A-A-11A3-3A-19A-3A2-27A3-A2-19A2-2A3-26A2-3A-19A-4A2-26A4-4A15-4A4-27A3-23ADA5-5A11-2ADA2D8-2D13A3DA13-4D7A2DGD18-2(DG)3D507-4(A-)7A4(-A)5-11A-A-11A3-3A-19A-3A2-27A3-A2-19A2-2A3-26A2-3A-19A-4A2-26A4-4A17C2A4-6A17C4A3-23ADA5-5A11-2ADA2D8-2D13A3DA13-4D7A4D18-7D507-4(A-)7A4(-A)5-5A17C3A3-3A-2A17C-3A2-6A17C4A3-A2-2A17C2-2A3-5A17C4A2-3A-2A17C-4A2-5A17C4A4-4A17C2A4-6A17C4A3-23ADA5-5A11-2ADA2D8-2D13A3DA13-4D7A4D18-7D507-A-A19-A5-4AC17-C2A3-3A-AC18-3A2-5AC17-C3A3-A2-AC19-2A3-4AC17-C3A2-3A-AC18-4A2-4AC17-C3A4-3AC17-CA4-6AAjLAmAaAdZLVRAyAlJApJPAkJ4A3-23ADA5-5A11-2ADA2D8-2D13A3DA13-4D7A4D18-5D2G507-A-A19-A5-4AC17-C2A3-3A-AC18-3A2-5AC17-C3A3-A2-AC19-2A3-4AC17-C3A2-3A-AC18-4A2-4AC17-C3A4-3AC17-CA4-6AWLAbSUAqXRZVAcMKPQAkK4A3-23ADA5-5A11-2ADA2D8-2D13A3DA13-DG2D7A4D18-7D507-A-A19-A5-4AC17-C2A3-3A-AC18-3A2-5AC17-C3A3-A2-AC19-2A3-4AC17-C3A2-3A-AC18-4A2-4AC17-C3A4-3AC17-CA4-6APKAcAhULAeTOFNAxEXAcAwAd4A3-23ADA5-5A11-2ADA2D8-2D13A3DA13-4D7A4D18-7D507-A-A19-A5-4AC17-C2A3-3A-AC18-3A2-5AC17-C3A3-A2-AC19-2A3-4AC17-C3A2-3A-AC18-4A2-4AC17-C3A4-3AC17-CA4-6AAdFAaPApOAeAsAgNYAyAuAxJArAv4A3-23ADA5-5A11-2ADA2D8-2D13A3DA13-4D7A4D18-DG5D507-A-A19-A5-4AC17-C2A3-3A-AC18-3A2-5AC17-C3A3-A2-AC19-2A3-4AC17-C3A2-3A-AC18-4A2-4AC17-C3A4-3AC17-CA4-6AAxAoZQAzWAiAyAfAZApAbAaR2Ag4A3-23ADA5-5A11-2ADA2D8-2D13A3DA13-4D7A4D18-7D507-A-A19-A5-4AC17-C2A3-3A-AC18-3A2-5AC17-C3A3-A2-AC19-2A3-4AC17-C3A2-3A-AC18-4A2-4AC17-C3A4-3AC17-CA4-6AAvPSAcAgAkIZSApVAlTAgRUI4A3-23ADA5-5A11-2ADA2D8-2D13A3DA13-4D7A4D13-4DG12D11-19D10-6D2(2ED)ED2EDED9-2DG2D2G5(DG)2DED7-4DG5DG12D6-3DG5DGDG11D6-12D-10D6-D3A2(DA)2(3DA)DA2DADA6-2(DA)2DA2D3AD3A2DA4D6-8(DA)3DA3D6-D3A5D4(AD)3A3D7-21D181-A-A19-A5-4AC17-C2A3-3A-AC18-3A2-5AC17-C3A3-A2-AC19-2A3-4AC17-C3A2-3A-AC18-4A2-4AC17-C3A4-3AC17-CA4-6ASQAjJAuApAnAcOKAdAcAhAwNAnAl4A3-23ADA5-5A11-2ADA2D8-2D13A3DA13-4D7A4D13-17A11-19A9-A19B2A6-A21B2A5-A22BA4-A23BA4-A12BD10B4(A4-A23B)A4-A23DA5-23D151-A-A19-A5-4AC17-C2A3-3A-AC18-3A2-5AC17-C3A3-A2-AC19-2A3-4AC17-C3A2-3A-AC18-4A2-4AC17-C3A4-3AC17-CA4-6AAqUWRJAsAcAzTESNEWAtAbO4A3-23ADA5-5A11-2ADA2D8-2D13A3DA13-4D7A4D13-A7-A-7A11-19A9-A19B2A6-A21B2A4-A2(23B2A2-2A)23B2A2-27A3(2-2A23B2A)2-27A3-A23D2A4-A21D2A121-A-A19-A5-4AC17-C2A3-3A-AC18-3A2-5AC17-C3A3-A2-AC19-2A3-4AC17-C3A2-3A-AC18-4A2-4AC17-C3A4-3AC17-CA4-6AZAPRPAjAAiAlAuAbYXAfAmAqAo4A3-23ADA5-5A11-2ADA2D8-2D13A3DA13-4D7A4D13-17A11-19A9-A19B2A6-A21B2A4-A2(23B2A2-2A)4(23B3A-2A)23B3A-A25B2A-A25DA3-3A19D3A121-A-A19-A5-4AC17-C2A3-3A-AC18-3A2-5AC17-C3A3-A2-AC19-2A3-4AC17-C3A2-3A-AC18-4A2-4AC17-C3A4-3AC17-CA4-6ANYAdNXVAvAeAfAbAlZAnAaLAiY4A3-23ADA5-5A11-2ADA2D8-2D13A3DA13-4D7A4D13-17A11-19A9-A19B2A6-A5BPAaLNOBAyAjXFQC4B2A4-A9BAlBNRAi2BIC5B2A-9ABLYEL2BJBEAC17AVNBAeAoMAeXBLAC11A6BN2(O2B)AbR2BC5B6A6BOBQ3BT2B2YC5B6A8BIBXAi2BX2BC5B6A6BLBAPBAyPV3BC5B19AC41A2-26A4-23A93-A-A19-A5-4AC17-C2A3-3A-AC18-3A2-5AC17-C3A3-A2-AC19-2A3-4AC17-C3A2-3A-AC18-4A2-4AC17-C3A4-3AC17-CA4-6AAtQAxAtAxAuAsAjBaTArVAfFLAaZ4A3-23ADA5-5A11-2ADA2D8-2D13A3DA13-4D7A4D13-17A11-19A9-A4B11C4B2A6-A4BC11-C4B2A4-A5BC11-C5B2A-8AC11-C16AC11-C11A3(5BC11-C5B6A)5BC11-C5B5A7B11C7B31A-27A3-26A91-A-A19-A5-4AC17-C2A3-3A-AC18-3A2-5AC17-C3A3-A2-AC19-2A3-4AC17-C3A2-3A-AC18-4A2-4AC17-C3A4-3AC17-CA4-6AOLAvAmAaRAsAkAdAhAfAdMAmKSAq4A3-23ADA5-5A11-2ADA2D8-2D13A3DA13-4D7A4D13-17A11-19A9-A4B11C4B2A6-A4BC11-C4B2A4-A5BC11-C5B2A-8AC11-C16AC11-C11A3(5BC11-C5B6A)5BC11-C5B5A7B11C7B31A-27A3-26A4-24A63-A-A19-A5-4AC17-C2A3-3A-AC18-3A2-5AC17-C3A3-A2-AC19-2A3-4AC17-C3A2-3A-AC18-4A2-4AC17-C3A4-3AC7-H9-CA4-6AAnESLAgTAuAvAsEAeSAiAbFAhL4A3-23ADA5-5A11-2ADA2D8-2D13A3DA13-4D7A4D13-17A11-19A9-A4B11C4B2A6-A4BC11-C4B2A4-A5BC11-C5B2A-8AC11-C16AC11-C11A3(5BC11-C5B6A)5BC11-C5B5A7B11C7B31A-27A3-26A4-24A6-22D35-A-A19-A5-4AC17-C2A3-3A-AC18-3A2-5AC17-C3A3-A2-AC19-2A3-4AC17-C3A2-3A-AC18-4A2-4AC17-C3A4-3AC7-H9-CA4-6AAoAmAqLAwAkNFIXOAbAhAcAoPO4A3-23ADA5-5A11-2ADA2D8-2D13A3DA13-4D7A4D13-17A11-19A9-A4B11C4B2A6-A4BC9-E-C4B2A4-A5BC9-E-C5B2A-8AC11-C16AC11-C11A3(5BC11-C5B6A)5BC11-C5B5A7B11C7B31A-27A3-26A4-24A6-22D16-2A17-A-A19-A5-4AC17-C2A3-3A-AC18-3A2-5AC11-H5-C3A3-A2-AC6-3E3H7-2A3-4AC6-E10-C3A2-3A-AC6-E11-4A2-4AC6-E10-C3A4-3AC6-E10-CA4-6AAlAmZKWAiMAdAkAnQAlTAaPQW4A3-23ADA5-5A11-2ADA2D8-2D13A3DA13-4D7A4D13-17A11-19A9-A4B11C4B2A6-A4BC11-C4B2A4-A5BC9-E-C5B2A-8AC11-C16AC11-C11A3(5BC11-C5B6A)5BC11-C5B5A7B11C7B31A-27A3-26A4-24A6-22D16-2A17-A-A19-A5-4AC2-5H10-C2A3-3A-AC6-H11-3A2-5AC6-H10-C3A3-A2-AC6-H-E10-2A3-4AC17-C3A2-3A-AC18-4A2-4AC17-C3A4-3AC17-CA4-6ABaSNFAfArAtUAkAfAzArTZQAcAk4A3-23ADA5-5A11-2ADA2D8-2D13A3DA13-4D7A4D13-17A11-19A9-A4B11C4B2A6-A4BC11-C4B2A4-A5BC8-2E-C5B2A-8AC11-C16AC11-C11A3(5BC11-C5B6A)5BC11-C5B5A7B11C7B31A-27A3-26A4-24A6-22D35-A-A19-A5-4AC3-H13-C2A3-3A-AC18-3A2-5AC17-C3A3-A2-AC6-H-E10-2A3-4AC17-C3A2-3A-AC18-4A2-4AC17-C3A4-3AC7-E9-CA4-6AXKAtAoAaMVUAwMUAfYSUJAp4A3-23ADA5-5A11-2ADA2D8-2D13A3DA13-4D7A4D13-17A11-19A9-A4B11C4B2A6-A4BC11-C4B2A4-A5BC8-E2-C5B2A-8AC11-C16AC11-C11A3(5BC11-C5B6A)5BC11-C5B5A7B11C7B31A-27A3-26A4-24A6-22D35-A-A4-H14-A5-4AC3-H13-C2A3-3A-AC18-3A2-5AC17-C3A3-A2-AC8-E10-2A3-4AC8-E8-C3A2-3A-AC8-E9-4A2-4AC17-C3A4-3AC17-CA4-6AFAjOPFVAnApArAiWAeYAjARAs4A3-23ADA5-5A11-2ADA2D8-2D13A3DA13-4D7A4D13-17A11-19A9-A4B11C4B2A6-A4BC11-C4B2A4-A5BC8-E2-C5B2A-8AC11-C16AC11-C11A3(5BC11-C5B6A)5BC11-C5B5A7B11C7B31A-27A3-26A4-24A63-A-A19-A5-4AC17-C2A3-3A-AC18-3A2-5AC17-C3A3-A2-AC19-2A3-4AC17-C3A2-3A-AC8-E9-4A2-4AC17-C3A4-3AC8-E8-CA4-6AAdAhAnQAmRKAzAgAhQO2WYRAj4A3-23ADA5-5A11-2ADA2D8-2D13A3DA13-4D7A4D13-17A11-19A9-A4B11C4B2A6-A4BC11-C4B2A4-A5BC7-2E2-C5B2A-8AC11-C16AC11-C11A3(5BC11-C5B6A)5BC11-C5B5A7B11C7B31A-27A3-26A91-A-A19-A5-4AC17-C2A3-3A-AC18-3A2-5AC17-C3A3-A2-AC19-2A3-4AC17-C3A2-3A-AC8-E9-4A2-4AC17-C3A4-3AC8-E8-CA4-6AAuAmAoUAbTBaAgUTAeQAtPQNV4A3-23ADA5-5A11-2ADA2D8-2D13A3DA13-4D7A4D13-17A11-19A9-A4B11C4B2A6-A4BC11-C4B2A4-A5BC7-E3-C5B2A-8AC7-E3-C16AC11-C11A3(5BC11-C5B6A)5BC11-C5B5A7B11C7B31A-27A3-26A91-4(A-)7A4(-A)5-5A17C3A3-3A-2A17C-3A2-6A17C4A3-A2-2A17C2-2A3-5A17C4A2-3A-2A17C-4A2-5A17C4A4-4A17C2A4-6A17C4A3-23ADA5-5A11-2ADA2D8-2D13A3DA13-4D7A4D13-17A11-19A9-A4B11C4B2A6-A4BC11-C4B2A4-A5BC7-E3-C5B2A-8AC7-E3-C16AC11-C11A3(5BC11-C5B6A)5BC11-C5B5A7B11C7B31A-27A120-4(A-)7A4(-A)5-11A-A-11A3-3A-19A-3A2-27A3-A2-19A2-2A3-26A2-3A-19A-4A2-26A4-4AAwAfLOJMAeArTAhAqNASW4A4-27A3-23ADA5-5A11-2ADA2D8-2D13A3DA13-4D7A4D14-16A11-A-17A9-AB-2B11C4B2A6-A2B-BC11-C4B2A4-A3B-BC11-C5B2A-6A-AC7-E3-C14A-AC11-C11A3(3B-BC11-C5B6A)3B-BC11-C5B5A4B-2B11C7B2A-27A149-4(A-)7A4(-A)5-11A-A-11A3-3A-19A-3A2-27A3-A2-19A2-2A3-26A2-3A-19A-4A2-26A4-4A15-4A4-27A3-23ADA5-5A11-2ADA2D8-2D13A3DA13-4D7A4D41-19A9-A4B11C4B2A6-A4BC11-C4B2A4-A5BC11-C5B2A-8AC7-E3-C16AC11-C11A3(5BC11-C5B6A)5BC11-C5B32A177-4(A-)7A4(-A)5-11A-A-11A3-3A-19A-3A2-27A3-A2-19A2-2A3-26A2-3A-19A-4A2-26A4-4A15-4A4-27A3-25A5-5A6-E6-2A2D8-5A5-E4-4A13-15A69-22A6-A4BC11-C4B2A4-7A7-2E2-8A17-E13-8A4(11-18A)11-9A206-4(A-)7A4(-A)5-11A-A-11A3-3A-19A-3A2-27A3-A2-19A2-2A3-26A2-3A-19A-4A2-26A4-4A15-4A4-27A3-25A5-4A14-4A48-E103-6A11-7A19-E391-4(A-)7A4(-A)5-25A3-3A-19A-3A2-27A3-A2-19A2-2A3-26A2-3A-19A-4A2-26A4-4A15-4A4-27A3-25A75-E28-3E4(28-E)388-
