model
size = 32, scale = 0.05, origin = -y
material 
  colors = A:#F3F B:#AAA C:#111 D:#0F3 E:#996 F:#CF3 G:#CC9 H:#FF6 I:#F09 J:#F96 K:#F33 L:#F9C M:#FFF N:#FF3 O:#F60 P:#CF6 Q:#FC6 R:#F00 S:#F66 T:#CFC U:#FC0 V:#FFC W:#FF9 X:#F93 Y:#F99 Z:#F90 Aa:#CC0 Ab:#FCC Ac:#CF9 Ad:#F03 Ae:#F69 Af:#F6C Ag:#F30 Ah:#FC3 Ai:#F36 Aj:#FCF Ak:#FF0
voxels
4-3(4(A-)8A4(-A)8-)4(A-)8A4(-A)4-5A3(-A)-8A3(-A)-5A6-3(A-)8A3(-A)6-7A18-7A2(32-6A20-6A)32-6A7(20-12A)2(20-6A32-6A)20-6A32-7A18-7A6-3(A-)8A3(-A)6-5A3(-A)-8A3(-A)-5A4-3(4(A-)8A4(-A)8-)4(A-)8A4(-A)7-2(11A-2A-11A6-)11A-2A-11A3-14A-2A-28A-2A-22A16B15AB16-B13A2B16-2B11A5(B20-B10A)2(B20-B5A5-B20-B5-5AB20-B10A)4(B20-B10A)B20-B11A2B16-2B13AB16-B15A16B22A-2A-28A-2A-14A3-2(11A-2A-11A6-)11A-2A-11A5-3A-20A-3A4-3A-A18CA-3A2-5A2(-20A-10A)-20A-5A6-2A16B2A6-7AB16-B8AC4A2B16-2B4A16(C2AC3AB20-B3A)C2AC4A2B16-2B4AC8AB16-B7A6-2A16B2A6-5A2(-20A-10A)-20A-5A2-3A-A18CA-3A4-3A-20A-3A3-6A18-6A-6AC18-C13A18B79A16B9AC5AB16-B5ACA2-F3A2B16-2B3A16(D4-F2AB20-B2A)D4-F3A2B16-2B3AD2-AC5AB16-B5AC9A16B79A18E13AC18-C6A-6A18-6A-4A2-A18-A2-8A2-C18-C2-8A2-A18BA2-8A2-20A2-4A6-20A12-2A16B2A6-AC5AB16-B5ACA2-F3A2B16-2B3A16(D4-F2AB20-B2A)D4-F3A2B16-2B3AD2-AC5AB16-B5ACA6-2A16B2A12-20A6-4A2-20A2-8A2-A18EA2-8A2-C18-C2-8A2-A18-A2-4A2(-A)-2A18-2A2(-A)-2A2(-A)C18-C2(A-)2A3-A-2A18B2A-A3-4A-22A-4A5-22A5-8A16B9AC5AB16-B5ACA2-F3A2B16-2B3A16(D4-F2AB20-B2A)D4-F3A2B16-2B3AD2-AC5AB16-B5AC9A16B8A5-22A5-4A-22A-4A3-A-2A18E2A-A3-2A2(-A)C18-C2(A-)2A2(-A)-2A18-2A2(-A)-7A18-10A4C18-4C10A18B8A2(C28AC2A)C6A16B6AC2AC5AB16-B5ACA2-F3A2B16-2B3A16(D4-F2AB20-B2A)D4-F3A2B16-2B3AD2-AC5AB16-B5AC2AC6A16B6A2(C2AC28A)C8A18E10A4C18-4C10A18-7A-2A4-18A4-2A-2AC4-18C4-C3ACA4B18A4BACA2-2(F26AD4-)F5A16B5AD4-F3A2B16-2B3AD2-AC4A2B16-2B4A16(C2AC3AB20-B3A)C2AC4A2B16-2B4ACA2-F3A2B16-2B3AD4-F5A16B5A2(D4-F26A)D2-ACA4E18A4EAC3AC4-18C4-C2A-2A4-18A4-2A-3A4-A16-A4-5AC4-C16-C4-C3ACA4BA16-A4BACA2-F5A16-5AD4-F5A16B5AD4-F2A22B2AD4-F2AB20-B2AD2-AC3AB20-B3ACA4-15(2B20-2B8-)2B20-2B4-AC3AB20-B3ACA2-F2AB20-B2AD4-F2A22B2AD4-F5A16B5AD4-F5A16-5AD2-ACA4EA16-A4EAC3AC4-C16-C4-C5A4-A16-A4-3A-2A4-A-14A-A4-2A-2AC4-C-14A-C4-C3ACA4BA-14A-A4BACA2-F5A-14A-5AD4-F5A16B5AD4-F2A22B2AD4-F2AB3-GZKYLG2WGLYKZG3-B2AD2-AC3AB3-GONIRS2TSRINOG3-B3ACA4-2B3-AiHXIGJ2UJGIXHAi3-2B4-4A2B2GAiAjKAaMAbJ2VJAbMAaKAjAi2G2B8A2BZOHKLAfQAeP2AdPAeQAfLKHOZ2B8A2BKNXAaAfHAhFAg2LAgFAhHAfAaXNK2B8A2BY2IMQAhAkMAc2HAcMAkAhQM2IY2B8A2BLRGAbAeFMVH2QHVMFAeAbGRL2B8A2BGS2JPAgAcHA2PAHAcAgP2JSG2(2B8A2BWTUVAdLHQP2JPQHLAdVUTW)2B8A2BGS2JPAgAcHA2PAHAcAgP2JSG2B8A2BLRGAbAeFMVH2QHVMFAeAbGRL2B8A2BY2IMQAhAkMAc2HAcMAkAhQM2IY2B8A2BKNXAaAfHAhFAg2LAgFAhHAfAaXNK2B8A2BZOHKLAfQAeP2AdPAeQAfLKHOZ2B8A2B2GAiAjKAaMAbJ2VJAbMAaKAjAi2G2B4A4-2B3-AiHXIGJ2UJGIXHAi3-2B4-AC3AB3-GONIRS2TSRINOG3-B3ACA2-F2AB3-GZKYLG2WGLYKZG3-B2AD4-F2A22B2AD4-F5A16B5AD4-F5A-14A-5AD2-ACA4EA-14A-A4EAC3AC4-C-14A-C4-C2A-2A4-A-14A-A4-2A-3A4-A-14A-A4-5AC4-C-14A-C4-C3ACA4BA-14A-A4BACA2-F5A-14A-5AD4-F5A2B12A2B5AD4-F2A5B12A5B2AD4-F2AB3-Z12AZ3-B2AD2-AC3AB3-O12AO3-B3ACA4-2B3-H12AH3-2B4-4A2BZOHK12AKHOZ2B392A2BZOHK12AKHOZ2B4A4-2B3-H12AH3-2B4-AC3AB3-O12AO3-B3ACA2-F2AB3-Z12AZ3-B2AD4-F2A5B12A5B2AD4-F5A2B12A2B5AD4-F5A-14A-5AD2-ACA4EA-14A-A4EAC3AC4-C-14A-C4-C5A4-A-14A-A4-3A-2A4-A-2A10-2A-A4-2A-2AC4-C-2A10-2A-C4-C3ACA4BA-2A10-2A-A4BACA2-F5A-2A10-2A-5AD4-F5A2BA10-A2B5AD4-F2A5BA10-A5B2AD4-F2AB3-KA10-AK3-B2AD2-AC3AB3-NA10-AN3-B3ACA4-2B3-XA10-AX3-2B4-4A2BKNXAaA10-AAaXNK2B15A10-11A320-11A10-15A2BKNXAaA10-AAaXNK2B4A4-2B3-XA10-AX3-2B4-AC3AB3-NA10-AN3-B3ACA2-F2AB3-KA10-AK3-B2AD4-F2A5BA10-A5B2AD4-F5A2BA10-A2B5AD4-F5A-2A10-2A-5AD2-ACA4EA-2A10-2A-A4EAC3AC4-C-2A10-2A-C4-C2A-2A4-A-2A10-2A-A4-2A-3A4-A-2A10-2A-A4-5AC4-C-2A-8B-2A-C4-C3ACA4BA-2A-8A-2A-A4BACA2-F5A-2A-8A-2A-5AD4-F5A2BA-8A-A2B5AD4-F2A5BA-8A-A5B2AD4-F2AB3-YA-8A-AY3-B2AD2-AC3AB3-IA-8A-AI3-B3ACA4-2B3-IA-8A-AI3-2B4-4A2BY2IMA-8A-AM2IY2B15A-8A-11A12-8A13-7(B28AB2-)B28AB13-8A12-11A-8A-15A2BY2IMA-8A-AM2IY2B4A4-2B3-IA-8A-AI3-2B4-AC3AB3-IA-8A-AI3-B3ACA2-F2AB3-YA-8A-AY3-B2AD4-F2A5BA-8A-A5B2AD4-F5A2BA-8A-A2B5AD4-F5A-2A-8A-2A-5AD2-ACA4EA-2A-8A-2A-A4EAC3AC4-C-2A-8E-2A-C4-C5A4-A-2A10-2A-A4-6A4-A-2A2-6A2-2A-A4-5AC4-C-2A-B6AB-2A-C4-C3ACA4BA-2A-8A-2A-A4BACA2-F5A-2A-8A-2A-5AD4-F5A2BA-8A-A2B5AD4-F2A5BA-8A-A5B2AD4-F2AB3-LA-8A-AL3-B2AD2-AC3AB3-RA-8A-AR3-B3ACA4-2B3-GA-8A-AG3-2B4-4A2BLRGAbA-8A-AAbGRL2B15A-8A-11A12-8A13-B28AB-192A-B28AB13-8A12-11A-8A-15A2BLRGAbA-8A-AAbGRL2B4A4-2B3-GA-8A-AG3-2B4-AC3AB3-RA-8A-AR3-B3ACA2-F2AB3-LA-8A-AL3-B2AD4-F2A5BA-8A-A5B2AD4-F5A2BA-8A-A2B5AD4-F5A-2A-8A-2A-5AD2-ACA4EA-2A-8A-2A-A4EAC3AC4-C-2A-E6AE-2A-C4-C5A4-A-2A2-6A2-2A-A4-4A-A4-A-2A2-A4-A2-2A-A4-A-A2-C4-C-2A-BA4CAB-2A-C4-C2-ACA4BA2(-2A)4C2(2A-)A4BACA2-F5A2(-2A)C2DC2(2A-)5AD4-F5A2BA-2A4C2A-A2B5AD4-F2A5BA-2A4C2A-A5B2AD4-F2AB3-GA-2A4C2A-AG3-B2AD2-AC3AB3-SA-2A4C2A-AS3-B3ACA4-2B3-JA-2A4C2A-AJ3-2B4-4A2BGS2JA-2A4C2A-A2JSG2B15A-2A4C2A-11A12-2A4C2A13-B28AB-14A-2A-14A-E10CA-4A-A9C2D2(2-ECD8C8A8C3D)2-E10CA-4A-A7C4D-14A-2A-14A-B28AB13-2A4C2A12-11A-2A4C2A-15A2BGS2JA-2A4C2A-A2JSG2B4A4-2B3-JA-2A4C2A-AJ3-2B4-AC3AB3-SA-2A4C2A-AS3-B3ACA2-F2AB3-GA-2A4C2A-AG3-B2AD4-F2A5BA-2A4C2A-A5B2AD4-F5A2BA-2A4C2A-A2B5AD4-F5A2(-2A)C2DC2(2A-)5AD2-ACA4EA2(-2A)4C2(2A-)A4EACA2-C4-C-2A-EA4CAE-2A-C4-C2-A-A4-A-2A2-A4-A2-2A-A4-A-4A4-A-2A2-A4-A2-2A-A4-5AC4-C-2A-BAC2-CAB-2A-C4-C3ACA4BA2(-2A)C2-C2(2A-)A4BACA2-F5A2(-2A)D2-D2(2A-)5AD4-F5A2BA-2AC2-C2A-A2B5AD4-F2A5BA-2AC2-C2A-A5B2AD4-F2AB3-WA-2AC2-C2A-AW3-B2AD2-AC3AB3-TA-2AC2-C2A-AT3-B3ACA4-2B3-UA-2AC2-C2A-AU3-2B4-4A2BWTUVA-2AC2-C2A-AVUTW2B15A-2AC2-C2A-11A12-2A4C2A13-B28AB-32A-2ED2C2E4C8A5C6D12-C8AC22-C8AC12-2ED8C8A3C8D-32A-B28AB13-2A4C2A12-11A-2AC2-C2A-15A2BWTUVA-2AC2-C2A-AVUTW2B4A4-2B3-UA-2AC2-C2A-AU3-2B4-AC3AB3-TA-2AC2-C2A-AT3-B3ACA2-F2AB3-WA-2AC2-C2A-AW3-B2AD4-F2A5BA-2AC2-C2A-A5B2AD4-F5A2BA-2AC2-C2A-A2B5AD4-F5A2(-2A)D2-D2(2A-)5AD2-ACA4EA2(-2A)C2-C2(2A-)A4EAC3AC4-C-2A-EAC2-CAE-2A-C4-C5A4-A-2A2-A4-A2-2A-A4-6A4-A-2A2-A4-A2-2A-A4-5AC4-C-2A-BAC2-CAB-2A-C4-C3ACA4BA2(-2A)C2-C2(2A-)A4BACA2-F5A2(-2A)D2-D2(2A-)5AD4-F5A2BA-2AC2-C2A-A2B5AD4-F2A5BA-2AC2-C2A-A5B2AD4-F2AB3-WA-2AC2-C2A-AW3-B2AD2-AC3AB3-TA-2AC2-C2A-AT3-B3ACA4-2B3-UA-2AC2-C2A-AU3-2B4-4A2BWTUVA-2AC2-C2A-AVUTW2B15A-2AC2-C2A-11A12-2A4C2A13-B28AB-32A-2ED2C2E4C8A5C6D12-C8AC22-C8AC12-2ED8C8A3C8D-32A-B28AB13-2A4C2A12-11A-2AC2-C2A-15A2BWTUVA-2AC2-C2A-AVUTW2B4A4-2B3-UA-2AC2-C2A-AU3-2B4-AC3AB3-TA-2AC2-C2A-AT3-B3ACA2-F2AB3-WA-2AC2-C2A-AW3-B2AD4-F2A5BA-2AC2-C2A-A5B2AD4-F5A2BA-2AC2-C2A-A2B5AD4-F5A2(-2A)D2-D2(2A-)5AD2-ACA4EA2(-2A)C2-C2(2A-)A4EAC3AC4-C-2A-EAC2-CAE-2A-C4-C5A4-A-2A2-A4-A2-2A-A4-4A-A4-A-2A2-A4-A2-2A-A4-A-A2-C4-C-2A-BA4CAB-2A-C4-C2-ACA4BA2(-2A)4C2(2A-)A4BACA2-F5A2(-2A)C2DC2(2A-)5AD4-F5A2BA-2A4C2A-A2B5AD4-F2A5BA-2A4C2A-A5B2AD4-F2AB3-GA-2A4C2A-AG3-B2AD2-AC3AB3-SA-2A4C2A-AS3-B3ACA4-2B3-JA-2A4C2A-AJ3-2B4-4A2BGS2JA-2A4C2A-A2JSG2B15A-2A4C2A-11A12-2A4C2A13-B28AB-14A-2A-14A-2E3C2E4CA-4A-A2(7C4D2-2ED2C2E4C8A)7C4D2-2E9CA-4A-A10CD-14A-2A-14A-B28AB13-2A4C2A12-11A-2A4C2A-15A2BGS2JA-2A4C2A-A2JSG2B4A4-2B3-JA-2A4C2A-AJ3-2B4-AC3AB3-SA-2A4C2A-AS3-B3ACA2-F2AB3-GA-2A4C2A-AG3-B2AD4-F2A5BA-2A4C2A-A5B2AD4-F5A2BA-2A4C2A-A2B5AD4-F5A2(-2A)C2DC2(2A-)5AD2-ACA4EA2(-2A)4C2(2A-)A4EACA2-C4-C-2A-EA4CAE-2A-C4-C2-A-A4-A-2A2-A4-A2-2A-A4-A-4A4-A-2A2-6A2-2A-A4-5AC4-C-2A-B6AB-2A-C4-C3ACA4BA-2A-8A-2A-A4BACA2-F5A-2A-8A-2A-5AD4-F5A2BA-8A-A2B5AD4-F2A5BA-8A-A5B2AD4-F2AB3-LA-8A-AL3-B2AD2-AC3AB3-RA-8A-AR3-B3ACA4-2B3-GA-8A-AG3-2B4-4A2BLRGAbA-8A-AAbGRL2B15A-8A-11A12-8A13-B28AB-192A-B28AB13-8A12-11A-8A-15A2BLRGAbA-8A-AAbGRL2B4A4-2B3-GA-8A-AG3-2B4-AC3AB3-RA-8A-AR3-B3ACA2-F2AB3-LA-8A-AL3-B2AD4-F2A5BA-8A-A5B2AD4-F5A2BA-8A-A2B5AD4-F5A-2A-8A-2A-5AD2-ACA4EA-2A-8A-2A-A4EAC3AC4-C-2A-E6AE-2A-C4-C5A4-A-2A2-6A2-2A-A4-6A4-A-2A10-2A-A4-5AC4-C-2A-8B-2A-C4-C3ACA4BA-2A-8A-2A-A4BACA2-F5A-2A-8A-2A-5AD4-F5A2BA-8A-A2B5AD4-F2A5BA-8A-A5B2AD4-F2AB3-YA-8A-AY3-B2AD2-AC3AB3-IA-8A-AI3-B3ACA4-2B3-IA-8A-AI3-2B4-4A2BY2IMA-8A-AM2IY2B15A-8A-11A12-8A13-7(B28AB2-)B28AB13-8A12-11A-8A-15A2BY2IMA-8A-AM2IY2B4A4-2B3-IA-8A-AI3-2B4-AC3AB3-IA-8A-AI3-B3ACA2-F2AB3-YA-8A-AY3-B2AD4-F2A5BA-8A-A5B2AD4-F5A2BA-8A-A2B5AD4-F5A-2A-8A-2A-5AD2-ACA4EA-2A-8A-2A-A4EAC3AC4-C-2A-8E-2A-C4-C5A4-A-2A10-2A-A4-3A-2A4-A-2A10-2A-A4-2A-2AC4-C-2A10-2A-C4-C3ACA4BA-2A10-2A-A4BACA2-F5A-2A10-2A-5AD4-F5A2BA10-A2B5AD4-F2A5BA10-A5B2AD4-F2AB3-KA10-AK3-B2AD2-AC3AB3-NA10-AN3-B3ACA4-2B3-XA10-AX3-2B4-4A2BKNXAaA10-AAaXNK2B15A10-11A320-11A10-15A2BKNXAaA10-AAaXNK2B4A4-2B3-XA10-AX3-2B4-AC3AB3-NA10-AN3-B3ACA2-F2AB3-KA10-AK3-B2AD4-F2A5BA10-A5B2AD4-F5A2BA10-A2B5AD4-F5A-2A10-2A-5AD2-ACA4EA-2A10-2A-A4EAC3AC4-C-2A10-2A-C4-C2A-2A4-A-2A10-2A-A4-2A-3A4-A-14A-A4-5AC4-C-14A-C4-C3ACA4BA-14A-A4BACA2-F5A-14A-5AD4-F5A2B12A2B5AD4-F2A5B12A5B2AD4-F2AB3-Z12AZ3-B2AD2-AC3AB3-O12AO3-B3ACA4-2B3-H12AH3-2B4-4A2BZOHK12AKHOZ2B392A2BZOHK12AKHOZ2B4A4-2B3-H12AH3-2B4-AC3AB3-O12AO3-B3ACA2-F2AB3-Z12AZ3-B2AD4-F2A5B12A5B2AD4-F5A2B12A2B5AD4-F5A-14A-5AD2-ACA4EA-14A-A4EAC3AC4-C-14A-C4-C5A4-A-14A-A4-3A-2A4-A-14A-A4-2A-2AC4-C-14A-C4-C3ACA4BA-14A-A4BACA2-F5A-14A-5AD4-F5A16B5AD4-F2A22B2AD4-F2AB3-GZKYLG2WGLYKZG3-B2AD2-AC3AB3-GONIRS2TSRINOG3-B3ACA4-2B3-AiHXIGJ2UJGIXHAi3-2B4-4A2B2GAiAjKAaMAbJ2VJAbMAaKAjAi2G2B8A2BZOHKLAfQAeP2AdPAeQAfLKHOZ2B8A2BKNXAaAfHAhFAg2LAgFAhHAfAaXNK2B8A2BY2IMQAhAkMAc2HAcMAkAhQM2IY2B8A2BLRGAbAeFMVH2QHVMFAeAbGRL2B8A2BGS2JPAgAcHA2PAHAcAgP2JSG2(2B8A2BWTUVAdLHQP2JPQHLAdVUTW)2B8A2BGS2JPAgAcHA2PAHAcAgP2JSG2B8A2BLRGAbAeFMVH2QHVMFAeAbGRL2B8A2BY2IMQAhAkMAc2HAcMAkAhQM2IY2B8A2BKNXAaAfHAhFAg2LAgFAhHAfAaXNK2B8A2BZOHKLAfQAeP2AdPAeQAfLKHOZ2B8A2B2GAiAjKAaMAbJ2VJAbMAaKAjAi2G2B4A4-2B3-AiHXIGJ2UJGIXHAi3-2B4-AC3AB3-GONIRS2TSRINOG3-B3ACA2-F2AB3-GZKYLG2WGLYKZG3-B2AD4-F2A22B2AD4-F5A16B5AD4-F5A-14A-5AD2-ACA4EA-14A-A4EAC3AC4-C-14A-C4-C2A-2A4-A-14A-A4-2A-3A4-A16-A4-5AC4-C16-C4-C3ACA4BA16-A4BACA2-F5A16-5AD4-F5A16B5AD4-F2A22B2AD4-F2AB20-B2AD2-AC3AB20-B3ACA4-15(2B20-2B8-)2B20-2B4-AC3AB20-B3ACA2-F2AB20-B2AD4-F2A22B2AD4-F5A16B5AD4-F5A16-5AD2-ACA4EA16-A4EAC3AC4-C16-C4-C5A4-A16-A4-3A-2A4-18A4-2A-2AC4-18C4-C3ACA4B18A4BACA2-2(F26AD4-)F5A16B5AD4-F3A2B16-2B3AD2-AC4A2B16-2B4A16(C2AC3AB20-B3A)C2AC4A2B16-2B4ACA2-F3A2B16-2B3AD4-F5A16B5A2(D4-F26A)D2-ACA4E18A4EAC3AC4-18C4-C2A-2A4-18A4-2A-7A18-10A4C18-4C10A18B8A2(C28AC2A)C6A16B6AC2AC5AB16-B5ACA2-F3A2B16-2B3A16(D4-F2AB20-B2A)D4-F3A2B16-2B3AD2-AC5AB16-B5AC2AC6A16B6A2(C2AC28A)C8A18E10A4C18-4C10A18-7A2(-A)-2A18-2A2(-A)-2A2(-A)C18-C2(A-)2A3-A-2A18B2A-A3-4A-22A-4A5-22A5-8A16B9AC5AB16-B5ACA2-F3A2B16-2B3A16(D4-F2AB20-B2A)D4-F3A2B16-2B3AD2-AC5AB16-B5AC9A16B8A5-22A5-4A-22A-4A3-A-2A18E2A-A3-2A2(-A)C18-C2(A-)2A2(-A)-2A18-2A2(-A)-4A2-A18-A2-8A2-C18-C2-8A2-A18BA2-8A2-20A2-4A6-20A12-2A16B2A6-AC5AB16-B5ACA2-F3A2B16-2B3A16(D4-F2AB20-B2A)D4-F3A2B16-2B3AD2-AC5AB16-B5ACA6-2A16B2A12-20A6-4A2-20A2-8A2-A18EA2-8A2-C18-C2-8A2-A18-A2-4A-6A18-6A-6AC18-C13A18B79A16B9AC5AB16-B5ACA2-F3A2B16-2B3A16(D4-F2AB20-B2A)D4-F3A2B16-2B3AD2-AC5AB16-B5AC9A16B79A18E13AC18-C6A-6A18-6A3-3A-20A-3A4-3A-A18CA-3A2-5A2(-20A-10A)-20A-5A6-2A16B2A6-7AB16-B8AC4A2B16-2B4A16(C2AC3AB20-B3A)C2AC4A2B16-2B4AC8AB16-B7A6-2A16B2A6-5A2(-20A-10A)-20A-5A2-3A-A18CA-3A4-3A-20A-3A5-2(11A-2A-11A6-)11A-2A-11A3-14A-2A-28A-2A-22A16B15AB16-B13A2B16-2B11A5(B20-B10A)2(B20-B5A5-B20-B5-5AB20-B10A)4(B20-B10A)B20-B11A2B16-2B13AB16-B15A16B22A-2A-28A-2A-14A3-2(11A-2A-11A6-)11A-2A-11A7-3(4(A-)8A4(-A)8-)4(A-)8A4(-A)4-5A3(-A)-8A3(-A)-5A6-3(A-)8A3(-A)6-7A18-7A2(32-6A20-6A)32-6A7(20-12A)2(20-6A32-6A)20-6A32-7A18-7A6-3(A-)8A3(-A)6-5A3(-A)-8A3(-A)-5A4-3(4(A-)8A4(-A)8-)4(A-)8A4(-A)4-
