model
size = 29 24 31, scale = 0.05, origin = -y
material 
  colors = A:#FF3 B:#1AAB9B C:#EEE D:#FC3 E:#F9C F:#F09 G:#FF6 H:#FF9 I:#FCC J:#F9F K:#CF9 L:#F96 M:#FC6 N:#FF0 O:#F6C P:#F99 Q:#F06 R:#FFF S:#F0F T:#CCC U:#CC0 V:#F60 W:#CC9 X:#F69 Y:#F63 Z:#CC3 Aa:#F6F Ab:#FC0 Ac:#F90 Ad:#F3C Ae:#F33 Af:#FCF Ag:#CFC Ah:#FC9 Ai:#CC6 Aj:#F66 Ak:#FFC Al:#F00 Am:#CF6 An:#F36 Ao:#F0C Ap:#F93 Aq:#CF0 Ar:#CF3 As:#CFF At:#F3F Au:#F30 Av:#CCF Aw:#F03 Ax:#F39
voxels
- B B - - - - - - - - - - - - - - - - - - - - - - - - B B   - AhQ - - - - - - - - - - - - - - - - - - - - - - - D U -   - - Q G - - - - - - - - - - - - - - - - - - - AtApAmE Ab-   - - ArY R AkP - - - - - - - - - - - - - - O N AtAq- - - -   - - - - N Q U AoAn- - - - - - - - - - Z AgH H - - - - - -   - - - - - - - AmR D AhY AqG O AmR I S AfR J - - - - - - -   - - - - - - - - - - - - - - - - - - - - - - - - - - - - -   - - - - - - - - - - - - - - - - - - - - - - - - - - - - -   - - - - - - - - - - - - - - - - - - - - - - - - - - - - -   - - - - - - - - - - - - - - - - - - - - - - - - - - - - -   - - - - - - - - - - - - - - - - - - - - - - - - - - - - -   - - - - - - - - - - - - - - - - - - - - - - - - - - - - -   - - - - - - - - - - - - - - - - - - - - - - - - - - - - -   - - - - - - - - - - - - - - - - - - - - - - - - - - - - -   - - - - - - - - - - - - - - - - - - - - - - - - - - - - -   - - - - - - - - - - - - - - - - - - - - - - - - - - - - -   - - - - - - - - - - - - - - - - - - - - - - - - - - - - -   - - - - - - - - - - - - - - - - - - - - - - - - - - - - -   - - - - - - - - - - - - - - - - - - - - - - - - - - - - -   - - - - - - - - - - - - - - - - - - - - - - - - - - - - -   - - - - - - - - - - - - - - - - - - - - - - - - - - - - -   - - - - - - - - - - - - - - - - - - - - - - - - - - - - -   - - - - - - - - - - - - - - - - - - - - - - - - - - - - -   - - - - - - - - - - - - - - - - - - - - - - - - - - - - -   
- B Ae- - - - - - - - - - - - - - - - - - - - - - - - F B   - A As- - - - - - - - - - - - - - - - - - - - - - - N M -   - - T Ac- - - - - - - - - - - - - - - - - - - N AhAtAbQ -   - - ApAdAgArR - - - - - - - - - - - - - - AqAaArG - - - -   - - - - I A J AjS - - - - - - - - - - AhAhI Ak- - - - - -   - - - - - - - Z AjN AnR AcAvV D R AxX AxAhQ - - - - - - -   - - - - - - - - - - - - - - - - - - - - - - - - - - - - -   - - - - - - - - - - - - - - - - - - - - - - - - - - - - -   - - - - - - - - - - - - - - - - - - - - - - - - - - - - -   - - - - - - - - - - - - - - - - - - - - - - - - - - - - -   - - - - - - - - - - - - - - - - - - - - - - - - - - - - -   - - - - - - - - - - - - - - - - - - - - - - - - - - - - -   - - - - - - - - - - - - - - - - - - - - - - - - - - - - -   - - - - - - - - - - - - - - - - - - - - - - - - - - - - -   - - - - - - - - - - - - - - - - - - - - - - - - - - - - -   - - - - - - - - - - - - - - - - - - - - - - - - - - - - -   - - - - - - - - - - - - - - - - - - - - - - - - - - - - -   - - - - - - - - - - - - - - - - - - - - - - - - - - - - -   - - - - - - - - - - - - - - - - - - - - - - - - - - - - -   - - - - - - - - - - - - - - - - - - - - - - - - - - - - -   - - - - - - - - - - - - - - - - - - - - - - - - - - - - -   - - - - - - - - - - - - - - - - - - - - - - - - - - - - -   - - - - - - - - - - - - - - - - - - - - - - - - - - - - -   - - - - - - - - - - - - - - - - - - - - - - - - - - - - -   
- B E - - - - - - - - - - - - - - - - - - - - - - - - AkB   - AbAi- - - - - - - - - - - - - - - - - - - - - - - E As-   - - S Au- - - - - - - - - - - - - - - - - - - AnD ApJ Ab-   - - AaM I AnAf- - - - - - - - - - - - - - I V N K - - - -   - - - - Z AtAcF Av- - - - - - - - - - AeAiQ T - - - - - -   - - - - - - - O L ArM ApAuF A U AvAbAkAvN W - - - - - - -   - - - - - - - - - - - - - - - - - - - - - - - - - - - - -   - - - - - - - - - - - - - - - - - - - - - - - - - - - - -   - - - - - - - - - - - - - - - - - - - - - - - - - - - - -   - - - - - - - - - - - - - - - - - - - - - - - - - - - - -   - - - - - - - - - - - - - - - - - - - - - - - - - - - - -   - - - - - - - - - - - - - - - - - - - - - - - - - - - - -   - - - - - - - - - - - - - - - - - - - - - - - - - - - - -   - - - - - - - - - - - - - - - - - - - - - - - - - - - - -   - - - - - - - - - - - - - - - - - - - - - - - - - - - - -   - - - - - - - - - - - - - - - - - - - - - - - - - - - - -   - - - - - - - - - - - - - - - - - - - - - - - - - - - - -   - - - - - - - - - - - - - - - - - - - - - - - - - - - - -   - - - - - - - - - - - - - - - - - - - - - - - - - - - - -   - - - - - - - - - - - - - - - - - - - - - - - - - - - - -   - - - - - - - - - - - - - - - - - - - - - - - - - - - - -   - - - - - - - - - - - - - - - - - - - - - - - - - - - - -   - - - - - - - - - - - - - - - - - - - - - - - - - - - - -   - - - - - - - - - - - - - - - - - - - - - - - - - - - - -   
- B A - - - - - - - - - - - - - - - - - - - - - - - - R B   - AlAd- - - - - - - - - - - - - - - - - - - - - - - AuJ -   - - AwS - - - - - - - - - - - - - - - - - - - AdAnL M U -   - - D L AfU Aw- - - - - - - - - - - - - - S K H Ab- - - -   - - - - A AfH K Ag- - - - - - - - - - AoQ AjT - - - - - -   - - - - - - - AiX P AoAmH AuP I G AvA AxQ Z - - - - - - -   - - - - - - - - - - - - - - - - - - - - - - - - - - - - -   - - - - - - - - - - - - - - - - - - - - - - - - - - - - -   - - - - - - - - - - - - - - - - - - - - - - - - - - - - -   - - - - - - - - - - - - - - - - - - - - - - - - - - - - -   - - - - - - - - - - - - - - - - - - - - - - - - - - - - -   - - - - - - - - - - - - - - - - - - - - - - - - - - - - -   - - - - - - - - - - - - - - - - - - - - - - - - - - - - -   - - - - - - - - - - - - - - - - - - - - - - - - - - - - -   - - - - - - - - - - - - - - - - - - - - - - - - - - - - -   - - - - - - - - - - - - - - - - - - - - - - - - - - - - -   - - - - - - - - - - - - - - - - - - - - - - - - - - - - -   - - - - - - - - - - - - - - - - - - - - - - - - - - - - -   - - - - - - - - - - - - - - - - - - - - - - - - - - - - -   - - - - - - - - - - - - - - - - - - - - - - - - - - - - -   - - - - - - - - - - - - - - - - - - - - - - - - - - - - -   - - - - - - - - - - - - - - - - - - - - - - - - - - - - -   - - - - - - - - - - - - - - - - - - - - - - - - - - - - -   - - - - - - - - - - - - - - - - - - - - - - - - - - - - -   
- B Ao- - - - - - - - - - - - - - - - - - - - - - - - U B   - AdA - - - - - - - - - - - - - - - - - - - - - - - AtAp-   - - AfV - - - - - - - - - - - - - - - - - - - AwAfAnAvD -   - - P K T AlR - - - - - - - - - - - - - - AoAtAqAk- - - -   - - - - AeAaAxH K - - - - - - - - - - AnAlAcG - - - - - -   - - - - - - - AqAeAcO G E H AaR F AxP Y AaF - - - - - - -   - - - - - - - - - - - - - - - - - - - - - - - - - - - - -   - - - - - - - - - - - - - - - - - - - - - - - - - - - - -   - - - - - - - - - - - - - - - - - - - - - - - - - - - - -   - - - - - - - - - - - - - - - - - - - - - - - - - - - - -   - - - - - - - - - - - - - - - - - - - - - - - - - - - - -   - - - - - - - - - - - - - - - - - - - - - - - - - - - - -   - - - - - - - - - - - - - - - - - - - - - - - - - - - - -   - - - - - - - - - - - - - - - - - - - - - - - - - - - - -   - - - - - - - - - - - - - - - - - - - - - - - - - - - - -   - - - - - - - - - - - - - - - - - - - - - - - - - - - - -   - - - - - - - - - - - - - - - - - - - - - - - - - - - - -   - - - - - - - - - - - - - - - - - - - - - - - - - - - - -   - - - - - - - - - - - - - - - - - - - - - - - - - - - - -   - - - - - - - - - - - - - - - - - - - - - - - - - - - - -   - - - - - - - - - - - - - - - - - - - - - - - - - - - - -   - - - - - - - - - - - - - - - - - - - - - - - - - - - - -   - - - - - - - - - - - - - - - - - - - - - - - - - - - - -   - - - - - - - - - - - - - - - - - - - - - - - - - - - - -   
- B X - - - - - - - - - - - - - - - - - - - - - - - - AvB   - AdW - - - - - - - - - - - - - - - - - - - - - - - AjAo-   - - L L - - - - - - - - - - - - - - - - - - - AiAvG V Am-   - - K P AsP An- - - - - - - - - - - - - - H W N G - - - -   - - - - AbU AtD M - - - - - - - - - - D S W Aq- - - - - -   - - - - - - - AcQ M AtS AfE AnN R Y AaO X D - - - - - - -   - - - - - - - - - - - - - - - - - - - - - - - - - - - - -   - - - - - - - - - - - - - - - - - - - - - - - - - - - - -   - - - - - - - - - - - - - - - - - - - - - - - - - - - - -   - - - - - - - - - - - - - - - - - - - - - - - - - - - - -   - - - - - - - - - - - - - - - - - - - - - - - - - - - - -   - - - - - - - - - - - - - - - - - - - - - - - - - - - - -   - - - - - - - - - - - - - - - - - - - - - - - - - - - - -   - - - - - - - - - - - - - - - - - - - - - - - - - - - - -   - - - - - - - - - - - - - - - - - - - - - - - - - - - - -   - - - - - - - - - - - - - - - - - - - - - - - - - - - - -   - - - - - - - - - - - - - - - - - - - - - - - - - - - - -   - - - - - - - - - - - - - - - - - - - - - - - - - - - - -   - - - - - - - - - - - - - - - - - - - - - - - - - - - - -   - - - - - - - - - - - - - - - - - - - - - - - - - - - - -   - - - - - - - - - - - - - - - - - - - - - - - - - - - - -   - - - - - - - - - - - - - - - - - - - - - - - - - - - - -   - - - - - - - - - - - - - - - - - - - - - - - - - - - - -   - - - - - - - - - - - - - - - - - - - - - - - - - - - - -   
- B U - - - - - - - - - - - - - - - - - - - - - - - - AgB   - F Ab- - - - - - - - - - - - - - - - - - - - - - - E K -   - - AkJ - - - - - - - - - - - - - - - - - - - AlH A ArAe-   - - R O H AjA - - - - - - - - - - - - - - AbAlAbP - - - -   - - - - AqV I AgV - - - - - - - - - - E T F L - - - - - -   - - - - - - - K Z AoP R AoAfV F AaO AnO M M - - - - - - -   - - - - - - - - - - - - - - - - - - - - - - - - - - - - -   - - - - - - - - - - - - - - - - - - - - - - - - - - - - -   - - - - - - - - - - - - - - - - - - - - - - - - - - - - -   - - - - - - - - - - - - - - - - - - - - - - - - - - - - -   - - - - - - - - - - - - - - - - - - - - - - - - - - - - -   - - - - - - - - - - - - - - - - - - - - - - - - - - - - -   - - - - - - - - - - - - - - - - - - - - - - - - - - - - -   - - - - - - - - - - - - - - - - - - - - - - - - - - - - -   - - - - - - - - - - - - - - - - - - - - - - - - - - - - -   - - - - - - - - - - - - - - - - - - - - - - - - - - - - -   - - - - - - - - - - - - - - - - - - - - - - - - - - - - -   - - - - - - - - - - - - - - - - - - - - - - - - - - - - -   - - - - - - - - - - - - - - - - - - - - - - - - - - - - -   - - - - - - - - - - - - - - - - - - - - - - - - - - - - -   - - - - - - - - - - - - - - - - - - - - - - - - - - - - -   - - - - - - - - - - - - - - - - - - - - - - - - - - - - -   - - - - - - - - - - - - - - - - - - - - - - - - - - - - -   - - - - - - - - - - - - - - - - - - - - - - - - - - - - -   
- B P - - - - - - - - - - - - - - - - - - - - - - - - P B   - S Ao- - - - - - - - - - - - - - - - - - - - - - - ApAm-   - - AcZ - - - - - - - - - - - - - - - - - - - H ApV AhAl-   - - F N AhO Z - - - - - - - - - - - - - - P R J A - - - -   - - - - H Y J AoAs- - - - - - - - - - AcAbU Y - - - - - -   - - - - - - - A I O V AxApAoAuAoAsO V AeF Ab- - - - - - -   - - - - - - - - - - - - - - - - - - - - - - - - - - - - -   - - - - - - - - - - - - - - - - - - - - - - - - - - - - -   - - - - - - - - - - - - - - - - - - - - - - - - - - - - -   - - - - - - - - - - - - - - - - - - - - - - - - - - - - -   - - - - - - - - - - - - - - - - - - - - - - - - - - - - -   - - - - - - - - - - - - - - - - - - - - - - - - - - - - -   - - - - - - - - - - - - - - - - - - - - - - - - - - - - -   - - - - - - - - - - - - - - - - - - - - - - - - - - - - -   - - - - - - - - - - - - - - - - - - - - - - - - - - - - -   - - - - - - - - - - - - - - - - - - - - - - - - - - - - -   - - - - - - - - - - - - - - - - - - - - - - - - - - - - -   - - - - - - - - - - - - - - - - - - - - - - - - - - - - -   - - - - - - - - - - - - - - - - - - - - - - - - - - - - -   - - - - - - - - - - - - - - - - - - - - - - - - - - - - -   - - - - - - - - - - - - - - - - - - - - - - - - - - - - -   - - - - - - - - - - - - - - - - - - - - - - - - - - - - -   - - - - - - - - - - - - - - - - - - - - - - - - - - - - -   - - - - - - - - - - - - - - - - - - - - - - - - - - - - -   
- B Y - - - - - - - - - - - - - - - - - - - - - - - - AwB   - H Au- - - - - - - - - - - - - - - - - - - - - - - AeAq-   - - H Am- - - - - - - - - - - - - - - - - - - M S ArM Ap-   - - P E O AfAs- - - - - - - - - - - - - - AjU Q L - - - -   - - - - H U I A E - - - - - - - - - - AxQ D Al- - - - - -   - - - - - - - AfM AtD J AmApAmArAmAeAuAjG V - - - - - - -   - - - - - - - - - - - - - - - - - - - - - - - - - - - - -   - - - - - - - - - - - - - - - - - - - - - - - - - - - - -   - - - - - - - - - - - - - - - - - - - - - - - - - - - - -   - - - - - - - - - - - - - - - - - - - - - - - - - - - - -   - - - - - - - - - - - - - - - - - - - - - - - - - - - - -   - - - - - - - - - - - - - - - - - - - - - - - - - - - - -   - - - - - - - - - - - - - - - - - - - - - - - - - - - - -   - - - - - - - - - - - - - - - - - - - - - - - - - - - - -   - - - - - - - - - - - - - - - - - - - - - - - - - - - - -   - - - - - - - - - - - - - - - - - - - - - - - - - - - - -   - - - - - - - - - - - - - - - - - - - - - - - - - - - - -   - - - - - - - - - - - - - - - - - - - - - - - - - - - - -   - - - - - - - - - - - - - - - - - - - - - - - - - - - - -   - - - - - - - - - - - - - - - - - - - - - - - - - - - - -   - - - - - - - - - - - - - - - - - - - - - - - - - - - - -   - - - - - - - - - - - - - - - - - - - - - - - - - - - - -   - - - - - - - - - - - - - - - - - - - - - - - - - - - - -   - - - - - - - - - - - - - - - - - - - - - - - - - - - - -   
- B Z - - - - - - - - - - - - - - - - - - - - - - - - AkB   - AsAa- - - - - - - - - - - - - - - - - - - - - - - I R -   - - R Ai- - - - - - - - - - - - - - - - - - - AcQ AbZ Y -   - - J AeAqM F - - - - - - - - - - - - - - N AiAeW - - - -   - - - - I W O ApK - - - - - - - - - - ArQ P Ae- - - - - -   - - - - - - - AhG P W H G AmX AgAnAjAmAiW Z - - - - - - -   - - - - - - - - - - - - - - - - - - - - - - - - - - - - -   - - - - - - - - - - - - - - - - - - - - - - - - - - - - -   - - - - - - - - - - - - - - - - - - - - - - - - - - - - -   - - - - - - - - - - - - - - - - - - - - - - - - - - - - -   - - - - - - - - - - - - - - - - - - - - - - - - - - - - -   - - - - - - - - - - C - - C - C - - C - - - - - - - - - -   - - - - - - - - - - C - - C - C - - C - - - - - - - - - -   - - - - - - - - - - C - C - - - C - C - - - - - - - - - -   - - - - - - - - - - C C - - - - - C C - - - - - - - - - -   - - - - - - - - - - C - - - - - - - C - - - - - - - - - -   - - - - - - - - - - - - - - - - - - - - - - - - - - - - -   - - - - - - - - - - - - - - - - - - - - - - - - - - - - -   - - - - - - - - - - - - - - - - - - - - - - - - - - - - -   - - - - - - - - - - - - - - - - - - - - - - - - - - - - -   - - - - - - - - - - - - - - - - - - - - - - - - - - - - -   - - - - - - - - - - - - - - - - - - - - - - - - - - - - -   - - - - - - - - - - - - - - - - - - - - - - - - - - - - -   - - - - - - - - - - - - - - - - - - - - - - - - - - - - -   
- B A - - - - - - - - - - - - - - - - - - - - - - - - K B   - G Af- - - - - - - - - - - - - - - - - - - - - - - AlT -   - - U O - - - - - - - - - - - - - - - - - - - AjL F E R -   - - AfY Y AkJ - - - - - - - - - - - - - - AdY V P - - - -   - - - - S Z F AmAo- - - - - - - - - - U AjAhAu- - - - - -   - - - - - - - AlAgV AuAaS G A AgK AiX AfZ A - - - - - - -   - - - - - - - - - - - - - - - - - - - - - - - - - - - - -   - - - - - - - - - - - - B B B B B - - - - - - - - - - - -   - - - - - - - - - - - B B B B B B B - - - - - - - - - - -   - - - - - - - - - - B B B B B B B B B - - - - - - - - - -   - - - - - - - - - B B B B B B B B B B B - - - - - - - - -   - - - - - - - - B B B B B B B B B B B B B - - - - - - - -   - - - - - - - B B B B B B B B B B B B B B B - - - - - - -   - - - - - - - B B B B B B B B B B B B B B B - - - - - - -   - - - - - - - B B B B B B B B B B B B B B B - - - - - - -   - - - - - - - B B B B B B B B B B B B B B B - - - - - - -   - - - - - - - - B B B B B B B B B B B B B - - - - - - - -   - - - - - - - - - B B B B B B B B B B B - - - - - - - - -   - - - - - - - - - - B B B B B B B B B - - - - - - - - - -   - - - - - - - - - - - B B B B B B B - - - - - - - - - - -   - - - - - - - - - - - - B B B B B - - - - - - - - - - - -   - - - - - - - - - - - - - - - - - - - - - - - - - - - - -   - - - - - - - - - - - - - - - - - - - - - - - - - - - - -   - - - - - - - - - - - - - - - - - - - - - - - - - - - - -   
- B Al- - - - - - - - - - - - - - - - - - - - - - - - H B   - AdAb- - - - - - - - - - - - - - - - - - - - - - - E Ak-   - - F Ai- - - - - - - - - - - - - - - - - - - O W AdAiZ -   - - M S D F Ac- - - - - - - - - - - - - - AoAxH E - - - -   - - - - O O K AmD - - - - - - - - - - I AcAgAj- - - - - -   - - - - - - - W E D E AbR S AjAsS AfA ApF I - - - - - - -   - - - - - - - - - - - - - - - - - - - - - - - - - - - - -   - - - - - - - - - - - - - - B B - - - - - - - - - - - - -   - - - - - AqAwY AfAeI C C C C C C C W AtV AcAbAi- - - - -   - - - - N I AgAuAcAnS C C C C C C C L J T Y F N Z - - - -   - - - AjD Z X M AdN AjC C C C C C C C C ArAuM AhAaQ - - -   - - - V K N L N C C C C C C C C C C C AuG ApAeAiAmD - - -   - - - K G ArP AbC C C C C C C C C C C AtY AqAsF E Ae- - -   - - - T Y A AbV C C C C C C C C C C C AtS T T G O An- - -   - - - R S AfAlT C C C C C C C C C C C G L AvApS H N - - -   - - - AnL U U AeC C C C C C C C C C C AiAwL AqAaJ D - - -   - - - Y AwAfApM C C C C C C C C C C C F AgAlAaV P K - - -   - - - - AgAcD Q C C C C C C C C C C C G X E AdE Ao- - - -   - - - - - - - - - - - - B B B B B - - - - - - - - - - - -   - - - - - - - - - - - - - - - - - - - - - - - - - - - - -   - - - - - - - - - - - - - - - - - - - - - - - - - - - - -   - - - - - - - - - - - - - - - - - - - - - - - - - - - - -   - - - - - - - - - - - - - - - - - - - - - - - - - - - - -   - - - - - - - - - - - - - - - - - - - - - - - - - - - - -   
- B E - - - - - - - - - - - - - - - - - - - - - - - - I B   - AeM - - - - - - - - - - - - - - - - - - - - - - - T D -   - - U Aj- - - - - - - - - - - - - - - - - - - AtAtApAvE -   - - R AlAjAgN - - - - - - - - - - - - - - H AbAtU - - - -   - - - - V AxH L Au- - - - - - - - - - G H AkV - - - - - -   - - - - - - - Y ArU AvAeApH AaAaAmH AlAiAiZ - - - - - - -   - - - - - - AaAmAnApL AvAqJ AkO E W L F AoAaAe- - - - - -   - - - - - AbAdE AtD AlAoAaP Q AuO D AgG AiH M Am- - - - -   - - - - AnAkAhO A A A A A A A A A A A AkS AiL S AdS - - -   - - - G AbR A H A A A A A A A A A A A A L P AlX L AaQ - -   - - - Y AjY AmJ A A A A A A A A A A A A P AmE AuAcO P - -   - - I S AlAoAwP A A A A A A A A A A A D R W G ArAkAuAm- -   - - S L AbAgX AoA A A A A A A A A A A AcN D ApAbAbAxAl- -   - - AjAwF I W AcA A A A A A A A A A A K H O A AwAjJ L - -   - - Z AgM D L F A A A A A A A A A A A AiAqY AdH AlO Ag- -   - - AhX Q E K ArA A A A A A A A A A A AeI AuAwAkAbAgAq- -   - - G L Q ArX AwA A A A A A A A A A A AvQ M D Z F K Aa- -   - - AgP ArAsA AqP Q AaU AcK AqF AxG X AlL Y O AaAlAmV - -   - - - AbAiJ E ApZ G O ApAeG ApAdAfAkL L P AoAgAdE S - - -   - - - - - - - - - - - - - - - - - - - - - - - - - - - - -   - - - - - - - - - - - - - - - - - - - - - - - - - - - - -   - - - - - - - - - - - - - - - - - - - - - - - - - - - - -   - - - - - - - - - - - - - - - - - - - - - - - - - - - - -   - - - - - - - - - - - - - - - - - - - - - - - - - - - - -   
- B Aq- - - - - - - - - - - - - - - - - - - - - - - - AvB   - AfT - - - - - - - - - - - - - - - - - - - - - - - V L -   - - AvI - - - - - - - - - - - - - - - - - - - G S X Z Al-   - - L AtAcG Ap- - - - - - - - - - - - - - M AwE At- - - -   - - - - F AkD AsAs- - - - - - - - - - AbAgP D - - - - - -   - - - - - - - S J U AiG AwAlAxAuAxR N V X Z - - - - - - -   - - - - - - L - - - - - - - - - AjAxAhT L N Ad- - - - - -   - - - - - T K V O AcAvA AeF V AnV N AmAeP ArH T - - - - -   - - - - Z ApX E A A A A A A A A A A A A A A AiM AgAw- - -   - - - T AhAqA J A A A A A A A A A A A A A AfAoP I H L - -   - - AlAvG AaE AsA A A A A A A A A A A A A U A U D AkP Aa-   - AhE L AgAdAfI A A A A A A A A A A A H AdArAcAbE Z AbT -   - H M AlR AhAuApA A A A A A A A A A A J AcAnK S Q X ApAe-   - W U E AjA AvAqB B B B B B B B B B B P AeAtAiAaW W A M -   - D R M D AmG T A A A A A A A A A A A AoAsX AeV AsL AdQ -   - O N U V AwApAvA A A A A A A A A A A AcT AoAvE I K AwY -   - Y H R Z X A L A A A A A A A A A A A F ApAxAoJ S X D Am-   - AuAqN AfW AdAlK AcS AcAxG AuJ AiAmAmK X G AvAgQ Y AbE -   - - I H A L AwE G K AjAkJ ApH AnAoE S X W S W K W ArAeAp-   - - - AqI K D M Y AiZ AtO A P AbA O X A L AaE AeAsAwM - -   - - - - - - - - - - - - - - - - - - - - - - - - - - - - -   - - - - - - - - - - - - - - - - - - - - - - - - - - - - -   - - - - - - - - - - - - - - - - - - - - - - - - - - - - -   - - - - - - - - - - - - - - - - - - - - - - - - - - - - -   
- B Q - - - - - - - - - - - - - - - - - - - - - - - - M B   - AtAr- - - - - - - - - - - - - - - - - - - - - - - U P -   - - AiAw- - - - - - - - - - - - - - - - - - - AwN L ApU -   - - N H AmAoAg- - - - - - - - - - - - - - G S T N - - - -   - - - - AxA C C Av- - - - - - - - - - AwY Y Aa- - - - - -   - - - - - - - AmW AtAjAnJ AkAqO H D E H AoI - - - - - - -   - - - - - - AiS E F V AtU AsAaH W AcM AkAgApAi- - - - - -   - - - - - AnF X AiAdK X AlAbAdJ D K U Z I AqN Av- - - - -   - - - - V AtG AuA A A A A A A A A A A A A T AhG R V - - -   - - - U AhX S ArA A A A A A A A A A A A A AvAmApN K A - -   - - S AfAhAoAaAnA A A A A A A A A A A A A L S A H T AfAa-   - T AjAcH AxV AtA A A A A A A A A A A H E AiQ L G AcAcAk-   - R Z AdW AjE X A A A A A A A A A A A AqArF W AlAkAeK Q -   - AnAhL D V J AoA A A A A A A A A A A I AsG AsE T AsAiG -   - Y G AcO K AsAxA A A A A A A A A A A Q J S I M M T AeAk-   - AuAgAkY T I AjA A A A A A A A A A A W F AaS U P ApAvT -   - H R AtAuR ApV A A A A A A A A A A A AsO V AjR U AqAoM -   - P AjF M AnAqK G R AwL A N AiR M AgY R Q J Y Z AcG E P -   - AmD AdN Y T T ApJ D P AfH S AxQ I AoAjArO AuAhAeAnN Ab-   - - V AcAbAuAvR A U AeAbU AqAaN Q D AgD AiAgH G AsR Ah- -   - - - - - - - - - - - - - - - - - - - - - - - - - - - - -   - - - - - - - - - - - - - - - - - - - - - - - - - - - - -   - - - - - - - - - - - - - - - - - - - - - - - - - - - - -   - - - - - - - - - - - - - - - - - - - - - - - - - - - - -   
- B I - - - - - - - - - - - - - - - - - - - - - - - - H B   - AxD - - - - - - - - - - - - - - - - - - - - - - - AvW -   - - E Aa- - - - - - - - - - - - - - - - - - - V AsZ L D -   - - ArAkAcQ An- - - - - - - - - - - - - - AhAuAwAb- - - -   - - - - AdW C AtAk- - - - - - - - - - AgL AmAt- - - - - -   - - - - - - - AbAwV O AoAdT AeQ R AiAlA AwAu- - - - - - -   - - - - - - P AjH Z AdAcL M AvW AxF E AmAqH U - - - - - -   - - - - - AhAmAlAkAfH F AcP AoAsN G M AwApP ApAt- - - - -   - - - - Y G AlAbA A A A A A A A A A A A A AmD G D I - - -   - - - I AuAgL F A A A A A A A A A A A A A AlAcAiAeZ L - -   - - F AtH R AgM A A A A A A A A A A A A A L K F AnN AwAr-   AeD ArAvP AjAxQ B B B B B B B B B B B AmX AsApG AbW Q X Ar  AnAeAwAnAmD J Q B B B B B B B B B B B AwW AbA Y AkL W AoAs  N AnAqR AlV O ArA A - A A A A A A F F X L AwAdS R K AsAxJ   D N ApAxL Z AgAiA A A A A A A A - F F W K H AwL Y X I AjF   K D AhN AgAfK N A A A A A A A A A F F L X AkD AwAoA S V O   G K AxP AxA AeAhA A A A A A A A A F F K A Z AeAgAgE AjK Ad  Y G AfZ J I M AmN D Y X D J AiAh- E G AeAeJ A D AxJ V T H   S Y AkJ O AtW S H AcS W O AsN G AbO S AvM P AfV J M AfQ At  - - AsAnAgAvAqX AqK L L Y I AhAgV H AaAoQ AoP Z O Q AcY -   - - - D Y AeAtN I AiAwK AuApAmR T J V AmY AcAvAfAgY - - -   - - - - - - - - - - - - - - - - - - - - - - - - - - - - -   - - - - - - - - - - - - - - - - - - - - - - - - - - - - -   - - - - - - - - - - - - - - - - - - - - - - - - - - - - -   
- B K - - - - - - - - - - - - - - - - - - - - - - - - Q B   - AhX Ad- - - - - - - - - - - - - - - - - - - - - - ArG -   - - A H - - - - - - - - - - - - - - - - - - - I N Y AcAv-   - - E AiF E Aa- - - - - - - - - - - - - - AxAlZ P - - - -   - - - - AdArC S Ag- - - - - - - - - - AdY AfU - - - - - -   - - - - - - - AhC M Z AqAtD P P AdAhZ C C U - - - - - - -   - - - - - - AoAmB B B B B B B B B B B B B AbL - - - - - -   - - - - - AfAcS B B B B B B B B B B B B B AkK At- - - - -   - - - - V U F X A A A A A A A A A A A A A R X F H Y - - -   - - - L Z AfArAuA A A A A A A A A A A A A Y A AdW AuAn- -   - - V AgAfAcAwArA A A A A A A A A A A A A AoE AcD M R T -   AbAdK AxA AdAqAnB B B B B B B B B B B AoAnG J R L V ApAnAk  AwAwT J I L ApAtB B B B B B B B B B B AgN S P N P Z A Y T   H D R O AtAcAhX F F A F F F F F F F F I D AaAoH AbAfAdAuM   AkAeAnAgAvAkAxAoF F F F F F F F A A F D K V AcAqAlA AwH P   Z AnY K AnAtAfAxA A A A A A A A A A A E G E F I U I D P U   AeAwM O U AjAqAoA A A A A A A A A A A ArY J ArQ ApAtAeAmAb  AnAgU AuApD I AgJ M AeQ J J AxU - I J AuAdA Z M A J Y AlAk  N X R AtD V Z I AsU M ArF U AjAfAlZ O ArL I J P AfP AmI Ad  - L N AtAcZ N D I R W AiO AlV AcE N AgAnAcAtAnU U AoE At-   - - AbAjD N AfArApN AqN AdAaK AdM ArK AtAkAvAbAbAfAcO Av-   - - - - - - - - - - - - - - - - - - - - - - - - - - - - -   - - - - - - - - - - - - - - - - - - - - - - - - - - - - -   - - - - - - - - - - - - - - - - - - - - - - - - - - - - -   
- B As- - - - - - - - - - - - - - - - - - - - - - - - O B   - F T Ad- - - - - - - - - - - - - - - - - - - - - - Q H -   - - ApAc- - - - - - - - - - - - - - - - - - - ArAlF AoAm-   - - AqAeA AeAt- - - - - - - - - - - - - - AnZ AsAa- - - -   - - - - I M C AsAt- - - - - - - - - - AuH N Af- - - - - -   - - - - - - - O C AuAgAjP AuK AcN AtAgC C X - - - - - - -   - - - - - - AnAdB B B B B B B B B B B B B AuM - - - - - -   - - - - - F R H B B B B B B B B B B B B B ArP Ao- - - - -   - - - - Y AdAxAiA A A A A A A A A A A A A AnU AmAjY - - -   - - - AhAmAcN AoA A A A A A A A A A A A A AtAbAxV AmE - -   - - AjA E AeP A A A A A A A A A A A A A A X AkAjK E ArH -   Y R V AmO AsZ AfB B B B B B B B B B B B B B O AlAtAqAvW Aq  AoJ K AwH T J P B B B B B B B B B B B B B B Y AaG AaL AsAp  AgU T X J ApAnAvA A A A A A A A A A A A A A AuAkAiAdAlI Ah  I AlR W P AqAbW A A A A A A A A A A A A A A M Q F AhE S Ax  D AaAnL AoAaAjE A A A A A A A A A A A A A A N G G A M AjAf  O Y AsAnAjU K U AvAiW AbX H AeZ A M AnAoAiU J AeAgG AoZ Ak  AdAoI N AlR AeApG F D AlAoAkM J AdP AtAxN AfAnAnI AgAmAhAs  H AgApD AbN M D ApG O U AxZ W AnAwU X AjAhAcAbN D R AxG Ab  - I AqK F H W AcA S Y ApAjAaAqAbD AbAoV AmAdAjD E AjAjAg-   - - T G M AqAqK AdAaAuD V R I AjAeAkAxK S L AlK ArD V R -   - - - Y Q I I AiAwV M AcK J Z AlAnR AjT X AcAbG AsV Ah- -   - - - - B B B B B B B B B B B B B B B B B B B B B B - - -   - - - - - - - - - - - - - - - - - - - - - - - - - - - - -   
- B T - - - - - - - - - - - - - - - - - - - - - - - - AmB   - AcAeF - - - - - - - - - - - - - - - - - - - - - - X Aw-   - - M Ad- - - - - - - - - - - - - - - - - - - ArZ AqAhT -   - - Q AcAjAoD - - - - - - - - - - - - - - AsR A Ah- - - -   - - - - D AgC Q Aq- - - - - - - - - - AfR J Y - - - - - -   - - - - - - - U C AfAkP V J AeM F V G C C F - - - - - - -   - - - - - - O AlB B B B B B B B B B B B B ArAb- - - - - -   - - - - - U Y AaB B B B B B B B B B B B B AwF Q - - - - -   - - - - Z R AuAkA A A A A A A A A A A A A AqM Q I E - - -   - - - AqN N M Q A A A A A A A A A A A A A ApQ ArAtO Ab- -   - - J AaArH N G A A A A A A A A A A A A A AhQ AiAvH V Am-   J E U AdA AqAbAkB B B B B B B B B B B B B B AeAoT I M AbT   AnM AlAhAfI V T B B B B B B B B B B B B B B AsAgR S P AkAe  AbU AaA U Q T M A A A A A A A A A A A A A A T I AnAjU R M   AjR AkAmAfW AeP A A A A A A A A A A A A A A ApD Y Z AbY Q   AlN Q AwAcAsM U A A A A A A A A A A A A A A AqE AuAhAkAoY   AnZ AhAlAfW AcT AtI AsY M Z U ApW D AeM J S Z X AaL Q S Aa  Y AfAhE P D AeApF S I AmW AaAbD E AcM P O AaJ AuAkK Q AaV   AuA H M AvO AsAqAdAjApE AqR AkAcAiK W U AgO AnArQ X ArV E   - I W U W Y T AaAcZ AqO I J R K S AiAqAbK AuAbAnG A AiE -   - - D R E AuApAdAeAhT H Z U Y AiAaAeI AkAeAtAjAtAkE N J -   - - - N AiM AqAhAsG AvJ N AlAoAeO AvZ R M AtAlX T AfAh- -   - - - - B G Q M AuQ O L AnAhAlJ J AnAsQ AtAaT P AvB - - -   - - - - - - - - - - - - - - - - - - - - - - - - - - - - -   
- B S - - - - - - - - - - - - - - - - - - - - - - - - E B   - N X S - - - - - - - - - - - - - - - - - - - - - - D Ai-   - - AuAa- - - - - - - - - - - - - - - - - - - AlH AnAwW -   - - ArO ApAhF - - - - - - - - - - - - - - AgAdU W - - - -   - - - - AqAxC X I - - - - - - - - - - Y AbAxAh- - - - - -   - - - - - - - AsC D AhAfAcAnQ AcY D AwC C Aj- - - - - - -   - - - - - - AqJ B B B B B B B B B B B B B AlAn- - - - - -   - - - - - V ApF B B B B B B B B B B B B B AbAtR - - - - -   - - - - V AhAhO A A A A A A A A A A A A A F X Y W U - - -   - - - U E AhAxAdA A A A A A A A A A A A A M AoAoAsApAs- -   - - L R J H AfH A A A A A A A A A A A A A Q AxAgI D J P -   ArAaP N AsW AkAiB B B B B B B B B B B B B B AkS AgE H R Aq  AiV AbH I D AsAoB B B B B B B B B B B B B B AtAaAxJ W N I   N E AlAqApO AbA A A A A A A A A A A A A A A F O J AsD H Z   AhJ U I AqY AwAfA A A A A A A A A A A A A A AdAuO I O AqN   AmAsApQ T AuH P A A A A A A A A A A A A A A AcAtAgApY I Ar  P AuArAcF AsH W E AeAhM AuM P AtQ AlU D ArI ApAsAhAeAcAhAb  Z M AsAkAdI P AsAfM AhU AvN U X G AbAbAcAwZ D I G AnK H Al  J N J AtAcApAmI AuQ H R G AbAbAoAkF AkK AqN AcS AgN AiW U   - AbF F AeAqAlS AvY W N ApV AkAxT M R AiApArK AjR D AeD -   - - O AdAsT L AjG AmD H A T R AjM Q Y AeAhA AiZ AjK AvO -   - - - AcT AvAgZ ApE O AqAdAeY V P Q AoAvAxAfAeAhD G Ao- -   - - - - B N ApW AoAdO H AqU Y Q L AfAiArM AfK W AkB - - -   - - - - - - - - - - - - - B B - - - - - - - - - - - - - -   
- B Aj- - - - - - - - - - - - - - - - - - - - - - - - AhB   - AaAlH - - - - - - - - - - - - - - - - - - - - - - AuAh-   - - AbJ - - - - - - - - - - - - - - - - - - - R AlL K Ax-   - - F P AaAvF - - - - - - - - - - - - - - Q AhJ E - - - -   - - - - O G C T Aj- - - - - - - - - - O P Q A - - - - - -   - - - - - - - S C U I L O W AuArAaK ArC C Aw- - - - - - -   - - - - - - O AaB B B B B B B B B B B B B AgO - - - - - -   - - - - - A AdV B B B B B B B B B B B B B X AgAu- - - - -   - - - - D AfH E A A A A A A A A A A A A A L K AvF J - - -   - - - X V U AiJ A A A A A A A A A A A A A P AeG ArP W - -   - - AvW Z AfAoAsA A A A A A A A A A A A A AbM ApAwAoE Ab-   N V W L AfAcA I B B B B B B B B B B B B B B W G J K Q U L   AhAhE K A AdAfApB B B B B B B B B B B B B B AqAkO G G AbAl  AmAhAiX I L P AqA A A A A A A A A A A A A A I T AgY AkAkE   S H S A AtAcAvT A A A A A A A A A A A A A A Z M K S T R M   X W AaE AvAkW AvA A A A A A A A A A A A A A N P AeL M Y U   P AoAdAoR AhAwG AlN ArAaAlJ AfG AkE P AlX O AtAvG X G E T   AoAmH AgAjAhH AgU P AsAdL U AcY R ArU AbAoAdX L S AuAiAiR   AcAxAiI D H AkR ApZ J AhAgAlAdS Y AsAbF AxH AoAlAaArF S An  - AjAoD V W Z AjD J F A AxAaL L AoJ AkM AjAiAxE V AnG Aa-   - - A E Z D AaD AcAnO AmJ AkAcAwAgF R Q V AoAjM E AtS O -   - - - ArAfO R V K AbAdAwO Q AkAgI O Y Q K A V U J X Aa- -   - - - - B AlT AwQ J A Z AfAnX S H V W AjW AcG S AkB - - -   - - - - - - - - - - - - - B B - - - - - - - - - - - - - -   
- B Af- - - - - - - - - - - - - - - - - - - - - - - - ApB   - AjAkAs- - - - - - - - - - - - - - - - - - - - - - P D -   - - AsI - - - - - - - - - - - - - - - - - - - E D AcAjR -   - - AbS D G Q - - - - - - - - - - - - - - X R ArK - - - -   - - - - AeS C AdM - - - - - - - - - - Q W AuAn- - - - - -   - - - - - - - AmC T AqAhU AaAdAoZ M AsC C V - - - - - - -   - - - - - - O AwB B B B B B B B B B B B B K Q - - - - - -   - - - - - Z H X B B B B B B B B B B B B B T ArAv- - - - -   - - - - AmJ J W A A A A A A A A A A A A A R AiAoAcAx- - -   - - - Q AwAnP L A A A A A A A A A A A A A AnN AmAeN A - -   - - Z W X AbAoK A A A A A A A A A A A A A Y AhAxAsP AmO -   AhM N AsW AjAcX B B B B B B B B B B B B B B AxL Q F O AuW   G N ArI L AlF A B B B B B B B B B B B B B B AjAgQ M H H E   AgAbA S K AbArE A A A A A A A A A A A A A A V AxArQ J P Ai  R V AfAjX F AwAfA A A A A A A A A A A A A A AhJ AiQ P AmS   AjT U Z A M AqAuA A A A A A A A A A A A A A AhO N ArAoAlAa  S Q Y AhAqArS L N R AdAbD AuR AsZ AxAfE M AnG F Q AsI AkD   X Q S A I AsL K H N H AkV ArAxT N AjAcArW Y Y M Y I Q Q O   AuArL AmQ J AwX AqH AiR Z AnN ApArV AdAsAqAuS Q AmS W G Y   - AiAwAwW F AgA I AqAoY AfAtP AqA K L J I H L Q E AjAsAk-   - - AgX AsO X E Q I A AoA X Z AaAfT AcF Z P AwArO Z I T -   - - - W I AdL AfW Q AfAgI AoJ AdU R AkO N AmAgAiH AhS - -   - - - - B AjO E AdL AjAmAkAcAdAmZ L AuAhAwN N X P B - - -   - - - - - - - - - - - - - - - - - - - - - - - - - - - - -   
- B P - - - - - - - - - - - - - - - - - - - - - - - - AeB   - AaZ G - - - - - - - - - - - - - - - - - - - - - - AiAn-   - - J Ap- - - - - - - - - - - - - - - - - - - AcG F AnJ -   - - AnA P V Ab- - - - - - - - - - - - - - F AkAeS - - - -   - - - - AvT C AkO - - - - - - - - - - AvAuArT - - - - - -   - - - - - - - J C R N R T AdAoApAgAuJ C C A - - - - - - -   - - - - - - D F B B B B B B B B B B B B B AfAe- - - - - -   - - - - - U AeO B B B B B B B B B B B B B U M O - - - - -   - - - - AkAfAnAdA A A A A A A A A A A A A AfQ AuJ Al- - -   - - - AsR AcN H A A A A A A A A A A A A A AcY AtO AbO - -   - - AnT Y AdD AiA A A A A A A A A A A A A AdAmAtAgF AuAq-   S AfAtApAoL K AoB B B B B B B B B B B B B B AdS K X AmA Aq  X AkX AqAgAcG A B B B B B B B B B B B B B B AwAjAeW AwAmT   AuAsAoAaI AkY AfA A A A A A A A A A A A A A D Z M L X AwAv  ArAbAxAdD AtS P A A A A A A A A A A A A A A AeAhW K W X L   AnAwAjAhE F L AvA A A A A A A A A A A A A A AnG AqX L W Al  U AcW AdV AdAjAeAfAlY J AuV A U V AhR AxAuP AsG J AvAaG Av  AlK L AwE H D AnAuAaS F H K AdApT AmAxAjAvZ T AkAsL O S Ao  AaAiK D J AiV N AvAkL O P T AwD AeS N V G J ApT I AlAuAaAm  - AeX AeAsAoZ D G Q AwAdAmR D AcM X P K ApAnAqM ApE AtV -   - - A AnI A AfK ApG AgH AlAnAeK Q AuZ T A AbAaP AqM AtE -   - - - N ApAfA G A AkX AiL Y AnAiY ArJ R AdAjAdU T U G - -   - - - - B B B B B B B B B B B B B B B B B B B B B B - - -   - - - - - - - - - - - - - - - - - - - - - - - - - - - - -   
- B N - - - - - - - - - - - - - - - - - - - - - - - - T B   - AxD Ad- - - - - - - - - - - - - - - - - - - - - - AcM -   - - K L - - - - - - - - - - - - - - - - - - - AtN P AgZ -   - - G AcK V E - - - - - - - - - - - - - - AqG AvAr- - - -   - - - - X AhC I At- - - - - - - - - - AmAbI S - - - - - -   - - - - - - - R C AeJ E AkR I AlG AfAlC C E - - - - - - -   - - - - - - Q AjB B B B B B B B B B B B B M X - - - - - -   - - - - - AsY D B B B B B B B B B B B B B U W I - - - - -   - - - - AjT AmV A A A A A A A A A A A A A R L Z AtAi- - -   - - - H V ApE Z A A A A A A A A A A A A A N K N F F Ax- -   - - T AqK AqO AfA A A A A A A A A A A A A H X ArAdG J At-   Y K R I T AaH A B B B B B B B B B B B B B B S AhAkA E AgD   AuT AnQ R AdJ I B B B B B B B B B B B B B B X H AsAdAiR V   M R Y W AnAhP AtA A A A A A A A A A A A A A AuW AbAwS AjZ   N AnAuAsY A AoAvA A A A A A A A A A A A A A ArD AwD AaD Af  AbY H I AuAmAcAnA A A A A A A A A A A A A A AnO H AeO V A   AmG I AqAmY M X AmT W L AjH W T M AsA AhAlP U AgApF S Q Z   AxAiApI AlS Q AuE M L AlAlAqE ApQ AbAdAmL AoApK AhM AaG J   AjF AqZ L L Q ArO P K E AbI AiAqY AwAwS AgAcD AeAxQ V AkAn  - G T N AgAwArAnH U X M F Q S AaAmH D X AxF AcM AfQ E T -   - - AvArAxAgAiAtJ AbA U M W AaAdE AkAeAuJ ArK W AkArJ M -   - - - A J X N X P AkE R Q AsO AhO Z AnArO AwAiAqAsAiAs- -   - - - - - - - - - - - - - - - - - - - - - - - - - - - - -   - - - - - - - - - - - - - - - - - - - - - - - - - - - - -   
- B Ax- - - - - - - - - - - - - - - - - - - - - - - - ArB   - V AjAe- - - - - - - - - - - - - - - - - - - - - - T Ai-   - - V As- - - - - - - - - - - - - - - - - - - AoQ K S Ag-   - - AhT R X Ab- - - - - - - - - - - - - - W G AcW - - - -   - - - - Y L C T S - - - - - - - - - - O AoAsAg- - - - - -   - - - - - - - AeC K AaAxAvP ArN AwD AjC C A - - - - - - -   - - - - - - U M B B B B B B B B B B B B B AdT - - - - - -   - - - - - E ApQ B B B B B B B B B B B B B AwAvAf- - - - -   - - - - AlAiD Y A A A A A A A A A A A A A D L AkG J - - -   - - - AmL S AcAmA A A A A A A A A A A A A AeAlAsApAsAk- -   - - AwAlAgAaK E A A A A A A A A A A A A A AnE AbA I Z Ap-   M V H L AxO AiO B B B B B B B B B B B B B B N AoR AaAhAnAl  Q K AkAgJ AuAeH B B B B B B B B B B B B B B D AcJ R AhR U   Y T Z AxO AtAvJ A A A A A A A A A A A A A A K F U J H AxAp  AmR AaJ AgAtAoP A A A A A A A A A A A A A A G ArAlU W N D   E AnR O K G AmAoA A A A A A A A A A A A A A Y AwAaAlD P Ac  K I Y AqAbW A AsY L I AqAfS Q W AbJ W AsD S T O AkG F W D   X Q AuAaV L E I AuAwApT P AjG AsF P E AbV X ApAuZ AkO L V   A W M AdT K AfS H AgAqAvAvZ AkI M AoAiAwZ AuAqAtAaT AdK Z   - AsN AhAeX AuAjP X T L W AhT S Q AcS H AfArAaAtR M H X -   - - AbA M A AvZ AmL AvAlE G M AjQ F AaAkA AnAdG J P AiA -   - - - - - - - - - - - - - - - - - - - - - - - - - - - - -   - - - - - - - - - - - - - - - - - - - - - - - - - - - - -   - - - - - - - - - - - - - - - - - - - - - - - - - - - - -   
- B Ad- - - - - - - - - - - - - - - - - - - - - - - - Z B   - AhAwAf- - - - - - - - - - - - - - - - - - - - - - AgAh-   - - D P - - - - - - - - - - - - - - - - - - - AbJ ApD Q -   - - AeAvF D F - - - - - - - - - - - - - - X AaAkAn- - - -   - - - - ArE C AlAs- - - - - - - - - - E A L O - - - - - -   - - - - - - - W C AjD H AcF A AsArU AhC C V - - - - - - -   - - - - - - AgAqB B B B B B B B B B B B B AhR - - - - - -   - - - - - AdK I B B B B B B B B B B B B B AhAjU - - - - -   - - - - AdAhAeZ A A A A A A A A A A A A A H D AlG H - - -   - - - J AhA M N A A A A A A A A A A A A A W V AaAiJ A - -   - - AgO A AmW ArA A A A A A A A A A A A A D Z AkF P AfP -   A U R AgAmAwAqA B B B B B B B B B B B B B B AnApU N ApAaT   E AlAjK AwX I AfB B B B B B B B B B B B B B Y AqApAhD V Av  AfAaD AeX W Z U A A A A A A A A A A A A A A AuT D AmAcE L   AuAkV M W L N AfA A A A A A A A A A A A A A H AvAcS K J Al  AvQ Z W L K ArAcA A A A A A A A A A A A A A P L K X AiAsE   AmAaAvAwAwI Q AvAiD Y AxF R AkG J D Q J AuU W A I AgH AuAo  AwO W AqAgApW L S K AuAjAdJ R AgAnAeG P H AlAsAfAtK J AvA   X AuE ApX AqAsAlAaG M V AcU Y R AbAnAkAoP AaI U AvAeP G Af  - AtAiAhL T I E O Y N AhAeAlAoAjAjN T AcAmAkS AfAnM AoAp-   - - S AxP AvS M AuS AbAhAsAaAgD AlD M F AlQ AjAcR W AcA -   - - - - - - - - - - - - - - - - - - - - - - - - - - - - -   - - - - - - - - - - - - - - - - - - - - - - - - - - - - -   - - - - - - - - - - - - - - - - - - - - - - - - - - - - -   
- B Y - - - - - - - - - - - - - - - - - - - - - - - - AwB   - AuS At- - - - - - - - - - - - - - - - - - - - - - S X -   - - L X - - - - - - - - - - - - - - - - - - - T M Z AqW -   - - AwAoP X Am- - - - - - - - - - - - - - Y AoM P - - - -   - - - - AmAoC AdQ - - - - - - - - - - P D S Am- - - - - -   - - - - - - - G C AvAuApAuAtI AlAsT AtC C X - - - - - - -   - - - - - - AaS B B B B B B B B B B B B B AoL - - - - - -   - - - - - U AkAaB B B B B B B B B B B B B AxAcAi- - - - -   - - - - ApAlQ V A A A A A A A A A A A A A AjAkS F T - - -   - - - AtAqAaG E A A A A A A A A A A A A A V AtAaAdAeAq- -   - - D G AaAkAkJ A A A A A A A A A A A A A K F O AcM AaD -   A P V AiAdQ T AsB B B B B B B B B B B B B B AxAcAvO AeAtAu  AdAbZ F AhG M I B B B B B B B B B B B B B B J K AoAgAnAvAr  AwAlAfG A AkP ApA A A A A A A A A A A A A A O AiAmK N AnAn  D U A S AmT U AqA A A A A A A A A A A A A A AgAeAxAeD R At  AeApI AaAwM AbT A A A A A A A A A A A A A A K AvAjM K AxX   AhS F H P Y AtF AbR AvU R AkZ L Z P AkD AjAmG N E O O AoG   H AaG AkAvAuAvM AlY W R AjAsN K J AbR AeAlAxAgD M AuH AgAi  W V S Z W M AnQ U AoE N D AbArX AnAlY AnAbAjR K U AtJ I F   - E AaAaE N R Q ApAgAiH V AwA A AbU AoN F V AjG R AtP D -   - - - - - - - - - - - - - - - - - - - - - - - - - - - - -   - - - - - - - - - - - - - - - - - - - - - - - - - - - - -   - - - - - - - - - - - - - - - - - - - - - - - - - - - - -   - - - - - - - - - - - - - - - - - - - - - - - - - - - - -   
- B Am- - - - - - - - - - - - - - - - - - - - - - - - AlB   - S AxAx- - - - - - - - - - - - - - - - - - - - - - P Aa-   - - AjAj- - - - - - - - - - - - - - - - - - - D L O AiAi-   - - L V J I Am- - - - - - - - - - - - - - G AiAcAg- - - -   - - - - U AtC T X - - - - - - - - - - AaN Y N - - - - - -   - - - - - - - AgC AiJ E AeP Z AqJ R V C C Z - - - - - - -   - - - - - - - R AmH T D AhAgAiG F AxR AqV AfF - - - - - -   - - - - - T - AjS AkAvK H K F AiO J N I E A G Av- - - - -   - - - - M R - D X Z L G W AeG F AdO H Q J I S W AmA - - -   - - - ArU An- V A A A A A A A A A A A A A AtAaE AxI K - -   - - AeAsR Y - Z A A A A A A A A A A A A A AvV AiAjAtT Af-   AmW AvJ N Au- AfB B B B B B B B B B B B B B AuM AgAkT D Ak  S E AoF H H - A B B B B B B B B B B B B B B M N K Z M AeQ   X AiAmO AqP - I A A A A A A A A A A A A A A N AbAeAaP AnG   AuS AxAdI Am- AtA A A A A A A A A A A A A A AbV M R U N Ak  ArAaAjH Q Al- AvA A A A A A A A A A A A A A V T W J AbD T   L F AjZ R Av- G Y U F W AqAiV AeApK Z P AfK L AtAjA AeA W   AgO V AaAnW - AkAmAfG D I N T AnD G N AbP X K AtZ AfAsAfE   - AdK R Y E H T E AcS O Q AhAeN AcY ArAlAvA X G AhU T P -   - - - - - - - - - - - - - - - - - - - - - - - - - - - - -   - - - - - - - - - - - - - - - - - - - - - - - - - - - - -   - - - - - - - - - - - - - - - - - - - - - - - - - - - - -   - - - - - - - - - - - - - - - - - - - - - - - - - - - - -   - - - - - - - - - - - - - - - - - - - - - - - - - - - - -   
- - - - - - - - - - - - - - - - - - - - - - - - - - - - -   - Z AlAh- - - - - - - - - - - - - - - - - - - - - - I F -   - - E Ax- - - - - - - - - - - - - - - - - - - P AqW AaAf-   - - AuAfAfG Ar- - - - - - - - - - - - - - G K AbAa- - - -   - - - - AcApC V T - - - - - - - - - - AfZ AiX - - - - - -   - - - - - - - AdC AvAnU E V H H AlAeD C C Aq- - - - - - -   - - - - - - - - - - - - - - - - - - - - - - - - - - - - -   - - - - - R L A G P L I AqAaAvO AtY T N AlQ N K - - - - -   - - - - AwY K AmAiAmAgZ T V L AgF AmAeAbE W H G Q Ar- - -   - - - T X AoX AwA A A A A A A A A A A A A AsAqY ArAnZ - -   - - ApApW AgA X A A A A A A A A A A A A A I I S AiAtN I -   F N D AqL I E AtAbG G A U AhH H K X M AjE H X AlP A ArF K   M ArAcAaK D AfL B B B B B B B B B B B B B B L L AmAfAiO X   Q A K AdX E AuK A A A A A A A A A A A A A A P AgAlU N AdA   Q AfAiAhA ArAvX A A A A A A A A A A A A A A AbAxL AfAhH E   ArU AeA E AsG A A A A A A A A A A A A A A A AlJ AgAcAmAiAf  AiH T M K F AiAgM S AjAsV J M X AtAxV K F AmAeE AfN I AxO   AoJ AeN AeG F K U AaV I E O Q AuX J T G AdAwAnJ U D D AjH   - - - - - - - - - - - - - - - - - - - - - - - - - - - - -   - - - - - - - - - - - - - - - - - - - - - - - - - - - - -   - - - - - - - - - - - - - - - - - - - - - - - - - - - - -   - - - - - - - - - - - - - - - - - - - - - - - - - - - - -   - - - - - - - - - - - - - - - - - - - - - - - - - - - - -   - - - - - - - - - - - - - - - - - - - - - - - - - - - - -   
- - - - - - - - - - - - - - - - - - - - - - - - - - - - -   - - AbF - - - - - - - - - - - - - - - - - - - - - - - - -   - - AlAr- - - - - - - - - - - - - - - - - - - D N ApAgI -   - - AnAvG E U - - - - - - - - - - - - - - J Z E Ad- - - -   - - - - AiArAfArAd- - - - - - - - - - Y N AqF - - - - - -   - - - - - - - AwL AiAtAwZ AkI AoAbAlD S AbI - - - - - - -   - - - - - - - - - - - - - - - - - - - - - - - - - - - - -   - - - - - - - - - - - - - - - - - - - - - - - - - - - - -   - - - - I P F AkAwL F Z D AjAgAcAcAdW AhS F M AtY O - - -   - - - E V O AtH AxK O AdE G E N Z T L U AiJ N S L AsV - -   - - U O E AdAvAkJ G AuAhArAkAfD AfAeK R F F H AaAcT AhL -   - - - - - - - - - - - - - - - - - - - - - - - - - - - - -   - X D J AsAiR AaAgS AtAmJ M AvG I Q A H S AdI E AtAqH X J   H AoAcP I AoAxR K L G AwF P G Y AtY E AqAaH Q J F AaW A U   W AxK AoApA N J AeAwAiX O U ApS AvAmAfI V AiW AsAdAdD E Al  D AjAiAcAqAfP U M AgF W AdAbA L AnE AuQ E AoAsI AcAhO AfAa  Y O AaJ AcAjI O AaI T AhAmArAbAsG AwM AxR AhX V AeAtAdL Ai  - - - - - - - - - - - - - - - - - - - - - - - - - - - - -   - - - - - - - - - - - - - - - - - - - - - - - - - - - - -   - - - - - - - - - - - - - - - - - - - - - - - - - - - - -   - - - - - - - - - - - - - - - - - - - - - - - - - - - - -   - - - - - - - - - - - - - - - - - - - - - - - - - - - - -   - - - - - - - - - - - - - - - - - - - - - - - - - - - - -   - - - - - - - - - - - - - - - - - - - - - - - - - - - - -   
- - - - - - - - - - - - - - - - - - - - - - - - - - - - -   - - - - - - - - - - - - - - - - - - - - - - - - - - - - -   - - - - - - - - - - - - - - - - - - - - - - - - - - - - -   - - T ApS AlH - - - - - - - - - - - - - - AfAuArU - - - -   - - - - - - - - - - - - - - - - - - - - - - - - - - - - -   - - - - - - - - - - - - - - - - - - - - - - - - - - - - -   - - - - - - - - - - - - - - - - - - - - - - - - - - - - -   - - - - - - - - - - - - - - - - - - - - - - - - - - - - -   - - - - - - - - - - - - - - - - - - - - - - - - - - - - -   - - - I H AwAhAeV Z AjK L K ArAkE F Z Q AdT AvO W AqJ - -   - - - - - - - - - - - - - - - - - - - - - - - - - - - - -   - - - - - - - - - - - - - - - - - - - - - - - - - - - - -   - - - - - - - - - - - - - - - - - - - - - - - - - - - - -   - - - - - - - - - - - - - - - - - - - - - - - - - - - - -   - - - - - - - - - - - - - - - - - - - - - - - - - - - - -   - - - - - - - - - - - - - - - - - - - - - - - - - - - - -   - - - - - - - - - - - - - - - - - - - - - - - - - - - - -   - - - - - - - - - - - - - - - - - - - - - - - - - - - - -   - - - - - - - - - - - - - - - - - - - - - - - - - - - - -   - - - - - - - - - - - - - - - - - - - - - - - - - - - - -   - - - - - - - - - - - - - - - - - - - - - - - - - - - - -   - - - - - - - - - - - - - - - - - - - - - - - - - - - - -   - - - - - - - - - - - - - - - - - - - - - - - - - - - - -   - - - - - - - - - - - - - - - - - - - - - - - - - - - - -   
