model
size = 11 4 5, scale = 0.05, origin = -y
material 
  colors = A:#444
voxels
-AAAA-AAAA- A----A----A A----A----A -AAAA-AAAA- 
----------- ----------- A---------A ----------- 
----------- ----------- A---------A ----------- 
----------- ----------- A---------A ----------- 
----------- ----------- A---------A ----------- 
