model
size = 16 31 31, scale = 0.05, origin = -y
material 
  colors = A:#000 B:#111 C:#E00 D:#700 E:#A00 F:#800 G:#B00
voxels
---------------- ---------------- ---------------- ---------------- ---------------- ---------------- ---------------- ---------------- ---------------- ---------------- ---------------- ---------------- ---------------- ---------------- ---------------- ---------------- ---------------- ---------------- -------AAAAA---- ------AAAABA---- ------AAAAAA---- -------AAAA----- ---------------- ---------------- ---------------- ---------------- ---------------- ---------------- ---------------- ---------------- ---------------- 
---------------- ---------------- ---------------- ---------------- ---------------- ---------------- ---------------- ---------------- ---------------- ---------------- ---------------- ---------------- ---------------- ---------------- ---------------- ---------------- ---------------- ---------AAAB--- ------AAAAAAA--- ------AAAAAAA--- ------AAAAAAA--- ------AAAAAAA--- ------AAAAAAA--- ------AAAAAAA--- ------AAAAAA---- ---------------- ---------------- ---------------- ---------------- ---------------- ---------------- 
---------------- ---------------- ---------------- ---------------- ---------------- ---------------- ---------------- ---------------- ---------------- ---------------- ---------------- ---------------- ---------------- ---------------- ---------------- ---------------- ---------------- --------AAAAAA-- -----AAAAAAAAA-- -----AAAAAABAA-- -----AAAAAAAAA-- -----ABAAABAAA-- -----AAAAAAAAA-- -----AAAAAAAAB-- -----AABAAABAA-- -----ABAAAAAA--- ------AAAAABA--- ---------------- ---------------- ---------------- ---------------- 
---------------- ---------------- ---------------- ---------------- ---------------- ---------------- ---------------- ---------------- ---------------- ---------------- ---------------- ---------------- ---------------- ---------------- ---------------- ---------------- ---------------- ------AAAAAAA--- -----AAAAAAAAA-- -----AAAAAAAAAA- -----AAAAAAAAAA- -----AAAAAAAAAA- -----AAAAAAAAAA- -----AAAAAAAAAA- -----AAAAAAAAA-- -----AAAAAAAAA-- -----AAAAAAAA--- ------AAAAAAA--- ---------------- ---------------- ---------------- 
---------------- ---------------- ---------------- ---------------- ---------------- ---------------- ---------------- ---------------- ---------------- ---------------- ---------------- ---------------- ---------------- ---------------- ---------------- ---------------- ---------------- -----AAAA-AAA--- -----AAAAAAAAA-- ----AAAAAAAAAAA- ----AAAAAAAAAAA- ----AAAAABAAAAA- ----AAAAAAAAAAA- -----AAAAAAAAAA- -----AAAAAAAAAA- -----AAAAAAAAAA- -----AAAAAAAAA-- -----AAAAAAAA--- -------AAAAA---- ---------------- ---------------- 
----AAAAAAA----- -----AAAAAA----- -----AAAAA------ -----AAAAAA----- -----AAABAA----- -----AAAAAA----- ------AAAAA----- ------AAAAA----- -------AAAA----- ---------------- ---------------- ---------------- ---------------- ------AAAAAAA--- -----AAAAAAAAAA- -----AAAAAAAAAA- -----AAAAAAAAAA- -----AAABAAABAA- ----AAAAAAAAAAA- ---AAAAAAAAAAAA- ---AAAAAAAAAAAA- ---AABAAA-AAAAA- ---AAAAAA-AAABA- ---AAAAAAAAAAAA- ----BAAAAAAAAAA- ----AAAAAAAAAAA- ----BAAAAAAAAAA- -----AAAABAAAA-- ------BAAAAAA--- ---------------- ---------------- 
--AAAAABAAAAA--- ---AAAAAAAAAA--- ---AAAAAAAAA---- ---AAAAAAAAAA--- ---AAAAAABBAA--- ---AAAAAAAAAA--- ----AAAAAAAAA--- ----AAAAAAAAA--- ----AAAAAAAAAAA- ----AAAAAAAAAAA- ----AAABAAAAAAA- -----AAAAAAAAAA- ----AAAAAAAAAAA- ----AABAAAAAAAA- ----AAAAAAAAAAA- ---AAAAAAABAAAA- ---AAAAAAAAAAAA- --AAAAAAAAAAAAA- ---AAAAAABAAAAAA --AAAAAAAAAAABAA --AAAAAAAAAAAAAA --AAAAAA--AAAAAA --AAABAA---AAAAA ---AAAAAA-AAAAAB ---AAAAAABAAAAAA ----BAABAAAAAAA- ----AAAAAAAAAAA- -----AAAAABAAA-- ------AAAAAAA--- --------AAA----- ---------------- 
--AAAAAAAAAAAAA- --ABAAAAAAAAAAA- --AAAAAAAAAAA--- --AAAAAAAAAAAAA- --AABAAAABAAAAA- --AAAAAAAAAAAAA- --AAAAAAAAAAAAA- ---ABAAAAAAAAAA- ---AABAAAAAAAAA- ---AAAAAAAAAAAA- ---AAAAAAAAAAAA- --BAAAAAAAAAAAA- ---AAAAAAAAAAAA- --AAAAAAAAAAAAB- --AAAAAAAAAAAAA- --AAAAAAAAAAAAAA -AAAAAAAAAAAAAAA -AAABAAAAAAAAAAA AAAAAAAAAAAAAAAA -AAAAAABAAAAAAAA -ABAAAAAAAAAAAAA -AAAAAAA--AAAAAA -AAAAAAA---AAAAA --AAAAAA---AAAAA --AAAAAAA-AAAAAA ---AAAAAAAAABAAA ----AAAAAAABAAA- ----AAAAAAABAA-- ------AAAAAAAA-- -------AAAAB---- ---------------- 
-BAAAAAAAAAAAAA- -AAAAABAAAAAAAA- -AAAAAAAAAAAAAA- -AAAAAAAAAAAAAA- -AAAAAAAAAAAAAA- -AAAAAAAAAAAAAA- --AAAAAAAABAAAA- --AAAAAAAAAAAAA- --AAAAAAAAAAAAA- --AAAAAAAAAAAAB- -CAAAAAAAAAAAAA- -AAAAAAAAAAAAAA- AAAAAAAAAAAAAAB- AAABAAAAAAAAAAAA AAAAAAAAAAAAAAAA ABAAAAAAAAAAAAAA AAAAAAAAAAABAAAA AAAAAABAAAAAAAAA AAAAAAAABAAAAAAA AAAAAAAAAAAAAAAA AAAAAAAAAAAAAAAA AAAAAAAA---AAAAA -AAAAAAA----AAAA -AAAAAAA---AAAAA --AAAAAAA-AAAAAA ---BAAAAAAAAAAAA ---AAAAAAAAAAAA- ----AAAAAAABAA-- -----AAAAAAAAA-- -------AAAAAA--- ---------------- 
AAABAAA-AAAAAAAA AAAAAAA-ABAAAAA- AAAAAAA-AAAAAAA- AAAAAAAAAAAAAAA- AAAAAAAAAAAAAAAA -AAAAAAAAAABAAA- -AAAAAAAAAAAAAAA -AAAAAAAAAAAAAAA -AAAAAAAAAAAAABA -AAAAAAAAAAAAAAA CAAAABAAAAAAAAAA CAAABAAAAAAAAAAA AAAAAAAAAAAAAAAA AAAAAAAAAABAAAAA AAAAAAAAAAAAAAAA AAAAABAAA-AAAAAA AAAAAAAA--AAAAAA AAAAAAAA---BABAA AAAAAAA----AAAAB CAAAAABA---AAABA CAABAAAA---AAAAA AAAAAAAAAA-AABAA AAAAAAAAAA-AAAAA -AAAAAAA---AAAAA --AABAAA---AAAAA --AAAAAAA-AAAAAA ---AAAAAAAAAAA-- ----AAAAAAAAAA-- -----AAAAAAAAA-- ------AAAAAAA--- -------AAAAA---- 
AAAAA-A--AAAAAAA AAAAA-A-ABAAAAAA AAAAA-A-AAAAAAB- AAAAA-A-AAAAAAAA AAAAA-AAAAAAAABA AAAAAAAAAAAAAAA- AAAAAAAAAAAAAAA- AAAAAAAAAAAAAAAA AAAAAAAAAAAAAAAA AAAAAAAAAAAAAAAA CAAAAAAAAAAABAAA CAAAAAAAAAAAAAAA CAAAAAAAAAAAAAAA AAAAAAAAAAAAAABA AAAAABAAAAAAAAAA AAABAAAAA-AAAAAA AAAAAAAA--AAABAA CAAAAAAA---AAAAA CAAAAAA----AAAAA DAAAAABA----AABA CAAAAABB----AAAA AAAAAAAAAA--AAAA AAAAAAAAAA--ABAA AAAAAAAA---AAAAA -BAAAAAA---AAAAA --AAAAAAA-AAAAAA --AAAAAAABAAAAA- ---AABAAAAAAAAA- ----AAAAAAAAAA-- -----AAAAAAAA--- -------AAAAA---- 
AAAAAA----AAAAAA AAAAAA----AAAAAA AAAAAA---AAAAAAA AAAABA---AABAAAA AAAAAB---AAAAAA- AAAAAA---AAAAAA- AAAAAAA--AAAAABA AAAAAAA--AAAAAAA AAAAAAA--AAAAAAA AAAAAAA--AAAAAAA AAAAAAA--AAAAAAA CAAAAA----AAAAAA CAAAAA-----BAAAA CAAAAA-----AAAAA AAAABA-----AAAAA CAAAAA------AAAA CAAAAA------AAAA DAAAAA------AAAA DAABA-------AAAA CAAAA-------AAAA AAAAA--------AAA AAAAAA-------AAA AAAAAA------AAAA AAAAAAA-----AAAA -AAAAAAA---AAAAA --AAAAAAA-AAAAAA --AAAAAAAAAAAAA- ---BAAAAAAAAAAA- ----AAAAAAAAAA-- ----------AAA--- -----------AA--- 
AAAAA------AAAAA BABAA-----ABAAAA AAAAA-----AAAAAA AAAAA-----AAABAA AAAAA-----AABAA- AAAAA-----AAAAA- AAAAAA----AAAAAA ABAAAA----AAAAAA AAAAAA----AAAABA AAAAAA----AAAAAA AAAAA-----AAAAAA CABAA------AAAAA EAAA-------AAAAA CAAAA-------AAAA CAAAB-------AAAA DAAAA-------AAAA DAAAA-------AAAA CAAAA--------AAA DAAA---------AAA CAAA---------AAA AABAA--------AAA AAAAA--------AAA AAAAAA------AAAA AAAAAAA-----AAAA -AAAAAAA---AAAAA --AAAAAAA-BAAAAA --AABAAAAAAAAAA- ---AAAAAAAAAAAA- ----AAAAAAABAA-- -----------AAA-- ------------A--- 
AAAAA------AAAAA AAAAA------AAAAA AAAAA-----AAAAAA AAAAA-----AAAAAA AAAAA-----AAAAA- AAAAA-----AAABAA AAAAA-----AAAAAA AAAAA------AAAAA AAAAA-------AAAB AAAAB-------AAAA CAAB--------AAAA CAAA--------AAAA CAAA--------AAAA EAAA--------AAAA CAAA---------AAA DAAA---------AAA DAAB---------AAA DABA---------AAA CABA---------AAA AAAA---------AAA AAAA---------AAA AAAAA--------AAA AABAAA------ABAA AAAAAA------AAAA -AAAAAA----BAAAA --AAAAAA---AAAAA --AAAAAAAAAAAAA- ---AAAAAAAAAAAA- ----AAAAAAABAA-- -----------AAA-- ------------A--- 
AABA-------AABAA AAAA-------AAAAA AAAA------AAAAAA AAAA------AAAAAA AAAA------AAAAA- AAAA------BAAAAA AAAA------AAABAA AAAA-------AAAAA CAAA--------AAAA CABA--------AAAA CAA----------AAA CAA----------AAA EAB----------AAA EAA----------AAA EAA----------AAA CAA----------AAA DAA----------AAA DAA----------AAA CAA----------AAA AAAA---------AAA AAAA---------AAA AAAAA-------AAAA AAAAA-------AAAA AAAAAA------AAAA -AAAAAA----AAAAA --AAAAAA---AAAAA --AAAAAAA-AAAAA- ---AAAAAAAAAAAA- ----AAA---AAAA-- -----------AAA-- ------------A--- 
ABAA-------AAAAA AAAA-------AAAAA AAAA------BAAAAA AAAA------AAAAA- AAAA------AAAAA- ABAA------AAAAAA CAAA-------AAAAA CAAB--------AAAA CAAA--------AAAA CAAA--------AAAA GAA----------AAA CAA----------AAA CAA----------AAA FAA----------AAA CAA----------AAA FAA----------AAA CAA----------AAA CAA----------AAA AAA----------AAA AAAA---------AAA AAAA---------AAA AAAAA-------AAAA AAAAA-------AAAB AAAAAA------AAAA -AAABA-----AAAAA --AAAAAA---AAAAA --AAAAAA--AAAAA- ---AAAAA--AAAAA- ----AAA---AAAA-- -----------AAA-- ------------A--- 
AAAA-------AAAAA AAAA-------AAAAA AAAA-------AAAAA AAAA-------AAAA- CAAA-------AAAA- CAAA-------AAAAA CAAA-------BAAAA CAAA--------AAAA EAAA--------AAAA EAAA--------AAAA GAAA---------AAA GAAA---------AAA CAAA---------AAA FABA---------AAA FAAB---------AAA FAAA---------BAA CAA----------ABA CAA----------AAA AAA----------AAA AAAA---------AAA AAAA---------AAA AAAAA-------AABA AAAAA-------AAAA AAAAAA------AAAA -AAAAA-----AAAAA --AAAAAA---AAAAA --AAAAAA--AAAAA- ---AAAAA--AAAAA- ----AAA---AAAA-- -----------AAA-- ------------A--- 
AAAA-------AAAAA AAAA-------AAAAA CAAA-------AAAAA CAAA-------AAAA- CAAA-------AABA- CAAA-------AAAAA CAAA-------AAAAA EAAA--------ABAA EAAA--------AAAA EAAA--------AAAA GAAA--------AAAA GAAA--------AAAA CAAA--------AAAA FAAA--------BAAA FAAA--------ABAA CAAA--------AAAA CAA---------AAAA CAA----------AAB CAA----------AAB AAAA---------AAA AAAA---------AAA AAAAA-------AAAA AAAAA-------AAAA AAAAAA------AAAA -AAAABA----AAAAA --AAAAAA---AAAAA --AAAAAAA-AAABA- ---AAAAAAAAAAAA- ----BAA---AAAA-- -----------AAA-- ------------A--- 
AAAAA------AAAA- AAAAA-----AAABAA AAAAA-----AAAAAA AAAAA-----ABAAA- AAAAA-----AAAAA- CAAAA------AAAAA CAAAA------AAAAA CBAAA------AAAAA CAAAA------AAAAA CAAAA------AAAAA EAAA-------AAAAA GAAA-------AAAAA GAAA-------AAAAA CAAA--------AAAA FAAA--------AAAA FAAA--------AAAA CAAA--------ABBA DAAA--------AAAA CAAA---------AAA AAAA---------AAA AAAA---------AAA AAAAA--------AAA AAAAAA------AAAA AAAAAA------AAAA -AAAAAA----AAAAA --AAAAAAB--AAABA --ABAAAAAAAAAAA- ---AAAAAAAAAAAA- ----AAAAAAAAAA-- -----------AAA-- ------------A--- 
AAAAB-----AAAAA- AAAAA-----AAAAAA AAAAA-----AAAAAA AAAAA-----AAAAA- AAAAA-----AAAAA- BAAAA-----AAAAAA AAAAA-----AAAAAA AAAAA-----AAAAAA AAAAA-----AAAAAA CAAAA-----AAAAAA CAAAA------AAAAA CAAAA------AAAAA CAAAA------AAAAA CAAAA-------AAAA DAAAA-------AAAA DAAAA-------ABAA CAAAA-------AAAA DAAAA-------AAAA DAAA---------AAA CAAA---------AAA AAAAA--------AAA AAABA--------AAA AAAAAA------AABA AAAAAAA-----AAAA -AAAAAAA---AABAA --BAAAAAA-AAAAAA --AAAAAAAAAAAAA- ---AAAAAAAAAAAA- ----AAAAAAAAAA-- -----------AAA-- ------------A--- 
AAAAAA----AAAAA- AAAAAA---AAAAAAA AAAABA---AAAAAAA AAAAAA---AAAAAAA AAAAAA---AAABAB- AAAAAA---AAAAAA- AAAAAA---AAAAAAA AAAABA---ABAAABA AAABAA---AAAAAAA AAAAAAA---AAAAAA AAAAAAA---AAAAAA AAAAAAA----AAAAA AAAAABA----AABAA CAAAAAA----AAAAA CAAAAA------AAAA CAAAAA------AAAA CAAAAA------AAAA CAAAAA------AAAA DAAAAA------AAAA DAAAA-------AAAA CAAAA--------AAA ABAAAA-------AAA AAAAAB------AAAA AAAAAAA-----AAAA -AAAAAAA---AAAAA --AAAAAAA-AAAAAA --AAAAAAAAAAAAA- ---AAAAAAAAAAAA- ----AAAAAAAAAA-- ----------AAA--- -----------AA--- 
AAAAAAA-AAAAAAA- AABAAAA-AAAAAAAA AAAAAAA-AAAAAAAA AAAAAAAAAAAAAAA- AAAAAAAAAAAAAAA- AAAAAAAAAAAAAAA- AAAAAAAAAAAAABA- AAAAAAAABAAAAAA- AAAAAAAAAAAAAAA- AAAAAAAAAAAAAAA- AAAAAAAAAAAAAAAA AAAAAAAAAAABAAAA AAAAAAAAABBAAAAA CAAAAAAAAAAAAAAA CAAAAAAAAAAAAAAA CAAAAAAAA-AAAAAA AAAAAAAA--AAAAAA AAAAAAAA---AAAAA EAAABAA----AAAAA CAAAAAA----AAAAA CBABAA------AAAA CAAAAAB-----AAAA AAAAAAA-----AAAA AAAAAAAA---AAABA --AAAAAA---AAAAA --AAAAAAA-AAAAAA --AAAAABAAAAAAA- ----AAAAAAAAAAA- -----AAAAAAAAA-- ------AAAAAAA--- -------AAAAA---- 
AAAAAAAAAAAAAA-- AAAAAAAAAAAAAA-- AAAAAAAAAAAAAA-- AAAAAAAAAABAAAA- AAAAAAAAAAAAAAA- AAAAAAAAAAAAAA-- AAAAAAABAAAAAA-- AAAAAAABAAAAAA-- AAAAAAAAAAAAAA-- AAAAAAAAAAAAAAA- AAAAAAAAAAAAAAA- AAAAAAABAAAAAAAA AAAAAAAAAABAAAA- AAAAAAAAAAAAAAAA CAAAAAAAAAAAAAAA AAAAAAAAAAAAAAAA AAAAAAAAAAAAAAAA AAAAAAAAAAAAAAAA AAAAAABAAAAAAAAA AAAAAAAAAAAAAAAA AABAAAAAAAAAAAAA AAAAAAAA---AABAA AAAAAAAA----AAAA -AAAAAAA---AAAAA --AAAAAAA-AAAAAA --AAAAAAAAAAAAAA --AAAAAAABAAAAA- ----AAAAAAAAAA-- -----AAAAAAAAA-- -------AAAABA--- ---------------- 
--AAAABAAAAAAA-- --AAAAAAAAAAAA-- AAABAAAAAABAA--- AAAAAAAAAAAABA-- AAAAAAAAAAAAAA-- -AAAABAAAAAAAA-- -AAAAAAAAAAAAA-- --AAAAAAAAAAAA-- --AAAAAAAAAAAA-- --AAAAAAAAAAAAA- -AAAAAAAAAAAAAA- -AAAAAAAAAAAAAA- AAAAAAAAAAAAAAA- AAAAAAAAAAABBAA- CAAAAAAAAAAAAAA- AAAAAAAABAABAAAA AAAAAAAAAAAAAAAA AAAAAAAAAAAABAAA AAAAAAAABBABAAAA AAAAAAAAAAAAAAAA AAAAAAAAAAAAAAAA AAAAAAAA--AAAAAA -AAAAAAA---AAAAA --AAAAAA---AAAAA --AAAAAAA-AAAAAA --AAAAAAAAAAAAAA ----AAAAAABAAAA- ----AAAAAAAAAA-- ------AAABAAAA-- -------AAAAA---- ---------------- 
--AAAAAAAAAAA--- ---AAAAAAAAAA--- ---AAAAAABAA---- ---AAAAAAAAAA--- ---AAAAAAAAAA--- ---ABAAAAAAAA--- ----AAAAAAAAA--- ----AABAAAAAA--- ----AAAAAAAAAA-- ----AAAAABAAAA-- ----AAAAAAAAAA-- ---AAAAAAAAAAA-- -AAAAAAAAAAAAA-- AAAAAAAAAABAAA-- AAAAAAAAAAAAAA-- AAAAAAAAAAAAAAB- AAAAAAAAAAAAAAA- -AAAAAAAAAAAAAA- -AAAAAAAAAAAAAAB -AAAAAAAAAAAAAAA -AAABAAAAAAAAAAA -AAAAAAA--AABAAA --AAAAAA---AAAAA --AAAAAAA-AAAAAA --AAAAAAAAAAAABA ----AAAAAAAAABA- ----AAAABAAAAAA- -----AAAAAAAAA-- ------AABAAAA--- --------AAA----- ---------------- 
----AAAAAAA----- -----AAAAAA----- -----AAAAA------ -----AAAAAA----- -----AAAAAA----- -----AAAAAA----- ------AAAAA----- ------AAAAA----- -------AAAB----- ---------------- ---------------- ---------------- ---------------- ------AAAAAAA--- -----AAAAAAAAA-- -----AAAAAAAAA-- -----AAAAAAAAA-- -----AAAAAAAAA-- ----AABAAAAAAAA- ---AAAAABAAAAAA- ---AAAAAAAAAAAA- ---BAAAAA-AAAAA- --AAABAAA-AAAAA- --AAAAAAAAAAAAA- ----AAAAAAAAAAA- ----AAAAAAAAAAA- ----AAAAAAAAAAA- -----AAAAAAAAA-- ------AAAAAAA--- ---------------- ---------------- 
---------------- ---------------- ---------------- ---------------- ---------------- ---------------- ---------------- ---------------- ---------------- ---------------- ---------------- ---------------- ---------------- ---------------- ---------------- ---------------- ---------------- -----AAAA-AAA--- -----AAAAAAAAA-- ----AAAAAAAAAAB- ----AAAAAAAAAAA- ----AAAAAAAAAAA- ----AAAAAAAAAAA- -----AAAAAAAAAA- -----AAAAABBAAA- -----AAAAAAAAAA- -----AAAAAAAAB-- -----AAAAABAA--- -------AAAAA---- ---------------- ---------------- 
---------------- ---------------- ---------------- ---------------- ---------------- ---------------- ---------------- ---------------- ---------------- ---------------- ---------------- ---------------- ---------------- ---------------- ---------------- ---------------- ---------------- ------AAAAAAA--- -----AAAAAAAAA-- -----AAAAAAAAAA- -----AAAAAAAAAA- -----AAAAAAAAAA- -----AAAAAAAAAA- -----AAAAAAAAAA- -----AAAAAAAAA-- -----AAAAAAAAA-- -----AAAAAAAA--- ------AAAAAAA--- ---------------- ---------------- ---------------- 
---------------- ---------------- ---------------- ---------------- ---------------- ---------------- ---------------- ---------------- ---------------- ---------------- ---------------- ---------------- ---------------- ---------------- ---------------- ---------------- ---------------- --------AAAAAA-- -----AAAAAAAAA-- -----AAAAAAAAA-- -----AAAAAAAAA-- -----AAAAAAAAA-- -----AAAAAAAAA-- -----AAAAAAAAA-- -----AABAAAAAA-- -----AAAAAAAA--- ------AAAAAAA--- ---------------- ---------------- ---------------- ---------------- 
---------------- ---------------- ---------------- ---------------- ---------------- ---------------- ---------------- ---------------- ---------------- ---------------- ---------------- ---------------- ---------------- ---------------- ---------------- ---------------- ---------------- ---------AAAA--- ------AAAAAAA--- ------AAAAAAA--- ------BAAAAAA--- ------AAAAAAA--- ------AAAAAAA--- ------AAAAAAA--- ------AAAAAA---- ---------------- ---------------- ---------------- ---------------- ---------------- ---------------- 
---------------- ---------------- ---------------- ---------------- ---------------- ---------------- ---------------- ---------------- ---------------- ---------------- ---------------- ---------------- ---------------- ---------------- ---------------- ---------------- ---------------- ---------------- -------AAAAA---- ------AAAAAA---- ------AAAAAA---- -------AAAA----- ---------------- ---------------- ---------------- ---------------- ---------------- ---------------- ---------------- ---------------- ---------------- 
