model
size = 15 32 29, scale = 0.05, origin = -y
material 
  colors = A:#100 B:#E64700 C:#DC0000 D:#E12300 E:#EB6B00
voxels
291-5A10-5A444-7A2(8-3A3-A)8-7A9-5A10-5A399-A5-A7-2A2-A3-A6-2A2-A3-A7-3(3A3-A8-)7A8-7A9-5A354-A5-A7-4(2A2-A3-A6-)2D2-A3-A6-2C2-A3-A6-A-2A4-A7-3D3-A8-7A9-5A324-A5-A7-2A2-A3-A5-2(A-A2-2(A4-))B-B2-A4-B4-A-A2-A4-D5-2A2-A3-C6-2C2-A3-C6-2A2-A3-D7-B2A3-B8-7A323-3A3-A7-2A2-A3-A5-A-A2-2(A4-)A-A2-A4-E4-B-B2-A4-B4-A-A2-2(A4-)2A4-A3-A5-C4-C2-C6-2A2-A3-A6-2B2-A3-B7-3E3-E9-5A37-2(12A3-)3B4A5B4-2(9A6-)2C4A3C6-9A6-2B4A3B6-9A8-5A9-7A8-7A54-4AC9-7A8-B2A3-B7-A-2A4-A6-5A3-A5-A-4A4-A3-A-6A4-A2-B-2(B4-)B2-A-2(A4-)A3-2A4-A3-A4-2C4-C3-C5-A4-A2-A6-2B2-A3-B6-A-2A4-A7-7A35-2A10-A2-E11-E2-B11-B2(2-2A9-2A)2-2C9-2C2-2A9-2A2-2B9-2B2-EA9-AE3-3A5-4A3-2A7-3A3-2A7-2AE2-4B4A5B2(2-13A)2-4C5-4C2-3A-2A4-3A2-4B2-A3-3B-2EA-A2-A4-AE-4A4-A3-2(2A-)2(A4-)A-E-A6-A3-E2(-B)6-B3-B2(-A)6-A3-A2-2A6-A3-A2-C-2(C4-)C3-2A4-A3-A4-2B4-B3-B5-2E2-A3-E7-7A34-2A11-A-A12-A-B12-B-D2(12-A-C)12-C-D12-A-B12-B-A12-2(A2-A11-)A-2A11-A-B12-B-D2(12-A-C)12-C2-D3-2D6-A2(2-B)2-A5-B-A3-A2-A5-2(A-A2-2(A4-))2(A-)A6-A3-A2(-B)6-B3-B2(-D)6-A3-A2(-C)6-A3-A2-2C6-C3-C2-2D6-2(A3-)2B4-B3-B5-2A2-A3-A7-3A3-A9-5A19-2A12-3(2A13-)DA13-CA13-2A13-DA13-2A13-2(3A12-)3(2A13-)DA13-CA13-3A4-2A6-D2A3-A2-A5-2A4-A2-A5-2(2A3-2(A4-))2(2A2-A6-A3-)2(A-)A6-D3-D2(-A)6-C3-C2(-A)6-A3-A2-2A6-D3-D2-A-2(A4-)A3-A-A2-A4-A5-4A3-2A8-5A19-A16(13-2A)5-2A6-2(2A4-A2-A5-)2(2A3-2(A4-))4(2A2-A6-A3-)2(A-)A6-A3-A2-A8-2(A2-)2A6-2(A3-)2A4-A3-A5-5A3-A7-A5-A9-5A4-A2(13-2A)13-AD13-AC13-2A13-AD6(13-2A)13-AD13-AC13-2A13-AD5-DA6-2(2A4-A2-A5-)2(2A3-2(A4-))2(2A2-A6-A3-)AD2-D6-A3-AC2-C6-A3-2(A-)A6-A3-A-2D8-2(A2-)2A6-2(A3-)2A4-A3-A5-2A2-A3-A7-4A-2A9-6A3-A13-2A13-AB13-BA13-DA13-2C13-CA13-DB13-BA3(13-2A)13-AB13-BA13-DA13-2C13-CA5-2A6-DB4-B2-A5-BA4-A2-A5-2(2A3-2(A4-))2A2-A6-A3-AB2-B6-B3-BA2-A6-D3-DA2-A6-C3-2(C-)C6-C3-C-2A8-2(D2-)2B6-B3-B2-A-A9-A3-3A7-A12-2A13-2A2-A13-AE13-AB13-BA13-2A13-AC13-CA13-AB13-BE2(13-2A)13-AE13-AB13-BA13-2A13-AC13-CA5-2A6-AB4-B2-A5-BE4-A2-A5-2(2A3-2(A4-))AE2-A6-A3-AB2-B6-B3-BA2-A6-A3-2A2-A6-A3-A2(-C)6-C3-C-2A8-2(A2-)B8-2(B2-)2E10-E3-2A8-A12-2A13-2A2-A13-2A13-AB13-BA13-2A13-AC13-CA13-AB13-BA3(13-2A)13-AB13-BA13-2A13-AC13-CA5-2A6-AB4-B2-A5-BA4-A2-A5-2(2A3-2(A4-))2A2-A6-A3-AB2-B6-B3-BA2-A6-A3-2A2-A6-A3-A2(-C)6-C3-C-2A8-2(A2-)B8-2(B2-)2A10-A3-2A8-A12-2A13-2A2-A13-AE13-AB13-BA13-2A13-AC13-CA13-AB13-BE2(13-2A)13-AE13-AB13-BA13-2A13-AC13-CA5-2A6-AB4-B2-A5-BE4-A2-A5-2(2A3-2(A4-))AE2-A6-A3-AB2-B6-B3-BA2-A6-A3-2A2-A6-A3-A2(-C)6-C3-C-2A8-2(A2-)B8-2(B2-)2E10-E3-2A8-A12-2A13-2A2-A13-2A13-AB13-BD2(13-AC)13-CD13-AB13-BA3(13-2A)13-AB13-BD2(13-AC)13-CD5-DA6-AB4-B2-A5-BA4-A2-A5-2(2A3-2(A4-))2A2-A6-A3-AB2-B6-B3-BD2-D6-A3-AC2-C6-A3-A2(-C)6-C3-C-2D8-2(A2-)2B10-B2-A-A9-A3-3A7-A12-2A13-2A2-A3(13-2A)13-DA13-CA13-2A13-DA6(13-2A)13-DA13-CA13-2A5-2A6-DA2(4-A2-A5-2A)2(3-2(A4-)2A)2(2-A6-A3-2A)2-A6-D3-DA2-A6-C3-C2(-A)6-A3-A-2A8-2(D2-)2A6-2(A3-)2A4-A3-A5-2A2-A3-A7-3A3-A9-6A3-A16(13-2A)5-2A6-2(2A4-A2-A5-)2(2A3-2(A4-))4(2A2-A6-A3-)2(A-)A6-A3-A2-A8-2(A2-)2A6-2(A3-)2A4-A3-A5-5A3-A7-A5-A9-5A4-2A12-2(2A13-)AD13-AC13-2A13-AD2(13-2A)13-2(3A12-)2(2A13-)AD13-AC13-2A13-A2D4-DA6-3A3-A2-A5-2A4-A2-A5-2(2A3-2(A4-))2(2A2-A6-A3-)A2(-D)6-A3-A2(-C)6-A3-2(A-)A6-A3-A2-2D6-A3-A2-A-2(A4-)A3-A-A2-A4-A5-4A3-2A8-5A20-2A11-A-A12-A-B12-B-A12-D-A12-C-C12-C-A12-D-B12-B-A12-2(A2-A11-)A-2A11-A-B12-B-A12-D-A12-C-C12-C2-A3-2A6-D2(2-B)2-A5-B-A3-A2-A5-2(A-A2-2(A4-))2(A-)A6-A3-A2(-B)6-B3-B2(-A)6-D3-D2(-A)6-C3-C2-2C6-C3-C2-2A6-2(D3-)2B4-A3-B5-2A2-A3-A7-3A3-A9-5A21-2A10-A2-E11-A2-B11-B2(2-2A8-3A)2-2C8-3C2-2A8-3A2-2B8-3B2-2A7-4A3-3A5-4A2(3-2A7-3A)2-5B3A5B2(2-13A)2-4C5-4C2-3A-2A4-3A2-4B2-A3-3B-E2A-A2-A4-2A-4A4-A3-2(2A-)2(A4-)A-E-A6-A3-A2(-B)6-B3-B2(-A)6-A3-A2-2A6-A3-A2-C-C4-A4-C3-2A4-A3-A4-2B4-A3-B5-2E2-E3-E7-7A36-2(12A3-)4B4A4B4-2(8A7-)3C4AC7-8A7-3B3A2B7-7A10-5A9-7A8-7A54-C3AC9-7A8-2BA3-B7-A-2A4-A6-5A3-A5-A-4A4-A3-A-6A4-A2-B-B4-A4-B2-A-2(A4-)A3-2A4-A3-A4-2C4-A3-C5-A4-A2-A6-2B2-A3-B6-A-2A4-A7-7A308-3A3-A7-2A6-A5-2(A-A2-2(A4-))B-B2-A4-B4-A-A2-2(A4-)2A4-A3-A5-C4-A2-C6-2A2-A3-A6-2B2-A3-B7-2EA3-E9-5A309-A5-A7-2A2-A3-A5-2(A-A2-2(A4-))B-B2-A4-B4-D-D2-A4-A5-2C2-A3-A6-2C2-A3-C6-2D2-A3-A7-2BA3-B8-7A323-A5-A7-4(2A2-A3-A6-)2A2-D3-D6-2A2-A3-C6-A-2A4-A7-3A3-D8-7A9-5A324-A5-A7-2A2-A3-A6-2A2-A3-A7-3(3A3-A8-)7A8-7A9-5A354-7A2(8-3A3-A)8-7A9-5A10-5A415-5A10-5A169-
