model
size = 14 14 7, scale = 0.05, origin = -y
material 
  colors = A:#EEE B:#100 C:#F0C
voxels
------AAAA---- -----AAA------ ----AAAA------ ----AAAAA----- -----AAAA----- ------AA------ -------------- ---------AA-AA ---------AAAA- -------------- -------------- -------------- -------------- -------------- 
-------------- -------------- ----AAAAA----- ----AAAAA----- ----AAAAA----- -----AAAAA---- -----AAAAAA--- ------AAAAA--- -------AAAA--- ---------AA--- -------------- -------------A ------------AA ------------AA 
-------------- -----AAA------ --AAAAAAA----- ----AAAAAA---- ----AAAAAAA--- ----AAAAAAA--- -----AAAAAA--- -----AAAAAA--- ------AAAAAA-- -------AAAAA-- ---------AAAA- --------AABAA- --------AAAAA- -------------- 
-------------- -AAA-AAA------ AAAACAAAA----- AA-AAAAAAA---- AA--AAAAAAA--- -A--AAAAAAA--- -A---AAAAAA--- -AA--AAAAAAA-- --A---AAAAAA-- --A----AAAAA-- -AA------AAAA- -A------AAAAA- AA-----AAAAAA- ------CAA----- 
-------------- -----AA------- --AAAAAA------ ----AAAAAA---- ----AAAAAAA--- ----AAAAAAA--- -----AAAAAA--- -----AAAAAA--- ------AAAAAA-- -------AAAAA-- ---------AAAA- --------AABAA- --------AAAAA- -------------- 
-------------- -------------- -------------- ------AAAAAA-- -----AAAAAA--- -----AAAAA-AA- ------AAA-AA-- -------AAAA--- --------AAA--- --------AA---- -------------- ------------AA -----------AAA -----------AA- 
-------------- -----------AAA ----------AA-- -------AAAAA-- -------AAAA--- --------AA---- -------------- -------------- -------------- -------------- -------------- -------------- -------------- -------------- 
