model
size = 25 31 21, scale = 0.05, origin = -y
material 
  colors = A:#F66 B:#003 C:#00C
voxels
------------------------- ------------------------- ------------------------- ------------------------- ------------------------- ------------------------- ------------------------- ------------------------- ------------------------- ------------------------- ------------------------- ------------------------- ------------------------- ------------------------- ------------------------- ------------------------- ------------------------- --------AAAACCAAA-------- --------ACCAACCAC-------- --------ACCAACCAA-------- --------ACAAACAAC-------- --------AACCCAAAA-------- --------AAAAAAAAA-------- --------AAABBBAAA-------- --------AAB---BAA-------- ------------------------- ------------------------- ------------------------- ------------------------- ------------------------- ------------------------- 
------------------------- ------------------------- ------------------------- ------------------------- ------------------------- ------------------------- ------------------------- ------------------------- ------------------------- ------------------------- ------------------------- ---------AAAAAAA--------- ---------AAAAAAA--------- ---------AAAAAAA--------- ---------ACAAAAA--------- ---------AACAAAA--------- ---------AAACAAA--------- ------AAA-------AA------- ------AA--------AA------- ------AA--------AA------- ------AA--------AA------- ------AA--------AA------- ------AAAA-----AAA------- ------AAAA-----AAA------- ------AAAB-----BAA------- ------------------------- ------------------------- ------------------------- ------------------------- ------------------------- ------------------------- 
------------------------- ------------------------- ------------------------- ------------------------- ----------CCCAA---------- ----------CCCAA---------- ----------AACAA---------- ----------AACAA---------- ----------AACAA---------- ----------AACAC---------- ----------AACCA---------- -------AAB-----BAA------- -------CC-------AC------- -------AA-------AB------- -------BA-------AA------- -------AA-------AA------- -------CA-------AA------- -----AA-----------A------ -----A------------A------ -----A------------A------ -----A------------A------ -----A------------A------ -----A------------A------ -----AAAAA-----AAAA------ -----AAAAA-----AAAA------ -----AAAAB-----BAAA------ -----AAAAB-----BAA------- ------------------------- ------------------------- ------------------------- ------------------------- 
----------BBBBB---------- ----------BBBBB---------- ----------AAAAA---------- ----------AAAAA---------- --------AA-----AA-------- --------AA-----AA-------- --------AA-----AA-------- --------AA-----AA-------- --------CA-----AA-------- --------AA-----AA-------- --------CC-----AC-------- ------AB---------BB------ ------B-----------C------ ------A-----------A------ ------C-----------C------ ------A-----------A------ ------C-----------C------ ----AA-------------A----- ----A--------------A----- ----A--------------A----- ----A--------------A----- ----A--------------A----- ----A--------------A----- ----AAAAAA-----A---A----- ----AAAAAA-----A---A----- ----AAAAAA-----A---A----- ----AAAAAA-----A--AA----- -----AAAAB-----BAAAA----- ------------------------- ------------------------- ------------------------- 
--------BB-----BB-------- --------BB-----BB-------- --------AA-----AA-------- --------AA-----AA-------- ------AA---------AA------ ------AA---------AA------ ------AA---------AA------ ------AA---------AA------ ------CC---------CC------ ------AA---------AA------ ------CC---------CC------ -----A-------------A----- -----C-------------C----- -----A-------------A----- -----C-------------C----- -----A-------------A----- -----C-------------C----- ---AA---------------A---- ---A----------------A---- ---A----------------A---- ---A----------------A---- ---A----------------A---- ---B----------------A---- ---BA----------A----A---- ---BA----------A----A---- ---BA----------A----A---- ---BA----------A----A---- ---BA----------A----A---- --BBAAAAAB-----BAAAAA---- ------------------------- ------------------------- 
-------B---------B------- -------B---------B------- -------A---------A------- -------A---------A------- ------A-----------A------ ------A-----------A------ ------A-----------A------ ------A-----------A------ ------C-----------C------ ------A-----------A------ ------C-----------C------ ----AB-------------AB---- ----B---------------C---- ----A---------------B---- ----C---------------C---- ----A---------------B---- ----C---------------C---- ---A-----------------A--- ---A-----------------A--- ---A-----------------A--- ---A-----------------A--- ---B-----------------A--- ---------------------A--- ---------------AAAAAAA--- ---------------AAAAAAA--- ---------------AAAAAAA--- ---------------AAAAAAA--- ---------------AAAAAA---- --BAAAAAAB-----BAAAAA---- ------------------------- ------------------------- 
------B-----------B------ ------B-----------B------ ------A-----------A------ ------A-----------A------ -----A-------------A----- -----A-------------A----- -----A-------------A----- -----A-------------A----- -----C-------------C----- -----A-------------A----- -----C-------------C----- ----A---------------A---- ----C---------------C---- ----A---------------A---- ----C---------------C---- ----A---------------A---- ----C---------------C---- ---A-----------------A--- ---A-----------------A--- ---A-----------------A--- ---A-----------------A--- ---B-----------------A--- ---------------------B--- ---------------------B--- ---------------------B--- ---------------------B--- ---------------------B--- ---------------------B--- ---------------------B--- -BBAAAAAAB-----BAAAAABBB- ------------------------- 
------B-----------B------ ------B-----------B------ ------A-----------A------ ------A-----------A------ -----A-------------A----- -----A-------------A----- -----A-------------A----- -----A-------------A----- -----C-------------C----- -----A-------------A----- -----C-------------C----- ---BB---------------BA--- ---C-----------------C--- ---A-----------------A--- ---C-----------------C--- ---A-----------------B--- ---C-----------------C--- --A-------------------A-- --A-------------------A-- --A-------------------A-- --A-------------------A-- --B-------------------B-- ------------------------- ------------------------- ------------------------- ------------------------- ------------------------- ------------------------- ------------------------- -BAAAAAAB-------BBAAAAAB- ------------------------- 
-----B-------------B----- -----B-------------B----- -----A-------------A----- -----A-------------A----- ----A---------------A---- ----A---------------A---- ----A---------------A---- ----A---------------A---- ----C---------------C---- ----A---------------A---- ----C---------------C---- ---A-----------------B--- ---C-----------------C--- ---A-----------------A--- ---C-----------------C--- ---A-----------------A--- ---C-----------------C--- --A-------------------A-- --A-------------------A-- --A-------------------A-- --B-------------------B-- ------------------------- ------------------------- ------------------------- ------------------------- ------------------------- ------------------------- ------------------------- ------------------------- ------------------------- BBAAAAAB---------BAAAAAAB 
-----B-------------B----- -----B-------------B----- -----A-------------A----- -----A-------------A----- ----A---------------A---- ----A---------------A---- ----A---------------A---- ----A---------------A---- ----C---------------C---- ----A---------------A---- ----C---------------C---- ---A-----------------A--- ---B-----------------C--- ---A-----------------A--- ---C-----------------C--- ---A-----------------A--- ---C-----------------C--- --A-------------------A-- --A-------------------A-- --B-------------------B-- ------------------------- ------------------------- ------------------------- ------------------------- ------------------------- ------------------------- ------------------------- ------------------------- ------------------------- ------------------------- BAAAAAB-----------BAAAAAB 
-----B-------------B----- -----B-------------B----- -----A-------------A----- -----A-------------A----- ----A---------------A---- ----A---------------A---- ----A---------------A---- ----A---------------A---- ----C---------------C---- ----A---------------A---- ----C---------------C---- ---A-----------------A--- ---C-----------------C--- ---A-----------------B--- ---C-----------------C--- ---A-----------------A--- ---C-----------------C--- --A-------------------A-- --B-------------------B-- ------------------------- ------------------------- ------------------------- ------------------------- ------------------------- ------------------------- ------------------------- ------------------------- ------------------------- ------------------------- ------------------------- BAAAAAB-----------BAAAAAB 
-----B-------------B----- -----B-------------B----- -----A-------------A----- -----A-------------A----- ----A---------------A---- ----A---------------A---- ----A---------------A---- ----A---------------A---- ----C---------------C---- ----A---------------A---- ----C---------------C---- ---A-----------------A--- ---C-----------------C--- ---A-----------------A--- ---B-----------------C--- ---A-----------------A--- ---C-----------------C--- --A-------------------A-- --A-------------------A-- --B-------------------B-- ------------------------- ------------------------- ------------------------- ------------------------- ------------------------- ------------------------- ------------------------- ------------------------- ------------------------- ------------------------- BAAAAAB-----------BAAAAAB 
-----B-------------B----- -----B-------------B----- -----A-------------A----- -----A-------------A----- ----A---------------A---- ----A---------------A---- ----A---------------A---- ----A---------------A---- ----C---------------C---- ----A---------------A---- ----C---------------C---- ---A-----------------B--- ---C-----------------C--- ---A-----------------A--- ---C-----------------C--- ---A-----------------A--- ---C-----------------C--- --A-------------------A-- --A-------------------A-- --A-------------------A-- --B-------------------B-- ------------------------- ------------------------- ------------------------- ------------------------- ------------------------- ------------------------- ------------------------- ------------------------- ------------------------- BBAAAAAB---------BAAAAAAB 
------B-----------B------ ------B-----------B------ ------A-----------A------ ------A-----------A------ -----A-------------A----- -----A-------------A----- -----A-------------A----- -----A-------------A----- -----C-------------C----- -----A-------------A----- -----C-------------C----- ---AB---------------BA--- ---C-----------------C--- ---A-----------------A--- ---C-----------------C--- ---B-----------------A--- ---C-----------------C--- --A-------------------A-- --A-------------------A-- --A-------------------A-- --A-------------------A-- --B-------------------B-- ------------------------- ------------------------- ------------------------- ------------------------- ------------------------- ------------------------- ------------------------- -BAAAAABB-------BBAAAAAB- ------------------------- 
------B-----------B------ ------B-----------B------ ------A-----------A------ ------A-----------A------ -----A-------------A----- -----A-------------A----- -----A-------------A----- -----A-------------A----- -----C-------------C----- -----A-------------A----- -----C-------------C----- ----A---------------B---- ----C---------------C---- ----A---------------A---- ----C---------------C---- ----A---------------A---- ----C---------------C---- ---A-----------------A--- ---A-----------------A--- ---A-----------------A--- ---A-----------------A--- ---B-----------------B--- ------------------------- ------------------------- ------------------------- ------------------------- ------------------------- ------------------------- ------------------------- -BBBAAAAAB-----BAAAAAABB- ------------------------- 
-------B---------B------- -------B---------B------- -------A---------A------- -------A---------A------- ------A-----------A------ ------A-----------A------ ------A-----------A------ ------A-----------A------ ------C-----------C------ ------A-----------A------ ------C-----------C------ ----AB-------------AA---- ----C---------------C---- ----A---------------B---- ----B---------------C---- ----A---------------A---- ----C---------------C---- ---A-----------------A--- ---A-----------------A--- ---A-----------------A--- ---A-----------------A--- ---A-----------------A--- ---B-----------------B--- ---B-----------------B--- ---B-----------------B--- ---B-----------------B--- ---B-----------------B--- ---B-----------------B--- ---BAAAAAB-----BAAAAAB--- ------------------------- ------------------------- 
--------BB-----BB-------- --------BB-----BB-------- --------AA-----AA-------- --------AA-----AA-------- ------AA---------AA------ ------AA---------AA------ ------AA---------AA------ ------AA---------AA------ ------CC---------AA------ ------AA---------AA------ ------CC---------AA------ -----A-------------A----- -----C-------------C----- -----A-------------A----- -----C-------------C----- -----A-------------A----- -----C-------------C----- ---AA---------------A---- ---AA---------------A---- ---AA---------------A---- ---AA---------------A---- ---AA---------------A---- ---AA---------------A---- ---AA---------------A---- ---AA---------------A---- ---AA---------------A---- ---AA---------------A---- ---AA---------------AB--- ---AAAAAAB-----BAAAAAB--- ------------------------- ------------------------- 
----------BBBBB---------- ----------BBBBB---------- ----------AAAAA---------- ----------AAAAA---------- --------AA-----AA-------- --------AA-----AA-------- --------AA-----AA-------- --------AA-----AA-------- --------CA-----CA-------- --------AA-----CA-------- --------CA-----CA-------- ------AB---------BA------ ------C-----------C------ ------A-----------A------ ------C-----------C------ ------B-----------A------ ------C-----------A------ -----AA------------A----- -----AA------------A----- -----AA------------A----- -----AA------------A----- -----AA------------A----- -----AA------------A----- -----AAAAA-----AAAAA----- -----AAAAA-----AAAAA----- -----AAAAA-----AAAAA----- -----AAAAA-----AAAAA----- ----AAAAAB-----BAAAAA---- ------------------------- ------------------------- ------------------------- 
------------------------- ------------------------- ------------------------- ------------------------- ----------AAAAA---------- ----------AAAAA---------- ----------AAAAA---------- ----------AAAAA---------- ----------AAACC---------- ----------AAACC---------- ----------AAACC---------- -------AAB-----BAA------- -------CA-------AA------- -------AA-------AA------- -------CA-------AA------- -------AA-------AA------- -------CA-------AA------- -------A----------A------ -------A----------A------ -------A----------A------ -------A----------A------ -------A----------A------ -------AB---------A------ -------AAA-----AAAA------ ------AAAA-----AAAA------ ------AAAB-----BAAAA----- ------AAAB-----BAAAA----- ------------------------- ------------------------- ------------------------- ------------------------- 
------------------------- ------------------------- ------------------------- ------------------------- ------------------------- ------------------------- ------------------------- ------------------------- ------------------------- ------------------------- ------------------------- ---------AAAACAA--------- ---------AACACAA--------- ---------AAACCAA--------- ---------ACAACAA--------- ---------AACCCAA--------- ---------AAAAAAA--------- -------AAAAAAAAAAA------- -------AAAAAAAAAAA------- -------AAAAAAAAAAA------- -------AAAAAAAAAAA------- -------AAAAAAAAAAA------- -------AAAAAAAAAAA------- -------AAAABBBAAAA------- -------AABB---BBAA------- ------------------------- ------------------------- ------------------------- ------------------------- ------------------------- ------------------------- 
------------------------- ------------------------- ------------------------- ------------------------- ------------------------- ------------------------- ------------------------- ------------------------- ------------------------- ------------------------- ------------------------- ------------------------- ------------------------- ------------------------- ------------------------- ------------------------- ------------------------- --------AAAACCCA--------- --------AAAACCCA--------- --------AAAACAAA--------- --------AACACAAA--------- --------AAACCAAA--------- --------AAAAAAAA--------- --------AAA---AA--------- --------AAB---BA--------- ------------------------- ------------------------- ------------------------- ------------------------- ------------------------- ------------------------- 
