model
size = 32 17 30, scale = 0.05, origin = -y
material 
  colors = A:#00B B:#3CC C:#222 D:#888 E:#FFC F:#E00 G:#FF3
voxels
71-2E14-2E13-3(4E12-)4E13-2E14-2E365-4C12-4C11-6C10-6C9-7(8C8-)8C9-6C10-6C11-4C12-4C300-4C12-4C11-6C10-6C9-7(8C8-)8C9-6C10-6C11-4C12-4C428-2(20A12-)20A460-2(20A12-)20A426-4(24A8-)24A392-4(24A8-)24A355-D31-D2G2-24A3-D4-24A8-24A2-2G4-24A8-24A355-D-30ADG30AD-30A2-30AG-2(30A2-)7A14B9A8-A14B2A4-3A8-A14B2(A4-4A9-A13B)A18-A11BA19-A11BA20-11A21-11A74-D-30ADG30AD-30A2-30AG-2(30A2-)2(30A8-3B12A2B4-3A8-BAB12AB4-4A9-2B12AB4-4A9-3B10A2B18-2B10AB19-B12A20-11A21-11A43-D30-2(2D30A)D-3(30AFE)30A2-)30A8-3B12A2B4-3A8-3B12AB4-4A9-2B12AB4-4A9-3B10A2B18-2B10AB19-B12A20-11A21-11A43-D30-2(2D30A)D-3(30AFE)30A2-4(30A8-3B12A2B4-3A8-3B12AB4-4A9-2B12AB4-4A9-3B10A2B18-2B10AB19-B12A20-11A21-11A43-D30-2(2D30A)D-4(30A2-))3(30A8-3B12A2B4-3A8-3B12AB4-4A9-2B12AB4-4A9-3B10A2B18-2B10AB19-B12A20-11A21-11A43-D30-2(2D30A)D-3(30AFE)30A2-)2(30A8-3B12A2B4-3A8-BAB12AB4-4A9-2B12AB4-4A9-3B10A2B18-2B10AB19-B12A20-11A21-11A74-D-30ADG30AD-30A2-30AG-2(30A2-))7A14B9A8-A14B2A4-3A8-A14B2(A4-4A9-A13B)A18-A11BA19-2A10BA20-11A21-11A74-D31-D2G2-24A3-D4-24A8-24A2-2G4-24A8-2(24A392-4(24A8-))24A426-2(20A12-)20A460-2(20A12-)20A332-4C12-4C11-6C10-6C9-7(8C8-)8C9-6C10-6C11-4C12-4C300-4C12-4C11-6C10-6C9-7(8C8-)8C9-6C10-6C11-4C12-4C365-2E14-2E13-3(4E12-)4E13-2E14-2E359-
