model
size = 30 14 12, scale = 0.05, origin = -y
material 
  colors = A:#222 B:#EEE C:#2D2D2D D:#7C1F16 E:#C7802D F:#E2943B G:#252525 H:#777
voxels
----BBBBBBBBBBBBBBBBBBBBB----- ---BBBBBBBBBBBBBBBBBBBBBBB---- ---BBBBBBBBBBBBBBBBBBBBBBB---- ----AAAAAAAAAAAAAAAAAAA------- -----CC---------AAAA---------- ------------------------------ ------------------------------ ------------------------------ ------------H----------------- ------------B----------------- ------------B----------------- ------------------------------ ------------------------------ ------------------------------ 
--BBBFEFEFEFEFEFEFEFEFEFBBB--- --BBDDDDDDDDDDDDDDDDDDDDDBBB-- --BBBBBBBBBBBBBBBBBBBBBBBBBB-- ---AAAAAAAAAAAAAAAAAAAAAA----- ---CCCCCC----AAAAAAAA--------- ---AAGG-GC-------GGG---------- ---AAA---GC------------------- ----GA----GCC----------------- ------------C----------------- ------------------------------ ------------B----------------- ------------B----------------- ------------------------------ ------------------------------ 
--BEFEFEFEFEFEFEFEFEFEFEFEBBB- -BBDDDDDDDDDDDDDDDDDDDDDDDDBB- -BBAAAAAAAAAAAAAAAAAAAAAAAAAB- --AAAAAAAAAAAAAAAAAAAAAAAAAA-- --CAAAAAACCCCAAAAAAAACCCC----- --AAAAADAAAAGCCCCAAACG-------- --AAAADBDAAAAAAAAC------------ --GCAADBDAAAAAAC-------------- --CCCCBBBAAAAC---------------- ---CCCDBDGAA------------------ -----CCCCCGA------------------ ---------CCAB----------------- ----------AA------------------ ------------------------------ 
-BBFEFEFEFEFEFEFEFEFEFEFEFEFB- BBDCCCCCCCCCCCCCCCCCCCCCCCCCB- BBA-------------------------B- -AA------------------------A-- -CA---------------------ACC--- -AA-----------------AACC------ -AA---------------CCB--------- -C--------------AAB----------- -G---------AAAAAB------------- -----------AAAA--------------- -----------AAAB--------------- -----------AAA---------------- -----------AA----------------- ------------------------------ 
BBFBFBFBFBBBFBBEBEBBFBFEBEFEBB BDCCCCDCCDCDCDDDCDDDCDDCDCDCBB BA--------------------------BB AA-------------------------AA- CC----------------------AAAC-- AA------------------AAAAC----- GA----------------AAAB-------- -C--------------AAAB---------- -C---------AAAAAAB------------ -G---------AAAAB-------------- -----------AAAA--------------- -----------AAAB--------------- -----------AAA---------------- -----------AA----------------- 
BFEBEBEBEBEFEBBFBFBBEBEBEBEFEB BDCDDCDCDDCDCCCDCCCDCDCCDDDCDB BA--------------------------BB DA-------------------------AA- CC----------------------AAAC-- AA------------------AAAAC----- AA----------------AAAB-------- GA--------------AAAB---------- -C---------AAAAAAB------------ -C---------AAAAB-------------- -----------AAAA--------------- -----------AAAB--------------- -----------AAA---------------- -----------AA----------------- 
BEFBFBFBFBBEFBFBBEBEBBFBBBFEFB BDCDDCDDCDCCCDDCCDDCCDCCDCDCDB BA--------------------------BB DA-------------------------AA- CC----------------------AAAC-- AA------------------AAAAC----- AA----------------AAAB-------- GA--------------AAAB---------- -C---------AAAAAAB------------ -C---------AAAAB-------------- -----------AAAA--------------- -----------AAAB--------------- -----------AAA---------------- -----------AA----------------- 
BBEFBFEBEBBBEBEBBFBFBBEBEBEFBB BDCCCCDCCDCDCDDDCDDDCDCCDDDCBB BA--------------------------BB AA-------------------------AA- CC----------------------AAAC-- AA------------------AAAAC----- GA----------------AAAB-------- -C--------------AAAB---------- -C---------AAAAAAB------------ -G---------AAAAB-------------- -----------AAAA--------------- -----------AAAB--------------- -----------AAA---------------- -----------AA----------------- 
-BBEFEFEFEFEFEFEFEFEFEFEFEFEB- BBDCCCCCCCCCCCCCCCCCCCCCCCCCB- BBA-------------------------B- -AA------------------------A-- -CA---------------------ACC--- -AA-----------------AACC------ -AA---------------AAB--------- -C--------------AAB----------- -G---------AAAAAB------------- -----------AAAA--------------- -----------AAAB--------------- -----------AAA---------------- -----------AA----------------- ------------------------------ 
--BFEFEFEFEFEFEFEFEFEFEFEFBBB- -BBDDDDDDDDDDDDDDDDDDDDDDDDBB- -BBAAAAAAAAAAAAAAAAAAAAAAAAAB- --AAAAAAAAAAAAAAAAAAAAAAAAAA-- --CAAAAAACCCCCAAAAAAACCCC----- --AAAAADAAAAGCCCCCAACG-------- --AAAADBDAAAAAAAAC------------ --GCAADBDAAAAAAC-------------- --CCCCBBBAAAAC---------------- ---CCCDBDGAAA----------------- -----CCCCCGA------------------ ---------CCAB----------------- ----------AA------------------ ------------------------------ 
--BBBEFEFEFEFEFEFEFEFEFEBBB--- --BBDDDDDDDDDDDDDDDDDDDDDBBB-- --BBBBBBBBBBBBBBBBBBBBBBBBBB-- ---AAAAAAAAAAAAAAAAAAAAAA----- ---CCCCCC----AAAAAAAA--------- ---AAGG-GC-------GGG---------- ---AAA---GC------------------- ----GA----GCC----------------- ------------C----------------- ------------------------------ ------------B----------------- ------------B----------------- ------------------------------ ------------------------------ 
----BBBBBBBBBBBBBBBBBBBBB----- ---BBBBBBBBBBBBBBBBBBBBBBB---- ---BBBBBBBBBBBBBBBBBBBBBBB---- ----AAAAAAAAAAAAAAAAAAA------- -----CC---------AAAA---------- ------------------------------ ------------------------------ ------------------------------ ------------H----------------- ------------B----------------- ------------B----------------- ------------------------------ ------------------------------ ------------------------------ 
