model
size = 23 12 29, scale = 0.05, origin = -y
material 
  colors = A:#111 B:#BBB C:#AE1212 D:#EEE
voxels
-------CCCCCCCCC------- -------CCCCCCCCC------- ----------------------- ----------------------- ----------------------- ----------------------- ----------------------- ----------------------- ----------------------- ----------------------- ----------------------- ----------------------- 
------CAADDDDDAAC------ ------CCCCCCCCCCC------ ----------------------- ----------------------- ----------------------- ----------------------- ----------------------- ----------------------- ----------------------- ----------------------- ----------------------- ----------------------- 
-----CAADAAAAADAAC----- -----CCCCCCCCCCCCC----- ----------------------- ----------------------- ----------------------- ----------------------- ----------------------- ----------------------- ----------------------- ----------------------- ----------------------- ----------------------- 
----CAADADDDDDADAAC---- ----CCCCCCCCCCCCCCC---- ----------------------- ----------------------- ----------------------- ----------------------- ----------------------- ----------------------- ----------------------- ----------------------- ----------------------- ----------------------- 
---CAADADAAAAADADAAC--- ---CCCCCCCCCCCCCCCCC--- ----------------------- ----------------------- ----------------------- ----------------------- ----------------------- ----------------------- ----------------------- ----------------------- ----------------------- ----------------------- 
---CADADADDDDDADADAC--- ---CCCCCCCCCCCCCCCCC--- ----------------------- ----------------------- ----------------------- ----------------------- ----------------------- ----------------------- ----------------------- ----------------------- ----------------------- ----------------------- 
--CADADADAAAAADADADAC-- --CCCCCCCCCCCCCCCCCCC-- ----------------------- ----------------------- ----------------------- ----------------------- ----------------------- ----------------------- ----------------------- ----------------------- ----------------------- ----------------------- 
--CDADADAADDDAADADADC-- --CCCCCCCCCCCCCCCCCCC-- --------D---DDD-------- --------D---D--D------- --------D---DDD-------- --------D---D--D------- ------DDDDD-DDD-------- ----------------------- ----------------------- ----------------------- ----------------------- ----------------------- 
--CDADADADAAADADADADC-- --CCCCDAAAAAAAAADCCCC-- ------AAAAAAAAAAA------ ------AAAAAAAAAAA------ ------AAAAAAAAAAA------ ------AAAAAAAAAAA------ ------AAAAAAAAAAA------ -------AAAAAAAAA------- --------AAAAAAA-------- ----------------------- ----------------------- ----------------------- 
--CDADABBBBBBBBBADADC-- --CCAAABBBBBBBBBAAACC-- ----AAA----B----AAA---- ----AAA----B----AAA---- -----AA----B----AA----- -----AA----B----AA----- -----AA----B----AA----- ------AAAAAAAAAAA------ -------AAAAAAAAA------- ----------------------- ----------------------- ----------------------- 
--CDADB---------BDADC-- --CAADB---------BDAAC-- ---AAA-----------AAA--- ---AAA-----------AAA--- ----AA-----------AA---- ----AA-----------AA---- ----AAA---------AAA---- -----AAAAAABAAAAAA----- ------AAAAAAAAAAA------ ----------AAA---------- ----------------------- ----------------------- 
--ADBB-----------BBDA-- --AABB-----------BBAA-- --AAAB-----------BAAA-- --AAAB-----------BAAA-- ---AAB-----------BAA--- ---AAB-----------BAA--- ----AAA---------AAA---- -----AA---------AA----- ------AAAAABAAAAA------ --------AAAAAAA-------- ----------------------- ----------------------- 
--AB---------------BA-- --AB---------------BA-- --A-----------------A-- --A-----------------A-- ---A---------------A--- ---A---------------A--- ----AAB---------BAA---- ----AAB---------BAA---- ------AAAAABAAAAA------ --------AAAAAAA-------- ----------------------- ----------------------- 
-AAB---------------BAA- -AAB---------------BAA- -AA-----------------AA- -AA-----------------AA- --AA---------------AA-- --AA---------------AA-- ---A---------------A--- ---AAA-----------AAA--- -----AABAAABAAABAA----- -------AAAAAAAAA------- ----------------------- ----------------------- 
-AB-----------------BA- -AB-----------------BA- -A-------------------A- -A-------------------A- --A-----------------A-- --A-----------------A-- ---A---------------A--- ---AAA-----------AAA--- -----AAAB-----BAAA----- -------AAAABAAAA------- ----------AAA---------- ----------------------- 
AAB-----------------BAA AAB-----------------BAA AA-------------------AA -A-------------------A- -AA-----------------AA- --A-----------------A-- --AA---------------AA-- ---AAA-----------AAA--- ----AAAA-------AAAA---- ------AAABABABAAA------ ---------AAAAA--------- ----------------------- 
AB-------------------BA AB-------------------BA AA-------------------AA AA-------------------AA -AA-----------------AA- -AA-----------------AA- --AA---------------AA-- --AAAA-----------AAAA-- ----AAAA-------AAAA---- ------AAAABBBAAAA------ --------AAAAAAA-------- ----------CCC---------- 
AB-------------------BA AB-------------------BA AB-------------------BA AB-------------------BA -AB-----------------BA- -AB-----------------BA- --AB---------------BA-- --AABB-----------BBAA-- ----AABB-------BBAA---- ------AABBBBBBBAA------ --------AAADAAA-------- ----------CCC---------- 
AB-------------------BA AB-------------------BA AA-------------------AA AA-------------------AA -AA-----------------AA- -AA-----------------AA- --AA---------------AA-- --AAAA-----------AAAA-- ----AAAA-------AAAA---- ------AAAABBBAAAA------ --------AAAAAAA-------- ----------CCC---------- 
AB-------------------BA AB-------------------BA AA-------------------AA AA-------------------AA -AA-----------------AA- -AA-----------------AA- --AA---------------AA-- --AAAA-----------AAAA-- ----AAAAAB---BAAAAA---- ------AAADABADAAA------ ---------AAAAA--------- ----------------------- 
AB-------------------BA AB-------------------BA AA-------------------AA -A-------------------A- -AA-----------------AA- --A-----------------A-- --AA---------------AA-- ---AAA-----------AAA--- -----AAABA---ABAAA----- -------AAAABAAAA------- ----------AAA---------- ----------------------- 
AAB-----------------BAA AAB-----------------BAA -A-------------------A- -A-------------------A- --A-----------------A-- --A-----------------A-- ---A---------------A--- ---AAAAB-------BAAAA--- -----AAAAAABAAADAA----- -------AAAAAAAAA------- ----------------------- ----------------------- 
-AB-----------------BA- -AB-----------------BA- -A-------------------A- -A-------------------A- --A-----------------A-- --A-----------------A-- ---AAAB---------BAAA--- ---AAADA-------ADAAA--- -----AAAAAABAAAAAA----- -------AAAAAAAAA------- ----------------------- ----------------------- 
-AAB---------------BAA- -AAB---------------BAA- -AA-----------------AA- --A-----------------A-- --A-----------------A-- ---AAB-----------BAA--- ---AADA---------ADAA--- ----AAAA-------AAAA---- ------AAAAABAAAAA------ ---------AAAAA--------- ----------------------- ----------------------- 
--ABB-------------BBA-- --ADB-------------BDA-- --AAB-------------BAA-- --AAB-------------BAA-- ---AB-------------BA--- ---ADA-----------ADA--- ----AAA---------AAA---- -----AAAAAABAAAAAA----- -------AAAAAAAAA------- ----------------------- ----------------------- ----------------------- 
--AAB-------------BAA-- --AAB-------------BAA-- --AAA-------------AAA-- --AAA-------------AAA-- ----A-------------A---- ----AA-----------AA---- -----AA---------AA----- -------AAAABAAAA------- ---------AAAAA--------- ----------------------- ----------------------- ----------------------- 
---AABB---------BBAA--- ---AABB---------BBAA--- ---AAA-----------AAA--- ---AAA-----------AAA--- -----A-----------A----- -----A-----------A----- ------AAAAABAAAAA------ ---------AAAAA--------- ----------------------- ----------------------- ----------------------- ----------------------- 
----AAABB-----BBAAA---- ----AAABB-----BBAAA---- ----AAAAB-----BAAAA---- ----AAAAAB---BAAAAA---- ------AAAABBBAAAA------ ------AAAAABAAAAA------ ---------AAAAA--------- ----------------------- ----------------------- ----------------------- ----------------------- ----------------------- 
------AADADADADAA------ ------AADDDDDDDAA------ ------AAA-----AAA------ ------AAAA---AAAA------ --------AAAAAAA-------- ---------AAAAA--------- ----------------------- ----------------------- ----------------------- ----------------------- ----------------------- ----------------------- 
