model
size = 15 32 15, scale = 0.05, origin = -y
material 
  colors = A:#C0C B:#111
voxels
5-11(5A10-)5B10(10-5A)10-5B9(10-5A)15-10(2A13-)2A7-2B4-2B10(13-2A)7-2B4-2B9(13-2A)5-11(8A-2A4-)4B4A-AB10(4-8A-2A)4-5B3A-AB9(4-8A-2A)3-11(4A4-2A-2A2-)B3A4-2A-AB10(2-4A4-2A-2A)2-B3A4-2A-AB9(2-4A4-2A-2A)11(2-3A-7A-A)2-B2A-7A-B10(2-3A-7A-A)2-B2A-7A-B8(2-3A-7A-A)2-3A-4A-2A-A-3A10(-2A2-2A-A-5A)2(-2A2-2A-A-2AB2A-2A2-2A2(-A)B3A9(-2A2-2A-A-5A))10(-A-2A2(-A)-5A)2(-A-2A2(-A)-2AB2(2A-A-)A-AB3A9(-A-2A2(-A)-5A))10(2(-A)-2A-A-5A)2(2(-A)-2A-A-2AB2A2(-A)-2A2(-A)B3A9(2(-A)-2A-A-5A))10(-A-3A-2A-5A)2(-A-3A2(-2A)B2A-A-3A-2A-AB3A9(-A-3A-2A-5A))10(-2A3-2A-6A)-2A3-2A-3AB2A-2A3-2A-2AB3A9(-2A3-2A-6A)-2A3-2A-3AB2A-2A3-2A-2AB3A8(-2A3-2A-6A)-2A3-2A2(-3A)10(-5A-3A2-3A)-5A-3A2-B2A-5A-2AB10(2-3A-5A-3A)2-B2A-5A-2AB9(2-3A-5A-3A)11(2-4A5-4A)2-B3A5-3AB10(2-4A5-4A)2-B3A5-3AB9(2-4A5-4A)3-11(11A4-)B9AB10(4-11A)4-B9AB9(4-11A)5-11(9A6-)2B5A2B10(6-9A)6-2B5A2B9(6-9A)8-11(5A10-)5B10(10-5A)10-5B9(10-5A)5-
