model
size = 21 23 21, scale = 0.05, origin = -y
material 
  colors = A:#933 B:#693400 C:#963 D:#040 E:#036 F:#06F G:#3D2300 H:#050 I:#070 J:#633 K:#009 L:#EEE M:#9CF N:#F96 O:#960 P:#E00 Q:#251300 R:#111 S:#66C
voxels
--------------------- --------------------- --------------------- --------------------- --------------------- --------------------- --------------------- --------------------- --------------------- --------------------- --------------------- -------BBBBBBB------- -------BBBBBBB------- -------BBBBBBB------- --------------------- --------------------- --------------------- --------------------- --------------------- --------------------- --------------------- --------------------- --------------------- 
--------------------- --------------------- -------BBBBBBB------- -------BBBBBBB------- -------BBBBBBB------- -------BBBBBBB------- -------BBBBBBB------- -------BBBBBBB------- -------BBBBBBB------- -------BBBBBBB------- -------BBBBBBB------- -----BBAAAAAAABB----- -----BBBBBBBBBBB----- -----BBBBBBBBBBB----- --------------------- --------------------- --------------------- --------------------- --------------------- --------------------- --------------------- --------------------- --------------------- 
--------BBBBB-------- --------BBBBB-------- -----BBBAAAAABBB----- -----BBAAAAAAABB----- -----BBAAAAAAABB----- -----BBAAAAAAABB----- -----BBAAAAAAABB----- -----BBAAAAAAABB----- -----BBAAAAAAABB----- -----BBAAAAAAABB----- -----BBAAAAAAABB----- ----BABEEEEEEEBBB---- ----BBB-------BBB---- ----BBB-------BBB---- --------------------- --------------------- --------------------- --------------------- --------------------- --------------------- --------------------- --------------------- --------------------- 
------BBBBBBBBB------ ------BBAAAAABB------ ----BBAAAAAAAABBB---- ----BAAAAAAAAAAAB---- ----BAAAAAAAAAAAB---- ----BAAAAAAAAAAAB---- ----BAAAAAAAAAAAB---- ----BAAAAAAAAAAAB---- ----BAAAAAAAAAAAB---- ----BAAAAAAAAAAAB---- ----BAAAAKJJJAAAB---- ---BBAEEE-EEEEEJBB--- ---BBB---------BBB--- ---BBB---------BBB--- --------------------- --------------------- ----------D---------- ---------DDD--------- --------DDDDD-------- --------DHIHD-------- --------------------- --------------------- --------------------- 
----BBBBBBBBBBBBB---- ----BBAAAAAAABBBB---- ---BAAAAAAAAAABBBB--- ---BAAAAAAAAAAAABB--- ---BAAAAAAAAAAAABB--- ---BAAAAAAAAAAAABB--- ---BAAAAAAAAAAAABB--- ---BAAAAAAAAAAAABB--- ---BAAAAAAAAAAAABB--- ---BAAAAAAAAAAAABB--- ---BAAAAAAAAKAAABB--- --BAAEEFFFFF-FFEBBB-- --BBB-----------BBB-- --BBB-----------BBB-- --------------------- --------------------- --------------------- --------------------- --------------------- --------DDDDD-------- --------DIIID-------- --------------------- --------------------- 
----BBBBBBBBBBBBB---- ----BAAAAAAAABBBB---- --BBAAAAAAAAAABBBBB-- --BAAAAAAAAAAAAABBB-- --BAAAAAAAAAAAAABBB-- --BAAAAAAAAAAAAABBB-- --BAAAAAAAAAAAAABBB-- --BAAAAAAAAAAAAABBB-- --BAAAAAAAAAAAAABBB-- --BAAAAAAAAAAAAABBB-- --BAAAAAGAAAAAAABBB-- -BBAEFFLCCOLCCFFEBBB- -BBB-------------BBB- -BBB-------------BBB- --------------------- --------------------- --------------------- --------------------- --------------------- --------------------- --------DDDDD-------- --------DHIHD-------- --------------------- 
---BBBBBBBBBBBBBBB--- ---BAAAAAAAAABBBBB--- --BAAAAAAAAAAAAAABB-- --BAAAAAAAAAAAAAABB-- --BAAAAAAAAAAAAAABB-- --BAAAAAAAAAAAAAABB-- --BAAAAAAAAAAAAAABB-- --BAAAAAAAAAAAAAABB-- --BAAAAAAAAAAAAAABB-- --BAAAAAAAAAAAAAABB-- --BAKAJJAAAAAAAAABB-- -BBE-FCCCCCCCCCFEEBB- -BB---------------BB- -BB---------------BB- --------------------- --------------------- --------------------- --------------------- --------------------- --------------------- --------------------- --------DDDDD-------- ---------DID--------- 
---BBBBBBBBBBBBBBB--- ---BAAAAAAAAABBBBB--- -BBAAAAAAAAAAAAAAABB- -BAAAAAAAAAAAAAAAABB- -BAAAAAAAAAAAAAAAABB- -BAAAAAAAAAAAAAAAABB- -BAAAAAAAAAAAAAAAABB- -BAAAAAAAAAAAAAAAABB- -BAAAAAAAAAAAAAAAABB- -BAAAAAAAAAAAAAAAABB- -BAAAAJJAAAAAAAAKABB- BBEEEFCCCCCCCCCL-EEBB BB-----OCCCCCC-----BB BB-----------------BB --------------------- --------------------- --------------------- --------------------- --------------------- ----------Q---------- --------------------- ----------H---------- ---------DHD--------- 
--BBBBBBBBBBBBBBBBB-- --BBAAAAABBAABBBBBB-- -BAAAAAAABBAAAAAAABB- -BAAAAAAABBAAAAAAABB- -BAAAAAAABBAAAAAAABB- -BAAAAAAABBAAAAAAABB- -BAAAAAAABBAAAAAAABB- -BAAAAAAAAAAAAAAAABB- -BAAAAAAAAAAAAAAAABB- -BAAAAAAAAAAAAAAAABB- -BAAAAJJAAAAAAAAAABB- BBEFFCCCCCCCCCCFFEEBB BB-----CCCCCCC-----BB BB------CCCCC------BB --------------------- --------------------- --------------------- --------------------- --------------------- --------------------- ----------G---------- -----DD---H---DD----- --------------------- 
--BBBBBBBBBBBBBBBBB-- --BBAAAAABBAABBBBBB-- -BAAAAAAABBAAAAAAABB- -BAAAAAAABBAAAAAAABB- -BAAAAAAABBAAAAAAABB- -BAAAAAAABBAAAAAAABB- -BAAAAAAABBAAAAAAABB- -BAAAAAAAABAAAAAAABB- -BAAAAAAAABAAAAAAABB- -BAAAAAAAABAAAAAAABB- -BAAAAGJAABAAAAAAABB- BBFFCCCCCCBCCCCCLEEBB BB-----CCCDCCO-----BB BB------CCHCC------BB ----------G---------- ----------G---------- ----------G---------- ----------G---------- ----------G---------- ----D-----G-----D---- ----DD----G----DD---- -----HD-------DH----- ------DD-----DD------ 
--BBBBBBBB-BBBBBBBB-- --BBAAAAAB-BABBBBBB-- -BAAAAAAAB-BAAAAAABB- -BAAAAAAAB-BAAAAAABB- -BAAAAAAAB-BAAAAAABB- -BAAAAAAAB-BAAAAAABB- -BAAAAAAAB-BAAAAAABB- -BAAAAAAAB-BAAAAAABB- -BAAAAAAAB-BAAAAAABB- -BAAAAAAAB-BAAAAAABB- -BAKAAAAAB-BAAAGAAKB- BBF-CCCCCJBACCCCFE-BB BB-----CCDMDCC-----BB BB------CHMHC------BB ---------GMG--------- ---------GMG--------- ---------GMG--------- ---------GMG--------- ----D----GMG----D---- ----D--Q-GIG-Q--D---- ----ID--GG-GG--DI---- -----IDHH---HHDI----- ------IH-----HI------ 
--BBBBBBBBBBBBBBBBB-- --BBAAAAABBAABBBBBB-- -BAAAAAAABBAAAAAAABB- -BAAAAAAABBAAAAAAABB- -BAAAAAAABBAAAAAAABB- -BAAAAAAABBAAAAAAABB- -BAAAAAAABBAAAAAAABB- -BAAAAAAAABAAAAAAABB- -BAAAAAAAABAAAAAAABB- -BAAAAAAAABAAAAAAABB- -BAAAAAAAABAAAAJAABB- BBFFCCCCCCBCCCCCFFEBB BB-----OCCDCCC-----BB BB------CCHCC------BB ----------G---------- ----------G---------- ----------G---------- ----------G---------- ----------G---------- ----D-----G-----D---- ----DD----G----DD---- -----HD-------DH----- ------DD-----DD------ 
--BBBBBBBBBBBBBBBBB-- --BBAAAAAAAAABBBBBB-- -BBAAAAAAAAAAAAAAAAB- -BBAAAAAAAAAAAAAAAAB- -BBAAAAAAAAAAAAAAAAB- -BBAAAAAAAAAAAAAAAAB- -BBAAAAAAAAAAAAAAAAB- -BBAAAAAAAAAAAAAAAAB- -BBAAAAAAAAAAAAAAAAB- -BAAAAAAAAAAAAAAAAAB- -BAAAAGAAAAAAAAAKAAB- BBEFLCCCCCCCCCCF-FEBB BB-----CCCCCCC-----BB BB------CCCCO------BB ---------NSN--------- ---------NPN--------- ---------PPP--------- ----------N---------- --------------------- --------------------- ----------G---------- -----DD---H---DD----- --------------------- 
---BBBBBBBBBBBBBBB--- ---BAAAAAAAAAABBBB--- -BBAAAAAAAAAAAAAABBB- -BBAAAAAAAAAAAAAABBB- -BBAAAAAAAAAAAAAABBB- -BBAAAAAAAAAAAAAABBB- -BBAAAAAAAAAAAAAABBB- -BBAAAAAAAAAAAAAABBB- -BBAAAAAAAAAAAAAABBB- -BBAAAAAAAAAAAAAABBB- -BBAAAAAAAAAAAAAABBB- BBEEFFCCCCCCCCCLFEEBB BB-----CCCCCCC-----BB BB--------N--------BB ----------R---------- --------------------- --------------------- --------------------- --------------------- ----------Q---------- --------------------- ----------H---------- ---------DHD--------- 
---BBBBBBBBBBBBBBB--- ---BBBBBBBBBBABBBB--- --BAAAAAAAAAAAAABBB-- --BAAAAAAAAAAAAABBB-- --BAAAAAAAAAAAAABBB-- --BAAAAAAAAAAAAABBB-- --BAAAAAAAAAAAAABBB-- --BAAAAAAAAAAAAABBB-- --BAAAAAAAAAAAAABBB-- --BAAAAAAAAAAAAABBB-- --BAKAAAAAAAAAAABBB-- -BAE-LCCCCCCCCFFEEBB- -BB---------------BB- -BB---------------BB- --------------------- --------------------- --------------------- --------------------- --------------------- --------------------- --------------------- --------DDDDD-------- ---------DID--------- 
----BBBBBBBBBBBBB---- ----BBBBBBBBBABBB---- --BBAAAAAAAAAAAABBB-- --BAAAAAAAAAAAAABBB-- --BAAAAAAAAAAAAABBB-- --BAAAAAAAAAAAAABBB-- --BAAAAAAAAAAAAABBB-- --BAAAAAAAAAAAAABBB-- --BAAAAAAAAAAAAABBB-- --BAAAAAAAAAAAAABBB-- --BAAAAAAAAAKAAABBB-- -BBAEFLCCCFL-FEEEBBB- -BBB-------------BBB- -BBB-------------BBB- --------------------- --------------------- --------------------- --------------------- --------------------- --------------------- --------DDDDD-------- --------DHIHD-------- --------------------- 
----BBBBBBBBBBBBB---- ----BBBBBBBBBABBB---- ---BBAAAAAAAAAAABB--- ---BBAAAAAAAAAAABB--- ---BBAAAAAAAAAAABB--- ---BBAAAAAAAAAAABB--- ---BBAAAAAAAAAAABB--- ---BBAAAAAAAAAAABB--- ---BBAAAAAAAAAAABB--- ---BBAAAAAAAAAAABB--- ---BBAAAAKAAAAAABB--- --BBBEFFF-EEEEEEBBB-- --BBB-----------BBB-- --BBB-----------BBB-- --------------------- --------------------- --------------------- --------------------- --------------------- --------DDDDD-------- --------DHIHD-------- --------------------- --------------------- 
------BBBBBBBBB------ ------BBBBBBBBB------ ----BBBBBAAAAABBB---- ----BBBBBAAAAABBB---- ----BBBBBAAAAABBB---- ----BBBBBAAAAABBB---- ----BBBBBAAAAABBB---- ----BBBBBAAAAABBB---- ----BBBBBAAAAABBB---- ----BBBBBAAAAABBB---- ----BBBAAAAAAKBBB---- ---BBBEEEEEEE-EBBB--- ---BBB---------BBB--- ---BBB---------BBB--- --------------------- --------------------- ----------D---------- ---------DDD--------- --------DDDDD-------- --------DHIHD-------- --------------------- --------------------- --------------------- 
--------BBBBB-------- --------BBBBB-------- -----BBBBBBBBBBB----- -----BBBBBBBBBBB----- -----BBBBBBBBBBB----- -----BBBBBBBBBBB----- -----BBBBBBBBBBB----- -----BBBBBBBBBBB----- -----BBBBBBBBBBB----- -----BBBBBBBBBBB----- -----BBBBBBBBBBB----- ----BBBEEEEEEEBBB---- ----BBB-------BBB---- ----BBB-------BBB---- --------------------- --------------------- --------------------- --------------------- --------------------- --------------------- --------------------- --------------------- --------------------- 
--------------------- --------------------- -------BBBBBBB------- -------BBBBBBB------- -------BBBBBBB------- -------BBBBBBB------- -------BBBBBBB------- -------BBBBBBB------- -------BBBBBBB------- -------BBBBBBB------- -------BBBBBBB------- -----BBBBBABBBBB----- -----BBBBBBBBBBB----- -----BBBBBBBBBBB----- --------------------- --------------------- --------------------- --------------------- --------------------- --------------------- --------------------- --------------------- --------------------- 
--------------------- --------------------- --------------------- --------------------- --------------------- --------------------- --------------------- --------------------- --------------------- --------------------- --------------------- -------BBBBBBB------- -------BBBBBBB------- -------BBBBBBB------- --------------------- --------------------- --------------------- --------------------- --------------------- --------------------- --------------------- --------------------- --------------------- 
