model
size = 23 28 29, scale = 0.05, origin = -y
material 
  colors = A:#933 B:#630 C:#400 D:#040 E:#050 F:#070 G:#200 H:#633 I:#9CF
voxels
----------------------- ----------------------- ----------------------- ----------------------- ----------------------- ----------------------- ----------------------- ----------------------- ----------------------- ----------------------- ----------------------- ----------------------- ----------------------- ----------------------- ----------------------- ----------------------- ----------------------- ----------------------- ----------------------- -----------D----------- ----------DDD---------- ---------DDDDD--------- ---------DEFED--------- ----------------------- ----------------------- ----------------------- ----------------------- ----------------------- 
----------------------- ----------------------- ----------------------- ----------------------- ----------------------- ----------------------- ----------------------- ----------------------- ----------------------- ----------------------- ----------------------- ----------------------- ----------------------- ----------------------- ----------------------- ----------------------- ----------------------- ----------------------- ----------------------- ----------------------- ----------------------- ----------------------- ---------DDDDD--------- ---------DFFFD--------- ----------------------- ----------------------- ----------------------- ----------------------- 
----------------------- ----------------------- ----------------------- ----------------------- ----------------------- ----------------------- ----------------------- ----------------------- ----------------------- ----------------------- ----------------------- ----------------------- ----------------------- ----------------------- ----------------------- ----------------------- ----------------------- ----------------------- ----------------------- ----------------------- ----------------------- ----------------------- ----------------------- ---------DDDDD--------- ---------DEFED--------- ----------------------- ----------------------- ----------------------- 
----------------------- ----------------------- ----------------------- ----------------------- ----------------------- ----------------------- ----------------------- ----------------------- ----------------------- ----------------------- ----------------------- ----------------------- ----------------------- ----------------------- ----------------------- ----------------------- ----------------------- ----------------------- ----------------------- ----------------------- ----------------------- ----------------------- ----------------------- ----------------------- ---------DDDDD--------- ----------DFD---------- ----------------------- ----------------------- 
----------------------- ----------------------- ----------------------- ----------------------- ----------------------- ----------------------- ----------------------- ----------------------- ----------------------- ----------------------- ----------------------- --------BBBBBBB-------- --------BBBBBBB-------- --------BBBBBBB-------- ----------------------- ----------------------- ----------------------- ----------------------- ----------------------- ----------------------- ----------------------- ----------------------- ----------------------- ----------------------- ----------------------- ----------DED---------- ----------------------- ----------------------- 
----------------------- ----------------------- --------BBBBBBB-------- --------BBBBBBB-------- --------BBBBBBB-------- --------BBBBBBB-------- --------BBBBBBB-------- --------BBBBBBB-------- --------BBBBBBB-------- --------BBBBBBB-------- --------BBBBBBB-------- ------BBAAAAAAABB------ ------BBBBBBBBBBB------ ------BBBBBBBBBBB------ ----------------------- ----------------------- ----------------------- ----------------------- ----------------------- ----------------------- ----------------------- ----------------------- ----------------------- ----------------------- ----------------------- -----------E----------- ----------------------- ----------------------- 
---------BBBBB--------- ---------BBBBB--------- ------BBBAAAAABBB------ ------BBAAAAAAABB------ ------BBAAAAAAABB------ ------BBAAAAAAABB------ ------BBAAAAAAABB------ ------BBAAAAAAABB------ ------BBAAAAAAABB------ ------BBAAAAAAABB------ ------BBAAAAAAABB------ -----BABCCCCCCCBBB----- -----BBB-------BBB----- -----BBB-------BBB----- ----------------------- ----------------------- ----------------------- ----------------------- ----------------------- ----------------------- ----------------------- ----------------------- ----------------------- ----------------------- ----------------------- -----------E----------- -----------E----------- ----------------------- 
-------BBBBBBBBB------- -------BBAAAAABB------- -----BBAAAAAAAABBB----- -----BAAAAAAAAAAAB----- -----BAAAAAAAAAAAB----- -----BAAAAAAAAAAAB----- -----BAAAAAAAAAAAB----- -----BAAAAAAAAAAAB----- -----BAAAAAAAAAAAB----- -----BAAAAAAAAAAAB----- -----BAAAAGHHHAAAB----- ----BBACCC-CCCCCHBB---- ----BBB---------BBB---- ----BBB---------BBB---- ----------------------- ----------------------- ----------------------- ----------------------- ----------------------- ----------------------- ----------------------- ----------------------- ----------------------- ----------------------- ----------------------- ----------------------- -----------E----------- -----------E----------- 
-----BBBBBBBBBBBBB----- -----BBAAAAAAABBBB----- ----BAAAAAAAAAABBBB---- ----BAAAAAAAAAAAABB---- ----BAAAAAAAAAAAABB---- ----BAAAAAAAAAAAABB---- ----BAAAAAAAAAAAABB---- ----BAAAAAAAAAAAABB---- ----BAAAAAAAAAAAABB---- ----BAAAAAAAAAAAABB---- ----BAAAAAAAAGAAABB---- ---BAACCCCCCC-CCCBBB--- ---BBB-----------BBB--- ---BBB-----------BBB--- ----------------------- ----------------------- ----------------------- ----------------------- ----------------------- ----------------------- ----------------------- ----------------------- ----------------------- ----------------------- ----------------------- ----------------------- ----------------------- -----------E----------- 
-----BBBBBBBBBBBBB----- -----BAAAAAAAABBBB----- ---BBAAAAAAAAAABBBBB--- ---BAAAAAAAAAAAAABBB--- ---BAAAAAAAAAAAAABBB--- ---BAAAAAAAAAAAAABBB--- ---BAAAAAAAAAAAAABBB--- ---BAAAAAAAAAAAAABBB--- ---BAAAAAAAAAAAAABBB--- ---BAAAAAAAAAAAAABBB--- ---BAAAAAGAAAAAAABBB--- --BBACCCC-CCCCCCCCBBB-- --BBB-------------BBB-- --BBB-------------BBB-- ----------------------- ----------------------- ----------------------- ----------------------- ----------------------- ----------------------- ----------------------- ----------------------- ----------------------- ----------------------- ----------------------- ----------------------- ----------------------- -----------E----------- 
----BBBBBBBBBBBBBBB---- ----BAAAAAAAAABBBBB---- ---BAAAAAAAAAAAAAABB--- ---BAAAAAAAAAAAAAABB--- ---BAAAAAAAAAAAAAABB--- ---BAAAAAAAAAAAAAABB--- ---BAAAAAAAAAAAAAABB--- ---BAAAAAAAAAAAAAABB--- ---BAAAAAAAAAAAAAABB--- ---BAAAAAAAAAAAAAABB--- ---BAGAHHAAAAAAAAABB--- --BBC-CCCCCCCCCCCCCBB-- --BB---------------BB-- --BB---------------BB-- ----------------------- ----------------------- ----------------------- ----------------------- ----------------------- ----------------------- ----------------------- ----------------------- ----------------------- ----------------------- ----------------------- -----------E----------- -----------E----------- -----------E----------- 
----BBBBBBBBBBBBBBB---- ----BAAAAAAAAABBBBB---- --BBAAAAAAAAAAAAAAABB-- --BAAAAAAAAAAAAAAAABB-- --BAAAAAAAAAAAAAAAABB-- --BAAAAAAAAAAAAAAAABB-- --BAAAAAAAAAAAAAAAABB-- --BAAAAAAAAAAAAAAAABB-- --BAAAAAAAAAAAAAAAABB-- --BAAAAAAAAAAAAAAAABB-- --BAAAAHHAAAAAAAAGABB-- -BBCCCCCCCCCCCCCC-CCBB- -BB-----------------BB- -BB-----------------BB- ----------------------- ----------------------- ----------------------- ----------------------- ----------------------- ----------------------- ----------------------- ----------------------- ----------------------- -----------E----------- -----------E----------- -----------E----------- ----------------------- ----------------------- 
---BBBBBBBBBBBBBBBBB--- ---BBAAAAABBAABBBBBB--- --BAAAAAAABBAAAAAAABB-- --BAAAAAAABBAAAAAAABB-- --BAAAAAAABBAAAAAAABB-- --BAAAAAAABBAAAAAAABB-- --BAAAAAAABBAAAAAAABB-- --BAAAAAAAAAAAAAAAABB-- --BAAAAAAAAAAAAAAAABB-- --BAAAAAAAAAAAAAAAABB-- --BAAAAHHAAAAAAAAAABB-- -BBCCCCCCCCCCCCCCCCCBB- -BB-----------------BB- -BB-----------------BB- ----------------------- ----------------------- ----------------------- ----------------------- ----------------------- ----------------------- ----------------------- ----------------------- -DD--------E----------- -----------E----------- ----------------------- --------------------DD- ----------------------- ----------------------- 
---BBBBBBBBBBBBBBBBB--- ---BBAAAAABBAABBBBBB--- --BAAAAAAABBAAAAAAABB-- --BAAAAAAABBAAAAAAABB-- --BAAAAAAABBAAAAAAABB-- --BAAAAAAABBAAAAAAABB-- --BAAAAAAABBAAAAAAABB-- --BAAAAAAAABAAAAAAABB-- --BAAAAAAAABAAAAAAABB-- --BAAAAAAAABAAAAAAABB-- --BAAAAGHAABAAAAAAABB-- -BBCCCC-CCCBCCCCCCCCBB- -BB--------D--------BB- -BB--------D--------BB- -----------D----------- -----------E----------- -----------E----------- -----------E----------- -----------E----------- -----------E----------- D----------E----------- DD---------E----------- -ED--------F----------- --DD------------------D ---------------------DD --------------------DE- -------------------DD-- ----------------------- 
---BBBBBBBB-BBBBBBBB--- ---BBAAAAAB-BABBBBBB--- --BAAAAAAAB-BAAAAAABB-- --BAAAAAAAB-BAAAAAABB-- --BAAAAAAAB-BAAAAAABB-- --BAAAAAAAB-BAAAAAABB-- --BAAAAAAAB-BAAAAAABB-- --BAAAAAAAB-BAAAAAABB-- --BAAAAAAAB-BAAAAAABB-- --BAAAAAAAB-BAAAAAABB-- --BAGAAAAAB-BAAAGAACB-- -BBC-CCCCCHBACCC-CC-BB- -BB-------DAD-------BB- -BB-------DAD-------BB- ----------DID---------- ----------EIE---------- ----------EIE---------- ----------EIE---------- ----------EIE---------- D---------EIE---------- D---------EIE---------- FD--------EFE---------- -FD------EF-FE--------D --FEEE--EE---EE-------D -----EEEE-----EE-----DF ---------------E----DF- ---------------EEEEEF-- ----------------------- 
---BBBBBBBBBBBBBBBBB--- ---BBAAAAABBAABBBBBB--- --BAAAAAAABBAAAAAAABB-- --BAAAAAAABBAAAAAAABB-- --BAAAAAAABBAAAAAAABB-- --BAAAAAAABBAAAAAAABB-- --BAAAAAAABBAAAAAAABB-- --BAAAAAAAABAAAAAAABB-- --BAAAAAAAABAAAAAAABB-- --BAAAAAAAABAAAAAAABB-- --BAAAAAAAABAAAAHAABB-- -BBCCCCCCCCBCCCCCCCCBB- -BB--------D--------BB- -BB--------D--------BB- -----------D----------- -----------E----------- -----------E----------- -----------E----------- -----------E----------- -----------E----------- D----------E----------- DD---------E----------- -ED--------F----------- --DD------------------D ---------------------DD --------------------DE- -------------------DD-- ----------------------- 
---BBBBBBBBBBBBBBBBB--- ---BBAAAAAAAAABBBBBB--- --BBAAAAAAAAAAAAAAAAB-- --BBAAAAAAAAAAAAAAAAB-- --BBAAAAAAAAAAAAAAAAB-- --BBAAAAAAAAAAAAAAAAB-- --BBAAAAAAAAAAAAAAAAB-- --BBAAAAAAAAAAAAAAAAB-- --BBAAAAAAAAAAAAAAAAB-- --BAAAAAAAAAAAAAAAAAB-- --BAAAAGAAAAAAAAAGAAB-- -BBCCCC-CCCCCCCCC-CCBB- -BB-----------------BB- -BB-----------------BB- ----------------------- ----------------------- ----------------------- ----------------------- ----------------------- ----------------------- ----------------------- ----------------------- -DD--------E----------- -----------E----------- ----------------------- --------------------DD- ----------------------- ----------------------- 
----BBBBBBBBBBBBBBB---- ----BAAAAAAAAAABBBB---- --BBAAAAAAAAAAAAAABBB-- --BBAAAAAAAAAAAAAABBB-- --BBAAAAAAAAAAAAAABBB-- --BBAAAAAAAAAAAAAABBB-- --BBAAAAAAAAAAAAAABBB-- --BBAAAAAAAAAAAAAABBB-- --BBAAAAAAAAAAAAAABBB-- --BBAAAAAAAAAAAAAABBB-- --BBAAAAAAAAAAAAAABBB-- -BBCCCCCCCCCCCCCCCCCBB- -BB-----------------BB- -BB-----------------BB- ----------------------- ----------------------- ----------------------- ----------------------- ----------------------- ----------------------- ----------------------- ----------------------- ----------------------- -----------E----------- -----------E----------- -----------E----------- ----------------------- ----------------------- 
----BBBBBBBBBBBBBBB---- ----BBBBBBBBBBABBBB---- ---BAAAAAAAAAAAAABBB--- ---BAAAAAAAAAAAAABBB--- ---BAAAAAAAAAAAAABBB--- ---BAAAAAAAAAAAAABBB--- ---BAAAAAAAAAAAAABBB--- ---BAAAAAAAAAAAAABBB--- ---BAAAAAAAAAAAAABBB--- ---BAAAAAAAAAAAAABBB--- ---BAGAAAAAAAAAAABBB--- --BAC-CCCCCCCCCCCCCBB-- --BB---------------BB-- --BB---------------BB-- ----------------------- ----------------------- ----------------------- ----------------------- ----------------------- ----------------------- ----------------------- ----------------------- ----------------------- ----------------------- ----------------------- -----------E----------- ----------------------- ----------------------- 
-----BBBBBBBBBBBBB----- -----BBBBBBBBBABBB----- ---BBAAAAAAAAAAAABBB--- ---BAAAAAAAAAAAAABBB--- ---BAAAAAAAAAAAAABBB--- ---BAAAAAAAAAAAAABBB--- ---BAAAAAAAAAAAAABBB--- ---BAAAAAAAAAAAAABBB--- ---BAAAAAAAAAAAAABBB--- ---BAAAAAAAAAAAAABBB--- ---BAAAAAAAAAGAAABBB--- --BBACCCCCCCC-CCCCBBB-- --BBB-------------BBB-- --BBB-------------BBB-- ----------------------- ----------------------- ----------------------- ----------------------- ----------------------- ----------------------- ----------------------- ----------------------- ----------------------- ----------------------- ----------------------- -----------E----------- ----------------------- ----------------------- 
-----BBBBBBBBBBBBB----- -----BBBBBBBBBABBB----- ----BBAAAAAAAAAAABB---- ----BBAAAAAAAAAAABB---- ----BBAAAAAAAAAAABB---- ----BBAAAAAAAAAAABB---- ----BBAAAAAAAAAAABB---- ----BBAAAAAAAAAAABB---- ----BBAAAAAAAAAAABB---- ----BBAAAAAAAAAAABB---- ----BBAAAAGAAAAAABB---- ---BBBCCCC-CCCCCCBBB--- ---BBB-----------BBB--- ---BBB-----------BBB--- ----------------------- ----------------------- ----------------------- ----------------------- ----------------------- ----------------------- ----------------------- ----------------------- ----------------------- ----------------------- ----------------------- -----------E----------- ----------------------- ----------------------- 
-------BBBBBBBBB------- -------BBBBBBBBB------- -----BBBBBAAAAABBB----- -----BBBBBAAAAABBB----- -----BBBBBAAAAABBB----- -----BBBBBAAAAABBB----- -----BBBBBAAAAABBB----- -----BBBBBAAAAABBB----- -----BBBBBAAAAABBB----- -----BBBBBAAAAABBB----- -----BBBAAAAAAGBBB----- ----BBBCCCCCCC-CBBB---- ----BBB---------BBB---- ----BBB---------BBB---- ----------------------- ----------------------- ----------------------- ----------------------- ----------------------- ----------------------- ----------------------- ----------------------- ----------------------- ----------------------- -----------E----------- -----------E----------- ----------------------- ----------------------- 
---------BBBBB--------- ---------BBBBB--------- ------BBBBBBBBBBB------ ------BBBBBBBBBBB------ ------BBBBBBBBBBB------ ------BBBBBBBBBBB------ ------BBBBBBBBBBB------ ------BBBBBBBBBBB------ ------BBBBBBBBBBB------ ------BBBBBBBBBBB------ ------BBBBBBBBBBB------ -----BBBCCCCCCCBBB----- -----BBB-------BBB----- -----BBB-------BBB----- ----------------------- ----------------------- ----------------------- ----------------------- ----------------------- ----------------------- ----------------------- ----------------------- ----------------------- -----------E----------- -----------E----------- ----------------------- ----------------------- ----------------------- 
----------------------- ----------------------- --------BBBBBBB-------- --------BBBBBBB-------- --------BBBBBBB-------- --------BBBBBBB-------- --------BBBBBBB-------- --------BBBBBBB-------- --------BBBBBBB-------- --------BBBBBBB-------- --------BBBBBBB-------- ------BBBBBABBBBB------ ------BBBBBBBBBBB------ ------BBBBBBBBBBB------ ----------------------- ----------------------- ----------------------- ----------------------- ----------------------- ----------------------- ----------------------- ----------------------- ----------------------- -----------E----------- ----------------------- ----------------------- ----------------------- ----------------------- 
----------------------- ----------------------- ----------------------- ----------------------- ----------------------- ----------------------- ----------------------- ----------------------- ----------------------- ----------------------- ----------------------- --------BBBBBBB-------- --------BBBBBBB-------- --------BBBBBBB-------- ----------------------- ----------------------- ----------------------- ----------------------- ----------------------- ----------------------- ----------------------- ----------------------- ----------------------- ----------DED---------- ----------------------- ----------------------- ----------------------- ----------------------- 
----------------------- ----------------------- ----------------------- ----------------------- ----------------------- ----------------------- ----------------------- ----------------------- ----------------------- ----------------------- ----------------------- ----------------------- ----------------------- ----------------------- ----------------------- ----------------------- ----------------------- ----------------------- ----------------------- ----------------------- ----------------------- ----------------------- ---------DDDDD--------- ----------DFD---------- ----------------------- ----------------------- ----------------------- ----------------------- 
----------------------- ----------------------- ----------------------- ----------------------- ----------------------- ----------------------- ----------------------- ----------------------- ----------------------- ----------------------- ----------------------- ----------------------- ----------------------- ----------------------- ----------------------- ----------------------- ----------------------- ----------------------- ----------------------- ----------------------- ----------------------- ---------DDDDD--------- ---------DEFED--------- ----------------------- ----------------------- ----------------------- ----------------------- ----------------------- 
----------------------- ----------------------- ----------------------- ----------------------- ----------------------- ----------------------- ----------------------- ----------------------- ----------------------- ----------------------- ----------------------- ----------------------- ----------------------- ----------------------- ----------------------- ----------------------- ----------------------- ----------------------- ----------------------- ----------------------- ---------DDDDD--------- ---------DEFED--------- ----------------------- ----------------------- ----------------------- ----------------------- ----------------------- ----------------------- 
----------------------- ----------------------- ----------------------- ----------------------- ----------------------- ----------------------- ----------------------- ----------------------- ----------------------- ----------------------- ----------------------- ----------------------- ----------------------- ----------------------- ----------------------- ----------------------- ----------------------- -----------D----------- ----------DDD---------- ---------DDDDD--------- ---------DEFED--------- ----------------------- ----------------------- ----------------------- ----------------------- ----------------------- ----------------------- ----------------------- 
