model
size = 13 22 14, scale = 0.05, origin = -y
material 
  colors = A:#630 B:#111 C:#F96 D:#888 E:#930
voxels
------------- ------------- ------------- ------------- ------------- ------------- ------------- ------------- ------------- ------------- ------------- ------------- ------C------ ------------- ------------- ------------- ------------- ------------- ------------- ------------- ------------- ------------- 
------------- ------------- ------------- ------------- ------------- ------------- ------------- ------------- ------------- ------------- ------------- -----CCC----- ------C------ ------C------ ------------- ------------- ------------- ------------- ------------- ------------- ------------- ------------- 
-AE-------AA- -AA-------EA- -AA-------AA- -AA-------AA- -AA-------AA- -AA-------AE- -AA-------AA- -EAAAAAAAAAA- -AAAAAAAAAAA- -AAAAAAAAAAA- -----CCC----- ----CCCCC---- ----C-C-C---- -----CCC----- ------C------ ------------- ------------- ------------- -DD-----DD--- --DD-----DD-- ---DD-----DD- ------------- 
-AA-------AA- -AA-------AA- -AACCCCCCCAA- -AACCCCCCCAA- -AACCCCCCCAA- -AACCCCCCCAA- -AACCCCCCCAA- -AAAAAAAAAAA- -AAAAAAAAAAA- -AAAAAAAAAAA- -----CCC----- ----CCCCC---- ----CBCBC---- ----CCCCC---- ----CCCCC---- ----CCCCC---- ------------- BBBBBB-BBBBBB BBBBBBBBBBBBB BBBBBBBBBBBBB BBBBBBBBBBBBB BBBBBB-BBBBBB 
------------- ------------- ------------- ------------- ------------- ------------- ------------- ------------- ------------- ------------- ------------- ------------- ------------- ------------- ------------- ------------- ------------- ------------- ------------- ------------- ------------- B-----------B 
------------- ------------- ------------- ------------- ------------- ------------- ------------- ------------- ------------- ------------- ------------- ------------- ------------- ------------- ------------- ------------- ------------- ------------- ------------- ------------- ------------- B-----------B 
------------- ------------- ------------- ------------- ------------- ------------- ------------- ------------- ------------- ------------- ------------- ------------- ------------- ------------- ------------- ------------- ------------- ------------- ------------- ------------- ------------- B-----------B 
------------- ------------- ------------- ------------- ------------- ------------- ------------- ------------- ------------- ------------- ------------- ------------- ------------- ------------- ------------- ------------- ------------- ------------- ------------- ------------- ------------- B-----------B 
------------- ------------- ------------- ------------- ------------- ------------- ------------- ------------- ------------- ------------- ------------- ------------- ------------- ------------- ------------- ------------- ------------- ------------- ------------- ------------- ------------- B-----------B 
------------- ------------- ------------- ------------- ------------- ------------- ------------- ------------- ------------- ------------- ------------- ------------- ------------- ------------- ------------- ------------- ------------- ------------- ------------- ------------- ------------- B-----------B 
------------- ------------- ------------- ------------- ------------- ------------- ------------- ------------- ------------- ------------- ------------- ------------- ------------- ------------- ------------- ------------- ------------- ------------- ------------- ------------- B-----------B B-----------B 
------------- ------------- ------------- ------------- ------------- ------------- ------------- ------------- ------------- ------------- ------------- ------------- ------------- ------------- ------------- ------------- ------------- ------------- ------------- B-----------B B-----------B ------------- 
------------- ------------- ------------- ------------- ------------- ------------- ------------- ------------- ------------- ------------- ------------- ------------- ------------- ------------- ------------- ------------- ------------- ------------- B-----------B B-----------B ------------- ------------- 
------------- ------------- ------------- ------------- ------------- ------------- ------------- ------------- ------------- ------------- ------------- ------------- ------------- ------------- ------------- ------------- ------------- ------------- B-----------B ------------- ------------- ------------- 
