model
size = 15 27 14, scale = 0.05, origin = -y
material 
  colors = A:#630 B:#930 C:#111 D:#F99 E:#EEE F:#F9C
voxels
--------------- --------------- --------------- --------------- ------BBB------ -----BBBBB----- -----ABBBB----- -----BBBBB----- ----BBBBBAB---- ----BBBBBBB---- ----BBBBBBB---- ----BBBBBBB---- ----BBBBBBB---- ----BBBBBBB---- -----ABBBB----- --------------- --------------- --------------- --------------- --------------- --------------- --------------- --------------- --------------- --------------- --------------- --------------- 
--------------- --------------- ------BBB------ -----BABBB----- -----BBBBA----- -----BBBBB----- ----BBBBBBB---- ----ABBBBBB---- ---BBBBBBBBB--- ---BBBBBBBBB--- ---BBBBBBBBA--- ---BBBBBBBBB--- ---BBBBBBBBB--- ---ABBBBBBBB--- ---BBBBBBBBB--- ---BBBBAABBB--- -----BBBBB----- --------------- --------------- --------------- --------------- --------------- --------------- --------------- --------------- --------------- --------------- 
-------A------- ------AAA------ -----AAAAA----- ----AAAAAAA---- ----AAAAAAA---- ----AAAAAAA---- ---AAAAAAAAA--- ---AAAAAAAAA--- --AAAAAAAAAAA-- --AAAAAAAAAAA-- --AAAAAAAAAAA-- --AAAAAAAAAAA-- --AAAAAAAAAAA-- --AAAAAAAAAAA-- --AAAAAAAAAAA-- --AAAAAAAAAAA-- ---AAAAAAAAA--- -------D------- ------FDF------ ------DDD------ ------DDD------ --------------- --------------- --------------- --------------- --------------- --------------- 
-------A------- ------AAA------ -----AAAAA----- ----AAAAAAA---- ----AAAAAAA---- ----AAAAAAA---- ---AAAAAAAAA--- ---AAAAAAAAA--- --AAAAAAAAAAA-- --AAAAAAAAAAA-- --AAAAAAAAAAA-- --AAAAAAAAAAA-- --AAAAAAAAAAA-- --AAAAAAAAAAA-- --AAAAAAAAAAA-- --AAAAAAAAAAA-- ---AAAAAAAAA--- ------DDD------ -----DDDDD----- -----DDDDD----- ---CCDDDDDCC--- --CCCCDDDCCCC-- -CCCCCCDCCCCCC- CCEECCCCCEECCCC -CCEECC-CCEECC- --CCEC---CCEC-- ---CC-----CC--- 
--------------- --------------- --------------- --------------- --------------- --------------- --------------- --------------- --------------- --------------- --------------- --------------- --------------- --------------- --------------- --------------- --------------- --------------- --------------- --------------- --------------- --------------- --------------- --------------- -C-----------C- --------------- --------------- 
--------------- --------------- --------------- --------------- --------------- --------------- --------------- --------------- --------------- --------------- --------------- --------------- --------------- --------------- --------------- --------------- --------------- --------------- --------------- --------------- --------------- --------------- --------------- --------------- -C-----------C- --------------- --------------- 
--------------- --------------- --------------- --------------- --------------- --------------- --------------- --------------- --------------- --------------- --------------- --------------- --------------- --------------- --------------- --------------- --------------- --------------- --------------- --------------- --------------- --------------- --------------- --------------- -C-----------C- --------------- --------------- 
--------------- --------------- --------------- --------------- --------------- --------------- --------------- --------------- --------------- --------------- --------------- --------------- --------------- --------------- --------------- --------------- --------------- --------------- --------------- --------------- --------------- --------------- --------------- --------------- -C-----------C- --------------- --------------- 
--------------- --------------- --------------- --------------- --------------- --------------- --------------- --------------- --------------- --------------- --------------- --------------- --------------- --------------- --------------- --------------- --------------- --------------- --------------- --------------- --------------- --------------- --------------- --------------- -C-----------C- --------------- --------------- 
--------------- --------------- --------------- --------------- --------------- --------------- --------------- --------------- --------------- --------------- --------------- --------------- --------------- --------------- --------------- --------------- --------------- --------------- --------------- --------------- --------------- --------------- --------------- --------------- -C-----------C- --------------- --------------- 
--------------- --------------- --------------- --------------- --------------- --------------- --------------- --------------- --------------- --------------- --------------- --------------- --------------- --------------- --------------- --------------- --------------- --------------- --------------- --------------- --------------- --------------- --------------- -C-----------C- -C-----------C- --------------- --------------- 
--------------- --------------- --------------- --------------- --------------- --------------- --------------- --------------- --------------- --------------- --------------- --------------- --------------- --------------- --------------- --------------- --------------- --------------- --------------- --------------- --------------- --------------- -C-----------C- -C-----------C- --------------- --------------- --------------- 
--------------- --------------- --------------- --------------- --------------- --------------- --------------- --------------- --------------- --------------- --------------- --------------- --------------- --------------- --------------- --------------- --------------- --------------- --------------- --------------- --------------- -C-----------C- -C-----------C- --------------- --------------- --------------- --------------- 
--------------- --------------- --------------- --------------- --------------- --------------- --------------- --------------- --------------- --------------- --------------- --------------- --------------- --------------- --------------- --------------- --------------- --------------- --------------- --------------- --------------- -C-----------C- --------------- --------------- --------------- --------------- --------------- 
