model
size = 17 9 16, scale = 0.05, origin = -y
material 
  colors = A:#E00 B:#F60 C:#FC0
voxels
-A-------------A- ----------------- ----------------- ----------------- ----------------- ----------------- ----------------- ----------------- ----------------- 
-A-------------A- -A-------------A- -A-------------A- ----------------- ----------------- ----------------- ----------------- ----------------- ----------------- 
----------------- ----------------- -A-------------A- ----------------- ----------------- ----------------- ----------------- ----------------- ----------------- 
----------------- ----------------- -A-------------A- -A-------------A- ----------------- ----------------- ----------------- ----------------- ----------------- 
----------------- ----------------- ----------------- -A-------------A- ----------------- ----------------- ----------------- ----------------- ----------------- 
----------------- ----------------- ----------------- -A-------------A- ----------------- ----------------- ----------------- ----------------- ----------------- 
----------------- ----------------- ----------------- -A-------------A- ----------------- ----------------- ----------------- ----------------- ----------------- 
----------------- ----------------- ----------------- -A-------------A- ----------------- ----------------- ----------------- ----------------- ----------------- 
----------------- ----------------- ----------------- -A-------------A- ----------------- ----------------- ----------------- ----------------- ----------------- 
----------------- ----------------- ----------------- -A-------------A- ----------------- ----------------- ----------------- ----------------- ----------------- 
----------------- ----------------- ----------------- -A-------------A- ----------------- ----------------- ----------------- ----------------- ----------------- 
----------------- ----------------- -A-------------A- -A-------------A- ----------------- ----------------- ----------------- ----------------- ----------------- 
----------------- ----------------- -A-------------A- -A-------------A- -A-------------A- ----------------- ----------------- ----------------- ----------------- 
----------------- ----------------- -A-------------A- -A-------------A- -A-------------A- ----------------- ----------------- ----------------- ----------------- 
---A---------A--- --AAA-------AAA-- -AAAAA-----AAAAA- AAAAAAAAAAAAAAAAA -AAAAA-----AAAAA- --AAA-------AAA-- ---A---------A--- ----------------- ----------------- 
----------------- --ABB-------BBA-- -ABCCB-----BCCBA- -BCCBA-----ABCCB- -ABCBA-----ABCBA- -AABAB-----BABAA- --AAAA-----AAAA-- --BAA-------AAB-- ---A---------A--- 
