model
size = 5 32 15, scale = 0.05, origin = -y
material 
  colors = A:#3D1E00 B:#390 C:#F63 D:#A16031
voxels
62-11(C4-)7(A4-)A14-9(D4-)D3-12(3C2-)2(ACA2-)5(3A2-)3A8-2(10(D4-)D3-3C-55CA3C2A3C31A-3A3-)10(D4-)D3-3C-55CA3C2A3C31A-3A8-9(D4-)D3-12(3C2-)2(ACA2-)5(3A2-)3A68-11(C4-)7(A4-)A124-7(A4-)A69-11(B4-)7(A4-)A14-9(D4-)D3-12(3B2-)2(ABA2-)5(3A2-)3A8-2(10(D4-)D3-3B-55BA3B2A3B31A-3A3-)10(D4-)D3-3B-55BA3B2A3B31A-3A8-9(D4-)D3-12(3B2-)2(ABA2-)5(3A2-)3A68-11(B4-)7(A4-)A7-
