model
size = 11 31 11, scale = 0.05, origin = -y
material 
  colors = A:#070 B:#330 C:#960 D:#800
voxels
---AAAAA--- ---AAAAA--- ---AAAAA--- ---AAAAA--- ---AAAAA--- ---AAAAA--- ---BBBBB--- ---CBBCB--- ---BBBCB--- ---CBBBB--- ---CBBBB--- ---BBBBC--- ---BBBCB--- ---CBBCB--- ---CBBCB--- ---BCBBC--- ---BBBBB--- ---AAAAA--- ---AAAAA--- ----------- ----------- ----------- ----------- ----------- ----------- ----------- ----------- ----------- ----------- ----------- ----------- 
--AAAAAAA-- --AAAAAAA-- --AAAAAAA-- --AAAAAAA-- --AAAAAAA-- --AAAAAAA-- --BAAAAAB-- --BAAAAAB-- --BAAAAAB-- --BAAAAAC-- --BAAAAAB-- --BAAAAAB-- --BAAAAAB-- --BAAAAAB-- --BAAAAAB-- --BAAAAAB-- --BAAAAAB-- --AAAAAAA-- --AAAAAAA-- ---AAAAA--- ---AAAAA--- ----------- ----------- ----------- ----------- ----------- ----------- ----------- ----------- ----------- ----------- 
-AAAAAAAAA- -AAAAAAAAA- -AAAAAAAAA- -AAAAAAAAA- -AAAAAAAAA- -AAAAAAAAA- -AAAAAAAAA- -AAAAAAAAA- -AAAAAAAAA- -AAAAAAAAA- -AAAAAAAAA- -AAAAAAAAA- -AAAAAAAAA- -AAAAAAAAA- -AAAAAAAAA- -AAAAAAAAA- -AAAAAAAAA- -AAAAAAAAA- -AAAAAAAAA- --AAAAAAA-- --AAAAAAA-- ----AAA---- ----AAA---- ----------- ----------- ----------- ----------- ----------- ----------- ----------- ----------- 
AAAAAAAAAAA AAAAAAAAAAA AAAAAAAAAAA AAAAAAAAAAA AAAAAAAAAAA AAAAAAAAAAA AAAAAAAAAAA AAAAAAAAAAA AAAAAAAAAAA AAAAAAAAAAA AAAAAAAAAAA AAAAAAAAAAA AAAAAAAAAAA AAAAAAAAAAA AAAAAAAAAAA AAAAAAAAAAA AAAAAAAAAAA AAAAAAAAAAA AAAAAAAAAAA -AAAAAAAAA- -AAAAAAAAA- ---AAAAA--- ---AAAAA--- ----AAA---- ----------- ----------- ----------- ----------- ----------- ----AAA---- ----------- 
AAAAAAAAAAA AAAAAAAAAAA AAAAAAAAAAA AAAAAAAAAAA AAAAAAAAAAA AAAAAAAAAAA AAAAAAAAAAA AAAAAAAAAAA AAAAAAAAAAA AAAAAAAAAAA AAAAAAAAAAA AAAAAAAAAAA AAAAAAAAAAA AAAAAAAAAAA AAAAAAAAAAA AAAAAAAAAAA AAAAAAAAAAA AAAAAAAAAAA AAAAAAAAAAA -AAAAAAAAA- -AAAAAAAAA- --AAAAAAA-- --AAAAAAA-- ---AAAAA--- ----AAA---- ----AAA---- ----AAA---- ----AAA---- ----AAA---- ---ACCCA--- ----CCC---- 
AAAAAAAAAAA AAAAAAAAAAA AAAAAAAAAAA AAAAAAAAAAA AAAAAAAAAAA AAAAAAAAAAA AAAAAAAAAAA AAAAAAAAAAA AAAAAAAAAAA AAAAAAAAAAA AAAAAAAAAAA AAAAAAAAAAA AAAAAAAAAAA AAAAAAAAAAA AAAAAAAAAAA AAAAAAAAAAA AAAAAAAAAAA AAAAAAAAAAA AAAAAAAAAAA -AAAAAAAAA- -AAAAAAAAA- --AAAAAAA-- --AAAAAAA-- ---AAAAA--- ----AAA---- ----AAA---- ----AAA---- ----AAA---- ----ADA---- ---ACCCA--- ----CCC---- 
AAAAAAAAAAA AAAAAAAAAAA AAAAAAAAAAA AAAAAAAAAAA AAAAAAAAAAA AAAAAAAAAAA AAAAAAAAAAA AAAAAAAAAAA AAAAAAAAAAA AAAAAAAAAAA AAAAAAAAAAA AAAAAAAAAAA AAAAAAAAAAA AAAAAAAAAAA AAAAAAAAAAA AAAAAAAAAAA AAAAAAAAAAA AAAAAAAAAAA AAAAAAAAAAA -AAAAAAAAA- -AAAAAAAAA- --AAAAAAA-- --AAAAAAA-- ---AAAAA--- ----AAA---- ----AAA---- ----AAA---- ----AAA---- ----AAA---- ---ACCCA--- ----CCC---- 
AAAAAAAAAAA AAAAAAAAAAA AAAAAAAAAAA AAAAAAAAAAA AAAAAAAAAAA AAAAAAAAAAA AAAAAAAAAAA AAAAAAAAAAA AAAAAAAAAAA AAAAAAAAAAA AAAAAAAAAAA AAAAAAAAAAA AAAAAAAAAAA AAAAAAAAAAA AAAAAAAAAAA AAAAAAAAAAA AAAAAAAAAAA AAAAAAAAAAA AAAAAAAAAAA -AAAAAAAAA- -AAAAAAAAA- ---AAAAA--- ---AAAAA--- ----AAA---- ----------- ----------- ----------- ----------- ----------- ----AAA---- ----------- 
-AAAAAAAAA- -AAAAAAAAA- -AAAAAAAAA- -AAAAAAAAA- -AAAAAAAAA- -AAAAAAAAA- -AAAAAAAAA- -AAAAAAAAA- -AAAAAAAAA- -AAAAAAAAA- -AAAAAAAAA- -AAAAAAAAA- -AAAAAAAAA- -AAAAAAAAA- -AAAAAAAAA- -AAAAAAAAA- -AAAAAAAAA- -AAAAAAAAA- -AAAAAAAAA- --AAAAAAA-- --AAAAAAA-- ----AAA---- ----AAA---- ----------- ----------- ----------- ----------- ----------- ----------- ----------- ----------- 
--AAAAAAA-- --AAAAAAA-- --AAAAAAA-- --AAAAAAA-- --AAAAAAA-- --AAAAAAA-- --AAAAAAA-- --AAAAAAA-- --AAAAAAA-- --AAAAAAA-- --AAAAAAA-- --AAAAAAA-- --AAAAAAA-- --AAAAAAA-- --AAAAAAA-- --AAAAAAA-- --AAAAAAA-- --AAAAAAA-- --AAAAAAA-- ---AAAAA--- ---AAAAA--- ----------- ----------- ----------- ----------- ----------- ----------- ----------- ----------- ----------- ----------- 
---AAAAA--- ---AAAAA--- ---AAAAA--- ---AAAAA--- ---AAAAA--- ---AAAAA--- ---AAAAA--- ---AAAAA--- ---AAAAA--- ---AAAAA--- ---AAAAA--- ---AAAAA--- ---AAAAA--- ---AAAAA--- ---AAAAA--- ---AAAAA--- ---AAAAA--- ---AAAAA--- ---AAAAA--- ----------- ----------- ----------- ----------- ----------- ----------- ----------- ----------- ----------- ----------- ----------- ----------- 
