model
size = 31 17 31, scale = 0.05, origin = -y
material 
  colors = A:#FABA3B B:#78552B C:#7BA23F D:#FFB11B E:#E83015 F:#EEE G:#FFD857
voxels
------------------------------- ------------------------------- ------------------------------- ------------CCCCCCC------------ ------------------------------- ------------------------------- ------------------------------- ------------------------------- ------------------------------- ------------------------------- ------------------------------- ------------------------------- ------------------------------- ------------------------------- ------------------------------- ------------------------------- ------------------------------- 
-------------AAAAA------------- ------------AAAAAAA------------ ------------AAAAAAA------------ ---------CCCCCCCCCCCCC--------- ------------------------------- ------------BBBBBBB------------ ------------------------------- ------------------------------- ------------------------------- ------------------------------- ------------CCCCCCC------------ ------------------------------- ------------------------------- ------------------------------- ------------------------------- ------------------------------- ------------------------------- 
----------AAAAAAAAAAA---------- ---------AAAAAAAAAAAAA--------- ---------AAAAAAAAAAAAA--------- -------CCCCCCCCCCCCCCCCC------- ------------BBBBBBB------------ ---------BBBBBBBBBBBBB--------- ------------BBBBBBB------------ ------------------EEEEE-------- ------FFFFF-------------------- --DDDDDDDDDDDDDDDDDDDDDDDDDDD-- ---------CCCCCCCCCCCCC--------- ------------AAAAAGA------------ ------------AGAAAAA------------ ------------------------------- ------------------------------- ------------------------------- ------------------------------- 
--------AAAAAAAAAAAAAAA-------- -------AAAAAAAAAAAAAAAAA------- -------AAAAAAAAAAAAAAAAA------- ------CCCCCCCCCCCCCCCCCCC------ ---------BBBBBBBBBBBBB--------- -------BBBBBBBBBBBBBBBBB------- ---------BBBBBBBBBBBBB--------- -----------------EEEEEEE------- ----FF-----FF------------------ --DDDDDDDDDDDDDDDDDDDDDDDDDDD-- -------CCCCCCCCCCCCCCCCC------- ---------AAAAAAAAAAAAA--------- ---------GAAAAAAAAAAAG--------- ------------AAAAAGA------------ ------------------------------- ------------------------------- ------------------------------- 
-------AAAAAAAAAAAAAAAAA------- ------AAAAAAAAAAAAAAAAAAA------ ------AAAAAAAAAAAAAAAAAAA------ -----CCCCCCCCCCCCCCCCCCCCC----- --------BBBBBBBBBBBBBBB-------- ------BBBBBBBBBBBBBBBBBBB------ --------BBBBBBBBBBBBBBB-------- ----------------EEEEEEEEE------ ---FF-------FF----------------- --DDDDDDDDDDDDDDDDDDDDDDDDDDD-- ------CCCCCCCCCCCCCCCCCCC------ --------GAAAAAAAAAAAAAA-------- --------GAAAAAAAAAAAAAA-------- ----------GGAAAAAAAAG---------- ------------GAAAAGA------------ ------------------------------- ------------------------------- 
------AAAAAAAAAAAAAAAAAAA------ -----AAAAAAAAAAAAAAAAAAAAA----- -----AAAAAAAAAAAAAAAAAAAAA----- ----CCCCCCCCCCCCCCCCCCCCCCC---- ------BBBBBBBBBBBBBBBBBBB------ -----BBBBBBBBBBBBBBBBBBBBB----- ------BBBBBBBBBBBBBBBBBBB------ ----EEEEE------EEEEEEEEEEE----- ---F---------F----------------- --DDDDDDDDDDDDDDDDDDDDDDDDDDD-- -----CCCCCCCCCCCCCCCCCCCCC----- ------AAAAAAAAAAAAAAAAAAA------ ------AAAAAAAAAAAAAAAAAAA------ --------AAAAAAAAAAAAAAG-------- ----------AAAAAAAAAAA---------- ------------------------------- ------------------------------- 
-----AAAAAAAAAAAAAAAAAAAAA----- ----AAAAAAAAAAAAAAAAAAAAAAA---- ----AAAAAAAAAAAAAAAAAAAAAAA---- ---CCCCCCCCCCCCCCCCCCCCCCCCC--- -----BBBBBBBBBBBBBBBBBBBBB----- ----BBBBBBBBBBBBBBBBBBBBBBB---- -----BBBBBBBBBBBBBBBBBBBBB----- ---EEEEEEE-----EEEEEEEEEEE----- --F-----------F---------------- --DDDDDDDDDDDDDDDDDDDDDDDDDDD-- ----CCCCCCCCCCCCCCCCCCCCCCC---- -----AAAAAAAAAAAAAAAAAAAAA----- -----GAAAAAAAAAAAAAAAAAAAG----- -------AAAAAAAAAAAAAAAAA------- --------AAAAAAAAAAAAAGG-------- ------------AAAGAAA------------ ------------------------------- 
----AAAAAAAAAAAAAAAAAAAAAAA---- ---AAAAAAAAAAAAAAAAAAAAAAAAA--- ---AAAAAAAAAAAAAAAAAAAAAAAAA--- --CCCCCCCCCCCCCCCCCCCCCCCCCCC-- -----BBBBBBBBBBBBBBBBBBBBB----- ---BBBBBBBBBBBBBBBBBBBBBBBBB--- -----BBBBBBBBBBBBBBBBBBBBB----- --EEEEEEEEE----EEEEE-EEEEE----- --F-----------F----FFFFF------- --DDDDDDDDDDDDDDDDDDDDDDDDDDD-- ---CCCCCCCCCCCCCCCCCCCCCCCCC--- -----AAAAAAAAAAAAAAAAAAAAA----- -----AAAAAAAAAAAAAAAAAAAAA----- ------AAAAAAAAAAAAAAAAAAA------ -------AGAAAAAAAAAAAAAAG------- ----------GAAAAAGAGAA---------- ------------------------------- 
---AAAAAAAAAAAAAAAAAAAAAAAAA--- ---AAAAAAAAAAAAAAAAAAAAAAAAA--- ---AAAAAAAAAAAAAAAAAAAAAAAAA--- --CCCCCCCCCCCCCCCCCCCCCCCCCCC-- ----BBBBBBBBBBBBBBBBBBBBBBB---- ---BBBBBBBBBBBBBBBBBBBBBBBBB--- ----BBBBBBBBBBBBBBBBBBBBBBB---- --EEEEEEEEE----EEEEEEEEEEE----- --F-----------F--FF-----FF----- --DDDDDDDDDDDDDDDDDDDDDDDDDDD-- ---CCCCCCCCCCCCCCCCCCCCCCCCC--- ----GAAAAAAAAAAAAAAAAAAAAAA---- ----AAAAAAAAAAAAAAAAAAAAAAA---- -----GAAAAAAAAAAAAAAAAAAAA----- ------AAAAAAAAAAAAAAAAGAA------ ---------AAAAGAAAAAAAA--------- ------------------------------- 
---AAAAAAAAAAAAAAAAAAAAAAAAA--- --AAAAAAAAAAAAAAAAAAAAAAAAAAA-- --AAAAAAAAAAAAAAAAAAAAAAAAAAA-- -CCCCCCCCCCCCCCCCCCCCCCCCCCCCC- ---BBBBBBBBBBBBBBBBBBBBBBBBB--- --BBBBBBBBBBBBBBBBBBBBBBBBBBB-- ---BBBBBBBBBBBBBBBBBBBBBBBBB--- --EEEE-EEEE----EEEEEEEEEEE----- --F-----------F-FF-------FF---- --DDDDDDDDDDDDDDDDDDDDDDDDDDD-- --CCCCCCCCCCCCCCCCCCCCCCCCCCC-- ---GAAAAAAAAAAAAAAAAAAAAAAAA--- ---AGAAAAAAAAAAAAAAAAAAAAAGG--- -----AAAAAAAAAAAAAAAAAAAAA----- ------AAAAAAAAAAAAAAAAAAA------ --------AAAAAAAAAAAAAAG-------- ------------------------------- 
--AAAAAAAAAAAAAAAAAAAAAAAAAAA-- --AAAAAAAAAAAAAAAAAAAAAAAAAAA-- --AAAAAAAAAAAAAAAAAAAAAAAAAAA-- -CCCCCCCCCCCCCCCCCCCCCCCCCCCCC- ---BBBBBBBBBBBBBBBBBBBBBBBBB--- --BBBBBBBBBBBBBBBBBBBBBBBBBBB-- ---BBBBBBBBBBBBBBBBBBBBBBBBB--- --EEEEEEEEE-----EEEEEEEEE------ --F-----------F-F---------F---- --DDDDDDDDDDDDDDDDDDDDDDDDDDD-- --CCCCCCCCCCCCCCCCCCCCCCCCCCC-- ---AAAAAAAAAAAAAAAAAAAAAAAAA--- ---AAAAAAAAAAAAAAAAAAAAAAAAG--- ----AAAAAAAAAAAAAAAAAAAAAAA---- -----AAAAAAAAAAAAAAAAAAAAA----- -------AAAAAAAAAAAAAAAAA------- ------------------------------- 
--AAAAAAAAAAAAAAAAAAAAAAAAAAA-- --AAAAAAAAAAAAAAAAAAAAAAAAAAA-- --AAAAAAAAAAAAAAAAAAAAAAAAAAA-- -CCCCCCCCCCCCCCCCCCCCCCCCCCCCC- ---BBBBBBBBBBBBBBBBBBBBBBBBB--- --BBBBBBBBBBBBBBBBBBBBBBBBBBB-- ---BBBBBBBBBBBBBBBBBBBBBBBBB--- --EEEEEEEEE-EEEEEEEEEEEE------- ---F---------F-F-----------F--- --DDDDDDDDDDDDDDDDDDDDDDDDDDD-- --CCCCCCCCCCCCCCCCCCCCCCCCCCC-- ---GAAAAAAAAAAAAAAAAAAAAAAAA--- ---AAAAAAAAAAAAAAAAAAAAAAAAA--- ----AAAAAAAAAAAAAAAAAAAAAAA---- -----GAAAAAAAAAAAAAAAAAAAA----- -------AGAGGAAAAAAAAGGAA------- -------------AAGAA------------- 
--AAAAAAAAAAAAAAAAAAAAAAAAAAA-- -AAAAAAAAAAAAAAAAAAAAAAAAAAAAA- -AAAAAAAAAAAAAAAAAAAAAAAAAAAAA- CCCCCCCCCCCCCCCCCCCCCCCCCCCCCCC --BBBBBBBBBBBBBBBBBBBBBBBBBBB-- -BBBBBBBBBBBBBBBBBBBBBBBBBBBBB- --BBBBBBBBBBBBBBBBBBBBBBBBBBB-- ---EEEEEEEEEEEEEEEEEEEE-------- ---FF-------FF-F-----------F--- --DDDDDDDDDDDDDDDDDDDDDDDDDDD-- -CCCCCCCCCCCCCCCCCCCCCCCCCCCCC- --AAAAAAAAAAAAAAAAAAAAAAAAAAA-- --AAAAAAAAAAAAAAAAAAAAAAAAAAA-- ---GAAAAAAAAAAAAAAAAAAAAAAAA--- ----AAAAAAAAAAAAAAAAAAAAAAG---- ------AAAAAAAAAAAAAAAAAAA------ ------------AAAAAAA------------ 
-AAAAAAAAAAAAAAAAAAAAAAAAAAAAA- -AAAAAAAAAAAAAAAAAAAAAAAAAAAAA- -AAAAAAAAAAAAAAAAAAAAAAAAAAAAA- CCCCCCCCCCCCCCCCCCCCCCCCCCCCCCC --BBBBBBBBBBBBBBBBBBBBBBBBBBB-- -BBBBBBBBBBBBBBBBBBBBBBBBBBBBB- --BBBBBBBBBBBBBBBBBBBBBBBBBBB-- ----EEEEEEEEEEEEEEEEEE--------- ----FF-----FF--F-----------F--- --DDDDDDDDDDDDDDDDDDDDDDDDDDD-- -CCCCCCCCCCCCCCCCCCCCCCCCCCCCC- --GAAAAAAAAAAAAAAAAAAAAAAAAAA-- --GAAAAAAAAAAAAAAAAAAAAAAAAAA-- ---AAAAAAAAAAAAAAAAAAAAAAAAA--- ----AAAAAAAAAAAAAAAAAAAAAAA---- ------GAAAAAAAAAAAAAAAGAA------ -----------AAAAAAAAA----------- 
-AAAAAAAAAAAAAAAAAAAAAAAAAAAAA- -AAAAAAAAAAAAAAAAAAAAAAAAAAAAA- -AAAAAAAAAAAAAAAAAAAAAAAAAAAAA- CCCCCCCCCCCCCCCCCCCCCCCCCCCCCCC --BBBBBBBBBBBBBBBBBBBBBBBBBBB-- -BBBBBBBBBBBBBBBBBBBBBBBBBBBBB- --BBBBBBBBBBBBBBBBBBBBBBBBBBB-- --------EEEEEEEEEEEEEEE-------- ------FFFFF-FFFFF----------F--- --DDDDDDDDDDDDDDDDDDDDDDDDDDD-- -CCCCCCCCCCCCCCCCCCCCCCCCCCCCC- --AAAAAAAAAAAAAAAAAAAAAAAAAAA-- --AAAAAAAAAAAAAAAAAAAAAAAAAAG-- ---AAAAAAAAAAAAAAAAAAAAAAAAA--- ----GAAAAAAAAAAAAAAAAAAAAAG---- ------AAAAAAAAAAAAAAAAAAA------ -----------AGAAAAAAA----------- 
-AAAAAAAAAAAAAAAAAAAAAAAAAAAAA- -AAAAAAAAAAAAAACAAAAAAAAAAAAAA- -AAAAAAAAAAAAAACAAAAAAAAAAAAAA- CCCCCCCCCCCCCCCBCCCCCCCCCCCCCCC --BBBBBBBBBBBBBBBBBBBBBBBBBBB-- -BBBBBBBBBBBBBBBBBBBBBBBBBBBBB- --BBBBBBBBBBBBB-BBBBBBBBBBBBB-- -------EEEEEEEEEEEEEEEEE------- ----------FF---F-FF--------F--- --DDDDDDDDDDDDDDDDDDDDDDDDDDD-- -CCCCCCCCCCCCCCCCCCCCCCCCCCCCC- --AAAAAAAAAAAAAAAAAAAAAAAAAAA-- --GAAAAAAAAAAAAAAAAAAAAAAAAAG-- ---AAAAAAAAAAAAAAAAAAAAAAAAA--- ----AAAAAAAAAAAAAAAAAAAAAAA---- ------AAAAAAAAAAAAAAAAGAA------ -----------AAAAAAGAA----------- 
-AAAAAAAAAAAAAAAAAAAAAAAAAAAAA- -AAAAAAAAAAAAAAAAAAAAAAAAAAAAA- -AAAAAAAAAAAAAAAAAAAAAAAAAAAAA- CCCCCCCCCCCCCCCCCCCCCCCCCCCCCCC --BBBBBBBBBBBBBBBBBBBBBBBBBBB-- -BBBBBBBBBBBBBBBBBBBBBBBBBBBBB- --BBBBBBBBBBBBBBBBBBBBBBBBBBB-- -------EEEEEEEEEEEEEEEEE------- ---------F------F--F------F---- --DDDDDDDDDDDDDDDDDDDDDDDDDDD-- -CCCCCCCCCCCCCCCCCCCCCCCCCCCCC- --AAAAAAAAAAAAAAAAAAAAAAAAAAA-- --AAAAAAAAAAAAAAAAAAAAAAAAAAA-- ---AAAAAAAAAAAAAAAAAAAAAAAAG--- ----AAAAAAAAAAAAAAAAAAAAAAA---- ------AAAAAAAAAAAAAAAAAGG------ -----------AAAAAAAAA----------- 
-AAAAAAAAAAAAAAAAAAAAAAAAAAAAA- -AAAAAAAAAAAAAAAAAAAAAAAAAAAAA- -AAAAAAAAAAAAAAAAAAAAAAAAAAAAA- CCCCCCCCCCCCCCCCCCCCCCCCCCCCCCC --BBBBBBBBBBBBBBBBBBBBBBBBBBB-- -BBBBBBBBBBBBBBBBBBBBBBBBBBBBB- --BBBBBBBBBBBBBBBBBBBBBBBBBBB-- ------EEEEEEEEEEEEEEEEEEE------ --------F-------FF--F----FF---- --DDDDDDDDDDDDDDDDDDDDDDDDDDD-- -CCCCCCCCCCCCCCCCCCCCCCCCCCCCC- --AAAAAAAAAAAAAAAAAAAAAAAAAAA-- --AAAAAAAAAAAAAAAAAAAAAAAAAAA-- ---AAAAAAAAAAAAAAAAAAAAAAAAA--- ----AAAAAAAAAAAAAAAAAAAAAAA---- ------AAAGAAAAAAAAAAAAAAA------ -----------AAAGAAAAA----------- 
--AAAAAAAAAAAAAAAAAAAAAAAAAAA-- -AAAAAAAAAAAAAAAAAAAAAAAAAAAAA- -AAAAAAAAAAAAAAAAAAAAAAAAAAAAA- CCCCCCCCCCCCCCCCCCCCCCCCCCCCCCC --BBBBBBBBBBBBBBBBBBBBBBBBBBB-- -BBBBBBBBBBBBBBBBBBBBBBBBBBBBB- --BBBBBBBBBBBBBBBBBBBBBBBBBBB-- ------EEEEEEEEEEEEEEEEEEE------ --------F--------FF-F---FF----- --DDDDDDDDDDDDDDDDDDDDDDDDDDD-- -CCCCCCCCCCCCCCCCCCCCCCCCCCCCC- --GAAAAAAAAAAAAAAAAAAAAAAAAAA-- --GAAAAAAAAAAAAAAAAAAAAAAAAAA-- ---GAAAAAAAAAAAAAAAAAAAAAAAA--- ----GAAAAAAAAAAAAAAAAAAAAAA---- ------AAAAAAAAAAAAAAAAGAG------ ------------AAAAAAA------------ 
--AAAAAAAAAAAAAAAAAAAAAAAAAAA-- --AAAAAAAAAAAAAAAAAAAAAAAAAAA-- --AAAAAAAAAAAAAAAAAAAAAAAAAAA-- -CCCCCCCCCCCCCCCCCCCCCCCCCCCCC- ---BBBBBBBBBBBBBBBBBBBBBBBBB--- --BBBBBBBBBBBBBBBBBBBBBBBBBBB-- ---BBBBBBBBBBBBBBBBBBBBBBBBB--- ------EEEEEEEEEEEEEEEEEEE------ -------F-----------FFFFF------- --DDDDDDDDDDDDDDDDDDDDDDDDDDD-- --CCCCCCCCCCCCCCCCCCCCCCCCCCC-- ---AAAAAAAAAAAAAAAAAAAAAAAAA--- ---AAAAAAAAAAAAAAAAAAAAAAAAA--- ----AAAAAAAAAAAAAAAAAAAAAAA---- -----AAAAAAAAAAAAAAAAAAAAA----- -------AAAAAAAAAAAAAGAAG------- -------------AAAAA------------- 
--AAAAAAAAAAAAAAAAAAAAAAAAAAA-- --AAAAAAAAAAAAAAAAAAAAAAAAAAA-- --AAAAAAAAAAAAAAAAAAAAAAAAAAA-- -CCCCCCCCCCCCCCCCCCCCCCCCCCCCC- ---BBBBBBBBBBBBBBBBBBBBBBBBB--- --BBBBBBBBBBBBBBBBBBBBBBBBBBB-- ---BBBBBBBBBBBBBBBBBBBBBBBBB--- ------EEEEEEEEE-EEEEEEEEE------ -------F-------------F--------- --DDDDDDDDDDDDDDDDDDDDDDDDDDD-- --CCCCCCCCCCCCCCCCCCCCCCCCCCC-- ---GAAAAAAAAAAAAAAAAAAAAAAAA--- ---GAAAAAAAAAAAAAAAAAAAAAAAA--- ----AAAAAAAAAAAAAAAAAAAAAAA---- -----AAAAAAAAAAAAAAAAAAAAG----- -------AAAGAGAAAAAAAAAAA------- ------------------------------- 
---AAAAAAAAAAAAAAAAAAAAAAAAA--- --AAAAAAAAAAAAAAAAAAAAAAAAAAA-- --AAAAAAAAAAAAAAAAAAAAAAAAAAA-- -CCCCCCCCCCCCCCCCCCCCCCCCCCCCC- ---BBBBBBBBBBBBBBBBBBBBBBBBB--- --BBBBBBBBBBBBBBBBBBBBBBBBBBB-- ---BBBBBBBBBBBBBBBBBBBBBBBBB--- ------EEEEEEEEEEEEEEEEEEE------ -------F-------------F--------- --DDDDDDDDDDDDDDDDDDDDDDDDDDD-- --CCCCCCCCCCCCCCCCCCCCCCCCCCC-- ---AAAAAAAAAAAAAAAAAAAAAAAAA--- ---AAAAAAAAAAAAAAAAAAAAAAAAA--- -----AAAAAAAAAAAAAAAAAAAAA----- ------AAAAAAAAAAAAAAAAAAA------ --------AAAAAAAAAAAAAAA-------- ------------------------------- 
---AAAAAAAAAAAAAAAAAAAAAAAAA--- ---AAAAAAAAAAAAAAAAAAAAAAAAA--- ---AAAAAAAAAAAAAAAAAAAAAAAAA--- --CCCCCCCCCCCCCCCCCCCCCCCCCCC-- ----BBBBBBBBBBBBBBBBBBBBBBB---- ---BBBBBBBBBBBBBBBBBBBBBBBBB--- ----BBBBBBBBBBBBBBBBBBBBBBB---- ------EEEEEEEEEEEEEEEEEEE------ -------F-------------F--------- --DDDDDDDDDDDDDDDDDDDDDDDDDDD-- ---CCCCCCCCCCCCCCCCCCCCCCCCC--- ----AAAAAAAAAAAAAAAAAAAAAAA---- ----GAAAAAAAAAAAAAAAAAAAAAG---- -----GAAAAAAAAAAAAAAAAAAAA----- ------AAAAAAAAAAAAAAAAGAA------ ---------AAAAAAAAAAAAA--------- ------------------------------- 
----AAAAAAAAAAAAAAAAAAAAAAA---- ---AAAAAAAAAAAAAAAAAAAAAAAAA--- ---AAAAAAAAAAAAAAAAAAAAAAAAA--- --CCCCCCCCCCCCCCCCCCCCCCCCCCC-- -----BBBBBBBBBBBBBBBBBBBBB----- ---BBBBBBBBBBBBBBBBBBBBBBBBB--- -----BBBBBBBBBBBBBBBBBBBBB----- ------EEEEEEEEEEEEEEEEEEE------ -------F-------------F--------- --DDDDDDDDDDDDDDDDDDDDDDDDDDD-- ---CCCCCCCCCCCCCCCCCCCCCCCCC--- -----AAAAAAAAAAAAAAAAAAAAA----- -----AAAAAAAAAAAAAAAAAAAAA----- ------AAAAAAAAAAAAAAAAAAG------ -------AGAAAAAAAAAAAAAAA------- ----------GAAAAAAGAAA---------- ------------------------------- 
-----AAAAAAAAAAAAAAAAAAAAA----- ----AAAAAAAAAAAAAAAAAAAAAAA---- ----AAAAAAAAAAAAAAAAAAAAAAA---- ---CCCCCCCCCCCCCCCCCCCCCCCCC--- -----BBBBBBBBBBBBBBBBBBBBB----- ----BBBBBBBBBBBBBBBBBBBBBBB---- -----BBBBBBBBBBBBBBBBBBBBB----- -------EEEEEEEEEEEEEEEEE------- --------F-----------F---------- --DDDDDDDDDDDDDDDDDDDDDDDDDDD-- ----CCCCCCCCCCCCCCCCCCCCCCC---- -----AAAAAAAAAAAAAAAAAAAAA----- -----AAAAAAAAAAAAAAAAAAAAA----- -------AAAAAAAAAAAAAAAAA------- --------GAAAAAAAAAAAGAA-------- ------------AAGAAAA------------ ------------------------------- 
------AAAAAAAAAAAAAAAAAAA------ -----AAAAAAAAAAAAAAAAAAAAA----- -----AAAAAAAAAAAAAAAAAAAAA----- ----CCCCCCCCCCCCCCCCCCCCCCC---- ------BBBBBBBBBBBBBBBBBBB------ -----BBBBBBBBBBBBBBBBBBBBB----- ------BBBBBBBBBBBBBBBBBBB------ -------EEEEEEEEEEEEEEEEE------- --------F-----------F---------- --DDDDDDDDDDDDDDDDDDDDDDDDDDD-- -----GCCCCCCCCCCCCCCCCCCCC----- ------AAAAAAAAAAAAAAAAAAA------ ------AAAAAAAAAAAAAAAAAAA------ --------GGAAAAAAAAAAAAA-------- ----------AGAAAAGGAAG---------- ------------------------------- ------------------------------- 
-------AAAAAAAAAAAAAAAAA------- ------AAAAAAAAAAAAAAAAAAA------ ------AAAAAAAAAAAAAAAAAAA------ -----CCCCCCCCCCCCCCCCCCCCC----- --------BBBBBBBBBBBBBBB-------- ------BBBBBBBBBBBBBBBBBBB------ --------BBBBBBBBBBBBBBB-------- --------EEEEEEEEEEEEEEE-------- ---------F---------F----------- --DDDDDDDDDDDDDDDDDDDDDDDDDDD-- ------CCCCCCCCCCCCCCCCCCC------ --------AAAAAAAAAAAAAAA-------- --------GAAAAAAAAAAAAAA-------- ----------AAAAAAAAAAA---------- ------------AAAAAAA------------ ------------------------------- ------------------------------- 
--------AAAAAAAAAAAAAAA-------- -------AAAAAAAAAAAAAAAAA------- -------AAAAAAAAAAAAAAAAA------- ------CCCCCCCCCCCCCCCCCCC------ ---------BBBBBBBBBBBBB--------- -------BBBBBBBBBBBBBBBBB------- ---------BBBBBBBBBBBBB--------- ---------EEEEEEEEEEEEE--------- ----------FF-----FF------------ --DDDDDDDDDDDDDDDDDDDDDDDDDDD-- -------CCCCCCCCCCCCCCCCC------- ---------AAAAAAAAAAAAA--------- ---------AAAAAAAAAAAAG--------- ------------AGGGGAA------------ ------------------------------- ------------------------------- ------------------------------- 
----------AAAAAAAAAAA---------- ---------AAAAAAAAAAAAA--------- ---------AAAAAAAAAAAAA--------- -------CCCCCCCCCCCCCCCCC------- ------------BBBBBBB------------ ---------BBBBBBBBBBBBB--------- ------------BBBBBBB------------ ----------EEEEEEEEEEE---------- ------------FFFFF-------------- --DDDDDDDDDDDDDDDDDDDDDDDDDDD-- ---------GCCCCCCCCCCCC--------- ------------AAGAAAA------------ ------------AAAAAAA------------ ------------------------------- ------------------------------- ------------------------------- ------------------------------- 
-------------AAAAA------------- ------------AAAAAAA------------ ------------AAAAAAA------------ ---------CCCCCCCCCCCCC--------- ------------------------------- ------------BBBBBBB------------ ------------------------------- ------------EEEEEEE------------ ------------------------------- ------------------------------- ------------CCCCCCC------------ ------------------------------- ------------------------------- ------------------------------- ------------------------------- ------------------------------- ------------------------------- 
------------------------------- ------------------------------- ------------------------------- ------------CCCCCCC------------ ------------------------------- ------------------------------- ------------------------------- ------------------------------- ------------------------------- ------------------------------- ------------------------------- ------------------------------- ------------------------------- ------------------------------- ------------------------------- ------------------------------- ------------------------------- 
