model
size = 11 29 31, scale = 0.05, origin = -y
material 
  colors = A:#FF0 B:#F60 C:#D00 D:#F30 E:#F63 F:#0F3 G:#FC0 H:#F90 I:#090 J:#008 K:#EEE L:#963 M:#222 N:#555 O:#F0F
voxels
----------- ----------- ----------- ----------- ----------- ----------- ----------- ----------- ----------- ----------- ----------- ----------- ----------- ----------- ----------- ----------- ----------- ----------- ----------- ----------- ----------- -----N----- -----N----- ----------- ----------- ----------- ----------- ----------- ----------- 
----------- ----------- ----------- ----------- ----------- ----------- ----------- ----------- ----------- ----------- ----------- ----------- ----------- ----------- ----------- ----------- ----------- ----------- ----------- ----------- ----------- -----N----- ----NNN---- -----N----- ----------- ----------- ----------- ----------- ----------- 
----------- ----------- ----------- ----------- ----------- ----------- ----------- ----------- ----------- ----------- ----------- ----------- ----------- ----------- ----------- ----------- ----------- ----------- ----------- ----------- ----------- ----NNN---- -----N----- ----NNN---- -----N----- ----------- ----------- ----------- ----------- 
----------- ----------- ----------- ----------- ----------- ----------- ----------- ----------- ----------- ----------- ----------- ----------- ----------- ----------- ----------- ----------- ----------- ----------- ----------- ----------- ----------- ----DDD---- ---CCDCC--- ---DDDDD--- ---DDDDD--- ----DDD---- ----------- ----------- ----------- 
----------- ----------- ----------- ----------- ----------- ----------- ----------- ----------- ----------- ----------- ----------- ----------- ----------- ----------- ----------- ----------- ----------- ----------- ----------- ----------- ----DDD---- ---CCCCC--- ---CCCCC--- ---CCCCC--- ---CCCCC--- ---CCCCC--- ---DDEDD--- ----------- ----------- 
----------- ----------- ----------- ----------- ----------- ----------- ----------- ----------- ----------- ----------- ----------- ----------- ----------- ----------- ----------- ----------- ----------- ----------- ----------- ----------- ---CCCCC--- ---CCCCC--- ---CCCCC--- ---KKKKK--- ---KKKKK--- ---KKKKK--- ---CCCCC--- ---DDODD--- ----------- 
----------- ----------- ----------- ----------- ----------- ----------- ----------- ----------- ----------- ----------- ----------- ----------- ----------- ----------- ----------- ----------- ----------- ----------- ----------- -----D----- ---CCCCC--- ---CCCCC--- ---CCCCC--- ---KKKKK--- ---MMMMM--- ---KKKKK--- ---CCCCC--- ---CCCCC--- ----DED---- 
----------- ----------- ----------- ----------- ----------- ----------- ----------- ----------- ----------- ----------- ----------- ----HBH---- ---HBBBH--- ---BBHBB--- ----HBH---- ----BDB---- ----DED---- ----BBB---- ----HHH---- ----CCC---- ---BBBBB--- ---CCCCC--- ---CCCCC--- ---KKKKK--- ---KKKKK--- ---KKKKK--- ---CCCCC--- ---CCCCC--- ---DEDED--- 
----------- ----------- ----------- ----------- ----------- ----------- ----------- ----------- ----------- ----------- --HBBHBBH-- --BHHHHHB-- --HHHHHHH-- --BBBBBBB-- --DDDDDDD-- --BBBBBBB-- --EEEEEEE-- --HHHHHHH-- --ECEEECE-- ---BBBBB--- ---DDDDD--- ---CCCCC--- ---CCCCC--- ---CCCCC--- ---CCCCC--- ---CCCCC--- ---CCCCC--- ---CCCCC--- ---DDDDD--- 
----------- ----------- ----------- ----------- ----------- ----------- ----------- ----------- --BHHHHHB-- --HHHBHHH-- --EEEEEEE-- -BBBBBBBBB- -BBBBBBBBB- -DDDDDDDDD- -BBBBBBBBB- -EEEEEEEEE- -BBBBBBBBB- --EEEEEEE-- --HHHHHHH-- ---BBBBB--- ---EEEEE--- ---DDDDD--- ---CCCCC--- ---CCCCC--- ---CCCCC--- ---CCCCC--- ---CCCCC--- ---EEEEE--- ---EDEDE--- 
----------- ----------- ----------- ----------- ----------- ----------- ----------- --HHHBHHH-- --BBBBBBB-- -BBBBBBBBB- -EEEEEEEEE- -BBBBBBBBB- -DDDDDDDDD- -BBBBBBBBB- -EEEEEEEEE- -BBBBBBBBB- -DDDDDDDDD- -EEEEEEEEE- -EEEEEEEEE- --BBBBBBB-- ---EEEEE--- ---DDDDD--- ---CCCCC--- ---DCCCD--- ---CCCCC--- ---CCCCC--- ---CCCCC--- ---HHHHH--- ----DDD---- 
----------- ----------- ----------- ----------- ----------- ----------- ----------- --BBBBBBB-- -BBBBBBBBB- -EEEEEEEEE- -DDDDDDDDD- -DDDDDDDDD- -BBBBBBBBB- -BBBBBBBBB- -GGAAAAAGG- -GGAAAAAGG- -AAAAAAAAA- -HHHHHHHHH- -BBBBBBBBB- --EEEEEEE-- ---BBBBB--- ---BBBBB--- ---HHHHH--- ---CCCCC--- ---HHHHH--- ---CCCCC--- ---HHHHH--- ---DDEDD--- ----------- 
----------- ----------- ----------- ----------- ----------- ----------- --HBHHHBH-- --BBBBBBB-- -EEEEEEEEE- -DDDDDDDDD- -BBBBBBBBB- -BBBBBBBBB- -BBBBBBBBB- -GGAAAAAGG- -AABBBBBAA- AAAAAAAAAAA AAAAAAAAAAA -AAAAAAAAA- -EEEEEEEEE- -HHHHHHHHH- ---EEEEE--- ---EEEEE--- ---EEEEE--- ---BBBBB--- ---CCCCC--- ---HHHHH--- ---DDEDD--- ----------- ----------- 
----------- ----------- ----------- ----------- ----------- ----------- --BBBBBBB-- -EEEEEEEEE- -DDDDDDDDD- -BBBBBBBBB- -BBBBBBBBB- -CCCCCCCCC- -GGAAAAAGG- -AAAAAAAAA- AAAAAAAAAAA AAAAAAAAAAA AAAAAAAAAAA AAAAAAAAAAA -AAAAAAAAA- -BBBBBBBBB- --HHHHHHH-- ---BBBBB--- ---BBBBB--- ---HHHHH--- ---EEDEE--- ---DEEED--- ----------- ----------- ----------- 
----------- ----------- ----------- ----------- ----------- --HHHBHHH-- -BBBBBBBBB- -DDDDDDDDD- -BBBBBBBBB- -BBBBBBBBB- -CCCCCCCCC- -GGGGGGGGG- -GGGGGGGGG- AAAAAAAAAAA AAAAAAAAAAA AAAAAAAAAAA AAAAAAAAAAA AAAAAAAAAAA AAAAAAAAAAA -AAAAAAAAA- --AAAAAAA-- --EEEEEEE-- ---GAAAG--- ----------- ----------- ----------- ----------- ----------- ----------- 
----------- ----------- ----------- ----------- ----------- --BBBBBBB-- -EEEEEEEEE- -DDDDDDDDD- -BBBBBBBBB- -CCCCCCCCC- -FFFFFFFFF- -AAAAAAAAA- -FFFFFFFFF- AAAAAAAAAAA AAAAAAAAAAA AAAAAAAAAAA AAAAAAAAAAA AAAAAAAAAAA AAAAAAAAAAA -AAAAAAAAA- --AAAAAAA-- --AAAGAAA-- ----------- ----------- ----------- ----------- ----------- ----------- ----------- 
----------- ----------- ----------- ----------- ----------- --EEEEEEE-- -DDDDDDDDD- -BBBBBBBBB- -BBBBBBBBB- -CCCCCCCCC- -IIIIIIIII- -FFFFFFFFF- GAAAAAAAAAG AAAAAAAAAAA AAAAAAAAAAA AAAAAAAAAAA AAAAAAAAAAA AAAAAAAAAAA AAAAAAAAAAA -AAAAAAAAA- --AGGAGGA-- ----------- ----------- ----------- ----------- ----------- ----------- ----------- ----------- 
----------- ----------- ----------- ----------- --HHHHHHH-- -BBBBBBBBB- -DDDDDDDDD- -BBBBBBBBB- -CCCCCCCCC- -IIIIIIIII- -FFFFFFFFF- AAAAAAAAAAA AAAAAAAAAAA AAAAAAAAAAA AAAAAAAAAAA AAAAAAAAAAA AAAAAAAAAAA AAAAAAAAAAA -AAAAAAAAA- --AAAGAAA-- ----------- ----------- ----------- ----------- ----------- ----------- ----------- ----------- ----------- 
----------- -MMM---MMM- -LLL---LLL- -LLL---LLL- -BBBBEBBBB- -EEEEEEEEE- -DDDDDDDDD- -CCCCCCCCC- -IIIIIIIII- -FFFFFFFFF- AAAAAAAAAAA AAAAAAAAAAA AAAAAAAAAAA AAAAAAAAAAA AAAAAAAAAAA AAAAAAAAAAA GGGAAAAAGGG -AAAAAAAAA- --AGGGGGA-- ----------- ----------- ----------- ----------- ----------- ----------- ----------- ----------- ----------- ----------- 
----------- ----------- -MMM---MMM- -LLL---LLL- -BBBBDBBBB- -DDDDDDDDD- -CCCCCCCCC- -IIIIIIIII- -FFFFFFFFF- -AAAAAAAAA- FFFFFFFFFFF AAAAAAAAAAA AAAAAAAAAAA AAAAAAAAAAA AAAAAAAAAAA GGGAAAAAGGG -AAAAAAAAA- --AAAAAAA-- ----------- ----------- ----------- ----------- ----------- ----------- ----------- ----------- ----------- ----------- ----------- 
----------- ----------- -LLL---LLL- -HHB---BHH- -EEEEDEEEE- -DDDDDDDDD- -CCCCCCCCC- -IIIIIIIII- -FFFFFFFFF- -FFFFFFFFF- AAAAAAAAAAA AAAAAAAAAAA AAAAAAAAAAA AAAAAAAAAAA AAAAAAAAAAA AAAAAAAAAAA -AAAAAAAAA- --AGGGGGA-- ----------- ----------- ----------- ----------- ----------- ----------- ----------- ----------- ----------- ----------- ----------- 
----------- ----------- -LLL---LLL- -BBBBBBBBB- -DDDDDDDDD- -BBBBBBBBB- -AAAAAAAAA- -FFFFFFFFF- -AAAAAAAAA- GGGGGGGGGGG AAAAAAAAAAA AAAAAAAAAAA AAAAAAAAAAA AAAAAAAAAAA AAAAAAAAAAA -AAAAAAAAA- --AAAGAAA-- ----------- ----------- ----------- ----------- ----------- ----------- ----------- ----------- ----------- ----------- ----------- ----------- 
----------- ----------- -HHH---HHH- -EEEEEEEEE- -DDDDDDDDD- -AAAAAAAAA- -FFFFFFFFF- -JJJJJJJJJ- GGGGGGGGGGG AAAAAAAAAAA GGGGGGGGGGG AAAAAAAAAAA AAAAAAAAAAA AAAAAAAAAAA -AAAAAAAAA- --AGGAGGA-- ----------- ----------- ----------- ----------- ----------- ----------- ----------- ----------- ----------- ----------- ----------- ----------- ----------- 
----------- ----------- -BBBBBBBBB- -BBBBBBBBB- -AAAAAAAAA- -FFFFFFFFF- -JJJJJJJJJ- AAAAAAAAAAA IIIIIIIIIII AAAAAAAAAAA AAAAAAAAAAA AAAAAAAAAAA AAAAAAAAAAA -AAAAAAAAA- --AAAGAAA-- ----------- ----------- ----------- ----------- ----------- ----------- ----------- ----------- ----------- ----------- ----------- ----------- ----------- ----------- 
----------- ----------- -BBBEBEBBB- -AAAAAAAAA- -FFFFFFFFF- -JJJJJJJJJ- -JJJJJJJJJ- IIIIIIIIIII AAAAAAAAAAA GGGGGGGGGGG AAAAAAAAAAA AAAAAAAAAAA -AAAAAAAAA- --AGGAGGA-- ----------- ----------- ----------- ----------- ----------- ----------- ----------- ----------- ----------- ----------- ----------- ----------- ----------- ----------- ----------- 
----------- -BBEBBBEBB- -FFFFFFFFF- -AAAAAAAAA- -AFFFFFFFA- -JJJJJJJJJ- AAAAAAAAAAA FFFFFFFFFFF AAAAAAAAAAA GGGGGGGGGGG AAAAAAAAAAA -AAAAAAAAA- --AAAGAAA-- ----------- ----------- ----------- ----------- ----------- ----------- ----------- ----------- ----------- ----------- ----------- ----------- ----------- ----------- ----------- ----------- 
----------- -BEBBBBBEA- -AAAAAAAAA- -FFFFFFFFF- -JJJJJJJJJ- -AJJJJJJJA- GGGGGGGGGGG IIIIIIIIIII GGGGGGGGGGG -AAAAAAAAA- --AAAGAAA-- ---AAAAA--- ----------- ----------- ----------- ----------- ----------- ----------- ----------- ----------- ----------- ----------- ----------- ----------- ----------- ----------- ----------- ----------- ----------- 
-BBEAEAEBB- -GGGGGGGGG- -FFFFFFFFF- -JJJJJJJJJ- -JJJJJJJJJ- -GGGGGGGGG- -AAAAAAAAA- -FFFFFFFFF- --AAAAAAA-- ----AFA---- ----------- ----------- ----------- ----------- ----------- ----------- ----------- ----------- ----------- ----------- ----------- ----------- ----------- ----------- ----------- ----------- ----------- ----------- ----------- 
-BABFFFBAB- -FFFFFFFFF- -IGIIIIIGI- --FFFFFFF-- -IAIIIIIAI- --AFFFFFA-- -FIIIIIIIF- -GFAFGFAFG- ----GFG---- ----------- ----------- ----------- ----------- ----------- ----------- ----------- ----------- ----------- ----------- ----------- ----------- ----------- ----------- ----------- ----------- ----------- ----------- ----------- ----------- 
--FGAIAGF-- ---AIIIA--- ---JJJJJ--- ---GIIIG--- ---FIIIF--- ---AAGAA--- ---IGFGI--- ----------- ----------- ----------- ----------- ----------- ----------- ----------- ----------- ----------- ----------- ----------- ----------- ----------- ----------- ----------- ----------- ----------- ----------- ----------- ----------- ----------- ----------- 
----IFI---- ----FAF---- ----GFG---- ----AFA---- ----AIA---- ----------- ----------- ----------- ----------- ----------- ----------- ----------- ----------- ----------- ----------- ----------- ----------- ----------- ----------- ----------- ----------- ----------- ----------- ----------- ----------- ----------- ----------- ----------- ----------- 
