model
size = 31 16 31, scale = 0.05, origin = -y
material 
  colors = A:#43341B B:#EEE C:#2A1F0F D:#BBE1C8 E:#FFB11B
voxels
------------------------------- ------------------------------- ------------BBBBBBB------------ ------------------------------- ------------------------------- ------------------------------- ------------------------------- ------------------------------- ------------------------------- ------------------------------- ------------------------------- ------------------------------- ------------------------------- ------------------------------- ------------------------------- ------------------------------- 
------------------------------- ------------------------------- ---------BBBBBBBBBBBBB--------- ------------------------------- ------------------------------- ------------------------------- ------------------------------- ------------------------------- ------------------------------- ------------------------------- ------------------------------- ------------------------------- ------------------------------- ------------------------------- ------------------------------- ------------------------------- 
------------------------------- ------------------------------- -------BBBBBDDDDDDDBBBBB------- ------------------------------- ------------------------------- ------------------------------- ------------------------------- ------------------------------- ------------------------------- ------------------------------- ------------------------------- ------------------------------- ------------------------------- ------------------------------- ------------------------------- ------------------------------- 
------------------------------- ------------BBBBBBB------------ ------BBBDDDBBBBBBBDDDBBB------ ------------------------------- ------------------------------- ------------------------------- ------------------------------- ------------------------------- ------------------------------- ------------------------------- ------------------------------- ------------------------------- ------------------------------- ------------------------------- ------------------------------- ------------------------------- 
------------------------------- ----------BBBBBBBBBBB---------- -----BBBDDBBBBBBBBBBBDDBBB----- ------------------------------- ------------------------------- ------------------------------- ------------------------------- ------------------------------- ------------------------------- ------------------------------- ------------------------------- ------------------------------- ------------------------------- ------------------------------- ------------------------------- ------------------------------- 
------------------------------- --------BBBBBBBBBBBBBBB-------- ----BBDDBBBB-------BBBBDDBB---- ------------------------------- ------------------------------- ------------------------------- ------------------------------- ------------------------------- ------------------------------- ------------------------------- ------------------------------- ------------------------------- ------------------------------- ------------------------------- ------------------------------- ------------------------------- 
------------BBBBBBB------------ -------BBBBB-------BBBBB------- ---BBDDBBB-----------BBBDDBB--- ------------------------------- ------------------------------- ------------------------------- ------------------------------- ------------------------------- ------------------------------- ------------------------------- ------------------------------- ------------------------------- ------------------------------- ------------------------------- ------------------------------- ------------------------------- 
----------BBBBBBBBBBB---------- ------BBBB-----------BBBB------ --BBBDBBB-------------BBBDBBB-- ------------------------------- ------------------------------- ------------------------------- ------------------------------- ------------------------------- ------------------------------- ------------------------------- ------------------------------- ------------------------------- ------------------------------- ------------------------------- ------------------------------- ------------------------------- 
---------BBBBBBBBBBBBB--------- -----BBBB-------------BBBB----- --BBDBBB---------------BBBDBB-- ------------------------------- ------------------------------- ------------------------------- ------------------------------- ------------------------------- ------------------------------- ------------------------------- ------------------------------- ------------------------------- ------------------------------- ------------------------------- ------------------------------- ------------------------------- 
--------BBBBBBBBBBBBBBB-------- -----BBB---------------BBB----- -BBDDBBCC---------------BBDDBB- -------CC---------------------- -------CC---------------------- -------CC---------------------- -------CC---------------------- -------CC---------------------- -------CC---------------------- -------CC---------------------- -------CC---------------------- -------CC---------------------- -------CC---------------------- ------------------------------- ------------------------------- ------------------------------- 
-------BBBBBBBBBBBBBBBBB------- ----BBB-----------------BBB---- -BBDBB-CAAA--------------BBDBB- -------CAAA-------------------- -------CAEE-------------------- -------CAAA-------------------- -------CAAA-------------------- -------CAAA-------------------- -------CAEE-------------------- -------CAAA-------------------- -------CAAA-------------------- -------CCCC-------------------- -------CCCC-------------------- -------CC---------------------- ------------------------------- ------------------------------- 
-------BBBBBBBBBBBBBBBBB------- ----BBB-----------------BBB---- -BBDBBCCAAAAA------------BBDBB- ------CCAAAAA------------------ ------CCAAAEE------------------ ------CCAAAAA------------------ ------CCAAAAA------------------ ------CCAAAAA------------------ ------CCAAAEE------------------ ------CCAAAAA------------------ ------CCAAAAA------------------ ------CCCCCCC------------------ ------CCCCCCC------------------ -------CCCC-------------------- ------------------------------- ------------------------------- 
------BBBBBBBBBBBBBBBBBBB------ ---BBB-------------------BBB--- BBDBBCCCAAAAAAAAAAA-------BBDBB -----CCCAAAAAAAAAAA------------ -----CCCAAAAAEEEEEE------------ -----CCCAAAAAAAAAAA------------ -----CCCAAAAAAAAAAA------------ -----CCCAAAAAAAAAAA------------ -----CCCAAAAAEEEEEE------------ -----CCCAAAAAAAAAAA------------ -----CCCAAAAAAAAAAA------------ -----CCCCCCCCCCCCCC------------ -----CCCCCCCCCCCCCC------------ ------CBBBCCCCCC--------------- ------------------------------- ------------------------------- 
------BBBBBBBBBBBBBBBBBBB------ ---BBB-------------------BBB--- BBDBBCAAAAAAAAAAAAAAA-----BBDBB -----CAAAAAAAAAAAAAAA---------- -----CAAAAAAAAAAAAAEE---------- -----CAAAAAAAAAAAAAAA---------- -----CAAAAAAAAAAAAAAA---------- -----CAAAAAAAAAAAAAAA---------- -----CAAAAAAAAAAAAAEE---------- -----CAAAAAAAAAAAAAAA---------- -----CAAAAAAAAAAAAAAA---------- -----CCCCCCCCCCCCCCCC---------- -----CCCCCCCCCCCCCCCC---------- ------BBBBBCCCCCCCC------------ -------BBB--------------------- ------------------------------- 
------BBBBBBBBBBBBBBBBBBB------ ---BBB-------------------BBB--- BBDBBCAAAAAAAAAAAAAAAAA---BBDBB ----CCAAAAAAAAAAAAAAAAA-------- ----CCAAAAAAAAAAAAAAAEE-------- ----CCAAAAAAAAAAAAAAAAA-------- ----CCAAAAAAAAAAAAAAAAA-------- ----CCAAAAAAAAAAAAAAAAA-------- ----CCAAAAAAAAAAAAAAAEE-------- ----CCAAAAAAAAAAAAAAAAA-------- ----CCAAAAAAAAAAAAAAAAA-------- ----CCCCCCCCCCCCCCCCCCC-------- ----CCCCCCCCCCCCCCCCCCC-------- -----BBBBBBBCCCCCCCCC---------- ------BBBBB-------------------- --------B---------------------- 
------BBBBBBBBBBBBBBBBBBB------ ---BBB-------------------BBB--- BBDBCCAAAAAAAAAAAAAAAAAAAAABDBB ----CCAAAAAAAAAAAAAAAAAAAAA---- ----CCAAAAAAAAAAAAAAAAAEEEE---- ----CCAAAAAAAAAAAAAAAAAAAAA---- ----CCAAAAAAAAAAAAAAAAAAAAA---- ----CCAAAAAAAAAAAAAAAAAAAAA---- ----CCAAAAAAAAAAAAAAAAAEEEE---- ----CCAAAAAAAAAAAAAAAAAAAAA---- ----CCAAAAAAAAAAAAAAAAAAAAA---- ----CCCCCCCCCCCCCCCCCCCCCCC---- ----CCCCCCCCCCCCCCCCCCCCCCC---- -----BBBBBBBCCCCCCCCCCCCC------ ------BBBBB-------------------- -------BBB--------------------- 
------BBBBBBBBBBBBBBBBBBB------ ---BBB-------------------BBB--- BBDBCCAAAAAAAAAAAAAAAAAAB-BBDBB ----CCAAAAAAAAAAAAAAAAAAB------ ----CCAAAAAAAAAAAAAAAAAB------- ----CCAAAAAAAAAAAAAAAAA-------- ----CCAAAAAAAAAAAAAAAAA-------- ----CCAAAAAAAAAAAAAAAAA-------- ----CCAAAAAAAAAAAAAAAEE-------- ----CCAAAAAAAAAAAAAAAAA-------- ----CCAAAAAAAAAAAAAAAAA-------- ----CCCCCCCCCCCCCCCCCCC-------- ----CCCCCCCCCCCCCCCCCCC-------- -----BBBBBBBCCCCCCCCC---------- ------BBBBB-------------------- --------B---------------------- 
------BBBBBBBBBBBBBBBBBBB------ ---BBB-------------------BBB--- BBDBBCAAAAAAAAAAAAAAAAABB-BBDBB -----CAAAAAAAAAAAAAAAAABB------ -----CAAAAAAAAAAAAAAAABBB------ -----CAAAAAAAAAAAAAAAB--------- -----CAAAAAAAAAAAAAAA---------- -----CAAAAAAAAAAAAAAA---------- -----CAAAAAAAAAAAAAEE---------- -----CAAAAAAAAAAAAAAA---------- -----CAAAAAAAAAAAAAAA---------- -----CCCCCCCCCCCCCCCC---------- -----CCCCCCCCCCCCCCCC---------- ------BBBBBBCCCCCCC------------ -------BBB--------------------- ------------------------------- 
------BBBBBBBBBBBBBBBBBBB------ ---BBB-------------------BBB--- BBDBBCAAAAAAAAAAAAABBBBBB-BBDBB -----CAAAAAAAAAAAAABBBBBB------ -----CAAAAAAAEEEEEABBB-BB------ -----CAAAAAAAAAAAAA--BB-------- -----CAAAAAAAAAAAAA------------ -----CAAAAAAAAAAAAA------------ -----CAAAAAAAEEEEEE------------ -----CAAAAAAAAAAAAA------------ -----CAAAAAAAAAAAAA------------ -----CCCCCCCCCCCCCC------------ -----CCCCCCCCCCCCCC------------ ------CBBBCCCCCC--------------- ------------------------------- ------------------------------- 
-------BBBBBBBBBBBBBBBBB------- ----BBB-----------------BBB---- -BBDBBCCAAAAA---BBBBBBBBBBBDBB- ------CCAAAAA----BBBBBBBB------ ------CCAAAEE-----BBB-BBB------ ------CCAAAAA-------BBB-------- ------CCAAAAA--------B--------- ------CCAAAAA------------------ ------CCAAAEE------------------ ------CCAAAAA------------------ ------CCAAAAA------------------ ------CCCCCCC------------------ ------CCCCCCC------------------ -------CCCC-------------------- ------------------------------- ------------------------------- 
-------BBBBBBBBBBBBBBBBB------- ----BBB-----------------BBB---- -BBDBB-CAAA--------BBBBBBBBDBB- -------CAAA-------BBBBBBB------ -------CAEE--------BBBBB------- -------CAAA---------BB--------- -------CAAA----------B--------- -------CAAA-------------------- -------CAEE-------------------- -------CAAA-------------------- -------CAAA-------------------- -------CCCC-------------------- -------CCCC-------------------- -------CC---------------------- ------------------------------- ------------------------------- 
--------BBBBBBBBBBBBBBB-------- -----BBB---------------BBB----- -BBDDBBCC----------BBBBBBBDDBB- -------CC----------BBBBBB------ -------CC----------BBBB-------- -------CC------------BB-------- -------CC---------------------- -------CC---------------------- -------CC---------------------- -------CC---------------------- -------CC---------------------- -------CC---------------------- -------CC---------------------- ------------------------------- ------------------------------- ------------------------------- 
---------BBBBBBBBBBBBB--------- -----BBBB-------------BBBB----- --BBDBBB-----------BBBBBBBDBB-- -------------------BBBBBB------ -------------------B-BB-------- ------------------------------- ------------------------------- ------------------------------- ------------------------------- ------------------------------- ------------------------------- ------------------------------- ------------------------------- ------------------------------- ------------------------------- ------------------------------- 
----------BBBBBBBBBBB---------- ------BBBB-----------BBBB------ --BBBDBBB----------BBBBBBDBBB-- -------------------BBBBB------- --------------------B-B-------- ------------------------------- ------------------------------- ------------------------------- ------------------------------- ------------------------------- ------------------------------- ------------------------------- ------------------------------- ------------------------------- ------------------------------- ------------------------------- 
------------BBBBBBB------------ -------BBBBB-------BBBBB------- ---BBDDBBB-----------BBBDDBB--- ------------------------------- ------------------------------- ------------------------------- ------------------------------- ------------------------------- ------------------------------- ------------------------------- ------------------------------- ------------------------------- ------------------------------- ------------------------------- ------------------------------- ------------------------------- 
------------------------------- --------BBBBBBBBBBBBBBB-------- ----BBDDBBBB-------BBBBDDBB---- ------------------------------- ------------------------------- ------------------------------- ------------------------------- ------------------------------- ------------------------------- ------------------------------- ------------------------------- ------------------------------- ------------------------------- ------------------------------- ------------------------------- ------------------------------- 
------------------------------- ----------BBBBBBBBBBB---------- -----BBBDDBBBBBBBBBBBDDBBB----- ------------------------------- ------------------------------- ------------------------------- ------------------------------- ------------------------------- ------------------------------- ------------------------------- ------------------------------- ------------------------------- ------------------------------- ------------------------------- ------------------------------- ------------------------------- 
------------------------------- ------------BBBBBBB------------ ------BBBDDDBBBBBBBDDDBBB------ ------------------------------- ------------------------------- ------------------------------- ------------------------------- ------------------------------- ------------------------------- ------------------------------- ------------------------------- ------------------------------- ------------------------------- ------------------------------- ------------------------------- ------------------------------- 
------------------------------- ------------------------------- -------BBBBBDDDDDDDBBBBB------- ------------------------------- ------------------------------- ------------------------------- ------------------------------- ------------------------------- ------------------------------- ------------------------------- ------------------------------- ------------------------------- ------------------------------- ------------------------------- ------------------------------- ------------------------------- 
------------------------------- ------------------------------- ---------BBBBBBBBBBBBB--------- ------------------------------- ------------------------------- ------------------------------- ------------------------------- ------------------------------- ------------------------------- ------------------------------- ------------------------------- ------------------------------- ------------------------------- ------------------------------- ------------------------------- ------------------------------- 
------------------------------- ------------------------------- ------------BBBBBBB------------ ------------------------------- ------------------------------- ------------------------------- ------------------------------- ------------------------------- ------------------------------- ------------------------------- ------------------------------- ------------------------------- ------------------------------- ------------------------------- ------------------------------- ------------------------------- 
