model
size = 30 30 29, scale = 0.05, origin = -y
material 
  colors = A:#DDD B:#222 C:#111 D:#555 E:#777 F:#444 G:#888 H:#AAA I:#BBB J:#007 K:#800
voxels
----AAAAAAAAAAAAAAAAAAAAAA---- ------------------------------ ------------------------------ ------------------------------ ------------------------------ ------------------------------ ------------------------------ ------------------------------ ------------------------------ ------------------------------ ------------------------------ ------------------------------ ------------------------------ ------------------------------ ------------------------------ ------------------------------ ------------------------------ ------------------------------ ------------------------------ ------------------------------ ------------------------------ ------------------------------ ------------------------------ ------------------------------ ------------------------------ ------------------------------ ------------------------------ ------------------------------ ------------------------------ ------------------------------ 
----AAAAAAAAAAAAAAAAAAAAAA---- ----A--------------------A---- ----A--------------------A---- ----A--------------------A---- ----A--------------------A---- ----A--------------------A---- ----A--------------------A---- ----A--------------------A---- ----A--------------------A---- ----A--------------------A---- ----AA------------------AA---- ------------------------------ ------------------------------ ------------------------------ ------------------------------ ------------------------------ ------------------------------ ------------------------------ ------------------------------ ------------------------------ ------------------------------ ------------------------------ ------------------------------ ------------------------------ ------------------------------ ------------------------------ ------------------------------ ------------------------------ ------------------------------ ------------------------------ 
----AAAAAAAAAAAAAAAAAAAAAA---- ----A--------------------A---- ----A--------------------A---- ----A--------------------A---- ----A--------------------A---- ----A--------------------A---- ----A--------------------A---- ----A--------------------A---- ----A--------------------A---- ----A--------------------A---- ----AAAAAAAAAAAAAAAAAAAAAA---- ------------------------------ ------------------------------ ------------------------------ ------------------------------ ------------------------------ ------------------------------ ------------------------------ ------------------------------ ------------------------------ ------------------------------ ------------------------------ ------------------------------ ------------------------------ -----------------------K------ ------------------------------ ------------------------------ ------------------------------ ------------------------------ ------------------------------ 
----AAAAAAAAAAAAAAAAAAAAAA---- ----AEEEEEEEEEEEEEEEEEEEEA---- ----AEEEEEEEEEEEEEEEEEEEEA---- ----A--------------------A---- ----A--------------------A---- ----A--------------------A---- ----A--------------------A---- ----A--------------------A---- ----A--------------------A---- ----A--------------------A---- ----AAAAAAAAAAAAAAAAAAAAAA---- ------------------------------ ------------------------------ ------------------------------ ------------------------------ ------------------------------ ------------------------------ ------------------------------ ------------------------------ ------------------------------ ------------------------------ ------------------------------ ------------------------------ ------------------------------ -----------------------B------ ------------------------------ ------------------------------ ------------------------------ ------------------------------ ------------------------------ 
------------------------------ ------------------------------ ----AEEEEEEEEEEEEEEEEEEEEA---- ----AEEEEEEEEEEEEEEEEEEEEA---- ----AEEEEEEEEEEEEEEEEEEEEA---- ----AEEEEEEEEEEEEEEEEEEEEA---- ----A--------------------A---- ----A--------------------A---- ----A--------------------A---- ----AEEEEEEEEEEEEEEEEEEEEA---- ----AAAAAAAAAAAAAAAAAAAAAA---- ------------------------------ ------------------------------ ------------------------------ ------------------------------ ------------------------------ ------------------------------ ------------------------------ ------------------------------ ------------------------------ ------------------------------ ------------------------------ ------------------------------ ------------------------------ -----------------------B------ ------------------------------ ------------------------------ ------------------------------ ------------------------------ ------------------------------ 
------------------------------ ------------------------------ ------------------------------ ------------------------------ ------------------------------ ----AEEEEEEEEEEEEEEEEEEEEA---- ----AEEEEEEEEEEEEEEEEEEEEA---- ----AEEEEEEEEEEEEEEEEEEEEA---- ----AEEEEEEEEEEEEEEEEEEEEA---- ----AEEEEEEEEEEEEEEEEEEEEA---- ----AAAAAAAAAAAAAAAAAAAAAA---- ------------------------------ ------------------------------ ------------------------------ ------------------------------ ------------------------------ ------------------------------ ------------------------------ ------------------------------ ------------------------------ ------------------------------ ------------------------------ ------------------------------ ------------------------------ -----------------------B------ ------------------------------ ------------------------------ ------------------------------ ------------------------------ ------------------------------ 
------------------------------ ------------------------------ ------------------------------ ------------------------------ ------------------------------ ------------------------------ ------------------------------ ------------------------------ ------AAAAAAAAAAAAAAAAAA------ ------------------------------ ------------------------------ ------------------------------ ------------------------------ ------------------------------ ------------------------------ ------------------------------ ------------------------------ ------------------------------ ------------------------------ ------------------------------ ------------------------------ ------------------------------ ------------------------------ -----------------------B------ -----------------------B------ ------------------------------ ------------------------------ ------------------------------ ------------------------------ ------------------------------ 
------------------------------ ------------------------------ ------------------------------ ------------------------------ ------------------------------ ------------------------------ ---AAAAAAAAAAAAAAAAAAAAAAAA--- --HAAAAAAAAAAAAAAAAAAAAAAAAH-- --AAAAAAAAAAAAAAAAAAAAAAAAAA-- --DAAAAAAAAAAAAAAAAAAAAAAAAD-- --DAAAAAAAAAAAAAAAAAAAAAAAAD-- --DDAAAAAAAAAAAAAAAAAAAAAADD-- --DDAAAAAAAAAAAAAAAAAAAAAADD-- --DDAAACBBFFDDEEDDFFBBCAAADD-- --DDAAACBBFFDDEEDDFFBBCAAADD-- --DDAAACBBFFDDEEDDFFBBCAAADD-- --DDAAACBBFFDDEEDDFFBBCAAADD-- --DDAAAAAAAAAAAAAAAAAAAAAADD-- --DDAAAAAAAAAAAAAAAAAAAAAADD-- --DDAAAAAAAAA----AAAAAAAAADD-- --DDAAAAAAAA-AAAA-AAAAAAAADD-- --DDAAAAAAA-AAAAAA-AAAAAAADD-- --DAAAAAAA-AAAAAAAA-AAAAAAAD-- --DAAAAAA-AAAAAAAAAA-AAAAAAD-- --AAAAAA-AAAAAAAAAAAA-AAAAAA-- --AAAAA-AAAAAAAAAAAAAA-AAAAA-- --AAAA-AAAAAAAAAAAAAAAA-AAAA-- --AAA-AAAJJJAAAAAAJJJAAA-AAA-- --AA-AAAAAAAAAAAAAAAAAAAA-AA-- ---CCCCCCCCCCCCCCCCCCCCCCCC--- 
------------------------------ ------------------------------ ------------------------------ ----AADDDDDDDDDDDDDDDDDDAA---- ---ADDDDDDDDDDDDDDDDDDDDDDA--- --ADDDDDDDDDDDDDDDDDDDDDDDDA-- --AAAAAAAAAAAAAAAAAAAAAAAAAA-- --AAAAAAAAAAAAAAAAAAAAAAAAAA-- --AAAAAAAAAAAAAAAAAAAAAAAAAA-- --AAAAAAAAAAAAAAAAAAAAAAAAAA-- --AAAAAAAAAAAAAAAAAAAAAAAAAA-- --AAAAAAAAAAAAAAAAAAAAAAAAAA-- --AAAAAAAAAAAAAAAAAAAAAAAAAA-- --AAAAAAAAAAAAAAAAAAAAAAAAAA-- --AAAAAAAAAAAAAAAAAAAAAAAAAA-- --AAAAAAAAAAAAAAAAAAAAAAAAAA-- --AAAAAAAAAAAAAAAAAAAAAAAAAA-- --AAAAAAAAAAAAAAAAAAAAAAAAAA-- --AAAAAAAAAAAAAAAAAAAAAAAAAA-- --AAAAAAAAAAA----AAAAAAAAAAA-- --AAAAAAAAAA-AAAA-AAAAAAAAAA-- --AAAAAAAAA--AAAAA-AAAAAAAAA-- --AAAAAAAA-AAAAAAAA-AAAAAAAA-- --AAAAAAA-AAAAAAAAAA-AAAAAAA-- --AAAAAA-AAAAAAAAAAAA-AAAAAA-- --AAAAA-AAAAAAAAAAAAAA-AAAAA-- --AAAA-AAAAAAAAAAAAAAAA-AAAA-- --AAA-AAAAAAAAAAAAAAAAAA-AAA-- --AA-AAAAAAAAAAAAAAAAAAAA--A-- ---CDDDFFFFFFDDDDDEEEEEGGGC--- 
------------------------------ ------------------------------ ------------------------------ ---AAAAAAAAAAAAAAAAAAAAAAAA--- --AAAAAAAAAAAAAAAAAAAAAAAAAA-- --AAAAAAAAAAAAAAAAAAAAAAAAAA-- --AAAAAAAAAAAAAAAAAAAAAAAAAA-- --AAAAAAAAAAAAAAAAAAAAAAAAAA-- --AAAAAAAAAAAAAAAAAAAAAAAAAA-- --AAAAAAAAAAAAAAAAAAAAAAAAAA-- --AAAAAAAAAAAAAAAAAAAAAAAAAA-- --AAAAAAAAAAAAAAAAAAAAAAAAAA-- --AAAAAAAAAAAAAAAAAAAAAAAAAA-- --AAAAAAAAAAAAAAAAAAAAAAAAAA-- --AAAAAAAAAAAAAAAAAAAAAAAAAA-- --AAAAAAAAAAAAAAAAAAAAAAAAAA-- --AAAAAAAAAAAAAAAAAAAAAAAAAA-- --AAAAAAAAAAAAAAAAAAAAAAAAAA-- --AAAAAAAAAAAAAAAAAAAAAAAAAA-- --AAAAAAAAAAA----AAAAAAAAAAA-- --AAAAAAAAAA-AAAA-AAAAAAAAAA-- --AAAAAAAAA-AAAAAA-AAAAAAAAA-- --AAAAAAAA-AAAAAAAA-AAAAAAAA-- --AAAAAAA-AAAAAAAAAA-AAAAAAA-- --AAAAAA-AAAAAAAAAAAA-AAAAAA-- --AAAAA-AAAAAAAAAAAAAA-AAAAA-- --AAAA-AAAAAAAAAAAAAAAA-AAAA-- --AAA-AAAAAAAAAAAAAAAAAA-AAA-- --AA-AAAAAAAAAAAAAAAAAAAA-AA-- ---CDDDDFFFFFFDDDDDEEEEEGGC--- 
------------------------------ ------------------------------ ---CCCCCCCCCCCCCCCCCCCCCCCC--- ---AAAAAAAAAAAAAAAAAAAAAAAA--- --AAAAAAAAAAAAAAAAAAAAAAAAAA-- --AAAAAAAAAAAAAAAAAAAAAAAAAA-- BBAAAAAAAAAAAAAAAAAAAAAAAAAABB BBAAAAAAAAAAAAAAAAAAAAAAAAAABB BBAAAAAAAAAAAAAAAAAAAAAAAAAABB BBAAAAAAAAAAAAAAAAAAAAAAAAAABB BBAAAAAAAAAAAAAAAAAAAAAAAAAABB BBAAAAAAAAAAAAAAAAAAAAAAAAAABB BBAAAAAAAAAAAAAAAAAAAAAAAAAABB --AAAAAAAAAAAAAAAAAAAAAAAAAA-- --AAAAAAAAAAAAAAAAAAAAAAAAAA-- --AAAAAAAAAAAAAAAAAAAAAAAAAA-- --AAAAAAAAAAAAAAAAAAAAAAAAAA-- --AAAAAAAAAAAAAAAAAAAAAAAAAA-- --AAAAAAAAAAAAAAAAAAAAAAAAAA-- --AAAAAAAAAAA----AAAAAAAAAAA-- --AAAAAAAAAA-AAAA-AAAAAAAAAA-- --AAAAAAAAACAAAAAA-AAAAAAAAA-- --AAAAAAAA-AAAAAAAA-AAAAAAAA-- --AAAAAAA-AAAAAAAAAA-AAAAAAA-- --AAAAAA-AAAAAAAAAAAA-AAAAAA-- --AAAAA-AAAAAAAAAAAAAA-AAAAA-- --AAAA-AAAAAAAAAAAAAAAA-AAAA-- --AAA-AAAAAAAAAAAAAAAAAA-AAA-- --AA-AAAAAAAAAAAAAAAAAAAACAA-- ---CDDDDDFFFFFFDDDDDEEEEEGC--- 
------------------------------ ------------------------------ ---CCCCCCCCCCCCCCCCCCCCCCCC--- ---AAAAAAAAAAAAAAAAAAAAAAAA--- BBAAAAAAAAAAAAAAAAAAAAAAAAAABB BBAAAAAAAAAAAAAAAAAAAAAAAAAABB BBAAAAAAAAAAAAAAAAAAAAAAAAAABB BBAAAAAAAAAAAAAAAAAAAAAAAAAABB BBAAAAAAAAAAAAAAAAAAAAAAAAAABB BBAAAAAAAAAAAAAAAAAAAAAAAAAABB BBAAAAAAAAAAAAAAAAAAAAAAAAAABB BBAAAAAAAAAAAAAAAAAAAAAAAAAABB BBAAAAAAAAAAAAAAAAAAAAAAAAAABB BBAAAAAAAAAAAAAAAAAAAAAAAAAABB BBAAAAAAAAAAAAAAAAAAAAAAAAAABB --AAAAAAAAAAAAAAAAAAAAAAAAAA-- --AAAAAAAAAAAAAAAAAAAAAAAAAA-- --AAAAAAAAAAAAAAAAAAAAAAAAAA-- --AAAAAAAAAAAAAAAAAAAAAAAAAA-- --AAAAAAAAAAACCCCAAAAAAAAAAA-- --AAAAAAAAAACAAAACAAAAAAAAAA-- --DAAAAAAAAAAAAAAACAAAAAAAAD-- --AAAAAAAACAAAAAAAACAAAAAAAA-- --AAAAAAACAAAAAAAAAACAAAAAAA-- --AAAAAACAAAAAAAAAAAACAAAAAA-- --AAAAACAAAAAAAAAAAAAACAAAAA-- --AAAACAAAAAAAAAAAAAAAACAAAA-- --AAACAAAAAAAAAAAAAAAAAACAAA-- --AACAAAAAAAAAAAAAAAAAAAAAAA-- ---CDDDDDDFFFFFFDDDDDEEEEEC--- 
------------------------------ ------------------------------ ---CCCCCCCCCCCCCCCCCCCCCCCC--- BB-AAAAAAAAAAAAAAAAAAAAAAAA-BB BBAAAAAAAAAAAAAAAAAAAAAAAAAABB BBAAAAAAAAAAAAAAAAAAAAAAAAAABB BBAAAAAAAAAAAAAAAAAAAAAAAAAABB BBAAAAAAAAAAAAAAAAAAAAAAAAAABB BBAAAAAAAAAAAAAAAAAAAAAAAAAABB BBAAAAAAAAAAAAAAAAAAAAAAAAAABB BBAAAAAAAAAAAAAAAAAAAAAAAAAABB BBAAAAAAAAAAAAAAAAAAAAAAAAAABB BBAAAAAAAAAAAAAAAAAAAAAAAAAABB BBAAAAAAAAAAAAAAAAAAAAAAAAAABB BBAAAAAAAAAAAAAAAAAAAAAAAAAABB BBAAAAAAAAAAAAAAAAAAAAAAAAAABB --AAAAAAAAAAAAAAAAAAAAAAAAAA-- --AAAAAAAAAAAAAAAAAAAAAAAAAA-- --AAAAAAAAAAAAAAAAAAAAAAAAAA-- --AAAAAAAAAAAAAAAAAAAAAAAAAA-- --AAAAAAAAAAAAAAAAAAAAAAAAAA-- --DAAAAAAAAAAAAAAAAAAAAAAAAD-- --AAAAAAAAAAAAAAAAAAAAAAAAAA-- --AAAAAAAAAAAAAAAAAAAAAAAAAA-- --AAAAAAAAAAAAAAAAAAAAAAAAAA-- --AAAAAAAAAAAAAAAAAAAAAAAAAB-- --BAAAAAAAAAAAAAAAAAAAAAAAAA-- --BAAAAAAAAAAAAAAAAAAAAAAAAB-- --AAAAAAAAAAAAAAAAAAAAAAAAAA-- ---CEDDDDDDFFFFFFDDDDDEEEEC--- 
------------------------------ ------------------------------ BB-CCCCCCCCCCCCCCCCCCCCCCCC-BB BB-AAAAAAAAAAAAAAAAAAAAAAAA-BB BBAAAAAAAAAAAAAAAAAAAAAAAAAABB BBAAAAAAAAAAAAAAAAAAAAAAAAAABB BBAAAAAAAAAAAAAAAAAAAAAAAAAABB BBAAAAAAAAAAAAAAAAAAAAAAAAAABB BBAAAAAAAAAAAAAAAAAAAAAAAAAABB BBAAAAAAAAAAAAAAAAAAAAAAAAAABB BBAAAAAAAAAAAAAAAAAAAAAAAAAABB BBAAAAAAAAAAAAAAAAAAAAAAAAAABB BBAAAAAAAAAAAAAAAAAAAAAAAAAABB BBAAAAAAAAAAAAAAAAAAAAAAAAAABB BBAAAAAAAAAAAAAAAAAAAAAAAAAABB BBAAAAAAAAAAAAAAAAAAAAAAAAAABB BBAAAAAAAAAAAAAAAAAAAAAAAAAABB --AAAAAAAAAAAAAAAAAAAAAAAAAA-- --AAAAAAAAAAAAAAAAAAAAAAAAAA-- --AAAAAAAAAAAAAAAAAAAAAAAAAA-- --AAAAAAAAAAAAAAAAAAAAAAAAAA-- --DAAAAAAAAAAAAAAAAAAAAAAAAD-- --AAAAAAAAAAAAAAAAAAAAAAAAAA-- --AAAAAAAAAAAAAAAAAAAAAAAAAA-- --AAAAAAAAAAAAAAAAAAAAAAAAAA-- --BAAAAAAAAAAAAAAAAAAAAAAAAA-- --AAAAAAAAAAAAAAAAAAAAAAAAAA-- --BAAAAAAAAAAAAAAAAAAAAAAAAB-- --AAAAAAAAAAAAAAAAAAAAAAAAAA-- ---CEEDDDDDDFFFFFFDDDDDEEEC--- 
------------------------------ BB--------------------------BB BB-CCCCCCCCCCCCCCCCCCCCCCCC-BB BB-AAAAAAAAAAAAAAAAAAAAAAAA-BB BBAAAAAAAAAAAAAAAAAAAAAAAAAABB BBAAAAAAAAAAAAAAAAAAAAAAAAAABB BBAAAAAAAAAAAAAAAAAAAAAAAAAABB BBAAAAAAAAAAAAAAAAAAAAAAAAAABB BBAAAAAAAAAAAAAAAAAAAAAAAAAABB BBAAAAAAAAAAAAAAAAAAAAAAAAAABB BBAAAAAAAAAAAAAAAAAAAAAAAAAABB BBAAAAAAAAAAAAAAAAAAAAAAAAAABB BBAAAAAAAAAAAAAAAAAAAAAAAAAABB BBAAAAAAAAAAAAAAAAAAAAAAAAAABB BBAAAAAAAAAAAAAAAAAAAAAAAAAABB BBAAAAAAAAAAAAAAAAAAAAAAAAAABB BBAAAAAAAAAAAAAAAAAAAAAAAAAABB BBAAAAAAAAAAAAAAAAAAAAAAAAAABB --AAAAAAAAAAAAAAAAAAAAAAAAAA-- --AAAAAAAAAAAAAAAAAAAAAAAAAA-- --DAAAAAAAAAAAAAAAAAAAAAAAAD-- --DAAAAAAAAAAAAAAAAAAAAAAAAD-- --AAAAAAAAAAAAAAAAAAAAAAAAAA-- --AAAAAAAAAAAAAAAAAAAAAAAAAA-- --BAAAAAAAAAAAAAAAAAAAAAAAAA-- --AAAAAAAAAAAAAAAAAAAAAAAAAA-- --AAAAAAAAAAAAAAAAAAAAAAAAAB-- --BAAAAAAAAAAAAAAAAAAAAAAAAA-- --AAAAAAAAAAAAAAAAAAAAAAAAAA-- ---CEEEDDDDDDFFFFFFDDDDDEEC--- 
------------------------------ BB--------------------------BB BB-CCCCCCCCCCCCCCCCCCCCCCCC-BB BB-AAAAAAAAAAAAAAAAAAAAAAAA-BB BBAAAAAAAAAAAAAAAAAAAAAAAAAABB BBAAAAAAAAAAAAAAAAAAAAAAAAAABB BBAAAAAAAAAAAAAAAAAAAAAAAAAABB BBAAAAAAAAAAAAAAAAAAAAAAAAAABB BBAAAAAAAAAAAAAAAAAAAAAAAAAABB BBAAAAAAAAAAAAAAAAAAAAAAAAAABB BBAAAAAAAAAAAAAAAAAAAAAAAAAABB BBAAAAAAAAAAAAAAAAAAAAAAAAAABB BBAAAAAAAAAAAAAAAAAAAAAAAAAABB BBAAAAAAAAAAAAAAAAAAAAAAAAAABB BBAAAAAAAAAAAAAAAAAAAAAAAAAABB BBAAAAAAAAAAAAAAAAAAAAAAAAAABB BBAAAAAAAAAAAAAAAAAAAAAAAAAABB BBAAAAAAAAAAAAAAAAAAAAAAAAAABB --AAAAAAAAAAAAAAAAAAAAAAAAAA-- --AAAAAAAAAAAAAAAAAAAAAAAAAA-- --DAAAAAAAAAAAAAAAAAAAAAAAAD-- --DAAAAAAAAAAAAAAAAAAAAAAAAD-- --AAAAAAAAAAAAAAAAAAAAAAAAAA-- --AAAAAAAAAAAAAAAAAAAAAAAAAA-- --AAAAAAAAAAAAAAAAAAAAAAAAAA-- --AAAAAAAAAAAAAAAAAAAAAAAAAA-- --AAAAAAAAAAAAAAAAAAAAAAAAAA-- --AAAAAAAAAAAAAAAAAAAAAAAAAA-- --AAAAAAAAAAAAAAAAAAAAAAAAAA-- ---CEEEEDDDDDDFFFFFFDDDDDEC--- 
BB--------------------------BB BB--------------------------BB BB-CCCCCCCCCCCCCCCCCCCCCCCC-BB BB-AAAAAAAAAAAAAAAAAAAAAAAA-BB BBAAAAAAAAAAAAAAAAAAAAAAAAAABB BBAAAAAAAAAAAAAAAAAAAAAAAAAABB BBAAAAAAAAAAAAAAAAAAAAAAAAAABB BBAAAAAAAAAAAAAAAAAAAAAAAAAABB BBAAAAAAAAAAAAAAAAAAAAAAAAAABB BBAAAAAAAAAAAAAAAAAAAAAAAAAABB BBAAAAAAAAAAAAAAAAAAAAAAAAAABB BBAAAAAAAAAAAAAAAAAAAAAAAAAABB BBAAAAAAAAAAAAAAAAAAAAAAAAAABB BBAAAAAAAAAAAAAAAAAAAAAAAAAABB BBAAAAAAAAAAAAAAAAAAAAAAAAAABB BBAAAAAAAAAAAAAAAAAAAAAAAAAABB BBAAAAAAAAAAAAAAAAAAAAAAAAAABB BBAAAAAAAAAAAAAAAAAAAAAAAAAABB BBAAAAAAAAAAAAAAAAAAAAAAAAAABB --AAAAAAAAAAAAAAAAAAAAAAAAAA-- --DAAAAAAAAAAAAAAAAAAAAAAAAD-- --DAAAAAAAAAAAAAAAAAAAAAAAAD-- --AAAAAAAAAAAAAAAAAAAAAAAAAA-- --AAAAAAAAAAAAAAAAAAAAAAAAAA-- --AAAAAAAAAAAAAAAAAAAAAAAAAA-- --AAAAAAAAAAAAAAAAAAAAAAAAAA-- --AAAAAAAAAAAAAAAAAAAAAAAAAA-- --AAAAAAAAAAAAAAAAAAAAAAAAAA-- --AAAAAAAAAAAAAAAAAAAAAAAAAA-- ---CEEEEEDDDDDDFFFFFFDDDDDC--- 
BB--------------------------BB BB--------------------------BB BB-CCCCCCCCCCCCCCCCCCCCCCCC-BB BB-AAAAAAAAAAAAAAAAAAAAAAAA-BB BBAAAAAAAAAAAAAAAAAAAAAAAAAABB BBAAAAAAAAAAAAAAAAAAAAAAAAAABB BBAAAAAAAAAAAAAAAAAAAAAAAAAABB BBAAAAAAAAAAAAAAAAAAAAAAAAAABB BBAAAAAAAAAAAAAAAAAAAAAAAAAABB BBAAAAAAAAAAAAAAAAAAAAAAAAAABB BBAAAAAAAAAAAAAAAAAAAAAAAAAABB BBAAAAAAAAAAAAAAAAAAAAAAAAAABB BBAAAAAAAAAAAAAAAAAAAAAAAAAABB BBAAAAAAAAAAAAAAAAAAAAAAAAAABB BBAAAAAAAAAAAAAAAAAAAAAAAAAABB BBAAAAAAAAAAAAAAAAAAAAAAAAAABB BBAAAAAAAAAAAAAAAAAAAAAAAAAABB BBAAAAAAAAAAAAAAAAAAAAAAAAAABB BBAAAAAAAAAAAAAAAAAAAAAAAAAABB --AAAAAAAAAAAAAAAAAAAAAAAAAA-- --DAAAAAAAAAAAAAAAAAAAAAAAAD-- --DAAAAAAAAAAAAAAAAAAAAAAAAD-- --AAAAAAAAAAAAAAAAAAAAAAAAAA-- --AAAAAAAAAAAAAAAAAAAAAAAAAA-- --AAAAAAAAAAAAAAAAAAAAAAAAAA-- --AAAAAAAAAAAAAAAAAAAAAAAAAB-- --BAAAAAAAAAAAAAAAAAAAAAAAAB-- --AAAAAAAAAAAAAAAAAAAAAAAAAB-- --AAAAAAAAAAAAAAAAAAAAAAAAAA-- ---CEEEEEEDDDDDDFFFFFFDDDDC--- 
BB--------------------------BB BB--------------------------BB BB-CCCCCCCCCCCCCCCCCCCCCCCC-BB BB-AAAAAAAAAAAAAAAAAAAAAAAA-BB BBAAAAAAAAAAAAAAAAAAAAAAAAAABB BBAAAAAAAAAAAAAAAAAAAAAAAAAABB BBAAAAAAAAAAAAAAAAAAAAAAAAAABB BBAAAAAAAAAAAAAAAAAAAAAAAAAABB IBAAAAAAAAAAAAAAAAAAAAAAAAAABI IBAAAAAAAAAAAAAAAAAAAAAAAAAABI IBAAAAAAAAAAAAAAAAAAAAAAAAAABI BBAAAAAAAAAAAAAAAAAAAAAAAAAABB BBAAAAAAAAAAAAAAAAAAAAAAAAAABB BBAAAAAAAAAAAAAAAAAAAAAAAAAABB BBAAAAAAAAAAAAAAAAAAAAAAAAAABB BBAAAAAAAAAAAAAAAAAAAAAAAAAABB BBAAAAAAAAAAAAAAAAAAAAAAAAAABB BBAAAAAAAAAAAAAAAAAAAAAAAAAABB BBAAAAAAAAAAAAAAAAAAAAAAAAAABB --AAAAAAAAAAAAAAAAAAAAAAAAAA-- --DAAAAAAAAAAAAAAAAAAAAAAAAD-- --DAAAAAAAAAAAAAAAAAAAAAAAAD-- --AAAAAAAAAAAAAAAAAAAAAAAAAA-- --AAAAAAAAAAAAAAAAAAAAAAAAAA-- --AAAAAAAAAAAAAAAAAAAAAAAAAA-- --BAAAAAAAAAAAAAAAAAAAAAAAAA-- --BAAAAAAAAAAAAAAAAAAAAAAAAA-- --AAAAAAAAAAAAAAAAAAAAAAAAAA-- --AAAAAAAAAAAAAAAAAAAAAAAAAA-- ---CGEEEEEEDDDDDDFFFFFFDDDC--- 
BB--------------------------BB BB--------------------------BB BB-CCCCCCCCCCCCCCCCCCCCCCCC-BB BB-AAAAAAAAAAAAAAAAAAAAAAAA-BB BBAAAAAAAAAAAAAAAAAAAAAAAAAABB BBAAAAAAAAAAAAAAAAAAAAAAAAAABB BBAAAAAAAAAAAAAAAAAAAAAAAAAABB BBAAAAAAAAAAAAAAAAAAAAAAAAAABB IBAAAAAAAAAAAAAAAAAAAAAAAAAABI IBAAAAAAAAAAAAAAAAAAAAAAAAAABI IBAAAAAAAAAAAAAAAAAAAAAAAAAABI BBAAAAAAAAAAAAAAAAAAAAAAAAAABB BBAAAAAAAAAAAAAAAAAAAAAAAAAABB BBAAAAAAAAAAAAAAAAAAAAAAAAAABB BBAAAAAAAAAAAAAAAAAAAAAAAAAABB BBAAAAAAAAAAAAAAAAAAAAAAAAAABB BBAAAAAAAAAAAAAAAAAAAAAAAAAABB BBAAAAAAAAAAAAAAAAAAAAAAAAAABB -BAAAAAAAAAAAAAAAAAAAAAAAAAABB --AAAAAAAAAAAAAAAAAAAAAAAAAA-- --DAAAAAAAAAAAAAAAAAAAAAAAAD-- --DAAAAAAAAAAAAAAAAAAAAAAAAD-- --AAAAAAAAAAAAAAAAAAAAAAAAAA-- --AAAAAAAAAAAAAAAAAAAAAAAAAA-- --AAAAAAAAAAAAAAAAAAAAAAAAAA-- --AAAAAAAAAAAAAAAAAAAAAAAAAA-- --AAAAAAAAAAAAAAAAAAAAAAAAAA-- --AAAAAAAAAAAAAAAAAAAAAAAAAA-- --AAAAAAAAAAAAAAAAAAAAAAAAAA-- ---CGGEEEEEEDDDDDDFFFFFFDDC--- 
BB--------------------------BB BB--------------------------BB BB-CCCCCCCCCCCCCCCCCCCCCCCC-BB BB-AAAAAAAAAAAAAAAAAAAAAAAA-BB BBAAAAAAAAAAAAAAAAAAAAAAAAAABB BBAAAAAAAAAAAAAAAAAAAAAAAAAABB BBAAAAAAAAAAAAAAAAAAAAAAAAAABB BBAAAAAAAAAAAAAAAAAAAAAAAAAABB IBAAAAAAAAAAAAAAAAAAAAAAAAAABI IBAAAAAAAAAAAAAAAAAAAAAAAAAABI IBAAAAAAAAAAAAAAAAAAAAAAAAAABI BBAAAAAAAAAAAAAAAAAAAAAAAAAABB BBAAAAAAAAAAAAAAAAAAAAAAAAAABB BBAAAAAAAAAAAAAAAAAAAAAAAAAABB BBAAAAAAAAAAAAAAAAAAAAAAAAAABB BBAAAAAAAAAAAAAAAAAAAAAAAAAABB BBAAAAAAAAAAAAAAAAAAAAAAAAAABB BBAAAAAAAAAAAAAAAAAAAAAAAAAABB BBAAAAAAAAAAAAAAAAAAAAAAAAAABB --AAAAAAAAAAAAAAAAAAAAAAAAAA-- --DAAAAAAAAAAAAAAAAAAAAAAAAD-- --DAAAAAAAAAAAAAAAAAAAAAAAAD-- --AAAAAAAAAAAAAAAAAAAAAAAAAA-- --AAAAAAAAAAAAAAAAAAAAAAAAAA-- --AAAAAAAAAAAAAAAAAAAAAAAAAA-- --AAAAAAAAAAAAAAAAAAAAAAAAAB-- --AAAAAAAAAAAAAAAAAAAAAAAAAB-- --AAAAAAAAAAAAAAAAAAAAAAAAAA-- --AAAAAAAAAAAAAAAAAAAAAAAAAA-- ---CGGGEEEEEEDDDDDDFFFFFFDC--- 
BB--------------------------BB BB--------------------------BB BB-CCCCCCCCCCCCCCCCCCCCCCCC-BB BB-AAAAAAAAAAAAAAAAAAAAAAAA-BB BBAAAAAAAAAAAAAAAAAAAAAAAAAABB BBAAAAAAAAAAAAAAAAAAAAAAAAAABB BBAAAAAAAAAAAAAAAAAAAAAAAAAABB BBAAAAAAAAAAAAAAAAAAAAAAAAAABB BBAAAAAAAAAAAAAAAAAAAAAAAAAABB BBAAAAAAAAAAAAAAAAAAAAAAAAAABB BBAAAAAAAAAAAAAAAAAAAAAAAAAABB BBAAAAAAAAAAAAAAAAAAAAAAAAAABB BBAAAAAAAAAAAAAAAAAAAAAAAAAABB BBAAAAAAAAAAAAAAAAAAAAAAAAAABB BBAAAAAAAAAAAAAAAAAAAAAAAAAABB BBAAAAAAAAAAAAAAAAAAAAAAAAAABB BBAAAAAAAAAAAAAAAAAAAAAAAAAABB BBAAAAAAAAAAAAAAAAAAAAAAAAAABB BBAAAAAAAAAAAAAAAAAAAAAAAAAABB --AAAAAAAAAAAAAAAAAAAAAAAAAA-- --DAAAAAAAAAAAAAAAAAAAAAAAAD-- --DAAAAAAAAAAAAAAAAAAAAAAAAD-- --AAAAAAAAAAAAAAAAAAAAAAAAAA-- --AAAAAAAAAAAAAAAAAAAAAAAAAA-- --BAAAAAAAAAAAAAAAAAAAAAAAAA-- --BAAAAAAAAAAAAAAAAAAAAAAAAB-- --BAAAAAAAAAAAAAAAAAAAAAAAAA-- --BAAAAAAAAAAAAAAAAAAAAAAAAA-- --AAAAAAAAAAAAAAAAAAAAAAAAAA-- ---CGGGGEEEEEEDDDDDDFFFFFFC--- 
BB--------------------------BB BB--------------------------BB BB-CCCCCCCCCCCCCCCCCCCCCCCC-BB BB-AAAAAAAAAAAAAAAAAAAAAAAA-BB BBAAAAAAAAAAAAAAAAAAAAAAAAAABB BBAAAAAAAAAAAAAAAAAAAAAAAAAABB BBAAAAAAAAAAAAAAAAAAAAAAAAAABB BBAAAAAAAAAAAAAAAAAAAAAAAAAABB BBAAAAAAAAAAAAAAAAAAAAAAAAAABB BBAAAAAAAAAAAAAAAAAAAAAAAAAABB BBAAAAAAAAAAAAAAAAAAAAAAAAAABB BBAAAAAAAAAAAAAAAAAAAAAAAAAABB BBAAAAAAAAAAAAAAAAAAAAAAAAAABB BBAAAAAAAAAAAAAAAAAAAAAAAAAABB BBAAAAAAAAAAAAAAAAAAAAAAAAAABB BBAAAAAAAAAAAAAAAAAAAAAAAAAABB BBAAAAAAAAAAAAAAAAAAAAAAAAAABB BBAAAAAAAAAAAAAAAAAAAAAAAAAABB BBAAAAAAAAAAAAAAAAAAAAAAAAAABB --AAAAAAAAAAAAAAAAAAAAAAAAAA-- --DAAAAAAAAAAAAAAAAAAAAAAAAD-- --DAAAAAAAAAAAAAAAAAAAAAAAAD-- --AAAAAAAAAAAAAAAAAAAAAAAAAA-- --AAAAAAAAAAAAAAAAAAAAAAAAAA-- --AAAAAAAAAAAAAAAAAAAAAAAAAA-- --BAAAAAAAAAAAAAAAAAAAAAAAAA-- --BAAAAAAAAAAAAAAAAAAAAAAAAB-- --BAAAAAAAAAAAAAAAAAAAAAAAAB-- --AAAAAAAAAAAAAAAAAAAAAAAAAA-- ---CGGGGGEEEEEEDDDDDDFFFFFC--- 
------------------------------ BB--------------------------BB BB-CCCCCCCCCCCCCCCCCCCCCCCC-BB BB-AAAAAAAAAAAAAAAAAAAAAAAA-BB BBAAAAAAAAAAAAAAAAAAAAAAAAAABB BBAAAAAAAAAAAAAAAAAAAAAAAAAABB BBAAAAAAAAAAAAAAAAAAAAAAAAAABB BBAAAAAAAAAAAAAAAAAAAAAAAAAABB BBAAAAAAAAAAAAAAAAAAAAAAAAAABB BBAAAAAAAAAAAAAAAAAAAAAAAAAABB BBAAAAAAAAAAAAAAAAAAAAAAAAAABB BBAAAAAAAAAAAAAAAAAAAAAAAAAABB BBAAAAAAAAAAAAAAAAAAAAAAAAAABB BBAAAAAAAAAAAAAAAAAAAAAAAAAABB BBAAAAAAAAAAAAAAAAAAAAAAAAAABB BBAAAAAAAAAAAAAAAAAAAAAAAAAABB BBAAAAAAAAAAAAAAAAAAAAAAAAAABB BBAAAAAAAAAAAAAAAAAAAAAAAAAABB --AAAAAAAAAAAAAAAAAAAAAAAAAA-- --AAAAAAAAAAACCCCAAAAAAAAAAA-- --AAAAAAAAAACAAAACAAAAAAAAAA-- --DAAAAAAAACAAAAAACAAAAAAAAD-- --AAAAAAAACAAAAAAAACAAAAAAAA-- --AAAAAAACAAAAAAAAAACAAAAAAA-- --AAAAAACAAAAAAAAAAAACAAAAAA-- --BAAAACAAAAAAAAAAAAAACAAAAA-- --BAAACAAAAAAAAAAAAAAAACAAAA-- --BAACAAAAAAAAAAAAAAAAAACAAA-- --AACAAAAAAAAAAAAAAAAAAAACAA-- ---CHGGGGGEEEEEEDDDDDDFFFFC--- 
------------------------------ BB--------------------------BB BB-CCCCCCCCCCCCCCCCCCCCCCCC-BB BB-AAAAAAAAAAAAAAAAAAAAAAAA-BB BBAAAAAAAAAAAAAAAAAAAAAAAAAABB BBAAAAAAAAAAAAAAAAAAAAAAAAAABB BBAAAAAAAAAAAAAAAAAAAAAAAAAABB BBAAAAAAAAAAAAAAAAAAAAAAAAAABB BBAAAAAAAAAAAAAAAAAAAAAAAAAABB BBAAAAAAAAAAAAAAAAAAAAAAAAAABB BBAAAAAAAAAAAAAAAAAAAAAAAAAABB BBAAAAAAAAAAAAAAAAAAAAAAAAAABB BBAAAAAAAAAAAAAAAAAAAAAAAAAABB BBAAAAAAAAAAAAAAAAAAAAAAAAAABB BBAAAAAAAAAAAAAAAAAAAAAAAAAABB BBAAAAAAAAAAAAAAAAAAAAAAAAAABB BBAAAAAAAAAAAAAAAAAAAAAAAAAABB BBAAAAAAAAAAAAAAAAAAAAAAAAAABB --AAAAAAAAAAAAAAAAAAAAAAAAAA-- --AAAAAAAAAAA----AAAAAAAAAAA-- --AAAAAAAAAA-AAAA-AAAAAAAAAA-- --AAAAAAAAA-AAAAAA-AAAAAAAAA-- --AAAAAAAA-AAAAAAAA-AAAAAAAA-- --AAAAAAA-AAAAAAAAAA-AAAAAAA-- --AAAAAA-AAAAAAAAAAAA-AAAAAA-- --AAAAA-AAAAAAAAAAAAAA-AAAAA-- --AAAA-AAAAAAAAAAAAAAAA-AAAA-- --BAA-AAAAAAAAAAAAAAAAAA-AAA-- --AA-AAAAAAAAAAAAAAAAAAAA-AA-- ---CHHGGGGGEEEEEEDDDDDDFFFC--- 
------------------------------ ------------------------------ BB-CCCCCCCCCCCCCCCCCCCCCCCC-BB BB-AAAAAAAAAAAAAAAAAAAAAAAA-BB BBAAAAAAAAAAAAAAAAAAAAAAAAAABB BBAAAAAAAAAAAAAAAAAAAAAAAAAABB BBAAAAAAAAAAAAAAAAAAAAAAAAAABB BBAAAAAAAAAAAAAAAAAAAAAAAAAABB BBAAAAAAAAAAAAAAAAAAAAAAAAAABB BBAAAAAAAAAAAAAAAAAAAAAAAAAABB BBAAAAAAAAAAAAAAAAAAAAAAAAAABB BBAAAAAAAAAAAAAAAAAAAAAAAAAABB BBAAAAAAAAAAAAAAAAAAAAAAAAAABB BBAAAAAAAAAAAAAAAAAAAAAAAAAABB BBAAAAAAAAAAAAAAAAAAAAAAAAAABB BBAAAAAAAAAAAAAAAAAAAAAAAAAABB BBAAAAAAAAAAAAAAAAAAAAAAAAAABB --AAAAAAAAAAAAAAAAAAAAAAAAAA-- --AAAAAAAAAAAAAAAAAAAAAAAAAA-- --AAAAAAAAAAA----AAAAAAAAAAA-- --AAAAAAAAAA-AAAA-AAAAAAAAAA-- --AAAAAAAAA-AAAAAA-AAAAAAAAA-- --AAAAAAAA-AAAAAAAA-AAAAAAAA-- --AAAAAAA-AAAAAAAAAA-AAAAAAA-- --AAAAAA-AAAAAAAAAAAA-AAAAAA-- --AAAAA-AAAAAAAAAAAAAA-AAAAA-- --AAAA-AAAAAAAAAAAAAAAA-AAAA-- --AAA-AAAAAAAAAAAAAAAAAA-AAA-- --AA-AAAAAAAAAAAAAAAAAAAA-AA-- ---CHHHGGGGGEEEEEEDDDDDDFFC--- 
------------------------------ ------------------------------ ---CCCCCCCCCCCCCCCCCCCCCCCC--- BB-AAAAAAAAAAAAAAAAAAAAAAAA-BB BBAAAAAAAAAAAAAAAAAAAAAAAAAABB BBDAAAAAAAAAAAAAAAAAAAAAAAADBB BBDDAAAAAAAAAAAAAAAAAAAAAADDBB BBDDAAAAAAAAAAAAAAAAAAAAAADDBB BBDDAAAAAAAAAAAAAAAAAAAAAADDBB BBDDAAAAAAAAAAAAAAAAAAAAAADDBB BBDDAAAAAAAAAAAAAAAAAAAAAADDBB BBDAAAAAAAAAAAAAAAAAAAAAAAADBB BBAAAAAAAAAAAAAAAAAAAAAAAAAABB BBAAAAAAAAAAAAAAAAAAAAAAAAAABB BBAAAAAAAAAAAAAAAAAAAAAAAAAABB BBAAAAAAAAAAAAAAAAAAAAAAAAAABB --AAAAAAAAAAAAAAAAAAAAAAAAAA-- --AAAAAAAAAAAAAAAAAAAAAAAAAA-- --AAAAAAAAAAAAAAAAAAAAAAAAAA-- --AAAAAAAAAAA----AAAAAAAAAAA-- --AAAAAAAAAA-AAAA-AAAAAAAAAA-- --AAAAAAAAA-AAAAAA-AAAAAAAAA-- --AAAAAAAA-AAAAAAAA-AAAAAAAA-- --AAAAAAA-AAAAAAAAAA-AAAAAAA-- --AAAAAA-AAAAAAAAAAAA-AAAAAA-- --AAAAA-AAAAAAAAAAAAAA-AAAAA-- --AAAA-AAAAAAAAAAAAAAAA-AAAA-- --AAA-AAAAAAAAAAAAAAAAAA-AAA-- --AA-AAAAAAAAAAAAAAAAAAAA-AA-- ---CHHHHGGGGGEEEEEEDDDDDDFC--- 
------------------------------ -----AADDDDDDDDDDDDDDDDAA----- ----ADDDDDDDDDDDDDDDDDDDDA---- ----DDDDDDDDDDDDDDDDDDDDDD---- BB--AAAAAAAAAAAAAAAAAAAAAA--BB BB--ACCCCCCCCCCCCCCCCCCCCA--BB BB--ACHCCCCCCCCCCCCCCCCHCA--BB BB--ACCCCCCCCCCCCCCCCCCCCA--BB BB--ACCCCCCCCCCCCCCCCCCCCA--BB BB--ACCCCCCCCCCCCCCCCCCCCA--BB BB--ACCCHHHHHHHHHHHHHHCCCA--BB BB--ACCCCCCCCCCCCCCCCCCCCA--BB BB--ACCCCCCCCCCCCCCCCCCCCA--BB BBHAACHCCCCCCCCCCCCCCCCHCAAHBB BBAAACCCCCCCCCCCCCCCCCCCCAAABB --AAAAAAAAAAAAAAAAAAAAAAAAAA-- --AAAAAAAADDDDDDDDDDAAAAAAAA-- --AAAAAADDDDDDDDDDDDDDAAAAAA-- --AAAAAAAAAAAAAAAAAAAAAAAAAA-- --DAAAAAAAAAA----AAAAAAAAAAD-- --DAAAAAAAAA-AAAA-AAAAAAAAAD-- --DAAAAAAAA-AAAAAA-AAAAAAAAD-- --DAAAAAAA-AAAAAAAA-AAAAAAAD-- --DAAAAAA-AAAAAAAAAA-AAAAAAD-- --DAAAAA-AAAAAAAAAAAA-AAAAAD-- --DAAAA-AAAAAAAAAAAAAA-AAAAD-- --DAAA-AAAAAAAAAAAAAAAA-AAAD-- --AAA-AAAAAAAAAAAAAAAAAA-AAA-- --AA-AAAAAAAAAAAAAAAAAAAA-AA-- ---CCCCCCCCCCCCCCCCCCCCCCCC--- 
------------------------------ ------------------------------ ------------------------------ ------------------------------ ------------------------------ ------------------------------ BB--------------------------BB BB--------------------------BB BB--------------------------BB BB--------------------------BB BB--------------------------BB BB--------------------------BB BB--------------------------BB ------------------------------ ------------------------------ ------------------------------ ------------------------------ ------------------------------ ------------------------------ ------------------------------ ------------------------------ ------------------------------ ------------------------------ ------------------------------ ------------------------------ ------------------------------ ------------------------------ ------------------------------ ------------------------------ ------------------------------ 
