model
size = 28 32 21, scale = 0.05, origin = -y
material 
  colors = A:#500 B:#B00 C:#D00
voxels
5-18B9-9(BA)2B8-9(AB)2A8-B3A11C4AB8-AB4A7C5ABA8-2AB5A3C6AB2A8-6A7C7A8-5A9C6A2(8-4A2C2A3C2A2C5A)8-3A2C2A5B2A2C4A8-3A2CABA3CABA2C4A8-B2A2C3ACBC3A2C3AB8-3A2C3ACBC3A2C4A8-2BA2CA2B3C2BA2CA3B8-2ABA2C2B3C2B2CAB3A8-B3A2C2A3C2A2C4AB8-2B3A9C4A2B8-A2B3A7C4A2BA8-A3B4A3C5A3BA8-A2B3A7C4A2BA8-3BA11C2A3B8-2AB6A2B6AB2A8-2AB4A6B4AB2A8-2AB3AB6-B3AB2A8-BAB2AB8-B2ABAB8-4BAB8-BA4B175-2(B20-B2(6-A20-A)6-)3(A20-A6-)B20-B6-A20-A3(6-B20-B)6-A20-A2(6-B20-B)2(6-A20-A)7(6-B20-B)6-B4A2B8-2B4AB146-B20-B2(6-A20-A)6-A20-B6-B20-B2(6-A20-A)6-B20-B6-A20-A6-B20-B6-A3(20-B6-B)20-B6-A20-A12(6-B20-B)6-B5AB8-B5AB117-B22-B3(4-A22-A)4-A22-B4-B22-A4-A22-A4-B22-B4-A5(22-B4-B)2(22-B4-A22-A4-B)10(22-B4-B)22-B4-3B4AB8-B4A3B88-B22-B4-A2(22-A4-B)22-A4-A22-A4-B22-B4-A7(22-B4-B)2(22-B4-A22-A4-B)3(22-B4-B)22-B216-7A4-B7AB8-B7AB59-B22-B4-B22-A4-A22-B4-B22-B4-A3(22-A4-B22-B4-B)3(22-B4-B)22-B4-A22-A5(4-B22-B)255-B7AB8-B7AB59-B2(22-B4-A)22-A4-B22-B4-B2(22-A4-B22-B4-A)2(22-A4-B22-B4-B)22-B4-B22-B4-A22-A4(4-B22-B)311-B3A5B8-5B3AB31-B22-B2(4-A22-A)3(4-B22-B4-A22-A)4-B22-A4-A22-A4-B22-B4-B22-A4-B22-B4-A22-A3(4-B22-B)338-B3AB4AB8-B4AB3AB30-B22-B2(4-A22-A)2(4-B22-B4-A22-A)4-B3(22-A4-A)22-A4-B22-A2(4-A22-A4-B22-B)2(4-B22-B)338-B2AB5AB8-B5AB2AB30-B22-B2(4-A22-A)4-B22-B4-A22-A4-B7(22-A4-A)22-A4-B22-A4-A3(22-B4-B)22-B338-BAB6AB8-B6ABAB30-2(B22-B2(4-A22-A)4-)8(A22-A4-)3(B22-B4-)B22-B338-2B7AB8-B7A2B30-B22-B2(4-A22-A)4-B2(22-B4-A22-A4-A)6(22-A4-A)22-B4-B22-A3(4-B22-B)338-3B6AB8-B6A3B30-B22-B2(4-A22-A)2(4-B22-B4-A22-A)4-A22-B3(4-A22-A)4-A2(22-B4-A22-A4-B)2(22-B4-B)22-B338-4B5AB8-B5A4B30-B22-B2(4-A22-A)3(4-B22-B4-A22-A)4-A22-B4-A22-A4-B22-B4-A22-B4-B22-B4-A22-A3(4-B22-B)339-4B4AB8-B4A4B31-B2(22-B4-A)4(22-A4-B22-B4-A)3(22-B4-B)22-B4-A22-A4(4-B22-B)312-4B3AB8-B3A4B32-B22-B4-B22-A4-A2(22-B4-B)2(22-A4-B22-B4-A)5(22-B4-B)2(22-B4-A22-A4-B)2(22-B4-B)22-B257-3B3AB8-B3A3B61-B22-B4-A2(22-A4-B)22-A4-A22-A9(4-B22-B)3(4-A22-A4-B22-B)4-B22-B229-3B3AB8-B3A3B61-B22-B3(4-A22-A)4-A22-B4-B22-A4-A2(22-A4-B22-B4-B)3(22-B4-B)4(22-B4-A22-A4-B)22-B174-2B3AB8-B3A2B90-B21-B3(5-A21-A)5-B21-B2(5-A21-A)5-B21-B5-A2(21-A5-B21-B5-B)21-B4(5-B21-B5-A21-A)2(5-B21-B)120-B3AB8-B3AB120-B20-B2(6-A20-A)6-A20-B6-B4(20-A6-A)20-A6-B20-B6-A20-A6-B20-B6-B4(20-A6-B20-B6-A)20-A2(6-B20-B)92-B3AB8-B3AB122-18B9-2(2B3(AB)A)2B8-2(2A3(BA)B)2A8-AB2A11C3ABA8-B5A7C6AB8-8A3C9A8-6A7C7A8-5A9C6A8-4A2C2A3C2A2C5A8-4A2CA5BA2C5A8-3A2CABA3CABA2C3AB8-3A2C3ACBC3A2C4A8-B2A2C3ACBC3A2C2A2B8-3A2CA2B3C2BA2C4A8-2BA2CA2B3C2BA2CA3B8-4A2C2A3C2A2C5A8-2B2A2C2A3C2A2C3A2B8-A2B2A9C3A3B8-3B3A7C4A3B8-A2B5A3C6A2BA8-3B3A7C4A3B8-2ABA11C2AB2A2(8-3B14A3B)8-2B6A4B5A3B9-B5AB4-B5AB10-B4AB6-B4AB145-
