model
size = 30 17 9, scale = 0.05, origin = -y
material 
  colors = A:#099 B:#BBB C:#096 D:#09C E:#0CF F:#9FF G:#EEE H:#DDD I:#111
voxels
------------------------------ ------------------------------ ------------------------------ ------------------------------ ------------------------------ ------------------------------ ------------------------------ -----------A------------------ ------------------------------ ------------------------------ ------------------------------ ------------------------------ ------------------------------ ------------------------------ ------------------------------ ------------------------------ ------------------------------ 
------------------------------ ------------------------------ ------------------------------ ------------------------------ ------------------------------ ------------------------------ ------------------------------ ----------AA------------------ ------------------------------ ------------------------------ ------------------------------ ------------------------------ ------------------------------ ------------------------------ ------------------------------ ------------------------------ ------------------------------ 
------------------------------ ------------------------------ ------------------------------ ------------------------------ ------------------------------ ------------------------------ -FG--------------------------- FFF-------AA------------------ --F-------AAAAAAAAAA---------- DDDDD-----AAAAAAAAAA---------- -DIDD----AAAAAAAAAA----------- ----D---CCCCCCCCC------------- --------CCCCCCCCC------------- ------------------------------ ------------------------------ ------------------------------ ------------------------------ 
------------------------------ ------------------------------ ------------------------------ ----------BBBBBBBBB----------- ----------BBBBBBBBB----------- ----------BBBBBBBBBBBB-------- -FG-------BBBBBBBBBBBB-------- FFF-------AAAAAAAAAADD-------- --AAAAAAAAAAAAAAAAAADD-------- DD---AAAAAAAAAAAAAAADD-------- -DDDDAAAAAAAAAAAAAAADD-------- ----DAAAAAAAAAAAA------------- --------CCCCCCCCC------------- ------------------------------ ------------------------------ ------------------------------ ------------------------------ 
---------------B-------------- --------------BB------------EE -------------BBB-----A-----EE- ----------BBBBBBBBB-AAA---EEE- --------BBBBBBBBBBBBBBAA-EEE-- -------HHBBBBBBBBBBBBBBBEEE--- -FGGGGGHBBBBBBBBBBBBBBBBEE---- FFFAAAAAAAAAAAAAA---DDDDE----- --AAAAAAAAAAAAA-----DDDDEE---- DD---A--------------DDDDEEE--- -DDDDAAAAAAAAA-----ADD----EE-- ----DAAACAAAA---AAAA------EEE- --------CCCCCCCCC-----------E- -----------CCCC-------------EE -----------CCCC--------------- ------------CC---------------- -------------C---------------- 
------------------------------ ------------------------------ ------------------------------ ----------BBBBBBBBB----------- ----------BBBBBBBBB----------- --------BBBBBBBBBBBBBB-------- -FG-----BBBBBBBBBBBBBB-------- FFF-----AAAAAAAAAAAADD-------- --F-----AAAAAAAAAAAADD-------- DDDDD---AAAAAAAAAAAADD-------- -DIDDAAAAAAAAAAAAAAADD-------- ----D---CAAAAAAAA------------- --------CCCCCCCCC------------- ------------------------------ ------------------------------ ------------------------------ ------------------------------ 
------------------------------ ------------------------------ ------------------------------ ------------------------------ ------------------------------ ------------------------------ ------------------------------ ----------AA------------------ ----------AAAAAAAAAA---------- ----------AAAAAAAAAA---------- ----------AAAAAAAAA----------- ---------CCCCCCCC------------- --------CCCCCCCCC------------- ------------------------------ ------------------------------ ------------------------------ ------------------------------ 
------------------------------ ------------------------------ ------------------------------ ------------------------------ ------------------------------ ------------------------------ ------------------------------ ----------AA------------------ ------------------------------ ------------------------------ ------------------------------ ------------------------------ ------------------------------ ------------------------------ ------------------------------ ------------------------------ ------------------------------ 
------------------------------ ------------------------------ ------------------------------ ------------------------------ ------------------------------ ------------------------------ ------------------------------ -----------A------------------ ------------------------------ ------------------------------ ------------------------------ ------------------------------ ------------------------------ ------------------------------ ------------------------------ ------------------------------ ------------------------------ 
