model
size = 3 28 4, scale = 0.05, origin = -y
material 
  colors = A:#030 B:#EEE C:#444 D:#FF3 E:#AAA
voxels
--- --- --- --- --- --- --- --- --- -A- --- --- --- --- --- --- --- --- --- --- --- --- --- --- --- --- --- --- 
-A- -A- -A- -B- -A- -A- -A- -B- -A- AAA -D- -C- -C- -C- -C- -C- -C- -C- -C- -C- -C- -C- -C- -C- -C- -C- -C- -E- 
-A- -B- -A- -A- -A- -B- -A- -A- -A- AAA -D- -B- -B- -B- -B- -B- -B- -B- -B- -B- -B- -B- -B- -B- -B- -B- -B- --- 
--- --- --- --- --- --- --- --- --- -A- --- --- --- --- --- --- --- --- --- --- --- --- --- --- --- --- --- --- 
