model
size = 6 10 6, scale = 0.05, origin = -y
material 
  colors = A:#030 B:#3F0 C:#600 D:#C00
voxels
------ ------ ------ ------ --AA-- --AA-- ------ ------ ------ ------ 
------ ------ ------ --AA-- -AAAA- -AAAA- --AA-- --AA-- ------ ------ 
--CC-- --DD-- --AA-- -AAAA- AA--AA AA--AA -AAAA- -AAAA- --A--- ------ 
--CC-- --DD-- --AB-- -AAAB- AA--BB AA--BB -ABBB- -ABBB- --BB-- --B--- 
------ ------ ------ --AA-- -AAAA- -AAAA- --AA-- --AA-- ------ ------ 
------ ------ ------ ------ --AA-- --AA-- ------ ------ ------ ------ 
