model
size = 20 32 28, scale = 0.05, origin = -y
material 
  colors = A:#CC0 B:#002 C:#FC9 D:#DDD E:#D00 F:#F69 G:#00F H:#C0F I:#E00 J:#00C K:#444 L:#00E M:#0CF N:#888 O:#004 P:#A00
voxels
88-C-C6(17-A-A)3(17-H-H)4(17-A-A)17-E-E17-A-A17-H-H17-A-A17-L-L4(17-A-A)192-C4-C-C6(12-A4-A-A)12-A4-H-H4(12-A4-A-A)2(17-A-A)17-E-E12-A4-A-A12-A4-H-H6(12-A4-A-A)192-2C3-C-C6(12-2A3-A-A)12-2A3-H-H4(12-2A3-A-A)2(17-A-A)17-E-E12-2A3-A-A12-2A3-H-H6(12-2A3-A-A)150-2(2D14-2D2-)2D-5C-C2(6-2D2-2D-5A-A)6-2D5-4(5A-A13-)5A-H4(13-5A-A)15-E2A-A15-3A-A15-2EA-E13-5A-A13-4AH-H6(13-5A-A)130-2D14-2D2(2-2B14-2B)2-BG-10C3-BG2(2-2B-10A3-2B)2-2D-10A3-2D5-8(10A10-)8A2E10-10A10-5AEA3E10-10A10-5AH4A5(10-10A)10-8A36-2H71-2D14-2D2(2-2B14-2B)3-G15-G2-2B-11C2-2B3-G-11A3-G2-2B-11A2(2-2B)-11A2-2B2-2D-11A2-2D5-17(11A9-)3A4EA16-2E17-2(4E16-)L2EL17-2E11-2D14-2D2-2B14-2B3-G15-G2-2B14-2B2-2B-12C-2B2-2B-12A-2B3-G-12A2-G2-2B-12A-2B2-2D-12A-2D5-4(12A8-)6(11AK8-)11A2M7-12A5(8-11AF)8-3A4EA15-4E15-H4EH15-2(4E16-)4E10-2D14-2D2-BG14-2G2(2-2B14-2B)-4I12C4I-2(2B-12A-2B2-)2G-12A-BG2-2D-12A-2D5-4(12A8-)2(11AK8-11AN8-)2(11AN8-)11A2M7-3(12A8-11AF8-)3A4E5A11-4E15-H4EH15-2(4E16-)4E10-2D14-2D2-2B14-2B3-G15-G2-2B14-2B2-2B-12C-2B2-2B-12A-2B3-G-12A2-G2-2B-12A-2B2-2D-12A-2D5-2(12A8-)12A7-2F11A3(7-2F10AK)3(8-11AK)8-11A2M7-2(12A8-)2(11AF8-12A8-)3A4E5A12-2E17-2(4E16-)L2EL17-2E11-2D14-2D2(2-2B14-2B)3-G15-G2-2B-11C2-2B3-G-11A3-G2-2B-11A2(2-2B)-11A2-2B2-2D-11A2-2D5-11A9-11A2(8-2F10A)2(2(9-11A)8-2F10A)3(8-2F10A)5(9-11A)126-2D14-2D2(2-2B14-2B)2-BG-10C3-BG2(2-2B-10A3-2B)2-2D-10A3-2D5-10A3(9-2F9A)3(10-10A)3(9-2F9A)8-3F9A2(10-10A)2(9-2F9A)4(10-10A)147-2(2D14-2D2-)2D-8C2(5-2D2-2D-8A)5-2D5-2(8A12-)8A2(2(11-2F7A)4(12-8A))11-2F7A4(12-8A)192-6C14-2(7A13-)7A3(12-2F6A)2(5(13-7A)2(12-2F6A))2(12-2F6A)193-7C3(13-7A)13-F6A13-7A12-2F6A12(13-7A)12-2F6A3(13-7A)193-9C4(11-9A)11-F8A10-2F8A12(11-9A)3(10-2F8A)11-9A191-11C3(9-11A)9-F9(10A8-2F)10A4(9-11A)2(8-2F10A)3(9-11A)189-12C2(8-12A)2(8-F11A)7-2F11A4(8-12A)3J5-2(12AJ7-)12A2(J6-2F11A)2(7-2F11A)8-12A7-2F10A4(F8-11A)F188-12C4(8-12A)2(8-F11A)3(8-12A)3J5-3(11AO8-)12AJ7-12A8-12A2(7-2F11A)7-2F10AF8-F11A8-F10AF8-12A8-3A4E4AF13-E17-2(4E16-)L2EL17-2E67-2D18-2D5-12C3(-2D5-12A)6(8-12A)3J5-4(12AJ7-)5(12A8-)11AF8-12A8-11AF8-3A4E5A11-4E15-H4EH15-2(4E16-)4E46-2D2(2-2D14-2B)2-2D-11C2-BG2(2-2D-11A2-2B)5-11A2-2D5-18(11A9-)3A4E4A12-4E15-H4EH15-2(4E16-)4E26-2D2-2D2(14-2B2-2B)15-G2-BG-10C3-2B2-2B-10A4-G2-2B-10A3-2B2-2D-10A3-2B5-10A3-2D5-17(10A10-)3A4E3A14-2E17-2(4E16-)L2EL17-2E11-2D14-2D2-2B14-2B2-2B15-G3-G14-2B2-2B-9C4-2B3-G-9A4-2B2-2B-9A5-G2-2B-9A4-2B2-2D-9A4-2D5-12(9A11-)5AH3A5(11-9A)35-2H71-2D14-2D2-2B14-2G3-G2(14-2B2-2B)-C3-C-2C8I-2B-A3-A-2A5-2B3-G-A3-A-2A5-2B2-2B-A3-A-2A5-BG2-2D-A3-A-2A5-2D5-12(A3-A-2A12-)A3-H-HA5(12-A3-A-2A)109-2D14-2D2-BG14-2B2-2B15-G2-2B14-2B-8IC-C2(6-2B2-2B5-A-A)7-G2-2G5-A-A6-2B2-2D5-A-A6-2D9-12(A-A17-)H-H5(17-A-A)110-2D14-2D2-2B14-2B3-G14-2B2-2B15-G2-2B5-C-C6-2B2-2B5-A-A7-G3-G5-A-A6-2B2-2B5-A-A6-2B2-2D5-A-A6-2D9-12(A-A17-)H-H5(17-A-A)110-2D18-2B14-2D2-2B14-2B3-G14-2B2-2B5-C-C6-BG3-G2(5-A-A6-2B2-2B)5-A-A6-2D2-2D5-13(A-A17-)H-H5(17-A-A)130-2D18-2(2B14-2D2-)BG5-P-P2(6-2D2-2B5-A-A)6-2D2-2D5-14(A-A17-)H-H17-A-A17-L-L3(17-A-A)150-4(2D18-)2D517-
