model
size = 29 32 23, scale = 0.05, origin = -y
material 
  colors = A:#070 B:#200 C:#633 D:#A00 E:#BBB F:#FF9 G:#EEE H:#0B0
voxels
795-7F22-F5-2(F22-3(F-))F20-4F3-4F883-20C9-20C76-F-F26-D-D23-F2-B-D23-D-3BD18-F4-D5B18-D2(-F)7B5-F11-2(D-)10B3-D9-F2(-D)12B2-D9-D-DF14B-D9-D-D16BD9-D-17BD9-D20B8-22B7-5BE10BE5B7-6BE8BE6B7-7BE6BE7B7-8BE4BE8B7-9BE2BE9B2(7-10B2E10B)7-9BE2BE9B7-2BEBE3BE4B4E2BE2B7-3BEB3E6BEB3E3B7-3B2EBE8BEB2EBEB7-2BEB2E8BEB2EBE2B7-3BE2BE8BE2BE3B2(7-22B)7-C20AC7-22C79-F28-D24-B3-D13-F9-3B2-D2-F10-D8-5B-D2-D10-D7-7BD2-D10-D6-10B-D10-D4-D12BD4-F5-D3-D14B4-D5-D3-16B3-D5-D2-17BA2-D5-D-20B-D16(4-2BA22B)6-C20AC7-3C17A2C133-B26-D3B25-5B23-7BD20-10B18-12B16-14B14-16B11-D17BA10-20B5-BADA15(21BAB2-B3A)21BAB2-3C22A2C2-6C17A4C9-H10-H98-F5-H11-H10-2(D28-)D25-F6(2-D25-D)2(-B3A21BABD)-8(B3A21BAB2-)B3A21BAG5(2-B3A21BAB)-C27A5C22A3C6-5A7-5A12-5A7-5A11-H5AH6-5A12-5A7-5AH11-4(5A7-5A12-)5A7-5AH11-5A7-5A12-5A7-5AD7-2(D3-5B7-5B8-)D3-2(5B7-)9(B3A21BAB2-)G2(3A21BAB2-B)3A21BAG4(2-B3A21BAB)-C27A3C24A3C2(5-7A)2(10-7A5-7A)10-7A4-H7A3-F7(6-7A5-7A3-D)6-2(7B5-6BA2(3-D)2-)7B5-6BA2-2D4(2-B3A21BAB)2(2-G2(3A21BAB2-B)3A21BAB)2-G2(3A21BAB2-B)3A21BAG3(2-B3A21BAB)-C27A3C24A3C4-2(9A3-9A8-)9A3-9A7-H2(9A3-9A8-)9A3-9A5-F5(2-9A3-9A5-D)2-A8B3-9B5-D2-A8B3-9B5-2D-A8B3-9B5-B3A21BABD-4(B3A21BAB2-)G2(3A21BAB2-B)3A21BAB2-G3A21BAB2-B3A21BAG2-B3A21BAB2-G2(3A21BAB2-B)3A21BAG2(2-B3A21BAB)-C27A3C24A3C3-11A-11A6-11AH7(11A6-11A-)11AF2(5-11A-11AD)5-2(2A9B-11B6-)2A9B-11B4-5(B-2A21BAB2-)B3A21BAG2-G2(3A21BAB2-B)3A21BAB2-G3A21BAB2-B3A21BAG2-B3A21BAB2-G2(3A21BAB2-B)3A21BAG2-B3A21BAB-C27A3C24A3C-F6(2(-11A)4-D)2(-11A)-F7(2-D2(-11A)-D)4(2-B-24AB)2-G-24A2(B2-B25A)G2-G2(25AB2-B)25AB2-G25AB2-B25AG4(2-B25AB)-C27A3C24A3C3-9(11A-11A6-)4(11A-11A5-D)11A-11A4-2(BD24AB2-)3(B-24AB2-)G2(25AB2-B)25AG2-G2(25AB2-B)25AB2-G25AB2-B25AG3(2-B25AB)-C27A3C24A3C3-4(11A-11A6-)11A-11AF7(5-11A-11AD)4-D11A-11ADF2-2D11A-11A2D2-BD4(24AB2-B-)24AB2-B25AB2-G2(25AB2-B)25AG2-G2(25AB2-B)25AB2-G25AB2-B25AG2(2-B25AB)-C27A3C24A3C3-11A-11A6-11A-11AH4-H2(11A-11A6-)11A-11A5-F6(11A-11A5-D)11A-11A4-2(2D11A-11AD3-)B-23AD4(B2-B-23A-)B2(2-B24A2B)2-G2(24A2B2-B)24ABG2-G5(24A2B2-B)24A2B-C26AC-2C24A3C4-5(9A3-9A8-)9A3-9AH7-7(9A3-9A8-)9A3-8AD5-2B23AB3-B24A2(B3-2B23A)4(B3-B24A)B3-G24AB3-B24AG3-B24AB3-G4(24AB3-B)24AB2-C26AC-4C22A3C2(5-7A)10-7A4-H7A10-7A5-7A9-H4(7A5-7A10-)7A5-7A2-F4-D2-7A5-7A2-D4-F4(2-7A5-7A2-D4-D)2-7A5-7A2-D9(3-B24AB)3-G24AB3-B24AG3-B24AB3-G3(24AB3-B)24AB2-C26AC-4C22A3C5-H12(5A7-5A12-)5A7-5A8-2D2-2(5A7-)15(B24AB3-)B24AB2-C26AC-5C21A3C2(19-H)11-H53-H17-H24-F28-D17-H10-D28-D23-F4(4-D23-D)4-3D21-D16(2-3B23AB)-4C23AC2-4C21A3C295-3(D28-)D27-B19A2DA15(B5-B22A)B5-C22AC5-2C18A4C14-F3(28-D)-F4-F21-D-D4-D21-D-B4-D16-F4-D3B3-D16-D-D2-5B2-D-F14-2(D-)7B2(-D)14-D-10BD-D14-D12B-D4-F8-F14BD4-D8-16BD3-D6-D18B3-D5-B19ADA2D5-15(B21AB6-)C21A2C5-2C18A4C43-D91-F25-B2-D24-3B-D23-5BD22-7B6-F8-F4-10B5-D8-D3-12B4-D8-D2-14B3-D8-D-16B2-D8-D18B-D7-B19ADA15(B6-B21A)B7-20A2C7-C18A3C157-F4-B23-D3-3B22-D2-5B21-D-7B20-10B18-12B16-14B13-D16B12-18B10-21B8-5BE10BE4B8-6BE8BE5B8-7B2(E6B)8-8BE4BE7B8-9BE2BE8B8-6BE3B2E3BE5B8-5B2(2E3B)2E4B8-4B3E2(2BE)2B3E3B8-3B4EBE4BEB4E2B8-7B2(E6B)8-6BE8BE5B4(8-21B)8-C18A3C7-21C879-19C10-19C4-
