model
size = 32 16 32, scale = 0.05, origin = -y
material 
  colors = A:#E28700 B:#800 C:#FFA750
voxels
76-2(7A25-)7A17-21B11-21B12-20B19-2(7A25-)7A217-7A22-2(13A19-)13A13-24B9-23B10-22B14-2(13A19-)13A22-7A153-7A22-13A17-2(17A15-)17A10-27B5-27B7-24B11-17A15-C16A15-2C15A17-13A22-7A118-13A17-17A14-2(19A13-)19A8-29B3-29B6-25B9-2(19A13-)A-C16A16-15A17-13A22-7A85-15A15-19A12-2(21A11-)21A6-30B2-30B3-28B8-21A11-2A-18A11-2A-C16AC12-C-C15AC16-14A19-11A81-19A12-21A10-2(23A9-)23A5-30B2-30B3-29B6-23A9-3AC18AC9-3A-C13AC-2AC10-2A-C12AC3-C12-A2-12A19-13A23-7A50-21A10-23A8-2(25A7-)25A4-2(30B2-)30B5-25A7-18AC6A7-4AC12AC-2C4A8-3A-C11AC2-2C2A10-2A2-10AC3-C-A15-10A23-9A50-21A9-25A6-2(27A5-)27A3-2(31B-)31B3-2(27A5-)19AC7A6-4A2C10A3C6A9-2A2-9AC3-4A12-A2-9AC3-3A16-9A3-A46-23A8-25A6-2(27A5-)27A3-31B-31B2-30B3-2(27A5-)27A6-4A2C8A2C9A8-3A2-7AC2-C7A10-2A3-6A4-6A15-7A3-C3A44-25A6-27A4-2(29A3-)29A2-31B-31B2-30B2-2(29A3-)29A4-6AC8AC11A6-5A-C5A2C-10A9-2A3-5A4-7A13-A2-3A5-C5A21-2A20-25A6-27A4-2(29A3-)29A2-32B-31B-30B2-2(29A3-)29A4-27A6-5A2C4A3C11A8-4A3-3A4-9A11-2A12-5A18-4A2-C2A15-25A6-27A4-2(29A3-)29A2-32B-63B-2(29A3-)29A4-7AC19A6-6A-3A2C13A8-5A2-2A2-C-10A11-2A13-4A18-3A3-4A13-27A4-29A2-3(31A-)96B2(31A-)31A2-29A4-7A2C18A6-6A3-A2(C-)11A9-4A12-5A18-2A2-5A13-27A4-29A2-3(31A-)96B2(31A-)31A2-9AC19A4-8A-C3A6C8A6-6AC4-C2-2C9A9-4A13-4A15-A3-A2-6A12-27A4-29A2-3(31A-)96B2(31A-)31A2-10AC4ACA3C9A4-8AC-C2AC5-C7A6-7A2(5-C)6A9-4A13-4A15-2A9-2A12-27A4-29A2-2(31A-)15AB15A2-78BA16B2(31A-)31A2-15AC3A2C8A4-9AC-2AC3-C2-C6A6-7AC2-CAC2-C4-C4A9-4A5-A9-2A15-3A22-27A4-29A2-2(31A-)31A2-95B2(31A-)31A2-15AC13A4-10AC2A2-3A4C5A6-8AC-CA3-CAC3-C3A9-4A5-A10-A15-5A2-4A14-27A4-29A2-2(31A-)31A2-31B-63B2(31A-)31A2-29A4-13A3C5A2C4A6-9ACAC3-C3AC2-C-A9-4A32-4A3-5A13-27A4-29A2-3(31A-)32B-63B2(31A-)31A2-25AC3A4-12A-CA2C4A4C2A6-10A2(C2-)C3A4-A9-5A11-2A19-3A5-3A14-25A6-27A4-2(29A3-)29A2-32B-63B-2(29A3-)25AC3A4-12AC10AC-2A6-10AC-CA2C5AC2-A8-8AC2-AC2-C4A14-4A11-3A18-A4-A2-3A14-25A6-27A4-2(29A3-)29A2-32B-63B-2(29A3-)11AC-C11A2C2A4-2(10AC2-)A6-9A3-3AC6A11-7A4-2AC2-5A13-5A9-5A21-2A3-A15-25A6-27A4-2(29A3-)29A4-30B-63B-29A3-11AC14AC2A3-10AC-C12AC-2A4-8AC3-C11A2-C6-7AC3-4AC7A11-5A4-4A-C6A13-2A10-C4A21-4A19-23A8-25A6-2(27A5-)27A4-31B2-62B2-27A5-9AC15ACA5-8AC-C14A-C7-4A2C3-14A10-A7-5A2C7A18-5A2-6A19-4A2-C3A46-21A9-25A6-2(27A5-)27A4-30B2-30B-31B3-27A5-26AC5-2(CA)4C18AC6-C-2C3-C16A16-7A2C6A17-7A2-5A18-6A3-2A47-21A10-22A9-2(25A7-)25A5-2(30B2-)30B4-25A7-CA2C21A7-2C2-C20A13-10AC7A15-9A-C5A16-8AC-4A18-8A2-A49-19A12-21A10-2(23A9-)23A6-2(29B3-)30B5-2(23A9-)23A11-13AC6A14-10AC-5A15-10AC-3A21-6A54-15A15-19A12-2(21A11-)21A7-2(29B3-)30B6-2(21A11-)21A12-13AC5A15-10AC-3A19-8A2-A84-13A17-17A14-2(19A13-)19A8-2(29B3-)29B8-2(19A13-)13AC5A14-11AC-4A17-9AC-2A22-6A90-7A22-13A17-2(17A15-)17A9-28B4-28B5-27B10-17A15-12AC4A15-11AC-4A17-9A2-2A22-6A154-7A22-2(13A19-)13A13-24B7-25B8-25B13-13A19-9A2C2A19-9A2-2A22-6A218-2(7A25-)7A17-22B10-22B11-21B18-7A25-5A27-5A343-15B16-16B16-17B264-
