model
size = 21 32 9, scale = 0.05, origin = -y
material 
  colors = A:#FF3 B:#777 C:#AAA
voxels
8-5C15-7C13-9B12-B7CB12-BC5BCB12-B7CB12-9B12-9A11-11A9-13A8-13A7-3(15A6-)15A5-17A3-19A2-19A-147A-19A2-19A3-17A5-15A7-13A9-11A12-7A15-C3BC15-7C13-9B3(12-C7BC)12-9B12-9A11-11A9-13A8-13A7-3(15A6-)15A5-17A3-19A2-19A-147A-19A2-19A3-17A5-15A7-13A9-11A12-7A15-2(CB)C15-7C13-2(9B12-C7BC12-)9B12-9A11-11A9-13A8-13A7-3(15A6-)15A5-17A3-19A2-19A-147A-19A2-19A3-17A5-15A7-13A9-11A12-7A15-C3BC15-7C13-2(9B12-C7BC12-)9B12-9A11-11A9-13A8-13A7-3(15A6-)15A5-17A3-19A2-19A-147A-19A2-19A3-17A5-15A7-13A9-11A12-7A15-2(CB)C15-7C13-2(9B12-C7BC12-)9B12-9A11-11A9-13A8-13A7-3(15A6-)15A5-17A3-19A2-19A-147A-2A-16A2-19A3-17A5-15A7-13A9-11A12-7A15-C3BC15-7C13-2(9B12-C7BC12-)9B12-9A11-11A9-13A8-13A7-3(15A6-)15A5-17A3-19A2-19A-147A-19A2-19A3-17A5-15A7-13A9-11A12-7A15-2(CB)C15-7C13-2(9B12-C7BC12-)9B12-9A11-11A9-13A8-13A7-3(15A6-)15A5-17A3-19A2-19A-147A-19A2-19A3-17A5-15A7-13A9-11A12-7A15-C3BC15-7C13-9B3(12-C7BC)12-9B12-9A11-11A9-13A8-13A7-3(15A6-)15A5-17A3-19A2-19A-147A-19A2-19A3-17A5-15A7-13A9-11A12-7A15-5C15-7C13-9B12-B7CB12-BC5BCB12-B7CB12-9B12-9A11-11A9-13A8-13A7-3(15A6-)15A5-17A3-19A2-19A-147A-19A2-19A3-17A5-15A7-13A9-11A12-7A7-
