model
size = 18 23 31, scale = 0.05, origin = -y
material 
  colors = A:#222 B:#111 C:#555 D:#0E0 E:#444 F:#0A0 G:#D00 H:#00E
voxels
------------------ ------------------ ------------------ ------------------ ------------------ ------------------ ------------------ ------------------ ------------------ --------A--------- ------------------ ------------------ ------------------ ------------------ ------------------ ------------------ ------------------ ------------------ ------------------ ------------------ ------------------ ------------------ ------------------ 
------------------ ------------------ ------------------ ------------------ ------------------ ------------AF---- ------------AA---- --------F--------- -------AFA-------- --------A--------- ------------------ ------------------ ------------------ ------------------ ------------------ ------------------ ------------------ ------------------ ------------------ ------------------ ------------------ ------------------ ------------------ 
------------------ ------------------ ------------------ ------------------ --------------A--- ------------ABA--- ------------AB---- --------BA-------- -------ABA---A---- -------AA--------- --------AA-------- --A--------------- ---A-------------- ------------------ ------------------ ------------------ ------------------ ------------------ ------------------ ------------------ ------------------ ------------------ ------------------ 
------------------ ------------------ ------------------ ------------------ ------------------ -------------AA--- ------------ABA--- ------------ABA--- --------AA---A---- -------ABAA------- ----A--AAA-------- --AFA---A--------- --AB-------------- ------------------ ------------------ ------------------ ------------------ ------------------ ------------------ ------------------ ------------------ ------------------ ------------------ 
------------------ ------------------ ------------------ ------------------ ------------------ -------------A---- --------------A--- ------------ABA--- ------------AA---- --------BA---AA--- -------ADA---A---- ---AA--AAAA------- --ABA---AA-------- --AA-------------- ------------------ ------------------ ------------------ ------------------ ------------------ ------------------ ------------------ ------------------ ------------------ 
------------------ ------------------ ------------------ ---------------AA- ---------------A-- ------------------ ------------------ -------------AA--- ------------AAA--- ------------ABB--- --------DA---A---- ---A---ABAA------- ---AA--AAB-------- --ABA---A--------- --AB-------------- ------------------ ------------------ ------------------ ------------------ ------------------ ------------------ ------------------ ------------------ 
------------------ ------------------ ----------------AA ---------------ABA ---------------AB- ------------------ ------------------ -------------A---- ------------DBA--- ------------AAA--- --------AA--AA---- -------AAA-------- -------AAA-------- ---DA---A--------- --AAA------------- --A--------------- ------------------ ------------------ ------------------ ------------------ ------------------ ------------------ ------------------ 
------------------ ------------------ ----------------A- ---------------AAA --------------AABA ---------------AA- ------------------ -------------A---- ------------DA---- -----------ABBA--- --------A---ABA--- -------BAA--A----- ------AABA-------- ---A---AB--------- --BBA------------- --AB-------------- --A--------------- ------------------ ------------------ ------------------ ------------------ ------------------ ------------------ 
------------------ ------------------ ------------------ ----------------A- ----------------AA ---------------ABA ---------------AA- ----------------A- -------------A---- -----------ADA---- -----------AAAA--- -------DA---AA---- ------ADAA--A----- ---A--AAAA-------- --DA---AB--------- -ABA-------------- --A--------------- ------------------ ------------------ ------------------ ------------------ ------------------ ------------------ 
------------------ ------------------ ------------------ ------------------ ----------------A- ---------------DAA --------------AAAA ---------------AB- ------------------ ------------AA---- -----------ABA---- -----------ABB---- -------BA---A----- ------ABAA-------- ---A--AAA--------- -ABA---A---------- -AA--------------- ------------------ ------------------ ------------------ ------------------ ------------------ ------------------ 
------------------ ------------------ ------------------ ------------------ ----------------A- ---------------BA- --------------ADBA ---------------AAA ---------------A-- ------------A----- -----------DAA---- -----------AAA---- -------AA--AA----- ------AAA--------- ------ABB--------- --DA---A---------- -ABA-------------- -A---------------- ------------------ ------------------ ------------------ ------------------ ------------------ 
------------------ ------------------ ---------------A-- ------------------ ------------------ ----------------A- --------------ADA- --------------ABBA ---------------AB- ------------A--A-- -----------BA----- ----------ABBA---- -------A---AAA---- ------BAA--A------ -----AAAA--------- --A---AA---------- -DBA-------------- -ABA-------------- -A---------------- ------------------ ------------------ ------------------ ------------------ 
--------------A--- -------------B-DA- ---------------A-- ------------------ ------------------ ------------------ ---------------AA- --------------AAA- --------------AAA- ---------------A-- ------------A----- ----------ADA----- ----------ABBA---- ------DA---AB----- -----ABAA--A------ --AAAAABA--------- -BAA--AB---------- ABBA-------------- -ABA-------------- ------------------ ------------------ ------------------ ------------------ 
--------------A--- -------------BAAA- -------------A-AA- --------------AB-- ------------------ ------------------ ---------------A-- --------------BAA- -------------AABA- --------------AB-- ------------------ -----------AA----- ----------AAA----- ----------AAA----- ------DA---A------ --AAAABAA--------- --AAAAAA---------- ABAAAAA----------- -AAAAA------------ --A--------------- ------------------ ------------------ ------------------ 
------------------ -------------AAA-- -------------BBBA- --------------AA-- --------------A--- ------------------ ---------------A-- --------------DA-- -------------ADAA- --------------AAA- --------------A--- -----------A------ ----------BBA----- -------AA-ABA----- ---AABAA--AA------ --AAAABA---------- --AAAABB---------- -AAAAAA----------- -AAABA------------ --AAB------------- ------------------ ------------------ ------------------ 
------------------ ---------------A-- -------------ABA-- --------------DB-- --------------A--- ------------------ ------------------ ---------------A-- -------------ABA-- -------------ABBA- --------------AA-- -----------A--A--- ----A----ABA------ --AAB--AAABAA----- --AABBAAAAAAA----- -A-AABAAAAA------- --AAAABAA--------- -AAAAAB----------- AAAAAA------------ -AAAA------------- ---A-------------- ------------------ ------------------ 
------------------ ------------------ -------------A-A-- ------------B-BA-- --------------A--- ------------------ ------------------ ------------------ --------------AA-- -------------AAA-- -------------ABB-- -----AB---AA--A--- ---BAA---AAA------ --ABAFBDAABA------ --A--DBAAABBA----- -AA-BBAAAAAA------ -AAAABAAA-A------- -AAAAABA---------- -AAAAABA---------- -AAAA------------- --AA-------------- ------------------ ------------------ 
------------------ ------------------ -------------A---- ------------AADA-- --------------BA-- -------------A---- ------------------ ------------------ --------------A--- -------------BBA-- -----A-D----AABA-- ----AAAB--AA-AA--- ---AAAFBBAAAAA---- --ABA--DAABAA----- --ABBD-AAAAAA----- -AAABFAAAAAA------ ---AABAAA-A------- --AAABBA---------- -AAAAAAA---------- -AAAAA------------ --AA-------------- ------------------ ------------------ 
------------------ ------------------ ------------------ ------------BAA--- ------------BBAA-- -------------AA--- -------------A---- ------------------ ----------A---A--- -------ABB---AA--- ----B-AFAF--ABBA-- ---AAAAFFBDAAABA-- ---AAAADFBAAAA---- --BAA--AAAAAA----- -AABD--AABBA------ -AA-BFAAAABA------ AAAABAAACAA------- -AAAABAAAA-------- -AAAABBAA--------- -AAAAAAA---------- --AAA------------- ------------------ ------------------ 
------------------ ------------------ ------------------ --------------A--- ------------ADA--- ------------ADB--- -------------AA--- -----------AAAAA-- --------AAAA-AA--- ------DAAABF-AA--- ----ABAAAFBD--A--- ---AAAAADAFA-BAA-- --AAAAA--AAAAAA--- --BA-----AAAAA---- -ABAH---ABAC------ -AABD-AAABBA------ AA-BBCCAAA-------- A-AABCEAC--------- -AAAABAAA--------- -AAAAAAA---------- --AAA-A----------- ------------------ ------------------ 
------------------ ------------------ ------------------ ------------------ ------------------ -----------AAAA--- ------------AAAA-- ----------BAAAAA-- -------BAAABAAA--- ------ABAAABBAAA-- --AA-BDAAAD-D-A--- --AAA-DA----ABA--- -AAA------AAABB--- -AAC-----AAAAAA--- -ABC----AAAAA----- -ABCH--AABAAA----- -A--F-CDABB------- AAABBCCCCAB------- --AABEAAA--------- --AAABAA---------- ---AAB------------ ------------------ ------------------ 
------------------ ------------------ ------------------ ------------------ ------------------ -----------B-AA--- -----------AAAAA-- ---------ABAAAAA-- -------AAABB-AAA-- ---BDBAAAAA--AAA-- --ACA---AAD-DAAA-- --BC--------BBA--- -ABC-------AABA--- -AAC-----AAAAAA--- -ACC----AADCAAB--- -ABC---AAAACA----- -ABBF-ACABAA------ ---BFCCDA-A------- --AABECAEA-------- ---ABBAAE--------- -----BA----------- ------------------ ------------------ 
------------------ ------------------ ------------------ ------------------ ------------------ -----------B------ -----------AAAA--- ---------B-AAA-A-- -----BAAAABAA-AA-- ---ABAAAAABDAAAA-- --BAB---A-GGAAAA-- -ABC------G-BAAAA- -ABC-------CBBAA-- -ACC------CCEBA--- -ACC-----ACCAAA--- -BCC---AAACCAA---- -ABH--AAABAAA----- --ABFC-CABA------- --ABCECCA--------- --AABEAAA--------- ----BB-A---------- ------------------ ------------------ 
------------------ ------------------ ------------------ ------------------ ------------------ ------------------ -----------BA----- ------A--A-AAAA--- -----AABAAAAAAAA-- ----BACCACBA-AA--- ---BDAC-CCBDAAAA-- -AAAD-----DDAAAA-- -ACD------FCBAAA-- -ACC------CCBBA--- -ACC-----ACCAA---- AAC-----AADAAA---- -ACD------CEA----- ---D-C-----A------ ---ACCDCAA-------- ---ACEACA--------- ----BAAA---------- ------------------ ------------------ 
------------------ ------------------ ------------------ ------------------ ------------------ ------------------ ------------------ ------------AA---- -----BAA-BAAA----- ----BBBCABAAAAA--- ---BAACCCCBAAAA--- --BAB-D--CGDAAAA-- -ACA------FDAAAA-- -BCC------FCBAA--- -AC-------CEBB---- -EC-------CAA----- -AC-------CAA----- -ACH-----ACA------ --AF-CC--BA------- --AACCCC-B-------- ---AE-AE---------- ------A----------- ------------------ 
------------------ ------------------ ------------------ ------------------ ------------------ ------------------ ------------------ ------------AA---- ------AA-AAAAAA--- ----AABAABAA-AA--- ---DBCDCCBB--AA--- --ADD-CC-CAAAAA--- -BCA-----GFDAAAA-- -BC-------FBBAA--- -BC-------CEBA---- -EC-------CEA----- -CC------DCA------ -AC------ACA------ -A-F--D--A-------- --AFCCDAAB-------- ---AECAEA--------- ------AE---------- ------------------ 
------------------ ------------------ ------------------ ------------------ ------------------ ------------------ ------------------ ------------------ ---------A-AA----- -----ABABAAA------ ----ACBACBAAA----- --ABACDCCB--A----- -BAD---C-G-AAA---- -BC------DFBA----- -BD-------CBBA---- -CC------CCEB----- -CC------CCA------ ACC------DCA------ -BD------AEA------ -BBFE-CA-A-------- --BEEEEA---------- ----EAAE---------- ------A----------- 
------------------ ------------------ ------------------ ------------------ ------------------ ------------------ ------------------ ------------------ ------------------ -----A--AA-------- ----BABABAAA------ ---AAACACBA-A----- --BBAC-CCBAAA----- -BAB-----GAAA----- -CC------FCBA----- -CC------CCBB----- EEE------CC-B----- AE-------DA------- B-D------CEA------ -D--E-----E------- --B---EABA-------- ----BB------------ ------------------ 
------------------ ------------------ ------------------ ------------------ ------------------ ------------------ ------------------ ------------------ ------------------ ------------------ ----B-A-AA-------- ---BBBCABAAA------ --DBADCCCB--A----- -AAD-D--CAAAA----- -AA------FDAA----- BAE------FC------- B--------CE------- B--------CA------- ---------EA------- --------AEE------- ------------------ ------------------ ------------------ 
------------------ ------------------ ------------------ ------------------ ------------------ ------------------ ------------------ ------------------ ------------------ ------------------ --------AA-------- ---AAB-EA--------- --BAACCCAA-------- -ABF-CC-C--A------ B-A-----GFA------- B--------FA------- ---------EE------- ---------EE------- ----------A------- ------------------ ------------------ ------------------ ------------------ 
------------------ ------------------ ------------------ ------------------ ------------------ ------------------ ------------------ ------------------ ------------------ ------------------ ------------------ -----B------------ ---AABECA--------- -BD-AEEEB--------- ------E-DB-------- --------DFA------- ----------A------- ----------B------- ------------------ ------------------ ------------------ ------------------ ------------------ 
