model
size = 18 23 31, scale = 0.05, origin = -y
material 
  colors = A:#222 B:#111 C:#555 D:#0E0 E:#444 F:#0A0 G:#D00 H:#00E
voxels
------------------ ------------------ ------------------ ------------------ ------------------ ------------------ ------------------ ------------------ ------------------ ---------A-------- ------------------ ------------------ ------------------ ------------------ ------------------ ------------------ ------------------ ------------------ ------------------ ------------------ ------------------ ------------------ ------------------ 
------------------ ------------------ ------------------ ------------------ ------------------ ----FA------------ ----AA------------ ---------F-------- --------AFA------- ---------A-------- ------------------ ------------------ ------------------ ------------------ ------------------ ------------------ ------------------ ------------------ ------------------ ------------------ ------------------ ------------------ ------------------ 
------------------ ------------------ ------------------ ------------------ ---A-------------- ---ABA------------ ----BA------------ --------AB-------- ----A---ABA------- ---------AA------- --------AA-------- ---------------A-- --------------A--- ------------------ ------------------ ------------------ ------------------ ------------------ ------------------ ------------------ ------------------ ------------------ ------------------ 
------------------ ------------------ ------------------ ------------------ ------------------ ---AA------------- ---ABA------------ ---ABA------------ ----A---AA-------- -------AABA------- --------AAA--A---- ---------A---AFA-- --------------BA-- ------------------ ------------------ ------------------ ------------------ ------------------ ------------------ ------------------ ------------------ ------------------ ------------------ 
------------------ ------------------ ------------------ ------------------ ------------------ ----A------------- ---A-------------- ---ABA------------ ----AA------------ ---AA---AB-------- ----A---ADA------- -------AAAA--AA--- --------AA---ABA-- --------------AA-- ------------------ ------------------ ------------------ ------------------ ------------------ ------------------ ------------------ ------------------ ------------------ 
------------------ ------------------ ------------------ -AA--------------- --A--------------- ------------------ ------------------ ---AA------------- ---AAA------------ ---BBA------------ ----A---AD-------- -------AABA---A--- --------BAA--AA--- ---------A---ABA-- --------------BA-- ------------------ ------------------ ------------------ ------------------ ------------------ ------------------ ------------------ ------------------ 
------------------ ------------------ AA---------------- ABA--------------- -BA--------------- ------------------ ------------------ ----A------------- ---ABD------------ ---AAA------------ ----AA--AA-------- --------AAA------- --------AAA------- ---------A---AD--- -------------AAA-- ---------------A-- ------------------ ------------------ ------------------ ------------------ ------------------ ------------------ ------------------ 
------------------ ------------------ -A---------------- AAA--------------- ABAA-------------- -AA--------------- ------------------ ----A------------- ----AD------------ ---ABBA----------- ---ABA---A-------- -----A--AAB------- --------ABAA------ ---------BA---A--- -------------ABB-- --------------BA-- ---------------A-- ------------------ ------------------ ------------------ ------------------ ------------------ ------------------ 
------------------ ------------------ ------------------ -A---------------- AA---------------- ABA--------------- -AA--------------- -A---------------- ----A------------- ----ADA----------- ---AAAA----------- ----AA---AD------- -----A--AADA------ --------AAAA--A--- ---------BA---AD-- --------------ABA- ---------------A-- ------------------ ------------------ ------------------ ------------------ ------------------ ------------------ 
------------------ ------------------ ------------------ ------------------ -A---------------- AAD--------------- AAAA-------------- -BA--------------- ------------------ ----AA------------ ----ABA----------- ----BBA----------- -----A---AB------- --------AABA------ ---------AAA--A--- ----------A---ABA- ---------------AA- ------------------ ------------------ ------------------ ------------------ ------------------ ------------------ 
------------------ ------------------ ------------------ ------------------ -A---------------- -AB--------------- ABDA-------------- AAA--------------- --A--------------- -----A------------ ----AAD----------- ----AAA----------- -----AA--AA------- ---------AAA------ ---------BBA------ ----------A---AD-- --------------ABA- ----------------A- ------------------ ------------------ ------------------ ------------------ ------------------ 
------------------ ------------------ --A--------------- ------------------ ------------------ -A---------------- -ADA-------------- ABBA-------------- -BA--------------- --A--A------------ -----AB----------- ----ABBA---------- ----AAA---A------- ------A--AAB------ ---------AAAA----- ----------AA---A-- --------------ABD- --------------ABA- ----------------A- ------------------ ------------------ ------------------ ------------------ 
---A-------------- -AD-B------------- --A--------------- ------------------ ------------------ ------------------ -AA--------------- -AAA-------------- -AAA-------------- --A--------------- -----A------------ -----ADA---------- ----ABBA---------- -----BA---AD------ ------A--AABA----- ---------ABAAAAA-- ----------BA--AAB- --------------ABBA --------------ABA- ------------------ ------------------ ------------------ ------------------ 
---A-------------- -AAAB------------- -AA-A------------- --BA-------------- ------------------ ------------------ --A--------------- -AAB-------------- -ABAA------------- --BA-------------- ------------------ -----AA----------- -----AAA---------- -----AAA---------- ------A---AD------ ---------AABAAAA-- ----------AAAAAA-- -----------AAAAABA ------------AAAAA- ---------------A-- ------------------ ------------------ ------------------ 
------------------ --AAA------------- -ABBB------------- --AA-------------- ---A-------------- ------------------ --A--------------- --AD-------------- -AADA------------- -AAA-------------- ---A-------------- ------A----------- -----ABB---------- -----ABA-AA------- ------AA--AABAA--- ----------ABAAAA-- ----------BBAAAA-- -----------AAAAAA- ------------ABAAA- -------------BAA-- ------------------ ------------------ ------------------ 
------------------ --A--------------- --ABA------------- --BD-------------- ---A-------------- ------------------ ------------------ --A--------------- --ABA------------- -ABBA------------- --AA-------------- ---A--A----------- ------ABA----A---- -----AABAAA--BAA-- -----AAAAAAABBAA-- -------AAAAABAA-A- ---------AABAAAA-- -----------BAAAAA- ------------AAAAAA -------------AAAA- --------------A--- ------------------ ------------------ 
------------------ ------------------ --A-A------------- --AB-B------------ ---A-------------- ------------------ ------------------ ------------------ --AA-------------- --AAA------------- --BBA------------- ---A--AA---BA----- ------AAA---AAB--- ------ABAADBFABA-- -----ABBAAABD--A-- ------AAAAAABB-AA- -------A-AAABAAAA- ----------ABAAAAA- ----------ABAAAAA- -------------AAAA- --------------AA-- ------------------ ------------------ 
------------------ ------------------ ----A------------- --ADAA------------ --AB-------------- ----A------------- ------------------ ------------------ ---A-------------- --ABB------------- --ABAA----D-A----- ---AA-AA--BAAA---- ----AAAAABBFAAA--- -----AABAAD--ABA-- -----AAAAAA-DBBA-- ------AAAAAAFBAAA- -------A-AAABAA--- ----------ABBAAA-- ----------AAAAAAA- ------------AAAAA- --------------AA-- ------------------ ------------------ 
------------------ ------------------ ------------------ ---AAB------------ --AABB------------ ---AA------------- ----A------------- ------------------ ---A---A---------- ---AA---BBA------- --ABBA--FAFA-B---- --ABAAADBFFAAAA--- ----AAAABFDAAAA--- -----AAAAAA--AAB-- ------ABBAA--DBAA- ------ABAAAAFB-AA- -------AACAAABAAAA --------AAAABAAAA- ---------AABBAAAA- ----------AAAAAAA- -------------AAA-- ------------------ ------------------ 
------------------ ------------------ ------------------ ---A-------------- ---ADA------------ ---BDA------------ ---AA------------- --AAAAA----------- ---AA-AAAA-------- ---AA-FBAAAD------ ---A--DBFAAABA---- --AAB-AFADAAAAA--- ---AAAAAA--AAAAA-- ----AAAAA-----AB-- ------CABA---HABA- ------ABBAAA-DBAA- --------AAACCBB-AA ---------CAECBAA-A ---------AAABAAAA- ----------AAAAAAA- -----------A-AAA-- ------------------ ------------------ 
------------------ ------------------ ------------------ ------------------ ------------------ ---AAAA----------- --AAAA------------ --AAAAAB---------- ---AAABAAAB------- --AAABBAAABA------ ---A-D-DAAADB-AA-- ---ABA----AD-AAA-- ---BBAAA------AAA- ---AAAAAA-----CAA- -----AAAAA----CBA- -----AAABAA--HCBA- -------BBADC-F--A- -------BACCCCBBAAA ---------AAAEBAA-- ----------AABAAA-- ------------BAA--- ------------------ ------------------ 
------------------ ------------------ ------------------ ------------------ ------------------ ---AA-B----------- --AAAAA----------- --AAAAABA--------- --AAA-BBAAA------- --AAA--AAAAABDB--- --AAAD-DAA---ACA-- ---ABB--------CB-- ---ABAA-------CBA- ---AAAAAA-----CAA- ---BAACDAA----CCA- -----ACAAAA---CBA- ------AABACA-FBBA- -------A-ADCCFB--- --------AEACEBAA-- ---------EAABBA--- -----------AB----- ------------------ ------------------ 
------------------ ------------------ ------------------ ------------------ ------------------ ------B----------- ---AAAA----------- --A-AAA-B--------- --AA-AABAAAAB----- --AAAADBAAAAABA--- --AAAAGG-A---BAB-- -AAAAB-G------CBA- --AABBC-------CBA- ---ABECC------CCA- ---AAACCA-----CCA- ----AACCAAA---CCB- -----AAABAAA--HBA- -------ABAC-CFBA-- ---------ACCECBA-- ---------AAAEBAA-- ----------A-BB---- ------------------ ------------------ 
------------------ ------------------ ------------------ ------------------ ------------------ ------------------ -----AB----------- ---AAAA-A--A------ --AAAAAAAABAA----- ---AA-ABCACCAB---- --AAAADBCC-CADB--- --AAAADD-----DAAA- --AAABCF------DCA- ---ABBCC------CCA- ----AACCA-----CCA- ----AAADAA-----CAA -----AEC------DCA- ------A-----C-D--- --------AACDCCA--- ---------ACAECA--- ----------AAAB---- ------------------ ------------------ 
------------------ ------------------ ------------------ ------------------ ------------------ ------------------ ------------------ ----AA------------ -----AAAB-AAB----- ---AAAAABACBBB---- ---AAAABCCCCAAB--- --AAAADGC--D-BAB-- --AAAADF------ACA- ---AABCF------CCB- ----BBEC-------CA- -----AAC-------CE- -----AAC-------CA- ------ACA-----HCA- -------AB--CC-FA-- --------B-CCCCAA-- ----------EA-EA--- -----------A------ ------------------ 
------------------ ------------------ ------------------ ------------------ ------------------ ------------------ ------------------ ----AA------------ ---AAAAAA-AA------ ---AA-AABAABAA---- ---AA--BBCCDCBD--- ---AAAAAC-CC-DDA-- --AAAADFG-----ACB- ---AABBF-------CB- ----ABEC-------CB- -----AEC-------CE- ------ACD------CC- ------ACA------CA- --------A--D--F-A- --------BAADCCFA-- ---------AEACEA--- ----------EA------ ------------------ 
------------------ ------------------ ------------------ ------------------ ------------------ ------------------ ------------------ ------------------ -----AA-A--------- ------AAABABA----- -----AAABCABCA---- -----A--BCCDCABA-- ----AAA-G-C---DAB- -----ABFD------CB- ----ABBC-------DB- -----BECC------CC- ------ACC------CC- ------ACD------CCA ------AEA------DB- --------A-AC-EFBB- ----------AEEEEB-- ----------EAAE---- -----------A------ 
------------------ ------------------ ------------------ ------------------ ------------------ ------------------ ------------------ ------------------ ------------------ --------AA--A----- ------AAABABAB---- -----A-ABCACAAA--- -----AAABCC-CABB-- -----AAAG-----BAB- -----ABCF------CC- -----BBCC------CC- -----B-CC------EEE -------AD-------EA ------AEC------D-B -------E-----E--D- --------ABAE---B-- ------------BB---- ------------------ 
------------------ ------------------ ------------------ ------------------ ------------------ ------------------ ------------------ ------------------ ------------------ ------------------ --------AA-A-B---- ------AAABACBBB--- -----A--BCCCDABD-- -----AAAAC--D-DAA- -----AADF------AA- -------CF------EAB -------EC--------B -------AC--------B -------AE--------- -------EEA-------- ------------------ ------------------ ------------------ 
------------------ ------------------ ------------------ ------------------ ------------------ ------------------ ------------------ ------------------ ------------------ ------------------ --------AA-------- ---------AE-BAA--- --------AACCCAAB-- ------A--C-CC-FBA- -------AFG-----A-B -------AF--------B -------EE--------- -------EE--------- -------A---------- ------------------ ------------------ ------------------ ------------------ 
------------------ ------------------ ------------------ ------------------ ------------------ ------------------ ------------------ ------------------ ------------------ ------------------ ------------------ ------------B----- ---------ACEBAA--- ---------BEEEA-DB- --------BD-E------ -------AFD-------- -------A---------- -------B---------- ------------------ ------------------ ------------------ ------------------ ------------------ 
