model
size = 18 24 32, scale = 0.05, origin = -y
material 
  colors = A:#222 B:#555 C:#111 D:#444 E:#0E0 F:#0A0 G:#00E H:#D00 I:#E00
voxels
134-E18-C17-C-2C354-2(C17-)2C17-C2D16-A2DA-AE11-A2-2A299-2(C17-)AD16-2D16-AD16-A-B2-D-C-A9-A3BD2AC11-ADB3A16-A246-C16-2C2(16-CD)16-AD16-2B8-C6-2AB6-AD8-AHB4-C2A9-A3BEACE10-CAD2B2A13-D2-A230-C16-E15-2ACA14-2A7-C8-CE8-C7-BE6-2DC6-A2B6-2D7-AB7-EA7-ACG6-2A9-G2B2-AC2A9-C4BAF11-A-DABA230-A2-C13-2A2D3C10-ECA4DC9-CAC4-2DC8-BA6-DCA6-C2B6-2(BD7-AB7-)BA7-AB7-BA7-AEH5-3A9-4B-ACA10-A2BABAC11-A2-2A230-2AC-2A11-FCBE2BAC9-CFC-2B-B9-CBA5-I2(BA7-CB7-)BD7-AB7-BD7-2B6-EBA7-CB6-AB8-A-B2-E-C2A9-A3BE2AE11-ADB3A16-A213-2C2-A11-ECBC2BA10-AEA-4BE8-C2A5-GEC7-CB7-BA7-CE7-BD7-AB7-BD7-2B6-2BA6-2AB6-AB8-CHB4-C2A9-C4BACF10-CAD2B2A13-D2-A230-CBCA-A11-FA4BA9-3CA2-2BH9-CA6-H2A7-CE7-BA7-2B6-2BD6-A2B6-EB7-AB7-EA7-ACG6-2A8-EH2B2-AC2A9-A4BAE11-A-DABA230-C2-A13-2C2B2AC10-ECAE3BC9-2AC4-BGC8-BA6-B2A6-CBE6-2B7-AB7-BD2(7-AB7-BA)7-C-H5-3A9-4B-AFA10-A2BABAF11-A2-2A230-A2C-2A11-FA4B2A9-CEC-2B-B9-ABA5-G2(BA7-CB7-)BD7-AB7-BD7-2B6-2BA7-AB6-AB8-AEB2-E-C2A9-A4B2AC11-ADB3A16-A213-AC2-A11-ECBC2BA10-AFA-E3BE8-C2A5-H-C7-CB7-BA7-CE7-BD7-AB7-BD7-2B6-EBA6-ACB6-AB8-CGB4-C2A9-C4BACE10-2AD2B2A13-D2-A230-ABCA-A11-EA4BA9-3CA2-2BG9-2C6-GCA7-CB7-BA7-2B6-2BD6-A2B6-EB7-AB7-BA7-2AH6-2A8-EH2B2-AC2A9-C4BAF11-A-DABA230-C2-A13-2C2B2AC10-F2CE3BA9-3C4-BHA8-BA6-B2A6-CBE6-2B7-AB7-BD7-AB7-EA7-AB7-BA7-C-G5-3A8-E3BE-ACA10-A2BABAE11-A2-2A230-A2C-2A11-EA4B2A9-AEC-EB-BE8-ABC5-GBC7-CB7-BA7-CB7-BD7-AB7-BD7-2B6-2BA7-AB6-AB8-C-B2-B-C2A9-C4B2AF11-ADB3A16-A213-2C2-A11-FABC2BA10-AFC-4B9-2CA5-H-2(A7-CB7-B)D7-AB7-BD7-2B6-EBA6-ACB6-AB8-AGB4-C2A9-A3BEACF10-2AD2B2A13-D2-A230-ABCA-A11-EA4BC9-2ACA2-2BGE8-AC6-HCA7-CE7-BA7-BE6-2BD6-A2B6-2B7-AB7-BA7-ACH6-2A9-G2B2-AC2A9-C4BAE11-A-DABA230-C2-A13-2A2B3A10-F2C4BA9-3A4-BGA8-BA6-BCA6-C2B6-2B7-AB7-BD7-AB7-EA7-AB7-BA7-AEH5-3A8-E3BE-AFA10-A2BABAF11-A2-2A213-A16-2ACB2A11-F2AE3BC9-3C-E2-BEC8-BC6-BA7-CBE6-2B7-AB7-BD2(7-AB7-BA)7-CBG5-ABA9-B-2B-2CA9-2A2BEBAC11-AD-3A230-2C2-A11-ECBC2BA10-AFA-4B9-C2A5-GEC7-CB7-BA7-CB7-BD7-AB7-BD7-2B6-2BA6-2AB6-AB8-AHB4-C2A9-A4BACE10-CAD2B2A13-D2-A230-ABCA-A11-EA4BC9-4C2-2BI9-CA6-I2A7-CE7-BA7-2B6-2BD6-A2B6-EB7-AB7-EA7-ACG6-2A8-EG2B2-AC2A9-A4BAF11-A-DABA230-C2-A13-AC2B3A10-FCAE3BC9-3C4-BGC8-BC6-BCA6-C2B6-2B7-AB7-BD2(7-AB7-BA)7-CEH5-3A9-4B-ACA10-A2BABAE11-A2-2A213-C16-A2CB2A11-E2CE3BA9-2AC-B2-B-A8-BA6-BA7-CBE6-2B7-AB7-BD2(7-AB7-BA)7-ABG5-ABA8-EB-BE-CEA9-2A2BEBAF11-AD-3A230-2C2-A11-FABC2BA10-CFA-E3BE8-2CA5-IEC7-CB7-BA7-CE7-BD7-AB7-BD7-2B6-2BA6-2AB6-AB8-CGB4-C2A9-C4BA2C10-CAD2B2A13-D2-A230-CBCA-A11-EA4BA9-2ACA2-2BI9-CA6-GCA7-CB7-BA7-2B6-2BD6-A2B6-EB7-AB7-BA7-2AH6-2A8-EH2B2-AC2A9-A4BAE11-A-DABA230-C2-A13-2A2B2AC10-ECAE3BC9-CAC4-BIC8-BA6-B2A6-CBE6-2B7-AB7-BD2(7-AB7-BA)7-C-G5-3A9-3BE-AFA10-A2BABAF11-A2-2A213-A16-3CB2A11-FCA4BA9-2AC-B2-BEA8-BA6-BC7-C2B6-2B7-AB7-BD2(7-AB7-BA)7-ABH5-ABA8-EB-BE-2CA9-CA4BAC11-AD-3A230-2C2-A11-EABC2BA10-AEA-E3BE8-2CA5-I-A7-CB7-BA7-CE7-BD7-AB7-BD7-DB6-EBA6-ACD6-AB8-C2D4-C2A9-C4DACF10-3C2D2A13-C2-A230-CBCA-A11-FA4BC9-A2CA2-2BGE8-2A6-GCA7-CB7-BA7-2D6-2BD6-C2D6-2B7-C8-BA8-C7-2A14-AC2A15-E16-C230-C2-A13-AC2B2AC10-ECA4BA9-2AC4-BIA8-DA6-B2A6-C8-2B16-2D2(16-DA)16-AC16-A246-A16-2ACB2A11-F2AD3BA9-2(C-)D2-BEA16-DA2(16-2D)2(17-C)299-AC2-A11-EC-C2DA16-2DC17-2C2(17-C)97-
