model
size = 32 32 28, scale = 0.05, origin = -y
material 
  colors = A:#080 B:#070 C:#0A0 D:#0B0 E:#400
voxels
586-2E8-2E20-2E8-2E85-D351-2(2E5-2E87-)2E5-2E276-5B6-5B15-7B3-8B3(14-8B-9B)14-7B3-8B15-4B7-5B338-4B3-4B20-5B3-5B15-D35-5B3-5B4-D14-5B3-5B51-5B3-5B20-4B3-4B17-D16-D19-D69-D55-3B27-A2B-A2B4-7A15-5A3B9A13-8A-B4(10A12-9A-)10A14-7A-8A17-3B8-3BA269-9(22A10-)4A2B9A2B4AB10-4A4B6A2B5AB10-4A2BAB5A9B10-3A5B5A6B3A10-2A6B3A8B3A10-A3B3A5B2A5B3A10-9AB12A6(10-22A)11-20A13-2A4BA3-2(A2B)2A26-D4-D236-22A10-21AB3(10-22A)10-21AB10-B20A3(B10-21A)B2(10-22A)10-7A12-3A11(10-22A)8-3ABA7B-A5BA3BA233-24A8-A22-A3(8-A22-B)2(8-B22-A)8-A22-A5(8-A22-B)8-A8-11A3-B3(8-A22-A)3-A3(4-A22-A2-2A)3-2A22-A2-2A4-A22-A2-A5-A2(22-A7-2A)22-A6-4A8B3A7B4A12-D7-D179-24A8-A2(22-B7-D2(A22-B8-)B22-B8-B)22-BD7-A22-B3(8-A22-A)8-B22-AD2-A4-B22-A2-2A4-A22-A2-3A3-A22-A2-5A-A22-A-6A-A22-10A22-8A-A22-5A-2A-A22-5A4-A22-2A-A5-A22-A8-A15-8A6-10A3B2A2BAB8A167-24A8-B22-AD7-B22-A8-A22-B8-B2(22-B8-A)2(22-B8-B)2(22-A8-A)3(22-A8-B)22-A3-A4-B22-A2-3A3-A22-A2-2AB2A-A22-A-6A2(-A22-8A)-A4(22-10A)22-5A-4A22-4A5-A22-2A5-12A2(2BA)B8A6-D160-24A8-A2(22-A8-B)22-B8-B22-A2(8-B22-B)4(8-B22-A)3(8-A22-A)3-2A3-A22-A2-2AB2A-A22-A-3AB2A2(-A22-8A)-A2(22-10A)22-4AC5A22-4AC3A2(-A22-8A)-A22-4A2-2A-A22-3A30-A5-12A7B8A17-B-BA2B2A3-D18-A-2A3B2A24-7A25-6A17-24A8-A22-A8-A22-B8-B2(22-B8-A)22-B8-B5(22-A8-A)22-A8-B22-A3-A4-B22-A2-2AB3-B22-A2-2AB2A-A22-A-6A-A22-5AC2A-A22-4A2C2A-A2(22-4AC5A)22-10A22-4AC5A22-10A22-8A-A22-5A-2A-A22-4A29-2A4-27A6-25A14-11A2(22-10A)15-24A8-A2(22-A8-B)2(22-B8-B)22-A8-B3(22-A8-A)3(22-A8-B)22-A3-2A3-A22-A2-2AB2A-A22-A-3AB2A2(-A22-8A)-A22-5AC2A-A22-5AC4A22-4A2C4A22-5AC2A-A22-4AC5A2(22-10A)22-8A-A22-4A2-2A25-2A4-28A4-27A11-16A16-16A18-13A13-24A8-A22-A7-DB22-B8-A22-B2(8-B22-A)D7-B22-A8-B22-A7-D2(B22-A8-)2(A22-A8-)A22-A3-AB3-A22-A2-2AB2A-A22-A-6A3(-A22-8A)-A22-5AC4A22-4AC5A22-4A2C2A-A22-4A2C4A2(22-10A)22-8A-A22-4A2-2A25-2A4-28A4-27A10-17A15-17A17-15A12-24A8-A22-A8-B22-B2(8-A22-A)3(8-B22-A)3(8-A22-A)2(8-B22-A)3-AB3-B22-A2-5A-A22-A-6A2(-A22-8A)-A22-5AC2A-A22-5A-4A22-4ACA2-2A22-4AC5A22-4A2C4A2(22-10A)22-8A-A22-4A2-2A25-2A4-28A4-27A10-17A15-17A17-15A12-24A4(8-A22-B)8-B22-B8-A3(22-B8-B)22-AD7-2(B22-A8-)A22-A3-2A3-A22-A2-5A-A22-A-6A2(-A22-8A)-A22-5AC4A22-4AC3A-A22-4AC5A22-10A22-4A2C4A2(22-10A)22-8A-A22-4A2-2A25-2A4-28A5-26A11-16A16-16A18-13A13-23A2(B8-A22-)BD7-A22-B8-A22-A8-A22-B8-B22-B8-A22-A3(8-A22-B)2(8-A22-A)4-A3-A22-A3-4A-A22-A-6A-A22-8A-A22-4A2C2A-A22-4A2C4A22-4AC3A-A22-10A22-4AC5A22-4A2C4A2(22-10A)22-4A-3A-A22-3A2-D2A25-2A4-27AD6-19AB3A14-14A19-13A20-C9A15-23A2(B8-B22-)2(B8-A22-)A8-A22-A3(8-B22-B)5(8-A22-A)3-2A3-A22-A2-5A-A22-A-3AC2A-A22-5AC2A-A2(22-10A)2(22-4AC3A-A)22-5AC2A-A22-8A-A22-10A22-4A2-2A-A22-3A30-A6-26A9-D8-7CB24-5C25-7C24-7CA16-24A8-A22-B8-B22-A8-B2(22-B8-A)2(22-A8-A)22-A2(8-B22-B)4(8-A22-A)4-A3-A22-A3-4A-A22-A-3AC2A-A22-8A-A3(22-10A)22-5AC4A22-5AC2A-A22-8A-A22-4A-3A-A22-3A3-2A-A22-3A30-A7-4A6B2A7BA2B2A20-6C25-C2-2A26-4C27-C4A18-24A8-A22-B8-A22-A2(8-B22-B)2(8-A22-B)D7-4(B22-B8-)3(B22-A8-)B22-A4-A3-B22-A4-3A-B22-2(A-)4A4(-A22-8A)-A22-4A-5A22-3A2-5A22-3A3-2ABA22-3A5-2A22-2A8-3A3B5AB6AB5A8-7A5-6A17-A101-4A18-24A3(8-A22-B)8-B22-A8-A2(22-A8-B)22-A2(8-A22-B)8-B22-B8-B22-A8-A22-A7-D3(A22-A8-)B22-A4-A3-B22-A4-3A-B22-A-A3(2-3A-A22-3A)3-2A-A22-3A6-A22-2A7-A22-A8-A22-A9-2A7B2ABA6B5A11-A2-2A7-2D4-D137-B23A8-A22-B3(8-A22-A)2(8-B22-A)18(8-A22-A)8-9AB7AB6A9-10A29-D151-B22A9-A21-B3(9-A21-A)9-B4(21-A9-A)5(21-A9-B)9(21-A9-A)31-5B2(3A2B)2(A2B)2A9-5A6B2A2B2AB5A14-3A5-7A17-A155-22A10-A20-B3(10-A20-A)10-B20-A9-D11(B20-B10-)2(B20-A10-)A20-A10-A20-A31-A9-A21-A10-4A3B5A8B2A12-16A16-5A5-7A16-A189-20A12-19AB3(12-20A)12-18A2B12-19AB6(12-20A)4(12-19AB)11-D19AB12-B18AB12-B19A12-20A22-10A11-A7B4A2BA2B4A13-16A17-8A2-5A16-D2-D11-D256-2(D23-)16AD15-3(16A16-)16A15-17A15-9(19A13-)B17AB13-19A14-18A14-3A4B3A2BAB4A13-11A-4A17-7A4-4A370-15A3(16-16A)16-8A-7A15-17A15-9(19A13-)18AB13-19A15-8AB7A16-3A2(BA)-A2(B2A)18-4A4-5A19-2A6-D375-11B20-2BA3B3-4B17-DABA4B-A-5BA16-7BADA6B16-7B3-6B15-A8B-A6B15-A7BA2(-A7BA13-A8B-8BA13-A8B)-7B2A13-A7BA2(-8BA13-A8B)-A6B2A13-A8BD8BA13-A8B-8BA14-A6BA-7BA16-A4BA3-5BA18-4A5-4A19-3A7-3A437-A31-A6-2A22-2A6-3A20-3A6-A-A20-3A6-D-A20-4A5-A-A20-2A-A4-2A-A18-D-2A-A4-A2-2A19-4A4-A2-2A19-3A-D3-2A-2A19-3A6-A-2A19-A-A6-A-2A20-2A6-A-2A28-4A21-D7-A662-2A61-A42-A31-A84-A31-A534-
