model
size = 32 9 13, scale = 0.05, origin = -y
material 
  colors = A:#F75C2F B:#F05E1C C:#E1591A D:#E67B4A
voxels
33-10B2C2D4C6BD5B2-C2A7B8C11AB2-CABA2D4B3CBD2BAD2A3C2A2BAB2-BA3CD4C5B3C3A3CDA2BAD2-DA4C2D2C5A3C2B7ABAB2-2(2BA)3B8A2(BD)2BD5AB2-D6BD4BD11B3C3B34-8BD10B2D8BD-B3(29A3B)29AB2D2(29A3B)29A2B-B2D10B6C9BDB-B3AD5A2D6AD10A2DB63AD63AB31ABD30AB32A3B3A2D4A2C4AB2DB7ADC6B2A2C4AC6A4B4AD2AB32AD30ABC3(30A2C)30AD32A4B8A2CD3ABD2BAD5BDA5BA2B2C2B4A2BA6B3A2B2AB32AB30ABC3(30A2C)30ACB31A2B2C3A2BA2BC2DADA4BA5B3D5BA2BCD2BAB5C4BD3CD5C2(B31A)C30ACD30ADC30A2C30ACB31A5B2A2BABDCDA2BA4BA5B2DC2B4A2B2C2BAB6C5B8CB30ADB31A4(C30AB)D31AB2D2BAD2BA2BCB3A3BADC2BD2B3A2B4A2B2CBD4BD3CD6BA2B2AB64AC31AC30ABC30ADC30ABD30A2(3BA)BD2ADC4A3B2AC5B3A2(2BA)2B2C7B3C7BABADABD63AC30ABD30ABC30A2C30AC32A2BA3BAB3A2D3A2C2B2AC5B3A2B3AD2A2CA2D4A3CAD6AB3AB64AB30A2B62AC31AC32A2BAC2B6CAB2DCD2B3AD2BCB3A2B15A3C12AB58A7B31AB30A2D95AB2A3BD7AD3AD12AB-4BD8BD4C5BD6B-B14AC15A2B25A7B3(30A2B)30AC32B-16B3D7BD3B34-14BC15B2-B19A6BD2BD2-BC3B8CD5A2D6C3B2-5B2CD5C7B7C3B2-B2ABD8CA4B2(D5B)2-B2A2B8C5ADA3B6AB2-5BD4CD2CB2(D5B)D3B33-
