model
size = 25 32 25, scale = 0.05, origin = -y
material 
  colors = A:#58B2DC B:#CEE4F2 C:#EEE D:#E03C8A E:#CA1515
voxels
634-7B768-7B16-11B741-7C16-2B7-2B12-4B7-4B714-7A16-2C7-2C12-2B11-2B9-3B11-3B689-5A17-11A13-C11-C10-2B13-2B7-3B13-3B663-5A18-9A14-13A11-CE12-C8-2B-E13-2B5-3B15-3B162-5B470-5A18-9A14-13A11-AE13A9-C3E12-C7-B-3E13-B5-2B2-E14-2B160-9B443-5A18-9A15-11A13-13A10-17A7-C2-E14-C5-B3-E15-B3-2B19-2B158-11B417-5A19-7A16-11A13-13A11-15A9-17A7-C17-C5-B19-B3-2B19-2B158-11B393-3B20-7A17-9A15-11A13-13A11-15A8-19A5-C19-B3-B21-B-2B21-2B156-13B17-3B347-3B21-B3AB18-9A15-11A13-13A11-15A9-17A7-19A5-C19-B3-B21-B-2B21-2B156-13B16-5B321-3B21-B3AB19-B5AB17-9A15-11A13-11ADA11-12AD2A9-13AD3A7-14AD4A5-C14-D4-B3-B15-D5-B-2B15-D5-2B17-2(D24-)2(D25-)6D31-13B16-5B22-11(B24-)B23-BAB21-B3AB19-B5AB17-9A15-9ACA13-10AC-A11-11AC-CA9-12AC-C2A7-13AC-C3A5-C13-C-C2(3-B)14-3C4-B-2B14-3C4-2B16-2(3C22-)3C23-8C18-C25-6C6-13B16-5B321-3B21-B3AB19-B5AB17-9A15-11A13-11ADA11-12AD2A9-13AD3A7-14AD4A5-C14-D4-B3-B15-D5-B-2B15-D5-2B17-2(D24-)2(D25-)6D31-13B17-3B347-3B21-B3AB18-9A15-11A13-13A11-15A9-17A7-19A5-C19-B3-B21-B-2B21-2B157-11B393-3B20-7A17-9A15-11A13-13A11-15A8-19A5-C19-B3-B21-B-2B21-2B157-11B417-5A19-7A16-11A13-13A11-15A9-17A7-C17-B5-B19-B3-2B19-2B159-9B443-5A18-9A15-11A13-13A10-17A7-C17-B5-B19-B3-2B19-2B161-5B470-5A18-9A14-13A11-15A9-C15-B7-B17-B5-2B17-2B662-5A18-9A14-13A11-C13-B8-2B15-2B5-3B15-3B687-5A17-11A13-C11-B10-2B13-2B7-3B13-3B712-7A16-2C7-2B12-2B11-2B9-3B11-3B738-5C2B16-2B7-2B12-4B7-4B764-7B16-11B791-7B159-
