model
size = 11 28 11, scale = 0.05, origin = -y
material 
  colors = A:#EEE B:#CAAD5F C:#E83015 D:#FBE251 E:#AAA F:#BBB G:#C4C4C4 H:#FFFFFB I:#313131
voxels
----------- ----------- ----AAA---- ---AAAAA--- ---CCCCC--- ---CCCCC--- ---CCCCC--- ---CCCCC--- ---AAAAA--- ---AAAAA--- ---AAAAA--- ---AAAAA--- ---AAAAA--- ---AAAAA--- ---AAAAA--- ---AAAAA--- ---AAAAA--- ---AAAAA--- ---AAAAA--- ---AAAAA--- ---AAAAA--- ---AAAAA--- ---AAAAA--- ---AAAAA--- ---AAAAA--- ---DDDDD--- ----DDD---- ----------- 
----------- ---EEEEE--- --AABBBAA-- --AABBBAA-- --CCCCCCC-- --ACCCCCC-- --CCCCCCC-- --CCCCCCC-- --AABBAAA-- --AAAAAAA-- --AAAAAAA-- --AAAAAAA-- --AAAAAAA-- --AAAAAAA-- --AAAAAAA-- --AAAAAAA-- --DAAAAAA-- --DAAAAAA-- --DAAAAAA-- --AAAAAAA-- --AAAAAAA-- --AABBAAA-- --AABBAAA-- --AABBBAA-- --AABBBAA-- --DD---DD-- ---DDDDD--- ----EEE---- 
----FFF---- --EEAAAEE-- -AABBBBBAA- -AABBBBBAA- -CCCCCCCCC- -AACCCCCCC- -CCCCCCCCC- -CCCCCCCCC- -AABBBAAAH- -AAAAAAAAH- -AAAAAAAAH- -AAAAAAAAA- -AAAAAAAAA- -AAAAAAAAH- -AAAAAAAAA- -DAAAAAAAG- -CAAAAAAAA- -CAAAAAAAG- -CAAAAAAAA- -DAAAAAAAG- -AAAAAAAAA- -AABBBAAAA- -AABBBAAAA- -AABBBBBAA- -AABBBBBAA- -DD-----DD- --DDDDDDD-- ---E---E--- 
---F---F--- -EEAEEEAEE- -ABBBBBBBA- AABBBBBBBAA CCCCBBBBCCC AAACBBBBCCC CCCCBBBBCCC CCCCBBAACCC DAABBBAAAAI AAABBBAAAAI AAABBBAAAAH AAABBBAAAAA AAABBBAAAAA AAABBBAAAHH DAABBBAAAAA CAABBBAAAGG CAABBBAAAAA AAABBBAAAGG CAABBBAAAAA CAABBBAAAGG DAABBBAAAAA AAABBBAAAAA AAABBBAAAAA AAABBBBBAAA AAABBBBBAAA DD-------DD -DDDDDDDDD- --E-----E-- 
--F-----F-- -EAEEEEEAE- AABBBBBBBAA AABBBBBBBAA CCCCBBBBCCC AAACBBBBCCC CCCCBBBBCCC DCCCBBBBCCC GAABBBBBAAH DAABBBBBAAH AAABBBBBAAH AAABBBBBAAA AAABBBBBAAA AAABBBBBAHH CAABBBBBAAA CAABBBBBAAG CAABBBBBAAA AAABBBBBAAA CAABBBBBAAA CAABBBBBAGG CAABBBAAAAA AAABBBAAAAA AAABBBAAAAA AAABBBBBAAA AAABBBBBAAA DD-------DD DDD--FDDDDD -E---FFFFFF 
--F-----F-- -EAEEEEEAE- AABBBBBBBAA AABBBBBBBAA CCCCBBBBCCC AAACBBBBCCC DCCCBBBBCCC GCCCBBBBCCC GAABBBBBAAI GAABBBBBAAI DAABBBBBAAH AAABBBBBAAA AAABBBBBAAA AAABBBBBAAA CAABBBBBAAA AAABBBBBAAG CAABBBBBAAA AAABBBBBAGG CAABBBBBAAA CAABBBBBAGG CAABBBBBAAA AAABBBBBAAA AAABBBBBAAA AAABBBBBAAA AAABBBBBAAA DD-------DD DDD--FDDDDD -E---F-F--F 
--F-----F-- -EAEEEEEAE- AABBBBBBBAA AABBBBBBBAA CCCCBBBBCCC AAACBBBBCCC CCCCBBBBCCC DCCCBBBBCCC GAABBBBBAAH DAABBBBBAAH AAABBBBBAAH AAABBBBBAAA AAABBBBBAAA AAABBBBBAHH CAABBBBBAAA CAABBBBBAAA CAABBBBBAAA AAABBBBBAGG CAABBBBBAAA CAABBBBBAAA CAAAAABBAAA AAAAAABBAAA AAAAAABBAAA AAABBBBBAAA AAABBBBBAAA DD-------DD DDD--FDDDDD -E---FFFFFF 
---F---F--- -EEAEEEAEE- -ABBBBBBBA- AABBBBBBBAA CCCCBBBBCCC AAACBBBBCCC CCCCBBBBCCC CCCCAABBCCC DAAAAABBAAI AAAAAABBAAI AAAAAABBAAH AAAAAABBAAA AAAAAABBAAA AAAAAABBAHH DAAAAABBAAA CAAAAABBAGG CAAAAABBAAA AAAAAABBAGG CAAAAABBAAA CAAAAABBAGG DAAAAABBAAA AAAAAABBAAA AAAAAABBAAA AAABBBBBAAA AAABBBBBAAA DD-------DD -DDDDDDDDD- --E-----E-- 
----FFF---- --EEAAAEE-- -AABBBBBAA- -AABBBBBAA- -CCCCCCCCC- -AACCCCCCC- -CCCCCCCCC- -CCCCCCCCC- -AAAAABBAH- -AAAAAAAAH- -AAAAAAAAH- -AAAAAAAAA- -AAAAAAAAA- -AAAAAAAAH- -AAAAAAAAA- -DAAAAAAAG- -CAAAAAAAA- -CAAAAAAAG- -CAAAAAAAA- -DAAAAAAAG- -AAAAAAAAA- -AAAAABBAA- -AAAAABBAA- -AABBBBBAA- -AABBBBBAA- -DD-----DD- --DDDDDDD-- ---E---E--- 
----------- ---EEEEE--- --AABBBAA-- --AABBBAA-- --CCCCCCC-- --ACCCCCC-- --CCCCCCC-- --CCCCCCC-- --AAAABAA-- --AAAAAAA-- --AAAAAAA-- --AAAAAAA-- --AAAAAAA-- --AAAAAAA-- --AAAAAAA-- --AAAAAAA-- --DAAAAAA-- --DAAAAAA-- --DAAAAAA-- --AAAAAAA-- --AAAAAAA-- --AAAABAA-- --AAAABAA-- --AABBBAA-- --AABBBAA-- --DD---DD-- ---DDDDD--- ----EEE---- 
----------- ----------- ----AAA---- ---AAAAA--- ---CCCCC--- ---CCCCC--- ---CCCCC--- ---CCCCC--- ---AAAAA--- ---AAAAA--- ---AAAAA--- ---AAAAA--- ---AAAAA--- ---AAAAA--- ---AAAAA--- ---AAAAA--- ---AAAAA--- ---AAAAA--- ---AAAAA--- ---AAAAA--- ---AAAAA--- ---AAAAA--- ---AAAAA--- ---AAAAA--- ---AAAAA--- ---DDDDD--- ----DDD---- ----------- 
