model
size = 11 28 11, scale = 0.05, origin = -y
material 
  colors = A:#FFECB1 B:#CAAD5F C:#E83015 D:#AAA E:#BBB F:#EEE
voxels
----------- ----------- ----CCC---- ---CCAAA--- ---CCAAA--- ---CCAAA--- ---CCAAA--- ---CCAAA--- ---CCAAA--- ---CCAAA--- ---CCAAA--- ---CCAAA--- ---CCAAA--- ---CCAAA--- ---CCAAA--- ---CCAAA--- ---CCAAA--- ---CCAAA--- ---CCAAA--- ---CCAAA--- ---CCAAA--- ---CCAAA--- ---CCAAA--- ---CCAAA--- ---CCAAA--- ---CCCCC--- ----AAA---- ----------- 
----------- ---DDDDD--- --CCBBBCC-- --AABBBAA-- --AABBBAA-- --AABBBAA-- --AABBBAC-- --AABBAAA-- --CABBAAA-- --CAAAAAC-- --CAAAAAA-- --CAAAAAA-- --CAAAAAA-- --CAAAAAA-- --CAAAAAA-- --CAAAAAA-- --CAAAAAA-- --CAAAAAA-- --AAAAAAC-- --AAAAAAC-- --AAAAAAA-- --AABBAAC-- --AABBAAC-- --AABBBAA-- --CABBBAA-- --CA---AC-- ---AAAAA--- ----DDD---- 
----EEE---- --DDAAADD-- -CABBBBBAC- -AABBBBBAA- -AABBBBBAA- -AABBBBBAC- -AABBBBBAC- -AABBBAAAC- -AABBBAAAA- -AAAAAAAAC- -AAAAAAAAA- -AAAAAAAAA- -AAAAAAAAA- -CAAAAAAAC- -CAAAAAAAC- -CAAAAAAAC- -CAAAAAAAA- -CAAAAAAAC- -CAAAAAAAC- -AAAAAAAAC- -AAAAAAAAC- -AABBBAAAC- -AABBBAAAC- -AABBBBBFA- -CABBBBBAA- -CA-----AC- --AAEEEAA-- ---D---D--- 
---E---E--- -DDADDDADD- -CBBBBBBBC- AABBBBBBBAA ABBBBBBBBBA ABBBBBBBBBC CAABBBBBAAA CAABBBAAAAA AAABBBAAAAA AAABBBAAAAC AAABBBAAAAC AAABBBAAAAA AAABBBAAAAC AAABBBAAAAC AAABBBAAAAC AAABBBAAAAC AAABBBAAAAC AAABBBAAAAC CAABBBAAAAA CAABBBAAAAC CAABBBAAAAA CAABBBAAAAC CAABBBAAAAC CAABBBBBAAA CAABBBBBAAA CA-------AC -AAEEEEEAA- --D-----D-- 
--E-----E-- -DADDDDDAD- CABBBBBBBAC AABBBBBBBAA ABBBBBBBBBC ABBBBBBBBBC AAABBBBBAAC CAABBBBBAAC CAABBBBBAAC CAABBBBBAAC CAABBBBBAAC CAABBBBBAAC AAABBBBBAAC AAABBBBBAAC AAABBBBBAAA AAABBBBBAAC AAABBBBBAAC AAABBBBBAAC AAABBBBBAAC AAABBBBBAAC AAABBBAAAAA AAABBBAAAAA CAABBBAAAAA CAABBBBBAAA CAABBBBBAAA CA-------AC AAE--EEEEAA -D---EEEEEE 
--E-----E-- -DADDDDDAD- CABBBBBBBAC AABBBBBBBAA ABBBBBBBBBA CBBBBBBBBBC CAABBBBBAAC AAABBBBBAAA CAABBBBBAAC CAABBBBBAAC AAABBBBBAAA CAABBBBBAAC CAABBBBBAAC CAABBBBBAAC CAABBBBBAAC CAABBBBBAAC AAABBBBBAAA AAABBBBBAAA AAABBBBBAAA AAABBBBBAAA AAABBBBBAAA AAABBBBBAAA AAABBBBBAAA AAABBBBBAAA AAABBBBBAAA CA-------AC AAE--EEEEEA -D---E-E--E 
--E-----E-- -DADDDDDAD- CABBBBBBBAC AABBBBBBBAA CBBBBBBBBBA CBBBBBBBBBA CAABBBBBAAA CAABBBBBAAC CAABBBBBAAC CAABBBBBAAC CAABBBBBAAC CAABBBBBAAC CAABBBBBAAA CAABBBBBAAA AAABBBBBAAA CAABBBBBAAA CAABBBBBAAA CAABBBBBAAA CAABBBBBAAA CAABBBBBAAA AAAAAABBAAA AAAAAABBAAA AAAAAABBAAC AAABBBBBAAC AAABBBBBAAC CA-------AC AAE--EEEEAA -D---EEEEEE 
---E---E--- -DDADDDADD- -CBBBBBBBC- AABBBBBBBAA ABBBBBBBBBA CBBBBBBBBBA AAABBBBBAAC AAAAAABBAAC AAAAAABBAAA CAAAAABBAAA CAAAAABBAAA AAAAAABBAAA CAAAAABBAAA CAAAAABBAAA CAAAAABBAAA CAAAAABBAAA CAAAAABBAAA CAAAAABBAAA AAAAAABBAAC CAAAAABBAAC AAAAAABBAAC CAAAAABBAAC CAAAAABBAAC AAABBBBBAAC AAABBBBBAAC CA-------AC -AAEEEEEAA- --D-----D-- 
----EEE---- --DDAAADD-- -CABBBBBAC- -AABBBBBAA- -AABBBBBAA- -CABBBBBAA- -CABBBBBAA- -CAAAABBAA- -AAAAABBAA- -CAAAAAAAA- -AAAAAAAAA- -AAAAAAAAA- -AAAAAAAAA- -CAAAAAAAC- -CAAAAAAAC- -CAAAAAAAC- -AAAAAAAAC- -CAAAAAAAC- -CAAAAAAAC- -CAAAAAAAA- -CAAAAAAAA- -CAAAABBAA- -CAAAABBAA- -AFBBBBBAA- -AABBBBBAC- -CA-----AC- --AAEEEAA-- ---D---D--- 
----------- ---DDDDD--- --CCBBBCC-- --AABBBAA-- --AABBBAA-- --AABBBAA-- --CABBBAA-- --AAAABAA-- --AAAABAC-- --CAAAAAC-- --AAAAAAC-- --AAAAAAC-- --AAAAAAC-- --AAAAAAC-- --AAAAAAC-- --AAAAAAC-- --AAAAAAC-- --AAAAAAC-- --CAAAAAA-- --CAAAAAA-- --AAAAAAA-- --CAAABAA-- --CAAABAA-- --AABBBAA-- --AABBBAC-- --CA---AC-- ---AAAAA--- ----DDD---- 
----------- ----------- ----CCC---- ---AAACC--- ---AAACC--- ---AAACC--- ---AAACC--- ---AAACC--- ---AAACC--- ---AAACC--- ---AAACC--- ---AAACC--- ---AAACC--- ---AAACC--- ---AAACC--- ---AAACC--- ---AAACC--- ---AAACC--- ---AAACC--- ---AAACC--- ---AAACC--- ---AAACC--- ---AAACC--- ---AAACC--- ---AAACC--- ---CCCCC--- ----AAA---- ----------- 
