model
size = 20 31 10, scale = 0.05, origin = -y
material 
  colors = A:#B00 B:#EEE C:#700 D:#CC0 E:#222 F:#BBB G:#E00
voxels
-------------------- -------------------- -------------------- -------------------- -------------------- -------------------- -------------------- -------------------- -------------------- -------------------- -------------------- -------------------- -------------------- -------------------- ----------AA-------- ----------AA-------- -------------------- -------------------- -------------------- -------------------- -------------------- -------------------- -------------------- -------------------- -------------------- -------------------- -------------------- -------------------- -------------------- -------------------- -------------------- 
-------------------- -------------------- -------------------- -------------------- -------------------- -------------------- -------------------- -------------------- -------------------- -------------------- -------------------- ---------AAA-------- --------AAAAA------- -------AAAAAA------- -------AAAAAA------- -------AAAAAA------- --------AAAAA------- -------------------- -------------------- -------------------- -------------------- -------------------- -------------------- -------------------- -------------------- -------------------- -------------------- -------------------- -------------------- -------------------- -------------------- 
-------------------- -------------------- -------------------- -------------------- -------------------- -------------------- -------------------- -------------------- -------------------- -------------------- ---------AAAA------- -------AAAAAA------- -------AAAAAAA------ ------AAAAAAAA------ ------AAAAAAAAA----- ------AAAAAAAA------ ------AAAAAAAA------ --------AAAAA------- ----------A--------- -------------------- -------------------- -------------------- -------------------- -------------------- -------------------- -------------------- -------------------- -------------------- -------------------- -------------------- -------------------- 
-------------------- -------------------- -------------------- -------------------- -------------------- -------------------- -------------------- -------------------- -------------------- ---------AAA-------- -------AAAAAA------- ------AAAAAAAA------ ------AAAAAAAAA----- -----AAAAAAAAAA----- -----AAAAAAAAAA----- -----AAAAAAAAAA----- ------AAAAAAAAA----- -------AAAAAAA------ --------AAAAA------- -------------------- -------------------- -------------------- -------------------- -------------------- -------------------- ----E----------E---- ---EEE--------EEE--- ----E----------E---- -------------------- -------------------- -------------------- 
-------------------- -------------------- -------------------- -------------------- -------------------- -------------------- -------------------- -------------------- -------------------- --------AAAAA------- -------AAAAAAA------ ------AAAAAAAAA----- -----AAAAAAAAAA----- -----AAAAAAAAAAA---- -----AAAAAAAAAAA---- -----AAAAAAAAAAA---- -----AAAAAAAAAAA---- ------AAAAAAAA------ -------AAAAAA------- ---------AAAA------- -------------------- -------------------- -------------------- --DDDDD------DDDDD-- -DDDEDDD----DDDEDDD- -DDEEEDD----DDEEEDD- -DEEEEED----DEEEEED- -DDEEEDD----DDEEEDD- -DDDEDDD----DDDEDDD- --DDDDD------DDDDD-- -------------------- 
-------------------- -------------------- -------------------- -------------------- -------------------- -------------------- -------------------- -------------------- -------------------- -------AAAAAA------- ------AAAAAAAA------ -----AAAAAAAAAA----- -----AAAAAAAAAAA---- -----AAAAAAAAAAA---- -----AAAAAAAAAAA---- -----AAAAAAAAAAA---- -----AAAAAAAAAAA---- ------AAAAAAAAA----- -------AAAAAAA------ --------AAAAA------- -------------------- -------------------- --BBBBB------BBBBB-- -BBBBBBB----BBBBBBB- BBBBBBBBB--BBBBBBBBB BBBBBBBBB--BBBBBBBBB BBBBBBBBB--BBBBBBBBB BBBBBBBBB--BBBBBBBBB BBBBBBBBB--BBBBBBBBB -BBBBBBB----BBBBBBB- --BBBBB------BBBBB-- 
------CCCCCCCCC----- -----C---------C---- ----CC---------CC--- -----C---------C---- ------CCCCCCCCC----- -------------------- -------------------- -------------------- ----------AA-------- -------AAAAAA------- ------AAAAAAAAA----- -----AAAAAAAAAA----- -----AAAAAAAAAAA---- -----AAAAAAAAAAA---- ----AAAAAAAAAAAA---- ----AAAAAAAAAAAA---- -----AAAAAAAAAAA---- ------AAAAAAAAA----- ------AAAAAAAA------ --------AAAAA------- -------------------- -------------------- --BBBBB------BBBBB-- -BBBBBBB----BBBBBBB- BBBBBBBBB--BBBBBBBBB BBBBBBBBB--BBBBBBBBB BBBBBBBBB--BBBBBBBBB BBBBBBBBB--BBBBBBBBB BBBBBBBBB--BBBBBBBBB -BBBBBBB----BBBBBBB- --BBBBB------BBBBB-- 
-----CCCCCCCCCCC---- ----C-FBFBFBFBF-C--- ----C---GGGGG---C--- ----C-BFBFBFBFB-C--- -----CCCCCCCCCCC---- -------------------- -------------------- -------------------- ----------AA-------- -------AAAAAA------- ------AAAAAAAA------ -----AAAAAAAAAA----- -----AAAAAAAAAAA---- -----AAAAAAAAAAA---- ----AAAAAAAAAAAA---- ----AAAAAAAAAAAA---- -----AAAAAAAAAAA---- ------AAAAAAAAA----- -------AAAAAAA------ --------AAAAA------- -------------------- -------------------- --BBBBB------BBBBB-- -BBBBBBB----BBBBBBB- BBBBBBBBB--BBBBBBBBB BBBBBBBBB--BBBBBBBBB BBBBBBBBB--BBBBBBBBB BBBBBBBBB--BBBBBBBBB BBBBBBBBB--BBBBBBBBB -BBBBBBB----BBBBBBB- --BBBBB------BBBBB-- 
-----CCCCCCCCCCC---- ----CCFBFBFBFBFCC--- ----CC-GGGGGGG-CC--- ----CCBFBFBFBFBCC--- -----CCCCCCCCCCC---- -------------------- -------------------- -------------------- -------------------- --------AAAAA------- ------AAAAAAAA------ ------AAAAAAAAA----- -----AAAAAAAAAAA---- -----AAAAAAAAAAA---- -----AAAAAAAAAAA---- -----AAAAAAAAAAA---- -----AAAAAAAAAAA---- ------AAAAAAAAA----- -------AAAAAAA------ --------AAAAA------- -------------------- -------------------- ---BBB--------BBB--- -BBBBBBB----BBBBBBB- BBBBBBBB---BBBBBBBB- BBBBBBBBB--BBBBBBBBB BBBBBBBBB--BBBBBBBBB BBBBBBBBB--BBBBBBBBB -BBBBBBB---BBBBBBBB- -BBBBBBB----BBBBBBB- ---BBB--------BBB--- 
----CCCCCCCCCCCCC--- ----CCFBFBFBFBFCC--- ----CCGGGGGGGGGCC--- ----CCBFBFBFBFBCC--- ----CCCCCCCCCCCCC--- -------------------- -------------------- -------------------- -------------------- -------------------- --------AAAAA------- -------AAAAAAA------ ------AAAAAAAA------ ------AAAAAAAAA----- ------AAAAAAAAA----- ------AAAAAAAAA----- ------AAAAAAAAA----- -------AAAAAA------- ---------AAAA------- -------------------- -------------------- -------------------- ----B----------B---- --BBBBB------BBBBB-- -BBBBBBB----BBBBBBB- BBBBBBBB----BBBBBBB- BBBBBBBBB--BBBBBBBBB -BBBBBBB----BBBBBBB- -BBBBBBB----BBBBBBB- --BBBBB------BBBBB-- ----B----------B---- 
