model
size = 32 18 12, scale = 0.05, origin = -y
material 
  colors = A:#FFF B:#F6F62D C:#EEF42D D:#FFF82D E:#0086A1 F:#E6F32D G:#70FF23 H:#DDF12D I:#D5F02D J:#C5ED2E K:#CDEE2D L:#ACF22A M:#A0F429 N:#B8EF2C O:#88F926 P:#94F727 Q:#7CFC24
voxels
8-2(20A12-)20D13-19B15-17C17-15F19-13H20-4IA7I21-4KA6K22-4JA5J23-2NANA4N24-2LALA3L24-3MAMA2M25-3PAPA26-4OAO27-4QA2(27-5G)9-2(26A6-)26D6-26B9-23C11-21F13-19H16-16I17-15K18-14J19-13N20-12L21-10M22-3P7A23-8OP23-2Q7A2(24-8G)5-12AG6AG9A3-29A3-29D4-28B5-27C9-4F16-3F11-3H15-3H14-I14-3I15-A13-KEK16-J12-3J17-A11-3N18-2L9-2L20-A3M6-2M20-2PMP6-2A21-APO6-OP21-3Q6-2A22-AG6-2G22-2G6-2G3-13A8G10A-31A-31D2-30B3-12C2A3C2A10C6-6F18-2F9-4H17-2H12-2I15-IEI14-A14-2K16-J13-2J17-A12-2N18-2L10-2L19-A2M8-ML19-3P8-2A20-AO8-OP20-2Q8-2A21-A8-2G21-G8-2G-14A8G42AD27E4D-31B3-11CA4CACA10C5-7F18-2F8-5H17-2H11-3I16-2I14-A15-2K15-J14-2J16-A13-N18-2L11-L19-A2M9-M19-3P9-A20-AO9-O20-2Q9-A21-A9-QA20-G9-22AG43AD27E4D-31B3-11CA3CA2CA10C5-7F18-2F8-5H17-2H11-3I16-2I14-A15-2K15-J14-2J16-A13-2N17-2L11-L19-A2M9-M19-3P9-A20-AO9-O20-2Q9-A21-A9-QA20-G9-16AG6AG42AD20EA6E4D-31B3-11CA2CA3CA10C5-7F18-2F8-5H17-2H11-3I16-2I14-A15-2K15-J14-2J16-A13-N18-2L11-L19-A2M9-M19-3P9-A20-AO9-O20-2Q9-A21-A9-QA20-G9-16A8G42AD27E4D-31B3-12C2A4CA10C5-7F17-3F9-4H16-3H12-2I15-IEI14-A14-2K16-J13-2J17-A12-2N18-2L10-2L19-A2M8-ML19-3P8-2A20-AO8-2O20-2Q8-2A21-A8-2G21-G8-2G-14A7G10A-31A-D27E3D2-30B4-28C8-5F16-3F12-2H15-3H14-I14-3I15-A13-3K16-J12-3J17-A11-3N18-2L9-2L20-A3M6-2M20-4P6-2A21-AEO6-2O21-QOQ6-2A22-AG6-2G22-2G6-2G3-13AG15A3-29A3-12D13E4D5-27B6-26C11-21F14-18H16-16I17-15K18-14J19-12N21-11L22-M2E6ML22-3P7A23-8OP23-2Q7A2(24-8G)2(6-26A)6-26D7-25B9-23C16-16F18-14H19-4IAI4E3I20-4KAK2E3K22-4JA4J24-2NANA3N25-2LALA2L25-3M2(AM)26-3PAPA26-4OAO27-4QA2(27-5G)2(11-7A8-6A)11-7D8-6D12-5B9-6B26-6C26-6F27-4H28-4I29-2K295-
