model
size = 32 18 12, scale = 0.05, origin = -y
material 
  colors = A:#FFF B:#3F1D93 C:#501B9C D:#2E1F8A E:#0086A1 F:#6119A6 G:#7118AF H:#8216B9 I:#B80EAB J:#D4097F K:#9314C2 L:#A413CC M:#AA11C1 N:#B110B6 O:#C60B95 P:#BF0DA0 Q:#CD0A8A
voxels
8-2(20A12-)20D13-19B15-17C17-15F19-13G20-4HA7H21-4KA6K22-4LA5L23-2MAMA4M24-2NANA3N24-3IAIA2I25-3PAPA26-4OAO27-4QA2(27-5J)9-2(26A6-)26D6-26B9-23C11-21F13-19G16-16H17-15K18-14L19-13M20-12N21-10I22-3P7A23-8OP23-QO7A24-Q7J24-8J5-12AD6AD9A3-29A3-29D4-28B5-27C9-4F16-3F11-3G15-3G14-H14-3H15-A13-KEK16-L12-3L17-A11-3M18-2N9-2N20-A3I6-2I20-2PIP6-2A21-APO6-OP21-3Q6-2A22-AJ6-2J22-2J6-2J3-13A8D10A-31A-31D2-30B3-12C2A3C2A10C6-6F18-2F9-4G17-2G12-2H15-HEH14-A14-2K16-L13-2L17-A12-2M18-2I10-2N19-A2I8-2I19-3P8-2A20-AO8-OP20-2Q8-2A21-A8-2J21-J8-2J-14A8D42AD27E4D-31B3-11CA4CACA10C5-7F18-2F8-5G17-2G11-3H16-2H14-A15-2K15-L14-2L16-A13-M18-2I11-N19-A2I9-I19-3P9-A20-AO9-O20-2Q9-A21-A9-JA20-J9-22AD43AD27E4D-31B3-11CA3CA2CA10C5-7F18-2F8-5G17-2G11-3H16-2H14-A15-2K15-L14-2L16-A13-2M17-2I11-N19-A2I9-I19-3P9-A20-AO9-O20-2Q9-A21-A9-JA20-J9-16AD6AD42AD20EA6E4D-31B3-11CA2CA3CA10C5-7F18-2F8-5G17-2G11-3H16-2H14-A15-2K15-L14-2L16-A13-M18-2I11-N19-A2I9-I19-3P9-A20-AO9-O20-2Q9-A21-A9-JA20-J9-16A8D42AD27E4D-31B3-12C2A4CA10C5-7F17-3F9-4G16-3G12-2H15-HEH14-A14-2K16-L13-2L17-A12-2M18-2I10-IN19-A2I8-2I19-3P8-2A20-AO8-2O20-2Q8-2A21-A8-2J21-J8-2J-14A7D10A-31A-D27E3D2-30B4-28C8-5F16-3F12-2G15-3G14-H14-3H15-A13-3K16-L12-3L17-A11-3M18-2I9-2N20-A3I6-IN20-2PIP6-2A21-AEO6-OP21-QOQ6-2A22-AJ6-2J22-2J6-2J3-13AD15A3-29A3-12D13E4D5-27B6-26C11-21F14-18G16-16H17-15K18-L4I9L19-4IN7M21-3I8N22-2IE6IN22-3P7A23-8OP23-2Q7A2(24-8J)2(6-26A)6-26D7-25B9-23C16-16F18-14G19-4HAH4E3H20-4KAK2E3K22-4LA4L24-2MAMA3M25-2NANA2N25-3I2(AI)26-3PAPA26-4OAO27-4QA2(27-5J)2(11-7A8-6A)11-7D8-6D12-5B9-6B26-6C26-6F27-4G28-4H29-2K295-
