model
size = 32 18 12, scale = 0.05, origin = -y
material 
  colors = A:#303030 B:#D7FD02 C:#FDFDFD D:#FD0202
voxels
8-20B12-20C12-20A13-19A15-17A17-15A19-13A20-4AB7A21-4AB6A22-4AB5A23-2ABAB4A24-2ABAB3A24-3ABAB2A25-3ABAB26-4ABA27-4AB2(27-5A)9-26B6-26C2(6-26A)9-23A11-21A13-19A16-16A17-15A18-14A19-13A20-12A21-10A22-3A7B23-9A23-2A7B2(24-8A)5-11BA6BA10B3-26C2BC3-29A4-28A5-27A9-4A16-3A11-3A15-3A14-A14-3A15-C13-3A16-A12-3A17-C11-3A18-2A9-2A20-C3A6-2A20-4A6-2B21-C2A6-2A21-3A6-2B22-CA6-2A22-2A6-2A3-12B8A11B-27C3BC-31A2-30A3-12A2D3A2D10A6-6A18-2A9-4A17-2A12-2A15-3A14-C14-2A16-A13-2A17-C12-2A18-2A10-2A19-C2A8-2A19-3A8-2B20-CA8-2A20-2A8-2B21-C8-2A21-A8-2A-13B8A11BC30BC32A-31A3-11AD4ADAD10A5-7A18-2A8-5A17-2A11-3A16-2A14-C15-2A15-A14-2A16-C13-A18-2A11-A19-C2A9-A19-3A9-B20-CA9-A20-2A9-B21-C9-AD20-A9-2D19BA12BC30BC32A-31A3-11AD3AD2AD10A5-7A18-2A8-5A17-2A11-3A16-2A14-C15-2A15-A14-2A16-C13-2A17-2A11-A19-C2A9-A19-3A9-B20-CA9-A20-2A9-B21-C9-AD20-A9-2D13BA6BA11BC30BC21AB10A-31A3-11AD2AD3AD10A5-7A18-2A8-5A17-2A11-3A16-2A14-C15-2A15-A14-2A16-C13-A18-2A11-A19-C2A9-A19-3A9-B20-CA9-A20-2A9-B21-C9-AD20-A9-2D13B8A11BC30BC32A-31A3-12A2D4AD10A5-7A17-3A9-4A16-3A12-2A15-3A14-C14-2A16-A13-2A17-C12-2A18-2A10-2A19-C2A8-2A19-3A8-2B20-CA8-2A20-2A8-2B21-C8-2A21-A8-2A-13B7A11B-C27B3C-31A2-30A4-28A8-5A16-3A12-2A15-3A14-A14-3A15-C13-3A16-A12-3A17-C11-3A18-2A9-2A20-C3A6-2A20-4A6-2B21-C2A6-2A21-ABA6-2B22-CA6-2A22-2A6-2A3-12BA16B3-12C15B2C3-29A5-27A6-26A11-21A14-18A16-16A17-15A18-14A19-12A21-11A22-10A22-3A7B23-9A23-2A7B2(24-8A)6-26B6-26C6-26A7-25A9-23A16-16A18-14A19-4AB8A20-4AB6A22-4AB4A24-2ABAB3A25-2ABAB2A25-3A2(BA)26-3ABAB26-4ABA27-4AB2(27-5A)11-7B8-6B11-7C8-6C11-7A8-6A12-5A9-2(6A26-)6A27-4A28-4A29-2A295-
