model
size = 32 18 12, scale = 0.05, origin = -y
material 
  colors = A:#000 B:#0F0F0F C:#323232 D:#646464 E:#0E0E0E F:#151515 G:#232323 H:#1C1C1C I:#2A2A2A J:#070707
voxels
8-2(20B12-)20A13-19A15-17A17-15A19-13A20-4AJ7A21-4AE6A22-4AF5A23-2AEAH4A24-2AFAG3A24-3AHAI2A25-3AGAC26-4AIA27-4AC2(27-5A)9-2(26B6-)26A6-26A9-23A11-21A13-19A16-16A17-15A18-14A19-13A20-12A21-10A22-3AEFHGI2C23-9A23-2AEFHGI2C2(24-8A)5-11BD6BD10B3-26B2CB3-29A4-28A5-27A9-4A16-3A11-3A15-3A14-A14-3A15-A13-3A16-A12-3A17-A11-3A18-2A9-2(2A20-4A6-)2C21-3A6-2A21-3A6-2C2(22-2A6-2A)3-12B8D11B-27B3CB-31A2-30A3-12A2C3A2C10A6-6A18-2A9-4A17-2A12-2A15-3A14-A14-2A16-A13-2A17-A12-2A18-2A10-2(2A19-3A8-)2C20-2A8-2A20-2A8-2C2(21-A8-2A)-13B8D12B30CB32A-31A3-11AC4ACAC10A5-7A18-2A8-5A17-2A11-3A16-2A14-A15-2A15-A14-2A16-A13-A18-2A11-2(A19-3A9-)C20-2A9-A20-2A9-C21-A9-2A20-A9-2A19BD13B30CB32A-31A3-11AC3AC2AC10A5-7A18-2A8-5A17-2A11-3A16-2A14-A15-2A15-A14-2A16-A13-2A17-2A11-2(A19-3A9-)C20-2A9-A20-2A9-C21-A9-2A20-A9-2A13BD6BD12B30CB21AC10A-31A3-11AC2AC3AC10A5-7A18-2A8-5A17-2A11-3A16-2A14-A15-2A15-A14-2A16-A13-A18-2A11-2(A19-3A9-)C20-2A9-A20-2A9-C21-A9-2A20-A9-2A13B8D12B30CB32A-31A3-12A2C4AC10A5-7A17-3A9-4A16-3A12-2A15-3A14-A14-2A16-A13-2A17-A12-2A18-2A10-2(2A19-3A8-)2C20-2A8-2A20-2A8-2C2(21-A8-2A)-13B7D11B-B27C3B-31A2-30A4-28A8-5A16-3A12-2A15-3A14-A14-3A15-A13-3A16-A12-3A17-A11-3A18-2A9-2(2A20-4A6-)2C21-3A6-2A21-ACA6-2C2(22-2A6-2A)3-12BD16B3-12B15C2B3-29A5-27A6-26A11-21A14-18A16-16A17-15A18-14A19-12A21-11A22-10A22-3AEFHGI2C23-9A23-2AEFHGI2C2(24-8A)2(6-26B)6-26A7-25A9-23A16-16A18-14A19-4AJ8A20-4AE6A22-4AF4A24-2AEAH3A25-2AFAG2A25-3AHAIA26-3AGAC26-4AIA27-4AC2(27-5A)2(11-7B8-6B)11-7A8-6A12-5A9-2(6A26-)6A27-4A28-4A29-2A295-
