model
size = 25 19 17, scale = 0.05, origin = -y
material 
  colors = A:#FEDFC3 B:#000 C:#562E17 D:#84492C E:#C2C3C7 F:#9AD0FF G:#EDE8FF H:#9AA9BC I:#94453E J:#CAD2E9 K:#FFAA57
voxels
------------------------- ------------------------- ------------------------- ------------------------- ------------------------- ------------------------- ------------------------- ------------------------- ------------------------- ------------------------- -----------B------------- -----------B------------- -----------AAA----------- -----------B-K----------- -----------B------------- ------------------------- ------------------------- ------------------------- ------------------------- 
------------------------- ------------------------- ------------------------- ------------------------- ------------------------- ------------------------- ------------------------- ------------------------- ------------------------- ------------------------- ----------AA------------- ----------AA------------- ----------AA-A----------- ----------AA------------- -----------B------------- -----------BB------------ ------------------------- ------------------------- ------------------------- 
------------------------- ------------------------- ------------------------- ------------------------- -------AAAAAA------------ ------AAAAAAA------------ ------AAAAAAAAAAAAA------ ------AAAAAAAAAAAAA------ ------AAAAAAAAAAAAA------ ------AAAAAAAAAAAAA------ ------AAAAAAAAAAAAAAAA--- ------AAAAAAAAAAA-------- ------AAAAAAAAAAA-------- -------AAAAAAAAAA-------- ---------AAAAAAAA-------- -----------BB------------ ------------------------- ------------------------- ------------------------- 
------------------------- ------------------------- ------------------------- ------------------------- ------AAAAAAA------------ -----AAAAAAAAAAAAA------- -----AAAAAAAAAAAAAAA----- -----AAAAAA-AAAAAAAA----- -----AAAAAA-AAAAAAAA----- -----AAAAAAAAAAAAAAAAA--- -----AAAAAAAAAAAAAAAAA--- -----AAAAAAA-AAAAAAAAA--- -----AAAAAAAAAAAA-------- ------AAAAAAAAAAA-------- ---------AAAAAAAA-------- -----------BFFFAA-------- ------------------------- ------------------------- ------------------------- 
------------------------- ------------------------- ------------------------- --------AAAAAAAAA-------- -----AAAAAAAAAAAA-------- -----AAAAAAAAAAAAA------- -----AAAADDAAAAAAAAA----- -----A---AAAAAAAAAAA----- -----A----AAAAAAAAAAAAA-- -----A----AAAAAAAAAACAA-- -----AAAAAAAAAAAAAAACAA-- -----AAAAAAA-AAAAAAADAA-- -----AAAAAAAAAAAAAAAAA--- -----AAAAAAAAAAAAAAAAA--- -------AAAAAGBAAAAAAAA--- -----------BG-HAA-------- ------------------------- ------------------------- ------------------------- 
------------------------- ------------------------- --------AAAEEEEEAAAA----- ------AAAAAAAAAAAAAAA---- -----AAAAAAAAAAAAAAAA---- ----AAAAAAAAAAAAAAAAA---- ----AAAAADDAAAAAAAAAA---- ----AA---AAAAAAAAAAAAAAA- ----AA---AAAAAAAAAAACAAA- ----AA----AAAAAAAAAACAAA- ----AAAAAAAAAAAAAAAACAAA- ----AAAAAAAA-AAAAAAADAAA- -----AAAAAAAAAAAAAAADAAA- -----AAAAAAAAAAAAAAADAAA- ------AAAAAAJBAAAAAAAAA-- ----BB-----BG-H---------- --BB--------------------- ------------------------- ------------------------- 
------------------------- BB----------------------- BBBBBBBAAAAEAEAEAAAAAA--- BBBBBBBAAAAAAAAAAAAAAA--- BBBBAAAAAAAAAAAAAAAAAA--- BBAAAAAAAAAAAAAAAAAAAA--- --BBAAAAADDAAAAAAAAACA--- --BBBBBB-AAAAAAAAAAACAAA- --BBBBBB--AAAAAAAAAACAAAA --BBBBBB--AAAAAAAAAACAAAA --BBBAAAAAAAAAAAAAAACAAAA --BBAAAAAAAA-AAAAAAADAAAA --BBBBBAAAAAAAAAAAAADDDAA --BBBAAAAAAAAAAAAAAAIDDA- --BBBBAAAAAAAAAAAAAAAAAA- --BBBB-----BFFH---------- --BBB-------------------- --BBB-------------------- ------------------------- 
------------------------- BBBBBBBBBBB-------------- BBBBBBBAAAAAAAAAAEAEEA--- BBBBBBBAAAAAAAAAAAAAAA--- BBBBAAAAADDAAAAAAAAAAA--- BBAAAAADDDDAAAAAAAAAAA--- --BBAAAAAAAAAAAAAAAACA--- --BBBBBB-A-AAAAAAAA-CAAA- --BBBBBB--AAAAAAAAAACAAAA --BBBBBB--AAAAAAAAAACAAAA --BBBAAAAAAAAAAAAAAACAAAA --BBAAAAAAAA-AAAAAAADAAAA --BBBBAAAAAAAAAAAAAADDDAA --BBBAAAAAAAAAAAAAAAIDDAA --BBBBAAAAAAAAAAAAAAAAAA- --BB-BBB---BB-------B---- --BBBBBB----------------- --BBBBBB----------------- -----BBB----------------- 
------------------------- BBBBBBBBBBBB------------- BBBBBBBAAAAAAAAAEAEAEA--- BBBBBBBAAAAAAAAAAAAAAA--- BBBBAAAAAAAAAAAAAAAA-A--- BBAAAAAAAAAAAAAAAAAA-A--- --BBAAAAAAAAAAAAAAAACA--- --BBBBBBAA-AAAAAAAA-CCAA- --BBBBBB--AAAAAAAAAACCAAA --BBBBBB--AAAAAAAAAACCAAA --BBBAAAAAAAAAAAAAAACCAAA -BBBBAAAAAAAAAAAAAAADDAAA BBBBBBBB-AAAAAAAAAAADDAAA BBBBBAAAAAAAAAAAAAAAIDAAA BBBBBBAAAAAAAAAAAAAAAAAA- BBBB---BBB-BB--AAB--B-A-- BBBB--------------------- --BBBBBB----------------- -------B----------------- 
------------------------- BBBBBBBBBBBBBB----------- BBBBBBBAAAAAAAAAEEAEEA--- BBBBBBBAAAAAAAAAAAAAAA--- BBBBAAAAAAAAAAAAAAAA-A--- BBAAAAAAAAAAAAAAAAAA-A--- --BBAAAAAAAAAAAAAAAAAA--- --BBBBBB---AAAAAAAAACCAA- --BBBBBB--AAAAAAAAAACCAAA --BBBBBB--AAAAAAAAAACCAAA --BBBAAAAAAAAAAAAAAACCAAA --BBBAAAAAAAAAAAAAAADDAAA --BBBBBAAAAAAAAAAAAADDAAA --BBBAAAAAAAAAAAAAAADDAAA --BBBBAAAAAAAAAAAAAAAAAA- --BBBBB----BB-------B---- --BBB-------------------- --BBBBBB----------------- -------B----------------- 
-B----------------------- BBBBBBBBBBBB------------- BBBBBBBAAAAAAAAAAAAAAA--- BBBBBBBAAAAAAAAAAAAAAA--- BBBBAAAAAAAAAAAAAAAAAA--- BBAAAAAAAAAAAAAAAAAAAA--- -BBBAAAAAAAAAAAAAAAAAA--- -BBBBBBB---AAAAAAAA-CAAA- -BBBBBBB--AAAAAAAAA-CAAAA -BBBBBBB--AAAAAAAAA-CCAAA -BBBBAAAAAAAAAAAAAA-AAAAA -BBBBADDAAAAAAAAAAA-AAAAA -BBBBBADAAAAAAAAAAA-AAAAA -BBBBAAAAAAAAAAAAAA-AAAAA -BBBBBAAAAAAAAAAAAAAAAAA- -BBBBBB----BFFH---------- ------------------------- ------------------------- ------------------------- 
---BBBBBB---------------- --BBBBBBBBB-------------- --BBBBBAAAAAAEEEAEEEEE--- BBBBBBBAAAAAAAAAAAAAAA--- BBBBAAAAAAAAAAAAAAAAAA--- BBAAAAAAAAAAAAAAAAAAAA--- -BBBAAAAAAAAAAAAAAAAAA--- -BBBB------AAAAAAAA-AAAA- -BBBB-----AAAAAAAAAAAAAAA -BBBB----AAAAAAAAAAACCAAA -BBBBAAAAAAAAAAAAAAAAAAAA -BBBBAAAAAAAAAAAAAAAAAAAA -BBBBAAAAA--AAAAAAAAAAAAA -BBBBAAAAAAAAAAAAAAAAAAA- ------AAAAAAGBAAAAAAAAAA- -----------BG-H---------- ------------------------- ------------------------- ------------------------- 
---BBBBBB---------------- ---BBBBBB---------------- ---BBBBAAAAEAEAEAEAEAA--- -BBBBBBAAAAAAAAAAAAAAA--- -BBBAAAAAAAAAAAAAAAAAA--- -BBBAAAAAAAAAAAAAAAAAA--- -BBBAAAAAAAAAAAAAAAAAA--- -BBBB------AAAAAAAA-AAAA- -BBBB-AA--AAAAAAAAAAAAAA- -BBBB-AAAAAAAAAAAAAACCAA- -BBBAAAAAAAAAAAAAAAAAAAA- -BBBAAAAAAAAAAAAAAAAAAAA- -BBBBAAAAA--AAAAAAAAAAAA- -BBBBAAAAAAAAAAAAAAAAAAA- -------AAAAAJBAAAAAAAAA-- -----------BG-HAA-------- ------------------------- ------------------------- ------------------------- 
------------------------- ------------------------- -------AAAAEEEEEAEEE----- ------AAAAAAAAAAAAAAA---- ----AAAAAAAAAAAAAAAAA---- ------AAAAAAAAAAAAAAA---- ----AAAAAAAAA-CAAAAAA---- ----AAAA---AABCAAAAAA---- ----AAAAAAAAAAAAAAAAAAA-- ----AAAAAAAAAAAAAAAAAAA-- ----AAAAAAAAAAAAAAAAAAA-- ----AAAAAA--AAAAAAAAAAA-- -----AAAA---AAAAAAAAAAA-- -----AAAAAAAAAAAAAAAAAA-- ---------AAAAAAAAAAAAA--- -----------BFFFAA-------- ------------------------- ------------------------- ------------------------- 
------------------------- ------------------------- ------------------------- --------AAAAAAA---------- ------AAAAAAAAA---------- ------AAAAAAAAA---------- -----AAAAAAAAAAAAAAAA---- -----A-AAAAAAAAAAAAAA---- -----AAAAAAAAAAAAAAAA---- ----AAAAAAAAAAAAAAAAA---- ----AAAAAAAAAAAAAAAAA---- -----AAAAA--AAAAAAAAA---- -----AAAAA--AAAAAAAAAAA-- ------AAAAAAAAAAAAAAAA--- ---------AAAAAAAA-------- -----------BB------------ ------------------------- ------------------------- ------------------------- 
------------------------- ------------------------- ------------------------- ------------------------- -------AAA--------------- ------AAAA--------------- ------AAAA--------------- -----AAAAA--------------- -----AAAAAA-------------- ------AAAAA-------------- ------AAAAAA------------- ------AAAAAA------------- ------AAAAAA-A----------- -----------B------------- -----------B------------- -----------B------------- ------------------------- ------------------------- ------------------------- 
------------------------- ------------------------- ------------------------- ------------------------- ------------------------- ------------------------- ------------------------- ------------------------- ------------------------- ------------------------- -----------B------------- -----------B------------- -----------AAA----------- -----------B------------- -----------B------------- ------------------------- ------------------------- ------------------------- ------------------------- 
