model
size = 31 14 29, scale = 0.05, origin = -y
material 
  colors = A:#FF2AA8 B:#FF00A5 C:#0A0000 D:#FF7CD4 E:#FF3DAE F:#FF5BBE G:#FF53B9 H:#FF87DC I:#FF95ED J:#FF6CC4 K:#FF0FA5 L:#FF1FA5 M:#FF9DFF N:#FFA0FF O:#FFAEFF P:#FFB3FF Q:#FF00A3 R:#030303
voxels
---------CCCCC---CCCCC--------- -------------CC-CC------------- --------------C-C-------------- --------------CCC-------------- ---------------C--------------- ------------------------------- ------------------------------- ------------------------------- ------------------------------- ------------------------------- ------------------------------- ------------------------------- ------------------------------- ---------CCCCCCCCCCCCC--------- 
------CCCCBBBB---BBBBCCCC------ ------C--FGEACB-BCAEGF--C------ --------JFGEALB-BLAEGFJ-------- -------DJFGEALCBCLAEGFJD------- ------HDJFGEALKCKLAEGFJDH------ ------HDJFGEALKQKLAEGFJDH------ ------HDJFGEALKQKLAEGFJDH------ ------HDJFGEALKQKLAEGFJDH------ ------HDJFGEALKQKLAEGFJDH------ ------HDJFGEALKQKLAEGFJDH------ -------DJFGEEALKLAEEGFJD------- --------JFGEEALKLAEEGFJ-------- ---------JFGEALKLAEGFJ--------- -------CCBBBBBBBBBBBBBCC------- 
------CCBBBBBB---BBBBBBCC------ ----CCCJJFGEACB-BCAEGFJJCCC---- ------DJJFGEALB-BLAEGFJJD------ -----HDDJFGEALCBCLAEGFJDDH----- -----HHDJFGEALKCKLAEGFJDHH----- -----IHDJFGEALKQKLAEGFJDHI----- -----IHDJFGEALKQKLAEGFJDHI----- -----IHDJFGEALKQKLAEGFJDHI----- -----IHDJFGEALKQKLAEGFJDHI----- -----IHDJFGEALKQKLAEGFJDHI----- -----IHDJFGEEALKLAEEGFJDHI----- ------HDJFGEEALKLAEEGFJDH------ -------HDJFGEALKLAEGFJDH------- -----CCCBBBBBBBBBBBBBBBCCC----- 
------BBBBBBBB---BBBBBBBB------ ---CCBCDDAAAACB-BCAAAADDCBCC--- ---CIHHDAAAAAAB-BAAAAAADHHIC--- ----IHHDAAAAAAABAAAAAAADHHI---- ----IHHDAAAAAAAAAAAAAAADHHI---- ----MIHDAAAAAAAAAAAAAAADHIM---- ----MIHDAAAAAAAAAAAAAAADHIM---- ----MIHDAAAAAAAAAAAAAAADHIM---- ----MIHDAAAAAAAAAAAAAAADHIM---- ----MIHDAAAAAAAAAAAAAAADHIM---- ----MIHDAAAAAAAAAAAAAAADHIM---- -----IHDDAAAAAAAAAAAAADDHI----- ---C-IHHDDAAAAAAAAAAADDHHICC--- ----CCBBBBBBBBBBBBBBBBBBBCC---- 
------BBBBBBBB---BBBBBBBB------ ---BBBCAAAAAACB-BCAAAAAACBBB--- --CCAAAAAAAAAAB-BAAAAAAAAAACC-- ---MAAAAAAAAAAABAAAAAAAAAAAM--- ---MAAAAAAAAAAAAAAAAAAAAAAAM--- ---MAAAAAAAAAAAAAAAAAAAAAAAM--- ---NAAAAAAAAAAAAAAAAAAAAAAAN--- ---NAAAAAAAAAAAAAAAAAAAAAAAN--- ---NAAAAAAAAAAAAAAAAAAAAAAAN--- ---NAAAAAAAAAAAAAAAAAAAAAAAN--- ---NAAAAAAAAAAAAAAAAAAAAAAAN--- --CNMAAAAAAAAAAAAAAAAAAAAAMNC-- --CCMAAAAAAAAAAAAAAAAAAAAACCC-- ----BBBBBBBBBBBBBBBBBBBBBBB---- 
------BBBBBBBB---BBBBBBBB------ ---BBBCAAAAAACB-BCAAAAAACBBB--- -CCCAAAAAAAAAAB-BAAAAAAAAAACCC- -CNAAAAAAAAAAAABAAAAAAAAAAAANC- --NAAAAAAAAAAKAAAKAAAAAAAAAAN-- --OAAAAAAAAAAKQAQKAAAAAAAAAAO-- --OAAAAAAAAAAKKQKKAAAAAAAAAAO-- --OAAAAAAAAAAAKQKAAAAAAAAAAAO-- --OAAAAAAAAAAAKQKAAAAAAAAAAAO-- --OAAAAAAAAAAAKQKAAAAAAAAAAAO-- -COAAAAAAAAAAAAKAAAAAAAAAAAAOC- -CCAAAAAAAAAAAAKAAAAAAAAAAAACC- --BBCAAAAAAAAAAAAAAAAAAAAABBB-- ----BBBBBBBBBBBBBBBBBBBBBBB---- 
------BBBBBBBB---BBBBBBBB------ ---BBBCAAAAAABB-BCAAAAAACBBB--- -BBCAAAAAAAEAAB-BAAEAAAAAAACBB- CCAAAAAAAAAEAACBCAAEAAAAAAAAACC -PAAAAAAAAAEA-CCC-AEAAAAAAAAAP- -PAAAAAAAAAEA--C--AEAAAAAAAAAP- -PAAAAAAAAAGE-----EGAAAAAAAAAP- -PAAAAAAAAAGE-----EGAAAAAAAAAP- -PAAAAAAAAAGE-----EGAAAAAAAAAP- -PAAAAAAAAAGE-----EGAAAAAAAAAP- CCAAAAAAAAAGE-----EGAAAAAAAAACC -BCAAAAAAAAGE-----EGAAAAAAAABB- --BBCAAAAAAAACCCCCAAAAAAAABBB-- ----BBBBBBBBBBBBBBBBBBBBBBB---- 
------BBBBBBBB---BBBBBBBB------ ---BBBCAAAACCCB-BCCCAAAACBBB--- -BBCAAAADFG--CB-BC--GFDAAAACBB- CCAAAAAADFG---CBC---GFDAAAAAACC CCAAAAAADFG---CCC---GFDAAAAAACC CCAAAAAADFG----C----GFDAAAAAACC CCAAAAAAIDF---------FDIAAAAAACC CCAAAAAAIDF---------FDIAAAAAACC CCAAAAAAIDF---------FDIAAAAAACC CCAAAAAAIDF---------FDIAAAAAACC CCAAAAAAIDF---------FDIAAAAAACC -BCAAAAAIDF---------FDIAAAAACB- --BBCAAAAAACCCCCCCCCAAAAAABBB-- ----BBBBBBBCCCCCCCCCBBBBBBB---- 
------BBBBBBBB---BBBBBBBB------ ---BBBCACCCCCCB-BCCCCCCACBBB--- -BBCONMI-----CB-BC-----IMNOCBB- -BAAONMI------CBC------IMNOAAB- -BAAONMI------CCC------IMNOAAB- -BAAONMI-------C-------IMNOAAB- -BAAPONM---------------MNOPAAB- -BAAPONM---------------MNOPAAB- -BAAPONM---------------MNOPAAB- -BAAPONM---------------MNOPAAB- -BAAPONM---------------MNOPAAB- -BCAPONM---------------MNOPABB- --BBCAAACCCC-------CCCCAAAABB-- ----BBBBCCCC-------CCCCBBBB---- 
------CCCCCCCC---CCCCCCCC------ ---CCCCCCC---CC-CC---CCCCCCC--- -CCCC---------C-C---------CCCC- -BBR----------CCC----------RBB- --CC-----------C-----------CC-- -BBC-----------------------CBB- --CC-----------------------CC-- -BBC-----------------------CBB- --CC-----------------------CC-- -BBC-----------------------CBB- -CRC-----------------------CCC- -CCCC---------------------CRCC- --CCCCCCC-------------CCCCCCC-- ----CCCCC-------------CCCCC---- 
------------------------------- ------------------------------- ------------------------------- -B---------------------------B- -B---------------------------B- -B---------------------------B- -B---------------------------B- -B---------------------------B- -B---------------------------B- -B---------------------------B- ------------------------------- ------------------------------- ------------------------------- ------------------------------- 
------------------------------- ------------------------------- ------------------------------- -B---------------------------B- -C---------------------------C- -C---------------------------C- -C---------------------------C- -B---------------------------C- -C---------------------------C- -B---------------------------B- ------------------------------- ------------------------------- ------------------------------- ------------------------------- 
------------------------------- ------------------------------- ------------------------------- -B---------------------------B- -C---------------------------C- -B---------------------------B- -C---------------------------B- -B---------------------------B- -C---------------------------C- -B---------------------------B- ------------------------------- ------------------------------- ------------------------------- ------------------------------- 
------------------------------- ------------------------------- ------------------------------- -B---------------------------B- -C---------------------------C- -B---------------------------B- -C---------------------------B- -C---------------------------B- -C---------------------------C- -B---------------------------B- ------------------------------- ------------------------------- ------------------------------- ------------------------------- 
------------------------------- ------------------------------- ------------------------------- -B---------------------------B- -B---------------------------B- -B---------------------------B- -B---------------------------B- -B---------------------------B- -B---------------------------B- -B---------------------------B- ------------------------------- ------------------------------- ------------------------------- ------------------------------- 
------------------------------- ------------------------------- ------------------------------- -B---------------------------B- -C---------------------------C- -B---------------------------C- -B---------------------------C- -B---------------------------C- -B---------------------------C- -B---------------------------B- ------------------------------- ------------------------------- ------------------------------- ------------------------------- 
------------------------------- ------------------------------- ------------------------------- -B---------------------------B- -C---------------------------B- -B---------------------------B- -B---------------------------C- -B---------------------------B- -B---------------------------C- -B---------------------------B- ------------------------------- ------------------------------- ------------------------------- ------------------------------- 
------------------------------- ------------------------------- ------------------------------- -B---------------------------B- -C---------------------------C- -C---------------------------C- -C---------------------------B- -C---------------------------C- -C---------------------------C- -B---------------------------B- ------------------------------- ------------------------------- ------------------------------- ------------------------------- 
------------------------------- ------------------------------- ------------------------------- -B---------------------------B- -B---------------------------B- -B---------------------------B- -B---------------------------B- -B---------------------------B- -B---------------------------B- -B---------------------------B- ------------------------------- ------------------------------- ------------------------------- ------------------------------- 
------------------------------- ------------------------------- ------------------------------- -B---------------------------B- -C---------------------------B- -B---------------------------B- -C---------------------------C- -B---------------------------C- -C---------------------------C- -B---------------------------B- ------------------------------- ------------------------------- ------------------------------- ------------------------------- 
------------------------------- ------------------------------- ------------------------------- -BB-------------------------BB- -CC-------------------------CC- -BC-------------------------CC- -CC-------------------------CC- -BC-------------------------BB- -CC-------------------------BB- -BB-------------------------BB- ------------------------------- ------------------------------- ------------------------------- ------------------------------- 
------------------------------- ------------------------------- ------------------------------- --BB-----------------------BB-- --CB-----------------------BB-- --CB-----------------------BB-- --CB-----------------------BC-- --CB-----------------------CC-- --CB-----------------------CC-- --BB-----------------------BB-- ------------------------------- ------------------------------- ------------------------------- ------------------------------- 
------------------------------- ------------------------------- ------------------------------- ---BB---------------------BB--- ---BC---------------------BB--- ---BC---------------------BB--- ---BB---------------------BB--- ---BC---------------------BB--- ---BC---------------------BB--- ---BB---------------------BB--- ------------------------------- ------------------------------- ------------------------------- ------------------------------- 
------------------------------- ------------------------------- ------------------------------- ----BB-------------------BB---- ----CB-------------------CC---- ----CC-------------------CC---- ----BC-------------------CC---- ----CC-------------------CC---- ----CB-------------------CC---- ----BB-------------------BB---- ------------------------------- ------------------------------- ------------------------------- ------------------------------- 
------------------------------- ------------------------------- ------------------------------- -----BB-----------------BB----- -----BC-----------------BB----- -----CC-----------------BB----- -----CB-----------------CC----- -----CC-----------------CB----- -----BC-----------------CC----- -----BB-----------------BB----- ------------------------------- ------------------------------- ------------------------------- ------------------------------- 
------------------------------- ------------------------------- ------------------------------- ------BB---------------BB------ ------CB---------------BB------ ------CB---------------BB------ ------BB---------------BC------ ------CB---------------BC------ ------CB---------------BC------ ------BB---------------BB------ ------------------------------- ------------------------------- ------------------------------- ------------------------------- 
------------------------------- ------------------------------- ------------------------------- -------BB-------------BB------- -------BC-------------BB------- -------BC-------------BB------- -------BC-------------BB------- -------BC-------------BB------- -------BC-------------CB------- -------BB-------------BB------- ------------------------------- ------------------------------- ------------------------------- ------------------------------- 
------------------------------- ------------------------------- ------------------------------- --------BBB---------BBB-------- --------CCC---------BCB-------- --------CBC---------BCB-------- --------CBC---------BCB-------- --------CBC---------BCB-------- --------CCC---------CCC-------- --------BBB---------BBB-------- ------------------------------- ------------------------------- ------------------------------- ------------------------------- 
------------------------------- ------------------------------- ------------------------------- ----------BBBBBBBBBBB---------- ----------CBBCBBCCCBB---------- ----------CBCBCBCBCBB---------- ----------CBCBCBCBCBB---------- ----------CBCBCBCBCBB---------- ----------CBCBCBCCCBC---------- ----------BBBBBBBBBBB---------- ------------------------------- ------------------------------- ------------------------------- ------------------------------- 
