model
size = 31 15 20, scale = 0.05, origin = -y
material 
  colors = A:#111 B:#EEE C:#E00 D:#0FF
voxels
------AAAAAAAAAAAAAAAAAAAA----- ------AAAAAAAAAAAAAAAAAAAA----- ------------------------------- ------------------------------- ------------------------------- ------------------------------- ------------------------------- ------------------------------- ------------------------------- ------------------------------- ------------------------------- ------------------------------- ------------------------------- ------------------------------- ------------------------------- 
------AAAAAAAAAAAAAAAAAAAA----- ------A------------------A----- ------------------------------- ------------------------------- ------------------------------- ------------------------------- ------------------------------- ------------------------------- ------------------------------- ------------------------------- ------------------------------- ------------------------------- ------------------------------- ------------------------------- ------------------------------- 
------AAAAAAAAAAAAAAAAAAAA----- ------A------------------A----- ------------------------------- ------------------------------- ------------------------------- ------------------------------- ------------------------------- ------------------------------- ------------------------------- ------------------------------- ------------------------------- ------------------------------- ------------------------------- ------------------------------- ------------------------------- 
------AAAAAAAAAAAAAAAAAAAA----- ------A-AAAAAAAAAAAAAAAA-A----- --------AAAABAAAAABAAAAA------- --------AAAABAAAAABAAAAA------- --------AAABBBBBBBBBBAAA------- --------AAABBBBBBBBBBAAA------- --------AAAABBBBBBBBBBAA------- --------AAABBBBBBBBBBBAA------- --------AAABDAABBBBBBBAA------- --------AAACCCCBBBBBBAAA------- --------AAACCCCBBBBBBAAA------- --------AAAAAAACAAAAAAAA------- --------AAAAAAAACAAAAAAA------- --------AAAAAAAAAAAAAAAA------- --------AAAAAAAAAAAAAAAA------- 
------AAA--------------AAA----- ------A-AAAAAAAAAAAAAAAA-A----- --------AAAAAAAAAAAAAAAA------- --------A------AA------A------- --------A------AA------A------- --------A------AA------A------- --------A------AA------A------- --------A------AA------A------- --------A------AA------A------- --------AAAAAAAAAAAAAAAA------- --------A--------------A------- --------AAAAAAAAAAAAAAAA------- --------AAAAAAAAAAAAAAAA------- --------AAAAAAAAAAAAAAAA------- --------AAAAAAAAAAAAAAAA------- 
------AAA--------------AAA----- ------A-AAAAAAAAAAAAAAAA-A----- --------AAAAAAAAAAAAAAAA------- --------A------AA------A------- --------A------AA------A------- --------A------AA------A------- --------A------AA------A------- --------A------AA------A------- --------A------AA------A------- --------AAAAAAAAAAAAAAAA------- --------AAAAAAAAAAAAAAAA------- --------AAAAAAAAAAAAAAAA------- --------AAAAAAAAAAAAAAAA------- --------AAAAAAAAAAAAAAAA------- --------AAAAAAAAAAAAAAAA------- 
------AAA--------------AAA----- ------A-AAAAAAAAAAAAAAAA-A----- --------AAAAAAAAAAAAAAAA------- --------A------AA------A------- --------A------AA------A------- --------A------AA------A------- --------A------AA------A------- --------A------AA------A------- --------A------AA------A------- --------AAAAAAAAAAAAAAAA------- --------AAAAAAAAAAAAAAAA------- --------AAAAAAAAAAAAAAAA------- --------AAAAAAAAAAAAAAAA------- --------AAAAAAAAAAAAAAAA------- --------AAAAAAAAAAAAAAAA------- 
------AAA--------------AAA----- ------A-AAAAAAAAAAAAAAAA-A----- --------AAAAAAAAAAAAAAAA------- --------A------AA------A------- ------BBA------AA------ABB----- ----BBBBA------AA------ABBBB--- -----BBBA------AA------ABBB---- -----BBBA------AA------ABBB---- -------BA------AA------AB------ --------AAAAAAAAAAAAAAAA------- --------AAAAAAAAAAAAAAAA------- --------AAAAAAAAAAAAAAAA------- --------AAAAAAAAAAAAAAAA------- --------AAAAAAAAAAAAAAAA------- --------AAAAAAAAAAAAAAAA------- 
------AAA--------------AAA----- ------A-AAAAAAAAAAAAAAAA-A----- --------AAAAAAAAAAAAAAAA------- --------A------AA------A------- ------BBA------AA------ABB----- ---BBBBBA------AA------ABBBB--- --BBBBBBA------AA------ABBBBBB- BBBBBBBBA------AA------ABBBBBBB -BB----BA------AA------AB----BB --------AAAAAAAAAAAAAAAA------- --------AAAAAAAAAAAAAAAA------- --------AAAAAAAAAAAAAAAA------- --------AAAAAAAAAAAAAAAA------- --------AAAAAAAAAAAAAAAA------- --------AAAAAAAAAAAAAAAA------- 
------AAA--------------AAA----- ------A-AAAAAAAAAAAAAAAA-A----- --------AAAAAAAAAAAAAAAA------- --------A------AA------A------- ------BBA------AA------ABB----- ----BBBBA------AA------ABBBB--- --BB-BB-A------AA------A-BB-BB- --BBBBBBA------AA------ABBBBBB- --BB---BA------AA------AB---BB- --------AAAAAAAAAAAAAAAA------- --------AAAAAAAAAAAAAAAA------- --------AAAAAAAAAAAAAAAA------- --------AAAAAAA--AAAAAAA------- --------AAAAAAAAAAAAAAAA------- --------AAAAAAAAAAAAAAAA------- 
------AAA--------------AAA----- ------A-AAAAAAAAAAAAAAAA-A----- --------AAAAAAAAAAAAAAAA------- --------A------AA------A------- ------BBA------AA------ABB----- ----BBBBA------AA------ABBBB--- --BB-BB-A------AA------A-BB-BB- --BBBBBBA------AA------ABBBBBB- --BB---BA------AA------AB---BB- --------AAAAAAAAAAAAAAAA------- --------AAAAAAAAAAAAAAAA------- --------AAAAAAAAAAAAAAAA------- --------AAAAAAA--AAAAAAA------- --------AAAAAAAAAAAAAAAA------- --------AAAAAAAAAAAAAAAA------- 
------AAA--------------AAA----- ------A-AAAAAAAAAAAAAAAA-A----- --------AAAAAAAAAAAAAAAA------- --------A------AA------A------- ------BBA------AA------ABB----- ---BBBBBA------AA------ABBBB--- --BBBBBBA------AA------ABBBBBB- BBBBBBBBA------AA------ABBBBBBB -BB----BA------AA------AB----BB --------AAAAAAAAAAAAAAAA------- --------AAAAAAAAAAAAAAAA------- --------AAAAAAAAAAAAAAAA------- --------AAAAAAAAAAAAAAAA------- --------AAAAAAAAAAAAAAAA------- --------AAAAAAAAAAAAAAAA------- 
------AAA--------------AAA----- ------A-AAAAAAAAAAAAAAAA-A----- --------AAAAAAAAAAAAAAAA------- --------A------AA------A------- ------BBA------AA------ABB----- ----BBBBA------AA------ABBBB--- -----BBBA------AA------ABBB---- -----BBBA------AA------ABBB---- -------BA------AA------AB------ --------AAAAAAAAAAAAAAAA------- --------AAAAAAAAAAAAAAAA------- --------AAAAAAAAAAAAAAAA------- --------AAAAAAAAAAAAAAAA------- --------AAAAAAAAAAAAAAAA------- --------AAAAAAAAAAAAAAAA------- 
------AAA--------------AAA----- ------A-AAAAAAAAAAAAAAAA-A----- --------AAAAAAAAAAAAAAAA------- --------A------AA------A------- --------A------AA------A------- --------A------AA------A------- --------A------AA------A------- --------A------AA------A------- --------A------AA------A------- --------AAAAAAAAAAAAAAAA------- --------AAAAAAAAAAAAAAAA------- --------AAAAAAAAAAAAAAAA------- --------AAAAAAAAAAAAAAAA------- --------AAAAAAAAAAAAAAAA------- --------AAAAAAAAAAAAAAAA------- 
------AAA--------------AAA----- ------A-AAAAAAAAAAAAAAAA-A----- --------AAAAAAAAAAAAAAAA------- --------A------AA------A------- --------A------AA------A------- --------A------AA------A------- --------A------AA------A------- --------A------AA------A------- --------A------AA------A------- --------AAAAAAAAAAAAAAAA------- --------AAAAAAAAAAAAAAAA------- --------AAAAAAAAAAAAAAAA------- --------AAAAAAAAAAAAAAAA------- --------AAAAAAAAAAAAAAAA------- --------AAAAAAAAAAAAAAAA------- 
------AAA--------------AAA----- ------A-AAAAAAAAAAAAAAAA-A----- --------AAAAAAAAAAAAAAAA------- --------A------AA------A------- --------A------AA------A------- --------A------AA------A------- --------A------AA------A------- --------A------AA------A------- --------A------AA------A------- --------AAAAAAAAAAAAAAAA------- --------A--------------A------- --------AAAAAAAAAAAAAAAA------- --------AAAAAAAAAAAAAAAA------- --------AAAAAAAAAAAAAAAA------- --------AAAAAAAAAAAAAAAA------- 
------AAAAAAAAAAAAAAAAAAAA----- ------A-AAAAAAAAAAAAAAAA-A----- --------AAAABAAAAABAAAAA------- --------AAAABAAAAABAAAAA------- --------AAABBBBBBBBBBAAA------- --------AAABBBBBBBBBBAAA------- --------AAAABBBBBBBBBBAA------- --------AAABBBBBBBBBBBAA------- --------AAABDAABBBBBBBAA------- --------AAACCCCBBBBBBAAA------- --------AAACCCCBBBBBBAAA------- --------AAAAAAACAAAAAAAA------- --------AAAAAAAACAAAAAAA------- --------AAAAAAAAAAAAAAAA------- --------AAAAAAAAAAAAAAAA------- 
------AAAAAAAAAAAAAAAAAAAA----- ------A------------------A----- ------------------------------- ------------------------------- ------------------------------- ------------------------------- ------------------------------- ------------------------------- ------------------------------- ------------------------------- ------------------------------- ------------------------------- ------------------------------- ------------------------------- ------------------------------- 
------AAAAAAAAAAAAAAAAAAAA----- ------A------------------A----- ------------------------------- ------------------------------- ------------------------------- ------------------------------- ------------------------------- ------------------------------- ------------------------------- ------------------------------- ------------------------------- ------------------------------- ------------------------------- ------------------------------- ------------------------------- 
------AAAAAAAAAAAAAAAAAAAA----- ------AAAAAAAAAAAAAAAAAAAA----- ------------------------------- ------------------------------- ------------------------------- ------------------------------- ------------------------------- ------------------------------- ------------------------------- ------------------------------- ------------------------------- ------------------------------- ------------------------------- ------------------------------- ------------------------------- 
