model
size = 25, scale = 0.05, origin = -y
material 
  colors = A:#DF7B33 B:#BE682B C:#9A5423 D:#F58738 E:#1A1A1A
voxels
------------------------- ------------------------- ------------------------- ------------------------- ------------------------- ------------------------- ------------------------- ------------------------- ------------------------- -----------AEC----------- ----------BDECA---------- ---------AACECAA--------- ---------EEEEEEE--------- ---------AADEBDD--------- ----------DCEDC---------- -----------BEC----------- ------------------------- ------------------------- ------------------------- ------------------------- ------------------------- ------------------------- ------------------------- ------------------------- ------------------------- 
------------------------- ------------------------- ------------------------- ------------------------- ------------------------- ------------------------- ------------------------- ---------CCCEACA--------- --------DABCEDDCD-------- -------ECDA---AACE------- -------EAA-----ABE------- -------EB-------DE------- -------EE-------EE------- -------EA-------AE------- -------EDB-----ABE------- -------EADA---DDAE------- --------CCBCEDCDB-------- ---------DCCEDBC--------- ------------------------- ------------------------- ------------------------- ------------------------- ------------------------- ------------------------- ------------------------- 
------------------------- ------------------------- ------------------------- ------------------------- ------------------------- ----------BBEAD---------- --------CBDDEADAB-------- -------AA-------AA------- ------EA---------CE------ ------D-----------D------ -----CA-----------AB----- -----DB-----------AC----- -----EE-----------EE----- -----BB-----------DB----- -----AB-----------AA----- ------D-----------A------ ------EA---------DE------ -------DA-------DC------- --------BAAAEABBB-------- ----------DAECB---------- ------------------------- ------------------------- ------------------------- ------------------------- ------------------------- 
------------------------- ------------------------- ------------------------- ------------------------- ---------CABECBC--------- -------CDC-----BDA------- ------BA---------BC------ -----EB-----------BE----- -----B-------------C----- ----CC-------------CC---- ----C---------------A---- ----D---------------C---- ----E---------------E---- ----A---------------D---- ----B---------------A---- ----CD-------------BA---- -----C-------------D----- -----EB-----------CE----- ------AB---------AA------ -------ACC-----CAB------- ---------CACEDCB--------- ------------------------- ------------------------- ------------------------- ------------------------- 
------------------------- ------------------------- ------------------------- ---------DBAEBAC--------- -------BA-------AC------- ------C-----------C------ -----C-------------A----- ----E---------------E---- ----A---------------C---- ---D-----------------C--- ---D-----------------A--- ---C-----------------D--- ---E-----------------E--- ---B-----------------B--- ---A-----------------B--- ---A-----------------C--- ----D---------------B---- ----E---------------E---- -----D-------------D----- ------C-----------B------ -------BB-------DD------- ---------CABEDDB--------- ------------------------- ------------------------- ------------------------- 
------------------------- ------------------------- ----------AAEBC---------- -------DBC-----DBA------- ------C-----------A------ -----C-------------A----- ----E---------------E---- ---A-----------------B--- ---D-----------------C--- ---A-----------------A--- --C-------------------B-- --A-------------------B-- --E-------------------E-- --C-------------------A-- --B-------------------D-- ---A-----------------D--- ---D-----------------B--- ---C-----------------B--- ----E---------------E---- -----D-------------C----- ------B-----------A------ -------BCC-----ACD------- ----------CBEDD---------- ------------------------- ------------------------- 
------------------------- ------------------------- --------DADCEDACB-------- ------CA---------CD------ -----A-------------C----- ----A---------------A---- ---E-----------------E--- ---D-----------------C--- --D-------------------B-- --D-------------------C-- --A-------------------C-- --B-------------------B-- --E-------------------E-- --D-------------------C-- --C-------------------D-- --A-------------------D-- --B-------------------B-- ---D-----------------B--- ---E-----------------E--- ----B---------------B---- -----D-------------B----- ------CA---------AC------ --------ABCDEBCCB-------- ------------------------- ------------------------- 
------------------------- ---------ADCEBDC--------- -------BD-------DD------- -----CA-----------BC----- ----B---------------C---- ---E-----------------E--- ---B-----------------B--- --C-------------------C-- --B-------------------B-- -A---------------------A- -A---------------------C- -D---------------------D- -E---------------------E- -C---------------------B- -D---------------------D- -A---------------------B- --B-------------------C-- --A-------------------C-- ---B-----------------A--- ---E-----------------E--- ----C---------------B---- -----BA-----------BB----- -------BC-------DD------- ---------BDDEDDA--------- ------------------------- 
------------------------- --------CAAAECDAA-------- ------DA---------CC------ -----C-------------D----- ----C---------------D---- ---E-----------------E--- --C-------------------A-- --A-------------------C-- -A---------------------A- -D---------------------D- -D---------------------C- -C---------------------B- -E---------------------E- -D---------------------C- -C---------------------A- -B---------------------D- -B---------------------D- --D-------------------C-- --C-------------------A-- ---E-----------------E--- ----D---------------A---- -----D-------------A----- ------CD---------BA------ --------BBCCECDCD-------- ------------------------- 
-----------AEC----------- -------ABDC---ADDD------- ------A-----------A------ ----DA-------------AA---- ---B-----------------C--- ---E-----------------E--- --D-------------------B-- -D---------------------C- -A---------------------B- -B---------------------A- -C---------------------D- C-----------------------A E-----------------------E A-----------------------D -C---------------------C- -D---------------------A- -B---------------------B- -C---------------------A- --D-------------------D-- ---E-----------------E--- ---B-----------------A--- ----BB-------------CA---- ------C-----------D------ -------BBAD---CDDB------- -----------BEB----------- 
----------BCECA---------- -------BCC-----CAC------- -----AD-----------BD----- ----B---------------C---- ---D-----------------B--- --E-------------------E-- --D-------------------B-- -C---------------------B- -B---------------------B- -D---------------------B- B-----------------------A D-----------------------D E-----------------------E D-----------------------A A-----------------------A -C---------------------C- -B---------------------A- -A---------------------D- --C-------------------A-- --E-------------------E-- ---A-----------------C--- ----D---------------B---- -----BB-----------BA----- -------DAC-----CBB------- ----------DBECB---------- 
---------CBDECBD--------- -------BB-------BB------- -----BA-----------CB----- ----A---------------D---- ---B-----------------C--- --E-------------------E-- --D-------------------A-- -D---------------------D- -C---------------------A- C-----------------------C D-----------------------A A-----------------------D E-----------------------E A-----------------------C D-----------------------A D-----------------------D -A---------------------C- -B---------------------D- --A-------------------B-- --E-------------------E-- ---C-----------------D--- ----A---------------A---- -----AB-----------BA----- -------AA-------BD------- ---------ABAEDDA--------- 
---------CBBEBBD--------- -------CD-------BC------- -----DC-----------CD----- ----A---------------A---- ---C-----------------B--- --E-------------------E-- --B-------------------D-- -B---------------------D- -A---------------------D- D-----------------------A C-----------------------C A-----------------------D E-----------------------E A-----------------------B C-----------------------A D-----------------------C -B---------------------D- -B---------------------A- --A-------------------D-- --E-------------------E-- ---D-----------------D--- ----D---------------C---- -----CA-----------DA----- -------AC-------AA------- ---------CCCEDBB--------- 
---------ACDEDBC--------- -------CA-------BB------- -----AB-----------BD----- ----A---------------B---- ---B-----------------D--- --E-------------------E-- --A-------------------A-- -D---------------------A- -A---------------------D- B-----------------------C D-----------------------A A-----------------------B E-----------------------E A-----------------------A C-----------------------D B-----------------------A -B---------------------A- -C---------------------B- --C-------------------C-- --E-------------------E-- ---A-----------------A--- ----D---------------A---- -----CB-----------AC----- -------DA-------BD------- ---------DBCEBCC--------- 
----------ADEAC---------- -------CAA-----BDD------- -----CD-----------CA----- ----D---------------B---- ---A-----------------A--- --E-------------------E-- --C-------------------A-- -A---------------------C- -B---------------------D- -A---------------------A- B-----------------------C C-----------------------D E-----------------------E A-----------------------B D-----------------------B -A---------------------D- -C---------------------C- -D---------------------B- --C-------------------A-- --E-------------------E-- ---C-----------------C--- ----D---------------C---- -----AA-----------BA----- -------ADB-----ABB------- ----------BAEBB---------- 
-----------BEB----------- -------ACCC---DDBC------- ------C-----------C------ ----DC-------------AC---- ---C-----------------B--- ---E-----------------E--- --B-------------------D-- -A---------------------C- -B---------------------B- -D---------------------A- -C---------------------B- D-----------------------B E-----------------------E C-----------------------A -A---------------------D- -D---------------------A- -A---------------------B- -C---------------------C- --B-------------------A-- ---E-----------------E--- ---A-----------------B--- ----DC-------------AC---- ------C-----------D------ -------BCBA---ACCD------- -----------DEC----------- 
------------------------- --------BDDAEACAA-------- ------BC---------AD------ -----B-------------A----- ----D---------------A---- ---E-----------------E--- --C-------------------D-- --B-------------------A-- -C---------------------C- -B---------------------A- -D---------------------C- -D---------------------C- -E---------------------E- -B---------------------A- -A---------------------A- -B---------------------A- -C---------------------D- --C-------------------A-- --D-------------------D-- ---E-----------------E--- ----A---------------B---- -----B-------------B----- ------AB---------CA------ --------CACCEBAAA-------- ------------------------- 
------------------------- ---------ADAEBDA--------- -------CD-------DA------- -----DD-----------BB----- ----C---------------C---- ---E-----------------E--- ---B-----------------A--- --C-------------------A-- --B-------------------A-- -B---------------------D- -B---------------------A- -A---------------------A- -E---------------------E- -C---------------------C- -B---------------------A- -B---------------------C- --A-------------------D-- --B-------------------D-- ---C-----------------D--- ---E-----------------E--- ----B---------------C---- -----BD-----------AB----- -------BD-------DC------- ---------ABCEACD--------- ------------------------- 
------------------------- ------------------------- --------BDCCECDDB-------- ------DC---------BD------ -----A-------------B----- ----A---------------B---- ---E-----------------E--- ---B-----------------D--- --C-------------------A-- --B-------------------B-- --D-------------------B-- --B-------------------D-- --E-------------------E-- --A-------------------C-- --D-------------------C-- --D-------------------B-- --B-------------------A-- ---D-----------------A--- ---E-----------------E--- ----D---------------B---- -----C-------------A----- ------DC---------BB------ --------BDBCEBABA-------- ------------------------- ------------------------- 
------------------------- ------------------------- ----------ABEAC---------- -------CAC-----AAC------- ------D-----------B------ -----A-------------D----- ----E---------------E---- ---C-----------------A--- ---B-----------------D--- ---A-----------------D--- --B-------------------A-- --A-------------------A-- --E-------------------E-- --B-------------------A-- --C-------------------A-- ---A-----------------D--- ---B-----------------A--- ---D-----------------B--- ----E---------------E---- -----D-------------D----- ------A-----------B------ -------BCD-----AAA------- ----------BDEAB---------- ------------------------- ------------------------- 
------------------------- ------------------------- ------------------------- ---------DCAECDC--------- -------CB-------CA------- ------C-----------D------ -----A-------------D----- ----E---------------E---- ----C---------------A---- ---B-----------------A--- ---A-----------------B--- ---D-----------------A--- ---E-----------------E--- ---B-----------------A--- ---C-----------------D--- ---B-----------------D--- ----A---------------C---- ----E---------------E---- -----B-------------D----- ------D-----------C------ -------AD-------DB------- ---------CADEBAC--------- ------------------------- ------------------------- ------------------------- 
------------------------- ------------------------- ------------------------- ------------------------- ---------AADECDB--------- -------DBA-----CAD------- ------DC---------CD------ -----ED-----------BE----- -----D-------------A----- ----CC-------------DA---- ----C---------------D---- ----C---------------D---- ----E---------------E---- ----B---------------A---- ----D---------------D---- ----CD-------------CD---- -----D-------------D----- -----EB-----------AE----- ------DB---------CC------ -------CAC-----BBD------- ---------BBAEACA--------- ------------------------- ------------------------- ------------------------- ------------------------- 
------------------------- ------------------------- ------------------------- ------------------------- ------------------------- ----------CBEDA---------- --------ADBDECDBB-------- -------AC-------DD------- ------EB---------DE------ ------A-----------A------ -----CD-----------DB----- -----AD-----------DD----- -----EE-----------EE----- -----AD-----------AC----- -----BA-----------DC----- ------B-----------C------ ------EC---------BE------ -------BA-------CB------- --------DACAEBDBD-------- ----------CBECC---------- ------------------------- ------------------------- ------------------------- ------------------------- ------------------------- 
------------------------- ------------------------- ------------------------- ------------------------- ------------------------- ------------------------- ------------------------- ---------BBBEAAA--------- --------BBADEBCDA-------- -------EDCC---BDCE------- -------EBC-----CAE------- -------EC-------DE------- -------EE-------EE------- -------EA-------CE------- -------EAD-----BBE------- -------EACA---BCAE------- --------CAADECBCB-------- ---------BBBEBCA--------- ------------------------- ------------------------- ------------------------- ------------------------- ------------------------- ------------------------- ------------------------- 
------------------------- ------------------------- ------------------------- ------------------------- ------------------------- ------------------------- ------------------------- ------------------------- ------------------------- -----------DEB----------- ----------BDEAD---------- ---------BBCEBBB--------- ---------EEEEEEE--------- ---------DAAEDBC--------- ----------DCEBD---------- -----------BEC----------- ------------------------- ------------------------- ------------------------- ------------------------- ------------------------- ------------------------- ------------------------- ------------------------- ------------------------- 
