model
size = 32, scale = 0.05, origin = -y
material 
  colors = A:#200 B:#E00 C:#080 D:#050 E:#F90 F:#0D0 G:#0A0 H:#FFF I:#070 J:#0B0 K:#700 L:#100
voxels
303-2E1020-2A2E2A27-E2-E986-8A24-2A4-2A25-E4-E923-4A26-3A2-3A24-2A4-2A24-A6-A24-E6-E889-6A25-3A2-3A23-3A4-3A22-2A6-2A23-E6-E889-6A24-3A4-3A2(22-2A6-2A)22-A8-A22-E8-E855-8A23-3A4-3A22-2A6-3A20-3A6-3A2(20-2A8-2A)21-E8-E823-8A23-3A4-3A21-H2A6-3A3(20-2A8-2A)20-A10-A20-E10-E790-8A23-H2A4-3A21-H2A6-3A20-2A8-3A3(18-2A10-2A)19-E10-E20-E768-10A21-3A3-G2-3A20-2A8-2A19-H2A8-3A3(18-2A10-2A)18-HA11-A18-2A11-E18-E677-2B27-7B24-10A21-3A2-AI2-3A19-3A3-AI3-3A18-2A5-F4-2A17-H2A10-3A16-HA12-2A16-2A12-2A16-HA12-2A17-HA11-E18-E675-2B2-2B25-3B2-3B22-5A2B5A19-3A-6A-3A18-HA3-4A3-2A17-H2A3-4A3-3A16-HA5-ACF4-2A16-LA6-G5-2A15-2HA6-G5-2A16-2A12-2A17-A13-E17-E673-2B6-2B22-3B5-2B21-3A6B3A19-5A4B5A17-H2A-3A2B3A-3A16-HA3-2A2B2A3-2A16-HA3-6A3-2A16-2A4-AJDCF3-3A14-HA7-2G5-2A14-2A7-G6-2A15-A14-A16-E14-E658-2B8-B21-3B7-3B18-3AB6-B3A17-4A2B4-2B4A2(16-2A-2A2B2-2B2A-2A)15-2(HA3-2A4B2A3-2A14-)2A3-3A2DF2C3-2A14-2A4-2AFC2D4-2A14-2A7-G-G4-2A15-E14-AE657-B10-B19-3B9-2B17-2(3AB8-B4A15-)4AB6-B4A15-HA-2AB6-B2A-3A13-2A2-A2B4-2BA2-AKA13-2A2-2AB4-B2A2-AKA12-H2A2-2A6BAC2-2A14-2A3-3A2B2ACF2-2A14-A5-2AFDCF5-A14-E8-G7-E654-3B12-2B17-2B11-B17-2AB10-B3A15-H2AB8-B2AKA14-H3AB8-B4A14-2A-AB8-BA-AKA13-2A-AB8-BA-AKA2(12-2A2-2AB6-B2A2-2A)12-HA3-2A2B2-2BAC3-2A12-HA4-3A2BACDI3-2A13-E6-FDCDG5-E23-2G630-B14-B15-2B14-B16-AB12-B2A14-3AB10-B3A14-H2AB10-B3A13-4AB10-B4A12-2A-2AB8-B2A-2(2A12-2A2-AB8-BA2-)2A12-HA2-2AB6-BAC2-2A12-2A3-2A6BCDI2-2A13-E5-FD2A2C5-E22-FD631-B2(14-2B)14-B15-2AB12-B2A14-2AB12-B2A13-2(2A-AB10-BA-2A12-)2A-AB10-BA-2A11-3A-AB10-BA-3A10-2A3-AB8-BA3-2A10-2A3-2AB6-BAC3-2A10-2A4-2A2B2-2BADC3-2A11-E5-FDA2BA2C5-E20-2(F2G)27-DG2-D28-D566-2B14-B16-B14-2B14-2AB12-B2A13-3AB12-B3A2(12-2A-AB10-BA-2A)11-2(2A2-AB10-BA2-2A10-)2(2A3-AB8-BA3-2A10-)2A3-2A2B4-2BAC3-2A11-E5-DA4BACD4-E19-DG2ADF28-DCG29-2D31-G534-2B14-B16-2B13-2B14-2AB12-B2A13-3AB12-B3A12-2A-AB10-BA-2A11-2A2-AB10-BA2-2A10-2A2-AB10-BA2-2A9-3A2-AB10-BA2-3A8-3A3-AB8-BA3-3A9-A4-AB8-BA4-A10-A4-AFB6-BGC4-A10-E6-F6BG-D4-E18-CG3AG2-GD24-CA-D-C2-C23-F64-F502-2B14-B16-B14-2B14-2AB12-B2A13-3AB12-B3A11-3A-AB10-BA-3A10-2A2-AB10-BA2-2A9-3A2-AB10-BA2-3A8-2A3-AB10-BA3-2(2A8-2A4-AB8-BA4-)2A8-E5-AG2B4-2B2A4-A17-DG4B2A6-E19-3AF29-AG2-C26-C8-C21-C30-F35-D471-B2(14-2B)14-B14-3AB12-B3A11-4AB12-B4A9-3A2-AB10-BA2-3A8-2A3-AB10-BA3-2A7-3A3-AB10-BA3-3A6-3A3-AB10-BA3-3A7-2A4-AB8-BA4-2A8-A5-2AB6-BAG5-A8-E6-FA2B2-2BAG6-E16-C2A2B3A26-AGFGD30-D4-C23-C4-GD3-GC50-C35-G471-B14-B15-2B14-B14-3AB12-B3A11-3A-AB10-BA-3A9-3A2-AB10-BA2-3A7-3A3-AB10-BA3-3A6-2A4-AB10-BA4-2A6-2A5-AB8-BA5-2A6-2A5-AB8-BJ5-2A6-E6-FAB6-BAG6-E14-GC6BAG24-5AF28-AF-D36-2C21-F4-CD-C3-C15-F10-D-DC2-G15-C11-D-D54-D440-B12-B17-2B12-B14-5AB10-B5A9-3A2-AB10-BA2-3A7-3A3-2AB8-B2A3-2(3A5-)2(AB8-BA5-3A4-3A5-)2AB6-BAJ5-3A5-A6-FAB6-B2A6-A6-E7-FAB4-BAF7-E15-GA4B2A24-G3A2GFD29-D31-D6-C17-C3-C2-DGD27-D-D3-3C3-C14-C11-FD-D31-2D53-F408-2B10-B20-B10-B14-7AB8-B7A7-4A2-2AB8-B2A2-4A5-2(3A5-2AB6-B2A5-3A4-)2A6-2AB6-BAJ6-2A4-2A7-2AB4-B2A7-2A4-E8-FA2B2-2BAF8-E14-CA4B2A23-C8A22-C45-C24-D24-F2(2-2C)11-I15-CF-G5-C4-C2F16-D-D2(3-C)5-I10-F10-C3-C2D84-GD376-2B8-2B21-B8-B14-9A2B5-B9A5-4A4-2A2B4-2B2A4-4A3-3A7-2AB4-B2A7-3A2-3A7-2A2B2-2B2A7-3A3-A8-GA6B2A8-A4-E8-D2A4B2A9-E14-C2A2B2AF25-6A27-2AGA23-I-C5-D6-2C32-C22-C12-I13-C9-C19-G3-CD7-C6-F15-D2-C5-F5-C33-I11-J9-C4-F17-J31-D35-2D346-B6-B23-2B6-2B12-12A2B2-2B12A2-4A3-2A-3A4B3A-2A3-4A2-2A9-2A4B2A9-2A2-2A9-3A2B3A9-2A2-E11-5AF11-E14-5AF27-4A55-C46-2(C18-)F2(13-C)22-C4-C26-D12-C11-C3-C2-G5-FCD20-D9-C4-F-I29-D12-F10-I4-C17-J31-D3-GD315-B31-B4-2B25-2B2-2B14-14A2B14A-12AG19AEA8-A3-4A3-A8-2A-E29-E144-D7-C49-D19-ID12-C13-C27-D7-C18-C24-C3-C8-C25-F6-C31-C4-CDF21-C20-C-J12-DF17-D13-D15-D5-DC24-D259-B31-2B-B27-6B13-7A7-B3A7-7AE30A2E4-22A4-E7-18A16-14A20-10A25-4A24-D4-2AD30-2D6-D23-D13-IJ9-C2-C41-C26-D8-D3-G18-D37-C18-G3-C2-C34-2C2-C4-C22-D10-I21-D20-C10-D4-C15-FD4-GD7-DJC14-JFI124-2B7-B22-B9-B21-2B8-B22-2B32-B6-B25-4B-B27-3B-B13-E4A10-2B10-4A2E6A8-B9-5AE2-E7A14-8A3-E27A5-E25A7-2E20AE11-2E16A2E14-2E12A2EC17-2E8A2E8-FD12-2E4A2E20-C2-JI-4E36-C26-GD7-D3-D18-D12-G24-C17-CG9-C-C23-C2-D6-C36-F-F42-F10-C4-C21-FC3-D22-F12-DCDJ12-DF63-B7-B23-B30-B31-B9-B22-B8-B23-B6-B25-B4-B29-2B16-A28-A2-2A26-AE3-2A24-AE5-2A22-AE7-4A17-2AE12-3A12-2A17-2A9-2A21-2A5-2A3-D21-5A11-IJ42-J2C9-C58-G8-C3-I53-C9-I42-CG3-D2-C4-C23-F9-F3-DC-C42-CD9-C5-C16-F31-I44-DCJD12-DJ607-C-F9-F31-D7-D18-CD57-D6-DC31-D9-D11-C3-D2-C4-F29-D3-C3-2D12-D3-F27-F10-F5-D16-F76-DCDJ11-2DF21-
