model
size = 18 30 21, scale = 0.05, origin = -y
material 
  colors = A:#100 B:#000 C:#099 D:#C39 E:#96F F:#093 G:#633 H:#93C I:#939 J:#336 K:#339 L:#636 M:#003 N:#9CC O:#669 P:#63C Q:#C99 R:#FCC S:#9C6 T:#936 U:#969 V:#6C3 W:#663
voxels
------CAALF------- ------FAACAA------ ------ANAAEA------ ------PAGGAA------ ------VOAJAC------ ------AAAAAA------ ------RAA-D------- ------AIA-A------- ------CA--F------- ------CA--A------- ------AE---------- ------G----------- ------------------ ------------------ ------------------ ------------------ ------------------ ------------------ ------------------ ------------------ ------------------ ------------------ ------------------ ------------------ ------------------ ------------------ ------------------ ------------------ ------------------ ------------------ 
-----CCA--FJJ----- ----AAF---AAAA---- ----AAA--AEHH----- ----EMP--GAAA----- ----ASV--JACC----- ----AAA-AAACC----- ----AAR-AHDAA----- ----DQAIAAAL------ ---AKCCAALFQ------ ---AAACATAAF------ ---ONAAEAAAA------ ---AAGGAEEMA------ ----OAJAUAS------- ----AAAAAAA------- ------HDD--------- ------------------ ------------------ ------------------ ------------------ ------------------ ------------------ ------------------ ------------------ ------------------ ------------------ ------------------ ------------------ ------------------ ------------------ ------------------ 
---UKC------DD---- ---AAA------AA---- ---DA-------AA---- ---AE-------AA---- ---AA-------EE---- ---TA-------AA---- ---AA------AAA---- --EED------FFF---- --UUK------AAA---- --AAA------AA----- --AAN------FF----- --AAA-----MAA----- ---AO----ASP------ ---AAAA-AAAV------ ----AAHDDAAA------ -----AAAADQ------- -------BBB-------- ------------------ ------------------ ------------------ ------------------ ------------------ ------------------ ------------------ ------------------ ------------------ ------------------ ------------------ ------------------ ------------------ 
---DK--------D---- ---LA--------A---- ---AA--------A---- ---AE--------T---- --EE---------A---- --AA---------E---- --AA---------U---- --AA---------A---- --DD--------II---- --LL--------KK---- --JJ--------A----- --AA-------NN----- --HH-------AA----- --AAA------OO----- ---CAA----AAA----- ----IAAA-DQA------ -----BBBBBBB------ ------BBBBB------- --------BB-------- ------------------ ------------------ ------------------ ------------------ ------------------ -------------III-- ------------KWKKK- ------------AAAWA- ------------AAWWA- -------------EEE-- ------------------ 
--QQ---------AA--- --FF---------AA--- --AA---------EE--- --AA---------AA--- --MM---------AA--- --SS---------AA--- --AA---------DD--- --A----------KK--- -QQ----------A---- -FF---------CC---- -DD---------AA---- -AA---------A----- --AA--------G----- --AA--------A----- ---EA------AA----- ---AIA-----AA----- ----BBB---BBB----- -----BBBBBBBB----- ------BBBBBB------ --------BBBB------ ---------AB------- ---------AAA------ --------BAAAA----- -------BBASAAAAA-- -------BBAAAAAAAA- -------BBAACCCCCCC ----------AAA-AAAA --------------AAAA --------------MMM- --------------BB-- 
--A-----------A--- --A-----------A--- --F-----------M--- --A-----------S--- --P-----------A--- -VV-----------A--- -AA-----------Q--- -RR----------CC--- -AA----------AA--- -A-----------C---- -D----------CC---- -AA---------AA---- -AA---------GG---- -TTT--------JJ---- --AA--------AA---- ---EI-------HH---- ----BB-----BBB---- -----BC----CB----- ------BBB--BB----- -------BBBMBB----- -------BBASGG----- -------BBAAJJJ---- -------BBA-AAA---- -------BB---HHHHH- ------BB------AAAA ------BB------CCCC --------------FFFF --------------AAAA --------------PPPP --------------BBB- 
-II-----------F--- -KK-----------A--- -AA-----------P--- -NN-----------V--- -AA-----------A--- -OO-----------R--- -AA-----------A--- -AA-----------C--- -I-----------AA--- -K-----------A---- -A-----------A---- -A-----------E---- -EE----------A---- -AA----------A---- --AA---------A---- ---AI-------DD---- ----BB------BB---- -----BC-----BB---- ------BB----BB---- -------B----BB---- -------BU---AA---- -------B----AAA--- ------BB-----AA--- ------BB-----DDDD- ------BB------AAAA -----BB-------AAAA --------------AAAA --------------NNNN --------------AAAA --------------BBB- 
-AA-----------AA-- -CC-----------NN-- -AA-----------AA-- -AA-----------OO-- -GG-----------AA-- -AA-----------AA-- -A------------II-- -A------------A--- AA-----------AA--- FB-----------AA--- AA-----------T---- AA-----------A---- -M-----------E---- -SS----------U---- --AA---------A---- ---AI--------D---- ----BB-------B---- -----BC------B---- -----BBB-----B---- ------BB-----BB--- -------B-----EE--- -------A-----UU--- ------BB------AA-- ------B-------DDD- -----BB-------AAAA -----BB-------AAAA --------------AAAA --------------AAAA --------------GGGG --------------BBB- 
-AA------------A-- -CC------------A-- -CC------------G-- -AA------------A-- -G-------------A-- -J------------AA-- AA------------A--- HH------------A--- AA------------D--- AB-----------LL--- FF-----------AA--- AA-----------A---- PP-----------EE--- -VV----------AA--- --AA---------AA--- --RRI--------AA--- ---BBB-------B---- ----BB-------BB--- -----BB------BB--- ------BB-----BB--- -------B------E--- ------BA------AA-- ------BB------AA-- ------B-------AAA- -----BB-------DDDD -----BB-------LLLL --------------CCCC --------------AAAA --------------GGGG --------------BBB- 
-AA------------C-- -AA------------A-- -A-------------G-- -E-------------J-- -A------------AA-- -A------------HH-- AA------------A--- DD------------L--- AA------------Q--- KB------------F--- AA-----------AA--- NN-----------AA--- AA-----------MM--- -OO-----------S--- --AA---------AA--- ---AI--------AA--- ----BB-------BB--- -----BC------BB--- -----BB-------B--- ------BB------B--- -------B------M--- ------BA------SS-- ------B-------AA-- ------B-------AA-- ------B-------QQQ- -----BB-------FFF- --------------AAAA --------------EEE- --------------AAA- ------------------ 
-AA------------A-- -AA------------E-- -TT------------A-- -A-------------A-- -E------------AA-- UU------------DD-- AA------------A--- DD------------F--- AA------------V--- CC------------A--- AA-----------RR--- AA-----------AA--- GG-----------AA--- -AA----------FF--- --AA---------AA--- ---AJ--------PP--- ----BB-------BB--- -----BD------BB--- -----BB------BB--- ------BB------B--- -------B------A--- ------BA------FF-- ------B-------AA-- ------B-------PP-- ------B-------VVV- -----BB-------AAAA --------------TTTT --------------AAAA --------------EEE- ------------------ 
-DD------------T-- -LL------------A-- -AA------------E-- -AA------------U-- -E-------------A-- AA------------DD-- AA------------A--- AA------------A--- DD------------O--- CC-----------AA--- CC-----------AA--- AA-----------I---- GG-----------K---- -JJ----------AA--- --AA---------NN--- --HHJ--------AA--- ---BBB-------B---- ----BB-------B---- -----BB------BB--- ------BB-----BB--- -------B------K--- ------BA------A--- ------BB------NN-- ------B-------AAA- -----BB-------OOOO -----BB-------AAAA --------------AAAA --------------AAAA --------------EEEE --------------BBB- 
-Q------------AA-- -F------------AA-- -A------------EE-- -A------------AA-- -M------------AA-- -S------------AA-- AA------------DD-- AA-----------AA--- QQ-----------AA--- AA-----------AA--- AA-----------A---- EE-----------A---- -A-----------C---- -AA----------A---- --AA---------A---- --DDJ--------G---- ---BBB-------B---- -----BD------B---- -----BBB-----B---- ------BB-----BB--- -------B-----CC--- -------A-----AA--- ------BB------A--- ------B-------GGG- -----BB-------AAAA -----BB-------AAAA --------------AAAA --------------AAAA --------------MMMM --------------BBB- 
-VV-----------AA-- -AA-----------AA-- -RR-----------MM-- -AA-----------SS-- -AA-----------AA-- -FF-----------AA-- -AA-----------QQ-- -PP----------AA--- -V-----------A---- -A-----------C---- -T-----------C---- -A-----------A---- -EE----------G---- -UU----------J---- --AA---------A---- --DDJ-------HH---- ---BBB------BB---- ----BBB-----BB---- ------BB----BB---- -------B----BB---- -------BA---GG---- -------AA---JJJ--- ------BB-----AA--- ------BB-----HHHH- ------BB------AAAA -----BB-------CCCC --------------RRRR --------------AAAA --------------AAAA --------------BBB- 
-OO-----------R--- -AA-----------A--- -AA-----------A--- -II-----------F--- -KK-----------A--- -AA-----------P--- -NN-----------V--- -AA----------CC--- -OO----------AA--- -L-----------A---- -A----------AA---- -AA---------EE---- -EE---------AA---- -AAA--------AA---- --AAG-------AA---- ---AJ-------DD---- ----BB-----BBB---- -----BB----AB----- ------BBB-BBB----- -------BBABBB----- -------BARAAA----- -------AAAIAAA---- -------BMA-AAA---- -------BS---DDDDD- ------BB------AAAA ------BB------AAAA --------------AAAA --------------IIII --------------KKKK --------------BBB- 
--AA---------AA--- --AA---------II--- --AA---------KK--- --AA---------AA--- --CC---------NN--- --AA---------AA--- --AA---------OO--- -GG----------AA--- -AA----------AA--- -FA---------AA---- -AA---------TT---- -AA---------A----- --MM--------E----- --SS--------U----- ---AG------AA----- ----JA-----DD----- ----BBB---BBB----- -----BBBBBBBB----- ------BBBBBB------ --------BBB------- ---------BA------- ---------AIU------ --------MAKAA----- -------BSFADDDDD-- -------BAANAAAAAW- -------BAPAAAAAAAA ----------AAA-AAAA --------------AAAA -------------CCCC- --------------BB-- 
---AA--------AA--- --CCH--------AA--- --CCA--------CC--- --AAC--------AA--- --GGF--------AA--- --JJA--------GG--- --AA---------AA--- --HH---------A---- --AA--------DD---- --CC--------LL---- --RR-------AA----- --AA-------AA----- --AA-------EE----- --FFA------AA----- ---AGA----KAA----- ----JAU--FAA------ -----BBBBBBB------ ------BBBBB------- ---------B-------- ------------------ ------------------ ------------------ ------------------ ------------------ -------------DWD-- ------------LWCLL- ------------CWCLC- ------------ACAAA- -------------GGG-- ------------------ 
---AA-------CC---- ---AHD------AA---- ---AAA------GG---- --EEC-------JJ---- --AAF-------AA---- --AAA-------HH---- --AAP-------AA---- --DDV------LLL---- --AAA------QQQ---- --AAR------FF----- --AAA-----DAA----- --IIC-----AA------ ---KC----RAM------ ---AAEA-AAIS------ ----GAEEMAKA------ -----AUASFA------- -----BBBBB-------- ------------------ ------------------ ------------------ ------------------ ------------------ ------------------ ------------------ ------------------ ------------------ ------------------ ------------------ ------------------ ------------------ 
----A------AA----- ----HD----AEEE---- ----AA----OAAA---- ----AA----LAAA---- ----FA----AAAA---- ----AN---AADD----- ----PA---EEAA----- ----VOA--UAFF----- ---AAAA-AAAA------ ---ARAAHDDAA------ ---AAIAAAADF------ ---ACAALFAA------- ---CCATAARA------- ----AEAAAAI------- ------EEM--------- ------------------ ------------------ ------------------ ------------------ ------------------ ------------------ ------------------ ------------------ ------------------ ------------------ ------------------ ------------------ ------------------ ------------------ ------------------ 
-----AA-AANT------ -----DDAAPAA------ -----AADQVOE------ ----AKCCAALU------ ----FAACATAA------ ----ANAAEAAD------ ----PAGGAEEA------ -----OAJAUAA------ ------AAAAA------- ------AHD-A------- ------AA--D------- ------AL---------- ------T----------- ------------------ ------------------ ------------------ ------------------ ------------------ ------------------ ------------------ ------------------ ------------------ ------------------ ------------------ ------------------ ------------------ ------------------ ------------------ ------------------ ------------------ 
--------Q--------- -------FF--------- -------A---------- -------A---------- ------------------ ------------------ ------------------ ------------------ ------------------ ------------------ ------------------ ------------------ ------------------ ------------------ ------------------ ------------------ ------------------ ------------------ ------------------ ------------------ ------------------ ------------------ ------------------ ------------------ ------------------ ------------------ ------------------ ------------------ ------------------ ------------------ 
