model
size = 14 15 32, scale = 0.05, origin = -y
material 
  colors = A:#FC0 B:#EEE C:#001 D:#222 E:#FF3 F:#F00 G:#555 H:#3C0 I:#3CC J:#C0C K:#900 L:#111 M:#306 N:#C33 O:#00D P:#69F Q:#800 R:#F39 S:#9FC T:#6CF
voxels
61-4F178-4F9-6F8-6F176-F4AF7-F6AF7-6F148-7B6-9B5-F6AFB5-F6AF7-F4A2F8-4A8-3L2A3L6-8L104-9B4-3B5F2B4-BF6AF2(B5-8A)2(6-8A)7-6A8-6A10-2A78-11B3-2B6F3B2-2B8A2B4-9A3(4-10A)5-8A6-8A7-6A10-2A64-11B3-2B6A3B2-2B8A2B2-11AB3(3-11A)3-10A4-10A5-8A7-6A61-12B2-2B8A2B2-B10AB5(2-12A)3-10A4-10A5-8A8-4A48-12B2-2B9AB2-B10A2B-5(12A2-)12A3-10A5-8A8-4A48-13B-B10A2B-B11A2B12AB-4(12A2-)12A3-10A5-8A7-6A47-15B10A4B11A2B12AB-4(12A2-)12A3-10A5-8A7-6A47-16B9A4B10A3B12AB-4(12A2-)12A3-10A5-8A7-6A47-16B8A5B10A3B12AB-4(12A2-)12A3-10A5-8A7-6A47-12B-4B6A19BA2B5-3BAB-A10-A2-2(2A3-)2A2-3A2D2A2D3(3A2-3A6D)3A3-AB6DBA5-8G46-12B2-3B6A3B2-13B-2CB5-2B2CB-2(2C8-2C2-)3C6-3(3C2-3C6D)3C3-2A6D2A6-6D47-11B3-3B6A3B2-12B2-C2E5-B2EC2-3I6-3I2-3M6-3M2-3C6-3C2-3O6-3O2-3J6D3J2-3C6D3C2-3A6D3A3-AG6DGA5-8G32-11B3-4B4A3B3-12B2-3C5-B3C2-3E6-3E2-3C6-3C2-3E6-2EQ2-3C6-3C2-3JD4-D3J2-3C6D3C2(2-3A6D3A)5-6D9-4G20-2(10B4-)11B4-2C5-B3C2-3E6-3E2-3C6-3C2-3E6-2EQ2-3C6-3C2-3J6-3J2-3C6-3C2-3A6D3A2-2AB6DB2A4-G6DG7-G4DG19-2(10B4-)11B4-2C5-B3C2-3E6-3E2-3I6-3I2-3C6-3C2(2-3H6-3H)2-3C6-3C2(2-3A6D3A)5-6DG7-G4DG9-4G6-2(10B4-)10B5-2C5-B3C2-3E6-3E2-3M6-3M2-3H6-3H2-2R8-2R2-2H8-2H2-2C8-2C2-3A6-3A3-2A6D2A5-G6DG6-G6DG18-2(10B4-)11B4-2C5-B3C2-3E6-3E2-3I6-3I2-3C6-3C2(2-3K6-3K)2-C8-2AC3-2A6-2A4-2A6D2A5-G6DG7-6D19-2(10B4-)11B3-3CB4-B3C2-3E6-3E2-3C6-3C2-3E6-2EQ2-3C6-3C2-NCA6-ACN2-C2A6-2AC18-AD4-DA7-6D33-10B4-2(11B3-)3C2B3-B3C2-3E6-3E2-3C6-3C2-E-E6-E-Q2-3C6-3C2-SCA6-ACS2-C2A6-2AC72-10B4-2(11B3-)C2E2B3-B2EC2-3P6-3P2-K-K6-K-K2-C-C6-C-C2-3N6-3N2-TCA6-ACT2-C2A6-2AC72-3(11B3-)3C2B3-B3C3(2-C-C6-C-C)2(2-3C6-3C)2-C2A6-AC13-A59-3(11B3-)2A-AB2-BC-CA2-A-A6-C-A2-A-2A4-2C-2(A2-)A4-C2-A2-4A4-3CA3-3A4-2CA4-2A6-2A73-3(11B3-)2A-A4BA-C2(A2-)A4-3(A2-)A4-A2-A3-5(3A4-)3A5-2A4-2A7-A4-A61-3(11B3-)2A-A4BA-2A3-2(A-A4-)A-6A-A3(4-10A)5-8A6-8A7-6A8-2A2-2A33-3(11B3-)3A-4A-2A4-A2-4A2-A4-2A-4A-2A3(4-10A)5-8A6-8A7-6A8-6A34-3(10B4-)2(2(2A2-)2A4-)3A-2A-3A5-2(8A6-)8A7-3(6A8-)6A10-2A23-3(8B6-)2(2A4-2A6-)3(8A6-)8A7-6A9-4A10-4A51-3(6B8-)2(6A8-)6A7-2(8A6-)8A7-6A74-
