model
size = 23 25 31, scale = 0.05, origin = -y
material 
  colors = A:#111 B:#FF9 C:#A00 D:#F00 E:#777 F:#DDD G:#FC3 H:#EEE I:#FCD021
voxels
----------------------- ----------------------- ----------------------- ----------------------- ----------------------- ----------------------- ----------------------- ----------------------- ----------------------- ----------DD----------- --------D----D--------- ---------DDDD---------- ----------------------- ----------------------- ----------------------- ----------------------- ----------------------- ----------------------- ----------------------- ----------------------- ----------------------- ----------------------- ----------------------- ----------------------- ----------------------- 
----------------------- ----------------------- ----------------------- ----------------------- ----------------------- ----------------------- ----------------------- ----------------------- ----------------------- ---------HDDH---------- --------DHDDHD--------- --------DDDDDD--------- ----------------------- ----------------------- ----------------------- ----------------------- ----------------------- ----------------------- ----------------------- ----------------------- ----------------------- ----------------------- ----------------------- ----------------------- ----------------------- 
----------------------- ----------------------- ----------------------- ----------------------- ----------------------- ----------------------- ----------------------- ----------------------- ----------------------- ---------DDDD---------- -------DBBDDBBD-------- --------DDDDDD--------- ----------------------- ----------------------- ----------------------- ----------------------- ----------------------- ----------------------- ----------------------- ----------------------- ----------------------- ----------------------- ----------------------- ----------------------- ----------------------- 
----------------------- ----------------------- ----------------------- ----------------------- ----------------------- ----------------------- ----------------------- ----------------------- --------BBBBBB--------- -------BBBBBBBB-------- -------BBBBBBBB-------- --------DBBBBD--------- ---------BBBB---------- -------AAABBAAA-------- -------AAAAAAAA-------- ----------------------- ----------------------- ----------------------- ----------------------- ----------------------- ----------------------- ----------------------- ----------------------- ----------------------- ----------------------- 
----------------------- ----------------------- ----------------------- ----------------------- ----------------------- ----------CC----------- ---------ACCA---------- --------CACCAF--------- -------CBBBBBBC-------- -------BBBBBBBB-------- -------BBBBBBBB-------- -------BBBBBBBB-------- -------BBBBBBBB-------- -------BBBBBBBB-------- --------BBBBBB--------- --------BBBBBB--------- ----------BB----------- ----------------------- ----------------------- ----------------------- ----------------------- ----------------------- ----------------------- ----------------------- ----------------------- 
----------------------- ----------------------- ----------------------- ---------FCCFA--------- --------AFCCFA--------- -------AFAAAAFA-------- -------AFAAAAFA-------- -------CAAAAAAC-------- ------CABBBBBBAC------- ------CBBBBBBBBC------- -------BBBBBBBB-C------ ------BBBBBBBBBBC------ ------BBBBBBBBBB------- ------BBBBBBBBBB------- -------BBBBBBBB-------- -------BBBBBBBB-------- --------BBBBBB--------- ----------BB----------- ----------------------- ----------------------- ----------------------- ----------------------- ----------------------- ----------------------- ----------------------- 
----------------------- ----------------------- --------AFFFFA--------- -------AAAAAAAA-------- ------AAAAAAAAAA------- ------AAAAAAAAAA------- ------AAAAAAAAAA------- ------AAAAAAAAAA------- ------AABBBBBBAA------- ------ABBBBBBBBA------- -----CBBBBBBBBBBA------ -----CBBBBBBBBBBA------ ----C-BBBBBBBBBB-C----- ----C-BBBBBBBBBB-C----- ------BBBBBBBBBB------- ------BBBBBBBBBB------- -------BBBBBBBB-------- --------BBBBBB--------- ----------------------- ----------------------- ----------------------- ----------------------- ----------------------- ----------------------- ----------------------- 
----------------------- --------AFFFFA--------- -------AAAAAAAA-------- ------AAAAAAAAAA------- -----AAAAAAAAAAAA------ -----AAAAAAAAAAAA------ -----AAAAAAAAAAAA------ -----AAAAAAAAAAAA------ -----AABBBBBBBBAA------ -----AABBBBBBBBAA------ -----ABBBBBBBBBBA------ -----ABBBBBBBBBBA------ ----ABBBBBBBBBBBBA----- ----ABBBBBBBBBBBBA----- ---C-BBBBBBBBBBBB-C---- ---C--BBBBBBBBBB--C---- ------BBBBBBBBBB------- -------BBBBBBBB-------- ---------BBBB---------- ----------------------- ----------------------- ----------------------- ----------------------- ----------------------- ----------------------- 
---------AFFA---------- -------AAAAAAAA-------- ------AAAAAAAAAA------- -----AAAAAAAAAAAA------ -----AAAAAAAAAAAA------ ----AAAAAAAAAAAAAA----- ----AAAAAAAAAAAAAA----- ----AAAAAAAAAAAAAA----- ----AAAAAAAAAAAAAA----- -----AAAAAAAAAAAA------ ----AABAAAAAAAAAA------ -----ABAAAAAAAAA------- ----ABBBBBBBBBBBBA----- ----ABBBBBBBBBBBBA----- ---A-BBBBBBBBBBBB-A---- ---A-BBBBBBBBBBBB-A---- --C---BBBBBBBBBB---C--- --C----BBBBBBBB----C--- ---------BBBB---------- ----------------------- ----------------------- ----------------------- ----------------------- ----------------------- ----------------------- 
--------AAAAAA--------- ------AAAAAAAAAA------- -----AAAAAAAAAAAA------ -----AAAAAAAAAAAA------ ----AAAAAAAAAAAAAA----- ----AAAAAAAAAAAAAA----- ----AAAAAAAAAAAAAA----- ----AAAAAAAAAAAAAA----- ----AAAAAAAAAAAAAA----- ----AAAAAAAAAAAAAA----- -----AAAAAAAAAAAAA----- -----AAAAAAAAAAAA------ ----ACBBBBBBBBBBCA----- ----ABBBBBBBBBBBBA----- ---ACBBBBBBBBBBBBCA---- ---A-BBBBBBBBBBBB-A---- --AC--BBBBBBBBBB--CA--- --A----BBBBBBBB----A--- --C-----BBBBBB-----C--- ----------------------- ----------------------- ----------------------- ----------------------- ----------------------- ----------------------- 
-------AAAAAAAA-------- ------AAAAAAAAAA------- -----AAAAAAAAAAAA------ ----AAAAAAAAAAAAAA----- ----AAAAAAAAAAAAAA----- ---AAAAAAAAAAAAAAAA---- ---AAAAAAAAAAAAAAAA---- ---AAAAAAAAAAAAAAAA---- ---AAAAAAAAAAAAAAAA---- ----AAAAAAAAAAAAAAA---- ----AAAAAAAAAAAAAA----- -----AAAAAAAAAAAA------ ----AABBBBBBBBBAAA----- ----ACBBBBBBBBAACA----- ----ABBBBBBBBBBBBA----- ---ACBBBBBBBBBBBBCA---- ---A--BBBBBBBBBB--A---- --A----BBBBBBBB----A--- --A-----BBBBBB-----A--- -C------------------C-- -C------------------C-- ---------------------C- ---------------------C- ----------------------- ----------------------- 
-------AAAAAAAA-------- -----AAAAAAAAAAAA------ ----AAAAAAAAAAAAAA----- ----AAAAAAAAAAAAAA----- ---AAAAAAAAAAAAAAAA---- ---AAAAAAAAAAAAAAAA---- ---AAAAAAAAAAAAAAAA---- --AAAAAAAAAAAAAAAAAA--- --AAAAAAAAAAAAAAAAAA--- ---AAAAAAAAAAAAAAAAA--- ----AAAAAAAAAAAAAA----- -----AAAAAAAAAAAAA----- ----ABAAAAAAAAACAA----- ----AAABAAAAABBAAA----- ----AAAAABBBBBBBCA----- ----ABBBBBBBBBBBBA----- ---A-GBBBBBBBBBB-GA---- --AC---BBBBBBBB---CA--- --A------BBBB------A--- -AC----------------CA-- -A------------------A-- -C------------------CA- C--------------------A- C--------------------C- ----------------------- 
------AAAAAAAAAA------- -----AAAAAAAAAAAA------ ----AAAAAAAAAAAAAA----- ----AAAAAAAAAAAAAAA---- ---AAAAAAAAAAAAAAAA---- --AAAAAAAAAAAAAAAAAA--- --AAAAAAAAAAAAAAAAAA--- --AAAAAAAAAAAAAAAAAA--- --AAAAAAAAAAAAAAAAAA--- --AAAAAAAAAAAAAAAAAA--- ---AAAAAAAAAAAAAAAAE--- ----AAAAAAAAAAAAAA----- -----AAAAAAAAAAAA------ -------A------IA------- ---------AA----AA------ ---AACBBBBBBBBBBCAA---- ---ACGBBBBBBBBBBGCA---- ---AC--BBBBBBBB--CA---- --AC-----BBBB-----CA--- --A----------------A--- -AC----------------CA-- -A------------------A-- AC------------------CA- A--------------------A- ----------------------C 
------AAAAAAAAAA------- -----AAAAAAAAAAAA------ ----AAAAAAAAAAAAAA----- ---AAAAAAAAAAAAAAAA---- ---AAAAAAAAAAAAAAAA---- --AAAAAAAAAAAAAAAAAA--- --AAAAAAAAAAAAAAAAAA--- --AAAAAAAAAAAAAAAAAA--- --AAAAAAAAAAAAAAAAAA--- --AAAAAAAAAAAAAAAAAA--- --EAAAAAAAAAAAAAAAAE--- ---AAAAAAAAAAAAAAAA---- -----AAAAAAAAAAAA------ ------AA------IA------- --------------A-------- ----AACCBBBBBBCCAA----- ----ACGBBBBBBBBGCA----- ----AC--BBBBBBG-CA----- ---AC------------CA---- --AC--------------CA--- --A----------------A--- -AC----------------CA-- -A------------------A-- AC------------------CA- ---------------------CA 
------AAAAAAAAAA------- -----AAAAAAAAAAAA------ ----AAAAAAAAAAAAAA----- ---AAAAAAAAAAAAAAAA---- --AAAAAAAAAAAAAAAAAA--- --AAAAAAAAAAAAAAAAAA--- --AAAAAAAAAAAAAAAAAA--- --AAAAAAAAAAAAAAAAAA--- --AAAAAAAAAAAAAAAAAA--- --AAAAAAAAAAAAAAAAAA--- --EAAAAAAAAAAAAAAAAE--- ---AAAAAAAAAAAAAAAA---- -----AAAAAAAAAAAA------ ------AAAAAAAAAA------- --------AAAAAA--------- -----AAACCCCCCAAA------ -----ACCCBBBBCCCA------ ----AAC-GGBBGG-CAA----- ----AC----------CA----- ---AC------------CA---- --AC--------------CA--- --AC--------------CA--- -AC----------------CA-- --------------------A-- ----------------------- 
------AAAAAAAAAA------- -----AAAAAAAAAAAA------ ----AAAAAAAAAAAAAA----- ---AAAAAAAAAAAAAAAA---- --AAAAAAAAAAAAAAAAAA--- --AAAAAAAAAAAAAAAAAA--- --AAAAAAAAAAAAAAAAAA--- --AAAAAAAAAAAAAAAAAA--- --AAAAAAAAAAAAAAAAAA--- --AAAAAAAAAAAAAAAAAA--- --EAAAAAAAAAAAAAAAAE--- ---AAAAAAAAAAAAAAAA---- -----AAAAAAAAAAAA------ ------AAAAAAAAAA------- --------AAAAAA--------- ----------------------- ----------------------- ----------------------- ----------------------- ----------------------- ----------------------- ----------------------- ----------------------- ----------------------- ----------------------- 
------AAAAAAAAAA------- -----AAAAAAAAAAAA------ ----AAAAAAAAAAAAAA----- ---AAAAAAAAAAAAAAAA---- --AAAAAAAAAAAAAAAAAA--- --AAAAAAAAAAAAAAAAAA--- --AAAAAAAAAAAAAAAAAA--- --AAAAAAAAAAAAAAAAAA--- --AAAAAAAAAAAAAAAAAA--- --AAAAAAAAAAAAAAAAAA--- --EAAAAAAAAAAAAAAAAE--- ---AAAAAAAAAAAAAAAA---- -----AAAAAAAAAAAA------ ------AAAAAAAAAA------- --------AAAAAA--------- ----------------------- ----------------------- ----------------------- ----------------------- ----------------------- ----------------------- ----------------------- ----------------------- ----------------------- ----------------------- 
------AAAAAAAAAA------- -----AAAAAAAAAAAA------ ----AAAAAAAAAAAAAA----- ---AAAAAAAAAAAAAAAA---- --AAAAAAAAAAAAAAAAAA--- --AAAAAAAAAAAAAAAAAA--- --AAAAAAAAAAAAAAAAAA--- --AAAAAAAAAAAAAAAAAA--- --EAAAAAAAAAAAAAAAAA--- --EAAAAAAAAAAAAAAAAE--- --EAAAAAAAAAAAAAAAAE--- ---AAAAAAAAAAAAAAAA---- -----AAAAAAAAAAAA------ ------AAAAAAAAAA------- --------AAAAAA--------- ----------------------- ----------------------- ----------------------- ----------------------- ----------------------- ----------------------- ----------------------- ----------------------- ----------------------- ----------------------- 
------AAAAAAAAAA------- -----AAAAAAAAAAAA------ ----AAAAAAAAAAAAAA----- ---AAAAAAAAAAAAAAAA---- --AAAAAAAAAAAAAAAAAA--- --AAAAAAAAAAAAAAAAAA--- --AAAAAAAAAAAAAAAAAA--- --AAAAAAAAAAAAAAAAAA--- --EAAAAAAAAAAAAAAAAE--- ---AAAAAAAAAAAAAAAA---- ---AAAAAAAAAAAAAAAA---- ---AAAAAAAAAAAAAAAA---- -----AAAAAAAAAAAA------ ------AAAAAAAAAA------- --------AAAAAA--------- ----------------------- ----------------------- ----------------------- ----------------------- ----------------------- ----------------------- ----------------------- ----------------------- ----------------------- ----------------------- 
------AAAAAAAAAA------- -----AAAAAAAAAAAA------ ----AAAAAAAAAAAAAA----- ----AAAAAAAAAAAAAAA---- ---AAAAAAAAAAAAAAAA---- --AAAAAAAAAAAAAAAAAA--- --AAAAAAAAAAAAAAAAAE--- --EAAAAAAAAAAAAAAAAE--- --EAAAAAAAAAAAAAAAAE--- ---AAAAAAAAAAAAAAAA---- ---AAAAAAAAAAAAAAAA---- ----AAAAAAAAAAAAAA----- -----AAAAAAAAAAAA------ ------AAAAAAAAAA------- ---------AAAA---------- ----------------------- ----------------------- ----------------------- ----------------------- ----------------------- ----------------------- ----------------------- ----------------------- ----------------------- ----------------------- 
-------AAAAAAAA-------- -----AAAAAAAAAAAA------ ----AAAAAAAAAAAAAA----- ----AAAAAAAAAAAAAA----- ---AAAAAAAAAAAAAAAA---- ---AAAAAAAAAAAAAAAAE--- --EAAAAAAAAAAAAAAAAE--- --EAAAAAAAAAAAAAAAA---- ---AAAAAAAAAAAAAAAA---- ---AAAAAAAAAAAAAAAA---- ----AAAAAAAAAAAAAAA---- ----AAAAAAAAAAAAAA----- -----AAAAAAAAAAAA------ -------AAAAAAAA-------- ----------------------- ----------------------- ----------------------- ----------------------- ----------------------- ----------------------- ----------------------- ----------------------- ----------------------- ----------------------- ----------------------- 
--------AAAAAAA-------- ------AAAAAAAAAA------- -----AAAAAAAAAAAA------ ----AAAAAAAAAAAAAA----- ----AAAAAAAAAAAAAA----- ---AAAAAAAAAAAAAAAA---- ---AAAAAAAAAAAAAAAA---- ---AAAAAAAAAAAAAAAA---- ---AAAAAAAAAAAAAAAA---- ----AAAAAAAAAAAAAAA---- ----AAAAAAAAAAAAAA----- ----AAAAAAAAAAAAAA----- ------AAAAAAAAAA------- -------AAAAAAAA-------- ----------------------- ----------------------- ----------------------- ----------------------- ----------------------- ----------------------- ----------------------- ----------------------- ----------------------- ----------------------- ----------------------- 
---------AAAA---------- -------AAAAAAAAA------- -----AAAAAAAAAAAA------ -----AAAAAAAAAAAA------ ----AAAAAAAAAAAAAA----- ----AAAAAAAAAAAAAA----- ---AAAAAAAAAAAAAAAA---- ----AAAAAAAAAAAAAA----- ----AAAAAAAAAAAAAA----- ----AAAAAAAAAAAAAA----- ----AAAAAAAAAAAAAA----- -----AAAAAAAAAAAA------ ------AAAAAAAAAA------- --------AAAAAA--------- ----------------------- ----------------------- ----------------------- ----------------------- ----------------------- ----------------------- ----------------------- ----------------------- ----------------------- ----------------------- ----------------------- 
----------------------- --------AAAAAAA-------- ------AAAAAAAAAA------- -----AAAAAAAAAAAA------ -----AAAAAAAAAAAA------ ----AAAAAAAAAAAAAA----- ----AAAAAAAAAAAAAA----- ----AAAAAAAAAAAAAA----- ----AAAAAAAAAAAAAA----- -----AAAAAAAAAAAAA----- -----AAAAAAAAAAAA------ ------AAAAAAAAAAA------ -------AAAAAAAA-------- ---------AAAA---------- ----------------------- ----------------------- ----------------------- ----------------------- ----------------------- ----------------------- ----------------------- ----------------------- ----------------------- ----------------------- ----------------------- 
----------------------- ---------AAAA---------- -------AAAAAAAA-------- ------AAAAAAAAAA------- -----AAAAAAAAAAAA------ -----AAAAAAAAAAAA------ -----AAAAAAAAAAAA------ -----AAAAAAAAAAAA------ -----AAAAAAAAAAAA------ -----AAAAAAAAAAAA------ -----AAAAAAAAAAAA------ ------AAAAAAAAAA------- -------AAAAAAAA-------- ----------AA----------- ----------------------- ----------------------- ----------------------- ----------------------- ----------------------- ----------------------- ----------------------- ----------------------- ----------------------- ----------------------- ----------------------- 
----------------------- ----------------------- --------AAAAAA--------- -------AAAAAAAA-------- ------AAAAAAAAAA------- -----AAAAAAAAAAAA------ -----AAAAAAAAAAAA------ -----AAAAAAAAAAAA------ -----AAAAAAAAAAAA------ -----AAAAAAAAAAAA------ ------AAAAAAAAAA------- -------AAAAAAAAA------- --------AAAAAA--------- ----------AA----------- ----------------------- ----------------------- ----------------------- ----------------------- ----------------------- ----------------------- ----------------------- ----------------------- ----------------------- ----------------------- ----------------------- 
----------------------- ----------------------- ----------------------- --------AAAAAA--------- -------AAAAAAAA-------- ------AAAAAAAAAA------- ------AAAAAAAAAA------- ------AAAAAAAAAA------- ------AAAAAAAAAA------- ------AAAAAAAAAA------- ------AAAAAAAAAA------- -------AAAAAAAA-------- --------AAAAAA--------- ----------AA----------- ----------------------- ----------------------- ----------------------- ----------------------- ----------------------- ----------------------- ----------------------- ----------------------- ----------------------- ----------------------- ----------------------- 
----------------------- ----------------------- ----------------------- ----------------------- --------AAAAAA--------- -------AAAAAAAA-------- -------AAAAAAAA-------- ------AAAAAAAAAA------- ------AAAAAAAAAA------- -------AAAAAAAAA------- -------AAAAAAAA-------- -------AAAAAAAA-------- --------AAAAAA--------- ----------AA----------- ----------------------- ----------------------- ----------------------- ----------------------- ----------------------- ----------------------- ----------------------- ----------------------- ----------------------- ----------------------- ----------------------- 
----------------------- ----------------------- ----------------------- ----------------------- ----------------------- ---------AAAA---------- --------AAAAAA--------- -------AAAAAAAA-------- -------AAAAAAAA-------- -------AAAAAAAA-------- -------AAAAAAAA-------- --------AAAAAA--------- ---------AAAAA--------- ----------AA----------- ----------------------- ----------------------- ----------------------- ----------------------- ----------------------- ----------------------- ----------------------- ----------------------- ----------------------- ----------------------- ----------------------- 
----------------------- ----------------------- ----------------------- ----------------------- ----------------------- ----------------------- -----------A----------- ---------AAAA---------- --------AAAAAA--------- --------AAAAAA--------- --------AAAAAA--------- --------AAAAAA--------- ---------AAAA---------- ----------------------- ----------------------- ----------------------- ----------------------- ----------------------- ----------------------- ----------------------- ----------------------- ----------------------- ----------------------- ----------------------- ----------------------- 
----------------------- ----------------------- ----------------------- ----------------------- ----------------------- ----------------------- ----------------------- ----------------------- ----------------------- ----------AA----------- ---------AAAA---------- ----------AA----------- ----------AA----------- ----------------------- ----------------------- ----------------------- ----------------------- ----------------------- ----------------------- ----------------------- ----------------------- ----------------------- ----------------------- ----------------------- ----------------------- 
