model
size = 22 31 17, scale = 0.05, origin = -y
material 
  colors = A:#111 B:#FC0 C:#693 D:#9C3 E:#6C3 F:#F63 G:#F33 H:#F90 I:#C33 J:#CC3 K:#C63 L:#FF0 M:#CC0 N:#963 O:#A00 P:#0C3 Q:#933
voxels
---------------------- ---------------------- ---------------------- ---------------------- ---------------------- ---------------------- ---------------------- ---------------------- ---------------------- ---------------------- ---------------------- ---------------------- ---------------------- ---------------------- ---------------------- ---------------------- ---------------------- ---------------------- --------BBBB---------- -------BBBBBHH-------- -------EEEEEBBBB------ ---------CCCEEEE------ ---------FFFCC-------- ---------BBBFF-------- ----------BBBB-------- ------------BB-------- ---------------------- ---------------------- ---------------------- ---------------------- ---------------------- 
---------------------- ------------A--L------ ------------A--A------ --------------------A- ------P--------------- ------A--------------- -------O-------------- -------A-------------- -------A-------------- -------A-------------- --------A------------- --------A------------- ---------------------- ---------------------- ---------------------- -------DDDDDD--------- -------CCCCCDDD------- -------NIIKNCC-------- ------BBBB--KKK------- -----BBBB-BBBBBBH----- -------DDDDDB-BBBB---- -------CCCCCDDDDD----- -------GGQGGCCCCC----- -------BBBBBQGGGG----- -------BBBBBBHHBB----- ---------EEEBBBB------ -----------CEE-------- ---------------------- ---------------------- ---------------------- ---------------------- 
-------A----L--------- -------A----A--A------ ------A----A---A------ ------A----A--AA----A- ------A----AA-A----LA- ------A-------A---AA-- -------A---------PA--- -------A---------A---- -------A--------AA---- -------A--------AO---- --------A--------A---- --------A--------A---- --------A-AA-----AA--- --------A-A---A---AA-- --------AAA----A---A-- ------DDDDDDDD-A--AA-- -----CCCCCCCCDDDDDD--- -----KKNIIKNKCCCC----- ----BHBBBBHHBKKII----- -----BBBBBBBBBBBHHH--- -----DDDDD---BBB-BB--- -----CCCC-----DDDD---- -----GGGG-----CCCC---- -----BBBBB----GGGG---- ------BBBB----HBBB---- -------EEEEEEBBBB----- -------CCCCCCEEEE----- -------------CC------- ---------------------- ---------------------- ---------------------- 
-------L-------------- -------A-------------- ----A-A----A---------- ----A-A----A--AA------ ----A------AA-A-----A- ----A-------P-A---AA-- ----A-------O-A---A--- ------------A-A--A---- -----A------A-A-AA---- -----A------A-A-A----- -----A------A-A--A---- -----A-----AA-A--A---- -----A--A-AA--A--AA--- -----A--A-A---A---AA-- ----DD--AAA----A---A-- ---CCDD--------A--AA-- ---IKCC--------DDDAD-- ---HHKK--------CCCC--- ---B-H---------IIIK--- ---DDB-----------HHH-- ---CCD-----------BBBB- ---GGC-----------DDD-- ----BG-----------CCC-- ----BB-----------GGG-- -----BB----------BB--- -----EEE---------BB--- ------CCCC-----EEE---- -------FFFFFF-CCC----- ---------BBBBFFF------ -------------B-------- ---------------------- 
-----A---------------- -----L---------------- ----A----------------- ----A----------------- ----A----------------- ----A-------A--------- ----A-------A-A------- ------------A-A------- -----A------A-A------- -----A------A-A------- -----A------A-A------- -----A-----AA-A------- -----A-AA-----A------- -----A-AA------------- ---DDA-A-------------- ---CC----------------- ---IK------------DDDD- --H-H------------CCC-- --B-B------------IKK-- ---DD------------HHHB- ---CC-------------BBB- ---GG-------------DDE- ---BB--------------CC- ---BB-------------GGF- -----B------------BB-- -----EE----------BBL-- -----CCC--------EEE--- -------FFFF-F--CCC---- --------BBBBBFFFF----- -------------BB------- ---------------------- 
-AA--A---------------- -AA--A---------------- ---------------------- --AA------------------ ---AA----------------- ---AA----------------- ---AA----------------- ---AA----------------- ---AA----------------- ---AA----------------- ---AA----------------- ---------------------- ---------------------- ---------------------- --DD-A-A-------------- --CC------------------ --II---------------DD- -BHH---------------CC- -LBB---------------KI- --DD---------------HBB --CC---------------BBB --GG---------------DE- --BB---------------CC- ---BB--------------GF- ---EE--------------BB- ----CE-------------LB- -----CC----------EEE-- -----FFFF--------CC--- -------BBB----FFFF---- ----------JJJBBBB----- -------------J-------- 
---------------------- ---------------------- --AA------------------ --AA------------------ ---------------------- ---------------------- ---------------------- ---------------------- ---------------------- ---------------------- ---AA---AA------------ --AA----AA------------ -------AA------------- -------AA------------- -DDD---A-------------- --CC------------------ --II---------------DDD -BHH---------------CCC -L-----------------KII --D----------------HBB --C-----------------BB --G-----------------E- --BB----------------C- --LB----------------F- ---EE--------------BB- ---CC--------------LB- -----C------------EEC- -----FFF---------CCC-- ------BBBB-----FFFF--- ----------JJJ-BBB----- ------------MJ-------- 
-------AA------------- -------AA------------- ---------------------- ---------------------- ---------------------- ---------------------- --------AA------------ --------AA------------ --------AA------------ --------AA------------ ---------------------- --AA------------------ --AA------------------ --AA------------------ -DD------------------- --C------------------- -II-----------------DD BB------------------CC LLB-----------------II -ED-----------------BB -CC-----------------BB -FG------------------E --B------------------C --L-----------------FF ---EE---------------B- ---CC---------------B- ----F--------------EC- -----FF------------CK- -----BBB---------FF--- -------JJJJJJ--BBBB--- ------------MJJMJ----- 
---------------------- ---------------------- -------AA------------- -------AA------------- --------AO------------ --------AA------------ ---------------------- ---------------------- ---------------------- ---------------------- ---------------------- ---------------------- ---------------------- --AA------------------ -DD------------------- --C------------------- -II------------------D BBH-----------------CC L-B-----------------II -ED-----------------BB -CC-----------------BB -FG------------------E -BB------------------C --L------------------F ---E----------------B- ---CC---------------B- ----F--------------EC- -----F-------------CK- -----BB----------FF--- -------JJJJJJ----BB--- -----------MMJJMJ----- 
-----AA--------------- -----AA--------------- ---------------------- ---------------------- ---------------------- ---------------------- ---------------------- ---------------------- ------AA-------------- -AA---AA-------------- -AA---AA-------------- --AA--AA-------------- --AA--AA-------------- --AA--AA-------------- -DD--AA--------------- --C------------------- -II------------------D BB------------------CC LLB-----------------II -ED-----------------BB -CC-----------------BB -FG------------------E --B------------------C --L-----------------FF ---E----------------B- ---CC---------------B- ----F--------------EC- -----F-------------CK- -----BB----------FF--- -------JJJJJJ---BBB--- -----------MMJJMJ----- 
--AA------------------ --AA------------------ ------AA-------------- ------AA-------------- ------AA-------------- -AA---AA-------------- -AA---AA-------------- -AA---AA-------------- -AA------------------- ---------------------- ---------------------- ---------------------- ---------------------- ---------------------- -DDD-DD--------------- --CC------------------ -III---------------DDD -B-----------------CCC LL-----------------KII -ED-----------------BB -CC-----------------BB --G-----------------EE --B-----------------CC --LB----------------F- ---EE---------------B- ---CC--------------LB- -------------------EC- -----FFF---------CCC-- -----BBBBB-----FFFF--- ----------JJJ-BBBB---- ------------MJ-------- 
--A------------------- --A------------------- --AA------------------ -OAA------------------ -AO------------------- ---------------------- ---------------------- ---------------------- ---------------------- ---------------------- ---------------------- ---------------------- ---------------------- --A------------------- -DDD------------------ --CC------------------ --II---------------DD- -BHH---------------CC- -L-B---------------KI- --D----------------HBB --C----------------BBB --GG----------------E- --BB----------------C- ---BB--------------GF- ---EE--------------BB- ---CC--------------LB- -----CC-----------EE-- -----FFFF--------CCC-- -------BBB----FFFF---- ----------JJJ-BBB----- ------------MJ-------- 
--A-AA---------------- --A-AA---------------- -A-------------------- -A-------------------- -A-------------------- -A-------A-A---------- -A-------A-A---------- --AAA----A-A---------- --AAA----A-A---------- --AAA----A-A---------- --AAA----A-A---------- --AAA---AA-A---------- --AAA----------------- --A-A----------------- --DDDA---------------- ---CC----------------- ---IK------------DDD-- --HHH------------CCC-- --BBB------------IKKI- ---DD-------------HHB- ---CC-------------BBB- ---GG--------------DE- ---BB--------------CC- ---BB--------------GF- ----B-------------BBB- -----EE-----------BL-- -----CCC---------EE--- -------FFF-----CCCC--- -------BBBBBB-FFF----- ----------JJJBBB------ ---------------------- 
----L----------------- ----A----------------- -A-AA---A--AA--------- -P-AA---A--A---------- -A-AA---AA-A-----A---- -A-AA----P-A---AA----- -A-AA----A-A---A------ --A------A-A--A------- --A------A-A-AA------- --A------A-A-A-------- --A------A-A--A------- --A-----AA-A--A------- --A--A-AA--A--AA------ -----A-A----A--AA----- --DDDAAAD---A---A----- ---CCD---------AA----- ---IKC----------DDDD-- ---HHK----------CCC--- --BBBH----------IIKK-- ---DB------------HHHB- ---CC------------BBBB- ---GG-------------DD-- ---BB-------------CC-- ----BB------------GG-- -----BB----------BBB-- -----EE----------BB--- -----CCCC-------EEE--- -------FFFFFF-CCCC---- --------BBBBBFFF------ -------------BB------- ---------------------- 
----A----A--A--------- ----A----A--A--------- ---A----A--AA--------- ---A----A--A-----A---- ---A----AA-A----LA---- ----A----------AA----- ----A---------PA------ ----A---------A------- ----A--------AA------- -------------AO------- -----A--------A------- -----A--------A------- -----A-AA--A--AA------ -----A-A----A--AA----- ---DDAAAD---A---A----- -----DDDDDDDDD-AA----- -----CCCCCCCCDDDDDD--- ----HKKNIIKNKCCCC----- ---BBHBBBB--BKKIII---- ------BBB----BBBHHH--- -----DDD------BBBBB--- -----CC--------DDDD--- -----GGG-------CCCC--- -----BBB-------GGGG--- -----BBBB------BBBB--- ------EEEEEEE-BBBB---- -------CCCCCCEEEE----- ----------FFFCCC------ -------------F-------- ---------------------- ---------------------- 
---------A--L--------- ---------A--A--------- ---------------------- ---A-------------A---- ---A------------------ ----A----------------- ----A----------------- ----A----------------- ----A----------------- ---------------------- -----A---------------- -----A---------------- ---------------------- ---------------------- -----DDD-------------- -------DDDDDDD-------- ------CCCCCCCDDD------ ------KNIIKNKCC------- -----HBBBBHHBKBII----- -----BBBBBBBBBBBHH---- ------DDDDDDDBBBBBB--- -----CCCCCC-CDDDD----- ------GGGQ---CCCC----- ------BBBBBBBGGGG----- ------BBBBBBBHHBB----- -------EEEEEBBBBB----- ---------CCCCEEE------ -------------C-------- ---------------------- ---------------------- ---------------------- 
---------------------- ---------------------- ---------------------- ---------------------- ---------------------- ---------------------- ---------------------- ---------------------- ---------------------- ---------------------- ---------------------- ---------------------- ---------------------- ---------------------- ---------------------- ----------DDDD-------- --------------D------- --------IIKNK--------- -------BBBHHBB-------- ------BBBBBBBBBB------ -------DDDDDBBBBB----- -------CCCCCCDDDD----- -------GGQGGQCCC------ -------BBBBGGGGG------ --------BBBBBHHB------ -------------BB------- ---------------------- ---------------------- ---------------------- ---------------------- ---------------------- 
