model
size = 26 16 20, scale = 0.05, origin = -y
material 
  colors = A:#562E17 B:#84492C C:#000 D:#FEEA41 E:#037C30 F:#A9523A G:#822D1B H:#94453E I:#A17A43 J:#8E695F K:#01512E L:#FFF M:#259A3E
voxels
-------------------------- -------------------------- -------------------------- -------------------------- -----C-------------------- -----C-------------------- -------------------------- -----C-------------------- -----C-------------------- -----C------AAA----------- ------------A-A----------- ------------AAA----------- -------------------------- -------------------------- -------------------------- -------------------------- 
-------------------------- -------------------------- -------------------------- -------------------------- -------------A------------ ----CACCCCCCAAA----------- ---CCCAAAAAAACAAAAAAA----- ---CCCAAAAACACAAAAAAA----- -----CCCCCCAAAAAAAAAAA---- -----CAAAAAAB-BAAAAAAA---- ------AAACAAB-AAAAAAAA---- ------CCCAAAA-A----AAA---- ------AAAAAA-------------- --------AAEE-------------- -----------E-------------- -------------------------- 
-------------------------- -------------------------- -------------------------- ----CCCCAAAAAA------------ ---CAAAAAAAAAA------------ ---CBBBBBBBBBBAAAAAAA----- --CBCBB------CBAAAAAA----- --CBCBB------CBAAAAAA----- ---CCBBDDDDDDDDAAAAAAA---- ---CCBBDDDDDD-BAAAAAAA---- ----CABBBLLLLAAAAAAAAA---- -----ABBB--BBAAAAAAAAAA--- -----CCCBBBBEAAAAAAAAA---- ------CCABEEEA--A--------- ---------KEEMA------------ -------------------------- 
-------------------------- -------------------------- -------------------------- ---CCAAAAAAAAA------------ --CBBBBBAAAAAAAAAAA------- --CBBBBBBBBBBBBAAAAAA----- ---CCCC------CBAAAAAA----- ---CCCC------CBAAAAAA----- --CFF-DDDDDDDDDAAAAAAAAA-- --CBBBBBBBBBBBBAAAAAAA---- ---CBBBBBBBBB-BBBBBAAA---- ----CBBBBBBBBBBBBBBAAAA--- -----ABBBHBBEBBBBBAAAAA--- -----AAABBEEEAAAAA-------- --------EEMCEA---A-------- -------------------------- 
--------------AAAA-------- --------------AAAA-------- --------CAAAAAAAAA-------- ---CCAAAAAAAAAAAAA-------- --CBBBBBAAAAAAAAAAA------- --CBBBBBBBBBBBBAAAAAA----- ---CCCCCCCCCCCCAAAAAA----- ---CCCCCCCCCCCCAAAAAAAAA-- --CFFFDDDDDDDDDAAAAAAAAA-- --CBBBBBBBBBBBBAAAAAAAAA-- ---CBBBBBBBBB-BBBBBHHBAA-- ----CBBBBBHBBBBBBBBBBBA--- -----ABBBB-BEBCBBBBBBBA--- -----AACBBEEEAAAAAAAAAA--- --------MKKKKA------------ -------------------------- 
---------AAAAAAAAAAAG----- -----C--CAAAAABBBBAAAA---- --------CAAAAABBBBAAAA---- ---CCACCCBBBBBBAAAAAAA---- --CBBBBBBBBBBBBAAAAAAA---- -CBBBBBBBBBBBBBAAAAAAA---- --CCCCCCCCCCCCCAAAAAAAAAA- --CCCCCCCCCCCCCAAAAAAAABA- --CFFFFDDDDDDDJAAAAAAAABA- --CBBBBBBBBBBBBAAAAAAAABA- ---CBBBBBBBBB-BBBBBHHBBAA- ----CCCCBBBBBBBBBBBBBBBAA- -----CCCBBBBEBEBBBBBBBBAA- -----CCCAKEEEAAAAAAAAAAA-- ----------EKEA------------ -------------------------- 
---------GGGGGAAAGGAG----- --------ABBBBBBBBBBBBA---- --------BBBBBBBBBBBBBA---- ---CCAAABBBBBBBAAAAAAAA--- --CBBBBBBBBBBBBAAAAAAAA--- -CBBBBBBBBBBBBBAAAAAAAA--- -CCCCCCCCCCCCCCAAAAAAAAAA- ---CCCCCCCCCCCCAAAAAAAABAA --CFFFFDDDDDDDJAAAAAAAABAA -CBBBBBBBBBBBBBAAAAAAAABAA --CCBBBBBBBBB-BBBBBHHBBBA- ----CCBBBBBBBBBBBBBBBBBBA- -----ABBBBBBBBCBBBJHHHBBA- -----AAAAAEE-AAAAAAAAAAAA- -----------E-A------------ -------------------------- 
---------AGAAAAAGAAGG----- --------CBBBBBBBBBBBBA---- --------BBBBBBBBBBBBBA---- ---CCAAABBBBBBBAAAAAAAA--- --CBBBBBBBBBBBBAAAAAAAA--- -CBBBBBBBBBBBBBAAAAAAAA--- CCCCCCCCCCCCCCCAAAAA-AAAA- -CCCCCCCCCCCCCCAAAAAAAABBA -CFFFFFFDDDDDDJAAAAAAAABBA CBBBBBBBBBBBBBBAAAAAAAABBA -CCCBBBBBBBBB-BBBBBHHBBBAA ---CCCCBBBBBBBBBBBBBBBBBAA -----ABBBBCBBBBBBJJHHHBBA- -----AAAAAAAABAAAAAAAAAAA- --------------A------C--A- -------------------------- 
---------GGAAAAAGGAAG----- --------CBBBBBBBBBBBBA---- --------CBBBBBBBBBBBBA---- ---CCCCCCBBBBBBAAAAAA-A--- --CBBBBBBBBBBBBAAAAAA-A--- -CBBBBBBBBBBBBBAAAAAAAA--- CCCCCCCCCCCCCCCAAAAA-AAAA- CFCCCCCCCCCCCCCAAAAAAAABBA -CFFFFFFDDDDDDJAAAAAAAABBA CBBBBBBBBBBBBBBAAAAAAAABBA -CCCBBBBBBBBBBBBBBBHHBBBBA ---CCCCCC-BBBBBBBBBBBBBBBA ----CBBBBBBBBDDDDJJHHHBBBA -----AAACAAAABBBBAAAABAAA- --------------BAA----C--A- --------------AAC--------- 
---------AAAAAAAAAAAA----- --------ABBBBBBBBBBBBA---- --------BBBBBBBBBBBBBA---- ---CCAAABBBBBBBAAAAAA-A--- --CBBBBBBBBBBBBAAAAAA-A--- -CBBBBBBBBBBBBBAAAAAAAA--- CCCCCCCCCCCCCCCAAAAAAAAAA- -CCCCCCCCCCCCCCAAAAAAAABBA -CFFFFFFDDDDDDJAAAAAAAABBA CBBBBBBBBBBBBBBAAAAAAAABBA -CCCBBBBBBBBBBBBBBBHHBBBBA ---CCCCCBBBBBBBBBBBBBBBBBA ----CBBBBBBBBBDBBBJHHBBBBA -----CCCACAAABBBBAAAABAAA- --------------BBA----C--A- --------------AAC--------- 
---------GAGGGAAGGGGG----- --------ABBBBBBBBBBBBA---- --------BBBBBBBBBBBBBA---- ---CCAAABBBBBBBAAAAAAAA--- --CBBBBBBBBBBBBAAAAAAAA--- -CBBBBBBBBBBBBBAAAAAAAA--- CCCCCCCCCCCCCCCAAAAA-AAAA- -CCCCCCCCCCCCCCAAAAA-AABBA -CFFFFFFDDDDDDJAAAAA-AABBA CBBBBBBBBBBBBBBAAAAA-AABBA -CCCBBBBBBBBBBBBBBBH-BBBBA ---CCCCBBBBBBBBBBBBB-BBBBA ----CBBBBBEEEBBBBBBH-AAAAA -----AAAAA-E-BAAAAAAAAAAA- -----------E--A------C--A- -------------------------- 
---------GAGAGAAGAGAA----- --------CBBBBBBBBBBBBA---- --------CBBBBBBBBBBBBA---- ---CCCCCCBBBBBBBBBBBBA---- --CBBBBBBBBBBBBBBBBBBA---- -CBBBBBBBBBBBBBBBBBBBA---- -CCCCCCCCCCCCCCCIBBB-A---- -CCCCCCCCCCCCCCCIIIIBAAAAA -CFFFFFFDDDDDDJJIIIIBAAAAA CBBBBBBBBBBBBBBBIIIIBAAAAA -CCCBBBBBBBBBBBBBBBHBBBBAA ---CCCBBBBB--BBCBBBBBBBBAA -----ABBBBEE-BBBBBBBBBBBA- -----AAABBEEEAAAAAAAAAAAA- --------EEECEA------------ -------------------------- 
---------GGGGGAAGG-------- --------ABBBBBBBBB-------- --------ABBBBBBBBBGAAA---- ----CAAAABBBBBBBBBBBBA---- --CCBBBBBBBBBBBBBBBBBA---- -CBBBBBBBBBBBBBBBBBBBA---- --CCCCCCCCCCCCCCIBBB-A---- -CCCCCCCCCCCCCCCIIIIBAAAAA -CFFFFFFDDDDDDJJIIIIBAAAAA -CBBBBBBBBBBBBBBIIIIBAAAAA --CCBBBBBBBBBBBBBBBBBBBBA- ----CBBBBBB--BBBBBBBBBBBA- -----CBBBBEEEBBBBBBBBBBBA- -----CCCKBEE-AAAAAAAAAAA-- ---------MKKMA------------ -------------------------- 
-------------------------- --------AAAAAAAAAAA------- --------ABBBBBBAAAA------- ----CAAAABBBBBBAAAAAAA---- ---CCBBBBBBBBBBAAAAAAA---- --CBBBBBBBB----AAAAAAA---- --CCCCCCCCCCCCCAAAAAAA---- -CCCCCCCCCCCCCCAAAAAAAAA-- -CFFFFFFDDDDDDDAAAAAAAAA-- --CBBBBBBBBBBBBAAAAAAAAA-- ---CBBBBBBBBBBBAAAAAAAAA-- ----CBBBBBB--BBAAAAAAAAA-- -----ABBBBEEEBBAAAAAAAAA-- -----AAACCEE-AAAAAAAAAAA-- ----------MKKA------------ -------------------------- 
-------------------------- -------------------------- --------CCAAAAAA---------- -----CCCCCBBBBAA---------- ---CCAABBBBBBBAA---------- --CBBAABBBB---AAAAAAAA---- --CCCCCCCCCCCCCAAAAAAA---- --CCCCCCCCCCCCCAAAA-AAA--- --C-FFFDDDDDDDDAAAAAAAA--- --CBBBBBBBBBBBBAAAAAAAAA-- ---CBBBBBBBBBBBAAAAAAAAA-- ----CBBBBBBB-BBAAAAAAAAA-- -----ABBAKEEEBBAAAAAAAA--- -----AAAA-EEEAAAAA-------- ----------KEEA---A-------- -------------------------- 
-------------------------- -------------------------- ---------------A---------- -------AACAAAA------------ ----C--BBBBBBB------------ ---CBAABBBB---AAAAAAAA---- ---CCCCCCCCCCCCAAAAAAA---- ---CCCCCCCCCCCCAAA----A--- --CFFFFDDDDDDDDAAAAHAAA--- --CBBBBBBBBBBBBAAAAHAAA--- ---CBBBBBBBBBAAAAAABAAAA-- ----CBBBAABBBAAAAAAAAAA--- -----CCC--EEEAA-A--------- ------CC--EEE------------- -------------------------- -------------------------- 
-------------------------- -------------------------- -------------------------- -------AAAAAAA------------ ----C--BAAAAAA------------ ----CAABAAAAAAAAAAAAAA---- ---CCCCCC----BBAAAAAAA---- ---CCCCCCCCCCCCAAA-------- ---CFFBBDDDDDDDAAAAAAA---- ---CBBBBDDDDDDBAAAAAAAA--- ---CBBBBLLLLLAAAAAAAAAA--- ----CCBBAABAAAAA---AA----- ------AA--AA-AA----------- ----------A--------------- -------------------------- -------------------------- 
-------------------------- -------------------------- -------------------------- -------------------------- ------AC------------------ ----CCBC------------------ ---CBBCAAAAA-AAA---------- ---CBBBAAAAAAAAAAAAAAA---- ---CCCCCAAAAAAAAAAAAAA---- ---CCCCCBBBBBAAAAAAAAA---- ----CCCCBBBBAAA----AAA---- -------AAAA---A----------- -------------------------- -------------------------- -------------------------- -------------------------- 
-------------------------- -------------------------- -------------------------- -------------------------- -------------------------- ------C------------------- ----CCA------------------- ----CCC-----AAAA---------- ------------A--A---------- --------CCCCA--A---------- --------CCCC-------------- --------CCC--------------- --------C----------------- -------------------------- -------------------------- -------------------------- 
-------------------------- -------------------------- -------------------------- -------------------------- -------------------------- -------------------------- ------C------------------- -------------------------- -------------------------- -------------AA----------- -------------------------- ----------C--------------- -------------------------- -------------------------- -------------------------- -------------------------- 
