model
size = 32 18 12, scale = 0.05, origin = -y
material 
  colors = A:#0F121F B:#FFF C:#EF0 D:#4100FF E:#FF8B2D F:#0063FF G:#0039FF H:#ABFF00 I:#FFD900 J:#750CFF K:#FFB12D L:#00FF48 M:#0052FF N:#FF5D2D O:#B80CFF P:#FF211F Q:#0028FF R:#00F5FF S:#00DFFF T:#00C3FF U:#890CFF V:#5E0CFF W:#008FFF X:#0078FF Y:#FFF100 Z:#C6FF00 Aa:#FFC400 Ab:#FFA42D Ac:#FF722D Ad:#1A1B26 Ae:#00FF9F Af:#FF482D Ag:#00B1FF Ah:#EA00FF Ai:#7DFF00
voxels
8-I-C-H-L-R-T-W-F-G-D13-IYCZHAiLAeRSTAgWXFMGQDV12-20A13-19A15-17A17-15A19-13A20-4AB7A21-4AB6A22-4AB5A23-2ABAB4A24-2ABAB3A24-3ABAB2A25-3ABAB26-4ABA27-4AB2(27-5A)9-E-K-I-C-H-L-R-T-W-F-G-D-J7-EAbKAaIYCZHAiLAeRSTAgWXFMGQDVJU2(6-26A)9-23A11-21A13-19A16-16A17-15A18-14A19-13A20-12A21-10A22-3A7B23-9A23-2A7B2(24-8A)5-N-E-K-I-C-H-L-R-T3-F-G-D-J-O3-NAcEAbKAaIYCZHALAeRSTAgAXFMGQDVJUO3-29A4-28A5-27A9-4A16-3A11-3A15-3A14-A14-3A15-P13-3A16-A12-3A17-E11-3A18-2A9-2A20-C3A6-2A20-4A6-2B21-L2A6-2A21-3A6-2B22-SA6-2A22-2A6-2A4-N-E-K-I-C-H9-F-G-D-J-O2-AfNAcEAbKAaIYCZH8AXFMGQDVJUOAh-30A3-29A4-16A3B9AU6-6A18-A10-4A17-A13-2(2A15-)P14-2A16-A13-2A17-E12-ABM17-2A10-2A19-C2A8-2A19-3A8-2B20-LA8-2A20-2A8-2B21-S8-2A21-A8-2A3-N-E-K-I-C-H9-F-G-D-J-O-PAfNAcEAbKAaIYCZH8AXFMGQDVJUOAh31A2-30AO3-11AB6AB9AU5-7A18-AJ8-5A17-AV11-3A16-AD14-P15-AQ15-A14-AG16-E13-AM17-2A11-AF18-C2A9-A19-3A9-B20-LA9-A20-2A9-B21-S9-AAd20-A9-2AdP-N-E-K-I-C-H-L-R-T-W-F-G-D-J-O-PAfNAcEAbKAaIYCZHAiLAeRSTAWXFMGQDVJUOAh31A2-30A4-11A8B9AU5-7A18-A9-5A17-A12-3A16-AD14-P15-A16-A14-A17-E13-AM17-2A11-A19-C2A9-A19-3A9-B20-LA9-A20-2A9-B21-S9-AAd20-A9-2AdP-N-E-K-I-C-H-L-R-T3-F-G-D-J-O-PAfNAcEAbKAaIYCZHALAeRSTAgAXFMGQDVJUOAh31A2-30AO3-11AB2AB3AB9AU5-7A18-A9-5A17-A12-3A16-AD14-P15-A16-A14-A17-E13-AM17-2A11-AF18-C2A9-A19-3A9-B20-LA9-A20-2A9-B21-S9-AAd20-A9-2AdP-N-E-K-I-C-H9-F-G-D-J-O-PAfNAcEAbKAaIYCZH8AXFMGQDVJUOAh31A2-30A4-11A3BA4B9AU5-7A17-ABJ9-4A16-ABV12-2(2A15-)P14-ABQ15-A13-ABG16-E12-ABM17-2A10-2A19-C2A8-2A19-3A8-2B20-LA8-2A20-2A8-2B21-S8-2A21-A8-2A3-N-E-K-I-C-H7-W-F-G-D-J-O-PAfNAcEAbKAaIYCZH7AWXFMGQDVJUO-31A2-30A4-28A8-5A16-3A12-2A15-3A14-A14-3A15-P13-3A16-A12-3A17-E11-3A18-2A9-2A20-C3A6-2A20-4A6-2B21-L2A6-2A21-ABA6-2B22-SA6-2A22-2A6-2A4-N-E-K-I-C-H-L-R-T-W-F-G-D-J4-AfNAcEAbKAaIYCZHALAeRSTAgWXFMGQDVJU3-29A5-27A6-26A11-21A14-12A4-2A16-10A4-2A17-9A4-2A18-14A19-12A21-11A22-10A22-3A7B23-9A23-2A7B2(24-8A)7-E-K-I-C-H-L-R-T-W-F-G-D-J6-AcEAbKAaIYCZHAiLAeRSTAgWXFMGQDVJ6-26A7-25A9-23A16-16A18-14A19-4AB8A20-4AB6A22-4AB4A24-2ABAB3A25-2ABAB2A25-3A2(BA)26-3ABAB26-4ABA27-4AB2(27-5A)11-K-I-C-H9-F-G-D11-KAaIYCZH8-XFMGQD11-7A8-6A12-5A9-2(6A26-)6A27-4A28-4A29-2A295-
