model
size = 32 18 12, scale = 0.05, origin = -y
material 
  colors = A:#0F121F B:#FFF C:#EF0 D:#0039FF E:#4100FF F:#FF8B2D G:#FFD900 H:#FFB12D I:#750CFF J:#0063FF K:#00FF48 L:#ABFF00 M:#0028FF N:#FF5D2D O:#B80CFF P:#FF211F Q:#008FFF R:#00DFFF S:#0052FF T:#5E0CFF U:#00C3FF V:#00F5FF W:#FFF100 X:#C6FF00 Y:#FFC400 Z:#890CFF Aa:#FFA42D Ab:#1A1B26 Ac:#7DFF00 Ad:#0078FF Ae:#FF722D Af:#00FF9F Ag:#00B1FF Ah:#FF482D Ai:#EA00FF
voxels
6-H-G-C-L9-J-D-E11-HYGWCXL8-AdJSDME11-7A8-6A12-5A9-2(6A26-)6A27-4A28-4A29-2A299-F-H-G-C-L-K-V-U-Q-J-D-E-I6-AeFAaHYGWCXLAcKAfVRUAgQAdJSDMETI6-26A7-25A9-23A16-16A18-14A19-4AB8A20-4AB6A22-4AB4A24-2ABAB3A25-2ABAB2A25-3A2(BA)26-3ABAB26-4ABA27-4AB2(27-5A)7-N-F-H-G-C-L-K-V-U-Q-J-D-E-I4-AhNAeFAaHYGWCXLAcKAfVRUAgQAdJSDMETIZ3-29A5-27A6-26A11-21A14-18A16-16A17-15A18-14A19-12A21-11A22-10A22-3A7B23-9A23-2A7B2(24-8A)5-N-F-H-G-C-L9-J-D-E-I-O-PAhNAeFAaHYGWCXLAc8AJSDMETIZO-31A2-30A4-17A2B9A8-5A16-3A12-2A15-3A14-A14-3A15-P13-3A16-A12-3A17-F11-3A18-2A9-2A20-C3A6-2A20-4A6-2B21-K2A6-2A21-ABA6-2B22-RA6-2A22-2A6-2A2-P-N-F-H-G-C-L11-D-E-I-O-PAhNAeFAaHYGWCXL10ASDMETIZOAi31A2-30A4-11AB6AB9A6-7A17-2AI9-4A16-2A13-2(2A15-)P14-2AM15-A13-2A17-F12-2A18-2A10-2A19-C2A8-2A19-3A8-2B20-KA8-2A20-2A8-2B21-R8-2A21-A8-2A-P-N-F-H-G-C3-K3-U-Q-J-D-E-I-O-PAhNAeFAaHYGWCXAAcKAfARUAgQAdJADMETIZOAi31A2-30A4-11A8B9AZ5-7A18-A9-5A17-A12-3A16-AE14-P15-AM15-A14-AD16-F13-AS17-2A11-A19-C2A9-A19-3A9-B20-KA9-A20-2A9-B21-R9-AAb20-A9-2AbP-N-F-H-G-C3-K-V-U-Q-J-D-E-I-O-PAhNAeFAaHYGWCXAAcKAfVAUAgQAdJADMETIZOAi31A2-30AO3-11AB6AB9A6-7A18-A9-5A17-AT11-3A16-AE14-P15-AM15-A14-AD16-F13-AS17-2A11-AJ18-C2A9-AAd18-3A9-B20-KA9-A20-2A9-B21-R9-AAb20-A9-2Ab2-N-F-H-G-C3-K-V3-Q-J-D-E-I-O-PAhNAeFAaHYGWCXAAcKAfVRAAgQAdJADMETIZOAi31A2-30A4-11A8B9AZ5-7A18-A9-5A17-A12-3A16-AE14-P15-AM15-A14-AD16-F13-AS17-2A11-A19-C2A9-A19-3A9-B20-KA9-A20-2A9-B21-R9-AAb20-A9-2Ab2-N-F-H-G-C-L11-D-E-I-O2-AhNAeFAaHYGWCXL10ASDMETIZOAi-30A3-29A4-11AB2AB3AB9A7-6A18-AI9-4A17-A13-2(2A15-)P14-2AM15-A13-2A17-F12-2A18-2A10-2A19-C2A8-2A19-3A8-2B20-KA8-2A20-2A8-2B21-R8-2A21-A8-2A3-N-F-H-G-C-L9-J-D-E-I-O3-NAeFAaHYGWCXLAc8AJSDMETIZO3-29A4-28A5-10A3BA4B9A9-4A16-3A11-3A15-3A14-A14-3A15-P13-3A16-A12-3A17-F11-3A18-2A9-2A20-C3A6-2A20-2ABA6-2B21-K2A6-2A21-3A6-2B22-RA6-2A22-2(2A6-)F-H-G-C-L-K-V-U-Q-J-D-E-I7-FAaHYGWCXLAcKAfVRUAgQAdJSDMETIZ2(6-26A)9-23A11-21A13-19A16-16A17-15A18-14A19-13A20-12A21-10A22-3A7B23-9A23-2A7B2(24-8A)11-G-C-L-K-V-U-Q-J-D-E13-GWCXLAcKAfVRUAgQAdJSDMET12-20A13-19A15-17A17-15A19-13A20-4AB7A21-4AB6A22-4AB5A23-2ABAB4A24-2ABAB3A24-3ABAB2A25-3ABAB26-4ABA27-4AB2(27-5A)5-
