model
size = 13 16 32, scale = 0.05, origin = -y
material 
  colors = A:#200F00 B:#121212 C:#FF3
voxels
5-2(4A9-)2(4B9-)4B10-2B139-2(6A7-)3(B4AB7-)2B2A2B9-2B125-2(8A5-)3(B6AB5-)2B5AB7-B2A2B8-4B110-2(10A3-)3(B8AB3-)3B6AB4-2B5AB5-7B108-2(12A-)3(B10AB-)4B7AB2-B8AB3-9B107-2(12A-)B11A2(-B10AB)-4B7AB-B7A-2AB-12B4-6B94-39AB3(11A2B)8A-2A14B-12B91-39AB3(11A2B)8A-2A27B4-6B81-39AB3(11A2B)8A-2A27B-12B78-39AB12AB2(11A2B)8A-2A27B-12B3-8B67-39AB12AB2(11A2B)8A-2A27B-12B2-10B106-11A2-B9AB-B11A2B8A-2A27B-12B2-8BCB4-8C94-11A2-B9AB-B11A2B8A-2A2B-11B-2B7-3B-3B6-3B2-2B4-B-CB4-B7C5-C6BC82-10A3-B8AB2-B10AB-B7A2(-2AB-12B-2B7-3B-3B6-3B2-2B4-B-2B4-8B5-C6BC83-9A3-2B7AB3-B9AB-2B6A)-2AB-12B-2B7-3B-3B6-3B2-2B4-B-3B3-8B5-C6BC83-9A3-2B7AB3-B9AB-2B6A-2AB-12B-2B7-3B-3B6-3B2-2B6-3B3-5B-2B5-6BAB5-C6BC70-9A3-2B7AB3-B9AB-2B6A-2AB-12B2(-2B7-3B)2-2B6-3B3-5B-2B5-8B5-C6BC70-9A3-2B7AB3-B9AB-2B6A-2AB-12B2(-2B7-3B)2-2B6-3B2-2(2B5-)6BAB5-C6BC5-8C57-9A3-2B7AB3-B9AB-2B6A-2AB-12B2(-2B7-3B)2-B7-3B2-2B6-B4-9B5-7B7-6B17-4(12A-)2B9AB-B10AB-B7A-2AB-12B-2B7-6B2(7-3B-2B)7-B4-B7-B5-7B7-6B16-52AB11A3B10A3B7A-2A17B7-6B2(7-3B-2B)2(7-B4-B)7-B5-7B8-4B4-52AB11A3B10A3B7A-2A17B7-6B2(7-3B-2B)3(7-B4-B)7-B15-52AB11A3B10A3B7A-2A17B7-6B7-3B-2B7-2B2-2B7-2B3-B7-B4-2(B7-B28-4(12A-)11AB-2B9AB-2B6AB-2B-12B2(-3B7-2B)2(2-2B7-2B)3-B7-2B3-)B7-B28-5(12A-)2B9AB-2B6AB-2B-12B2(-3B7-2B)2(2-2B7-2B)3-B7-2B3-B7-B28-5(12A-)2B9AB-2B6AB-2B-12B-3B3(7-2B2-2B)2(7-2B3-B)7-B29-5(11A2-)B9AB2-B6AB-2B2-11B2(2-2B7-2B)2-B8-2B2-2B7-2B3-2(B7-B4-)B7-B16-5(10A3-)B8AB3-B6AB-B3-10B3(3-2B7-B)4(4-B7-B)17-6(8A5-)7(8B5-)8B6-7B19-6(6A7-)7(6B7-)6B8-4B10-3B5-
