model
size = 19 32 32, scale = 0.05, origin = -y
material 
  colors = A:#200 B:#000 C:#200F00
voxels
7-2(4B15-)2(4A15-)4A16-2A509-2(6B13-)3(A4BA13-)2A2B2A15-2A489-2(8B11-)3(A6BA11-)A5B2A12-2A2BA15-4A468-2(10B9-)3(A8BA9-)A6B3A10-A5B2A12-7A465-2(12B7-)3(A10BA7-)A7B4A8-A8BA10-9A12-4A448-2(12B7-)11B2(A7-A10B)A7-A7B4A7-A2B-7BA7-12A10-6A447-3(13B6-)3(A11BA6-)A2B-8BA6-13A6-12A9-8A427-3(13B6-)3(A11BA6-)A2B-8BA2(6-13A)7-10A11-6A409-3(13B6-)3(A11BA6-)A2B-8BA2(6-13A)6-12A8-10A407-3(13B6-)12B2(A6-A11B)A6-A2B-8BA2(6-13A)6-12A8-10A10-8A389-3(13B6-)12B2(A6-A11B)A6-A2B-8BA2(6-13A)6-12A8-10A9-10A446-10BA8-A9BA7-A11BA6-A2B-8BA2(6-13A)6-12A8-10A9-10A10-8A428-10BA8-A9BA7-A11BA6-A2B-8BA6-11A-A6-3A7-2A7-3A6-3A8-2A-A4-2A9-10A10-8A428-10B9-A8B2A7-A10B2A6-A2B-7B2A2(6-13A6-3A7-2A7-3A6-3A8-2A-A4-2A9-10A10-8A428-9B10-A7BABA7-A9B3A6-A2B-6B3A)6-13A6-3A7-2A7-3A6-3A7-3A-A4-2A9-10A10-8A12-6A410-9B10-A7BABA7-A9B3A6-A2B-6B3A6-13A6-3A7-2A7-3A6-3A7-3A6-2A9-3A-6A10-AB6A11-8A147-2C16-4C14-6C12-8C9-12C5-3(16C3-)16C101-9B10-A7BABA7-A9B3A6-A2B-6B3A6-13A6-2(3A7-2A7-)3A6-2A9-3A-6A10-8A11-8A234-3(C16-C-)C15A2C3-13C84-9B10-A7BABA7-A9B3A6-A2B-6B3A6-13A6-2(3A7-2A7-)3A6-2A9-3A5-2A10-AB6A12-7A52-2A16-4A15-4A14-6A13-6A12-7A12-8A11-8A10-2(10A5-C3-)10A4-2C2-11A4-2C-12A4-2C17AC-C13A2C4-14C64-9B10-A7BA2B7-A9B3A6-A2B-6B3A6-13A6-2(3A7-2A7-)3A7-A9-2A6-2A2(9-10A)11-6A12-8A10-7(10A9-)10A5-C3-10A5-C2-11A5-C2-A10-A3-2C-2A10-A3-2C-A11-A3-2C2A11-4AC-CA13-AC3-C13-C5-4(12B7-)10B2AB6-A10B2A6-A2B-7B2A6-13A6-2(3A7-2A7-)3A2(7-2A8-2A)7-2A8-3(10A9-)10A8-12A7-A9-2A4(7-A10-A)3(4-C2-A10-A)3-2C-2A10-A3-2C-2A10-2A2-2C-A11-2A2-2C2A11-4AC-CA13-AC3-C13-C5-5(13B6-)A10B2A6-A2B-7B2A6-13A6-3A7-3A6-3A7-2A7-3A6(7-2A8-2A)8-A7-2A8-3A6-A10-2A3(6-A11-A)2(3-C2-A11-A)3(2-2C-2A11-A)2-2C-2A11-2A-2C-A13-A-2C2A13-2AC-CA13-AC3-C13-C5-5(13B6-)A10B2A6-A2B-7B2A6-13A2(6-3A7-3A)6-3A6(7-2A8-2A)8-A7-2A9-2A2(6-A11-A)5-2(2A11-A3-C-)5(2A11-A2-2C-)2A11-2A-2C-A13-A-2C2A13-2AC-CA13-AC3-C13-C5-5(13B6-)A10B2A6-A2B-7B2A6-13A2(6-3A7-3A)2(7-2A)4(8-2A7-2A)7-3A7-2A7-3A8-A6-3A9-2A2(5-2A11-A)2(3-C-2A11-A)5(2-2C-2A11-A)2-2C-2A11-2A-2C-A13-A-2C2A13-2AC-CA13-AC3-C13-C6-5(12B7-)A9B2A7-2A-A6B2A7-12A2(7-2A7-3A)2(7-2A)8-2(2A7-)4(3A7-2A7-)3A8-A6-3A9-2A2(5-2A11-A)3-C7(-2A11-A2-2C)-2A11-2A-2C-A13-A-2C2A13-2AC-CA13-AC3-C13-C6-5(12B7-)A9B2A7-2A-A6B2A7-12A7-2A2(7-3A6-3A)6(7-2A7-3A)8-A6-3A9-2A3(5-2A11-A)6(2-2C-2A11-A)2-2C-2A11-2A-2C-A13-A-2C2A13-2AC-CA13-AC3-C13-C6-5(12B7-)A9B2A6-3A-A6B2A6-13A2(6-3A7-3A)6-6(3A7-2A7-)3A8-A6-3A9-2A4(5-2A11-A)5(2-2C-2A11-A)2-2C-2A11-2A-2C-A13-A-2C2A13-2AC-CA13-AC3-C13-C6-3(12B7-)12B6-BA11B6-2A9B2A6-3A-A6B2A6-13A6-3A7-3A6-7(3A7-2A7-)3A8-A6-3A9-2A5(5-2A11-A)4(2-2C-2A11-A)2-2C-2A11-2A-2C-A13-A-2C2A13-2AC-CA13-AC3-C13-C6-3(11B8-)11B7-12B7-2A9BA7-3A-A6BA7-12A4(7-3A7-2A)7-3A7-A8-3(3A7-2A7-)3A8-A7-2A9-2A2(6-A11-A)4(5-2A11-A)3(2-2C-2A11-A)2-2C-2A11-2A-2C-A13-A-2C2A13-2AC-CA13-AC3-C13-C7-5(10B9-)A8BA9-A-A6BA9-10A3(9-A7-2A)9-A3(7-A8-3A)2(7-2A7-3A)8-A7-2A9-2A6(6-A11-A)5-2A11-A3-C2(-2A11-A2-2C)-2A11-2A-2C-A13-A-2C2A13-2AC-CA13-AC3-C13-C8-5(8B11-)A6BA8(11-8A)11-7A12-7A9-12A7-8(13A6-)13A3-C-14A2-2(2C-15A-)2C17AC2-15AC4-13C10-5(6B13-)6A7(12-7A)13-6A13-5A15-3A35-3C16-3C15-5C13-7C12-7C11-9C9-11C7-13C4-16C3-3(17C2-)17C4-13C22-
