model
size = 32 13 26, scale = 0.05, origin = -y
material 
  colors = A:#90C B:#000 C:#CF3 D:#EEE E:#E00
voxels
17-9B23-BC5BCB24-B3AC2A25-B6A26-5B272-3AC8B3-3BC13-C2BC4BA11B19-4B7A2B19-2BAB7A2B19-12B21-3BA2BABC2B22-9B24-4B3A28-A142-CAC9A20-4B2CA2B2(4A9-3B16-)CA2C9-3B17-ACB9-3B17-AC2B6-2A2B18-A2C3B2-6C19-C6B6C19-3CA2CA5C23-A2C2B2C106-AC10A20-3BEB2CA2B2A12-3C14-B2A2(12-2C15-3A)12-2A16-3A11-2D16-2BA10-3D17-B2A9-2D18-B5A3-3C2D19-6A2B3CD22-4A2B3C72-CAC9A20-C2BAEA2CB2(3A14-2C13-)B2A14-CB3(14-2A)14-2D14-A2(2B12-2D16-)2BA10-3D17-B3A6-2C2D19-AC4A2B4C22-2(CA)2B2C42-AC8A20-2(AC)AEB2C3A15-3C12-2A15-3C12-BA16-C13-BA15-2A13-BA15-2D13-B2(2A14-DB14-)3A12-2D16-2CA10-3D17-2AC2A5-4C19-2B2C6BC71-3A5E3A17-2C11-2A2(17-2C11-DB)17-2A11-DBA16-2D12-DA16-B13-BA15-DB13-B2A13-2DB14-3C12-2D16-4A7-3CB18-A2B2C6BC25-BEC2E41-3B5ECA18-AB11-2A17-2A11-B19-C11-2B17-AC11-DB17-2D2(11-DB17-2B)12-BA15-2D13-B2C13-2D15-4A9-2AB17-6A6BA23-2A3B2E40-6AEB2CA19-A-BACB5-CA2(19-B10-CB)19-2B10-B19-D2(11-2B17-2D)11-2B16-3D12-BC14-3D14-3C10-2CB17-CE2C2AB2-3BC22-CA2BE3B40-6A4CA19-4A4B3-CA19-2A9-CB30-CB19-2C9-CB19-2D9-AB19-D11-B18-2D11-2B17-2D11-2BC14-3D13-3C11-4C15-C3BC2A8C20-BC4E3C40-5A2BA2C20-4A2BC2B2-C20-2A9-C31-A21-C9-2A19-2C9-2A19-2B9-2A19-C11-2C17-2B11-2C15-3B13-3C11-C3B15-5C2A7CB20-BC4EBE41-5A2B3A20-2A7B3A20-2A9-2(A31-)A20-2(2C9-2A19-)2C9-2C18-2C11-2C16-2C13-2C12-A2CB15-CE3C9AC20-BCE2(AB)42-2(5A2B3A20-3A6B3A20-2A9-2(B31-)B21-C9-A20-2C9-2B19-2C9-2B18-2B11-2B16-2B13-BA12-A2CB15-14AC20-AE2B2AEA41-)5A2B3A20-2A7B3A20-2A9-2(A31-)A20-2(2C9-2A19-)2C9-2C18-2C11-2C16-2C13-2C12-A2CB15-CE3C9AC20-BCE2(AB)42-5A2BA2C20-4A2BC2B2-C20-2A9-C31-A21-C9-2A19-2C9-2A19-2B9-2A19-C11-2C17-2B11-2C15-3B13-3C11-C3B15-5C2A7CB20-BC4EBE41-6A4CA19-4A4B3-CA19-2A9-CB30-CB19-2C9-CB19-2D9-AB19-D11-B18-2D11-2B17-2D11-2BC14-3D13-3C11-4C15-C3BC2A8C20-BC4E3C40-6AEB2CA19-A-BACB5-CA2(19-B10-CB)19-2B10-B19-D2(11-2B17-2D)11-2B16-3D12-BC14-3D14-3C10-2CB17-CE2C2AB2-3BC22-CA2BE3B41-3B5ECA18-AB11-2A17-2A11-B19-C11-2B17-AC11-DB17-2D2(11-DB17-2B)12-BA15-2D13-B2C13-2D15-4A9-2AB17-6A6BA23-2A3B2E41-3A5E3A17-2C11-2A2(17-2C11-DB)17-2A11-DBA16-2D12-DA16-B13-BA15-DB13-B2A13-2DB14-3C12-2D16-4A7-3CB18-A2B2C6BC25-BEC2E11-AC8A20-2(AC)AEB2C3A15-3C12-2A15-3C12-BA16-C13-BA15-2A13-BA15-2D13-B2(2A14-DB14-)3A12-2D16-2CA10-3D17-2AC2A5-4C19-2B2C6BC40-CAC9A20-C2BAEA2CB2(3A14-2C13-)B2A14-CB3(14-2A)14-2D14-A2(2B12-2D16-)2BA10-3D17-B3A6-2C2D19-AC4A2B4C22-2(CA)2B2C42-AC10A20-3BEB2CA2B2A12-3C14-B2A2(12-2C15-3A)12-2A16-3A11-2D16-2BA10-3D17-B2A9-2D18-B5A3-3C2D19-6A2B3CD22-4A2B3C74-CAC9A20-4B2CA2B2(4A9-3B16-)CA2C9-3B17-ACB9-3B17-AC2B6-2A2B18-A2C3B2-6C19-C6B6C19-3CA2CA5C23-A2C2B2C111-3AC8B3-3BC13-C2BC4BA11B19-4B7A2B19-2BAB7A2B19-12B21-3BA2BABC2B22-9B24-4B3A28-A155-9B23-BC5BCB24-B3AC2A25-B6A26-5B264-
