model
size = 21 22 21, scale = 0.05, origin = -y
material 
  colors = A:#FF3 B:#111
voxels
--------------------- --------------------- --------------------- --------------------- --------------------- --------------------- --------------------- ---------AAA--------- --------AAAAA-------- -------AAAAAAA------- -------AAAAAAA------- -------AAAAAAA------- -------AAAAAAA------- --------AAAAA-------- ---------AAA--------- --------------------- --------------------- --------------------- --------------------- --------------------- --------------------- --------------------- 
--------------------- --------------------- --------------------- --------------------- --------------------- --------AAAAA-------- -------AAAAAAA------- ------AAAAAAAAA------ -----AAAAAAAAAAA----- -----AAAAAAAAAAA----- -----AAAAAAAAAAA----- -----AAAAAAAAAAA----- -----AAAAAAAAAAA----- -----AAAAAAAAAAA----- ------AAAAAAAAA------ -------AAAAAAA------- --------AAAAA-------- --------------------- --------------------- --------------------- --------------------- --------------------- 
--------------------- --------------------- --------------------- --------------------- -------AAAAAAA------- ------AAAAAAAAA------ -----AAAAAAAAAAA----- ----AAAAAAAAAAAAA---- ----AAAAAAAAAAAAA---- ----AAAAAAAAAAAAA---- ----AAAAAAAAAAAAA---- ----AAAAAAAAAAAAA---- ----AAAAAAAAAAAAA---- ----AAAAAAAAAAAAA---- ----AAAAAAAAAAAAA---- -----AAAAAAAAAAA----- ------AAAAAAAAA------ -------AAAAAAA------- --------------------- --------------------- --------------------- --------------------- 
--------------------- --------------------- --------------------- -------AAAAAAA------- -----AAAAAAAAAAA----- ----AAAAAAAAAAAAA---- ----AAAAAAAAAAAAA---- ---AAAAAAAAAAAAAAA--- ---AAAAAAAAAAAAAAA--- ---AAAAAAAAAAAAAAA--- ---AAAAAAAAAAAAAAA--- ---AAAAAAAAAAAAAAA--- ---AAAAAAAAAAAAAAA--- ---AAAAAAAAAAAAAAA--- ---AAAAAAAAAAAAAAA--- ----AAAAAAAAAAAAA---- ----AAAAAAAAAAAAA---- -----AAAAAAAAAAA----- -------AAAAAAA------- --------------------- --------------------- --------------------- 
--------------------- --------------------- -------AAAAAAA------- -----AAAAAAAAAAA----- ----AAAAAAAAAAAAA---- ---AAAAAAAAAAAAAAA--- ---AAAAAAAAAAAAAAA--- --AAAAAAAAAAAAAAAAA-- --AAAAAAAAAAAAAAAAA-- --AAAAAAAAAAAAAAAAA-- --AAAAAAAAAAAAAAAAA-- --AAAAAAAAAAAAAAAAA-- --AAAAAAAAAAAAAAAAA-- --AAAAAAAAAAAAAAAAA-- --AAAAAAAAAAAAAAAAA-- ---AAAAAAAAAAAAAAA--- ---AAAAAAAAAAAAAAA--- ----AAAAAAAAAAAAA---- -----AAAAAAAAAAA----- -------AAAAAAA------- --------------------- --------------------- 
--------------------- --------AAAAA-------- ------AAAAAAAAA------ ----AAAAAAAAAAAAA---- ---AAAAAAAAAAAAAAA--- ---AAAAAAAAAAAAAAA--- --AAAAAAAAAAAAAAAAA-- --AAAAAAAAAAAAAAAAA-- -AAAAAAAAAAAAAAAAAAA- -AAAAAAAAAAAAAAAAAAA- -AAAAAAAAAAAAAAAAAAA- -AAAAAAAAAAAAAAAAAAA- -AAAAAAAAAAAAAAAAAAA- -AAAAAAAAAAAAAAAAAAA- --AAAAAAAAAAAAAAAAA-- --AAAAAAAAAAAAAAAAA-- ---AAAAAAAAAAAAAAA--- ---AAAAAAAAAAAAAAA--- ----AAAAAAAAAAAAA---- ------AAAAAAAAA------ --------AAAAA-------- --------------------- 
--------------------- -------AAAAAAA------- -----AAAAAAAAAAA----- ----AAAAAAAAAAAAA---- ---AAAAAAAAAAAAAAA--- --AAAAAAAAAAAAAAAAA-- --AAAAAAAAAAAAAAAAA-- -AAAAAAAAAAAAAAAAAAA- -AAAAAAAAAAAAAAAAAAA- -AAAAAAAAAAAAAAAAAAA- -AAAAAAAAAAAAAAAAAAA- -AAAAAAAAAAAAAAAAAAA- -AAAAAAAAAAAAAAAAAAA- -AAAAAAAAAAAAAAAAAAA- -AAAAAAAAAAAAAAAAAAA- --AAAAAAAAAAAAAAAAA-- --AAAAAAAAAAAAAAAAA-- ---AAAAAAAAAAAAAAA--- ----AAAAAAAAAAAAA---- -----AAAAAAAAAAA----- -------AAAAAAA------- --------------------- 
---------AAA--------- ------AAAAAAAAA------ ----AAAAAAAAAAAAA---- ---AAAAAAAAAAAAAAA--- --AAAAAAAAAAAAAAAAA-- --AAAAAAAAAAAAAAAAA-- -AAAAAAAAAAAAAAAAAAA- -AAAAAAAAAAAAAAAAAAA- -AAAAAAAAAAAAAAAAAAA- AAAAAAAAAAAAAAAAAAAAA AAAAAAAAAAAAAAAAAAAAA AAAAAAAAAAAAAAAAAAAAA AAAAAAAAAAAAAAAAAAAAA -AAAAAAAAAAAAAAAAAAA- -AAAAAAAAAAAAAAAAAAA- -AAAAAAAAAAAAAAAAAAA- --AAAAAAAAAAAAAAAAA-- --AAAAAAAAAAAAAAAAA-- ---AAAAAAAAAAAAAAA--- ----AAAAAAAAAAAAA---- ------AAAAAAAAA------ ---------AAA--------- 
--------AAAAA-------- -----AAAAAAAAAAA----- ----AAAAAAAAAAAAA---- ---AAAAAAAAAAAAAAA--- --AAAAAAAAAAAAAAAAA-- -AAAAAAAAAAAAAAAAAAA- -AAAAAAAAAAAAAAAAAAA- -AAAAAAAAAAAAAAAAAAA- BAAAAAAAAAAAAAAAAAAAA BAAAAAAAAAAAAAAAAAAAA BAAAAAAAAAAAAAAAAAAAA BAAAAAAAAAAAAAAAAAAAA BAAAAAAAAAAAAAAAAAAAA BAAAAAAAAAAAAAAAAAAAA -AAAAAAAAAAAAAAAAAAA- -AAAAAAAAAAAAAAAAAAA- -AAAAAAAAAAAAAAAAAAA- --AAAAAAAAAAAAAAAAA-- ---AAAAAAAAAAAAAAA--- ----AAAAAAAAAAAAA---- -----AAAAAAAAAAA----- --------AAAAA-------- 
-------AAAAAAA------- -----AAAAAAAAAAA----- ----AAAAAAAAAAAAA---- ---AAAAAAAAAAAAAAA--- --AAAAAAAAAAAAAAAAA-- -AAAAAAAAAAAAAAAAAAA- -BAAAAAAAAAAAAAAAAAA- BAAAAAAAAAAAAAAAAAAAA BAAAAAAAAAAAAAAAAAAAA BAAAAAAAAAAAAAAAAAAAA BAAAAAAAAAAAAAAAAAAAA BAAAAAAAAAAAAAAAAAAAA BAAAAAAAAAAAAAAAAAAAA BAAAAAAAAAAAAAAAAAAAA BAAAAAAAAAAAAAAAAAAAA -BAAAAAAAAAAAAAAAAAA- -AAAAAAAAAAAAAAAAAAA- --AAAAAAAAAAAAAAAAA-- ---AAAAAAAAAAAAAAA--- ----AAAAAAAAAAAAA---- -----AAAAAAAAAAA----- -------AAAAAAA------- 
-------AAAAAAA------- -----AAAAAAAAAAA----- ----AAAAAAAAAAAAA---- ---AAAAAAAAAAAAAAA--- --BAAAAAAAAAAAAAAAA-- -BAAAAAAAAAAAAAAAAAA- -BAAAAAAAAAAAAAAAAAA- BBAAAAAAAAAAAAAAAAAAA BBAAAAAAAAAAAAAAAAAAA BBAAAAAAAAAAAAAAAAAAA BBAAAAAAAAAAAAAAAAAAA BAAAAAAAAAAAAAAAAAAAA BBAAAAAAAAAAAAAAAAAAA BBAAAAAAAAAAAAAAAAAAA BBAAAAAAAAAAAAAAAAAAA -BAAAAAAAAAAAAAAAAAA- -BAAAAAAAAAAAAAAAAAA- --BAAAAAAAAAAAAAAAA-- ---AAAAAAAAAAAAAAA--- ----AAAAAAAAAAAAA---- -----AAAAAAAAAAA----- -------AAAAAAA------- 
-------AAAAAAA------- -----AAAAAAAAAAA----- ----AAAAAAAAAAAAA---- ---AAAAAAAAAAAAAAA--- --AAAAAAAAAAAAAAAAA-- -AAAAAAAAAAAAAAAAAAA- -BAAAAAAAAAAAAAAAAAA- BAAAAAAAAAAAAAAAAAAAA BAAAAAAAAAAAAAAAAAAAA BAAAAAAAAAAAAAAAAAAAA BAAAAAAAAAAAAAAAAAAAA BAAAAAAAAAAAAAAAAAAAA BAAAAAAAAAAAAAAAAAAAA BAAAAAAAAAAAAAAAAAAAA BAAAAAAAAAAAAAAAAAAAA -BAAAAAAAAAAAAAAAAAA- -AAAAAAAAAAAAAAAAAAA- --AAAAAAAAAAAAAAAAA-- ---AAAAAAAAAAAAAAA--- ----AAAAAAAAAAAAA---- -----AAAAAAAAAAA----- -------AAAAAAA------- 
--------AAAAA-------- -----AAAAAAAAAAA----- ----AAAAAAAAAAAAA---- ---AAAAAAAAAAAAAAA--- --AAAAAAAAAAAAAAAAA-- -AAAAAAAAAAAAAAAAAAA- -AAAAAAAAAAAAAAAAAAA- -AAAAAAAAAAAAAAAAAAA- BAAAAAAAAAAAAAAAAAAAA BAAAAAAAAAAAAAAAAAAAA BAAAAAAAAAAAAAAAAAAAA BAAAAAAAAAAAAAAAAAAAA BAAAAAAAAAAAAAAAAAAAA BAAAAAAAAAAAAAAAAAAAA -AAAAAAAAAAAAAAAAAAA- -AAAAAAAAAAAAAAAAAAA- -AAAAAAAAAAAAAAAAAAA- --AAAAAAAAAAAAAAAAA-- ---AAAAAAAAAAAAAAA--- ----AAAAAAAAAAAAA---- -----AAAAAAAAAAA----- --------AAAAA-------- 
---------AAA--------- ------AAAAAAAAA------ ----AAAAAAAAAAAAA---- ---AAAAAAAAAAAAAAA--- --AAAAAAAAAAAAAAAAA-- --AAAAAAAAAAAAAAAAA-- -AAAAAAAAAAAAAAAAAAA- -AAAAAAAAAAAAAAAAAAA- -AAAAAAAAAAAAAAAAAAA- AAAAAAAAAAAAAAAAAAAAA AAAAAAAAAAAAAAAAAAAAA AAAAAAAAAAAAAAAAAAAAA AAAAAAAAAAAAAAAAAAAAA -AAAAAAAAAAAAAAAAAAA- -AAAAAAAAAAAAAAAAAAA- -AAAAAAAAAAAAAAAAAAA- --AAAAAAAAAAAAAAAAA-- --AAAAAAAAAAAAAAAAA-- ---AAAAAAAAAAAAAAA--- ----AAAAAAAAAAAAA---- ------AAAAAAAAA------ ---------AAA--------- 
--------------------- -------AAAAAAA------- -----AAAAAAAAAAA----- ----AAAAAAAAAAAAA---- ---AAAAAAAAAAAAAAA--- --AAAAAAAAAAAAAAAAA-- --AAAAAAAAAAAAAAAAA-- -AAAAAAAAAAAAAAAAAAA- -AAAAAAAAAAAAAAAAAAA- -AAAAAAAAAAAAAAAAAAA- -AAAAAAAAAAAAAAAAAAA- -AAAAAAAAAAAAAAAAAAA- -AAAAAAAAAAAAAAAAAAA- -AAAAAAAAAAAAAAAAAAA- -AAAAAAAAAAAAAAAAAAA- --AAAAAAAAAAAAAAAAA-- --AAAAAAAAAAAAAAAAA-- ---AAAAAAAAAAAAAAA--- ----AAAAAAAAAAAAA---- -----AAAAAAAAAAA----- -------AAAAAAA------- --------------------- 
--------------------- --------AAAAA-------- ------AAAAAAAAA------ ----AAAAAAAAAAAAA---- ---AAAAAAAAAAAAAAA--- ---AAAAAAAAAAAAAAA--- --AAAAAAAAAAAAAAAAA-- --AAAAAAAAAAAAAAAAA-- -AAAAAAAAAAAAAAAAAAA- -AAAAAAAAAAAAAAAAAAA- -AAAAAAAAAAAAAAAAAAA- -AAAAAAAAAAAAAAAAAAA- -AAAAAAAAAAAAAAAAAAA- -AAAAAAAAAAAAAAAAAAA- --AAAAAAAAAAAAAAAAA-- --AAAAAAAAAAAAAAAAA-- ---AAAAAAAAAAAAAAA--- ---AAAAAAAAAAAAAAA--- ----AAAAAAAAAAAAA---- ------AAAAAAAAA------ --------AAAAA-------- --------------------- 
--------------------- --------------------- -------AAAAAAA------- -----AAAAAAAAAAA----- ----AAAAAAAAAAAAA---- ---AAAAAAAAAAAAAAA--- ---AAAAAAAAAAAAAAA--- --AAAAAAAAAAAAAAAAA-- --AAAAAAAAAAAAAAAAA-- --AAAAAAAAAAAAAAAAA-- --AAAAAAAAAAAAAAAAA-- --AAAAAAAAAAAAAAAAA-- --AAAAAAAAAAAAAAAAA-- --AAAAAAAAAAAAAAAAA-- --AAAAAAAAAAAAAAAAA-- ---AAAAAAAAAAAAAAA--- ---AAAAAAAAAAAAAAA--- ----AAAAAAAAAAAAA---- -----AAAAAAAAAAA----- -------AAAAAAA------- --------------------- --------------------- 
--------------------- --------------------- --------------------- -------AAAAAAA------- -----AAAAAAAAAAA----- ----AAAAAAAAAAAAA---- ----AAAAAAAAAAAAA---- ---AAAAAAAAAAAAAAA--- ---AAAAAAAAAAAAAAA--- ---AAAAAAAAAAAAAAA--- ---AAAAAAAAAAAAAAA--- ---AAAAAAAAAAAAAAA--- ---AAAAAAAAAAAAAAA--- ---AAAAAAAAAAAAAAA--- ---AAAAAAAAAAAAAAA--- ----AAAAAAAAAAAAA---- ----AAAAAAAAAAAAA---- -----AAAAAAAAAAA----- -------AAAAAAA------- --------------------- --------------------- --------------------- 
--------------------- --------------------- --------------------- --------------------- -------AAAAAAA------- ------AAAAAAAAA------ -----AAAAAAAAAAA----- ----AAAAAAAAAAAAA---- ----AAAAAAAAAAAAA---- ----AAAAAAAAAAAAA---- ----AAAAAAAAAAAAA---- ----AAAAAAAAAAAAA---- ----AAAAAAAAAAAAA---- ----AAAAAAAAAAAAA---- ----AAAAAAAAAAAAA---- -----AAAAAAAAAAA----- ------AAAAAAAAA------ -------AAAAAAA------- --------------------- --------------------- --------------------- --------------------- 
--------------------- --------------------- --------------------- --------------------- --------------------- --------AAAAA-------- -------AAAAAAA------- ------AAAAAAAAA------ -----AAAAAAAAAAA----- -----AAAAAAAAAAA----- -----AAAAAAAAAAA----- -----AAAAAAAAAAA----- -----AAAAAAAAAAA----- -----AAAAAAAAAAA----- ------AAAAAAAAA------ -------AAAAAAA------- --------AAAAA-------- --------------------- --------------------- --------------------- --------------------- --------------------- 
--------------------- --------------------- --------------------- --------------------- --------------------- --------------------- --------------------- ---------AAA--------- --------AAAAA-------- -------AAAAAAA------- -------AAAAAAA------- -------AAAAAAA------- -------AAAAAAA------- --------AAAAA-------- ---------AAA--------- --------------------- --------------------- --------------------- --------------------- --------------------- --------------------- --------------------- 
