model
size = 23 16 10, scale = 0.05, origin = -y
material 
  colors = A:#111 B:#FF3
voxels
----------------------- ----------------------A A---------------------- ----------------------- ----------------------- ----------------------- ----------------------- ----------------------- ----------------------- ----------------------- ----------------------- ----------------------- ----------------------- ----------------------- ----------------------- ----------------------- 
----------------------A A---------------------- ----------------------- ----------------------- ----------------------- ----------------------- ----------------------- ----------------------- ----------------------- ----------------------- ----------------------- ----------------------- ----------------------- ----------------------- ----------------------- --AAAAAAAAAAAAAAAAAAA-- 
----------------------A A---------------------- ----------------------- ----------------------- ----------------------- ----------------------- ----------------------- ----------------------- ----------------------- ----------------------- ----------------------- ----------------------- ----------------------- ----------------------- ----------------------- -BAAABABBBAABBBBABABAB- 
----------------------A A---------------------- ----------------------- ----------------------- ----------------------- ----------------------- ----------------------- ----------------------- ----------------------- ----------------------- ----------------------- ----------------------- ----------------------- ----------------------- ----------------------- ABAAABABAAAABAABABBBBBA 
----------------------A A---------------------- ----------------------- ----------------------- ----------------------- ----------------------- ----------------------- ----------------------- ----------------------- A---------------------A B---------------------B B---------------------B B---------------------B B---------------------B A---------------------A ABABABABAAAABAABABBABBA 
----------------------- ----------------------A A---------------------A A---------------------A A---------------------A A---------------------A A---------------------A A---------------------A A---------------------A A---------------------A A---------------------A A---------------------A A---------------------A A---------------------A A---------------------A ABABABABBBAABAABABAAABA 
----------------------- ----------------------- ----------------------- ----------------------- ----------------------- ----------------------- ----------------------- ----------------------- ----------------------- ----------------------- ----------------------- ----------------------- ----------------------- ----------------------- A---------------------A ABBABBABAAAABAABABAAABA 
----------------------- ----------------------- ----------------------- ----------------------- ----------------------- ----------------------- ----------------------- ----------------------- ----------------------- ----------------------- ----------------------- ----------------------- ----------------------- ----------------------- ----------------------- ABBABBABAAAABAABABAAABA 
----------------------- ----------------------- ----------------------- ----------------------- ----------------------- ----------------------- ----------------------- ----------------------- ----------------------- ----------------------- ----------------------- ----------------------- ----------------------- ----------------------- ----------------------- -BAAABABBBAABBBBABAAAB- 
----------------------- ----------------------- ----------------------- ----------------------- ----------------------- ----------------------- ----------------------- ----------------------- ----------------------- ----------------------- ----------------------- ----------------------- ----------------------- ----------------------- ----------------------- --AAAAAAAAAAAAAAAAAAA-- 
