model
size = 31 31 4, scale = 0.05, origin = -y
material 
  colors = A:#081818
voxels
-----A----------------------AA- -----AAA------------------AAAA- -----AA-AA--------------AAA-A-- ------A--AA-----------AAA--AA-- ------A---AA--------AA-----A--- -------A----AA-----AA-----AA--- -------A-----AA--AA------AA---- -------AA-----AAAA-------A----- --------A-------A-------AA----- --------A---------------A------ --------AA-------------A------- -------AA-------------AA------- ------AA---------------AA------ -----AA-----------------AA----- ----AA-------------------AA---- ---AA---------------------AA--- --AA----AA-----------------AA-- AA---AAAAA----------A--------AA AAAAAA---A---------AAAAAAAAAAAA ---------A---------A----------- ----------A-------AA----------- ----------A-------A------------ ----------A------A------------- ----------AA----AA------------- -----------A----A-------------- -----------A---A--------------- -----------A---A--------------- ------------A-A---------------- ------------A-A---------------- ------------AA----------------- -------------A----------------- 
-----A----------------------AA- -----AAA------------------AAAA- -----AA-AA--------------AAA-A-- ------A--AA-----------AAA--AA-- ------A---AA--------AA-----A--- -------A----AA-----AA-----AA--- -------A-----AA--AA------AA---- -------AA-----AAAA-------A----- --------A-------A-------AA----- --------A---------------A------ --------AA-------------A------- -------AA-------------AA------- ------AA---------------AA------ -----AA-----------------AA----- ----AA-------------------AA---- ---AA---------------------AA--- --AA----AA-----------------AA-- AA---AAAAA----------A--------AA AAAAAA---A---------AAAAAAAAAAAA ---------A---------A----------- ----------A-------AA----------- ----------A-------A------------ ----------A------A------------- ----------AA----AA------------- -----------A----A-------------- -----------A---A--------------- -----------A---A--------------- ------------A-A---------------- ------------A-A---------------- ------------AA----------------- -------------A----------------- 
-----A----------------------AA- -----AAA------------------AAAA- -----AA-AA--------------AAA-A-- ------A--AA-----------AAA--AA-- ------A---AA--------AA-----A--- -------A----AA-----AA-----AA--- -------A-----AA--AA------AA---- -------AA-----AAAA-------A----- --------A-------A-------AA----- --------A---------------A------ --------AA-------------A------- -------AA-------------AA------- ------AA---------------AA------ -----AA-----------------AA----- ----AA-------------------AA---- ---AA---------------------AA--- --AA----AA-----------------AA-- AA---AAAAA----------A--------AA AAAAAA---A---------AAAAAAAAAAAA ---------A---------A----------- ----------A-------AA----------- ----------A-------A------------ ----------A------A------------- ----------AA----AA------------- -----------A----A-------------- -----------A---A--------------- -----------A---A--------------- ------------A-A---------------- ------------A-A---------------- ------------AA----------------- -------------A----------------- 
-----A----------------------AA- -----AAA------------------AAAA- -----AA-AA--------------AAA-A-- ------A--AA-----------AAA--AA-- ------A---AA--------AA-----A--- -------A----AA-----AA-----AA--- -------A-----AA--AA------AA---- -------AA-----AAAA-------A----- --------A-------A-------AA----- --------A---------------A------ --------AA-------------A------- -------AA-------------AA------- ------AA---------------AA------ -----AA-----------------AA----- ----AA-------------------AA---- ---AA---------------------AA--- --AA----AA-----------------AA-- AA---AAAAA----------A--------AA AAAAAA---A---------AAAAAAAAAAAA ---------A---------A----------- ----------A-------AA----------- ----------A-------A------------ ----------A------A------------- ----------AA----AA------------- -----------A----A-------------- -----------A---A--------------- -----------A---A--------------- ------------A-A---------------- ------------A-A---------------- ------------AA----------------- -------------A----------------- 
