model
size = 31 31 4, scale = 0.05, origin = -y
material 
  colors = A:#092A2E B:#152629 C:#0B2320 D:#0A2326
voxels
--------CCAAA--------AAAA------ ---------BCCAC-----CCACC------- ----------BBCBB--CCCCCC-------- ------------DDCBBBDBB---------- ---------ABBDADACCBBBB--------- -------ADBDAAABDDBCCABA-------- ------BBABBABADCADBBCCABA------ -----BABBAAAADBCDDDBBBDBAAA---- ---AABAAA--ADDBCBDABBABDBBAA--- --AACAA---AADABCABDABB-AABDA--- --BCAA---AADAABCBAADABA--ACCA-- -AAA----AACDA-ACAA-DDABA---ACA- AA------AACAA-BCBA-BDDBA-----AA -------AACAA-AACAAAAADAA------- ------AAAAAA-BBCAAA-ABDBA------ ------AACBB--ABCBBA-ABDDAA----- -----AAAABA--AACAAA--ABDAA----- -----AAAAB---BBABAA---BACA----- -----ACAB----ABCAA-----ACAB---- -----AAA-----BBCAA------ACA---- ----ACB------ABCAA------AAA---- ----AA-------BBAAA-------AAA--- ----A--------AACAA--------CA--- --------------ACA----------C--- --------------ACA-------------- --------------AAA-------------- --------------AAA-------------- ---------------A--------------- ---------------A--------------- ---------------A--------------- ---------------A--------------- 
--------CCAAA--------AAAA------ ---------BCCAC-----CCACC------- ----------BBCBB--CCCCCC-------- ------------DDCBBBDBB---------- ---------ABBDADACCBBBB--------- -------ADBDAAABDDBCCABA-------- ------BBABBABADCADBBCCABA------ -----BABBAAAADBCDDDBBBDBAAA---- ---AABAAA--ADDBCBDABBABDBBAA--- --AACAA---AADABCABDABB-AABDA--- --BCAA---AADAABCBAADABA--ACCA-- -AAA----AACDA-ACAA-DDABA---ACA- AA------AACAA-BCBA-BDDBA-----AA -------AACAA-AACAAAAADAA------- ------AAAAAA-BBCAAA-ABDBA------ ------AACBB--ABCBBA-ABDDAA----- -----AAAABA--AACAAA--ABDAA----- -----AAAAB---BBABAA---BACA----- -----ACAB----ABCAA-----ACAB---- -----AAA-----BBCAA------ACA---- ----ACB------ABCAA------AAA---- ----AA-------BBAAA-------AAA--- ----A--------AACAA--------CA--- --------------ACA----------C--- --------------ACA-------------- --------------AAA-------------- --------------AAA-------------- ---------------A--------------- ---------------A--------------- ---------------A--------------- ---------------A--------------- 
--------CCAAA--------AAAA------ ---------BCCAC-----CCACC------- ----------BBCBB--CCCCCC-------- ------------DDCBBBDBB---------- ---------ABBDADACCBBBB--------- -------ADBDAAABDDBCCABA-------- ------BBABBABADCADBBCCABA------ -----BABBAAAADBCDDDBBBDBAAA---- ---AABAAA--ADDBCBDABBABDBBAA--- --AACAA---AADABCABDABB-AABDA--- --BCAA---AADAABCBAADABA--ACCA-- -AAA----AACDA-ACAA-DDABA---ACA- AA------AACAA-BCBA-BDDBA-----AA -------AACAA-AACAAAAADAA------- ------AAAAAA-BBCAAA-ABDBA------ ------AACBB--ABCBBA-ABDDAA----- -----AAAABA--AACAAA--ABDAA----- -----AAAAB---BBABAA---BACA----- -----ACAB----ABCAA-----ACAB---- -----AAA-----BBCAA------ACA---- ----ACB------ABCAA------AAA---- ----AA-------BBAAA-------AAA--- ----A--------AACAA--------CA--- --------------ACA----------C--- --------------ACA-------------- --------------AAA-------------- --------------AAA-------------- ---------------A--------------- ---------------A--------------- ---------------A--------------- ---------------A--------------- 
--------CCAAA--------AAAA------ ---------BCCAC-----CCACC------- ----------BBCBB--CCCCCC-------- ------------DDCBBBDBB---------- ---------ABBDADACCBBBB--------- -------ADBDAAABDDBCCABA-------- ------BBABBABADCADBBCCABA------ -----BABBAAAADBCDDDBBBDBAAA---- ---AABAAA--ADDBCBDABBABDBBAA--- --AACAA---AADABCABDABB-AABDA--- --BCAA---AADAABCBAADABA--ACCA-- -AAA----AACDA-ACAA-DDABA---ACA- AA------AACAA-BCBA-BDDBA-----AA -------AACAA-AACAAAAADAA------- ------AAAAAA-BBCAAA-ABDBA------ ------AACBB--ABCBBA-ABDDAA----- -----AAAABA--AACAAA--ABDAA----- -----AAAAB---BBABAA---BACA----- -----ACAB----ABCAA-----ACAB---- -----AAA-----BBCAA------ACA---- ----ACB------ABCAA------AAA---- ----AA-------BBAAA-------AAA--- ----A--------AACAA--------CA--- --------------ACA----------C--- --------------ACA-------------- --------------AAA-------------- --------------AAA-------------- ---------------A--------------- ---------------A--------------- ---------------A--------------- ---------------A--------------- 
