model
size = 27 31 4, scale = 0.05, origin = -y
material 
  colors = A:#0B3235 B:#0A262F
voxels
AAAAABBB-BBBBBBBBBBBBBBA--- -----BA--AB--BA-----BBA---- -----B---AB--BA-----BA----- -----B---AB--BA-----BA----- -----B---AB--BA-----AA----- -----B---AB--BA-----AA----- ----BB---AB--AA-----AA----- ----AB---AB--AA------AA---- ----A----AA--AA------AA---- ----B----A----AA-----AA---- ----B----B----AA------A---- AAAAAAA--B-----A------AA--- AA----A--B-----A-------A--- AA----A-AA-----AA------B--- AA----A-B------AA---BBBBBBA -AA--AA-A------AA---BB----A -AA--A-AA-------A---BB----A --A-AA-BA-------A---AB----A --AAA--B--------A---AA---AA -------A---------A---AA--A- -------A---------B----AAA-- -------B---------B--------- -------B-----ABBBBBBBA----- ---ABBBBBBAA-AA-B-A-AA----- ---A--AA-A-A-AA-B-A--A----- ---A--A---AA-AA---A--A----- ---AA-----A---A-----A------ ----A-----A---A----AA------ ----AA---AA---AA--AA------- -----A--AA-----AAAA-------- ------AAA------------------ 
AAAAABBB-BBBBBBBBBBBBBBA--- -----BA--AB--BA-----BBA---- -----B---AB--BA-----BA----- -----B---AB--BA-----BA----- -----B---AB--BA-----AA----- -----B---AB--BA-----AA----- ----BB---AB--AA-----AA----- ----AB---AB--AA------AA---- ----A----AA--AA------AA---- ----B----A----AA-----AA---- ----B----B----AA------A---- AAAAAAA--B-----A------AA--- AA----A--B-----A-------A--- AA----A-AA-----AA------B--- AA----A-B------AA---BBBBBBA -AA--AA-A------AA---BB----A -AA--A-AA-------A---BB----A --A-AA-BA-------A---AB----A --AAA--B--------A---AA---AA -------A---------A---AA--A- -------A---------B----AAA-- -------B---------B--------- -------B-----ABBBBBBBA----- ---ABBBBBBAA-AA-B-A-AA----- ---A--AA-A-A-AA-B-A--A----- ---A--A---AA-AA---A--A----- ---AA-----A---A-----A------ ----A-----A---A----AA------ ----AA---AA---AA--AA------- -----A--AA-----AAAA-------- ------AAA------------------ 
AAAAABBB-BBBBBBBBBBBBBBA--- -----BA--AB--BA-----BBA---- -----B---AB--BA-----BA----- -----B---AB--BA-----BA----- -----B---AB--BA-----AA----- -----B---AB--BA-----AA----- ----BB---AB--AA-----AA----- ----AB---AB--AA------AA---- ----A----AA--AA------AA---- ----B----A----AA-----AA---- ----B----B----AA------A---- AAAAAAA--B-----A------AA--- AA----A--B-----A-------A--- AA----A-AA-----AA------B--- AA----A-B------AA---BBBBBBA -AA--AA-A------AA---BB----A -AA--A-AA-------A---BB----A --A-AA-BA-------A---AB----A --AAA--B--------A---AA---AA -------A---------A---AA--A- -------A---------B----AAA-- -------B---------B--------- -------B-----ABBBBBBBA----- ---ABBBBBBAA-AA-B-A-AA----- ---A--AA-A-A-AA-B-A--A----- ---A--A---AA-AA---A--A----- ---AA-----A---A-----A------ ----A-----A---A----AA------ ----AA---AA---AA--AA------- -----A--AA-----AAAA-------- ------AAA------------------ 
AAAAABBB-BBBBBBBBBBBBBBA--- -----BA--AB--BA-----BBA---- -----B---AB--BA-----BA----- -----B---AB--BA-----BA----- -----B---AB--BA-----AA----- -----B---AB--BA-----AA----- ----BB---AB--AA-----AA----- ----AB---AB--AA------AA---- ----A----AA--AA------AA---- ----B----A----AA-----AA---- ----B----B----AA------A---- AAAAAAA--B-----A------AA--- AA----A--B-----A-------A--- AA----A-AA-----AA------B--- AA----A-B------AA---BBBBBBA -AA--AA-A------AA---BB----A -AA--A-AA-------A---BB----A --A-AA-BA-------A---AB----A --AAA--B--------A---AA---AA -------A---------A---AA--A- -------A---------B----AAA-- -------B---------B--------- -------B-----ABBBBBBBA----- ---ABBBBBBAA-AA-B-A-AA----- ---A--AA-A-A-AA-B-A--A----- ---A--A---AA-AA---A--A----- ---AA-----A---A-----A------ ----A-----A---A----AA------ ----AA---AA---AA--AA------- -----A--AA-----AAAA-------- ------AAA------------------ 
