model
size = 32 30 3, scale = 0.05, origin = -y
material 
  colors = A:#0A2326 B:#080818 C:#0D313B
voxels
29-A3-2A6-2A22-2A6-A19-A4-2ACAC2AB10A9-C4-3(A-)2B6-2C8A8-3(B-)2B4-3C12A5-13B15A11-B30-2B64-B21-2A8-B5-A7-2(A8-)B4-2A7-A2-2A4-A7-BA4-A2-A4-2A2-2A4-A7-B5-A2-A4-A3-3A3-A7-A4-2A2-A4-A2-2A-A3-2A5-2(2A3-)A4-A2-2(A3-)A5-3(A4-)A2-A3-2A2-7A3-2A4-A-4A2-A2-3A2-2A4-A2-2A5-3A2(2-A)-2A5-A3-2A2-A6-2A2-A2-4A6-2(A3-A2-2A7-A2-A3-2A7-)A2-2A3-A7-A2-A3-3A6-2A-A4-2A6-A2-A3-A-2A6-A-A5-2A5-3A4-A2-2A5-A-A6-2A5-2A4-A3-2A4-3A8-2A3-2A4-A2-2A5-2A10-A3-2A3-5A6-2A15-A3-A35-A3-2A6-2A22-2A6-A19-A4-2ACAC2AB10A9-C4-3(A-)2B6-2C8A8-3(B-)2B4-3C12A5-13B15A11-B30-2B64-B21-2A8-B5-A7-2(A8-)B4-2A7-A2-2A4-A7-BA4-A2-A4-2A2-2A4-A7-B5-A2-A4-A3-3A3-A7-A4-2A2-A4-A2-2A-A3-2A5-2(2A3-)A4-A2-2(A3-)A5-3(A4-)A2-A3-2A2-7A3-2A4-A-4A2-A2-3A2-2A4-A2-2A5-3A2(2-A)-2A5-A3-2A2-A6-2A2-A2-4A6-2(A3-A2-2A7-A2-A3-2A7-)A2-2A3-A7-A2-A3-3A6-2A-A4-2A6-A2-A3-A-2A6-A-A5-2A5-3A4-A2-2A5-A-A6-2A5-2A4-A3-2A4-3A8-2A3-2A4-A2-2A5-2A10-A3-2A3-5A6-2A15-A3-A35-A3-2A6-2A22-2A6-A19-A4-2ACAC2AB10A9-C4-3(A-)2B6-2C8A8-3(B-)2B4-3C12A5-13B15A11-B30-2B64-B21-2A8-B5-A7-2(A8-)B4-2A7-A2-2A4-A7-BA4-A2-A4-2A2-2A4-A7-B5-A2-A4-A3-3A3-A7-A4-2A2-A4-A2-2A-A3-2A5-2(2A3-)A4-A2-2(A3-)A5-3(A4-)A2-A3-2A2-7A3-2A4-A-4A2-A2-3A2-2A4-A2-2A5-3A2(2-A)-2A5-A3-2A2-A6-2A2-A2-4A6-2(A3-A2-2A7-A2-A3-2A7-)A2-2A3-A7-A2-A3-3A6-2A-A4-2A6-A2-A3-A-2A6-A-A5-2A5-3A4-A2-2A5-A-A6-2A5-2A4-A3-2A4-3A8-2A3-2A4-A2-2A5-2A10-A3-2A3-5A6-2A15-A3-A6-
