model
size = 31 32 3, scale = 0.05, origin = -y
material 
  colors = A:#0F3129 B:#182818 C:#080818
voxels
8-2CB4-5A20-CA3-2A4B2A9-9AC5A2B2C2B5A5-A6-A-CB2-10A2-4A2-A6-A-CB18-2(A-)7ACB2A5-14A-A6-C4B2A-2A2B2A8-3A6-C2A4BA3BA-A17-2A-2A2BAB2A2-A17-2(A-)3A2-A-5A14-BA-A4-A3-5A8-A2-A-2BA-A4-A2-2A-4A-A5-2A-4A2-A4-A2-A3-5A5-2(A-)A2-A6-2(A2-)2A3BA5-A-7A5-A-2A2-A4B6-A2-2AC2A2-3A2(-A)2-2ABACBA5-A2-A2C5A-B3A3-2A-A2CA5-A2-ABCA-AC2BA-BA3-2A-ACBA6-A-2ACA7-BA2-2A3-2C7-3A-B2A6-2(A3-)3A8-2A-BA-A4-A3-7A10-2AB3A3B4C6B2A12-BA3B9A3-2A12-BA-A2(2-2A)5-2A12-2B2A4-3A6-2A12-AB12-5A12-ABA10-A2-2A14-AB10-2A2B16-3B2-3A3-A2BA17-A2B2(-A)2-A2BA19-A2B4A2B2A22-4A2BA19-2CB4-5A20-CA3-2A4B2A9-9AC5A2B2C2B5A5-A6-A-CB2-10A2-4A2-A6-A-CB18-2(A-)7ACB2A5-14A-A6-C4B2A-2A2B2A8-3A6-C2A4BA3BA-A17-2A-2A2BAB2A2-A17-2(A-)3A2-A-5A14-BA-A4-A3-5A8-A2-A-2BA-A4-A2-2A-4A-A5-2A-4A2-A4-A2-A3-5A5-2(A-)A2-A6-2(A2-)2A3BA5-A-7A5-A-2A2-A4B6-A2-2AC2A2-3A2(-A)2-2ABACBA5-A2-A2C5A-B3A3-2A-A2CA5-A2-ABCA-AC2BA-BA3-2A-ACBA6-A-2ACA7-BA2-2A3-2C7-3A-B2A6-2(A3-)3A8-2A-BA-A4-A3-7A10-2AB3A3B4C6B2A12-BA3B9A3-2A12-BA-A2(2-2A)5-2A12-2B2A4-3A6-2A12-AB12-5A12-ABA10-A2-2A14-AB10-2A2B16-3B2-3A3-A2BA17-A2B2(-A)2-A2BA19-A2B4A2B2A22-4A2BA19-2CB4-5A20-CA3-2A4B2A9-9AC5A2B2C2B5A5-A6-A-CB2-10A3-3A2-A6-A-CB18-2(A-)7ACB2A5-14A-A6-C4B2A-2A2B2A8-3A6-C2A4BA3BA-A17-2A-2A2BAB2A2-A17-2(A-)3A2-A-5A14-BA-A4-A3-5A8-A2-A-2BA-A4-A2-2A-4A-A5-2A-4A2-A4-A2-A3-5A5-2(A-)A2-A6-2(A2-)2A3BA5-A-7A5-A-2A2-A4B6-A2-2AC2A2-3A2(-A)2-2ABACBA5-A2-A2C5A-B3A3-2A-A2CA5-A2-ABCA-AC2BA-BA3-2A-ACBA6-A-2ACA7-BA2-2A3-2C7-3A-B2A6-2(A3-)3A8-2A-BA-A4-A3-7A10-2AB3A3B4C6B2A12-BA3B9A3-2A12-BA-A2(2-2A)5-2A12-2B2A4-3A6-2A12-AB12-5A12-ABA10-A2-2A14-AB10-2A2B16-3B2-3A3-A2BA17-A2B2(-A)2-A2BA19-A2B4A2B2A22-4A2BA11-
