model
size = 32, scale = 0.05, origin = -y
material 
  colors = A:#FFE000 B:#9CF C:#FF009E D:#00BEDD E:#111 F:#FFF
voxels
22A3E2C6-19A3E2A4C4-17A3E4A5C4-23A6C3-23A3(7C25A)7C12A4F9A7C12AF2EF9A7C-11AF2EF9A6C2-11A4F9A5C3-24A4C5-23A2C7-22A10-19A13-16A16-12A20-11D22-10D22-9D23-9D3(24-8D)25-7D25-6D26-6D3(27-5D)28-3D22-22A3E2C6-24A4C4-24A5C4-28AC3-29A2(C3A28B)C2(3A22B7C)3A10B12A7C-2A10B12A6C2-2A10B12A5C3-2A10B12A4C5-A10B12A2C7-A10B11A10-A10B8A13-A5B10A16-A5B6A20-11D22-10D22-9D23-9D2(24-8D)24-3D-4D25-7D25-6D26-6D3(27-5D)28-3D22-22A3E2C6-24A4C4-24A5C4-28AC3-29A2(C3A28B)C2(3A22B7C)3A10B12A7C-2A10B12A6C2-2A10B12A5C3-2A10B12A4C5-A10B12A2C7-A10B11A10-A10B8A13-A5B10A16-A5B6A20-11D4(22-10D22-9D23-9D3(24-8D)25-7D25-6D26-6D3(27-5D)28-3D22-22A3E2C6-24A4C4-24A5C4-28AC3-29A2(C3A28B)C2(3A22B7C)3A10B12A7C-2A10B12A6C2-2A10B12A5C3-2A10B12A4C5-A10B12A2C7-A10B11A10-A10B8A13-A5B10A16-A5B6A20-D7B3D)22-10D22-9D23-9D3(24-8D)25-7D25-6D26-6D3(27-5D)28-3D22-22A3E2C6-24A4C4-24A2C2-C2(4-28AC3-29A2(C3A28B)C2(3A22B7C)3A10B12A7C-2A10B12A6C2-2A10B12A5C3-2A10B12A4C5-A10B12A2C7-A10B11A10-A10B8A13-A5B10A16-A5B6A20-11D22-10D22-9D23-9D3(24-8D)25-7D25-6D26-6D3(27-5D)28-3D22-22A3E2C6-24A4C4-24A5C)5(4-28AC3-29A2(C3A28B)C2(3A22B7C)3A10B12A7C-2A10B12A6C2-2A10B12A5C3-2A10B12A4C5-A10B12A2C7-A10B11A10-A10B8A13-A5B10A16-12A466-22A3E2C6-24A4C4-24A5C)9(4-26A3C3-26A4C2(3A28BC)2(3A22B7C)3A10B12A7C-2A10B12A6C2-2A10B12A5C3-2A10B12A4C5-A10B12A2C7-A10B11A10-A10B8A13-A5B10A16-12A466-22A3E2C6-24A4C4-24A5C)4-26A3C3-26A4C2(2A29BC)2(2A23B7C)2A11B12A7C-A11B12A6C2-A11B12A5C3-2A10B12A4C5-A10B12A2C7-A10B11A10-A10B8A13-A5B10A16-12A466-4(22A3E2C6-24A4C4-24A5C4-26A3C3-26A4C2(2A29BC)2(2A23B7C)2A11B12A7C-A11B12A6C2-A11B12A5C3-2A10B12A4C5-A10B12A2C7-A10B11A10-A10B8A13-A5B10A16-A5B6A20-11D22-10D22-9D23-9D3(24-8D)25-7D25-6D26-6D3(27-5D)28-3D22-)2(22A3E2C6-24A4C4-24A5C4-23A6C3-26A4C2(2A29BC)2(2A23B7C)2A11B12A7C-A11B12A6C2-A11B12A5C3-2A10B12A4C5-A10B12A2C7-A10B11A10-A10B8A13-A5B10A16-A5B6A20-11D22-10D22-9D23-9D3(24-8D)25-7D25-6D26-6D3(27-5D)28-3D22-)22A3E2C6-24A4C4-24A5C4-23A6C3-26A4C2(2A29BC)2(2A23B7C)2A11B12A7C-A11B12A6C2-A11B12A5C3-2A10B12A4C5-A10B12A2C7-A10B11A10-A10B8A13-A10B5A16-A10BA20-11D22-10D22-9D23-9D3(24-8D)25-7D25-6D26-6D3(27-5D)28-3D22-22A3E2C6-19A3E2A4C4-17A3E4A5C4-23A6C3-23A3(7C25A)7C12A4F9A7C12AF2EF9A7C-11AF2EF9A6C2-11A4F9A5C3-24A4C5-23A2C7-22A10-19A13-16A16-12A20-11D22-10D22-9D23-9D3(24-8D)25-7D25-6D26-6D3(27-5D)28-3D22-
