model
size = 32, scale = 0.05, origin = -y
material 
  colors = A:#F3F B:#111 C:#AAA
voxels
12-5(8B24-)A6BA24-2A4B2A2(24-3A2B3A)6(24-8B)2(24-8A)6(24-8B)2(24-3A2B3A)24-2A4B2A24-A6BA4(24-8B)53-9(14A18-)2(6(14B18-)2(14A18-))5(14A18-)14A23-3A22-9(18A14-)2(6(18B14-)2(18A14-))5(18A14-)18A18-3A3-3A18-9(20A12-)2(6(20B12-)2(20A12-))5(20A12-)20A14-4A7-3A15-9(22A10-)2(6(22B10-)2(22A10-))5(22A10-)22A12-2A13-3A11-9(24A8-)2(6(24B8-)2(24A8-))5(24A8-)24A10-2A16-2A9-9(26A6-)2(6(26B6-)2(26A6-))5(26A6-)26A8-2A18-2A7-9(28A4-)2(6(28B4-)2(28A4-))5(28A4-)28A6-2A20-2A6-9(28A4-)2(6(28B4-)2(28A4-))5(28A4-)28A5-2A22-A5-9(30A2-)2(6(30B2-)2(30A2-))5(30A2-)30A4-A23-2A4-30(30A2-)30A3-A10-5C10-A4-30(30A2-)30A3-A10-C3-C11-A2-992A-2A10-C3-C11-A2-992A-A11-5C11-2A-992A-A11-5C12-A-993A12-5C13-994A12-5C13-993A2(-A11-5C12-A-992A)-2A26-A3-30(30A2-)30A3-A25-2A3-30(30A2-)30A3-2A9-5C10-A4-9(30A2-)2(6(30B2-)2(30A2-))5(30A2-)30A4-A23-2A5-9(28A4-)2(6(28B4-)2(28A4-))5(28A4-)28A5-2A22-A6-9(28A4-)2(6(28B4-)2(28A4-))5(28A4-)28A6-2A20-2A7-9(26A6-)2(6(26B6-)2(26A6-))5(26A6-)26A8-2A17-3A9-9(24A8-)2(6(24B8-)2(24A8-))5(24A8-)24A10-2A16-2A11-9(22A10-)2(6(22B10-)2(22A10-))5(22A10-)22A12-2A13-3A13-9(20A12-)2(6(20B12-)2(20A12-))5(20A12-)20A14-14A17-9(18A14-)2(6(18B14-)2(18A14-))5(18A14-)18A18-9A21-9(14A18-)2(6(14B18-)2(14A18-))5(14A18-)14A23-3A27-5(8B24-)A6BA24-2A4B2A2(24-3A2B3A)6(24-8B)2(24-8A)6(24-8B)2(24-3A2B3A)24-2A4B2A24-A6BA4(24-8B)44-
