model
size = 13 32 10, scale = 0.05, origin = -y
material 
  colors = A:#0C3501 B:#012808 C:#001900 D:#000 E:#03034D F:#008 G:#081600 H:#091B08 I:#20261C J:#34696B K:#424286 L:#6D0000 M:#743600 N:#669 O:#63C P:#309 Q:#030 R:#0B0 S:#080
voxels
27-2D-2G-2D-2G15-2G-2D-2G-2D15-3(IH-)IH15-2J-2K-2M-2L300-14B9(11A2B)6(11-2B)11AB-11B183-2B3(CAB)C2B11A2C24A2B11AC13AC11A2B11A2C24A2B11DCADQDFO2FNFJDA2(CD)EF2EFEFD2BDSDFOFNPJKD2CDRD7EDBA11D2B11DC-CB2C2(BAC)B183-BCA3(B2A)BC12A2(B11AB26A)2(B11AB13AC12A)B11ABC25A-2(2AB)ACBAC183-2(BA)CBACB2A2B12AB13AB11A2C11A2(B13AB11A2(C12AB)11AC12A)B-BACBCABACBA183-2B2(2AB)CABC2B25AC11A2B11A2C24A2B24A2C11A2B12AC11AC12A2B11AC25A2B11AB-CBACBCAB2AB183-BAC3(B2A)B12ACB11AB26AB11ABC24ACB11AB12AC13AB11ABC11AC13AB11AB12ABC12A-2(2AB)ACBCA183-2(BC)ABCABAC2BC11AB13AB11AC12AB13AB11A2C11AB13A2(B24ABC12A)B11AC12A3B2(CAB)2ABC-14(2B11-)2B2(CAB)2ABC2B11AC13AC11A2B12AC11AC12A2B11A2C24A2B24A2C11A2B11AC13AC11A2B11ACBA2BCBCAB2CB-14(2B11-)14BCBC2BACBAC3BACBC2BACBAC3B2(2ABA2B)CBACB2ABCA3B2ABACBCAB2A3BCAB2ABCABC2BCB2AB2CBCA3BACBAC2BABCA3BACB2ABCABC2BCBCABACB2A3BACBCABACBCA3B2ABCABACBC2BCBAC2(B2A)3B2(2AB)CABAC3BCAB2ABCABA2BC3(BCA)2B-11B183-
