model
size = 30 32 25, scale = 0.05, origin = -y
material 
  colors = A:#FFFB96 B:#FFF C:#F44800 D:#CBDBFC E:#9BADB7 F:#847E87
voxels
2-8(9A8-9A4-)9A8-9A5-8A8-8A7-7A8-7A9-6A8-6A606-5(11A6-11A2-)11A6-11A3-15(10A6-10A4-)10A6-10A5-9A6-9A7-2(7A8-)6A10-6A9-4A12-4A185-13A3(4-26A)4-13A-4(12A4-12A2-)11(28A2-)28A3-4(26A4-)12A3E11A6-9AE3-E8A9-7AE-2E-E7A11-5A2E-E2-2E5A18-2(E-)2E24-E-E2-E20-14A38-4A6-4A2-4A6-8A6-4A2-4A6-18A2-25A3(2CA2-AC8A2C13A)2(2C4AC8A2C13A)2C4A2C7A2C18(4A11C)2A-4(A11C4A11CA2-)A3F8C4A8C3FA2-A3-A7C4A7CA3-A2-A3-2A16C2A3-A6-2A5CD4AD5C2A2(10-20A)11-18A12-18A13-16A16-12A9-3A8-3A2-3A8-6A8-3A2-3A8-7A2(6-10A)4-A3C2A2C2A4-3A2(C13A3C2A2C9A)C13A7C9AC13A3C2B2C9AC13A3C2B3C8AC13(4A12C2B12C)3A3F10C2B10C3F2A3-A9C2B9CA3-2A3-3A7C2D7C3A3-A4-3A5C6D5C3A8-3A5C6D5C3A9-2(2A5C6D5C2A10-)2A16C2A11-18A14-14A2(8-3A)2-3A8-4ABA8-3A2-3A8-AB2ABA7-10A7-A2(B2A)6-A2BC2ACB2A6-2(2AB)3A5-A2BC2ACB2A5-3AB2AB4A4-A3B2A2B2A4-4AB2AB4A4-A7B2A4-4ABEAB5A3-A7B2A3-5AB2AB9A8B9AB2A2(8B2C)8B12(2A28B)2AF26BF2A-2A22B2(2A-)5A5C6D5C5A-A2-5A5C6D5C5A5-4A5C6D5C4A7-3A5C6D5C3A9-2A5C6D5C2A10-2A16C2A10-20A12-16A7-2A9-3A2-3A9-4A9-3A2-3A9-5A7-10A7-2AEAB2A6-A2B4CB2A6-2ABEAB3A5-A3B2C2B2A5-3ABEAB4A4-A3B2C2B2A4-4ABEAB4A4-A7B2A4-4AB2AB5A3-A7B2A3-5AB2AB9A8B9AB2A2(8B2C)8B13(2A28B)3A26B9A5C6D5C7A-6A5C6D5C6A3-5A5C6D5C5A5-4A5C6D5C4A7-3A5C6D5C3A8-3A16C3A8-2A2CF12E3C2A10-3A-A-3A3-2A-3A6-2A9-3A2-3A9-4A9-3A2-3A9-AE3A7-10A7-4AB2A6-A2B4C2BA6-2(2AB)3A5-A3B2C3BA5-3AB7A4-A3B2C3B2(A4-12A4-A8B)A4-12A2-3A8B3A2-11AB19F14(10A20B)10A7C6D7C5A-4A7C6D7C4A2-4A7C6D7C4A3-3A7C6D7C3A5-2A7C6D7C2A7-A20CA8-2A2C13EB2C2A9-3A5-3A-8A5-2A9-3A2-3A9-4A9-3A2-3A9-5A7-10A7-4AB2A6-A2B4C2BA6-2ABEAB3A5-A3B2C3BA5-3AB6A5-A3B2C3B2(A5-10A5-A8B)A5-10A4-2A8B2A4-10A20F14(10A20B)10A7C6D7C5A-4A7C6D7C4A2-4A7C6D7C4A3-3A7C6D7C3A4-3A7C6D7C3A5-2A20C2A6-3A2C13EB2C3A8-4A-A-4A-3A-4A5-2A9-3A2-3A9-4A9-3A2-3A9-5A7-10A7-2AE4A6-A2B4C2BA6-5AB2A6-A3B2C3BA6-2ABE4A6-A3B2C3B3(A6-8A6-A8B)A6-8A22F9A14(20B10A)7C6D7C5A-4A7C6D7C4A2-4A7C6D7C4A3-3A7C6D7C3A4-3A7C6D7C3A5-2A20C2A6-3A-C13EB2C3A7-4A5-2(3A-)5A4-2E9-3A2-3A9-2A2E9-3A2-3A9-A4E7-10A7-3A4E6-A2B4C2BA6-4A4E6-A3B2C3BA6-ACBA4E6-A3B2C3BA6-A2B5E6-A8BA6-A2BA4E2(6-A8BA6-8E)22F14(8E22B)8E22D4E-3E8B6D8B3E2-3E8B6D8B3E3-2E8B6D8B2E4-2E8B6D8B2E5-EB19C2BE6-3A2CB12EB2C3A7-5A-A-3A2-3A-5A4-2A9-3A2-3A9-4A9-3A2-3A9-5A7-10A7-2AE4A6-A2B4C2BA6-5ABCA6-A3B2C3BA6-ACBE4A6-A3B2C3B3(A6-8A6-A8B)A6-8A22F14(8A22B)8A22D4A-3A8B6D8B3A2-3A8B6D8B3A3-2A8B6D8B2A4-2A8B6D8B2A5-AB19C2BA6-3A-CB12EB2C3A7-12A-3A-5A4-2A9-3A2-3A9-4A9-3A2-3A9-5A7-10A7-7A6-A2B4C2BA6-3AEABCA6-A3B2C3BA6-ACB5A6-A3B2C3B3(A6-8A6-A8B)A6-8A22F14(8A22B)8A22D4A-3A8B6D8B3A2-3A8B6D8B3A3-2A8B6D8B2A4-2A8B6D8B2A5-AB19C2BA6-3A-17C3A7-22A4-2A9-3A2-3A9-4A9-3A2-3A9-5A7-10A7-2AE4A6-A2B4C2BA6-5ABCA6-A3B2C3BA6-ACBE4A6-A3B2C3B3(A6-8A6-A8B)A6-8A22F13(8A22B)8A8B-13B8A8D-13D4A-3A8B-5D8B3A2-3A8B-5D8B3A3-2A8B-5D8B2A4-2A8B6D8B2A5-AB19C2BA6-3AC16EC3A7-5A6-A5-A-3A4-2E9-3A2-3A9-2A2E9-3A2-3A9-A4E7-10A7-3A4E6-A2B4C2BA6-3A5E6-A3B2C3BA6-ACBA4E6-A3B2C3BA6-A2B5E6-A8BA6-A2BA4E2(6-A8BA6-8E)22F14(8E22B)8E22D4E-3E8B6D8B3E2-3E8B6D8B3E3-2E8B6D8B2E4-2E8B6D8B2E5-EB19C2BE6-3AC16EC3A7-4A2(2-A)3-2A2-A-3A4-2A9-3A2-3A9-4A9-3A2-3A9-5A7-10A7-7A6-A2B4C2BA6-5ABCA6-A3B2C3BA6-ACB2ABCA6-A3B2C3BA6-A2B5A6-A8BA6-9A5-A8BA5-10A4-2A8B2A4-9AB20FB14(8A22B)8A22D4A-3A8B6D8B3A2-3A8B6D8B3A3-2A8B6D8B2A4-2A8B6D8B2A5-AB19C2BA6-3AC16EC3A7-4A-A2-2(A-)2A3-A-3A4-2A9-3A2-3A9-4A9-3A2-3A9-5A7-10A7-7A6-A2B4C2BA6-3AEABCA6-A3B2C3BA6-ACB2A2BA6-A3B2C3BA6-A2BE4A6-A8BA6-9A5-A8BA5-11A2-3A8B3A2-10A2B18F2B14(8A22B)8A22D4A-3A8B6D8B3A2-3A8B6D8B3A3-2A8B6D8B2A4-2A8B6D8B2A5-AB19C2BA6-3AC16EC3A7-4A2(-A)3-A-2A-A2-3A4-2(2A9-3A2-3A9-AE)3A7-10A7-2AE4A6-A2B4C2BA6-5ABCA6-A3B2C3BA6-ACBEABCA6-A3B2C3BA6-A2B5A6-A8BA6-9A5-A8BA5-16A8B15A5B2C8B2C5B14(8A22B)8A22D4A-3A8B6D8B3A2-3A8B6D8B3A3-2A8B6D8B2A4-2A8B6D8B2A5-AB19C2BA6-3AC16EC3A7-3A2(2-A)-A-2A3-A-3A4-2A9-3A2-3A9-4A9-3A2-3A9-5A7-10A7-7A6-A2BC3A2BA6-5ABCA6-A2BC3A2BA6-ACB2ABCA6-A2BC3A2BA6-A2B5A6-A2BC3A2BA6-9A5-A2BC3A2BA5-16A2B4C2B15A5B2C2B4C2B2C5B14(8A9B4C9B)4A-3A9D4C9D3A2-3A8BD4CD8B3A2-3A8B6D8B3A3-2A8B6D8B2A4-2A8B6D8B2A5-AB19C2BA6-3AC16EC3A7-3A-2A3-A3-2A-A2-3A4-2A9-3A2-3A9-4A9-3A2-3A9-5A7-10A7-7A6-A2BC3A2BA6-5ABCA6-A2BC3A2BA6-ACB2ABCA6-A2BC3A2BA6-A2B5A6-A2BC3A2BA6-9A5-A2BC3A2BA5-16A2B4C2B15A5B2C2B4C2B2C5B13(8A9B4C9B)4A-3A9B4C9B3A2-3A9D4C9D3A2-3A8BD4CD8B3A3-2(2A8B6D8B2A4-)2A8B6D8B2A5-AB19C2BA6-3AC16EC3A7-3A8-A6-4A4-2A9-3A2-3A9-4A9-3A2-3A9-5A7-10A7-7A3(6-AC6ACA6-8A)6-AC6ACA6-9A5-AC6ACA5-16AC6AC15A12(8C6A8C8A)8B6A8B4A-3A8B6A8B3A2-3A9B4C9B3A2-3A9D4C9D3A3-2A8BD4CD2(8B2A4-2A8B6D)8B2A5-A8B6D8BA6-AB19C2BA6-24A8-20A6-2(2A8-3A2-3A8-2A2-)2A7-4A2-4A7-2A2-3A6-AC2A2-2ACA6-3A3(2-10AC2A2-2AC10A)2-10AC6AC10A2-A-8AC6AC10A3(2-A-A8C6A9C2A)2(2-A-9C6A9C2A)-3A13(9C6A)9C3A-2(2AC8B6A8BC2A2-)2AC9B4C9BC2A3-3A8D4C8D3A4-3A7BD4CD7B3A4-3A7B6D7B3A5-4A5B6D7B2A6-4A5B6D7B2A7-3A5B6D7BA8-22A10-18A8-2(2A7-3A2-3A7-2A4-)3A5-4A2-4A5-3A2(4-12A2-12A)2(4-3A3-6A2-6A3-3A)4-12A2-12A4-26A4(4-A-24A)3-9(28A2-)2A9C6A9C2A3-A2C20A2CA2(4-26A)5-24A6-24A7-22A9-20A10-20A38-9(10A4-10A6-)2(24A6-)A-22A5-10(26A4-)3A7E6A7E3A4-26A5-24A7-22A9-20A11-18A14-14A403-7A6-7A9-9A4-9A7-8(10A4-10A6-)10A4-10A7-8A6-8A304-
