model
size = 25 32 30, scale = 0.05, origin = -y
material 
  colors = A:#9BADB7 B:#FFF C:#F44800 D:#CBDBFC E:#000 F:#FFFB96 G:#847E87
voxels
2-15AE3A6-5A2(E2AE3A)6-4AE2A2(EA)2(E3A)6-4AEAE3A2(EA)E4A7-3AE2A2(EA)2(E3A)7-3(3AE)AE4A7-2AE15A7(7-7AE3AE6A)7-3(7AE3AE7A6-)7A4(E3AE7A7-6A)E3AE6A8-6AE3AE5A9-6AE3AE4A10-6A2(E3A)183-21A4-2A3B16A4-5A12B4A4-5A4B2(F3B)4A4-5A12B4A4-5AB3F8B4A5-3A2B3F5B7(7A5-8AE3AE)6(8A4-8AE3AE)2(8A5-7AE3AE)8A5-A2G4AE3AE8A5-A2-4AE3AE7A6-A2-4AE3AE6A10-4AE3AE5A12-2(3AE)4A131-2(6A15-2A2-)23A4(2-3A2B18A)2(2-23A)3(3-9AE3AE8A)3-9(9AE3AE9A2-)9AE3AE9A3-A2G2(5AE3AE9A3-A2-)5AE3AE8A7-5AE3AE8A8-4AE3AE7A10-2(3AE)6A12-2AE3AE5A80-2(4A18-2A-)5A17-2A4(-3A2B19A)2(-24A)-10A3(E3AE9A2-9A)9(E3AE10A-9A)E3AE9A2-2A2G2(5AE3AE9A3-A2-)5AE3AE9A6-5AE3AE8A7-5AE3AE8A8-4AE3AE8A9-2(3AE)7A11-2AE3AE6A12-13A29-2(3A20-A-)4A18-2A-5A17-2A3(-9A12-3A)2(-9A6-9A)-3A2C2B2F6G3B6A-3A2C2B3F8B6A2-2A2C2B3F8B7A4(-2A2C2B3F10BCAF2A)5(-2A2C2B3F11BAB2A)-2A2C2B3F10B5A-2AGC2B3F10B4A2-2A-4A2F10B4A2-2A-4ABFD3BD5B4A3-A-4ABF11B3A5-4ABF11B2A7-3A2(BF11B2A8-2A)BF11BA9-3A5BF5B2A12-11A5-2(3A20-A-)4A19-A-5A17-2A-5A16-3A-2(8A13-2(A-))8A13-3A-8A8-8A-2AB2C2B9G2B6A-2AB2C13B9AB2C13B7A4(-AB2C15B2CF2A)5(-AB2C18B2A)-AB2C19BA-AB2C18BE2-AB5A15BA2-AB5ABC9D4BA2-7ABC12B2A3-6ABC12B2A4-5A2(BC12BA6-4A)BC12BA7-4A10FB3A9-14A4-2(3A20-A-)4A19-A-4A18-2A-5A16-3A-2(5A16-2(A-))7A14-3A-7A10-7A-2AB2C2B10GB6A-2AB2C13B9AB2C13B7A5(-AB2C15B2CF2A)4(-AB2C15B2CB2A)-AB2C19BA-AB2C18BE2-AB2C18BA2-A2B3F3C12DBA2-3A2(3F3C12B2A3-2A)3F3C12B2A4-A3F3C12BA5-A3F14CBA6-5A11C3A8-16A3-2(3A20-A-)4A19-A-4A18-2A-5A16-3A-2(5A16-2(A-))5A16-3A-7A10-7A-2AB2C2B10GB6A-2AB2C13B9AB2C13B7A5(-AB2C15B2CF2A)4(-AB2C15B2CB2A)-AB2C19BA-AB2C18BE2-AB2C18BA2-AB7C12DBA2-3A2(6C12B2A3-2A)6C12B2A4-A6C12BA5-A17CBA5-6A4C7E3A7-8A6-3A3-2(3A20-A-)4A19-A-4A18-2A4(-5A16-3A)-8A8-8A-2AB2C2B10GB6A-2AB2C13B9AB2C13B7A5(-AB2C15B2CF2A)4(-AB2C15B2CB2A)-AB2C19BA-AB2C18BE2-AB2C18BA2-AB7C12DBA2-3A2(6C12B2A3-2A)2(6C12B2A4-A)17CBA4-2A2BCGBG2BC7E3A6-12A-A2-2A3-2(3A20-A-)4A19-A-4A18-2A4(-5A16-3A)-9A6-9A-2AB4C10GC6A-2AB2C13B9AB2C13B7A9(-AB2C15B2CF2A)-AB2C17BFBA-AB2C17BCE2-AB2C17BFA2-AB7C12DFA3(3-2A6C12B2A)4-A6C12B2A4-A17CBA4-2A2B6GC7E3A5-3A-A4-A3-2(A-)2A3-2(4A19-A-)3(24A-)3AB20A3(-3A2B19A)-3A4C10GC6A-3A2C13B10A2C13B7A9(-2A2C15B2CF2A)-2A2C17BFBA-2A2C17BCE2-2A2C17BFA3-A7C12DFA3(3-2A6C12B2A)4-A6C12B2A4-A17CBA4-2A2B6GC7E3A5-10A7-2A4-3(23A2-)5A12B5(6A2-2A15B)6A2-2A2C2B10GB6A2-2(2A2C13B7A-)9(2A2C15B2CF2A-)2A2C17BFBA-2A2C17BCE3-A2C17BFA3-A7C12DFA3(3-2A6C12B2A)4-A6C12B2A4-A17CBA4-2A2B6GC7E3A5-10A3(-A)-2A5-3(22A3-)4A12B5(6A3-A15B)6A3-A2C2B10GB2(6A3-A2C13B)7A9(2-A2C15B5A)2-2(A2C15B4A3-)A2C17BFA3-A2C17DFA4(3-EA18D2A)3-EA17CDA4-2A2B6GC7E3A5-3A-6A-5A-2A6-3(20A5-)3A12B4(5A5-2A13B)5A4-A15B5A4-AFC2B10GB3(6A3-AFC13B)11(2C4A3-AFC13B)4CFA3-E2C13D4CFA4-A14D4C2(2A4-A18D)2A3-EA18D2A4-A17CDA4-2A2B6GC7E3A5-3A6-A2-A-A2-2A57-17A8-2A12B2(3A8-A13B)2(3A7-2A13B)4A5-A15B5A4-AF3B10GB3(6A3-AF14B)11(2C4A3-AF14B)4CFA3-EC14D4CFA4-A14D4C2A3-E3(A18D2A4-)A17CDA4-2A2B6GC7E3A5-2(3A-)3A2-A2-3A57-17A8-2A12B2(3A8-A13B)2(3A7-2A13B)4A5-A15B5A4-AF3B10GB3(6A3-AF14B)11(2C4A3-AF14B)4CFA3-EC14D4CFA4-A14D4C3(2A3-EA18D)2A3-EA17CDA4-2A2B6GC7E3A5-10A2-A-A2-2A6-3(20A5-)3A12B4(5A5-2A13B)5A4-A15B5A4-AFC2B10GB3(6A3-AFC13B)11(2C4A3-AFC13B)4CFA3-A2C13D4CFA3-EA14D4C3(2A4-A18D)2A4-A17CDA4-2A2B6GC7E3A5-10A-A3-A-2A5-3(22A3-)4A12B5(6A3-A15B)6A3-A2C2B10GB2(6A3-A2C13B)7A9(2-A2C15B5A)2-2(A2C15B4A3-)A2C8B-8BFA3-A2C8D-8DFA3-2A3(9D-8D2A3-EA)18D2A3-EA17CDA4-2A2B6GC7E3A5-4A-A-3A2-A-A2-2A4-3(23A2-)5A12B5(6A2-2A15B)6A2-2A2C2B10GB6A2-2(2A2C13B7A-)9(2A2C15B2CF2A-)2A2C17BFBA-2A2C17BCE3-A2C17BFA3-A7C12DFA3(3-2A6C12B2A)4-A6C12B2A4-A17CBA4-2A2B6GC7E2(3A5-)2A3-A3-2A3-2(4A19-A-)3(24A-)3AB20A3(-3A2B19A)-3A4C10GC6A-3A2C13B10A2C13B7A9(-2A2C15B2CF2A)-2A2C17BFBA-2A2C17BCE2-2A2C17BFA3-A7C12DFA3(3-2A6C12B2A)4-A6C12B2A4-A17CBA4-2A2B6GC7E3A5-4A-A-3A-A5-2A3-2(3A20-A-)4A19-A-4A18-2A4(-5A16-3A)-9A6-9A-2AB4C10GC6A-2AB2C13B9AB2C13B7A9(-AB2C15B2CF2A)-AB2C17BFBA-AB2C17BCE2-AB2C17BFA2-AB7C12DFA3(3-2A6C12B2A)4-A6C12B2A4-A17CBA4-2A2B6GC7E2(3A5-)2A2-4A-2A3-2(3A20-A-)4A19-A-4A18-2A4(-5A16-3A)-8A8-8A-2AB2C2B10GB6A-2AB2C13B9AB2C13B7A5(-AB2C15B2CF2A)4(-AB2C15B2CB2A)-AB2C19BA-AB2C18BE2-AB2C18BA2-AB7C12DBA2-3A2(6C12B2A3-2A)2(6C12B2A4-A)17CBA4-2A2B2GBG2BC7E3A6-3A-A-4A4-A-2A3-2(3A20-A-)4A19-A-4A18-2A-5A16-3A-2(5A16-2(A-))5A16-3A-7A10-7A-2AB2C2B10GB6A-2AB2C13B9AB2C13B7A5(-AB2C15B2CF2A)4(-AB2C15B2CB2A)-AB2C19BA-AB2C18BE2-AB2C18BA2-AB7C12DBA2-3A2(6C12B2A3-2A)6C12B2A4-A6C12BA5-A17CBA5-6A4C7E3A7-12A3-2A3-2(3A20-A-)4A19-A-4A18-2A-5A16-3A-2(5A16-2(A-))7A14-3A-7A10-7A-2AB2C2B10GB6A-2AB2C13B9AB2C13B7A5(-AB2C15B2CF2A)4(-AB2C15B2CB2A)-AB2C19BA-AB2C18BE2-AB2C18BA2-A2B3F3C12DBA2-3A2(3F3C12B2A3-2A)3F3C11BF2A4-A3F3C11BFA5-A3F14CFA6-5A-C2-7C3A8-16A3-2(3A20-A-)4A19-A-5A17-2A-5A16-3A-2(8A13-2(A-))8A13-3A-8A8-8A-2AB2C3B8G2B6A-2AB2C13B9AB2C13B7A4(-AB2C15B2CF2A)5(-AB2C18B2A)-AB2C19BA-AB2C18BE2-AB5A15BA2-AB5ABC9D4BA2-7ABC12B2A3-6ABC12B2A4-5A2(BC12BA6-4A)B10C3BA7-4A10FB3A9-14A4-2(3A20-A-)4A18-2A-5A17-2A3(-9A12-3A)2(-9A6-9A)-3A2C2B2F6G3B6A-3A2C2B3F8B6A2-2A2C2B3F8B5A-A4(-2A2C2B3F10BCAF2A)5(-2A2C2B3F11BAB2A)-2A2C2B3F10B5A-2AGC2B3F10B4A2-2A-4A2F10B4A2-2A-4ABFD3BD5B4A3-A-4ABF11B3A5-4ABF11B2A7-3A2(BF11B2A8-2A)BF11BA9-3A5BF5B2A12-11A5-2(4A18-2A-)5A17-2A4(-3A2B19A)2(-24A)-10A3(E3AE7A-A2-9A)E3AE7A-2A8(-9AE3AE10A)-9AE3AE9A2-2A2G2(5AE3AE9A3-A2-)5AE3AE9A6-5AE3AE8A7-5AE3AE8A8-4AE3AE8A9-2(3AE)7A11-2AE3AE6A12-13A29-2(6A15-2A2-)23A4(2-3A2B18A)2-23A2-21A4(-A3-9AE3AE6A)-2A2-9AE3AE6A-2A8(2-9AE3AE9A)3-A2G2(5AE3AE9A3-A2-)5AE3AE8A7-5AE3AE8A8-4AE3AE7A10-2(3AE)6A12-2AE3AE5A81-21A4-2A3B16A4-5A12B2(4A4-5A4B2(E3B))4A4-5AB3F2(E3B)4A5-3A2B3FE4B7(7A5-8AE3AE)6(8A4-8AE3AE)2(8A5-7AE3AE)8A5-A2G4AE3AE8A5-A2-4AE3AE7A6-A2-4AE3AE6A10-4AE3AE5A12-2(3AE)4A133-3(8AE3AE6A6-)8A11(E3AE6A7-7A)3(E3AE7A6-7A)4(E3AE7A7-6A)E3AE6A8-6AE3AE5A9-6AE3AE4A10-6A2(E3A)182-
