model
size = 25 32 30, scale = 0.05, origin = -y
material 
  colors = A:#000 B:#FFF C:#F44800 D:#CBDBFC E:#FFFB96 F:#847E87
voxels
2-15AB3A6-5A2(B2AB3A)6-4AB2A2(BA)2(B3A)6-4ABAB3A2(BA)B4A7-3AB2A2(BA)2(B3A)7-3(3AB)AB4A7-2AB15A7(7-7AB3AB6A)7-3(7AB3AB7A6-)7A4(B3AB7A7-6A)B3AB6A8-6AB3AB5A9-6AB3AB4A10-6A2(B3A)183-21A3(4-2A2B17A)4-2A2B2A11B4A4-2A2B2A3EB3A4B4A5-A2B2A3E7(B3AB7A5-8A)6(B3AB8A4-8A)2(B3AB8A5-7A)B3AB8A5-A2F4AB3AB8A5-A2-4AB3AB7A6-A2-4AB3AB6A10-4AB3AB5A12-2(3AB)4A131-2(6A15-2A2-)2(23A2-)7A3B5C3B5A2-7A3EB3A4B5A2-7A3E2(B3AB8A2-10A)4(B3AB8A3-9A)9(B3AB9A2-9A)B3AB9A3-A2F2(5AB3AB9A3-A2-)5AB3AB8A7-5AB3AB8A8-4AB3AB7A10-2(3AB)6A12-2AB3AB5A80-2(4A18-2A-)5A17-2A-24A3(-7A2B15A)2(-24A)-10A3(B3AB9A2-9A)9(B3AB10A-9A)B3AB9A2-2A2F2(5AB3AB9A3-A2-)5AB3AB9A6-5AB3AB8A7-5AB3AB8A8-4AB3AB8A9-2(3AB)7A11-2AB3AB6A12-13A29-2(3A20-A-)4A18-2A-5A17-2A-9A3(12-3A-7ABA)6-9A-7ABA6-A2B6A-3A2C2B2E6F3B6A-3A2C2B3E8B6A2-11(2A2C2B3E8B7A-)2AFC2B3E8B6A2-2A-A2B3E8B6A2-2A-4ABE2(D3B)6A3-A-4ABE8B6A5-4ABE8B5A7-3A2(BE8B5A8-2A)BE8B4A9-10A2B4A12-11A5-2(3A20-A-)4A19-A-5A17-2A-5A16-3A-2(8A13-2(A-))8A13-3A-8A8-8A-3A2C2B9F4BC3A-3A2C15BC7A5(2C15BC4A-2A)6(2C16B4A-2A)2C16B2AB2-3AC16B3A2-7ABC9D2B3A2-7ABC11B3A3-6ABC11B3A4-5A2(BC11B2A6-4A)BC11B2A7-11A3E2B2A9-14A4-2(3A20-A-)4A19-A-4A18-2A-5A16-3A-2(5A16-2(A-))7A14-3A-7A10-7A-3A2C2B10F3BC3A-3A2C15BC7A10(2C15BC4A-2A)2C16B4A-2A2C16B2AB2-2A2C16B3A2-2AB3E3C11D3A2-2A2(B3E3C11B3A3-A)B3E3C11B3A4-A3E3C11B2A5-A3E14C2A6-12A4CE2A8-16A3-2(3A20-A-)4A19-A-4A18-2A-5A16-3A-2(5A16-2(A-))5A16-3A-7A10-4A2BA-3A2C2B10F3B2C2A-3A2C15B2C6A10(2C15B2C3A-2A)2C17B3A-2A2C17BAB2-2A2C17B2A2-2A7C12D2A2-2A7C2(12B2A3-AE6C)12B2A4-A6C12BA5-A17CBA5-10A7B2EA7-8A6-3A3-2(3A20-A-)4A19-A-4A18-2A4(-5A16-3A)-8A8-5A2BA-3A2C2B10F3B2C2A-3A2C15B2C6A10(2C15B2C3A-2A)2C17B3A-2A2C17BAB2-2A2C17B2A2-2A7C12D2A2-2A7C2(12B2A3-AE6C)12B2A4-A6C12B2A4-A17CBA4-5A5BA7B2EA6-12A-A2-2A3-2(3A20-A-)4A19-A-4A18-2A4(-5A16-3A)-9A6-6A2BA-3A4C10F5C2A-3A2C15B2C6A10(2C15B2C3A-2A)2C17B3A-2A2C17BAB2-2A2C17B2A2-2A7C12D2A3-A7C2(12B2A3-AE6C)12B2A4-A6C12B2A4-A17CBA4-4A6BA7B2EA5-3A-A4-A3-2(A-)2A3-2(4A19-A-)6(24A-)21A2BA-3A4C10F5C2A-3A2C15B2C6A10(2C15B2C3A-2A)2C17B3A-2A2C17BAB2-2A2C17B2A3-A7C12D2A3-A7C2(12B2A3-AE6C)12B2A4-A6C12B2A4-A17CBA4-4A6BA7B2EA5-10A7-2A4-10(23A2-)11(2A2C15B2C3A-)2A2C17B3A-2A2C17BAB3-A2C17B2A3-A7C12D2A3-A7C12B2A3-AE6C12B2A3-BE2(6C12B2A4-A)17CBA4-4A6BA7B2EA5-10A3(-A)-2A5-10(22A3-)A2C15B2E2A3-10(A2C15B2E3A2-)2(A2C15B2E2A3-)A2C17B2A3-A2C17D2A3-B19D3(2A3-BE18D)2A3-BE17CDA4-4A6BA7B2EA5-3A-6A-5A-2A6-7(20A5-)20A4-21A4-22A13(3-AEC13B2C2E2A)3-AEC13B4C2A3-B2C13D4C2A4-A14D4C2(2A4-A18D)2A3-BA18D2A4-A17CDA4-4A6BA7B2EA5-3A6-A2-A-A2-2A57-3(17A8-)17A7-18A7-19A5-21A4-22A13(3-AE14B2C2E2A)3-AE14B4C2A3-BC14D4C2A4-A14D4C2A3-B3(A18D2A4-)A17CDA4-4A6BA7B2EA5-2(3A-)3A2-A2-3A57-3(17A8-)17A7-18A7-19A5-21A4-22A13(3-AE14B2C2E2A)3-AE14B4C2A3-BC14D4C2A4-A14D4C3(2A3-BA18D)2A3-BA17CDA4-4A6BA7B2EA5-10A2-A-A2-2A6-7(20A5-)20A4-21A4-22A13(3-AEC13B2C2E2A)3-AEC13B4C2A3-A2C13D4C2A3-BA14D4C3(2A4-A18D)2A4-A17CDA4-4A6BA7B2EA5-10A-A3-A-2A5-10(22A3-)A2C15B2E2A3-10(A2C15B2E3A2-)2(A2C15B2E2A3-)A2C8B-8B2A3-A2C8D-8D2A3-A10D2(-8D2A3-BE9D)-8D2A3-BE18D2A3-BE17CDA4-4A6BA7B2EA5-4A-A-3A2-A-A2-2A4-10(23A2-)11(2A2C15B2C3A-)2A2C17B3A-2A2C17BAB3-A2C17B2A3-A7C12D2A3-A7C12B2A3-AE6C12B2A3-BE2(6C12B2A4-A)17CBA4-4A6BA7B2EA5-3A5-2A3-A3-2A3-2(4A19-A-)6(24A-)21A2BA-3A4C10F5C2A-3A2C15B2C6A10(2C15B2C3A-2A)2C17B3A-2A2C17BAB2-2A2C17B2A3-A7C12D2A3-A7C2(12B2A3-AE6C)12B2A4-A6C12B2A4-A17CBA4-4A6BA7B2EA5-4A-A-3A-A5-2A3-2(3A20-A-)4A19-A-4A18-2A4(-5A16-3A)-9A6-6A2BA-3A4C10F5C2A-3A2C15B2C6A10(2C15B2C3A-2A)2C17B3A-2A2C17BAB2-2A2C17B2A2-2A7C12D2A3-A7C2(12B2A3-AE6C)12B2A4-A6C12B2A4-A17CBA4-4A6BA7B2EA5-3A5-2A2-4A-2A3-2(3A20-A-)4A19-A-4A18-2A4(-5A16-3A)-8A8-5A2BA-3A2C2B10F3B2C2A-3A2C15B2C6A10(2C15B2C3A-2A)2C17B3A-2A2C17BAB2-2A2C17B2A2-2A7C12D2A2-2A7C2(12B2A3-AE6C)12B2A4-A6C12B2A4-A17CBA4-5A5BA7B2EA6-3A-A-4A4-A-2A3-2(3A20-A-)4A19-A-4A18-2A-5A16-3A-2(5A16-2(A-))5A16-3A-7A10-4A2BA-3A2C2B10F3B2C2A-3A2C15B2C6A10(2C15B2C3A-2A)2C17B3A-2A2C17BAB2-2A2C17B2A2-2A7C12D2A2-2A7C2(12B2A3-AE6C)12B2A4-A6C12BA5-A17CBA5-10A7B2EA7-12A3-2A3-2(3A20-A-)4A19-A-4A18-2A-5A16-3A-2(5A16-2(A-))7A14-3A-7A10-7A-3A2C2B10F3BC3A-3A2C15BC7A10(2C15BC4A-2A)2C16B4A-2A2C16B2AB2-2A2C16B3A2-2AB3E3C11D3A2-2A2(B3E3C11B3A3-A)B3E3C11B3A4-A3E3C11B2A5-A3E14C2A6-5A-A2-3A4CE2A8-16A3-2(3A20-A-)4A19-A-5A17-2A-5A16-3A-2(8A13-2(A-))8A13-3A-8A8-8A-3A2C3B8F4BC3A-3A2C15BC7A5(2C15BC4A-2A)6(2C16B4A-2A)2C16B2AB2-3AC16B3A2-7ABC9D2B3A2-7ABC11B3A3-6ABC11B3A4-5A2(BC11B2A6-4A)B10C2B2A7-11A3E2B2A9-14A4-2(3A20-A-)4A18-2A-5A17-2A-9A3(12-3A-7ABA)6-9A-7ABA6-A2B6A-3A2C2B2E6F3B6A-3A2C2B3E8B6A2-2A2C2B3E8B5A-A10(-2A2C2B3E8B7A)-2AFC2B3E8B6A2-2A-A2B3E8B6A2-2A-4ABE2(D3B)6A3-A-4ABE8B6A5-4ABE8B5A7-3A2(BE8B5A8-2A)BE8B4A9-10A2B4A12-11A5-2(4A18-2A-)5A17-2A-24A3(-7A2B15A)2(-24A)-10A3(B3AB7A-A2-9A)B3AB7A-2A8(-9AB3AB10A)-9AB3AB9A2-2A2F2(5AB3AB9A3-A2-)5AB3AB9A6-5AB3AB8A7-5AB3AB8A8-4AB3AB8A9-2(3AB)7A11-2AB3AB6A12-13A29-2(6A15-2A2-)2(23A2-)7A3BA3CA3B5A2-7A3E5A3B5A2-7A3E4A2(B8A2-10AB3A)4(B6A-A3-9AB3A)2(B6A-2A2-9AB3A)7(B9A2-9AB3A)B9A3-A2F2(5AB3AB9A3-A2-)5AB3AB8A7-5AB3AB8A8-4AB3AB7A10-2(3AB)6A12-2AB3AB5A81-21A3(4-2A2B17A)4-2A2B2A2(3BA)3B4A4-2A2B2A3E5A3B4A5-A2B2A3E4A7(B7A5-8AB3A)6(B8A4-8AB3A)2(B8A5-7AB3A)B8A5-A2F4AB3AB8A5-A2-4AB3AB7A6-A2-4AB3AB6A10-4AB3AB5A12-2(3AB)4A133-3(8AB3AB6A6-)8A11(B3AB6A7-7A)3(B3AB7A6-7A)4(B3AB7A7-6A)B3AB6A8-6AB3AB5A9-6AB3AB4A10-6A2(B3A)182-
