model
size = 30 32 25, scale = 0.05, origin = -y
material 
  colors = A:#B967FF B:#FFF C:#FF71CE D:#05FFA1 E:#F44800 F:#CBDBFC G:#01CDFE H:#847E87
voxels
2-8(9A8-9A4-)9A8-9A5-8A8-8A7-7A8-7A9-6A8-6A606-5(11A6-11A2-)11A6-11A3-15(10A6-10A4-)10A6-10A5-9A6-9A7-2(7A8-)6A10-6A9-4A12-4A185-13A3(4-26A)4-13A-4(12A4-12A2-)11(28A2-)28A3-4(26A4-)12A3B11A6-9AB3-B8A9-7AB-2B-B7A11-5A2B-B2-2B5A18-2(B-)2B24-B-B2-B20-14A38-4A6-4A2-4A6-8A6-4A2-4A6-18A3(2-28A)2-20A10(7C4A7C12A)5CED4ADE5C12A5CED4ADE5C6A-4(5A5CED4ADE5C5A2-)A3HA5CED4ADE5CA3HA2-A3-A5CED4ADE5CA3-A2-A3-A5C2E4D2E5CA3-A6-A5CEF4AFE5CA10-A5CEFA2CAFE5CA10-A5C2G4A2G5CA11-18A12-18A13-16A16-12A9-3A8-3A2-3A8-6A8-3A2-3A8-7A2(6-10A)4-3AC2AC3A4-19AC2AC26AC2AC23AC2D4C2DC20AC2D4C2DC16A2(4CDED)4C6(12A5DED4CDE5D)7(12A5CED4CDE5C)7A3H2A5CED4CDE5C2A3H2A3-2A5CED4CDE5C2(2A3-)2A5C3E2F3E5C2A3-A4-2A5CE6FE5C2A8-2A5CE6FE5C2A9-A5C8G5C2(A10-A6C6G6C)A11-3A2D8G2D3A14-14A2(8-3A)2-3A8-6A8-3A2-3A8-6A7-10A7-7A6-3AD2AD3A6-9A5-3AD2AD3A5-11A4-3AD2AD3A4-12A4-A3D2A3DA4-5AB7A3-A3D2A3DA3-AC16AB2D2A2DB5AC11A3B2EB2D2A2DB2E3B5(G11A6B6D6B)G7(11A5CB6DB6C)6AH4A5CB6DB6C3AH2A-4A5CB6DB6C3A-2A-4A5C8G6C3A-A2-4A5C8G6C3A5-3A5C8G6C2A7-2A5C8G6CA9-2(A6C6G6CA10-)4A12G4A12-16A7-2A9-3A2-3A9-4A9-3A2-3A9-5A7-10A7-2AB4A6-3AD2AD3A6-3AB5A5-3AD2AD3A5-4AB6A4-3AD2AD3A4-5AB6A4-A3D2A3DA4-13A3-A3D2A3DA3-18AB2D2A2DB17A3B2EB2D2A2DB2E4B5(11A6B6D7B)9(11A5CB6DB6C)11A5C8G6C5A-5A5C8G6C4A3-4A5C8G6C3A5-3A5C8G6C2A7-2(2A6C6G6C2A8-)5AHG8HGH5A10-3A-A-3A3-2A-3A6-2A9-3A2-3A9-4A9-3A2-3A9-AB3A7-10A7-7A6-3AD2AD3A6-9A5-3AD2AD3A5-11A3(4-3AD2AD3A4-12A)2-5AD2AD5A2-12A6H2D2A2D7H5(G3C7A6B6D7B)G3C9(7A5CB6DB10C)7A5CE6FE7C4A-5A5CE6FE7C3A2-5A5CE6FE7C3A3-4A5CE6FE7C2A5-3A6C6F6C3A7-2A6C6E6C2A8-4A14H4A9-3A5-3A-8A5-2A9-3A2-3A9-4A9-3A2-3A9-5A7-10A7-7A6-3AD2AD3A6-3AB5A4(5-3AD2AD3A5-10A)4-4AD2AD4A4-10A7H2D2A2D7H5(G3C7A6B6D7B)G3C9(7A5CB6DB10C)7A5CE6FE7C4A-5A5CE6FE7C3A2-5A5CE6FE7C3A3-4A5CE6FE7C2A4-4A5CE6FE5C4A5-3AD16ED3A6-4A2C12H2C4A8-4A-A-4A-3A-4A5-2A9-3A2-3A9-4A9-3A2-3A9-5A7-10A7-2AB4A6-3AD2AD3A6-8A6-3AD2AD3A6-3AB4A4(6-3AD2AD3A6-8A)7H3D2A3D7H14(3C7A19BG)3C7A6E6F7EG4A-5A6E6F7EG3A2-5AD5E6F5E3D3A3-4AD5E6F5E3D2A4-4AD5E6F5E3D2A5-3AD16E3DA6-3A-E13H2E4A7-4A5-2(3A-)5A4-BA9-3A2-3A9-2ABA9-3A2-3A9-A2B2A7-10A7-3A2(B3A6-3AD2AD3A6-4A)B3A6-3AD2AD3A6-3A2B3A6-3AD2AD3A6-4AB3A6-3AD2AD3A6-3A2B3A6-3AD2AD3A6-3A5B7H3D2A3D7H428B22F4B-11B6F11B2-2B4D5B6F5B4D2B3-B4D5B6F5B4DB4-B4D5B6F5B4DB5-B3D16E3DB6-4A2E12H2E4A7-5A-A-3A2-3A-5A4-2A9-3A2-3A9-4A9-3A2-3A9-5A7-10A7-2AB4A6-3AD2AD3A6-8A6-3AD2AD3A6-3AB4A4(6-3AD2AD3A6-8A)7H3D2A3D7H14(8AG20BG)8AG20FG4A-3AG7B6F7BG3A2-3A3D5B6F5B3D3A3-2A3D5B6F5B3D2A4-2A3D5B6F5B3D2A5-A3D16E3DA6-3A-2E12H2E4A7-12A-3A-5A4-2A9-3A2-3A9-4A9-3A2-3A9-5A7-10A7-7A6-3AD2AD3A6-3AB4A5(6-3AD2AD3A6-8A)7H3D2A3D7H14(8AG20BG)8AG20FG4A-3AG7B6F7BG3A2-3A3D5B6F5B3D3A3-2A3D5B6F5B3D2A4-2A3D5B6F5B3D2A5-A3D16E3DA6-3A-16E4A7-22A4-2A9-3A2-3A9-4A9-3A2-3A9-5A7-10A7-2AB4A6-3AD2AD3A6-8A6-3AD2AD3A6-3AB4A4(6-3AD2AD3A6-8A)7H3D2A3D7H13(8AG20BG)8AG7B-12BG8AG7F-12FG4A-3AG7B-5F7BG3A2-3A3D5B-5F5B3D3A3-2A3D5B-5F5B3D2A4-2A3D5B6F5B3D2A5-A3D16E3DA6-4A16B4A7-5A6-A5-A-3A4-BA9-3A2-3A9-2ABA9-3A2-3A9-A2B2A7-10A7-3A2(B3A6-3AD2AD3A6-3A2B3A6-3AD2AD3A6-4A)B3A6-3AD2AD3A6-3A2B3A6-3AD2AD3A6-3A5B7H3D2A3D7H428B22F4B-11B6F11B2-2B4D5B6F5B4D2B3-B4D5B6F5B4DB4-B4D5B6F5B4DB5-B3D16E3DB6-4A16B4A7-4A2(2-A)3-2A2-A-3A4-2A9-3A2-3A9-4A9-3A2-3A9-5A7-10A7-7A3(6-3AD2AD3A6-8A)6-3AD2AD3A6-9A5-3AD2AD3A5-10A4-4AD2AD4A4-6A3CB6H3D2A3D6HB11(5A3C22B)2(7AC22B)C6AC22BC6AC22FC3A-2AC8B6F8BC2A2-2AC3D5B6F5B3DC2A3-AC3D5B6F5B3DCA4-2A3D5B6F5BD4A5-A3D16ED3A6-4A16B4A7-4A-A2-2(A-)2A3-A-3A4-2A9-3A2-3A9-4A9-3A2-3A9-5A7-10A7-7A6-3AD2AD3A6-3AB4A6-3AD2AD3A6-8A6-3AD2AD3A6-3AB4A6-3AD2AD3A6-9A5-3AD2AD3A5-11A2-5AD2AD5A2-7A3C2G5H3D2A3D5H11(2G5A3C2G18B)2(2G7AC2G18B)2GC6AC2G18B2GC6AC2G18F2GC3A-2AC2G6B6F6B2GC2A2-2AC3D5B6F5B3DC2A3-AC3D5B6F5B3DCA4-2A3D5B6F5BD4A5-A3D16ED3A6-4A16B4A7-4A2(-A)3-A-2A-A2-3A4-2(2A9-3A2-3A9-AB)3A7-10A7-2AB4A6-3AD2AD3A6-8A6-3AD2AD3A6-3AB4A6-3AD2AD3A6-8A6-3AD2AD3A6-9A5-3AD2AD3A5-18AD2AD14A3C2G3B2E3D2A3D2E3B11(2G5A3C2G18B)2(2G7AC2G18B)2GC6AC2G18B2GC6AC2G18F2GC3A-2AC2G6B6F6B2GC2A2-2AC3D5B6F5B3DC2A3-AC3D5B6F5B3DCA4-2A3D5B6F5BD4A5-A3D16ED3A6-4A16B4A7-3A2(2-A)-A-2A3-A-3A4-2A9-3A2-3A9-4A9-3A2-3A9-5A7-10A7-7A3(6-3AD2AD3A6-8A)6-3AD2AD3A6-9A5-3AD2AD3A5-18AD2AD14A3CDG3B2E3D2A3D2E3B11(GD5A3CDG7B4E7B)2(GD7ACDG7B4E7B)GDC6ACDG7B4E7BGDC3A-2ACDG7F4E7FGDC2A2-2ACDG6BF4EF6BGDC2A2-2AC3D5B6F5B3DC2A3-AC3D5B6F5B3DCA4-2A3D5B6F5BD4A5-A3D16ED3A6-4A16B4A7-3A-2A3-A3-2A-A2-3A4-2A9-3A2-3A9-4A9-3A2-3A9-5A7-10A7-7A3(6-3AD2AD3A6-8A)6-3AD2AD3A6-9A5-3AD2AD3A5-18AD2AD14A3CDG3B2E3D2A3D2E3B11(GD5A3CDG7B4E7B)2(GD7ACDG7B4E7B)GDC3A-2ACDG7B4E7BGDC2A2-2ACDG7F4E7FGDC2A2-2ACDG6BF4EF6BGD3A3-2(AC3D5B6F5B3D2A4-)2A3D5B6F5B3D2A5-A3D16E3DA6-4A16B4A7-3A8-A6-4A4-2A9-3A2-3A9-4A9-3A2-3A9-5A7-10A7-7A3(6-3AC2AC3A6-8A)6-3AC2AC3A6-9A5-3AC2AC3A5-18AC2AC25ADC2ACD11(24AE4CE)24AB4CB12A-2(2ACDG7B4C7BGDC2A2-)2ACDG7F4C7FGDC2A3-ACDG6BF4CF6BGD2(2A4-AC3D5BF4CF5B3D)2A5-2(A22CA6-)4A16C4A8-20A6-2(2A8-3A2-3A8-2A2-)2A7-4A2-4A7-2A2-3A6-4A2-4A6-3A6(2-13A)2-28A2-A-10AC2AC12A2-A-9ADC2ACD4(11A2-A-9AE4CE)11A-12A6(E4CE24A)E4CE12A-11AB4CB11A2(2-4AG7B4C7BG4A)3-3AG7F4C7FG3A4-3AG6BF4CF6BG3A4-3A2D5BF4CF5B2D3A5-2A2D5BF4CF5B2D2A6-2A20C2A7-A20CA8-3A16C3A10-18A8-2(2A7-3A2-3A7-2A4-)3A5-4A2-4A5-3A2(4-12A2-12A)2(4-3A3-6A2-6A3-3A)4-12A2-12A4-26A4-A-8AD4AD3(10A4-A-8AG4AG)10A3-9(11AG4AG11A2-)2(4AG6EG)4A3-2(26A4-)26A5-24A6-24A7-22A9-20A10-20A38-9(10A4-10A6-)2(24A6-)A-22A5-10(26A4-)3A7B6A7B3A4-26A5-24A7-22A9-20A11-18A14-14A403-7A6-7A9-9A4-9A7-8(10A4-10A6-)10A4-10A7-8A6-8A304-
