model
size = 30 32 25, scale = 0.05, origin = -y
material 
  colors = A:#FF71CE B:#FFF C:#05FFA1 D:#01CDFE E:#F44800 F:#CBDBFC G:#847E87
voxels
2-8(9A8-9A4-)9A8-9A5-8A8-8A7-7A8-7A9-6A8-6A606-5(11A6-11A2-)11A6-11A3-15(10A6-10A4-)10A6-10A5-9A6-9A7-2(7A8-)6A10-6A9-4A12-4A185-13A3(4-26A)4-13A-4(12A4-12A2-)11(28A2-)28A3-4(26A4-)12A3B11A6-9AB3-B8A9-7AB-2B-B7A11-5A2B-B2-2B5A18-2(B-)2B24-B-B2-B20-14A38-4A6-4A2-4A6-6ACA6-4A2-4A6-A4(C4AC11A2-11A)9(C4AC24A)C43AEC4ACE22AEC4ACE11A-4(10AEC4ACE10A2-)A3G6AEC4ACE6A3GA2-A3-6AEC4ACE6A3-A2-A3-6A2E4C2E6A3-A6-2(6AEF4AFE6A10-)6A2D4A2D6A11-6AC4AC6A12-6AC4AC6A13-2A12C2A16-12A9-3A8-3A2-3A8-6A8-3A2-3A8-7A6-10A6-5A3C2A4-A2C4A2CA4-2(2A3C)2(7A2C4A2C7A3C2A3C)7A2C4A2C7A3C12A2C4A2C21ACEC4ACEC14A5(7CEC4ACE7C8A)7CEC4ACE7C15A6(EC4ACE22A)EC4ACE12A3G7AEC4ACE7A3G2A3-7AEC4ACE7A3-2A3-7A3E2F3E7A3-A4-7AE6FE7A8-7AE6FE7A9-6A8D6A2(10-7A6D7A)11-3A2C8D2C3A14-14A2(8-3A)2-3A8-6A8-3A2-3A8-6A7-10A7-4A2CA6-A8CA6-A2(2C2A)5-A8CA5-2(2A2C)3A4-A8CA4-3A2C2A2C3A4-A8CA4-3A2CB7A3-A8CA3-17ADB6CBD14A2D3B2EB6CB2E3B5(2D8A2D6B6C6B)2D15A6(B6CB22A)B6CB12AG9AB6CB9AG2A-9AB6CB9A-2A-9A8D9A-A2-9A8D9A5-8A8D8A7-7A8D7A9-2(7A6D7A10-)4A12D4A12-16A7-2A9-3A2-3A9-4A9-3A2-3A9-5A7-10A7-2ABA2CA6-A8CA6-A2CBADC2A5-A8CA5-2ACDBADC3A4-A8CA4-3ACDBA2D3A4-A8CA4-3A2D8A3-A8CA3-17ADB6CBD14AD4B2EB6CB2E4B5(D8AD7B6C7B)D15A9(B6CB22A)8D11A-10A8D10A3-9A8D9A5-8A8D8A7-2(8A6D8A8-)5AGD8GDG5A10-3A-A-3A3-2A-3A6-2A9-3A2-3A9-4A9-3A2-3A9-AB3A7-10A7-4A2CA6-A8CA6-A2C2ADC2A5-A8CA5-2ACD2ADC3A4-A8CA4-3ACD2A2D3A4-A8CA4-3A2D7A4-A8CA4-12A2-2ADB6CBD2A2-10ADB6G6C7G5(D8AD7B6C7B)D15A9(B6CB22A)E6FE11A-10AE6FE10A2-10AE6FE10A3-9AE6FE9A5-9A6F9A7-8A6E8A8-4A14G4A9-3A5-3A-8A5-2A9-3A2-3A9-4A9-3A2-3A9-5A7-10A7-4A2CA6-A8CA6-A2CBA2(DC2A5-A8CA5-2ACD2A)2D2A5-A8CA5-2A2D6A5-A8CA5-10A4-ADB6CBDA4-9AD7G6C7G5(D8AD7B6C7B)D15A9(B6CB22A)E6FE11A-10AE6FE10A2-10AE6FE10A3-9AE6FE9A4-9AE6FE9A5-A3C16E3CA6-6A12G6A8-4A-A-4A-3A-4A5-2A9-3A2-3A9-4A9-3A2-3A9-5A7-10A7-2ABA2CA6-A8CA6-A2C2ADCA6-A8CA6-ACDBADCA6-A8CA6-ACD2A2DA6-A8CA6-A2D5A2(6-A8CA6-8A)7G8C7G14(8AD20BD)8AD7E6F7ED4A-3AD7E6F7ED3A2-3A3C5E6F5E3C3A3-2A3C5E6F5E3C2A4-2A3C5E6F5E3C2A5-A3C16E3CA6-2AC-E13G2E2C2A7-4A5-2(3A-)5A4-BA9-3A2-3A9-2ABA9-3A2-3A9-A2B2A7-10A7-3AB2CA6-A8CA6-A2C2(ABDCA6-A8CA6-ACD)2B2DA6-A8CA6-A2DAB2DA6-A8CA6-A2D2B2DA6-A8CA6-A2D5B7G8C7G428B22F4B-11B6F11B2-2B4C5B6F5B4C2B3-B4C5B6F5B4CB4-B4C5B6F5B4CB5-B3C16E3CB6-2A2C2E12G2E2C2A7-5A-A-3A2-3A-5A4-2A9-3A2-3A9-4A9-3A2-3A9-5A7-10A7-2ABA2CA6-A8CA6-A2C2ADCA6-A8CA6-ACDBADCA6-A8CA6-ACD2A2DA6-A8CA6-A2D5A2(6-A8CA6-8A)7G8C7G14(8AD20BD)8AD20FD4A-3AD7B6F7BD3A2-3A3C5B6F5B3C3A3-2A3C5B6F5B3C2A4-2A3C5B6F5B3C2A5-A3C16E3CA6-2AC-2E12G2E2C2A7-12A-3A-5A4-2A9-3A2-3A9-4A9-3A2-3A9-5A7-10A7-4A2CA6-A8CA6-A2CBA2(DCA6-A8CA6-ACD2A)2DA6-A8CA6-A2D5A2(6-A8CA6-8A)7G8C7G14(8AD20BD)8AD20FD4A-3AD7B6F7BD3A2-3A3C5B6F5B3C3A3-2A3C5B6F5B3C2A4-2A3C5B6F5B3C2A5-A3C16E3CA6-2AC-16E2C2A7-22A4-2A9-3A2-3A9-4A9-3A2-3A9-5A7-10A7-2ABA2CA6-A8CA6-A2C2ADCA6-A8CA6-ACDBADCA6-A8CA6-ACD2A2DA6-A8CA6-A2D5A2(6-A8CA6-8A)7G8C7G13(8AD20BD)8AD7B-12BD8AD7F-12FD4A-3AD7B-5F7BD3A2-3A3C5B-5F5B3C3A3-2A3C5B-5F5B3C2A4-2A3C5B6F5B3C2A5-A3C16E3CA6-2A2C16B2C2A7-5A6-A5-A-3A4-BA9-3A2-3A9-2ABA9-3A2-3A9-A2B2A7-10A7-3A2(B2CA6-A8CA6-A2C2B2CA6-A8CA6-A2CA)B2CA6-A8CA6-A2C2B2CA6-A8CA6-A2C5B7G8C7G428B22F4B-11B6F11B2-2B4C5B6F5B4C2B3-B4C5B6F5B4CB4-B4C5B6F5B4CB5-B3C16E3CB6-2A2C16B2C2A7-4A2(2-A)3-2A2-A-3A4-2A9-3A2-3A9-4A9-3A2-3A9-5A7-10A7-4A2(2CA6-A8CA6-A2C2A)2CA6-A8CA6-A2C5A6-A8CA6-9A5-A8CA5-10A4-2A8C2A4-9AB6G8C6GB14(8A22B)8A22F4A-3A8B6F8B3A2-3A3C5B6F5B3C3A3-2A3C5B6F5B3C2A4-2A3C5B6F5B3C2A5-A3C16E3CA6-2A2C16B2C2A7-4A-A2-2(A-)2A3-A-3A4-2A9-3A2-3A9-4A9-3A2-3A9-5A7-10A7-4A2CA6-A8CA6-A2CBA2CA6-A8CA6-A2C2A2CA6-A8CA6-A2CB4A6-A8CA6-9A5-A8CA5-11A2-3A8C3A2-10A2D5G8C5G14(2D8A2D18B)2D8A2D18F2D4A-3A2D6B6F6B2D3A2-3A3C5B6F5B3C3A3-2A3C5B6F5B3C2A4-2A3C5B6F5B3C2A5-A3C16E3CA6-2A2C16B2C2A7-4A2(-A)3-A-2A-A2-3A4-2(2A9-3A2-3A9-AB)3A7-10A7-2ABA2CA6-A8CA6-A2C2A2CA6-A8CA6-A2CBA2CA6-A8CA6-A2C5A6-A8CA6-9A5-A8CA5-16A8C15A2D3B2E8C2E3B14(2D8A2D18B)2D8A2D18F2D4A-3A2D6B6F6B2D3A2-3A3C5B6F5B3C3A3-2A3C5B6F5B3C2A4-2A3C5B6F5B3C2A5-A3C16E3CA6-2A2C16B2C2A7-3A2(2-A)-A-2A3-A-3A4-2A9-3A2-3A9-4A9-3A2-3A9-5A7-10A7-7A3(6-A8CA6-8A)6-A8CA6-9A5-A8CA5-16A8C15ACD3B2E8C2E3B14(DC8ACD7B4E7B)DC4A-3ACD7F4E7FDC3A2-3ACD6BF4EF6BDC3A2-3A3C5B6F5B3C3A3-2A3C5B6F5B3C2A4-2A3C5B6F5B3C2A5-A3C16E3CA6-2A2C16B2C2A7-3A-2A3-A3-2A-A2-3A4-2A9-3A2-3A9-4A9-3A2-3A9-5A7-10A7-7A3(6-A8CA6-8A)6-A8CA6-9A5-A8CA5-16A8C15ACD3B2E8C2E3B13(DC8ACD7B4E7B)DC4A-3ACD7B4E7BDC3A2-3ACD7F4E7FDC3A2-3ACD6BF4EF6BDC3A3-2(2A3C5B6F5B3C2A4-)2A3C5B6F5B3C2A5-A3C16E3CA6-2A2C16B2C2A7-3A8-A6-4A4-2A9-3A2-3A9-4A9-3A2-3A9-5A7-10A7-7A3(6-A2C4A2CA6-8A)6-A2C4A2CA6-9A5-A2C4A2CA5-16A2C4A2C15ACD5E2C4A2C5E11(DC8ACD7E4A7E)DC8ACD7B4A7BDC4A-2(3ACD7B4A7BDC3A2-)3ACD7F4A7FDC3A3-2ACD6BF4AF6BDC2(2A4-2A3C5BF4AF5B3C)2A5-2(24A6-)24A8-20A6-2(2A8-3A2-3A8-2A2-)2A7-4A2-4A7-2A2-3A6-A2CA2-A2CA6-3A3(2-10A2CA2-A2C10A)2-10A2C4A2C10A2-A-8A2C4A2C10A2-A-ACD5E2C4A2C5E4(DC3A2-A-ACD7E4A7E)DC3A-4A6(CD7E4A7EDC8A)CD7E4A7EDC4A-2(3ACD7B4A7BDC3A2-)3ACD7B4A7BDC3A3-2ACD7F4A7FDC2A4-2ACD6BF4AF6BDC2A4-2A3C5BF4AF5B3C2A5-A3C5BF4AF5B3CA6-24A7-22A8-22A10-18A8-2(2A7-3A2-3A7-2A4-)3A5-4A2-4A5-3A4-8A3CA2-A3C8A4-3A8CA2-A8C2(3A4-3A3-5CA2-A5C3-)3A4-3A8CA2-A8C3A4-3A8C4A8C3A4-A-A6D2C4A2C6D3(3A4-A-A8D4A8D)3A3-9(2(4A8D)4A2-)2(4AD6ED)4A3-2(3A8C15A4-)3A8C15A5-2A8C14A6-3A7C14A7-22A9-20A10-20A38-9(10A4-10A6-)2(24A6-)A-22A5-10(26A4-)3A7B6A7B3A4-26A5-24A7-22A9-20A11-18A14-14A403-7A6-7A9-9A4-9A7-8(10A4-10A6-)10A4-10A7-8A6-8A304-
