model
size = 25 32 30, scale = 0.05, origin = -y
material 
  colors = A:#05FFA1 B:#FFF C:#01CDFE D:#F44800 E:#CBDBFC F:#847E87
voxels
2-15AB3A6-5A2(B2AB3A)6-4AB2A2(BA)2(B3A)6-4ABAB3A2(BA)B4A7-3AB2A2(BA)2(B3A)7-3(3AB)AB4A7-2AB15A7(7-7AB3AB6A)7-3(7AB3AB7A6-)7A4(B3AB7A7-6A)B3AB6A8-6AB3AB5A9-6AB3AB4A10-6A2(B3A)183-4(21A4-)5A8C8A4-5A8C8A5-4A8C8A2(5-8AC11A)4(5-8AB3AB7A)5-6(8AB3AB8A4-)8A2(B3AB8A5-7A)B3AB8A5-A2F4AB3AB8A5-A2-4AB3AB7A6-A2-4AB3AB6A10-4AB3AB5A12-2(3AB)4A131-2(6A15-2A2-)4(23A2-)6A8C9A2(2-10AC12A)3(3-9AB3AB8A)3-9(9AB3AB9A2-)9AB3AB9A3-A2F2(5AB3AB9A3-A2-)5AB3AB8A7-5AB3AB8A8-4AB3AB7A10-2(3AB)6A12-2AB3AB5A80-2(4A18-2A-)5A17-2A6(-24A)-6A3(4C2(B3C)6A2-5A)9(4C2(B3C)7A-5A)4C2(B3C)6A2-2A2F2(A4C2(B3C)6A3-A2-)A4C2(B3C)6A6-A4C2(B3C)5A7-18A8-17A9-15A11-2AB3AB6A12-13A29-2(3A20-A-)4A18-2A-5A17-2A2(-9A12-3A)-5AC3A12-3A2(-5AC3A6-9A)-5A4C6FB2C6A-5A5CB3C2B2C6A2-11(4A5CB3C2B2C7A-)2AF2(A5CB3C2B2C6A2-2A-)A5CE3C2E2C6A3-A-A5CB3C2B2C6A5-19A7-18A8-17A8-16A9-16A12-11A5-2(3A20-A-)4A19-A-5A17-2A-5A16-3A-2(8A13-2(A-))5AC2A13-3A-5AC2A8-8A-5ACB9F7CA-5AC10B7C7A11(C10B7C2A-4A)C10B7CB2-4AC10B6C2A2-4A2C3D6E6C2A2-4A2C3D6B6C2A3-22A4-20A2(6-19A)7-18A9-14A4-2(3A20-A-)4A19-A-4A18-2A-5A16-3A-2(5A16-2(A-))7A14-3A-5ACA10-7A-5A2B10F3B2DCA-5A15B2DC7A10(15B2DC2A-4A)17BC2A-4A17BDB2-4A17B2A2-4A2C3D12E2A2-4A2C3D12B2A2(3-22A)4-20A5-20A6-19A8-16A3-2(3A20-A-)4A19-A-4A18-2A-5A16-3A-2(5A16-2(A-))5A16-3A-7A10-7A-5A2B10F3B2DCA-5A15B2DC7A10(15B2DC2A-4A)17BC2A-4A17BDB2-4A17B2A2-4A2C3D12E2A2-4A2(2C3D12B2A3-3A)2C3D12B2A4-2A2C3D12BA5-2A2C14DBA5-2A2C6D7B2CA7-8A6-3A3-2(3A20-A-)4A19-A-4A18-2A4(-5A16-3A)-8A8-8A-5A2B10F3B2DCA-5A15B2DC7A10(15B2DC2A-4A)17BC2A-4A17BDB2-4A17B2A2-4A2C3D12E2A2-4A2(2C3D12B2A3-3A)2(2C3D12B2A4-2A)2C14DBA4-3A2C6D7B2CA6-12A-A2-2A3-2(3A20-A-)4A19-A-4A18-2A4(-5A16-3A)-9A6-9A-5A2D10F5DCA-5A15B2DC7A10(15B2DC2A-4A)17BC2A-4A17BDB2-4A17B2A2-4A2C3D12E3(2A3-3A2C3D12B)2A4-2A2C3D12B2A4-2A2C14DBA4-3AC6FD7B2CA5-3A-A4-A3-2(A-)2A3-2(4A19-A-)6(24A-)5A4C15A-5A2D10F5DCA-5A15B2DC7A10(15B2DC2A-4A)17BC2A-4A17BDB2-4A17B2A3-3A2C3D12E3(2A3-3A2C3D12B)2A4-2A2C3D12B2A4-2A2C14DBA4-3A2C5FD7B2CA5-10A7-2A4-8(23A2-)2A2D4B15A2-2A2D2B2F15A2-11(2A2D15B2DC2A-)2A2D17BC2A-2A2D17BDB3-A2D17B2A3-A2D2C3D12E2(2A3-A2D2C3D12B)2A3-B4C2(3D12B2A4-A3C)14DBA4-2A2C6FD7B2CA5-10A3(-A)-2A5-10(22A3-)7A11B2DCA3-10(7A11B2DC2A2-)2(7A13BCA3-)7A13B2A3-A2D2(2C15E2A3-B2E)2C15E2A3-B4C2(15E2A3-BA3C)14DEA4-2A2C6FD7B2CA5-3A-6A-5A-2A6-7(20A5-)20A4-21A4-22A13(3-7A9B4DCA)3-7A9B4D2A3-BAD2(2C11E4D2A4-AE)2C15E2A4-A3C15E2A3-BA3C15E2A4-A3C14DEA4-2A2C6FD7B2CA5-3A6-A2-A-A2-2A57-3(17A8-)17A7-18A7-19A5-21A4-22A13(3-7A9B4DCA)3-7A9B4D2A3-BAE2C11E4D2A4-AE2C11E4D2A3-BAE2C3(15E2A4-A3C)14DEA4-2A2C6FD7B2CA5-2(3A-)3A2-A2-3A57-3(17A8-)17A7-18A7-19A5-21A4-22A13(3-7A9B4DCA)3-7A9B4D2A3-BAE2C11E4D2A4-AE2C11E4D2A3-BAE2C3(15E2A3-BA3C)14DEA4-2A2C6FD7B2CA5-10A2-A-A2-2A6-7(20A5-)20A4-21A4-22A13(3-7A9B4DCA)3-7A9B4D2A3-2AD2C11E4D2A3-BAE2C11E4D2A4-AE2C3(15E2A4-A3C)14DEA4-2A2C6FD7B2CA5-10A-A3-A-2A5-10(22A3-)7A11B2DCA3-10(7A11B2DC2A2-)2(7A13BCA3-)7A4B-8B2A3-A2D2C6E-8E2A3-A2(2E2C6E-8E2A3-B)4C6E-8E2A3-BA3C15E2A3-BA3C14DEA4-2A2C6FD7B2CA5-4A-A-3A2-A-A2-2A4-8(23A2-)2A2D4B15A2-2A2D2B2F15A2-11(2A2D15B2DC2A-)2A2D17BC2A-2A2D17BDB3-A2D17B2A3-A2D2C3D12E2(2A3-A2D2C3D12B)2A3-B4C2(3D12B2A4-A3C)14DBA4-2A2C6FD7B2CA5-3A5-2A3-A3-2A3-2(4A19-A-)6(24A-)5A4C15A-5A2D10F5DCA-5A15B2DC7A10(15B2DC2A-4A)17BC2A-4A17BDB2-4A17B2A3-3A2C3D12E3(2A3-3A2C3D12B)2A4-2A2C3D12B2A4-2A2C14DBA4-3A2C5FD7B2CA5-4A-A-3A-A5-2A3-2(3A20-A-)4A19-A-4A18-2A4(-5A16-3A)-9A6-9A-5A2D10F5DCA-5A15B2DC7A10(15B2DC2A-4A)17BC2A-4A17BDB2-4A17B2A2-4A2C3D12E3(2A3-3A2C3D12B)2A4-2A2C3D12B2A4-2A2C14DBA4-3AC6FD7B2CA5-3A5-2A2-4A-2A3-2(3A20-A-)4A19-A-4A18-2A4(-5A16-3A)-8A8-8A-5A2B10F3B2DCA-5A15B2DC7A10(15B2DC2A-4A)17BC2A-4A17BDB2-4A17B2A2-4A2C3D12E2A2-4A2(2C3D12B2A3-3A)2(2C3D12B2A4-2A)2C14DBA4-3A2C3F3D7B2CA6-3A-A-4A4-A-2A3-2(3A20-A-)4A19-A-4A18-2A-5A16-3A-2(5A16-2(A-))5A16-3A-7A10-7A-5A2B10F3B2DCA-5A15B2DC7A10(15B2DC2A-4A)17BC2A-4A17BDB2-4A17B2A2-4A2C3D12E2A2-4A2(2C3D12B2A3-3A)2C3D12B2A4-2A2C3D12BA5-2A2C14DBA5-2A2C6D7B2CA7-12A3-2A3-2(3A20-A-)4A19-A-4A18-2A-5A16-3A-2(5A16-2(A-))7A14-3A-5ACA10-7A-5A2B10F3B2DCA-5A15B2DC7A10(15B2DC2A-4A)17BC2A-4A17BDB2-4A17B2A2-4A2C3D12E2A2-4A2C3D12B2A2(3-22A)4-20A5-20A6-5A-A2-10A8-16A3-2(3A20-A-)4A19-A-5A17-2A-5A16-3A-2(8A13-2(A-))5AC2A13-3A-5AC2A8-8A-5AC2B8F7CA-5AC10B7C7A11(C10B7C2A-4A)C10B7CB2-4AC10B6C2A2-4A2C3D6E6C2A2-4A2C3D6B6C2A3-22A4-20A2(6-19A)7-18A9-14A4-2(3A20-A-)4A18-2A-5A17-2A2(-9A12-3A)-5AC3A12-3A2(-5AC3A6-9A)-5A4C6FB2C6A-5A5CB3C2B2C6A2-4A5CB3C2B2C5A-A10(-4A5CB3C2B2C7A)-2AF2(A5CB3C2B2C6A2-2A-)A5CE3C2E2C6A3-A-A5CB3C2B2C6A5-19A7-18A8-17A8-16A9-16A12-11A5-2(4A18-2A-)5A17-2A6(-24A)-6A3(4C2(B3C)4A-A2-5A)4C2(B3C)4A-2A8(-5A4C2(B3C)7A)-5A4C2(B3C)6A2-2A2F2(A4C2(B3C)6A3-A2-)A4C2(B3C)6A6-A4C2(B3C)5A7-18A8-17A9-15A11-2AB3AB6A12-13A29-2(6A15-2A2-)4(23A2-)6A8C9A2-10AC12A2-10AC10A4(-A3-9AB3AB6A)-2A2-9AB3AB6A-2A8(2-9AB3AB9A)3-A2F2(5AB3AB9A3-A2-)5AB3AB8A7-5AB3AB8A8-4AB3AB7A10-2(3AB)6A12-2AB3AB5A81-4(21A4-)5A8C8A4-5A8C8A5-4A8C8A2(5-8AC11A)4(5-8AB3AB7A)5-6(8AB3AB8A4-)8A2(B3AB8A5-7A)B3AB8A5-A2F4AB3AB8A5-A2-4AB3AB7A6-A2-4AB3AB6A10-4AB3AB5A12-2(3AB)4A133-3(8AB3AB6A6-)8A11(B3AB6A7-7A)3(B3AB7A6-7A)4(B3AB7A7-6A)B3AB6A8-6AB3AB5A9-6AB3AB4A10-6A2(B3A)182-
