model
size = 25 32 30, scale = 0.05, origin = -y
material 
  colors = A:#F44800 B:#FFF C:#CBDBFC D:#847E87 E:#000
voxels
2-15AB3A6-5A2(B2AB3A)6-4AB2A2(BA)2(B3A)6-4ABAB3A2(BA)B4A7-3AB2A2(BA)2(B3A)7-3(3AB)AB4A7-2AB15A7(7-7AB3AB6A)7-3(7AB3AB7A6-)7A4(B3AB7A7-6A)B3AB6A8-6AB3AB5A9-6AB3AB4A10-6A2(B3A)183-21A2(4-4AB16A)3(4-4A15B2A)7(5-3A15B2A)5-3A15B3A6(4-3A6B3AB8A)2(5-2A6B3AB8A)5-A2D5B3AB8A5-A2-A4B3AB7A6-A2-4AB3AB6A10-4AB3AB5A12-2(3AB)4A131-2(6A15-2A2-)3(23A2-)2(8A12B3A2-)5A15B3A2-5A4(15B3A3-4A)2(15B4A2-4A)7(6B3AB9A2-4A)6B3AB9A3-A2D6B3AB9A3-A2-A5B3AB9A3-A2-5AB3AB8A7-5AB3AB8A8-4AB3AB7A10-2(3AB)6A12-2AB3AB5A80-2(4A18-2A-)5A17-2A4(-24A)2(-5AB18A)-5A3(15B4A2-4A)2(15B5A-4A)7(6B3AB10A-4A)6B3AB9A2-2A2D6B3AB9A3-A2-A5B3AB9A3-A2-5AB3AB9A6-5AB3AB8A7-5AB3AB8A8-4AB3AB8A9-2(3AB)7A11-2AB3AB6A12-13A29-2(3A20-A-)4A18-2A-5A17-2A3(-9A12-3A)2(-5AB3A6-9A)-5A2B8D5B4A-5A15B4A2-10(4A15B5A-)4A19BA-2AD2(A17B2A2-2A-)6A12C2A3-A-6A11B3A5-6A11B2A7-5A2(11B2A8-4A)11BA9-16A12-11A5-2(3A20-A-)4A19-A-5A17-2A-5A16-3A-2(8A13-2(A-))5AB2A13-3A-5AB2A8-8A-5A2B9D4B4A-5A15B10A10(15B5A-4A)19BA-4A17BAB2-4A17B2A2-9A12C2A2-9A12B2A3-8A12B2A4-7A2(12BA6-6A)12BA7-18A9-14A4-2(3A20-A-)4A19-A-4A18-2A-5A16-3A-2(5A16-2(A-))7A14-3A-7A10-7A-5A2B10D3B4A-5A15B10A10(15B5A-4A)19BA-4A17BAB2-4A17B2A2-9A12C2A2-9A2(12B2A3-8A)12B2A4-7A12BA5-18ABA6-19A8-16A3-2(3A20-A-)4A19-A-4A18-2A-5A16-3A-2(5A16-2(A-))5A16-3A-7A10-7A-5A2B10D3B4A-5A15B10A10(15B5A-4A)19BA-4A17BAB2-4A17B2A2-9A12C2A2-9A2(12B2A3-8A)12B2A4-7A12BA5-18ABA5-10A7B3A7-8A6-3A3-2(3A20-A-)4A19-A-4A18-2A4(-5A16-3A)-8A8-8A-5A2B10D3B4A-5A15B10A10(15B5A-4A)19BA-4A17BAB2-4A17B2A2-9A12C2A2-9A2(12B2A3-8A)12B2A4-7A12B2A4-18ABA4-11A7B3A6-12A-A2-2A3-2(3A20-A-)4A19-A-4A18-2A4(-5A16-3A)-9A6-9A-7A10D7A-5A15B10A10(15B5A-4A)19BA-4A17BAB2-4A17B2A2-9A12C3(2A3-8A12B)2A4-7A12B2A4-18ABA4-4A6DA7B3A5-3A-A4-A3-2(A-)2A3-2(4A19-A-)7(24A-)7A10D7A-5A15B10A10(15B5A-4A)19BA-4A17BAB2-4A17B2A3-8A12C3(2A3-8A12B)2A4-7A12B2A4-18ABA4-4A6DA7B3A5-10A7-2A4-2(23A2-)7(4A15B4A2-)4A2B10D3B4A2-11(4A15B5A-)4A19BA-4A17BAB3-3A17B2A3-8A12C2(2A3-8A12B)2A3-B2(7A12B2A4-)18ABA4-4A6DA7B3A5-10A3(-A)-2A5-2(22A3-)7(3A15B4A3-)3A2B10D3B2(4A3-3A15B)9(5A2-3A15B)5A2-3(3A17B2A3-)3A17C4(2A3-B19C)2A3-B18ACA4-4A6DA7B3A5-3A-6A-5A-2A6-4(20A5-)3A12B3(5A5-2A13B)5A4-3A13B5A4-3A2B10DB14(6A3-3A13B)6A3-B2A13C6A4-A14C6A2(4-A18C2A)3-2B18C2A4-18ACA4-4A6DA7B3A5-3A6-A2-A-A2-2A57-3(17A8-)17A7-2A13B3A7-A14B4A5-2A14B5A4-2A3B10DB14(6A3-2A14B)6A3-BA14C6A4-A14C6A3-B3(A18C2A4-)18ACA4-4A6DA7B3A5-2(3A-)3A2-A2-3A57-3(17A8-)17A7-2A13B3A7-A14B4A5-2A14B5A4-2A3B10DB14(6A3-2A14B)6A3-BA14C6A4-A14C6A2(3-BA18C2A)3-BE18C2A3-B18ACA4-4A6DA7B3A5-10A2-A-A2-2A6-4(20A5-)3A12B3(5A5-2A13B)5A4-3A13B5A4-3A2B10DB14(6A3-3A13B)6A3-3A13C6A3-2B14C6A3(4-A18C2A)4-18ACA4-4A6DA7B3A5-10A-A3-A-2A5-2(22A3-)7(3A15B4A3-)3A2B10D3B2(4A3-3A15B)9(5A2-3A15B)5A2-2(3A17B2A3-)3A8B-8B2A3-3A8C-8C2A3-A3(10C-8C2A3-B)19C2A3-B18ACA4-4A6DA7B3A5-4A-A-3A2-A-A2-2A4-2(23A2-)7(4A15B4A2-)4A2B10D3B4A2-11(4A15B5A-)4A19BA-4A17BAB3-3A17B2A3-8A12C2(2A3-8A12B)2A3-B2(7A12B2A4-)18ABA4-4A6DA7B2(3A5-)2A3-A3-2A3-2(4A19-A-)7(24A-)7A10D7A-5A15B10A10(15B5A-4A)19BA-4A17BAB2-4A17B2A3-8A12C3(2A3-8A12B)2A4-7A12B2A4-18ABA4-4A6DA7B3A5-4A-A-3A-A5-2A3-2(3A20-A-)4A19-A-4A18-2A4(-5A16-3A)-9A6-9A-7A10D7A-5A15B10A10(15B5A-4A)19BA-4A17BAB2-4A17B2A2-9A12C3(2A3-8A12B)2A4-7A12B2A4-18ABA4-4A6DA7B2(3A5-)2A2-4A-2A3-2(3A20-A-)4A19-A-4A18-2A4(-5A16-3A)-8A8-8A-5A2B10D3B4A-5A15B10A10(15B5A-4A)19BA-4A17BAB2-4A17B2A2-9A12C2A2-9A2(12B2A3-8A)12B2A4-7A12B2A4-18ABA4-4A4D3A7B3A6-3A-A-4A4-A-2A3-2(3A20-A-)4A19-A-4A18-2A-5A16-3A-2(5A16-2(A-))5A16-3A-7A10-7A-5A2B10D3B4A-5A15B10A10(15B5A-4A)19BA-4A17BAB2-4A17B2A2-9A12C2A2-9A2(12B2A3-8A)12B2A4-7A12BA5-18ABA5-10A7B3A7-12A3-2A3-2(3A20-A-)4A19-A-4A18-2A-5A16-3A-2(5A16-2(A-))7A14-3A-7A10-7A-5A2B10D3B4A-5A15B10A10(15B5A-4A)19BA-4A17BAB2-4A17B2A2-9A12C2A2-9A2(12B2A3-8A)12B2A4-7A12BA5-18ABA6-5A-A2-10A8-16A3-2(3A20-A-)4A19-A-5A17-2A-5A16-3A-2(8A13-2(A-))5AB2A13-3A-5AB2A8-8A-5A3B8D4B4A-5A15B10A10(15B5A-4A)19BA-4A17BAB2-4A17B2A2-9A12C2A2-9A12B2A3-8A12B2A4-7A12BA6-6A12BA6-17ABA7-18A9-14A4-2(3A20-A-)4A18-2A-5A17-2A3(-9A12-3A)2(-5AB3A6-9A)-5A3B7D5B4A-5A15B4A2-4A15B3A-A9(-4A15B5A)-4A19BA-2AD2(A17B2A2-2A-)6A12C2A3-A-6A11B3A5-6A11B2A7-5A2(11B2A8-4A)11BA9-16A12-11A5-2(4A18-2A-)5A17-2A4(-24A)2(-5AB18A)-5A3(15B2A-A2-4A)15B2(2A-)4A15B5A7(-4A6B3AB10A)-4A6B3AB9A2-2A2D6B3AB9A3-A2-A5B3AB9A3-A2-5AB3AB9A6-5AB3AB8A7-5AB3AB8A8-4AB3AB8A9-15A11-2AB3AB6A12-13A29-2(6A15-2A2-)3(23A2-)10AB3ABAB6A2-10AB3AB8A2-5A2B2A2B3AB8A2-5A4(6B3AB6A-A3-4A)2(6B3AB6A-2A2-4A)7(6B3AB9A2-4A)6B3AB9A3-A2D6B3AB9A3-A2-A5B3AB9A3-A2-5AB3AB8A7-5AB3AB8A8-4AB3AB7A10-2(3AB)6A12-2AB3AB5A81-21A2(4-4AB16A)3(4-4A15B2A)7(5-3A15B2A)5-3A15B3A6(4-3A6B3AB8A)2(5-2A6B3AB8A)5-A2D5B3AB8A5-A2-A4B3AB7A6-A2-4AB3AB6A10-4AB3AB5A12-2(3AB)4A133-3(8AB3AB6A6-)8A11(B3AB6A7-7A)3(B3AB7A6-7A)4(B3AB7A7-6A)B3AB6A8-6AB3AB5A9-6AB3AB4A10-6A2(B3A)182-
