model
size = 25 32 30, scale = 0.05, origin = -y
material 
  colors = A:#FFF B:#F44800 C:#FFFB96 D:#CBDBFC E:#000 F:#847E87
voxels
2-15AE3A6-5A2(E2AE3A)6-4AE2A2(EA)2(E3A)6-4AEAE3A2(EA)E4A7-3AE2A2(EA)2(E3A)7-3(3AE)AE4A7-2AE15A7(7-7AE3AE6A)7-3(7AE3AE7A6-)7A4(E3AE7A7-6A)E3AE6A8-6AE3AE5A9-6AE3AE4A10-6A2(E3A)183-3(21A4-)9AC3AC7A4-21A4-6A3C12A5-5A3C12A6(5-8AE3AE7A)5-6(8AE3AE8A4-)8A2(E3AE8A5-7A)E3AE8A5-A2F4AE3AE8A5-A2-4AE3AE7A6-A2-4AE3AE6A10-4AE3AE5A12-2(3AE)4A131-2(6A15-2A2-)23A2-10AC3AC8A2-10A5B8A2-6A4C13A2-5A5C13A2(2-10AE3AE8A)3(3-9AE3AE8A)3-9(9AE3AE9A2-)9AE3AE9A3-A2F2(5AE3AE9A3-A2-)5AE3AE8A7-5AE3AE8A8-4AE3AE7A10-2(3AE)6A12-2AE3AE5A80-2(4A18-2A-)5A17-2A6(-24A)-10A3(E3AE9A2-9A)9(E3AE10A-9A)E3AE9A2-2A2F2(5AE3AE9A3-A2-)5AE3AE9A6-5AE3AE8A7-5AE3AE8A8-4AE3AE8A9-2(3AE)7A11-2AE3AE6A12-13A29-2(3A20-A-)4A18-2A-5A17-2A3(-9A12-3A)2(-9A6-9A)-3A2B2A2C6F5A2BCA-3A2B2A3C10A2BCA2-5(2A2B2A3C10A2BC2A-)6(2A2B2A3C15A-)2AFB2A3C14A2-2A-3A3C14A2-2A-5ACD3AD9A3-A-5AC14A5-5AC13A7-4A2(C13A8-3A)C12A9-8AC7A12-11A5-2(3A20-A-)4A19-A-5A17-2A-5A16-3A-2(8A13-2(A-))8A13-3A-8A8-8A-3A2B2A9F4A2BCA-3A2B15A2BC5A5(2B15A2BC2A-2A)6(2B20A-2A)2B18AE2-3AB19A2-8AB9D5A2-8AB14A3-7AB14A4-6A2(B13A6-5A)B13A7-4A10C4A9-14A4-2(3A20-A-)4A19-A-4A18-2A-5A16-3A-2(5A16-2(A-))7A14-3A-7A10-7A-3A2B2A10F3A2BCA-3A2B15A2BC5A6(2B15A2BC2A-2A)4(2B15A2B3A-2A)2B20A-2A2B18AE2-2A2B19A2-3A3C3B12D2A2-3A2(3C3B14A3-2A)3C3B14A4-A3C3B13A5-A3C14B2A6-2A14B2CA8-16A3-2(3A20-A-)4A19-A-4A18-2A-5A16-3A-2(5A16-2(A-))5A16-3A-7A10-7A-3A2B2A10F3A2BCA-3A2B15A2BC5A6(2B15A2BC2A-2A)4(2B15A2B3A-2A)2B20A-2A2B18AE2-2A2B19A2-2A7B12D2A2-2A7B2(14A3-AC6B)14A4-A6B13A5-A17B2A5-3A7B7E2CA7-8A6-3A3-2(3A20-A-)4A19-A-4A18-2A4(-5A16-3A)-8A8-8A-3A2B2A10F3A2BCA-3A2B15A2BC5A6(2B15A2BC2A-2A)4(2B15A2B3A-2A)2B20A-2A2B18AE2-2A2B19A2-2A7B12D2A2-2A7B2(14A3-AC6B)14A4-A6B14A4-A17B2A4-4ABFAF2AB7E2CA6-12A-A2-2A3-2(3A20-A-)4A19-A-4A18-2A4(-5A16-3A)-9A6-9A-3A4B10F5BCA-3A2B15A2BC5A10(2B15A2BC2A-2A)2B17AC2A-2A2B17ABE2-2A2B17ACA2-2A7B12DCA3-A7B2(12ACA3-AC6B)12ACA4-A6B14A4-A17B2A4-4A6FB7E2CA5-3A-A4-A3-2(A-)2A3-2(4A19-A-)7(24A-)3A4B10F5BCA-3A2B15A2BC5A10(2B15A2BC2A-2A)2B17AC2A-2A2B17ABE2-2A2B17ACA3-A7B12DCA3-A7B2(12ACA3-AC6B)12ACA4-A6B14A4-A17B2A4-4A6FB7E2CA5-10A7-2A4-9(23A2-)2A2B2A10F3A2BCA2-11(2A2B15A2BC2A-)2A2B17AC2A-2A2B17ABE3-A2B17ACA3-A7B12DCA3-A7B12ACA3-AC6B12ACA3-EC6B12ACA4-A6B14A4-A17B2A4-4A6FB7E2CA5-10A3(-A)-2A5-9(22A3-)A2B2A10F3A2(3CA3-A2B15A)10(3C2A2-A2B15A)3CA3-A2B15A3CA3-A2B17ACA3-A2B17DCA3-E19D3(CA3-EC18D)2A3-EC17BDA4-4A6FB7E2CA5-3A-6A-5A-2A6-7(20A5-)20A4-21A4-ACB2A10FA14(2B3CA3-ACB13A)4BCA3-E2B13D4BCA4-A14D4B2(CA4-A18D)CA3-EA18D2A4-A17BDA4-4A6FB7E2CA5-3A6-A2-A-A2-2A57-3(17A8-)17A7-18A7-19A5-21A4-AC3A10FA14(2B3CA3-AC14A)4BCA3-EB14D4BCA4-A14D4BCA3-E2(A18DCA4-)A18D2A4-A17BDA4-4A6FB7E2CA5-2(3A-)3A2-A2-3A57-3(17A8-)17A7-18A7-19A5-21A4-AC3A10FA14(2B3CA3-AC14A)4BCA3-EB14D4BCA4-A14D4B3(CA3-EA18D)2A3-EA17BDA4-4A6FB7E2CA5-10A2-A-A2-2A6-7(20A5-)20A4-21A4-ACB2A10FA14(2B3CA3-ACB13A)4BCA3-A2B13D4BCA3-EA14D4B3(CA4-A18D)2A4-A17BDA4-4A6FB7E2CA5-10A-A3-A-2A5-9(22A3-)A2B2A10F3A2(3CA3-A2B15A)10(3C2A2-A2B15A)3CA3-A2B15A3CA3-A2B8A-8ACA3-A2B8D-8DCA3-A10D2(-8DCA3-EC9D)-8DCA3-EC18D2A3-EC17BDA4-4A6FB7E2CA5-4A-A-3A2-A-A2-2A4-9(23A2-)2A2B2A10F3A2BCA2-11(2A2B15A2BC2A-)2A2B17AC2A-2A2B17ABE3-A2B17ACA3-A7B12DCA3-A7B12ACA3-AC6B12ACA3-EC6B12ACA4-A6B14A4-A17B2A4-4A6FB7E2CA5-3A5-2A3-A3-2A3-2(4A19-A-)7(24A-)3A4B10F5BCA-3A2B15A2BC5A10(2B15A2BC2A-2A)2B17AC2A-2A2B17ABE2-2A2B17ACA3-A7B12DCA3-A7B2(12ACA3-AC6B)12ACA4-A6B14A4-A17B2A4-4A6FB7E2CA5-4A-A-3A-A5-2A3-2(3A20-A-)4A19-A-4A18-2A4(-5A16-3A)-9A6-9A-3A4B10F5BCA-3A2B15A2BC5A10(2B15A2BC2A-2A)2B17AC2A-2A2B17ABE2-2A2B17ACA2-2A7B12DCA3-A7B2(12ACA3-AC6B)12ACA4-A6B14A4-A17B2A4-4A6FB7E2CA5-3A5-2A2-4A-2A3-2(3A20-A-)4A19-A-4A18-2A4(-5A16-3A)-8A8-8A-3A2B2A10F3A2BCA-3A2B15A2BC5A6(2B15A2BC2A-2A)4(2B15A2B3A-2A)2B20A-2A2B18AE2-2A2B19A2-2A7B12D2A2-2A7B2(14A3-AC6B)14A4-A6B14A4-A17B2A4-4A2FAF2AB7E2CA6-3A-A-4A4-A-2A3-2(3A20-A-)4A19-A-4A18-2A-5A16-3A-2(5A16-2(A-))5A16-3A-7A10-7A-3A2B2A10F3A2BCA-3A2B15A2BC5A6(2B15A2BC2A-2A)4(2B15A2B3A-2A)2B20A-2A2B18AE2-2A2B19A2-2A7B12D2A2-2A7B2(14A3-AC6B)14A4-A6B13A5-A17B2A5-3A7B7E2CA7-12A3-2A3-2(3A20-A-)4A19-A-4A18-2A-5A16-3A-2(5A16-2(A-))7A14-3A-7A10-7A-3A2B2A10F3A2BCA-3A2B15A2BC5A6(2B15A2BC2A-2A)4(2B15A2B3A-2A)2B20A-2A2B18AE2-2A2B19A2-3A3C3B12D2A2-3A2(3C3B14A3-2A)3C3B11AC2A4-A3C3B11ACA5-A3C14BCA6-2A3B-B2-7B2CA8-16A3-2(3A20-A-)4A19-A-5A17-2A-5A16-3A-2(8A13-2(A-))8A13-3A-8A8-8A-3A2B3A8F4A2BCA-3A2B15A2BC5A5(2B15A2BC2A-2A)6(2B20A-2A)2B18AE2-3AB19A2-8AB9D5A2-8AB14A3-7AB14A4-6A2(B13A6-5A)10B4A7-4A10C4A9-14A4-2(3A20-A-)4A18-2A-5A17-2A3(-9A12-3A)2(-9A6-9A)-3A2B2A2C6F5A2BCA-3A2B2A3C10A2BCA2-2A2B2A3C10A2BC-A4(-2A2B2A3C10A2BC2A)6(-2A2B2A3C15A)-2AFB2A3C14A2-2A-3A3C14A2-2A-5ACD3AD9A3-A-5AC14A5-5AC13A7-4A2(C13A8-3A)C12A9-8AC7A12-11A5-2(4A18-2A-)5A17-2A6(-24A)-10A3(E3AE7A-A2-9A)E3AE7A-2A8(-9AE3AE10A)-9AE3AE9A2-2A2F2(5AE3AE9A3-A2-)5AE3AE9A6-5AE3AE8A7-5AE3AE8A8-4AE3AE8A9-2(3AE)7A11-2AE3AE6A12-13A29-2(6A15-2A2-)23A2-10AE3AE8A2-10AE3BE8A2-6A4CE3AE8A2-5A5CE12A2-10AE3AE8A2-10A4(E3AE6A-A3-9A)2(E3AE6A-2A2-9A)7(E3AE9A2-9A)E3AE9A3-A2F2(5AE3AE9A3-A2-)5AE3AE8A7-5AE3AE8A8-4AE3AE7A10-2(3AE)6A12-2AE3AE5A81-3(21A4-)2(9AE3AE7A4-)6A3CE3AE7A5-5A3CE11A6(5-8AE3AE7A)5-6(8AE3AE8A4-)8A2(E3AE8A5-7A)E3AE8A5-A2F4AE3AE8A5-A2-4AE3AE7A6-A2-4AE3AE6A10-4AE3AE5A12-2(3AE)4A133-3(8AE3AE6A6-)8A11(E3AE6A7-7A)3(E3AE7A6-7A)4(E3AE7A7-6A)E3AE6A8-6AE3AE5A9-6AE3AE4A10-6A2(E3A)182-
