model
size = 25 32 30, scale = 0.05, origin = -y
material 
  colors = A:#01CDFE B:#FFF C:#F44800 D:#CBDBFC E:#847E87
voxels
2-15AB3A6-5A2(B2AB3A)6-4AB2A2(BA)2(B3A)6-4ABAB3A2(BA)B4A7-3AB2A2(BA)2(B3A)7-3(3AB)AB4A7-2AB15A7(7-7AB3AB6A)7-3(7AB3AB7A6-)7A4(B3AB7A7-6A)B3AB6A8-6AB3AB5A9-6AB3AB4A10-6A2(B3A)183-4(21A4-)2A2C17A4-2A2C17A3(5-20A)4(5-8AB3AB7A)5-6(8AB3AB8A4-)8A2(B3AB8A5-7A)B3AB8A5-A2E4AB3AB8A5-A2-4AB3AB7A6-A2-4AB3AB6A10-4AB3AB5A12-2(3AB)4A131-2(6A15-2A2-)2(23A2-)3(3A2C18A2-)23A2-23A3(3-9AB3AB8A)3-9(9AB3AB9A2-)9AB3AB9A3-A2E2(5AB3AB9A3-A2-)5AB3AB8A7-5AB3AB8A8-4AB3AB7A10-2(3AB)6A12-2AB3AB5A80-2(4A18-2A-)5A17-2A-24A3(-3A2C19A)2(-24A)-10A3(B3AB9A2-9A)9(B3AB10A-9A)B3AB9A2-2A2E2(5AB3AB9A3-A2-)5AB3AB9A6-5AB3AB8A7-5AB3AB8A8-4AB3AB8A9-2(3AB)7A11-2AB3AB6A12-13A29-2(3A20-A-)4A18-2A-5A17-2A3(-9A12-3A)2(-9A6-9A)-9A6EB8A-10AB3A2B8A2-11(9AB3A2B9A-)2AE2(6AB3A2B8A2-2A-)6AD3A2D8A3-A-6AB3A2B8A5-6AB3A2B7A7-5A2(B3A2B7A8-4A)B3A2B6A9-4AC11A12-11A5-2(3A20-A-)4A19-A-5A17-2A-5A16-3A-2(8A13-2(A-))8A13-3A-8A8-8A-6AB9E8A-6A10B15A11(10B9A-5A)10B7AB2-5A10B8A2-6A3C6D8A2-6A3C6B8A3-5A3C6B8A4-4A2(3C6B7A6-3A)3C6B7A7-18A9-14A4-2(3A20-A-)4A19-A-4A18-2A-5A16-3A-2(5A16-2(A-))7A14-3A-7A10-4AC2A-3A2C2B10E3B2C2A-3A2C15B2C6A10(2C15B2C3A-2A)2C17B3A-2A2C17BCB2-2A2C17B2A2-2A2C2A3C12D2A2-2A2C2A3C12B2A3-A2C2A3C12B2A3-5A3C12B2A4-4A3C12BA5-4A14CBA6-19A8-16A3-2(3A20-A-)4A19-A-4A18-2A-5A16-3A-2(5A16-2(A-))5A16-3A-7A10-4AC2A-3A2C2B10E3B2C2A-3A2C15B2C6A10(2C15B2C3A-2A)2C17B3A-2A2C17BCB2-2A2C17B2A2-2A2C2A3C12D2A2-2A2C2A3C12B2A3-A2C2A3C12B2A3-5A3C12B2A4-4A3C12BA5-4A14CBA5-4A6C7B3A7-8A6-3A3-2(3A20-A-)4A19-A-4A18-2A4(-5A16-3A)-8A8-5AC2A-3A2C2B10E3B2C2A-3A2C15B2C6A10(2C15B2C3A-2A)2C17B3A-2A2C17BCB2-2A2C17B2A2-2A2C2A3C12D2A2-2A2C2A3C12B2A3-A2C2A3C12B2A3-5A2(3C12B2A4-4A)14CBA4-5A6C7B3A6-12A-A2-2A3-2(3A20-A-)4A19-A-4A18-2A4(-5A16-3A)-9A6-6AC2A-3A4C10E5C2A-3A2C15B2C6A10(2C15B2C3A-2A)2C17B3A-2A2C17BCB2-2A2C17B2A2-2A2C2A3C12D2(2A3-A2C2A3C12B)2A3-5A2(3C12B2A4-4A)14CBA4-4A6EC7B3A5-3A-A4-A3-2(A-)2A3-2(4A19-A-)6(24A-)15A7C2A-3A4C10E5C2A-3A2C15B2C6A10(2C15B2C3A-2A)2C17B3A-2A2C17BCB2-2A2C17B2A3-A2C2A3C12D2(2A3-A2C2A3C12B)2A3-5A2(3C12B2A4-4A)14CBA4-5A5EC7B3A5-10A7-2A4-2(23A2-)2A2C5B14A5(2-2A2C10B9A)2-2A2C15B2C2A2-2A2C2B10E3B2C2A2-11(2A2C15B2C3A-)2A2C17B3A-2A2C17BCB3-A2C17B2A3-A2C2A3C12D2(2A3-A2C2A3C12B)2A3-B2(4A3C12B2A4-)4A14CBA4-4A6EC7B3A5-10A3(-A)-2A5-22A3-8A5C4(9A3-3A10B)2(9A3-A2C10B)9A3-A2C15B2C2A3-A2C2B10E3B2(2C2A3-A2C15B)9(2C3A2-A2C15B)2C3A2-3(A2C17B2A3-)A2C2(2A15D2A3-B2D)2A3(15D2A3-B4A)14CDA4-4A6EC7B3A5-3A-6A-5A-2A6-2(20A5-)2(2A10C8A5-)2AC9B8A5-2A2(10B8A5-AC)10B8A4-2AC13B4CA4-2AC2B10EB14(4C2A3-2AC13B)4C2A3-B2C2(2A11D4C2A4-AD)2A15D2A4-4A15D2A3-B4A15D2A4-4A14CDA4-4A6EC7B3A5-3A6-A2-A-A2-2A57-3(17A8-)17A7-AC16A7-AB17A5-2AB18A4-2AB19A14(3-2A14B4C2A)3-BCD2A11D4C2A4-AD2A11D4C2A3-BCD2A3(15D2A4-4A)14CDA4-4A6EC7B3A5-2(3A-)3A2-A2-3A57-3(17A8-)17A7-AC16A7-AB17A5-2AB18A4-2AB19A14(3-2A14B4C2A)3-BCD2A11D4C2A4-AD2A11D4C2A3-BCD2A3(15D2A3-B4A)14CDA4-4A6EC7B3A5-10A2-A-A2-2A6-2(20A5-)2(2A10C8A5-)2AC9B8A5-2A2(10B8A5-AC)10B8A4-2AC13B4CA4-2AC2B10EB14(4C2A3-2AC13B)4C2A3-A2C2A11D4C2A3-BAD2A11D4C2A4-AD2A3(15D2A4-4A)14CDA4-4A6EC7B3A5-10A-A3-A-2A5-22A3-8A5C4(9A3-3A10B)2(9A3-A2C10B)9A3-A2C15B2C2A3-A2C2B10E3B2(2C2A3-A2C15B)9(2C3A2-A2C15B)2C3A2-2(A2C17B2A3-)A2C8B-8B2A3-A2C2A6D-8D2A3-A2(2D2A6D-8D2A3-B)4A6D-8D2A3-B4A15D2A3-B4A14CDA4-4A6EC7B3A5-4A-A-3A2-A-A2-2A4-2(23A2-)2A2C5B14A5(2-2A2C10B9A)2-2A2C15B2C2A2-2A2C2B10E3B2C2A2-11(2A2C15B2C3A-)2A2C17B3A-2A2C17BCB3-A2C17B2A3-A2C2A3C12D2(2A3-A2C2A3C12B)2A3-B2(4A3C12B2A4-)4A14CBA4-4A6EC7B2(3A5-)2A3-A3-2A3-2(4A19-A-)6(24A-)15A7C2A-3A4C10E5C2A-3A2C15B2C6A10(2C15B2C3A-2A)2C17B3A-2A2C17BCB2-2A2C17B2A3-A2C2A3C12D2(2A3-A2C2A3C12B)2A3-5A2(3C12B2A4-4A)14CBA4-5A5EC7B3A5-4A-A-3A-A5-2A3-2(3A20-A-)4A19-A-4A18-2A4(-5A16-3A)-9A6-6AC2A-3A4C10E5C2A-3A2C15B2C6A10(2C15B2C3A-2A)2C17B3A-2A2C17BCB2-2A2C17B2A2-2A2C2A3C12D2(2A3-A2C2A3C12B)2A3-5A2(3C12B2A4-4A)14CBA4-4A6EC7B2(3A5-)2A2-4A-2A3-2(3A20-A-)4A19-A-4A18-2A4(-5A16-3A)-8A8-5AC2A-3A2C2B10E3B2C2A-3A2C15B2C6A10(2C15B2C3A-2A)2C17B3A-2A2C17BCB2-2A2C17B2A2-2A2C2A3C12D2A2-2A2C2A3C12B2A3-A2C2A3C12B2A3-5A2(3C12B2A4-4A)14CBA4-5A3E3C7B3A6-3A-A-4A4-A-2A3-2(3A20-A-)4A19-A-4A18-2A-5A16-3A-2(5A16-2(A-))5A16-3A-7A10-4AC2A-3A2C2B10E3B2C2A-3A2C15B2C6A10(2C15B2C3A-2A)2C17B3A-2A2C17BCB2-2A2C17B2A2-2A2C2A3C12D2A2-2A2C2A3C12B2A3-A2C2A3C12B2A3-5A3C12B2A4-4A3C12BA5-4A14CBA5-4A6C7B3A7-12A3-2A3-2(3A20-A-)4A19-A-4A18-2A-5A16-3A-2(5A16-2(A-))7A14-3A-7A10-4AC2A-3A2C2B10E3B2C2A-3A2C15B2C6A10(2C15B2C3A-2A)2C17B3A-2A2C17BCB2-2A2C17B2A2-2A2C2A3C12D2A2-2A2C2A3C12B2A3-A2C2A3C12B2A3-5A3C12B2A4-4A3C12BA5-4A14CBA6-5A-A2-10A8-16A3-2(3A20-A-)4A19-A-5A17-2A-5A16-3A-2(8A13-2(A-))8A13-3A-8A8-8A-6A2B8E8A-6A10B15A11(10B9A-5A)10B7AB2-5A10B8A2-6A3C6D8A2-6A3C6B8A3-5A3C6B8A4-4A2(3C6B7A6-3A)9C7A7-18A9-14A4-2(3A20-A-)4A18-2A-5A17-2A3(-9A12-3A)2(-9A6-9A)-9A6EB8A-10AB3A2B8A2-9AB3A2B7A-A10(-9AB3A2B9A)-2AE2(6AB3A2B8A2-2A-)6AD3A2D8A3-A-6AB3A2B8A5-6AB3A2B7A7-5A2(B3A2B7A8-4A)B3A2B6A9-4AC11A12-11A5-2(4A18-2A-)5A17-2A-24A3(-3A2C19A)2(-24A)-10A3(B3AB7A-A2-9A)B3AB7A-2A8(-9AB3AB10A)-9AB3AB9A2-2A2E2(5AB3AB9A3-A2-)5AB3AB9A6-5AB3AB8A7-5AB3AB8A8-4AB3AB8A9-2(3AC)7A11-2AB3AB6A12-13A29-2(6A15-2A2-)2(23A2-)3(3A2C18A2-)23A2-21A4(-A3-9AB3AB6A)-2A2-9AB3AB6A-2A8(2-9AB3AB9A)3-A2E2(5AB3AB9A3-A2-)5AB3AB8A7-5AB3AB8A8-4AB3AB7A10-2(3AB)6A12-2AB3AB5A81-4(21A4-)2A2C17A4-2A2C17A3(5-20A)4(5-8AB3AB7A)5-6(8AB3AB8A4-)8A2(B3AB8A5-7A)B3AB8A5-A2E4AB3AB8A5-A2-4AB3AB7A6-A2-4AB3AB6A10-4AB3AB5A12-2(3AB)4A133-3(8AB3AB6A6-)8A11(B3AB6A7-7A)3(B3AB7A6-7A)4(B3AB7A7-6A)B3AB6A8-6AB3AB5A9-6AB3AB4A10-6A2(B3A)182-
