model
size = 32 28 24, scale = 0.05, origin = -y
material 
  colors = A:#54FC00 B:#FC002A C:#00DF70 D:#2500DF E:#DF5D00 F:#005049 G:#DF00DF H:#000 I:#DF0082 J:#006C63 K:#FCD200 L:#FC0000 M:#79FF36 N:#FC6900 O:#0095DF P:#36BCFF Q:#FF791A R:#9FFF70 S:#00332F
voxels
368-H30-AHA61-E33-E159-E635-HE3-EH27-AHA29-E2O29-2OE29-E32-E30-E-E31-O30-OE602-A7-A23-A7-A24-2A3-2A27-3E61-E31-OEO29-EOE601-3(E9-E21-)E9-E22-2A5-2A25-5E28-3A408-H11-H19-A11-A19-H11-H83-H11-H19-H11-H52-4(H9-H21-)H9-H22-A7-A24-7E19-J-J4-5A19-3J-J26-2J2-J-J26-J-A-J26-J-J2-2J26-J-3J28-J-J256-11(A11-A19-)A11-A16-3B-A9-A16-2(2B-)9E16-B-3B-B-7A16-B-5B-B22-11B21-B-7B-B21-11B22-B-5B-B24-B-3B-B26-2B-2B28-3B256-H11-H2(2(19-A11-A)2(19-H11-H))19-A11-A20-A9-A22-9E22-L-7A22-2(L30-)L37-2N-2N26-2N3-2N25-N-2N2-N27-NHN27-N2-2N-N25-2N3-2N26-2N-2N111-F32-F31-F30-F31-F7-2(A11-)F7-3(A11-A12-F6-)2(A11-)F7-A11-A10-F8-A11-A10-2F7-A11-A10-F-F7-A9-A13-F8-9E14-F8-F7A16-F6-F25-2(F4-)3D20-F2-F4-2(D-)D20-2F4-7D24-4D-4D22-D-7D-D21-2(3D-)3D21-D-7D-D22-4D-4D24-7D26-2(D-)D28-3D15-2F31-FC30-CFC29-CFC28-CF2C28-CFC6-H11-H10-CFC30-CFC6-H9-H12-CFC6-H9-H11-2CFC6-H9-H11-CFC7-H9-H10-CF2C7-H9-H10-C2F2C6-H9-H10-2(CF)C2(7-A)12-2CFC7-C7E3-3M8-CF2C5-CFC2AP2A2(3-M)8-CF2C3-CFC3-L4-M5-M7-2CFC2-CFC4-L3-M2-3M2-M7-2(2CF)2C4-L2-M2-3M-M2-M7-2C2F2C5-L2(2-M)-S2M2-M8-4C6-L2-M2-2M-2M2-M18-L3-M2-3M2-M19-L4-R5-M26-M3-M28-3M136-F32-F31-F30-2(F31-)F32-2(F7-E9-E13-)F7-E9-E12-F8-E9-E11-F2(9-E)11-2F8-E9-E11-F-F8-2A5-2A14-F10-5E4-3B9-F8-F-K3A4-5B9-F6-F2-K6-3(B-)B9-F4-F9-B-5B-B9-F2-F9-11B9-2F10-2B-5B-2B21-11B22-B-5B-B24-3(B-)B26-5B28-3B287-J-J28-2(J-)J26-3J-3J14-A7-A2(-J)3-J-J13-A7-A2-J2-L2-J14-A7-A2(-J)3-J-J13-A7-A2-3J-3J14-A7-A3-2(J-)J16-2A3-2A5-J-J17-K-3E-L24-2I2-C3-L24-K7-L23-K8-2(L32-)L416-3L28-5D26-L2(D-)DL24-4D-4D22-L4(D-)DL13-HE3-EH-L2D-3D-2DL13-HE3-EH-L4(D-)DL13-HE3-QH2-4D-4D14-HE3-EH3-L2(D-)DL17-3A6-5D19-C8-3L16-KI-3G25-2I3-C27-K31-K619-3L20-3A3-3L23-AHA3L26-3A94-C26-KI2-3G24-3I3-C26-K4-C26-K350-2(K30-IK31-K127-)K31-K30-2I5-C25-2I3-3G24-K5-C31-C312-K31-I31-2(2I30-)K63-2(K31-)2I30-K31-K63-K31-K30-3I30-KI30-K6-C30-3G30-C31-C247-K30-2I31-KI30-K31-K30-3I30-K30-2I31-2I30-K31-2I29-3I30-K30-2I31-2I30-K103-C30-3G30-C246-K31-2I126-K30-2I31-KI30-K63-K31-K30-3I30-KI30-K136-C30-3G30-C245-I191-KI30-K127-2(K31-)K105-2(C31-)C30-3G30-C735-C31-C30-3G29-3G30-C351-2(2(C31-)C95-)3(C31-)C30-3G30-C31-C351-2(C30-3G29-3G30-2(C31-))2(C31-)C30-3G29-3G30-C31-C350-3G29-3G30-C31-C30-2(3G29-)3G30-C31-C30-3G29-3G30-C31-C30-3G30-C31-C415-G127-2(C31-)C95-C31-C30-3G29-3G30-C31-C767-2(C31-)C495-
