model
size = 31 29 26, scale = 0.05, origin = -y
material 
  colors = A:#00FFFA B:#F00 C:#E900FF D:#000 E:#A64500
voxels
---------B-----------B--------- ------------------------------- ------------------------------- ------------------------------- ------------------------------- ------------------------------- ------------------------------- ------------------------------- ------------------------------- ------------------------------- ------------------------------- ------------------------------- ------------------------------- ------------------------------- ------------------------------- ------------------------------- ------------------------------- ------------------------------- ------------------------------- ------------------------------- ------------------------------- ------------------------------- ------------------------------- ------------------------------- ------------------------------- ------------------------------- ------------------------------- ------------------------------- ------------------------------- 
--------B-------------B-------- ------------------------------- ------------------------------- ------------------------------- ------------------------------- ------------------------------- ------------------------------- ------------------------------- ------------------------------- ------------------------------- ------------------------------- ------------------------------- ------------------------------- ------------------------------- ------------------------------- ------------------------------- ------------------------------- ------------------------------- ------------------------------- ------------------------------- ------------------------------- ------------------------------- ------------------------------- ------------------------------- ------------------------------- ------------------------------- ------------------------------- ------------------------------- ------------------------------- 
--------B-------------B-------- ------------------------------- ------------------------------- ------------------------------- ------------------------------- ------------------------------- ------------------------------- ------------------------------- ------------------------------- ------------------------------- ------------------------------- ------------------------------- ------------------------------- ----------B---------B---------- -----------B-------B----------- ------------B-----B------------ ------------------------------- ------------------------------- ------------------------------- ------------------------------- ------------------------------- ------------------------------- ------------------------------- ------------------------------- ------------------------------- ------------------------------- ------------------------------- ------------------------------- ------------------------------- 
-------B---------------B------- ------------------------------- ------------------------------- ------------------------------- ------------------------------- ------------------------------- ------------------------------- ------------------------------- ------------------------------- ------------------------------- ------------------------------- ------------------------------- ---------B-----------B--------- ------------------------------- ------------------------------- ------------------------------- -------------B---B------------- ------------------------------- ------------------------------- ------------------------------- ------------------------------- ------------------------------- ------------------------------- ------------------------------- ------------------------------- ------------------------------- ------------------------------- ------------------------------- ------------------------------- 
-------B---------------B------- ------------------------------- ------------------------------- ------------------------------- ------------------------------- ------------------------------- ------------------------------- ------------------------------- ------------------------------- ------------------------------- ------------------------------- --------B-------------B-------- ------------------------------- ------------------------------- ------------------------------- ------------------------------- ------------------------------- --------------BBB-------------- --------------DDD-------------- --------------D-D-------------- --------------DDD-------------- --------------D-D-------------- --------------D-D-------------- --------------B-B-------------- --------------B-B-------------- --------------D-D-------------- ------------------------------- ------------------------------- ------------------------------- 
------B-----------------B------ ------------------------------- ------------------------------- ------------------------------- ------------------------------- ------------------------------- ------------------------------- ------------------------------- ------------------------------- ------------------------------- ------------------------------- -------B---------------B------- ------------------------------- ------------------------------- ---------------B--------------- ---------------A--------------- --------------DDD-------------- ------------A-CCC-A------------ ------------AACCCAA------------ ------------BACCCAB------------ ------------BBCCCBB------------ ------------ABCCCBA------------ ------------AACCCAA------------ -------------ACCCA------------- ------------AACCCAA------------ ------------AACCCAA------------ --------------DDD-------------- ------------------------------- ------------------------------- 
------B-----------------B------ ------------------------------- ------------------------------- ------------------------------- ------------------------------- ------------------------------- ------------------------------- ------------------------------- ------------------------------- ------------------------------- ------------------------------- ------B-----------------B------ ------------------------------- ------------------------------- -------------BCCCB------------- -------------ACCCA------------- ------------DD---DD------------ -----------ACC---CCA----------- -----------ACC---CCA----------- -----------BAC---CAB----------- -----------BAA---AAB----------- -----------AAA---AAA----------- ------------AA---AA------------ ------------CA---AC------------ ------------AA---AA------------ -----------AAA---AAA----------- ------------DD---DD------------ --------------AAA-------------- ------------------------------- 
-----B-------------------B----- ------------------------------- ------------------------------- ------------------------------- ------------------------------- ------------------------------- ------------------------------- ------------------------------- ------------B-----B------------ -------------B---B------------- --------------AAA-------------- --------------ABA-------------- -----B--------ABA--------B----- --------------AAA-------------- -----------BCC---CCB----------- -----------ACC---CCA----------- -----------D-------D----------- ----------AC-------CA---------- ----------AC-------CA---------- ----------BA-------AB---------- ----------BA-------AB---------- ----------AA-------AA---------- -----------C-------C----------- -----------C-------C----------- -----------C-------C----------- ----------AA-------AA---------- -----------D-------D----------- ------------AAAAAAA------------ --------------AAA-------------- 
-----B-------------------B----- ------------------------------- ------------------------------- ------------------------------- ------------------------------- ------------------------------- ------------------------------- ------------------------------- ------------------------------- ------------------------------- ------------------------------- ------------------------------- ----B-------BA---AB-------B---- ---B--------AA---AA--------B--- -----------C-------C----------- -----------C-------C----------- ----------D---------D---------- ----------A---------A---------- ---------AC---------CA--------- ---------BA---------AB--------- ---------BA---------AB--------- ---------AA---------AA--------- ----------C---------C---------- ----------C---------C---------- ----------C---------C---------- ---------AA---------AA--------- ----------D---------D---------- -----------AAAAAAAAA----------- ------------AAAAAAA------------ 
----B---------------------B---- ------------------------------- ------------------------------- ------------------------------- ------------------------------- ------------------------------- ------------------------------- ------------------------------- ------------------------------- ------------------------------- ------------------------------- ------------------------------- -----------A-------A----------- -----------A-------A----------- ---B-----BC---------CB-----B--- ---------AC---------CA--------- ---------D-----------D--------- ---------D-----------D--------- ---------A-----------A--------- --------AA-----------AA-------- --------BA-----------AB-------- --------AA-----------AA-------- --------AA-----------AA-------- ---------C-----------C--------- --------AA-----------AA-------- --------AA-----------AA-------- ---------D-----------D--------- ----------AAAAAAAAAAA---------- -----------AAAAAAAAA----------- 
----B---------------------B---- ------------------------------- ------------------------------- ------------------------------- ------------------------------- ------------------------------- ------------------------------- ------------------------------- ------------------------------- ------------------------------- ------------------------------- ------------------------------- ----------B---------B---------- ----------A---------A---------- ---------C-----------C--------- --B------C-----------C------B-- --------D-------------D-------- -------BB-------------BB------- --------D-------------D-------- -------AC-------------CA------- -------BA-------------AB------- -------BA-------------AB------- -------AA-------------AA------- -------AA-------------AA------- -------AA-------------AA------- -------AA-------------AA------- --------D-------------D-------- ---------AAAAAAAAAAAAA--------- ----------AAAAAAAAAAA---------- 
-----B-------------------B----- ---------B-----------B--------- ------------------------------- ---------A-----------A--------- ---------A-----------A--------- ---------A-----------A--------- ------------------------------- ---------B-----------B--------- ---------B-----------B--------- ------------------------------- ------------------------------- ------------------------------- ----------A---------A---------- ----------A---------A---------- --------BC-----------CB-------- --------AC-----------CA-------- --B-----D-------------D-----B-- --------D-------------D-------- -------BA-------------AB------- -------BA-------------AB------- -------BA-------------AB------- --------C-------------C-------- --------C-------------C-------- --------C-------------C-------- --------C-------------C-------- --------C-------------C-------- --------D-------------D-------- ---------AAAAAAAAAAAAA--------- ----------AAAAAAAAAAA---------- 
-----B-------------------B----- ------------------------------- ---------A-----------A--------- ---------B-----------B--------- ---------B-----------B--------- ---------B-----------B--------- ---------A-----------A--------- ---------A-----------A--------- ---------A-----------A--------- ---------A-----------A--------- ---------B-----------B--------- ---------B-----------B--------- ---------B-----------B--------- ---------A-----------A--------- --------C-------------C-------- --------C-------------C-------- -------D---------------D------- --B----C---------------C----B-- ------BA---------------AB------ ------BA---------------AB------ -------D---------------D------- -------D---------------D------- -------D---------------D------- -------D---------------D------- -------D---------------D------- -------D---------------D------- -------D---------------D------- --------AAAAAAAAAAAAAAA-------- ---------AAAAAAAAAAAAA--------- 
------B-----------------B------ ------------------------------- ---------A-----------A--------- ---------B-----------B--------- ------------------------------- ---------B-----------B--------- ---------A-----------A--------- ---------B-----------B--------- ---------B-----------B--------- ---------A--------------------- ---------A-----------A--------- ---------A-----------A--------- ---------A-----------A--------- ---------A-----------A--------- -------BC-------------CB------- -------AC-------------CA------- -------D---------------D------- ------BC---------------CB------ ---AAABC---------------CBAAA--- ---A-ABC---------------CBA-A--- ---AAA-D---------------D-AAA--- --BDDDBC---------------CBDDDB-- --BD-DBC---------------CBD-DB-- --BDDDBC---------------CBDDDB-- ---AAA-D---------------D-AAA--- ---A-A-D---------------D-A-A--- ---AAA-D---------------D-AAA--- --------AAAAAAAAAAAAAAA-------- ---------AAAAAAAAAAAAA--------- 
------B-----------------B------ ------------------------------- ---------A-----------A--------- ---------B-----------B--------- ---------B-----------B--------- ---------B-----------B--------- ---------A-----------A--------- ---------A-----------A--------- ---------A-----------A--------- ---------A-----------A--------- ---------B-----------B--------- ---------B-----------B--------- ---------B-----------B--------- ---------A-----------A--------- --------C-------------C-------- --------C-------------C-------- -------D---------------D------- --B----C---------------C----B-- ------BA---------------AB------ ------BA---------------AB------ -------D---------------D------- -------D---------------D------- -------D---------------D------- -------D---------------D------- -------D---------------D------- -------D---------------D------- -------D---------------D------- --------AAAAAAAAAAAAAAA-------- ---------AAAAAAAAAAAAA--------- 
-------B---------------B------- ------------------------------- ------------------------------- ---------A-----------A--------- ---------A-----------A--------- ---------A-----------A--------- ------------------------------- ---------B-----------B--------- ---------B-----------B--------- ------------------------------- ------------------------------- ------------------------------- ----------A---------A---------- ----------A---------A---------- --------BC-----------CB-------- --------AC-----------CA-------- -B------D-------------D------B- --------D-------------D-------- -------BA-------------AB------- -------BA-------------AB------- -------BA-------------AB------- --------C-------------C-------- --------C-------------C-------- --------C-------------C-------- --------C-------------C-------- --------C-------------C-------- --------D-------------D-------- ---------AAAAAAAAAAAAA--------- ----------AAAAAAAAAAA---------- 
-------B---------------B------- ------------------------------- ------------------------------- ------------------------------- ------------------------------- ------------------------------- ------------------------------- ------------------------------- ------------------------------- ------------------------------- ------------------------------- ------------------------------- ----------B---------B---------- ----------A---------A---------- ---------C-----------C--------- -B-------C-----------C-------B- --------D-------------D-------- -------BB-------------BB------- --------D-------------D-------- -------AC-------------CA------- -------BA-------------AB------- -------BA-------------AB------- -------AA-------------AA------- -------AA-------------AA------- -------AA-------------AA------- -------AA-------------AA------- --------D-------------D-------- ---------AAAAAAAAAAAAA--------- ----------AAAAAAAAAAA---------- 
--------B-------------B-------- ------------------------------- ------------------------------- ------------------------------- ------------------------------- ------------------------------- ------------------------------- ------------------------------- ------------------------------- ------------------------------- ------------------------------- ------------------------------- -----------A-------A----------- -----------A-------A----------- B--------BC---------CB--------B ---------AC---------CA--------- ---------D-----------D--------- ---------D-----------D--------- ---------A-----------A--------- --------AA-----------AA-------- --------BA-----------AB-------- --------AA-----------AA-------- --------AA-----------AA-------- ---------C-----------C--------- --------AA-----------AA-------- --------AA-----------AA-------- ---------D-----------D--------- ----------AAAAAAAAAAA---------- -----------AAAAAAAAA----------- 
---------BB---------BB--------- ------------------------------- ------------------------------- ------------------------------- ------------------------------- ------------------------------- ------------------------------- ------------------------------- ------------------------------- ------------------------------- ------------------------------- ------------------------------- ------------BA---AB------------ B-----------AA---AA-----------B -----------C-------C----------- -----------C-------C----------- ----------D---------D---------- ----------E---------A---------- ---------AC---------CA--------- ---------BA---------AB--------- ---------BA---------AB--------- ---------AA---------AA--------- ----------C---------C---------- ----------C---------C---------- ----------C---------C---------- ---------AA---------AA--------- ----------D---------D---------- -----------AAAAAAAAA----------- ------------AAAAAAA------------ 
-----------BB--B--BB----------- ------------------------------- ------------------------------- ------------------------------- -------------A---A------------- --------------BBB-------------- --------------B-B-------------- --------------BBB-------------- --------------AAA-------------- --------------ABA-------------- --------------ABA-------------- --------------ABA-------------- -B------------ABA------------B- --------------AAA-------------- -----------BCC---CCB----------- -----------ACC---CCA----------- -----------D-------D----------- ----------AC-------CA---------- ----------AC-------CA---------- ----------BA-------AB---------- ----------BA-------AB---------- ----------AA-------AA---------- -----------C-------C----------- -----------C-------C----------- -----------C-------C----------- ----------AA-------AA---------- -----------D-------D----------- ------------AAAAAAA------------ --------------AAA-------------- 
-------------BB-BB------------- ------------------------------- ------------------------------- ------------------------------- ------------------------------- ------------------------------- ------------------------------- ------------------------------- ------------------------------- ------------------------------- ------------------------------- -B---------------------------B- ------------------------------- ------------------------------- -------------BCCCB------------- -------------ACCCA------------- ------------DD---DD------------ -----------ACC---CCA----------- -----------ACC---CCA----------- -----------BAC---CAB----------- -----------BAA---AAB----------- -----------AAA---AAA----------- ------------AA---AA------------ ------------CA---AC------------ ------------AA---AA------------ -----------AAA---AAA----------- ------------DD---DD------------ --------------AAA-------------- ------------------------------- 
-----------BB-----BB----------- ------------------------------- ------------------------------- ------------------------------- ------------------------------- ------------------------------- ------------------------------- ------------------------------- ------------------------------- ------------------------------- --B-------------------------B-- ------------------------------- ------------------------------- ------------------------------- ---------------B--------------- ---------------A--------------- --------------DDD-------------- ------------A-CCC-A------------ ------------AACCCAA------------ ------------BACCCAB------------ ------------BBCCCBB------------ ------------ABCCCBA------------ ------------AACCCAA------------ -------------ACCCA------------- ------------AACCCAA------------ ------------AACCCAA------------ --------------DDD-------------- ------------------------------- ------------------------------- 
----------B---------B---------- ------------------------------- ------------------------------- ------------------------------- ------------------------------- ------------------------------- ------------------------------- ------------------------------- ------------------------------- --B-------------------------B-- ------------------------------- ------------------------------- ------------------------------- ------------------------------- ------------------------------- ------------------------------- ------------------------------- --------------BBB-------------- --------------DDD-------------- --------------D-D-------------- --------------DDD-------------- --------------D-D-------------- --------------D-D-------------- --------------B-B-------------- --------------B-B-------------- --------------D-D-------------- ------------------------------- ------------------------------- ------------------------------- 
------------------------------- ---------B-----------B--------- ------------------------------- ------------------------------- ------------------------------- ------------------------------- ------------------------------- ------------------------------- ---B-----------------------B--- ------------------------------- ------------------------------- ------------------------------- ------------------------------- ------------------------------- ------------------------------- ------------------------------- ------------------------------- ------------------------------- ------------------------------- ------------------------------- ------------------------------- ------------------------------- ------------------------------- ------------------------------- ------------------------------- ------------------------------- ------------------------------- ------------------------------- ------------------------------- 
------------------------------- ------------------------------- --------B-------------B-------- -------B---------------B------- ------------------------------- ------------------------------- ----B---------------------B---- ---B-----------------------B--- ------------------------------- ------------------------------- ------------------------------- ------------------------------- ------------------------------- ------------------------------- ------------------------------- ------------------------------- ------------------------------- ------------------------------- ------------------------------- ------------------------------- ------------------------------- ------------------------------- ------------------------------- ------------------------------- ------------------------------- ------------------------------- ------------------------------- ------------------------------- ------------------------------- 
------------------------------- ------------------------------- ------------------------------- ------------------------------- ------B-----------------B------ -----B-------------------B----- ------------------------------- ------------------------------- ------------------------------- ------------------------------- ------------------------------- ------------------------------- ------------------------------- ------------------------------- ------------------------------- ------------------------------- ------------------------------- ------------------------------- ------------------------------- ------------------------------- ------------------------------- ------------------------------- ------------------------------- ------------------------------- ------------------------------- ------------------------------- ------------------------------- ------------------------------- ------------------------------- 
