model
size = 22 21 4, scale = 0.05, origin = -y
material 
  colors = A:#FF0 B:#181808
voxels
AAA---AA------AA---AAA AAA---AA------AA---AAA ---AAA--AAAAAA--AAA--- ---AAA--AAAAAA--AAA--- ---AAA--AAAAAA--AAA--- ------AA------AA------ ------AA------AA------ ------AA------AA------ AAAAAAAAAAAAAAAAAAAAAA AAAAAAAAAAAAAAAAAAAAAA AAAAAAAAAAAAAAAAAAAAAA AAAAAA--AAAAAA--AAAAAA AAAAAA--AAAAAA--AAAAAA ---AAAAAAAAAAAAAAAA--- ---AAAAAAAAAAAAAAAA--- ---AAAAAAAAAAAAAAAA--- ------AAAAAAAAAA------ ------AAAAAAAAAA------ ------AAAAAAAAAA------ --------AAAAAA-------- --------AAAAAA-------- 
AAA---AA------AA---AAA AAA---AA------AA---AAA ---AAA--AAAAAA--AAA--- ---AAA--AAAAAA--AAA--- ---AAA--AAAAAA--AAA--- ------AA------AA------ ------AA------AA------ ------AA------AA------ AAAAAAAAAAAAAAAAAAAAAA AAAAAAAAAAAAAAAAAAAAAA AAAAAAAAAAAAAAAAAAAAAA AAAAAABBAAAAAABBAAAAAA AAAAAABBAAAAAABBAAAAAA ---AAAAAAAAAAAAAAAA--- ---AAAAAAAAAAAAAAAA--- ---AAAAAAAAAAAAAAAA--- ------AAAAAAAAAA------ ------AAAAAAAAAA------ ------AAAAAAAAAA------ --------AAAAAA-------- --------AAAAAA-------- 
AAA---AA------AA---AAA AAA---AA------AA---AAA ---AAA--AAAAAA--AAA--- ---AAA--AAAAAA--AAA--- ---AAA--AAAAAA--AAA--- ------AA------AA------ ------AA------AA------ ------AA------AA------ AAAAAAAAAAAAAAAAAAAAAA AAAAAAAAAAAAAAAAAAAAAA AAAAAAAAAAAAAAAAAAAAAA AAAAAABBAAAAAABBAAAAAA AAAAAABBAAAAAABBAAAAAA ---AAAAAAAAAAAAAAAA--- ---AAAAAAAAAAAAAAAA--- ---AAAAAAAAAAAAAAAA--- ------AAAAAAAAAA------ ------AAAAAAAAAA------ ------AAAAAAAAAA------ --------AAAAAA-------- --------AAAAAA-------- 
AAA---AA------AA---AAA AAA---AA------AA---AAA ---AAA--AAAAAA--AAA--- ---AAA--AAAAAA--AAA--- ---AAA--AAAAAA--AAA--- ------AA------AA------ ------AA------AA------ ------AA------AA------ AAAAAAAAAAAAAAAAAAAAAA AAAAAAAAAAAAAAAAAAAAAA AAAAAAAAAAAAAAAAAAAAAA AAAAAA--AAAAAA--AAAAAA AAAAAA--AAAAAA--AAAAAA ---AAAAAAAAAAAAAAAA--- ---AAAAAAAAAAAAAAAA--- ---AAAAAAAAAAAAAAAA--- ------AAAAAAAAAA------ ------AAAAAAAAAA------ ------AAAAAAAAAA------ --------AAAAAA-------- --------AAAAAA-------- 
