model
size = 27 18 4, scale = 0.05, origin = -y
material 
  colors = A:#F0F B:#181808
voxels
AAAAA-----------------AAAAA AAAAA-----------------AAAAA -----AAAA---AAAA--AAAA----- -----AAAA---AAAA--AAAA----- --------AAAA----AAAA------- --------AAAA----AAAA------- AAAAAAAAAAAAAAAAAAAAAAAAAAA AAAAAAAAAAAAAAAAAAAAAAAAAAA AAAAAAAAAAAAAAAAAAAAAAAAAAA AAAAAAAA----AAAA----AAAAAAA AAAAAAAA----AAAA----AAAAAAA AAAAAAAAAAAAAAAAAAAAAAAAAAA AAAAAAAAAAAAAAAAAAAAAAAAAAA ---AAAAAAAAAAAAAAAAAAAAA--- ---AAAAAAAAAAAAAAAAAAAAA--- ---------AAAAAAAAA--------- ---------AAAAAAAAA--------- ---------AAAAAAAAA--------- 
AAAAA-----------------AAAAA AAAAA-----------------AAAAA -----AAAA---AAAA--AAAA----- -----AAAA---AAAA--AAAA----- --------AAAA----AAAA------- --------AAAA----AAAA------- AAAAAAAAAAAAAAAAAAAAAAAAAAA AAAAAAAAAAAAAAAAAAAAAAAAAAA AAAAAAAAAAAAAAAAAAAAAAAAAAA AAAAAAAABBBBAAAABBBBAAAAAAA AAAAAAAABBBBAAAABBBBAAAAAAA AAAAAAAAAAAAAAAAAAAAAAAAAAA AAAAAAAAAAAAAAAAAAAAAAAAAAA ---AAAAAAAAAAAAAAAAAAAAA--- ---AAAAAAAAAAAAAAAAAAAAA--- ---------AAAAAAAAA--------- ---------AAAAAAAAA--------- ---------AAAAAAAAA--------- 
AAAAA-----------------AAAAA AAAAA-----------------AAAAA -----AAAA---AAAA--AAAA----- -----AAAA---AAAA--AAAA----- --------AAAA----AAAA------- --------AAAA----AAAA------- AAAAAAAAAAAAAAAAAAAAAAAAAAA AAAAAAAAAAAAAAAAAAAAAAAAAAA AAAAAAAAAAAAAAAAAAAAAAAAAAA AAAAAAAABBBBAAAABBBBAAAAAAA AAAAAAAABBBBAAAABBBBAAAAAAA AAAAAAAAAAAAAAAAAAAAAAAAAAA AAAAAAAAAAAAAAAAAAAAAAAAAAA ---AAAAAAAAAAAAAAAAAAAAA--- ---AAAAAAAAAAAAAAAAAAAAA--- ---------AAAAAAAAA--------- ---------AAAAAAAAA--------- ---------AAAAAAAAA--------- 
AAAAA-----------------AAAAA AAAAA-----------------AAAAA -----AAAA---AAAA--AAAA----- -----AAAA---AAAA--AAAA----- --------AAAA----AAAA------- --------AAAA----AAAA------- AAAAAAAAAAAAAAAAAAAAAAAAAAA AAAAAAAAAAAAAAAAAAAAAAAAAAA AAAAAAAAAAAAAAAAAAAAAAAAAAA AAAAAAAA----AAAA----AAAAAAA AAAAAAAA----AAAA----AAAAAAA AAAAAAAAAAAAAAAAAAAAAAAAAAA AAAAAAAAAAAAAAAAAAAAAAAAAAA ---AAAAAAAAAAAAAAAAAAAAA--- ---AAAAAAAAAAAAAAAAAAAAA--- ---------AAAAAAAAA--------- ---------AAAAAAAAA--------- ---------AAAAAAAAA--------- 
