model
size = 32 20 32, scale = 0.05, origin = -y
material 
  colors = A:#300 B:#960 C:#111 D:#330 E:#633 F:#630 G:#555 H:#963 I:#444 J:#777 K:#888 L:#050 M:#03C N:#BBB O:#200
voxels
398-3AF27-6B507-4C26-2F5CD23-9FB21-10F2B20-12B323-3(2M30-)2M20-2C8-2M17-2F5CD5-2M15-2A2F5C2DB3-2M14-3A2F5C2D2B2-2M14-8A3F3B2-2M13-2A7B3F4B-2M13-16B-2M318-2(3M29-)3M17-F5C6-3M15-3F5C2D4-3M13-5F5C2D2B2-2(3M12-6F5C2D2BD-)3M11-5F5A3F4BF3M11-10A3F4BF-2M10-GJ17B3M368-DH5CD22-2D2F5CD2B19-3D2F5CD3B17-4D2F5C2D2BD15-5D2F5C2D2BDF13-6D2F5C2D2BD2F12-11A4F2B3F11-12A10F10-2BG14BMB3M10-FJ325-2H5CD22-3DH5CDBD19-4DH5C4D16-6DH5C5DF14-6DH5C5DF13-7DH5C5D2F11-8DA5C5D3F10-12A10F9-13A11F8-3BI12B6M2B8-J2I29-J264-H5C23-4H5CDBD19-4DA5CDB2D16-6DA5C5DF13-7DA5C5D2F12-7DA5C5D2F11-8DA5C5D3F9-9DA5C5D2(4F8-20A)4F7-4BI11B6M4B6-3IG30-I10-5L218-2C26-3H5CDB20-5H5CDB2D16-6DA5CDB3DF13-7DA5C5D2F11-8DA5C5D3F10-8DA5C5D3F9-9DA5C5D4F8-9DA5C5D4F7-2(21A5F6-)15B8M3B6-I-JIG27-GJG10-2L2-L14-GI12-3L184-2H5CH21-5H5CD2BD17-6H5C5D15-6DA5C5DF13-7DA5C5D2F11-8DA5C5D3F9-9DA5C5D4F7-2(10DA5C5D5F6-)21A5F5-22A6F4-16B8M4B4-2J3-I10-E16-3JG9-2LE-L14-KJ-J10-LEL30-L123-4C24-4H5C3H18-6H5C5D15-7H5C5DF13-7DA5C5D2F11-8DA5C5D3F9-9DA5C5D4F7-10DA5C5D4FD6-10DA5C5D4FD5-11DA5C5D4F2D4-26A2D4-27AF4-17B7M4B4-G3J-J26-3JGI9-L3-L13-2G13-3L152-7HA21-5H9A17-6H10A14-E7H10A2F11-2E17A3F9-2E18A4F8-2E18A4F7-2E19A4FD5-2(3E19A4F2D4-)3E23A2D3-4E26A2-18B7M5B2-G5JI25-K4JI9-L3-L12-2JIJGJ10-3L13-G2-J134-8H2A20-5H9A16-7H10AF13-E7H10A2F11-2E17A3F9-2E18A4F7-3E18A4FA6-2E19A4FA5-3E19A4F2A4-3E19A4F2A3-2(4E26A2-)19B6M5B2-K7J9-E14-6JGK7-2LE-L12-G2JIJK10-LEL13-GJI14-L91-4H24-9H3A18-6H10A15-7H11A12-2E7H13A9-3E21A8-2E22A7-3E23A5-3E25A4-3E25A3-3(4E26A2-)19B5M6B2-7JG24-K4JIGI7-2L2-L12-4JI2-I8-3L14-2J-J28-NG73-6H23-9H3A18-6H10A14-E17A2D11-2E17A3D9-3E17A4D7-3E18A5D6-3E23A5-3E25A4-3E25A3-2(4E26A2-)4E26A-22BM9BG7JK23-K6J-J7-5L11-6JK25-K3JI29-2JN30-N40-7HA21-10H4A17-6H10A14-2C16A2D11-3C16A3D9-4C16A4D7-5C16A4DA6-2E24A5-3E25A3-2(4E26A2-)4E26A-5E27A32B7J2G23-I4J27-G5J26-J-2G-I28-GN72-3C5H21-14A16-17AD13-2C16A2D11-3C16A3D9-4C16A4D7-5C16A4DA5-3E25A4-3E25A3-2(4E26A2-)4E26A-5E27A32BK7JKI23-G4JG26-4JI27-2GNJ103-3C5H21-14A16-18A13-2C18A11-3C19A9-4C20A7-5C21A5-3E25A4-3E25A3-2(4E26A2-)4E26A-5E27A32BI6JIJ23-G2JIKG26-KGJG31-K104-3C5H21-14A17-2B14A14-4B16A11-K4B17A9-2K4B18A7-B2K4B19A6-B2K4B19A5-2B2K4B20A3-2(3B2K4B21A2-)3B2K4B21A-10B22A32BK2J-GJG25-IGK10-5F14-G140-2C4H23-12A18-2B14A14-4B16A11-K4B17A9-2K4B18A7-C2K4B18AI6-C2K4B18AI5-2C2K4B18A2I4-2C2K4B18A2I3-3B2K4B18A3I2-3B2K4B21A2-9B21A-13B5A14BJGJ10-5F21-5L-2(5F27-)C31-C64-C3H24-11AG18-2B11A3G15-3B11A4G12-K4B11A6G9-2K4B11A7G8-2K4B11A7G7-C2K4B11A8G5-2C2K4B11A8GA4-2C2K4B11A8GA3-2(3B2K4B21A2-)9B21A2-12B5A13B14-F3-F21-L2-2L-F3-F22-3L2-F3-F27-5F121-10A20-B11A2G16-3B11A4G13-4B11A5G11-K4B11A6G9-2K4B11A7G7-C2K4B11A8G6-C2K4B11A8G5-2C2K4B11A8GA4-2B2K4B20A3-3B2K4B21A2-9B21A2-12B5A13B10-E3-F3-O21-L-E2L-F3-F22-LEL2-F3-F23-L3-5F122-8A21-B11A2G17-2B11A3G14-4B11A4GC11-K4B11A4G2C9-2K4B11A4G3C8-2K4B11A4G3C7-C2K4B11A4G3CG5-2C2K4B11A4G3CGA2(4-2B2K4B15A3C2A)3-9B15A3C3A2-12B4A14B14-5F21-L3-L-5F22-3L2-5F156-4A24-11AG18-2C11A3G15-3C11A4G13-A3C11A4GC11-KA3C11A4G2C9-2K15A4G3C7-E2K15A4G3CG6-E2K15A4G3CG5-2(2E2K19A3C2A4-)2E21A3C2A4-28B41-5L-5F218-3I5A21-6I6A2G17-7I6A3G15-8I6A4G13-9I6A4GC11-K9I6A4G2C9-2K15A4G3C7-E2K15A4G3CG2(6-E2K19A3CA)5-2E21A3C2A4-28B273-2A26-10A20-C13A16-3C15A13-A3C15AC11-K19A2C10-K19A2C9-2K19A3C8-2K19A3C7-E2K19A3CA6-E21A3CA6-26B43-5L256-6A23-12A19-C13A16-C4E13A13-6E13AC12-6E13AC11-K6E13A2C9-2K6E13A3C8-2K19A3C8-E20A3C7-26B43-L2-2L28-3L256-A3I4A22-3A3I6A19-3EA3I7A16-5EA3I9A14-5EA3I9A13-6EA3I9AC11-7EA3I9A2C10-16E4A2C9-17E4A3C8-24B14-E29-L-E5L25-LEL30-L257-C3I3AI22-2EC3I3A3I19-3EC3I3A4I17-4EC3I3A5I15-5EC3I3A6I13-6EC3I3A6IA12-15E5A11-16E6A10-22B45-L2-2L2-L25-6L318-3IA2C24-EC3IA2C2A20-3EC3IA2C4A17-4EC3IA2C5A16-4EC3IA2C5A15-14E4A14-14E4A13-20B19-E26-5LE-L28-LEL30-L321-IA27-C3IA3C22-2EC3IA5C19-3EC3IA6C18-12E2A17-13E3A16-16B51-L3-L28-3L415-2IAC26-C3IA2CA23-10E21-11EA20-12B53-5L542-4E27-6B205-
