model
size = 31 32 32, scale = 0.05, origin = -y
material 
  colors = A:#171828 B:#180808 C:#0F9 D:#E8E9E8 E:#080818 F:#585858 G:#009F79
voxels
12-7A24-7E24-7A921-3A2CA2C3A20-2E7A2E20-4A3C4A918-2AC7AC2A18-E11AE18-2A2C5A2C2A916-2AC9AC2A16-E13AE16-15A914-17A14-E15AE14-2AC11AC2A912-2AC13AC2A12-E17AE12-2AC13AC2A911-AC15ACA12-E17AE12-19A910-21A10-E19AE10-2AC15AC2A909-AC17ACA10-E19AE10-AC17ACA908-2AC17AC2A8-E21AE8-23A907-23A8-E21AE8-AC19ACA907-AC19ACA8-E21AE8-AC19ACA906-2AC19AC2A6-E23AE6-25A905-25A2(6-E23AE6-AC21ACA905-AC21ACA)6-E23AE6-25A904-27A4-E25AE4-27A2(903-AC23ACA4-E25AE4-AC23ACA)902-2AC23AC2A2-E27AE2-29A901-29A2-E27AE2-AC27A901-AC25ACA2-E27AE2-AC25ACA566-B-B11-B-B318-AC25ACA2-E27AE2-AC25ACA564-3(B-)B7-3(B-)B316-AC25ACA2-E27AE2-29A562-4(B-)B7-4(B-)B313-31AE29AE31A561-5(B-)B3-5(B-)B313-AC27ACAE29AEAC27ACA560-12B3-12B2(4-12A3-12A)5-2(11A3-11A6-)10A5-10A6-10A5-10A2(7-8A)8-8A7-8A2(9-6A)2(11-4A)6-AC27ACAE29AE31A7D3B11D3B13D5B9D5B11DBFG4B7D2BFG3B10DBG5B7D2BG4B9DBF7B5D2BF6B8DBF7B5D2BF6B4D-3(3D9B5D9B3D2-)2(3D6BD2B5D6BD2B3D2-)3D6BD2B2D-2D6BD2B3D2-3D6BD2B2D-2D6BD2B3D3-2(3D4BD2B3D-3D4BD2B3D4-)4D5B4D-4D5B4D4-5D3B5D-5D3B5D4-12D3-12D4-B10CB3-B10CB2(4-12A3-12A)5-2(11A3-11A6-)10A5-10A6-10A5-10A2(7-8A)8-8A7-8A2(9-6A)2(11-4A)6-AC27ACAE29AE31AD2(5C5B9C5B5C2D)2(4CBF5B7C2BF4B4C2D)3CBF7B5C2BF6B3C2D3CBF7B5C2BF6B3CD-3(D2C9B5C9B2CD2-)D2C6BD2B5C6BD2B2CD2-2(D2C6BD2B2C)2(D2-D2C6BD2BCD-DC6BD2B2C)D3-2(D2C4BD2B2CD-D2C4BD2B2CD4-)2(D3C5B3CD-D3C5B3CD4-)D10CD3-D10CD4-B10CB3-B10CB2(4-12A3-12A)5-2(11A3-11A6-)10A5-10A6-10A5-10A2(7-8A)8-8A7-8A2(9-6A)2(11-4A)6-31AE29AE31AD2(5C5B9C5B5C2D)2(4CBF5B7C2BF4B4C2D)3CBF7B5C2BF6B3C2D3CBF7B5C2BF6B3CD-3(D2C9B5C9B2CD2-)D2C6BD2B5C6BD2B2CD2-2(D2C6BD2B2C)2(D2-D2C6BD2BCD-DC6BD2B2C)D3-2(D2C4BD2B2CD-D2C4BD2B2CD4-)2(D3C5B3CD-D3C5B3CD4-)D10CD3-D10CD3(4-12A3-12A)3(5-2(11A3-11A6-)10A5-10A6-10A5-10A2(7-8A)8-8A7-8A2(9-6A)2(11-4A)6-AC27AC249A-5(29A2-)14A-14A2-14A-14A3-4(13A-13A4-)3(12A3-12A4-)12A3-12A)5-2(11A3-11A6-)10A5-10A6-10A5-10A2(7-8A)8-8A7-8A2(9-6A)2(11-4A)6-
