model
size = 30 31 32, scale = 0.05, origin = -y
material 
  colors = A:#0FF B:#FF0 C:#180808 D:#181808 E:#080818 F:#180818 G:#F9E9E9 H:#282808
voxels
12-6A24-6A892-3A2GAG3A20-4A2G4A889-2AG6AG2A18-2A2G4A2G2A887-2AG8AG2A16-14A885-16A14-2AG10AG2A883-2AG12AG2A12-2AG12AG2A882-AG14AGA12-18A881-20A10-2AG14AG2A880-AG16AGA10-AG16AGA879-2AG16AG2A8-22A878-22A8-AG18AGA878-AG18AGA8-AG18AGA877-2AG18AG2A6-24A876-24A2(6-AG20AGA876-AG20AGA)6-24A875-26A4-26A2(874-AG22AGA4-AG22AGA)873-2AG22AG2A2-28A872-28A2-28A2(872-AG24AGA2-AG24AGA)872-AG24AGA2-28A871-60A2(870-AG26AG2AG26AGA)870-AG26AG2AG4A13C4D2C3AGA5-2(14C4D2C10-)3(2C2B2F2B2E2C2B2E2B2D10-)3(4C2B2F4B2E2B2D2C10-)3(6C2B2F2C2B2E2D2C10-)3(2C16B2D10-)3(2C4B2F4B2E4B2D10-)2(4C12B2D2C10-)4C12B2D2C12-2(4C8B2H2D14-)4C8B2H2D16-2(4C4B2F2C18-)4C4B2F2C20-2(8C22-)8C11-36A13C4D2C5A5-2(14C4D2C10-)3(2C2B2F2B2E2C2B2E2B2D10-)3(4C2B2F4B2E2B2D2C10-)3(6C2B2F2C2B2E2D2C10-)3(2C16B2D10-)3(2C4B2F4B2E4B2D10-)2(4C12B2D2C10-)4C12B2D2C12-2(4C8B2H2D14-)4C8B2H2D16-2(4C4B2F2C18-)4C4B2F2C20-2(8C22-)8C11-AG26AG7A13C4D2C5A5-2(14C4D2C10-)3(2C2B2F2B2E2C2B2E2B2D10-)3(4C2B2F4B2E2B2D2C10-)3(6C2B2F2C2B2E2D2C10-)3(2C16B2D10-)3(2C4B2F4B2E4B2D10-)2(4C12B2D2C10-)4C12B2D2C12-2(4C8B2H2D14-)4C8B2H2D16-2(4C4B2F2C18-)4C4B2F2C20-2(8C22-)8C11-AG26AG2AG4A13C4D2C3AGA5-2(14C4D2C10-)3(2C2B2F2B2E2C2B2E2B2D10-)3(4C2B2F4B2E2B2D2C10-)3(6C2B2F2C2B2E2D2C10-)3(2C16B2D10-)3(2C4B2F4B2E4B2D10-)2(4C12B2D2C10-)4C12B2D2C12-2(4C8B2H2D14-)4C8B2H2D16-2(4C4B2F2C18-)4C4B2F2C20-2(8C22-)8C11-AG26AG2AG26AGA870-
