model
size = 31 31 32, scale = 0.05, origin = -y
material 
  colors = A:#0FF B:#080818 C:#F9E9E9
voxels
12-7A24-7A921-3A2CA2C3A20-4A3C4A918-2AC7AC2A18-2A2C5A2C2A916-2AC9AC2A16-15A914-17A14-2AC11AC2A912-2AC13AC2A12-2AC13AC2A911-AC15ACA12-19A910-21A10-2AC15AC2A909-AC17ACA10-AC17ACA908-2AC17AC2A8-23A907-23A8-AC19ACA907-AC19ACA8-AC19ACA906-2AC19AC2A6-25A905-25A2(6-AC21ACA905-AC21ACA)6-25A904-27A4-27A2(903-AC23ACA4-AC23ACA)902-2AC23AC2A2-29A901-29A2-29A2(901-AC25ACA2-AC25ACA)901-AC25ACA2-29A900-62A2(899-AC27AC2AC27ACA)899-AC27AC2AC7A14B6ACA9-14B17-14B11-3(8B4A2B4A8B5-)3(2(2B2A)10B2(2A2B)5-)3(2B2A2B14A2B2A2B5-)3(2B22A2B5-)2(4B4A2B6A2B4A4B5-)4B4A2B6A2B4A4B7-2(4B14A4B9-)4B14A4B11-3(4B2A6B2A4B13-)3(2B2A4B2-4B2A2B13-)2(6B6-6B13-)2(6B6-)40A14B8A9-14B17-14B11-3(8B4A2B4A8B5-)3(2(2B2A)10B2(2A2B)5-)3(2B2A2B14A2B2A2B5-)3(2B22A2B5-)2(4B4A2B6A2B4A4B5-)4B4A2B6A2B4A4B7-2(4B14A4B9-)4B14A4B11-3(4B2A6B2A4B13-)3(2B2A4B2-4B2A2B13-)2(6B6-6B13-)2(6B6-)AC27AC10A14B8A9-14B17-14B11-3(8B4A2B4A8B5-)3(2(2B2A)10B2(2A2B)5-)3(2B2A2B14A2B2A2B5-)3(2B22A2B5-)2(4B4A2B6A2B4A4B5-)4B4A2B6A2B4A4B7-2(4B14A4B9-)4B14A4B11-3(4B2A6B2A4B13-)3(2B2A4B2-4B2A2B13-)2(6B6-6B13-)2(6B6-)AC27AC2AC7A14B6ACA9-14B17-14B11-3(8B4A2B4A8B5-)3(2(2B2A)10B2(2A2B)5-)3(2B2A2B14A2B2A2B5-)3(2B22A2B5-)2(4B4A2B6A2B4A4B5-)4B4A2B6A2B4A4B7-2(4B14A4B9-)4B14A4B11-3(4B2A6B2A4B13-)3(2B2A4B2-4B2A2B13-)2(6B6-6B13-)2(6B6-)AC27AC2AC27ACA899-
