model
size = 15 12 5, scale = 0.05, origin = -y
material 
  colors = A:#936 B:#C03 C:#C06 D:#F06 E:#F36 F:#F39 G:#939 H:#C0C I:#C09
voxels
--------------- --------------- -------I------- ------C-C------ -----D---D----- ----A-----A---- ---A-------A--- --G---F-F---G-- ---A-E---E-A--- ----A-----A---- --------------- --------------- 
--------------- -------I------- ------C-C------ -----F---F----- ----E-----E---- ---G-------G--- --D----F----D-- -G----F-F----G- --D---A-A---D-- ---C-C---C-C--- ----A-----A---- --------------- 
-------H------- ------HIH------ -----CCBCC----- ----EBB-BBE---- ---EEB---BEE--- --DDB--H--BDD-- -DDB--HHH--BDD- AAB---BAB---BAA -AAB-BA-AB-BAA- --AABAA-AABAA-- ---AAA---AAA--- ----C-----C---- 
--------------- -------I------- ------C-C------ -----F---F----- ----E-----E---- ---G-------G--- --D----F----D-- -G----F-F----G- --D---A-A---D-- ---C-E---E-C--- ----A-----A---- --------------- 
--------------- --------------- -------I------- ------C-C------ -----D---D----- ----A-----A---- ---A-------A--- --G---F-F---G-- ---A-E---E-A--- ----A-----A---- --------------- --------------- 
