model
size = 17 14 5, scale = 0.05, origin = -y
material 
  colors = A:#111 B:#0F6 C:#936 D:#F06 E:#C06 F:#F36 G:#C09 H:#C03
voxels
----------------- ----------------- ----------------- --------A-------- -------A-A------- ------A---A------ -----A-----A----- ----A-------A---- ---A---A-A---A--- ----A-A---A-A---- -----A-----A----- ----------------- ----------------- ----------------- 
----------------- ----------------- --------B-------- -------B-BA------ ------B---B------ -----B-----B----- ----B-------B---- ---B----A----B--- --B----A-A----B-- ---B---B-B---B--- ----B-B---B-B---- -----B-----B----- ----------------- ----------------- 
--------A-------- -------AAA------- ------AAGAA------ -----AAEBEAA----- ----AAHB-BBAA---- ---AAFB---BFAA--- --AADB-----BDAA-- -AADB---B---BDAA- AACB---BBB---BCAA -AACB-BAAAB-BCAA- --AACBCAAACBCAA-- ---AACAA-AACAA--- ----AAA---AAA---- -----A-----A----- 
----------------- ----------------- --------B-------- -------B-B------- ------B---B------ -----B-----B----- ----B-------B---- ---B----A----B--- --B----B-B----B-- ---B---B-B---B--- ----B-B---B-B---- -----B-----B----- ----------------- ----------------- 
----------------- ----------------- ----------------- --------A-------- -------A-A------- ------A---A------ -----A-----A----- ----A-------A---- ---A---A-A---A--- ----A-A---A-A---- -----A-----A----- ----------------- ----------------- ----------------- 
