model
size = 17 14 5, scale = 0.05, origin = -y
material 
  colors = A:#C6C B:#0F6 C:#936 D:#F06 E:#C06 F:#F36 G:#C09 H:#C03
voxels
----------------- ----------------- ----------------- --------A-------- -------A-A------- ------A---A------ -----A-----A----- ----A---A---A---- ---A---A-----A--- ----A-A---A-A---- -----A-----A----- ----------------- ----------------- ----------------- 
----------------- ----------------- --------B-------- -------B-B------- ------B---B------ -----B-----B----- ----B-------B---- ---B----A----B--- --B----A-A----B-- ---B---B-B---B--- ----B-B--AB-B---- -----B-----B----- ----------------- ----------------- 
--------B-------- -------AAA------- ------AAGAA------ -----AAEBEAA----- ----AAHB-BBAA---- ---AAFB---BFAA--- --AADB-----BDAA-- -AADB---B---BDAA- BACB---BBB---BCAB -AACB-BAAAB-BCAA- --AACACAAACBCAA-- ---AACAA-AACAA--- ----AAA---AAA---- -----B-----B----- 
----------------- ----------------- --------B-------- -------B-B------- ------B---B------ -----B-----B----- ----B-------B---- ---B----A----B--- --B----B-B----B-- ---B---B-B---B--- ----B-B---B-B---- -----B-----B----- ----------------- ----------------- 
----------------- ----------------- ----------------- --------A-------- -------A-A------- ------A---A------ -----A-----A----- ----A---A---A---- ---A---A-A---A--- ----A-A---A-A---- -----A-----A----- ----------------- ----------------- ----------------- 
