model
size = 17 14 5, scale = 0.05, origin = -y
material 
  colors = A:#C6C B:#111 C:#222 D:#936 E:#F06 F:#C06 G:#F36 H:#C09 I:#C03 J:#0F6
voxels
----------------- ----------------- ----------------- --------A-------- -------A-A------- ------A---A------ -----A-----A----- ----A---A---A---- ---A---A-A---A--- ----A-A---A-A---- -----A-----A----- ----------------- ----------------- ----------------- 
----------------- ----------------- --------C-------- -------C-C------- ------C---C------ -----C-----C----- ----C-------C---- ---C----A----C--- --C----A-A----C-- ---C---C-C---C--- ----C-C---C-C---- -----C-----C----- ----------------- ----------------- 
--------A-------- -------AAA------- ------AAHAA------ -----AAFBFAA----- ----AAIB-BJAA---- ---AAGB---BGAA--- --AAEB-----BEAA-- -AAEB---B---BEAA- AADB---BCB---BDAA -AADB-BAAAB-BDAA- --AADBDAAADBDAA-- ---AADAA-AADAA--- ----AAA---AAA---- -----A-----A----- 
----------------- ----------------- --------B-------- -------B-B------- ------B---B------ -----B-----B----- ----B-------B---- ---B----A----B--- --B----B-B----B-- ---B---B-B---B--- ----B-B---B-B---- -----B-----B----- ----------------- ----------------- 
----------------- ----------------- ----------------- --------A-------- -------A-A------- ------A---A------ -----A-----A----- ----A---A---A---- ---A---A-A---A--- ----A-A---A-A---- -----A-----A----- ----------------- ----------------- ----------------- 
