model
size = 15 12 5, scale = 0.05, origin = -y
material 
  colors = A:#C6C B:#111 C:#222 D:#936 E:#F06 F:#C06 G:#F36 H:#C09 I:#C03 J:#0F6 K:#C0C
voxels
--------------- --------------- -------A------- ------A-A------ -----A---A----- ----A-----A---- ---A---A---A--- --A---A-A---A-- ---A-A---A-A--- ----A-----A---- --------------- --------------- 
--------------- -------C------- ------C-C------ -----C---C----- ----C-----C---- ---C-------C--- --C----A----C-- -C----A-A----C- --C---C-C---C-- ---C-C---C-C--- ----C-----C---- --------------- 
-------A------- ------AHA------ -----AFBFA----- ----AIB-BJA---- ---AGB---BGA--- --AEB-----BEA-- -AEB---K---BEA- ADB---BCB---BDA -ADB-BA-AB-BDA- --ADBDA-ADBDA-- ---ADA---ADA--- ----A-----A---- 
--------------- -------B------- ------B-B------ -----B---B----- ----B-----B---- ---B-------B--- --B----A----B-- -B----B-B----B- --B---B-B---B-- ---B-B---B-B--- ----B-----B---- --------------- 
--------------- --------------- -------A------- ------A-A------ -----A---A----- ----A-----A---- ---A---A---A--- --A---A-A---A-- ---A-A---A-A--- ----A-----A---- --------------- --------------- 
