model
size = 23 18 10, scale = 0.05, origin = -y
material 
  colors = A:#555 B:#111
voxels
----------------------- ----------------------A A---------------------- ----------------------- ----------------------- ----------------------- ----------------------- ----------------------- ----------------------- ----------------------- ----------------------- ----------------------- ----------------------- ----------------------- ----------------------- ----------------------- ----------------------- ----------------------- 
----------------------A A---------------------- ----------------------- ----------------------- ----------------------- ----------------------- ----------------------- ----------------------- ----------------------- ----------------------- ----------------------- ----------------------- ----------------------- ----------------------- ----------------------- --AAAAAAA-----AAAAAAA-- ----------------AAAAA-- ----------------AAAAA-- 
----------------------A A---------------------- ----------------------- ----------------------- ----------------------- ----------------------- ----------------------- ----------------------- ----------------------- ----------------------- ----------------------- ----------------------- ----------------------- ----------------------- ----------------------- -AAABBBBB-----BBAAAAAA- -AAA------------AAAAAA- ----------------AAAAAA- 
----------------------A A---------------------- ----------------------- ----------------------- ----------------------- ----------------------- ----------------------- ----------------------- ----------------------- ----------------------- ----------------------- ----------------------- ----------------------- ----------------------- ----------------------- AABAABBBBB---BBBAAABAAA AA-AA-----------AAA-AAA ----------------AAA-AAA 
----------------------A A---------------------- ----------------------- ----------------------- ----------------------- ----------------------- ----------------------- ----------------------- ----------------------- A---------------------A A---------------------A A---------------------A A---------------------A A---------------------A A---------------------A ABBBABBBBB---BBBAABBBAA A---A-----------AA---AA ----------------AA---AA 
----------------------- ----------------------A A---------------------A A---------------------A A---------------------A A---------------------A A---------------------A A---------------------A A---------------------A A---------------------A A---------------------A A---------------------A A---------------------A A---------------------A A---------------------A ABBBABBBBBB-BBBBBBBBBAA A---A----------------AA ---------------------AA 
----------------------- ----------------------- ----------------------- ----------------------- ----------------------- ----------------------- ----------------------- ----------------------- ----------------------- ----------------------- ----------------------- ----------------------- ----------------------- ----------------------- A---------------------A ABBBABBBBBBBBBBBAABBBAA A---A-----------AA---AA ----------------AA---AA 
----------------------- ----------------------- ----------------------- ----------------------- ----------------------- ----------------------- ----------------------- ----------------------- ----------------------- ----------------------- ----------------------- ----------------------- ----------------------- ----------------------- ----------------------- AABAABBBBBBBBBBBAAABAAA AA-AA-----------AAA-AAA ----------------AAA-AAA 
----------------------- ----------------------- ----------------------- ----------------------- ----------------------- ----------------------- ----------------------- ----------------------- ----------------------- ----------------------- ----------------------- ----------------------- ----------------------- ----------------------- ----------------------- -AAABBBBBBBBBBBBAAAAAA- -AAA------------AAAAAA- ----------------AAAAAA- 
----------------------- ----------------------- ----------------------- ----------------------- ----------------------- ----------------------- ----------------------- ----------------------- ----------------------- ----------------------- ----------------------- ----------------------- ----------------------- ----------------------- ----------------------- --AAAAAAAAAAAAAAAAAAA-- --AAAAAAAAAAAAAAAAAAA-- ----------------AAAAA-- 
