model
size = 10, scale = 0.05, origin = -y
material 
  colors = A:#FFC
voxels
---------- --AAAAAA-- -AA----AA- -A-AAAA-A- -AAAAAAAA- -AAAAAAAA- -AAAAAAAA- -AA-AA-AA- --AAAAAA-- ---------- 
---------- -AAAAAAAA- -AAAAAAAA- -AAAAAAAAA AAAAAAAAAA AAAAAAAAAA AAAAAAAAAA -AAAAAAAA- -AAAAAAAA- --AAAAAAA- 
---AAAA--- -AAAAAAAA- AAAAAAAAAA AAAAAAAAAA AAAAAAAAAA AAAAAAAAAA AAAAAAAAAA AAAAAAAAAA -AAAAAAAA- -AAAAAAAA- 
---AAAA--- -AAAAAAAA- AAAAAAAAAA AAAAAAAAAA AAAAAAAAAA AAAAAAAAAA AAAAAAAAAA AAAAAAAAAA -AAAAAAAA- -AAAAAAAA- 
---AAAA--- -AAAAAAAA- AAAAAAAAAA AAAAAAAAAA AAAAAAAAAA AAAAAAAAAA AAAAAAAAAA AAAAAAAAAA -AAAAAAAA- -AAAAAAAA- 
---AAAA--- -AAAAAAAA- AAAAAAAAAA AAAAAAAAAA AAAAAAAAAA AAAAAAAAAA AAAAAAAAAA AAAAAAAAAA -AAAAAAAA- -AAAAAAAA- 
---AAAA--- -AAAAAAAA- AAAAAAAAAA AAAAAAAAAA AAAAAAAAAA AAAAAAAAAA AAAAAAAAAA AAAAAAAAAA -AAAAAAAA- -AAAAAAAA- 
---AAAA--- --AAAAAAA- -AAAAAAAA- AAAAAAAAAA AAAAAAAAAA AAAAAAAAAA AAAAAAAAAA AAAAAAAAA- -AAAAAAAA- -AAAAAAAA- 
---------- --AAAAAA-- --AAAAAA-- AAAAAAAAA- AAAAAAAAA- AAAAAAAAA- AAAAAAAAA- -AAAAAAAA- --AAAAAA-- ---------- 
---------- ---------- --AAAAAA-- --AAAAAA-- -AAAAAAAA- -AAAAAAAA- -AAAAAAAA- --AAAAAA-- ---AAAA--- ---------- 
