model
size = 30 32 18, scale = 0.05, origin = -y
material 
  colors = A:#FAFAFA B:#FFF C:#FC3 D:#66F E:#0FF F:#F90 G:#A8A8A8 H:#B0B0B0 I:#ABABAB J:#3A3A92 K:#AE8B22 L:#0BB M:#D9822B
voxels
9-12B18-10B2A18-3B5ABA2B18-2B2A3BA4B18-A2B2A7B18-12B18-5BABA4B18-2B8A2B18-3A4BA2B2A18-2A8BAB18-3EH5B3F18-4EHB2A4F18-4EIH2B4F18-4EGIHB4F18-3E3GIHA3F18-HI5GIH3A18-BHI5GIH2B18-BAHI5GIHB18-2BAHI5GIH18-3CAHI3G3D18-4CAHIG4D17-5C2AHI5D15-B5C2ABH5DB14-2B3C3A2BH3DHB15-2B3A7B2A17-2A5BA3BA21-4BAB169-3(2B12-2B14-)2B12-BA6(14-2A12-2A)14-AH12-2A2(14-AE12-FA)14-AEA10-AFA14-AHA10-3A15-4(2A10-2A16-)2A10-AH14-2ACA10-AD3A10-4A12-4A2(10-3A14-3A)11-2A14-2A13-2A12-2A15-4A6-4A16-14A134-4(B16-B12-)5(A16-A12-)3(2A14-2A12-)2A14-2A13-4(A14-)3(2A12-2A14-)2A12-2A15-A12-A11-3A2-A12-A2-3(3A6-3A18-)3A7-2A18-2A8-4A14-4A9-3A14-3A12-A14-A15-4A6-2ABA103-4(B18-B10-)4(A18-A10-)A18-A11-5(A16-A12-)A16-A13-9(A14-)A9-A4-A14-A3-2(AB4-B23-)AB4-BA22-2A4-B2A20-3A5-3A18-3A6-4A16-4A7-4A14-4A10-2A14-2B14-2A10-BA73-4(B18-B10-)A18-B4(10-A18-A)3(10-2A16-2A)11-3(A16-A12-)2A14-2A12-2A14-2A13-5(A14-)A8-B5-A14-A4-2(2B2-B25-)2B2-2B24-2B3-BA22-AB4-B2A20-2AB4-4A18-3AB5-4A16-4A7-4A14-4B11-A14-B15-B12-B42-4(B20-B8-)2(A20-B8-)A20-A9-7(A18-A10-)A18-A11-3(A16-A12-)A16-A13-A14-A8-B5-A14-A5-A3(2-B26-B)2-2B24-2B2-ABA22-A2B3-3A20-2AB4-4A18-4A5-4A16-4B8-3A14-3B13-B12-B42-A3(20-B8-B)3(20-B8-A)3(20-A8-A)20-A9-5(A18-A10-)2A16-2A10-2A16-2A11-2(A16-A12-)2A14-2A6-B6-A14-A6-2(2B28-)BA28-B-A26-A2-AB24-2B2-2BA22-A2B3-B2A20-2AB5-3A18-3B7-4A14-4B11-A14-A41-A20-B2(8-B20-A)9(8-A20-A)2(8-2A18-2A)9-A18-A3(10-2A16-2A)11-A16-A12-2A14-2A6-B5-2A14-2A5-2(2B28-)2(BA28-)A-B26-B2-2B24-2B3-BA22-AB4-3A20-3B6-2A18-2B10-AB14-BA40-B20-B8-B20-A4(8-A20-B)8(8-A20-A)8-2A18-2A2(8-3A16-3A)9-2(2A16-2A10-)3A14-3A5-A5-2A14-2A5-2A28-BA3(28-2B)28-A-B26-A2-2B24-BA3-BA22-2B5-2A20-2B8-BAB14-BAB39-2(B2(20-B8-A)20-B8-)6(A20-A8-)2A18-2A8-2A18-2A9-A18-A3(10-2A16-2A)11-A16-A12-2A14-2A6-B5-2A14-2A5-3(2B28-)2(BA28-)B-B26-B2-2B24-BA3-2A22-2B5-2A20-AB8-BAB14-2AB39-4(B20-B8-)A20-B5(8-A20-A)9-5(A18-A10-)2A16-2A10-2A16-2A11-2(A16-A12-)2A14-2A6-B6-A14-A6-4(2B28-)B-A26-B2-2B24-2B3-BA22-2A4-B2A20-3B6-2A18-2B10-AB14-2B40-B20-B8-A20-B8-B20-A8-B3(20-B8-A)20-A9-7(A18-A10-)A18-A11-3(A16-A12-)A16-A13-A14-A7-B6-A14-A6-3(2B28-)B-B26-B2-2B24-2B2-2BA22-ABA3-B2A20-2AB5-4A16-4B7-4A14-4B11-AB13-B42-2(B18-B10-)2(B18-A10-)5(A18-A10-)2(2A16-2A10-)2A16-2A11-2(A16-A12-)A16-A13-9(A14-)A8-B5-A14-A5-2(A2-A26-)A2-B26-A2-2B24-BA2-2BA22-ABA3-B2A20-2AB4-B3A18-3AB5-4A16-4B8-3A14-3B13-A12-B43-3(B18-A10-)B2(18-B10-A)3(18-A10-A)18-A11-5(A16-A12-)A16-A13-9(A14-)A8-B5-A14-A4-2B2-B2(25-2B2-A)B24-BA3-BA22-2A4-B2A20-2AB4-4A18-3AB5-4A16-4A7-4A14-4B11-A14-A15-B12-B44-3(B16-A12-)B16-B5(12-A16-A)5(12-2A14-2A)13-2(A14-)3(2A12-2A14-)2A12-2A15-2(2A10-)B5-A12-A4-A2(B4-)A14-A3-AB4-A23-AB4-2A22-AB4-3A20-2AB5-3A18-3A6-4A16-4A7-4A14-4A10-2A14-AB14-2A10-BA17-AB8-2B46-2B12-2B14-2B2(12-BA14-AB)12-BA4(14-2A12-2A)7(14-3A10-3A)15-4(2A10-2A16-)2A10-2A11-3A2-A12-A2-3A6-5A14-5A2(6-3A18-3A)7-2A18-2A8-4A14-4A9-3A14-3A12-A14-A15-2A10-BA17-2A8-AB19-AB6-2B21-B6-B19-9B2A3B16-9BA4B16-8B3A3B16-7B4A3B9(16-14A)17-7(12A18-)13A14-3(18A12-)18A13-16A15-14A16-14A18-10A20-10A21-B2A2BA2B23-6B21-7BA3BA18-4B7AB18-3BM4F4B18-3B2ABMFA3B4(18-6AMF4A)18-12A18-3AL4E2(4A18-6ALE)4A19-3(5ALE3A20-)10A20-2AJ4D4(3A20-2AJDAJD)3A20-2AJ4D3A17-16A14-5AKCAKC6A15-5A2(KC)5A17-5AK2C4A18-3AK4C4A19-2AKCAKC3A21-AK4C2A23-6A72-
