model
size = 21 25 15, scale = 0.05, origin = -y
material 
  colors = A:#777 B:#BA9425 C:#C6AB40 D:#B9B9B9
voxels
--------------------- --------------------- --------------------- --------------------- --------------------- --------------------- --------------------- --------------------- --------A---A-------- -------A-----A------- ------A-------A------ -A---A---------A---A- -A-----------------A- -A-----------------A- -A-----------------A- -A-----------------A- --------------------- --------------------- --------------------- -A-----------------A- -A-----------------A- -A-----------------A- -A-----------------A- -A-----------------A- --------------------- 
------BBBCBCBBB------ ------BBCCCCBBB------ ------BBBCBBCBB------ ------BBBCCCBBB------ ------BBBCBBCBB------ ------BBCCCCBBB------ ------BBBCBCBBB------ -------D-----D------- -------DA---AD------- --------D---D-------- -AAAAA---DDD---AAAAA- -A---A---------A---A- -AAAAA---------AAAAA- --------------------- --------------------- -AA---------------AAA A-A---------------A-A A-A---------------A-A A-A---------------A-A AAA---------------AAA --------------------- --------------------- --------------------- -A-----------------A- --------------------- 
--------------------- --------------------- --------------------- --------------------- --------------------- --------------------- --------------------- --------------------- --------A---A-------- -------A-----A------- ------A-------A------ -A---A---------A---A- -A-----------------A- -A-----------------A- -A-----------------A- -A-----------------A- --------------------- --------------------- --------------------- -A-----------------A- -A-----------------A- -A-----------------A- -A-----------------A- AAA---------------AAA --------------------- 
--------------------- --------------------- --------------------- --------------------- --------------------- --------------------- --------------------- --------------------- --------------------- --------------------- --------------------- --------------------- --------------------- --------------------- --------------------- --------------------- --------------------- --------------------- --------------------- --------------------- --------------------- --------------------- --------------------- A-A---------------A-A --------------------- 
--------------------- --------------------- --------------------- --------------------- --------------------- --------------------- --------------------- --------------------- --------------------- --------------------- --------------------- --------------------- --------------------- --------------------- --------------------- --------------------- --------------------- --------------------- --------------------- --------------------- --------------------- --------------------- --------------------- A-A---------------A-A --------------------- 
--------------------- --------------------- --------------------- --------------------- --------------------- --------------------- --------------------- --------------------- --------------------- --------------------- --------------------- --------------------- --------------------- --------------------- --------------------- --------------------- --------------------- --------------------- --------------------- --------------------- --------------------- --------------------- --------------------- A-A---------------A-A --------------------- 
--------------------- --------------------- --------------------- --------------------- --------------------- --------------------- --------------------- --------------------- --------------------- --------------------- --------------------- --------------------- --------------------- --------------------- --------------------- --------------------- --------------------- --------------------- --------------------- --------------------- --------------------- --------------------- -A-----------------A- AAA---------------AAA -A-----------------A- 
--------------------- --------------------- --------------------- --------------------- --------------------- --------------------- --------------------- --------------------- --------------------- --------------------- --------------------- --------------------- --------------------- --------------------- --------------------- --------------------- --------------------- --------------------- --------------------- --------------------- --------------------- --------------------- --A---------------A-- --------------------- --A---------------A-- 
--------------------- --------------------- --------------------- --------------------- --------------------- --------------------- --------------------- --------------------- --------------------- --------------------- --------------------- --------------------- --------------------- --------------------- --------------------- --------------------- --------------------- --------------------- --------------------- --------------------- --------------------- --------------------- ---A-------------A--- --------------------- ---A-------------A--- 
--------------------- --------------------- --------------------- --------------------- --------------------- --------------------- --------------------- --------------------- --------------------- --------------------- --------------------- --------------------- --------------------- --------------------- --------------------- --------------------- --------------------- --------------------- --------------------- --------------------- --------------------- --------------------- ----A-----------A---- ---AAA---------AAA--- ----A-----------A---- 
--------------------- --------------------- --------------------- --------------------- --------------------- --------------------- --------------------- --------------------- --------------------- --------------------- --------------------- --------------------- --------------------- --------------------- --------------------- --------------------- --------------------- --------------------- --------------------- --------------------- --------------------- --------------------- --------------------- ---A-A---------A-A--- --------------------- 
--------------------- --------------------- --------------------- --------------------- --------------------- --------------------- --------------------- --------------------- --------------------- --------------------- --------------------- --------------------- --------------------- --------------------- --------------------- --------------------- --------------------- --------------------- --------------------- --------------------- --------------------- --------------------- --------------------- ---A-A---------A-A--- --------------------- 
--------------------- --------------------- --------------------- --------------------- --------------------- --------------------- --------------------- --------------------- --------------------- --------------------- --------------------- --------------------- --------------------- --------------------- --------------------- --------------------- --------------------- --------------------- --------------------- --------------------- --------------------- --------------------- --------------------- ---A-A--AAAAA--A-A--- --------------------- 
--------------------- --------------------- --------------------- --------------------- --------------------- --------------------- --------------------- --------------------- --------------------- --------------------- --------------------- --------------------- --------------------- --------------------- --------------------- --------------------- --------------------- --------------------- --------------------- --------------------- --------------------- --------------------- ----AAAAA---AAAAA---- ---AAA--A---A--AAA--- ----AAAAA---AAAAA---- 
--------------------- --------------------- --------------------- --------------------- --------------------- --------------------- --------------------- --------------------- --------------------- --------------------- --------------------- --------------------- --------------------- --------------------- --------------------- --------------------- --------------------- --------------------- --------------------- --------------------- --------------------- --------------------- --------------------- --------AAAAA-------- --------------------- 
