model
size = 21 22 15, scale = 0.05, origin = -y
material 
  colors = A:#777
voxels
--------------------- ----A---AAAAA---A---- ---A-------------A--- --A---------------A-- -A-----------------A- --------------------- --------------------- --------------------- -A-----------------A- -A-----------------A- -A-----------------A- -A-----------------A- -A-----------------A- --------------------- --------------------- --------------------- -A-----------------A- -A-----------------A- -A-----------------A- -A-----------------A- -A-----------------A- --------------------- 
----AAAAA---AAAAA---- ----A---A---A---A---- ----AAAAA---AAAAA---- --------------------- AAA---------------AAA A-A---------------A-A A-A---------------A-A A-A---------------A-A AAA---------------AAA --------------------- --------------------- --------------------- AAA---------------AAA A-A---------------A-A A-A---------------A-A A-A---------------A-A AAA---------------AAA --------------------- --------------------- --------------------- -A-----------------A- --------------------- 
--------------------- ----A---AAAAA---A---- ---A-------------A--- --A---------------A-- -A-----------------A- --------------------- --------------------- --------------------- -A-----------------A- -A-----------------A- -A-----------------A- -A-----------------A- -A-----------------A- --------------------- --------------------- --------------------- -A-----------------A- -A-----------------A- -A-----------------A- -A-----------------A- AAA---------------AAA --------------------- 
--------------------- --------------------- --------------------- --------------------- --------------------- --------------------- --------------------- --------------------- --------------------- --------------------- --------------------- --------------------- --------------------- --------------------- --------------------- --------------------- --------------------- --------------------- --------------------- --------------------- A-A---------------A-A --------------------- 
--------------------- --------------------- --------------------- --------------------- --------------------- --------------------- --------------------- --------------------- --------------------- --------------------- --------------------- --------------------- --------------------- --------------------- --------------------- --------------------- --------------------- --------------------- --------------------- --------------------- A-A---------------A-A --------------------- 
--------------------- --------------------- --------------------- --------------------- --------------------- --------------------- --------------------- --------------------- --------------------- --------------------- --------------------- --------------------- --------------------- --------------------- --------------------- --------------------- --------------------- --------------------- --------------------- --------------------- A-A---------------A-A --------------------- 
--------------------- --------------------- --------------------- --------------------- --------------------- --------------------- --------------------- --------------------- --------------------- --------------------- --------------------- --------------------- --------------------- --------------------- --------------------- --------------------- --------------------- --------------------- --------------------- -A-----------------A- AAA---------------AAA -A-----------------A- 
--------------------- --------------------- --------------------- --------------------- --------------------- --------------------- --------------------- --------------------- --------------------- --------------------- --------------------- --------------------- --------------------- --------------------- --------------------- --------------------- --------------------- --------------------- --------------------- --A---------------A-- --------------------- --A---------------A-- 
--------------------- --------------------- --------------------- --------------------- --------------------- --------------------- --------------------- --------------------- --------------------- --------------------- --------------------- --------------------- --------------------- --------------------- --------------------- --------------------- --------------------- --------------------- --------------------- ---A-------------A--- --------------------- ---A-------------A--- 
--------------------- --------------------- --------------------- --------------------- --------------------- --------------------- --------------------- --------------------- --------------------- --------------------- --------------------- --------------------- --------------------- --------------------- --------------------- --------------------- --------------------- --------------------- --------------------- ----A-----------A---- ---AAA---------AAA--- ----A-----------A---- 
--------------------- --------------------- --------------------- --------------------- --------------------- --------------------- --------------------- --------------------- --------------------- --------------------- --------------------- --------------------- --------------------- --------------------- --------------------- --------------------- --------------------- --------------------- --------------------- --------------------- ---A-A---------A-A--- --------------------- 
--------------------- --------------------- --------------------- --------------------- --------------------- --------------------- --------------------- --------------------- --------------------- --------------------- --------------------- --------------------- --------------------- --------------------- --------------------- --------------------- --------------------- --------------------- --------------------- --------------------- ---A-A---------A-A--- --------------------- 
--------------------- --------------------- --------------------- --------------------- --------------------- --------------------- --------------------- --------------------- --------------------- --------------------- --------------------- --------------------- --------------------- --------------------- --------------------- --------------------- --------------------- --------------------- --------------------- --------------------- ---A-A--AAAAA--A-A--- --------------------- 
--------------------- --------------------- --------------------- --------------------- --------------------- --------------------- --------------------- --------------------- --------------------- --------------------- --------------------- --------------------- --------------------- --------------------- --------------------- --------------------- --------------------- --------------------- --------------------- ----AAAAA---AAAAA---- ---AAA--A---A--AAA--- ----AAAAA---AAAAA---- 
--------------------- --------------------- --------------------- --------------------- --------------------- --------------------- --------------------- --------------------- --------------------- --------------------- --------------------- --------------------- --------------------- --------------------- --------------------- --------------------- --------------------- --------------------- --------------------- --------------------- --------AAAAA-------- --------------------- 
