model
size = 30 13 6, scale = 0.05, origin = -y
material 
  colors = A:#008 B:#009 C:#222 D:#333 E:#444 F:#555
voxels
------------------------------ ------------------------------ ------------------------------ -------------BBB-------------- ------------BAAAB------------- -----------BAAAAAB------------ -----------BAAAAAB------------ -----------BAAAAAB------------ ------------BAAAB------------- -------------BBB-------------- ------------------------------ ------------------------------ ------------------------------ 
------------------------------ ---BBB------------------BBBB-- ---BABBB--------------BBBAAA-- ---BAAAABB---BAB-----BAAAAAA-- ---BAAAAAABBACDDABBBBAAAAAAA-- --ABAAAAAAAACCCCCAAAAAAAAAAAB- -AABAAAAAAAACCDDCAAAAAAAAAAAB- --ABAAAAAAAACEEECAAAAAAAAAAAB- ---BAAAAABBBACCCABBBBAAAAAAA-- ---BAAABB----BAB-----BBAAAAA-- ---BABB----------------BBAAA-- ---BB--------------------BBB-- ------------------------------ 
--AAAAA------------------AA--- --ACCAAAA--------------AAAAAA- -AACCDDDAAA-----------BCCCCCA- -AAACDDEDCBA-BAB--AAAAEEEFFDA- -AAAAAAACDDCACDDAADEDCCCDEEFAA AAADCCCAAAACCCCCCDAAAAAAAAADEA AEAEEEEEDDDDCCDDCCDCCCCCCCAACA AAADCCCAACCCDEEECCCCCDDEEEEDAA AAAAAAAAACCAAFEEAADCAAACDEEEAA -AAACCCDDBA--BAB--AAACAAAACCA- -AADDDDAAA---------AAAADCCCCA- -AAEAAAA--------------AAADDDA- -AAAAA------------------AAAAA- 
--AAAAA------------------AAA-- --ACCAAAA--------------AAAAAA- -AACCDDDAAA-----------BCCCCCA- -AAACDDEDCA-ABAB--AAAAEEEFFDA- -AAAAAAACDDACCDDAADEDCCCDEEFAA AADDCCCAAAACCCCCCDAAAAAAAAADEA AEEEEEEEDDDDCCDDCCDCCCCCCCAACA AACDCCCAACCCDEEECCCCCDDEEEEDAA AAAAAAAAACCAAFEEAAACAAACDEEEAA -ACACCCDDAA--BAB--AAACAAAACCA- -ADDDDDAAA---------AAAADCCCCA- -AAEAAAA--------------AAADDDA- -AAAAA------------------AAAAA- 
------------------------------ ---BB-------------------BBBB-- ---ABBBB--------------BBAAAB-- --BAAAABBB---BAB-----BBAAAAB-- --BAAAAAAABBACDDABBBBAAAAAAB-- --BAAAAAAAAACCCCCAAAAAAAAAAAB- -BAAAAAAAAAACCDDCAAAAAAAAAAAB- -BAAAAAAAAAACEEECAAAAAAAAAAAB- --BAAAAABBBBACCCABBBBAAAAAAB-- --BAAABBB----BAB-----BBBAAAB-- --BAABB----------------BBAAB-- --BBB--------------------BBB-- ------------------------------ 
------------------------------ ------------------------------ ------------------------------ -------------BBB-------------- ------------BAAAB------------- -----------BAAAAAB------------ -----------BAAAAAB------------ -----------BAAAAAB------------ ------------BAAAB------------- -------------BBB-------------- ------------------------------ ------------------------------ ------------------------------ 
