model
size = 30 13 6, scale = 0.05, origin = -y
material 
  colors = A:#111 B:#222 C:#333 D:#444 E:#555
voxels
------------------------------ ------------------------------ ----AA--------------------A--- ------AAA----AAA--------AA---- ---------A-AAAAAAA----AA------ -------AAA-AAAAAAA--AA-------- ----AAA----AAAAAAA-A---------- --------AA-AAAAAAA-A---------- ------AA---AAAAAAA--AAAA------ ----AA-------AAA--------AAA--- ------------------------------ ------------------------------ ------------------------------ 
------------------------------ ---AA-------------------AAAA-- ---AAAAA--------------AAAAAA-- ---AAAAAAA---AAA-----AAAAAAA-- ---AAAAAAAAAABCCAAAAAAAAAAAA-- --AAAAAAAAAABBBBBAAAAAAAAAAAA- -AAAAAAAAAAABBCCBAAAAAAAAAAAA- --AAAAAAAAAABDDDBAAAAAAAAAAAA- ---AAAAAAAAAABBBAAAAAAAAAAAA-- ---AAAAAA----AAA-----AAAAAAA-- ---AAAA----------------AAAAA-- ---A---------------------AAA-- ------------------------------ 
--AAAAA------------------AA--- --ABBAAAA--------------AAAAAA- -AABBCCCAAA-----------ABBBBBA- -AAABCCDCBAA-AAA--AAAADDDEECA- -AAAAAAABCCBABCCAACDCBBBCDDEAA AAACBBBAAAABBBBBBCAAAAAAAAACDA ADADDDDDCCCCBBCCBBCBBBBBBBAABA AAACBBBAABBBCDDDBBBBBCCDDDDCAA AAAAAAAAABBAAEDDAACBAAABCDDDAA -AAABBBCCAA--AAA--AAABAAAABBA- -AACCCCAAA---------AAAACBBBBA- -AADAAAA--------------AAACCCA- -AAAA-------------------AAAAA- 
--AAAAA------------------AAA-- --ABBAAAA--------------AAAAAA- -AABBCCCAAA-----------ABBBBBA- -AAABCCDCBA-AAAA--AAAADDDEECA- -AAAAAAABCCABBCCAACDCBBBCDDEAA AACCBBBAAAABBBBBBCAAAAAAAAACDA ADDDDDDDCCCCBBCCBBCBBBBBBBAABA AABCBBBAABBBCDDDBBBBBCCDDDDCAA AAAAAAAAABBAAEDDAAABAAABCDDDAA -ABABBBCCAA--AAA--AAABAAAABBA- -ACCCCCAAA---------AAAACBBBBA- -AADAAAA--------------AAACCCA- -AAAA-------------------AAAAA- 
------------------------------ ---AA-------------------AAAA-- ---AAAAA--------------AAAAAA-- --AAAAAAAA---AAA-----AAAAAAA-- --AAAAAAAAAAABCCAAAAAAAAAAAA-- --AAAAAAAAAABBBBBAAAAAAAAAAAA- -AAAAAAAAAAABBCCBAAAAAAAAAAAA- -AAAAAAAAAAABDDDBAAAAAAAAAAAA- --AAAAAAAAAAABBBAAAAAAAAAAAA-- --AAAAAAA----AAA-----AAAAAAA-- --AAAAA----------------AAAAA-- --AA---------------------AAA-- ------------------------------ 
------------------------------ ------------------------------ ---AA------------------------- -----AA------AAA--------AA---- -------AA--AAAAAAA--AAAA------ ---------A-AAAAAAA-A---------- -----------AAAAAAA------------ ---------A-AAAAAAA-A---------- -----AAAA--AAAAAAA--AA-------- ---AA--------AAA------AAA----- -------------------------AA--- ------------------------------ ------------------------------ 
