model
size = 27 28 14, scale = 0.05, origin = -y
material 
  colors = A:#0FF B:#00E C:#0FC D:#0CC E:#09C F:#0F9 G:#9D6D0E H:#0F6 I:#963 J:#930 K:#EEE L:#111 M:#0CF N:#008 O:#200 P:#AAA
voxels
--------------------------- --------------------------- --------------------------- --------------------------- --------------------------- --------------------------- --------------------------- --------------------------- --------------------------- --------------------------- --------------------------- --------------------------- --------------------------- --------------------------- --------------------------- --------------------------- --------------------------- --------------------------- --------LLL-----LLL-------- --------------------------- --------------------------- --------------------------- --------------------------- --------------------------- --------------------------- --------------------------- --------------------------- --------------------------- 
--------------------------- --------------------------- --------------------------- --------------------------- --------------------------- --------------------------- --------------------------- --------------------------- --------------------------- --------------------------- --------------------------- --------------------------- --------------------------- --------------------------- --------------------------- --------------------------- --------------------------- --------------------------- ----------LL---LL---------- --------------------------- --------------------------- --------------------------- --------------------------- --------------------------- --------------------------- --------------------------- --------------------------- --------------------------- 
--------------------------- --------------------------- --------------------------- --------------------------- --------------------------- -------------J------------- ------------JJJ------------ -----------JJJJJ----------- -----------JJJJJ----------- -----------JJJJJ----------- -----------JJJJJ----------- ----------JJOOOJ----------- ---------IGOGGGOG---------- --------GGGGIIGGGII-------- --------IIKKIIGKKGGG------- -------IGKNNKGKPNKII------- -------GGKPNKGKNNKII------- -------GIGKKGGGKKGGG------- --------GGLLGIILLII-------- ----------GGIIIGG---------- -----------GIGGG----------- ------------GGI------------ ------------IGI------------ ------------IGG------------ -------------G------------- --------------------------- --------------------------- --------------------------- 
-------------B------------- ------------BAB------------ ------------BAB------------ -----------BAFAB----------- ----------BBAFABB---------- ---------BAAFHFAAB------BBB BBB------BAFHAHFFAB----BAB- -BAB----BAFHADAHFAB---BAB-- --BAB---BAFHADAHFAB--BAB--- ---BABB--BFHADAHAB--BAB---- ----BAABBAFHADAHFABBAB----- -----BAAAFHAADAHFAAAAB----- -----BAFFHADDCDAAFFFB------ ------BFHHADFCCDDAAFAB----- -----BAFHADDFCCDDAAHFAB---- ----BAFHADMMMCMDDAAHFAB---- ----BAFHADMMMCMDDAAHFAB---- ----BAFHAADMCCFDDAAFFAB---- -----BAFHHADCCFDAHHFAB----- ------BAFFHADCDAHFFAB------ -------BAAFHADAHFAAB------- --------BBAFHAHFABB-------- ---------BAFHAHFAB--------- ---------BAFHAHFAB--------- ----------BAFHFAB---------- -----------BAFAB----------- ------------BAB------------ -------------B------------- 
--------------------------- -------------A------------- -------------A------------- ------------ACA------------ ------------ACA------------ ----------AACBCAA---------- ----------ACBDBCCA------A-- --A------ACBDEDBCA-----A--- ---A-----ACBDEDBCA----A---- ----A-----CBDEDBB----A----- -----AA--ACBDEDBCA--A------ ------AAABBDDEDBCAAAA------ ------ACCBDEEFEDDCCC------- -------CBBDECFFEEDDCA------ ------ACBDEECFFEEDDBCA----- -----ACBDECCCFCEEDDBCA----- -----ACBDECCCFCEEDDBCA----- -----ACBDDECFFCEEDDCCA----- ------ACBBDEFFCEDBBCA------ -------ACCBDEFDDBCCA------- --------AACBDEDBCAA-------- ----------ACBDBCA---------- ----------ACBDBCA---------- ----------ACBDBCA---------- -----------ACBCA----------- ------------ACA------------ -------------A------------- --------------------------- 
--------------------------- --------------------------- --------------------------- -------------C------------- -------------C------------- ------------C-C-B---------- -----------C-B-AA---------- ----------C-DEDAA---------- ----------C-DED-C---------- ----------C-DED------------ ----------C-DED-C---------- -----------DDED-C---------- -------CC-DEEFEDDBBB------- -------C--DECFFEEDDB------- -------C-DEECFFEEDD-C------ ------C-DECCCFCEEDD-C------ ------C-DECCCFCEEDD-C------ ------C-DDECFFCEEDDCC------ -------C--DEFFCED--C------- --------CC-DEFDD-CC-------- ----------C-DED-C---------- -----------C-D-C----------- -----------C-D-C----------- -----------C-D-C----------- ------------C-C------------ -------------C------------- --------------------------- --------------------------- 
--------------------------- --------------------------- --------------------------- --------------------------- ----------------B---------- ---------------AA---------- ----------------B---------- ------------DED-B---------- ------------DED------------ ------------DED------------ ------------DED------------ -----------DDED------------ ----------DEEFEDD---------- ----------DECFFEEDD-------- ---------DEECFFEEDD-------- --------DECCCFCEEDD-------- --------DECCCFCEEDD-------- --------DDECFFCEEDD-------- ----------DEFFCED---------- -----------DEFDD----------- -----------BDEDB----------- -------------D------------- -------------D------------- -------------D------------- --------------------------- --------------------------- --------------------------- --------------------------- 
--------------------------- --------------------------- --------------------------- ----------------B---------- ---------------AA---------- -----------B----B---------- ----------AA--------------- ----------AA-E------------- -------------E------------- -------------E------------- -------------E------------- -------------E------------- ---------B-EEBE--B--------- --------AA-ECBBEAA--------- --------AAEECBBEAA--------- ---------ECCAACEE---------- ---------ECCAACEE---------- ----------ECBBCEE---------- -----------EBBCE----------- -----------B-B-B----------- -----------B-E-B----------- --------------------------- --------------------------- --------------------------- --------------------------- --------------------------- --------------------------- --------------------------- 
--------------------------- --------------------------- ----------------B---------- ---------------AA---------- -----------B----B---------- ----------AA--------------- -----------B--------------- -----------B--------------- --------------------------- --------------------------- --------------------------- ---------B-------B--------- --------AA------AA--------- ---------B---B---B--------- ---------B--AA---B--------- -------------B------------- -------------B------------- --------------------------- -----------B---B----------- -----------AA--AA---------- -----------B---B----------- --------------------------- --------------------------- --------------------------- --------------------------- --------------------------- --------------------------- --------------------------- 
--------------------------- ----------------B---------- ---------------AA---------- -----------B----B---------- ----------AA--------------- -----------B--------------- --------------------------- --------------------------- --------------------------- --------------------------- ---------B-------B--------- --------AA------AA--------- ---------B---B---B--------- ------------AA------------- -------------B------------- --------------------------- --------------------------- -----------B---B----------- -----------AA--AA---------- -----------B---B----------- --------------------------- --------------------------- --------------------------- --------------------------- --------------------------- --------------------------- --------------------------- --------------------------- 
--------------------------- ----------------B---------- -----------B----B---------- ----------AA--------------- -----------B--------------- --------------------------- --------------------------- --------------------------- --------------------------- ---------B-------B--------- --------AA------AA--------- ---------B---B---B--------- ------------AA------------- -------------B------------- --------------------------- --------------------------- -----------B---B----------- -----------AA--AA---------- -----------B---B----------- --------------------------- --------------------------- --------------------------- --------------------------- --------------------------- --------------------------- --------------------------- --------------------------- --------------------------- 
--------------------------- -----------B----B---------- ----------AA--------------- -----------B--------------- --------------------------- --------------------------- --------------------------- --------------------------- ---------B-------B--------- --------AA------AA--------- ---------B---B---B--------- ------------AA------------- -------------B------------- --------------------------- -----------B---B----------- -----------B---B----------- -----------AA--AA---------- -----------B---B----------- --------------------------- --------------------------- --------------------------- --------------------------- --------------------------- --------------------------- --------------------------- --------------------------- --------------------------- --------------------------- 
--------------------------- -----------B--------------- -----------B--------------- --------------------------- --------------------------- --------------------------- --------------------------- --------------------------- ---------B-------B--------- ---------B-------B--------- -------------B------------- -------------B------------- --------------------------- --------------------------- --------------------------- --------------------------- --------------------------- --------------------------- --------------------------- --------------------------- --------------------------- --------------------------- --------------------------- --------------------------- --------------------------- --------------------------- --------------------------- --------------------------- 
--------------------------- -----------B--------------- --------------------------- --------------------------- --------------------------- --------------------------- --------------------------- --------------------------- ---------B-------B--------- --------------------------- -------------B------------- --------------------------- --------------------------- --------------------------- --------------------------- --------------------------- --------------------------- --------------------------- --------------------------- --------------------------- --------------------------- --------------------------- --------------------------- --------------------------- --------------------------- --------------------------- --------------------------- --------------------------- 
