model
size = 24 26 24, scale = 0.05, origin = -y
material 
  colors = A:#93E9FF B:#F96 C:#FF3 D:#F09 E:#0F3 F:#FC3 G:#F9C H:#F9F I:#CC9 J:#FF9 K:#FCF L:#FC6 M:#CF9 N:#F6C O:#F3C P:#F69 Q:#F99 R:#F30 S:#F93 T:#F33 U:#F03 V:#FC0 W:#FF6 X:#F00 Y:#CF6 Z:#F0C Aa:#F39 Ab:#CF0 Ac:#CFC Ad:#CC6 Ae:#F66 Af:#FFF Ag:#FCC Ah:#FC9 Ai:#FF0 Aj:#CCF Ak:#F90 Al:#CCC Am:#F60 An:#FFC Ao:#F63 Ap:#F0F Aq:#F36 Ar:#CF3 As:#CFF At:#F3F Au:#CC0 Av:#555 Aw:#F6F Ax:#CC3 Ay:#F06 Az:#EEE Ba:#0F9 Bb:#222 Bc:#444 Bd:#111 Be:#001 Bf:#888 Bg:#09C Bh:#0C3
voxels
- - - - - - - - - - - - - - - - - - - - - - - -   - - - - - - - - - - - - - - - - - - - - - - - -   - - - - - - - - - - - - - - - - - - - - - - - -   - - - - - - - - - - - - - - - - - - - - - - - -   - - - - - - - - - - - - - - - - - - - - - - - -   - - - - - - - - - - - - - - - - - - - - - - - -   - - - - - - - - - - - - - - - - - - - - - - - -   - - - - - - - - - - - - - - - - - - - - - - - -   - - - - - - - - - - - - - - - - - - - - - - - -   - - - - - - - - - - - - - - - - - - - - - - - -   - - - - - - - - - - - - - - - - - - - - - - - -   - - - - - - - - - - - - - - - - - - - - - - - -   - - - - - - - - - - - - - - - - - - - - - - - -   - - - - - - - - - - - - - - - - - - - - - - - -   - - - - - - - - - - - - - - - - - - - - - - - -   - - - - - - - - - - - - - - - - - - - - - - - -   - - - - - - - - - - - - - - - - - - - - - - - -   - - - - - - - - - - - - - - - - - - - - - - - -   - - - - - - - - - - - - - - - - - - - - - - - -   - - - - - - - - - - - - - - - - - - - - - - - -   - - - - - - - - - - - - - - - - - - - - - - - -   - - - - - - - - - - - - - - - - - - - - - - - -   - - - - - - - - - - - - - - - - - - - - - - - -   - - - - - - - - - - - - - - - - - - - - - - - -   - - - - - - BaBa- - - - - - - - - - - - - - - -   - - - - - - - - - - - - - - - - - - - - - - - -   
- - - - - - - - - - - - - - - - - - - - - - - -   - - - - - - - - - - - - - - - - - - - - - - - -   - - - - - - - - - - - - - - - - - - - - - - - -   - - - - - - - - - - - - - - - - - - - - - - - -   - - - - - - - - - - - - - - - - - - - - - - - -   - - - - - - - - - - - - - - - - - - - - - - - -   - - - - - - - - - - - - - - - - - - - - - - - -   - - - - - - - - - - - - - - - - - - - - - - - -   - - - - - - - - - - - - - - - - - - - - - - - -   - - - - - - - - - - - - - - - - - - - - - - - -   - - - - - - - - - - - - - - - - - - - - - - - -   - - - - - - - - - - - - - - - - - - - - - - - -   - - - - - - - - - - - - - - - - - - - - - - - -   - - - - - - - - - - - - - - - - - - - - - - - -   - - - - - - - - - - - - - - - - - - - - - - - -   - - - - - - - - - - - - - - - - - - - - - - - -   - - - - - - - - - - - - - - - - - - - - - - - -   - - - - - - - - - - - - - - - - - - - - - - - -   - - - - - - - - - - - - - - - - - - - - - - - -   - - - - - - - - - - - - - - - - - - - - - - - -   - - - - - - - - - - - - - - - - - - - - - - - -   - - - - - - - - - - - - - - - - - - - - - - - -   - - - - - - - - - - - - - - - - - - - - - - - -   - - - - - - - - - - - - - - - - - - - - - - - -   - - - - - - BaBfBa- - - - - - - - - - - - - - -   - - - - - - - - - - - - - - - - - - - - - - - -   
- - - - - - - - - - - - - - - - - - - - - - - -   - - - - - - - - - - - - - - - - - - - - - - - -   - - - - - - - - - - - - - - - - - - - - - - - -   - - - - - - - - - - - - - - - - - - - - - - - -   - - - - - - - - - - - - - - - - - - - - - - - -   - - - - - - - - - - - - - - - - - - - - - - - -   - - - - - - - - - - - - - - - - - - - - - - - -   - - - - - - - - - - - - - - - - - - - - - - - -   - - - - - - - - - - - - - - - - - - - - - - - -   - - - - - - - - - - - - - - - - - - - - - - - -   - - - - - - - - - - - - - - - - - - - - - - - -   - - - - - - - - - - - - - - - - - - - - - - - -   - - - - - - - - - - - - - - - - - - - - - - - -   - - - - - - - - - - - - - - - - - - - - - - - -   - - - - - - - - - - - - - - - - - - - - - - - -   - - - - - - - - - - - - - - - - - - - - - - - -   - - - - - - - - - - - - - - - - - - - - - - - -   - - - - - - - - - - - - - - - - - - - - - - - -   - - - - - - - - - - - - - - - - - - - - - - - -   - - - - - - - - - - - - - - - - - - - - - - - -   - - - - - - - - - - - - - - - - - - - - - - - -   - - - - - - - - - - - - - - - - - - - - - - - -   - - - - - - - - - - - - - - - - - - - - - - - -   - - - - - - - - - - - - - - - - - - - - - - - -   - - - - - - - BaBfBa- - - - - - - - - - - - - -   - - - - - - - - - - - - - - - - - - - - - - - -   
- - - - - - - - - - - - - - - - - - - - - - - -   - - - - - BhBg- BhBg- - - - - - - - Af- - - - -   - - - - - - - - - - - - - - - - - - - - - - - -   - - - - AvAvAvAvAvAvAvAvAvAvAvAvAvAvAvAv- - - -   - - - - Av- E E E E E E E E E E E E - Av- - - -   - - - - AvE E E D D D D D D D D E E E Av- - - -   - - - - AvE E D D - - - - - - D D E E Av- - - -   - - - - AvE E D - D D D D D D - D E E Av- - - -   - - - - AvE D - D D E E E E D D - D E Av- - - -   - - - - AvE D D E E E E E E E E D D E Av- - - -   - - - - AvE E E E E - E E - E E E E E Av- - - -   - - - - AvE AzAzAzE E E E E E AzAzAzE Av- - - -   - - - - AvAzAzAzAzAzE E E E AzAzAzAzAzAv- - - -   - - - - AvAzBdBdBdAzAzE E AzAzBdBdBdAzAv- - - -   - - - - AvAzBdBdBdAzAzE E AzAzBdBdBdAzAv- - - -   - - - - AvAzBdBdBdAzAzE E AzAzBdBdBdAzAv- - - -   - - - - AvAzAzAzAzAzE E E E AzAzAzAzAzAv- - - -   - - - - AvE AzAzAzE - E E - E AzAzAzE Av- - - -   - - - - AvAvAvAvAvAvAvAvAvAvAvAvAvAvAvAv- - - -   - - - - - - - - - - - - - - - - - - - - - - - -   - - - - - - - - - - - - - - - - - - - - - - - -   - - - - - - - - - - - - - - - - - - - - - - - -   - - - - - - - - - - - - - - - - - - - - - - - -   - - - - - - - - - - - - - - - - - - - - - - - -   - - - - - - - - BaBfBa- - - - - - - - - - - - -   - - - - - - - - - - - - - - - - - - - - - - - -   
- - - B V AnAkAiAuAyAoJ Z AdD N N P B AuR - - -   - - - U AnAlAnF S AyApI Y Z N J AoC AcX Ar- - -   - - C AcAfL AtM F ArB F AaC O H R G AaAwAqAk- -   - - G P A A A A A A A A A A A A A A A A AtAn- -   - - K B A E A A A A A A A A A A A A E A P At- -   - - R Q A A A A A A A A A A A A A A A A Z D - -   - - AjV A A A A A A A A A A A A A A A A AaO - -   - - W X A A A A A A A A A A A A A A A A AeAk- -   - - S AuA A A A A A A A A A A A A A A A AmT - -   - - C S A A A A A A A A A A A A A A A A M As- -   - - O F A A A A A A E A A E A A A A A A AlAl- -   - - U AkA A A A A A A A A A A A A A A A AfS - -   - - F M A A A A A A A A A A A A A A A A AqAb- -   - - T AdA A A A A A A A A A A A A A A A AoAw- -   - - AqT A A A A A A A A A A A A A A A A R O - -   - - AiAjA A A A A A A A A A A A A A A A J Ah- -   - - F Z A A A A A A A A A A A A A A A A Q C - -   - - M Y A A A A A A E A A E A A A A A A Y Y - -   - - W AaA A A A A A A A A A A A A A A A X U - -   - - AoAeK O B AdAoAlY H L ApW AnAkApAkG B P - -   - - - AmQ J M T R AfAaQ AyAwAdAxD B O ArAc- - -   - - - - - - - - - - - - - - - - - - - - - - - -   - - - - - - - - - - - - - - - - - - - - - - - -   - - - - - - - - - - - - - - - - - - - - - - - -   - - - - - - - - - BaBfBa- - - - - - - - - - - -   - - - - - - - - - - - - - - - - - - - - - - - -   
- - - AgB N AxH ArAeAqI AyAeJ V N AeAuG Ad- - -   - - - S U AcAiAsAqAxAoAsArF AbAmJ AmV AdT - - -   - AaAwAbAcM ArAgAtAhR AgAdAmAgAlH AhAnApAjG L -   AtBbAmAlA A A A A A A A A A A A A A A A Z K BbAf  AjBbG AjA A A A A A A A A A A A A A A A Y R BbH   AqAcH B A A A A A A A A A A A A A A A A AaAjAmAu  AfBbAsX A A A A A A A A A A A A A A A A AeW BbX   AaBbAgG A A A A A A A A A A A A A A A A AmS BbAw  AiL S L A A A A A A A A A A A A A A A A AhC L An  Q BbAbAuA A A A A A A A A A A A A A A A AhO BbAy  AxBbAlAfA A A A A A A A A A A A A A A A J U BbW   H AgAjAiA A A A A A A A A A A A A A A A I F Y An  AqBbB J A A A A A A A A A A A A A A A A F T BbAl  V BbX AbA A A A A A A A A A A A A A A A N AqBbL   AeArG AgA A A A A A A A A A A A A A A A AoAiJ Q   X BbL AyA A A A A A A A A A A A A A A A R F BbAu  V BbAuI A A A A A A A A A A A A A A A A L M BbV   D AuAfAsA A A A A A A A A A A A A A A A AiW Z An  - K AiAgA A A A A A A A A A A A A A A A V AoAk-   - - J ApAeAnS AsAcQ AxAqAfX C S AnY C S AmAp- -   - - - AeAmAtAbAgAaAxAiAfAqV AgAhAxG K AbAl- - -   - - - - - - - - - - - BeBe- - - - - - - - - - -   - - - - - - - - - - - BeBe- - - - - - - - - - -   - - - - - - - - - - - BaBa- - - - - - - - - - -   - - - - - - - - - - BaBa- - - - - - - - - - - -   - - - - - - - - - - - Ba- - - - - - - - - - - -   
- - - - - - - - - - - - - - - - - - - - - - - -   - - - ApS B AdAuT K AgAtAfAhN U AmAhB AuR - - -   - AnApB AbAcZ S AqC F AtAqY J P AlC Q K L AhAu-   O BcAwU AlAaC F AiAgG W AoApH I T Y V AkAiAhBcAa  U BcAmAcAjH K AkF AtArAdR P Q B L U X O V J BcAi  F Z G P B N Q M M AjAsD J R Z M AyP AuB AmI O Q   T BcH B X AcAjAdW AqH W Q ArAkP AoI S AkAlF BcAx  AqBcAsQ G M I T AoAfD ApY AqD C Y B F AnT N BcH   AiF AgV L T G AjApAaN AwX AtArG G M AkAtL AoAnAq  F BcS X AuL AdZ B AiO AmB P U K N P M D AyR BcV   M BcAbAuAfI ApY U Q J G AcZ AbR J C AdO AoL BcAe  W AsAlS AiAbAwAaAcAxAdH AaAaS AjH G T AkY AiO X   AoBcAjF J AgN AeP H Z AsH AeAhW Q K AjT G V BcV   ApBcB AkAbAxR AmB AqC AgN AmAaS Z R Z AsN AmBcD   B N X M AgAiAtAhQ V K S AcM K C AkAjY AlJ AlAsL   U BcG AdAyArAtAhV AeQ AbM AlAnO D W AaS H T BcAy  AcBcL T I C W J X X AjAlT AfAsU ArS AeAbQ L BcAy  P AdAuAjAsK AdI AuV I AjL AqV F U C AmAwZ AyAbAr  - Z AfZ AgAuD F S D G B I AoU T AbO AhO AkAoAw-   - - AiY ApK W N F L AdX AbR J AqS U AhAhD Y - -   - - - AaAeAkApAoAkAyApG AgJ AnAiAhF J C Ar- - -   - - - - - - - - - - BeBeBeBe- - - - - - - - - -   - - - - - - - - - - - BeBe- - - - - - - - - - -   - - - - - - - - - - - BaBa- - - - - - - - - - -   - - - - - - - - - - - - BaBa- - - - - - - - - -   - - - - - - - - - - - - Ba- - - - - - - - - - -   
- - - - - - - - - - - - - - - - - - - - - - - -   - - - - - - - - - - - - - - - - - - - - - - - -   - Q T R B B Z N ApL G G C AlAaAoP AaAxO AuC Ah-   - V AqJ U AcAcAoAeAuArH K L K R I AeH AkK Y Y -   - X AiQ AcAaAgR AxAfAsAsQ Q AnL B AmAqT AkU Ap-   - AuF Y P H F L AhAiH AgAjAuAsAiM M V AsO P P -   - S M X B N G AiW J D S I V V V P AlAeAlB I R -   - F W B Q AcArV AcAbN AbG AnU AmC AfX S AkB Ar-   - AkAoAcV M AsAmAfAgO AlAdAfJ AlG AqV AbAnM Aq-   - M ApAaX T H AlAeAyJ AjApAoAnT K AoD AwAtP At-   - AdB H AuL D T F I AdB AwZ AxL R R L O D C P -   - T U N S I N L AmAsZ X N AcAwAyAjJ AyAhO G Z -   - AjAcAcF AbO AyAxAgC G R AgAfAoW Q AyC AkK Aa-   - Z P M AkAgJ AoK ApK L AtF H Y S Y ArY T R Ae-   - Y B T M AxAdY C AeQ AuAtG AuG C X AdU AsAjAm-   - AaQ L AdAiZ G AgAxAjAfW ArX N O B AiP AlW M -   - AeV I T ArC N AtAhI AiAdAsAwJ U AcAhI S S Al-   - AmX AbAjC K J AjW G J D H AnH F AaY B AbC Af-   - AhAuAgZ K Q H AqAcAdAbW D AyQ T H ApM AwO Aq-   - - S AxY AuAjQ AfAfApAgApN W Z AqN P P O U - -   - - - - - - I Z AaAeAwAyAwO AnAkAiAc- - - - - -   - - - - - - - - - - - - - - - - - - - - - - - -   - - - - - - - - - - - - - - - - - - - - - - - -   - - - - - - - - - - - - - - - - - - - - - - - -   - - - - - - - - - - - - BaBfBa- - - - - - - - -   - - - - - - - - - - - - - - - - - - - - - - - -   
- - - - - - - - - - - - - - - - - - - - - - - -   - - - - - - - - - - - - - - - - - - - - - - - -   - - J F R D R R B - - - - - - U AoAbAoAyAhAa- -   - - Q G J ArL AjM - - - - - - P R AwR AyY Ae- -   - - Y ArQ U AiW P - - - - - - I L O J ArApAm- -   - - X AsY AbV S C - - - - - - B AiAhQ AdP M - -   - - B H X S AmC G - - - - - - M V C Y AiR Al- -   - - AcD B AhAlO K - - - - - - P AmY X AhArAf- -   - - AaN AcAaT U R - - - - - - C AlU B Y AqAq- -   - - H O AaK L F Aj- - - - - - G T P AcApAtAo- -   - - N J H AnAyT W - - - - - - K L I AaP P R - -   - - AcAdN AsAoAqS - - - - - - R AyB H R Z J - -   - - M Z AcV Y AiC N S M AiL AhAjAoM N ArAaQ - -   - - T C M U G F O O AhW Q I J W Y P AcAqAeY - -   - - L K T J N M U J AaAoAxAbI S G C M AtAmX - -   - - I Q L AnJ W F AdK ApH AgF C N G T P M B - -   - - AbAjI AxH AoT Z AnB AqAxN O J K L Z AlAc- -   - - AgI AbAwQ ApAqC AsU V AiAoU H R I AaAfAa- -   - - AxG AgAfZ B AiK V AcAeArR F Q AjAbAeAqH - -   - - - - AxH AkU F Q U P X C L T Z W AgAm- - - -   - - - - - - - - - AjJ B V K Ai- - - - - - - - -   - - - - - - - - - - - - - - - - - - - - - - - -   - - - - - - - - - - - - - - - - - - - - - - - -   - - - - - - - - - - - - - - - - - - - - - - - -   - - - - - - - - - - - - - BaBfBa- - - - - - - -   - - - - - - - - - - - - - - - - - - - - - - - -   
- - - - - - - - - - - - - - - - - - - - - - - -   - - - - - - - - - - - - - - - - - - - - - - - -   - - F G F B H - - - - - - - - - - N M ApH Ab- -   - - N ArG AkQ - - - - - - - - - - AcAlP AqAw- -   - - AoAsArAnZ - - - - - - - - - - M AfR V O - -   - - R H AsAtAk- - - - - - - - - - T AqArAeAh- -   - - L D H D D - - - - - - - - - - L AoAqX C - -   - - AiN D O Ar- - - - - - - - - - I R AtV Y - -   - - V O N AkU - - - - - - - - - - AbJ P D U - -   - - AmJ O T Ab- - - - - - - - - - AgQ Z L P - -   - - AlAdJ AsS - - - - - - - - - - AxY AaAyI - -   - - T Z AdAlAh- - - - - - - - - - AiX AeAyB - -   - - L C Z S AaZ S - - - - - - AdAjArB AmArM - -   - - AyK C AbK Y AbN X AcAmR AwApW C AcM AdP - -   - - AoQ K AwAnAaAlO B AgM ArAfAwS K AaAlAiC - -   - - Y AjQ O AsAeAjJ AcF AlAqH N C AuH AfAhG - -   - - G I AjAhV AmB AdAaG AfAtAuR O K N AqY K - -   - - N G I C U AhX Z H ArAqP X AtU AkAcAoApR - -   - - J AdG Y J AhG C N AsAoZ AwAtF O M R P Aj- -   - - - - AdU AnJ L K AcH R AaAnW T B T J - - - -   - - - - - - - - - - - D J - - - - - - - - - - -   - - - - - - - - - - - - - - - - - - - - - - - -   - - - - - - - - - - - - - - - - - - - - - - - -   - - - - - - - - - - - - - - - - - - - - - - - -   - - - - - - - - - - - - - - BaBfBa- - - - - - -   - - - - - - - - - - - - - - - - - - - - - - - -   
- - - - - - - - - - - - - - - - - - - - - - - -   - - - - - - - - - - - - - - - - - - - - - - - -   - - AgN G T - - - - - - - - - - - - X AdT N - -   - - ApJ ArL - - - - - - - - - - - - G ApL Ac- -   - - AeH AsAy- - - - - - - - - - - - L AwI M - -   - - AxQ H Ao- - - - - - - - - - - - AuN AbT - -   - - AhZ D Y - - - - - - - - - - - - AfR AgL - -   - - W AkN G - - - - - - - - - - - - AiAtAxI - -   - - AcD O N - - - - - - - - - - - - J AtAiAb- -   - - AfArJ J - - - - - - - - - - - - AbW ArAg- -   - - AeU AdH - - - - - - - - - - - - AgAdC Ax- -   - - F AbZ Q - - - - - - - - - - - - AyD K Ai- -   - - AmS C Z Q Q - - - - - - - - AdAfI W AuAr- -   - - AxAhK AkZ AjP - - - - - - AfApAeAsApK C - -   - - K AaQ D AkI I T P ArG H AeAeAwF AgAwAkK - -   - - C K AjArD G B AjI AsArAsX F N AmApAmO Au- -   - - AgAnI U ArAdM Z B H AsAgV AmR AxAeG B K - -   - - AtAsG AbU ApP Y M D H S D AxAtK AxH AkAk- -   - - AjV AdS AbAwC AaP N D AbL K AtC AhAsAnO - -   - - - - - - - - - AeC O N AlAy- - - - - - - - -   - - - - - - - - - - - - - - - - - - - - - - - -   - - - - - - - - - - - - - - - - - - - - - - - -   - - - - - - - - - - - - - - - - - - - - - - - -   - - - - - - - - - - - - - - - - - - - - - - - -   - - - - - - - - - - - - - - - BaBfBa- - - - - -   - - - - - - - - - - - - - - - - - - - - - - - -   
- - - - - - - - - - - - - - - - - - - - - - - -   - - - - - - - - - - - - - - - - - - - - - - - -   - - AtAeN P - - - - - - - - - - - - S AdW Ay- -   - - W AmJ B - - - - - - - - - - - - AbZ AdI - -   - - AdM H Q - - - - - - - - - - - - AlC D As- -   - - D AlQ V - - - - - - - - - - - - AjK W Ag- -   - - W AfZ X - - - - - - - - - - - - B Q ApAp- -   - - ApAqAkAu- - - - - - - - - - - - X AjAwAe- -   - - AwAoD S - - - - - - - - - - - - G I AmAx- -   - - AmR ArF - - - - - - - - - - - - L G G Ah- -   - - G J U Ak- - - - - - - - - - - - AuAdH W - -   - - H Q AbM - - - - - - - - - - - - AfApAsAc- -   - - AsY S AdW - - - - - - - - - - S AiAwAgAf- -   - - AgX AhT S W - - - - - - - - AfF J N S Ae- -   - - S B AaAjC AdAuAg- - - - B K AeAkAbR AbF - -   - - AbAcK Z O D V AyX AkAgB U AnF M AgAtAlAm- -   - - AlAaAnY U W AnI AuO AxX AcAsAmAdAyAtAjAx- -   - - AjH AsAaF ApAfAsS B AiG P V AxT I W B K - -   - - - N V AeT AwAoAgF AkArL B U K AjAsAdX - - -   - - - - - - - - - - - AnC - - - - - - - - - - -   - - - - - - - - - - - - - - - - - - - - - - - -   - - - - - - - - - - - - - - - - - - - - - - - -   - - - - - - - - - - - - - - - - - - - - - - - -   - - - - - - - - - - - - - - - - - - - - - - - -   - - - - - - - - - - - - - - - - BaBa- - - - - -   - - - - - - - - - - - - - - - - - - - - - - - -   
- - - - - - - - - - - - - - - - - - - - - - - -   - - - - - - - - - - - - - - - - - - - - - - - -   - - G AkAe- - - - - - - - - - - - - - AxM Ap- -   - - H T Am- - - - - - - - - - - - - - AiP B - -   - - AsAsM - - - - - - - - - - - - - - ArC U - -   - - AgAlAl- - - - - - - - - - - - - - C G Ac- -   - - S S Af- - - - - - - - - - - - - - K K P - -   - - AbAbAq- - - - - - - - - - - - - - AuR B - -   - - - - - Ah- - - - - - - - - - - - W - - - - -   - - AjO R - - - - - - - - - - - - - - AkW V - -   - - B AhJ - - - - - - - - - - - - - - O S X - -   - - - - - An- - - - - - - - - - - - Am- - - - -   - - G Y Y As- - - - - - - - - - - - G AkO S - -   - - L U X V Y - - - - - - - - - - J H AnU F - -   - - - - - - G W Ap- - - - - - AuK Q - - - - - -   - - AfI AcJ N ApB Ad- - - - AnX AnY AgD T M - -   - - AiB AaAnJ AwU T AwC AtAhAtAwAsX S O AqAd- -   - - J M H AxH AmAcAjO K P AaD AnV B AbAkAiT - -   - - - P N AwQ G P Z AhAuZ K O AyU AcAlT F - - -   - - - - - - - - - - - - - - - - - - - - - - - -   - - - - - - - - - - - - - - - - - - - - - - - -   - - - - - - - - - - - - - - - - - - - - - - - -   - - - - - - - - - - - - - - - - - - - - - - - -   - - - - - - - - - - - - - - - - - - - - - - - -   - - - - - - - - - - - - - - - - - - - - - - - -   - - - - - - - - - - - - - - - - - - - - - - - -   
- - - - - - - - - - - - - - - - - - - - - - - -   - - - - - - - - - - - - - - - - - - - - - - - -   - - W AiAk- - - - - - - - - - - - - - I W P - -   - - S F T - - - - - - - - - - - - - - B AcZ - -   - - C M As- - - - - - - - - - - - - - M AfAa- -   - - O W Al- - - - - - - - - - - - - - P AeAe- -   - - U AoS - - - - - - - - - - - - - - C F Am- -   - - F ApAb- - - - - - - - - - - - - - G AmM - -   - - - - - F - - - - - - - - - - - - Ae- - - - -   - - AqU O - - - - - - - - - - - - - - R K Af- -   - - AiAcAh- - - - - - - - - - - - - - AjC Aq- -   - - - - - Ad- - - - - - - - - - - - Al- - - - -   - - M B Y T - - - - - - - - - - - - AfS AtR - -   - - W Q U AjW - - - - - - - - - - AtAqC AjJ - -   - - - - - - S Ao- - - - - - - - AuP - - - - - -   - - ApX I Y C Z N - - - - - - F X Z R U AfY - -   - - B AuB AaO AcAoI AfArAgD AgN AwAaJ F AaX - -   - - U S M AeU AgR AbAeC S ArF AoAnAeQ T AiB - -   - - - - - - - - L AgF K AbU G R - - - - - - - -   - - - - - - - - - - - - - - - - - - - - - - - -   - - - - - - - - - - - - - - - - - - - - - - - -   - - - - - - - - - - - - - - - - - - - - - - - -   - - - - - - - - - - - - - - - - - - - - - - - -   - - - - - - - - - - - - - - - - - - - - - - - -   - - - - - - - - - - - - - - - - - - - - - - - -   - - - - - - - - - - - - - - - - - - - - - - - -   
- - - - - - - - - - - - - - - - - - - - - - - -   - - - - - - - - - - - - - - - - - - - - - - - -   - - W AkAi- - - - - - - - - - - - - - ArO Ay- -   - - AnO F - - - - - - - - - - - - - - AsU Ar- -   - - AlB M - - - - - - - - - - - - - - H F Ad- -   - - L AkW - - - - - - - - - - - - - - D T Ai- -   - - Q AnAo- - - - - - - - - - - - - - N AqAh- -   - - AuAtAp- - - - - - - - - - - - - - O AiY - -   - - - - - Ar- - - - - - - - - - - - Af- - - - -   - - AnO U - - - - - - - - - - - - - - AdM P - -   - - AfAkAc- - - - - - - - - - - - - - Z W R - -   - - - - - P - - - - - - - - - - - - Q - - - - -   - - Z AsB Z - - - - - - - - - - - - AxK ApAq- -   - - AcAlQ AaAp- - - - - - - - - - AeH Q B At- -   - - - - - - AwAm- - - - - - - - I X - - - - - -   - - F AbX AmN G N - - - - - - H F V V I AcZ - -   - - G AwAuM R H AcAjAoAxX J AuAuN D AeG P Aa- -   - - ArO S AlAtAsM I Y AwG AbV X AoL X AdB Ae- -   - - - - - - - - - - - AfL - - - - - - - - - - -   - - - - - - - - - - - - - - - - - - - - - - - -   - - - - - - - - - - - - - - - - - - - - - - - -   - - - - - - - - - - - - - - - - - - - - - - - -   - - - - - - - - - - - - - - - - - - - - - - - -   - - - - - - - - - - - - - - - - - - - - - - - -   - - - - - - - - - - - - - - - - - - - - - - - -   - - - - - - - - - - - - - - - - - - - - - - - -   
- - - - - - - - - - - - - - - - - - - - - - - -   - - - - - - - - - - - - - - - - - - - - - - - -   - - - - Ak- - - - - - - - - - - - - - Ak- - - -   - - - - O - - - - - - - - - - - - - - An- - - -   - - - - B - - - - - - - - - - - - - - At- - - -   - - - - Ak- - - - - - - - - - - - - - D - - - -   - - - - An- - - - - - - - - - - - - - O - - - -   - - - - At- - - - - - - - - - - - - - Ak- - - -   - - - - - Am- - - - - - - - - - - - Z - - - - -   - - - - O - - - - - - - - - - - - - - As- - - -   - - - - Ak- - - - - - - - - - - - - - Al- - - -   - - - - - Af- - - - - - - - - - - - F - - - - -   - - - - AsAq- - - - - - - - - - - - G Ab- - - -   - - - - AlAoAf- - - - - - - - - - K ArAw- - - -   - - - - - - AeAl- - - - - - - - AfR - - - - - -   - - - - AbJ F S Af- - - - - - X H AjH Ah- - - -   - - - - AwQ AmAbH I AtAhAhQ AuV AuW D C - - - -   - - - - O Y AxAwAuG AtC AaV K D X S N Y - - - -   - - - - - - - - - - - - - - - - - - - - - - - -   - - - - - - - - - - - - - - - - - - - - - - - -   - - - - - - - - - - - - - - - - - - - - - - - -   - - - - - - - - - - - - - - - - - - - - - - - -   - - - - - - - - - - - - - - - - - - - - - - - -   - - - - - - - - - - - - - - - - - - - - - - - -   - - - - - - - - - - - - - - - - - - - - - - - -   - - - - - - - - - - - - - - - - - - - - - - - -   
- - - - - - - - - - - - - - - - - - - - - - - -   - - - - - - - - - - - - - - - - - - - - - - - -   - - - - Ai- - - - - - - - - - - - - - G - - - -   - - - - J - - - - - - - - - - - - - - K - - - -   - - - - Ab- - - - - - - - - - - - - - R - - - -   - - - - Ag- - - - - - - - - - - - - - Aj- - - -   - - - - Ay- - - - - - - - - - - - - - W - - - -   - - - - I - - - - - - - - - - - - - - S - - - -   - - - - - Ah- - - - - - - - - - - - H - - - - -   - - - - Ag- - - - - - - - - - - - - - O - - - -   - - - - Ap- - - - - - - - - - - - - - U - - - -   - - - - - I - - - - - - - - - - - - Ae- - - - -   - - - - AxF - - - - - - - - - - - - X T - - - -   - - - - AhN Aa- - - - - - - - - - Z V Aq- - - -   - - - - - - K U C - - - - - - B AeAc- - - - - -   - - - - AcR AnP K K - - - - AnU X AgL F - - - -   - - - - AfL AsI Q AnV U D AqAfAcV F AyM - - - -   - - - - - - - B AjAsAmAbArAfAoP D - - - - - - -   - - - - - - - - - - - - - - - - - - - - - - - -   - - - - - - - - - - - - - - - - - - - - - - - -   - - - - - - - - - - - - - - - - - - - - - - - -   - - - - - - - - - - - - - - - - - - - - - - - -   - - - - - - - - - - - - - - - - - - - - - - - -   - - - - - - - - - - - - - - - - - - - - - - - -   - - - - - - - - - - - - - - - - - - - - - - - -   - - - - - - - - - - - - - - - - - - - - - - - -   
- - - - - - - - - - - - - - - - - - - - - - - -   - - - - - - - - - - - - - - - - - - - - - - - -   - - - - J L - - - - - - - - - - - - D Ah- - - -   - - - - I Ai- - - - - - - - - - - - N Ah- - - -   - - - - F V - - - - - - - - - - - - O J - - - -   - - - - N Am- - - - - - - - - - - - J I - - - -   - - - - AoAl- - - - - - - - - - - - AdF - - - -   - - - - R T - - - - - - - - - - - - Z N - - - -   - - - - - L - - - - - - - - - - - - C - - - - -   - - - - AiAy- - - - - - - - - - - - K R - - - -   - - - - V Ao- - - - - - - - - - - - Q L - - - -   - - - - - Y - - - - - - - - - - - - Aj- - - - -   - - - - AlG Af- - - - - - - - - - U I V - - - -   - - - - T N H Aq- - - - - - - - ApAbG Am- - - -   - - - - - - AuAtF B - - - - AyAkB S - - - - - -   - - - - AyH X P M AcW Z AiAoI AnU AhApT - - - -   - - - - AoQ AwZ W AaAnY J ApAsAtAcAaAwL - - - -   - - - - - - - - - - - AaAb- - - - - - - - - - -   - - - - - - - - - - - - - - - - - - - - - - - -   - - - - - - - - - - - - - - - - - - - - - - - -   - - - - - - - - - - - - - - - - - - - - - - - -   - - - - - - - - - - - - - - - - - - - - - - - -   - - - - - - - - - - - - - - - - - - - - - - - -   - - - - - - - - - - - - - - - - - - - - - - - -   - - - - - - - - - - - - - - - - - - - - - - - -   - - - - - - - - - - - - - - - - - - - - - - - -   
- - - - - - - - - - - - - - - - - - - - - - - -   - - - - - - - - - - - - - - - - - - - - - - - -   - - - - J Au- - - - - - - - - - - - AjC - - - -   - - - - AdK - - - - - - - - - - - - I Y - - - -   - - - - Z Ak- - - - - - - - - - - - G U - - - -   - - - - C O - - - - - - - - - - - - AdP - - - -   - - - - K B - - - - - - - - - - - - ApI - - - -   - - - - Q Ak- - - - - - - - - - - - AwB - - - -   - - - - - An- - - - - - - - - - - - N - - - - -   - - - - I At- - - - - - - - - - - - R P - - - -   - - - - G D - - - - - - - - - - - - AtC - - - -   - - - - - O - - - - - - - - - - - - At- - - - -   - - - - ApAkAhAm- - - - - - - - O AeW K - - - -   - - - - AwT J M At- - - - - - AoB F AdR - - - -   - - - - - - I AlD P AfU P AxAqZ AkAm- - - - - -   - - - - R AlF AfO I AeJ B AhAoAcAnAxW W - - - -   - - - - - S N AqAkB F AnQ W R AgAtK Ap- - - - -   - - - - - - - - - - - - - - - - - - - - - - - -   - - - - - - - - - - - - - - - - - - - - - - - -   - - - - - - - - - - - - - - - - - - - - - - - -   - - - - - - - - - - - - - - - - - - - - - - - -   - - - - - - - - - - - - - - - - - - - - - - - -   - - - - - - - - - - - - - - - - - - - - - - - -   - - - - - - - - - - - - - - - - - - - - - - - -   - - - - - - - - - - - - - - - - - - - - - - - -   - - - - - - - - - - - - - - - - - - - - - - - -   
- - - - - - - - - - - - - - - - - - - - - - - -   - - - - - - - - - - - - - - - - - - - - - - - -   - - - - Y AhS - - - - - - - - - - AsAfAa- - - -   - - - - AaY Ah- - - - - - - - - - AlAqAe- - - -   - - - - AeApAa- - - - - - - - - - S AoAm- - - -   - - - - AmP K - - - - - - - - - - AbR M - - - -   - - - - AhR An- - - - - - - - - - AwJ Al- - - -   - - - - AhArAs- - - - - - - - - - O Q Af- - - -   - - - - - - V - - - - - - - - - - Ah- - - - - -   - - - - I AtU - - - - - - - - - - C X Ao- - - -   - - - - F P J - - - - - - - - - - Y B R - - - -   - - - - - Z An- - - - - - - - - - U Ac- - - - -   - - - - AoAaAxW T - - - - - - AnAfP AaQ - - - -   - - - - R AeAwApL Q V AjAgB AiAlAoI H Y - - - -   - - - - - - AfAwI V X Z AtM ArL Z B - - - - - -   - - - - AiM H AmAbX AuY AjP C Q AcM AcB - - - -   - - - - - - - - - - S AaAqC - - - - - - - - - -   - - - - - - - - - - - - - - - - - - - - - - - -   - - - - - - - - - - - - - - - - - - - - - - - -   - - - - - - - - - - - - - - - - - - - - - - - -   - - - - - - - - - - - - - - - - - - - - - - - -   - - - - - - - - - - - - - - - - - - - - - - - -   - - - - - - - - - - - - - - - - - - - - - - - -   - - - - - - - - - - - - - - - - - - - - - - - -   - - - - - - - - - - - - - - - - - - - - - - - -   - - - - - - - - - - - - - - - - - - - - - - - -   
- - - - - - - - - - - - - - - - - - - - - - - -   - - - - - - - - - - - - - - - - - - - - - - - -   - - - - - H AgAdAt- - - - - - H AxP Ae- - - - -   - - - - - AqAtZ At- - - - - - N AwC X - - - - -   - - - - - V AjC W - - - - - - AcAfG V - - - - -   - - - - - AeAqK Ad- - - - - - M H K D - - - - -   - - - - - X AfQ D - - - - - - T AuR L - - - - -   - - - - - V AaAjW - - - - - - L X AjAy- - - - -   - - - - - - AiI Ap- - - - - - I AwW - - - - - -   - - - - - L Q G Aw- - - - - - AbAnS Ar- - - - -   - - - - - AyAxAdAm- - - - - - AgAyC Ad- - - - -   - - - - - - H ApG - - - - - - AxW O - - - - - -   - - - - - ArAqAwH AsAjZ F I H AiAnU Ah- - - - -   - - - - - AdV N AsAlI AaM AbD ArAlF Y - - - - -   - - - - - - AeR AgS G AeW AgN C L T - - - - - -   - - - - - AhX AtS AbAdAmAoAxO K Q AqP - - - - -   - - - - - - - - - - - - - - - - - - - - - - - -   - - - - - - - - - - - - - - - - - - - - - - - -   - - - - - - - - - - - - - - - - - - - - - - - -   - - - - - - - - - - - - - - - - - - - - - - - -   - - - - - - - - - - - - - - - - - - - - - - - -   - - - - - - - - - - - - - - - - - - - - - - - -   - - - - - - - - - - - - - - - - - - - - - - - -   - - - - - - - - - - - - - - - - - - - - - - - -   - - - - - - - - - - - - - - - - - - - - - - - -   - - - - - - - - - - - - - - - - - - - - - - - -   
- - - - - - - - - - - - - - - - - - - - - - - -   - - - - - - - - - - - - - - - - - - - - - - - -   - - - - - T C AxAhAiI AqAuAcQ H H U P - - - - -   - - - - - L O AiJ J F AtAfAgV AuN AcR - - - - -   - - - - - I U ArI AbN P AiF X X AcP Ar- - - - -   - - - - - AbF C F AgAoZ J G AuAwM B Aq- - - - -   - - - - - AgT K N AyR AaAbArS AnT Q At- - - - -   - - - - - AxAqAuAoI L AeAgAsF AyL V P - - - - -   - - - - - - AiK R AsAiAmAyH AkW I X - - - - - -   - - - - - ArF AkL AgV M I D M AnAbAuAa- - - - -   - - - - - C M O AiApAmAlAsN AdAlAgS Ae- - - - -   - - - - - - W B V AeAlAfAgO T L AxF - - - - - -   - - - - - AuAoAkAmAxT AqApJ AjQ AiAkM - - - - -   - - - - - K ApAnAlAhL AoAeAdZ AuArM Al- - - - -   - - - - - - B AtT W AyR AxZ Y V C Ad- - - - - -   - - - - - - - - - - - - - - - - - - - - - - - -   - - - - - - - - - - - - - - - - - - - - - - - -   - - - - - - - - - - - - - - - - - - - - - - - -   - - - - - - - - - - - - - - - - - - - - - - - -   - - - - - - - - - - - - - - - - - - - - - - - -   - - - - - - - - - - - - - - - - - - - - - - - -   - - - - - - - - - - - - - - - - - - - - - - - -   - - - - - - - - - - - - - - - - - - - - - - - -   - - - - - - - - - - - - - - - - - - - - - - - -   - - - - - - - - - - - - - - - - - - - - - - - -   - - - - - - - - - - - - - - - - - - - - - - - -   
- - - - - - - - - - - - - - - - - - - - - - - -   - - - - - - - - - - - - - - - - - - - - - - - -   - - - - - - - - - - - - - - - - - - - - - - - -   - - - - - - - - - I AhZ S AuH - - - - - - - - -   - - - - - - - - - F C Y AbK Aq- - - - - - - - -   - - - - - - - P U N Y AaAwAkV X Aw- - - - - - -   - - - - - - - C AcAoU AeO O AeG An- - - - - - -   - - - - - - - G P R P AmAhB X L Ay- - - - - - -   - - - - - - - K B L I AhC AkV AuW - - - - - - -   - - - - - - - R Q AiB AhY AnD AfAn- - - - - - -   - - - - - - - AjV V M J U AtL AiAl- - - - - - -   - - - - - - - W X AmP I P D AyJ L - - - - - - -   - - - - - - - - - AlC F I O Ay- - - - - - - - -   - - - - - - - - - T G N B AkAr- - - - - - - - -   - - - - - - - - - - - - - - - - - - - - - - - -   - - - - - - - - - - - - - - - - - - - - - - - -   - - - - - - - - - - - - - - - - - - - - - - - -   - - - - - - - - - - - - - - - - - - - - - - - -   - - - - - - - - - - - - - - - - - - - - - - - -   - - - - - - - - - - - - - - - - - - - - - - - -   - - - - - - - - - - - - - - - - - - - - - - - -   - - - - - - - - - - - - - - - - - - - - - - - -   - - - - - - - - - - - - - - - - - - - - - - - -   - - - - - - - - - - - - - - - - - - - - - - - -   - - - - - - - - - - - - - - - - - - - - - - - -   - - - - - - - - - - - - - - - - - - - - - - - -   
- - - - - - - - - - - - - - - - - - - - - - - -   - - - - - - - - - - - - - - - - - - - - - - - -   - - - - - - - - - - - - - - - - - - - - - - - -   - - - - - - - - - - - - - - - - - - - - - - - -   - - - - - - - - - - - - - - - - - - - - - - - -   - - - - - - - - - C AkAmAaAtQ - - - - - - - - -   - - - - - - - - - K M AlH AtY - - - - - - - - -   - - - - - - - - - Q AdT N W X - - - - - - - - -   - - - - - - - - - AjT L AcAdB - - - - - - - - -   - - - - - - - - - I AjAyM D Ac- - - - - - - - -   - - - - - - - - - G Z AoT W Aa- - - - - - - - -   - - - - - - - - - AdY Y L ApH - - - - - - - - -   - - - - - - - - - - - - - - - - - - - - - - - -   - - - - - - - - - - - - - - - - - - - - - - - -   - - - - - - - - - - - - - - - - - - - - - - - -   - - - - - - - - - - - - - - - - - - - - - - - -   - - - - - - - - - - - - - - - - - - - - - - - -   - - - - - - - - - - - - - - - - - - - - - - - -   - - - - - - - - - - - - - - - - - - - - - - - -   - - - - - - - - - - - - - - - - - - - - - - - -   - - - - - - - - - - - - - - - - - - - - - - - -   - - - - - - - - - - - - - - - - - - - - - - - -   - - - - - - - - - - - - - - - - - - - - - - - -   - - - - - - - - - - - - - - - - - - - - - - - -   - - - - - - - - - - - - - - - - - - - - - - - -   - - - - - - - - - - - - - - - - - - - - - - - -   
