model
size = 14 25 32, scale = 0.05, origin = -y
material 
  colors = A:#111 B:#100 C:#EEE D:#222
voxels
258-2B348-2B12-2B334-2B12-2A12-2B320-2(2B2(12-2A)12-2B306-)2B3(12-2A)12-2B292-2B4(12-2A)12-2B23-B-B2-B-B135-2B11-A2BA7-2(B2-B2AB2-B4-)B2-4B2-B50-5(2B12-)2B37-A-A2-A-A93-2B11-B2AB9-B4AB6-B-6A-B3(4-A-6A-A)4-B-B4AB-B6-BA2BAB9-B2AB2(10-2ADA)10-4A11-3(2A12-)2B23-A-A2-A-A65-2B11-B2AB9-B4AB8-6A6-B8AB4-3(10AB3-)2(10A4-)B-6A-B6-B4AB8-B4AB9-2(4A10-)C2AC10-4A10-C2AC10-B2AB22-A-A2-A-A65-2A10-6A8-6A6-B9AB3-10AB3(2-B11A)3-10AB3-10A4-B8AB5-8A7-B4AB9-2(4A10-)3(C2AC10-)B2AB24-A11-A-A2-A-A37-2A12-2A10-6A6-B-6A-AB3-11A2-B11A3(B-12A)2-B10AB3-10A4-B8AB5-8A7-B4AB9-5(4A10-)B2AB37-2A3-2A7-A4-A8-A-2A-A10-2A12-2A3-A4-B-6A-AB3-A-6A-2A2-B11AB-2(13AB)12AB-12A3-B9AB3-B9A5-8AB5-8A7-B4AB9-4(4A10-)B2AB11-2A24-A4-A22-B4-B8-B-2A-A8-A-2A-A6-B3-2A3-AB3-A2-4A2-2A2-BA-6A-2AB-9A-17AB12AB-12A2-11AB3-B9A5-8AB5-8A7-B4AB9-4(4A10-)B2AB11-2A38-A4-A36-B-2A-B8-A-2A2(-A)B3-B2(-A-2A)3-A2-4A2-2AB-BA2-4A2-2(6A-)16A2B12A2-11AB3-B9A5-8AB5-8A6-8A8-3(4A10-)B2AB10-B2AB51-B4-B50-B-2A3-AB3-B2(-A)2(B-)2A3-2(A-)2A-A-2A2-BA2-4A2-2AB-2A2-4A2-6A2-4A2-3AB2A-6A-2AB-2A-6A-2A3-B-6A-A6-6A-B6-2(6A8-)6A9-2(4A10-)B2AB137-2A4-2(B3-)2A3-2A2-BA2(3-2A)B-2A2(2-4A2-6A)2-4A2-2A2B2A-6A-2A2-AB-6A-2A5-6A-B6-2(6A8-)6A9-2(4A10-)B2AB151-2A4-2(B3-)2A3-2AB-2(2A3-)2(6A2-4A2-)3AB2A2-4A2-2AB-2A-6A-2A3-B-6A-B6-6A8-6A9-3(4A10-)B2AB165-2A4-2(B3-)2A3-2AB-2(2A3-)6A2-4A2-3AB2A2-4A2-2AB-2A2-4A2(2-2A)2-4A2-A4-B-6A-B6-6A10-3(2A12-)2B180-2A4-2(B3-)2A3-2AB-2(2A3-)6A2-4A2-2A2B2A2-4A2(2-2A)2-4A2-A4-B2-4A2-B7-4A10-4A11-2(2A12-)2B194-2A4-2(B3-)2A3-2AB-2(2A3-)3AB2(2A3-)2(2A2-)4A2-2A3-B2-4A2-B7-4A11-3A11-2(2A12-)2B214-2(B3-)2A3-2AB-2(2A3-)2A2B2(2A3-)2(2A2-)4A2-A4-B2-4A2-B7-4A11-2A2(12-2B)228-2(B3-)2A3-2AB-2(2A3-)AB-2BA3-2A3-A4-B2-4A2-B7-4A11-2A12-2B256-2(B3-)2A3-2AB2-A3-2A3-AB-3B3-2A3-B7-4A10-4A11-2B270-B3-B8-2AB2-A3-2A2(3-B)4-2A11-4A10-4A11-2B270-B3-B8-A-B2-A3-2A2(3-B)4-2A11-4A10-4A11-2B270-B3-B8-B-B2-A2(3-2A7-B4-2A11-4A11-2B284-B3-B8-B4-B)3-2B12-2A11-A2BA297-B3-B13-B3-2B12-2A12-2B302-B31-2A12-2B334-2B244-
