model
size = 12 33 20, scale = 0.05, origin = -y
material 
  colors = A:#222
voxels
221-2A9-2(4A8-)4A9-2A322-2A9-4A7-6A5-2(8A4-)8A5-6A7-4A9-2A286-2A8-6A5-8A4-8A3-2(10A2-)10A3-8A4-8A5-6A8-2A214-2A9-2(4A8-)4A9-2A9-4A6-8A4-8A3-4(10A2-)10A3-8A4-8A6-4A200-4A7-5(6A6-)6A5-8A3-10A2-10A-36A-10A2-10A3-8A5-6A7-4A8-4A9-2A153-4A7-6A5-5(8A4-)8A3-10A2-10A-60A-10A2-10A3-2(8A4-)8A5-6A7-4A9-2A118-2A8-6A5-8A4-8A3-2(10A2-)10A3-8A4-8A3-10A2-10A-60A-4(10A2-)10A3-8A4-8A5-6A8-2A58-2A9-3(4A8-)4A7-6A5-8A3-4(10A2-)10A3-8A4-8A3-10A-60A-5(10A2-)10A3-8A4-8A6-4A44-4A7-5(6A6-)6A5-8A3-4(10A2-)10A3-8A5-6A4-10A2-10A-36A-2(10A2-)10A-36A-10A2-10A3-8A5-6A8-2A21-4A7-6A5-4(8A4-)8A5-6A5-8A3-4(10A2-)10A3-8A5-6A5-8A3-10A-24A-2(10A2-)10A-60A-10A2-10A3-8A6-4A9-2A8-6A5-8A4-8A3-2(10A2-)10A3-3(8A4-)8A3-2(10A2-)10A3-8A4-8A5-6A5-8A4-8A3-3(10A2-)10A-72A-10A2-10A3-8A6-4A8-4A7-6A5-8A3-4(10A2-)10A3-3(8A4-)8A3-10A2-10A3-8A5-6A8-2A9-4A6-8A4-8A3-2(10A2-)10A-72A-10A2-10A3-8A6-4A8-4A7-6A5-8A3-5(10A2-)10A3-4(8A4-)8A5-6A7-4A8-4A9-2A9-4A6-8A4-8A3-10A2-10A-60A-10A2-10A3-8A5-6A8-2A9-4A7-6A5-8A3-6(10A2-)10A3-2(8A4-)8A5-6A6-6A7-4A8-4A9-2A9-4A6-8A4-8A3-7(10A2-)10A3-8A4-8A6-4A21-2A8-6A5-8A4-8A3-5(10A2-)10A3-8A4-8A5-2(6A6-)6A7-4A8-4A9-2A8-6A5-5(8A4-)8A3-2(10A2-)10A3-8A4-8A5-6A8-2A33-4A7-6A5-4(8A4-)8A5-6(6A6-)6A7-4A8-4A9-2A8-6A5-4(8A4-)8A5-6A5-2(8A4-)8A5-6A7-4A9-2A57-4A7-9(6A6-)6A7-2(4A8-)4A21-2A8-6A6-6A5-2(8A4-)8A5-6A6-6A7-2(4A8-)4A9-2A94-2A9-3(4A8-)4A7-6A6-6A7-4A9-3(2A10-)2A34-2A9-4A7-6A6-6A5-8A5-6A6-6A7-4A9-2A166-2A10-2A9-2(4A8-)4A9-2A82-2A9-4A7-2(6A6-)6A7-4A9-2A334-2A10-2A9-4A9-2A10-2A113-
