model
size = 5 32 9, scale = 0.05, origin = -y
material 
  colors = A:#FC0 B:#FFF C:#444 D:#222 E:#AAA F:#BBB G:#111 H:#FC3 I:#EEE J:#DDD
voxels
32-A129-A28-2AH2-3A3-15(E4-)5(F4-)E4-F2(4-B)4-A2(4-G)3(4-D)2-2AG2A-3A3-D2(4-C)3(4-D)8(4-C)2(4-D)3(4-C)4-D4-F4-I4-B8-2AH3-D3(4-G)4-D2-2AG2A-3A3-3(D4-)3(C4-)D2(4-C)4(4-D)5(4-C)4-D4-F2(4-B)13-3A26-2AJ2A-2AH3-20(B4-)B17-2(A-)A25-2(A-)A2-A122-2(A-)5(2A3-)2A2(-A)2-A124-A2-2(2A-2A5-)2A-2A2-A134-A3(4-H)4-A132-
