model
size = 32, scale = 0.05, origin = -y
material 
  colors = A:#222 B:#111 C:#FFA60C D:#EEE E:#444 F:#001 G:#200
voxels
43-C36-5A22-C9A22-2C8B885-C30-C7-4A-A20-12A18-C-12A18-5C9B879-C-C13-3A21-A2G8A14-C3-14A13-2C-14A2B14-2CB3C2F8B759-3(4A28-)3A36-6A17-3G12A17-14AB10-16A3B-A11-2BCB4C8B759-2(8A24-)6A26-4A38-7A13-G-3GA2G2A-8A13-A-6A3G4A4B6-16A6B10-4B5CBC4AB27-3CA2(28-4C)2(28-2(DC))2(2(28-4D)3(28-D3C))2(28-4D)2(28-2(DC))26-2(8C24-)A6CA24-3A2C3A23-10A23-8A24-6A26-3A40-6A9-A-A2-G17A9-A-A2-15A4B4-18A6B8-5B5C7AF24-2C6A24-2C4ACA3(24-2C4A2C)24-2D4ADC24-2D2(4A2D24-CD)4ACD4(24-CD4A2D)24-CD4ACD24-CD2(4A2D24-2D)4ADC2(24-2C4A2C)23-C8AC22-10A3-2A17-10A2-2(2A18-10A-)2A20-9A23-7A25-4A37-G2A2-G3A8-A3-20A8-22A3B4-19A6B7-6B3C9AF22-C8AF2(22-C9A)2(22-C8AC)22-D2(2(8AC22-C)3(8AD22-C))8AC22-D2(8AC22-C)8AC20-14A2-3A13-14A-2A15-14A18-14A17-12AB20-10AB21-10A22-6A39-3A-3A10-G7A2-12A8-A-8A2-10A3B4-13A2-6A4B7-5BFC6A2-6A18-2C4A2-4A2F18-2C4A2-5AF18-AC4A2-6A18-6A2-6A18-AC4A2-4ACA6(18-2C4A2-4A2C)18-2C4A2-4AC19-6(2C4A2-4A2C18-)AC4A2-4ACA15-9A2-11A10-9A2-8A13-9A2-6A15-9A2-4ABA15-14AB19-12A20-11A21-6A39-A2-AG4A6-E2-G5A6-11A6-A2-6A6-9A3B2-12A6-6A3B5-6B6A6-6A14-FC4A6-6A14-6A6-5AF4(14-6A6-6A)14-AC4A6-4ACA4(14-2C4A6-4A2C)14-2C4A6-3AC16-4(2C4A6-4A2C14-)AC4A6-4ACA2(14-6A6-6A)13-7A6-10A9-E6A6-6A13-7A6-3AB15-7A6-2AB15-15A2F16-13AF18-12AF19-7AF40-2A2-4A5-A2-G4A10-4AG4A5-A2-5A10-8A2B2-10A10-5A3B4-2BF2B5A10-5A12-F4A10-5A12-B4A2(10-4AF12-5A)8(10-5A12-5A)10-2A2C13-5(5A10-5A12-)5A10-5A2-2A8-5A10-5A2-A8-6A10-8A8-E5A10-3AB12-6A10-2AB13-6A10-E14-17AF14-15ABF15-15A17-3AE4AFA40-A-A2-3A8-G3A12-4AG3A8-4A12-7A2B2-9A12-5A2B4-4B5A12-4AB10-F4A12-5A10-B4A12-5A2(10-5A12-4AF)10-5A12-5A10-E4A12-4AE10-E4A12-5A10-5A12-4AE3(10-5A12-5A)10-5A12-3AB11-2(5A12-5A10-)5A12-4AE3(10-5A12-5A)-2A7-5A12-5A-A8-5A12-3A2B2A8-5A12-2AB12-5A12-E14-F4A26-F16AB14-F15AB15-10AE3A18-3AE3AF2A40-A2-A-3A8-GA-A12-A-2AG3A8-4A12-7A2B2-9A12-5A2B4-4B5A12-5A2(10-F4A12-4AB)3(10-F4A12-5A)3(10-5A12-5A)2(10-5A12-4AE)10-E4A12-5A10-E4A12-3AB11-E4A2(12-5A10-5A)12-4AE10-4AE2(12-5A10-5A)12-5A-2A7-5A12-7A8-5A12-5A2BA7-F4A12-2AE12-F4A12-AE13-5A26-17AB14-17A15-14A18-3AE2AF4A40-2(A-)3A8-G-A14-A-AG3A8-3A14-7AB2-8A14-4A3B3-E2BF4A14-4A10-F3A2(14-4A10-4A)2(14-3AB10-4A)13-5A3(10-4A13-4AB)10-F3A2(13-5A10-4A)13-4AE10-4A13-3AB11-4A13-4AE2(10-3AE13-5A)10-E3A13-4AB2(10-E3A13-5A)-2A6-5A13-8A6-F4A13-3AE3A7-F4A13-2AE11-5A13-AB12-5A13-B12-19A13-17A15-15A17-6AFB2AE43-A-3A7-EA-A14-A-5A7-4A14-7AB2-8A14-5A2B3-2BF5A14-4AB8-E4A14-4AB8-F3(4A14-4AB8-E)4A13-5AB8-E4A13-5AB8-5A2(13-5AB8-E4A)13-5AB8-F4A13-6A8-F4A13-5AB8-F4A13-4AB9-F4A13-5AE8-F4A13-5AB8-F3AB13-5AB8-F4A2(13-5AB8-5A)2(13-8A6-5A)13-5AE8-5A13-2AB11-5A13-AB12-E4A13-A12-B18A13-15AEA15-11A-2AE17-4AEF2A2BA42-2A-4A6-E3A14-8A6-4A14-7AB10A14-5A2B-A3BF2(5A14-4AB8-)F4A14-4AB8-5A14-4AB8-E4A14-4AB5(8-5A13-5AE)2(8-E4A13-5AB)8-5A13-4AB9-5A13-5AE8-4AB13-5AB8-5A2(13-5AB8-B4A)13-5AB8-2(5A13-8A6-)5A13-3A2BE8-E4A13-2AB11-E4A13-2A12-5A13-A12-17AE14-15A2B15-15A17-5AE5A42-A2-4A6-E-A16-6A7-3A16-6A2B8A16-4A2B2-2BFB3(4A16-3AB8-)E3A2(16-3AB8-4A)4(14-5AB8-4A)3(14-5AB8-B3A)14-4AB9-5(4A14-5AB8-)4A14-8A6-4A14-7A7-4A14-5AB8-4A14-4A10-4A14-2A12-4A14-B12-17A2B13-E15AB15-16A16-5AE5A42-A2-G3A6-E-A16-7A6-3A16-6AB9A16-4A2B-5B5(4A16-3AB8-)2(4A14-5AB8-)2(B3A14-5AB8-)F3A2(14-6A8-4A)14-5AB8-4A14-4AB9-4A14-5AB8-4A14-5AE2(8-B3A14-5AB)8-4A14-5AB8-2(4A14-8A6-)4A14-6A8-4A14-2A2E10-4A14-AB12-4A14-B12-19A13-E16A15-16A16-11A41-A3-G3A24-7A8-G16-16A16-5A8B2(3A16-4AB8-)E2A2(16-4AB8-3A)17-3A3(B8-3A15-5A)2(B8-B2A15-5A)2(E8-F2A15-5A)B8-F2A15-4AB9-2(F2A15-5AB8-)2(3A15-5AE8-)B2A15-5AB8-B2A2(15-8A6-3A)15-6A8-3A15-2A2B10-3A15-AB12-B2A15-A12-E18A13-17AB14-11A4B17-B2AF2AE4A41-A2-AG2A25-2A-3A9-G16-7AB2-6A16-5A2B3-3B4(3A16-4AB8-)3A17-3A2(B8-3A15-5A)B2(8-F2A15-5AE)8-F2(2A15-6A8-E)2A15-5AB8-E2A15-4AB9-2(E2A15-5AB8-)F2A15-5AB8-E2(2A15-5AB8-F)2A2(15-7AB6-3A)15-4ABE8-B2A15-3AB10-3A15-A2B11-3A15-B12-18AB13-15A2B15-15A17-B2AF2AE4A41-A2-G3A25-2A-3A9-G16-7AB2-6A16-4A3B3-BF2B2(2A16-4A10-)2(BA16-4A10-)2A17-3A3(10-FA15-5A)3(10-2A15-5A)10-2A15-4AE10-2A15-3AB11-2(2A15-5A10-)2A15-4AE3(10-EA15-5A)-2A6-E2A15-6ABE6-F2A15-4A2B8-3A15-3AE10-B2A15-2AE11-B2A28-19A13-17A15-15A17-3AF6AB40-2A2-G3A9-2E13-3A-3A10-2A13-8AB2-8A13-5A3B3-BF2B4A13-5A3(10-4A13-4AB)10-F3A13-AG2A4(B10-4A13-4A)B2(10-4A13-5A)10-4A13-4AE10-4A13-3AB11-3(4A13-5A10-)4A13-4AE2(10-4A13-5A)-2A7-F3A13-5A-A8-B3A13-5AE9-4A13-4AB10-4A13-AEA12-4A13-E13-17AE14-16A16-14A18-2AF4AEAB40-A-7A8-3A12-E6A10-3A12-7A2B2-9A12-5A2B4-BF2B2(5A12-5A10-)2(F4A12-5A10-)4(5A12-5A10-)5A12-4AE10-5A12-5A2(10-5A12-4AE)10-5A12-4A11-6(5A12-5A10-)5A12-5A-A8-F4A12-6A9-5A12-3ABE10-5A12-2AB12-5A12-A13-17AE14-16AE15-10A-3A18-7AEBA39-A-7A10-3A10-8A11-3A10-9AB2-10A10-5A4B3-BF3B2(5A10-5A12-)F4A3(10-5A12-5A)10-4AE12-5A6(10-5A12-C4A)10-3AC13-4(C4A10-5A12-)2(5A10-5A12-)5A10-5A11-6A10-7A9-F5A10-4AE2A9-F5A10-2ABE12-6A9-2AB13-16A-B14-15AE16-11A3F18-6AE3A37-2A-4AG2A2(7-A4-4A6-10A)2B2-12A6-6A4B4-BF4B6A6-6A14-F5A3(6-6A14-6A)6-6A14-AC4A6-4ACE14-2C4A6-4ACA5(14-2C4A6-4A2C)14-2C4A6-4AC15-4(2C4A6-4A2C14-)2C4A6-4ACA14-AC4A6-6A14-6A6-6A13-7A6-7A12-7A6-8A11-7A6-4ABA13-7A6-2ABE14-15AB17-14AB17-12A20-4AE4A35-2A-3A2G3A7-A5-4A4-11A7-A5-4A4-10A2B4-12A4-5A5B6-5BFB3(5A4-5A18-)AC3A4-3ACA15(18-2C3A4-3A2C)18-2C3A4-3ACA15-8A4-8A12-8A4-9A11-8A4-8A12-8A4-4AEB14-2F13AE18-13A19-8A2EA21-8A30-A2-2A-3AGAG2A14-5A2-12A13-5A2-12AB4-13A2-4A6B-A5-5BF3B2(4A2-4A22-)4A4(2-3AC22-C3A)2-3AD22-C2(3(3A2-3AC22-D)2(3A2-3AC22-C))3A2-3AD2(22-C3A2-3AC)20-AC4A2-6A18-6A2-6A3-A14-6A2-9A15-6A2-5ABA16-2F11AB19-11AB20-10A22-7A30-4A-3A3G14-2A2-19A9-2A2-19A4-18A6B2(-A)4-4BF5B8A24-6ACA4(24-2C4A2C)24-CD2(4A2D24-2D)4ADC24-DC4(4ADC24-2D)4ADC24-DC2(4ADC24-2D)4A2D24-CD4A2D2(24-2C4A2C)23-C8AC3(22-10A)21-F12A20-9AB22-8A24-5A29-5G2A3G18-7A2G5AGA-3A12-20A6-16A6B2(-A)6-BF9B4AB27-3(4C28-)2(2(CD)28-)2(2(4D28-)3(3CD28-))2(4D28-)2(CD)28-2(CD)26-2(8C24-)A6CA24-8A23-11A22-7AB24-6AB25-4A29-A4-AG2A20-4AG3A3G2A-3A15-11A3G3A10-16A3B2-A10-F15B759-2(8A24-)7A25-4A29-A4-G26-A4-7A20-A4-7A14-16A-A14-16B759-3(4A28-)3A28-G4-A26-A4-G4A22-A2-G-5A18-14A18-14B925-A31-A22-10A22-10B875-
