model
size = 32, scale = 0.05, origin = -y
material 
  colors = A:#111 B:#EEE C:#001 D:#CF3 E:#DDD
voxels
398-4B27-A4BA25-2A4B2A24-2A4C2A24-8A24-2A4B2A25-A4BA27-4B700-4B26-8C23-B2A2C4AB21-2B8A2B20-2B8A2B19-3(3B8A3B18-)3B8A3B19-2B8A2B20-2B8A2B21-B8AB23-8A26-4B541-2B27-8B22-4B4A4B19-3B8A3B18-2B10A2B17-2(2B12A2B16-)B14AB15-2B14A2B14-2B14A2B15-B14AB2(16-2B12A2B)17-2B10A2B18-3B8A3B19-4B4A4B22-8B27-2B444-6B24-4B2A4B20-3B8A3B17-2B12A2B16-B14AB15-2B14A2B14-B16AB13-2(2B16A2B12-)2(B18AB12-)2B16A2B12-2B16A2B13-B16AB14-2B14A2B15-B14AB16-2B12A2B17-3B8A3B20-4B2A4B24-6B377-8A22-12A19-14A17-16A15-18A13-20A12-20A11-7(22A10-)22A11-20A12-20A13-18A15-16A17-14A19-12A22-8A312-8A22-12A19-14A16-18A14-18A13-20A11-22A10-22A9-7(24A8-)24A9-22A10-22A11-20A13-18A14-18A16-14A19-12A22-8A249-6A23-12A19-14A16-18A13-20A12-20A11-22A9-2(24A8-)24A7-5(26A6-)26A7-2(24A8-)24A9-22A11-20A12-20A13-18A16-14A19-12A23-6A188-2A26-10A20-14A16-18A13-20A11-22A10-22A9-24A8-24A7-3(26A6-)26A5-28A4-28A5-3(26A6-)26A7-24A8-24A9-22A10-22A11-20A13-18A16-14A20-10A26-2A155-8A21-14A17-16A15-18A13-20A11-22A9-24A7-2(26A6-)26A5-7(28A4-)28A5-2(26A6-)26A7-24A9-22A11-20A13-18A15-16A17-14A21-8A122-4A24-12A18-16A15-18A13-20A11-22A9-24A7-26A6-26A5-3(28A4-)28A3-3(30A2-)30A3-3(28A4-)28A5-26A6-26A7-24A9-22A11-20A13-18A15-16A18-12A24-4A90-8A21-14A17-16A14-20A11-22A9-24A8-24A7-26A5-2(28A4-)28A3-7(30A2-)30A3-2(28A4-)28A5-26A7-24A8-24A9-22A11-20A14-16A17-14A21-8A87-10A20-14A16-18A13-20A11-22A9-24A7-26A6-26A5-28A4-28A3-9(30A2-)30A3-28A4-28A5-26A6-26A7-24A9-22A11-20A13-18A16-14A20-10A57-4A24-12A18-16A15-18A12-22A9-24A8-24A7-26A5-28A4-28A3-3(30A2-)30A-128A-3(30A2-)30A3-28A4-28A5-26A7-24A8-24A9-22A12-18A15-16A18-12A24-4A27-6A23-12A18-16A14-20A11-22A9-24A7-26A6-26A5-28A4-28A3-2(30A2-)30A-192A-2(30A2-)30A3-28A4-28A5-26A6-26A7-24A9-22A11-20A14-16A18-12A23-6A25-8A21-14A17-16A14-20A11-22A9-24A7-26A6-D25A5-D27A3-30A2(2-D29A)-256A-2(30A2-)30A3-28A5-26A6-26A7-24A9-22A11-20A14-16A17-14A21-8A24-8A21-14A16-18A13-20A11-22A9-D23A7-D25A5-28A4-28A3-D29A2(2-30A)-D31AD223A-2(30A2-)30A3-28A4-28A5-26A7-24A9-22A11-20A13-18A16-14A21-8A24-8A21-14A16-18A13-20A11-22A9-24A7-D25A5-28A4-28A3-D29A2(2-30A)-D255A-2(30A2-)30A3-28A4-28A5-26A7-24A9-22A11-20A13-18A16-14A21-8A24-8A21-14A17-16A14-20A11-22A9-D23A7-D25A6-D25A5-D27A3-2(D29A2-)D29A-D31AD223A-2(30A2-)30A3-28A5-26A6-26A7-24A9-22A11-20A14-16A17-14A21-8A25-6A23-12A18-16A14-20A11-22A9-24A7-D25A6-26A5-28A4-28A3-2(30A2-)D29A-192A-2(30A2-)30A3-28A4-28A5-26A6-26A7-24A9-22A11-20A14-16A18-12A23-6A27-4A24-12A18-16A15-18A12-22A9-24A8-24A7-26A5-28A4-28A3-3(30A2-)30A-128A-3(30A2-)30A3-28A4-28A5-26A7-24A8-24A9-22A12-18A15-16A18-12A24-4A57-10A20-14A16-18A13-20A11-22A9-24A7-26A6-26A5-28A4-28A3-9(30A2-)30A3-28A4-28A5-26A6-26A7-24A9-22A11-20A13-18A16-14A20-10A87-8A21-14A17-16A14-20A11-22A9-24A8-24A7-26A5-2(28A4-)28A3-7(30A2-)30A3-2(28A4-)28A5-26A7-24A8-24A9-22A11-20A14-16A17-14A21-8A90-4A24-12A18-16A15-18A13-20A11-22A9-24A7-26A6-26A5-3(28A4-)28A3-3(30A2-)30A3-3(28A4-)28A5-26A6-26A7-24A9-22A11-20A13-18A15-16A18-12A24-4A122-8A21-14A17-16A15-18A13-20A11-22A9-24A7-2(26A6-)26A5-7(28A4-)28A5-2(26A6-)26A7-24A9-22A11-20A13-18A15-16A17-14A21-8A155-2A26-10A20-14A16-18A13-20A11-22A10-22A9-24A8-24A7-3(26A6-)26A5-28A4-28A5-3(26A6-)26A7-24A8-24A9-22A10-22A11-20A13-18A16-14A20-10A26-2A188-6A23-12A19-14A16-18A13-20A12-20A11-22A9-2(24A8-)24A7-5(26A6-)26A7-2(24A8-)24A9-22A11-20A12-20A13-18A16-14A19-12A23-6A249-8A22-12A19-14A16-18A14-18A13-20A11-22A10-22A9-7(24A8-)24A9-22A10-22A11-20A13-18A14-18A16-14A19-12A22-8A312-8A22-12A19-14A17-16A15-18A13-20A12-20A11-7(22A10-)22A11-20A12-20A13-18A15-16A17-14A19-12A22-8A377-6B24-4B2A4B20-3B8A3B17-2B12A2B16-B14AB15-2B14A2B14-B16AB13-2(2B16A2B12-)2(B18AB12-)2B16A2B12-2B16A2B13-B16AB14-2B14A2B15-B14AB16-2B12A2B17-3B8A3B20-4B2A4B24-6B444-2B27-8B22-4B4A4B19-3B8A3B18-2B10A2B17-2(2B12A2B16-)B14AB15-2B14A2B14-2B14A2B15-B14AB2(16-2B12A2B)17-2B10A2B18-3B8A3B19-4B4A4B22-8B27-2B541-4B26-8A23-B8AB21-2BAC4A2C2B20-2B7AC2B19-3(3B8A3B18-)3B8A3B19-2B7AC2B20-2BAC5AC2B21-BA7CB23-8A26-4B700-4B27-C4BA25-AC3BEA2(C24-AC5A)C24-ACBE2BAC25-C3BEA27-4B398-
