model
size = 22 12 20, scale = 0.05, origin = -y
material 
  colors = A:#FC0 B:#070 C:#39C D:#3CC E:#C0C F:#C0F
voxels
---------------------- ---------------------- ---------------------- ---------------------- ----------EF---------- ----------FE---------- ----------EF---------- ----------FE---------- ---------------------- ---------------------- ---------------------- ---------------------- 
----------AA---------- ---------A--A--------- --------A----A-------- -------A--AA--A------- ---------ABBA--------- ---------ABBA--------- ---------ABBA--------- ---------ABBA--------- -------A--AA--A------- --------A----A-------- ---------A--A--------- ----------AA---------- 
---------------------- ---------------------- ---------------------- ---------------------- -------AAAAAAAA------- ---------AAAA--------- -------AAAAAAAA------- ---------AAAA--------- ------A--------A------ ---------------------- ---------------------- ---------------------- 
---------------------- ---------------------- ---------------------- ---------------------- -----AAA------AAA----- ---------------------- -----AAA------AAA----- -----A----------A----- -----A----------A----- -----A----------A----- ---------------------- ---------------------- 
---------------------- ---------------------- ---------------------- ---------------------- ----AA----------AA---- ---------------------- ----AA----------AA---- ----A------------A---- ----A------------A---- ----A------------A---- ----A------------A---- ----A------------A---- 
---------------------- ---------------------- ---------------------- ---------------------- ---AA------------AA--- ---------------------- ---AA------------AA--- ---A--------------A--- ---A--------------A--- ---A--------------A--- ---------------------- ---------------------- 
---------------------- ---------------------- ---------------------- ---------------------- ---A--------------A--- ---------------------- ---A--------------A--- ---------------------- ---------------------- ---------------------- ---------------------- ---------------------- 
---------------------- ---------------------- ---------------------- ---------------------- --A---------------AA-- ---------------------- --A---------------AA-- ---------------------- ---------------------- ---------------------- ---------------------- ---------------------- 
---------------------- ---------------------- ---------------------- ---------------------- --A----------------A-- ---------------------- --A----------------A-- ---------------------- ---------------------- ---------------------- ---------------------- ---------------------- 
---------------------- ---------------------- ---------------------- ---------------------- -AA----------------AA- -AA----------------AA- -AA----------------AA- -AA----------------AA- -A------------------A- ---------------------- ---------------------- ---------------------- 
---------------------- ---------------------- ---------------------- ---------------------- -AA----------------AA- CBA----------------ABD DBA----------------ABC CAA----------------AAD -A------------------A- -A------------------A- ---------------------- ---------------------- 
---------------------- ---------------------- ---------------------- ---------------------- -AA----------------AA- DBA----------------ABC CBA----------------ABD DAA----------------AAC -A------------------A- -A------------------A- ---------------------- ---------------------- 
---------------------- ---------------------- ---------------------- ---------------------- -AA----------------AA- -AA----------------AA- -AA----------------AA- -AA----------------AA- -A------------------A- ---------------------- ---------------------- ---------------------- 
---------------------- ---------------------- ---------------------- ---------------------- --A----------------A-- ---------------------- --A----------------A-- ---------------------- ---------------------- ---------------------- ---------------------- ---------------------- 
---------------------- ---------------------- ---------------------- ---------------------- --A---------------AA-- ---------------------- --A---------------AA-- ---------------------- ---------------------- ---------------------- ---------------------- ---------------------- 
---------------------- ---------------------- ---------------------- ---------------------- ---A--------------A--- ---------------------- ---A--------------A--- ---------------------- ---------------------- ---------------------- ---------------------- ---------------------- 
---------------------- ---------------------- ---------------------- ---------------------- ---AA------------AA--- ---------------------- ---AA------------AA--- ---A--------------A--- ---------------------- ---------------------- ---------------------- ---------------------- 
---------------------- ---------------------- ---------------------- ---------------------- ----AA----------AA---- ---------------------- ----AA----------AA---- ----A------------A---- ----A------------A---- ---------------------- ---------------------- ---------------------- 
---------------------- ---------------------- ---------------------- ---------------------- -----AA--------AA----- ------AA------AA------ -----AA--------AA----- -----A----------A----- ---------------------- ---------------------- ---------------------- ---------------------- 
---------------------- ---------------------- ---------------------- ---------------------- ---------------------- --------A----A-------- ---------------------- ---------------------- ---------------------- ---------------------- ---------------------- ---------------------- 
