model
size = 22 6 22, scale = 0.05, origin = -y
material 
  colors = A:#FC0 B:#070 C:#FF3 D:#080 E:#03F F:#050 G:#E00 H:#06F I:#00B
voxels
---------------------- ----------DB---------- ----------BD---------- ----------FB---------- ----------BD---------- ---------------------- 
---------AAAA--------- ---------ABBA--------- ---------ABBA--------- ---------ABBA--------- ---------ABBA--------- ---------AAAA--------- 
---------------------- -------AAAAAAAA------- -------HCCCCCCE------- -------AAAAAAAA------- ---------AAAA--------- ---------------------- 
-----A----------A----- -----AAA------AAA----- -----CCA------ACC----- -----AAA------AAA----- -----A----------A----- ---------------------- 
----A------------A---- ----AA----------AA---- ----GA----------AG---- ----AA----------AA---- ----A------------A---- ---------------------- 
---A--------------A--- ---AA------------AA--- ---CA------------AC--- ---AA------------AA--- ---A--------------A--- ---------------------- 
---------------------- ---A--------------A--- ---C--------------C--- ---A--------------A--- ---------------------- ---------------------- 
---------------------- --A---------------AA-- --H---------------AE-- --A---------------AA-- ---------------------- ---------------------- 
---------------------- --A----------------A-- --C----------------C-- --A----------------A-- ---------------------- ---------------------- 
-A------------------A- -AA----------------AA- -AC----------------AA- -AA----------------AA- -AA----------------AA- -A------------------A- 
-A------------------A- FBA----------------ABD DBC----------------ABB BBA----------------ABD DBA----------------ABB -A------------------A- 
-A------------------A- DBA----------------ABF BBC----------------ABD DBA----------------ABB FBA----------------ABD -A------------------A- 
-A------------------A- -AA----------------AA- -AC----------------AA- -AA----------------AA- -AA----------------AA- -A------------------A- 
---------------------- --A----------------A-- --C----------------C-- --A----------------A-- ---------------------- ---------------------- 
---------------------- --A---------------AA-- --H---------------AI-- --A---------------AA-- ---------------------- ---------------------- 
---------------------- ---A--------------A--- ---C--------------C--- ---A--------------A--- ---------------------- ---------------------- 
---A--------------A--- ---AA------------AA--- ---CA------------AC--- ---AA------------AA--- ---A--------------A--- ---------------------- 
----A------------A---- ----AA----------AA---- ----GA----------AG---- ----AA----------AA---- ----A------------A---- ---------------------- 
-----A----------A----- -----AA--------AA----- -----CCA------ACC----- -----AAA------AAA----- -----A----------A----- ---------------------- 
---------------------- -------AAAAAAAA------- -------ECCCCCCE------- -------AAAAAAAA------- ---------AAAA--------- ---------------------- 
---------AAAA--------- ---------ABBA--------- ---------ABBA--------- ---------ABBA--------- ---------ABBA--------- ---------AAAA--------- 
---------------------- ----------DB---------- ----------BD---------- ----------DB---------- ----------BD---------- ---------------------- 
