model
size = 32 19 3, scale = 0.05, origin = -y
material 
  colors = A:#081808 B:#081818 C:#192526
voxels
11-A10-3A4-2A-2A2-2A6-A5-A4-2A3-3BA-C-AB2-3A2-2A5-A-2A-CA-2A2-B-C-B3-C2-A2BA-3A-CAC3-C4-BA-CBA2-ABA-A2-B-A3-2B4-C3-BC2-CBA2-B3-B2(-2A)2-BCA2(3-B)3-C-BA-2B2-B4-A3-B-C3-B3-3A-CB-C-3A-A2BA-A2-4A-A2B2A3-6A4-A3-A-3A9-2A72-A32-A3-2A3-3A20-A-ABA3-A2-AC19-A-B2A3-B2-CA19-AB2-A3-A2-CA19-BA2-A4-3A18-3A3-A31-2A31-A10-3A4-2A-2A2-2A6-A5-A4-2A3-3BA-C-AB2-3A2-2A5-A-2A-CA-2A2-B-C-B3-C2-A2BA-3A-CAC3-C4-BA-CBA2-ABA-A2-B-A3-2B4-C3-BC2-CBA2-B3-B2(-2A)2-BCA2(3-B)3-C-BA-2B2-B4-A3-B-C3-B3-3A-CB-C-3A-A2BA-A2-4A-A2B2A3-6A4-A3-A-3A9-2A72-A32-A3-2A3-3A20-A-ABA3-A2-AC19-A-B2A3-B2-CA19-AB2-A3-A2-CA19-BA2-A4-3A18-3A3-A31-2A31-A10-3A4-2A-2A2-2A6-A5-A4-2A3-3BA-C-AB2-3A2-2A5-A-2A-CA-2A2-B-C-B3-C2-A2BA-3A-CAC3-C4-BA-CBA2-ABA-A2-B-A3-2B4-C3-BC2-CBA2-B3-B2(-2A)2-BCA2(3-B)3-C-BA-2B2-B4-A3-B-C3-B3-3A-CB-C-3A-A2BA-A2-4A-A2B2A3-6A4-A3-A-3A9-2A72-A32-A3-2A3-3A20-A-ABA3-A2-AC19-A-B2A3-B2-CA19-AB2-A3-A2-CA19-BA2-A4-3A18-3A3-A31-2A20-
