model
size = 32 31 32, scale = 0.05, origin = -y
material 
  colors = A:#F0F B:#F2BB08 C:#180808 D:#181808 E:#080818 F:#180818 G:#F9E9E9 H:#282808
voxels
12-8A24-8A950-3A2G2A2G3A20-4A2GA2G3A947-2AG8AG2A18-2A2G6A2G2A945-2AG10AG2A16-16A943-18A14-2AG12AG2A941-2AG14AG2A12-2AG14AG2A940-AG16AGA12-20A939-22A10-2AG16AG2A938-AG18AGA10-AG18AGA937-2AG18AG2A8-24A936-24A8-AG20AGA936-AG20AGA8-AG20AGA935-2AG20AG2A6-26A934-26A2(6-AG22AGA934-AG22AGA)6-26A933-28A4-28A2(932-AG24AGA4-AG24AGA)931-2AG24AG2A2-30A930-30A2-30A2(930-AG26AGA2-AG26AGA)930-AG26AGA2-30A929-64A2(928-AG28AG2AG28AGA)928-AG28AG2AG4A15C4DC4AGA6-2(14C4D2C12-)3(2C2B2F2B2E2C2B2E2B2D12-)3(4C2B2F4B2E2B2D2C12-)3(6C2B2F2C2B2E2D2C12-)3(2C16B2D12-)3(2C4B2F4B2E4B2D12-)2(4C12B2D2C12-)4C12B2D2C14-2(4C8B2C2D16-)4C8B2C2D18-2(4C4B2F2C20-)4C4B2F2C22-2(8C24-)8C12-38A15C4DC6A6-2(14C4D2C12-)3(2C2B2F2B2E2C2B2E2B2D12-)3(4C2B2F4B2E2B2D2C12-)3(6C2B2F2C2B2E2D2C12-)3(2C16B2D12-)3(2C4B2F4B2E4B2D12-)2(4C12B2D2C12-)4C12B2D2C14-2(4C8B2H2D16-)4C8B2H2D18-2(4C4B2F2C20-)4C4B2F2C22-2(8C24-)8C12-AG28AG7A15C4DC6A6-2(14C4D2C12-)3(2C2B2F2B2E2C2B2E2B2D12-)3(4C2B2F4B2E2B2D2C12-)3(6C2B2F2C2B2E2D2C12-)3(2C16B2D12-)3(2C4B2F4B2E4B2D12-)2(4C12B2D2C12-)4C12B2D2C14-2(4C8B2H2D16-)4C8B2H2D18-2(4C4B2F2C20-)4C4B2F2C22-2(8C24-)8C12-AG28AG2AG4A15C4DC4AGA6-2(14C4D2C12-)3(2C2B2F2B2E2C2B2E2B2D12-)3(4C2B2F4B2E2B2D2C12-)3(6C2B2F2C2B2E2D2C12-)3(2C16B2D12-)3(2C4B2F4B2E4B2D12-)2(4C12B2D2C12-)4C12B2D2C14-2(4C8B2C2D16-)4C8B2C2D18-2(4C4B2F2C20-)4C4B2F2C22-2(8C24-)8C12-AG28AG2AG28AGA928-
