model
size = 30 31 32, scale = 0.05, origin = -y
material 
  colors = A:#080818 B:#F0F C:#0FF D:#F9E9E9
voxels
12-6B24-6B892-3B2DBD3B20-4B2D4B889-2BD6BD2B18-2B2D4B2D2B887-2BD8BD2B16-14B885-16B14-2BD10BD2B883-2BD12BD2B12-2BD12BD2B882-BD14BDB12-18B881-20B10-2BD14BD2B880-BD16BDB10-BD16BDB879-2BD16BD2B8-22B878-22B8-BD18BDB878-BD18BDB8-BD18BDB877-2BD18BD2B6-24B876-24B2(6-BD20BDB876-BD20BDB)6-24B875-26B4-26B2(874-BD22BDB4-BD22BDB)873-2BD22BD2B2-28B872-28B2-28B2(872-BD24BDB2-BD24BDB)872-BD24BDB2-28B871-60B2(870-BD26BD2BD26BDB)870-BD26BD2BD7B13A6BDB8-14A16-14A10-3(8A4C2A4C8A4-)3(2(2A2C)10A2(2C2A)4-)3(2A2C2A14C2A2C2A4-)3(2A22C2A4-)2(4A4C2A6C2A4C4A4-)4A4C2A6C2A4C4A6-2(4A14C4A8-)4A14C4A10-3(4A2C6A2C4A12-)3(2A2C4A2-4A2C2A12-)2(6A6-6A12-)2(6A6-)39B13A8B8-14A16-14A10-3(8A4C2A4C8A4-)3(2(2A2C)10A2(2C2A)4-)3(2A2C2A14C2A2C2A4-)3(2A22C2A4-)2(4A4C2A6C2A4C4A4-)4A4C2A6C2A4C4A6-2(4A14C4A8-)4A14C4A10-3(4A2C6A2C4A12-)3(2A2C4A2-4A2C2A12-)2(6A6-6A12-)2(6A6-)BD26BD10B13A8B8-14A16-14A10-3(8A4C2A4C8A4-)3(2(2A2C)10A2(2C2A)4-)3(2A2C2A14C2A2C2A4-)3(2A22C2A4-)2(4A4C2A6C2A4C4A4-)4A4C2A6C2A4C4A6-2(4A14C4A8-)4A14C4A10-3(4A2C6A2C4A12-)3(2A2C4A2-4A2C2A12-)2(6A6-6A12-)2(6A6-)BD26BD2BD7B13A6BDB8-14A16-14A10-3(8A4C2A4C8A4-)3(2(2A2C)10A2(2C2A)4-)3(2A2C2A14C2A2C2A4-)3(2A22C2A4-)2(4A4C2A6C2A4C4A4-)4A4C2A6C2A4C4A6-2(4A14C4A8-)4A14C4A10-3(4A2C6A2C4A12-)3(2A2C4A2-4A2C2A12-)2(6A6-6A12-)2(6A6-)BD26BD2BD26BDB870-
