model
size = 32 32 8, scale = 0.05, origin = -y
material 
  colors = A:#FC3
voxels
33-4A23-3A2-5A20-5A3-5A18-5A4-6A16-6A5-6A14-6A7-5A13-6A9-5A12-5A11-5A10-5A14-4A8-4A17-3A7-4A19-3A6-3A22-2A4-2A25-2A2-2A27-4A29-2A30-2A29-A2-A27-A4-A25-A6-A397-2A26-2A-5A22-11A20-6A-6A18-6A3-6A16-6A5-6A14-6A7-6A12-6A9-6A10-6A11-6A8-6A13-5A8-5A15-5A6-5A17-5A4-5A21-2A4-2A25-2A2-2A27-4A29-2A29-4A27-2A2-2A25-2A4-2A24-A6-A23-A8-A21-A10-A19-A12-A17-A279-3A26-8A22-11A20-6A-6A18-6A3-6A16-6A5-6A14-6A7-6A12-6A9-6A10-6A11-6A8-6A13-6A6-6A15-6A4-6A17-6A2-6A20-4A2-4A23-8A25-6A27-4A27-6A25-8A23-4A2-4A22-3A4-3A21-3A6-3A19-3A8-3A17-3A10-3A15-3A12-3A13-3A14-3A11-3A16-3A9-3A18-3A7-2A22-2A5-2A24-2A3-2A26-2A-2A28-2A32-3A26-8A22-11A20-6A-6A18-6A3-6A16-6A5-6A14-6A7-6A12-6A9-6A10-6A11-6A8-6A13-6A6-6A15-6A4-6A17-6A2-6A20-4A2-4A23-8A25-6A27-4A27-6A25-8A23-4A2-4A22-3A4-3A21-3A6-3A19-3A8-3A17-3A10-3A15-3A12-3A13-3A14-3A11-3A16-3A9-3A18-3A7-3A20-3A5-2A24-2A3-2A26-2A2-A28-3A30-4A26-8A22-11A20-6A-6A18-6A3-6A16-6A5-6A14-6A7-6A12-6A9-6A10-6A11-6A8-6A13-6A6-6A15-6A4-6A17-6A2-6A20-4A2-4A23-8A25-6A27-4A27-6A25-8A23-4A2-4A22-3A4-3A21-3A6-3A19-3A8-3A17-3A10-3A15-3A12-3A2(14-2A)13-2A16-2A11-2A18-2A9-2A20-2A7-A24-A5-A26-A3-A28-A-A30-4A26-8A22-11A20-6A-6A18-6A3-6A16-6A5-6A14-6A7-6A12-6A9-6A10-6A11-6A8-6A13-6A6-6A15-6A4-6A17-6A2-6A20-4A2-4A23-8A25-6A27-4A27-6A25-8A23-4A2-4A22-3A4-3A21-3A6-3A19-3A8-3A17-3A10-3A15-3A12-3A2(14-2A)13-2A16-2A11-2A18-2A9-2A20-2A7-A24-A100-2A26-2A-5A22-5A-5A20-5A3-5A18-5A5-5A16-5A7-5A14-5A9-2(5A12-)4A10-4A15-4A8-4A17-4A6-4A19-3A6-3A20-4A4-4A21-4A3-3A24-3A-2A27-4A29-2A29-4A27-3A-2A25-2A4-2A24-A6-A23-A8-A396-4A22-4A2-5A20-5A3-5A18-5A5-5A16-5A7-5A14-5A9-2(5A12-)4A10-4A15-4A8-4A17-4A7-3A19-3A6-3A21-3A5-2A23-3A3-2A26-2A-2A28-3A30-A31-A495-
