model
size = 27 11 20, scale = 0.05, origin = -y
material 
  colors = A:#555 B:#100
voxels
----------BBBBBBBBBB------- --------------AAAAAA------- --------------AAAAAA------- ---------------AAAA-------- --------------------------- --------------------------- --------------------------- --------------------------- --------------------------- --------------------------- --------------------------- 
--------BBAAAAAAAAAABB----- -------------AAAAAAAAA----- -------------AAAAAAAAA----- -------------AAAAAAAAA----- -------------AAAAAAAA------ --------------AAAAAA------- --------------------------- --------------------------- --------------------------- --------------------------- --------------------------- 
------BBAAAAAA-----AAABB--- ----------AAAAAAAAAAAAAA--- -----------AAAAAAAAAAAA---- -----------AAAAAAAAAAAA---- -----------AAAAAAAAAAAA---- ------------AAAAAAAAAA----- -------------AAAAAAAA------ ----------------AA--------- --------------------------- --------------------------- --------------------------- 
----BBAAAAAA---------AAAB-- ---------AAAAA-----AAAAAA-- ----------AAAAAAAAAAAAAA--- ----------AAAAAAAAAAAAAA--- ----------AAAAAAAAAAAAAA--- -----------AAAAAAAAAAAA---- ------------AAAAAAAAAA----- -------------AAAAAAAA------ ----------------AA--------- --------------------------- --------------------------- 
---BAAAAAA-------------AB-- ---------AAA---------AAAA-- ---------AAAAA-----AAAAAA-- ---------AAAAA-----AAAAAA-- ---------AAAAA-----AAAAAA-- ----------AAAA-----AAAAA--- -----------AAA-----AAAA---- ------------AAAAAAAAAA----- -------------AAAAAAAA------ --------------------------- --------------------------- 
--BAAAAAAA-------------AAB- --------AAA-----------AAAA- --------AAAA---------AAAAA- --------AAAA---------AAAAA- ---------AAA---------AAAA-- ---------AAA---------AAAA-- ----------AA---------AAA--- -----------AAA-----AAAA---- ------------AAAAAAAAAA----- --------------AAAAAA------- --------------------------- 
-BAAAAAAA---------------AB- --------AA-------------AAA- --------AAA-----------AAAA- --------AAA-----------AAAA- --------AAA-----------AAAA- ---------AA-----------AAA-- ---------AA-----------AAA-- ----------AAA-------AAAA--- -----------AAAAAAAAAAAA---- -------------AAAAAAAA------ --------------------------- 
-BAAAAAAA---------------AAB -------AAA-------------AAAA -------AAAA-----------AAAAA --------AAA-----------AAAA- --------AAA-----------AAAA- --------AAA-----------AAAA- ---------AA-----------AAA-- ----------AA---------AAA--- -----------AAAAAAAAAAAA---- ------------AAAAAAAAAA----- ---------------AAAA-------- 
BAAAAAAA-----------------AB -------AA---------------AAA -------AAA-------------AAAA -------AAA-------------AAAA --------AA-------------AAA- --------AA-------------AAA- ---------A-------------AA-- ----------A-----------AA--- -----------AAAAAAAAAAAA---- ------------AAAAAAAAAA----- --------------AAAAAA------- 
BAAAAAAA-----------------AB -------AA---------------AAA -------AAA-------------AAAA -------AAA-------------AAAA --------AA-------------AAA- --------AA-------------AAA- ---------A-------------AA-- ---------AA-----------AAA-- ----------AAAAAAAAAAAAAA--- ------------AAAAAAAAAA----- --------------AAAAAA------- 
BAAAAAAA-----------------AB -------AA---------------AAA -------AAA-------------AAAA -------AAA-------------AAAA --------AA-------------AAA- --------AA-------------AAA- ---------A-------------AA-- ---------AA-----------AAA-- ----------AAAAAAAAAAAAAA--- ------------AAAAAAAAAA----- --------------AAAAAA------- 
BAAAAAAA-----------------AB -------AA---------------AAA -------AAA-------------AAAA -------AAA-------------AAAA --------AA-------------AAA- --------AA-------------AAA- ---------A-------------AA-- ----------A-----------AA--- -----------AAAAAAAAAAAA---- ------------AAAAAAAAAA----- --------------AAAAAA------- 
-BAAAAAA-----------------AB -------AA---------------AAA -------AAA-------------AAAA --------AA-------------AAA- --------AA-------------AAA- --------AA-------------AAA- ---------A-------------AA-- ----------A-----------AA--- -----------AAAAAAAAAAAA---- ------------AAAAAAAAAA----- ---------------AAAA-------- 
-BAAAAAAA---------------AB- --------AA-------------AAA- --------AAA-----------AAAA- --------AAA-----------AAAA- --------AAA-----------AAAA- ---------AA-----------AAA-- ---------AA-----------AAA-- ----------AA---------AAA--- -----------AAAAAAAAAAAA---- -------------AAAAAAAA------ --------------------------- 
--BAAAAAA---------------AB- --------AA-------------AAA- --------AAA-----------AAAA- --------AAA-----------AAAA- ---------AA-----------AAA-- ---------AA-----------AAA-- ----------A-----------AA--- -----------AA-------AAA---- ------------AAAAAAAAAA----- --------------AAAAAA------- --------------------------- 
---BAAAAAA-------------AB-- ---------AA-----------AAA-- ---------AAA---------AAAA-- ---------AAA---------AAAA-- ---------AAA---------AAAA-- ----------AA---------AAA--- -----------A---------AA---- ------------AA-----AAA----- -------------AAAAAAAA------ --------------------------- --------------------------- 
----BBAAAA-------------AB-- ---------AAA---------AAAA-- ----------AAAA-----AAAAA--- ----------AAAA-----AAAAA--- ----------AAAA-----AAAAA--- -----------AAA-----AAAA---- ------------AA-----AAA----- -------------AAAAAAAA------ ----------------AA--------- --------------------------- --------------------------- 
------BBAAAA---------ABB--- ----------AAAA-----AAAAA--- -----------AAAAAAAAAAAA---- -----------AAAAAAAAAAAA---- -----------AAAAAAAAAAAA---- ------------AAAAAAAAAA----- -------------AAAAAAAA------ ----------------AA--------- --------------------------- --------------------------- --------------------------- 
--------BBAAAA-----ABB----- ------------AAAAAAAAAA----- ------------AAAAAAAAAA----- ------------AAAAAAAAAA----- -------------AAAAAAAA------ --------------AAAAAA------- --------------------------- --------------------------- --------------------------- --------------------------- --------------------------- 
----------BBBBBBBBBB------- --------------AAAAAA------- --------------AAAAAA------- ---------------AAAA-------- --------------------------- --------------------------- --------------------------- --------------------------- --------------------------- --------------------------- --------------------------- 
