model
size = 22 23 25, scale = 0.05, origin = -y
material 
  colors = A:#111 B:#FCFAF2 C:#FEDFE1 D:#AAA
voxels
---------------------- ---------------------- ---------------------- ----------------AA---- ----------------AA---- ----------------AA---- ----------------AA---- ----------------AA---- ----------------AA---- ----------------AA---- ----------------AA---- ----------------AA---- ----------------AA---- ----------------AA---- ----------------A----- ----------------A----- ---------------------- ---------------------- ---------------------- ---------------------- ---------------------- ---------------------- ---------------------- 
---------------------- ----------------AA---- ----------------AA---- ------A---------AA---- ----AAA---------AA---- ----AAA---------AA---- ----AAA---------AA---- ----AAA---------AA---- ----AAA---------AA---- ----AAA---------AA---- ----AAA---------AA---- ----AAA---------AA---- ----AAA---------AA---- -----AA---------AA---- ----AAA---------A----- -----AA---------A----- ------A---------A----- ----------------A----- ----------------A----- ----------------A----- -------AA------AA----- --------AAAAAAA-A----- ---------AAAAA-------- 
------AAAAAAAAAAAAA--- -----AAAAAAAAAAAAAA--- ----AAAABBBBCCDAAAA--- ---AAAAABBBBCCDAAAA--- ---AAAAABBBBCCDAAAA--- ---AAAAABBBBCCDAAAA--- ---AAAAABBBBCCDAAAA--- ---AAAAABBBBCCDAAAA--- ---AAAAABBBBCCDAAAA--- ---AAAAABBBBCCDAAAA--- ---AAAAABBBBCCDAAAA--- ---AAAAABBBBCCDAAAA--- ---AAAAABBBBCCDAAAA--- ---AAAAABBBBCCDAAA---- -----AAABBBBCCDAAA---- -----AAABBBBCCDAAA---- ----AAAABBBBCCDAAA---- ----AAAABBBBCCCAAA---- ----AAAABBBBBBBAAA---- ----AAAABBBBBBBAAA---- -----AAAABBBBBAAAA---- ------AAAAAAAAAA------ --------AAAAAAA------- 
------AAAAAAAAAAAAA--- ----AAAAAAAAAAAAAAAA-- ---AAAAAABBBBBBAAAAA-- --AAAAAAABBBBBBAAAAA-- --AAAAAAABBBBBBAAAAA-- --AAAAAAABBBBBBAAAAA-- --AAAAAAABBBBBBAAAAA-- --AAAAAAABBBBBBAAAAA-- --AAAAAAABBBBBBAAAAA-- --AAAAAAABBBBBBAAAAA-- --AAAAAAABBBBBBAAAAA-- --AAAAAAABBBBBBAAAAA-- ---AAAAAABBBBBBAAAA--- ---AAAAAABBBBBBAAA---- ----AAAAABBBBBBAAA---- ----AAAAABBBBBBAAA---- -----AAAABBBBBBAAA---- -----AAAABBBBBBAAA---- -----AAAABBBBBBAAA---- -----AAAABBBBBAAAA---- -----AAAABBBBBAAAA---- -----AAAAAAAAAAAAA---- ------AAAAAAAAAA------ 
-----AAAAAAAAAAAAAAA-- ----AAAAAAAAAAAAAAAAA- --AAAAAAABBBBAAAAAAAA- -AAAAAAAABBBBAAAAAAAA- -AAAAAAAABBBBAAAAAAAA- -AAAAAAAABBBBAAAAAAAA- -AAAAAAAABBBBAAAAAAAA- -AAAAAAAABBBBAAAAAAAA- -AAAAAAAABBBBAAAAAAAA- --AAAAAAABBBBAAAAAAA-- --AAAAAAABBBBAAAAAAA-- ---AAAAAABBBBAAAAAAA-- ---AAAAAABBBBAAAAAA--- ---AAAAAABBBBAAAAA---- ----AAAAABBBBAAAAA---- ----AAAAABBBBAAAAA---- ----AAAAABBBBAAAAA---- ----AAAAABBBBAAAAA---- ----AAAAABBBBAAAAA---- ----AAAAAAABAAAAAA---- ----AAAAAAAAAAAAAA---- ----AAAAAAAAAAAAAA---- ------AAAAAAAAAAA----- 
----AAAAAAAAAAAAAAAA-- ---AAAAAAAAAAAAAAAAAA- --AAAAAAAABBAAAAAAAAA- -AAAAAAAAABBAAAAAAAAA- -AAAAAAAAABBAAAAAAAAA- -AAAAAAAAABBAAAAAAAAA- -AAAAAAAAABBAAAAAAAAA- -AAAAAAAAABBAAAAAAAAA- -AAAAAAAAABBAAAAAAAAA- --AAAAAAAABBAAAAAAAA-- --AAAAAAAABBAAAAAAAA-- ---AAAAAAABBAAAAAAAA-- ---AAAAAAABBAAAAAAA--- ---AAAAAAABBAAAAAAA--- ----AAAAAABBAAAAAA---- ----AAAAAABBAAAAAA---- ----AAAAAABBAAAAAA---- ----AAAAAABBAAAAAA---- ----AAAAAABBAAAAAA---- ----AAAAAAAAAAAAAA---- ----AAAAAAAAAAAAAA---- ----AAAAAAAAAAAAAA---- ------AAAAAAAAAAA----- 
----AAAAAAAAAAAAAAAA-- ---AAAAAAAAAAAAAAAAAA- -AAAAAAAAABBAAAAAAAAAA AAAAAAAAAABBAAAAAAAAAA AAAAAAAAAABBAAAAAAAAAA AAAAAAAAAABBAAAAAAAAAA AAAAAAAAAABBAAAAAAAAAA AAAAAAAAAABBAAAAAAAAAA -AAAAAAAAABBAAAAAAAAA- --AAAAAAAABBAAAAAAAA-- --AAAAAAAABBAAAAAAAA-- ---AAAAAAABBAAAAAAAA-- ---AAAAAAABBAAAAAAA--- ---AAAAAAABBAAAAAAA--- ----AAAAAABBAAAAAA---- ----AAAAAABBAAAAAA---- ----AAAAAABBAAAAAA---- ----AAAAAABAAAAAAA---- ----AAAAAABAAAAAAA---- ----AAAAAAAAAAAAAA---- ----AAAAAAAAAAAAAA---- ----AAAAAAAAAAAAAA---- ------AAAAAAAAAAA----- 
---AAAAAAAAAAAAAAAAAA- --AAAAAAAAAAAAAAAAAAAA -AAAAAAAAAAAAAAAAAAAAA AAAAAAAAAAAAAAAAAAAAAA AAAAAAAAAAAAAAAAAAAAAA AAAAAAAAAAAAAAAAAAAAAA AAAAAAAAAAAAAAAAAAAAAA AAAAAAAAAAAAAAAAAAAAAA --AAAAAAAAAAAAAAAAAAA- --AAAAAAAAAAAAAAAAAAA- --AAAAAAAAAAAAAAAAAAA- --AAAAAAAAAAAAAAAAAA-- ---AAAAAAAAAAAAAAAAA-- ---AAAAAAAAAAAAAAAA--- ----AAAAAAAAAAAAAAA--- ----AAAAAAAAAAAAAAA--- ----AAAAAAAAAAAAAAA--- ----AAAAAAAAAAAAAAA--- ----AAAAAAAAAAAAAAA--- ----AAAAAAAAAAAAAA---- ----AAAAAAAAAAAAAA---- ----AAAAAAAAAAAAAA---- ------AAAAAAAAAAA----- 
--AAAAAAAAAAAAAAAAAAA- AAAAAAAAAAAAAAAAAAAAAA AAAAAAAAAAAAAAAAAAAAAA AAAAAAAAAAAAAAAAAAAAAA AAAAAAAAAAAAAAAAAAAAAA AAAAAAAAAAAAAAAAAAAAAA AAAAAAAAAAAAAAAAAAAAAA -AAAAAAAAAAAAAAAAAAAAA --AAAAAAAAAAAAAAAAAAA- --AAAAAAAAAAAAAAAAAAA- --AAAAAAAAAAAAAAAAAAA- --AAAAAAAAAAAAAAAAAA-- ---AAAAAAAAAAAAAAAAA-- ---AAAAAAAAAAAAAAAA--- ----AAAAAAAAAAAAAAA--- ----AAAAAAAAAAAAAAA--- ----AAAAAAAAAAAAAAA--- ----AAAAAAAAAAAAAAA--- ----AAAAAAAAAAAAAAA--- ----AAAAAAAAAAAAAAA--- ----AAAAAAAAAAAAAAA--- ----AAAAAAAAAAAAAA---- ------AAAAAAAAAAA----- 
--AAAAAAAAAAAAAAAAAAAA AAAAAAAAAAAAAAAAAAAAAA AAAAAAAAAAAAAAAAAAAAAA AAAAAAAAAAAAAAAAAAAAAA AAAAAAAAAAAAAAAAAAAAAA AAAAAAAAAAAAAAAAAAAAAA AAAAAAAAAAAAAAAAAAAAAA -AAAAAAAAAAAAAAAAAAAAA --AAAAAAAAAAAAAAAAAAA- --AAAAAAAAAAAAAAAAAAA- --AAAAAAAAAAAAAAAAAAA- --AAAAAAAAAAAAAAAAAA-- ---AAAAAAAAAAAAAAAAA-- ---AAAAAAAAAAAAAAAA--- ----AAAAAAAAAAAAAAA--- ----AAAAAAAAAAAAAAA--- ----AAAAAAAAAAAAAAA--- ----AAAAAAAAAAAAAAA--- ----AAAAAAAAAAAAAAA--- ----AAAAAAAAAAAAAAA--- ----AAAAAAAAAAAAAAA--- ----AAAAAAAAAAAAAA---- ------AAAAAAAAAAA----- 
-AAAAAAAAAAAAAAAAAAAA- AAAAAAAAAAAAAAAAAAAAAA AAAAAAAAAAAAAAAAAAAAAA AAAAAAAAAAAAAAAAAAAAAA AAAAAAAAAAAAAAAAAAAAAA AAAAAAAAAAAAAAAAAAAAAA AAAAAAAAAAAAAAAAAAAAAA -AAAAAAAAAAAAAAAAAAAAA --AAAAAAAAAAAAAAAAAAAA --AAAAAAAAAAAAAAAAAAA- --AAAAAAAAAAAAAAAAAAA- --AAAAAAAAAAAAAAAAAAA- ---AAAAAAAAAAAAAAAAA-- ---AAAAAAAAAAAAAAAA--- ----AAAAAAAAAAAAAAA--- ----AAAAAAAAAAAAAAA--- ----AAAAAAAAAAAAAAA--- ----AAAAAAAAAAAAAAA--- ----AAAAAAAAAAAAAAA--- ----AAAAAAAAAAAAAAA--- ----AAAAAAAAAAAAAAA--- ----AAAAAAAAAAAAAA---- -----AAAAAAAAAAAA----- 
-AAAAAAAAAAAAAAAAAAAA- -AAAAAAAAAAAAAAAAAAAA- AAAAAAAAAAAAAAAAAAAAAA AAAAAAAAAAAAAAAAAAAAAA AAAAAAAAAAAAAAAAAAAAAA AAAAAAAAAAAAAAAAAAAAAA AAAAAAAAAAAAAAAAAAAAAA -AAAAAAAAAAAAAAAAAAAAA -AAAAAAAAAAAAAAAAAAAAA --AAAAAAAAAAAAAAAAAAA- --AAAAAAAAAAAAAAAAAAA- --AAAAAAAAAAAAAAAAAAA- ---AAAAAAAAAAAAAAAAA-- ---AAAAAAAAAAAAAAAAA-- ----AAAAAAAAAAAAAAA--- ----AAAAAAAAAAAAAAA--- ----AAAAAAAAAAAAAAA--- ----AAAAAAAAAAAAAAA--- ----AAAAAAAAAAAAAAA--- ----AAAAAAAAAAAAAAA--- ----AAAAAAAAAAAAAAA--- ----AAAAAAAAAAAAAA---- -----AAAAAAAAAAAA----- 
-AAAAAAAAAAAAAAAAAAA-- -AAAAAAAAAAAAAAAAAAAA- -AAAAAAAAAAAAAAAAAAAA- -AAAAAAAAAAAAAAAAAAAA- -AAAAAAAAAAAAAAAAAAAA- -AAAAAAAAAAAAAAAAAAAA- -AAAAAAAAAAAAAAAAAAAA- -AAAAAAAAAAAAAAAAAAAA- -AAAAAAAAAAAAAAAAAAAA- --AAAAAAAAAAAAAAAAAAA- --AAAAAAAAAAAAAAAAAAA- --AAAAAAAAAAAAAAAAAAA- ---AAAAAAAAAAAAAAAAAA- ---AAAAAAAAAAAAAAAAA-- ----AAAAAAAAAAAAAAA--- ----AAAAAAAAAAAAAAA--- ----AAAAAAAAAAAAAAA--- ----AAAAAAAAAAAAAAA--- ----AAAAAAAAAAAAAAA--- ----AAAAAAAAAAAAAAA--- ----AAAAAAAAAAAAAAA--- ----AAAAAAAAAAAAAA---- -----AAAAAAAAAAAA----- 
--AAAAAAAAAAAAAAAAAA-- -AAAAAAAAAAAAAAAAAAA-- -AAAAAAAAAAAAAAAAAAAA- -AAAAAAAAAAAAAAAAAAAA- -AAAAAAAAAAAAAAAAAAAA- -AAAAAAAAAAAAAAAAAAAA- -AAAAAAAAAAAAAAAAAAAA- -AAAAAAAAAAAAAAAAAAAA- --AAAAAAAAAAAAAAAAAAA- --AAAAAAAAAAAAAAAAAAA- --AAAAAAAAAAAAAAAAAAA- --AAAAAAAAAAAAAAAAAAA- ---AAAAAAAAAAAAAAAAAA- ---AAAAAAAAAAAAAAAAA-- ----AAAAAAAAAAAAAAAA-- ----AAAAAAAAAAAAAAAA-- ----AAAAAAAAAAAAAAAA-- ----AAAAAAAAAAAAAAAA-- ----AAAAAAAAAAAAAAA--- ----AAAAAAAAAAAAAAA--- ----AAAAAAAAAAAAAAA--- ----AAAAAAAAAAAAAA---- -----AAAAAAAAAAAA----- 
--AAAAAAAAAAAAAAAAA--- --AAAAAAAAAAAAAAAAAA-- --AAAAAAAAAAAAAAAAAA-- --AAAAAAAAAAAAAAAAAA-- --AAAAAAAAAAAAAAAAAA-- --AAAAAAAAAAAAAAAAAA-- --AAAAAAAAAAAAAAAAAA-- --AAAAAAAAAAAAAAAAAA-- --AAAAAAAAAAAAAAAAAA-- --AAAAAAAAAAAAAAAAAA-- --AAAAAAAAAAAAAAAAAA-- --AAAAAAAAAAAAAAAAAA-- ---AAAAAAAAAAAAAAAAA-- ---AAAAAAAAAAAAAAAAA-- ---AAAAAAAAAAAAAAAAA-- ---AAAAAAAAAAAAAAAAA-- ---AAAAAAAAAAAAAAAAA-- ---AAAAAAAAAAAAAAAAA-- ---AAAAAAAAAAAAAAAAA-- ---AAAAAAAAAAAAAAAA--- ---AAAAAAAAAAAAAAAA--- ----AAAAAAAAAAAAAA---- -----AAAAAAAAAAAA----- 
---AAAAAAAAAAAAAAAA--- ---AAAAAAAAAAAAAAAA--- ---AAAAAAAAAAAAAAAA--- ---AAAAAAAAAAAAAAAA--- ---AAAAAAAAAAAAAAAA--- ---AAAAAAAAAAAAAAAA--- ---AAAAAAAAAAAAAAAA--- ---AAAAAAAAAAAAAAAA--- ---AAAAAAAAAAAAAAAA--- ---AAAAAAAAAAAAAAAA--- ---AAAAAAAAAAAAAAAA--- ---AAAAAAAAAAAAAAAA--- ---AAAAAAAAAAAAAAAA--- ---AAAAAAAAAAAAAAAA--- ---AAAAAAAAAAAAAAAA--- ---AAAAAAAAAAAAAAAA--- ---AAAAAAAAAAAAAAAA--- ---AAAAAAAAAAAAAAAA--- ---AAAAAAAAAAAAAAAA--- ---AAAAAAAAAAAAAAAA--- ---AAAAAAAAAAAAAAA---- ----AAAAAAAAAAAAAA---- -----AAAAAAAAAAAA----- 
----AAAAAAAAAAAAAA---- ----AAAAAAAAAAAAAA---- ----AAAAAAAAAAAAAA---- ----AAAAAAAAAAAAAA---- ----AAAAAAAAAAAAAA---- ----AAAAAAAAAAAAAA---- ----AAAAAAAAAAAAAA---- ----AAAAAAAAAAAAAA---- ----AAAAAAAAAAAAAA---- ----AAAAAAAAAAAAAA---- ----AAAAAAAAAAAAAA---- ----AAAAAAAAAAAAAA---- ----AAAAAAAAAAAAAA---- ----AAAAAAAAAAAAAA---- ----AAAAAAAAAAAAAA---- ----AAAAAAAAAAAAAA---- ----AAAAAAAAAAAAAA---- ----AAAAAAAAAAAAAA---- ----AAAAAAAAAAAAAA---- ----AAAAAAAAAAAAAA---- ----AAAAAAAAAAAAAA---- -----AAAAAAAAAAAA----- ------AAAAAAAAAAA----- 
----AAAAAAAAAAAA------ ----AAAAAAAAAAAAA----- ----AAAAAAAAAAAAAA---- ----AAAAAAAAAAAAAA---- ----AAAAAAAAAAAAAA---- ----AAAAAAAAAAAAAA---- ----AAAAAAAAAAAAAA---- ----AAAAAAAAAAAAAA---- ----AAAAAAAAAAAAAA---- ----AAAAAAAAAAAAAA---- ----AAAAAAAAAAAAAA---- ----AAAAAAAAAAAAAA---- ----AAAAAAAAAAAAAA---- ----AAAAAAAAAAAAAA---- ----AAAAAAAAAAAAAA---- ----AAAAAAAAAAAAAA---- ----AAAAAAAAAAAAAA---- -----AAAAAAAAAAAA----- -----AAAAAAAAAAAA----- -----AAAAAAAAAAAA----- ------AAAAAAAAAA------ -------AAAAAAAA------- -------AAAAAAAA------- 
-----AAAAAAAAAA------- -----AAAAAAAAAAA------ -----AAAAAAAAAAA------ -----AAAAAAAAAAAA----- -----AAAAAAAAAAAA----- -----AAAAAAAAAAAA----- -----AAAAAAAAAAAA----- -----AAAAAAAAAAAA----- -----AAAAAAAAAAAA----- -----AAAAAAAAAAAA----- -----AAAAAAAAAAAA----- -----AAAAAAAAAAAA----- ------AAAAAAAAAAA----- ------AAAAAAAAAAA----- ------AAAAAAAAAAA----- -------AAAAAAAAA------ -------AAAAAAAAA------ -------AAAAAAAAA------ -------AAAAAAAAA------ -------AAAAAAAAA------ --------AAAAAAA------- --------AAAAA--------- ---------AAAAA-------- 
--------AAAAA--------- --------AAAAA--------- --------AAAAA--------- --------AAAAA--------- ----AAAAAAAAA--------- ---AA----AAAAAA------- ---------AAAA--------- ---------AAAA--------- ---------AAAA--------- ---------AAAA--------- ---------AAAA--------- ---------AAAA--------- ---------AAAA--------- ---------AAAA--------- ---------AAAA--------- ---------AAAA--------- ---------AAAA--------- ---------AAAA--------- ---------AAAA--------- ---------AAAA--------- ----------AA---------- ---------------------- ---------------------- 
--------AA--AA-------- --------AA--AA-------- --------AA--AA-------- --------A-AAA--------- -----AAAAAAAA--------- ----AAA-A---AAA------- ----A--------AA------- ---------------------- ---------------------- ---------------------- ---------------------- ---------------------- ---------------------- ---------------------- ---------------------- ---------------------- ---------------------- ---------------------- ---------------------- ---------------------- ---------------------- ---------------------- ---------------------- 
-------AAAA----------- -------AAAA----------- -------AAAA----------- --------AAA-A--------- ------A-A--AA--------- ------A-A---AAAA------ ----A--------A-A------ ---------------------- ---------------------- ---------------------- ---------------------- ---------------------- ---------------------- ---------------------- ---------------------- ---------------------- ---------------------- ---------------------- ---------------------- ---------------------- ---------------------- ---------------------- ---------------------- 
--------AA------------ --------AA------------ --------AA------------ --------AA------------ -------AAA-A---------- ------------A-AAA----- ----------------A----- ---------------------- ---------------------- ---------------------- ---------------------- ---------------------- ---------------------- ---------------------- ---------------------- ---------------------- ---------------------- ---------------------- ---------------------- ---------------------- ---------------------- ---------------------- ---------------------- 
---------------------- ---------------------- ---------------------- ---------------------- -------A--AA---------- -------A----A-A------- ---------------------- ---------------------- ---------------------- ---------------------- ---------------------- ---------------------- ---------------------- ---------------------- ---------------------- ---------------------- ---------------------- ---------------------- ---------------------- ---------------------- ---------------------- ---------------------- ---------------------- 
---------------------- ---------------------- ---------------------- ---------------------- ---------------------- ----AAAA------A------- ---------------------- ---------------------- ---------------------- ---------------------- ---------------------- ---------------------- ---------------------- ---------------------- ---------------------- ---------------------- ---------------------- ---------------------- ---------------------- ---------------------- ---------------------- ---------------------- ---------------------- 
