model
size = 20 9 20, scale = 0.05, origin = -y
material 
  colors = A:#111 B:#222 C:#555
voxels
-------------------- -------------------- -------------------- --------------AAA--- --------------AAA--- ----------A---AAA--- -------------------- -------------------- -------------------- 
-------------------- -------------------- -------------BB----- ------------AAAAA--- ------------A--AA--- ---------AAA---AA--- ----------AAA-A----- ---------A--A------- -------------------- 
-------------------- -------------------- -------------------- ----------AAAAAAAA-- -----------BAAAAA--- --------AAABAAAAA--- ----------AABAAA---- --------AAAAA-AA---- -------------------- 
-------------------- -------------------- --------A----------- --------AAAAAAAAAAA- --------ABAAAAAAA--- -------AAABAAAAAA--- -----A--BAAB-AAA---- -------AAAAA-AAA---- ------AB------------ 
-------------------- -------------------- --------A-BBB------- ------AAAAAAA--AAAA- -------AAA-AA--AAAAA ------AAABBAAAAAAAA- -----AABBBAAAAAAAA-- ------A-BAAAAAAAA--- ------BBA----------- 
------------A------- -----------AA------- -------A--AAAB-AC--- -----A-AAAAAAAABBAAA -----AAABAAAAABAAAAA -----AABAAA-A-AAAAA- ----AAAABBBAAAAAAA-- -----A-ABBAAAAAAA--- -----ABBAA---------- 
-----------A-------- -------A--AAA-CC---- ------AB-B-AAAAA---- ----A--AA--AAAAAAAAA ----AAAAA---AAAAAAA- ----AAA-----ABAAAAA- ---AAAAAAAAA-AAAAA-- ------A-BAABAAA----- -----BB-AAAA-------- 
---------AA--------- ---------AA-C------- ------ABBAAAACA----- ---AAAAAAAAAAABBAAA- ---AAAAA----AAAAAAA- ----AAAA--A-BAAAAA-- ---AAAAAAAAAAAAAAA-- -----BBBAAA-A----A-- -----AB--AA-A------- 
-------------------- ------A--AA-C------- -----ABAAAAC-AAAC--- --AAAAAAAAAA-AAABAAA ----A--AAAAAAABAABA- -----BAAAAAAA--AAA-- -----BB--AAAA--AA--- -----AA----A---A---- -------------------- 
-------------------- -----ABAAA--A------- -----BA-AAC-AA------ --AAAAAAAAAAAAAAAA-- ----AA-A----AAAAAAA- -----B------AAAAAA-- ----AA-------AAAA--- ----AA--------A----- -------------------- 
-------A------------ -----BAAAA-A-------- ----AAAAAA-AA------- --AAAAAAAAAAAAAA--A- ---ABBBAAAA--AAA---- ---AAAAAA-AA--A----- ----A-----A--------- -------------------- -------------------- 
------A------------- -----AA-A----------- ----AAAAA----------- -A-AAAA-AAAA-------- --AAAAA-AAAA-------- ---AAA-AA-AA-------- ---AA--A--AA-------- -------------------- -------------------- 
-------------------- ----AA-------------- ---AAAA------------- -AAAAAAAAAA--------- ---A--AA------------ --AAA--AAA---------- ---AA--AA----------- -------------------- -------------------- 
-------------------- ---A---------------- ---AA--------------- -AAAAAAAAA---------- -AAAAAAA------------ ---BA-AAA----------- ---AA-AA------------ -------------------- -------------------- 
-------------------- -------------------- --A----------------- AAABAAA------------- A-ABAAA------------- ----AAA------------- -------------------- -------------------- -------------------- 
-------------------- -------------------- --A----------------- AAAAAA-------------- AAAA-A-------------- --BBAA-------------- -------------------- -------------------- -------------------- 
-------------------- -------------------- -------------------- AAAAA--------------- AAAA---------------- -------------------- -------------------- -------------------- -------------------- 
-------------------- -------------------- -------------------- AAAA---------------- -------------------- -------------------- -------------------- -------------------- -------------------- 
-------------------- -------------------- -------------------- AAA----------------- -------------------- -------------------- -------------------- -------------------- -------------------- 
-------------------- -------------------- -------------------- AA------------------ -------------------- -------------------- -------------------- -------------------- -------------------- 
