model
size = 21 13 30, scale = 0.05, origin = -y
material 
  colors = A:#222 B:#FCFAF2
voxels
--------------------- --------------------- --------------AAA---- -------AAAAAAA------- --------------------- --------------------- --------------------- --------------------- --------------------- --------------------- --------------------- --------------------- --------------------- 
--------------------- ----AA----------A---- ----AA--------AAA---- ------AAAAAAAA------- --------------------- --------------------- --------------------- --------------------- --------------------- --------------------- --------------------- --------------------- --------------------- 
---A-------------A--- ----AA----------A---- ----AA--------AAA---- ------AAAABAAA------- --------------------- --------------------- --------------------- --------------------- --------------------- --------------------- --------------------- --------------------- --------------------- 
---A-------------A--- ----AA----------A---- ----AA--------AAA---- ------ABBBBAAA------- --------------------- --------------------- --------------------- --------------------- --------------------- --------------------- --------------------- --------------------- --------------------- 
---A-------------A--- ----AA----------A---- ----AA--------AAA---- ------ABAAAAAA------- --------------------- --------------------- --------------------- --------------------- --------------------- --------------------- --------------------- --------------------- --------------------- 
---A-------------A--- ----AA----------A---- ----AA--------AAA---- ------AABAAAAA------- --------------------- --------------------- --------------------- --------------------- --------------------- --------------------- --------------------- --------------------- --------------------- 
---A-------------A--- ----AA----------A---- ----AA--------AAA---- ------ABAAAAAA------- --------------------- --------------------- --------------------- --------------------- --------------------- --------------------- --------------------- --------------------- --------------------- 
---A-------------A--- ----AA----------A---- ----AA--------AAA---- ------ABBBBAAA------- --------------------- --------------------- --------------------- --------------------- --------------------- --------------------- --------------------- --------------------- --------------------- 
---A-------------A--- ----AA----------A---- ----AA--------AAA---- ------AAAABAAA------- --------------------- --------------------- --------------------- --------------------- --------------------- --------------------- --------------------- --------------------- --------------------- 
---AAA----------AA--- ---AAAA---------A---- ---AAAAAAAAAAAAAA---- -----AAAAAAAAA------- -----AAAAAAAAA------- -----AAAAAAAAA------- -----AAAAAAAAA------- -----AAAAAAAAA------- -----AAAAAAAAA------- ------AAAAABAA------- --------------------- --------------------- --------------------- 
---AAA----------A---- ---AAAA------AAAA---- ---AAAA-----AAAA----- -----AA-----AAAA----- -----AA-----AAAA----- -----AA-----AAAA----- -----AA-----AAAA----- -----AA-----AAAA----- -----AAAAAAAAAA------ ------AABBBAAA------- --------------------- --------------------- --------------------- 
---AAA----------A---- ---AA---------AAA---- ---AA---------AAA---- ----A---------AAA---- ----A---------AAA---- ----A---------AAA---- ----A---------AAA---- ----A---------AAA---- ----AAAAAAAAAAAAA---- -----AAAAAAAAAAA----- -------BAAAAA-------- ---------BA---------- --------------------- 
---AA----------AAA--- ---A-----------AAA--- ---A-----------AAA--- ---A-----------AAA--- ---A-----------AAA--- ---A-----------AAA--- ---A-----------AAA--- ---A-----------AAA--- ---AAAAAAAAAAAAAA---- ----AAAAAAAAAAAAA---- ----AAAAAAAAAAA------ -------ABBBAA-------- --------------------- 
--AA-----------AAAA-- --A--------------AA-- --A------------AAAA-- --A------------AAAA-- --A------------AAAA-- --A------------AAAA-- --A------------AAAA-- --A------------AAA--- ---AAAAAAAAAAAAAAA--- ---AAAAAAAAAAAAAAA--- ----AAAAAAAAAAAAA---- ----AAAAAAABAA------- --------------------- 
-AAA-------------AAA- -AA--------------AAA- -AA--------------AAA- -AA--------------AAA- -A---------------AAA- -A---------------AA-- --A--------------AA-- --A--------------AA-- --AAAABAAAAABAAAAAA-- ---AAAAAAAAAAAAAAA--- ---AAAAAAAAAAAAAAA--- ----AAAAAAAAAAAAA---- ------AAAA----------- 
-AAA-------------AAA- -A---------------AAA- -A---------------AAA- -A---------------AAA- -A---------------AAA- -A---------------AAA- -A---------------AAA- -A---------------AA-- --AAAAABAAABAAAAAAA-- --AAAAAAAAAAAAAAAAA-- ---AAAAAAAAAAAAAAA--- ----AAAAAAAAAAAAAA--- -----AAABBBBAA------- 
AAA---------------AAA AA---------------AAAA AA----------------AAA AA---------------AAAA -A---------------AAA- -A---------------AAA- -A---------------AAA- -A---------------AAA- --AAAAAABABAAAAAAAA-- --AAAAAAAAAAAAAAAAA-- ---AAAAAAAAAAAAAAA--- ----AAAAAAAAAAAAAA--- -----ABBAAAABBAAA---- 
AAA---------------AAA AA---------------AAAA AA----------------AAA AA---------------AAAA AA---------------AAAA AA---------------AAA- -A---------------AAA- -A---------------AAA- -AAAAAAAABAAAAAAAAAA- --AAAAAAAAAAAAAAAAA-- ---AAAAAAAAAAAAAAA--- ----AAAAAAAAAAAAAA--- -----AAAAAAAAAAAA---- 
AAA---------------AAA AA---------------AAAA AA----------------AAA AA---------------AAAA AA---------------AAAA AA---------------AAAA AA---------------AAA- -A---------------AAA- -AAAAAAABABAAAAAAAAA- --AAAAAAAAAAAAAAAAA-- ---AAAAAAAAAAAAAAAA-- ----AAAAAAAAAAAAAA--- -----AAABBBBAAAAA---- 
AAA---------------AAA AA---------------AAAA AA----------------AAA AA---------------AAAA AA---------------AAAA AA---------------AAAA AA---------------AAAA -A---------------AAA- -AAAAAABAAABAAAAAAAA- --AAAAAAAAAAAAAAAAA-- ----AAAAAAAAAAAAAAA-- ----AAAAAAAAAAAAAA--- ------AAAABAAAA------ 
AAAA--------------AAA AAA--------------AAAA AAA---------------AAA AAA--------------AAAA AAA--------------AAAA AAA--------------AAAA -AA--------------AAAA -AA--------------AAAA -AAAAABAAAAABAAAAAAA- --AAAAAAAAAAAAAAAAAA- ----AAAAAAAAAAAAAAA-- ----AAAABBBBBBAAAA--- ------AB------------- 
AAAA-------------AAAA AAA-------------AAAAA AAA--------------AAAA AAA--------------AAAA AAA--------------AAAA -AA--------------AAAA -AA--------------AAAA -AA--------------AAAA -AAAAAAAAAAAAAAAAAAA- --AAAAAAAAAAAAAAAAAA- ----AAAAAAAAAAAAAAA-- -----AAAAAAAAAAAAA--- --------------------- 
AAAAA-----------AAAAA AAA------------AAAAAA AAA--------------AAAA AAA--------------AAAA -AA--------------AAAA -AA--------------AAAA -AA--------------AAAA --A--------------AAAA --AAAAAAAAAAAAAAAAAA- ---AAAAAAAAAAAAAAAAA- ----AAAAAAAAAAAAAAA-- -----AAABAAABAAAA---- --------------------- 
-AAAA-----------AAAA- -AA-----------AAAAAA- -AA------------AAAAA- -AA------------AAAAA- -AA------------AAAAA- -AA------------AAAAA- --A------------AAAAA- --A------------AAAAA- --AAAAAAAAAAAAAAAAA-- ---AAAAAAAAAAAAAAAA-- ----AAAAAAABBAAAAA--- -----AAABBB---A------ --------------------- 
-AAAAA----------AAAA- -AAAA---------AAAAAA- -AAAAA-A-A-A-A-AAAAA- -AAAA---------AAAAAA- -AAAA---------AAAAAA- --AAAA--------AAAAAA- --AAAAAAAAAAAAAAAAAA- --AAAAAAAAA-AAAAAAA-- ---AAAAAAAAAAAAAAA--- ---AAAAAAAAAAAAAA---- ----AAAABAAABA------- -----AAA------------- --------------------- 
--AAAAA---------AAA-- --AAAAAAAAAAAAAAAAA-- --AAAAAAAAAAAAAAAAA-- --AAAAAAAAAAAAAAAAA-- --AAAAAAAAAAAAAAAAA-- --AAAAAAAAAAAAAAAAA-- --AAAAAAAAAAAAAAAAA-- ---AAAAAAAAAAAAAAA--- ---AAAAAAAAAAABAA---- ----AAAAAAAAAAA------ -----AAAAAAAAA------- --------------------- --------------------- 
---AAAAAAA-----AAA--- ---AAAAAAAAAAAAAAA--- ---AAAAAAAAAAAAAAA--- ---AAAAAAAAAAAAAA---- ---AAAAAAAAAAAAAA---- ---AAAAAAAAAAAAA-A--- ---AAAAAAAAAAAAA-A--- ---AAAAAAAAAAAAA----- ----AAAAAAAAAB------- ----AAAAAAAAAA------- -----AAAAA----------- --------------------- --------------------- 
----AAAAAAA---AAA---- ----AAAAAAAAAAAAA---- ----AAAAAAAAAAAAA---- ----AAAAAAAAAAAA----- ----AAAAAAAAAAAA----- ----AAAAAAAAAAA------ ----AAAAAAAAAA------- ----AAAAAAAAAA------- ----AABBAAAAA-------- -----AAAAAAAA-------- --------------------- --------------------- --------------------- 
-----AAAAAAAAAAA----- -----AAAAAAAAAA------ -----ABAAAAAAAB------ -----AAAAAAAAAA------ -----AAAAAAAAAA------ -----AAAAAAAAA------- -----AAAABAAA-------- -------ABAAAB-------- --------------------- --------------------- --------------------- --------------------- --------------------- 
-------AAAAAAA------- -------AAAAAAA------- -------BAAAAAB------- --------BAAAB-------- --------ABABA-------- --------AABA--------- -----------B--------- --------------------- --------------------- --------------------- --------------------- --------------------- --------------------- 
