model
size = 22 17 22, scale = 0.05, origin = -y
material 
  colors = A:#FFF B:#0052FF C:#008FFF D:#00B1FF E:#0039FF F:#EA00FF G:#B80CFF H:#890CFF I:#750CFF J:#5E0CFF K:#0078FF L:#4100FF M:#0063FF N:#0028FF
voxels
---------AAAA--------- ---------------------- ---------------------- ---------------------- ---------------------- ---------------------- ---------------------- ---------------------- ---------------------- ---------------------- ---------------------- ---------------------- ---------------------- ---------------------- ---------------------- ---------------------- ---------------------- 
-------AAAAAAAA------- ---------------------- ---------------------- ---------------------- ---------------------- ---------------------- ---------------------- ---------------------- ---------------------- ---------------------- ---------------------- ---------------------- ---------------------- ---------------------- ---------------------- ---------------------- ---------------------- 
-----AAAAAAAAAAAA----- ---------------------- ---------------------- ---------------------- ---------------------- ---------------------- ---------------------- ---------------------- ---------------------- ---------------------- ---------------------- ---------------------- ---------------------- ---------------------- ---------------------- ---------------------- ---------------------- 
----AAAAAAAAAAAAAA---- ---------FEEF--------- ---------FEEF--------- ---------FEEF--------- ---------FEEF--------- ---------FEEF--------- ---------FEEF--------- ---------FEEF--------- ---------FEEF--------- ---------FEEF--------- ---------FEEF--------- ---------FEEF--------- ---------FEEF--------- ---------FEEF--------- ---------FEEF--------- ---------FEEF--------- ---------FEEF--------- 
---AAAAAAAAAAAAAAAA--- -------BBAAAABB------- -------GBAAAABG------- -------GBAAAABG------- -------GBAAAABG------- -------GBAAAABG------- -------GBAAAABG------- -------GBAAAABG------- -------GBAAAABG------- -------GBAAAABG------- -------GBAAAABG------- -------GBAAAABG------- -------GBAAAABG------- -------GBAAAABG------- -------GBAAAABG------- -------GBAAAABG------- -------BBAAAABB------- 
--AAAAAAAAAAAAAAAAAA-- ------MAAAAAAAAM------ ------MAAAAAAAAM------ ------HAAAAAAAAH------ ------HAAAAAAAAH------ ------HAAAAAAAAH------ ------HAAAAAAAAH------ ------HAAAAAAAAH------ ------HAAAAAAAAH------ ------HAAAAAAAAH------ ------HAAAAAAAAH------ ------HAAAAAAAAH------ ------HAAAAAAAAH------ ------HAAAAAAAAH------ ------HAAAAAAAAH------ ------MAAAAAAAAM------ ------MAAAAAAAAM------ 
--AAAAAA------AAAAAA-- -----KAA------AAK----- -----KAAAAAAAAAAK----- -----KAAAAAAAAAAK----- -----IAAAAAAAAAAI----- -----IAAAAAAAAAAI----- -----IAAA----AAAI----- -----IAAAAAAAAAAI----- -----IAAAAAAAAAAI----- -----IAAAAAAAAAAI----- -----IAAAAAAAAAAI----- -----IAAAAAAAAAAI----- -----IAAAAAAAAAAI----- -----IAAAAAAAAAAI----- -----KAAAAAAAAAAK----- -----KAAAAAAAAAAK----- -----KAABAAAABAAK----- 
-AAAAA----------AAAAA- ----CAA--------AAC---- ----CAAA------AAAC---- ----CAAA------AAAC---- ----CAAA------AAAC---- ----JAA-AAAAAA-AAJ---- ----JAAAAAAAAAAAAJ---- ----JAAAAAAAAAAAAJ---- ----JAAAAAAAAAAAAJ---- ----JAAAAAAAAAAAAJ---- ----JAAAAAAAAAAAAJ---- ----JAAAAAAAAAAAAJ---- ----JAAAAAAAAAAAAJ---- ----CAAAAAAAAAAAAC---- ----CAAAAAAAAAAAAC---- ----CAAAAAAAAAAAAC---- ----CAAABAAAABAAAC---- 
-AAAAA----------AAAAA- ----CAA--------AAC---- ----CAA--------AAC---- ----CAA--------AAC---- ----CAA--------AAC---- ----CAA--------AAC---- ----CA-A------A-AC---- ----CAAAAAAAAAAAAC---- ----CAAAAAAAAAAAAC---- ----CAAAAAAAAAAAAC---- ----CAAAAAAAAAAAAC---- ----CAAAAAAAAAAAAC---- ----CAAAAAAAAAAAAC---- ----CAAAAAAAAAAAAC---- ----CAAAAAAAAAAAAC---- ----CAAAAAAAAAAAAC---- ----CAABBBBBBBBAAC---- 
AAAAA------------AAAAA ---DAAA--------AAAD--- ---DAAA--------AAAD--- ---DAAA--------AAAD--- ---DAAA--------AAAD--- ---DAAA--------AAAD--- ---LAAA--------AAAL--- ---LAAAAAAAAAAAAAAL--- ---LAAAAAAAAAAAAAAL--- ---LAAAAAAAAAAAAAAL--- ---LAAAAAAAAAAAAAAL--- ---LAAAAAAAAAAAAAAL--- ---DAAAAAAAAAAAAAAD--- ---DAAAAAAAAAAAAAAD--- ---DAAAAAAAAAAAAAAD--- ---DAAAAAAAAAAAAAAD--- ---DAAABBBBBBBBAAAD--- 
AAAAA------------AAAAA ---DAA----------AAD--- ---DAA----------AAD--- ---DAA----------AAD--- ---DAA----------AAD--- ---DAA----------AAD--- ---DAAA--------AAAD--- ---NAAAAAAAAAAAAAAN--- ---NAAAAAAAAAAAAAAN--- ---NAAAAAAAAAAAAAAN--- ---NAAAAAAAAAAAAAAN--- ---DAAAAAAAAAAAAAAD--- ---DAAAAAAAAAAAAAAD--- ---DAAAAAAAAAAAAAAD--- ---DAAAAAAAAAAAAAAD--- ---DAAAAAAAAAAAAAAD--- ---DAAAABBBBBBAAAAD--- 
AAAAA------------AAAAA ---DAA----------AAD--- ---DAA----------AAD--- ---DAA----------AAD--- ---DAA----------AAD--- ---DAA----------AAD--- ---DAAA--------AAAD--- ---NAAAAAAAAAAAAAAN--- ---NAAAAAAAAAAAAAAN--- ---NAAAAAAAAAAAAAAN--- ---NAAAAAAAAAAAAAAN--- ---DAAAAAAAAAAAAAAD--- ---DAAAAAAAAAAAAAAD--- ---DAAAAAAAAAAAAAAD--- ---DAAAAAAAAAAAAAAD--- ---DAAAAAAAAAAAAAAD--- ---DAAAAAAAAAAAAAAD--- 
AAAAA------------AAAAA ---DAAA--------AAAD--- ---DAAA--------AAAD--- ---DAAA--------AAAD--- ---DAAA--------AAAD--- ---DAAA--------AAAD--- ---LAAA--------AAAL--- ---LAAAAAAAAAAAAAAL--- ---LAAAAAAAAAAAAAAL--- ---LAAAAAAAAAAAAAAL--- ---LAAAAAAAAAAAAAAL--- ---LAAAAAAAAAAAAAAL--- ---DAAAAAAAAAAAAAAD--- ---DAAAAAAAAAAAAAAD--- ---DAAAAAAAAAAAAAAD--- ---DAAAAAAAAAAAAAAD--- ---DAAAEAEEEEAEAAAD--- 
-AAAAA----------AAAAA- ----CAA--------AAC---- ----CAA--------AAC---- ----CAA--------AAC---- ----CAA--------AAC---- ----CAA--------AAC---- ----CA-A------A-AC---- ----CAAAAAAAAAAAAC---- ----CAAAAAAAAAAAAC---- ----CAAAAAAAAAAAAC---- ----CAAAAAAAAAAAAC---- ----CAAAAAAAAAAAAC---- ----CAAAAAAAAAAAAC---- ----CAAAAAAAAAAAAC---- ----CAAAAAAAAAAAAC---- ----CAAAAAAAAAAAAC---- ----CAAEAEEEEAEAAC---- 
-AAAAA----------AAAAA- ----CAA--------AAC---- ----CAAA------AAAC---- ----CAAA------AAAC---- ----CAAA------AAAC---- ----JAA-AAAAAA-AAJ---- ----JAAAAAAAAAAAAJ---- ----JAAAAAAAAAAAAJ---- ----JAAAAAAAAAAAAJ---- ----JAAAAAAAAAAAAJ---- ----JAAAAAAAAAAAAJ---- ----JAAAAAAAAAAAAJ---- ----JAAAAAAAAAAAAJ---- ----CAAAAAAAAAAAAC---- ----CAAAAAAAAAAAAC---- ----CAAAAAAAAAAAAC---- ----CAAEEEEEEEEAAC---- 
--AAAAAA------AAAAAA-- -----KAA------AAK----- -----KAAAAAAAAAAK----- -----KAAAAAAAAAAK----- -----IAAAAAAAAAAI----- -----IAAAAAAAAAAI----- -----IAAA----AAAI----- -----IAAAAAAAAAAI----- -----IAAAAAAAAAAI----- -----IAAAAAAAAAAI----- -----IAAAAAAAAAAI----- -----IAAAAAAAAAAI----- -----IAAAAAAAAAAI----- -----IAAAAAAAAAAI----- -----KAAAAAAAAAAK----- -----KAAAAAAAAAAK----- -----KAAAAAAAAAAK----- 
--AAAAAAAAAAAAAAAAAA-- ------MAAAAAAAAM------ ------MAAAAAAAAM------ ------HAAAAAAAAH------ ------HAAAAAAAAH------ ------HAAAAAAAAH------ ------HAAAAAAAAH------ ------HAAAAAAAAH------ ------HAAAAAAAAH------ ------HAAAAAAAAH------ ------HAAAAAAAAH------ ------HAAAAAAAAH------ ------HAAAAAAAAH------ ------HAAAAAAAAH------ ------HAAAAAAAAH------ ------MAAAAAAAAM------ ------MAAAAAAAAM------ 
---AAAAAAAAAAAAAAAA--- -------BBAAAABB------- -------GBAAAABG------- -------GBAAAABG------- -------GBAAAABG------- -------GBAAAABG------- -------GBAAAABG------- -------GBAAAABG------- -------GBAAAABG------- -------GBAAAABG------- -------GBAAAABG------- -------GBAAAABG------- -------GBAAAABG------- -------GBAAAABG------- -------GBAAAABG------- -------GBAAAABG------- -------BBAAAABB------- 
----AAAAAAAAAAAAAA---- ---------FEEF--------- ---------FEEF--------- ---------FEEF--------- ---------FEEF--------- ---------FEEF--------- ---------FEEF--------- ---------FEEF--------- ---------FEEF--------- ---------FEEF--------- ---------FEEF--------- ---------FEEF--------- ---------FEEF--------- ---------FEEF--------- ---------FEEF--------- ---------FEEF--------- ---------FEEF--------- 
-----AAAAAAAAAAAA----- ---------------------- ---------------------- ---------------------- ---------------------- ---------------------- ---------------------- ---------------------- ---------------------- ---------------------- ---------------------- ---------------------- ---------------------- ---------------------- ---------------------- ---------------------- ---------------------- 
-------AAAAAAAA------- ---------------------- ---------------------- ---------------------- ---------------------- ---------------------- ---------------------- ---------------------- ---------------------- ---------------------- ---------------------- ---------------------- ---------------------- ---------------------- ---------------------- ---------------------- ---------------------- 
---------AAAA--------- ---------------------- ---------------------- ---------------------- ---------------------- ---------------------- ---------------------- ---------------------- ---------------------- ---------------------- ---------------------- ---------------------- ---------------------- ---------------------- ---------------------- ---------------------- ---------------------- 
