model
size = 22 17 23, scale = 0.05, origin = -y
material 
  colors = A:#FFF B:#0063FF C:#008FFF D:#0039FF E:#00C3FF F:#00F5FF G:#00B1FF
voxels
---------AAAA--------- ---------------------- ---------------------- ---------------------- ---------------------- ---------------------- ---------------------- ---------------------- ---------------------- ---------------------- ---------------------- ---------------------- ---------------------- ---------------------- ---------------------- ---------------------- ---------------------- 
-------AAAAAAAA------- ---------------------- ---------------------- ---------------------- ---------------------- ---------------------- ---------------------- ---------------------- ---------------------- ---------------------- ---------------------- ---------------------- ---------------------- ---------------------- ---------------------- ---------------------- ---------------------- 
-----AAAAAAAAAAAA----- ---------------------- ---------------------- ---------------------- ---------------------- ---------------------- ---------------------- ---------------------- ---------------------- ---------------------- ---------------------- ---------------------- ---------------------- ---------------------- ---------------------- ---------------------- ---------------------- 
----AAAAAAAAAAAAAA---- ---------FFFF--------- ---------AAAA--------- ---------EEEE--------- ---------AAAA--------- ---------CCCC--------- ---------AAAA--------- ---------BBBB--------- ---------AAAA--------- ---------DDDD--------- ---------AAAA--------- ---------BBBB--------- ---------AAAA--------- ---------BBBB--------- ---------AAAA--------- ---------CCCC--------- ---------AAAA--------- 
---AAAAAAAAAAAAAAAA--- -------FFFFFFFF------- -------AAAAAAAA------- -------EEEEEEEE------- -------AAAAAAAA------- -------CCCCCCCC------- -------AAAAAAAA------- -------BBBBBBBB------- -------AAAAAAAA------- -------DDDDDDDD------- -------AAAAAAAA------- -------BBBBBBBB------- -------AAAAAAAA------- -------BBBBBBBB------- -------AAAAAAAA------- -------CCCCCCCC------- -------AAAAAAAA------- 
--AAAAAAAAAAAAAAAAAA-- ------FFFFFFFFFF------ ------AAAAAAAAAA------ ------EEEEEEEEEE------ ------AAAAAAAAAA------ ------CCCCCCCCCC------ ------AAAAAAAAAA------ ------BBBBBBBBBB------ ------AAAAAAAAAA------ ------DDDDDDDDDD------ ------AAAAAAAAAA------ ------BBBBBBBBBB------ ------AAAAAAAAAA------ ------BBBBBBBBBB------ ------AAAAAAAAAA------ ------CCCCCCCCCC------ ------AAAAAAAAAA------ 
--AAAAAA------AAAAAA-- -----FFF------FFF----- -----AAAAAAAAAAAA----- -----EEEEEEEEEEEE----- -----AAAAAAAAAAAA----- -----CCCCCCCCCCCC----- -----AAAA----AAAA----- -----BBBBBBBBBBBB----- -----AAAAAAAAAAAA----- -----DDDDDDDDDDDD----- -----AAAAAAAAAAAA----- -----BBBBBBBBBBBB----- -----AAAAAAAAAAAA----- -----BBBBBBBBBBBB----- -----AAAAAAAAAAAA----- -----CCCCCCCCCCCC----- -----AAABAAAABAAA----- 
-AAAAA----------AAAAA- ----FFF--------FFF---- ----AAAA------AAAA---- ----EEEE------EEEE---- ----AAAA------AAAA---- ----CCC-CCCCCC-CCC---- ----AAAAAAAAAAAAAA---- ----BBBBBBBBBBBBBB---- ----AAAAAAAAAAAAAA---- ----DDDDDDDDDDDDDD---- ----AAAAAAAAAAAAAA---- ----BBBBBBBBBBBBBB---- ----AAAAAAAAAAAAAA---- ----BBBBBBBBBBBBBB---- ----AAAAAAAAAAAAAA---- ----CCCCCCCCCCCCCC---- ----AAAABAAAABAAAA---- 
-AAAAA----------AAAAA- ----FFF--------FFF---- ----AAA--------AAA---- ----EEE--------EEE---- ----AAA--------AAA---- ----CCC--------CCC---- ----AA-A------A-AA---- ----BBBBBBBBBBBBBB---- ----AAAAAAAAAAAAAA---- ----DDDDDDDDDDDDDD---- ----AAAAAAAAAAAAAA---- ----BBBBBBBBBBBBBB---- ----AAAAAAAAAAAAAA---- ----BBBBBBBBBBBBBB---- ----AAAAAAAAAAAAAA---- ----CCCCCCCCCCCCCC---- ----AAABBBBBBBBAAA---- 
AAAAA------------AAAAA ---FFFF--------FFFF--- ---AAAA--------AAAA--- ---EEEE--------EEEE--- ---AAAA--------AAAA--- ---CCCC--------CCCC--- ---AAAA--------AAAA--- ---BBBBBBBBBBBBBBBB--- ---AAAAAAAAAAAAAAAA--- ---DDDDDDDDDDDDDDDD--- ---AAAAAAAAAAAAAAAA--- ---BBBBBBBBBBBBBBBB--- ---AAAAAAAAAAAAAAAA--- ---BBBBBBBBBBBBBBBB--- ---AAAAAAAAAAAAAAAA--- ---CCCCCCCCCCCCCCCC--- ---AAAABBBBBBBBAAAA--- 
AAAAA------------AAAAA ---FFF----------FFF--- ---AAA----------AAA--- ---EEE----------EEE--- ---AAA----------AAA--- ---CCC----------CCC--- ---AAAA--------AAAA--- ---BBBBBBBBBBBBBBBB--- ---AAAAAAAAAAAAAAAA--- ---DDDDDDDDDDDDDDDD--- ---AAAAAAAAAAAAAAAA--- ---BBBBBBBBBBBBBBBB--- ---AAAAAAAAAAAAAAAA--- ---BBBBBBBBBBBBBBBB--- ---AAAAAAAAAAAAAAAA--- ---CCCCCCCCCCCCCCCC--- ---AAAAABBBBBBAAAAA--- 
AAAAA------------AAAAA ---FFF----------FFF--- ---AAA----------AAA--- ---EEE----------EEE--- ---AAA----------AAA--- ---CCC----------CCC--- ---AAAA--------AAAA--- ---BBBBBBBBBBBBBBBB--- ---AAAAAAAAAAAAAAAA--- ---DDDDDDDDDDDDDDDD--- ---AAAAAAAAAAAAAAAA--- ---BBBBBBBBBBBBBBBB--- ---AAAAAAAAAAAAAAAA--- ---BBBBBBBBBBBBBBBB--- ---AAAAAAAAAAAAAAAA--- ---CCCCCCCCCCCCCCCC--- ---AAAAAAAAAAAAAAAA--- 
AAAAA------------AAAAA ---FFF----------FFF--- ---AAA----------AAA--- ---EEE----------EEE--- ---AAA----------AAA--- ---CCC----------CCC--- ---AAAA--------AAAA--- ---BBBBBBBBBBBBBBBB--- ---AAAAAAAAAAAAAAAA--- ---DDDDDDDDDDDDDDDD--- ---AAAAAAAAAAAAAAAA--- ---BBBBBBBBBBBBBBBB--- ---AAAAAAAAAAAAAAAA--- ---BBBBBBBBBBBBBBBB--- ---AAAAAAAAAAAAAAAA--- ---CCCCCCCCCCCCCCCC--- ---AAAAGAGGGGAGAAAA--- 
AAAAAA----------AAAAAA ----FF----------FF---- ----AA----------AA---- ----EE----------EE---- ----AA----------AA---- ----CC----------CC---- ----AAA--------AAA---- ----BBBBBBBBBBBBBB---- ----AAAAAAAAAAAAAA---- ----DDDDDDDDDDDDDD---- ----AAAAAAAAAAAAAA---- ----BBBBBBBBBBBBBB---- ----AAAAAAAAAAAAAA---- ----BBBBBBBBBBBBBB---- ----AAAAAAAAAAAAAA---- ----CCCCCCCCCCCCCC---- ----AAAGAGGGGAGAAA---- 
-AAAAA----------AAAAA- ----FF----------FF---- ----AA----------AA---- ----EE----------EE---- ----AA----------AA---- ----CCC--------CCC---- ----AAA--------AAA---- ----BBBBBBBBBBBBBB---- ----AAAAAAAAAAAAAA---- ----DDDDDDDDDDDDDD---- ----AAAAAAAAAAAAAA---- ----BBBBBBBBBBBBBB---- ----AAAAAAAAAAAAAA---- ----BBBBBBBBBBBBBB---- ----AAAAAAAAAAAAAA---- ----CCCCCCCCCCCCCC---- ----AAAGGGGGGGGAAA---- 
-AAAAAA--------AAAAAA- ----FFF--------FFF---- ----AAA--------AAA---- ----EEE--------EEE---- ----AAA--------AAA---- ----CCC--------CCC---- ----AAAA------AAAA---- ----BBBBBBBBBBBBBB---- ----AAAAAAAAAAAAAA---- ----DDDDDDDDDDDDDD---- ----AAAAAAAAAAAAAA---- ----BBBBBBBBBBBBBB---- ----AAAAAAAAAAAAAA---- ----BBBBBBBBBBBBBB---- ----AAAAAAAAAAAAAA---- ----CCCCCCCCCCCCCC---- ----AAAAAAAAAAAAAA---- 
-AAAAAAA------AAAAAAA- -----FFFFFFFFFFFF----- -----AAAAAAAAAAAA----- -----EEEEEEEEEEEE----- -----AAAA----AAAA----- -----CCC------CCC----- -----AAAA----AAAA----- -----BBBBBBBBBBBB----- -----AAAAAAAAAAAA----- -----DDDDDDDDDDDD----- -----AAAAAAAAAAAA----- -----BBBBBBBBBBBB----- -----AAAAAAAAAAAA----- -----BBBBBBBBBBBB----- -----AAAAAAAAAAAA----- -----CCCCCCCCCCCC----- -----AAAAAAAAAAAA----- 
--AAAAAAAAAAAAAAAAAA-- ------FFF----FFF------ ------AAAAAAAAAA------ ------EEEEEEEEEE------ ------AAAAAAAAAA------ ------CCCCCCCCCC------ ------AAAAAAAAAA------ ------BBBBBBBBBB------ ------AAAAAAAAAA------ ------DDDDDDDDDD------ ------AAAAAAAAAA------ ------BBBBBBBBBB------ ------AAAAAAAAAA------ ------BBBBBBBBBB------ ------AAAAAAAAAA------ ------CCCCCCCCCC------ ------AAAAAAAAAA------ 
---AAAAAAAAAAAAAAAA--- --------FFFFFF-------- --------AAAAAA-------- --------EEEEEE-------- --------AAAAAA-------- --------CCCCCC-------- --------AAAAAA-------- --------BBBBBB-------- --------AAAAAA-------- --------DDDDDD-------- --------AAAAAA-------- --------BBBBBB-------- --------AAAAAA-------- --------BBBBBB-------- --------AAAAAA-------- --------CCCCCC-------- --------AAAAAA-------- 
----AAAAAAAAAAAAAA---- ---------------------- ---------------------- ---------------------- ---------------------- ---------------------- ---------------------- ---------------------- ---------------------- ---------------------- ---------------------- ---------------------- ---------------------- ---------------------- ---------------------- ---------------------- ---------------------- 
-----AAAAAAAAAAAA----- ---------------------- ---------------------- ---------------------- ---------------------- ---------------------- ---------------------- ---------------------- ---------------------- ---------------------- ---------------------- ---------------------- ---------------------- ---------------------- ---------------------- ---------------------- ---------------------- 
-------AAAAAAAA------- ---------------------- ---------------------- ---------------------- ---------------------- ---------------------- ---------------------- ---------------------- ---------------------- ---------------------- ---------------------- ---------------------- ---------------------- ---------------------- ---------------------- ---------------------- ---------------------- 
---------AAAA--------- ---------------------- ---------------------- ---------------------- ---------------------- ---------------------- ---------------------- ---------------------- ---------------------- ---------------------- ---------------------- ---------------------- ---------------------- ---------------------- ---------------------- ---------------------- ---------------------- 
