model
size = 22 17 23, scale = 0.05, origin = -y
material 
  colors = A:#FFF B:#B80CFF C:#890CFF D:#5E0CFF E:#750CFF F:#0063FF G:#0052FF H:#0039FF I:#0028FF J:#4100FF K:#EA00FF L:#0078FF M:#00DFFF N:#00C3FF O:#008FFF P:#00B1FF Q:#00F5FF
voxels
---------AAAA--------- ---------------------- ---------------------- ---------------------- ---------------------- ---------------------- ---------------------- ---------------------- ---------------------- ---------------------- ---------------------- ---------------------- ---------------------- ---------------------- ---------------------- ---------------------- ---------------------- 
-------AAAAAAAA------- ---------------------- ---------------------- ---------------------- ---------------------- ---------------------- ---------------------- ---------------------- ---------------------- ---------------------- ---------------------- ---------------------- ---------------------- ---------------------- ---------------------- ---------------------- ---------------------- 
-----AAAAAAAAAAAA----- ---------------------- ---------------------- ---------------------- ---------------------- ---------------------- ---------------------- ---------------------- ---------------------- ---------------------- ---------------------- ---------------------- ---------------------- ---------------------- ---------------------- ---------------------- ---------------------- 
----AAAAAAAAAAAAAA---- ---------QQQQ--------- ---------MMMM--------- ---------NNNN--------- ---------PPPP--------- ---------OOOO--------- ---------LLLL--------- ---------FFFF--------- ---------GGGG--------- ---------HHHH--------- ---------IIII--------- ---------JJJJ--------- ---------DDDD--------- ---------EEEE--------- ---------CCCC--------- ---------BBBB--------- ---------KKKK--------- 
---AAAAAAAAAAAAAAAA--- -------QQQQQQQQ------- -------MMMMMMMM------- -------NNNNNNNN------- -------PPPPPPPP------- -------OOOOOOOO------- -------LLLLLLLL------- -------FFFFFFFF------- -------GGGGGGGG------- -------HHHHHHHH------- -------IIIIIIII------- -------JJJJJJJJ------- -------DDDDDDDD------- -------EEEEEEEE------- -------CCCCCCCC------- -------BBBBBBBB------- -------KKKKKKKK------- 
--AAAAAAAAAAAAAAAAAA-- ------QQQQQQQQQQ------ ------MMMMMMMMMM------ ------NNNNNNNNNN------ ------PPPPPPPPPP------ ------OOOOOOOOOO------ ------LLLLLLLLLL------ ------FFFFFFFFFF------ ------GGGGGGGGGG------ ------HHHHHHHHHH------ ------IIIIIIIIII------ ------JJJJJJJJJJ------ ------DDDDDDDDDD------ ------EEEEEEEEEE------ ------CCCCCCCCCC------ ------BBBBBBBBBB------ ------KKKKKKKKKK------ 
--AAAAAA------AAAAAA-- -----QQQ------QQQ----- -----MMMMMMMMMMMM----- -----NNNNNNNNNNNN----- -----PPPPPPPPPPPP----- -----OOOOOOOOOOOO----- -----LLLL----LLLL----- -----FFFFFFFFFFFF----- -----GGGGGGGGGGGG----- -----HHHHHHHHHHHH----- -----IIIIIIIIIIII----- -----JJJJJJJJJJJJ----- -----DDDDDDDDDDDD----- -----EEEEEEEEEEEE----- -----CCCCCCCCCCCC----- -----BBBBBBBBBBBB----- -----KKKAKKKKAKKK----- 
-AAAAA----------AAAAA- ----QQQ--------QQQ---- ----MMMM------MMMM---- ----NNNN------NNNN---- ----PPPP------PPPP---- ----OOO-OOOOOO-OOO---- ----LLLLLLLLLLLLLL---- ----FFFFFFFFFFFFFF---- ----GGGGGGGGGGGGGG---- ----HHHHHHHHHHHHHH---- ----IIIIIIIIIIIIII---- ----JJJJJJJJJJJJJJ---- ----DDDDDDDDDDDDDD---- ----EEEEEEEEEEEEEE---- ----CCCCCCCCCCCCCC---- ----BBBBBBBBBBBBBB---- ----KKKKAKKKKAKKKK---- 
-AAAAA----------AAAAA- ----QQQ--------QQQ---- ----MMM--------MMM---- ----NNN--------NNN---- ----PPP--------PPP---- ----OOO--------OOO---- ----LL-L------L-LL---- ----FFFFFFFFFFFFFF---- ----GGGGGGGGGGGGGG---- ----HHHHHHHHHHHHHH---- ----IIIIIIIIIIIIII---- ----JJJJJJJJJJJJJJ---- ----DDDDDDDDDDDDDD---- ----EEEEEEEEEEEEEE---- ----CCCCCCCCCCCCCC---- ----BBBBBBBBBBBBBB---- ----KKKAAAAAAAAKKK---- 
AAAAA------------AAAAA ---QQQQ--------QQQQ--- ---MMMM--------MMMM--- ---NNNN--------NNNN--- ---PPPP--------PPPP--- ---OOOO--------OOOO--- ---LLLL--------LLLL--- ---FFFFFFFFFFFFFFFF--- ---GGGGGGGGGGGGGGGG--- ---HHHHHHHHHHHHHHHH--- ---IIIIIIIIIIIIIIII--- ---JJJJJJJJJJJJJJJJ--- ---DDDDDDDDDDDDDDDD--- ---EEEEEEEEEEEEEEEE--- ---CCCCCCCCCCCCCCCC--- ---BBBBBBBBBBBBBBBB--- ---KKKKAAAAAAAAKKKK--- 
AAAAA------------AAAAA ---QQQ----------QQQ--- ---MMM----------MMM--- ---NNN----------NNN--- ---PPP----------PPP--- ---OOO----------OOO--- ---LLLL--------LLLL--- ---FFFFFFFFFFFFFFFF--- ---GGGGGGGGGGGGGGGG--- ---HHHHHHHHHHHHHHHH--- ---IIIIIIIIIIIIIIII--- ---JJJJJJJJJJJJJJJJ--- ---DDDDDDDDDDDDDDDD--- ---EEEEEEEEEEEEEEEE--- ---CCCCCCCCCCCCCCCC--- ---BBBBBBBBBBBBBBBB--- ---KKKKKAAAAAAKKKKK--- 
AAAAA------------AAAAA ---QQQ----------QQQ--- ---MMM----------MMM--- ---NNN----------NNN--- ---PPP----------PPP--- ---OOO----------OOO--- ---LLLL--------LLLL--- ---FFFFFFFFFFFFFFFF--- ---GGGGGGGGGGGGGGGG--- ---HHHHHHHHHHHHHHHH--- ---IIIIIIIIIIIIIIII--- ---JJJJJJJJJJJJJJJJ--- ---DDDDDDDDDDDDDDDD--- ---EEEEEEEEEEEEEEEE--- ---CCCCCCCCCCCCCCCC--- ---BBBBBBBBBBBBBBBB--- ---KKKKKKKKKKKKKKKK--- 
AAAAA------------AAAAA ---QQQ----------QQQ--- ---MMM----------MMM--- ---NNN----------NNN--- ---PPP----------PPP--- ---OOO----------OOO--- ---LLLL--------LLLL--- ---FFFFFFFFFFFFFFFF--- ---GGGGGGGGGGGGGGGG--- ---HHHHHHHHHHHHHHHH--- ---IIIIIIIIIIIIIIII--- ---JJJJJJJJJJJJJJJJ--- ---DDDDDDDDDDDDDDDD--- ---EEEEEEEEEEEEEEEE--- ---CCCCCCCCCCCCCCCC--- ---BBBBBBBBBBBBBBBB--- ---KKKKAKAAAAKAKKKK--- 
AAAAAA----------AAAAAA ----QQ----------QQ---- ----MM----------MM---- ----NN----------NN---- ----PP----------PP---- ----OO----------OO---- ----LLL--------LLL---- ----FFFFFFFFFFFFFF---- ----GGGGGGGGGGGGGG---- ----HHHHHHHHHHHHHH---- ----IIIIIIIIIIIIII---- ----JJJJJJJJJJJJJJ---- ----DDDDDDDDDDDDDD---- ----EEEEEEEEEEEEEE---- ----CCCCCCCCCCCCCC---- ----BBBBBBBBBBBBBB---- ----KKKAKAAAAKAKKK---- 
-AAAAA----------AAAAA- ----QQ----------QQ---- ----MM----------MM---- ----NN----------NN---- ----PP----------PP---- ----OOO--------OOO---- ----LLL--------LLL---- ----FFFFFFFFFFFFFF---- ----GGGGGGGGGGGGGG---- ----HHHHHHHHHHHHHH---- ----IIIIIIIIIIIIII---- ----JJJJJJJJJJJJJJ---- ----DDDDDDDDDDDDDD---- ----EEEEEEEEEEEEEE---- ----CCCCCCCCCCCCCC---- ----BBBBBBBBBBBBBB---- ----KKKAAAAAAAAKKK---- 
-AAAAAA--------AAAAAA- ----QQQ--------QQQ---- ----MMM--------MMM---- ----NNN--------NNN---- ----PPP--------PPP---- ----OOO--------OOO---- ----LLLL------LLLL---- ----FFFFFFFFFFFFFF---- ----GGGGGGGGGGGGGG---- ----HHHHHHHHHHHHHH---- ----IIIIIIIIIIIIII---- ----JJJJJJJJJJJJJJ---- ----DDDDDDDDDDDDDD---- ----EEEEEEEEEEEEEE---- ----CCCCCCCCCCCCCC---- ----BBBBBBBBBBBBBB---- ----KKKKKKKKKKKKKK---- 
-AAAAAAA------AAAAAAA- -----QQQQQQQQQQQQ----- -----MMMMMMMMMMMM----- -----NNNNNNNNNNNN----- -----PPPP----PPPP----- -----OOO------OOO----- -----LLLL----LLLL----- -----FFFFFFFFFFFF----- -----GGGGGGGGGGGG----- -----HHHHHHHHHHHH----- -----IIIIIIIIIIII----- -----JJJJJJJJJJJJ----- -----DDDDDDDDDDDD----- -----EEEEEEEEEEEE----- -----CCCCCCCCCCCC----- -----BBBBBBBBBBBB----- -----KKKKKKKKKKKK----- 
--AAAAAAAAAAAAAAAAAA-- ------QQQ----QQQ------ ------MMMMMMMMMM------ ------NNNNNNNNNN------ ------PPPPPPPPPP------ ------OOOOOOOOOO------ ------LLLLLLLLLL------ ------FFFFFFFFFF------ ------GGGGGGGGGG------ ------HHHHHHHHHH------ ------IIIIIIIIII------ ------JJJJJJJJJJ------ ------DDDDDDDDDD------ ------EEEEEEEEEE------ ------CCCCCCCCCC------ ------BBBBBBBBBB------ ------KKKKKKKKKK------ 
---AAAAAAAAAAAAAAAA--- --------QQQQQQ-------- --------MMMMMM-------- --------NNNNNN-------- --------PPPPPP-------- --------OOOOOO-------- --------LLLLLL-------- --------FFFFFF-------- --------GGGGGG-------- --------HHHHHH-------- --------IIIIII-------- --------JJJJJJ-------- --------DDDDDD-------- --------EEEEEE-------- --------CCCCCC-------- --------BBBBBB-------- --------KKKKKK-------- 
----AAAAAAAAAAAAAA---- ---------------------- ---------------------- ---------------------- ---------------------- ---------------------- ---------------------- ---------------------- ---------------------- ---------------------- ---------------------- ---------------------- ---------------------- ---------------------- ---------------------- ---------------------- ---------------------- 
-----AAAAAAAAAAAA----- ---------------------- ---------------------- ---------------------- ---------------------- ---------------------- ---------------------- ---------------------- ---------------------- ---------------------- ---------------------- ---------------------- ---------------------- ---------------------- ---------------------- ---------------------- ---------------------- 
-------AAAAAAAA------- ---------------------- ---------------------- ---------------------- ---------------------- ---------------------- ---------------------- ---------------------- ---------------------- ---------------------- ---------------------- ---------------------- ---------------------- ---------------------- ---------------------- ---------------------- ---------------------- 
---------AAAA--------- ---------------------- ---------------------- ---------------------- ---------------------- ---------------------- ---------------------- ---------------------- ---------------------- ---------------------- ---------------------- ---------------------- ---------------------- ---------------------- ---------------------- ---------------------- ---------------------- 
