model
size = 26 31 26, scale = 0.05, origin = -y
material 
  colors = A:#1A1A1A B:#434343 C:#00FF15 D:#777
voxels
----------AAAAAA---------- ----------CAACAC---------- ----------AAACAC---------- ----------AAACCA---------- ----------AAACAC---------- ----------CAACCC---------- ----------AAAAAA---------- -------------------------- -------------------------- -------------------------- -------------------------- -------------------------- -------------------------- -------------------------- -------------------------- -------------------------- -------------------------- -------------------------- -------------------------- -------------------------- -------------------------- -------------------------- -------------------------- -------------------------- -------------------------- -------------------------- -------------------------- -------------------------- -------------------------- -------------------------- -------------------------- 
-------AAAAAAAAAAAA------- -------ACCAAAAAAAAA------- -------ACAAAAAAAAAA------- -------ACAAAAAAAAAC------- -------ACAAAAAAAAAC------- -------ACCAAAAAAAAC------- -------AAAAAAAAAAAA------- -----------BCBB----------- -----------CBCB----------- -----------BBBC----------- -------------------------- -------------------------- -------------------------- -------------------------- -------------------------- -------------------------- -------------------------- -------------------------- -------------------------- -------------------------- -------------------------- -------------------------- -------------------------- -------------------------- -------------------------- -------------------------- -------------------------- -------------------------- -------------------------- -------------------------- -------------------------- 
------AAAA------AAAA------ ------AAAA------AAAC------ ------AAAA------AAAC------ ------AAAA------AAAC------ ------AAAA------AAAA------ ------AAAA------AAAA------ ------AAAA------AAAA------ --------CBB----BCB-------- --------BCB----CBC-------- --------BBC----BBB-------- --------AAAAAAAAAA-------- ---------AAAAAAAA--------- -----------BCBB----------- -----------CBCB----------- -----------BBBC----------- -------------------------- -------------------------- -------------------------- -------------------------- -------------------------- -------------------------- -------------------------- -------------------------- -------------------------- -------------------------- -------------------------- -------------------------- -------------------------- -------------------------- -------------------------- -------------------------- 
-----AA------------AA----- -----AA------------AA----- -----AA------------AA----- -----AA------------AC----- -----AA------------AC----- -----AA------------AC----- -----AAA----------AAA----- ------BB----------BB------ ------BC----------BC------ ------CB----------CB------ -------AA--------AA------- -------AAA------AAA------- --------CBBB--BBCB-------- --------BCBB--BCBC-------- --------BBCB--BBBB-------- ----------AAAAAA---------- -------------------------- -------------------------- -------------------------- -------------------------- -------------------------- -------------------------- -------------------------- -------------------------- -------------------------- -------------------------- -------------------------- -------------------------- -------------------------- -------------------------- -------------------------- 
----AA--------------AA---- ----AA--------------AA---- ----BA--------------AA---- ----AA--------------AA---- ----AA--------------AA---- ----AA--------------AA---- ----AA--------------AA---- -----B--------------C----- -----C--------------B----- -----B--------------B----- -----AA------------AA----- ------AA----------AA------ -------BB--------BB------- -------CB--------BB------- -------BB--------BC------- --------AA------AA-------- ---------AAAAAAAA--------- ---------BCBBBCBB--------- -------------------------- -------------------------- -------------------------- -------------------------- -------------------------- -------------------------- -------------------------- -------------------------- -------------------------- -------------------------- -------------------------- -------------------------- -------------------------- 
---AA----------------AA--- ---AA----------------AA--- ---BA----------------AA--- ---AA----------------AA--- ---AA----------------AA--- ---AA----------------AA--- ---AA----------------AA--- ----C----------------B---- ----B----------------C---- ----B----------------B---- ----AA--------------AA---- -----A--------------A----- -----BB------------BC----- -----CB------------CB----- -----BC------------BB----- ------AA----------AA------ -------AAA------AAA------- --------BABBBBBBABB------- ---------CBCBCBCB--------- -------------------------- -------------------------- -------------------------- -------------------------- -------------------------- -------------------------- -------------------------- -------------------------- -------------------------- -------------------------- -------------------------- -------------------------- 
--AA------------------AA-- --AA------------------AC-- --BA------------------AC-- --AA------------------AC-- --AA------------------AC-- --AA------------------AC-- --AA------------------AA-- ---B------------------B--- ---C------------------B--- ---B------------------C--- ----A----------------A---- ----A----------------A---- -----C--------------B----- -----B--------------C----- -----B--------------B----- -----AA------------AA----- ------AA----------AA------ ------CBBB------BBBC------ --------BB------BC-------- ----------BBCBBB---------- ----------AAAAAA---------- -------------------------- -------------------------- -------------------------- -------------------------- -------------------------- -------------------------- -------------------------- -------------------------- -------------------------- -------------------------- 
-AA--------------------AA- -AA--------------------AA- -BA--------------------AA- -AA--------------------AC- -AA--------------------AA- -AA--------------------AC- -AAA------------------AAA- ---B------------------B--- ---B------------------C--- ---C------------------B--- ---A------------------A--- ---AA----------------AA--- ----B----------------B---- ----C----------------B---- ----B----------------C---- -----A--------------A----- -----AA------------AA----- ------BBB--------BBBB----- -------CB--------BB------- --------BCBB--BBCB-------- --------AAAA--AAAA-------- -----------AAAA----------- -------------------------- -------------------------- -------------------------- -------------------------- -------------------------- -------------------------- -------------------------- -------------------------- -------------------------- 
-AA--------------------AA- -AA--------------------AA- -AA--------------------AA- -AA--------------------AC- -AA--------------------AC- -AA--------------------AC- -AA--------------------AA- --B--------------------C-- --C--------------------B-- --B--------------------B-- --AA------------------AA-- ---A------------------A--- ---BB----------------BB--- ---BB----------------BC--- ---CB----------------BB--- ----A----------------A---- -----A--------------A----- -----BBB----------BBB----- ------BB----------BC------ -------BBB------BBB------- -------AAB------AAA------- ---------AACBBCAA--------- -------------------------- -------------------------- -----------AAAA----------- -----------AAAC----------- -----------BAAA----------- -----------AAAA----------- -------------------------- -------------------------- -------------------------- 
-AA--------------------AA- -AA--------------------AA- -AA--------------------AA- -AA--------------------AA- -AA--------------------AA- -AA--------------------AA- -AA--------------------AA- --C--------------------B-- --B--------------------C-- --B--------------------B-- --A--------------------A-- --AA------------------AA-- ---B------------------C--- ---C------------------B--- ---B------------------B--- ----A----------------A---- ----AA--------------AA---- ----BAB------------BAB---- -----CB------------BB----- -------CB--------BC------- -------AA--------BA------- --------ACBBBBBBCA-------- ------------AB------------ ----------AAAAAA---------- ----------AAAAAA---------- ---------AAAAAAAA--------- ---------AAAAAAAA--------- ----------AAAAAA---------- ----------AAAAAA---------- ------------AB------------ -------------------------- 
AA----------------------AA AA----------------------AA AA----------------------AA AA---------------------AAA AA---------------------AAA AA---------------------AAA AA----------------------AA --B--------------------B-- --C--------------------B-- --B--------------------C-- --A--------------------A-- --A--------------------A-- ---C------------------B--- ---B------------------C--- ---B------------------B--- ---A------------------A--- ----A----------------A---- ----CB--------------BB---- -----B--------------C----- ------BB----------BB------ ------AA----------AA------ --------ABB----BBA-------- ----------AAAAAA---------- ---------BAAAAAAA--------- ---------AAAAAAAA--------- ---------AAAAAAAA--------- ---------AAAAAAAA--------- ---------AAAAAAAB--------- ---------AAAAAAAA--------- ----------CAAAAA---------- -------------------------- 
AA----------------------AA CA----------------------AA CA----------------------AA CA---------------------BAA AA---------------------BAA CA---------------------BAC AA----------------------AA -B----------------------B- -B----------------------C- -C----------------------B- --A--------------------A-- --A--------------------A-- --BB------------------BB-- --CB------------------BB-- --BB------------------BC-- ---A------------------A--- ----A----------------A---- ----BB--------------BC---- -----C--------------B----- ------BB----------BB------ ------AA----------AA------ -------ACB------BCA------- ----------AAAAAA---------- ---------AAAAAAAC--------- --------AAAAAAAAAA-------- --------AAAAAAAAAA-------- --------AAAAAAAAAA-------- --------BAAAAAAAAA-------- ---------AAAAAAAA--------- ----------AAAAAA---------- -----------AABA----------- 
AA----------------------AA CA----------------------AC AA----------------------AC CA---------------------BAC AA---------------------DAC CA---------------------BAC AA----------------------AA -B----------------------C- -C----------------------B- -B----------------------B- --A--------------------A-- --A--------------------A-- --B--------------------B-- --B--------------------C-- --C--------------------B-- ---A------------------A--- ----A----------------A---- ----BB--------------BB---- -----B--------------C----- ------C------------B------ ------A------------A------ -------ABB------BBA------- ---------AAAAAAAA--------- ---------AAAAAAAA--------- --------AAAAAAAAAA-------- --------AAAAAAAAAB-------- --------AAAAAAAAAA-------- --------AAAAAAAAAA-------- ---------AAAAAAAA--------- ---------AAAAAAAA--------- -----------AAAA----------- 
AA----------------------AA CA----------------------AA AA----------------------AA CA---------------------BAA CA---------------------DAA CA---------------------BAC AA----------------------AA -C----------------------B- -B----------------------C- -B----------------------B- --A--------------------A-- --A--------------------A-- --B--------------------C-- --C--------------------B-- --B--------------------B-- ---A------------------A--- ----A----------------A---- ----BB--------------BB---- -----C--------------B----- ------B------------C------ ------A------------A------ -------ABB------BBA------- ---------AAAAAAAA--------- ---------BAAAAAAA--------- --------AAAAAAAAAA-------- --------AAAAAAAAAA-------- --------AAAAAAAAAA-------- --------AAAAAAAAAA-------- ---------AAAAAAAA--------- ---------AAAAAAAC--------- -----------AAAA----------- 
AA----------------------AA AA----------------------AA AA----------------------AA AA---------------------BAA AA---------------------DAA AA---------------------BAA AA----------------------AA -B----------------------B- -C----------------------B- -B----------------------C- --A--------------------A-- --A--------------------A-- --CB------------------BB-- --BB------------------BC-- --BB------------------BB-- ---A------------------A--- ----A----------------A---- ----CB--------------BB---- -----B--------------C----- ------BB----------BB------ ------AA----------BA------ -------ACB------BCA------- ----------AAAABB---------- ---------AAAAAAAA--------- --------AAAAAAAAAA-------- --------AAAAAAAAAA-------- --------CAAAAAAAAB-------- --------AAAAAAAAAA-------- ---------BAAAAAAA--------- ----------AAAAAA---------- -----------BACA----------- 
AA----------------------AA AA----------------------AA AA----------------------AA AA---------------------BAA AA---------------------BAA AA---------------------BAA AA----------------------AA --B--------------------B-- --B--------------------C-- --C--------------------B-- --A--------------------A-- --A--------------------A-- ---B------------------B--- ---C------------------B--- ---B------------------C--- ---A------------------A--- ----A----------------A---- ----BB--------------BC---- -----C--------------B----- ------BB----------BB------ ------AA----------AA------ --------ABB----BBA-------- ----------AAAAAA---------- ---------AAAAAAAA--------- ---------AAAAAAAA--------- ---------AAAAAAAA--------- ---------AAAAAAAA--------- ---------AAAAAAAA--------- ---------AAAAAAAA--------- ----------AAAAAA---------- -------------------------- 
-AA--------------------AA- -CA--------------------AC- -AA--------------------AC- -AA--------------------AC- -AA--------------------AC- -AA--------------------AC- -AA--------------------AA- --B--------------------C-- --C--------------------B-- --B--------------------B-- --A--------------------A-- --AA------------------AA-- ---B------------------B--- ---B------------------C--- ---C------------------B--- ----A----------------A---- ----AA--------------AA---- ----BAB------------BAB---- -----BB------------BC----- -------CB--------BC------- -------AA--------AA------- --------ACBBBBBBCA-------- ------------AA------------ ----------BAAAAA---------- ----------AAAAAB---------- ---------AAAAAAAA--------- ---------BAAAAAAA--------- ----------AAAAAA---------- ----------AABAAB---------- ------------AA------------ -------------------------- 
-AA--------------------AA- -CA--------------------AC- -AA--------------------AA- -AA--------------------AA- -AA--------------------AA- -AA--------------------AC- -AA--------------------AA- --C--------------------B-- --B--------------------C-- --B--------------------B-- --AA------------------AA-- ---A------------------A--- ---BB----------------BC--- ---CB----------------BB--- ---BB----------------BB--- ----A----------------A---- -----A--------------A----- -----BBB----------BBB----- ------CB----------BB------ -------BBB------BBB------- -------AAA------AAA------- ---------AACBBCAA--------- -------------------------- -------------------------- -----------AAAA----------- -----------ACAA----------- -----------AAAA----------- -----------AAAA----------- -------------------------- -------------------------- -------------------------- 
-AA--------------------AA- -CA--------------------AC- -CA--------------------AC- -CA--------------------AC- -CA--------------------AC- -CA--------------------AC- -AAA------------------AAA- ---B------------------B--- ---C------------------B--- ---B------------------C--- ---A------------------A--- ---AB----------------AA--- ----C----------------B---- ----B----------------C---- ----B----------------B---- -----A--------------A----- -----AB------------AA----- ------BBB--------BBBC----- -------BB--------BC------- --------BCBB--BBCB-------- --------AAAA--AAAA-------- -----------AAAA----------- -------------------------- -------------------------- -------------------------- -------------------------- -------------------------- -------------------------- -------------------------- -------------------------- -------------------------- 
--AA------------------AA-- --AA------------------AA-- --AA------------------AA-- --AA------------------AA-- --AA------------------AA-- --AA------------------AA-- --AA------------------AA-- ---B------------------B--- ---B------------------C--- ---C------------------B--- ----A----------------A---- ----A----------------A---- -----B--------------B----- -----C--------------B----- -----B--------------C----- -----AA------------AA----- ------AA----------AA------ ------CBBB------BBBB------ --------CB------BB-------- ----------BBBCBB---------- ----------AAAAAA---------- -------------------------- -------------------------- -------------------------- -------------------------- -------------------------- -------------------------- -------------------------- -------------------------- -------------------------- -------------------------- 
---AA----------------AA--- ---AA----------------AA--- ---AA----------------AA--- ---AA----------------AA--- ---AA----------------AA--- ---AA----------------AA--- ---AA----------------AA--- ----B----------------C---- ----C----------------B---- ----B----------------B---- ----AA--------------AA---- -----A--------------A----- -----BB------------CB----- -----BC------------BC----- -----CB------------BB----- ------AA----------AA------ -------AAA------AAA------- --------BABBBBBBABB------- ---------BCBCBCBC--------- -------------------------- -------------------------- -------------------------- -------------------------- -------------------------- -------------------------- -------------------------- -------------------------- -------------------------- -------------------------- -------------------------- -------------------------- 
----AA--------------AA---- ----CA--------------AA---- ----AA--------------AC---- ----AA--------------AC---- ----AA--------------AC---- ----CA--------------AC---- ----AA--------------AA---- -----C--------------B----- -----B--------------C----- -----B--------------B----- -----AA------------AA----- ------AA----------AA------ -------CB--------BB------- -------BB--------BC------- -------BB--------BB------- --------AA------AA-------- ---------AAAAAAAA--------- ---------BBCBBBCB--------- -------------------------- -------------------------- -------------------------- -------------------------- -------------------------- -------------------------- -------------------------- -------------------------- -------------------------- -------------------------- -------------------------- -------------------------- -------------------------- 
-----AA------------AA----- -----CA------------AC----- -----AA------------AA----- -----CA------------AA----- -----AA------------AA----- -----CA------------AA----- -----AAA----------AAA----- ------BB----------BB------ ------CB----------CB------ ------BC----------BC------ -------AA--------AA------- -------AAA------AAA------- --------BBBB--BCBB-------- --------CBCB--BBCB-------- --------BCBB--BBBC-------- ----------AAAAAA---------- -------------------------- -------------------------- -------------------------- -------------------------- -------------------------- -------------------------- -------------------------- -------------------------- -------------------------- -------------------------- -------------------------- -------------------------- -------------------------- -------------------------- -------------------------- 
------AAAA------AAAA------ ------CAAA------AAAA------ ------CAAA------AAAC------ ------CAAA------AAAC------ ------CAAA------AAAC------ ------CAAA------AAAC------ ------AAAA------AAAA------ --------BCB----BBC-------- --------CBC----BCB-------- --------BBB----CBB-------- --------AAAAAAAAAA-------- ---------AAAAAAAA--------- -----------CBBB----------- -----------BCBC----------- -----------BBCB----------- -------------------------- -------------------------- -------------------------- -------------------------- -------------------------- -------------------------- -------------------------- -------------------------- -------------------------- -------------------------- -------------------------- -------------------------- -------------------------- -------------------------- -------------------------- -------------------------- 
-------AAAAAAAAAAAA------- -------AACAAAAAACAA------- -------AACAAAAAACAA------- -------AAAAAAAAACAA------- -------AACAAAAAACAA------- -------AACAAAAAACAA------- -------AAAAAAAAAAAA------- -----------BBCB----------- -----------BCBC----------- -----------CBBB----------- -------------------------- -------------------------- -------------------------- -------------------------- -------------------------- -------------------------- -------------------------- -------------------------- -------------------------- -------------------------- -------------------------- -------------------------- -------------------------- -------------------------- -------------------------- -------------------------- -------------------------- -------------------------- -------------------------- -------------------------- -------------------------- 
----------AAAAAA---------- ----------ACAACC---------- ----------ACAACA---------- ----------CAAACA---------- ----------ACAACA---------- ----------ACAACC---------- ----------AAAAAA---------- -------------------------- -------------------------- -------------------------- -------------------------- -------------------------- -------------------------- -------------------------- -------------------------- -------------------------- -------------------------- -------------------------- -------------------------- -------------------------- -------------------------- -------------------------- -------------------------- -------------------------- -------------------------- -------------------------- -------------------------- -------------------------- -------------------------- -------------------------- -------------------------- 
