model
size = 26 31 26, scale = 0.05, origin = -y
material 
  colors = A:#020835 B:#B3006E C:#BBA5FF D:#BCA5FF
voxels
----------AAAAAA---------- ----------CAACAC---------- ----------AAACAC---------- ----------AAACCA---------- ----------AAACAC---------- ----------CAACCC---------- ----------AAAAAA---------- -------------------------- -------------------------- -------------------------- -------------------------- -------------------------- -------------------------- -------------------------- -------------------------- -------------------------- -------------------------- -------------------------- -------------------------- -------------------------- -------------------------- -------------------------- -------------------------- -------------------------- -------------------------- -------------------------- -------------------------- -------------------------- -------------------------- -------------------------- -------------------------- 
-------AAAAAAAAAAAA------- -------ACCAAAAAAAAA------- -------ACAAAAAAAAAA------- -------ACAAAAAAAAAC------- -------ACAAAAAAAAAC------- -------ACCAAAAAAAAC------- -------AAAAAAAAAAAA------- -----------BCBB----------- -----------CBCB----------- -----------BBBC----------- -------------------------- -------------------------- -------------------------- -------------------------- -------------------------- -------------------------- -------------------------- -------------------------- -------------------------- -------------------------- -------------------------- -------------------------- -------------------------- -------------------------- -------------------------- -------------------------- -------------------------- -------------------------- -------------------------- -------------------------- -------------------------- 
------AAAA------AAAA------ ------AAAA------AAAC------ ------AAAA------AAAC------ ------AAAA------AAAC------ ------AAAA------AAAA------ ------AAAA------AAAA------ ------AAAA------AAAA------ --------CBB----BCB-------- --------BCB----CBC-------- --------BBC----BBB-------- --------AAAAAAAAAA-------- ---------AAAAAAAA--------- -----------DADD----------- -----------ADAD----------- -----------DDDA----------- -------------------------- -------------------------- -------------------------- -------------------------- -------------------------- -------------------------- -------------------------- -------------------------- -------------------------- -------------------------- -------------------------- -------------------------- -------------------------- -------------------------- -------------------------- -------------------------- 
-----AA------------AA----- -----AA------------AA----- -----AA------------AA----- -----AA------------AC----- -----AA------------AC----- -----AA------------AC----- -----AAA----------AAA----- ------BB----------BB------ ------BC----------BC------ ------CB----------CB------ -------AA--------AA------- -------AAA------AAA------- --------ADDC--CDAD-------- --------DADC--CADA-------- --------DDAC--CDDD-------- ----------AAAAAA---------- -------------------------- -------------------------- -------------------------- -------------------------- -------------------------- -------------------------- -------------------------- -------------------------- -------------------------- -------------------------- -------------------------- -------------------------- -------------------------- -------------------------- -------------------------- 
----AA--------------AA---- ----AA--------------AA---- ----BA--------------AA---- ----AA--------------AA---- ----AA--------------AA---- ----AA--------------AA---- ----AA--------------AA---- -----B--------------C----- -----C--------------B----- -----B--------------B----- -----AA------------AA----- ------AA----------AA------ -------DC--------CD------- -------AC--------CD------- -------DC--------CA------- --------AA------AA-------- ---------AAAAAAAA--------- ---------BDBBBDBB--------- -------------------------- -------------------------- -------------------------- -------------------------- -------------------------- -------------------------- -------------------------- -------------------------- -------------------------- -------------------------- -------------------------- -------------------------- -------------------------- 
---AA----------------AA--- ---AA----------------AA--- ---BA----------------AA--- ---AA----------------AA--- ---AA----------------AA--- ---AA----------------AA--- ---AA----------------AA--- ----C----------------B---- ----B----------------C---- ----B----------------B---- ----AA--------------AA---- -----A--------------A----- -----DD------------DA----- -----AD------------AD----- -----DA------------DD----- ------AA----------AA------ -------AAA------AAA------- --------BABBBBBBABB------- ---------DBDBDBDB--------- -------------------------- -------------------------- -------------------------- -------------------------- -------------------------- -------------------------- -------------------------- -------------------------- -------------------------- -------------------------- -------------------------- -------------------------- 
--AA------------------AA-- --AA------------------AC-- --BA------------------AC-- --AA------------------AC-- --AA------------------AC-- --AA------------------AC-- --AA------------------AA-- ---B------------------B--- ---C------------------B--- ---B------------------C--- ----A----------------A---- ----A----------------A---- -----A--------------D----- -----D--------------A----- -----D--------------D----- -----AA------------AA----- ------AA----------AA------ ------DBBB------BBBD------ --------BB------BD-------- ----------BBDBBB---------- ----------AAAAAA---------- -------------------------- -------------------------- -------------------------- -------------------------- -------------------------- -------------------------- -------------------------- -------------------------- -------------------------- -------------------------- 
-AA--------------------AA- -AA--------------------AA- -BA--------------------AA- -AA--------------------AC- -AA--------------------AA- -AA--------------------AC- -AAA------------------AAA- ---B------------------B--- ---B------------------C--- ---C------------------B--- ---A------------------A--- ---AA----------------AA--- ----D----------------D---- ----A----------------D---- ----D----------------A---- -----A--------------A----- -----AA------------AA----- ------BBB--------BBBB----- -------DB--------BB------- --------BDBB--BBDB-------- --------AAAA--AAAA-------- -----------AAAA----------- -------------------------- -------------------------- -------------------------- -------------------------- -------------------------- -------------------------- -------------------------- -------------------------- -------------------------- 
-AA--------------------AA- -AA--------------------AA- -AA--------------------AA- -AA--------------------AC- -AA--------------------AC- -AA--------------------AC- -AA--------------------AA- --B--------------------C-- --C--------------------B-- --B--------------------B-- --AA------------------AA-- ---A------------------A--- ---DC----------------CD--- ---DC----------------CA--- ---AC----------------CD--- ----A----------------A---- -----A--------------A----- -----BBB----------BBB----- ------BB----------BD------ -------BBB------BBB------- -------AAB------AAA------- ---------AACBBCAA--------- -------------------------- -------------------------- -----------AAAA----------- -----------AAAC----------- -----------BAAA----------- -----------AAAA----------- -------------------------- -------------------------- -------------------------- 
-AA--------------------AA- -AA--------------------AA- -AA--------------------AA- -AA--------------------AA- -AA--------------------AA- -AA--------------------AA- -AA--------------------AA- --C--------------------B-- --B--------------------C-- --B--------------------B-- --A--------------------A-- --AA------------------AA-- ---D------------------A--- ---A------------------D--- ---D------------------D--- ----A----------------A---- ----AA--------------AA---- ----BAB------------BAB---- -----DB------------BB----- -------DB--------BD------- -------AA--------BA------- --------ACBBBBBBCA-------- ------------AB------------ ----------AAAAAA---------- ----------AAAAAA---------- ---------AAAAAAAA--------- ---------AAAAAAAA--------- ----------AAAAAA---------- ----------AAAAAA---------- ------------AB------------ -------------------------- 
AA----------------------AA AA----------------------AA AA----------------------AA AA---------------------AAA AA---------------------AAA AA---------------------AAA AA----------------------AA --B--------------------B-- --C--------------------B-- --B--------------------C-- --A--------------------A-- --A--------------------A-- ---A------------------D--- ---D------------------A--- ---D------------------D--- ---A------------------A--- ----A----------------A---- ----DB--------------BB---- -----B--------------D----- ------BB----------BB------ ------AA----------AA------ --------ABB----BBA-------- ----------AAAAAA---------- ---------BAAAAAAA--------- ---------AAAAAAAA--------- ---------AAAAAAAA--------- ---------AAAAAAAA--------- ---------AAAAAAAB--------- ---------AAAAAAAA--------- ----------CAAAAA---------- -------------------------- 
AA----------------------AA CA----------------------AA CA----------------------AA CA---------------------BAA AA---------------------BAA CA---------------------BAC AA----------------------AA -B----------------------B- -B----------------------C- -C----------------------B- --A--------------------A-- --A--------------------A-- --DC------------------CD-- --AC------------------CD-- --DC------------------CA-- ---A------------------A--- ----A----------------A---- ----BB--------------BD---- -----D--------------B----- ------BB----------BB------ ------AA----------AA------ -------ACB------BCA------- ----------AAAAAA---------- ---------AAAAAAAC--------- --------AAAAAAAAAA-------- --------AAAAAAAAAA-------- --------AAAAAAAAAA-------- --------BAAAAAAAAA-------- ---------AAAAAAAA--------- ----------AAAAAA---------- -----------AABA----------- 
AA----------------------AA CA----------------------AC AA----------------------AC CA---------------------BAC AA---------------------CAC CA---------------------BAC AA----------------------AA -B----------------------C- -C----------------------B- -B----------------------B- --A--------------------A-- --A--------------------A-- --D--------------------D-- --D--------------------A-- --A--------------------D-- ---A------------------A--- ----A----------------A---- ----BB--------------BB---- -----B--------------D----- ------D------------B------ ------A------------A------ -------ABB------BBA------- ---------AAAAAAAA--------- ---------AAAAAAAA--------- --------AAAAAAAAAA-------- --------AAAAAAAAAB-------- --------AAAAAAAAAA-------- --------AAAAAAAAAA-------- ---------AAAAAAAA--------- ---------AAAAAAAA--------- -----------AAAA----------- 
AA----------------------AA CA----------------------AA AA----------------------AA CA---------------------BAA CA---------------------CAA CA---------------------BAC AA----------------------AA -C----------------------B- -B----------------------C- -B----------------------B- --A--------------------A-- --A--------------------A-- --D--------------------A-- --A--------------------D-- --D--------------------D-- ---A------------------A--- ----A----------------A---- ----BB--------------BB---- -----D--------------B----- ------B------------D------ ------A------------A------ -------ABB------BBA------- ---------AAAAAAAA--------- ---------BAAAAAAA--------- --------AAAAAAAAAA-------- --------AAAAAAAAAA-------- --------AAAAAAAAAA-------- --------AAAAAAAAAA-------- ---------AAAAAAAA--------- ---------AAAAAAAC--------- -----------AAAA----------- 
AA----------------------AA AA----------------------AA AA----------------------AA AA---------------------BAA AA---------------------CAA AA---------------------BAA AA----------------------AA -B----------------------B- -C----------------------B- -B----------------------C- --A--------------------A-- --A--------------------A-- --AC------------------CD-- --DC------------------CA-- --DC------------------CD-- ---A------------------A--- ----A----------------A---- ----DB--------------BB---- -----B--------------D----- ------BB----------BB------ ------AA----------BA------ -------ACB------BCA------- ----------AAAABB---------- ---------AAAAAAAA--------- --------AAAAAAAAAA-------- --------AAAAAAAAAA-------- --------CAAAAAAAAB-------- --------AAAAAAAAAA-------- ---------BAAAAAAA--------- ----------AAAAAA---------- -----------BACA----------- 
AA----------------------AA AA----------------------AA AA----------------------AA AA---------------------BAA AA---------------------BAA AA---------------------BAA AA----------------------AA --B--------------------B-- --B--------------------C-- --C--------------------B-- --A--------------------A-- --A--------------------A-- ---D------------------D--- ---A------------------D--- ---D------------------A--- ---A------------------A--- ----A----------------A---- ----BB--------------BD---- -----D--------------B----- ------BB----------BB------ ------AA----------AA------ --------ABB----BBA-------- ----------AAAAAA---------- ---------AAAAAAAA--------- ---------AAAAAAAA--------- ---------AAAAAAAA--------- ---------AAAAAAAA--------- ---------AAAAAAAA--------- ---------AAAAAAAA--------- ----------AAAAAA---------- -------------------------- 
-AA--------------------AA- -CA--------------------AC- -AA--------------------AC- -AA--------------------AC- -AA--------------------AC- -AA--------------------AC- -AA--------------------AA- --B--------------------C-- --C--------------------B-- --B--------------------B-- --A--------------------A-- --AA------------------AA-- ---D------------------D--- ---D------------------A--- ---A------------------D--- ----A----------------A---- ----AA--------------AA---- ----BAB------------BAB---- -----BB------------BD----- -------DB--------BD------- -------AA--------AA------- --------ACBBBBBBCA-------- ------------AA------------ ----------BAAAAA---------- ----------AAAAAB---------- ---------AAAAAAAA--------- ---------BAAAAAAA--------- ----------AAAAAA---------- ----------AABAAB---------- ------------AA------------ -------------------------- 
-AA--------------------AA- -CA--------------------AC- -AA--------------------AA- -AA--------------------AA- -AA--------------------AA- -AA--------------------AC- -AA--------------------AA- --C--------------------B-- --B--------------------C-- --B--------------------B-- --AA------------------AA-- ---A------------------A--- ---DC----------------CA--- ---AC----------------CD--- ---DC----------------CD--- ----A----------------A---- -----A--------------A----- -----BBB----------BBB----- ------DB----------BB------ -------BBB------BBB------- -------AAA------AAA------- ---------AACBBCAA--------- -------------------------- -------------------------- -----------AAAA----------- -----------ACAA----------- -----------AAAA----------- -----------AAAA----------- -------------------------- -------------------------- -------------------------- 
-AA--------------------AA- -CA--------------------AC- -CA--------------------AC- -CA--------------------AC- -CA--------------------AC- -CA--------------------AC- -AAA------------------AAA- ---B------------------B--- ---C------------------B--- ---B------------------C--- ---A------------------A--- ---AA----------------AA--- ----A----------------D---- ----D----------------A---- ----D----------------D---- -----A--------------A----- -----AB------------AA----- ------BBB--------BBBB----- -------BB--------BD------- --------BDBB--BBDB-------- --------AAAA--AAAA-------- -----------AAAA----------- -------------------------- -------------------------- -------------------------- -------------------------- -------------------------- -------------------------- -------------------------- -------------------------- -------------------------- 
--AA------------------AA-- --AA------------------AA-- --AA------------------AA-- --AA------------------AA-- --AA------------------AA-- --AA------------------AA-- --AA------------------AA-- ---B------------------B--- ---B------------------C--- ---C------------------B--- ----A----------------A---- ----A----------------A---- -----D--------------D----- -----A--------------D----- -----D--------------A----- -----AA------------AA----- ------AA----------AA------ ------DBBB------BBBD------ --------DB------BB-------- ----------BBBDBB---------- ----------AAAAAA---------- -------------------------- -------------------------- -------------------------- -------------------------- -------------------------- -------------------------- -------------------------- -------------------------- -------------------------- -------------------------- 
---AA----------------AA--- ---AA----------------AA--- ---AA----------------AA--- ---AA----------------AA--- ---AA----------------AA--- ---AA----------------AA--- ---AA----------------AA--- ----B----------------C---- ----C----------------B---- ----B----------------B---- ----AA--------------AA---- -----A--------------A----- -----DD------------AD----- -----DA------------DA----- -----AD------------DD----- ------AA----------AA------ -------AAA------AAA------- --------BABBBBBBABB------- ---------BDBDBDBD--------- -------------------------- -------------------------- -------------------------- -------------------------- -------------------------- -------------------------- -------------------------- -------------------------- -------------------------- -------------------------- -------------------------- -------------------------- 
----AA--------------AA---- ----CA--------------AA---- ----AA--------------AC---- ----AA--------------AC---- ----AA--------------AC---- ----CA--------------AC---- ----AA--------------AA---- -----C--------------B----- -----B--------------C----- -----B--------------B----- -----AA------------AA----- ------AA----------AA------ -------AC--------CD------- -------DC--------CA------- -------DC--------CD------- --------AA------AA-------- ---------AAAAAAAA--------- ---------BBDBBBDB--------- -------------------------- -------------------------- -------------------------- -------------------------- -------------------------- -------------------------- -------------------------- -------------------------- -------------------------- -------------------------- -------------------------- -------------------------- -------------------------- 
-----AA------------AA----- -----CA------------AC----- -----AA------------AA----- -----CA------------AA----- -----AA------------AA----- -----CA------------AA----- -----AAA----------AAA----- ------BB----------BB------ ------CB----------CB------ ------BC----------BC------ -------AA--------AA------- -------AAA------AAA------- --------DDDC--CADD-------- --------ADAC--CDAD-------- --------DADC--CDDA-------- ----------AAAAAA---------- -------------------------- -------------------------- -------------------------- -------------------------- -------------------------- -------------------------- -------------------------- -------------------------- -------------------------- -------------------------- -------------------------- -------------------------- -------------------------- -------------------------- -------------------------- 
------AAAA------AAAA------ ------CAAA------AAAA------ ------CAAA------AAAC------ ------CAAA------AAAC------ ------CAAA------AAAC------ ------CAAA------AAAC------ ------AAAA------AAAA------ --------BCB----BBC-------- --------CBC----BCB-------- --------BBB----CBB-------- --------AAAAAAAAAA-------- ---------AAAAAAAA--------- -----------ADDD----------- -----------DADA----------- -----------DDAD----------- -------------------------- -------------------------- -------------------------- -------------------------- -------------------------- -------------------------- -------------------------- -------------------------- -------------------------- -------------------------- -------------------------- -------------------------- -------------------------- -------------------------- -------------------------- -------------------------- 
-------AAAAAAAAAAAA------- -------AACAAAAAACAA------- -------AACAAAAAACAA------- -------AAAAAAAAACAA------- -------AACAAAAAACAA------- -------AACAAAAAACAA------- -------AAAAAAAAAAAA------- -----------BBCB----------- -----------BCBC----------- -----------CBBB----------- -------------------------- -------------------------- -------------------------- -------------------------- -------------------------- -------------------------- -------------------------- -------------------------- -------------------------- -------------------------- -------------------------- -------------------------- -------------------------- -------------------------- -------------------------- -------------------------- -------------------------- -------------------------- -------------------------- -------------------------- -------------------------- 
----------AAAAAA---------- ----------ACAACC---------- ----------ACAACA---------- ----------CAAACA---------- ----------ACAACA---------- ----------ACAACC---------- ----------AAAAAA---------- -------------------------- -------------------------- -------------------------- -------------------------- -------------------------- -------------------------- -------------------------- -------------------------- -------------------------- -------------------------- -------------------------- -------------------------- -------------------------- -------------------------- -------------------------- -------------------------- -------------------------- -------------------------- -------------------------- -------------------------- -------------------------- -------------------------- -------------------------- -------------------------- 
