model
size = 32 11 28, scale = 0.05, origin = -y
material 
  colors = A:#533519 B:#221C06 C:#D4B007
voxels
12-8A341-14A336-18A333-20A331-22A329-24A16-2B4C2B24-3B2C3B24-2B4C2B239-26A13-2(2B8A2B20-)2B8A2B22-8A24-8A174-10A8-10A11-2(B2A8-2AB18-)B2A8-2AB19-2A8-2A20-2A8-2A22-2(8A24-)8A78-8A12-8A10-2(BA12-AB16-)BA12-AB17-A12-A18-A12-A19-2A8-2A21-11A22-10A22-8A25-6A2(14-8A)8-2(BA14-AB14-)BA14-AB15-A14-A16-A14-A17-A12-A19-A11-A20-12A20-11A22-9A12-7A16-7A7-2(BA16-AB12-)BA16-AB13-A16-A14-A16-A15-A14-A17-A12-2A18-14A18-13A20-2A6-3A11-7A16-7A7-2(BA16-AB12-)BA16-AB13-A16-A14-A16-A15-A14-A16-2A12-2A17-15A17-4A6-4A19-A10-2A9-7A18-7A5-2(BA18-AB10-)BA18-AB11-A18-A12-A18-A13-A16-A14-A16-A15-17A16-3A2-5A-4A17-2A11-A9-2(7A18-7A5-2(BA18-AB10-)BA18-AB11-A18-A12-A18-A13-2(A16-A14-)18A15-3A3-5A-4A17-A5-3A4-2A8-)7A18-7A5-2(BA18-AB10-)BA18-AB11-A18-A12-A18-A13-A16-A14-A16-A15-17A16-3A2-5A-4A17-2A11-A10-7A16-7A7-2(BA16-AB12-)BA16-AB13-A16-A14-A16-A15-A14-A16-2A13-A17-15A17-4A6-4A19-A10-2A10-7A16-7A7-2(BA16-AB12-)BA16-AB13-A16-A14-A16-A15-A14-A17-A13-A18-14A18-13A20-2A6-3A11-8A14-8A8-2(BA14-AB14-)BA14-AB15-A14-A16-A14-A17-A12-A19-A11-A20-12A20-11A22-9A13-8A12-8A10-2(BA12-AB16-)BA12-AB17-A12-A18-A12-A19-2A8-2A21-11A22-10A22-8A25-6A15-10A8-10A11-2(B2A8-2AB18-)B2A8-2AB19-2A8-2A20-2A8-2A22-2(8A24-)8A79-26A13-2(2B8A2B20-)2B8A2B22-8A24-8A176-24A16-2(8B24-)8B241-22A331-20A333-18A336-14A341-8A332-
