model
size = 22 32 26, scale = 0.05, origin = -y
material 
  colors = A:#0C0 B:#555 C:#888 D:#00F E:#EEE F:#0A0 G:#0B0 H:#E00 I:#0E0 J:#A00 K:#111 L:#90F M:#90C N:#FF0 O:#F9F P:#200 Q:#500
voxels
50-3(M2(21-D)21-)M482-2(7A15-)2(7D15-)2(7A2(15-7D)15-)7A17-4A18(18-A2-A)59-2(9A13-)2(9D13-)2(9A2(13-9D)13-)2(9A13-)16(4ABC3A13-)4ABC3A16-A2-A18-A2-A15-10A12(11-11A)2(11-5ABC4A)3-A7-5ABC4A3-2A6-5ABC4A4-A6-5ABC4A4-2A5-5ABC4A5-A5-G4ABC4A5-2A2(4-5ABC4A6-A)4-5ABC4A6-2A2(3-5ABC4A7-A)3-5ABC4A7-D3-5ABC4A7-A4-4ABC4A7-D4-4ABC4A6-2A4-4ABC5A5-A5-4ABC3A-2A3-2A8-A2-A4-5A6-10A11-10AL2(11-D10A)11-11A11-D10A11-D9ADB10-10AD2(B10-D10A)D10-11A2D2(9-D10A-D)9-5ABC4A-2D8-5ABC4A2-DA7-5ABC4A3-2A6-J4ABC4A4-A6-G4ABC4A4-2A5-G4ABC4A5-A5-G4ABC4A5-2A4-G4ABC4A6-A4-5ABC4A6-A3-FE4ABC4A6-2A2-F2(5ABC4A7-A3-)5ABC4A7-D3-5ABC4A7-A3-5ABC4A7-D4-4ABC4A6-2A4-4ABC5A5-A5-4ABC3A-2A3-2A8-A2-A4-5A6-10A11-11A11-D9AL11-D10A11-11A11-D10A11-D9ADB10-10A2D10-D10AB10-D10AD10-11A2D2(9-D10A-D)9-5ABC4A-2D8-5ABC4A2-DA7-J4ABC4A3-2A6-H4ABC4A4-A6-H4ABC4A4-2A5-G4ABC4A5-A5-G4ABC4A5-2A4-G4ABC4A6-A3-FE4ABC4A6-A-IF2E4ABC4A6-2A-F2E4ABC4A7-A2-6A2(BC4A7-A3-5ABC4A7-D3-5A)BC4A6-2A4-4ABC5A5-A5-4ABC3A-2A3-2A8-A2-A4-5A6-10A11-10AL3(2(11-D10A)11-11A)2(11-D10A)11-5ABC4A11-J4ABC4A3-A7-H4ABC4A3-2A6-H4ABC4A4-A6-G4ABC4A4-2A5-G4ABC4A5-A5-G4ABC4A5-2A3-FE4ABC4A6-A-2F2E4ABC4A6-A2-3E4ABC4A6-2AI3E4ABC4A7-A-F2E4ABC4A7-A2-6ABC4A7-D3-5ABC4A7-A3-5ABC4A7-D3-G4ABC4A6-2A3-5ABC5A5-A5-4ABC3A-2A3-2A8-A2-A4-5A6-10A11-11A11-D9AL11-D10A3(11-11A2(11-D10A))11-5ABC4A11-J4ABC4A11-H3(4ABC4A11-G)4ABC4A10-FE4ABC4A8-2F2(2E4ABC4A9-K)2E4ABC4A8-2F2E4ABC4A8-IF2E4ABC4A9-F2E4ABC4A10-6ABC4A11-5ABC4A11-G4ABC4A11-5ABC4A12-4ABC3A16-A2-A15-10A11-10AL3(2(11-D10A)11-11A)2(11-D10A)11-5ABC4A11-J4ABC4A11-H3(4ABC4A11-G)4ABC4A10-FE4ABC4A8-2F2E4ABC4A9-K2E4ABC4A9-3E4ABC4A8-2F2E4ABC4A8-IF2E4ABC4A9-F2E4ABC4A10-6ABC4A11-5ABC4A11-G4ABC4A11-5ABC4A12-4ABC3A16-A2-A15-10A4(11-11A2(11-D10A))11-5ABC4A11-J4ABC4A11-H3(4ABC4A11-G)4ABC4A10-FE4ABC4A8-2F2(2E4ABC4A9-K)2E4ABC4A8-2F2E4ABC4A8-IF2E4ABC4A9-F2E4ABC4A10-6A2(BC4A11-G4A)BC4A11-5ABC4A12-4ABC3A16-A2-A15-10A4(11-11A2(11-D10A))11-5ABC4A11-J4ABC4A11-H4(4ABC4A11-G)4ABC4A10-FE4ABC4A8-2F2E4ABC4A9-3E4ABC4A8-IF2E4ABC4A9-F2E4ABC4A10-6ABC4A11-5ABC4A11-G4A2(BC4A11-5A)BC4A12-4ABC3A16-A2-A15-10A4(11-11A2(11-D10A))11-5ABC4A11-J4ABC4A11-H4ABC4A11-G4ABC4A11-5A3(BC4A11-G4A)BC4A10-FE4ABC4A8-IF2E4ABC4A9-F2E4ABC4A10-6A2(BC4A11-5A)BC4A11-G4A2(BC4A11-5A)BC4A12-4ABC3A16-A2-A15-10A4(11-11A2(11-D10A))11-5ABC4A11-J4ABC4A11-H3(4ABC4A11-G)4A2(BC4A11-5A)BC4A11-G4ABC4A9-2FE4ABC4A10-6A6(BC4A11-5A)BC4A12-4ABC3A16-A2-A15-10A4(11-11A2(11-D10A))11-5ABC4A11-J4ABC4A11-H4A2(BC4A11-G4A4(BC4A11-5A))BC4A11-G4A3(BC4A11-5A)BC4A12-4ABC3A16-A2-A15-10A4(11-11A2(11-D10A))11-5ABC4A11-J4ABC4A11-H4ABC4A11-G4A2(BC4A11-5A)BC4A11-G4ABC4A11-5ABC4A11-G4ABC4A9-2FE4ABC4A10-F3(5ABC4A11-)2(G4ABC4A11-)5ABC4A11-5ABC4A12-4ABC3A16-A2-A15-10A4(11-11A2(11-D10A))11-5ABC4A11-J4ABC4A11-H2(4ABC4A11-G)4A2(BC4A11-5A)BC4A11-G4ABC4A10-GE4ABC4A8-IF2E4ABCAIFA9-F2E4ABC2AFA10-6A2(BC4A11-5A)BC4A11-G4A2(BC4A11-5A)BC4A12-4ABC3A16-A2-A15-10A4(11-11A2(11-D10A))11-5ABC4A11-J4ABC4A11-H4ABC4A11-G4ABC4A11-5A2(BC4A11-G4A)BC4A10-GE4ABC4A8-2F2E4ABCA2FA9-3E4ABC2AEA8-I3E4ABCAIEA9-F2E4ABC2AFA10-6ABC4A11-5ABC4A11-G4A2(BC4A11-5A)BC4A12-4ABC3A16-A2-A15-10A4(11-11A2(11-D10A))11-5ABC4A11-J4ABC4A11-H3(4ABC4A11-G)4ABC4A10-GE4ABC4A8-2F2E4ABCA2F2(A9-K2E4ABC2AK)A8-2F2E4ABC2AFA8-IF2E4ABCAIFA9-F2E4ABC2AFA10-6ABC4A11-5ABC4A11-G4ABC4A11-5ABC4A12-4ABC3A16-A2-A15-10A4(11-11A2(11-D10A))11-5ABC4A11-J4ABC4A11-H4ABC4A11-G4ABC4A11-5ABC4A11-G4ABC4A10-FE4ABCA2FA8-2F2E4ABCAFEA9-K2E4ABC2AKA9-3E4ABC2AEA8-2F2E4ABC2AFA8-IF2E4ABCAIFA9-F2E4ABC2AFA10-6ABC4A11-5ABC4A11-G4ABC4A11-5ABC4A12-4ABC3A16-A2-A15-10A4(11-11A2(11-D10A))11-5ABC4A11-J4ABC4A11-H4ABC4A11-G4A2(BC4A11-5A)BC4A10-FE4ABC4A8-2F2E4ABCA2F2(A9-K2E4ABC2AK)A8-2F2E4ABC2AFA8-IF2E4ABCAIFA9-F2E4ABC2AFA10-6ABC4A11-5ABC4A11-G4ABC4A11-5ABC4A12-4ABC3A16-A2-A15-10A11-11A11-D10A10-2D10A2(10-N11A2(10-2D10A))10-O11A2(11-D10A)11-5ABC4A11-J4ABC4A3-A7-H4ABC4A3-2A6-H4ABC4A4-A6-5ABC4A4-2A5-5ABC4A5-A5-5ABC4A5-2A3-FE4ABC4A6-A-2F2E4ABCA2FA6-A2-3E4ABC2AEA6-2AGF2E4ABCAIFA7-A-F2E4ABC2AFA7-A2-6ABC4A7-A3-5ABC4A7-A3-G4ABC4A7-A3-5ABC4A6-2A3-5ABC5A5-A5-4ABC3A-2A3-2A8-A2-A4-5A6-10A11-11A2(11-D10A)11-11A11-D10A11-D9ADB10-10A2D10-D10AB10-D10AD10-11A2D2(9-D10A-D)9-5ABC4A-2D8-5ABC4A2-DA7-J4ABC4A3-2A6-H4ABC4A4-A6-H4ABC4A4-2A5-5ABC4A5-A5-G4ABC4A5-2A4-5ABC4A6-A3-FE4ABC4A6-A-IF2E4ABCAIFA6-2A-F2E4ABC2AFA7-A2-6ABC4A7-A3-5ABC4A7-A3-G4A2(BC4A7-A3-5A)BC4A6-2A4-4ABC5A5-A5-4ABC3A-2A3-2A8-A2-A4-5A6-10A11-11A2(11-D10A)11-11A11-D10A11-D9ADB10-10AD2(B10-D10A)D10-11A2D2(9-D10A-D)9-5ABC4A-2D8-5ABC4A2-DA7-5ABC4A3-2A6-J4ABC4A4-A6-G4ABC4A4-2A5-5ABC4A5-A5-G4ABC3AG5-2A2(4-5ABC3AG6-A)3-FE4ABC2AFG6-2A2-6ABC3AG7-A3-5ABC3AG7-A3-G4A2(BC3AG7-A3-5A)BC4A7-A4-4ABC4A6-2A4-4ABC5A5-A5-4ABC3A-2A3-2A8-A2-A4-5A6-10A12(11-11A)2(11-5ABC4A)3-A7-5ABC4A3-2A6-5ABC4A4-A6-5ABC4A4-2A5-G4ABC4A5-A5-G4ABC4A5-2A2(4-5ABC4A6-A)4-5ABC4A6-2A4(3-5ABC4A7-A)4-4ABC4A7-A4-4ABC4A6-2A4-4ABC5A5-A5-4ABC3A-2A3-2A8-A2-A4-5A28-2(9A13-)2(9D13-)2(9A2(13-9D)13-)2(9A13-)16(4ABC3A13-)4ABC3A16-A2-A18-A2-A38-2(7A15-)2(7D15-)2(7A2(15-7D)15-)7A17-4A14(18-A2-A)18-A-QA18-A-P2(A18-A2-)A33-
