model
size = 13 32 10, scale = 0.05, origin = -y
material 
  colors = A:#930 B:#C30 C:#C60 D:#FC3 E:#F93 F:#FC0 G:#FC6 H:#369 I:#960 J:#C93 K:#399 L:#963 M:#C90 N:#DDD O:#336 P:#036 Q:#69C R:#99C S:#F90 T:#D00 U:#669
voxels
6-B11-3B9-2BK2B8-B2KHB8-PKD2H8-EGEMH8-EG2EC8-JD2EC98-7D253-B5-B6-2(B5-)2B5-2B4-BQ5-HB4-KR5-EH4-KD2(ME)CEU4-CGM2(EC)EG4-CG2EB2CED4-JGJCBTCJD5-G3CB2C6-GCBCMJC6-7F5-D7FD6-CBC2J8-CB2CJ8-M4C9-3I35-EDCEC7-2EGA2ES6-ED3AED6-7A7-5B111-B5-B6-2(B5-)2B5-2B3-2BQ5-H2B2-BKR5-2HB2-HKDKEMK2HUP2-DCGMECKHEGO2-DQGQKBKHOHC2-DJGJCBTCJDC2-DMG3CB2CDE3-CGCBCMJCD4-9F3-D9FD4-LCBC2JL6-LCB2CJL6-LM4CL6-7I2(6-7A)6-AEDCECA6-2EG3ES6-ED2G2ED6-AD2GEDA6-7B6-7N6-2A3-2A6-A5-A120-B11-2B11-B-D9-O2-H9-O2-D9-C2-D9-E2-E9-D3-D7-D3-DF7-FD3-C7-G4-C7-D2(5-L)6-2(I5-)2(A7-A4-)A7-G4-D7-E4-G7-C4-A7-A4-B7-B4-N7-N5-2(2A3-2A6-)2A3-2A107-B11-2B11-BE11-3H9-OH-D9-C2-D9-E2-E9-D3-D7-D3-DF7-FD3-C7-G4-C7-D4-C7-E4-I7-I2(4-A7-A)4-D7-G4-D7-E2(4-A7-A)4-B7-B57-2A3-2A94-B11-2B11-BED9-OH-H9-O2-D9-C2-D9-E2-E9-D3-F7-F3-DF7-FD3-C7-G4-C7-D4-C7-E4-I7-I2(4-A7-A)4-D7-G4-D7-E4-A7-A4-B7-B70-2A3-2A95-2(B9-B2-)D9-O2(2-D9-C)3-M7-D4-C7-D4-F7-F3-DF7-FD3-C7-G2(5-L)6-2(L5-)I7-I2(4-A7-A)4-D7-G4-D7-E4-A7-A4-B7-B70-2A3-2A82-2(B9-B2-)BK7-UP3-C7-G4-C7-D4-J7-D4-M7-D4-C7-D4-F7-F4-DF5-FD2(5-L)2(6-2L3-2L)6-2I3-2I2(6-A5-A)5-A7-A4-D7-E4-A7-2(A5-)A6-B5-B58-2A3-2A34-2KH8-BQ2GJPB6-BKGDMPB5-2BKREMC2B4-BQER2ECHB4-KEJD2ECEH5-D2(ME)CE6-GM2(EC)E6-G2EB2CE6-GJCBTCJ6-G3CB2C6-GCBCMJC6-7F6-D5F2D6-CBC2J9-B2C10-3C10-3I9-5A8-5A7-AEDCECA6-2EG3ES6-E5-D6-A5-A6-B5-B6-N5-N3(6-2A3-2A)7-A3-A10-B11-3B9-2BK2B7-2B2GJ2B6-BKGDMPB7-KGEMC9-G2E113-6D98-EG3E8-D2G2E7-7A6-7B6-7N6-2A3-2A7-A3-A30-
