model
size = 32 16 31, scale = 0.05, origin = -y
material 
  colors = A:#FFF B:#FFD900 C:#B80CFF D:#5E0CFF E:#890CFF F:#750CFF
voxels
7-2(3A12-)7A8-7A9-2A4B2A8-2A4B2A7-3AB3-B2A6-2AB3-B3A6-2AB5-B2A4-2AB5-B2A6-AB7-BA4-AB7-BA5-AB9-BA2-A2(B9-BA4-AB9-B4A)2(B9-BA4-AB9-BA2-A)B9-BA5-AB7-BA4-AB7-BA7-AB5-BA6-AB5-BA9-A5BA8-A5BA11-5A10-5A13-3A12-3A15-2(A14-)2(5A10-)9A6-9A7-11A4-11A5-5A3-4A4-4A3-5A4-4A5-4A2-4A5-4A3-4A7-3A2-3A2(7-4A2-4A7-8A)7-4A2-4A7-3A2-3A7-4A3-4A5-4A2-4A5-4A4-5A3-5A2-5A3-5A5-11A4-11A7-9A6-9A9-7A8-7A11-5A10-5A2(14-A)15-3A12-3A13-2(5A10-)10A4-10A6-5A3-5A2-2(5A3-)5A5-4A2-4A5-5A2-3AC7-C2A2-2A2(C7-C3A2-3AC7-C6A)C7-C3A2-3AC7-C2A2-2AC7-C3A2-5A5-4A2-4A5-2(5A3-)5A2-5A3-5A5-4A3C2A8-2A3C4A7-7A10-7A11-3A12-3A15-A14-A139-5AD6A2-6AD5A4-2(14A2-)4ACFADAFC3A2-3ACFADAFC4A2-4ACF3AFC8ACF3AFC4A2-4ACF3AFC3A2-3ACF3AFC4A2-4ACFADAFC3A2-3ACFADAFC4A2(2-14A)2(4-5AD5A)387-B30-B480-C30-C480-E30-E480-A30-A480-D30-D480-4(A30-A449-A28-A-)A30-A5(449-E28-E-DA28-AD)3(449-A28-A-DA28-AD)480-DA28-AD480-2A28-2A480-EA28-AE480-CA28-AC480-2B28-2B480-2C28-2C480-2E28-2E480-2A28-2A480-2D28-2D224-
