model
size = 17 6 14, scale = 0.05, origin = -y
material 
  colors = A:#100 B:#FC3 C:#111
voxels
-------------BBB- ------BBBBB--ACB- ------BAAABAAAAB- ------BBCABACAA-- ------BAAABAAA--- ------BBBBB------ 
----------------- ----------------- ---BAAAAAAAAAB--- ---BAAAAAAAAAB--- ---BAAAAAAAAAB--- ----------------- 
----------------- ----------------- --B-----------B-- --B-----------B-- --B-----------B-- ----------------- 
----------------- ----------------- -B-------------B- -B-------------B- -B-------------B- ----------------- 
----------------- ----------------- A---------------A A---------------A A---------------A ----------------- 
----------------- ----------------- A---------------A A---------------A A---------------A ----------------- 
----------------- ----------------- B---------------B B---------------B B---------------B ----------------- 
----------------- ----------------- B---------------B B---------------B B---------------B ----------------- 
----------------- ----------------- B---------------B B---------------B B---------------B ----------------- 
----------------- ----------------- A---------------A A---------------A A---------------A ----------------- 
----------------- ----------------- A---------------A A---------------A A---------------A ----------------- 
----------------- ----------------- -B-------------B- -B-------------B- -B-------------B- ----------------- 
----------------- ----------------- --BBA-------ABB-- --BBA-------ABB-- --BBA-------ABB-- ----------------- 
----------------- ----------------- -----AABBBAA----- -----AABBBAA----- -----AABBBAA----- ----------------- 
