model
size = 17 6 14, scale = 0.05, origin = -y
material 
  colors = A:#600 B:#BBB C:#AAA D:#111
voxels
-CBC------------- -BAA--CBCBC------ -CAAAABAAAB------ --ADADCADCC------ ---AAABAAAB------ ------CBCBC------ 
----------------- ----------------- ---BAAAAAAAAAB--- ---BAAAAAAAAAB--- ---CAAAAAAAAAC--- ----------------- 
----------------- ----------------- --B-----------B-- --C-----------C-- --B-----------B-- ----------------- 
----------------- ----------------- -C-------------C- -B-------------B- -B-------------B- ----------------- 
----------------- ----------------- A---------------A A---------------A A---------------A ----------------- 
----------------- ----------------- A---------------A A---------------A A---------------A ----------------- 
----------------- ----------------- C---------------C B---------------B C---------------C ----------------- 
----------------- ----------------- B---------------B C---------------C B---------------B ----------------- 
----------------- ----------------- C---------------C B---------------B C---------------C ----------------- 
----------------- ----------------- A---------------A A---------------A A---------------A ----------------- 
----------------- ----------------- A---------------A A---------------A A---------------A ----------------- 
----------------- ----------------- -C-------------C- -B-------------B- -C-------------B- ----------------- 
----------------- ----------------- --BCA-------ABB-- --CBA-------ABC-- --BCA-------ACB-- ----------------- 
----------------- ----------------- -----AACBCAA----- -----AABCBAA----- -----AACBCAA----- ----------------- 
