model
size = 14 10 32, scale = 0.05, origin = -y
material 
  colors = A:#555 B:#211E55 C:#222 D:#43341B E:#563F2E F:#FFB11B G:#E83015 H:#111 I:#F75C2F
voxels
19-4F10-F2-F8-2(2F-)2F6-F-F2-F-F7-F-2F-F8-A4FA64-2A2B2A7-3A2H3A5-B2(2-H)-AB4-B-HC2HCH-B5-ACH2BHCA6-2AB2-B2A7-A4-A49-3A2B3A5-4A2B4A3-B4-2B4-B2-B4-2B4-B3-4A2B4A5-2AB2-B2A7-A4-A49-3A2B3A4-2A2-A2BA2-2A-B12-2B12-B-2A2-A2BA2-2A4-2AB2-B2A7-A4-A35-3A2-3A5-4A2-4A3-A4-2B4-A-B12-2B12-B-A4-2B4-A3-3AB2-B3A4(5-2A4-2A34-3A2-3A5-3(A2-)A3-A4-2B4-A-B12-2B12-B-A4-2B4-A3-A2(2-B)2-A)5-2A4-2A34-3A2-3A5-4(A2-)2A4-2B4-2AB11-3B11-2B2A4-2B4-2A2-A2(2-B)2-A5-2A4-2A34-3A2-3A4-2A2-A2BA2-2A-A12-AB11-3B11-2BA11-2A-2A2-4B2-2(2A4-)2A33-2(4A2-)2(2A-)2B7A2-2A3-4A-AB2-2A3-3A4B2-2A3-3A3BA2-2A3-8A-2A-2B6A2(2-4B)31-5A2B5A2(-A)2EA-BA2E4A-3(A2-)3AB-3(A2-)A3B-2(A2-)AE-A2B3A2C4A2E4A-A2-4A2-3A-2B2-4B2-2B30-5A2B5A-BA4E2B4EAB2(2A4-)2ABA4-2A4-A2BA4-2E-E2-AB2A-2C3-4E2A2B10-2B43-5A2B5A-2A4E2(BA4-2A)2(4-A2BA4-2E)4-A2BA-2C3-4EAB2AC2-C6-2A2(43-12B-30B4D2E4D3BA4-2E4-A2BA10-A3B10-2B)43-5A2B5A-6A2B6AB5A2B5A3B4D2E4D3BA4-2E4-A2BA4-2E4-AB2A10-2A43-5A2B5A-B5A2B5AB6A2B6A3B8A4BA4D2A4DAB2A4D2B4D2A2(2B4D)2B3-2D-2B-2D6-2D4-2D18-5A2B5A2(-A)2-A2BA2-4A-A2-A2BA2-3AB-B2-4A2-4B-B2-4A2-3BA-A2-A2BA2-4A-A2-A2BA2-3A-2B2-4B2-2B31-2(4A2-)6A2B7A2-3A2B4A-AB2-8AB-2B2-8AB-BA2-2A4B2(3A-)2AB2-B2A-2A2(2-4B)33-2(2A4-)2A2-A2B2(2A-)A8-A3-AB12-2B12-BA4-4B4-A-4A4-4A5-A4-A35-2A4-2A5-4(A2-)2A4-2B4-2AB12-2B12-B2A3-4B3-2A2-4(3A4-3A6-A4-A35-2A4-2A5-3(A2-)A3-A4-2B4-A-B12-2B12-B-A3-4B3-A3-)3A4-3A6-A4-A35-2A4-2A5-4A2-4A3-A4-2B4-A-B12-2B12-B-A3-4B3-A3-3A4-3A6-C4-C8-2(C4-)14C17-2(2C4-)2C2-4C2-2C-C12-2C12-C-2C2-4C2-2(2C4-)2C31-14C17-2C4-2C5-4C2-CA2C3-C4-2C4-C2-C4-2C4-C3-C2AC2-C2AC5-2C4-2C76-2G4-2G5-3(G2-)G4-3(G2-)G5-2G4-2G104-2I4-2I6-2I4-2I73-
