model
size = 32 32 11, scale = 0.05, origin = -y
material 
  colors = A:#EEE B:#FFF C:#005CAF D:#DDD
voxels
498-4B3(28-B2AB)28-4C184-2C-2C26-C2A-2AC24-C2AB-B2AC22-C2AB3-B2AC21-2CB5-BAC22-C7-2C22-C7-C477-2(4A28-)4A18-A9B4AB17-2B13AB16-2B8A4CAB16-B14AB10-2CB2-2B2AB12AB2-B2C3-2CBA3B7AB8AB-2AB2C-2CBAB9AB7AB6ABC2-B3AB17A2B4AB4-2(B6A)-8AB2AB6-B4AB6A3-9AB8-B9A5-7AB10-2B6A6-5A2B13-2A2B2A6-4A2B19-A7-2A2B20-C7-C22-10C22-10B22-B5ABA2B22-AB2A2(BA)2B22-2(2AB)2A2B21-BA2(B3A)B21-2(B9A2B20-)B7ABA2B20-B3AB5A2B20-4AB5A2B20-3AB5A3B20-10A2B20-10ABA20-B4AB7AB17-2(B6A)B16-DB13AB16-B14AB16-15AB16-16A11-C3-17A4-C7-A-19A2-2A8-16A4-5A8-15A2(4-A)2C29AB2-B12A5-11A4-12A5-10A6-11A5-9A8-B9A5-8A11-3B5A5-7A15-2ABA7-4AB19-C7-C21-C9-AC20-B9-AB20-BA8-2A19-2BA8-2A19-ABA2(8-2AB18-3A)2(8-2AB18-D2A)5(8-2AB18-B2A)8-3AB16-DB2A8-4A16-D3A8-4A16-B3A3(8-4A16-4A)8-4A11-C3-5A8-5A3-C7-A-A13-6A-2A8-2A13-A5-2A10-6A8-A9-A2C11A8-10AB2-B10A8-10A3-11A8-9A5-10A8-9A7-8A8-8A9-9A5-8A13-A2B2A7-5A19-C7-C21-C10-C20-A10-B19-BA2(10-AB18-2A)2(10-2A18-2A)10-AB6(18-2A10-2A)17-D2A10-2AB16-B2A3(10-3A16-3A)10-2AB2(16-3A10-3A)11-C3-4A10-4A3-C6-2A-A14-5A-2A8-2A19-A11-5A19-A2C10A10-9AB2-B9A10-9A3-10A10-9A4-9A10-8A6-8A10-8A8-9A5-8A12-2B4A7-2AB3A18-C7-C21-C10-C20-A10-B20-A10-A19-BA3(10-AB18-2A)3(10-2A18-2A)10-AB3(18-2A10-2A)B2(16-B2A10-3A)5(16-3A10-3A)11-C3-4A10-4A3-C7-A-A3-A10-5A-2A8-2A19-2A10-5A19-A2C10A10-9AB2-B9A10-9A3-10A10-9A4-9A10-8A6-8A10-7A8-B9A5-8A12-2(B2A)7-3AB2A18-C7-C22-C8-AC20-2A8-AB2(20-2A8-2A)19-B2A2(8-2A19-3A)7(8-2AB18-3A)4(8-4A16-B3A)2(8-4A16-4A)8-4A11-C3-5A8-5A3-C7-A-A3-2A8-6A-2A8-2A13-A5-2A10-6A8-A10-2C11A8-10AB2-B10A8-10A4-10A8-9A5-10A8-9A6-9A8-8A8-10A5-8A13-B4A7-4AB19-C7-C22-11C21-11B20-2B3AB4A2B20-BAB3AB2ABAB20-B5AB4AB20-B4AB3ABAB20-B3AB6A3(B20-B10A)B20-B11A2(20-12A)B18-B13A18-15A17-3(15A16-B)5A5-5A16-B5A5-5A11-C3-7A5-6A3-C7-A-A3-4A5-7A-2A8-3(2A5-)2A10-8A5-2A10-2C13A5-11AB3-12A5-11A4-12A5-10A6-11A5-9A7-11A5-9A9-B8A5-8A14-B3A7-A3B20-C7-C313-4B25-2B5A3B21-B10AB20-2AB9AB18-B6A2B5A18-B13A18-2(B6A)B17-B11ABAB17-B13AB17-B4A5-4AB17-5A5-5A11-C3-7A5-5A4-C7-A-8A5-7A-AC8-3(2A5-)3A3-2C4-8A5-2A9-AC-B12A5-11AB3-12A5-10A6-11A5-9A7-11A5-9A8-10A5-6ABA12-4AB2A5-4AB2A18-A7-A23-C7-C599-8B22-2B8A3B17-2B7A2B4AB10-2C3-B5A4B7AB4-C3-C3B-B10AB7A4B2C3-B16A2B9AC3-B26AB5-2B6AB15A2B6-2A2B18A3B8-3A2B3AB10A4B11-2BA3B2A5-2A4B19-BA5-2(AB)21-AB5-A24-2C5-C890-3A28-A2B2AB26-B2A2BAB26-5A27-5C13-
