model
size = 32 32 11, scale = 0.05, origin = -y
material 
  colors = A:#111 B:#222 C:#FFF
voxels
498-4B3(28-B2AB)28-4C184-2C-2C26-C2A-2AC24-C2AB-B2AC22-C2AB3-B2AC21-2CB5-BAC22-C7-2C22-C7-C477-2(4A28-)4A18-A9B4AB17-B14AB16-B9A4CAB16-B14AB10-2CB2-B16AB2-B2C3-2CBAB19A-2AB2C-2CBAB17AB6ABC2-B27AB4-2(B6A)-8AB2AB6-B4AB6A3-9AB8-B9A5-7AB10-B7A6-6AB13-3AB2A6-4A2B19-A7-2A2B20-C7-C22-10C22-10B22-B5AB2AB22-2(4AB)22-2(5AB3AB21-B)9A2B20-B9ABA20-B7A2(BA)20-B9ABA20-10ABA20-3AB6A2(BA20-10A)BA20-B4AB7AB17-2(B6A)B16-2B13AB3(16-16A)11-C3-17A4-C7-A-19A2-2A8-16A4-5A8-15A2(4-A)2C29AB2-B12A5-11A4-12A5-10A6-11A5-9A8-B9A5-8A11-AB6A5-7A15-2ABA7-4AB19-C7-C21-C9-AC20-B9-2A20-BA8-2A19-2BA8-2A19-ABA2(8-2AB18-3A)7(8-2AB18-B2A)8-3AB16-AB2A3(8-4A16-4A)8-3AB2(16-4A8-4A)11-C3-5A8-5A3-C7-A-A13-6A-2A8-2A13-A5-2A10-6A8-A9-A2C11A8-10AB2-B10A8-10A3-11A8-9A5-10A8-9A7-8A8-8A9-9A5-7AB13-2AB2A7-5A19-C7-C21-C10-C20-A10-A19-BA10-AB5(18-2A10-2A)18-BA4(10-2A18-2A)10-2A17-6(3A10-3A16-)3A10-3A11-C3-4A10-4A3-C6-2A-A14-5A-2A8-2A19-A11-5A19-A2C10A10-9AB2-B9A10-9A3-10A10-7A2B4-9A10-7AB6-8A10-7AB8-9A5-8A12-6A7-2AB3A18-C7-C21-C10-C2(20-A10-A)19-BA10-2A2(18-2A10-AB)4(18-2A10-2A)18-BA2(10-2A18-2A)2(10-2AB2(16-3A10-3A)16-3A)10-3A16-3A10-3A11-C3-4A10-4A3-C7-A-A3-A10-5A-2A8-2A19-2A10-5A19-A2C10A10-9AB2-B9A10-9A3-10A10-7A2B4-9A10-7AB6-8A10-7A8-10A5-7AB12-B5A7-3AB2A18-C7-C22-C8-AC3(20-2A8-2A)19-B2A8-2A19-3A8-AB19-6(3A8-2AB18-)3A8-3A18-3A8-3AB3(16-B3A8-4A)16-4A8-3AB2(16-4A8-4A)11-C3-5A8-5A3-C7-A-A3-2A8-6A-2A8-2A13-A5-2A10-6A8-A10-2C11A8-10AB2-B10A8-10A4-10A8-9A5-10A8-9A6-9A8-8A8-10A5-8A13-B4A7-4AB19-C7-C22-11C21-11B20-2B3AB4A2B20-BAB6ABA6(B20-B10A)B20-B7A3BA20-12A20-13A18-B13A18-14AB17-3(15A16-B)5A5-5A16-B5A5-5A11-C3-7A5-6A3-C7-A-A3-4A5-7A-2A8-3(2A5-)2A10-8A5-2A10-2C13A5-11AB3-12A5-11A4-12A5-9AB6-11A5-9A7-11A5-9A9-9A5-8A14-B3A7-A3B20-C7-C313-4B25-3B4A3B21-AB9AB20-B11AB2(18-B13A)18-2(B6A)B17-B11ABAB17-B13AB17-B4A5-4AB17-5A5-5A11-C3-7A5-5A4-C7-A-8A5-7A-AC8-3(2A5-)3A3-2C4-8A5-2A9-AC-B12A5-11AB3-12A5-10A6-11A5-9A7-B10A5-9A8-10A5-6ABA12-4AB2A5-4AB2A18-A7-A23-C7-C599-8B22-2B8A3B17-2B7A2B4AB10-2C3-B8AB7AB4-C3-C3B-B10AB7A4B2C3-B16A2B9AC3-B26AB5-2B6AB16AB6-2AB21AB8-3AB4AB13AB11-B2A3B2A5-2A4B19-BA5-2(AB)21-AB5-A24-2C5-C890-3A28-A2B2AB26-B2A2BAB26-5A27-5C13-
