model
size = 30 27 7, scale = 0.05, origin = -y
material 
  colors = A:#555 B:#888 C:#AAA D:#777 E:#FF0 F:#200 G:#444 H:#FC0
voxels
------BBDBBBBBBBBBDBBBDB------ -------BBDDBDBDBBBBDBDD------- --------BBBBBBBBBDBBDB-------- ---------FEEEFEEEFEEE--------- ---------FEFEFEFEFEFE--------- ---------FEEEFEEEFEEE--------- ----------BBBBBBBBBB---------- ----------CCEHBBHECC---------- --------CCCCCCBBCCCDCD-------- --------BBBBBBBBBBBBDB-------- --------CDCCEHBBHECCDC-------- -------CCCDCCCBBCCCCCCD------- -------BDBBBBBBBBBBBDDB------- -------CCCDCEHBBHECCCDC------- ------CCDCCCCCBBCCCDCDCC------ ------BBDBBBBBBBBBBBDBDD------ ------CCCCDCEHBBHECCCCCC------ -----CCDCCCECCBBCCECCDDDC----- -----BBBBBBGBBBBBBGBBBBBB----- BB---BCBCCBECCBBCCEBCCBCB---AA BCB--BCBCDBCCFFFFACBCCBCB--BBB BBBBBBCBCCBCCCBBCCDBCDBCBBBBCB --BCDBCBCCBDCBGGBCCBCCBCBCCB-- --BCCBCBECBCBG--GBCBCEBCBCCB-- --BBBBCBGCBBG----GBBCGBCBBBB-- -----BCBECBG------GBCEBCB----- -----BBBBB----------BBBBB----- 
------AAAAAAAAAAAAAAAAAA------ -------AAAAAAAAAAAAAAAA------- --------AAAAAAAAAAAAAA-------- ---------FAAAAAAAAAAF--------- ---------FAAAAAAAAAAF--------- ---------FAAAAAAAAAAF--------- ----------AAAAAAAAAA---------- ----------AAAAAAAAAA---------- --------AAAAAAAAAAAAAA-------- --------AAAAAAAAAAAAAD-------- --------CAAAAAAAAAAAAA-------- -------CCAAAAAAAAAAAAAA------- -------AAAAAAAAAAAAAAAA------- -------AAAAAAAAAAAAAAAA------- ------AAAAAAAAAAAAAAAAAA------ ------AAAAAAAAAAAAAAAAAA------ ------AAAAAAAAAAAAAAAAAA------ -----AAAAAAAAAAAAAAAAAAAA----- -----AAAAAAAAAAAAAAAAAAAA----- AA---AAAAAAAAAAAAAAAAAAAA---AA AAA--AAAAAAAAAAAAAAAAAAAA--AAA AAAAAAAAAAAAAAAAAAAAAAAAAAAAAA --AAAAAAAAAAAAAAAAAAAAAAAAAA-- --AAAAAAAAAAAA--AAAAAAAAAAAA-- --CAAAAAAAAAA----AAAAAAAAAAA-- -----AAACAAA------AAAAAAA----- -----AAAA------------AADA----- 
------A----------------A------ -------AAA----------AAA------- --------AA----------AA-------- ---------E----------E--------- ---------E----------E--------- ---------E----------E--------- ------------------------------ ------------------------------ --------A------------A-------- --------C------------D-------- --------C------------D-------- -------C--------------A------- -------A--------------D------- -------A--------------D------- ------A----------------A------ ------D----------------C------ ------A----------------A------ ------------------------------ ------------------------------ AA--------------------------AC AAA------------------------AAA DDAAAAA----------------AAAAAAD --DAAAA----------------AAAAA-- --AAAAA----------------AAAAA-- --AAAAA----------------AADDA-- -----AAA---------------AA----- -----AAAA------------ACDD----- 
------A----------------A------ -------DAA----------AAA------- --------AA----------AA-------- ---------E----------E--------- ---------F----------F--------- ---------E----------E--------- ------------------------------ ------------------------------ --------A------------A-------- --------C------------A-------- --------A------------A-------- -------D--------------A------- -------D--------------A------- -------D--------------A------- ------A----------------D------ ------A----------------A------ ------A----------------A------ ------------------------------ ------------------------------ CA--------------------------AA AAA------------------------AAA CAAAAAA----------------AAAAAAC --AAAAA----------------AAAAD-- --AAAAA----------------AAAAA-- --AAAAA----------------AAAAA-- -----AAA---------------AD----- -----CADA------------AADD----- 
------C----------------A------ -------DAA----------AAA------- --------AA----------AA-------- ---------E----------E--------- ---------E----------E--------- ---------E----------E--------- ------------------------------ ------------------------------ --------A------------C-------- --------A------------A-------- --------A------------D-------- -------D--------------C------- -------D--------------C------- -------C--------------A------- ------C----------------D------ ------A----------------C------ ------A----------------A------ ------------------------------ ------------------------------ AA--------------------------AC AAA------------------------AAA AAAAAAA----------------AAAAAAD --AAAAA----------------AAAAA-- --CAAAA----------------AAAAA-- --AADAA----------------AAADA-- -----AAA---------------AA----- -----ADAA------------AADD----- 
------AAAAAAAAAAAAAAAAAA------ -------DAAAAAAAAAAAAAAA------- --------AAAAAAAAAAAAAA-------- ---------FAAAAAAAAAAF--------- ---------FAAAAAAAAAAF--------- ---------FAAAAAAAAAAF--------- ----------AAAAAAAAAA---------- ----------AAAAAAAAAA---------- --------AAAAAAAAAAAAAA-------- --------AAAAAAAAAAAAAA-------- --------AAAAAAAAAAAAAC-------- -------AAAAAAAAAAAAAAAA------- -------AAAAAAAAAAAAAAAA------- -------AAAAAAAAAAAAAAAA------- ------AAAAAAAAAAAAAAAAAA------ ------AAAAAAAAAAAAAAAAAA------ ------AAAAAAAAAAAAAAAAAA------ -----AAAAAAAAAAAAAAAAAAAA----- -----AAAAAAAAAAAAAAAAAAAA----- AA---AAAAAAAAAAAAAAAAAAAA---AA AAA--AAAAAAAAAAAAAAAAAAAA--AAA AAAAAAAAAAAAAAAAAAAAAAAAAAAAAA --AAAAAAAAAAAAAAAAAAAAAAAAAA-- --AAAAAAAAAAAA--AAAAAAAAAAAA-- --AAAAAAAAAAA----AAAAAAAAAAA-- -----AAACAAA------AAAAAAA----- -----AAAA------------AAAA----- 
------BDBBBDBBBBBBBBBDBB------ -------DDBDBBBBDBDBDDBB------- --------BDBBDBBBBBBBBB-------- ---------EEEFEEEFEEEF--------- ---------EFEFEFEFEFEF--------- ---------EEEFEEEFEEEF--------- ----------BBBBBBBBBB---------- ----------CCCCBBCCCC---------- --------DCDCCCBBCCCCCC-------- --------BDBBBBBBBBBBBB-------- --------CDCCCCBBCCCCDC-------- -------DCCCCCCBBCCCDCCC------- -------BDDBBBBBBBBBBBDB------- -------CDCCCCCBBCCCDCCC------- ------CCDCDCCCBBCCCCCDCC------ ------DDBDBBBBBBBBBBBDBB------ ------CCCCCCCCBBCCCDCCCC------ -----CDDDCCCCCBBCCCCCCDCC----- -----BBBBBBBBBBBBBCBBBBBB----- AA---BCBCCBBCCBBCCCBCCBCB---BB BBB--BCBCCBCCBBBBCCBDCBCB--BCB BCBBBBCBDCBDCCBBCCCBCCBCBBBBBB --BCCBCBCCBCCBGGBCDBCCBCBDCB-- --BCCBCBCCBCBG--GBCBCBBCBCCB-- --BBBBCBCCBBG----GBBCBBCBBBB-- -----BCBCCBG------GBCBBCB----- -----BBBBB----------BBBBB----- 
