model
size = 20 27 15, scale = 0.05, origin = -y
material 
  colors = A:#369 B:#069 C:#C90 D:#3CF E:#093 F:#0F3
voxels
-------------------- -------------------- -------------------- -------------------- -------------------- -------------------- -------------------- -------------------- -------------------- -------------------- -------------------- -------------------- -------------------- -------------------- ---------C---------- --------ABC--------- -------AADCB-------- -------AADCA-------- -------AAADCC------- ------AAAAADCA------ -----AABAAADCCA----- ----BAEAEAAADCB----- ----BBAABAAAACCA---- ----ABA-----BACC---- ---AAB-------BECA--- -------------------- -------------------- 
-------------------- -------------------- -------------------- -------------------- -------------------- -------------------- -------------------- -------------------- ---------A---------- ---------AB--------- ---------AB--------- --------AAAB-------- -------ABAAAA------- -------AABBBA------- ------BABABBAA------ -----ABAAAAAAA------ -----DBAAAAAAAA----- ----AAAAAAAAAAA----- ----ABAAAAAAAAAA---- ---BAAAAAAAAAAAE---- --AAAAAAAAAAAAAA---- -ABAAAAAAAAAAAAAAA-- -AEBAAAAAAAAAAAAAAA- -AABAAA-----AAAAAAA- -BAAAA-------BAAAB-- ---BA---------AC---- -------------------- 
--------A----------- --------BAB--------- -------ABBCA-------- -------AABCCB------- ------AAAAACB------- -----AAAAADAC------- ----BAEAABADCC------ ---AABAAAAAADC------ ---FFFABAAAAADC----- --AEAAAAAAAABACCA--- --FFFAABAAAABADCAA-- -AAAABAAAAAAABACCA-- -AAAABAAAAAAAABACAB- -AABAAAAAAAAAABACCE- AABAABAAAAAAAAABACC- AAEBAAAAAAAAAAABBAC- BAAADAAAAAAAAAAABAA- BEADAAAAAAAAAAAABAE- BADAAAAAAAAAAAAAABA- AAAAAAAAAAAAAAAABBB- AAAAAAAAAAAAAAAAAAAB AAAAAAAAAAAAAAAAAAAE AAAAAAAAAAAAAAAAAAB- AAAAAAA-----AAAAAAA- -BBAAB-------BAAAB-- ---CA--------BAC---- ----A---------A----- 
-------------------- -------AA----------- ------AAAA---------- ------AAAAA--------- -----AAAAAAAAB------ ----AAAAAAAAABB----- ---AAAAAAAAAAABB---- ---AAAAAAAAAAACBA--- --FAAAAAAAAAAAAAA--- --AAAAAAAAAAAAAAA--- -FAAAAAAAAAAAAAAAB-- -BAAAAAAAAAAAAAAAA-- -BAAAAAAAAAAAAAAAAA- BAAAAAAAAAAAAAAAAAA- BAAAAAAAAAAAAAAAAAA- EAAAAAAAAAAAAAAAAAB- BAAAAAAAAAAAAAAAAAC- BAAAAAAAAAAAAAAAAAB- BAAAAAAAAAAAAAAAAAA- BAAAAAAAAAAAAAAAAAA- BAAAAAAAAAAAAAAAAAA- EAAAAAAAAAAAAAAAAAAA BAAAAAA-----AAAAAAA- AAAAAB-------BAAAAA- -ABAAB-------BAABB-- ---CAB-------AAC---- ----A--------BE----- 
-------------------- -------AB----------- ------ABBA---------- ------BBBBB--------- -----AABBBABBA------ ----BBABBBBBBBA----- ---ABBBBBBBBBBAA---- ---BBBBBBBBBBBBAA--- --FBBBBB-BBBBBBAB--- --DBBB-----BBBBBB--- -FBBBB-----BBBBBBA-- -ABBB---B---BBBBBB-- -BBBBB-----BBBBBBBB- DBBBBB-----BBBBBBBB- ABBBBBBB-BBBBBBBBBB- DBBBBBBBBBBBBBBBBBB- BBBBBBBBBBBBBBBBBBC- EBBBBBBBBBBBBBBBBBC- BBBBBBBBBBBBBBBBBBB- BBBBBBBBB-ABBBBBBBB- BBBBBBBB---ABBBBBBB- BBBBBBA-----ABBBBBBA AAAAAA-------ABBBBA- AAAAAA-------AAAAAA- -DAAAB-------BAABA-- ---CAB-------AAC---- ----EB-------BD----- 
-------------------- -------------------- -------------------- -------------------- -------------------- -------------------- -------------------- -------------------- -------------------- -------------------- -------------------- -------------------- -------------------- -------------------- -------------------- -------------------- -------------------- -------------------- -------------------- -------------------- -------------------- -------------------- -AAAA--------------- AAAAA---------AAAA-- -AAAAB-------BAAAA-- ---CAB-------BAC---- ----AB-------AA----- 
-------------------- -------------------- -------------------- -------------------- -------------------- -------------------- -------------------- -------------------- -------------------- -------------------- -------------------- -------------------- -------------------- -------------------- -------------------- -------------------- -------------------- -------------------- -------------------- -------------------- -------------------- -------------------- -------------------- -AAAA--------------- -DAAAA-------BAAA--- ---CAB-------BAC---- ----AB-------AD----- 
-------------------- -------------------- -------------------- -------------------- -------------------- -------------------- -------------------- -------------------- -------------------- -------------------- -------------------- -------------------- -------------------- -------------------- -------------------- -------------------- -------------------- -------------------- -------------------- -------------------- -------------------- -------------------- -------------------- --AAA--------------- --CAAB-------AAA---- ---CAA-------AAC---- ----EB-------AA----- 
-------------------- -------------------- -------------------- -------------------- -------------------- -------------------- -------------------- -------------------- -------------------- -------------------- -------------------- -------------------- -------------------- -------------------- -------------------- -------------------- -------------------- -------------------- -------------------- -------------------- -------------------- -------------------- -------------------- --AAA--------------- --CAAB-------------- ---AAB-------AA----- ----AB-------AA----- 
-------------------- -------------------- -------------------- -------------------- -------------------- -------------------- -------------------- -------------------- -------------------- -------------------- -------------------- -------------------- -------------------- -------------------- -------------------- -------------------- -------------------- -------------------- -------------------- -------------------- -------------------- -------------------- -------------------- ----A--------------- ---AAB-------------- ---EAA-------AA----- -----A-------A------ 
-------------------- -------------------- -------------------- -------------------- -------------------- -------------------- -------------------- -------------------- -------------------- -------------------- -------------------- -------------------- -------------------- -------------------- -------------------- -------------------- -------------------- -------------------- -------------------- -------------------- -------------------- -------------------- -------------------- -----A-------------- ----AAAA---AAAA----- ----AAA-----AAE----- -------------------- 
-------------------- -------------------- -------------------- -------------------- -------------------- -------------------- -------------------- -------------------- -------------------- -------------------- -------------------- -------------------- -------------------- -------------------- -------------------- -------------------- -------------------- -------------------- -------------------- -------------------- -------------------- -------------------- -----------AA------- -----AAA--AAAA------ -----EAAA-AAAA------ -----AA-----AA------ -------------------- 
-------------------- -------------------- -------------------- -------------------- -------------------- -------------------- -------------------- -------------------- -------------------- -------------------- -------------------- -------------------- -------------------- -------------------- -------------------- -------------------- -------------------- -------------------- -------------------- -------------------- -------------------- -------------------- ------AAA-AAAA------ -----AAAAAAAAA------ ------AAAAAADA------ -------------------- -------------------- 
-------------------- -------------------- -------------------- -------------------- -------------------- -------------------- -------------------- -------------------- -------------------- -------------------- -------------------- -------------------- -------------------- -------------------- -------------------- -------------------- -------------------- -------------------- -------------------- ------A-----AA------ ------AA---AAA------ ------AA---AEA------ ------AAA-BBAA------ ------ABBAABA------- -------AAAAA-------- -------------------- -------------------- 
-------------------- -------------------- -------------------- -------------------- -------------------- -------------------- -------------------- -------------------- -------------------- -------------------- -------------------- -------------------- -------------------- -------------------- -------------------- -------------------- -------------------- -------------------- -------------------- -------------------- -------------------- -------------------- -------------------- ---------AA--------- ---------AA--------- -------------------- -------------------- 
