model
size = 16 22 20, scale = 0.05, origin = -y
material 
  colors = A:#84492C B:#000 C:#94453E
voxels
---------------- ---------------- ---------------- ---------------- ---------------- ---------------- ---------------- ---------------- ---------------- ---------------- ---------------- ---------------- -----AAAAAAA---- -----AAAAAAA---- ----AAAAAAAA---- ----AAAAAAAA---- ----AAAAAAAA---- ----AAAAAAAA---- ----AAAAAAAA---- -----AAAAA------ ------AAAA------ ---------------- 
---------------- ---------------- ---------------- ---------------- ---------------- -------AAAAA---- -------AAAAA---- -------AAAAA---- -------AAAAA---- --------AAAA---- --------AAAA---- ---------AAA---- -----AAAAAAA---- -----AAAAAAA---- -AAAAAAAAAAA---- -AAAAAAAAAAA---- ----AAAAAAAA---- ----AAAAAAAA---- -----AAAAAAA---- -----AAAAAAA---- -----AAAAA------ ---------------- 
---------------- ---------------- ---------------- ---------A------ --------A------- -------AAAAA---- -------AAAAA---- -------AAAAA---- -------AAAAA---- --AAAAAAAAAA---- -AAAAAAAAAAA---- -AAAAAAA-AAA---- -AAAAAAAAAAA---- AAAAAAAAAAAA---- AAAAAAAAAAAAA--- AAAAAAAAAAAAA--- AAAAAAAAAAAAA--- AAAAAAAAAAAA---- AAAAAAAAAAAA---- -AAAAAAA-AAA---- ---AAAAA-------- ---------------- 
---------------- ---------------- --------AAAA---- -------AAAAA---- -------ACAAA---- ------AABBAA---- ------ABABBA---- ------AAAAAA---- --AAAAAAAAAA---- -AAAAAAAAAAA---- -AAAAAAAAAAA---- -AAAAAAAAAAA---- AAAAAAAAAAAA---- AAAAAAAAAAAA---- AAAAAAAAAAAAAA-- AAAAAAAA-AAAAA-- AAAAAAAA-AAAAA-- AAAAAAAA-AAAAAAA AAAAAAAA-AAAA--- -AAAAAAA-AAAA--- ---------------- ---------------- 
----AAAA-------- ----AAAAAAAA---- --AAAAAAAAAAA--- --AAAAAAAC-AA--- --AAAAAAAAAAA--- --AAAAAABBA-A--- --AAAAABA---A--- --AAAAAA----A--- -AAAAAAA----A--- -AAAAAAAAAAAA--- -AAAAAAAAAAAA--- -AAAAAAAAAAAA--- AAAAAAAAAAAAAA-- AAAAAAAAAAAAAA-- AAAAAAAAAAAAAA-- AAAAAAAAAAAAAA-- AAAAAAAAAAAAAA-- AAAAAAAAAAAAAAAA AAAAAAAAAAAAA--- -AAAAAAA-AAAA--- -AAAAAAA-AAA---- ---------------- 
-----AAA-------- --A-AAAAAAAAAA-- --AAAAAAAAAAAA-- --AAAAAAAAAAAA-- ----AAAAA-AAAA-- ----AAAA--AAAA-- ----AAAB--AAAA-- ----AAAA--AAAA-- ---AAAAAAAAAAAA- -AAAAAAAAAAAAAA- -AAAAAAAAAAAAAAA AAAAAAAAAAAAAAAA AAAAAAAAA-AAAAAA AAAAAAAAA-AAAAAA AAAAAAAAA-AAAAAA AAAAAAAAA-AAAAAA AAAAAAAAA-AAAAAA AAAAAAAAAAAAAAAA AAAAAAAAAAAAA--- -AAAAAAA-AAAA--- -AAAAAA-AAAA---- ---------------- 
-----AAA-------- AAA-AAAAAAAAAAA- AAAAAAAAAAAAAAA- AAAAAAAAAAAAAAA- --AAAAAAA-AAAAA- AAAAAAAB--AAAAA- AAAAAAAA--AAAAA- AAAAAAAA--AAAAA- --AAAAAAAAAAAAA- -AAAAAAAAAAAAAAA -AAAAAAAAAAAAAAA AAAAAAAAAAAAAAAA AAAAAAAAA-AAAAAA AAAAAAAAA-AAAAAA AAAAAAAAA-AAAAAA AAAAAAAAA-AAAAAA AAAAAAAAA-AAAAAA AAAAAAAAAAAAAAAA AAAAAAAAAAAAA--- -AAAAAAA-AAAA--- -AAAAAAAAAAAA--- ---AA----------- 
----AAAA-------- AAAAAAAAAAAAAAAA AAAAAAAAAAAAAAA- AABBBAAAAAAAAAA- --AAAABBBAAAAAA- AAAAAAAAAAAAAAA- AAAAAAAAAAAAAAA- AAAAAAAAAAAAAAA- --AAAAAAAAAAAAA- -AAAAAAAAAAAAAA- -AAAAAAAAAAAAAA- AAAAAAAAAAAAAAAA AAAAAAAAAAAAAAAA AAAAAAAAAAAAAAAA AAAAAAAAAAAAAAAA AAAAAAAAAAAAAAAA AAAAAAAAAAAAAAAA AAAAAAAAAAAAAAAA AAAAAAAAAAAAA--- -AAAAAAA---AA--- -AAAAAAAAAAAA--- --AAA----------- 
----AAAA-------- AAAAAAAAAAAA-AAA AAAAAAAAAAAA-AAA AABAAAAAAAAAAAA- --AAAAAAAAAAAAA- AAAAAAAA-AAAAAA- AAAAAAAA-AAAAAA- AAAAAAAAAAAAAAA- --AAAAAAAAAAAAA- -AAAAAAAAAAAAAA- -AAAAAAAAAAAAAA- -AAAAAAAAAAAAAA- AAAAAAAAAAAAAAA- AAAAAAAAAAAAAAA- AAAAAAAAAAAAAAA- AAAAAAAAAAAAAAA- AAAAAAAAAAAAAAA- AAAAAAAAAAAAAAA- AAAAAAAAAAAAA--- -AAAAAAAAAAAA--- -AAAAAAAAAAAA--- --AAA----------- 
----AAAA-------- -----AAA-AAAAAA- --A---AAAAAAAAA- --A---AAAAAAAAA- --AA--AAAAAAAAA- ---AAAAA-AAAAAA- ---AAAAA-AAAAAA- ---AAAAAAAAAAAA- --AAAAAAAAAAAAA- -AAAAAAAAAAAAAA- -AAAAAAAAAAAAAA- -AAAAAAAAAAAAAA- -AAAAAAAAAAAAAA- -AAAAAAAAAAAAAA- ---AAAAAAAAAAAA- ---AAAAAAAAAAAA- ---AAAAAAAAAAAA- ---AAAAAAAAAAAA- ---AAAAAAAAAA--- ---AAAAAAAAAA--- ---AAAAAAAAAA--- ---AA----------- 
----AAAA-------- AAAAAAAAAAAAAAAA AAAAAAAAAAAAAAAA AAABBAAAAAAAAAA- --AAAABBAAAAAAA- AAAAAABA-AAAAAA- AAAAAAAA-AAAAAA- AAAAAAA-BAAAAAA- --AAAAA--AAAAAA- -AAAAAA--AAAAAA- -AAAAAAAAAAAAAA- -AAAAAAAAAAAAAAA AAAAAAAAAAAAAAAA AAAAAAAAAAAAAAAA AAAAAAAAAAAAAAAA AAAAAAAAAAAAAAAA AAAAAAAAAAAAAAAA AAAAAAAAAAAAAAAA AAAAAAAAAAAAA--- -AAAAAAAAAAAA--- -AAAAAAAAAAAA--- --AAA----------- 
----AAAA-------- AAAAAAAAAAAAAAAA AAAAAAAAAAAAAAA- AAAAAAAAAAAAAAA- --AAAAAAAAAAAAA- AAAAAAAB-AAAAAA- AAAAAAAA-AAAAAA- AAAAAAAAAAAAAAA- --AAAAA--AAAAAA- -AAAAAA--AAAAAAA -AAAAAAAAAAAAAAA AAAAAAAAAAAAAAAA AAAAAAAAAAAAAAAA AAAAAAAAAAAAAAAA AAAAAAAAAAAAAAAA AAAAAAAAAAAAAAAA AAAAAAAAAAAAAAAA AAAAAA-AAAAAAAAA AAAAAAAAAAAAA--- -AAAAAAAAAAAA--- -AAAAAAAAAAAA--- ---------------- 
-----AAA-------- AAAAAAAAAAAA-AA- AAAAAAAAAAAAAAA- AAAAAAAAAAAAAAA- --AAAAAA-AAAAAA- AAAAAAAA-AAAAAA- AAAAAAA--AAAAAA- AAAAAAAAAAA-AAA- --AAAAA--AA-AAA- -AAAAAA--AA-AAA- -AAAAAAAAAA-AAAA AAAAAAAAAAA-AAAA AAAAAAAAAAA-AAAA AAAAAAAAA--AAAAA AAAAAAAAAAAAAAAA AAAAAAAAAAAAAAAA AAAAAAAAAAAAAAAA AAAAAA-AAAAAAAAA AAAAAAAAAAAAA--- -AAAAAAAAAAAA--- -AAAAAAAAAAAA--- ---------------- 
----AAAA-------- ----AAAAAAAAAAA- ---AAAAAAAAAAAA- ---AAAAAAAAAAAA- ---AAAAAAAAAAAA- ---AAAAA-AAAAAA- ---AAAA--AAAAAA- ---AAAAAAAAAAAA- --AAAAAAAAAAAAA- -AAAAAAAAAAAAAA- -AAAAAAAAAAAAAA- AAAAAAAAAAAAAAA- AAAAAAAAAAAAAAA- AAAAAAAAA--AAAA- AAAAAAAAAAAAAAA- AAAAAAAAAAAAAAA- AAAAAAAAAAAAAAA- AAAAA--AAAAAAAAA AAAAA-AAAAAAA--- -AAAA-AAAAAAA--- -AAAAAAAAAAAA--- ---------------- 
-----AAA-------- -----AAAAAAAAA-- ---AAAAAAAAAAA-- ---AAAAAAAAAAA-- ---AAAAA---AAA-- ---AAAAA---AAA-- ---AAAA---AAAA-- ---AA--A--AAAA-- ---AAAAAAAAAAA-- -AAAAAAAAAAAAA-- -AAAAAAAAAAAAA-- AAAAAAAAAAAAAA-- AAAAAAAAAAAAAA-- AAAAAAAAAAAAAA-- AAAAAAAAAAAAAA-- AAAAAAAAAAAAAA-- AAAAAAA---AAAA-- AAAAAAAAAAAAAAAA AAAAAAAAAAAAA--- -AAAAAAAAAAAA--- -AAAAAAAAAAA---- ---------------- 
-------A-------- -------AA--AAA-- -------AA--AAA-- -------AAA-AAA-- -------AAA-AAA-- -------AAA-AAA-- -------AAA-AAA-- ---AA--AAA-AAA-- ---AAAAAAA-AAA-- -AAAAAAAAAAAAA-- -AAAAAAAAAAAAA-- -AAAAAAAAAAAAA-- -AAAAAAAAAAAAA-- AAAAAAAAAAAAAA-- AAAAAAAAAAAAAA-- AAAAAAAAAAAAA--- AAAAAAA---AAA--- AAAAAAAAAAAAA--- AAAAAAAAAAAAA--- -AAAAAAAAAAAA--- -AAAAAAAAAAA---- ---------------- 
---------------- --------A-AAA--- --------A-AAA--- --------AAAAAA-- --------AAAAAA-- --------AAAAAA-- --------AA-AAA-- -------AAA-AAA-- -----AAAAA-AAA-- -AAAAAAAAAAAAA-- -AAAAAAAAAAAAA-- -AAAAAAAAAAAAA-- -AAAAAAAAAAAAA-- AAAAAAAAAAAAAA-- AAAAAAAAAAAAAA-- AAAAAAAAAAAAA--- AAAAA-----AAA--- AAAAAAAAAAAAA--- AAAAAAAAAAAAA--- -AAAAAAAAAAAA--- -AAAAAAAAAAA---- ---------------- 
---------------- ---------------- ---------------- ---------------- ---------------- ---------------- ---------------- -----------AAA-- -----------AAA-- -----AAAAAAAAA-- ----AAAAAAAAAA-- ----AAAAAAAAAA-- --A-AAAAAAAAAA-- -AAAAAAAAAAAAA-- -AAAAAAAAAAAAA-- -----AAAAAAAA--- -----------AA--- ---AAAAA---AA--- ---AAAA----AA--- ---AAAAAAAAAA--- ---AAAAAAAAA---- ---------------- 
---------------- ---------------- ---------------- ---------------- ---------------- ---------------- ---------------- ---------------- ----------AAA--- -----AAAAAAAA--- ----AAAAAAAAA--- ----AAAAAAAAA--- ----AAAAAAAAA--- --AAAAAAAAAAA--- --AAAAAAAA------ ---AAAAAAAA----- ----AAAAAAA----- ---AAAAAAAA----- ---AA----------- ---AA-AAAAAA---- ------AAAAAA---- ---------------- 
---------------- ---------------- ---------------- ---------------- ---------------- ---------------- ---------------- ---------------- -----------A---- -----------A---- -----------A---- -----------A---- -----------A---- ---------------- ---------------- ---------------- ---------------- ---------------- ---------------- ---------------- ---------------- ---------------- 
