model
size = 11 14 19, scale = 0.05, origin = -y
material 
  colors = A:#000 B:#D9CDC1 C:#84492C D:#EDE8FF E:#FFF F:#1E1729
voxels
----------- ----------- ----------- ----------- ----------- -----AAAA-- -----AAAA-- ----AAAAA-- ----AAAAA-- ----AAAAA-- ----AAAAA-- ----AAAAA-- -----AAAA-- ------AAA-- 
--A-------- --AA------- --AA------- -AAAAAAAAA- -AAAAAAAAA- -AAAAAAAAA- -AAAAAAAAA- -AAAAAAAAA- -AAAAAAAAA- -AAAAAAAAA- -AAAAAAAAA- -----AAAAA- -----AAAAA- -----AAAAA- 
--A-------- -AAAAAAAAAA -AAAAAAAAAA -AAAAAAAAAA -AAAAAAAAA- -AAAAAAAAA- -AAAAAAAAA- -AAAAAAAAA- -AAAAAAAAA- -AAAAAAAAA- -AAAAAAAAA- --AAAAAAAA- -AAAAAAA-A- -AAAAAAA-A- 
--A-------- -AAAAAAAAAA -AAAAAAAAAA -ABBBBBBBCA -ABBBBBBBCA -ABBBBBBBCA -ABBBBBBBCA -ABCCCCCCCA -ABCCCCCACA -ACCCCCCACA -ACCCCCCACA -ACCCCCC-AA --AAAAAA-A- --A------AA 
--A-------- -AAAAAAAAAA -AAAAAAAAAA -ABBBBBBBCA -ABBAAAAAAA -ABBAAAAAAA -ABBAAAAAAA -ABBAAAAAAA -ABBAAAAAAA -ABCAAAAAAA -ABCAAAAAAA --BCAAAAAAA -BECAAAA-A- -BEAAAAA-AA 
--A-------- -AAAAAAAAAA -AAAAAAAAAA -A-BBBBBBCA -ABBAAAAAAA -A-BAAAAA-A -ABBAAAAA-A -ABBAAAAA-A -ABBAAAAA-A -ABCAAAAA-A --BCAAAAAAA -BBCAAAAAAA -BECAAAA-A- -BEAAAA-AAA 
--A-------- -AAAAAAAAAA -AAAAAAAAAA --ABBBBBBCA -BBBAAAAAAA --BBAAAAA-A -BBBAAAAA-A --BBAAAAA-A -BBBAAAAA-A -BBCAAAAA-A -BBCAAAAAAA DFBCAAAAAAA DFECAAAA-A- DD-EAAAAAAA 
----------- AAAAAAAAAAA -AAAAAAAAAA ---BBCCCCCA --BBAAAAAAA ---BAAAAAAA --BBAAAAAAA ---BAAAAAAA --BBAAAAAAA ---BAAAAAAA --BCAAAAAAA DDBCAAAAAAA DFECAAAA--- DD-EAAAAAAA 
----------- AAAAAAAAAAA -AAAAAAAAAA ---BBCCCCCA --BBAAAAAAA ---BAAAAAAA --BBAAAAAAA ---BAAAAAAA --BBAAAAAAA ---BAAAAAAA --BCAAAAAAA DDBCAAAAAAA DFECAAAAAA- DD-EAAAAAAA 
----------- AAAAAAAAAAA -AAAAAAAAAA ---BBCCCCCA --BBAAAAAAA ---BAAAAAAA --BBAAAAAAA ---BAAAAAAA --BBAAAAAAA ---BAAAAAAA --BBAAAAAAA --BBAAAAAAA DD-EAAAAAA- ---EAAAAAAA 
----------- AAAAAAAAAAA -AAAAAAAAAA ---BBCCCCCA --BBAAAAAAA ---BAAAAAAA --BBAAAAAAA ---BAAAAAAA --BBAAAAAAA ---BAAAAAAA --BBAAAAAAA DDBBAAAAAAA DFECAAAAAA- DD-EAAAAAAA 
----------- AAAAAAAAAAA -AAAAAAAAAA ---BBCCCCCA --BBAAAAAAA ---BAAAAAAA --BBAAAAAAA ---BAAAAAAA --BBAAAAAAA ---BAAAAAAA --BBAA-AAAA DDBBAAAAAAA DFECAAAAAA- DD-EAAAAAAA 
----------- -AAAAAAAAAA -AAAAAAAAAA --ABBCCCCCA -BBBAAAAAAA --BBAAAAAAA -BBBAAAAA-A ---BAAAAAAA -BBBAAAAAAA -BBBAAAAAAA -BBBAA-AAAA DFBBAAAAAAA DFECAAAAAA- DD-EAAAAAAA 
--A-------- -AAAAAAAAAA -AAAAAAAAAA -AABBCCCCCA -ABBAAAAAAA -AABAAAAAAA -ABBAAAAA-A -ABBAAAAAAA -ABBAAAAAAA -ABBAAAAAAA --BBA--AAAA -BBBA-AAAAA -BECA-AAAA- -BEAAAAAAAA 
--A-------- -AAAAAAAAAA -AAAAAAAAAA -ABBBBBBBBA -ABBAAAAAAA -ABBAAAAAAA -ABBAAAAAAA -ABBAAAAAAA -ABBAAAAAAA -ABBAAA---A -ABBAAAAAAA --BBAAAAAAA -BECAAAAAA- -BEAAAAAAAA 
--A-------- -AAAAAAAAAA -AAAAAAAAAA -ABBBBBBBBA -ABBAAAAAAA -ABBAAAAAAA -ABBAAAAAAA -ABBAAAAAAA -ABBAAAAAAA -ACCAAAAAAA -ACCAAAAAAA -ACCAAAAAAA --ACAAAAAA- --AAAAAAAAA 
--A-------- -AAAAAAAAAA -AAAAAAAAAA -AAAAAAAABA -AAAAAAAAAA -AAAAAAAAAA -AAAAAAAAAA -AAAAAAAAAA -AAAAAAAAAA -AAAAAAAAAA -AAAAAAAAAA -AAAAAAAAAA -AAAAAAAAA- -AAAAAAAAAA 
----------- -AAAAAAAAAA -AAAAAAAAAA -AAAAAAAABA -AAAAAAAAAA -AAAAAAAAAA -AAAAAAAAAA -AAAAAAAAAA -AAAAAAAAAA -AAAAAAAAAA -AAAAAAAAAA -AAAAAAAAAA -AAAAAAAAA- -----AAAAAA 
----------- ----------- ----------- -AAAAAAAAA- -AAAAAAAAA- -AAAAAAAAA- -AAAAAAAAA- -AAAAAAAAA- -AAAAAAAAA- -AAAAAAAAA- -AAAAAAAAA- -AAAAAAAAA- -AAAAAAAAA- ------AAAA- 
