model
size = 11 14 19, scale = 0.05, origin = -y
material 
  colors = A:#D9CDC1 B:#FFF
voxels
----------- ----------- ----------- ----------- ----------- ----------- ----------- ----------- ----AAAAA-- ----AAAAA-- ----AAAAA-- ----AAAAA-- -----AAAA-- ------AAA-- 
----------- ----------- ----------- ----------- ----------- ----------- ----------- ----------- -AAAAAAAAA- -AAAAAAAAA- -AAAAAAAAA- -----AAAAA- -----AAAAA- -----AAAAA- 
--A-------- -AA-------- --A-------- -AA-------- -AA-------- -AA-------- -AA-------- -AA-------- -AAAAAAAAA- -AAAAAAAAA- -AAAAAAAAA- --AAAAAAAA- -AAAAAAAAA- -AAAAAAAAA- 
--A-------- -AA-------- --AAAAAAAAA -AAAAAAAAAA -AAAAAAAAAA -AAAAAAAAAA -AAAAAAAAAA -AAAAAAAAAA -AAAAAAAAAA -AAAAAAAAAA -AAAAAAAAAA -AAAAAAA-AA --AAAAAAAAA -AAAAAAAAAA 
--A-------- -AA-------- -AAAAAAAAAA -AAAAAAAAAA -AAAAAAAAAA -AAAAAAAAAA -AAAAAAAAAA -AAAAAAAAAA -AAAAAAAAAA -AAAAAAAAAA -AAAAAAAAAA --AAAAAAAAA -AAAAAAAAAA -AAAAAAAAAA 
--A-------- -AAAAAAAAAA -AAAAAAAAAA -A-AAAAAAAA -AAAAAAAAAA -A-AAAAAA-A -AAAAAAAA-A -AAAAAAAA-A -AAAAAAAA-A -AAAAAAAA-A --AAAAAAAAA -AAAAAAAAAA -AAAAAAA-AA -AAAAAAAAAA 
--A-------- -AAAAAAAAAA -AAAAAAAAAA --AAAAAAAAA -AAAAAAAAAA --AAAAAAA-A -AAAAAAAA-A --AAAAAAA-A -AAAAAAAA-A --AAAAAAA-A -AAAAAAAAAA BAAAAAAAAAA BAAAAAAA-AA BAAAAAAAAAA 
----------- AAAAAAAAAAA -AAAAAAAAAA ---AAAAAAAA --AAAAAAAAA ---AAAAAAAA --AAAAAAAAA ---AAAAAAAA --AAAAAAAAA ---AAAAAAAA --AAAAAAAAA BAAAAAAAAAA BAAAAAAA--A BAAAAAAAAAA 
----------- AAAAAAAAAAA -AAAAAAAAAA ---AAAAAAAA --AAAAAAAAA ---AAAAAAAA --AAAAAAAAA ---AAAAAAAA --AAAAAAAAA ---AAAAAAAA --AAAAAAAAA BAAAAAAAAAA BAAAAAAAAAA BAAAAAAAAAA 
----------- AAAAAAAAAAA -AAAAAAAAAA ---BAAAAAAA --AAAAAAAAA ---BAAAAAAA --AAAAAAAAA ---BAAAAAAA --AAAAAAAAA ---BAAAAAAA --AAAAAAAAA --AAAAAAAAA -B-AAAAAAAA -AAAAAAAAAA 
----------- AAAAAAAAAAA -AAAAAAAAAA ---AAAAAAAA --AAAAAAAAA ---AAAAAAAA --AAAAAAAAA ---AAAAAAAA --AAAAAAAAA ---AAAAAAAA --AAAAAAAAA BAAAAAAAAAA BAAAAAAAAAA BAAAAAAAAAA 
----------- AAAAAAAAAAA -AAAAAAAAAA ---AAAAAAAA --AAAAAAAAA ---AAAAAAAA --AAAAAAAAA ---AAAAAAAA --AAAAAAAAA ---AAAAAAAA --AAAA-AAAA BAAAAAAAAAA BAAAAAAAAAA BAAAAAAAAAA 
----------- -AAAAAAAAAA -AAAAAAAAAA --AAAAAAAAA -AAAAAAAAAA --AAAAAAAAA -AAAAAAAA-A ---AAAAAAAA -AAAAAAAAAA --AAAAAAAAA -AAAAA-AAAA BAAAAAAAAAA BAAAAAAAAAA BAAAAAAAAAA 
--A-------- -AAAAAAAAAA -AAAAAAAAAA -AAAAAAAAAA -AAAAAAAAAA -AAAAAAAAAA -AAAAAAAA-A -AAAAAAAAAA -AAAAAAAAAA -AAAAAAAAAA --AAA--AAAA -AAAA-AAAAA -AAAA-AAAAA -AAAAAAAAAA 
--A-------- -AAAAAAAAAA -AAAAAAAAAA -AAAAAAAAAA -AAAAAAAAAA -AAAAAAAAAA -AAAAAAAAAA -AAAAAAAAAA -AAAAAAAAAA -AAAAAA---A -AAAAAAAAAA --AAAAAAAAA -AAAAAAAAAA -AAAAAAAAAA 
--A-------- -AAAAAAAAAA --AAAAAAAAA -AAAAAAAAAA -AAAAAAAAAA -AAAAAAAAAA -AAAAAAAAAA -AAAAAAAAAA -AAAAAAAAAA -AAAAAAAAAA -AAAAAAAAAA -AAAAAAAAAA --AAAAAAAAA -AAAAAAAAAA 
--A-------- -AAAAAAAAAA --AAAAAAAAA -AAAAAAAAAA -AAAAAAAAAA -AAAAAAAAAA -AAAAAAAAAA -AAAAAAAAAA -AAAAAAAAAA -AAAAAAAAAA -AAAAAAAAAA -AAAAAAAAAA -AAAAAAAAAA -AAAAAAAAAA 
----------- ----------- ----------- ----------- ----------- ----------- ----------- ----------- -AAAAAAAAAA -AAAAAAAAAA -AAAAAAAAAA ---AAAAAAAA ----AAAAAAA -----AAAAAA 
----------- ----------- ----------- ----------- ----------- ----------- ----------- ----------- --AAAAAAAA- --AAAAAAAA- --AAAAAAAA- ---AAAAAAA- -----AAAAA- ------AAAA- 
