model
size = 11 21 19, scale = 0.05, origin = -y
material 
  colors = A:#000 B:#D9CDC1 C:#84492C D:#1E1729 E:#FFF F:#94453E
voxels
----------- ----------- ----------- ----------- ----------- ----------- ----------- ----------- ----------- ----------- ----------- ----------- -----AAAA-- -----AAAA-- ----AAAAA-- ----AAAAA-- ----AAAAA-- ----AAAAA-- ----AAAAA-- -----AAAA-- ------AAA-- 
-AAAAAAAAA- -AAAAAAAAA- -AAAAAAAAA- -AAAAAAAAA- -AAAAAAAAA- -AAAAAAAAA- -AAAAAAAAA- -AAAAAAAAA- -AAAAAAAAA- -AAAAAAAAA- -AAAAAAAAA- -AAAAAAAAA- -AAAAAAAAA- -AAAAAAAAA- -AAAAAAAAA- -AAAAAAAAA- -AAAAAAAAA- -AAAAAAAAA- -----AAAAA- -----AAAAA- -----AAAAA- 
-AAAAAAAAAA -AAAAAAAAA- -AAAAAAAAA- -AAAAAAAACA -AAAAAAACA- -AAAAAAAAA- -AAAAAAAAA- -AAAAAAAAA- -AAAAAAAAA- -AAAAAAAAA- -AAAAAAAAA- -AAAAAAAAA- -AAAAAAAAA- -AAAAAAAAA- -AAAAAAAAA- -AAAAAAAAA- -AAAAAAAAA- -AAAAAAAAA- --AAAAAAAA- -AAAAAAA-A- -AAAAAAA-A- 
-AAAAAAAAAA -AAAAAAAAAA -AAAAAAABCA -AAAAAABBCA -AAAAAABBCA -AAAAABBBAA -AAAAABBBAA -AAAAABBBCA -AABBBBBBCA -ABBBBBBBCA -ABBBBBBBCA -ABBBBBBBCA -ABBBBBBBCA -ABBBBBBBCA -ABCCCCCCCA -ABCCCCCACA -ACCCCCCACA -ACCCCCCACA -ACCCCCC-AA --AAAAAA-A- --A------AA 
----ACCCAAA -A--BCCCCCA -ABBBBBBBCA -A--BBBBBFA -A--BBBBBCA -A--BBBBBAA -A--BBBBB-A -A--BBBB--A -A--BBBB--A -ABBBBBBBCA -ABBBBBBBCA -ABBAAAAAAA -ABBAAAAAAA -ABBAAAAAAA -ABBAAAAAAA -ABBAAAAAAA -ABCAAAAAAA -ABCAAAAAAA --BCAAAAAAA -BECAAAA-A- -BEAAAAA-AA 
-----BCCAAA -AB-BBCCCCA -ABBBBBBBCA -ABBBBBBBCA -A--BBBBB-A -A--BBBB--A -A--BBBB--A -A--BBBB--A -A--BBBBBCA -ABBBBBBBCA -A-BBBBBBCA -ABBAAAAAAA -A-BAAAAA-A -ABBAAAAA-A -ABBAAAAA-A -ABBAAAAA-A -ABCAAAAA-A --BCAAAAAAA -BBCAAAAAAA -BECAAAA-A- -BEAAAA-AAA 
-AAAABCCAAA -ABABBCCCCA -ABBBBBBBCA -ABBBBBBBCA -AABBBBBB-A -ABBBBBB--A -AABBBBB--A -ABBBBBB--A -AAABBBBBCA -ABBBBBBBCA --ABBBBBBCA -BBBAAAAAAA --BBAAAAA-A -BBBAAAAA-A --BBAAAAA-A -BBBAAAAA-A -BBCAAAAA-A -BBCAAAAAAA DDBCAAAAAAA DDECAAAA-A- DD-EAAAAAAA 
----ABCCAAA -ABBBBCCCCA -ABBBBCCCCA -ABBBBCCCCA -AABBBAAACA -ABBBBCCCCA -AABBBCCCCA -ABBBBCCCCA -AAABBCCCCA -ABBBBCCCCA ---BBCCCCCA --BBAAAAAAA ---BAAAAAAA --BBAAAAAAA ---BAAAAAAA --BBAAAAAAA --BCAAAAAAA --BCAAAAAAA DDBCAAAAAAA DDECAAAA--- DD-EAAAAAAA 
----ABCCAAA -ABBBBCCCCA -ABBBBCCCCA -ABBBBCCCCA -A-BBBCCCCA -ABBBBCC-CA -A-BBBCC-CA -ABBBBCCCCA ---ABBCCCCA --BBBBCCCCA ---BBCCCCCA --BBAAAAAAA ---BAAAAAAA --BBAAAAAAA ---BAAAAAAA --BBAAAAAAA --BCAAAAAAA --BCAAAAAAA DDBCAAAAAAA DDECAAAAAA- DD-EAAAAAAA 
-AAAABCCAAA -AAA-BCC-CA -ABA--CCCCA -ABA--CCCCA -ABB--CCCCA -ABBBBCC-CA -ABBBBCC-CA -ABBBBCCCCA ---BBBCCCCA --BBBBCCCCA ---BBCCCCCA --BBAAAAAAA ---BAAAAAAA --BBAAAAAAA ---BAAAAAAA --BBAAAAAAA --BBAAAAAAA --BBAAAAAAA --BBAAAAAAA DD-EAAAAAA- ---EAAAAAAA 
----ABCCAAA -ABBBBCCCCA -ABBBBCCCCA -ABBBBCCCCA -A-BBBAACCA -ABBBBAC-CA -A-BBBCC-CA -ABBBBC-ACA --ABBBC--CA --BBBBC--CA ---BBCCCCCA --BBAAAAAAA ---BAAAAAAA --BBAAAAAAA ---BAAAAAAA --BBAAAAAAA --BBAAAAAAA --BBAAAAAAA DDBBAAAAAAA DDECAAAAAA- DD-EAAAAAAA 
----ABCCAAA -ABBBBCCCCA -ABBBBCCCCA -ABBBBCCCCA -AABBBCCCCA -ABBBBCA-CA -AABBBCC-CA -ABBBBCCCCA -AABBBC--CA -ABBBBC--CA ---BBCCCCCA --BBAAAAAAA ---BAAAAAAA --BBAAAAAAA ---BAAAAAAA --BBAAAAAAA --BBAAAAAAA --BBAA-AAAA DDBBAAAAAAA DDECAAAAAA- DD-EAAAAAAA 
-AAAABCCAAA -ABBBBCCCCA -ABBBBCCCCA -ABBBBCCCCA -AABBBCC-CA -ABBBBCC-CA -AABBBC--CA -ABBBBCCCCA -AABBBC--CA -ABBBBC--CA --ABBCCCCCA -BBBAAAAAAA --BBAAAAAAA -BBBAAAAA-A ---BAAAAAAA -BBBAAAAAAA -BBBAAAAAAA -BBBAA-AAAA DDBBAAAAAAA DDECAAAAAA- DD-EAAAAAAA 
-AAABBCCAAA -AAABBCCCCA -AABBBCCCCA -AABBBCCCCA -AABBBCCCCA -AABBBCC-CA -AABBBC--CA -AABBBCCCCA -AABBBCCCCA -ABBBBCCCCA -AABBCCCCCA -ABBAAAAAAA -AABAAAAAAA -ABBAAAAA-A -ABBAAAAAAA -ABBAAAAAAA -ABBAAAAAAA --BBA--AAAA -BBBA-AAAAA -BECA-AAAA- -BEAAAAAAAA 
-A---BBBAAA -A---BBBBBA -A-BBBBBBBA -A-BBBBBBBA -A-BBBBB--A -A-BBBBB--A -A-BBBB---A -A-BB--B--A -A-BBBBBBBA -ABBBBBBBBA -ABBBBBBBBA -ABBAAAAAAA -ABBAAAAAAA -ABBAAAAAAA -ABBAAAAAAA -ABBAAAAAAA -ABBAAA---A -ABBAAAAAAA --BBAAAAAAA -BECAAAAAA- -BEAAAAAAAA 
-------BAAA -AAAAAABBAA -AAAAAABBAA -AAAAAABBBA -AAAAAABBBA -AAAAAABBBA -AAAAAABBBA -AABBAABBBA -AABBBBBBBA -ABBBBBBBBA -ABBBBBBBBA -ABBAAAAAAA -ABBAAAAAAA -ABBAAAAAAA -ABBAAAAAAA -ABBAAAAAAA -ACCAAAAAAA -ACCAAAAAAA -ACCAAAAAAA --ACAAAAAA- --AAAAAAAAA 
--------AAA -AAAAAAABAA -AAAAAAABAA -AAAAAAABBA -AAAAAAABBA -AAAAAAABBA -AAAAAAABBA -AAAAAAAABA -AAAAAAAABA -AAAAAAAABA -AAAAAAAABA -AAAAAAAAAA -AAAAAAAAAA -AAAAAAAAAA -AAAAAAAAAA -AAAAAAAAAA -AAAAAAAAAA -AAAAAAAAAA -AAAAAAAAAA -AAAAAAAAA- -AAAAAAAAAA 
----------- -AAAAAAAAAA -AAAAAAAAAA -AAAAAAAAAA -AAAAAAAAAA -AAAAAAAAAA -AAAAAAAAAA -AAAAAAAAAA -AAAAAAAAAA -AAAAAAAABA -AAAAAAAABA -AAAAAAAAAA -AAAAAAAAAA -AAAAAAAAAA -AAAAAAAAAA -AAAAAAAAAA -AAAAAAAAAA -AAAAAAAAAA -AAAAAAAAAA -AAAAAAAAA- -----AAAAAA 
----------- -AAAAAAAAA- -AAAAAAAAA- -AAAAAAAAA- -AAAAAAAAA- -AAAAAAAAA- -AAAAAAAAA- -AAAAAAAAA- -AAAAAAAAA- -AAAAAAAAA- -AAAAAAAAA- -AAAAAAAAA- -AAAAAAAAA- -AAAAAAAAA- -AAAAAAAAA- -AAAAAAAAA- -AAAAAAAAA- -AAAAAAAAA- -AAAAAAAAA- -AAAAAAAAA- ------AAAA- 
