model
size = 27 31 27, scale = 0.05, origin = -y
material 
  colors = A:#9CF
voxels
----------AAAAAAA---------- ----------AAAAAAA---------- -----------AAAAA----------- ------------AAA------------ --------------------------- --------------------------- --------------------------- --------------------------- --------------------------- --------------------------- --------------------------- --------------------------- --------------------------- --------------------------- --------------------------- --------------------------- --------------------------- --------------------------- --------------------------- --------------------------- --------------------------- --------------------------- --------------------------- --------------------------- --------------------------- --------------------------- --------------------------- --------------------------- --------------------------- --------------------------- --------------------------- 
--------AAAAAAAAAAA-------- --------AAAAAAAAAAA-------- --------AAAAAAAAAAA-------- ---------AAAAAAAAA--------- -----------AAAAA----------- --------------------------- --------------------------- --------------------------- --------------------------- --------------------------- --------------------------- --------------------------- --------------------------- --------------------------- --------------------------- --------------------------- --------------------------- --------------------------- --------------------------- --------------------------- --------------------------- --------------------------- --------------------------- --------------------------- --------------------------- --------------------------- --------------------------- --------------------------- --------------------------- --------------------------- --------------------------- 
------AAAAAAAAAAAAAAA------ ------AAAAAAAAAAAAAAA------ ------AAAAAAAAAAAAAAA------ -------AAAAAAAAAAAAA------- ---------AAAAAAAAA--------- -----------AAAAA----------- --------------------------- --------------------------- --------------------------- --------------------------- --------------------------- --------------------------- --------------------------- --------------------------- --------------------------- --------------------------- --------------------------- --------------------------- --------------------------- --------------------------- --------------------------- --------------------------- --------------------------- --------------------------- --------------------------- --------------------------- --------------------------- --------------------------- --------------------------- --------------------------- --------------------------- 
----AAAAAA-------AAAAAA---- ----AAAAAAAAAAAAAAAAAAA---- ----AAAAAAAAAAAAAAAAAAA---- -----AAAAAAAAAAAAAAAAA----- ------AAAAAAAAAAAAAAA------ --------AAAAAAAAAAA-------- --------------------------- --------------------------- --------------------------- --------------------------- --------------------------- --------------------------- --------------------------- --------------------------- --------------------------- --------------------------- --------------------------- --------------------------- --------------------------- --------------------------- --------------------------- --------------------------- --------------------------- --------------------------- --------------------------- --------------------------- --------------------------- --------------------------- --------------------------- --------------------------- --------------------------- 
---AAAAA-----------AAAAA--- ---AAAAAAA-------AAAAAAA--- ---AAAAAAAAAAAAAAAAAAAAA--- ----AAAAAAAAAAAAAAAAAAAA--- -----AAAAAAAAAAAAAAAAAA---- ------AAAAAAAAAAAAAAA------ ----------AAAAAAA---------- -----------AAAAA----------- -------------A------------- -------------A------------- --------------------------- --------------------------- --------------------------- --------------------------- --------------------------- --------------------------- --------------------------- --------------------------- --------------------------- --------------------------- --------------------------- --------------------------- --------------------------- --------------------------- --------------------------- --------------------------- --------------------------- --------------------------- --------------------------- --------------------------- --------------------------- 
---AAAA-------------AAAA--- ---AAAAA-----------AAAAA--- ---AAAAAAAA-----AAAAAAAA--- ---AAAAAAAAAAAAAAAAAAAAA--- ----AAAAAAAAAAAAAAAAAAA---- -----AAAAAAAAAAAAAAAAA----- --------AAAAAAAAAAA-------- -----------AAAAA----------- -----------AAAAA----------- ------------AAA------------ -------------A------------- -------------A------------- --------------------------- --------------------------- --------------------------- --------------------------- --------------------------- --------------------------- --------------------------- --------------------------- --------------------------- --------------------------- --------------------------- --------------------------- --------------------------- --------------------------- --------------------------- --------------------------- --------------------------- --------------------------- --------------------------- 
--AAAA---------------AAAA-- --AAAAA-------------AAAAA-- --AAAAAAA---------AAAAAAA-- ---AAAAAAAA-----AAAAAAAA--- ---AAAAAAAAAAAAAAAAAAAAA--- ----AAAAAAAAAAAAAAAAAAA---- -------AAAAAAAAAAAAA------- -----------AAAAA----------- -----------AAAAA----------- -----------AAAAA----------- ------------AAA------------ ------------AAA------------ -------------A------------- -------------A------------- -------------A------------- --------------------------- --------------------------- --------------------------- --------------------------- --------------------------- --------------------------- --------------------------- --------------------------- --------------------------- --------------------------- --------------------------- --------------------------- --------------------------- --------------------------- --------------------------- --------------------------- 
--AAA-----------------AAA-- --AAAA---------------AAAA-- --AAAAA-------------AAAAA-- --AAAAAAA---------AAAAAAA-- ---AAAAAAAA-----AAAAAAAA--- ----AAAAAAAAAAAAAAAAAAA---- ------AAAAAAAAAAAAAAA------ ---------AAAAAAAAA--------- -----------AAAAA----------- -----------AAAAA----------- -----------AAAAA----------- ------------AAA------------ ------------AAA------------ ------------AAA------------ ------------AAA------------ -------------A------------- -------------A------------- --------------------------- --------------------------- --------------------------- --------------------------- --------------------------- --------------------------- --------------------------- --------------------------- --------------------------- --------------------------- --------------------------- --------------------------- --------------------------- --------------------------- 
-AAA-------------------AAA- -AAAA-----------------AAAA- -AAAAAA-------------AAAAA-- --AAAAAA-----------AAAAAA-- --AAAAAAA---------AAAAAA--- ---AAAAAAAA-----AAAAAAAA--- -----AAAAAAAAAAAAAAAAA----- --------AAAAAAAAAAA-------- -----------AAAAA----------- -----------AAAAA----------- -----------AAAAA----------- -----------AAAAA----------- -----------AAAAA----------- ------------AAA------------ ------------AAA------------ ------------AAA------------ -------------A------------- -------------A------------- --------------------------- --------------------------- --------------------------- --------------------------- --------------------------- --------------------------- --------------------------- --------------------------- --------------------------- --------------------------- --------------------------- --------------------------- --------------------------- 
-AAA-------------------AAA- -AAAA-----------------AAAA- -AAAAA---------------AAAAA- -AAAAAA-------------AAAAA-- --AAAAAA-----------AAAAAA-- ---AAAAAAA-------AAAAAAA--- -----AAAAAA-----AAAAAA----- -------AAAAAAAAAAAAA------- -----------AAAAA----------- -----------AAAAA----------- -----------AAAAA----------- -----------AAAAA----------- -----------AAAAA----------- -----------AAAAA----------- -----------AAAAA----------- ------------AAA------------ ------------AAA------------ -------------A------------- -------------A------------- -------------A------------- --------------------------- --------------------------- --------------------------- --------------------------- --------------------------- --------------------------- --------------------------- --------------------------- --------------------------- --------------------------- --------------------------- 
AAA---------------------AAA AAAA-------------------AAAA -AAAAA---------------AAAAA- -AAAAAA-------------AAAAAA- -AAAAAAA-----------AAAAAA-- --AAAAAAA---------AAAAAA--- ----AAAAAA-------AAAAAA---- -------AAAAAAAAAAAAA------- -----------AAAAA----------- -----------AAAAA----------- -----------AAAAA----------- -----------AAAAA----------- -----------AAAAA----------- -----------AAAAA----------- -----------AAAAA----------- -----------AAAAA----------- ------------AAA------------ ------------AAA------------ ------------AAA------------ -------------A------------- -------------A------------- -------------A------------- --------------------------- --------------------------- --------------------------- --------------------------- --------------------------- --------------------------- --------------------------- --------------------------- --------------------------- 
AAA---------------------AAA AAAA-------------------AAAA AAAAA-----------------AAAAA -AAAAA---------------AAAAA- -AAAAAA-------------AAAAA-- --AAAAAA-----------AAAAA--- ----AAAAA---------AAAAA---- ------AAAAAAAAAAAAAAA------ -----------AAAAA----------- -----------AAAAA----------- -----------AAAAA----------- -----------AAAAA----------- -----------AAAAA----------- -----------AAAAA----------- -----------AAAAA----------- -----------AAAAA----------- -----------AAAAA----------- -----------AAAAA----------- ------------AAA------------ ------------AAA------------ ------------AAA------------ -------------A------------- -------------A------------- -------------A------------- --------------------------- --------------------------- --------------------------- --------------------------- --------------------------- --------------------------- --------------------------- 
AAA---------------------AAA AAAA-------------------AAAA AAAAA-----------------AAAAA AAAAAA---------------AAAAA- -AAAAAA-------------AAAAA-- --AAAAAA-----------AAAAA--- ----AAAAA---------AAAAA---- ------AAAAAAAAAAAAAAA------ -----------AAAAA----------- -----------AAAAA----------- -----------AAAAA----------- -----------AAAAA----------- -----------AAAAA----------- -----------AAAAA----------- -----------AAAAA----------- -----------AAAAA----------- -----------AAAAA----------- -----------AAAAA----------- -----------AAAAA----------- -----------AAAAA----------- ------------AAA------------ ------------AAA------------ ------------AAA------------ -------------A------------- -------------A------------- --------------------------- --------------------------- --------------------------- --------------------------- --------------------------- --------------------------- 
AAA---------------------AAA AAAA-------------------AAAA AAAAA-----------------AAAAA AAAAAA---------------AAAAA- -AAAAAA-------------AAAAA-- --AAAAAA-----------AAAAA--- ----AAAAA---------AAAAA---- ------AAAAAAA-AAAAAAA------ -----------AAAAA----------- -----------AAAAA----------- -----------AAAAA----------- -----------AAAAA----------- -----------AAAAA----------- -----------AAAAA----------- -----------AAAAA----------- -----------AAAAA----------- -----------AAAAA----------- -----------AAAAA----------- -----------AAAAA----------- -----------AAAAA----------- -----------AAAAA----------- -----------AAAAA----------- ------------AAA------------ ------------AAA------------ -------------A------------- -------------A------------- --------------------------- --------------------------- --------------------------- --------------------------- --------------------------- 
AAA---------------------AAA AAAA-------------------AAAA AAAAA-----------------AAAAA AAAAAA---------------AAAAA- -AAAAAA-------------AAAAA-- --AAAAAA-----------AAAAA--- ----AAAAA---------AAAAA---- ------AAAAAAAAAAAAAAA------ -----------AAAAA----------- -----------AAAAA----------- -----------AAAAA----------- -----------AAAAA----------- -----------AAAAA----------- -----------AAAAA----------- -----------AAAAA----------- -----------AAAAA----------- -----------AAAAA----------- -----------AAAAA----------- -----------AAAAA----------- -----------AAAAA----------- -----------AAAAA----------- -----------AAAAA----------- -----------AAAAA----------- ------------AAA------------ ------------AAA------------ -------------A------------- -------------A------------- --------------------------- --------------------------- --------------------------- --------------------------- 
AAA---------------------AAA AAAA-------------------AAAA AAAAA-----------------AAAAA -AAAAA---------------AAAAA- -AAAAAA-------------AAAAA-- --AAAAAA-----------AAAAA--- ----AAAAA---------AAAAA---- ------AAAAAAAAAAAAAAA------ -----------AAAAA----------- -----------AAAAA----------- -----------AAAAA----------- -----------AAAAA----------- -----------AAAAA----------- -----------AAAAA----------- -----------AAAAA----------- -----------AAAAA----------- -----------AAAAA----------- -----------AAAAA----------- -----------AAAAA----------- -----------AAAAA----------- -----------AAAAA----------- -----------AAAAA----------- -----------AAAAA----------- -----------AAAAA----------- ------------AAA------------ ------------AAA------------ -------------A------------- -------------A------------- --------------------------- --------------------------- --------------------------- 
AAA---------------------AAA AAAA-------------------AAAA -AAAAA---------------AAAAA- -AAAAAA-------------AAAAAA- -AAAAAAA-----------AAAAAA-- --AAAAAAA---------AAAAAA--- ----AAAAAA-------AAAAAA---- -------AAAAAAAAAAAAA------- -----------AAAAA----------- -----------AAAAA----------- -----------AAAAA----------- -----------AAAAA----------- -----------AAAAA----------- -----------AAAAA----------- -----------AAAAA----------- -----------AAAAA----------- -----------AAAAA----------- -----------AAAAA----------- -----------AAAAA----------- -----------AAAAA----------- -----------AAAAA----------- -----------AAAAA----------- -----------AAAAA----------- -----------AAAAA----------- -----------AAAAA----------- ------------AAA------------ ------------AAA------------ -------------A------------- --------------------------- --------------------------- --------------------------- 
-AAA-------------------AAA- -AAAA-----------------AAAA- -AAAAA---------------AAAAA- -AAAAAA-------------AAAAA-- --AAAAAA-----------AAAAAA-- ---AAAAAAA-------AAAAAAA--- -----AAAAAA-----AAAAAA----- -------AAAAAAAAAAAAA------- -----------AAAAA----------- -----------AAAAA----------- -----------AAAAA----------- -----------AAAAA----------- -----------AAAAA----------- -----------AAAAA----------- -----------AAAAA----------- -----------AAAAA----------- -----------AAAAA----------- ------------AAA------------ ------------AAA------------ ------------AAA------------ ------------AAA------------ ------------AAA------------ ------------AAA------------ -----------AAAAA----------- -----------AAAAA----------- -----------AAAAA----------- ------------AAA------------ ------------AAA------------ -------------A------------- --------------------------- --------------------------- 
-AAA-------------------AAA- -AAAA-----------------AAAA- -AAAAAA-------------AAAAA-- --AAAAAA-----------AAAAAA-- --AAAAAAA---------AAAAAA--- ---AAAAAAAA-----AAAAAAAA--- -----AAAAAAAAAAAAAAAAA----- --------AAAAAAAAAAA-------- -----------AAAAA----------- -----------AAAAA----------- -----------AAAAA----------- -----------AAAAA----------- -----------AAAAA----------- -----------AAAAA----------- -----------AAAAA----------- -----------AAAAA----------- ------------AAA------------ ------------AAA------------ -------------A------------- -------------A------------- -------------A------------- -------------A------------- -------------A------------- ------------AAA------------ -----------AAAAA----------- -----------AAAAA----------- -----------AAAAA----------- ------------AAA------------ -------------A------------- -------------A------------- --------------------------- 
--AAA-----------------AAA-- --AAAA---------------AAAA-- --AAAAA-------------AAAAA-- --AAAAAAA---------AAAAAAA-- ---AAAAAAAA-----AAAAAAAA--- ----AAAAAAAAAAAAAAAAAAA---- ------AAAAAAAAAAAAAAA------ ---------AAAAAAAAA--------- -----------AAAAA----------- -----------AAAAA----------- -----------AAAAA----------- -----------AAAAA----------- -----------AAAAA----------- -----------AAAAA----------- ------------AAA------------ ------------AAA------------ -------------A------------- -------------A------------- -------------A------------- --------------------------- --------------------------- --------------------------- -------------A------------- -------------A------------- -------------A------------- -------------A------------- ------------AAA------------ ------------AAA------------ ------------AAA------------ -------------A------------- --------------------------- 
--AAAA---------------AAAA-- --AAAAA-------------AAAAA-- --AAAAAAA---------AAAAAAA-- ---AAAAAAAA-----AAAAAAAA--- ---AAAAAAAAAAAAAAAAAAAAA--- ----AAAAAAAAAAAAAAAAAAA---- -------AAAAAAAAAAAAA------- -----------AAAAA----------- -----------AAAAA----------- -----------AAAAA----------- -----------AAAAA----------- -----------AAAAA----------- ------------AAA------------ ------------AAA------------ -------------A------------- -------------A------------- -------------A------------- --------------------------- --------------------------- --------------------------- --------------------------- --------------------------- --------------------------- --------------------------- --------------------------- --------------------------- -------------A------------- -------------A------------- -------------A------------- -------------A------------- -------------A------------- 
---AAAA-------------AAAA--- ---AAAAA-----------AAAAA--- ---AAAAAAAA-----AAAAAAAA--- ---AAAAAAAAAAAAAAAAAAAAA--- ----AAAAAAAAAAAAAAAAAAA---- -----AAAAAAAAAAAAAAAAA----- --------AAAAAAAAAAA-------- -----------AAAAA----------- -----------AAAAA----------- -----------AAAAA----------- -----------AAAAA----------- ------------AAA------------ -------------A------------- -------------A------------- --------------------------- --------------------------- --------------------------- --------------------------- --------------------------- --------------------------- --------------------------- --------------------------- --------------------------- --------------------------- --------------------------- --------------------------- --------------------------- --------------------------- --------------------------- --------------------------- --------------------------- 
---AAAAA-----------AAAAA--- ---AAAAAAA-------AAAAAAA--- ---AAAAAAAAAAAAAAAAAAAAA--- ----AAAAAAAAAAAAAAAAAAA---- -----AAAAAAAAAAAAAAAAAA---- ------AAAAAAAAAAAAAAA------ ----------AAAAAAA---------- -----------AAAAA----------- -----------AAAAA----------- ------------AAA------------ ------------AAA------------ -------------A------------- --------------------------- --------------------------- --------------------------- --------------------------- --------------------------- --------------------------- --------------------------- --------------------------- --------------------------- --------------------------- --------------------------- --------------------------- --------------------------- --------------------------- --------------------------- --------------------------- --------------------------- --------------------------- --------------------------- 
----AAAAAA-------AAAAAA---- ----AAAAAAAAAAAAAAAAAAA---- ----AAAAAAAAAAAAAAAAAAA---- -----AAAAAAAAAAAAAAAAA----- ------AAAAAAAAAAAAAAA------ ---------AAAAAAAAA--------- -----------AAAAA----------- -----------AAAAA----------- -----------AAAAA----------- -------------A------------- --------------------------- --------------------------- --------------------------- --------------------------- --------------------------- --------------------------- --------------------------- --------------------------- --------------------------- --------------------------- --------------------------- --------------------------- --------------------------- --------------------------- --------------------------- --------------------------- --------------------------- --------------------------- --------------------------- --------------------------- --------------------------- 
------AAAAAAAAAAAAAAA------ ------AAAAAAAAAAAAAAA------ ------AAAAAAAAAAAAAAA------ -------AAAAAAAAAAAAA------- --------AAAAAAAAAAA-------- --------------------------- --------------------------- --------------------------- --------------------------- --------------------------- --------------------------- --------------------------- --------------------------- --------------------------- --------------------------- --------------------------- --------------------------- --------------------------- --------------------------- --------------------------- --------------------------- --------------------------- --------------------------- --------------------------- --------------------------- --------------------------- --------------------------- --------------------------- --------------------------- --------------------------- --------------------------- 
--------AAAAAAAAAAA-------- --------AAAAAAAAAAA-------- ---------AAAAAAAAA--------- ----------AAAAAAA---------- --------------------------- --------------------------- --------------------------- --------------------------- --------------------------- --------------------------- --------------------------- --------------------------- --------------------------- --------------------------- --------------------------- --------------------------- --------------------------- --------------------------- --------------------------- --------------------------- --------------------------- --------------------------- --------------------------- --------------------------- --------------------------- --------------------------- --------------------------- --------------------------- --------------------------- --------------------------- --------------------------- 
----------AAAAAAA---------- -----------AAAAA----------- ------------AAA------------ --------------------------- --------------------------- --------------------------- --------------------------- --------------------------- --------------------------- --------------------------- --------------------------- --------------------------- --------------------------- --------------------------- --------------------------- --------------------------- --------------------------- --------------------------- --------------------------- --------------------------- --------------------------- --------------------------- --------------------------- --------------------------- --------------------------- --------------------------- --------------------------- --------------------------- --------------------------- --------------------------- --------------------------- 
