model
size = 26 31 26, scale = 0.05, origin = -y
material 
  colors = A:#252525 B:#EEE C:#00FF98 D:#F00 E:#8700FF F:#F70 G:#F90 H:#FB0 I:#FD0 J:#BFFF00 K:#00FF48 L:#FF3700 M:#FF5900 N:#0CFF00 O:#00A1FF P:#50F Q:#A500FF R:#005DFF S:#D4864E T:#FF6 U:#D4AB8E
voxels
----------AAAAAA---------- ----------BABAAB---------- ----------AABAAB---------- ----------AABBBA---------- ----------AABAAB---------- ----------BABBBA---------- ----------AAAAAA---------- -------------------------- -------------------------- -------------------------- -------------------------- -------------------------- -------------------------- -------------------------- -------------------------- -------------------------- -------------------------- -------------------------- -------------------------- -------------------------- -------------------------- -------------------------- -------------------------- -------------------------- -------------------------- -------------------------- -------------------------- -------------------------- -------------------------- -------------------------- -------------------------- 
-------AAAAAAAAAAAA------- -------ABBAAAAAAAAB------- -------ABAAAAAAAAAB------- -------ABAAAAAAAABB------- -------ABAAAAAAAABA------- -------ABBAAAAAAABA------- -------AAAAAAAAAAAA------- -----------DDDD----------- -----------LLLL----------- -----------MMMM----------- -------------------------- -------------------------- -------------------------- -------------------------- -------------------------- -------------------------- -------------------------- -------------------------- -------------------------- -------------------------- -------------------------- -------------------------- -------------------------- -------------------------- -------------------------- -------------------------- -------------------------- -------------------------- -------------------------- -------------------------- -------------------------- 
------AAAA------AAAA------ ------AAAA------AAAA------ ------AAAA------AAAA------ ------AAAA------AAAB------ ------AAAA------AAAB------ ------AAAA------AAAB------ ------AAAA------AAAA------ --------DDD----DDD-------- --------LLL----LLL-------- --------MMM----MMM-------- --------FFFFFFFFFF-------- ---------GGGGGGGG--------- -----------HHHH----------- -----------IIII----------- -----------JJJJ----------- -------------------------- -------------------------- -------------------------- -------------------------- -------------------------- -------------------------- -------------------------- -------------------------- -------------------------- -------------------------- -------------------------- -------------------------- -------------------------- -------------------------- -------------------------- -------------------------- 
-----AA------------AA----- -----AA------------AA----- -----AA------------AA----- -----DA------------AA----- -----DA------------AA----- -----AA------------AA----- -----AAA----------AAA----- ------DD----------DD------ ------LL----------LL------ ------MM----------MM------ -------FF--------FF------- -------GGG------GGG------- --------HHHH--HHHH-------- --------IIII--IIII-------- --------JJJJ--JJJJ-------- ----------NNNNNN---------- -------------------------- -------------------------- -------------------------- -------------------------- -------------------------- -------------------------- -------------------------- -------------------------- -------------------------- -------------------------- -------------------------- -------------------------- -------------------------- -------------------------- -------------------------- 
----AA--------------AA---- ----AA--------------AB---- ----DA--------------AB---- ----DA--------------AB---- ----DA--------------AB---- ----DA--------------AB---- ----AA--------------AA---- -----D--------------D----- -----L--------------L----- -----M--------------M----- -----FF------------FF----- ------GG----------GG------ -------HH--------HH------- -------II--------II------- -------JJ--------JJ------- --------NN------NN-------- ---------KKKKKKKK--------- ---------CCCCCCCC--------- -------------------------- -------------------------- -------------------------- -------------------------- -------------------------- -------------------------- -------------------------- -------------------------- -------------------------- -------------------------- -------------------------- -------------------------- -------------------------- 
---AA----------------AA--- ---DA----------------AA--- ---DA----------------AA--- ---DA----------------AB--- ---DA----------------AA--- ---AA----------------AB--- ---AA----------------AA--- ----D----------------D---- ----L----------------L---- ----M----------------M---- ----FF--------------FF---- -----G--------------G----- -----HH------------HH----- -----II------------II----- -----JJ------------JJ----- ------NN----------NN------ -------KKK------KKK------- --------CTCCCCCCTCC------- ---------OOOOOOOO--------- -------------------------- -------------------------- -------------------------- -------------------------- -------------------------- -------------------------- -------------------------- -------------------------- -------------------------- -------------------------- -------------------------- -------------------------- 
--AA------------------AA-- --AA------------------AA-- --DA------------------AA-- --DA------------------AB-- --DA------------------AB-- --DA------------------AB-- --AA------------------AA-- ---D------------------D--- ---L------------------L--- ---M------------------M--- ----F----------------F---- ----G----------------G---- -----H--------------H----- -----I--------------I----- -----J--------------J----- -----NN------------NN----- ------KK----------KK------ -------CCC------CCCC------ --------OO------OO-------- ----------RRRRRR---------- ----------PPPPPP---------- -------------------------- -------------------------- -------------------------- -------------------------- -------------------------- -------------------------- -------------------------- -------------------------- -------------------------- -------------------------- 
-AA--------------------AA- -AA--------------------AA- -AA--------------------AA- -DA--------------------AA- -DA--------------------AA- -AA--------------------AA- -AAA------------------AAA- ---D------------------D--- ---L------------------L--- ---M------------------M--- ---F------------------F--- ---GG----------------GG--- ----H----------------H---- ----I----------------I---- ----J----------------J---- -----N--------------N----- -----KK------------KK----- ------CCC--------CCCC----- -------OO--------OO------- --------RREE--EERR-------- --------PPPE--EPPP-------- -----------EEEE----------- -------------------------- -------------------------- -------------------------- -------------------------- -------------------------- -------------------------- -------------------------- -------------------------- -------------------------- 
-AA--------------------AA- -AA--------------------AA- -AA--------------------AA- -AA--------------------AA- -AA--------------------AA- -AA--------------------AB- -AA--------------------AA- --D--------------------D-- --L--------------------L-- --M--------------------M-- --FF------------------FF-- ---G------------------G--- ---HH----------------HH--- ---II----------------II--- ---JJ----------------JJ--- ----N----------------N---- -----K--------------K----- -----CCC----------CCC----- ------OE----------OO------ -------REE------EER------- -------PPE------EPP------- ---------EEQQQQEE--------- -------------------------- -------------------------- -----------AAAA----------- -----------AAAD----------- -----------BAAA----------- -----------AAAA----------- -------------------------- -------------------------- -------------------------- 
-AA--------------------AA- -AA--------------------AB- -AA--------------------AB- -AA--------------------AB- -AA--------------------AB- -AA--------------------AB- -AA--------------------AA- --D--------------------D-- --L--------------------L-- --M--------------------M-- --F--------------------F-- --GG------------------GG-- ---H------------------H--- ---I------------------I--- ---J------------------J--- ----N----------------N---- ----KK--------------KK---- ----CTC------------CTC---- -----OO------------OO----- -------RE--------ER------- -------PE--------EP------- --------EQQQQQQQQE-------- ------------AB------------ ----------AAAAAA---------- ----------AAAAAA---------- ---------AAAAAAAA--------- ---------AAAAAAAA--------- ----------AAAAAA---------- ----------AAAAAA---------- ------------AB------------ -------------------------- 
AA----------------------AA BA----------------------AA AA----------------------AA AA---------------------SAA AA---------------------SAA BA---------------------SAB AA----------------------AA --D--------------------D-- --L--------------------L-- --M--------------------M-- --F--------------------F-- --G--------------------G-- ---H------------------H--- ---I------------------I--- ---J------------------J--- ---N------------------N--- ----K----------------K---- ----CC--------------CC---- -----O--------------O----- ------RE----------ER------ ------PP----------PP------ --------EQQ----QQE-------- ----------AAAAAA---------- ---------BAAAAAAA--------- ---------AAAAAAAA--------- ---------AAAAAAAA--------- ---------AAAAAAAA--------- ---------AAAAAAAB--------- ---------AAAAAAAA--------- ----------BAAAAA---------- -------------------------- 
AA----------------------AA BA----------------------AA BA----------------------AA BA---------------------SAA BA---------------------UAA BA---------------------SAA AA----------------------AA -D----------------------D- -L----------------------L- -M----------------------M- --F--------------------F-- --G--------------------G-- --HH------------------HH-- --II------------------II-- --JJ------------------JJ-- ---N------------------N--- ----K----------------K---- ----CC--------------CC---- -----O--------------O----- ------RE----------ER------ ------PE----------EP------ -------EQQ------QQE------- ----------AAAAAA---------- ---------AAAAAAAB--------- --------AAAAAAAAAA-------- --------AAAAAAAAAA-------- --------AAAAAAAAAA-------- --------DAAAAAAAAA-------- ---------AAAAAAAA--------- ----------AAAAAA---------- -----------AABA----------- 
AA----------------------AA BA----------------------AB AA----------------------AB AA---------------------SAB AA---------------------UAB BA---------------------SAB AA----------------------AA -D----------------------D- -L----------------------L- -M----------------------M- --F--------------------F-- --G--------------------G-- --H--------------------H-- --I--------------------I-- --J--------------------J-- ---N------------------N--- ----K----------------K---- ----CC--------------CC---- -----O--------------O----- ------R------------R------ ------P------------P------ -------EQQ------QQE------- ---------AAAAAAAA--------- ---------AAAAAAAA--------- --------AAAAAAAAAA-------- --------AAAAAAAAAB-------- --------AAAAAAAAAA-------- --------AAAAAAAAAA-------- ---------AAAAAAAA--------- ---------AAAAAAAA--------- -----------AAAA----------- 
AA----------------------AA AA----------------------AB AA----------------------AA AA---------------------SAA AA---------------------UAA AA---------------------SAB AA----------------------AA -D----------------------D- -L----------------------L- -M----------------------M- --F--------------------F-- --G--------------------G-- --H--------------------H-- --I--------------------I-- --J--------------------J-- ---N------------------N--- ----K----------------K---- ----CC--------------CC---- -----O--------------O----- ------R------------R------ ------P------------P------ -------EQQ------QQE------- ---------AAAAAAAA--------- ---------BAAAAAAA--------- --------AAAAAAAAAA-------- --------AAAAAAAAAA-------- --------AAAAAAAAAA-------- --------AAAAAAAAAA-------- ---------AAAAAAAA--------- ---------AAAAAAAD--------- -----------AAAA----------- 
AA----------------------AA AA----------------------AB AA----------------------AB AA---------------------SAB AA---------------------UAB AA---------------------SAB AA----------------------AA -D----------------------D- -L----------------------L- -M----------------------M- --F--------------------F-- --G--------------------G-- --HH------------------HH-- --II------------------II-- --JJ------------------JJ-- ---N------------------N--- ----K----------------K---- ----CC--------------CC---- -----O--------------O----- ------RE----------ER------ ------PE----------EP------ -------EQQ------QQE------- ----------AAAAAB---------- ---------AAAAAAAA--------- --------AAAAAAAAAA-------- --------AAAAAAAAAA-------- --------BAAAAAAAAB-------- --------AAAAAAAAAA-------- ---------BAAAAAAA--------- ----------AAAAAA---------- -----------DABA----------- 
AA----------------------AA AA----------------------AA AA----------------------AA AA---------------------SAA AA---------------------SAA AA---------------------SAA AA----------------------AA --D--------------------D-- --L--------------------L-- --M--------------------M-- --F--------------------F-- --G--------------------G-- ---H------------------H--- ---I------------------I--- ---J------------------J--- ---N------------------N--- ----K----------------K---- ----CC--------------CC---- -----O--------------O----- ------RE----------ER------ ------PP----------PP------ --------EQQ----QQE-------- ----------AAAABA---------- ---------AAAAAAAA--------- ---------AAAAAAAA--------- ---------AAAAAAAA--------- ---------AAAAAAAA--------- ---------AAAAAAAA--------- ---------AAAAAAAA--------- ----------AAAAAA---------- -------------------------- 
-AA--------------------AA- -AA--------------------AA- -AA--------------------AB- -SA--------------------AB- -AA--------------------AB- -AA--------------------AB- -AA--------------------AA- --D--------------------D-- --L--------------------L-- --M--------------------M-- --F--------------------F-- --GG------------------GG-- ---H------------------H--- ---I------------------I--- ---J------------------J--- ----N----------------N---- ----KK--------------KK---- ----CTC------------CTC---- -----OO------------OO----- -------RE--------ER------- -------PE--------EP------- --------EQQQQQQQQE-------- ------------AA------------ ----------BAAAAA---------- ----------AAAAAD---------- ---------AAAAAAAA--------- ---------DAAAAAAA--------- ----------AAAAAA---------- ----------AABAAB---------- ------------AA------------ -------------------------- 
-AA--------------------AA- -AA--------------------AB- -AA--------------------AA- -SA--------------------AA- -AA--------------------AA- -AA--------------------AA- -AA--------------------AA- --D--------------------D-- --L--------------------L-- --M--------------------M-- --FF------------------FF-- ---G------------------G--- ---HH----------------HH--- ---II----------------II--- ---JJ----------------JJ--- ----N----------------N---- -----K--------------K----- -----CCC----------CCC----- ------OO----------OO------ -------REE------EER------- -------PPE------EPP------- ---------EEQQQQEE--------- -------------------------- -------------------------- -----------AAAA----------- -----------ABAA----------- -----------AAAA----------- -----------AAAA----------- -------------------------- -------------------------- -------------------------- 
-AA--------------------AA- -AA--------------------AA- -AA--------------------AB- -SA--------------------AB- -AA--------------------AB- -AA--------------------AB- -AAA------------------AAA- ---D------------------D--- ---L------------------L--- ---M------------------M--- ---F------------------F--- ---GG----------------GG--- ----H----------------H---- ----I----------------I---- ----J----------------J---- -----N--------------N----- -----KK------------KK----- ------CCC--------CCCC----- -------OO--------OO------- --------RREE--EERR-------- --------PPPE--EPPP-------- -----------EEEE----------- -------------------------- -------------------------- -------------------------- -------------------------- -------------------------- -------------------------- -------------------------- -------------------------- -------------------------- 
--AA------------------AA-- --AA------------------AA-- --AA------------------AA-- --AA------------------AA-- --AA------------------AA-- --AA------------------AA-- --AA------------------AA-- ---D------------------D--- ---L------------------L--- ---M------------------M--- ----F----------------F---- ----G----------------G---- -----H--------------H----- -----I--------------I----- -----J--------------J----- -----NN------------NN----- ------KK----------KK------ -------CCC------CCCC------ --------OO------OO-------- ----------RRRRRR---------- ----------PPPPPP---------- -------------------------- -------------------------- -------------------------- -------------------------- -------------------------- -------------------------- -------------------------- -------------------------- -------------------------- -------------------------- 
---AA----------------AA--- ---AA----------------AB--- ---AA----------------AB--- ---AA----------------AB--- ---AA----------------AB--- ---AA----------------AB--- ---AA----------------AA--- ----D----------------D---- ----L----------------L---- ----M----------------M---- ----FF--------------FF---- -----G--------------G----- -----HH------------HH----- -----II------------II----- -----JJ------------JJ----- ------NN----------NN------ -------KKK------KKK------- --------CTCCCCCCTCC------- ---------OOOOOOOO--------- -------------------------- -------------------------- -------------------------- -------------------------- -------------------------- -------------------------- -------------------------- -------------------------- -------------------------- -------------------------- -------------------------- -------------------------- 
----AA--------------AA---- ----AA--------------AB---- ----AA--------------AA---- ----AA--------------AA---- ----AA--------------AA---- ----AA--------------AB---- ----AA--------------AA---- -----D--------------D----- -----L--------------L----- -----M--------------M----- -----FF------------FF----- ------GG----------GG------ -------HH--------HH------- -------II--------II------- -------JJ--------JJ------- --------NN------NN-------- ---------KKKKKKKK--------- ---------CCCCCCCC--------- -------------------------- -------------------------- -------------------------- -------------------------- -------------------------- -------------------------- -------------------------- -------------------------- -------------------------- -------------------------- -------------------------- -------------------------- -------------------------- 
-----AA------------AA----- -----BA------------AB----- -----BA------------AB----- -----BA------------AB----- -----AA------------AB----- -----BA------------AB----- -----AAA----------AAA----- ------DD----------DD------ ------LL----------LL------ ------MM----------MM------ -------FF--------FF------- -------GGG------GGG------- --------HHHH--HHHH-------- --------IIII--IIII-------- --------JJJJ--JJJJ-------- ----------NNNNNN---------- -------------------------- -------------------------- -------------------------- -------------------------- -------------------------- -------------------------- -------------------------- -------------------------- -------------------------- -------------------------- -------------------------- -------------------------- -------------------------- -------------------------- -------------------------- 
------AAAA------AAAA------ ------BAAA------AAAA------ ------AAAA------AAAA------ ------BAAA------AAAA------ ------BAAA------AAAA------ ------BAAA------AAAA------ ------AAAA------AAAA------ --------DDD----DDD-------- --------LLL----LLL-------- --------MMM----MMM-------- --------FFFFFFFFFF-------- ---------GGGGGGGG--------- -----------HHHH----------- -----------IIII----------- -----------JJJJ----------- -------------------------- -------------------------- -------------------------- -------------------------- -------------------------- -------------------------- -------------------------- -------------------------- -------------------------- -------------------------- -------------------------- -------------------------- -------------------------- -------------------------- -------------------------- -------------------------- 
-------AAAAAAAAAAAA------- -------ABBAAAAAABAB------- -------AAAAAAAAABAB------- -------AAAAAAAAAABA------- -------AAAAAAAAABAB------- -------AAAAAAAAABAB------- -------AAAAAAAAAAAA------- -----------DDDD----------- -----------LLLL----------- -----------MMMM----------- -------------------------- -------------------------- -------------------------- -------------------------- -------------------------- -------------------------- -------------------------- -------------------------- -------------------------- -------------------------- -------------------------- -------------------------- -------------------------- -------------------------- -------------------------- -------------------------- -------------------------- -------------------------- -------------------------- -------------------------- -------------------------- 
----------AAAAAA---------- ----------BABBBA---------- ----------BAAABA---------- ----------BAABBA---------- ----------BAAABA---------- ----------BABBBA---------- ----------AAAAAA---------- -------------------------- -------------------------- -------------------------- -------------------------- -------------------------- -------------------------- -------------------------- -------------------------- -------------------------- -------------------------- -------------------------- -------------------------- -------------------------- -------------------------- -------------------------- -------------------------- -------------------------- -------------------------- -------------------------- -------------------------- -------------------------- -------------------------- -------------------------- -------------------------- 
