model
size = 22 28 22, scale = 0.05, origin = -y
material 
  colors = A:#D0004C B:#00AA90 C:#A8D8B9
voxels
---------------------- ---------------------- ---------------------- ---------------------- ---------------------- ---------------------- ---------------------- ---------AAAA--------- --------AA--AA-------- -------AAA--AAA------- -----AAAAAAAAAAAA----- ---AAAAAAAAAAAAAAAA--- --A---A-A-A-AA-A---A-- --A-A-A---A-A--A-A-A-- --A-AAA-A-A--A-A-AAA-- --A---A---A-AA-A---A-- ---AAAAAAAAAAAAAAAA--- -----AAAAAAAAAAAA----- -------AAA--AAA------- --------AAAAAA-------- ----------AA---------- ---------------------- ---------------------- ---------------------- ---------------------- ---------------------- ---------------------- ---------------------- 
---------------------- ---------------------- ---------------------- ---------------------- ---------------------- ---------------------- ---------AAAA--------- --------AAAAAA-------- -------AAABBAAA------- ------AAAABBAAAA------ -----AAAAAAAAAAAA----- --AAAAAAAAAAAAAAAAAA-- --ACCCACACCCCACACCCA-- --ACACACCCCCCCCACACA-- --ACACACACCCCACACACA-- --ACCCACCCCCCCCACCCA-- --BAAAAAAAAAAAAAAAAB-- -----AAAAAAAAAAAA----- ------BAAABBAAAB------ -------BAAAAAAB------- --------BBAABB-------- ---------BBBB--------- ---------------------- ---------------------- ---------------------- ---------------------- ---------------------- ---------------------- 
---------------------- ---------------------- ---------------------- ---------------------- ---------------------- --------BBBBBB-------- -------BBAAAABB------- ------BBAAAAAABB------ -----BBAAAAAAAABB----- ----BBAAAAAAAAAABB---- ---BBAAAAAAAAAAAABB--- --AAAAAAAAAAAAAAAAAA-- -BAAAAAAAAAAAAAAAAAAB- -BAAAAAAAAAAAAAAAAAAB- -BAAAAAAAAAAAAAAAAAAB- -BAAAAAAAAAAAAAAAAAAB- --AAAAAAAAAAAAAAAAAA-- ---BBAAAAAAAAAAAABB--- ----BBAAAAAAAAAABB---- -----BBAAAAAAAABB----- ------BBAAAAAABB------ -------BBAAAABB------- --------BBBBBB-------- ---------------------- ---------------------- ---------------------- ---------------------- ---------------------- 
---------------------- ---------------------- ---------------------- ---------------------- -------BBBBBBBB------- ------BBAAAAAABB------ -----BBAAAAAAAABB----- ----BBAAAAAAAAAABB---- ---BBAAAAAAAAAAAABB--- ---BAAAAAAAAAAAAAABB-- --BAAAAAAAAAAAAAAAAB-- -BAAAAAAAAAAAAAAAAAAB- -BAAAAAAAAAAAAAAAAAAB- AAAAAAAAAAAAAAAAAAAAAA AAAAAAAAAAAAAAAAAAAAAA -BAAAAAAAAAAAAAAAAAAB- -BAAAAAAAAAAAAAAAAAAB- --AAAAAAAAAAAAAAAAAA-- ---AAAAAAAAAAAAAAAAA-- ---AAAAAAAAAAAAAAAA--- ----AAAAAAAAAAAAAA---- -----AAAAAAAAAAAA----- ------AAAAAAAAAA------ -------AAAAAAAA------- ---------------------- ---------------------- ---------------------- ---------------------- 
---------------------- ---------------------- ---------------------- -------AAAAAAAA------- ------AAAAAAAAAA------ -----AAAAAAAAAAAA----- ----AAAAAAAAAAAAAA---- ---AAAAAAAAAAAAAAAA--- --BAAAAAAAAAAAAAAAAB-- --BAAAAAAAAAAAAAAAAB-- -BAAAAAAAAAAAAAAAAAAB- -BAAAAAAAAAAAAAAAAAAB- AAAAAAAAAAAAAAAAAAAAAA AAAAAAAAAAAAAAAAAAAAAA AAAAAAAAAAAAAAAAAAAAAA AAAAAAAAAAAAAAAAAAAAAA -BAAAAAAAAAAAAAAAAAAB- -BAAAAAAAAAAAAAAAAAAB- --AAAAAAAAAAAAAAAAAA-- --AAAAAAAAAAAAAAAAAA-- ---AAAAAAAAAAAAAAAA--- ----AAAAAAAAAAAAAA---- -----AAAAAAAAAAAA----- ------AAAAAAAAAA------ -------AAAAAAAA------- ---------------------- ---------------------- ---------------------- 
---------------------- ---------------------- --------AAAAAA-------- ------AAAAAAAAAA------ -----AAAAAAAAAAAA----- ----AAAAAAAAAAAAAA---- ---AAAAAAAAAAAAAAAA--- --BAAAAAAAAAAAAAAAAB-- --BAAAAAAAAAAAAAAAAB-- -BAAAAAAAAAAAAAAAAAAB- -BAAAAAAAAAAAAAAAAAAB- AAAAAAAAAAAAAAAAAAAAAA AAAAAAAAAAAAAAAAAAAAAA AAAAAAAAAAAAAAAAAAAAAA AAAAAAAAAAAAAAAAAAAAAA AAAAAAAAAAAAAAAAAAAAAA AAAAAAAAAAAAAAAAAAAAAA -BAAAAAAAAAAAAAAAAAAB- -BAAAAAAAAAAAAAAAAAAB- --AAAAAAAAAAAAAAAAAA-- --AAAAAAAAAAAAAAAAAA-- ---AAAAAAAAAAAAAAAA--- ----AAAAAAAAAAAAAA---- -----AAAAAAAAAAAA----- ------AAAAAAAAAA------ --------AAAAAA-------- ---------------------- ---------------------- 
---------------------- ---------AAAA--------- ------AAAAAAAAAA------ -----AAAAAAAAAAAA----- ----AAAAAAAAAAAAAA---- ---AAAAAAAAAAAAAAA---- ---AAAAAAAAAAAAAAAA--- --BAAAAAAAAAAAAAAAAB-- -AAAAAAAAAAAAAAAAAAAA- AAAAAAAAAAAAAAAAAAAAAA AAAAAAAAAAAAAAAAAAAAAA AAAAAAAAAAAAAAAAAAAAAA AAAAAAAAAAAAAAAAAAAAAA AAAAAAAAAAAAAAAAAAAAAA AAAAAAAAAAAAAAAAAAAAAA AAAAAAAAAAAAAAAAAAAAAA AAAAAAAAAAAAAAAAAAAAAA AAAAAAAAAAAAAAAAAAAAAA AAAAAAAAAAAAAAAAAAAAAA -BAAAAAAAAAAAAAAAAAAB- --AAAAAAAAAAAAAAAAAA-- ---AAAAAAAAAAAAAAAA--- ---AAAAAAAAAAAAAAAA--- ----AAAAAAAAAAAAAA---- -----AAAAAAAAAAAA----- ------AAAAAAAAAA------ ---------AAAA--------- ---------------------- 
----------AA---------- -------AAAAAAAA------- ------AAAAAAAAAA------ ----AAAAAAAAAAAAAA---- ----AAAAAAAAAAAAAA---- ---AAAAAAAAAAAAAAAA--- --BAAAAAAAAAAAAAAAAB-- --BAAAAAAAAAAAAAAAAB-- AAAAAAAAAAAAAAAAAAAAAA AAAAAAAAAAAAAAAAAAAAAA AAAAAAAAAAAAAAAAAAAAAA -CAAAAAAAAAAAAAAAAAAC- AAAAAAAAAAAAAAAAAAAAAA AAAAAAAAAAAAAAAAAAAAAA AAAAAAAAAAAAAAAAAAAAAA --BAAAAAAAAAAAAAAAAB-- -CAAAAAAAAAAAAAAAAAAC- -CAAAAAAAAAAAAAAAAAAC- AAAAAAAAAAAAAAAAAAAAAA -BAAAAAAAAAAAAAAAAAAB- -BAAAAAAAAAAAAAAAAAAB- --AAAAAAAAAAAAAAAAAA-- ---AAAAAAAAAAAAAAAA--- ---AAAAAAAAAAAAAAAA--- ----AAAAAAAAAAAAAA---- ------AAAAAAAAAA------ -------AAAAAAAA------- ----------AA---------- 
--------AAAAAA-------- -------AAAAAAAA------- -----AAAAAAAAAAAA----- ----AAAAAAAAAAAAAA---- ---AAAAAAAAAAAAAAAA--- ---AAAAAAAAAAAAAAAA--- --BAAAAAAAAAAAAAAAAB-- -BAAAAAAAAAAAAAAAAAAB- AAAAAAAAAAAAAAAAAAAAAA -CAAAAAAAAAAAAAAAAAAC- AAAAAAAAAAAAAAAAAAAAAA -CAAAAAAAAAAAAAAAAAAC- AAAAAAAAAAAAAAAAAAAAAA -CAAAAAAAAAAAAAAAAAAC- AAAAAAAAAAAAAAAAAAAAAA --BAAAAAAAAAAAAAAAAB-- --BAAAAAAAAAAAAAAAAB-- -CAAAAAAAAAAAAAAAAAAC- AAAAAAAAAAAAAAAAAAAAAA AAAAAAAAAAAAAAAAAAAAAA -BAAAAAAAAAAAAAAAAAAB- --AAAAAAAAAAAAAAAAAA-- --AAAAAAAAAAAAAAAAAA-- ---AAAAAAAAAAAAAAAA--- ----AAAAAAAAAAAAAA---- -----AAAAAAAAAAAA----- -------AAAAAAAA------- --------AAAAAA-------- 
--------AAAAAA-------- ------AAAAAAAAAA------ -----AAAAAAAAAAAA----- ----AAAAAAAAAAAAAA---- ---AAAAAAAAAAAAAAAA--- --BAAAAAAAAAAAAAAAAB-- --BAAAAAAAAAAAAAAAAB-- AAAAAAAAAAAAAAAAAAAAAA AAAAAAAAAAAAAAAAAAAAAA -CAAAAAAAAAAAAAAAAAAC- AAAAAAAAAAAAAAAAAAAAAA -CAAAAAAAAAAAAAAAAAAC- AAAAAAAAAAAAAAAAAAAAAA -CAAAAAAAAAAAAAAAAAAC- AAAAAAAAAAAAAAAAAAAAAA --BAAAAAAAAAAAAAAAAB-- -CAAAAAAAAAAAAAAAAAAC- -CAAAAAAAAAAAAAAAAAAC- AAAAAAAAAAAAAAAAAAAAAA AAAAAAAAAAAAAAAAAAAAAA -BAAAAAAAAAAAAAAAAAAB- -BAAAAAAAAAAAAAAAAAAB- --AAAAAAAAAAAAAAAAAA-- ---AAAAAAAAAAAAAAAA--- ----AAAAAAAAAAAAAA---- -----AAAAAAAAAAAA----- ------AAAAAAAAAA------ --------AAAAAA-------- 
-------AAABBAAA------- ------AAAAAAAAAA------ -----AAAAAAAAAAAA----- ----AAAAAAAAAAAAAA---- ---AAAAAAAAAAAAAAAA--- --BAAAAAAAAAAAAAAAAB-- -BAAAAAAAAAAAAAAAAAAB- AAAAAAAAAAAAAAAAAAAAAA AAAAAAAAAAAAAAAAAAAAAA -CAAAAAAAAAAAAAAAAAAC- AAAAAAAAAAAAAAAAAAAAAA -CAAAAAAAAAAAAAAAAAAC- AAAAAAAAAAAAAAAAAAAAAA -CAAAAAAAAAAAAAAAAAAC- AAAAAAAAAAAAAAAAAAAAAA AAAAAAAAAAAAAAAAAAAAAA AAAAAAAAAAAAAAAAAAAAAA AAAAAAAAAAAAAAAAAAAAAA AAAAAAAAAAAAAAAAAAAAAA AAAAAAAAAAAAAAAAAAAAAA AAAAAAAAAAAAAAAAAAAAAA -BAAAAAAAAAAAAAAAAAAB- --AAAAAAAAAAAAAAAAAA-- ---AAAAAAAAAAAAAAAA--- ----AAAAAAAAAAAAAA---- -----AAAAAAAAAAAA----- ------AAAABBAAAA------ -------AAA--AAA------- 
-------AAABBAAA------- ------AAAAAAAAAA------ -----AAAAAAAAAAAA----- ----AAAAAAAAAAAAAA---- ---AAAAAAAAAAAAAAAA--- --BAAAAAAAAAAAAAAAAB-- -BAAAAAAAAAAAAAAAAAAB- AAAAAAAAAAAAAAAAAAAAAA AAAAAAAAAAAAAAAAAAAAAA -CAAAAAAAAAAAAAAAAAAC- AAAAAAAAAAAAAAAAAAAAAA -CAAAAAAAAAAAAAAAAAAC- AAAAAAAAAAAAAAAAAAAAAA -CAAAAAAAAAAAAAAAAAAC- AAAAAAAAAAAAAAAAAAAAAA AAAAAAAAAAAAAAAAAAAAAA AAAAAAAAAAAAAAAAAAAAAA AAAAAAAAAAAAAAAAAAAAAA AAAAAAAAAAAAAAAAAAAAAA AAAAAAAAAAAAAAAAAAAAAA AAAAAAAAAAAAAAAAAAAAAA -BAAAAAAAAAAAAAAAAAAB- --AAAAAAAAAAAAAAAAAA-- ---AAAAAAAAAAAAAAAA--- ----AAAAAAAAAAAAAA---- -----AAAAAAAAAAAA----- ------AAAABBAAAA------ -------AAA--AAA------- 
--------AAAAAA-------- ------AAAAAAAAAA------ -----AAAAAAAAAAAA----- ----AAAAAAAAAAAAAA---- ---AAAAAAAAAAAAAAAA--- --BAAAAAAAAAAAAAAAAB-- --BAAAAAAAAAAAAAAAAB-- AAAAAAAAAAAAAAAAAAAAAA AAAAAAAAAAAAAAAAAAAAAA -CAAAAAAAAAAAAAAAAAAC- AAAAAAAAAAAAAAAAAAAAAA -CAAAAAAAAAAAAAAAAAAC- AAAAAAAAAAAAAAAAAAAAAA -CAAAAAAAAAAAAAAAAAAC- AAAAAAAAAAAAAAAAAAAAAA --BAAAAAAAAAAAAAAAAB-- -CAAAAAAAAAAAAAAAAAAC- -CAAAAAAAAAAAAAAAAAAC- AAAAAAAAAAAAAAAAAAAAAA AAAAAAAAAAAAAAAAAAAAAA -BAAAAAAAAAAAAAAAAAAB- -BAAAAAAAAAAAAAAAAAAB- --AAAAAAAAAAAAAAAAAA-- ---AAAAAAAAAAAAAAAA--- ----AAAAAAAAAAAAAA---- -----AAAAAAAAAAAA----- ------AAAAAAAAAA------ --------AAAAAA-------- 
--------AAAAAA-------- -------AAAAAAAA------- -----AAAAAAAAAAAA----- ----AAAAAAAAAAAAAA---- ---AAAAAAAAAAAAAAAA--- ---AAAAAAAAAAAAAAAA--- --BAAAAAAAAAAAAAAAAB-- -BAAAAAAAAAAAAAAAAAAB- AAAAAAAAAAAAAAAAAAAAAA -CAAAAAAAAAAAAAAAAAAC- AAAAAAAAAAAAAAAAAAAAAA -CAAAAAAAAAAAAAAAAAAC- AAAAAAAAAAAAAAAAAAAAAA -CAAAAAAAAAAAAAAAAAAC- AAAAAAAAAAAAAAAAAAAAAA --BAAAAAAAAAAAAAAAAB-- --BAAAAAAAAAAAAAAAAB-- -CAAAAAAAAAAAAAAAAAAC- AAAAAAAAAAAAAAAAAAAAAA AAAAAAAAAAAAAAAAAAAAAA -BAAAAAAAAAAAAAAAAAAB- --AAAAAAAAAAAAAAAAAA-- --AAAAAAAAAAAAAAAAAA-- ---AAAAAAAAAAAAAAAA--- ----AAAAAAAAAAAAAA---- -----AAAAAAAAAAAA----- -------AAAAAAAA------- --------AAAAAA-------- 
----------AA---------- -------AAAAAAAA------- ------AAAAAAAAAA------ ----AAAAAAAAAAAAAA---- ----AAAAAAAAAAAAAA---- ---AAAAAAAAAAAAAAAA--- --BAAAAAAAAAAAAAAAAB-- --BAAAAAAAAAAAAAAAAB-- AAAAAAAAAAAAAAAAAAAAAA AAAAAAAAAAAAAAAAAAAAAA AAAAAAAAAAAAAAAAAAAAAA -CAAAAAAAAAAAAAAAAAAC- AAAAAAAAAAAAAAAAAAAAAA AAAAAAAAAAAAAAAAAAAAAA AAAAAAAAAAAAAAAAAAAAAA --BAAAAAAAAAAAAAAAAB-- -CAAAAAAAAAAAAAAAAAAC- -CAAAAAAAAAAAAAAAAAAC- AAAAAAAAAAAAAAAAAAAAAA -BAAAAAAAAAAAAAAAAAAB- -BAAAAAAAAAAAAAAAAAAB- --AAAAAAAAAAAAAAAAAA-- ---AAAAAAAAAAAAAAAA--- ---AAAAAAAAAAAAAAAA--- ----AAAAAAAAAAAAAA---- ------AAAAAAAAAA------ -------AAAAAAAA------- ----------AA---------- 
---------------------- ---------AAAA--------- ------AAAAAAAAAA------ -----AAAAAAAAAAAA----- ----AAAAAAAAAAAAAA---- ---AAAAAAAAAAAAAAA---- ---AAAAAAAAAAAAAAAA--- --BAAAAAAAAAAAAAAAAB-- -AAAAAAAAAAAAAAAAAAAA- AAAAAAAAAAAAAAAAAAAAAA AAAAAAAAAAAAAAAAAAAAAA AAAAAAAAAAAAAAAAAAAAAA AAAAAAAAAAAAAAAAAAAAAA AAAAAAAAAAAAAAAAAAAAAA AAAAAAAAAAAAAAAAAAAAAA AAAAAAAAAAAAAAAAAAAAAA AAAAAAAAAAAAAAAAAAAAAA AAAAAAAAAAAAAAAAAAAAAA AAAAAAAAAAAAAAAAAAAAAA -BAAAAAAAAAAAAAAAAAAB- --AAAAAAAAAAAAAAAAAA-- ---AAAAAAAAAAAAAAAA--- ---AAAAAAAAAAAAAAAA--- ----AAAAAAAAAAAAAA---- -----AAAAAAAAAAAA----- ------AAAAAAAAAA------ ---------AAAA--------- ---------------------- 
---------------------- ---------------------- --------AAAAAA-------- ------AAAAAAAAAA------ -----AAAAAAAAAAAA----- ----AAAAAAAAAAAAAA---- ---AAAAAAAAAAAAAAAA--- --BAAAAAAAAAAAAAAAAB-- --BAAAAAAAAAAAAAAAAB-- -BAAAAAAAAAAAAAAAAAAB- -BAAAAAAAAAAAAAAAAAAB- AAAAAAAAAAAAAAAAAAAAAA AAAAAAAAAAAAAAAAAAAAAA AAAAAAAAAAAAAAAAAAAAAA AAAAAAAAAAAAAAAAAAAAAA AAAAAAAAAAAAAAAAAAAAAA AAAAAAAAAAAAAAAAAAAAAA -BAAAAAAAAAAAAAAAAAAB- -BAAAAAAAAAAAAAAAAAAB- --AAAAAAAAAAAAAAAAAA-- --AAAAAAAAAAAAAAAAAA-- ---AAAAAAAAAAAAAAAA--- ----AAAAAAAAAAAAAA---- -----AAAAAAAAAAAA----- ------AAAAAAAAAA------ --------AAAAAA-------- ---------------------- ---------------------- 
---------------------- ---------------------- ---------------------- -------AAAAAAAA------- ------AAAAAAAAAA------ -----AAAAAAAAAAAA----- ----AAAAAAAAAAAAAA---- ---AAAAAAAAAAAAAAAA--- --BAAAAAAAAAAAAAAAAB-- --BAAAAAAAAAAAAAAAAB-- -BAAAAAAAAAAAAAAAAAAB- -BAAAAAAAAAAAAAAAAAAB- AAAAAAAAAAAAAAAAAAAAAA AAAAAAAAAAAAAAAAAAAAAA AAAAAAAAAAAAAAAAAAAAAA AAAAAAAAAAAAAAAAAAAAAA -BAAAAAAAAAAAAAAAAAAB- -BAAAAAAAAAAAAAAAAAAB- --AAAAAAAAAAAAAAAAAA-- --AAAAAAAAAAAAAAAAAA-- ---AAAAAAAAAAAAAAAA--- ----AAAAAAAAAAAAAA---- -----AAAAAAAAAAAA----- ------AAAAAAAAAA------ -------AAAAAAAA------- ---------------------- ---------------------- ---------------------- 
---------------------- ---------------------- ---------------------- ---------------------- -------BBBBBBBB------- ------BBAAAAAABB------ -----BBAAAAAAAABB----- ----BBAAAAAAAAAABB---- ---BBAAAAAAAAAAAABB--- ---BAAAAAAAAAAAAAABB-- --BAAAAAAAAAAAAAAAAB-- -BAAAAAAAAAAAAAAAAAAB- -BAAAAAAAAAAAAAAAAAAB- AAAAAAAAAAAAAAAAAAAAAA AAAAAAAAAAAAAAAAAAAAAA -BAAAAAAAAAAAAAAAAAAB- -BAAAAAAAAAAAAAAAAAAB- --AAAAAAAAAAAAAAAAAA-- ---AAAAAAAAAAAAAAAAA-- ---AAAAAAAAAAAAAAAA--- ----AAAAAAAAAAAAAA---- -----AAAAAAAAAAAA----- ------AAAAAAAAAA------ -------AAAAAAAA------- ---------------------- ---------------------- ---------------------- ---------------------- 
---------------------- ---------------------- ---------------------- ---------------------- ---------------------- --------BBBBBB-------- -------BBAAAABB------- ------BBAAAAAABB------ -----BBAAAAAAAABB----- ----BBAAAAAAAAAABB---- ---BBAAAAAAAAAAAABB--- --AAAAAAAAAAAAAAAAAA-- -BAAAAAAAAAAAAAAAAAAB- -BAAAAAAAAAAAAAAAAAAB- -BAAAAAAAAAAAAAAAAAAB- -BAAAAAAAAAAAAAAAAAAB- --AAAAAAAAAAAAAAAAAA-- ---BBAAAAAAAAAAAABB--- ----BBAAAAAAAAAABB---- -----BBAAAAAAAABB----- ------BBAAAAAABB------ -------BBAAAABB------- --------BBBBBB-------- ---------------------- ---------------------- ---------------------- ---------------------- ---------------------- 
---------------------- ---------------------- ---------------------- ---------------------- ---------------------- ---------------------- ---------AAAA--------- --------AAAAAA-------- -------AAABBAAA------- ------AAAABBAAAA------ -----AAAAAAAAAAAA----- --AAAAAAAAAAAAAAAAAA-- --ACCCACACCCCACACCCA-- --ACACACCCCCCCCACACA-- --ACACACACCCCACACACA-- --ACCCACCCCCCCCACCCA-- --BAAAAAAAAAAAAAAAAB-- -----AAAAAAAAAAAA----- ------BAAABBAAAB------ -------BAAAAAAB------- --------BBAABB-------- ---------BBBB--------- ---------------------- ---------------------- ---------------------- ---------------------- ---------------------- ---------------------- 
---------------------- ---------------------- ---------------------- ---------------------- ---------------------- ---------------------- ---------------------- ---------AAAA--------- --------AA--AA-------- -------AAA--AAA------- -----AAAAAAAAAAAA----- ---AAAAAAAAAAAAAAAA--- --A---A-AA-A-A-A---A-- --A-A-A--A-A---A-A-A-- --AAA-A-A--A-A-AAA-A-- --A---A-AA-A---A---A-- ---AAAAAAAAAAAAAAAA--- -----AAAAAAAAAAAA----- -------AAA--AAA------- --------AAAAAA-------- ----------AA---------- ---------------------- ---------------------- ---------------------- ---------------------- ---------------------- ---------------------- ---------------------- 
