model
size = 32 18 11, scale = 0.05, origin = -y
material 
  colors = A:#E00 B:#EEE C:#555 D:#699 E:#A00 F:#888 G:#800 H:#FF0 I:#111
voxels
10-2(20B12-)20F12-10AE9A13-9A4E6A15-10A3E3A17-11AE3A18-10A3E22-10A26-5A91-10G86-10G67-8B18D2B4-28B4-7F20BF2(4-28A)5-27A7-25A9-AB21A12-BAB17A15-AB15A18-B13A20-12A20-B11AG20-2(11A21-)11AG22-9A24-8A2-3B26D2B-31B-2F27ABF-18A10C3A2-17A11C2A3-17A10CA6-15A10CA9-AB11A9CA12-BAB7A9CA15-AB5A9CA18-B4A8CA20-3A8CA20-B2A8CAG20-2(2A8CA21-)2A8CAG22-8CA24-7CA-2B6DBDB3DB3(D3B)4D33BF18A10HABF18AF10-C2A-17AF10-C2A3-15A2F9-C2A5-3AEAE9A9-CA10-B-2EAE5AF8-CA12-2(B-)2E3AF8-CA16-B-3EA8-CA18-B2-2E7-CA21-2E7-CA20-BAE7-CAG20-2(2E7-CA21-)2E7-CAG20-2E7-CA21-2E7-CA-B7DBD3B7(DB)4D33BF18A9IHABF18AF10-C2A-17AF10-C2A3-15A2F9-C2A5-2A2EAE9A9-C2A9-B-2EAE5AF8-CA12-2(B-)2E3AF8-CA16-B-3EA8-CA18-B2-2E7-CA21-2E7-CA20-BAE7-CAG20-2E2(7-CA21-HE)7-CAG20-HE7-CA21-2E7-C3B5D10(BD)B4D33BF18A9IHABF18AF10-C2A-17AF10-C2A3-15A2F9-C2A5-2A2EAE9A9-C2A9-B-2EAE5AF8-C2A11-2(B-)2E3AF8-C2A15-B-3EA8-C2A17-B2-2E7-CA21-2E7-CA20-BAE7-CAG20-2E7-CA21-HE7-CA21-AE7-CAG20-HE7-CA21-2E7-C2IB5D10(BD)B4D33BF18A9IHABF18AF10-C2A-17AF10-C2A3-15A2F9-C2A5-2A2EAE9A9-C2A9-B-2EAE5AF8-CA12-2(B-)2E3AF8-CA16-B-3EA8-CA18-B2-2E7-CA21-2E7-CA20-BAE7-CAG20-2E2(7-CA21-HE)7-CAG20-HE7-CA21-2E7-C4B4D2(3BD)B3(D3B)4D33BF18A10HABF18AF10-C2A-17AF10-C2A3-15A2F9-C2A5-3AEAE9A9-CA10-B-2EAE5AF8-CA12-2(B-)2E3AF8-CA16-B-3EA8-CA18-B2-2E7-CA21-2E7-CA20-BAE7-CAG20-2(2E7-CA21-)2E7-CAG20-2E7-CA21-2E7-CA2-3B26D2B-31B-2F27ABF-18A10C3A2-17A11C2A3-17A10CA6-15A10CA9-AB11A9CA12-BAB7A9CA15-AB5A9CA18-B4A8CA20-3A8CA20-B2A8CAG20-2(2A8CA21-)2A8CAG22-8CA24-7CA4-8B18D2B4-28B4-28F4-17AE10A4-17A4E7A5-19A3E5A7-19AE5A9-AB15A3E3A12-BAB17A15-AB15A18-B13A20-12A20-B11AG20-2(11A21-)11AG22-9A24-8A11-2(20B12-)20F12-10AE9A13-9A4E6A15-10A3E3A17-11AE3A18-10A3E22-10A26-5A90-11G85-11G64-
