model
size = 32, scale = 0.05, origin = -y
material 
  colors = A:#FF6A00 B:#0E0 C:#E00 D:#EEE E:#111 F:#9F0 G:#F63 H:#000 I:#C00 J:#C09 K:#93F L:#777 M:#F33 N:#0D0 O:#F66 P:#500 Q:#0B0 R:#F3F S:#00F T:#007 U:#222 V:#0FC W:#050 X:#D00 Y:#C93 Z:#002 Aa:#070 Ab:#555
voxels
33-2B26-2B2-2B26-2B651-A8-A21-2(2A4G)20-4A4-4A2(20-3AD4-D3A)20-R3A4-4A20-R11A21-2H6A2H14-DE8-H2A2TH14-4B24-4B64-4B24-4B192-4B24-4B19-2H11-B2-B15-2H7-B2-3B-B15-2H7-B-5B16-2H8-4B2-B15-2H7-B2-2B2-B24-B2-4B26-5B-B24-B-3B2-B24-B2-B32-4B24-4B11-A2G3-A2G22-4A4G2A21-12AK19-4A4-4A2(I19-3AD4-D3A)I19-R3A4-4A20-R11A45-ED8-H2TSTZ14-B2-B24-B2-B-2E26-2E2-DE26-ED-B2-B24-B2-B161-2F26-2F-B2FB24-B2FB-2(2F16-2H8-2F2-)2F26-2F34-2C16-2H8-2C2-2C26-2C34-2(2F26-2F2-)2F26-2F-B2FB24-B2FB-2F8-AGA3-2AG9-2F11-Y9A21-12AK19-R3A4-4AI83-R3AL-2L2A2L20-5A2-5A55-HS2-SU14-B2-B24-B2-B-ED26-DE2-2E26-2E-B2-B24-B2-B161-2F26-2F-B2FB15-GH7-B2FB-2(2F16-2H8-2F2-)2F26-2F20-2H12-2C16-2H8-2C2-2C26-2C34-2(2F26-2F2-)2F26-2F-B2FB8-GA3-A10-B2FB-2F8-3AG-2GAK9-2F11-10A21-12AK19-R3A4L4AI21-3D-C3D24-8D22-R4AL2-2A2L20-5A2-5A55-US2-SH14-4B24-4B64-4B24-4B192-4B15-2H7-4B32-B2-B24-B2-5B24-6B-B24-B-3B-2B24-2(2B-)2B24-2B-3B-B24-B-6B24-5B2-B24-B2-B32-4B8-2A3-A10-4B11-4A-3AK22-Y9A21-12AK19-R11AI23-Q4N27-Q4N23-R4AC-2A2LAb20-5A2-4AL55-US2-SU47-2B26-2B2-2B26-2B244-2H343-2A3-A25-4A-3AK22-Y9A21-12AK19-R11AI23-I3NI28-3N24-R4A-CA3LAb20-5A2-4AL55-US2-SU353-2H343-2A3-A25-3AM-AMAK22-Y9A21-12AK19-R11AI24-3N29-3N24-R4AC-A3LAb20-5A2-4AL55-US2-SH353-2H343-2A3-A25-Y2AM-AMAK22-Y9A21-12AK19-R11AI21-7D25-7D23-R4A2-2A3L20-5A2-5A55-US2-SZ353-2H343-YA3-A25-3AM-AMAK22-Y9A21-12AK19-12AI83-R6A5L20-5A2-5A55-HS2-SU353-2H343-2A3-A25-4A-3AK22-10A21-12AK19-12AI19-2(5A2-4AE20-)R10AE20-12A21-10A24-HT2STU28-A2GA28-M2AM28-A2MA123-3(CA2GA27-)CA2MA27-C4O-2H24-C4A28-D2(2GA28-A)2GA28-4A188-4O27-QA2M2AK25-QA2G3A25-QA2G4AK23-QA2G4AI23-2(Q6AZ24-)Q6AX24-QA2M3AD24-Q2(M2A)26-A2GH27-2A2-2A3(K25-6A)2(K25-2A2G2A)K21-4C6A4(K21-4C3E3A)2H20-4CEO2GOA2H23-CAO2GOAK25-DO2GOAK25-AO2AOA2(4I22-2A2G2A)K25-AO2A3(OAK25-AO2G)OA2(K25-6A)K25-D6A25-D7AK23-D7AI23-DA2G3AZ24-DA2G3AX24-D6AD24-D6AN24-D6A25-D3AH26-GA4-AG24-3A-4A4(24-8A)21-3C4E4A24-8D4(28-E3A)H20-3C4E4AH21-2C8A24-D7A2EI2(C20-D7A3I)21-7(D7A24-)8DAK22-D8AI22-2(D7AX23-)D7AD23-D7AN23-D7A24-GQ5AG23-2A7-A22-M8AM4(22-10A)20-2C5E5A22-L4-5(E4A27-)E3AH19-2C6E5A21-C10A3EC18-2(D9A2IC19-)4(D9A22-)D9A21-P10A21-D10A21-P10AI20-2(P9AX21-)P9AD21-P9AN22-V8AN22-M8AM22-DAQ7A22-A8-A22-10A5J18-M6AM-5J17-10A4J18-10A3J19-10A3J17-2C5E5A3J19-L4-E4A3J23-WE4A4J22-AaE4A-4J21-AaE4A-4J22-E4A27-E4A21-L5-E3AH19-3C5E5A3E5C14-D9A2I2C18-D9A2IC18-V5(10A2I19-P)10A2I19-V10A2I19-P9AX21-V9AX2(21-P9AD)21-V9AW23-M6AM23-D9A22-D4QT4A21-2A8-3A19-13A3J16-2(12AE19-)M10AME19-13AJ17-C6E6AC19-2D4-E3A2D2(E24-WE5A)E24-WE6A3J21-AaE6A2(19-D5-E4ADA)17-2CL5E7A9C8-CD13A9C10-D12A7C11-P13A7C11-VD10ADA7C11-PD10ADA6C12-P13A6C12-V2(13A5C13-P)12AD19-2D8A3D19-V10AWC19-V10AWN18-PM10AWN18-P11AWN19-V11AN19-D10A21-DAQ4T3A22-2A8-3A19-13A3J16-2(12AE19-)M10AME19-13AJ17-C6E6AC19-2D4-E3A2D2(E24-WE5A)E24-WE6A3J21-AaE6A2(19-D5-E4ADA)17-2CL5E7A9C8-CD13A9C10-D12A7C11-P13A2(7C11-PD10ADA)6C12-P13A6C12-V2(13A5C13-P)12AD19-2D8A3D19-V10AWC19-V10AWN18-PM10AWN18-P11AWN19-V11AN19-D10A21-DAQ4T3A23-A8-A22-10A5J18-M6AM-5J17-10A4J18-10A3J19-10A3J17-2C5E5A3J19-L4-E4A3J23-WE4A4J22-AaE4A-4J21-AaE4A-4J22-E4A27-E4A21-L5-E3AH19-3C5E5A3E5C14-D9A2I2C18-D9A2IC18-2(P10A2I19-)V3(10A2I19-P)10A2I19-V10A2I19-2(P9AX21-)2(P9AD21-)V9AW23-M6AM23-D9A22-D4QT4A22-2A7-A22-M8AM4(22-10A)20-2C5E5A22-L4-5(E4A27-)E3AH19-2C6E5A21-C10A3EC18-2(D9A2IC19-)4(D9A22-)D9A21-P10A21-D10A21-P10AI20-P9AX21-V9AX21-P9AD21-P9AN22-V8AN22-M8AM22-DAQ7A23-GA4-AG24-3A-4A4(24-8A)21-3C4E4A24-8D4(28-E3A)H20-3C4E4AH21-2C8A24-D7A2EI2(C20-D7A3I)21-7(D7A24-)8DAK22-D8AI22-2(D7AX23-)D7AD23-D7AN23-D7A24-GQ5AG25-2A2-2A3(K25-6A)2(K25-2A2G2A)K21-4C6A4(K21-4C3E3A)2H20-4CEO2GOA2H23-CAO2GOAK25-DO2GOAK25-AO2AOA2(4I22-2A2G2A)K25-AO2A3(OAK25-AO2G)OA2(K25-6A)K25-D6A25-D7AK23-D7AI23-DA2G3AE24-DA2G3AX24-D6AD24-D6AN24-D6A25-D3AH28-A2GA28-M2AM28-A2MA123-3(CA2GA27-)CA2MA27-C4O-2H24-C4A28-D2(2GA28-A)2GA28-4A188-4O27-QA2M2AK25-QA2G3A25-QA2G4AK23-QA2G4AI23-Q6AE24-Q6AZ24-Q6AX24-QA2M3AD24-Q2(M2A)26-A2GH353-2H343-2A3-A25-4A-3AK22-10A21-12AK19-12AI19-5A2-4AZ20-5A2-4AE20-R10AE20-12A21-10A24-HT2STU353-2H343-YA3-A25-Y2AM-AMAK22-10A21-12AK19-12AI83-R6A5L20-5A2-5A55-HS2-SU353-2H343-2A3-A25-Y2AM-AMAK22-Y9A21-12AK19-R11AI21-7D25-7D23-R4A2-2A3L20-5A2-5A55-US2-SZ353-2H343-2A3-A25-Y2AM-AMAK22-Y9A21-12AK19-R11AI24-3N29-3N24-R4AC-A3LAb20-5A2-4AL55-US2-SZ47-2B26-2B2-2B26-2B244-2H343-2A3-A25-4A-3AK22-Y9A21-12AK19-R11AI23-I3NI28-3N24-R4A-CA3LAb20-5A2-4AL55-HS2-SH14-4B24-4B64-4B24-4B192-4B15-2H7-4B32-B2-B24-B2-5B24-6B-B24-B-3B-2B24-2(2B-)2B24-2B-3B-B24-B-6B24-5B2-B24-B2-B32-4B8-2A3-A10-4B11-4A-3AK22-10A21-12AK19-R11AI23-Q4N27-Q4N23-R4AC-2A2LAb20-5A2-4AL55-US2-SZ14-B2-B24-B2-B-ED26-DE2-2E26-2E-B2-B24-B2-B161-2F26-2F-B2FB15-GH7-B2FB-2(2F16-2H8-2F2-)2F26-2F20-2H12-2C16-2H8-2C2-2C26-2C34-2(2F26-2F2-)2F26-2F-B2FB8-GA3-A10-B2FB-2F8-3AG-2GAK9-2F11-10A21-12AK19-R3A4L4AI21-3D-C3D24-8D22-R4AL2-2A2L12-DE6-5A2-5A12-ED41-HS2-SH14-B2-B24-B2-B-2E26-2E2-DE26-ED-B2-B24-B2-B161-2F26-2F-B2FB24-B2FB-2(2F16-2H8-2F2-)2F26-2F34-2C16-2H8-2C2-2C26-2C34-2(2F26-2F2-)2F26-2F-B2FB24-B2FB-2F8-AGA3-2AG9-2F11-Y9A21-12AK19-R3A4-4AI83-R3AL-2L2A2L20-5A2-5A55-US2-SU14-4B24-4B64-4B24-4B192-4B24-4B19-2H11-B2-B15-2H7-B2-3B-B15-2H7-B-5B16-2H8-4B2-B15-2H7-B2-2B2-B24-B2-4B26-5B-B24-B-3B2-B24-B2-B32-4B24-4B11-A2G3-A2G22-4A4G2A21-12AK19-4A4-4A2(I19-3AD4-D3A)I19-R3A4-4A20-R11A55-H2TSTU47-2B26-2B2-2B26-2B651-A8-A21-2(2A4G)20-4A4-4A2(20-3AD4-D3A)20-R3A4-4A20-R11A21-2H6AHU24-U2A2TH14-
