model
size = 20 24 4, scale = 0.05, origin = -y
material 
  colors = A:#EEE B:#222
voxels
--BABABABABABABABA-- -B--A--B----A--B--A- -A--B--A----B--A--B- --A--B-B----A-A--B-- --B--A-A----B-B--A-- ---B-B-B----A-A-A--- ---A-A--B--A--B-B--- ---B--A-A--B-B--A--- ----B-B-B--A-A-A---- ----A-A-A--B-B-B---- -----A--B--A--B----- -----BA-A--B-BA----- ------B-B--A-A------ ------A-A--B-B------ -------AB--AB------- -------BA--BA------- -------A-AB-B------- -------B-BA-A------- --------B--A-------- --------A--B-------- --------B--A-------- -------------------- -------------------- -------------------- 
-A----------------B- AAABABABABABABABABAB BABABABABABABABABAAA -BABABABABABABABAAA- --AABABABABABABABA-- --AAABABABABABABAB-- --BABABABABABABAAA-- --AAABABABABABABAB-- --B-AABABABABABA-A-- ----ABABABABABAA---- ---A-ABABABABAB-B--- ---B-BABABABABA-A--- ----B-BABABABA-A---- ----A-ABABABAA-B---- ----BA-ABABAB-BA---- -----B-BABABA-A----- -----ABABABABAB----- ------ABABABAB------ ------BABABABA------ -------BABABA------- -------AAABAB------- --------A--B-------- -------------------- -------------------- 
B------------------A ABA--------------BAA AAAA------------BAAB AAAB------------AAAB --AA------------BA-- --ABA----------BAA-- --AAB----------ABA-- --AAA----------BAA-- --AAB----------ABA-- --ABA----------BAB-- ---AB----------AA--- ---AA----------BA--- ---ABA--------BAB--- ----ABA------BAB---- ----AAB------ABA---- ----ABA------BAB---- -----A--------B----- -----BA------BA----- ------BA----BA------ ------AB----AB------ -------AB--AA------- -------BABAAA------- -------------------- -------------------- 
-------------------- A------------------B BAB--------------ABA -BA--------------BA- -AB--------------AB- -BA--------------BA- --B--------------A-- --AB------------AB-- --BA------------BA-- --AB------------AB-- --BA------------BA-- --AB------------AB-- ---A------------B--- ---B------------A--- ---AB----------AB--- ---BA----------BA--- ---AB----------AB--- ----A----------B---- ----BA--------BA---- -----BA------BA----- ------BA----BA------ -------BA--BA------- -------ABABAB------- --------ABAB-------- 
