model
size = 18 18 30, scale = 0.05, origin = -y
material 
  colors = A:#C0F B:#222 C:#444 D:#0FC
voxels
-------BBBB------- -------BBBB------- ------------------ ------------------ ------------------ ------------------ ------------------ ------------------ ------------------ ------------------ ------------------ ------------------ ------------------ ------------------ ------------------ ------------------ ------------------ ------------------ 
------BBBBBB------ ------BBBBBB------ --------DD-------- --------DD-------- ------------------ ------------------ ------------------ ------------------ ------------------ ------------------ ------------------ ------------------ ------------------ ------------------ ------------------ ------------------ ------------------ ------------------ 
-----BBBBBBBB----- -----BBBBBBBB----- -------DDDD------- -------DDDD------- -------DDDD------- ------------------ ------------------ ------------------ ------------------ ------------------ ------------------ ------------------ ------------------ ------------------ ------------------ ------------------ ------------------ ------------------ 
----BBBBBBBBBB---- ----BBBBBBBBBB---- ------AAAAAA------ ------AAAAAA------ ------AAAAAA------ -------AAAA------- ------------------ ------------------ ------------------ ------------------ ------------------ ------------------ ------------------ ------------------ ------------------ ------------------ ------------------ ------------------ 
---BBBBBBBBBBBB--- ---BBBBBBBBBBBB--- -----AAAAAAAA----- -----AAAAAAAA----- -----AAAAAAAA----- -------AAAA------- -------DDDD------- ------------------ ------------------ ------------------ ------------------ ------------------ ------------------ ------------------ ------------------ ------------------ ------------------ ------------------ 
--BBBBBBBBBBBBBB-- --BBBBBBBBBBBBBB-- ----AAAAAAAAAA---- ----AAAAAAAAAA---- ----AAAAAAAAAA---- ------AAAAAA------ -------AAAA------- -------AAAA------- ------------------ ------------------ ------------------ ------------------ ------------------ ------------------ ------------------ ------------------ ------------------ ------------------ 
-BBBBBBBBBBBBBBBB- -BBBBBBBBBBBBBBBB- ---AAAAAAAAAAAA--- ---AAAAAAAAAAAA--- ---AAAAAAAAAAAA--- -----AAACCAAA----- ------AAAAAA------ ------AAAAAA------ -------DDDD------- ------------------ ------------------ ------------------ ------------------ ------------------ ------------------ ------------------ ------------------ ------------------ 
-BBBBBBBBBBBBBBBB- -BBBBBBBBBBBBBBBB- --AAAACCCCCCAAAA-- --AAAACCCCCCAAAA-- --AAAAAACCAAAAAA-- ----AAAACCAAAA---- ------AAAAAA------ ------AAAAAA------ -------AAAA------- -------AAAA------- ------------------ ------------------ ------------------ ------------------ ------------------ ------------------ ------------------ ------------------ 
BBBBBBBBBBBBBBBBBB BBBBBBBBBBBBBBBBBB --AAAACCCCCCAAAA-- --AAAACCCCCCAAAA-- --AAAAAACCAAAAAA-- ---AAAAACCAAAAA--- -----AAAAAAAA----- -----AAAAAAAA----- ------AAAAAA------ -------AAAA------- ------------------ ------------------ ------------------ ------------------ ------------------ ------------------ ------------------ ------------------ 
BBBBBBBBBBBBBBBBBB BBBBBBBBBBBBBBBBBB -AAAAACCCCCCAAAAA- -AAAAACCCCCCAAAAA- --AAAAAACCAAAAAA-- ---AAAAACCAAAAA--- ----AAAAAAAAAA---- ----AAAAAAAAAA---- ------AAAAAA------ -------AAAA------- ------------------ ------------------ ------------------ ------------------ ------------------ ------------------ ------------------ ------------------ 
BBBBBBBBBBBBBBBBBB BBBBBBBBBBBBBBBBBB -AAAAACCCCCCAAAAA- -AAAAACCCCCCAAAAA- --AAAAAACCAAAAAA-- ---AAAAACCAAAAA--- ----AAAAAAAAAA---- ----AAAAAAAAAA---- ------AAAAAA------ -------AAAA------- -------DDDD------- ------------------ ------------------ ------------------ ------------------ ------------------ ------------------ ------------------ 
BBBBBBBBBBBBBBBBBB BBBBBBBBBBBBBBBBBB -AAAAACCCCCCAAAAA- -AAAAACCCCCCAAAAA- --AAAAAACCAAAAAA-- ---AAAAACCAAAAA--- ----AAAAAAAAAA---- ----AAAAAAAAAA---- -----AAAAAAAA----- ------AAAAAA------ -------DDDD------- ------------------ ------------------ ------------------ ------------------ ------------------ ------------------ ------------------ 
BBBBBBBBBBBBBBBBBB BBBBBBBBBBBBBBBBBB -AAAAACCCCCCAAAAA- -AAAAACCCCCCAAAAA- --AAAAAACCAAAAAA-- ---AAAAACCAAAAA--- ----AAAAAAAAAA---- ----AAAAAAAAAA---- -----AAAAAAAA----- ------AAAAAA------ -------DDDD------- ------------------ ------------------ ------------------ ------------------ ------------------ ------------------ ------------------ 
BBBBBBBBBBBBBBBBBB BBBBBBBBBBBBBBBBBB -AAAAACCCCCCAAAAA- -AAAAACCCCCCAAAAA- --AAAAAACCAAAAAA-- ---AAAAACCAAAAA--- ----AAAAAAAAAA---- ----AAAAAAAAAA---- -----AAAAAAAA----- ------AAAAAA------ -------AAAA------- -------AAAA------- ------------------ ------------------ ------------------ ------------------ ------------------ ------------------ 
BBBBBBBBBBBBBBBBBB BBBBBBBBBBBBBBBBBB -AAAAACCCCCCAAAAA- -AAAAACCCCCCAAAAA- --AAAAAACCAAAAAA-- ---AAAAACCAAAAA--- ----AAAAAAAAAA---- ----AAAAAAAAAA---- -----AAAAAAAA----- ------AAAAAA------ ------AAAAAA------ -------AAAA------- ------------------ ------------------ ------------------ ------------------ ------------------ ------------------ 
BBBBBBBBBBBBBBBBBB BBBBBBBBBBBBBBBBBB -AAAAACCCCCCAAAAA- -AAAAACCCCCCAAAAA- --AAAAAACCAAAAAA-- ---AAAAACCAAAAA--- ----AAAAAAAAAA---- ----AAAAAAAAAA---- -----AAAAAAAA----- ------AAAAAA------ ------AAAAAA------ -------AAAA------- ------------------ ------------------ ------------------ ------------------ ------------------ ------------------ 
BBBBBBBBBBBBBBBBBB BBBBBBBBBBBBBBBBBB -AAAAACCCCCCAAAAA- -AAAAACCCCCCAAAAA- --AAAAAACCAAAAAA-- ---AAAAACCAAAAA--- ----AAAAAAAAAA---- ----AAAAAAAAAA---- -----AAAAAAAA----- ------AAAAAA------ ------AAAAAA------ -------AAAA------- ------------------ ------------------ ------------------ ------------------ ------------------ ------------------ 
BBBBBBBBBBBBBBBBBB BBBBBBBBBBBBBBBBBB -AAAAACCCCCCAAAAA- -AAAAACCCCCCAAAAA- --AAAAAACCAAAAAA-- ---AAAAACCAAAAA--- ----AAAAAAAAAA---- ----AAAAAAAAAA---- -----AAAAAAAA----- ------AAAAAA------ ------AAAAAA------ ------AAAAAA------ -------DDDD------- ------------------ ------------------ ------------------ ------------------ ------------------ 
BBBBBBBBBBBBBBBBBB BBBBBBBBBBBBBBBBBB -AAAAACCCCCCAAAAA- -AAAAACCCCCCAAAAA- --AAAAAACCAAAAAA-- ---AAAAACCAAAAA--- ----AAAAAAAAAA---- ----AAAAAAAAAA---- -----AAAAAAAA----- ------AAAAAA------ ------AAAAAA------ ------AAAAAA------ -------DDDD------- ------------------ ------------------ ------------------ ------------------ ------------------ 
BBBBBBBBBBBBBBBBBB BBBBBBBBBBBBBBBBBB -AAAAACCCCCCAAAAA- -AAAAACCCCCCAAAAA- --AAAAAACCAAAAAA-- ---AAAAACCAAAAA--- ----AAAAAAAAAA---- ----AAAAAAAAAA---- ----AAAAAAAAAA---- ----AAAAAAAAAA---- ----AAAAAAAAAA---- ------AAAAAA------ -------DDDD------- ------------------ ------------------ ------------------ ------------------ ------------------ 
BBBBBBBBBBBBBBBBBB BBBBBBBBBBBBBBBBBB -AAAAACCCCCCAAAAA- -AAAAACCCCCCAAAAA- --AAAAACCCCAAAAA-- ---AAAACCCCAAAA--- ---CACCCCCCCCAC--- ---CACCCCCCCCAC--- ---CACCCCCCCCAC--- ---CACCCCCCCCAC--- ----AACCCCCCAA---- ------AACCAA------ -------ACCA------- -------CCCC------- -------CCCC------- -------CCCC------- -------CCCC------- -------CCCC------- 
BBBBBBBBBBBBBBBBBB BBBBBBBBBBBBBBBBBB -AAAAACCCCCCAAAAA- -AAAAACCCCCCAAAAA- --AAAAACCCCAAAAA-- ---AAAACCCCAAAA--- ---CACCCCCCCCAC--- -DCCACCCCCCCCACCD- -DCCACCCCCCCCACCD- ---CACCCCCCCCAC--- ----AACCCCCCAA---- ------AACCAA------ -------ACCA------- -------CCCC------- -------CCCC------- -------CCCC------- -------CCCC------- -------CCCC------- 
-BBBBBBBBBBBBBBBB- -BBBBBBBBBBBBBBBB- --AAAAAAAAAAAAAA-- --AAAAAAAAAAAAAA-- --AAAAAAAAAAAAAA-- ---AAAAAAAAAAAA--- ---CAAAAAAAAAAC--- -DCCAAAAAAAAAACCD- -DCCAAAAAAAAAACCD- ---CAAAAAAAAAAC--- ----AAAAAAAAAA---- ------AACCAA------ -------ACCA------- -------CCCC------- -------CCCC------- -------CCCC------- -------CCCC------- -------CCCC------- 
-BBBBBBBBBBBBBBBB- -BBBBBBBBBBBBBBBB- ---AAAAAAAAAAAA--- ---AAAAAAAAAAAA--- ---AAAAAAAAAAAA--- ----AAAAAAAAAA---- ---CAAAAAAAAAAC--- ---CAAAAAAAAAAC--- ---CAAAAAAAAAAC--- ---CAAAAAAAAAAC--- -------AAAA------- -------ACCA------- -------AAAA------- ------------------ ------------------ ------------------ ------------------ ------------------ 
--BBBBBBBBBBBBBB-- --BBBBBBBBBBBBBB-- ---AAAAAAAAAAAA--- ---AAAAAAAAAAAA--- ---AAAAAAAAAAAA--- ----AAAAAAAAAA---- -----AAAAAAAA----- -----AAAAAAAA----- -----AAAAAAAA----- -------AAAA------- -------AAAA------- -------ACCA------- -------ADDA------- ------------------ ------------------ ------------------ ------------------ ------------------ 
--BBBBBBBBBBBBBB-- --BBBBBBBBBBBBBB-- ----AAAAAAAAAA---- ----AAAAAAAAAA---- ----AAAAAAAAAA---- -----AAAAAAAA----- -------AAAA------- -------AAAA------- -------AAAA------- --------AA-------- --------AA-------- --------AA-------- --------AA-------- ------------------ ------------------ ------------------ ------------------ ------------------ 
---BBBBBBBBBBBB--- ---BBBBBBBBBBBB--- ----AAAADDAAAA---- ----AAAADDAAAA---- ----AAAADDAAAA---- ------AADDAA------ --------DD-------- --------DD-------- --------DD-------- --------DD-------- --------DD-------- --------DD-------- --------DD-------- ------------------ ------------------ ------------------ ------------------ ------------------ 
---BBBBBBBBBBBB--- ---BBBBBBBBBBBB--- -----AAADDAAA----- -----AAADDAAA----- -----AAADDAAA----- --------DD-------- --------DD-------- --------DD-------- --------DD-------- --------DD-------- ------------------ ------------------ ------------------ ------------------ ------------------ ------------------ ------------------ ------------------ 
----BBBBBBBBBB---- ----BBBBBBBBBB---- -------ADDA------- -------ADDA------- -------ADDA------- ------------------ ------------------ ------------------ ------------------ ------------------ ------------------ ------------------ ------------------ ------------------ ------------------ ------------------ ------------------ ------------------ 
------------------ ------BBBBBB------ ------------------ ------------------ ------------------ ------------------ ------------------ ------------------ ------------------ ------------------ ------------------ ------------------ ------------------ ------------------ ------------------ ------------------ ------------------ ------------------ 
