model
size = 14 13 24, scale = 0.05, origin = -y
material 
  colors = A:#555 B:#C3C C:#777 D:#0FC
voxels
-------------- -------------- -------------- -------------- -------------- -------------- -----CCCC----- ------CC------ -----CCCC----- -------------- -------------- -------------- -------------- 
-------------- -------------- -------------- -------------- -------------- -------------- -----CCCC----- ------CC------ -----CCCC----- -------------- -------------- -------------- -------------- 
-------------- -------------- -------------- -------------- -------------- -------------- -----CCCC----- ------CC------ -----CCCC----- -------------- -------------- -------------- -------------- 
-------------- -------------- -------------- -------------- -------------- -------------- -----CCCC----- ------CC------ -----CCCC----- -------------- -------------- -------------- -------------- 
-------------- -------------- -------------- -------------- -------------- -----CCCC----- -----CCCC----- -----CCCC----- -----CCCC----- -----CCCC----- -------------- -------------- -------------- 
-------------- -------------- -------------- ----CCCCCC---- ----CCCCCC---- ----CCCCCC---- ----CCCCCC---- ----CCCCCC---- ----CCCCCC---- ----CCCCCC---- ----CCCCCC---- -------------- -------------- 
---AAABBAAA--- DAAAAAAAAAAAAD DAAAAAAAAAAAAD DAAAAAAAAAAAAD -AAAAAAAAAAAA- --AAAAAAAAAA-- -------------- --AAAAAAAAAA-- -AAAAAAAAAAAA- DAAAAAAAAAAAAD DAAAAAAAAAAAAD DAAAAAAAAAAAAD ---AAABBAAA--- 
-AAAB-BB-BAAA- DAAABBAABBAAAD --AAAAAAAAAA-- DAAAAAAAAAAAAD -AAAAAAAAAAAA- --AAAAAAAAAA-- -------------- --AAAAAAAAAA-- -AAAAAAAAAAAA- DAAAAAAAAAAAAD --AAAAAAAAAA-- DAAABBAABBAAAD -AAAB-BB-BAAA- 
-AAAB-BB-BAAA- DAAABBAABBAAAD DAAAAAAAAAAAAD DAAAAAAAAAAAAD --AAAAAAAAAAA- --AAAAAAAAAA-- -------------- --AAAAAAAAAA-- --AAAAAAAAAAA- DAAAAAAAAAAAAD DAAAAAAAAAAAAD DAAABBAABBAAAD -AAAB-BB-BAAA- 
--ABB-BB-BBA-- -AAABBAABBAAAD --AAAAAAAAAAAD --AAAAAAAAAA-- -------------- -------------- -------------- -------------- -------------- --AAAAAAAAAA-- --AAAAAAAAAAAD -AAABBAABBAAAD --ABB-BB-BBA-- 
--ABB-BB-BBA-- --AABBAABBAA-- --AAAAAAAAAA-- -------------- -------------- -------------- -------------- -------------- -------------- -------------- --AAAAAAAAAA-- --AABBAABBAA-- --ABB-BB-BBA-- 
--ABB-BB-BBA-- --AABBAABBAA-- -------------- -------------- -------------- -------------- -------------- -------------- -------------- -------------- -------------- --AABBAABBAA-- --ABB-BB-BBA-- 
--AAB-BB-BAA-- --AABBAABBAA-- -------------- -------------- -------------- -------------- -------------- -------------- -------------- -------------- -------------- --AABBAABBAA-- --AAB-BB-BAA-- 
--AAB-BB-BAA-- --AABBAABBA--- -------------- -------------- -------------- -------------- -------------- -------------- -------------- -------------- -------------- --AABBAABBA--- --AAB-BB-BAA-- 
--AAAABBAAAA-- --AAAAAAAAA--- -------------- -------------- -------------- -------------- -------------- -------------- -------------- -------------- -------------- --AAAAAAAAA--- --AAAABBAAAA-- 
---AAABBAAA--- --AAAAAAAAA--- ----AAAAAA---- -------------- -------------- -------------- -------------- -------------- -------------- -------------- ----AAAAAA---- --AAAAAAAAA--- ---AAABBAAA--- 
-------------- --AAAAAAAAA--- --AAAAAAAAA--- -------------- -------------- -------------- -------------- -------------- -------------- -------------- --AAAAAAAAA--- --AAAAAAAAA--- -------------- 
-------------- ----AABBAA---- --AAAAAAAAA--- -----AAAA----- -------------- -------------- -------------- -------------- -------------- -----AAAA----- --AAAAAAAAA--- ----AABBAA---- -------------- 
-------------- -------------- --AAAAAAAAA--- --AAAAAAAAA--- -------------- -------------- -------------- -------------- -------------- --AAAAAAAAA--- --AAAAAAAAA--- -------------- -------------- 
-------------- -------------- ----AABBAA---- --AAAAAAAAA--- -------------- -------------- -------------- -------------- -------------- --AAAAAAAAA--- ----AABBAA---- -------------- -------------- 
-------------- -------------- -------------- ---AAAAAAAA--- -------------- -------------- -------------- -------------- -------------- ---AAAAAAAA--- -------------- -------------- -------------- 
-------------- -------------- -------------- ----BBBBBB---- ---BBBBBBBB--- ---BBBBBBBB--- -------------- ---BBBBBBBB--- ---BBBBBBBB--- ----BBBBBB---- -------------- -------------- -------------- 
-------------- -------------- -------------- -------------- -----BBBB----- -----BBBB----- -------------- -----BBBB----- -----BBBB----- -------------- -------------- -------------- -------------- 
-------------- -------------- -------------- -------------- ------BB------ -----BBBB----- -------------- -----BBBB----- ------BB------ -------------- -------------- -------------- -------------- 
