model
size = 20 21 12, scale = 0.05, origin = -y
material 
  colors = A:#444 B:#222 C:#F0F D:#0FC
voxels
-------------------- -------------------- -------------------- -------------------- -------------------- -------------------- -------------------- -------------------- -------------------- -------CCCCCC------- -------C----C------- -------C---CC------- -------C----C------- -------CCCCCC------- -------------------- -------------------- -------------------- -------------------- -------------------- -------------------- -------------------- 
-------------------- -------------------- -------------------- -------------------- -------------------- -------------------- -------------------- -------------------- -------------------- -------AAAAAA------- -------A----A------- --BBBBBA---AABBBBB-- --BBBBBA----ABBBBB-- -------AAAAAA------- -------------------- -------------------- -------------------- -------------------- -------------------- -------------------- -------------------- 
---------AA--------- ---------AA--------- ---------AA--------- ---------AA--------- ---------AA--------- ---------AA--------- ----AAAAAAAAAAAA---- ----A-A--AA--A-A---- ----A-A--AA--A-A---- ----A-AAAAAAAA-A---- ----A-AABBBBAA-A---- -BBAAAAABBBBAAAAABB- -BBBBBB-BBBB-BBBBBB- -------------------- -------------------- -------------------- -------------------- -------------------- -------------------- -------------------- -------------------- 
-------------------- --------AAAA-------- --------AAAA-------- --------AAAA-------- --------AAAA-------- ---AAAAAAAAAAAAAA--- ---AAAAAAAAAAAAAA--- ---AABABBAABBABAA--- ---AABABBAABBABAA--- ---AABAAAAAAAABAA--- ---BBBBBBBBBBBBBB--- BB----------------BB BB----------------BB -------------------- -------------------- -------------------- -------------------- -------------------- -------------------- -------------------- -------------------- 
--------AAAA-------- --------AAAA-------- --------AAAA-------- --------AAAA-------- ------AAAAAAAA------ ---AAAAAAAAAAAAAA--- ---AAAAAAAAAAAAAA--- ---AAAAAAAAAAAAAA--- --AAAAAAAAAAAAAAAA-- --AAAAAAAAAAAAAAAA-- --BBBBBBBBBBBBBBBB-- BB----------------BB BB----------------BB -------------------- -------------------- -------------------- -------------------- -------------------- -------------------- -------------------- -------------------- 
-------------------- --------AAAA-------- --------AAAA-------- --------AAAA-------- ------AAAAAAAA------ ---AAAAAAAAAAAAAA--- --BAAAAAAAAAAAAAAB-- ---AAAAAAAAAAAAAA--- -AAAAAAAAAAAAAAAAAA- -AAAAAAAAAAAAAAAAAA- -BBBBBBBBBBBBBBBBBB- BB----------------BB BB----------------BB -------------------- -------------------- -------------------- -------------------- -------------------- -------------------- -------------------- -------------------- 
-------------------- -------AAAAAA------- -------AAAAAA------- -------AAAAAA------- -----AAAAAAAAAA----- ---AAAAAAAAAAAAAA--- --BAAAAAAAAAAAAAAB-- ---AAAAAAAAAAAAAA--- -AAAAAAAAAAAAAAAAAA- -BAAAAAAAAAAAAAAAAB- -BBBBBBBAAAABBBBBBB- BB----------------BB BB------AAAA------BB -------------------- --------AAAA-------- -------------------- --------AAAA-------- -------------------- --------AAAA-------- -------------------- --------AAAA-------- 
-------------------- -------AAAAAA------- -------AAAAAA------- -------AAAAAA------- -----AAAAAAAAAA----- ---AAAAAAAAAAAAAA--- --BAAAAAAAAAAAAAAB-- ---AAAAAAAAAAAAAA--- -AAAAAAAAAAAAAAAAAA- -AAAAAAAAAAAAAAAAAA- -BBBBBBBAAAABBBBBBB- BB-------DD-------BB BB------AAAA------BB ---------DD--------- --------AAAA-------- ---------DD--------- --------AAAA-------- ---------DD--------- --------AAAA-------- ---------DD--------- --------AAAA-------- 
-------------------- -------------------- -------------------- -------------------- -----AAAAAAAAAA----- ---AAAAAAAAAAAAAA--- ---AAAAAAAAAAAAAA--- ---AAAAAAAAAAAAAA--- --AAAAAAAAAAAAAAAA-- --AAAAAAAAAAAAAAAA-- --BBBBBBAAAABBBBBB-- BB-------AA-------BB BB------AAAA------BB ---------AA--------- --------AAAA-------- -------------------- --------AAAA-------- -------------------- --------AAAA-------- -------------------- --------AAAA-------- 
-------------------- -------------------- -------------------- -------------------- -------------------- ---AAAAABAABAAAAA--- ---ABAAABAABAAABA--- ---AAAAABAABAAAAA--- ---ABAAABAABAAABA--- --AABAAABAABAAABAA-- --BBBAAABAABAAABBB-- --BBBBBBBAABBBBBBB-- --BBBBBBBAABBBBBBB-- -------------------- -------------------- -------------------- -------------------- -------------------- -------------------- -------------------- -------------------- 
-------------------- -------------------- -------------------- -------------------- -------------------- -----AAA-AA-AAA----- -----AAA-AA-AAA----- -----AAA-AA-AAA----- -----AAA-AA-AAA----- -----AAA-AA-AAA----- -----AAA-AA-AAA----- -----BAB-BB-BAB----- -----BBB-BB-BBB----- -------------------- -------------------- -------------------- -------------------- -------------------- -------------------- -------------------- -------------------- 
-------------------- -------------------- -------------------- -------------------- -------------------- -------------------- -------------------- ------B------B------ ------A------A------ ------B------B------ ------A------A------ ------A------A------ -------------------- -------------------- -------------------- -------------------- -------------------- -------------------- -------------------- -------------------- -------------------- 
