model
size = 28 30 10, scale = 0.05, origin = -y
material 
  colors = A:#FC3 B:#FF0
voxels
---------------------------- ---------------------------- ---------------------------- ---------------------------- ---------------------------- ---------------------------- ---------------------------- ---------------------------- ---------------------------- ---------------------------- ---------------------------- ---------------------------- ---------------------------- ---------------------------- ------------BB-------------- ------------BB-------------- ---------------------------- ---------------------------- ---------------------------- ---------------------------- ---------------------------- ---------------------------- ---------------------------- ---------------------------- ---------------------------- ---------------------------- ---------------------------- ---------------------------- ---------------------------- ---------------------------- 
-------------BB------------- -------------BABBBBBBB------ -------------BAAAAAAAABB---- -------------BABBBBBBBAABB-- -------------BA-------BAAB-- -------------BA--------BAAB- -------------BA---------BAB- -------------BA---------BAAB -------------BA---------BAAB -------------BA---------BAAB ------------BAA---------BAAB -----------BAAAB-------BAAAB BBBBBBBBBBBAAAAB------BAAAB- BAAAAAAAAAAAAAAABBBBBBAAAAB- BAAAAAAAAAAABBAAAAAAAAAAAB-- BAAAAAAAAAAABBAAAAAAAAAAAB-- BAAAAAAAAAAAAAAABBBBBBAAAAB- BBBBBBBBBBBAAAAB------BAAAB- -----------BAAAB-------BAAAB ------------BAA---------BAAB -------------BA---------BAAB -------------BA---------BAAB -------------BA---------BAAB -------------BA---------BAB- -------------BA--------BAAB- -------------BA-------BAAB-- -------------BABBBBBBBAABB-- -------------BAAAAAAAABB---- -------------BBBBBBBBB------ -------------B-------------- 
-------------AA------------- -------------AAAAAAAAA------ -------------AAAAAAAAAAA---- -------------AAAAAAAAAAAAA-- -------------AA-------AAAA-- -------------AA--------AAAA- -------------AA---------AAA- -------------AA---------AAAA -------------AA---------AAAA -------------AA---------AAAA ------------AAA---------AAAA -----------AAAAA-------AAAAA AAAAAAAAAAAAAAAA------AAAAA- AAAAAAAAAAAAAAAAAAAAAAAAAAA- AAAAAAAAAAAAAAAAAAAAAAAAAA-- AAAAAAAAAAAAAAAAAAAAAAAAAA-- AAAAAAAAAAAAAAAAAAAAAAAAAAA- AAAAAAAAAAAAAAAA------AAAAA- -----------AAAAA-------AAAAA ------------AAA---------AAAA -------------AA---------AAAA -------------AA---------AAAA -------------AA---------AAAA -------------AA---------AAA- -------------AA--------AAAA- -------------AA-------AAAA-- -------------AAAAAAAAAAAAA-- -------------AAAAAAAAAAA---- -------------AAAAAAAAA------ -------------A-------------- 
-------------AA------------- -------------AAAAAAAAA------ -------------AAAAAAAAAAA---- -------------AAAAAAAAAAAAA-- -------------AA-------AAAA-- -------------AA--------AAAA- -------------AA---------AAA- -------------AA---------AAAA -------------AA---------AAAA -------------AA---------AAAA ------------AAA---------AAAA -----------AAAAA-------AAAAA AAAAAAAAAAAAAAAA------AAAAA- AAAAAAAAAAAAAAAAAAAAAAAAAAA- AAAAAAAAAAAAAAAAAAAAAAAAAA-- AAAAAAAAAAAAAAAAAAAAAAAAAA-- AAAAAAAAAAAAAAAAAAAAAAAAAAA- AAAAAAAAAAAAAAAA------AAAAA- -----------AAAAA-------AAAAA ------------AAA---------AAAA -------------AA---------AAAA -------------AA---------AAAA -------------AA---------AAAA -------------AA---------AAA- -------------AA--------AAAA- -------------AA-------AAAA-- -------------AAAAAAAAAAAAA-- -------------AAAAAAAAAAA---- -------------AAAAAAAAA------ -------------A-------------- 
-------------AA------------- -------------AAAAAAAAA------ -------------AAAAAAAAAAA---- -------------AAAAAAAAAAAAA-- -------------AA-------AAAA-- -------------AA--------AAAA- -------------AA---------AAA- -------------AA---------AAAA -------------AA---------AAAA -------------AA---------AAAA ------------AAA---------AAAA -----------AAAAA-------AAAAA AAAAAAAAAAAAAAAA------AAAAA- AAAAAAAAAAAAAAAAAAAAAAAAAAA- AAAAAAAAAAAAAAAAAAAAAAAAAA-- AAAAAAAAAAAAAAAAAAAAAAAAAA-- AAAAAAAAAAAAAAAAAAAAAAAAAAA- AAAAAAAAAAAAAAAA------AAAAA- -----------AAAAA-------AAAAA ------------AAA---------AAAA -------------AA---------AAAA -------------AA---------AAAA -------------AA---------AAAA -------------AA---------AAA- -------------AA--------AAAA- -------------AA-------AAAA-- -------------AAAAAAAAAAAAA-- -------------AAAAAAAAAAA---- -------------AAAAAAAAA------ -------------A-------------- 
-------------AA------------- -------------AAAAAAAAA------ -------------AAAAAAAAAAA---- -------------AAAAAAAAAAAAA-- -------------AA-------AAAA-- -------------AA--------AAAA- -------------AA---------AAA- -------------AA---------AAAA -------------AA---------AAAA -------------AA---------AAAA ------------AAA---------AAAA -----------AAAAA-------AAAAA AAAAAAAAAAAAAAAA------AAAAA- AAAAAAAAAAAAAAAAAAAAAAAAAAA- AAAAAAAAAAAAAAAAAAAAAAAAAA-- AAAAAAAAAAAAAAAAAAAAAAAAAA-- AAAAAAAAAAAAAAAAAAAAAAAAAAA- AAAAAAAAAAAAAAAA------AAAAA- -----------AAAAA-------AAAAA ------------AAA---------AAAA -------------AA---------AAAA -------------AA---------AAAA -------------AA---------AAAA -------------AA---------AAA- -------------AA--------AAAA- -------------AA-------AAAA-- -------------AAAAAAAAAAAAA-- -------------AAAAAAAAAAA---- -------------AAAAAAAAA------ -------------A-------------- 
-------------AA------------- -------------AAAAAAAAA------ -------------AAAAAAAAAAA---- -------------AAAAAAAAAAAAA-- -------------AA-------AAAA-- -------------AA--------AAAA- -------------AA---------AAA- -------------AA---------AAAA -------------AA---------AAAA -------------AA---------AAAA ------------AAA---------AAAA -----------AAAAA-------AAAAA AAAAAAAAAAAAAAAA------AAAAA- AAAAAAAAAAAAAAAAAAAAAAAAAAA- AAAAAAAAAAAAAAAAAAAAAAAAAA-- AAAAAAAAAAAAAAAAAAAAAAAAAA-- AAAAAAAAAAAAAAAAAAAAAAAAAAA- AAAAAAAAAAAAAAAA------AAAAA- -----------AAAAA-------AAAAA ------------AAA---------AAAA -------------AA---------AAAA -------------AA---------AAAA -------------AA---------AAAA -------------AA---------AAA- -------------AA--------AAAA- -------------AA-------AAAA-- -------------AAAAAAAAAAAAA-- -------------AAAAAAAAAAA---- -------------AAAAAAAAA------ -------------A-------------- 
-------------AA------------- -------------AAAAAAAAA------ -------------AAAAAAAAAAA---- -------------AAAAAAAAAAAAA-- -------------AA-------AAAA-- -------------AA--------AAAA- -------------AA---------AAA- -------------AA---------AAAA -------------AA---------AAAA -------------AA---------AAAA ------------AAA---------AAAA -----------AAAAA-------AAAAA AAAAAAAAAAAAAAAA------AAAAA- AAAAAAAAAAAAAAAAAAAAAAAAAAA- AAAAAAAAAAAAAAAAAAAAAAAAAA-- AAAAAAAAAAAAAAAAAAAAAAAAAA-- AAAAAAAAAAAAAAAAAAAAAAAAAAA- AAAAAAAAAAAAAAAA------AAAAA- -----------AAAAA-------AAAAA ------------AAA---------AAAA -------------AA---------AAAA -------------AA---------AAAA -------------AA---------AAAA -------------AA---------AAA- -------------AA--------AAAA- -------------AA-------AAAA-- -------------AAAAAAAAAAAAA-- -------------AAAAAAAAAAA---- -------------AAAAAAAAA------ -------------A-------------- 
-------------BB------------- -------------BBBBBBBBB------ -------------BAAAAAAAABB---- -------------BABBBBBBBAABB-- -------------BA-------BAAB-- -------------BA--------BAAB- -------------BA---------BAB- -------------BA---------BAAB -------------BA---------BAAB -------------BA---------BAAB ------------BAA---------BAAB -----------BAAAB-------BAAAB BBBBBBBBBBBAAAAB------BAAAB- BAAAAAAAAAAAAAABBBBBBBAAAAB- BAAAAAAAAAAAAAAAAAAAAAAAAB-- BAAAAAAAAAAAAAAAAAAAAAAAAB-- BAAAAAAAAAAAAAABBBBBBBAAAAB- BBBBBBBBBBBAAAAB------BAAAB- -----------BAAAB-------BAAAB ------------BBA---------BAAB -------------BA---------BAAB -------------BA---------BAAB -------------BA---------BAAB -------------BA---------BAB- -------------BA--------BAAB- -------------BA-------BAAB-- -------------BABBBBBBBAABB-- -------------BAAAAAAAABB---- -------------BBBBBBBBB------ -------------B-------------- 
---------------------------- ---------------------------- ---------------------------- ---------------------------- ---------------------------- ---------------------------- ---------------------------- ---------------------------- ---------------------------- ---------------------------- ---------------------------- ---------------------------- ---------------------------- ---------------------------- ------------BB-------------- ------------BB-------------- ---------------------------- ---------------------------- ---------------------------- ---------------------------- ---------------------------- ---------------------------- ---------------------------- ---------------------------- ---------------------------- ---------------------------- ---------------------------- ---------------------------- ---------------------------- ---------------------------- 
