model
size = 15 25 10, scale = 0.05, origin = -y
material 
  colors = A:#E00 B:#111 C:#600 D:#400 E:#30C F:#90C G:#FF0
voxels
-----DD--DD---- -----BD--DB---- --------------- ------------A-- ------------B-- ---B--------A-- ---B--------B-- ---B--------A-- BBBBBBB-----B-- ---B--------A-- ---B--------B-- ---B------AAAAA ---B------A-A-A ---B------A-A-A ---B------A-A-A ---B------A---A ---B----------- ---B----------- --------------- --------------- --------------- --------------- --------------- --------------- --------------- 
-----DD--DD---- -----BD--DB---- --------------- --------------- --------------- --------------- --------------- --------------- --------------- --------------- ---BB------BB-- ---BB------BB-- --------------- --------------- --------------- --------------- --------------- --------------- --------------- --------------- --------------- --------------- --------------- --------------- --------------- 
-----DD--DD---- -----BD--DB---- --------------- --------------- --------------- --------------- --------------- --------------- --------------- --------------- ---BB------BB-- ---BB------BB-- --------------- --------------- --------------- ------A--A----- ------CCCC----- --------------- --------------- --------------- --------------- --------------- --------------- --------------- --------------- 
-----DD--DD---- -----BD--DB---- --------------- --------------- --------------- --------------- --------------- --------------- --------------- --------------- ---BB------BB-- ---BB------BB-- -----AAAAAA---- ------CCCC----- -----C----C---- -----BA--AB---- -----CCCCGC---- ------CCCC----- --------------- --------------- --------------- --------------- --------------- --------------- --------------- 
-----DD--DD---- -----BB--BB---- -----BB--BB---- -----BB--BB---- -----BBBBBB---- -----DBDDBD---- -----BBBBBB---- -----BDBBDB---- -----BBBBBB---- ---BBBDBBDBBB-- ---BBBBBBBBBB-- ---BBBDBBDBBB-- -----ACCCCA---- ------BBBB----- -----BBBBBB---- -----BBBBBC---- ---ACCCCCGGCA-- ---AACCCCGCAA-- --AAAACCCCAAAA- --AAAA----AAAA- -AAAA------AAAA -AAAA------AAAA --AA--------AA- --AA--------AA- ---AA------AA-- 
-----DD--DD---- -----BB--BB---- -----BB--BB---- -----BB--BB---- -----BBBBBB---- -----DBBBBD---- -----BCBBCB---- -----BCBBCB---- -----BCCCCB---- -----BCCCCB---- -----BCCCCB---- -----BCCCCB---- -----ACCCCA---- -----CFCCCC---- ----CFFCCCFC--- ----CFFCCCFC--- ---ACCCEEGGGA-- ---AACCEEGGAA-- --AAAACCCCAAAA- --AAAA----AAAA- -AAAA------AAAA -AAAA------AAAA --AA--------AA- --AA--------AA- ---AA------AA-- 
-----DD--DD---- -----BB--BB---- -----BB--BB---- -----BB--BB---- -----BBBBBB---- -----DDDDDD---- -----BBBBBB---- -----BBBBBB---- -----BBBBBB---- -----BCBBCB---- -----BBBBBB---- -----ACBBCA---- -----ACCCCA---- -----CFCCCC---- -----CFCCCC---- ----CFFCCCCC--- ---ACCCEEEECA-- ---AACCEEEECA-- --AAACCCCCCAAA- --AAAA----AAAA- -AAAA------AAAA -AAAA------AAAA --AA--------AA- --AA--------AA- ---AA------AA-- 
--------------- --------------- --------------- --------------- --------------- --------------- --------------- --------------- --------------- --------------- --------------- --------------- -----AAAAAA---- -----CFCCCC---- ----CCFCCCCC--- ----CCFCCCCC--- -----CEEEEC---- ---AACEEEECAA-- --AAA-CCCC-AA-- --AAA------AA-- --AAA------AAA- --AAA------AA-- ---A--------A-- --------------- --------------- 
--------------- --------------- --------------- --------------- --------------- --------------- --------------- --------------- --------------- --------------- --------------- --------------- --------------- ------CCCC----- ----C-CCCC-C--- ------CCCC----- ------CCEC----- ------CCCC----- ---AA------AA-- ---AA------AA-- ---AA------AA-- --------------- --------------- --------------- --------------- 
--------------- --------------- --------------- --------------- --------------- --------------- --------------- --------------- --------------- --------------- --------------- --------------- --------------- --------------- -------CC------ -------CC------ -------CC------ --------------- --------------- --------------- --------------- --------------- --------------- --------------- --------------- 
