model
size = 32 8 25, scale = 0.05, origin = -y
material 
  colors = A:#FFF B:#4D5139
voxels
14-4B28-4B25-3B4-3B18-5B8-5B10-5B16-5B3-4B24-4B78-4B28-B2AB25-3B4A3B18-4B3A4-3A4B10-4B5A8-5A4B3-3B5A16-5A3B-5A2(20-5A2-3A24-3A15-4B28-B2AB25-3B4A3B18-4B3A4-3A4B10-4B-4A8-4A-4B3-3B5A16-5A3B-A-3A)19(20-3A-A2-3A24-3A15-4B28-B2AB25-3B4A3B18-4B3A4-3A4B10-4B-4A8-4A-4B3-3B5A16-5A3B-A-3A)20-3A-A2-3A24-3A15-4B28-B2AB25-3B4A3B18-4B3A4-3A4B10-4B-4A8-4A-4B3-2B-5A16-5A3B-5A20-5A2-3A24-3A15-4B28-4B25-3B4-3B18-5B8-5B10-5B16-5B3-3B2AB20-6B64-
