model
size = 19 28 18, scale = 0.05, origin = -y
material 
  colors = A:#0052FF B:#FFF C:#0063FF D:#0078FF E:#008FFF F:#00B1FF G:#890CFF H:#B80CFF I:#00C3FF J:#EA00FF K:#00DFFF L:#00F5FF M:#750CFF N:#0039FF O:#0028FF P:#4100FF Q:#5E0CFF
voxels
----BBBBBAAA------- ---BB----AAAA------ --BB-----AAAAA----- -BB------AAAAAA---- -B-------AAAAAAA--- BB-------AAAAAAAA-- J--------AAAAAAAAA- H--------AAAAAAAA-- G--------AAAAAAAA-- M--------AAAAAAAA-- Q--------AAAAAAAA-- P--------AAAAAAAA-- O--------AAAAAAAA-- N--------AAAAAAAA-- A--------AAAAAAAA-- C--------AAAAAAAA-- D--------AAAAAAAA-- E--------AAAAAAAA-- F--------AAAAAAAA-- I--------AAAAAAAAA- K--------AAAAAAAA-- L--------AAAAAAA--- BB-------AAAAAA---- -B-------AAAAA----- -B-------AAAA------ --B------AAA------- ---BB--BBB--------- ----BBBB----------- 
----BBBBBAAAC------ ---BB----AAAA------ --BB-----AAAAA----- -BB------AAAAAA---- -B-------AAAAAAA--- BB-------AAAAAAAA-- J--------AAAAAAAAA- H--------AAAAAAAA-- G--------AAAAAAAA-- M--------AAAAAAAA-- Q--------AAAAAAAA-- P--------AAAAAAAA-- O--------AAAAAAAA-- N--------AAAAAAAA-- A--------AAAAAAAA-- C--------AAAAAAAA-- D--------AAAAAAAA-- E--------AAAAAAAA-- F--------AAAAAAAA-- I--------AAAAAAAAA- K--------AAAAAAAA-- L--------AAAAAAA--- BB-------AAAAAA---- -B-------AAAAA----- -B-------AAAA------ --BB-----AAAC------ ---BB--BBB--------- ----BBBB----------- 
---------AAAC------ ---------AAAAD----- ---------AAAAA----- ---------AAAAAA---- ---------AAAAAAA--- ---------AAAAAAAA-- ---------AAAAAAAAA- ---------AAAAAAAA-- ---------AAAAAAAA-- ---------AAAAAAAA-- ---------AAAAAAAA-- ---------AAAAAAAA-- ---------AAAAAAAA-- ---------AAAAAAAA-- ---------AAAAAAAA-- ---------AAAAAAAA-- ---------AAAAAAAA-- ---------AAAAAAAA-- ---------AAAAAAAA-- ---------AAAAAAAAA- ---------AAAAAAAA-- ---------AAAAAAA--- ---------AAAAAA---- ---------AAAAA----- ---------AAAAD----- ---------AAAC------ ------------------- ------------------- 
---------AAAC------ ---------AAAAD----- ---------AAAAAE---- ---------AAAAAA---- ---------AAAAAAA--- ---------AAAAAAAA-- ---------AAAAAAAAA- ---------AAAAAAAA-- ---------AAAAAAAA-- ---------AAAAAAAA-- ---------AAAAAAAA-- ---------AAAAAAAA-- ---------AAAAAAAA-- ---------AAAAAAAA-- ---------AAAAAAAA-- ---------AAAAAAAA-- ---------AAAAAAAA-- ---------AAAAAAAA-- ---------AAAAAAAA-- ---------AAAAAAAAA- ---------AAAAAAAA-- ---------AAAAAAA--- ---------AAAAAA---- ---------AAAAAE---- ---------AAAAD----- ---------AAAC------ ------------------- ------------------- 
---------AAAC------ ---------AAAAD----- ---------AAAAAE---- ---------AAAAAAF--- ---------AAAAAAA--- ---------AAAAAAAA-- ---------AAAAAAAAA- ---------AAAAAAAA-- ---------AAAAAAAA-- ---------AAAAAAAG-- ---------AAAAAAAM-- ---------AAAAAAAM-- ---------AAAAAAAA-- ---------AAAAAAAA-- ---------AAAAAAAH-- ---------AAAAAAAG-- ---------AAAAAAAA-- ---------AAAAAAAA-- ---------AAAAAAAA-- ---------AAAAAAAAA- ---------AAAAAAAA-- ---------AAAAAAA--- ---------AAAAAAF--- ---------AAAAAE---- ---------AAAAD----- ---------AAAC------ ------------------- ------------------- 
---------AAAC------ ---------AAAAD----- ---------AAAAAE---- ---------AAAAAAF--- ---------AAAAAAAI-- ---------AAAAAAAA-- ---------AAAAAAAAA- ---------AAAAAAAA-- ---------AAAAAAAA-- ---------AAAAAAAG-- ---------AAAAAAAA-- ---------AAAAAAAA-- ---------AAAAAAAA-- ---------AAAAAAAJ-- ---------AAAAAAAH-- ---------AAAAAAAG-- ---------AAAAAAAM-- ---------AAAAAAAM-- ---------AAAAAAAA-- ---------AAAAAAAAA- ---------AAAAAAAA-- ---------AAAAAAAI-- ---------AAAAAAF--- ---------AAAAAE---- ---------AAAAD----- ---------AAAC------ ------------------- ------------------- 
---------AAAC------ ---------AAAAD----- ---------AAAAAE---- ---------AAAAAAF--- ---------AAAAAAAI-- ---------AAAAAAAAK- ---------AAAAAAAAA- ---------AAAAAAAA-- ---------AAAAAAAA-- ---------AAAAAAAG-- ---------AAAAAAAH-- ---------AAAAAAAJ-- ---------AAAAAAAA-- ---------AAAAAAAJ-- ---------AAAAAAAH-- ---------AAAAAAAG-- ---------AAAAAAAA-- ---------AAAAAAAA-- ---------AAAAAAAA-- ---------AAAAAAAAA- ---------AAAAAAAAK- ---------AAAAAAAI-- ---------AAAAAAF--- ---------AAAAAE---- ---------AAAAD----- ---------AAAC------ ------------------- ------------------- 
---------AAAC------ ---------AAAAD----- ---------AAAAAE---- ---------AAAAAAF--- ---------AAAAAAAI-- ---------AAAAAAAAK- ---------AAAAAAAAAL ---------AAAAAAAA-- ---------AAAAAAAA-- ---------AAAAAAAG-- ---------AAAAAAAH-- ---------AAAAAAAJ-- ---------AAAAAAAA-- ---------AAAAAAAJ-- ---------AAAAAAAH-- ---------AAAAAAAG-- ---------AAAAAAAA-- ---------AAAAAAAA-- ---------AAAAAAAA-- ---------AAAAAAAAAL ---------AAAAAAAAK- ---------AAAAAAAI-- ---------AAAAAAF--- ---------AAAAAE---- ---------AAAAD----- ---------AAAC------ ------------------- ------------------- 
---------AAAC------ ---------AAAAD----- ---------AAAAAE---- ---------AAAAAAF--- ---------AAAAAAAI-- ---------AAAAAAAAK- ---------AAAAAAAAAL ---------AAAAAAAA-- ---------AAAAAAAA-- ---------AAAAAAAG-- ---------AAAAAAAH-- ---------AAAAAAAJ-- ---------AAAAAAAA-- ---------AAAAAAAJ-- ---------AAAAAAAH-- ---------AAAAAAAG-- ---------AAAAAAAA-- ---------AAAAAAAA-- ---------AAAAAAAA-- ---------AAAAAAAAAL ---------AAAAAAAAK- ---------AAAAAAAI-- ---------AAAAAAF--- ---------AAAAAE---- ---------AAAAD----- ---------AAAC------ ------------------- ------------------- 
---------AAAC------ ---------AAAAD----- ---------AAAAAE---- ---------AAAAAAF--- ---------AAAAAAAI-- ---------AAAAAAAAK- ---------AAAAAAAAAL ---------AAAAAAAA-- ---------AAAAAAAA-- ---------AAAAAAAG-- ---------AAAAAAAH-- ---------AAAAAAAJ-- ---------AAAAAAAA-- ---------AAAAAAAJ-- ---------AAAAAAAH-- ---------AAAAAAAG-- ---------AAAAAAAA-- ---------AAAAAAAA-- ---------AAAAAAAA-- ---------AAAAAAAAAL ---------AAAAAAAAK- ---------AAAAAAAI-- ---------AAAAAAF--- ---------AAAAAE---- ---------AAAAD----- ---------AAAC------ ------------------- ------------------- 
---------AAAC------ ---------AAAAD----- ---------AAAAAE---- ---------AAAAAAF--- ---------AAAAAAAI-- ---------AAAAAAAAK- ---------AAAAAAAAAL ---------AAAAAAAA-- ---------AAAAAAAA-- ---------AAAAAAAG-- ---------AAAAAAAH-- ---------AAAAAAAJ-- ---------AAAAAAAA-- ---------AAAAAAAJ-- ---------AAAAAAAH-- ---------AAAAAAAG-- ---------AAAAAAAA-- ---------AAAAAAAA-- ---------AAAAAAAA-- ---------AAAAAAAAAL ---------AAAAAAAAK- ---------AAAAAAAI-- ---------AAAAAAF--- ---------AAAAAE---- ---------AAAAD----- ---------AAAC------ ------------------- ------------------- 
---------AAAC------ ---------AAAAD----- ---------AAAAAE---- ---------AAAAAAF--- ---------AAAAAAAI-- ---------AAAAAAAAK- ---------AAAAAAAAA- ---------AAAAAAAA-- ---------AAAAAAAA-- ---------AAAAAAAG-- ---------AAAAAAAH-- ---------AAAAAAAJ-- ---------AAAAAAAA-- ---------AAAAAAAJ-- ---------AAAAAAAH-- ---------AAAAAAAG-- ---------AAAAAAAA-- ---------AAAAAAAA-- ---------AAAAAAAA-- ---------AAAAAAAAA- ---------AAAAAAAAK- ---------AAAAAAAI-- ---------AAAAAAF--- ---------AAAAAE---- ---------AAAAD----- ---------AAAC------ ------------------- ------------------- 
---------AAAC------ ---------AAAAD----- ---------AAAAAE---- ---------AAAAAAF--- ---------AAAAAAAI-- ---------AAAAAAAA-- ---------AAAAAAAAA- ---------AAAAAAAA-- ---------AAAAAAAA-- ---------AAAAAAAG-- ---------AAAAAAAA-- ---------AAAAAAAA-- ---------AAAAAAAA-- ---------AAAAAAAJ-- ---------AAAAAAAH-- ---------AAAAAAAG-- ---------AAAAAAAM-- ---------AAAAAAAM-- ---------AAAAAAAA-- ---------AAAAAAAAA- ---------AAAAAAAA-- ---------AAAAAAAI-- ---------AAAAAAF--- ---------AAAAAE---- ---------AAAAD----- ---------AAAC------ ------------------- ------------------- 
---------AAAC------ ---------AAAAD----- ---------AAAAAE---- ---------AAAAAAF--- ---------AAAAAAA--- ---------AAAAAAAA-- ---------AAAAAAAAA- ---------AAAAAAAA-- ---------AAAAAAAA-- ---------AAAAAAAG-- ---------AAAAAAAM-- ---------AAAAAAAM-- ---------AAAAAAAA-- ---------AAAAAAAA-- ---------AAAAAAAH-- ---------AAAAAAAG-- ---------AAAAAAAA-- ---------AAAAAAAA-- ---------AAAAAAAA-- ---------AAAAAAAAA- ---------AAAAAAAA-- ---------AAAAAAA--- ---------AAAAAAF--- ---------AAAAAE---- ---------AAAAD----- ---------AAAC------ ------------------- ------------------- 
---------AAAC------ ---------AAAAD----- ---------AAAAAE---- ---------AAAAAA---- ---------AAAAAAA--- ---------AAAAAAAA-- ---------AAAAAAAAA- ---------AAAAAAAA-- ---------AAAAAAAA-- ---------AAAAAAAA-- ---------AAAAAAAA-- ---------AAAAAAAA-- ---------AAAAAAAA-- ---------AAAAAAAA-- ---------AAAAAAAA-- ---------AAAAAAAA-- ---------AAAAAAAA-- ---------AAAAAAAA-- ---------AAAAAAAA-- ---------AAAAAAAAA- ---------AAAAAAAA-- ---------AAAAAAA--- ---------AAAAAA---- ---------AAAAAE---- ---------AAAAD----- ---------AAAC------ ------------------- ------------------- 
---------AAAC------ ---------AAAAD----- ---------AAAAA----- ---------AAAAAA---- ---------AAAAAAA--- ---------AAAAAAAA-- ---------AAAAAAAAA- ---------AAAAAAAA-- ---------AAAAAAAA-- ---------AAAAAAAA-- ---------AAAAAAAA-- ---------AAAAAAAA-- ---------AAAAAAAA-- ---------AAAAAAAA-- ---------AAAAAAAA-- ---------AAAAAAAA-- ---------AAAAAAAA-- ---------AAAAAAAA-- ---------AAAAAAAA-- ---------AAAAAAAAA- ---------AAAAAAAA-- ---------AAAAAAA--- ---------AAAAAA---- ---------AAAAA----- ---------AAAAD----- ---------AAAC------ ------------------- ------------------- 
----BBBBBAAAC------ ---BB----AAAA------ --BB-----AAAAA----- -BB------AAAAAA---- -B-------AAAAAAA--- BB-------AAAAAAAA-- J--------AAAAAAAAA- H--------AAAAAAAA-- G--------AAAAAAAA-- M--------AAAAAAAA-- Q--------AAAAAAAA-- P--------AAAAAAAA-- O--------AAAAAAAA-- N--------AAAAAAAA-- A--------AAAAAAAA-- C--------AAAAAAAA-- D--------AAAAAAAA-- E--------AAAAAAAA-- F--------AAAAAAAA-- I--------AAAAAAAAA- K--------AAAAAAAA-- L--------AAAAAAA--- BB-------AAAAAA---- -B-------AAAAA----- -B-------AAAA------ --BB-----AAAC------ ---BB--BBB--------- ----BBBB----------- 
----BBBBBAAA------- ---BB----AAAA------ --BB-----AAAAA----- -BB------AAAAAA---- -B-------AAAAAAA--- BB-------AAAAAAAA-- J--------AAAAAAAAA- H--------AAAAAAAA-- G--------AAAAAAAA-- M--------AAAAAAAA-- Q--------AAAAAAAA-- P--------AAAAAAAA-- O--------AAAAAAAA-- N--------AAAAAAAA-- A--------AAAAAAAA-- C--------AAAAAAAA-- D--------AAAAAAAA-- E--------AAAAAAAA-- F--------AAAAAAAA-- I--------AAAAAAAAA- K--------AAAAAAAA-- L--------AAAAAAA--- BB-------AAAAAA---- -B-------AAAAA----- -B-------AAAA------ --B------AAA------- ---BB--BBB--------- ----BBBB----------- 
