model
size = 15 31 15, scale = 0.05, origin = -y
material 
  colors = A:#CC543A B:#43341B C:#CB4042 D:#855B32
voxels
--------------- --------------- --------------- --------------- --------------- --------------- --------------- --------------- --------------- --------------- --------------- --------------- --------------- --------------- --------------- --------------- --------------- --------------- --------------- --------------- --------------- --------------- --------------- --------------- -----AAAA------ -----AAAAA----- -----AAAAA----- -----AAAAA----- -----AAAAA----- -----AAAAA----- -----CCCCC----- 
--------------- --------------- --------------- --------------- --------------- --------------- --------------- --------------- --------------- --------------- --------------- --------------- --------------- --------------- --------------- --------------- --------------- --------------- --------------- --------------- --------------- --------------- --------------- ----AAAAA------ ----AAAAAAAA--- ----AAAAAAAA--- ----AAAAAAAA--- ---AAAAAAAAA--- ---AAAAAAAAA--- ---AA---AAAA--- ---CCA---ACC--- 
--------------- --------------- --------------- --------------- --------------- --------------- --------------- --------------- --------------- --------------- --------------- --------------- --------------- --------------- --------------- --------------- --------------- --------------- --------------- --------------- --------------- --------------- -------AAA----- ---AAAAAAAA---- --AAAAAAAAAA--- --AAAAAAAAAAA-- --AAAAAAAAAAA-- --AAAAAAAAAAA-- --AAAAAAAAAAA-- --AA-----AAAA-- --CA-------AC-- 
--------------- --------------- --------------- --------------- --------------- --------------- --------------- --------------- --------------- --------------- --------------- --------------- --------------- --------------- --------------- --------------- --------------- --------------- --------------- --------------- --------------- --------------- ----AAAAAAAA--- ---AAAAAAAAA--- -AAAAAAAAAAAAA- -AAAAAAAAAAAAA- -AAAAAAAAAAAAA- -AAAAAAAAAAAAA- -AAAA------AAA- -AA--------AAA- -CA---------AC- 
--------------- --------------- --------------- --------------- --------------- --------------- --------------- --------------- --------------- --------------- --------------- --------------- --------------- --------------- --------------- --------------- --------------- --------------- --------------- --------------- --------------- --------------- ---AAAAAAAAA--- --AAAAAAAAAAA-- -AAAAAAAAAAAAA- -AAAAAAAAAAAAA- -AAAAAAAAAAAAA- -AAA-A-----AAA- -AAA--------AA- -AA---------AA- -C-----------C- 
--------------- --------------- --------------- --------------- --------------- --------------- --------------- --------------- --------------- --------------- --------------- --------------- --------------- --------------- --------------- --------------- --------------- --------------- --------------- --------------- --------------- --------------- ---AAAAAAAAA--- -AAAAAAAAAAAA-- -AAAAAAAAAAAAA- AAAAAAAAAAAAAA- AAAAA------AAAA AAAAA-------AAA AAA---------AAA AAA----------AA CA-----------AC 
------BBB------ ------BBB------ ------BBB------ ------BBB------ ------BBB------ ------BBB------ ------BBB------ ------BBB------ ------BBB------ ------BBB------ ------BBB------ ------BBB------ ------BBB------ ------BBB------ ------BBB------ ------BBB------ ------BBB------ ------BBB------ ------BBB------ ------BBB------ ------BBB------ ------BBB------ --AAAAAAAAAA--- -AAAAAAAAAAAA-- AAAAAAAAAAAAAA- AAAAAAAAAAAAAA- AAAA--------AAA AAA---------AAA AAA---------AAA AA-----------AA C-------------C 
------BBB------ ------BBB------ ------BBB------ ------BBB------ ------BBB------ ------BBB------ ------BBB------ ------BBB------ ------BBB------ ------BBB------ ------BBB------ ------BBB------ ------BBB------ ------BBB------ ------BBB------ ------BBB------ ------BBB------ ------BBB------ ------BBB------ ------BBB------ ------BBB------ ------BBB------ ---AAAABAAAA--- --AAAAA-AAAAA-- -AAAAAA-AAAAAA- AAAAAAAAAAAAAA- AAA---------AAA AAA---------AAA AAA----------AA AA-----------AA C-------------C 
------BBB------ ------BBB------ ------BBB------ ------BBB------ ------BBB------ ------BBB------ ------BBB------ ------BBB------ ------BBB------ ------BBB------ ------BBB------ ------BBB------ ------BBB------ ------BBB------ ------BBB------ ------BBB------ ------BBB------ ------BBB------ ------BBB------ ------BBB------ ------BBB------ ------BBB------ ---AAAADAAAA--- --AAAAAAAAAAA-- -AAAAAAAAAAAA-- AAAAAAAAAAAAAA- AAAA--------AA- AAA---------AAA AAA----------AA AA-----------AA C-------------C 
--------------- --------------- --------------- --------------- --------------- --------------- --------------- --------------- --------------- --------------- --------------- --------------- --------------- --------------- --------------- --------------- --------------- --------------- --------------- --------------- --------------- --------------- ---AAAAAAAAA--- --AAAAAAAAAAA-- -AAAAAAAAAAAA-- AAAAAAAAAAAAAA- AAAAA-------AA- AAA---------AA- AAAAA-------AAA AAA----------AA CA-----------AC 
--------------- --------------- --------------- --------------- --------------- --------------- --------------- --------------- --------------- --------------- --------------- --------------- --------------- --------------- --------------- --------------- --------------- --------------- --------------- --------------- --------------- --------------- ---AAAAAAAAA--- ---AAAAAAAAAA-- --AAAAAAAAAAA-- -AAAAAAAAAAAAA- -AAA-----AAAAA- -AA-------A-AA- -AAA--------AA- -AA---------AA- -C-----------C- 
--------------- --------------- --------------- --------------- --------------- --------------- --------------- --------------- --------------- --------------- --------------- --------------- --------------- --------------- --------------- --------------- --------------- --------------- --------------- --------------- --------------- --------------- ----AAAAAAA---- ---AAAAAAAAAA-- --AAAAAAAAAAA-- -AAAAAAAAAAAA-- -AAAA---AAAAAA- -AAA-----AAAAA- -AAA------A-AA- -AA---------AA- -CA---------AC- 
--------------- --------------- --------------- --------------- --------------- --------------- --------------- --------------- --------------- --------------- --------------- --------------- --------------- --------------- --------------- --------------- --------------- --------------- --------------- --------------- --------------- --------------- -----AAA------- ----AAAAAAAA--- ---AAAAAAAAAA-- --AAAAAAAAAAA-- --AAAAA-AAAAA-- --AAA---AAAAA-- --AA-----AAAA-- --AA------AAA-- --CA-------AC-- 
--------------- --------------- --------------- --------------- --------------- --------------- --------------- --------------- --------------- --------------- --------------- --------------- --------------- --------------- --------------- --------------- --------------- --------------- --------------- --------------- --------------- --------------- --------------- -----AAA------- ----AAAAAAA---- ---AAAAAAAAA--- ---AAAAAAAAA--- ---AAAAAAAAA--- ---AA---AAAA--- ---AAAAAAAAA--- ---CC-----CC--- 
--------------- --------------- --------------- --------------- --------------- --------------- --------------- --------------- --------------- --------------- --------------- --------------- --------------- --------------- --------------- --------------- --------------- --------------- --------------- --------------- --------------- --------------- --------------- --------------- --------------- ------AA------- -----AAAAA----- -----AAAAA----- -----AAAAA----- -----AAAAA----- -----CCCCC----- 
