model
size = 32 10 12, scale = 0.05, origin = -y
material 
  colors = A:#100 B:#630 C:#111 D:#492B00 E:#001 F:#222 G:#800 H:#B00 I:#A00 J:#E00 K:#45331E L:#D00
voxels
254-CA285-C31-CF223-AC29-CA30-F224-A29-2AC28-C2A31-CAC93-2A94-AC29-2A28-E4AF24-HGEB3A26-JEA-F29-2A-A29-A39-B24-A4-DB-B22-A-AC-2B12-3B9-C-CA-2B10-2(D3B)5-G2E4AD6B4-2B5-2DBK2BIG3B2A3-2B2-3BD2B8-D3BG4B2AC24-HIEB3A28-2C2A31-2C157-AC26-GE4AC25-LE2BAC28-4AC30-A191-2A29-2A28-ACF2A30-A256-F28-A-A317-A320-AC320-C128-
