model
size = 22 27 22, scale = 0.05, origin = -y
material 
  colors = A:#777 B:#555 C:#444
voxels
---------------------- ---------------------- ---------------------- ---------------------- ---------------------- ---------------------- ---------------------- ---------------------- ---------------------- ---------------------- ---------------------- ---------------------- ---------------------- ---------------------- ---------------------- ---------------------- ---------------------- ---------------------- ---------------------- ---------------------- ---------------------- ---------------------- -------CCCCCCCC------- -------CCCCCCCC------- ---------------------- ---------------------- ---------------------- 
-------ABBAABBA------- -------ABBAABBA------- -------ABBAABBA------- -------ABBAABBA------- -------ABBAABBA------- -------ABBAABBA------- -------ABBAABBA------- -------ABBAABBA------- -------ABBAABBA------- -------ABBAABBA------- -------ABBAABBA------- -------ABBAABBA------- -------ABBAABBA------- -------ABBAABBA------- -------ABBAABBA------- -------ABBAABBA------- -------ABBAABBA------- -------ABBAABBA------- -------ABBAABBA------- -------ABBAABBA------- -------ABBAABBA------- -------ABBAABBA------- -----CCAAAAAAAACC----- -----CCAAAAAAAACC----- -------CCCCCCCC------- ---------------------- ---------------------- 
-----BBAAAAAAAABB----- -----BBAAAAAAAABB----- -----BBAAAAAAAABB----- -----BBAAAAAAAABB----- -----BBAAAAAAAABB----- -----BBAAAAAAAABB----- -----BBAAAAAAAABB----- -----BBAAAAAAAABB----- -----BBAAAAAAAABB----- -----BBAAAAAAAABB----- -----BBAAAAAAAABB----- -----BBAAAAAAAABB----- -----BBAAAAAAAABB----- -----BBAAAAAAAABB----- -----BBAAAAAAAABB----- -----BBAAAAAAAABB----- -----BBAAAAAAAABB----- -----BBAAAAAAAABB----- -----BBAAAAAAAABB----- -----BBAAAAAAAABB----- -----BBAAAAAAAABB----- -----BBAAAAAAAABB----- ----CAAAAAAAAAAAAC---- ----CAAAAAAAAAAAAC---- -----CCAAAAAAAACC----- -------BBBBBBBB------- ---------------------- 
----AAAAAAAAAAAAAA---- ----AAAAAAAAAAAAAA---- ----AAAAAAAAAAAAAA---- ----AAAAAAAAAAAAAA---- ----AAAAAAAAAAAAAA---- ----AAAAAAAAAAAAAA---- ----AAAAAAAAAAAAAA---- ----AAAAAAAAAAAAAA---- ----AAAAAAAAAAAAAA---- ----AAAAAAAAAAAAAA---- ----AAAAAAAAAAAAAA---- ----AAAAAAAAAAAAAA---- ----AAAAAAAAAAAAAA---- ----AAAAAAAAAAAAAA---- ----AAAAAAAAAAAAAA---- ----AAAAAAAAAAAAAA---- ----AAAAAAAAAAAAAA---- ----AAAAAAAAAAAAAA---- ----AAAAAAAAAAAAAA---- ----AAAAAAAAAAAAAA---- ----AAAAAAAAAAAAAA---- ----AAAAAAAAAAAAAA---- ---CAAAAAAAAAAAAAAC--- ---CAAAAAAAAAAAAAAC--- ----CAAAAAAAAAAAAC---- -----BBBBBBBBBBBB----- ---------------------- 
---BAAAAAAAAAAAAAAB--- ---BAAAAAAAAAAAAAAB--- ---BAAAAAAAAAAAAAAB--- ---BAAAAAAAAAAAAAAB--- ---BAAAAAAAAAAAAAAB--- ---BAAAAAAAAAAAAAAB--- ---BAAAAAAAAAAAAAAB--- ---BAAAAAAAAAAAAAAB--- ---BAAAAAAAAAAAAAAB--- ---BAAAAAAAAAAAAAAB--- ---BAAAAAAAAAAAAAAB--- ---BAAAAAAAAAAAAAAB--- ---BAAAAAAAAAAAAAAB--- ---BAAAAAAAAAAAAAAB--- ---BAAAAAAAAAAAAAAB--- ---BAAAAAAAAAAAAAAB--- ---BAAAAAAAAAAAAAAB--- ---BAAAAAAAAAAAAAAB--- ---BAAAAAAAAAAAAAAB--- ---BAAAAAAAAAAAAAAB--- ---BAAAAAAAAAAAAAAB--- ---BAAAAAAAAAAAAAAB--- --CAAAAAAAAAAAAAAAAC-- --CAAAAAAAAAAAAAAAAC-- ---CAAAAAAAAAAAAAAC--- ----BBBBBBBBBBBBBB---- ---------------------- 
--BAAAAAAAAAAAAAAAAB-- --BAAAAAAAAAAAAAAAAB-- --BAAAAAAAAAAAAAAAAB-- --BAAAAAAAAAAAAAAAAB-- --BAAAAAAAAAAAAAAAAB-- --BAAAAAAAAAAAAAAAAB-- --BAAAAAAAAAAAAAAAAB-- --BAAAAAAAAAAAAAAAAB-- --BAAAAAAAAAAAAAAAAB-- --BAAAAAAAAAAAAAAAAB-- --BAAAAAAAAAAAAAAAAB-- --BAAAAAAAAAAAAAAAAB-- --BAAAAAAAAAAAAAAAAB-- --BAAAAAAAAAAAAAAAAB-- --BAAAAAAAAAAAAAAAAB-- --BAAAAAAAAAAAAAAAAB-- --BAAAAAAAAAAAAAAAAB-- --BAAAAAAAAAAAAAAAAB-- --BAAAAAAAAAAAAAAAAB-- --BAAAAAAAAAAAAAAAAB-- --BAAAAAAAAAAAAAAAAB-- --BAAAAAAAAAAAAAAAAB-- -CAAAAAAAAAAAAAAAAAAC- -CAAAAAAAAAAAAAAAAAAC- --CAAAAAAAAAAAAAAAAC-- ---BBBBBBBBBBBBBBBB--- ---------------------- 
--BAAAAAAAAAAAAAAAAB-- --BAAAAAAAAAAAAAAAAB-- --BAAAAAAAAAAAAAAAAB-- --BAAAAAAAAAAAAAAAAB-- --BAAAAAAAAAAAAAAAAB-- --BAAAAAAAAAAAAAAAAB-- --BAAAAAAAAAAAAAAAAB-- --BAAAAAAAAAAAAAAAAB-- --BAAAAAAAAAAAAAAAAB-- --BAAAAAAAAAAAAAAAAB-- --BAAAAAAAAAAAAAAAAB-- --BAAAAAAAAAAAAAAAAB-- --BAAAAAAAAAAAAAAAAB-- --BAAAAAAAAAAAAAAAAB-- --BAAAAAAAAAAAAAAAAB-- --BAAAAAAAAAAAAAAAAB-- --BAAAAAAAAAAAAAAAAB-- --BAAAAAAAAAAAAAAAAB-- --BAAAAAAAAAAAAAAAAB-- --BAAAAAAAAAAAAAAAAB-- --BAAAAAAAAAAAAAAAAB-- --BAAAAAAAAAAAAAAAAB-- -CAAAAAAAAAAAAAAAAAAC- -CAAAAAAAAAAAAAAAAAAC- --CAAAAAAAAAAAAAAAAC-- ---BBBBBBBBBBBBBBBB--- ---------------------- 
-AAAAAAAAAAAAAAAAAAAA- -AAAAAAAAAAAAAAAAAAAA- -AAAAAAAAAAAAAAAAAAAA- -AAAAAAAAAAAAAAAAAAAA- -AAAAAAAAAAAAAAAAAAAA- -AAAAAAAAAAAAAAAAAAAA- -AAAAAAAAAAAAAAAAAAAA- -AAAAAAAAAAAAAAAAAAAA- -AAAAAAAAAAAAAAAAAAAA- -AAAAAAAAAAAAAAAAAAAA- -AAAAAAAAAAAAAAAAAAAA- -AAAAAAAAAAAAAAAAAAAA- -AAAAAAAAAAAAAAAAAAAA- -AAAAAAAAAAAAAAAAAAAA- -AAAAAAAAAAAAAAAAAAAA- -AAAAAAAAAAAAAAAAAAAA- -AAAAAAAAAAAAAAAAAAAA- -AAAAAAAAAAAAAAAAAAAA- -AAAAAAAAAAAAAAAAAAAA- -AAAAAAAAAAAAAAAAAAAA- -AAAAAAAAAAAAAAAAAAAA- -AAAAAAAAAAAAAAAAAAAA- CAAAAAAAAAAAAAAAAAAAAC CAAAAAAAAAAAAAAAAAAAAC -CAAAAAAAAAAAAAAAAAAC- --BBBBBBBBBBBBBBBBBB-- ---------------------- 
-BAAAAAAAAAAAAAAAAAAB- -BAAAAAAAAAAAAAAAAAAB- -BAAAAAAAAAAAAAAAAAAB- -BAAAAAAAAAAAAAAAAAAB- -BAAAAAAAAAAAAAAAAAAB- -BAAAAAAAAAAAAAAAAAAB- -BAAAAAAAAAAAAAAAAAAB- -BAAAAAAAAAAAAAAAAAAB- -BAAAAAAAAAAAAAAAAAAB- -BAAAAAAAAAAAAAAAAAAB- -BAAAAAAAAAAAAAAAAAAB- -BAAAAAAAAAAAAAAAAAAB- -BAAAAAAAAAAAAAAAAAAB- -BAAAAAAAAAAAAAAAAAAB- -BAAAAAAAAAAAAAAAAAAB- -BAAAAAAAAAAAAAAAAAAB- -BAAAAAAAAAAAAAAAAAAB- -BAAAAAAAAAAAAAAAAAAB- -BAAAAAAAAAAAAAAAAAAB- -BAAAAAAAAAAAAAAAAAAB- -BAAAAAAAAAAAAAAAAAAB- -BAAAAAAAAAAAAAAAAAAB- CAAAAAAAAAAAAAAAAAAAAC CAAAAAAAAAAAAAAAAAAAAC -CAAAAAAAAAAAAAAAAAAC- --BBBBBBBBBBBBBBBBBB-- ---------------------- 
-BAAAAAAAAAAAAAAAAAAB- -BAAAAAAAAAAAAAAAAAAB- -BAAAAAAAAAAAAAAAAAAB- -BAAAAAAAAAAAAAAAAAAB- -BAAAAAAAAAAAAAAAAAAB- -BAAAAAAAAAAAAAAAAAAB- -BAAAAAAAAAAAAAAAAAAB- -BAAAAAAAAAAAAAAAAAAB- -BAAAAAAAAAAAAAAAAAAB- -BAAAAAAAAAAAAAAAAAAB- -BAAAAAAAAAAAAAAAAAAB- -BAAAAAAAAAAAAAAAAAAB- -BAAAAAAAAAAAAAAAAAAB- -BAAAAAAAAAAAAAAAAAAB- -BAAAAAAAAAAAAAAAAAAB- -BAAAAAAAAAAAAAAAAAAB- -BAAAAAAAAAAAAAAAAAAB- -BAAAAAAAAAAAAAAAAAAB- -BAAAAAAAAAAAAAAAAAAB- -BAAAAAAAAAAAAAAAAAAB- -BAAAAAAAAAAAAAAAAAAB- -BAAAAAAAAAAAAAAAAAAB- CAAAAAAAAAAAAAAAAAAAAC CAAAAAAAAAAAAAAAAAAAAC -CAAAAAAAAAAAAAAAAAAC- --BBBBBBBAAAABBBBBBB-- ---------CCCC--------- 
-AAAAAAAAAAAAAAAAAAAA- -AAAAAAAAAAAAAAAAAAAA- -AAAAAAAAAAAAAAAAAAAA- -AAAAAAAAAAAAAAAAAAAA- -AAAAAAAAAAAAAAAAAAAA- -AAAAAAAAAAAAAAAAAAAA- -AAAAAAAAAAAAAAAAAAAA- -AAAAAAAAAAAAAAAAAAAA- -AAAAAAAAAAAAAAAAAAAA- -AAAAAAAAAAAAAAAAAAAA- -AAAAAAAAAAAAAAAAAAAA- -AAAAAAAAAAAAAAAAAAAA- -AAAAAAAAAAAAAAAAAAAA- -AAAAAAAAAAAAAAAAAAAA- -AAAAAAAAAAAAAAAAAAAA- -AAAAAAAAAAAAAAAAAAAA- -AAAAAAAAAAAAAAAAAAAA- -AAAAAAAAAAAAAAAAAAAA- -AAAAAAAAAAAAAAAAAAAA- -AAAAAAAAAAAAAAAAAAAA- -AAAAAAAAAAAAAAAAAAAA- -AAAAAAAAAAAAAAAAAAAA- CAAAAAAAAAAAAAAAAAAAAC CAAAAAAAAAAAAAAAAAAAAC -CAAAAAAAAAAAAAAAAAAC- --BBBBBBBAAAABBBBBBB-- ---------CCCC--------- 
-AAAAAAAAAAAAAAAAAAAA- -AAAAAAAAAAAAAAAAAAAA- -AAAAAAAAAAAAAAAAAAAA- -AAAAAAAAAAAAAAAAAAAA- -AAAAAAAAAAAAAAAAAAAA- -AAAAAAAAAAAAAAAAAAAA- -AAAAAAAAAAAAAAAAAAAA- -AAAAAAAAAAAAAAAAAAAA- -AAAAAAAAAAAAAAAAAAAA- -AAAAAAAAAAAAAAAAAAAA- -AAAAAAAAAAAAAAAAAAAA- -AAAAAAAAAAAAAAAAAAAA- -AAAAAAAAAAAAAAAAAAAA- -AAAAAAAAAAAAAAAAAAAA- -AAAAAAAAAAAAAAAAAAAA- -AAAAAAAAAAAAAAAAAAAA- -AAAAAAAAAAAAAAAAAAAA- -AAAAAAAAAAAAAAAAAAAA- -AAAAAAAAAAAAAAAAAAAA- -AAAAAAAAAAAAAAAAAAAA- -AAAAAAAAAAAAAAAAAAAA- -AAAAAAAAAAAAAAAAAAAA- CAAAAAAAAAAAAAAAAAAAAC CAAAAAAAAAAAAAAAAAAAAC -CAAAAAAAAAAAAAAAAAAC- --BBBBBBBAAAABBBBBBB-- ---------CCCC--------- 
-BAAAAAAAAAAAAAAAAAAB- -BAAAAAAAAAAAAAAAAAAB- -BAAAAAAAAAAAAAAAAAAB- -BAAAAAAAAAAAAAAAAAAB- -BAAAAAAAAAAAAAAAAAAB- -BAAAAAAAAAAAAAAAAAAB- -BAAAAAAAAAAAAAAAAAAB- -BAAAAAAAAAAAAAAAAAAB- -BAAAAAAAAAAAAAAAAAAB- -BAAAAAAAAAAAAAAAAAAB- -BAAAAAAAAAAAAAAAAAAB- -BAAAAAAAAAAAAAAAAAAB- -BAAAAAAAAAAAAAAAAAAB- -BAAAAAAAAAAAAAAAAAAB- -BAAAAAAAAAAAAAAAAAAB- -BAAAAAAAAAAAAAAAAAAB- -BAAAAAAAAAAAAAAAAAAB- -BAAAAAAAAAAAAAAAAAAB- -BAAAAAAAAAAAAAAAAAAB- -BAAAAAAAAAAAAAAAAAAB- -BAAAAAAAAAAAAAAAAAAB- -BAAAAAAAAAAAAAAAAAAB- CAAAAAAAAAAAAAAAAAAAAC CAAAAAAAAAAAAAAAAAAAAC -CAAAAAAAAAAAAAAAAAAC- --BBBBBBBAAAABBBBBBB-- ---------CCCC--------- 
-BAAAAAAAAAAAAAAAAAAB- -BAAAAAAAAAAAAAAAAAAB- -BAAAAAAAAAAAAAAAAAAB- -BAAAAAAAAAAAAAAAAAAB- -BAAAAAAAAAAAAAAAAAAB- -BAAAAAAAAAAAAAAAAAAB- -BAAAAAAAAAAAAAAAAAAB- -BAAAAAAAAAAAAAAAAAAB- -BAAAAAAAAAAAAAAAAAAB- -BAAAAAAAAAAAAAAAAAAB- -BAAAAAAAAAAAAAAAAAAB- -BAAAAAAAAAAAAAAAAAAB- -BAAAAAAAAAAAAAAAAAAB- -BAAAAAAAAAAAAAAAAAAB- -BAAAAAAAAAAAAAAAAAAB- -BAAAAAAAAAAAAAAAAAAB- -BAAAAAAAAAAAAAAAAAAB- -BAAAAAAAAAAAAAAAAAAB- -BAAAAAAAAAAAAAAAAAAB- -BAAAAAAAAAAAAAAAAAAB- -BAAAAAAAAAAAAAAAAAAB- -BAAAAAAAAAAAAAAAAAAB- CAAAAAAAAAAAAAAAAAAAAC CAAAAAAAAAAAAAAAAAAAAC -CAAAAAAAAAAAAAAAAAAC- --BBBBBBBBBBBBBBBBBB-- ---------------------- 
-AAAAAAAAAAAAAAAAAAAA- -AAAAAAAAAAAAAAAAAAAA- -AAAAAAAAAAAAAAAAAAAA- -AAAAAAAAAAAAAAAAAAAA- -AAAAAAAAAAAAAAAAAAAA- -AAAAAAAAAAAAAAAAAAAA- -AAAAAAAAAAAAAAAAAAAA- -AAAAAAAAAAAAAAAAAAAA- -AAAAAAAAAAAAAAAAAAAA- -AAAAAAAAAAAAAAAAAAAA- -AAAAAAAAAAAAAAAAAAAA- -AAAAAAAAAAAAAAAAAAAA- -AAAAAAAAAAAAAAAAAAAA- -AAAAAAAAAAAAAAAAAAAA- -AAAAAAAAAAAAAAAAAAAA- -AAAAAAAAAAAAAAAAAAAA- -AAAAAAAAAAAAAAAAAAAA- -AAAAAAAAAAAAAAAAAAAA- -AAAAAAAAAAAAAAAAAAAA- -AAAAAAAAAAAAAAAAAAAA- -AAAAAAAAAAAAAAAAAAAA- -AAAAAAAAAAAAAAAAAAAA- CAAAAAAAAAAAAAAAAAAAAC CAAAAAAAAAAAAAAAAAAAAC -CAAAAAAAAAAAAAAAAAAC- --BBBBBBBBBBBBBBBBBB-- ---------------------- 
--BAAAAAAAAAAAAAAAAB-- --BAAAAAAAAAAAAAAAAB-- --BAAAAAAAAAAAAAAAAB-- --BAAAAAAAAAAAAAAAAB-- --BAAAAAAAAAAAAAAAAB-- --BAAAAAAAAAAAAAAAAB-- --BAAAAAAAAAAAAAAAAB-- --BAAAAAAAAAAAAAAAAB-- --BAAAAAAAAAAAAAAAAB-- --BAAAAAAAAAAAAAAAAB-- --BAAAAAAAAAAAAAAAAB-- --BAAAAAAAAAAAAAAAAB-- --BAAAAAAAAAAAAAAAAB-- --BAAAAAAAAAAAAAAAAB-- --BAAAAAAAAAAAAAAAAB-- --BAAAAAAAAAAAAAAAAB-- --BAAAAAAAAAAAAAAAAB-- --BAAAAAAAAAAAAAAAAB-- --BAAAAAAAAAAAAAAAAB-- --BAAAAAAAAAAAAAAAAB-- --BAAAAAAAAAAAAAAAAB-- --BAAAAAAAAAAAAAAAAB-- -CAAAAAAAAAAAAAAAAAAC- -CAAAAAAAAAAAAAAAAAAC- --CAAAAAAAAAAAAAAAAC-- ---BBBBBBBBBBBBBBBB--- ---------------------- 
--BAAAAAAAAAAAAAAAAB-- --BAAAAAAAAAAAAAAAAB-- --BAAAAAAAAAAAAAAAAB-- --BAAAAAAAAAAAAAAAAB-- --BAAAAAAAAAAAAAAAAB-- --BAAAAAAAAAAAAAAAAB-- --BAAAAAAAAAAAAAAAAB-- --BAAAAAAAAAAAAAAAAB-- --BAAAAAAAAAAAAAAAAB-- --BAAAAAAAAAAAAAAAAB-- --BAAAAAAAAAAAAAAAAB-- --BAAAAAAAAAAAAAAAAB-- --BAAAAAAAAAAAAAAAAB-- --BAAAAAAAAAAAAAAAAB-- --BAAAAAAAAAAAAAAAAB-- --BAAAAAAAAAAAAAAAAB-- --BAAAAAAAAAAAAAAAAB-- --BAAAAAAAAAAAAAAAAB-- --BAAAAAAAAAAAAAAAAB-- --BAAAAAAAAAAAAAAAAB-- --BAAAAAAAAAAAAAAAAB-- --BAAAAAAAAAAAAAAAAB-- -CAAAAAAAAAAAAAAAAAAC- -CAAAAAAAAAAAAAAAAAAC- --CAAAAAAAAAAAAAAAAC-- ---BBBBBBBBBBBBBBBB--- ---------------------- 
---BAAAAAAAAAAAAAAB--- ---BAAAAAAAAAAAAAAB--- ---BAAAAAAAAAAAAAAB--- ---BAAAAAAAAAAAAAAB--- ---BAAAAAAAAAAAAAAB--- ---BAAAAAAAAAAAAAAB--- ---BAAAAAAAAAAAAAAB--- ---BAAAAAAAAAAAAAAB--- ---BAAAAAAAAAAAAAAB--- ---BAAAAAAAAAAAAAAB--- ---BAAAAAAAAAAAAAAB--- ---BAAAAAAAAAAAAAAB--- ---BAAAAAAAAAAAAAAB--- ---BAAAAAAAAAAAAAAB--- ---BAAAAAAAAAAAAAAB--- ---BAAAAAAAAAAAAAAB--- ---BAAAAAAAAAAAAAAB--- ---BAAAAAAAAAAAAAAB--- ---BAAAAAAAAAAAAAAB--- ---BAAAAAAAAAAAAAAB--- ---BAAAAAAAAAAAAAAB--- ---BAAAAAAAAAAAAAAB--- --CAAAAAAAAAAAAAAAAC-- --CAAAAAAAAAAAAAAAAC-- ---CAAAAAAAAAAAAAAC--- ----BBBBBBBBBBBBBB---- ---------------------- 
----AAAAAAAAAAAAAA---- ----AAAAAAAAAAAAAA---- ----AAAAAAAAAAAAAA---- ----AAAAAAAAAAAAAA---- ----AAAAAAAAAAAAAA---- ----AAAAAAAAAAAAAA---- ----AAAAAAAAAAAAAA---- ----AAAAAAAAAAAAAA---- ----AAAAAAAAAAAAAA---- ----AAAAAAAAAAAAAA---- ----AAAAAAAAAAAAAA---- ----AAAAAAAAAAAAAA---- ----AAAAAAAAAAAAAA---- ----AAAAAAAAAAAAAA---- ----AAAAAAAAAAAAAA---- ----AAAAAAAAAAAAAA---- ----AAAAAAAAAAAAAA---- ----AAAAAAAAAAAAAA---- ----AAAAAAAAAAAAAA---- ----AAAAAAAAAAAAAA---- ----AAAAAAAAAAAAAA---- ----AAAAAAAAAAAAAA---- ---CAAAAAAAAAAAAAAC--- ---CAAAAAAAAAAAAAAC--- ----CAAAAAAAAAAAAC---- -----BBBBBBBBBBBB----- ---------------------- 
-----BBAAAAAAAABB----- -----BBAAAAAAAABB----- -----BBAAAAAAAABB----- -----BBAAAAAAAABB----- -----BBAAAAAAAABB----- -----BBAAAAAAAABB----- -----BBAAAAAAAABB----- -----BBAAAAAAAABB----- -----BBAAAAAAAABB----- -----BBAAAAAAAABB----- -----BBAAAAAAAABB----- -----BBAAAAAAAABB----- -----BBAAAAAAAABB----- -----BBAAAAAAAABB----- -----BBAAAAAAAABB----- -----BBAAAAAAAABB----- -----BBAAAAAAAABB----- -----BBAAAAAAAABB----- -----BBAAAAAAAABB----- -----BBAAAAAAAABB----- -----BBAAAAAAAABB----- -----BBAAAAAAAABB----- ----CAAAAAAAAAAAAC---- ----CAAAAAAAAAAAAC---- -----CCAAAAAAAACC----- -------BBBBBBBB------- ---------------------- 
-------ABBAABBA------- -------ABBAABBA------- -------ABBAABBA------- -------ABBAABBA------- -------ABBAABBA------- -------ABBAABBA------- -------ABBAABBA------- -------ABBAABBA------- -------ABBAABBA------- -------ABBAABBA------- -------ABBAABBA------- -------ABBAABBA------- -------ABBAABBA------- -------ABBAABBA------- -------ABBAABBA------- -------ABBAABBA------- -------ABBAABBA------- -------ABBAABBA------- -------ABBAABBA------- -------ABBAABBA------- -------ABBAABBA------- -------ABBAABBA------- -----CCAAAAAAAACC----- -----CCAAAAAAAACC----- -------CCCCCCCC------- ---------------------- ---------------------- 
---------------------- ---------------------- ---------------------- ---------------------- ---------------------- ---------------------- ---------------------- ---------------------- ---------------------- ---------------------- ---------------------- ---------------------- ---------------------- ---------------------- ---------------------- ---------------------- ---------------------- ---------------------- ---------------------- ---------------------- ---------------------- ---------------------- -------CCCCCCCC------- -------CCCCCCCC------- ---------------------- ---------------------- ---------------------- 
