model
size = 26 31 4, scale = 0.05, origin = -y
material 
  colors = A:#E00 B:#CF3 C:#FF0
voxels
-------------------------- -------------------------- -------------------------- -------------------------- -------------------------- -------------------------- -------------------------- -------------------------- -------------------------- -------------------------- -------------------------- -------------------------- -------------------------- -------------------------- -------------------------- -------------------------- -------------------------- -------------------------- -------------------------- -------------------------- -------------------------- -------------------------- -------------------------- -------------------------- -------------------------- ------B------------------- -------------------------- -------------B------------ -------------------------- -------------------------- -------------------------- 
-------------------------- -------------------------- -------------------------- -------------------------- -------------------------- -------------------------- -------------------------- -------------------------- -------------------------- -------------------------- -------------------------- -------------------------- -------------------------- -------------------------- -------------------------- -------------------------- -------------------------- -------------------------- -------------------------- -------------------------- -------------------------- -------------------------- -------------------------- -------------------------- ------------------B-BB---- -----BBBBBB-BBBBB---B----- ------BBBB-BBB------B----- -------BBB--BB------------ -------------B------------ -------------------------- -------------------------- 
-------------------------- -------------------------- -------------------------- -------------------------- -------------------------- -------------------------- -------------------------- -------------------------- -------------------------- -------------------------- -------------------------- -------------------------- -------------------------- -------------------------- -------------------------- -------------------------- ------B------------------- ------B------------------- ------BB------------------ -------B------------------ -------BB----------------- --------BB---------------- ------B--BB--------------- ----B-B---B--BB-------BB-- --B-BBBBB-BBBBB-BBBBBB--B- --BB-BBBBBBBBBBBB-BBB----- ------BB--BBBB-BBBBBB----- ------BBBBBBB------------- ---------BBBB-----BB------ --------BB---BBBBB-------- -------------------------- 
------------AAAAAAAA------ -----------AAAAAAAAAA----- -----------AAAAAAAAAA----- ----------AAAAAAAAAAAA---- ---------AAAAAAAAAAAAAA--- --------AAAAAAAACCCCAAAA-- --------AAAACCCCCAACCAAA-- -------AAAACCAAAAAAAAAAAA- ------AAAAAAAAAACCCCCAAAAA ------AAAAACCCCCCAAAAAAAAA ------AAAAAAAAAAAAAAAAAAAA ------AAAAAAAAAAAAAAAAAAAA ------AAAAAAAAAAAAAAAAAAAA --B---AAAAAAAAAAAAAAAAAAAA --B-B-AAAAAAAAAAAAAAAAAAAA --BBBBAAAAAAAAAAAAAAAAAAAA ---B-BAAAAAAAAAAAAAAAAAAAA ---B--AAACCCCCAAAACCCCCAAA ----B-AAAACAACAAAACAACAAAA -B--BBAAACCCCCAAAACCCCCAAA -B---BAAAAAAAAAAAAAAAAAAAA -B---BAAAAAAAAAAAAAAAAAAAA -BB-B-AAAAAAAAAAAAAAAAAAAA B-BBB-AAAAAAAAAAAAAAAAAAAA BBB-BBAAAAAAAAAAAAAAAAAAAA --BBBBBBBBBBBBBBBBBBBB--B- ---BBBBBBBBBBBBBBBBBBBBB-- -------BBBB--BBB---BB----- -------B-BBBB-----BBB----- --------BBBBBBBBBBB------- ------------BB------------ 
