model
size = 20 25 6, scale = 0.05, origin = -y
material 
  colors = A:#EEE B:#111 C:#CF3 D:#0E0 E:#C33 F:#E00
voxels
-------------------- -------------------- -------------------- -------------------- -------------------- -------------------- -------------------- ---------EE--------- -------------------- -------------------- -------------------- -------------------- -------------------- -------------------- -------------------- -------------------- -------------------- -------------------- -------------------- -------------------- -------------------- -------------------- -------------------- -------------------- -------------------- 
-------------------- -------------------- -------------------- -------------------- -------------------- -------------------- -------------------- ---------EE--------- -------------------- -------------------- -------------------- -------------------- -------------------- -------------------- -------------------- -------------------- -------------------- -------------------- -------------------- -------------------- -------------------- -------------------- -------------------- -------------------- -------------------- 
-------------------- -------------------- -------------------- -------------------- -------------------- -------------------- -------------------- ---------EE--------- --------A--A-------- -------------------- -------------------- -------------------- -------------------- -------------------- -------------------- -------------------- -------------------- -------------------- -------------------- -------------------- -------------------- -------------------- -------------------- -------------------- -------------------- 
-------------------- -------------------- -------------------- -------------------- -------------------- -------------------- -------------------- ---------EE--------- --------A--A-------- -------------------- -------------------- -------------------- -------------------- -------------------- -------------------- -------------------- -------------------- -------------------- -------------------- -------------------- -------------------- -------------------- -------------------- -------------------- -------------------- 
-------------------- -------------------- -------------------- -------------------- -------------------- -------------------- --------DDDD-------- --------DDDD-------- --------DDDD-------- -------------------- -------------------- -------------------- -------------------- -------------------- -------------------- -------------------- -------------------- -------------------- -------------------- -------------------- -------------------- -------------------- -------------------- -------------------- -------------------- 
------AAAAAAAA------ -----AAAAAAAAAA----- -----AAAAAAAAAA----- ----AAAAAAAAAAAA---- ---AAAAAAAAAAAAAA--- --AAAAAABBBBAAAAAA-- --AAAAABBBBBBAAAAA-- -AAAAAABBBBBBAAAAAA- AAAAAAABBBBBBAAAAAAA AAAAAAAABBBBAAAAAAAA AAAAAAAAAAAAAAAAAAAA AAAAAAAAAAAAAAAAAAAA AAAAAAAAAAAAAAAAAAAA AAAAAAAAAAAAAAAAAAAA AAAAAAAAAAAAAAAAAAAA AAAAAAAAAAAAAAAAAAAA AABBBBBBBAABBBBBBBAA AABBBBCCBAABCCBBBBAA AABCFFCBBAABBCFFCBAA AABCCFCBBAABBCFCCBAA AABCCCCBBAABBCCCCBAA AABBBBBBBAABBBBBBBAA AAAAAAAAAAAAAAAAAAAA AAAAAAAAAAAAAAAAAAAA AAAAAAAAAAAAAAAAAAAA 
