model
size = 20 25 6, scale = 0.05, origin = -y
material 
  colors = A:#0C0 B:#111 C:#CF3 D:#00E E:#C33 F:#E00 G:#EEE H:#0E0
voxels
-------------------- -------------------- -------------------- -------------------- -------------------- -------------------- -------------------- ---------EE--------- -------------------- -------------------- -------------------- -------------------- -------------------- -------------------- -------------------- -------------------- -------------------- -------------------- -------------------- -------------------- -------------------- -------------------- -------------------- -------------------- -------------------- 
-------------------- -------------------- -------------------- -------------------- -------------------- -------------------- -------------------- ---------EE--------- -------------------- -------------------- -------------------- -------------------- -------------------- -------------------- -------------------- -------------------- -------------------- -------------------- -------------------- -------------------- -------------------- -------------------- -------------------- -------------------- -------------------- 
-------------------- -------------------- -------------------- -------------------- -------------------- -------------------- -------------------- ---------EE--------- --------G--G-------- -------------------- -------------------- -------------------- -------------------- -------------------- -------------------- -------------------- -------------------- -------------------- -------------------- -------------------- -------------------- -------------------- -------------------- -------------------- -------------------- 
-------------------- -------------------- -------------------- -------------------- -------------------- -------------------- -------------------- ---------EE--------- --------G--G-------- -------------------- -------------------- -------------------- -------------------- -------------------- -------------------- -------------------- -------------------- -------------------- -------------------- -------------------- -------------------- -------------------- -------------------- -------------------- -------------------- 
-------------------- -------------------- -------------------- -------------------- -------------------- -------------------- --------DDDD-------- --------DHHD-------- --------DDDD-------- -------------------- -------------------- -------------------- -------------------- -------------------- -------------------- -------------------- -------------------- -------------------- -------------------- -------------------- -------------------- -------------------- -------------------- -------------------- -------------------- 
------AAAAAAAA------ -----AAAAAAAAAA----- -----AAAAAAAAAA----- ----AAAAAAAAAAAA---- ---AAAAAAAAAAAAAA--- --AAAAAABBBBAAAAAA-- --AAAAABBBBBBAAAAA-- -AAAAAABBBBBBAAAAAA- AAAAAAABBBBBBAAAAAAA AAAAAAAABBBBAAAAAAAA AAAAAAAAAAAAAAAAAAAA AAAAAAAAAAAAAAAAAAAA AAAAAAAAAAAAAAAAAAAA AAAAAAAAAAAAAAAAAAAA AAAAAAAAAAAAAAAAAAAA AAAAAAAAAAAAAAAAAAAA AABBBBBBBAABBBBBBBAA AABBBBCCBAABCCBBBBAA AABCFFCBBAABBCFFCBAA AABCCFCBBAABBCFCCBAA AABCCCCBBAABBCCCCBAA AABBBBBBBAABBBBBBBAA AAAAAAAAAAAAAAAAAAAA AAAAAAAAAAAAAAAAAAAA AAAAAAAAAAAAAAAAAAAA 
