model
size = 24 24 28, scale = 0.05, origin = -y
material 
  colors = A:#111 B:#FCC C:#EEE D:#300 E:#FFF
voxels
------------------------ ------------------------ ------------------------ ------------------------ ------------------------ ------------------------ ------------------------ ------------------------ ------------------------ ---------CCCCCC--------- ---------CC--CC--------- ---------CC--CC--------- ---------CC--CC--------- ---------CC--CC--------- ------------------------ ------------------------ ------------------------ ------------------------ ------------------------ ------------------------ ------------------------ ------------------------ ------------------------ ------------------------ 
------------------------ ------------------------ ------------------------ ------------------------ ------------------------ ------------------------ ------------------------ ------------------------ ---------CCCCCC--------- ---------CC--CC--------- ---------CC--CC--------- ---------CC--CC--------- ---------CC--CC--------- ---------CC--CC--------- ----------CCCC---------- ------------------------ ------------------------ ------------------------ ------------------------ ------------------------ ------------------------ ------------------------ ------------------------ ------------------------ 
------------------------ ------------------------ ------------------------ ------------------------ ------------------------ ------------------------ ------------------------ ------------------------ ---------CCCCCC--------- ---------CAAAA---------- ---------AAAAAA--------- ---------AAAAAA--------- ---------AAAAAA--------- ---------AAAAAA--------- ----------AAAA---------- ------------------------ ------------------------ ------------------------ ------------------------ ------------------------ ------------------------ ------------------------ ------------------------ ------------------------ 
------------------------ ------------------------ ------------------------ ------------------------ ------------------------ ------------------------ ------------------------ ---------AAAAAA--------- --------AAAAAAAA-------- -------AAAAAAAAAA------- -------AAAAAAAAAA------- -------AAAAAAAAAA------- -------AAAAAAAAAA------- -------AAAAAAAAAA------- -------AAAAAAAAAA------- --------AAAAAAAA-------- ---------AAAAAA--------- ------------------------ ------------------------ ------------------------ ------------------------ ------------------------ ------------------------ ------------------------ 
------------------------ ------------------------ ------------------------ ------------------------ ------------------------ -----------AA----------- ---------AAAAAA--------- -------AAAAAAAAAA------- -------AAAAAAAAAA------- ------AAAAAAAAAAAA------ ------AAAAAAAAAAAA------ -----AAAAAAAAAAAAAA----- -----AAAAAAAAAAAAAA----- ------AAAAAAAAAAAA------ ------AAAAAAAAAAAA------ -------AAAAAAAAAA------- -------AAAAAAAAAA------- ---------AAAAAA--------- -----------AA----------- ------------------------ ------------------------ ------------------------ ------------------------ ------------------------ 
------------------------ ------------------------ ------------------------ ------------------------ ---------AAAAAA--------- -------AAAAAAAAAA------- ------AAAAAAAAAAAA------ -----AAAAAAAAAAAAAA----- -----AAAAAAAAAAAAAA----- ----AAAAAAAAAAAAAAAA---- ----AAAAAAAAAAAAAAAA---- ----AAAAAAAAAAAAAAAA---- ----AAAAAAAAAAAAAAAA---- ----AAAAAAAAAAAAAAAA---- ----AAAAAAAAAAAAAAAA---- -----AAAAAAAAAAAAAA----- -----AAAAAAAAAAAAAA----- ------AAAAAAAAAAAA------ -------AAAAAAAAAA------- ---------AAAAAA------E-- ------------------------ ------------------------ ------------------------ ------------------------ 
------------------------ ------------------------ ------------------------ ---------AAAAAA--------- -------AAAAAAAAAA------- -----AAAAAAAAAAAAAA----- -----AAAAAAAAAAAAAA----- ----AAAAAAAAAAAAAAAA---- ----AAAAAAAAAAAAAAAA---- ---AAAAAAAAAAAAAAAAAA--- ---AAAAAAAAAAAAAAAAAA--- ---AAAAAAAAAAAAAAAAAA--- ---AAAAAAAAAAAAAAAAAA--- ---AAAAAAAAAAAAAAAAAA--- ---AAAAAAAAAAAAAAAAAA--- ----AAAAAAAAAAAAAAAA---- ----AAAAAAAAAAAAAAAA---- -----AAAAAAAAAAAAAA----- -----AAAAAAAAAAAAADEEE-- -------AAAAAAAAAA----E-- ---------AAAAAA--------- ------------------------ ------------------------ ------------------------ 
------------------------ ------------------------ -----------AA----------- -------DDAAAAAAAA------- -----AAAAAAAAAAAAAA----- ----AAAAAAAAAAAAAAAA---- ----AAAAAAAAAAAAAAAA---- ---AAAAAAAAAAAAAAAAAA--- ---AAAAAAAAAAAAAAAAAA--- ---AAAAAAAAAAAAAAAAAA--- ---AAAAAAAAAAAAAAAAAA--- --AAAAAAAAAAAAAAAAAAAA-- --AAAAAAAAAAAAAAAAAAAA-- ---AAAAAAAAAAAAAAAAAA--- ---AAAAAAAAAAAAAAAAAA--- ---AAAAAAAAAAAAAAAAAA--- ---AAAAAAAAAAAAAAAAAA--- ----AAAAAAAAAAAAAAAAC--- ----AAAAAAAAAAAAADDDEE-- -----AAAAAAAAAAAAADEEE-- -------AAAAAAAAAA------- -----------AA----------- ------------------------ ------------------------ 
------------------------ ------------------------ ---------AAAAAA--------- ------AAAAAAAAAAAA------ -----AAAAAAAAAAAAAA----- ----AAAAAAAAAAAAAAAA---- ---AAAAAAAAAAAAAAAAAA--- ---AAAAAAAAAAAAAAAAAA--- ---AAAAAAAAAAAAAAAAAA--- --AAAAAAAAAAAAAAAAAAAA-- --AAAAAAAAAAAAAAAAAAAA-- --AAAAAAAAAAAAAAAAAAAA-- --AAAAAAAAAAAAAAAAAAAA-- --AAAAAAAAAAAAAAAAAAAA-- --AAAAAAAAAAAAAAAAAAAA-- ---AAAAAAAAAAAAAAAAAA--- ---AAAAAAAAAAAAAAAAAA--- ---AAAAAAAAAAAAAAAAAAC-- ----AAAAAAAAAAABBBDDEE-- -----AAAAAAAAAABDDDEEE-- ------AAAAAAAAAAAA------ ---------AAAAAA--------- ------------------------ ------------------------ 
------------------------ ---------AAAAAA--------- -------AAAAAAAAAA------- -----AAAAAAAAAAAAAA----- ----AAAAAAAAAAAAAAAA---- ---AAAAAAAAAAAAAAAAAA--- ---AAAAAAAAAAAAAAAAAA--- --AAAAAAAAAAAAAAAAAAAA-- --AAAAAAAAAAAAAAAAAAAA-- -AAAAAAAAAAAAAAAAAAAAAA- -AAAAAAAAAAAAAAAAAAAAAA- -AAAAAAAAAAAAAAAAAAAAAA- -AAAAAAAAAAAAAAAAAAAAAA- -AAAAAAAAAAAAAAAAAAAAAA- -AAAAAAAAAAAAAAAAAAAAAA- --AAAAAAAAAAAAAAAAAAAA-- --AAAAAAAAAAAAAAAAAAAA-- ---AAAAAAAAAAAAAAAAAAC-- ---AAAAAAAAAAAABBBDDDE-- ----AAAAAAAAAAABBDDDEE-- -----AAAAAAAAAAAAAA----- -------AAAAAAAAAA------- ---------AAAAAA--------- ------------------------ 
------------------------ --------AAAAAAAA-------- -------AAAAAAAAAA------- -----AAAAAAAAAAAAAA----- ----AAAAAAAAAAAAAAAA---- ---AAAAAAAAAAAAAAAAAA--- ---AAAAAAAAAAAAAAAAAA--- --AABBBBBBBAAAAAAAAAAA-- -AAABBBBBBBAAAAAAAAAAAA- -AAABBBBBBBAAAAAAAAAAAA- -AAABBBBBBBAAAAAAAAAAAA- -AAABBBBBBBAAAAAAAAAAAA- -DAAAAAABBBAAAAAAAAAAAA- -AAAAAAABBBAAAAAAAAAAAA- -AAAAAAABBBAAAAAAAAAAAA- -AAAAAAABBBAAAAAAAAAAAA- --AAAAAAAAAAAAABBBBBDD-- ---AAAAAAAAAAAABBBBBDE-- ---AAAAAAAAAAAABBBBDDE-- ----AAAAAAAAAAABBBDDEE-- -----AAAAAAAAAAAAAA----- -------AAAAAAAAAA------- --------AAAAAAAA-------- ------------------------ 
----------AAAA---------- -------AAAAAAAAAA------- ------AAAAAAAAAAAA------ ----AAAAAAAAAAAAAAAA---- ---AAAAAAAAAAAAAAAAAA--- ---AAAAAAAAAAAAAAAAAA--- --AAAAAAAAAAAAAAAAAAAA-- -AAABBBBBBBAAAAAAAAAAAA- -AAABBBBBBBAAAAAAAAAAAA- -AAABBBBBBBAAAAAAAAAAAA- AAAABBBBBBBAAAAAAAAAAAAA AAAABBBBBBBAAAAAAAAAAAA- DDAAAAAABBBAAAAAAAAAAAA- AAAAAAAABBBAAAAAAAAAAAA- -AAAAAAABBBAAAAAAAAAAAA- -AAAAAAABBBAAAAAAAAAAAA- -AAAAAAAAAAAAAABBBBBDDA- --AAAAAAAAAAAAABBBBBDD-- ---AAAAAAAAAAAABBBBDDE-- ---AAAAAAAAAAAABBBDDDE-- ----AAAAAAAAAAAAAAAA---- ------AAAAAAAAAAAA------ -------AAAAAAAAAA------- ----------AAAA---------- 
---------AAAAAA--------- -------AAAAAAAAAA------- ------AAAAAAAAAAAA------ ----AAAAAAAAAAAAAAAA---- ---AAAAAAAAAAAAAAAAAA--- ---AAAAAAAAAAAAAAAAAA--- --AAAAAAAAAAAAAAAAAAAA-- -AAABBBBBBBAAAAAAAAAAAA- -AAABBBBBBBAAAAAAAAAAAA- AAAABBBBBBBAAAAAAAAAAAAA AAAABBBBBBBAAAAAAAAAAAA- AAAABBBBBBBAAAAAAAAAAA-- ABAAAAAABBBAAAAAAAAAAAAA AAAAAAAABBBAAAAAAAAAAAA- AAAAAAAABBBAAAAAAAAAAAAA -AAAAAAABBBAAAAAAAAAAAA- -AAAAAAAAAAAAAABBBBBBDA- --AAAAAAAAAAAAABBBBBDA-- ---AAAAAAAAAAAABBBBBDE-- ---AAAAAAAAAAAABBBBDD--- ----AAAAAAAAAAAAAAAA---- ------AAAAAAAAAAAA------ -------AAAAAAAAAA------- ---------AAAAAA--------- 
---------AAAAAA--------- -------AAAAAAAAAA------- -----AAAAAAAAAAAAAA----- ----AAAAAAAAAAAAAAAA---- ---AAAAAAAAAAAAAAAAAA--- --AAAAAAAAAAAAAAAAAAAA-- --AAAAAAAAAAAAAAAAAAAA-- -AAAAAAAAAAAAAAAAAAAAAA- -AAAAAAAAAAAAAAAAAAAAAA- AAAAAAAAAAAAAAAAAAAAAAA- AAAAAAAAAAAAAAAAAAAAAAA- AAAAAAAAAAAAAAAAAAAAAAAA AAAAAAAAAAAAAAAAAAAAAAAA AAAAAAAAAAAAAAAAAAAAAAAA AAAAAAAAAAAAAAAAAAAAAAAA -AAAAAAAAAAAAAAAAAAAAAA- -AAAAAAAAAAAAAAAAAABBDA- --AAAAAAAAAAAAABBBBBDA-- --AAAAAAAAAAAAABBBAAAA-- ---AAAAAAAAAAAABBBAAA--- ----AAAAAAAAAAAAAAAA---- -----AAAAAAAAAAAAAA----- -------AAAAAAAAAA------- ---------AAAAAA--------- 
---------AAAAAA--------- -------AAAAAAAAAA------- -----AAAAAAAAAAAAAA----- ----AAAAAAAAAAAAAAAA---- ---AAAAAAAAAAAAAAAAAA--- --AAAAAAAAAAAAAAAAAAAA-- --AAAAAAAAAAAAAAAAAAAA-- -AAAAAAAAAAAAAAAAAAAAAA- -AAAAAAAAAAAAAAAAAAAAAA- AAAAAAAAAAAAAAAAAAAAAAAA AAAAAAAAAAAAAAAAAAAAAAAA AAAAAAAAAAAAAAAAAAAAAAAA AAAAAAAAAAAAAAAAAAAAAAAA AAAAAAAAAAAAAAAAAAAAAAAA AAAAAAAAAAAAAAAAAAAAAAAA -AAAAAAAAAAAAAAAAAAAAAA- -AAAAAAAAAAAAAAAAAABBDA- --AAAAAAAAAAAAABBBBBDA-- --AAAAAAAAAAAAABBBAAAA-- ---AAAAAAAAAAAABBBAAA--- ----AAAAAAAAAAAAAAAA---- -----AAAAAAAAAAAAAA----- -------AAAAAAAAAA------- ---------AAAAAA--------- 
---------AAAAAA--------- -------AAAAAAAAAA------- ------AAAAAAAAAAAA------ ----AAAAAAAAAAAAAAAA---- ---AAAAAAAAAAAAAAAAAA--- ---AAAAAAAAAAAAAAAAAA--- --AAAAAAAAAAAAAAAAAAAA-- -AAAAAAAAAAAAAAAAAAAAAA- -AAAAAAAAAAAAAAAAAAAAAA- AAAAAAAAAAAAAAAAAAAAAAA- AAAAAAAAAAAAAAAAAAAAAAAA AAAAAAAAAAAAAAAAAAAAAAAA AAAAAAAAAAAAAAAAAAAAAAAA AAAAAAAAAAAAAAAAAAAAABAA AAAAAAAAAAAAAAAAAAAAABAA -AAAAAAAAAAAAAAAAAAABBA- -AAAAAAAAAAAAAAAAAABBDA- --AAAAAAAAAAAAABBBBBDD-- ---AAAAAAAAAAAABBBBBDE-- ---AAAAAAAAAAAABBBBDD--- ----AAAAAAAAAAAAAAAA---- ------AAAAAAAAAAAA------ -------AAAAAAAAAA------- ---------AAAAAA--------- 
----------AAAA---------- -------AAAAAAAAAA------- ------AAAAAAAAAAAA------ ----AAAAAAAAAAAAAAAA---- ---AAAAAAAAAAAAAAAAAA--- ---AAAAAAAAAAAAAAAAAA--- --AAAAAAAAAAAAAAAAAAAA-- -AAAAAAAAAAAAAAAAAAAAAA- -AAAAAAAAAAAAAAAAAAAAAA- -AAAAAAAAAAAAAAAAAAAAAA- AAAAAAAAAAAAAAAAAAAAAAAA AAAAAAAAAAAAAAAAAAAAAAA- AAAAAAAAAAAAAAAAAAAAAAA- AAAAAAAAAAAAAAAAAAAAABAA -AAAAAAAAAAAAAAAAAAAABA- -AAAAAAAAAAAAAAAAAAABDA- -AAAAAAAAAAAAAAAAAABDDA- --AAAAAAAAAAAAABBBBBDD-- ---AAAAAAAAAAAABBBBDDE-- ---AAAAAAAAAAAABBBDDDE-- ----AAAAAAAAAAAAAAAA---- ------AAAAAAAAAAAA------ -------AAAAAAAAAA------- ----------AAAA---------- 
------------------------ --------AAAAAAAA-------- -------AAAAAAAAAA------- -----AAAAAAAAAAAAAA----- ----AAAAAAAAAAAAAAAA---- ---AAAAAAAAAAAAAAAAAA--- ---AAAAAAAAAAAAAAAAAA--- --AAAAAAAAAAAAAAAAAAAA-- -AAAAAAAAAAAAAAAAAAAAAA- -AAAAAAAAAAAAAAAAAAAAAA- -AAAAAAAAAAAAAAAAAAAAAA- -AAAAAAAAAAAAAAAAAAAAAA- -AAAAAAAAAAAAAAAAAAAAAA- -AAAAAAAAAAAAAAAAAAAAAA- -AAAAAAAAAAAAAAAAAAAAAA- -AAAAAAAAAAAAAAAAAAAAAA- --AAAAAAAAAAAAAAAAABDD-- ---AAAAAAAAAAAABBBBBDE-- ---AAAAAAAAAAAAAABBDDE-- ----AAAAAAAAAAAAABDDEE-- -----AAAAAAAAAAAAAA----- -------AAAAAAAAAA------- --------AAAAAAAA-------- ------------------------ 
------------------------ ---------AAAAAA--------- -------AAAAAAAAAA------- -----AAAAAAAAAAAAAA----- ----AAAAAAAAAAAAAAAA---- ---AAAAAAAAAAAAAAAAAA--- ---AAAAAAAAAAAAAAAAAA--- --AAAAAAAAAAAAAAAAAAAA-- --AAAAAAAAAAAAAAAAAAAA-- -AAAAAAAAAAAAAAAAAAAAAA- -AAAAAAAAAAAAAAAAAAAAAA- -AAAAAAAAAAAAAAAAAAAAAA- -AAAAAAAAAAAAAAAAAAAAAA- -AAAAAAAAAAAAAAAAAAAAAA- -AAAAAAAAAAAAAAAAAAAAAA- --AAAAAAAAAAAAAAAAAAAA-- --AAAAAAAAAAAAAAAAABDD-- ---AAAAAAAAAAAABBBBDDE-- ---AAAAAAAAAAAAAABDDDE-- ----AAAAAAAAAAAAADDDEE-- -----AAAAAAAAAAAAAA----- -------AAAAAAAAAA------- ---------AAAAAA--------- ------------------------ 
------------------------ ------------------------ ---------AAAAAA--------- ------AAAAAAAAAAAA------ -----AAAAAAAAAAAAAA----- ----AAAAAAAAAAAAAAAA---- ---AAAAAAAAAAAAAAAAAA--- ---AAAAAAAAAAAAAAAAAA--- ---AAAAAAAAAAAAAAAAAA--- --AAAAAAAAAAAAAAAAAAAA-- --AAAAAAAAAAAAAAAAAAAA-- --AAAAAAAAAAAAAAAAAAAA-- --AAAAAAAAAAAAAAAAAAAA-- --AAAAAAAAAAAAAAAAAAAA-- --AAAAAAAAAAAAAAAAAAAA-- ---AAAAAAAAAAAAAAAAAA--- ---AAAAAAAAAAAAAAAADD--- ---AAAAAAAAAAAABBBBDDE-- ----AAAAAAAAAAAAABDDEE-- -----AAAAAAAAAAAADDEEE-- ------AAAAAAAAAAAA------ ---------AAAAAA--------- ------------------------ ------------------------ 
------------------------ ------------------------ -----------AA----------- -------AAAAAAAAAA------- -----AAAAAAAAAAAAAA----- ----AAAAAAAAAAAAAAAA---- ----AAAAAAAAAAAAAAAA---- ---AAAAAAAAAAAAAAAAAA--- ---AAAAAAAAAAAAAAAAAA--- ---AAAAAAAAAAAAAAAAAA--- ---AAAAAAAAAAAAAAAAAA--- --AAAAAAAAAAAAAAAAAAAA-- --AAAAAAAAAAAAAAAAAAAA-- ---AAAAAAAAAAAAAAAAAA--- ---AAAAAAAAAAAAAAAAAA--- ---AAAAAAAAAAAAAAAAAA--- ---AAAAAAAAAAAAAAAADD--- ----AAAAAAAAAAABBBDDE--- ----AAAAAAAAAAAAADDDEE-- -----AAAAAAAAAAAADDEEE-- -------AAAAAAAAAA------- -----------AA----------- ------------------------ ------------------------ 
------------------------ ------------------------ ------------------------ ---------AAAAAA--------- -------AAAAAAAAAA------- -----AAAAAAAAAAAAAA----- -----AAAAAAAAAAAAAA----- ----AAAAAAAAAAAAAAAA---- ----AAAAAAAAAAAAAAAA---- ---AAAAAAAAAAAAAAAAAA--- ---AAAAAAAAAAAAAAAAAA--- ---AAAAAAAAAAAAAAAAAA--- ---AAAAAAAAAAAAAAAAAA--- ---AAAAAAAAAAAAAAAAAA--- ---AAAAAAAAAAAAAAAAAA--- ----AAAAAAAAAAAAAAAA---- ----AAAAAAAAAAAAAAAA---- -----AAAAAAAAAABAAA----- -----AAAAAAAAAAAAAA--E-- -------AAAAAAAAAA----E-- ---------AAAAAA--------- ------------------------ ------------------------ ------------------------ 
------------------------ ------------------------ ------------------------ ------------------------ ---------AAAAAA--------- -------AAAAAAAAAA------- ------AAAAAAAAAAAA------ -----AAAAAAAAAAAAAA----- -----AAAAAAAAACAAAA----- ----AAAAAAAAAA-AAAAA---- ----AAAAAAAAAA-AAAAA---- ----AAAAAAAAAA-AAAAA---- ----AAAAAAAAAAAAAAAA---- ----AAAAAAAAAAAAAAAA---- ----AAAAAAAAAAAAAAAA---- -----AAAAAAAAAAAAAA----- -----AAAAAAAAAAAAAA----- ------AAAAAAAAAAAA------ -------AAAAAAAAAA------- ---------AAAAAA------E-- ------------------------ ------------------------ ------------------------ ------------------------ 
------------------------ ------------------------ ------------------------ ------------------------ ------------------------ ------------------------ ---------A-------------- -------AAA-----AA------- -------AAACCCCCAA------- ------AAAAAAAA-AAA------ ------AAAAAAAA-AAA------ -----AAAAAAAAA-AAAA----- -----AAAAAAAAAAAAAA----- ------AAAAAAAAAAAA------ ------AAAAAAAAAAAA------ -------AAAAAAAAAA------- -------AAAAAAAAAA------- ---------AAAAAA--------- -----------AA----------- ------------------------ ------------------------ ------------------------ ------------------------ ------------------------ 
------------------------ ------------------------ ------------------------ ------------------------ ------------------------ ------------------------ ------------------------ ------------------------ --------AACCCCCA-------- -------AAAAAAA-AA------- -------AAAAAAA-AA------- -------AAAAAAA-AA------- -------AAAAAAAAAA------- -------AAAAAAAAAA------- -------AAAAAAAAAA------- --------AAAAAAAA-------- ---------AAAAAA--------- ------------------------ ------------------------ ------------------------ ------------------------ ------------------------ ------------------------ ------------------------ 
------------------------ ------------------------ ------------------------ ------------------------ ------------------------ ------------------------ ------------------------ ------------------------ ---------CCCCCC--------- ---------CAAAAC--------- ---------CAAAAC--------- ---------CAAAAC--------- ---------CAAAAA--------- ---------AAAAAA--------- ---------CAAAAC--------- ------------------------ ------------------------ ------------------------ ------------------------ ------------------------ ------------------------ ------------------------ ------------------------ ------------------------ 
------------------------ ------------------------ ------------------------ ------------------------ ------------------------ ------------------------ ------------------------ ------------------------ ------------------------ ---------CC--CC--------- ---------CC--CC--------- ---------CC--CC--------- ---------CC--CC--------- ---------CC--CC--------- ----------C--C---------- ------------------------ ------------------------ ------------------------ ------------------------ ------------------------ ------------------------ ------------------------ ------------------------ ------------------------ 
------------------------ ------------------------ ------------------------ ------------------------ ------------------------ ------------------------ ------------------------ ------------------------ ------------------------ ---------CCCCCC--------- ------------------------ ------------------------ ------------------------ ------------------------ ----------CCCC---------- ------------------------ ------------------------ ------------------------ ------------------------ ------------------------ ------------------------ ------------------------ ------------------------ ------------------------ 
