model
size = 32, scale = 0.05, origin = -y
material 
  colors = A:#042F08 B:#066F08 C:#074F07 D:#2E8F4E E:#020B09 F:#2C6F4F G:#0D8F2E H:#4E8F4E I:#0C6F30 J:#2AAE2E K:#2E902D L:#2C6F2E M:#2D6E6F N:#0F6E6D O:#4DD10C P:#4D704E Q:#0C4F2F R:#0B2F2E S:#0F4E6D T:#6A7051 U:#089009 V:#0F4E4F W:#4DAF30 X:#116F4F Y:#4CAC4C Z:#4D8C6F Aa:#12B02D Ab:#0B0D2E Ac:#4E6E6F Ad:#2CAE4C Ae:#4E8F2E Af:#9A8F59 Ag:#6F9050 Ah:#2EF308 Ai:#118F6F Aj:#2E916F Ak:#2E8F0F Al:#4FAD0D Am:#6D8E6E An:#2D4F4F Ao:#6B706F Ap:#0F8E4E Aq:#2E4F6E Ar:#30D00F As:#9F701C At:#138E8E Au:#09CE09 Av:#0E2F4F Aw:#2AAD8D Ax:#4D536E Ay:#6E7030 Az:#4D7030 Ba:#09AF0C Bb:#4EF109 Bc:#4C514F Bd:#71AC71 Be:#2DCC2C Bf:#2C918F Bg:#2CAE0F Bh:#2CAD6F Bi:#4EB370 Bj:#9C5E43 Bk:#6CB02F Bl:#6DAD50 Bm:#6D522F Bn:#4DCE2E Bo:#8B8E2E Bp:#11CC2D Bq:#10728E Br:#8FB35A Bs:#6F5162 Bt:#2E326D Bu:#6E6E8F Bv:#6E912E Bw:#4F8C8C Bx:#61B09A By:#6F528F Bz:#2D700C Ca:#2D6F8C Cb:#59A397 Cc:#6CB00D Cd:#6F5110 Ce:#2D3150 Cf:#4E500F Cg:#6F700C Ch:#0FB150 Ci:#70108E Cj:#2EC94F Ck:#6E8F0D Cl:#4E708D Cm:#2D4E2E Cn:#8D6F0C Co:#6ED00F Cp:#09F103 Cq:#AD901A Cr:#0ECF6D Cs:#0F306C Ct:#4D900D Cu:#4C4F2E Cv:#53306E Cw:#6D2A92 Cx:#914E70 Cy:#13AD8D Cz:#6C918C Da:#8C5110 Db:#30CF6E Dc:#0B124B Dd:#50E92F De:#6ECE6C Df:#4FCA6F Dg:#A3706B Dh:#9BAE22 Di:#904E91 Dj:#9D2FA8 Dk:#6ED12D Dl:#12AE6D Dm:#0C4F8E Dn:#8DAE10 Do:#9B229F Dp:#0BD08F Dq:#2A500D Dr:#4D6F0D Ds:#70D24D Dt:#592698 Du:#A05C5F Dv:#90CD30 Dw:#2B4C8B Dx:#321169 Dy:#472F50 Dz:#D0AF31 Ea:#96D446 Eb:#470452 Ec:#BBA455 Ed:#0CC94E Ee:#B09170 Ef:#AFB24E Eg:#4FD04F Eh:#A2DEAD Ei:#B0B32D Ej:#2D348E Ek:#4F2A18 El:#6DE65C Em:#8C900E En:#2F0B4F Eo:#6E5FB0 Ep:#8DF00C Eq:#4B2E30 Er:#4B8CAB Es:#138BAD Et:#CF6E53 Eu:#4757A6 Ev:#AD4E99 Ew:#6D6BAB Ex:#8E6E9B Ey:#CAAE4E Ez:#53D08D Fa:#8C919A Fb:#10F44E Fc:#D1D845 Fd:#2DF250
voxels
257-A30-2A30-E31-E719-BC207-A30-AC21-2B7-AbR21-2B7-AbS21-2B30-A23-2(C31-)C543-2G31-IC207-A31-BI19-BeG9-2S19-AdGB8-SBq8-A10-AiQ9-BqCy8-A3-Au6-SR23-G31-2G30-CR30-2E510-2J31-JP63-2Bg29-BIY2AmD2A23-Dd-QVBh2DX24-2OAeE-2GFN24-AaGBp-G29-2Aa-BnO11-2G15-IBBnO11-GD7-U9-AfBl11-2D7-B9-2Af11-CyBx7-A3-Ar6-At20-A3-2J30-GAp31-N31-Dc312-Ab30-2E31-A133-OJ6-AhBe22-Al-Af6-BeIC21-2Bj7-2C22-2O28-KC2-DgAz2-A23-KAz4-DFAE22-O3-Q3-D21-3C3-P-2AzL17-Ah6-2GAa-Q-WO11-G5-Aa-Au5-B-Q-F-Ar11-Aa4-GAa-G7-2AT13-2J3-2G-G3-O5-BjAf12-BxAm3-2B-R3-2O18-BhAm3-A2-E4-Bn23-E7-Bx31-Bf312-2Av30-AbAv30-CQ30-2C30-A101-O6-AlO23-DP4-SDAlBeI21-N-Ax3-S3-CXP20-AiK8-DF18-ApX2-MEv7-Ck18-Ai4-AcKPNA3-Cc13-Ah5-C7-D3-J13-2Ah2-2G8-D3-K13-AhO4-Ab8-G2-X13-JBiBp3-2Ab-C3-J-Q2-I7-AaAr4-2AaBp5-3AZ-ApAa11-Ar-Al3-IX-Ap2-BeW-D2-Bm7-E6-EeCn2-AB-2At2-DdW-LAn9-E6-T2Cn-CU-Av4-Bo-2T-IC17-E7-2Bo2Z-2BA27-R177-E31-A68-N31-NX30-VX30-BI29-2C164-N5-SFAyAgN21-AcAj4-AqMAcCx-2MS16-OArZ-K3-2HEdAgAc-PMF15-O3-J3-2YAk3-Ck18-P2-TAc-ABz2-2O-Cc13-AhBb3-Q2-TBd2Ad3-O2-JEh13-CcCk-AuJ4-D4-OAr-2K13-CcCk3-Ab9-D-2F13-Bi-Y2-Ab8-2QA-I7-OAl4-Aw-Ds3-N6-Ap-E-C-VQ5-OAlAe2-N2-Bx2-I-L-FAs-2G3-AV-QB5-AsCn2-2R-At2-Ao-Z2-ClBcE6-EA6-2CnBm-B-C4-2Ac2-Aj-G20-A4-Bv3-ArF-Q4-2E2C17-GQAn2-CA4-2E2C19-M31-X4-C31-CB12-U11-IBC3-2A12-U11-AiQE16-CB11-BiNE16-A12-Am-Am31-Am21-N2Aw5-2BkAf22-AwBhJ4-Ck2Bo22-2GBe5-2Bo226-AyTN21-Ac7-AcT-2M13-Ah5-AoZ5-Bg3-Ap-MAy10-WAh3-2O-Ak5-D-2W-CqAyAlBb9-OWCj2(F-)ZB5-Cm2-O-FcAmAlAh8-OCo-BnF-F2-G4-Ac3-YG-Eh10-Bn-G-2AyB3-JU-H5-G-Aw9-AuAh-U-DhBo-F2-AjLC6-M2-Bk13-Bi-CfA2-HAd7-A2-BkJ6-AlBe3-Aw2-ACL3-I4-AAl-CT2-I6-DN2-S-AfBo-D4-Y2-S3-A2AwIB6-AyBcTEVG3-Cb5-K-P15-BmTAq-Q3-Dg4-AjK2H4-2N2Aa8-AnBt-C3-Ca2-Bs5-Av3-ER2B15-NAd3-2HD2EO22-J2D-AoH2-AuO16-Bc5-AdHBg-I-V-GAd13-AuCd2BcAv5-LFBgAe-V-C-X11-AuKCd7-2Be-2Ae4-2S11-UD8-AlOAd6-E12-BF8-AlAg-D17-2B10-Ag-AgAm27-DuAyBl2AmAb21-AwBi3-2P-Co24-BiBn2-FP-Bb25-BnBlUQAvCnDa26-BlU2-CnDa58-L30-2Cm75-F17-BdAo12-W14-Bb-NBfZ11-Aj-Bs13-OWNAt10-2D2-P12-W-WR-Ap-WB6-M2-Ae-AsCg10-2W-XM-P-Ak5-Cv3-Bd-Am2Ah8-O-Aa-AiM2-P6-Cx5-BfJAu8-BnBrG2-Ao3-Ad3-AgAm7-IBa7-AuJ-U2-BmY2-An3-2K7-B8-AaAp-C-Ae4-G2-2AI5-Am-Bk8-Ba-EA-2Ak3-Ad2L-2B4-Z-T-2O7-2NAj-Ak-TF-H2KI-BBz-Q2X-Cz2-O8-Bq-VH-AtD2-DAk2B-I-Aj2B-Bw2EgAa8-T-ApX-BwD2-Y2B3-YAm3-2Cy2Aa7-Da-CeXQ-AoAj2-D-2AfAeH2-S12-2TCf4-BmAc2-HBq2AgZ4-Bv19-HY-2PF2-AcP2-Bv15-BcAi2-UK5-K-Ad2-Bl12-AuCqAsBcSV2-2B4-V-P2-Cb6-C5-KBo6-B5-H2PS-S6-A5-2Bd7-K2-2YZ2TRE7-Ab4-N-Dm7-P3-PApAqAg14-NAb7-NF4-Ax-Am23-Y5-An22-Bi2-H4-Q23-BiAmBlH-Ag2A25-Am2-Q-As25-R-2Bg-As26-2AtAe31-VL29-V-Bl60-WEf10-2Bb-F13-2W-BdAf10-WD-W13-2WAi2-Cn8-2W2-Be13-O2-AnCgCf9-Bu2-I13-F-R11-Y3-Bc12-Af-DfAM2C8-M3-Y12-AfT2-M-I7-Bu4-At11-EzBxAq2-Ao-GU6-Ae5-O10-Aj-I2-Bl2-B6-J6-C8-2Aa-C-F2-AzAm6-K7-Al7-G-EA-Ag2-FW6-K2-J-Bw2-Al7-B2-AjAc-H2-Ak7-ArR-XAb2-O7-AAqDm3-T3-Br6-OAj-RAbBjFa8-Bo2BjAnQ-K3-Y6-FAf13-Bo-Cd2CeQK3-Ad6-TBj13-2T5-Bm2-Ad5-L2-M12-Bw3-AtDbFb-T-Aq3-QAq4-Ay13-AhBcSAiCh-L2-AvWJQ5-As6-A5-Ah-Bc-VK-L2-KAz2L4-ACb6-A6-AlBk2-K2-L8-2A7-R5-Bd-Bd5-D7-Ag9-Av4-N-BfBwAo4-H7-Ag9-S4-2NBq4-EL7-L2Bf13-S7-F6-P2-R21-Ac2-KDF-KCAb21-Am2-P2-UDLAvAb20-C4-Ay3-C-CB19-FBh2-Ay7-B19-At2-H29-T-H29-T31-Aj28-W-AaAl10-Am2-P13-W-Ce2-Ey9-W2-T14-Bm2-CdAs8-W3-Cb14-Ao2(-T)8-M3-V11-C-Dm2-T-Ce9-Bl-JCvAoM9-A-Ca-A-BtCe9-Ae-LAgAoMF10-CaAi-Bt-Ab8-Ae4-BeMFO7-AwBfS3-Bh9-J5-FAlO7-2AwQ2-W-B8-Y6-BeAr6-QN-B2-FL8-Ba6-Ax8-QSBt-Cj-YD-Aa5-2U6-Ax8-BSNAj-Ag2-DC5-2BAr-2J-BjAs7-A2-DmDpAj4-Ag5-2B2-S-Ab10-CqCt3-R4-Y6-F-P12-CtDn3-Ac4-Z6-Z-Ac12-De3-SAcDjCk2-An5-By2-U12-Bx3-SDbDs-AcBhE5-H3-Bj11-At-BbAdS-Bp-P-R4-H3-XAs6-E3-At2Bw2-Ae-Bp-L-F4-M2-D8-B2-AvBq2-Bb-Ay-K-L2-BtAd2J4-Ab7-I5-DJDzCq2-AdK9-B8-S5-D2-Bm2-XM9-B8-2Ai3-2Ai5-E4-D5-R9-At3-Ai7-Ao2-Ag2D2-DVR13-S7-H-L3-H2-V19-2AAq2-Ao3-MAcAv-V18-A4-Az6-AkL18-Ak4-Cf6-CD19-D3-A7-Ax20-P2-C28-Az-Aj58-DlAiAuAlCd9-Af3-Bz13-Bh2-CdBc9-As3-P14-AxF-Ax9-P2-Ba11-2G2-Av-BhBu8-N2-A12-2G-Bf2-AtAc8-Z-H13-2CBf-V2-M8-By-Ac2-Z11-U-Ai-Z2-I7-F2-AsYDM11-ND-Z-2Ak7-Ai6-O8-At-Q2-S-2Ak7-Bd6-BeAr7-S-AbCiCw-H9-Q5-NQI6-R-BtDtExAo2-Y8-I4-A2AbC6-ACj2-Cj3-D9-P-VC10-ABb3-KD2-W7-Ao-N12-CtAl3-CE2-Ak6-Y3-Al11-CtJ4-Ci2-B5-2Ak2-H12-AjFDaCfCeBc3-BE4-A3-D12-AwT2Cf-Bc-DkAx-E5-H2-D12-Aj2-2Ad-DkK-L5-B2-L12-AtCbDgDa2-X2(-K)5-M3-A7-B-AbAvBq2-AhBbBs-JG2-Y-OBQ4-Ab7-IGE3-GJ-BjCx2-K-DCOQD3-L8-GAp4-X2-CgAy2-H-2FAVD4-E7-AiBh3-VAi6-H2-Q-KI3-AE8-Bi3-R7-Ae2-B2-K2-H10-Aj3-A6-H2-AjI3-H2-XQ12-E5-D2-F5-M3-Q17-J3-L6-P2-H17-J4-B6-D-D18-Ad3-A7-P19-M3-A27-Bs2-Ac28-Bs2-H27-N2-Az9-2Af2-L14-2S-X9-2Bj2-D11-Aa2-AxN-S9-Ax3-G11-2Aa-Av-Cz-Cy8-X2-Ar12-GMBf4-Aw8-D-ApBb12-Ab2-Aj3-Cr7-By-J14-C-Aj-Br2-G7-K-Bl3-G11-ID-Br2-Bg7-B2-T2JG11-IBp-Aq2-J7-B5-B11-AkCiAx2-WAd8-Ae3-I9-EAb3-Ao3-G8-Q3-I9-E4-2O2-Q8-D2-2C11-Cf2-G-J-Ad8-T-Bu12-WBm4-W-B7-Y3-BnAr10-Aj-BmAc2Ap2-B6-H3-WBn10-Aj-As5-F6-A4-An11-Ac7-N7-U2-AnE2-A7-S-AzEe2-Ak2-Ap7-H-Ad12-FYAyAsBy2(2-Ak)6-W-J10-ARQ4-ClEw-Dl-Y5-U2-D9-GA3-BaAu-CxBy2-BrK5-D2-Cm9-Aa4-I3-Ce2-BrG5-P3-E8-Bi3-2I6-H-X4-D2-Ag9-Bd3-A6-F2-2B3-Ag2-P9-2Ag2-A5-D2-T5-Z2-F10-Bm8-An2-F5-G3-D18-H2-Bl6-F2-H17-B4-B5-Bt2-K17-B4-A6-CiFBg17-A32-Cm2-An62-Ad11-BdBi-Q10-Ah2-SAnBc-X10-U2-T10-AaArJ2-Y-S9-Ax2-Aa11-DwJZ4-Ai8-X3-Bn11-AqM5-Ad8-D2-Al12-EAv5-Cj8-Bk-DF12-2E-CfBr2-Cj8-K-M15-An2-Af-Bg8-B-Ac14-BgK2-Ao-Y8-B2-AoG12-2J-Ba2-Y8-K4-E11-2Ad-D2-I8-B2-Cj-Ah12-DlGAu2-I8-B2-FDrO10-BjAxMB-U-I8-E2-BjBoO9-Af-MBqBiDv2-D8-Aa3-Aa10-AdCf-AtBi2-U8-HK3-AaG9-F7-Dc6-R4-BlGI8-Aw8-Ab7-P2-E-2C7-S2-BsBh2-J2-E6-Am2-N2-2A7-AvWE2-2Ai-FAn7-W-J11-QAn-E2-CrAi-F-E5-B2-J18-Ai2-Bj6-U2-L9-Aa4-A3-CeI-BrCq6-F-K9-Bb3-BC4-2B2-Ak4-D2-D9-BbAg2-B5-B3-Ba4-D2-L9-AgAf7-W4-Bg5-Z-Ac10-2As6-Bj3-H6-Z2-F9-DaAyCu5-M3-Am6-Ax2-P17-G3-K7-Aj-K17-B3-K8-FK17-Ab3-X91-V16-VAy10-AhBb-DaBjDuClR10-2UPT11-BbO4-N10-U2-R12-Cg4-X9-V2-Af13-Cb4-H9-D2-As13-Z4-Ao9-J-Ac14-Av-W2-Cw8-F2-Ca14-DyAn-T-H9-D-Aj14-Bc2-Bw-W9-D-Db14-W2-K-Bv9-L-BcT13-Y2-K-Bc8-B-Ai-M13-F2-W-R8-C-P2-OBpBa8-AxM-AcP2-R8-C-Ay-BoOApB7-O2-BqAc3-V8-Au2-Z-BxNC7-Ak-D2-Dk2-B9-Ad3-BfSR6-G3-CaN3-B7-RBq3-G2-E6-M8-C7-Ad3-LQ8-R-WSBhZ-J2-U7-K-HBd2F8-IAr4-Ad-V-E6-P-Q-2SR7-CI5-AdAu2-E6-U-E2-2E14-ChAaDAc7-F-F9-Cp9-KR-AcAk5-An2-Ac8-2Bb6-Bu2-B2-Ak5-An-Ae10-O6-Bu-B3-Bg5-Ag-L10-BvAe4-2MW4-Bg5-Bd2-Q9-BvAy4-MCl5-W5-Bd2-F10-Ay2Aq3-Ac4-X7-H-F11-3Aq2-Ca4-U7-Ak-L15-2V4-G8-2B16-V3-D92-M-Z27-BbO-Af-Aw27-Bn4-Cr10-UAgBw13-Cg4-De10-F-T14-P3-H10-Aj-Bv13-Z5-Do9-H-G13-An5-Cw8-Ae2-I13-I-J3-Ax8-M2-I13-PLAd3-Bk8-M-H14-BlY-I2-J8-M-Ax14-W3-AkBz9-XAi15-F2-W-R8-Z-Am14-M-HP2-R8-Q-Bv-I10-OBeAiAAv3-A8-A2-ZI10-ArBe3-G2-A9-M2-D9-G2-MEuF3-B9-H2-I8-C-BdBcMByAo4-E6-DtAe3-2G7-IAp4-Di4-E6-D-PAmNGB7-ICp4-DiEf2-Dq6-L-L3-RC6-EA5-Dd2-An7-L-L3-E15-J2-BAk5-P2-Ad17-CwJ9-Q2-P16-DiDg-Ac2-Bg5-P2-P9-2Al5-BuBlL9-Am2-R9-AlAe5-Bi11-Ag2-F10-MN4-Cl4-H6-J3-Ab10-Aq2M2-Ac4-Ac6-B3-2A10-Aq-N-A3-I8-D2-QA11-2XAp4-L9-BBg20-T31-Am60-FDAw28-Av3-AjCa26-Bn4-Z12-Ch14-H3-De11-MT14-W4-Ec7-G-F-W14-Aj4-Af7-Aa-Ac2-Aw12-An5-Dh7-AuBe3-S12-B5-Ax7-Ar4-A12-E5-J8-H2-Az13-BlJChCm2-U8-Ag2-L13-Bg2Ap-Ak-U8-L-2C12-Cf-R2-CgB8-D-F15-CmHKB-C8-Q-Bv-E13-A-X2-A8-E-Az-I10-Bg4-G2-A9-M-GD9-J-AlDBtBq3-B9-Cr-WI8-C-Bk4-D2-C7-BeAe-DW9-NX4-M4-E5-B2-Z10-EAv5-Dj3-W6-X-D11-E7-F2-2B5-F2-D17-Bl4-I5-B-H18-Bl4-G5-Q2-Aq17-BrBn3-Be5-P2-M17-W4-Ao5-Bd2-L10-Ch5-A11-J3-Ag9-Ai2NBhBu2-J3-Ae6-B3-Ag10-2NBhAmAeJ4-Cc6-2B2-K12-NAaAeBg3-Bz9-Bc2-A12-2L4-F10-KL19-Ag30-Z60-T3-Y27-Av4-Ca8-C18-Aj3-Dt8-B18-Bi4-Ci7-I2-BjAeBk13-W4-Dj7-GIAc2-Co13-Bp4-Ao7-AaD3-Bi13-Aa4-J7-Au4-N12-AB4-Ak8-W3-Q12-2E4-B8-Bv3-F14-ZCm2-U8-Ae3-Az13-I2(L-)U8-Az-BAU10-2BmAy2R-CgC9-IF15-AyDu-XEt10-AaF15-C-Cr2-T9-ArAz-2Ak10-AhDBt-Ed2-Bf9-DAz-HAc8-XJAlDBtBq3-M9-MAi-2U7-N-D3-Bq3-Am7-BAo-K10-2X3-AsBs3-K6-B2-Z10-2E3-ZAf-F3-An5-D2-By10-E3-AiDl2-P3-Q5-H2-L18-Bd3-Ai5-F2-E18-Bi3-Cr5-Q2-F18-J3-Z5-B2-F17-Aw4-Ao6-H-K16-A5-By6-H2-H13-BuCxAm4-W7-P2-H14-AgY4-Dr7-F2-P16-H3-Aq7-M2-D15-Y4-V8-BgJD15-Ad32-Aw2-H31-Ag27-Z3-Be27-Z3-Ar9-2C17-Aj3-2Eb7-2B17-De4-Ci7-2I2AyAsCo14-Bc3-Dj7-I4-OAr13-Ca3-Ao8-Aj3-Bn14-Cz3-J8-Bi3-J14-T3-Ba8-Bd4-Be13-Dk3-B8-Af4-G13-AlAu2-C8-T4-I8-ZBs3-L-EcBo9-Az2-M2A9-BmCqBm-R-2As9-I-Ch14-BmCx-X-Af7-ET2-Ax14-C-Cr2-Ax7-2T-P2-G13-Cy3-N9-ML2-Ac8-GBaAh2-Aw3-M7-Ab-MQ11-G4-Aw3-Bm7-AbAo-Ak10-2U3-AyAc4-Cg6-L-Ch11-B2-Ai2Z-Aa3-Ay5-Av2-By14-AiEs2-X3-Bs5-M2-L13-EAb3-I3-Ca5-F-2L19-K2-Dp5-Q2-Ah18-T3-M5-Aa2-K17-Aw4-Cw6-H-K17-X4-By6-Y2-IC15-Q3-W7-P2-KG15-F3-Ax7-F3-G15-Y3-Aq7-An2-K16-Af3-V8-U2J16-Z4-Au89-Az-Aj-Be27-Z4-Ar9-C17-F3-M9-C18-Ar2-N9-AvAi2Al13-2Cu3-P9-X2-Bd-Ar12-Bt3-Ac9-Aj3-2Ar13-Ax2-Bl9-Bw3-2J13-T3-U8-Bu3-2G13-Bk3-C8-Am3-2I13-Al2-Bd8-Aj5-I8-Z4-UX-Bo8-Ak4-N9-ZAmDhCk-BAp-Dh8-K3-Bj12-BkCkF3-Az7-An3-AxAy15-S2-An7-H3-Ax15-Bf3-Ax7-IAe2-AcAf9-2B3-Aj3-Cl7-AbAd2-AcH9-A4-N3-Bm7-F2-Ba-2A12-OFBq3-Cn5-J2-J14-FJO-Q3-Bj5-F-H15-R3-X3-Ao4-Ap2-T14-2E3-R3-Bf4-At-F21-K3-R4-H-Ae20-H3-Bt4-H-Bc19-T3-Cv5-D-T18-Bm3-Ad7-Z-A17-EAp2-L8-LY-B15-RU2-Ax7-Bm2-HB16-Aq2-Er7-R2-H17-R2-Ap8-DqJ18-B3-F8-Cj22-J32-D25-K-Y28-XGA-Dr11-BbO16-GEq-M9-EAe17-2Ar-Dc9-Av-AlCc12-CdCuBy3-P9-N2-Cc14-Ax3-Ac9-Ad2-Ad15-Ai3-Ad7-C3-Ad15-M3-U7-I3-Ai15-Ad3-C8-Ad2-N-2C12-U2-W9-Aj3-2C8-Bh4-C2-Az8-L4-R8-AtDDfBk2-C2-Dh7-B3-2Ay11-DfBkAlBnAi2-Y7-L2-I-As13-AhBb3-F6-Ao4-HY14-Bu3-B6-L4-HY14-Bx4-Bz5-L3-H-H15-Ds3-AfB4-P2-JAq-BC12-OBe-Df3-B4-L-Z15-I2J2-Bh2-P4-H2-P15-IB3-S2-Ax4-F2-Aj20-Aq3-S3-F2-NAb19-F3-R3-F2-Ae20-D3-Cs3-Ag-P20-Ac3-An4-Ci2-M18-2Bm3-An2V2E-W-P20-Bg2-MVG-FAcWAF20-H2-R-Z2-Ao-Bs-H18-EAz2-RFH5-T-Bu17-R3-U7-M-Ao17-Q3-Fd7-RN18-K3-Cj7-E24-Bl25-K-AhCp28-BaCEpBb11-CoO13-EAbAt2-D11-BvO14-EBfCz-NDc10-TAu13-As-By-Bm2-A8-Am2-Bo11-Ao2As-Cy3-Q7-Br3-Br11-Ao3-Aq3-An7-Ct3-Bd15-F3-Aq7-L3-N15-Cd3-Ap7-D3-N-2C11-Bu4-Bp7-H4-AC12-Bf4-Ar6-Ag3-F-A8-BqD4-C3-Ah5-V3-G-Cc10-2DAa3-Cu-Ad6-Ak3-G-Y10-QXAaAh-Ce3-E5-Ao3-Ao-Y11-BBa2-Bm3-B5-Ao3-Ao-Y11-A3-Af4-Ba4-L2-DM-Aa15-Ea4-B3-V2-J-Bs-BC15-Ak3-B3-V2-Y-Bj2-A15-Bh3-Y3-H-L21-Aj3-V2-Cu3-N20-Aq4-LSP3-NAb19-Bt4-LSP2-Az21-O4-FPT2-T20-Ay4-2FTH2-Z19-AsAy8-Z2-Di18-As-K5-H5-Bq19-C5-HAc-K2-X20-D4-PHD2N-D19-N3-KHAq3-N2-Ax18-L3-2H4-Q-Cs18-K4-HP5-E19-W32-2Cp31-Bb27-2Ai2-Ba10-AwBoO14-R-Cz11-BfBw-J14-AyBs-AsBlLB7-Am2-G12-Bx2As-F3-C7-Ag3-Af10-BfBx3-Ca3-I6-T4-Cz10-At4-F3-F6-P4-Bf15-Af3-Ba5-BkD4-Bq14-Bu4-Au5-QD3-2E14-V4-Ar5-Q3-Ag-Bb9-R4-V4-A5-L3-B-Be9-RV3-RAz3-A5-C3-V-ApAq8-A-C3-L3-P5-Q3-F-VI9-2C3-T3-L6-P2-M-AbA9-2E3-T2(4-Ae)3-Ca17-Ae5-2B2-K2-FBj18-Ar4-2CAzH3-AfAs19-An2-Y-EoH3-CwCbBs17-LJ4-BkH4-Z21-Ad2-V5-IHO20-D7-Q22-Ar9-N20-Bk4-I6-I19-Af11-F18-2Af12-P19-Ab11-P20-X6-F3-D19-Y5-HAe-Ag2-D18-Ag5-K5-G19-Ag6-Ab31-Q36-2R30-RAv16-2Ai12-N-DgBd14-I-BrDn10-Bf2-Bf13-Em-F2-EnAkA7-Am2-N12-BxBrCf-Bj4-K5-Ag3-V11-AwBx3-Bu4-C5-T4-Aw10-Aw5-Aj2-Ct6-P4-N9-AvBq5-Ag2-F5-H5-N8-2E5-Ea3-Ac4-Aj6-R14-Z4-X4-F5-2A9-Ab4-R4-I5-K3-D-AaBa7-EA4-C5-R4-J3-Cp-AaI8-AC4-L4-Dp2Bf-Az3-W3-I14-D4-Bn2By2BcAf2-Ad3-A14-Bf5-AmCl2F3-K18-F-Ar5-LK3-Al16-E2-AhAu10-Bi18-Ce-Az2-DDb6-Cb18-LG3-Db7-V17-E-J2-Cz-F-AgTBC2GC16-A2-J2-BrBcDAcI21-U-G2-VMQXAqIE19-2E-Bh2-Y-XAzAqCiCmB18-E-Cb2-DYQ4-H-Dq20-2DJ3-H4-AzP19-E10-AzAf19-E5-K5-Am19-Aa7-I3-D18-Ag2-Ad3-HDIX-Al19-Bl3-DHPHXAb28-V37-RE16-E13-Cm-2M14-AbN12-F-Ac16-JWCc-ES7-T2-Bf13-CcBz3-J-2Aj5-Cl3-N12-BkAh2ADy2-K-K5-Ap3-V11-AwBi4-CaCv2-Cg5-M3-P10-VN5-Cl3-Dz5-Ac3-I10-2V5-Ao3-DAk2-BcD4-IA8-AE6-Be3-Ac2BzBg6-I14-AtZAo4-ChL2Bz6-A16-Ay4-HBk2HBz5-A16-A5-2LBL3-BpAu2-C14-P7-Q4-CiS2-A14-J-Cj9-BlAo15-BA-Db-Cj10-Be15-AAv-AxG-K9-Ar16-SBw2Aq-K-F7-D17-T-Bu-BH-Ap6-S18-Ce-Cr-K2(-Ap)BA-PV17-E-An2-P-YF3-A-Q17-E2-Bg-Ax26-B-F-Az26-AC-N-AzCv25-2CD-K3-2AzHM-L21-Ch2-BzNAp-H-ZD22-2Ae-NGJOAm-D22-Cq2-AeG-L3-W20-Bg-AuKZNDLI2-Ak20-BgAy-Ak2M2DIAb2Q22-Ab3-2HF29-Aq35-AeAk2-M14-A12-C-Z2M14-A2An2-2E6-B3-At15-J-Ah-E-V2-C2UAy2-Aa14-2AhBa2-J-2Aw-2ZLBe3-Bg13-BpAh2-Bv-ChS2-T2Bv2Y3-Ag12-ApAa4-S-Cv2-BcAoAz2Z3-BkE10-2An5-BtDx3-2DBhAjH3-J11-I6-Cl5-HY5-Ap11-B6-Ah5-Bg6-I13-EAbAtCbBnG5-Z6-A17-Dn12-2F17-A3-Af7-P16-E2-P-Y8-AfCd-SAe13-CB-PG-Ax7-Af-AjSAe13-BQ-AmC-Cw6-FDAa-Bs15-VDf-A-J8-VAq16-S2-Aq-Be4-H3-G18-Cx-Bu-U-Ab-K2C2-C19-Av-Ai-K-AkE2C2-VA17-S-An2-Ax2-E2-2C-C17-S2-GA6-A20-An2-GP27-U-V-2Do25-2U-VAb37-OHAg24-2O5-2Ag22-2AlO4-BDH22-Ae7-D2Q21-F9-Q94-2Ae2-N14-U7-RE2-EAk-K-M14-BIG2-A2IFAn2BU3-MAc16-KAu2-Q-DK4-Y-X14-Ah2-AhO2-Ab-AcZ6-X13-BpAh3-Ah2-AbF-K3-Cc-L13-ApAu4-Ai-M9-Ar12-UG5-2Cs10-2G11-U7-V2-2JD-D2-YG12-C7-C2-DX-2X2-XQ15-AVMBn-2CQ2V-C2L-RAE17-BnAe-EB2-Q-C2-2AnA18-Ae2H-AcBhDK2-BdBw16-2A-V-YSBiBh4-Bo4-DdBb12-AB-LU-Ax2X3-HEk3-N-Bb13-GF-E-DxRC3-Bl3-Bs-Bo14-F2-E-B4-Y-YAp-AqBj16-El-Cd2-E2-Bl-As2-G19-Cq-D-AdEAv3-2D19-BfCu2-BtAd-E3-XIE18-Bf-2AcCv6-R20-Bf2-Bh7-E20-M2-2Bh27-Aa-EAb2Ci26-Au-EAb37-2IM24-2O5-M24-Al30-AeW30-D31-F76-DW13-2A4-A7-B2-H15-BG3-IU4-AeDdAAdBsBj16-2Au3-2Ba-AsTCtBb-AdAq18-Cp3-EjBa-E2-Ap2G21-SAq-Aa-L-I-2B13-Ba7-M-CsKBx3-F-G12-UBa6-Aq2-MOBx-T2-F13-C7-Aq-Al3-N-2Am-A12-E7-AuAaAl-B3-BsT-A15-AIX2Aa4-A4-R21-AhBb2-Av2AbB-AtAw21-Cb7-F-Aw20-2At4-BaAu2ArF19-BaG2E4-2IAh6-CgOAaBA10-Ba-E5-2C-AhAbA2-As-De14-GP2-ECAnF-DAw-I2-AsAf16-CcO2-UBFV-AmBd2B20-2D3-RA-BdBi20-Ao2Cd2S5-2At20-BrAsBc8-R20-Y-DwS28-K2-CsBt27-Au3-Bt27-Au40-3C229-Bk13-2A15-2Bk14-2C4-2U8-BrBd21-Ba-2Af5-Bi22-BaBwAfAeKIU2-N19-SCh2-ApBhJAa-2A-AvE18-SAlO-ApAdI2QU2-2E17-Bv2-OG-Q2B2Al21-BvBeOArICR2A-Co26-2A2-BdAw16-UBGBaAu7-EAbCbN27-CRVNDc27-IXV29-2I39-AaBA11-AuE7-Au-A4-AfBiAaB13-2Ah5-QI-AC3-AfBi16-2O4-A3-2C21-O9-E50-BrAsBc29-DvCkBcS28-Ar2-SCs27-Ah31-Cp272-Co31-O31-Bn30-2Bh25-B2C2-NS30-2Av21-2G8-E18-EiCg-GC4-Co21-2BoBkJIC3-2Bp22-AfBdAtXCA2-2Bp17-AB4-2AtRA4-N25-AbA4-E101-B30-NR20-2A7-AtN21-A120-CkAdAi28-BbOAd2Ap27-2Ah335-Bn31-AaG30-2G30-IB30-2C30-2A58-Bp30-GBp23-2AtAb4-UB25-Ab5-C133-E205-OAd30-Bb400-Ba31-B31-C31-A89-U31-2C679-
