model
size = 21 24 25, scale = 0.05, origin = -y
material 
  colors = A:#444 B:#222 C:#888 D:#EEE
voxels
--------------------- --------------------- --------------------- --------------------- --------------------- --------------------- --------------------- --------CC----------- -------CCC----------- -------CC------------ --------------------- --------------------- --------------------- --------------------- --------------------- ------------A-------- ---------AAAA-------- --------AAAAA-------- --------AAAA--------- --------AAA---------- --------------------- --------------------- --------------------- --------------------- 
--------------------- --------------------- --------------------- --------------------- --------------------- --------------------- --------------------- -------CCCC---------- -------C-CC---------- -------CC------------ -------CC------------ -------CC------------ --------------------- --------------------- --------------------- ----------AAAA------- ---------A---A------- --------A----A------- --------A---A-------- -------AAAAA--------- ---------A----------- --------------------- --------------------- --------------------- 
--------------------- --------------------- --------------------- --------------------- --------------------- --BB----------------- --BB----------------- --B-----CCC---------- --B-----C--C--------- --B----CCCCC--------- ------C-C-CC--------- ------CCC------------ --------------------- --------------------- ------------AAA------ ----------AA--A------ ---------AA---A------ --------AAA--A------- --------AA-AA-------- -------AA-C---------- -------AAAC---------- ---------A----------- --------------------- --------------------- 
--------------------- --------------------- --------------------- --------------------- --------------------- BB-B----------------- B--B----------------- ---B----------------- ---B-----CCC--------- ----------C-C-------- ------CCC-CCC-------- ------C-C------------ -------CC------------ --------------------- ------------AAAA----- -----------A---A----- -----------AA-AA----- -----------AAA------- --------AAC---------- -------A--C---------- -------AA-CC--------- ---------A----------- --------------------- --------------------- 
--------------------- --------------------- --------------------- --------------------- -BB------------------ -B-BB---------------- B---B-------C-------- B--BB-------CC------- -C----------CC------- -----------C-C------- ------CCC--CC-------- ------C-C------------ -------CC------------ --------------------- -------------AAA----- ------------A--A----- -------------AAA----- --------------------- --------AAC---------- --------A-C---------- -------AA--C--------- --------AA-C--------- ---------AA---------- --------------------- 
--------------------- --------------------- --------------------- --------------------- -BB------------------ ---BB-------CC------- BB--B-------C-------- B-B-B-------C-------- -CC----C----C-------- ------CCC---C-------- ------C-C------------ ------C-C------------ -------CC------------ --------------------- --------------AA----- -------------A--A---- -------------AAAA---- --------------------- --------A-C---------- --------A-C---------- --------A--C--------- --------A--C--------- ---------AA---------- --------------------- 
--------------------- --------------------- --------------------- --------------------- --B---------CC------- ----BB------CC------- -B--B--BC------------ --BBBBBCC------------ --CC--B-C------------ ------C-C------------ ------C-C------------ ------CCC------------ --------------------- --------------------- --------------AAA---- --------------A-A---- --------------AAA---- --------------------- --------------------- --------AAAC--------- --------------------- --------A--CC-------- ----------A---------- --------------------- 
-------------CC------ -------------CC------ -------------CC------ -------------CC------ --BB--------C-C------ --BBBB-BC---CC------- -BB--BB-C------------ --B--A--C------------ --BCCB--C------------ ------CCC------------ ------CCC------------ --------------------- --------------------- --------------------- ---------------AAA--- --------------A--A--- ---------------AAA--- --------------------- --------------------- --------AAAC--------- --------------------- --------A---C-------- ----------A---------- ----------A---------- 
--------------------- -------------DD------ -------------DD------ -------------DC------ -------BC---C-C------ --BBBBB-C---C-C------ --B--A--C---CCCC----- --BA--A-C---CCCC----- ---BCACCC-----CC----- -----C--------------- --------------------- --------------------- --------------------- ----------------AA--- ---------------A-A--- ---------------A-A--- ---------------AA---- --------------------- --------------------- ---------A----------- --------------------- --------A------------ --------------------- ----------A---------- 
--------------------- -------------DD------ --------------D------ -------BB----DD------ ------B--C---DC------ ---BB-B--C--C-C------ --B-BB--C---CC-C----- --BB--A-C---CC--A---- ---BA-AC----CC--A---- ----CCC-------AAA---- ---------------AA---- ---------------AAA--- ----------------AA--- ----------------AA--- ---------------A-A--- ---------------AAA--- --------------------- --------------------- --------------------- --------------------- --------------------- --------------------- --------------------- --------------------- 
--------------------- --------------D------ --------B-----D------ -------B-C---DD------ ------B--C---DC------ ------B--C---DC------ ----BB--C-----AAA---- ---BA-A-C-----A-A---- ---BB--AC-----AAA---- -----CCC------AAA---- ---------------AAA--- ---------------AAA--- ----------------AA--- ----------------AA--- ----------------AA--- --------------------- --------------------- --------------------- --------------------- --------------------- --------------------- --------------------- --------------------- --------------------- 
--------------------- --------------------- -------BB------------ -------B-C-----D----- -------B-C---DDAA---- -------BA----D-AA---- -----BB-C----D--A---- ----BAA--C---DAAA---- ----BA-AC------------ -----CCC------------- --------------------- --------------------- --------------------- --------------------- --------------------- --------------------- --------------------- --------------------- --------------------- --------------------- --------------------- --------------------- --------------------- --------------------- 
--------------------- --------------------- -------BB------D----- -------B-C----D-A---- -------B-C----D-A---- -------B-C---DDDA---- ------B--C---D-AA---- -----B---C---DA------ -----BA-C----AA------ ------CC-----AAD----- -------------AAD----- -------------AAD----- --------------------- --------------------- --------------------- --------------------- --------------------- --------------------- --------------------- --------------------- --------------------- --------------------- --------------------- --------------------- 
--------------------- ---------------D----- --------------D-A---- -------BCC----D-A---- -------B-C-----AA---- ------B--C----------- ------B--C---DD------ ------B--C---A-D----- ------BCC----A-D----- ------------A--D----- ------------A--D----- ------------A---B---- -------------DBBB---- ---------------BB---- --------------------- --------------------- --------------------- --------------------- --------------------- --------------------- --------------------- --------------------- --------------------- --------------------- 
--------------------- --------------DDA---- --------------D-A---- --------C-----D-A---- -------BCC-----A----- -------BCC----------- -------BCC----DD----- -------BC----A-D----- ------------A--D----- ------------A--D----- ------------A---B---- ------------A----B--- -------------D-BBB--- -------------BB--B--- -----------------B--- --------------------- --------------------- --------------------- --------------------- --------------------- --------------------- --------------------- --------------------- --------------------- 
--------------DD----- --------------D-A---- --------------D-A---- --------------DAA---- --------------------- ---------------D----- --------------D-B---- ------------AA--B---- ------------A--D----- ------------A--D----- -------------D--BB--- -------------D----B-- -------------D--B-B-- --------------BB-B--- --------------------- --------------------- --------------------- --------------------- --------------------- --------------------- --------------------- --------------------- --------------------- --------------------- 
--------------DD----- --------------DD----- --------------D-A---- --------------DAA---- --------------------- --------------DDB---- --------------D-B---- ------------AA--B---- ------------A--D----- -------------AC--B--- --------------DBBB--- -------------D----B-- -------------D----B-- --------------BBBB--- ----------------B---- --------------------- --------------------- --------------------- --------------------- --------------------- --------------------- --------------------- --------------------- --------------------- 
--------------DD----- --------------DD----- --------------DD----- --------------DD----- --------------DD----- --------------D-B---- -------------A--B---- ------------A--AB---- ------------A-A--B--- -------------AABBB--- ---------------D--B-- --------------D---B-- --------------D---BB- ---------------CCB--- --------------------- --------------------- --------------------- --------------------- --------------------- --------------------- --------------------- --------------------- --------------------- --------------------- 
--------------DD----- --------------DD----- --------------DD----- -------------A-D----- --------------DD----- -------------A--DB--- -------------A---B--- ------------A----BB-- -------------A-AA-B-- --------------D---B-- --------------D---B-- --------------D---B-- --------------D---BB- --------------D--B--- ---------------CCCB-- --------------------- --------------------- --------------------- --------------------- --------------------- --------------------- --------------------- --------------------- --------------------- 
--------------DDB---- --------------D-B---- --------------DD----- -------------A-D----- -------------A-D----- -------------A--DB--- -------------A---B--- -------------A----B-- -------------A----B-- --------------D---B-- --------------D---B-- --------------D--B--- --------------D---CB- --------------D-CCBB- ---------------C-CB-- ----------------B-B-- --------------------- --------------------- --------------------- --------------------- --------------------- --------------------- --------------------- --------------------- 
--------------DD----- --------------D-B---- --------------D-B---- --------------DD----- -------------A-D----- -------------A-D----- -------------A--DB--- --------------D--B--- --------------D---B-- --------------D--BB-- --------------D--B--- --------------DC-B--- --------------D-CB-B- ---------------C---B- ---------------CB---- ----------------B-BB- --------------------- --------------------- --------------------- --------------------- --------------------- --------------------- --------------------- --------------------- 
--------------DD----- --------------D-B---- --------------D-B---- --------------D-B---- --------------D-B---- --------------DD----- --------------D-B---- --------------D--B--- --------------D--B--- --------------D-B---- ---------------DB---- ----------------CBB-- ---------------C-BBBB ---------------CB--B- --------------------- ----------------BBBB- --------------------- --------------------- --------------------- --------------------- --------------------- --------------------- --------------------- --------------------- 
--------------------- --------------DDB---- --------------D-B---- --------------D-B---- --------------D-B---- --------------D-B---- --------------D-B---- --------------D-B---- --------------DDB---- ---------------DB---- --------------------- -----------------BB-- --------------------B ----------------B---- --------------------- ----------------BB-B- --------------------- --------------------- --------------------- --------------------- --------------------- --------------------- --------------------- --------------------- 
--------------------- --------------------- --------------DD----- --------------DDB---- --------------D-B---- --------------D-B---- --------------DDB---- --------------DDB---- --------------------- --------------------- --------------------- --------------------- ----------------B---- ----------------B---- -----------------B--- -----------------B--- --------------------- --------------------- --------------------- --------------------- --------------------- --------------------- --------------------- --------------------- 
--------------------- --------------------- --------------------- --------------------- ---------------D----- ---------------D----- --------------------- --------------------- --------------------- --------------------- --------------------- --------------------- --------------------- --------------------- -----------------B--- --------------------- --------------------- --------------------- --------------------- --------------------- --------------------- --------------------- --------------------- --------------------- 
