model
size = 31 25 31, scale = 0.05, origin = -y
material 
  colors = A:#9CC
voxels
------------AAAAAAA------------ -------------A-A-A------------- ------------------------------- ------------------------------- ------------------------------- ------------------------------- ------------------------------- ------------------------------- ------------------------------- ------------------------------- ------------------------------- ------------------------------- ------------------------------- ------------------------------- ------------------------------- ------------------------------- ------------------------------- ------------------------------- ------------------------------- ------------------------------- ------------------------------- ------------------------------- ------------------------------- ------------------------------- ------------------------------- 
---------AAAAAAAAAAAAA--------- ---------A-A-AAAAAAA-A--------- ------------------------------- ------------------------------- ------------------------------- ------------------------------- ------------------------------- ------------------------------- ------------------------------- ------------------------------- ------------------------------- ------------------------------- ------------------------------- ------------------------------- ------------------------------- ------------------------------- ------------------------------- ------------------------------- ------------------------------- ------------------------------- ------------------------------- ------------------------------- ------------------------------- ------------------------------- ------------------------------- 
-------AAAAAAAAAAAAAAAAA------- -------A-A-AAAAAAAA-A---------- -------------A----------------- ------------------------------- ------------------------------- ------------------------------- ------------------------------- ------------------------------- ------------------------------- ------------------------------- ------------------------------- ------------------------------- ------------------------------- ------------------------------- ------------------------------- ------------------------------- ------------------------------- ------------------------------- ------------------------------- ------------------------------- ------------------------------- ------------------------------- ------------------------------- ------------------------------- ------------------------------- 
------AAAAAAAAAAAAAAAAAAA------ -------A-AA-AAAA-A--AA-AA------ ---------A--AAA--A--A---------- ------------------------------- ------------------------------- ------------------------------- ------------------------------- ------------------------------- ------------------------------- ------------------------------- ------------------------------- ------------------------------- ------------------------------- ------------------------------- ------------------------------- ------------------------------- ------------------------------- ------------------------------- ------------------------------- ------------------------------- ------------------------------- ------------------------------- ------------------------------- ------------------------------- ------------------------------- 
-----AAAAAAAAAAAAAAAAAAAAA----- -----A-AAAA-AAAAAAAAAA-A-A----- ----------A-AAA-AAA--A-A------- ------------AA----------------- ------------------------------- ------------------------------- ------------------------------- ------------------------------- ------------------------------- ------------------------------- ------------------------------- ------------------------------- ------------------------------- ------------------------------- ------------------------------- ------------------------------- ------------------------------- ------------------------------- ------------------------------- ------------------------------- ------------------------------- ------------------------------- ------------------------------- ------------------------------- ------------------------------- 
----AAAAAAAAA-------AAAAAAAA--- ------AAAAAAAAAAAAAAA-AA-A----- -------A---AAAAAA-A---A--A----- ------------AAA---------------- -------------A----------------- ------------------------------- ------------------------------- ------------------------------- ------------------------------- ------------------------------- ------------------------------- ------------------------------- ------------------------------- ------------------------------- ------------------------------- ------------------------------- ------------------------------- ------------------------------- ------------------------------- ------------------------------- ------------------------------- ------------------------------- ------------------------------- ------------------------------- ------------------------------- 
---AAAAAAAA-----------AAAAAAA-- ---A--AAAAAAAAAAAAAAAAAA-AAA--- ------A-A--AAAAAAAAAA-A---A---- ---------A-AAAAAAAA------------ ----------AAA-AA-A------------- ------------------------------- ------------------------------- ------------------------------- ------------------------------- ------------------------------- ------------------------------- ------------------------------- ------------------------------- ------------------------------- ------------------------------- ------------------------------- ------------------------------- ------------------------------- ------------------------------- ------------------------------- ------------------------------- ------------------------------- ------------------------------- ------------------------------- ------------------------------- 
--AAAAAAAA-------------AAAAAA-- ----AAAAAAAAAAAAAAAAAAA-AAA-A-- -------A-AA-AAAAAAAAAAA---A---- ---------A-AAAAAAAAAA---------- ---------AAAAAAAAA------------- ------------AAAA--------------- --------------AA--------------- ------------------------------- ------------------------------- ------------------------------- ------------------------------- ------------------------------- ------------------------------- ------------------------------- ------------------------------- ------------------------------- ------------------------------- ------------------------------- ------------------------------- ------------------------------- ------------------------------- ------------------------------- ------------------------------- ------------------------------- ------------------------------- 
--AAAAAAA---------------AAAAA-- ---AAAAAAAAAA-----AAAAAAAAA-A-- ----AA--A-AAAAAAAAAAA-AAAA----- --------AA-AAAAAAAAAAA--A------ ---------AAAAAAAAAAAA---------- ----------AAAAAAAA------------- -----------AAA--A-------------- ------------AAAA--------------- -------------AAA--------------- ---------------A--------------- ------------------------------- ------------------------------- ------------------------------- ------------------------------- ------------------------------- ------------------------------- ------------------------------- ------------------------------- ------------------------------- ------------------------------- ------------------------------- ------------------------------- ------------------------------- ------------------------------- ------------------------------- 
-AAAAAAA-----------------AAAAA- -A--AAAAAAA---------AAAAAA-A--- --------AAAAA-----AAAAAAAA----- --------AAAAA-----AAAAAAA------ -------AAAAAA-----AAAA-A------- ---------AAAA----AAA----------- ---------AAAAAA-AA------------- ----------AA-AAAAA------------- ----------AAAAAAA-------------- -----------AAAAAA-------------- ------------AAAA--------------- -------------AAA--------------- --------------A---------------- ------------------------------- ------------------------------- ------------------------------- ------------------------------- ------------------------------- ------------------------------- ------------------------------- ------------------------------- ------------------------------- ------------------------------- ------------------------------- ------------------------------- 
-AAAAAA------------------AAAAA- --A-AAAAAA-----------AAAAA-A-A- ------AAAAA---------AAA-AA----- ------AAAAAA--------AAAAA------ ------AAAAAA--------AAAA------- --------AAAA------AAAA--------- ---------AAAA----AAAA---------- ---------AAAAAAAAAAAA---------- ---------AAAAAAAAAA------------ ---------AAAAAAAAA------------- ----------AAAAAAAA------------- -----------AAAAAAA------------- ------------AAAAA-------------- -------------A-AA-------------- ---------------AA-------------- ----------------A-------------- ------------------------------- ------------------------------- ------------------------------- ------------------------------- ------------------------------- ------------------------------- ------------------------------- ------------------------------- ------------------------------- 
-AAAAAA-------------------AAAA- --AAA--AA-------------AAA-AAA-- ---AA-AAAA-----------AAAAA----- -----AAAAAA----------AAA------- ------AAAAAA---------AAA------- --------AAAA--------AAA-------- ---------AAA------AAAA--------- ---------AAA-----AAAAA--------- ---------AAA-----AAAAA--------- ---------AAA-----AAAAA--------- ---------AAA-----AAAA---------- ----------AAAAAAAA------------- -----------AAAAAAA------------- ------------AA-AAA------------- -------------AAAA-------------- --------------A-A-------------- ----------------A-------------- ------------------------------- ------------------------------- ------------------------------- ------------------------------- ------------------------------- ------------------------------- ------------------------------- ------------------------------- 
AAAAAA---------------------AAAA AA-A-AAAA-------------AAAAA-A-A -A--AAAAAA-----------AAAAA--A-- ----AAAAAA-----------AAAA------ ----AAAAAAA----------AAA------- ------AAAAA----------AA-------- --------AAA--------AAA--------- --------AAA-------AAAA--------- ---------AA-------AAAA--------- ---------AA-------AAA---------- ----------A-------AAA---------- -----------AAAAAAAAAA---------- ------------AAAAAAAA----------- -------------AAAAA------------- -------------AAAAA------------- -------------AAAAA------------- --------------A-AA------------- ----------------A-------------- ----------------A-------------- -----------------A------------- ------------------------------- ------------------------------- ------------------------------- ------------------------------- ------------------------------- 
AAAAAA---------------------AAAA --AAAAAA---------------AAAAA-A- --A--AAA---------------AAAA---- ----A-AAA--------------A-AA---- ------AAA--------------AA------ -------AAA------------A-------- -------AAA----------AAA-------- --------AA---------AAAA-------- --------AA---------AAA--------- ---------A---------AA---------- ---------AA--------AA---------- ----------AAAAAAAAAAA---------- -----------AAAAAAAAA----------- ------------AAAAAAAA----------- ------------AAAAAAA------------ -------------AAAAA------------- -------------AAAAA------------- --------------AAAA------------- ---------------AAA------------- ----------------AA------------- -----------------AA------------ -----------------A------------- ------------------------------- ------------------------------- ------------------------------- 
AAAAAA---------------------AAAA AAA-AAAA---------------AAAAAAAA -AA-AAAA---------------AAAAAA-- --AAAAAAA--------------AAA-A--- ---AAAAAA--------------A------- -----AAAAA-------------A------- -------AAA-----------AA-------- -------AAA----------AAAA------- --------AA---------AAAA-------- --------AA---------AAAA-------- ---------A---------AAA--------- ---------AAAAAAAAAAAAA--------- ----------AAAAAAAAAAA---------- ----------AAAAAAAAAA----------- -----------AAAAAAAA------------ -----------AAAAAAAA------------ ------------AAAAAAA------------ -------------AAAAA------------- --------------AAAA------------- ---------------AAAA------------ ----------------AAAA----------- -----------------A-AA---------- ------------------A-AA--------- ------------------------------- ------------------------------- 
AAAAAA---------------------AAAA --AAAAAA---------------AAAA-A-- ---AAAAA---------------AAA-A--- ----AAAAA--------------AA------ -----AAAA--------------A------- -------AAA-------------A------- -------AAA-----------AA-------- -------AAA----------AAAA------- -------AAA---------AAAAA------- --------AA---------AAAAA------- --------AA---------AA-A-------- --------AAAAAAAAAAAAA---------- ---------AAAAAAAAAAAA---------- ---------AAAAAAAAAAA----------- ----------AAAAAAAAAA----------- ----------AAAAAAAAAA----------- -----------AAAAAAAA------------ ------------AAAAAAA------------ -------------AAAAAA------A----- --------------AAAAA------A----- ---------------AAAAA----A------ ----------------AAAAAAAA------- ------------------AAAA--------- ------------------AAAA--------- ------------------------------- 
AAAAAA---------------------AAAA AAAAAAAA---------------AAAAAAAA -AAAAAAA---------------AAAAA-A- ---AAAAAA--------------AA-A---- -----AAAA--------------AA------ -----AAAAA-------------A------- -------AAA-----------AAA------- -------AAA----------AAAA------- --------AA---------AAAA-------- ---------A---------AAA--------- ---------A---------AA---------- ---------AAAAAAAAAAAA---------- ---------AAAAAAAAAAAA---------- ----------AAAAAAAAAA----------- -----------AAAAAAAA------------ -----------AAAAAAAA------------ ------------AAAAAAA------------ ------------AAAAAAA------A----- -------------AAAAAA------AA---- --------------AAAAA-----AAA---- --------------AAAAAA---AAA----- ---------------AAAAAAAAAA------ ----------------AAAAAAAA------- -----------------AAAA-A-------- ------------------AAA---------- 
AAAAAA---------------------AAAA AA-AAAAA---------------AAAAA-A- ----AAAA---------------AA-A---- ----AAAAA--------------AAAA---- -----AAAA--------------AA------ -----AAAAA------------A-------- -------AAA----------AAA-------- -------AAA---------AAAA-------- --------AA---------AAA--------- --------AA---------AAA--------- ---------A---------AAA--------- ----------AAAAAAAAAAA---------- -----------AAAAAAAAA----------- -----------AAAAAAAAA----------- ------------AAAAAAA------------ ------------AAAAAAA------------ -------------AAAAAA------------ --------------AAAA------------- --------------AAAA------------- ---------------AAA------------- ----------------AAAAA--AA------ ----------------AAAAAAAA------- ------------------AAAAA-------- ------------------A--A--------- ------------------------------- 
AAAAAA---------------------AAAA --AAAAAAA-------------AAAAAAAAA ----A-AAAA-----------AAAAAAAA-- -----AAAAA-----------AAAAAA---- -----AAAAAA----------AAA------- ------AAAAA----------AA-------- -------AAAA--------AAAA-------- --------AAA-------AAAAA-------- --------AAA-------AAAA--------- ---------AA-------AAAA--------- ----------A-------AAA---------- -----------AAAAAAAAA----------- -----------AAAAAAAA------------ ------------AAAAAAA------------ ------------AAAAAA------------- -------------AAAAA------------- -------------AAAAA------------- --------------AAA-------------- ---------------AAA------------- ---------------AAA------------- ----------------AAA------------ ------------------AAAA--------- ------------------------------- ------------------------------- ------------------------------- 
-AAAAAA-------------------AAAA- ---AA-AAA-------------AAAAAAA-- ----AAAAAA-----------AAAAAAA--- ----AAAAAAA----------AAAAA----- -----AAAAAAA---------AAA------- ------AAAAAA---------AA-------- ---------AAA------AAAAA-------- ---------AAA-----AAAAA--------- ---------AAA-----AAAA---------- ----------AA-----AAAA---------- -----------A-----AAA----------- ------------AAAAAAA------------ -----------AAAAAAA------------- ------------AAAAAA------------- ------------AAA--A------------- -------------AAAA-------------- --------------AA-A------------- ---------------AA-------------- ----------------A-------------- ----------------A-------------- -----------------A------------- ------------------------------- ------------------------------- ------------------------------- ------------------------------- 
-AAAAAA-------------------AAAA- --AAAAAAAA-----------AAAAAA-A-- ---AAAAAAAA---------AAAAAAA---- ------AAAAAA--------AAAAAA----- ------AAAAAA--------AAAAA------ --------AAAA--------A--A------- ----------AAA----AAAA---------- ----------AAAAAAAAAAA---------- ----------AAAAAAAAAA----------- -----------AAAAAAAAA----------- -----------AAAAAAAA------------ ------------AAAAAA------------- -------------AAAA-------------- --------------A---------------- -------------AA---------------- --------------AA--------------- ---------------A--------------- ------------------------------- ------------------------------- ------------------------------- ------------------------------- ------------------------------- ------------------------------- ------------------------------- ------------------------------- 
-AAAAAAA-----------------AAAAA- ----A-AAAAA---------AAAAAAAA--- ------AAAAAAA-----AAAAAAAAA---- --------AAAAA-----AAAAAAA------ ------A-AAAAA-----AAAA--A------ ---------A-AA-----AAA---------- -----------AAAAAAAAAA---------- ------------AAAAAAAA----------- -----------AAAAAAAA------------ -----------AAAAAAA------------- -------------AAAA-------------- --------------AA-A------------- -------------A-AA-------------- --------------A---------------- ------------------------------- ------------------------------- ------------------------------- ------------------------------- ------------------------------- ------------------------------- ------------------------------- ------------------------------- ------------------------------- ------------------------------- ------------------------------- 
--AAAAAAA---------------AAAAA-- -----AA-AAAAA-----AAAAAAA-AAA-- ------A-AAAAAAAAAAAAAAAAAA----- ----------AAAAAAAAAAAAA-AA----- ----------AAAAAAAAAAAA--------- ----------AAAAAAAA-A----------- ------------AAAAAAA------------ ------------AAAAAA------------- -------------AAAAA------------- --------------AA--------------- ------------------------------- ------------------------------- ------------------------------- ------------------------------- ------------------------------- ------------------------------- ------------------------------- ------------------------------- ------------------------------- ------------------------------- ------------------------------- ------------------------------- ------------------------------- ------------------------------- ------------------------------- 
--AAAAAAAA-------------AAAAAA-- ----AA--AAAAAAAAAAAAAAAAAAA---- ---AA-----AAAAAAAAAAAAAA-AA---- ---------AAAAAAAAAAAAA--------- ----------AA-AAAAAA-AA--------- -----------AAAAA--------------- -------------AAA--------------- -------------AAA--------------- ------------------------------- ------------------------------- ------------------------------- ------------------------------- ------------------------------- ------------------------------- ------------------------------- ------------------------------- ------------------------------- ------------------------------- ------------------------------- ------------------------------- ------------------------------- ------------------------------- ------------------------------- ------------------------------- ------------------------------- 
---AAAAAAAA-----------AAAAAA--- ---A--AA-AAAAAAAAAAAAAAAA-AA--- -------A--A-AAAAAAAAAA-AA------ -----------AA-AAAAAAAA--------- -----------AAAAAA---A---------- -------------AAA--------------- ------------------------------- ------------------------------- ------------------------------- ------------------------------- ------------------------------- ------------------------------- ------------------------------- ------------------------------- ------------------------------- ------------------------------- ------------------------------- ------------------------------- ------------------------------- ------------------------------- ------------------------------- ------------------------------- ------------------------------- ------------------------------- ------------------------------- 
----AAAAAAAAA-------AAAAAAA---- -------A-A-AAAAAAAAAAAAAAA----- ---------AA-AAAAA-AA-AA-------- -----------A-AAA-----A--------- --------------AA--------------- ------------------------------- ------------------------------- ------------------------------- ------------------------------- ------------------------------- ------------------------------- ------------------------------- ------------------------------- ------------------------------- ------------------------------- ------------------------------- ------------------------------- ------------------------------- ------------------------------- ------------------------------- ------------------------------- ------------------------------- ------------------------------- ------------------------------- ------------------------------- 
-----AAAAAAAAAAAAAAAAAAAAA----- ------A-A--A-AAAAAAA-A-AA------ -----------A-AAA-AA--A--------- --------------A---A------------ ------------------------------- ------------------------------- ------------------------------- ------------------------------- ------------------------------- ------------------------------- ------------------------------- ------------------------------- ------------------------------- ------------------------------- ------------------------------- ------------------------------- ------------------------------- ------------------------------- ------------------------------- ------------------------------- ------------------------------- ------------------------------- ------------------------------- ------------------------------- ------------------------------- 
------AAAAAAAAAAAAAAAAAAA------ ------A-A-AA-A-A-AAAAA-A------- -----------------A------------- ------------------------------- ------------------------------- ------------------------------- ------------------------------- ------------------------------- ------------------------------- ------------------------------- ------------------------------- ------------------------------- ------------------------------- ------------------------------- ------------------------------- ------------------------------- ------------------------------- ------------------------------- ------------------------------- ------------------------------- ------------------------------- ------------------------------- ------------------------------- ------------------------------- ------------------------------- 
-------AAAAAAAAAAAAAAAAA------- --------A-AA-A-AAAA-A-A-------- ------------------------------- ------------------------------- ------------------------------- ------------------------------- ------------------------------- ------------------------------- ------------------------------- ------------------------------- ------------------------------- ------------------------------- ------------------------------- ------------------------------- ------------------------------- ------------------------------- ------------------------------- ------------------------------- ------------------------------- ------------------------------- ------------------------------- ------------------------------- ------------------------------- ------------------------------- ------------------------------- 
--------AAAAAAAAAAAAAA--------- -----------A-A--A--A-A--------- ------------------------------- ------------------------------- ------------------------------- ------------------------------- ------------------------------- ------------------------------- ------------------------------- ------------------------------- ------------------------------- ------------------------------- ------------------------------- ------------------------------- ------------------------------- ------------------------------- ------------------------------- ------------------------------- ------------------------------- ------------------------------- ------------------------------- ------------------------------- ------------------------------- ------------------------------- ------------------------------- 
------------AAAAAAA------------ ---------------A-A------------- ------------------------------- ------------------------------- ------------------------------- ------------------------------- ------------------------------- ------------------------------- ------------------------------- ------------------------------- ------------------------------- ------------------------------- ------------------------------- ------------------------------- ------------------------------- ------------------------------- ------------------------------- ------------------------------- ------------------------------- ------------------------------- ------------------------------- ------------------------------- ------------------------------- ------------------------------- ------------------------------- 
