model
size = 21 17 17, scale = 0.05, origin = -y
material 
  colors = A:#630 B:#F90 C:#FFF D:#FC0 E:#FF9 F:#111 G:#DDD H:#BBB I:#300
voxels
-------DDDDDDD------- -------DDDDDDD------- --------------------- --------------------- --------------------- --------------------- --------------------- --------------------- --------------------- --------------------- --------------------- --------------------- --------------------- --------------------- --------------------- --------------------- --------------------- 
----DDDD-----DDDD---- ----DDDDEEEEEDDDD---- --------------------- --------------------- --------------------- --------------------- --------------------- --------------------- --------------------- --------------------- --------------------- --------------------- --------------------- --------------------- --------------------- --------------------- --------------------- 
---DD-----------DD--- ---DDEEECCDCCEEEDD--- --------------------- --------------------- --------------------- --------------------- --------------------- --------------------- --------------------- --------------------- --------------------- --------------------- --------------------- --------------------- --------------------- --------------------- --------------------- 
---D-------------D--- ---DECCCCCCCCCCCED--- --------------------- --------------------- --------------------- --------------------- --------------------- --------------------- --------------------- --------------------- --------------------- --------------------- --------------------- --------------------- --------------------- --------------------- --------------------- 
--DD-------------DD-- -ABDECCCCCCCCCCCEDBA- AB-----------------BA B-------------------B A-------------------A B-------------------B A-------------------A B-------------------B A-------------------A B-------------------B A-------------------A B-------------------B AA-----------------AA -BB---------------BB- --AB--AAA---------A-- ---BABAAABABGBABABA-- ------AAA------------ 
--D----FF---------D-- -BAECCCFFCCCCCCCCEAB- BA-----------------AB A-------------------A B-------------------B A-------------------A B-------------------B A-------------------A B-------------------B A-------------------A B-------------------B A-------------------A BB-----------------BB -AA---------------AA- --BA--AAA---------B-- ---ABAAAAABABGHABAB-- ------AAA----GH------ 
--D-----FF--------D-- -ABECCCCFFCCCCCCCEBA- AB-----------------BA B-------------------B A-------------------A B-------------------B A-------------------A B-------------------B A-------------------A B-------------------B A-------------------A B-------------------B AA-----------------AA -BB---------------BB- --AB--AAA---------A-- ---BA-AAABABABGHABA-- ------AAA-----GH----- 
--D------FF-------D-- -BAECCCCCFFCCCCCCEAB- BA-----------------AB A-------------------A B-------------------B A-------------------A B-------------------B A-------------------A B-------------------B A-------------------A B-------------------B A-------------------A BB-----------------BB -AA---------------AA- --BA--AAA---------B-- ---ABAAAAABABAGHBAB-- ------AAA-----GH----- 
--D-------A-------D-- -ABEDCCCCCICCCCCDEBA- AB-----------------BA B-------------------B A-------------------A B-------------------B A-------------------A B-------------------B A-------------------A B-------------------B A-------------------A B-------------------B AA-----------------AA -BB---------------BB- --AB--AAA---------A-- ---BA-AAABABABGHABA-- ------AAA-----GH----- 
--D------FF-------D-- -BAECCCCCFFCCCCCCEAB- BA-----------------AB A-------------------A B-------------------B A-------------------A B-------------------B A-------------------A B-------------------B A-------------------A B-------------------B A-------------------A BB-----------------BB -AA---------------AA- --BA--AAA---------B-- ---ABAAAAABABAGHBAB-- ------AAA-----GH----- 
--D-----FF--------D-- -ABECCCCFFCCCCCCCEBA- AB-----------------BA B-------------------B A-------------------A B-------------------B A-------------------A B-------------------B A-------------------A B-------------------B A-------------------A B-------------------B AA-----------------AA -BB---------------BB- --AB--AAA---------A-- ---BA-AAABABABGHABA-- ------AAA-----GH----- 
--D----FF---------D-- -BAECCCFFCCCCCCCCEAB- BA-----------------AB A-------------------A B-------------------B A-------------------A B-------------------B A-------------------A B-------------------B A-------------------A B-------------------B A-------------------A BB-----------------BB -AA---------------AA- --BA--AAA---------B-- ---ABAAAAABABGHABAB-- ------AAA----GH------ 
--DD--FF---------DD-- -ABDECFFCCCCCCCCEDBA- AB-----------------BA B-------------------B A-------------------A B-------------------B A-------------------A B-------------------B A-------------------A B-------------------B A-------------------A B-------------------B AA-----------------AA -BB---------------BB- --AB--AAA---------A-- ---BABAAABABGBABABA-- ------AAA------------ 
---D--F----------D--- ---DECFCCCCCCCCCED--- --------------------- --------------------- --------------------- --------------------- --------------------- --------------------- --------------------- --------------------- --------------------- --------------------- --------------------- --------------------- --------------------- --------------------- --------------------- 
---DD-----------DD--- ---DDEEECCDCCEEEDD--- --------------------- --------------------- --------------------- --------------------- --------------------- --------------------- --------------------- --------------------- --------------------- --------------------- --------------------- --------------------- --------------------- --------------------- --------------------- 
----DDDD-----DDDD---- ----DDDDEEEEEDDDD---- --------------------- --------------------- --------------------- --------------------- --------------------- --------------------- --------------------- --------------------- --------------------- --------------------- --------------------- --------------------- --------------------- --------------------- --------------------- 
-------DDDDDDD------- -------DDDDDDD------- --------------------- --------------------- --------------------- --------------------- --------------------- --------------------- --------------------- --------------------- --------------------- --------------------- --------------------- --------------------- --------------------- --------------------- --------------------- 
