model
size = 32 5 20, scale = 0.05, origin = -y
material 
  colors = A:#111 B:#BBB
voxels
5-10A3-10A9-A8BA3-A8BA4-6A2(8B5A)5-A8BA3-A8BA9-10A3-10A68-15(A30-A128-)A30-A96-A62-A64-A62-A127-A128-
