model
size = 32 5 20, scale = 0.05, origin = -y
material 
  colors = A:#E00 B:#111 C:#EEE
voxels
5-10A3-10A9-A6BCBA3-A2(BC)4BA4-4ABA5BCBC5A2BCBC3B5A5-A4B2(CB)A3-A2(BC)4BA9-10A3-10A68-15(A30-A128-)A30-A96-A62-A64-A62-A127-A128-
