model
size = 32 11 32, scale = 0.05, origin = -y
material 
  colors = A:#111
voxels
96-A5-3A4-14A4-2A3-25A2-193A2(96-A6(30-2A)30-33A)2(64-A31-A6(30-2A)30-33A)7(31-A31-8(2A30-)33A)31-A31-8(2A30-)14(34A9(30-2A)30-)34A3(31-A)3(6(30-2A)30-33A96-A)6(30-2A)30-385A
