model
size = 32, scale = 0.05, origin = -y
material 
  colors = A:#111
voxels
2(30-2A)30-17(4A28-)4A25-12A20-12A16-16A5-6A5-18A3-244A2(96-2(A31-)A25(30-2A)30-33A)2(96-A27(30-2A)30-33A)2(64-A31-A27(30-2A)30-33A)2(64-3(A31-)A25(30-2A)30-33A)64-2(A31-)4(A26(30-2A)30-33A32-3(A31-))A31-2(A25(30-2A)30-33A32-4(A31-))A25(30-2A)30-33A32-3(A31-)4(A26(30-2A)30-33A96-A31-)A31-2(A25(30-2A)30-33A96-2(A31-))A25(30-2A)4(30-33A64-A31-A27(30-2A))2(30-33A64-3(A31-)A25(30-2A))30-33A64-2(A31-)A26(30-2A)30-33A96-A31-A26(30-2A)30-33A3-A7-A8-A2-A3-A4-4(31A-)864A
