model
size = 32, scale = 0.05, origin = -y
material 
  colors = A:#200
voxels
1025A29(30(30-2A)30-34A)30(30-2A)30-1057A
