model
size = 31 22 30, scale = 0.05, origin = -y
material 
  colors = A:#E00 B:#FFA9BA C:#400 D:#800 E:#B00 F:#222 G:#111 H:#630
voxels
------------------------------- ------------------------------- ------------------------------- ------------------------------- ------------------------------- ------------------------------- ------------------------------- ------------------------------- ------------------------------- ------------------------------- ------------------------------- ------------------------------- ------------------------------- ------------------------------- ------------------------------- ------------------------------- ------------------------------- ------------------------------- ------------------------------- ------------------------------- ------------------------------- ---------------H--------------- 
------------------------------- ------------------------------- ------------------------------- ------------------------------- ------------------------------- ------------------------------- ------------------------------- ------------------------------- ------------------------------- ------------------------------- ------------------------------- ------------------------------- ------------------------------- ------------------------------- ------------------------------- ------------------------------- ------------------------------- ------------------------------- ------------------------------- ------------------------------- ------------------------------- ---------------H--------------- 
------------------------------- ------------------------------- ------------------------------- ------------------------------- ------------------------------- ------------------------------- ------------------------------- ------------------------------- ------------------------------- ------------------------------- ------------------------------- ------------------------------- ------------------------------- ------------------------------- ------------------------------- ------------------------------- ------------------------------- ------------------------------- ------------------------------- ------------------------------- ---------------H--------------- ------------------------------- 
------------------------------- ------------------------------- ------------------------------- ------------------------------- ------------------------------- ------------------------------- ------------------------------- ------------------------------- ------------------------------- ------------------------------- ------------------------------- ------------------------------- ------------------------------- ------------------------------- ------------------------------- ------------------------------- ------------------------------- ------------------------------- ------------------------------- ------------------------------- ---------------H--------------- ------------------------------- 
------------------------------- ------------------------------- ------------------------------- ------------------------------- ------------------------------- ------------------------------- ------------------------------- ------------------------------- ------------------------------- ------------------------------- ------------------------------- ------------------------------- ------------------------------- ------------------------------- ------------------------------- ------------------------------- ------------------------------- ------------------------------- ------------------------------- ---------------H--------------- ------------------------------- ------------------------------- 
------------------------------- ------------------------------- ------------------------------- ------------------------------- ------------------------------- ------------------------------- ------------------------------- ------------------------------- ------------------------------- ------------------------------- ------------------------------- ------------------------------- ------------------------------- ------------------------------- ------------------------------- ------------------------------- ------------------------------- ------------------------------- ------------------------------- ---------------H--------------- ------------------------------- ------------------------------- 
------------------------------- ------------------------------- ------------------------------- ------------------------------- ------------------------------- ------------------------------- ------------------------------- ------------------------------- ------------------------------- ------------------------------- ------------------------------- ------------------------------- ------------------------------- ------------------------------- ------------------------------- ------------------------------- ------------------------------- ------------------------------- ---------------H--------------- ------------------------------- ------------------------------- ------------------------------- 
------------------------------- ------------------------------- ------------------------------- ------------------------------- ------------------------------- ------------------------------- ------------------------------- ------------------------------- ------------------------------- ------------------------------- ------------------------------- ------------------------------- ------------------------------- ------------------------------- ------------------------------- ------------------------------- ------------------------------- ---------------H--------------- ------------------------------- ------------------------------- ------------------------------- ------------------------------- 
------------------------------- ------------------------------- ------------------------------- ------------------------------- ------------------------------- ------------------------------- ------------------------------- ------------------------------- ------------------------------- ------------------------------- ------------------------------- ------------------------------- ------------------------------- ------------------------------- ------------------------------- ---------------A--------------- --------------AHA-------------- ---------------H--------------- ------------------------------- ------------------------------- ------------------------------- ------------------------------- 
------------------------------- ------------------------------- ------------------------------- ------------------------------- ------------------------------- ------------------------------- ------------------------------- ------------------------------- ------------------------------- ------------------------------- ------------------------------- ------------------------------- ------------------------------- ------------------------------- ---------------A--------------- --------------AAA-------------- -------------AAAAA------------- --------------ABA-------------- ---------------A--------------- ------------------------------- ------------------------------- ------------------------------- 
------------------------------- ------------------------------- ------------------------------- ------------------------------- ------------------------------- ------------------------------- ------------------------------- ------------------------------- ------------------------------- ------------------------------- ------------------------------- ------------------------------- ---------------B--------------- --------------AAA-------------- -------------AAAAA------------- -------------AAAAA------------- -------------AAAAA------------- -------------AAAAA------------- --------------AAA-------------- ------------------------------- ------------------------------- ------------------------------- 
------------------------------- ------------------------------- ------------------------------- ------------------------------- ------------------------------- ------------------------------- ------------------------------- ------------------------------- ------------------------------- ------------------------------- ------------------------------- ---------------B--------------- --------------BBB-------------- -------------A---A------------- -------------AAAAA------------- -------------AAAAA------------- -------------AAAAA------------- -------------AAAAA------------- -------------AAAAA------------- --------------AAA-------------- ------------------------------- ------------------------------- 
------------------------------- ------------------------------- ------------------------------- ------------------------------- ------------------------------- ------------------------------- ------------------------------- ------------------------------- ------------------------------- ---------------B--------------- --------------BBB-------------- --------------BBB-------------- -------------ABBBA------------- -------------A-B-A------------- -------------AAAAA------------- -------------AAAAA------------- -------------GAAAG------------- -------------AAAAA------------- -------------AAAAA------------- --------------AAA-------------- ------------------------------- ------------------------------- 
------------------------------- ------------------------------- ------------------------------- ------------------------------- ------------------------------- ------------------------------- ------------------------------- ---------------B--------------- --------------BBB-------------- -------------BBBBB------------- -------------BBBBB------------- -------------ABBBA------------- -------------ABBBA------------- -------------A---A------------- -------------AAAAA------------- -------------AAAAA------------- -------------AAAAA------------- -------------AAAAA------------- -------------AAAAA------------- --------------AAA-------------- ------------------------------- ------------------------------- 
------------------------------- ------------------------------- ------------------------------- ------------------------------- ------------------------------- ---------------B--------------- --------------BBB-------------- -------------BBBBB------------- -------------BBBBB------------- ------------BBBBBBB------------ ------------BBBBBBB------------ ------------AABBBAA------------ ------------AABBBAA------------ -------------AAAAA------------- -------------AAAAA------------- -------------AAAAA------------- -------------AAAAA------------- -------------AAAAA------------- --------------AAA-------------- ------------------------------- ------------------------------- ------------------------------- 
------------------------------- ------------------------------- ------------------------------- ------------------------------- ---------------B--------------- --------------BBB-------------- -------------BBBBB------------- -------------BBBBB------------- ------------BBBBBBB------------ ------------BBBBBBB------------ ------------ABBBBBA------------ ------------AABBBAA------------ ------------AAAAAAA------------ ------------AAAAAAA------------ --------------AAA-------------- -------------AAAAA------------- -------------AAAAA------------- ---------------A--------------- ------------------------------- ------------------------------- ------------------------------- ------------------------------- 
------------------------------- ------------------------------- ------------------------------- ---------------B--------------- --------------BBB-------------- -------------BBBBB------------- -------------BBBBB------------- ------------BBBBBBB------------ ------------BBBBBBB------------ ------------ABBBBBA------------ ------------ABBBBBA------------ ------------AGBBBGA------------ ------------AAAAAAA------------ ------------GAAAAAG------------ -----------G--AAA--G----------- ----------G---AAA---G---------- ---------G-----A-----G--------- --------G-------------G-------- -------G---------------G------- -----GG-----------------GG----- ------------------------------- ------------------------------- 
------------------------------- ------------------------------- ---------------B--------------- --------------BBB-------------- -------------BBBBB------------- -------------BBBBB------------- ------------BBBBBBB------------ ------------BBBBBBB------------ ------------ABBBBBA------------ ------------ABBBBBA------------ ------------ABBBBBA------------ ------------ACBBBCA------------ ------------CAAAAAC------------ -----------CF-AAA-FC----------- ----------CF---A---FC---------- ---------CF---------FC--------- --------CF-----------FC-------- -------CF-------------FC------- ------CF---------------FC------ -----GF-----------------FG----- ---GG---------------------GG--- ------------------------------- 
------------------------------- ------------------------------- --------------BBB-------------- -------------BBBBB------------- -------------BBBBB------------- ------------BBBBBBB------------ ------------BBBBBBB------------ ------------AABBBAA------------ ------------AAABAAA------------ ------------AAAAAAA------------ ------------ADAAADA------------ ------------CFAAAFC------------ -----------CFAAAAAFC----------- ----------CC--AAA--CC---------- ---------CC---------CC--------- --------CC-----------CC-------- -------CC-------------CC------- -----DCC---------------CCD----- ----CCC-----------------CCC---- ----GF-------------------FG---- --GG-----------------------GG-- -GG-------------------------GG- 
------------------------------- ---------------B--------------- --------------BBB-------------- -------------BBBBB------------- ------------BBBBBBB------------ ------------BBBBBBB------------ ------------ABBBBBA------------ ------------AABBBAA------------ ------------AAABAAA------------ -----------EEFAAAFEE----------- ----------EDFFAAAFFDE---------- ---------EDDFAAAAAFDDE--------- --------EDDC--AAA--CDDE-------- -------EDDC---------CDDE------- ------EDDC-----------CDDE------ -----EDDC-------------CDDE----- ----EDDC---------------CDDE---- ---DDCC-----------------CCDD--- ---CC---------------------CC--- --CCF---------------------FCC-- GGFF-----------------------FFG- ------------------------------- 
------------------------------- ---------------B--------------- --------------BBB-------------- -------------BBBBB------------- ------------BBBBBBB------------ ------------ABBBBBA------------ ------------ABBBBBA------------ ------------BFBBBFB------------ -----------BFFABAFFB----------- ----------BEFFAAAFFEB---------- ---------BED-AAAAA-DEB--------- --------BED---AAA---DEB-------- -------BED-----------DEB------- ------BED-------------DEB------ -----BED---------------DEB----- ----BED-----------------DEB---- ---EED-------------------DEE--- --DED---------------------DED-- -DDD-----------------------DDD- GCC-------------------------CCG -F---------------------------FG ------------------------------- 
---------------B--------------- ---------------B--------------- --------------BBB-------------- -------------BBBBB------------- ------------ABBBBBA------------ ------------ABBBBBA------------ ------------ABBBBBA------------ ------------AFBBBFA------------ -----------E-AABAA-E----------- ----------E--AAAAA--E---------- ---------E----AAA----E--------- --------E------A------E-------- -------E---------------E------- ------E-----------------E------ -----E-------------------E----- ----E---------------------E---- ---E-----------------------E--- --E-------------------------E-- -D---------------------------D- ------------------------------- ------------------------------- ------------------------------- 
---------------B--------------- --------------BBB-------------- --------------BBB-------------- -------------BBBBB------------- ------------ABBBBBA------------ ------------ABBBBBA------------ ------------ABBBBBA------------ ------------ABBBBBA------------ -------------AAAAA------------- --------------AAA-------------- ---------------A--------------- ------------------------------- ------------------------------- ------------------------------- ------------------------------- ------------------------------- ------------------------------- ------------------------------- ------------------------------- ------------------------------- ------------------------------- ------------------------------- 
---------------B--------------- --------------BBB-------------- --------------BBB-------------- -------------ABBBA------------- -------------ABBBA------------- ------------ABBBBBA------------ ------------ABBBBBA------------ -------------AAAAA------------- --------------AAA-------------- ---------------A--------------- ------------------------------- ------------------------------- ------------------------------- ------------------------------- ------------------------------- ------------------------------- ------------------------------- ------------------------------- ------------------------------- ------------------------------- ------------------------------- ------------------------------- 
---------------B--------------- --------------BBB-------------- --------------BBB-------------- --------------ABA-------------- -------------ABBBA------------- -------------ABBBA------------- -------------ABBBA------------- --------------AAA-------------- ---------------A--------------- ------------------------------- ------------------------------- ------------------------------- ------------------------------- ------------------------------- ------------------------------- ------------------------------- ------------------------------- ------------------------------- ------------------------------- ------------------------------- ------------------------------- ------------------------------- 
---------------B--------------- --------------AAA-------------- --------------ABA-------------- --------------ABA-------------- --------------ABA-------------- --------------ABA-------------- --------------AAA-------------- ---------------A--------------- ------------------------------- ------------------------------- ------------------------------- ------------------------------- ------------------------------- ------------------------------- ------------------------------- ------------------------------- ------------------------------- ------------------------------- ------------------------------- ------------------------------- ------------------------------- ------------------------------- 
------------------------------- ---------------A--------------- --------------AAA-------------- --------------ABA-------------- --------------ABA-------------- ---------------A--------------- ------------------------------- ------------------------------- ------------------------------- ------------------------------- ------------------------------- ------------------------------- ------------------------------- ------------------------------- ------------------------------- ------------------------------- ------------------------------- ------------------------------- ------------------------------- ------------------------------- ------------------------------- ------------------------------- 
------------------------------- ---------------A--------------- ---------------A--------------- --------------AAA-------------- ---------------A--------------- ------------------------------- ------------------------------- ------------------------------- ------------------------------- ------------------------------- ------------------------------- ------------------------------- ------------------------------- ------------------------------- ------------------------------- ------------------------------- ------------------------------- ------------------------------- ------------------------------- ------------------------------- ------------------------------- ------------------------------- 
------------------------------- ------------------------------- ---------------A--------------- ---------------A--------------- ------------------------------- ------------------------------- ------------------------------- ------------------------------- ------------------------------- ------------------------------- ------------------------------- ------------------------------- ------------------------------- ------------------------------- ------------------------------- ------------------------------- ------------------------------- ------------------------------- ------------------------------- ------------------------------- ------------------------------- ------------------------------- 
------------------------------- ------------------------------- ---------------A--------------- ------------------------------- ------------------------------- ------------------------------- ------------------------------- ------------------------------- ------------------------------- ------------------------------- ------------------------------- ------------------------------- ------------------------------- ------------------------------- ------------------------------- ------------------------------- ------------------------------- ------------------------------- ------------------------------- ------------------------------- ------------------------------- ------------------------------- 
