model
size = 27 29 7, scale = 0.05, origin = -y
material 
  colors = A:#EEE B:#306 C:#0FF D:#111 E:#90F F:#0CF G:#0FC H:#3F6 I:#005 J:#004 K:#09C L:#0C9 M:#099 N:#096 O:#30C P:#396 Q:#6FC R:#0F9 S:#036 T:#3C6 U:#3FC V:#06F W:#06C X:#C30 Y:#008 Z:#F96 Aa:#069 Ab:#3C9 Ac:#09F Ad:#006 Ae:#AAA
voxels
- - - D D - - - - - - - - - - - - - - - - - D D - - -   - - D C C D - - - - - - - - - - - - - - - D AaAaD - -   - - D C C M D - - - - - - - - - - - - - D M M AaD - -   - - D AcAcM D - - - - - - - - - - - - D C M M AaD - -   - - - D M M AaD - - - - - - - - - - D AcAcC C D - - -   - - - - D M AaD - - D D D D D D - - D AcAcC D - - - -   - - - - - D D D D D W W W T T S D D D D D D - - - - -   - - - - D D M L L L L W W T T S Y R R R R D - - - - -   - - - D M M M L L L L W W T T S Y Y Y Y Y D D - - - -   - - D M M M P L L L L W W S S S S S Y Y S S R D - - -   - - D M P P P L L L L W W R R R R S Y Y S S R D - - -   - D P P P P P P P P W W W R R R R S S S S S S R D - -   - D P P P P P P P P M M M P P P P S T T T S S R R D -   D F O O O O O O O M Z X X M P P P AbAbAbAbT T T T T -   D F F O O O O O M Z Z X X X M O O P P AbAbT T T T T D   D F F L L O O O M Z D D D X M O O P P L L L L L L L D   D F F L L AdAdO M Z X X X X M O O P P L L L L L L L D   - D F F L AeO D O M Z X X M O O D O O O L L L L L D -   - D F F L L D D D L M M M O O D D D D O R R R R L D -   - - D F L L D D D L L L N N N D A D D O R R R R D - -   - - D F L L D A D L L L N N N D A D D O R R R R D - -   - - - D M L AeA D L L L N N N N D N C C C C R D - - -   - - - D M L L D L N N N N N N N N N C C C C R D - - -   - - - - D M L L L N N N N N N N N N C C C C D - - - -   - - - - - D M M F F V V V N N N N N C C C D - - - - -   - - - - - - D M F V V V V V F F F F F F D - - - - - -   - - - - - - - D D V V V V V F F F F D D - - - - - - -   - - - - - - - - - D D V V F F F D D - - - - - - - - -   - - - - - - - - - - - D D D D D - - - - - - - - - - -   
- - - I I - - - - - - - - - - - - - - - - - I I - - -   - - I A A I - - - - - - - - - - - - - - - I A A I - -   - - I A A A I - - - - - - - - - - - - - I A A A I - -   - - I A A A I - - - - - - - - - - - - I A A A A I - -   - - - I A A A I - - - - - - - - - - I A A A A I - - -   - - - - I A A I - - I I I I I I - - A A A A I - - - -   - - - - - I A A I I A A A A A A I I A A A I - - - - -   - - - - I A A A A A A A A A A A A A A A A I - - - - -   - - - Q A A A A A A A A A A A A A A A A A A I - - - -   - - Q Q A A A A A A A A A A A A A A A A A A A I - - -   - - K K A A A A A A A A A A A A A A A A A A A I - - -   - I A A A A A A A A A A A A A A A A A A A A A A I - -   - I A A A A A A A A A A A A A A A A A A A A A A A I -   I A A A A A A A A A A A A A A A A A A A A A A A A I -   I A A A A A A A A A A A A A A A A A A A A A A A A A I   I A A A A A A A A A A A A A A A A A A A A A A A A A I   I A A A A A A A A A A A A A A A A A A A A A A A A A I   - I A A A A A A A A A A A A A A A A A A A A A A A I -   - I A A A A A A A A A A A A A A A A A A A A A A A I -   - - I A A A A A A A A A A A A A A A A A A A A A I - -   - - I A A A A A A A A A A A A A A A A A A A A A I - -   - - - I A A A A A A A A A A A A A A A A A A A I - - -   - - - I A A A A A A A A A A A A A A A A A A A I - - -   - - - - I A A A A A A A A A A A A A A A A A I - - - -   - - - - - K K K A A A A A A A A A A A A A I - - - - -   - - - - - - K K A A A A A A A A A A A A I - - - - - -   - - - - - - - K I A A A A A A A A A I I - - - - - - -   - - - - - - - - - I I A A A A A I I - - - - - - - - -   - - - - - - - - - - - I I I I I - - - - - - - - - - -   
- - - J J - - - - - - - - - - - - - - - - - J J - - -   - - J K G G - - - - - - - - - - - - - - - J Q J J - -   - - Q K G G G - - - - - - - - - - - - - Q J J G G - -   - - J Q G G G - - - - - - - - - - - - J F J K G G - -   - - - Q G G G Q - - - - - - - - - - J J F J G J - - -   - - - - J K J J - - Q K Q Q K J - - J F F K G - - - -   - - - - - J J J J J J K K K K J J J J J J J - - - - -   - - - - J J A A A A A A A A A A A A A A J H - - - - -   - - - Q J A A A A A A A A A A A A A A A A J J - - - -   - - Q Q A A A A A A A A A A A A A A A A A A F C - - -   - - K K A A A A A A A A A A A A A A A A A A A J - - -   - K J A A A A A A A A A A A A A A A A A A A A J J - -   - K J A A A A A A A A A A A A A A A A A A A A A J C -   K K A A A A A A A A A A A A A A A A A A A A A A J J -   Q J A A A A A A A A A A A A A A A A A A A A A A A K J   Q J A A A A A A A A A A A A A A A A A A A A A A A K J   K J A A A A A A A A A A A A A A A A A A A A A A A J C   - J J A A A A A A A A A A A A A A A A A A A U U U C -   - J J A A A A A A A A A A A A A A A A A A A A A J C -   - - K J A A A A A A A A A A A A A A A A A A A J C - -   - - K J A A A A A A A A A A A A A A A A A A G K C - -   - - - H J A A A A A A A A A A A A A A A A A G K - - -   - - - J J A A A A A A A A A A A A A G G H H H J - - -   - - - - K J A A A A A A A A A A A A G G H H H - - - -   - - - - - Q Q K A A A A A A A A A A G G J J - - - - -   - - - - - - Q K A A A A A A A A A A G G H - - - - - -   - - - - - - - K J J A A A A A A A J G G - - - - - - -   - - - - - - - - - J J J A A A J K K - - - - - - - - -   - - - - - - - - - - - H J K J J - - - - - - - - - - -   
- - - - - - - - - - - - - - - - - - - - - - - - - - -   - - - - - - - - - - - - - - - - - - - - - - - - - - -   - - - - - - - - - - - - - - - - - - - - - - - - - - -   - - - - - - - - - - - - - - - - - - - - - - - - - - -   - - - - - - - - - - - - - - - - - - - - - - - - - - -   - - - - - - - - - - - - - - - - - - - - - - - - - - -   - - - - - - - - - - - - - - - - - - - - - - - - - - -   - - - - - - C C C C C C C C C C C C C C - - - - - - -   - - - - - C C C C C C C C C C C C C C C C - - - - - -   - - - - C C C C C C C C C C C C C C C C C C - - - - -   - - - C C C C C C C C C C C C C C C C C C C C - - - -   - - - C C C C C C C C C C C C C C C C C C C C - - - -   - - - H C C C C C C C C C C C C C C C C C C C C - - -   - - C C C C C C C C C C C C C C C C C C C C C C - - -   - - C C C C C C C C C C C C C C C C C C C C C C C - -   - - C C C C C C C C C C C C C C C C C C C C C C C - -   - - C C C C C C C C C C C C C C C C C C C C C C C - -   - - - C C C C C C C C C C C C C C C C C C C U U - - -   - - - C C C C C C C C C C C C C C C C C C C C K - - -   - - - - C C C C C C C C C C C C C C C C C C C - - - -   - - - - H H C C C C C C C C C C C C C C C C G - - - -   - - - - - H C C C C C C C C C C C C C C C C - - - - -   - - - - - H C C C C C C C C C C C C G G H H - - - - -   - - - - - - C C C C C C C C C C C C G G H - - - - - -   - - - - - - - C C C C C C C C C C C G G - - - - - - -   - - - - - - - - C C C C C C C C C C G - - - - - - - -   - - - - - - - - - - C C C C C C C - - - - - - - - - -   - - - - - - - - - - - - C C C - - - - - - - - - - - -   - - - - - - - - - - - - - - - - - - - - - - - - - - -   
- - - - - - - - - - - - - - - - - - - - - - - - - - -   - - - - - - - - - - - - - - - - - - - - - - - - - - -   - - - - - - - - - - - - - - - - - - - - - - - - - - -   - - - - - - - - - - - - - - - - - - - - - - - - - - -   - - - - - - - - - - - - - - - - - - - - - - - - - - -   - - - - - - - - - - - - - - - - - - - - - - - - - - -   - - - - - - - - - - - - - - - - - - - - - - - - - - -   - - - - - - F F F F F F F F F F F F F F - - - - - - -   - - - - - F F B B B B B B B B B B B B F F - - - - - -   - - - - F F B B B B B B B B B B B B B B F F - - - - -   - - - F F B B B B B B B B B B B B B B B B F F - - - -   - - - F B B B B B B B B B B B B B B B B B F F - - - -   - - - F B B B B B B B B B B B B B B B B G G G G - - -   - - F F B B B B B B B B B B B B B B B B G G H H - - -   - - H B B B B B B B B B B B B B B B B B G G H H G - -   - - H B B B B B B B B B B B B B B B B B G G G G G - -   - - F F B B B B B B B B B B B B B B B B B B B K F - -   - - - F B B B B B B B B B B B B B B B B B B U U - - -   - - - F H H H H B B B B B B B B B B B B B B F F - - -   - - - - H H H H B B B B B B B B B B B B B F F - - - -   - - - - H H H H B B B B B B B B B B B B B F G - - - -   - - - - - H B B B B B B B B B B B B B B F F - - - - -   - - - - - H F B B B B B B B B B B B G G C C - - - - -   - - - - - - F F B B B B B B B B B B G H H - - - - - -   - - - - - - - Q Q B B B B B B B B H H G - - - - - - -   - - - - - - - - Q F F F B B B F F F G - - - - - - - -   - - - - - - - - - - F H F Q K K F - - - - - - - - - -   - - - - - - - - - - - - F F F - - - - - - - - - - - -   - - - - - - - - - - - - - - - - - - - - - - - - - - -   
- - - - - - - - - - - - - - - - - - - - - - - - - - -   - - - - - - - - - - - - - - - - - - - - - - - - - - -   - - - - - - - - - - - - - - - - - - - - - - - - - - -   - - - - - - - - - - - - - - - - - - - - - - - - - - -   - - - - - - - - - - - - - - - - - - - - - - - - - - -   - - - - - - - - - - - - - - - - - - - - - - - - - - -   - - - - - - - - - - - - - - - - - - - - - - - - - - -   - - - - - - - - - - - - - - - - - - - - - - - - - - -   - - - - - - - B B B B B B B B B B B B - - - - - - - -   - - - - - - B B B B B B B B B B B B B B - - - - - - -   - - - - - B B B B B B B B B B B B B B B B - - - - - -   - - - - B B B B B B B B B B B B B B B B B - - - - - -   - - - - B B B B B B B B B B B B B B B B G G - - - - -   - - - - B B B B B B B B B B B B B B B B G G - - - - -   - - - B B B B B B B B B B B B B B B B B G G H - - - -   - - - B B B B B B B B B B B B B B B B B G G G - - - -   - - - - B B B B B B B B B B B B B B B B B U B - - - -   - - - - B B B B B B B B B B B B B B B B B U - - - - -   - - - - - H H H B B B B B B B B B B B B B B - - - - -   - - - - - H H H B B B B B B B B B B B B B - - - - - -   - - - - - - H H B B B B B B B B B B B B B - - - - - -   - - - - - - B B B B B B B B B B B B B B - - - - - - -   - - - - - - - B B B B B B B B B B B G G - - - - - - -   - - - - - - - - B B B B B B B B B B G - - - - - - - -   - - - - - - - - - B B B B B B B B H - - - - - - - - -   - - - - - - - - - - - - B B B - - - - - - - - - - - -   - - - - - - - - - - - - - - - - - - - - - - - - - - -   - - - - - - - - - - - - - - - - - - - - - - - - - - -   - - - - - - - - - - - - - - - - - - - - - - - - - - -   
- - - - - - - - - - - - - - - - - - - - - - - - - - -   - - - - - - - - - - - - - - - - - - - - - - - - - - -   - - - - - - - - - - - - - - - - - - - - - - - - - - -   - - - - - - - - - - - - - - - - - - - - - - - - - - -   - - - - - - - - - - - - - - - - - - - - - - - - - - -   - - - - - - - - - - - - - - - - - - - - - - - - - - -   - - - - - - - - - - - - - - - - - - - - - - - - - - -   - - - - - - - - - - - - - - - - - - - - - - - - - - -   - - - - - - - E E E E E E Q E E E E E - - - - - - - -   - - - - - - E E C C E E E E E E C C C E - - - - - - -   - - - - - E E E E E E Q Q Q E E C C C E E - - - - - -   - - - - H H E E H H H Q Q Q E E C C C E E - - - - - -   - - - - H H E E E H H E E E F F C G G G G G - - - - -   - - - - E E C C E E E H E E F F C G G G G G - - - - -   - - - E E E U E E H H H H H H H E G G G G G G - - - -   - - - E E E U E C H H H H H H H F F E K G G G - - - -   - - - - E E K E E H H H H H H Q H F K E E U E - - - -   - - - - E G E E E E K K K K U K K K E E E U - - - - -   - - - - - H H H U K K K K K K K K K E F E G - - - - -   - - - - - H H H C G G K K K K K K K E F E - - - - - -   - - - - - - H H E G G E E G G G G E E E G - - - - - -   - - - - - - E E E E E E E G G G G F E E - - - - - - -   - - - - - - - K E H H E F F F F E F G G - - - - - - -   - - - - - - - - E H H E E E H K U E G - - - - - - - -   - - - - - - - - - E E E E E E E E E - - - - - - - - -   - - - - - - - - - - - - E U U - - - - - - - - - - - -   - - - - - - - - - - - - - - - - - - - - - - - - - - -   - - - - - - - - - - - - - - - - - - - - - - - - - - -   - - - - - - - - - - - - - - - - - - - - - - - - - - -   
