model
size = 21 32 20, scale = 0.05, origin = -y
material 
  colors = A:#010101 B:#FFF C:#BFBFBF
voxels
197-6A14-3(8A13-)8A14-6A17-2A479-6A13-9A11-2(11A10-)4A4-2(4A8-4A5-)4A8-5A4-4A9-12A9-5A2B4A11-9A13-7A412-9A11-12A8-5A4-4A8-3A7-4A2(6-3A9-3A)6-3A10-2A6-2A11-2A6-3A10-2A6-3A9-3A6-2(4A7-)4A5-4A8-13A9-11A12-8A15-3A61-2A18-4A16-6A16-2ABA18-2A182-12A8-13A2(7-4A)6-3A10-2A6-2A11-3A4-3A12-5(2A4-2A13-)2A4-3A11-3A5-2A11-3A5-3A9-3A7-4A6-4A7-6A-6A9-12A10-9A12-4A2B3A12-3A2(B2A)12-2AB4ABA12-AB2AC3AB12-2A6BA13-2A4BA15-2A2BA76-3A5-4A9-4A3-5A8-6A2-5A8-14A6-15A5-4A10-3A4-3A11-3A2(4-2A13-2A)4-2A14-5(2A2-2A15-)2A2-3A14-2A3-2A13-3A3-3A12-2A4-3A11-3A5-3A9-3A6-4A8-2(3A7-)C2A8-4A2(6-C2A9-3A)6-CA10-2A7-2A10-ABC5-3A10-4A3-2B2A11-3A3C3A13-7A52-7A2-7A4-4A-3A2-2A2-3A4-4A2-2A-2A3-2(3A4-)4A3-3A4-3A12-2A4-2A13-2A4-A4(15-2A2-2A)16-2(A2-A17-)2(2A-A17-)2A-2A16-A2(2-2A15-2A)3-2A13-3A3-2A13-2A4-3A11-3A5-2A11-3A5-3A10-2A6-3A10-2A2(7-2A9-3A)7-2A9-2A8-3A7-2A10-3A5-3A11-9A14-6A30-2(8A2-)3A5-A-2A5-2A2-2A6-4A5-2A2-2A6-3A6-3(2A2-2A15-)2A2-2A16-3(A2-A17-)2(4A17-)4A18-3A2(17-4A)17-2A-2A16-2A-2A15-2A2-2A15-2A3-2A14-2A3-2A13-2A4-2A13-2(2A5-2A12-)A2(6-2A11-2A)7-2A9-2(3A7-)3A9-4A4-3A11-9A15-3A10-9A2-8A2-2A6-A-2A6-A2-A7-3A7-7(A2-A17-)4A17-4A18-4(2A19-)3A18-3A17-2A-A17-2A-2A16-A2(2-2A15-2A)3-2A14-2A3-2(2A13-2A4-)2A13-2A5-2A12-A6-2A11-2A7-2A9-3A8-2A7-3A10-4A-4A14-5A9-9A2-8A2-A7-A-2A6-A2-A7-3A7-7(A2-A17-)4A18-6(2A19-)3A18-3A2(17-2A-A)17-A2-2A16-A2-2A2(15-2A3-A)15-A2(4-2A13-2A)5-2A12-A6-3A10-2A2(7-3A)10-3A3-4A13-6A8-9A2-8A2-A7-A-2A6-A2-A7-3A7-7(A2-A17-)4A18-3A18-6(2A19-)3A18-A-A17-2A-2(A17-A2-)2A16-2(A3-A15-C)A3-A15-A2(4-2A13-2A)4-3A11-3A4-5A8-4A7-4A4-6A10-6A8-9A2-8A2-A7-A-2A6-A2-A7-3A7-2(A2-A17-)2(A2-2A16-)3(A2-A17-)2A-A17-4A18-6(2A19-)3A18-A-A17-2A-2(A17-A2-)2A16-A3-A15-CA3-3(A15-A4-)A15-A3-2A15-2A-6A9-2A-12A4-8A8-6A8-9A2-8A2-2A6-A-2A5-2A2-A7-3A7-A2-2A16-A4(2-2A15-2A)2-2A16-2(A2-A17-)2(4A17-)4A5(18-3A)2(17-2A-A)17-A2-2A16-A2-2A2(15-2A3-A)3(15-A4-A)15-A3-2A15-2A-2A3-A9-A3-12A2-9A8-6A9-8A2-7A3-3A5-A-2A5-2A2-2A6-3A6-2A2-2A7-2A6-2(2A3-A15-)2(A4-A15-)2A2-2A15-2A2(2-2A16-A)2-A17-A2-7(A17-2A-)2A16-A2(2-2A15-2A)3-A15-2A3-A15-A4-2A14-A4-2A2(13-2A4-AC)13-2A3-AC14-3A-2AC-C2A7-28A9-4A11-7A2-7A2(4-2A)-2(2A4-)2A5-4A2(4-2A)6-2A5-4(2A4-2A13-)2A4-2A14-2A3-A3(15-2A2-2A)16-4(A2-A17-)2(A2-2A16-)A2-2A2(15-2A3-A)15-A4-2A14-A2(4-2A13-2A)5-A13-2A5-2A11-2A5-3A11-2A5-5A7-5A4-17A4-3A-9A30-6A3-6A6-7A2-6A2(6-15A)6-2(3A3-)3A2(6-2A11-2A)6-2A12-2(2A4-2A13-)2A4-2A14-A4-A6(15-2A2-2A)15-2A3-A15-2A3-2A14-2A3-2(2A13-2A4-)2A13-2A5-2A12-2A5-2(2A11-2A6-)3A9-2(3A7-)3A8-13A10-9A16-A58-3A3-4A11-3A3-4A10-5A-5A9-13A8-4A5-4A8-2A9-3A6-A2C9-3A6-AC11-2A6-AC11-3A4-2AC12-3(2A4-2A13-)2A3(4-2A14-A)3(4-2A13-2A)5-2A12-2A5-2(2A11-CA6-)3A9-3A7-2A9-2(3A7-)3A8-4A5-4A9-11A11-9A160-7A12-11A10-11A9-2(3A7-3A8-)2A9-3A6-3A10-3(2A6-2A11-)3A5-2A12-2A4-3A2(12-2A5-2A)11-3A5-2(2A11-2A6-)3A9-3A7-2A9-2(3A7-)3A8-4A6-3A9-4A3-4A10-11A11-9A13-7A223-9A12-9A11-4A2-5A10-3A5-4A8-4A6-3A8-3A7-2(3A8-)2A8-2A9-3A7-2A9-3A6-3A2(9-3A7-2A)9-3A7-3A8-2A8-3A7-3A8-4A5-4A9-4A3-4A10-11A11-9A13-8A14-5A289-4A16-7A14-8A12-9A12-10A10-4A3-4A10-4A4-3(3A10-3A5-)3A10-4A3-4A10-11A11-10A11-9A13-7A15-5A417-A18-5A16-6A5(14-7A)15-5A18-A262-
