model
size = 31 31 12, scale = 0.05, origin = -y
material 
  colors = A:#111 B:#E00 C:#DDD D:#EEE
voxels
---------AAAAAAAAAAAAA--------- ---------AAAAAAAAAAAAA--------- ---------AAAAAAAAAAAAA--------- ---------AAAAAAAAAAAAA--------- ---------AAAAAAAAAAAAA--------- ---------AAAAAAAAAAAAA--------- ---------AAAAAAAAAAAAA--------- ---------AAAAAAAAAAAAA--------- ---------AAAAAAAAAAAAA--------- ---------AAAAAAAAAAAAA--------- ---------AAAAAAAAAAAAA--------- ---------AAAAAAAAAAAAA--------- ---------AAAAAAAAAAAAA--------- ---------AAAAAAAAAAAAA--------- ---------AAAAAAAAAAAAA--------- --------AAAAAAAAAAAAAAA-------- --------AAAAAAAAAAAAAAA-------- -------AAAAAAAAAAAAAAAAA------- -------AAAAAAAAAAAAAAAAA------- ------AAAAAAAAAAAAAAAAAAA------ ------AAAAAAAAAAAAAAAAAAA------ ------AAAAAAAAAAAAAAAAAAA------ -----AAAAAAAAAAAAAAAAAAAAA----- -----AAAAAAAAAAAAAAAAAAAAA----- ------AAAAAAAAAAAAAAAAAAA------ -------AAAAAAAAAAAAAAAAA------- ----------AAAAAAAAAAA---------- ------------------------------- ------------------------------- ------------------------------- ------------------------------- 
--------A-------------A-------- --------A-------------A-------- --------A-------------A-------- --------A-------------A-------- --------A-------------A-------- --------A-------------A-------- --------A-------------A-------- --------A-------------A-------- --------A-------------A-------- --------A-------------A-------- --------A-------------A-------- --------A-------------A-------- --------A-------------A-------- --------A-------------A-------- --------A-------------A-------- --------A-------------A-------- -------A---------------A------- -------A---------------A------- ------AA---------------AA------ ------AA---------------AA------ -----AAA---------------AAA----- ----AAAA---------------AAAA---- ----AAAA---------------AAAA---- ----AAAAA-------------AAAAA---- ------AAAA-----------AAAAA----- ------AAAAAA-------AAAAAA------ -------AAAAAAAAAAAAAAAAA------- ---------AAAAAAAAAAAAA--------- -----------AAAAAAAAA----------- ------------------------------- ------------------------------- 
-------A---------------A------- -------A---------------A------- -------A---------------A------- -------A---------------A------- -------A---------------A------- -------A---------------A------- -------A---------------A------- -------A---------------A------- -------A---------------A------- -------A---------------A------- -------A---------------A------- -------A---------------A------- -------A---------------A------- -------A---------------A------- -------A---------------A------- -------A---------------A------- -------A---------------A------- ------A-----------------A------ ------A-----------------A------ -----AA-----------------AA----- -----AA-----------------AA----- -----AA-----------------AA----- ---AAA-------------------AAA--- --A-AAA-----------------AAAAA-- -----AAA---------------AAAA---- -----AAAA-------------AAAA----- ------AAAAAAAAAAAAAAAAAAA------ -------AAAAAAAAAAAAAAAAA------- ---------AAAAAAAAAAAAA--------- ------------AAAAAAA------------ ------------------------------- 
-------A---------------A------- -------A---------------A------- -------A---------------A------- -------A---------------A------- -------A---------------A------- -------A---------------A------- -------A---------------A------- -------A---------------A------- -------A---------------A------- -------A---------------A------- -------A---------------A------- -------A---------------A------- -------A---------------A------- -------A---------------A------- -------A---------------A------- -------A---------------A------- ------A-----------------A------ ------A-----------------A------ -----AA-----------------AA----- -----AA-----------------AA----- ------------------------------- ------------------------------- --AA-----------------------AA-- --AAA---------------------AAA-- -AAAA---------------------AAAA- -----A-------------------AAA--- ----AAAA---------------AAAA---- -----AAAAAA---------AAAAAA----- -------AAAAAA-----AAAAAA------- ---------AAAA-----AAAA--------- ------------AAAAAAA------------ 
------A-----------------A------ ------A-----------------A------ ------A-----------------A------ ------A-----------------A------ ------A-----------------A------ ------A-----------------A------ ------A-----------------A------ ------A-----------------A------ ------A-----------------A------ ------A-----------------A------ ------A-----------------A------ ------A-----------------A------ ------A-----------------A------ ------A-----------------A------ ------A-----------------A------ ------A-----------------A------ ------A-----------------A------ -----AA-----------------AA----- ------------------------------- ------------------------------- ------------------------------- ------------------------------- ------------------------------- ------------------------------- -AAA-----------------------AAA- AAAAA---------------------AAAAA --AAA---------------------AAA-- ----AAAAA-------------AAAAA---- -----AAAAA-----------AAAAA----- --------AA-----------AA-------- ----------AAA-----AAA---------- 
------A-----------------A------ ------A-----------------A------ ------A-----------------A------ ------A-----------------A------ ------A-----------------A------ ------A-----------------A------ ------A-----------------A------ ------A-----------------A------ ------A-----------------A------ ------A-----------------A------ ------A-----------------A------ ------A-----------------A------ ------A-----------------A------ ------A-----------------A------ ------A-----------------A------ ------A-----------------A------ -----AA-----------------AA----- ------------------------------- ------------------------------- ------------------------------- ------------------------------- ------------------------------- ------------------------------- ------------------------------- -AAA-----------------------AAA- AAAAA---------------------AAAAA -AAAA---------------------AAAA- ---AAA-------------------AAA--- ----AAAAAA-----------AAAAAA---- ------AAAA-----------AAAA------ ----------A---------A---------- 
------A-----------------A------ ------A-----------------A------ ------A-----------------A------ ------A-----------------A------ ------A-----------------A------ ------A-----------------A------ ------A-----------------A------ ------A-----------------A------ ------A-----------------A------ ------A-----------------A------ ------A-----------------A------ ------A-----------------A------ ------A-----------------A------ ------A-----------------A------ ------A-----------------A------ ------A-----------------A------ -----AA-----------------AA----- ------------------------------- ------------------------------- ------------------------------- ------------------------------- ------------------------------- ------------------------------- ------------------------------- -AAA-----------------------AAA- ADAAA---------------------ADDDA -AAAA---------------------AAAA- ---AAA-------------------AAA--- ----AAAAAA-----------AAAAAA---- ------AAAA-----------AAAA------ ----------A---------A---------- 
------A-----------------A------ ------A-----------------A------ ------A-----------------A------ ------A-----------------A------ ------A-----------------A------ ------A-----------------A------ ------A-----------------A------ ------A-----------------A------ ------A-----------------A------ ------A-----------------A------ ------A-----------------A------ ------A-----------------A------ ------A-----------------A------ ------A-----------------A------ ------A-----------------A------ ------A-----------------A------ ------A-----------------A------ -----AA-----------------AA----- ------------------------------- ------------------------------- ------------------------------- ------------------------------- ------------------------------- ------------------------------- -AAA-----------------------AAA- AAAAA---------------------AAAAA --AAA---------------------AAA-- ----AAAAA-------------AAAAA---- -----AAAAA-----------AAAAA----- --------AA-----------AA-------- ----------AAA-----AAA---------- 
-------A---------------A------- -------A---------------A------- -------A---------------A------- -------A---------------A------- -------A---------------A------- -------A---------------A------- -------A---------------A------- -------A---------------A------- -------A---------------A------- -------A---------------A------- -------A---------------A------- -------A---------------A------- -------A---------------A------- -------A---------------A------- -------A---------------A------- -------A---------------A------- ------A-----------------A------ ------A-----------------A------ -----AA-----------------AA----- -----AA-----------------AA----- ------------------------------- ------------------------------- --AA-----------------------AA-- --AAA---------------------AAA-- -AAAAA-------------------AAAAA- ---AAAAAA-------------AAAAAA--- ----AAAAAA-----------AAAAAA---- -----AAAAA-----------AAAAA----- -------AAAAA-------AAAAA------- ---------AAA-------AAA--------- ------------A-----A------------ 
--------A-------------A-------- --------A-------------A-------- --------A-------------A-------- --------A-------------A-------- --------A-------------A-------- --------A-------------A-------- --------A-------------A-------- --------A-------------A-------- --------A-------------A-------- --------A-------------A-------- --------A-------------A-------- --------A-------------A-------- --------A-------------A-------- --------A-------------A-------- --------A-------------A-------- -------A---------------A------- -------A---------------A------- ------A-----------------A------ ------A-----------------A------ -----AA-----------------AA----- -----AA-----------------AA----- -----AA-----------------AA----- ---AAAA-----------------AAAA--- --AAAAA-----------------AAAAA-- ----AAAA---------------AAAA---- -----AAAAA-----------AAAAA----- ------AAAA-----------AAAA------ -------AAAAAAAAAAAAAAAAA------- ---------AAAAAAAAAAAAA--------- ------------AAAAAAA------------ ------------------------------- 
---------A-----------A--------- ---------A-----------A--------- ---------A-----------A--------- ---------A-----------A--------- ---------A-----------A--------- ---------A-----------A--------- ---------A-----------A--------- ---------A-----------A--------- ---------A-----------A--------- ---------A-----------A--------- ---------A-----------A--------- ---------A-----------A--------- ---------A-----------A--------- ---------A-----------A--------- --------AA-----------AA-------- --------A-------------A-------- --------A-------------A-------- -------A---------------A------- ------AA---------------AA------ ------AA---------------AA------ -----AAA---------------AAA----- ----AAAA---------------AAAA---- ----AAAA---------------AAAA---- ----AAAA---------------AAAA---- -----AAAA-------------AAAA----- ------AAAAA---------AAAAA------ -------AAAAAAAAAAAAAAAAA------- ---------AAAAAAAAAAAAA--------- ------------AAAAAAA------------ ------------------------------- ------------------------------- 
----------AAAAAAAAAAA---------- ----------AAAAAAAAAAA---------- ----------AAAAAAAAAAA---------- ----------AAAAAAAAAAA---------- ----------AAAAAAAAAAA---------- ----------AAAAAAAAAAA---------- ----------AAAAAAAAAAA---------- ----------AAAAAAAAAAA---------- ----------AAAAAAAAAAA---------- ----------AAAAAAAAAAA---------- ----------AAACAAACCAA---------- ----------AACACAAAACA---------- ----------ACAAACAAACA---------- ---------AACAAACAAACAA--------- ---------AACAAACACCAAA--------- ---------AAAAAAAAAAAAA--------- --------AAAAAAAAAAAAAAA-------- --------AAAAABAAAACCCAA-------- -------AAAAABBBAAAACAAAA------- -------AAAABBBBBAAACAAAA------- ------AAAABBBBBBBAACAAAAA------ ------AAAABBBBBBBAACAAAAA------ -----AAAAAABBABBAACCCAAAAA----- -----AAAAAAAAAAAAAAAAAAAAA----- ------AAAAAAAAAAAAAAAAAAA------ -------AAAAAAAAAAAAAAAAA------- ----------AAAAAAAAAAA---------- ------------------------------- ------------------------------- ------------------------------- ------------------------------- 
