model
size = 21 30 30, scale = 0.05, origin = -y
material 
  colors = A:#555 B:#C30 C:#FF0 D:#E00 E:#00E F:#60F G:#EEE H:#0E0 I:#90F J:#111
voxels
--------------------- --------------------- --------------------- --------------------- --------------------- --------------------- --------------------- --------------------- --------------------- --------------------- --------------------- --------------------- --------------------- --------------------- --------------------- --------------------- --------------------- --------------------- --------------------- --------------------- --------------------- --------------------- --------------------- --------------------- ---------BB---------- --------------------- --------------------- --------------------- --------------------- --------------------- 
--------------------- --------------------- --------------------- --------------------- --------------------- --------------------- --------------------- --------------------- --------------------- --------------------- --------------------- --------------------- --------------------- --------------------- --------------------- --------------------- --------------------- --------------------- --------------------- --------------------- --------------------- --------------------- --------------------- --------------------- ---------BB---------- --------------------- --------------------- --------------------- --------------------- --------------------- 
--------------------- --------------------- --------------------- --------------------- --------------------- --------------------- --------------------- --------------------- --------------------- --------------------- --------------------- --------------------- --------------------- --------------------- --------------------- --------------------- --------------------- --------------------- --------------------- --------------------- --------------------- --------------------- --------------------- ---------BB---------- ---------BB---------- --------------------- --------------------- --------------------- --------------------- --------------------- 
--------------------- --------------------- --------------------- --------------------- --------------------- --------------------- --------------------- --------------------- --------------------- --------------------- --------------------- --------------------- --------------------- --------------------- --------------------- --------------------- --------------------- --------------------- --------------------- --------------------- --------------------- --------------------- --------------------- ---------BB---------- --------BBBB--------- ---------BB---------- --------------------- --------------------- --------------------- --------------------- 
--------------------- --------------------- --------------------- --------------------- --------------------- --------------------- --------------------- --------------------- ------AAAAAAAA------- ------AAAAAAAA------- ------AAAAAAAA------- ------AAAAAAAA------- -------AAAAAA-------- --------------------- --------------------- --------------------- --------------------- --------------------- --------------------- --------------------- --------------------- --------------------- --------------------- ---------BB---------- --------BBBB--------- --------BBBB--------- --------------------- --------------------- --------------------- --------------------- 
--------------------- --------------------- --------------------- --------------------- --------------------- --------------------- --------------------- -------AAAAAA-------- ----AAAAAAAAAAAA----- ----AAAAAAAAAAAA----- ----AAAAAAAAAAAA----- ----AAAAAAAAAAAA----- -----AAAAAAAAAA------ -------AAAAAA-------- --------------------- --------------------- --------------------- --------------------- --------------------- --------------------- --------------------- --------------------- --------------------- ---------AA---------- --------BAAB--------- --------BAAB--------- -------J----J-------- --------------------- --------------------- --------------------- 
-BBBBBB------BBBBBB-- --------------------- --------------------- --------------------- --------------------- --------------------- -------AAAAAA-------- -----AAAAAAAAAA------ ---AAAAAAAAAAAAAA---- ---AAAAAAAAAAAAAA---- ---AAAAAAAAAAAAAA---- ---AAAAAAAAAAAAAA---- ----AAAAAAAAAAAA----- -----AAAAAAAAAA------ -------AAAAAA-------- -------AAAAAA-------- --------AAAA--------- --------------------- --------------------- --------------------- --------------------- --------------------- --------------------- --------AAAA--------- --------AAAA--------- ------GGAAAAGG------- ------GGGAAGGG------- ------GGGAAGGG------- --------------------- --------------------- 
BBBBBBBB----BBBBBBBB- --------------------- --------------------- --------------------- --------------------- -------AAAAAA-------- -----AAAAAAAAAA------ ---AAAAAAAAAAAAAA---- --AAAAAAAAAAAAAAAA--- --AAAAAAAAAAAAAAAA--- --AAAAAAAAAAAAAAAA--- --AAAAAAAAAAAAAAAA--- ---AAAAAAAAAAAAAA---- ----AAAAAAAAAAAA----- ------AAAAAAAA------- -------AAAAAA-------- -------AAAAAA-------- -------AAAAAA-------- --------AAAA--------- --------AAAA--------- ---------AA---------- ---------AA---------- ---------AA---------- --------AAAA--------- --------AAAA--------- ------GGAAAAGG------- ------GGGAAGGG------- ------GGGAAGGG------- ---------AA---------- --------------------- 
BBBBBBBB----BBBBBBBB- --------------------- --------------------- --------------------- -------AAAAAA-------- -----AAAAAAAAAA------ ----AAAAAAAAAAAA----- ---AAAAAAAAAAAAAA---- -AAAAAAAAAAAAAAAAAA-- -AAAAAAAAAAAAAAAAAA-- -AAAAAAAAAAAAAAAAAA-- -AAAAAAAAAAAAAAAAAA-- ---AAAAAAAAAAAAAA---- ----AAAAAAAAAAAA----- -----AAAAAAAAAA------ ------AAAAAAAA------- -------AAAAAA-------- -------AAAAAA-------- --------AAAA--------- --------AAAA--------- ---------AA---------- ---------AA---------- ---------AA---------- --------AAAA--------- --------AAAA--------- --------AAAA--------- --------AAAA--------- --------AAAA--------- ---------AA---------- --------------------- 
BBBBBBBB----BBBBBBBB- --------------------- --------------------- --------------------- ------AAAAAAAA------- ----AAAAAAAAAAAA----- ---AAAAAAAAAAAAAA---- --AAAAAAAAAAAAAAAA--- -AAAAAAAAAAAAAAAAAA-- -AAAAAAAAAAAAAAAAAA-- -AAAAAAAAAAAAAAAAAA-- -AAAAAAAAAAAAAAAAAA-- --AAAAAAAAAAAAAAAA--- ---AAAAAAAAAAAAAA---- ----AAAAAAAAAAAA----- ------AAAAAAAA------- -------AAAAAA-------- --------AAAA--------- --------AAAA--------- ---------AA---------- --------------------- --------------------- --------------------- ---------AA---------- ---------AA---------- ---------AA---------- ---------AA---------- ---------AA---------- ---------AA---------- --------------------- 
-BBBBBB------BBBBBB-- --------------------- --------------------- --------------------- -----AAAAAAAAAA------ ----AAAAAAAAAAAA----- ---AAAAAAAAAAAAAA---- --AAAAAAAAAAAAAAAA--- AAAAAAAAAAAAAAAAAAAA- AAAAAAAAAAAAAAAAAAAA- AAAAAAAAAAAAAAAAAAAA- AAAAAAAAAAAAAAAAAAAA- --AAAAAAAAAAAAAAAA--- ---AAAAAAAAAAAAAA---- ----AAAAAAAAAAAA----- ------AAAAAAAA------- --------AAAA--------- --------------------- --------------------- --------------------- --------------------- --------------------- --------------------- --------------------- ---------AA---------- ---------AA---------- ---------AA---------- ---------AA---------- --------------------- --------------------- 
-BBBBBB------BBBBBB-- --------------------- --------------------- --------------------- ----AAAAAAAAAAAA----- ---AAAAAAAAAAAAAA---- --AAAAAAAAAAAAAAAA--- -AAAAAAAAAAAAAAAAAA-- AAAAAAAAAAAAAAAAAAAA- AAAAAAAAAAAAAAAAAAAA- AAAAAAAAAAAAAAAAAAAA- AAAAAAAAAAAAAAAAAAAA- --AAAAAAAAAAAAAAAA--- ---AAAAAAAAAAAAAA---- ----AAAAAAAAAAAA----- -------AAAAAA-------- --------------------- --------------------- --------------------- --------------------- --------------------- --------------------- --------------------- --------------------- --------------------- --------------------- --------------------- --------------------- --------------------- --------------------- 
--BBBB--------BBBB--- --------------------- --------------------- --------------------- ----AAAAAAAAAAAA----- ---AAAAAAAAAAAAAA---- --AAAAAAAAAAAAAAAA--- -AAAAAAAAAAAAAAAAAA-- AAAAAAAAAAAAAAAAAAAA- AAAAAAAAAAAAAAAAAAAA- AAAAAAAAAAAAAAAAAAAA- AAAAAAAAAAAAAAAAAAAA- --AAAAAAAAAAAAAAAA--- ---AAAAAAAAAAAAAA---- ----AAAAAAAAAAAA----- --------AAAA--------- --------------------- --------------------- --------------------- --------------------- --------------------- --------------------- --------------------- --------------------- --------------------- --------------------- --------------------- --------------------- --------------------- --------------------- 
--BBBB---AA---BBBB--- ---BB----AA----BB---- ---BB----AA----BB---- ---BB----AA----BB---- ----AAAAAAAAAAAA----- ---AAAAAAAAAAAAAA---- --AAAAAAAAAAAAAAAA--- -AAAAAAAAAAAAAAAAAA-- AAAAAAAAAAAAAAAAAAAA- AAAAAAAAAAAAAAAAAAAA- AAAAAAAAAAAAAAAAAAAA- AAAAAAAAAAAAAAAAAAAA- --AAAAAAAAAAAAAAAA--- ---AAAAAAAAAAAAAA---- ----AAAAAAAAAAAA----- --------------------- --------------------- --------------------- --------------------- --------------------- --------------------- --------------------- --------------------- --------------------- --------------------- --------------------- --------------------- --------------------- --------------------- --------------------- 
--BBBB---AA---BBBB--- ---BB----AA----BB---- ---BB----AA----BB---- ---BB----AA----BB---- ----AAAAAAAAAAAA----- ---AAAAAAAAAAAAAA---- --AAAAAAAAAAAAAAAA--- -AAAAAAAAAAAAAAAAAA-- AAAAAAAAAAAAAAAAAAAA- AAAAAAAAAAAAAAAAAAAA- AAAAAAAAAAAAAAAAAAAA- AAAAAAAAAAAAAAAAAAAA- ---AAAAAAAAAAAAAACC-- ----AAAAAAAAAAAA-CC-- -----AAAAAAAAAA------ --------------------- --------------------- --------------------- --------------------- --------------------- --------------------- --------------------- --------------------- --------------------- --------------------- --------------------- --------------------- --------------------- --------------------- --------------------- 
---BB----------BB---- --------------------- --------------------- --------------------- ----AAAAAAAAAAAA----- ---AAAAAAAAAAAAAA---- --AAAAAAAAAAAAAAAA--- -AAAAAAAAAAAAAAAAAA-- AAAAAAAAAAAAAAAAAAAA- AAAAAAAAAAAAAAAAAAAA- AAAAAAAAAAAAAAAAAAAA- AAAAAAAAAAAAAAAAAAAA- ---AAAAAAAAAAAAAACC-- ----AAAAAAAAAAAA-CC-- ------AAAAAAAFF------ -------------FF------ --------------------- --------------------- --------------------- --------------------- ----CC--------------- ----CC--------------- --------------------- -----------EE-------- -----------EE-------- --------------------- --------------------- --------------------- --------------------- --------------------- 
---BB----------BB---- --------------------- --------------------- --------------------- -----AAAAAAAAAA------ ----AAAAAAAAAAAA----- ---AAAAAAAAAAAAAA---- --AAAAAAAAAAAAAAAA--- AAAAAAAAAAAAAAAAAAAA- AAAAAAAAAAAAAAAAAAAA- AAAAAAAAAAAAAAAAAAAA- AAAAAAAAAAAAAAAAAAAA- ----AAAAAAAAAAAA----- -----AAAAAAAAAA------ -------AAAAAAFF------ -------------FF------ --------------------- ----------------DD--- ----------------DD--- --------------------- ----CC--------------- ----CC--------------- --------------------- -----------EE-------- -----------EE-------- --------------------- --------------------- --------------------- --------------------- --------------------- 
--------------------- --------------------- --------------------- --------------------- ------AAAAAAAA------- ----AAAAAAAAAAAA----- ---AAAAAAAAAAAAAA---- --AAAAAAAAAAAAAAAA--- -AAAAAAAAAAAAAAAAAA-- -AAAAAAAAAAAAAAAAAA-- -AAAAAAAAAAAAAAAAAA-- -AAAAAAAAAAAAAAAAAAEE -----AAAAAAAAAA----EE -------AAAAAA-------- --------------------- FF------------------- FF------------------- ----------------DD--- ----------------DD--- --------------------- --------------------- --------------------- --------------------- --------------------- --------------------- --------------------- --------------------- --------------------- --------------------- --------------------- 
--------------------- --------------------- --------------------- --------------------- -------AAAAAA-------- -----AAAAAAAAAA------ ----AAAAAAAAAAAA----- ---AAAAAAAAAAAAAA---- -AAAAAAAAAAAAAAAAAA-- -AAAAAAAAAAAAAAAAAA-- -AAAAAAAAAAAAAAAAAA-- -AAAAAAAAAAAAAAAAAAEE -------AAAAAA------EE --------------------- --------------------- FF------------------- FF------------------- --------------------- --------------------- ---EE---------------- ---EE---------------- --------------------- --------------------- --------------------- --------------------- --------------------- --------------------- --------------------- --------------------- --------------------- 
--------------------- --------------------- --------------------- --------------------- --------------------- -------AAAAAA-------- -----AAAAAAAAAA------ ---AAAAAAAAAAAAAA---- --AAAAAAAAAAAAAAAA--- --AAAAAAAAAAAAAAAA--- --AAAAAAAAAAAAAAAA--- --AAAAAAAAAAAAAAAA--- --------------------- --------------------- --------------------- --------------------- --------------------- --------------------- --------------------- ---EE---------------- ---EE----FF------EE-- ---------FF------EE-- --------------------- --------------------- --------------------- --------------------- --------------------- --------------------- --------------------- --------------------- 
--------------------- --------------------- --------------------- --------------------- --------------------- --------------------- -------AAAAAA-------- -----AAAAAAAAAA------ ---AAAAAAAAAAAAAA---- ---AAAAAAAAAAAAAA---- ---AAAAAAAAAAAAAA---- ---AAAAAAAAAAAAAA---- --DD----------------- --DD----------------- --------------------- --------------------- --------------------- --------------------- --------------------- --------------------- ---------FF------EE-- ---------FF------EE-- --HH----------------- --HH----------------- --------------------- --------------------- --------------------- --------------------- --------------------- --------------------- 
--------------------- --------------------- --------------------- --------------------- --------------------- --------------------- --------------------- -------AAAAAA-------- ----AAAAAAAAAAAAF---- ----AAAAAAAAAAAAF---- ----AAAAAAAAAAAA----- ----AAAAAAAAAAAA----- --DD---FF------------ --DD---FF------------ --------------------- --------------------- --------------------- --------------------- --------------------- --------------------- --------------------- --------------------- --HH---CC------------ --HH---CC------------ --------------------- --------------------- --------------------- ----------II--------- ----------II--------- --------------------- 
--------------------- --------------------- --------------------- --------------------- --------------------- --------------------- --------------------- --------------------- ------AAAAAAAA-FF---- ------AAAAAAAA-FF---- ------AAAAAAAA------- ------AAAAAAAA------- -------FF------------ -------FF------------ --------------CC----- --------------CC----- --------------------- ----------DD--------- ----------DD--------- --------------------- --------------------- --------------------- -------CC-----HH----- -------CC-----HH----- --------------------- II------------------- II------------------- ----------II--------- ----------II--------- --------------------- 
--------------------- --------------------- --------------------- --------------------- --------------------- --------------------- --------------------- --------------------- --------------------- --------------------- --------------------- --------------------- --------------------- -CC------------------ -CC-----------CC----- --------------CC----- --------------------- ----------DD--------- ----------DD--------- --------------------- --------------------- --------------------- --------------HH----- --------------HH----- --------------------- II------------------- II------------------- --------------------- --------------------- --------------------- 
--------------------- --------------------- --------------------- --------------------- --------------------- --------------------- --------------------- --------------------- --------------------- --------------------- --------------------- --------------------- --------------------- -CC------------------ -CC------------------ --------------------- --------------------- --------------------- --------------------- --------------------- --------------------- --EE----------------- --EE-DD-------------- -----DD-------------- --------------------- --------------------- --------------------- --------------------- --------------DD----- --------------DD----- 
--------------------- --------------------- --------------------- --------------------- --------------------- --------------------- --------------------- --------------------- --------------------- --------------------- --------------------- --------------------- --------------------- --------------------- --------------------- --------------------- ----II--------------- ----II--------------- --------------------- --------------------- --------------------- --EE----------------- --EE-DD------CC------ -----DD------CC------ --------------------- --------------------- --------------------- --------------------- --------------DD----- --------------DD----- 
--------------------- --------------------- --------------------- --------------------- --------------------- --------------------- --------------------- --------------------- --------------------- --------------------- --------------------- --------------------- --------------------- --------------------- --------------------- --------------------- ----II--------------- ----II--------------- --------------------- --------------------- --------------------- --------------------- -------------CC------ -------------CC------ --------------------- --------------------- --------------------- --------------------- --------------------- --------------------- 
--------------------- --------------------- --------------------- --------------------- --------------------- --------------------- --------------------- --------------------- --------------------- --------------------- --------------------- --------------------- --------------------- --------------------- --------------------- --------------------- --------------------- --------------------- --------------------- --------------------- --------------------- --------------------- --------------------- --------------------- --------------------- --------------------- --------------------- --------------------- --------------------- --------------------- 
--------------------- --------------------- --------------------- --------------------- --------------------- --------------------- --------------------- --------------------- --------------------- --------------------- --------------------- --------------------- ------------HH------- ------------HH------- -----DD-------------- -----DD-------------- --------------------- --------------------- --------------------- ----------HH--------- ----------HH--------- --------------------- --------------------- ----------II--------- ----CC----II--------- ----CC--------------- --------------------- --------------------- --------------------- --------------------- 
--------------------- --------------------- --------------------- --------------------- --------------------- --------------------- --------------------- --------------------- --------------------- --------------------- --------------------- --------------------- ------------HH------- ------------HH------- -----DD-------------- -----DD-------------- --------------------- --------------------- --------------------- ----------HH--------- ----------HH--------- --------------------- --------------------- ----------II--------- ----CC----II--------- ----CC--------------- --------------------- --------------------- --------------------- --------------------- 
