model
size = 15 24 16, scale = 0.05, origin = -y
material 
  colors = A:#FFF B:#3F0 C:#001 D:#100
voxels
--------------- --------------- --------------- --------------- --------------- --------------- --------------- --------------- --------------- --------------- --------------- --------------- --------------- --------------- --------------- -----A---A----- -----AAAAA----- ----AAAAAAA---- ----AAAAAAA---- -----AAAAA----- ------A-A------ --------------- --------------- --------------- 
--------------- --------------- --------------- --------------- --------------- --------------- --------------- --------------- --------------- --------------- --------------- --------------- --------------- --------------- -----AAAAA----- -----AA-AA----- ----AAAAAAAA--- ---A-AAAAA-A--- ---A--AAA--A--- ---AA-AAA-AA--- ----AA-A-AA---- -----AAAAA----- --------------- --------------- 
--------------- --------------- --------------- --------------- --------------- --------------- --------------- --------------- --------------- --------------- --------------- --------------- --------------- -----AAAAA----- ----A--A--A---- ---AAAA-AAAA--- ---AA-----AA--- --A-A-----A-A-- ---AAA---AAA--- ---A-A---A-A--- ---A--AAA--A--- ----A-----A---- -----AAAAA----- --------------- 
--------------- --------------- --------------- --------------- --------------- --------------- --------------- --------------- --------------- --------------- --------------- --------------- ------AAA------ ----AA---AA---- ---A--AAA--A--- ---A-A---A-A--- --A-A-----A-A-- --A-A-----A-A-- --AA-------AA-- --A-A-----A-A-- ---A-A---A-A--- ----A-AAA-A---- -----AA-AA----- -------A------- 
--------------- --------------- --------------- --------------- --------------- --------------- --------------- --------------- --------------- --------------- --------------- --------------- -----AAAAA----- ---AA-AAA-AA--- ---A-A---A-A--- ---AA-----AA--- --AA-------AA-- --AA-------AA-- --AA-------AA-- --AA-------AA-- ---AA-----AA--- ---A-A---A-A--- ----A-AAA-A---- -----AAAAA----- 
--------------- --------------- --------------- --------------- --------------- --------------- --------------- --------------- --------------- --------------- --BB-------BB-- --BB-------BB-- ---AAAA-AAAA--- ---A-AA-AA-A--- ---AA-----AA--- --A-A-----A-A-- --AA-------AA-- --AA-------AA-- --AA-------AA-- --AA-------AA-- --A-A-----A-A-- ---A-A---A-A--- ---AA-AAA-AA--- -----AA-AA----- 
----BBBBBBB---- ---BBBBBBBBB--- --BBB-----BBB-- -BBB-------BBB- BBB---------BBB BBB---------BBB -B-----------B- -BB---------BB- BBB---------BBB BBBB--------BBB -B-B-------B-B- --B-BB---BB-B-- ---A--AAA--A--- ---A-AAAAA-A--- ---AA-----AA--- ---AA-----AA--- ---AA-----AA--- --AA-------AA-- --AA-------AA-- --AA-------AA-- --A-A-----A-A-- ---AA-----AA--- ---A-A---A-A--- ----AAAAAAA---- 
----BBBBBBB---- --BB-BBBBB-BB-- -B--B-----B--B- -B-B-------B-B- B-B---------B-B B-B---------B-B BB-----------BB B-B---------B-B B-B---------B-B B--B--------B-B -B-B-------B-B- --B-BB---BB-B-- --B---AAA---B-- ---A-AAAAA-A--- ---AA-----AA--- ---AA-----AA--- ---AA-----AA--- ---AA-----AA--- ---AA-----AA--- ---AA-----AA--- ---AA-----AA--- ---AA-----AA--- ---A-AAAAA-A--- ----AAAAAAA---- 
----BBBBBBBB--- --BB-BBBBB--B-- -B--B-----B--B- -B-B-------B-B- B-B---------B-B B-B---------B-B BB-----------BB B-B---------B-B B-B---------B-B B--B--------B-B -B-B-------B-B- -B--BB---BB--B- --B---AAA---B-- ---A--AAA--A--- ---A-A---A-A--- ---AA-----AA--- ---AA-----AA--- ---AA-----AA--- ---AA-----AA--- ---AA-----AA--- ---AA-----AA--- ---AA-----AA--- ---AAAAAAAAA--- -----AAAAA----- 
----BBBBBBB---- ---BBBBBBBBB--- --BBB-----BBB-- -BBB-------BBB- BBB---------BBB BBB---------BBB -B-----------B- BBB---------BBB BBB---------BBB -BBB--------BBB -BBB-------BBB- --BBBB---BBBB-- ---B--AAA--B--- ----A-----A---- ---A-AAAAA-A--- ---AA-----AA--- ---AA-----AA--- ---AA-----AA--- ---AA-----AA--- ---AA-----AA--- ---AA-----AA--- ---A-A---A-A--- ----A-AAA-A---- -----AAAAA----- 
--------------- --------------- --------------- --------------- --------------- --------------- --------------- --------------- --------------- --------------- --------------- ----B-----B---- ----AA---AA---- ---A--AAA--A--- ---A--AAA--A--- ---A-A---A-A--- ---AA-----AA--- ---AA-----AA--- ---A-A---A-A--- ---A-A---A-A--- ---A-AAAAA-A--- ----A-AAA-A---- ----AAAAAAA---- --------------- 
--------------- --------------- --------------- --------------- --------------- --------------- --------------- --------------- --------------- --------------- --------------- ----B-----B---- ----AAA-AAA---- ----A--A--A---- ----A-AAA-A---- ----AA---AA---- ---A-A---A-A--- ---A-A---A-A--- ---A--AAA--A--- ----CCAAACC---- ----CC---CC---- -----AAAAA----- ------AAA------ --------------- 
--------------- --------------- --------------- --------------- --------------- --------------- --------------- --------------- --------------- --------------- --------------- --------------- ----AAA-AAA---- ----A--A--A---- ----A--A--A---- ----A-A-A-A---- ---AA-A-A-AA--- ----AAA-AAA---- ----AA-A-AA---- ------A-A------ ------AAA------ --------------- --------------- --------------- 
--------------- --------------- --------------- --------------- --------------- --------------- --------------- --------------- --------------- --------------- --------------- --------------- ----AAA-AAA---- ----A-A-A-A---- -----AA-AA----- -----AA-AA----- -----A-A-A----- ------AAA------ ------ACA------ ------ACA------ --------------- --------------- --------------- --------------- 
--------------- --------------- --------------- --------------- --------------- --------------- --------------- --------------- --------------- --------------- --------------- --------------- -----AA-AA----- -----D-A-D----- -----A-A-A----- -----A-A-A----- ------CCC------ ------CCC------ --------------- --------------- --------------- --------------- --------------- --------------- 
--------------- --------------- --------------- --------------- --------------- --------------- --------------- --------------- --------------- --------------- --------------- --------------- ------C-C------ -----CCCCC----- ------CAC------ ------AAA------ --------------- --------------- --------------- --------------- --------------- --------------- --------------- --------------- 
