model
size = 32 14 13, scale = 0.05, origin = -y
material 
  colors = A:#FFF B:#500 C:#00B D:#0F6 E:#070 F:#0F9 G:#C30 H:#111 I:#00D J:#00A
voxels
81-3AD6A21-B2AD8A19-ABAD6AD2A19-2A2B9A22-A2B2C2A253-3A29-3A21-B3A-5A-4A12-5A2B4-4A4-AE9-C5ABA2-3A4-3A-AE8-2AC4AB12A2-A10-AC3AB4AD7-3A16-B3AD3A3B2A22-D3A190-3A2-3A24-A-A4-A10-2ADAC9A3-9AE4-2AD2ACA8-10A3-A3-2AD5A5-2A10-2A-E3-AD11A11-2A-AE3-AD22A-2AE4-D5AC2AB8A3-4A7-6AC2AB2AD4-2ACB12-5ACAB3AD4A17-4ACAB2AD3A23-CBCA-DA2H28-A57-CA8-3A2-I2A13-DCA8-3A2-3A-2AE5-4A3-8A3-6A3-2A2-A3-5A7-12A-A2-A-CA5-7A12-2A2-A-FC23-A-A2-A-AC20-6A2-D2-AC14-8A5-D2-2AC5-8A2-A2B8-2A-3AC7A4-A2C12-2A-2AC5A4-2A15-2AF3ACB2-D3-A18-F6-CAD-JE27-DAE20-3A2-2A25-3A-3A17-3A4-2(A3-)BA2(B2A)2B7A3-2A-A2-F6A7-12A2-2A-C7-7A12-A-2A-A26-A-GA-A23-5AGA2-F18-6AE3-D2-A15-3A2-AB7-A-A11-4A2-AHE9-A2-F8-2A2-2AHE12-A2-F5-B2A3-A16-3A7-A3-JA26-D3A19-B2A29-A-A28-A3-4A3B4(AB)11A-A2-A2F4A7-12A2-2A-A7-7A12-A-2A-C27-3A-C24-3AG2A-A19-6AHE2-A-A16-3A-2AHE5-D-A13-3A2-2A9-A2-A9-3A2-JCA11-A2-A8-A4-J15-2AB7-A3-HJ26-D3A52-A28-3A-5A4(BA)B13A-A-4AF2A4-A3-12A2-3A7-8A12-A-3A28-4A26-3AEA-C20-5AGE2-A-A17-7A5-D-A14-3AJ2A9-A-A11-3A-AC12-A-A10-A3-A15-2A9-A2-AH27-3A81-9A4(BA)3B11A-A-7A3-2A3-12A2-3A7-8A12-5A29-E2A26-5A-C19-5AG2A2-A-A17-2A-3AG5-D-A13-5A2J9-A-A11-2A2-CH12-A-A9-2A3-C15-2A8-D3-2H26-4A19-3A2-3A7-2A15-3A-4A7-2A8-3A2-2A3-A4-7A2-8A3-A-A2-6A3-2A4-11A2-2A-A6-9A11-A-EA-A27-3A-A24-6A-A19-8A2-D-A16-3A2-2GH5-A2-C11-4A-2AHJ8-A2-C9-2A2-CAH12-D2-A6-CBA3-C16-3A7-B3-HA26-3AH19-ABA2-D2A7-3A2-3A9-ABA-D3A7-A-A2-I2A2-3A2(3-A)4-2(7A3-)A-A3-5A3-3A3-11A2-EA2-A5-9A11-A-2A2-A25-A-2A2-A22-3A-3A2-A16-6A-A2H2-D2-A6-10A2-2G3E6-D2-A4-6A4-2AG11-D2-2A-2AC3A4-2A14-D2-CA2(2-2A)2-C16-2AC6-BF2A2H27-F2A35-EA3-3A24-A2E4-A2-2A5-15A3-7A2-AE2-2A7-5A3-10A2-E2-A2-5A8-A10-A-2A-A2-13A9-3A-2A-A2-22A2-3A2-2A-7ACF7A4-A2JA5-CD-8ACAI3AGA2G2A10-DA-7AFI5AG14-CAB6A2IAC2A17-2CAB4AIF2-AC102-AIA29-I2A11-BADCA4-F10A-3AE6-ABADACA3-F4A4-2A4-JA4-2ABD3AC3AF3A-4A2-4AJA4-2ABD3AC3AFG11A2-JA4-2ADB4A2C2FGA2IA6-2A2JA5-ADB4A4-2I3G4A2E10-DAB4A26-AB3A234-EAI5A23-2AE7A21-A2IAE6A21-I4AE5A23-4AE2A230-
