model
size = 24 29 25, scale = 0.05, origin = -y
material 
  colors = A:#6B4897 B:#080A09 C:#000 D:#140E12 E:#FEEDE9 F:#FCE6E5 G:#7454A2 H:#F9E1E1 I:#8D6CB9 J:#161A18 K:#FFF L:#B775E1 M:#7F5FAC N:#B05F5F O:#281515 P:#363636 Q:#9D79C8 R:#494358 S:#FFED8D T:#302C2C U:#F2D9D9 V:#E4D9DD W:#90797F X:#ECA2A2 Y:#BD6E6E Z:#8E3939 Aa:#463752 Ab:#351818 Ac:#8C7373 Ad:#FBF6F6 Ae:#F1E9E9 Af:#251E1E Ag:#DA4E64 Ah:#E15A69 Ai:#CB4057 Aj:#7F0020 Ak:#600 Al:#F0D1C6 Am:#472D2D An:#EABDBA Ao:#B6A6A6 Ap:#300
voxels
- - - - - - - - - - - - - - - - - - - - - - - -   - - - - - - - - - - - - - - - - - - - - - - - -   - - - - - - - - - - - - - - - - - - - - - - - -   - - - - - - - - - - - - - - - - - - - - - - - -   - - - - - - - - - - - - - - - - - - - - - - - -   - - - - - - - - - - - - - - - - - - - - - - - -   - - - - - - - - - - - - - - - - - - - - - - - -   - - - - - - - - - - - - - - - - - - - - - - - -   - - - - - - - - - - - - - - - - - - - - - - - -   - - - - - - - - - - - - - - - - - - - - - - - -   - - - - - - - - - - - - - - - - - - - - - - - -   - - - - - - - - - - - - A A - - - - - - - - - -   - - - - - - - - - - - A A A - - - - - - - - - -   - - - - - - - - - - - A A A I A - - - - - - - -   - - - - - - - - - - A G A I A A A - - - - - - -   - - - - - - - - - - A A I A A A A - - - - - - -   - - - - - - - - - - G A A A A A G - - - - - - -   - - - - - - - - - - A A A A A G - - - - - - - -   - - - - - - - - - - A A A A G - - - - - - - - -   - - - - - - - - - - - - - - - - - - - - - - - -   - - - - - - - - - - - - - - - - - - - - - - - -   - - - - - - - - - - - - - - - - - - - - - - - -   - - - - - - - - - - - - - - - - - - - - - - - -   - - - - - - - - - - - - - - - - - - - - - - - -   - - - - - - - - - - - - - - - - - - - - - - - -   - - - - - - - - - - - - - - - - - - - - - - - -   - - - - - - - - - - - - - - - - - - - - - - - -   - - - - - - - - - - - - - - - - - - - - - - - -   - - - - - - - - - - - - - - - - - - - - - - - -   
- - - - - - - - - - - - - - - - - - - - - - - -   - - - - - - - - - - - - - - - - - - - - - - - -   - - - - - - - - - - - - - - - - - - - - - - - -   - - - - - - - - - - - - - - - - - - - - - - - -   - - - - - - - - - - - - - - - - - - - - - - - -   - - - - - - - - - - - - - - - - - - - - - - - -   - - - - - - - - - - - - - - - - - - - - - - - -   - - - - - - - - - - - - - - - - - - - - - - - -   - - - - - - - - - - - - - - - - - - - - - - - -   - - - - - - - - - - - - - A A - - - - - - - - -   - - - - - - - - - - - - A A A - - - - - - - - -   - - - - - - - - - - - A A A A - - - - - - - - -   - - - - - - - - - - I A A A A - I A - - - - - -   - - - - - - - - - M A A A A G I A A A - - - - -   - - - - - - - - - - A A A A I A A A G - - - - -   - - - - - - - - - A A A A I A A A G A - - - - -   - - - - - - - - - A A I A I A B A B - - - - - -   - - - - - - - - - G M A A A B C B B - - - - - -   - - - - - - - - - M A A A G A C B - - - - - - -   - - - - - - - - - A A A A A C C - - - - - - - -   - - - - - - - - - - - A A A - - - - - - - - - -   - - - - - - - - - - - - - - - - - - - - - - - -   - - - - - - - - - - - - - - - - - - - - - - - -   - - - - - - - - - - - - - - - - - - - - - - - -   - - - - - - - - - - - - - - - - - - - - - - - -   - - - - - - - - - - - - - - - - - - - - - - - -   - - - - - - - - - - - - - - - - - - - - - - - -   - - - - - - - - - - - - - - - - - - - - - - - -   - - - - - - - - - - - - - - - - - - - - - - - -   
- - - - - - - - - - - - - - - - - - - - - - - -   - - - - - - - - - - - - - - - - - - - - - - - -   - - - - - - - - - - - - - - - - - - - - - - - -   - - - - - - - - - - - - - - - - - - - - - - - -   - - - - - - - - - - - - - - - - - - - - - - - -   - - - - - - - - - - - - - - - - - - - - - - - -   - - - - - - - - - - - - - - - - - - - - - - - -   - - - - - - - - - - - - - - - - - - - - - - - -   - - - - - - - - - - - - F E - - - - - - - - - -   - - - - - - - - - - - - - A A - - - - - - - - -   - - - - - - - - - - - - A G A - - - - - - - - -   - - - - - - - - - - - I M A A - - I A - - - - -   - - - - - - - - - - G I A A A A A M A - - - - -   - - - - - - - - - A M - A A - I A A A G A - - -   - - - - - - - - A A I A - A A A A A A M B - - -   - - - - - - - - A A A A A A A A G C B B - - - -   - - - - - - - - I G A A A A A G B D D - - - - -   - - - - - - - - I A A A A A A B B B - - - - - -   - - - - - - - - - A A A A A C G C - - - - - - -   - - - - - - - - A A A A A B A C C - - - - - - -   - - - - - - - - - A A A A C B B - - - - - - - -   - - - - - - - - - - - A A B B - - - - - - - - -   - - - - - - - - - - - - - - - - - - - - - - - -   - - - - - - - - - - - - - - - - - - - - - - - -   - - - - - - - - - - - - - - - - - - - - - - - -   - - - - - - - - - - - - - - - - - - - - - - - -   - - - - - - - - - - - - - - - - - - - - - - - -   - - - - - - - - - - - - - - - - - - - - - - - -   - - - - - - - - - - - - - - - - - - - - - - - -   
- - - - - - - - - - - - - - - - - - - - - - - -   - - - - - - - - - - - - - - - - - - - - - - - -   - - - - - - - - - - - - - - - - - - - - - - - -   - - - - - - - - - - - - - - - - - - - - - - - -   - - - - - - - - - - - - - - - - - - - - - - - -   - - - - - - - - - - - - - - - - - - - - - - - -   - - - - - - - - - - - - E E - - - - - - - - - -   - - - - - - - - - - - - E E - - - - - - - - - -   - - - - - - - - - - - - E E - - - - - - - - - -   - - - - - - - - - - - - E E - - - - D - - - - -   - - - - - - - - - - - - - - - - - - D A - - - -   - - - - - - A - I - - - - - - - - - I A - - - -   - - - - - - A - I - - I - - - - - I A A A - - -   - - - - - - A G Q A I C E E - - A A I A A - - -   - - - - - - A G Q G I P E E P - - A B B B - - -   - - - - - - A G G A - F E E F P A A A B - - - -   - - - - - - A G G I - A A F F - A A A A - - - -   - - - - - - A M G I A A A F - A A A A A - - - -   - - - - - - - G I A A A A - G A A A A A - - - -   - - - - - - - - A A A A A G G A A A A - - - - -   - - - - - - - - G A A A A G B C - A - - - - - -   - - - - - - - - - A A A A B B B - - - - - - - -   - - - - - - - - - - - - - B B - - - - - - - - -   - - - - - - - - - - - - - - - - - - - - - - - -   - - - - - - - - - - - - - - - - - - - - - - - -   - - - - - - - - - - - - - - - - - - - - - - - -   - - - - - - - - - - - - - - - - - - - - - - - -   - - - - - - - - - - - - - - - - - - - - - - - -   - - - - - - - - - - - - - - - - - - - - - - - -   
- - - - - - - - - - - - - - - - - - - - - - - -   - - - - - - - - - - - - - - - - - - - - - - - -   - - - - - - - - - - - - - - - - - - - - - - - -   - - - - - - - - - - - - - - - - - - - - - - - -   - - - - - - - - - - - - - - - - - J - - - - - -   - - - - - - - - - - - - E E - - - D - - - - - -   - - - - - - - - - - E E E E E E - - D - - - - -   - - - - - - A - - E E E E E E E E - D - - - - -   - - - - - - A - - E E E E E E E E - J - - - - -   - - - - - - G - Q - E E E E E E - - D - - - - -   - - - - - - I C Q - - - E E - - - - D A - - - -   - - - - - A A C Q - D P E E T D - - B G - - - -   - - - - - A A C I D D C E E C J D D B C A - - -   - - - - - G B C I C ApC E E C AcC D C C A - - -   - - - - - G B B I E E AcE E W E E E C A G - - -   - - - - - G B B Q P E E F E E E P P C A G - - -   - - - - - A A A C F F F F F F F F A A G G - - -   - - - - - - A B G F F F F F F F F A C A A - - -   - - - - - - A A A A F F F F F H A C C A A - - -   - - - - - - A A G B H H H H H H A A A A - - - -   - - - - - - - A G C G A A G A A A A A - - - - -   - - - - - - - - A A A A A A A C A A - - - - - -   - - - - - - - - - A A A B B B - - - - - - - - -   - - - - - - - - - - - - - B - - - - - - - - - -   - - - - - - - - - - - - - - - - - - - - - - - -   - - - - - - - - - - - - - - - - - - - - - - - -   - - - - - - - - - - - - - - - - - - - - - - - -   - - - - - - - - - - - - - - - - - - - - - - - -   - - - - - - - - - - - - - - - - - - - - - - - -   
- - - - - - - - - - - - - - - - - - - - - - - -   - - - - - - - - - - - - - - - - - - - - - - - -   - - - - - - - - - - - - - - - - - - - - - - - -   - - - - - - - - - - - - - - - - - - - - - - - -   - - - - - - - - - - - E E E E - - J - - - - - -   - - - - - - - - - E E E E E E E E B D - - - - -   - - - - - - A C E E E E AdAeE E E - B - - - - -   - - - - - - A C E E E E N N E E E E B B - - - -   - - - - - - A C E E E E E - E E E E B B - - - -   - - - - - - A C Q U E E E E E E U AlB B B - - -   - - - - - A C C Q L L E E E E K K - - B B - - -   - - C B - A C C D L O E E E E O K D D B B A - -   - - - B B A G C D O E C E E V V O D B B B A - -   - - - B B A A C F F C C - - C C F F B B A G - -   - - - - B A A C F E E W - - W E E F C B B - - -   - - - - B A A B F E E - - - - E E F P B A - - -   - - - - - A A F F F F - - - - F F F F B A - - -   - - - - - A B F F F F F - - F F F F A A A - - -   - - - - - - B B H H H H F F H H F F C B A - - -   - - - - - - A B H H H H H H H H H B C A - - - -   - - - - - - A A G B H H H H H H C B A A - - - -   - - - - - - - A A A G A A A A A A A A - - - - -   - - - - - - - - - A A A A A C A A A - - - - - -   - - - - - - - - - - A A B B - A - - - - - - - -   - - - - - - - - - - - - - - - - - - - - - - - -   - - - - - - - - - - - - - - - - - - - - - - - -   - - - - - - - - - - - - - - - - - - - - - - - -   - - - - - - - - - - - - - - - - - - - - - - - -   - - - - - - - - - - - - - - - - - - - - - - - -   
- - - - - - - - - - - - - - - - - - - - - - - -   - - - - - - - - - - - - - - - - - - - - - - - -   - - - - - - - - - - - - - - - - - - - - - - - -   - - - - - - - - - - - - F F - - - - - - - - - -   - - - - - - - - C - E E F E E E - - B - - - - -   - - - - - - - C - E E E E E E E E - B - - - - -   - - - - - - - C E E S N X X N S E E D B - - - -   - - - - - - B C E E S N N N N S E E D B - - - -   - - - - - - B B C C C C - - C C C C AfB - - - -   - - - - - C C AmAnL L C - C C K K C AoB B - - -   - - - - - C C D L L L C - C C K K K D B B A A -   - - C C - C C D L L L C - C C K K K V B B M - -   - - - B C C C F L L L C - - C K K K F B B A - -   - - - B C C F F C C C C - - C C C C B F B A - -   - - - - B C F F C C - - - - - - C - B F A A - -   - - - - B C F C - - - - - - - - - - B F A - - -   - - - - B B F F - - - - - - - - - - B F A A - -   - - - A B B F F - - - - - - - - - - B F A A A -   - - - A A B B H H - - - - - - - - H H B A G A -   - - - - A A B H H H - - - - - - H H C A A A - -   - - - - - A A B B B B - - - - - B C A A A - - -   - - - - - G A A B A B - - - - B B A A A G - - -   - - - - - - A A A A A A A A A A A A A A - - - -   - - - - - - - - - A A A B B A A A A - - - - - -   - - - - - - - - - - - - - - - - - - - - - - - -   - - - - - - - - - - - - - - - - - - - - - - - -   - - - - - - - - - - - - - - - - - - - - - - - -   - - - - - - - - - - - - - - - - - - - - - - - -   - - - - - - - - - - - - - - - - - - - - - - - -   
- - - - - - - - - - - - - - - - - - - - - - - -   - - - - - - - - - - - - - - - - - - - - - - - -   - - - - - - - - - - - - - - - - - B - - - - - -   - - - - - - - - C - - - - - - - - B B - - - - -   - - - - - - - C C - E F H H F E - - B - - - - -   - - - - - - - B - E E E H H E E E E B - - - - -   - - - - - - B B E E S N Y Y N S E E B D - - - -   - - - - - - B D E C C C - - C C C - E D - - - -   - - - - - C B P C C AgAh- - Z AiC C T B - - - -   - - - - - C C E C C C C - - C C C C C D D - - -   - - - - - C C C C C C C - C C C C C C D D - - -   - - - - - C C C C C C C - C C C C C C D D J - -   - - - C C - C C C C C C - - C C C C C J D A - -   - - - C C - B C C C C - - - - C C C C F D A A -   - - - - C - C - C C - - - - - - C C D F B A A -   C C - - B C F - - - - - - - - - - - B F B A - -   C C B B B C F - - - - - - - - - - - B F B A - -   - - B D B C F - - - - - - - - - - - B H B A A -   - - - A D B H - - - - - - - - - - - B H B A A -   - - - - G B B H - - - - - - - - - - B B A G - -   - - - - - A B A C - - - - - - - - C B A A A - -   - - - - - A A B A B B - - - - B C C A A A - - -   - - - - - - A A A A B - A A - B A A A A - - - -   - - - - - - - A A A A A A A A A A A A - - - - -   - - - - - - - - - - - - B A A - - - - - - - - -   - - - - - - - - - - - - - - - - - - - - - - - -   - - - - - - - - - - - - - - - - - - - - - - - -   - - - - - - - - - - - - - - - - - - - - - - - -   - - - - - - - - - - - - - - - - - - - - - - - -   
- - - - - - - - - - - - - - - - - - - - - - - -   - - - - - - - - - - - - - - - - - - - - - - - -   - - - - - - - - C - - - - - - - - - - - - - - -   - - - - - - - C C - - - - - - - - B - - - - - -   - - - - - - - C C - F H H H H F - - C - - - - -   - - - - - - B B E E F H H H H F E E C B - - - -   - - - - - - B B E E - - - - - - E E C B - - - -   - - - - - - B A - C C - - - - C C - A B - - - -   - - - - - C B E - C Aj- - - - Z Ak- E B B - - -   - - - - - C C U R R C C - - C C AaR U A B - - -   - - - - - C A - K K R - - - - AaK K - A D D - -   - - - - C B A C K K R - - - - R K K C A - D - -   - - - - B B G C R K C - - - - C K R C F A D A A   - - - - C B B - C C C - - - - C C C C B A B A -   - - - - C A B - - - - - - - - - - - - B A B A -   C C C - B B F B - - - - - - - - - - - F B B A -   C C C B C B F - - - - - - - - - - - - B B A - -   - C B B B B B - - - - - - - - - - - - C C A - -   - - - B B C B B - - - - - - - - - - - C C A - -   - - - B B B C B - - - - - - - - - - - C A - - -   - - - - D B C C C - - - - - - - - B B B A - - -   - - - - - D B B C - B - - - - C C B B A - - - -   - - - - - - D D B A A B - - - A A A A A - - - -   - - - - - - - D A A I A A A A A A A A - - - - -   - - - - - - - - - A A A B A A G A - - - - - - -   - - - - - - - - - - - - - - - - - - - - - - - -   - - - - - - - - - - - - - - - - - - - - - - - -   - - - - - - - - - - - - - - - - - - - - - - - -   - - - - - - - - - - - - - - - - - - - - - - - -   
- - - - - - - - - - - - - - - - - - - - - - - -   - - - - - - - - - - - - - - - - - - - - - - - -   - - - - - - - - C - - - - - - - - - - - - - - -   - - - - - - - D C - - - - - - - - - - - - - - -   - - - - - - - D C - - H H H H H - - C - - - - -   - - - - - - D C C F F H H H H F F - C - - - - -   - - - - - - D C E F F - - - - F F E C - - - - -   - - - - - B D C E - - - - - - - - E C C - - - -   - - - - - B C C - - - - - - - - - - C B B - - -   - - - - - B B B C C C - - - - C C C B B B - - -   - - - - - B A C K K C T - - T C K K C M D - - -   - - - - B C G C K K D D - - D D K K C G D J - A   - - - - B C F C C D D - - - - D D K C F D D - A   - - - - - C F C C D - - - - - - D C - F M D - A   - - - - - G F C - - - - - - - - - - C F G B A -   - - - - - C F C - - - - - - - - - - C F B B A -   - C C C C C B - - - - - - - - - - - - B B B A -   - - B B - C B - - - - - - - - - - - - B B A - -   - - - B B C B B - - - - - - - - - - - C B A - -   - - - B D B B B - - - - - - - - - - B C A - - -   - - - - D D B - - - - - - - - - - - C C A - - -   - - - - - D B B C - - - - - - - C C I A - - - -   - - - - - - J B B B A B - - A A C A A A - - - -   - - - - - - - D B B A B A A A A A A A - - - - -   - - - - - - - - B A A A A A G A A - - - - - - -   - - - - - - - - - A A A A A - - - - - - - - - -   - - - - - - - - - - A A A A - - - - - - - - - -   - - - - - - - - - - - - - - - - - - - - - - - -   - - - - - - - - - - - - - - - - - - - - - - - -   
- - - - - - - - - - - - - - - - - - - - - - - -   - - - - - - - - - - - - - - - - - - - - - - - -   - - - - - - - - - - - - - - - - - - - - - - - -   - - - - - - - - - - - - - - - - - - - - - - - -   - - - - - - - - - - - - - - - - - - - - - - - -   - - - - - - - C - F H H - - H H F - C - - - - -   - - - - - - J C F F H - - - - H F E C - - - - -   - - - - - - B C F E - - - - - - - F C B - - - -   - - - - - B B F H - - - - - - - - - F B - - - -   - - - - - B B B - - - - - - - - - - F B C - - -   - - - - - C B B - - D T - - T D - - B B B - - -   - - - - - - B B O AbO D - - D O AbO B B B - - -   - - - - - B F B O D D - - - - D D O D F D D - A   - - - - - B F D D D - - - - - - D D D F B B - -   - - - - B B F C - - - - - - - - - - C F B B - -   - - - - B C H C - - - - - - - - - - C H D B A -   - - - - C - C - - - - - - - - - - - - H B B - -   - - - - C - C - - - - - - - - - - - - C B - - -   - - - - C C C - - - - - - - - - - - - C B A - -   - - - - D B - B - - - - - - - - - - C B A A - -   - - - - D J B - - - - - - - - - - - C B A - - -   - - - - - J J B B - - - - - - - B C C A G - - -   - - - - - - D B B B A - - - B B B A A A - - - -   - - - - - - - B B B B B A B B A A A A - - - - -   - - - - - - - - - A A A G G A A A - - - - - - -   - - - - - - - - - A A A A I - - - - - - - - - -   - - - - - - - - - A G A A A - - - - - - - - - -   - - - - - - - - - - A A A A - - - - - - - - - -   - - - - - - - - - - - - - - - - - - - - - - - -   
- - - - - - - - - - - - - - - - - - - - - - - -   - - - - - - - - - - - - - - - - - - - - - - - -   - - - - - - - - - - - - - - - - - - - - - - - -   - - - - - - - - - C - - - - - - C - - - - - - -   - - - - - - - - - C - - - - - - C - - - - - - -   - - - - - - - - - B H - - - - - - - - C - - - -   - - - - - - - C E F H - - - - H F E C C - - - -   - - - - - - - B F F - - - - - - F F B C - - - -   - - - - - - B B H H - - - - - - H H B B C - - -   - - - - - - B H H H - - - - - - - H H B C - - -   - - - - - B J E - - - - - - - - - - F B B - - -   - - - - - B J F - - - - - - - - - - F J B - - -   - - - - B B D F D - - - - - - - - D F D B - - -   - - - - B B B D - - - - - - - - - - D B D - - -   - - - - B C H D - - - - - - - - - - D H C - - -   - - - - B B H D - - - - - - - - - - B H B - - -   - - - - C - C - - - - - - - - - - - - B B - - -   - - - - C - C - - - - - - - - - - - - C C - G -   - - - - C - C B - - - - - - - - - - - B C G G -   - - - - B B - C - - - - - - - - - - B B A A - -   - - - - - B - - - - - - - - - - - - B C A A - -   - - - - - A B B - - - - - - - - B B B A A - - -   - - - - - A A B A A B - - - - B B A A A - - - -   - - - - - - A A G B B C A B B B A G - - - - - -   - - - - - - - - A A A A A A A A A - - - - - - -   - - - - - - - - A A A - A A - - - - - - - - - -   - - - - - - - - - A A A A A A - - - - - - - - -   - - - - - - - - - A G I A A A - - - - - - - - -   - - - - - - - - - - - - - A A - - - - - - - - -   
- - - - - - - - - - - - - - - - - - - - - - - -   - - - - - - - - - - - - - - - - - - - - - - - -   - - - - - - - - - - - - - - - - - - - - - - - -   - - - - - - - - - C - - - - - - C - - - - - - -   - - - - - - - - - C - - - - - - C C - - - - - -   - - - - - - - - B B - - - - - - C B C C - - - -   - - - - - - - C B - H - - - - H - D C C - - - -   - - - - - - C C J H H - - - - H H J F C - - - -   - - - - - - C F H H - - - - - - H H F C - - - -   - - - - - B B F H H - - - - - - - H H F C - - -   - - - - - B D B H - - - - - - - - H H H B - - -   - - - - B B H F - - - - - - - - - - H F B - - -   - - - - B B B H - - - - - - - - - - H B D - - -   - - - - B B B B - - - - - - - - - - - B B - - -   - - - - B B B - - - - - - - - - - - - J B - - -   - - - A B - B B - - - - - - - - - - - D B - - -   - - - A B - B - - - - - - - - - - - - B B A - -   - - - G C - C - - - - - - - - - - - - B C A A A   - - - - G - C B - - - - - - - - - - - C C - A A   - - - - G G - B - - - - - - - - - - C B A G A -   - - - A I B G B - - - - - - - - - - B B - A - -   - - - - A A A A - - - - - - - - - B B I - - - -   - - - - - A A B B B C - A B B C C B G G - - - -   - - - - - - A A A A C B A B B B C A A - - - - -   - - - - - - - - A A B A A I A G A - - - - - - -   - - - - - - - - A A - - A A A - - - - - - - - -   - - - - - - - - A A A - - - - - - - - - - - - -   - - - - - - - - - A A A A A A - - - - - - - - -   - - - - - - - - - - A A - A A - - - - - - - - -   
- - - - - - - - - - - - - - - - - - - - - - - -   - - - - - - - - - - - - - - - - - - - - - - - -   - - - - - - - - - C - - - - - - C - - - - - - -   - - - - - - - - - C - - - - - - C - - - - - - -   - - - - - - - - - C - - - - - - C C - - - - - -   - - - - - - - C C B - - - - - - B B C - - - - -   - - - - - - - C B B - - - - - - D B C C - - - -   - - - - - - C C B B H - - - - H B B B C - - - -   - - - - - B C B C H H - - - - H H C B C - - - -   - - - - - B H B H H - - - - - - H H B B B - - -   - - - - - H H C H - - - - - - - H H C F B - - -   - - - - B F F C H - - - - - - - - H C F F - - -   - - - A B F B B C - - - - - - - - C C B F B - -   - - - A B B B C C - - - - - - - - C C D B D - -   - - - A B B C C - - - - - - - - - - - B B A - -   - - - A B - D - - - - - - - - - - - - B B G - -   - - - G B - C - - - - - - - - - - - - B A A - -   - - - - A - C - - - - - - - - - - - - C A A - A   - - - - A C - B - - - - - - - - - - - C B A A A   - - A A - A C B - - - - - - - - - - B C A A - -   - G A A A A A B B - - - - - - - - - C B A - - -   - - - A A A A B B - - - - - - - - C B A A - - -   - - - - - A A A C C C - - - B B B C A A - - - -   - - - - - - A A I B A C A B A C A A A - - - - -   - - - - - - - - - B A A A A I A A - - - - - - -   - - - - - - - - - - - - - A G A - - - - - - - -   - - - - - - - - - A - - - - - - - - - - - - - -   - - - - - - - - - A A A - A A - - - - - - - - -   - - - - - - - - - A A A - A A - - - - - - - - -   
- - - - - - - - - - - - - - - - - - - - - - - -   - - - - - - - - - - - - - - - - - - - - - - - -   - - - - - - - - - C - - - - - - C - - - - - - -   - - - - - - - - - C - - - - - - C - - - - - - -   - - - - - - - - - B B - - - - B B B - - - - - -   - - - - - - - - B D B - - - - B D B - - - - - -   - - - - - - - C B B B - - - - B B B - - - - - -   - - - - - - C C B D - - - - - - J B - C - - - -   - - - - - A B B B - - - - - - - - B B C - - - -   - - - - A B C C C H - - - - - - H B C C B - - -   - - - - A B B C B - - - - - - - - C C B B - - -   - - - - A B B C B - - - - - - - - B C B D - - -   - - - G A - D - B - - - - - - - - C - B D A - -   - - - A A D B B C - - - - - - - - C B B J A - -   - - - A B J J B - - - - - - - - - - B B A G - -   - - - A B D B - - - - - - - - - - - - C D A - -   - - - - B B B - - - - - - - - - - - - C B A - -   - - - - A B C - - - - - - - - - - - - C B A - -   - - - - A A C C - - - - - - - - - - C C A - - -   - A A A - A C C - - - - - - - - - - B C A A - -   A A G A A A C C C - - - - - - - - - C B A A - -   - A A A A A C C C - - - - - - B - C B A G A - -   - - - - - - A C B C A A - B B B B B C A - - - -   - - - - - - - - B B A C A B B A A G - - - - - -   - - - - - - - - - - A A B A A A - - - - - - - -   - - - - - - - - - - - - - A G A - - - - - - - -   - - - - - - - - - A - - - - - - - - - - - - - -   - - - - - - - - - G A G - - A - - - - - - - - -   - - - - - - - - - - A G - - A - - - - - - - - -   
- - - - - - - - - - - - - - - - - - - - - - - -   - - - - - - - - - - C - - - C C - - - - - - - -   - - - - - - - - - C C - - - - C - - - - - - - -   - - - - - - - - - C C C C C C C C - - - - - - -   - - - - - - - - - B B C B B C B B - - - - - - -   - - - - - - - - - C D B B B J D C B - - - - - -   - - - - - - - C C B D D B B J D J C - - - - - -   - - - - - - - C C C B B B B B C B J C C - - - -   - - - - - - B C J C C B - - B B C J C C - - - -   - - - - A B B C B C - - - - - - C B C C C - - -   - - - - A D C C C B - - - - - - C B B C B - - -   - - - - G D B B C - - - - - - - - C B C B - - -   - - - - A D B C C - - - - - - - - C C B G A - -   - - - - A D D B B - - - - - - - - B B B A G - -   - - - - A B D C B - - - - - - - - B B B A A - -   - - - - A B B - - - - - - - - - - - - C B A - -   - - - - A B B - - - - - - - - - - - - C B A - -   - - - - A I C C - - - - - - - - - - - C C - - -   - - - - - C B C - - - - - - - - - - B B C A A -   - - - - - - B C - - - - - - - - - - C B C A - -   A A G - - - C B C - - - - - - - - C A B A A - -   - - - - - - - C A C - - - - - - B B C C - - - -   - - - - - - - C B B A C A B C A C A A - - - - -   - - - - - - - - - A A A A B A B A A G - - - - -   - - - - - - - - - - A A - - A A G - - - - - - -   - - - - - - - - - - - - - - G A A - - - - - - -   - - - - - - - - - - - - - - - - - - - - - - - -   - - - - - - - - - - A A - - - - - - - - - - - -   - - - - - - - - - - A A - - - - - - - - - - - -   
- - - - - - - - - - - - - - - - - - - - - - - -   - - - - - - - - - - C - C C C - - - - - - - - -   - - - - - - - - - - - C C C C C - - - - - - - -   - - - - - - - - - - C C B C C C - - - - - - - -   - - - - - - - - - - B C B B B C C - - - - - - -   - - - - - - - - - C B B B B B B C - - - - - - -   - - - - - - - - C C B D B B D B B C - - - - - -   - - - - - - - - C B B J B B D D B C C - - - - -   - - - - - - - C C C B D B B D C B C C C - - - -   - - - - - - C C B C B B C C B C B B C B - - - -   - - - - - - C C C C C C - - C C C C C C A - - -   - - - - - B B B B C C C - - C C C B B B A - - -   - - - - - - D B B C C - - - - C C B - B B A - -   - - - - - B J B B C - - - - - - C C B B G A - -   - - - - - B D - C - - - - - - - - C - B B A - -   - - - - - B B B - - - - - - - - - - - B C A - -   - - - - - B B B - - - - - - - - - - - B B - - -   - - - - - B B D - - - - - - - - - - - B B - A -   - - - - - B I D - - - - - - - - - - B C B A A -   - - - - - - D B A - - - - - - - - B B D - A A -   - - - - - - B C B - - - - - - - A B A A - - - -   - - - - - - - C B A - B A A C B G A A - - - - -   - - - - - - - - B B A B A B B B B A A - - - - -   - - - - - - - - - A A A A C B G - A - - - - - -   - - - - - - - - - - - - - - - A A - - - - - - -   - - - - - - - - - - - - - - - A A - - - - - - -   - - - - - - - - - - - - - - - - - - - - - - - -   - - - - - - - - - - A A - - - - - - - - - - - -   - - - - - - - - - - A A - - - - - - - - - - - -   
- - - - - - - - - - - - C C - - - - - - - - - -   - - - - - - - - - - - - C C - - - - - - - - - -   - - - - - - - - - - - - C C - - - - - - - - - -   - - - - - - - - - - - C C C C C - - - - - - - -   - - - - - - - - - - C C C C C C - - - - - - - -   - - - - - - - - - C C C C C C C C - - - - - - -   - - - - - - - - - B B C C C C C B B - - - - - -   - - - - - - - - B B B B B B B B B B - - - - - -   - - - - - - - C B B B J B B D B B B A - - - - -   - - - - - - - B B C C B C C B B C C D A - - - -   - - - - - - B B C C C B C C B C C C D A - - - -   - - - - - - B D B C C C C C C C B B B B A - - -   - - - - - - D B B B C C B B C C C B D D G - - -   - - - - - - D C C B C C B B C C B C B B A - - -   - - - - - - D D C B C C B B C B B C D B B - - -   - - - - - B D J - - - - - - - - - - J B I - - -   - - - - - D A D B - - - - - - - - - D C I - - -   - - - - - - J D B - - - - - - - - - D C A - - -   - - - - - - B G C - - - - - - - - - B B A - - -   - - - - - - B G B A - - - - - - A B B B - - - -   - - - - - - - G A A - C A - C C A A B - - - - -   - - - - - - - - A G A B A A B B B G A - - - - -   - - - - - - - - - A A A A C B B G G A - - - - -   - - - - - - - - - - A A A - - - - - - - - - - -   - - - - - - - - - - - - - - - - A - - - - - - -   - - - - - - - - - - - - - - - - A A - - - - - -   - - - - - - - - - - - - - - - - - - - - - - - -   - - - - - - - - - - - A - - - - - - - - - - - -   - - - - - - - - - - - - - - - - - - - - - - - -   
- - - - - - - - - - - - - - - - - - - - - - - -   - - - - - - - - - - - - - - - - - - - - - - - -   - - - - - - - - - - - - - - - - - - - - - - - -   - - - - - - - - - - - - - - - - - - - - - - - -   - - - - - - - - - - - - - - - - - - - - - - - -   - - - - - - - - - - - - C C C - - - - - - - - -   - - - - - - - - - B B C B C B C B - - - - - - -   - - - - - - - - - D B B B D B B B - - - - - - -   - - - - - - - - B B B B B D B D B B - - - - - -   - - - - - - - - B B B B B B D B B B B - - - - -   - - - - - - - - B B C C D D D C C B D - - - - -   - - - - - - B B C B C B C C C C C C J J - - - -   - - - - - - B C C B B B C B B B C C J D - - - -   - - - - - - I C C B B C B B C B B C D B - - - -   - - - - - - A C C C B B B B C B - C C C - - - -   - - - - - - A C C C - - - - - - - - C C A - - -   - - - - - - A B C C - - - - - - - B C B A - - -   - - - - - - A A C B B - - - - - - B C B A - - -   - - - - - - G I B B A - - - - - A A B A - - - -   - - - - - - - G A A B B - - - C A A B B - - - -   - - - - - - - - A B B C A B C C B A A A - - - -   - - - - - - - - - A A A A C C B B A A - - - - -   - - - - - - - - - A A A A - - - - - - - - - - -   - - - - - - - - - - - - - - - - - - - - - - - -   - - - - - - - - - - - - - - - - - - - - - - - -   - - - - - - - - - - - - - - - - - - - - - - - -   - - - - - - - - - - - - - - - - - - - - - - - -   - - - - - - - - - - - - - - - - - - - - - - - -   - - - - - - - - - - - - - - - - - - - - - - - -   
- - - - - - - - - - - - - - - - - - - - - - - -   - - - - - - - - - - - - - - - - - - - - - - - -   - - - - - - - - - - - - - - - - - - - - - - - -   - - - - - - - - - - - - - - - - - - - - - - - -   - - - - - - - - - - - - - - - - - - - - - - - -   - - - - - - - - - - - - - - - - - - - - - - - -   - - - - - - - - - - - - - - - - - - - - - - - -   - - - - - - - - - - B B B B - - - - - - - - - -   - - - - - - - - - D B B B B B B B D - - - - - -   - - - - - - - - B D B D B B B D B B - - - - - -   - - - - - - - - B D D C C C B D D B D - - - - -   - - - - - - - - A A D B B J D B D B D - - - - -   - - - - - - - A B B C B D B B B B B D A - - - -   - - - - - - - A B B C B B B B B C C B A - - - -   - - - - - - A C C C B B B C C B C C C A - - - -   - - - - - - A A C C C C C B C C C C C C - - - -   - - - - - - A I C C C C C B B C C B C G - - - -   - - - - - - - G C G B C B B B A C B B G - - - -   - - - - - - - - A B B B B B B B C B B A - - - -   - - - - - - - - A A C C B B C C G A A A - - - -   - - - - - - - - A A A A A G B A G A A A - - - -   - - - - - - - - - A A A A G - - - - - - - - - -   - - - - - - - - - - A A - - - - - - - - - - - -   - - - - - - - - - - - - - - - - - - - - - - - -   - - - - - - - - - - - - - - - - - - - - - - - -   - - - - - - - - - - - - - - - - - - - - - - - -   - - - - - - - - - - - - - - - - - - - - - - - -   - - - - - - - - - - - - - - - - - - - - - - - -   - - - - - - - - - - - - - - - - - - - - - - - -   
- - - - - - - - - - - - - - - - - - - - - - - -   - - - - - - - - - - - - - - - - - - - - - - - -   - - - - - - - - - - - - - - - - - - - - - - - -   - - - - - - - - - - - - - - - - - - - - - - - -   - - - - - - - - - - - - - - - - - - - - - - - -   - - - - - - - - - - - - - - - - - - - - - - - -   - - - - - - - - - - - - - - - - - - - - - - - -   - - - - - - - - - - - - - - - - - - - - - - - -   - - - - - - - - - - - A - B - - - - - - - - - -   - - - - - - - - - A G A D D D G A A - - - - - -   - - - - - - - - - A A J D J J B A A - - - - - -   - - - - - - - - A A D J D J D D C A A - - - - -   - - - - - - - A A D B B B B B B B B A - - - - -   - - - - - - - A A B B B B B B B C C A A - - - -   - - - - - - - G I C C B B B C B C C I A - - - -   - - - - - - - A C C C C C B C C C C C M - - - -   - - - - - - - A I A A C C B B C A I C A - - - -   - - - - - - - - A A B C B B B A A A C - - - - -   - - - - - - - - A A G C B B B G A A - - - - - -   - - - - - - - - A A G A A A - A G A - A - - - -   - - - - - - - - - A A A G A - - - - - A - - - -   - - - - - - - - - - A A A - - - - - - - - - - -   - - - - - - - - - - - - - - - - - - - - - - - -   - - - - - - - - - - - - - - - - - - - - - - - -   - - - - - - - - - - - - - - - - - - - - - - - -   - - - - - - - - - - - - - - - - - - - - - - - -   - - - - - - - - - - - - - - - - - - - - - - - -   - - - - - - - - - - - - - - - - - - - - - - - -   - - - - - - - - - - - - - - - - - - - - - - - -   
- - - - - - - - - - - - - - - - - - - - - - - -   - - - - - - - - - - - - - - - - - - - - - - - -   - - - - - - - - - - - - - - - - - - - - - - - -   - - - - - - - - - - - - - - - - - - - - - - - -   - - - - - - - - - - - - - - - - - - - - - - - -   - - - - - - - - - - - - - - - - - - - - - - - -   - - - - - - - - - - - - - - - - - - - - - - - -   - - - - - - - - - - - - - - - - - - - - - - - -   - - - - - - - - - - - A - - - A - - - - - - - -   - - - - - - - - - - A A - - - A G - - - - - - -   - - - - - - - - - A A - - J D A G A - - - - - -   - - - - - - - - A A - - D J D - I A - - - - - -   - - - - - - - - A M B B D B B - - A A - - - - -   - - - - - - - - A - B B B B B - C A A - - - - -   - - - - - - - - A - A A C C C A - - A - - - - -   - - - - - - - - - A A A C B A A G - - - - - - -   - - - - - - - - - A A I B B I A A A - - - - - -   - - - - - - - - - A A A B B A G A - - - - - - -   - - - - - - - - - A A A A A - G A - - - - - - -   - - - - - - - - - - A G A A - - - - - - - - - -   - - - - - - - - - - A G A A - - - - - - - - - -   - - - - - - - - - - - - - - - - - - - - - - - -   - - - - - - - - - - - - - - - - - - - - - - - -   - - - - - - - - - - - - - - - - - - - - - - - -   - - - - - - - - - - - - - - - - - - - - - - - -   - - - - - - - - - - - - - - - - - - - - - - - -   - - - - - - - - - - - - - - - - - - - - - - - -   - - - - - - - - - - - - - - - - - - - - - - - -   - - - - - - - - - - - - - - - - - - - - - - - -   
- - - - - - - - - - - - - - - - - - - - - - - -   - - - - - - - - - - - - - - - - - - - - - - - -   - - - - - - - - - - - - - - - - - - - - - - - -   - - - - - - - - - - - - - - - - - - - - - - - -   - - - - - - - - - - - - - - - - - - - - - - - -   - - - - - - - - - - - - - - - - - - - - - - - -   - - - - - - - - - - - - - - - - - - - - - - - -   - - - - - - - - - - - - - - - - - - - - - - - -   - - - - - - - - - - - - - - - - - - - - - - - -   - - - - - - - - - - - - - - - A - - - - - - - -   - - - - - - - - - - - - - - - A A - - - - - - -   - - - - - - - - - - - - - - - - I - - - - - - -   - - - - - - - - - - - - - - - - - - - - - - - -   - - - - - - - - - - - A A A A - - - - - - - - -   - - - - - - - - - - A A A I A A - - - - - - - -   - - - - - - - - - - A A A A A A - - - - - - - -   - - - - - - - - - - A A - - A A - - - - - - - -   - - - - - - - - - - - - - - - - - - - - - - - -   - - - - - - - - - - - A A G - - - - - - - - - -   - - - - - - - - - - G A A A - - - - - - - - - -   - - - - - - - - - - - - - - - - - - - - - - - -   - - - - - - - - - - - - - - - - - - - - - - - -   - - - - - - - - - - - - - - - - - - - - - - - -   - - - - - - - - - - - - - - - - - - - - - - - -   - - - - - - - - - - - - - - - - - - - - - - - -   - - - - - - - - - - - - - - - - - - - - - - - -   - - - - - - - - - - - - - - - - - - - - - - - -   - - - - - - - - - - - - - - - - - - - - - - - -   - - - - - - - - - - - - - - - - - - - - - - - -   
- - - - - - - - - - - - - - - - - - - - - - - -   - - - - - - - - - - - - - - - - - - - - - - - -   - - - - - - - - - - - - - - - - - - - - - - - -   - - - - - - - - - - - - - - - - - - - - - - - -   - - - - - - - - - - - - - - - - - - - - - - - -   - - - - - - - - - - - - - - - - - - - - - - - -   - - - - - - - - - - - - - - - - - - - - - - - -   - - - - - - - - - - - - - - - - - - - - - - - -   - - - - - - - - - - - - - - - - - - - - - - - -   - - - - - - - - - - - - - - - - - - - - - - - -   - - - - - - - - - - - - - - - - - - - - - - - -   - - - - - - - - - - - - - - - - - - - - - - - -   - - - - - - - - - - - - A A - - - - - - - - - -   - - - - - - - - - - - - G A - - - - - - - - - -   - - - - - - - - - - - - G A A - - - - - - - - -   - - - - - - - - - - - - - - - - - - - - - - - -   - - - - - - - - - - - - - - - - - - - - - - - -   - - - - - - - - - - - - - - - - - - - - - - - -   - - - - - - - - - - - A A A - - - - - - - - - -   - - - - - - - - - - - - A A - - - - - - - - - -   - - - - - - - - - - - - - - - - - - - - - - - -   - - - - - - - - - - - - - - - - - - - - - - - -   - - - - - - - - - - - - - - - - - - - - - - - -   - - - - - - - - - - - - - - - - - - - - - - - -   - - - - - - - - - - - - - - - - - - - - - - - -   - - - - - - - - - - - - - - - - - - - - - - - -   - - - - - - - - - - - - - - - - - - - - - - - -   - - - - - - - - - - - - - - - - - - - - - - - -   - - - - - - - - - - - - - - - - - - - - - - - -   
- - - - - - - - - - - - - - - - - - - - - - - -   - - - - - - - - - - - - - - - - - - - - - - - -   - - - - - - - - - - - - - - - - - - - - - - - -   - - - - - - - - - - - - - - - - - - - - - - - -   - - - - - - - - - - - - - - - - - - - - - - - -   - - - - - - - - - - - - - - - - - - - - - - - -   - - - - - - - - - - - - - - - - - - - - - - - -   - - - - - - - - - - - - - - - - - - - - - - - -   - - - - - - - - - - - - - - - - - - - - - - - -   - - - - - - - - - - - - - - - - - - - - - - - -   - - - - - - - - - - - - - - - - - - - - - - - -   - - - - - - - - - - - - - - - - - - - - - - - -   - - - - - - - - - - - - - A - - - - - - - - - -   - - - - - - - - - - - - - A - - - - - - - - - -   - - - - - - - - - - - - - - - - - - - - - - - -   - - - - - - - - - - - - - - - - - - - - - - - -   - - - - - - - - - - - - - - - - - - - - - - - -   - - - - - - - - - - - - - - - - - - - - - - - -   - - - - - - - - - - - - - - - - - - - - - - - -   - - - - - - - - - - - - - A - - - - - - - - - -   - - - - - - - - - - - - - - - - - - - - - - - -   - - - - - - - - - - - - - - - - - - - - - - - -   - - - - - - - - - - - - - - - - - - - - - - - -   - - - - - - - - - - - - - - - - - - - - - - - -   - - - - - - - - - - - - - - - - - - - - - - - -   - - - - - - - - - - - - - - - - - - - - - - - -   - - - - - - - - - - - - - - - - - - - - - - - -   - - - - - - - - - - - - - - - - - - - - - - - -   - - - - - - - - - - - - - - - - - - - - - - - -   
