model
size = 26 11 28, scale = 0.05, origin = -y
material 
  colors = A:#D9ADE4 B:#010101 C:#060606 D:#090909 E:#1A1A1A F:#141414 G:#111 H:#0F0F0F I:#0C0C0C J:#040404 K:#000 L:#1C1C1C M:#222 N:#171717 O:#131314
voxels
-------------------------- -------------------------- -------------------------- -------------------------- -------------------------- ------------CC------------ -------------------------- -------------------------- -------------------------- -------------------------- -------------------------- 
-----CCC----------CCC----- ----DCCCHD------DHCCCD---- ---EAAAAAJG----GJAAAADE--- --FFAAAAAAE----EAAAAAAFF-- -HEAAAAAAAAFCCFAAAAAAAAEH- ILMAAAAAAAADCCDAAAAAAAAMLI GDFAAAAAAADDBBDDAAAAAAAFDG ---EAAAAAAE----EAAAAAAE--- ---IHAAAAGK----KGAAAAHI--- ----BCCCCI------ICCCCB---- ------CC----------CC------ 
-----CCCC--------CCCC----- ----DHAAID------DIAAHD---- ---EAAAAAAG----GAAAAAAE--- --KAAAAAAAE----EAAAAAAAK-- GDFAAAAAAAAF--FAAAAAAAAFDG GJEAAAAAAAAE--EAAAAAAAAEJG DDEAAAAAAAAN--NAAAAAAAAEDD --EAAAAAAAO----OAAAAAAAE-- ---DAAAAADF----FDAAAAAD--- ----BBCCCJ------JCCCBB---- ------CC----------CC------ 
-------------------------- -------------------------- -------------------------- -------------------------- -------------------------- B------------------------B C------------------------C -------------------------- -------------------------- -------------------------- -------------------------- 
-------------------------- -------------------------- -------------------------- -------------------------- -------------------------- B------------------------B B------------------------B -------------------------- -------------------------- -------------------------- -------------------------- 
-------------------------- -------------------------- -------------------------- -------------------------- -------------------------- B------------------------B B------------------------B -------------------------- -------------------------- -------------------------- -------------------------- 
-------------------------- -------------------------- -------------------------- -------------------------- -------------------------- B------------------------B B------------------------B B------------------------B -------------------------- -------------------------- -------------------------- 
-------------------------- -------------------------- -------------------------- -------------------------- -------------------------- B------------------------B B------------------------B B------------------------B -------------------------- -------------------------- -------------------------- 
-------------------------- -------------------------- -------------------------- -------------------------- -------------------------- B------------------------B B------------------------B B------------------------B -------------------------- -------------------------- -------------------------- 
-------------------------- -------------------------- -------------------------- -------------------------- -------------------------- -------------------------- B------------------------B B------------------------B -------------------------- -------------------------- -------------------------- 
-------------------------- -------------------------- -------------------------- -------------------------- -------------------------- -------------------------- B------------------------B B------------------------B -------------------------- -------------------------- -------------------------- 
-------------------------- -------------------------- -------------------------- -------------------------- -------------------------- -------------------------- B------------------------B B------------------------B -------------------------- -------------------------- -------------------------- 
-------------------------- -------------------------- -------------------------- -------------------------- -------------------------- -------------------------- B------------------------B B------------------------B -------------------------- -------------------------- -------------------------- 
-------------------------- -------------------------- -------------------------- -------------------------- -------------------------- -------------------------- B------------------------B B------------------------B -------------------------- -------------------------- -------------------------- 
-------------------------- -------------------------- -------------------------- -------------------------- -------------------------- -------------------------- C------------------------C B------------------------B B------------------------B -------------------------- -------------------------- 
-------------------------- -------------------------- -------------------------- -------------------------- -------------------------- -------------------------- B------------------------B H------------------------H C------------------------C -------------------------- -------------------------- 
-------------------------- -------------------------- -------------------------- -------------------------- -------------------------- -------------------------- B------------------------B C------------------------C B------------------------B -------------------------- -------------------------- 
-------------------------- -------------------------- -------------------------- -------------------------- -------------------------- -------------------------- -------------------------- C------------------------C B------------------------B -------------------------- -------------------------- 
-------------------------- -------------------------- -------------------------- -------------------------- -------------------------- -------------------------- -------------------------- I------------------------I C------------------------C -------------------------- -------------------------- 
-------------------------- -------------------------- -------------------------- -------------------------- -------------------------- -------------------------- -------------------------- BB----------------------BB B------------------------B -------------------------- -------------------------- 
-------------------------- -------------------------- -------------------------- -------------------------- -------------------------- -------------------------- -------------------------- B------------------------B BB----------------------BB -------------------------- -------------------------- 
-------------------------- -------------------------- -------------------------- -------------------------- -------------------------- -------------------------- -------------------------- B------------------------B BB----------------------BB B------------------------B -------------------------- 
-------------------------- -------------------------- -------------------------- -------------------------- -------------------------- -------------------------- -------------------------- B------------------------B BB----------------------BB -------------------------- -------------------------- 
-------------------------- -------------------------- -------------------------- -------------------------- -------------------------- -------------------------- B------------------------B BB----------------------BB B------------------------B -------------------------- -------------------------- 
-------------------------- -------------------------- -------------------------- -------------------------- -------------------------- -------------------------- B------------------------B BB----------------------BB B------------------------B -------------------------- -------------------------- 
-------------------------- -------------------------- -------------------------- -------------------------- B------------------------B B------------------------B BB----------------------BB B------------------------B -------------------------- -------------------------- -------------------------- 
-------------------------- -------------------------- -------------------------- -------------------------- B------------------------B BB----------------------BB B------------------------B -------------------------- -------------------------- -------------------------- -------------------------- 
-------------------------- -------------------------- -------------------------- -------------------------- B------------------------B B------------------------B -------------------------- -------------------------- -------------------------- -------------------------- -------------------------- 
