model
size = 15 18 13, scale = 0.05, origin = -y
material 
  colors = A:#1F1F1F B:#262626 C:#323232 D:#414141 E:#5A5B5A F:#555655 G:#0F0F0F H:#3A3C3A I:#161616 J:#4A4A48 K:#515150 L:#2C2F2C M:#070707 N:#000 O:#464643
voxels
--------------- --------------- --------------- --------------- --------------- ------FH------- -----KNL------- ----DIG-------- ----KJC-------- ---FNE--------- ---HNF--------- ---CC---------- --------------- --------------- --------------- --------------- --------------- --------------- 
--------------- --------------- --------------- --------------- --------------- ------HH------- -----HFB------- ----BDBH------- ----CDH-------- ---FCB--------- ---CCH--------- ---CBD--------- ---DF---------- --------------- --------------- --------------- --------------- --------------- 
--------------- --------------- --------------- --------------- --------------- ------B-------- -----BBB------- ----DBB-------- ---CBBBCA------ ---BBB-CF------ ---BBBCF------- --AACFC-------- --ACK---------- --CDC---------- ---G----------- --------------- --------------- --------------- 
--------------- ------------BHH -----------BBH- ----------BLHF- ---------BBDD-- --------BBDFM-- -------BBBJF--- ------ABBJJ---- -----AAAAJ----- ---AAAAADJ----- --AAACAHIK----- --A-CCCKE------ -AAACCED------- -AANEDF-------- --FAFE--------- --FH----------- --------------- --------------- 
--------------- ------------BBH -----------BBGF ----------BLLG- ---------BBBE-- --------BBBMB-- -------BBBBK--- ------AABJD---- -----AA-AJJ---- ---AAAAAAE----- --AAAAAACN----- -AAA--EEN------ -A---EHE------- -AA-CFEB------- -AKCEBE-------- -CFCEE--------- ---CC---------- --------------- 
--------------D ------------BDD -----------BBDE ----------BBHE- ---------BBDFJ- --------BBBJF-- -------BBBJD--- ------ABBJFE--- ----A-AAADD---- ----AAAABK----- --AAAAAAOE----- -AAAA---E------ -ABB---NJ------ -BBBBBMN------- -ABBBGM-------- -IIBEM--------- --IIC---------- ----C---------- 
-------------DD ------------DDE -----------DLFM ----------BBBL- ---------ABBLE- --------AABAI-- --------AAAAN-- ------AAAAOM--- ------AAAAN---- ----FAAAAA----- ---CBKAABA----- -AAFA---G------ -AAI---EM------ -AKBBBKG------- -AILKGDM------- -AIIKMM-------- ---ICM--------- ----C---------- 
-------------DD ------------DDD ------------DDE -----------BLD- ----------BBFJ- ---------AAAK-- --------AADDJ-- ------AAADFK--- ------AAADE---- ----JAAAAB----- ----BAAACE----- -AHBA---E------ -AAL---KM------ -AA----G------- -AIIK-GG------- -AIIKGM-------- ---IIM--------- ----E---------- 
--------------- ------------DDD -----------DDGE ----------BLLG- ---------BBBL-- --------BLBEG-- -------BBBJE--- -------AAHN---- ------ADABI---- ----JAAAAE----- ---CBAAACG----- -AAFA---B------ -AAC---GG------ AAK----G------- -AIIK-G-------- -AIIKGG-------- ---IIG--------- ----C---------- 
--------------- ------------DDD -----------DDDJ ----------BDDE- ---------BBBL-- ---------BJEE-- --------BBJE--- ------ABBHE---- ------AOAFJ---- ----CAAAAK----- --AAAAAAHF----- -AAAC--HG------ -ABB--HG------- AAKBBBKG------- -ABBBFG-------- -AIIKL--------- ---IC---------- ----C---------- 
--------------- --------------- -----------BB-- ----------BBM-- ---------BLIL-- --------BBLH--- -------CCBBM--- ------AJAEG---- -----AAAAM----- ----AAAAAH----- --AAAAAAF------ -AAAA-AI------- -ABB-JNG------- -AABBGG-------- -ACFCG--------- -AICG---------- ---FC---------- --------------- 
--------------- --------------- -----------BH-- ----------BBJ-- ---------BLOE-- --------BBHH--- -------CCCDA--- ------ACCDN---- -----AAAHK----- ----AAAAB------ ---AACACH------ --AACFCG------- -AACFDL-------- -ACCFJG-------- -CCFCC--------- --CCE---------- --------------- --------------- 
--------------- --------------- --------------- --------------- --------------- ----------H---- ---------C----- --------C------ ------CC------- -----CHFC------ ----CCFC------- ----CKC-------- ---CHF--------- --------------- --------------- --------------- --------------- --------------- 
