model
size = 24 27 16, scale = 0.05, origin = -y
material 
  colors = A:#161616 B:#565957 C:#3A3C3A D:#262626 E:#2C2F2C F:#515551 G:#070707 H:#0F0F0F I:#000 J:#4E4E4C K:#3F3F3F L:#464643 M:#323232 N:#4A4C46 O:#1F1F1F
voxels
------------------------ ------------------------ ------------------------ ------------------------ ------------------------ ------------------------ ------------------------ ------------------------ ------------------------ ------------------------ ------------------------ ------------------------ ------------------------ ------------------------ ------------------------ ------------------------ ------------------------ ------------------------ ------------------------ -------C---------------- -------CCC-------------- ---------N-------------- ------------------------ ------------------------ ------------------------ ------------------------ ------------------------ 
------------------------ ------------------------ ------------------------ ------------------------ ------------------------ ------------------------ ------------------------ ------------------------ ------------------------ ------------------------ ------------------------ ------------------------ -------------G---------- ------------------------ --------LLB------------- -------LLBBN------------ ------FBCNBJB----------- ------BBDLNFJKC--------- -----CCBJDNFBK---------- -----BNBBJBICB---------- ------BBCCCCB----------- -------HBBBBF----------- --------IHH------------- ------------------------ ------------------------ ------------------------ ------------------------ 
------------------------ ------------------------ ------------------------ ------------------------ ------------------------ ------------------------ ------------------------ ------------------------ -------------FFMM------- ------------MMHHH------- -----------FMGGGHH------ -----------FHGGGG------- ----------FMHGGOA------- ----------BGIGOO-------- --------EEBBGOOG-------- -------EEEEBFGD--------- ------EELNBBB-C--------- ----ECELDLNBBCCC-------- ---CJBEBAANBLDBB-------- --JMBHDEAABEDCI--------- ---B-BNDEEBDJM---------- -----FBKGDDMCN---------- ------FFBBBBB----------- ---------K-------------- ------------------------ ------------------------ ------------------------ 
------------------------ ------------------------ ------------------------ ------------------------ ------------------------ ------------------------ ---------------BBB------ -------------BBBFFM----- ------------BBFMMHH----- -----------BBFMHHHG----- -----------BBGGGHIG----- ----------BBHGGGGGK----- ---------BBMHGGOGD------ ---------BBKAAOGJB------ -------AEEAAAAAFB------- -----AAEEAEKAIBB-------- -----AAAAAAAKBB--------- ----CAEAAAAAEDDC-------- --DDDAEAAAAABDDBC------- --BCKAAAAAAAACKA-------- --BBJBAAEABAABB--------- ---JEBAAADDABKB--------- ----DKBCAAANCB---------- -----IGJJBBFK----------- ------IDDHIA------------ ------------------------ ------------------------ 
------------------------ ------------------------ -------------------DC--- ------------------CCBC-- -----------------BCCJBF- ---------------KBBBCCC-- --------------LBBBFFCC-- -------------KBBFFMGI--- ------------KBB-MAAG---- -----------KL----HGB---- ----------KL------BB---- ----------K------LB----- ---------K-AA---JBK----- ---------KAAAA--LK------ ------AAAAAAAAAKK------- -----AAEEAEBAAAKJ------- ----AAEEAAABAAKK-------- ---AAAE-AAAAEAFCC------- ---AADE---A-BADDC------- -CJDAFDE---EDDDJN------- -GNBAFDDEBBCDABB-------- -BJJAAAADDDDABL--------- ---JMAAAADDAAIG--------- ---NMHAAAAAAGGG--------- ----MHHGDDGIG----------- ------IIDDII------------ ------------------------ 
------------------------ -------------------ACC-- -------------------ACCC- ------------------LACCCC ----------------KKCAAKF- --------------BKKBKCCFA- -------------CBKBBFLCA-- ------------CCL---MGB--- -----------BB------BK--- ----------BB-------KK--- ---------BC--------K---- ---------NC-------LC---- --------BBAAA----KCJ---- -------ACAAAAA---BJ----- -----AAAAEEEAAA-CN------ ----AAAEEEEF-AAACH------ ----AAEE---BEAABJ------- ---AA-E-----BANB-------- ---A--E-----BA-DDC------ -CDA--EE---EBADDG------- -IDFFDDDEBBCDADB-------- -BFAACDDDDDDAABC-------- --JJAA---DDDA-E--------- ---MMAAAAAAAADE--------- ----MHIAAAAGGH---------- -----HIIDGII------------ ------------------------ 
------------------------ -------------------EA--- -------------------EAACF ----------------BCEAAAAF ---------------BBEAAAAFD --------------BBBAAAAFD- ------------BBBB--KJFD-- -----------BBB------DC-- -----------BB-------KB-- ----------B---------B--- ---------BB--------BJ--- ---------BA--------I---- --------BAAAA-----HH---- --------AA-AAA----H----- -----AAAAEEE-AA--HH----- ----AAAEEEEE--AAHH------ ---AA-EE---EL-AAH------- ---A--E-----FAAB-------- ---A--E-----BAC-DC------ -M-A--FE---EBAADGD------ -FDAFF-EEBBCDADBC------- -BJAFFDDDDEDDA-C-------- --JMAFDDDDDDAAEG-------- ---HAAA---DAAEE--------- ----HIAAAAAAGE---------- -----IIIDIIGG----------- --------DI-------------- 
--------------------AA-- -------------------EAA-- -----------------C-EAAAF ----------------BCEA-AAF ---------------BBAA---FD -------------BBB-AAA-FD- ------------BBB----AFDC- -----------BBB------DH-- ----------BB---------F-- ---------BB---------FF-- ---------B----------B--- --------BBA--------FB--- --------BAAAA------H---- -------CAA-AAA----GG---- -----AAAEEEE-AA--GG----- ----AAAEEEEF--AAEH------ ---AA-EE---BB-AAE------- ---A--E-----L-ABB------- --AA--E-----B-CCDC------ -CA---JE---EB-ADDG------ BFDAF--EEBFF-ADBCG------ -BFAFFDDCBEDDDDC-------- --JAAFDDDDDDDAEG-------- ---HAA--DDDAAEE--------- ---HHAAAAAAAEEE--------- -----IIIDIIGGE---------- -------IDII------------- 
--------------------AM-- -------------------EAA-- -----------------C-EAAAF ----------------CCEA--AF ---------------CCAA---FD -------------CCC-AAA-FD- ------------CCC----AFDC- -----------CC-------DB-- ----------CC---------B-- ---------CC---------BB-- ---------C----------B--- --------CCA--------FB--- --------CAAAA------B---- -------CAA-AAA----G----- -----AAAEEEE-AA--HG----- ----AAAEEEEE--AA-H------ ---AA-EE---LB-AAJ------- ---A--E-----F-ABB------- --AA--E-----B-CCDC------ -MA---FE---EB-ADDG------ BFDAF--EEBBC-ADBCG------ -BJAFFDDBBEDDDDC-------- --JAAFDDDDDDDAEG-------- ---HAA--DDDAAEE--------- ---HHHAAAAAADE---------- -----IIIDIIGG----------- -------IDII------------- 
--------------------A--- -------------------EA--- -------------------EAAAF ----------------CCEAAAAF ---------------CCAA---FD --------------CCJAAA-FD- ------------CCCJ---AFDC- -----------CCC------DC-- ----------CCC-------CJ-- ----------CC-------FBB-- ---------CC--------CB--- ---------CA-------CBB--- --------CAAAA-----CB---- --------AA-AAA---CB----- -----AAAAEEE-AA--BB----- ----AAAEEEEE--AABB------ ---AA-EE---LE-AAB------- ---A--E-----FAABB------- ---A--E-----BACCDC------ -C-A--KE---EBAADGD------ -IDAFFDEEBBCDADBC------- -BJAFFDDDDEDDA-C-------- --JMA-DDDDDDAAEG-------- ---HAAA---DAAEE--------- ----HIAAAAAGGE---------- -----IIIDIIGG----------- --------DI-------------- 
------------------------ -------------------ADE-- -------------------ADDK- -----------------CEAAADF ----------------CCAAAAFD ---------------CCDDAAFM- -------------NCC--DDAC-- ------------JCC----DCC-- -----------JCC-----CC--- ----------JCC------CC--- ---------JCC------CC---- ---------KCA------CF---- --------CCAAA----JF----- -------ACAAAAA--CCC----- -----AAAAAEE-AA-CF------ ----AAAEEEEB-DAAF------- ----AAEE---BFAAC-------- ---AA-E-----BANC-------- ---A--E-----BACDDC------ -CCA-JEE---EBADDH------- -IDFFDDDEBBCDADB-------- -BFAADDDDDDDAABC-------- --JJAA---DDDAGD--------- ---CMAAAAAAAGHE--------- ----MHIAAAAGGH---------- -----HIIDDII------------ ------------------------ 
------------------------ ------------------------ -------------------ADD-- ------------------EDDDD- -----------------CDDDDD- ---------------CCBCDDD-- --------------CCBBBBCF-- -------------CCBBBBBL--- ------------CCBBBBKBL--- -----------CCCCBBABL---- ----------CCF--LHFB----- ---------CLJ----FCC----- ---------CBAA---BC------ ---------CAAAA-CBC------ ------AAAAAAAAABB------- ----AAAEAAABAAAB-------- ----AAEEAAAAABBC-------- ----AAE-AAAAEACJC------- --KAADE--AAABADDC------- -NJDAFDE--AEDDDJN------- -IBBAFDDEEBCAABB-------- -BJJAAAADDDDABE--------- ---JMAAAADAAAIG--------- ---NMHAAAAAIIIG--------- ----MHHHDDHIG----------- ------IIDDI------------- ------------------------ 
------------------------ ------------------------ ------------------------ ------------------------ ------------------------ -----------------B------ ---------------BBBB----- --------------BBBBBB---- -------------BBBBBBC---- ------------BCBBBCK----- -----------BBLCBAFB----- ----------BBHGOCCJ------ ----------BEOHHGB------- ---------NFAAHIGH------- -------AEECAAGHH-------- ------AEEEEBBHM--------- -----AAAAAABBBB--------- ----CAAAAAAABDDC-------- --KCDAAAAAAABDDB-------- --BCCAAAAAAADBFA-------- --BBJBAAAAAADBB--------- ---JKBBAADDABBB--------- ----HKBCBABBCB---------- -----ILJBBBBK----------- -------DHLEI------------ ------------------------ ------------------------ 
------------------------ ------------------------ ------------------------ ------------------------ ------------------------ ------------------------ ------------------------ ------------------------ ------------------------ ------------BN---------- ------------EJCC-------- -----------FHHIB-------- ----------FEHHHGF------- ----------FEEHHA-------- --------LLLFEHG--------- -------BLBBBHG---------- ------FFCNBBB-C--------- ----ECLEDLNFCCC--------- ---CJBLBJDNBBKBB-------- --JMBLDBBJBIDBI--------- -----BGDBJLDJJ---------- ------BCIDMKJC---------- -------BBBBBB----------- ------------------------ ------------------------ ------------------------ ------------------------ 
------------------------ ------------------------ ------------------------ ------------------------ ------------------------ ------------------------ ------------------------ ------------------------ ------------------------ ------------------------ ------------------------ ------------------------ ------------------------ ------------------------ ------------------------ --------LBB------------- -------BCNBL------------ -------BDLNB------------ ------CBJDNB-K---------- -----BCCBJBICB---------- ------BBCCCCB----------- -------HBBBB------------ ---------H-------------- ------------------------ ------------------------ ------------------------ ------------------------ 
------------------------ ------------------------ ------------------------ ------------------------ ------------------------ ------------------------ ------------------------ ------------------------ ------------------------ ------------------------ ------------------------ ------------------------ ------------------------ ------------------------ ------------------------ ------------------------ ------------------------ ------------------------ ------------------------ ------------------------ -------CC--------------- ------------------------ ------------------------ ------------------------ ------------------------ ------------------------ ------------------------ 
