model
size = 22 24 12, scale = 0.05, origin = -y
material 
  colors = A:#2C2F2C B:#565957 C:#3F3F3F D:#262626 E:#515551 F:#1F1F1F G:#070707 H:#4E4E4C I:#0F0F0F J:#464643 K:#4A4C46 L:#3A3C3A M:#323232 N:#161616 O:#000
voxels
---------------------- ---------------------- ---------------------- ---------------------- ---------------------- ---------------------- ---------------------- ---------------------- ---------------------- ---------------------- ---------------------- ---------------------- ---------------------- ------CAA------------- -----CAAAA------------ ----CAAAAA------------ -----AAAAA------------ -----AAAA------------- ------AA-------------- ---------------------- ---------------------- ---------------------- ---------------------- ---------------------- 
---------------------- ----------------EEF--- ---------------EEEFF-- ----------------EEGEF- ---------------AAEEEE- --------------AAAAIE-- --------------AAAA---- -------------AAAA----- ------------AAAA------ ----------AAAAA------- --------JCAAAA-------- ------BBCAAAAA-------- ----BBJCAAAAA--------- ----JBHAAAAAB--------- ---ABHAAAAAB---------- ---BHAAAAAJB---------- --BJAAAAACBB---------- --CAAAAAABB----------- --CAAAAABBE----------- ----FAABBB------------ -----CCBG------------- ---------------------- ---------------------- ---------------------- 
----------------EAA--- ---------------EEFAAA- ---------------EEEFAA- --------------CHIEEFA- -------------BCAAIIEE- ------------BCAAAACEE- -----------JCAAAAACE-- ----------LCCAAAAJC--- --------BECCAAAAKH---- -------JJBCAAAAEH----- ------CBECAAAAEH------ -----CEBCAAAAEEB------ ---CCBLCAAAAABO------- ---CB-CAAAAALJ-------- --JBB-----BBKB-------- --BAAA---AHBN--------- --BCA----JBGN--------- -BBFA---AEGG---------- -HBFF-AH-BBG---------- -CC-FFAHGNI----------- -----FBBGG------------ -----BHGI------------- -----C---------------- ---------------------- 
---------------EEEE--- ---------------EEEAAA- --------------BCEFFAE- --------------BCIIFFE- -------------BJAIIIEME ------------BBC---ICJ- ----------CBBA---BCEG- ---------CBBCA--HBN--- --------CCBCA--EHG---- ------CHCCC---ABID---- -----CCCC----AEGN----- ----CCC-C----HHO------ ---CCC------AHGD------ ---CD-------CCD------- --CDD-------CG-------- --B---------GG-------- -J---------GG--------- -HFF-----DCIG--------- -CFFF----DCG---------- -H--FFF--GG----------- -----FFING------------ -----MGIG------------- -----BEG-------------- ---------------------- 
---------------EKEE--- ---------------EFEE--- --------------BIEF--E- -------------BBIIIFFE- ------------BB---IIEFF -----------BB-----IIE- ----------BB-------BE- ---------BB-------D--- --------BB-------MJ--- ------BBBH------MJ---- -----BBMM-------J----- ----BB---------J------ ---BB---------MK------ --JH--------HHJ------- --C---------HDC------- -CC----------I-------- -C----------O--------- -CFF-------NG--------- -CFFF------G---------- -C--FFF--GGG---------- -----FFODDG----------- -----FGGDD------------ -----BOG-------------- ---------------------- 
---------------ELEE--- ---------------EFEE--- --------------BIEFF-E- -------------BBIIIFFE- ------------BB---IIEFE -----------BB-----IIE- ----------BB-------BE- ---------BB-------K--- -------BBB-------KK--- ------BBB-------KK---- -----BBB--------K----- ----BB---------K------ ---BB---------KK------ --BB----------K------- --B----------MK------- -CB----------D-------- -CF---------G--------- -JFFF------GG--------- -CFFFF-----G---------- -L--FFF---GG---------- ------F-KDD----------- -----FKCKK------------ -----JKG-------------- -----C---------------- 
----------------EEED-- ---------------EEEDDD- --------------CCEDFDE- --------------CCIIDFE- -------------CC--IIEEF -----------BCC----IEE- ----------BEC-----BBE- ---------BBC-----BE--- --------EBB------B---- ------HHBB------BK---- -----HHE-------BK----- ----EHH--------K------ ---HH---------JK------ ---H---------KK------- --B----------K-------- --B-A-------DD-------- -K-AA-------D--------- -CFFAAA----GG--------- -CF-FAAA--GO---------- -F--AFF--DG----------- ------F-KD------------ -----FBKK------------- -----CBK-------------- ---------------------- 
----------------EDED-- ----------------EFDDD- ---------------EEEFFD- --------------CHDEEMF- -------------CCDDDEEE- ------------CCDDDDBC-- -----------CCDDDDLJB-- ----------CCKDDDHCB--- --------BCCCDDDDCB---- -------BCCCDDDDCB----- ------BJCCDDDDCB------ ----BBBC----DCBB------ ---BBBC------BB------- ---BBC------BBB------- --EEC-------BB-------- --CCAA-----BB--------- -CCFAF----BBB--------- -CFAFFFA--BB---------- -CFAAFFA-BBD---------- -CAAAAAFBBD----------- --AAAAFBBE------------ ---AACCBE------------- -----CC--------------- ---------------------- 
---------------------- -----------------FF--- ----------------EEE--- ---------------CEEEE-- --------------CCDIEE-- -------------CCDDDJ--- ------------CCDDDCB--- -----------CCDDDCB---- ---------CCCDDDCB----- --------CCCDDDJJ------ ------CCCCDDDDJC------ -----CCCCDDDDCC------- ----CCCCDDDDCC-------- ----CCCDDDDDCJ-------- ---CCCDDDDDCC--------- --CCCADDDDCCB--------- --CCCFDDDJCB---------- --CBFFFDACB----------- --B--FFBCBB----------- -AAAA-BCJB------------ -AAAABCCB------------- --AABBCH-------------- ---AL----------------- ---------------------- 
---------------------- ---------------------- ---------------------- ---------------------- ---------------------- ---------------------- ---------------------- ---------------------- ---------------------- ---------------------- --------CCDD---------- -------CCDDD---------- ------CCDDDDC--------- -----CCDDDDCJ--------- ----CCDDDDCB---------- ----AHADDDJC---------- ---AABEADCC----------- ---B-ABACJ------------ --B---BBB------------- -BB---BH-------------- LAA--D---------------- AAAAHD---------------- -AAAE----------------- --AA------------------ 
---------------------- ---------------------- ---------------------- ---------------------- ---------------------- ---------------------- ---------------------- ---------------------- ---------------------- ---------------------- ---------------------- ---------------------- ---------------------- ---------------------- ---------------------- ----AB---------------- ---AAAB--------------- ---EAAJK-------------- --BBLAAA-------------- -BBBBBE--------------- BBDEED---------------- AADEDD---------------- AAAHH----------------- --AB------------------ 
---------------------- ---------------------- ---------------------- ---------------------- ---------------------- ---------------------- ---------------------- ---------------------- ---------------------- ---------------------- ---------------------- ---------------------- ---------------------- ---------------------- ---------------------- ---------------------- ---------------------- ---AJ----------------- --ABLB---------------- -ABBBBA--------------- EBDEEA---------------- BEDEBA---------------- -JFLL----------------- --NA------------------ 
