model
size = 14 17 32, scale = 0.05, origin = -y
material 
  colors = A:#CF3 B:#EEE C:#111
voxels
33-4B2(10-4A)191-2B2-2B8-BA2BAB7-3A2-3A7-6A8-6A9-4A162-8B6-B6AB2(6-2A4-2A)6-3A2-3A8-4A161-10B4-2B6-2B2(4-2A6-2A)5-3A2-3A7-6A160-10B4-B8-B4-A8-A4-2A6-2A4-4A2-4A6-6A159-12B2-BA8-AB2-2A8-2A3-A8-A2(4-3C)6-A4CA145-12B2-B10AB2-B10-B2(2-2A8-2A)3-3C4-3C5-3C2B3C144-12B2-B2A6-2AB2-B10-B2-A10-A2-2A8-2A3-2A6-2A5-2B4A2B144-12B-2B10-3BA10-AB-A10-A2-2A8-2A2-3A6-3A3-3B4A3B5-8C129-16B10-4B10-2B-2(A10-A2-)2A8-2A3-2A6-2A4-2(2C2A)2C5-3B2C3B115-15B12-3B10-2BAC10-CA-C10-C2-CA8-AC2-2A8-2A3-10A4-3B4C3B7-4C103-15B12-2B12-B2C10-2C-2(C10-C2-)2A8-2A2-4A4-4A3-10C4-10C100-15B3-A4-A3-BC12-3C10-2CBC10-CB-2(C10-C2-)2A8-2A3-10A4-B8AB5-3B2C3B87-15B2-2A4-2A2-BC2-2A4-2A2-2C12-CBC10-CB-2(C10-C2-)2A8-2A2-4A4-4A3-B8AB5-8C87-15B12-BC3-6A3-2C3-2A2-2A3-CBC10-C2BC10-CB2C10-2C-C10-C2-2A8-2A2-C3A4-3AC3-C3B2C3BC5-3B2C3B73-16B10-2BCB2-6A2-B2C3-6A3-CB3-6A3-2B12-B2C10-4C10-2C-C10-C2-3A6-3A2-A4C2-4CA3-10C6-6C8-CB2CBC47-12B-2B10-2BCB-8A-B3C-2A4-2A-2CB2-8A2-2B3-6A3-B2C4-2A4-2(4C10-)2C-A10-A2-C2A6-2AC2(2-2A2C4-2C2A)3-3(A2C)A6-2B2C2B33-12B2-B10-B2-C10AC-2C2A6-2A3C-3A4-3A-2C-10A-2C2-8A2-3C-8A-4C-8A-2C2A10-2A2C10-4CA8-A2C3A8-6A2C4-2C3A2-A2C4A2CA5-2C4A2C18-12B2-B10-B2-C10AC-2C2(A8-A4C)2A6-2A4C2A6-2A2CB-2(2A2-)2A-BC-10A-C2A2-6A2-3A12-2A12-3A10-5A8-7A6-4A-12A4-8C4-12B2-B10-B2-C10AC-2C2(A8-A4C)10-2(4CA8-A)4C3A4-3A2C14AC-10A-2C4-4A4-2C12-C2A10-4A10-6A2(-4A)-12A2-12B2-B10-B2-C10AC2-C2A6-2AC-BCA8-ACB2C2(A8-A4C)2A6-2A4C2A6-2A2C4A6-4AC5A2-5ACB12ABC2A2-4A2-2AC3A8-5A10-2(4A3-)2A-12A2-12B2-B10-B2-C-8A-C2-C2A6-2AC-2CA8-A3C-A8-A-2C-2A6-2A-CB-2A6-2A-BC-2A6-2A-CA-2A6-2A-AC-2A6-2A-CB-4A2-4A-BC12AC42A-12A2-12B2-B10-B2-B-8A-B2-C10AC-2CA8-A2CBC2A6-2ACBC-3A4-3A-2C2-2A4-2A2-CA2-2A4-2(2A2-)2A4-2A2-AC2-A6-A2-2C-2A6-2A-2C3A6-3AC3A8-5A10-2A29-12B2-B10-2(B2-)6A2-B2-12A2-C2A6-2AC-2C2A6-2A4C-2A4-2A-3C3-A4-A3-CA3-A4-A3-AC2-2A4-2A2-CA2-2A4-2A2-5A6-8A6-4A-2A8-2A44-12B2(2-B10-B)2-12A2-3A6-3A2-A-A6-2(A-)2A-2A4-2A-2(4A2-A4-A2-)2A2C2-A4-A2-2C2A-2A4-2A-6A6-4A-2A8-2A58-12B2-B10-B2-A10-A2-A-8A-A2-A-A6-A2(-A2-A-2A4-2A)-2(A2-)A4-A2-A-3(2A2-)2A2C2(2-2A)2-2C-A-3A2-3A-A2-4A4-4A72-12B2-BA8-AB2-2B8-2B2-3B6A3B2-3B6-3B2-C-BA4-AB-C2-B-BA4-AB-2(2(B2-)2(2A2-))B2-C3-A2-A3-C2-2C-2A2-2A-2C2(2-5A)4-3A2-3A61-10B3-2B8-2B2-2B8-2B3-2B6A2B3-3BA4-A3B2-C2B2A2-2A2BC2-2B-2A2-2A-2B2-2C-2A2-2A-2C2-2B2-4A2-2B2-2C2-4A2(2-2C)2-4A2-2C3-2A-4A-2A5-8A7-2A2-2A48-10B4-B8-B4-C8-C4-C-6A-C2(4-B-6A-B)4-B2-4A2-B4-CB-4A-BC4-2B-4A-2B4-CB2-2A2-BC4-CA2-2A2-AC4-3A-2A-3A5-8A7-2A2-2A48-10B4-2B6-2B4-CB6-BC4-CB2-2A2-BC4-2B2-2A2-2(2B4-2B6-)2B4-CB6-BC5-2(BA4-AB6-)3A2-3A6-3A2-3A7-6A63-8B6-2B4-2B6-2C4-2C4(6-3C2-3C)6-3C2A3C6-B6AB7-6A8-6A9-4A10-4A65-2(6B8-)2C2A2C8-6C9-C2AC10-4C2(10-C2AC)11-2C118-
