model
size = 14 17 32, scale = 0.05, origin = -y
material 
  colors = A:#CF3 B:#111 C:#EEE
voxels
33-2(4A10-)4A191-2A2-2A8-6A7-3A2-3A7-6A8-6A9-4A162-2(8A6-)2(2A4-2A6-)3A2-3A8-4A161-10A3(4-2A6-2A)5-3A2-3A7-6A160-10A2(4-A8-A)4-2A6-2A4-4A2-4A6-6A159-12A2(2-2A8-2A)3-A8-A2(4-3B)6-A4BA145-2(12A2-)A10-A2(2-2A8-2A)3-3B4-3B5-3B2C3B144-12A2-3A6-3A2(2-A10-A)2-2A8-2A3-2A6-2A5-2C4A2C144-12A-2A10-4A10-2A-A10-A2-2A8-2A2-3A6-3A3-3C4A3C5-8B129-14ABA10-AB2A10-2A-2(A10-A2-)2A8-2A3-2A6-2A4-2(2B2A)2B5-3C2B3C115-14AB12-B2A10-3AB10-BA-B10-B2-BA8-AB2-2A8-2A3-10A4-3C4B3C7-4B103-14AB12-BA12-A2B10-2B-2(B10-B2-)2A8-2A2-4A4-4A3-10B4-10B100-14AB3-A4-A3-BA12-A2B10-2BCB10-BC-2(B10-B2-)2A8-2A3-10A4-C8AC5-3C2B3C87-14AB2-2A4-2A2-BA2-2A4-2A2-AB12-BCB10-BC-2(B10-B2-)2A8-2A2-4A4-4A3-C8AC5-8B87-14AB12-BA3-6A3-AB3-2A2-2A3-BCB10-B2CB10-BC2B10-2B-B10-B2-2A8-2A2-B3A4-3AB3-B3C2B3CB5-3C2B3C73-16A10-4A2-6A2-2AB3-6A3-BC3-6A3-2C12-C2B10-4B10-2B-B10-B2-3A6-3A2-A4B2-4BA3-10B6-6B8-BC2BCB47-12A-2A10-4A-8A-2A2B-2A4-2A-2BC2-8A2-2C3-6A3-C2B4-2A4-2(4B10-)2B-A10-A2-B2A6-2AB2(2-2A2B4-2B2A)3-3(A2B)A6-2C2B2C33-12A2-B10-B2-12A-2B2A6-2A3B-3A4-3A-2B-10A-2B2-8A2-3B-8A-4B-8A-2B2A10-2A2B10-4BA8-A2B3A8-6A2B4-2B3A2-A2B4A2BA5-2B4A2B18-12A2-B10-B2-12A-2B2(A8-A4B)2A6-2A4B2A6-2A2BC-2(2A2-)2A-CB-10A-B2A2-6A2-3A12-2A12-3A10-5A8-7A6-4A-12A4-8B4-12A2-B10-B2-12A-2B2(A8-A4B)10-2(4BA8-A)4B3A4-3A2B14AB-10A-2B4-4A4-2B12-B2A10-4A10-6A2(-4A)-2(12A2-)B10-B2-12A2-B2A6-2AB-CBA8-ABC2B2(A8-A4B)2A6-2A4B2A6-2A2B4A6-4AB5A2-5ABC12ACB2A2-4A2-2AB3A8-5A10-2(4A3-)2A-2(12A2-)B10-B2-A-8A-A2-B2A6-2AB-2BA8-A3B-A8-A-2B-2A6-2A-BC-2A6-2A-CB-2A6-2A-BA-2A6-2A-AB-2A6-2A-BC-4A2-4A-CB12AB42A-2(12A2-)B10-B2-A-8A-A2-B10AB-2BA8-A2BCB2A6-2ABCB-3A4-3A-2B2-2A4-2A2-BA2-2A4-2(2A2-)2A4-2A2-AB2-A6-A2-2B-2A6-2A-2B3A6-3AB3A8-5A10-2A29-12A2-A10-2(A2-)6A2-A2-12A2-B2A6-2AB-2B2A6-2A4B-2A4-2A-3B3-A4-A3-BA3-A4-A3-AB2-2A4-2A2-BA2-2A4-2A2-5A6-8A6-4A-2A8-2A44-12A2(2-A10-A)2-12A2-3A6-3A2-A-A6-2(A-)2A-2A4-2A-2(4A2-A4-A2-)2A2B2-A4-A2-2B2A-2A4-2A-6A6-4A-2A8-2A58-12A2(2-A10-A)2-A-8A-A2-A-A6-A2(-A2-A-2A4-2A)-2(A2-)A4-A2-A-3(2A2-)2A2B2(2-2A)2-2B-A-3A2-3A-A2-4A4-4A72-12A2-2A8-2A2-2C8-2C2-3C6A3C2-3C6-3C2-B-CA4-AC-B2-C-CA4-AC-2(2(C2-)2(2A2-))C2-B3-A2-A3-B2-2B-2A2-2A-2B2(2-5A)4-3A2-3A61-10A3-2A8-2A2-2C8-2C3-2C6A2C3-3CA4-A3C2-B2C2A2-2A2CB2-2C-2A2-2A-2C2-2B-2A2-2A-2B2-2C2-4A2-2C2-2B2-4A2(2-2B)2-4A2-2B3-2A-4A-2A5-8A7-2A2-2A48-10A4-A8-A4-B8-B4-B-6A-B2(4-C-6A-C)4-C2-4A2-C4-BC-4A-CB4-2C-4A-2C4-BC2-2A2-CB4-BA2-2A2-AB4-3A-2A-3A5-8A7-2A2-2A48-10A4-2A6-2A4-BC6-CB4-BC2-2A2-CB4-2C2-2A2-2(2C4-2C6-)2C4-BC6-CB5-2(CA4-AC6-)3A2-3A6-3A2-3A7-6A63-8A6-2A4-2A6-2B4-2B4(6-3B2-3B)6-3B2A3B6-C6AC7-6A8-6A9-4A10-4A65-2(6A8-)2B2A2B8-6B9-B2AB10-4B2(10-B2AB)11-2B118-
