model
size = 32 8 32, scale = 0.05, origin = -y
material 
  colors = A:#080 B:#FFF C:#FFA500 D:#070 E:#960
voxels
2(E31-)E191-2D6A24-D9A22-D6-3A182-2D6A24-D11A20-D6-5A180-2D6A24-D11A20-D6-6A31-A2B30-2B113-2D6A24-D11A20-D6-6A31-A5B27-6B109-2D6A24-D11A20-D6-6A31-A5B27-8B30-3B74-2D6A24-D11A20-D6-6A31-A5B27-8B30-3B3C70-C2D6A24-D11A20-D6-6A31-A5B27-8B30-3B5C30-2C2-C13(32-2C2D6A24-D11A20-D6-6A31-A5B27-8B30-3B5C30-5C)32-2CE31-E8-3A20-E8-4A31-A5B27-8B30-3B5C30-5C32-2C2(E31-)E45-4B28-7B30-3B5C30-5C32-2C2(E31-)E47-2B30-5B30-3B5C30-5C32-2C2(E31-)E81-3B30-3B5C30-5C32-C-2(E31-)E117-5C30-5C34-6(2(E31-)E191-)
