model
size = 31 14 29, scale = 0.05, origin = -y
material 
  colors = A:#FF6905 B:#0A0000 C:#A0A0A0 D:#8F8F8F E:#F6D644 F:#828282 G:#6F6F6F H:#F28214 I:#F2AB14 J:#F29114 K:#FAEB88 L:#FDF4B9 M:#F3BC27 N:#A8A8A8 O:#FF5705 P:#A3A3A3 Q:#B9E7FD R:#B9B9B9 S:#4AA7F6 T:#1352F1 U:#FF3A05 V:#1224B0 W:#F23914 X:#ED2707 Y:#030303
voxels
---------BBBBB---BBBBB--------- -------------BB-BB------------- --------------B-B-------------- --------------BBB-------------- ---------------B--------------- ------------------------------- ------------------------------- ------------------------------- ------------------------------- ------------------------------- ------------------------------- ------------------------------- ------------------------------- ---------BBBBBBBBBBBBB--------- 
------BBBBCFGC---CFCGBBBB------ ------B--IJHABC-RBAHJI--B------ --------MIJHAOG-COAHJIM-------- -------EMIJHAOBGBOAHJIME------- ------KEMIJHAOUBUOAHJIMEK------ ------KEMIJHAOUXUOAHJIMEK------ ------KEMIJHAOUXUOAHJIMEK------ ------KEMIJHAOUXUOAHJIMEK------ ------KEMIJHAOUXUOAHJIMEK------ ------KEMIJHAOUXUOAHJIMEK------ -------EMIJHHAOUOAHHJIME------- --------MIJHHAOUOAHHJIM-------- ---------MIJHAOUOAHJIM--------- -------BBCDCFPFPFCFCGDBB------- 
------BBCNFDCD---RCDPDCBB------ ----BBBMMIJHABG-PBAHJIMMBBB---- ------EMMIJHAOC-GOAHJIMME------ -----KEEMIJHAOBCBOAHJIMEEK----- -----KKEMIJHAOUBUOAHJIMEKK----- -----LKEMIJHAOUXUOAHJIMEKL----- -----LKEMIJHAOUXUOAHJIMEKL----- -----LKEMIJHAOUXUOAHJIMEKL----- -----LKEMIJHAOUXUOAHJIMEKL----- -----LKEMIJHAOUXUOAHJIMEKL----- -----LKEMIJHHAOUOAHHJIMEKL----- ------KEMIJHHAOUOAHHJIMEK------ -------KEMIJHAOUOAHJIMEK------- -----BBBCGPDCNDFCDCDNCGBBB----- 
------RGNDGCRN---GDCGPDRC------ ---BBCBEEAAAABC-FBAAAAEEBCBB--- ---BLKKEAAAAAAG-RAAAAAAEKKLB--- ----LKKEAAAAAAAGAAAAAAAEKKL---- ----LKKEAAAAAAAAAAAAAAAEKKL---- ----QLKEAAAAAAAAAAAAAAAEKLQ---- ----QLKEAAAAAAAAAAAAAAAEKLQ---- ----QLKEAAAAAAAAAAAAAAAEKLQ---- ----QLKEAAAAAAAAAAAAAAAEKLQ---- ----QLKEAAAAAAAAAAAAAAAEKLQ---- ----QLKEAAAAAAAAAAAAAAAEKLQ---- -----LKEEAAAAAAAAAAAAAEEKL----- ---B-LKKEEAAAAAAAAAAAEEKKLBB--- ----BBGFFCGCFCFCDCFCCFCCNBB---- 
------PRGFCDCR---FRGFCRFD------ ---DCRBAAAAAABD-GBAAAAAABRCF--- --BBAAAAAAAAAAC-CAAAAAAAAAABB-- ---QAAAAAAAAAAACAAAAAAAAAAAQ--- ---QAAAAAAAAAAAAAAAAAAAAAAAQ--- ---QAAAAAAAAAAAAAAAAAAAAAAAQ--- ---SAAAAAAAAAAAAAAAAAAAAAAAS--- ---SAAAAAAAAAAAAAAAAAAAAAAAS--- ---SAAAAAAAAAAAAAAAAAAAAAAAS--- ---SAAAAAAAAAAAAAAAAAAAAAAAS--- ---SAAAAAAAAAAAAAAAAAAAAAAAS--- --BSQAAAAAAAAAAAAAAAAAAAAAQSB-- --BBQAAAAAAAAAAAAAAAAAAAAABBB-- ----CDCGDCDPDNCFCDNDFCDGCGC---- 
------RPDCFCRD---CDCDFGCF------ ---CFDBAAAAAABC-PBAAAAAABPRG--- -BBBAAAAAAAAAAG-GAAAAAAAAAABBB- -BSAAAAAAAAAAAACAAAAAAAAAAAASB- --SAAAAAAAAAAWAAAWAAAAAAAAAAS-- --TAAAAAAAAAAWXAXWAAAAAAAAAAT-- --TAAAAAAAAAAWWXWWAAAAAAAAAAT-- --TAAAAAAAAAAAWXWAAAAAAAAAAAT-- --TAAAAAAAAAAAWXWAAAAAAAAAAAT-- --TAAAAAAAAAAAWXWAAAAAAAAAAAT-- -BTAAAAAAAAAAAAWAAAAAAAAAAAATB- -BBAAAAAAAAAAAAWAAAAAAAAAAAABB- --NCBAAAAAAAAAAAAAAAAAAAAACCF-- ----GFDCFNFCGFDNDNCPCFPCDCF---- 
------GFRDGRCN---RCRCRFND------ ---DCRBAAAAAACD-FBAAAAAABDCD--- -GCBAAAAAAAHAAC-GAAHAAAAAAABCN- BBAAAAAAAAAHAABGBAAHAAAAAAAAABB -VAAAAAAAAAHA-BBB-AHAAAAAAAAAV- -VAAAAAAAAAHA--B--AHAAAAAAAAAV- -VAAAAAAAAAJH-----HJAAAAAAAAAV- -VAAAAAAAAAJH-----HJAAAAAAAAAV- -VAAAAAAAAAJH-----HJAAAAAAAAAV- -VAAAAAAAAAJH-----HJAAAAAAAAAV- BBAAAAAAAAAJH-----HJAAAAAAAAABB -GBAAAAAAAAJH-----HJAAAAAAAACF- --CDBAAAAAAAABBBBBAAAAAAAACGP-- ----CGPGDFDNFPGCNCNFGNCDCND---- 
------DNCNDPRD---NDNDCNCF------ ---PDCBAAAABBBP-PBBBAAAABPRC--- -FGBAAAAEIJ--BG-CB--JIEAAAABFD- BBAAAAAAEIJ---BCB---JIEAAAAAABB BBAAAAAAEIJ---BBB---JIEAAAAAABB BBAAAAAAEIJ----B----JIEAAAAAABB BBAAAAAALEI---------IELAAAAAABB BBAAAAAALEI---------IELAAAAAABB BBAAAAAALEI---------IELAAAAAABB BBAAAAAALEI---------IELAAAAAABB BBAAAAAALEI---------IELAAAAAABB -CBAAAAALEI---------IELAAAAABD- --DCBAAAAAABBBBBBBBBAAAAAACCD-- ----FDCFDCCBBBBBBBBBCFDCFCN---- 
------CFGDCDCN---RPRCGDNC------ ---DCGBABBBBBBF-GBBBBBBABRCD--- -DCBTSQL-----BC-CB-----LQSTBCF- -GAATSQL------BNB------LQSTAAG- -RAATSQL------BBB------LQSTAAD- -GAATSQL-------B-------LQSTAAG- -CAAVTSQ---------------QSTVAAD- -FAAVTSQ---------------QSTVAAF- -GAAVTSQ---------------QSTVAAD- -FAAVTSQ---------------QSTVAAC- -CAAVTSQ---------------QSTVAAG- -FBAVTSQ---------------QSTVACC- --CFBAAABBBB-------BBBBAAAAGP-- ----DCNCBBBB-------BBBBGNDR---- 
------BBBBBBBB---BBBBBBBB------ ---BBBBBBB---BB-BB---BBBBBBB--- -BBBB---------B-B---------BBBB- -FBY----------BBB----------YBF- --BB-----------B-----------BB-- -DBB-----------------------BBC- --BB-----------------------BB-- -CBB-----------------------BBP- --BB-----------------------BB-- -CBB-----------------------BBD- -BYB-----------------------BBB- -BBBB---------------------BYBB- --BBBBBBB-------------BBBBBBB-- ----BBBBB-------------BBBBB---- 
------------------------------- ------------------------------- ------------------------------- -P---------------------------D- -G---------------------------C- -F---------------------------D- -C---------------------------F- -F---------------------------G- -C---------------------------C- -F---------------------------N- ------------------------------- ------------------------------- ------------------------------- ------------------------------- 
------------------------------- ------------------------------- ------------------------------- -D---------------------------G- -B---------------------------B- -B---------------------------B- -B---------------------------B- -C---------------------------B- -B---------------------------B- -C---------------------------C- ------------------------------- ------------------------------- ------------------------------- ------------------------------- 
------------------------------- ------------------------------- ------------------------------- -R---------------------------C- -B---------------------------B- -G---------------------------R- -B---------------------------C- -F---------------------------R- -B---------------------------B- -G---------------------------D- ------------------------------- ------------------------------- ------------------------------- ------------------------------- 
------------------------------- ------------------------------- ------------------------------- -C---------------------------R- -B---------------------------B- -D---------------------------C- -B---------------------------R- -B---------------------------P- -B---------------------------B- -P---------------------------C- ------------------------------- ------------------------------- ------------------------------- ------------------------------- 
------------------------------- ------------------------------- ------------------------------- -P---------------------------R- -C---------------------------C- -N---------------------------F- -F---------------------------D- -C---------------------------G- -N---------------------------C- -D---------------------------G- ------------------------------- ------------------------------- ------------------------------- ------------------------------- 
------------------------------- ------------------------------- ------------------------------- -D---------------------------C- -B---------------------------B- -P---------------------------B- -D---------------------------B- -P---------------------------B- -D---------------------------B- -G---------------------------D- ------------------------------- ------------------------------- ------------------------------- ------------------------------- 
------------------------------- ------------------------------- ------------------------------- -P---------------------------D- -B---------------------------P- -D---------------------------C- -C---------------------------B- -D---------------------------F- -C---------------------------B- -P---------------------------N- ------------------------------- ------------------------------- ------------------------------- ------------------------------- 
------------------------------- ------------------------------- ------------------------------- -G---------------------------C- -B---------------------------B- -B---------------------------B- -B---------------------------F- -B---------------------------B- -B---------------------------B- -D---------------------------R- ------------------------------- ------------------------------- ------------------------------- ------------------------------- 
------------------------------- ------------------------------- ------------------------------- -D---------------------------F- -D---------------------------G- -P---------------------------D- -D---------------------------N- -G---------------------------F- -N---------------------------G- -D---------------------------F- ------------------------------- ------------------------------- ------------------------------- ------------------------------- 
------------------------------- ------------------------------- ------------------------------- -C---------------------------D- -B---------------------------P- -N---------------------------F- -B---------------------------B- -N---------------------------B- -B---------------------------B- -C---------------------------D- ------------------------------- ------------------------------- ------------------------------- ------------------------------- 
------------------------------- ------------------------------- ------------------------------- -GC-------------------------CC- -BB-------------------------BB- -PB-------------------------BB- -BB-------------------------BB- -DB-------------------------CF- -BB-------------------------CC- -NC-------------------------CG- ------------------------------- ------------------------------- ------------------------------- ------------------------------- 
------------------------------- ------------------------------- ------------------------------- --CC-----------------------CC-- --BC-----------------------CC-- --BC-----------------------CD-- --BC-----------------------CB-- --BC-----------------------BB-- --BC-----------------------BB-- --GD-----------------------CF-- ------------------------------- ------------------------------- ------------------------------- ------------------------------- 
------------------------------- ------------------------------- ------------------------------- ---CD---------------------CD--- ---CB---------------------CF--- ---GB---------------------CC--- ---CC---------------------CC--- ---RB---------------------CF--- ---CB---------------------CG--- ---RC---------------------CD--- ------------------------------- ------------------------------- ------------------------------- ------------------------------- 
------------------------------- ------------------------------- ------------------------------- ----CC-------------------CC---- ----BC-------------------BB---- ----BB-------------------BB---- ----RB-------------------BB---- ----BB-------------------BB---- ----BC-------------------BB---- ----CD-------------------CC---- ------------------------------- ------------------------------- ------------------------------- ------------------------------- 
------------------------------- ------------------------------- ------------------------------- -----FD-----------------CD----- -----CB-----------------CF----- -----BB-----------------CD----- -----BC-----------------BB----- -----BB-----------------BF----- -----CB-----------------BB----- -----FC-----------------CF----- ------------------------------- ------------------------------- ------------------------------- ------------------------------- 
------------------------------- ------------------------------- ------------------------------- ------CC---------------CC------ ------BC---------------CD------ ------BC---------------CF------ ------GC---------------CB------ ------BC---------------CB------ ------BC---------------CB------ ------CD---------------CC------ ------------------------------- ------------------------------- ------------------------------- ------------------------------- 
------------------------------- ------------------------------- ------------------------------- -------DC-------------CF------- -------CB-------------CC------- -------NB-------------CD------- -------DB-------------CC------- -------CB-------------CD------- -------DB-------------BC------- -------CC-------------CG------- ------------------------------- ------------------------------- ------------------------------- ------------------------------- 
------------------------------- ------------------------------- ------------------------------- --------CDC---------CDC-------- --------BBB---------CBD-------- --------BDB---------CBF-------- --------BPB---------CBD-------- --------BRB---------CBC-------- --------BBB---------BBB-------- --------PCC---------CGF-------- ------------------------------- ------------------------------- ------------------------------- ------------------------------- 
------------------------------- ------------------------------- ------------------------------- ----------PDNDNDGNCDF---------- ----------BCNBGFBBBGC---------- ----------BDBCBPBCBCD---------- ----------BNBPBCBDBDG---------- ----------BCBNBDBCBNR---------- ----------BDBGBDBBBGB---------- ----------DCGDCPDGCDC---------- ------------------------------- ------------------------------- ------------------------------- ------------------------------- 
