model
size = 32 21 32, scale = 0.05, origin = -y
material 
  colors = A:#6F6F6F B:#B1C0FF
voxels
109-6A22-14A18-14A22-6A568-10A18-18A14-18A16-14A22-6A504-10A18-3A-10A-3A13-20A12-8A4-8A13-18A16-14A497-16A14-20A10-2(8A8-)6A12-6A10-20A13-5A-6A-5A20-6A27-4B29-2B379-8A19-4A-8A-4A11-24A8-5A14-5A8-4A16-4A8-10A4-10A10-8A4B8A15-2A10B2A20-10B22-10B23-8B25-6B310-14A15-20A10-9A6-9A8-4A16-4A8-3A18-3A8-6A12-6A9-6A10B6A13-A6B2-6BA17-14B18-14B19-12B21-10B23-8B25-6B245-16A13-22A8-7A12-7A6-4A18-4A6-4A19-3A7-5A14-5A8-6A12B6A11-A2B-B8AB-2BA16-B-2B6-2B-B18-4B6-4B18-5B4-5B18-14B19-4B-2B-4B21-10B23-8B27-2B155-8A19-4A-8A-4A11-24A6-7A14-7A4-5A18-5A4-4A20-4A5-5A16-5A6-4A18B4A9-A3B12A3BA13-3B12-3B14-4B10-4B14-3B-B8-B-3B16-2B-B6-B-2B18-5B-2B-5B18-14B19-12B22-8B26-4B119-14A15-20A9-26A6-5A16-5A5-4A20-4A4-3A22-3A5-5A16-5A6-4A18B4A8-A3B14A3BA11-5(4B12-)4B13-4B10-4B14-3B12-3B15-16B17-6B2-6B19-12B22-8B116-16A13-22A8-7A-2A6-2A-7A6-5A16-5A4-4A22-4A2-3A24-3A3-5A18-5A4-5A18B5A6-A3B16A3BA9-3B16-3B10-3B16-3B11-3B14-3B2(12-4B)13-3B12-3B14-4B10-4B15-5B6-5B17-6B2-6B20-10B24-6B85-16A13-22A7-8A12-8A4-5A18-5A3-3A24-3A2-3A24-3A3-4A20-4A4-4A20B4A6-A2B18A2BA9-2(2B18-2B10-)3B16-3B11-2B16-2B2(12-4B)13-3B12-3B14-3B12-3B16-14B19-12B21-10B24-6B52-18A11-24A6-7A14-7A4-4A20-4A3-3A24-3A2-2A26-2A3-3A22-3A4-3A22B3A7-B-18A-2(B10-B20-)B10-2B18-2B10-3B16-3B11-3B14-3B2(12-4B)13-3B12-3B16-2B10-2B18-5B-2B-5B19-12B23-6B52-18A11-24A6-7A14-7A4-4A20-4A3-2A26-2A2-2A26-2A3-3A22-3A4-3A22B3A7-B20A3(B10-B20-)B10-2B18-2B10-3B16-3B11-3B14-3B2(12-4B)13-3B12-3B16-5B4-5B18-14B20-10B50-18A11-24A6-6A16-6A2-A-3A22-3A-4A26-6A26-3A-4A22-4A2-A-2A22B2A-A4-A2B20A2BA8-4(B20-B10-)2B18-2B10-3B16-3B11-3B14-3B13-4B10-4B16-4B6-4B18-14B19-12B23-6B20-18A11-10A4-10A6-6A16-6A2-A-3A22-3A-4A26-5A28-2A-3A24-3A2-A-A24BA-A4-A2B20A2BA7-2B20-2B8-2B20-2B9-2(B20-B10-)2B18-2B10-3B16-3B11-3B14-3B13-3B12-3B15-2B-B8-B-2(2B17-5B4-5B19-12B23-6B20-18A11-10A4-10A6-6A16-6A2-A-3A22-3A-4A26-5A28-2A-3A24-3A2-A-A24BA-A4-A2B20A2BA7-2B20-2B8-2B20-2B9-3(B20-B10-)3B16-3B11-3B14-3B2(12-4B)14-2B12-)2B17-5B4-5B19-12B23-6B20-18A11-10A4-10A6-6A16-6A2-A-3A22-3A-4A26-5A28-2A-3A24-3A2-A-A24BA-A4-A2B20A2BA7-2B20-2B8-2B20-2B9-2(B20-B10-)2B18-2B10-3B16-3B11-3B14-3B13-3B12-3B15-2B-B8-B-2B17-5B4-5B19-12B23-6B20-18A11-24A6-6A16-6A2-A-3A22-3A-4A26-6A26-3A-4A22-4A2-A-2A22B2A-A4-A2B20A2BA8-4(B20-B10-)2B18-2B10-3B16-3B11-3B14-3B13-4B10-4B16-4B6-4B18-14B19-12B23-6B20-18A11-24A6-7A14-7A4-4A20-4A3-2A26-2A2-2A26-2A3-3A22-3A4-3A22B3A7-B20A3(B10-B20-)B10-2B18-2B10-3B16-3B11-3B14-3B2(12-4B)13-3B12-3B16-5B4-5B18-14B20-10B50-18A11-24A6-7A14-7A4-4A20-4A3-3A24-3A2-2A26-2A3-3A22-3A4-3A22B3A7-B-18A-2(B10-B20-)B10-2B18-2B10-3B16-3B11-3B14-3B2(12-4B)13-3B12-3B16-3B8-3B18-5B-2B-5B19-12B23-6B53-16A13-22A7-8A12-8A4-5A18-5A3-3A24-3A2-3A24-3A3-4A20-4A4-4A20B4A6-A2B18A2BA9-2(2B18-2B10-)3B16-3B11-2B16-2B2(12-4B)13-3B12-3B14-3B12-3B16-14B19-12B21-10B24-6B53-16A13-22A8-7A-2A6-2A-7A6-5A16-5A4-4A22-4A2-3A24-3A3-5A18-5A4-5A18B5A6-A3B16A3BA9-3B16-3B10-3B16-3B11-3B14-3B2(12-4B)13-3B12-3B14-4B10-4B15-5B6-5B17-6B2-6B20-10B24-6B86-14A15-20A9-26A6-6A15-5A5-4A20-4A4-3A22-3A5-5A16-5A6-4A18B4A8-A3B14A3BA11-5(4B12-)4B13-4B10-4B14-3B12-3B16-14B18-6B2-6B19-12B22-8B120-8A19-4A-8A-4A11-24A6-7A14-7A4-5A18-5A4-4A20-4A5-5A16-5A6-4A18B4A9-A3B12A3BA13-3B12-3B14-4B10-4B14-3B-B8-B-3B16-2B-B6-B-2B18-5B-2B-5B18-14B19-12B22-8B26-4B150-16A13-22A8-7A12-7A6-4A18-4A6-3A20-3A7-5A14-5A8-6A12B6A11-A2B-B8AB-2BA16-B-2B6-2B-B18-4B6-4B18-5B4-5B18-14B19-4B-2B-4B21-10B23-8B27-2B184-14A15-20A10-9A6-9A8-4A16-4A8-3A18-3A8-6A12-6A9-6A10B6A13-A6B2-6BA17-14B18-14B19-12B21-10B23-8B25-6B249-8A19-4A-8A-4A11-24A8-5A14-5A8-4A16-4A8-10A4-10A10-8A4B8A15-2A10B2A20-10B22-10B23-8B25-6B341-16A14-20A10-2(8A8-)6A12-6A10-20A13-5A-6A-5A20-6A27-4B29-2B410-10A18-3A-10A-3A13-20A12-8A4-8A13-18A16-14A532-10A18-18A14-18A16-14A22-6A538-6A22-14A18-14A22-6A461-
