model
size = 25 19 23, scale = 0.05, origin = -y
material 
  colors = A:#84492C B:#FEAE89 C:#000 D:#A17A43 E:#FEEA41 F:#A9523A G:#FF8CDF H:#562E17 I:#94453E J:#037C30 K:#8E695F L:#C34B29 M:#FFF N:#ED00A8 O:#1E1729
voxels
------------------------- ------------------------- ------------------------- ------------------------- ------------------------- ------------------------- ------------------------- ------------------------- ------------------------- ------------------------- ------------------------- ----------BB------------- ------------------------- ------------------------- ------------------------- ------------------------- ------------------------- ------------------------- ------------------------- 
------------------------- ------------------------- ------------------------- ------------------------- ------------------------- ------------------------- ------------------------- ------------------------- ------------------------- ---------C--------------- -------C-C--------------- ------CC-CB-B------------ -----C-C-C--------------- -------C----------------- -------C--C-------------- -------CC-C-C------------ ---------CCC------------- ---------C--------------- ------------------------- 
------------------------- ------------------------- ------------------------- ------------------------- ------------------------- ------------------------- ------CCC---------------- -----CCC----------------- -----CCB-C--------------- ------CBBBBBBBBBB-------- -----CCCBBBBBBBBBBBBB---- ---C-CABBBBBABBBBBBBB---- -----CABBBBBBBBBBBBBB---- ------CB-CBBBBB---------- ------CCCC-CC-B---------- -------CCC-C------------- ------------------------- ---------CC-------------- ------------------------- 
------------------------- ------------------------- ------------------------- ------------------------- ----------C-------------- ------CCCCBCC------------ -----CAAABBBBBBBBB------- ----CAAABBBBBBBBBB------- ----CAAABBBBBBBBBB------- ---CCCACBBBBBCCBDBBBB---- ---CCCABBBBCCCCCDDDBBB--- ---C-CAABBAAAAAABBBBBB--- -----CAABBAAAAABBBBBBB--- -----CAABBAAAAABBBBBBB--- -C----BAAACAACBB---BBB--- ------BBAACAC------------ -------CCHHLC------------ --------C---C------------ ------------------------- 
------------------------- ------------------------- -----------C------------- ----------CB------------- --------CCBB-----BBB----- -----CCCAAABCBBBBBBB----- ----CAAAAABABAAAAABB----- ---CAAAAAABBBAAAAABB----- ---CAAAABBBABAAAAABB----- --CACAACCBCCCCCCDDAABB--- --CACAACCCCCCCCCDDDABB--- --CCCAAEEEEEEEEEDDDABB--- --CCCAAEEEEEEEAAAAAAAB--- -CC-CBAMMMMMMAAAAAAAAB--- -C---BAMA--AACBBBBBBBBB-- -----BBBAAAAJCBBBBBBBB--- -------BAHHLLC----------- --------C----C----------- ------------------------- 
------------------------- -----------C------------- ----------CBC------------ ---------CBABBBB-B------- -------CCAABBBBBBABB----- -----CCAAAAABAABAAAAB---- ---CCAAAAAAAAAAAAABBBB--- --CAAAAAAAAAAAAAAAABBB--- --CAAAAAAAAAAAAAAAABBB--- ---CCCCCCCCCCCCCDDDAAB--- ---CCCCCCCCCCCCCDDDDBBB-- --CFF-EEEEEEEEEKDDDDBBBB- -CCAAAAAAAAAAAAAAADDDBBB- -CCCAAAAAAAAAAAAAAAAIBBB- ----CAAAAAAAACBBBBBBBBBB- ----CBBBAHAAJCBBBBBBBBB-- -----BBBAHHLLC--BB------- -----CC-C----C----------- ------------------------- 
-----------C------------- --------C-CCC------------ --------CCBBBBBB--------- --------CCAAAAABBBBB----- ------CCAAAABAABAAAAB---- -----CCAAAAAAAAAAAAAAB--- ---CCAAAAAAAAAAAAAABBB--- --CAAAAAAAAAAAAAAAABBB--- --CAAAAAAAAAAAAAAAABBB--- ---CCCCCCCCCCCCCDDDDAB--- ---CCCCCCCCCCCCCDDDDBBBB- --CFFFEEEEEEEEEKDDDDBBBB- -CCAAAAAAAAAAAAADDDDDBBB- -C-CAAAAAAAAAAAAAAAIIBBB- ----CAAAAAIAACBBBBBBBBBB- -----BBBAA-AJCBBBBBBBBBB- ------BBAHHLLCBBBBBBBBB-- --------C----C----------- ------------------------- 
------------------------- -----------CC------------ --------CCCBBGGG--------- --------CCAABAAAGGBG----- -----CCCAAAAAAABABBAG---- -----CCAAAAAAAAAAAAAAG--- ---CCAAAAAAAAAAAAAAAAB--- --CAAAAAAAAAAAAAAAAAAB--- -CAAAAAAAAAAAAAAAAAAAB--- --CCCCCCCCCCCCCCDDDDDB--- --CCCCCCCCCCCCCCDDDDBBBG- C-CFFFFEEEEEEEKKDDDDBBBB- -CCAAAAAAAAAAAAADDDDDABB- ---CAAAAAAAAAAAAAAAIIABB- ----CAAAAAAAACBBBBBBBBBB- -----BBBAAAAJCBBBBBBBBBB- ------BBAHHLLCBBBBBBBBBB- --------C----C----------- ------------------------- 
------------------------- -----------CC------------ -------CCCCBBGBG--------- -------CCCAABAAABGBG----- -----C-CAAAAAAA-ABAAB---- -----CCAAAAAAAAAAAAAAB--- ---CCAAAAAAAAAAAAAAAAB--- --CAAAAAAAAAAAAAAAAAAB--- -CAAAAAAAAAAAAAAAAAAAB--- -CCCCCCCCCCCCCCCDDDDDB--- ---CCCCCCCCCCCCCDDDDBBBG- C-CFFFFEEEEEEEKKDDDDBBBB- -CAAAAAAAAAAAAAADDDDDAAB- --CCAAAAAAAAAAAAAAAIIAAB- ----CCAAAAAAACBBBBBBBBBBB -----BBBAAAAC-BBBBBBBBBBB ------BBCHHL-CBBBBBBBBBB- -------------C----------- ------------------------- 
-----------C------------- -----------CC------------ -------CCCCCBGBG--------- --------CCAABAAABGBG----- -----C-CAAAAAAA-BAAAG---- -----CCAAAAAAAAAAAAAAG--- --CCCAAAAAAAAAAAAAAAAB--- --CAAAAAAAAAAAAAAAAAABG-- -CAAAAAAAAAAAAAAAAAAABB-- CCCCCCCCCCCCCCCCDDDD-BB-- CCCCCCCCCCCCCCCCDDDDBBBB- CCFFFFFFEEEEEEKKDDDDBBBB- CAAAAAAAAAAAAAAADDDDDAAB- -CCCAAAAAAAAAAAAAAAIIAAB- ---CCCCAAAAAAABBBBBBBBBBB -----BBBCCCCCABBBBBBBBBBB ------BBC-CCCBBBBBBBBBBB- ----------CCC--------N--- ------------------------- 
------------------------- ---------C-CC------------ -------CCCCCCBBB--------- --------CCAAAAAABBBB----- ------CCAAAAAAA-BABBB---- -----CCAAAAAAAAAAAAAAB--- --CCCAAAAAAAAAAAAAAAAB--- --CAAAAAAAAAAAAAAAAAABB-- -CAAAAAAAAAAAAAAAAAAABB-- CCCCCCCCCCCCCCCCDDDD-BB-- CFCCCCCCCCCCCCCCDDDDBBBB- -CFFFFFFEEEEEEKKDDDDBBBB- CAAAAAAAAAAAAAAADDDDDAAB- -CCCAAAAABAAAAAAAAAIIAAB- ---CCCCCCBBAAABBBBBBBBBBB ----CBBBCBBBBEBBBBBBBBBBB ------BB---BBBBBBBBBBBBB- ---------------BB----N--- ---------------BB-------- 
------------------------- ---------C-CCC----------- -------CCCCCCCBB--------- --------CCAAAAAABBBB----- ------CCAAAAAAA-BBBAB---- -----CCAAAAAAAABAAAAAB--- --CCCAAAAAAAAAAAAAAAAB--- --CAAAAAAAAAAAAAAAAAABB-- -CAAAAAAAAAAAAAAAAAAABB-- CCCCCCCCCCCCCCCCDDDDDBB-- -CCCCCCCCCCCCCCCDDDDBBBB- -CFFFFFFEEEEEEKKDDDDBBBB- CAAAAAAAAAAAAAAADDDDDAAB- -CCCAAAAAAAAAAAAAAAIIAAB- ---CCCCCC--AAABBBBBBBBBBB ---CCBBB-CCCCEBBBBBBBBBBB ----CBBB-CC--BBBBBBBBBBB- -----CCC--CC---BB----N--- ---------------BB-------- 
------------------------- -----------CC------------ -------CCCCCCGGG--------- --------CCAAAAAAGGBB----- ------CCAAAAAAB-BAAAB---- -----CCAAAAAAAABAAAAAB--- --CCCAAAAAAAAAAAAAAAAB--- --CAAAAAAAAAAAAAAAAAABB-- -CAAAAAAAAAAAAAAAAAAABB-- CCCCCCCCCCCCCCCCDDDA-BB-- -CCCCCCCCCCCCCCCDDDD-BBB- -CFFFFFFEEEEEEKKDDDD-BBB- CAAAAAAAAAAAAAAADDDD-BBB- -CCCAAAAAAAAAAAAAAAI-BBB- ---CCCCAAAAAA--BBBBB-BBBB ----CBBBCHJJJJBBBBBB-BBBB ------BB-HHLCJBBBBBBBBBB- ------------CC-------N--- ------------------------- 
------------------------- -----------CC------------ -------CCCCCBBBG--------- --------CCAAAAABBBBG----- ------CCAAAAAAB-BAAAG---- ---C-CCAAAAAAAABAAAAAG--- --CCCAAAAAAAAAAAAAAAAB--- --CAAAAAAAAAAAAAAAAAAB--- -CAAAAAAAAAAAAAAAAAAAB--- -CCCCCCCCCCCCCCCDAAA-B--- -CCCCCCCCCCCCCCCDDDDABBG- -CFFFFFFEEEEEEKKDDDDABBB- CAAAAAAAAAAAAAAADDDDABBB- -CCCAAAAAAAAAAAAAAAIABBB- ---CCCAAAAA--ABBBBBBBBBBB -----BBBAAJJ---BBBBBBBBBB ------BBCHHLLJBBBBBBBBBB- -------------C----------- ------------------------- 
------------------------- -----------CC------------ --------CCCBBGGG--------- --------CCAABBBBBBBB----- ------CCCAAAABB-BAAAB---- -----CCAAAAAAAABAAAABB--- ----CAAAAAAAAAAAAAAAAB--- --CCAAAAAAAAAAAAAAAAAB--- -CAAAAAAAAAABBAAAAAAAB--- --CCCCCCCCCCCCCCDAAA-B--- -CCCCCCCCCCCCCCCDDDDABB-- -CFFFFFFEEEEEEKKDDDDABBB- -CAAAAAAAAAAAAAADDDDABBB- --CCAAAAAAAAAAAAAAAAABBB- ----CAAAAAA--ABBBBBBBBBB- ----CBBBAAJJJ--BBBBBBBBB- -----BBBAHHLL-BBBBBBBBBB- -----C--C----C----------- ------------------------- 
------------------------- ------------------------- ---------CCCC------------ --------CCCBB-BBBB------- -------CCABBB-B--BBB----- -----CCAAABBBBBBBAAB-B--- ----CAAAAABBBABBAAAABB--- ---CCAAAAAAAAABAAAAABB--- --CAAAAAAAA----AAAAABB--- --CCCCCCCCCCCCCCAAAAAB--- -CCCCCCCCCCCCCCCDDDDDBB-- -CFFFFFFEEEEEEEKDDDDDBBB- --CAAAAAAAAAAAAADDDDDBBB- ---CAAAAAAAAAAAAAAAAABBB- ----CAAAAAA--ABBBBBBBBBB- -----BBBAHJJJJ-BBBBBBBBB- -----BBBAHHLLJBBBBBBBBB-- -----CC-C----C----------- ------------------------- 
------------------------- ------------------------- ------------------------- --------CCC---B---------- --------CC-C--B--BBB----- ------CCAB-CCBBBBBBB----- -----CAAABCCBBBBBBBB----- ---CCAAAAABBBBBBBBBB----- --CAAAAAAAA---BABBBB----- --CCCCCCCCCBBBCCAAAABBB-- --CCCCCCCCCCCCCCDDDDDDB-- --C-FFFEEEEEEEEKDDDDDDB-- --CAAAAAAAAAAAAADDDDDDDB- ---CAAAAAAAAAAAAAAAAAAAB- ----CAAAAAAA-ABBBBBBBBBB- -----BBBAHJJJCBBBBBBBBB-- -----BBBAHHLLC--BB------- -----CC-C----C----------- ------------------------- 
------------------------- ------------------------- ------------------------- ---------C--------------- --------CC--------------- ------CCCCCC--B-B-------- -----CAAABCCC--B--------- ----CAAAAABBBBBB--------- ---CAAAAAABBBBBB--------- ---CCCCCCCCBBBCABBBBBBB-- ---CCCCCCCCCBCCCCACCCCB-- --CFFFFEEEEEEEEEEKKIIIB-- --CAAAAAAAAAAAAAAAAIIIB-- ---CAAAAAAAAAAAAAAAAAAAB- ----CAAAAAAAABBBBBBBBBB-- ----CBBBAAJJJC----------- -----CBBAHHLJC----------- ------C-C---CC----------- ------------C------------ 
------------------------- ------------------------- ------------------------- ------------------------- --------CCCC------------- ------CCCCBB------------- -----CAAAABBBB----------- ----CAAAABBBBB----------- ----CAAAABABBBB---------- ---CCCCCCCCCBCCBBBBBBBB-- ---CCCCCCCCCCCCCCACCCCB-- ---CFFAAEEEEEEEEEKKIIIB-- CCCCAAAAEEEEEEAAAKKIIBB-- ---CAAAAMMMMMBABBBBBBBB-- ----CCBAAAABB-BB---BB---- ----C-BBAAAAC------------ --------CCCCC------------ --------CCCCC------------ ------------------------- 
------------------------- ------------------------- ------------------------- ------------------------- ------------------------- ----------C-------------- ------CCCCBB------------- -----CCCCBBB------------- ----CCACCBBB------------- ---CAACABACBBBBBBB------- ---CAAAABBBBBBBBBBBBBB--- ---CCCCCABBBBBBBBBBBBB--- ---CCCCCABBBBBBBBBBBBB--- ----CCCCAABBBBB---------- ------CBABB---B---------- -------CCCCC------------- ------------------------- ----------C-------------- ------------------------- 
------------------------- ------------------------- ------------------------- ------------------------- ------------------------- ------------------------- ------------------------- ------------------------- ------C--C--------------- ----CCAC-CB-B------------ ----CCCC-C--------------- -----C--OC--------------- --------CC--------------- --------CC--------------- -------CC---------------- --------CCCC------------- ------------------------- ------------------------- ------------------------- 
------------------------- ------------------------- ------------------------- ------------------------- ------------------------- ------------------------- ------------------------- ------------------------- ------------------------- ------C---BB------------- ------------------------- -----C-CC---------------- ------------------------- ------------------------- ------------------------- ----------C-------------- ------------------------- ------------------------- ------------------------- 
------------------------- ------------------------- ------------------------- ------------------------- ------------------------- ------------------------- ------------------------- ------------------------- ------------------------- ------------------------- ------------------------- -----C-C----------------- ------------------------- ------------------------- ------------------------- ------------------------- ------------------------- ------------------------- ------------------------- 
