model
size = 28 26 3, scale = 0.05, origin = -y
material 
  colors = A:#122829 B:#06373A
voxels
-----A---------------------- --ABAA-----BAA--BB----A--AA- -AB-----AA--A---A---AAA---AA AA-----ABAA-A---A--AA-A---BA AA-----A--A-A---A-AA--A--AB- -AAA---BAAA-A--AAAA---A--A-- --BBAA--BB-----AB-----AA-BAA -----A------A----------A---A ---------------------------- --------------A--AAA-------- -------AA-----A---A--------- -------AA--A-AA---A--------- --------A--A-A----A--------- --------A--A-A---AAA-------- --------A-AAAA--AA-AA------- --------AAA-BA-AA---A------- ------AAAA--BA-A----AA------ ---------------------------- ---------------------------- ---------------------------- A--A-A--AAA----AAA---------- A--A-A---A----AB-BA--------- AA-A-A---A----A---AAABBBAAAA AAAAAA--AAA---A---A----AAABB AAA--A-AA-A---AA-AA----A-B-B A-----AA--AA--BAAA-----B-B-- 
-----A---------------------- --ABAA-----BAA--BB----A--AA- -AB-----AA--A---A---AAA---AA AA-----ABAA-A---A--AA-A---BA AA-----A--A-A---A-AA--A--AB- -AAA---BAAA-A--AAAA---A--A-- --BBAA--BB-----AB-----AA-BAA -----A------A----------A---A ---------------------------- --------------A--AAA-------- -------AA-----A---A--------- -------AA--A-AA---A--------- --------A--A-A----A--------- --------A--A-A---AAA-------- --------A-AAAA--AA-AA------- --------AAA-BA-AA---A------- ------AAAA--BA-A----AA------ ---------------------------- ---------------------------- ---------------------------- A--A-A--AAA----AAA---------- A--A-A---A----AB-BA--------- AA-A-A---A----A---AAABBBAAAA AAAAAA--AAA---A---A----AAABB AAA--A-AA-A---AA-AA----A-B-B A-----AA--AA--BAAA-----B-B-- 
-----A---------------------- --ABAA-----BAA--BB----A--AA- -AB-----AA--A---A---AAA---AA AA-----ABAA-A---A--AA-A---BA AA-----A--A-A---A-AA--A--AB- -AAA---BAAA-A--AAAA---A--A-- --BBAA--BB-----AB-----AA-BAA -----A------A----------A---A ---------------------------- --------------A--AAA-------- -------AA-----A---A--------- -------AA--A-AA---A--------- --------A--A-A----A--------- --------A--A-A---AAA-------- --------A-AAAA--AA-AA------- --------AAA-BA-AA---A------- ------AAAA--BA-A----AA------ ---------------------------- ---------------------------- ---------------------------- A--A-A--AAA----AAA---------- A--A-A---A----AB-BA--------- AA-A-A---A----A---AAABBBAAAA AAAAAA--AAA---A---A----AAABB AAA--A-AA-A---AA-AA----A-B-B A-----AA--AA--BAAA-----B-B-- 
