model
size = 32 32 12, scale = 0.05, origin = -y
material 
  colors = A:#0A0718 B:#070D18 C:#081B14
voxels
239-A30-3A29-3A3-B22-C2-3A2-A23-2(A3-)A23-A7-A23-2A4(5-A25-A)5-2(A24-A6-)A24-A7-A31-A23-A7-C23-A8-B22-2A3(31-A)30-A31-A316-2(A6-)A16-2(3A4-)3A15-4A3-3A3-B3-A14-A-2AC2-3A2-A22-2A2(3-A)23-A7-A23-2A5-A25-A5-A21-A3-2(A5-)B15-A3-2(A5-)A15-A3-2(A5-)B18-2(A6-A24-)A7-A22-A8-A19-5A7-C19-5A8-B3-C18-2A8-3A20-A9-A21-A31-A30-A31-A316-2(A6-)A16-2(3A4-)3A14-5A3-3A3-B3-A13-2A-2AC2-3A2-A5-A11-2(2A3-)A3-A5-A11-A5-A7-A6-A10-A5-2A5-A7-B10-A6-A5-A7-A13-A3-2(A5-)B-A13-A3-2(A5-)A-A13-A3-2(A5-)B-2(A10-A5-A6-A7-)B10-2A4-A7-A6-A11-A3-A8-A5-A11-7A7-C5-A11-7A8-B3-C18-2A8-3A20-A9-A21-A31-A30-A31-A316-2(A6-)A16-2(3A4-)3A14-5A3-3A3-B3-A13-2A-2AC2-3A2-A5-A11-2(2A3-)A3-A5-A11-A5-A7-A6-A10-A5-2A5-A7-B9-2A6-A5-A7-A9-2(A3-)2(A5-)B-A9-2(A3-)2(A5-)A-A9-2(A3-)2(A5-)B-2(A10-A5-A6-A7-)B10-2A4-A7-A6-A11-A3-A8-A5-A11-7A7-C5-A11-7A8-B3-C18-2A8-3A20-A9-A21-A31-A30-A31-A316-2(A6-)A16-2(3A4-)3A14-5A3-3A3-B3-A13-2A-2AC2-3A2-A5-A11-2(2A3-)A3-A5-A11-A5-A7-A6-A10-A5-2A5-A7-B9-2A6-A5-A7-A9-2(A3-)2(A5-)B-A9-2(A3-)2(A5-)A-A9-2(A3-)2(A5-)B-2(A10-A5-A6-A7-)B10-2A4-A7-A6-A11-A3-A8-A5-A11-7A7-C5-A11-7A8-B3-C18-2A8-3A20-A9-A21-A31-A30-A31-A316-2(A6-)A16-2(3A4-)3A14-5A3-3A3-B3-A13-2A-2AC2-3A2-A5-A11-2(2A3-)A3-A5-A11-A5-A7-A6-A10-A5-2A5-A7-B9-2A6-A5-A7-A9-2(A3-)2(A5-)B-A9-2(A3-)2(A5-)A-A9-2(A3-)2(A5-)B-2(A10-A5-A6-A7-)B10-2A4-A7-A6-A11-A3-A8-A5-A11-7A7-C5-A11-7A8-B3-C18-2A8-3A20-A9-A21-A31-A30-A31-A316-2(A6-)A16-2(3A4-)3A14-5A3-3A3-B3-A13-2A-2AC2-3A2-A5-A11-2(2A3-)A3-A5-A11-A5-A7-A6-A10-A5-2A5-A7-B9-2A6-A5-A7-A9-2(A3-)2(A5-)B-A9-2(A3-)2(A5-)A-A9-2(A3-)2(A5-)B-2(A10-A5-A6-A7-)B10-2A4-A7-A6-A11-A3-A8-A5-A11-7A7-C5-A11-7A8-B3-C18-2A8-3A20-A9-A21-A31-A30-A31-A316-2(A6-)A16-2(3A4-)3A14-5A3-3A3-B3-A13-2A-2AC2-3A2-A5-A11-2(2A3-)A3-A5-A11-A5-A7-A6-A10-A5-2A5-A7-B9-2A6-A5-A7-A9-2(A3-)2(A5-)B-A9-2(A3-)2(A5-)A-A9-2(A3-)2(A5-)B-2(A10-A5-A6-A7-)B10-2A4-A7-A6-A11-A3-A8-A5-A11-7A7-C5-A11-7A8-B3-C18-2A8-3A20-A9-A21-A31-A30-A31-A84-2A7(28-4A)3(6-A)7-4A5-2(3A4-)3A6-4A4-5A3-3A3-B3-A5-4A4-2A-2AC2-3A2-A5-A4-4A2(3-2A)2(3-A)5-A4-4A3-A5-A7-A6-A3-4A3-A5-2A5-A7-B3-4A2-2A6-A5-A7-A3-4A2-2(A3-)2(A5-)B-A3-4A2-2(A3-)2(A5-)A-A3-4A2-2(A3-)2(A5-)B-2(A3-4A3-A5-A6-A7-)B3-4A3-2A4-A7-A6-A3-4A4-A3-A8-A5-A4-4A3-7A7-C5-A4-4A3-7A8-B3-C5-4A9-2A8-3A6-4A10-A9-A7-2(4A10-A17-)2(4A9-A18-)9(4A28-)4A3(6-A)7-4A5-2(3A4-)3A6-4A4-5A3-3A3-B3-A5-4A4-2A-2AC2-3A2-A5-A4-4A2(3-2A)2(3-A)5-A4-4A3-A5-A7-A6-A3-4A3-A5-2A5-A7-B3-4A2-2A6-A5-A7-A3-4A2-2(A3-)2(A5-)B-A3-4A2-2(A3-)2(A5-)A-A3-4A2-2(A3-)2(A5-)B-2(A3-4A3-A5-A6-A7-)B3-4A3-2A4-A7-A6-A3-4A4-A3-A8-A5-A4-4A3-7A7-C5-A4-4A3-7A8-B3-C5-4A9-2A8-3A6-4A10-A9-A7-2(4A10-A17-)2(4A9-A18-)9(4A28-)4A3(6-A)7-4A5-2(3A4-)3A6-4A4-5A3-3A3-B3-A5-4A4-2A-2AC2-3A2-A5-A4-4A2(3-2A)2(3-A)5-A4-4A3-A5-A7-A6-A3-4A3-A5-2A5-A7-B3-4A2-2A6-A5-A7-A3-4A2-2(A3-)2(A5-)B-A3-4A2-2(A3-)2(A5-)A-A3-4A2-2(A3-)2(A5-)B-2(A3-4A3-A5-A6-A7-)B3-4A3-2A4-A7-A6-A3-4A4-A3-A8-A5-A4-4A3-7A7-C5-A4-4A3-7A8-B3-C5-4A9-2A8-3A6-4A10-A9-A7-2(4A10-A17-)2(4A9-A18-)34(4A28-)2A
