model
size = 15 32 12, scale = 0.05, origin = -y
material 
  colors = A:#630 B:#100 C:#960 D:#AAA
voxels
4-5C7(10-5A)11-2(2(5A10-)6A9-)6(6A9-)7A8-7A2-2(A5-6A3-)A2(5-6A2-2A)4-7A2-2A3-8A2-2A2-10A-2A2-13A2(2-5BA5B2D)2-2C5-C2(7-2A5-A)7-4(2A5-2A6-)2A2(5-3A)4B3A5-10A2(6-9A)6-4(10A5-)10A4-13(13A2-)5BA5B2D2-5BA5B2D-C8-C3(5-A8-A)5-4(A8-2A4-)A8B3A3(3-12A)2-C12A2-3(C13A-)C14ACA13BCA3(13-C11(A14-)2(B14-)C8-C2(5-A8-A)5-5(A8-2A4-)A8B3A2(3-12A)2-C12A2-13A2-3(14A-)17A13B2A)13-C13(A14-)C8-C2(5-A8-A)5-5(A8-2A4-)A8B3A2(3-12A)2-C12A2-13A2-12A-A2(-14A)-17A13B2A13-C11(A14-)2(B14-)C8-C2(5-A8-A)5-A8-4(2A4-2A7-)2A4-2A7B3A3(3-12A)2-C12A2-3(C13A-)C14ACA13BCA13-C11(A14-)B14-B15-2C6-C3(6-2A6-A)2(7-A6-A)7-2(A6-2A6-)A6B2A2(6-9A)6-10A5(4-11A)4-11(13A2-)13A-14A2(2-13B)4-6C6(9-6A)9-2(7A8-)7A5(9-6A)8-7A8-2(6A9-)7A8-9A6-10A4-7(12A3-)12A2-13A2(2-13B)292-6A6-10A4-7(12A3-)12A2-13A2(2-BA11B)309-4A7-9A4-7(12A3-)12A4-5BA3B6-5BA3B2-
