model
size = 11, scale = 0.05, origin = -y
material 
  colors = A:#E00 B:#F93 C:#0A0 D:#FC0
voxels
--AAAAAAA-- ----------- ----------- ----------- ----------- ----------- ----------- ----------- ----------- ----------- ----------- 
-A-------A- -AAAAAAAAA- ----------- ----------- ----------- ----------- ----------- ----------- ----------- ----------- ----------- 
A---------A -A-------A- --AAAAAAA-- ----------- ----------- ----------- ----------- ----------- ----------- ----------- ----------- 
A---------A -A-------A- --A-----A-- ---AAAAA--- ----------- ----------- ----------- ----------- ----------- ----------- ----------- 
A---------A -A-------A- --A-----A-- ---AAAAA--- ----------- ----------- ----------- ----------- ----------- ----------- ----------- 
A---------A -A-------A- --A-----A-- ---AAAAA--- -----C----- ----CC----- -----CC---- -----C----- ----BBB---- ----BDB---- ----BBB---- 
A---------A -A-------A- --A-----A-- ---AAAAA--- ----------- ----------- ----------- ----------- ----------- ----------- ----------- 
A---------A -A-------A- --A-----A-- ---AAAAA--- ----------- ----------- ----------- ----------- ----------- ----------- ----------- 
A---------A -A-------A- --AAAAAAA-- ----------- ----------- ----------- ----------- ----------- ----------- ----------- ----------- 
-A-------A- -AAAAAAAAA- ----------- ----------- ----------- ----------- ----------- ----------- ----------- ----------- ----------- 
--AAAAAAA-- ----------- ----------- ----------- ----------- ----------- ----------- ----------- ----------- ----------- ----------- 
