model
size = 27 30 10, scale = 0.05, origin = -y
material 
  colors = A:#263838 B:#F11315 C:#B75C63
voxels
--------AAAAAAAAA---------- --------A-------A---------- --------A-------AAA-------- --------AAAAA-----A-------- --------AAAAA-----A-------- ---------AA---------------- ----------A---------------- ----------A---------------- -----------A--------------- --------A---A-------------- --------AA----------------- ----------A---------------- ------------------A-------- ------------------A-------- -----------------AA-------- ---------------AAAA-------- -------------AAAAAA-------- -----------AAAAAAAA-------- -----------AAAAAAAA-------- --------A----AAAAAA-------- --------A----AAAAAA-------- --------AA---ABBAAA-------- -------------ABBAAA-------- --------AAAAAAAAAAA-------- --------A-----AAAA--------- --------A----AAAAAA-------- --------A--AAAAAAAA-------- -----------ABBAAA---------- -----------ABBAA----------- -----------CCC------------- 
--------AAAAAAAAA---------- --------A-------A---------- ------AAA-------AAAAA------ --------AAAAA-----A-------- --------AAAAA-----A-------- ---------AA---------------- ----------A---------------- ----------A---------------- ------AA---A--------A------ ------AAA---A-------A------ --------AA---------AA------ ----------A--------AA------ ------A-----------AAA------ ------AA----------AAA------ -----------------AAAA------ ---------------AAAAAA------ -------------AAAAAAAA------ -----------AAAAAAAAAA------ ------AA---AAAAAAAAAA------ --------A----AAAAAAAA------ -------AA----AAAAAAAA------ ------AAAA---ABBAAAAA------ -------------ABBAAAAA------ --------AAAAAAAAAAA-A------ --------A-----AAAA--A------ --------A----AAAAAAAA------ ------AAA--AAAAAAAAAA------ -----------ABBAAA--AA------ -----------ABBAA---AA------ -----------CCC------------- 
--------AAAAAAAAA---------- --------A-------A---------- ------AAA-------AAAAA------ --------AAAAA-----A-------- --------AAAAA-----A-------- ---------AA---------------- ----------A---------------- ----------A---------------- ------AA---A--------A------ ------AAA---A-------A------ --------AA---------AA------ ----------A--------AA------ ------A-----------AAA------ ------AA----------AAA------ -----------------AAAA------ ---------------AAAAAA------ -------------AAAAAAAA------ -----------AAAAAAAAAA------ ------AA---AAAAAAAAAA------ --------A----AAAAAAAA------ -------AA----AAAAAAAA------ ------AAAA---ABBAAAAA------ -------------ABBAAAAA------ --------AAAAAAAAAAA-A------ --------A-----AAAA--A------ --------A----AAAAAAAA------ ------AAA--AAAAAAAAAA------ -----------ABBAAA--AA------ -----------ABBAA---AA------ -----------CCC------------- 
--------AAAAAAAAA---------- --------A-------A---------- ----AAAAA-------AAAAAAA---- --------AAAAA-----A-------- --------AAAAA-----A-------- ----AA---AA---------------- ----AA----A----------AA---- ----AA----A----------AA---- ----AAAA---A--------AAA---- ----AAAAA---A-------AAA---- --------AA---------AAAA---- ----------A--------AAAA---- ----AAA-----------AAAA----- ------AA----------AAAAA---- -----------------AAAAAA---- ----A----------AAAAAAAA---- ----A--------AAAAAAAA------ -----------AAAAAAAAAA------ ------AA---AAAAAAAAAA------ -----A--A----AAAAAAAAA----- -----A-AA----AAAAAAAAA----- -----AAAAA---ABBAAAAAAA---- -------------ABBAAAAAAA---- ----A---AAAAAAAAAAA-AAA---- ----A---A-----AAAA--AAA---- ----A---A----AAAAAAAAAA---- ----AAAAA--AAAAAAAAAAAA---- ----A------ABBAAA--AAAA---- -----------ABBAA---AAAA---- -----------CCC------------- 
--------AAAAAAAAA---------- --------A-------A---------- --AAAAAAA-------AAAAAAAAA-- --------AAAAA-----A-------- --------AAAAA-----A-------- --AAAA---AA---------------- ---AAA----A----------AA---- --AAAA----A----------AA---- --AAAAAA---A--------AAA---- --AAAAAAA---A-------AAA---- --------AA---------AAAA---- ----------A--------AAAA---- --AAAAA-----------AAAA----- --AA--AA----------AAAAAA--- --AA-------------AAAAAAAA-- --AAA----------AAAAAAAAAA-- --AAA--------AAAAAAAA--AA-- --AA-------AAAAAAAAAA--AA-- --AA--AA---AAAAAAAAAA---A-- -----A--A----AAAAAAAAA--A-- -----A-AA----AAAAAAAAA----- -----AAAAA---ABBAAAAAAA---- -------------ABBAAAAAAAAA-- --AAA---AAAAAAAAAAA-AAAAA-- --AAA---A-----AAAA--AAAAA-- --AAA---A----AAAAAAAAAAAA-- --AAAAAAA--AAAAAAAAAAAAAA-- --AAA------ABBAAA--AAAA---- --AA-------ABBAA---AAAA---- -----------CCC------------- 
--------AAAAAAAAA---------- --------A-------A---------- --AAAAAAA-------AAAAAAAAA-- --------AAAAA-----A-------- --------AAAAA-----A-------- --AAAA---AA---------------- ---AAA----A----------AA---- --AAAA----A----------AA---- --AAAAAA---A--------AAA---- --AAAAAAA---A-------AAA---- --------AA---------AAAA---- ----------A--------AAAA---- --AAAAA-----------AAAA----- --AA--AA----------AAAAAA--- --AA-------------AAAAAAAA-- --AAA----------AAAAAAAAAA-- --AAA--------AAAAAAAA--AA-- --AA-------AAAAAAAAAA--AA-- --AA--AA---AAAAAAAAAA---A-- -----A--A----AAAAAAAAA--A-- -----A-AA----AAAAAAAAA----- -----AAAAA---ABBAAAAAAA---- -------------ABBAAAAAAAAA-- --AAA---AAAAAAAAAAA-AAAAA-- --AAA---A-----AAAA--AAAAA-- --AAA---A----AAAAAAAAAAAA-- --AAAAAAA--AAAAAAAAAAAAAA-- --AAA------ABBAAA--AAAA---- --AA-------ABBAA---AAAA---- -----------CCC------------- 
--------AAAAAAAAA---------- --------A-------A---------- --AAAAAAA-------AAAAAAAAA-- --------AAAAA-----A-------- --------AAAAA-----A-------- --AAAA---AA---------------- ---AAA----A----------AA---- --AAAA----A----------AA---- --AAAAAA---A--------AAA---- --AAAAAAA---A-------AAA---- --------AA---------AAAA---- ----------A--------AAAA---- --AAAAA-----------AAAA----- --AA--AA----------AAAAAA--- --AA-------------AAAAAAAA-- --AAA----------AAAAAAAAAA-- --AAA--------AAAAAAAA--AA-- --AA-------AAAAAAAAAA--AA-- --AA--AA---AAAAAAAAAA---A-- -----A--A----AAAAAAAAA--A-- -----A-AA----AAAAAAAAA----- -----AAAAA---ABBAAAAAAA---- -------------ABBAAAAAAAAA-- --AAA---AAAAAAAAAAA-AAAAA-- --AAA---A-----AAAA--AAAAA-- --AAA---A----AAAAAAAAAAAA-- --AAAAAAA--AAAAAAAAAAAAAA-- --AAA------ABBAAA--AAAA---- --AA-------ABBAA---AAAA---- -----------CCC------------- 
--------AAAAAAAAA---------- --------A-------A---------- -AAAAAAAA-------AAAAAAAAAA- -A------AAAAA-----A------A- -A------AAAAA-----A------AA -AAAAA---AA---------------A ---AAA----A----------AA---A --AAAA----A----------AA---A -AAAAAAA---A--------AAA---A -AAAAAAAA---A-------AAA---A -A------AA---------AAAA--AA -A--------A--------AAAA--A- -AAAAAA-----------AAAA---A- -AAA--AA----------AAAAAA-A- -AAA-------------AAAAAAAAA- -AAAA----------AAAAAAAAAA-- -AAAA--------AAAAAAAA--AAA- --AA-------AAAAAAAAAA--AAA- -AAA--AA---AAAAAAAAAA---AA- -A---A--A----AAAAAAAAA--AAA -A---A-AA----AAAAAAAAA----A -A---AAAAA---ABBAAAAAAA---A -A-----------ABBAAAAAAAAAAA -AAAA---AAAAAAAAAAA-AAAAA-- --AAA---A-----AAAA--AAAAA-- --AAA---A----AAAAAAAAAAAA-- AAAAAAAAA--AAAAAAAAAAAAAA-- AAAAA------ABBAAA--AAAA---- AAAA-------ABBAA---AAAA---- -----------CCC------------- 
--------AAAAAAAAA---------- --------A-------A---------- -AAAAAAAA-------AAAAAAAAAA- -A------AAAAA-----A------A- -A------AAAAA-----A------AA -AAAAA---AA---------------A ---AAA----A----------AA---A --AAAA----A----------AA---A -AAAAAAA---A--------AAA---A -AAAAAAAA---A-------AAA---A -A------AA---------AAAA--AA -A--------A--------AAAA--A- -AAAAAA-----------AAAA---A- -AAA--AA----------AAAAAA-A- -AAA-------------AAAAAAAAA- -AAAA----------AAAAAAAAAA-- -AAAA--------AAAAAAAA--AAA- --AA-------AAAAAAAAAA--AAA- -AAA--AA---AAAAAAAAAA---AA- -A---A--A----AAAAAAAAA--AAA -A---A-AA----AAAAAAAAA----A -A---AAAAA---ABBAAAAAAA---A -A-----------ABBAAAAAAAAAAA -AAAA---AAAAAAAAAAA-AAAAA-- --AAA---A-----AAAA--AAAAA-- --AAA---A----AAAAAAAAAAAA-- AAAAAAAAA--AAAAAAAAAAAAAA-- AAAAA------ABBAAA--AAAA---- AAAA-------ABBAA---AAAA---- -----------CCC------------- 
--------AAAAAAAAA---------- --------A-------A---------- -AAAAAAAA-------AAAAAAAAAA- -A------AAAAA-----A------A- -A------AAAAA-----A------AA -AAAAA---AA---------------A ---AAA----A----------AA---A --AAAA----A----------AA---A -AAAAAAA---A--------AAA---A -AAAAAAAA---A-------AAA---A -A------AA---------AAAA--AA -A--------A--------AAAA--A- -AAAAAA-----------AAAA---A- -AAA--AA----------AAAAAA-A- -AAA-------------AAAAAAAAA- -AAAA----------AAAAAAAAAA-- -AAAA--------AAAAAAAA--AAA- --AA-------AAAAAAAAAA--AAA- -AAA--AA---AAAAAAAAAA---AA- -A---A--A----AAAAAAAAA--AAA -A---A-AA----AAAAAAAAA----A -A---AAAAA---ABBAAAAAAA---A -A-----------ABBAAAAAAAAAAA -AAAA---AAAAAAAAAAA-AAAAA-- --AAA---A-----AAAA--AAAAA-- --AAA---A----AAAAAAAAAAAA-- AAAAAAAAA--AAAAAAAAAAAAAA-- AAAAA------ABBAAA--AAAA---- AAAA-------ABBAA---AAAA---- -----------CCC------------- 
