model
size = 32 32 27, scale = 0.05, origin = -y
material 
  colors = A:#F60 B:#FC0 C:#F03 D:#E00 E:#C60 F:#F63 G:#500
voxels
832-2(5(6C26-)6C858-)5(6C26-)6C387-2(3B29-)3B26-2(6A3B23-)6A3B20-3(3E9A3B17-)2(15A3B14-)15A3B11-3(18A14-)3(3A3-9A17-)13AF19-12AF19-11A2F379-2(3B29-)3B26-2(6A3B23-)6A3B20-3(3E9A3B17-)2(15A3B14-)15A3B11-3(18A14-)3(3A3-9A17-)14AF18-13AF18-12A2F378-2(3B29-)3B26-2(6A3B23-)6A3B20-3(3E9A3B17-)2(15A3B14-)15A3B11-3(18A14-)3(3A3-9A17-)15A2(18-14A)2(11(17-15A)3(17-9A3-3A)17-6A9-15A2-2(6A9-5AD11-)3(3A15-12A2-)3(3A18-9A2-)3(3A15-9A5-)3(3A12-3F14-)12A2EF18-11A2EF18-14A)11(17-15A)3(17-9A3-3A)17-6A9-15A2-2(6A9-5AD11-)3(3A15-12A2-)3(3A18-9A2-)3(3A15-9A5-)3(3A12-3F14-)2(2(12A2EF17-)15A11(17-3A9-3A)17-3(3A12-3A14-)3A15-12A2-2(3A15-2AD11-)3A2(18-14A)18-11A3(30-2A)2(18-14A)18-17A2(12-3G14-3A)12-3G14-)2(12A2EF17-)15A11(17-3A9-3A)17-3(3A12-3A14-)3A15-12A2-2(3A15-2A9D3-)3A2(18-14A)18-11A3(30-2A)2(18-14A)18-17A2(12-3G14-3A)12-3G14-2(12A2EF17-)15A3(11(17-3A9-3A)17-3(3A12-6A11-)3A18-9A2(2-3A18-9D)32-5(2A30-)2A3(21-3A3-5A)15-2(6A3-3A20-)6A3-3A5-12A2EF18-11A2EF18-14A)11(17-3A9-3A)17-3(3A12-3A14-)3A15-12A2-2(3A15-2A9D3-)2(3A2(18-14A)18-11A3(30-2A)2(18-14A)18-17A2(12-3G14-3A)12-3G14-2(12A2EF17-)15A11(17-3A9-3A)17-3(3A12-3A14-)3A15-12A2-2(3A15-2AD11-))3A2(18-14A)18-11A3(30-2A)2(18-14A)18-17A2(12-3G14-3A)12-3G14-2(12A2EF17-)12(15A17-)3(9A3-3A17-)2(6A9-15A2-2(6A9-5AD11-)3(3A15-12A2-)3(3A18-9A2-)3(3A15-9A5-)3(3A12-3A14-)12A2EF18-11A2EF18-14A11(17-15A)3(17-9A3-3A)17-)6A9-15A2-2(6A9-5AD11-)3(3A15-12A2-)3(3A18-9A2-)3(3A15-9A5-)3(3A12-3A14-)3(12A2EF18-11A2EF18-14A378-2(3B29-)3B26-2(6A3B23-)6A3B20-3(12A3B17-)2(15A3B14-)15A3B11-3(18A14-)3(3A3-9A17-))12A2E19-11A2E19-13A850-2(5(6C26-)6C858-)6(6C26-)
