model
size = 29 26 31, scale = 0.05, origin = -y
material 
  colors = A:#00FCE7 B:#FCD200 C:#54FC00 D:#FC0093 E:#00897E F:#2500DF G:#DF00DF H:#00FC15 I:#FF791A J:#DF5D00 K:#FC6900
voxels
----------------------------- ----------------------------- ----------------------------- ----------------------------- -----------J--J--J----------- ------------JEJEJ------------ -------------EJE------------- -------------EEE------------- ----------------------------- ----------------------------- ----------------------------- ----------------------------- ----------------------------- ----------------------------- ----------------------------- ----------------------------- ----------------------------- ----------------------------- ----------------------------- ----------------------------- ----------------------------- ----------------------------- ----------------------------- ----------------------------- ----------------------------- ----------------------------- 
----------------------------- ----------------------------- ----------------------------- ----------------------------- ----------------------------- ----------JE-----EJ---------- -----------EJ---JE----------- -----------F-----F----------- ----------F-F-H-F-F---------- -----------F-----F----------- ----------------------------- ----------------------------- ----------------------------- ----------------------------- ----------------------------- ----------------------------- ----------------------------- ----------------------------- ----------------------------- ----------------------------- ----------------------------- ----------------------------- ----------------------------- ----------------------------- ----------------------------- ----------------------------- 
----------------------------- ----------------------------- ----------------------------- ----------------------------- ----------------------------- ----------E-------E---------- ----------E-------E---------- ----------B--DDD--B---------- ----------B-DDDDD-B---------- --------------H-------------- --------------H-------------- ----------------------------- ----------------------------- ----------------------------- ----------------------------- ----------------------------- ----------------------------- ----------------------------- ----------------------------- ----------------------------- ----------------------------- ----------------------------- ----------------------------- ----------------------------- ----------------------------- ----------------------------- 
----------------------------- ----------------------------- ----------------------------- ----------------------------- ----------------------------- ---------E---------E--------- ---------E---------E--------- ---------B---------B--------- ---------B---------B--------- -----------DDDDDDD----------- -------------DDD------------- --------------H-------------- --------------H-------------- ----------------------------- ----------------------------- ----------------------------- ----------------------------- ----------------------------- ----------------------------- ----------------------------- ----------------------------- ----------------------------- ----------------------------- ----------------------------- ----------------------------- ----------------------------- 
--------K-----------K-------- --------K-----------K-------- ----------------------------- ----------------------------- ----------------------------- ---------E---------E--------- ---------E---------E--------- ---------B---------B--------- ---------B---------B--------- ---------BB-------BB--------- ------------D---D------------ -------------DDD------------- --------------D-------------- --------------H-------------- ----------------------------- ----------------------------- ----------------------------- ----------------------------- ----------------------------- ----------------------------- ----------------------------- ----------------------------- ----------------------------- ----------------------------- ----------------------------- ----------------------------- 
----------------------------- --------E-----------E-------- --------E-----------E-------- --------E-----------E-------- --------E-----------E-------- --------E-----------E-------- --------E-----------E-------- --------E-----------E-------- --------B-----------B-------- --------B--B-----B--B-------- ----------D-------D---------- ------------D---D------------ -----------DDD-DDD----------- --------------D-------------- --------------H-------------- ----------------------------- ----------------------------- ----------------------------- ----------------------------- ----------------------------- ----------------------------- ----------------------------- ----------------------------- ----------------------------- ----------------------------- ----------------------------- 
----------------------------- --------E-----------E-------- --------E-----------E-------- --------J-----------J-------- --------J-----------J-------- --------J-----------J-------- --------J-----------J-------- --------E-----------E-------- ----------------------------- --------B-----------B-------- --------B--BB---BB--B-------- ---------DB-------BD--------- ----------------------------- -----------DFD-DFD----------- --------------D-------------- --------------H-------------- ----------------------------- ----------------------------- ----------------------------- ----------------------------- ----------------------------- ----------------------------- ----------------------------- ----------------------------- ----------------------------- ----------------------------- 
----------------------------- ----------------------------- --------E-----------E-------- --------E-----------E-------- --------E-----------E-------- --------E-----------E-------- --------E-----------E-------- --------E-----------E-------- --------A-----------A-------- --------B-----------B-------- -------B-------------B------- --------B--BB---BB--B-------- ---------BB-------BB--------- ----------------------------- ----------DDFDDDFDD---------- --------------H-------------- ----------------------------- ----------------------------- ----------------------------- ----------------------------- ----------------------------- ----------------------------- ----------------------------- ----------------------------- ----------------------------- ----------------------------- 
----------------------------- ----------------------------- ----------------------------- --------K-----------K-------- --------K-----------K-------- ---------E---------E--------- ---------E---------E--------- ----------------------------- --------A-----------A-------- ----------------------------- -------B-------------B------- -------D-----B-B-----D------- -----------BB---BB----------- ---------BB-------BB--------- ----------D-------D---------- -----------FFDDDFF----------- --------------H-------------- ----------------------------- ----------------------------- ----------------------------- ----------------------------- ----------------------------- ----------------------------- ----------------------------- ----------------------------- ----------------------------- 
----------------------------- ----------------------------- ----------------------------- ----------------------------- ----------------------------- ---------E---------E--------- ---------E---------E--------- ---------C---------C--------- --------A-----------A-------- --------A-----------A-------- -------B-------------B------- ------B---------------B------ -------B-----B-B-----B------- --------D--BB---BB--D-------- ----------D-------D---------- ----------D-------D---------- -----------DDD-DDD----------- ----------------------------- ----------------------------- ----------------------------- ----------------------------- ----------------------------- ----------------------------- ----------------------------- ----------------------------- ----------------------------- 
----------------------------- ----------------------------- ----------------------------- ----------------------------- ----------------------------- ----------E-------E---------- ----------E-------E---------- ----------C-------C---------- -------A-C---------C-A------- --------A-----------A-------- ----------------------------- ------B---------------B------ ----------------------------- -------B-----B-B-----B------- ----------D-------D---------- ---------D---------D--------- ----------D-------D---------- ----------------------------- ----------------------------- ----------------------------- ----------------------------- ----------------------------- ----------------------------- ----------------------------- ----------------------------- ----------------------------- 
----------------------------- ----------------------------- ----------------------------- ----------------------------- ----------------------------- -----------EE---EE----------- -----------EE---EE----------- -----------CG---GC----------- ----------C-------C---------- -------A-F---------F-A------- -------A-------------A------- ----------------------------- -----B-----------------B----- ------B---------------D------ ----------------------------- ---------D---------D--------- ---------D---------D--------- ----------------------------- ----------------------------- ----------------------------- ----------------------------- ----------------------------- ----------------------------- ----------------------------- ----------------------------- ----------------------------- 
----------------------------- ----------------------------- --------------K-------------- -------------EEE------------- ------------KEJEK------------ -------------EJE------------- -------------EEE------------- ------------GAAAG------------ -----------C-AAA-C----------- ------A---C---H---C---A------ ------A-FF----H----FF-A------ -------A------H------A------- -----B--------H--------B----- -----D--------H--------B----- ------B-------H-------D------ ---------D---------D--------- ---------D---------D--------- ----------------------------- ----------------------------- ----------------------------- ----------------------------- ----------------------------- ----------------------------- ----------------------------- ----------------------------- ----------------------------- 
----------------------------- ----------------------------- ----------------------------- ----------------------------- ----------------------------- ----------------------------- ----------------------------- ------------G---G------------ ----------------------------- -----------C-A-A-C----------- -----A----C--A-A--C----A----- ------A-F----A-A----F-A------ --------------H-------------- ----B---------H--------B----- -----D--------H--------B----- ---------D----H----D--------- --------D-----------D-------- ----------------------------- ----------------------------- ----------------------------- ----------------------------- ----------------------------- ----------------------------- ----------------------------- ----------------------------- ----------------------------- 
----------------------------- ----------------------------- ----------------------------- ----------------------------- ----------------------------- ----------------------------- ----------------------------- ----------------------------- ------------G---G------------ ----------------------------- ----A----C-C-----C-C----A---- -----A----C--A-A--C----A----- -------F-----A-A-----F------- ----B---------H-------------- ----B---------H--------B----- -----B--------H--------B----- --------D-----H-----D-------- ----------------------------- ----------------------------- ----------------------------- ----------------------------- ----------------------------- ----------------------------- ----------------------------- ----------------------------- ----------------------------- 
----------------------------- ----------------------------- ----------------------------- ----------------------------- ----------------------------- ----------------------------- ----------------------------- ----------------------------- ------------G---G------------ ------------G---G------------ ----------------------------- ----A----CCC-----CCC----A---- -------------A-A------------- ------F------A-A------F------ ----B---------H--------B----- -----B-----------------B----- --------D-----H-----D-------- --------------H-------------- ----------------------------- ----------------------------- ----------------------------- ----------------------------- ----------------------------- ----------------------------- ----------------------------- ----------------------------- 
----------------------------- ----------------------------- ----------------------------- ----------------------------- ----------------------------- ----------------------------- ----------------------------- ----------------------------- ------------G---G------------ ------------G---G------------ ----------------------------- ---A----C-----------C----A--- ----A----CCC-----CCC----A---- ------F------A-A------F------ -------------A-A------------- ------B-------H-------B------ ----------------------------- --------------H-------------- ----------------------------- ----------------------------- ----------------------------- ----------------------------- ----------------------------- ----------------------------- ----------------------------- ----------------------------- 
----------------------------- ----------------------------- ----------------------------- ----------------------------- ----------------------------- ----------------------------- ----------------------------- ----------------------------- ----------------------------- ------------G---G------------ ------------G---G------------ --A-------------------------- ---A----C-----------C----A--- ----A-F--BC-A---A-CB--F-A---- ------------A---A------------ ------B------A-A------B------ --------------H-------------- ----------------------------- --------------H-------------- ----------------------------- ----------------------------- ----------------------------- ----------------------------- ----------------------------- ----------------------------- ----------------------------- 
----------------------------- ----------------------------- ----------------------------- ----------------------------- ----------------------------- ----------------------------- ----------------------------- ----------------------------- ----------------------------- ------------G---G------------ ------------G---G------------ ----------------------------- --A----C-------------C----A-- ---A----C-----------C----A--- -----F---C-A-----A-C---F----- ------------A---A------------ -------------A-A------------- --------------H-------------- --------------H-------------- ----------------------------- ----------------------------- ----------------------------- ----------------------------- ----------------------------- ----------------------------- ----------------------------- 
----------------------------- ----------------------------- ----------------------------- ----------------------------- ----------------------------- ----------------------------- ----------------------------- ----------------------------- ----------------------------- ----------------------------- ------------G---G------------ ------------G---G------------ -A-------------------------A- --A----C-------------C----A-- --------C-----------C-------- ----I-----AA-----AA-----I---- ------------I---I------------ -------------A-A------------- --------------H-------------- --------------H-------------- ----------------------------- ----------------------------- ----------------------------- ----------------------------- ----------------------------- ----------------------------- 
----------------------------- ----------------------------- ----------------------------- ----------------------------- ----------------------------- ----------------------------- ----------------------------- ----------------------------- ----------------------------- ----------------------------- ------------G---G------------ ------------G---G------------ A---------------------------- -A----C---------------C----A- -------C-------------C------- ---F----C-----------C----F--- ----F-----AA-----AA-----F---- ------------I---I------------ -------------A-A------------- --------------H-------------- ----------------------------- ----------------------------- ----------------------------- ----------------------------- ----------------------------- ----------------------------- 
----------------------------- ----------------------------- ----------------------------- ----------------------------- ----------------------------- ----------------------------- ----------------------------- ----------------------------- ----------------------------- ----------------------------- ----------------------------- ------------G---G------------ ------------G---G------------ A---------------------------- --F---C---------------C---F-- --F----B-------------B----F-- ---I----C-----------C----I--- ----F-----AA-----AA-----F---- ------------I---I------------ -------------A-A------------- --------------H-------------- ----------------------------- ----------------------------- ----------------------------- ----------------------------- ----------------------------- 
----------------------------- ----------------------------- ----------------------------- ----------------------------- ----------------------------- ----------------------------- ----------------------------- ----------------------------- ----------------------------- ----------------------------- ----------------------------- ------------G---G------------ ------------G---G------------ ----------------------------- --F--C-----------------C--F-- -F----C---------------C----F- --I----C-------------C----I-- ---I----C-----------C----I--- ----F-----AA-----AA-----F---- ------------A---A------------ -------------AHA------------- ----------------------------- ----------------------------- ----------------------------- ----------------------------- ----------------------------- 
----------------------------- ----------------------------- ----------------------------- ----------------------------- ----------------------------- ----------------------------- ----------------------------- ----------------------------- ----------------------------- ----------------------------- ----------------------------- ----------------------------- -----------G-----G----------- -----------G-----G----------- -F-------------------------F- -----C-----------------C----- -F----B---------------B----F- --F----C-------------C----F-- ---F----C-----------C----F--- ----F-----AIA---AIA-----F---- -------------A-A------------- --------------H-------------- ----------------------------- ----------------------------- ----------------------------- ----------------------------- 
----------------------------- ----------------------------- ----------------------------- ----------------------------- ----------------------------- ----------------------------- ----------------------------- ----------------------------- ----------------------------- ----------------------------- ----------------------------- ----------------------------- -----------G-----G----------- I----------G-----G----------I ----------------------------- ----------------------------- -----C-----------------C----- -F----C---------------C----F- --F----B-------------B----F-- ---I-F---A---------A---F-I--- ----F-----AIA---AIA-----F---- -------------A-A------------- --------------H-------------- ----------------------------- ----------------------------- ----------------------------- 
----------------------------- ----------------------------- ----------------------------- ----------------------------- ----------------------------- ----------------------------- ----------------------------- ----------------------------- ----------------------------- ----------------------------- ----------------------------- ----------------------------- ----------------------------- ----------G-------G---------- ----------------------------- ----------------------------- -----C-----------------C----- ------C---------------C------ -------C--------------C------ --------A-----------A-------- -----I---I---------I---I----- ----------AAAA-AAAA---------- --------------H-------------- ----------------------------- ----------------------------- ----------------------------- 
----------------------------- ----------------------------- ----------------------------- ----------------------------- ----------------------------- ----------------------------- ----------------------------- ----------------------------- ----------------------------- ----------------------------- ----------------------------- ----------------------------- ----------------------------- ----------G-------G---------- ----------------------------- ----------------------------- ----------------------------- -----C-----------------C----- ------C---------------C------ --------A-----------A-------- --------A-----------A-------- ---------A---------A--------- ------------AA-AA------------ --------------H-------------- ----------------------------- ----------------------------- 
----------------------------- ----------------------------- ----------------------------- ----------------------------- ----------------------------- ----------------------------- ----------------------------- ----------------------------- ----------------------------- ----------------------------- ----------------------------- ----------------------------- ----------------------------- ----------------------------- ----------------------------- ----------------------------- ----------------------------- -----C-----------------C----- ------C---------------C------ ----------------------C------ --------A-----------A-------- ---------A---------A--------- -----------A-----A----------- -------------AHA------------- ----------------------------- ----------------------------- 
----------------------------- ----------------------------- ----------------------------- ----------------------------- ----------------------------- ----------------------------- ----------------------------- ----------------------------- ----------------------------- ----------------------------- ----------------------------- ----------------------------- ----------------------------- ----------------------------- ----------------------------- ----------------------------- ----------------------------- ----------------------------- ------C---------------------- ------C---------------C------ ----------------------------- --------I-----------I-------- -----------A-----A----------- ------------IA-AI------------ --------------H-------------- ----------------------------- 
----------------------------- ----------------------------- ----------------------------- ----------------------------- ----------------------------- ----------------------------- ----------------------------- ----------------------------- ----------------------------- ----------------------------- ----------------------------- ----------------------------- ----------------------------- ----------------------------- ----------------------------- ----------------------------- ----------------------------- ----------------------------- ----------------------------- ------C---------------------- ----------------------------- ----------------------------- ----------------------------- ------------A---A------------ -------------AAA------------- --------------H-------------- 
----------------------------- ----------------------------- ----------------------------- ----------------------------- ----------------------------- ----------------------------- ----------------------------- ----------------------------- ----------------------------- ----------------------------- ----------------------------- ----------------------------- ----------------------------- ----------------------------- ----------------------------- ----------------------------- ----------------------------- ----------------------------- ----------------------------- ----------------------------- ----------------------------- ----------------------------- ----------------------------- ----------------------------- -------------I-I------------- ----------------------------- 
