model
size = 32 12 15, scale = 0.05, origin = -y
material 
  colors = A:#063
voxels
13-5A378-A5-A25-A5-A376-2A5-2A23-A7-A342-2A7-2A21-A9-A341-A9-A21-A9-A105-A-A29-A-A233-A9-A81-A19-A3-A2-A264-A9-A49-A19-A2-A3-2A26-A193-A73-2A9-2A20-A9-A17-A19-4A3-5A28-A188-A105-2A9-2A16-A14-A2(-2A)6-5A16-A10-3A23-A5-2A29-2A30-A61-A135-3A12-2(3A13-)5A10-A17-A12-A17-2A3-2A6-4A15-A10-3A29-A28-A-2A28-A-A166-2A17-2A30-3A30-2A9-2A14-A4-3A4-A18-A7-A31-A253-A31-A11-A20-A5-A18-A5-A25-A337-A19-A6-2A4-A369-2A30-A9-A405-A37-
