model
size = 21 17 17, scale = 0.05, origin = -y
material 
  colors = A:#BBB B:#003 C:#FFF D:#AAA E:#006 F:#111 G:#DDD H:#300
voxels
-------AAAAAAA------- -------AAAAAAA------- -------AAAAAAA------- --------------------- --------------------- --------------------- --------------------- --------------------- --------------------- --------------------- --------------------- --------------------- --------------------- --------------------- --------------------- --------------------- --------------------- 
----AAAA-----AAAA---- ----AAAADDDDDAAAA---- ----AAAADDDDDAAAA---- --------------------- --------------------- --------------------- --------------------- --------------------- --------------------- --------------------- --------------------- --------------------- --------------------- --------------------- --------------------- --------------------- --------------------- 
---AA-----------AA--- ---AADDDCCACCDDDAA--- ---AADDDAAAAADDDAA--- --------------------- --------------------- --------------------- --------------------- --------------------- --------------------- --------------------- --------------------- --------------------- --------------------- --------------------- --------------------- --------------------- --------------------- 
---A-------------A--- ---ADCCCCCCCCCCCDA--- ---ADAAAAAAAAAAADA--- --------------------- --------------------- --------------------- --------------------- --------------------- --------------------- --------------------- --------------------- --------------------- --------------------- --------------------- --------------------- --------------------- --------------------- 
--AA-------------AA-- -BBADCCCCCCCCCCCDABB- BB-ADAAAAAAAAAAADA-BB B-------------------B B-------------------B B-------------------B B-------------------B B-------------------B B-------------------B B-------------------B B-------------------B B-------------------B BB-----------------BB -BB---------------BB- --BB--EEE---------B-- --BBBBEEEBBBGBBBBBB-- ------EEE------------ 
--A----FF---------A-- -BBDCCCFFCCCCCCCCDBB- BB-ADAAAAAAAAAAADA-BB B-------------------B B-------------------B B-------------------B B-------------------B B-------------------B B-------------------B B-------------------B B-------------------B B-------------------B BB-----------------BB -BB---------------BB- --BB--EEE---------B-- --BBBBEEEBBBBGABBBB-- ------EEE----GA------ 
--A-----FF--------A-- -BBDCCCCFFCCCCCCCDBB- BB-ADAAAAAAAAAAADA-BB B-------------------B B-------------------B B-------------------B B-------------------B B-------------------B B-------------------B B-------------------B B-------------------B B-------------------B BB-----------------BB -BB---------------BB- --BB--EEE---------B-- --BBBBEEEBBBBBGABBB-- ------EEE-----GA----- 
--A------FF-------A-- -CCDCCCCCFFCCCCCCDCC- CC-ADAAAAAAAAAAADA-CC C-------------------C C-------------------C C-------------------C C-------------------C C-------------------C C-------------------C C-------------------C C-------------------C C-------------------C CC-----------------CC -CC---------------CC- --CC--EEE---------C-- --CCCCEEECCCCCGACCC-- ------EEE-----GA----- 
--A-------E-------A-- -CCDACCCCCHCCCCCADCC- CC-ADAAAAAAAAAAADA-CC C-------------------C C-------------------C C-------------------C C-------------------C C-------------------C C-------------------C C-------------------C C-------------------C C-------------------C CC-----------------CC -CC---------------CC- --CC--EEE---------C-- --CCC-EEE-C-C-GACCC-- ------EEE-----GA----- 
--A------FF-------A-- -CCDCCCCCFFCCCCCCDCC- CC-ADAAAAAAAAAAADA-CC C-------------------C C-------------------C C-------------------C C-------------------C C-------------------C C-------------------C C-------------------C C-------------------C C-------------------C CC-----------------CC -CC---------------CC- --CC--EEE---------C-- --CCCCEEECCCCCGACCC-- ------EEE-----GA----- 
--A-----FF--------A-- -BBDCCCCFFCCCCCCCDBB- BB-ADAAAAAAAAAAADA-BB B-------------------B B-------------------B B-------------------B B-------------------B B-------------------B B-------------------B B-------------------B B-------------------B B-------------------B BB-----------------BB -BB---------------BB- --BB--EEE---------B-- --BBBBEEEBBBBBGABBB-- ------EEE-----GA----- 
--A----FF---------A-- -BBDCCCFFCCCCCCCCDBB- BB-ADAAAAAAAAAAADA-BB B-------------------B B-------------------B B-------------------B B-------------------B B-------------------B B-------------------B B-------------------B B-------------------B B-------------------B BB-----------------BB -BB---------------BB- --BB--EEE---------B-- --BBBBEEEBBBBGABBBB-- ------EEE----GA------ 
--AA--FF---------AA-- -BBADCFFCCCCCCCCDABB- BB-ADAAAAAAAAAAADA-BB B-------------------B B-------------------B B-------------------B B-------------------B B-------------------B B-------------------B B-------------------B B-------------------B B-------------------B BB-----------------BB -BB---------------BB- --BB--EEE---------B-- --BBBBEEEBBBGBBBBBB-- ------EEE------------ 
---A--F----------A--- ---ADCFCCCCCCCCCDA--- ---ADAAAAAAAAAAADA--- --------------------- --------------------- --------------------- --------------------- --------------------- --------------------- --------------------- --------------------- --------------------- --------------------- --------------------- --------------------- --------------------- --------------------- 
---AA-----------AA--- ---AADDDCCACCDDDAA--- ---AADDDAAAAADDDAA--- --------------------- --------------------- --------------------- --------------------- --------------------- --------------------- --------------------- --------------------- --------------------- --------------------- --------------------- --------------------- --------------------- --------------------- 
----AAAA-----AAAA---- ----AAAADDDDDAAAA---- ----AAAADDDDDAAAA---- --------------------- --------------------- --------------------- --------------------- --------------------- --------------------- --------------------- --------------------- --------------------- --------------------- --------------------- --------------------- --------------------- --------------------- 
-------AAAAAAA------- -------AAAAAAA------- -------AAAAAAA------- --------------------- --------------------- --------------------- --------------------- --------------------- --------------------- --------------------- --------------------- --------------------- --------------------- --------------------- --------------------- --------------------- --------------------- 
