model
size = 24 32 26, scale = 0.05, origin = -y
material 
  colors = A:#5A3C00 B:#E00 C:#2D1500 D:#001 E:#800 F:#444 G:#777 H:#F90
voxels
321-4A19-5A18-3A2-A18-2A22-2A2-2A18-2A-3A18-5A19-4A598-4A19-5A18-3A2-A18-2A22-2A2-2A6-2B10-2A-3A8B8-2B5A4B5E8-16B22-2B476-3A20-4A18-6A17-7A5-17A-A5-16A-2A4-16A-3A4-10A-9A4-19A2B3-13A8B3-5A2B5A9B3-5A2B4A10B3-19A2B4-2(19A5-)19A6-17A7-17A8-16A9-15A10-14A11-12A14-9A190-5A18-6A17-7A16-8A2(14-10A)5-17ACA5-16AC2A4-16AC3A4-2(19A2B3-)3(19AD4-)19A2B4-18A2B4-19A5-19A6-18A6-17A8-16A9-15A10-14A11-12A14-9A190-5A15-9A14-10A13-11A6-18A3(5-19A)4-2(19A2B3-)19AD4-19AF3(4-19AD)5-2(18A2B4-)19A2(6-18A)7-16A9-15A10-14A11-12A14-9A13-6(7A17-)7A4-3A10-7A2-5A3(10-14A)6-18A3(5-19A)4-19A2B3-2(19AD4-)19AG4-19AF2(4-19AD)5-18AD5-18A2B4-19A2(6-18A)7-16A9-15A10-14A11-12A14-9A12-5(8A16-)8A5-2A9-8A4-3A9-8A2-5A3(9-15A)6-18A3(5-19A)4-19A2B3-3(19AD4-)19AG4-19AF4-19A2(D5-18A)2B4-19A2(6-18A)7-16A9-15A10-14A11-12A14-9A12-5(8A16-)8A5-2A9-8A4-3A9-8A2-5A3(9-15A)6-18A3(5-19A)4-19A2B3-4(19AD4-)19AG4-19AF5-18AD5-18A2B4-19A2(6-18A)7-16A9-15A10-14A11-12A14-9A11-5(10A14-)10A4-2A8-10A3-3A8-10A-4AC3(8-16A)6-18A3(5-19A)4-2(19A2B3-)4(19AD4-)19AD5-2(18A2B4-)19A2(6-18A)7-16A9-15A10-14A11-12A14-9A11-3(10A14-)2(10A5-C8-)10A4-AC8-10A3-2AC8-10A-5A3(8-16A)6-19A4-2(19A5-)19A4-20A4-2(19A2B3-)3(19AD4-)19A2B4-18A2B4-19A5-19A6-18A6-17A8-16A9-15A10-14A11-12A14-9A10-3(12A12-)3(12A3-2C7-)12A2-C2A3(7-17A)7-18A5-19A4-2(19A5-)19A4-2(22A2-)4(19A2B3-)19A2B4-2(19A5-)19A6-18A6-17A8-16A9-15A10-14A11-12A14-9A10-3(12A12-)3(12A3-2C7-)12A2-C2A3(7-17A)7-18A5-19A4-2(19A5-)19A4-20A-A2-22A2-2(20A4-)2(19A2B3-)20A3(5-19A)6-17A7-17A2(8-16A9-15A10-14A11-12A14-9A10-3(13A11-)3(13A2-2C7-)13A-C2A7-17A2(7-16AC)7-18A5-19A4-2(19A5-)19A4-71A-22A2-19A2B3-20AB3-19A3(6-18A)2(7-17A))8-16A9-15A10-14A11-12A14-9A10-3(12A12-)3(12A3-2C7-)12A2-C2A3(7-17A)7-18A5-19A4-2(19A5-)19A4-20A-A2-22A2-2(20A4-)2(19A2B3-)20A2(5-19A)5-18A2(7-17A)8-16A9-15A10-14A11-12A14-9A10-3(12A12-)3(12A3-2C7-)12A2-C2A3(7-17A)7-18A5-19A4-2(19A5-)19A4-2(22A2-)4(19A2B3-)19A2B4-2(19A5-)19A6-17A7-17A8-16A9-15A10-14A11-12A14-9A11-3(10A14-)2(10A5-C8-)10A4-AC8-10A3-2AC8-10A-5A3(8-16A)6-19A4-2(19A5-)19A4-20A4-2(19A2B3-)3(19AD4-)19A2B4-18A2B4-19A5-19A6-18A6-17A8-16A9-15A10-14A11-12A14-9A11-5(10A14-)10A4-2A8-10A3-3A8-10A-4AC3(8-16A)6-18A3(5-19A)4-2(19A2B3-)2(19AD4-)19AF2(4-19AD)5-2(18A2B4-)19A2(6-18A)7-16A9-15A10-14A11-12A14-9A12-5(8A16-)8A5-2A9-8A4-3A9-8A2-5A3(9-15A)6-18A3(5-19A)4-19A2B3-4(19AD4-)19AF4-19A2(D5-18A)2B4-19A2(6-18A)7-16A9-15A10-14A11-12A14-9A12-5(8A16-)8A5-2A9-8A4-3A9-8A2-5A3(9-15A)6-18A3(5-19A)4-19A2B3-4(19AD4-)19AG4-19AF5-18AD5-18A2B4-19A2(6-18A)7-16A9-15A10-14A11-12A14-9A13-6(7A17-)7A4-3A10-7A2-5A3(10-14A)6-18A3(5-19A)4-19A2B3-5(19AD4-)19AG5-18AF5-18A2B4-19A2(6-18A)7-16A9-15A10-14A11-12A14-9A190-5A14-10A13-11A2(12-12A)3(5-19A)4-2(19A2B3-)11A-7A4(D4-19A)D5-2(18A2B4-)19A2(6-18A)7-16A9-15A10-14A11-12A14-9A194-A17-7A16-8A15-9A14-10A5-7A2-10A5-17ACA5-16AC2A4-16AC3A4-19A2B3-11A-7A2B3-3(19AD4-)19A2B4-18A2B4-19A5-19A6-18A6-17A8-16A9-15A10-14A11-12A14-9A239-4A19-5A18-6A17-7A5-17A-A5-16A-2A4-16A-3A4-10A-9A4-19A2B3-13A8B3-5A2B5A9B3-5A2B4A10B3-19A2B4-2(19A5-)19A6-17A7-17A8-16A9-15A10-14A11-12A14-9A328-4A19-A3-A18-A-A2-A18-2A22-2A2-2A6-2B10-2A-3A8B8-2B5A4B5E8-16B22-2B564-3AH19-5A18-3A2-A18-2A22-2A2-2A18-2A-3A18-5A19-4A277-
