model
size = 31 32 31, scale = 0.05, origin = -y
material 
  colors = A:#069 B:#963 C:#400 D:#BBB E:#966 F:#003 G:#E00 H:#663 I:#036 J:#C63 K:#C6C L:#330 M:#111 N:#009 O:#300 P:#FF0 Q:#F90
voxels
787-3BE3B24-2BE3BE951-E12B18-E6BE4BH946-6BH9BH14-BHE14B516-4A26-5A25-3A2-A25-2A29-2A2-2A25-2A-3A25-5A26-4A208-E5B2E4BE6B12-5BE9BE3B515-4A26-5A25-3A2-A25-2A29-2A2-2A25-2A-3A6-2C17-5A7-2C10-7C4A10C10-21C10-17C2M2C10-21C104-6BH14B10-2B2H16BE398-3A27-4A25-6A24-7A12-17A-A12-16A-2A12-15A-3A12-9A-9A12-19A12-18A2C11-18A2C3(10-21C)10-C19AC11-19A12-19A13-17A12-22BE8-23B16-7B24-2DLQL2D24-2D3L2D24-3BE3B24-2(2BE)H186-5A25-6A24-7A23-8A2(21-10A)5(12-19A)12-18A2C11-18A4(G11-2C17A)2C11-19A12-19A13-18A10-25B6-E24B13-11B2(20-2D7B2D)20-E9BE20-H10B184-5A22-9A21-10A20-11A13-18A6(12-19A)12-18A2C11-18AJ3(11-2C17AG)11-2C17A2C11-2(19A12-)19A9-26BE4-H22BE2BE11-13B2(18-D11BD)18-13B18-7BH5B19-4(7A24-)7A4-3A17-7A2-5A3(17-14A)13-18A6(12-19A)12-18A2C11-18AG11-2C17AK11-2C17AJ11-2C17AG11-2C17A2C11-2(19A12-)19A9-23BE3B4-BHE22BEB10-15B2(16-D13BD)16-E13BE16-10BH4B17-3(8A23-)8A5-2A16-8A4-3A16-8A2-5A3(16-15A)13-18A6(12-19A)12-18A2C11-18A2(G11-2C17A)K11-2C17AJ11-2C17A2C11-2(19A12-)19A8-E28B2-2BE25BE8-17B2(14-D15BD)14-17B14-13B2E2B16-3(8A23-)8A5-AF16-8A4-2AF16-8A2-4AF3(16-15A)13-18A6(12-19A)12-18A2C11-18A3(G11-2C17A)K11-2C17A2C11-2(19A12-)19A8-26BH2B2-25BE3B7-19B2(12-D17BD)12-E18B12-19B14-2(10A21-)2(10A4-2F15-)10A3-2AF15-10A-5A3(15-16A)13-18A2(12-19A)12-18AF3(12-19A)12-18A2C11-18A4(G11-2C17A)2C11-2(19A12-)19A8-BH23BE3B2-29B7-19B2(12-D17BD)12-19B12-7BE10BH14-10A21-3(10A4-2F15-)10A3-2AF15-10A-5A3(15-16A)13-19A11-19A12-18AF4(12-19A)12-18A2C11-18A4(G11-2C17A)2C11-2(19A12-)19A7-32BE29B5-21B2(10-D19BD)10-21B10-4BE16B12-12A19-3(12A3-2F14-)12A2-2AF3(14-17A)14-18A12-19A11-19A12-18AF12-19A12-2(21A10-)19A12-18A2C11-18A2(2C10-2C17A)2(G11-2C17A)2C11-2(19A12-)18A8-BH2BE25BE28BE2B5-21B2(10-D19BD)10-21B10-E20B12-12A19-3(12A3-2F14-)12A2-2AF3(14-17A)14-18A12-19A11-19A12-18AF12-19A12-2(21A10-)2(19A12-)19A11-2C17A2C10-2(2C17AG11-)2C17A2C11-19A12-18A13-18A8-62B5-21B2(10-D19BD)10-20BE10-2BE4BE8BE4B12-13A18-3(13A2-2F14-)13A-2AF14-16AF2(14-17A)14-18A12-19A11-3(19A12-)2(23A8-)22A9-21A10-19A11-3(2C17A2C10-)2C18AC11-2(18A13-)18A8-BE13BO11B2E2BH14BO13B2E5-10B-10B2(10-D9B-9BD)10-H20B10-6BH14B12-13A18-3(13A2-2F14-)13A-2AF14-16AF2(14-17A)14-18A12-19A11-3(19A12-)2(23A8-)22A9-21A10-19A11-3(2C17A2C10-)2C18AC11-2(18A13-)18A8-30BE29BEB5-21B2(10-D19BD)10-E19BE10-4BE3BH2(4BE)2B12-12A19-12A3-2F14-12A3-FN14-12A3-2F14-12A2-2AF3(14-17A)14-18A12-19A11-19A12-18AF12-19A12-2(21A10-)2(19A12-)19A11-2C17A2C10-2(2C17AG11-)2C17A2C11-19A12-18A13-18A8-3BE2(28BH)5-21B2(10-D19BD)10-E20B10-H20B12-12A19-12A3-2N2(14-12A3-2F)14-12A2-2AF3(14-17A)14-18A12-19A11-19A12-18AF12-19A12-2(21A10-)19A12-18A2C11-18A2(2C10-2C17A)2(G11-2C17A)2C11-2(19A12-)18A8-E2BH22BEH5BE24BE3B5-21B2(10-D19BD)10-21B10-7BE12BE13-10A21-3(10A4-2F15-)10A3-2AF15-10A-5A3(15-16A)13-19A11-19A12-18AF4(12-19A)12-18A2C11-18A4(G11-2C17A)2C11-2(19A12-)19A8-29B2-29B7-19B2(12-D17BD)12-19B12-2BE7BE8B14-10A21-3(10A4-2F15-)10A3-2AF15-10A-5A3(15-16A)13-18A2(12-19A)12-18AF3(12-19A)12-18A2C11-18A4(G11-2C17A)2C11-2(19A12-)19A8-25BH3B2-29B7-19B2(12-D17BD)12-19B12-12BEBH4B15-2(8A23-)2(8A5-2F16-)8A4-2AF16-8A2-4AF3(16-15A)13-18A6(12-19A)12-18A2C11-18AJ3(11-2C17AG)11-2C17A2C11-2(19A12-)19A8-25B2E2B2-28BH8-17B2(14-D15BD)2(14-17B)16-3(8A23-)8A5-2A16-8A4-3A16-8A2-5A3(16-15A)13-18A6(12-19A)12-18A2C11-18AK11-2C17AJ2(11-2C17AG)11-2C17A2C11-2(19A12-)19A9-27B4-BE23BEB10-15B2(16-D13BD)16-15B16-2BE12B18-7A24-A4I2A24-4AI2A24-A4I2A24-2AI4A4-3A17-7A2-5A3(17-14A)13-18A6(12-19A)12-18A2C11-18AG11-2C17AK11-2C17AJ11-2C17AG11-2C17A2C11-2(19A12-)19A9-H26B4-4BE22B11-13B2(18-D11BD)18-13B18-5B2E2BH3B183-5A21-10A20-11A2(19-12A)5(12-19A)12-10A-8A12-18A2C11-18A2(G11-2C17A)K11-2C17AJ11-2C17A2C11-2(19A12-)19A10-22BE2B6-2BE21BE13-11B2(20-2D7B2D)2(20-11B)188-A24-7A23-8A22-9A21-10A12-7A2-10A4(12-19A)12-10A-8A12-18A2C11-18A4(G11-2C17A)2C11-19A12-19A13-18A11-23B8-23B16-7B2(24-7D)24-2BEBE2B24-E2BE3B249-4A26-5A25-6A24-7A12-17A-A12-16A-2A12-15A-3A12-9A-9A12-19A12-18A2C11-18A2C10-7C4A10C2(10-21C)10-CA19C12-18A15-16A16-14A13-21B10-3BEBH14BH514-4A26-A3-A25-A-A2-A25-2A29-2A2-2A25-2A-3A6-2C17-5A7-2C10-7C4A10C10-21C10-17C2M2C10-21C105-19B12-2E16BE515-4A26-5A25-3A2-A25-2A29-2A2-2A25-PA-3A25-5A26-4A209-5BH11B14-EH2BH8B2(EB)946-10BH2B18-4BHE7B951-BE2B2EH24-7B167-
