model
size = 29 32 30, scale = 0.05, origin = -y
material 
  colors = A:#963 B:#39F C:#30F D:#69F E:#111 F:#0F3 G:#EEE H:#90C I:#C30 J:#5A3C00 K:#C93 L:#888 M:#0FF
voxels
683-2B120-2B719-5B-B15-B2C2B6-B2-B13-BDB4C5-2B2-2B12-2D8B2-B19-2D2B2-B2-C2B14-2B2-3B2-2B18-3B7-2B19-4BC4-3B15-B438-3AG24-5A23-3A2-A23-2A27-2A2-2A23-2A-3A23-K4A24-4A-4B25-8B13-17B11-8B2C8B11-9B4C6B6-2B3-17B8-2B2-2B2D7BC5B9-15B4C14-5B2C3-4BC14-6BC3-5B13-5B9-2B399-B19-3B2-4A-2B14-2B3-B-5A-2B15-2B3-3A2-A2B17-3B-2A4-2B18-3B2A2-2A2B13-3B5-2A-3A2B13-B-5B-5A3B18-B2-4A-5B11-CB2-17B9-15B-5B9-C13B-4BC11-12B-4BC7-3B-12B-6B6-16B-5B8-4B3-14B9-B-2B2-5B2C6B10-4B2-5B2C6B13-2B-5B2D2B-4B315-3A25-4A23-6A22-7A10-8B9A-A10-7B9A-2A9-7B13A9-7B3A-9A9-7B2(8A5E8-8B)5A2BA5E8-8B4A3B3A3E8-C14B6A8-15B6A8-2C15B4AB7-17B4A2(C7-20BA)2B6-21BD9-20B9-21B8-20B9-B3C2B-5D8B19-4B203-5A23-6A22-7A21-8A11-2B6-10A12-2B5-10A10-8B11A10-4B2(15A9-5B)5AJ9A9-5B14AE8-5B2(15AE7-6B)15AE7-C5B16A7-6B15AJ7-C5B2(16A7-6B)16AC6-6B16A2B6-C4B16AD9-19BD9-21B8-20B9-20B14-7B6D199-5A20-9A19-10A18-11A11-6B12A10-7B12A2(10-4B15A)2(9-C4B15A)9-C4B14AE8-5B15AF7-6B15AF6-7B15AE2(6-7B16A)6-7B15AJ6-7B16A6-C6B16AB6-C5B16A2B6-C4B16A2B8-19BD9-20BD8-21B8-20B9-2B3-4BC7BD16-4C25-2(7A22-)3EL3E2(22-7A)4-3A15-7A2-5A3(15-14A)11-4B14A2(10-4B15A)10-C3B15A9-C4B2(15A9-5B)14AE8-5B15AM7-6B15AF6-7B15AE2(5-G7B16A)5-G7B15AJ5-G7B16A6-C6B16A7-6B16AB7-5B16A2B8-19BD9-20B9-21B8-21B9-3B-2BC10B19-2CB2-3CBC15-2(8A21-)E6AE21-8A5-2A14-8A4-3A14-8A2-5A3(14-15A)11-3B3(15A10-4B)15A9-5B15A9-D4B15A9-5B14AE8-5B15AG6-7B15AM6-7B15AE5-G7B2(16A4-9B)15AJ5-G7B16A6-C6B16A7-C5B16AB7-C4B16A2B8-2(19BD9-)20B9-3C18B11-12B3C-2B13-B4-4B19-2(8A21-)E6AE21-8A5-2A14-8A4-3A14-8A2-5A3(14-15A)11-3B2(15A10-4B)15A10-D3B2(15A9-D4B)15A9-5B14AE8-5B15AF6-7B15AG6-7B15AE5-G7B16A4-9B15AJ4-9B16A5-G7B16A6-7B16A7-C5B16AB7-5B16A2B7-22B7-2(20BD8-)3B2C16B14-15B14-B2C24-2(10A19-)E8AE19-10A4-2A13-10A3-3A13-10A-5A3(13-16A)11-3B15A10-4B2(15A10-D3B)3(15A9-5B)14AE8-5B2(15AF6-7B)15AE3(5-G7B16A)B4-G7B16A6-7B16A7-6B16AB7-5B16AB9-21B8-20B9-19BD8-4B2C14BD9-B4-C12B18-2C5-4B14-2(10A19-)E8AE19-10A4-2A13-10A3-3A13-10A-4AJ2(13-16A)13-B15A11-3B15AI9-4B15A10-D3B15A10-4B15A9-5B2(15A9-C4B)14AE8-5B2(15AF6-7B)15AE2(6-7B16A)6-C6B2(16AB5-7B)16A7-6B16A8-5B16AC9-3(21B8-)20B9-15B2CB19-7B16-2(12A17-)E10AE17-12A3-2A12-12A2-3A3(12-17A)12-2B15AI10-3B15AI9-2(4B15A10-)C3B2(15A9-C4B)15A9-5B14AE8-5B2(15AF7-6B)15AE2(7-C5B16A7-6B16A)2(B6-6B16A)B7-5B16A2(C9-19B)C9-21B8-21B13-16B39-2(12A17-)E10AE17-12A3-2A12-12A2-3A12-17A3(12-B16A)I10-3B15AI9-4B2(15A10-C3B)15A9-2(5B17A7-)5B14AE8-5B2(15AF7-6B)15AE2(7-C5B16A7-6B16A)2(7-6B16A)B7-5B16AB9-20B2(9-19BC)9-20B14-3B5D5B24-4DB13-2(13A16-)E11AE16-13A2-2A12-13A-3A12-17A3(12-B16A)I10-3B15AI9-2(4B15A10-)4B15A9-2(5B18A6-)5B18A5-5B15AE8-5B15AF8-5B15AE2(8-C4B16A8-5B16A)3(8-5B16A)13-C13BA15-C12BA16-C11B17-11B18-13B23-2B17-2(13A16-)E11AE16-13A2-2A12-13A-3A12-17A3(12-B16A)I10-3B15AI9-C3B2(15A10-4B)15A9-3(5B18A6-)4B15AE9-4B15AF9-C3B15AE9-C3B2(16A10-C2B)16A10-3B2(16A11-CB)16AB11-C16AC12-C15BC13-15BC14-14BC14-11B18-9B20-3CB2-2B18-2(12A17-)E10AE17-12A3-2A12-12A2-3A12-17A2(12-B16A)12-2B15AI10-3B15AI9-4B15A10-C3B15A10-D3B15A9-D4B2(17A7-5B)14AE9-4B2(15AF9-C3B)15AE9-4B16A10-3B2(16A10-C2B)16A11-CB16AB10-CB16AB11-B16AC12-17B13-16B14-15BH2(13-12B4H)16-4B19-2(12A17-)E10AE17-12A3-2A12-12A2-3A3(12-17A)12-2B15AI10-3B15AI9-4B2(15A10-C3B)2(15A9-D4B)15A9-5B14AE9-4B2(15AF8-5B)15AE8-5B16A8-5B15AJ2(8-5B16A)3(B7-5B16A)BH6-22B3(H12-16B)H12-2B6C6B25-4B14-2(10A19-)E8AE19-10A4-2A13-10A3-3A13-10A-5A2(13-16A)13-B15A11-3B15AI9-2(4B15A10-)C3B15A9-C4B2(15A9-5B)14AE9-4B15AF8-5B15AF6-7B15AE2(6-7B16A)6-7B15AJ6-2(7B16AB5-)7B16ABH5-6B16ABH6-22B3(10-19B)13-12B2D16-3B5-2B17-2(10A19-)E8AE19-10A4-2A13-10A3-3A13-10A-5A3(13-16A)11-3B15A10-4B2(15A10-D3B)2(15A9-C4B)15A7-7B14AE2(7-6B15AF)5-8B15AE4(4-G8B16A)B4-8B16ABH4-7B16ABH5-C5B16AB7-C21B10-19B10-20B9-17BDB13-10B4D15-2B-2B2-3B19-2(8A21-)E6AE21-8A5-2A14-8A4-3A14-8A2-5A3(14-15A)11-3B15A10-C3B15A10-4B15A10-D3B2(15A9-5B)15A7-7B14AE7-C5B15AF7-6B15AF5-8B15AE4-G8B2(16A3-10B)16AB3-G8B16AB4-8B16ABH4-C6B16AB6-C5B16AB7-22B10-20B9-17B2DB9-16BD13-10B3D3B19-4D2(21-8A)21-E6AE21-8A5-2A14-8A4-3A14-8A2-5A3(14-15A)11-2(3B15A10-C)3B15A10-D3B15A9-D4B15A9-5B15A7-7B14AE2(7-C5B15AF)5-8B15AE4-G8B16A3-10B15AJ3-10B16AB3-G8B16ABH3-8B16ABH4-7B16AB6-6B16A2B6-23B9-19BD9-18BD10-2BC14B12-BC-2C6B2D4B45-2(7A22-)4EL2E2(22-7A)4-3A15-7A2-5A3(15-14A)11-4B14A10-4B2(15A10-C3B)2(15A9-D4B)15A7-7B14AE7-6B15AF7-C5B15AF5-8B15AE3(4-G8B16A)H3-G8B16AB4-C7B16AB5-C6B16AB6-C5B16A2B6-22B8-20BD9-20B9-2B2C14B12-C2-14B17-4B3-5B170-5A19-10A18-11A2(17-12A)10-7B12A10-4B15A10-C3B2(15A9-D4B)15A7-BD5B6A-7AE7-6B15AF7-C5B15AF5-BC6B15AE3(5-8B16A)B4-8B16AB4-C7B16AB5-C6B16AB6-6B16A2B6-B2C19B3(10-C18B)12-12B2C2B14-4B5-B178-A22-7A21-8A20-9A19-10A10-7B2-10A10-4B3AB11A10-D3B15A9-C4B15A9-5B5AJ9A7-7B6A-7A2(E7-6B15A)E6-7B15AE2(6-7B16A)4(B5-7B16A)2B5-6B16AB7-2BC19B10-C18B10-20B9-17B-B11-2B-B4-4B2C2B21-3BC233-4A24-5A21-B-6A22-7A10-2D5B10A-A10-D2B3DB9A-2A9-D2B2D2B9A-3A9-DB2D3B3A-9A7-B4D4B6AE2A4E7-B2D6B6A2(EA)3E7-8BC5A2EB2EA2EB6-C7BC4A3EBAEA2EB6-C16B5AB5-C3(19B3AB6-)21BA2B5-21BAB2(7-22B)8-22B8-21B8-8B2CB2C5B12-2B-2B4-2B2C4B342-B24-4AB23-A3-AB22-A-A2-A2B21-2A5-B21-2A2-2A-2B20-2A-3A2(-B)4-2B5-2BCBC2B-5A2(2-B)2-2B6-5BCB-4A3-2B-B10-2C11B2D3BD2B7-15B2D2C2DB7-C3BC11B2D2C2DB7-C2BC12BDBC2D2B6-C3BC12BD2B2D6-BC13BC5B2C7-15B4D3B7-7B3-8B2D2B9-2B6-9BD2B10-B-B4-C4BC6B12-2B10-3B396-3AG24-5A23-3A2-A23-KA27-2A2-2A23-KA-3A15-BC6-5A17-3BC3-4A21-B29-2C5B17-3B-9B18-B-12B5-B9-B2-9B-BD14-12B2-4B9-2B3-9B5-2B9-2B3-8BC3B2-2B13-8B3-B19-6B3-B713-CB-4B21-9B20-9B21-3BCBC2B21-8B21-3B3C2B-B19-5BC2B23-6B745-B4-4B20-2B2(-B)-2B21-3B30-3B24-B3-2B24-2B-2B25-B100-
