model
size = 22 24 29, scale = 0.05, origin = -y
material 
  colors = A:#006 B:#FC0 C:#1F9EFF D:#187CC9 E:#FFC822 F:#FFCE48 G:#FFCA0C H:#FFC814 I:#3D3D3D J:#FFCD38 K:#FFCF56 L:#06F M:#FFD15E N:#FFD46F
voxels
---------------------- ---------------------- ---------BAAB--------- ---------BAAB--------- ---------BAAB--------- ----------AA---------- ----------BB---------- ---------------------- ---------------------- ---------------------- ---------------------- ---------------------- ---------------------- ---------------------- ---------------------- ---------------------- ---------------------- ---------------------- ---------------------- ---------------------- ---------------------- ---------------------- ---------------------- ---------------------- 
--------AAAAAA-------- --------BBAABB-------- -------BBBAABBB------- -------ABAAAABA------- -------ABIIIIBA------- -------AAAAAAAA------- --------GGBBGG-------- ---------GBBG--------- ----------BB---------- ----------BB---------- ---------------------- ---------------------- ---------------------- ---------------------- ---------------------- ---------------------- ---------------------- ---------------------- ---------------------- ---------------------- ---------------------- ---------------------- ---------------------- ---------------------- 
------AAAAAAAAAA------ ------AAAAAAAAAA------ ------BBAAAAAABB------ ------AAAAAAAAAA------ ------DIIIIIIIID------ ------AAAAAAAAAA------ -------HGBBBBGH------- -------HGBBBBGH------- --------GGBBGG-------- ---------GBBG--------- ---------GBBG--------- ----------BB---------- ----------BB---------- ---------------------- ---------------------- ---------------------- ---------------------- ---------------------- ---------------------- ---------------------- ---------------------- ---------------------- ---------------------- ---------------------- 
-----AAAAAAAAAAAA----- -----ALLLLLLLLLLA----- -----BLLLLBBLLLLB----- -----AAAAAAAAAAAA----- -----CIIIIIIIIIIC----- -----AAAAAAAAAAAA----- -----EHBBBBBBBBHE----- -----EHBBBBBBBBHE----- ------HHBGBBGBHH------ -------HGGBBGGH------- -------HGGBBGGH------- --------GGBBGG-------- ---------GBBG--------- ---------GBBG--------- ----------BB---------- ---------------------- ---------------------- ---------------------- ---------------------- ---------------------- ---------------------- ---------------------- ---------------------- ---------------------- 
----AAA--------AAA---- ----AALAAAAAAAALAA---- ----BALLBBBBBBLLAB---- ----AAAAAAAAAAAAAA---- ----DIIIIIAAIIIIID---- ----AAAAAAAAAAAAAA---- ----EBBGGG--GGGBBE---- ----EBBHGG--GGHBBE---- ----EEBHG----GHBEE---- -----EHHG----GHHE----- -----EHHG----GHHE----- ------EHG----GHE------ -------HG----GH------- -------HGG--GGH------- --------HG--GH-------- --------EHHHHE-------- --------AAAAAA-------- ---------------------- ---------------------- ---------------------- ---------------------- ---------------------- ---------------------- ---------------------- 
---AAA----------AAA--- ---ALLAAAAAAAAAALLA--- ---BLLBBAAAAAABBLLB--- ---AAAAAAA--AAAAAAA--- ---CIIIAAA--AAAIIIC--- ---AAAAAAA--AAAAAAA--- ---JBEH--------HEBJ--- ---JBEH--------HEBJ--- ---JBEH--------HEBJ--- ---JEEH--------HEEJ--- ----EEH--------HEE---- -----EH--------HE----- -----EE--------EE----- ------EH------HE------ ------EE------EE------ ------EE------EE------ ------AAAAAAAAAA------ -------ABBAABBA------- ---------BAAB--------- ---------------------- ---------------------- ---------------------- ---------------------- ---------------------- 
--AA--------------AA-- --AAAA----------AAAA-- --BBBBAA------AABBBB-- --AAAAA--------AAAAA-- --DIIAA--------AAIID-- --AAAAA--------AAAAA-- --JEE------------EEJ-- --JEE------------EEJ-- --JEE------------EEJ-- --JEE------------EEJ-- ---JE------------EJ--- ---JE------------EJ--- ---JE------------EJ--- ----EE----------EE---- -----E----------E----- -----E----------E----- -----AAA------AAA----- -----CDAAAAAAAADC----- ------AABAAAABAA------ -------BBBAABBB------- ---------------------- ---------------------- ---------------------- ---------------------- 
--A----------------A-- --AA--------------AA-- --BAAA----------AAAB-- --AAAA----------AAAA-- --CAA------------AAC-- --AAA------------AAA-- --J----------------J-- --J----------------J-- --J----------------J-- --J----------------J-- --J----------------J-- --J----------------J-- ---J--------------J--- ---J--------------J--- ---JJ------------JJ--- ----J------------J---- ----AA----------AA---- ----DAA--------AAD---- -----AAAA----AAAA----- -----BBAAAAAAAABB----- -------ABBAABBA------- ---------------------- ---------------------- ---------------------- 
--A----------------A-- -AA----------------AA- -BBA--------------ABB- -AAA--------------AAA- -DIA--------------AID- -AAA--------------AAA- -FF----------------FF- -FF----------------FF- -FF----------------FF- -FF----------------FF- --F----------------F-- --F----------------F-- --F----------------F-- --F----------------F-- ---F--------------F--- ---F--------------F--- ---AA------------AA--- ----CA----------AC---- ----AA----------AA---- ----BAA--------AAB---- -----AAAAAAAAAAAA----- -------ABBAABBA------- ---------------------- ---------------------- 
--A----------------A-- -AA----------------AA- -BBA--------------ABB- -AAA--------------AAA- -CIA--------------AIC- -AAA--------------AAA- -F------------------F- -F------------------F- -F------------------F- -F------------------F- -F------------------F- --F----------------F-- --F----------------F-- --F----------------F-- --F----------------F-- --F----------------F-- --AA--------------AA-- ---DA------------AD--- ----AA----------AA---- ----BA----------AB---- -----AAAAAAAAAAAA----- ------CABBAABBAC------ ---------------------- ---------------------- 
--A----------------A-- -AA----------------AA- -BA----------------AB- AAA----------------AAA DIA----------------AID AIA----------------AIA KF------------------FK KF------------------FK KF------------------FK -F------------------F- -F------------------F- -F------------------F- -F------------------F- --F----------------F-- --F----------------F-- --F----------------F-- --AA--------------AA-- --CA--------------AC-- ---AAA----------AAA--- ----BA----------AB---- -----AAAAAAAAAAAA----- ------DABAAAABAD------ ---------BAAB--------- ---------------------- 
--A----------------A-- -AA----------------AA- -BA----------------AB- AAA----------------AAA CIA----------------AIC AAA----------------AAA K--------------------K K--------------------K K--------------------K K--------------------K -K------------------K- -K------------------K- -K------------------K- -F------------------F- -F------------------F- -AA----------------AA- --CA--------------AC-- --DA--------------AD-- --AA--------------AA-- ---BA------------AB--- ----AA----------AA---- -----DAAAAAAAAAAD----- ------CABBAABBAC------ ---------------------- 
--A----------------A-- -AA----------------AA- -BA----------------AB- AA------------------AA DA------------------AD AA------------------AA K--------------------K K--------------------K M--------------------M M--------------------M M--------------------M K--------------------K -K------------------K- -K------------------K- -AA----------------AA- -CA----------------AC- --DA--------------AD-- --CA--------------AC-- --AA--------------AA-- ---BA------------AB--- ----AA----------AA---- -----CAAAAAAAAAAC----- ------DABBAABBAD------ ----------AA---------- 
--A----------------A-- -AA----------------AA- -BA----------------AB- AA------------------AA CA------------------AC AA------------------AA M--------------------M M--------------------M M--------------------M M--------------------M M--------------------M M--------------------M K--------------------K K--------------------K AA------------------AA -DA----------------AD- -CA----------------AC- --DA--------------AD-- --AA--------------AA-- --BA--------------AB-- ---AA------------AA--- ----CAA--------AAC---- -----DCAAAAAAAACD----- -------ABBAABBA------- 
--A----------------A-- -AA----------------AA- -BA----------------AB- AA------------------AA DA------------------AD CA------------------AC AA------------------AA N--------------------N N--------------------N N--------------------N M--------------------M M--------------------M M--------------------M AA------------------AA DA------------------AD CA------------------AC -DA----------------AD- -CA----------------AC- --AA--------------AA-- --BA--------------AB-- ---AA------------AA--- ----DAA--------AAD---- -----CDAAAAAAAADC----- -------ABBAABBA------- 
--A----------------A-- -AA----------------AA- -BA----------------AB- AA------------------AA CA------------------AC DA------------------AD CA------------------AC AA------------------AA N--------------------N N--------------------N N--------------------N N--------------------N M--------------------M AA------------------AA CA------------------AC DA------------------AD -CA----------------AC- -DA----------------AD- --AA--------------AA-- --BA--------------AB-- --AAA------------AAA-- ----CAA--------AAC---- -----DCAAAAAAAACD----- -------ABBAABBA------- 
--A----------------A-- -AA----------------AA- -BA----------------AB- AA------------------AA DA------------------AD CA------------------AC DA------------------AD AA------------------AA AA------------------AA A--------------------A AA------------------AA AA------------------AA AA------------------AA CA------------------AC DA------------------AD CA------------------AC -DA----------------AD- --CA--------------AC-- --AA--------------AA-- --BA--------------AB-- ---AA------------AA--- ----DAA--------AAD---- -----CDAAAAAAAADC----- -------ABBAABBA------- 
--A----------------A-- -AA----------------AA- -BA----------------AB- AA------------------AA CA------------------AC DA------------------AD CA------------------AC AA------------------AA BA------------------AB AA------------------AA CA------------------AC DA------------------AD CA------------------AC DA------------------AD -CA----------------AC- -DA----------------AD- --CA--------------AC-- --DA--------------AD-- --AA--------------AA-- ---BA------------AB--- ----AA----------AA---- -----DA--------AD----- ------CAAAAAAAAC------ -------ABBAABBA------- 
--A----------------A-- -AA----------------AA- -BA----------------AB- -AA----------------AA- -DA----------------AD- CA------------------AC DA------------------AD AA------------------AA BA------------------AB AA------------------AA DA------------------AD CA------------------AC -DA----------------AD- -CA----------------AC- -DA----------------AD- -CA----------------AC- --DA--------------AD-- --CA--------------AC-- --AA--------------AA-- ---BA------------AB--- ----AA----------AA---- -----CA--------AC----- ------DAAAAAAAAD------ -------ABBAABBA------- 
--A----------------A-- -AAA--------------AAA- -BA----------------AB- -AA----------------AA- -CA----------------AC- -DA----------------AD- -CA----------------AC- -AA----------------AA- BA------------------AB -AA----------------AA- -CA----------------AC- -DA----------------AD- -CA----------------AC- -DA----------------AD- -CA----------------AC- --DA--------------AD-- --CA--------------AC-- --DA--------------AD-- ---AA------------AA--- ----BA----------AB---- -----AA--------AA----- ------CAA----AAC------ -------ABAAAABA------- ---------BAAB--------- 
--A----------------A-- --AA--------------AA-- --BA--------------AB-- -AA----------------AA- -DA----------------AD- -CA----------------AC- -DA----------------AD- -AA----------------AA- -BA----------------AB- -AA----------------AA- -DA----------------AD- -CA----------------AC- -DA----------------AD- -CA----------------AC- --DA--------------AD-- --CA--------------AC-- --DA--------------AD-- ---CA------------AC--- ----AA----------AA---- ----BA----------AB---- -----AA--------AA----- ------DAAA--AAAD------ -------ABBAABBA------- ----------AA---------- 
--A----------------A-- --AA--------------AA-- --BA--------------AB-- --AA--------------AA-- --CA--------------AC-- --DA--------------AD-- --CA--------------AC-- -AA----------------AA- -BA----------------AB- -AA----------------AA- -CA----------------AC- --DA--------------AD-- --CA--------------AC-- -DA----------------AD- --CA--------------AC-- --DA--------------AD-- ---CA------------AC--- ---AA------------AA--- ----AA----------AA---- ----BAA--------AAB---- -----AAAAA--AAAAA----- -------ABBAABBA------- ----------AA---------- ---------------------- 
--A----------------A-- --AA--------------AA-- --BAA------------AAB-- --AA--------------AA-- --DA--------------AD-- --CA--------------AC-- --DA--------------AD-- --AA--------------AA-- --BA--------------AB-- --AA--------------AA-- --DA--------------AD-- --CA--------------AC-- --DA--------------AD-- --CA--------------AC-- --DA--------------AD-- --CA--------------AC-- ---DAA----------AAD--- ----AAA--------AAA---- ----BAAA------AAAB---- -----BBAA----AABB----- -------ABAAAABA------- ---------BAAB--------- ---------------------- ---------------------- 
---AA------------AA--- --AAAA----------AAAA-- --B-MA----------AM-B-- --ABA------------ABA-- --CAA------------AAC-- --DAA------------AAD-- --CA--------------AC-- --AA--------------AA-- --BA--------------AB-- --AA--------------AA-- --CA--------------AC-- --DA--------------AD-- --CAA------------AAC-- --DA--------------AD-- --CAA------------AAC-- ---DAA----------AAD--- ----AAA--------AAA---- -----BBA------ABB----- -----BBBAA--AABBB----- -------BBAAAABB------- ---------BAAB--------- ---------------------- ---------------------- ---------------------- 
----AA----------AA---- ----ABA--------ABA---- ---BBBAAA----AAABBB--- ---AAAAA------AAAAA--- ---DCAAA------AAACD--- ---CDAA--------AADC--- ---DAAA--------AAAD--- --AAAAA--------AAAAA-- --BAA------------AAB-- --AAAA----------AAAA-- --DAAAA--------AAAAD-- ---CAAA--------AAAC--- ---DCAA--------AACD--- ---CAAA--------AAAC--- ---DCAAA------AAACD--- ----DAAAA----AAAAD---- ------BAAA--AAAB------ -------BAAAAAAB------- --------BBAABB-------- ---------BBBB--------- ---------------------- ---------------------- ---------------------- ---------------------- 
------A--------A------ ------BAAAAAAAAB------ ------BBMAAAAMBB------ -----ABBAA--AABBA----- -----DABA----ABAD----- -----CAAA----AAAC----- ----CDCA------ACDC---- ---AAAAA------AAAAA--- ---BBAA--------AABB--- ---AAAA--------AAAA--- ---DCDCA------ACDCD--- ----DCDA------ADCD---- -----DCAA----AACD----- ----DCAAA----AAACD---- -----DABA----ABAD----- ------ABBA--ABBA------ -------BBBAABBB------- --------BBAABB-------- ----------BB---------- ---------------------- ---------------------- ---------------------- ---------------------- ---------------------- 
-------AAAAAAAA------- -------BBBAABBB------- --------BBAABB-------- --------BBAABB-------- --------BAAAAB-------- -------BBAAAABB------- -------AAAAAAAA------- -------AAAAAAAA------- -----BBAAA--AAABB----- ------AAAA--AAAA------ -------AAAAAAAA------- -------AAAAAAAA------- -------ABAAAABA------- -------ABAAAABA------- --------BAAAAB-------- ---------BAAB--------- ----------AA---------- ---------------------- ---------------------- ---------------------- ---------------------- ---------------------- ---------------------- ---------------------- 
---------------------- ---------------------- ---------------------- ----------AA---------- ---------BAAB--------- ---------BAAB--------- --------BBAABB-------- --------BBBBBB-------- -------BBBAABBB------- -------ABBAABBA------- --------BBAABB-------- --------BBAABB-------- ---------BAAB--------- ---------BAAB--------- ---------BAAB--------- ----------AA---------- ---------------------- ---------------------- ---------------------- ---------------------- ---------------------- ---------------------- ---------------------- ---------------------- 
---------------------- ---------------------- ---------------------- ---------------------- ---------------------- ---------------------- ---------------------- ---------------------- ----------BB---------- ----------BB---------- ---------------------- ---------------------- ---------------------- ---------------------- ---------------------- ---------------------- ---------------------- ---------------------- ---------------------- ---------------------- ---------------------- ---------------------- ---------------------- ---------------------- 
