model
size = 22 24 29, scale = 0.05, origin = -y
material 
  colors = A:#2D2D2D B:#D7FF00 C:#272727 D:#000 E:#3D3D3D F:#595959 G:#323232 H:#353535 I:#4B4B4B J:#666 K:#06F L:#717171 M:#FC0 N:#7F7F7F
voxels
---------------------- ---------------------- ---------CCCC--------- ---------CCCC--------- ---------BBBB--------- ----------DD---------- ----------AA---------- ---------------------- ---------------------- ---------------------- ---------------------- ---------------------- ---------------------- ---------------------- ---------------------- ---------------------- ---------------------- ---------------------- ---------------------- ---------------------- ---------------------- ---------------------- ---------------------- ---------------------- 
--------DDDDDD-------- --------BCBBCB-------- -------CCMDDMCC------- -------CCDDDDCC------- -------BBEEEEBB------- -------DDDDDDDD------- --------GGAAGG-------- ---------GAAG--------- ----------AA---------- ----------AA---------- ---------------------- ---------------------- ---------------------- ---------------------- ---------------------- ---------------------- ---------------------- ---------------------- ---------------------- ---------------------- ---------------------- ---------------------- ---------------------- ---------------------- 
------DDDDDDDDDD------ ------CCDDDDDDCC------ ------CMDDDDDDMC------ ------CDDDDDDDDC------ ------BEEEEEEEEB------ ------DDDDDDDDDD------ -------HGAAAAGH------- -------HGAAAAGH------- --------GGAAGG-------- ---------GAAG--------- ---------GAAG--------- ----------AA---------- ----------AA---------- ---------------------- ---------------------- ---------------------- ---------------------- ---------------------- ---------------------- ---------------------- ---------------------- ---------------------- ---------------------- ---------------------- 
-----DDDDDDDDDDDD----- -----BKKKKKKKKKKB----- -----CKKKKMMKKKKC----- -----CDDDDDDDDDDC----- -----BEEEEEEEEEEB----- -----DDDDDDDDDDDD----- -----EHAAAAAAAAHE----- -----EHAAAAAAAAHE----- ------HHAGAAGAHH------ -------HGGAAGGH------- -------HGGAAGGH------- --------GGAAGG-------- ---------GAAG--------- ---------GAAG--------- ----------AA---------- ---------------------- ---------------------- ---------------------- ---------------------- ---------------------- ---------------------- ---------------------- ---------------------- ---------------------- 
----DDD--------DDD---- ----CDKDDDDDDDDKDC---- ----CDKKMMMMMMKKDC---- ----CDDDDDAADDDDDC---- ----BEEEEEAAEEEEEB---- ----DDDDDDCCDDDDDD---- ----EAAGGG--GGGAAE---- ----EAAHGG--GGHAAE---- ----EEAHG----GHAEE---- -----EHHG----GHHE----- -----EHHG----GHHE----- ------EHG----GHE------ -------HG----GH------- -------HGG--GGH------- --------HG--GH-------- --------EHHHHE-------- --------DDDDDD-------- ---------------------- ---------------------- ---------------------- ---------------------- ---------------------- ---------------------- ---------------------- 
---DDD----------DDD--- ---BKKDDDDDDDDDDKKB--- ---CKKMMAAAAAAMMKKC--- ---CDDDAAA--AAADDDC--- ---BEEEAAA--AAAEEEB--- ---DDDDCCC--CCCDDDD--- ---IAEH--------HEAI--- ---IAEH--------HEAI--- ---IAEH--------HEAI--- ---IEEH--------HEEI--- ----EEH--------HEE---- -----EH--------HE----- -----EE--------EE----- ------EH------HE------ ------EE------EE------ ------EE------EE------ ------DDCCCCCCDD------ -------BBBBBBBB------- ---------CCCC--------- ---------------------- ---------------------- ---------------------- ---------------------- ---------------------- 
--DD--------------DD-- --CDDD----------DDDC-- --CMMMAA------AAMMMC-- --CDDDA--------ADDDC-- --BEEAA--------AAEEB-- --DDDCC--------CCDDD-- --IEE------------EEI-- --IEE------------EEI-- --IEE------------EEI-- --IEE------------EEI-- ---IE------------EI--- ---IE------------EI--- ---IE------------EI--- ----EE----------EE---- -----E----------E----- -----E----------E----- -----DCC------CCD----- -----BBAAAAAAAABB----- ------CCCAAAACCC------ -------CCCCCCCC------- ---------------------- ---------------------- ---------------------- ---------------------- 
--D----------------D-- --BD--------------DB-- --CAAA----------AAAC-- --CAAA----------AAAC-- --BAA------------AAB-- --DCC------------CCD-- --I----------------I-- --I----------------I-- --I----------------I-- --I----------------I-- --I----------------I-- --I----------------I-- ---I--------------I--- ---I--------------I--- ---II------------II--- ----I------------I---- ----DC----------CD---- ----BAA--------AAB---- -----CAAA----AAAC----- -----CCAAAAAAAACC----- -------CCCCCCCC------- ---------------------- ---------------------- ---------------------- 
--D----------------D-- -CD----------------DC- -CMA--------------AMC- -CDA--------------ADC- -BEA--------------AEB- -DDC--------------CDD- -FF----------------FF- -FF----------------FF- -FF----------------FF- -FF----------------FF- --F----------------F-- --F----------------F-- --F----------------F-- --F----------------F-- ---F--------------F--- ---F--------------F--- ---DC------------CD--- ----BA----------AB---- ----CA----------AC---- ----CAA--------AAC---- -----CCAAAAAAAACC----- -------BBBBBBBB------- ---------------------- ---------------------- 
--D----------------D-- -CD----------------DC- -CMA--------------AMC- -CDA--------------ADC- -BEA--------------AEB- -DCC--------------CCD- -F------------------F- -F------------------F- -F------------------F- -F------------------F- -F------------------F- --F----------------F-- --F----------------F-- --F----------------F-- --F----------------F-- --F----------------F-- --DC--------------CD-- ---BA------------AB--- ----CA----------AC---- ----CA----------AC---- -----CAAAAAAAAAAC----- ------BBBBBBBBBB------ ---------------------- ---------------------- 
--D----------------D-- -BD----------------DB- -CA----------------AC- BDA----------------ADB BEA----------------AEB DEC----------------CED JF------------------FJ JF------------------FJ JF------------------FJ -F------------------F- -F------------------F- -F------------------F- -F------------------F- --F----------------F-- --F----------------F-- --F----------------F-- --DC--------------CD-- --BA--------------AB-- ---CAA----------AAC--- ----CA----------AC---- -----CAAAAAAAAAAC----- ------BBBDDDDBBB------ ---------BBBB--------- ---------------------- 
--D----------------D-- -CA----------------AC- -CA----------------AC- CDA----------------ADC BEA----------------AEB DCC----------------CCD J--------------------J J--------------------J J--------------------J J--------------------J -J------------------J- -J------------------J- -J------------------J- -F------------------F- -F------------------F- -DC----------------CD- --CC--------------CC-- --BA--------------AB-- --CA--------------AC-- ---CA------------AC--- ----CA----------AC---- -----BAAAAAAAAAAB----- ------BBBBBBBBBB------ ---------------------- 
--D----------------D-- -CA----------------AC- -CA----------------AC- BA------------------AB CA------------------AC DC------------------CD J--------------------J J--------------------J L--------------------L L--------------------L L--------------------L J--------------------J -J------------------J- -J------------------J- -DC----------------CD- -BA----------------AB- --CA--------------AC-- --BA--------------AB-- --CA--------------AC-- ---CA------------AC--- ----CA----------AC---- -----BAAAAAAAAAAB----- ------BBBBDDBBBB------ ----------BB---------- 
--D----------------D-- -BA----------------AB- -CA----------------AC- BA------------------AB BA------------------AB DC------------------CD L--------------------L L--------------------L L--------------------L L--------------------L L--------------------L L--------------------L J--------------------J J--------------------J DC------------------CD -BA----------------AB- -CA----------------AC- --BA--------------AB-- --CA--------------AC-- --CA--------------AC-- ---CA------------AC--- ----BAA--------AAB---- -----BBAAAAAAAABB----- -------BBBBBBBB------- 
--D----------------D-- -CA----------------AC- -CA----------------AC- CA------------------AC BA------------------AB BA------------------AB DC------------------CD N--------------------N N--------------------N N--------------------N L--------------------L L--------------------L L--------------------L DC------------------CD BA------------------AB BA------------------AB -CA----------------AC- -BA----------------AB- --CA--------------AC-- --CA--------------AC-- ---CA------------AC--- ----BAA--------AAB---- -----BBAAAAAAAABB----- -------BBBBBBBB------- 
--D----------------D-- -CA----------------AC- -CA----------------AC- BA------------------AB CA------------------AC BA------------------AB BA------------------AB DC------------------CD N--------------------N N--------------------N N--------------------N N--------------------N L--------------------L DC------------------CD BA------------------AB BA------------------AB -CA----------------AC- -BA----------------AB- --CA--------------AC-- --CA--------------AC-- --CCA------------ACC-- ----BAA--------AAB---- -----BBAAAAAAAABB----- -------BBBBBBBB------- 
--D----------------D-- -BA----------------AB- -CA----------------AC- BA------------------AB BA------------------AB CA------------------AC BA------------------AB BA------------------AB DC------------------CD D--------------------D DC------------------CD DC------------------CD DC------------------CD BA------------------AB BA------------------AB BA------------------AB -CA----------------AC- --BA--------------AB-- --CA--------------AC-- --CA--------------AC-- ---CA------------AC--- ----BAA--------AAB---- -----BBAAAAAAAABB----- -------BBBBBBBB------- 
--D----------------D-- -CD----------------DC- -CA----------------AC- CA------------------AC BA------------------AB BA------------------AB CA------------------AC BA------------------AB BA------------------AB DC------------------CD BA------------------AB BA------------------AB BA------------------AB BA------------------AB -BA----------------AB- -BA----------------AB- --CA--------------AC-- --BA--------------AB-- --CA--------------AC-- ---CA------------AC--- ----CA----------AC---- -----BA--------AB----- ------BAAAAAAAAB------ -------BBBBBBBB------- 
--D----------------D-- -CD----------------DC- -CA----------------AC- -CA----------------AC- -CA----------------AC- BA------------------AB BA------------------AB CA------------------AC BA------------------AB BA------------------AB CA------------------AC BA------------------AB -BA----------------AB- -BA----------------AB- -BA----------------AB- -BA----------------AB- --CA--------------AC-- --BA--------------AB-- --CA--------------AC-- ---CA------------AC--- ----CA----------AC---- -----BA--------AB----- ------BAAAAAAAAB------ -------BBBBBBBB------- 
--D----------------D-- -BDD--------------DDB- -CA----------------AC- -CA----------------AC- -BA----------------AB- -CA----------------AC- -BA----------------AB- -BA----------------AB- CA------------------AC -BA----------------AB- -BA----------------AB- -CA----------------AC- -BA----------------AB- -BA----------------AB- -BA----------------AB- --BA--------------AB-- --CA--------------AC-- --BA--------------AB-- ---CA------------AC--- ----CA----------AC---- -----CA--------AC----- ------BAA----AAB------ -------BBAAAABB------- ---------BBBB--------- 
--D----------------D-- --CD--------------DC-- --CA--------------AC-- -CA----------------AC- -BA----------------AB- -BA----------------AB- -CA----------------AC- -BA----------------AB- -BA----------------AB- -CA----------------AC- -BA----------------AB- -BA----------------AB- -CA----------------AC- -BA----------------AB- --BA--------------AB-- --BA--------------AB-- --CA--------------AC-- ---BA------------AB--- ----CA----------AC---- ----CA----------AC---- -----CA--------AC----- ------BAAA--AAAB------ -------BBBAABBB------- ----------BB---------- 
--D----------------D-- --CD--------------DC-- --CA--------------AC-- --CA--------------AC-- --CA--------------AC-- --BA--------------AB-- --BA--------------AB-- -CA----------------AC- -BA----------------AB- -BA----------------AB- -CA----------------AC- --BA--------------AB-- --BA--------------AB-- -CA----------------AC- --BA--------------AB-- --BA--------------AB-- ---CA------------AC--- ---BA------------AB--- ----CA----------AC---- ----CAA--------AAC---- -----CCAAA--AAACC----- -------BBBAABBB------- ----------BB---------- ---------------------- 
--D----------------D-- --BD--------------DB-- --CAA------------AAC-- --CA--------------AC-- --BA--------------AB-- --CA--------------AC-- --BA--------------AB-- --BA--------------AB-- --CA--------------AC-- --BA--------------AB-- --BA--------------AB-- --CA--------------AC-- --BA--------------AB-- --BA--------------AB-- --CA--------------AC-- --BA--------------AB-- ---CAA----------AAC--- ----BAA--------AAB---- ----CAAA------AAAC---- -----CCAA----AACC----- -------CCAAAACC------- ---------BBBB--------- ---------------------- ---------------------- 
---DD------------DD--- --CCDA----------ADCC-- --C-LA----------AL-C-- --CMA------------AMC-- --BAA------------AAB-- --BAA------------AAB-- --CA--------------AC-- --BA--------------AB-- --BA--------------AB-- --CA--------------AC-- --BA--------------AB-- --BA--------------AB-- --CAA------------AAC-- --BA--------------AB-- --BAA------------AAB-- ---CAA----------AAC--- ----CCA--------ACC---- -----BBA------ABB----- -----CCCAA--AACCC----- -------CCAAAACC------- ---------CCCC--------- ---------------------- ---------------------- ---------------------- 
----DD----------DD---- ----BCD--------DCB---- ---CCCAAA----AAACCC--- ---CCAAA------AAACC--- ---BBAAA------AAABB--- ---BBAA--------AABB--- ---BAAA--------AAAB--- --CAAAA--------AAAAC-- --BAA------------AAB-- --BAAA----------AAAB-- --CAAAA--------AAAAC-- ---BAAA--------AAAB--- ---BBAA--------AABB--- ---CAAA--------AAAC--- ---BBAAA------AAABB--- ----CCAAA----AAACC---- ------CAAA--AAAC------ -------BAAAAAAB------- --------CCAACC-------- ---------CCCC--------- ---------------------- ---------------------- ---------------------- ---------------------- 
------D--------D------ ------CDDDDDDDDC------ ------CCLAAAALCC------ -----CCCAA--AACCC----- -----BCBA----ABCB----- -----CBAA----AABC----- ----CBBA------ABBC---- ---CBBCA------ACBBC--- ---BBAA--------AABB--- ---BCBA--------ABCB--- ---CBBBA------ABBBC--- ----BBCA------ACBB---- -----CBAA----AABC----- ----CBBAA----AABBC---- -----BCBA----ABCB----- ------BBBA--ABBB------ -------CCCAACCC------- --------BBBBBB-------- ----------CC---------- ---------------------- ---------------------- ---------------------- ---------------------- ---------------------- 
-------DDDDDDDD------- -------BCCBBCCB------- --------CCCCCC-------- --------CCAACC-------- --------BAAAAB-------- -------BCAAAACB------- -------CAAAAAAC------- -------BAAAAAAB------- -----CBAAA--AAABC----- ------BAAA--AAAB------ -------CAAAAAAC------- -------BAAAAAAB------- -------BCAAAACB------- -------CBAAAABC------- --------BAAAAB-------- ---------BAAB--------- ----------CC---------- ---------------------- ---------------------- ---------------------- ---------------------- ---------------------- ---------------------- ---------------------- 
---------------------- ---------------------- ---------------------- ----------CC---------- ---------BBBB--------- ---------CCCC--------- --------BBBBBB-------- --------BBBBBB-------- -------BBBAABBB------- -------BCCAACCB------- --------BBBBBB-------- --------BBBBBB-------- ---------CCCC--------- ---------BBBB--------- ---------BBBB--------- ----------BB---------- ---------------------- ---------------------- ---------------------- ---------------------- ---------------------- ---------------------- ---------------------- ---------------------- 
---------------------- ---------------------- ---------------------- ---------------------- ---------------------- ---------------------- ---------------------- ---------------------- ----------BB---------- ----------CC---------- ---------------------- ---------------------- ---------------------- ---------------------- ---------------------- ---------------------- ---------------------- ---------------------- ---------------------- ---------------------- ---------------------- ---------------------- ---------------------- ---------------------- 
