model
size = 22 24 29, scale = 0.05, origin = -y
material 
  colors = A:#2D2D2D B:#000 C:#FF2800 D:#FFF E:#EA1700 F:#F5F5F5 G:#FF6A00 H:#222 I:#F90 J:#00FF15 K:#00EF0B L:#FF2600 M:#FF4800 N:#F80 O:#FB0 P:#06F Q:#FC0 R:#FD0
voxels
---------------------- ---------------------- ---------ECEC--------- ---------BBBB--------- ---------FDFD--------- ----------BB---------- ----------CC---------- ---------------------- ---------------------- ---------------------- ---------------------- ---------------------- ---------------------- ---------------------- ---------------------- ---------------------- ---------------------- ---------------------- ---------------------- ---------------------- ---------------------- ---------------------- ---------------------- ---------------------- 
--------BBBBBB-------- --------ECECEC-------- -------ECCBBCEC------- -------BBBBBBBB------- -------FDDDDDFD------- -------BBBBBBBB------- --------LLCCLL-------- ---------LCCL--------- ----------CC---------- ----------CC---------- ---------------------- ---------------------- ---------------------- ---------------------- ---------------------- ---------------------- ---------------------- ---------------------- ---------------------- ---------------------- ---------------------- ---------------------- ---------------------- ---------------------- 
------BBBBBBBBBB------ ------ECBBBBBBEC------ ------CCBBBBBBCE------ ------BBBBBBBBBB------ ------DDDDDDDDDF------ ------BBBBBBBBBB------ -------MLCCCCLM------- -------MLCCCCLM------- --------LLCCLL-------- ---------LCCL--------- ---------LCCL--------- ----------CC---------- ----------CC---------- ---------------------- ---------------------- ---------------------- ---------------------- ---------------------- ---------------------- ---------------------- ---------------------- ---------------------- ---------------------- ---------------------- 
-----BBBBBBBBBBBB----- -----CPPPPPPPPPPE----- -----EPPPPCCPPPPC----- -----BBBBBBBBBBBB----- -----FDDDDDDDDDDD----- -----BBBBBBBBBBBB----- -----GMCCCCCCCCMG----- -----GMCCCCCCCCMG----- ------MMCLCCLCMM------ -------MLLCCLLM------- -------MLLCCLLM------- --------LLCCLL-------- ---------LCCL--------- ---------LCCL--------- ----------CC---------- ---------------------- ---------------------- ---------------------- ---------------------- ---------------------- ---------------------- ---------------------- ---------------------- ---------------------- 
----BBB--------BBB---- ----EBPBBBBBBBBPBC---- ----CBPPCCCCCCPPBE---- ----BBBBBBAABBBBBB---- ----DDDDDDAADDDDDF---- ----BBBBBBHHBBBBBB---- ----GCCLLL--LLLCCG---- ----GCCMLL--LLMCCG---- ----GGCML----LMCGG---- -----GMML----LMMG----- -----GMML----LMMG----- ------GML----LMG------ -------ML----LM------- -------MLL--LLM------- --------ML--LM-------- --------GMMMMG-------- --------BBBBBB-------- ---------------------- ---------------------- ---------------------- ---------------------- ---------------------- ---------------------- ---------------------- 
---BBB----------BBB--- ---CPPBBBBBBBBBBPPE--- ---EPPCCAAAAAACCPPC--- ---BBBBAAA--AAABBBB--- ---FDDDAAA--AAADDDD--- ---BBBBHHH--HHHBBBB--- ---NCGM--------MGCN--- ---NCGM--------MGCN--- ---NCGM--------MGCN--- ---NGGM--------MGGN--- ----GGM--------MGG---- -----GM--------MG----- -----GG--------GG----- ------GM------MG------ ------GG------GG------ ------GG------GG------ ------BBHHHHHHBB------ -------FDFDFDFD------- ---------BBBB--------- ---------------------- ---------------------- ---------------------- ---------------------- ---------------------- 
--BB--------------BB-- --EBBB----------BBBC-- --CCCCAA------AACCCE-- --BBBBA--------ABBBB-- --DDDAA--------AADDF-- --BBBHH--------HHBBB-- --NGG------------GGN-- --NGG------------GGN-- --NGG------------GGN-- --NGG------------GGN-- ---NG------------GN--- ---NG------------GN--- ---NG------------GN--- ----GG----------GG---- -----G----------G----- -----G----------G----- -----BHH------HHB----- -----FDAAAAAAAAFD----- ------BBBAAAABBB------ -------CECECECE------- ---------------------- ---------------------- ---------------------- ---------------------- 
--B----------------B-- --CB--------------BE-- --EAAA----------AAAC-- --BAAA----------AAAB-- --FAA------------AAD-- --BHH------------HHB-- --N----------------N-- --N----------------N-- --N----------------N-- --N----------------N-- --N----------------N-- --N----------------N-- ---N--------------N--- ---N--------------N--- ---NN------------NN--- ----N------------N---- ----BH----------HB---- ----DAA--------AAF---- -----BAAA----AAAB----- -----CEAAAAAAAAEC----- -------BBBBBBBB------- ---------------------- ---------------------- ---------------------- 
--B----------------B-- -EB----------------BC- -CCA--------------ACE- -BBA--------------ABB- -DDA--------------ADF- -BBH--------------HBB- -II----------------II- -II----------------II- -II----------------II- -II----------------II- --I----------------I-- --I----------------I-- --I----------------I-- --I----------------I-- ---I--------------I--- ---I--------------I--- ---BH------------HB--- ----FA----------AD---- ----BA----------AB---- ----EAA--------AAC---- -----BBAAAAAAAABB----- -------DFDFDFDF------- ---------------------- ---------------------- 
--B----------------B-- -CB----------------BE- -ECA--------------ACC- -BBA--------------ABB- -FDA--------------ADD- -BHH--------------HHB- -I------------------I- -I------------------I- -I------------------I- -I------------------I- -I------------------I- --I----------------I-- --I----------------I-- --I----------------I-- --I----------------I-- --I----------------I-- --BH--------------HB-- ---DA------------AF--- ----BA----------AB---- ----CA----------AE---- -----BAAAAAAAAAAB----- ------DFDFDFDFDF------ ---------------------- ---------------------- 
--B----------------B-- -EB----------------BC- -CA----------------AE- BBA----------------ABB DDA----------------ADF BDH----------------HDB OI------------------IO OI------------------IO OI------------------IO -I------------------I- -I------------------I- -I------------------I- -I------------------I- --I----------------I-- --I----------------I-- --I----------------I-- --BH--------------HB-- --FA--------------AD-- ---BAA----------AAB--- ----EA----------AC---- -----BAAAAAAAAAAB----- ------FDFBBBBDFD------ ---------JKJK--------- ---------------------- 
--B----------------B-- -CA----------------AE- -EA----------------AC- BBA----------------ABB FDA----------------ADD BHH----------------HHB O--------------------O O--------------------O O--------------------O O--------------------O -O------------------O- -O------------------O- -O------------------O- -I------------------I- -I------------------I- -BH----------------HB- --FH--------------HD-- --DA--------------AF-- --BA--------------AB-- ---CA------------AC--- ----BA----------AB---- -----FAAAAAAAAAAD----- ------JKJKJKJKJK------ ---------------------- 
--B----------------B-- -EA----------------AC- -CA----------------AE- BA------------------AB DA------------------AF BH------------------HB O--------------------O O--------------------O Q--------------------Q Q--------------------Q Q--------------------Q O--------------------O -O------------------O- -O------------------O- -BH----------------HB- -FA----------------AD- --DA--------------AF-- --FA--------------AD-- --BA--------------AB-- ---EA------------AE--- ----BA----------AB---- -----DAAAAAAAAAAF----- ------KJKJBBKJKJ------ ----------CE---------- 
--B----------------B-- -CA----------------AE- -EA----------------AC- BA------------------AB FA------------------AD BH------------------HB Q--------------------Q Q--------------------Q Q--------------------Q Q--------------------Q Q--------------------Q Q--------------------Q O--------------------O O--------------------O BH------------------HB -DA----------------AF- -FA----------------AD- --DA--------------AF-- --BA--------------AB-- --CA--------------AE-- ---BA------------AB--- ----DAA--------AAF---- -----KJAAAAAAAAKJ----- -------CECECECE------- 
--B----------------B-- -BA----------------AB- -CA----------------AE- BA------------------AB DA------------------AF FA------------------AD BH------------------HB R--------------------R R--------------------R R--------------------R Q--------------------Q Q--------------------Q Q--------------------Q BH------------------HB DA------------------AF FA------------------AD -DA----------------AF- -FA----------------AD- --BA--------------AB-- --EA--------------AC-- ---BA------------AB--- ----FAA--------AAD---- -----JKAAAAAAAAJK----- -------ECECECEC------- 
--B----------------B-- -BA----------------AB- -BA----------------AB- BA------------------AB FA------------------AD DA------------------AF FA------------------AD BH------------------HB R--------------------R R--------------------R R--------------------R R--------------------R Q--------------------Q BH------------------HB FA------------------AD DA------------------AF -FA----------------AD- -DA----------------AF- --BA--------------AB-- --CA--------------AE-- --BBA------------ABB-- ----DAA--------AAF---- -----KJAAAAAAAAKJ----- -------CECECECE------- 
--B----------------B-- -JA----------------AK- -BA----------------AB- BA------------------AB DA------------------AF FA------------------AD DA------------------AF FA------------------AD BH------------------HB B--------------------B BH------------------HB BH------------------HB BH------------------HB FA------------------AD DA------------------AF FA------------------AD -DA----------------AF- --FA--------------AD-- --BA--------------AB-- --EA--------------AC-- ---BA------------AB--- ----FAA--------AAD---- -----JKAAAAAAAAJK----- -------ECECECEC------- 
--B----------------B-- -KB----------------BJ- -JA----------------AK- BA------------------AB BA------------------AB DA------------------AF FA------------------AD DA------------------AF FA------------------AD DH------------------HF FA------------------AD DA------------------AF FA------------------AD DA------------------AF -FA----------------AD- -DA----------------AF- --FA--------------AD-- --BA--------------AB-- --BA--------------AB-- ---CA------------AC--- ----BA----------AB---- -----FA--------AD----- ------JAAAAAAAAK------ -------CECECECE------- 
--B----------------B-- -BB----------------BB- -KA----------------AJ- -JA----------------AK- -BA----------------AB- BA------------------AB DA------------------AF FA------------------AD DA------------------AF FA------------------AD DA------------------AF FA------------------AD -DA----------------AF- -FA----------------AD- -DA----------------AF- -FA----------------AD- --BA--------------AB-- --KA--------------AJ-- --BA--------------AB-- ---EA------------AE--- ----BA----------AB---- -----DA--------AF----- ------KAAAAAAAAJ------ -------ECECECEC------- 
--B----------------B-- -BBB--------------BBB- -BA----------------AB- -KA----------------AJ- -JA----------------AK- -BA----------------AB- -BA----------------AB- -DA----------------AF- FA------------------AD -DA----------------AF- -FA----------------AD- -DA----------------AF- -FA----------------AD- -DA----------------AF- -FA----------------AD- --BA--------------AB-- --BA--------------AB-- --JA--------------AK-- ---BA------------AB--- ----CA----------AE---- -----BA--------AB----- ------DAA----AAF------ -------KJAAAAKJ------- ---------CECE--------- 
--B----------------B-- --EB--------------BE-- --BA--------------AB-- -BA----------------AB- -KA----------------AJ- -JA----------------AK- -BA----------------AB- -BA----------------AB- -DA----------------AF- -FA----------------AD- -DA----------------AF- -FA----------------AD- -DA----------------AF- -FA----------------AD- --BA--------------AB-- --EA--------------AE-- --BA--------------AB-- ---KA------------AJ--- ----BA----------AB---- ----EA----------AC---- -----BA--------AB----- ------FAAA--AAAD------ -------JKJAAKJK------- ----------CE---------- 
--B----------------B-- --CB--------------BC-- --EA--------------AE-- --BA--------------AB-- --JA--------------AK-- --KA--------------AJ-- --BA--------------AB-- -EA----------------AE- -BA----------------AB- -DA----------------AF- -FA----------------AD- --DA--------------AF-- --FA--------------AD-- -BA----------------AB- --EA--------------AE-- --CA--------------AC-- ---BA------------AB--- ---JA------------AK--- ----BA----------AB---- ----CAA--------AAE---- -----BBAAA--AAABB----- -------FDFAADFD------- ----------JK---------- ---------------------- 
--B----------------B-- --BB--------------BB-- --CAA------------AAC-- --BA--------------AB-- --KA--------------AJ-- --JA--------------AK-- --BA--------------AB-- --CA--------------AC-- --EA--------------AE-- --BA--------------AB-- --BA--------------AB-- --BA--------------AB-- --BA--------------AB-- --EA--------------AE-- --CA--------------AC-- --EA--------------AE-- ---BAA----------AAB--- ----KAA--------AAJ---- ----BAAA------AAAB---- -----ECAA----AACE----- -------BBAAAABB------- ---------DFDF--------- ---------------------- ---------------------- 
---BB------------BB--- --BDBA----------ABFB-- --B-QA----------AQ-B-- --BCA------------ACB-- --JAA------------AAK-- --KAA------------AAJ-- --BA--------------AB-- --EA--------------AE-- --CA--------------AC-- --EA--------------AE-- --CA--------------AC-- --CA--------------AC-- --EAA------------AAE-- --CA--------------AC-- --EAA------------AAE-- ---EAA----------AAE--- ----BBA--------ABB---- -----JKA------AJK----- -----BBBAA--AABBB----- -------CEAAAAEC------- ---------BBBB--------- ---------------------- ---------------------- ---------------------- 
----BB----------BB---- ----FDB--------BFD---- ---BDFAAA----AAADFB--- ---BBAAA------AAABB--- ---KBAAA------AAABJ--- ---JKAA--------AAJK--- ---BAAA--------AAAB--- --CAAAA--------AAAAC-- --EAA------------AAE-- --CAAA----------AAAC-- --EAAAA--------AAAAE-- ---EAAA--------AAAE--- ---CEAA--------AAEC--- ---EAAA--------AAAE--- ---CEAAA------AAAEC--- ----CEAAA----AAAEC---- ------BAAA--AAAB------ -------JAAAAAAK------- --------BBAABB-------- ---------CECE--------- ---------------------- ---------------------- ---------------------- ---------------------- 
------B--------B------ ------BBBBBBBBBB------ ------DBQAAAAQBF------ -----DFDAA--AAFDF----- -----BDFA----ADFB----- -----BBAA----AABB----- ----BBBA------ABBB---- ---ECECA------ACECE--- ---CEAA--------AAEC--- ---ECEA--------AECE--- ---CECEA------AECEC--- ----CECA------ACEC---- -----CEAA----AAEC----- ----CECAA----AACEC---- -----CECA----ACEC----- ------CECA--ACEC------ -------BBBAABBB------- --------KJKJKJ-------- ----------BB---------- ---------------------- ---------------------- ---------------------- ---------------------- ---------------------- 
-------BBBBBBBB------- -------BJKJKJKB------- --------BJKJKB-------- --------BKAAJB-------- --------BAAAAB-------- -------DFAAAADF------- -------BAAAAAAB------- -------BAAAAAAB------- -----CEAAA--AAAEC----- ------CAAA--AAAC------ -------CAAAAAAC------- -------EAAAAAAE------- -------CBAAAABC------- -------EBAAAABE------- --------EAAAAE-------- ---------EAAE--------- ----------BB---------- ---------------------- ---------------------- ---------------------- ---------------------- ---------------------- ---------------------- ---------------------- 
---------------------- ---------------------- ---------------------- ----------JK---------- ---------BKJB--------- ---------BBBB--------- --------DFBBDF-------- --------FDFDFD-------- -------CBFAADBC------- -------EBDAAFBE------- --------BFDFDB-------- --------BDFDFB-------- ---------FDFD--------- ---------DFDF--------- ---------BDFB--------- ----------BB---------- ---------------------- ---------------------- ---------------------- ---------------------- ---------------------- ---------------------- ---------------------- ---------------------- 
---------------------- ---------------------- ---------------------- ---------------------- ---------------------- ---------------------- ---------------------- ---------------------- ----------DF---------- ----------FD---------- ---------------------- ---------------------- ---------------------- ---------------------- ---------------------- ---------------------- ---------------------- ---------------------- ---------------------- ---------------------- ---------------------- ---------------------- ---------------------- ---------------------- 
