model
size = 22 31 30, scale = 0.05, origin = -y
material 
  colors = A:#111 B:#3CC
voxels
---------------------- ---------------------- -----------B---------- -----------B---------- -----------B---------- -----------B---------- ---------------------- ---------------------- ---------------------- ---------------------- ---------------------- ---------------------- ---------------------- ---------------------- ---------------------- ---------------------- ---------------------- ---------------------- ---------------------- ---------------------- ---------------------- ---------------------- ---------------------- ---------------------- ---------------------- ---------------------- ---------------------- ---------------------- ---------------------- ---------------------- ---------------------- 
--------AAAAAAA------- ---------AAAAA-------- ---------AAAAA-------- ----------BAB--------- ----------BAB--------- ----------BBB--------- -----------B---------- -----------B---------- -----------B---------- -----------B---------- -----------B---------- -----------B---------- ---------------------- ---------------------- ---------------------- ---------------------- ---------------------- ---------------------- ---------------------- ---------------------- ---------------------- ---------------------- ---------------------- ---------------------- ---------------------- ---------------------- ---------------------- ---------------------- ---------------------- ---------------------- ---------------------- 
------AAAAAAAAAAA----- ------AAAAAAAAAAA----- -------AAAAAAAAA------ -------AAAAAAAAA--B--- --------AAAAAAA--BB--- ----------AAA--------- ---------------------- ---------------------- ---------------------- ---------------------- ---------------------- -----------B---------- -----------B---------- ---------------------- ---------------------- ---------------------- ---------------------- ---------------------- ---------------------- ---------------------- ---------------------- ---------------------- ---------------------- ---------------------- ---------------------- ---------------------- ---------------------- ---------------------- ---------------------- ---------------------- ---------------------- 
-----AAAAAAAAAAAAA---- -----AAAAAAAAAAAAA---- -----AAAAAAAAAAAAA---- --BB--AAAAAAAAAAA----- ------AAAAAAAAAAAB---- -------AAAAAAAAA------ ---------AAAAA-------- ---------------------- ---------------------- ---------------------- ---------------------- ---------------------- -----------B---------- -----------B---------- ---------------------- ---------------------- ---------------------- ---------------------- ---------------------- ---------------------- ---------------------- ---------------------- ---------------------- ---------------------- ---------------------- ---------------------- ---------------------- ---------------------- ---------------------- ---------------------- ---------------------- 
----AAAAAAAAAAAAAAA--- ----AAAAAAAAAAAAAAA--- ---BAAAAAAAAAAAAAAA--- ---B-AAAAAAAAAAAAA---- -----AAAAAAAAAAAAA---- ------AAAAAAAAAAA----- -------AAAAAAAAA------ ---------AAAAA-------- ---------------------- ---------------------- ---------------------- ---------------------- ---------------------- -----------B---------- -----------B---------- -----------B---------- ---------------------- ---------------------- ---------------------- ---------------------- ---------------------- ---------------------- ---------------------- ---------------------- ---------------------- ---------------------- ---------------------- ---------------------- ---------------------- ---------------------- ---------------------- 
---AA-------------AA-- ---AA-------------AA-- ----A-------------A--- ----A-------------A--- ----A-------------A--- -----A-----------A---- ------A---------A----- -------AAAAAAAAA------ ----------AAA--------- ---------------------- ---------------------- ---------------------- ---------------------- ---------------------- ---------------------- -----------B---------- -----------B---------- -----------B---------- ---------------------- ---------------------- ---------------------- ---------------------- ---------------------- ---------------------- ---------------------- ---------------------- ---------------------- ---------------------- ---------------------- ---------------------- ---------------------- 
---AA-------------AA-- ---AA-------------AA-- ---AA-------------AA-- ---AA-------------AA-- ----A-------------A--- ----AA-----------AA--- -----A----------AA---- ------AAAAAAAAAAA----- --------AAAAAAA------- ---------------------- ---------------------- ---------------------- ---------------------- ---------------------- ---------------------- ---------------------- ---------------------- -----------B---------- -----------B---------- -----------B---------- ---------------------- ---------------------- -----------B---------- -----------B---------- ---------------------- ---------------------- ---------------------- ---------------------- ---------------------- ---------------------- ---------------------- 
--AAA-------------AAA- ---AA-------------AA-- ---AA-------------AA-- ---AA-------------AA-- ---AA-------------AA-- ----AA-----------AA--- -----A----------AA---- ------AA-------AA----- -------AAAAAAAAA------ -----------A---------- ---------------------- ---------------------- ---------------------- ---------------------- ---------------------- ---------------------- ---------------------- ---------------------- ---------------------- -----------B---------- -----------B---------- -----------B---------- -----------B---------- ---------------------- ---------------------- ---------------------- ---------------------- ---------------------- ---------------------- ---------------------- ---------------------- 
--AAA-------------AAA- --AAA-------------AAA- --AAA-------------AAA- ---AA-------------AA-- ---AA-------------AA-- ----AA-----------AA--- ----AA----------AAA--- -----AAA-------AAA---- -------AA-----AA------ ---------AAAAA-------- ---------------------- ---------------------- ---------------------- ---------------------- ---------------------- ---------------------- ---------------------- ---------------------- ---------------------- ---------------------- -----------B---------- -----------B---------- ---------------------- ---------------------- ---------------------- ---------------------- ---------------------- ---------------------- ---------------------- ---------------------- ---------------------- 
--AAA-------------AAA- --AAA-------------AAA- --AAA-------------AAA- ---AA-------------AA-- ---AA-------------AA-- ---AAA-----------AAA-- ----AA----------AAA--- -----AAA-------AAA---- ------AAA-----AAA----- ---------AAAAA-------- ---------------------- ---------------------- ---------------------- ---------------------- ---------------------- ---------------------- ---------------------- ---------------------- ---------------------- ---------------------- ---------------------- -----------B---------- -----------B---------- ---------------------- ---------------------- ---------------------- ---------------------- ---------------------- ---------------------- ---------------------- ---------------------- 
--AAA-------------AAA- --AAA-------------AAA- --AAA-------------AAA- --AAA-------------AAA- ---AA-------------AA-- ---AAA-----------AAA-- ----AA----------AAA--- -----AAA-------AAA---- ------AAA-----AAA----- --------AAAAAAA------- -----------B---------- -----------B---------- -----------B---------- -----------B---------- ---------------------- ---------------------- ---------------------- ---------------------- ---------------------- ---------------------- ---------------------- ---------------------- -----------B---------- -----------B---------- -----------B---------- ---------------------- ---------------------- ---------------------- ---------------------- ---------------------- ---------------------- 
--AAA-------------AAA- BBAAA-------------AAA- -BAAA-------------AAA- ---AA-------------AABB ---AA-------------AA-- ---AAA-----------AAA-- ----AA----------AAA--- -----AAA-------AAA---- ------AAA-----AAA----- ---------AAAAA-------- ---------------------- ---------------------- ---------------------- -----------B---------- -----------B---------- ---------------------- ---------------------- ---------------------- ---------------------- ---------------------- ---------------------- ---------------------- ---------------------- ---------------------- -----------B---------- ---------------------- ---------------------- ---------------------- ---------------------- ---------------------- ---------------------- 
--AAA-------------AAA- --AAA-------------AAA- --AAA-------------AAA- ---AA-------------AA-B ---AA-------------AA-- ----AA-----------AA--- ----AA----------AAA--- -----AAA-------AAA---- -------AA-----AA------ ---------AAAAA-------- ---------------------- ---------------------- ---------------------- ---------------------- -----------B---------- -----------B---------- ---------------------- ---------------------- ---------------------- ---------------------- ---------------------- ---------------------- ---------------------- -----------B---------- -----------B---------- -----------B---------- -----------B---------- ---------------------- ---------------------- ---------------------- ---------------------- 
--AAA-------------AAA- ---AA-------------AA-- ---AA-------------AA-- ---AA-------------AA-- ---AA-------------AA-- ----AA-----------AA--- -----A----------AA---- ------AA-------AA----- -------AAAAAAAAA------ -----------A---------- ---------------------- ---------------------- ---------------------- ---------------------- ---------------------- -----------B---------- -----------B---------- ---------------------- ---------------------- ---------------------- ---------------------- ---------------------- ---------------------- -----------B---------- ---------------------- ---------------------- -----------B---------- -----------B---------- ---------------------- ---------------------- ---------------------- 
---AA-------------AA-- ---AA-------------AA-- ---AA-------------AA-- ---AA-------------AA-- ----A-------------A--- ----AA-----------AA--- -----A----------AA---- ------AA-------AA----- --------AAAAAAA------- ---------------------- ---------------------- ---------------------- ---------------------- ---------------------- ---------------------- ---------------------- -----------B---------- -----------B---------- -----------B---------- -----------B---------- ---------------------- ---------------------- ---------------------- ---------------------- ---------------------- ---------------------- ---------------------- -----------B---------- ---------------------- ---------------------- ---------------------- 
---AA-------------AA-- ---AA-------------AA-- ----A-------------A--- ----A-------------A--- ----A-------------A--- ----BA-----------A---- ------A---------A----- -------AAAAAAAAA------ ----------AAA--------- ---------------------- ---------------------- ---------------------- ---------------------- ---------------------- ---------------------- ---------------------- ---------------------- -----------B---------- -----------B---------- ---------------------- ---------------------- ---------------------- ---------------------- ---------------------- ---------------------- ---------------------- ---------------------- ---------------------- ---------------------- ---------------------- ---------------------- 
----A-------------A--- ----A-------------A--- ----A-------------A--- -----A-----------A---- -----A-----------A---- ---BB-A---------A----- -------AAAAAAAAAB----- ---------AAAAA-------- -----------B---------- -----------B---------- -----------B---------- ---------------------- ---------------------- ---------------------- ---------------------- ---------------------- ---------------------- ---------------------- -----------B---------- -----------B---------- ---------------------- ---------------------- ---------------------- ---------------------- ---------------------- ---------------------- ---------------------- ---------------------- ---------------------- ---------------------- ---------------------- 
-----AAAAAAAAAAAAA---- -----AAAAAAAAAAAAA---- -----AAAAAAAAAAAAA---- ------AAAAAAAAAAA----- ------AAAAAAAAAAA----- -------AAAAAAAAA------ ---------AAAAA--B----- -----------B----B----- -----------B---------- ---------------------- -----------B---------- -----------B---------- ---------------------- ---------------------- ---------------------- ---------------------- ---------------------- ---------------------- ---------------------- -----------B---------- -----------B---------- ---------------------- ---------------------- ---------------------- ---------------------- ---------------------- ---------------------- ---------------------- ---------------------- ---------------------- ---------------------- 
------AAAAAAAAAAA----- ------AAAAAAAAAAA----- -------AAAAAAAAA------ -------AAAAAAAAA------ --------AAAAAAA------- ----------AAA--------- ---------------------- ---------------------- ---------------------- ---------------------- ---------------------- -----------B---------- -----------B---------- -----------B---------- ---------------------- ---------------------- ---------------------- ---------------------- ---------------------- ---------------------- -----------B---------- -----------B---------- ---------------------- ---------------------- ---------------------- ---------------------- ---------------------- ---------------------- ---------------------- ---------------------- ---------------------- 
--------AAAAAAA------- ---------AAAAA-------- ---------AAAAA-------- -----------A---------- -----------B---------- -----------B---------- ---------------------- ---------------------- ---------------------- ---------------------- ---------------------- ---------------------- ---------------------- -----------B---------- -----------B---------- ---------------------- ---------------------- ---------------------- ---------------------- -----------B---------- -----------B---------- -----------B---------- -----------B---------- -----------B---------- -----------B---------- ---------------------- ---------------------- ---------------------- ---------------------- ---------------------- ---------------------- 
---------------------- ---------------------- -----------B---------- -----------B---------- -----------B---------- -----------B---------- -----------B---------- ---------------------- ---------------------- ---------------------- ---------------------- ---------------------- ---------------------- ---------------------- -----------B---------- -----------B---------- -----------B---------- -----------B---------- ---------------------- ---------------------- ---------------------- ---------------------- ---------------------- ---------------------- -----------B---------- -----------B---------- -----------B---------- ---------------------- ---------------------- ---------------------- ---------------------- 
---------------------- ---------------------- ---------------------- ---------------------- ---------------------- ---------------------- -----------B---------- -----------B---------- -----------B---------- -----------B---------- -----------B---------- -----------B---------- ---------------------- ---------------------- ---------------------- ---------------------- -----------B---------- -----------B---------- -----------B---------- ---------------------- ---------------------- ---------------------- ---------------------- ---------------------- ---------------------- ---------------------- -----------B---------- -----------B---------- -----------B---------- ---------------------- ---------------------- 
---------------------- ---------------------- ---------------------- ---------------------- ---------------------- ---------------------- ---------------------- -----------B---------- -----------B---------- ---------------------- ---------------------- -----------B---------- ---------------------- ---------------------- ---------------------- ---------------------- ---------------------- ---------------------- -----------B---------- -----------B---------- ---------------------- ---------------------- ---------------------- ---------------------- ---------------------- ---------------------- ---------------------- ---------------------- -----------B---------- ---------------------- ---------------------- 
---------------------- ---------------------- ---------------------- ---------------------- ---------------------- ---------------------- ---------------------- ---------------------- -----------B---------- -----------B---------- ---------------------- ---------------------- ---------------------- ---------------------- ---------------------- ---------------------- ---------------------- ---------------------- ---------------------- -----------B---------- ---------------------- ---------------------- ---------------------- ---------------------- ---------------------- ---------------------- ---------------------- ---------------------- -----------B---------- -----------B---------- -----------B---------- 
---------------------- ---------------------- ---------------------- ---------------------- ---------------------- ---------------------- ---------------------- ---------------------- ---------------------- -----------B---------- -----------B---------- ---------------------- ---------------------- ---------------------- ---------------------- ---------------------- ---------------------- ---------------------- ---------------------- -----------B---------- -----------B---------- ---------------------- ---------------------- ---------------------- ---------------------- ---------------------- ---------------------- ---------------------- -----------B---------- ---------------------- -----------B---------- 
---------------------- ---------------------- ---------------------- ---------------------- ---------------------- ---------------------- ---------------------- ---------------------- ---------------------- ---------------------- -----------B---------- -----------B---------- ---------------------- ---------------------- ---------------------- ---------------------- ---------------------- ---------------------- ---------------------- ---------------------- -----------B---------- -----------B---------- -----------B---------- ---------------------- ---------------------- ---------------------- ---------------------- ---------------------- ---------------------- ---------------------- ---------------------- 
---------------------- ---------------------- ---------------------- ---------------------- ---------------------- ---------------------- ---------------------- ---------------------- ---------------------- ---------------------- ---------------------- -----------B---------- -----------B---------- -----------B---------- -----------B---------- -----------B---------- ---------------------- ---------------------- ---------------------- ---------------------- -----------B---------- ---------------------- -----------B---------- -----------B---------- ---------------------- -----------B---------- ---------------------- ---------------------- ---------------------- ---------------------- ---------------------- 
---------------------- ---------------------- ---------------------- ---------------------- ---------------------- ---------------------- ---------------------- ---------------------- ---------------------- ---------------------- ---------------------- -----------B---------- -----------B---------- -----------B---------- ---------------------- -----------B---------- -----------B---------- -----------B---------- ---------------------- ---------------------- ---------------------- ---------------------- ---------------------- -----------B---------- -----------B---------- -----------B---------- ---------------------- ---------------------- ---------------------- ---------------------- ---------------------- 
---------------------- ---------------------- ---------------------- ---------------------- ---------------------- ---------------------- ---------------------- ---------------------- ---------------------- ---------------------- ---------------------- ---------------------- ---------------------- -----------B---------- -----------B---------- ---------------------- ---------------------- -----------B---------- -----------B---------- ---------------------- ---------------------- ---------------------- ---------------------- ---------------------- ---------------------- -----------B---------- -----------B---------- ---------------------- ---------------------- ---------------------- ---------------------- 
---------------------- ---------------------- ---------------------- ---------------------- ---------------------- ---------------------- ---------------------- ---------------------- ---------------------- ---------------------- ---------------------- ---------------------- ---------------------- ---------------------- -----------B---------- ---------------------- ---------------------- ---------------------- ---------------------- ---------------------- ---------------------- ---------------------- ---------------------- ---------------------- ---------------------- ---------------------- ---------------------- ---------------------- ---------------------- ---------------------- ---------------------- 
