model
size = 22 30 23, scale = 0.05, origin = -y
material 
  colors = A:#F60 B:#E00 C:#6C0 D:#90C E:#111 F:#FF0 G:#EEE
voxels
---------------------- ---------------------- ---------------------- ---------------------- ---------------------- ---------------------- ---------------------- ---------------------- ---------------------- ---------------------- ---------------------- ---------------------- ---------------------- ---------------------- ---------------------- -----CCCCFDFCCCCC----- -----ACFFAFCCCFCA----- -----CCFCFCCFDCCC----- -----FFDFAFCCCDCF----- -----CCFCCACFCFFC----- -----AADDFFCFCAAA----- ------FFADCDCAFF------ -------FFFFFDFF------- ---------------------- ---------------------- ---------------------- ---------------------- ---------------------- ---------------------- ---------------------- 
---------------------- ---------------------- ---------------------- ---------------------- ---------------------- ---------------------- ---------------------- ---------------------- ---------------------- ---------------------- ---------------------- ---------------------- ---------------------- -----ACCCCCCCCCCA----- -----DCCCCAACCCCD----- ---DAAAACAAAACAAAAD--- ---DAAAAAAAAAAAAAAD--- ---DCAAAAAAAAAAAACD--- ---DCAAAAAAAAAAAACD--- ---CCAAAAAAAAAAAACC--- ----CAAAAAAAAAAAAC---- ----CAAAAAAAAAAAAC---- -----CCAFFFFFFACC----- ------CAFCFCCCAC------ --------DFFDFC-------- ---------------------- ---------------------- ---------------------- ---------------------- ---------------------- 
---------------------- ---------------------- ---------------------- ---------------------- ---------------------- ---------------------- ---------------------- ---------------------- ---------------------- ---------------------- ---------------------- -----DDACCCCCCADD----- -----DCCCCCCCCCCD----- -----DCCCCCCCCCCD----- -----DAAAAAAAAAAD----- --DDAAAAAAAAAAAAAADD-- --DDAAAAAAAAAAAAAADD-- --DDAAAAAAAAAAAAAADD-- --DDAAAAAAAAAAAAAADD-- --DAAAAAAAAAAAAAAAAD-- --DAAAAAAAAAAAAAAAAD-- ---CCAAAAAAAAAAAACC--- ---CCAAAAAAAAAAAACC--- ----CAAAAAAAAAAAAC---- -----CFFAAAAACCFC----- -------FFAFCAFF------- ---------------------- ---------------------- ---------------------- ---------------------- 
---------------------- ---------------------- ---------------------- ---------------------- ---------------------- ---------------------- ---------------------- ---------------------- -----BBBADCCDABBB----- -----BADDDCCDDDAB----- -----BDDDDCCDDDDB----- -----BDAAAAAAAADB----- -----BAAAAAAAAAAB----- ----DDAAAA--AAAADD---- ----DDAAAA--AAAADD---- -DAAAAAAAA--AAAAAAAAD- -DAAAAAAAA--AAAAAAAAD- -DDAAAAAAA--AAAAAAADD- -DDAAAAAAA--AAAAAAADD- -DDAAAAAAA--AAAAAAADD- -DDAAAAAAA--AAAAAAADD- --DAAAAAAA--AAAAAAAD-- --DDAAAAAA--AAAAAADD-- ---DCAAAAA--AAAAACD--- ----CCAAAA--AAAACC---- -----CAAAA--AAAAC----- -------FFCCADDF------- ---------------------- ---------------------- ---------------------- 
---------------------- ---------------------- ---------------------- ---------------------- ---------------------- ---------------------- ---------------------- ---------------------- -----B----------B----- -----B----------B----- -----B----------B----- -----B----------B----- -----B----------B----- ----DDAAAA--AAAADD---- -ADDDDAAAA--AAAADDDDA- -AAAAAAAAA--AAAAAAAAA- -AAAAAAAAA--AAAAAAAAA- -AAAAAAAAA--AAAAAAAAA- -AAAAAAAAA--AAAAAAAAA- -AAAAAAAAA--AAAAAAAAA- -BAAAAAAAA--AAAAAAAAB- -BAAAAAAAA--AAAAAAAAB- -BDDAAAAAA--AAAAAADDB- --DDAAAAAA--AAAAAADD-- ---DDAAAAA--AAAAADD--- ----DCAAAA--AAAACD---- -----CFAAAAAAAAFC----- --------FDAAFF-------- ---------------------- ---------------------- 
---------------------- ---------------------- ---------------------- ---------------------- ---------------------- ---------------------- ---------------------- ---------------------- ---BBB----------BBB--- ---BBB----------BBB--- ---BBB----------BBB--- ---BBB----------BBB--- ---BBB----------BBB--- ---AAAAAAA--AAAAAAA--- -BAAAAAAAA--AAAAAAAAB- -BAAAAAAAA--AAAAAAAAB- BBAAAAAAAA--AAAAAAAABB BBAAAAAAAA--AAAAAAAABB BBAAAAAAAA--AAAAAAAABB BBAAAAAAAA--AAAAAAAABB BBAAAAAAAA--AAAAAAAABB BBAAAAAAAA--AAAAAAAABB -BAAAAAAAA--AAAAAAAAB- -BBAAAAAAA--AAAAAAABB- --BDDAAAAA--AAAAADDB-- ---DDAAAAA--AAAAADD--- ----DDAAAAAAAAAADD---- ------CCFFAAFFCC------ ---------------------- ---------------------- 
---------------------- ---------------------- ---------------------- ---------------------- ---------------------- ---------------------- ---------------------- ---------------------- --BBAA----------AABB-- --BBAA----------AABB-- --AAAA----------AAAA-- --AAAA----------AAAA-- --AAAA----------AAAA-- --AAA------------AAA-- -BAAA------------AAAB- -BAAA------------AAAB- BBAAA------------AAABB BBAAA------------AAABB BBAAA------------AAABB BBAAA------------AAABB AAAAA------------AAAAA AAAAA------------AAAAA -AAAA------------AAAA- -CAAA------------AAAA- -BBAA------------AABB- --BAA------------AAB-- ---BBDAAAAAAAAAADBB--- -----DCCAAAAAACCD----- -------CCCFFCCC------- ---------------------- 
---------------------- ---------------------- ---------------------- ---------------------- ---------------------- ---------------------- ---------------------- ---------------------- --BBAA----------AABB-- --BBAA----------AABB-- --BAAA----------AAAB-- --BAAA----------AAAB-- --AAAA----------AAAA-- --AAA------------AAA-- -BAAA------------AAAB- BBAAA------------AAABB BBAAA------------AAABB BBAAA------------AAABB BBAAA------------AAABB BBAAA------------AAABB AAAAA------------AAAAA AAAAA------------AAAAA AAAAA------------AAAAC CCAAA------------AAAAC -AAAA------------AAAA- --AAA------------AAA-- ---BBAAAAAAAAAAAABB--- ----BDDDAAAAAADDDB---- ------DDCCAACCDD------ ---------------------- 
---------------------- ---------------------- --C----------------A-- --B----------------C-- --B----------------B-- --A----------------A-- --B----------------B-- --B----------------B-- --BBAA----------AABB-- -BBBAA----------AABBB- -BBAAA----------AAABB- -BBAAA----------AAABB- -BAAAA----------AAAAB- -BAAAA----------AAAAB- -BAAAA----------AAAAB- BBAAAA----------AAAABB BBAAAA----------AAAABB BBAAAA----------AAAABB BBAAAA----------AAAABB BBAAAA----------AAAABC AAAAAA----------AAAAAC AAAAAA----------AAAAAA AAAAAA----------AAAAAA AAAAAA----------AAAAAC -AAAAA----------AAAAA- -AAAAA----------AAAAA- --ABBAAAAAAAAAAAABBA-- ----BDDDAAAAAADDDB---- -----DDDDAAAADDDD----- ---------CAAC--------- 
---------------------- --A----------------A-- --A----------------A-- --A----------------C-- --A----------------C-- --A----------------C-- --A----------------C-- --A----------------C-- --AAAA----------AAAA-- -CAAAA----------AAAAA- -CAAAA----------AAAAA- CCAAAA----------AAAAAA AAAAAA----------AAAAAA AAAAAA----------AAAAAA AAAAAA----------AAAAAA AAAAAA----------AAAAAA AAAAAA----------AAAAAA AAAAAA----------AAAAAA AAAAAA----------AAAAAA AAAAAA----------AAAAAC CAAAAA----------AAAAAC CAAAAA----------AAAAAA CAAAAA----------AAAAAA AAAAAA----------AAAAAA -AAAAA----------AAAAA- -AAAAA----------AAACC- --CAAAAAAAAAAAAAAAAC-- ---AAAAAAAAAAAAAAAA--- -----AAAAAAAAAAAA----- --------AAAACC-------- 
---------------------- --B----------------B-- --B----------------B-- --B----------------B-- --B----------------C-- --B----------------C-- --B----------------B-- --B----------------B-- --BBBB----------BBBB-- -BBBBB----------BBBBC- -BBBBB----------BBBBB- BBBBBB----------BBBBBB CBBBBB----------BBBBBB CBBBBB----------BBBBBC BBBBBB----------BBBBBB BBBBBB----------BBBBBB BBBBBB----------BBBBBC BAAAAA----------AAAAAB BBBBBB----------BBBBBB BBBBBB----------BBBBBB BBBBBB----------BBBBBB BBBBBB----------BBBBBB BBBBBB----------BBBBBC BBBBBB----------BBBBBB -BBBBB----------BBBBB- -BBBBB----------BBBBB- --BBBBBBAAAAAABBBBBB-- ---BBBBBAAAAAABBBBB--- -----BBBAAAAAABBB----- -------BAAACCCB------- 
---------------------- --B----------------B-- --B----------------B-- --B----------------B-- --B----------------B-- --B----------------B-- --B----------------B-- --B----------------B-- --BBBB----------BBBB-- -BBBBB----------BBBBB- -BBBBB----------BBBBB- BBBBBB----------BBBBBB BBBBBB----------BBBBBB BBBBBB----------BBBBBB BBBBBB----------BBBBBB BBBBBB----------BBBBBB BBBBBB----------BBBBBB BAAAAA----------AAAAAB BBBBBB----------BBBBBB BBBBBB----------BBBBBB BBBBBB----------BBBBBB BBBBBB----------BBBBBB BBBBBB----------BBBBBB BBBBBB----------BBBBBB -BBBBB----------BBBBB- -BBBBB----------BBBBB- --BBBBBBAAAAAABBBBBB-- ---BBBBBAAAAAABBBBB--- -----CBBAAAAAABBB----- -------BAAAAAAB------- 
---------------------- --B----------------B-- --B----------------B-- --B----------------B-- --B----------------B-- --B----------------B-- --B----------------B-- --B----------------B-- --BBBB----------BBBB-- -BBBBB----------BBBBB- -BBBBB----------BBBBB- BBBBBB----------BBBBBB BBBBBB----------BBBBBB BBBBBB----------BBBBBB BBBBBB----------BBBBBB BBBBBB----------BBBBBB BBBBBB----------BBBBBB BAAAAA----------AAAAAB BBBBBB----------BBBBBB BBBBBB----------BBBBBB BBBBBB----------BBBBBB CBBBBB----------BBBBBB CBBBBB----------BBBBBB BBBBBB----------BBBBBB -BBBBB----------BBBBB- -BBBBB----------BBBBB- --BBBBBBAAAAAABBBBBB-- ---BBBBBAAAAAABBBBB--- -----BBBAAAAAABBB----- -------BCCAAAAB------- 
---------------------- ---A--------------C--- ---A--------------C--- --CA--------------AA-- --AA--------------AA-- --AA--------------AA-- --AA--------------AA-- --AA--------------AA-- --AAAA----------AAAA-- -AAAAA----------AAAAA- -AAAAA----------AAAAA- AAAAAA----------AAAAAA AAAAAA----------AAAAAA AAAAAA----------AAAAAC CAAAAA----------AAAAAC AAAAAA----------AAAAAC CAAAAA----------AAAAAA AAAAAA----------AAAAAA AAAAAA----------AAAAAA BAAAAA----------AAAAAB BAAAAA----------AAAAAB CAAAAA----------AAAAAB CAAAAA----------AAAAAA AAAAAA----------AAAAAA -CAAAA----------AAAAA- -BAAAA----------AAAAB- --BBAAAAAAAAAAAAAABB-- ---BAAAAAAAAAAAAAAB--- -----AAAAAAAAAAAA----- --------DAAAAD-------- 
---------------------- ---A--------------C--- ---A--------------C--- --CA--------------AA-- --AA--------------AC-- --CA--------------AC-- --AA--------------AA-- --AA--------------AC-- --AAAA----------AAAA-- -AAAAA----------AAAAA- -AAAAA----------AAAAA- CAAAAA----------AAAAAA CAAAAA----------AAAAAC AAAAAA----------AAAAAC AAAAAA----------AAAAAC AAAAAA----------AAAAAA CAAAAA----------AAAAAA BAAAAA----------AAAAAB BAAAAA----------AAAAAB BAAAAA----------AAAAAB BAAAAA----------AAAAAB BAAAAA----------AAAAAB AAAAAA----------AAAAAA BBAAAA----------AAAABB -BAAAA----------AAAAB- -BAAAA----------AAAAB- --ABAAAAAAAAAAAAAABA-- ----CAAAAAFFAAAAAA---- -----AADCAFFACDAA----- ---------CFFC--------- 
---------------------- ---A--------------A--- ---A--------------A--- --AA--------------AA-- --AA--------------AA-- --AA--------------AA-- --AA--------------AA-- --AA--------------AA-- --AAAA----------AAAA-- --AAAA----------AAAC-- -AAAAA----------AAACC- AAAAAA----------AAAAAA AAAAAA----------AAAAAA AAAAAA----------AAAAAC AAAAAA----------AAAAAA AAAAAA----------AAAAAC AAAAAA----------AAAAAA BAAAAA----------AAAAAB BAAAAA----------AAAAAB BAAAAA----------AAAAAB BAAAAA----------AAAAAB BAAAAA----------AAAAAB AAAAAA----------AAAAAA BBAAAA----------AAAABB -BAAAA----------AAAAB- --AAAA----------AAAA-- ---BAAAAAAAAAAAAAAB--- ----AAAAAAFFAAAAAA---- ------DCCAFFACCD------ ---------------------- 
---------------------- ----AA----------AA---- ---AA------------AA--- ---F--------------F--- --AA--------------AA-- --BA--------------AB-- --BF--------------FB-- --BA--------------AB-- --BBAA----------AABB-- --BBAA----------AABC-- -AAAAA----------AAACC- -AAAAA----------AAAAA- -AAAAA----------AAAAA- -CAAAA----------AAAAA- -CAAAA----------AAAAB- CCAAAA----------AAAABB BBAAAA----------AAAABB BAAAAA----------AAAAAB DAAAAA----------AAAAAD DAAAAA----------AAAAAD CAAAAA----------AAAAAC CAAAAA----------AAAAAC CAAAAA----------AAAAAC AAAAAA----------AAAAAA -AAAAA----------AAAAA- --AAAA----------AAAA-- ---DDAAAAAAAAAAAADD--- -----DCAAAFFAAACD----- -------CAAFFAAC------- ---------------------- 
---------------------- -----A----------A----- ---------------------- ---------------------- ---------------------- ---------------------- ---------------------- ---------------------- ----AA----------AA---- ---AAA----------AAA--- --AAAA----------AAAA-- -AAAAA----------AAAAA- -AAAAA----------AAAAC- -CAAAA----------AAAAA- -CBAAA----------AAABB- -CBAAA----------AAABB- -BAAAA----------AAAAB- -BAAAA----------AAAAB- -AAAAA----------AAAAA- -AAAAA----------AAAAA- -AAAAA----------AAAAA- -CAAAA----------AAAAC- -CAAAA----------AAAAC- -CAAAA----------AAAAC- --DAAA----------AAAD-- ---DAA----------AAD--- ----CCAAAAAAAAAACC---- ------CCFFFFFFCC------ ---------------------- ---------------------- 
---------------------- -----A----------A----- ---------------------- ---------------------- ---------------------- ---------------------- ---------------------- ---------------------- ----AAAAAAAAAAAAAA---- ----AAAAAAAAAAAAAA---- ---AAAAAAAAAAAAAAAA--- -AAAAAAAAAAAAAAAAAAAA- -AAAAAAAAAEEAAAAAAAAA- -AAAAAAAAAEEAAAAAAAAA- --BAAAAAAAEEAAAAAAAB-- --BAAAAAAAAAAAAAAAAB-- -BAAAAAAAAAAAAAAAAAAB- -BAAEEEAAAAAAAAEEEAAB- -DDAEEEEAAAAAAEEEEADD- -DDAEEEEAAAAAAEEEEADD- -DDAAEEAAAAAAAAEEAADD- --DAAAAAAAAAAAAAAAAD-- --AAAAAAAAAAAAAAAAAA-- --DAAAAAAAAAAAAAAAAD-- ---CCAAAAAAAAAAAACC--- ----CCAAAAAAAAAACC---- -----CCAAAAAAAACC----- --------FFFFFF-------- ---------------------- ---------------------- 
-------AAAAAAAA------- ------AAAAAAAAAA------ ------AAAAAAAAAA------ ------GGGGGGGGGG------ ------GGGGGGGGGG------ ------GGGGGGGGGG------ ------AAAAAAAAAA------ -----AAAAAAAAAAAA----- ----AAAAAAAAAAAAAA---- ----AAAAAAAAAAAAAA---- -AAAAAAAAAAAAAAAAAAAA- -AAAAAAAAAEEAAAAAAAAA- -AAAAAAAAE--EAAAAAAAA- -AAAAAAAAE--EAAAAAAAA- --CAAAAAAE--EAAAAAAC-- --DAAAAAAAEEAAAAAAAD-- --DAAEEEAAAAAAEEEAAD-- --DAE--EAAAAAAE--EAD-- --DE----EAAAAE----ED-- --DE----EAAAAE----ED-- --DAE--EAAAAAAE--EAD-- --DAAEEAAAAAAAAEEAAD-- --DAAAAAAAAAAAAAAAAD-- ---CAAAAAAAAAAAAAAC--- ----CAAAAAAAAAAAAC---- -----CFAAAAAAAAFC----- ------FFFAAAAFFF------ ---------------------- ---------------------- ---------------------- 
-------AAFAAFAA------- ------AAAAAAAAAA------ ------AAAAAAAAAA------ ------GGGGGGGGGG------ ------GGGGGGGGGG------ ------GGGGGGGGGG------ ------AAAAAAAAAA------ -----AAAAAAAAAAAA----- ----AAAAAFAAFAAAAA---- ----AABACFAAFCABAA---- -AAAAABACFAAFCABAAAAA- -AAAACCCDDEEDDCCCAAAA- -BBAAADDDE--EDDDAAABB- -BBCDDDDCE--ECDDDDCBB- ---DDDCCCE--ECCCDDD--- ---DCCCCFAEEAFCCCCD--- ---DCEEEAAAAAAEEECD--- ---FE--EAAAAAAE--EF--- ---E----EAAAAE----E--- ---E----EAAAAE----E--- ---CE--EAAAAAAE--EC--- ---CCEEAAAAAAAAEECC--- ---CCCFAAAAAAAAFCCC--- ----CCFAAAAAAAAFCC---- -----CFAAAAAAAAFC----- ------FFAAAAAAFF------ ---------------------- ---------------------- ---------------------- ---------------------- 
---------------------- ------AFAAAAAAFA------ ------FAAAFFAAAF------ ---------------------- ---------------------- ---------------------- ------ABBAAAAABA------ ------BBABABABBB------ ----FFABBFAAFBAAFF---- ----BB----------BB---- --FABB----------BBAF-- --BBBC----EE----CBBB-- --BCCC---E--E---CCCB-- ---------E--E--------- ---------E--E--------- ----------EE---------- -----EE--------EE----- ----E--E------E--E---- ---E----E----E----E--- ---E----E----E----E--- ----E--E------E--E---- -----EE--------EE----- ---------------------- ---------------------- ---------------------- ---------------------- ---------------------- ---------------------- ---------------------- ---------------------- 
---------------------- ---------------------- ---------------------- ---------------------- ---------------------- ---------------------- ---------------------- ---------------------- ---------------------- ---------------------- ---------------------- ----------EE---------- ---------E--E--------- ---------E--E--------- ---------E--E--------- ----------EE---------- -----EE--------EE----- ----E--E------E--E---- ---E----E----E----E--- ---E----E----E----E--- ----E--E------E--E---- -----EE--------EE----- ---------------------- ---------------------- ---------------------- ---------------------- ---------------------- ---------------------- ---------------------- ---------------------- 
