model
size = 25 25 3, scale = 0.05, origin = -y
material 
  colors = A:#FC9 B:#E00 C:#D00
voxels
------------------------- ------------------------- ------------------------- ------------------------- -------C----------C------ -------C---------CC------ -------C--CCCCCCCCC------ -------C--C---C---C------ -------C--C---C---C------ -------C--C-CCCCC-C------ -------C--C---C---C------ ---CC--C--C---C---C------ ----CC-C--CCCCCCCCCC----- -----CCCCC--------------- ------CCC--CCCCCCC------- -------C---C-----C------- ----CCCC---C-----C------- -------CC--CCCCCCC------- ------------------------- -------C---CCCCCCC------- ------C------------------ ------------------------- ------------------------- ------------------------- ------------------------- 
------------------------- ------------------------- ------------------------- ------------------------- -------B----------B------ -------B---------BB------ -------B--BBBBBBBBB------ -------B--B---B---B------ -------B--B---B---B------ -------B--B-BBBBB-B------ -------B--B---B---B------ ---BB--B--B---B---B------ ----BB-B--BBBBBBBBBB----- -----BBBBB--------------- ------BBB--BBBBBBB------- -------B---B-----B------- ----BBBB---B-----B------- -------BB--BBBBBBB------- ------------------------- -------B---BBBBBBB------- ------B------------------ ------------------------- ------------------------- ------------------------- ------------------------- 
---------AAAAAAA--------- -------AAAAAAAAAAA------- -----AAAAAAAAAAAAAAA----- ----AAAAAAAAAAAAAAAAA---- ---AAAAAAAAAAAAAAAAAAA--- --AAAAAAAAAAAAAAAAAAAAA-- --AAAAAAAAAAAAAAAAAAAAA-- -AAAAAAAAAAAAAAAAAAAAAAA- -AAAAAAAAAAAAAAAAAAAAAAA- AAAAAAAAAAAAAAAAAAAAAAAAA AAAAAAAAAAAAAAAAAAAAAAAAA AAAAAAAAAAAAAAAAAAAAAAAAA AAAAAAAAAAAA-AAAAAAAAAAAA AAAAAAAAAAAAAAAAAAAAAAAAA AAAAAAAAAAAAAAAAAAAAAAAAA AAAAAAAAAAAAAAAAAAAAAAAAA -AAAAAAAAAAAAAAAAAAAAAAA- -AAAAAAAAAAAAAAAAAAAAAAA- --AAAAAAAAAAAAAAAAAAAAA-- --AAAAAAAAAAAAAAAAAAAAA-- ---AAAAAAAAAAAAAAAAAAA--- ----AAAAAAAAAAAAAAAAA---- -----AAAAAAAAAAAAAAA----- -------AAAAAAAAAAA------- ---------AAAAAAA--------- 
