model
size = 32, scale = 0.05, origin = -y
material 
  colors = A:#700 B:#400 C:#500 D:#444 E:#0E0 F:#F90 G:#555 H:#111 I:#0F6 J:#AAA K:#E00 L:#6F6 M:#888 N:#6FF O:#CF0 P:#3F0 Q:#9F0 R:#CC0
voxels
652-11(D-F2(-D)25-)D-F2(-D)665-D-F2(-D)313-D-F2(-D)25-D-F2(-D)571-3H28-5H26-7H25-2HBHB2H25-7H26-5H28-3H219-D-F2(-D)25-D-F2(-D)506-5B26-7B24-9B22-4(11B21-)11B22-9B24-7B26-5B154-D-F2(-D)25-D-F2(-D)474-5B25-9B22-11B21-11B20-4(13B19-)13B20-11B21-11B22-9B25-5B122-D-F2(-D)25-D-F2(-D)27-2(3C2(29-3A)29-)6(A-A29-)3A29-3A28-B3AB25-3B3A3B22-4B3A4B21-4B3A4B20-4(5B3A5B19-)5B3A5B20-4B3A4B21-4B3A4B22-3B3A3B25-5B122-D-F2(-D)25-D-F2(-D)26-5C2(27-5A)27-C3AC2(27-5A)27-2AI2A27-2AR2A27-2AL2A27-2AQ2A27-2AL2A27-2AI2A3(27-5A)25-2B5A2B22-3B5A3B21-3B5A3B20-4(4B5A4B19-)4B5A4B20-3B5A3B21-3B5A3B22-2B5A2B25-5B122-2(D-F2(-D)25-)7C2(25-7A)25-C5AC11(25-7A)24-B7AB22-2B7A2B21-2B7A2B20-4(3B7A3B19-)3B7A3B20-2B7A2B21-2B7A2B22-B5A3B25-4B123-D-F2(-D)25-D-F2(-D)23-11C2(21-11A)21-2C7A2C2(21-11A)19-15A16-17A15-18A14-2(18A19-7A20-)18A14-18A10-25A7-A-21A-A3(7-25A)8-23A9-23A10-21A11-21A12-19A14-17A16-15A19-11A23-7A57-D-F2(-D)25-D-F2(-D)23-11C2(21-11A)21-C9AC2(21-11A)19-15A16-17A15-18A14-2(18A15-4G7A5G15-)18A14-18A10-4(25A7-)25A8-23A9-23A10-21A11-21A12-19A14-17A16-15A19-11A23-7A57-D-F2(-D)25-D-F2(-D)22-13C2(19-13A)19-C11AC2(19-13A)18-15A16-17A15-18A14-18A15-G14AM15-18A15-G14AG15-18A14-18A10-4(25A7-)25A8-23A9-23A10-21A11-21A12-19A14-17A16-15A19-11A23-7A57-D-F2(-D)25-D-F2(-D)21-15C2(17-15A)17-C13AC3(17-15A)16-17A15-18A14-18A15-M14AG15-18A15-G14AM15-18A14-18A10-4(25A7-)25A8-23A9-23A10-21A11-21A12-19A14-17A16-15A19-11A23-7A57-D-F2(-D)25-D-F2(-D)20-17C2(15-17A)15-C15AC4(15-17A)15-18A14-18A15-G14AM15-18A15-M14AM15-18A14-18A10-4(25A7-)25A8-23A9-23A10-21A11-21A12-19A14-17A16-15A19-11A23-7A57-D-F2(-D)25-D-F2(-D)20-17C2(15-17A)15-C15AC4(15-17A)15-18A14-2(18A15-G14AG15-)18A14-18A10-4(25A7-)25A8-23A9-23A10-21A11-21A12-19A14-17A16-15A19-11A23-7A57-D-F2(-D)25-D-F2(-D)21-15C2(17-15A)17-C13AC3(17-15A)16-17A15-3(18A14-)18A15-M14AG15-18A14-18A10-4(25A7-)25A8-23A9-23A10-21A11-21A12-19A14-17A16-15A19-11A23-7A57-D-F2(-D)25-D-F2(-D)22-13C2(19-13A)19-C11AC2(19-13A)18-15A16-17A15-3(18A14-)18A15-G14AG15-18A14-18A10-4(25A7-)25A8-23A9-23A10-21A11-21A12-19A14-17A16-15A19-11A23-7A57-D-F2(-D)25-D-F2(-D)23-11C2(21-11A)21-C9AC2(21-11A)19-15A16-17A15-3(18A14-)18A15-G16A2(14-18A)10-4(25A7-)25A8-23A9-23A10-21A11-21A12-19A14-17A16-15A19-11A23-7A57-D-F2(-D)25-D-F2(-D)23-11C2(21-11A)21-2C7A2C2(21-11A)19-15A16-17A15-6(18A14-)18A10-4(25A7-)25A8-23A9-23A10-21A11-21A12-19A14-17A16-15A19-11A23-7A57-2(D-F2(-D)25-)7C2(25-7A)25-C5AC2(25-7A)21-17A8(14-18A)8-2(30A2-)30A-384A12-D-F2(-D)25-D-F2(-D)26-5C2(27-5A)27-C3AC2(27-5A)21-2(18A14-)4A2B6H2B4A4(14-3A3B6H3B3A)14-4A10B4A14-18A8-30A3-28A3-30A-384A12-D-F2(-D)25-D-F2(-D)27-3C2(29-3A)29-3C2(29-3A)22-18A14-4AB2A4K2AB4A6(14-3AB10-B3A)14-4A10B4A8-2(30A2-)30A-63A2(D31A)D64A2-I26AI2-32A2-I26AI2-96A12-D-F2(-D)25-D-F2(-D)181-2(16A16-)3AB2A4K2AB3A4(16-2AB10-B2A)15-3AB10-B3A14-3AB-G6-G-B3A14-4A10B4A8-2(30A2-)30A-2(63AD)64A2-O26AO2-32A2-I26AI2-96A12-D-F2(-D)25-D-F2(-D)180-2(18A14-)4AB2A4K2AB4A14-3AB-G6-G-4(B3A14-3AB10-)B3A14-3AB-G6-G-B3A14-4A10B4A8-2(30A2-)30A-2(63AD)64A2-I26AI2-32A2-I26AI2-96A12-D-F2(-D)25-D-F2(-D)148-3(18A14-)4AB2A4K2AB4A14-3AB-G6-G-4(B3A14-3AB10-)B3A14-3AB-G6-G-B3A14-4A10B4A8-2(30A2-)30A-192A2-I26AI2-32A2-O26AO2-96A12-D-F2(-D)25-D-F2(-D)117-4(16A16-)3AB2A4K2AB3A16-2AB-G6-G-3(B2A16-2AB10-)B2A15-3AB10-B3A14-3AB-G6-G-B3A14-4A10B4A8-2(30A2-)30A-63A2(D31A)D64A2-I26AI2-32A2-I26AI2-96A12-D-F2(-D)25-D-F2(-D)116-4(18A14-)4AB2A4K2AB4A14-3AB-G6-G-4(B3A14-3AB10-)B3A14-3AB-G6-G-B3A14-4A10B4A8-2(30A2-)30A-192A2-I26AI2-32A2-I26AI2-96A12-D-F2(-D)25-D-F2(-D)84-5(18A14-)4AB2A4K2AB4A14-3AB-G6-G-4(B3A14-3AB10-)B3A14-3AB-G6-G-B3A14-4A10B4A8-2(30A2-)30A-63A2(D31A)D64A2-I26AI2-32A2-I26AI2-96A12-D-F2(-D)25-D-F2(-D)85-5(16A16-)3AB8AB3A16-2AB-G6-G-3(B2A16-2AB10-)B2A15-3AB10-B3A14-3AB-G6-G-B3A14-4A10B4A8-2(30A2-)30A-221AI2-61AI2-96A12-D-F2(-D)25-D-F2(-D)21-17A6(14-18A)14-4AB8AB4A14-3AB-8G-4(B3A14-3AB10-)B3A14-3AB-8G-B3A14-4A10B4A8-30A3-28A3-30A-286AI97A12-D-F2(-D)25-D-F2(-D)20-6(2(4A3-)4A14-)4A-8A-4A14-3AJ10C4A6(14-4A10-B3A)14-3AJ14A8-2(9AJ20A2-)9A3(J2A)J11A-10A3(J2A)J17A6J2(2AJ)2A8J71A24ENPLE4A22E2N2L2E4A20E2N2L4E4A18EPN2L6E4A18EIL8E98A12-D-F2(-D)25-D-F2(-D)21-17(3A10-3A16-)16A8-97A30C5(2AC28-C)2A30C65A12-D-F2(-D)25-D-F2(-D)985-D-F2(-D)25-D-F2(-D)13-
