model
size = 12 19 32, scale = 0.05, origin = -y
material 
  colors = A:#FEED3F B:#004 C:#FFF59C D:#005 E:#007 F:#008 G:#002 H:#00A I:#00B J:#00D K:#00E L:#FFED5B M:#FDD736 N:#FFF691 O:#FAC12C P:#FAA821 Q:#F4801D R:#EEE S:#001 T:#9CF
voxels
4-5C7-5A7-5G198-C4A2C5-A5RA2(5-G)6-5B185-C2A2(CA)C4-A6CA4-2G5-G5-7B184-4(CA)C3-A7CA3-G6-2G3-B6-2B4-6B173-C2ACAC2AC3-A7CA3-G7-G3-B7-B3-9B170-C2A3(CA)C2-A8CA2-2G7-G2-2B7-B2-3B5-2B4-6D160-3(CA)C2AC2-A8NA2-G8-G2(2-B8-B)3-9D158-C2A2(CA)C2AC-A9NA-G8-2G-2(B8-B2-)10D158-5(CA)C-A9NA-G9-G-B8-2B-B8-B2-3D5-2D4-6D148-C2A2(CA)C2AC-A9NA-G9-G2(-B8-2B)-D8-D3-8D147-5(CA)C-A9LA-G9-G2(-B8-2B)-D8-D2-10D145-C3A2(CA)C2ACA10LAG10-G-B8-2B-B8-B2-D8-D2-2(3D4-)6E135-C2A5(CA)9L2AG9-2G2B8-B2-B8-B2(2-D8-D)3-8E134-5(CA)C-A9LA-G9-G-2B8-B2-B8-B2(2-D8-D)2-2E6C2E133-C2A2(CA)C2AC-11A-G9-G-2B8-B2-B8-B2(2-D8-D)2-E8-E3-E6NE122-5(CA)C-11A-G9-G2(-2B8-B)2(2-D8-D)2(2-E8-E)3-F6LF110-C2A2(CA)C2AC-11A-G9-G2(-2B8-B)-2D8-D2-D8-D2(2-E8-E)2-F8-F3-F6AF98-5(CA)C-11A-2G8-G2(-2B8-B)2(-2D8-D)-2E8-E2-E8-E2(2-F8-F)3-H6MH86-C2A2(CA)C2AC-A9MA-2G8-G2(-2B8-B)2(-2D8-D)2(-2E8-E)-2F8-F2-F8-F2-H8-H2-2H6OH4-I6OI62-5(CA)C-A9MA-2G8-G2(-2B8-B)2(-2D8-D)2(-2E8-E)2(-2F8-F)2(2-H8-H)2-I8-I3-I6PI4-J6PJ38-C2A2(CA)C2AC-AJ8MA-2G8-G2(-2B8-B)2(-2D8-D)2(-2E8-E)2(-2F8-F)-2H8-H2-H8-H2(2-I8-I)2-JG7-J3-J6QJ4-K6QK14-5(CA)2CA10MA2G7-3G2(2B7-2B-)2(2D7-2D-)AE7-2E-2E7-2E-NF7-2F-2F7-2F2(-2H7-2H)2(2-I7-2I)2-J7-2J2-2J5-JTJ2-2K5-2K3-2K5-2K2-C2A5(CA)3O3H4OA2G7-3G2B7-5B7-2B2(-2D7-2D)-2E7-2E-LE7-2E2(-2F7-2F)2(-2H7-2H)-2I7-2I2-I7-2I2(2-J7-2J)2-K7-K3-K7-K2-4(CA)C2ACAO3(F2O)A2G7-3GQB7-5B7-3B2D7-5D7-2D2(-2E7-2E)-2F7-2F-CF7-FL2(-2H7-2H)-2I7-2I2-I7-2I2(2-J7-2J)2-K7-K3-K7-K2-C2A5(CA)2O2(EO)E3OA2G7-3GQB7-3BPB7-3BOD7-3DMD7-2D-AE7-2E-LE7-2E-NF7-2F-CF7-2F2(-2H7-HA)-2I7-2I2-I7-2I2(2-J7-2J)2-K7-K3-K7-K2-4(CA)C2ACAO3(D2O)A2G7-3GQB7-5B7-3B2(2D7-2D-)2(2E7-2E-)2F7-2F-CF7-2F-2H7-HA-2H7-HM-2I7-2I2-I7-2I2-J7-2J2-J7-J2(3-K7-K)2-C2A5(CA)4PB5PA2G7-3G2B7-5B7-2B2(-2D7-2D)-2E7-2E-LE7-2E2(-2F7-2F)2(-2H7-2H)2-I7-IM2-I7-2I2-J7-2J2-J7-J2(3-K7-K)2-C3A3(CA)C-A4PG4PA-2G7-2G2(-2B7-2B)2(-2D7-2D)-AE7-2E-2E7-2E-NF7-2F-2F7-2F2(-2H7-2H)2-I7-2I2-I7-IO2-2(J7-J3-)2(K7-K3-)3(CA)C2AC2-A2P3S3PA2-2G5-3G2(2-2B5-3B)2(2-2D5-3D)2(2-2E5-3E)2(2-2F5-3F)2(2-2H5-3H)2-2I5-3I2-2I5-2I3-2J5-JO3-2J5-2J2(3-2K5-2K)3-C2ACAC2AC3-A7QA2(3-3G)4(3-3B)2(3-3D)3-DTD3-3D4(3-3E)4(3-3F)4(3-3H)4-2(2I3-2I5-)2J3-JP5-JK3-KJ5-2K3-2K2(5-K)5-C5AC5-3(AQ)A5-7G2(5-7B)5-A5DA5-DM3DMD5-O5EO5-7E2(5-7F)5-7H6-5H2(7-5I)7-4JP7-J3QP7-K3-K19-5C7-5A7-5G8-3N10-L11-A11-M11-O10-3P93-3Q29-
