model
size = 25 28 25, scale = 0.05, origin = -y
material 
  colors = A:#111 B:#FC3 C:#0F6
voxels
------------------------- ------------------------- ------------------------- ------------------------- ------------------------- ------------------------- ------------------------- ------------------------- ------------------------- -----------AAA----------- ----------AAAAA---------- ---------AAAAAAA--------- ---------AAAAAAA--------- ---------AAAAAAA--------- ----------AAAAA---------- -----------AAA----------- ------------------------- ------------------------- ------------------------- ------------------------- ------------------------- ------------------------- ------------------------- ------------------------- ------------------------- ------------------------- ------------------------- ------------------------- 
------------------------- ------------------------- ------------------------- ------------------------- ------------------------- ------------------------- ------------------------- ---------AAAAAAA--------- --------AAAAAAAAA-------- -------AAAAAAAAAAA------- -------AAAAAAAAAAA------- -------AAAAAAAAAAA------- -------AAAAAAAAAAA------- -------AAAAAAAAAAA------- -------AAAAAAAAAAA------- -------AAAAAAAAAAA------- --------AAAAAAAAA-------- ---------AAAAAAA--------- ------------------------- ------------------------- ------------------------- ------------------------- ------------------------- ------------------------- ------------------------- ------------------------- ------------------------- ------------------------- 
------------------------- ------------------------- ------------------------- ------------------------- ------------------------- ----------AAAAA---------- --------AAAAAAAAA-------- -------AAAAAAAAAAA------- ------AAAAAAAAAAAAA------ ------AAAAAAAAAAAAA------ -----AAAAAAAAAAAAAAA----- -----AAAAAAAAAAAAAAA----- -----AAAAAAAAAAAAAAA----- -----AAAAAAAAAAAAAAA----- -----AAAAAAAAAAAAAAA----- ------AAAAAAAAAAAAA------ ------AAAAAAAAAAAAA------ -------AAAAAAAAAAA------- --------AAAAAAAAA-------- ----------AAAAA---------- ------------------------- ------------------------- ------------------------- ------------------------- ------------------------- ------------------------- ------------------------- ------------------------- 
------------------------- ------------------------- ------------------------- ------------------------- ---------AAAAAAA--------- -------AAAAAAAAAAA------- ------AAAAAAAAAAAAA------ -----AAAAAAAAAAAAAAA----- -----AAAAAAAAAAAAAAA----- ----AAAAAAAAAAAAAAAAA---- ----AAAAAAAAAAAAAAAAA---- ----AAAAAAAAAAAAAAAAA---- ----AAAAAAAAAAAAAAAAA---- ----AAAAAAAAAAAAAAAAA---- ----AAAAAAAAAAAAAAAAA---- ----AAAAAAAAAAAAAAAAA---- -----AAAAAAAAAAAAAAA----- -----AAAAAAAAAAAAAAA----- ------AAAAAAAAAAAAA------ -------AAAAAAAAAAA------- ---------AAAAAAA-B------- -------------B-B-B------- -------------B-B-B------- -------------BBBBB------- ---------------B--------- ---------------B--------- ---------------B--------- --------------BBB-------- 
------------------------- ------------------------- ------------------------- ---------AAAAAAA--------- -------AAAAAAAAAAA------- ------AAAAAAAAAAAAA------ -----AAAAAAAAAAAAAAA----- ----AAAAAAAAAAAAAAAAA---- ----AAAAAAAAAAAAAAAAA---- ---AAAAAAAAAAAAAAAAAAA--- ---AAAAAAAAAAAAAAAAAAA--- ---AAAAAAAAAAAAAAAAAAA--- ---AAAAAAAAAAAAAAAAAAA--- ---AAAAAAAAAAAAAAAAAAA--- ---AAAAAAAAAAAAAAAAAAA--- ---AAAAAAAAAAAAAAAAAAA--- ----AAAAAAAAAAAAAAAAA---- ----AAAAAAAAAAAAAAAAA---- -----AAAAAAAAAAAAAAA----- ------AAAAAAAAAAAAA------ -------AAAAAAAAAAA------- ---------AAAAAAA--------- ------------------------- ------------------------- ------------------------- ------------------------- ------------------------- ------------------------- 
------------------------- ------------------------- ----------AAAAA---------- -------AAAAAAAAAAA------- ------AAAAAAAAAAAAA------ -----AAAAAAAAAAAAAAA----- ----AAAAAAAAAAAAAAAAA---- ---AAAAAAAAAAAAAAAAAAA--- ---AAAAAAAAAAAAAAAAAAA--- ---AAAAAAAAAAAAAAAAAAA--- --AAAAAAAAAAAAAAAAAAAAA-- --AAAAAAAAAAAAAAAAAAAAA-- --AAAAAAAAAAAAAAAAAAAAA-- --AAAAAAAAAAAAAAAAAAAAA-- --AAAAAAAAAAAAAAAAAAAAA-- ---AAAAAAAAAAAAAAAAAAA--- ---AAAAAAAAAAAAAAAAAAA--- ---AAAAAAAAAAAAAAAAAAA--- ----AAAAAAAAAAAAAAAAA---- -----AAAAAAAAAAAAAAA----- ------AAAAAAAAAAAAA------ -------AAAAAAAAAAA------- ----------AAAAA---------- ------------------------- ------------------------- ------------------------- ------------------------- ------------------------- 
------------------------- ------------------------- --------AAAAAAAAA-------- ------AAAAAAAAAAAAA------ -----AAAAAAAAAAAAAAA----- ----AAAAAAAAAAAAAAAAA---- ---AAAAAAAAAAAAAAAAAAA--- ---AAAAAAAAAAAAAAAAAAA--- --AAAAAAAAAAAAAAAAAAAAA-- --AAAAAAAAAAAAAAAAAAAAA-- --AAAAAAAAAAAAAAAAAAAAA-- --AAAAAAAAAAAAAAAAAAAAA-- --AAAAAAAAAAAAAAAAAAAAA-- --AAAAAAAAAAAAAAAAAAAAA-- --AAAAAAAAAAAAAAAAAAAAA-- --AAAAAAAAAAAAAAAAAAAAA-- --AAAAAAAAAAAAAAAAAAAAA-- ---AAAAAAAAAAAAAAAAAAA--- ---AAAAAAAAAAAAAAAAAAA--- ----AAAAAAAAAAAAAAAAA---- -----AAAAAAAAAAAAAAA----- ------AAAAAAAAAAAAA------ --------AAAAAAAAA-------- ------------------------- ------------------------- ------------------------- ------------------------- ------------------------- 
------------------------- ---------AAAAAAA--------- -------AAAAAAAAAAA------- -----AAAAAAAAAAAAAAA----- ----AAAAAAAAAAAAAAAAA---- ---AAAAAAAAAAAAAAAAAAA--- ---AAAAAAAAAAAAAAAAAAA--- --AAAAAAAAAAAAAAAAAAAAA-- --AAAAAAAAAAAAAAAAAAAAA-- -AAAAAAAAAAAAAAAAAAAAAAA- -AAAAAAAAAAAAAAAAAAAAAAA- -AAAAAAAAAAAAAAAAAAAAAAA- -AAAAAAAAAAAAAAAAAAAAAAA- -AAAAAAAAAAAAAAAAAAAAAAA- -AAAAAAAAAAAAAAAAAAAAAAA- -AAAAAAAAAAAAAAAAAAAAAAA- --AAAAAAAAAAAAAAAAAAAAA-- --AAAAAAAAAAAAAAAAAAAAA-- ---AAAAAAAAAAAAAAAAAAA--- ---AAAAAAAAAAAAAAAAAAA--- ----AAAAAAAAAAAAAAAAA---- -----AAAAAAAAAAAAAAA----- -------AAAAAAAAAAA------- ---------AAAAAAA--------- ------------------------- ------------------------- ------------------------- ------------------------- 
------------------------- --------AAAAAAAAA-------- ------AAAAAAAAAAAAA------ -----AAAAAAAAAAAAAAA----- ----AAAAAAAAAAAAAAAAA---- ---AAAAAAAAAAAAAAAAAAA--- --AAAAAAAAAAAAAAAAAAAAA-- --AAAAAAAAAAAAAAAAAAAAA-- -AAAAAAAAAAAAAAAAAAAAAAA- -AAAAAAAAAAAAAAAAAAAAAAA- -AAAAAAAAAAAAAAAAAAAAAAA- -AAAAAAAAAAAAAAAAAAAAAAA- -AAAAAAAAAAAAAAAAAAAAAAA- -AAAAAAAAAAAAAAAAAAAAAAA- -AAAAAAAAAAAAAAAAAAAAAAA- -AAAAAAAAAAAAAAAAAAAAAAA- -AAAAAAAAAAAAAAAAAAAAAAA- --AAAAAAAAAAAAAAAAAAAAA-- --AAAAAAAAAAAAAAAAAAAAA-- ---AAAAAAAAAAAAAAAAAAA--- ----AAAAAAAAAAAAAAAAA---- -----AAAAAAAAAAAAAAA----- ------AAAAAAAAAAAAA------ --------AAAAAAAAA-------- ------------------------- ------------------------- ------------------------- ------------------------- 
-----------AAA----------- -------AAAAAAAAAAA------- ------AAAAAAAAAAAAA------ ----AAAAAAAAAAAAAAAAA---- ---AAAAAAAAAAAAAAAAAAA--- ---AAAAAAAAAAAAAAAAAAA--- --AAAAAAAAAAAAAAAAAAAAA-- -AAAAAAAAAAAAAAAAAAAAAAA- -AAAAAAAAAAAAAAAAAAAAAAA- -AAAAAAAAAAAAAAAAAAAAAAA- -AAAAAAAAAAAAAAAAAAAAAAA- AAAAAAAAAAAAAAAAAAAAAAAAA AAAAAAAAAAAAAAAAAAAAAAAAA AAAAAAAAAAAAAAAAAAAAAAAAA -AAAAAAAAAAAAAAAAAAAAAAA- -AAAAAAAAAAAAAAAAAAAAAAA- -AAAAAAAAAAAAAAAAAAAAAAA- -AAAAAAAAAAAAAAAAAAAAAAA- --AAAAAAAAAAAAAAAAAAAAA-- ---AAAAAAAAAAAAAAAAAAA--- ---AAAAAAAAAAAAAAAAAAA--- ----AAAAAAAAAAAAAAAAA---- ------AAAAAAAAAAAAA------ -------AAAAAAAAAAA------- -----------AAA----------- ------------------------- ------------------------- ------------------------- 
----------AAAAA---------- -------AAAAAAAAAAA------- -----AAAAAAAAAAAAAAA----- ----AAAAAAAAAAAAAAAAA---- ---AAAAAAAAAAAAAAAAAAA--- --AAAAAAAAAAAAAAAAAAAAA-- --AAAAAAAAAAAAAAAAAAAAA-- -AAAAAAAAAAAAAAAAAAAAAAA- -AAAAAAAAAAAAAAAAAAAAAAA- -AAAAAAAAAAAAAAAAAAAAAAA- AAAAAAAAAAAAAAAAAAAAAAAAA AAAAAAAAAAAAAAAAAAAAAAAAA AAAAAAAAAAAAAAAAAAAAAAAAA AAAAAAAAAAAAAAAAAAAAAAAAA AAAAAAAAAAAAAAAAAAAAAAAAA -AAAAAAAAAAAAAAAAAAAAAAA- -AAAAAAAAAAAAAAAAAAAAAAA- -AAAAAAAAAAAAAAAAAAAAAAA- --AAAAAAAAAAAAAAAAAAAAA-- --AAAAAAAAAAAAAAAAAAAAA-- ---AAAAAAAAAAAAAAAAAAA--- ----AAAAAAAAAAAAAAAAA---- -----AAAAAAAAAAAAAAA----- -------AAAAAAAAAAA------- ----------AAAAA---------- ------------------------- ------------------------- ------------------------- 
---------AAAAAAA--------- -------AAAAAAAAAAA------- -----AAAAAAAAAAAAAAA----- ----AAAAAAAAAAAAAAAAA---- ---AAAAAAAAAAAAAAAAAAA--- --AAAAAAAAAAAAAAAAAAAAA-- --AAAAAAAAAAAAAAAAAAAAA-- -AAAAAAAAAAAAAAAAAAAAAAA- -AAAAAAAAAAAAAAAAAAAAAAA- AAAAAAAAAAAAAAAAAAAAAAAAA AAAAAAAAAAAAAAAAAAAAAAAAA AAAAAAAAAAAAAAAAAAAAAAAAA AAAAAAAAAAAAAAAAAAAAAAAAA AAAAAAAAAAAAAAAAAAAAAAAAA AAAAAAAAAAAAAAAAAAAAAAAAA AAAAAAAAAAAAAAAAAAAAAAAAA -AAAAAAAAAAAAAAAAAAAAAAA- -AAAAAAAAAAAAAAAAAAAAAAA- --AAAAAAAAAAAAAAAAAAAAA-- --AAAAAAAAAAAAAAAAAAAAA-- ---AAAAAAAAAAAAAAAAAAA--- ----AAAAAAAAAAAAAAAAA---- -----AAAAAAAAAAAAAAA----- -------AAAAAAAAAAA------- ---------AAAAAAA--------- ------------------------- ------------------------- ------------------------- 
---------AAAAAAA--------- -------AAAAACAAAAA------- -----AAAAAAACAAAAAAA----- ----AAAAAAAACAAAAAAAA---- ---AAAAAAAAACAAAAAAAAA--- --AAAAAAAAAACAAAAAAAAAA-- --AAAAAAAAAACAAAAAAAAAA-- -AAAAAAAAAAACAAAAAAAAAAA- -AAAAAAAAAAACAAAAAAAAAAA- AAAAAAAAAAAACAAAAAAAAAAAA AAAAAAAAAAAACAAAAAAAAAAAA AAAAAAAAAAAACAAAAAAAAAAAA AAAAAAAAAAAAAAAAAAAAAAAAA AAAAAAAAAAAAAAAAAAAAAAAAA AAAAAAAAAAAAAAAAAAAAAAAAA AAAAAAAAAAAAAAAAAAAAAAAAA -AAAAAAAAAAAAAAAAAAAAAAA- -AAAAAAAAAAAAAAAAAAAAAAA- --AAAAAAAAAAAAAAAAAAAAA-- --AAAAAAAAAAAAAAAAAAAAA-- ---AAAAAAAAAAAAAAAAAAA--- ----AAAAAAAAAAAAAAAAA---- -----AAAAAAAAAAAAAAA----- -------AAAAAAAAAAA------- ---------AAAAAAA--------- ------------------------- ------------------------- ------------------------- 
---------AAAAAAA--------- -------AAAAAAAAAAA------- -----AAAAAAAAAAAAAAA----- ----AAAAAAAAAAAAAAAAA---- ---AAAAAAAAAAAAAAAAAAA--- --AAAAAAAAAAAAAAAAAAAAA-- --AAAAAAAAAAAAAAAAAAAAA-- -AAAAAAAAAAAAAAAAAAAAAAA- -AAAAAAAAAAAAAAAAAAAAAAA- AAAAAAAAAAAAAAAAAAAAAAAAA AAAAAAAAAAAAAAAAAAAAAAAAA AAAAAAAAAAAAAAAAAAAAAAAAA AAAAAAAAAAAAAAAAAAAAAAAAA AAAAAAAAAAAAAAAAAAAAAAAAA AAAAAAAAAAAAAAAAAAAAAAAAA AAAAAAAAAAAAAAAAAAAAAAAAA -AAAAAAAAAAAAAAAAAAAAAAA- -AAAAAAAAAAAAAAAAAAAAAAA- --AAAAAAAAAAAAAAAAAAAAA-- --AAAAAAAAAAAAAAAAAAAAA-- ---AAAAAAAAAAAAAAAAAAA--- ----AAAAAAAAAAAAAAAAA---- -----AAAAAAAAAAAAAAA----- -------AAAAAAAAAAA------- ---------AAAAAAA--------- ------------------------- ------------------------- ------------------------- 
----------AAAAA---------- -------AAAAAAAAAAA------- -----AAAAAAAAAAAAAAA----- ----AAAAAAAAAAAAAAAAA---- ---AAAAAAAAAAAAAAAAAAA--- --AAAAAAAAAAAAAAAAAAAAA-- --AAAAAAAAAAAAAAAAAAAAA-- -AAAAAAAAAAAAAAAAAAAAAAA- -AAAAAAAAAAAAAAAAAAAAAAA- -AAAAAAAAAAAAAAAAAAAAAAA- AAAAAAAAAAAAAAAAAAAAAAAAA AAAAAAAAAAAAAAAAAAAAAAAAA AAAAAAAAAAAAAAAAAAAAAAAAA AAAAAAAAAAAAAAAAAAAAAAAAA AAAAAAAAAAAAAAAAAAAAAAAAA -AAAAAAAAAAAAAAAAAAAAAAA- -AAAAAAAAAAAAAAAAAAAAAAA- -AAAAAAAAAAAAAAAAAAAAAAA- --AAAAAAAAAAAAAAAAAAAAA-- --AAAAAAAAAAAAAAAAAAAAA-- ---AAAAAAAAAAAAAAAAAAA--- ----AAAAAAAAAAAAAAAAA---- -----AAAAAAAAAAAAAAA----- -------AAAAAAAAAAA------- ----------AAAAA---------- ------------------------- ------------------------- ------------------------- 
-----------AAA----------- -------AAAAAAAAAAA------- ------AAAAAAAAAAAAA------ ----AAAAAAAAAAAAAAAAA---- ---AAAAAAAAAAAAAAAAAAA--- ---AAAAAAAAAAAAAAAAAAA--- --AAAAAAAAAAAAAAAAAAAAA-- -AAAAAAAAAAAAAAAAAAAAAAA- -AAAAAAAAAAAAAAAAAAAAAAA- -AAAAAAAAAAAAAAAAAAAAAAA- -AAAAAAAAAAAAAAAAAAAAAAA- AAAAAAAAAAAAAAAAAAAAAAAAA AAAAAAAAAAAAAAAAAAAAAAAAA AAAAAAAAAAAAAAAAAAAAAAAAA -AAAAAAAAAAAAAAAAAAAAAAA- -AAAAAAAAAAAAAAAAAAAAAAA- -AAAAAAAAAAAAAAAAAAAAAAA- -AAAAAAAAAAAAAAAAAAAAAAA- --AAAAAAAAAAAAAAAAAAAAA-- ---AAAAAAAAAAAAAAAAAAA--- ---AAAAAAAAAAAAAAAAAAA--- ----AAAAAAAAAAAAAAAAA---- ------AAAAAAAAAAAAA------ -------AAAAAAAAAAA------- -----------AAA----------- ------------------------- ------------------------- ------------------------- 
------------------------- --------AAAAAAAAA-------- ------AAAAAAAAAAAAA------ -----AAAAAAAAAAAAAAA----- ----AAAAAAAAAAAAAAAAA---- ---AAAAAAAAAAAAAAAAAAA--- --AAAAAAAAAAAAAAAAAAAAA-- --AAAAAAAAAAAAAAAAAAAAA-- -AAAAAAAAAAAAAAAAAAAAAAA- -AAAAAAAAAAAAAAAAAAAAAAA- -AAAAAAAAAAAAAAAAAAAAAAA- -AAAAAAAAAAAAAAAAAAAAAAA- -AAAAAAAAAAAAAAAAAAAAAAA- -AAAAAAAAAAAAAAAAAAAAAAA- -AAAAAAAAAAAAAAAAAAAAAAA- -AAAAAAAAAAAAAAAAAAAAAAA- -AAAAAAAAAAAAAAAAAAAAAAA- --AAAAAAAAAAAAAAAAAAAAA-- --AAAAAAAAAAAAAAAAAAAAA-- ---AAAAAAAAAAAAAAAAAAA--- ----AAAAAAAAAAAAAAAAA---- -----AAAAAAAAAAAAAAA----- ------AAAAAAAAAAAAA------ --------AAAAAAAAA-------- ------------------------- ------------------------- ------------------------- ------------------------- 
------------------------- ---------AAAAAAA--------- -------AAAAAAAAAAA------- -----AAAAAAAAAAAAAAA----- ----AAAAAAAAAAAAAAAAA---- ---AAAAAAAAAAAAAAAAAAA--- ---AAAAAAAAAAAAAAAAAAA--- --AAAAAAAAAAAAAAAAAAAAA-- --AAAAAAAAAAAAAAAAAAAAA-- -AAAAAAAAAAAAAAAAAAAAAAA- -AAAAAAAAAAAAAAAAAAAAAAA- -AAAAAAAAAAAAAAAAAAAAAAA- -AAAAAAAAAAAAAAAAAAAAAAA- -AAAAAAAAAAAAAAAAAAAAAAA- -AAAAAAAAAAAAAAAAAAAAAAA- -AAAAAAAAAAAAAAAAAAAAAAA- --AAAAAAAAAAAAAAAAAAAAA-- --AAAAAAAAAAAAAAAAAAAAA-- ---AAAAAAAAAAAAAAAAAAA--- ---AAAAAAAAAAAAAAAAAAA--- ----AAAAAAAAAAAAAAAAA---- -----AAAAAAAAAAAAAAA----- -------AAAAAAAAAAA------- ---------AAAAAAA--------- ------------------------- ------------------------- ------------------------- ------------------------- 
------------------------- ------------------------- --------AAAAAAAAA-------- ------AAAAAAAAAAAAA------ -----AAAAAAAAAAAAAAA----- ----AAAAAAAAAAAAAAAAA---- ---AAAAAAAAAAAAAAAAAAA--- ---AAAAAAAAAAAAAAAAAAA--- --AAAAAAAAAAAAAAAAAAAAA-- --AAAAAAAAAAAAAAAAAAAAA-- --AAAAAAAAAAAAAAAAAAAAA-- --AAAAAAAAAAAAAAAAAAAAA-- --AAAAAAAAAAAAAAAAAAAAA-- --AAAAAAAAAAAAAAAAAAAAA-- --AAAAAAAAAAAAAAAAAAAAA-- --AAAAAAAAAAAAAAAAAAAAA-- --AAAAAAAAAAAAAAAAAAAAA-- ---AAAAAAAAAAAAAAAAAAA--- ---AAAAAAAAAAAAAAAAAAA--- ----AAAAAAAAAAAAAAAAA---- -----AAAAAAAAAAAAAAA----- ------AAAAAAAAAAAAA------ --------AAAAAAAAA-------- ------------------------- ------------------------- ------------------------- ------------------------- ------------------------- 
------------------------- ------------------------- ----------AAAAA---------- -------AAAAAAAAAAA------- ------AAAAAAAAAAAAA------ -----AAAAAAAAAAAAAAA----- ----AAAAAAAAAAAAAAAAA---- ---AAAAAAAAAAAAAAAAAAA--- ---AAAAAAAAAAAAAAAAAAA--- ---AAAAAAAAAAAAAAAAAAA--- --AAAAAAAAAAAAAAAAAAAAA-- --AAAAAAAAAAAAAAAAAAAAA-- --AAAAAAAAAAAAAAAAAAAAA-- --AAAAAAAAAAAAAAAAAAAAA-- --AAAAAAAAAAAAAAAAAAAAA-- ---AAAAAAAAAAAAAAAAAAA--- ---AAAAAAAAAAAAAAAAAAA--- ---AAAAAAAAAAAAAAAAAAA--- ----AAAAAAAAAAAAAAAAA---- -----AAAAAAAAAAAAAAA----- ------AAAAAAAAAAAAA------ -------AAAAAAAAAAA------- ----------AAAAA---------- ------------------------- ------------------------- ------------------------- ------------------------- ------------------------- 
------------------------- ------------------------- ------------------------- ---------AAAAAAA--------- -------AAAAAAAAAAA------- ------AAAAAAAAAAAAA------ -----AAAAAAAAAAAAAAA----- ----AAAAAAAAAAAAAAAAA---- ----AAAAAAAAAAAAAAAAA---- ---AAAAAAAAAAAAAAAAAAA--- ---AAAAAAAAAAAAAAAAAAA--- ---AAAAAAAAAAAAAAAAAAA--- ---AAAAAAAAAAAAAAAAAAA--- ---AAAAAAAAAAAAAAAAAAA--- ---AAAAAAAAAAAAAAAAAAA--- ---AAAAAAAAAAAAAAAAAAA--- ----AAAAAAAAAAAAAAAAA---- ----AAAAAAAAAAAAAAAAA---- -----AAAAAAAAAAAAAAA----- ------AAAAAAAAAAAAA------ -------AAAAAAAAAAA------- ---------AAAAAAA--------- ------------------------- ------------------------- ------------------------- ------------------------- ------------------------- ------------------------- 
------------------------- ------------------------- ------------------------- ------------------------- ---------AAAAAAA--------- -------AAAAAAAAAAA------- ------AAAAAAAAAAAAA------ -----AAAAAAAAAAAAAAA----- -----AAAAAAAAAAAAAAA----- ----AAAAAAAAAAAAAAAAA---- ----AAAAAAAAAAAAAAAAA---- ----AAAAAAAAAAAAAAAAA---- ----AAAAAAAAAAAAAAAAA---- ----AAAAAAAAAAAAAAAAA---- ----AAAAAAAAAAAAAAAAA---- ----AAAAAAAAAAAAAAAAA---- -----AAAAAAAAAAAAAAA----- -----AAAAAAAAAAAAAAA----- ------AAAAAAAAAAAAA------ -------AAAAAAAAAAA------- ---------AAAAAAA--------- ------------------------- ------------------------- ------------------------- ------------------------- ------------------------- ------------------------- ------------------------- 
------------------------- ------------------------- ------------------------- ------------------------- ------------------------- ----------AAAAA---------- --------AAAAAAAAA-------- -------AAAAAAAAAAA------- ------AAAAAAAAAAAAA------ ------AAAAAAAAAAAAA------ -----AAAAAAAAAAAAAAA----- -----AAAAAAAAAAAAAAA----- -----AAAAAAAAAAAAAAA----- -----AAAAAAAAAAAAAAA----- -----AAAAAAAAAAAAAAA----- ------AAAAAAAAAAAAA------ ------AAAAAAAAAAAAA------ -------AAAAAAAAAAA------- --------AAAAAAAAA-------- ----------AAAAA---------- ------------------------- ------------------------- ------------------------- ------------------------- ------------------------- ------------------------- ------------------------- ------------------------- 
------------------------- ------------------------- ------------------------- ------------------------- ------------------------- ------------------------- ------------------------- ---------AAAAAAA--------- --------AAAAAAAAA-------- -------AAAAAAAAAAA------- -------AAAAAAAAAAA------- -------AAAAAAAAAAA------- -------AAAAAAAAAAA------- -------AAAAAAAAAAA------- -------AAAAAAAAAAA------- -------AAAAAAAAAAA------- --------AAAAAAAAA-------- ---------AAAAAAA--------- ------------------------- ------------------------- ------------------------- ------------------------- ------------------------- ------------------------- ------------------------- ------------------------- ------------------------- ------------------------- 
------------------------- ------------------------- ------------------------- ------------------------- ------------------------- ------------------------- ------------------------- ------------------------- ------------------------- -----------AAA----------- ----------AAAAA---------- ---------AAAAAAA--------- ---------AAAAAAA--------- ---------AAAAAAA--------- ----------AAAAA---------- -----------AAA----------- ------------------------- ------------------------- ------------------------- ------------------------- ------------------------- ------------------------- ------------------------- ------------------------- ------------------------- ------------------------- ------------------------- ------------------------- 
