model
size = 32, scale = 0.05, origin = -y
material 
  colors = A:#887C7C B:#5D0808 C:#FFF D:#553E3E E:#770505 F:#D11111 G:#7C001C H:#4F0005 I:#430B0B J:#2A0E0E K:#FF3B3B L:#900202 M:#3B1501 N:#200000 O:#FF938F P:#FF7F75 Q:#A00 R:#069E1D S:#100 T:#710016 U:#DE0000 V:#A7F597 W:#2DD209 X:#FF6B5A
voxels
360-2R13-2R14-R2SR11-R2SR13-WCSR11-WCSR14-VR13-VR879-CX13-2C14-4C11-4C12-6C9-6C11-6C9-6C12-4C11-4C14-2C13-2C846-F3C11-O3C13-5C9-O5C11-6C9-6C11-6C9-5CF12-5C10-4CO12-3CO11-4C845-F3C11-K3C12-K5C9-O5C11-5CO9-6C11-6C9-5CF11-O4CO9-6C12-K3C11-4C121-A2B27-A31-2AB2(30-2A)595-F2CK11-KCFK12-2F3CO9-F4CK11-5CO9-5CF11-F5C9-5CF11-EF4C9-T3CO14-KC3-M2-MN5-2C18-NMDB29-D4-4A19-AD4AB-B6AB16-3AG2AB-2BE5A17-A-B2E2-BA3BA21-3A2-B3ABAB20-3AB-2B2A2BA20-2LB3-B2A30-LB563-2FCK11-KFPK12-F4CK9-F4CF11-O4CO9-K4CO11-L4CK2-I6-4COL11-E-F2CK-2MIMN3-K2CT15-P2F-NAI-BAN3-KTK18-D2AI2-ANBS19-DNM2(DA)I-6A16-B6ABID6AEA14-4AB3AID6A17-2AE3A2-I6A16-A3B3AB2-7A15-2A2B3AB2-4AB3A15-2A-3AB-B4A-2A17-5A2-E2BAB21-2AE3-LA-A453-Q31-F45-4F11-KFPF12-F4CO9-E4CL11-L4CO3-I5-K4CO11-L4CK2-DIM4-K3CFK12-P3CP-DA-DM3-K2CK15-P2C-S2AIDAD3-KCK16-2N3A3-2ABSN-N14-AB6AB-D6ABA13-8AB-D9A12-9AB7A2B13-2B6AB-I8A13-8AB-I9A13-7AB-I9A13-2AB4AB-B4AB3A15-6AB-B4AB-A18-2AEBA-BABEAB20-5A-L3A23-A-A3-3A25-A204-U2(31-F)31-2(Q30-F)G30-FG13-F16-F13-4F11-KFCF12-F4CK3-I5-K4CL11-L4CP3-2I4-E4CL11-P4CP-2M2HN3-K4CL11-E4CP-DAHAB3-K2CK-M12-E3CN3A-HA2B2-K2CK13-2N2B3AB2-3AMANA2N12-D7AB-D10A10-B8AB-I10A10-9AB-8AB12-B8AB-I8AE2(12-8AB-10A)13-7AB-B9A14-6AB-B4AB3A16-6A-B4A-BA18-B4A-B3AB2-A21-BA-L4A24-A4-2A277-2(F31-)F30-2F-F28-2F-F27-O3FK9-EPFCF12-P4CP8-E5CL11-P4CP9-E4CL10-L5CP-HM-HB3-D4CM11-P5CD2AI2AB2-D3CBM12-T3C4A-D2AB-M3AM11-DNA2B4AB2-3AB6A10-D8AB-H10A10-D8AB-I8AB11-9AB-8AB12-9AB-I8ABA10-B8AB-I8A12-9AB-B9A12-9AB10A13-AB6AB7AE15-A2(-B4AB)2A16-L-BAB2A-I3AB-2A19-B-BA-E4A2-A21-B4-BA31-A356-F15-FOF10-E4F13-T2CFK8-HECFCE11-LF4CK8-E4CT11-L5CP8-HA4CF10-L5CP2(-HD)3-D5A10-D6C3AI2ABM-D4AMA10-D4C4AI-3AN4AM-B9-D8AB2-8AB10-10AB-H8A11-11A2(-4A)11-10AB-8AB-2A8-10AB-I11A10-B7AB-I8A2E11-B7AB2-7AB13-2B7A-7AB14-B-B5AB-7AE16-B5AB-B8A15-EB4A2-I3A2B2A18-2AB2A-B4AB2A19-2(A2-)2BA2-2A22-A4-A308-2(F31-)FO11-3E14-EF2CFK7-HF3A2E11-L2C4A2-I4-H6AQ10-L2C4A7-H7A9-D5A2C2HD-HD2BN7A8-D4A3C3AI4AM6AB8-AD8ABI-8A2BG9-9ABIH2A4-2AB-B8-B4A3-3A-D2A4-AB11-D4A3-3AD2A5-AB-B9-D4A3-3AB2A5-2AE2A8-11AB3A3-6A8-2B8AB-B11A11-B6AB-B7AEAE13-B6A-B7A2-B13-B5AB-8AE15-B5AB-B8A14-AB5A2B9A15-E6A2B2ABAB2A18-5A2-ABA2-2A19-2A-A-BA-E314-F24-2F5-Q24-4E3-QE4-F4E13-EC3AB7-H4A2EQ10-D6AH-I3-H8AQ8-D7AH3-I2-H7AB8-D6ACBHDIHDH8AB7-D11AJ13A6-12AID4A4-4A6-AB3A5-ABI7A3-B2A8-3A2-5AD7A-2AEA8-4A2-2A2-8A2-2AB8-B4A2-2A2-3A-4A-3AB8-6A2-A2-4A-2A2-2AB9-8A-3AB3A3-5A9-LA2-7A-11A10-A3-6A-9AEB14-6A-9A13-3B5AB-B8A13-9A-10A13-AB11A2B3A16-EB4A2B3A2-2A18-5A2-A2BQ22-2A-A-BA220-U31-F12-U18-F12-F13-F4-FE11-F10-D4E3-FE4-H4E2FQ9-D5ABJ2I4-H7AQ8-D7AD2I3-H9A8-D8AJI-J-H9AB7-D8AHDIAD10A7-12AJ6A2-5A6-4A2-2A-3AJ7A2-5A5-3A2-5A-AD8A2-4A5-4A-5A-10A2-2BA7-9A2-2A-7AB9-B4A2(-4A2-2A)9-6A-2A3-2A-3A2-3A-B7-B5A-2A2-4A-2A-5AEB6-3A2B12A-5A2B8-LA3B6A-9AB-B10-A-B6A-B8A14-B7A-B8AE13-8A2-8A14-A2B10A2B3A18-4A2B3AE-2A18-B4A2-2ABEL20-5A2-2A25-A67-2(U31-)4(F31-)2F26-F3-QF2-I2B2-2F11-D4E-F3-2Q2-HAFE3AF8-2D5ABJ2HI2H-H3AE4A7-D8A2D2IH-J9AG6-D9A-DIH-H9AG6-D9AH2DAD9AG6-D6A-5A-B-3A3-5AB4-D4A-7AJ7A2-5A4-4A-7A2J-7A2-5A4-2A2-7A2-8A2-3A7-9A4-7A-2AB7-B9A2-2A-5A-4A2G5-5A-4A2-2A-4A-6AB5-6A-2A3-2A-3A2-5A7-B6A-A-13ABA8-L2A2B6A-9ABA13-B6A2B8A2BA11-B7A-8AE-A11-9A-8AB13-3AB11A3BA14-2A-E10A2-A18-B4A2B4AE20-5A2-4A22-3A289-2J5-B14-3D2E3-2JH2J2-IDA-D2AFG7-D5A2DJD3AJ2-3AD3ABF6-D8AD4A-JH9A6-D9A2-A2-H11A5-10AHD2AJ3A2-5AE5-B25AG5-28A4-4A-24A3-4A-17A-3AB2A4-B20A-3AB5-E4A-5A2-A-6A-5AB4-6A-4A2-2A2(-5A)B6-9A2-2A-4A-7A6-B7A-8A-7A8-4B6AB13A11-B19A12-B15A2(BA)11-2B6A-6ABA-BA11-2AB6A-5AE-B14-2A2-11AE19-2B5AB3AEA21-4AB-4A22-2A-A2-A283-I23-3D4-BI2-J4-D2-2D2A8-D3A2DB-J2I3J-J-A2D3AB7-B7AB6J-H8A6-11A4-J-11A4-6A-5A2-2J5A-6A4-B8A-17AG3-14A-15A2-14A-16A2-D3A2(-8A)-2ABE3A2-B3A-17A-2AG6-5A-21AB4-11A2-2A-5A-6A4-AB9A2-2A-4A-7A6-B2AB4A-8A-6AG8-BA2-6AB10AB2AG7-BA2-6A2-9AB2A8-B2A-19A13-6A2-7AB2A13-B6A2-7A2B15-2B13A19-5AB6A22-3A-4A25-AB-2A216-F30-4FD2ID25-FI3H2ID3-D14-2D5-D3H2ID2J6-A7-B3A3D2-AD3AHD-I2-D-D3A6-B6A2BAE3A2HJA2DAD4A5-11AD2-J2H11A3-7A-5AD-AD2(5A-)A3-D5A3-9A3-6AG3-14A-15A2-31A-AB29A3-21A-3AG5-22A-4AG4-11A2-A2-5A-6AB3-11A2-2A-12A4-B27A5-B25AG6-B10A2-9A-G9-B19A13-AB-B5A2-8A13-2B17A14-17A16-A2B12A20-2B3AB4A25-AB-3A119-2(F31-)F4-B26-2F5D26-2D4AD24-BH6AD2-DFG18-D7A2HD2B3-A7-DA2D-D3-7A2-2B-D-3A5-B4ADA2D-7AJ-7AG5-9AD2AD4AB11A2-28A-A3-D4A4-10A3-6A3-31A-30A2-31A-AB22A-AB2-A3-B24AB5-16A-13A3-11A-4A-12A3-10A-9A-6AB5-B12AB14A5-B10A2-8AB-BA8-B10A-8A2B11-B8A2-6A3B13-15AB16-14A2B18-12A21-3ABA2BA-2B23-A-A2-A126-D28-5DB26-3DAD4-DA17-D3-D4AD-4D17-D2-D6A2DH17-5D8A2H4D14-3D13A3-A7-D2A-D-2D-7AHDA2B6A5-D2AD3A-9A2-6AG5-27AG3-29A4-5A2-11A-A3-5A3-B13A-16A-14A-31A-16A-AB12A-9A-A-EB2A2-B25AG4-12A-3A2-11AB2-12A-17A3-10A-9A-5AB5-B13AB10AB7-B12A-9AB9-12A-10A11-B8A2-9AB13-B14ABAB15-B9A4BA18-A2B5AB2-3A21-BA2BA28-A2-A60-EDE29-EDEB28-EDAB27-D4AD20-3D3-D4A-3D5A10-4DA3D6AD4AD2A10-4D2AD10A3D2A10-2D20A11-AD17A-A8-20A2-3AG5-B18A-6AG5-17A-9AG3-28AB3-B6A-14A-6A3-I14AB62A2-40A2-2AEA3-B26A5-10A2-4A-11AB2-11A-18A3-14AB11A2BA3-14A-10A3B5-B12A-11AB8-11A-11A9-B9A2-8ABA11-2B8AB7AB15-2B14A18-B2AB3AB-B3A20-AB-4B-B2A24-2(A2-)A24-AED2A2(27-D3AB)27-D4A24-2D-D3AB-2D-D2A12-A6D-D4AD8A9-11A-12A8-11A3-10A8-10A3-11A9-D22A7-20A2-3AG6-18A-7A5-B7A-3A3-13A3-14A-14A3-B6A-6A3-5A-6A3-I6A-4A6-3A2-22A4-31A-12A3-17A-10AE4-B9A2-5A-9A4-11A-10A-6AB2-2(B14A)3-B12A2-B11ABA3-B12A2-11AB6-B12A-11AB7-11AE-7AB-B2A8-B9A2-6AB3-A10-2B8A-7AB15-7AEB5AB18-A2BA3B-2B2A2B21-B3-B2-2A30-A25-A-D2A27-AD2A29-2A30-3AG21-A2-D2A3-GABD6A10-5AD4A3-10A8-2(25A7-)25A8-25A6-20A2-3AG6-18A2-6A5-B7A2(-9A)4-29A3-6A-5A4-5A-6A3-B6A2-5A3-4A2-17A2-11A2-18A3(-10A)-8A-11A3-8A2-7A-8AB4-9A-17AB4-2(B13A)4-B12A2-B13A3-14A-11AE6-12AE-12A7-11AE-6AB-2B2A8-AB8AB-6AB3-BA10-B7AB-8A15-7AB-B2A2BABA16-AB4A2-3AB24-2AB-B2A30-2A58-DA29-3A30-2A23-2A2-D2A3-G2D5A11-6AD16A8-3(25A7-)E24AG6-20A2-3AG6-6A-11A2-6A5-8A-9A2-8A4-29A3-12A4-12A3-B7A-5A3-4A-2(8A2-)5A-4A3-8A-8A3-9A3-8A-9A2-3AEB4A2-8A2-B9A-3A2B14A3-14AB14A3-14A-12ABA3-B13A-11A2BA4-12AB-B11A6-12AB-10ABA7-11AB-7ABA2BA8-10A2-6AB2-3A9-2B7AB-8A15-3AB3AG-3A-2ABA17-B-3AE-BAB25-3A-2A31-A59-D31-A32-A23-4A-A4-G-5A13-9ABAG9A10-23A8-2(25A7-)G24A7-G18A2-3AG7-18A-7A5-17A2-9A4-16A-12A3-12A5-12A2-B7A-5A3-12A3-8A2-4A2-5A-2(8A2-)5A-5A2-7A2-9A-4A2(2-14A2-B13A)2-13AB3-B12AB-12A5-13AB-11A6-B12AB-B10A2B5-B11A3-8AB-B7-11AB-5A5B10-10AB-6A16-B7AB-9A14-3A2B2AG-2AB2A2-A21-A2-BA31-A180-6A5-5A14-8AD3-8A11-12AB9A10-23A8-24A9-G22AB8-18A2-3AG8-6A-9A2-7A5-27A5-12A4-11A5-13A3-12A4-13A2-13AG2-B14A-12AG3-8A3(-6A)3-B13A2-14A3-B12A2-13A4-B12A2(B-12AB4-13A)2-10A2B6-B11AB-B8ABA7-B11AB-5AB3AB9-11AB-4A2-3BA11-AB7AB-6A17-E6AG-7A17-A-BE2AE-5A23-2A3-BA30-A182-4A5-4A16-8A3-G7A12-9A2B-8A11-22A10-22A11-G20AB9-23A10-G13A-8A7-11A4-11A6-G11A2-12A5-14A-11AG5-2(14A-12AG4-)B13A-12AG5-12AB-11AG5-2B11AB-12AB4-B12A2-12AB5-E11A2-12A6-E11A2-12A7-11AB-8A4B7-2B9AB-5A2BA2B10-10AB-3AE3-2B14-2B5AB-5A19-E5AG-5A22-2BA2-AB2A29-2A213-A9-3A17-6AB4-6A14-8A3-8A13-8AB2-B8A11-2B8A2-8A12-E9A2-9A11-G9A2-9AB10-G7A-A2-11A2(8-G11A-10AG)8-12A-11AG2(5-13AB-12A)5-B12AB-13A5-B11AB-12A7-11AB2(-12A6-12AG)-12A7-11AG-9AB2A7-11AE-4A2B2AB2-B9-B3AB4AB-4A2-2B14-A3B4AB-3AB22-4AG-4A23-3A2-2BA26-B281-2A8-4A17-4ABA6-6A13-3A3BAB4-7A14-3B3AB4-AB5A14-7A4-7AB12-10A-8AB11-11A-9AG10-AE9AB9AG9-A2B9A-10A9-AB10A-10A9-B-10A-11A7-2B-9AB-11A7-3B9AB-11A8-B11A-11A10-B8A2-B9A10-10AB-10A9-12A-8A2B10-10AB-8AB11-A2B8A-4A2-2A15-2A-B3AB-2A3B21-B3AB-2B2-B22-3AB-BA27-B346-A9-A-3A15-2A10-B4A18-BEB-2A-AB-4A16-8A-5ABA15-16A2B13-10AG9A13-9AB2(9A13-9A-)9A11-B10A-11A9-11AB11A10-B9AB10A9-B-B8AG-10A9-A2-8AB-7A3B11-B8A2-7A2B12-10A-B7A14-9A-7A16-4B3AB-3A2B22-2BA2-BA2B24-2A479-2B-AB-2BA19-2B2(4AB)19-2B2(5AG)16-A2B5AG-5A2G2(15-2B7A-6AG)15-AB15AG13-AB8AB4AB3A-A11-A2B6AB-4AB3A13-2AB6AB-4AB3A13-BA2B5AB-4A2B3A12-4B5AB-5AB17-2B5A2-E4A2B16-3A3BE6-2A19-2A2BA2-A3B23-2BA2-B2A26-2B540-4B2-A-A22-B4A-B3A22-5A-B4A19-2B5AB5A19-B5A2B6A18-2B5AB3ABEA18-2AG3AEB3AB-A18-6A2-B3A-EA17-6A2-B3A-BA18-AB3A3-3A23-3A3-4A20-2B3AB2-3A727-3AB2-B2A23-3AG-AB2A22-4AB-A2BA22-4AB-2AB24-G2AB-3AB21-5AB2-3B21-5A4-2A22-4A4-2A23-3A3-2A25-A370-
