model
size = 26 32 20, scale = 0.05, origin = -y
material 
  colors = A:#FFF B:#000 C:#FFC9DF
voxels
376-2A23-4A23-2A752-2A23-2(4A22-)4A23-2A726-2A22-2A2-2A20-2A2-2A21-A2-A22-4A23-2A24-2A544-2C24-2C22-2B2A2B21-4B22-A2BA21-6A19-3A2-3A18-3A2-3A19-2A2-2A21-A2-A22-4A23-2A24-2A336-6(2B24-)2B22-6C19-2B4A2B18-B6AB18-3A2-3A19-6A19-2(3A2-3A18-)2A4-2A19-2A2-2A20-2A2-2A21-A2-A22-4A23-3(2A24-)2A22-2B2A2B19-B6AB19-A4-A-A150-2B23-4A21-AB2-BA20-2B2-2B20-AB2ABA21-4A2(22-B2AB)20-8C17-2(B8AB16-)3(3A4-3A16-)2A6-2A14-4A6-4A12-2C3A4-3A2C12-3C3A2-3A3C14-C3A2-3AC19-A2-A3(22-4A)20-8A16-2AB6AB2A13-A2B8A2BA11-3B10A3B11-14A12-14A16-6A73-4A21-6A19-2(3A2-3A18-)3A2-3A19-6A20-6A19-CBA2-ABC17-4C2-4C15-B2A6-2AB13-2B2A6-2A2B12-B3A6-3AB12-4A6-4A13-3A6-3A12-5A6-5A9-6A6-6A8-ACA-2A6-2A-ACA8-2C2A-2A4-2A-2A2C9-3C4A2-4A3C12-5A2-5A17-2A2-2A20-6A19-3A2-3A16-5A2-5A12-6A4-6A10-4A8-4A9-B16AB8-6A6-6A9-16A11-14A13-12A16-8A20-4A20-3A2-3A18-2A4-2A17-3(3A4-3A16-)4A2-4A16-C2A4-2AC15-3C6-3C14-2A8-2A13-BA10-AB12-BA10-AB11-4A8-4A10-4A8-4A9-4A10-4A8-3A12-3A7-3A14-3A6-3CA12-A3C7-C5A6-5AC9-2C4A4-4A2C12-5A2-5A16-3A2-3A17-3A4-3A13-5A6-5A9-4A10-4A8-3A12-3A7-B2A14-2AB6-4A12-4A7-4A10-4A8-7A4-7A9-5A-4A-5A11-14A16-A4-A19-2A4-2A17-2A6-2A16-2A6-2A15-3A6-3A14-3A6-3A13-4A6-4A12-3A8-3A11-4A8-4A11-2A10-2A11-2A12-2A2(10-BA12-AB)9-3A12-3A7-3A14-3A3(6-2A16-2A)6-C2A14-2AC6-2C4A8-4A2C7-6A6-6A13-2A4-2A14-5A6-5A9-5A8-5A7-3A14-3A6-BA16-AB5-3A16-3A5-2(2A16-2A6-)4A12-4A7-4A10-4A9-4A8-4A40-A6-A17-2A6-2A16-A8-A15-2A8-2A13-3A8-3A13-2A8-2A12-3A10-3A11-2A10-2A11-2A12-2A9-3A12-3A2(8-BA14-AB)7-2(2A16-2A6-)A18-A5-2(2A18-2A4-)CA18-AC5-C2A14-2AC6-5A10-5A32-5A10-5A6-3A14-3A6-2A16-2A5-BA18-AB2(4-2A18-2A)5-A18-A6-2A16-2A6-3A14-3A7-3A12-3A38-A8-A16-A8-A15-2A8-2A14-A10-A13-2A10-2A2(12-A)11-2A12-2A10-A14-A9-2A14-2A8-2A14-2A7-3A14-3A6-BA16-AB6-2A16-2A6-A18-A5-2A18-2A2(4-A20-A)4-C20-C4-CA18-AC4-3A16-3A5-2A16-2A6-3A14-3A5-2A18-2A4-BA18-AB4-2A18-2A2(4-A20-A)2(4-2A18-2A)5-2A16-2A6-2A16-2A62-2A8-2A14-A10-A13-2A10-2A2(12-A)11-2A12-2A10-A14-A9-2A14-2A8-A16-A7-2(2A16-2A6-)B18-B6-A18-A5-2A18-2A2(4-A20-A)3-2(2A20-2A2-)2A20-2A3-4(2A18-2A4-)A20-A3-2A20-2A2-2A20-2A3-2(A20-A4-)2A18-2A4-2A18-2A5-A18-A62-A10-A13-2A10-2A2(12-A)11-2A12-2A10-2A12-2A9-2(2A14-2A8-)A16-A7-2A16-2A6-A18-A5-2(BA18-AB4-)A20-A4-A20-A3-2(2A20-2A2-)A22-A10(2-2A20-2A)3-2(A20-A4-)2A18-2A86-A12-A11-2A12-2A10-A14-A9-2A14-2A8-2A14-2A7-2(2A16-2A6-)A18-A5-2(2A18-2A4-)A20-A4-A20-A3-2(2A20-2A2-)4(A22-A2-)3(2A20-2A2-)4(A22-A2-)2(2A20-2A2-)2A20-2A3-A20-A111-2A12-2A10-A14-A9-2A14-2A7-2(2A16-2A6-)A18-A5-2(2A18-2A4-)A20-A3-2(2A20-2A2-)2(A22-A2-)A22-A-2A2(22-4A)22-2A-9(A22-A2-)2A20-2A2-2A20-2A110-A14-A9-2A14-2A8-A16-A7-2A16-2A6-A18-A5-2(2A18-2A4-)A20-A3-2(2A20-2A2-)2(A22-A2-)A22-A-2A11(22-4A)22-2A-2(A22-A2-)2A20-2A135-A16-A7-2A16-2A6-A18-A5-2(2A18-2A4-)A20-A3-2(2A20-2A2-)A22-A2-A22-A-2A4(22-4A)22-3A24-2A24-3A8(22-4A)22-2A-A22-A185-2(2A18-2A4-)A20-A3-2A20-2A2(2-A22-A)-2A4(22-4A)22-3A6(24-2A)24-3A6(22-4A)22-2A210-A20-A3-2A20-2A2(2-A22-A)-2A3(22-4A)22-3A15(24-2A)24-A287-A22-A-2A22-4A22-3A13(24-2A)24-A104-
