model
size = 31 27 15, scale = 0.05, origin = -y
material 
  colors = A:#E0BEA5 B:#946A6A C:#FDEFDA D:#FFF E:#887C7C F:#FCE0B6 G:#774949 H:#553E3E
voxels
------------------------------- ------------------------------- ------------------------------- ------------------------------- ------------------------------- ------------------------------- ------------------------------- ------------------------------- ------------------------------- ------------------------------- --------------CCC-------------- --------------CC--------------- ------------------------------- ------------------------------- ------------------------------- ------------------------------- ------------------------------- ------------------------------- ------------------------------- ------------------------------- ------------------------------- ------------------------------- ------------------------------- ------------------------------- ------------------------------- ------------------------------- ------------------------------- 
------------------------------- ------------------------------- ------------------------------- ------------------------------- ------------------------------- ------------------------------- ------------------------------- ------------------------------- ------------------------------- -----------BABCCAA------------- ----------FCCCAAACCC----------- -------------BAADD------------- ------------------------------- ------------------------------- ------------------------------- ------------------------------- ------------------------------- ------------------------------- ------------------------------- ------------------------------- ------------------------------- ------------------------------- ------------------------------- ------------------------------- ------------------------------- ------------------------------- ------------------------------- 
------------------------------- ------------------------------- ------------------------------- ------------------------------- ------------------------------- ------------------------------- ------------------------------- ------------------------C------ ------AFF----------------B----- -----CCCC--FFB-DDDDCCC--CC----- ------AAC-FAAFDAAAAACCCCFF----- -----------BB-BBBBABAE--------- --------------CCCC------------- ------------------------------- ------------------------------- ------------------------------- ------------------------------- ------------------------------- ------------------------------- ------------------------------- ------------------------------- ------------------------------- ------------------------------- ------------------------------- ------------------------------- ------------------------------- ------------------------------- 
------------------------------- ------------------A------------ ------------------CA----------- ---------------------A--------- --------------------FC--------- ---------------------CCA------- ----------------------BCA------ ----------------------BBBA----- -----AD------------------------ --A--AADF------------ACEEFC---- -----EEEE-FFBBAAAAADDFFFAACE--- ------------------B-BB---BBB--- ------------------------------- ------------------CC----------- ------------------------------- ------------------------------- ------------------------------- ------------------------------- ------------------------------- ------------------------------- ------------------------------- ------------------------------- ------------------------------- ------------------------------- ------------------------------- ------------------------------- ------------------------------- 
------------------------------- ----------------CCD------------ ----------------FFFA----------- ------------------B--A--------- --------------------BAD-------- --------------------BBDD------- ----------------------BDD------ -------------------------C----- --D---------------------------- -DAE-AD------------------EFC--- ----------------------FDDDBAE-- --------------------------BAG-- --------------------------BBG-- ------------------AACBCDDE----- --------------BCCCCDDDDA------- --------------BDDDCC----------- -------------DBCC-------------- ------------------------------- ------------------------------- ------------------------------- ------------------------------- ------------------------------- ------------------------------- ------------------------------- ------------------------------- ------------------------------- ------------------------------- 
--------------DF--------------- --------------CFDD------------- ------------------------------- ------------------------------- ---------------------D--------- ------------------------------- ------------------------------- ------------------------------- ------------------------------- DD-------------------------FE-- ---------------------------BFG- --------------------------BBAGG ----------------------BBBBBAAH- ------------------DDBBAAEEEGGG- ---------------FFAAAAACE------- -----------DDD-BAAAFCE--------- ----------DCDA-BACB------------ -------------E-A--------------- ------------------------------- ------------------------------- ------------------------------- ------------------------------- ------------------------------- ------------------------------- ------------------------------- ------------------------------- ------------------------------- 
------------------------------- ------------------------------- ------------------------------- ------------------------------- ------------------------------- ------------------------------- ------------------------------- ------------------------------- ------------------------------- ------------------------------- ------------------------------- ----------------------------BBE ---------------------------BDAH ----------------------AEE-BBAAH -----------------DDCCCE-----BG- --------D-BFDD-BAB----------G-- ------CCADBFAB-BBB-----ACG----- ----------BBEE--------C-------- ------------------------------- ------------------------------- ------------------------------- ------------------------------- ------------------------------- ------------------------------- ------------------------------- ------------------------------- ------------------------------- 
------------------------------- ------------------------------- ------------------------------- ------------------------------- ------------------------------- ------------------------------- ------------------------------- ------------------------------- ------------------------------- ------------------------------- ------------------------------- ------------------------------- -----------------------------D- ----------------------------BBB ----------------------------BAH ----BAADD-----------------BBAG- ----CCAAAB-------------AADGGGB- ------DCC-------------ACBB----- ------------------AACCCC------- --------------AABCCCCA--------- --------------CCCC------------- ---------------A--------------- ------------------------------- ------------------------------- ------------------------------- ------------------------------- ------------------------------- 
------------------------------- ------------------------------- ------------------------------- ------------------------------- ------------------------------- ------------------------------- ------------------------------- ------------------------------- ------------------------------- ------------------------------- ------------------------------- ------------------------------- ------------------------------- ------------------------------- -----------------------------AE --B--DD---------------------EAH --C-DAAA----------------DDDDAAB ----EE----------------DDBBBBBB- -----------------AAAADAAB------ -------------FAABAAAAAB-------- -------------CAAAABBA---------- --------------AE-A------------- ------------------------------- ------------------------------- ------------------------------- ------------------------------- ------------------------------- 
------------------------------- ------------------------------- ------------------------------- ------------------------------- ------------------------------- ------------------------------- ------------------------------- ------------------------------- ------------------------------- ------------------------------- ------------------------------- ------------------------------- ------------------------------- ------------------------------- ------------------------------- DD---------------------------DE -AB-AA----------------------EDA ----------------------DB----EAB ------------------DDBBBB-----B- -------------FAABBBBBB--------- -----------BFAAABB------------- -------------EEE-E------------- ------------------------------- ------------------------------- ------------------------------- ------------------------------- ------------------------------- 
------------------------------- ------------------------------- ------------------------------- ------------------------------- ------------------------------- ------------------------------- ------------------------------- ------------------------------- ------------------------------- ------------------------------- ------------------------------- ------------------------------- ------------------------------- ------------------------------- ------------------------------- ------------------------------- ------------------------------E -----------------------------DE ----------------------------BE- --------------------------BBBE- -------AAA--FDAA-------EECBE--- ------CCCC-----------CCCCE----- ------------------ACCCAA------- ------------------CCA---------- ------------------------------- ------------------------------- ------------------------------- 
------------------------------- ------------------------------- ------------------------------- ------------------------------- ------------------------------- ------------------------------- ------------------------------- ------------------------------- ------------------------------- ------------------------------- ------------------------------- ------------------------------- ------------------------------- ------------------------------- ------------------------------- ------------------------------- ------------------------------- ------------------------------- ------------------------------- ------------------------------- -----AAADB--------------------- -----CAAEB------------DDBE----- ------CE----------FFFBBB------- -----------------BAABB--------- ----------------FC-E----------- -------------CBC--------------- ------------------------------- 
------------------------------- ------------------------------- ------------------------------- ------------------------------- ------------------------------- ------------------------------- ------------------------------- ------------------------------- ------------------------------- ------------------------------- ------------------------------- ------------------------------- ------------------------------- ------------------------------- ------------------------------- ------------------------------- ------------------------------- ------------------------------- ------------------------------- ------------------------------- -----FFF----------------------- --AC-FEE----------------------- ------E------------------------ ------------------FB----------- ---------------DFB------------- ------------ADBC--------------- ----------CCCE----------------- 
------------------------------- ------------------------------- ------------------------------- ------------------------------- ------------------------------- ------------------------------- ------------------------------- ------------------------------- ------------------------------- ------------------------------- ------------------------------- ------------------------------- ------------------------------- ------------------------------- ------------------------------- ------------------------------- ------------------------------- ------------------------------- ------------------------------- ------------------------------- ------------------------------- -DDC--------------------------- ------------------------------- ------------------------------- ------------------------------- ------------------------------- ----------BDD------------------ 
------------------------------- ------------------------------- ------------------------------- ------------------------------- ------------------------------- ------------------------------- ------------------------------- ------------------------------- ------------------------------- ------------------------------- ------------------------------- ------------------------------- ------------------------------- ------------------------------- ------------------------------- ------------------------------- ------------------------------- ------------------------------- ------------------------------- ------------------------------- ------------------------------- ------------------------------- ------------------------------- ------------------------------- ------------------------------- ------------------------------- -------DF---------------------- 
