model
size = 31 25 15, scale = 0.05, origin = -y
material 
  colors = A:#FDEFDA B:#E0BEA5 C:#946A6A D:#FFF E:#887C7C F:#FCE0B6 G:#774949 H:#553E3E
voxels
------------------------------- ------------------------------- ------------------------------- ------------------------------- ------------------------------- ------------------------------- ------------------------------- ------------------------------- ------------------------------- --------------AAA-------------- --------------AA--------------- ------------------------------- ------------------------------- ------------------------------- ------------------------------- ------------------------------- ------------------------------- ------------------------------- ------------------------------- ------------------------------- ------------------------------- ------------------------------- ------------------------------- ------------------------------- ------------------------------- 
------------------------------- ------------------------------- ------------------------------- ------------------------------- ------------------------------- ------------------------------- ------------------------------- ------------------------------- -----------CBCAABB------------- ----------AAAABBBAAA----------- -------------ABBDD------------- ------------------------------- ------------------------------- ------------------------------- ------------------------------- ------------------------------- ------------------------------- ------------------------------- ------------------------------- ------------------------------- ------------------------------- ------------------------------- ------------------------------- ------------------------------- ------------------------------- 
------------------------------- ------------------------------- ------------------------------- ------------------------------- ------------------------------- ------------------------------- ------------------------A------ -------------------------C----- -----AAAA--FFC-DDDDAAA--AA----- ------BBA-ABBFDBBBBBAAAAFF----- -----------AA-CCCCBCBE--------- --------------AAAA------------- ------------------------------- ------------------------------- ------------------------------- ------------------------------- ------------------------------- ------------------------------- ------------------------------- ------------------------------- ------------------------------- ------------------------------- ------------------------------- ------------------------------- ------------------------------- 
------------------B------------ ------------------AB----------- ---------------------B--------- --------------------FA--------- ---------------------AAB------- ----------------------CAB------ ----------------------CCCB----- ------D------------------------ --BF-BBDF------------BAEEFA---- -----AAAE-AAAAAABBBDDFFFBBAE--- ------------------C-CC---CCC--- ------------------------------- ------------------AA----------- ------------------------------- ------------------------------- ------------------------------- ------------------------------- ------------------------------- ------------------------------- ------------------------------- ------------------------------- ------------------------------- ------------------------------- ------------------------------- ------------------------------- 
---------------FAAD------------ ----------------AAFB----------- ------------------A--B--------- --------------------CBD-------- --------------------CCDD------- ----------------------CDD------ -------------------------A----- --DF--------------------------- -DBE-BA------------------EFA--- ----------------------FDDDCBE-- --------------------------CBG-- --------------------------CCG-- ------------------BAACADDE----- --------------CAAAADDDDB------- --------------CDDDAA----------- -------------DCAA-------------- ------------------------------- ------------------------------- ------------------------------- ------------------------------- ------------------------------- ------------------------------- ------------------------------- ------------------------------- ------------------------------- 
--------------AADD------------- ------------------------------- ------------------------------- ---------------------D--------- ------------------------------- ------------------------------- ------------------------------- ------------------------------- DD-------------------------FE-- ---------------------------CFG- --------------------------CCBGG ----------------------AAACCBBH- ------------------DAAABBEEEGGG- ---------------FFBBBBBAE------- -----------DDD-CBBBFAE--------- -----------ADB-CBAC------------ -------------E-B--------------- ------------------------------- ------------------------------- ------------------------------- ------------------------------- ------------------------------- ------------------------------- ------------------------------- ------------------------------- 
------------------------------- ------------------------------- ------------------------------- ------------------------------- ------------------------------- ------------------------------- ------------------------------- ------------------------------- ------------------------------- ------------------------------- ----------------------------CCE ---------------------------CDBH ----------------------AAE-CCBBH -----------------AAAAEE-----CG- -----------FDD-AAC----------G-- ---------DCFBC-CCC-----EEG----- -----------CEE--------A-------- ------------------------------- ------------------------------- ------------------------------- ------------------------------- ------------------------------- ------------------------------- ------------------------------- ------------------------------- 
------------------------------- ------------------------------- ------------------------------- ------------------------------- ------------------------------- ------------------------------- ------------------------------- ------------------------------- ------------------------------- ------------------------------- ------------------------------- -----------------------------D- ----------------------------CCC ----------------------------CBH --------FA----------------AABG- ---------C-------------ABDGGGC- ----------------------BACC----- ------------------BBAAAA------- --------------BBCAAAAB--------- --------------AAAA------------- ---------------B--------------- ------------------------------- ------------------------------- ------------------------------- ------------------------------- 
------------------------------- ------------------------------- ------------------------------- ------------------------------- ------------------------------- ------------------------------- ------------------------------- ------------------------------- ------------------------------- ------------------------------- ------------------------------- ------------------------------- -------B----------------------- -------FF--------------------BE ---------EA-----------------EBH ------------------------AAADBBC ----------------------ADCCCCCC- -----------------BBBBABBC------ -------------FBBCBBBBBC-------- -------------ABBBBCCB---------- --------------BE-B------------- ------------------------------- ------------------------------- ------------------------------- ------------------------------- 
------------------------------- ------------------------------- ------------------------------- ------------------------------- ------------------------------- ------------------------------- ------------------------------- ------------------------------- ------------------------------- ------------------------------- ------------------------------- -----D-A----------------------- -------AA---------------------- --------AA--------------------- -----------------------------DE ----------------------------EDB ----------------------AC----EBC ------------------AAAACC-----C- -------------FBAAACCCC--------- -----------CFBBBCC------------- -------------EEE-E------------- ------------------------------- ------------------------------- ------------------------------- ------------------------------- 
------------------------------- ------------------------------- ------------------------------- ------------------------------- ------------------------------- ------------------------------- ------------------------------- ------------------------------- ------------------------------- ------------------------------- ----AAE------------------------ -----DD------------------------ ------------------------------- ------------------------------- ------------------------------- ------------------------------E -----------------------------DE ----------------------------CE- --------------------------ACCE- -------BBB--FAAA-------EEAAE--- -------AAA-----------AAAAE----- ------------------BAAABB------- ------------------AAB---------- ------------------------------- ------------------------------- 
------------------------------- ------------------------------- ------------------------------- ------------------------------- ------------------------------- ------------------------------- ------------------------------- ------------------------------- ------------------------------- ------------------------------- ------------------------------- ------------------------------- ------------------------------- ------------------------------- ------------------------------- ------------------------------- ------------------------------- ------------------------------- -----ABE----------------------- ------BBAA--------------------- --------EA------------AAAA----- ------------------AAAACC------- -----------------ABBCC--------- ----------------AA-E----------- -------------AAA--------------- 
------------------------------- ------------------------------- ------------------------------- ------------------------------- ------------------------------- ------------------------------- ------------------------------- ------------------------------- ------------------------------- ------------------------------- ------------------------------- ------------------------------- ------------------------------- ------------------------------- ------------------------------- ------------------------------- -----D------------------------- -----AA------------------------ ------BA----------------------- -------F----------------------- ------------------------------- ------------------------------- ------------------AC----------- ----------DD-D-AAC------------- -----------DAACA--------------- 
------------------------------- ------------------------------- ------------------------------- ------------------------------- ------------------------------- ------------------------------- ------------------------------- ------------------------------- ------------------------------- ------------------------------- ------------------------------- ------------------------------- ------------------------------- ------------------------------- ------------------------------- ------------------------------- ------------------------------- ------------------------------- ------------------------------- ------------------------------- ------------------------------- ------------------------------- ------------------------------- --------F---------------------- --------A-AD------------------- 
------------------------------- ------------------------------- ------------------------------- ------------------------------- ------------------------------- ------------------------------- ------------------------------- ------------------------------- ------------------------------- ------------------------------- ------------------------------- ------------------------------- ------------------------------- ------------------------------- ------------------------------- ------------------------------- ------------------------------- ------------------------------- ------------------------------- ------------------------------- ------------------------------- ------------------------------- ------------------------------- -------D----------------------- --------D---------------------- 
