model
size = 32 32 28, scale = 0.05, origin = -y
material 
  colors = A:#FCE0B6 B:#FDEFDA C:#946A6A D:#887C7C E:#553E3E F:#E0BEA5 G:#FBD091 H:#774949 I:#884F4F J:#FFF K:#100
voxels
134-2E17-2DB10-2FA16-GB12-2FG14-FBC12-B2F13-FB2C13-B2F11-FGBC16-FGC7-FGB2C17-C-GA6-2B2CAF14-3FCGA5-F5B748-AD20-DA8-3D17-2DAB9-FDH16-2DC11-ADH14-F2A11-FEDHE12-H2CAF10-2F3E2D8-E2HDACF13-C2EDE6-E2H2DH12-2GE-EGDE5-3E-D2AB11-2FB-E3A5-B2AE2ABF15-CB3GA2C2BA3B21-2G6B26-G3B626-D22-D7-2D21-DB7-B22-DC8-2C20-C41-FE19-2CA7-FBAE17-3AF10-E18-I10-FAE17-2EB9-FA2E2-4E4-H2E3-AE2F13-C2A4E2H2EAEC19-CGAE3A2EA2C19-B2CGB4A5B20-2B3A4B26-K2AB529-D23-2(D7-AC22-)2D5-AC23-ICD69-FA21-2C7-BA21-ACF39-AE20-EB7-FAE20-EB12-2H2E8-2EH19-ADE-3E2-E2A15-C2HC3ADE3A2E4AC2H11-6F2ADA4EA6B16-2B2C4A2B23-2BAB2A2B2C24-2B2AB465-D23-2D5-BC23-DI6-C24-D5-AC24-AD30-FB37-A30-FA24-F31-A7-E22-E7-FA22-EB6-A36-3D9-E3H12-BA2DHA2D7-E4AEAH9-FAD4A2D6-EA3D2AB15-3A3D3EAE19-C2B7AE2A2CD19-2B4A-EBA24-A5B431-D25-I5-B25-D31-CD4-C25-C4-A26-CB31-A36-A25-AF4-A63-FE24-E5-E25-E7-2E29-BAD19-2EH7-FAD20-A2B12-3H8-D18-2HA2E7-HA4H15-2E3-5E4-2A19-CB5A3E23-G3BA3B26-G3B368-D31-B25-CD31-D4-C25-C32-C3-A27-AB34-2A26-A3-2A26-B36-E25-E5-E25-EA6-E30-2E21-2EH5-BAE22-2A11-H13-HEH12-3HE13-H2AC11-2BE15-EAB15-2H3E4-5E16-5B2A4E2A5B19-2C4AH25-2G6B25-G2B2HB335-D26-D31-D35-A59-CB31-A30-A3-F27-2B34-A31-AE26-E36-AE23-2E5-BE24-AB7-KE17-2E11-AE17-EAC9-BAE17-2EB12-E2A11-2AE12-3B5A8-5A3B15-E7A2E4-IH15-AB5AB2AHE20-3B6A3B24-GB2A304-D26-D4-C26-D31-C35-C27-AB2-F28-A34-F27-BA31-B34-A27-EA30-2A3-A25-E4-BE25-2A7-E20-E9-EA19-EAC8-2A20-AB39-K4A15-2I3A8-2A4-EA7-AE4-2A2B11-5A5-B2AE2H15-2BG7AB4A2B18-CD2C5A2C24-AGAIH28-G2AE272-B26-D31-C35-A27-AB2-C28-A34-F28-A31-B34-F27-E31-2A30-E3-2A26-2A36-FH21-EA7-FA21-AB7-FA29-BA30-BA23-2A10-4A9-4AH13-B4A10-3AB17-11A2C17-G10A5B21-B4AB25-AB5AD238-B26-D3-BC26-A35-A31-A27-2A31-A33-FA28-B31-B2-A27-E2-FA27-EA62-E2-A29-A4-F23-E7-FH22-AB6-F2(30-2A)24-A9-2A15-AH3-A9-3A14-2AB16-3A5-5AC15-5A8-4A15-3A3-6A4-A7-2B10-9A9-2A11-2G9A119-7D26-3CDCD26-C4D16-B26-D3-AC26-A31-A35-A27-2A-BA28-A33-2A28-A31-B33-FA27-E2-2A28-A63-E35-FA23-2E5-2A24-A5-2A30-2A24-A5-AB24-A8-2A17-3B44-2A14-2A6-2A5-3A14-AF5-4AGE3-D7-2A7-D3-2AC4B7-11A7-3B11-2GAG2J5A22-2J4-J2A56-3DA3D25-D6A16-A8-D5AD9-D16-5D16-F11-3CD10-2A4-B26-A35-A27-A3-B28-A63-A-2A28-B31-A2-A27-D2-FA28-A-CA28-A-A29-A31-E3-AE24-E5-2A24-2A36-2A23-2A5-2A23-2A6-B-A19-2ABG8-A20-A11-2A16-A6-3AE3-2A16-A4-AC4AE3-A16-A2-E7AB6-11A5-5A4BAKB2AB2(5A3B)A5B3-3J6B2A4-4A3J5B14-2B5-3B23-D5-D25-F2-2C-A15-2A8-D2C2ACA9-D5-2B9-D3AD10-A5-F9-DC4AD9-AB4-A10-5D10-2A4-B11-3D11-E4-A31-B27-2A2-B27-2A34-A28-A31-A30-ED2-A27-AD2-C28-A-FA27-EA31-E29-E5-AE24-2A37-A23-2A6-2A22-2A6-3A21-C3-G4-2A20-C4-2G30-3A2E2-2A16-A2-GC2F5AB-2A16-A-E9A3C2ED5A2-5AC3E5AB14AB2-14A-3J2A5B3A4-4A6B2A2J4-2J5-BAB5-2BA6-BJ15-D5-2D24-F-4CA15-2A8-DC5A9-A5-BA24-A5-FA8-D5AD15-2A8-C6A15-B10-C3ADB9-E15-6DB14-2A26-E3-B27-E35-A27-2A2-A27-2A30-AD30-ED2-A27-AD2-C27-EA-AB27-2A35-H25-A5-A25-A38-EA22-C3-A3-2A21-AB3-FAG2-2A20-A3-F2AGE2-A20-G-GAF6A-A17-A-D12A17-12A2B7A6-2A2B2A3B3AB3A5B5A5-7A3B3A-A7B5A6-5A5B2A45-D5-2D24-2(D2C)A16-A8-F6A8-2A5-BA23-DA6-F8-2D4AD9-A5-FA8-D6A8-E6-BA10-5A8-EA6-C8-2C5A14-2A10-C4D10-EA3-BA10-DF2DC10-EA3-BA26-A35-2A31-F26-A4-F26-D3-FA26-E3-2A26-H3-BH26-HA31-A4-H24-A5-HA24-H34-AG3-E21-2A2-CF2G2-2A20-AB2-2F2AG-2A19-2A-2GF4AG-A19-2AG3A2C6A18-D5A2-2B5A15-DAB3AB4A2B2-A17-B3-2BAB2AB25-2BA2-2B26-B16-4A26-2(D2-)D25-D2CACDA25-3F4A16-B23-DA15-D5AD9-A6-F8-D6A16-B14-A8-EA15-7A8-C6-AC9-6A15-BA8-D6A9-2A4-BA10-FCD2A9-2A15-2(CD)CA15-F11-2DA11-2A4-F25-HA31-D3-2A25-HD4-B25-HA3-BAH24-AE4-H25-AE34-A-HAH22-2C-C-FA-A23-A2-CFAGK26-AF-2AG-EA19-2A-2GF-C2AG3A18-2AG3A-CB5A17-5ABA2-B5A17-5ABA4-5AD14-3A2BA9-BA16-B14-A16-B20-2I4A26-6A25-3DA2DA2(25-D6A)16-BA22-D16-2D5A8-A16-D6A16-AC7-D6-A7-E16-7A8-A16-D5-A15-AC8-A-5A8-EA5-BA9-F5A8-2A16-6A16-A9-C3ACA8-HE5-FA9-C-C2AC8-HA5-FE12-CAC8-HE5-A10-2C2DA10-HD4-B25-AD4-AH23-C2(A5-AH23-H)C3-FA-AH21-HA-AC-F3AH21-4AF-C3A24-2AF-C3AHEA18-A-4A2-2B4A17-5AB4-5A17-4AB6-5AD14-D3ABA7-2AB2A13-B2A2B12-BA4-F4A5-AB14-BA4-5A5-B21-6A25-2A-4A25-7D25-D6AD24-D6AD25-D4A17-F8-F6A7-DA16-I7A16-A7-A5-2A16-C7-7A8-A16-A5-A16-AC7-7A16-BA7-F6A7-E2A7-A13-A7-H18-6A8-2E6-FE8-6A7-HAD6-FE9-DC3A7-HA6-2A9-C4AC9-E5-2A9-CE3AC9-C6-AH8-5C9-CD3-C2-AH9-C3A8-H2A-C-FA-AH8-C3AC8-H3AC-C4AH8-4A7-H4AF-C4AH8-3CA7-5AF2-C3A21-5A2-2B2AH8-4A8-3AB5-3A2E15-4A2B6-B4A6-4A5-3A2B8-2B3A4-5A4-D3AB10-A2BA4-5A4-BA2B14-F4-F5A4-B15-F2A3-6A3-AB16-2A2-7A2-2AB20-A5-A25-A5-AD23-D3AB4A23-D-7A25-DA2DA18-BC6-F7A6-D17-I4A2-A5-B10-F7-I6A17-BC6-I6A7-A17-A5-A17-AC6-7A17-BC6-7A6-2EA8-BE6-F5-A6-H2A16-F6A18-E6-A5-A7-2C8-AE6-2(A2-)A6-3A8-AC7-6A6-IE8-2A8-6A8-2C3-BA-AE8-5AC7-CA2-C-CA2-AH7-C4AC6-H2A-AF-F2A-AH7-6A6-C4AF2-C4AH6-C4AE6-C5A2-5AH5-AC5A5-H4AB4-3AHC5-AC5A5-4A2B5-B2AC7-4AC5-3A2B7-B2A2E4-D4AC4-3AB10-B3A4-5AC3-D2AB12-B2A4-6A3-2A2B13-BAD3-6A3-3B19-A5-A21-FA2-7A2-2A17-B2A-7A-2AB18-4A5-A-3A20-2A6-A23-3AB-B3AD22-4AB-ADBD24-ID2-D19-BC4-AI2AD4A5-DA11-F5-I7A5-BA17-I6A18-A6-I6A6-AB10-2C5-2(A2-)A6-A18-7A18-AC5-7A6-2C9-BAC2(5-A)5-2AB17-F6A25-A5-A6-CA10-2E5-2(A2-)D5-I2A10-AC5-7A5-2A6-2A2-AC6-2(A2-)A7-2A-AC-F2A-AE6-7A6-C2A-AC-F3A-AE5-7A6-CA-2AF-F3A-AE5-7A5-H6A3-5AH4-6AE5-C4AB4-5AH4-A2-A-2A4-C5A6-4AC4-7A4-C3AB8-B2AH5-6A4-3A2B9-2BAH4-D4AD3-3AB12-2B2A3-6A3-2AB14-BAD2-2A-A2-A3-AB16-2F3-F5A2-3B17-FA-A5-A-2A22-4A-2A22-12AB20-3A4I5A53-A7-AD22-A4B3-A24-I2G28-3AD-4D18-2C4-3A-A2DA4-2B17-3AG2-3A3-BA18-C8A17-B2A4-7A5-2A18-7A25-8A5-C11-BAC4-7A5-CB18-F6A25-A5-A19-2E4-A-5A4-2CA12-ACE3-7A4-C2A6-F2A-2AC5-2(A2-)A6-2A-2AC-F6AC4-7A5-C5AF2-6AE4-7A5-C6A2-AB2A-AE4-A-5A4-6AB5-5AE3-A5-A4-HG4A7-5A3-2(A2-)E4-C3AB8-AB3A3-7A3-C4A10-2BA4-A-5A3-C2AB13-BHA2-F5AD3-BAB15-FAD-D5AD2-A2B16-3F-F5-A2-2B21-F6A23-F2A5-A-AB21-8A-A23-8A23-9AG119-B58-C15-DA13-BAC2-A2G3-4A-BAB16-C-2A2G-4A-D16-BA3-9A4-2B12-2CAE2-7A3-2AB19-8A18-BAC3-7A4-CA14-2C3-8A2-CAB19-7A20-EC3-7A3-3A14-2AC2-7A2-AC2A8-B2A-2BC4-7A5-EA2-2AC2-F2A-3AC3-7A3-C3A-2AF4-3A-3AC2-7A3-2C6A5-B2A-2A3-7A3-CAG-A2B7-2B3AE2-2A4-A3-AG-2B10-B3A3-2(A2-)E3-I4B11-BAFA2-7A3-A2BA12-2BAF2-F6A2-C3B19-F5AD22-FA-7A-2C19-F3A5-A-CB20-A-7A-A22-10A22-9A23-5AG3A23-4A2-3G212-2C-A7-D2-2A17-ACAG5-4A2B15-A2-C4AG2ABAD18-B8A2D5-B16-2C5AB7A19-C9A3-E15-B3C3AG6AIAB17-2E-9ACD21-7AD20-2CA-8A2CA11-FA5-AC-7A-2A6-AF4-FB3-2BC2-7A2-2CAB2-AF6-2A2-F2AC8A-2CABA-3A7-BA-F2AC8A-2CAG2-AB12-FAC-5A-A2-IG18-FE-6AE2-CA18-FE-7A2-AB18-FA2-6A-2AB21-D6A23-AD7A-DC20-9ACA21-9ACD23-3AG4A24-3AG4A25-5GA24-2A6-G245-2A9-2B20-4AG2-2GB20-B3A9-A19-5A3B-2DA2B19-4A3B3AB19-2C3AG4-4AB18-6A2G3ABD21-3A3B2AD22-11AC20-AE9A22-E2AG5A20-2AC3AG2D6A18-6AB5A2B18-11AIG20-AC6AE-CG19-2A-3AG6A20-12A21-D7A24-3A3B3A23-3A4G3A22-8AD23-2A2G2-3A25-AG-2GA409-4BD28-5B24-2AG3-B-3BA20-2A2G3-GBAB22-A2B3-3D23-3A3-2BD23-4AB4A23-2AG-GB3A23-2AG3-2D2H22-3AB-2B2AD21-4A3B3AD21-5A2B2AEA22-3AG-2D2A22-4A3G3AD22-8AD23-2A6BG24-AG4-BG24-A2G2-2GA24-G6-A473-4B28-G2B125-5B28-3B58-2A6-D23-A2B3-2BA23-A6B2A23-3A4-DA23-2AG4-2D27-BG29-4B766-B125-4B333-
