model
size = 32 32 31, scale = 0.05, origin = -y
material 
  colors = A:#FDEFDA B:#FFF C:#100 D:#887C7C E:#F63C9E F:#FCE0B6 G:#553E3E H:#101111 I:#946A6A J:#F7A224 K:#069E1D L:#2A0E0E M:#F57195 N:#D11111 O:#FF9D9D P:#2DD209 Q:#710016 R:#774949 S:#F8B148 T:#FBD091 U:#FC8599 V:#F9245A W:#F92F62 X:#4F0005 Y:#F9C16D Z:#A7F597 Aa:#A34806 Ab:#FF8982 Ac:#7F4504 Ad:#571D02 Ae:#FF938F Af:#200000 Ag:#E0BEA5 Ah:#BC5E08 Ai:#703F03 Aj:#2B0500 Ak:#461A01 Al:#BE5A08 Am:#782F04 An:#411101
voxels
47-OI30-3BD26-F5B25-O5MEOB24-2X6H23-FHGFDBCF2D22-DHDCFB2(HF)22-2H3C2H-H26-GHD2GD21-F2(HB)FH2BDF21-D2(HB)FH2BHBH-C19-HFHDFHFGH-GD21-5H3-R2D18-F2DH2E2XEMR3D17-H2(2FD)-Ag2DF2D2AHB14-OA4FB-AgDB-DA2BAH13-MUO2AB-2F3BFOBALAAeM11-AbMUBLA2F2-F2-B4-3M11-2M3-B2F11-2M12-M3-BFA30-BF3-F27-FA-B29-3B254-B2F59-IO2B2I-I25-3B2D-2O22-OD5B2D21-F12B21-3HBH2B4H20-B2HDF-2B-HBH20-CHB2HD3HB2H18-H2-2BC2-H-2H-H18-DFHBHFBF2H2DHB18-D3B2(HB)-BDBHF18-HD2BHBH5B2HC17-3H7B4H18-2DAfD6HG3D17-HD2H3D2C6D15-2O2B13D3B12-OH3BFDB5DF3D2BU-Ab10-M7BA10B2MAb10-2M6B-F2-FBO2A3BMAb10-MBUFL3B4-FB2FA2B2M12-M6B4-2F3B-B18-2BF3-F2B6-F18-B2-2BF27-4B29-2B30-BF30-AF126-2BF29-3BF57-FIB4FODI22-IO4B4DI20-I2D6B2D19-DLBH7B-BD18-3H-2H4B2-HC18-GDB2HBH4B-2B18-H2BHB2-HBH2BHBC17-3HB2-2HB4HBFG16-3B-6B2D2BFH16-8B-4BF2C16-H12B3D16-H2D4B-3BH-2D16-H2DH2B3H2BH-2D3-F13-FD2-3DH-HG4D2-AB11-D3BD2-D-2D2-4D4B11-O6B2-3DBF2D4BUD10-M7B-BDG9B2M8-2M6BC-B2-3B-4B-2M9-MBF4BC4-B-2F3BMBM10-M6BC4-F6B-MO10-2B3-2BC3-BF2B3-B-2B16-2BC-CBFB25-B-4B28-2B2(30-AB)29-D2(AF30-)2F30-2BT29-B3D7-2F49-DFD5F22-I2-B2D2BDB21-2I-D7B2D17-2D2IH-7B2D17-HDHB2H9BH16-DH-BH10B17-2H-3B-H7BC17-B2-2BH3B2HBH2B17-4B2-4B2D2BHC16-5B2-BH4BFHD16-HD7B-5BD16-2D3B-4BHBH2D16-4D2B3HB-2HD-D3-D9-2FID2-3BD-C2H2D-D2-3B10-2D2B-2B2(D2-)4D6B8-O7BC2-2D-3D6BM8-M-2B-3BC2-D2-9BM7-2M3B-3BH4-4B-5BM8-M3BF3BH3-H10BM8-U7BC3-H3B-3BF2BU9-2B3-3BC-C4B17-B5-2BC-C2B7-2B17-2BCB30-2B30-BF30-AB29-D2A29-DBA29-OBA30-BDTD18-C4-2YFD-B2DTCD6-F18-I29-I4D4F21-2IDB4D3BF20-2ID8BDF18-D2I3BG5BDFD16-HDHBH8BD2H16-HD-11BC17-BH2-2BH8BC16-DB2-B-2B3-4BD16-D2B4-B-2B2D2BH17-H13BDH16-HD13BD15-3D9B4D3-2H9-DI3D7B-H2D-D3-2D7-FB2DBD-5B-4D-D-A-3B8-FD3B3-BG-5D-2D6B6-O7B3-7D7B7-2M6B4-D2-9BU9-U3B-2BH2-2H10BM9-U6BH4-2B-6BMAb9-UB2-3BC3-HB2-B-2B-BM10-2B3-3BH-C2B7-BO10-B5-2BH-C2B7-2B17-2BCBF28-2BF30-BF29-FAO29-2AI29-DAI19-C9-DAITD17-H9-OBDT2D3C13-BC4-TF2A2BDT-2DCF3C-F18-2DI27-7D2F21-2ID2B4D3F19-3I9BDF17-2D2I7B-BDF2D14-2HDH10B-DH14-H2DB-8B2-B2D15-H2B2-7B-3BC16-2(3B-)B3-3BH16-H4B-6BD2B2C15-2H2-11B3D14-HD3-9B-2DH14-3D10B4DF-2DA4-F3-3D3-6BH6D2-2DB4-AF6B2-4BDB8D-2BH6-F5B3-CG10D5B6-8B3-3D-2D8BAF5-2M6B3-D3-10B7-2M7BH3-H10BM7-2M7BH3-H5B2(-B)M10-2B-4BC3-HB-3B-B-2B10-2B3-F2BH-HB7-3B17-BH-3B7-2B17-FBC2BF27-3BO28-FBO29-2AO19-C9-DADI18-B9-DA2D8-C9-BC8-OADFD4-2C3-C7-BO7-ADA-FD6C-DF8-BC2-C3FAD2B2DB8DF19-2DI27-2DB5D21-2ID3B3DFBF20-2I9B2D16-3D8B-2B4D13-CHD-H10B2DHC13-3HB-12BD16-HBH4B-7BGC14-CH8B3-3BHC14-CFH13BH-D12-2DFB-12B3D12-2D-2B-2(4BA)B2DF12-4D2B-3BA4BA4DH2D5-B4FD-5BA5B6D-2D5-3B2D3B-B-6B9D2BH3-2A8B2-G3BG-4DA4BAH5-D-6B3-2DB-10BAF5-D4BA2BC-GHB2-10B7-2M7BHC-C7B2(-B)8-9BH2-C4B-2B3-A9-5B-BAC2-C2B-B4-2BA10-B4-FABH-C2B6-2BA9-A6-F2BH2BF7-2B9-B7-F4B28-F2BI18-A9-ABI18-2A9-2BDI9-C7-2C9-CA2C9-I8-B9-2C2D6-C-2CF7-B8-3CD2CGH-Aj2(CD)-C7-BOC5-A2C2Q3DACI2(2DC)7-DB5CY2D4BA3N3D2LDF15-I5D-2I22-I8DB21-2D5B2D-BD20-2D9B2D16-3D3B3A5B4D13-4D3B3A2E4B3DC12-2HDBH2B3A2E5BDC14-H4B2A2B2E5BH2C13-DH7B2EBA2B2-HD13-D4B2A2B2E4ABD-D12-2D6B2A2E4AB2-DIF10-I-D5B2A2E5AB2D2F6-2FD2ID6B2A2E2B3A6DB4-2B3D-A3B5A4B2A5D2BA3-5B2A3BAG3A3B2A2DA2D4B3-AL3B3A2BC2-4B7A4BA4-A3B3A2BGC2-B-8A3BAL5-3B4ABC-H2-2(B3A)4B7-6B2ABHC2-3A8B8-6B3AH2-C2AB2-6B8-BA-2B-2FAC2-CA2B4-5B7-2A6-FAH-C2B6-4B7-2A7-FAHA8-C2B8-2A8-3A8-C-B8-2A8-DAD9-2C8-A9-3CI9-C7-BA9-CA3C4-C-3C7-BAC7-6C4-4CDI6-2BD-C5-6C4-CDC2DF7-B-3C3-AiC3-2C3-3C2DCF7-BCA3C2-2C3-2Q2H2C2AB2DF7-3BHBF2C2D2Q3N3-2NQ3DF15-8DI21-10DI21-2D4A4DB2D17-2IDB6A3B3D14-D2ID2B4A2E3B2DCD13-DIH3B4A3EBABDHDC12-2DH3B4A3EBA2BDH2C11-2D3B5A3E2A2BDH13-2I-B6A3E2A2B4D11-I2-2B5A3E3AB4D11-2ID4B3A3E3AB4D11-DID5B2A3E3A3B3DF4-L7DBA2B3A3E7A3DBA2-I3B2DF8A2EB6A2D3BAF-AB-3B5A2CG2A2B7AD4BA2-A4B5A3-B2AB8A4B4-A3B5A2B2HB10AB-F6-4B4AB2C2-9A2BF7-5B3AB2H-C4A2BA4BF7-6B-2AHC-C4A8B7-BAB5-2AC-C3AF2-2F4B7-BAF5-F2AHA2BF5-C3B7-BA6-5ABF5-HC3B7-2A6-H3A9-C-2B7-AC6-6C7-CA2B6-2A8-6C6-2CBC6-BA9-5C4-CAj2DBC6-BAC7-6C4-HA2DBF6-2BA2C5-C4-G3-4C2DF7-BCB2C3-C5-2C-6CDA7-4B3CAiC9-2C2QCDF7-4B3AQ11-N2-QDA13-2I8D22-3DA6D21-G2D4A4D2ID16-2ID9A2B3D14-3ID6A2E4ADHD13-2I2D6A3E3ABDHC12-GIDB6A3E3A2B2C12-ID2B6A3E3AB2D-G11-2D2B6A3E4AB3D11-DH2B6A3E3A2B2DI7-D3-2D2B6A3E3A3B3DF5-LD2-3DBA2B3A3E4A3B3D3-L7DB7A3E9AD2BA7BD8A2E8A5BA6B8A2B11A3BFJ2-AL3B5A-AGB11A3BAJ2-AD2B6A-BH-12ABF-J4-4B5ABC-H10A2B2-J4-4B6A2-C5AB4A2B2-J4-BAB6AH2-C3AB2-2B2A2B7-BCBA2-2F2AH-C4A2-LB2A2B7-BA4-2L3AH2ABAC3-HC2AB7-BA4-LH5A2BL4-2C2AB5-B-2C5-CA6C6-C2AB5-ICAC6-6C7-CA2B5-I2A7-7C6-C3B6-2AC7-C3-2C5-CA3B7-AC7-C4-L4-3C3B6-BA2C16-4CBDF5-2B3C4-C7-7CBDF5-C3B2C13-2C2-CBDF4-4BA2Q18-QDA12-4DG6D20-3D2A2G5DI18-IG7A3D2BIR16-ID9ABA2BRD15-ID6A2E5AG9-J6-DB5A4E4AD2G7-T4-2D2B5A4E4ABD-G11-2D2B5A4E4A2B-G10-G2D2B6A3E6A2D3-J4-2GI2D2B6A3E6A2D3-J4-G2IBDB7A3E6AB2DF3-2I2DID3B7A3E7A3DBA-2I4D2B8A3E10A3B2A5B9A2E11A2BJ-5B8AB13A3BK2-4B8A2B13AFAK2-DL2B8ABH13AF-P4-2B8AH-C10A-F2-K3-3B7AH-C4A2B7A2-J3-B4AF4AH2-C3AB2-B4AB2-T4-BCAF-L4AH-C3ABLHLB3AB7-ACF3-C4AH4AC2-H4AB5-B2AC4-C2A2C4AHC2-H2C2AB5-B2AC4-CA7C6-2CAB5-2B2C5-8C6-2CAB5-BA2C6-2C3-2C5-2CA2B5-BAC7-C11-2C3B6-D2C17-3C2AB6-D2C17-4C3A5-B3C18-2C2ADF4-2B2C19-C2AD4-2B3N20-Q2DF10-5D4G3D20-3DA5G4DI2G15-GB10A2DBDG15-GD13ADR8-J6-GB5A3E5AD3G6-V4-3DB4A5E6ACG6-M3-2GD2B4A5E6A8-Y2-2GD3B4A5E6A2DI2-J5-G2DAB6A4E6A2D3-W4-GAD10A3E6ABD2-BAe-I-4D10A3E6AB3DBS-2IA3D10A3E7A3D2BAc2I2A2D10A3E10A2BJ16A2E11A2BK16AE12A2BK2ABA2B23ABAP2-M3B23AFAK3-A2B8A2HB8A4F2-Z3-A2B7AH2-C4AB5A-BL-K3-10AH2-C3A2BL4A2BD-J4-4AL5AH-C3A2CL4A2B2-S4-AC2-2L5AH4A2-2C3A2B5-BA2C4-C8AH3-2(CA)2B5-B-2C4-CA5C2AC4-2C2AB5-B2AC4-4C2-3C6-C2AB5-BA2C5-2C4-2C6-CABD4-OB3C6-C11-2CABD4-OB3C3-3C11-4C2BDF-OBA3C19-3CADF-O2H3C20-2CADF-OB3AC20-C2ADF-2L2AN21-2QADA11-3D5G3D2-G18-2D7G3DAkG17-D10A2DBG16-GD14AR8-J5-3D5A3E7A6-J-V4-G2DB4A5E6AR5-J-V2-2GD2B5A5E6ADR6-J2-2D8A5E6A2DR2-J2-Aa2-2D8A5E6ABD3-N-AaI2G10A5E6AB2DFBW-AaI12A5E7A3DBS-AaI13A4E9AD2B2JI13A4E8A2-ABKJ15A2E8A3-FBKT15A2E7A4-2FPT3A2B10A2E7A4-2FKJ3A2B10AE8A2F2-2AP2-M3B8A2H9A4F2-K2-3B8AH2-C9A5-Z2-A2B8AH2-C10A2-B-K2-12A-C3ABL4C2A3B-J3-ACA2-H6AH3ABC-3C2A3B-T2-B-2C3-C5AC3AHC2-2C2A2B5-B-2C3-8C2AC4-2CA2B5-2B2C4-4C2-3C6-C2ABO3-2B2(3C4-)2C5-2C2AB2O2-2B3C3-C14-3C2BDO2-BA2C4-C13-5CBDF3-F3C19-3CADO3-3C21-2C2AO3-A2C21-2CADF3-AN23-N2AL12-D7G4D20-D8G3D19-D12AG17-D14AR6-J8-2D5A3E7A6-W-J4-2G2D4A5E6AR5-W-J2-2G2D6A5E7AR4-T4-2D8A5E7ABG5-G2-10A5E6A2B-D-J2-G2-10A5E7A3DBS3-D11A5E8A2DBS-J-12A5E12A2J13A5E12AKJ2(14A4E12A2K)3A2B10A3E10ABAPS3A2B10A2E10A2FAKJ-4B8A2H2E7A4F2-P2-4B8AH-CE9A2BL-K2-3B8A2H-CE4A3C3A2B-Z2-3B8AC2-3AB-4C2A3B-K2-2BCA2H6A2-3AH2-3C2A3B-J4-2C2-H2A5C2A2C4-C2A3B4-2BC4-H6CA2C5-C2AB-B3-3B2C3-4C2-4C5-C2AB-2B2-2B3C3-C8-C5-C3ABDB2-BA2C18-2CACABDF3-A3C2-C15-4CADF3-F2C21-2CADA3-FC23-CADA3-2C23-C3A2-2AN24-NAD12-D8G4D19-2GA7G3D18-D12AG17-D13AG7-JS7-2D5A2E7AR6-NS6-GD5AEC2E7A6-W4-2G2D6A5E6A2R4-S2-2G4D6A5E7ABGD2-Ac-G2-10A5E7AB2D2-Ah3D11A5E8A2D-AAcS13A5E8AD2A-AhS13A5E12AJK13A5E12AKP13A5E12A2K13A5E12A2P4AB9A4E12AKZ3A2B10A3E8AB2FAPS-4B10A3E6A2F-F2-KY-4B8AHC3E8A3B-P2-3B8A2HC3E5AC2A3B-K2-3B9A2H2EABC2A2C3A2B-K3-LB6A4C-3AC-2C-C2A3B-J3-B3CH2A6CA3C4-C2A3B4-B-2C2-H11C4-C2A3B4-B2AC2-5C2-4C5-C2A4B3-2A2C2-2C13-4C4B3-A3C2-C15-4CA2B3-3C20-3CADF3-3C21-2CADF2-3C23-CADF2-AC24-CADF2-AC25-NAD12-10G2D20-10G3D18-D12ADG7-J7-GD13ADG7-V7-2D5A2E6ADR6-JM7-D5A4E5ADA6-2J4-G3D5A5E6AR10-4D6A5E7AB2A5-2D10A5E10A2-2JD12A5E11A-JS13A5E10A3-K13A5E12AJP13A5E10A2-2K13A5E10AF-KP13A5E9A3F2K3AB9A5E9A3F2P-4B9A4E9A2FAKZ-4B10A3E8A-O2-PS-4B10A3E7A3B2-KS-4B10A3E2A3C3ABO2-P2-2B7A2CACA9C3A2B-K2-LB6A15C2A3B-J2-2B5A12C3-C3A2B4-B2A7C3-4C5-C3A3B3-DA7C5-2C6-2(CA)3B3-A3C2-2C13-5CA2B3-3C19-4CABA3-2C22-2C2AF2-A2C22-3CDA2-F2C22-3CDF2-AC24-CADF-2AC25-NAD11-11G2D19-2D10GD18-GD9A2GD9-J7-GD13AD8-V7-GD13ADG7-V7-2D5A3E5A2D7-J3-G-3D5A5E4ADAR6-Ad3-A3D6A5E6AR-2A2-JAa-2D10A5E10A2-WSD12A5E11A-WK13A5E11AAc-P13A5E7AF4AJK13A5E6A2F2A-AKP13A5E6A2F2AF-2K13A5E6A2F2AFAKZ-12A5E6A4F2A2K-4B8A5E6A4FA-2P-4B9A4E6A2F-B2-2K-4B10A3E7AF4-PJ-4B10AC2E4AC3A4-K2-3B6ACA7C3AC3A-B2-J3-B6A12C-2C2A3B-J2-2B2A6C2-3C6-2C3A2B5-2A6C4-C8-C3A3B3-2A6C13-2CAC2A2B3-A3C17-5CA2B3-3C18-C2-2CA2B2(2-A2C23-2CAF)2-3C23-2CDL-2AC24-2CDA-2AC25-NDA11-10G2-D19-2D10GD19-2D7A3GD17-G2D10A2G9-J7-GD13A9-J7-D6A3E5AG14-2D6A5E4A2D2-2G7-2D8A5E6AGR2B2-J4-10A5E7AG2A2-NS-2D10A5E12AWKA-11A5E12AJK13A5E11A2-P13A5E7AF2A2FJK13A5E7AF2A2FKP13A5E7AF2AFA2K-12A5E6A3F3AKP2-3B8A5E6A3FBA-KP-4B8A5E6A2F2B2-PK-4B9AEC2E6AF2A-B-KJ-4B7A5CE4AC3A2-2BK3-3B5A9C2ALC3A4BJ3-B3A2CA7C2(2-2C)3A2B5-B2A6C11-2C3ABL5-2A6C12-2C5AL3-3A2C16-C2AC3AB3-2A2C17-4C3AB3-A2C17-2C2-3C2B2-A2C23-2C2A2-3C23-2CDF2-F2C24-CDL-FAC25-CDA-2AC25-NAD11-10G22-2D4GA3G2-D19-D7A4GD17-2GD8A3GD17-2D11AG3D14-G7A2E5A2D2G12-G7A4E4A2DA2GI8-D-8A5E6A2I2B7-2D8A5E10A2-2J3D10A5E3A2D5A2-JKD12A5E3A2D5A3-P13A5E10A3-K13A5E7AF2AFA-P13A5E10A2FJK13A5E7AF4AKP-12A5E6AF-3A-2K2-2AB8A5E6AB-F2A-KP2-3B8A5E7A2B2A-2K3-2B8A4CE7AB2-A-2J3-2B7A5CE4AC2A3-BAJ4-B6A8C2ACHC3A2-2B5-3A2CA4C2-C2-3C-2C2A4B5-2A6C11-C3A4B4-2A3C2-C12-C4A3B3-3A2C16-C5AB4-3AC17-4C2A2B3-2(AC)21-2C2B2-A3C23-CBD2-3C24-CAF2-F2(C25-CDF-2A)C25-NAD11-R7G24-2D7G23-2D5A4G20-GD8A3GD17-2D11A2D17-8AE5A3D14-G7A3E3A4D10-4D7A5E3A3D10-D10A5E2A4DI6-JAn12A5E2A3D5A3-S-12A5E2A3D5A3-K-12A5E2A3D5A3-P-12A5E3AD3AF2AFA-K13A5E10AFA-K-12A5E6AF3AFAJK-12A2(5E11A-JP3-10A)5E8ABA2-2J3-10A4CE8AB2A-2J3-8ACA4CE8AB-2A5-4A2CA3C3-2C2ACAC3A4B5-3A7C3-7C4A2BL5-2A7C8-2C4A4B4-LA3C2-2C10-2C4A3B3-L2A2C4-C10-2C2AC2A2B3-3AC17-4C2A2B3-2(AC)21-2CA3-A4C22-CAB2-3C24-CBF2-FC25-CDF-2AC24-QC2D-3A25-NDA11-2R5G25-DR6G24-2D6AG22-3D7A2GD18-2D8A3GDG9-J6-D13AD2-G7-Y5-D9AE4ADI14-D9A3E3ADI-D12-10A4E2AD2ID9-12A5E2A4D2F5-S-12A5E2A3D2(AF)A3-T-12A5E2A3D4AFA2-K-F11A5E2A2D2F3AF2A-K-F11A5E4A2F3A2F2-K2-11A5E4A2F3AF2A-P2-11A5E6AF4A2-K3-10A5E10A3-J3-10A3ECE10A3-J3-8A6CE6A2-2A7-8A2C3-2C6A2F3A6-8AC5-CAC4A3F2AO5-4AC2A2C5-4C3A2F2A2B5-2A7C5-5C5A3B4-2A4C2-2C8-3C5A2B4-A3C15-3CAC2A2B3-3AC17-5CA2B3-A3C20-3CA4-5C20-2CA3-F2C24-CAF2-FC25-C-F2-AC24-2C-F-2AC7-C16-QND14-6G24-D-9G21-2DG4A4G19-G3D6A3G11-J7-2I8A2G2D10-V7-2I8AGDAD10-M6-D2I8A4D10-S5-D9AE2ADADI9-Am5-9A3E3AD3I7-Al5-8A5E2ADFD2F6-Ad-12A5E2AD4AFA4-S2-F10A5E2AD6FA3-T-2F10A5E2AD6F2A2-K2-11A5E3A3FA2FA3-K2-11A5E3A3F-A-3A-K3-10A5E4A2F4A3-J3-10A5E10A3-J4-9A3ECE6A2F2A8-7A6CE6A3FA7-7A3C3-2C6A3FA7-6A3C5-CAC4A3F2A6-4ACA3C5-4C3A3FA2B5-2A8C6-2C3A2F2A2B5-A4C2-2C8-2CAC4A2B4-A3C14-5C3A2B3-3AC16-5C2A2B3-3AC18-4C3A3-A4C19-3CA4-5C20-2CD4-FC2-C20-2CD4-2C7-C15-CAD4-AQ23-NAD14-2G30-R5G24-2D2G3A3G21-I2D5A2G13-J7-3I7AGD12-V7-3I7A3DG10-V5-GD3I6A4DIG9-J5-DA2I6AEA4DI15-D9AE2A3D3I13-9A3E3A2(DF)A11-9A5E2ADFAF2-A8-10A5E2AD4F2A4-J2-F2A2F6A5E2AD2F-4A2(3-S3-A3F6A5E3A2FA-3A)3-J3-A2F7A5E4A2F-2A4-J3-10A5E9A9-9A3C2E6A2FA9-8A5CE6A2F2A7-8A7C6A3F8-7A3C3-2CAC4A3F8-4A6C3-5C3A3FA2B5-3A7C2-C3-2C3A2F2A2B5-A8C8-C2AC3A-2B4-A5C2-C9-5C3A2B3-2A3C13-2C2-2C4AB3-3A2C13-C4-2C3AB3-2A6C15-3C2A4-A5C2-3C12-3CAD4-A5C2-4C12-QCAD4-A5C2-4C13-QAD4-2ANQ2-6C13-N3D76-DR-GIG24-2I2DR2A2IG22-2I2D3A2ID13-J8-2I6A2D13-J7-3I6ADI-I18-3I7ADF3I16-2I8AEA4F-2I13-10AEA3FD2FA12-10A3EA2FD3F11-2A2F6A5E2ADF-A2-A8-A4F5A5E3AF6A7-5F5A5E3A-2A-3A7-5F5A5E3A-5A8-4F6A5E4A2F2A10-3F6A5E5AF-A10-9A5E8A10-9A3C2E6AFA9-9A5CE6A2FA9-8A7C5A2FA10-7A8C4A2F2A9-2(2A2C)2-6C3A3FA8-2A6C7-2C2AC2A3-B5-2A6C8-6C3A2B5-2A6C8-2C2-2C3A-B4-3A6C13-C3A5-4A7C12-C3AB4-4A8C10-3C2A5-4A5CE3C10-2C2A5-3A10C2-C8-QAD5-3A2Q4-4C2-C8-2ND81-R26-2I3D2G25-2I3DAI25-2IAD3AI24-2I6AD21-3I7A2F20-3I7A4F17-2I9A5F15-11AEA4F2-A11-2A3F6A3EA2FA-3A10-A5F4A4E4A-6A7-2(6F4A5E3A-4A9-)A4F5A5E4AF3A10-3F2(6A5E4A2F2A10-A2F)6A5E6AFA10-D2F6A5E6AFA11-2F5A4C2E6AFA11-6A6CE6A2FA10-5A9C6AF2G9-5A3C2-4CA3C3ABRA6-4A2E3C6-6C4A7-3A3E3C7-6C3A7-3A4E2C11-2C3A6-5A4E2C10-C4AB4-6A4E5C6-3C3A5-AL5AC3E4C6-3C2A7-3A12C7-Q2A8-2AQ3C6-2C7-2NA143-4D26-2I5D24-3I3ADAD22-4I6AF22-2I7A4F18-I9A4F17-12A3F16-A2-F6AAfE2A2F15-A-4F5A3E4A-3A2(10-6F4A5E3A-F2A)11-4F5A5E3A3F12-A2F6A5E4A2FA12-2(2F6A5E4A2F2A11-)2(2F6A5E6AFA11-)2F5A3C3E6AFR11-6A7C6A2F2-B7-6A9C6AF-RB6-6AE11C5AB-C6-4A3E5C3-6C2AB-C6-L3A3E5C5-4C2ADA7-5A3E6C4-2C4AD6-L5A4E5C4-2C4A9-6A4E3C4-3C3A9-4A6CX4C3-2C3A8-AD2NQC4NX8-QF3A145-D27-2I-4D25-2ID2A3D23-3I6A23-2I7A2F21-9A3F20-10A3F19-F10A2F19-2F6AE4A2-2A12-2F-2F5A3E3AF-2F12-A4F4A4E3AF-3F12-3F5A5E3A4F12-2F6A5E4A3F12-2F6A2(5E4A4F11-3F5A)5E6A3F10-3F5A5E6AFG11-2F6A5E6A2FG10-8A5E6A2FG9-9AE3CE7AF2-L7-7A2E7C6A2-C6-6A4E8C5A9-6A5E8C4A9-7A5E3C2-2C4A10-6A5E3C2-2C4A10-A2D6A2E8C3A10-4D8A7C4A9-5D2NQ6NFXFCN2AD145-D31-2D2(-D25-2ID2A)DA24-2IAD4A24-D9AF21-D10AF21-F11A20-F11A19-2F6AE4A2F16-AF7AE4A2F2-F13-2F5A4E4A2F-F13-2F5A4E5A3F13-TF5A4E5A4F12-TF5A4E5A4F11-3F5A4E7A2F11-3F5A4E7AF12-2F6A2(4E7A2F11-8A)4E8AF9-A-8A5E7AD11-6A7E2C6A12-5A6E4C5A12-7A3E5C4A13-D6A3E5C4A13-DAD8A3C6A10-7D15A10-2DL5DQ3DN6DA2L207-D-2D-D25-ID-2A-A25-2D-2A-A26-AD2F2A-2A22-FA3F5A22-5F6A21-5F7A20-3F9A2F17-2F6AE4A2F17-2F6AE5AF2-F14-2F5A2E6A2-2F13-2F5A2E6A4F13-F6A2E7A2F13-2F6A2E8AF12-3F6A2E8AF12-2F6A2(3E8AD12-8A)3E8A13-8A3E9A13-7A5E7A13-7A5E6A14-18A15-AD9AD5A14-2DL9A2D2ALA16-L3D3AD6ALAL12-D2-7DL5D2-A243-A2-A28-2F-A26-D-F4-A24-4F-A-2A23-5F4A22-5F6A21-5F8A18-4F10A18-2F13A17-2(2F14A16-)2F15A15-F16A15-2(17A14-F)17A14-T2(17A15-)16A16-15AL17-14A19-L8A-2A21-4AD36-D311-2F60-F-2F2(-A)24-4FC4A23-4F5A22-5F6A-L18-4F9AL18-2F12A18-2F13A17-2F14A16-2F4AL3AD5A16-F5AL4AD5A15-11ADAO3A15-11ADA2O2A15-11AD2AO2A15-7AL3AD4A16-4AD6AD4A16-3AD7AD3AL17-AD2L6AD3A19-DL2AL4AD2A21-L2AL3A3-A22-2AL81-
