model
size = 32 29 32, scale = 0.05, origin = -y
material 
  colors = A:#FFF B:#100 C:#FDEFDA D:#553E3E E:#887C7C F:#F61969 G:#F92F62 H:#DE0000 I:#900202 J:#F2408D K:#069E1D L:#FCE0B6 M:#F8B148 N:#F63C9E O:#F14383 P:#2A0E0E Q:#946A6A R:#2DD209 S:#F9245A T:#F14286 U:#FBD091 V:#F9C16D W:#710016 X:#F69300 Y:#F14288 Z:#5D0808 Aa:#C52323 Ab:#770505 Ac:#F7A224 Ad:#5A000B Ae:#101111 Af:#A00 Ag:#FC7B8E Ah:#4F0005 Ai:#DD960A Aj:#FF9D9D Ak:#AC5B07 Al:#430B0B Am:#F94E7C An:#F9638D Ao:#FF3B3B Ap:#8C5505 Aq:#BB6808 Ar:#774949 As:#200000 At:#FC8599 Au:#FC304A Av:#C67A08 Aw:#360B01 Ax:#FF7F75 Ay:#F04481 Az:#DD880A Ba:#843505 Bb:#B75807
voxels
299-2K30-2R642-A-L20-B6-A-A2LP19-2B5-C2AU-P6-B14-LQ-AjCUCV2C3V-VBV15-CL2QCPUV-2UC3U20-L-2(CU)AL3-AU24-LA153-3I28-IAaAd2Aa27-I3AdI27-2IAdAaI28-IAaI417-2AL29-3AB19-Q5-7A7-LV10-ABA2-5AE-E2LB-AeLBC11-AeL2AAj4EA5EV3EV12-UC4U4EU6E2VC14-A3L-2ED3E4AEL20-DR-2E3-A-A21-R3-2K4-A21-R3-R24-D2-Ad26-KA32-H32-2I9-H2-Aa17-2I12-Aa18-Ad450-2AU29-A2EB7-2B10-AB4-AE3A2E-LBAjB-L2E10-3AAj7ALA3E2-3EV8-L-U2E2AE5A2-3A2EAEV11-C6E5A2E3A2E-L12-A2LEU4DA2E2A2-AV17-E2-2KDADE4A-A17-K2-R3K2D3(-A)17-2D2R27-KAAm5-R2-R18-K-AmA11-H2I17-AHI8-2IH2I17-4I6-2H3AdF16-3I7-IHAdIAaF16-I-I8-2IAa438-AEUE18-B4-2VLE-A2EUBE6-B9-BAAe2-L-2E2A3ELE-E2B2E11-14A2EL4E9-2LAE2A3-12A2E10-LU5E7AE2P3A-V10-2A5E4D3A-3APDA14-2DE2DA2DAeAD-6A14-K-KDK-2A-2D2-2A2-A15-R2DAm2C-2R3K4-P2R12-K2AAm4-AD2RDR17-A4-2I8-H21-3I2-2A2-H-2H17-5I6-2AHAd18-2I-I6-2H2Ad18-2IH34-3Aa28-2GYAa29-Ay339-Ae9-AjAEUE17-AB4-BL2C2AEU-E2-3BP-B8-B2AB-3LE-2A2EA2EB5E9-B3AC15A2EV8-LU3E3A-9A2C3AEV8-CU4E2A-6A3PC2ALC9-A3L2E2AD6AE3APE2A12-LDED-2D8A2-3A14-K3DKDAAe2DK-ADA2U15-RADAmC2-A4DKR2-R-2R11-4A4-AD2ADR17-K-AH3I2-5A2HK20-3I2-3A-2HAHF16-H5I-2A2-2AHF17-5I6-2H20-2IDH4-D2-H22-2DAa3G-3X23-D4GYXAkXM17-Y5-2G2Y2X2AkM24-G2-2M3X28-3M269-AAj8-EC-L6-B-2B8-2A2-2B4-2A2E5-B3EB8-3ABQL4-2AEA5-4EP8-2A-3A4-5A3-5AV8-L3E2AB-3B6A2C4AE8-2L2E2D4BA3B3A4CAEVL7-4L2D6A2BAD2A2D2AEA10-2L-D-2AD5A2DADA-AUA11-K2D2AD6A4DA4U12-RD3AC5A2B2D-K2RP12-P3AAaHC7A2R15-AKAmA3H-H6AKAK13-HA2-HA3H-8AH17-A4H-7AH2F16-I3H2-AC3A2H19-DAaD2H-3A2D3H15-AaGAe2AaAc4-3D19-GAeGYG3-2D3G-AqAcM16-GY5-4GY-AiVM23-2GMY-MV302-AAjB9-AE6-2B2EL7-EAAjB8-A7-E2PEB7-4A8-A7-A2E9-2A18-3A-P6-CL2E2A14-C2AE-L6-3L2E2D2(4-B)5CV9-3L2E-D4BAB2-BA3B3DEU8-L3D-D5A4BA2BDAeD3U9-2K3D5A4B2A2DPA3U10-2RD7A2B3ABDKDR2-2K10-5AC7A2CDKR13-5A2CH6AC-2A13-6ACACH3A4-2H13-H-3A2C2AH4AC2H-H17-AC2AH-4AC3H19-AD5AC3DAqH16-4G-9DAq16-5G2-7DMDM17-2Y3-3D3G4M22-2D3GAn-MV26-MH273-BAC17-BA2EL7-3A17-C3EL7-3A18-C2EC6-CA-A18-2CPV5-4L2A16-Af2CEU6-3L3A14-W3CEC6-3L3D2(B4-)5B3D2A7-2L3DA5B4-B2AB2DK13-2D6A4-B2A2BPK-R11-8AB2-B4A3D2-PK8-2D8A3B4ADC2D11-D7AC8A2CK11-H16A2CKH12-H-AC13AHAH16-C10A2C2H17-11ADCDH15-2G2D7A3DMBa16-4G2X-2A6D16-2GY2G2AkX7DM19-2X2Ak3D2Y2D2M19-2XAk2X2-3H3I20-2MX4-5I28-2IAd206-3A19-B2E7-3A18-2CEL6-L3A18-2CEV5-2L3A18-Af2CV5-3LEC18-AfCEU5-Q3L2A16-W2CEU5-Q3L3A11-5B2DEU5-2Q2DADA5B6-3A2BDK9-2RD7A6-B3ABD2K8-R-D8A4-B4A3D2P9-D7A-A3-B4A2CD9-KD8A5-5A2CD9-HK7A6-5AC2K10-H-2C3A7-4ACAH12-H2-C2A7-5ABHA13-D-3A6-3AC2D15-2G4A5-2A3D11-2Ai2-3GD3A3-3A3D12-Ai-2Ai3GD-D5A5D11-Ai4-GYAnG-2D3-2DAd2DM26-H-Ad2H29-Ad-H30-2Ad205-2AB21-AEV4-AB2A20-2CEV4-C3A20-AfCEV4-LEAC20-AfCEC4-L3EC18-Af2CEU4-Q3EC19-CEU5-2Q2E2A13-B4-AfDU5-2Q2D3AB4-B5-BAB2-WDKD5-D-2D4A4BAB4-B2A2BD3K5-2R2K10A4-B4A2DP7-2KR10A5-4A2CDP8-11A5-4A2CD7-IK11A5-3A3C2B5-2I2HC8A6-3AC2A7-I2AdHC8A6-3AC-A7-3IHI-5A8-2A2D10-3IAv-DA-3A2(3-A)DGD2Aa8-3X-2GD4A3-4A2DGAoAa8-2XAk2X3GD3A4-A-OFD2G9-2XM2X3G4D5-F2OF11-MXM2XGAn-2D8-FOF12-3X15-F26-H4-2H24-H2OH27-2(H2O29-)3F29-3F30-F19-AB22-2BV4-3AB21-C2EV2-3A2C20-WC2E3-4AC20-W2CEV2-LQAECB19-W2CEC2-3Q2EB20-CEU3-3QE2CA6-S12-AfEU4-2QDC3AB4-B6-B4-WDKD4-4D4A4BA2B3-BAB2-WD2K4-R2KDC12A2-B2A4BD7-K14A5-2A3CPH5-DR13A5-2A2CAH7-13A6-2A2C-2BH2-I-HC12A6-2AC3-H3-I-2HC10A7-AC8-I-2HAM9A6-2AD-G9-HAcAvM6A2-3A3-A4G8-HAp4-3A5-4A-D4G9-AcAp-3G3A5-3AOD2GYAn9-V2-3G2D6-H3OFAoY16-2D8-H3OFY22-2H3-HOFOG13-F7-F2OH3-HF15-Ab2O5-2Ab2OH18-F3O5-HAb2O19-F3O5-Ab3O20-2O6-2(H2O29-)Ag2O15-AjA2CB22-2BEV-2P3CB21-AfC2E2-A2C2B21-AfCEP2-L2C2B21-AfCE3-L2C3B20-PCEV2-LQC3B20-PCEC2-2Q2C3B19-PCEU3-2DC5B4-S12-P2KD3-2DC5A9B-2B4-Ah3KD3-RDC14AB2A6B2K4-KAB14A4-3A3CH4-D16A2-5A3CH3-DR16A-6A2-2BH2-I-C14A3-4A5HF2-IH15A3-4A4-F3-I2HCBb13A4-2A8-I-2HAzM14A-2A2DF8-HM2Ac8A2-6A2D2G8-H2M2-D4A5-4AO4G7-4M2-FO8-3AAbO2GAx14-FO5-H2-H3Ab2OGF13-2F5-F2OH-H4OG14-F-2F3-Ab2OFH2-2O2F13-FJ2-F3-Ab2OFH2-H2O13-F-JFO3-H3JF19-3J3F2-H2AgOF20-2F5-H2AgOF20-2F6-2JOF28-3F17-CB23-WBEV3-2CB-B20-W2CP3-C4B20-WCEC3-C3B21-WCEP3-C4B20-WCEC3-C4B20-PCEU2-L2C4B19-PD2E3-DC6B17-WDK4-2DCA6BA2B6-B4-AhB3KR-R3D10A6BA6B2KH2-KPBD15A5-AC-CH3-K2D16A2-4AJ-H4-I24A2OH4-IC16A-6A2OHF3-IC16A2-2A2-3HF4-IHCAF13A4-2AH7-I2H2FM14A2-AD2G9-2M18AD2G8-3MAD7A-7AOD2G7-H2M2-Ab2O2A-2A3-3AAg3OGAn8-2M-Ab4OT-3AH-HA2Ag2O-An11-2Ab4O2-2Ab2JH-HAgJ2O-J11-2Ab4O2-2Ab2J3-H2AgJOJ10-3J3OJ2-5JH2-2Ag2O12-5JF2-5JH17-6J3-H4J19-F4J3-5J19-5F3-5J28-2F18-C24-ZBCV2-2CB-2B20-Z2CV2-2C5B20-ZCE2-PC4B21-ZCE2-2C4B20-ZCEU2-2C5B19-ZC2E2-LE6B18-WD2ER-DED9B14-ZDKR3-RDC10B4-B-B4-PB2K3-RAD11A4BABA4BABKH2-RA2D16A6-A2JH3-ABD17A2-4A2JH3-2AD22AJ2HF3-24A-H2IF3-IC16A2-3A-AFH2F3-ICA2F14A5-AoH6-2H3F15A3-AG9-2FO18AD2G7-F2-MAAb8A-F5AOD2G9-M-J2Ab5A3-2F3A3O2J11-5J4-H-2FAJAg3O3J10-5J3-3AF-HAg2JO3J12-4J2-F3J3-H6J9-2J-4J2-F2J-JH3-4J11-6J2-5JH4-N12-7J3-3J20-2F3J4-5J18-5F3-5J47-2C24-ZBEL2-2C-4B20-ZCV2-C6B20-ZCV2-C5B21-ZCE2-C6B20-PCE2-C7B18-P2CEK-QC6B18-WD2ER-DR7B17-ZD3K3-D7B8-3B4-2BK4-RAD2A4B4A5B3A4BABKH2-K2AD18A4-A2FKH-RABD18A-4AF2H2-27AHIF3-19A-5AFHIF3-3AG15A2-2A-AH2I4-C2AG17A2(-A)HI4-2E2JFO17A-AGH5-H3J2F18ADG7-3JF12AF6A2JG6-3F-A3F7AH2F3A3J2FJ5-2F2-5F6AH3FAF2J3FJ5-H2-8F-3A-F2-7F8-8F2-FJ2F3-H5FJ8-3FJ3F3-FJ2F4-5F9-3F3JF3-FJ2F5-3F10-S2FJF2S3-5F5-2F12-2FSFS3-6F19-F7-3F48-2C24-ZBEL-3C2-B22-ZCV-2C6B20-ZCU-2C5B21-Z2C-2C6B20-PCED2Q6B19-P2CERD2Q5B19-WD2PK-DQ6B18-ZD5-RD6B9-3B4-2BK4-RAD2A4BA4-4B3A4BABKH2-KA2D10AB7A4-H-DKH-RABD18A5-I2H2-22AC4-2IF3-20A-AC-AH2I3-4AG17A3-ABHI4-3AG16A3-2ADH6-EA2G16A2-A2DH4-IHE2AG19A2D5-3H3AD16A-A2D5-4H-A2D8A-AF2A4-2D5-3H3-5AE3A2-H2F2N11-I5-4F6-F2-2N17-4F29-G183-3C11-B12-WCEL-3C-2B13-B8-AfEV-2C6B20-AfCV-2C6B20-ZCD-2C6B19-2B2CK2Q6B18-2B3CRD2Q5B19-B2DE2-KQ5B12-B6-ZDQ4-RD5B8-3BAB4-2BK4-K2D2A4B6-B5A4BABK2H-KA2D6A6B6A3-IAHDKH-RABD6A5B7A3-IHI2H2-10A5B7A3-I-2I3-10A5B8A4-2I4-3AG17A4-AsHI4-3AG16A5-DH4-I3A2G15A3-A2DH4-2IEA2G15A2-2A2D5-3H3AD16A2-2D5-2I2HAD13AF5-DA5-2IH2-10A2(-H)F2N3-2A6-I5-AFA2E8-2N17-4FT27-3G182-3C2-B7-2B2-B-B7-WCEL-3C-2B10-4B7-B3C-2C5B11-2B7-BAfCV-2C7B19-ZCEK2C5B20-2BCEK2Q5B13-B5-2B2CD2(KQ)4B12-2B6-B2D4-K5B11-2B6-ZD2Q2-R2Q4B10-4B4-2BK2Q2-KQD2A3B8-B4A4BABRH3RA2D4A3B4-2B5A3-IAHDKH-RABD4A9B5A3-IH-2H2-2AC5A9B5A3-I-2I3-8A9B5A3-I-2I4-8A7B7A3-AsH4-3A2G5A5B8A2-ADH4-2C4G16A2-A2D5-2IC3G15A4-2DM4-2I3AGD14A-N2-2D5-2I2-AD11A-2A2-N2-2DA4-2I2-C11AEHAF3N2-2A6-I3-A2E7A3-2F2N16-2F2EAG7-F18-2F2-G8-F18-2G30-G121-3C2-B8-B-4B7-WCEL-3C3B9-5B7-Af2CV-3C4B10-4B6-BZEV-3C6B10-B8-ZCEK3C4B19-2B2CE-A2Q4B12-2B6-BE2Q2-KQ4B12-3B4-BD6-Q5B12-2BU4-U4Q-R2Q4B12-BA2U2-2B3Q-KA2QA4B10-B2A4BA2DKR-KA2D2A5B7-B3A3-I3-2K-RABC3A11B4A2-2I3-2H-RAC4A11B4A2-2I6-7A11B4A2-2I6-8A9B5A4-AeH5-CGAeG4A7B6A4-MAp4-CA4G4A5B6A4-2MAiAc3-IA4GD15A4-MAiM3-2I2AGD15A-N2-2DV4-2I2AE15A2-N2-2DA4-2I2(-E)10AHE2F3N2-ADA9-2E7A2E-E-F2N3-2A11-F2A-2A2E5-F17-G2F3-G7-F17-2G31-G122-2C2-2B6-4B-2B6-AhAlCEL-3CW3B7-7B5-AhWCEV-3C5B8-6B5-WCEV-3C4B11-2B7-WC2E-3C6B18-PCV2-2AQ4B19-2B2E2Q2-K4B14-B6-Q5-R5B13-B8Q3-RQ5B13-2B3-BK4-K2AQ5B11-B2A3BAZP2DRKA2DA6B8-B2A2H2IH2-2D-K6A7B4-B3A2H2I3-A2-R6A11B4AH-2I3-H2-7A11B4A2-2I6-C3AG2A11B3A3-IH7-CAAa2G2A9B5A3-4M4-AAa3G3A7B5A4-4M3-I2AYG2D14A4-4M3-I3AG15A2-N2-2D2M3-I-3AD13A3-N2-2D8-C-12AE-F3N2-2DA11-E6A-E3-F2N3-2A8-4F5A7-2F14-5F2-AG7-F16-2G4-G26-G123-2CAf-2B6-2B11-2AlC-L-4C3B2-B15-Al2BCV2-CPC6B17-2BCEC-CPC5B18-B2CE2-2C7B17-PBC2E2-R6B18-3BEQ3-K4B14-B4-2DQ4-K6B13-2B2-3BU4-RA5B13-BA4BK5-RA6B12-BA2BABZ2BP2K2AD7B9-B3A2HAHC2D-KAP3A7B6-B2AHA3H2-A2-R5A13B3A2H2I6-6A13B3AH-I7-C6A11B3A3-2AH5-4AYGA11B3A3-A3M5-3AYGDA9B4A2-AD3MAc3-4A2GD3A5B6A2-A2D3M5-2AYA2D12A2-N3D2M6-4AD12A3-NA-D8-E-13AE-F3NA-2A10-9A2E3-F2N3-2A8-4F3A2G7-2F4-E9-5FA2-G24-2G2-2A152-2C4B-B2-4B9-2AlBCL4-2C4B2(-2B)9-BP3BCV4-C6B16-2B2CV4-C5B16-BP3C4-A7B14-2BZB2C4-R7B13-3B-PB2EQ2-K8B12-2B-BPD5-R6B14-5BK5-2A6B13-3BA2BK3-3A7B11-B4ABCDP2-C3A7B10-BC4A-2DP-CAP3A6B8-BAC3AH5-C5A8B4-2B2A4H6-C5A13B3ACHI7-C6A11B5A-IM6-7A11B4A-2A2M6-7A9B4A2-AD2MAc5-5A2D2A5B5A2-A3DM7-4A2D12A2-A2D2M7-C16A3-2A-DA7-CE9A2E2A2-F3N4A8-10A2-E3-F2N2-3A8-F8A7-2F3-AE9-2F4A-2G23-2G-3A2-T150-2CBW5B-4B6-6BCL4-2C10B7-6BC2EV4-7B7-3B2-B-ZB3C6-5B7-B6-2BZ2B2Q4-A7B8-B3-3BZ2B2E4-K8B11-6BCE4-K6BAB12-5BQ5-A8B11-6BK5-2A6B13-B2A2BDK3-3A7B11-B3AB2C2PB-2APA6B11-2C-3ACD3-6A5B9-BC2-I7-6A7B5-2B2ACHI7-5AY13B3ACHI7-4AFYD11B5A2-2M6-3A2FD11B6AD3M4-5AF2D9B3A2-AD4M5-7ADA5B4A2-AD4MAc4-C-C16A3-AD-2M7-C-13A5-2AD2A7-CE11A4-F2N-4A6-3AE2AE3A2E6-F2N-3AE8-2A2E3-2G7-2F3-AE8-GFE2A4-T12-A9-G2F-A28-G126-2CBC10B5-B-3B2WL6-C10B3-B-7B2CE6-8B5-7BZ2BCQAE5-7B4-6B-5BC7-R7B5-3B2-6BC7-R6B10-B2-3B2CE5-K8B11-2BA2CDA6-8B12-BA3BK5-2A6B12-2BA2BD6-2A7B11-B3A2C2(P2-)A2P6B14-2A-P2B3-4A6B9-BH5-PB3-6A7B5-2BABH4-AeB3-4AYA13B2A-CH3-A4-C3A2YD11B3A3-MAcA5-C3A2YA11B3A-A-AeMAc5-2C3AFAD9B2A-2ADM4Ac6-C5A2D5B4A2-2DAAcMAc6-C-15A3-2A-AM2A4-AC15A4-2A2D2A6-2(AE)3AE6A5-NA-AAw2A5-5A-E2-2EG-A6-2N-3AE6-2AFE5-GT8-2F-3A7-4F19-A8-4F28-2G128-B4C3W2B7-B-B2Ah2WC8-C9B2-9B3C8-8B3-9B3CA7-7B3-B-9B3C7-R7B4-5B-5B2C6-RA6B9-2B-3B3C6-KA6B11-3BD2CDK5-RA7B11-2BD2CDK4-R2A7B11-2BAC2DA4-E3A6B11-B2ADCD3-P-EA2P6B13-2ADP5-E4A6B9-BH4-D2-B2-E4A8B5-2BAH4-AB4-E5A13B2A6-AeA4-3AAbYA11B2A5-A2-BA2-E4AFA11B2A4-MAcA-A3-E7A9B3A-DAu4A5-E8AD5B3A3-DG4A6-E6A2D7A3-2DG4A5-AE-14A4-6A7-4AE-3A2E2A5-N4AE8-3A3-2AET8-NAN2AE7-4F5-G9-2F-2A8-4F5-G21-G3F29-2G130-5CW2AhB7-2Ah2W3C8-CE4BCBW7BAh3B4C9-7B-B-5B2CB2C3E4-A3-8B-4B-BA3B2C2E5-A2-7B4-6BA2B2C2E5-R-R7B8-4B4DAr7-K7B10-2B5DArK3-CKA7B10-2B5DK4-C3A6B10-2B3D2BA4-C3A6B10-2BAC2DA3-B-3AP6B13-3DB5-5A6B8-BH2-CAD2(P2-)5A8B4-2BA-CHC-AeAB-P2-6A13BA5-A-B4-C6A11BA2-Au6-BA2-C4AFA11BA2-2G4A-BA2-C7A9B2A2D2G4A5-C-8A5B2A5DG-3A5-2A-8AD7A2D2G3AE6-11A2E3A2-A2DG3AE5-3ATA-E4AT3-A4-3AF2AE6-AS2A3-2AG9-2AN-A8-4F4-2G9-2F10-S4F27-S3F29-G131-4E3CI4Ah3B3W5C4-A4-5E3C5B2WC2E3CE5-AC3-E7B2-B-2B2C6E5-2C3-16B4E2P5-2C2-C8B-5BAB6E5-2C-R7B-B4-3BAB4D6-2CKA8B8-BC4DB5-2C2A7B9-2BC-D-B7-2A7B9-2BPC-2Q6-3A7B6-B-2B2D-2B7-C2A7B6-3B2-DBDP7-C3A7B6-BABH-CDAe2(P2-)C-3A14BAB3-3A5-C5A13BA-B2-2A-B4-7A11BA2-2GA3-2BA2-7A11B3-2GA3-3A2-C7A8B2A2D3GF2A-2A4-C8A5B3A3D2G3A6-A2-8ADAD6AD2G2AE7-AT2-E11A2-2AG2A8-2A3-AE5AEA2-A3-NANF2A6-FS4-A-2AGT-A6-3N9-3F7-G9-2F10-3F29-3F157-2A3-7E15C5-AC3-2EP5EC10EC2P5-2C4-6EA5B7EPC5-2C4-2A7BC2B7E2C5-2C3-AC6B-6BD4E2C5-2C2-A8B2(2-B)2A3-2C6-2C-RA6B-B7-S3-C2Q2-C2-2C-A8B8-B2CQ5-C2-2C2A9B6-3BC2-Q6-2C2A8B5-3B2DP2-P6-AC2A9B3-3B2-D2CDP6-5A8B2-3BCSG-NCAP6-5A14BSAa2-C2AP2A4-5A12BCS3-2C3A4-7A11BS2-GB2C-ABA3-3A-2AG9BABM-3GA3-2A3-AS5AG6B3A2-GD2G2F3A4-AST3AG3A2B5A3-3GF4A4-A3-AE11A4-2G3A6-CS4-11A4-2N2A7-SAT2-5AGAEA-2A3-F2NF8-FS5-A-2GT-A7-FN9-2F7-G11-F10-2F30-2F158-AC7-P3E3C2E5C2(PC)5-2C4-E2-13E2-3C5-AC8-ECE4C4E3-3C6-C7-2ACAC2-CEP2EN2-3C6-C5-C3AC4B-2C2DN2-5C4-C3-BCA10B2-AN2-7C-AC3-A8B2-B3-SN2-2CQ4C-AC2-2A7B5-3BC2Q-3C-2C2(2-A)9B3-4BCBQ-3C-2C-2AC2A14BD3C-2PB2CPC2(-2A)13BAS-NC-2(AB)3C-4AC12BA3-2N3C3B2C-3A-A13BC-AaCN-C5AC-AT2ACA9BA2B2-S2N-C2A-3A-AS2AC2A11BS2-2N2(C-)2A3-A2S4AAa5B3A2B-Y3G4-A4-S-2AEAGAMB6A-A-3GS-3A5-G2-A-EYAt7A5-2GS-3A5-2STA2-3A-6A4-FNAtFA7-GS3-E4AGT2A-A4-F2NFA7-2F4-2AT2GTEA-A4-F2NF8-2F4-2A-T12-N9-2F5-E24-2F191-A4-6A2-2A4-E4-C6-2C4-5C3-2A16-2C4-5C3-2A9-2C5-AC5-4C-C-2A3-2S4-3C4-AC5-CT2C-5B2-2S3-4C4-AC3-C-C3SCA5B2-S3-5C9-2A3SL8B2S2-7C5-A-2AS3BC4-3BCS3-2C-3C-3A-4A10BAPC-PCP6C-A2C2-2A8BC2BA3-N-2CPCPA2-AC3-2A8B2CAC3-N-C5A2-3A2-2A7BAC2A4-N-C5A2-ATA-C3A5BACALAC2-2N-C2A-2A2-A4-E3A3B2ACLBA3-2N2-2A-A3-S5-2(4A2B)Ac-SAN2-C6-S2-EA-AaAM7AB2AcY2GNF-C6-G-SE-A2YMAc6A-A-3GNF3A5-G2-C-ASAM3A-2A5-F2NF2A6-G2S2-5AGT-E7-2NFA7-FT3-3ATG2-2E7-2NF8-2G4-2A-T11-2N16-E14-N279-A31-2A9-C20-A10-C6-A8-T2-5C7-3C5-A11-L6C-S4-3C4-A-2A2-A5-3CL2CLBS4-4C3-A-5A2-2TS-2C2BC2LS-S2-3C4-7A-3TS2C2AC3L3SCA3C4-AC2A-CAC3TSAC2AC2LC3S-4CA3-AC3-CAC2TSLAC4AC2-SN-3C2A3-ACAE-C2A2TSE3A-L4-SN-3C2A3-3SA-2A-3T3A-C2A3-SN2-2CA4-G2S2C2A-3T3A2-C4-2NF-2C5-G-S2-C2A3T4ALAAc-2S2N2-C6-G5-CA3T3A-AM2-AaG-NF8-G4-C2A4T-A6-YN-FCA6-GT4-2A2TGT9-N-F2C7-T3-3A2T11-N-F14-AEGT11-N-F15-EG12-N266-
