model
size = 26 32 25, scale = 0.05, origin = -y
material 
  colors = A:#090 B:#0F6 C:#0C6 D:#0C0
voxels
410-B23-2A24-A23-B2A24-A24-2A46-B657-A24-2A97-3A23-A22-4A604-A25-A24-2A170-2A607-A220-3AB557-A23-B-A23-3A218-A337-B50-A25-A23-3A49-B69-A270-A25-A22-4A20-3A23-B161-A25-A24-2A23-2A24-A25-A49-AB24-2(A25-)A43-A315-B25-3A443-A14-3A25-2A25-B315-A300-2(A25-)2A24-2A25-3A25-2A9-2A14-A370-A25-A195-B25-2A3(25-A)79-B36-2A386-A2(24-2A)194-2A169-B25-A438-A25-B117-2(A25-)A195-2A24-A25-A387-A417-2(A25-)B361-2A442-A387-B2A440-2A389-A21-C77-C340-A390-2A19-AD4-AC19-DC3-D25-C20-D340-A24-BA312-2C20-C4-2C16-B-CD4-D19-AD4-3D17-2D3-3DC18-DC2-CD19-CD4-D20-DC339-A25-4A22-2A-2A25-A252-C22-A25-3A5-A-C17-CD3-CD46-C4-C418-B24-2A25-A221-A25-2A54-C527-2A24-B2A191-3A637-2(A25-)A113-B25-A691-3A25-2A109-2A24-B667-B27-A25-3A25-B54-2A747-B-A25-2A52-2A777-2A2(25-A)166-
