model
size = 20 32 9, scale = 0.05, origin = -y
material 
  colors = A:#090 B:#0C6 C:#0F3 D:#0C0 E:#0F6
voxels
390-2(A19-)A18-2AE17-A18-2A18-A6-E12-A19-2(B9-B29-)B338-A19-3A12-E6-A19-2AE17-2A84-2A4-B13-2A11-A7-A4-B5-BAB6-ADAB8-D9-D2-B5-BDB7-BAB8-D9-D8-BDB8-B127-A19-2AC18-A19-A73-E6-A18-2A18-2(A13-A5-)E13-2A11-E34-C30-EAE18-A13-AE4-A13-A4-BDB18-2(D18-BDB5-B9-B2-)D26-B97-2A18-A19-A60-2(A19-)2A19-A12-A6-AC11-2(A19-)A31-A8-A10-2A7-A11-A6-2A11-2A5-2A12-A5-A13-A19-A25-2(B39-)B85-3(A19-)A74-A19-2(A10-A8-)A10-A6-C2A10-2A6-A12-A18-2A18-3(A19-)A27-C53-C191-A19-A41-3A19-2(A12-A6-)A10-3A6-2A9-2A8-A8-CA9-2AC99-C352-A17-A3-A15-A3-A14-2A3-AC13-A19-A26-C10-C502-A3-A15-A3-A35-C579-A3-A630-
