model
size = 9 32 7, scale = 0.05, origin = -y
material 
  colors = A:#0C0 B:#090 C:#0C6 D:#0F3 E:#0F6
voxels
5-B8-B7-B43-B8-B242-2B7-2B2(8-B)7-2B7-B7-2B72-B7-DB8-B81-A69-D27-D24-B34-DB8-B9-B8-2B16-2B7-B8-B35-B16-D2-A6-A-A15-C2A7-A96-B8-B6-D2B8-B80-B7-D2(B8-)2B7-BA-2A4-BECA6-3A2C4-A2CA5-3CACA3-3AC112-B107-B7-2B7-AB3A5-2C3A4-2C2A4-AC2(A2C)2-2AC-2A2-C3A241-A9-2A5-A-A10-AC4-2A-2A4-A2-A249-A26-A7-A5-
