model
size = 32 32 31, scale = 0.05, origin = -y
material 
  colors = A:#FDEFDA B:#FFF C:#100 D:#887C7C E:#F63C9E F:#FCE0B6 G:#553E3E H:#101111 I:#946A6A J:#2A0E0E K:#D11111 L:#FF9D9D M:#710016 N:#774949 O:#FBD091 P:#703F03 Q:#F9C16D R:#200000 S:#4F0005 T:#E0BEA5 U:#2B0500 V:#B76907 W:#461A01 X:#974D06
voxels
47-LI30-3BD26-F5B25-9B26-6H23-FHGFDBCF2D22-DHDCFB2(HF)22-2H-2C2H-H26-GHD2GD21-F2(HB)FH2BDF21-D2(HB)FH2BHBH21-HFHDFHFGH-GD21-5H3-N2D18-F2D2HC2-2DN3D17-H2(2FD)-T2DF2D2AHB12-B-2L4FB-TDB-DA2BAH13-H2B2LB-2F3BFLBAJA-B12-3BJA2F2-F2-B5-2B11-2B3-B2F9-2BFB12-B3-BFA30-B33-A-B29-3B254-B-F59-IL2B2I-I25-3B2D-2L22-LD5B2D21-F12B21-3HBH2B4H20-B2HDF-2B-HBH21-HB2HD3HB2H18-H2-2B3-H-2H-H18-DFHBHFBF2H2DHB18-D3B2(HB)-BDBHF18-HD2BHBH5B2HD17-3H7B4H18-2DRD6HG3D17-HD2H3D2C6D15-BF2B13D3B12-BH3BFDB5DF3D3B12-8BA12B12-7B-F2-FBL2A4B11-3BFJ3B4-FB2FA4B13-6B4-2F3B-B18-2BF3-F2B6-F18-B2-2BF27-4B29-2B30-BF30-AF3(30-2F)30-2BF29-3BF57-FIB4FLDI22-IL4B4DI20-I2D6B2D19-DJBH7B-BD18-3H-2H4B2-HC18-GDB2HBH4B-2B18-H2BHB2-HBH2BHBC17-3HB2-2HB4HBFG16-3B-6B2D2BFH16-8B-4BF2C16-H12B3D16-H2D4B-3BH-2D16-H2DH2B3H2BH-2D3-F13-FD2-3DH-HG4D2-AB11-D3BD2-D-2D2-4D4B11-7B2-3DBF2D5BDB9-8B-BDG9BDB8-A7BC-B2-3B-4B-BH9-2BF4BC4-B-2F5BL10-7BC4-F6B-BL10-2B3-3B3-BF2B3-B-2B16-3B-2BFB7-B17-B-4B28-2B2(30-AB)29-DAF29-LAF30-2F30-2BO29-B3D7-2D49-DFD5F22-I2-B2D2BDB21-2I-D7B2D17-2D2IH-7B2D17-HDHB2H9BH16-DH-BH10B17-2H-3B-H7BC17-B2-2BH3B2HBH2B17-4B2-4B2D2BHC16-5B2-BH4BFHD16-HD7B-5BD16-2D3B-4BHBH2D16-4D2B3HB-2HD-D3-D9-2FID2-3BD-C2H2D-D2-3B10-2D2B-2B2(D2-)4D6B7-9BC2-2D-3D7B8-B-2B-3BC2-D2-10B8-4B-3BH4-4B-5BJ8-A3BF3BH3-H10B9-A7BC3-H3B-3BF3B9-2B3-3BH-H4B17-B5-3B-3B7-2B17-4B10-B19-2B30-BF30-AB29-D2A29-DBA29-LBA30-BDOD18-B4-2QFD-B2DO2D6-D18-I29-I4D4F21-2IDB4D3BF20-2ID8BDF18-D2I3BG5BDFD16-HDHBH8BD2H16-HD-11BC17-BH2-2BH8BC16-DB2-B-2B3-4BD16-D2B4-B-2B2D2BH17-H13BD2H15-HD13BD15-3D9B4D3-2H9-DI3D7B-H2D-D3-2D7-FB2DBD-5B-4D-D-A-3B8-FD3B3-BG-5D-2D6B6-8B3-7D7B7-A7B4-D2-10B9-4B-2BH2-2H11B9-7BH4-2B-6BJ10-2B2-3BC3-HB2-B2(-2B)10-2B3-3BH-H2B7-BL10-B5-2BH-3B7-2B17-2BHBF28-2BF30-BF29-FAL29-2AI19-B9-DAI19-H9-DAIOD17-H9-LBDO4DI13-2B4-OF2A2BDO-5DIJ-D18-2DI27-7D2F21-2ID2B4D3F19-3I9BDF17-2D2I7B-BDF2D14-2HDH10B-DH14-H2DB-8B2-B2D15-H2B2-7B-3BC16-2(3B-)B3-3BH16-H4B-6BD2B2C15-2H2-11B3D14-HD3-9B-2DH14-3D10B4DF-2DA4-F3-3D3-6BH6D2-2DB4-AF6B2-4BDB8D-2BH6-F5B3-CG10D5B6-8B3-3D-2D8BAF5-BD6B3-D3-10B9-7BH3-H10BA7-9BH3-H5B2(-B)J10-2B-4BC3-HB-3B-B-2B10-2B3-F2BH-HB7-3B17-BH-3B7-2B17-FBH2BF27-3BL28-FBL29-2AL19-B9-DADI18-B9-DA2D8-I9-BH8-LADFD4-GI3-D7-BL7-ADA-F4D2ID-2D8-2B2-4FAD2B2DB9D19-2DI27-2DB5D21-2ID3B3DFBF20-2I9B2D16-3D8B-2B4D13-CHD-H10B2DHC13-3HB-12BD16-HBH4B-7BGC14-CH8B3-3BHC15-FH13BH-D12-2DFB-12B3D12-2D-2B-2(4BA)B2DF12-4D2B-3BA4BA4DH2D5-B4FD-5BA5B6D-2D5-3B2D3B-B-6B9D2BH3-2A8B2-G3BG-4DA4BAH5-D-6B3-2DB-10BAF5-D4BA2BC-GHB2-10B7-I8BHC-C7B2(-B)A7-9BH2-C4B-2B3-A9-5B-BAC2-C2B-B4-2BA10-B4-FABH-C2B6-2BA9-A6-F2BH2BF7-2B9-B7-F4B28-F2BI18-A9-ABI18-2A9-2BDI9-F7-2B9-CA2C9-D8-B9-2C2D6-G-IDF7-B8-3CD2CGH-UGDID-D7-BLF5-A2C2M3DAGI6D7-DBL3FOQ2D4BA3K3D2J2D15-I5D-2I22-I8DB21-2D5B2D-BD20-2D9B2D16-3D3B3A5B4D13-4D3B3A2E4B3D13-2HDBH2B3A2E5BDC14-H4B2A2B2E5BH2C13-DH7B2EBA2B2-HD13-D4B2A2B2E4ABD-D12-2D6B2A2E4AB2-DIF10-I-D5B2A2E5AB2D2F6-2FD2ID6B2A2E2B3A6DB4-2B3D-A3B5A4B2A5D2BA3-5B2A3BAG3A3B2A2DA2D4B3-AJ3B3A2BC2-4B7A4BA4-A3B3A2BGC2-B-8A3BAJ5-3B4ABC-H2-2(B3A)4B7-6B2ABHC2-3A8B8-6B3AH2-C2AB2-6B8-BA-2B-2FAC2-CA2B4-5B7-2A6-FAH-C2B6-4B7-2A7-FAHA8-C2B8-2A8-3A8-CFB8-2A8-DAD9-FB8-2A8-3CI9-B7-BA9-CA2CD4-C-GDB7-BAF7-6C4-RGI2DF6-2BD-P5-6C4-GDI3D7-B-2FP3-PC3-2C3-3C4D7-2BA2FV2-2C3-2M2H2C2AB3D7-3BHBF4D2M3K3-2KM4D15-8DI21-10DI21-2D4A4DB2D17-2IDB6A3B3D14-D2ID2B4A2E3B2DCD13-DIH3B4A3EBABDHDC12-2DH3B4A3EBA2BDH2C11-2D3B5A3E2A2BDH13-2I-B6A3E2A2B4D11-I2-2B5A3E3AB4D11-2ID4B3A3E3AB4D11-DID5B2A3E3A3B3DF4-J7DBA2B3A3E7A3DBA2-I3B2DF8A2EB6A2D3BAF-AB-3B5A2CG2A2B7AD4BA2-A4B5A3-B2AB8A4B4-A3B5A2B2HB10AB-F6-4B4AB2C2-9A2BF7-5B3AB2H-C4A2BA4BF7-6B-2AHC-C4A8B7-BAB5-2AC-C3AF2-2F4B7-BAF5-F2AHA2BF5-C3B7-BA6-5ABF5-HC3B7-2A6-H3A9-C3B7-AC6-6C7-CA2B6-2A8-5CD6-CA2B6-BA9-5C4-CU2D2B6-BAC7-6C4-HA2DBD6-2BAQX5-C4-G3-4C3D7-BFBCP3-C5-2C-H5C2D7-4BCV2PC9-2C2MC2D7-4B3AM11-K2-M2D13-2I8D22-3DA6D21-G2D4A4D2ID16-2ID9A2B3D14-3ID6A2E4ADHD13-2I2D6A3E3ABDHC12-GIDB6A3E3A2B2C12-ID2B6A3E3AB2D-G11-2D2B6A3E4AB3D11-DH2B6A3E3A2B2DI7-D3-2D2B6A3E3A3B3DF5-JD2-3DBA2B3A3E4A3B3D3-J7DB7A3E9AD2BA7BD8A2E8A5BA6B8A2B11A3BFA2-AJ3B5A-AGB11A3BA3-AD2B6A-BH-12ABF6-4B5ABC-H10A2B7-4B6A2-C5AB4A2B7-BAB6AH2-C3AB2-2B2A2B7-BCBA2-2F2AH-C4A2-JB2A2B7-BA4-2J3AH2ABAC3-HC2AB7-BA4-JH5A2BJ4-2C2AB5-B-2C5-CA5CD6-C2AB5-ICAC6-6C7-CA2B5-I2A7-7C6-C3B6-2AC7-C3-2C5-CA3B7-AC7-C4-J4-3C3B6-BA2C16-4CB2D5-2B3C4-C7-7CB2D5-4B2C13-2C2-CB2D4-4BA2M18-M2D12-4DG6D20-3D2A2G5DI18-IG7A3D2BIN16-ID9ABA2BND15-ID6A2E5AG16-DB5A4E4AD2G12-2D2B5A4E4ABD-G11-2D2B5A4E4A2B-G10-G2D2B6A3E6A2D8-2GI2D2B6A3E6A2D8-G2IBDB7A3E6AB2DF3-2I2DID3B7A3E7A3DBA-2I4D2B8A3E10A3B2A5B9A2E11A3B-5B8AB13A3BF2-4B8A2B13AFA3-DJ2B8ABH13AF6-2B8AH-C10A-F6-A2B7AH-C4A2B7A6-B4AF4AH2-C3AB2-B4AB7-BCAF-J4AH-C3ABJHJB3AB7-ACF3-C4AH4AC2-H4AB5-B2AC4-C2A2C4AHC2-H2C2AB5-B2AC4-CA7C6-2CAB5-2B2C5-7CD6-2CAB5-BA2C6-2C3-CH5-2CA2B5-BAC7-C11-2C3B6-D2C17-3C2AB6-D2C17-4C2AJ5-B3C18-2C2A2D4-2B2C19-C2AD4-2B3K20-M3D10-5D4G3D20-3DA5G4DI2G15-GB10A2DBDG15-GD13ADN15-GB5A3E5AD3G11-3DB4A5E6ACG10-2GD2B4A5E6A11-2GD3B4A5E6A2DI8-G2DAB6A4E6A2D8-GAD10A3E6ABD2-B2-I-4D10A3E6AB3D2B-2IA3D10A3E7A3D3B2I2A2D10A3E10A3B16A2E11A3B16AE12A2BF2ABA2B23ABA3-A3B23AFA4-A2B8A2HB8A4F6-A2B7AH2-C4AB5A-BJ5-10AH2-C3A2BJ4A2BD6-4AJ5AH-C3A2CJ4A2B7-AC2-2J5AH4A2-2C3A2B5-BA2C4-C8AH3-2(CA)2B5-B-2C4-CA5C2AC4-2C2AB5-B2AC4-4C2-3C6-C2AB5-BA2C5-2C4-CH6-CABD4-LB3C6-C11-2CABD4-LB3C3-3C11-4C2B2D-LBA3C19-3CA2D-L2H3C20-2CA2D-LB3AC20-C2A2D-2J2AK21-2MA2D11-3D5G3D2-G18-2D7G3DWG17-D10A2DBG16-GD14AN14-3D5A3E7A13-G2DB4A5E6AN10-2GD2B5A5E6ADN9-2D8A5E6A2DN8-2D8A5E6ABD5-2I2G10A5E6AB2DFB2-2I12A5E7A3D3B2I13A4E9AD3B2I13A4E8A2-A2B16A2E8A3-F2B16A2E7A4-2F5A2B10A2E7A4-2F2-3A2B10AE8A2F2-2A3-4B8A2H9A4F5-3B8AH2-C9A8-A2B8AH2-C10A2-B4-12A-C3ABJ4C2A3B5-ACA2-H6AH3ABC-3C2A3B4-B-2C3-C5AC3AHC2-2C2A2B5-B-2C3-8C2AC4-2CA2B5-2B2C4-4C2-3C6-C2ABL3-2B2(3C4-)HC5-2C2AB2L2-2B3C3-C14-3C2BDL2-BA2C4-C13-5CB2D3-4C19-3CADL3-3C21-2C2AL3-A2C21-2CA2D3-AK23-K2AJ12-D7G4D20-D8G3D19-D12AG17-D14AN15-2D5A3E7A13-2G2D4A5E6AN10-2G2D6A5E7AN9-2D8A5E7ABG7-G10A5E6A2B-D6-G10A5E7A3D2B3-D11A5E8A2D3B2-12A5E27A5E2(12AB15A4E)17A2B10A3E10AB2A-3A2B10A2E10A2FA3-4B8A2H2E7A4F5-4B8AH-CE9A2BJ4-3B8A2H-CE4A3C3A2B4-3B8AC2-3AB-4C2A3B4-2BCA2H6A2-3AH2-3C2A3B6-2C2-H2A5C2A2C4-C2A3B4-2BC4-H6CA2C5-C2AB-B3-3B2C3-4C2-4C5-C2AB-2B2-2B3C3-C8-C5-C3ABDB2-BA2C18-2CACAB2D3-A3C2-C15-4CA2D3-3C21-2C2(A2D3-2C23-C)2AD2-2AK24-KAD12-D8G4D19-2GA7G3D18-D12AG17-D13AG16-2D5A2E7AN14-GD5AEC2E7A11-2G2D6A5E6A2N7-2G4D6A5E7ABGD6-G10A5E7AB2D3-3D11A5E8A2D-A-D13A5E8AD18A3(5E27A)5E18AB9A4E13A-3A2B10A3E8AB2FA3-4B10A3E6A2F-F5-4B8AHC3E8A3B4-3B8A2HC3E5AC2A3B4-3B9A2H2EABC2A2C3A2B5-JB6A4C-3AC-2C-C2A3B5-B3CH2A6CA3C4-C2A3B4-B-2C2-H11C4-C2A3B4-B2AC2-5C2-4C5-C2A4B3-2A2C2-2C13-4C4B3-A3C2-C15-4CA2B3-3C20-3CA2D3-3C21-2CA2D2-3C23-CA2D2-AC24-CA2D2-AC25-KAD12-10G2D20-10G3D18-D12ADG15-GD13ADG15-2D5A2E6ADN15-D5A4E5ADA12-G3D5A5E6AN10-4D6A5E7AB2A5-2D10A5E10A3-2D12A5E11A2-14A5E11A-15A5E27A5E10A3-14A5E10AF-F14A5E9A4F-3AB9A5E9A4F2-4B9A4E9A2FA3-4B10A3E8A-L5-4B10A3E7A3B5-4B10A3E2A3C3ABL5-2B7A2CACA9C3A2B4-JB6A15C2A3B4-2B5A12C3-C3A2B4-B2A7C3-4C5-C3A3B3-DA7C5-2C6-2(CA)3B3-A3C2-2C13-5CA2B3-3C19-4CA2B3-2C22-2C2AD2-A2C22-3C2D2-3C22-3C2D2-AC24-CA2D-2AC25-KAD11-11G2D19-2D10GD18-GD9A2GD17-GD13AD16-GD13ADG15-2D5A3E5A2D11-G-3D5A5E4ADAN10-A3D6A5E6AN-2A5-2D10A5E10A3-2D12A5E11A2-D13A5E27A5E7AF19A5E6A2F2A-16A5E6A2F2AF-15A5E6A2F2AF2A2-12A5E6A4F2A3-4B8A5E6A4FA4-4B9A4E6A2F-B5-4B10A3E7AF7-4B10AC2E4AC3A7-3B6ACA7C3AC3A-B6-B6A12C-2C2A3B4-2B2A6C2-3C6-2C3A2B5-2A6C4-C8-C3A3B3-2A6C13-2CAC2A2B3-A3C17-5CA2B3-3C18-C2-2CA2B2(2-A2C23-2CAD)2-3C23-2CDJ-2AC24-2C2D-2AC25-K2D11-10G2-D19-2D10GD19-2D7A3GD17-G2D10A2G17-GD13A17-D6A3E5AG14-2D6A5E4A2D2-2G7-2D8A5E6AGN2B7-10A5E7AG2A5-2D10A5E12A2-A-11A5E12A2-13A5E11A3-13A5E7AF2A2F-14A5E7AF2A2FA-13A5E7A2(F2A)2-12A5E6A3F3A4-3B8A5E6A3FBA4-4B8A5E6A2F2B5-4B9AEC2E6AF2A-B4-4B7A5CE4AC3A2-2B4-3B5A9C2AJC3A4B4-B3A2CA7C2(2-2C)3A2B5-B2A6C11-2C3ABJ5-2A6C12-2C5AJ3-3A2C16-C2AC3AB3-2A2C17-4C3AB3-A2C17-2C2-3C2B2-A2C23-2CAD2-3C23-2C2D2-3C24-CDJ-2AC25-C2D-2AC25-KAD11-10G22-2D4GA3G2-D19-D7A4GD17-2GD8A3GD17-2D11AG3D14-G7A2E5A2D2G12-G7A4E4A2DA2GI8-D-8A5E6A2I2B7-2D8A5E10A4-3D10A5E3A2D5A4-D12A5E3A2D5A4-13A5E10A4-13A5E7AF2AFA-14A5E10A2F2-13A5E7AF4A3-12A5E6AF-3A5-2AB8A5E6AB-F2A5-3B8A5E7A2B2A6-2B8A4CE7AB2-A6-2B7A5CE4AC2A3-BA5-B6A8C2ACHC3A2-2B5-3A2CA4C2-C2-3C-2C2A4B5-2A6C11-C3A4B4-2A3C2-C12-C4A3B3-3A2C16-C5AB4-3AC17-4C2A2B3-2(AC)21-2C2B2-A3C23-CBD2-3C24-CAD2-2C2(25-C2D-2AC)25-KAD11-N7G24-2D7G23-2D5A4G20-GD8A3GD17-2D11A2D17-8AE5A3D14-G7A3E3A4D10-4D7A5E3A3D10-D10A5E2A4DI8-3(12A5E2A3D5A5-)12A5E3AD3AF2AFA2-13A5E10AFA3-12A5E6AF3AFA3-12A2(5E11A6-10A)5E8ABA7-10A4CE8AB2A6-8ACA4CE8AB-2A5-4A2CA3C3-2C2ACAC3A4B5-3A7C3-7C4A2BJ5-2A7C8-2C4A4B4-JA3C2-2C10-2C4A3B3-J2A2C4-C10-2C2AC2A2B3-3AC17-4C2A2B3-2(AC)21-2CA3-A4C22-CAB2-3C24-CBD2-2C25-C2D-2AC24-MC2D-2AC25-K2D11-2N5G25-DN6G24-2D6AG22-3D7A2GD18-2D8A3GDG16-D13AD2-G13-D9AE4ADI14-D9A3E3ADI-D12-10A4E2AD2ID9-12A5E2A4D2F7-12A5E2A3D2(AF)A5-12A5E2A3D4AFA4-F11A5E2A2D2F3AF2A3-F11A5E4A2F3A2F5-11A5E4A2F3AF2A4-11A5E6AF4A6-10A5E10A7-10A3ECE10A7-8A6CE6A2-2A7-8A2C3-2C6A2F3A6-8AC5-CAC4A3F2AL5-4AC2A2C5-4C3A2F2A2B5-2A7C5-5C5A3B4-2A4C2-2C8-3C5A2B4-A3C15-3CAC2A2B3-3AC17-5CA2B3-A3C20-3CA4-5C20-2CA3-3C24-CAD2-AC25-C-D2-AC24-2C-D-2AC7-C16-MKD14-6G24-D-9G21-2DG4A4G19-G3D6A3G19-2I8A2G2D18-2I8AGDAD17-D2I8A4D16-D9AE2ADADI15-9A3E3AD3I13-8A5E2ADFD2F8-12A5E2AD4AFA7-F10A5E2AD6FA5-2F10A5E2AD6F2A5-11A5E3A3FA2FA6-11A5E3A3F-A-3A5-10A5E4A2F4A7-10A5E10A8-9A3ECE6A2F2A8-7A6CE6A3FA7-7A3C3-2C6A3FA7-6A3C5-CAC4A3F2A6-4ACA3C5-4C3A3FA2B5-2A8C6-2C3A2F2A2B5-A4C2-2C8-2CAC4A2B4-A3C14-5C3A2B3-3AC16-5C2A2B3-3AC18-4C3A3-A4C19-3CA4-5C20-2CD4-2C2-C20-2CD4-2C7-C15-CAD4-AM23-KAD14-2G30-N5G24-2D2G3A3G21-I2D5A2G21-3I7AGD20-3I7A3DG16-GD3I6A4DIG15-DA2I6AEA4DI15-D9AE2A3D3I13-9A3E3A2(DF)A11-9A5E2ADFAF2-A8-10A5E2AD4F2A7-F2A2F6A5E2AD2F-4A2(7-A3F6A5E3A2FA-3A)7-A2F7A5E4A2F-2A8-10A5E9A9-9A3C2E6A2FA9-8A5CE6A2F2A7-8A7C6A3F8-7A3C3-2CAC4A3F8-4A6C3-5C3A3FA2B5-3A7C2-C3-2C3A2F2A2B5-A8C8-C2AC3A-2B4-A5C2-C9-5C3A2B3-2A3C13-2C2-2C4AB3-3A2C13-C4-2C3AB3-2A6C15-3C2A4-A5C2-3C12-3CAD4-A5C2-4C12-MCAD4-A5C2-4C13-MAD4-2AKM2-6C13-K3D76-DN-GIG24-2I2DN2A2IG22-2I2D3A2ID22-2I6A2D21-3I6ADI-I18-3I7ADF3I16-2I8AEA4F-2I13-10AEA3FD2FA12-10A3EA2FD3F11-2A2F6A5E2ADF-A2-A8-A4F5A5E3AF6A7-5F5A5E3A-2A-3A7-5F5A5E3A-5A8-4F6A5E4A2F2A10-3F6A5E5AF-A10-9A5E8A10-9A3C2E6AFA9-9A5CE6A2FA9-8A7C5A2FA10-7A8C4A2F2A9-2(2A2C)2-6C3A3FA8-2A6C7-2C2AC2A3-B5-2A6C8-6C3A2B5-2A6C8-2C2-2C3A-B4-3A6C13-C3A5-4A7C12-C3AB4-4A8C10-3C2A5-4A5CE3C10-2C2A5-3A10C2-C8-MAD5-3A2M4-4C2-C8-2KD81-N26-2I3D2G25-2I3DAI25-2IAD3AI24-2I6AD21-3I7A2F20-3I7A4F17-2I9A5F15-11AEA4F2-A11-2A3F6A3EA2FA-3A10-A5F4A4E4A-6A7-2(6F4A5E3A-4A9-)A4F5A5E4AF3A10-3F2(6A5E4A2F2A10-A2F)6A5E6AFA10-D2F6A5E6AFA11-2F5A4C2E6AFA11-6A6CE6A2FA10-5A9C6AF2G9-5A3C2-4CA3C3ABNA6-4A2E3C6-6C4A7-3A3E3C7-6C3A7-3A4E2C11-2C3A6-5A4E2C10-C4AB4-6A4E5C6-3C3A5-AJ5AC3E4C6-3C2A7-3A12C7-M2A8-2AM3C6-2C7-2KA143-4D26-2I5D24-3I3ADAD22-4I6AF22-2I7A4F18-I9A4F17-12A3F16-A2-F6ARE2A2F15-A-4F5A3E4A-3A2(10-6F4A5E3A-F2A)11-4F5A5E3A3F12-A2F6A5E4A2FA12-2(2F6A5E4A2F2A11-)2(2F6A5E6AFA11-)2F5A3C3E6AFN11-6A7C6A2F2-B7-6A9C6AF-NB6-6AE11C5AB-C6-4A3E5C3-6C2AB-C6-J3A3E5C5-4C2ADA7-5A3E6C4-2C4AD6-J5A4E5C4-2C4A9-6A4E3C4-3C3A9-4A6CS4C3-2C3A8-AD2KMC4KS8-MK3A145-D27-2I-4D25-2ID2A3D23-3I6A23-2I7A2F21-9A3F20-10A3F19-F10A2F19-2F6AE4A2-2A12-2F-2F5A3E3AF-2F12-A4F4A4E3AF-3F12-3F5A5E3A4F12-2F6A5E4A3F12-2F6A2(5E4A4F11-3F5A)5E6A3F10-3F5A5E6AFG11-2F6A5E6A2FG10-8A5E6A2FG9-9AE3CE7AF2-J7-7A2E7C6A2-C6-6A4E8C5A9-6A5E8C4A9-7A5E3C2-2C4A10-6A5E3C2-2C4A10-A2D6A2E8C3A10-4D8A7C4A9-5D2KM7KS2CK2AD145-D31-2D2(-D25-2ID2A)DA24-2IAD4A24-D9AF21-D10AF21-F11A20-F11A19-2F6AE4A2F16-AF7AE4A2F2-F13-2F5A4E4A2F-F13-2F5A4E5A3F13-OF5A4E5A4F12-OF5A4E5A4F11-3F5A4E7A2F11-3F5A4E7AF12-2F6A2(4E7A2F11-8A)4E8AF9-A-8A5E7AD11-6A7E2C6A12-5A6E4C5A12-7A3E5C4A13-D6A3E5C4A13-DAD8A3C6A10-7D15A10-2DJ5DM3DK6DA2J207-D-2D-D25-ID-2A-A25-2D-2A-A26-AD2F2A-2A22-FA3F5A22-5F6A21-5F7A20-3F9A2F17-2F6AE4A2F17-2F6AE5AF2-F14-2F5A2E6A2-2F13-2F5A2E6A4F13-F6A2E7A2F13-2F6A2E8AF12-3F6A2E8AF12-2F6A2(3E8AD12-8A)3E8A13-8A3E9A13-7A5E7A13-7A5E6A14-18A15-AD9AD5A14-2DJ9A2D2AJA16-J3D3AD6AJAJ12-D2-7DJ5D2-A243-A2-A28-2F-A26-D-F4-A24-4F-A-2A23-5F4A22-5F6A21-5F8A18-4F10A18-2F13A17-2(2F14A16-)2F15A15-F16A15-2(17A14-F)17A14-O2(17A15-)16A16-15AJ17-14A19-J8A-2A21-4AD36-D311-2F60-F-2F2(-A)24-4FC4A23-4F5A22-5F6A-J18-4F9AJ18-2F12A18-2F13A17-2F14A16-2F4AJ3AD5A16-F5AJ4AD5A15-11ADAL3A15-11ADA2L2A15-11AD2AL2A15-7AJ3AD4A16-4AD6AD4A16-3AD7AD3AJ17-AD2J6AD3A19-DJ2AJ4AD2A21-J2AJ3A3-A22-2AJ81-
