model
size = 26 32 32, scale = 0.05, origin = -y
material 
  colors = A:#101111 B:#FDEFDA C:#553E3E D:#887C7C E:#FFF F:#F63C9E G:#F92F62 H:#F8B148 I:#2A0E0E J:#F7A224 K:#C52323 L:#F14288 M:#946A6A N:#360B01 O:#100 P:#F9638D Q:#DD960A R:#BB6808 S:#FC304A T:#FF9D9D U:#F9C16D V:#774949 W:#FCE0B6 X:#F9245A Y:#FF3B3B Z:#200000 Aa:#FC8599 Ab:#FC4292 Ac:#F61969 Ad:#8C5505 Ae:#F04481 Af:#843505 Ag:#FF7F75 Ah:#CA7508 Ai:#EE4775 Aj:#F57195 Ak:#D11111 Al:#3B1501
voxels
208-2I24-7A3I-2A13-14A12-10A-2A13-2A-4A19-A493-E2-W22-E-2WI21-E-D-I9-D11-D-3DI3D-2DA2D11-2D-2DI6D2-D11-4D5-4DA15-D48-2AI7-I15-3A4-7A12-16A12-15A9-A-7A6-A16-2A486-4EW13-D7-5ED2-D7-3D7-2ED-DI4D-TA5D8-E15D10-DE11DA2D10-C4D2-6DAD13-2D25-C22-2A7-IAI14-8A-6A-I9-18A9-17A11-10A-3A14-5A484-2E4D10-3D7-3E3D-2D3TM-5D7-6E4D-D-6D7-3E2-2(3ED)E3D9-4E3D4E4D-D9-2CE2D2(2-D)CDED11-2CECD8-A12-5C21-A9-A15-3AC3A2C3A-2AIAI8-18A8-19A12-9A-4A13-5A483-E3D-3D18-2E7D-3DM-3D8-7EDE9D8-14E-3D8-5E-D3I4ED-2D8-C-3EI-D3-CIC2D10-2CAEC6-C3D11-C2-3C20-2A5I2C6-I2-A7-2A3CE4C2A2-6A6-19A7-3A2E6AE7A8-4A2-A3E4A-2A9-4A-A-4A41-4KC20-3GLK22-2Ae387-E2D2-8D2MI10-E3D2E12D8-13E2(DE)D8-9E3B4ED-D7-6E4I2B3E3D8-5E-D3-2CI5D8-5EC20-E2A4C3-C15-2A9C3-I5A6-2AEC3E2CEA2-8A5-2A6E3A2E10A3-3A4E4A2E2A-6A4-3A2E3A4E2A12-8AE4A14-5AC2A17-KA4G20-5GKL19-3G3L21-TG361-E3DE10D11-2ED5E9D2I7-17E2D7-8E4B5E2D7-9E6BE4D6-6ECD6C5D7-6E6C14-5E6C15-6E6C-I4AI3A4-10E3C10A3-A13E9A3-2A11E5AI4A3-A10E2A-3A3-2A5-7E4A14-2A3E4C17-AGA4C19-CAC4G2-RJAh14-6GL-RQU15-4GLP3-U354-4E6B4DE3I2D6-5E6B4E3D8-5E7B5E2-I6-5E8B3ED2-I6-6E10B-D8-7ECB7CD9-6E6CAC12-6E5C2I13-3E4B5CI2C-3AI3A3-4E7B3C9A3-7E3B2-2E10A2-A5E6-12A2-A7B2-8A-4A3-A8B5A12-E5B4CR15-8C-CR15-9CHCH14-CGC4G-3HQ14-C5GP-2HU353-15B5D6-E15B4D6-18BID6-E16B3D6-E16B2DI6-2E11B4C3D6-2E9B5C10-2E8B3CIC11-3E8B5C-2AI3A3-4E8BC3BE7A2-5E10BE8A2-B3E10BE3A-5A2-12BAE3A3-4A2-11BA-2A11-9BCBIC13-BCB5CRCHCAf13-11CAf14-10C2H14-3C2L3C-3H352-17BE2D6-18B2D6-19BD6-18B3D5-17B3D6-14B4C2D6-E12B4C9-E11B4C10-2E11B4C-2I-3A2-6A11BE6A2-6A11BE7A-6A9B2EAO5A2-6A8BE3A8-6A5B3EA-A9-6A5B3C12-6A3B4C13-ACA9C14-11CAd14-ACA3C-3CH15-13(6A20-)2(2F17B3D4-)2(4F15B3D4-)4F14B3D5-2B2F12B3C2D5-15B4C7-14B4C8-E14B3CI3-A3-9A9BEI5A-9A9BE6A-9A8BE2O5A-9A6B2EA8-9A5BI2A9-9A2B3C12-9AB2CGCAc2K9-9A3CGY2K10-9A2C-2GL11-9A2C15-12(9A17-)5A-3A17-2F17B4D3-4F15B3D4-2(5F15B3D3-)5F14B3D4-5F12B2C3D4-2B2F12B3C7-15B4C7-16B3C3-A3-11A8BI5A-11A7BE18A6B2AOAO3A-11A5B2A8-11A3B3A9-10A4C2AG9-10A2C2GA2G9-10A2C5GP8-9A2C4GLP9-10AC-Y2L11-11A-GLP11-11A2-G12-2(11A15-)5(10AI15-)4(11A15-)2F19B2D3-4F17BDI3-5F16BD4-5F16B2D3-5F15B3D3-5F15BC2D3-2B2F13B3C-C4-17B2C7-17B2CI-4A-12A8BI17A8B18A4B3A3O16A3B4A7-12A2B3A9-11A4C11-10A6CAcG8-10A4C4G8-11AC5GP8-12A3GAg10-12A3G11-12A2GP11-6(12A14-)3(11AI14-)2(12A14-)2F20BI3-4F17B2DI2-5F16BDID2-2(5F16B2D3-)5F14B2C2D3-4F14B3C5-17B3C6-18B3C-3AI14A4BA2B19AB56A7-16A10-12A3C11-11A3C3G9-11A3C4G8-11A3C3G9-11A3C2GP9-14AGP10-8(14A12-)3(12AIA12-)14A12-2F20BD3-4F18B3D-5F17B3D-2(5F16B3D2-)5F13B3C2D3-4F14B2C6-18B2C6-16BAB2C2-3A-20AC73A2(-A)6-15A11-14AGY10-13AC2G10-12A2C3G9-11A4C2G9-12A3C2G9-15AGP9-12(15A11-)3F19B2D2-4F18BD3-5F17B3D-2(5F17B2D2-)5F14B2C2D3-4F14B3C5-16BAB2C6-15B3A3C-3A-17A-A3C3A-16A3-22A2-6A-A-15A2(-A)7-15AX10-14A2G10-13A3G10-13AC2G10-13A3CG9-14A2CG9-13(16A10-)4F18B2D2-5F17B2D2-5F18B3-2(5F17B3D-)5F14B2C2I3-4F15BC6-15B3A2CI5-14B5A2C-3A-16A3-3C3A-15A4-22A5-2A2-A-15AC2A2-2A4-14AGCO9-13A3GC9-13A2G2C9-13AG-2C2(9-14A3C)9-13(16A10-)4F17B3D2-5F18BD2-5F17BD3-5F18BD2-5F18B2D-5F13B4CDC2-2B2F13B4C5-16BAB3C5-15B4A2C2-A2-17A-A3C20A3-3A-18A5-22A4-2A4-15A-Z9-14AG-C9-13AG3C9-14A-2C9-14A3C9-15A2C9-15ACAl12(9-17A)9-2(5F17B2D2-5F17BD3-)5F17BCD2-B3F13B5C4-16B5C5-17B4C5-16BAB3C-C2A-19A3C47A3-3AO19A3-3A3-16AZ5(9-15A2C)9-15ACN12(9-17A)9-5F17B2D2-5F16B2D2(3-5F17BD)3-5F14BDBM4-B3F12B3C-D5-16B2C8-16B3C-C5-17B5C-2A-20A3C44A-A2-4A-16A6-3A3-15A-A9-15A-H-Ad7-15A3HQJ6-15A-H2QH6-15A2C-U7-2(15A2C9-)11(17A9-)13A2-2A9-5F16B3D2-2(5F16B2D3-)5F16BM4-B4F13B4D4-B3F12B2(2C8-16B)2C8-BC12B2A3CI3C3A3C17A3C4AC13A-4A2E18A5-20A6-4A3-14AH11-14A6H2(6-15A5H)6-14A3C3H6-15A2C9-14A3C9-15ACN10(9-17A)9-12A3-2A9-5F16BD4-5F16B2D3-5F16BD4-4F17B2D3-B3F14B4D4-2(16B2C8-)BC14B2C8-3C10B3A3CI2CI-A-4C15AB3CI2A6C8A3-4AE7A4CAC4A5-13ACA3C3A7-3A3-8AC4A3H10-13AC3H-H7-12A2C5HJ6-11A5C4H6-12A4CH-H7-2(14A2C10-)14ACN10(10-16A)10-5A-6A3-A10-5F15B2D4-5F16BD4-5F15BD5-B3F16BD5-BF17B3D4-16B3C7-16B2C8-3C13B3C7-4C10B3ACB2CI4-CH5C12A3CI-2A3H6C4A3-10AC2HG6C3A5-10AGA7C2A7-3A3-7A4C-2A2H10-8A2C2A2C4H8-11A4C3HJ7-10A6C2H8-11A4C3H8-14A2C10-13A3C10-14ACN10(10-16A)16-10A10-5F14B4D3-4F16BD5-B3F14B3M5-B2F15B3D5-19B2D5-16B2CM7-16B2C8-3C13B3C7-3C10B3A3B4I3-3H5C10ABCI3-2A4H6C4A-5AE5A2H2GC3G3C2A6-7ACH7G2C2A6-3A4-4CA3G3C3-3H9-CAC4A7CA4H7-8ACA3C6H7-9A3C6HJ7-10A3C-C2H9-11A4C11-13A2C11-13ACN10(11-15A)14-8A3-A11-4F15B2D5-3F15BM2-D4-B2F14BM8-17BD8-18BD7-16BCM8-16B2C8-2C14B2C8-4C10BA2BCI3-2I4-5C10A3I-IA3-3H6C9A3I4A-3H6GC3A5-AI6ACH7G-CA7-3A4-4C4G5-2HJ10-4C3A2(2C-)A2HJH8-7A4C-HJH4J7-8A3C2-2JH2J8-8A2C5-H10-9ACA-2C12-12A2N11(12-14A)15-7A16-3F16B7-17BM2(8-17BD)8-11BC5BD8-10B3C3BCM8-9B4C3B2C8-10B3C2B3C8-CAC8B3C2BCI4-IA3-5C6AC2ACI5-2A4-H-3C9ACI3-3A2-3H4GKS-2A5-AI-I3A2-4H2G-G10-A-2A4-3H2GK8-J13-H2A8-H2J10-4A3CA2CS3-J11-5AC2A2C2G14-7A3CG15-8A2C16-9ACAN11(14-12A)14-7A19-17BDB7-15B4D7-14B4D8-15B3D8-3B13C2V8-17C2V7-18C8-2C2B3CB9C9-BA4B3AB2CI3C6-2A2-AC9A3CACI5-2A5-3AG-4AC2ACI4-I2A2-3H-3G2-S3A2-A-I3-IA3-4H3G10-A-3A4-4H5-S17-3H4-3G15-2A6C-3G14-A9CGS14-2A7C3G14-4AN5CG15-7A3CAN14-12A14-10(11A15-)6A3-A16-9B3D4B2D8-8B9D9-8B7D2ID8-B2C6B8D9-7C2I7C10-9CIC-5C9-10C3-2C-2C8-10CI3-I11-2C2B7CI-ICI10-3C7A2(2CI)5-2A4-2C2A2G2-2A3C2AI4-IA3-3H2A2GK-6A-AIA-I2A3-4H-2K2-K7-A-3A4-5H3-3G16-C2H4-4G14-5C-C5G14-A8C2GAb14-A8C2G15-2AC3N3CG16-3A3-4A-N14-2A5-4A15-3A-A-3A9(17-9A)17-4A4-A17-13D2B2I9-15DI10-15D11-8CI6D11-4C7-C15-2C25-2C23-I2CI4CI16-I9CI3-2I5-2A3-3C2B4A2CI2CAI5-2A3-A2C3A2G4AC2AI5-2A3-AO2CAG2K4-A-2AI3AE2A3-3HAG10-2A-4A4-5H4-2GAk15-4H2-5G20-GC4G14-C6-GC2GAi14-C8-2GAb14-2C362-D2I7D3-BI11-DI7D5-D11-2I2D2I3D17-3CD2I2C18-C79-2I-6I15-IC2BI7C-4I3-2I4-C2A2B5AC3A2B5-2A3-3AC11ABI-B-EA6-2C3AK4-7A2EA4-3HC10-7A5-5H3-G17-2HJH2-L4GK20-4G2X21-3GXAa24-Aa562-2I3-2I2A4I12-14AIA2I-IA6-21A5-21A6-AC4A4-9A6-3H9-7A6-4HJ2-2G17-2H3J-L3G17-H4-4G24-Aj589-3AI-8IAIA10-4AI15A6-20A7-19A8-18A8-H7-8A9-3J2-G2K18-2H3-KG19-H5-LG25-L407-
