model
size = 23 32 32, scale = 0.05, origin = -y
material 
  colors = A:#101111 B:#FDEFDA C:#553E3E D:#FFF E:#887C7C F:#F92F62 G:#946A6A H:#F8B148 I:#2A0E0E J:#F63C9E K:#F14288 L:#FCE0B6 M:#C52323 N:#F7A224 O:#F61969 P:#FF9D9D Q:#FC8599 R:#F9245A S:#F9C16D T:#F9638D U:#DD960A V:#8C5505 W:#7F4504 X:#DD880A Y:#C67A08 Z:#770505 Aa:#A15906 Ab:#B75807 Ac:#DD7A0A
voxels
201-3I-2I11-A5I6A3(9-14A)9-5A-8A447-G9-2D11-D2G5-I-DBD12-E-G2-P-4E12-2ED3G2EI2E20-3E64-2AI12-A3I2A2I5A8-15A9-14A8-15A6-9A-7A447-G8-4D9-5D3-6D9-DA2E2DGP6E9-2A12E19-4E57-A2-3I2(2-A)8-A2-A2I2ADI5A7-5A4D7A5-10AD7A5-12A11-3A2-4A455-2DG7-DE2D10-4DP-7D10-4E3D2E4D10-10E3D15-4E4C16-2E2-3C15-2I4-2C11-2A2I2C2ICA9-3A-I6D5A5-6A2DA3D6A4-11A2D6A5-14A8-3A5-6A427-D7-L-2L2E9-3DA3-2L-I3ED9-6DP7D9-2D2E3D4-3D9-9E5D11-8E4C13-5E5C13-I2-4C-2C9-A3-IC-7C6-2AIAI-A6D4A4-7AD3AD7A3-9A-10A3-9A2-8A4-2A5-2A3-4A15-A2-M21-MF20-MKT4-N16-F4-2HU21-S309-3D5-L-2L3ED7-5D2-4LIE2-D7-6DB9D7-6E4D-5D8-7E4D-3D13-3E2D2C3D13-2E2C-4CD13-10C8-2AI2-AC2D5CA7-6A6D4A3-8A2DA2D7A2-21A3-20A2-2A6-2A2-7A12-A2-MA5-2CA12-M2F5-3C11-M4F2-2HNVC12-2FK3-3HNH18-2H2U20-S285-4D2-3L-2L3E2D6-3D-2D2GL2DEIED-D6-4D-12D8-4E5D-5D8-5E2C8D9-2(E-)3C7D14-C2-3DC2D9-2(C-)2C-3D3CD9-ACI-IC5DC2D8-I3A-I5D3AD2-9A6D6A-10AD3ADAD5A-14A2DAD4A2-2(A3-)2A-9A14-A-MCM2CADA11-M2FA3MFNH2A11-2FA2FKF-2HCA11-3F2K2-2(5H18-)3H285-ED2PLA3L2-3E2D6-3D-3D2L2DIE4D6-4D2-11D6-D4E2(D-)8D8-4ED3C7D8-5E-2C7D8-2(CE)2-2C7D8-8C7D8-ACDC-C9D8-4AI2D-5DAD-10A11DA-9A13D-12A10D2-A2-11A5D2A12-3A-AD2C3D12-6FCH3C11-8F2H2C12-F2(-K)2-3HC18-4HC19-H285-5DA2D3L5ED6-E16D7-D-14D8-EB13D9-E4DC8D9-7C7D10-6C7D9-6C8D9-A2DC10D9-A13D2-7A7DB6D-8A6D8B-8A2-A2D9B-3A2-2A2-5A8B7-2A2-5A2B3C2B12-4F6CB12-6F-2HC12-3FK3F2-HC13-F2-T4-3C305-7D5BD2EDB6-6D7B4D7-2DB3D5B4DB4-E2-3EBD6B5D4-G3-2E2D6B4DB4-G3-2E2D2CB8D4-3G3CD4C8D6-G-2C2D2C9D8-E14D7-IA2D4B4D4A2-5A7D2B3D4A-7ADA3D6B4A-10A2D6B4A2-A5-6A5B4A5-8ACA4BC3A12-3F7CA11-5F6CA11-5FC2-4C11-2FKT2F2-3CA12-T6-4A19-2A2I19-2I2A19-I3A8(19-4A)22-A3-7D13B3-DB4D14B3-DBE2D15B3-2G4E14B3-2G5E13B3-3G3E2D10BDB3-4G3CD9B3D4-G-G2C3D6B5D6-3CBD6B6D5-2IDA7B7A-5AD3A6B7A-6AD3A2D3B7A-11A4B7A5-A-3AHA4B7A5-7A3CB7A9-AaY-4CA4C2A11-3F8CA11-4F7CA11-5F5C2A11-2FT2-2C5A2(16-7A)16-A2I4A16-2I5A16-I6A6(16-7A)19-4A3-5D14BJ2-5D15BJ2-6D14BJ2-3GD2E14BJ2-4G3E13BJ2-4G2E15B3-3G2C15B3-3G3C14B4-4C15B5-ID3A4B9A-4A2D4A3B15ADA-3A2B9A2-5A3-2A2B9A2-A-2A-A-2AHBC9A9-X3H3C7A8-NHY2H4C6A7-V-N2-F-F4C4A6-HNV2-4F5C3A7-S3-4F4C4A12-F-3C6A14-AI7A14-2I7A4(14-I8A)5(14-9A)19-4A-2ID18BJ2-D3(19BJ3-)2G17BJ2-3G18B4-GC17B4-3C16B5-C3BA13B6-AB3A2B10A-3AIAB5AB17A3-2AB10A-6A2-H2AB10A2-3A4-W3H2C8A8-Ab4H3C7A8-X2H-H-2C7A6-2HNHN-5C6A6-3H3-5C6A5-HS2H3-4C7A6-S5-CAC8A2(13-10A2(13-I9A))13-I9A4(13-10A)16-2(2A3-)5(19BJ3-)E18BJ3-2E18B4-2C17B4-4C3A12B4-I4C14A2-2A3C-A-19AC4-2(19A3-)ACH3C8A9-W3H2C8A7-Ac3H2-3C7A7-3H3-3C7A5-5H-5C7A2(5-3H3-2C10A)2(11-12A)2(11-2I10A)11-I11A2(11-2I10A)4(11-12A)15-A3-4A2(2-20BJ)2-I19B2(J2-20B)J3-2E17BJ3-2EC17B4-E2C16B5-4CA13B4-5C14A3-A3C2A2-17ACA4-19A4-14A-3A3-5C9A8-7C8A8-C3-3C8A7-3H2-4C7A6-H-H3-3C8A6-2H2-C-C10A6-H3-2C11A11(10-13A)10-2A-A2-7A5(2-20BJ)2-2G18BJ2-2GE18B5-C17B5-4CA13B5-4C14A4-A2C2A-13A-7A-F-17A3-2F14A3-A2-2F4C11A6-2F5C9A8-F2-3C9A12-3C8A11-3C9A9-3C11A9-2C12A12(9-14A)4(-21BJ)-3G18BJ2-3G17BJ2-3GC17B4-GC17B5-CAC3A12B4-5C14A4-AC2A2-19A2-2F18A2-3F15A-2A2-2F2C13A3-A2-2F3C11A7-3F3C10A8-F2-3C9A10-3C10A9-3C11A9-2C12A12(9-14A)4(-21BJ)-3G18BJ-4G18B2-3G18B4-GC17B4-2CB3A13B4-2C17A4-AC2A-20A2-2F19A2-2F18A2-3FC15A4-2(2F3C11A7-)3F3C10A9-3C11A8-3C12A8-2C13A12(8-15A)4(-21BJ)-4G18B-5G17B2-4G17B4-2G17B4-GC2BA14B4-2C17A3-A2C17A-3AB2A-2(2F18A3-)2F2C14A-AF-3F2C11A4-5F3C11A5-F-2F3C11A8-F2C12A8-3C12A8-2C13A12(8-15A)4(-21BJ)2-4G17B3-4G16B2-5G16B4-3G16B4-2GC16B4-2CB16A3-ACB17A2-2AB3A-20A2-2FC17A3-2F2C13A2-FA4F2C11A4-5F3C11A4-5F2C12A7-F3C12A2(8-2C13A)12(8-15A)3(-21BJ)-22B3-3G17B3-4G16B4-3GC15B4-3G2C14B5-G2C15B4-3CB15A3-20A2-8AC12A-7A-3C18A3F3C13A-AM-2F3C11A4-MFK2F2C12A5-K2F3C12A6-KF2(3C12A8-)2C13A12(8-15A)-21BJ-B2I18BJ-BI19BJ-22B2-B3G17B4-3GC15B4-3G2C14B5-2G3C13B5-G3C13BC5-CACB12A2C2-A2I15A3C2-3A-3A3C9A2C-3A3-A5C10A-4A2-A6C13A3-K2F-3C9A7-KF2CA3C8A6-Q2F5C9A7-K-4C10A9-3C11A9-2C12A11(9-14A)9-6A-7A2(4-18BJ)4-BE17B4-3E16B4-2E17B3-3GCEBC13B4-2G2-E2C12B5-GC-2C12BC5-5C11B2C5-A3C8AC2A3C2-A2I11A7C2-2A3-3AC4A8C-3A3-3A4C2A3C4A-3A3-4A3C3AC5A-3A6-5C8A11-4C8A10-5C8A9-5C9A10-3C10A9-C13A11(9-14A)9-6A2-6A4-18BJ4-BE17B4-3E16B4-4E15B4-3E2BC13B5-E-2E2C12B4-2C3-2C12B5-C3-2C10B2C6-4C7B2CB3C4-IA4C6A6C3-13A7CH2-3A-8A8CH-3A3-AKA10CA2C2-3A2-OKA10CA2C-3A3-2OK2C-2CA3C3AC8-O6C8A10-5C8A10-4C9A9-3C11A10(10-13A)9-14A10-13A10-6A2-5A4-18BJ5-2E16B5-3E15B6-2E5BE9B5-E-E4C2E3G6B9-3C2E3G6B5-C4-3CE3G6B6-C2-6C5B3C6-I4C2BC2B7C3-3I4CB4A6C5-11A3CF2C4-12A3C4F-CH2-5AK-2A6CF2C-2C2-2A-A-2KACH8CA2C2-A4-3K2-8CA2C8-2O-7C5A12-5C6A12-3C8A9-2C-C10A12(11-12A)11-6A12-17B6-B2E14B7-3E2BE10B6-3E2C3E3G6B8-4CE5G5B10-2CE5G5B11-CE5G5B10-4C3G3AB2C6-2I-I5C2A6C3-3IC2I2C5AC2FC3F3-3ABAIC3A3C4F-F3-9AHA2C5F-CH-7A-A-2HC6F2-H2-A3-AZKA-2H2C4F3CH8-2O-3H9C13-H-2(3CA)14-4C5A11-5C7A13-4C6A13(13-10A)7-BE14B8-2E13B7-3EB3E9B7-6E2-2GC5B7-4C5-2GC4B15-3G4BC15-3GC2B2C11-IC-3GC3ABC10-I5C3A3CB4-A2I-2IC5A4FCFC3-4A2-IC3AC8F3-4A-2A-AH-7F2C2-8A-3H6F2-H3-A-A5-4H4F3C9-O3-3HC2-4C13-3H-7C15-C-C5A12-3C-2C5A17-6A14-A-7A12(14-9A)8-7E8B8-8E7B10-3E-3E6B11-E4-G6C17-G5C18-5C15-G-G5C15-2G6C10-4I4CA4C4-2A3-I2C4AC2F4C4-2A4-I3A8FC4-2A3-I5-6F2A3-7A-4H6FC5-A4-A-4H5F14-4H21-H5-C-2C15-4C4A17-C2A2CA13-C3-CA4C17-6A12(16-7A)8-3EI8EB2E9-14E15-2E2C4E16-E6C2(18-5C)18-4C12-2I-CI-I5C10-I5CI6C5-A2-2AC4A8C4-2A4-5AF2A2C-CA5-2(A4-)6F-A4-6A2-HN-5F8-A5-4H-3F14-F-3H2-F14-2(F-)H19-F5-7C18-3C-C18-4C20-A288-2E3-EI7E15-I7E16-E3C3E17-6C78-4I2C3-I3C10-A7CI5C5-2A-AIAB4AC2A2(CA)5-A3-9A3C2A5-2A2-4A2-3M2F-A6-6A4-M3FQ8-2A-2A2-H2N4F13-M-M3H-3F13-2F-RHN17-2KQ527-3I3C-6I7-A2I2ACAC3A4CA6-17A8-7A2-5A10-3A6-AF10-5A5-M2F12-2A2-N-M2FQR13-M-3H3F15-2K-HN18-R2-H526-6A5IA8-2A-12A8-15A9-5A4-5A9-4A5-4A8-A-3A18-4A5-2FR17-N3-KR17-N4-Q372-
