model
size = 26 32 31, scale = 0.05, origin = -y
material 
  colors = A:#FDEFDA B:#FFF C:#F63C9E D:#887C7C E:#FCE0B6 F:#101111 G:#553E3E H:#946A6A I:#2A0E0E J:#100 K:#FF9D9D L:#774949 M:#FBD091 N:#2B0500 O:#200000 P:#461A01 Q:#E0BEA5
voxels
26-KBH23-4BDH20-6B20-9B17-8F18-EFDBE-EDJD16-J-EBF-EFBE16-3J3F-2F17-FMHJ3G2D17-FBDJBEDEB17-F2BFBEFB2F16-F2BFE2F2-GD15-3F4-L4D17-2D-L5D16-Q2DLE3DABAF-B12-QDBE-DEA3BA2F10-E4B-EK2B2AIA2-B10-2E2-EB7-A3B20-3BEB63-B23-3B24-B25-B154-B2-E48-3B2HK-2H17-3B2DH-3K16-6B3D17-11B15-2BF2B6F15-EF-2BJ-2FBF15-F-D4F2B3F15-2(F-)4F-FB14-B2E2FG3DF-B14-F2B-2BD2BFE15-F7B3FJD13-6B2F-2FD14-6FG4D15-3J2D-6D2-E11-D-10D2BKB10-DA3DBE4D5B10-5BE12B8-2E2-E2BKB2A7B9-E2-E2B3EA6B13-3E4B2-2B14-E3B9-EB10-2BE21-4B22-3B23-2BE23-A3(BE23-E)BE23-3BE22-4BE47-5EDK2DH16-BD2B6DH15-7B3D16-7B-2BDB14-BF3B3-2FBF14-2F3BFB-3BD15-2FBF4BF2BJ13-2(FB)6F2BEG12-5BF3D2B2EF12-3B-6BEF2J12-10BDF2D12-2B-4B2F-3D13-3F2B2F-4D4-EA8-F2-F2G6D2-BAB9-3D2-6D6B9-4DBDE3D8BDB6-2BDG14BDB6-2B2-5B-6B-2BF7-B2-2B-3E7BIK11-E6B-3B-2BK10-BE4B4-2B-3B9-2BE2B10-KB7-5B21-3B23-A-B23-A2B2(23-ABE)23-EBE23-3BM22-2B4D10-3D33-2D6E18-3D3BDBE17-8B3DE14-9B2DE14-5BF5BEF13-BF3BF5BE14-F-10BJ13-4BFBF2BF3B13-5BF2D4BFJ14-BF6BEBF2D11-4B-8BD12-5B2FBDF3D13-3FB2-2F-D-2D4-AD8-2J2F3D2-2D2-5B8-2D2-7D9B6-3D-5DB-9B6-2D2-15B7-B2-6B2-7BI7-B-F4BE10B10-F5B-4B2E4B8-F5B6-B2-B10-4B10-3B7-3B14-2B7-3B23-2BE23-A2B23-A3(DA23-B)2DMD21-B3DM3D9-2D33-3D5E18-4D4B2E16-5B-2B2DED14-G7B2D2ED13-9BDFEF13-10B2E14-BF9BDJ13-2B4-5B2D13-2B-3B2D4BF13-12B2(DF)10-13B2D11-7B6D5-2F6-4B2-F3D-2D4-3D6-B2-5D2-2D-AB-4B7-8D-3D9B4-10D11B6-2D2-16B7-2F7B-8B7-F2-3B-10BI10-F2B3-B-3B2-3B9-F3B10-2BK8-F3B11-3B7-F2BE13-E8-2BE14-B8-2BE23-ADK3(23-ADH)MD21-B2DM6DH15-B2DM-8D2HI2-D7-D2H23-6D2E18-DB3DB4E16-5B-2B2DED14-6B-B2D2E2D12-8BD-D2F13-6B2-2B3D13-5B2-4BDJ14-2B4-4BDF-J11-7BD-2BD2JD11-12B4D10-8B2(-B)3DF10-B-6B6D-E-F2DFA4-4B2F2D-5D4-2D2B4-2B2(DB)10D2-3BF4-14D6B-B4-4D2-3D11B-AE3-2D3-15BA8-F15BA9-F7B2-B2-2BI10-FB2-4B2-B2-3B9-FB11-4B8-F3B11-3B7-F3BE12-B8-3BK13-B8-B2(DK23-A)2DH22-A3D12-H9-A2DED7-GH5-D6-AD-E6D3HD2-3D7-B3DB14D7-3DH22-2B6D18-2B4DEBDE16-8B4D14-4B-3B6D12-9B3DFJ12-11B2D14-10BDGJG11-3B4-4BDF2J11-8B-2BDF-2D10-BA9B5D10-2BA6BA2B3DE10-B2A6BA4DEDF3DB5-7B7DED-3DB5-6B13D3BF3-BD2B2G-6DA7BAF3-3DB2-14B2AE3-FDB2-15BA7-F10B2(-2B)A8-F6B-3B4-BA9-F3B-2B6-3BA9-F2B10-3BA7-2F2BE11-3B7-BA2B13-B8-3BH13-B8-2BH23-B2DH14-E7-2A2D13-HD7-2A2D9-GH-H2DE6-AB4DG2F-N2GD2H2D-D6-2AB4D2AGH9D6-4B6A4DB3I2D6-4D-D2H18-7DBH17-3B3D-B2D16-8B4D14-A7B3DF2D12-2A2C6B4DJ11-AB2C7B2DJH11-2B2C7B-F3J10-2B2C2BA3B3-FJD10-BA2C6AB2D-2D10-2A2C6ABD2-2DH2E7-2A2CAB5A2B3D3E7-2A2C3B5A8D2B4-3A5B3A8D3BA3-3A4B3A3DA4D5BA2-6B5AD4A6B2A3-2B-12A5BAI4-F-B5AB4A7B8-4A12B9-F2A2B3-9B9-FA3B6-7B7-FA3B8-E5B6-F2A11-FE3B7-3A11-F2E2B7-2AD13-E2B7-3AH13-EB7-2A3D7-F-2G2DB7-2A3D6-FO2GH3DED5-2A2DG6-OG2DH4D6-3A2DG4-F2A7D6-4A2D4F4ADB5D5-15A5D6-2(7DH18-)2A5DBH2D15-4A4B5D13-2A2C4BA2DFJD12-2A3C2B2AB2DFD2J10-2A3C2B2A3BDF3J9-2A3CB2A3B2DFN11-2A3C4A3B5D9-2A3C5AB6D9-2A3C5A2B6D8-2A3C5A4B5DE6-2A3C11ADB3DB2A2-2A2CB10A3D4B2AE-3A3B10AD3B-3BA-2B2AB12A6BA2-F2B14A2B-2E7-13A3BE8-F6A2B2A6BE7-F6A-2B-8B7-F3ABAE4-2E6BE5-F2A3BE7-E6B5-3AB2E7-F7B5-2A12-FA4B6-2A2D11-EA3B6-2A3D10-EA3B6-3A2D7-FNA2D3BI5-3ADI7-FA4DBD6-4AG5-2F2A3DB3D5-5A2F2-F5ADB4D5-7A2F7AB4D5-17AB2D6-2(7D19-)2A5D3HD15-5A4B2DLD13-2A2C6A2DFD12-2A3C5AB2DF-J10-2A3C5A3B3J10-2A3C5A2B2DG-G9-2A3C6A2B4D9-2A3C5A3B3DH9-2A3C5A4B5DE6-2A3C6A3BAB5D5-2A3C12ABAD4BA-2A2C12A8BA-B16A5B2EA-B17A4BA4-B17AB2E5-2F15A2BA6-F6ABAB6A3B7-F5A2B2-E2B4A2B7-F6AI3-I2B3A3B5-F3AB2AI5-F2B3A2B5-A-A3BI6-FB4A2B5-2ADED9-F4A2B5-2A2D11-F2A2BD5-2A3D9-NA4BD5-4AF8-F2A4B6-AC2AI7-F3A4BD5-2C2AI6-F5A2B3D4-2C3A6F6A2B3D4-2C16AB3D4-2C17A3D4-8D18-G8DH16-3A4DBDBH-L13-6AB2A2B2LD12-2A2C7ADG-D11-5C6ABD3G10-5C6A2BDJ-G9-5C7A2BD-G9-2A3C9A3D9-2A3C10A2D9-2A3C10AB3D2E5-2A3C11A5DB2A2-2A3C15A5B-2A2C16A5B20A5BE-2B18ABEA3-FB18ABE5-FB14AE-2E5-2F5A3B11A6-F5A2B2-IB6AB7-F5AB2IF-IB5A2B5-F6AIF3-F6A2B5-6A2F4-2F5A2B5-3ADAF8-F4ABK5-2A3D9-F4A2B5-3ADF8-F3A3BD5-3AI9-F2A5B5-2CA9-F4ABABI5-2CAI7-F8ADI4-2C2A7F9A3D3-2C18A2D4-2C17A4D3-4G4D18-4G6D2H2G12-5ADA3DBHDG12-11A2DL12-4C8AD4G9-5C9A2JG9-5C9AD11-5C9A3D2H7-5C10A2DH8-2A3C10ABD4-B4-2A3C10AB5D2BA2-2A3C11A5D4B-2A3C16A4BE2A2C17A4B3AC17A3BAE-21AB2A2-AB18ABEA3-2FB12A2E-2E8-7AB8A-2BI5-F5A3BI7A3BD5-F5AB4I6A3B5-F6A3-F-I5A3B5-6AF5-F5A3B5-6AF6-F5ABK5-5AF8-F4ABK5-3A3F8-F3ABD6-2AI10-F4ABD6-2CI9-F5A2B3D3-2CI4-5F8A3D3-2CA4F14A2(2D3-2C19A)2D3-4G4D4-G13-5G5DP2G13-7A3D2BG13-13AL12-4C10AL11-5C10AL10-5C9A2DL9-5C10A2D2L7-5C10ABD9-5C10ABDHD2EB4-5C11A5D4B-5C12A2(DA)4B-5C12A4-A3B3A2C12A5-E3B3A2C11A6-2EBA-2A2C11A6-2EA2-2AC12A2E3-E2A3-F14A5EI6-F14A11-F6AB8A3-2B4-JF4ABIF3I6A4B4-F4A2BF2-F-F5A4B4-6A2F4-F5A3B5-6AF6-F4A3B5-AC3AF8-F4AB-K4-ACA3F7-F5AB-2K3-ACF10-F4A2B2DK3-2CF8-2F6AB3DK2-2CF6-2F10ADK3-2CA5F14AK3-2C19A2D3-2C20AI3-6G6D14-7G4DG14-8AD3AG13-13AL12-4C10AL11-5C10AL10-5C11AL9-5C11ABLG7-5C10A2BD-D6-5C11A5D2B3-5C12A3D5B-5C18ABA-5C19ABA5C18A2BA5C18AB4A3C16AB3A-2A2C15A3E2A2-FA2C11A6E6-F2C14A2B2I5-F2C15A3B5-F3A2B-IFAF6A4B5-4ABF3-3F5A4B4-5ABF6-F4A4B4-5AF7-F4AB-2B4-2C3AF7-F4AB2-2B3-2CA3F7-F5AB-DB3-2CF9-F6AB3D3-2CF7-2F8AB2D3-2CF7-F10A2D3-2CA7F11A2D3-2C20A2D2-2C20AD3-7G6D13-GA6G5D13-11ADG13-12AG13-3C10AL12-J3C10AG11-5C10A3L8-5C11ABDGD6-5C11AB3DB5-5C12A3DB-2A2-5C13AD6A-2(5C21A)5C20AM5C21A5C20A-2A3C13AB3E2A2-2A3C10A2E2-2E5-2(FA3C13A4B4-)FA2CA2BIF2A2F6A3B5-4ABF2-2F2-F4A4B4-5AB2(F6-F4A4B4-2C4A)F6-F4A2B-2B3-2C2A3F5-F5A2B-2B3-2CAF7-F9A3B2-2CF8-F9A3D2-2CAF5-2F10A2D3-2C2A5F12A2D3-2C19A3D2-3C19A2D2-8G4D14-9G4D13-2(11A2DG12-)3C8A2DL12-4C8ADAL11-5C10AL10-5C11AB3A6-5C16A5-5C17A4-5C17A-2A-5C21A5C16A4-A5C15A2E2-2E5C14A7E5C14A6E-5C14A3EA3-2A3C12AE-K6-2A3C11A4BK5-2A3C12A2BKB5-2A2C15A3B4-2A2C3A6F5A4B4-2A2C3A2F4-F5A3B4-3C4A2F4-F5A4B3-3C3A3F4-F5A4B3-3C2AF6-F7A4B2-2C2A2F5-F9A3B2-2CA3F4-F11A2D2-2C2A3F-2F11A3D2-2C5AF13A2D3-2C19A2D3-4C18A2D2-9G2D15-10G2D14-7AGAG2D14-11A2D13-11A2DG12-4C7A3DG11-5C7AD2AL10-5C10AL-3A6-5C16A5-5C17A4-5C20A-5C11AE8A-5C10A2E4A-4A5C9A3E3A2E-3A5C9A3E-2ABE3A-5C9A6EB2A3-5C9A3E-2EBA4-5C10A2E2-B6-2A3C11AEA2-B5-2A3C13A2-B5-2A3C12AB-2B5-2A3C4AF-I6A4B4-5C3AF3-F6A3B4-4C4AF4-F5A4B3-3C4AF4-F7A3B3-4C2AF4-F9A3B2-4CAF5-F9A3B2-2C4AF2-2F11A2D2-2C5A2F13A2D2-2C19ADI3-3C18A2D3-4C17A3D2-7G-G-D15-10GD15-6A4G2D14-9A3G14-11AD14-4C7ADG13-5C6A3D4-2G6-5C10AGLG3B5-5C11AG4A5-5C18A3-5C19A2-5C17A4-5C11AE4A3E2-5C11AE4A2E2A-5C11A2E3AE3A-5C10A4EAB2A3-5C10A2E-E2BA4-5C9AB3E3B5-5C10AEABA-2B4-2A3C12AB2-3B3-2A3C5A2I5A6B3-2A3C3AF3-F6A3B4-5C3AF3-F6A2BI4-4C4A4-F7ABAI3-4C3AF4-F9AB3-5CAF5-F9AB3-5CA2F2-2F9A3B2-2C5A3F12A2D2-3C18A3D2-3C18ADI3-4C17A2D3-5C17A2D2-7G-G17-2GA4G-G-D15-4A6G2D14-6A4GDG14-9AG4D12-3C7A3D3G10-4C6A3D2A2G2H7-5C6AD3A2HA2B6-5C6AD9A2(5-5C5A3D8A)5-5C6AD9A5-5C11AE4AE2A2-5C16A2EA2-5C11AE7A2-5C10AE2-4A4-5C10AB-2E3A4-5C11A3B3A4-5C11AB4-A4-5C11A4-2B2A2-5C5AF6A3-4B2-5C4AF-F6A5B3-5C3AF3-F5A5B3-4C4AF3-F6A4BI2-4C2AF5-F7A2B-B2-5CAF4-F9A2B3-5CAF3-F10A3B2-3C4A3F11AB2D2-3C19A2D2-4C17A2D3-5C16A2D3-5C17A2D2-4G22-5G21-3A6G17-5A5GD15-8AG2DG14-2AC7A4DG11-4C5A5DP11-5C5ADH3D2-H8-5C4A2DH2DAH10-5C4A4D7A6-2(5C4A4D8A5-)5C5A2D4AE3A2EA3-5C15A2E2A2-5C10AEAE2A2E2A2-2(5C17A4-)5C12A2B2A5-5C12A2B3A4-5C12A2B-B2A3-5C13A6B2-5C5AF8A3B2I2-5C4A3F6A5BI2-4C5A3F7A5B2-5C2A2F-2F8A4B2-6CAF3-F9A3B2-6CA2F-F11A4-4C5AF12AB3-4C17ABD3-5C16A3D2-5C16A2D3-5C16A3D2-3G23-4G22-4AG21-5A4GD16-4A5GDG15-5AG2A2D3-G12-2AC5A2DH3-G11-4C5ADH2-2D11-5C4ADH-HDH11-5C4A2DH2DA2E9-5C4A2DAD2AEA2EA6-5C3A5D6A2EA4-5C4A2D3E5A2E2A3-5C6A3E5AE-E4-5C6A3E5AE4A2-5C10AE6A4-2(5C16A5-)5C10A2-4A5-5C10A3E4A4-5C10A4E3AK3-5C10A3E2A4B2-5C14A5B2-5C15A3BI2-5C4AF11A3B2-6C2A3F10A3B2-6C3AF12A-B2-9C13A4-9C13A2(2D2-5C16A-)D3-5C16AD4-4G22-5G-2G18-3A5G18-4A4GD17-4A3G3D16-4AG2DA2D16-4A6D16-2AC2A2DA2DH15-4C4A2DH-3H11-5C3A2DE-D3E10-5C3A2D4AEA2EA7-5C3A2DE2(A2E)AE2A5-5C3A2D4EA4E3A4-5C5A4E2A3E2A5-5C5A4EA-2A-4A3-5C6A3E6A6-5C16A5-5C10A3E3A5-5C9A5E2A5-5C9A5EA6-5C9A5E3A4-5C9A5E2A2BK2-5C10A3E3A3B2-5C16A2BI2-6C15A3B2-7C14A2BK2-7C16AK2-10C12A4-10C11AD4-9C11A2D4-5C16AD4-5C15A2D30-4G22-3A2G-G19-3A2G21-4AG2(-D)17-4A4DHG16-3A5D2HG15-2ACA6DH15-2AC2A5DH-3H11-4C4A2DE-DE2A10-5C3A2DE-AE3-EA7-5C3A2DE-4EA-A7-5C4ADE-E2-2AE3A5-5C5A3EA2-5A5-5C5A3E2A-4A6-5C6A3EA-3A7-5C14A7-5C10A2E2A7-5C9A4E2A6-2(5C9A5E7-)5C9A5E2A2B3-5C10A3E2A-2BK2-5C14A-A2BK2-6C15A2BK2-7C15ABK2-7C15A2B2-11C11A4-11C9A2D4-10C10A2D4-5C15A2D4-5C14A4D55-2HG23-A3HG21-2A2HD21-3A2D21-3ADH2-H18-3AD2E4H16-2ACA6E2-2H12-2ACA5EDE-EA12-4C2A3EDE-2E3-A8-5C4ADE2(2-2A)7-5C5AE3A-6A5-5C5A-E3A-4A6-5C5A-E7A7-5C6A3E3A9-5C8AEA-2A8-5C13A8-5C9A2E2A8-2(5C9A3E2A7-)5C9A4E3A5-5C10A4E2A5-5C13A4-B3-7C13A-2B3-8C12A2-B3-8C13A5-11C10AB4-11C10A5-10C10AD5-5C14A2D5-4C15A2D58-H24-G25-2H24-2AH23-3AD22-3A3E20-3A5E18-3A5E-E16-2ACA6E3-A12-4C2A3EA2-2A-A10-4C6A-9A6-5C5A-7A8-5C5A-E5A9-5C6A2E4A9-5C7A2E3A9-5C7A3E3A8-5C10AE2A8-5C10AEA9-5C10AE2A8-5C10A2E2A7-5C11A2E2GA5-5C13ABLBA4-7C14A2(5-8C13A)5-11C10AB4-11C9A6-10C9A7-4C15A7-3C16A137-2D24-A2D23-3AE-E20-2(3A5E18-)4A4E18-OAC3A3E17-4C6A-5A2(10-5C5A-2E3A)10-5C5A4EA11-5C6A3E2A10-5C6A3E3A9-5C7A2E3A2(9-5C10AEA)G8-5C10AEL9-5C10A2EL3-B4-5C11AEL-L2B4-7C10A2B-G5-8C10AB7-8C10AD2A5-10C9ADA5-10C9A7-CA6C11A7-2A2C15A7-17ADA137-D25-3D2(23-3A)2E21-3A4E19-4A4E18-6A2E3-A14-2AC6A2-E3A11-4C5AE-3EA11-4C5AE-5E10-5C5A6E10-5C6A5E10-5C6A6E9-5C7A6E8-5C10A4E7-5C10AEG9-5C10A2ELG7-5C10A3EG7-5C11A2E2-2I4-7C10AB8-8C9AD8-8C9A9-9C9A8-9C8A9-CA6C10A8-19A7-9A3D4A2D138-D25-2D2(24-2A)24-4A2E20-6AE19-8A3-E14-9A2-E2(14-2AC6A3E)2-2E10-4C6A3E-2E10-4C7A5E10-4C7A7E8-4C8A6E8-4C11A3E8-4C11AE10-2(4C11A3E8-)4C12A2E8-5C11A2D8-2(7C10A9-)2(CA6C8A10-)17A9-18A8-13D2A2I165-D25-2(2A24-)2A-3A20-6A20-7A19-8A18-9A2E15-2AC6A2E15-2AC7AE4-E10-3C9A2-3E9-3C9A5E9-3C10A3E10-3C12AE10-3C11ADE2(10-3C12AD)10-3C12A11-3C13A10-5C11A-D8-5C10A11-11AI3A11-5A2D4AI2A12-6A2D3A2I2A11-A2D9AI2AI10-D2I7D3-AI193-A25-A28-A22-A2-2A21-6A20-7A19-2(10A16-)11A15-2(13A13-)3(14A12-)14AD2(11-15A)11-14A12-13A13-11A2I13-11A15-5A2-3A16-D7-K24-D304-A2-A22-A-3A21-5A21-7A-2I16-9AI16-10A16-12A14-13A13-4A2D7A13-6AD7A12-6AD2AK4A12-6AD2A2K3A12-6AD3A2K3A11-I5AD4AKA13-6AD4AIA13-6AD4A2I13-6AD4AI14-6AD3A16-4A4-2A94-
