model
size = 13 17 16, scale = 0.05, origin = -y
material 
  colors = A:#F90 B:#EEE C:#BBB D:#FC6
voxels
------------- ------------- ------------- ------------- ------------- -----CCC----- -----CCC----- -----CCC----- -----CCC----- -----CCC----- -----CCC----- -----CCC----- -----CCC----- ------------- ------------- ------------- ------------- 
------------- ------------- ------------- ------------- ------------- -----CCC----- ------------- ------------- ------------- ------------- ------------- ------------- -----CCC----- ------------- ------------- ------------- ------------- 
------------- ------------- ------------- ------------- ------------- -----CCC----- ------------- ------------- ------------- ------------- ------------- ------------- -----CCC----- ------------- ------------- ------------- ------------- 
----CCCCC---- ----AAAAA---- ----AAAAA---- ----AAAAA---- ----AAAAA---- ----AAAAA---- ----AAAAA---- ----AAAAA---- ----AAAAA---- ----AAAAA---- ----AAAAA---- ----AAAAA---- ----AAAAA---- ----AAAAA---- ----AAAAA---- ------------- ------------- 
--CCCCCCCCC-- --AAAAAAAAA-- --AAAAAAAAA-- --AAAAAAAAA-- --AAAAAAAAA-- --AAAAAAAAA-- --AAAAAAAAA-- --AAAAAAAAA-- --AAAAAAAAA-- --AAAAAAAAA-- --AAAAAAAAA-- --AAAAAAAAA-- --AAAAAAAAA-- --AABBBBBAA-- --AABBBBBAA-- ----BBBBB---- ------------- 
-CCCCCCCCCCC- -AAAAAAAAAAA- -AAAAAAAAAAA- -AAAAAAAAAAA- -AAAAAAAAAAA- -AAAAAAAAAAA- -AAAAAAAAAAA- -AAAAAAAAAAA- -AAAAAAAAAAA- -AAAAAAAAAAA- BAAAAAAAAAAA- BAAAAAAAAAAA- BAAAAAAAAAAA- BABBBBBBBBBA- BABBBBBBBBBA- BBBBBBBBBBB-- ----BBBBB---- 
-CCCCCCCCCCC- -AAAAAAAAAAA- -AAAAAAAAAAA- -AAAAAAAAAAA- -AAAAAAAAAAA- -AAAAAAAAAAA- BAAAAAAAAAAA- BAAAAAAAAAAA- BAAAAAAAAAAA- BAAAAAAAAAAA- BAAAAAAAAAAA- BAAAAAAAAAAA- BAAAAAAAAAAA- BABBBBBBBBBA- BABBBBBBBBBA- BBBBBBBBBB--- ---BBBBBB---- 
CCCCCCCCCCCCC AAAAAAAAAAAAA AAAAAAAAAAAAA AAAAAAAAAAAAA AAAAAAAAAAAAA AAAAAAAAAAAAA AAAAAAAAAAAAA AAAAAAAAAAAAA AAAAAAAAAAAAA AAAAAAAAAAAAA AAAAAAAAAAAAA AAAAAAAAAAAAA AAAAAAAAAAAAA BBBBBBBBBBBBA BBBBBBBBBBBBA BBBBBBBBBBBB- --BBBB---BB-- 
CCCCCCCCCCCCC AAAAAAAAAAAAA AAAAAAAAAAAAA AAAAAAAAAAAAA AAAAAAAAAAAAA AAAAAAAAAAAAA BAAAAAAAAAAAA BAAAAAAAAAAAA BAAAAAAAAAAAA BAAAAAAAAAAAA BAAAAAAAAAAAA BAAAAAAAAAAAA BAAAAAAAAAAAA BBBBBBBBBBBBA BBBBBBBBBBBBA BBBBBBBBBBB-- ---BBBBBB-B-- 
CCCCCCCCCCCCC AAAAAAAAAAAAA AAAAAAAAAAAAA AAAAAAAAAAAAA AAAAAAAAAAAAA AAAAAAAAAAAAA AAAAAAAAAAAAA AAAAAAAAAAAAA AAAAAAAAAAAAA AAAAAAAAAAAAA AAAAAAAAAAAAA AAAAAAAAAAAAA BAAAAAAAAAAAA BBBBBBBBBBBBA BBBBBBBBBBBBA BBBBBBBBBBBB- --B-BB-BB---- 
CCCCCCCCCCCCC AAAAAAAAAAAAA AAAAAAAAAAAAA AAAAAAAAAAAAA AAAAAAAAAAAAA AAAAAAAAAAAAA AAAAAAAAAAAAA AAAAAAAAAAAAA AAAAAAAAAAAAA AAAAAAAAAAAAA AAAAAAAAAAAAA AAAAAAAAAAAAA AAAAAAAAAAAAA BBBBBBBBBBBBA BBBBBBBBBBBBA BBBBBBBBBBBB- --B-BBBBBBB-- 
CCCCCCCCCCCCC AAAAAAAAAAAAA AAAAAAAAAAAAA AAAAAAAAAAAAA AAAAAAAAAAAAA AAAAAAAAAAAAA AAAAAAAAAAAAA AAAAAAAAAAAAA AAAAAAAAAAAAA AAAAAAAAAAAAA AAAAAAAAAAAAA AAAAAAAAAAAAA AAAAAAAAAAAAA ABBBBBBBBBBBA BBBBBBBBBBBBA BBBBBBBBBBBB- --B-BBBBBBB-- 
-CCCCCCCCCCC- -ADDDAAAAAAA- -ADDDAAAAAAA- -ADDDAAAAAAA- -ADDDAAAAAAA- -ADDDDDDAAAA- -ADDDAAAAAAA- -ADDDAAAAAAA- -ADDDAAAAAAB- -ADDDAAAAAAB- -ADDDAAAAAAB- -ADDDAAAAAABB -AAAAAAAAAABB -ABBBBBBBBBBB -ABBBBBBBBBBB --BBBBBBBBBBB -----B--BB--- 
-CCCCCCCCCCC- -ADDDAAAAAAA- -ADDDAAAAAAA- -ADDDAAAAAAA- -ADDDAAAAAAA- -ADDDDDDAAAA- -ADDDAAAAAAA- -ADDDAAAAAAA- -ADDDAAAAAAA- -ADDDAAAAAAA- -ADDDAAAAAAA- -ADDDAAAAAAA- -AAAAAAAAAAA- -ABBBBBBBBBB- -ABBBBBBBBBB- --BB--BBBBB-- -------BB---- 
--CCCCCCCCC-- --AAAAAAAAA-- --AAAAAAAAA-- --AAAAAAAAA-- --AAAAAAAAA-- --AAAAAAAAA-- --AAAAAAAAA-- --AAAAAAAAA-- --AAAAAAAAA-- --AAAAAAAAA-- --AAAAAAAAA-- --AAAAAAAAA-- --AAAAAAAAA-- --AABBBBBAA-- --AABBBBBAA-- ----BBBBB---- ------------- 
----CCCCC---- ----AAAAA---- ----AAAAA---- ----AAAAA---- ----AAAAA---- ----AAAAA---- ----AAAAA---- ----AAAAA---- ----AAAAA---- ----AAAAA---- ----AAAAA---- ----AABAA---- ----AABAA---- ----AABAA---- ----AABAA---- ------B------ ------------- 
