model
size = 24 26 3, scale = 0.05, origin = -y
material 
  colors = A:#EEE B:#5DAC81 C:#00AA90 D:#7DB9DE E:#E195A9 F:#F596AA G:#111 H:#855B32 I:#D0587C J:#E03C8A K:#F7D94C L:#B9887D M:#FBE251 N:#F17C67
voxels
------------------------ ------------------------ ------------------------ ------------------------ ------------------------ ------------------------ ------------------------ ------------------------ ------------------------ -K--------LJJL--------K- -K--------JMMJ--------K- ----------JMMJ---------- ----------LJJL---------- ------------------------ ------------------------ ------------------------ ------------------------ ------------------------ ------------------------ ------------------------ ---------CBBBBC--------- -----BBBBBBBBBBBBBB----- --------BBCBBCBB-------- ------------------------ ------------------------ ------------------------ 
------------------------ ------------------------ -----------FF----------- ----------EFFE---------- ----------EFFE---------- ----------EFFE---------- -------D--------D------- -------D--------D------- -------D--------D------- -------D--HHHH--D------- AAA----D--HNNH--D----AAA A-A----D--HNNH--D----A-A A-A----D--HHHH--D----A-A A-A----D--------D----A-A A-A----D--------D----A-A AAA--D------------D--AAA CBB------------------BBC ------------------------ ---C----------------C--- ----B--------------B---- ---CB--------------BC--- ----BBBBBBBBBBBBBBBB---- ------CCBBBBBBBBCC------ --------CCCCCCCC-------- ------------------------ ------------------------ 
---------AAAAAA--------- -------AAAAAAAAAA------- ------AAAAAAAAAAAA------ -----AAAAAAAAAAAAAA----- -----AAAAAAAAAAAAAA----- ----AAAAAGGGGGGAAAAA---- ----AAAAAAAAAAAAAAAA---- ---AAAAAAAAAAAAAAAAAA--- ---AAAEAEAAAAAAEAEAAA--- ---AAEIAIAAAAAAIAIEAA--- AAAAAEIAIAAAAAAIAIEAAAAA AFAAAEIAIAAAAAAIAIEAAAFA AFAAAAEAEAAAAAAEAEAAAAFA AFAAAAAAAAAAAAAAAAAAAAFA AFAAAAAAAAAAAAAAAAAAAAFA AAAAADAGAAAAAAAAGADAAAAA BCBAAADGDAAAAAADGDAAABCB --BAAAGGGAAAAAAGGGAAAB-- --BAAAAAAAAAAAAAAAAAAB-- --BBAAAAAAAAAAAAAAAABB-- --BBBAAAAAAAAAAAAAABBB-- --CBBAAAAAAAAAAAAAABBC-- -----BAAAAAAAAAAAAB----- -----BBBAAAAAAAABBB----- --------BCCCCCCB-------- --------BBBCCBBB-------- 
