model
size = 26 31 27, scale = 0.05, origin = -y
material 
  colors = A:#604000 B:#E00 C:#200 D:#330 E:#A00 F:#111 G:#100 H:#EEE
voxels
-------------------------- -------------------------- -------------------------- -------------------------- -------------------------- -------------------------- -------------------------- -------------------------- -------------------------- -------------------------- -------------------------- -------------------------- -------------------------- -------------------------- -------------------------- -------------------------- -------------------------- -------------------------- -------------------------- -------------------------- -------------------------- -------------------------- -------------------------- -BBBBBBBBBBBBBBBBBBBBBBBB- -BBBBBBBBBBBBBBBBBBBBBBBB- -------------------------- -------------------------- -------------------------- -------------------------- -------------------------- -------------------------- 
-------------------------- -------------------------- -------------------------- -------------------------- -------------------------- -------------------------- -------------------------- -------------------------- -------------------------- -------------------------- -------------------------- -------------------------- -------------------------- -------------------------- -------------------------- -------------------------- -------------------------- -------------------------- -------------------------- -------------------------- -------------------------- -------------------------- -------------------------- -BBBBBBBBBBBBBBBBBBBBBBBB- -BBBBBBBBBBBBBBBBBBBBBBBB- -BBBBBBBBBBBBBBBBBBBBBBBB- -------------------------- -------------------------- -------------------------- -------------------------- -------------------------- 
-------------------------- -------------------------- -------------------------- -------------------------- -------------------------- -------------------------- -------------------------- -------------------------- -------------------------- -------------------------- -------------------------- -------------------------- -------------------------- -------------------------- -------------------------- -------------------------- -------------------------- -------------------------- -------------------------- -------------------------- -------------------------- -------------------------- -------------------------- -BBBBBBBBBBBBBBBBBBBBBBBB- -BBBBBBBBBBBBBBBBBBBBBBBB- -BBBBBBBBBBBBBBBBBBBBBBBB- -BBBBBBBBBBBBBBBBBBBBBBBB- -------------------------- -------------------------- -------------------------- -------------------------- 
-------------------------- -------------------------- -------------------------- -------------------------- -------------------------- -------------------------- -------------------------- -------------------------- -------------------------- -------------------------- -------------------------- -------------------------- -------------------------- ------------AA------------ ------------AA------------ -------------------------- -------------------------- -------------------------- -------------------------- -------------------------- -------------------------- -------------------------- -------------------------- -BBBBBBBBBBBBBBBBBBBBBBBB- -BBBBBBBBBBBBBBBBBBBBBBBB- -BBBBBBBBBBBBBBBBBBBBBBBB- -BBBBBBBBBBBBBBBBBBBBBBBB- -BBBBBBBBBBBBBBBBBBBBBBBB- -------------------------- -------------------------- -------------------------- 
-------------------------- -------------------------- -------------------------- -------------------------- -------------------------- -------------------------- -------------------------- -------------------------- -------------------------- -------------------------- -------------------------- -------------------------- -------------------------- ------------AA------------ ------------AA------------ ------------AA------------ -------------------------- -------------------------- -------------------------- -------------------------- -------------------------- -------------------------- -------------------------- -BBBBBBBBBBBBBBBBBBBBBBBB- -BBBBBBBBBBBBBBBBBBBBBBBB- -BBBBBBBBBBBBBBBBBBBBBBBB- -BBBBBBBBBBBBBBBBBBBBBBBB- -BBBBBBBBBBBBBBBBBBBBBBBB- -BBBBBBBBBBBBBBBBBBBBBBBB- -------------------------- -------------------------- 
-------------------------- -------------------------- -------------------------- -------------------------- -------------------------- -------------------------- -------------------------- -------------------------- -------------------------- -------------------------- -------------------------- -------------------------- -------------------------- ----------AAAAAA---------- ----------AAAAAA---------- ------------AA------------ ------------AA------------ -------------------------- -------------------------- -------------------------- -------------------------- -------------------------- -------------------------- -BBBBBBBBBBBBBBBBBBBBBBBB- -BBAAAAAAAAAAAAAAAAAAAABB- -BBCCCCCCCCCCCCCCCCCCCCBB- -BBCCCCCCCCCCCCCCCCCCCCBB- -BBBBBBBBBBBBBBBBBBBBBBBB- -BBBBBBBBBBBBBBBBBBBBBBBB- -------------------------- -------------------------- 
-------------------------- -------------------------- -------------------------- -------------------------- -------------------------- -------------------------- -------------------------- -------------------------- ----------AAAAAA---------- --------AAAAAAAAAA-------- -------------------------- -------------------------- -------------------------- ----------AAAAAA---------- ----------AAAAAA---------- ------------AA------------ ------------AA------------ -------------------------- -------------------------- -----------F--F----------- ----FFFFFFF----FFFFFFF---- -------------------------- -------------------------- -BBBBBBBBBBBBBBBBBBBBBBBB- -BBAAAAAAAAAAAAAAAAAAAABB- -BBCCCCCCCCCCCCCCCCCCCCBB- -BBCCCCCCCCCCCCCCCCCCCCBB- -BBBBBBBBBBBBBBBBBBBBBBBB- -BBBBBBBBBBBBBBBBBBBBBBBB- -BBBBBBBBBBBBBBBBBBBBBBBB- -------------------------- 
-------------------------- -------------------------- -------------------------- -----CCCCCCCCCCCCCCCC----- -----CCCCCCCCCCCCCCCC----- ---CCCCCCCCCCCCCCCCCCCC--- --CCCCCCCCCCCCCCCCCCCCCC-- --CCCCCCCCCCCCCCCCCCCCCC-- --CCCCCCCCCCCCCCCCCCCCCC-- --CCCCCCCCCCCCCCCCCCCCCC-- --CCCCCCCCCCCCCCCCCCCCCC-- --CCCCCCCCCCCCCCCCCCCCCC-- --AAAAAAAAAAAAAAAAAAAAAA-- --AAAAAAAAAAAAAAAAAAAAAA-- --AAAAAAAAAAAAAAAAAAAAAA-- --AAAADDAAAAAAAAAADDAAAA-- --AAADGGDAAAAAAAADGGDAAA-- --AAADHGDAAAAAAAADGHDAAA-- --AADDDDDDAAAAAADDDDDDAA-- --AAAAAAAAAAAAAAAAAAAAAA-- --AAAAAAAAAAAAAAAAAAAAAA-- --AAAAAAAAAAAAAAAAAAAAAA-- --AAAAAAAAAAAAAAAAAAAAAA-- -BBBBBBBBBBBBBBBBBBBBBBBB- -BBAAAAAAAAAAAAAAAAAAAABB- -BBCCCCCCCCCCCCCCCCCCCCBB- -BBCCCCCCCCCCCCCCCCCCCCBB- -BBBBBBBBBBBBBBBBBBBBBBBB- -BBBBBBBBBBBBBBBBBBBBBBBB- -BBBBBBBBBBBBBBBBBBBBBBBB- -------------------------- 
-------------------------- -------------------------- -------------------------- -----CCCCCCCCCCCCCCCC----- -----CCCCCCCCCCCCCCCC----- ---CCCCCCCCCCCCCCCCCCC---- --CAAAAAAAAAAAAAAAAACCCC-- --CAAAAAAAAAAAAAAAAAAAAC-- --CAAAAAAAAAAAAAAAAAAAAC-- --CAAAAAAAAAAAAAAAAAAAAC-- --CAAAAAAAAAAAAAAAAAAAAC-- --CAAAAAAAAAAAAAAAAAAAAC-- --AAAAAAAAAAAAAAAAAAAAAA-- --AAAAAAAAAAAAAAAAAAAAAA-- --AAAAAAAAAAAAAAAAAAAAAA-- --AAAAAAAAAAAAAAAAAAAAAA-- --AAAAAAAAAAAAAAAAAAAAAA-- --AAAAAAAAAAAAAAAAAAAAAA-- --AAAAAAAAAAAAAAAAAAAAAA-- --AAAAAAAAAAAAAAAAAAAAAA-- --AAAAAAAAAAAAAAAAAAAAAA-- --AAAAAAAAAAAAAAAAAAAAAA-- --AAAAAAAAAAAAAAAAAAAAAA-- -BBAAAAAAAAAAAAAAAAAAAABB- -BBAAAAAAAAAAAAAAAAAAAABB- -BBCCCCCCCCCCCCCCCCCCCCBB- -BBCCCCCCCCCCCCCCCCCCCCBB- -BBBBBBBBBBBBBBBBBBBBBBBB- -BBBBBBBBBBBBBBBBBBBBBBBB- -BBBBBBBBBBBBBBBBBBBBBBBB- -------------------------- 
-------------------------- -------------------------- -------------------------- -------------------------- -----CCCCCCCCCCCCCCCC----- ---CCCCCCCCCCCCCCCCCCC---- --CAAAAAAAAAAAAAAAAACCCC-- --CAAAAAAAAAAAAAAAAAAAAC-- --CAAAAAAAAAAAAAAAAAAAAC-- --CAAAAAAAAAAAAAAAAAAAAC-- --CAAAAAAAAAAAAAAAAAAAAC-- --CAAAAAAAAAAAAAAAAAAAAC-- --AAAAAAAAAAAAAAAAAAAAAA-- --AAAAAAAAAAAAAAAAAAAAAA-- --AAAAAAAAAAAAAAAAAAAAAA-- --AAAAAAAAAAAAAAAAAAAAAA-- --AAAAAAAAAAAAAAAAAAAAAA-- --AAAAAAAAAAAAAAAAAAAAAA-- --AAAAAAAAAAAAAAAAAAAAAA-- --AAAAAAAAAAAAAAAAAAAAAA-- --AAAAAAAAAAAAAAAAAAAAAA-- --AAAAAAAAAAAAAAAAAAAAAA-- --AAAAAAAAAAAAAAAAAAAAAC-- -BBAAAAAAAAAAAAAAAAAAAABB- -BBAAAAAAAAAAAAAAAAAAAABB- -BBCCCCCCCCCCCCCCCCCCCCBB- -BBCCCCCCCCCCCCCCCCCCCCBB- -BBBBBBBBBBBBBBBBBBBBBBBB- -BBBBBBBBBBBBBBBBBBBBBBBB- -BBBBBBBBBBBBBBBBBBBBBBBB- -BBBBBBBBBBBBBBBBBBBBBBBB- 
-------------------------- -------------------------- -------------------------- -------------------------- -------------------------- ---CCCCCCCCCCCCCCCCCCC---- --CAAAAAAAAAAAAAAAAACCCC-- --CAAAAAAAAAAAAAAAAAAAAC-- --CAAAAAAAAAAAAAAAAAAAAC-- --CAAAAAAAAAAAAAAAAAAAAC-- --CAAAAAAAAAAAAAAAAAAAAC-- --CAAAAAAAAAAAAAAAAAAAAC-- --AAAAAAAAAAAAAAAAAAAAAA-- --AAAAAAAAAAAAAAAAAAAAAA-- --AAAAAAAAAAAAAAAAAAAAAA-- --AAAAAAAAAAAAAAAAAAAAAA-- --AAAAAAAAAAAAAAAAAAAAAA-- --AAAAAAAAAAAAAAAAAAAAAA-- --AAAAAAAAAAAAAAAAAAAAAA-- --AAAAAAAAAAAAAAAAAAAAAA-- --AAAAAAAAAAAAAAAAAAAAAA-- --AAAAAAAAAAAAAAAAAAAAAA-- --CAAAAAAAAAAAAAAAAAAAAC-- -BBAAAAAAAAAAAAAAAAAAAABB- -BBAAAAAAAAAAAAAAAAAAAABB- -BBAAAAAAAAAAAAAAAAAAAABB- -BBAAAAAAAAAAAAAAAAAAAABB- -BBBBBBBBBBBBBBBBBBBBBBBB- -BBBBBBBBBBBBBBBBBBBBBBBB- -BBBBBBBBBBBBBBBBBBBBBBBB- -BBBBBBBBBBBEEEBBBBBBBBBB- 
-----------AAAA----------- -----------AAAA----------- -----------AAAA----------- -----------AAAA----------- -----------AAAA----------- ---CCCCCCCCCCCCCCCCCCC---- --CAAAAAAAAAAAAAAAAACCCC-- --CAAAAAAAAAAAAAAAAAAAAC-- --CAAAAAAAAAAAAAAAAAAAAC-- --CAAAAAAAAAAAAAAAAAAAAC-- --CAAAAAAAAAAAAAAAAAAAAC-- --CAAAAAAAAAAAAAAAAAAAAC-- --AAAAAAAAAAAAAAAAAAAAAA-- --AAAAAAAAAAAAAAAAAAAAAA-- --AAAAAAAAAAAAAAAAAAAAAA-- --AAAAAAAAAAAAAAAAAAAAAA-- --AAAAAAAAAAAAAAAAAAAAAA-- --CAAAAAAAAAAAAAAAAAAAAC-- --CAAAAAAAAAAAAAAAAAAAAC-- --CAAAAAAAAAAAAAAAAAAAAC-- --CAAAAAAAAAAAAAAAAAAAAC-- --CAAAAAAAAAAAAAAAAAAAAC-- --CAAAAAAAAAAAAAAAAAAAABB- -BBAAAAAAAAAAAAAAAAAAAABB- -BBAAAAAAAAAAAAAAAAAAAABB- -BBAAAAAAAAAAAAAAAAAAAABB- -BBAAAAAAAAAAAAAAAAAAAABB- -BBBBBBBBBBBBBBBBBBBBBBBB- -BBBBBBBBBBBBBBBBBBBBBBBB- -BBBBBBBBBBBBBBBBBBBBBBBB- -BBBBBBBBBBEEEEEBBBBBBBBB- 
---------AAAAAAAA--------- ---------AAAAAAAA--------- ---------AAAAAAAA--------- ---------AAAAAAAA--------- ---------AAAAAAAA--------- ---------AAAAAAAA--------- --CAAAAAAAAAAAAAAAAAAAAC-- --CAAAAAAAAAAAAAAAAAAAAC-- --CAAAAAAAAAAAAAAAAAAAAC-- --CAAAAAAAAAAAAAAAAAAAAC-- --CAAAAAAAAAAAAAAAAAAAAC-- --CAAAAAAAAAAAAAAAAAAAAC-- --AAAAAAAAAAAAAAAAAAAAAC-- --AAAAAAAAAAAAAAAAAAAAAC-- --AAAAAAAAAAAAAAAAAAAAAC-- --AAAAAAAAAAAAAAAAAAAAAC-- --AAAAAAAAAAAAAAAAAAAAAC-- --CAAAAAAAAAAAAAAAAAAAAC-- --CAAAAAAAAAAAAAAAAAAAAC-- --CAAAAAAAAAAAAAAAAAAAAC-- --CAAAAAAAAAAAAAAAAAAAAC-- --CAAAAAAAAAAAAAAAAAAAAC-- -BBAAAAAAAAAAAAAAAAAAAABB- -BBAAAAAAAAAAAAAAAAAAAABB- -BBAAAAAAAAAAAAAAAAAAAABB- -BBAAAAAAAAAAAAAAAAAAAABB- -BBAAAAAAAAAAAAAAAAAAAABB- -BBBBBBBBBBBBBBBBBBBBBBBB- -BBBBBBBBBBBBBBBBBBBBBBBB- -BBBBBBBBBBBBBBBBBBBBBBBB- -BBBBBBBBBBEEBEEBBBBBBBBB- 
-------AAAAAAAAAAAAA------ -------AAAAAAAAAAAAA------ -------AAAAAAAAAAAAA------ -------AAAAAAAAAAAAA------ -------AAAAAAAAAAAAA------ -------AAAAAAAAAAAAA------ --CAAAAAAAAAAAAAAAAAAAAC-- --CAAAAAAAAAAAAAAAAAAAAC-- --CAAAAAAAAAAAAAAAAAAAAC-- --CAAAAAAAAAAAAAAAAAAAAC-- --CAAAAAAAAAAAAAAAAAAAAC-- --CAAAAAAAAAAAAAAAAAAAAC-- --CAAAAAAAAAAAAAAAAAAAAC-- --CAAAAAAAAAAAAAAAAAAAAC-- --CAAAAAAAAAAAAAAAAAAAAC-- --CAAAAAAAAAAAAAAAAAAAAC-- --CAAAAAAAAAAAAAAAAAAAAC-- --CAAAAAAAAAAAAAAAAAAAAC-- --CAAAAAAAAAAAAAAAAAAAAC-- --CAAAAAAAAAAAAAAAAAAAAC-- --CAAAAAAAAAAAAAAAAAAAAC-- --CAAAAAAAAAAAAAAAAAAAAC-- -BBAAAAAAAAAAAAAAAAAAAABB- -BBAAAAAAAAAAAAAAAAAAAABB- -BBAAAAAAAAAAAAAAAAAAAABB- -BBAAAAAAAAAAAAAAAAAAAABB- -BBAAAAAAAAAAAAAAAAAAAABB- -BBBBBBBBBBBBBBBBBBBBBBBB- -BBBBBBBBBBBBBBBBBBBBBBBB- -BBBBBBBBBBBBBBBBBBBBBBBB- -BBBBBBBBBBEEEEEBBBBBBBBB- 
-----AAAAAAAAAAAAAAAA----- -----AAAAAAAAAAAAAAAA----- -----AAAAAAAAAAAAAAAA----- -----AAAAAAAAAAAAAAAA----- -----AAAAAAAAAAAAAAAA----- -----AAAAAAAAAAAAAAAA----- --CAAAAAAAAAAAAAAAAAAAAA-- --CAAAAAAAAAAAAAAAAAAAAA-- --CAAAAAAAAAAAAAAAAAAAAA-- --CAAAAAAAAAAAAAAAAAAAAA-- --CAAAAAAAAAAAAAAAAAAAAA-- --CAAAAAAAAAAAAAAAAAAAAAAA --CAAAAAAAAAAAAAAAAAAAAAAA --CAAAAAAAAAAAAAAAAAAAAAAA --CAAAAAAAAAAAAAAAAAAAAA-- --CAAAAAAAAAAAAAAAAAAAAAAA --CAAAAAAAAAAAAAAAAAAAAAAA --CAAAAAAAAAAAAAAAAAAAAC-- --CAAAAAAAAAAAAAAAAAAAAC-- --CAAAAAAAAAAAAAAAAAAAAC-- --CAAAAAAAAAAAAAAAAAAAAC-- --CAAAAAAAAAAAAAAAAAAAAC-- -BBAAAAAAAAAAAAAAAAAAAABB- -BBAAAAAAAAAAAAAAAAAAAABB- -BBAAAAAAAAAAAAAAAAAAAABB- -BBAAAAAAAAAAAAAAAAAAAABB- -BBAAAAAAAAAAAAAAAAAAAABB- -BBBBBBBBBBBBBBBBBBBBBBBB- -BBBBBBBBBBBBBBBBBBBBBBBB- -BBBBBBBBBBBBBBBBBBBBBBBB- -BBBBBBBBBBBEEEBBBBBBBBBB- 
-----AAAAAAAAAAAAAAAA----- -----AAAAAAAAAAAAAAAA----- -----AAAAAAAAAAAAAAAA----- -----AAAAAAAAAAAAAAAA----- -----AAAAAAAAAAAAAAAA----- -----AAAAAAAAAAAAAAAA----- --AAAAAAAAAAAAAAAAAAAAAA-- --AAAAAAAAAAAAAAAAAAAAAA-- --AAAAAAAAAAAAAAAAAAAAAA-- --AAAAAAAAAAAAAAAAAAAAAA-- --AAAAAAAAAAAAAAAAAAAAAA-- AAAAAAAAAAAAAAAAAAAAAAAAAA AAAAAAAAAAAAAAAAAAAAAAAA-A AAAAAAAAAAAAAAAAAAAAAAAAA- --AAAAAAAAAAAAAAAAAAAAA--- AAAAAAAAAAAAAAAAAAAAAAAA-A AAAAAAAAAAAAAAAAAAAAAAAAAA --CAAAAAAAAAAAAAAAAAAAAAAA --CAAAAAAAAAAAAAAAAAAAAC-- --CAAAAAAAAAAAAAAAAAAAAC-- --CAAAAAAAAAAAAAAAAAAAAC-- -BBAAAAAAAAAAAAAAAAAAAABB- -BBAAAAAAAAAAAAAAAAAAAABB- -BBAAAAAAAAAAAAAAAAAAAABB- -BBAAAAAAAAAAAAAAAAAAAABB- -BBAAAAAAAAAAAAAAAAAAAABB- -BBAAAAAAAAAAAAAAAAAAAABB- -BBBBBBBBBBBBBBBBBBBBBBBB- -BBBBBBBBBBBBBBBBBBBBBBBB- -BBBBBBBBBBBBBBBBBBBBBBBB- -BBBBBBBBBBBBBBBBBBBBBBBB- 
-----AAAAAAAAAAAAAAAA----- -----AAAAAAAAAAAAAAAA----- -----AAAAAAAAAAAAAAAA----- -----AAAAAAAAAAAAAAAA----- -----AAAAAAAAAAAAAAAA----- -----AAAAAAAAAAAAAAAA----- --AAAAAAAAAAAAAAAAAAAAAA-- --AAAAAAAAAAAAAAAAAAAAAA-- --AAAAAAAAAAAAAAAAAAAAAA-- --AAAAAAAAAAAAAAAAAAAAAA-- --AAAAAAAAAAAAAAAAAAAAAA-- AAAAAAAAAAAAAAAAAAAAAAAAAA AAAAAAAAAAAAAAAAAAAAAAAA-A --AAAAAAAAAAAAAAAAAAAAAAA- ----AAAAAAAAAAAAAAAAAAAA-- AAAAAAAAAAAAAAAAAAAAAAAA-- AAAAAAAAAAAAAAAAAAAAAAAAAA AAAAAAAAAAAAAAAAAAAAAAAAAA --CAAAAAAAAAAAAAAAAAAAAAAA --CAAAAAAAAAAAAAAAAAAAAC-- --CAAAAAAAAAAAAAAAAAAAAC-- -BBAAAAAAAAAAAAAAAAAAAABB- -BBAAAAAAAAAAAAAAAAAAAABB- -BBAAAAAAAAAAAAAAAAAAAABB- -BBAAAAAAAAAAAAAAAAAAAABB- -BBAAAAAAAAAAAAAAAAAAAABB- -BBAAAAAAAAAAAAAAAAAAAABB- -BBBBBBBBBBBBBBBBBBBBBBBB- -BBBBBBBBBBBBBBBBBBBBBBBB- -BBBBBBBBBBBBBBBBBBBBBBBB- -------------------------- 
-----AAAAAAAAAAAAAAAA----- -----AAAAAAAAAAAAAAAA----- -----AAAAAAAAAAAAAAAA----- -----AAAAAAAAAAAAAAAA----- -----AAAAAAAAAAAAAAAA----- -----AAAAAAAAAAAAAAAA----- --AAAAAAAAAAAAAAAAAAAAAA-- --AAAAAAAAAAAAAAAAAAAAAA-- --AAAAAAAAAAAAAAAAAAAAAA-- --AAAAAAAAAAAAAAAAAAAAAA-- --AAAAAAAAAAAAAAAAAAAAAA-- AAAAAAAAAAAAAAAAAAAAAAAAAA AAAAAAAAAAAAAAAAAAAAAAAA-A --AAAAAAAAAAAAAAAAAAAAAAAA --AAAAAAAAAAAAAAAAAAAAAA-- --AAAAAAAAAAAAAAAAAAAAAA-- AAAAAAAAAAAAAAAAAAAAAAAA-- AAAAAAAAAAAAAAAAAAAAAAAAAA AAAAAAAAAAAAAAAAAAAAAAAAAA --CAAAAAAAAAAAAAAAAAAAAC-- --CAAAAAAAAAAAAAAAAAAAAC-- -BBAAAAAAAAAAAAAAAAAAAABB- -BBAAAAAAAAAAAAAAAAAAAABB- -BBAAAAAAAAAAAAAAAAAAAABB- -BBAAAAAAAAAAAAAAAAAAAABB- -BBAAAAAAAAAAAAAAAAAAAABB- -BBAAAAAAAAAAAAAAAAAAAABB- -BBBBBBBBBBBBBBBBBBBBBBBB- -BBBBBBBBBBBBBBBBBBBBBBBB- -BBBBBBBBBBBBBBBBBBBBBBBB- -------------------------- 
-----AAAAAAAAAAAAAAAA----- -----AAAAAAAAAAAAAAAA----- -----AAAAAAAAAAAAAAAA----- -----AAAAAAAAAAAAAAAA----- -----AAAAAAAAAAAAAAAA----- -----AAAAAAAAAAAAAAAA----- --AAAAAAAAAAAAAAAAAAAAAA-- --AAAAAAAAAAAAAAAAAAAAAA-- --AAAAAAAAAAAAAAAAAAAAAA-- --AAAAAAAAAAAAAAAAAAAAAA-- --AAAAAAAAAAAAAAAAAAAAAA-- AAAAAAAAAAAAAAAAAAAAAAAA-- AAAAAAAAAAAAAAAAAAAAAAAAAA AAAAAAAAAAAAAAAAAAAAAAAA-A --AAAAAAAAAAAAAAAAAAAAAAAA --AAAAAAAAAAAAAAAAAAAAAAAA -AAAAAAAAAAAAAAAAAAAAAAAAA AAAAAAAAAAAAAAAAAAAAAAAAAA AAAAAAAAAAAAAAAAAAAAAAAAAA --CAAAAAAAAAAAAAAAAAAAAC-- --CAAAAAAAAAAAAAAAAAAAABB- -BBAAAAAAAAAAAAAAAAAAAABB- -BBAAAAAAAAAAAAAAAAAAAABB- -BBAAAAAAAAAAAAAAAAAAAABB- -BBAAAAAAAAAAAAAAAAAAAABB- -BBAAAAAAAAAAAAAAAAAAAABB- -BBAAAAAAAAAAAAAAAAAAAABB- -BBBBBBBBBBBBBBBBBBBBBBBB- -BBBBBBBBBBBBBBBBBBBBBBBB- -BBBBBBBBBBBBBBBBBBBBBBBB- -------------------------- 
-----AAAAAAAAAAAAAAAA----- -----AAAAAAAAAAAAAAAA----- -----AAAAAAAAAAAAAAAA----- -----AAAAAAAAAAAAAAAA----- -----AAAAAAAAAAAAAAAA----- -----AAAAAAAAAAAAAAAA----- --AAAAAAAAAAAAAAAAAAAAAA-- --AAAAAAAAAAAAAAAAAAAAAA-- --AAAAAAAAAAAAAAAAAAAAAA-- --AAAAAAAAAAAAAAAAAAAAAA-- --AAAAAAAAAAAAAAAAAAAAAA-- --AAAAAAAAAAAAAAAAAAAAAA-- AAAAAAAAAAAAAAAAAAAAAAAA-- AAAAAAAAAAAAAAAAAAAAAAAAAA AAAAAAAAAAAAAAAAAAAAAAAAAA AAAAAAAAAAAAAAAAAAAAAAAAAA AAAAAAAAAAAAAAAAAAAAAAAAAA AAAAAAAAAAAAAAAAAAAAAAAAAA AAAAAAAAAAAAAAAAAAAAAAAAAA --CAAAAAAAAAAAAAAAAAAAAC-- -BBAAAAAAAAAAAAAAAAAAAABB- -BBAAAAAAAAAAAAAAAAAAAABB- -BBAAAAAAAAAAAAAAAAAAAABB- -BBAAAAAAAAAAAAAAAAAAAABB- -BBAAAAAAAAAAAAAAAAAAAABB- -BBAAAAAAAAAAAAAAAAAAAABB- -BBAAAAAAAAAAAAAAAAAAAABB- -BBAAAAAAAAAAAAAAAAAAAABB- -BBBBBBBBBBBBBBBBBBBBBBBB- -------------------------- -------------------------- 
-----AAAAAAAAAAAAAAAA----- -----AAAAAAAAAAAAAAAA----- -----AAAAAAAAAAAAAAAA----- -----AAAAAAAAAAAAAAAA----- -----AAAAAAAAAAAAAAAA----- -----AAAAAAAAAAAAAAAA----- -----AAAAAAAAAAAAAAAA----- --AAAAAAAAAAAAAAAAAAAAAA-- --AAAAAAAAAAAAAAAAAAAAAA-- --AAAAAAAAAAAAAAAAAAAAAA-- --AAAAAAAAAAAAAAAAAAAAAA-- --AAAAAAAAAAAAAAAAAAAAAA-- --AAAAAAAAAAAAAAAAAAAAAA-- AAAAAAAAAAAAAAAAAAAAAAAA-- AAAAAAAAAAAAAAAAAAAAAAAA-- AAAAAAAAAAAAAAAAAAAAAAAC-- AAAAAAAAAAAAAAAAAAAAAAAC-- AAAAAAAAAAAAAAAAAAAAAAAC-- AAAAAAAAAAAAAAAAAAAAAAAC-- --CAAAAAAAAAAAAAAAAAAAAC-- -BBAAAAAAAAAAAAAAAAAAAABB- -BBAAAAAAAAAAAAAAAAAAAABB- -BBBBBBBBBBBBBBBBBBBBBBBB- -BBBBBBBBBBBBBBBBBBBBBBBB- -BBBBBBBBBBBBBBBBBBBBBBBB- -BBBBBBBBBBBBBBBBBBBBBBBB- -BBBBBBBBBBBBBBBBBBBBBBBB- -BBBBBBBBBBBBBBBBBBBBBBBB- -BBBBBBBBBBBBBBBBBBBBBBBB- -------------------------- -------------------------- 
-------AAAAAAAAAAAA------- -------AAAAAAAAAAAA------- -------AAAAAAAAAAAA------- -------AAAAAAAAAAAA------- -------AAAAAAAAAAAA------- -------AAAAAAAAAAAA------- -------AAAAAAAAAAAA------- -------AAAAAAAAAAAA------- -------AAAAAAAAAAAA------- --ACCCCCCCCCCCCCCCCCCCCC-- --AAAAAAAAAAAAACCCCCCCCC-- --AAAAAAAAAAAAACCCCCCCCC-- --AAAAAAAAAAAAACCCCCCCCC-- --AAAAAAAAAAAAACCCCCCCCC-- --AAAAAAAAAAAAACCCCCCCCC-- --CAAAAAAAAAAAACCCCCCCCC-- --CAAAAAAAAAAAAAAAAAAAAC-- --CAAAAAAAAAAAAAAAAAAAAC-- --CAAAAAAAAAAAAAAAAAAAAC-- --CAAAAAAAAAAAAAAAAAAAABB- -BBAAAAAAAAAAAAAAAAAAAABB- -BBAAAAAAAAAAAAAAAAAAAABB- -BBBBBBBBBBBBBBBBBBBBBBBB- -BBBBBBBBBBBBBBBBBBBBBBBB- -BBBBBBBBBBBBBBBBBBBBBBBB- -BBBBBBBBBBBBBBBBBBBBBBBB- -BBBBBBBBBBBBBBBBBBBBBBBB- -BBBBBBBBBBBBBBBBBBBBBBBB- -------------------------- -------------------------- -------------------------- 
---------AAAAAAAA--------- ---------AAAAAAAA--------- ---------AAAAAAAA--------- ---------AAAAAAAA--------- ---------AAAAAAAA--------- ---------AAAAAAAA--------- ---------AAAAAAAA--------- ---------AAAAAAAA--------- ---------AAAAAAAA--------- --CCCCCCCCCCCCCCCCCCCCCC-- --CAAAAAAAAAAAACCCCCCCCC-- --CAAAAAAAAAAAACCCCCCCCC-- --CAAAAAAAAAAAACCCCCCCCC-- --CAAAAAAAAAAAACCCCCCCCC-- --CAAAAAAAAAAAACCCCCCCCC-- --CAAAAAAAAAAAACCCCCCCCC-- --CAAAAAAAAAAAAAAAAAAAAC-- --CAAAAAAAAAAAAAAAAAAAAC-- --CAAAAAAAAAAAAAAAAAAAAC-- -BBAAAAAAAAAAAAAAAAAAAABB- -BBAAAAAAAAAAAAAAAAAAAABB- -BBAAAAAAAAAAAAAAAAAAAABB- -BBBBBBBBBBBBBBBBBBBBBBBB- -BBBBBBBBBBBBBBBBBBBBBBBB- -BBBBBBBBBBBBBBBBBBBBBBBB- -BBBBBBBBBBBBBBBBBBBBBBBB- -BBBBBBBBBBBBBBBBBBBBBBBB- -------------------------- -------------------------- -------------------------- -------------------------- 
-----------AAAA----------- -----------AAAA----------- -----------AAAA----------- -----------AAAA----------- -----------AAAA----------- -----------AAAA----------- -----------AAAA----------- -----------AAAA----------- -----------AAAA----------- --CCCCCCCCCCCCCCCCCCCCCC-- --CAAAAAAAAAAAACCCCCCCCC-- --CAAAAAAAAAAAACCCCCCCCC-- --CAAAAAAAAAAAACCCCCCCCC-- --CAAAAAAAAAAAACCCCCCCCC-- --CAAAAAAAAAAAACCCCCCCCC-- --CAAAAAAAAAAAACCCCCCCCC-- --CAAAAAAAAAAAAAAAAAAAAC-- --CAAAAAAAAAAAAAAAAAAAAC-- --CAAAAAAAAAAAAAAAAAAAAC-- -BBAAAAAAAAAAAAAAAAAAAABB- -BBAAAAAAAAAAAAAAAAAAAABB- -BBAAAAAAAAAAAAAAAAAAAABB- -BBBBBBBBBBBBBBBBBBBBBBBB- -BBBBBBBBBBBBBBBBBBBBBBBB- -BBBBBBBBBBBBBBBBBBBBBBBB- -BBBBBBBBBBBBBBBBBBBBBBBB- -------------------------- -------------------------- -------------------------- -------------------------- -------------------------- 
-------------------------- -------------------------- -------------------------- -------------------------- -------------------------- -------------------------- -------------------------- -------------------------- -------------------------- --CCCCCCCCCCCCCCCCCCCCCC-- --CCCCCCCCCCCCCCCCCCCCCC-- --CCCCCCCCCCCCCCCCCCCCCC-- --CCCCCCCCCCCCCCCCCCCCCC-- --CAAAAAAAAAAAACCCCCCCCC-- --CAAAAAAAAAAAACCCCCCCCC-- --CAAAAAAAAAAAACCCCCCCCC-- --CAAAAAAAAAAAAAAAAAAAAC-- --CAAAAAAAAAAAAAAAAAAAAC-- --CAAAAAAAAAAAAAAAAAAAAC-- -BBAAAAAAAAAAAAAAAAAAAABB- -BBAAAAAAAAAAAAAAAAAAAABB- -BBAAAAAAAAAAAAAAAAAAAABB- -BBBBBBBBBBBBBBBBBBBBBBBB- -BBBBBBBBBBBBBBBBBBBBBBBB- -BBBBBBBBBBBBBBBBBBBBBBBB- -------------------------- -------------------------- -------------------------- -------------------------- -------------------------- -------------------------- 
-------------------------- -------------------------- -------------------------- -------------------------- -------------------------- -------------------------- -------------------------- -------------------------- -------------------------- -------------------------- --CCCCCCCCCCCCCCCCCCCCCC-- --CCCCCCCCCCCCCCCCCCCCCC-- --CCCCCCCCCCCCCCCCCCCCCC-- --CAAAAAAAAAAAAAAAAAACCC-- --CAAAAAAAAAAAAAAAAAACCC-- --CAAAAAAAAAAAAAAAAAACCC-- --CAAAAAAAAAAAAAAAAAACCC-- --CAAAAAAAAAAAAAAAAAACCC-- -BBAAAAAAAAAAAAAAAAAAAABB- -BBBBBBBBBBBBBBBBBBBBBBBB- -BBBBBBBBBBBBBBBBBBBBBBBB- -BBBBBBBBBBBBBBBBBBBBBBBB- -BBBBBBBBBBBBBBBBBBBBBBBB- -------------------------- -------------------------- -------------------------- -------------------------- -------------------------- -------------------------- -------------------------- -------------------------- 
-------------------------- -------------------------- -------------------------- -------------------------- -------------------------- -------------------------- -------------------------- -------------------------- -------------------------- -------------------------- -------------------------- -------------------------- -------------------------- --CCCCCCCCCCCCCCCCCCCCCC-- --CCCCCCCCCCCCCCCCCCCCCC-- --CCCCCCCCCCCCCCCCCCCCCC-- --CCCCCCCCCCCCCCCCCCCCCC-- --CCCCCCCCCCCCCCCCCCCCCC-- -BBBBBBBBBBBBBBBBBBBBBBBB- -BBBBBBBBBBBBBBBBBBBBBBBB- -------------------------- -------------------------- -------------------------- -------------------------- -------------------------- -------------------------- -------------------------- -------------------------- -------------------------- -------------------------- -------------------------- 
