model
size = 30 32 29, scale = 0.05, origin = -y
material 
  colors = A:#963 B:#800 C:#700 D:#903 E:#111 F:#30F G:#D00 H:#3F0 I:#CF6 J:#90C K:#633 L:#006 M:#C90 N:#EEE O:#5A3C00
voxels
404-2(2A28-)2A40-B856-4A26-4A27-2A40-B29-B124-2B18-G4-B6-B15-3G3-B8-3B11-2G4-B11-4B7-2G2-3B15-3B5-G3-B12-3B4-B5-G2-2B3-B10-2(2B3-)2G-2B3-2B11-2B3-B3-2G20-2(B3-)G295-6J23-8J114-4A26-4A27-2A69-2B28-B29-B6-2B20-2B6-BCB4-3B8-2BG3BD4-2B2C6-2B4-BD5B2D2B4-2B2CB5-B3-BD5BD3B5-9B2(-2B)D2BD5BC6-BD6B2CB-2C2(3BD)2B7-2(BD)4BCB-C2(3BD)4B6-4BD3B2C-C7BD3B6-6BD3BC-C6BD4B7-6BD3B2-G3B3-2B13-2B2-B3-G141-14A15-12AO3A12-20A10-20A9-8(22A8-)4A2F10A2F4A8-3AF2LF8AF2LF3A8-3AFNLF8AFLNF3A8-2A6F6A6F2A6-2B22AB5-2B2A5K8A5K2AB4-3B2(22AB5-2B)22AB4-3B22AC5-C2B20A3B4-C11B-13B4-12B-12B5-12B-6BD5B7-6BD3B2-G3B3-B15-B2-B3-G6-B134-14A15-16A12-19A11-20A9-3(22A8-)22A9-20A9-6(22A8-)22A6-2B22AB4-3B2(22AB5-2B)22AB5-3B20A2B4-4B20A3B4-C2B20A3B4-12BA12B4-13BA11BD5-12B-12B7-10B2-G4BD5B8-3BC6B-G9B11-C2(2-B)3-B4-B134-16A12-19A11-20A9-4(22A8-)22A9-20A9-4(22A8-)22AB7-3(22AB5-2B)22AC4-3B22AC4-4B20ABD4-C3B20A3B4-C2B20A2B5-24BD3-27B6-24B7-10B2-11B8-3BC2BC3B-7BC2B11-2(B2-)B3-B4-B162-19A11-20A10-21A5(8-22A)9-20A9-2(22A8-)22AB7-22A7-B22A6-2B22AB2(4-3B21ABC)4-3B21ABD5-3B20A2B5-3B20A3B4-C2B20ABD4-26BD2-28B6-24B6-23B8-3BC2BC3B-4BD2B2CB11-C2(2-B)3-B4-B21-2(2A28-)IH2(28-2A)19-19A11-2(20A10-)21A2(8-22A)2(7-B22A)3(8-22A)B7-22A8-22A6-2B22AB5-2B22AB4-2B-21ABC5-B-B20A2B5-C-B20ABD5-B-B20A3B4-C-B20A3B3-4B20A2B4-27B4-25B6-24B7-22B9-D9B-4BD3BCB11-C2-2B-B3-2B3-B19-2(6A24-)IH2AIH3(24-6A)17-2(20A10-)20A9-22A8-3(22A7-B)4(22AB6-B)2(21A2B5-2B)21A2B4-3B21A2B5-3B20ABD5-C2B2(20A3B3-4B)20A2B4-4B20A2B6-26B4-24B6-23BC7-22B8-BD15BD3BC11-CB2-B-2B3-2B2-2BC15-2(10A20-)IH6AIH3(20-10A)16-19A3(10-20A)8-B2(22AB7-)2(22AB6-B)2(22A7-B)22A7-2B2(20AB6-3B)20A2B4-4B20ABD5-3B20A2B5-C2B20A3B3-4B20A2B5-3B20ABC5-3B20A2B6-C23BC5-C23B6-24B7-21BC8-BD3BD11BD3BC12-2(B2-)2B3-B4-B12-2(16A14-)HIH10AIHI3(14-16A)13-18A12-19A2(10-20A)B9-20A7-M24AM2(4-26A)6-22A6-26A4-26A5-2B2(20AB6-3B)20A2B4-4B20ABD5-C2B20A2B5-C2B20A5B-4B20A5B2-3B20A4B3-3B20A4B4-2(C26B3-)26B5-21BC8-D4BD2BD4BC4BD3B12-B2-B3-2B2-2B3-B12-2(16A14-)I14AH3(14-16A)13-2(18A12-)19A2(10-20A)7-26A4-24A-A6-22A8-22A6-21A2-3A2(4-26A)6-B20AB7-2B20ABD5-3B20A2B5-C2B20A4B3-3B20A10B20A5B-4B20A4B2-4B20A5B2-C27B-2C27B3-26B5-22B8-D4BD2BD4BC4BD3B11-2B2-B4-2(B3-)B12-2(16A14-)H14AI3(14-16A)14-17A2(12-18A)11-20A10-20A7-26A4-24A-A6-22A9-20A9-22A6-2(26A4-)26A5-2B20A2B5-3B20A3B4-3B20A4B2-C3B20A10B20A4B2-4B20A3BC2-4B20A5B2-C25BC2-27BC4-26B5-D20BC9-BC2(2BD)4BC6B13-C3-B4-B3-B-B2(14-16A)14-I14AH4(14-16A)14-17A3(12-18A)8-26A4-24A-A4-26A6-2(22A8-)22A6-26A4-26A5-2B20A2B5-3B20A3B3-4B20A4B2-C3B2(20A5B-4B)20A4B2-4B20A5B2-26BC2-29B3-23BC3B4-21BC9-4B2(D3B)C6B12-2C2-CB3-2B2-2B-B2(14-16A)14-H14AI5(14-16A)14-17A2(12-18A)10-2B18ABA6-26A4-24A-A5(4-26A)5-2B20A2B5-3B20A3B3-4B20A4B2-C3B2(20A4B2-4B)20A3BC3-3B20A4B3-24B-BC2-25B-3B2-24B-2B5-22B9-2BC5BD3BC6B12-C2-2C4-C2(2-2B)13-2(16A14-)I14AH6(14-16A)2(13-B16A)2B9-2B19AB8-B20AB6-5(26A4-)26A5-2B20A2B5-2(3B20A3B3-C)3B20A4B2-4B2(20A5B2-3B)20A4B2-25B-3B-25B-2B3-24B-2B6-21B9-8BD3BC6B12-C2-C5-C2-B3-2B13-2(16A14-)H14AI6(14-16A)2(13-B16A)2B8-3B19A2(B7-2B2(20AB8-B)20A)C8-B20AC7-2B20A2B5-3B20A3B3-C3B2(20A4B2-4B)20A4B3-3B20A5B-2B-B20A4B2-2B2(-22B-2B3-B)-10BC2D9B8-22B9-5BC10BC4B10-C-2B5-C2-2B3-B14-2(14A16-)HI10AIH6(16-14A)14-2B14AB13-B16A2B8-3B19A2(D8-B20A)B7-2B20AD7-2B20AB8-B20AB7-2B20A2B7-B20A2B6-2B20A2B5-3B20A2BC3-4B20A3BC2-4B20A4B2-4B20A5B2-3B20A5B-2B-B20A4B2-2B-25B3-B-10BCB2D8B-2B2-13B3-9B8-6BC3B3-10B11-B2-B5-4BC2B-B23-B3-B16-2(10A20-)2H6AIH5(20-10A)20-A2B3A3BA16-17B12-20B8-23B8-21BD8-22B7-23B7-22BD8-B20AB7-2B20A2B6-2B20ABC6-2B20A2B5-3B20A2BC4-3B20A3B3-4B2(20A5B2-3B)20A3B4-B-B20A3B5-11B2CBD9B6-11B4-8B6-12B4-9B7-C4B2C3B4-3B2C4B10-2B2-B8-B2-2B47-2(6A24-)3(IH)3(24-6A)2(24-A4BA)24-3D3B17-18B12-20B9-22B8-22B7-22BD7-23B8-21BD8-22B2(7-23BC)5-25B5-24B5-26B4-26B5-23BC6-25B4-13BC11B6-11B3-10B6-11B4-D7B8-10B4-8B8-C3B2C3BD4-4BC3B11-B3-B8-BC2-2B309-6B2D3B2D5B13-19B9-22B7-23B7-22BD2(8-22B)8-21BD2(7-24B)6-23B6-24B6-23BC7-22BC7-11B2C10B6-12B2C11B4-13B2-10B7-10B3-10B6-11B4-D4B2C2B7-10B4-5BC3B7-C3BC4BD4-5BC2B10-2B3-B9-BC2-B340-4B2D2BDCBD2B2C3B9-3B3D2BDCBD2C2DB2C3B7-2B2DC2B2D2CBDB2CB2D2C2B8-22B8-21BD8-22B2(7-23B)C7-24B6-23B6-12BC11B6-C11B2C11B6-12BC11B5-12B2(2-11B4-13B)2-10B6-4BD2BD3B3-BD4B2C3B5-3BD4BD2B8-B2-2B7-BD5BD2B8-B2-B8-4BC3BDB8-B2-B10-B3-2B442-BD2C2BDBC2BD2B2CB2D2CB8-2BC2BDB2C3BD2BC6B8-2BC4BC13BD7-23B8-12BC10BC6-11B2C11B5-12BC10BC6-12B2-10B7-C10B2-11B6-11B2(2-10B5-13B)2-10B6-7BD4B2-11B11-B7-2BD3BC4B11-B12-B2-B13-B29-2B548-7B7-12B4-7B7-12B2-11B6-11B2-10B6-2C9BC2-9BC7-11B2-10B7-C9BC2-11B6-11B2-9BC5-13B2-9BC6-12B2-9BC7-B2CBC6B2-11B19-2BC7B622-7B23-B2C4B9-9B5-2B3C2B9-9B4-7BC9-C6B2C4-7BC9-9B4-9B8-C6B2C4-8BC8-2(9B4-8B9-)BCB2C4B4-9B21-B2CBC2B703-4B24-6B6-5BCB2(11-6B6-7B)C10-5BC6-7B11-6B6-7B11-3C3B6-7B23-2BCB2CB774-5B13-4E2(8-5B13-E2BE)8-5B13-4E8-5B25-3B2C835-4E2(15-2B9-E2BE)26-4E897-2B28-2B308-
