model
size = 26 29 24, scale = 0.05, origin = -y
material 
  colors = A:#963 B:#5A3C00 C:#303 D:#2D1500 E:#001 F:#AAA
voxels
-------------------------- -------------------------- -------------------------- -------------------------- -------------------------- -------------------------- -------------------------- -------------------------- -------------------------- -------------------------- -------------------------- ------------AA------------ ------------AA------------ -------------------------- -------------------------- -------------------------- -------------------------- -------------------------- -------------------------- -------------------------- -------------------------- -------------------------- -------------------------- -------------------------- -------------------------- -------------------------- -------------------------- -------------------------- -------------------------- 
-------------------------- -------------------------- -------------------------- -------------------------- -------------------------- -------------------------- -------------------------- -------------------------- -------------------------- -------------------------- -------------------------- ------------AA------------ ------------AA------------ ------------AA------------ -------------------------- -------------------------- -------------------------- -------------------------- -------------------------- -------------------------- -------------------------- -------------------------- -------------------------- -------------------------- -------------------------- -------------------------- -------------------------- -------------------------- -------------------------- 
-------------------------- -------------------------- -------------------------- -------------------------- -------------------------- -------------------------- -------------------------- -------------------------- -------------------------- -------------------------- -------------------------- ----------AAAAAA---------- ----------AAAAAA---------- ------------AA------------ ------------AA------------ -------------------------- -------------------------- -------------------------- -------------------------- -------------------------- -------------------------- -------------------------- -------------------------- -------------------------- -------------------------- -------------------------- -------------------------- -------------------------- -------------------------- 
-------------------------- -------------------------- -------------------------- -------------------------- -------------------------- -------------------------- ----------AAAAAA---------- ---------AAAAAAAA--------- -------------------------- -------------------------- -------------------------- ----------AAAAAA---------- ----------AAAAAA---------- ------------AA------------ ------------AA------------ -------------------------- -------------------------- -----------D--D----------- ----DDDDDDD----DDDDDDD---- -------------------------- -------------------------- -------------------------- -------------------------- -------------------------- -------------------------- -------------------------- -------------------------- -------------------------- -------------------------- 
-------------------------- ------AAAAAAAAAAAAAA------ -----AAAAAAAAAAAAAAAA----- ---AAAAAAAAAAAAAAAAAAAA--- ---AAAAAAAAAAAAAAAAAAAA--- --AAAAAAAAAAAAAAAAAAAAAA-- --AAAAAAAAAAAAAAAAAAAAAA-- --AAAAAAAAAAAAAAAAAAAAAA-- --AAAAAAAAAAAAAAAAAAAAAA-- --AAAAAAAAAAAAAAAAAAAAAA-- --AAAAAAAAAAAAAAAAAAAAAA-- --AAAAAAAAAAAAAAAAAAAAAA-- --AAAAAAAAAAAAAAAAAAAAAA-- --AAAACCAAAAAAAAAACCAAAA-- --AAACEECAAAAAAAACEECAAA-- --AAACFECAAAAAAAACEFCAAA-- --AACCCCCCAAAAAACCCCCCAA-- --AAAAAAAAAAAAAAAAAAAAAA-- --AAAAAAAAAAAAAAAAAAAAAA-- --AAAAAAAAAAAAAAAAAAAAAA-- --AAAAAAAAAAAAAAAAAAAAAA-- --AAAAAAAAAAAAAAAAAAAAAA-- --AAAAAAAAAAAAAAAAAAAAAA-- ---AAAAAAAAAAAAAAAAAAAA--- -------------------------- -------------------------- -------------------------- -------------------------- -------------------------- 
-------------------------- ------AAAAAAAAAAAAAA------ -----AAAAAAAAAAAAAAAA----- ---AAAAAAAAAAAAAAAAAAA---- ---AAAAAAAAAAAAAAAAAAAA--- --AAAAAAAAAAAAAAAAAAAAAA-- --AAAAAAAAAAAAAAAAAAAAAA-- --AAAAAAAAAAAAAAAAAAAAAA-- --AAAAAAAAAAAAAAAAAAAAAA-- ---AAAAAAAAAAAAAAAAAAAA--- --AAAAAAAAAAAAAAAAAAAAAA-- --AAAAAAAAAAAAAAAAAAAAAA-- --AAAAAAAAAAAAAAAAAAAAAA-- --AAAAAAAAAAAAAAAAAAAAAA-- --AAAAAAAAAAAAAAAAAAAAAA-- --AAAAAAAAAAAAAAAAAAAAAA-- --AAAAAAAAAAAAAAAAAAAAAA-- --AAAAAAAAAAAAAAAAAAAAAA-- --AAAAAAAAAAAAAAAAAAAAAA-- --AAAAAAAAAAAAAAAAAAAAAA-- --AAAAAAAAAAAAAAAAAAAAAA-- --BAAAAAAAAAAAAAAAAAAAAB-- --BAAAAAAAAAAAAAAAAAAAAB-- --BAAAAAAAAAAAAAAAAAAAAB-- --BBBBBBBBBBBBBBBBBBBBBB-- --BBBBBBBBBBBBBBBBBBBBBB-- -------------------------- -------------------------- -------------------------- 
-------------------------- -------------------------- -----AAAAAAAAAAAAAAAA----- ---AAAAAAAAAAAAAAAAAAA---- ---AAAAAAAAAAAAAAAAAAAA--- --AAAAAAAAAAAAAAAAAAAAAA-- --AAAAAAAAAAAAAAAAAAAAAA-- --AAAAAAAAAAAAAAAAAAAAAA-- --AAAAAAAAAAAAAAAAAAAAAA-- --AAAAAAAAAAAAAAAAAAAAAA-- ---AAAAAAAAAAAAAAAAAAAA--- --AAAAAAAAAAAAAAAAAAAAAA-- --AAAAAAAAAAAAAAAAAAAAAA-- --AAAAAAAAAAAAAAAAAAAAAA-- --AAAAAAAAAAAAAAAAAAAAAA-- --AAAAAAAAAAAAAAAAAAAAAA-- --AAAAAAAAAAAAAAAAAAAAAA-- --AAAAAAAAAAAAAAAAAAAAAA-- --AAAAAAAAAAAAAAAAAAAAAA-- --AAAAAAAAAAAAAAAAAAAAAA-- --AAAAAAAAAAAAAAAAAAAAAA-- --BAAAAAAAAAAAAAAAAAAAAB-- --BAAAAAAAAAAAAAAAAAAAAB-- --BAAAAAAAAAAAAAAAAAAAAB-- --BBBBBBBBBBBBBBBBBBBBBB-- --BBBBBBBBBBBBBBBBBBBBBB-- --BBBBBBBBBBBBBBBBBBBBBB-- -------------------------- -------------------------- 
-------------------------- -------------------------- -------------------------- ---AAAAAAAAAAAAAAAAAAA---- ---AAAAAAAAAAAAAAAAAAAA--- ---AAAAAAAAAAAAAAAAAAAAA-- --AAAAAAAAAAAAAAAAAAAAAA-- --AAAAAAAAAAAAAAAAAAAAAA-- --AAAAAAAAAAAAAAAAAAAAAA-- --AAAAAAAAAAAAAAAAAAAAAA-- --AAAAAAAAAAAAAAAAAAAAAA-- ---AAAAAAAAAAAAAAAAAAAA--- --AAAAAAAAAAAAAAAAAAAAAA-- --AAAAAAAAAAAAAAAAAAAAAA-- --AAAAAAAAAAAAAAAAAAAAAA-- --AAAAAAAAAAAAAAAAAAAAAA-- --AAAAAAAAAAAAAAAAAAAAAA-- --AAAAAAAAAAAAAAAAAAAAAA-- --AAAAAAAAAAAAAAAAAAAAAB-- --AAAAAAAAAAAAAAAAAAAAAB-- --AAAAAAAAAAAAAAAAAAAAAB-- --BAAAAAAAAAAAAAAAAAAAAB-- --BAAAAAAAAAAAAAAAAAAAAB-- --BAAAAAAAAAAAAAAAAAAAAB-- --BBBBBBBBBBBBBBBBBBBBBB-- --BBBBBBBBBBBBBBBBBBBBBB-- --BBBBBBBBBBBBBBBBBBBBBB-- --BBBBBBBBBBBBBBBBBBBBBB-- -------------------------- 
------------AA------------ ------------AA------------ ------------AA------------ ---AAAAAAAAAAAAAAAAAAA---- ---AAAAAAAAAAAAAAAAAAAA--- ---AAAAAAAAAAAAAAAAAAAA--- ---AAAAAAAAAAAAAAAAAAAAA-- --AAAAAAAAAAAAAAAAAAAAAA-- --AAAAAAAAAAAAAAAAAAAAAA-- --AAAAAAAAAAAAAAAAAAAAAA-- --AAAAAAAAAAAAAAAAAAAAAA-- --AAAAAAAAAAAAAAAAAAAAAA-- --AAAAAAAAAAAAAAAAAAAAAA-- --AAAAAAAAAAAAAAAAAAAAAA-- --AAAAAAAAAAAAAAAAAAAAAA-- --AAAAAAAAAAAAAAAAAAAAAA-- --AAAAAAAAAAAAAAAAAAAAAA-- --AAAAAAAAAAAAAAAAAAAAAA-- --AAAAAAAAAAAAAAAAAAAAAB-- --BAAAAAAAAAAAAAAAAAAAAB-- --BAAAAAAAAAAAAAAAAAAAAB-- --BAAAAAAAAAAAAAAAAAAAAB-- --BAAAAAAAAAAAAAAAAAAAAB-- --BAAAAAAAAAAAAAAAAAAAAB-- --BBBBBBBBBBBBBBBBBBBBBB-- --BBBBBBBBBBBBBBBBBBBBBB-- --BBBBBBBBBBBBBBBBBBBBBB-- --BBBBBBBBBBBBBBBBBBBBBB-- -------------------------- 
----------AAAAAA---------- ----------AAAAAA---------- ----------AAAAAA---------- ----------AAAAAA---------- ---AAAAAAAAAAAAAAAAAAAA--- ---AAAAAAAAAAAAAAAAAAAA--- ---AAAAAAAAAAAAAAAAAAAA--- --AAAAAAAAAAAAAAAAAAAAAA-- --AAAAAAAAAAAAAAAAAAAAAA-- --AAAAAAAAAAAAAAAAAAAAAA-- --AAAAAAAAAAAAAAAAAAAAAA-- --AAAAAAAAAAAAAAAAAAAAAA-- --AAAAAAAAAAAAAAAAAAAAAA-- --AAAAAAAAAAAAAAAAAAAAAA-- --AAAAAAAAAAAAAAAAAAAAAA-- --AAAAAAAAAAAAAAAAAAAAAB-- --AAAAAAAAAAAAAAAAAAAAAB-- --AAAAAAAAAAAAAAAAAAAAAB-- --AAAAAAAAAAAAAAAAAAAAAB-- --BAAAAAAAAAAAAAAAAAAAAB-- --BAAAAAAAAAAAAAAAAAAAAB-- --BAAAAAAAAAAAAAAAAAAAAB-- --BAAAAAAAAAAAAAAAAAAAAB-- --BAAAAAAAAAAAAAAAAAAAAB-- --BBBBBBBBBBBBBBBBBBBBBB-- --BBBBBBBBBBBBBBBBBBBBBB-- --BBBBBBBBBBBBBBBBBBBBBB-- --BBBBBBBBBBBBBBBBBBBBBB-- --BBBBBBBBBBBBBBBBBBBBBB-- 
--------AAAAAAAAAA-------- --------AAAAAAAAAA-------- --------AAAAAAAAAA-------- --------AAAAAAAAAA-------- ----AAAAAAAAAAAAAAAAAAA--- ---AAAAAAAAAAAAAAAAAAAA--- ---AAAAAAAAAAAAAAAAAAAA--- ---AAAAAAAAAAAAAAAAAAAA--- --AAAAAAAAAAAAAAAAAAAAAA-- --AAAAAAAAAAAAAAAAAAAAAA-- --AAAAAAAAAAAAAAAAAAAAAA-- --AAAAAAAAAAAAAAAAAAAAAA-- --AAAAAAAAAAAAAAAAAAAAAA-- --AAAAAAAAAAAAAAAAAAAAAA-- --AAAAAAAAAAAAAAAAAAAAAA-- --BAAAAAAAAAAAAAAAAAAAAB-- --BAAAAAAAAAAAAAAAAAAAAB-- --BAAAAAAAAAAAAAAAAAAAAB-- --BAAAAAAAAAAAAAAAAAAAAB-- --BAAAAAAAAAAAAAAAAAAAAB-- --BAAAAAAAAAAAAAAAAAAAAB-- --BAAAAAAAAAAAAAAAAAAAAB-- --BAAAAAAAAAAAAAAAAAAAAB-- --BAAAAAAAAAAAAAAAAAAAAB-- --BBBBBBBBBBBBBBBBBBBBBB-- --BBBBBBBBBBBBBBBBBBBBBB-- --BBBBBBBBBBBBBBBBBBBBBB-- --BBBBBBBBBBBBBBBBBBBBBB-- --BBBBBBBBBBBBBBBBBBBBBB-- 
-----AAAAAAAAAAAAAAAA----- -----AAAAAAAAAAAAAAAA----- -----AAAAAAAAAAAAAAAA----- -----AAAAAAAAAAAAAAAA----- ----AAAAAAAAAAAAAAAAAA---- ----AAAAAAAAAAAAAAAAAAA--- ---AAAAAAAAAAAAAAAAAAAA--- ---AAAAAAAAAAAAAAAAAAAA--- ---AAAAAAAAAAAAAAAAAAAA--- AAAAAAAAAAAAAAAAAAAAAAAAAA AAAAAAAAAAAAAAAAAAAAAAAAAA AAAAAAAAAAAAAAAAAAAAAAAAAA --AAAAAAAAAAAAAAAAAAAAAA-- AAAAAAAAAAAAAAAAAAAAAAAAAA AAAAAAAAAAAAAAAAAAAAAAAAAA --BAAAAAAAAAAAAAAAAAAAAB-- --BAAAAAAAAAAAAAAAAAAAAB-- --BAAAAAAAAAAAAAAAAAAAAB-- --BAAAAAAAAAAAAAAAAAAAAB-- --BAAAAAAAAAAAAAAAAAAAAB-- --BAAAAAAAAAAAAAAAAAAAAB-- --BAAAAAAAAAAAAAAAAAAAAB-- --BAAAAAAAAAAAAAAAAAAAAB-- --BAAAAAAAAAAAAAAAAAAAAB-- --BBBBBBBBBBBBBBBBBBBBBB-- --BBBBBBBBBBBBBBBBBBBBBB-- --BBBBBBBBBBBBBBBBBBBBBB-- --BBBBBBBBBBBBBBBBBBBBBB-- --BBBBBBBBBBBBBBBBBBBBBB-- 
-----AAAAAAAAAAAAAAAA----- -----AAAAAAAAAAAAAAAA----- -----AAAAAAAAAAAAAAAA----- -----AAAAAAAAAAAAAAAA----- ----AAAAAAAAAAAAAAAAAA---- ----AAAAAAAAAAAAAAAAAA---- ----AAAAAAAAAAAAAAAAAAA--- ---AAAAAAAAAAAAAAAAAAAA--- ---AAAAAAAAAAAAAAAAAAAA--- AAAAAAAAAAAAAAAAAAAAAAAAAA AAAAAAAAAAAAAAAAAAAAAAAA-A --AAAAAAAAAAAAAAAAAAAAAA-- --AAAAAAAAAAAAAAAAAAAAAA-- AAAAAAAAAAAAAAAAAAAAA--AAA AAAAAAAAAAAAAAAAAAAAAAAAAA AAAAAAAAAAAAAAAAAAAAAAAAAA --BAAAAAAAAAAAAAAAAAAAAB-- --BAAAAAAAAAAAAAAAAAAAAB-- --BAAAAAAAAAAAAAAAAAAAAB-- --BAAAAAAAAAAAAAAAAAAAAB-- --BAAAAAAAAAAAAAAAAAAAAB-- --BAAAAAAAAAAAAAAAAAAAAB-- --BAAAAAAAAAAAAAAAAAAAAB-- --BAAAAAAAAAAAAAAAAAAAAB-- --BBBBBBBBBBBBBBBBBBBBBB-- --BBBBBBBBBBBBBBBBBBBBBB-- --BBBBBBBBBBBBBBBBBBBBBB-- --BBBBBBBBBBBBBBBBBBBBBB-- --BBBBBBBBBBBBBBBBBBBBBB-- 
-----AAAAAAAAAAAAAAAA----- -----AAAAAAAAAAAAAAAA----- -----AAAAAAAAAAAAAAAA----- -----AAAAAAAAAAAAAAAA----- -----AAAAAAAAAAAAAAAAA---- ----AAAAAAAAAAAAAAAAAA---- ----AAAAAAAAAAAAAAAAAA---- ---AAAAAAAAAAAAAAAAAAAA--- ---AAAAAAAAAAAAAAAAAAAA--- AAAAAAAAAAAAAAAAAAAAAAAAAA AAAAAAAAAAAAAAAAAAAAAAAA-A --AAAAAAAAAAAAAAAAAAAAAA-- ---AAAAAAAAAAAAAAAAAAAA--- --AAAAAAAAAAAAAAAAAAAAAA-- AAAAAAAAAAAAAAAAAAAAAAAAAA AAAAAAAAAAAAAAAAAAAAAAAAAA AAAAAAAAAAAAAAAAAAAAAAAAAA --BAAAAAAAAAAAAAAAAAAAAB-- --BAAAAAAAAAAAAAAAAAAAAB-- --BAAAAAAAAAAAAAAAAAAAAB-- --BAAAAAAAAAAAAAAAAAAAAB-- --BAAAAAAAAAAAAAAAAAAAAB-- --BAAAAAAAAAAAAAAAAAAAAB-- --BAAAAAAAAAAAAAAAAAAAAB-- --BBBBBBBBBBBBBBBBBBBBBB-- --BBBBBBBBBBBBBBBBBBBBBB-- --BBBBBBBBBBBBBBBBBBBBBB-- --BBBBBBBBBBBBBBBBBBBBBB-- -------------------------- 
-----AAAAAAAAAAAAAAAA----- -----AAAAAAAAAAAAAAAA----- -----AAAAAAAAAAAAAAAA----- -----AAAAAAAAAAAAAAAA----- -----AAAAAAAAAAAAAAAA----- -----AAAAAAAAAAAAAAAAA---- ----AAAAAAAAAAAAAAAAAA---- ----AAAAAAAAAAAAAAAAAA---- ----AAAAAAAAAAAAAAAAAA---- AAAAAAAAAAAAAAAAAAAAAAAAAA AAAAAAAAAAAAAAAAAAAAAAAA-A AAAAAAAAAAAAAAAAAAAAAAAAAA --AAAAAAAAAAAAAAAAAAAAAA-- --AAAAAAAAAAAAAAAAAAAAAA-- --AAAAAAAAAAAAAAAAAAAAAA-- AAAAAAAAAAAAAAAAAAAAAAAAAA AAAAAAAAAAAAAAAAAAAAAAAAAA --BAAAAAAAAAAAAAAAAAAAAB-- --BAAAAAAAAAAAAAAAAAAAAB-- --BAAAAAAAAAAAAAAAAAAAAB-- --BAAAAAAAAAAAAAAAAAAAAB-- --BAAAAAAAAAAAAAAAAAAAAB-- --BAAAAAAAAAAAAAAAAAAAAB-- --BAAAAAAAAAAAAAAAAAAAAB-- --BBBBBBBBBBBBBBBBBBBBBB-- --BBBBBBBBBBBBBBBBBBBBBB-- --BBBBBBBBBBBBBBBBBBBBBB-- --BBBBBBBBBBBBBBBBBBBBBB-- -------------------------- 
-----AAAAAAAAAAAAAAAA----- -----AAAAAAAAAAAAAAAA----- -----AAAAAAAAAAAAAAAA----- -----AAAAAAAAAAAAAAAA----- -----AAAAAAAAAAAAAAAA----- -----AAAAAAAAAAAAAAAA----- -----AAAAAAAAAAAAAAAAA---- ----AAAAAAAAAAAAAAAAAA---- ----AAAAAAAAAAAAAAAAAA---- --BBAAAAAAAAAAAAAAAAAABA-- AAAAAAAAAAAAAAAAAAAAAAAAAA AAAAAAAAAAAAAAAAAAAAAAAA-A AAAAAAAAAAAAAAAAAAAAAAAAAA AAAAAAAAAAAAAAAAAAAAAAAAAA AAAAAAAAAAAAAAAAAAAAAAAAAA AAAAAAAAAAAAAAAAAAAAAAAAAA AAAAAAAAAAAAAAAAAAAAAAAAAA --BAAAAAAAAAAAAAAAAAAAAB-- --BAAAAAAAAAAAAAAAAAAAAB-- --BAAAAAAAAAAAAAAAAAAAAB-- --BAAAAAAAAAAAAAAAAAAAAB-- --BAAAAAAAAAAAAAAAAAAAAB-- --BAAAAAAAAAAAAAAAAAAAAB-- --BAAAAAAAAAAAAAAAAAAAAB-- --BBBBBBBBBBBBBBBBBBBBBB-- --BBBBBBBBBBBBBBBBBBBBBB-- --BBBBBBBBBBBBBBBBBBBBBB-- --BBBBBBBBBBBBBBBBBBBBBB-- -------------------------- 
-----AAAAAAAAAAAAAAAA----- -----AAAAAAAAAAAAAAAA----- -----AAAAAAAAAAAAAAAA----- -----AAAAAAAAAAAAAAAA----- -----AAAAAAAAAAAAAAAA----- -----AAAAAAAAAAAAAAAA----- -----AAAAAAAAAAAAAAAA----- ----BAAAAAAAAAAAAAAAA----- ----BAAAAAAAAAAAAAAAABB--- --BBAAAAAAAAAAAAAAAAAAAB-- --BAAAAAAAAAAAAAAAAAAAAB-- AAAAAAAAAAAAAAAAAAAAAAAAAA AAAAAAAAAAAAAAAAAAAAAAAAAA AAAAAAAAAAAAAAAAAAAAAAAAAA AAAAAAAAAAAAAAAAAAAAAAAAAA AAAAAAAAAAAAAAAAAAAAAAAAAA AAAAAAAAAAAAAAAAAAAAAAAAAA --BAAAAAAAAAAAAAAAAAAAAB-- --BAAAAAAAAAAAAAAAAAAAAB-- --BAAAAAAAAAAAAAAAAAAAAB-- --BAAAAAAAAAAAAAAAAAAAAB-- --BAAAAAAAAAAAAAAAAAAAAB-- --BAAAAAAAAAAAAAAAAAAAAB-- --BAAAAAAAAAAAAAAAAAAAAB-- --BBBBBBBBBBBBBBBBBBBBBB-- --BBBBBBBBBBBBBBBBBBBBBB-- --BBBBBBBBBBBBBBBBBBBBBB-- -------------------------- -------------------------- 
-----AAAAAAAAAAAAAAAA----- -----AAAAAAAAAAAAAAAA----- -----AAAAAAAAAAAAAAAA----- -----AAAAAAAAAAAAAAAA----- -----AAAAAAAAAAAAAAAA----- -----AAAAAAAAAAAAAAAA----- -----AAAAAAAAAAAAAAAA----- ----BAAAAAAAAAAAAAAAA----- ----BAAAAAAAAAAAAAAAABB--- --BBAAAAAAAAAAAAAAAAAAAB-- --BAAAAAAAAAAAAAAAAAAAAB-- --BAAAAAAAAAAAAAAAAAAAAB-- --BAAAAAAAAAAAAAAAAAAAAB-- --BAAAAAAAAAAAAAAAAAAAAB-- --BAAAAAAAAAAAAAAAAAAAAB-- --BAAAAAAAAAAAAAAAAAAAAB-- --BAAAAAAAAAAAAAAAAAAAAB-- --BAAAAAAAAAAAAAAAAAAAAB-- --BAAAAAAAAAAAAAAAAAAAAB-- --BAAAAAAAAAAAAAAAAAAAAB-- --BAAAAAAAAAAAAAAAAAAAAB-- --BAAAAAAAAAAAAAAAAAAAAB-- --BAAAAAAAAAAAAAAAAAAAAB-- --BAAAAAAAAAAAAAAAAAAAAB-- --BBBBBBBBBBBBBBBBBBBBBB-- --BBBBBBBBBBBBBBBBBBBBBB-- --BBBBBBBBBBBBBBBBBBBBBB-- -------------------------- -------------------------- 
------AAAAAAAAAAAAAA------ ------AAAAAAAAAAAAAA------ ------AAAAAAAAAAAAAA------ ------AAAAAAAAAAAAAA------ ------AAAAAAAAAAAAAA------ ------AAAAAAAAAAAAAA------ ------AAAAAAAAAAAAAA------ ----BBAAAAAAAAAAAAAAB----- ----BAAAAAAAAAAAAAAAABB--- --BBAAAAAAAAAAAAAAAAAAAB-- --BAAAAAAAAAAAAAAAAAAAAB-- --BAAAAAAAAAAAAAAAAAAAAB-- --BAAAAAAAAAAAAAAAAAAAAB-- --BAAAAAAAAAAAAAAAAAAAAB-- --BAAAAAAAAAAAAAAAAAAAAB-- --BAAAAAAAAAAAAAAAAAAAAB-- --BAAAAAAAAAAAAAAAAAAAAB-- --BAAAAAAAAAAAAAAAAAAAAB-- --BAAAAAAAAAAAAAAAAAAAAB-- --BAAAAAAAAAAAAAAAAAAAAB-- --BAAAAAAAAAAAAAAAAAAAAB-- --BAAAAAAAAAAAAAAAAAAAAB-- --BAAAAAAAAAAAAAAAAAAAAB-- --BAAAAAAAAAAAAAAAAAAAAB-- --BBBBBBBBBBBBBBBBBBBBBB-- --BBBBBBBBBBBBBBBBBBBBBB-- -------------------------- -------------------------- -------------------------- 
--------AAAAAAAAAA-------- --------AAAAAAAAAA-------- --------AAAAAAAAAA-------- --------AAAAAAAAAA-------- --------AAAAAAAAAA-------- --------AAAAAAAAAA-------- --------AAAAAAAAAA-------- ----BBBBBBBBBBBBBBBBB----- ----BBBBBBBBBBBBBBBBBBB--- --BBBBBBBBBBBBBBBBBBBBBB-- --BBBBBBBBBBBBBBBBBBBBBB-- --BBBBBBBBBBBBBBBBBBBBBB-- --BBBBBBBBBBBBBBBBBBBBBB-- --BBBBBBBBBBBBBBBBBBBBBB-- --BAAAAAAAAAAAAAAAAAAAAB-- --BAAAAAAAAAAAAAAAAAAAAB-- --BAAAAAAAAAAAAAAAAAAAAB-- --BAAAAAAAAAAAAAAAAAAAAB-- --BAAAAAAAAAAAAAAAAAAAAB-- --BAAAAAAAAAAAAAAAAAAAAB-- --BAAAAAAAAAAAAAAAAAAAAB-- --BAAAAAAAAAAAAAAAAAAAAB-- --BAAAAAAAAAAAAAAAAAAAAB-- --BAAAAAAAAAAAAAAAAAAAAB-- --BBBBBBBBBBBBBBBBBBBBBB-- -------------------------- -------------------------- -------------------------- -------------------------- 
----------AAAAAA---------- ----------AAAAAA---------- ----------AAAAAA---------- ----------AAAAAA---------- ----------AAAAAA---------- ----------AAAAAA---------- ----------AAAAAA---------- ----BBBBBBBBBBBBBBBBB----- ----BBBBBBBBBBBBBBBBBBB--- --BBBBBBBBBBBBBBBBBBBBBB-- --BBBBBBBBBBBBBBBBBBBBBB-- --BBBBBBBBBBBBBBBBBBBBBB-- --BBBBBBBBBBBBBBBBBBBBBB-- --BBBBBBBBBBBBBBBBBBBBBB-- --BBBBBBBBBBBBBBBBBBBBBB-- --BBBBBBBBBBBBBBBBBBBBBB-- --BBBBBBBBBBBBBBBBBBBBBB-- --BBBBBBBBBBBBBBBBBBBBBB-- --BBBBBBBBBBBBBBBBBBBBBB-- --BBBBBBBBBBBBBBBBBBBBBB-- --BBBBBBBBBBBBBBBBBBBBBB-- --BBBBBBBBBBBBBBBBBBBBBB-- --BBBBBBBBBBBBBBBBBBBBBB-- --BBBBBBBBBBBBBBBBBBBBBB-- -------------------------- -------------------------- -------------------------- -------------------------- -------------------------- 
-------------------------- -------------------------- -------------------------- -------------------------- -------------------------- -------------------------- -------------------------- ----BBBBBBBBBBBBBBBBB----- ----BBBBBBBBBBBBBBBBBBB--- --BBBBBBBBBBBBBBBBBBBBBB-- --BBBBBBBBBBBBBBBBBBBBBB-- --BBBBBBBBBBBBBBBBBBBBBB-- --BBBBBBBBBBBBBBBBBBBBBB-- --BBBBBBBBBBBBBBBBBBBBBB-- --BBBBBBBBBBBBBBBBBBBBBB-- --BBBBBBBBBBBBBBBBBBBBBB-- --BBBBBBBBBBBBBBBBBBBBBB-- --BBBBBBBBBBBBBBBBBBBBBB-- --BBBBBBBBBBBBBBBBBBBBBB-- --BBBBBBBBBBBBBBBBBBBBBB-- --BBBBBBBBBBBBBBBBBBBBBB-- --BBBBBBBBBBBBBBBBBBBBBB-- --BBBBBBBBBBBBBBBBBBBBBB-- -------------------------- -------------------------- -------------------------- -------------------------- -------------------------- -------------------------- 
-------------------------- -------------------------- -------------------------- -------------------------- -------------------------- -------------------------- -------------------------- -------------------------- ----BBBBBBBBBBBBBBBBBBB--- --BBBBBBBBBBBBBBBBBBBBBB-- --BBBBBBBBBBBBBBBBBBBBBB-- --BBBBBBBBBBBBBBBBBBBBBB-- --BBBBBBBBBBBBBBBBBBBBBB-- --BBBBBBBBBBBBBBBBBBBBBB-- --BBBBBBBBBBBBBBBBBBBBBB-- --BBBBBBBBBBBBBBBBBBBBBB-- --BBBBBBBBBBBBBBBBBBBBBB-- --BBBBBBBBBBBBBBBBBBBBBB-- --BBBBBBBBBBBBBBBBBBBBBB-- --BBBBBBBBBBBBBBBBBBBBBB-- --BBBBBBBBBBBBBBBBBBBBBB-- -------------------------- -------------------------- -------------------------- -------------------------- -------------------------- -------------------------- -------------------------- -------------------------- 
-------------------------- -------------------------- -------------------------- -------------------------- -------------------------- -------------------------- -------------------------- -------------------------- -------------------------- -------------------------- -------------------------- --BBBBBBBBBBBBBBBBBBBBBB-- --BBBBBBBBBBBBBBBBBBBBBB-- --BBBBBBBBBBBBBBBBBBBBBB-- --BBBBBBBBBBBBBBBBBBBBBB-- --BBBBBBBBBBBBBBBBBBBBBB-- --BBBBBBBBBBBBBBBBBBBBBB-- --BBBBBBBBBBBBBBBBBBBBBB-- -------------------------- -------------------------- -------------------------- -------------------------- -------------------------- -------------------------- -------------------------- -------------------------- -------------------------- -------------------------- -------------------------- 
