model
size = 28 17 7, scale = 0.05, origin = -y
material 
  colors = A:#FCF078 B:#FFEA3F C:#FDEF5B D:#FED638 E:#FAA821 F:#F9C12C G:#FEF6A1 H:#002 I:#00B J:#005 K:#004 L:#EF7F1B M:#001 N:#E00 O:#007 P:#00D Q:#00A R:#008 S:#00E
voxels
---------------------------- ---------------------------- ---------------------------- ---------------------------- ---------------------------- ---------------------------- ---------------------------- ---------------------------- ------------H--H------------ ------------M--M------------ ---------------------------- ---------------------------- ---------------------------- ---------------------------- ---------------------------- ---------------------------- ---------------------------- 
---------------------------- ---------------------------- ---------------------------- ---------------------------- ---------------------------- ---------------------------- ---------------------------- ------------KKKK------------ ------------MHHM------------ ------------MMMM------------ -----------HM--MH----------- ---------------------------- ---------------------------- ---------------------------- ---------------------------- ---------------------------- ---------------------------- 
---------------------------- ---------------------------- ---------------------------- ---------------------------- ---------------------------- ---------------------------- ------------J--J------------ -----------EL--LE----------- ----------EEL--LEE---------- ---------FEHL--LHEF--------- --------FFHH----HHFF-------- ---------FKH----HKF--------- ---------KK------KK--------- --------JJ--------JJ-------- ---------------------------- ---------------------------- ---------------------------- 
---------------------------- ---------------------------- ---------------------------- ---------------------------- ---------------------------- ---------------------------- ---------------------------- --------D---L--L---D-------- --------DFEEL--LEEFD-------- -------BDNEE----EENDB------- ------CBNNNE----ENNNBC------ -------BDNE------ENDB------- --------DF--------FD-------- --------J----------J-------- --------J----------J-------- ---------------------------- ---------------------------- 
---------------------------- ---------------------------- ---------------------------- ---------------------------- ---------------------------- ---------------------------- ---------------------------- -------B------------B------- ------CBD----------DBC------ -----ACBDF--------FDBCA----- ----AACBDFE------EFDBCAA---- ---QAACBDF--------FDBCAAQ--- ---QRACBD----------DBCARQ--- ----RRCB------------BCRR---- -----ROO------------OOR----- ------OO------------OO------ -------O------------O------- 
---------------------------- ---------------------------- ---------------------------- ---------------------------- ------C--------------C------ -----AC--------------CA----- ----AACB------------BCAA---- --PGAAC--------------CAAGP-- --GGAA----------------AAGG-- --GGA------------------AGG-- --QG--------------------GQ-- --Q----------------------Q-- ---------------------------- ---------------------------- ---------------------------- ---------------------------- ---------------------------- 
--------D----------D-------- -------BD----------DB------- ------CBD----------DBC------ -----ACB------------BCA----- ----SAC--------------CAS---- ---SAA----------------AAS--- --PSA------------------ASP-- -PPG--------------------GPP- III----------------------III IIG----------------------GII -II----------------------II- ---------------------------- ---------------------------- ---------------------------- ---------------------------- ---------------------------- ---------------------------- 
