model
size = 18 21 5, scale = 0.05, origin = -y
material 
  colors = A:#F2E100 B:#F00 C:#0F0F0F D:#070707 E:#593621
voxels
------------------ ------------------ ------------------ ------------------ ------------------ ------------------ ------------------ ------------------ ------------------ -----E------E----- -----E------E----- -----E------E----- -----E------E----- -----E------E----- -----E------E----- -----E------E----- -----E------E----- ------------------ ------------------ ------------------ ------------------ 
------------------ ------------------ ------------------ ------------------ ------------------ ------------------ ------------------ ------------------ ------------------ -----E------E----- ------------------ ------------------ ------------------ ------------------ ------------------ ------------------ -----E------E----- ------------------ ------------------ ------------------ ------------------ 
------------------ ------------------ -------AAAA------- ------AAAAAA------ -----AAAAAAAA----- -----AAAAAAAA----- ----AAAAAAAAAA---- ----AAAAAAAAAA---- ---AAAAAAAAAAAA--- ---AAAAAAAAAAAA--- --AA----------AA-- --AA----------AA-- --AA----------AA-- -AAA----------AAA- -AAA----------AAA- -AAA----------AAA- -AAAAAAAAAAAAAAAA- -AAAAAAAAAAAAAAAA- -AAAAAAAAAAAAAAAA- -AAAAAAAAAAAAAAAA- ------------------ 
--------AA-------- -------AAAA------- ------AAAAAA------ -----AAAAAAAA----- ----AAAAAAAAAA---- ----AAAAAAAAAA---- ---AAAAAAAAAAAA--- ---AAAAAADDDDDA--- --AAABBBBCCCCDAA-- --AAABBBBCCCCDAA-- -AAAABBBBCCCCDAAA- -AAAABBBBCCCCDAAA- -AAADCCCCBBBBAAAA- AAAADCCCCBBBBAAAAA AAAADCCCCBBBBAAAAA AAAADDDDDBBBBAAAAA AAAADDDDDAAAAAAAAA AAAAAAAAAAAAAAAAAA AAAAAAAAAAAAAAAAAA AAAAAAAAAAAAAAAAAA AA------AA------AA 
------------------ ------------------ ------------------ ------------------ ------------------ ------------------ ------------------ ------------------ ------------------ ------------------ ------------------ --------AA-------- --------AA-------- ------------------ ------------------ ------------------ ------------------ ------------------ ------------------ ------------------ ------------------ 
