model
size = 14 28 15, scale = 0.05, origin = -y
material 
  colors = A:#111 B:#222 C:#050 D:#020 E:#080 F:#E00
voxels
-------------- -------------- -------------- -------------- -------------- -------------- ---A---------- AAAA---------- AAAA---------- AAAA---------- AAAA---------- AAAA---------- AAAA---------- AAAA---------- AAAA---------- AAAA---------- AAAAA--------- AAAAA--------- ---AAA-------- ----AAA------- -----AAA------ ------AAA----- -------AA----- -------------- -------------- AAA----------- AAA----------- AAA----------- 
-------------- -------------- -------------- -------------- ---A---------- --AA---------- --AA---------- AAAA---------- AAAA---------- AAAA---------- AAAA---------- AAAA---------- AAAA---------- AAAA---------- AAAA---------- AAAA---------- AAAAA--------- AAAAA--------- -A-AAA-------- -A--AAA------- -A---AAA------ -A----AAA----- -A-----AAA---- -A------AA---- -A------------ AAA----------- AAA----------- AAA----------- 
-------------- -------------- ---A---------- --AA---------- -AAA---------- -AAB---------- -AAB---------- -AAA---------- -AAB---------- -AAB---------- -AAA---------- -AAAB--------- -AAAB--------- -AAAB--------- -AAAB--------- AAAAB--------- AAAAA--------- --AAA--------- ---AAA-------- ----AAA------- -----AAA------ ------AAA----- -------AAA---- --------AAA--- ---------AA--- AAA----------- AAA----------- AAA----------- 
-------------- ---A---------- --AA---------- --AA---------- -AAA---------- -AAD---------- -AAB---------- -AAA---------- -AAE---------- -AAB---------- -AAA---------- -AAAB--------- -AAAC--------- -AAAB--------- -AAAC--------- AAAAB--------- AAAAA--------- --AAA--------- ---AAA-------- ----AAA------- -----AAA------ ------AAA----- -------AAA---- --------AAA--- ---------AAA-- ----------AA-- -------------- -------------- 
---A---------- --AA---------- -AAB---------- -AAB---------- -AAA---------- -AAB---------- -AAB---------- -AAA---------- -AAB---------- -AAB---------- -AAA---------- -AAAB--------- -AAAC--------- -AAAB--------- -AAAC--------- AAAAB--------- AAAAA--------- --AAA--------- ---AAA-------- ----AAA------- -----AAA------ ------AAA----- -------AAA---- --------AAB--- ---------AAA-- ----------AAA- -----------AA- -------------- 
---A---------- --AA---------- -AAD---------- -AAB---------- -AAA---------- -AAA---------- -AAA---------- -AAA---------- -AAA---------- -AAA---------- -AAA---------- -AAAB--------- -AAAC--------- -AAAB--------- -AAAB--------- AAAAB--------- AAAAA--------- --AAA--------- ---AAA-------- ----AAA------- -----AAA------ ------AAA----- -------AAB---- --------AAA--- ---------AAB-- ----------AAA- -----------AAA ------------AA 
---A---------- --AA---------- -AAB---------- -AAB---------- -AAA---------- -AAB---------- -AAB---------- -AAA---------- -AAB---------- -AAB---------- -AAA---------- -AAAB--------- -AAAC--------- -AAAB--------- -AAAB--------- AAAAB--------- AAAAA--------- --AAA--------- ---AAA-------- ----AAA------- -----AAA------ ------AAB----- -------AAA---- --------AAB--- ---------AAA-- ----------AAB- -----------AAA ------------AA 
---A---------- --AA---------- -AAA---------- -AAA---------- -AAA---------- -AAD---------- -AAB---------- -AAA---------- -AAD---------- -AAB---------- -AAA---------- -AAAB--------- -AAAB--------- -AAAB--------- -AAAC--------- AAAAB--------- AAAAA--------- --AAA--------- ---AAA-------- ----AAA------- -----AAA------ ------AAA----- -------AAB---- --------AAA--- ---------AAB-- ----------AAA- -----------AAA ------------AA 
---A---------- --AA---------- -AAB---------- -AAB---------- -AAA---------- -AAB---------- -AAB---------- -AAA---------- -AAB---------- -AAB---------- -AAA---------- -AAAB--------- -AAAB--------- -AAAB--------- -AAAB--------- AAAAB--------- AAAAA--------- --AAA--------- ---AAA-------- ----AAA------- -----AAA------ ------AAB----- -------AAA---- --------AAB--- ---------AAA-- ----------AAB- -----------AAA ------------AA 
---A---------- --AA---------- -AAD---------- -AAB---------- -AAA---------- -AAA---------- -AAA---------- -AAA---------- -AAA---------- -AAA---------- -AAA---------- -AAAB--------- -AAAC--------- -AAAB--------- -AAAB--------- AAAAB--------- AAAAA--------- --AAA--------- ---AAA-------- ----AAA------- -----AAA------ ------AAA----- -------AAB---- --------AAA--- ---------AAB-- ----------AAA- -----------AAA ------------AA 
---A---------- --AA---------- --AB---------- --AB---------- -AAA---------- -AAB---------- -AAB---------- -AAA---------- -AAB---------- -AAB---------- -AAA---------- -AAAB--------- -AAAB--------- -AAAB--------- -AAAC--------- AAAAB--------- AAAAA--------- --AAA--------- ---AAA-------- ----AAA------- -----AAA------ ------AAA----- -------AAA---- --------AAB--- ---------AAA-- ----------AAA- -----------AA- -------------- 
-------------- ---A---------- --AA---------- --AA---------- -AAA---------- -AAD---------- -AAB---------- -AAA---------- -AAF---------- -AAB---------- -AAA---------- -AAAB--------- -AAAC--------- -AAAB--------- -AAAC--------- AAAAB--------- AAAAA--------- --AAA--------- ---AAA-------- ----AAA------- -----AAA------ ------AAA----- -------AAA---- --------AAA--- ---------AAA-- ----------AA-- -------------- -------------- 
-------------- -------------- ---A---------- --AA---------- --AA---------- --AB---------- -AAB---------- -AAA---------- -AAB---------- -AAB---------- -AAA---------- -AAAB--------- -AAAB--------- -AAAB--------- -AAAB--------- AAAAB--------- AAAAA--------- --AAA--------- ---AAA-------- ----AAA------- -----AAA------ ------AAA----- -------AAA---- --------AAA--- ---------AA--- -------------- -------------- -------------- 
-------------- -------------- -------------- -------------- ---A---------- --AA---------- --AA---------- --AA---------- --AA---------- --AA---------- --AA---------- --AA---------- --AA---------- --AA---------- --AA---------- --AA---------- --AAA--------- --AAA--------- ---AAA-------- ----AAA------- -----AAA------ ------AAA----- -------AAA---- --------AA---- -------------- -------------- -------------- -------------- 
-------------- -------------- -------------- -------------- -------------- -------------- ---A---------- --AA---------- --AA---------- --AA---------- --AA---------- --AA---------- --AA---------- --AA---------- --AA---------- --AA---------- --AAA--------- --AAA--------- ---AAA-------- ----AAA------- -----AAA------ ------AAA----- -------AA----- -------------- -------------- -------------- -------------- -------------- 
