model
size = 18 22 15, scale = 0.05, origin = -y
material 
  colors = A:#FFD000
voxels
------------------ ------------------ ------------------ ------------------ ------------------ ------------------ ------------------ ------AAAAAA------ ------AAAAAA------ ------AAAAAA------ ------AAAAAA------ ------AAAAAA------ ------AAAAAA------ ------------------ ------------------ ------------------ ------------------ ------------------ ------------------ ------------------ ------------------ ------------------ 
------------------ ------------A----- -----------AA----- ----------AAA----- ---------AAAA----- ---------AAAA----- ---------AAAA----- ----AA-----AA----- ----AA-----AA----- ----AA-----AA----- ----AA-----AA----- ----AA-----AA----- -----AAAAAAAA----- ------AAAAAA------ ------------------ ------------------ ------------------ ------------------ ------------------ ------------------ ------------------ ------------------ 
-------------A---- -------------A---- -------------A---- -------------A---- -------------A---- -------------A---- -------------A---- ---AA--------A---- ---AA--------A---- ---AA--------A---- ---AA--------A---- ---AA--------A---- ----A--------A---- -----AAAAAAAAA---- ------AAAAAA------ ------------------ ------------------ ------------------ ------------------ ------------------ ------------------ ------------------ 
--------------A--- --------------A--- --------------A--- --------------A--- --------------A--- --------------A--- --------------A--- --AA----------A--- --AA-------------- --AA-------------- --AA----------A--- --AA----------A--- ---A----------A--- ----AA--------A--- -----AAAAAAAAA---- ------AAAAAA------ ------------------ ------------------ ------------------ ------------------ ------------------ ------------------ 
--------------A--- --------------A--- --------------A--- --------------A--- --------------A--- --------------A--- --------------A--- --A-----------A--- --A--------------- --A--------------- --A-----------A--- --A-----------A--- --A-----------A--- ---AAA--------A--- ----AAAAAAAAAAA--- -----AAAAAAAAA---- ------AAAAAA------ ------------------ ------------------ ------------------ ------------------ ------------------ 
------------------ ------------------ ------------------ ------------------ ------------------ ------------------ ------------------ --A--------------- --A--------------- --A--------------- --A------------A-- --A------------A-- --A------------A-- --AAAA---------A-- ---AAA---------A-- ----AAAAAAAAAAAA-- -----AAAAAAAAA---- ------------------ ------------------ ------------------ ------------------ ------------------ 
------------------ ------------------ ------------------ ------------------ ------------------ ------------------ ------------------ --A--------------- --A------------A-- --A------------A-- --A------------A-- --A------------A-- --A------------A-- --AAAA---------A-- ---AAA---------A-- ----AAAAAAAAAAAA-- -----AAAAAAAAAAA-- ------AAAAAAAA---- ------------------ ------------------ ------------------ ------------------ 
------------------ ------------------ ------------------ ------------------ ------------------ ------------------ ------------------ --A-------------AA --A-------------AA --A-------------AA --A-------------AA --A-------------AA --A-------------AA --AAAA----------AA --AAAA----------AA ----AAAAAAAAAAAAAA ---AAAAAAAAAAAAAAA --AAAAAAAAAAAAAAAA -AAAAAAAAAAAAAAAAA AAAAAAAAAAAAAAAAAA AAAAAAAAAAAAAAAAAA AAAAAAAAAAAAAAAAAA 
------------------ ------------------ ------------------ ------------------ ------------------ ------------------ ------------------ --A--------------- --A------------A-- --A------------A-- --A------------A-- --A------------A-- --A------------A-- --AAAA---------A-- ---AAA---------A-- ----AAAAAAAAAAAA-- -----AAAAAAAAAAA-- ------AAAAAAAA---- ------------------ ------------------ ------------------ ------------------ 
------------------ ------------------ ------------------ ------------------ ------------------ ------------------ ------------------ --A--------------- --A--------------- --A--------------- --A------------A-- --A------------A-- --A------------A-- --AAAA---------A-- ---AAA---------A-- ----AAAAAAAAAAAA-- -----AAAAAAAAA---- ------------------ ------------------ ------------------ ------------------ ------------------ 
--------------A--- --------------A--- --------------A--- --------------A--- --------------A--- --------------A--- --------------A--- --A-----------A--- --A--------------- --A--------------- --A-----------A--- --A-----------A--- --A-----------A--- ---AAA--------A--- ----AAAAAAAAAAA--- -----AAAAAAAAA---- ------AAAAAA------ ------------------ ------------------ ------------------ ------------------ ------------------ 
--------------A--- --------------A--- --------------A--- --------------A--- --------------A--- --------------A--- --------------A--- --AA----------A--- --AA-------------- --AA-------------- --AA----------A--- --AA----------A--- ---A----------A--- ----AA--------A--- -----AAAAAAAAA---- ------AAAAAA------ ------------------ ------------------ ------------------ ------------------ ------------------ ------------------ 
-------------A---- -------------A---- -------------A---- -------------A---- -------------A---- -------------A---- -------------A---- ---AA--------A---- ---AA--------A---- ---AA--------A---- ---AA--------A---- ---AA--------A---- ----A--------A---- -----AAAAAAAAA---- ------AAAAAA------ ------------------ ------------------ ------------------ ------------------ ------------------ ------------------ ------------------ 
------------------ ------------A----- -----------AA----- ----------AAA----- ---------AAAA----- ---------AAAA----- ---------AAAA----- ----AA------A----- ----AA------A----- ----AA------A----- ----AA------A----- ----AA------A----- -----AAAAAAAA----- ------AAAAAA------ ------------------ ------------------ ------------------ ------------------ ------------------ ------------------ ------------------ ------------------ 
------------------ ------------------ ------------------ ------------------ ------------------ ------------------ ------------------ ------AAAAAA------ ------AAAAAA------ ------AAAAAA------ ------AAAAAA------ ------AAAAAA------ ------AAAAAA------ ------------------ ------------------ ------------------ ------------------ ------------------ ------------------ ------------------ ------------------ ------------------ 
