model
size = 7 17 17, scale = 0.05, origin = -y
material 
  colors = A:#FF0 B:#E00
voxels
------- ------- ------- ------- ------- ------- AAABAAA ABBBBBA ABABABA ABBBBBA AAABAAA ------- ------- ------- ------- ------- ------- 
------- ------- ------- ------- AAABAAA AAABAAA ------- ------- ------- ------- ------- AAABAAA AAABAAA ------- ------- ------- ------- 
------- ------- AAABAAA AAABAAA ------- ------- ------- ------- ------- ------- ------- ------- ------- AAABAAA AAABAAA ------- ------- 
------- ------- AAABAAA ------- ------- ------- ------- ------- ------- ------- ------- ------- ------- ------- AAABAAA ------- ------- 
------- AAABAAA ------- ------- ------- ------- ------- ------- ------- ------- ------- ------- ------- ------- ------- AAABAAA ------- 
------- AAABAAA ------- ------- ------- ------- ------- ------- ------- ------- ------- ------- ------- ------- ------- AAABAAA ------- 
AAABAAA ------- ------- ------- ------- ------- ------- ------- ------- ------- ------- ------- ------- ------- ------- ------- AAABAAA 
ABBBBBA ------- ------- ------- ------- ------- ------- ------- ------- ------- ------- ------- ------- ------- ------- ------- ABBBBBA 
ABABABA ------- ------- ------- ------- ------- ------- ------- ------- ------- ------- ------- ------- ------- ------- ------- ABABABA 
ABBBBBA ------- ------- ------- ------- ------- ------- ------- ------- ------- ------- ------- ------- ------- ------- ------- ABBBBBA 
AAABAAA ------- ------- ------- ------- ------- ------- ------- ------- ------- ------- ------- ------- ------- ------- ------- AAABAAA 
------- AAABAAA ------- ------- ------- ------- ------- ------- ------- ------- ------- ------- ------- ------- ------- AAABAAA ------- 
------- AAABAAA ------- ------- ------- ------- ------- ------- ------- ------- ------- ------- ------- ------- ------- AAABAAA ------- 
------- ------- AAABAAA ------- ------- ------- ------- ------- ------- ------- ------- ------- ------- ------- AAABAAA ------- ------- 
------- ------- AAABAAA AAABAAA ------- ------- ------- ------- ------- ------- ------- ------- ------- AAABAAA AAABAAA ------- ------- 
------- ------- ------- ------- AAABAAA AAABAAA ------- ------- ------- ------- ------- AAABAAA AAABAAA ------- ------- ------- ------- 
------- ------- ------- ------- ------- ------- AAABAAA ABBBBBA ABABABA ABBBBBA AAABAAA ------- ------- ------- ------- ------- ------- 
