model
size = 14 18 20, scale = 0.05, origin = -y
material 
  colors = A:#EEE
voxels
------AA------ ------AA------ ------AA------ ------AA------ -------------- -------------- -------------- -------------- -------------- -------------- -------------- -------------- -------------- -------------- -------------- -------------- -------------- -------------- 
------AA------ ------AA------ ------AA------ ------AA------ -------------- -------------- -------------- -------------- -------------- -------------- -------------- -------------- -------------- -------------- -------------- -------------- -------------- -------------- 
----AAAAAA---- ----AAAAAA---- ----AAAAAA---- ----AAAAAA---- ------AA------ ------AA------ ------AA------ ------AA------ -------------- -------------- -------------- -------------- -------------- -------------- -------------- -------------- -------------- -------------- 
----AAAAAA---- ----AAAAAA---- ----AAAAAA---- ----AAAAAA---- ------AA------ ------AA------ ------AA------ ------AA------ -------------- -------------- -------------- -------------- -------------- -------------- -------------- -------------- -------------- -------------- 
----AAAAAA---- ----AAAAAA---- ----AAAAAA---- ----AAAAAA---- ----AAAAAA---- ----AAAAAA---- ------AAAA---- ------AAAA---- ------AA------ ------AA------ ------AA------ ------AA------ ------AA------ ------AA------ -------------- -------------- -------------- -------------- 
----AAAAAA---- ----AAAAAA---- ----AAAAAA---- ----AAAAAA---- ----AAAAAA---- ----AAAAAA---- ------AAAA---- ------AAAA---- ------AA------ ------AA------ ------AA------ ------AA------ ------AA------ ------AA------ -------------- -------------- -------------- -------------- 
--AAAAAAAAAA-- --AAAAAAAAAA-- --AAAAAAAAAA-- --AAAAAAAAAA-- --AAAAAAAA---- --AAAAAAAA---- ----AAAAAA---- ----AAAAAA---- ----AAAAAA---- ----AAAAAA---- ----AAAAAA---- ----AAAAAA---- ----AAAA------ ----AAAA------ ------AA------ ------AA------ -------------- -------------- 
--AAAAAAAAAA-- --AAAAAAAAAA-- --AAAAAAAAAA-- --AAAAAAAAAA-- --AAAAAAAA---- --AAAAAAAA---- ----AAAAAA---- ----AAAAAA---- ----AAAAAA---- ----AAAAAA---- ----AAAAAA---- ----AAAAAA---- ----AAAA------ ----AAAA------ ------AA------ ------AA------ -------------- -------------- 
AAAAAAAAAAAAAA AAAAAAAAAAAAAA AAAAAAAAAAAAAA AAAAAAAAAAAAAA AAAAAAAAAAAAAA AAAAAAAAAAAAAA --AAAAAAAAAA-- --AAAAAAAAAA-- --AAAAAAAAAA-- --AAAAAAAAAA-- ----AAAAAA---- ----AAAAAA---- ----AAAAAA---- ----AAAAAA---- ----AAAAAA---- ----AAAAAA---- ------AA------ ------AA------ 
AAAAAAAAAAAAAA AAAAAAAAAAAAAA AAAAAAAAAAAAAA AAAAAAAAAAAAAA AAAAAAAAAAAAAA AAAAAAAAAAAAAA --AAAAAAAAAA-- --AAAAAAAAAA-- --AAAAAAAAAA-- --AAAAAAAAAA-- ----AAAAAA---- ----AAAAAA---- ----AAAAAA---- ----AAAAAA---- ----AAAAAA---- ----AAAAAA---- ------AA------ ------AA------ 
AAAAAAAAAAAAAA AAAAAAAAAAAAAA AAAAAAAAAAAAAA AAAAAAAAAAAAAA AAAAAAAAAAAAAA AAAAAAAAAAAAAA --AAAAAAAAAA-- --AAAAAAAAAA-- --AAAAAAAAAA-- --AAAAAAAAAA-- ----AAAAAA---- ----AAAAAA---- ----AAAAAA---- ----AAAAAA---- ----AAAAAA---- ----AAAAAA---- ------AA------ ------AA------ 
AAAAAAAAAAAAAA AAAAAAAAAAAAAA AAAAAAAAAAAAAA AAAAAAAAAAAAAA AAAAAAAAAAAAAA AAAAAAAAAAAAAA --AAAAAAAAAA-- --AAAAAAAAAA-- --AAAAAAAAAA-- --AAAAAAAAAA-- ----AAAAAA---- ----AAAAAA---- ----AAAAAA---- ----AAAAAA---- ----AAAAAA---- ----AAAAAA---- ------AA------ ------AA------ 
--AAAAAAAAAA-- --AAAAAAAAAA-- --AAAAAAAAAA-- --AAAAAAAAAA-- --AAAAAAAA---- --AAAAAAAA---- ----AAAAAA---- ----AAAAAA---- ----AAAAAA---- ----AAAAAA---- ----AAAAAA---- ----AAAAAA---- ----AAAA------ ----AAAA------ ------AA------ ------AA------ -------------- -------------- 
--AAAAAAAAAA-- --AAAAAAAAAA-- --AAAAAAAAAA-- --AAAAAAAAAA-- --AAAAAAAA---- --AAAAAAAA---- ----AAAAAA---- ----AAAAAA---- ----AAAAAA---- ----AAAAAA---- ----AAAAAA---- ----AAAAAA---- ----AAAA------ ----AAAA------ ------AA------ ------AA------ -------------- -------------- 
----AAAAAA---- ----AAAAAA---- ----AAAAAA---- ----AAAAAA---- ----AAAAAA---- ----AAAAAA---- ----AAAAAA---- ----AAAAAA---- ------AAAA---- ------AAAA---- ------AA------ ------AA------ ------AA------ ------AA------ -------------- -------------- -------------- -------------- 
----AAAAAA---- ----AAAAAA---- ----AAAAAA---- ----AAAAAA---- ----AAAAAA---- ----AAAAAA---- ----AAAAAA---- ----AAAAAA---- ------AAAA---- ------AAAA---- ------AA------ ------AA------ ------AA------ ------AA------ -------------- -------------- -------------- -------------- 
----AAAAAA---- ----AAAAAA---- ----AAAAAA---- ----AAAAAA---- ------AA------ ------AA------ ------AA------ ------AA------ -------------- -------------- -------------- -------------- -------------- -------------- -------------- -------------- -------------- -------------- 
----AAAAAA---- ----AAAAAA---- ----AAAAAA---- ----AAAAAA---- ------AA------ ------AA------ ------AA------ ------AA------ -------------- -------------- -------------- -------------- -------------- -------------- -------------- -------------- -------------- -------------- 
------AA------ ------AA------ ------AA------ ------AA------ -------------- -------------- -------------- -------------- -------------- -------------- -------------- -------------- -------------- -------------- -------------- -------------- -------------- -------------- 
------AA------ ------AA------ ------AA------ ------AA------ -------------- -------------- -------------- -------------- -------------- -------------- -------------- -------------- -------------- -------------- -------------- -------------- -------------- -------------- 
