model
size = 24 19 32, scale = 0.05, origin = -y
material 
  colors = A:#222 B:#A00 C:#FF9 D:#F00 E:#FC3 F:#111 G:#EEE
voxels
83-2D20-D4-D19-4D404-G2DG19-DG2DGD18-6D403-4D18-D2C2D2CD17-6D378-6C17-8C16-8C17-D4CD19-4C18-3F2C3F16-8F257-2B2-2B18-B4-B17-B6CB5(16-8C)17-6C18-6C20-2C212-AB2-BA17-BA4-AB15-BA6CAB14-B8CB15-8C-2(B13-10C)14-10C15-8C16-8C17-6C20-2C187-2B4-2B16-A-4B-A15-A-6C-A14-A8CA13-B10CA12-B10CA11-B-10C-B10-B-10C-B12-10C14-10C15-8C17-6C185-A6-A16-A6BA15-A8CA14-A8CA13-A10CA12-A10CA11-A12CA10-A12CA9-B-12C-B8-B2-10C2-B11-10C15-8C18-4C162-AB4-BA15-2AC4BEA14-2A7CEA14-A8C2A11-2A9CE2A11-A10CA11-A12CA10-A12CA9-A-12C-A8-A-12C-A7-B3-10C3-B6-B4-8C4-B13-4C163-6B17-8B15-10B13-12B12-A11B11-2A10C2A10-AB10CBA10-A12CA9-AB12CBA8-A-12C-A7-AB2-10C2-BA6-A4-8C4-A6-B5-6C5-B156-6B17-8B13-14B10-14B9-BA14B8-ACAB2C6AB3A8-ACA3C10A9-AB8C2ABA10-A12CA9-AB12CBA8-A2-10C2-A7-A4-8C4-A6-A5-6C5-A5-B18-B4-B18-B24-B23-B60-2B17-12B10-16B8-16B7-18B6-5AB6AB5A6-4AB8AB4A6-2ACA8C6A8-AB10CB2A9-A12CA9-A-E10C-EA7-AB3-8C3-B2(A6-)4C6-A5-AB16-BA4-A18-A4-B18-B2(A2-B20-)B54-14B8-18B6-18B5-20B4-7A6B7A4-6A2B4A2B6A5-A2CA2B6C2B4A6-2ACAB7CAB4A7-2AB10CB2A8-ABE10CEBA8-AB2-8C2-BA7-AB5-4C5-BA6-A16-A5-AB16-BA4-A18-A3-AB18-BA2-A20-A24-B28-16B6-3(20B4-)20A4-8A4B8A4-7A6B7A4-6A2B4A2B6A5-2ACA2B6C2B4A8-ABE8CEBA10-AB2-6CE-BA9-AB12-BA7-AB14-BA6-A16-A5-AB16-BA4-A18-A3-AB18-BA23-BA27-18B5-20B3-2(22B2-)2(22A2-)22A3-8A4B8A5-3AC2A6B6A9-A3B4C3BA11-2AB-2E2C2E-B2A10-AB10-BA9-AB12-BA7-AB14-BA6-AB14-BA5-AB16-BA23-A53-7B4-7B5-20B3-2(22B2-)3(22A2-)22A3-5AC8AC5A9-3A4B3A18-2E205-6B8-6B3-9B4-9B2(2-10B)-A10B2-10B12A2-11A-22A2-9A-2A-9A2-8A6-8A3-6A8-6A244-5B10-5B3-8B6-8B-9B6-9BA9B4-10B10A4-19A6-18A6-9A-7A8-7A3-5A10-5A244-5B10-5B3-7B8-7B-9B6-18B6-9B9A6-18A6-17A8-8A-7A8-7A2-5A12-5A243-4B12-4B3-7B8-7B2(-8B8-16B8-8B8A2(8-16A)8-15A10-7A-5A12-5A243-4B12-4B3-6B10-6B)-8B8-16B8-8B8A2(8-16A)8-15A10-7A-5A12-5A243-4B12-4B3-7B8-7B-9B6-18B6-9B9A2(6-18A)6-9A-7A8-7A2-6A10-6A243-5B10-5B3-8B6-8B-10B4-20B4-10B10A4-20A4-10A-9A4-9A2-8A6-8A3-6A8-6A245-5B8-5B2(4-9B)2(2-10B)-23B25A-2(22A2-)10A2-10A3-7A6-7A245-6B6-6B5-20B3-2(22B2-)22A2-22A3-20A4-20A5-8A2-8A247-6B4-6B7-18B5-20B3-22B2-22A3-20A4-20A5-18A7-16A249-14B8-18B5-2(20B4-)20A4-20A5-18A6-18A8-14A251-12B10-16B7-2(18B6-)2(18A6-)18A7-16A9-14A253-8B13-14B9-2(16B8-)2(16A8-)16A9-14A12-10A278-10B12-2(14B10-)14A10-14A11-12A13-10A17-4A284-4B18-8B15-10B13-12A13-10A15-8A18-4A250-
