model
size = 32 26 32, scale = 0.05, origin = -y
material 
  colors = A:#F0F B:#AE00AE C:#081808 D:#171828 E:#080818 F:#5F115C G:#553354 H:#341433
voxels
45-3(7C25-)7C727-4(4C3-4C21-)A9-A22-A7-A23-A7-A24-3A-3A26-2A-2A28-A-A504-4(A11-A19-)AB9-BA20-A9-A2(21-2A7-2A)22-3A3-3A23-3A3-3A24-3A-3A26-2A-2A28-A-A439-3(AB11-BA17-)A13-A17-AB11-BA18-AB9-B2(A19-A2B7-2B)A19-2A9B2A20-A9BA21-2A2BABA2B2A22-4AB4A24-3A-3A26-2A-2A28-A-A374-4(AB13-BA15-)AB13-BA16-3(AB11-BA17-)A2B3-3B3-2BA17-2AB3-3B3-B2A17-2A2B2-BAB2-2B2A18-2A3B3A3B2A19-3A2BABA2B3A21-4A-4A24-3A-3A27-A-A29-A-A309-3(AB15-BA13-)2AB13-B2A13-2AB13-B2A14-3(AB13-BA15-)AB13-BA16-AB11-BA17-A2(B5-)BA17-A2B3-3B3-2BA17-3AB-2(BA)B-B3A18-2A3BA-A3B2A19-3A2BABA2B3A21-3A-B-3A24-3AB3A27-A-A29-A-A244-3(AB16-2BA11-)2AB15-B2A11-2AB15-B2A12-3(AB15-BA13-)AB15-BA14-2(AB13-BA15-)A2B11-2BA15-3AB3-3B3-B3A16-2A2B2-3B2-2B2A17-4AB-BAB-B4A19-2A2BA-A2B2A21-2A2BA-A2B2A23-3A-3A26-2A-2A28-A-A212-6(AB17-BA11-)AB17-BA12-3(AB15-BA13-)AB15-BA14-AB13-BA15-2AB11-B2A16-A-2B3-B3-2B-A17-2A2B3-B3-2B2A17-2A2B2-3B2-2B2A18-2AB2-3B2-B2A20-2A2BA-A2B2A21-5A-5A23-3A-3A27-A-A179-3(2AB17-B2A9-)AB19-BA9-AB19-BA10-5(AB17-BA11-)2AB15-B2A12-AB15-BA13-A2B13-2BA14-A3B9-3BA15-A3B9-3BA16-A2B4-B4-2BA17-3AB2-3B2-B3A18-2A9B2A19-6AB6A21-4A-4A23-4A-4A26-A-A147-8(AB19-BA9-)AB19-BA10-AB17-BA11-AB17-BA12-3(AB15-BA13-)2AB13-B2A14-AB13-BA15-2A2B4-B4-2B2A16-A2B3-BAB3-2BA17-3A3BABA3B3A18-2A3BA-A3B2A20-5A-5A22-4A-4A26-A-A114-3(AB20-2BA7-)3(AB21-BA7-)2AB19-B2A8-3(AB19-BA9-)AB19-BA10-AB17-BA11-AB17-BA12-2(AB15-BA13-)2AB13-B2A14-2A2B9-2B2A16-A2B4-B4-2BA17-3A4BA4B3A18-2A9B2A19-3A2BABA2B3A21-4A-4A23-4A-4A26-A-A82-8(AB21-BA7-)2AB19-B2A8-3(AB19-BA9-)2AB17-B2A10-AB17-BA11-2AB15-B2A12-AB15-BA13-2A2B11-2B2A14-A2B11-2BA15-3A2B2-3B2-2B3A16-2A2B2-3B2-2B2A18-2AB2-3B2-B2A20-2A2BA-A2B2A21-5A-5A23-3A-3A79-3(2AB21-B2A5-)AB23-BA5-2AB21-B2A6-5(AB21-BA7-)2AB19-B2A8-AB19-BA9-AB19-BA10-AB17-BA11-AB17-BA12-AB15-BA13-2AB13-B2A14-AB13-BA15-2A2B9-2B2A16-A2B9-2BA17-2A2(B4-)B2A18-2A9B2A20-5AB5A22-4A-4A78-3(2AB21-B2A5-)3(AB23-BA5-)2AB21-B2A6-4(AB21-BA7-)AB21-BA8-AB19-BA9-AB19-BA10-AB17-BA11-A2B15-2BA12-2AB13-2BA13-2AB13-2BA14-2AB11-B2A16-A2(B5-)B2A16-2AB4-A4-B3A17-A11BA19-6AB6A20-5A-5A23-3A-3A47-3(2AB21-B2A5-)3(AB23-BA5-)2AB21-B2A5-2AB21-B2A6-4(AB21-BA7-)AB21-BA8-AB19-BA9-AB19-BA10-A2B15-2BA11-3AB13-2B2A12-2AB13-2BA13-3AB11-B3A14-2A2(B5-)B2A16-2A2(B4-)B3A16-2A5BA5B2A18-6AB6A20-5A-5A22-4AB4A26-3A17-2(2AB21-B2A5-)2AB21-B2A6-2(B23-B7-)2(2B21-2B7-)2B2(21-B9-B)21-B3(9-2B19-2B)10-3B15-3B11-3B16-2B12-BAB13-B-B2(13-3B)15-2B11-2BA16-2B11-3B17-6B-6B19-6B3-4B20-BAB2AB-2BAB21-4B2A-4B25-4B27-B3AB27-5A16-3(2AB21-B2A5-)3(AB23-BA5-)2AB21-B2A5-2AB21-B2A6-4(AB21-BA7-)AB21-BA8-AB19-BA9-AB19-BA10-A2B15-2BA11-2AB16-2A12-2AB13-2BA13-2AB13-B2A14-2AB11-B2A16-2A2(B4-)B3A16-2A11B2A18-7A2-4A20-6A2B3A22-9A25-5A16-3(2AB21-B2A5-)3(AB23-BA5-)2AB21-B2A6-4(AB21-BA7-)AB21-BA8-AB19-BA9-AB19-BA10-AB17-BA11-A2B15-2BA12-AB16-A13-2AB13-2BA14-AB13-BA16-A2(B5-)B2A16-2AB3-BAB3-B2A18-2(A5B)A19-13A21-4A-4A23-9A26-3A17-3(2AB21-B2A5-)AB23-BA3(5-2AB21-B2A)6-3(AB21-BA7-)2AB19-B2A8-AB19-BA9-AB19-BA10-AB17-BA11-AB17-BA12-AB15-BA13-2AB13-B2A14-AB13-BA15-2AB11-B2A15-2A2B4-B4-2B2A16-3AB2-BAB2-B3A18-2A4BA4B2A19-6AB6A21-4A-4A24-3A-3A47-5(2AB21-B2A5-)2AB21-B2A6-4(AB21-BA7-)2AB19-B2A8-AB19-BA9-AB19-BA10-AB17-BA11-A2B15-2BA12-AB15-BA13-2AB13-B2A14-A2B11-2BA15-3A2(B4-)B3A16-2A2B3-B3-2B2A17-4A3BA3B4A18-3A3BA3B3A20-5AB5A22-4A-4A24-3A-3A47-4(2AB21-B2A5-)2AB21-B2A6-3(AB21-BA7-)A2B19-2BA7-2AB19-B2A8-2(2AB17-B2A9-)2AB17-B2A10-2AB15-B2A11-3AB13-B3A12-2AB13-B2A13-3AB11-B3A14-2A2B4-B4-2B2A15-4AB2-BAB2-B4A16-3A4BA4B3A18-13A19-13A20-5AB5A22-4A-4A25-2A-2A48-2(2A2B19-2B2A5-)2A2B19-2B2A6-3(AB21-BA7-)A2B19-2BA7-2AB19-B2A2(7-3AB17-B3A)8-2(2AB17-B2A9-)2A2B15-2B2A10-2AB15-B2A12-2(2AB13-B2A13-)3A2(B5-)B3A14-2A3B3-B3-3B2A16-3AB2-BAB2-B3A17-4A3BA3B4A18-13A19-13A20-5AB5A23-3A-3A27-A-A49-4AB17-B4A5-4AB17-B4A6-3AB17-B3A3(7-A2B19-2BA)3(7-3AB17-B3A)8-2AB17-B2A9-2A2B15-2B2A9-3AB15-B3A10-3AB13-B3A11-3AB13-B3A12-3AB11-B3A13-3A2B4-B4-2B3A14-2A2B4-B4-2B2A15-4A4BA4B4A16-4A3BA3B4A17-15A18-13A20-5AB5A22-4AB4A25-2A-2A28-A-A50-5(3AB17-B3A7-)3A2B15-2B3A2(7-4AB15-B4A)8-2(3AB15-B3A9-)4AB13-B4A10-3AB13-B3A11-4AB11-B4A12-3AB11-B3A13-4AB9-B4A13-4A3B2-B2-3B4A14-4A2B2-B2-2B4A16-5A2BA2B5A17-15A18-13A19-6AB6A21-4A-4A24-3A-3A27-A-A82-3(4AB15-B4A7-)3A2B15-2B3A2(7-4AB15-B4A)8-2(3AB15-B3A9-)2(4AB13-B4A9-)4AB13-B4A10-3AB13-B3A11-4AB11-B4A12-3A3B3-B3-3B3A13-4A2B3-B3-2B4A14-5A3BA3B5A15-6A2BA2B6A16-15A17-15A18-13A20-5AB5A22-4A-4A25-2A-2A113-2(5AB13-B5A7-)5AB13-B5A8-3A2B13-2B3A5(9-4AB13-B4A)9-4A2B11-2B4A10-3A2B11-2B3A11-4A3B3-B3-3B4A12-3A3B3-B3-3B3A2(13-6A3BA3B6A)14-17A15-17A16-15A18-13A19-13A20-5AB5A23-3A-3A27-A-A114-5A2B11-2B5A7-5A2B11-2B5A8-4A2B11-2B4A9-3A2B13-2B3A2(9-4AB13-B4A)9-4A2B11-2B4A9-5A2(B5-)B5A9-5A2B4-B4-2B5A10-5A3B2-B2-3B5A11-5A11B5A12-2(6A3BA3B6A13-)19A14-17A15-17A16-15A17-15A18-13A20-5AB5A23-3AB4A25-2A-2A146-3(6A11B6A9-)3(5A13B5A9-)6A11B6A10-5A5BA5B5A11-6A4BA4B6A11-8A2BA2B8A12-2(19A13-)19A14-17A15-17A16-15A17-15A18-13A20-5AB5A22-4A-4A25-2A-2A178-23A9-23A10-5(21A11-)21A12-2(19A13-)19A14-17A15-17A16-2(15A17-)15A18-13A20-5AB5A22-4AB4A24-3A-3A210-4(21A11-)21A12-3(19A13-)19A14-2(17A15-)17A16-15A17-15A18-13A20-5AB5A22-4AB4A24-3A-3A274-2(10AB10A11-)10AB10A12-3(9AB9A13-)9AB9A14-2(8AB8A15-)8AB8A16-7AB7A17-7AB7A18-6AB6A20-5AB5A22-4AB4A25-2A-2A338-22A10-AG3E2AD6AD2A3D2A10-6AD8AD6A10-AF3ADF8AFD3AFA10-AD3AD2AH2D5AD3AFA10-AE2AF5A2D5AF2AD2A8-2AD2AE6A2D4A2(D2A)8-AFD2AD7ADF3AD2ADFA8-ADF2AE8AD3AD2AFDA8-AD3AE8ADF2AD3AD2A7-AD3AE9AE2ADA-AD2A6-A2EA-AE3AD5AD2AFA-AEDA6-AD2A-2ADA2E2(2AD)AD2A-2ADA3-4AD2A-2A2(FAD)E2AEAF2A-2AD5AD2ADA3-3AD2AEF6A2-2AD2(2AF)DFDA5-4AE6A4-ADF2E4AD2A6-7A7-2AE3A-5A8-3A9-5A257-
