model
size = 20 27 8, scale = 0.05, origin = -y
material 
  colors = A:#667171 B:#7E8C8C C:#C18A26 D:#53380D E:#14141A F:#35353A G:#9F2E2E H:#000
voxels
-------------------- ---------HH--------- --------AHHB-------- -------AAABBB------- -------AAABBB------- -------AAABBB------- ------AAAABBBB------ ------AAAABBBB------ ------AAAABBBB------ -----AAAAABBBBB----- ----AAAAAABBBBBB---- ---BBBBBBBAAAAAAA--- --BBBBBHBBAAHAAAAA-- --BBBBBHBBAAHAAAAA-- --BBBBBHBBAAHAAAAA-- ---BBBBHBBAAHAAAA--- ---BBBBBBBAAAAAAA--- ----BBBBBBAAAAAA---- ----BBBBBBAAAAAA---- ----BBBB----AAAA---- ---BBBB------AAAA--- ---BBB--------AAA--- ---BB----------AA--- --BB------------AA-- --B--------------A-- -------------------- -------------------- 
-------------------- --------FHHF-------- -------FAHHBF------- ------FAAABBBF------ ------FAAABBBF------ ------FAAABBBF------ -----FAAAABBBBF----- -----FAAAABBBBF----- -----FAAAABBBBF----- ----FAAAAABBBBBF---- ---FAAAAAABBBBBBF--- --FBBBBBBBAAAAAAAF-- -FBBBBBBBBAAAAAAAAF- -FBBBBBBBBAAAAAAAAF- -FBBBBBBBBAAAAAAAAF- --FBBBBBBBAAAAAAAF-- --FBBBBBBBAAAAAAAF-- ---FBBBBBBAAAAAAF--- ---FBBBBBBAAAAAAF--- ---FBBBBFFFFAAAAF--- --FBBBBF----FAAAAF-- --FBBBF------FAAAF-- --FBBF--------FAAF-- -FBBF----------FAAF- -FBF------------FAF- --F--------------F-- -------------------- 
--------EEEE-------- -------EDDDDE------- ------EDDDDDDE------ -----ECCCCCCCCE----- -----ECCCCCCCCE----- -----EDDDDDDDDE----- ----EDDDDDDDDDDE---- ----ECCCCCCCCCCE---- ----ECCCCCCCCCCE---- ---EDDDDDDDDDDDDE--- --EDDDDDDDDDDDDDDE-- -ECCCCCCCCCCCCCCCCE- ECCCCCCCCCCCCCCCCCCE EDDDDDDDDDDDDDDDDDDE EDDDDDDDDDDDDDDDDDDE -ECCCCCCCCCCCCCCCCE- -ECCCCCCCCCCCCCCCCE- --EDDDDDDDDDDDDDDE-- --EDDDDDDDDDDDDDDE-- --ECCCCCCCCCCCCCCE-- -ECCCCCCEEEECCCCCCE- -EDDDDDE----EDDDDDE- -EDDDDE------EDDDDE- ECCCCE--------ECCCCE ECCCE----------ECCCE -EDE------------EDE- --E--------------E-- 
-------------------- -------------------- -------------------- -------------------- -------------------- -------------------- -------------------- -------------------- -------------------- ------G------G------ ------G------G------ -------------------- -------------------- -------------------- -------------------- ------G------G------ ------G------G------ -------------------- -------------------- -------------------- -------------------- -------------------- -------------------- -------------------- -------------------- -------------------- -------------------- 
-------------------- -------------------- -------------------- -------------------- -------------------- -------------------- -------------------- -------------------- -------------------- ------G------G------ ------G------G------ -------------------- -------------------- -------------------- -------------------- ------G------G------ ------G------G------ -------------------- -------------------- -------------------- -------------------- -------------------- -------------------- -------------------- -------------------- -------------------- -------------------- 
-------------------- -------------------- -------------------- -------------------- -------------------- -------------------- -------------------- -------------------- -------------------- ------GG----GG------ ------GG----GG------ -------------------- -------------------- -------------------- -------------------- ------GG----GG------ ------GG----GG------ -------------------- -------------------- -------------------- -------------------- -------------------- -------------------- -------------------- -------------------- -------------------- -------------------- 
-------------------- -------------------- -------------------- -------------------- -------------------- -------------------- -------------------- -------------------- -------------------- -------GG--GG------- -------GG--GG------- -------------------- -------------------- -------------------- -------------------- -------GG--GG------- -------GG--GG------- -------------------- -------------------- -------------------- -------------------- -------------------- -------------------- -------------------- -------------------- -------------------- -------------------- 
-------------------- -------------------- -------------------- -------------------- -------------------- -------------------- -------------------- -------------------- -------------------- --------GGGG-------- --------GGGG-------- -------------------- -------------------- -------------------- -------------------- --------GGGG-------- --------GGGG-------- -------------------- -------------------- -------------------- -------------------- -------------------- -------------------- -------------------- -------------------- -------------------- -------------------- 
