model
size = 20 23 26, scale = 0.05, origin = -y
material 
  colors = A:#6A4028 B:#EEA9A9 C:#F19483 D:#563F2E E:#F8C3CD F:#43341B
voxels
-------------------- --BBBB--BBBB--BBBB-- --BBBB--BBBB--BBBB-- -------------------- -------------------- -------------------- -------------------- -------------------- -------------------- -------------------- -------------------- -------------------- -------------------- -------------------- -------------------- -------------------- -------------------- -------------------- -------------------- -------------------- -------------------- -------------------- -------------------- 
---CC---CCCC---CC--- --BBBB-BBBBBB-BBBB-- --BBBB-BBBBBB-BBBB-- --BBB---BBBB---BBB-- -------------------- -------------------- -------------------- -------------------- -------------------- -------------------- -------------------- -------------------- -------------------- -------------------- -------------------- -------------------- -------------------- -------------------- -------------------- -------------------- -------------------- -------------------- -------------------- 
--CCCC-CCCCCC-CCCC-- --BCCCCCCCCCCCCCCB-- --BCCCCCCCCCCCCCCB-- --BBBB-BBBBBB-BBBB-- --------EEEE-------- -------------------- -------------------- -------------------- -------------------- -------------------- -------------------- -------------------- -------------------- -------------------- -------------------- -------------------- -------------------- -------------------- -------------------- -------------------- -------------------- -------------------- -------------------- 
--CCCC-CCCCCC-CCCC-- --BCCCCCCCCCCCCCCB-- --BCCCCCCCCCCCCCCB-- --BBBB-BBBBBB-BBBB-- --EEEE--EEEE--EEEE-- -------------------- -------------------- -------------------- -------------------- -------------------- -------------------- -------------------- -------------------- -------------------- -------------------- -------------------- -------------------- -------------------- -------------------- -------------------- -------------------- -------------------- -------------------- 
--CCCC-CCCCCC-CCCC-- --BCCCCCCCCCCCCCCB-- --BCCCCCCCCCCCCCCB-- --BBBBBBBBBBBBBBBB-- --EEEEBBEEEEBBEEEE-- -----EEEEEEEEEE----- -------------------- -------------------- -------------------- -------------------- -------------------- -------------------- -------------------- -------------------- -------------------- -------------------- -------------------- -------------------- -------------------- -------------------- -------------------- -------------------- -------------------- 
--CCCCCCCCCCCCCCCC-- --BCCCCCCCCCCCCCCB-- --BCCCCCCCCCCCCCCB-- --BBBBBBBBBBBBBBBB-- --BBBBBBBBBBBBBBBB-- ---EEBBBBBBBBBBEE--- -------------------- ----AFAFAFAFAFAF---- ----FAFAFAFAFAFA---- -------------------- -------------------- -------------------- -------------------- -------------------- -------------------- -------------------- -------------------- -------------------- -------------------- -------------------- -------------------- -------------------- -------------------- 
---CCCCCCCCCCCCCC--- ---BCCCCCCCCCCCCB--- --BBCCCCCCCCCCCCBB-- --BBBBBBBBBBBBBBBB-- --BBBBBBBBBBBBBBBB-- ---EEECEEEEEECEEE--- ---AFFFFFFFFFFFFA--- ---FFFFFFFFFFFFFA--- ---A------------A--- -------------------- -------------------- -------------------- -------------------- -------------------- -------------------- -------------------- -------------------- -------------------- -------------------- -------------------- -------------------- -------------------- -------------------- 
---CCCCCCCCCCCCCC--- ---BCCCCCCCCCCCCB--- --BBCCCCCCCCCCCCBB-- --BBBBBBBBBBBBBBBB-- --BBBBBBBBBBBBBBBB-- ---BEBBBBBBBBBBEB--- --F--EEEEEEEEEE--F-- --AAAAAAAAAAAAAAAA-- --A-AFAFAFAFAFAF-A-- ----FAFAFAFAFAFA---- -----AAFAFAFAFA----- -----AAAAAAAAAA----- ------AAAAAAAA------ -------AAAAAA------- -------------------- ------AAAAAAAA------ -----AAAAAAAAAA----- ---AAAAAAAAAAAAAA--- ---AAAAAAAAAAAAAA--- ---AAADADAAAAAAAA--- ----ADADADADADAA---- -------------------- -------------------- 
---CCCCCCCCCCCCCC--- ---BCCCCCCCCCCCCB--- ---BCCCCCCCCCCCCB--- --BBBBBBBBBBBBBBBB-- --BBBBBBBBBBBBBBBB-- ---BEBBBBBBBBBBEB--- -A--CEEEEEEEEEEC--A- -AAAAAAAAAAAAAAAAAA- -A-AAAAAAAAAAAAAA-A- ---AAAAAAAAAAAAAA--- ---DAAAAAAAAAAADA--- ----DAAAAAAAAAAA---- ----ADAAAAAAAAAD---- ----DADAAAAAAADA---- ----ADADADADADAD---- ---ADAAAAAAAAADAD--- --ADAAAAAAAAAAADAD-- -ADAAAAAAAAAAAAAAAD- -DAAAAAAAAAAAAAAADA- -ADAAAAAAAAAAAAAAAD- --ADAAAAAAAAAAAAAD-- ---ADADADADADADAD--- -------------------- 
----CCCCCCCCCCCC---- ---BCCCCCCCCCCCCB--- ---BCCCCCCCCCCCCB--- --BBBBBBBBBBBBBBBB-- --BBBBBBBBBBBBBBBB-- --BCBBBBBBBBBBBBCB-- F--CEEEEEEEEEEEEC--F AAAAAAAAAAAAAAAAAAAA --FAAAAAAAAAAAAAAF-- --AAAAAAAAAAAAAAAA-- --AAAAAAAAAAAAAAAA-- ---AAAAAAAAAAAAAD--- ---DAAAAAAAAAAAAA--- ---AAAAAAAAAAAAAD--- ---DAAAAAAAAAAAAA--- --AAAAAAAAAAAAAAAD-- -DAAAAAAAAAAAAAAAAA- -AAAAAAAAAAAAAAAAAA- AAAAAAAAAAAAAAAAAAAA AAAAAAAAAAAAAAAAAAAA -AAAAAAAAAAAAAAAAAA- --AAAAAAAAAAAAAAAD-- ---DADADADADADADA--- 
-----CCCCCCCCCC----- ---CCCCCCCCCCCCCC--- ---BCCCCCCCCCCCCB--- --BBBBBBBBBBBBBBBB-- --BBBBBBBBBBBBBBBB-- --BCBBBBBBBBBBBBCB-- F--CEEEEEEEEEEEEC--F AAAAAAAAAAAAAAAAAAAA -AAAAAAAAAAAAAAAAAA- -FAAAAAAAAAAAAAAAAF- --AAAAAAAAAAAAAAAA-- --DAAAAAAAAAAAAAAA-- --AAAAAAAAAAAAAAAD-- --DAAAAAAAAAAAAAAA-- --AAAAAAAAAAAAAAAD-- --DAAAAAAAAAAAAAAA-- -AAAAAAAAAAAAAAAAAA- AAAAAAAAAAAAAAAAAAAA AAAAAAAAAAAAAAAAAAAA AAAAAAAAAAAAAAAAAAAA -AAAAAAAAAAAAAAAAAD- --DAAAAAAAAAAAAAAA-- ---ADADADADADADAD--- 
------CCCCCCCC------ ---CCCCCCCCCCCCCC--- ---BCCCCCCCCCCCCB--- --BBBBBBBBBBBBBBBB-- --BBBBBBBBBBBBBBBB-- --BCBBBBBBBBBBBBCB-- F--CEEEEEEEEEEEEC--F AAAAAAAAAAAAAAAAAAAA -FAAAAAAAAAAAAAAAAF- -AAAAAAAAAAAAAAAAAA- -FAAAAAAAAAAAAAAAAF- --AAAAAAAAAAAAAAAD-- --DAAAAAAAAAAAAAAA-- --AAAAAAAAAAAAAAAD-- --DAAAAAAAAAAAAAAA-- --AAAAAAAAAAAAAAAD-- -DAAAAAAAAAAAAAAAAA- AAAAAAAAAAAAAAAAAAAA AAAAAAAAAAAAAAAAAAAA AAAAAAAAAAAAAAAAAAAD -AAAAAAAAAAAAAAAAAA- --AAAAAAAAAAAAAAAD-- ---DADAAAAAAAAADA--- 
-------CCCCCC------- ---CCCCCCCCCCCCCC--- ---BCCCCCCCCCCCCB--- --BBBBBBBBBBBBBBBB-- --BBBBBBBBBBBBBBBB-- --BCBBBBBBBBBBBBCB-- F--CEEEEEEEEEEEEC--F AAAAAAAAAAAAAAAAAAAA -AAAAAAAAAAAAAAAAAA- -FAAAAAAAAAAAAAAAAF- -AAAAAAAAAAAAAAAAAA- --DAAAAAAAAAAAAAAA-- --AAAAAAAAAAAAAAAD-- --DAAAAAAAAAAAAAAA-- --AAAAAAAAAAAAAAAD-- --DAAAAAAAAAAAAAAA-- -AAAAAAAAAAAAAAAAAA- AAAAAAAAAAAAAAAAAAAA AAAAAAAAAAAAAAAAAAAA AAAAAAAAAAAAAAAAAAAA -AAAAAAAAAAAAAAAAAD- --DAAAAAAAAAAAAAAA-- ---ADAAAAAAAAAAAD--- 
-------CCCCCC------- ---CCCCCCCCCCCCCC--- --CBCCCCCCCCCCCCBC-- --BBBBBBBBBBBBBBBB-- --BBBBBBBBBBBBBBBB-- --BCBBBBBBBBBBBBCB-- F--CEEEEEEEEEEEEC--F AAAAAAAAAAAAAAAAAAAA -FAAAAAAAAAAAAAAAAF- -AAAAAAAAAAAAAAAAAA- -FAAAAAAAAAAAAAAAAF- --AAAAAAAAAAAAAAAD-- --DAAAAAAAAAAAAAAA-- --AAAAAAAAAAAAAAAD-- --DAAAAAAAAAAAAAAA-- --AAAAAAAAAAAAAAAD-- -DAAAAAAAAAAAAAAAAA- AAAAAAAAAAAAAAAAAAAA AAAAAAAAAAAAAAAAAAAA AAAAAAAAAAAAAAAAAAAD -DAAAAAAAAAAAAAAAAA- --AAAAAAAAAAAAAAAD-- ---DAAAAAAAAAAADA--- 
-------CCCCCC------- ---CCCCCCCCCCCCCC--- --CBCCCCCCCCCCCCBC-- --BBBBBBBBBBBBBBBB-- --BBBBBBBBBBBBBBBB-- --BCBBBBBBBBBBBBCB-- F--CEEEEEEEEEEEEC--F AAAAAAAAAAAAAAAAAAAA -AAAAAAAAAAAAAAAAAA- -FAAAAAAAAAAAAAAAAF- -AAAAAAAAAAAAAAAAAA- --DAAAAAAAAAAAAAAA-- --AAAAAAAAAAAAAAAD-- --DAAAAAAAAAAAAAAA-- --AAAAAAAAAAAAAAAD-- --DAAAAAAAAAAAAAAA-- -AAAAAAAAAAAAAAAAAA- AAAAAAAAAAAAAAAAAAAA AAAAAAAAAAAAAAAAAAAA AAAAAAAAAAAAAAAAAAAA -AAAAAAAAAAAAAAAAAD- --DAAAAAAAAAAAAAAA-- ---ADAAAAAAAAAAAD--- 
------CCCCCCCC------ ---CCCCCCCCCCCCCC--- --CCCCCCCCCCCCCCCC-- --BBBBBBBBBBBBBBBB-- --BBBBBBBBBBBBBBBB-- --BCBBBBBBBBBBBBCB-- F--CEEEEEEEEEEEEC--F AAAAAAAAAAAAAAAAAAAA -FAAAAAAAAAAAAAAAAF- -AAAAAAAAAAAAAAAAAA- -FAAAAAAAAAAAAAAAAF- --AAAAAAAAAAAAAAAD-- --DAAAAAAAAAAAAAAA-- --AAAAAAAAAAAAAAAD-- --DAAAAAAAAAAAAAAA-- --AAAAAAAAAAAAAAAD-- -DAAAAAAAAAAAAAAAAA- AAAAAAAAAAAAAAAAAAAA AAAAAAAAAAAAAAAAAAAA AAAAAAAAAAAAAAAAAAAD -DAAAAAAAAAAAAAAAAA- --AAAAAAAAAAAAAAAD-- ---DAAAAAAAAAAADA--- 
-----CCCCCCCCCC----- --CCCCCCCCCCCCCCCC-- --CCCCCCCCCCCCCCCC-- --BBBBBBBBBBBBBBBB-- --BBBBBBBBBBBBBBBB-- --BCBBBBBBBBBBBBCB-- F--CEEEEEEEEEEEEC--F AAAAAAAAAAAAAAAAAAAA -AAAAAAAAAAAAAAAAAA- -FAAAAAAAAAAAAAAAAF- -AAAAAAAAAAAAAAAAAA- --DAAAAAAAAAAAAAAA-- --AAAAAAAAAAAAAAAD-- --DAAAAAAAAAAAAAAA-- --AAAAAAAAAAAAAAAD-- --DAAAAAAAAAAAAAAA-- -AAAAAAAAAAAAAAAAAA- AAAAAAAAAAAAAAAAAAAA AAAAAAAAAAAAAAAAAAAA DAAAAAAAAAAAAAAAAAAA -AAAAAAAAAAAAAAAAAD- --DAAAAAAAAAAAAAAA-- ---ADAAAAAAAAAAAD--- 
----CCCCCCCCCCCC---- --CCCCCCCCCCCCCCCC-- --CCCCCCCCCCCCCCCC-- --BBBBBBBBBBBBBBBB-- --BBBBBBBBBBBBBBBB-- --BCBBBBBBBBBBBBCB-- F--CEEEEEEEEEEEEC--F AAAAAAAAAAAAAAAAAAAA -FAAAAAAAAAAAAAAAAF- -AAAAAAAAAAAAAAAAAA- -FAAAAAAAAAAAAAAAAF- --AAAAAAAAAAAAAAAD-- --DAAAAAAAAAAAAAAA-- --AAAAAAAAAAAAAAAD-- --DAAAAAAAAAAAAAAA-- --AAAAAAAAAAAAAAAD-- -DAAAAAAAAAAAAAAAAA- AAAAAAAAAAAAAAAAAAAA AAAAAAAAAAAAAAAAAAAA AAAAAAAAAAAAAAAAAAAD -DAAAAAAAAAAAAAAAAA- --AAAAAAAAAAAAAAAD-- ---DAAAAAAAAAAADA--- 
----CCCCCCCCCCCC---- --CCCCCCCCCCCCCCCC-- --CCCCCCCCCCCCCCCC-- --BBBBBBBBBBBBBBBB-- --BBBBBBBBBBBBBBBB-- --CCBBBBBBBBBBBBCC-- F--CEEEEEEEEEEEEC--F AAAAAAAAAAAAAAAAAAAA -AAAAAAAAAAAAAAAAAA- -FAAAAAAAAAAAAAAAAF- -AAAAAAAAAAAAAAAAAA- --DAAAAAAAAAAAAAAA-- --AAAAAAAAAAAAAAAD-- --DAAAAAAAAAAAAAAA-- --AAAAAAAAAAAAAAAD-- --DAAAAAAAAAAAAAAA-- -AAAAAAAAAAAAAAAAAA- AAAAAAAAAAAAAAAAAAAA AAAAAAAAAAAAAAAAAAAA DAAAAAAAAAAAAAAAAAAA -AAAAAAAAAAAAAAAAAD- --DAAAAAAAAAAAAAAA-- ---ADAAAAAAAAAAAD--- 
----CCCCCCCCCCCC---- --CCCCCCCCCCCCCCCC-- --CCCCCCCCCCCCCCCC-- --BBBBBBBBBBBBBBBB-- --BBBBBBBBBBBBBBBB-- --CCBBBBBBBBBBBBCC-- F--CEEEEEEEEEEEEC--F AAAAAAAAAAAAAAAAAAAA -FAAAAAAAAAAAAAAAAF- -AAAAAAAAAAAAAAAAAA- -FAAAAAAAAAAAAAAAAF- --AAAAAAAAAAAAAAAD-- --DAAAAAAAAAAAAAAA-- --AAAAAAAAAAAAAAAD-- --DAAAAAAAAAAAAAAA-- --AAAAAAAAAAAAAAAD-- -DAAAAAAAAAAAAAAAAA- AAAAAAAAAAAAAAAAAAAA AAAAAAAAAAAAAAAAAAAA AAAAAAAAAAAAAAAAAAAD -DAAAAAAAAAAAAAAAAA- --AAAAAAAAAAAAAAAD-- ---DAAAAAAAAAAADA--- 
----CCCCCCCCCCCC---- --CCCCCCCCCCCCCCCC-- --CCCCCCCCCCCCCCCC-- --BBBBBBBBBBBBBBBB-- --BBBBBBBBBBBBBBBB-- --CCBBBBBBBBBBBBCC-- F--CEEEEEEEEEEEEC--F AAAAAAAAAAAAAAAAAAAA -AAAAAAAAAAAAAAAAAA- -FAAAAAAAAAAAAAAAAF- -AAAAAAAAAAAAAAAAAA- --DAAAAAAAAAAAAAAA-- --AAAAAAAAAAAAAAAD-- --DAAAAAAAAAAAAAAA-- --AAAAAAAAAAAAAAAD-- --DAAAAAAAAAAAAAAA-- -AAAAAAAAAAAAAAAAAA- AAAAAAAAAAAAAAAAAAAA AAAAAAAAAAAAAAAAAAAA DAAAAAAAAAAAAAAAAAAA -AAAAAAAAAAAAAAAAAD- --DAAAAAAAAAAAAAAA-- ---ADAAAAAAAAADAD--- 
----CCCCCCCCCCCC---- --CCCCCCCCCCCCCCCC-- --CCCCCCCCCCCCCCCC-- --BBBBBBBBBBBBBBBB-- --BBBBBBBBBBBBBBBB-- --CCBBBBBBBBBBBBCC-- F--CEEEEEEEEEEEEC--F AAAAAAAAAAAAAAAAAAAA -FAAAAAAAAAAAAAAAAF- -AAAAAAAAAAAAAAAAAA- --DAAAAAAAAAAAAAAA-- --AAAAAAAAAAAAAAAD-- --DAAAAAAAAAAAAAAA-- --AAAAAAAAAAAAAAAD-- --DAAAAAAAAAAAAAAA-- --AAAAAAAAAAAAAAAD-- -DAAAAAAAAAAAAAAAAA- AAAAAAAAAAAAAAAAAAAA AAAAAAAAAAAAAAAAAAAA AAAAAAAAAAAAAAAAAAAA -DAAAAAAAAAAAAAAAAA- --AAAAAAAAAAAAAAAD-- ---DADADAAAAADADA--- 
-----CCCCCCCCCC----- ---CCCCCCCCCCCCCC--- ---CCCCCCCCCCCCCC--- ---BBBBBBBBBBBBBB--- ---BBBBBBBBBBBBBB--- ---CCBBBBBBBBBBCC--- -AAEEEEEEEEEEEEEEAA- AAAAAAAAAAAAAAAAAAAA -AAFAFAAAAAAAAAFAFA- --AAFAAAAAAAAAAAFA-- ---AAAAAAAAAAAAAD--- ---DAAAAAAAAAAAAA--- ---AAAAAAAAAAAAAD--- ---DAAAAAAAAAAAAA--- ---AAAAAAAAAAAAAD--- --DDAAAAAAAAAAAAAD-- -ADAAAAAAAAAAAAAAAD- -DAAAAAAAAAAAAAAAAA- AAAAAAAAAAAAAAAAAADA ADAAAAAAAAAAAAAAAAAA -AAAAAAAAAAAAAAAAAD- --DAAAAAAAAAAAAADA-- ----DADADADADADA---- 
-------CCCCCC------- ----CCCCCCCCCCCC---- ----CCCCCCCCCCCC---- -----CCBBBBBBCC----- -----CCBBBBBBCC----- -----CCBBBBBBCC----- --FAAAEEEEEEEEAAAF-- -AFFFFAAAAAAAAFFFFA- ------AFAFAFAF------ -----AFAFAFAFAF----- ----DAAAAAAAAADA---- ----AAAAAAAAAAAD---- ----DAAAAAAAAAAA---- ----AAAAAAAAAAAD---- ----DADADADADADA---- ----ADAAAAAAAAAD---- ---ADAAAAAAAAAAAD--- --ADAAAAAAAAAAAAAD-- --DAAAAAAAAAAAAAAA-- --AAAAAAAAAAAAAAAD-- ---DAAAAAAAAAAAAA--- ----ADAAAAAAAAAD---- ------ADADADAD------ 
-------------------- ------CCCCCCCC------ ------CCCCCCCC------ -------CBBBBC------- -------BBBBBB------- -------CBBBBC------- ---FFFFFFFFFFFFFFA-- --FAFFFFFFFFFFFFAF-- --AA------------AA-- -------------------- ------AAAAAAAA------ -----AAAAAAAAAA----- -----AAAAADADAA----- -----DADADADADA----- -------------------- ------ADADADAD------ -----AAAAAAAAAA----- ----AAAAAAAAAAAA---- ---AAAAAAAAAAAAAD--- ---AAAAAAAAAAAAAA--- ----DAAAAAAAAAAA---- -----ADAAAAAAAD----- -------ADADAD------- 
-------------------- -------------------- -------------------- -------------------- -------------------- -------------------- -------------------- ----AFAFAFFAFAFA---- ----AAAAAAAAAAAA---- -------------------- -------------------- -------------------- -------------------- -------------------- -------------------- -------------------- ------AAAAAAAA------ -----AAAAAAAAAA----- ----AAAAAAAAAAAA---- ----AAAAAAADADAD---- ----ADDADADADADA---- ------ADADADAD------ -------------------- 
