model
size = 32 32 21, scale = 0.05, origin = -y
material 
  colors = A:#6A4028 B:#E83015 C:#9F353A D:#D75455 E:#CC543A F:#734338 G:#563F2E H:#CB4042 I:#E98B2A J:#FC9F4D K:#994639
voxels
74-12A17-F17A13-F18AF12-20A11-AF18AFA10-FAF16AFAF10-2(AF)3A4(FA)2F2(AF)A10-4(FA)24-3(AF)26-3(FA)26-2(AF)2A27-2(AF)A27-2(FA)F28-3IA28-3IF28-I-I28-5J27-JAFAJ411-3(GA)8-3(AG)11-5(GA)2G5(AG)9-2(GA)G14A2(GA)G8-AG20AGA8-G22AG8-AF22A7-AF23A7-25A7-AF23A7-11A2(KA)5(CA)7-AF8A8C3(HC)9-F6AF7C2HE3B11-8A5CHEB3E3B10-F6AF3CHE3BEBE3B11-6A2CH2(3E3B)E10-F5ACHD2(3B3D)B10-AF4ACE2(D3BDB)DB10-F5AH2D2(3B3D)B10-6AE2B2(3E3B)E10-F2AFACE2B2(EBE3B)E11-2(AF)H2(3B3E)3B20-3B3D337-G8A4-8AG10-22A9-24A8-G22AG2(8-24A)7-F24AF6-26A6-F24AF6-15A10CA6-F9A13CB9-8A9C4B2E9-8A6C8BE9-7A5C10B2E9-6A3C12B2E9-6A2C15B2(9-6AC16B)9-6A15B2E9-5AC15B2E10-4AC15B2E10-2(FA)C2(3D3B)3DB11-2(AF)3-D3B2(DB)17-2(FA)2(28-AFA)F220-9A4-9A10-G20AG9-G22AG2(8-24A)7-2(F24AF6-26A6-)F14A11C6-10A13CE9-F7A9C6BD8-C7A6C9BE9-E5A5C12B9-E5A3C14B9-B5A2C14BD9-E5AC15BD9-B5AC15BD8-E6A17B8-E5AC17B8-EC4AC17B8-BH4AC2(3D3B)3DBD8-BC4AHDBD3B3D3B2(DB)D8-BH4AC2(3D3B)3DBD8-EC3ACH2(3B3E)3B2E9-E3AH2(E3BEB)E3BE10-FAFH2E2(3B3E)2B17-B3D3B3D2B143-G8A4-8AG10-22A9-24A8-G22AG8-24A7-2(26A6-F24AF6-)15A10CA6-F9A14CD8-C7A9C6BD8-AB6A6C10B9-E5A5C12B9-E5A3C14B8-B6A2C14BD8-B6AC16B8-B6AC15BD8-E6A17B8-E5AC17B8-EB4AC17B8-2B4AC16BD8-2B4AC17B8-2B4AC16BD8-EB3A2C15B2E8-EB3AC16B2E9-3AC17BE10-AFAC2B2(3D3B)2D12-FAFH2B2(DBD3B)DB108-9A4-9A10-G20AG9-G22AG8-24A7-3(26A6-)F24AF6-26A6-F14A11C6-10A14CE8-8A9C6BD9-E6A6C10B9-E5A5C12B8-EB5A3C14B8-B6A2C14B2(D8-B6AC15B)D8-E6A17B8-E5AC17B8-EB4AC17B2(8-2B4AC16BD)7-3B4AC16BDB6-3B3A2C15B2EB6-3B3AC16B2EB7-B3AC17B2E8-B3AC2B2(3D3B)3DB10-3AC2B2(3D3B)3D11-AFA2B12-2B17-B12-B46-G8A4-8AG9-G22AG2(8-24A)7-4(26A6-)F24AF6-15A10CA6-F9A14CB8-C7A9C6BE9-B6A6C9BE8-B6A5C11BE8-B6A3C13BE8-D6A2C15B2(8-D6AC16B)8-B6A16BE8-B5AC16BE8-2B4AC16BE8-DB4AC17B7-D2B4AC18B4-5B4AC20B2-5B3A2C20B2-5B3AC21B4-2B3AC20B7-B3AC19B8-B3AC18B10-FAF2BE3B3E3B2E3B16-B12-B46-9A4-9A9-24A8-G22AG8-24A7-3(26A6-)F24AF6-26A6-F14A11C6-10A14CE8-8A9C7B9-E6A6C9BE8-B6A5C12B8-B6A3C13BE8-D6A2C15B8-D6AC16B7-2D6AC17B6-2B6A17BE6-2B5AC18B6-3B4AC17BE2(6-D2B4AC18B)3-6B4AC27B3A2C27B3AC22B-4B3AC22B4-2B3AC20B7-B3AC19B9-AFA6BEBE3BE5B14-3B10-3B45-G8A4-8AG9-G22AG2(8-24A)7-4(26A6-)F24AF6-15A10CA6-F9A14CB8-C7A9C6BE9-B6A6C9BE8-B6A5C11BE8-B6A3C13BE8-D6A2C15B7-2(2D6AC17B6-)2B6A17BE6-2B5AC17BE6-3B4AC17BE2(6-D2B4AC18B)3-6B4AC27B3A2C2(27B3AC)23B-4B3AC22B4-2B3AC20B7-BF2A6B3E11B9-F2A3BD8-7B12-F3BD8-5B12-9A4-9A9-24A8-G22AG8-24A7-3(26A6-)F24AF6-26A6-F14A11C6-10A14CE8-8A9C6BD9-E6A6C10B8-E6A5C12B8-E6A3C14B8-B6A2C14BD7-2(2B6AC16BD6-)EB6A18B6-EB5AC18B6-E2B2(4AC18B6-3B)4AC18B3-6B4AC27B3A2C2(27B3AC)23B-4B3AC22B3-3B3AC21B5-2B3A21B7-B3A2(3BDBD)8B10-FA3BD8-6B11-G8A4-8AG9-G22AG2(8-24A)7-4(26A6-)F24AF6-15A10CA6-F9A14CD8-C7A9C6BE9-B6A6C10B8-E6A5C12B8-E6A3C14B8-B6A2C14BD7-2B6AC17B6-2B6AC16BD6-EB6A18B6-EB5AC18B6-E2B2(4AC18B6-3B)4AC18B3-6B4AC27B3A2C2(27B3AC)23B-4B3AC22B3-3B3AC21B5-2BF2A21B7-BF2A2(3B3D)8B10-AF2(3B3D)6B11-9A4-9A9-24A8-G22AG8-24A7-3(26A6-)F24AF6-26A6-F14A11C6-10A14CE8-8A9C6BD9-E6A6C10B8-E6A5C12B8-E6A3C14B7-2B6A2C15B2(D6-2B6AC16B)D6-EB6A18B6-EB5AC18B6-E2B2(4AC18B6-3B)4AC18B3-6B4AC27B3A2C2(27B3AC)23B-4B3AC22B3-3B3AC21B5-2B3A21B7-B3A20B10-FA18B11-G8A4-8AG9-G22AG2(8-24A)7-4(26A6-)F24AF6-15A10CA6-F9A14CB8-C7A9C6BE9-B6A6C9BE8-B6A5C11BE8-B6A3C13BE7-DB6A2C16B2(6-DB6AC17B)6-2B6A17BE6-2B5AC17BE6-3B4AC17BE2(6-D2B4AC18B)3-6B4AC27B3A2C2(27B3AC)23B-4B3AC22B3-3B3AC21B5-2BF2A21B7-BF2A20B10-AF2B2(3D3B)3DB11-9A4-9A9-24A8-G22AG8-24A7-3(26A6-)F24AF6-26A6-F14A11C6-10A14CE8-8A9C7B9-E6A6C9BE8-B6A5C12B8-B6A3C13BE7-DB6A2C16B2(6-DB6AC17B)6-2B6A17BE6-2B5AC18B6-3B4AC17BE2(6-D2B4AC18B)3-6B4AC27B3A2C2(27B3AC)23B-4B3AC22B3-3B3AC21B5-2B3A21B7-B3A20B10-FA2B2(DBD3B)2(DB)11-G8A4-8AG9-G22AG2(8-24A)7-4(26A6-)F24AF6-15A10CA6-F9A14CB8-C7A9C6BE9-B6A6C9BE8-2E5A5C11BE8-2E5A3C13BE7-DB6A2C16B2(6-DB6AC17B)6-2B6A17BE6-2B5AC17BE6-3B4AC17BE2(6-D2B4AC18B)3-6B4AC27B3A2C2(27B3AC)23B-4B3AC22B3-3B3AC21B5-2BF2A21B7-BF2A2E18B11-F2E2(3D3B)3D12-9A4-9A10-G20AG9-G22AG8-24A7-3(26A6-)F24AF6-26A6-F14A11C6-10A14CD8-8A9C6BD9-E6A6C10B8-2E5A5C12B8-2E5A3C14B7-2B6A2C15B2(D6-2B6AC16B)D6-EB6A18B6-EB5AC18B6-E2B4AC18B2(6-3B4AC17BD)3-6B4AC17BD9B3A2C2(27B3AC)23B-4B3AC22B4-2B3AC20B7-BAFA20B9-AFA2E2(3B3E)5B14-E2(3B3E)B14-G8A4-8AG10-22A9-2(24A8-)24A7-2(26A6-F24AF6-)15A10CA6-F9A14CE8-C7A9C6BD9-B6A6C10B8-2E5A5C12B8-2E5A3C14B8-B6A2C14BD7-2B6AC17B6-2B6AC16BD6-EB6A18B6-EB5AC18B6-E2B4AC18B6-3B4AC17BD6-3B4AC18B3-6B4AC17BD9B3A2C27B3AC22B-2BEB3AC22B4-2B3AC20B7-B3AC19B9-FAF18B14-2E2(3B3E)2B45-9A4-9A10-G20AG9-G22AG2(8-24A)7-2(F24AF6-26A6-)F14A11C6-10A14C9-8A9C6BE9-E6A6C10B9-E5A5C12B8-2E5A3C14B8-B6A2C14BD7-2(2B6AC16BD6-)EB6A18B6-EB5AC18B6-E2B4AC18B3(6-3B4AC17BD)6-E2B3A2C14B3EB6-E2B3AC15B3EB7-E3AC16B3E8-B3ACB3(3D3B)9-3ACB2(3D3B)3D2B10-A-A2B2(3D3B)3D76-4(GA)G4-4(GA)G10-AG7A4G7AGA9-AG20AGA8-G22AG2(8-24A)7-F24AF6-26A6-F24AF6-15A10CA6-F9A14C9-C7A9C3BEBE9-F7A6C7B2E10-E5A5C10BE10-B5A3C12B2E8-2D5A2C15B2(8-2D5AC16B)8-B6A17B7-2B5AC18B6-3B2(4AC18B6-3D)4AC18B7-2D4AC17B8-2B3A2C14B3E8-2B3AC15B2E9-B3AC16B2E10-3ACB2(3D3B)3DB11-FAFH2(BD)2(3BDBD)142-3(AG)6-3(GA)13-AG16AGA11-AG18AGA9-24A8-24A3(7-25A)7-F14A10C7-10A14C9-F7A9CBEB12-8A6C4E3B11-F6A5C3BEBE3BE11-E5A3C5B3E3BE11-D5A2C9B2(3D2B10-D5AC10B)3D3B8-2B5A14B3E8-2B4AC14BEBE8-2B4AC14B3E8-2D4AC11B3D2B9-2D4AC11BDBD2B9-2D4AC11B3D2B9-2B3ACH2B2(3E3B)E10-2B3AH2(3BEBE)3BE11-3AHE2(3B3E)3B12-AFA257-15A15-19A12-21A10-22A9-12A2F4(AF)2A8-F6A2(FA)F2A4(FA)2F8-6A4(FA)4(CA)CH7-FAF3A3(FA)CA5C2(HC)H9-3(FA)F2A6C2H16-3(FA)F5CH19-3(AF)4CHEB20-2(AF)A2CHE6B17-2(FA)FCH3B3D3BD15-2(AF)AC2(D3BDB)14-2(FA)FHD3B3D3B2D14-2(AF)A2B3E3B3E2B14-2(FA)H2BEBE3BEBE2B14-2(AF)C2B3E3B3E2B14-2(FA)H2D3B3D3BD15-2(AF)C2(BD3BD)15-2(FA)H2D3B3D2B17-AFA28-2(AF)28-FAF184-
