model
size = 27 32 26, scale = 0.05, origin = -y
material 
  colors = A:#EEA9A9 B:#AB3B3A C:#F19483 D:#B54434 E:#6A4028 F:#E83015 G:#9F353A H:#D05A6E I:#D75455 J:#F8C3CD K:#43341B L:#FFF M:#994639 N:#C46243 O:#CB4042 P:#E87A90 Q:#B55D4C R:#F4A7B9 S:#DB8E71 T:#B9887D U:#CB1B45
voxels
681-F28-F10-GD26-GF44-F107-4D2(23-4A)185-3I24-3I342-B28-B8-2GD19-G26-B26-F133-6D21-C2ACAC21-6C19-H2(26-A)26-J2A25-J4A23-5C2(22-H2I2H)22-5H206-G12-G43-B4-B3-B13-2(DB)3-B2-D16-2B-2(D3-)DBD16-2(B3-)4B19-B6-B26-BG26-GF123-8D18-2C6AC17-10C17-2C3-2H4C16-2CH4-H3C16-2C2H4-2HC17-3A2H4-H18-3A6C19-C2A2C21-HO2IOH21-H4IH21-H2IOIH23-3H25-H2(26-J)24-2CJ2C21-3GJ2G19-2GD2JAJD2G16-GF-6A-FG13-BG12-GD11-BD3BG2D2B4GDB11-5B-D2B-4B13-2(2B-)3B-5BD11-FB-2B-DB2-6B17-2B-B4-2B19-B-B3-2B21-2B26-B26-F73-10D16-2C7A2C15-3C7A3C14-3CK2M4A3C14-3CML3K2A3C14-3C2M4K3MC15-4A2M2KLKMC16-4A6CA16-2C4A2C19-CPO2IOHC18-ACP4IHCA17-2JP2IOIH3J16-J3-APA3-J20-ARA24-ASA19-2J3-ATA3-2J11-G2-A3C2GT2G3CA11-DB-2CD3GS2G2D2C-B9-F3-2GQ4ACEG-Q-F9-DB2CACAR4ACA2CBD10-BA12CA2G9-D2BDBNQ6NDUD2B10-5BD3BDGBG3B11-2(4BD)5BDBG9-2D2(3BD)5BD13-FD3B2D2B4DB13-BD5B-G3DBG17-DFB-G2B20-DG-2D23-D-BG23-DFD47-11D15-C11AC13-C12AC13-3(C13AC12-)C13AC13-2C11AC14-C8A3C15-C8AC16-12A15-13A14-2A3L2(3A2KL2A14-2AL2K)3A3L2A13-B2A3L3A3L2A11-3B12A3B9-3B12A2B10-3BC10AC2B10-2(3B12A3B9-)D4B8A6B8-18B10-18B9-D14BD13-14B13-7BD6B17-3BDB-2B19-2BD2B-B21-BD2B23-2B21-11E16-C9AC15-C11AC13-C12A2C11-2C13AC11-2(2C13A2C10-)AC13A2C11-2(3C11AC12-)4(2C10A3C12-)2C12A2(B12-B13A)B10-2(3B12A3B9-)D2B12A2BD8-D3B12A2B10-3B12A4B8-5B8A5BD2(9-18B)9-BD15B12-13BD8-F4-14B7-F6-2B-5B-3B14-B3-5B16-2F5-4B23-3B20-11E16-C9AC15-C11AC13-C12A2C11-C15A2(C10-16A)C10-17A2(10-C16A)10-2(C14AC11-)C15AD10-C15AB10-B15AD2(10-B15AB)2(8-4B12A3B)-DB4-5B12A4B8-D2B12A3B8-2D2B12A3B9-5B8A5B9-18BD9-18B9-D16B8-F19B6-B4-14B-BF10-10B15-11B17-2BD3-3B24-2B21-11E16-C9AC15-C11AC13-C12A2C11-C15A2(C10-16A)C10-17A3(9-18A)9-17A5(B9-B16A)B8-4B12A6B4-5B12A5BD5-4B12A4B8-2(D2B12A3B9-)D4B8A5B5-F3-17BD8-20B7-20B5-24B4-2DB2D13BD4B9-9B3DB12-D10B4-B11-D2BD3-2B7-BF16-FB21-11E16-C9AC15-C11AC13-C12A3C10-15A2C10-16AC5(9-18A)7-3C16A3C4-3(C2-C16AC2-C3-)C2-C16AC2-C4-3C16A3C4-6B12A5B5-5B12A6B5-4B12A4B8-D2B12A3B9-3B12A4B8-5B8A7B3-F3-18B2-BF4-19BD7-D19B5-24B5-20BDBF6-11B-2D2B11-11B2-D4B9-2B-B2-5B3-4BF16-BD20-11E16-C9AC15-C11AC13-13A3C10-15A2C10-17A5(9-18A)6-6(4C16A4C3-)6B12A6B4-D4B12A5BD5-4B12A4B5-6B12A5B5-5B12A6B2-F2B-5B8A9BF2B2-21BD4-D19B7-D20B4-B2D21B4-23B6-B2-9B-2D2B11-4B-6B2-D3B12-FB2-D3B4-F-3B15-DBF20-11E16-C9AC15-C11AC13-13A3C10-15A2C6(9-18A)7-2(3C16A3C5-)3C16A3C4-4C16A4C3-4C16A4C4-3C16A3C4-6B12A6B3-F5B12A5BD3-F5B12A4B6-5B12A5B5-5B12A5BD2-9B8A9B-D24BDF3-19BD7-D20B5-2D21B4-B-20B10-9B-2D2B11-5BD5B2-D3B11-2B3-BD3B5-DB17-DB20-11E16-C9AC15-C11AC13-13A3C10-15A2C3(9-18A)8-B3(18A9-)C16AC7-3(3C16A3C5-)3C16A3C6-2C16A2C6-5B12A5BD4-5B12A6B4-5B12A5B5-5B12A5B4-6B12A6B3-D7B8A8BD-D26B2-22B6-19BD6-22B6-20B10-10B-4B11-3B-6BD2-4B10-F2B4-D2BD3-D2BD18-D20-11E16-C9AC15-C11AC13-13A2C11-15A2C4(9-18A)3(8-B18A)B6-2B3(18AB7-B)18ABD6-B18A2B2(5-5B12A5B)D5-4B12A5B5-5B12A5B4-6B12A5BD2-D8B8A9B-25B2D2-21B7-20B6-22B6-21BF6-12B-2BDB11-3B-BD5B2-D3BD9-B-D4-3B5-BD18-B22-9E17-C9AC15-C10A2C13-14AC11-15A2C2(9-18A)2(8-B18A)B7-B18AB7-D2(18AB7-B)18AB6-DB18A2B5-2B18ABD5-2B18AB6-2B18AB5-6B12A4BD5-5B12A5B6-4B12A5BF4-5B12A5B4-6B12A6B2-9B8A9B-26BF22BD7-20B5-23B5-2B-17BDF8-2(11B16-)D-D4-3B24-BDB21-9E17-C9AC15-C10A2C13-13A2C11-15AC10-17AC3(9-18A)B7-D2(18AD7-B)18AB7-B18ABD6-B18AB6-2B18AD7-B18AB6-2B18ABD4-F5B12A5B5-5B12A6B5-4B12A4B6-5B12A5B4-6B12A6B3-8B8A9BF26B2-2B2D18B7-2D18B5-D22B7-12BD3B-2B10-10B16-4B-5B19-2B2-D3B24-BD22-9E17-C7A2C16-2C9A2C13-12A2C12-15AC10-17A10-3(18A8-B)18AB2(7-B18AD)2(7-D18AB)7-B18AB7-B18A2B5-DB18A2B5-5B12A5B4-D5B12A5BD3-F5B12A4B6-5B12A4B5-6B12A3B6-8B8A6B4-23B6-3D2(18B9-)D18BF8-11B-B2-D11-10B16-4B-6B17-2BD2-4B25-DB47-C7A2C16-2C9A2C13-C11A2C13-15A11-16A10-17A10-18A8-2(B18AB7-)D18AB6-2B18AB7-B18A2B6-B18A2B5-2B18ABD5-2B18AD6-2B18AB6-D4B12A5BD4-5B12A5B6-D3B12A4B4-7B12A3B6-6B12A3B5-9B8A6B5-19B10-D16B12-D15B12-14BD12-9B4-B14-8B17-4B2-5B16-F-B4-3BD23-2D48-C7AC18-C9AC15-C10A2C13-14A13-15A11-16A10-17AB8-B2(17AB8-D)17A2B7-D18A2B5-2D18AB6-DB18AD2(6-2B18AB)6-3B16ABD6-5B12A5B5-5B12A5BF5-D3B12A3B7-5B12A3B7-D4B12A3B6-8B8A5BD6-D16BD10-17B13-15B12-9B3-2B15-B3D3B4-B19-3B4-B18-5B23-3B24-BF48-9C18-10C17-C8AC16-C11AC13-14A13-15A2(10-B16A)D3(9-B16AB)4(8-2B16AB)8-DB16A3B5-5B12A4BD5-F4B12A5BD5-4B12A3BD8-3B12A2BD9-3B12A3BD9-4B8A5BF9-14BD10-F16B12-15BD12-11B-2B14-D2B2D3B24-3B23-5B3-B19-B2D24-F76-10C17-C8AC17-11A15-13A14-13A11-B16AB9-B16AD9-B16AB8-2B16A2B8-B3(16A2B7-2B)16A2B7-DB16A2BD6-2B16A3B5-F4B12A5B6-4B12A6B5-4B12A4B8-3B12A4B8-D2B12A2B2D9-D3B8A3B2D10-15B11-F15B12-15B13-12B-B13-2B-2D4B24-4B22-4BD23-B-D4-F156-B20-8BD2B13-8BD7B11-D10BD4B11-D15B10-17BD9-D17B8-BD17B9-D18B8-18BDB7-19BD7-D18B8-19B9-19B8-F18B8-17BF8-17B10-F2(D15B11-)15B11-15BF11-F15BF11-11B-2B12-B-F3-6B14-F8-4B22-D3B210-B5-B21-2B3-B20-BD4(B-)B14-5BD7B13-6BD7B13-14B-B10-15B-B10-D16B10-16BF10-15BF11-16B11-D16B10-D17BD8-16B-B9-F16B9-D16B11-15B12-14BD12-14B14-11BDB15-5BD3BFB16-5BD3B-F16-F3-FBF52-B293-B-B2-B-D17-2(D-)B2-2B2-B15-B2-2B-4B-B15-B2-7B-2B14-9BD-2B13-F13B14-F12B14-13B13-2BD10BD13-2BD11B13-11BDB14-D12B14-11B2D14-D10B16-B2D4BDBFB16-BD2BDB-BDBF17-3B3-DB18-B2DB3-FD21-D110-F322-B26-2(B-)B22-B-3B2-D16-B2-2(B-)2B-D16-B-3BD-2B-B17-5B-2B-B15-B-8BF16-B-4BD2BF17-B-2BD4B18-D-2BD4B19-7BD19-F5BDB19-DFB24-B26-B24-B519-B-B22-2(B-)B23-B2-D23-B2-B21-2(B-)DB21-2(B-)2B21-B-BDB22-F-DBD23-FBDB24-D284-
