model
size = 16 32 14, scale = 0.05, origin = -y
material 
  colors = A:#EEA9A9 B:#E83015 C:#F19483 D:#F8C3CD
voxels
361-B-B9-D2BD3B7-BA2(BD)A3B6-7BA2B2(6-10B)7-8B9-6B12-3B43-3C12-7A8-8A8-4A4-A7-D3A12-D3A13-D2(2A14-)2A13-2AD13-A2D95-2(AD2A11-)2D3AC9-AD2AD3A8-2(AD)3A2B6-ABAD2BA3B5-A2B2A2BA4B4-13B3(4-12B)5-10B6-9B9-6B39-11C4-3C10A3-2C11A3-2C5A3-4A2-2C5A4-2AD3-C5A2(-2A)D4-C4A-5AD4-2C2A2-D4AD4-2C3A2-4D5-2(C3AD11-)C2A13-C3A12-C4A11-3AC3A8-3A3C3A7-2A2C5A7-2AC7A6-AC6ACA6-C8AC5-9A2B5-A2B2A2BA4B4-3B2A2BA5B2-15B2(2-14B)3-13B4-11B5-10B7-8B10-5B8-8C6-4A8C3-13AC2-D13A2-D7A3-4A2-C6A-3C3A2-7A2-AC3A3-C5AC6A3-C4AC-4A5-C6A-DA5-AC5AD8-AC5AD7-2AC4A9-2AC5A9-2C6A8-2C2(7AC7-C)2(9A6-C)10A5-C10A3-10A2BC3-2(2A2B)A5B2-4B2A2BA5B2-15B-32B-15B2-13B4-11B6-9B9-6B7-8C6-9AC5-11AC4-11A2C3-D7A3-AC3-D7A-2CAC4-C6A2-2A2C3-7A-C2-2C4-C5AC8-9A7-8AD6-8A8-D6AC8-D7AC7-D8AC7-C9A6-2(C10A5-)C10A4-2C11A3-AC10AC3-10A3B3-2(2A2B)A5B2-D3B2A2BA6B-64B2(2-14B)4-11B7-8B7-4C9-3C4A4C4-C11AC2-D13A2-D7A3C4A-D7AC6A2-C6A-5AD2-C6A2C-3AD2-C6AC2-2A4-C8A7-C8A6-C8A7-8AC7-9AC6-11A5-D10A5-2(12A4-)C12A2(3-13A)2(3-D9A3B3-DA2B2A2BA6B-4B2A2BA71B-15B2-14B3-13B5-10B4-8C6-10A2C3-2(14A2-)15A-D7AC6A-D7AC5AD2-7ACA-3AD2-13AD2-C5A2C-A3D2-2C5AC8-7AC8-8A8-10A6-2(11A5-)D11A4-D12A2(3-13A)3-D12A)3-D9A3B3-DA2B2A2BA6B-4B2A2BA71B-15B2-14B3-13B5-10B6-4C9-3C4A4C4-C11AC2-D13A2-D7A3C4A-D7AC6A2-C6A-5AD2-C6A2C-3AD2-C6AC2-2A4-C8A7-C8A6-C8A7-8AC7-9AC6-11A5-D10A5-2(12A4-)C12A2(3-13A)3-D9A3B3-DA2B2A2BA6B-4B2A2BA71B-15B2-14B3-13B5-10B4-8C6-9AC5-11AC4-11A2C3-D7A3-AC3-D7A-2CAC4-C6A2-2A2C3-7A-C2-2C4-C5AC8-9A7-8AD6-8A8-D6AC8-D7AC7-D8AC7-C9A6-2(C10A5-)C10A4-2C11A3-AC10AC3-10A3B3-2(2A2B)A5B2-D3B2A2BA6B-64B2(2-14B)4-11B7-8B5-8C6-4A8C3-13AC2-D13A2-D7A3-4A2-C6A-3C3A2-7A2-AC3A3-C5AC6A3-C4AC-4A5-C6A-DA5-AC5AD8-AC5AD7-2AC4A9-2AC5A9-2C6A8-2C2(7AC7-C)2(9A6-C)10A5-C10A3-10A2BC3-2(2A2B)A5B2-4B2A2BA5B2-15B-32B-15B2-13B4-11B6-9B9-6B22-11C4-3C10A3-2C11A3-2C5A3-4A2-2C5A4-2AD3-C5A2(-2A)D4-C4A-5AD4-2C2A2-D4AD4-2C3A2-4D5-2(C3AD11-)C2A13-C3A12-C4A11-3AC3A8-3A3C3A7-2A2C5A7-2AC7A6-AC6ACA6-C8AC5-9A2B5-A2B2A2BA4B4-3B2A2BA5B2-15B2(2-14B)3-13B4-11B5-10B7-8B10-5B26-3C12-7A8-8A8-4A4-A7-D3A12-D3A13-D2(2A14-)2A13-2AD13-A2D95-2(AD2A11-)2D3AC9-AD2AD3A8-2(AD)3A2B6-ABAD2BA3B5-A2B2A2BA4B4-13B3(4-12B)5-10B6-9B9-6B382-B-B9-D2BD3B7-BA2(BD)A3B6-7BA2B2(6-10B)7-8B9-6B12-3B22-
