model
size = 32 20 32, scale = 0.05, origin = -y
material 
  colors = A:#FFD700
voxels
13-3A29-3(7A25-)3A124-4A28-8A24-8A28-4A124-3A3(25-7A)29-3A64-2(4A28-)4A146-4A28-4A6-4A18-4A6-4A28-4A146-2(4A28-)4A105-2(3A29-)3A142-3A29-3A12-3A14-3A12-3A29-3A142-2(3A29-)3A110-2(2A30-)2A140-2A30-2A16-2A12-2A16-2A30-2A140-2(2A30-)2A113-2(2A30-)2A138-2A30-2A18-2A10-2A18-2A30-2A138-2(2A30-)2A147-2A30-2A31-A72-A31-2A30-2A52-2A30-2A31-A72-A31-2A30-2A181-2(2A30-)2A70-2(2A30-)2A54-2(2A30-)2A70-2(2A30-)2A183-2(2A30-)2A68-2(2A30-)2A56-2(2A30-)2A68-2(2A30-)2A185-2(A31-)A68-2(A31-)A58-2(A31-)A68-2(A31-)A186-2(2A30-)2A66-2(2A30-)2A58-2(2A30-)2A66-2(2A30-)2A187-2(2(A31-)A66-2(A31-)A60-2(A31-)A66-2(A31-)A188-)2(2A30-)2A64-2(2A30-)2A60-2(2A30-)2A64-2(2A30-)2A189-2(2(A31-)A64-2(A31-)A62-2(A31-)A64-2(A31-)A190-)2(A31-)A64-2(A31-)A62-2(A31-)A64-2(A31-)A222-2(2(A31-)2A2(31-A)126-2(A31-)2A2(31-A)254-)2(A31-)2A2(31-A)126-2(A31-)2A2(31-A)253-2(2A30-)4A2(30-2A)124-2(2A30-)4A2(30-2A)2(252-2(A31-)A2-2(A31-)A124-2(A31-)A2-2(A31-)A)251-2(2A30-)2A2-2(2A30-)2A122-2(2A30-)2A2-2(2A30-)2A250-2(A31-)A4-2(A31-)A122-2(A31-)A4-2(A31-)A249-2(2A30-)2A4-2(2A30-)2A120-2(2A30-)2A4-2(2A30-)2A247-2(2A30-)2A6-2(2A30-)2A118-2(2A30-)2A6-2(2A30-)2A246-A2(30-2A)8-2(2A30-)A118-A2(30-2A)8-2(2A30-)A276-2(2A10-2A18-)2A10-2A178-2(2A10-2A18-)2A10-2A305-2(2A12-2A16-)2A12-2A176-2(2A12-2A16-)2A12-2A302-2(3A14-3A12-)3A14-3A172-2(3A14-3A12-)3A14-3A297-2(4A18-4A6-)4A18-4A166-2(4A18-4A6-)4A18-4A291-4A2(24-8A)24-4A160-4A2(24-8A)24-4A144-
