model
size = 32 3 32, scale = 0.05, origin = -y
material 
  colors = A:#FFF B:#DEDEDE C:#222832 D:#2C384A E:#2D2F32 F:#BE0909 G:#610404 H:#8A0707 I:#191919
voxels
33-I63-I30-IEG30-I3(32-G30-HEH30-H32-H30-GEG30-G)32-G30-HE2I29-H32-I30-I5E27-I62-IE3-4E88-E6-3E86-E8-5C82-2E5-3CB2A3C81-E3-3C3A2(BA)3C79-E3-C2A2(B3A)B3C77-2E-2C3A3(BA)B3AC78-E-CA3(B3A)B2C77-E2C2A3(BA)2(FA)B2AC78-C3(B3A)F3A2C77-C4(AB)2(AFAB)AC77-C2AB3(3AF)2A2D76-2C2(BA)2(F2(AB)A)BD77-C2(3AB)3AF3ABAD77-2DABAF6(AB)D78-DB2(3AF)3AB2A2D78-2D2AB2(AF)3(AB)AD80-DA3(B3A)2D80-3D2A3(BA)B2AD83-3D3AB3A3D85-3DBAB3D89-5D38-
