model
size = 31, scale = 0.05, origin = -y
material 
  colors = A:#4B568B B:#4B4B4B C:#FFF
voxels
------------C--C--C------------ ------------C-CCC-C------------ ------------AAAAAAA------------ ------------AAAAAAA------------ -------------AAAAA------------- --------------AAA-------------- ------------------------------- ------------------------------- ------------------------------- ------------------------------- ------------------------------- ------------------------------- ------------------------------- ------------------------------- ------------------------------- ------------------------------- ------------------------------- ------------------------------- ------------------------------- ------------------------------- ------------------------------- ------------------------------- ------------------------------- ------------------------------- ------------------------------- ------------------------------- ------------------------------- ------------------------------- ---------------A--------------- ---------------A--------------- ---------------A--------------- 
------------------------------- -----------C-------C----------- ----------AAAAAAAAAAA---------- ----------AAAAAAAAAAA---------- ----------AAAAAAAAAAA---------- -----------AAAAAAAAA----------- -------------AAAAA------------- ---------------A--------------- ------------------------------- ------------------------------- ------------------------------- ------------------------------- ------------------------------- ------------------------------- ------------------------------- ------------------------------- ------------------------------- ------------------------------- ------------------------------- ------------------------------- ------------------------------- ------------------------------- ------------------------------- ------------------------------- ------------------------------- ------------------------------- ------------------------------- ---------------A--------------- ---------------A--------------- ---------------A--------------- ------------------------------- 
------------------------------- ---------C-----------C--------- ---------AAAA-----AAAA--------- ---------AAA-------AAA--------- ---------AAAABBBBBAAAA--------- ---------AAAAAAAAAAAAA--------- ----------AAAAAAAAAAA---------- -------------AAAAA------------- -------------AAAAA------------- --------------AAA-------------- ------------------------------- ------------------------------- ------------------------------- ------------------------------- ------------------------------- ------------------------------- ------------------------------- ------------------------------- ------------------------------- ------------------------------- ------------------------------- ------------------------------- ------------------------------- ------------------------------- ------------------------------- ---------------A--------------- ---------------A--------------- ---------------A--------------- ---------------A--------------- ---------------A--------------- ------------------------------- 
--------C-------------C-------- --------C-------------C-------- --------AAA---------AAA-------- --------AA-----------AA-------- --------AAA---------AAA-------- --------AAABBBBBBBBBAAA-------- ---------AAAAAAAAAAAAA--------- ---------CCCAAAAAAACCC--------- ---------BCCAAAAAAACCB--------- ---------CCCAAAAAAACCC--------- -------------AAAAA------------- --------------AAA-------------- ------------------------------- ------------------------------- ------------------------------- ------------------------------- ------------------------------- ------------------------------- ------------------------------- ------------------------------- ------------------------------- ------------------------------- ------------------------------- ---------------A--------------- ---------------A--------------- ---------------A--------------- ---------------A--------------- ---------------A--------------- ---------------A--------------- ------------------------------- ------------------------------- 
------------------------------- -------C---------------C------- -------AA-------------AA------- -------A---------------A------- -------AAAA---------AAAA------- -------AAAAB-------BAAAA------- --------AAAABBBBBBBAAAA-------- ---------CCCAAAAAAACCC--------- ---------CCCAAAAAAACCC--------- ---------CCCAAAAAAACCC--------- -----------AAAAAAAAA----------- ------------AAAAAAA------------ -------------AAAAA------------- --------------AAA-------------- ------------------------------- ------------------------------- ------------------------------- ------------------------------- ------------------------------- ------------------------------- ------------------------------- ---------------A--------------- ---------------A--------------- ---------------A--------------- ---------------A--------------- ---------------A--------------- ---------------A--------------- ---------------A--------------- ------------------------------- ------------------------------- ------------------------------- 
------------------------------- ------------------------------- ------AAA-------------AAA------ ------AA---------------AA------ ------AAA-------------AAA------ ------AAAB-----------BAAA------ -------AABBB-------BBBAA------- ---------CCCBBBBBBBCCC--------- ---------CCCAAAAAAACCC--------- ---------CCCAAAAAAACCC--------- ----------AAAAAAAAAAA---------- ----------AAAAAAAAAAA---------- -----------AAAAAAAAA----------- ------------AAAAAAA------------ -------------AAAAA------------- --------------AAA-------------- ------------------------------- ------------------------------- ------------------------------- ---------------A--------------- ---------------A--------------- ---------------A--------------- ---------------A--------------- ---------------A--------------- ---------------A--------------- ---------------A--------------- ---------------A--------------- ------------------------------- ------------------------------- ------------------------------- ------------------------------- 
------------------------------- ------C-----------------C------ ------AA---------------AA------ ------A-----------------A------ ------AAB-------------BAA------ ------AABB-----------BBAA------ -------ABBB---------BBBA------- --------AAABBBBBBBBBAAA-------- --------AAAAAAAAAAAAAAA-------- ---------AAAAAAAAAAAAA--------- ---------AAAAAAAAAAAAA--------- ----------AAAAAAAAAAA---------- ----------AAAAAAAAAAA---------- -----------AAAAAAAAA----------- ------------AAAAAAA------------ -------------AAAAA------------- --------------AAA-------------- --------------AAA-------------- ---------------A--------------- ---------------A--------------- ---------------A--------------- ---------------A--------------- ---------------A--------------- ---------------A--------------- ---------------A--------------- ---------------A--------------- ---------------A--------------- ------------------------------- ------------------------------- ------------------------------- ------------------------------- 
-----C-------------------C----- -----C-------------------C----- -----AAA---------------AAA----- -----AA-----------------AA----- -----AAB---------------BAA----- -----AAAB-------------BAAA----- ------AABB-----------BBAA------ --------AABBBBBBBBBBBAA-------- --------AAAAAAAAAAAAAAA-------- --------AAAAAAAAAAAAAAA-------- ---------AAAAAAAAAAAAA--------- ---------AAAAAAAAAAAAA--------- ----------AAAAAAAAAAA---------- ----------AAAAAAAAAAA---------- -----------AAAAAAAAA----------- ------------AAAAAAA------------ -------------AAAAA------------- --------------AAA-------------- --------------AAA-------------- --------------AAA-------------- ---------------A--------------- ---------------A--------------- ---------------A--------------- ---------------A--------------- ---------------A--------------- ---------------A--------------- ------------------------------- ------------------------------- ------------------------------- ------------------------------- ------------------------------- 
------------------------------- ------------------------------- -----AA-----------------AA----- -----A-------------------A----- -----AAB---------------BAA----- -----AAAB-------------BAAA----- ------AABB-----------BBAA------ -------AAABBBBBBBBBBBAAA------- -------AAAAAAAAAAAAAAAAA------- --------AAAAAAAAAAAAAAA-------- --------AAAAAAAAAAAAAAA-------- ---------AAAAAAAAAAAAA--------- ---------AAAAAAAAAAAAA--------- ----------AAAAAAAAAAA---------- ----------AAAAAAAAAAA---------- -----------AAAAAAAAA----------- -------------AAAAA------------- -------------AAAAA------------- --------------AAA-------------- --------------AAA-------------- --------------AAA-------------- ---------------A--------------- ---------------A--------------- ---------------A--------------- ---------------A--------------- ------------------------------- ------------------------------- ------------------------------- ------------------------------- ------------------------------- ------------------------------- 
------------------------------- -----C-------------------C----- -----AA-----------------AA----- -----A-------------------A----- -----AAB---------------BAA----- -----AAAB-------------BAAA----- ------AABB-----------BBAA------ -------AAABBBBBBBBBBBAAA------- -------AAAAAAAAAAAAAAAAA------- -------AAAAAAAAAAAAAAAAA------- --------AAAAAAAAAAAAAAA-------- --------AAAAAAAAAAAAAAA-------- ---------AAAAAAAAAAAAA--------- ---------AAAAAAAAAAAAA--------- ----------AAAAAAAAAAA---------- ----------AAAAAAAAAAA---------- ------------AAAAAAA------------ -------------AAAAA------------- -------------AAAAA------------- --------------AAA-------------- --------------AAA-------------- --------------AAA-------------- ---------------A--------------- ---------------A--------------- ---------------A--------------- ------------------------------- ------------------------------- ------------------------------- ------------------------------- ------------------------------- ------------------------------- 
-----C-------------------C----- -----C-------------------C----- -----AA-----------------AA----- -----A-------------------A----- -----AAB---------------BAA----- -----AAAB-------------BAAA----- ------AABB-----------BBAA------ -------AAABBBBBBBBBBBAAA------- -------AAAAAAAAAAAAAAAAA------- -------AAAAAAAAAAAAAAAAA------- --------AAAAAAA-AAAAAAA-------- --------AAAAAAAAAAAAAAA-------- ---------AAAAAA-AAAAAA--------- ---------AAAAAAAAAAAAA--------- ----------AAAAA-AAAAA---------- ----------AAAAAAAAAAA---------- -----------AAAAAAAAA----------- ------------AAAAAAA------------ -------------AAAAA------------- -------------AAAAA------------- --------------AAA-------------- --------------AAA-------------- --------------AAA-------------- ---------------A--------------- ------------------------------- ------------------------------- ------------------------------- ------------------------------- ------------------------------- ------------------------------- ------------------------------- 
------------------------------- -----C-------------------C----- -----AA-----------------AA----- -----A-------------------A----- -----AAB---------------BAA----- -----AAAB-------------BAAA----- ------AABB-----------BBAA------ -------AAABBBBBBBBBBBAAA------- -------AAAAAAAAAAAAAAAAA------- -------AAAAAAAAAAAAAAAAA------- --------AAAAAAAAAAAAAAA-------- --------AAAAAAAAAAAAAAA-------- ---------AAAAAAAAAAAAA--------- ---------AAAAAAAAAAAAA--------- ----------AAAAAAAAAAA---------- ----------AAAAAAAAAAA---------- ----------AAAAAAAAAAA---------- -----------AAAAAAAAA----------- ------------AAAAAAA------------ -------------AAAAA------------- -------------AAAAA------------- --------------AAA-------------- --------------AAA-------------- ---------------A--------------- ------------------------------- ------------------------------- ------------------------------- ------------------------------- ------------------------------- ------------------------------- ------------------------------- 
------------------------------- ------------------------------- -----AA-----------------AA----- -----A-------------------A----- -----AAB---------------BAA----- -----AAAB-------------BAAA----- ------AABB-----------BBAA------ -------AAABBBBBBBBBBBAAA------- -------AAAAAAAAAAAAAAAAA------- --------AAAAAAAAAAAAAAA-------- -----AAAAAAAAAAAAAAAAAAAAA----- ----AAAAAAAAAAAAAAAAAAAAAAA---- ---AAAAAAAAAAAAAAAAAAAAAAAAA--- --AAAAAAAAAAAAAAAAAAAAAAAAAAA-- -AAAAAAAAAAAAAAAAAAAAAAAAAAAAA- -AAA---AAAAAAAAAAAAAAAAA---AAA- AAA-----AAAAAAAAAAAAAAA-----AAA AA-------AAAAAAAAAAAAA-------AA A----------AAAAAAAAA----------A ------------AAAAAAA------------ -------------AAAAA------------- -------------AAAAA------------- --------------AAA-------------- ------------------------------- ------------------------------- ------------------------------- ------------------------------- ------------------------------- ------------------------------- ------------------------------- ------------------------------- 
-----C-------------------C----- -----C-------------------C----- -----AAA---------------AAA----- -----AA-----------------AA----- -----AAB---------------BAA----- -----AAAB-------------BAAA----- ------AABB-----------BBAA------ --------AABBBBBBBBBBBAA-------- --------AAAAAAAAAAAAAAA-------- --------AAAAAAAAAAAAAAA-------- ---------AAAAAAAAAAAAA--------- ---------AAAAAAAAAAAAA--------- ---------AAAAAAAAAAAAA--------- ---------AAAAAAAAAAAAA--------- ---------AAAAAAAAAAAAA--------- ---------AAAAAAAAAAAAA--------- ---------AAAAAAAAAAAAA--------- ----------AAAAAAAAAAA---------- -----------AAAAAAAAA----------- ------------AAAAAAA------------ ------------AAAAAAA------------ -------------AAAAA------------- --------------AAA-------------- ------------------------------- ------------------------------- ------------------------------- ------------------------------- ------------------------------- ------------------------------- ------------------------------- ------------------------------- 
------------------------------- ------C-----------------C------ ------AA---------------AA------ ------A-----------------A------ ------ABB-------------BBA------ ------AAB-------------BAA------ -------AAB-----------BAA------- --------AABBBBBBBBBBBAA-------- --------AAAAAAAAAAAAAAA-------- ---------AAAAAAAAAAAAA--------- ---------AAAAAAAAAAAAA--------- ---------AAAAAAAAAAAAA--------- ---------AAAAAAAAAAAAA--------- ---------AAAAAAAAAAAAA--------- ---------AAAAAAAAAAAAA--------- ---------AAAAAAAAAAAAA--------- ----------AAAAAAAAAAA---------- ----------AAAAAAAAAAA---------- ----------AAAAAAAAAAA---------- -----------AAAAAAAAA----------- ------------AAAAAAA------------ ------------AAAAAAA------------ -------------AAAAA------------- ---------------A--------------- ------------------------------- ------------------------------- ------------------------------- ------------------------------- ------------------------------- ------------------------------- ------------------------------- 
------------------------------- ------------------------------- ------AAA-------------AAA------ ------AA---------------AA------ ------AAB-------------BAA------ ------AAAB-----------BAAA------ -------AABBB-------BBBAA------- ---------AAABBBBBBBAAA--------- ---------AAAAAAAAAAAAA--------- ---------AAAAAAAAAAAAA--------- ---------AAAAAAAAAAAAA--------- ---------AAAAAAAAAAAAA--------- ---------AAAAAAAAAAAAA--------- ---------AAAAAAAAAAAAA--------- ----------AAAAAAAAAAA---------- ----------AAAAAAAAAAA---------- ----------AAAAAAAAAAA---------- ----------AAAAAAAAAAA---------- ----------AAAAAAAAAAA---------- -----------AAAAAAAAA----------- -----------AAAAAAAAA----------- ------------AAAAAAA------------ -------------AAAAA------------- --------------AAA-------------- ------------------------------- ------------------------------- ------------------------------- ------------------------------- ------------------------------- ------------------------------- ------------------------------- 
------------------------------- -------C---------------C------- -------AA-------------AA------- -------A---------------A------- -------ABBB---------BBBA------- -------AAABB-------BBAAA------- --------AAAABBBBBBBAAAA-------- ---------AAAAAAAAAAAAA--------- ---------AAAAAAAAAAAAA--------- ----------AAAAAAAAAAA---------- ----------AAAAAAAAAAA---------- ----------AAAAAAAAAAA---------- ----------AAAAAAAAAAA---------- ----------AAAAAAAAAAA---------- ----------AAAAAAAAAAA---------- ----------AAAAAAAAAAA---------- ----------AAAAAAAAAAA---------- ----------AAAAAAAAAAA---------- ----------AAAAAAAAAAA---------- ----------AAAAAAAAAAA---------- -----------AAAAAAAAA----------- ------------AAAAAAA------------ -------------AAAAA------------- --------------AAA-------------- ---------------A--------------- ------------------------------- ------------------------------- ------------------------------- ------------------------------- ------------------------------- ------------------------------- 
--------C-------------C-------- --------C-------------C-------- --------AAA---------AAA-------- --------AA-----------AA-------- --------ABB---------BBA-------- --------AAABBBBBBBBBAAA-------- ---------AAAAAAAAAAAAA--------- -----------AAAAAAAAA----------- -----------AAAAAAAAA----------- -----------AAAAAAAAA----------- -----------AAAAAAAAA----------- -----------AAAAAAAAA----------- -----------AAAAAAAAA----------- -----------AAAAAAAAA----------- -----------AAAAAAAAA----------- -----------AAAAAAAAA----------- ----------AAAAAAAAAAA---------- ----------AAAAAAAAAAA---------- ----------AAAAAAAAAAA---------- ----------AAAAAAAAAAA---------- ----------AAAAAAAAAAA---------- -----------AAAAAAAAA----------- ------------AAAAAAA------------ --------------AAA-------------- --------------AAA-------------- ------------------------------- ------------------------------- ------------------------------- ------------------------------- ------------------------------- ------------------------------- 
------------------------------- ---------C-----------C--------- ---------AAAA-----AAAA--------- ---------AAA-------AAA--------- ---------AABBBBBBBBBAA--------- ---------AAAAAAAAAAAAA--------- ----------AAAAAAAAAAA---------- -------------AAAAA------------- -------------AAAAA------------- -------------AAAAA------------- -------------AAAAA------------- ------------AAAAAAA------------ ------------AAAAAAA------------ -----------AAAAAAAAA----------- -----------AAAAAAAAA----------- -----------AAAAAAAAA----------- -----------AAAAAAAAA----------- -----------AAAAAAAAA----------- ----------AAAAAAAAAAA---------- ----------AAAAAAAAAAA---------- ----------AAAAAAAAAAA---------- -----------AAAAAAAAA----------- ------------AAAAAAA------------ -------------AAAAA------------- --------------AAA-------------- ---------------A--------------- ------------------------------- ------------------------------- ------------------------------- ------------------------------- ------------------------------- 
------------------------------- -----------C-------C----------- ----------AAAAAAAAAAA---------- ----------AAAAAAAAAAA---------- ----------AAAAAAAAAAA---------- ----------AAAAAAAAAAA---------- ------------AAAAAAA------------ -------------AAAAA------------- -------------AAAAA------------- -------------AAAAA------------- -------------AAAAA------------- -------------AAAAA------------- -------------AAAAA------------- ------------AAAAAAA------------ -----------AAAAAAAAA----------- -----------AAAAAAAAA----------- -----------AAAAAAAAA----------- -----------AAAAAAAAA----------- -----------AAAAAAAAA----------- -----------AAAAAAAAA----------- ----------AAAAAAAAAAA---------- -----------AAAAAAAAA----------- ------------AAAAAAA------------ -------------AAAAA------------- -------------AAAAA------------- --------------AAA-------------- ------------------------------- ------------------------------- ------------------------------- ------------------------------- ------------------------------- 
------------C--C--C------------ ------------C-CCC-C------------ ------------AAAAAAA------------ ------------AAAAAAA------------ ------------AAAAAAA------------ ------------AAAAAAA------------ --------------AAA-------------- ------------------------------- ------------------------------- ------------------------------- ---------------A--------------- --------------AAA-------------- --------------AAA-------------- -------------AAAAA------------- ------------AAAAAAA------------ -----------AAAAAAAAA----------- -----------AAAAAAAAA----------- -----------AAAAAAAAA----------- -----------AAAAAAAAA----------- -----------AAAAAAAAA----------- -----------AAAAAAAAA----------- -----------AAAAAAAAA----------- ------------AAAAAAA------------ -------------AAAAA------------- -------------AAAAA------------- --------------AAA-------------- ------------------------------- ------------------------------- ------------------------------- ------------------------------- ------------------------------- 
------------------------------- ------------------------------- ------------------------------- ------------------------------- ------------------------------- ------------------------------- ------------------------------- ------------------------------- ------------------------------- ------------------------------- ------------------------------- ------------------------------- --------------AAA-------------- --------------AAA-------------- -------------AAAAA------------- -------------AAAAA------------- ------------AAAAAAA------------ ------------AAAAAAA------------ -----------AAAAAAAAA----------- -----------AAAAAAAAA----------- -----------AAAAAAAAA----------- -----------AAAAAAAAA----------- ------------AAAAAAA------------ ------------AAAAAAA------------ -------------AAAAA------------- -------------AAAAA------------- ---------------A--------------- ------------------------------- ------------------------------- ------------------------------- ------------------------------- 
------------------------------- ------------------------------- ------------------------------- ------------------------------- ------------------------------- ------------------------------- ------------------------------- ------------------------------- ------------------------------- ------------------------------- ------------------------------- ------------------------------- ------------------------------- ------------------------------- --------------AAA-------------- --------------AAA-------------- --------------AAA-------------- -------------AAAAA------------- ------------AAAAAAA------------ ------------AAAAAAA------------ ------------AAAAAAA------------ ------------AAAAAAA------------ ------------AAAAAAA------------ ------------AAAAAAA------------ ------------AAAAAAA------------ -------------AAAAA------------- --------------AAA-------------- ------------------------------- ------------------------------- ------------------------------- ------------------------------- 
------------------------------- ------------------------------- ------------------------------- ------------------------------- ------------------------------- ------------------------------- ------------------------------- ------------------------------- ------------------------------- ------------------------------- ------------------------------- ------------------------------- ------------------------------- ------------------------------- ------------------------------- ------------------------------- --------------AAA-------------- --------------AAA-------------- -------------AAAAA------------- -------------AAAAA------------- -------------AAAAA------------- -------------AAAAA------------- ------------AAAAAAA------------ ------------AAAAAAA------------ ------------AAAAAAA------------ -------------AAAAA------------- --------------AAA-------------- ------------------------------- ------------------------------- ------------------------------- ------------------------------- 
------------------------------- ------------------------------- ------------------------------- ------------------------------- ------------------------------- ------------------------------- ------------------------------- ------------------------------- ------------------------------- ------------------------------- ------------------------------- ------------------------------- ------------------------------- ------------------------------- ------------------------------- ------------------------------- ------------------------------- ------------------------------- --------------AAA-------------- --------------AAA-------------- --------------AAA-------------- -------------AAAAA------------- -------------AAAAA------------- -------------AAAAA------------- -------------AAAAA------------- -------------AAAAA------------- --------------AAA-------------- ------------------------------- ------------------------------- ------------------------------- ------------------------------- 
------------------------------- ------------------------------- ------------------------------- ------------------------------- ------------------------------- ------------------------------- ------------------------------- ------------------------------- ------------------------------- ------------------------------- ------------------------------- ------------------------------- ------------------------------- ------------------------------- ------------------------------- ------------------------------- ------------------------------- ------------------------------- ------------------------------- ------------------------------- --------------AAA-------------- --------------AAA-------------- --------------AAA-------------- --------------AAA-------------- -------------AAAAA------------- -------------AAAAA------------- --------------AAA-------------- --------------AAA-------------- ------------------------------- ------------------------------- ------------------------------- 
------------------------------- ------------------------------- ------------------------------- ------------------------------- ------------------------------- ------------------------------- ------------------------------- ------------------------------- ------------------------------- ------------------------------- ------------------------------- ------------------------------- ------------------------------- ------------------------------- ------------------------------- ------------------------------- ------------------------------- ------------------------------- ------------------------------- ------------------------------- ------------------------------- ------------------------------- ------------------------------- ---------------A--------------- --------------AAA-------------- --------------AAA-------------- --------------AAA-------------- ---------------A--------------- ---------------A--------------- ---------------A--------------- ------------------------------- 
------------------------------- ------------------------------- ------------------------------- ------------------------------- ------------------------------- ------------------------------- ------------------------------- ------------------------------- ------------------------------- ------------------------------- ------------------------------- ------------------------------- ------------------------------- ------------------------------- ------------------------------- ------------------------------- ------------------------------- ------------------------------- ------------------------------- ------------------------------- ------------------------------- ------------------------------- ------------------------------- ------------------------------- --------------AAA-------------- --------------AAA-------------- ---------------A--------------- ---------------A--------------- ---------------A--------------- ---------------A--------------- ---------------A--------------- 
------------------------------- ------------------------------- ------------------------------- ------------------------------- ------------------------------- ------------------------------- ------------------------------- ------------------------------- ------------------------------- ------------------------------- ------------------------------- ------------------------------- ------------------------------- ------------------------------- ------------------------------- ------------------------------- ------------------------------- ------------------------------- ------------------------------- ------------------------------- ------------------------------- ------------------------------- ------------------------------- ------------------------------- ---------------A--------------- ---------------A--------------- ---------------A--------------- ---------------A--------------- ---------------A--------------- ---------------A--------------- ---------------A--------------- 
------------------------------- ------------------------------- ------------------------------- ------------------------------- ------------------------------- ------------------------------- ------------------------------- ------------------------------- ------------------------------- ------------------------------- ------------------------------- ------------------------------- ------------------------------- ------------------------------- ------------------------------- ------------------------------- ------------------------------- ------------------------------- ------------------------------- ------------------------------- ------------------------------- ------------------------------- ------------------------------- ------------------------------- ---------------A--------------- ---------------A--------------- ---------------A--------------- ------------------------------- ------------------------------- ------------------------------- ------------------------------- 
------------------------------- ------------------------------- ------------------------------- ------------------------------- ------------------------------- ------------------------------- ------------------------------- ------------------------------- ------------------------------- ------------------------------- ------------------------------- ------------------------------- ------------------------------- ------------------------------- ------------------------------- ------------------------------- ------------------------------- ------------------------------- ------------------------------- ------------------------------- ------------------------------- ------------------------------- ------------------------------- ------------------------------- ------------------------------- ---------------A--------------- ---------------A--------------- ------------------------------- ------------------------------- ------------------------------- ------------------------------- 
