model
size = 30 10 31, scale = 0.05, origin = -y
material 
  colors = A:#844010 B:#53280A C:#A96148 D:#D0FCFA E:#AAF0F5 F:#E4FDFD
voxels
------------------------------ ------------------------------ -----------C------C----------- -----------CC----CC----------- -----------EEC--CEE----------- -----------EEC--CEE----------- -----------EEC--CEE----------- -----------EEC--CEE----------- -----------CC-CC-CC----------- ------------------------------ 
-----------B------B----------- --------CCCBB----BBCCC-------- --------DDEBBB--BBBEDD-------- --------DDEBBBBBBBBEDD-------- --------DDE--BBBB--EDD-------- --------DDE--BBBB--EDD-------- --------DDE--BBBB--EDD-------- --------DDE--BBBB--EDD-------- --------CCCBBBBBBBBCCC-------- -----------BBBBBBBB----------- 
--------BBB--------BBB-------- ------CCBBB--------BBBCC------ ------FD--------------DF------ ------FD--------------DF------ ------FD--------------DF------ ------FD--------------DF------ ------FD--------------DF------ ------FD--------------DF------ ------CCBBB--------BBBCC------ --------BBB--------BBB-------- 
------BB--------------BB------ ------BB--------------BB------ -----C------------------C----- -----F------------------F----- -----F------------------F----- -----F------------------F----- -----F------------------F----- -----F------------------F----- -----CBB--------------BBC----- ------BB--------------BB------ 
-----B------------------B----- -----B------------------B----- -----B------------------B----- ----C--------------------C---- ----F--------------------F---- ----F--------------------F---- ----F--------------------F---- ----C--------------------C---- -----B------------------B----- -----B------------------B----- 
------------------------------ ----B--------------------B---- ----B--------------------B---- ----B--------------------B---- ---C----------------------C--- ---C----------------------C--- ---C----------------------C--- ----B--------------------B---- ----B--------------------B---- ----B--------------------B---- 
------------------------------ ------------------------------ ---B----------------------B--- --BB----------------------BB-- --BB----------------------BB-- --BB----------------------BB-- --BB----------------------BB-- --BB----------------------BB-- ---B----------------------B--- ------------------------------ 
------------------------------ ------------------------------ ------------------------------ ------------------------------ --A------------------------A-- --A------------------------A-- --A------------------------A-- ------------------------------ ------------------------------ ------------------------------ 
------------------------------ ------------------------------ ------------------------------ ------------------------------ --A------------------------A-- --A------------------------A-- --A------------------------A-- ------------------------------ ------------------------------ ------------------------------ 
------------------------------ ------------------------------ ------------------------------ ------------------------------ -A--------------------------A- -A--------------------------A- -A--------------------------A- ------------------------------ ------------------------------ ------------------------------ 
------------------------------ ------------------------------ ------------------------------ ------------------------------ -A--------------------------A- -A--------------------------A- -A--------------------------A- ------------------------------ ------------------------------ ------------------------------ 
------------------------------ ------------------------------ ------------------------------ ------------------------------ -A--------------------------A- -A--------------------------A- -A--------------------------A- ------------------------------ ------------------------------ ------------------------------ 
------------------------------ ------------------------------ ------------------------------ ------------------------------ A----------------------------A A----------------------------A A----------------------------A ------------------------------ ------------------------------ ------------------------------ 
------------------------------ ------------------------------ ------------------------------ ------------------------------ A----------------------------A A----------------------------A A----------------------------A ------------------------------ ------------------------------ ------------------------------ 
------------------------------ ------------------------------ ------------------------------ ------------------------------ A----------------------------A A----------------------------A A----------------------------A ------------------------------ ------------------------------ ------------------------------ 
------------------------------ ------------------------------ ------------------------------ ------------------------------ A----------------------------A A----------------------------A A----------------------------A ------------------------------ ------------------------------ ------------------------------ 
------------------------------ ------------------------------ ------------------------------ ------------------------------ A----------------------------A A----------------------------A A----------------------------A ------------------------------ ------------------------------ ------------------------------ 
------------------------------ ------------------------------ ------------------------------ ------------------------------ A----------------------------A A----------------------------A A----------------------------A ------------------------------ ------------------------------ ------------------------------ 
------------------------------ ------------------------------ ------------------------------ ------------------------------ A----------------------------A A----------------------------A A----------------------------A ------------------------------ ------------------------------ ------------------------------ 
------------------------------ ------------------------------ ------------------------------ ------------------------------ A----------------------------A A----------------------------A A----------------------------A ------------------------------ ------------------------------ ------------------------------ 
------------------------------ ------------------------------ ------------------------------ ------------------------------ -A--------------------------A- -A--------------------------A- -A--------------------------A- ------------------------------ ------------------------------ ------------------------------ 
------------------------------ ------------------------------ ------------------------------ ------------------------------ -A--------------------------A- -A--------------------------A- -A--------------------------A- ------------------------------ ------------------------------ ------------------------------ 
------------------------------ ------------------------------ ------------------------------ ------------------------------ -A--------------------------A- -A--------------------------A- -A--------------------------A- ------------------------------ ------------------------------ ------------------------------ 
------------------------------ ------------------------------ ------------------------------ ------------------------------ --A------------------------A-- --A------------------------A-- --A------------------------A-- ------------------------------ ------------------------------ ------------------------------ 
------------------------------ ------------------------------ ------------------------------ ------------------------------ --AA----------------------AA-- --AA----------------------AA-- --AA----------------------AA-- ------------------------------ ------------------------------ ------------------------------ 
------------------------------ ------------------------------ ------------------------------ ------------------------------ ---A----------------------A--- ---A----------------------A--- ---A----------------------A--- ------------------------------ ------------------------------ ------------------------------ 
------------------------------ ------------------------------ ------------------------------ ------------------------------ ----A--------------------A---- ----A--------------------A---- ----A--------------------A---- ------------------------------ ------------------------------ ------------------------------ 
------------------------------ ------------------------------ ------------------------------ ------------------------------ -----AA----------------AA----- -----AA----------------AA----- -----AA----------------AA----- ------------------------------ ------------------------------ ------------------------------ 
------------------------------ ------------------------------ ------------------------------ ------------------------------ ------AA--------------AA------ ------AA--------------AA------ ------AA--------------AA------ ------------------------------ ------------------------------ ------------------------------ 
------------------------------ ------------------------------ ------------------------------ ------------------------------ --------AAA--------AAA-------- --------AAA--------AAA-------- --------AAA--------AAA-------- ------------------------------ ------------------------------ ------------------------------ 
------------------------------ ------------------------------ ------------------------------ ------------------------------ -----------AAAAAAAA----------- -----------AAAAAAAA----------- -----------AAAAAAAA----------- ------------------------------ ------------------------------ ------------------------------ 
