model
size = 20 12 30, scale = 0.05, origin = -y
material 
  colors = A:#BB1313 B:#191919 C:#1E1E1E D:#B81212 E:#D7387F F:#379D30 G:#D97708 H:#124BC6 I:#2B7F26 J:#C73473 K:#B05E06 L:#1146B8 M:#1A1A1A
voxels
------CCCCCCCC------ -------------------- -------------------- -------------------- -------------------- -------------------- -------------------- -------------------- -------------------- -------------------- -------------------- -------------------- 
----CCCAAADAACCC---- -------BBBBBB------- -------------------- -------------------- -------------------- -------------------- -------------------- -------------------- -------------------- -------------------- -------------------- -------------------- 
---CCAAAAAAAAAACC--- -----BBBBBBBBBB----- -------------------- -------------------- -------------------- -------------------- -------------------- -------------------- -------------------- -------------------- -------------------- -------------------- 
--CCAAAADAAAAAADCC-- ----BBBBBBBBBBBB---- -------------------- -------------------- -------------------- -------------------- -------------------- -------------------- -------------------- -------------------- -------------------- -------------------- 
--CAAAAAAAAADAAAAC-- ---BEBBBHBFBFBGGB--- -------------------- -------------------- -------------------- -------------------- -------------------- -------------------- -------------------- -------------------- -------------------- -------------------- 
--CADAAAAAAAAAAAAC-- ---BEBBBHBFBFBGBB--- -------------------- -------------------- -------------------- -------------------- -------------------- -------------------- -------------------- -------------------- -------------------- -------------------- 
-CCAAAAAAAADAAAAACC- ---BEEEBHBBFBBGBB--- -------------------- -------------------- -------------------- -------------------- -------------------- -------------------- -------------------- -------------------- -------------------- -------------------- 
-CAAADDAAAAAAAAADAC- --BBEBEBHBFBFBGBBB-- -------------------- -------------------- -------------------- -------------------- -------------------- -------------------- -------------------- -------------------- -------------------- -------------------- 
-CAAAAAAAAAAAAAAAAC- --BBEEEBHBFBFBGBBB-- -------------------- -------------------- -------------------- -------------------- -------------------- -------------------- -------------------- -------------------- -------------------- -------------------- 
-CDAAAAADADDAADAAAC- --BBBBBBBBBBBBBBBB-- -------------------- -------------------- -------------------- -------------------- -------------------- -------------------- -------------------- -------------------- -------------------- -------------------- 
-CAAAAADAAAAAAAAAAC- --BBBBBBBBBBBBBBBB-- -------BBBBBB------- --------BBBB-------- -------------------- -------------------- -------------------- -------------------- -------------------- -------------------- -------------------- -------------------- 
-CAADAA------AAADAC- --BBBBBAAADAABBBBB-- -----BBAAAAAABB----- -----BBBADAABBB----- ------BBBBBBBB------ -------BBBBBB------- -------------------- -------------------- -------------------- -------------------- -------------------- -------------------- 
-CAAA----------AAAC- --BBBAA------AABBB-- ----BAA------AAB---- ----BAAA----AAAB---- ----BBAAAAADAABB---- -----BBAAAAAABB----- ------BBBBBBBB------ ---------BB--------- -------------------- -------------------- -------------------- -------------------- 
-CA--------------AC- --BAD----------AAB-- ---BA----------AB--- ---BA----------AB--- ---BAA--------AAB--- ----BDA------AAB---- -----BAAAAAAAAB----- ------BBBAABBB------ ---------BB--------- -------------------- -------------------- -------------------- 
-CA--------------DC- --BA------------AB-- --BA------------AB-- --BA------------AB-- --BA------------AB-- ---BA----------AB--- ----BA--------AB---- -----BAAAAAAAAB----- ------BBBBBBBB------ -------------------- -------------------- -------------------- 
-CA--------------AC- -BA--------------AB- -BA--------------AB- -BA--------------AB- --BD------------AB-- --BA------------AB-- ---BA----------AB--- ----BAA------AAB---- -----BBAAAADABB----- -------BBBBBB------- -------------------- -------------------- 
-CA--------------AC- -BD--------------AB- -BA--------------AB- -BA--------------AB- -BA--------------AB- --BA------------AB-- --BA------------AB-- ---BAA--------AAB--- ----BBADAAADAABB---- ------BBBBBBBB------ -------------------- -------------------- 
CA----------------AC CA----------------AC CA----------------AC -CA--------------AC- -CA--------------AC- -CA--------------AC- --BA------------AB-- ---BA----------AB--- ----BAAA----AAAB---- -----BBBAAADBBB----- --------BBBB-------- -------------------- 
EA----------------AE EA----------------AE EA----------------AE EA----------------AE -JA--------------AJ- -CA--------------AC- --BA------------AB-- ---BA----------AB--- ----BAA------AAB---- -----BBAAAAAABB----- -------BBBBBB------- -------------------- 
HA----------------AH HD----------------AH HA----------------AH HA----------------AH -LA--------------AL- -CA--------------AC- --BA------------AB-- --BAA----------AAB-- ---BBDD------AABB--- -----BBAAAAADBB----- -------BBBBBB------- ---------DA--------- 
FA----------------DF FA----------------AF FA----------------AF FA----------------AF -IA--------------AI- -CA--------------AC- --BA------------AB-- --BAA----------DAB-- ---BBAA------AABB--- -----BBAADAAABB----- -------BBBBBB------- ---------AD--------- 
GA----------------AG GA----------------AG GA----------------AG GA----------------AG -KA--------------AK- -CD--------------AC- --BA------------AB-- ---BA----------AB--- ----BAA------AAB---- -----BBAAAAAABB----- -------BBBBBB------- -------------------- 
CA----------------AC CA----------------AC CA----------------AC -CA--------------AC- -CA--------------AC- -CA--------------AC- --BA------------AB-- ---BA----------AB--- ----BAAD----AAAB---- -----BBBAAAABBB----- --------BBBB-------- -------------------- 
-CA--------------AC- -BD--------------AB- -BA--------------AB- -BA--------------AB- -BA--------------AB- --BA------------AB-- --BA------------AB-- ---BAA--------ADB--- ----BBAAAAAAAABB---- ------BBBBBBBB------ -------------------- -------------------- 
-CA--------------AC- -BA--------------AB- -BA--------------AB- -BA--------------AB- --BD------------DB-- --BA------------AB-- ---BA----------AB--- ----BAD------AAB---- -----BBAAAADABB----- -------BBBBBB------- -------------------- -------------------- 
--CA------------AC-- --BA------------AB-- --BA------------AB-- --BA------------AB-- --BA------------AB-- ---BA----------AB--- ----BD--------AB---- -----BAAAAAAAAB----- ------BBBBBBBB------ -------------------- -------------------- -------------------- 
--CAD----------AAC-- --BAA----------AAB-- ---BA----------AB--- ---BA----------AB--- ---BAA--------AAB--- ----BAA------DAB---- -----BAAAAAAAAB----- ------BBBAABBB------ ---------BB--------- -------------------- -------------------- -------------------- 
---CCAA------AACC--- ---BBAA------AABB--- ----BAA------DAB---- ----BAAAADAAAAAB---- ----BBAAADAAAABB---- -----BCAAAAAACB----- ------CCCCCCCC------ ---------BB--------- -------------------- -------------------- -------------------- -------------------- 
-----CC------CC----- -----BC------CB----- -----BC------CB----- -----BCKIILJJCB----- ------CGFFHEEC------ -------GFFHEE------- -------------------- -------------------- -------------------- -------------------- -------------------- -------------------- 
-------CMCCCC------- -------------------- -------------------- -------------------- -------------------- -------------------- -------------------- -------------------- -------------------- -------------------- -------------------- -------------------- 
