model
size = 14 26 7, scale = 0.05, origin = -y
material 
  colors = A:#EEE B:#222 C:#111 D:#BDC0BA E:#DDD23B F:#FFFFFB
voxels
-------------- -------------- -------------- -------------- ------CC------ -----CCCC----- ----CCCCCC---- ----CCCCCC---- ----CCCCC----- -----CCCC----- ------CC------ -------------- -------------- -------------- -------------- -------------- -------------- -------------- -------------- -------------- -------------- -------------- -------------- -------------- -------------- -------------- 
-----AAAA----- ----E----A---- ---A-CCCC-E--- --A-C----C-A-- -E-C--CC--C-E- -AC--CCCC--CA- -A--CCCCCC--E- --E-CCCCCC-A-- ---ACCCCCCA--- ----ACCCCE---- -----ACCA----- -------------- -------------- -------------- -------------- -------------- -------------- -------------- -------------- -------------- -------------- -------------- -------------- -------------- -------------- -------------- 
-----AAAA----- ----AAAAAA---- ---AAAAAAAA--- --AAAAAAAAAA-- -AAAAAAAAAAAA- -AAAAAFFAAAAA- -AAAAAFFAAAAA- --AAAAFFAAAA-- ---AAAFFAAA--- ----AAFFAA---- -----AFFA----- -----DDDD----- ----D----D---- ---E------D--- ---D------A--- --D--------D-- --D--------D-- -D----------D- -A----------E- D------------D -------------- -------------- -------------- -------------- -------------- -------------- 
-----AAAE----- ----AEBB-A---- ---A-BBBB-A--- --E-B----B-E-- -A-B--BB--B-E- -AB--BBBB--BA- -E--BBBBBB--E- --ABBBBBBBBE-- ---ABBBBBBA--- ----EBBBBE---- -----EBBA----- -------------- -------------- -------------- -------------- -------------- -------------- -------------- -------------- D------------D A------------D -------------- -------------- -------------- -------------- -------------- 
-------------- -------------- -------------- -------------- ------BB------ -----BBBB----- ----BBBBBB---- ----BBBBBB---- ----BBBBBB---- -----BBBB----- ------BB------ -------------- -------------- -------------- -------------- -------------- -------------- -------------- -------------- -------------- D------------D E------------E -------------- -------------- -------------- -------------- 
-------------- -------------- -------------- -------------- -------------- -------------- -------------- -------------- -------------- -------------- -------------- -------------- -------------- -------------- -------------- -------------- -------------- -------------- -------------- -------------- -------------- D------------D D------------A -------------- -------------- -------------- 
-------------- -------------- -------------- -------------- -------------- -------------- -------------- -------------- -------------- -------------- -------------- -------------- -------------- -------------- -------------- -------------- -------------- -------------- -------------- -------------- -------------- -------------- D------------D DD----------ED -ED--------DA- --DDEDDAADDD-- 
