model
size = 12 14 32, scale = 0.05, origin = -y
material 
  colors = A:#E7E0D2 B:#E9C470 C:#1E1E1E D:#323232 E:#E7E3DA F:#3C3C3C G:#8D1204 H:#CCB683 I:#E0D2B2 J:#BB1313 K:#379D30 L:#D5AC5B M:#D7387F N:#124BC6 O:#D97708 P:#141414
voxels
4-4C8-4C151-2CFD2C6-C4BC7-4A139-C2(FD)C6-H4BH6-6A137-2C2(DF)2C4-H6BH4-A6-A5-6A124-2C6M2C2-H8BH3-A6-A4-8A123-CDFDMDFMFC2-H8BH3-A6-A2(4-2A)6-4A112-2CFDFMFDMD2CH10BH-E8-E3-A6-A5-6A111-C2(FD)4MFDCH10BH-E8-E3-A6-A4-A6LA110-C5(DF)CH10BH-E8-E3-A6-A4-L6IL6-4I100-CFD6NFDCH10BH-E8-E2-E8-E3-L6-L5-6I99-C5(DF)CH10BHA10-A-E8-E3-A6-A4-P6JP98-C2(FD2K)FDCH10BHA10-A-E8-E2-E8-E3-A6-A4-L6IL86-C2(DF)2K2(DF)CH10BHA10-A-A8-A2-E8-E3-A6-A4-P6OP86-C2(FD)2K2(FD)CH10BHA10-A-A8-A2-E8-E3-2(A6-A4-)L6IL74-2C2(F2KD)2CH10BH-2(A8-A2-)E8-E3-2(A6-A4-)P6KP75-C4(DF)C2-H8BH2(2-A8-A)2(2-E8-E)3-2(A6-A4-)L6IL63-CF6ODC2-H8BH3(2-A8-A)2-E8-E3-2(A6-A4-)P6NP63-CDO3(DF)C2-H8BH3(2-A8-A)2-E8-E3-3(A6-A4-)L6IL51-CFO3(FD)C2-H8BH3(2-A8-A)2(2-E8-E)3-3(A6-A4-)P6MP39-C4(DF)C2-HB6JBH4(2-A8-A)2(2-E8-E)3-3(A6-A4-)L6IL27-C4(FD)C2-HB6JBH5(2-A8-A)4(2-E8-E)3-2L4I2L5-L4IL6-L4IL3-2C4(DF)2CH2BJ2B2J3BHMA8-A2MA8-AM-6(A8-A2-)E8-E2-E8-E16-6G3-C5(DF)CH2BJ2B2J3BH2A4(8-4A)8-2A-3(A8-A2-)E8-E2-E8-E25-CFD6JFDCH2BJ2B2J3BHN5(A8-A2N)A8-AN-2(A8-A2-)E8-E37-C2(DF)JFDJDFCH2B5J3BH2A5(8-4A)8-2A-A8-A2(2-E8-E)37-C2(FD)JDFJFDCH5B2J3BHK4(A8-A2K)A8-AK-2(A8-A2-)E8-E49-C2(DF)4JDFCH2B2GB2J3BH2A2(8-4A)8-2A-4(A8-A2-)E8-E49-C5(FD)CH2BGB4J2BHOA8-AO-5(A8-A2-)E8-E2-E8-E49-2C3(FD)GD2CH2BG7BH-6(A8-A2-)E8-E62-2C6G2C2-HBG6BH6(2-2A6-2A)2-2E6-2E63-2C2(FD)2C4-H6BH3(4-AG6A)4-EG5A3(E4-E6G)E6-4G55-6C6-H4CH3(6-AE2GEA)6-2E2G2E7-3(4G8-)4G52-
