model
size = 17 24 14, scale = 0.05, origin = -y
material 
  colors = A:#C6F B:#FCF
voxels
----------------- ----------------- ----A-A-A-A-A---- ----A-A-A-A-A---- --AAAAAAAAAAAAA-- ---AABBBABBBAA--- --AABBBBABBBBAA-- ---ABBBBABBBBA--- --AABBBBABBBBAA-- ---BBBBBABBBBB--- ---BBBABABBBBB--- ---BABABABABAB--- ---AAAAAAAAAAA--- ---A----A----A--- ---A----A----A--- ---AAAAAAAAAAA--- ---BBBBBABBBBB--- ---BBBBBABBBBB--- ---BBBBBABBBBB--- ---BBBBBABBBBB--- --ABABABABABABA-- ---AAAAAAAAAAA--- ---A-A-A-A-A-A--- -------A-A------- 
--AAAAAAAAAAAAA-- --A-----------A-- AAA-----------AAA A---------------A A---------------A A---------------A A---------------A A---------------A A-A-----------A-A A-A-----------A-A AAA-----------AAA ----------------- --A-----------A-- --A-----------A-- --A-----------A-- --A-----------A-- ----------------- ----------------- ----------------- --A-----------A-- ---A-A-A-A-A-A--- --AAAAAAAAAAAAA-- --A-A-A-A-A-A-A-- ------A-A-A------ 
----------------- ----------------- ----------------- ----------------- ----------------- ----------------- ----------------- ----------------- ----------------- ----------------- ----------------- ----------------- ----------------- ---A---------A--- ---A---------A--- ----------------- ----------------- ----------------- ----------------- ----------------- ----------------- ----------------- ----------------- ----------------- 
----------------- ----------------- ----------------- ----------------- ----------------- ----------------- ----------------- ----------------- ----------------- ----------------- ----------------- ----------------- ----------------- ---A---------A--- ---A---------A--- ----------------- ----------------- ----------------- ----------------- ----------------- ----------------- ----------------- ----------------- ----------------- 
----------------- ----------------- ----------------- ----------------- ----------------- ----------------- ----------------- ----------------- ----------------- ----------------- ----------------- ----------------- ----------------- ---A---------A--- ---A---------A--- ----------------- ----------------- ----------------- ----------------- ----------------- ----------------- ----------------- ----------------- ----------------- 
----------------- ----------------- ----------------- ----------------- ----------------- ----------------- ----------------- ----------------- ----------------- ----------------- ----------------- ----------------- ----------------- ---A---------A--- ---A---------A--- ----------------- ----------------- ----------------- ----------------- ----------------- ----------------- ----------------- ----------------- ----------------- 
----------------- ----------------- ----------------- ----------------- ----------------- ----------------- ----------------- ----------------- ----------------- ----------------- ----------------- ----------------- ----------------- ---A---------A--- ---A---------A--- ----------------- ----------------- ----------------- ----------------- ----------------- ----------------- ----------------- ----------------- ----------------- 
----------------- ----------------- ----------------- ----------------- ----------------- ----------------- ----------------- ----------------- ----------------- ----------------- ----------------- ----------------- ----------------- ---A---------A--- ---A---------A--- ----------------- ----------------- ----------------- ----------------- ----------------- ----------------- ----------------- ----------------- ----------------- 
----------------- ----------------- ----------------- ----------------- ----------------- ----------------- ----------------- ----------------- ----------------- ----------------- ----------------- ----------------- ----------------- ---A---------A--- ---A---------A--- ----------------- ----------------- ----------------- ----------------- ----------------- ----------------- ----------------- ----------------- ----------------- 
----------------- ----------------- ----------------- ----------------- ----------------- ----------------- ----------------- ----------------- ----------------- ----------------- ----------------- ----------------- ----------------- ---A---------A--- ---A---------A--- ----------------- ----------------- ----------------- ----------------- ----------------- ----------------- ----------------- ----------------- ----------------- 
----------------- ----------------- ----------------- ----------------- ----------------- ----------------- ----------------- ----------------- ----------------- ----------------- ----------------- ----------------- ----------------- ---A---------A--- ---A---------A--- ----------------- ----------------- ----------------- ----------------- ----------------- ----------------- ----------------- ----------------- ----------------- 
----------------- ----------------- ----------------- ----------------- ----------------- ----------------- ----------------- ----------------- ----------------- ----------------- ----------------- ----------------- ----------------- ---A---------A--- ---A---------A--- ----------------- ----------------- ----------------- ----------------- ----------------- ----------------- ----------------- ----------------- ----------------- 
----------------- ----------------- ----------------- ----------------- ----------------- ----------------- ----------------- ----------------- ----------------- ----------------- ----------------- ----------------- ----------------- ---A---------A--- ---A---------A--- ----------------- ----------------- ----------------- ----------------- ----------------- ----------------- ----------------- ----------------- ----------------- 
----------------- ----------------- ----------------- ----------------- ----------------- ----------------- ----------------- ----------------- ----------------- ----------------- ----------------- ----------------- ---AAAAAAAAAAA--- ---AAAAAAAAAAA--- ---AAAAAAAAAAA--- ----------------- ----------------- ----------------- ----------------- ----------------- ----------------- ----------------- ----------------- ----------------- 
