model
size = 31 13 7, scale = 0.05, origin = -y
material 
  colors = A:#FFADAD B:#E00
voxels
------------------------------- B------------------------------ B-AAAAAAAAA-------------------- --AABBBBBAA-------------------- -BABABABABA-------------------- -BABBAAABBA-------------------- --ABAAAAABA-------------------- --ABAAAAABA-------------------- --ABAAAAABA-------------------- --ABBAAABBA-------------------- --ABABABABA-------------------- --AABBBBBAA-------------------- --BAAAAAAAA-------------------- 
B------------------------------ ------------------------------- -BAAABBBAAAA------------------- -BAAAAAAAAAA------------------- -BAAAAAAAAAA------------------- -AAAAAAAAAAA------------------- -BAAAAAAAAAB------------------- -BAAAAAAAAAB------------------- -BAAAAAAAAAB------------------- -AAAAAAAAAAA------------------- -BAAAAAAAAAA------------------- -BAAAABBBAAA------------------- -BAAABBBAAAA------------------- 
------------------------------- B------------------------------ BBAAABABAAAA------------------- -AAAAAAAAAAA------------------- -AAAAAAAAAAA------------------- -AAAAAAAAAAA------------------- -BBAAAAAAAABBAA-BAA-BAA-BAA-BA- -AAAAAAAAAAAAA-BAA-BAA-BAA-BA-- -BBAAAAAAAABA-BAA-BAA-BAA-BAAA- -AAAAAAAAAAA------------------- -AAAAAAAAAAA------------------- -AAAAABABAAA------------------- -BAAABABAAAA------------------- 
B------------------------------ ------------------------------- -BBBBBBBBBBB------------------- -BBAAAAAAAAB------------------- -BBAAAAAAAAB------------------- -BBAAAAAAAAB------------------- -BBAAAAAAAAB-BAA-BAA-BAA-BAA-B- -BBAAAAAAAAB------------------B -BBAAAAAAAAB-BAA-BAA-BAA-BAA-B- -BBAAAAAAAAB------------------- -BBAAAAAAAAB------------------- -BBBBBBBBBBB------------------- -BBBBBBBBBBB------------------- 
------------------------------- B------------------------------ BBAAABABAAAA------------------- -AAAAAAAAAAA------------------- -AAAAAAAAAAA------------------- -AAAAAAAAAAA------------------- -BBAAAAAAAABA-BAA-BAA-BAA-BAAA- -AAAAAAAAAAAAA-BAA-BAA-BAA-BA-- -BBAAAAAAAABBAA-BAA-BAA-BAA-BA- -AAAAAAAAAAA------------------- -AAAAAAAAAAA------------------- -AAAAABABAAA------------------- -BAAABABAAAA------------------- 
B------------------------------ ------------------------------- -BAAABBBAAAA------------------- -BAAAAAAAAAA------------------- -BAAAAAAAAAA------------------- -AAAAAAAAAAA------------------- -BAAAAAAAAAB------------------- -BAAAAAAAAAB------------------- -BAAAAAAAAAB------------------- -AAAAAAAAAAA------------------- -BAAAAAAAAAA------------------- -BAAAABBBAAA------------------- -BAAABBBAAAA------------------- 
------------------------------- B------------------------------ B-AAAAAAAAA-------------------- --ABBBBBBBA-------------------- -BABABABABA-------------------- -BABBAAABBA-------------------- --ABAAAAABA-------------------- --ABAAAAABA-------------------- --ABAAAAABA-------------------- --ABBAAABBA-------------------- --ABABABABA-------------------- --ABBBBBBBA-------------------- --BAAAAAAAA-------------------- 
