model
size = 21 14 26, scale = 0.05, origin = -y
material 
  colors = A:#444 B:#B00 C:#A00 D:#D00 E:#777
voxels
--------------------- --------------------- --------------------- --------------------A --------------------A --------------------A --------------------A --------------------- --------------------- --------------------- --------------------- --------------------- --------------------- --------------------- 
--------------------- --------------------- --------------------- --------------------- --------------------A --------------------A --------------------A --------------------A --------------------- --------------------- --------------------- --------------------- --------------------- --------------------- 
--------------------- --------------------- --------------------- --------------------- --------------------- --------------------A --------------------A --------------------A --------------------A --------------------- --------------------- --------------------- --------------------- --------------------- 
--------------------- --------------------- --------------------- --------------------- --------------------- --------------------- --------------------A --------------------A --------------------A --------------------A --------------------- --------------------- --------------------- --------------------- 
--------------------- --------------------- --------------------- --------------------- --------------------- --------------------- --------------------- --------------------A --------------------A --------------------A --------------------- --------------------- --------------------- --------------------- 
--------------------- --------------------- --------------------- --------------------- --------------------- --------------------- --------------------- --------------------A --------------------A --------------------A --------------------- --------------------- --------------------- --------------------- 
--------------------- --------------------- --------------------- --------------------- --------------------- --------------------- --------------------- --------------------A --------------------A --------------------A --------------------- --------------------- --------------------- --------------------- 
--------------------- --------------------- --------------------- --------------------- --------------------- --------------------- --------------------- --------------------A --------------------A --------------------A --------------------- --------------------- --------------------- --------------------- 
--------------------- --------------------- --------------------- --------------------- --------------------- --------------------- --------------------- --------------------A --------------------A --------------------A --------------------- --------------------- --------------------- --------------------- 
--------------------- --------------------- --------------------- --------------------- --------------------- --------------------- --------------------A --------------------A --------------------A --------------------A --------------------- --------------------- --------------------- --------------------- 
--------------------- --------------------- --------------------- --------------------- --------------------- --------------------- --------------------A --------------------A --------------------A --------------------A --------------------- --------------------- --------------------- --------------------- 
--------------------- --------------------- --------------------- --------------------- --------------------- --------------------- --------------------A --------------------A --------------------A --------------------A --------------------- --------------------- --------------------- --------------------- 
--------------------- --------------------- --------------------- --------------------- --------------------- -------------------A- --------------------A --------------------A --------------------A --------------------A --------------------- --------------------- --------------------- --------------------- 
--------------------- --------------------- --------------------- --------------------- --------------------- -------------------A- --------------------A --------------------A --------------------A --------------------A --------------------- --------------------- --------------------- --------------------- 
--------------------- --------------------- --------------------- --------------------- --------------------- -------------------A- --------------------A --------------------A --------------------A --------------------A --------------------- --------------------- --------------------- --------------------- 
--------------------- --------------------- --------------------- --------------------- ------------------A-- -------------------A- --------------------A --------------------A --------------------A --------------------A -------------------A- --------------------- --------------------- --------------------- 
--------------------- --------------------- --------------------- --------------------- ------------------A-- -------------------A- --------------------A --------------------A --------------------A --------------------A -------------------A- --------------------- --------------------- --------------------- 
--------------------- --------------------- --------------------- -----------------A--- ------------------A-- -------------------A- --------------------A --------------------A --------------------A --------------------A -------------------A- ------------------A-- --------------------- --------------------- 
--------------------- --------------------- --------------------- -----------------A--- ------------------A-- -------------------A- -------------------AA -------------------AA -------------------AA -------------------AA -------------------A- ------------------A-- --------------------- --------------------- 
--------------------- --------------------- ----------------A---- -----------------A--- ------------------A-- ------------------AA- ------------------AAA ------------------AAA ------------------AAA ------------------AAA ------------------AA- ------------------A-- -----------------A--- --------------------- 
--------------------- ---------------A----- ----------------A---- -----------------A--- -----------------AA-- -----------------AAA- -----------------AAAA -----------------AAAA -----------------AAAA -----------------AAAA -----------------AAA- -----------------AA-- -----------------A--- ----------------A---- 
--------------A------ ---------------A----- ----------------A---- ----------------AA--- ----------------AAA-- ----------------AAAA- ----------------AAAAA ----------------AAAAA ----------------AAAAA ----------------AAAAA ----------------AAA-- ----------------AA--- ----------------AA--- ---------------AA---- 
-----AAAAAAAAAA------ ----AAAAAAAAAAAA----- ---AAAACCCCCAAAAA---- --AAAAC-----CAAAAA--- -AAAAC-------CAAAAA-- AAAAC---------CAAAAA- AAAAC---------CAAAAA- AAAAC---------CAAAAAA AAAAC---------CAAAAAA AAAAC---------CAAAAA- -AAAAC-------CAAAAA-- --AAAAC-----CAAAAA--- ---AAAACCCCCAAAAA---- ----AAAAAAAAAAAA----- 
----AAAAAAAAAAA------ ---AAAAAAAAAAAAA----- --AAAAA-----AAAAA---- -AAAAA-CCCCC-AAAAA--- AAAAA-CC---CC-AAAAA-- AAAA-CC-----CC-AAAA-- AAAA-C-------C-AAAAA- AAAA-C-------C-AAAAA- AAAA-C-------C-AAAAA- AAAA-CC-----CC-AAAAA- AAAAA-CC---CC-AAAAA-- -AAAAA-CCCCC-AAAAA--- --AAAAA-----AAAAA---- ---AAAAAAAAAAAAA----- 
--------------------- ----AAAAAAAAAAA------ ---AEAA-----AAEA----- --AAAA-BBBBB-AAAA---- -AAAA-BBBBBBB-AAAA--- AAAA-BBBBBBBBB-AAAA-- AAAA-BBBBBBBBB-AAAA-- AAAA-BBBBBBBBB-AAAA-- AAAA-BBBBBBBBB-AAAA-- AAAA-BBBBBBBBB-AAAA-- -AAAA-BBBBBBB-AAAA--- --AAAA-BBBBB-AAAA---- ---AEAA-----AAEA----- ----AAAAAAAAAAA------ 
--------------------- --------------------- --------------------- --------------------- --------DDD---------- -------DDDDD--------- ------DDD-DDD-------- ------DD---DD-------- ------DDD-DDD-------- -------DDDDD--------- --------DDD---------- --------------------- --------------------- --------------------- 
