model
size = 4 4 32, scale = 0.05, origin = -y
material 
  colors = A:#EEE B:#F60 C:#AAA D:#888 E:#DDD F:#960 G:#E00 H:#693 I:#F93 J:#F63 K:#B00 L:#993 M:#690
voxels
IJGFJGB2GBGIFIGJBM3B2A2F2ABK2B2FBHDH2AHB2AFBDFHLGDCB2ADG2A2DCD2FDCAD2ACD2A2CAC2DC2AC3AC6A2C94A-12A2(-2A-3A-8A)5(-2A2-2A-8A)3(-2A2-A2-8A)2(2(2-A)3-2A-4A)2-A6-3(2A-4A9-)2A2-2A3(10-2E2-2E)5-
