model
size = 16 8 16, scale = 0.05, origin = -y
material 
  colors = A:#EEE B:#FF0 C:#0F3 D:#D00 E:#93F F:#00E G:#E00 H:#FF6 I:#60F
voxels
DDDDDDDDDDDDDDDD ---------------- ---------------- ---------------- ---------------- ---------------- ---------------- ---------------- 
DBBBBBBBBBBBBBBD -BBBBBBBBBBBBBB- ---------------- ---------------- ---------------- ---------------- ---------------- ---------------- 
DBBBBBBBBBBBBBBD -BAAAAAAAAAAAAB- --EEEEEEEEEEEE-- ---------------- ---------------- ---------------- ---------------- ---------------- 
DBBBBBBBBBBBBBBD -BAAAAAAAAAAAAB- --EAAAAAAAAAAE-- ---FFFFFFFFFF--- ---------------- ---------------- ---------------- ---------------- 
DBBBBBBBBBBBBBBD -BAAAAAAAAAAAAB- --EAAAAAAAAAAE-- ---FAAAAAAAAF--- ----CCCCCCCC---- ---------------- ---------------- ---------------- 
DBBBBBBBBBBBBBBD -BAAAAAAAAAAAAB- --EAAAAAAAAAAE-- ---FAAAAAAAAF--- ----CCCCCCCC---- -----GGGGGG----- ---------------- ---------------- 
DBBBBBBBBBBBBBBD -BAAAAAAAAAAAAB- --EAAAAAAAAAAE-- ---FAAAAAAAAF--- ----CCCCCCCC---- -----GGGGGG----- ------HHHH------ ---------------- 
DBBBBBBBBBBBBBBD -BAAAAAAAAAAAAB- --EAAAAAAAAAAE-- ---FAAAAAAAAF--- ----CCCCCCCC---- -----GGGGGG----- ------HHHH------ -------II------- 
DBBBBBBBBBBBBBBD -BAAAAAAAAAAAAB- --EAAAAAAAAAAE-- ---FAAAAAAAAF--- ----CCCCCCCC---- -----GGGGGG----- ------HHHH------ -------II------- 
DBBBBBBBBBBBBBBD -BAAAAAAAAAAAAB- --EAAAAAAAAAAE-- ---FAAAAAAAAF--- ----CCCCCCCC---- -----GGGGGG----- ------HHHH------ ---------------- 
DBBBBBBBBBBBBBBD -BAAAAAAAAAAAAB- --EAAAAAAAAAAE-- ---FAAAAAAAAF--- ----CCCCCCCC---- -----GGGGGG----- ---------------- ---------------- 
DBBBBBBBBBBBBBBD -BAAAAAAAAAAAAB- --EAAAAAAAAAAE-- ---FAAAAAAAAF--- ----CCCCCCCC---- ---------------- ---------------- ---------------- 
DBBBBBBBBBBBBBBD -BAAAAAAAAAAAAB- --EAAAAAAAAAAE-- ---FFFFFFFFFF--- ---------------- ---------------- ---------------- ---------------- 
DBBBBBBBBBBBBBBD -BAAAAAAAAAAAAB- --EEEEEEEEEEEE-- ---------------- ---------------- ---------------- ---------------- ---------------- 
DBBBBBBBBBBBBBBD -BBBBBBBBBBBBBB- ---------------- ---------------- ---------------- ---------------- ---------------- ---------------- 
DDDDDDDDDDDDDDDD ---------------- ---------------- ---------------- ---------------- ---------------- ---------------- ---------------- 
