model
size = 16 14 31, scale = 0.05, origin = -y
material 
  colors = A:#CF3 B:#FF0 C:#9CF D:#111 E:#F3F F:#EEE
voxels
-----FFFFFF----- -----FFFFFF----- ---------------- ---------------- -----FFFFFF----- -----FFFFFF----- ---------------- ---------------- ---------------- ---------------- ---------------- ---------------- ---------------- ---------------- 
----DDDDDDDD---- ----ABBBBBBA---- ----AAAAAAAA---- ----AAAAAAAA---- ----ABBBBBBA---- -----AAAAAA----- ---------------- ---------------- ---------------- ---------------- ---------------- ---------------- ---------------- ---------------- 
----DDDDDDDD---- ----ABBBBBBA---- ----ABBBBBBA---- ----ABBBBBBA---- ----ABBBBBBA---- ----AAAAAAAA---- ---------------- ---------------- ---------------- ---------------- ---------------- ---------------- ---------------- ---------------- 
---D-D-DD-D-D--- ---EABAAAABAE--- ---EBBBBBBBCE--- ---EBBBBBBBCE--- ---EBDDDDDDBE--- ----A------A---- ---------------- ---------------- ---------------- ---------------- ---------------- ---------------- ---------------- ---------------- 
--D--D----D--D-- --AAABAAAABAAA-- --ABBBBBBBBCBA-- --ABBBBBBBBCBA-- --ABBBBBBBBBBA-- ---AAAAAAAAAA--- ---------------- ---------------- ---------------- ---------------- ---------------- ---------------- ---------------- ---------------- 
---DDDDDDDDDD--- ---BBBBBBBBBB--- --ABBBBBBBBBBA-- --ABBBBBBBBBBA-- --ABBDDDDDDBBA-- ---AA------AA--- ---------------- ---------------- ---------------- ---------------- ---------------- ---------------- ---------------- ---------------- 
-DD--D----D--DD- -EBAABAAAABAABE- -EBBBBBBBBBCBCE- -EBBBBBBBBBCBCE- -EBBBBBBBBBBBBE- --AAAAAAAAAAAA-- ---------------- ---------------- ---------------- ---------------- ---------------- ---------------- ---------------- ---------------- 
--DD-D-EE-D-DD-- --ABABABBABABB-- -AABBBBBBBBCBCA- -AABBBBBBBBCBCA- -AABBDDDDDDBBBA- --AAA------AAA-- ---------------- ---------------- ---------------- ---------------- ---------------- ---------------- ---------------- ---------------- 
DDDDDDEEEEDDDDDD AABBBBBBBBBBBBBA ABBBBBBBBBBBBBBA ABBBBBBBBBBBBBBA ABBBBBBBBBBBBBBA -AEEEAAEEAAEEEA- ---------------- ---------------- ---------------- ---------------- ---------------- ---------------- ---------------- ---------------- 
--D---E--E---D-- -ABAAABAABAAABA- ABBBBBBBBBBBBBBA ABBBBBBBBBBBBBBA ABBBBBBBBBBBBBBA -AABBAAAAAABBAA- ---AD------DA--- ---------------- ---------------- ---------------- ---------------- ---------------- ---------------- ---------------- 
DDDDDEEEEEEDDDDD AABBBBBBBBBBBBBA ABBBBBBBBBBBBBBA ABBBBBBBBBBBBBBA ABBBBBBBBBBBBBBA AAABBAAAAAABBAAA ---AD------DA--- ---------------- ---------------- ---------------- ---------------- ---------------- ---------------- ---------------- 
--D-DE----ED-D-- -ABABBAAAABBABA- ABBCBBCCCBBBBBBA ABBCBBCCCBBBBBBA ACCCCCCCCCCBBBBA ACCCCCCCCCCBBBBA EEEEDEEEEEEDEEEE ---ED------DE--- ---------------- ---------------- ---------------- ---------------- ---------------- ---------------- 
DDDDDEEEEEEDDDDD AABBBBBBBBBBBBBA ABBBBBBBBBBBBBBA ABBBBBBBBBBBBBBA ACCCCCCCCCCBBBBA ECCCCCCCCCCBBBBE ACCCDCCCCCCDBBBA AAAADAAAAAADAAAA ---AD------DA--- ---------------- ---------------- ---------------- ---------------- ---------------- 
--D--E----E--D-- -ABAABAAAABAABA- ABBBBBCCCBBBBBBA ABBBBBCCCBBBBBBA ECCCCCCCCCCBBBBE ACCCCCCCCCCBBBBA ACCCDCCCCCCDBBBA ACCCDBBBBBBDBBBA EEEEDEEEEEEDBEEE ---ED------DE--- ---------------- ---------------- ---------------- ---------------- 
DDDDDEEEEEEDDDDD AABBBBBBBBBBBBBA ABBBBBBBBBBBBBBA EBBBBBBBBBBBBBBE ACCCCCCCCCCBBBBA ABCCCCCCCCCBBBBA ACCCCCCCCCCBBBBA EBCCCBBBBBBBBBBE ACCCCCCCCBBBBBBA AAAEAAAAAAAAEAAA ---------------- ---------------- ---------------- ---------------- 
--D--E----E--D-- -ABAABAAAABAABA- EBBCCBCCCBBBBBBE ABBCCBCCCBBBBBBA ACCCCCCCCCCBBBBA ABCCCCCCCCCBBBBA ECCCCCCCCCCBBBBE ABCCCBBBBBBBBBBA ACCCCCCCCBBBBBBA EEEEAEEEEEEAEEEE ---------------- ---------------- ---------------- ---------------- 
DDDDDEEEEEEDDDDD EBBBBBBBBBBBBBBE ABBBBBBBBBBBBBBA -DBBBBBBBBBBBBD- ACCCCCCCCCCBBBBA -DCCCCCCCCCBBBD- ACCCCCCCCCCBBBBA -DCCCBBBBBBCCCD- ECCCCCCCCBBBBBBE AAAEAAAAAAAAEAAA ---------------- ---------------- ---------------- ---------------- 
--D--E----E--D-- -ABAABAAAABAABA- ABBCCBCCCBBBBBBA -DBCCBCCCCCCBCD- ECCCCCCCCCCBBBBE -DCCCCCCCCCBBBD- ACCCCCCCCCCBBBBA -DCCCBBBBBBCCCD- ACCCCCCCCBBBBBBA AAAEAAAAAAAAEAAA ---------------- ---------------- ---------------- ---------------- 
DDDDDEEEEEEDDDDD ABBBBBBBBBBBBBBA ABBBBBBBBBBBBBBA -DBBBBBBBBBBBBD- ACCCCCCCCCCBBBBA -DCCCCCCCCCBBBD- ECCCCCCCCCCBBBBE -DCCCBBBBBBCCCD- ACCCCCCCCBBBBBBA AAAEAAAAAAAAEAAA ---------------- ---------------- ---------------- ---------------- 
--D--E----E--D-- -ABAABAAAABAABA- EBBCCAAAAAABBBBE -DBCCAAAAAACCBD- ACCCCAAAAAABBBBA -DCCCAAAAAABBBD- ACCCCAAAAAABBBBA -DCCCAAAAAACCCD- ACCCCAAAAAABBBBA AAAEAAAAAAAAEAAA ---------------- ---------------- ---------------- ---------------- 
DDDDDEEEEEEDDDDD EBBBAAAAAAAAAABE ABBBA------AAABA ABBBA------AAABA ECCCA------AAABE ACCCA------AAABA ACCCA------AAABA ACCCA------AAABA ACCCA------AAABA AAAEA------AEAAA ---------------- ---------------- ---------------- ---------------- 
--D--E----E--D-- -ABAAAAAAAAAAAA- ABBA--------AABA ECBA--------AABE ACCA--------AABA ACCA--------AABA ACCA--------AABA ACCA--------AABA ACCA--------AABA ACAE--------EABA -E------------E- -E------------E- -E------------E- -E------------E- 
DDDDDEEEEEEDDDDD ABAAAAAAAAAAAABA EBA----------ABE ABA----------ABA ACA----------ABA ACA----------ABA ACA----------ABA ACA----------ABA ACA----------ABA ACA----------ABA -E------------A- -A------------A- -A------------A- -E------------A- 
--D--E-EE-E--D-- -AAAAAAAAAAAAAA- AA------------AA AA------------AA AA------------AA AA------------AA AA------------AA AA------------AA AA------------AA AA------------AA -E------------E- -E------------E- -E------------E- -E------------E- 
DDDDDE----EDDDDD AAAAAAAAAAAAAABA AA------------BA -D------------D- -D------------D- -D------------D- -D------------D- -D------------D- AA------------AA AA------------AA -E------------A- -A------------A- -A------------A- -E------------A- 
--D--EE--EE--D-- -AAAAAAAAAAAAAA- AA------------AA AA------------AA AA------------AA AA------------AA AA------------AA AA------------AA AA------------AA AA------------AA -E------------E- -E------------E- -E------------E- -E------------E- 
DDDDDDEEEEDDDDDD AAAAAAAAAAAAAABA AA------------AA -D------------D- -D------------D- -D------------D- -D------------D- -D------------D- AA------------AA AA------------AA -E------------A- -A------------A- -A------------A- -E------------A- 
--D---E--E---D-- -AAAAAAAAAAAAAA- AA------------AA AA------------AA AA------------AA AA------------AA AA------------AA AA------------AA AA------------AA AA------------AA -E------------E- -E------------E- -E------------E- -E------------E- 
DDDDD--DD--DDDDD AABAAAAAAAAAAABA AAA----------ABA -DA----------AD- -DA----------AD- -DA----------AD- -DA----------AD- -DA----------AD- AAA----------ABA AAA----------ABA -E------------A- -A------------A- -A------------A- -E------------A- 
-DDDDDDDDDDDDDD- -ABAAAAAAAAAAAA- AABAAAAAAAAAAABA ABBAAAEEEEAAAABA ACCAAAEAAEAAAABA ACCAAAEAAEAAAABA ACCAAAEAAEAAAABA ACCAAAEAAEAAAABA ACCBAAEAAEAAAABA ACAAAAAAAAAAAABA -E------------E- -E------------E- -E------------E- -E------------E- 
D-D-D-DDDD-D-D-D A-A-A-AAAA-A-A-A AAAAAFFFFFFAAAAA AAAAAF----FAAAAA AAAAAF-AA-FAAAAA AAAAAF-AA-FAAAAA AAAAAF-AA-FAAAAA AAAAAF-AA-FAAAAA AAAAAF-AA-FAAAAA AAAAAAAAAAAAAAAA ---------------- ---------------- ---------------- ---------------- 
