model
size = 16 14 31, scale = 0.05, origin = -y
material 
  colors = A:#FF0 B:#9CF C:#111 D:#E00 E:#EEE
voxels
-----EEEEEE----- -----EEEEEE----- ---------------- ---------------- -----EEEEEE----- -----EEEEEE----- ---------------- ---------------- ---------------- ---------------- ---------------- ---------------- ---------------- ---------------- 
----CCCCCCCC---- ----AAAAAAAA---- ----AAAAAAAA---- ----AAAAAAAA---- ----AAAAAAAA---- -----AAAAAA----- ---------------- ---------------- ---------------- ---------------- ---------------- ---------------- ---------------- ---------------- 
----CCCCCCCC---- ----AAAAAAAA---- ----AAAAAAAA---- ----AAAAAAAA---- ----AAAAAAAA---- ----AAAAAAAA---- ---------------- ---------------- ---------------- ---------------- ---------------- ---------------- ---------------- ---------------- 
---C-C-CC-C-C--- ---DAAAAAAAAD--- ---DAAAAAAABD--- ---DAAAAAAABD--- ---DACCCCCCAD--- ----A------A---- ---------------- ---------------- ---------------- ---------------- ---------------- ---------------- ---------------- ---------------- 
--C--C----C--C-- --AAAAAAAAAAAA-- --AAAAAAAAABAA-- --AAAAAAAAABAA-- --AAAAAAAAAAAA-- ---AAAAAAAAAA--- ---------------- ---------------- ---------------- ---------------- ---------------- ---------------- ---------------- ---------------- 
---CCCCCCCCCC--- ---AAAAAAAAAA--- --AAAAAAAAAAAA-- --AAAAAAAAAAAA-- --AAACCCCCCAAA-- ---AA------AA--- ---------------- ---------------- ---------------- ---------------- ---------------- ---------------- ---------------- ---------------- 
-CC--C----C--CC- -DAAAAAAAAAAAAD- -DAAAAAAAAABABD- -DAAAAAAAAABABD- -DAAAAAAAAAAAAD- --AAAAAAAAAAAA-- ---------------- ---------------- ---------------- ---------------- ---------------- ---------------- ---------------- ---------------- 
--CC-C-DD-C-CC-- --AAAAAAAAAAAA-- -AAAAAAAAAABABA- -AAAAAAAAAABABA- -AAAACCCCCCAAAA- --AAA------AAA-- ---------------- ---------------- ---------------- ---------------- ---------------- ---------------- ---------------- ---------------- 
CCCCCCDDDDCCCCCC AAAAAAAAAAAAAAAA AAAAAAAAAAAAAAAA AAAAAAAAAAAAAAAA AAAAAAAAAAAAAAAA -ADDDAADDAADDDA- ---------------- ---------------- ---------------- ---------------- ---------------- ---------------- ---------------- ---------------- 
--C---D--D---C-- -AAAAAAAAAAAAAA- AAAAAAAAAAAAAAAA AAAAAAAAAAAAAAAA AAAAAAAAAAAAAAAA -AAAAAAAAAAAAAA- ---AC------CA--- ---------------- ---------------- ---------------- ---------------- ---------------- ---------------- ---------------- 
CCCCCDDDDDDCCCCC AAAAAAAAAAAAAAAA AAAAAAAAAAAAAAAA AAAAAAAAAAAAAAAA AAAAAAAAAAAAAAAA AAAAAAAAAAAAAAAA ---AC------CA--- ---------------- ---------------- ---------------- ---------------- ---------------- ---------------- ---------------- 
--C-CD----DC-C-- -AAAAAAAAAAAAAA- AAABAABBBAAAAAAA AAABAABBBAAAAAAA ABBBBBBBBBBAAAAA ABBBBBBBBBBAAAAA DDDBCDDDDDDCADDD ---DC------CD--- ---------------- ---------------- ---------------- ---------------- ---------------- ---------------- 
CCCCCDDDDDDCCCCC AAAAAAAAAAAAAAAA AAAAAAAAAAAAAAAA AAAAAAAAAAAAAAAA ABBBBBBBBBBAAAAA DBBBBBBBBBBAAAAD ABBBCBBBBBBCAAAA AAABCAAAAAACAAAA ---AC------CA--- ---------------- ---------------- ---------------- ---------------- ---------------- 
--C--D----D--C-- -AAAAAAAAAAAAAA- AAAAAABBBAAAAAAA AAAAAABBBAAAAAAA DBBBBBBBBBBAAAAD ABBBBBBBBBBAAAAA ABBBCBBBBBBCAAAA ABBBCAAAAAACAAAA DDDBCDDDDDDCADDD ---DC------CD--- ---------------- ---------------- ---------------- ---------------- 
CCCCCDDDDDDCCCCC AAAAAAAAAAAAAAAA AAAAAAAAAAAAAAAA DAAAAAAAAAAAAAAD ABBBBBBBBBBAAAAA AABBBBBBBBBAAAAA ABBBBBBBBBBAAAAA DABBBAAAAAAAAAAD ABBBBBBBBAAAAAAA AAADAAAAAAAADAAA ---------------- ---------------- ---------------- ---------------- 
--C--D----D--C-- -AAAAAAAAAAAAAA- DAABBABBBAAAAAAD AAABBABBBAAAAAAA ABBBBBBBBBBAAAAA AABBBBBBBBBAAAAA DBBBBBBBBBBAAAAD AABBBAAAAAAAAAAA ABBBBBBBBAAAAAAA DDDDADDDDDDADDDD ---------------- ---------------- ---------------- ---------------- 
CCCCCDDDDDDCCCCC DAAAAAAAAAAAAAAD AAAAAAAAAAAAAAAA -CAAAAAAAAAAAAC- ABBBBBBBBBBAAAAA -CBBBBBBBBBAAAC- ABBBBBBBBBBAAAAA -CBBBAAAAAABBBC- DBBBBBBBBAAAAAAD AAADAAAAAAAADAAA ---------------- ---------------- ---------------- ---------------- 
--C--D----D--C-- -AAAAAAAAAAAAAA- AAABBABBBAAAAAAA -CABBABBBBBBABC- DBBBBBBBBBBAAAAD -CBBBBBBBBBAAAC- ABBBBBBBBBBAAAAA -CBBBAAAAAABBBC- ABBBBBBBBAAAAAAA AAADAAAAAAAADAAA ---------------- ---------------- ---------------- ---------------- 
CCCCCDDDDDDCCCCC AAAAAAAAAAAAAAAA AAAAAAAAAAAAAAAA -CAAAAAAAAAAAAC- ABBBBBBBBBBAAAAA -CBBBBBBBBBAAAC- DBBBBBBBBBBAAAAD -CBBBAAAAAABBBC- ABBBBBBBBAAAAAAA AAADAAAAAAAADAAA ---------------- ---------------- ---------------- ---------------- 
--C--D----D--C-- -AAAAAAAAAAAAAA- DAABBAAAAAAAAAAD -CABBAAAAAABBAC- ABBBBAAAAAAAAAAA -CBBBAAAAAAAAAC- ABBBBAAAAAAAAAAA -CBBBAAAAAABBBC- ABBBBBAAAAAAAAAA AAADAAAAAAAADAAA ---------------- ---------------- ---------------- ---------------- 
CCCCCDDDDDDCCCCC DAAAAAAAAAAAAAAD AAAAA------AAAAA AAAAA------AAAAA DBBBA------AAAAD ABBBA------AAAAA ABBBA------AAAAA ABBBA------AAAAA ABBBA------AAAAA AAADA------ADAAA ---------------- ---------------- ---------------- ---------------- 
--C--D----D--C-- -AAAAAAAAAAAAAA- AAAA--------AAAA DBAA--------AAAD ABBA--------AAAA ABBA--------AAAA ABBA--------AAAA ABBA--------AAAA ABBA--------AAAA ABAD--------DAAA -D------------D- -D------------D- -D------------D- -D------------D- 
CCCCCDDDDDDCCCCC AAAAAAAAAAAAAAAA DAA----------AAD AAA----------AAA ABA----------AAA ABA----------AAA ABA----------AAA ABA----------AAA ABA----------AAA ABA----------AAA -D------------A- -A------------A- -A------------A- -A------------D- 
--C--D-DD-D--C-- -AAAAAAAAAAAAAA- AA------------AA AA------------AA AA------------AA AA------------AA AA------------AA AA------------AA AA------------AA AA------------AA -D------------D- -D------------D- -D------------D- -D------------D- 
CCCCCD----DCCCCC AAAAAAAAAAAAAAAA AA------------AA -C------------C- -C------------C- -C------------C- -C------------C- -C------------C- AA------------AA AA------------AA -D------------A- -A------------A- -A------------A- -A------------D- 
--C--DD--DD--C-- -AAAAAAAAAAAAAA- AA------------AA AA------------AA AA------------AA AA------------AA AA------------AA AA------------AA AA------------AA AA------------AA -D------------D- -D------------D- -D------------D- -D------------D- 
CCCCCCDDDDCCCCCC AAAAAAAAAAAAAAAA AA------------AA -C------------C- -C------------C- -C------------C- -C------------C- -C------------C- AA------------AA AA------------AA -D------------A- -A------------A- -A------------A- -A------------D- 
--C---D--D---C-- -AAAAAAAAAAAAAA- AA------------AA AA------------AA AA------------AA AA------------AA AA------------AA AA------------AA AA------------AA AA------------AA -D------------D- -D------------D- -D------------D- -D------------D- 
CCCCC--CC--CCCCC AAAAAAAAAAAAAAAA AAA----------AAA -CA----------AC- -CA----------AC- -CA----------AC- -CA----------AC- -CA----------AC- AAA----------AAA ABA----------AAA -D------------A- -A------------A- -A------------A- -A------------D- 
-CCCCCCCCCCCCCC- -AAAAAAAAAAAAAA- AAAAAAAAAAAAAAAA AAAAAADDDDAAAAAA ABBAAADAADAAAAAA ABBAAADAADAAAAAA ABBAAADAADAAAAAA ABBAAADAADAAAAAA ABBAAADAADAAAAAA ABAAAAAAAAAAAAAA -D------------D- -D------------D- -D------------D- -D------------D- 
C-C-C-CCCC-C-C-C A-A-A-AAAA-A-A-A AAAAAEEEEEEAAAAA AAAAAE----EAAAAA AAAAAE-AA-EAAAAA AAAAAE-AA-EAAAAA AAAAAE-AA-EAAAAA AAAAAE-AA-EAAAAA AAAAAE-AA-EAAAAA AAAAAAAAAAAAAAAA ---------------- ---------------- ---------------- ---------------- 
