model
size = 32, scale = 0.05, origin = -y
material 
  colors = A:#FFDBB1 B:#B3997C C:#FFF D:#E3E3E3 E:#EFEFEF F:#7787FF G:#000 H:#F7F7F7 I:#D3D3D3 J:#CFCFCF K:#0008FF L:#878787 M:#AFAFAF N:#F00 O:#8F8F8F P:#78FF00 Q:#C2C9FF R:#505050 S:#747474 T:#CBCBCB
voxels
121-4A28-4A138-18C13-3C7G10C11-4C2(G2C)G11C10-4CG2CG3CG2CGMGCG3C10-4CG2CM4(GC)M2G3C10-3CG5CGC2G9C10-3CG5CR6L2F4C10-3CGCG3CS6C2F4C10-3CG2C2GCTG5C2F4C10-4CGMCFGCG5C2F4C10-5CGCFC2G7F4C10-6CG2(11F4C10-7C)2F6J3F4C10-7C2F4JFJ2FQ4C10-7C2F4JFJFQ5C11-20C13-18C232-30A-3A2P60A2(30B2A)2B26-2B2A2B3-20E3-2B2A2B2-2E18A2E2-2B2A2B-2E20A2E14(-2B2A2B-E22AE)-2B2A2B-2E20A2E-2B2A2B2-2E18A2E2-2B2A2B3-20E3-2B2A2B26-2B2(2A30B)A-30A65-131A2I22A2I5AI2-22D2-I4AI-2D20A2D-I5A2D22A2D16(6AD24AD)6A2D22A2D5AI-2D20A2D-I4AI2-22D2-I5A2I22A2I67A64-163A2I22A2I6AI24AI582AI24AI6A2I22A2I99A4(2-28A4-28A2-960A)2-11A5-12A4-28A3-29(30A2-)30A3-9A7-12A4-28A3-29(30A2-)30A3-8A8-12A4-28A3-29(30A2-)30A3-8A4-4A5-7A4-28A3-28(30A2-)30A3-28A4-7A4-5A4-8A4-28A3-25(30A2-)30A4-2(26A6-)26A7-24A6-7A3-6A3-9A4-28A3-25(30A2-)30A4-2(26A6-)26A7-24A6-7A3-18A4-28A3-24(30A2-)30A3-28A5-2(26A6-)26A8-22A7-7A3-6A3-9A4-28A3-24(30A2-)30A3-28A5-26A6-26A7-24A9-22A7-7A4-5A4-8A4-28A3-24(30A2-)30A4-26A6-26A7-11(AB)2A8-11(A-)2A38-8A4-4A5-7A4-28A3-23(30A2-)30A3-28A5-26A7-11(AB)2A8-11(A-)2A70-8A8-12A4-28A3-23(30A2-)30A3-28A6-11(AB)2A8-11(A-)2A102-9A7-12A4-28A3-23(30A2-)30A4-2A10(BA)B3A7-11(A-)2A134-11A5-12A4-28A3-22(30A2-)30A3-3A10(BA)B4A6-11(A-)2A166-2(28A4-28A3-6(30A2-)4(30A3-B26AB3-)8(30A2-)30A3-28A196-)28A4-28A3-6(30A2-)4(30A3-B26AB3-)8(30A2-)30A4-26A197-28A4-28A3-6(30A2-)4(30A3-B26AB3-)7(30A2-)4A10(BA)B5A3-3A10(-A)-4A228-28A4-28A3-6(30A2-)4(30A4-B24AB4-)7(30A2-)4A10(BA)B5A4-2A10(-A)-3A293-6(28A4-)4(28A6-B22AB6-)7(28A4-)3A10(BA)B4A6-11(A-)2A294-6(28A4-)4(28A6-B22AB6-)6(28A4-)3A10(BA)B4A5-2A10(-A)-3A326-26A5-5(28A4-)4(28A6-B22AB6-)6(28A4-)3A10(BA)B4A5-2A10(-A)-3A357-5(28A4-)28A5-B24AB5-2(28A6-B22AB6-)28A5-B24AB5-6(28A4-)3A10(BA)B4A6-11(A-)2A359-26A5-3(28A4-)5A2(2B2A)2B4A3B6A4-5A2(2B2A)2B3A2(BA)B5A5-B16A5B3A3(B5-28A5-B24A)B5-5(3A10(BA)B4A4-)3A10(BA)B4A5-2A10(-A)-3A421-3(28A4-)5A2(2-2A)2-4A3-6A4-5A2(2-2A)2-3A2(-O)-5A6-16A5-3A6-12A7H9A6-10A3H2K2H7A6-12AH2N2HKH9A6-10AH2K2HKH7A6-12A3H2K2H9A6-10A7H7A6-5(3A10(-A)-4A4-)28A6-11(A-)2A292-
