model
size = 32 32 3, scale = 0.05, origin = -y
material 
  colors = A:#005CAF B:#EEE
voxels
9-13A17-18A13-10A2-8A10-5A4-4A2-8A8-5A6-4A2-3A-5A6-4A8-4A2-2A2-4A5-4A10-4A-3A-5A3-4A13-2(2A2-)5A2-4A10-2A2-2(A3-)4A-4A9-5A10-8A8-7A10-7A7-4A2B3A10-5A7-4A4B3A9-4A7-4A2B2A2B3A8-4A7-3A2B4AB4A7-4A6-4AB12A5-2A7-5AB12A7-2A4-6A2B4AB7A4-4A4-7A2B2A2B7A4-4A4-8A4B8A4-5A4-8A2B8A5-5A4-18A4-3A-3A4-7A-8A4-3A2-3A5-5A3-6A4-4A2-4A21-4A4-4A2-2A3-2A10-5A5-4A-2A3-3A8-5A7-7A3-3A5-6A9-7A2-4A2-7A11-20A14-16A18-12A19-13A17-2A13B3A13-A18BA10-2A20BA8-A23B2A6-A24BA5-A26BA3-A28BA2-A28BA-A2(30B2A)14B2-14B2A13B4-13B2A12B-3B2-12B2A12B-4B-12B2A11BA18BA12BA19BA11BA-4B-12B2A12B2-2B2-12B2A13B4-13B2A14B2-14B2A30BA-2(A28BA2-)A27BA4-A26BA5-A24BA7-A22BA9-A20BA11-2A16B2A14-2A12B2A18-12A19-13A17-18A13-20A10-23A8-26A6-26A5-28A3-30A2-30A-416A-2(30A2-)29A4-28A5-26A7-24A9-22A11-20A14-16A18-12A10-
