model
size = 12 19 32, scale = 0.05, origin = -y
material 
  colors = A:#FEED3F B:#004 C:#FFF59C D:#005 E:#007 F:#008 G:#002 H:#00A I:#00B J:#00D K:#00E L:#FFED5B M:#FDD736 N:#FFF691 O:#FAC12C P:#FAA821 Q:#F4801D R:#EEE S:#001 T:#9CF
voxels
3-5C7-5A7-5G198-2C4AC5-A5RA2(5-G)6-5B186-2(CA)C2AC4-A6CA4-G5-2G4-7B184-4(CA)C3-A7CA3-2G6-G3-2B6-B5-6B172-C2ACAC2AC3-A7CA3-G7-G3-B7-B3-9B171-3(CA)C2AC2-A8CA2-G7-2G2-B7-2B2-2B5-3B4-6D160-C2A3(CA)C2-A8NA2-G8-G2(2-B8-B)2-9D158-C2A2(CA)C2AC-A9NA-2G8-G2(2-B8-B)2-10D157-5(CA)C-A9NA-G9-G-2B8-B2-B8-B2-2D5-3D4-6D147-C2A2(CA)C2AC-A9NA-G9-G2(-2B8-B)2-D8-D3-8D146-5(CA)C-A9LA-G9-G2(-2B8-B)2-D8-D2-10D145-C2A2(CA)C3ACA10LAG10-G2B8-B2-B8-B2-D8-D2-2(3D4-)6E135-4(CA)2(C2A)9LA2G9-G-B8-2B-B8-B2(2-D8-D)3-8E135-5(CA)C-A9LA-G9-G-B8-2B-B8-B2(2-D8-D)2-2E6C2E134-C2A2(CA)C2AC-11A-G9-G-B8-2B-B8-B2(2-D8-D)2-E8-E3-E6NE123-5(CA)C-11A-G9-G2(-B8-2B)-2(D8-D2-)E8-E2-E8-E3-F6LF111-C2A2(CA)C2AC-11A-G9-G2(-B8-2B)-D8-2D-D8-D2(2-E8-E)2-F8-F3-F6AF99-5(CA)C-11A-G8-2G2(-B8-2B)2(-D8-2D)-E8-2E-E8-E2(2-F8-F)3-H6MH87-C2A2(CA)C2AC-A9MA-G8-2G2(-B8-2B)2(-D8-2D)2(-E8-2E)-F8-2F-F8-F2-H8-H3-H6O2H3-I6OI63-5(CA)C-A9MA-G8-2G2(-B8-2B)2(-D8-2D)2(-E8-2E)2(-F8-2F)-2(H8-H2-)I8-I3-I6PI4-J6PJ39-C2A2(CA)C2AC-A8MJA-G8-2G2(-B8-2B)2(-D8-2D)2(-E8-2E)2(-F8-2F)-H8-2H-H8-H2(2-I8-I)2-J7-GJ3-J6QJ4-K6QK14-2C5(AC)A10MA3G7-2G2(-2B7-2B)2(-2D7-2D)-2E7-EA-2E7-2E-2F7-FN-2F7-2F2(-2H7-2H)-2(2I7-I2-)2J7-J2-JTJ5-2J2(3-2K5-2K)-4(CA)C2ACA4O3H3OA3G7-2G3B7-2B-2B7-2B2(-2D7-2D)-2E7-2E-2E7-EL2(-2F7-2F)2(-2H7-2H)-2I7-2I-2I7-I2(2-2J7-J)2(3-K7-K)-C2A5(CA)3(2OF)OA3G7-2G3B7-BQ3B7-2B3D7-2D-2D7-2D2(-2E7-2E)-2F7-2F-LF7-FC2(-2H7-2H)-2I7-2I-2I7-I2(2-2J7-J)2(3-K7-K)-4(CA)C2ACA3O2(EO)E2OA3G7-2G3B7-BQ3B7-BP3D7-DO-2D7-DM-2E7-EA-2E7-EL-2F7-FN-2F7-FC2(-AH7-2H)-2I7-2I-2I7-I2(2-2J7-J)2(3-K7-K)-C2A5(CA)3(2OD)OA3G7-2G3B7-BQ3B7-2B2(-2D7-2D)2(-2E7-2E)-2F7-2F-2F7-FC-AH7-2H-MH7-2H-2I7-2I-2I7-I2-2J7-J3-J7-J2(3-K7-K)-4(CA)C2ACA5PB4PA3G7-2G3B7-2B-2B7-2B2(-2D7-2D)-2E7-2E-2E7-EL2(-2F7-2F)2(-2H7-2H)-MI7-I2-2I7-I2-2J7-J3-J7-J2(3-K7-K)2-3(CA)C3AC-A4PG4PA-2G7-2G2(-2B7-2B)2(-2D7-2D)-2E7-EA-2E7-2E-2F7-FN-2F7-2F2(-2H7-2H)-2I7-I2-OI7-I2(3-J7-J)2(3-K7-K)2-C2A3(CA)C2-A3P3S2PA2-3G5-2G2(2-3B5-2B)2(2-3D5-2D)2(2-3E5-2E)2(2-3F5-2F)2(2-3H5-2H)2-3I5-2I3-2I5-2I3-OJ5-2J3-2J5-2J2(3-2K5-2K)3-C2ACAC2AC3-A7QA2(3-3G)4(3-3B)3(3-3D)3-DTD4(3-3E)4(3-3F)4(3-3H)4-2(2I3-2I5-)PJ3-2J5-JK3-KJ5-2K3-2K2(5-K)5-C5AC5-3(AQ)A5-7G2(5-7B)5-A5DA5-DM3DMD5-O5EO5-7E2(5-7F)5-7H6-5H2(7-5I)7-P4J7-P3QJ7-K3-K19-5C7-5A7-5G8-3N10-L11-A11-M11-O10-3P93-3Q28-
