model
size = 19 19 28, scale = 0.05, origin = -y
material 
  colors = A:#EEE B:#00A C:#E00 D:#F63 E:#555 F:#008
voxels
BBBBBBBBBBBBBBBBBBB BAAAAAAAAAAAAAAAAAB BAAAAAAAAAAAAAAAAAB BAAAAAAAAAAAAAAAAAB BAAAAAAAAAAAAAAAAAB BAAAAAAAAAAAAAAAAAB BAAAAAAAAAAAAAAAAAB BBBBBBBBBBBBBBBBBBB ------------------- ------------------- ------------------- ------------------- ------------------- ------------------- ------------------- ------------------- ------------------- ------------------- ------------------- 
BAAAAAAAAAAAAAAAAAB BAAAAAAAAAAAAAAAAAB BAAAAAAAAAAAAAAAAAB BAAAAAAAAAAAAAAAAAB BAAAAAAAAAAAAAAAAAB BAAAAAAAAAAAAAAAAAB BAAAAAAAAAAAAAAAAAB BACCCCCCAACCCAAACCB ------------------- ------------------- ------------------- ------------------- ------------------- ------------------- ------------------- ------------------- ------------------- ------------------- ------------------- 
BAAAAAAAAAAAAAAAAAB BAAAAAAAAAAAAAAAAAB BAAAAAAAAAAAAAAAAAB BAAAAAAAAAAAAAAAAAB BAAAAAAAAAAAAAAAAAB BAAAAAAAAAAAAAAAAAB BAAAAAAAAAAAAAAAAAB BAAACCCCAACCCAAACCB BACCCCCCAACCCAACCCB ------------------- ------------------- ------------------- ------------------- ------------------- ------------------- ------------------- ------------------- ------------------- ------------------- 
------------------- BAAAAAAAAAAAAAAAAAB BAAAAAAAAAAAAAAAAAB BAAAAAAAAAAAAAAAAAB BAAAAAAAAAAAAAAAAAB BAAAAAAAAAAAAAAAAAB BAAAAAAAAAAAAAAAAAB BAAAAAAAAACCCACCCCB BACCCAAAAACCCCCCCAB ------------------- ------------------- ------------------- ------------------- ------------------- ------------------- ------------------- ------------------- ------------------- ------------------- 
------------------- BAAAAAAAAAAAAAAAAAB BAAAAAAAAAAAAAAAAAB BAAAAAAAAAAAAAAAAAB BAAAAAAAAAAAAAAAAAB BAAAAAAAAAAAAAAAAAB BAAAAAAAAAAAAAAAAAB BAAAAAAAAACCCAAAAAB BACCCAAAAACCCAAAAAB BACCCAAAAACCCCCAAAB ------------------- ------------------- ------------------- ------------------- ------------------- ------------------- ------------------- ------------------- ------------------- 
------------------- BAAAAAAAAAAAAAAAAAB BAAAAAAAAAAAAAAAAAB BAAAAAAAAAAAAAAAAAB BAAAAAAAAAAAAAAAAAB BAAAAAAAAAAAAAAAAAB BAAAAAAAAAAAAAAAAAB BAAAAAAAAACCCAAAAAB BACCCAAAAACCCAAAAAB BACCCCCCAACCCCCCCAB ------------------- ------------------- ------------------- ------------------- ------------------- ------------------- ------------------- ------------------- ------------------- 
------------------- ------------------- BAAAAAAAAAAAAAAAAAB BAAAAAAAAAAAAAAAAAB BAAAAAAAAAAAAAAAAAB BAAAAAAAAAAAAAAAAAB BAAAAAAAAAAAAAAAAAB BAAAAAAAAACCCAAAAAB BACCCAAAAACCCAAAAAB BACCCCCCAACCCAAACCB ------------------- ------------------- ------------------- ------------------- ------------------- ------------------- ------------------- ------------------- ------------------- 
------------------- ------------------- BAAAAAAAAAAAAAAAAAB BAAAAAAAAAAAAAAAAAB BAAAAAAAAAAAAAAAAAB BAAAAAAAAAAAAAAAAAB BAAAAAAAAAAAAAAAAAB BAAAAAAAAACCCAAAAAB BACCCAAAAACCCAAAAAB BACCCAAAAACCCAAACCB BACCCAAAAACCCAAACCB ------------------- ------------------- ------------------- ------------------- ------------------- ------------------- ------------------- ------------------- 
------------------- ------------------- BAAAAAAAAAAAAAAAAAB BAAAAAAAAAAAAAAAAAB BAAAAAAAAAAAAAAAAAB BAAAAAAAAAAAAAAAAAB BAAAAAAAAAAAAAAAAAB BAAAAAAAAACCCAAAAAB BACCCAAAAACCCAAAAAB BACCCAAAAACCCAAACCB BACCCAAAAACCCAAACCB ------------------- ------------------- ------------------- ------------------- ------------------- ------------------- ------------------- ------------------- 
------------------- ------------------- ------------------- BAAAAAAAAAAAAAAAAAB BAAAAAAAAAAAAAAAAAB BAAAAAAAAAAAAAAAAAB BAAAAAAAAAAAAAAAAAB BAAAAAAAAACCCAAAAAB BACCCAAAAACCCAAAAAB BACCCAAAAACCCAAAAAB BACCCCCCAACCCCCCCAB ------------------- ------------------- ------------------- ------------------- ------------------- ------------------- ------------------- ------------------- 
------------------- ------------------- ------------------- BAAAAAAAAAAAAAAAAAB BAAAAAAAAAAAAAAAAAB BAAAAAAAAAAAAAAAAAB BAAAAAAAAAAAAAAAAAB BAAAAAAAAACCCAAAAAB BACCCAAAAACCCAAAAAB BACCCAAAAACCCAAAAAB BACCCCCCAACCCCCCAAB BACCCCCCAACCCCCCAAB ------------------- ------------------- ------------------- ------------------- ------------------- ------------------- ------------------- 
------------------- ------------------- ------------------- BAAAAAAAAAAAAAAAAAB BAAAAAAAAAAAAAAAAAB BAAAAAAAAAAAAAAAAAB BAAAAAAAAAAAAAAAAAB BAAAAAAAAAAAAAAAAAB BAAAAAAAAAAAAAAAAAB BAAAAAAAAAAAAAAAAAB BAAAAAAAAAAAAAAAAAB BAAAAAAAAAAAAAAAAAB ------------------- ------------------- ------------------- ------------------- ------------------- ------------------- ------------------- 
------------------- ------------------- ------------------- ------------------- BAAAAAAAAAAAAAAAAAB BAAAAAAAAAAAAAAAAAB BAAAAAAAAAAAAAAAAAB BAAAAAAAAAAAAAAAAAB BAAAAAAAAAAAAAAAAAB BAAAAAAAAAAAAAAAAAB BAAAAAAAAAAAAAAAAAB BAAAAAAAAAAAAAAAAAB ------------------- ------------------- ------------------- ------------------- ------------------- ------------------- ------------------- 
------------------- ------------------- ------------------- ------------------- BAAAAAAAAAAAAAAAAAB BAAAAAAAAAAAAAAAAAB BAAAAAAAAAAAAAAAAAB BAAAAAAAAAAAAAAAAAB BAAAAAAAAAAAAAAAAAB BAAAAAAAAAAAAAAAAAB BAAAAAAAAAAAAAAAAAB BAAAAAAAAAAAAAAAAAB BAAAAAAAAAAAAAAAAAB ------------------- ------------------- ------------------- ------------------- ------------------- ------------------- 
------------------- ------------------- ------------------- ------------------- BAAAAAAAAAAAAAAAAAB BAAAAAAAAAAAAAAAAAB BAAAAAAAAAAAAAAAAAB BAAAAAAAAAAAAAAAAAB BAAAAAAAAAAAAAAAAAB BAAAAAAAAAAAAAAAAAB BAAAAAAAAAAAAAAAAAB BAAAAAAAAAAAAAAAAAB BAAAAAAAAAAAAAAAAAB ------------------- ------------------- ------------------- ------------------- ------------------- ------------------- 
------------------- ------------------- ------------------- ------------------- ------------------- BAAAAAAAAAAAAAAAAAB BAAAAAAAAAAAAAAAAAB BAAAAAAAAAAAAAAAAAB BAAAAAAAAAAAAAAAAAB BAAAAAAAAAAAAAAAAAB BAAAAAAAAAAAAAAAAAB BAAAAAAAAAAAAAAAAAB BFFFFFFFFFFFFFFFFFB ------------------- ------------------- ------------------- ------------------- ------------------- ------------------- 
------------------- ------------------- ------------------- ------------------- ------------------- BAAAAAAAAAAAAAAAAAB BAAAAAAAAAAAAAAAAAB BAAAAAAAAAAAAAAAAAB BAAAAAAAAAAAAAAAAAB BAAAAAAAAAAAAAAAAAB BAAAAAAAAAAAAAAAAAB BAAAAAAAAAAAAAAAAAB BAAEAAEAAEAAEAAEAAB -DD-AA-DD-DD-DD-DD- ------------------- ------------------- ------------------- ------------------- ------------------- 
------------------- ------------------- ------------------- ------------------- BAAAAAAAAAAAAAAAAAB BAAAAAAAAAAAAAAAAAB BAAAAAAAAAAAAAAAAAB BAAAAAAAAAAAAAAAAAB BAAAAAAAAAAAAAAAAAB BAAAAAAAAAAAAAAAAAB BAAAAAAAAAAAAAAAAAB BAAAAAAAAAAAAAAAAAB BAAEAAEAAEAAEAAEAAB -DD-AA-DD-DD-DD-DD- ----AA------------- ------------------- ------------------- ------------------- ------------------- 
------------------- ------------------- ------------------- BAAAAAAAAAAAAAAAAAB BAAAAAAAAAAAAAAAAAB BAAAAAAAAAAAAAAAAAB BAAAAAAAAAAAAAAAAAB BAAAAAAAAAAAAAAAAAB BAAAAAAAAAAAAAAAAAB BAAAAAAAAAAAAAAAAAB BAAAAAAAAAAAAAAAAAB BAAAAAAAAAAAAAAAAAB BAAEAAEAAEAAEAAEAAB -DD-AA-DD-DD-DD-DD- ----AA------------- ----AA------------- ------------------- ------------------- ------------------- 
------------------- ------------------- BAAAAAAAAAAAAAAAAAB BAAAAAAAAAAAAAAAAAB BAAAAAAAAAAAAAAAAAB BAAAAAAAAAAAAAAAAAB BADDADDADDADDADDADB BADDADDADDADDADDADB BADEDDEDDEDDEDDEDDB BADEDDEDDEDDEDDEDDB BADDEDDEDDEDDEDDEDB BADDEDDEDDEDDEDDEDB BADEDDEDDEDDEDDEDDB -DD-AA-DD-DD-DD-DD- ----AA------------- ----DD------------- ----DD------------- ------------------- ------------------- 
------------------- BAAAAAAAAAAAAAAAAAB BAAAAAAAAAAAAAAAAAB BA----------------B BA----------------B BA----------------B ------------------B ------------------B ------------------B ------------------- ------------------- ------------------- ------------------- ------------------- ------------------- ----DD------------- ----DD------------- ----DD------------- ------------------- 
------------------- BAAAAAAAAAAAAAAAAAB BAAAAAAAAAAAAAAAAAB BA----------------B BA----------------B BA----------------B ------------------B ------------------B ------------------B ------------------- ------------------- ------------------- ------------------- ------------------- ------------------- ----DD------------- ----DD------------- ----DD------------- ----DD------------- 
BAAAAAAAAAAAAAAAAAB BAAAAAAAAAAAAAAAAAB BAAAAAAAAAAAAAAAAAB BAAAAAAAAAAAAAAAAAB BAAAAAAAAAAAAAAAAAB BAA---------------B BAA---------------B BAA---------------B BAA---------------B BAA---------------B BAA---------------B BAA---------------B BAA---------------B BAA---------------B BAA---------------B BAAAAAAAAAAAAAAAAAB ------------------- ----DD------------- ----DD------------- 
------------------- BAAAAAAAAAAAAAAAAAB BAAAAAAAAAAAAAAAAAB BAAAAAAAAAAAAAAAAAB BAAAAAAAAAAAAAAAAAB BAA---------------B BAA---------------B BAA---------------B BAA---------------B BAA---------------B BAA---------------B BAA---------------B BAA---------------B BAA---------------B BAA---------------B BACCACACACAACAACCAB ------------------- ------------------- ------------------- 
------------------- ------------------- ------------------- BAAAAAAAAAAAAAAAAAB BAAAAAAAAAAAAAAAAAB BAA---------------B BAA---------------B BAA---------------B BAA---------------B BAA---------------B BAA---------------B BAA---------------B BAA---------------B BAA---------------B BAA---------------B BCAAACCCACACCACAAAB ------------------- ------------------- ------------------- 
------------------- ------------------- ------------------- ------------------- ------------------- BAAAAAAAAAAAAAAAAAB BAAAAAAAAAAAAAAAAAB BAAAAAAAAAAAAAAAAAB BAAAAAAAAAAAAAAAAAB BAAAAAAAAAAAAAAAAAB BA----------------B BA----------------B BA----------------B BA----------------B BA----------------B BCAAACACACCACACAAAB ------------------- ------------------- ------------------- 
------------------- ------------------- ------------------- ------------------- ------------------- ------------------- BAAAAAAAAAAAAAAAAAB BAAAAAAAAAAAAAAAAAB BAAAAAAAAAAAAAAAAAB BAAAAAAAAAAAAAAAAAB BAAAAAAAAAAAAAAAAAB BA----------------B BA----------------B BA----------------B BA----------------B BACCACCCACAACAACCAB ------------------- ------------------- ------------------- 
------------------- ------------------- ------------------- ------------------- ------------------- ------------------- ------------------- ------------------- BBBBBBBBBBBBBBBBBBB BAAAAAAAAAAAAAAAAAB BAAAAAAAAAAAAAAAAAB BAAAAAAAAAAAAAAAAAB BAAAAAAAAAAAAAAAAAB BAAAAAAAAAAAAAAAAAB BAAAAAAAAAAAAAAAAAB BBBBBBBBBBBBBBBBBBB ------------------- ------------------- ------------------- 
