model
size = 10 13 16, scale = 0.05, origin = -y
material 
  colors = A:#DDD B:#D00 C:#E00 D:#111 E:#EEE
voxels
---------- ---------- ---------- ---------- ---------- ---------- ----EE---- ----EE---- ---------- ---------- ---------- ---------- ---------- 
---------- -A-------- ---------- AAAAAAAAAA AAAAAAAAAA AAAAAAAAAA AAAAAAAAAA AAAAAAAAAA AAAAAAAAAA AAAAAAAAAA AAAAAAAAAA ---------- ---------- 
--------A- -A------A- -A------A- AAAAAAAAAA AAAAAAAAAA AAAAAAAAAA AAAAAAAAAA AAAAAAAAAA AAAAAAAAAA AAAAAAAAAA AAAAAAAAAA ---------- ---------- 
---------- ---------- ---------- AAAAAAAAAA AAAAAAAAAA AAAAAAAAAA AAAAAAAAAA AAAAAAAAAA AAAAAAAAAA AAAAAAAAAA AAAAAAAAAA ---------- ---------- 
---------- ---------- ---------- AAAAAAAAAA AAAAAAAAAA AAAAAAAAAA AAAAAAAAAA AAAAAAAAAA AAAAAAAAAA AAAAAAAAAA AAAAAAAAAA ---------- ---------- 
---------- ---------- ---------- AAAAAAAAAA AAAAAAAAAA AAAAAAAAAA AAAAAAAAAA AAAAAAAAAA AAAAAAAAAA AAAAAAAAAA AAAAAAAAAA ---------- ---------- 
---------- ---------- ---------- AAAAAAAAAA AAAAAAAAAA AAAAAAAAAA AAAAAAAAAA AAAAAAAAAA AAAAAAAAAA AAAAAAAAAA AAAAAAAAAA ---------- ---------- 
---------- ---------- ---------- AAAAAAAAAA AAAAAAAAAA AAAAAAAAAA AAAAAAAAAA AAAAAAAAAA AAAAAAAAAA AAAAAAAAAA AAAAAAAAAA ---------- ---------- 
---------- ---------- ---------- AAAAAAAAAA AAAAAAAAAA AAAAAAAAAA AAAAAAAAAA AAAAAAAAAA AAAAAAAAAA AAAAAAAAAA AAAAAAAAAA ---------- ---------- 
---------- ---------- ---------- AAAAAAAAAA AAAAAAAAAA AAAAAAAAAA AAAAAAAAAA AAAAAAAAAA AAAAAAAAAA AAAAAAAAAA AAAAAAAAAA ---------- ----CC---- 
---------- ---------- ---------- AAAAAAAAAA AAAAAAAAAA AAAAAAAAAA AAAAAAAAAA AAAAAAAAAA AAAAAAAAAA AAAAAAAAAA AAAACCAAAA ----CC---- ----CC---- 
---------- ---------- ---------- AAAAAAAAAA AAAAAAAAAA AAAAAAAAAA AAAAAAAAAA AAAAAAAAAA AAAAAAAAAA BAAAAAAAAB BBBBBBBBBB ----CC---- ---------- 
---------- ---------- ---------- AAAAAAAAAA AAAAAAAAAA AAAAAAAAAA AAAAAAAAAA AAAAAAAAAA DAAAAAAAAD BAAAAAAAAB BBBBBBBBBB ---------- ---------- 
---------- --------A- ---------- AAAAAAAAAA AAAAAAAAAA AAAAAAAAAA AAAAAAAAAA AAAAAAAAAA DAAAAAAAAD BAAAAAAAAB BBBBBBBBBB ---------- ---------- 
-A-------- -A------A- -A------A- AAAAAAAAAA AAAAAAAAAA AAAAAAAAAA AAAAAAAAAA AAAAAAAAAA DAAAAAAAAD BAAAAAAAAB BBBBBBBBBB ---------- ---------- 
---------- ---------- ---------- AAAAAAAAAA AAAAAAAAAA AAAAAAAAAA AAAAAAAAAA AAAAAAAAAA AAAAAAAAAA BBBBBBBBBB BBBBBBBBBB ---------- ---------- 
