model
size = 20 20 21, scale = 0.05, origin = -y
material 
  colors = A:#EEE B:#111
voxels
-------------------- -------------------- -------------------- -------------------- -------------------- -------------------- -------------------- --------AAAA-------- -------AABBAA------- -------AABBAA------- ------ABBAABBA------ ------AAAAAAAA------ -------AAAAAA------- -------------------- -------------------- -------------------- -------------------- -------------------- -------------------- -------------------- 
-------------------- -------------------- -------------------- -------------------- -------------------- -------AAAAAA------- ------AAAAAAAA------ -----AAAAAAAAAA----- -----AAAAAAAAAA----- -----AAAAAAAAAA----- -----AAAAAAAAAA----- -----AAAAAAAAAA----- -----AAAAAAAAAA----- ------AAAAAAAA------ -------AAAAAA------- -------------------- -------------------- -------------------- -------------------- -------------------- 
-------------------- -------------------- -------------------- -------------------- -------AAAAAA------- -----AAAAAAAAAA----- -----AAAAAAAAAA----- ----AAAAAAAAAAAA---- ----AAAAAAAAAAAA---- ----AAAAAAAAAAAA---- ----AAAAAAAAAAAA---- ----AAAAAAAAAAAA---- ----AAAAAAAAAAAA---- -----AAAAAAAAAA----- -----AAAAAAAAAA----- -------AAAAAA------- -------------------- -------------------- -------------------- -------------------- 
-------------------- -------------------- -------------------- ------AAAAAAAA------ -----AAAAAAAAAA----- ----AAAAAAAAAAAA---- ---AAAAAAAAAAAAAA--- ---AAAAAAAAAAAAAA--- ---AAAAAAAAAAAAAA--- ---AAAAAAAAAAAAAA--- ---AAAAAAAAAAAAAA--- ---AAAAAAAAAAAAAA--- ---AAAAAAAAAAAAAA--- ---AAAAAAAAAAAAAA--- ----AAAAAAAAAAAA---- -----AAAAAAAAAA----- ------AAAAAAAA------ -------------------- -------------------- -------------------- 
-------------------- -------------------- -------AAAAAA------- -----AAAAAAAAAA----- ----AAAAAAAAAAAA---- ---AAAAAAAAAAAAAA--- ---AAAAAAAAAAAAAA--- --AAAAAAAAAAAAAAAA-- --AAAAAAAAAAAAAAAA-- --AAAAAAAAAAAAAAAA-- --AAAAAAAAAAAAAAAA-- --AAAAAAAAAAAAAAAA-- --AAAAAAAAAAAAAAAA-- ---AAAAAAAAAAAAAA--- ---AAAAAAAAAAAAAA--- ----AAAAAAAAAAAA---- -----AAAAAAAAAA----- -------AAAAAA------- -------------------- -------------------- 
---A------------A--- ---A----AAAA----A--- ---A-AAAAAAAAAA-A--- ---AAAAAAAAAAAAAA--- ---AAAAAAAAAAAAAA--- --AAAAAAAAAAAAAAAA-- --AAAAAAAAAAAAAAAA-- --AAAAAAAAAAAAAAAA-- -AAAAAAAAAAAAAAAAAA- -AAAAAAAAAAAAAAAAAA- -AAAAAAAAAAAAAAAAAA- -AAAAAAAAAAAAAAAAAA- --AAAAAAAAAAAAAAAA-- --AAAAAAAAAAAAAAAA-- --AAAAAAAAAAAAAAAA-- ---AAAAAAAAAAAAAA--- ----AAAAAAAAAAAA---- -----AAAAAAAAAA----- --------AAAA-------- -------------------- 
-------------------- ------AAAAAAAA------ -----AAAAAAAAAA----- ---AAAAAAAAAAAAAA--- ---AAAAAAAAAAAAAA--- --AAAAAAAAAAAAAAAA-- -AAAAAAAAAAAAAAAAAA- -AAAAAAAAAAAAAAAAAA- -AAAAAAAAAAAAAAAAAA- -AAAAAAAAAAAAAAAAAA- -AAAAAAAAAAAAAAAAAA- -AAAAAAAAAAAAAAAAAA- -AAAAAAAAAAAAAAAAAA- -AAAAAAAAAAAAAAAAAA- --AAAAAAAAAAAAAAAA-- ---AAAAAAAAAAAAAA--- ---AAAAAAAAAAAAAA--- -----AAAAAAAAAA----- ------AAAAAAAA------ -------------------- 
---------AA--------- ------AAAAAAAA------ ----AAAAAAAAAAAA---- ---AAAAAAAAAAAAAA--- --AAAAAAAAAAAAAAAA-- --AAAAAAAAAAAAAAAA-- -AAAAAAAAAAAAAAAAAA- -AAAAAAAAAAAAAAAAAA- -AAAAAAAAAAAAAAAAAA- AAAAAAAAAAAAAAAAAAAA AAAAAAAAAAAAAAAAAAAA -AAAAAAAAAAAAAAAAAA- -AAAAAAAAAAAAAAAAAA- -AAAAAAAAAAAAAAAAAA- --AAAAAAAAAAAAAAAA-- --AAAAAAAAAAAAAAAA-- ---AAAAAAAAAAAAAA--- ----AAAAAAAAAAAA---- ------AAAAAAAA------ ---------AA--------- 
--------AAAA-------- -----AAAAAAAAAA----- ----AAAAAAAAAAAA---- ---AAAAAAAAAAAAAA--- --AAAAAAAAAAAAAAAA-- -AAAAAAAAAAAAAAAAAA- -AAAAAAAAAAAAAAAAAA- -AAAAAAAAAAAAAAAAAA- AAAAAAAAAAAAAAAAAAAA AAAAAAAAAAAAAAAAAAAA AAAAAAAAAAAAAAAAAAAA AAAAAAAAAAAAAAAAAAAA -AAAAAAAAAAAAAAAAAA- -AAAAAAAAAAAAAAAAAA- -AAAAAAAAAAAAAAAAAA- --AAAAAAAAAAAAAAAA-- ---AAAAAAAAAAAAAA--- ----AAAAAAAAAAAA---- -----AAAAAAAAAA----- --------AAAA-------- 
-------AAAAAA------- -----AAAAAAAAAA----- ---AAAAAAAAAAAAAA--- --AAAAAAAAAAAAAAAA-- --AAAAAAAAAAAAAAAA-- -AAAAAAAAAAAAAAAAAA- -AAAAAAAAAAAAAAAAAA- AAAAAAAAAAAAAAAAAAAA AAAAAAAAAAAAAAAAAAAA AAAAAAAAAAAAAAAAAAAA AAAAAAAAAAAAAAAAAAAA AAAAAAAAAAAAAAAAAAAA AAAAAAAAAAAAAAAAAAAA -AAAAAAAAAAAAAAAAAA- -AAAAAAAAAAAAAAAAAA- --AAAAAAAAAAAAAAAA-- --AAAAAAAAAAAAAAAA-- ---AAAAAAAAAAAAAA--- -----AAAAAAAAAA----- -------AAAAAA------- 
-------AAAAAA------- -----AAAAAAAAAA----- ---AAAAAAAAAAAAAA--- --AAAAAAAAAAAAAAAA-- --AAAAAAAAAAAAAAAA-- -AAAAAAAAAAAAAAAAAA- -AAAAAAAAAAAAAAAAAA- AAAAAAAAAAAAAAAAAAAA AAAAAAAAAAAAAAAAAAAA AAAAAAAAAAAAAAAAAAAA AAAAAAAAAAAAAAAAAAAA AAAAAAAAAAAAAAAAAAAA AAAAAAAAAAAAAAAAAAAA -AAAAAAAAAAAAAAAAAA- -AAAAAAAAAAAAAAAAAA- --AAAAAAAAAAAAAAAA-- --AAAAAAAAAAAAAAAA-- ---AAAAAAAAAAAAAA--- -----AAAAAAAAAA----- -------AAAAAA------- 
-------AAAAAA------- -----AAAAAAAAAA----- ---AAAAAAAAAAAAAA--- --AAAAAAAAAAAAAAAA-- --AAAAAAAAAAAAAAAA-- -AAAAAAAAAAAAAAAAAA- -AAAAAAAAAAAAAAAAAA- AAAAAAAAAAAAAAAAAAAA AAAAAAAAAAAAAAAAAAAA AAAAAAAAAAAAAAAAAAAA AAAAAAAAAAAAAAAAAAAA AAAAAAAAAAAAAAAAAAAA AAAAAAAAAAAAAAAAAAAA -AAAAAAAAAAAAAAAAAA- -AAAAAAAAAAAAAAAAAA- --AAAAAAAAAAAAAAAA-- --AAAAAAAAAAAAAAAA-- ---AAAAAAAAAAAAAA--- -----AAAAAAAAAA----- -------AAAAAA------- 
--------AAAA-------- -----AAAAAAAAAA----- ----AAAAAAAAAAAA---- ---AAAAAAAAAAAAAA--- --AAAAAAAAAAAAAAAA-- -AAAAAAAAAAAAAAAAAA- -AAAAAAAAAAAAAAAAAA- -AAAAAAAAAAAAAAAAAA- AAAAAAAAAAAAAAAAAAAA AAAAAAAAAAAAAAAAAAAA AAAAAAAAAAAAAAAAAAAA AAAAAAAAAAAAAAAAAAAA -AAAAAAAAAAAAAAAAAA- -AAAAAAAAAAAAAAAAAA- -AAAAAAAAAAAAAAAAAA- --AAAAAAAAAAAAAAAA-- ---AAAAAAAAAAAAAA--- ----AAAAAAAAAAAA---- -----AAAAAAAAAA----- --------AAAA-------- 
---------AA--------- ------AAAAAAAA------ ----AAAAAAAAAAAA---- ---AAAAAAAAAAAAAA--- --AAAAAAAAAAAAAAAA-- --AAAAAAAAAAAAAAAA-- -AAAAAAAAAAAAAAAAAA- -AAAAAAAAAAAAAAAAAA- -AAAAAAAAAAAAAAAAAA- AAAAAAAAAAAAAAAAAAAA AAAAAAAAAAAAAAAAAAAA -AAAAAAAAAAAAAAAAAA- -AAAAAAAAAAAAAAAAAA- -AAAAAAAAAAAAAAAAAA- --AAAAAAAAAAAAAAAA-- --AAAAAAAAAAAAAAAA-- ---AAAAAAAAAAAAAA--- ----AAAAAAAAAAAA---- ------AAAAAAAA------ ---------AA--------- 
-------------------- ------AAAAAAAA------ -----AAAAAAAAAA----- ---AAAAAAAAAAAAAA--- ---AAAAAAAAAAAAAA--- --AAAAAAAAAAAAAAAA-- -AAAAAAAAAAAAAAAAAA- -AAAAAAAAAAAAAAAAAA- -AAAAAAAAAAAAAAAAAA- -AAAAAAAAAAAAAAAAAA- -AAAAAAAAAAAAAAAAAA- -AAAAAAAAAAAAAAAAAA- -AAAAAAAAAAAAAAAAAA- -AAAAAAAAAAAAAAAAAA- --AAAAAAAAAAAAAAAA-- ---AAAAAAAAAAAAAA--- ---AAAAAAAAAAAAAA--- -----AAAAAAAAAA----- ------AAAAAAAA------ -------------------- 
---A------------A--- ---A----AAAA----A--- ---A-AAAAAAAAAA-A--- ---AAAAAAAAAAAAAA--- ---AAAAAAAAAAAAAA--- --AAAAAAAAAAAAAAAA-- --AAAAAAAAAAAAAAAA-- --AAAAAAAAAAAAAAAA-- -AAAAAAAAAAAAAAAAAA- -AAAAAAAAAAAAAAAAAA- -AAAAAAAAAAAAAAAAAA- -AAAAAAAAAAAAAAAAAA- --AAAAAAAAAAAAAAAA-- --AAAAAAAAAAAAAAAA-- --AAAAAAAAAAAAAAAA-- ---AAAAAAAAAAAAAA--- ----AAAAAAAAAAAA---- -----AAAAAAAAAA----- --------AAAA-------- -------------------- 
-------------------- -------------------- -------AAAAAA------- -----AAAAAAAAAA----- ----AAAAAAAAAAAA---- ---AAAAAAAAAAAAAA--- ---AAAAAAAAAAAAAA--- --AAAAAAAAAAAAAAAA-- --AAAAAAAAAAAAAAAA-- --AAAAAAAAAAAAAAAA-- --AAAAAAAAAAAAAAAA-- --AAAAAAAAAAAAAAAA-- --AAAAAAAAAAAAAAAA-- ---AAAAAAAAAAAAAA--- ---AAAAAAAAAAAAAA--- ----AAAAAAAAAAAA---- -----AAAAAAAAAA----- -------AAAAAA------- -------------------- -------------------- 
-------------------- -------------------- -------------------- ------AAAAAAAA------ -----AAAAAAAAAA----- ----AAAAAAAAAAAA---- ---AAAAAAAAAAAAAA--- ---AAAAAAAAAAAAAA--- ---AAAAAAAAAAAAAA--- ---AAAAAAAAAAAAAA--- ---AAAAAAAAAAAAAA--- ---AAAAAAAAAAAAAA--- ---AAAAAAAAAAAAAA--- ---AAAAAAAAAAAAAA--- ----AAAAAAAAAAAA---- -----AAAAAAAAAA----- ------AAAAAAAA------ -------------------- -------------------- -------------------- 
-------------------- -------------------- -------------------- -------------------- -------AAAAAA------- -----AAAAAAAAAA----- -----AAAAAAAAAA----- ----AAAAAAAAAAAA---- ----AAAAAAAAAAAA---- ----AAAAAAAAAAAA---- ----AAAAAAAAAAAA---- ----AAAAAAAAAAAA---- ----AAAAAAAAAAAA---- -----AAAAAAAAAA----- -----AAAAAAAAAA----- -------AAAAAA------- -------------------- -------------------- -------------------- -------------------- 
-------------------- -------------------- -------------------- -------------------- -------------------- -------AAAAAA------- ------AAAAAAAA------ -----AAAAAAAAAA----- -----AAAAAAAAAA----- -----AAAAAAAAAA----- -----AAAAAAAAAA----- -----AAAAAAAAAA----- -----AAAAAAAAAA----- ------AAAAAAAA------ -------AAAAAA------- -------------------- -------------------- -------------------- -------------------- -------------------- 
-------------------- -------------------- -------------------- -------------------- -------------------- -------------------- -------------------- -------------------- -------------------- ---------AA--------- ---------AA--------- -------------------- -------------------- -------------------- -------------------- -------------------- -------------------- -------------------- -------------------- -------------------- 
