model
size = 22 19 32, scale = 0.05, origin = -y
material 
  colors = A:#063 B:#111 C:#090 D:#EEE E:#030
voxels
-AC3A3(C2A)C3ACA-AC18-C3A18-2ACA18-AC2A18-2A-A18-A2-A18-A-2A18-4A18-2ACA18-AC-3AC5A2C5AC3A178-20A-2A2BD5B2D5BD2B4ABD3B2D4B2D3BDB2A-A3B3D6B3D3BA2-AD6BD2BD6BDA2-A3B3D6B3D3BA2-AB3D2BD4BD2B3DBA2-A2B5DB2DB5D2BA-2A2BD3BD4BD3BD2B4ABD2BD8BD2BDB2A-A2B4C2A2C2A4C2BA178-5AE8AE5A-B20ABC20AC-2(B2(2A6-)2AB2-)2(C2(2A6-)2AC2-)C2(2A6-)2AC-5A5-2A5-5AC20AC-A4B3(A2C)A4BA178-2A2E12A2E2A-BA8-2A8-AB2A-16A-2A-2(B-2(2A5-)2A-B2-)2(C-2(2A5-)2A-C2-)C-2(2A5-)2A-C-BA-16A-AB2A2-14A2-2A-ABC3B2(2CA)2C3BCBA178-2A2E3AE4AE3A2E2A-3A2-12A2-5A2-14A2-2A-A2-14A2-A2-C3(2-14A2(2-C))2-14A2-C-2A2-14A2-4A3-12A3-2A-A4B3AB2CB3A4BA178-2A3EAE6AEA3E2A-22AC20AC-20A2-B18AB3(2-C18AC)-B20AB22A-CBC2BAC2A2C2ACA2BCBC178-20A-B20AB22A-B18AB4(2-20A)-C20AC22A-3A2B4A2C4A2B3A178-A2E14A2EA-44A2-4(18A4-)18A2-A-18A-AB20AB-AC3AB3A2C3AB3ACA10-B2CB164-5A10-5A-10A2-13A16-4A-A3-3A4-3A3-A-AC-A2-4AB2-B4A2-A-CA2(-A2-2A2BA2-A2B2A2-A-2A)-A2-4A4-4A2-A-4A4-3A2-3A4-13A2-10A-2AC6A2C6AC2A10-A2CA18-B2CB142-2A16-2A-9A4-12A2-4B4-4B2-3AB2A16-2AB3A16-3AC2A16-2ACB2A16-2ABC2A16-2AC3A2-4BA2-A4B2-8A4BA2-A4B5A-2ABC12ACB2A32-2(4A18-)A2BA120-7A6-7A-5A3B6-3B8A16-6A16-3AC2A16-2AC3A16-6A16-8A3B6-3B5A-4A3B6-3B4A4-5A6-5A78-4A18-A2CA99-4A10-4A4-3AB10-B3A4-2A14-2A3-3(3A14-3A2-)3A14-3A3-3AB10-B3A4-3AB10-B3A5-3A10-3A100-4A18-A2BA77-2(2A14-2A4-)2A14-2A3-2(3A14-3A2-)C2A14-2AC2-B2A14-2AB3-2A14-2A4-2A14-2A143-4A100-A14-A5-2A14-2A3-3A14-3A3(2-B2A14-2AB)3-2A14-2A165-4A18-C2AC120-3(A18-A2-)A18-A208-B2AB120-2(2A16-2A2-)CA16-AC2-2A16-2A208-4A18-A2CA99-2(A16-A4-)B16-B4-A16-A231-A2BA99-B16-B3(4-A16-A)231-4A99-2(A16-A4-)B16-B4-A16-A231-B2AB121-A16-A4-B16-B4-A16-A231-C2AC121-C16-C3(4-A16-A)209-4B121-A16-A4-B16-B4-C16-C4-A16-A209-4A121-2(A16-A4-)B16-B4-A16-A209-C2AC121-2(A16-A4-)C16-C4-A16-A209-B2AB121-3(2A14-2A4-)A16-A209-C2AC121-BA14-AB4-CA14-AC2(4-2A14-2A)209-B2AB144-B14-B6-A14-A5-BA14-AB5-A14-A166-4A18-4A144-CA12-AC3(6-2A12-2A)144-C2AC18-A2BA167-2A10-2A8-BA10-AB7-3A10-3A6-C2A10-2AC122-4A18-4A147-2A6-2A11-3A6-3A2(10-2A8-2A)9-2(3A8-)2BA8-A2B9-BA8-AB11-A8-A59-C2AC18-4A149-6A14-2(3B4A3B12-)3B4-3B12-B8-B11-2A8-2A10-4A4-4A11-B2A4-2AB12-AB6ABA13-C6AC16-B2AB18-A2BA194-4A17-6A15-2A4-2A58-CA4-AC14-2A4-2A15-6A17-4A141-
