model
size = 24 13 32, scale = 0.05, origin = -y
material 
  colors = A:#FC3 B:#222 C:#111 D:#F00
voxels
81-D4-D19-4D283-6D18-6D3-C23-C22-2C22-C185-2C19-D2A2D2AD17-6D3-2B22-2(2B21-3B21-)2B111-6A17-8A16-8A17-D4AD19-4A18-3C2A3C2-2B12-8C-3B21-2B17-2B2-3B10-2B8-2C13-CB25-B47-6A17-3(8A16-)8A14-B-8A14-2B-6A17-B6A3-B15-2C2B2-3B10-B5-3C-3B12-CB7-2B14-2CBC46-6A17-8A16-8A13-2B10A12-2B10A13-B10A13-2B8A15-CB7A15-3C5A2-B14-3C2B2-3B13-B2-C-C2-2B14-4BC22-4A19-6A17-8A15-10A12-B-10A12-2B10A13-B10A13-2B9A13-3B8A14-2B7A16-3B2A2C18-4B2CB16-4B2C-2C16-6A17-8A15-10A14-10A13-3(12A12-)12A13-B9A14-2B8A15-2B2A3BA17-6B21-5C16-6A17-8A15-10A13-5(12A12-)12A13-10A15-4A3BA18-2A4B17-6C17-8A15-10A14-10A13-5(12A12-)12A13-10A2C13-8A3C14-3A2BAB2C15-3C2-C17-8A13-14A10-14A9-2(16A8-)16A9-14ABC8-14AB10-12ABC11-10A2B13-2(2A3B)15-2(2A2B)15-3C3-2C14-12A10-16A8-16A7-18A3(6-16ABC)7-14A2B9-12A2BC11-3A2B4A3B9-3B-2A3B3A2B11-C3B-2ABA18-3C3-3C12-14A8-18A6-18A5-20A2(4-17AB2A)5-15A2BA6-15A2BA7-5A3B5A2BA8-2B-3A3B4A11-3B-3A2B3A14-3B-4A3-B14-C5-4C10-16A6-5(20A4-)7A2B11A4-7A3B10A5-6A4B8A8-B2-3A2B3A13-2B2-6A25-3B20-3C9-18A5-20A3-2(22A2-)8A2B12A2(2-8A3B11A)3-8A2B10A5-18A12-6A20-2A4-2B21-3B20-2C10-7A4-7A5-20A3-2(22A2-)9AB12A2-9A2B11A2(2-22A)3-7A-4A-7A20-2B20-4B20-2B32-6A8-6A3-9A4-9A2(2-10A)-11A2-22A2-11A-22A2-9A-2A-9A2-8A6-8A3-6A8-6A19-3B21-2B55-5A10-5A3-8A6-8A-9A6-19A4-20A4-19A6-18A6-9A-7A8-7A3-5A10-5A100-5A10-5A3-7A8-7A-9A3(6-18A)6-17A8-8A-7A8-7A2-5A12-5A99-4A12-4A3-7A8-7A2(-8A4(8-16A)8-15A10-7A-5A12-5A99-4A12-4A3-6A10-6A)-8A4(8-16A)8-15A10-7A-5A12-5A99-4A12-4A3-7A8-7A-9A4(6-18A)6-9A-7A8-7A2-6A10-6A99-5A10-5A3-8A6-8A-10A3(4-20A)4-10A-9A4-9A2-8A6-8A3-6A8-6A101-5A8-5A2(4-9A)2(2-10A)-48A-2(22A2-)10A2-10A3-7A6-7A101-6A6-6A5-20A3-3(22A2-)22A3-20A4-20A5-8A2-8A103-6A4-6A7-18A5-20A3-22A2-22A3-20A4-20A5-18A7-16A105-14A8-18A5-3(20A4-)20A5-18A6-18A8-14A107-12A10-16A7-4(18A6-)18A7-16A9-14A109-8A13-14A9-4(16A8-)16A9-14A12-10A134-10A12-3(14A10-)14A11-12A13-10A17-4A140-4A18-8A15-10A13-12A13-10A15-8A18-4A130-
