model
size = 25 16 22, scale = 0.05, origin = -y
material 
  colors = A:#7B90D2 B:#005CAF C:#FFF D:#211E55 E:#111 F:#FCFAF2 G:#A5A051 H:#E83015
voxels
FCEC----CECFDDD---------- --EC----CE--------------- --EC----CE--------------- --EC----CE--------------- --EC----CE--------------- ------------------------- ------------------------- ------------------------- ------------------------- ------------------------- ------------------------- ------------------------- ------------------------- ------------------------- ------------------------- ------------------------- 
EEE------ECDDDD---------- FCE------ECFDDD---------- FC--------CFDDD---------- FC--------CFDDD---------- FCEC----CECFDDD---------- FCHC----CECFDDD---------- ---H--------------------- ------------------------- ------------------------- ------------------------- ------------------------- ------------------------- ------------------------- ------------------------- ------------------------- ------------------------- 
--E------E-----DBBBBAA--- --EE----EE-----DBBBBAA--- ---------------DBBBBAA--- ---------------DBBBBAA--- ---------------DBBBBAA--- FCEC----CECFDDDDBBBBAA--- FCEC----CECFDDDDBBBBAA--- FCEC----CECFDDD---------- ------------------------- ------------------------- ------------------------- ------------------------- ------------------------- ------------------------- ------------------------- ------------------------- 
--------------------AAAA- --------------------AAAA- --------------------AAAA- --------------------AAAA- --------------------AAAA- --------------------AAAA- --------------DDBBBBAAAA- FCE------ECFDDD---------- FCEC----CECFDDD---------- FCEC----CECFDDD---------- -----FFFF---------------- -----------GGGGG--------- ------------EEEE--------- ------------------------- ------------------------- ------------------------- 
--------------------AAAAA --------------------AAAAA --------------------AAAAA --------------------AAAAA --------------------AAAAA --------------------AAAAA ---------------DBBBBAAAAA ---------------DBBBBAA--- ---------------DBBBBAA--- FCEC----CECFDDDDBBBBAA--- FCEH----CECFDDDD--------- -------FF--GGGGG--------- ------------E--E--------- ------------------------- ------------------------- ------------------------- 
------------------------- ------------------------- ------------------------- ------------------------- ------------------------- ------------------------- --------------------AAAAA --------------------AAAA- --------------------AAAA- ----------------BBBBAAAA- --EH-----E------BBBBAA--- FCH----FCECGGGGG--------- -----FFFF---EE-E--------- ------------------------- ------------------------- ------------------------- 
------------------------- ------------------------- ------------------------- ------------------------- ------------------------- ------------------------- --------------------AAAAA --------------------AAAAA --------------------AAAAA --------------------AAAAA ----------------BBBBAAAA- FCEC----CECGGGGGBBBBAA--- FHHH---FCEC----E--------- ------------------------- ------------------------- ------------------------- 
------------------------- ------------------------- ------------------------- ------------------------- ------------------------- ------------------------- ------------------------- ------------------------- ------------------------- ------------------------- --------------------AAAAA -----------GGGGGBBBBAAAA- FCEC---FCECDDDDDBBBBAA--- FCEC-FFFCEC-------------- ------------------------- ------------------------- 
------------------------- ------------------------- ------------------------- ------------------------- ------------------------- ------------------------- ------------------------- ------------------------- ------------------------- ------------------------- --------------------AAAAA -----------GGGGG----AAAAA -----------DDDDDBBBBAAAA- FCEC----CECFDDDDBBBBAA--- FCEC---FCECFDDD---------- ------------------------- 
------------------------- ------------------------- ------------------------- ------------------------- ------------------------- ------------------------- ------------------------- ------------------------- ------------------------- ------------------------- ------------------------- --------------------AA--- --------------------AAAAA ---------------DBBBBAAAA- FCEC----CECFDDD---------- FCEC-FFFCECFDDD---------- 
------------------------- ------------------------- ------------------------- ------------------------- ------------------------- ------------------------- ------------------------- ------------------------- ------------------------- ------------------------- ------------------------- ------------------------- --------------------AAAAA ---------------DBBBBAAAAA ---------------DBBBBAA--- FCEH----CECFDDD---------- 
------------------------- ------------------------- ------------------------- ------------------------- ------------------------- ------------------------- ------------------------- ------------------------- ------------------------- ------------------------- ------------------------- ------------------------- --------------------AAAAA ---------------DBBBBAAAAA ---------------DBBBBAAAA- FCEC----CECFDDD---------- 
------------------------- ------------------------- ------------------------- ------------------------- ------------------------- ------------------------- ------------------------- ------------------------- ------------------------- ------------------------- --------------------AAAAA --------------------AAAAA --------------------AAAAA ---------------DBBBBAAAA- FCEC----CECFDDDDBBBBAA--- FCEC-FFFCECFDDD---------- 
------------------------- ------------------------- ------------------------- ------------------------- ------------------------- ------------------------- ------------------------- ------------------------- ------------------------- ------------------------- --------------------AAAAA ------------GGG-----AAAAA ---------------DBBBBAAAA- FCEC----CECFDDDDBBBBAA--- FCEC----CECFDDD---------- ------------------------- 
------------------------- ------------------------- ------------------------- ------------------------- ------------------------- ------------------------- ------------------------- ------------------------- ------------------------- --------------------AAAA- ---------------DBBBBAAAAA ------------GGGDBBBBAAAAA FCEC----CECFDDDDBBBBAA--- FCEH-FFFCECFDDD---------- ------------------------- ------------------------- 
------------------------- ------------------------- ------------------------- ------------------------- ------------------------- ------------------------- --------------------AAAAA --------------------AAAAA --------------------AAAAA -----------------BBBAAAAA ---------------GGBBBAA--- FCEC----CECFGGGGG-------- FCEC---FCEC--EEEE-------- ------------------------- ------------------------- ------------------------- 
------------------------- ------------------------- ------------------------- ------------------------- --------------------AAAAA --------------------AAAAA --------------------AAAAA --------------------AAAA- -----------------BBBAAAA- ----------------BBBBAA--- --E------E------B-------- FC-H-FFFCECFGGGGG-------- -------------E--E-------- ------------------------- ------------------------- ------------------------- 
--------------------AAAAA --------------------AAAAA --------------------AAAAA --------------------AAAAA --------------------AAAA- --------------------AAAA- -----------------BBBAAAA- -----------------BBBAA--- -----------------BBBAA--- FCEC----CECF----B-------- FHHH---FCECF----B-------- ------------GGGGG-------- -------------EE-E-------- ------------------------- ------------------------- ------------------------- 
--------------------AAAA- ---E----------------AAAA- --------------------AAAA- --------------------AAAA- ---------------DBBBBAAAA- ---------------DBBBBAA--- ---------------DBBBBAA--- FCE------ECFDDDDD-------- FCEC----CECFDDDDD-------- FCEH-FFFCECFDDDDD-------- ------------DDDDD-------- ------------GGGGG-------- ----------------E-------- ------------------------- ------------------------- ------------------------- 
--E------------DBBBBAA--- --EE----EE-----DBBBBAA--- ---------------DBBBBAA--- ---------------DBBBBAA--- ---------------DBBBBAA--- FCEC----CECFDDD---------- FCEC----CECFDDD---------- FCEC---FCECFDDD---------- ------------------------- ------------------------- ------------------------- ------------------------- ------------------------- ------------------------- ------------------------- ------------------------- 
EEE------ECDDDD---------- FCE------ECFDDD---------- FC--------CFDDD---------- FC--------CFDDD---------- FCEC----CECFDDD---------- FCEC--FFCECFDDD---------- ------------------------- ------------------------- ------------------------- ------------------------- ------------------------- ------------------------- ------------------------- ------------------------- ------------------------- ------------------------- 
FCEC----CECFDDD---------- --EC----CE--------------- --EC----CE--------------- --EC----CE--------------- --EC----CE--------------- ------------------------- ------------------------- ------------------------- ------------------------- ------------------------- ------------------------- ------------------------- ------------------------- ------------------------- ------------------------- ------------------------- 
