model
size = 32 32 31, scale = 0.05, origin = -y
material 
  colors = A:#9CF B:#FF9 C:#FFC D:#FF6 E:#BBB F:#FF3 G:#100 H:#A00 I:#FFF J:#E00
voxels
32A2-28A5-3B10-H9-3B5-2(5B9-H8-5B4-)5B18-5B5-3B20-3B390-3C20-3C5-5C18-5C4-5C18-5C5-3C20-3C291-32A2-28A4-5B18-3(5B4-5B9-H8-)5B4-5B18-5B388-3(5B18-5B4-)5B18-5B290-32A2-28A4-5B18-4(5B4-5B9-H8-)5B388-3(5B18-5B4-)5B18-5B290-32A2-28A2(4-5B18-5B)3(4-5B8-3E7-5B)17-11(3E29-)3E16-3(5B8-3E7-5B4-)5B8-3E7-5B17-4(3E29-)3E30-E111-32A2-28A2(4-5B18-5B)4-5B7-5E2(6-5B4-5B7-E3-E)6-5B16-11(E3-E27-)E3-E15-3(5B7-E3-E6-5B4-)5B7-E3-E6-5B16-4(E3-E27-)5E28-3E29-3E78-32A2-28A4-5B3-4H5-4H2-2(5B4-)3H5-3H3-2(5B4-)3H5E3H3-5B4-5B5-2H2(E-)E2H2(4-5B)6-H2(E-)EH5-5B16-11(2(E-)E27-)2(E-)E15-3(5B7-2(E-)E6-5B4-)5B7-2(E-)E6-5B16-4(2(E-)E27-)5E27-5E28-3E30-E47-32A2-28A2(4-5B18-5B)4-5B7-5E2(6-5B4-5B7-E3-E)6-5B16-11(E3-E27-)E3-E15-3(5B7-E3-E6-5B4-)5B7-E3-E6-5B16-4(E3-E27-)5E28-3E29-3E78-32A2-28A2(4-5B18-5B)3(4-5B8-3E7-5B)17-11(3E29-)3E16-3(5B8-3E7-5B4-)5B8-3E7-5B17-4(3E29-)3E30-E111-32A2-28A4-5B18-4(5B4-5B9-H8-)5B388-3(5B18-5B4-)5B18-5B290-32A2-28A4-5B18-3(5B4-5B9-H8-)5B4-5B18-5B388-3(5B18-5B4-)5B18-5B290-32A2-14AH13A3(4-5B9-H8-5B)2(4-5B18-5B)388-3(5B18-5B4-)5B2(18-5B290-32A2-28A5(4-5B18-5B)388-5B18-5B4-B3AB2(18-5B4-5B))18-5B290-64A3B3AC3(18-10B3AB)18-14B18-9B2(12-5G11-4B)2(13-3G12-4B)14-G13-4B13-G-G12-4B11-2G-G-2G10-4B9-4G3-4G8-4B8-4G5-4G7-4B9-3G5-3G8-4B10-G7-G9-4B28-9B18-10B3AB2(18-14B)18-7B288-64AB2(6A18D5A3B)6A23D3B6A2D15F6D3B2A5BD6(15F6D3BA7D)8FA6F2(6D3BA7D9F2A4F)6D3BA7D10F4AF6D3BA7D10F3A2F2(6D3BA7D15F)6D3B6A2D15FD8B6A2(18D14B)18-7B289-30A2-B29A10(2-B28AB)2-B12AFG14A6(B2-B28A)B2-B5A2D15A2D4AB2-B5A19D4AB2-6B19D5B80-2I62-2I92-J4-J77-33AB30A2B17(28A4B)5A2D15A2D4A4B5A19D4A12B13D19B13D9B42-7(12C20-)12C11-30A2-B29A19(2-B28AB)2-10B10A10B12-B8AB22-9B2(C21-7(C10AC20-)12C10-33AB30A2B18(28A4B)28A13B10A21B-B8AB-10B11-B8AC21-7(C10AC20-)12C11-30A2-B29A19(2-B28AB)2-10B10A10B12-B8AB22-B8A)C21-7(C10AC20-)12C10-33AB30A2B18(28A4B)28A13B10A21B2(-10B)11-10C21-7(C10AC20-)12C11-30A2-B29A19(2-B28AB)2-30B75-7(12C20-)12C10-33AB30A2B18(28A4B)28A3BA40B11-11B43-10C21-5(12C20-)12C21-10C12-30A2-B29A19(2-B28AB)2-30B321-64AB19(29A3B)25A38B288-64A6B15(20A12B)20A166B293-2(2(22A10-)16(B20AB10-)4(22B10-)22B298-)2(22A10-)6(22B10-)4B2-B-2B-B-7B-B10-2B2-2(B-)2B-B-7B-B10-B-3B-B-2B-B-7B-B10-B-3B-B4-B-6B-2B10-B-3B-B5(-2B)2(10-B-3B-2B2-3B3(-B)-2B)10-2B2-B-2B2-4B2(-3B)10-4B2-2B2-4B2(-3B)6(10-22B)293-
