model
size = 30 26 21, scale = 0.05, origin = -y
material 
  colors = A:#FF0 B:#111 C:#EEE D:#FC9 E:#444 F:#F93 G:#E00 H:#00F
voxels
------------------------------ ------------------------------ ------------------------------ ------------------------------ -------BBB---------BBBB------- -----BBDDB---------BDDBB------ ----BAEAB-----------BAEB------ ----BAEB-------------BAB------ ----BEAB---------------------- ------------------------------ ------------------------------ ------------------------------ ------------------------------ ------------------------------ ------------------------------ ------------------------------ ------------------------------ ------------------------------ ------------------------------ ------------------------------ ------------------------------ ------------------------------ ------------------------------ ------------------------------ ------------------------------ ------------------------------ 
------------------------------ ------------------------------ ------------------------------ ------------------------------ -------BBB---------BBBB------- -----BBDDB---------BDDBB------ ----BAAAB-----------BAAB------ ----BAAB-------------BAB------ ----BAAB---------------------- ------------------------------ ------------------------------ ------------------------------ ------------------------------ ------------------------------ ------------------------------ ------------------------------ ------------------------------ ------------------------------ ------------------------------ ------------------------------ ------------------------------ ------------------------------ ------------------------------ ------------------------------ ------------------------------ ------------------------------ 
------------------------------ ------------------------------ ------------------------------ ------------------------------ ------------------------------ ------------------------------ --------------------BBB------- ---------------------BAB------ ----BAAB---------------------- ------------------------------ -----BBB-------------BBB------ ------------------------------ -----BBB------BB-----BBB------ --------------BB-------------- ------BB-BBB-BFFB-BBB-BB------ ---------BHB-BBBB-BHB--------- ---------CHB------CHB--------- ---------BBB------BBB--------- ------------------------------ ------------------------------ ------------------------------ ------------------------------ ------------------------------ ------------------------------ ------------------------------ ------------------------------ 
--------BBB--------BBB-------- --------BAB--------BAB-------- ------BBBEBBBBBBBBBBABBB------ ----BBAAAAAADDDDDDAEAAAABB---- --BBAAAAAAAADDDDDDEAAAAAAABB-- -BAAAAAAAAAADDDDDDAAAAAAAAAAB- -BEAAAAAAAEADDDDDDAEBAABAEAAB- BAAAAAAAAAADDDDDDDDAABABAAEAAB BAAAAAAAAADDDDDDDDDDAAAAAEAAEB BEAEAAAAADDDDDDDDDDDDAAAAAAAAB BAAAABBBDDDGGDDDDGGDDBBBAEAAAB BAAEAAADDDGDDGGGGDDGDDDAAAAEAB BAEAABBBDDDDDDBBDDDDDBBBAAEEAB BAAAAAADDDDDDDBBDDDDDDDAAAAAAB -BAAEABBDBBBDBFFBDBBBDBBAAAAB- -BAAAAADDBHBDBBBBDBHBDDAAEAAB- --BAEAAAACHBDDDDDDCHBAAAAEAB-- --BAAAEAABBBADDDDABBBAEAEAAB-- ---BAAEEAAAAAADDAAAAAAEAAAB--- ---BAAAAAAEAAEAAEAAAEAAEAAB--- ----BBAFFFFFAABBAAFFFFFABB---- -----BAAFFFAAB--BAAFFFAAB----- ------BAAFAAB----BEAFAAB------ -------BAAEB------BAAAB------- --------BAB--------BEB-------- ---------B----------B--------- 
--------AAA--------AAA-------- --------AAA--------AAA-------- ------AAAACAAAAAAAAAAAAA------ ----AAAAAAACCCCCCCAAAAAAAA---- --AAAAAAAAACCCCCCCAAAAAAAAAA-- -AAAAAAAAAACCCCCCCAAAAAAAAAAA- -AAAAAAAAAACCCCCCCAAAAAAAAAAA- AAAAAAAAAACCCCCCCCCAAAAAAAAAAA AAAAAACAACCCCCCCCCCCAAAAAAAAAA AAAAAAAACCCCCCCCCCCCAAAAAAAAAA AAAAAACCCCCCCCCCCCCCAAAAAAAAAA AAAAAAACCCCCCCCCCCCCAAAAAAAAAA AAAAAACCCCCCCCCCCCCCAAAAAAAAAA AAAAAAACCCCCCCCCCCCCAAAAAAAAAA -AAAAACCCCCCCCCCCCCCAAAAAAAAA- -AAAAAACCCCCCCCCCCCCAAAAAAAAA- --BAAAAAACCCCCCCCCCCAAAAAAAA-- --AAAAAAACCCACCCCACCAAAAAAAA-- ---AAAAAAAAAAACCAAAAAAAAAAA--- ---AAAAAAAAAAAAAAAAAAAAAAAA--- ----AAACCCCCAAAAAAAAAAAAAA---- -----AAACCAAAA--AAAAAAAAA----- ------AAACAAA----AAAAAAA------ -------AAAAA------AAAAA------- --------AAA--------AAA-------- ---------A----------A--------- 
--------AAA--------AAA-------- --------AAA--------AAA-------- ------AAAACAAAAAAAAAAAAA------ ----AAAAAAAAAAAAAAAAAAAAAA---- --AAAAAAAAAAAAAAAAAAAAAAAAAA-- -AAAAAAAAAAAAAAAAAAAAAAAAAAAA- -AAAAAAAAAAAAAAAAAAAAAAAAAAAA- AAAAAAAAAAAAAAAAAAAAAAAAAAAAAA AAAAAACAAAAAAAAAAAAAAAAAAAAAAA BAAAAAAAAAAAAAAAAAAAAAAAAAAAAA AAAAAACCCAACCAAAAAAAAAAAAAAAAA BAAAAAAAAACAAAAAAAAAAAAAAAAABB AAAAAACCCAAAAAAAAAAAAAAAAAAABB AAAAAAAAAAAAAAAAAAAAAAAAAAAAAE -AAAAACCAAAAAACCAAAAAAAAAAAAA- -AAAAAAAAAAAAAAAAAAAAAAAAAAAA- --AAAAAAAAACAAAAAAAAAAAAAAAA-- --AAAAAAAAAAAAAAAAAAAAAAAAAA-- ---AAAAAAAAAAAAAAAAAAAAABBA--- ---AAAAAAAAAAAAAAAAAAAAABBE--- ----BAAAAAAAAABBBBAAAAAAAA---- -----EAAAAAAAA--BBAAAAAAA----- ------AAAABBA----BAAAAAA------ -------BAABB------AABBE------- --------AAE--------AAA-------- ---------A----------A--------- 
--------AAA--------AAA-------- --------AAA--------AAA-------- -------AAAAAAAAAAAAAAAAA------ ------AAAAAAAAAAAAAAAAAA------ -----AAAAAAAAAAAAAAAAAAAAA---- ---AAAAAAAAAAAAAAAAAAAAAAAAA-- --ACAAACAAAAAAAAAAAAAAAAAAAA-- -AACAACAAAAAAAAAAAAAAAAAAAAAA- -AAAAACAAAAAAAAAAAAAAAAAAAAAA- -AAAAAAAAAAAAAAAAAAAAAAAAAAAA- -AAAAACCCAACCAAAAAAAAAAAAAAAA- -AAAAAAAAACAAAAAAAAAAAAAAAAAB- -BAAAACCCAAAAAAAAAAAAAAAAAAAB- --AAAAAAAAAAAAAAAAAAAAAAAAAAA- --EAAACCAAAAAACCAAAAAAAAAAAAA- ---AAAAAAAAAAAAAAAAAAAAAAAAAA- ---BBAAAAAACAAAAAAAAAAAAAAAA-- ----BAAAAAAAAAAAAAAAAAAAAAAE-- ----BAAAAAAAAAAAAAAAAAAABBA--- -----AAAAAAAAAAAAAAAAAAAB----- ------AAAAAAA----AAAAAAA------ -------AAAAA------AAAAA------- --------AAB--------AAA-------- ---------A----------E--------- ------------------------------ ------------------------------ 
--------AAA--------AAA-------- --------AAA--------AAB-------- -------AAAAAAEAAAAABAAAA------ -------AABBAAAAAAAAAAABA------ -----AAAAAAAAAAAAAAAAAAAA----- ---AAAAAAAAAAAAAAAAAAAAAAA---- --AAAAAAAAAAAAAAAAAAAAAAAAA--- --AAAAAAAAAAAAAAAAAAAAAAAAAA-- -AAAAAAAAAAAAAAAAAAAAAAAAAAA-- -BAAAAAAAAAAAAAAAAAAAAAAAAAAA- -AAAAAAAAAAAAAAAAAAAAAAAAAAAA- -AAAAAAAAAAAAAAAAAAAAAAAAAAAB- -AAAAAAAAAAAAAAAAAAAAAAAAAAAB- --AAAAAAAAAAAAAAAAAAAAAAAAAA-- --AAAAAAAAAAAAAAAAAAAAAAAAAE-- ---AAAAAAAAAAAAAAAAAAAAAAAA--- ---BBAAAAAAAAAAAAAAAAAAAAAA--- ----EAAAAAAAAAAAAAAAAAAAAA---- ----BAAAAAAAAAAAAAAAAAAABB---- -----AAAAAAAAAAAAAAAAAAAB----- ------AAAAAAA----AAAAAAA------ -------AAAAE------AAAAA------- --------BAA--------AAA-------- ---------A----------B--------- ------------------------------ ------------------------------ 
------------------------------ ------------------------------ ------------------------------ ------------------------------ -----AAAAAEAAAEABAABAAAAA----- ---AAAAAAAEAAAAAAAAAAAAAAA---- --EAAAAAAAAAAAAAAAAAAAAAAAA--- --AAAAAAAAAAAAAAAAAAAAAAAAAB-- -AAAAAAAAAAAAAAAAAAAAAAAAAAB-- -BAAAAAAAAAAAAAAAAAAAAAAAAAAA- -AAAAAAAAAAAAAAAAAAAAAAAAAAAA- -AAAAAAAAAAAAAAAAAAAAAAAAAAAB- -BAAAAAAAAAAAAAAAAAAAAAAAAAAB- --AAAAAAAAAAAAAAAAAAAAAAAAAA-- --AAAAAAAAAAAAAAAAAAAAAAAAAA-- ---AAAAAAAAAAAAAAAAAAAAAAAA--- ---ABAAAAAAAAAAAAAAAAAAAAAA--- ----EAAAAAAAAAAAAAAAAAAAAA---- ----AAAAAAAAAAAAAAAAAAAABB---- -----AAAAAAAAABAAAAAAAAAB----- ------BBBBAAA----EAAAAAA------ -------BBBAA------AAAAE------- --------AAA--------AAA-------- ---------A----------B--------- ------------------------------ ------------------------------ 
------------------------------ ------------------------------ ------------------------------ ------------------------------ ------------------------------ ------ABAAEAAAAAEAAAAAAA------ ----AAAAABEAAAAAAAAAAABBE----- ---AAABAAAEEAAAAABAAAABBBA---- ---ABAAAAAAAAAAAAAAABBAAAAA--- --AAAAEAABBAAAAEEAAABBAAEEA--- --AABEAAAAAEAAAAAAAAABBAAAA--- --AAAAAAAAAAAAAAABBAABBABAE--- ---AABAABBABBBAAABBAAABBBAA--- ---EABAABBABBBAAAAAAAABBBAE--- ----AAEBBBAAAAAAEABBAEAABA---- ----AAEBAAAAAAAAEABBAEAABA---- -----AAAAAAABBAAEAAAABEAA----- -----AAAEBBAEEABAAAAAAEAA----- ------AAAAAAEEAAAAAEEAAA------ -------AAAAA------AABAA------- --------BBE--------ABA-------- ---------B----------B--------- ------------------------------ ------------------------------ ------------------------------ ------------------------------ 
------------------------------ ------------------------------ ------------------------------ ------------------------------ ------------------------------ ------------------------------ -------------AAA-------------- -------------EAA-------------- ------------------------------ ------------------------------ ------------------------------ ------------------------------ ------------------------------ ------------------------------ ------------------------------ ------------------------------ ------------------------------ ------------------------------ ------------------------------ ------------------------------ ------------------------------ ------------------------------ ------------------------------ ------------------------------ ------------------------------ ------------------------------ 
------------------------------ ------------------------------ ------------------------------ ------------------------------ ------------------------------ ------------------------------ -------------BBB-------------- -------------BBB-------------- ------------------------------ ------------------------------ ------------------------------ ------------------------------ ------------------------------ ------------------------------ ------------------------------ ------------------------------ ------------------------------ ------------------------------ ------------------------------ ------------------------------ ------------------------------ ------------------------------ ------------------------------ ------------------------------ ------------------------------ ------------------------------ 
------------------------------ ------------------------------ ------------------------------ ------------------------------ ------------------------------ ------------------------------ -------------AAA-------------- -------------EAA-------------- ------------------------------ ------------------------------ ------------------------------ ------------------------------ ------------------------------ ------------------------------ ------------------------------ ------------------------------ ------------------------------ ------------------------------ ------------------------------ ------------------------------ ------------------------------ ------------------------------ ------------------------------ ------------------------------ ------------------------------ ------------------------------ 
------------------------------ ------------------------------ ------------------------------ ------------------------------ ------------------------------ ------------------------------ -------------AAA-------------- -------------AAA-------------- --------AABABAAA-------------- --------EAEEBABA-------------- ------------------------------ ------------------------------ ------------------------------ ------------------------------ ------------------------------ ------------------------------ ------------------------------ ------------------------------ ------------------------------ ------------------------------ ------------------------------ ------------------------------ ------------------------------ ------------------------------ ------------------------------ ------------------------------ 
------------------------------ ------------------------------ ------------------------------ ------------------------------ ------------------------------ ------------------------------ -------------AAA-------------- -------------AAA-------------- --------AABABABA-------------- --------AABABAEA-------------- ------------------------------ ------------------------------ ------------------------------ ------------------------------ ------------------------------ ------------------------------ ------------------------------ ------------------------------ ------------------------------ ------------------------------ ------------------------------ ------------------------------ ------------------------------ ------------------------------ ------------------------------ ------------------------------ 
------------------------------ ------------------------------ ------------------------------ ------------------------------ ------------------------------ ------------------------------ ------------------------------ ------------------------------ --------BB-------------------- --------BB-------------------- ------------------------------ ------------------------------ ------------------------------ ------------------------------ ------------------------------ ------------------------------ ------------------------------ ------------------------------ ------------------------------ ------------------------------ ------------------------------ ------------------------------ ------------------------------ ------------------------------ ------------------------------ ------------------------------ 
------------------------------ ------------------------------ ------------------------------ ------------------------------ ------------------------------ ------------------------------ ------------------------------ ------------------------------ --------AA-------------------- --------AA-------------------- ------------------------------ ------------------------------ ------------------------------ ------------------------------ ------------------------------ ------------------------------ ------------------------------ ------------------------------ ------------------------------ ------------------------------ ------------------------------ ------------------------------ ------------------------------ ------------------------------ ------------------------------ ------------------------------ 
------------------------------ ------------------------------ ------------------------------ ------------------------------ ------------------------------ ------------------------------ ------------------------------ ------------------------------ --------BB-------------------- --------BB-------------------- ------------------------------ ------------------------------ ------------------------------ ----------------AAAA---------- ----------------BAAB---------- ------------------------------ ------------------------------ ------------------------------ ------------------------------ ------------------------------ ------------------------------ ------------------------------ ------------------------------ ------------------------------ ------------------------------ ------------------------------ 
------------------------------ ------------------------------ ------------------------------ ------------------------------ ------------------------------ ------------------------------ ------------------------------ ------------------------------ --------AABABABABAA----------- --------EABABABABBB----------- -----------------AA----------- -----------------AA----------- -----------------AA----------- ----------------EAAA---------- ----------------AAAA---------- -----------------AB----------- -----------------A------------ ------------------------------ ------------------------------ ------------------------------ ------------------------------ ------------------------------ ------------------------------ ------------------------------ ------------------------------ ------------------------------ 
------------------------------ ------------------------------ ------------------------------ ------------------------------ ------------------------------ ------------------------------ ------------------------------ ------------------------------ --------AABABABABAA----------- --------AABABABABBB----------- -----------------AA----------- -----------------EA----------- -----------------AA----------- ----------------AAAA---------- ----------------AAAA---------- -----------------EA----------- -----------------AA----------- -----------------B------------ ------------------------------ ------------------------------ ------------------------------ ------------------------------ ------------------------------ ------------------------------ ------------------------------ ------------------------------ 
------------------------------ ------------------------------ ------------------------------ ------------------------------ ------------------------------ ------------------------------ ------------------------------ ------------------------------ ------------------------------ ------------------------------ ------------------------------ ------------------------------ ------------------------------ ----------------AEAA---------- ----------------BAAB---------- ------------------------------ ------------------------------ ------------------------------ ------------------------------ ------------------------------ ------------------------------ ------------------------------ ------------------------------ ------------------------------ ------------------------------ ------------------------------ 
