model
size = 22 14 18, scale = 0.05, origin = -y
material 
  colors = A:#111 B:#BBB C:#90F D:#03F E:#0C0 F:#F60 G:#FF3 H:#E00
voxels
---BBB----------BBB--- ---AAA----------AAA--- ---AAA----------AAA--- ---AAA----------AAA--- ---AAA----------AAA--- ---AAA----------AAA--- ---AAA----------AAA--- ---AAA----------AAA--- ---GGG----------GGG--- ---AAA----------AAA--- ---FFF----------FFF--- ---AAA----------AAA--- ---HHH----------HHH--- ---AAA----------AAA--- 
--BBBBB--------BBBBB-- --AAAAA--------AAAAA-- --AAAAA--------AAAAA-- --AAAAA--------AAAAA-- --AAAAA--------AAAAA-- --AAAAA--------AAAAA-- --AAAAA--------AAAAA-- --AAAAA--------AAAAA-- --GGGGG--------GGGGG-- --AAAAA--------AAAAA-- --FFFFF--------FFFFF-- --AAAAA--------AAAAA-- --HHHHH--------HHHHH-- --AAAAA--------AAAAA-- 
--BBBBB--------BBBBB-- --AAAAA--------AAAAA-- --AAAAA--------AAAAA-- --AAAAA--------AAAAA-- --AAAAA--------AAAAA-- --AAAAA--------AAAAA-- --AAAAA--------AAAAA-- --AAAAA--------AAAAA-- --GGGGG--------GGGGG-- --AAAAA--------AAAAA-- --FFFFF--------FFFFF-- --AAAAA--------AAAAA-- --HHHHH--------HHHHH-- --AAAAA--------AAAAA-- 
-BBBBBBB------BBBBBBB- -AAAAAAA------AAAAAAA- -AAAAAAA------AAAAAAA- -AAAAAAA------AAAAAAA- -AAAAAAA------AAAAAAA- -AAAAAAA------AAAAAAA- -AAAAAAA------AAAAAAA- -AAAAAAA------AAAAAAA- -GGGGGGG------GGGGGGG- -AAAAAAA------AAAAAAA- -FFFFFFF------FFFFFFF- -AAAAAAA------AAAAAAA- -HHHHHHH------HHHHHHH- -AAAAAAA------AAAAAAA- 
-BBBBBBB------BBBBBBB- -AAAAAAA------AAAAAAA- -AAAAAAA------AAAAAAA- -AAAAAAA------AAAAAAA- -AAAAAAA------AAAAAAA- -AAAAAAA------AAAAAAA- -AAAAAAA------AAAAAAA- -AAAAAAA------AAAAAAA- -GGGGGGG------GGGGGGG- -AAAAAAA------AAAAAAA- -FFFFFFF------FFFFFFF- -AAAAAAA------AAAAAAA- -HHHHHHH------HHHHHHH- -AAAAAAA------AAAAAAA- 
BBBBBBBBB----BBBBBBBBB AAAAAAAAA----AAAAAAAAA AAAAAAAAA----AAAAAAAAA -AAAAAAA------AAAAAAA- -AAAAAAA------AAAAAAA- -AAAAAAA------AAAAAAA- -AAAAAAA------AAAAAAA- -AAAAAA--------AAAAA-- --GGGGG--------GGGGG-- --AAAAA--------AAAAA-- --FFFFF--------FFFFF-- --AAAAA--------AAAAA-- --HHHHH--------HHHHH-- --AAAAA--------AAAAA-- 
BBBBBBBBB----BBBBBBBBB AAAAAAAAA----AAAAAAAAA AAAAAAAAA----AAAAAAAAA -AAAAAAA------AAAAAAA- -AAAAAAA------AAAAAAA- -AAAAAAA------AAAAAAA- --AAAAA--------AAAAA-- --AAAAA--------AAAAA-- ---GGG----------GGG--- ---AAA----------AAA--- ---FFF----------FFF--- ---AAA----------AAA--- ---HHH----------HHH--- ---AAA----------AAA--- 
BBBBBBBBB----BBBBBBBBB AAAAAAAAA----AAAAAAAAA AAAAAAAAA----AAAAAAAAA -AAAAAAA------AAAAAAA- -AAAAAAA------AAAAAAA- --AAAAA--------AAAAA-- --AAAAA--------AAAAA-- ---AAA----------AAA--- ---------------------- ---------------------- ---------------------- ---------------------- ---------------------- ---------------------- 
BBBBBBBBB----BBBBBBBBB AAAAAAAAA----AAAAAAAAA AAAAAAAAA----AAAAAAAAA -AAAAAAA------AAAAAAA- -AAAAAAA------AAAAAAA- --AAAAA--------AAAAA-- ---AAA----------AAA--- ---------------------- ---------------------- ---------------------- ---------------------- ---------------------- ---------------------- ---------------------- 
BBBBBBBBB----BBBBBBBBB AAAAAAAAA----AAAAAAAAA AAAAAAAAA----AAAAAAAAA -AAAAAAA------AAAAAAA- -AAAAAAA------AAAAAAA- --AAAAA--------AAAAA-- ---------------------- ---------------------- ---------------------- ---------------------- ---------------------- ---------------------- ---------------------- ---------------------- 
BBBBBBBBB----BBBBBBBBB EEEEEEEEE----EEEEEEEEE EEEEEEEEE----EEEEEEEEE -EEEEEEE------EEEEEEE- -EEEEEEE------EEEEEEE- --EEEEE--------EEEEE-- ---------------------- ---------------------- ---------------------- ---------------------- ---------------------- ---------------------- ---------------------- ---------------------- 
BBBBBBBBB----BBBBBBBBB AAAAAAAAA----AAAAAAAAA AAAAAAAAA----AAAAAAAAA -AAAAAAA------AAAAAAA- -AAAAAAA------AAAAAAA- --AAAAA--------AAAAA-- ---------------------- ---------------------- ---------------------- ---------------------- ---------------------- ---------------------- ---------------------- ---------------------- 
BBBBBBBBB----BBBBBBBBB DDDDDDDDD----DDDDDDDDD DDDDDDDDD----DDDDDDDDD -DDDDDDD------DDDDDDD- -DDDDDDD------DDDDDDD- --DDDDD--------DDDDD-- ---------------------- ---------------------- ---------------------- ---------------------- ---------------------- ---------------------- ---------------------- ---------------------- 
BBBBBBBBB----BBBBBBBBB AAAAAAAAA----AAAAAAAAA AAAAAAAAA----AAAAAAAAA -AAAAAAA------AAAAAAA- -AAAAAAA------AAAAAAA- --AAAAA--------AAAAA-- ---------------------- ---------------------- ---------------------- ---------------------- ---------------------- ---------------------- ---------------------- ---------------------- 
BBBBBBBBB----BBBBBBBBB CCCCCCCCC----CCCCCCCCC CCCCCCCCC----CCCCCCCCC -CCCCCCC------CCCCCCC- -CCCCCCC------CCCCCCC- --CCCCC--------CCCCC-- ---------------------- ---------------------- ---------------------- ---------------------- ---------------------- ---------------------- ---------------------- ---------------------- 
-BBBBBBB------BBBBBBB- -AAAAAAA------AAAAAAA- -AAAAAAA------AAAAAAA- -AAAAAAA------AAAAAAA- -AAAAAAA------AAAAAAA- --AAAAA--------AAAAA-- ---------------------- ---------------------- ---------------------- ---------------------- ---------------------- ---------------------- ---------------------- ---------------------- 
-BBBBBBB------BBBBBBB- -AAAAAAA------AAAAAAA- -AAAAAAA------AAAAAAA- --AAAAA--------AAAAA-- --AAAAA--------AAAAA-- ---AAA----------AAA--- ---------------------- ---------------------- ---------------------- ---------------------- ---------------------- ---------------------- ---------------------- ---------------------- 
--BBBBB--------BBBBB-- --AAAAA--------AAAAA-- --AAAAA--------AAAAA-- ---AAA----------AAA--- ---AAA----------AAA--- ---------------------- ---------------------- ---------------------- ---------------------- ---------------------- ---------------------- ---------------------- ---------------------- ---------------------- 
