model
size = 22 14 19, scale = 0.05, origin = -y
material 
  colors = A:#111 B:#FF3 C:#BBB
voxels
---------------------- ---------------------- ---------------------- ---------------------- ---------------------- ---------------------- ---------------------- ---------------------- ---BBB----------BBB--- ---------------------- ---BBB----------BBB--- ---------------------- ---BBB----------BBB--- ---------------------- 
---CCC----------CCC--- ---AAA----------AAA--- ---AAA----------AAA--- ---AAA----------AAA--- ---AAA----------AAA--- ---AAA----------AAA--- ---AAA----------AAA--- ---AAA----------AAA--- --BBBBB--------BBBBB-- ---AAA----------AAA--- --BBBBB--------BBBBB-- ---AAA----------AAA--- --BBBBB--------BBBBB-- ---AAA----------AAA--- 
--CCCCC--------CCCCC-- --AAAAA--------AAAAA-- --AAAAA--------AAAAA-- --AAAAA--------AAAAA-- --AAAAA--------AAAAA-- --AAAAA--------AAAAA-- --AAAAA--------AAAAA-- --AAAAA--------AAAAA-- -BBBBBBB------BBBBBBB- --AAAAA--------AAAAA-- -BBBBBBB------BBBBBBB- --AAAAA--------AAAAA-- -BBBBBBB------BBBBBBB- --AAAAA--------AAAAA-- 
--CCCCC--------CCCCC-- --AAAAA--------AAAAA-- --AAAAA--------AAAAA-- --AAAAA--------AAAAA-- --AAAAA--------AAAAA-- --AAAAA--------AAAAA-- --AAAAA--------AAAAA-- --AAAAA--------AAAAA-- -BBBBBBB------BBBBBBB- --AAAAA--------AAAAA-- -BBBBBBB------BBBBBBB- --AAAAA--------AAAAA-- -BBBBBBB------BBBBBBB- --AAAAA--------AAAAA-- 
-CCCCCCC------CCCCCCC- -AAAAAAA------AAAAAAA- -AAAAAAA------AAAAAAA- -AAAAAAA------AAAAAAA- -AAAAAAA------AAAAAAA- -AAAAAAA------AAAAAAA- -AAAAAAA------AAAAAAA- -AAAAAAA------AAAAAAA- BBBBBBBBB----BBBBBBBBB -AAAAAAA------AAAAAAA- BBBBBBBBB----BBBBBBBBB -AAAAAAA------AAAAAAA- BBBBBBBBB----BBBBBBBBB -AAAAAAA------AAAAAAA- 
-CCCCCCC------CCCCCCC- -AAAAAAA------AAAAAAA- -AAAAAAA------AAAAAAA- -AAAAAAA------AAAAAAA- -AAAAAAA------AAAAAAA- -AAAAAAA------AAAAAAA- -AAAAAAA------AAAAAAA- -AAAAAAA------AAAAAAA- BBBBBBBBB----BBBBBBBBB -AAAAAAA------AAAAAAA- BBBBBBBBB----BBBBBBBBB -AAAAAAA------AAAAAAA- BBBBBBBBB----BBBBBBBBB -AAAAAAA------AAAAAAA- 
CCCCCCCCC----CCCCCCCCC AAAAAAAAA----AAAAAAAAA AAAAAAAAA----AAAAAAAAA -AAAAAAA------AAAAAAA- -AAAAAAA------AAAAAAA- -AAAAAAA------AAAAAAA- -AAAAAAA------AAAAAAA- -AAAAAA--------AAAAA-- -BBBBBBB------BBBBBBB- --AAAAA--------AAAAA-- -BBBBBBB------BBBBBBB- --AAAAA--------AAAAA-- --BBBBBB------BBBBBBB- --AAAAA--------AAAAA-- 
CCCCCCCCC----CCCCCCCCC AAAAAAAAA----AAAAAAAAA AAAAAAAAA----AAAAAAAAA -AAAAAAA------AAAAAAA- -AAAAAAA------AAAAAAA- -AAAAAAA------AAAAAAA- --AAAAA--------AAAAA-- --AAAAA--------AAAAA-- --BBBBB--------BBBBB-- ---AAA----------AAA--- --BBBBB--------BBBBB-- ---AAA----------AAA--- ---BBBB--------BBBBB-- ---AAA----------AAA--- 
CCCCCCCCC----CCCCCCCCC AAAAAAAAA----AAAAAAAAA AAAAAAAAA----AAAAAAAAA -AAAAAAA------AAAAAAA- -AAAAAAA------AAAAAAA- --AAAAA--------AAAAA-- --AAAAA--------AAAAA-- ---AAA----------AAA--- ---BBB----------BBB--- ---------------------- ---BBB----------BBB--- ---------------------- ---BBB----------BBB--- ---------------------- 
CCCCCCCCC----CCCCCCCCC AAAAAAAAA----AAAAAAAAA AAAAAAAAA----AAAAAAAAA -AAAAAAA------AAAAAAA- -AAAAAAA------AAAAAAA- --AAAAA--------AAAAA-- ---AAA----------AAA--- ---------------------- ---------------------- ---------------------- ---------------------- ---------------------- ---------------------- ---------------------- 
CCCCCCCCC----CCCCCCCCC AAAAAAAAA----AAAAAAAAA AAAAAAAAA----AAAAAAAAA -AAAAAAA------AAAAAAA- -AAAAAAA------AAAAAAA- --AAAAA--------AAAAA-- ---------------------- ---------------------- ---------------------- ---------------------- ---------------------- ---------------------- ---------------------- ---------------------- 
CCCCCCCCC----CCCCCCCCC BBBBBBBBB----BBBBBBBBB BBBBBBBBB----BBBBBBBBB -BBBBBBB------BBBBBBB- -BBBBBBB------BBBBBBB- --BBBBB--------BBBBB-- --BB-BB--------BB-BB-- ---BBB----------BBB--- ----B------------B---- ---------------------- ---------------------- ---------------------- ---------------------- ---------------------- 
CCCCCCCCC----CCCCCCCCC AAAAAAAAA----AAAAAAAAA AAAAAAAAA----AAAAAAAAA -AAAAAAA------AAAAAAA- -AAAAAAA------AAAAAAA- --AAAAA--------AAAAA-- ---------------------- ---------------------- ---------------------- ---------------------- ---------------------- ---------------------- ---------------------- ---------------------- 
CCCCCCCCC----CCCCCCCCC BBBBBBBBB----BBBBBBBBB BBBBBBBBB----BBBBBBBBB -BBBBBBB------BBBBBBB- -BBBBBBB------BBBBBBB- --BBBBB--------BBBBB-- --BB-BB--------BB-BB-- ---BBB----------BBB--- ----B------------B---- ---------------------- ---------------------- ---------------------- ---------------------- ---------------------- 
CCCCCCCCC----CCCCCCCCC AAAAAAAAA----AAAAAAAAA AAAAAAAAA----AAAAAAAAA -AAAAAAA------AAAAAAA- -AAAAAAA------AAAAAAA- --AAAAA--------AAAAA-- ---------------------- ---------------------- ---------------------- ---------------------- ---------------------- ---------------------- ---------------------- ---------------------- 
CCCCCCCCC----CCCCCCCCC BBBBBBBBB----BBBBBBBBB BBBBBBBBB----BBBBBBBBB -BBBBBBB------BBBBBBB- -BBBBBBB------BBBBBBB- --BBBBB--------BBBBB-- --BB-BB--------BB-BB-- ---BBB----------BBB--- ----B------------B---- ---------------------- ---------------------- ---------------------- ---------------------- ---------------------- 
-CCCCCCC------CCCCCCC- -AAAAAAA------AAAAAAA- -AAAAAAA------AAAAAAA- -AAAAAAA------AAAAAAA- -AAAAAAA------AAAAAAA- --AAAAA--------AAAAA-- ---------------------- ---------------------- ---------------------- ---------------------- ---------------------- ---------------------- ---------------------- ---------------------- 
-CCCCCCC------CCCCCCC- -AAAAAAA------AAAAAAA- -AAAAAAA------AAAAAAA- --AAAAA--------AAAAA-- --AAAAA--------AAAAA-- ---AAA----------AAA--- ---------------------- ---------------------- ---------------------- ---------------------- ---------------------- ---------------------- ---------------------- ---------------------- 
--CCCCC--------CCCCC-- --AAAAA--------AAAAA-- --AAAAA--------AAAAA-- ---AAA----------AAA--- ---AAA----------AAA--- ---------------------- ---------------------- ---------------------- ---------------------- ---------------------- ---------------------- ---------------------- ---------------------- ---------------------- 
