model
size = 22 14 18, scale = 0.05, origin = -y
material 
  colors = A:#111 B:#FF3 C:#BBB
voxels
---CCC----------CCC--- ---AAA----------AAA--- ---AAA----------AAA--- ---AAA----------AAA--- ---AAA----------AAA--- ---AAA----------AAA--- ---AAA----------AAA--- ---AAA----------AAA--- ---BBB----------BBB--- ---AAA----------AAA--- ---BBB----------BBB--- ---AAA----------AAA--- ---BBB----------BBB--- ---AAA----------AAA--- 
--CCCCC--------CCCCC-- --AAAAA--------AAAAA-- --AAAAA--------AAAAA-- --AAAAA--------AAAAA-- --AAAAA--------AAAAA-- --AAAAA--------AAAAA-- --AAAAA--------AAAAA-- --AAAAA--------AAAAA-- --BBBBB--------BBBBB-- --AAAAA--------AAAAA-- --BBBBB--------BBBBB-- --AAAAA--------AAAAA-- --BBBBB--------BBBBB-- --AAAAA--------AAAAA-- 
--CCCCC--------CCCCC-- --AAAAA--------AAAAA-- --AAAAA--------AAAAA-- --AAAAA--------AAAAA-- --AAAAA--------AAAAA-- --AAAAA--------AAAAA-- --AAAAA--------AAAAA-- --AAAAA--------AAAAA-- --BBBBB--------BBBBB-- --AAAAA--------AAAAA-- --BBBBB--------BBBBB-- --AAAAA--------AAAAA-- --BBBBB--------BBBBB-- --AAAAA--------AAAAA-- 
-CCCCCCC------CCCCCCC- -AAAAAAA------AAAAAAA- -AAAAAAA------AAAAAAA- -AAAAAAA------AAAAAAA- -AAAAAAA------AAAAAAA- -AAAAAAA------AAAAAAA- -AAAAAAA------AAAAAAA- -AAAAAAA------AAAAAAA- -BBBBBBB------BBBBBBB- -AAAAAAA------AAAAAAA- -BBBBBBB------BBBBBBB- -AAAAAAA------AAAAAAA- -BBBBBBB------BBBBBBB- -AAAAAAA------AAAAAAA- 
-CCCCCCC------CCCCCCC- -AAAAAAA------AAAAAAA- -AAAAAAA------AAAAAAA- -AAAAAAA------AAAAAAA- -AAAAAAA------AAAAAAA- -AAAAAAA------AAAAAAA- -AAAAAAA------AAAAAAA- -AAAAAAA------AAAAAAA- -BBBBBBB------BBBBBBB- -AAAAAAA------AAAAAAA- -BBBBBBB------BBBBBBB- -AAAAAAA------AAAAAAA- -BBBBBBB------BBBBBBB- -AAAAAAA------AAAAAAA- 
CCCCCCCCC----CCCCCCCCC AAAAAAAAA----AAAAAAAAA AAAAAAAAA----AAAAAAAAA -AAAAAAA------AAAAAAA- -AAAAAAA------AAAAAAA- -AAAAAAA------AAAAAAA- -AAAAAAA------AAAAAAA- -AAAAAA--------AAAAA-- --BBBBB--------BBBBB-- --AAAAA--------AAAAA-- --BBBBB--------BBBBB-- --AAAAA--------AAAAA-- --BBBBB--------BBBBB-- --AAAAA--------AAAAA-- 
CCCCCCCCC----CCCCCCCCC AAAAAAAAA----AAAAAAAAA AAAAAAAAA----AAAAAAAAA -AAAAAAA------AAAAAAA- -AAAAAAA------AAAAAAA- -AAAAAAA------AAAAAAA- --AAAAA--------AAAAA-- --AAAAA--------AAAAA-- ---BBB----------BBB--- ---AAA----------AAA--- ---BBB----------BBB--- ---AAA----------AAA--- ---BBB----------BBB--- ---AAA----------AAA--- 
CCCCCCCCC----CCCCCCCCC AAAAAAAAA----AAAAAAAAA AAAAAAAAA----AAAAAAAAA -AAAAAAA------AAAAAAA- -AAAAAAA------AAAAAAA- --AAAAA--------AAAAA-- --AAAAA--------AAAAA-- ---AAA----------AAA--- ---------------------- ---------------------- ---------------------- ---------------------- ---------------------- ---------------------- 
CCCCCCCCC----CCCCCCCCC AAAAAAAAA----AAAAAAAAA AAAAAAAAA----AAAAAAAAA -AAAAAAA------AAAAAAA- -AAAAAAA------AAAAAAA- --AAAAA--------AAAAA-- ---AAA----------AAA--- ---------------------- ---------------------- ---------------------- ---------------------- ---------------------- ---------------------- ---------------------- 
CCCCCCCCC----CCCCCCCCC AAAAAAAAA----AAAAAAAAA AAAAAAAAA----AAAAAAAAA -AAAAAAA------AAAAAAA- -AAAAAAA------AAAAAAA- --AAAAA--------AAAAA-- ---------------------- ---------------------- ---------------------- ---------------------- ---------------------- ---------------------- ---------------------- ---------------------- 
CCCCCCCCC----CCCCCCCCC BBBBBBBBB----BBBBBBBBB BBBBBBBBB----BBBBBBBBB -BBBBBBB------BBBBBBB- -BBBBBBB------BBBBBBB- --BBBBB--------BBBBB-- ---------------------- ---------------------- ---------------------- ---------------------- ---------------------- ---------------------- ---------------------- ---------------------- 
CCCCCCCCC----CCCCCCCCC AAAAAAAAA----AAAAAAAAA AAAAAAAAA----AAAAAAAAA -AAAAAAA------AAAAAAA- -AAAAAAA------AAAAAAA- --AAAAA--------AAAAA-- ---------------------- ---------------------- ---------------------- ---------------------- ---------------------- ---------------------- ---------------------- ---------------------- 
CCCCCCCCC----CCCCCCCCC BBBBBBBBB----BBBBBBBBB BBBBBBBBB----BBBBBBBBB -BBBBBBB------BBBBBBB- -BBBBBBB------BBBBBBB- --BBBBB--------BBBBB-- ---------------------- ---------------------- ---------------------- ---------------------- ---------------------- ---------------------- ---------------------- ---------------------- 
CCCCCCCCC----CCCCCCCCC AAAAAAAAA----AAAAAAAAA AAAAAAAAA----AAAAAAAAA -AAAAAAA------AAAAAAA- -AAAAAAA------AAAAAAA- --AAAAA--------AAAAA-- ---------------------- ---------------------- ---------------------- ---------------------- ---------------------- ---------------------- ---------------------- ---------------------- 
CCCCCCCCC----CCCCCCCCC BBBBBBBBB----BBBBBBBBB BBBBBBBBB----BBBBBBBBB -BBBBBBB------BBBBBBB- -BBBBBBB------BBBBBBB- --BBBBB--------BBBBB-- ---------------------- ---------------------- ---------------------- ---------------------- ---------------------- ---------------------- ---------------------- ---------------------- 
-CCCCCCC------CCCCCCC- -AAAAAAA------AAAAAAA- -AAAAAAA------AAAAAAA- -AAAAAAA------AAAAAAA- -AAAAAAA------AAAAAAA- --AAAAA--------AAAAA-- ---------------------- ---------------------- ---------------------- ---------------------- ---------------------- ---------------------- ---------------------- ---------------------- 
-CCCCCCC------CCCCCCC- -AAAAAAA------AAAAAAA- -AAAAAAA------AAAAAAA- --AAAAA--------AAAAA-- --AAAAA--------AAAAA-- ---AAA----------AAA--- ---------------------- ---------------------- ---------------------- ---------------------- ---------------------- ---------------------- ---------------------- ---------------------- 
--CCCCC--------CCCCC-- --AAAAA--------AAAAA-- --AAAAA--------AAAAA-- ---AAA----------AAA--- ---AAA----------AAA--- ---------------------- ---------------------- ---------------------- ---------------------- ---------------------- ---------------------- ---------------------- ---------------------- ---------------------- 
