model
size = 18 32 16, scale = 0.05, origin = -y
material 
  colors = A:#080 B:#0A0 C:#070 D:#050 E:#111 F:#0B0 G:#00E
voxels
202-2(3A15-)5A14-3A71-2A15-4A13-2(6A12-)5AD12-6A13-4A15-2A266-7A11-2A4BA11-2A2BDBA2(10-3A5B)10-5A14-4AB14-3AB13-4A2B12-4A2B11-6A2B10-8A9-2(9AB8-)10A8-10A9-8A10-8A11-6A13-4A195-6A11-8A9-9A9-2A5B2A9-2A2(7B8-3A)7B8-5A2B11-5A6B7-5A2(6B6-6A)6B6-7A5B6-9AB7-10A2B2(6-11AB)2(6-12A)7-10A8-10A9-8A11-6A140-6C11-8C10-8A9-2(10A8-)2A8B8-2A8B7-3A8B6-4A8B5-7A6B4(5-7A5BE)5-8A6B4-10A2B5-11A3B2(4-12A2B)4-13AB5-2(12A6-)12A7-10A9-8A11-6A47-6D12-7D11-8D2(10-9C)9-10C8-10A6-12A6-13A5-4A9B7-2A2(9B4-5A)9B4-7A6B5-7A5BE5-7A5BG2(5-7A5BE)4-9A6B3-2(11A3B4-)2(12A2B4-)13AB2(4-14A)5-13A5-12A7-10A9-8A11-AD4A29-7D11-8D10-9D9-10C8-11C6-13C5-12A6-2(13A5-)4A3(9B4-5A)9B4-2(7A5BE5-)7A2(5BE4-8A)5BE4-9A6B3-11A3B3-12A4B2(2-13A3B)2-15AB3-2(14A4-)14A5-11AD6-12A7-10A9-3A2F3A13-2A13-7D11-8D10-10D8-11C7-12C5-14C2(4-13AC)4-13A5-4A8B5-5A11B2-2(5A10B3-)7A5B5-3(8A5BE4-)9A4BE4-9A6B2(2-12A4B)2-13A3B3(2-15AB)3-2(14A4-)14A5-12A7-10A9-2A4F2A12-4A12-7D11-8D10-10D8-11C7-12C5-14C4-12A6-13AC4-13A5-4A8B5-3(5A10B3-)8A4(6B3-9A)6B2-10A6B2(2-12A4B)2-13A3B2(2-15AB)2-14A2B2-16A3-14A4-14A5-12A7-10A9-A6FA11-6A11-7D11-8D10-10D8-11C7-12C5-14C4-12A6-13AC4-13A5-4A8B5-3(5A10B3-)8A4(6B3-9A)6B2-10A6B2-12A4B2(2-13A3B)2(2-15AB)2-12A4B2-16A3-14A4-14A5-12A7-10A9-A6FA11-6A11-7D11-8D10-10D8-11C7-12C5-14C2(4-13AC)4-13A5-4A8B5-5A11B2-2(5A10B3-)8A4B5-4(9A4BE4-)11A4B2-12A4B2(2-13A3B)2(2-15AB)2-12A4B3-2(14A4-)14A5-12A7-10A9-2A4FAD12-4A12-7D11-8D10-9D9-10C8-11C6-13C5-12A6-2(13A5-)4A3(9B4-5A)9B4-2(8A4BE5-)8A2(4BE4-9A)4BE4-11A4B3-11A3B3-2(13A3B2-)14A2B2-14A2B3-11A3B2(4-14A)5-12A6-12A7-10A9-3A2F3A13-2A13-6D12-7D11-8D2(10-9C)9-10C8-10A6-12A6-13A5-4A9B6-3A2(9B4-5A)9B4-8A5B5-8A4BE5-8A4BG2(5-8A4BE)4-11A4B3-11A3B2(4-12A2B)2(4-13AB)4-11A3B4-14A5-13A5-12A7-10A9-8A11-6A104-6C11-8C10-8A9-2(10A8-)2A7BA2(7-3A8B)6-4A8B5-8A5B4(5-8A4BE)5-10A4B4-10A2B5-12A2B3(4-13AB)5-11AB2(6-12A)7-10A9-8A11-6A158-6A11-8A10-3AD4A10-8A8-3AB6A2(8-3A7B)8-6AB11-6A5B7-6A2(5B6-7A)5B6-9AB8-9AB7-11AB2(6-12A)6-11AB6-12A7-10A8-10A9-8A11-6A263-3ABA13-3A2B13-2(5A14-)4A13-5AB12-5AB11-8A10-8A9-3(10A8-)10A9-8A10-8A11-6A13-4A282-2(A17-)5A14-3A89-2A15-4A13-3AD2A2(12-6A)13-4A15-2A117-
