model
size = 32, scale = 0.05, origin = -y
material 
  colors = A:#E00 B:#B00 C:#EEE D:#111 E:#D00 F:#BBB G:#DDD
voxels
3A9(6(2B2A)2B6A)6(2B2A)2B3A133C2D5C2D4C2D2(5C2D10C2D5C2D2C4D)2(5C2D10C2D5C4D2C2D)5C2D7C8D2C2D4C2D2C8D4C8D2C2D4C2D2C8D66C3A9(6(2B2A)2B6A)6(2B2A)2B291AC12(30A2C)30AC258A5E2A5E4A5E2A5E5A6(2B2A)2B291AC8(30A2C)30ACD30A2D30ADC30A2C30AC258AE3FE2AE3FE3A3D2FE2AE3FE2A33B8(30A2B)30ABC8(30A2C)30ACD30A2D30ADC30A2C30ACB8(30A2B)AE3FE2AE3FE3ADE3FE2AE3FEA34B8(30A2B)30ABC8(30A2C)30ACD30A2D30ADC30A2C30ACB8(30A2B)AEF2GE2AEFGDE5D2GFE2AE2GFEAB3A6(2B2A)2B291AC3(30A2C)30ACD6(30A2D)30ADC30A2C30AC258AEFGDE2AEFGDED3AD2GFE2AEDGFE5A6(2B2A)2B291AC3(30A2C)30ACD6(30A2D)30ADC30A2C30AC258A4ED2A4ED4A2D3EA3D3E2A33B8(30A2B)30ABC8(30A2C)30ACD30A2D30ADC30A2C30ACB8(30A2B)4A2D6A2D4A2(DA)D7A34B8(30A2B)30ABC8(30A2C)30ACD30A2D30ADC30A2C30ACB8(30A2B)A3EDE7AD5ADA2DA5EAB3A6(2B2A)2B291AC8(30A2C)30ACD30A2D30ADC30A2C30AC258AEDF5D3FAD4A3F3AE3FE5A6(2B2A)2B291AC12(30A2C)30AC258AEFDF2D2AD2GDAD3A3F3AE3FE2A33B8(30A2B)30ABC12(30A2C)30ACB8(30A2B)AED2FE3AD2G6DF2G3AE2GFEA34B8(30A2B)30ABC3(30A2C)30ACD6(30A2D)30ADC30A2C30ACB8(30A2B)AE3FE3AFDF6DFG2D2A2DGFEAB3A6(2B2A)2B291AC3(30A2C)30ACD6(30A2D)30ADC30A2C30AC258A5E4ADA6D2A2(DA)D4E5A6(2B2A)2B291AC4(30A2C)2(30ACD)30A2C2(30ADC)3(30A2C)30AC266AD2A7DADA2D7A33B8(30A2B)30ABC4(30A2C)2(30ACD)30A2C2(30ADC)3(30A2C)30ACB8(30A2B)9A2DA9D9A34B8(30A2B)30ABC5(30A2C)30ADC30A2D30ACD4(30A2C)30ACB8(30A2B)11A7DA4D7AB3A6(2B2A)2B291AC5(30A2C)30ADC30A2D30ACD4(30A2C)30AC266A9D4AD11A6(2B2A)2B291AC3(30A2C)30ACD6(30A2D)30ADC30A2C30AC258A5E5DE8D2EA2D4E2A33B8(30A2B)30ABC3(30A2C)30ACD6(30A2D)30ADC30A2C30ACB8(30A2B)AEF2G2DAE2F7D2GFEADE2DFEA34B8(30A2B)30ABC12(30A2C)30ACB8(30A2B)AEFGDE2AEFDF7DGFEADEGDFEAB3A6(2B2A)2B291AC12(30A2C)30AC258AE2FDE2AE2(FD)A2DAD3FEADE3FE5A6(2B2A)2B291AC8(30A2C)30ACD30A2D30ADC30A2C30AC258AE3FE2A2D2F3D2(ADE3FE)2A33B8(30A2B)30ABC8(30A2C)30ACD30A2D30ADC30A2C30ACB8(30A2B)A5EA3D3E4AD4EA2D4EA34B8(30A2B)30ABC8(30A2C)30ACD30A2D30ADC30A2C30ACB8(30A2B)6A2DAD8A2(D5A)B3A6(2B2A)2B291AC3(30A2C)30ACD6(30A2D)30ADC30A2C30AC258A3E2D2AE2D2E2ADAE2D2E2A2D3E5A6(2B2A)2B291AC3(30A2C)30ACD6(30A2D)30ADC30A2C30AC258AEFGDE2AEDGFE4AE2DFE2AEDGFE2A33B8(30A2B)30ABC8(30A2C)30ACD30A2D30ADC30A2C30ACB8(30A2B)AEF2GE2AEDGFE4AE2GFE2AE2GFEA34B8(30A2B)30ABC8(30A2C)30ACD30A2D30ADC30A2C30ACB8(30A2B)AE3FE2AEFDFE4AE3FE2AE3FEAB3A6(2B2A)2B291AC8(30A2C)30ACD30A2D30ADC30A2C30AC258AE3FE2AEFDFE4AE3FE2AE3FE5A6(2B2A)2B291AC12(30A2C)30AC258A5E2A5E4A5E2A5E5A9(6(2B2A)2B6A)6(2B2A)2B3A133C2D5C2D4C2(2D5C2D10C2D5C4D2C)2D2(5C2D10C2D5C2D2C4D)5C2D7C8D2C2D4C2D2C8D4C8D2C2D4C2D2C8D66C3A8(6(2B2A)2B6A)6(2B2A)2B3A
