model
size = 23 28 21, scale = 0.05, origin = -y
material 
  colors = A:#EEE B:#111 C:#FFC D:#E00
voxels
----------------------- ----------------------- ----------------------- ----------------------- ----------------------- ----------------------- ----------------------- ----------------------- ----------------------- ----------------------- ----------------------- ----------------------- ----------------------- -------------ABB------- ----------AAAAA-------- ---------AAAAAA-------- ---------AAAAA--------- ----------AAA---------- ----------------------- ----------------------- ----------------------- ----------------------- ----------------------- ----------------------- ----------------------- ----------------------- ----------------------- ----------------------- 
----------------------- ----------------------- ----------------------- ----------------------- ----------------------- ----------------------- ----------------------- ----------------------- ----------------------- ----------------------- ----------------------- ----------------------- ----------------------- -------------AAB------- -------CAAAAAAABB------ ------CCAAAAAAABB------ -------CAAAAAAB-------- --------AAAAA---------- -----------B----------- ----------------------- ----------------------- ----------------------- ----------------------- ----------------------- ----------------------- ----------------------- ----------------------- ----------------------- 
----------------------- ----------------------- ----------------------- ----------------------- ----------------------- ----------------------- ----------------------- ----------------------- ----------------------- ----------------------- ----------------------- ----------------------- ----------------------- -------------AAAB------ -------CAAAAAAAAB------ ------CCAAAAAAAAB------ ------CCAAAAAAAB------- -------CAAAABBB-------- ----------------------- ---------------B------- ----------------------- ----------------------- ----------------------- ----------------------- ----------------------- ----------------------- ----------------------- ----------------------- 
----------------------- ----------------------- ----------------------- ----------------------- ----------------------- ----------------------- ----------------------- ----------------------- ----------------------- ----------------------- ----------------------- ----------------------- ----------------------- -------------AAAB------ ------CCA----AAAAB----- ----CCCCAA---AAAAB----- -----CCCAAA--AAABB----- ------CCA----BBB------- ----------------------- ---------------B------- ----------------------- ----------------------- ----------------------- ----------------------- ----------------------- ----------------------- ----------------------- ----------------------- 
----------------------- ---------------B------- ---------------B------- ---------------B------- ----------------------- ----------------------- ----------------------- ----------------------- ----------------------- --------------BB------- --------------BB------- ----------------B------ ----------------B------ -------------AAAAB----- -----CCC-----AAAAB----- ----CCCCA----AAAAB----- ----CCCCAA--BAAAAB----- -----CCCA----BAABB----- --------------BBB------ --------------BBB------ ---------------B------- ---------------B------- ------------------B---- ----------------------- ----------------------- ----------------------- ----------------------- ----------------------- 
--------------AABBB---- -----------AAAAAB------ -----------AAAAA------- --------------ABBB----- --------------BBB------ ------------AAABB------ --------------BB------- --------------BB------- --------------BB------- --------------BB------- --------------BB-BB---- --------------BBBB----- -----------AAAAAABB---- ------------AAAAABB---- ----C-C-----AAAAAAB---- ---CCCCC----AAAAAAB---- ----CCCC-----AAAAB----- -----C------BAAAAB----- ------------BBBBBB----- --------------BBB------ --------------BBBB----- --------------BBBB----- ---------------B-BB---- -----------------BB---- ----------------------- ----------------------- ----------------------- ----------------------- 
--------------AAA------ ----------AAAAAAAA----- -----------AAAAAAA----- -----------AAAAAAB----- -----------AAAAABB----- ------------AAAABB----- ------------AAABBB----- ------------AAA-BB----- ------------AAA-BB----- -----------AAAAAB------ ---------BAAAAAABB----- ---------BAAAAAAABB---- ----------AAAAAAAAB---- ----------AAAAAAAAB---- ----C-----AAAAAAAAB---- --CCCC------AAAAAAB---- --CCCCC-----BAAAAAB---- ---C--------BAAAAB----- -------------B-BBB----- --------------B-BB----- ----------------BB----- --------------BBBBB---- -------------BBBBBB---- --------------B--BB---- -----------------B----- ---------------B------- ----------------------- ----------------------- 
--------------AAAA----- ----------AAAAAAAAB---- ----------AAAAAAAA----- ----------AAAAAAAAB---- ----------AAAAAAABB---- -----------AAAAAABBB--- -----------AAAAABBB---- ----------BAAAAAB------ ----------BAAAAAB------ ---------BAAAAAAABB---- ---------BAAAAAAABB---- --------BBAAAAAAAAB---- --------BBAAAAAAAAB---- --------BBAAAAAAAABB--- --------BBAAAAAAAABB--- -CCCC----BBAAAAAAAB---- -CCCCC-----BBAAAAABB--- CCCC--------BAAAAABB--- -C----------BBAAAB----- --------------BBBBB---- -------------BBBBBBB--- -------------BBAAABB--- ------------BBBBAAAB--- ------------BBBBBBBB--- -------------B-BBBB---- ---------------B-B----- ---------------B------- ----------------------- 
-------------AAAAA----- ----------AAAAAAAA----- ----------AAAAAAAABB--- ----------AAAAAAAABB--- ----------AAAAAAAB----- ----------AAAAAAAB----- ----------AAAAAAAB----- ----------AAAAAAABB---- ----------AAAAAAAB----- ----------AAAAAAAB----- ----------AAAAAAAB----- ----------AAAAAAAAB---- ----------AAAAAAAAB---- ----------AAAAAAAABB--- ----------AAAAAAAABBB-- --CC-------AAAAAAABBB-- -CCC---------AAAAABBB-- -CC---------BAAAAABBB-- CCC----------BAAAABBB-- -------------BAAAAABB-- -------------BAAAAAAB-- -------------BAAAAAAB-- -------------BAAAAAAB-- -------------BAAAAAAB-- -------------BBAAAABB-- --------------BBBBB---- ----------------B------ ----------------------- 
-------------AAAAAB---- ----------AAAAAAAAB---- ----------AAAAAAAAB---- ----------AAAAAAAAB---- ----------AAAAAAAABB--- ----------AAAAAAABBB--- ----------AAAAAAABBBB-- ----------AAAAAAABBB--- ----------AAAAAAABB---- ----------AAAAAAABB---- ----------AAAAAAAB----- ----------AAAAAAAAB---- ----------AAAAAAAABB--- ----------AAAAAAAABB--- ----------AAAAAAAAB---- --CC--------AAAAAAB---- -CCC---------AAAAAB---- -CCC-------BBAAAAAB---- CCC---------BBAAAAB---- -------------BAAAAAB--- -----------BBAAAAAAABB- ------------BAAAAAAABB- ------------BAAAAAAAB-- ------------BBAAAAAABB- -------------BAAAAAAB-- --------------BBAABB--- --------------BBBB----- ----------------B------ 
-------------AAAAA----- ----------AAAAAAAA----- ----------AAAAAAAA----- ----------AAAAAAAA----- ----------AAAAAAAA----- ----------AAAAAAAB----- ----------AAAAAAAB-B--- ----------AAAAAAAB-B--- ----------AAAAAAABB---- ----------AAAAAAABB---- ----------AAAAAAAABBB-- ----------AAAAAAAABBB-- ----------AAAAAAAABBB-- ----------AAAAAAAABBB-- ----------AAAAAAAABBB-- --C--------BAAAAAABBB-- -CCC-------BBAAAAABBB-- -CC--------BBAAAAABBB-- CC-----------BAAAAB---- -------------BAAAAABBB- ------------BAAAAAAABB- ------------BAAAAAAABB- ------------BAAAAAAABB- -------------BAAAAAAB-- -------------BAAAAAAB-- --------------BAAABB--- ---------------BBB----- ----------------------- 
-------------AAAAA----- ----------AAAAAAAAB---- ----------AAAAAAAAB---- ----------AAAAAAAAB---- ----------AAAAAAAAB---- ----------AAAAAAAB----- ----------AAAAAAAB----- ----------AAAAAAAB----- ----------AAAAAAAB----- ----------AAAAAAABB---- ----------AAAAAAAABB--- ----------AAAAAAAAB---- ----------AAAAAAAAB---- ----------AAAAAAAAB---- ---------BAAAAAAAABB--- ------------AAAAAAB---- -C-----------AAAAABB--- -C-----------AAAAABB--- CC------------AAAAB---- --------------AAAAAB--- -------------AAAAAAAB-- -------------DDAAAAAB-- -------------AAAAAAAB-- --------------AAAAAABB- -----------BBBAAAAAABB- ------------BBBAAABB--- ---------------BBB----- ----------------------- 
-------------AAAAA----- ----------AAAAAAAA----- ----------AAAAAAAA----- ----------AAAAAAAA----- ----------AAAAAAAAB---- ----------AAAAAAAB----- ----------AAAAAAABB---- ----------AAAAAAABB---- ----------AAAAAAAB----- ----------AAAAAAAB----- ----------AAAAAAAB----- ---------BAAAAAAAABB--- --------BBAAAAAAAABBB-- --------BBAAAAAAAABBB-- ---------BAAAAAAAABBB-- ---------BBAAAAAAABBB-- -CC--------BAAAAAABBB-- -CC---------BAAAAABB--- CC----------BBAAABB---- ------------BBAAABBB--- ------------BBAAAAABB-- -------------BAAAAA-B-- ------------BBAAAAABB-- ------------BBAAAAABB-- --------------BAAAA-B-- --------------BBBBBBB-- ----------------------- ----------------------- 
-------------AAAAABB--- ----------AAAAAAAABB--- ----------AAAAAAAABBB-- ----------AAAAAAAABBB-- ----------AAAAAAAABBB-- ----------AAAAAAABBB--- ----------BAAAAABB----- ----------BAAAAABB----- --------BBBAAAAABB----- --------BBBAAAAAABB---- -------BBBAAAAAAAB----- --------BBAAAAAAAB-B--- --------BBAAAAAAAABB--- ---------BAAAAAAAAB---- ---------BAAAAAAAAB---- -----------BAAAAAAB---- -CCC-------BAAAAAAB---- -CCC--------BAAAAAB---- CCC-----------AAAB----- ------------BBAABBB---- ------------BBB-BBBBB-- -------------BBBBBBBB-- -------------BBBBBBBB-- --------------BBBBB-B-- ---------------BBBBBB-- -----------------B--B-- ----------------------- ----------------------- 
------------AAAAA-BB--- ----------AAAAAAAABB--- ----------AAAAAAAAB---- ----------AAAAAAAAB---- ------------AAAAAB----- ------------AAAAABB---- ------------AAAABB----- ------------AAAABB----- ------------AAAAB------ --------B---AAAABBB---- --------B--AAAAABBB---- ---------BAAAAAABBB---- ---------BAAAAAAABB---- ---------BAAAAAAABBB--- ----------BAAAAAAAB---- ------------AAAAAAB---- --CCC-------AAAAAABB--- -CCCC--------AAAAABB--- CCC---------BBAAABB---- -------------BBBBBBB--- ---------------BBB-B--- ---------------B-B-B--- --------------B--B----- ---------------B-B----- -----------------B----- ----------------------- ----------------------- ----------------------- 
------------AAAA-BBBB-- ----------AAAAAAA-BBB-- ----------AAAAAAA------ -------------AAA------- ----------------------- ----------------------- ---------------B------- -------------B-B------- -------------B-BB------ --------------BBBB----- --------------BBBB----- ---------------BBB----- --------------BBBB----- --------------BBB------ ----------------BB----- ------------AAAAABBB--- -CCCCC------AAAAAAB---- -CCCCC--------AAAAB---- -CC----------BBABB----- ---------------BBBB---- ---------------B-B-B--- ----------------------- ----------------------- ----------------------- ----------------------- ----------------------- ----------------------- ----------------------- 
-------------------BB-- ----------------------- ----------------------- ----------------------- ----------------------- ----------------------- ----------------------- ----------------------- ----------------------- ----------------------- ----------------------- ---------------B------- ---------------BB------ ----------------B------ ----------------B------ -----CCCA-AAAAAABB----- --CCCCCCA-AAAAAABBB---- --CCCCCC---AAAAABB----- --------------BBBB----- ---------------BB------ ----------------------- ----------------------- ----------------------- ----------------------- ----------------------- ----------------------- ----------------------- ----------------------- 
---------------------BB ----------------------- ----------------------- ----------------------- ----------------------- ----------------------- ----------------------- ----------------------- ----------------------- ----------------------- ----------------------- ----------------------- ----------------------- ----------------------- ----------------------- -----CCCAAAAAAABBB----- ---CCCCCAAAAAAA-BB----- ----CCCCAAAAAAA-BB----- ----------------B------ ----------------------- ----------------------- ----------------------- ----------------------- ----------------------- ----------------------- ----------------------- ----------------------- ----------------------- 
----------------------B ----------------------- ----------------------- ----------------------- ----------------------- ----------------------- ----------------------- ----------------------- ----------------------- ----------------------- ----------------------- ----------------------- ----------------------- ----------------------- ----------------------- ------CCAAAAAA--B------ -----CCCAAAAAA---B----- -----CCCAAAAAA--B------ ----------------------- ----------------------- ----------------------- ----------------------- ----------------------- ----------------------- ----------------------- ----------------------- ----------------------- ----------------------- 
----------------------- ----------------------- ----------------------- ----------------------- ----------------------- ----------------------- ----------------------- ----------------------- ----------------------- ----------------------- ----------------------- ----------------------- ----------------------- ----------------------- ----------------------- -------CAAAAA---------- -------CAAAAA---------- -------CCAAAA---------- ----------------------- ----------------------- ----------------------- ----------------------- ----------------------- ----------------------- ----------------------- ----------------------- ----------------------- ----------------------- 
----------------------- ----------------------- ----------------------- ----------------------- ----------------------- ----------------------- ----------------------- ----------------------- ----------------------- ----------------------- ----------------------- ----------------------- ----------------------- ----------------------- ----------------------- --------CAAA----------- --------CAAA----------- ---------AA------------ ----------------------- ----------------------- ----------------------- ----------------------- ----------------------- ----------------------- ----------------------- ----------------------- ----------------------- ----------------------- 
