model
size = 32 28 24, scale = 0.05, origin = -y
material 
  colors = A:#FF0
voxels
16-8A23-26(10A22-)10A21-13A2(18-2A10-2A)4(18-2A2-6A2-2A)14(18-14A)18-2A-8A-5(2A18-2A2-6A2-)2A18-14A17-16A16-A14-A16-A3-8A3-5(A16-A2-10A2-)A16-A2-10A-2A10(16-A2-10A2-A)16-A2-10A-2A16-A2-11A-6(A16-A2-10A2-)A16-16A15-18A14-2A3-8A4-A14-2A2-A8-A3-5(A14-2A-A10-A2-)A14-4A10-2A-3(A14-2A-A10-A2-)A14-4A7(10-A2-A14-2A-A)10-2A-7(A14-2A-A10-A2-)A14-4A10-4A13-20A12-2A2-11A4-A12-2A2-A10-2A24(2-A12-2A-A12-A)2-A2(12-4A)12-20A11-A4-13A3-A10-A3-A13-24(A2-A10-A2-A14-)A2-A10-4A14-4A10-22A10-A3-14A3-A10-A2-A14-A2-24(A10-A-A16-A-)A10-3A16-3A10-23A8-A3-16A3-A8-A2-A16-A2-24(A8-A-A18-A-)A8-3A18-3A8-24A8-A3-17A2-A8-A2-A17-24(A-A8-A-A18-)A-A8-3A18-3A8-24A8-A2-18A2-A8-A-A18-A-A2(8-2A20-2A)4-6A20-2A3-7A20-2A2-8A20-2A2-3A3-11(2A20-2A8-)2A20-2A4-2A2-2A2(20-2A3-7A)20-2A5-5A4(20-2A8-2A)20-2A8-24A8-A2-18A2-A8-A-A18-A-A2(8-2A20-2A)4-6A20-2A3-A4-2A20-2A2-A4-3A20-2A-A3-2A-2A20-2A-4A3-2(2A20-5A5-)5(2A20-4A6-)2(2A20-5A5-)2A20-2A-3A4-2A20-2A-6A-2A20-2A-9A20-2A2-8A20-2A4-6A4(20-2A8-2A)20-2A8-24A8-A2-18A2-A8-A-A18-A-A2(8-2A20-2A)5-5A20-2A4-A3-2A20-2A2-A4-3A20-2A-A2-3A-2A20-3A3-A3-2A20-3A2-A4-2A20-3A-2A4-2A20-3A-A3(5-2A20-5A)2(5-2A20-3A-A)5-2A20-3A2-A4-2A20-3A3-A3-2(2A20-2A-A-4A-)2A20-2A2-3A3-2A20-2A4-6A4(20-2A8-2A)20-2A8-24A8-A2-18A2-A8-A-A18-A-A2(8-2A20-2A)5-5A20-2A4-A3-2A20-2A2-A4-3A20-2A-A2-3A-2A20-3A3-A3-2A20-3A2-A4-2A20-3A-2A4-2A20-3A-A3(5-2A20-5A)2(5-2A20-3A-A)5-2A20-3A2-A4-2A20-3A3-A3-2A20-2A-A-4A-2A20-2A-9A20-2A2-2A4-2A20-2A4-6A4(20-2A8-2A)20-2A8-24A8-A2-18A2-A8-A-A18-A-A2(8-2A20-2A)4-6A20-2A3-A2-A-2A20-2A2-A4-3A20-2A-A3-2A-2A20-2A-4A3-2(2A20-5A5-)5(2A20-4A6-)2(2A20-5A5-)2A20-2A-3A4-2A20-2A-6A-2A20-2A-9A20-2A2-2A3-3A20-2A4-6A4(20-2A8-2A)20-2A8-24A8-A2-18A2-A8-A-A18-A-A2(8-2A20-2A)4-6A20-2A3-7A20-2A2-8A20-2A2-3A3-11(2A20-2A8-)2A20-2A4-2A2-2A2(20-2A3-7A)20-2A5-5A4(20-2A8-2A)20-2A8-24A8-A3-16A3-A8-A2-A16-A2-17(A8-A-A18-A-)4(A8-3A18-A-)3(A8-A-A18-A-)A8-3A18-3A9-23A8-A3-16A3-A8-A2-A16-A2-18(A8-A-A18-A-)A8-3A5(18-A-A8-A-A)18-A-A8-3A18-3A9-22A10-A3-14A3-A10-A2-A14-A2-24(A10-A-A16-A-)A10-3A16-3A11-20A11-A4-13A3-A10-A3-A13-24(A2-A10-A2-A14-)A2-A10-4A14-4A11-20A12-A4-10A4-A12-A3-A10-2A48(2-A12-A)2-A2(12-4A)13-18A14-A5-7A4-A14-A3-2A7-A3-24(A14-A2-A10-A2-)A14-4A10-4A15-16A16-A14-A16-A4-7A3-24(A16-A2-10A2-)A16-16A18-12A19-2(2A10-2A18-)24(2A2-6A2-2A18-)14A21-8A23-26(10A22-)10A7-
