model
size = 26 32 3, scale = 0.05, origin = -y
material 
  colors = A:#5BCEFA B:#F5A9B8 C:#FFF D:#F5F8FA E:#F5F0F1 F:#EFC405
voxels
427-3(5A5-5A11-)3(5B5-5B11-)3(5C5-5C11-)3(5B5-5B11-)2(5A5-5A11-)5A5-5A448-3(5A5-5A11-)3(5B5-5B11-)3(5C5-5C11-)3(5B5-5B11-)2(5A5-5A11-)5A5-5A31-8(D25-E25-)D5A20-E5A20-D5A20-E5B20-D5B20-E5B20-D5C20-E5C20-D5C20-E5B20-D5B20-E5B20-D5A20-E5A20-D5A20-F25-
