model
size = 30 9 9, scale = 0.05, origin = -y
material 
  colors = A:#F6F B:#C3F C:#C6C
voxels
------------------------------ ------------------------------ ------------------------------ ------------------------------ -------------------------C---- ------------------------------ ------------------------------ ------------------------------ ------------------------------ 
------------------------------ ------------------------------ ------------------------------ ------------------------AAA--- ------------------------AAA--- ------------------------AAA--- ------------------------------ ------------------------------ ------------------------------ 
------------------------------ ------------------------------ -----------------------BBBBB-- -----------------------BAAAB-- -----------------------BAAAB-- -----------------------BAAAB-- -----------------------BBBBB-- ------------------------------ ------------------------------ 
------------------------------ ------------------------AAA--- -----------------------BAAAB-- ----------------------CAAAAAC- -C---C----------------CAAAAAC- ----------------------CAAAAAC- -----------------------BAAAB-- ------------------------AAA--- ------------------------------ 
-------------------------C---- ------------------------AAA--- -----------------------BAAAB-- -C---C----------------CAAAAAC- CAAAAAAAAAAAAAAAAAAAAACAAAAACC -C---C----------------CAAAAAC- -----------------------BAAAB-- ------------------------AAA--- -------------------------C---- 
------------------------------ ------------------------AAA--- -----------------------BAAAB-- ----------------------CAAAAAC- -C---C----------------CAAAAAC- ----------------------CAAAAAC- -----------------------BAAAB-- ------------------------AAA--- ------------------------------ 
------------------------------ ------------------------------ -----------------------BBBBB-- -----------------------BAAAB-- -----------------------BAAAB-- -----------------------BAAAB-- -----------------------BBBBB-- ------------------------------ ------------------------------ 
------------------------------ ------------------------------ ------------------------------ ------------------------AAA--- ------------------------AAA--- ------------------------AAA--- ------------------------------ ------------------------------ ------------------------------ 
------------------------------ ------------------------------ ------------------------------ ------------------------------ -------------------------C---- ------------------------------ ------------------------------ ------------------------------ ------------------------------ 
