model
size = 26 27 8, scale = 0.05, origin = -y
material 
  colors = A:#EEE B:#111
voxels
-----------BBAA----------- ----------BBBAAA---------- ---------BBBBAAAA--------- --------BBBBBAAAAA-------- --------BBBBBAAAAA-------- --------BBBBBAAAAA-------- -------BBBBBBAAAAAA------- -------BBBBBBAAAAAA------- -------BBBBBBAAAAAA------- -------BBBBBBAAAAAA------- -------BBBBBBAAAAAA------- -------BBBBBBAAAAAA------- -------B----BA----A------- -----------BBAA----------- -------BBBBBBAAAAAA------- -------BBBBBBAAAAAA------- -------BBBBBBAAAAAA------- -------BBBBBBAAAAAA------- --------BBBBBAAAAA-------- -------------------------- -------------------------- -------------------------- -------------------------- -------------------------- -------------------------- -------------------------- -------------------------- 
-----------BBAA----------- ---------BBBBAAAA--------- ---------BBBBAAAA--------- --------BBBAAAAAAA-------- --------BBBBBAAAAA-------- -------BBBBBBAAAAAA------- -------BBBBBBAAAAAAA------ ------BBBBBBBAAAAAAA------ ------BBBBBBBAAAAAAA------ ------BBBBBBBAAAAAAA------ ------BBBBBBBAAAAAAA------ ------BBAAABBAABBBAA------ ------BAAAAABABBBBBA------ ------BAAAABBAABBBBA------ ------BBAABBBAAABBAA------ ------BBBBBBBAAAAAAA------ ------BBBBBBBAAAAAAA------ ------BBBBBBBAAAAAAA------ -------BBBBBBAAAAAA------- --------BBBBBAAAAA-------- -------------------------- -------------------------- -------------------------- -------------------------- -------------------------- -------------------------- -------------------------- 
-----------BBAA----------- ---------BBBBAAAA--------- --------BBB----AA--------- -------BBBBAAAAAAAA------- -------BBBBBBAAAAAA------- ------BBBBBBBAAAAAAA------ ------BBBBBBBAAAAAAA------ ------BBBBBBBAAAAAAA------ ------BBBBBBBAAAAAAA------ ------BBBBBBBAAAAAAA------ ------BBBBBBBAAAAAAA------ ------BBAAABBAAAAAAA------ ------BAAAAABAAAAAAA------ ------BAAAABBAAAAAAA------ ------BBAABBBAAAAAAA------ ------BBBBBBBAAAAAAA------ ------BBBBBBBAAAAAAA------ ------BBBBBBBAAAAAAA------ ------BBBBBBBAAAAAAA------ -------BBBBBBAAAAAA------- --------BBBBBAAAAA-------- -------------------------- -------------------------- -------------------------- -------------------------- -------------------------- -------------------------- 
-----------BBAA----------- ---------BBBBAAAA--------- --------BBB----AAA-------- -------BBBBAAAAAAAA------- ------BBBBBBBAAAAAAA------ -----BBBBBBBBAAAAAAAA----- -----BBBBBBBBAAAAAAAA----- -----BBBBBBBBAAAAAAAA----- -----BBBBBBBBAAAAAAAA----- -----BBBBBBBBAAAAAAAA----- -----BBBBBBBBAAAAAAAA----- -----BBBAAABBAAAAAAAA----- -----BBAAAAABAAAAAAAA----- -----BBAAAABBAAAAAAAA----- -----BBBAABBBAAAAAAAA----- -----BBBBBBBBAAAAAAAA----- -----BBBBBBBBAAAAAAAA----- -----BBBBBBBBAAAAAAAA----- -----BBBBBBBBAAAAAAAA----- ------BBBBBBBAAAAAAA------ -------BBBBBBAAAAAA------- --------BBBBBAAAAA-------- -------------------------- -------------------------- -------------------------- -------------------------- -------------------------- 
-----------BBAA----------- ---------BBBBAAAA--------- --------BBBBBAAAAA-------- -------BBBBAABBAAAA------- ------BBBBBBBAAAAAAA------ -----BBBBBBBBAAAAAAAA----- ----BBBBBBBBBAAAAAAAAA---- ----BBBBBBBBBAAAAAAAAA---- ----BBBBBBBBBAAAAAAAAA---- ----BBBBBBBBBAAAAAAAAA---- -----BBBBBBBBAAAAAAAA----- -----BBBAAABBAABBBAAA----- -----BBAAAAABABBBBBAA----- -----BBAAAABBAABBBBAA----- ----BBBBAABBBAAABBAAAA---- ----BBBBBBBBBAAAAAAAAA---- ----BBBBBBBBBAAAAAAAAA---- ----BBBBBBBBBAAAAAAAAA---- ----BBBBBBBBBAAAAAAAAA---- -----BBBBBBBBAAAAAAAA----- ------BBBBBBBAAAAAAA------ -------BBBBBBAAAAAA------- --------BBBBBAAAAA-------- -------------------------- -------------------------- -------------------------- -------------------------- 
-----------BBAA----------- ---------BBBBAAAA--------- --------BBBBBAAAAA-------- -------BBBBBBAAAAAA------- ------BBBBBBBAAAAAAA------ -----BBBBBBBBAAAAAAAA----- ----BBBBBBBBBAAAAAAAAA---- ----BBBBBBBBBAAAAAAAAA---- ----BBBBBBBBBAAAAAAAAA---- ----BBBBBBBBBAAAAAAAAA---- -----BBBBBBBBAAAAAAAA----- -----BBBBBBBBAAAAAAAA----- -----BBBBBBBBAAAAAAAA----- -----BBBBBBBBAAAAAAAA----- ----BBBBBBBBBAAAAAAAAA---- ---BBBBBBBBBBAAAAAAAAAA--- --BBBBBBBBBBBAAAAAAAAAAA-- --BBBBBBBBBBBAAAAAAAAAAA-- -BB-BBBBBBBBBAAAAAAAAA-AA- -B---BBBBBBBBAAAAAAAA---A- BB---BBBBBBBBAAAAAAAA---AA B-----BBBBBBBAAAAAAA-----A B------BBBBBBAAAAAA------A B------BBBBBBAAAAAA------A B-----BB----------AA-----A B---BBB------------AAA---A BBBBB----------------AAAAA 
-----------BBAA----------- ---------BBBBAAAA--------- --------BBBBBAAAAA-------- -------BBBBBBAAAAAA------- ------BBBBBBBAAAAAAA------ -----BBBBBBBBAAAAAAAA----- ----BBBBBBBBBAAAAAAAAA---- ----BBBBBBBBBAAAAAAAAA---- ----BBBBBBBBBAAAAAAAAA---- ----BBBBBBBBBAAAAAAAAA---- -----BBBBBBBBAAAAAAAA----- -----BBBBBBBBAAAAAAAA----- -----BBBBBBBBAAAAAAAA----- -----BBBBBBBBAAAAAAAA----- ----BBBBBBBBBAAAAAAAAA---- ---BBBBBBBBBBAAAAAAAAAA--- ---BBBBBBBBBBAAAAAAAAAA--- ---BBBBBBBBBBAAAAAAAAAA--- --BABBBBBBBBBAAAAAAAAABA-- -BAABBBBBBBBBAAAAAAAABBBA- -BAAABBBBBBBBAAAAAAAABBBA- -AAAABBBBBBBBAAAAAAABBBBBA -AAAAAABBBBBBAAAAAABBBBBBA -AAAAAABBBBBBAAAAAABBBBBBA -AAAAA-B-----------ABBBBBA -AAA----------------AABBBA -------------------------- 
-------------------------- -------------------------- -------------------------- -------------------------- -------------------------- -------------------------- -------------------------- -------------------------- -------------------------- -------------------------- -------------------------- -------------------------- -------------------------- -------------------------- -------------------------- -------------------------- -------------------------- -------------------------- --BBBBB-------------AAA--- --BBBBBB-----------AAAAA-- --BBBBBB----------AAAAAAA- --BBBBBB----------AAAAAA-- ---BBBBB----------AAAAA--- ----BBB-----------AAAA---- ------B------------A------ -------------------------- -------------------------- 
