model
size = 27 18 20, scale = 0.05, origin = -y
material 
  colors = A:#630 B:#CC6 C:#FF9 D:#300 E:#996 F:#633
voxels
--------------------------- --------------------------- --------------------------- --------------------------- --------------------------- --------------------------- -----CCC------------------- ---CCBBB------------------- -CCBBCCC------------------- CBBCCCB-------------------- CCCCBBC-------------------- --CCC---------------------- --------------------------- --------------------------- --------------------------- --------------------------- --------------------------- --------------------------- 
-------CCCCCCCCCCCCC------- -------BBBBBBBBBBBBB------- --------------------------- --------------------------- --------------------------- ------BBB------------------ -----CAAB------------------ ---CCCAAB------------------ -CCCCCAC------------------- CCCCCCC-------------------- CCCCCCC-------------------- --CCC---------------------- --------------------------- --------------------------- --------------------------- --------------------------- --------------------------- --------------------------- 
-----CCCCCCCCCCCCCCCCC----- -----BBBBBBBBBBBBBABBB----- -----BBBBBBBBBBBBBBB------- --------------------------- --------------------------- ------BBBBBB--------------- ------BBBBBB--------------- ------BBBBB---------------- ------BBBB----------------- ------BBB------------------ --------------------------- --------------------------- --------------------------- --------------------------- --------------------------- --------------------------- --------------------------- --------------------------- 
----CCCCCCCCCCCCCCCCCCC---- ----BBBBBBBBBBBBBBABBBB---- ----BBBBBBBBBBBBBBABBC----- -----BAAAAAAAAAAAAAB------- -----BAAAAAAAAAAAAA-------- -----BFFFFFFBB------------- -----BFFFFFFB-------------- -----BFFFFBB--------------- -----BFFBBB---------------- -----BFFBB----------------- -----BBBB------------------ --------------------------- --------------------------- --------------------------- --------------------------- --------------------------- -----DDDDD----------------- -----DDDDD----------------- 
---CCCCCCCCCCCCCCCCCCCCC--- ---BBBBBBBBBBBBBBBABBBBB--- ---BBBBBBBBBBBBBBBABBBB---- ----BAAAAAAAAAAAAAABBB----- ----BAAAAAAAAAAAAAAB------- ----BAAAAAAAAAAAAAA-------- ----BAAAAAAAAAAAAA--------- ----AAAAAA----------------- ----AAAAAA----------------- ----AAAAAA----------------- ----AAAAAD----------------- -----DDDDD----------------- -----DDDDD----------------- -----DDDDD----------------- -----DDDDD----------------- -----DDDDD----------------- ----DDDDDDD---------------- ----DDDDDDD---------------- 
--CCCCCCCCCCCCCCCCCCCCCCC-- --CBABBBBBBBBBBBBBABBBBBB-- --BBABBBBBBBBBBBBBABBBBB--- ---BAAAAAAAAAAAAAAABBBB---- ---BAAAAAAAAAAAAAAABBB----- ---BAAAAAAAAAAAAAAAB------- ---BAAAAAAAAAAAAAAA-------- ---BAAAAA-AAAAAAAA--------- ---AAAAAAAD---------------- ---AAAAAAAD---------------- ---AAAAAAAD---------------- ----DAAAAAD---------------- ----DAAAAAD---------------- ----DDDDDDD---------------- ----DD---DD---------------- ----DD---DD---------------- ---DDD---DAD--------------- ---DDD---DDD--------------- 
--CCCCCCCCCCCCCCCCCCCCCCCC- --BAABBBBBBBBBBBBBABBBBBBB- --BAABBBBBBBBBBBBBABBBBBBC- --BAAAAAAAAAAAAAAAABBBBBB-- --BAAAAAAAAAAAAAAAABBBBB--- --BAAAAAAAAAAAAAAAABBBB---- --CAAAAAAAAAAAAAAAAB------- --BAAAAAAAAAAAAAAAA-------- --BAAAAAAAAD-AAAAA--------- --AAAAAAAAAD--------------- --AAAAAAAAAD--------------- ---DAAAAAAAD--------------- ---DAAAAAAAD--------------- ---DDDDDDDAD--------------- ---DD-----DD--------------- ---DD-----DD--------------- --DDD-----DDD-------------- --DDD-----DDD-------------- 
--CCCCCCCCCCCCCCCCCCCCCCCCC --BAABBBBBBBBBBBBBABBBBBBBB --BAABBBBBBBBBBBBBABBBBBBB- --BAAAAAAAAAAAAAAAABBBBBBB- --BAAAAAAAAAAAAAAAABBBBBB-- --BAAAAAAAAAAAAAAAABBBBB--- --BAAAAAAAAAAAAAAAABBBB---- --BAAAAAAAAAAAAAAAAB------- --BAAAAAAAAAAAAAAAA-------- --BAAAAAAAAAAAAAAA--------- --AAAAAAAAAAAAA------------ ---DAAAAAAAAD-------------- ---DAAAAAAAAD-------------- ---DDDDDDDDDD-------------- ---D-------DD-------------- ---D-------DD-------------- --DD-------DDD------------- --DD-------DDD------------- 
--CCCCCCCCCCCCCCCCCCCCCCCCC --BAABBBBBBBBBBBBBAABEBBBBC --BAABBBBBBBBBBBBBAABEEEBB- --BAAAAAAAAAAAAAAAAABEEEBB- --BAAAAAAAAAAAAAAAAABBBBB-- --BAAAAAAAAAAAAAAAAABBBB--- --BAAAAAAAAAAAAAAAAABBC---- --BAAAAAAAAAAAAAAAABB------ --BAAAAAAAAAAAAAAAAB------- --BAAAAAAAAAAAAAAAA-------- --AAAAAAAAAAAAA------------ ---DAAAAAAAAD-------------- ---DAAAAAAAAD-------------- ---DDDDDDDDDD-------------- ---D--------D-------------- ---D--------D-------------- --DD--------DD------------- --DD--------DD------------- 
--CCCCCCCCCCCCCCCCCCCCCCCCC --BAABBBBBBBBBBBBBAABEBBBBB --BAABBBBBBBBBBBBBAABEEEBB- --BAAAAAAAAAAAAAAAAABEEEBB- --BAAAAAAAAAAAAAAAAABEEEB-- --BAAAAAAAAAAAAAAAAABBBB--- --BAAAAAAAAAAAAAAAAABBB---- --BAAAAAAAAAAAAAAAABB------ --BAAAAAAAAAAAAAAAAC------- --BAAAAAAAAAAAAAAAA-------- --AAAAAAAAAAAAA------------ ---DAAAAAAAAD-------------- ---DAAAAAAAAD-------------- ---DDDDDDDDDD-------------- ---D--------D-------------- ---D--------D-------------- --DD--------DD------------- --DD--------DD------------- 
--CCCCCCCCCCCCCCCCCCCCCCCCC --BAABBBBBBBBBBBBBAAEEEEBBB --BAABBBBBBBBBBBBBAAEEEEBC- --BAAAAAAAAAAAAAAAAAEBBBBB- --BAAAAAAAAAAAAAAAAAEBBBB-- --BAAAAAAAAAAAAAAAAAEBBB--- --BAAAAAAAAAAAAAAAAAEBB---- --BAAAAAAAAAAAAAAAABB------ --BAAAAAAAAAAAAAAAAB------- --BAAAAAAAAAAAAAAAA-------- --AAAAAAAAAAAAA------------ ---DAAAAAAAAD-------------- ---DAAAAAAAAD-------------- ---DDDDDDDDDD-------------- ---D--------D-------------- ---D--------D-------------- --DD--------DD------------- --DD--------DD------------- 
--CCCCCCCCCCCCCCCCCCCCCCCCC --BAABBBBBBBBBBBBBAAEEEEBBB --BAABBBBBBBBBBBBBAAEEEEBB- --BAAAAAAAAAAAAAAAAAEEEEBB- --BAAAAAAAAAAAAAAAAABBBBB-- --BAAAAAAAAAAAAAAAAABBBB--- --BAAAAAAAAAAAAAAAAABBB---- --BAAAAAAAAAAAAAAAABB------ --BAAAAAAAAAAAAAAAAC------- --BAAAAAAAAAAAAAAAA-------- --AAAAAAAAAAAAA------------ ---DAAAAAAAAD-------------- ---DAAAAAAAAD-------------- ---DDDDDDDDDD-------------- ---D--------D-------------- ---D--------D-------------- --DD--------DD------------- --DD--------DD------------- 
--CCCCCCCCCCCCCCCCCCCCCCCCC --BAABBBBBBBBBBBBBAAEEBBBBC --BAABBBBBBBBBBBBBAEEEBBBB- --BAAAAAAAAAAAAAAAAEEEBBBB- --BAAAAAAAAAAAAAAAAEBBBBB-- --BAAAAAAAAAAAAAAAAEBBBC--- --BAAAAAAAAAAAAAAAABBBB---- --BAAAAAAAAAAAAAAAAB------- --BAAAAAAAAAAAAAAAA-------- --BAAAAAAAAAAAAAAA--------- --AAAAAAAAAAAAA------------ ---DAAAAAAAAD-------------- ---DAAAAAAAAD-------------- ---DDDDDDDDAD-------------- ---D-------DD-------------- ---D-------DD-------------- --DD-------DDD------------- --DD-------DDD------------- 
--CCCCCCCCCCCCCCCCCCCCCCCC- --BAABBBBBBBBBBBBBAAEEBBBB- --BAABBBBBBBBBBBBBAEEEBBBB- --BAAAAAAAAAAAAAAAAEEEBBB-- --BAAAAAAAAAAAAAAAAEBBBB--- --BAAAAAAAAAAAAAAAABBBB---- --CAAAAAAAAAAAAAAAAB------- --BAAAAAAAAAAAAAAAA-------- --BAAAAAAAAD--AAAA--------- --AAAAAAAAAD--------------- --AAAAAAAAAD--------------- ---DAAAAAAAD--------------- ---DAAAAAAAD--------------- ---DDDDDDDDD--------------- ---DD-----DD--------------- ---DD-----DD--------------- --DDD-----DDD-------------- --DDD-----DDD-------------- 
--CCCCCCCCCCCCCCCCCCCCCCC-- --BBEBBBBBBBBBBBBBAAEEBEB-- --BBEBBBBBBBBBBBBBAEEBBB--- ---BEAAAAAAAAAAAAAAEEBB---- ---BEAAAAAAAAAAAAAAEBC----- ---BEAAAAAAAAAAAAAAB------- ---BAAAAAAAAAAAAAAA-------- ---BAAAAA-AAAAAAAA--------- ---AAAAAAAD---------------- ---AAAAAAAD---------------- ---AAAAAAAD---------------- ----DAAAAAD---------------- ----DAAAAAD---------------- ----DDDDDAD---------------- ----DD---DD---------------- ----DD---DD---------------- ---DDD---DDD--------------- ---DDD---DDD--------------- 
---CCCCCCCCCCCCCCCCCCCCC--- ---BBBBBBBBBBBBBBBAABBBB--- ---CBBBBBBBBBBBBBBAEBBB---- ----BAAAAAAAAAAAAAABBB----- ----BAAAAAAAAAAAAAAB------- ----BAAAAAAAAAAAAAA-------- ----BAAAAAAAAAAAAA--------- ----AAAAAA----------------- ----AAAAAD----------------- ----AAAAAD----------------- ----AAAAAD----------------- -----DDDDD----------------- -----DDDDD----------------- -----DDDDD----------------- -----DDDDD----------------- -----DDDDD----------------- ----DDDDDDD---------------- ----DDDDDDD---------------- 
----CCCCCCCCCCCCCCCCCCC---- ----BBBBBBBBBBBBBBABBBC---- ----BBBBBBBBBBBBBBABBB----- -----BAAAAAAAAAAAAAB------- -----BAAAAAAAAAAAAA-------- -----BBBFBBBBB------------- -----FFFFBBBB-------------- -----FFFFBBB--------------- -----FFFFBB---------------- -----FFFFB----------------- -----BBBB------------------ --------------------------- --------------------------- --------------------------- --------------------------- --------------------------- -----DDDDD----------------- -----DDDDD----------------- 
-----CCCCCCCCCCCCCCCCC----- -----BBBBBBBBBBBBBABBB----- -----BBBBBBBBBBBBBAB------- --------------------------- --------------------------- ------BBBBBB--------------- ------BBBBBB--------------- ------BBBBB---------------- ------BBBB----------------- ------BBB------------------ --------------------------- --------------------------- --------------------------- --------------------------- --------------------------- --------------------------- --------------------------- --------------------------- 
-------CCCCCCCCCCCCC------- -------BBBBBBBBBBBBB------- --------------------------- --------------------------- --------------------------- ------BBB------------------ -----CAAB------------------ ---CCCAAB------------------ -CCCCCCC------------------- CCCCCCC-------------------- CCCCCCC-------------------- --CCC---------------------- --------------------------- --------------------------- --------------------------- --------------------------- --------------------------- --------------------------- 
--------------------------- --------------------------- --------------------------- --------------------------- --------------------------- --------------------------- -----CCC------------------- ---CCBBB------------------- -CCBBCCC------------------- CBBCCCB-------------------- CCCCBBC-------------------- --CCC---------------------- --------------------------- --------------------------- --------------------------- --------------------------- --------------------------- --------------------------- 
