model
size = 16 10 18, scale = 0.05, origin = -y
material 
  colors = A:#DDD B:#111 C:#EEE D:#BBB E:#FF3 F:#3FF G:#FF6
voxels
----BBB--------- ------BB-------- -------BBBBBBBBB ---------------- ---------------- ---------------- ---------------- ---------------- ---------------- ---------------- 
---BBB---------- -----AA--------- ------AAAAAAAAAB -------ADAACAAAA ---------------- ---------------- ---------------- ---------------- ---------------- ---------------- 
--BBB----------- ----AA---------- -----AA--------- ------AAAAAAAAAB -------AADCAADAA ---------------- ---------------- ---------------- ---------------- ---------------- 
-BB------------- --AA------------ ----A----------- -----DA--------- ------AAAAAAAAAB -------AAAAAAAAA ---------------- ---------------- ---------------- ---------------- 
BBB------------- D-AAAA---------- --CAAE---------- ---CAAAA-------- ----DAAAAAAAA--- ------AAACAAAAAB --------AAAAEAAA --------F------F --------F------F ---------------- 
BAA------------- A-AAAA---------- --DAAA---------- ---AAACA-------- ----ACCAAAA----- ------CDAAAAA--- --------AAEADAAB --------AAAAAAA- ---------------- ---------------- 
BAC------------- A-AAAA---------- --EACC---------- ---AAAAA-------- ----AAAAAAA----- ------ADAAAAA--- --------AAACAAAB --------AAAAAAA- ---------AAADA-- ---------------- 
BAA------------- C-AAAA---------- --AAAA---------- ---AAAAA-------- ----CAAAAAA----- ------AADAAAA--- --------ACAAAAAB --------AAAAAAA- ---------AAAAA-- ----------EAA--- 
BCA------------- A-AAAA---------- --CACA---------- ---AAAAA-------- ----AAAAAAA----- ------CCACAAA--- --------AAAAAAAB --------AAAAAAA- ---------AAAAA-- ----------ACD--- 
BAA------------- D-AEAA---------- --AACA---------- ---CAAAA-------- ----AAAAAAA----- ------AAAAAAA--- --------CAAAAAAB --------AAAAAAA- ---------DAAAA-- ----------AAA--- 
BAD------------- A-AAAA---------- --CACA---------- ---AAAAA-------- ----CAAAAAA----- ------GAAAAAA--- --------AAADCAAB --------AAAAAAA- ---------AAAAA-- ----------ADA--- 
BCA------------- C-AAAA---------- --AAAA---------- ---AAAAA-------- ----ADAAAAA----- ------ADCAAAA--- --------AAAAAAAB --------AAAAAAA- ---------AAAAA-- ---------------- 
BCA------------- A-AAAA---------- --DAAA---------- ---AAAAA-------- ----ACAAAAA----- ------ACAAAAA--- --------AAACAAAB --------AAAAAAA- ---------------- ---------------- 
BBB------------- E-AAAA---------- --AACC---------- ---CAADA-------- ----AAAAAAAAA--- ------AAAAAAAAAB --------AAAAAEAA --------F------F --------F------F ---------------- 
-BB------------- --AA------------ ----A----------- -----AA--------- ------AAAAAAAAAB -------AAAAAAAAA ---------------- ---------------- ---------------- ---------------- 
--BBB----------- ----AA---------- -----DA--------- ------AAAAAAAAAB -------DAADAADAD ---------------- ---------------- ---------------- ---------------- ---------------- 
---BBB---------- -----AA--------- ------AAAAAAAAAB -------CAAAAAAAA ---------------- ---------------- ---------------- ---------------- ---------------- ---------------- 
----BBB--------- ------BB-------- -------BBBBBBBBB ---------------- ---------------- ---------------- ---------------- ---------------- ---------------- ---------------- 
