model
size = 15 21 9, scale = 0.05, origin = -y
material 
  colors = A:#AAA B:#888 C:#BBB D:#EEE E:#FF3 F:#3FF
voxels
-------D------- -------D------- -------D------- -------D------- -------D------- --------------- --------------- --------------- --------------- --------------- --------------- --------------- --------------- --------------- --------------- --------------- --------------- --------------- --------------- --------------- --------------- 
------BDB------ ------BDB------ ------ADA------ ------ADA------ ------DDD------ -------D------- -------D------- -------D------- -------D------- -------D------- --------------- --------------- --------------- --------------- --------------- --------------- --------------- --------------- --------------- --------------- -------F------- 
----BBBCBBB---- ----BBBCBBB---- ----AAACAAA---- ----AAACAAA---- ----DDCCCDD---- ------BCB------ ------BCB------ ------ACA------ ------ACA------ ------DDD------ -------D------- -------D------- -------D------- -------D------- -------D------- -------D------- -------D------- -------D------- -------D------- -------D------- -------D------- 
---EBBBCBBBE--- ---EBBBCBBBE--- ---EAAACAAAE--- ---EAAACAAAE--- ---DCCCCCCDD--- ----EBBCBBE---- ----EBBCBBE---- ----EAACAAE---- ----EAACAAE---- ----DDDCDDD---- ------BCB------ ------BCB------ ------ACA------ ------ACA------ ------ACA------ ------ACA------ ------ACA------ ------ACA------ ------CCC------ ------CCC------ ------DCD------ 
F-BBBBBCBBBBB-F --BBBBBCBBBBB-- --AAAAACAAAAA-- --AAAAACAAAAA-- --DCCCCCCCDDD-- ---BBBBCBBBB--- ---BBBBCBBBB--- ---AAAACAAAA--- ---AAAACAAAA--- ---DDDDCDDDD--- ----BEBCBEB---- ----BEBCBEB---- ----AEACAEA---- ----AEACAEA---- ----AEACAEA---- ----AEACAEA---- ----AEACAEA---- ----AEACAEA---- ----CCCCCCC---- ----CCCCCCC---- ----DDDCDDD---- 
FBBBBBBCBBBBBBF -BBBBBBCBBBBBB- -AAAAAACAAAAAA- -AAAAAACAAAAAA- -DCCCCCCCCDDDD- --BBBBBCBBBBB-- --BBBBBCBBBBB-- --AAAAACAAAAA-- --AAAAACAAAAA-- --DDDDDCDDDDD-- ---BBBBCBBBB--- ---BBBBCBBBB--- ---AAAACAAAA--- ---AAAACAAAA--- ---AAAACAAAA--- ---AAAACAAAA--- ---AAAACAAAA--- ---AAAACAAAA--- ---CCCCCCCCC--- ---CCCCCCCCC--- ---DCCCCCCCD--- 
BBBB-------BBBB BBBB-------BBBB AAAA-------AAAA AAAA-------AAAA DCCC-------DDDD -BBB-------BBB- -BBB-------BBB- -AAA-------AAA- -AAA-------AAA- -DDD-------DDD- --BB-------BB-- --BB-------BB-- --AA-------AA-- --AA-------AA-- --AA-------AA-- --AA-------AA-- --AA-------AA-- --AA-------AA-- --CC-------CC-- --CC-------CC-- --DC-------CD-- 
CCC---------CCC CCC---------CCC CCC---------CCC CCC---------CCC CCC---------CCC BBB---------BBB BBB---------BBB AAA---------AAA AAA---------AAA DDD---------DDD -BB---------BB- -BB---------BB- -AA---------AA- -AA---------AA- -AA---------AA- -AA---------AA- -AA---------AA- -AA---------AA- -CC---------CC- -CC---------CC- -DC---------CD- 
E-------------E E-------------E E-------------E E-------------E E-------------E E-------------E EE-----------EE EE-----------EE EE-----------EE EE-----------EE -E-----------E- -E-----------E- -E-----------E- -EC---------CE- -EC---------CE- -EC---------CE- -EC---------CE- -EC---------CE- -EC---------CE- -EC---------CE- -EC---------CE- 
