model
size = 7 32 21, scale = 0.05, origin = -y
material 
  colors = A:#60C B:#BBB C:#EEE D:#306 E:#309 F:#FF3 G:#3CF H:#FF9 I:#6FF J:#30C
voxels
73-2(A6-)I208-3A4-3A213-5A2-5A198-2(5A2-)5A205-2(5A2-)5A198-2(5A2-)5A205-5A2-5A212-5A2-5A172-E38-10AD3A3-19(C6-)C27-D6-E5(6-A)3-2A2D3AFA3DAFH-3B-F2-19(3B4-)BCB5-C12-3D3-5E3-2(GEG4-AEA4-)GJG2-2A3D2AF4DJ2FC3BCFHC3BCH-17(C3BC2-)C3BC3-CBC4-CBC5-C6-D6-E5(6-A)3-2A2D3AFA3DA2F-3B-H2-19(3B4-)BCB5-C20-E38-10AD3A3-19(C6-)C74-2(5A2-5A212-)2(5A2-)5A212-2(5A2-)5A205-2(5A2-)5A219-5A2-5A213-3A4-3A215-2(A6-)I136-
