model
size = 23 32 27, scale = 0.05, origin = -y
material 
  colors = A:#FC0 B:#FC3 C:#FFD21F D:#001
voxels
289-2AC11-2A4-2A2B2A-2A8-BA3-2A2BAB2-BA8-3A-2A4BABA2B9-AB3A2B3A-BA10-2A2BAB2AB3-A14-3AB565-C15-C6-BA7-CA4-2A5-2A-A3-CA-2A3-A-AB4-AB2-A2-2A-2A2-A2-BA5-A3-4A-4A3-A6-2A2-2A5-2A2-2A6-2A2-2A5-3A-2A7-6A3-2(B2A)9-AB2AB5AB2A15-3A495-2B15-BC4-2B15-AB4-B-A13-A-A4-A2-A11-A2-A4-B3-A9-A3-2(A4-)2A5-2A4-B4-A5-2(3A-)A3-B5-A12-A2-A6-A15-A7-A13-A9-5A3-5A14-A2B2A471-AB15-2B3-B2-B13-3(B2-)A13-2(A2-)B3-A11-A3-B2-A2-2A11-2A2(2-A)3-2A9-2A3-B2-A3-3A7-3A2(3-A)5-3A-3A5-A4-A17-A4-2A15-2A6-4A7-4A11-9A468-BAB15-3B2-A-B15-B-B2-B-A15-A-2(A2-)A13-2(A2-)A-A15-A-A2-B2-A13-3(A2-)A13-2(A2-)A3-3A2(-2A)-3A2(3-A)3(5-A)4-A17-A5-2A13-2A8-5A3-5A15-3A288-2(C17-C4-)2C15-2C3-2C17-BC2-2B17-CB2-2C17-2B2-CB17-BC2-BA17-2B-B2-B15-B2-2B2-A15-A2-BA2-A15-A2-2B2-A15-A2-2A2-A15-A2-A-A2-A13-2(A2-)A3-A11-A3-A2-A4-5A-5A4-A3-A17-A5-A15-A7-6A3-6A14-3A265-2C15-2C3-2(2C17-2C2-)C-C15-C-C2-C-B15-B-B2-CB17-2B2-CB17-BC2-2B17-2B-B2-B15-B2-2B2-B15-B2-BA2-A15-A2-2A3-A13-A3-BA3-A13-A3-2B3-A13-A3-2A3-A13-A3-A-A2-A13-A2-B2-A3-4A5-4A2(3-A)6-2A-2A6-A5-A15-A7-6A3-6A14-3A242-C17-C3-C-C15-C-C2(2-2C17-2C)2(-C)17-C-CB-B17-C-CB-C17-B-2B-B17-2(B-)2B17-2B-B-A17-B-2B2-B15-B2-2(2B3-A13-A3-2A3-A13-A3-)BA3-A13-A3-2A3-A13-A3-A-A3-2A2(-3A)-2A3-A2-A5-A7-A5-A3-2A15-2A6-6A3-6A14-3A241-3(2C17-2C2-)2C17-2C2(-C)17-C-2C-B17-C-CB-B17-B-BC-B17-B-2B2-B15-B2-CB2-2B13-2(2B2-)B15-B2-2B2-A15-A2-2A2-A15-A2-B2A-A15-A-2(4A2-A13-A2-)2A-A2-A13-2(A2-)A3-6A-6A3-A2-A7-2A-2A7-A3-3A13-3A7-2A9-2A12-9A215-2C17-2(2C2-2C7-3C7-)2C25-C2-2C11-2C2-C2-5C11-5C-2B-B-C11-2(C-)2C2B2-B13-B2-BCB-3B13-3B-2B3-B13-B3-2(2B2-B15-B2-)BA2-A15-A2-2B2-A15-A2-3A-A15-A-AB2A-A15-A-AB-A2-A13-2(A2-)A3-A11-A3-A2-A4-4A3-4A4-A2-2A2(5-A)5-2(2A4-)2A-2A4-2A8-2A9-2A12-9A215-C19-C2-2C3-11C3-2C2-C2-3C10-2C2-C4-4C10-3C5-2C15-2C4-C17-C4-C-BC11-2C-C3-C3B13-3BC2(2-B)13-B2-B-B3(2-B15-B2-2B)2-A15-A2-2A2-A15-A2-AB2-A15-A2-2(A-)A15-A-2(A2-)A13-2(A2-)A3-A11-A3-A2-A4-2A7-2A4-A3-2A3-A7-A3-2A6-A3-3A-3A3-A2(9-2A)12-9A215-C19-C2-C4-11C4-C5-2C11-2C7-C15-C5-C3-C13-C4-C2-C11-C2-C3-B2-A13-2(C2-)B2-B13-B2-C-B2-B15-B2-CB3(2-B15-B2-2B)2-A15-A2-BA2-A15-A2-AB2-A15-A2-2(A-)A15-A-B2(2-A)13-2(A2-)A3-A11-A3-A2-A3-A11-2(A3-)2A2-A9-A2-2A6-A2-4A-4A2-A9-3A7-3A13-7A216-C19-C7-11C2(11-C)8-2C13-2C5-C17-C3-2C17-2C2-C3-C11-C3-C2(2-B)13-B2-B-B3(2-B15-B2-2B)2-B15-B2-BA2-A15-A2-2A2-A15-A2-2(A-)A15-A-A2-A-A15-A-B2-A-A15-A-2(A2-)A13-A2-A3-A2-2A9-2A2-A5-2(A3-A7-)2A2-3A-3A2-2A10-2A7-2A14-7A244-11C2(11-C)9-C13-C6-2C15-2C3-2C17-2C2-2B2-B11-C2-2C2-C3-B11-B3-B-C3-B13-B3-2(CB2-B15-B2-)2B2-B15-B2-2B2-A15-A2-2(A-)2(A15-A-A2-A-)A15-A-2(A2-)A13-A2-A3-A-A13-A-A4-A2-2A9-2A2-A5-2(A3-A7-)3(3A-)3A11-2A5-2A16-5A248-5C14-4C5-4C10-C11-C9-C13-C6-2C15-2C4-C17-C4-C2-B11-B2-2(B3-)B11-B3-B-B3-B13-B3-2(2B2-B15-B2-)B2(-A)15-A-B2-A-A15-A-A2-B-A15-A-B2(2-A)13-3(A2-)A13-A2-A3-A2-A11-A2-A5-A2-A9-A2-A7-A2-2A5-2A2-A9-2A2-2A-2A2-2A12-4A-4A39-5D17-7D16-6DA17-4DA157-3C16-4C3-4C2(11-C)10-C11-C8-2C13-2C5-B17-C4-B3-2B7-2B3-C4-B2-B11-2(B2-)2B3-B11-B3-BC2B2-B13-B2-CB-B2-B13-3(B2-)A13-A2-B2(2-A)2(13-3(A2-)A)13-A2-B3-A2-A11-A2-A4-A3-A9-A3-A5-2(A3-A7-)2A2-3A-3A2-2A10-2A7-2A14-3A-3A38-4D-4D14-D7-D15-D5-D16-A5-A17-5A134-3C19-5C15-3C5-3C2(11-C)9-C13-C6-C2B13-3B4-CB4-3B-3B4-2C4-B3-3B5-3B3-B3-CB3-B9-B3-2B3-2(B2-B11-B2-B4-)A2-A11-A2-2(B3-)A11-A3-A2-A3-A11-2(A3-)A2-A11-A2-A4-A3-A9-A3-A5-2(A3-A7-)A2(3-2A)3-A9-A4-A-A4-A11-5A-5A36-3D3-3D14-D2-A-A2-D13-DA7-2D13-A7-D14-A7-A15-3A-3A17-5A156-5C14-4C5-4C10-C11-C10-B11-C9-C13-B6-3B4-2B-2B4-2BC4-2B3-4B-4B3-2B4-B3-3B5-3B3-B4-B3-2B7-2B3-B4-A3-2A7-2A3-A4-A3-A9-A3-B4-B3-A9-A3-B4-2A2-2A7-2A2-AB5-A3-2A5-2A3-A6-2A3-3A-3A3-2A7-2A4-A-A4-2A10-4A3-4A16-3A17-DA5-2D14-D-AD-DA-D13-D2-A3-A2-D12-D9-D12-C9-D13-A7-A14-4A-4A14-C3A-4A17-3A157-5C15-4C3-4C11-C3B5-2CBC2(10-B11-B)9-B13-B7-2B4-2B-2B4-2B6-2B3-3B-3B3-2B6-2B3-3A-3A3-AB6-BA2-4A-4A2-2A6-2A2-4A-4A2-2A7-B3-3A-3A3-B8-3A2-2A-2A2-3A2(9-2A)11-3AB7A15-5A39-3D4A2D13-4(D9-D12-)2A8-A12-5A-5A11-6A-5AC12-9A15-7A133-3C19-2C-2C18-C4B15-2C7B2C11-4B5-2BCB10-4B5-4B10-B-2B5-2B-2(B10-B11-)B10-A11-A10-BA-A5-A-AB10-2B3A3-4AB12-B3A-2ABA14-B8A83-9D13-2D7-2D12-2D8-2(D12-D9-)D13-2A5-2A14-3A3-3A12-A2(-4A)-A12-A2(-2A)-A14-B2A3-3A14-A2-3A2-A109-2(3C20-)CBC20-BCB19-CBC2B17-5BCB14-2(11B12-)4BA3B2AB12-2(B3A)2BA13-2B2A2B3A15-5ABA17-2B3A109-7D16-D5-D14-3D6-2D12-D9-D13-2(A7-A14-)2A5-2A14-2A5-2A-B12-A7-A15-2A3-2A17-5A501-5D18-D3-D16-2D5-2D14-B7-A14-2A5-2A14-3A3-3A13-2(2A7-2A12-)B-7A-A11-CB2-5A2-ABC13-A3-A523-2(7D16-)4AB2A13-C2A-2AB2A-3AB10-2A2-3A2-2A12-B3A3-4A13-3AB5A47-B14-B3-A591-B-A3-2(A-)C14-5A18-A3-A18-4AC64-BA2-C593-B3-A17-7A15-3AB5A16-5A683-A7-A14-C7-A16-B3-A22-B668-C16-A3-A18-B3-C78-
