model
size = 21 32 3, scale = 0.05, origin = -y
material 
  colors = A:#0038A8 B:#D60270 C:#9B4F96 D:#FBF0FF E:#FCF5FF F:#EFC405
voxels
9(D20-E20-)2(D4A4-4A8-E4A4-4A8-)D4A4-4A8-E4C4-4C8-D4C4-4C8-E4C4-4C2(8-D4B4-4B8-E4B4-4B)8-D4B4-4B8-F403-5(4A4-4A9-)3(4C4-4C9-)4(4B4-4B9-)4B4-4B420-5(4A17-)3(4C17-)4(4B17-)4B21-
