model
size = 30 32 32, scale = 0.05, origin = -y
material 
  colors = A:#1A1B26 B:#0052FF C:#FFD900 D:#4100FF E:#0028FF F:#0039FF G:#750CFF H:#5E0CFF I:#890CFF J:#B80CFF
voxels
403-4A25-3(6A24-)6A25-4A685-6A23-8A21-10A19-6(12A18-)12A19-10A21-8A23-6A408-B16-B108-6A22-10A19-12A15-B-14A-B11-AB16ABA11-B16AB13-5(16A14-)16A12-AB16ABA11-B16AB15-12A19-10A22-6A108-B16-B11-A18-A190-AB16-BA11-B16-B47-8A20-AC8ACA17-14A14-B16AB11-ABAC12ACABA9-AB2-C12AC2-BA9-AB-C12AC-BA13-5(C12AC16-)C12AC12-A2B-C12AC-2BA9-ABAC12ACABA11-B16AB14-14A17-12A20-8A47-B16-B11-AB16-BA9-2A18-2A188-2AB16-B2A9-AB6-4A6-BA11-B3-C8AC3-B14-2AC8AC2A15-3AC8AC3A13-BAC12ACAB11-AB-C12AC-BA9-A2B-C12AC-2BA8-AB2-C12AC2-BA7-2A3BC12AC3B2A11-C12AC16-C12AC15-BC12ACB14-BC12ACB15-C12AC16-C12AC11-A3B-C12AC-3BA7-A2B-C12AC-2BA9-AB-C12AC-BA11-BAC12ACAB13-16A15-14A14-B3-C8AC3-B11-AB6-4A6-BA9-2AB16-B2A8-2A18-2A188-3A6-4A6-3A8-A2B3-C8AC3-2BA9-AB-2AC8AC2A-BA11-B3AC8AC3AB12-B-CAC8ACAC-B11-AB-C12AC-BA9-A2B-C12AC-2BA8-A3BC12AC3BA7-2AB-BC12ACB-B2A6-A4BC12AC4BA6-A3-GC12ACG3-A9-2GC12AC2G2(12-GBC12ACBG)12-2GC12AC2G9-A3-GC12ACG3-2(A6-A3BGC12ACG3B)A7-A2B-C12AC-2BA9-AB-C12AC-BA11-B-C12AC-B12-BAC12ACAB11-AB-2AC8AC2A-BA9-A2B3-C8AC3-2BA8-2AB6-4A6-B2A8-2A18-2A188-3A3-C8AC3-3A8-A2B-2AC8AC2A-2BA8-A2B3AC8AC3A2BA9-AB-CAC8ACAC-BA9-2AB-CAC8ACAC-B2A2(8-A3BC12AC3BA)7-2A3BC12AC3B2A2(6-A4BC12AC4BA)6-A-2DBC12ACB2D-A6-A-D2BC12AC2BD-A8-D2BC12AC2BD10-D2BC12AC2BD8-A-D2BC12AC2BD-A6-A-2DBC12ACB2D-3(A6-A4BC12AC4B)A7-A3BC12AC3BA8-2AB-C12AC-B2A9-AB-C12AC-BA9-A2B2(AC)8A2(CA)2BA8-A2B-2AC8AC2A-2BA8-2AB3-C8AC3-B2A8-2A18-2A107-4A54-8A15-3A-2AC8AC2A-3A8-A2B3AC8AC3A2BA8-A2B-CAC8ACAC-2BA8-2AB-CAC8ACAC-B2A8-A3BCAC8ACAC3BA8-A3BC12AC3BA7-2A3BC12AC3B2A3(6-A4BC12AC4BA)6(6-AE3BC12AC3BEA)4(6-A4BC12AC4BA)7-A3BC12AC3BA8-A2B-C12AC-2BA8-A2B-CAC8ACAC-2BA8-A2B2(AC)8A2(CA)2BA8-2AB-2AC8AC2A-B2A8-2A5-8A5-2A105-8A23-6A21-AC8ACA13-6AC8AC6A2(8-A2B-CAC8ACAC-2BA)2(8-A3BCAC8ACAC3BA)7-2A3BC12AC3B2A4(6-A4BC12AC4BA)6(6-E4BC12AC4BE)5(6-A4BC12AC4BA)7-A3BC12AC3B2(A8-A2B-CAC8ACAC-2B)A8-2AB3AC8AC3AB2A8-2A3-AC8ACA3-2A16-6A82-10A20-10A18-14A12-22A8-A2B-C12AC-2B2(A8-A3BC12AC3B)A7-2A3BC12AC3B2A3(6-A4BC12AC4BA)9(6-E4BC12AC4BE)5(6-A4BC12AC4BA)7-A3BC12AC3BA8-A2B-C12AC-2BA8-2ABAC12ACAB2A8-2A2-14A2-2A14-10A79-12A18-12A16-16A11-3A-C12AC-3A8-A2B-C12AC-2BA8-A3BC12AC3BA7-2A3BC12AC3B2A3(6-A4BC12AC4BA)2(6-E4BC12AC4BE)6-2D3BC12AC3B2D5-5(3D3BC12AC3B3D4-)3D3BC12AC3B3D5-2(E4BC12AC4BE6-)4(A4BC12AC4BA6-)A4BC12AC4BA7-2(A2B-C12AC-2BA8-)22A13-12A21-6A50-14A16-14A15-AC12ACA11-A2B-C12AC-2BA8-A3BC12AC3BA7-2A3BC12AC3B2A3(6-A4BC12AC4BA)2(6-E4BC12AC4BE)6-2D3BC12AC3B2D5-7(3D3BC12AC3B3D4-)3D3BC12AC3B3D5-2(E4BC12AC4BE6-)4(A4BC12AC4BA6-)A4BC12AC4BA7-A2B-C12AC-2BA8-4AC12AC4A9-20A15-10A47-2(16A14-)AC12ACA11-A2B-C12AC-2BA7-2A3BC12AC3B2A3(6-A4BC12AC4BA)2(6-E4BC12AC4BE)6-2D3BC12AC3B2D5-3D3BC12AC3B3D4-3D3BC12AC3B3D3-4(G6BC12AC6BG2-)G6BC12AC6BG3-2(3D3BC12AC3B3D4-)3D3BC12AC3B3D5-2(E4BC12AC4BE6-)3(A4BC12AC4BA6-)A2BABC12ACBA2BA7-AB2-C12AC2-BA8-3A-C12AC-3A9-20A12-16A44-2(16A14-)AC12ACA10-2A3BC12AC3B2A3(6-A4BC12AC4BA)2(6-E4BC12AC4BE)6-2D3BC12AC3B2D5-3D3BC12AC3B3D4-3D3BC12AC3B3D3-6(G6BC12AC6BG2-)G6BC12AC6BG3-2(3D3BC12AC3B3D4-)3D3BC12AC3B3D5-2(E4BC12AC4BE6-)2(A4BC12AC4BA6-)A4BC12AC4BA7-2(AB)C12AC2(BA)8-3A-C12AC-3A9-20A12-16A20-4A20-2(16A14-)AC12ACA10-4(A4BC12AC4BA6-)E4BC12AC4BE6-E4BC12AC4BE5-3D3BC12AC3B3D4-3D3BC12AC3B3D3-2(G6BC12AC6BG2-)G6BC12AC6BG-3A2(5BC12AC5B6A)5BC12AC5B3A-2(G6BC12AC6BG2-)G6BC12AC6BG3-3D3BC12AC3B3D4-3D3BC12AC3B3D5-2(E4BC12AC4BE6-)2(A4BC12AC4BA6-)A4BC12AC4BA7-A3BC12AC3BA8-4AC12AC4A9-20A10-20A17-6A19-2(16A14-)AC12ACA10-4(A4BC12AC4BA6-)E4BC12AC4BE6-E4BC12AC4BE5-3D3BC12AC3B3D4-3D3BC12AC3B3D3-G6BC12AC6BG2-G6BC12AC6BG-3A5BC12AC5B3A2-2(26C4-)26C2-3A5BC12AC5B3A-G6BC12AC6BG2-G6BC12AC6BG3-3D3BC12AC3B3D4-3D3BC12AC3B3D5-2(E4BC12AC4BE6-)2(A4BC12AC4BA6-)A4BC12AC4BA7-A3BC12AC3BA8-4AC12AC4A9-20A10-20A16-8A18-2(16A14-)AC12ACA10-4(A4BC12AC4BA6-)E4BC12AC4BE6-E4BC12AC4BE5-3D3BC12AC3B3D4-3D3BC12AC3B3D3-G6BC12AC6BG2-G6BC12AC6BG-3A5BC12AC5B3A2-2(26C4-)26C2-3A5BC12AC5B3A-G6BC12AC6BG2-G6BC12AC6BG3-3D3BC12AC3B3D4-3D3BC12AC3B3D5-2(E4BC12AC4BE6-)2(A4BC12AC4BA6-)A4BC12AC4BA7-A3BC12AC3BA8-4AC12AC4A9-20A10-20A16-8A18-2(16A14-)AC12ACA10-4(A4BC12AC4BA6-)E4BC12AC4BE6-E4BC12AC4BE5-3D3BC12AC3B3D4-3D3BC12AC3B3D3-G6BC12AC6BG2-G6BC12AC6BG-3A5BC12AC5B3A2-2(26C4-)26C2-3A5BC12AC5B3A-G6BC12AC6BG2-G6BC12AC6BG3-3D3BC12AC3B3D4-3D3BC12AC3B3D5-2(E4BC12AC4BE6-)2(A4BC12AC4BA6-)A4BC12AC4BA7-A3BC12AC3BA8-4AC12AC4A9-20A10-20A16-8A18-2(16A14-)AC12ACA10-4(A4BC12AC4BA6-)E4BC12AC4BE6-E4BC12AC4BE5-3D3BC12AC3B3D4-3D3BC12AC3B3D3-G2B3ABC12ACB3A2B2(G2-G6BC12AC6B)G-3A2(5BC12AC5B6A)2B2ABC12ACB2A2B3A-2(G6BC12AC6BG2-)G6BC12AC6BG3-3D3BC12AC3B3D4-3D3BC12AC3B3D5-2(E4BC12AC4BE6-)2(A4BC12AC4BA6-)A4BC12AC4BA7-A3BC12AC3BA8-4AC12AC4A9-20A10-20A17-6A19-2(16A14-)AC12ACA10-4(A4BC12AC4BA6-)2(E4BC12AC4BE6-)2D3BC12AC3B2D5-3D3BC12AC3B3D4-3D2ABC12ACB2A3D3-4(G6BC12AC6BG2-)G3B2ABC12ACB2A3B2(G2-G6BC12AC6B)G3-2(3D3BC12AC3B3D4-)3D3BC12AC3B3D5-2(E4BC12AC4BE6-)2(A4BC12AC4BA6-)A4BC12AC4BA7-A3BC12AC3BA8-4AC12AC4A9-20A12-16A20-4A20-2(16A14-)AC12ACA10-A3B-C12AC-3B4(A6-A4BC12AC4B)A2(6-E4BC12AC4BE)6-2D2ABC12ACB2A2D5-3D2ABC12ACB2A3D4-3D3BC12AC3B3D3-3(G6BC12AC6BG2-)G3B2ABC12ACB2A3BG2-G6BC12AC6BG3-2(3D3BC12AC3B3D4-)3D3BC12AC3B3D5-2(E4BC12AC4BE6-)3(A4BC12AC4BA6-)A4BC12AC4BA7-4AC12AC4A8-4AC12AC4A9-3AC12AC3A12-16A44-2(16A14-)16A10-A3B-C12AC-3B5(A6-A4BC12AC4B)A2(6-E3ABC12ACB3AE)6-2D2ABC12ACB2A2D5-4(3D3BC12AC3B3D4-)3D2ABC12ACB2A3(3D4-3D3BC12AC3B)3D5-2(E4BC12AC4BE6-)4(A4BC12AC4BA6-)AB3AC12AC3ABA7-4AC12AC4A8-4AC12AC4A9-3AC12AC3A15-10A47-2(16A14-)16A10-2(A3B-C12AC-3BA6-)3(A4BC12AC4BA6-)2(AB2ABC12ACB2ABA6-)E3ABC12ACB3AE6-E4BC12AC4BE6-2D3BC12AC3B2D5-3(3D3BC12AC3B3D4-)3D2ABC12ACB2A2(3D4-3D3BC12AC3B)3D5-2(E4BC12AC4BE6-)4(A4BC12AC4BA6-)AB3AC12AC3ABA7-4AC12AC4A8-4AC12AC4A12-C12AC17-12A21-6A49-2(16A14-)16A10-A3B16A3BA6-A3B-C12AC-3B2(A6-A4BC12AC4B)4(A6-AB2ABC12ACB2AB)A5(6-E4BC12AC4BE)6-EB2ABC12ACB2AB3(E6-E4BC12AC4B)E6-A4BC12AC4B4(A6-A2BCACBC8ACBCAC2B)A7-2A2(CA)C8A2(CA)C2A8-3(CA)C8A3(CA)C9-3AC12AC3A13-C12AC18-10A78-14A18-2C6A2C18-14A11-A3BA4C6A4CA2(3BA6-A3B-C12AC-)3B3(A6-AB2ABC12ACB2AB)A6-4ABC12ACB4A3(6-A4BC12AC4BA)3(6-E4BC12AC4BE)6-EB2ABC12ACB2AB2(E6-E4BC12AC4B)E2(6-A4BC12AC4BA)3(6-A2BCACBC8ACBCAC2BA)7-2A2(CA)C8A2(CA)C2A8-3(CA)C8A3(CA)C9-3(AC)8A3(CA)11-2AC12AC2A15-12A107-14A18-4C2A4C18-14A11-A3B3-4C2A4C3-3BA6-A3B16A3BA6-AB2A-C12AC-2ABA6-AB3AC12AC3ABA6-AB2ABC12ACB2ABA6-4ABC12ACB4A6-3A2BC12AC2B3A6-2AF2BC12AC2BF2A7-A3BC12AC3BA7-4(A4BC12AC4BA6-)AB2ABC12ACB2AB4(A6-A4BC12AC4B)A2(6-2(ACBC)8A2(CBCA))7-3(CA)C8A3(CA)C8-3(CA)C8A3(CA)C9-3(AC)8A3(CA)11-2AC12AC2A14-C12AC137-12A20-8C20-12A12-AB2A5-6C5-2ABA6-AB2A-14A-2A2(BA6-AB20A)BA2(6-24A)7-3ABC12ACB3A3(8-AF2BC12AC2BFA)7-3(ABF2BC12AC2BFBA6-)5(AB2ABC12ACB2ABA6-)4(AC)8A4(CA)7-3(CA)C8A3(CA)C8-3(CA)C8A3(CA)C9-3(AC)8A3(CA)11-2AC12AC2A14-C12AC18-10A140-10A50-10A13-AB2A16-2(2ABA6-AB2A3-10A3-)2ABA2(6-24A)7-22A8-4AC12AC4A3(8-A3FC12AC3FA)9-3FC12AC3F8-A2-2FC12AC2F2-A6-AB3FC12AC3FBA6-AB2AFC12ACF2A2(BA6-AB3AC12AC3A)BA6-AB2AB14CB2ABA6-AB3AC12AC3ABA7-3(CA)C8A3(CA)C8-3(CA)C8A3(CA)C9-3AC12AC3A11-2AC12AC2A14-C12AC19-8A25-2A147-4A56-4A2(16-4C)6-AB2A6-4A6-2ABA6-4A4-8A4-4A6-2A3-14A3-2A7-A-18A-A8-A-18A-A10-18A11-A2E14F2EA10-A2E14F2EA9-2A2E14F2E2A10-2E14F2E13-E14FE10-A3-E14FE3-A6-4A16F4A3(6-24A)7-4A14C4A8-C3AC12AC3AC9-3AC12AC3A12-AC12ACA16-12A21-6A25-4A256-3C18-3C6-3A18-3A6-2A7-6A7-2A13-4A2-4A19-12A16-16A14-16A13-2(2A2D2H6F2H2D2A12-)2A2D2H6F2H2D2A14-2(2D2H6F2H2D16-)2D2H6F2H2D11-A2-A-2D2H6F2H2D-A2-A2(6-24A)8-20A11-18A13-16A15-14A17-12A19-10A22-6A285-2C20-2C6-A22-A47-2A26-6A21-12A18-12A17-4AGI2JIG4A16-4AGI2JIG4A20-4(GI2JIG24-)GI2JIG15-A3-16A3-A12-12A19-10A21-8A23-6A25-4A27-2A508-2A27-4A25-6A23-A6-A172-8A24-4A27-2A374-
