model
size = 32 32 30, scale = 0.05, origin = -y
material 
  colors = A:#F60 B:#F30 C:#002 D:#B00 E:#F33 F:#111 G:#BBB H:#F63 I:#EEE J:#555 K:#F96 L:#444 M:#9F3
voxels
453-2D17-2D10-4D15-4D9-4D15-4D10-2D17-2D874-4D15-4D8-DE2AED13-DE2AE2(D7-DA-2AD13-D2A-A)D7-DE2AED13-DE2AED8-4D15-4D841-4D15-4D8-3(D4AD13-D4AD7-)D4AD13-D4AD8-4D15-4D873-4B15-4B2(9-B2AB15-B2AB)9-4B15-4B938-2A17-2A11-2A17-2A949-2B20-5A4-2B-B3-5A11-5A4-B-2B3-5A21-2B861-4E27-6A25-8A19-7ABAB7A15-8AB8A20-8A25-6A27-4A700-4A26-8A23-E8AE21-12A20-12A19-14A18-B13A18-13AB18-14A19-12A20-12A21-10A23-8A26-4A541-2A27-8A22-12A19-E12AE18-14A17-2(16A16-)16A15-16ABA14-18A15-2(16A16-)16A17-14A18-14A19-12A22-8A27-2A444-6A24-10A20-14A17-16A16-16A15-E16AE14-18A13-3(20A12-)B19A2(12-20A)13-18A14-18A15-16A16-16A17-14A20-10A24-6A345-4BH2BE22-AE10A19-14A16-18A14-18A13-20A11-22A10-22A9-7(24A8-)24A9-22A10-22A11-20A13-18A14-18A16-14A19-12A22-8A246-HE3A2H3AEH20-3B2A2M2A3B19-4A7-3A16-4A11-3A13-2A16-2A12-2A17-A11-3A17-2A9-2(3A18-3A8-)3A18-3A7-5(4A19-3A6-)4A19-3A7-3A19-2(2A8-4A18-)2A9-4A17-A11-4A14-2A12-5A12-3A13-5A9-4A16-6A2M6A19-5A2M5A23-6B119-2FD6-D2F20-3A6-3A20-3A2-2H2-3A20-4AE2AE4A19-HB10ABH16-6A7-5A13-5A11-4A11-3A16-3A10-3A17-2A9-4A17-3A8-3A18-3A7-2(4A18-4A6-)4A19-3A5-3(5A19-4A4-)5A19-4A5-2(4A19-3A6-)5A18-3A7-4A18-2A8-5A17-2A9-5A14-3A10-6A12-4A11-6A9-5A13-18A16-14A20-10A26-2A88-F3CF4-4CF18-A3CA4-A2C2A18-A2C2AEHKE2AC2A18-14A17-16A15-6A7-5A13-5A11-4A11-3A16-3A9-4A17-3A7-5A17-2(4A6-4A18-)4A5-5A18-5A2(4-5A19-4A)3-6A19-5A2-6A19-5A3-2(5A19-4A4-)5A19-4A5-2(5A18-3A6-)6A17-3A7-6A14-4A9-6A12-4A11-6A9-5A13-18A15-16A17-14A21-8A84-F-2CJ-F2-FI3C2F16-AF2CACAKHAIJC3A16-AC14A16-16A14-20A11-8A7-7A9-7A11-6A8-4A16-4A7-5A17-4A5-6A17-2(5A4-5A18-)5A3-6A18-6A2-6A19-5A-7A3(19-13A)19-6A-6A19-5A2-6A19-5A3-2(6A18-4A4-)7A17-4A5-7A14-5A7-7A12-5A8-8A9-7A9-22A11-20A14-16A17-14A21-8A51-F3CJGIF2-F2IG3CF14-A3CAGIAKHA2IA2C2A14-A2C12AC2A14-AC14ACA13-20A11-8A7-7A9-7A11-6A7-5A16-5A6-5A17-4A5-6A17-5A4-5A18-5A3-2(6A18-6A2-)6A19-5A-7A3(19-13A)19-6A-2(6A19-5A2-)7A18-5A3-6A18-4A4-7A17-4A5-7A14-5A6-8A12-6A7-8A9-7A9-22A11-20A13-18A16-14A20-10A49-F3CJGIGF2-F3GJ3CF12-A3C2AIGAKHA3GA2C2A12-A2C14AC2A12-18ACA11-22A9-9A7-8A8-7A11-6A7-5A16-5A5-6A17-5A4-6A17-5A3-2(6A18-6A2-)6A18-6A-7A5(19-13A)19-6A-6A19-2(5A2-7A18-)5A3-7A17-4A4-8A14-6A5-8A12-6A7-8A9-7A8-24A9-22A12-18A15-16A18-12A24-4A20-F2CLI3GF2-F4G3CF12-A3C2A2GAKEA2G2A3CA12-AC15A2CA12-B17ACB11-B20AB9-9A2(7-8A)11-7A6-5A16-5A5-6A17-5A4-6A17-5A3-6A18-6A2-6A18-6A-7A18-14A6(19-13A)19-6A-7A18-5A2-7A18-5A3-7A17-4A4-8A14-6A5-8A12-6A6-9A9-8A7-24A9-22A11-20A14-16A18-12A23-6A19-F2CJI2GCF2-FCGIJG2CF12-A2C6AKH6A2CA12-BC16ACB12-B18AB11-B20AB9-B8A7-7AB7-8A11-7A5-6A16-6A4-6A17-5A3-7A17-6A2-6A18-6A-7A2(18-14A)19-13A19-6A-B5A19-13A19-4AB-7A2(19-13A)19-14A18-6A-7A18-5A2-8A17-5A3-8A14-6A4-9A12-7A5-9A9-8A7-24A9-22A11-20A13-18A16-14A21-8A18-D2C2LI2CF2-FC2J2L2CD12-A2C6AKH6A2CA12-BC16ACB12-B18AB11-B20AB9-B8A7-7AB7-8A11-7A5-6A16-6A4-6A17-5A3-7A17-6A2-6A18-6A-7A2(18-14A)2(19-13A)19-4AB2-B5A3(19-13A)19-14A18-6A-7A18-5A2-8A17-5A3-8A14-6A4-9A12-7A5-9A9-8A7-24A9-22A11-20A13-18A16-14A21-8A18-D3CL3CF2-F3CL3CD12-B2C6AKH6A2CB12-B2C14A2CB12-BC16ACB11-B20AB9-9A2(7-8A)11-7A6-5A16-5A5-6A17-5A3-7A17-2(6A2-6A18-)6A-7A18-14A6(19-13A)19-6A-2(7A18-5A2-)8A17-5A3-8A14-6A5-8A12-6A6-9A9-8A7-24A9-22A11-20A14-16A17-14A21-8A19-D6CF3-6CD14-A2C5AKHF4A2CAB13-AC14AC2A12-BC16ACA11-22A9-9A2(7-8A)11-7A6-5A16-5A5-6A17-5A4-6A17-5A3-6A18-6A2-6A18-6A-7A18-14A6(19-13A)19-6A-7A18-5A2-7A18-5A3-7A17-4A4-8A14-6A5-8A12-6A6-9A9-8A7-24A9-22A11-20A14-AB12ABA18-12A23-6A21-F4CF4-F4CF16-E2C4A2H4A2CE16-16A15-B16AB13-20A11-8A7-6A10-7A11-6A7-5A16-5A6-5A17-4A5-6A17-5A4-5A18-5A3-2(6A18-6A2-)6A19-5A-7A3(19-13A)19-6A-2(6A19-5A2-)7A18-5A3-6A18-4A4-7A17-4A5-7A14-5A6-8A12-6A7-8A9-7A9-22A11-20A13-18A16-AB10ABA20-3A5B2A52-3FD6-D3F18-3E3A2H3A3E17-2E2AF9A2E16-17A13-20A11-8A7-7A9-7A11-6A8-4A16-4A7-5A17-4A5-6A17-2(5A4-5A18-)5A3-6A18-6A2-6A19-5A-7A3(19-13A)19-6A-6A19-5A2-6A19-5A3-2(6A18-4A4-)7A17-4A5-7A14-5A7-7A12-5A8-8A9-7A9-22A11-20A14-16A17-2AB8AB2A21-8A90-4A24-2E8A2E18-16A15-18A13-7A7-2(6A11-)5A9-4A16-4A7-5A17-4A6-5A17-4A5-3(5A18-5A4-)5A19-4A3-3(6A19-5A2-)6A19-5A3-2(5A19-4A4-)6A18-4A4-6A18-4A5-6A17-3A6-7A14-5A7-7A12-5A9-7A9-6A11-20A13-18A15-16A18-2A2B4A2B2A24-4A93-2D27-8A21-14A17-16A15-6A7-5A13-5A11-3A12-3A16-3A9-4A17-3A7-5A17-2(4A6-4A18-)4A5-5A18-5A2(4-5A19-4A)3-6A19-5A2-6A19-5A3-2(5A19-4A4-)5A19-4A5-2(5A18-3A6-)6A17-3A7-6A14-4A9-6A12-4A11-6A9-5A13-18A15-16A17-14A21-8A154-4D27-A4EA23-12A19-4A7-3A16-4A11-3A13-2A16-2A12-2A17-A11-3A17-2A9-2(3A18-3A8-)3A18-3A7-5(4A19-3A6-)4A19-3A7-3A19-2(2A8-4A18-)2A9-4A17-A11-4A13-3A12-5A11-4A13-6A7-5A16-14A19-12A23-6A249-8A22-3A7-2A19-2A9-3A16-3A10-5A14-2A13-3A13-2A17-A11-2A18-2A10-2A18-2A9-3A18-3A7(8-3A19-2A)9-3A18-A10-3A17-2A11-3A30-3A13-2A14-4A11-3A16-4A7-3A19-12A22-8A312-8A22-10A21-A2-A5-B3A18-2A12-2A15-A16-A13-3A15-2A12-2A15-3A11-3A16-3A10-3A17-2A6(10-3A16-3A)11-2A16-2A12-6A9-5A13-6A7-5A15-16A17-14A19-12A22-8A377-6B23-3B5-B21-2B9-3B18-B12-3B16-B14-2(B15-)2B14-B16-B13-5(2B16-2B12-)2B16-2B13-B16-B14-B16-B15-4B9-3B16-5B7-4B17-5B5-4B20-10B24-6B205-
