model
size = 32 28 22, scale = 0.05, origin = -y
material 
  colors = A:#111 B:#FC3
voxels
45-7(2A2-2A26-)A4-A26-2(A31-)A537-5A-2A2-2A5-A3(14-5A-A-2A-A3-3A)15-4A-A-2A-A3-3A15-2(A-2A-)2(A4-A16-A-A2-A-2A-)A4-A16-A-A2-6A4-A18-A2-6A23-A2-2A-3A6(26-2A2-2A)26-2(2A30-)2A280-8A2-A-6A14-A4-6A-3A2-A14-A4-A-3A-4A2(2-A15-A3-A-3A-A-2A)2-A15-2A2-A2-2A-A4(-4A16-2A-2A2(2-A))-4A16-2A-2A2-A3-3(5A16-5A2-2A2-)3A-A16-5A2-2A2-3A-A18-3A2-2A2-3A20-3A2-2A2-3A21-2A2-7A21-2A2-6A22-2A2-6A23-7A25-7A153-2ABAB2A25-2ABAB2A16-3A2(-2A)5-10A7-4A2-4A5-2(2A6-4A5-3A3-A-2A-A3-)3A5-4A6-2A3-A3-2A3-3A5-4A11-A3-3A2-3A2(4-4A12-A4-2A-4A)2(4-4A11-A5-2A-4A)4-3A12-A5-2A-3A5-3A12-2(A2-)2A-3A5-3A12-3(A-)6A5-2A13-3(A-)6A2-2A-2A14-2A-A-6A3(-A)15-2A-A-8A-3A15-2A-A-5A2(-2A)16-2A-A-5A2-A-2A17-2(A-)2A-2A2-A-A18-2(A-)2A-3A2(-A)18-12A-A20-2(10A22-)4(9A23-)9A15-6A10-2A2-3A8-2A2-4A-A7-A-9A2(4-2A-5A-A7-A3-3A3-A)4-2A-4A-2A7-A3-3A2-A6-6A2-A7-A2-4A2-A6-7A2-A6-A2-3A3-A6-7A2-A6-A2-2A2(-A)7-7A2-A6-A2-2(3A2-A8-6A2-A6-2A-)3A2-A8-3A-2A2-A6-2A-3A2-A9-2A-3A-A6-2A2(2-A)10-2A-A-3A6-2A5-A10-3A2-3A6-3A3-2A10-3A2-3A7-2A3-2A11-2A-4A5-A-2A2-2A12-7A5-2A-A2-2A12-3A-3A5-8A13-2A-3A6-6A14-2A-2A7-3A-2A14-5A7-6A15-5A6-5A17-4A6-4A19-3(3A6-3A20-)3A7-2A14-2A30-2A3-3A8-2A5-3A6-2A3-3A8-3A3-A2-A6-2(2A3-3A8-3A3-A-A7-)2A3-3A8-2A4-A-A7-2A4-2A8-2A3-2A-A7-2A4-2(2A8-2A3-A-A8-A-A3-)2A9-A3-2A10-2A3-2(2A9-A3-2A10-3A2-)2A9-2A-3A10-3A-2A10-4A-A10-A-4A10-5A12-5A10-5A12-3A-A9-6A12-2A12-6A12-A-2A13-A-A13-3A13-2A14-3A12-3A14-3A12-A-A15-2A11-3A16-3A10-A-A16-3A3(10-2A18-2A)10-2A44-5(2A22-2A6-)2A22-A7-2A21-5(2A8-2A20-)A10-A19-3(2A10-2A18-)2A10-A-A17-A3(12-2A16-2A)12-2A15-3(2A14-)2A13-A-A15-3(2A12-2A16-)2A12-2A42-2A30-2(2A24-2A4-)2A24-A5-2A23-2A6-A23-3(2A6-2A22-)A7-2A22-A8-A21-2(2A8-2A20-)A9-2A2(20-A10-A)19-2(2A10-2A18-)2A11-A18-A2(12-2A16-2A)12-2A16-A4(14-2A)15-2(A14-A16-)A14-A73-2A26-2A2-2A25-3A2-A-A2(24-3A3-2A)2(24-2A4-2A)23-A-A5-3(2A22-2A6-)2A21-2A8-A21-3(2A8-2A20-)A10-A19-2(2A10-2A18-)A11-2A18-A12-A17-2A12-2A16-2A13-A16-A3(14-2A)2(14-A16-A)14-A73-A30-3A27-3A-A27-5A26-2(A-)2A26-3A-2A25-A-2A2(-A)24-A-A2-3A24-3A3-2A24-2A4-2A23-A-A4-A-A22-3A4-3A2(22-2A6-2A)21-A-A7-2(2A20-2A8-)2A19-A-A9-A19-2A10-2A18-2A11-A17-2A12-2A16-2A13-A16-A3(14-2A)2(14-A16-A)14-A104-A31-3A25-3(5A2-A24-)3A2-A-A24-3A2-A-A23-A-2A2(2-A)3(22-3A4-A-A)21-A-A2(6-A-A20-3A)6-A-A20-2A8-2A19-A-A8-A-A2(18-2A10-2A)18-2A11-A17-2A12-2A16-2A13-A15-2(2A14-)2A15-A14-A16-A13-2A16-2A12-2A136-3A25-2A2-A-A25-A3-A2-2(A24-A4-A-)A23-2A5-2A23-2A5-A-A22-A6-A-A22-A2(7-2A21-2A)7-A-A3(20-A9-2A)19-2(2A10-2A18-)A12-A18-A12-2A16-2A12-2A15-3(2A14-)2A13-3(2A16-2A12-)A138-A26-A3-2A26-A3-A-2A2(24-A4-A-A)23-2A4-A2-A2(22-2A5-3A)22-A6-2A-A21-A7-A-A20-2A7-3A20-2A8-2A20-2A8-A-A19-2A8-3A18-2A10-2A18-2A10-A-A17-2A10-3A16-2A12-2A14-2A-A13-2A13-3A14-A-A12-A-A15-3A10-A-A16-3A10-2A2(18-2A9-3A)137-4A24-2A2-4A24-2A3-3A24-2(2A3-2A-A23-)2A4-3A23-2A4-A-A22-2A7-A21-A-A7-2A20-A-A7-2A19-A2-A8-A19-A-A2(9-2A18-3A)10-A17-A-A11-2A16-3A11-2A16-2(2A13-)2A-A13-3A10-3A-A14-A-2A10-3A16-A-2A7-3A-A17-5A4-5A19-2(5A2-5A20-)4A4-4A140-2A25-2A3-2A22-3A-A4-A22-2A2-A4-A21-3A-A5-2A20-5A5-2A21-4A6-2A20-3A7-2A19-A-2A7-A-A18-4A7-A-A18-3A9-2A18-2A10-2A17-2A11-A-A16-2A12-2A15-A-A12-A-A14-2A13-A-A13-3A14-A-A11-2A-A14-A2-6A-5A-A16-2A-10A-2A17-14A20-10A24-2(6A26-)6A112-3A18-4A6-A-2A18-7A3-A-2A18-2A-4A4-3A18-2A-3A5-3A18-2(A-)2A5-A-2A17-A-A8-4A17-3A9-A-A18-2A9-3A17-A-A9-3A17-2A11-A-A2(16-2A11-3A)15-A-A12-A-A14-A-A12-A-A13-A-A14-A-A12-A-A14-A-3A7-3A-A16-A-14A16-3A5-A4-2A19-12A27-A241-2A19-4A7-A-A18-2(A-A8-A2-A17-)3A8-A2-2A16-3A9-A2-2(A16-3A10-A-)A16-2A12-2A16-2A12-3A14-A-A12-A-A14-A-A13-2(2A14-)2A13-A-A14-A-A5-2A4-2A-A14-A-3A2-4A3-A-A16-16A16-3A-7A2-2A18-2A-10A21-10A302-4A15-4A9-A2-2A2(14-2A-A10-A2-A)9-A4-3A11-A2-2(A9-A4-3A12-A-)A9-A4-3A13-A-2A6-2A4-3A13-2(A-2A4-)3A13-A2-A4-A-2A4-A-A14-4A3-4A4-3A14-4A2-5A3-3A15-11A-3A-A16-7A2-7A16-2A2-2A-8A19-10A-A21-10A22-A319-3A4-2A18-A4-3A4-2A2-4A10-4A2-4A3-8A11-A3-6A3-2(8A11-A3-7A2-)8A12-A-8A2-8A12-10A2-8A13-3A-5A2-7A14-3A-4A-2A-6A14-8A-2A-6A15-2(A-)3A-2A-5A19-3A-9A19-9A2-2A19-11A21-2A-2A3-3A31-A374-3A4-3A21-2(2A-A-)A20-3(A-)2A2(-A)15-4A2(-A)-5A2-A15-4A3(-A)-2A3-A16-3A3(-A)-2A2-A17-2A2-2(3(A-)4A-A20-)2(A-)6A-A20-3A-6A-A21-A2(2-2A)-A21-A2-2A2-4A21-A2-A4-3A21-A8-2A442-2A28-6A22-2A2-8A20-2(2A2-7A-A19-)2A2-2(3A-)A19-2(2A2-)5A19-2A2(2-2A4-A-A20-A)2-A5-2(2A30-)2A31-A536-2A26-2A2-2A5-2A19-2A2-2A5-3A29-4(2A30-)A587-
