model
size = 32 28 22, scale = 0.05, origin = -y
material 
  colors = A:#F60 B:#FF6 C:#FC3 D:#FC0 E:#FFF F:#F9C G:#FC6 H:#FF3 I:#F33 J:#FC9 K:#CCF L:#FCF M:#F30 N:#F99 O:#CC6 P:#F66 Q:#CF6 R:#F0C S:#F6C T:#F39 U:#F63 V:#FFC W:#F93 X:#F9F Y:#F09 Z:#F3F Aa:#F96 Ab:#F6F Ac:#FF9 Ad:#F3C Ae:#F90 Af:#F03 Ag:#CF9 Ah:#FCC Ai:#CC0 Aj:#F06 Ak:#FF0 Al:#CF3 Am:#CFC An:#CFF Ao:#F00 Ap:#F0F Aq:#CCC Ar:#CC9 As:#CC3 At:#F36 Au:#CF0 Av:#F69
voxels
45-FC2-AfC26-LS2-AcAe26-MU2-VAg26-KM2-AsO26-BG2-AbI26-WAk2-EK26-HD2-XR26-Ad4-Q26-Af31-C31-I537-ApAnZMT-QD2-AjAe5-K14-AbXYZP-Af-AbAj-Ag3-AiAmAt14-AYAdZA-Av-SU-O3-WAvE14-FSAeBAg-Ar-MQ-I3-CAaT15-AdIOAq-Aa-ZF-K3-AeNAk15-Ac-YE-Ag-ZS-R4-D16-O-B2-Av-BAc-Q4-Ao16-R-Ap2-H-OX-T4-Ai16-H-Ab2-FJYNVP4-W18-A2-LQBREA23-F2-MAp-AeUJ26-KAv2-RJ26-BM2-AmAc26-WAl2-AhAr26-HAt2-2C26-AdZ2-FS26-AfAv2-AlU26-CR30-IT30-AtP280-ArKATOQApM2-I-MAkQAcCQ14-Aa4-AoAbZAiAcG-AcAlT2-Ap14-Ag4-Aa-ZWX-FNHP2-Av15-H3-Am-BCN2(-L)A2-M15-Ad3-T-OAeR-M-AiJ2-Al15-AfW2-X2-AgAe-K-LJXK16-CAu-ArS2-O2-B-AeAcAiR16-IAq-FAm2-I2-W-AdArAoQ16-AtK-OAg2-K2-H-AaCAbT16-AkAa-ApI2-R2-Ad-AeSVP16-CAo-AbG2-Q3-AmVUAjA16-AgFAkSAr2-TJ2-AgZMBJ16-BGAlMAu2-PT2-IYGVJ16-UAiHZAh2-AL2-GAdAk-Ac16-ApELZAs2-JV2-ArAeD-Ar18-AiBAk2-JAn2-AuIA20-LOAl2-AcD2-AhAnAq21-YH2-ArAfZBAsAqI21-BL2-CAcYUAkW22-ApAi2-SVAdApAlAu23-LAhFUAsAeAa25-AeAjGMAbIAf208-AiAaG-AqZ-AfY5-NICHAdAnOAmAoAe7-W2AoN2-BGAuG5-AiK6-AbAgAmAg5-AuAbF3-O-WAj-Ag3-DR6-VOAhAq5-AqVG3-Y-JAj-Av3-VQAn5-AjICE6-AjAi3-B3-2H3-ETX5-BKFAt11-Ap3-AhFI2-UPY4-AsVRAl12-Ab4-LG-LRAS4-LAqQAn12-A4-MAr-AeAmJAd4-HGTX11-Ac5-KAu-AdAhJAc4-AhNPY11-X5-BAh-AaCAcO4-ZAiA12-N5-WAs-AeFAr5-KDJ12-R2-V2-HAk-VAlC5-AtVJ12-Ae-Y-Al-AdAlVZAnS5-2E13-Y-Al-At-AfHAqYXU2-SF-TU14-AqAf-Z-CLGAdYM2(-O)-Ak15-KAu-Av-IAiNAeSGArY-ApXN15-AaW-R-AtLAiIAd-FB-AbAn16-AoJ-T-AkAeDAnAc2-Ap-SAh17-T-P-CAd-AqO2-Ab-M18-L-A-AgAa-WRAq-A-Z18-VAjAgYBAeUAuHISF-Z20-AqGUVRAbLGMX22-EAjApZAmAdNAjZAn22-AtAjAaYAhJKUZ24-AlAfAdCHArQB24-OAmAeFQ2FO2(23-9A)15-AdDBISE10-ApAn2-2AiAf8-AdJ2-GAdUAr-W7-Ab-AbBDWAmHYIO4-AeH-AqAjAcRAn-J7-S3-VCAv3-I4-IQ-GUOAmAh-T7-M3-EAeAa3-K4-AnAf-NQRAh-AcL7-Z3-UAgN2-W6-AvAeAiFHC2-V7-Z2-AfROD2-Au6-ArAgDSLFAs2-Ap6-B2-CAmI3-Ab6-AaOVAcNAlJ2-Ab6-O2-IAh-Ai-H7-AgIEXKAnB2-S6-Y2-AtCR2-L8-KUNArXAm2-M6-BG-AkFQ2-N8-3RFYE2-Z6-ApAi-CAlT2-K8-QAmAe-SP2-Z6-AbE-AgAnP2-Ar9-AhY-AdCD-B6-AAk2-X2-I10-CAl-Ac-AEO6-FAc5-At10-FAfS2-AqXY6-XAuAi3-KAk10-AlAuM2-IAiB7-AhD3-RC11-WZ-HGAoAp5-E-AjV2-ArQ12-JZLAhAj2Ab5-PW-E2-CT12-TBN-UVA5-CAuAnUAvRSP13-OK-QAjF6-AqAhRAaHU14-YAr-FB7-KApAm-LM14-BFESV7-AaPAhDNG15-OTAcAqAh6-AoAsCAoK17-AkXGW6-FJFAi19-2NAu6-GBAl20-RAiAq6-AiAmAn20-ADK6-E2A20-3A6-3A14-AtAu30-AkAb3-AoMZ8-AcH5-IXAj6-CAd3-FGK8-NAdO3-R2-Ar6-AgJ3-GAkAt8-QAfY3-Q-Ao7-BH3-AiDE8-AoCB3-T-Ab7-UQ3-EAT8-AaI4-P-V7-ApAf4-AqAk8-AmAt3-RA-Aj7-AaAv4-IN8-TAk3-Q-A8-Af-B3-GAs8-XC3-T-J8-Am-Am3-AjX9-Ag3-PAc10-AgE3-UAt9-B3-AAr10-AvPK2-QD9-U3-JC10-HCAa2-FP9-ApW-YJS10-FAAo-AhS10-AaAuApAd-U10-L-FAkApAc10-AfAqAbAeAr12-LGDPX10-AmKSIC12-HAiA-N9-AhAvAaMAnS12-AhE12-AsAaAoZAqU12-Z-IB13-Z-M13-AcGAm13-BAu14-AuAjE12-AiOAb14-AhUP12-E-Ad15-QC11-WAkB16-FAW10-C-Ap16-SAsJ10-AeAu18-LT10-AgAh18-AL10-OA19-A10-2A44-AnAg22-2D6-DI22-AoP6-AfG22-AiAo6-AcAr22-WD6-VAu22-CY6-AsAh22-Ae7-AbAs21-ArAg8-AkAl20-AnO8-AlAn20-AhI8-HX20-ApK8-LY20-PR8-AiS20-As10-Ad19-AJ10-AcAp18-FB10-OP18-XAm10-RAs18-AnE10-H-Ao17-Ah12-BAi16-AbW12-AmW16-AAu12-EC16-FAq12-PAe15-PX14-AgR14-AAn14-OAe13-Ap-Ah15-YAk12-AbAq16-AlD12-SE16-2A12-MA16-2A12-2A42-LAv30-VAa24-AqAd4-AnN24-KAe4-2D24-Aa5-AfAo23-GAo6-Ai23-AiF6-WAd22-EG6-CAe22-AkAi6-AeI22-Ac7-AgAn22-Au8-Aq21-AAh8-2W20-AsAj8-AuH20-L9-AbAd20-H10-Af20-Ah10-C19-AcZ10-IAc18-OK10-AtAr18-RAt11-C18-H12-ST16-ApL12-UX16-PN12-MS16-As14-AmQ14-HJ14-AgAf14-AdB15-Av14-Af2(16-A14-A)73-TX26-XAl2-XAi25-M2An2-S-As24-KAhX3-2Ab24-BWY3-VE24-WAu4-AjX24-HAq4-BAi23-N-K5-AoAe22-AsAf6-AbAd22-XC6-VAa22-AtI6-AjAe21-OD8-V21-RP8-ZAm20-HAo8-YAh20-LD8-AdC20-N10-F19-ZK10-AlAe18-ZAr10-AnAg18-B11-XO18-O12-I17-LY12-KR16-AiB13-H16-L14-LAb14-ArAe14-NAd14-Aa2(16-A14-A)73-D30-IAoAc27-2MAt-X27-ZGAkWN26-F-Ak-CR26-SBD-2Ae25-H-OA-Ag-V24-F-Y2-OAlE24-LNB3-AfU24-MR4-AuR23-W-Ae4-W-At22-CBY4-JAhD22-AeW6-CP22-AgH6-FAo21-Ab-Ad7-DH20-SI8-YAd20-MK8-GAf19-Av-R9-C19-RZ10-IY18-TB11-Ad17-MP12-AeF16-ZA13-G16-Z14-AiT14-PB14-EL14-C2(16-A14-A)104-E31-PQAg25-XApAeMC2-As24-AnPAgGA2-Ak24-AhAsOAkAs2-Al24-WJI2-T-H24-AuBK2-X-L23-J-AmR2-S2-Al22-BKE4-Av-H22-AmAaP4-Aa-L22-EAoC4-N-Ai21-S-F6-Aa-Au20-UCG6-Ae-W20-MAAi6-V-J20-GAs8-AaT19-F-L8-Ae-Q18-LD10-VAf18-MA10-AnAv18-KAq11-Ar17-AaB12-AaAq16-AoW13-K15-KF14-AaE14-AtG15-At14-E16-A13-JA16-2A12-2A136-VQC25-HAi2-An-Ag25-F3-D2-R24-L4-Ar-Am24-M4-Aa-Ah23-PK5-AaC23-AoB5-Af-N22-D6-Am-As22-Y7-AnX21-QG7-XAt21-TAj7-Y-V20-P9-PAn20-A9-AoD20-J9-DAf19-AbJ10-AcI18-AdAc10-VAn18-J12-Aq18-H12-WAf16-MQ12-AuAc15-AvG14-VAi14-MAk14-AsD13-TAl16-VQ12-LAt16-AAp12-VA16-2A12-A138-Al26-U3-YAf26-Q3-Ad-AvAp24-F4-W-Av24-S4-J-M23-AgAc4-T2-Ag22-IX5-AAtO22-GN5-AgZI22-Ar6-AqAv-Z21-Au7-R-Y20-ArAh7-TQAd20-AnAs8-TAe20-AhAk8-P-D19-ApAl8-AAnY18-ApP10-AqG18-PAs10-W-W17-AsJ10-AuAjJ16-UJ12-AlT15-Y-B13-LZ14-AlAm14-V-Ae12-E-Ah15-RIM10-Aq-Au16-TAnK10-EAt18-AB9-AjAtA18-2A9-3A137-IAkAjI24-RB2-AtJUG24-HU3-2QAj24-LAp3-ApF-J23-NAa3-AvS-T23-KAf4-AcFL23-ArAm4-X-V22-TF7-An21-At-O7-DX20-D-Ap7-AfS19-Am2-Ab8-Am19-E-X9-AgAe18-PDAt9-IAd18-CYD10-Aa17-S-G11-AeG16-MAsAj11-VAj16-ZL13-UV14-E-H13-QAsAj12-G-E14-F-AlK10-WNY16-E-AtT7-QApH-Al17-AkEPDAn4-TAfAbAdD19-TAAoDK2-NAkAvSAf20-3AAfB2-DN3A20-4A4-4A140-MAg25-ArB3-AlAq22-AvOX-Ap4-E22-AaAp2-Ab4-At21-AtNAb-As5-UAd20-2DSWAk5-MAe21-AoMAuAl6-IE20-AiZAq7-AnU19-D-ZK7-Aq-X18-YCBAa7-W-At18-GAeO9-AhD18-AjAg10-CP17-AaAj11-F-Z16-AfAl12-DB15-R-O12-Y-E14-TAv13-G-E13-MPAa14-B-E12-Al-N14-Ap2-AuMHQZG-GAvAqUQ-Ag16-DC-AlQFKNLAjMWQ-ZAq17-SAdAtAfSAtAiMUAlAuF2Av20-ZAvAcEDKQAtAbS24-XTVBFZ2(26-6A)112-AgAuH18-YMArP6-B-AbF18-BGAnCAkVAh3-O-AdL18-ApAk-ACZC4-ArJM18-AbD-AsAgY5-AuHK18-A-P-BAd5-Ah-BAe17-F-As8-AsAfWAg17-XIJ9-Av-O18-GB9-ArAdI17-Ah-Am9-AaAfK17-WU11-C-N16-AuQ11-IQAi16-AqF11-AtTD15-E-S12-P-E14-E-Ac12-A-E13-D-Ao14-E-E12-Af-F14-E-XAoB7-AlAcAs-Ao16-E-AaAmAbBWAlArAsLAfXJVF16-AkAoAm5-An4-BAs19-TPAj2AbZAhHAdWRAm27-Ah241-XE19-AmUNX7-At-J18-Ah-As8-D2-Au17-C-X8-P2-W17-FAkAt8-Ao2-JAk16-Al2D9-E2-C16-AnAP10-D-Ag16-XAqAo10-Af-B16-YI12-AnU16-SG12-DApD14-Al-Aj12-Af-Ao14-H-U13-AfAi14-LO14-AmW13-E-R14-Av-Ad5-AnW4-CT-H14-Aa-JAvAa2-NDJK3-A-Ae16-AgHArAoAkUQAfTAtAoRAuAsNAd16-OQAa-NRAoAcLED2-LAs18-AfAg-AsAmAa2VTYPAdH21-AiXAhAmAsAnAkGAJ302-RAqEAa15-BJPAj9-T2-AeB14-ApT-Aj10-Au2-V14-AbL-Al10-Ab2-Aq9-An4-AVJ11-Ad2-G9-X4-FAnAc12-V-N9-Y4-XDAr12-Aj-Ai9-S4-AnAfC13-I-AnAv6-EAd4-AhAcS13-An-AhAr4-Ab-PAc4-WVU13-Aq2-Aa4-Ad-CO4-Au-M14-UPAgU3-JKAR4-AqAbG14-RAsAvM2-AfHAtAsH3-AjKE15-AmJHAcAqAjAmQE2L-AbZAj-X16-BFNIAjAvAf2-NApVYAlAoAi16-AmL2-AlAa-AkAhKAbAjAdOF19-AoAjONArNZArAB-Ak21-UAkDAaAsK2FVI22-Q319-AmAvV4-EX18-Au4-TMAj4-PAt2-BJCB10-AbPAbN2-YXAlB3-AcCDAGUAcS11-V3-AU2SAtV3-OAPAqAkApArU11-Aj3-JMAdAmZAqT2-RAsAoIDAaCM11-B3-J2AcAgAvGP2-HLDGAAfSG12-Am-WAcNOIRNA2-LHYAjAqAmUAk12-EAfCArQRGTAiAg2-NAhGUIAvMD13-AvAeC-HArPDAq2-KZAjQGAaG14-ArAgS-LAuAV-WAr-KAjFAjNAk14-AaOUAmNAhAgE-AuAn-AtAlSU2D15-I-T-AsAqU-AqAh-EOAcQAo19-ArAkE-MK2ApTAkXFAi19-FAlAtAmAcAaPAbAk2-SW19-OHUAhNAoAsSNQR21-ApL-CQ3-AsApAe31-Y374-JPAv4-FAcY21-HQ-Aa-BW-X-G20-W-Ap-N-UC-An-Aj15-YAdUK-Au-Av-DSApAeT2-Aj15-GAfMR-Ab-M-Ao-AaAg3-Al16-CAcQ-Ad-Al-Ai-AfO2-Y17-IN2-J-At-W-AmIJAq-Ak20-H-Z-C-AvKJK-J20-Q-Av-AeHAaRAcAa-Q20-AfAbR-AgLNQArAo-Ap21-S2-ON2-CF-Av21-M2-IK2-SGTM21-Z2-K4-AiLAl21-Z8-VAt442-GAk28-AgRAiCAoAl22-AoM2-OHEAgAiAfAmV20-AbAc2-ILAkBWAuE-Aj19-VN2-KNAcUCWP-Al19-AjQ2-RKAu-AeJC-O19-BAo2-QAr2-AgTAAcAk19-VAa2-TF4-As-J20-Am2-PO4-L-Q20-T2-A5-HAb30-AhE30-ZX31-Ai536-AbU26-AoAr2-SM5-AtB19-DAu2-MAc5-DOJ29-PY30-AoB30-DAp30-YAb30-G587-
