model
size = 32, scale = 0.05, origin = -y
material 
  colors = A:#06C B:#EEE C:#F0C
voxels
78A-11A2-7A-10A2-8A3-9A-9A2-7A3-10A2-8A2-6A3-12A2-6A4-4A4-12A3-5A4-3A4-14A3-4A5-A5-14A4-2A12-15A4-A11-16A16-17A14-19A17-14A22-8A23-7A2(23-8A)22-13A18-18A14-17A16-16A11-A4-15A6-A5-2A4-13A6-2A4-4A3-12A6-3A4-5A3-11A4-5A4-6A3-9A3-3(8A2-)10A2-9A2-19A-11A-100A-B28AC2-B12AC11A2C2AC2-BAC10A2C8A3C3AC2-B2AC9A2C7A3C4AC2-B2A2C8A2C6A3C5AC2-B3A2C6A4C4A4C5AC2-B3A3C5A4C3A4C6AC2-B4A3C4A5CA5C6AC2-B4A4C2A12C6AC2-B5A4CA11C7AC2-B5A16C7AC2-B6A14C8AC2-B7A17C4AC2-B6A23C2-B4A23CAC2-B2A23C3AC2-BA23C4AC2-B22C6AC2-B3A18C7AC2-B7A14C7AC2-B6A16C6AC2-B6A11CA4C6AC2-B5A6CA5C2A4C5AC2-B4A6C2A4C4A3C5AC2-B3A6C3A4C5A3C4AC2-B3A4C5A4C6A3C3AC2-B2A3C2(8A2C)3AC2-BA2C10A2C9A2C2AC2-B13AC11AC2AC2-B28AC-64A-29(B28AC2-)2(B28AC-64A-15(B28AC2-)6(B28AC-A)B29ABA6(B29AB-)B28AC2-)B28AC-64A-20(B28AC2-)B28AC-2(AB29AB)-6(B28AC2-)B28AC-64A-2(B28AC2-)12(B29AB-)6(B28AC2-)B28AC-2(AB29AB)-6(B28AC2-)B28AC-64A-B28AC2-B28AC-2(AB29AB)8(-B29AB)2(2(AB29AB)-6(B28AC2-)B28AC-)64A-B28AC2-3(B28AC-A)5(B28AC2-)B29AB-3(B29ABA)2(B28AC2-)B28AC-12(AB29AB)-B28AC2-B28AC-64A-2(B28AC2-)3(B28AC-A)3(B28AC2-)B29AB-2(B29ABA)B28AC-A3(B28AC2-)B28AC-12(AB29AB)-B28AC2-B28AC-64A-3(B28AC2-)3(B28AC-A)B29AB-3(B29ABA)B28AC-A18(B28AC2-)B28AC-64A-4(B28AC2-)B28AC-3(AB29AB)AB28AC-A20(B28AC2-)B28AC-64A-4(B28AC2-)B29AB-2(B29ABA)B28AC-A7(B28AC2-)B28AC-12(AB29AB)-B28AC2-B28AC-64A2(-B28AC2-B28AC-12(AB29AB))-B28AC2-B28AC-64A-B28AC2-B28AC-12(AB29AB)-B28AC2-2(2(B28AC-2(AB29AB)-2(B28AC2-))B28AC-2(AB29AB)-B28AC2-B28AC-64A-15(B28AC2-))2(2(B28AC-2(AB29AB)-2(B28AC2-))B28AC-2(AB29AB)-B28AC2-B28AC-64A-B28AC2-B28AC-12(AB29AB)-B28AC2-)B28AC-12(AB29AB)-B28AC2-B28AC-64A-3(B28AC2-)3(B28AC-A)3(B29AB-)6(B28AC2-)B28AC-12(AB29AB)-B28AC2-B28AC-64A-4(B28AC2-)B28AC-3(AB29AB)2(-B29AB)-19(B28AC2-)B28AC-64A-4(B28AC2-)B29AB-2(B29ABA)B28AC-2(AB29AB)2(-B29AB)-17(B28AC2-)B28AC-64A-3(B28AC2-)3(B29AB-)B28AC2-3(B28AC-A)3(B29AB-)2(B28AC2-)B28AC-12(AB29AB)-B28AC2-B28AC-64A-2(B28AC2-)3(B29AB-)3(B28AC2-)3(B28AC-A)B29ABA2(B29AB-)B28AC2-B28AC-12(AB29AB)-B28AC2-B28AC-64A-B28AC2-B28AC-2(AB29AB)8(AB28AC-)2(2(AB29AB)-6(B28AC2-)B28AC-)64A-B28AC2-12(B28AC-A)7(B28AC2-)B28AC-2(AB29AB)-6(B28AC2-)B28AC-64A-20(B28AC2-)B28AC-2(AB29AB)-6(B28AC2-)2(B28AC-64A-16(B28AC2-)4(B29AB-)3(B29ABA)4(B28AC-A)2(B28AC2-))B28AC-64A-29(B28AC2-)B28AC-64A-B28AC2-B11AB16AC2-BAB9A2B13ABAC2-BA2B8A3B10A2B2AC2-B2A3B5A4B8A3B3AC2-B2A4B4A5B5A4B4AC2-B3A4B2(3A5B)5AC2-B3A2(6BA)5B6AC2-B4A17B7AC2-B4A16B8AC2-B5A14B9AC2-B6A15B7AC2-B7A17B4AC2-B3A25BC2-28BAC2-BA23B4AC2-B3A19B6AC2-B6A15B7AC2-B8A14B6AC2-B7A16B5AC2-B6A18B4AC2-B5A12BA7B3AC2-B4A5B2A6B3A6B2AC2-B3A4B5A5B6A4BAC2-B2A3B7A5B8A2BAC2-BA3B9A3B10A2BC2-3B12A2B11ABC2-B14A2B12AC2-B15AB12AC2-B28AC-109A-21A-9A2-13A-6A2-8A3-10A2-8A3-5A4-8A3-9A4-4A5-5A4-11A4-2(3A5-)12A2(6-A)5-14A17-15A16-17A14-19A15-18A17-11A25-4A27-6A23-11A19-16A15-19A14-17A16-15A18-13A12-A7-11A5-2A6-3A6-9A4-5A5-6A4-7A3-7A5-8A2-6A3-9A3-10A2-4A2-12A2-11A-18A2-31A-78A
