model
size = 22 25 27, scale = 0.05, origin = -y
material 
  colors = A:#222 B:#111 C:#444 D:#555 E:#EEE
voxels
---------------------- ---------------------- ---------------------- ---------------------- ---------------------- ---------------------- ---------------------- ----------DD---------- ----------DD---------- ---------------------- ---------------------- ---------------------- ---------------------- ---------------------- ---------------------- ---------------------- ---------------------- ---------------------- ---------------------- ---------------------- ---------------------- ---------------------- ---------------------- ---------------------- ---------------------- 
---------------------- ---------------------- ---------------------- ---------------------- ---------------------- ---------------------- ---------BBBB--------- ---------BBBB--------- ---------BBBB--------- ---------BBBB--------- ----------AA---------- ---------------------- ---------------------- ---------------------- ---------------------- ---------------------- ---------------------- ---------------------- ---------------------- ---------------------- ---------------------- ---------------------- ---------------------- ---------------------- ---------------------- 
---------------------- ---------------------- ---------------------- ---------------------- ---------------------- ---------------------- ---------CCCC--------- ---------CEEC--------- --------AAAAAA-------- --------AAAAAA-------- --------AAAAAA-------- ----------AA---------- ---------------------- ---------------------- ---------------------- ---------------------- ---------------------- ---------------------- ---------------------- ---------------------- ---------------------- ---------------------- ---------------------- ---------------------- ---------------------- 
---------------------- ---------------------- ---------------------- ---------------------- ---------------------- ---------------------- --------CCCCCC-------- --------CCCCCC-------- --------AA--AA-------- --------AAAAAA-------- --------AAAAAA-------- ---------AAAA--------- ---------------------- ---------------------- ---------------------- ---------------------- ---------------------- ---------------------- ---------------------- ---------------------- ---------------------- ---------------------- ---------------------- ---------------------- ---------------------- 
---------------------- ---------------------- ---------------------- ---------------------- ---------------------- ---------------------- --------CCCCCC-------- --------CC--CC-------- --------AA--AA-------- --------AA--AA-------- --------AAAAAA-------- --------AAAAAA-------- ---------AAAA--------- ---------------------- ---------------------- ---------------------- ---------------------- ---------------------- ---------------------- ---------------------- ---------------------- ---------------------- ---------------------- ---------------------- ---------------------- 
---------------------- ---------------------- ---------------------- ---------------------- ---------------------- ----------CC---------- --------CCCCCC-------- --------CC--CC-------- --------A----A-------- --------AA--AA-------- --------AAAAAA-------- --------AAAAAA-------- --------AAAAAA-------- ---------AAAA--------- ---------------------- ---------------------- ---------------------- ---------------------- ---------------------- ---------------------- ---------------------- ---------------------- ---------------------- ---------------------- ---------------------- 
---------------------- ---------------------- ---------------------- ---------------------- ---------------------- ---------CCCC--------- --------CCCCCC-------- -------CCC--CCC------- -------AA----AA------- -------AAA--AAA------- --------AA--AA-------- --------AAAAAA-------- --------AAAAAA-------- ---------AAAA--------- ---------------------- ---------------------- ---------------------- ---------------------- ---------------------- ---------------------- ---------------------- ---------------------- ---------------------- ---------------------- ---------------------- 
---------------------- ---------------------- ---------------------- ---------------------- ---------------------- ---------CCCC--------- --------CCCCCC-------- -------CC----CC------- -------AA----AA------- -------AA----AA------- --------AA--AA-------- --------AA--AA-------- --------AAAAAA-------- --------AAAAAA-------- ---------------------- ---------------------- ---------------------- ---------------------- ---------------------- ---------------------- ---------------------- ---------------------- ---------------------- ---------------------- ---------------------- 
---------------------- ---------------------- ---------------------- ---------------------- ---------------------- --------CCCCCC-------- -------CCC--CCC------- -------CC----CC------- -------A------A------- -------AA----AA------- -------AA----AA------- --------AA--AA-------- --------AAAAAA-------- --------AAAAAA-------- ---------AAAA--------- ---------------------- ---------------------- ---------------------- ---------------------- ---------------------- ---------------------- ---------------------- ---------------------- ---------------------- ---------------------- 
---------------------- ---------------------- ---------------------- ---------------------- ----------CC---------- --------CCCCCC-------- -------CCC--CCC------- ------CCC----CCC------ -------A------A------- -------A------A------- -------AA----AA------- -------AAA--AAA------- --------AAAAAA-------- --------AAAAAA-------- ---------AAAA--------- ---------------------- ---------------------- ---------------------- ---------------------- ---------------------- ---------------------- ---------------------- ---------------------- ---------------------- ---------------------- 
---------------------- ---------------------- ---------------------- ---------------------- ---------CCCC--------- -------CCCCCCCC------- -------CC----CC------- ------CC------CC------ ------BA------AB------ ------BA------AB------ -------AA----AA------- -------AA----AA------- --------AA--AA-------- --------AAAAAA-------- --------AAAAAA-------- ---------AAAA--------- ---------------------- ---------------------- ---------------------- ---------------------- ---------------------- ---------------------- ---------------------- ---------------------- ---------------------- 
---------------------- ---------------------- ---------------------- ---------------------- --------CCCCCC-------- -------CCC--CCC------- ------CCC----CCC------ ------CC------CC------ ------BA------AB------ ------BA------AB------ ------BA------AB------ -------AA----AA------- -------AAA--AAA------- --------AAAAAA-------- --------AAAAAA-------- ---------AAAA--------- ---------------------- ---------------------- ---------------------- ---------------------- ---------------------- ---------------------- ---------------------- ---------------------- ---------------------- 
---------------------- ---------------------- ---------------------- ---------CCCC--------- -------CCCCCCCC------- -------CCC--CCC------- ------CC------CC------ ------CC------CC------ ------B--------B------ ------BA------AB------ ------BA------AB------ -------AA----AA------- -------AA----AA------- --------AA--AA-------- --------AAAAAA-------- --------AAAAAA-------- ---------AAAA--------- ---------------------- ---------------------- ---------------------- ---------------------- ---------------------- ---------------------- ---------------------- ---------------------- 
---------------------- ---------------------- ---------CCCC--------- -------CCCCCCCC------- -------CCCCCCCC------- ------CCC----CCC------ -----CCC------CCC----- ------C--------C------ ------B--------B------ ------BA------AB------ ------BA------AB------ ------BAA----AAB------ -------AA----AA------- --------AA--AA-------- --------AAAAAA-------- --------AAAAAA-------- ---------AAAA--------- ---------------------- ---------------------- ---------------------- ---------------------- ---------------------- ---------------------- ---------------------- ---------------------- 
---------------------- ---------------------- --------CCCCCC-------- -------CCCCCCCC------- ------CCC----CCC------ -----CCC------CCC----- -----CC--------CC----- -----CC--------CC----- -----BA--------AB----- -----BB--------BB----- ------BA------AB------ ------BA------AB------ -------AA----AA------- -------AAA--AAA------- --------AAAAAA-------- --------AAAAAA-------- --------AAAAAA-------- ---------AAAA--------- ---------------------- ---------------------- ---------------------- ---------------------- ---------------------- ---------------------- ---------------------- 
---------------------- ---------------------- --------CCCCCC-------- ------CCCC--CCCC------ -----CCC------CCC----- -----CC--------CC----- -----CC--------CC----- -----CC--------CC----- -----BA--------AB----- -----BB--------BB----- -----BB--------BB----- -----BBA------ABB----- -----BBAA----AABB----- ------BAA----AAB------ -------AAA--AAA------- -------AAA--AAA------- -------AAAAAAAA------- --------AAAAAA-------- --------AAAAAA-------- ---------AAAA--------- ---------------------- ---------------------- ---------------------- ---------------------- ---------------------- 
---------------------- ---------CCCC--------- -------CCCCCCCC------- ------CCC----CCC------ -----CCC------CCC----- -----CC--------CC----- ----CC----------CC---- ----CC----------CC---- ----BB----------BB---- ----BB----------BB---- ----BBB--------BBB---- -----BB--------BB----- ----BBBA------ABBB---- -----BBA------ABB----- ------BAA----AAB------ ------BAA----AAB------ -------AA----AA------- -------AA----AA------- -------AAAAAAAA------- --------AAAAAA-------- ---------AAAA--------- ---------------------- ---------------------- ---------------------- ---------------------- 
---------------------- -------CCCCCCCC------- ------CCCCCCCCCC------ -----CCCC----CCCC----- ----CCC--------CCC---- ----CC----------CC---- ----CC----------CC---- ----CC----------CC---- ---BBB----------BBB--- ---BBB----------BBB--- ----BB----------BB---- ----BB----------BB---- ----BB----------BB---- ----BBB--------BBB---- -----BB--------BB----- -----BBA------ABB----- -------AA----AA------- -------AA----AA------- ------BAA----AAB------ -------AAAAAAAA------- --------AAAAAA-------- ---------AAAA--------- ---------------------- ---------------------- ---------------------- 
----------CC---------- ------CCCCCCCCCC------ -----CCCC----CCCC----- ----CCCC------CCCC---- ----CCC--------CCC---- ----CC----------CC---- ---CC------------CC--- ---CC------------CC--- ---BB------------BB--- ---BB------------BB--- ---BB------------BB--- ---BB------------BB--- ---BB------------BB--- ---BBB----------BBB--- ----BB----------BB---- ----BBB--------BBB---- ----B------------B---- ----B------------B---- -----BBA------ABB----- ------BAA----AAB------ -------AAAAAAAA------- --------AAAAAA-------- ---------AAAA--------- ---------------------- ---------------------- 
---------------------- ------CCC----CCC------ ----CCCC------CCCC---- ----CC----------CC---- ----CC----------CC---- ---CC------------CC--- ---CC------------CC--- ---CC------------CC--- ---B--------------B--- --BB--------------BB-- --BB--------------BB-- ---B--------------B--- ---B--------------B--- ---B--------------B--- ---BB------------BB--- ---BB------------BB--- ---BB------------BB--- ---BB------------BB--- ----BBB--------BBB---- -----BBA------ABB----- ------BAA----AAB------ -------AAAAAAAA------- --------AAAAAA-------- ---------------------- ---------------------- 
---------------------- ---------------------- ----CC----------CC---- ---CCC----------CCC--- ---CC------------CC--- ---CC------------CC--- ---CC------------CC--- ---C--------------C--- --BB--------------BB-- --BB--------------BB-- --BB--------------BB-- --BB--------------BB-- --BB--------------BB-- --BB--------------BB-- ---B--------------B--- ---BB------------BB--- ---BB------------BB--- ---BB------------BB--- ----BB----------BB---- ----BBB--------BBB---- -----BBA------ABB----- ------BAA----AAB------ -------AAAAAAAA------- --------AAAAAA-------- ---------------------- 
---------------------- ---------------------- ---------------------- ---CC------------CC--- ---CC------------CC--- --CC--------------CC-- --CC--------------CC-- --CC--------------CC-- --B----------------B-- --B----------------B-- --B----------------B-- --B----------------B-- --B----------------B-- --BB--------------BB-- --BB--------------BB-- --BB--------------BB-- ---B--------------B--- ---BB------------BB--- ---BBB----------BBB--- ----BB----------BB---- -----BB--------BB----- -----BBA------ABB----- ------BAAAAAAAAB------ -------BBBBBBBB------- ---------BBBB--------- 
---------------------- ---------------------- ---------------------- ---------------------- --CC--------------CC-- --CC--------------CC-- --CC--------------CC-- -CC----------------CC- -BB----------------BB- -BB----------------BB- -B------------------B- -B------------------B- -B------------------B- --B----------------B-- --BB--------------BB-- --BB--------------BB-- --BB--------------BB-- --BBB------------BBB-- --BBB------------BBB-- ---BBB----------BBB--- ----BB----------BB---- -----BB--------BB----- -----BBAA----AABB----- ------BBBBBBBBBB------ ---------BBBB--------- 
---------------------- ---------------------- ---------------------- ---------------------- ---------------------- --C----------------C-- -CC----------------CC- -CC----------------CC- -BB----------------BB- -B------------------B- -B------------------B- -B------------------B- -B------------------B- -B------------------B- -BB----------------BB- --B----------------B-- --BB--------------BB-- --BB--------------BB-- --BBB------------BBB-- ---BB------------BB--- ----BB----------BB---- ----BBB--------BBB---- -----BB--------BB----- ---------------------- ---------------------- 
---------------------- ---------------------- ---------------------- ---------------------- ---------------------- ---------------------- ---------------------- ---------------------- -B------------------B- BB------------------BB BB------------------BB BB------------------BB BB------------------BB -B------------------B- -B------------------B- -BB----------------BB- --B----------------B-- --B----------------B-- --B----------------B-- ---------------------- ---------------------- ---------------------- ---------------------- ---------------------- ---------------------- 
---------------------- ---------------------- ---------------------- ---------------------- ---------------------- ---------------------- ---------------------- ---------------------- ---------------------- ---------------------- B--------------------B BB------------------BB BB------------------BB -B------------------B- -B------------------B- -B------------------B- ---------------------- ---------------------- ---------------------- ---------------------- ---------------------- ---------------------- ---------------------- ---------------------- ---------------------- 
---------------------- ---------------------- ---------------------- ---------------------- ---------------------- ---------------------- ---------------------- ---------------------- ---------------------- ---------------------- ---------------------- B--------------------B BB------------------BB -B------------------B- -B------------------B- ---------------------- ---------------------- ---------------------- ---------------------- ---------------------- ---------------------- ---------------------- ---------------------- ---------------------- ---------------------- 
