model
size = 23 32 32, scale = 0.05, origin = -y
material 
  colors = A:#D5B78D B:#979997 C:#C09668 D:#DCCDA9 E:#180808 F:#281818 G:#B27F50 H:#93522D I:#CD8D52 J:#6C3618 K:#343848 L:#383838 M:#E8E9E8 N:#283918 O:#F9E9E9 P:#081808 Q:#263838 R:#898B87 S:#180818 T:#687B78 U:#385858 V:#BBBBBA W:#182818 X:#080818 Y:#A9A9A7 Z:#506E70 Aa:#263828 Ab:#484848 Ac:#685850 Ad:#787978 Ae:#485858 Af:#748D91 Ag:#282818 Ah:#186858 Ai:#17282C Aj:#3A755C Ak:#92B1B1 Al:#AA989B Am:#0761C8 An:#334838 Ao:#D3D4D3 Ap:#285948 Aq:#384848 Ar:#B9B9A9 As:#AE663E At:#488918 Au:#F6C835 Av:#392828 Aw:#385847 Ax:#281828 Ay:#686868 Az:#585858 Ba:#485848 Bb:#284848 Bc:#383828 Bd:#081818 Be:#8A796B Bf:#280808 Bg:#181808 Bh:#787868 Bi:#594848 Bj:#585848 Bk:#588389 Bl:#536858 Bm:#171828 Bn:#687968 Bo:#8D7352 Bp:#647C56 Bq:#588D75 Br:#F0C76F Bs:#4B3517 Bt:#285858 Bu:#C7414D Bv:#A9B3B9 Bw:#8C98AF Bx:#EF7477 By:#8E7886 Bz:#786858 Ca:#74B9ED Cb:#64AEEA Cc:#2899D9 Cd:#484858 Ce:#484838 Cf:#F83955 Cg:#68687B Ch:#6F778F Ci:#B41013 Cj:#EED8DF Ck:#326868 Cl:#DBA46C Cm:#9E8C68 Cn:#282839 Co:#0757B3 Cp:#B0DB83 Cq:#686858 Cr:#F11315 Cs:#92B092 Ct:#485838 Cu:#382818 Cv:#174D50 Cw:#489989 Cx:#695869 Cy:#5C9B9D Cz:#48382F Da:#382839 Db:#389989 Dc:#786868 Dd:#5858A9 De:#075CBD Df:#0649A2 Dg:#E9DAC8 Dh:#D2F9F6 Di:#974E51 Dj:#6C3829 Dk:#762D46 Dl:#BDA7A1 Dm:#383818 Dn:#488987 Do:#574818 Dp:#4A3848 Dq:#686848 Dr:#F9E9F9 Ds:#95692F Dt:#381818 Du:#383808 Dv:#4F556C Dw:#6D5231 Dx:#484828 Dy:#B8AD7F Dz:#584738
voxels
459-C22-D22-O664-EJA19-HAcDB20-COB21-OB22-D251-2H19-H2GA19-2C2A19-2ADA20-2AD295-C2EA18-CHAcDQ20-COB21-OB2(22-D)205-2H18-JHGHAo17-3H2GY17-G3CAAc17-4ADAl18-4ABv21-A2(D22-)D43-3C19-2IAD18-2HJHJ132-C2H2EA18-CHAcDL19-2COBl19-ADO2(B21-D)B2(22-O)159-GC17-2J2GHAo16-J3H2GAl16-2G3CAc17-C4ADAl17-5AV19-3AAa21-DB20-2DAy19-3AC18-4CCn18-C2IAR18-2HJHAd17-JHG2IG21-IA45-C19-H2IH17-CHI2EB12-D2A3-CHAcDT12-AOD3-3COT11-DA2DO3-ADOAe11-AD3O4-ADAq11-3DA5-ADAn12-2AD6-AL21-A2(O22-)D113-HG17-2CG2HCj16-C3H2GB16-2G3CAc16-GC4ADAl16-C5AV16-6AAd16-4A2DBn16-4A2DAi17-5AQ17-A4CBm17-2C2IAR17-3HJBh18-JHG2IV16-C2A2CIA14-C3A2CI2C14-4A2CIGB12-6AIH2ICd11-3ADADCHI2EBw11-AD2A2DACHAcDAf10-3A5D4BZ10-ADA4DAC3BT10-2A4DOD2C2BAn10-A3D2AOA2C2BCe11-3A2D2A3CBV12-2ADAD2A2CAV18-2ACACx19-A2CAn14-O2AcDR19-2K2Ac19-ERFJ19-F2E26-2G17-H2G2HAo16-C3H2GY15-H2G3CBi16-GC4ADAl15-2CA4BBv15-3A4BAi14-AC2A4BAi14-C3A4BAe14-C3A4BW14-C3A4BBd14-3AC4BR13-2A2CH3BAd14-2AGFJHG2IV12-C2(2A2C)IV11-2CAC3A2CICCv11-C6A2CIGAf11-C6AIH2ICn10-C3ADADCHI2EAf10-2AD2A2DACHAcDBb9-4A5D4BAi9-2ADA4DA4BAv9-3A6D4BBg10-A3D4A4BW10-4A2D2A4BP11-3ADAD5BBy11-2A4CA5B13-AC2ACI3BAa14-5O18-R2K2B3-Bg14-FER2BCp2-X15-F2MB3-X21-2G17-4GHAo16-4H2GAl15-H2G3CDz16-GC4ADY14-3CA4BY14-2C2A4BAb14-2C2A4BW13-AC3A4BAe2(13-2C3A4BP)12-2C3AC4BR12-C2A2CH3BAd13-C2AGFJ4BAr11-2C2A2CA4BV11-2CAC3A4BAf10-2C6A4BAi10-2C6A4BBt9-2C3ADADC4BAp9-C2AD2A2DA4BU9-4A5D4BAb9-2ADA4DA5B9-3A6D4BAa9-2A3D4A4BBe10-4A2DA5BBc10-4ADAD5BAo10-3A4C5BDr12-GAC2A5BDp13-Au-4O16-2AuR2K2B2-NX12-Ak2MER2BCp2-X15-4MB2-P21-2G17-G3CHCj16-G3H2GB15-H2G3CBi15-2GC4ADY14-3CA4BBv13-3C2A4BL13-A2C2A4BW13-AC3A4BAq13-2C3A4BBd12-A2C3A4BX12-2C3AC4BR11-2C2A2CH3BDc12-2C2AGFJ4BAo11-2C2A2CA4BV10-3CAC3A4BBt10-2C6A4BAi9-A2C6A4BAj9-2C3ADADC4BZ9-C2AD2A2DA4BQ9-4A5D4BBa8-3ADA4DA4BAz8-4A6D4BBh9-2A3D4A4BAg9-5A2DA5BF9-5ADAD5BAv10-3AAyAeDArDyArAbZBBe11-CG8-BX12-Au2-Al2OAl16-BrER2K2B-AtNX12-Ak2MER2BE2BW14-Dh4M2B-Ct21-2G17-4GHAo16-G3H2GAr15-H2G3CAd15-2GC4ADAo13-G3CA4BY13-3C2A4BAe12-CG2C2A4BAi12-3C3A4BAz12-A2C3A4BBm12-A2C3A4BX11-A2C3AC4BAo11-AC2A2CH3BAl11-3C2AGFJ4BAo10-3C2A2CA4BV9-G3CAC3A4BAi9-3C6A4BAi9-A2C6A4BCn9-2C3ADADC4BAx8-2C2AD2A2DA4BAx8-5A5D4BQ8-3ADA4DA4BQ8-4A6D4BBz8-3A3D4A4BDt8-6A2DA5BAx8-6ADAD5BX8-ACAArAkT3UBTAvZYAo10-C24-Br3-AlO17-Br2-2K2B-AlNP12-FE-ER2BE2BAn13-7MB-Bp22-G17-5GM16-G3H2GY15-C2G3CAc15-HGC4ADAr13-G3CA4BY12-G3C2A4BAq12-CG2C2A4BY11-G3C3A5B11-G3C3A4BL11-A3C3A4BS11-3C3AC5B10-A2C2A2CH3BDc11-A2C2AGFJ4BV9-A3C2A2CA5B10-3CAC3A4BK9-3C6A4BQ8-GA2C6A4BDa8-3C3ADADC4BCz8-2C2AD2A2DA4BDa8-C4A5D4BQ8-3ADA4DA4BAb8-4A6D4BBo8-3A3D4A4BDq8-6A2DA5BX8-6ADAD5BP8-ACBjBnBTAe2UAeTBiAwBY8-AC24-Bd22-3N2-KB-EYAhP12-FJ2ERBE3BBd12-3MAkMAk2MB-Ap40-6G16-G3H2GY15-3G3CBi15-HGC4ADY13-H3C5AB12-H3C2A4BL12-CG2C2A4BBg11-G3C3A4BAx11-G3C3A4BAv10-G4C3A4BP10-G3C3AC5B10-A2C2A2CH3BAd10-A3C2AGFJ4BV9-A3C2A2CA4BY9-A3CAC3A4BQ8-A3C6A4BQ8-GA2C6A4BBm8-3C3ADADC4BAi8-2C2AD2A2DA4BBc8-C4A5D4BAb8-C2ADA4DA4BCz8-C3A6D4BBo8-3A3D4A4BBo8-6A2DA5BP8-6ADAD5BP8-CBaBj3TCeW2AwTAzAeAkAf8-C48-3NAhAa3-2YArBd12-F2J4E3BN12-3MAkMAk2MB-At62-2G2H2GA15-3G3CAc15-HGC4ADV13-H3C5AY12-G3C2A4BBl11-GCG2C2A4BQ11-G3C3A4BZ10-2G3C3A4BAw10-G4C3A4BW10-G3C3AC5B10-3C2A2CH3BBy10-G3C2AGFJ4BV9-G3C2A2CA4BY9-A3CAC3A4BAn8-G3C6A4BX8-2A2C6A4BCj8-3C3ADADC4BV8-2C2AD2A2DA4BAg8-C4A5D4BAn8-C2ADA4DA3BAb9-C3A6D3BAa9-C2A3D4A3BP9-C5A2DA4BQ9-C5ADAD5BP8-CLDxBaAqU3CBkBbUAqTAj8-C5-DlArAq40-N2AaAhApAjL4SN12-F2JER5BAp13-2M2(AkM)2B-Aj84-3G3C2A14-2GC4ADAd13-H3C5AAy12-H3C2A4BBn11-HCG2C2A4BBc11-G3C3A4BBl10-2G3C3A4BQ10-G4C3A4BL9-2G3C3AC5B9-G3C2A2CH4BBm9-G3C2AGFJ4BK8-2G3C2A2CA4BR8-2G3CAC3A4BAg8-4C6A4BAg8-GA2C6A4BAw8-3C3ADADC4BBi7-CAC2AD2A2DA4BX7-C5A5D4BX7-G3ADA4DA3BN8-G4A5D4BN8-G3A3D3A4BP8-G6A2DA4BP8-G6ADAD5BAt7-GAC2AAbAwZBkBw2AfUChTU7-GAClAC2(22-At)BpRAoBCq2S3-N14-JER2B2WAgAh14-2(MAk)M2B-Ao84-3G3C2A14-2GC4ADBz13-G3C5ABj12-G3C6AQ11-HCG2C4A2DBn11-H3C5A2DW10-HG3C3A4BBh10-G4C3A4BBe9-CG3C3AC4BBh9-G3C2A2CH4BBh8-2G3C2AGFJ4BQ8-2G3C2A2CA4BQ7-3G3CAC3A4BAb7-G4C6A4BBa7-CGA2C6A4BAe7-4C3ADADC4BAb7-GAC2AD2A2DA4BS7-G5A5D4BX7-G-2ADA4DA3BX8-G4A5D4BN8-G3A3D3A4BN8-G6A2DA4BP7-2G6ADAD5BAa6-2GAC2ABzCeCkQBaBwAqUZAeAi6-2GBuBrABu19-Cr22-N2-Bp2-VRAz2S3-Y14-JER2BWBmCaR14-JFEAk3B-S106-CGC3AGDA13-G3C5AD12-G3C6AD11-2CG2C4A2DAi11-G3C5A2DQ10-HG3C7AAd10-H4C3A4CAd9-HG3C3AC4BAd9-G3C2A2CH4BAd8-2G3C2AGFJ4BT8-2G3C2A2CA4BQ5-C4G3CAC3A4BQ4-2CJG4C6A4BQ4-DAH2GA2C6A4BAb3-IDGH4C3ADADC4BL3-D-A2GAC2AD2A2DA4BAa2-CO2-AG5A5D4BX2-I3-AG3ADA4DA3BP3-D3-AG4A5D4BP6-DCG3A3D3A4BP6-ACH6A2DA4BN6-CGH5ADkDAD5BAa5-2GHAC2ABz-CyBqArAfBlAcAyCxAi5-2GH2CiCrCf16-HJ-J19-C2-N2(2-V)RAz2S3-Aa2-A2C12-2BWDdCbAj17-2B3-S150-4C4A2GD11-2CG2C4A3D11-G3C5A3D10-2G3C8A10-G4C3A5C9-HG3C3A2C2IAB9-H3C2A2C3HJHB8-2G3C2AGFJ5B8-2G3C2A2CA5B5-5G3CAC3A5B5-CJG4C6A4BAg5-GH2GA2C6A4BF4-2GH4C3ADADC4BBe3-DIAG-AC2AD2A2DA4BF2-JOCHA-5A5D4BX2-ICGJA-3ADA4DA3BP3-DG-HA-4A5D4BAn2-C-G-DC-3A3D3A4BP-C2-J-AC-6A2DA4BAn-I3-GCG-5ADjDAD5BNC2-4G-AAvCuBcAe-AfDnBk2TChBwBk-C2-J3G-G14-C2-F2HJ17-C4J2(2-At)2-VAlAmLS3-Ah2-ACJ12-AmBWDeCbBq17-AmCc3-L240-G4C3A5C9-2G3C3A2C2IAAe9-G3C2A2C3HJHAn9-G3C2AGFJHG2IAg8-2G3C2A2CA4BAx6-GI2G3CAC3A4BAv5-CJG4C6A5B5-G-2GA2C6A5B4-2G2-3C3ADADC4BBy4-GA2-AC2AD2A2DA4BAg3-GCH2-5A5D4BF3-CG3-3ADA4DA3BP4-GH3-4A5D4BQ3-AGH3-G2A3D3A4BAn2-2AJH3-6A2DA4BAn2-ICJG3-5ADiDAD5BP-ICG4-GC2AQ-AkBvAvUApAwCvAjBt-CIJ4-GBsDoBs12-2HF20-C2J10-CsBqAmLS3-Bq2-AC13-AmBWCoCaAl17-AmCc3-L275-G9-G3C2A2C5GB9-G3C2AGFJHG2IAx8-2G3C2(2A2C)IAx8-2G3CAC3A4BAv7-G4C6A4BAx7-2GA2C6A5B7-H3C3ADADC5B7-HAC2AD2A2DA4BF7-H5A5D4BAx7-H3ADA4DA3BP8-G4A5D4BP8-G3A3D3A4BP8-G6A2DA4BP8-G5ABiDAD5BAa7-GAC2AAw-TCwAe5QAp7-GBxAsBuAs42-Aa2NAa2-Ap2AhLS3-Ar17-AmBWDfCaR17-AmCc3-S275-G9-EBf2C2AC6GV9-E3C2AGFJHG2IX9-E3C2(2A2C)IB7-EBfG3CAC3A5B6-EG4C6A5B5-2E2GA2C6A5B5-2EH3C3ADADC5B6-EHAC2AD2A2DA4BL6-EH5A5D4BAv7-H3ADA4DA4BAg7-H4A6D4BQ7-H3A3D3A5BAa7-J6A2DA5BBp7-J6ADAD5BP7-FAC2ABe2ZCwU5BN7-JBuHDsCf2-Au2-2SBg2SF10-Au3-Au16-AtNAaN2-Bn2Aj2S3-Aa17-AmBSCoCbAp17-2Am3-L218-12E10-E44-EBf2J2A2C5GBg8-2E3C2AGFJHG2IB6-E2-E3C2(2A2C)IB6-2EBfG3CAC3A4BCq6-EG4C6A4BAd5-FC2GA2C6A4BAg5-FIH3C3ADADC4BAg6-EHAC2AD2A2DA4BR6-EH5A5D4BAi6-FH3ADA4DA4BAb7-E4A6D4BAa7-E3A3D4A4BQ7-E6A2D2A4BAn7-E6ADAD5BBd7-EAC2AAbAzCgDbAj5BBd7-EAsBoGCm5-Cd2(KL)Aq7-2E32-S3-N18-Am2WBgAa240-13E10-4EJ2A6E9-7EA6E8-2E3C2A2C3HJHJ9-E3C2AGFJHG2IAf6-E-2E3C2(2A2C)IAy6-2EAG3CAC3A4BBl6-EG4C6A4BBb5-EC2GA2C6A4BZ5-EIH3C3ADADC4BAf4-2F2HAC2AD2A2DA4BCy4-2F2H5A5D5B4-EFIH3ADA4DA4BCs3-2EBfEF4A6D4BR5-Bf-E3A3D4A4BP6-EJ6A2D2A4BP6-EJ6A2(DA)4BK6-EFA2BsBcAqTZDbAp5BP6-EJBa8-AbKL3K41-S3-N18-Am2WAgN218-12E10-EF3C5A2CA10-E4C3A5C9-EG3C3A2C2IAAf8-2E3C2A2C3HJHAd8-2E3C2AGFJHG2IU6-4E3C2(2A2C)IT6-2EFG3CAC3A4BZ6-EG4C6A4BAf5-EC2GA2C6A4BAf5-EIH3C3ADADC4BT4-EA2HAC2AD2A2DA4BAf4-EA2H5A5D4BU4-EAIH3ADA4DA4BAq3-EC-EF4A6D4BBl3-2E2-F3A3D4A4BX3-FE-FJ6A2D2A4BX4-Bf-EJ6A2(DA)4BN6-EFAC2AAbChBkAfAjA4BN6-EBaClAsBxA5-LAb2L2K41-S2WAg23-P218-3F9E10-EG3C8A10-E4C3A4CCg9-FG3C3A2C2IAAd9-E3C2A2C3HJHAd9-E3C2AGFJHG2IR7-3E3C2(2A2C)IAd5-3EFG3CAC3A2CICBy5-2EG4C6A4BAd5-EC2GA2C6A4BR5-EIH3C3ADADC4BR4-EA2HAC2AD2A2DA4BAy4-EA2H5A5D4BZ4-EAIH3ADA4DA4BBt3-ECAEH4A6D4BU4-EAFH3A3D4A4BX4-2ECJ6A2D2A4BDu4-2EGJ6A2(DA)4BP4-EFIFAC2ABeTAdYApA4BP4-2EHBaBxAsIAs5-3LKLK41-2AhAyAhP197-2(F-)6E12-E10F11-E3C5A3D10-EG3C7AAr10-E4C3A3CU10-EG3C3A2C2ICk10-E3C2A2C3HJZ9-2E3C2AGFJHGIAj8-3E3C2(2A2C)U7-2EFG3CAC3A2CIAj7-2E4C6A2CIAj7-E2GA2C6A3BAj6-EIH3C3ADADC4BU4-EA2HAC2AD2A2DA4BCk4-EA2H5A5D4BU4-EAIH3ADA4DA4BZ4-EAIH4A6D4BT4-EAIH3A3D4A4BAz4-EACJ6A2D2A4BT4-EAGJ6A2(DA)4BZ4-ECIFAC2ABeZAzBApA4BK4-FEHCtAsBxCfAs5-KLAbKLK41-2AhVAhP22-An197-2F8E12-F2C5A3D10-EF3C7AD10-E4C3A4CD9-EG3C3A2C2IAD9-E3C2A2C3HJHD8-2E3C2AGFJHG2ID7-3E3C2(2A2C)ID7-EFG3CAC3A2CICB5-3E4C6A2CIK7-E2GA2C6A3BK6-2EH3C3ADADC3BK6-E2HAC2AD2A2DA3BK5-2E2H5A5D4BAb5-EIH3ADA4DA4BAy4-EAIH4A6D4BBb4-EAIH3A3D4A4BBb4-EACJ6A2D2A4BAe4-2EGJ6A2(DA)4BAe4-2EIFADmCuAgBbTVUBbA4BU5-EHTBj8-4L2K18-Au22-NAhArAhZ22-T219-11E11-12E10-F12E10-13E9-F3C2A2C3H3F8-2E3CA9F7-3E3CA8FD6-E2FG3CA5FC2FD6-2E4C6A2CIGD7-EGA2C6AIHIK7-EH3C3ADADCHIEK7-EHAC2AD2A2DACHAcAb6-E2H5A5D3CK6-EIH3ADA4DA4BAq4-2EIH4A6D4BU4-2EIH3A3D4A4BU4-2ECJ6A2D2A4BAe5-EGJ6A2(DA)4BDv5-EIFAC2AAqAiTBkApA4BCg5-FEZBjCmGDw5-2LKCd2K21-Au20-NAtNV22-Dg224-2(F-F20-)2(F-)2E17-5E10-13EF9-7EF4E2F7-13E3F6-2EF11E3F7-F4CA6FC3F7-EGA2C6AIH2ID7-E3C3ADADCHIEK7-EHAC2AD2A2DACHAcK7-EH5A5D3CK7-EH3ADA4DACADOAq6-EH4A6DACADAw6-EH3A3D4A4BQ6-EJ2(A2F)2D2A4BF5-2EJ2(A2F)2(DA)4BD5-FEFAC3ACUZBbA4BD6-EJAsClIAsCmL3-3L3K42-3NAg22-F292-2F20-3E16-F3E-F16-2E4-F5-F9-E2F4-F5-F8-4EF2EF4E3F8-E14F7-EC13FD7-EA2FAD8F2D7-EA2FA10FD7-EA2FD5FA4FD6-EHA2FA5FD4FD6-EHA2FD10F2(D6-EJ10FA3F)L6-2E2(A2F)TBAp3A2FBc6-2EACi2AsBoW3-K2LKAbK22-E22-Bc22-Bh315-F40-F43-EF-F2-2F14-E2FEF2EF5E2F7-5EF2EF5E2(2F8-EFE2F2EFEF3E)2F2(7-2E2(FE3FE)FE)6-3(F2E)FEF3EFE6-FE15F6-2(FE3FE)5F6-F2E9F2A2FD8-E3FLBjAa2F6K45-D22-D400-F24-2F9-E9-F-F10-E8-F2-F10-E8-F-2F10-E8-F-F2-E4-2E10-F2-F-2E4-2E10-FE-F20-4E-E3-2E2-E9-3E3-2(E-)E2-E9-F3E2(4FE)F8-4E2(2FEFE)F594-E22-E13-F21-2(F2E)F7E9-2E3-2(2E2-)E10-F-3E2-3E13-F2-E3-2E3-E92-
