model
size = 32 32 13, scale = 0.05, origin = -y
material 
  colors = A:#1B1B1B B:#1E1E1E C:#987914
voxels
9-2(14A18-)14A20-10A469-3A6-3A19-6A2-6A17-16A16-16A15-3A2CAC2(A2C)2AC2A14-3A5(C2A)13-4A2CAC2(A2C)2AC3A12-4A4(C2A)C3A12-4A2CAC3(A2C)3A14-16A18-12A114-2(A14-A16-)A14-A17-14A18-14A19-7(12A20-)12A19-3(14A18-)14A17-16A16-16A15-5A-6A-5A14-5A3-2A3-5A14-2(5A8-)3A3-5A8-5A3-3A-5AB6A8-6AB5A-4AB6A8-6AB4A4-2AB6A8-6AB2A7-AB6A8-6ABA9-B6A8-6AB11-6A8-6A14-16A79-2(A16-A14-)A16-A15-2(2A12-2A16-)2A12-2A17-5(A12-A18-)A12-A17-3(2A12-2A16-)2A-A8-A-2A16-2A12-2A15-5(2A14-)2A13-3A14-3A12-3A14-3A7-4AB3A14-3AB4A-5AB3A14-3AB10AB3A14-3AB5A2-3AB3A14-3AB3A5-2AB3A14-3AB2A7-AB3A14-3ABA9-B3A14-3AB11-4A2-A6-A2-4A15-5A4-5A20-2A6-2A17-2A16-2A12-2A16-2A13-A16-A2(14-2A)15-6(A14-A16-)A14-A15-12(2A14-)A16-A13-2(2A16-2A12-)2A16-2A8-3A-2A16-2A-3A4-3ABA18-AB3A6-AB20-BA9-B20-B5-2A28-2A-2A26-2A3-2A24-2A5-2AB2A16-2AB2A7-AB3A14-3ABA9-B7A6-7AB14-4A6-4A15-2(2A16-2A12-)2A16-2A13-27(2A14-)2A13-3(2A16-2A12-)2A16-2A10-A-A18-A-A9-BA18-AB101-A30-A-A28-A3-3AB2A16-2AB3A5-2AB3A14-3AB2A7-AB5A10-5ABA10-6A8-6A3(12-2A16-2A)12-3A14-3A13-25(2A14-)2A13-3(2A16-2A12-)2A16-2A10-A-A18-A-A9-BA18-AB101-A30-A-A28-A3-3AB2A16-2AB3A5-2AB3A14-3AB2A7-AB5A10-5ABA9-B6A8-6AB11-3(2A16-2A12-)3A14-3A13-25(2A14-)2A13-3(2A16-2A12-)2A16-2A10-A-A18-A-A9-BA18-AB101-A30-A-A28-A3-3AB2A16-2AB3A5-2AB3A14-3AB2A7-AB5A10-5ABA9-B6A8-6AB11-2(2A16-2A12-)2A16-2A13-27(2A14-)2A13-3(2A16-2A12-)2A16-2A10-A-A18-A-A9-BA18-AB101-A30-A-A28-A3-3AB2A16-2AB3A5-2AB3A14-3AB2A7-AB5A10-5ABA10-6A8-6A2(12-2A16-2A)13-A16-A2(14-2A)15-6(A14-A16-)A14-A15-12(2A14-)A16-A13-2(2A16-2A12-)2A16-2A10-A-2A16-2A-A9-BA18-AB69-2A28-2A-2A26-2A3-2A24-2A5-2AB3A15-2AB2A7-AB3A14-3ABA9-B7A6-7AB12-6A6-6A3(14-A16-A)15-2(2A12-2A16-)2A12-2A17-5(A12-A18-)A12-A17-4(2A12-2A16-)2A12-2A15-5(2A14-)2A13-3A14-3A8-2A2-3A14-3A2-2A4-3AB3A14-3AB3A9-2A14-2A7-2A5-2A14-2A5-2A2-A3-3A14-3A3-A5-2AB3A14-3AB2A7-AB3A14-3ABA9-B3A14-3AB11-4A2-A6-A2-4A12-8A4-8A14-6A4-6A3(16-A14-A)17-14A18-14A19-7(12A20-)12A19-3(14A18-)14A17-16A16-16A15-5A-6A-5A14-5A3-2A3-5A14-2(5A8-)3A2-6A8-6A2-3A-5AB6A8-6AB5A2-3AB6A8-6AB3A5-2AB6A8-6AB2A7-AB6A8-6ABA9-B6A8-6AB11-6A8-6A13-18A15-7A2C7A18-12A19-2(14A18-)14A20-10A469-4A4-4A19-14A17-16A16-16A15-18A14-18A13-3(20A12-)20A13-18A15-16A17-5A4C5A755-5A2-5A19-14A17-16A16-16A15-18A15-16A17-14A20-4A2C4A75-
