model
size = 32 18 32, scale = 0.05, origin = -y
material 
  colors = A:#FF009E B:#8C00F1 C:#FFE000 D:#E00 E:#9CF F:#111
voxels
3-4B18-4B5-6B16-6B3-3(8B14-8B2-)8B14-8B-10A12-20A12-10A-8A14-8A2-8A14-8A3-6A16-6A4-6A16-6A2-10A12-20A12-10A-8A14-8A2-8A14-8A3-6A16-6A4-6A16-6A5-4B18-4B5-6B16-6B3-3(3B2C3B14-8B2-)3B2C3B3(14-8B-4A5CA12-14A5CA12-10A-3A4CA14-8A2-3A4CA14-8A3-2A3CA16-6A4-2A3CA16-6A2-2A4C4A12-11A5C4A12-10A-A4C3A14-8A2-2A3C3A14-8A3-2A2C2A16-6A4-6A16-6A5-4B18-4B5-6B16-6B3-8B3(14-8B2-3B2C3B))4(14-8B-4A5CA12-A3C10A5CA12-A4C5A-3A4CA14-A4C3A2-3A4CA14-A4CF2A3-2A3CA16-A3C2A4-2A3CA16-A3C2A2-2A4C4A12-11A5C4A12-10A-A4C3A14-8A2-2A3C3A14-8A3-2A2C2A16-6A4-6A16-6A5-4B18-4B5-6B16-6B3-8B3(14-8B2-3B2C3B))14-8B-4A5CA12-A3C10A5CA12-A4C5A-3A4CA14-A4C3A2-3A4CA14-A4CF2A3-2A3CA16-A3C2A4-2A3CA16-A3C2A2-2A4C4A12-11A5C4A12-10A-A4C3A14-8A2-2A3C3A14-8A3-2A2C2A16-6A4-6A16-6A5-4B18-4B5-6B16-6B3-3(8B14-8B2-)8B14-8B-10A12-20A12-10A-8A14-8A2-8A14-8A3-6A16-6A4-6A16-6A2-10A12-20A12-10A-8A14-8A2-8A14-8A3-6A16-6A4-6A16-6A6917-4B18-4B5-6B16-6B3-3(8B14-8B2-)8B14-8B-10A12-20A12-10A-8A14-8A2-8A14-8A3-6A16-6A4-6A16-6A2-10A12-20A12-10A-8A14-8A2-8A14-8A3-6A16-6A4-6A16-6A5-4B18-4B5-6B16-6B3-8B14-B4C3B2-2B5C2(B14-B4C3B2-2BE4C)B14-B4C3B-4A5CA12-A3C3D7A5CA12-A4C2D3A-3A4CA14-A4CD2A2-3A4CA14-A4CF2A3-6A16-A3CDA4-6A16-A3CDA2-2A6C2A12-12A7CA12-AC8A-2A5CA14-8A2-3A4CA14-8A3-3A2CA16-6A4-6A16-6A5-4B18-4B5-6B16-6B3-8B14-B4C3B2-2B5C2(B14-B4C3B2-2BE4C)B14-B4C3B-4A5CA12-A3C3D7A5CA12-A4C2D3A-3A4CA14-A4CD2A2-3A4CA14-A4CF2A3-6A16-A3CDA4-6A16-A3CDA2-2A6C2A12-12A7CA12-AC8A-2A5CA14-8A2-3A4CA14-8A3-3A2CA16-6A4-6A16-6A5-4B18-4B5-6B16-6B3-8B14-B4C3B2-2B5C2(B14-B4C3B2-2BE4C)B14-B4C3B-4A5CA12-A3C3D7A5CA12-A4C2D3A-3A4CA14-A4CD2A2-3A4CA14-A4CF2A3-6A16-A3CDA4-6A16-A3CDA2-2A6C2A12-12A7CA12-AC8A-2A5CA14-8A2-3A4CA14-8A3-3A2CA16-6A4-6A16-6A5-4B18-4B5-6B16-6B3-8B14-B4C3B2-2B5C2(B14-B4C3B2-2BE4C)B14-B4C3B-4A5CA12-A3C3D7A5CA12-A4C2D3A-3A4CA14-A4CD2A2-3A4CA14-A4CF2A3-6A16-A3CDA4-6A16-A3CDA2-2A6C2A12-12A7CA12-AC8A-2A5CA14-8A2-3A4CA14-8A3-3A2CA16-6A4-6A16-6A5-4B18-4B5-6B16-6B3-8B14-B4C3B2-2B5C2(B14-B4C3B2-2BE4C)B14-B4C3B-4A5CA12-A3C3D7A5CA12-A4C2D3A-3A4CA14-A4CD2A2-3A4CA14-A4CF2A3-6A16-A3CDA4-6A16-A3CDA2-2A6C2A12-12A7CA12-AC8A-2A5CA14-8A2-3A4CA14-8A3-3A2CA16-6A4-6A16-6A5-4B18-4B5-6B16-6B3-8B14-B4C3B2-2B5C2(B14-B4C3B2-2BE4C)B14-B4C3B-10A12-A3C3D13A12-A4C2D3A-8A14-A4CD2A2-8A14-A4CF2A3-6A16-A3CDA4-6A16-A3CDA2-10A12-20A12-AC8A-8A14-8A2-8A14-8A3-6A16-6A2(4-6A16-6A5-4B18-4B5-6B16-6B3-8B14-B4C3B2-2B5C2(B14-B4C3B2-2BE4C)B14-B4C3B-10A12-A3C3D13A12-A4C2D3A-8A14-A4CD2A2-8A14-A4CF2A3-6A16-A3CDA4-6A16-A3CDA2-10A12-2A6C12A12-A8CA-8A14-A6CA2-8A14-A5C2A3-6A16-A3C2A)4-6A16-6A5-4B18-4B5-6B16-6B3-3(8B14-8B2-)8B14-8B-2(10A12-20A12-10A-8A14-8A2-8A14-8A3-6A16-6A4-6A16-6A2-)
