model
size = 26 32 28, scale = 0.05, origin = -y
material 
  colors = A:#F0F B:#F9F C:#F3F D:#C3C E:#F6F F:#C9C G:#FC3 H:#FC0 I:#C6C J:#F9C K:#C39 L:#F93 M:#C93 N:#969 O:#C96 P:#EEE Q:#966 R:#C99 S:#100 T:#800 U:#F6C V:#C69 W:#444 X:#C0C Y:#DDD Z:#C09 Aa:#636 Ab:#900 Ac:#039 Ad:#CCF Ae:#CCC Af:#002 Ag:#666 Ah:#777 Ai:#BBB Aj:#00F Ak:#C9F Al:#00A Am:#C06 An:#03C Ao:#E00 Ap:#A00 Aq:#00D Ar:#004 As:#001 At:#500 Au:#700 Av:#400 Aw:#200 Ax:#630
voxels
416-2D22-2D-2(AD20-DA2-)2AD18-D2A2-2AD18-D2A3-2AD16-D2A4-C3A14-2A2C5-2C2A12-2A2C8-C2A10-2AC577-D2-A18-A2-D2(-A)18-A-AD-2(3A18-3A2-)2(4A16-4A2-)5A14-5A3-5A12-5A5-5A-2AC2DC2A-5A7-7AD2-D7A7-D6AD4-D4A3D264-AD20-DA3-AD18-DA4-AD17-D2A4-2AD16-D2A4-2AD7-FB7-D2A5-AD7-2B7-DA6-AD16-D3(A6-A18-)A6-AC16-CA6-AE16-EA2-D-3AD16-D3AD-3AD16-D4A-3A2D14-2D4A2(-4AD14-D5A)D5AD12-D5AD-6AD10-D6A2-D6A-EC4ACE-6AD3-D8AL2AL8AD5-20A42-Aj195-2A20-2A3-2A18-2A5-3(2A16-2A6-)2A6-BF2B2(6-2A)6-4B2(6-2A)2(7-2B7-2A6-DA)7-2B7-2A6-2D7-2B7-DA4-2(AC)6-4B6-2(CA)2-3AE5-I4BD5-E3AD-3AB2AmZI8BUZ2AmB4AD4A16B5AD4AE14BE5AD5A14B6AD5A14B12AE12BE6A-6AEB2J4B2JBE6A2-7AJEC4ACEJ7A2-10A4L10A3-22A10-M2H5M2HM16-H-GQAjQG-H20-HGH2(24-G)QG24-M23-4J20-2J4B2J16-J10BJ13-J4B4F4BJ8-2A-J4BF4OR4BJ-2A5-2A5BF5-R4B2A6-2ABR4BY3P-R4B2A6-2A2R14B2A6-2ARF4BIFBN6B2A6-DARAk14B2A6-DARAkF13B2A6-DARF14B2A6-DAAkQ2AoAk6BAk2AqQAk2A6-2DWAoApAwApI4BYAlAsAlAqWDA4-3ACWAtAuAvAp6B2(AlAr)W2(CA)2-3AE5BI4BDI4BE3A2D3ABUZKI8BU3KB9A16B10AE14BE11A2(14B12A)E12BE13AE10BE7A-7ABEC4ACEB7A2-10A4L10A3-22A8-GM2H7A2HMG11-An2G9A2GAn120-4B20-8B16-12B13-6B2F6B11-J5B4OF6B8-A5BF4RAxF5B8-A6BY3PW6B8-A17B8-A6BIFBN7B4(8-A17B)8-DBVSAbTI5BAdAfPAg2B5-3ACBAaSTK6BFAcAeWBC3A2-3AE5BI4BDI4BE3A2D3ABUZKI8BU3KB9A16B10AE14BE11A2(14B12A)E12BE13AE10BE7A-7ABEC4ACEB7A2-10A4L10A3-22A7-GHM2H7A2HMHG9-GH2G9A2GHG10-G3-7A3-G10-GQG11-GQG10-M13-M42-4B20-8B16-12B13-6B2F6B11-6B2OROF6B9-5BFNY2PAhF5B9-6BV2NAiQ6B9-17B9-6BIFBN7B4(9-17B)9-BVSAbTI5BAdAfPAg2B4-D3ACBAaSTK6BFAcAeWBC3A2D3AE5BI4BDI4BE8ABUZKI8BU3KB9A16B5AC4AE14BE4A2(2C5A14B5A)2C5AE12BE5AC7AE10BE7A-7ABEC4ACEB7A2-10A4L10A3-22A7-2M13A2M9-2G13A2G11-4A4C5A95-4J20-2J4BJB16-12B13-6B2F6B11-6B2OROF6B9-5BFNY2PAhF5B9-6BV2NAiQ6B9-17B9-6BIFBN7B4(9-17B)9-BVSAbTI5BAdAfPAg2B4-4ACBAaSTK6BFAcAeWBC8AE5BI4BDI4BE8ABUZKI8BU3KB9A16B5AC4AE14BE4A2(2C5A14B5A)2C5AE12BE5AC7AE10BE7A-7ABEC4ACEB7A2-10A4L10A3-22A6-M2H13A2HM7-H2G13A2GH10-2A8C3A95-4J20-2J4BJB16-12B13-6B2F6B11-6B2OROF6B9-5BFNY2PAhF5B9-6BV2NAiQ6B9-17B9-6BIFBN7B2(9-17B)2(8-A17B)8-DBVSAbTI5BAdAfPAg2B4-4ACBAaSTK6BFAcAeWBC8AE5BI4BDI4BE8ABUZKI8BU3KB4AC4A16B4A2C4AE14BE4A2(2C5A14B5A)2C5AE12BE5AC7AE10BE7A-7ABEC4ACEB7A2-10A4L10A3-22A6-3H13A3H7-H17AH8-3A11C2A94-4J20-2J4B2J16-BJ10B13-6B2F6B11-6B2OROF6B9-5BFNY2PAhF5B9-6BV2NAiQ6B9-17B9-6BIFBN7B9-17B5-2B2-17B-2B2(2-JB2A16B2ABJ)-AJBADBVSAbTI5BAdAfPAgBDABJ3ACACBAaSTK6BFAcAeWBCAC6AE5BI4BDI4BE4AC3ABUZKI8BU3KB3A2C4A16B4A2C4AE14BE4A2(2C5A14B5A)2C5AE12BE5AC7AE10BE7A-7ABEC4ACEB7A2-10A4L10A3-22A6-H17AH8-17A9-2A13CA91-B2J4B3J16-10B15-12B13-6B2F6B11-6B2OROF6B9-5BFNY2PAhF5B9-6BV2NAiQ6B9-17B9-6BIFBN7B9-17B5-2B2A17BA2B2-2B2A16B2A2B-A2B2A16B2(2A2B)ADBVSAbTI5BAdAfPAgBDA2BD2ACACBAaSTK6BFAcAeWBCAC6AE5BI4BDI4BE4AC3ABUZKI8BU3KB3A2C4A16B4A2C4AE14BE4A2(2C5A14B5A)2C5AE12BE5AC7AE10BE7A-7ABEC4ACEB7A2-10A4L10A3-22A6-H17AH7-G17AG8-A14CA91-10B16-10B15-12B13-6B2F6B11-6B2OROF6B9-5BFNY2PAhF5B9-6BV2NAiQ6B9-17B9-6BIFBN7B9-17B5-B3A16B3A3-2B2A16B2A2B-A2B2A16B2A2BDA2BADBVSAbTI5BAdAfPAgBDA2B3ACACBAaSTK6BFAcAeWBCAC2AC3AE5BI4BDI4BE3A2C3ABUZKI8BU3KB3A2C4A16B4A2C4AE14BE4A2(2C5A14B5A)2C5AE12BE5AC7AE10BE7A-7ABEC4ACEB7A2-10A4L10A3-22A6-M17AM7-Q17AQ7-GA14CA-G33-G17-G37-10B16-10B15-12B13-6B2F6B11-6B2OROF6B9-5BFNY2PAhF5B9-6BV2NAiQ6B9-17B9-6BIFBN7B7-DA16B2A4-2D2A16B2A2D-5A16B4AD5A16B9ADBVSAbTI5BAdAfPAgBD6ACACBAaSTK6BFAcAeWBCAC2AC3AE5BI4BDI4BE3A2C3ABUZKI8BU3KB3A2C4A16B4A2C4AE14BE4A2(2C5A14B5A)2C5AE12BE5AC7AE10BE7A-7ABEC4ACEB7A2-10A4L10A3-22A6-M17AM6-2Aj17A2Aj6-GA14CA-G7-G17-G7-Q17-Q7-M17-M11-10B16-10B15-12B13-6B2F6B11-6B2OROF6B9-5BFNY2PAhF5B9-6BV2NAiQ6B9-17B9-6BIFBN7B7-DA16BA5-2D2A16B2A2D-5A16B4AD5A16B9ADBVSAbTI5BAdAfPAgBD4A2(CA)CBAaSTK6BFAcAeWB2(CA)2C3AE5BI4BDI4BE3A2C3ABUZKI8BU3KB3A2C4A16B4A2C4AE14BE4A2(2C5A14B5A)2C5AE12BE5AC7AE10BE7A-7ABEC4ACEB7A2-10A4L10A3-22A6-M17AM7-Q17AQ7-GA14CA-G33-G17-G37-10B16-10B15-12B13-6B2F6B11-6B2OROF6B9-5BFNY2PAhF5B9-6BV2NAiQ6B9-17B9-6BIFBN6BD7-DA16BA5-2D2A16B2A2D-5A16B10A16B9ADBVSAbTI5BAdAfPAgBD4A2(CA)CBAaSTK6BFAcAeWB2(CA)7(2C24A)C26A-24A2-24A3-22A6-H17AH7-G17AG8-A13C2A91-10B16-10B15-12B13-6B2F6B11-6B2OROF6B9-5BFNY2PAhF5B9-6BV2NAiQ6B9-17B7-DA6BIFBN6BA7-DA16BA5-2D2A16B2A2D-5A16B10A16B9ADBVSAbTI5BAdAfPAgBD4A2(CA)CBAaSTK6BFAcAeWB2(CA)7(2C24A)C26A-24A2-24A3-22A6-H17AH8-17A9-2A11C3A117-2X6D2X16-X8CX15-D10CD14-D10CD12-2X11A2CAB9-X15AB7-D17AD7-D18A7-20AD3-2D20A2D-78AC7(24A2C)24AC26A-24A2-24A3-22A6-3H13A3H7-H17AH9-3A8C3A196-10C13-D15AD8-D16AD7-D18A7-20AD5-20AD3-2D20A2D-78AC7(24A2C)24AC26A-24A2-24A3-22A6-M2H13A2HM7-H2G13A2GH10-3A7C2A197-10C13-D15AD8-18A7-2(20AD5-)21A3-D21A2D-78AC7(24A2C)24AC26A-24A2-24A3-22A7-2M13A2M9-2G13A2G12-10A222-12AX11-AX16A7-20A6-21A5-21A3-D21A2D-104AC6(24A2C)24AC26A-24A3-22A4-22A7-GHM2H7A2HMHG9-GH2G9A2GHG10-G3-7A3-G221-9A17-9A15-13A10-20A6-21A3-D21A2D-130AC4(24A2C)24AC26A-24A2-24A3-22A5-20A9-GM2H7A2HMG11-An2G9A2GAn346-20A4-X21A2D2-24A-260A3-20A7-18A10-14A12-14A14-M3H3M3HM15-2H-GQAjQG-2H19-3G2(24-G)QG24-M274-21AD3-X2A3C12A3C3A2-3A2C2AD11A2(2C3A2-3A2C14A)2C3A3(2-24A)2-3A4C10A4C2(3A2-3A18C)3A2-5A14C5A4-3A14C3A7-18A10-14A71-Aj411-5(8A18-)8A694-8D18-8A18-C6AC18-D6AD2(18-8A)694-8A18-D6AD18-C6AC18-D6AD18-7AC18-8A694-A6DA3(18-D6AD)18-7AC18-8A694-C6AC18-A5D2(AC18-AD4C)DC18-A6DC18-C4A3C399-
