model
size = 21 32 14, scale = 0.05, origin = -y
material 
  colors = A:#222 B:#63C C:#3A1C74 D:#412083 E:#FC3 F:#9571DE G:#331966 H:#5027A0 I:#000 J:#B59AEB K:#482491 L:#5E2FBD M:#FF0 N:#572BAE O:#F93 P:#111 Q:#FF9 R:#FF6 S:#7547D2 T:#A585E5 U:#855CD8 V:#444 W:#555 X:#300 Y:#FF3 Z:#99C
voxels
3-7AK6AC6-2C6AD6A6-2C13A6-6C9A6-9C5AC6-10C5A6-2D3CD3CH2C3A6-7D4CKC2A6-5KR4DM4C6-K4HRMKD2MDCKC6-2(HN)H2M2Q2M3CD6-HN3LN4MKDK2C6-LNL2BR4MRK2DC6-L3BR2Q2M2QRK2D6-NLB4J2Q3JH2K6-NF4JF2MF3JHK6-2F2J7F2JFH6-FJV2FVFV4FVJL6-FJW2FWFW4FWJF6-FJPF2PF3P2FPJF6-FJ2PFP6FPJF6-DJP2FPF7PN6-CF2J7F2JFN6-2C3J5F3J2L7-2C9JLH9-3C5J2KD133-8AK6ACA4-3C2(6AD)4-3C14A4-D6C10A4-10C5ACA4-11C6A4-3D3CD3CH2C4A4-8D4CKC2AD4-6K5D5CA4-HK4H3K4DCK2C4-2HNHN3H2K2D3CDC4-2HN3L2NH3KDK3C4-2(NL)3B2L2H2K2D2C4-NL7BLNH2K3D4-2NLB2S2F2BL2NH2KD4-HNLBSF3TS2BLNHKD4-HLIBSF4JFZBLNHK4-LNLIBFI2JITIBI2LH4-KHILUBITJITISIBLN4-2DHIH3IFTIFS2ILN4-2DKCLN2UB4S2B2L4-2DHIDILNI2BIBIL2N4-2C3(DI)LIUIBIL2N4-3CDI2D2(ID)LI3LN4-2A3C6DLKL2HD4-3AKA2C3D3K4D4-8A2C7D5-AC2A7O4D88-16(19A2-)16AQ2A-BG15AEAG2BG15AYAG2BG15AEA2(G2BG17A)G3B2(17A4B)17A2B2-16AD4-15A2D4-6A5E2A4D5-C2A9E70-14(E17-E2-)E17-E-BG17-G2BG17-GB168-2B17-4B3-A13-2B2-A15-D4-2A11-3D7-AOE7-EOA47-13(A17-A2-)A17-A-BG17-GB252-2B17-2B-G15-ABG3-2A13-2A6-OE9-EO26-5(B17-B2-)3(H17-H2-)3(D17-D2-)C17-C2-C17-C-BC17-CB294-2B17-2B-GA15-AG4-AE11-EA7-2(OE9-EO5-5(B17-B2-)3(H17-H2-)3(D17-D2-)C17-C2-C17-C-BC17-CB294-2B17-2B-G17-G2-3A13-3A5-)OE9-EO5-5(B17-B2-)3(H17-H2-)3(D17-D2-)C17-C2-C17-C-BC17-CB294-2B17-2B-G17-G3-2A13-2A6-OE9-EO5-13(A17-A2-)A17-A-BG17-GB252-2B17-2B-G17-G2-2A15-2A4-2A2E7-2E3A2(7-2E)6-6(EA15-AE2-)E2A13-2A2(E2-EA15-A)6(E2-E17-)E-BG17-G2BG17-GB168-2B17-4B17-2B-G17-G2-3A13-3A4-16A9-7E14-7O8-2(A-A13-A-A2-)A-2A11-2A6(-A2-A-15A)-A7(2-19A)2-G17AG-B4(G17AG2B)G17AG3B2(17A4B)17A2B-2(G17AG2-)19A4-16A6-14A48-11(15A6-)15A5-3(17A4-)17A3-19A6(2-G17AG)2-G4(2IA)2(IA)IG2-GA3(I2A)IAI2A2IG2-AXI2AIA2(I2A)3(IA)2-2(2AI)2(A2I)A2(I2A)2-19A5-14A69-11(15A6-)15A5-17A4-6AR4AM5A4-6ARM2A2M5A4-6A2M2Q2M5A4-7A4M6A3-7AR4MR6A2-6AR2Q2M2QR5A2-9A2Q8A2-9A2M8A6(2-19A)106-
