model
size = 21 32 14, scale = 0.05, origin = -y
material 
  colors = A:#222 B:#63C C:#3A1C74 D:#412083 E:#FC3 F:#855CD8 G:#000 H:#5027A0 I:#331966 J:#EEE K:#7547D2 L:#482491 M:#F93 N:#BBB O:#DDD P:#9571DE Q:#A585E5 R:#B59AEB S:#300 T:#FF9 U:#FF3 V:#99C
voxels
3-7AL6AC6-2C6AD6A6-2C13A6-6C9A6-9C5AC6-10C5A6-2D3CD3CH2C3A6-2D4AD2C3AC2A6-L2AN3JD2A3J2C6-LANJHA2JDNJANJC6-2(HANJ)2A3JCD6-HANJK3(ANJ)C6-KF2J2ANJH2JANJC6-K2B4JBKF3J2D6-FK3FP2FBK2FH2L6-FK2FP3Q2FBKFHL6-KG2FP4RPFBKFH6-FKGFPG2RGQGFG2K6-HGK2FGQRGQ2(GF)K6-DHGH3GPQGPF2GK6-D2LK8F2BK6-DHGDGKFG2BGFGKF6-C3(DG)KGFGBGKF6-2CDG2D2(GD)KG3K7-3C6DKLKH9-4C3D3LD133-8AL6ACA4-3C2(6AD)4-3C14A4-D6C10A4-10C5ACA4-11C6A4-3D3CD3CH2C4A4-8D4CLC2AD4-6L5D5CA4-HL4H3L4DCL2C4-2HFHF3H2L2D3CDC4-2HF3K2FH3LDL3C4-2(FK)2BF2K2H2L2D2C4-FK2B4FBKFH2L3D4-2FK3F2PFBK2FH2LD4-HFK2FP3Q2FBKFHLD4-HKG2FP4RPVBKFHL4-KFKGFPG2RGQGFG2KH4-LHGK2FGQRGQ2(GF)KF4-2DHGH3GPQGPF2GKF4-2DLCK8F2B2K4-2DHGDGKFG2BGFGK2F4-2C3(DG)KGFGBGK2F4-3CDG2D2(GD)KG3KF4-2A3C6DKLK2HD4-3ALA2C3D3L4D4-8A2C7D5-AC2A7M4D88-16(19A2-)16AT2A-BI15AEAI2BI15AUAI2BI15AEA2(I2BI17A)I3B2(17A4B)17A2B2-16AD4-15A2D4-6A5E2A4D5-C2A9E70-E17A14(E2-E17-)E-BI17-I2BI17-IB168-2B17-4B3-A13-2B2-A15-D4-2A11-3D7-AME7-EMA47-19A13(2-A17-A)-BI17-IB252-2B17-2B-I15-AFI3-2A13-2A6-ME9-EM26-B17A4(B2-B17-)B3(2-H17-H)3(2-D17-D)2(2-C17-C)-BC17-CB294-2B17-2B-IA15-AI4-AE11-EA7-2(ME9-EM5-B17A4(B2-B17-)B3(2-H17-H)3(2-D17-D)2(2-C17-C)-BC17-CB294-2B17-2B-I17-I2-3A13-3A5-)ME9-EM5-B17A4(B2-B17-)B3(2-H17-H)3(2-D17-D)2(2-C17-C)-BC17-CB294-2B17-2B-I17-I3-2A13-2A6-ME9-EM5-19A13(2-A17-A)-BI17-IB252-2B17-2B-I17-I2-2A15-2A4-2A2E7-2E3A2(7-2E)6-E17A5(E2-EA15-A)E2-E2A13-2A2(E2-EA15-A)6(E2-E17-)E-BI17-I2BI17-IB168-2B17-4B17-2B-I17-I2-3A13-3A4-16A9-7E14-7M8-A-15A-A2-A-A13-A-A2-A-2A11-2A6(-A2-A-15A)-A7(2-19A)2-I17AI-B4(I17AI2B)I17AI3B2(17A4B)17A2B-2(I17AI2-)19A4-16A6-14A48-11(15A6-)15A5-3(17A4-)17A3-19A6(2-I17AI)2-I4(2GA)2(GA)GI2-IA3(G2A)GAG2A2GI2-ASG2AGA2(G2A)3(GA)2-2(2AG)2(A2G)A2(G2A)2-19A5-14A69-11(15A6-)15A5-17A4-2(3A3J)N4A4-2A2(JNA)2J2AJN3A4-3A3J2(2AJN)3A4-2A2(JNA)JN2AJN3A3-3AJNA2JAJN2A2J4A2-4A3J3A4J5A4(2-19A)2-4AO3AOAO2AO5A2-4A3(OA)O2AO5A2-5AOA2OAOA3O4A2-19A106-
