model
size = 26 27 9, scale = 0.05, origin = -y
material 
  colors = A:#F93 B:#EEE C:#F60 D:#F96 E:#F99 F:#111
voxels
-------------------------- -------------------------- -------------------------- -------------------------- -------------------------- ------------EE------------ ------------EE------------ -------------------------- -------------------------- -------------------------- --------AAA----AAA-------- -------ABBBA--ABBBA------- -------BBFBB--BBFBB------- -------BBFBA--ABFBB------- -------ABBA----ABBA------- --------AA------AA-------- -------------------------- -------------------------- -------------------------- -------------------------- -------------------------- -------------------------- -------------------------- -------------------------- -------------------------- -------------------------- -------------------------- 
-----------CCCC----------- ----------AACCAA---------- ---------AAAAAAAA--------- --------CCABBBBACC-------- --------CAAAAAAAAC-------- --------CAAAEEAAAC-------- -------CCAAAAAAAACC------- -------AAAAAAAAAAAA------- -------AAAAAAAAAAAA------- -------AAAAAAAAAAAA------- -------AAAAAAAAAAAA------- -------ABBBAAAABBBA------- ------CBBBBBAABBBBBC------ ------CBBBBAAAABBBBC------ -------ABBAAAAAABBA------- -------AAAAAAAAAAAA------- -------AAAAAAAAAAAA------- -------CCCCCAACCCCC------- --------CCCAAAACCC-------- -------------------------- -------------------------- -------------------------- -------------------------- -------------------------- -------------------------- -------------------------- -------------------------- 
-------------------------- ---------AAAAAAAA--------- ---------AAAAAAAA--------- --------AAABBBBAAA-------- --------AAAAAAAAAA-------- -------CAAAAEEAAAAC------- ------CAAAAAAAAAAAAC------ ------AAAAAAAAAAAAAA------ ------AAAAAAAAAAAAAA------ ------AAAAAAAAAAAAAA------ ------AAAAAAAAAAAAAA------ ------AABBBAAAABBBAA------ ------ABBBBBAABBBBBA------ ------ABBBBAAAABBBBA------ ------AABBAAAAAABBAA------ ------AAAAAAAAAAAAAA------ ------AAAAAAAAAAAAAA------ ------AAAAAAAAAAAAAA------ -------AAAAAAAAAAAA------- --------AAAAAAAAAA-------- -------------------------- -------------------------- -------------------------- -------------------------- -------------------------- -------------------------- -------------------------- 
-------------------------- ---------AAAAAAAA--------- --------AAA----AA--------- -------CAAABBBBAAAC------- -------CAAAAAAAAAAC------- ------CAAAAAEEAAAAAC------ ------CAAAAAAAAAAAAC------ ------AAAAAAAAAAAAAA------ ------AAAAAAAAAAAAAA------ ------AAAAAAAAAAAAAA------ ------AAAAAAAAAAAAAA------ ------AABBBAAAABBBAA------ ------ABBBBBAABBBBBA------ ------ABBBBAAAABBBBA------ ------AABBAAAAAABBAA------ ------AAAAAAAAAAAAAA------ ------AAAAAAAAAAAAAA------ ------AAAAAAAAAAAAAA------ ------AAAAAAAAAAAAAA------ -------AAAAAAAAAAAA------- --------AAAAAAAAAA-------- -------------------------- -------------------------- -------------------------- -------------------------- -------------------------- -------------------------- 
-------------------------- ---------AAAAAAAA--------- --------AAA----AAA-------- -------AAAABBBBAAAA------- ------CAAAAAAAAAAAAC------ -----CAAAAAAAAAAAAAAC----- -----CAAAAAAAAAAAAAAC----- -----CAAAAAAAAAAAAAAC----- -----AAAAAAAAAAAAAAAA----- -----AAAAAAAAAAAAAAAA----- -----AAAAAAAAAAAAAAAA----- -----AAABBBAAAABBBAAA----- -----AABBBBBAABBBBBAA----- -----AABBBBAAAABBBBAA----- -----AAABBAAAAAABBAAA----- -----AAAAAAAAAAAAAAAA----- -----AAAAAAAAAAAAAAAA----- -----AAAAAAAAAAAAAAAA----- -----AAAAAAAAAAAAAAAA----- ------AAAAAAAAAAAAAA------ -------AAAAAAAAAAAA------- --------AACAAAACAA-------- -------------------------- -------------------------- -------------------------- -------------------------- -------------------------- 
-------------------------- ---------AAAAAAAA--------- --------AAAAAAAAAA-------- -------AAAAAAAAAAAA------- ------AAAAAAAAAAAAAA------ -----AAAAAAAAAAAAAAAA----- ----CAAAAAAAAAAAAAAAAC---- ----CAAAAAAAAAAAAAAAAC---- ----CAAAAAAAAAAAAAAAAC---- ----CAAAAAAAAAAAAAAAAC---- -----AAAAAAAAAAAAAAAA----- -----AAABBBAAAABBBAAA----- -----AABBBBBAABBBBBAA----- -----AABBBBAAAABBBBAA----- ----CAAABBAAAAAABBAAAC---- ----CAAAAAAAAAAAAAAAAC---- ----CAAAAAAAAAAAAAAAAC---- ----CAAAAAAAAAAAAAAAAC---- ----AAAAAAAAAAAAAAAAAA---- -----AAAAAAAAAAAAAAAA----- ------AAAAAAAAAAAAAA------ -------AAAAAAAAAAAA------- --------ACCCAACCCA-------- -------------------------- -------------------------- -------------------------- -------------------------- 
-------------------------- ---------AAAAAAAA--------- --------AAAAAAAAAA-------- -------AAAAAAAAAAAA------- ------AAAAAAAAAAAAAA------ -----AAAAAAAAAAAAAAAA----- ----AAAAAAAAAAAAAAAAAA---- ----AAAAAAAAAAAAAAAAAA---- ----AAAAAAAAAAAAAAAAAA---- ----AAAAAAAAAAAAAAAAAA---- -----AAAAAAAAAAAAAAAA----- -----AAAAAAAAAAAAAAAA----- -----AAAAAAAAAAAAAAAA----- -----AAAAAAAAAAAAAAAA----- ----AAAAAAAAAAAAAAAAAA---- ---CAAAAAAAAAAAAAAAAAAC--- --CCAAAAAAAAAAAAAAAAAACC-- --CCAAAAAAAAAAAAAAAAAACC-- -CC-AAAAAAAAAAAAAAAAAA-CC- -C---AAAAAAAAAAAAAAAA---C- CC---AAAAAAAAAAAAAAAA---CC C-----AAAAAAAAAAAAAA-----C C------CACCCAACCCAC------C C------CACCCAACCCAC------C C-----CC----------CC-----C C---CCC------------CCC---C CCCCC----------------CCCCC 
-------------------------- ---------AAAAAAAA--------- --------AAAAAAAAAA-------- -------AAAAAAAAAAAA------- ------AAAAAAAAAAAAAA------ -----AAAAAAAAAAAAAAAA----- ----AAAAAAAAAAAAAAAAAA---- ----AAAAAAAAAAAAAAAAAA---- ----AAAAAAAAAAAAAAAAAA---- ----AAAAAAAAAAAAAAAAAA---- -----AAAAAAAAAAAAAAAA----- -----AAAAAAAAAAAAAAAA----- -----AAAAAAAAAAAAAAAA----- -----AAAAAAAAAAAAAAAA----- ----AAAAAAAAAAAAAAAAAA---- ---AAAAAAAAAAAAAAAAAAAA--- ---AAAAAAAAAAAAAAAAAAAA--- ---AAAAAAAAAAAAAAAAAAAA--- --ADAAAAAAAAAAAAAAAAAADA-- -ADDDAAAAAAAAAAAAAAAADDDA- -DDDDAAAAAAAAAAAAAAAADDDD- -DDDDDAAAAAAAAAAAAAADDDDDA -DDDDDDAAAAAAAAAAAADDDDDDA -DDDDDDAAAAAAAAAAAADDDDDDA -DDDDD-A-----------ADDDDDA -DDD----------------ADDDDA -------------------------- 
-------------------------- -------------------------- -------------------------- -------------------------- -------------------------- -------------------------- -------------------------- -------------------------- -------------------------- -------------------------- -------------------------- -------------------------- -------------------------- -------------------------- -------------------------- -------------------------- -------------------------- -------------------------- --AAAAA-------------AAA--- --AAAAAA-----------AAAAA-- --AAAAAA----------AAAAAAA- --AAAAAA----------AAAAAA-- ---AAAAA----------AAAAA--- ----AAA-----------AAAA---- ------A------------A------ -------------------------- -------------------------- 
