model
size = 13 32 28, scale = 0.05, origin = -y
material 
  colors = A:#222 B:#111
voxels
43-4B8-6B6-3B2-3B5-2(2B4-)3B2(4-2B)2(6-2B3-2B)6-B4-2B5-2B4-2B5-B6-B4-2B6-B4-B8-4B10-B246-B3A8-B-3A8-2B2-2A6-2B4-2A5-2B4-A2(2B3-2B6-)2B3-2B5-A2B3-2B5-2(2B4-)3B2(4-2B)5-3B2-3B6-6B8-4B232-2A9-2A2-2A7-A-2A-A6-3A2-3A371-5A7-A4-A6-A2-3A-A5-A-A3-2A5-2A4-2A345-5A7-A4-2(A6-)A5-A-4A2-A3-A-A4-A-A3-A-A5-2A3-2A6-2A82-A12-2A2-A9-4A10-A195-3A8-2A3-2(A6-)A5-3(A3-)A2-2A-A2-A3-A-A4-A-A3-A-A5-2(2A3-2A6-)2A42-A12-2A5-A6-A4-2A6-2A2-2A8-4A9-3A193-5A7-2(A5-)A7-A3-A4-2(A3-)A2-2(2A-)A3-A-A5-A-A2-A-A5-2(2A3-2A6-)2A3-2A7-A16-A7-2A3-A6-2A4-2(2A5-)A4-2A6-2A3-2A6-2A-3A8-4A192-5A7-2(A5-)A7-A3-2(A4-)A-A4-2(A-A3-)A3-A2-A-A2-A5-A-3A2-A5-A-A2-2A6-A-A2(2-2A7-2A)2-2(A7-2A3-)2A5-A-A3-2(2A5-)A4-2A6-2A2-2A8-4A10-A181-5A7-2(A5-)A7-A3-A9-A-A5-2A3-A-A3-2A2-A2-2(3A2-A5-A-)3A-A2(7-2A2-2A)7-2A2-A8-2A2-A7-2A3-2A6-2A3-2A5-3A4-A5-2A5-A12-2A2-A9-4A179-5A6-2A2(5-A)7-A3-A8-A3-A9-2(3A4-)2A2(3-A)3-2A2-A5-A-3A2-A6-2(A-)2A7-3A-3(2A7-2A2-)2A7-A3-A12-2A5-2(2A4-)2A6-2A2-3A6-A-3A9-3A167-5A6-2A2(5-A)7-A3-A8-A3-A9-A-A11-2A3-5A3-2A2-A5-A2-2A2-A6-3(A-)A6-2(A-)2A7-3A-2A7-2(A-)2A7-2A2-2(A7-2A3-)A6-A-A3-2A4-A-A2(4-2A)6-6A8-4A167-3A8-2A3-2A5-A7-A3-A8-A3-A9-A2-A9-A-A11-2A3-5A3-2(2A2-A5-A2-)2(A-)A6-3A-2(2A7-2(A-))2A7-2A2-A7-2A3-A6-A-A3-A6-2(2A4-)3A5-2A2-3A7-4A168-A10-5A7-2(A5-)A7-A3-A8-A3-A9-A2-A9-A-A11-2A3-5A2(3-2A)3-A2-2(A-)A5-A2-2(A-)A6-2(2(A-)2A7-)2A2-A8-2A2-2(A7-2A3-)2A210-3A8-2A3-2A5-A6-A5-A7-A3-2(A9-A2-)A9-A-A11-2A5-3A3-3A2-2A3-A2-3A-A6-3(A-)A6-2(A-)2(2A7-2A2-)A249-4A8-A4-2A5-A6-A5-A7-A3-A8-A3-3(A9-A2-)A4-3A3-A-A2-2A3-A2-2(A-)A6-2A-3A2(7-2A2-2A)7-2A2-A249-5A7-2(A5-)2(A7-A4-)A7-A3-A8-A3-2(A9-A2-)A3-5A-2(A2-)A5-2(2A-)A6-2A-3A7-2A2(-A)7-2A2-2A7-2A2-A236-4A8-A4-A7-2(A5-)4(A7-A4-)A8-A2-A9-2(A2-)6A-A2-A-A6-2A-A2-A6-2(A-2A-A7-)A-3A9-A-2A236-5A7-A5-A6-2(A5-)A6-A5-3(A7-A4-)8A-A2-A9-2(A2-)6A2-2A2-A6-3(A-2A-A7-)5A8-2A-2A8-2A-A21-A12-A4-2A3-3A5-7A7-5A8-4A128-4A8-A4-A7-4(A5-A6-)7A13-A3-9A-A2-A10-A-A2-6A2-2A2-A6-3(A-2A-A7-)5A8-A-3A8-2A-2A7-3A-2A6-4A2(-A)3-2A-3A2-A-3A2-3A3-A5-4A3-A4-4A5-7A7-5A101-2A10-A2-2A7-A4-A7-2(A5-A6-)A4-2A6-5A22-8A2-3A8-A-A10-2A2-7A2-2(2A-A7-A-)2A-A7-4A-A7-A-3A8-A-3A7-A2-3A6-A3-2A-A4-A3-2(A-)A3-A4-A2-A-3A5-A2-A8-A3-A7-2A3-2(2A5-)7A7-5A76-A10-5A7-A4-A7-2(A5-A6-)A3-3A6-4A33-11A2-A10-A-A10-2A2-7A2-4(2A-A7-A-)3A8-A-3A7-A2-2A-A5-A2-2(A-)A4-A3-A-A2-A-2A4-2(A2-)A5-2(A3-A8-)A3-A7-2(A5-)A7-5A62-A11-4A8-2(A4-A7-)A5-A6-A2-3A7-3A38-7A2-4A7-A-A10-A-A6-2(2A2-)5A2-4(A-2A-A7-)A-3A7-A2-2A-A6-3(A-)A5-A2-A-A2-2(A3-)2(A2-)3A2(3-A)2(8-A3-A)7-2(A5-)A7-5A63-A10-4A8-2(A4-A7-)A4-2A6-A2-3A7-3A47-12A-A10-A-A10-2A7-2(2A2-)7A2-3(2A-A7-A-)2A-A6-A2-2A-A6-3(A-)A5-A2-A-A2-2(A3-)2(A2-)3A2(3-A)2(8-A3-A)7-2(A5-)A7-5A62-A11-4A8-2(A4-A7-)A5-A6-A4-2A6-5A45-12A-A10-3(2A11-)2A2-7A2-2(2A-A7-A-)2A-A6-A2-2A-A5-2(A2-)A-2(A3-)2(A2-)A-A4-A2-A3-A4-A3-A8-A3-A7-A5-2(A6-)A4-A7-5A63-B10-5B7-B4-B7-3(B5-B6-)6B49-6B-6B6-4(2B11-)2B2-7B2(2-2B)4-B2-B-2B6-B-B2-B-B4-2(B2-)B-2(B3-)2(B2-)3B2(3-B)8-B3-B8-B4-B6-B5-2(B6-)B3-2B8-3A63-2B9-2B2-2B7-B4-2(B6-)2(B5-B6-)B6-7B55-14B3(11-2B)11-B-B10-B-B3-4B2(2-B)-6B2(2-B)2-4B3-2(B2-)3B2(3-B)8-B4-B7-B4-B6-B5-2(B6-)B4-B7-6B74-3B8-2B3-B7-B4-2(B6-)2(B5-B6-)B6-7B55-12B-B2(11-2B)11-B-B10-B-4(B9-B2-)B8-B3-B8-B4-B7-B4-B6-B5-2(B6-)B4-B7-6B73-4B8-6B6-7B6-4B-3B2(5-8B)6-7B59-6B3-12B-26B-12B-11B2-5B-5B2-4B-B-4B2-5B-5B2-10B2(4-9B)4-8B5-8B6-6B7-6B17-
