model
size = 17 21 17, scale = 0.05, origin = -y
material 
  colors = A:#89916B B:#EEA9A9 C:#DB4D6D D:#BBB E:#FFF F:#E16B8C G:#AAA H:#111 I:#DDD J:#0D5661
voxels
----------------- ----------------- ----------------- ----------------- ----------------- ----------------- ----------------- CCC-------------- CCC-------------- CCC-------------- CCC-------------- CCC-------------- CCC-------------- CCC-------------- ----------------- ----------------- ----------------- ----------------- ----------------- ----------------- ----------------- 
----------------- ----------------- ----------------- ----------------- CCC-------------- CCC-------------- CCC-------------- CCC-------------- -FG-------------- -FG-------------- -FG-------------- -FG-------------- -FG-------------- CCC-------------- CCC-------------- CCC-------------- CCC-------------- ----------------- ----------------- ----------------- ----------------- 
----------------- ----------------- ----------------- CCC-------------- CCC-------------- -FG-------------- -FG-------------- -FG-------------- -ED-------------- -ED-------------- -CD-------------- -ED-------------- -ED-------------- -FG-------------- -FG-------------- -FG-------------- CCC-------------- CCC-------------- ----------------- ----------------- ----------------- 
----------------- ----------------- ----------------- CCC-------------- -FG-------------- -ED-------------- -ED-------------- -ED-------------- -ED-------------- -ED-------------- -ED-------------- -ED-------------- -ED-------------- -ED-------------- -ED-------------- -ED-------------- -FG-------------- CCC-------------- ----------------- ----------------- ----------------- 
--ABABABABABA---- -AB---------AB--- CB-----------BAA- CCC------------B- -FG------------A- -ED------------B- -ED------------A- -ED------------B- -ED------------I- -ED------------B- -ED------------A- -ED------------B- -ED-----------AAA -ED-----------AAA -ED-----------AAA -ED------------B- -FG------------A- CCC-----------BB- CB-----------BAA- -AB---------AB--- --ABABABABABA---- 
--BABABABABAB---- -BA---------BA--- CA-----------ABB- -FC------------A- -EG------------B- -ED------------A- -ED------------DD -ED------------II -ED------------B- -ED------------A- -ED------------B- -ED------------A- HHD-----------AAA HHD-----------AAA -ED-----------AAA -ED------------A- -EG------------B- -FC-----------AA- CA-----------ABB- -BA---------BA--- --BABABABABAB---- 
--ABABABABABA---- -AB---------AB--- CB-----------BAA- -FC------------B- -EG------------A- -ED------------DD -ED------------II -ED------------B- -ED------------A- -ED------------B- -ED------------A- HHD------------B- HHD-----------AAA -ED-----------AAA -ED-----------AAA -ED------------B- -EG------------A- -FC-----------BB- CB-----------BAA- -AB---------AB--- --ABABABABABA---- 
--BABABABABAB---- -BA---------BA--- CA-----------ABB- -FC------------A- -EG------------B- -ED------------DD -ED------------II -ED------------A- -ED------------B- -ED------------A- HHD------------B- HHD------------A- -ED-----------AAA -ED-----------AAA -ED-----------AAA -ED------------A- -EG------------B- -FC-----------AA- CA-----------ABB- -BA---------BA--- --BABABABABAB---- 
--ABABABABABA---- -AB---------AB--- CB-----------BAA- -FC-----------BB- -CG------------A- -ED------------DD -ED------------II -ED-------------- -ED------------A- -ED-------------- AJD------------A- -ED-------------- -ED-----------AAA -ED-----------AAA -ED-----------AAA -ED-------------- -CG------------A- -FC-----------BB- CB-----------BAA- -AB---------AB--- --ABABABABABA---- 
--BABABABABAB---- -BA---------BA--- CA-----------ABB- -FC------------A- -EG------------B- -ED------------DD -ED------------II -ED------------A- -ED------------B- -ED------------A- HHD------------B- HHD------------A- -ED-----------AAA -ED-----------AAA -ED-----------AAA -ED------------A- -EG------------B- -FC-----------AA- CA-----------ABB- -BA---------BA--- --BABABABABAB---- 
--ABABABABABA---- -AB---------AB--- CB-----------BAA- -FC------------B- -EG------------A- -ED------------DD -ED------------II -ED------------B- -ED------------A- -ED------------B- -ED------------A- HHD------------B- HHD-----------AAA -ED-----------AAA -ED-----------AAA -ED------------B- -EG------------A- -FC-----------BB- CB-----------BAA- -AB---------AB--- --ABABABABABA---- 
--BABABABABAB---- -BA---------BA--- CA-----------ABB- -FC------------A- -EG------------B- -ED------------A- -ED------------DD -ED------------II -ED------------B- -ED------------A- -ED------------B- -ED------------A- HHD-----------AAA HHD-----------AAA -ED-----------AAA -ED------------A- -EG------------B- -FC-----------AA- CA-----------ABB- -BA---------BA--- --BABABABABAB---- 
--ABABABABABA---- -AB---------AB--- CB-----------BAA- CCC------------B- -FG------------A- -ED------------B- -ED------------A- -ED------------B- -ED------------I- -ED------------B- -ED------------A- -ED------------B- -ED-----------AAA HHD-----------AAA HHD-----------AAA -ED------------B- -FG------------A- CCC-----------BB- CB-----------BAA- -AB---------AB--- --ABABABABABA---- 
----------------- ----------------- ----------------- CCC-------------- -FG-------------- -ED-------------- -ED-------------- -ED-------------- -ED-------------- -ED-------------- -ED-------------- -ED-------------- -ED-------------- -ED-------------- HHD-------------- -ED-------------- -FG-------------- CCC-------------- ----------------- ----------------- ----------------- 
----------------- ----------------- ----------------- CCC-------------- CCC-------------- -FG-------------- -FG-------------- -FG-------------- -ED-------------- -ED-------------- -CD-------------- -ED-------------- -ED-------------- -FG-------------- -FG-------------- -FG-------------- CCC-------------- CCC-------------- ----------------- ----------------- ----------------- 
----------------- ----------------- ----------------- ----------------- CCC-------------- CCC-------------- CCC-------------- CCC-------------- -FG-------------- -FG-------------- -FG-------------- -FG-------------- -FG-------------- CCC-------------- CCC-------------- CCC-------------- CCC-------------- ----------------- ----------------- ----------------- ----------------- 
----------------- ----------------- ----------------- ----------------- ----------------- ----------------- ----------------- CCC-------------- CCC-------------- CCC-------------- CCC-------------- CCC-------------- CCC-------------- CCC-------------- ----------------- ----------------- ----------------- ----------------- ----------------- ----------------- ----------------- 
