model
size = 25 32 3, scale = 0.05, origin = -y
material 
  colors = A:#FFF B:#A30262 C:#D362A4 D:#FF9A56 E:#D52D00 F:#FFF5F5 G:#EFC405
voxels
409-3(4B21-)3(4C21-)3(4A21-)3(4D21-)2(4E21-)4E442-3(2(4B4-)4B5-)3(2(4C4-)4C5-)3(2(4A4-)4A5-)3(2(4D4-)4D5-)2(2(4E4-)4E5-)2(4E4-)4E25-8(A24-F24-)A4B12-4B4-F4B12-4B4-A4B12-4B4-F4C12-4C4-A4C12-4C4-F4C12-4C4-5A12-4A4-F4A12-4A4-5A12-4A4-F4D12-4D4-A4D12-4D4-F4D12-4D4-A4E12-4E4-F4E12-4E4-A4E12-4E4-G24-
