model
size = 12 14 32, scale = 0.05, origin = -y
material 
  colors = A:#0F0F0F B:#373737 C:#1E1E1E D:#323232 E:#0A0A0A F:#3C3C3C G:#8D1204 H:#141414 I:#282828 J:#BB1313 K:#379D30 L:#124BC6 M:#D7387F N:#D97708
voxels
4-4C8-4C151-2CFD2C6-C4BC7-4A139-C2(FD)C6-H4BH6-6A137-2C2(DF)2C4-H6BH4-A6-A5-6A124-2C6G2C2-H8BH3-A6-A4-8A123-CDG3(DF)C2-H8BH3-A6-A2(4-2A)6-4A112-2C4(FD)2CH10BH-E8-E3-A6-A5-6A111-CFD4J2(FD)CH10BH-E8-E3-A6-A4-A6CA110-CDFJFDJ2(DF)CH10BH-E8-E3-A6-A4-C6IC6-4I100-CFDJDFJ2(FD)CH10BH-E8-E2-E8-E3-C6-C5-6I99-CDF6JDFCH10BHA10-A-E8-E3-A6-A4-H6JH98-C5(FD)CH10BHA10-A-E8-E2-E8-E3-A6-A4-C6IC86-C5(DF)CH10BHA10-A-A8-A2-E8-E3-A6-A4-H6NH86-C5(FD)CH10BHA10-A-A8-A2-E8-E3-2(A6-A4-)C6IC74-2C4(FD)2CH10BH-2(A8-A2-)E8-E3-2(A6-A4-)H6KH75-C3(DF)NFC2-H8BH2(2-A8-A)2(2-E8-E)3-2(A6-A4-)C6IC63-C3(FD)NDC2-H8BH3(2-A8-A)2-E8-E3-2(A6-A4-)H6LH63-CD6NFC2-H8BH3(2-A8-A)2-E8-E3-3(A6-A4-)C6IC51-C4(FD)C2-H8BH3(2-A8-A)2(2-E8-E)3-3(A6-A4-)H6MH39-C2(D2KF)C2-HB6JBH4(2-A8-A)2(2-E8-E)3-3(A6-A4-)C6IC27-CFDF2KDFDC2-HB6JBH5(2-A8-A)4(2-E8-E)3-2C4I2C5-C4IC6-C4IC3-2CDFD2KFDF2CH2BJ2B2J3BHMA8-A2MA8-AM-6(A8-A2-)E8-E2-E8-E16-6G3-C2(DF2K)DFCH2BJ2B2J3BH2A4(8-4A)8-2A-3(A8-A2-)E8-E2-E8-E25-C5(FD)CH2BJ2B2J3BHL5(A8-A2L)A8-AL-2(A8-A2-)E8-E37-CDF6LDFCH2B5J3BH2A5(8-4A)8-2A-A8-A2(2-E8-E)37-C5(FD)CH5B2J3BHK4(A8-A2K)A8-AK-2(A8-A2-)E8-E49-CDF4M2(DF)CH2B2GB2J3BH2A2(8-4A)8-2A-4(A8-A2-)E8-E49-CFDMDFM2(FD)CH2BGB4J2BHNA8-AN-5(A8-A2-)E8-E2-E8-E49-2CFMFDMDFD2CH2BG7BH-6(A8-A2-)E8-E62-2C6M2C2-HBG6BH6(2-2A6-2A)2-2E6-2E63-2C2(FD)2C4-H6BH4-A6G2(A4-6AG)A4-E5AG3(E4-E6G)E6-4G55-6C6-H4CH3(6-AE2GEA)6-2E2G2E7-3(4G8-)4G52-
