model
size = 12 14 32, scale = 0.05, origin = -y
material 
  colors = A:#FFF B:#004DFF C:#E6E6E6 D:#1E1E1E E:#323232 F:#3C3C3C G:#750787 H:#8D1204 I:#008026 J:#FAFAFA K:#BB1313 L:#FFED00 M:#E40303 N:#FF8C00 O:#C8C8C8 P:#D7387F Q:#379D30 R:#D97708 S:#124BC6 T:#141414
voxels
4-4D8-4D151-2DFE2D6-D4AD7-4M139-D2(FE)D6-C4AC6-6M137-2D2(EF)2D4-C6AC4-M6-M5-6M124-2D6H2D2-C8AC3-M6-M4-8M123-DEH3(EF)D2-C8AC3-M6-M2(4-2M)6-4N112-2D4(FE)2DC10AC-M8-M3-M6-M5-6N111-DFE4K2(FE)DC10AC-N8-N3-N6-N4-N6ON110-DEFKFEK2(EF)DC10AC-N8-N3-N6-N4-O6JO6-4J100-DFEKEFK2(FE)DC10AC-N8-N2-N8-N3-O6-O5-6J99-DEF6KEFDC10ACN10-N-N8-N3-L6-L4-T6KT98-D5(FE)DC10ACN10-N-L8-L2-L8-L3-L6-L4-O6JO86-D5(EF)DC10ACL10-L-L8-L2-L8-L3-L6-L4-T6RT86-D5(FE)DC10ACL10-L-L8-L2-L8-L3-2(L6-L4-)O6JO74-2D4(FE)2DC10AC-2(L8-L2-)L8-L3-2(L6-L4-)T6QT75-D3(EF)RFD2-C8AC4(2-L8-L)3-2(I6-I4-)O6JO63-D3(FE)RED2-C8AC2(2-L8-L)2(2-I8-I)3-2(I6-I4-)T6ST63-DE6RFD2-C8AC4(2-I8-I)3-3(I6-I4-)O6JO51-D4(FE)D2-C8AC5(2-I8-I)3-3(I6-I4-)T6PT39-D2(E2QF)D2-CA6KAC6(2-I8-I)3-I6-I2(4-B6-B)4-O6JO27-DFEF2QEFED2-CA6KAC4(2-I8-I)5(2-B8-B)3-2O4J2O5-O4JO6-O4JO3-2DEFE2QFEF2DC2AK2A2K3AC2I8-4I8-2I-7(B8-B2-)B8-B16-6H3-D2(EF2Q)EFDC2AK2A2K3AC2B4(8-4B)8-2B-4(B8-B2-)B8-B25-D5(FE)DC2AK2A2K3AC2B5(8-4B)8-2B-2(B8-B2-)B8-B37-DEF6SEFDC2A5K3AC2B5(8-4B)8-2B-B8-B2(2-G8-G)37-D5(FE)DC5A2K3AC2B3(8-4B)8-2B2G8-2G-2(G8-G2-)G8-G49-DEF4P2(EF)DC2A2HA2K3AC2B8-4B8-2B2G8-2G-4(G8-G2-)G8-G49-DFEPEFP2(FE)DC2AHA4K2AC2G8-2G-6(G8-G2-)G8-G49-2DFPFEPEFE2DC2AH7AC-6(G8-G2-)G8-G62-2D6P2D2-CAH6AC7(2-GC6-CG)63-2D2(FE)2D4-C6AC4-G6H2(G4-G5CH)G4-6CH3(C4-C6H)C6-4H55-6D6-C4DC6-2C2H2C2(6-GC2HCG)6-2C2H2C7-3(4H8-)4H52-
