model
size = 12 14 32, scale = 0.05, origin = -y
material 
  colors = A:#FFF B:#004DFF C:#E6E6E6 D:#1E1E1E E:#323232 F:#3C3C3C G:#750787 H:#008026 I:#8D1204 J:#FAFAFA K:#BB1313 L:#FFED00 M:#E40303 N:#FF8C00 O:#C8C8C8 P:#D7387F Q:#379D30 R:#D97708 S:#124BC6 T:#141414
voxels
4-4D8-4D151-2DFE2D6-D4AD7-4M139-D2(FE)D6-C4AC6-6M137-2D2(EF)2D4-C6AC4-M6-M5-6M124-2D6P2D2-C8AC3-M6-M4-8M123-DEFEPEFPFD2-C8AC3-M6-M2(4-2M)6-4N112-2DFEFPFEPE2DC10AC-M8-M3-M6-M5-6N111-D2(FE)4PFEDC10AC-N8-N3-N6-N4-N6ON110-D5(EF)DC10AC-N8-N3-N6-N4-O6JO6-4J100-DFE6SFEDC10AC-N8-N2-N8-N3-O6-O5-6J99-D5(EF)DC10ACN10-N-N8-N3-L6-L4-T6KT98-D2(FE2Q)FEDC10ACN10-N-L8-L2-L8-L3-L6-L4-O6JO86-D2(EF)2Q2(EF)DC10ACL10-L-L8-L2-L8-L3-L6-L4-T6RT86-D2(FE)2Q2(FE)DC10ACL10-L-L8-L2-L8-L3-2(L6-L4-)O6JO74-2D2(F2QE)2DC10AC-2(L8-L2-)L8-L3-2(L6-L4-)T6QT75-D4(EF)D2-C8AC4(2-L8-L)3-2(H6-H4-)O6JO63-DF6RED2-C8AC2(2-L8-L)2(2-H8-H)3-2(H6-H4-)T6ST63-DER3(EF)D2-C8AC4(2-H8-H)3-3(H6-H4-)O6JO51-DFR3(FE)D2-C8AC5(2-H8-H)3-3(H6-H4-)T6PT39-D4(EF)D2-CA6KAC6(2-H8-H)3-H6-H2(4-B6-B)4-O6JO27-D4(FE)D2-CA6KAC4(2-H8-H)5(2-B8-B)3-2O4J2O5-O4JO6-O4JO3-2D4(EF)2DC2AK2A2K3AC2H8-4H8-2H-7(B8-B2-)B8-B16-6I3-D5(EF)DC2AK2A2K3AC2B4(8-4B)8-2B-4(B8-B2-)B8-B25-DFE6KFEDC2AK2A2K3AC2B5(8-4B)8-2B-2(B8-B2-)B8-B37-D2(EF)KFEKEFDC2A5K3AC2B5(8-4B)8-2B-B8-B2(2-G8-G)37-D2(FE)KEFKFEDC5A2K3AC2B3(8-4B)8-2B2G8-2G-2(G8-G2-)G8-G49-D2(EF)4KEFDC2A2IA2K3AC2B8-4B8-2B2G8-2G-4(G8-G2-)G8-G49-D5(FE)DC2AIA4K2AC2G8-2G-6(G8-G2-)G8-G49-2D3(FE)IE2DC2AI7AC-6(G8-G2-)G8-G62-2D6I2D2-CAI6AC7(2-GC6-CG)63-2D2(FE)2D4-C6AC3(4-GI5CG)4-CI6C3(4-C6IC)6-4I55-6D6-C4DC6-2C2I2C2(6-GC2ICG)6-2C2I2C7-3(4I8-)4I52-
