model
size = 31 26 31, scale = 0.05, origin = -y
material 
  colors = A:#F00 B:#0F6 C:#F09 D:#FF0 E:#0FF F:#30F G:#93F
voxels
------------------------------- ------------------------------- ------------------------------- ------------------------------- ------------------------------- ------------------------------- ------------------------------- ------------------------------- ------------------------------- ------------------------------- ------------------------------- ------------------------------- ------------------------------- ---------------C--------------- --------------C-C-------------- -------------CCCCC------------- --------------CCC-------------- ------------------------------- ------------------------------- ------------------------------- ------------------------------- ------------------------------- ------------------------------- ------------------------------- ------------------------------- ------------------------------- 
------------------------------- ------------------------------- ------------------------------- ------------------------------- ------------------------------- ------------------------------- ------------------------------- ------------------------------- ------------------------------- ------------------------------- ------------------------------- ------------------------------- --------------BBB-------------- ---------C---BBDBB---C--------- ----------C-BBD-DBB-C---------- ---------CC-BDDDDDB-CC--------- ---------C--BBBBBBB--C--------- ------------------------------- ------------GGGGGGG------------ ------------------------------- ------------------------------- ------------------------------- ------------------------------- ------------------------------- ------------------------------- ------------------------------- 
------------------------------- ------------------------------- ------------------------------- ------------------------------- ------------------------------- ------------------------------- ------------------------------- ------------------------------- ------------------------------- ------------------------------- ------------------------------- ------------------------------- ---------BB---------BB--------- ---------BB---------BB--------- --------C-DB-------BD-C-------- --------CDDB-------BDDC-------- ---------BBB-------BBB--------- ------------AAAAAAA------------ ---------E-GAAAAAAAG-E--------- ------------G-GGG-G------------ ------------------------------- ------------------------------- ------------------------------- ------------------------------- ------------------------------- ------------------------------- 
------------------------------- ------------------------------- ------------------------------- ------------------------------- ------------------------------- ------------------------------- ------------------------------- ------------------------------- ------------------------------- ------------------------------- ------------------------------- ------------------------------- --------B-------------B-------- --------B-------------B-------- -------BD-------------DB------- ------CBD-------------DBC------ -------BB-------------BB------- ---------AAA-------AAA--------- --------EAAA-------AAAE-------- ---------E-GAAAAAAAG-E--------- ------------AAAAAAA------------ ------------FFFFFFF------------ -------------F---F------------- ------------------------------- ------------------------------- ------------------------------- 
------------------------------- ------------------------------- ------------------------------- ------------------------------- ------------------------------- ------------------------------- ------------------------------- ------------------------------- ------------------------------- ------------------------------- ------------------------------- ------------------------------- ------------------------------- ------B-----------------B------ -----CB-----------------BC----- -----CD-----------------DC----- ------BA---------------AB------ --------A-------------A-------- -------EAA-----------AAE------- ---------EAA-------AAE--------- --------EEAA-------AAEE-------- -----------FAAAAAAAF----------- -----------FAAAAAAAF----------- ------------FFF-FFF------------ ------------------------------- ------------------------------- 
------------------------------- ------------------------------- ------------------------------- ------------------------------- ------------------------------- ------------------------------- ------------------------------- ------------------------------- ------------------------------- ------------------------------- ------------------------------- ------------------------------- ------------------------------- -----B-------------------B----- ----CD-------------------DC---- ----CD-------------------DC---- -----B-------------------B----- ------AA---------------AA------ -----EAA---------------AAE----- -------EAA-----------AAE------- -------EAA-----------AAE------- ----------AA-------AA---------- --------EEAAAAAAAAAAAEE-------- ------------FF---FF------------ ------------------------------- ------------------------------- 
------------------------------- ------------------------------- ------------------------------- ------------------------------- ------------------------------- ------------------------------- ------------------------------- ------------------------------- ------------------------------- ------------------------------- ------------------------------- ------------------------------- ------------------------------- ----B---------------------B---- ----B---------------------B---- ---CD---------------------DC--- ----B---------------------B---- -----A-------------------A----- ----EAA-----------------AAE---- -----E-A---------------A-E----- -------A---------------A------- --------AA-----------AA-------- -------EAAAA-------AAAAE------- -----------FAAAAAAAF----------- ------------FF---FF------------ ------------------------------- 
------------------------------- ---B-----------------------B--- ---B-----------------------B--- ---B-----------------------B--- ---B-----------------------B--- ---B-----------------------B--- ---B-----------------------B--- ------------------------------- ---B-----------------------B--- ---B-----------------------B--- ---B-----------------------B--- ---B-----------------------B--- ---B-----------------------B--- ---B-----------------------B--- ---B-----------------------B--- ---B-----------------------B--- ---BA---------------------AB--- -----A-------------------A----- ----EA-------------------AE---- ------A-----------------A------ -----EA-----------------AE----- -------A---------------A------- ------EAAA-----------AAAE------ --------EEAAAAAAAAAAAEE-------- -----------F-F-F-F-F----------- ------------------------------- 
---B-----------------------B--- --CD-----------------------DC-- --CD-----------------------DC-- --CD-----------------------DC-- --CD-----------------------DC-- --CD-----------------------DC-- --CD-----------------------DC-- ---B-----------------------B--- --CD-----------------------DC-- --CD-----------------------DC-- --CD-----------------------DC-- --CD-----------------------DC-- --CD-----------------------DC-- --CD-----------------------DC-- --CD-----------------------DC-- --CD-----------------------DC-- ---B-----------------------B--- ----A---------------------A---- ---EA---------------------AE--- ----EA-------------------AE---- ----EA-------------------AE---- ------A-----------------A------ -----EAAA-------------AAAE----- -------EEAAAAAAAAAAAAAEE------- ---------E-FFFFFFFFF-E--------- ------------------------------- 
--B-------------------------B-- -CD-------------------------DC- ------------------------------- ------------------------------- ------------------------------- ------------------------------- -CD-------------------------DC- --B-------------------------B-- -CD-------------------------DC- ------------------------------- ------------------------------- ------------------------------- ------------------------------- ------------------------------- ------------------------------- -CD-------------------------DC- --B-------------------------B-- ---A-----------------------A--- ---AA---------------------AA--- -----A-------------------A----- -----A-------------------A----- ------A-----------------A------ ------AA---------------AA------ -------EAAAAAAAAAAAAAAAE------- ---------E--FF---FF--E--------- ------------------------------- 
--B-------------------------B-- -CD-------------------------DC- -CD-------------------------DC- -CD-------------------------DC- -CD-------------------------DC- -CD-------------------------DC- -CD-------------------------DC- --B-------------------------B-- -CD-------------------------DC- -CD-------------------------DC- -CD-------------------------DC- -CD-------------------------DC- -CD-------------------------DC- -CD-------------------------DC- -CD-------------------------DC- -CD-------------------------DC- --B-------------------------B-- ---A-----------------------A--- --EA-----------------------AE-- ---EA---------------------AE--- ---EA---------------------AE--- -----A-------------------A----- ----EAA-----------------AAE---- -----E-AAAAAAAAAAAAAAAAA-E----- -------EE--FFF-F-FFF--EE------- ------------------------------- 
------------------------------- --B-------------------------B-- --B-------------------------B-- --B-------------------------B-- --B-------------------------B-- --B-------------------------B-- --B-------------------------B-- ------------------------------- --B-------------------------B-- --B-------------------------B-- --B-------------------------B-- --B-------------------------B-- --B-------------------------B-- --B-------------------------B-- --B-------------------------B-- --B-------------------------B-- --B-------------------------B-- ---A-----------------------A--- --EA-----------------------AE-- ----A---------------------A---- ---EA---------------------AE--- -----A-------------------A----- ----EAA-----------------AAE---- -----E-AAAAAA-----AAAAAA-E----- -------EE-FF-AAAAA-FF-EE------- -------------FFFFF------------- 
------------------------------- ------------------------------- ------------------------------- ------------------------------- ------------------------------- ------------------------------- ------------------------------- ------------------------------- ------------------------------- ------------------------------- ------------------------------- ------------------------------- ------------------------------- ------------------------------- -B---------------------------B- -B---------------------------B- -B---------------------------B- --A-------------------------A-- -EA-------------------------AE- --EA-----------------------AE-- --EA-----------------------AE-- ----A---------------------A---- ---EAA-------------------AAE--- ----EEAAAAAA-------AAAAAAEE---- -------E--FFAAAAAAAFF--E------- ------------F-----F------------ 
------------------------------- ------------------------------- ------------------------------- ------------------------------- ------------------------------- ------------------------------- ------------------------------- ------------------------------- ------------------------------- ------------------------------- ------------------------------- ------------------------------- -B---------------------------B- -B---------------------------B- -B---------------------------B- CD---------------------------DC -B---------------------------B- --A-------------------------A-- --A-------------------------A-- ---A-----------------------A--- ---A-----------------------A--- ----A---------------------A---- ----AA-------------------AA---- ------AAAAA---------AAAAA------ -------E-F-AAAAAAAAA-F-E------- -----------F-FFFFF-F----------- 
------------------------------- ------------------------------- ------------------------------- ------------------------------- ------------------------------- ------------------------------- ------------------------------- ------------------------------- ------------------------------- ------------------------------- ------------------------------- ------------------------------- -B---------------------------B- CD---------------------------DC CD---------------------------DC CD---------------------------DC -B---------------------------B- --A-------------------------A-- -EA-------------------------AE- --EA-----------------------AE-- --EA-----------------------AE-- ----A---------------------A---- ---EAA-------------------AAE--- ----EEAAAAA---------AAAAAEE---- -------E-FFAAAAAAAAAFF-E------- -----------F-F---F-F----------- 
------------------------------- ------------------------------- ------------------------------- ------------------------------- ------------------------------- ------------------------------- ------------------------------- ------------------------------- ------------------------------- ------------------------------- ------------------------------- ------------------------------- -B---------------------------B- CD---------------------------DC ------------------------------- CD---------------------------DC CB---------------------------BC --A-------------------------A-- -EA-------------------------AE- ---A-----------------------A--- --EA-----------------------AE-- ----A---------------------A---- ---EAA-------------------AAE--- -----EAAAAA---------AAAAAE----- -------E---AAAAAAAAA---E------- -----------F-F-F-F-F----------- 
------------------------------- ------------------------------- ------------------------------- ------------------------------- ------------------------------- ------------------------------- ------------------------------- ------------------------------- ------------------------------- ------------------------------- ------------------------------- ------------------------------- -B---------------------------B- CD---------------------------DC CD---------------------------DC CD---------------------------DC -B---------------------------B- --A-------------------------A-- -EA-------------------------AE- --EA-----------------------AE-- --EA-----------------------AE-- ----A---------------------A---- ---EAA-------------------AAE--- ----EEAAAAA---------AAAAAEE---- -------E-FFAAAAAAAAAFF-E------- -----------F-F---F-F----------- 
------------------------------- ------------------------------- ------------------------------- ------------------------------- ------------------------------- ------------------------------- ------------------------------- ------------------------------- ------------------------------- ------------------------------- ------------------------------- ------------------------------- -B---------------------------B- -B---------------------------B- -B---------------------------B- CD---------------------------DC -B---------------------------B- --A-------------------------A-- --A-------------------------A-- ---A-----------------------A--- ---A-----------------------A--- ----A---------------------A---- ----AA-------------------AA---- ------AAAAA---------AAAAA------ -------E-F-AAAAAAAAA-F-E------- -----------F-FFFFF-F----------- 
------------------------------- ------------------------------- ------------------------------- ------------------------------- ------------------------------- ------------------------------- ------------------------------- ------------------------------- ------------------------------- ------------------------------- ------------------------------- ------------------------------- ------------------------------- ------------------------------- -B---------------------------B- -B---------------------------B- -B---------------------------B- --A-------------------------A-- -EA-------------------------AE- --EA-----------------------AE-- --EA-----------------------AE-- ----A---------------------A---- ---EAA-------------------AAE--- ----EEAAAAAA-------AAAAAAEE---- -------E--FFAAAAAAAFF--E------- ------------F-----F------------ 
------------------------------- ------------------------------- ------------------------------- --B-------------------------B-- --B-------------------------B-- --B-------------------------B-- --B-------------------------B-- --B-------------------------B-- --B-------------------------B-- ------------------------------- --B-------------------------B-- --B-------------------------B-- --B-------------------------B-- --B-------------------------B-- --B-------------------------B-- --B-------------------------B-- --B-------------------------B-- ---A-----------------------A--- --EA-----------------------AE-- ----A---------------------A---- ---EA---------------------AE--- -----A-------------------A----- ----EAA-----------------AAE---- -----E-AAAAAA-----AAAAAA-E----- -------EE-FF-AAAAA-FF-EE------- -------------FFFFF------------- 
------------------------------- ------------------------------- --B-------------------------B-- -CD-------------------------DC- -CD-------------------------DC- -CD-------------------------DC- -CD-------------------------DC- -CD-------------------------DC- -CD-------------------------DC- --B-------------------------B-- -CD-------------------------DC- -CD-------------------------DC- -CD-------------------------DC- -CD-------------------------DC- -CD-------------------------DC- -CD-------------------------DC- --B-------------------------B-- ---A-----------------------A--- --EA-----------------------AE-- ---EA---------------------AE--- ---EA---------------------AE--- -----A-------------------A----- ----EAA-----------------AAE---- -----E-AAAAAAAAAAAAAAAAA-E----- -------EE--FFF-F-FFF--EE------- ------------------------------- 
------------------------------- ------------------------------- --B-------------------------B-- -CD-------------------------DC- ------------------------------- ------------------------------- ------------------------------- ------------------------------- -CD-------------------------DC- --B-------------------------B-- -CD-------------------------DC- ------------------------------- ------------------------------- ------------------------------- ------------------------------- -CD-------------------------DC- --B-------------------------B-- ---A-----------------------A--- ---AA---------------------AA--- -----A-------------------A----- -----A-------------------A----- ------A-----------------A------ ------AA---------------AA------ -------EAAAAAAAAAAAAAAAE------- ---------E--FF---FF--E--------- ------------------------------- 
------------------------------- ------------------------------- ---B-----------------------B--- --CD-----------------------DC-- --CD-----------------------DC-- --CD-----------------------DC-- --CD-----------------------DC-- --CD-----------------------DC-- --CD-----------------------DC-- ---B-----------------------B--- --CD-----------------------DC-- --CD-----------------------DC-- --CD-----------------------DC-- --CD-----------------------DC-- --CD-----------------------DC-- --CD-----------------------DC-- ---B-----------------------B--- ----A---------------------A---- ---EA---------------------AE--- ----EA-------------------AE---- -----A-------------------A----- -----EA-----------------AE----- -----EAAA-------------AAAE----- -------EEAAAAAAAAAAAAAEE------- ---------E-FFFFFFFFF-E--------- ------------------------------- 
------------------------------- ------------------------------- ------------------------------- ---B-----------------------B--- ---B-----------------------B--- ---B-----------------------B--- ---B-----------------------B--- ---B-----------------------B--- ---B-----------------------B--- ------------------------------- ---B-----------------------B--- ---B-----------------------B--- ---B-----------------------B--- ---B-----------------------B--- ---B-----------------------B--- ---B-----------------------B--- ---BA---------------------AB--- -----A-------------------A----- ----EA-------------------AE---- -----EA-----------------AE----- ------A-----------------A------ ------EA---------------AE------ ------EAAA-----------AAAE------ --------EEAAAAAAAAAAAEE-------- -----------F-F-F-F-F----------- ------------------------------- 
------------------------------- ------------------------------- ------------------------------- ----B---------------------B---- ---CB---------------------BC--- ---CB---------------------BC--- ---CD---------------------DC--- ------------------------------- ------------------------------- ------------------------------- ------------------------------- ------------------------------- ------------------------------- ---CD---------------------DC--- ---CB---------------------BC--- ---CB---------------------BC--- ----B---------------------B---- -----A-------------------A----- ----EAA-----------------AAE---- ------EA---------------AE------ -------A---------------A------- --------AA-----------AA-------- --------AAAA-------AAAA-------- -----------FAAAAAAAF----------- ------------FF---FF------------ ------------------------------- 
------------------------------- ------------------------------- ------------------------------- ------------------------------- ------------------------------- -----B-------------------B----- ----CB-------------------BC---- ----CB-------------------BC---- ----CB-------------------BC---- ----CB-------------------BC---- ----CB-------------------BC---- ----CB-------------------BC---- ----CB-------------------BC---- ----CB-------------------BC---- -----B-------------------B----- -----B-------------------B----- -----B-------------------B----- ------AA---------------AA------ -----EAA---------------AAE----- ------E-AA-----------AA-E------ --------AA-----------AA-------- --------EEAA-------AAEE-------- --------EEAAAAAAAAAAAEE-------- ------------FF---FF------------ ------------------------------- ------------------------------- 
------------------------------- ------------------------------- ------------------------------- ------------------------------- ------------------------------- ------B-----------------B------ ------B-----------------B------ ------B-----------------B------ ------B-----------------B------ ------B-----------------B------ ------B-----------------B------ ------B-----------------B------ ------B-----------------B------ ------B-----------------B------ ------B-----------------B------ ------B-----------------B------ ------BA---------------AB------ --------A-------------A-------- ------E-AA-----------AA-E------ --------EEAA-------AAEE-------- ----------AA-------AA---------- ------------AAAAAAA------------ -----------FAAAAAAAF----------- ------------FFF-FFF------------ ------------------------------- ------------------------------- 
------------------------------- ------------------------------- ------------------------------- ------------------------------- ------------------------------- ------------------------------- ------------------------------- -------BB-------------BB------- ------CBD-------------DBC------ -------BB-------------BB------- ------CDD-------------DDC------ ------C-D-------------D-C------ ------C-D-------------D-C------ ------CDD-------------DDC------ -------BB-------------BB------- ------CBD-------------DBC------ -------BBA------------BB------- ---------AAA-------AAA--------- --------EAAA-------AAAE-------- ---------E-GAAAAAAAG-E--------- -----------GAAAAAAAG----------- ------------------------------- ------------FFFFFFF------------ ------------------------------- ------------------------------- ------------------------------- 
------------------------------- ------------------------------- ------------------------------- ------------------------------- ------------------------------- ------------------------------- ---------BBB-------BBB--------- ---------BDD-------DDB--------- --------CBD---------DBC-------- ---------BDD-------DDB--------- -------CCBDB-------BDBCC------- --------CBBB-------BBBC-------- --------CBDD-------DDBC-------- -------CCBD---------DBCC------- ---------BDD-------DDB--------- --------CBDB-------BDBC-------- ---------BBB-------BBB--------- ------------AAAAAAA------------ ---------E-GAAAAAAAG-E--------- ------------G-G-G-G------------ ------------G-GGG-G------------ ------------------------------- ------------------------------- ------------------------------- ------------------------------- ------------------------------- 
------------------------------- ------------------------------- ------------------------------- ------------------------------- --------------BBB-------------- ------------BBBDBBB------------ ------------BBDDDBB------------ ----------CCDBD-DBDCC---------- ----------C-DBD-DBD-C---------- ----------CCDBD-DBDCC---------- ----------C-BBD-DBB-C---------- ------------BBDDDBB------------ ----------CCDBBBBBDCC---------- ----------C-DBDDDBD-C---------- ----------CCDBD-DBDCC---------- ----------C-BBDDDBB-C---------- ------------BBBBBBB------------ ------------------------------- ------------G-GGG-G------------ ------------------------------- ------------------------------- ------------------------------- ------------------------------- ------------------------------- ------------------------------- ------------------------------- 
------------------------------- ------------------------------- ------------------------------- ------------------------------- ------------------------------- ---------------C--------------- ------------C-CCC-C------------ ------------C-C-C-C------------ ------------C-C-C-C------------ ------------C-C-C-C------------ --------------C-C-------------- --------------CCC-------------- ------------C-----C------------ ------------C-CCC-C------------ ------------C-C-C-C------------ --------------CCC-------------- ---------------C--------------- ------------------------------- ------------------------------- ------------------------------- ------------------------------- ------------------------------- ------------------------------- ------------------------------- ------------------------------- ------------------------------- 
