model
size = 31 26 30, scale = 0.05, origin = -y
material 
  colors = A:#0089A7 B:#E83015 C:#000 D:#D0104C E:#FFB11B F:#00896C G:#0C4842
voxels
------------------------------- ------------------------------- ------------------------------- ------------------------------- ------------------------------- ------------------------------- ------------------------------- ------------------------------- ------------------------------- ------------------------------- ------------------------------- ------------------------------- ------------------------------- ------------CEEEEEC------------ ------------EECCCEE------------ ------------ECFFFCE------------ ------------ECFFFCE------------ ------------------------------- ------------------------------- ------------------------------- ------------------------------- ------------------------------- ------------------------------- ------------------------------- ------------------------------- ------------------------------- 
------------------------------- ------------------------------- ------------------------------- ------------------------------- ------------------------------- ------------------------------- ------------------------------- ------------------------------- ------------------------------- ---------------C--------------- --------------CAC-------------- -------------CAAAC------------- -------------CAAAC------------- ------------CBBBBBC------------ -----------CBBBBBBBC----------- -----------CBBBBBBBC----------- -----------CBBBBBBBC----------- ------------DCDCDCD------------ ------------CCEEECC------------ ------------CECCCEC------------ ------------ECFFFCE------------ ------------------------------- ------------------------------- ------------------------------- ------------------------------- ------------------------------- 
------------------------------- ------------------------------- ------------------------------- ------------------------------- ------------------------------- ------------------------------- ------------------------------- ------------------------------- ------------------------------- -------------C---C------------- ------------CG---GC------------ -----------CGG---GGC----------- ----------CGGG---GGGC---------- ---------CCC-------CCC--------- ---------BBB-------BBB--------- ---------BBB-------BBB--------- ---------CCC-------CCC--------- -----------CAAAAAAAC----------- ---------C--AAAAAAA--C--------- ------------BBBBBBB------------ -----------CBBBBBBBC----------- ------------ECFFFCE------------ ------------ECFFFCE------------ ------------------------------- ------------------------------- ------------------------------- 
------------------------------- ------------------------------- ------------------------------- ------------------------------- ------------------------------- ------------------------------- ------------------------------- ------------------------------- ------------------------------- ------------------------------- ------------------------------- ------------------------------- ------------------------------- -------CC-------------CC------- -------BB-------------BB------- -------BB-------------BB------- -------CC-------------CC------- ---------AAA-------AAA--------- --------CAAA-------AAAC-------- ---------C-BAAAAAAAB-C--------- -----------BAAAAAAAB----------- -----------CBBBBBBBC----------- -----------CBBBBBBBC----------- ------------CECCCEC------------ ------------------------------- ------------------------------- 
------------------------------- ------------------------------- ------------------------------- ------------------------------- ------------------------------- ------------------------------- ------------------------------- ------------------------------- ------------------------------- ------------------------------- ------------------------------- ------------------------------- ------------------------------- ------C-----------------C------ ------B-----------------B------ ------B-----------------B------ ------CC---------------CC------ --------A-------------A-------- ------CCAA-----------AACC------ --------BCAA-------AACB-------- --------C-AA-------AA-C-------- ----------CBAAAAAAABC---------- ----------CBAAAAAAABC---------- ------------BBBBBBB------------ -------------CEEEC------------- ------------------------------- 
------------------------------- ------------------------------- ------------------------------- ------------------------------- ------------------------------- ------------------------------- ------------------------------- ------------------------------- ------------------------------- ------------------------------- ------------------------------- ------------------------------- ------------------------------- -----C-------------------C----- -----B-------------------B----- -----B-------------------B----- -----C-------------------C----- ------AA---------------AA------ -----CAA---------------AAC----- ------BBAA-----------AABB------ -------BAA-----------AAB------- --------C-AA-------AA-C-------- --------C-AAAAAAAAAAA-C-------- ----------CBBBBBBBBBC---------- --------------CCC-------------- ------------------------------- 
------------------------------- ------------------------------- ------------------------------- ------------------------------- ------------------------------- ------------------------------- ------------------------------- ------------------------------- ------------------------------- ------------------------------- ------------------------------- ------------------------------- ------------------------------- ----C---------------------C---- ----B---------------------B---- ----B---------------------B---- ----C---------------------C---- -----A-------------------A----- ----CAA-----------------AAC---- -----BBA---------------ABB----- ------BA---------------AB------ -------BAA-----------AAB------- -------BAAAA-------AAAAB------- --------C-CBAAAAAAABC-C-------- -----------BBBBBBBBB----------- ------------------------------- 
------------------------------- ------------------------------- ------------------------------- -DD-------------------------DD- -DD-------------------------DD- -DD-------------------------DD- ------------------------------- ------------------------------- ------------------------------- ------------------------------- ------------------------------- ------------------------------- ------------------------------- ---C-----------------------C--- ---B-----------------------B--- ---B-----------------------B--- ---CC---------------------CC--- -----A-------------------A----- ----CA-------------------AC---- -----BA-----------------AB----- -----BA-----------------AB----- ------BA---------------AB------ ------BAAA-----------AAAB------ -------CC-AAAAAAAAAAA-CC------- ----------CBBBBBBBBBC---------- ------------------------------- 
------------------------------- ------------------------------- ------------------------------- -DD-------------------------DD- -DD-------------------------DD- -DD-------------------------DD- ------------------------------- ------------------------------- ------------------------------- ------------------------------- ------------------------------- ------------------------------- ------------------------------- ---C-----------------------C--- ---B-----------------------B--- ---B-----------------------B--- ---C-----------------------C--- ----A---------------------A---- ---CA---------------------AC--- ----BA-------------------AB---- ----BA-------------------AB---- -----BA-----------------AB----- -----BAAA-------------AAAB----- ------BC-AAAAAAAAAAAAA-CB------ ----------CBBBBBBBBBC---------- ------------------------------- 
------------------------------- --C-------------------------C-- --C-------------------------C-- -DD-------------------------DD- -DD-------------------------DD- -DD-------------------------DD- --C-------------------------C-- --C-------------------------C-- --C-------------------------C-- --C-------------------------C-- --C-------------------------C-- --C-------------------------C-- --C-------------------------C-- --C-------------------------C-- --B-------------------------B-- --B-------------------------B-- --C-------------------------C-- ---A-----------------------A--- --CAA---------------------AAC-- ---BBA-------------------ABB--- ----BA-------------------AB---- -----BA-----------------AB----- -----BAA---------------AAB----- ------BCAAAAAAAAAAAAAAACB------ ---------CBBBBBBBBBBBC--------- ------------------------------- 
--C-------------------------C-- --B-------------------------B-- --CC-----------------------CC-- -DDC-----------------------CDD- -DDC-----------------------CDD- -DDC-----------------------CDD- --CC-----------------------CC-- --B-------------------------B-- --B-------------------------B-- --B-------------------------B-- --B-------------------------B-- --B-------------------------B-- --B-------------------------B-- --B-------------------------B-- --B-------------------------B-- --B-------------------------B-- --C-------------------------C-- ---A-----------------------A--- --CA-----------------------AC-- ---BA---------------------AB--- ---BA---------------------AB--- ----BA-------------------AB---- ----BAA-----------------AAB---- -----BBAAAAAAAAAAAAAAAAABB----- -------C-CBBBBBBBBBBBC-C------- ------------------------------- 
--C-------------------------C-- --B-------------------------B-- CCCC-----------------------CCCC CDDC-----------------------CDDC CDDC-----------------------CDDC CDDC-----------------------CDDC CCCC-----------------------CCCC --B-------------------------B-- --B-------------------------B-- --B-------------------------B-- --B-------------------------B-- --B-------------------------B-- --B-------------------------B-- --B-------------------------B-- --B-------------------------B-- --B-------------------------B-- --C-------------------------C-- ---A-----------------------A--- --CA-----------------------AC-- ---BA---------------------AB--- ---BA---------------------AB--- ----BA-------------------AB---- ----BAA-----------------AAB---- -----BBAAAAAA-----AAAAAABB----- -------C-CBBBAAAAABBBC-C------- -------------CCCCC------------- 
-C---------------------------C- -B---------------------------B- CC---------------------------CC CDD-------------------------DDC CDD-------------------------DDC CDD-------------------------DDC CC---------------------------CC -B---------------------------B- -B---------------------------B- -B---------------------------B- -B---------------------------B- -B---------------------------B- -B---------------------------B- -B---------------------------B- -B---------------------------B- -B---------------------------B- -C---------------------------C- --A-------------------------A-- -CA-------------------------AC- --BA-----------------------AB-- --BA-----------------------AB-- ---BA---------------------AB--- ---BAA-------------------AAB--- ----BBAAAAAA-------AAAAAABB---- ------BC-CBBAAAAAAABBC-CB------ ------------CEEEEEC------------ 
------------------------------- -C---------------------------C- -C---------------------------C- -DD-------------------------DD- -DD-------------------------DD- -DD-------------------------DD- -C---------------------------C- -C---------------------------C- -C---------------------------C- -C---------------------------C- -B---------------------------B- -B---------------------------B- -B---------------------------B- -B---------------------------B- -B---------------------------B- -B---------------------------B- -C---------------------------C- --A-------------------------A-- -CA-------------------------AC- --BA-----------------------AB-- --BA-----------------------AB-- ---BA---------------------AB--- ---BAA-------------------AAB--- ----BBAAAAA---------AAAAABB---- ------BC-CBAAAAAAAAABC-CB------ -----------CEECCCEEC----------- 
------------------------------- ------------------------------- ------------------------------- -DD-------------------------DD- -DD-------------------------DD- -DD-------------------------DD- ------------------------------- ------------------------------- ------------------------------- ------------------------------- -C---------------------------C- -B---------------------------B- -B---------------------------B- -B---------------------------B- -B---------------------------B- -B---------------------------B- -C---------------------------C- --A-------------------------A-- -CA-------------------------AC- --BA-----------------------AB-- --BA-----------------------AB-- ---BA---------------------AB--- ---BAA-------------------AAB--- ----BBAAAAA---------AAAAABB---- ------BC-CBAAAAAAAAABC-CB------ -----------CECFFFCEC----------- 
------------------------------- ------------------------------- ------------------------------- -DD-------------------------DD- -DD-------------------------DD- -DD-------------------------DD- ------------------------------- ------------------------------- ------------------------------- ------------------------------- -C---------------------------C- -B---------------------------B- -B---------------------------B- -B---------------------------B- -B---------------------------B- -B---------------------------B- -C---------------------------C- --A-------------------------A-- -CA-------------------------AC- --BA-----------------------AB-- --BA-----------------------AB-- ---BA---------------------AB--- ---BAA-------------------AAB--- ----BBAAAAA---------AAAAABB---- ------BC-CBAAAAAAAAABC-CB------ -----------CECFFFCEC----------- 
------------------------------- ------------------------------- ------------------------------- -DD-------------------------DD- -DD-------------------------DD- -DD-------------------------DD- ------------------------------- ------------------------------- ------------------------------- ------------------------------- ------------------------------- -C---------------------------C- -C---------------------------C- -C---------------------------C- -B---------------------------B- -B---------------------------B- -C---------------------------C- --A-------------------------A-- -CA-------------------------AC- --BA-----------------------AB-- --BA-----------------------AB-- ---BA---------------------AB--- ---BAA-------------------AAB--- ----BBAAAAA---------AAAAABB---- ------BC-CBAAAAAAAAABC-CB------ -----------CECFFFCEC----------- 
------------------------------- ------------------------------- ------------------------------- ------------------------------- ------------------------------- ------------------------------- ------------------------------- ------------------------------- ------------------------------- ------------------------------- ------------------------------- ------------------------------- ------------------------------- -C---------------------------C- -B---------------------------B- -B---------------------------B- -C---------------------------C- --A-------------------------A-- -CA-------------------------AC- --BA-----------------------AB-- --BA-----------------------AB-- ---BA---------------------AB--- ---BAA-------------------AAB--- ----BBAAAAA---------AAAAABB---- ------BC-CBAAAAAAAAABC-CB------ -----------CEECCCEEC----------- 
------------------------------- ------------------------------- ------------------------------- ------------------------------- ------------------------------- ------------------------------- ------------------------------- ------------------------------- ------------------------------- ------------------------------- ------------------------------- ------------------------------- ------------------------------- -C---------------------------C- -B---------------------------B- -B---------------------------B- -C---------------------------C- --A-------------------------A-- -CA-------------------------AC- --BA-----------------------AB-- --BA-----------------------AB-- ---BA---------------------AB--- ---BAA-------------------AAB--- ----BBAAAAAA-------AAAAAABB---- ------BC-CBBAAAAAAABBC-CB------ ------------CEEEEEC------------ 
------------------------------- ------------------------------- ------------------------------- ------------------------------- ------------------------------- ------------------------------- ------------------------------- ------------------------------- ------------------------------- ------------------------------- ------------------------------- ------------------------------- ------------------------------- --C-------------------------C-- --B-------------------------B-- --B-------------------------B-- --C-------------------------C-- ---A-----------------------A--- --CA-----------------------AC-- ---BA---------------------AB--- ---BA---------------------AB--- ----BA-------------------AB---- ----BAA-----------------AAB---- -----BBAAAAAA-----AAAAAABB----- -------C-CBBBAAAAABBBC-C------- -------------CCCCC------------- 
------------------------------- ------------------------------- ------------------------------- ------------------------------- ------------------------------- ------------------------------- ------------------------------- ------------------------------- ------------------------------- ------------------------------- ------------------------------- ------------------------------- ------------------------------- --C-------------------------C-- --B-------------------------B-- --B-------------------------B-- --C-------------------------C-- ---A-----------------------A--- --CA-----------------------AC-- ---BA---------------------AB--- ---BA---------------------AB--- ----BA-------------------AB---- ----BAA-----------------AAB---- -----BBAAAAAAAAAAAAAAAAABB----- -------C-CBBBBBBBBBBBC-C------- ------------------------------- 
------------------------------- ------------------------------- ------------------------------- ------------------------------- ------------------------------- ------------------------------- ------------------------------- ------------------------------- ------------------------------- ------------------------------- ------------------------------- ------------------------------- ------------------------------- --C-------------------------C-- --B-------------------------B-- --B-------------------------B-- --C-------------------------C-- ---A-----------------------A--- --CAA---------------------AAC-- ---BBA-------------------ABB--- ----BA-------------------AB---- -----BA-----------------AB----- -----BAA---------------AAB----- ------BCAAAAAAAAAAAAAAACB------ ---------CBBBBBBBBBBBC--------- ------------------------------- 
------------------------------- ------------------------------- ------------------------------- ------------------------------- ------------------------------- ------------------------------- ------------------------------- ------------------------------- ------------------------------- ------------------------------- ------------------------------- ------------------------------- ------------------------------- ---C-----------------------C--- ---B-----------------------B--- ---B-----------------------B--- ---C-----------------------C--- ----A---------------------A---- ---CA---------------------AC--- ----BA-------------------AB---- ----BA-------------------AB---- -----BA-----------------AB----- -----BAAA-------------AAAB----- ------BC-AAAAAAAAAAAAA-CB------ ----------CBBBBBBBBBC---------- ------------------------------- 
------------------------------- ------------------------------- ------------------------------- ------------------------------- ------------------------------- ------------------------------- ------------------------------- ------------------------------- ------------------------------- ------------------------------- ------------------------------- ------------------------------- ------------------------------- ---C-----------------------C--- ---B-----------------------B--- ---B-----------------------B--- ---CC---------------------CC--- -----A-------------------A----- ----CA-------------------AC---- -----BA-----------------AB----- -----BA-----------------AB----- ------BA---------------AB------ ------BAAA-----------AAAB------ -------CC-AAAAAAAAAAA-CC------- ----------CBBBBBBBBBC---------- ------------------------------- 
------------------------------- ------------------------------- ------------------------------- ------------------------------- ------------------------------- ------------------------------- ------------------------------- ------------------------------- ------------------------------- ------------------------------- ------------------------------- ------------------------------- ------------------------------- ----C---------------------C---- ----B---------------------B---- ----B---------------------B---- ----C---------------------C---- -----A-------------------A----- ----CAA-----------------AAC---- -----BBA---------------ABB----- ------BA---------------AB------ -------BAA-----------AAB------- -------BAAAA-------AAAAB------- --------C-CBAAAAAAABC-C-------- -----------BBBBBBBBB----------- ------------------------------- 
------------------------------- ------------------------------- ------------------------------- ------------------------------- ------------------------------- ------------------------------- ------------------------------- ------------------------------- ------------------------------- ------------------------------- ------------------------------- ------------------------------- ------------------------------- -----C-------------------C----- -----B-------------------B----- -----B-------------------B----- -----C-------------------C----- ------AA---------------AA------ -----CAA---------------AAC----- ------BBAA-----------AABB------ -------BAA-----------AAB------- --------C-AA-------AA-C-------- --------C-AAAAAAAAAAA-C-------- ----------CBBBBBBBBBC---------- -------------CCCCC------------- ------------------------------- 
------------------------------- ------------------------------- ------------------------------- ------------------------------- ------------------------------- ------------------------------- ------------------------------- ------------------------------- ------------------------------- ------------------------------- ------------------------------- ------------------------------- ------------------------------- ------C-----------------C------ ------B-----------------B------ ------B-----------------B------ ------CC---------------CC------ --------A-------------A-------- ------CCAA-----------AACC------ --------BCAA-------AACB-------- --------C-AA-------AA-C-------- ----------CBAAAAAAABC---------- ----------CBAAAAAAABC---------- -----------CBBBBBBBC----------- ------------CEEEEEC------------ ------------------------------- 
------------------------------- ------------------------------- ------------------------------- ------------------------------- ------------------------------- ------------------------------- ------------------------------- ------------------------------- ------------------------------- ------------------------------- ------------------------------- ------------------------------- ------------------------------- -------CC-------------CC------- -------BB-------------BB------- -------BB-------------BB------- -------CCC------------CC------- ---------AAA-------AAA--------- --------CAAA-------AAAC-------- ---------C-CAAAAAAAC-C--------- -----------CAAAAAAAC----------- -----------EBBBBBBBE----------- -----------EBBBBBBBE----------- ------------ECCCCCE------------ ------------------------------- ------------------------------- 
------------------------------- ------------------------------- ------------------------------- ------------------------------- ------------------------------- ------------------------------- ------------------------------- ------------------------------- ------------------------------- ------------------------------- ------------------------------- ------------------------------- ------------------------------- ---------CCC-------CCC--------- ---------BBB-------BBB--------- ---------BBB-------BBB--------- ---------CCC-------CCC--------- ------------AAAAAAA------------ ---------C--AAAAAAA--C--------- ------------CBBBBBC------------ ------------BBBBBBB------------ ------------CCFFFAC------------ ------------CFFFFFC------------ ------------------------------- ------------------------------- ------------------------------- 
------------------------------- ------------------------------- ------------------------------- ------------------------------- ------------------------------- ------------------------------- ------------------------------- ------------------------------- ------------------------------- ------------------------------- ------------------------------- ------------------------------- ------------------------------- ------------CCCCCCC------------ ------------BBBBBBB------------ ------------BBBBBBB------------ ------------CCCCCCC------------ ------------DCDCDCD------------ ------------CCCCCCC------------ -------------EEEEE------------- ------------EECCCEE------------ -----------------C------------- ------------------------------- ------------------------------- ------------------------------- ------------------------------- 
