model
size = 32 30 32, scale = 0.05, origin = -y
material 
  colors = A:#040 B:#400 C:#330 D:#EEE E:#036 F:#005 G:#09F H:#444 I:#06F J:#C90 K:#AAA
voxels
428-2(8A24-)8B24-8B852-16A17-14A2(18-3B8A3B)22-6A27-4A788-6A8-6A14-5A6-5A16-B4A6-4AB16-2B5A2-5A2B18-12A20-12A21-10A23-8A27-2A692-5A12-5A11-2(4A12-)2B2A12-2A2B12-2B3A10-3A2B14-4A8-4A16-5A6-5A17-14A19-12A21-10A23-8A656-4A16-4A9-3A16-3A10-B2A16-2AB10-B3A14-3AB12-2(2A14-)3A12-3A14-4A10-4A15-5A6-5A17-14A19-12A21-10A25-4A593-4A18-4A7-3A18-3A2(8-B2A18-2AB)10-2A16-2A2(12-3A14-3A)13-4A10-4A14-5A8-5A15-16A17-14A20-10A25-4A560-4A20-4A5-3A20-3A2(6-B2A20-2AB)8-2(2A18-2A10-)3A16-3A11-3A14-3A2(12-4A)13-5A8-5A15-16A17-14A20-10A25-4A527-4A22-4A3-3A22-3A5-BA22-AB6-BA22-AB7-2(2A20-2A8-)3A18-3A9-3A16-3A10-4A14-4A11-4A12-4A13-5A8-5A15-16A17-14A20-10A524-3A24-3A3-2A24-2A4-BA24-AB4-B2A22-2AB5-2A22-2A6-3A20-3A7-2A20-2A8-3A18-3A9-3A16-3A10-4A14-4A11-5A10-5A13-6A6-6A15-16A18-12A22-8A492-4A24-4A-3A24-3A2-B2A24-2AB3-BA24-A2B2-2EA24-A2(4-2E2A22-2A)4-2E-2A20-2A5-2E-3A18-3A5-2E2-3A16-3A6-2E2-4A14-4A6-2E3-5A10-5A7-2E4-18A16-14A20-10A26-2A463-3A26-3A-2A26-2A2-BA26-AB2-B2A24-2AB2-2(D2A24-2A3-)DF2A22-2A4-DG3A20-3A4-DF-2A20-2A5-DG-3A18-3A5-DF2-4A14-4A6-DG3-4A12-4A7-DF4-6A6-6A8-2E5-16A18-12A22-8A460-3A26-3A-2A26-2A-2BA26-A3BDA26-A2B-3(D2A24-2A3-)D-2A22-2A4-DF3A20-3A4-DF-3A18-3A5-DG-4A16-4A5-DF2-4A14-4A6-DG3-6A8-6A7-DF4-18A8-2E6-14A20-10A459-2AC26-C5A26-3ABDA26-2A2BDA26-2AB-DA26-A2(3-D2A24-2A)3-I3A22-3A3-IG2A22-2A4-DG3A20-3A4-DF-3A18-3A5-DG2-4A14-4A6-DF3-5A10-5A7-DG4-8A2-8A8-2E5-16A18-12A24-4A80-H26-H10(4-C26-C)2-2AC26-C4AC26-C2ABDC26-CA2BDA26-2AB-DA26-2A2-DA26-A3-I2(2A24-2A3-D)-2A22-2A4-IF3A20-3A4-DG-3A18-3A5-DF2-3A16-3A6-DG3-4A12-4A7-DF4-6A6-6A8-2E5-16A18-12A23-6A47-H26-H11(4-C26-C)2-2AC26-C4AC26-C2ABDC26-CA2BDA26-2AB-DA26-2A2-IA26-2A2-2(D2A24-2A3-)D-2A22-2A4-DG3A20-3A4-IF-3A18-3A5-DG-4A16-4A5-DF2-5A12-5A6-DG3-7A6-7A7-2E5-16A18-12A22-8A14-H26-H12(4-C26-C)2-2AC26-C4AC26-C2ABAC26-CA2BDC26-CAB-2(DA26-2A2-)I2(2A24-2A3-D)3A22-3A3-IF3A20-3A4-DG-3A18-3A5-DF-4A16-4A5-DG2-5A12-5A6-DF3-6A8-6A7-2E5-16A17-14A21-8A14-H26-H12(4-C26-C)2-2AC26-C4AC26-C2ABAC26-CA2BAC26-CAB-2(DA26-2A2-)D2(2A24-2A3-I)3A22-3A3-DG3A20-3A4-DF-3A18-3A5-DG-4A16-4A5-DF2-5A12-5A6-DG3-6A8-6A7-2E5-16A17-14A21-8A46-H26-H11(4-C26-C)2-2AC26-C4AC26-C2ABAC26-CA2B2A26-2AB-2(DA26-2A2-)2(D2A24-2A3-)DG2A22-2A4-DF3A20-3A4-DG-3A18-3A5-DF-4A16-4A5-IG2-5A12-5A6-DF3-7A6-7A7-2E5-16A18-12A22-8A78-H26-H10(4-C26-C)2-2AC26-C4AC26-C2ABAC26-CA2B2A26-2AB-DA26-2A2-DA26-A2(3-D2A24-2A)3-DF2A22-2A4-DG3A20-3A4-DF-3A18-3A5-DG2-3A16-3A6-DF3-4A12-4A7-2E4-6A6-6A15-16A18-12A23-6A429-2AC26-C5A26-3AB2A26-2A3BA26-2AB-EA26-A2(J2-E2A24-2A)K2-2E2A22-3A3-2E2A22-2A4-2E3A20-3A4-2E-3A18-3A5-2E2-4A14-4A6-2E3-5A10-5A13-8A2-8A15-16A18-12A24-4A430-3A26-3A-2A26-2A2-BA26-A2B-BA26-A2B2-2(2A24-2A4-)2A24-2A5-2A22-2A6-3A20-3A7-3A18-3A8-4A16-4A9-4A14-4A11-6A8-6A13-18A16-14A20-10A459-3A26-3A-2A26-2A2-BA26-AB2-B2A24-2AB3-2A24-2A4-2A24-2A5-2A22-2A6-3A20-3A7-2A20-2A8-3A18-3A9-4A14-4A11-4A12-4A13-6A6-6A15-16A18-12A22-8A460-4A24-4A-3A24-3A2-B2A24-2AB2-2BA24-A2B4-A24-A2(J5-2A22-2A)K6-2A20-2A8-3A18-3A9-3A16-3A10-4A14-4A11-5A10-5A13-18A16-14A20-10A26-2A464-3A24-3A3-2A24-2A4-BA24-AB4-B2A22-2AB5-2A22-2A6-3A20-3A7-2A20-2A8-3A18-3A9-3A16-3A10-4A14-4A11-5A10-5A13-6A6-6A15-16A18-12A22-8A493-4A22-4A3-3A22-3A2(4-2BA22-A2B)6-2(2A20-2A8-)3A18-3A9-3A16-3A10-4A14-4A11-4A12-4A13-5A8-5A15-16A17-14A20-10A525-4A20-4A5-3A20-3A2(6-B2A20-2AB)8-2(2A18-2AJ9-)3A16-3AK10-3A14-3A2(12-4A)13-5A8-5A15-16A17-14A20-10A25-4A529-4A18-4A7-3A18-3A2(8-B2A18-2AB)10-2A16-2A2(12-3A14-3A)13-4A10-4A14-5A8-5A15-16A17-14A20-10A25-4A562-4A16-4A9-3A16-3A10-B2A16-2AB10-B3A14-3AB12-2A14-2AJ13-3A12-3AJ13-4A10-4AK14-5A6-5A17-14A19-12A21-10A25-4A595-5A12-5A11-2(4A12-)2B2A12-2A2B12-2B3A10-3A2B14-4A8-3AJ16-5A6-4AJ17-14AK18-12A21-10A23-8A658-6A8-6A14-5A6-5A16-B4A6-4AB16-2B5A2-5A2B18-12A20-12A21-10A23-8A27-2A695-16A17-14A18-3B8A3B18-3B8A2B23-6A27-4A794-2(8A24-)8B24-8B-B426-
