model
size = 32, scale = 0.05, origin = -y
material 
  colors = A:#050 B:#111 C:#EEE D:#D00 E:#800 F:#040
voxels
367-2D123-8E22-3E6A3E18-3E10A3E17-14A23-4A118-3F10-3F15-F3CF8-F3CF14-2CB2C8-2CB2C14-A3CA8-A3CA15-3A10-3A502-4D120-3E6-3E19-E12BE16-3E12B3E14-3A12B3A17-12A21-F8AF23-2F4A2F20-3F3-F2AF3-3F15-2FC2F3-2A3-2FC2F13-2F3C2F6-2F3C2F12-7C6-7C12-2A3C2A6-2A3C2A13-2AC2A8-2AC2A15-3A10-3A469-6D179-2E16-2E12-A18BA13-18A14-F16AF15-3F10A3F15-2ACAF8AFAC2A13-A5CF6AF5CA12-A5CAF4AFA5CA11-A7CFA2-AF7CA11-A5C2A4-2A5CA12-A5CA6-A5CA13-2AC2A8-2AC2A16-A12-A248-2A29-4E27-6E122-6D27-4D147-2E18-2E10-A20BA10-2A2B2A10B2A2B2A10-FAB16ABAF11-F18AF12-20A12-A2C14A2CA11-A5C10A5CA10-A7C6A7CA10-A7C2A2-2A7CA11-A5C2A4-2A5CA12-2A3C2A6-2A3C2A14-3A10-3A212-8A22-5A2B5A20-12E22-8E153-6D177-2E3-3B8-3B3-2E8-E2B-B2A10B2AB-2BE8-A3B16A3BA9-22A11-20A11-A2C16A2CA10-A3C14A3CA10-A4C12A4CA10-A6C8A6CA10-A7C2A2-2A7CA11-A5CA6-A5CA13-5A8-5A179-8A22-2A8B2A19-A5B2-5BA18-E12-E182-6D208-2E4-2B10-2B4-2E6-2E3-B2A10B2AB3-2E7-A3B16A3BA9-22A11-20A11-AC18ACA10-A3C14A3CA10-A4C12A4CA11-A5C8A5CA12-2A3C2A6-2A3C2A14-3A10-3A148-8A22-2A8B2A18-2A2B8-2B2A16-AB12-BA16-E14-E150-4D27-6D240-2E4-3B8-3B4-2E6-2AB-2B3A8B3A2B-B2A8-AB18ABA11-20A12-20A11-AC18ACA11-A2C14A2CA12-A3C12A3CA13-2AC3A6-3AC2A16-A12-A147-12A18-2A12B2A15-A2B12-2B2(A14-AB14-B)A13-2E16-2E115-6D272-E6-B10-B6-E6-AB4-BA10BAB4-BA7-A4B14A4BA9-22A10-22A11-20A12-20A13-AC14ACA15-5A6-5A17-2A10-2A146-14A17-A5BA2BA5BA15-A2B4-B2-B4-2BA13-2AB14-B2A12-2AB14-B2A10-2E2B16-2B2E113-6D271-2E24-2E4-EB6-12B6-BE5-A2B2-2B12A2B2-2BA7-2A2B16A2B2A9-22A11-20A13-18A14-8A2-8A15-4A8-4A17-3A8-3A19-A10-A88-4A21-18A12-3A2BA10BA2B3A10-2AB2-B10-B2-B2A9-3AB16-B3A8-3AB16-B3A7-E4B16-4BE80-6D27-4D304-EB7-4B2-4B7-BE5-AB4-3B3A2B3A3B4-BA6-2A4B14A4B2A7-24A9-22A12-18A14-7A4-7A15-5A6-5A16-4A8-4A17-3A8-3A19-A10-A54-8A20-16A13-5A12B5A9-A-4B12-4B-A8-A2B18-2BA7-E3B18-3BE81-4D27-6D334-EB10-B4-B10-BE3-AB6-B-8B-B6-BA5-A9B6A9BA7-24A8-24A10-20A13-7A4-7A14-6A6-6A15-4A8-4A17-3A8-3A19-A10-A53-10A20-14A14-5A12B5A9-A-4B12-4B-A7-E2B20-2BE112-6D334-E28-E2-EB26-BE2-AB11-4B11-BA3-A4B6-B4AB6-4BA5-3A7B6A7B3A7-24A9-22A11-8A4-8A13-6A6-6A15-4A8-4A17-3A8-3A19-A10-A24-4A24-12A18-16A13-4A14B4A9-A4B14-4BA7-EB22-BE112-6D27-4D302-2E28-2EAB28-BA-AB12-2B12-BA3-A2B9-B2AB9-2BA5-2AB6-2B4A2B6-B2A7-2A6B8A6B2A8-24A10-9A2-9A14-4A8-4A17-3A8-3A18-2A10-2A54-6A23-12A18-16A13-4A14B4A8-3A3B14-3B3A5-E2AB20-B2AE5-2B22-2B112-6D27-4D238-E30-2E30-EAB28-BA-AB26-BA3-AB11-2B11-BA5-AB8-2B2A2B8-BA6-2A2B3-3B6A3B3-2B2A7-3A3B12A3B3A10-9A2-9A14-4A8-4A17-2A10-2A19-A10-A54-8A21-14A17-16A13-3A16B3A8-4AB16-B4A5-E2A2B18-2B2AE3-E3B22-3BE142-6D27-4D206-E30-EA2(B28-B2A)2B26-2BA-AB12-2B12-BA3-AB10-B2AB10-BA5-A2B5-3B4A3B5-2BA6-3A5B10A5B3A8-22A12-6A6-6A16-2A10-2A19-A10-A54-8A21-14A16-18A13-3A14B3A9-4A2B14-2B4A5-2A3B18-3B2A3-E2B24-2BE2-E28-E142-6D173-E30-EA3(B28-B2A)B28-BA-AB26-BA2-AB10-6B10-BA3-A2B7-B6AB7-2BA5-2A7B8A7B2A7-24A10-8A4-8A14-4A8-4A84-8A21-14A16-18A13-4A12B4A10-4A2B12-2B4A7-3A2B16-2B3A5-2A2B20-2B2A2-2E2B24-2B3E30-E77-6D27-4D110-E30-2E30-EA4(B28-B2A)B28-BA-AB26-BA2-AB10-2B2-2B10-BA3-A2B6-2(2B2A)2B6-2BA5-2A6B10A6B2A7-24A10-8A4-8A14-4A8-4A84-8A21-14A17-16A14-5A10B5A10-5A2B10-2B5A8-3A2B14-2B3A7-3AB18-B3A4-3A2B20-2B3A-E4B22-4B2E3B24-3B2E-B10-6D10-B-E14-4D78-E30-2E30-EA3(B28-B2A)2B26-2B3(2AB28-B)A-AB26-BA2-AB9-B6-B9-BA3-A2B5-2BA6BA2B5-2BA5-2A5B12A5B2A8-22A12-6A6-6A17-A10-A87-6A23-12A18-16A14-6A3B2D3B6A11-5A2B8-2B5A9-4A2B12-2B4A7-2ABAB16-BAB2A6-AB-B18-B-BA4-3AB8-6D8-B3A2-3AB8-6D8-B3A-2(AB)10-4D10-2(BA)E2(-B26-B-2E)30-EA4(B28-B2A)2B26-2BA-AB26-BA-A2B26-2B2AB28-BA-AB26-BA2-AB26-BA3-AB7-B8-B7-BA5-A2B-4BA8BA4B-2BA7-2AB18AB2A10-20A14-4A3-2A3-4A118-4A24-12A18-16A15-5A2B4D2B5A12-5A2B2-4D2-2B5A9-4A2B4-4D4-2B4A8-A3B6-4D6-3BA7-AB8-6D8-BA5-2AB9-4D9-B2A4-AB24-BA3-2AB24-B2A-2(AB)24-BAB2A3B24-3B2A2B26-2B2(2AB28-B)2(2A2B26-2B)A-AB26-BA2-AB26-BA-A2B26-2B2A2B26-2BA-AB26-BA3-AB24-BA5-AB3-3B10-3B3-BA7-A3B3A10B3A3BA9-22A12-18A17-A4-2A4-A149-10A20-14A16-18A13-3A4B6D4B3A11-2A2B3-B6DB3-2B2A9-A2B6-6D6-2BA7-AB9-4D9-BA6-AB22-BA5-FAB22-BAF4-AB24-BA3-2(2AB24-B2A2-)2A2B22-2B2A2(2-A2B24-2BA)3(2-AB26-BA)2-FAB24-BAF2(2-2AB24-B2A)2-2A2B22-2B2A4-A2B-B16-B-2BA7-A7B8-7BA8-8A8B8A10-20A16-12A24-4A154-8A21-14A17-16A14-2A6B4A6B2A11-2AB6-4D6-B2A9-A2B18-2BA7-AB22-BA5-AB24-BA4-FAB22-BAF4-2AB22-B2A4-FB24-BF3-3AB22-B3A2-2A2B22-2B2A2-A3B22-3BA2-A2B24-2BA2-2AB24-B2A2-AB26-BA2(2-2AB24-B2A)2-FA2B22-2BAF2(2-A5B18-5BA)3-FA5B14-5BAF6-A3BA4B2-2B2-4BA3BA9-8A2B2A2B8A13-16A20-8A27-2A157-4A24-12A18-16A15-2(2A6B)2A12-2A2B6-2D6-2B2A9-A2B18-2BA7-AB-B18-B-BA5-AB24-BA4-2AB22-B2A4-FAB22-BAF2(4-2AB22-B2A)4-A2B22-2BA3-A2BAB20-BA2BA2-A3B22-3BA2(2-2AB24-B2A)3-AB24-BA4-A2B22-2BA4-FBAB20-BABF3-F5B18-5BF3-F5B16-5BF4-2A6B12-6B2A6-A3B2A12B2A3BA9-22A14-14A22-6A217-8A21-14A17-2A12B2A15-A2B12-2BA12-2AB16-B2A9-A2B18-2BA7-A2B20-2BA6-FAB20-BAF6-2AB20-B2A5-3AB20-B3A4-2AB22-B2A4-A3B20-3BA3-A2BAB20-BA2BA2-2(A2B)18-2(2BA)3-2A2B20-2B2A4-2AB22-B2A4-2A2B20-2B2A4-ABA2B18-2BABA4-FBA2B18-2BABF4-AB3AB16-B3ABA4-A2B3AB6-2B6-B3A2BA5-2A2(BA)14B2(AB)2A8-2AB16AB2A12-18A18-10A26-2A222-2A26-10A20-2(2A4B)2A16-2A2(2B4-)2B2A12-3AB14-B3A9-2(AB)16-2(BA)2(8-A2B18-2BA)7-2A2B18-2B2(2A6-2AB20-B)2A5-A3B20-3BA3-2(2AB)18-2(B2A)2-2(A2B)18-2(2BA)3-3(2A3B18-3B2A4-)FBA3B7-2B7-3BABF4-ABA2(4B5-)4BABA5-5A2B2-8B2-2B5A6-6A14B6A8-2AB7A2B7AB2A12-18A17-12A24-4A282-8A22-2A2B4A2B2A19-A2B2-4B2-2BA16-2AB12-B2A12-3AB14-B3A10-A2B16-2BA9-A3B16-3BA8-A3B16-3BA7-2A3B16-3B2A6-2A2B18-2B2A5-A5B16-5BA4-AB2A2B16-2B2ABA4-AB2AB18-B2ABA5-3AB18-B3A6-2A2B18-2B2A6-3A2(2B7-)2B3A6-4AB7-2B7-B4A6-4A3B3-6B3-3B4A8-3A16B3A12-2(2A6B)2A14-18A17-12A23-6A344-10A21-A4B2A4BA19-AB4-2B4-BA16-2AB12-B2A13-A2B14-2BA11-A3B14-3BA9-A4B14-4BA8-A5B12-5BA8-2A5B4-2B4-5B2A7-3A3B6-2B6-3B3A6-3A2B16-2B3A6-4AB16-B4A7-2AB18-B2A2(8-3AB7-2B7-B3A)8-3A2B5-4B5-2B3A9-2A4B-8B-4B2A11-2A2BA10BA2B2A14-A6B2A6BA17-14A21-8A26-4A377-10A21-A4B2A4BA18-2A2B2-4B2-2B2A15-A3B4-2B4-3BA13-A3B12-3BA11-2A4B4-2B4-4B2A10-A6B2-4B2-6BA10-A20BA10-A4B3-6B3-4BA10-A3B5-4B5-3BA3(10-2AB7-2B7-B2A)10-3AB5-4B5-B3A10-4AB3-2B2A2B3-B4A11-4A3B6A3B4A13-18A16-14A20-10A25-4A411-2A2-2A24-2(2A2B)2A20-2A10B2A17-A14BA15-A16BA14-A16BA13-A18BA12-A8B2A8BA11-A9B2A9BA10-2ABA2B-8B-2BAB2A10-3A2B3-6B3-2B3A10-3AB5-4B5-B3A10-3A2B3-2B2A2B3-2B3A11-3A2B-8B-2B3A13-3A3BAB2ABA3B3A14-18A16-14A21-8A25-6A474-6A24-4A2B4A20-6A2B6A17-16A16-A2(2B4A)2BA15-2A3B2A4B2A3B2A14-A7B2A7BA13-2(2A7B)2A12-3A14B3A2(12-2A16B2A)13-A7B2A7BA15-A5BA2BA5BA16-2A3B6A3B2A18-12A21-10A24-6A540-2A28-6A24-10A20-14A18-14A17-5(16A16-)16A17-14A19-12A23-6A668-2A28-6A25-8A23-10A21-2(12A20-)12A21-10A23-8A25-6A28-2A399-
