model
size = 20 26 20, scale = 0.05, origin = -y
material 
  colors = A:#222 B:#ECB88A C:#FFFFFB
voxels
-------------------- -------------------- -------------------- -------------------- -------------------- -------------------- -------------------- -------------------- -------------------- -------------------- -------------------- -------------------- -------------------- -------------------- ------AAAAAAAA------ ------AAAAAAAA------ -------------------- -------------------- -------------------- -------------------- -------------------- -------------------- -------------------- -------------------- -------------------- -------------------- 
-------------------- -------------------- -------------------- -------------------- -------------------- -------------------- -------------------- -------------------- -------------------- -------------------- -------------------- -------------------- -------------------- -------------------- ----AAAAAAAAAAAA---- ----AAAAAAAAAAAA---- -------------------- -------------------- -------------------- -------------------- -------------------- -------------------- -------------------- -------------------- -------------------- -------------------- 
-------------------- -------------------- -------------------- -------------------- -------------------- -------------------- ---------BB--------- ---------BB--------- -------------------- -------------------- -------------------- -------------------- -------------------- -------------------- ---AAAAAAAAAAAAAA--- ---AAAAAAAAAAAAAA--- -------------------- -------------------- -------------------- -------------------- -------------------- -------------------- -------------------- -------------------- -------------------- -------------------- 
-------------------- -------------------- ------CCC--CCC------ -----CCCCCCCCCC----- ----CCCCCCCCCCCC---- ----C-CCCCCCCC-C---- -------CCBBCC------- ---------BB--------- -------------------- -------A----A------- -------------------- ------A-A--A-A------ -------A----A------- -------------------- --AAAAAAAAAAAAAAAA-- --AAAAAAAAAAAAAAAA-- -------AAAAAA------- -------AAAAAA------- -------AAAAAA------- -------AAAAAA------- -------AAAAAA------- -------AAAAAA------- -------AAAAAA------- -------AAAAAA------- -------AAAAAA------- -------AAAAAA------- 
-------------------- -------------------- --------BBBB-------- ------BBBBBBBB------ -----BBBBBBBBBB----- -----BBBBBBBBBB----- ----BBBBBBBBBBBB---- ----BBBBBBBBBBBB---- ----BBBBBBBBBBBB---- ----BBBBBBBBBBBB---- -----BBBBBBBBBB----- -----BBBBBBBBBB----- ------BBBBBBBB------ --------BBBB-------- -AAAAAAAAAAAAAAAAAA- -AAAAAAAAAAAAAAAAAA- -----AAAAAAAAAA----- -----AAAAAAAAAA----- -----AAAAAAAAAA----- -----AAAAAAAAAA----- -----AAAAAAAAAA----- -----AAAAAAAAAA----- -----AAAAAAAAAA----- -----AAAAAAAAAA----- -----AAAAAAAAAA----- -----AAAAAAAAAA----- 
-------------------- ---------BB--------- ------BBBBBBBB------ -----BBBBBBBBBB----- ----BBBBBBBBBBBB---- ----BBBBBBBBBBBB---- ----BBBBBBBBBBBB---- ---BBBBBBBBBBBBBB--- ---BBBBBBBBBBBBBB--- ----BBBBBBBBBBBB---- ----BBBBBBBBBBBB---- ----BBBBBBBBBBBB---- -----BBBBBBBBBB----- ------BBBBBBBB------ -AAAAAAAAAAAAAAAAAA- -AAAAAAAAAAAAAAAAAA- ----AAAAAAAAAAAA---- ----AAAAAAAAAAAA---- ----AAAAAAAAAAAA---- ----AAAAAAAAAAAA---- ----AAAAAAAAAAAA---- ----AAAAAAAAAAAA---- ----AAAAAAAAAAAA---- ----AAAAAAAAAAAA---- ----AAAAAAAAAAAA---- ----AAAAAAAAAAAA---- 
-------------------- -------BBBBBB------- -----BBBBBBBBBB----- ----BBBBBBBBBBBB---- ----BBBBBBBBBBBB---- ---BBBBBBBBBBBBBB--- ---BBBBBBBBBBBBBB--- ---BBBBBBBBBBBBBB--- ---BBBBBBBBBBBBBB--- ---BBBBBBBBBBBBBB--- ---BBBBBBBBBBBBBB--- ----BBBBBBBBBBBB---- ----BBBBBBBBBBBB---- -----BBBBBBBBBB----- AAAAAAAAAAAAAAAAAAAA AAAAAAAAAAAAAAAAAAAA ----AAAAAAAAAAAA---- ----AAAAAAAAAAAA---- ----AAAAAAAAAAAA---- ----AAAAAAAAAAAA---- ----AAAAAAAAAAAA---- ----AAAAAAAAAAAA---- ----AAAAAAAAAAAA---- ----AAAAAAAAAAAA---- ----AAAAAAAAAAAA---- ----AAAAAAAAAAAA---- 
---------BB--------- ------BBBBBBBB------ -----BBBBBBBBBB----- ----BBBBBBBBBBBB---- ---BBBBBBBBBBBBBB--- ---BBBBBBBBBBBBBB--- ---BBBBBBBBBBBBBB--- --BBBBBBBBBBBBBBBB-- --BBBBBBBBBBBBBBBB-- ---BBBBBBBBBBBBBB--- ---BBBBBBBBBBBBBB--- ---BBBBBBBBBBBBBB--- ----BBBBBBBBBBBB---- -----BBBBBBBBBB----- AAAAAAAAAAAAAAAAAAAA AAAAAAAAAAAAAAAAAAAA ---AAAAAAAAAAAAAA--- ---AAAAAAAAAAAAAA--- ---AAAAAAAAAAAAAA--- ---AAAAAAAAAAAAAA--- ---AAAAAAAAAAAAAA--- ---AAAAAAAAAAAAAA--- ---AAAAAAAAAAAAAA--- ---AAAAAAAAAAAAAA--- ---AAAAAAAAAAAAAA--- ---AAAAAAAAAAAAAA--- 
--------BBBB-------- ------BBBBBBBB------ ----BBBBBBBBBBBB---- ----BBBBBBBBBBBB---- ---BBBBBBBBBBBBBB--- ---BBBBBBBBBBBBBB--- --BBBBBBBBBBBBBBBB-- --BBBBBBBBBBBBBBBB-- --BBBBBBBBBBBBBBBB-- --BBBBBBBBBBBBBBBB-- ---BBBBBBBBBBBBBB--- ---BBBBBBBBBBBBBB--- ----BBBBBBBBBBBB---- ----BBBBBBBBBBBB---- AAAAAAAAAAAAAAAAAAAA AAAAAAAAAAAAAAAAAAAA ---AAAAAAAAAAAAAA--- ---AAAAAAAAAAAAAA--- ---AAAAAAAAAAAAAA--- ---AAAAAAAAAAAAAA--- ---AAAAAAAAAAAAAA--- ---AAAAAAAAAAAAAA--- ---AAAAAAAAAAAAAA--- ---AAAAAAAAAAAAAA--- ---AAAAAAAAAAAAAA--- ---AAAAAAAAAAAAAA--- 
-------BBBBBB------- -----BBBBBBBBBB----- ----BBBBBBBBBBBB---- ---BBBBBBBBBBBBBB--- ---BBBBBBBBBBBBBB--- --BBBBBBBBBBBBBBBB-- --BBBBBBBBBBBBBBBB-- --BBBBBBBBBBBBBBBB-- --BBBBBBBBBBBBBBBB-- --BBBBBBBBBBBBBBBB-- --BBBBBBBBBBBBBBBB-- ---BBBBBBBBBBBBBB--- ---BBBBBBBBBBBBBB--- ----BBBBBBBBBBBB---- AAAAAAAAAAAAAAAAAAAA AAAAAAAAAAAAAAAAAAAA ---AAAAAAAAAAAAAA--- ---AAAAAAAAAAAAAA--- ---AAAAAAAAAAAAAA--- ---AAAAAAAAAAAAAA--- ---AAAAAAAAAAAAAA--- ---AAAAAAAAAAAAAA--- ---AAAAAAAAAAAAAA--- ---AAAAAAAAAAAAAA--- ---AAAAAAAAAAAAAA--- ---AAAAAAAAAAAAAA--- 
-------BBBBBB------- -----BBBBBBBBBB----- ----BBBBBBBBBBBB---- ---BBBBBBBBBBBBBB--- ---BBBBBBBBBBBBBB--- --BBBBBBBBBBBBBBBB-- --BBBBBBBBBBBBBBBB-- --BBBBBBBBBBBBBBBB-- --BBBBBBBBBBBBBBBB-- --BBBBBBBBBBBBBBBB-- --BBBBBBBBBBBBBBBB-- ---BBBBBBBBBBBBBB--- ---BBBBBBBBBBBBBB--- ----BBBBBBBBBBBB---- AAAAAAAAAAAAAAAAAAAA AAAAAAAAAAAAAAAAAAAA ---AAAAAAAAAAAAAA--- ---AAAAAAAAAAAAAA--- ---AAAAAAAAAAAAAA--- ---AAAAAAAAAAAAAA--- ---AAAAAAAAAAAAAA--- ---AAAAAAAAAAAAAA--- ---AAAAAAAAAAAAAA--- ---AAAAAAAAAAAAAA--- ---AAAAAAAAAAAAAA--- ---AAAAAAAAAAAAAA--- 
--------BBBB-------- ------BBBBBBBB------ ----BBBBBBBBBBBB---- ----BBBBBBBBBBBB---- ---BBBBBBBBBBBBBB--- ---BBBBBBBBBBBBBB--- --BBBBBBBBBBBBBBBB-- --BBBBBBBBBBBBBBBB-- --BBBBBBBBBBBBBBBB-- --BBBBBBBBBBBBBBBB-- ---BBBBBBBBBBBBBB--- ---BBBBBBBBBBBBBB--- ----BBBBBBBBBBBB---- ----BBBBBBBBBBBB---- AAAAAAAAAAAAAAAAAAAA AAAAAAAAAAAAAAAAAAAA ---AAAAAAAAAAAAAA--- ---AAAAAAAAAAAAAA--- ---AAAAAAAAAAAAAA--- ---AAAAAAAAAAAAAA--- ---AAAAAAAAAAAAAA--- ---AAAAAAAAAAAAAA--- ---AAAAAAAAAAAAAA--- ---AAAAAAAAAAAAAA--- ---AAAAAAAAAAAAAA--- ---AAAAAAAAAAAAAA--- 
---------BB--------- ------BBBBBBBB------ -----BBBBBBBBBB----- ----BBBBBBBBBBBB---- ---BBBBBBBBBBBBBB--- ---BBBBBBBBBBBBBB--- ---BBBBBBBBBBBBBB--- --BBBBBBBBBBBBBBBB-- --BBBBBBBBBBBBBBBB-- ---BBBBBBBBBBBBBB--- ---BBBBBBBBBBBBBB--- ---BBBBBBBBBBBBBB--- ----BBBBBBBBBBBB---- -----BBBBBBBBBB----- AAAAAAAAAAAAAAAAAAAA AAAAAAAAAAAAAAAAAAAA ---AAAAAAAAAAAAAA--- ---AAAAAAAAAAAAAA--- ---AAAAAAAAAAAAAA--- ---AAAAAAAAAAAAAA--- ---AAAAAAAAAAAAAA--- ---AAAAAAAAAAAAAA--- ---AAAAAAAAAAAAAA--- ---AAAAAAAAAAAAAA--- ---AAAAAAAAAAAAAA--- ---AAAAAAAAAAAAAA--- 
-------------------- -------BBBBBB------- -----BBBBBBBBBB----- ----BBBBBBBBBBBB---- ----BBBBBBBBBBBB---- ---BBBBBBBBBBBBBB--- ---BBBBBBBBBBBBBB--- ---BBBBBBBBBBBBBB--- ---BBBBBBBBBBBBBB--- ---BBBBBBBBBBBBBB--- ---BBBBBBBBBBBBBB--- ----BBBBBBBBBBBB---- ----BBBBBBBBBBBB---- -----BBBBBBBBBB----- AAAAAAAAAAAAAAAAAAAA AAAAAAAAAAAAAAAAAAAA ----AAAAAAAAAAAA---- ----AAAAAAAAAAAA---- ----AAAAAAAAAAAA---- ----AAAAAAAAAAAA---- ----AAAAAAAAAAAA---- ----AAAAAAAAAAAA---- ----AAAAAAAAAAAA---- ----AAAAAAAAAAAA---- ----AAAAAAAAAAAA---- ----AAAAAAAAAAAA---- 
-------------------- ---------BB--------- ------BBBBBBBB------ -----BBBBBBBBBB----- ----BBBBBBBBBBBB---- ----BBBBBBBBBBBB---- ----BBBBBBBBBBBB---- ---BBBBBBBBBBBBBB--- ---BBBBBBBBBBBBBB--- ----BBBBBBBBBBBB---- ----BBBBBBBBBBBB---- ----BBBBBBBBBBBB---- -----BBBBBBBBBB----- ------BBBBBBBB------ -AAAAAAAAAAAAAAAAAA- -AAAAAAAAAAAAAAAAAA- ----AAAAAAAAAAAA---- ----AAAAAAAAAAAA---- ----AAAAAAAAAAAA---- ----AAAAAAAAAAAA---- ----AAAAAAAAAAAA---- ----AAAAAAAAAAAA---- ----AAAAAAAAAAAA---- ----AAAAAAAAAAAA---- ----AAAAAAAAAAAA---- ----AAAAAAAAAAAA---- 
-------------------- -------------------- --------BBBB-------- ------BBBBBBBB------ -----BBBBBBBBBB----- -----BBBBBBBBBB----- ----BBBBBBBBBBBB---- ----BBBBBBBBBBBB---- ----BBBBBBBBBBBB---- ----BBBBBBBBBBBB---- -----BBBBBBBBBB----- -----BBBBBBBBBB----- ------BBBBBBBB------ --------BBBB-------- -AAAAAAAAAAAAAAAAAA- -AAAAAAAAAAAAAAAAAA- -----AAAAAAAAAA----- -----AAAAAAAAAA----- -----AAAAAAAAAA----- -----AAAAAAAAAA----- -----AAAAAAAAAA----- -----AAAAAAAAAA----- -----AAAAAAAAAA----- -----AAAAAAAAAA----- -----AAAAAAAAAA----- -----AAAAAAAAAA----- 
-------------------- -------------------- -------------------- ---------BB--------- -------BBBBBB------- ------BBBBBBBB------ ------BBBBBBBB------ -----BBBBBBBBBB----- -----BBBBBBBBBB----- ------BBBBBBBB------ ------BBBBBBBB------ -------BBBBBB------- ---------BB--------- -------------------- --AAAAAAAAAAAAAAAA-- --AAAAAAAAAAAAAAAA-- -------AAAAAA------- -------AAAAAA------- -------AAAAAA------- -------AAAAAA------- -------AAAAAA------- -------AAAAAA------- -------AAAAAA------- -------AAAAAA------- -------AAAAAA------- -------AAAAAA------- 
-------------------- -------------------- -------------------- -------------------- -------------------- ---------BB--------- --------BBBB-------- -------BBBBBB------- -------BBBBBB------- --------BBBB-------- ---------BB--------- -------------------- -------------------- -------------------- ---AAAAAAAAAAAAAA--- ---AAAAAAAAAAAAAA--- -------------------- -------------------- -------------------- -------------------- -------------------- -------------------- -------------------- -------------------- -------------------- -------------------- 
-------------------- -------------------- -------------------- -------------------- -------------------- -------------------- -------------------- -------------------- -------------------- -------------------- -------------------- -------------------- -------------------- -------------------- ----AAAAAAAAAAAA---- ----AAAAAAAAAAAA---- -------------------- -------------------- -------------------- -------------------- -------------------- -------------------- -------------------- -------------------- -------------------- -------------------- 
-------------------- -------------------- -------------------- -------------------- -------------------- -------------------- -------------------- -------------------- -------------------- -------------------- -------------------- -------------------- -------------------- -------------------- ------AAAAAAAA------ ------AAAAAAAA------ -------------------- -------------------- -------------------- -------------------- -------------------- -------------------- -------------------- -------------------- -------------------- -------------------- 
