model
size = 30 31 9, scale = 0.05, origin = -y
material 
  colors = A:#2A4A5B B:#4B4B4B C:#959595 D:#E3E3E3 E:#5E5E5E F:#BBB G:#46647C
voxels
------------------------------ ------------------------------ ------------------------------ ------------------------------ ------------------------------ ------------------------------ ------BBB------------BBBBB---- ----BBBBBB--------BBBBBBB----- ----BBBBBB------BBBBBBBBB----- ----BBBBBB-----BBBBBBBB------- ----BBBBBB---BBBBBBBB--------- ----BBBBBBB-BBBBBBBB---------- ----BBBBBBBBBBBBBB------------ -----BBBBBBBBBBBBBB----------- -----BBBBBBBBBBBBBBBB--------- -----BBBBBBBBBBBBBBBBBBB------ -----BBBBBBBB-BBBBBBBBBBB----- ------BBBBBBB----BBBBBBBBBB--- ------BBBBBBBB-----BBBBBBBB--- ------BBBBBBBBB-----BBBBBBB--- -------BBBBBBBB------BBBBBB--- -------BBBBBBBBBBBBBBBBBBB---- --------BBBBBBBBBBBBBBBBB----- ----------BBBBBBBBBBBBBB------ --------------BBBBBBBB-------- ------------------------------ ------------------------------ ------------------------------ ------------------------------ ------------------------------ ------------------------------ 
--------------AA-------------- ------------AAAAAA------------ ----------AAAAAAAAAA---------- --------AAAAAA--AAAAAA-------- ------AAAAAA------AAAAAA------ ----AAAAAA----------AAAAAA---- ---AAABBB------------BBBBBA--- ---ABBBBBB--------BBBBBBBAA--- ---ABBBBBB------BBBBBBBBBAA--- --AABBBBBB-----BBBBBBBB-AAAA-- --AABBBBBB---BBBBBBBB----AAA-- --AABBBBBBB-BBBBBBBB-----AAA-- --AABBBBBBBBBBBBBB-------AAA-- -AAAABBBBBBBBBBBBBB------AAAA- -AAA-BBBBBBBBBBBBBBBB-----AAA- -AAA-BBBBBBBBBBBBBBBBBBB--AAA- -AAA-BBBBBBBB-BBBBBBBBBBB-AAA- AAAA--BBBBBBB----BBBBBBBBBBAAA AAA---BBBBBBBB-----BBBBBBBBAAA AAA---BBBBBBBB------BBBBBBBAAA AAA----BBBBBBBB------BBBBBBAAA AAA----BBBBBBBBBBBBBBBBBBB-AAA AAAA----BBBBBBBBBBBBBBBBB-AAAA AAAAAA----BBBBBBBBBBBBBBAAAAAA AAAAAAAA------BBBBBBBBAAAAAAAA --AAAAAAAA----------AAAAAAAA-- ----AAAAAAAA------AAAAAAAA---- ------AAAAAAAA--AAAAAAAA------ --------AAAAAAAAAAAAAA-------- ----------AAAAAAAAAA---------- ------------AAAAAA------------ 
--------------AA-------------- ------------AAAAAA------------ ----------AAAAAAAAAA---------- --------AAAAAAFEAAAAAA-------- ------AAAAAAFFDCEEAAAAAA------ ----AAAAAAFFDDDCCCEEAAAAAA---- ---AAAAAFFDDDDDCCCCCEEAAAAA--- ---AAAFFDDDDDDDCCCCCCCEEAAA--- ---AAAFDDDDDDDDCCCCCCCCEAAA--- --AAAAFDDDDDDDDCCCCCCCCCAAAA-- --AAAFDDDDDDDDDCCCCCCCCCECAA-- --AAAFDDDDDDDDDCCCCCCCCCECAA-- --AAAFDDDDDDDDDCCCCCCCCCECAA-- -AAAAFDDDDDDDDDCCCCCCCCCECAAA- -AAAFDDDDDDDDDDCCCCCCCCCCEAAA- -AAAFDDDDDDDDDDCCCCCCCCCCEAAA- -AAAFDDDDDDDDDDCCCCCCCCCCEAAA- AAAAFDDDDDDDDDDCCCCCCCCCCEAAAA AAAFDDDDDDDDDDDCCCCCCCCCCCEAAA AAAFDDDDDDDDDDDCCCCCCCCCCCEAAA AAAFDDDDDDDDDDDCCCCCCCCCCCEAAA AAAFDDDDDDDDDDDCCCCCCCCCCCEAAA AAAAFFDDDDDDDDDCCCCCCCCCEEAAAA AAAAAAFFDDDDDDDCCCCCCCEEAAAAAA AAAAAAAAFFDDDDDCCCCCEEAAAAAAAA --AAAAAAAAFFDDDCCCEEAAAAAAAA-- ----AAAAAAAAFFDCEEAAAAAAAA---- ------AAAAAAAAFEAAAAAAAA------ --------AAAAAAAAAAAAAA-------- ----------AAAAAAAAAA---------- ------------AAAAAA------------ 
--------------AA-------------- ------------AAAAAA------------ ----------AAAAAAAAAA---------- --------AAAAAAAAAAAAAA-------- ------AAAAAAAAAAAAAAAAAA------ ----AAAAAAAAAAAAAAAAAAAAAA---- ---AAAAAAAAAAAAAAAAAAAAAAAA--- ---AAAAAAAAAAAAAAAAAAAAAAAA--- ---AAAAAAAAAAAAAAAAAAAAAAAA--- --AAAAAAAAAAAAAAAAAAAAAAAAAA-- --AAAAAAAAAAAAAAAAAAAAAAAAAA-- --AAAAAAAAAAAAAAAAAAAAAAAAAA-- --AAAAAAAAAAAAAAAAAAAAAAAAAA-- -AAAAAAAAAAAAAAAAAAAAAAAAAAAA- -AAAAAAAAAAAAAAAAAAAAAAAAAAAA- -AAAAAAAAAAAAAAAAAAAAAAAAAAAA- -AAAAAAAAAAAAAAAAAAAAAAAAAAAA- AAAAAAAAAAAAAAAAAAAAAAAAAAAAAA AAAAAAAAAAAAAAAAAAAAAAAAAAAAAA AAAAAAAAAAAAAAAAAAAAAAAAAAAAAA AAAAAAAAAAAAAAAAAAAAAAAAAAAAAA AAAAAAAAAAAAAAAAAAAAAAAAAAAAAA AAAAAAAAAAAAAAAAAAAAAAAAAAAAAA AAAAAAAAAAAAAAAAAAAAAAAAAAAAAA AAAAAAAAAAAAAAAAAAAAAAAAAAAAAA --AAAAAAAAAAAAAAAAAAAAAAAAAA-- ----AAAAAAAAAAAAAAAAAAAAAA---- ------AAAAAAAAAAAAAAAAAA------ --------AAAAAAAAAAAAAA-------- ----------AAAAAAAAAA---------- ------------AAAAAA------------ 
--------------AA-------------- ------------AAAAAA------------ ----------AAAAAAAAAA---------- --------AAAAAAEEAAAAAA-------- ------AAAAAAEECCEEAAAAAA------ ----AAAAAAEEECCFDEEEAAAAAA---- ---AAAAAEECCECCFDECCEEAAAAA--- ---AAAEECCCFECFFDECCCFEEAAA--- ---AAAEECCFFECFFDECCFFEEAAA--- --AAAAEECFFFECFFDECFFFECAAAA-- --AAAECECFFFECFFDECFFFECCCAA-- --AAAECECFFFECFFDECFFFECFCAA-- --AAAECECFFFECFFDECFFFECFCAA-- -AAAAECECFFFECFFDECFFFECFCAAA- -AAAECFECFFFECFFDECFFFECFEAAA- -AAAECFECFFFECFFDECFFFECFEAAA- -AAAECFECFFDECFFDECFFDECFEAAA- AAAAECFECFFDECFFDECFFDECFEAAAA AAAECFDECFFDECFFDECFFDEFFDEAAA AAAECFDECFFDECFFDECFFDEFFDEAAA AAAECFDECFFDECFFDECFFDEFFDEAAA AAAECFDECFFDECFFDECFFDEFFDEAAA AAAAEEDECFFDECFFDECFFDECEEAAAA AAAAAAEECFFDECFFDECFFDEEAAAAAA AAAAAAAAEEFDECFFDECFEEAAAAAAAA --AAAAAAAAEEECFFDEEEAAAAAAAA-- ----AAAAAAAAEEFDEEAAAAAAAA---- ------AAAAAAAAEEAAAAAAAA------ --------AAAAAAAAAAAAAA-------- ----------AAAAAAAAAA---------- ------------AAAAAA------------ 
--------------AA-------------- ------------AAAAAA------------ ----------AAAAAAAAAA---------- --------AAAAAA--AAAAAA-------- ------AAAAAA------AAAAAA------ ----AAAAAA----------AAAAAA---- ---AAAAA--------------AAAAA--- ---AAA------------------AAA--- ---AAA------------------AAA--- --AAAA------------------AAAA-- --AAA--------------------AAA-- --AAA--------------------AAA-- --AAA--------------------AAA-- -AAAA--------------------AAAA- -AAA---EE------------EE---AAA- -AAA---EE------------EE---AAA- -AAA---EE------------EE---AAA- AAAA---EE------------EE---AAAA AAA------------------------AAA AAA------------------------AAA AAA------------------------AAA AAA------------------------AAA AAAA----------------------AAAA AAAAAA------------------AAAAAA AAAAAAAA--------------AAAAAAAA --AAAAAAAA----------AAAAAAAA-- ----AAAAAAAA------AAAAAAAA---- ------AAAAAAAA--AAAAAAAA------ --------AAAAAAAAAAAAAA-------- ----------AAAAAAAAAA---------- ------------AAAAAA------------ 
------------------------------ ------------------------------ ------------------------------ ------------------------------ ------------------------------ ------------------------------ ------------------------------ ------------------------------ ------------------------------ ------------------------------ ------------------------------ ------------------------------ ------------------------------ ------------------------------ --------AA----------AA-------- --------GG----------GG-------- --------GG----------GG-------- --------AA----------AA-------- ------------------------------ ------------------------------ ------------------------------ ------------------------------ ------------------------------ ------------------------------ ------------------------------ ------------------------------ ------------------------------ ------------------------------ ------------------------------ ------------------------------ ------------------------------ 
------------------------------ ------------------------------ ------------------------------ ------------------------------ ------------------------------ ------------------------------ ------------------------------ ------------------------------ ------------------------------ ------------------------------ ------------------------------ ------------------------------ ------------------------------ ------------------------------ ---------AAA------AAA--------- ---------GGG------GGG--------- ---------GGG------GGG--------- ---------AAA------AAA--------- ------------------------------ ------------------------------ ------------------------------ ------------------------------ ------------------------------ ------------------------------ ------------------------------ ------------------------------ ------------------------------ ------------------------------ ------------------------------ ------------------------------ ------------------------------ 
------------------------------ ------------------------------ ------------------------------ ------------------------------ ------------------------------ ------------------------------ ------------------------------ ------------------------------ ------------------------------ ------------------------------ ------------------------------ ------------------------------ ------------------------------ ------------------------------ -----------AAAAAAAA----------- -----------GGGGGGGG----------- -----------GGGGGGGG----------- -----------AAAAAAAA----------- ------------------------------ ------------------------------ ------------------------------ ------------------------------ ------------------------------ ------------------------------ ------------------------------ ------------------------------ ------------------------------ ------------------------------ ------------------------------ ------------------------------ ------------------------------ 
