model
size = 30 31 24, scale = 0.05, origin = -y
material 
  colors = A:#2A4A5B B:#F70 C:#46647C
voxels
------------------------------ ------------------------------ ------------------------------ ------------------------------ ------------------------------ ------------------------------ ------BBB------------BBBBB---- ----BBBBBB--------BBBBBBB----- ----BBBBBB------BBBBBBBBB----- ----BBBBBB-----BBBBBBBB------- ----BBBBBB---BBBBBBBB--------- ----BBBBBBB-BBBBBBBB---------- ----BBBBBBBBBBBBBB------------ -----BBBBBBBBBBBBBB----------- -----BBBBBBBBBBBBBBBB--------- -----BBBBBBBBBBBBBBBBBBB------ -----BBBBBBBB-BBBBBBBBBBB----- ------BBBBBBB----BBBBBBBBBB--- ------BBBBBBBB-----BBBBBBBB--- ------BBBBBBBB------BBBBBBB--- -------BBBBBBBB------BBBBBB--- -------BBBBBBBBBBBBBBBBBBB---- --------BBBBBBBBBBBBBBBBB----- ----------BBBBBBBBBBBBBB------ --------------BBBBBBBB-------- ------------------------------ ------------------------------ ------------------------------ ------------------------------ ------------------------------ ------------------------------ 
------------------------------ ------------------------------ ------------------------------ ------------------------------ ------------------------------ ------------------------------ ------BBB------------BBBBB---- ----BBBBBB--------BBBBBBB----- ----BBBBBB------BBBBBBBBB----- ----BBBBBB-----BBBBBBBB------- ----BBBBBB---BBBBBBBB--------- ----BBBBBBB-BBBBBBBB---------- ----BBBBBBBBBBBBBB------------ -----BBBBBBBBBBBBBB----------- -----BBBBBBBBBBBBBBBB--------- -----BBBBBBBBBBBBBBBBBBB------ -----BBBBBBBBABBBBBBBBBBB----- ------BBBBBBBAAAABBBBBBBBBB--- ------BBBBBBBBAAA--BBBBBBBB--- ------BBBBBBBBAAA---BBBBBBB--- -------BBBBBBBBAA----BBBBBB--- -------BBBBBBBBBBBBBBBBBBB---- --------BBBBBBBBBBBBBBBBB----- ----------BBBBBBBBBBBBBB------ --------------BBBBBBBB-------- ------------------------------ ------------------------------ ------------------------------ ------------------------------ ------------------------------ ------------------------------ 
------------------------------ ------------------------------ ------------------------------ ------------------------------ ------------------------------ ------------------------------ ------BBB------------BBBBB---- ----BBBBBB--------BBBBBBB----- ----BBBBBB---AAABBBBBBBBB----- ----BBBBBB---AABBBBBBBB------- ----BBBBBB---BBBBBBBB--------- ----BBBBBBB-BBBBBBBB---------- ----BBBBBBBBBBBBBB------------ -----BBBBBBBBBBBBBBA---------- -----BBBBBBBBBBBBBBBB--------- -----BBBBBBBBBBBBBBBBBBB------ -----BBBBBBBB-BBBBBBBBBBB----- ------BBBBBBB----BBBBBBBBBB--- ------BBBBBBB----AABBBBBBBB--- ------BBBBBBB----AAABBBBBBB--- -------BBBBBB----AAA-BBBBBB--- -------BBBBBB----BBBBBBBBB---- --------BBBBB----BBBBBBBB----- ----------BBB----BBBBBBB------ -------------ABBBBBBBB-------- -------------AAAA------------- ------------------------------ ------------------------------ ------------------------------ ------------------------------ ------------------------------ 
--------------AA-------------- -------------AAAA------------- -------------AAAA------------- -------------AAAA------------- -------------AAAA------------- -------------AAAA------------- ------BBB----AAAA----BBBBB---- ----BBBBBB---AAAA-BBBBBBB----- ----BBBBBBAAA----BBBBBBBB----- ----BBBBBBAAA----BBBBBB------- ----BBBBBBAAA----BBBB--------- ----BBBBBBBAB----BBB---------- ----BBBBBBBBB----BAA---------- -----BBBBB-------BB-AA-------- -----BBBBB-------BBBBA-------- -----BBBBB-------BBBBBBB------ -----BBBBB-------BBBBBBBB----- ------BBBB-------BBBBBBBBBB--- ------BBBB---------BBBBBBBB--- ------BBBB----------BBBBBBB--- -------BBB----------ABBBBBB--- -------BBB----------BBBBBB---- --------BB----------BBBBB----- --------------------BBBB------ ----------AAA----BBBBB-------- ----------AAA----AAA---------- -------------AAAA------------- -------------AAAA------------- -------------AAAA------------- -------------AAAA------------- -------------AAAA------------- 
--------------AA-------------- ------------AAAAAA------------ ----------AAAAAAAAAA---------- ----------AAAA--AAAA---------- ----------AAA----AAA---------- ----------AAA----AAA---------- ------BBB-AAA----AAA-BBBBB---- ----BBBBBBAAA----ABBBBBBB----- ----BBBB------------BBBBB----- ----BBBB------------BBB------- ----BBBB------------BA-------- ----BBBB------------AA-------- ----BBBB------------AA-------- ----ABB---------------AAAA---- ----ABB---------------AAAA---- ----ABB---------------BBAA---- ----ABB---------------BBBA---- ----AAB---------------BBBBB--- ----AAB---------------BBBBB--- ----AAB---------------BBBBB--- ----AAA---------------BBBBB--- ----AAA---------------BBBB---- ----AAAA--------------BBBA---- --------AA------------BB------ --------AA----------BB-------- --------AA----------AA-------- ----------AAA----AAA---------- ----------AAAA--AAAA---------- ----------AAAAAAAAAA---------- ----------AAAAAAAAAA---------- ------------AAAAAA------------ 
------------------------------ ------------A----A------------ ----------AAA----AAA---------- --------AAAAA----AAAAA-------- --------AAAA------AAAA-------- --------AA----------AA-------- --------AA----------AA-------- --------AA----------AA-------- ----AAAA--------------AAAA---- ----AAAA--------------AAAA---- ----AAAA--------------AAAA---- ----AAAA--------------AAAA---- ----AAAA--------------AAAA---- -AAAA---------------------AAA- -AAA----------------------AAA- -AAA----------------------AAA- -AAA----------------------AAA- AAAA----------------------AAAA AAAA----------------------AAAA AAAA----------------------AAAA AAAA----------------------AAAA AAAA----------------------AAAA AAAA----------------------AAAA ----AAAA--------------AAAA---- ----AAAA--------------AAAA---- ----AAAAAA----------AAAAAA---- --------AAAA------AAAA-------- --------AAAAA----AAAAA-------- --------AAAAA----AAAAA-------- ----------AAA----AAA---------- ------------A----A------------ 
------------------------------ ------------------------------ ------------------------------ --------AA----------AA-------- ------AAAA----------AAAA------ ----AAAAAA----------AAAAAA---- ----AAAA--------------AAAA---- ----AAAA--------------AAAA---- ---AAA------------------AAA--- --AAAA------------------AAAA-- --AAA---------------------AA-- --AAA---------------------AA-- --AAA---------------------AA-- -AAA----------------------AAA- -AAA----------------------AAA- -AAA----------------------AAA- -AAA----------------------AAA- AAAA----------------------AAAA AAA------------------------AAA AAA------------------------AAA AAA------------------------AAA AAA------------------------AAA AAAA----------------------AAAA AAAAAA------------------AAAAAA AAAAAAAA--------------AAAAAAAA --AAAAAA--------------AAAAAA-- ----AAAAAA----------AAAAAA---- ------AAAA----------AAAA------ --------AA----------AA-------- ------------------------------ ------------------------------ 
------------------------------ ------------------------------ ------------------------------ ------------------------------ ------AA--------------AA------ ----AAAA--------------AAAA---- ---AAAAA--------------AAAAA--- ---AAA------------------AAA--- ---A----------------------A--- --AA----------------------AA-- --AA----------------------AA-- --AA----------------------AA-- --AA----------------------AA-- --AA----------------------AA-- --AA----------------------AA-- --AA----------------------AA-- --AA----------------------AA-- -AA------------------------AA- -AA------------------------AA- -AA------------------------AA- -AA------------------------AA- -AA------------------------AA- -AA------------------------AA- AAAA----------------------AAAA AAAA----------------------AAAA --AA----------------------AA-- ----AAAA--------------AAAA---- ------AA--------------AA------ ------------------------------ ------------------------------ ------------------------------ 
------------------------------ ------------------------------ ------------------------------ ------------------------------ ------------------------------ ------------------------------ ---A----------------------A--- ---A----------------------A--- ---A----------------------A--- --AA----------------------AA-- --AA----------------------AA-- --AA----------------------AA-- --AA----------------------AA-- --AA----------------------AA-- --AA----------------------AA-- --AA----------------------AA-- --AA----------------------AA-- -AA------------------------AA- -AA------------------------AA- -AA------------------------AA- -AA------------------------AA- -AA------------------------AA- -AA------------------------AA- AAA------------------------AAA AAA------------------------AAA ------------------------------ ------------------------------ ------------------------------ ------------------------------ ------------------------------ ------------------------------ 
------------------------------ ------------------------------ ------------------------------ ------------------------------ ------------------------------ ------------------------------ ---A----------------------A--- ---A----------------------A--- ---A----------------------A--- --AA----------------------AA-- --AA----------------------AA-- --AA----------------------AA-- --AA----------------------AA-- --AA----------------------AA-- --AA----------------------AA-- --AA----------------------AA-- --AA----------------------AA-- -AA------------------------AA- -AA------------------------AA- -AA------------------------AA- -AA------------------------AA- -AA------------------------AA- -AA------------------------AA- AAA------------------------AAA AAA------------------------AAA ------------------------------ ------------------------------ ------------------------------ ------------------------------ ------------------------------ ------------------------------ 
------------------------------ ------------------------------ ------------------------------ ------------------------------ ------------------------------ ------------------------------ ---A----------------------A--- ---A----------------------A--- ---A----------------------A--- --AA----------------------AA-- --AA----------------------AA-- --AA----------------------AA-- --AA----------------------AA-- --AA----------------------AA-- --AA----------------------AA-- --AA----------------------AA-- --AA----------------------AA-- -AA------------------------AA- -AA------------------------AA- -AA------------------------AA- -AA------------------------AA- -AA------------------------AA- -AA------------------------AA- AAA------------------------AAA AAA------------------------AAA ------------------------------ ------------------------------ ------------------------------ ------------------------------ ------------------------------ ------------------------------ 
------------------------------ ------------------------------ ------------------------------ ------------------------------ ------------------------------ ------------------------------ ---A----------------------A--- ---A----------------------A--- ---A----------------------A--- --AA----------------------AA-- --AA----------------------AA-- --AA----------------------AA-- --AA----------------------AA-- --AA----------------------AA-- --AA----------------------AA-- --AA----------------------AA-- --AA----------------------AA-- -AA------------------------AA- -AA------------------------AA- -AA------------------------AA- -AA------------------------AA- -AA------------------------AA- -AA------------------------AA- AAA------------------------AAA AAA------------------------AAA ------------------------------ ------------------------------ ------------------------------ ------------------------------ ------------------------------ ------------------------------ 
------------------------------ ------------------------------ ------------------------------ ------------------------------ ------------------------------ ------------------------------ ------------------------------ ---A----------------------A--- ---A----------------------A--- --AA----------------------AA-- --AA----------------------AA-- --AA----------------------AA-- --AA----------------------AA-- --AA----------------------AA-- --AA----------------------AA-- --AA----------------------AA-- --AA----------------------AA-- -AA------------------------AA- -AA------------------------AA- -AA------------------------AA- -AA------------------------AA- -AA------------------------AA- -AA------------------------AA- AAA------------------------AAA AAA------------------------AAA ------------------------------ ------------------------------ ------------------------------ ------------------------------ ------------------------------ ------------------------------ 
------------------------------ ------------------------------ ------------------------------ ------------------------------ ------------------------------ ------------------------------ ------------------------------ ---A----------------------A--- ---A----------------------A--- --AA----------------------AA-- --AA----------------------AA-- --AA----------------------AA-- --AA----------------------AA-- --AA----------------------AA-- --AA----------------------AA-- --AA----------------------AA-- --AA----------------------AA-- -AA------------------------AA- -AA------------------------AA- -AA------------------------AA- -AA------------------------AA- -AA------------------------AA- -AA------------------------AA- AAA------------------------AAA AAA------------------------AAA ------------------------------ ------------------------------ ------------------------------ ------------------------------ ------------------------------ ------------------------------ 
------------------------------ ------------------------------ ------------------------------ ------------------------------ ------------------------------ ------------------------------ ------------------------------ ---A----------------------A--- ---A----------------------A--- --AA----------------------AA-- --AA----------------------AA-- --AA----------------------AA-- --AA----------------------AA-- --AA----------------------AA-- --AA----------------------AA-- --AA----------------------AA-- --AA----------------------AA-- -AA------------------------AA- -AA------------------------AA- -AA------------------------AA- -AA------------------------AA- -AA------------------------AA- -AA------------------------AA- AAA------------------------AAA AAA------------------------AAA ------------------------------ ------------------------------ ------------------------------ ------------------------------ ------------------------------ ------------------------------ 
------------------------------ ------------------------------ ------------------------------ ------------------------------ ------------------------------ ------------------------------ ------------------------------ ---A----------------------A--- ---A----------------------A--- --AA----------------------AA-- --AA----------------------AA-- --CA----------------------AC-- --CA----------------------AC-- --CA----------------------AC-- --CA----------------------AC-- --AA----------------------AA-- --AA----------------------AA-- -AA------------------------AA- -AA------------------------AA- -CA------------------------AC- -CA------------------------AC- -AA------------------------AA- -AA------------------------AA- AAA------------------------AAA AAA------------------------AAA ------------------------------ ------------------------------ ------------------------------ ------------------------------ ------------------------------ ------------------------------ 
------------------------------ ------------------------------ ------------------------------ ------------------------------ ------------------------------ ------------------------------ ------------------------------ ---A----------------------A--- ---A----------------------A--- --AA----------------------AA-- --CA----------------------AC-- ------------------------------ ------------------------------ ------------------------------ ------------------------------ --CA----------------------AC-- --AA----------------------AA-- -AA------------------------AA- -CA------------------------AC- ------------------------------ ------------------------------ -CA------------------------AC- -AA------------------------AA- AAA------------------------AAA AAA------------------------AAA ------------------------------ ------------------------------ ------------------------------ ------------------------------ ------------------------------ ------------------------------ 
------------------------------ ------------------------------ ------------------------------ ------------------------------ ------------------------------ ------------------------------ ------------------------------ ------------------------------ ---A----------------------A--- --CA----------------------AC-- ------------------------------ ------------------------------ ------------------------------ ------------------------------ ------------------------------ ------------------------------ --CA----------------------AC-- -CA------------------------AC- ------------------------------ ------------------------------ ------------------------------ ------------------------------ -CA------------------------AC- AAA------------------------AAA AAA------------------------AAA ------------------------------ ------------------------------ ------------------------------ ------------------------------ ------------------------------ ------------------------------ 
------------------------------ ------------------------------ ------------------------------ ------------------------------ ------------------------------ ------------------------------ ------------------------------ ------------------------------ ---A----------------------A--- --CA----------------------AC-- ------------------------------ ------------------------------ ------------------------------ ------------------------------ ------------------------------ ------------------------------ --CA----------------------AC-- -CA------------------------AC- ------------------------------ ------------------------------ ------------------------------ ------------------------------ -CA------------------------AC- AAA------------------------AAA AAA------------------------AAA ------------------------------ ------------------------------ ------------------------------ ------------------------------ ------------------------------ ------------------------------ 
------------------------------ ------------------------------ ------------------------------ ------------------------------ ------------------------------ ------------------------------ ------------------------------ ------------------------------ ---A----------------------A--- --CA----------------------AC-- ------------------------------ ------------------------------ ------------------------------ ------------------------------ ------------------------------ ------------------------------ --CA----------------------AC-- -CA------------------------AC- ------------------------------ ------------------------------ ------------------------------ ------------------------------ -CA------------------------AC- AAA------------------------AAA AAA------------------------AAA ------------------------------ ------------------------------ ------------------------------ ------------------------------ ------------------------------ ------------------------------ 
------------------------------ ------------------------------ ------------------------------ ------------------------------ ------------------------------ ------------------------------ ------------------------------ ------------------------------ ---A----------------------A--- --CA----------------------AC-- ------------------------------ ------------------------------ ------------------------------ ------------------------------ ------------------------------ ------------------------------ --CA----------------------AC-- -CA------------------------AC- ------------------------------ ------------------------------ ------------------------------ ------------------------------ -CA------------------------AC- AAA------------------------AAA AAA------------------------AAA ------------------------------ ------------------------------ ------------------------------ ------------------------------ ------------------------------ ------------------------------ 
------------------------------ ------------------------------ ------------------------------ ------------------------------ ------------------------------ ------------------------------ ------------------------------ ------------------------------ ------------------------------ --AA----------------------AA-- --CA----------------------AC-- ------------------------------ ------------------------------ ------------------------------ ------------------------------ --CA----------------------AC-- --AA----------------------AA-- -AA------------------------AA- -CA------------------------AC- ------------------------------ ------------------------------ -CA------------------------AC- -AA------------------------AA- ------------------------------ ------------------------------ ------------------------------ ------------------------------ ------------------------------ ------------------------------ ------------------------------ ------------------------------ 
------------------------------ ------------------------------ ------------------------------ ------------------------------ ------------------------------ ------------------------------ ------------------------------ ------------------------------ ------------------------------ ------------------------------ --AA----------------------AA-- --CA----------------------AC-- --CA----------------------AC-- --CA----------------------AC-- --CA----------------------AC-- --AA----------------------AA-- ------------------------------ ------------------------------ -AA------------------------AA- -CA------------------------AC- -CA------------------------AC- -AA------------------------AA- ------------------------------ ------------------------------ ------------------------------ ------------------------------ ------------------------------ ------------------------------ ------------------------------ ------------------------------ ------------------------------ 
------------------------------ ------------------------------ ------------------------------ ------------------------------ ------------------------------ ------------------------------ ------------------------------ ------------------------------ ------------------------------ ------------------------------ ------------------------------ ------------------------------ ------------------------------ ------------------------------ ------------------------------ ------------------------------ ------------------------------ ------------------------------ ------------------------------ -AA------------------------AA- -AA------------------------AA- ------------------------------ ------------------------------ ------------------------------ ------------------------------ ------------------------------ ------------------------------ ------------------------------ ------------------------------ ------------------------------ ------------------------------ 
