model
size = 30 31 9, scale = 0.05, origin = -y
material 
  colors = A:#777 B:#C80000 C:#004 D:#39C E:#007 F:#002 G:#005 H:#888 I:#F3C J:#FF0 K:#FC6 L:#FCC M:#F3F N:#FCF O:#FF3 P:#FF9 Q:#FFF R:#F6F S:#FFC
voxels
------------------------------ ------------------------------ ------------------------------ ------------------------------ ------------------------------ ------------------------------ ------BBB------------BBBBB---- ----BBBBBB--------BBBBBBB----- ----BBBBBB------BBBBBBBBB----- ----BBBBBB-----BBBBBBBB------- ----BBBBBB---BBBBBBBB--------- ----BBBBBBB-BBBBBBBB---------- ----BBBBBBBBBBBBBB------------ -----BBBBBBBBBBBBBB----------- -----BBBBBBBBBBBBBBBB--------- -----BBBBBBBBBBBBBBBBBBB------ -----BBBBBBBB-BBBBBBBBBBB----- ------BBBBBBB----BBBBBBBBBB--- ------BBBBBBBB-----BBBBBBBB--- ------BBBBBBBBB-----BBBBBBB--- -------BBBBBBBB------BBBBBB--- -------BBBBBBBBBBBBBBBBBBB---- --------BBBBBBBBBBBBBBBBB----- ----------BBBBBBBBBBBBBB------ --------------BBBBBBBB-------- ------------------------------ ------------------------------ ------------------------------ ------------------------------ ------------------------------ ------------------------------ 
--------------AA-------------- ------------AAAAAA------------ ----------AAAAAAAAAA---------- --------AAAAAA--AAAAAA-------- ------AAAAAA------AAAAAA------ ----AAAAAA----------AAAAAA---- ---AAABJP------------BDDDDA--- ---ADDDDDB--------QDDDDDDAA--- ---ADDDDDI------JDDDDDDDJAA--- --AADDDDDD-----DDDDDDDK-AAAA-- --AADDDDDD---KDDDDDDD----AAA-- --AAIDDDDDI-DDDDDDDQ-----AAA-- --AALDDDDDDDDDDDDD-------AAA-- -AAAADDDDDDDDDDDDIB------AAAA- -AAA-DDDDDDDDDDDDDDDM-----AAA- -AAA-DDDDDDDDDDDDDDDDDDL--AAA- -AAA-LDDDDDDD-BKDDDDDDDDD-AAA- AAAA--DDDDDDD----LDDDDDDDDOAAA AAA---DDDDDDDR-----PDDDDDDDAAA AAA---NDDDDDDD------NDDDDDDAAA AAA----DDDDDDDM------DDDDDDAAA AAA----KDDDDDDDDDDDDDDDDDD-AAA AAAA----DDDDDDDDDDDDDDDDD-AAAA AAAAAA----NIDDDDDDDDDDDMAAAAAA AAAAAAAA------OSIDDDIJAAAAAAAA --AAAAAAAA----------AAAAAAAA-- ----AAAAAAAA------AAAAAAAA---- ------AAAAAAAA--AAAAAAAA------ --------AAAAAAAAAAAAAA-------- ----------AAAAAAAAAA---------- ------------AAAAAA------------ 
--------------AA-------------- ------------AAAAAA------------ ----------AAAAAAAAAA---------- --------AAAAAAGFAAAAAA-------- ------AAAAAAGGECFFAAAAAA------ ----AAAAAAGGEEECCCFFAAAAAA---- ---AAAAAGGEEEEECCCCCFFAAAAA--- ---AAAGGEEEEEEECCCCCCCFFAAA--- ---AAAGEEEEEEEECCCCCCCCFAAA--- --AAAAGEEEEEEEECCCCCCCCCAAAA-- --AAAGEEEEEEEEECCCCCCCCCFCAA-- --AAAGEEEEEEEEECCCCCCCCCFCAA-- --AAAGEEEEEEEEECCCCCCCCCFCAA-- -AAAAGEEEEEEEEECCCCCCCCCFCAAA- -AAAGEEEEEEEEEECCCCCCCCCCFAAA- -AAAGEEEEEEEEEECCCCCCCCCCFAAA- -AAAGEEEEEEEEEECCCCCCCCCCFAAA- AAAAGEEEEEEEEEECCCCCCCCCCFAAAA AAAGEEEEEEEEEEECCCCCCCCCCCFAAA AAAGEEEEEEEEEEECCCCCCCCCCCFAAA AAAGEEEEEEEEEEECCCCCCCCCCCFAAA AAAGEEEEEEEEEEECCCCCCCCCCCFAAA AAAAGGEEEEEEEEECCCCCCCCCFFAAAA AAAAAAGGEEEEEEECCCCCCCFFAAAAAA AAAAAAAAGGEEEEECCCCCFFAAAAAAAA --AAAAAAAAGGEEECCCFFAAAAAAAA-- ----AAAAAAAAGGECFFAAAAAAAA---- ------AAAAAAAAGFAAAAAAAA------ --------AAAAAAAAAAAAAA-------- ----------AAAAAAAAAA---------- ------------AAAAAA------------ 
--------------AA-------------- ------------AAAAAA------------ ----------AAAAAAAAAA---------- --------AAAAAAAAAAAAAA-------- ------AAAAAAAAAAAAAAAAAA------ ----AAAAAAAAAAAAAAAAAAAAAA---- ---AAAAAAAAAAAAAAAAAAAAAAAA--- ---AAAAAAAAAAAAAAAAAAAAAAAA--- ---AAAAAAAAAAAAAAAAAAAAAAAA--- --AAAAAAAAAAAAAAAAAAAAAAAAAA-- --AAAAAAAAAAAAAAAAAAAAAAAAAA-- --AAAAAAAAAAAAAAAAAAAAAAAAAA-- --AAAAAAAAAAAAAAAAAAAAAAAAAA-- -AAAAAAAAAAAAAAAAAAAAAAAAAAAA- -AAAAAAAAAAAAAAAAAAAAAAAAAAAA- -AAAAAAAAAAAAAAAAAAAAAAAAAAAA- -AAAAAAAAAAAAAAAAAAAAAAAAAAAA- AAAAAAAAAAAAAAAAAAAAAAAAAAAAAA AAAAAAAAAAAAAAAAAAAAAAAAAAAAAA AAAAAAAAAAAAAAAAAAAAAAAAAAAAAA AAAAAAAAAAAAAAAAAAAAAAAAAAAAAA AAAAAAAAAAAAAAAAAAAAAAAAAAAAAA AAAAAAAAAAAAAAAAAAAAAAAAAAAAAA AAAAAAAAAAAAAAAAAAAAAAAAAAAAAA AAAAAAAAAAAAAAAAAAAAAAAAAAAAAA --AAAAAAAAAAAAAAAAAAAAAAAAAA-- ----AAAAAAAAAAAAAAAAAAAAAA---- ------AAAAAAAAAAAAAAAAAA------ --------AAAAAAAAAAAAAA-------- ----------AAAAAAAAAA---------- ------------AAAAAA------------ 
--------------AA-------------- ------------AAAAAA------------ ----------AAAAAAAAAA---------- --------AAAAAAFFAAAAAA-------- ------AAAAAAFFCCFFAAAAAA------ ----AAAAAAFFFCCGEFFFAAAAAA---- ---AAAAAFFCCFCCGEFCCFFAAAAA--- ---AAAFFCCCGFCGGEFCCCGFFAAA--- ---AAAFFCCGGFCGGEFCCGGFFAAA--- --AAAAFFCGGGFCGGEFCGGGFCAAAA-- --AAAFCFCGGGFCGGEFCGGGFCCCAA-- --AAAFCFCGGGFCGGEFCGGGFCGCAA-- --AAAFCFCGGGFCGGEFCGGGFCGCAA-- -AAAAFCFCGGGFCGGEFCGGGFCGCAAA- -AAAFCGFCGGGFCGGEFCGGGFCGFAAA- -AAAFCGFCGGGFCGGEFCGGGFCGFAAA- -AAAFCGFCGGEFCGGEFCGGEFCGFAAA- AAAAFCGFCGGEFCGGEFCGGEFCGFAAAA AAAFCGEFCGGEFCGGEFCGGEFGGEFAAA AAAFCGEFCGGEFCGGEFCGGEFGGEFAAA AAAFCGEFCGGEFCGGEFCGGEFGGEFAAA AAAFCGEFCGGEFCGGEFCGGEFGGEFAAA AAAAFFEFCGGEFCGGEFCGGEFCFFAAAA AAAAAAFFCGGEFCGGEFCGGEFFAAAAAA AAAAAAAAFFGEFCGGEFCGFFAAAAAAAA --AAAAAAAAFFFCGGEFFFAAAAAAAA-- ----AAAAAAAAFFGEFFAAAAAAAA---- ------AAAAAAAAFFAAAAAAAA------ --------AAAAAAAAAAAAAA-------- ----------AAAAAAAAAA---------- ------------AAAAAA------------ 
--------------AA-------------- ------------AAAAAA------------ ----------AAAAAAAAAA---------- --------AAAAAA--AAAAAA-------- ------AAAAAA------AAAAAA------ ----AAAAAA----------AAAAAA---- ---AAAAA--------------AAAAA--- ---AAA------------------AAA--- ---AAA------------------AAA--- --AAAA------------------AAAA-- --AAA--------------------AAA-- --AAA--------------------AAA-- --AAA--------------------AAA-- -AAAA--------------------AAAA- -AAA---FF------------FF---AAA- -AAA---FF------------FF---AAA- -AAA---FF------------FF---AAA- AAAA---FF------------FF---AAAA AAA------------------------AAA AAA------------------------AAA AAA------------------------AAA AAA------------------------AAA AAAA----------------------AAAA AAAAAA------------------AAAAAA AAAAAAAA--------------AAAAAAAA --AAAAAAAA----------AAAAAAAA-- ----AAAAAAAA------AAAAAAAA---- ------AAAAAAAA--AAAAAAAA------ --------AAAAAAAAAAAAAA-------- ----------AAAAAAAAAA---------- ------------AAAAAA------------ 
------------------------------ ------------------------------ ------------------------------ ------------------------------ ------------------------------ ------------------------------ ------------------------------ ------------------------------ ------------------------------ ------------------------------ ------------------------------ ------------------------------ ------------------------------ ------------------------------ --------AA----------AA-------- --------HH----------HH-------- --------HH----------HH-------- --------AA----------AA-------- ------------------------------ ------------------------------ ------------------------------ ------------------------------ ------------------------------ ------------------------------ ------------------------------ ------------------------------ ------------------------------ ------------------------------ ------------------------------ ------------------------------ ------------------------------ 
------------------------------ ------------------------------ ------------------------------ ------------------------------ ------------------------------ ------------------------------ ------------------------------ ------------------------------ ------------------------------ ------------------------------ ------------------------------ ------------------------------ ------------------------------ ------------------------------ ---------AAA------AAA--------- ---------HHH------HHH--------- ---------HHH------HHH--------- ---------AAA------AAA--------- ------------------------------ ------------------------------ ------------------------------ ------------------------------ ------------------------------ ------------------------------ ------------------------------ ------------------------------ ------------------------------ ------------------------------ ------------------------------ ------------------------------ ------------------------------ 
------------------------------ ------------------------------ ------------------------------ ------------------------------ ------------------------------ ------------------------------ ------------------------------ ------------------------------ ------------------------------ ------------------------------ ------------------------------ ------------------------------ ------------------------------ ------------------------------ -----------AAAAAAAA----------- -----------HHHHHHHH----------- -----------HHHHHHHH----------- -----------AAAAAAAA----------- ------------------------------ ------------------------------ ------------------------------ ------------------------------ ------------------------------ ------------------------------ ------------------------------ ------------------------------ ------------------------------ ------------------------------ ------------------------------ ------------------------------ ------------------------------ 
