model
size = 30 31 24, scale = 0.05, origin = -y
material 
  colors = A:#2A4A5B B:#4B4B4B C:#46647C
voxels
------------------------------ ------------------------------ ------------------------------ ------------------------------ ------------------------------ ------------------------------ ------------------------------ ------------------------------ ------------------------------ ------------------------------ ---BBBBBBBBB------BBBBBBBB---- ---BBBBBBBBBBB---BBBBBBBBBB--- -BBBBBBBBBBBBBB--BBBBBBBBBBB-- -BBBBBBBBBBBBBB--BBBBBBBBBBB-- -BBBB-BBBB-BBBB----------BBB-- -BBBB-BBBB-BBBB---BBBBBBBBBB-- -BBBB-BBBB-BBBB---BBBBBBBBBB-- -BBBB-BBBB-BBBB---BBBBBBBBBB-- -BBBB-BBBB-BBBB---BBBBBBBBBB-- -BBBB-BBBB-BBBB----------BBB-- -BBBB-BBBB-BBBB--BBBBBBBBBBB-- -BBBB-BBBB-BBBB--BBBBBBBBBBB-- -BBBB-BBBB-BBBB--BBBBBBBBB---- ------------------------------ ------------------------------ ------------------------------ ------------------------------ ------------------------------ ------------------------------ ------------------------------ ------------------------------ 
------------------------------ ------------------------------ ------------------------------ ------------------------------ ------------------------------ ------------------------------ ------------------------------ ------------------------------ ------------------------------ ------------------------------ ---BBBBBBBBB------BBBBBBBB---- ---BBBBBBBBBBB---BBBBBBBBBB--- -BBBBBBBBBBBBBB--BBBBBBBBBBB-- -BBBBBBBBBBBBBBAABBBBBBBBBBB-- -BBBB-BBBB-BBBBAA--------BBB-- -BBBB-BBBB-BBBBAA-BBBBBBBBBB-- -BBBB-BBBB-BBBBAA-BBBBBBBBBB-- -BBBB-BBBB-BBBBAA-BBBBBBBBBB-- -BBBB-BBBB-BBBBAA-BBBBBBBBBB-- -BBBB-BBBB-BBBBAA--------BBB-- -BBBB-BBBB-BBBBAABBBBBBBBBBB-- -BBBB-BBBB-BBBBAABBBBBBBBBBB-- -BBBB-BBBB-BBBBAABBBBBBBBB---- ------------------------------ ------------------------------ ------------------------------ ------------------------------ ------------------------------ ------------------------------ ------------------------------ ------------------------------ 
------------------------------ ------------------------------ ------------------------------ ------------------------------ ------------------------------ ------------------------------ ------------------------------ ------------------------------ -------------AAAA------------- -------------AAAA------------- ---BBBBBBBBB-AAAA-BBBBBBBB---- ---BBBBBBBBBBBAAABBBBBBBBBB--- -BBBBBBBBBBBBBBAABBBBBBBBBBB-- -BBBBBBBBBBBB----BBBBBBBBBBB-- -BBBB-BBBBABB----AAA-----BBB-- -BBBB-BBBBABB----ABBBBBBBBBB-- -BBBB-BBBBABB----ABBBBBBBBBB-- -BBBB-BBBBABB----ABBBBBBBBBB-- -BBBB-BBBBABB----ABBBBBBBBBB-- -BBBB-BBBBABB----AAA-----BBB-- -BBBB-BBBBABB----BBBBBBBBBBB-- -BBBB-BBBBABB----BBBBBBBBBBB-- -BBBB-BBBBABB----BBBBBBBBB---- -------------AAAA------------- -------------AAAA------------- -------------AAAA------------- ------------------------------ ------------------------------ ------------------------------ ------------------------------ ------------------------------ 
--------------AA-------------- -------------AAAA------------- -------------AAAA------------- -------------AAAA------------- -------------AAAA------------- -------------AAAA------------- -------------AAAA------------- -------------AAAA------------- ----------AAA----AAA---------- ----------AAA----AAA---------- ---BBBBBBBBBA----ABBBBBBBB---- ---BBBBBBBBBB-------BBBBBBB--- -BBBBBBBBBBBB-------BBBBBBBB-- -BBBBBBBBB----------BBBBBBBB-- -BBBB-BBBB----------AA---BBB-- -BBBB-BBBB----------BBBBBBBB-- -BBBB-BBBB----------BBBBBBBB-- -BBBB-BBBB----------BBBBBBBB-- -BBBB-BBBB----------BBBBBBBB-- -BBBB-BBBB----------AA---BBB-- -BBBB-BBBB----------BBBBBBBB-- -BBBB-BBBB----------BBBBBBBB-- -BBBB-BBBB----------BBBBBB---- ----------AAA----AAA---------- ----------AAA----AAA---------- ----------AAA----AAA---------- -------------AAAA------------- -------------AAAA------------- -------------AAAA------------- -------------AAAA------------- -------------AAAA------------- 
--------------AA-------------- ------------AAAAAA------------ ----------AAAAAAAAAA---------- ----------AAAA--AAAA---------- ----------AAA----AAA---------- ----------AAA----AAA---------- ----------AAA----AAA---------- ----------AAA----AAA---------- --------AA----------AA-------- --------AA----------AA-------- ---BBBBBBB----------BBBBBB---- ---BBBBBBB------------BBBBB--- -BBBBBBBBB------------BBBBBB-- -BBBBBBB--------------BBBBBB-- -BBBBABB--------------AAABBB-- -BBBBABB--------------BBBBBB-- -BBBBABB--------------BBBBBB-- -BBBBABB--------------BBBBBB-- -BBBBABB--------------BBBBBB-- -BBBBABB--------------AAABBB-- -BBBBABB--------------BBBBBB-- -BBBBABB--------------BBBBBB-- -BBBBABB--------------BBBB---- --------AA----------AA-------- --------AA----------AA-------- --------AA----------AA-------- ----------AAA----AAA---------- ----------AAAA--AAAA---------- ----------AAAAAAAAAA---------- ----------AAAAAAAAAA---------- ------------AAAAAA------------ 
------------------------------ ------------A----A------------ ----------AAA----AAA---------- --------AAAAA----AAAAA-------- --------AAAA------AAAA-------- --------AA----------AA-------- --------AA----------AA-------- --------AA----------AA-------- ----AAAA--------------AAAA---- ----AAAA--------------AAAA---- ----AAAA--------------AAAA---- ----AAAA--------------AAAA---- ----AAAA--------------AAAA---- -AAAA---------------------AAA- -AAA----------------------AAA- -AAA----------------------AAA- -AAA----------------------AAA- AAAA----------------------AAAA AAAA----------------------AAAA AAAA----------------------AAAA AAAA----------------------AAAA AAAA----------------------AAAA AAAA----------------------AAAA ----AAAA--------------AAAA---- ----AAAA--------------AAAA---- ----AAAAAA----------AAAAAA---- --------AAAA------AAAA-------- --------AAAAA----AAAAA-------- --------AAAAA----AAAAA-------- ----------AAA----AAA---------- ------------A----A------------ 
------------------------------ ------------------------------ ------------------------------ --------AA----------AA-------- ------AAAA----------AAAA------ ----AAAAAA----------AAAAAA---- ----AAAA--------------AAAA---- ----AAAA--------------AAAA---- ---AAA------------------AAA--- --AAAA------------------AAAA-- --AAA---------------------AA-- --AAA---------------------AA-- --AAA---------------------AA-- -AAA----------------------AAA- -AAA----------------------AAA- -AAA----------------------AAA- -AAA----------------------AAA- AAAA----------------------AAAA AAA------------------------AAA AAA------------------------AAA AAA------------------------AAA AAA------------------------AAA AAAA----------------------AAAA AAAAAA------------------AAAAAA AAAAAAAA--------------AAAAAAAA --AAAAAA--------------AAAAAA-- ----AAAAAA----------AAAAAA---- ------AAAA----------AAAA------ --------AA----------AA-------- ------------------------------ ------------------------------ 
------------------------------ ------------------------------ ------------------------------ ------------------------------ ------AA--------------AA------ ----AAAA--------------AAAA---- ---AAAAA--------------AAAAA--- ---AAA------------------AAA--- ---A----------------------A--- --AA----------------------AA-- --AA----------------------AA-- --AA----------------------AA-- --AA----------------------AA-- --AA----------------------AA-- --AA----------------------AA-- --AA----------------------AA-- --AA----------------------AA-- -AA------------------------AA- -AA------------------------AA- -AA------------------------AA- -AA------------------------AA- -AA------------------------AA- -AA------------------------AA- AAAA----------------------AAAA AAAA----------------------AAAA --AA----------------------AA-- ----AAAA--------------AAAA---- ------AA--------------AA------ ------------------------------ ------------------------------ ------------------------------ 
------------------------------ ------------------------------ ------------------------------ ------------------------------ ------------------------------ ------------------------------ ---A----------------------A--- ---A----------------------A--- ---A----------------------A--- --AA----------------------AA-- --AA----------------------AA-- --AA----------------------AA-- --AA----------------------AA-- --AA----------------------AA-- --AA----------------------AA-- --AA----------------------AA-- --AA----------------------AA-- -AA------------------------AA- -AA------------------------AA- -AA------------------------AA- -AA------------------------AA- -AA------------------------AA- -AA------------------------AA- AAA------------------------AAA AAA------------------------AAA ------------------------------ ------------------------------ ------------------------------ ------------------------------ ------------------------------ ------------------------------ 
------------------------------ ------------------------------ ------------------------------ ------------------------------ ------------------------------ ------------------------------ ---A----------------------A--- ---A----------------------A--- ---A----------------------A--- --AA----------------------AA-- --AA----------------------AA-- --AA----------------------AA-- --AA----------------------AA-- --AA----------------------AA-- --AA----------------------AA-- --AA----------------------AA-- --AA----------------------AA-- -AA------------------------AA- -AA------------------------AA- -AA------------------------AA- -AA------------------------AA- -AA------------------------AA- -AA------------------------AA- AAA------------------------AAA AAA------------------------AAA ------------------------------ ------------------------------ ------------------------------ ------------------------------ ------------------------------ ------------------------------ 
------------------------------ ------------------------------ ------------------------------ ------------------------------ ------------------------------ ------------------------------ ---A----------------------A--- ---A----------------------A--- ---A----------------------A--- --AA----------------------AA-- --AA----------------------AA-- --AA----------------------AA-- --AA----------------------AA-- --AA----------------------AA-- --AA----------------------AA-- --AA----------------------AA-- --AA----------------------AA-- -AA------------------------AA- -AA------------------------AA- -AA------------------------AA- -AA------------------------AA- -AA------------------------AA- -AA------------------------AA- AAA------------------------AAA AAA------------------------AAA ------------------------------ ------------------------------ ------------------------------ ------------------------------ ------------------------------ ------------------------------ 
------------------------------ ------------------------------ ------------------------------ ------------------------------ ------------------------------ ------------------------------ ---A----------------------A--- ---A----------------------A--- ---A----------------------A--- --AA----------------------AA-- --AA----------------------AA-- --AA----------------------AA-- --AA----------------------AA-- --AA----------------------AA-- --AA----------------------AA-- --AA----------------------AA-- --AA----------------------AA-- -AA------------------------AA- -AA------------------------AA- -AA------------------------AA- -AA------------------------AA- -AA------------------------AA- -AA------------------------AA- AAA------------------------AAA AAA------------------------AAA ------------------------------ ------------------------------ ------------------------------ ------------------------------ ------------------------------ ------------------------------ 
------------------------------ ------------------------------ ------------------------------ ------------------------------ ------------------------------ ------------------------------ ------------------------------ ---A----------------------A--- ---A----------------------A--- --AA----------------------AA-- --AA----------------------AA-- --AA----------------------AA-- --AA----------------------AA-- --AA----------------------AA-- --AA----------------------AA-- --AA----------------------AA-- --AA----------------------AA-- -AA------------------------AA- -AA------------------------AA- -AA------------------------AA- -AA------------------------AA- -AA------------------------AA- -AA------------------------AA- AAA------------------------AAA AAA------------------------AAA ------------------------------ ------------------------------ ------------------------------ ------------------------------ ------------------------------ ------------------------------ 
------------------------------ ------------------------------ ------------------------------ ------------------------------ ------------------------------ ------------------------------ ------------------------------ ---A----------------------A--- ---A----------------------A--- --AA----------------------AA-- --AA----------------------AA-- --AA----------------------AA-- --AA----------------------AA-- --AA----------------------AA-- --AA----------------------AA-- --AA----------------------AA-- --AA----------------------AA-- -AA------------------------AA- -AA------------------------AA- -AA------------------------AA- -AA------------------------AA- -AA------------------------AA- -AA------------------------AA- AAA------------------------AAA AAA------------------------AAA ------------------------------ ------------------------------ ------------------------------ ------------------------------ ------------------------------ ------------------------------ 
------------------------------ ------------------------------ ------------------------------ ------------------------------ ------------------------------ ------------------------------ ------------------------------ ---A----------------------A--- ---A----------------------A--- --AA----------------------AA-- --AA----------------------AA-- --AA----------------------AA-- --AA----------------------AA-- --AA----------------------AA-- --AA----------------------AA-- --AA----------------------AA-- --AA----------------------AA-- -AA------------------------AA- -AA------------------------AA- -AA------------------------AA- -AA------------------------AA- -AA------------------------AA- -AA------------------------AA- AAA------------------------AAA AAA------------------------AAA ------------------------------ ------------------------------ ------------------------------ ------------------------------ ------------------------------ ------------------------------ 
------------------------------ ------------------------------ ------------------------------ ------------------------------ ------------------------------ ------------------------------ ------------------------------ ---A----------------------A--- ---A----------------------A--- --AA----------------------AA-- --AA----------------------AA-- --CA----------------------AC-- --CA----------------------AC-- --CA----------------------AC-- --CA----------------------AC-- --AA----------------------AA-- --AA----------------------AA-- -AA------------------------AA- -AA------------------------AA- -CA------------------------AC- -CA------------------------AC- -AA------------------------AA- -AA------------------------AA- AAA------------------------AAA AAA------------------------AAA ------------------------------ ------------------------------ ------------------------------ ------------------------------ ------------------------------ ------------------------------ 
------------------------------ ------------------------------ ------------------------------ ------------------------------ ------------------------------ ------------------------------ ------------------------------ ---A----------------------A--- ---A----------------------A--- --AA----------------------AA-- --CA----------------------AC-- ------------------------------ ------------------------------ ------------------------------ ------------------------------ --CA----------------------AC-- --AA----------------------AA-- -AA------------------------AA- -CA------------------------AC- ------------------------------ ------------------------------ -CA------------------------AC- -AA------------------------AA- AAA------------------------AAA AAA------------------------AAA ------------------------------ ------------------------------ ------------------------------ ------------------------------ ------------------------------ ------------------------------ 
------------------------------ ------------------------------ ------------------------------ ------------------------------ ------------------------------ ------------------------------ ------------------------------ ------------------------------ ---A----------------------A--- --CA----------------------AC-- ------------------------------ ------------------------------ ------------------------------ ------------------------------ ------------------------------ ------------------------------ --CA----------------------AC-- -CA------------------------AC- ------------------------------ ------------------------------ ------------------------------ ------------------------------ -CA------------------------AC- AAA------------------------AAA AAA------------------------AAA ------------------------------ ------------------------------ ------------------------------ ------------------------------ ------------------------------ ------------------------------ 
------------------------------ ------------------------------ ------------------------------ ------------------------------ ------------------------------ ------------------------------ ------------------------------ ------------------------------ ---A----------------------A--- --CA----------------------AC-- ------------------------------ ------------------------------ ------------------------------ ------------------------------ ------------------------------ ------------------------------ --CA----------------------AC-- -CA------------------------AC- ------------------------------ ------------------------------ ------------------------------ ------------------------------ -CA------------------------AC- AAA------------------------AAA AAA------------------------AAA ------------------------------ ------------------------------ ------------------------------ ------------------------------ ------------------------------ ------------------------------ 
------------------------------ ------------------------------ ------------------------------ ------------------------------ ------------------------------ ------------------------------ ------------------------------ ------------------------------ ---A----------------------A--- --CA----------------------AC-- ------------------------------ ------------------------------ ------------------------------ ------------------------------ ------------------------------ ------------------------------ --CA----------------------AC-- -CA------------------------AC- ------------------------------ ------------------------------ ------------------------------ ------------------------------ -CA------------------------AC- AAA------------------------AAA AAA------------------------AAA ------------------------------ ------------------------------ ------------------------------ ------------------------------ ------------------------------ ------------------------------ 
------------------------------ ------------------------------ ------------------------------ ------------------------------ ------------------------------ ------------------------------ ------------------------------ ------------------------------ ---A----------------------A--- --CA----------------------AC-- ------------------------------ ------------------------------ ------------------------------ ------------------------------ ------------------------------ ------------------------------ --CA----------------------AC-- -CA------------------------AC- ------------------------------ ------------------------------ ------------------------------ ------------------------------ -CA------------------------AC- AAA------------------------AAA AAA------------------------AAA ------------------------------ ------------------------------ ------------------------------ ------------------------------ ------------------------------ ------------------------------ 
------------------------------ ------------------------------ ------------------------------ ------------------------------ ------------------------------ ------------------------------ ------------------------------ ------------------------------ ------------------------------ --AA----------------------AA-- --CA----------------------AC-- ------------------------------ ------------------------------ ------------------------------ ------------------------------ --CA----------------------AC-- --AA----------------------AA-- -AA------------------------AA- -CA------------------------AC- ------------------------------ ------------------------------ -CA------------------------AC- -AA------------------------AA- ------------------------------ ------------------------------ ------------------------------ ------------------------------ ------------------------------ ------------------------------ ------------------------------ ------------------------------ 
------------------------------ ------------------------------ ------------------------------ ------------------------------ ------------------------------ ------------------------------ ------------------------------ ------------------------------ ------------------------------ ------------------------------ --AA----------------------AA-- --CA----------------------AC-- --CA----------------------AC-- --CA----------------------AC-- --CA----------------------AC-- --AA----------------------AA-- ------------------------------ ------------------------------ -AA------------------------AA- -CA------------------------AC- -CA------------------------AC- -AA------------------------AA- ------------------------------ ------------------------------ ------------------------------ ------------------------------ ------------------------------ ------------------------------ ------------------------------ ------------------------------ ------------------------------ 
------------------------------ ------------------------------ ------------------------------ ------------------------------ ------------------------------ ------------------------------ ------------------------------ ------------------------------ ------------------------------ ------------------------------ ------------------------------ ------------------------------ ------------------------------ ------------------------------ ------------------------------ ------------------------------ ------------------------------ ------------------------------ ------------------------------ -AA------------------------AA- -AA------------------------AA- ------------------------------ ------------------------------ ------------------------------ ------------------------------ ------------------------------ ------------------------------ ------------------------------ ------------------------------ ------------------------------ ------------------------------ 
