model
size = 30 31 9, scale = 0.05, origin = -y
material 
  colors = A:#2A4A5B B:#959595 C:#4B4B4B D:#E3E3E3 E:#5E5E5E F:#BBB G:#46647C
voxels
------------------------------ ------------------------------ ------------------------------ ------------------------------ ------------------------------ ------------------------------ ------------------------------ ------------------------------ ------------------------------ ------------------------------ ------------------------------ ----CCCCCCCCCCC-CCCCCCCCC----- ----CCCCCCCCCCC-CCCCCCCC------ ----CCCCCCCCCC--CCCCCCCC------ ------------------------------ ----CCC-CCC-CCC-CCC----------- ----CCC-CCC-CCC-CCC----------- ----CCC-CCC-CCC-CCC----------- ----CCC-CCC-CCC-CCC----------- ----CCC-CCC-CCC-CCC----------- ----CCC-CCC-CCC-CCC----------- ----CC--CC--CC--CC------------ ------------------------------ ------------------------------ ------------------------------ ------------------------------ ------------------------------ ------------------------------ ------------------------------ ------------------------------ ------------------------------ 
--------------AA-------------- ------------AAAAAA------------ ----------AAAAAAAAAA---------- --------AAAAAA--AAAAAA-------- ------AAAAAA------AAAAAA------ ----AAAAAA----------AAAAAA---- ---AAAAA--------------AAAAA--- ---AAA------------------AAA--- ---AAA------------------AAA--- --AAAA------------------AAAA-- --AAA--------------------AAA-- --AACCCCCCCCCCC-CCCCCCCCCAAA-- --AACCCCCCCCCCC-CCCCCCCC-AAA-- -AAACCCCCCCCCC--CCCCCCCC-AAAA- -AAA----------------------AAA- -AAACCC-CCC-CCC-CCC-------AAA- -AAACCC-CCC-CCC-CCC-------AAA- AAAACCC-CCC-CCC-CCC-------AAAA AAA-CCC-CCC-CCC-CCC--------AAA AAA-CCC-CCC-CCC-CCC--------AAA AAA-CCC-CCC-CCC-CCC--------AAA AAA-CC--CC--CC--CC---------AAA AAAA----------------------AAAA AAAAAA------------------AAAAAA AAAAAAAA--------------AAAAAAAA --AAAAAAAA----------AAAAAAAA-- ----AAAAAAAA------AAAAAAAA---- ------AAAAAAAA--AAAAAAAA------ --------AAAAAAAAAAAAAA-------- ----------AAAAAAAAAA---------- ------------AAAAAA------------ 
--------------AA-------------- ------------AAAAAA------------ ----------AAAAAAAAAA---------- --------AAAAAAFEAAAAAA-------- ------AAAAAAFFDBEEAAAAAA------ ----AAAAAAFFDDDBBBEEAAAAAA---- ---AAAAAFFDDDDDBBBBBEEAAAAA--- ---AAAFFDDDDDDDBBBBBBBEEAAA--- ---AAAFDDDDDDDDBBBBBBBBEAAA--- --AAAAFDDDDDDDDBBBBBBBBBAAAA-- --AAAFDDDDDDDDDBBBBBBBBBEBAA-- --AAAFDDDDDDDDDBBBBBBBBBEBAA-- --AAAFDDDDDDDDDBBBBBBBBBEBAA-- -AAAAFDDDDDDDDDBBBBBBBBBEBAAA- -AAAFDDDDDDDDDDBBBBBBBBBBEAAA- -AAAFDDDDDDDDDDBBBBBBBBBBEAAA- -AAAFDDDDDDDDDDBBBBBBBBBBEAAA- AAAAFDDDDDDDDDDBBBBBBBBBBEAAAA AAAFDDDDDDDDDDDBBBBBBBBBBBEAAA AAAFDDDDDDDDDDDBBBBBBBBBBBEAAA AAAFDDDDDDDDDDDBBBBBBBBBBBEAAA AAAFDDDDDDDDDDDBBBBBBBBBBBEAAA AAAAFFDDDDDDDDDBBBBBBBBBEEAAAA AAAAAAFFDDDDDDDBBBBBBBEEAAAAAA AAAAAAAAFFDDDDDBBBBBEEAAAAAAAA --AAAAAAAAFFDDDBBBEEAAAAAAAA-- ----AAAAAAAAFFDBEEAAAAAAAA---- ------AAAAAAAAFEAAAAAAAA------ --------AAAAAAAAAAAAAA-------- ----------AAAAAAAAAA---------- ------------AAAAAA------------ 
--------------AA-------------- ------------AAAAAA------------ ----------AAAAAAAAAA---------- --------AAAAAAAAAAAAAA-------- ------AAAAAAAAAAAAAAAAAA------ ----AAAAAAAAAAAAAAAAAAAAAA---- ---AAAAAAAAAAAAAAAAAAAAAAAA--- ---AAAAAAAAAAAAAAAAAAAAAAAA--- ---AAAAAAAAAAAAAAAAAAAAAAAA--- --AAAAAAAAAAAAAAAAAAAAAAAAAA-- --AAAAAAAAAAAAAAAAAAAAAAAAAA-- --AAAAAAAAAAAAAAAAAAAAAAAAAA-- --AAAAAAAAAAAAAAAAAAAAAAAAAA-- -AAAAAAAAAAAAAAAAAAAAAAAAAAAA- -AAAAAAAAAAAAAAAAAAAAAAAAAAAA- -AAAAAAAAAAAAAAAAAAAAAAAAAAAA- -AAAAAAAAAAAAAAAAAAAAAAAAAAAA- AAAAAAAAAAAAAAAAAAAAAAAAAAAAAA AAAAAAAAAAAAAAAAAAAAAAAAAAAAAA AAAAAAAAAAAAAAAAAAAAAAAAAAAAAA AAAAAAAAAAAAAAAAAAAAAAAAAAAAAA AAAAAAAAAAAAAAAAAAAAAAAAAAAAAA AAAAAAAAAAAAAAAAAAAAAAAAAAAAAA AAAAAAAAAAAAAAAAAAAAAAAAAAAAAA AAAAAAAAAAAAAAAAAAAAAAAAAAAAAA --AAAAAAAAAAAAAAAAAAAAAAAAAA-- ----AAAAAAAAAAAAAAAAAAAAAA---- ------AAAAAAAAAAAAAAAAAA------ --------AAAAAAAAAAAAAA-------- ----------AAAAAAAAAA---------- ------------AAAAAA------------ 
--------------AA-------------- ------------AAAAAA------------ ----------AAAAAAAAAA---------- --------AAAAAAEEAAAAAA-------- ------AAAAAAEEBBEEAAAAAA------ ----AAAAAAEEEBBFDEEEAAAAAA---- ---AAAAAEEBBEBBFDEBBEEAAAAA--- ---AAAEEBBBFEBFFDEBBBFEEAAA--- ---AAAEEBBFFEBFFDEBBFFEEAAA--- --AAAAEEBFFFEBFFDEBFFFEBAAAA-- --AAAEBEBFFFEBFFDEBFFFEBBBAA-- --AAAEBEBFFFEBFFDEBFFFEBFBAA-- --AAAEBEBFFFEBFFDEBFFFEBFBAA-- -AAAAEBEBFFFEBFFDEBFFFEBFBAAA- -AAAEBFEBFFFEBFFDEBFFFEBFEAAA- -AAAEBFEBFFFEBFFDEBFFFEBFEAAA- -AAAEBFEBFFDEBFFDEBFFDEBFEAAA- AAAAEBFEBFFDEBFFDEBFFDEBFEAAAA AAAEBFDEBFFDEBFFDEBFFDEFFDEAAA AAAEBFDEBFFDEBFFDEBFFDEFFDEAAA AAAEBFDEBFFDEBFFDEBFFDEFFDEAAA AAAEBFDEBFFDEBFFDEBFFDEFFDEAAA AAAAEEDEBFFDEBFFDEBFFDEBEEAAAA AAAAAAEEBFFDEBFFDEBFFDEEAAAAAA AAAAAAAAEEFDEBFFDEBFEEAAAAAAAA --AAAAAAAAEEEBFFDEEEAAAAAAAA-- ----AAAAAAAAEEFDEEAAAAAAAA---- ------AAAAAAAAEEAAAAAAAA------ --------AAAAAAAAAAAAAA-------- ----------AAAAAAAAAA---------- ------------AAAAAA------------ 
--------------AA-------------- ------------AAAAAA------------ ----------AAAAAAAAAA---------- --------AAAAAA--AAAAAA-------- ------AAAAAA------AAAAAA------ ----AAAAAA----------AAAAAA---- ---AAAAA--------------AAAAA--- ---AAA------------------AAA--- ---AAA------------------AAA--- --AAAA------------------AAAA-- --AAA--------------------AAA-- --AAA--------------------AAA-- --AAA--------------------AAA-- -AAAA--------------------AAAA- -AAA---EE------------EE---AAA- -AAA---EE------------EE---AAA- -AAA---EE------------EE---AAA- AAAA---EE------------EE---AAAA AAA------------------------AAA AAA------------------------AAA AAA------------------------AAA AAA------------------------AAA AAAA----------------------AAAA AAAAAA------------------AAAAAA AAAAAAAA--------------AAAAAAAA --AAAAAAAA----------AAAAAAAA-- ----AAAAAAAA------AAAAAAAA---- ------AAAAAAAA--AAAAAAAA------ --------AAAAAAAAAAAAAA-------- ----------AAAAAAAAAA---------- ------------AAAAAA------------ 
------------------------------ ------------------------------ ------------------------------ ------------------------------ ------------------------------ ------------------------------ ------------------------------ ------------------------------ ------------------------------ ------------------------------ ------------------------------ ------------------------------ ------------------------------ ------------------------------ --------AA----------AA-------- --------GG----------GG-------- --------GG----------GG-------- --------AA----------AA-------- ------------------------------ ------------------------------ ------------------------------ ------------------------------ ------------------------------ ------------------------------ ------------------------------ ------------------------------ ------------------------------ ------------------------------ ------------------------------ ------------------------------ ------------------------------ 
------------------------------ ------------------------------ ------------------------------ ------------------------------ ------------------------------ ------------------------------ ------------------------------ ------------------------------ ------------------------------ ------------------------------ ------------------------------ ------------------------------ ------------------------------ ------------------------------ ---------AAA------AAA--------- ---------GGG------GGG--------- ---------GGG------GGG--------- ---------AAA------AAA--------- ------------------------------ ------------------------------ ------------------------------ ------------------------------ ------------------------------ ------------------------------ ------------------------------ ------------------------------ ------------------------------ ------------------------------ ------------------------------ ------------------------------ ------------------------------ 
------------------------------ ------------------------------ ------------------------------ ------------------------------ ------------------------------ ------------------------------ ------------------------------ ------------------------------ ------------------------------ ------------------------------ ------------------------------ ------------------------------ ------------------------------ ------------------------------ -----------AAAAAAAA----------- -----------GGGGGGGG----------- -----------GGGGGGGG----------- -----------AAAAAAAA----------- ------------------------------ ------------------------------ ------------------------------ ------------------------------ ------------------------------ ------------------------------ ------------------------------ ------------------------------ ------------------------------ ------------------------------ ------------------------------ ------------------------------ ------------------------------ 
