model
size = 30 31 9, scale = 0.05, origin = -y
material 
  colors = A:#777 B:#004 C:#007 D:#002 E:#005 F:#C80000 G:#FF9B00 H:#888
voxels
------------------------------ ------------------------------ ------------------------------ ------------------------------ ------------------------------ ------------------------------ ------------------------------ ------------------------------ ------------------------------ ------------------------------ ------------------------------ ----FFFFFFFFFFG-FFFFFFFFG----- ----FFFFFFFFFFG-FFFFFFFFG----- ----GGGGGGGGGG--GGGGGGGG------ ------------------------------ ----FFG-FFG-FFG-FFG----------- ----FFG-FFG-FFG-FFG----------- ----FFG-FFG-FFG-FFG----------- ----FFG-FFG-FFG-FFG----------- ----FFG-FFG-FFG-FFG----------- ----FFG-FFG-FFG-FFG----------- ----GG--GG--GG--GG------------ ------------------------------ ------------------------------ ------------------------------ ------------------------------ ------------------------------ ------------------------------ ------------------------------ ------------------------------ ------------------------------ 
--------------AA-------------- ------------AAAAAA------------ ----------AAAAAAAAAA---------- --------AAAAAA--AAAAAA-------- ------AAAAAA------AAAAAA------ ----AAAAAA----------AAAAAA---- ---AAAAA--------------AAAAA--- ---AAA------------------AAA--- ---AAA------------------AAA--- --AAAA------------------AAAA-- --AAA--------------------AAA-- --AAFFFFFFFFFFG-FFFFFFFFGAAA-- --AAFFFFFFFFFFG-FFFFFFFFGAAA-- -AAAGGGGGGGGGG--GGGGGGGG-AAAA- -AAA----------------------AAA- -AAAFFG-FFG-FFG-FFG-------AAA- -AAAFFG-FFG-FFG-FFG-------AAA- AAAAFFG-FFG-FFG-FFG-------AAAA AAA-FFG-FFG-FFG-FFG--------AAA AAA-FFG-FFG-FFG-FFG--------AAA AAA-FFG-FFG-FFG-FFG--------AAA AAA-GG--GG--GG--GG---------AAA AAAA----------------------AAAA AAAAAA------------------AAAAAA AAAAAAAA--------------AAAAAAAA --AAAAAAAA----------AAAAAAAA-- ----AAAAAAAA------AAAAAAAA---- ------AAAAAAAA--AAAAAAAA------ --------AAAAAAAAAAAAAA-------- ----------AAAAAAAAAA---------- ------------AAAAAA------------ 
--------------AA-------------- ------------AAAAAA------------ ----------AAAAAAAAAA---------- --------AAAAAAEDAAAAAA-------- ------AAAAAAEECBDDAAAAAA------ ----AAAAAAEECCCBBBDDAAAAAA---- ---AAAAAEECCCCCBBBBBDDAAAAA--- ---AAAEECCCCCCCBBBBBBBDDAAA--- ---AAAECCCCCCCCBBBBBBBBDAAA--- --AAAAECCCCCCCCBBBBBBBBBAAAA-- --AAAECCCCCCCCCBBBBBBBBBDBAA-- --AAAECCCCCCCCCBBBBBBBBBDBAA-- --AAAECCCCCCCCCBBBBBBBBBDBAA-- -AAAAECCCCCCCCCBBBBBBBBBDBAAA- -AAAECCCCCCCCCCBBBBBBBBBBDAAA- -AAAECCCCCCCCCCBBBBBBBBBBDAAA- -AAAECCCCCCCCCCBBBBBBBBBBDAAA- AAAAECCCCCCCCCCBBBBBBBBBBDAAAA AAAECCCCCCCCCCCBBBBBBBBBBBDAAA AAAECCCCCCCCCCCBBBBBBBBBBBDAAA AAAECCCCCCCCCCCBBBBBBBBBBBDAAA AAAECCCCCCCCCCCBBBBBBBBBBBDAAA AAAAEECCCCCCCCCBBBBBBBBBDDAAAA AAAAAAEECCCCCCCBBBBBBBDDAAAAAA AAAAAAAAEECCCCCBBBBBDDAAAAAAAA --AAAAAAAAEECCCBBBDDAAAAAAAA-- ----AAAAAAAAEECBDDAAAAAAAA---- ------AAAAAAAAEDAAAAAAAA------ --------AAAAAAAAAAAAAA-------- ----------AAAAAAAAAA---------- ------------AAAAAA------------ 
--------------AA-------------- ------------AAAAAA------------ ----------AAAAAAAAAA---------- --------AAAAAAAAAAAAAA-------- ------AAAAAAAAAAAAAAAAAA------ ----AAAAAAAAAAAAAAAAAAAAAA---- ---AAAAAAAAAAAAAAAAAAAAAAAA--- ---AAAAAAAAAAAAAAAAAAAAAAAA--- ---AAAAAAAAAAAAAAAAAAAAAAAA--- --AAAAAAAAAAAAAAAAAAAAAAAAAA-- --AAAAAAAAAAAAAAAAAAAAAAAAAA-- --AAAAAAAAAAAAAAAAAAAAAAAAAA-- --AAAAAAAAAAAAAAAAAAAAAAAAAA-- -AAAAAAAAAAAAAAAAAAAAAAAAAAAA- -AAAAAAAAAAAAAAAAAAAAAAAAAAAA- -AAAAAAAAAAAAAAAAAAAAAAAAAAAA- -AAAAAAAAAAAAAAAAAAAAAAAAAAAA- AAAAAAAAAAAAAAAAAAAAAAAAAAAAAA AAAAAAAAAAAAAAAAAAAAAAAAAAAAAA AAAAAAAAAAAAAAAAAAAAAAAAAAAAAA AAAAAAAAAAAAAAAAAAAAAAAAAAAAAA AAAAAAAAAAAAAAAAAAAAAAAAAAAAAA AAAAAAAAAAAAAAAAAAAAAAAAAAAAAA AAAAAAAAAAAAAAAAAAAAAAAAAAAAAA AAAAAAAAAAAAAAAAAAAAAAAAAAAAAA --AAAAAAAAAAAAAAAAAAAAAAAAAA-- ----AAAAAAAAAAAAAAAAAAAAAA---- ------AAAAAAAAAAAAAAAAAA------ --------AAAAAAAAAAAAAA-------- ----------AAAAAAAAAA---------- ------------AAAAAA------------ 
--------------AA-------------- ------------AAAAAA------------ ----------AAAAAAAAAA---------- --------AAAAAADDAAAAAA-------- ------AAAAAADDBBDDAAAAAA------ ----AAAAAADDDBBECDDDAAAAAA---- ---AAAAADDBBDBBECDBBDDAAAAA--- ---AAADDBBBEDBEECDBBBEDDAAA--- ---AAADDBBEEDBEECDBBEEDDAAA--- --AAAADDBEEEDBEECDBEEEDBAAAA-- --AAADBDBEEEDBEECDBEEEDBBBAA-- --AAADBDBEEEDBEECDBEEEDBEBAA-- --AAADBDBEEEDBEECDBEEEDBEBAA-- -AAAADBDBEEEDBEECDBEEEDBEBAAA- -AAADBEDBEEEDBEECDBEEEDBEDAAA- -AAADBEDBEEEDBEECDBEEEDBEDAAA- -AAADBEDBEECDBEECDBEECDBEDAAA- AAAADBEDBEECDBEECDBEECDBEDAAAA AAADBECDBEECDBEECDBEECDEECDAAA AAADBECDBEECDBEECDBEECDEECDAAA AAADBECDBEECDBEECDBEECDEECDAAA AAADBECDBEECDBEECDBEECDEECDAAA AAAADDCDBEECDBEECDBEECDBDDAAAA AAAAAADDBEECDBEECDBEECDDAAAAAA AAAAAAAADDECDBEECDBEDDAAAAAAAA --AAAAAAAADDDBEECDDDAAAAAAAA-- ----AAAAAAAADDECDDAAAAAAAA---- ------AAAAAAAADDAAAAAAAA------ --------AAAAAAAAAAAAAA-------- ----------AAAAAAAAAA---------- ------------AAAAAA------------ 
--------------AA-------------- ------------AAAAAA------------ ----------AAAAAAAAAA---------- --------AAAAAA--AAAAAA-------- ------AAAAAA------AAAAAA------ ----AAAAAA----------AAAAAA---- ---AAAAA--------------AAAAA--- ---AAA------------------AAA--- ---AAA------------------AAA--- --AAAA------------------AAAA-- --AAA--------------------AAA-- --AAA--------------------AAA-- --AAA--------------------AAA-- -AAAA--------------------AAAA- -AAA---DD------------DD---AAA- -AAA---DD------------DD---AAA- -AAA---DD------------DD---AAA- AAAA---DD------------DD---AAAA AAA------------------------AAA AAA------------------------AAA AAA------------------------AAA AAA------------------------AAA AAAA----------------------AAAA AAAAAA------------------AAAAAA AAAAAAAA--------------AAAAAAAA --AAAAAAAA----------AAAAAAAA-- ----AAAAAAAA------AAAAAAAA---- ------AAAAAAAA--AAAAAAAA------ --------AAAAAAAAAAAAAA-------- ----------AAAAAAAAAA---------- ------------AAAAAA------------ 
------------------------------ ------------------------------ ------------------------------ ------------------------------ ------------------------------ ------------------------------ ------------------------------ ------------------------------ ------------------------------ ------------------------------ ------------------------------ ------------------------------ ------------------------------ ------------------------------ --------AA----------AA-------- --------HH----------HH-------- --------HH----------HH-------- --------AA----------AA-------- ------------------------------ ------------------------------ ------------------------------ ------------------------------ ------------------------------ ------------------------------ ------------------------------ ------------------------------ ------------------------------ ------------------------------ ------------------------------ ------------------------------ ------------------------------ 
------------------------------ ------------------------------ ------------------------------ ------------------------------ ------------------------------ ------------------------------ ------------------------------ ------------------------------ ------------------------------ ------------------------------ ------------------------------ ------------------------------ ------------------------------ ------------------------------ ---------AAA------AAA--------- ---------HHH------HHH--------- ---------HHH------HHH--------- ---------AAA------AAA--------- ------------------------------ ------------------------------ ------------------------------ ------------------------------ ------------------------------ ------------------------------ ------------------------------ ------------------------------ ------------------------------ ------------------------------ ------------------------------ ------------------------------ ------------------------------ 
------------------------------ ------------------------------ ------------------------------ ------------------------------ ------------------------------ ------------------------------ ------------------------------ ------------------------------ ------------------------------ ------------------------------ ------------------------------ ------------------------------ ------------------------------ ------------------------------ -----------AAAAAAAA----------- -----------HHHHHHHH----------- -----------HHHHHHHH----------- -----------AAAAAAAA----------- ------------------------------ ------------------------------ ------------------------------ ------------------------------ ------------------------------ ------------------------------ ------------------------------ ------------------------------ ------------------------------ ------------------------------ ------------------------------ ------------------------------ ------------------------------ 
