model
size = 32 32 6, scale = 0.05, origin = -y
material 
  colors = A:#FC0 B:#F00 C:#AAA D:#EEE
voxels
4-24A8-24A6-28A4-28A2-4A7(24-8A)2(2-10CD-8CD-8A)2-10D2-8D2-8A24-6(8A2-3(2CD-)2CD7-)8A4(2-2D)8-6(8A24-)4A2-28A4-28A6-3(24A8-)24A6-28A4-28A2-4A7(24-8A)2(2-10CD-8CD-8A)2-10D2-8D2-8A24-6(8A2-3(2CD-)2CD7-)8A4(2-2D)8-6(8A24-)4A2-28A4-28A6-24A8-24A6-28A4-28A2-68A23(24B8A)24B68A2-3(28A4-)28A2-68A23(24B8A)24B68A2-28A4-28A6-24A8-24A6-28A4-28A2-4A7(24-8A)2(2-D8C-D10C-8A)3-8D2-10D-8A24-6(8A8-4(D2C-))8A9-3(2D2-)2D-6(8A24-)4A2-28A4-28A6-3(24A8-)24A6-28A4-28A2-4A7(24-8A)2(2-D8C-D10C-8A)3-8D2-10D-8A24-6(8A8-4(D2C-))8A9-3(2D2-)2D-6(8A24-)4A2-28A4-28A6-24A8-24A4-
