model
size = 13 12 32, scale = 0.05, origin = -y
material 
  colors = A:#000 B:#FFFEFE C:#0B0000 D:#040009 E:#FFFDF3 F:#0A010B G:#5B4135 H:#130200 I:#11050B J:#FEEBE2 K:#533B32 L:#3B231B M:#130A14 N:#52382C O:#FFF4EB P:#D8B5A6 Q:#FDE5D9 R:#1C1113 S:#100511 T:#1A0905 U:#EBCBBB V:#AD8C7B W:#927364 X:#624539 Y:#65493E Z:#443A43 Aa:#F2D3C4 Ab:#190D12 Ac:#FEE2D3 Ad:#896D61 Ae:#92766B Af:#FCECEB Ag:#BA9A8B Ah:#22161C Ai:#211621 Aj:#9B8074 Ak:#FEEADA Al:#F6D9CA Am:#8C7165 An:#0B0511 Ao:#583D31 Ap:#5B4B4B Aq:#291E25 Ar:#F6E4E3 As:#E7C8B8 At:#6A4D41 Au:#42291F Av:#62545A Aw:#24110C Ax:#190300 Ay:#AA8C82 Az:#FEF9ED Ba:#EACDC2 Bb:#312630 Bc:#CAABA3 Bd:#C4A290 Be:#645353 Bf:#4A3D42 Bg:#745D59 Bh:#53454B Bi:#746363 Bj:#CBAB9C Bk:#5B433B Bl:#452D26 Bm:#4C332B Bn:#220E09 Bo:#231412 Bp:#B29283 Bq:#E3C4BB Br:#31252B Bs:#FFF3E4 Bt:#DFBDAD Bu:#130D19 Bv:#6C5145 Bw:#927A74 Bx:#32201E By:#CCB4B0 Bz:#3D2A24 Ca:#C2A59B Cb:#3B2B2A Cc:#997C73 Cd:#180E19 Ce:#FBDBCB Cf:#443537 Cg:#241B24 Ch:#83685C Ci:#25191B Cj:#594D55 Ck:#6D5854 Cl:#9A8482 Cm:#B2958A Cn:#A99493 Co:#64504D Cp:#A39393 Cq:#3C323A Cr:#44383C Cs:#997B6C Ct:#F2D5C9 Cu:#96796A Cv:#321C14 Cw:#5B3B29 Cx:#D2B4AB Cy:#6B5C62 Cz:#0D0915 Da:#050311 Db:#ECCFBF Dc:#E3CBC4 Dd:#816559 De:#2D2225 Df:#523D3A Dg:#7B5D52 Dh:#DABAAB Di:#D5AF99 Dj:#9E8278 Dk:#725344 Dl:#B19491 Dm:#DBC5C4 Dn:#B39A94 Do:#BA9E99 Dp:#140A0A Dq:#4C434B Dr:#322423 Ds:#43312B Dt:#514445 Du:#6B5A5B Dv:#351E16 Dw:#816254 Dx:#7C6054 Dy:#CDB0A5 Dz:#342A33 Ea:#E3C3B2 Eb:#3C3032 Ec:#73656A Ed:#2C1913 Ee:#CCB2AB Ef:#BA9D93 Eg:#8A6B5C Eh:#4B3A3A Ei:#1E131B Ej:#4E4144 Ek:#1B121C El:#7B6563 Em:#BBAAAB En:#393036 Eo:#8B7B7B Ep:#C8A998 Eq:#745B53 Er:#53413D Es:#382C34 Et:#837375 Eu:#E3CDCB Ev:#9C8A8A Ew:#C3B3B4 Ex:#D5B8AA Ey:#594643 Ez:#6C544C Fa:#89767A Fb:#271714 Fc:#A48983 Fd:#E4C2AE Fe:#DBC2BB Ff:#BCA39B Fg:#54494D Fh:#D0BEBD Fi:#AB928A Fj:#171018 Fk:#826A63 Fl:#76686C Fm:#665759 Fn:#F3DCD3 Fo:#74605D Fp:#2C222B Fq:#F5E1DB Fr:#6B626B Fs:#230A01 Ft:#5C4944 Fu:#AA9BA2 Fv:#655A63 Fw:#2A0C00 Fx:#7A5B4C Fy:#331506 Fz:#D3BDBA Ga:#381908 Gb:#CAB8B6 Gc:#382625 Gd:#624E4B Ge:#433332 Gf:#84716E Gg:#8A7573 Gh:#836D6A Gi:#DCC1B4 Gj:#7B6B6B Gk:#927C7B Gl:#A4867A Gm:#A38C8A Gn:#A6918B Go:#7D6965 Gp:#4D3934 Gq:#C4A6A1 Gr:#1B0C09 Gs:#F7DED4 Gt:#D3B3A4 Gu:#8C7B82 Gv:#442C24 Gw:#1A1421 Gx:#796C73 Gy:#2B1C1B Gz:#93807D Ha:#E4D3D1 Hb:#5C525A Hc:#CCBBBA Hd:#8C7974 He:#EBD3CB Hf:#C3ABA5 Hg:#BBA5A3 Hh:#7E6962 Hi:#6D4C3A Hj:#533426
voxels
30-WChAyVUAc7-3EAz2B7-AzEJAk2B111-Ao2GXAmBdAl5-Db-ChGVAm2Bs5-2E4-2B5-BAzQE3B8-2E2B97-AlDg2GX2Y2Ag4-ODbX5-E4-2E5-2B5-EAfE2-B-B6-EAzE3B86-AoGAt2Bv5-Bj2X2GAtBvAtDiAc3-O7-AzB3-2E6-2B3-BArB4-2B6-6B85-4G2YCmQ2-JWAoGX3-DkDiQ2-JO8-B2-2B7-2B3-2ArB4-3B5-6B83-2X2KAoGYAt2Cm2-U2GX6-Q2-J9-BE-BEw8-Ev3-Eu2B4-BxGnAp5-5BDmCn81-AmGAoBm2K2Ao2GBd2-UG8-Bs2JO9-OE-2Cp8-BhE2-FCbDtC4-RAb5-AvEoBiDrDpIAh80-AkAe3N4K2GBd-2Ce8-A-Bs2O8-A-EBCpF8-DCp2-FIC5-RI5-C4AIAbR8-2AI68-AkDx4NKBmKGKVJAk9-A-JO10-AAzBFgA8-ACr2-IAqAiA5-Dp5-4A-S2Av7-2A3I67-AkDx3NBl2LNBkKVQAc10-AOE11-EOEiA8-AAi2-CZDqA5-2F4-3A3-AhAi7-A3CI11-Ci55-AaAt2BmGvL2CvBz2KCu-As9-A-DyE9-2AAcGu2A8-AEb2-AFCq6-AD4-2AhA3-FlDz6-F-ACI2Av7-2ACDp55-UAe2BlLEdBnAwBzBlBkCh-Bd6-3A2-DiBs7-2A2-AsGx2A7-A-A2-FSCj6-AD4-FrF5-S6-I2A2-AhFp7-3ARC11-CiR41-BdAgLBzLEdBn2AwEd2Bk-Bd3-3A2-A2-EaBc4-4A-A-EaBcF2A7-AAn2-A2D6-2A4-ZCg4-A-M4-M-A2-A-Hb6-BrDSC2-Ha8-AbICbBf41-UAgLCvBoT2H2TDsU-PFi-A-2AHAx2-Cx-P3-A4-AuCCc-BhF2D7-AxA2-FAD6-2A4-Z2A3-A-A4-Cd-A2-A-D6-Ah-C-A-Ai7-I-C2-A8-2IA2Bb28-BpLBoAwT2H2THhAc-PCa-3AAxY3-Hg-AsHf-A4-WAu-He-CrMD7-Fy-A2-2DFA5-FwA4-Cd-A4-AxA4-Fr-A2-2AC5-S-A2-A-Fv6-Cr2Ab-A-Aq8-AbCdCDuAi28-PDf2AwAxC2HTDl3-EpA-2ALY3-Fz2-Ee-A4-WCs-Q2-MD7-Fy-A2-2(DA)5-GaA4-DA5-GaA4-Z-A3-A-A4-M2(2-A)-A5-Cf2-FwAx-Cb7-SAb3-Ej9-BoRApEn15-PDfHBnAx2CH2Bx3-P2-AFsG4-Ar2-Bc2A3-2VCs-Ar2-CdF7-Eg-A2-FAD6-HiA4-3A4-HjA4-Z2-4A-A4-Fu2-3A2-A5-Dz-Cw4-A5-Fm5-Fo7-AbS-CDcBf9-Ai6-AeCTH2CHBxCo3-Bj2-CDv4-Ar3-Dy-A2-WVBjP-E2-CdM7-V-A2-MFD6-CuR4-3A4-CwA4-F-Eg4-EzA4-Em-Eg2-2A-A5-CDx-Cw3-A5-Ap-Am4-Cq6-F2-A-Bh8-SM-BbAq3-BpCTH4CBg3-Bt8-By3-Ee-2ABmAdAgBjP-E2-FjM-2A4-Dh-A2-MD-H5-DhA4-A-A4-DdAb4-A-Dv4-DdA5-CjBp2-A-ByA5-FvBa-FxCbA-A5-BrCk-FxBeA-Cq5-Ec-FfCnCrFzFl7-EbAqBfAhEsAq3-BtHCH2CACAm4-Bj7-By3-Hc4-CsEfAsAa-Q2-F2(-A)4-U-De2-MF-H5-AaDe4-ACb5-AjDr5-AhH4-AyA5-DHd4-FnA5-FBa4-OA5-AiCl4-CnA5-AvBhDc3-FgBu6-BbEl7-DbGyC4ACAe4-Ee8-Q3-Gz3-2EfAsAl-Q3-R2-C4-Ac-A2-M2-A5-JDt3-FABo5-BjAp5-2Ft4-CtA5-AqBg4-CtA5-FpEb4-ArAn5-DzR4-FuZ28-FdAe2C3ACFk4-By8-Fq3-Ec3-AjAgPU-Fq3-Ec2-C4-Ac-A2-F2-Fs5-OCo3-SA-C4-BqDt5-ABw4-CtA5-FEv4-JF11-EuZ42-Bw2C3ACFkGs3-Af8-Ba3-Af3-CuBpGtUEaBa3-D2-Cv5-CnA2-D2-Cw6-Fm3-AnD-Au4-FnFo5-AiFc4-JA11-AfGw55-FiTH3AHDsBq4-Fh7-Bq3-B2-AdCuDjCaPVBq3-D-Dw6-ClBr2-A2-Dw5-DyEh3-2DL5-AaFj5-CyAg4-JA11-EDq55-FfAw2BnCHFbLCm4-Fh8-Aa3-Dm-AmAeCcDlBcBp-As3-ErCs6-AyA3-Dr-Dg5-AyA3-D-Dk5-CtA4-ADu5-AfF68-GqBxBnBoGrHFbBzBp4-Ew8-Aa3-Af-WDjCcFc2Do-Fd3-EyAj6-CkA3-BoDw6-BwA3-A-Dk5-FeA4-ABe5-FeA68-CaAu2LDvLAuBmCa4-Dm8-P3-B-W2CcBw2Dn-P3-CqAm6-BkD3-AGp6-CoD3-A-Ez5-FaD4-SBe5-FaD11-Bh56-AgG2BlBz2AuGCa4-Af8-Ex3-Af-WAdBgGoClDo-Ex3-DqAp6-DgAn3-I-Ds5-CoAn4-FEy5-DuCz4-AAp5-CyD5-Av5-Bi56-AaGlAt2G2NBvEp4-Aa8-Bt3-B2-2EqBgClDl-Ba4-BeW5-BfBu4-RBk5-BfAn4-A-Er4-EsBu4-A-Gm3-DnCj6-ZBy3-2Et57-As2AdAtGBvChBt5-Dh6-Aa5-B2-BgGhDj2-Gi4-Em-Ad3-Bw-Cg4-2Ci4-CjEn5-A-Ck3-BiBr6-ACk3-BiBu6-AGj3-GkD7-Bi3-Eo45-QBcAd2AjAeAyBt5-Dc6-Al5-B6-Ce5-E2-AeDdEl-Bu6-DeGdAd-Be-Da6-F-Ap-Ge-Cz6-A-BeYDf-Da7-BfGfYBgAq8-BhGgBcBiZ46-2Cx2AjAy8-BqAl2AkAlAc7-2JCeBaAlQ7-GbCyCfEhCgEi8-FCfEjBrA8-EkBbCfCgD8-CzBbGcEkDa8-2ARS10-AMAn42-
