model
size = 13 32 10, scale = 0.05, origin = -y
material 
  colors = A:#000 B:#7D0202 C:#272727 D:#0098FE E:#0DA1DB F:#74837E G:#059CED H:#0DA1DD I:#58C9CC J:#688884 K:#7E7E77 L:#847B72 M:#3B9FA1 N:#59908D O:#5E8D8B P:#59C9CC Q:#10A4D4 R:#069CEC S:#0BA1DE T:#8D766F U:#817C76 V:#58908E W:#B86054 X:#77817B Y:#678986 Z:#5E79A7 Aa:#5BC9CE Ab:#1AABBB Ac:#17A7C4 Ad:#13A6CE Ae:#10A4D3 Af:#17A9C4 Ag:#1AABBD Ah:#2EA6A9 Ai:#5D8E8B Aj:#429C9C Ak:#18A9C0 Al:#12A6CE Am:#12A6CF An:#17A9C2 Ao:#9C6F65 Ap:#638B88 Aq:#10A2D4 Ar:#0A9FE5 As:#867972 At:#35A2A4 Au:#36A1A4 Av:#17A7C5 Aw:#3B98AB Ax:#897771 Ay:#987167 Az:#519393 Ba:#6A769D Bb:#4E9595 Bc:#549290 Bd:#608D89 Be:#62C9CC Bf:#31A4A6 Bg:#5BC7CA Bh:#5BCACE Bi:#62CACE Bj:#5DC9CC Bk:#0B9FE2
voxels
382-3E10-3E306-3(2A5-2A4-)2A3-4A4-9A4-2(8A5-)3A2-3A6-SArEAq2GD6-7D8(6-3A-3A)31-2(3A3-3A4-)3A3-3A5-3(2A3-2A6-)2A2(3-3A4-3A)3-3A2(3-4A)2-4A2(2-5A)-5A2-5A-5A3(2-11A)2-I6A-3A2-I3A4-3A2-2A5-4A2-3A4-H3A2-AHSG3-H2R4-3D3-3D4(4-2A-A-4A)4-4A-4A4-A-2A-4A4-2A-A8(-4A4-4A)-4A3-5A-5A2-5A-3A-A2-5A2(-2A)2(2-3(2A-)2A)2-A2-2A2(-2A2-A)-2A2(3-4A3-3A)3-2ACA4-2A3-A2CBg9-2CAI9-Bh2ABi9-PA-Aa9-PA-Bj8-AC2-AaG7-GBk2-2D7-2D3(2-2(2A-)2(A-)A)2-2(2A-)2(A-)C2-2A2-2(A-)AC4-2A2(-A)-2A4-3A3-A-A3-4A2-A2-2A2(2-4A2-A-3A)2-4A2-2(A-)A2-4A4-2AF2-2A-A5-2A2-NA-2(A2-)2C2-OA-2(A2-)2(AC2-CA2-A-A2-)AC-AC3-A-A2-ABb-AC3-A-A3-C-ABc3-A-A3-C-2C3-A-A3-JFC4-3A3-A2F11-CY11-BdBe11-CU2(11-CB)A9-AVBC9-BfT2B9-IB-Z9-P2-D9-D2-2A2(4-A2(2-2A))4-A2-2A2-CA4-A2-2W2-CA4-2(A2-CB2-CA2-A-)A2-MB2-CA2-A-A2-2X2-O3-A5-Ax2-C3-A5-L2-Y3-A4-AAy2-C3-A5-F2-B3-A4-AzB2-N3-A4-2B2-O3-A5-B2-2(B3-A-A3-B-A)B5-A3-2(B-AB9-)B-2B9-4B9-3B4(11-2B)10-4B2(9-3BC)9-2B-Z9-Ba2-D9-D2-2A2-3(A-)2(A2-2A2-A-A3-)A2-BAo2-A-A2-ApB2-BC2-A-A2(2-2B)2-A-A2-AC5(2-B3-A-A3-B)2(2-B3-A-A3-C)2-BA2-A-A2-2C2-BA2-A-A2-2J2-BA2-A-A2-AK2-2L2-A-A2-AT2-As3-A-A2-AC2-U3-A-A2-AC-AK3-A-A3-C-AC3-A5-C-BC3-2A4-C-BAt3-2A4-VB2C9-CBKA9-MBCA9-NB2C9-F2BM9-C2-Au9-C2-C9-C2-Av9-Aw2-2D7-2D3-4A-4A4-4A2(-4A3-5A)-4A3-AC3A-4A3-BAh2(-2A)-2C5(2-CA2(-2A)-AC)2-Ai4A-4AC2-Aj4A-4AC2-B-3A-4AC2-5A-5A2-5A-3A-A2-A-3A-4A3-5A-5A2(2-3(2A-)2A)2-2A2-A-A3(2(2-2A)2-3A)2-2A2-A3-3A2-2A3(2-A9-A)2-A8-2A2-2A7-2A2-AkAl7-AmAn2-3D5-3D4-3(2A3-2A6-)2A3-2A5-8(3A3-3A4-)3A3-2A5-3A3-2A6-2A4-A6-2(2A4-)3(3A3-3A4-)4(4A-4A4-)4A-4A3-2(11A2-)3(2A7-2A2-)A-A2-2A-2A4-AbAcQHAdAeQAfAg4-9D317-2A3-2A5-4(9A4-)9A5-7A16-
