model
size = 20 32 16, scale = 0.05, origin = -y
material 
  colors = A:#4083C4 B:#4981BB C:#2290D9 D:#5E79A7 E:#0F93EF F:#6A769D G:#7C718D H:#3D84C5 I:#059CED J:#62C9CC K:#0A9FE5
voxels
6-A3B4-DF10-2AB5-2B10-3B5-A11-A2B17-2A18-A338-2A4-2AD11-2AD2-5A9-4A2-5A9-A3E2-4A18-A113-ADAB3-ADF10-C-2A3-C-B10-A-A2C2-C-F10-A-A2C2-C2A10-AD2EF2-C2A10-ADAEF2-2A11-ABAEC3-A11-ABA2C3-A11-2(3BEA15-)BA2-A117-2(4A15-B)5A13-5A2B2(13-7A)11-BAB6A2D9-BAB4A2-BD9-7A2-2A9-8A-2A10-2A4-4A107-ADG-2C-2G-C2AE6-CBG-EC-GA-2ACE6-2AG-2C2-A2C3A7-AG-2C2-AC4A7-AG-C3-G4AE7-2D-C3-G2(AB)C7-BD-C3-A2C2AC8-D-C3-A2C3A10-C-BA-2C2AB10-A2BCF2C2A10-C-ABCAD3A10-C3BABF3A10-5ABF2A12-5ABA13-5A2BA12-7A12-9A11-3A3-2AB11-3A4-2A3(11-2A5-BA)10-2B7-2D9-A9-D8-2A9-BA7-4AB3AB2-2A8-3A5-2B2A18-BA86-6A-2A2C-GAB5-C-AB2A2-AEC2-EB5-C-2B2C2-AE3-CA5-CE2BA3-AE3-HA5-5A3-DE3-EA5-4AC3-DE3-CA5-4AD3-AE3-CA5-2B2AC3-AE3-2A5-BA2BA3-D-C-D2A6-A2BA5-C-2A7-AB2A5-A-FA7-B2A6-A-AB8-B2A5-4A8-ABA5-3A9-2BA2(5-3A9-3A)6-5(2A9-2A7-)2A9-B2(A8-)2A9-A8-2A9-AB7-A11-B7-2A10-A7-2A9-BA18-2A18-A45-2DA6-2A4-2(2A-)DA13-B-2A-DA13-A-A2-FA13-A2(4-FA13-B)4-DA13-B4-DB13-A4-D-B12-A2(5-BA11-2A)5-B-D10-2A6-AB4(9-2A7-2A)11(9-A)8-2(2A9-2A7-)3(A11-A7-)A19-A11-A7-A10-2A18-2A24-BA13-2A-2ABD14-2A-2AD14-BA-2AF14-D2ABAF14-D2A-AB2(14-B2A2-A)14-J2A2-AB2(13-BA3-2A)13-A3(5-2A11-2A)6-2(A11-A7-)2A9-2A7-2A6(9-A)9-2A8-A9-2A7-2A9-2A3(7-A11-A)7-A59-A19-2A9-2A18-A5-A15-5A15-A2-2(2A16-A-)AC16-2A-2C2(15-2A2-C)15-2A2-2(A15-A3-)2A13-2A3-2A13-2A4-A13-B5-B12-2A5-B2(A11-A7-)A10-2A7-2A9-2A8-5(A9-)2A8-A9-2A7-2A10-3(A7-A11-)A87-2A18-2A9-A5-A16-4A16-A-2A16-4A16-5A2(15-2A-AC)15-2A-2A15-A3(3-A14-2A)3-2A13-A4-BD13-A5-A12-2A5-2A11-A7-A11-A7-2A9-2A7-2A2(9-A)8-2A5(9-A)9-2A7-2A9-2A2(7-A11-A)128-A9-A5-D16-A-AB16-2A-3(B16-A2-)A16-A2-BH15-A2-2A15-A2-DA14-2A2-B2(A14-A4-)2A12-2A4-2A12-2A5-2A11-A6-2A11-A7-2A9-2A7-2A8-A-A8-2A7-2A9-2A6-3A3(9-2A7-2A)9-A2(9-2A7-2A)9-2A118-BA8-A9-A5-2D14-AB2-A15-2B2-B15-AB2-BA15-B2-B15-2B2-2A14-DB2-2A2(14-BA3-A)14-B2(4-2A13-A)4-AB12-2A5-2B11-A6-BA10-2A7-2A9-2A7-2A8-2A9-9A-A9-10A11-5AB2A12-5AB3A11-9A10-3A-7A9-3A-2A2B3A9-2A3-6A9-ABA-2ABDABA9-AB8-B10-A8-3(A19-)A9-3(2A8-)A5-2A13-DAD2-AC13-2A3-2C13-A-B2-2A13-BDB2-2A14-D2(4-A14-B)2(4-2A13-C)4-2A13-A5-B12-CE5-2B11-A6-2B10-2A7-2A9-2A7-A-A2-4A2BA9-8A2BA10-7ABA72-3A3-A13-7A13-B6A12-9A11-2B3AB3A11-B2(19-A)8-C10-A8-A10-A8-C9-2A35-ECA9-3AEI3-CB10-2(A-)E3-CA13-IE3-2A13-IK3-2A13-EC3-2A13-E4-2A2(13-C5-A)D11-BC5-BD11-2A5-2F10-2A6-F-A9-2A7-3A7-2A9-6ABAB2A9-8ABA12-2A334-A-2A-D2A3-ADB2A4-B5-A4-AF2-E4-A5-A4-A2D-E4-A5-A4-CB2DK4-A10-CB2DB4-A6-2(A3-AB2D5-2B5-)H3-2ABD6-AB4-H3-2AB7-2A8-3A7-2(2A8-)4A-2AF-2BA9-6A4B11-5ABA2B368-2F2AD2(3A-)B2D4-BAEA-E2A-CAC-BD5-3AB-E2A-C2A-DA5-AC2A-CAF-3C8-A2CA-C2A-A2C8-2AB4A-4C9-9A2C9-A2B-7A9-A2BF7A10-2B8A10-6A4B11-5A4B13-A2-3B389-2A-AD2ABDA-F8-2A-A-EA2BC2A8-A2-2FEAB2C2A11-FJCAB2CD12-F3ABACD12-A-4A-F13-2A17-B2(2A18-)2A458-FD17-A2B2(18-2A)18-A19-B533-
