model
size = 30 31 24, scale = 0.05, origin = -y
material 
  colors = A:#777 B:#39C C:#F3C D:#F6F E:#888 F:#FCC G:#FFF H:#F3F I:#FF3 J:#FCF K:#FF0 L:#FF6 M:#F90 N:#F66 O:#FFC P:#FC6 Q:#FC9 R:#FF9 S:#F0C T:#F09
voxels
------------------------------ ------------------------------ ------------------------------ ------------------------------ ----DCCCCCCCG--HCC------HCC--- ---CBBBBBBBBBC-LBBB----DBBH--- --CBBCDDDDDBBBP-OBBC--JBBB---- -LBBMJ------KBB--CBBG-BBB----- -DBCDBC------BBK--BBBBBBL----- -CBKOBBBI----DBN---BBBBM------ -CBF-KBBBT---GBQ---HBBB------- -CBF---BBBH--GBQ--FBBBBH------ -CBF----CBBB-NBD--BBBBBBK----- -HBG-----GBBGCBR-BBBI-BBBL---- -JBB------IBKBBI-BBG---BBB---- --BBBI-----FBBBKBBC----JBBC--- --FBBBBBBBBBBB---------------- ---IBBBBBBBBB----------NPBK--- ------IFFFI------------IJBB--- --JNG---------------------BI-- -DBIGBK-BBCBBBL-BBCCBCHBBBBMM- -CG--BBLBR-BG-C-BH--B--B--BO-- -DBI-BB-BC-BC-FK-C--B--B--BC-- --F--BB-CB-CB-BQ-B--BJ-BM-CB-- ----BBF-GB-RB-BC-BO-BP-CB-DB-- ---BBF--IC--C-BH--CCCH--NCHCL- ---BG------------------------- ---BK-SJ---------------------- ----CGH----------------------- ------------------------------ ------------------------------ 
------------------------------ ------------------------------ ------------------------------ ------------------------------ ----DCCCCCCCG--HCC------HCC--- ---CBBBBBBBBBC-LBBB----DBBH--- --CBBCDDDDDBBBP-OBBC--JBBB---- -LBBMJ------KBB--CBBG-BBB----- -DBCDBC------BBK--BBBBBBL----- -CBKOBBBI----DBN---BBBBM------ -CBF-KBBBT---GBQ---HBBB------- -CBF---BBBH--GBQ--FBBBBH------ -CBF----CBBB-NBD--BBBBBBK----- -HBG-----GBBGCBRABBBI-BBBL---- -JBB------IBKBBIABBG---BBB---- --BBBI-----FBBBKBBC----JBBC--- --FBBBBBBBBBBBAAA------------- ---IBBBBBBBBBAAAA------NPBK--- ------IFFFI--AAAA------IJBB--- --JNG--------AAAA---------BI-- -DBIGBK-BBCBBBLABBCCBCHBBBBMM- -CG--BBLBR-BGACABH--B--B--BO-- -DBI-BB-BC-BCAFKAC--B--B--BC-- --F--BB-CB-CB-BQ-B--BJ-BM-CB-- ----BBF-GB-RB-BC-BO-BP-CB-DB-- ---BBF--IC--C-BH--CCCH--NCHCL- ---BG------------------------- ---BK-SJ---------------------- ----CGH----------------------- ------------------------------ ------------------------------ 
------------------------------ ------------------------------ ------------------------------ ------------------------------ ----DCCCCCCCG--HCC------HCC--- ---CBBBBBBBBBC-LBBB----DBBH--- --CBBCDDDDDBBBP-OBBC--JBBB---- -LBBMJ------KBB--CBBG-BBB----- -DBCDBC------BBKA-BBBBBBL----- -CBKOBBBI----DBNA--BBBBM------ -CBF-KBBBT---GBQA--HBBB------- -CBF---BBBH--GBQA-FBBBBH------ -CBF----CBBB-NBDA-BBBBBBK----- -HBG-----GBBG----BBBI-BBBL---- -JBB------IBK----BBG---BBB---- --BBBI----AFB----BCA---JBBC--- --FBBBBBBBBBB----AAA---------- ---IBBBBBBBBB----AAA---NPBK--- ------IFFFIAA----AAA---IJBB--- --JNG-----AAA----AAA------BI-- -DBIGBK-BBCBB----BCCBCHBBBBMM- -CG--BBLBRABG----HAAB--B--BO-- -DBI-BB-BCABC----CAAB--B--BC-- --F--BB-CB-CBABQAB--BJ-BM-CB-- ----BBF-GB-RBABCABO-BP-CB-DB-- ---BBF--IC--CABHA-CCCH--NCHCL- ---BG------------------------- ---BK-SJ---------------------- ----CGH----------------------- ------------------------------ ------------------------------ 
--------------AA-------------- -------------AAAA------------- -------------AAAA------------- -------------AAAA------------- ----DCCCCCCCGAAHCC------HCC--- ---CBBBBBBBBBCALBBB----DBBH--- --CBBCDDDDDBBBPAOBBC--JBBB---- -LBBMJ------KBBAACBBG-BBB----- -DBCDBC---AAA----ABBBBBBL----- -CBKOBBBI-AAA----AABBBBM------ -CBF-KBBBTAAA----AAHBBB------- -CBF---BBBHAA----AFBBBBH------ -CBF----CBBBA----ABBBBBBK----- -HBG----AG----------IABBBL---- -JBB----AA----------AA-BBB---- --BBBI--AA----------AA-JBBC--- --FBBBBBBB----------AA-------- ---IBBBBBB----------AA-NPBK--- ------IFFF----------AA-IJBB--- --JNG---AA----------AA----BI-- -DBIGBK-BB----------BCHBBBBMM- -CG--BBLBR----------BA-B--BO-- -DBI-BB-BC----------BA-B--BC-- --F--BB-CBACB-BQ-BAABJ-BM-CB-- ----BBF-GBARB-BC-BOABP-CB-DB-- ---BBF--ICAAC-BH-ACCCH--NCHCL- ---BG--------AAAA------------- ---BK-SJ-----AAAA------------- ----CGH------AAAA------------- -------------AAAA------------- -------------AAAA------------- 
--------------AA-------------- ------------AAAAAA------------ ----------AAAAAAAAAA---------- ----------AAAA--AAAA---------- ----DCCCCC--------AA----HCC--- ---CBBBBBB---------A---DBBH--- --CBBCDDDD---------B--JBBB---- -LBBMJ----AA--------B-BBB----- -DBCDBC-AA-----------BBBL----- -CBKOBBBIA------------BM------ -CBF-KBBBT------------B------- -CBF---BBB------------BH------ -CBF----C-------------BBK----- -HBGAAAA--------------BBBL---- -JBBAAAA--------------ABBB---- --BBBIAA--------------AJBBC--- --FBBBBB--------------AAAA---- ---IBBBB--------------ANPBK--- ----AAIF--------------AIJBB--- --JNGAAA--------------AAAABI-- -DBIGBKA--------------HBBBBMM- -CG-ABBL--------------ABAABO-- -DBIABBA--------------ABAABC-- --F--BB-CB----------BJ-BM-CB-- ----BBF-GB----------BP-CB-DB-- ---BBF--IC----------CH--NCHCL- ---BG-----AAA----AAA---------- ---BK-SJ--AAAA--AAAA---------- ----CGH---AAAAAAAAAA---------- ----------AAAAAAAAAA---------- ------------AAAAAA------------ 
------------------------------ ------------A----A------------ ----------AAA----AAA---------- --------AAAAA----AAAAA-------- ----DCCC----------AAAA--HCC--- ---CBBBB------------AA-DBBH--- --CBBCDD------------AAJBBB---- -LBBMJ--AA-----------A--B----- -DBCDBCA-----------------A---- -CBKOBB-----------------AA---- -CBFAKB----------------AAA---- -CBFAAA-----------------AA---- -CBFAAAA-----------------A---- -HBGA---------------------AAA- -JBB----------------------AAA- -ABB----------------------CAA- -AFB----------------------AAA- AAAI-----------------------AAA AAAA-----------------------AAA AAJN-----------------------IAA ADBI-----------------------MMA ACGA-----------------------OAA ADBI-----------------------CAA --F-ABBA--------------ABMACB-- ----BBFA--------------ACBADB-- ---BBFAA--------------AANCHCL- ---BG---AAAA------AAAA-------- ---BK-SJAAAAA----AAAAA-------- ----CGH-AAAAA----AAAAA-------- ----------AAA----AAA---------- ------------A----A------------ 
------------------------------ ------------------------------ ------------------------------ --------AA----------AA-------- ----DCCC------------AAAAHCC--- ---CBBBB------------AAADBBH--- --CBBCDD--------------JBBB---- -LBBMJAA----------------BA---- -DBC--C------------------AA--- -CBK--------------------AAAA-- -CBFA---------------------AA-- -CBFA---------------------AA-- -CBFA---------------------AA-- -HBG----------------------AAA- -JBB----------------------AAA- -ABB----------------------CAA- -AFB----------------------AAA- AAAI-----------------------AAA AAA------------------------AAA AAJ------------------------IAA ADB------------------------MMA ACG------------------------OAA ADBI-----------------------CAA AAFAA--------------------ACBAA AAAABBFA--------------A--ADBAA --ABBFAA--------------AANCHCL- ---BGAAAAA----------AAAAAA---- ---BK-SJAA----------AAAA------ ----CGH-AA----------AA-------- ------------------------------ ------------------------------ 
------------------------------ ------------------------------ ------------------------------ ------------------------------ ------AA--------------AA------ ----AAAA--------------AAAA---- ---AAAAA--------------AAAAA--- ---AAA------------------AAA--- --------------------------A--- --AA----------------------AA-- --AA----------------------AA-- --AA----------------------AA-- --AA----------------------AA-- --AA----------------------AA-- --AA----------------------AA-- --AA----------------------AA-- --AA----------------------AA-- -AA------------------------AA- -AA------------------------AA- -AA------------------------AA- -AA------------------------AA- -AA------------------------AA- -AA------------------------AA- AAAA----------------------AAAA AAAA----------------------AAAA --AA----------------------AA-- ----AAAA--------------AAAA---- ------AA--------------AA------ ------------------------------ ------------------------------ ------------------------------ 
------------------------------ ------------------------------ ------------------------------ ------------------------------ ------------------------------ ------------------------------ --------------------------A--- ---A----------------------A--- ---A----------------------A--- --AA----------------------AA-- --AA----------------------AA-- --AA----------------------AA-- --AA----------------------AA-- --AA----------------------AA-- --AA----------------------AA-- --AA----------------------AA-- --AA----------------------AA-- -AA------------------------AA- -AA------------------------AA- -AA------------------------AA- -AA------------------------AA- -AA------------------------AA- -AA------------------------AA- AAA------------------------AAA AAA------------------------AAA ------------------------------ ------------------------------ ------------------------------ ------------------------------ ------------------------------ ------------------------------ 
------------------------------ ------------------------------ ------------------------------ ------------------------------ ------------------------------ ------------------------------ ---A----------------------A--- ---A----------------------A--- ---A----------------------A--- --AA----------------------AA-- --AA----------------------AA-- --AA----------------------AA-- --AA----------------------AA-- --AA----------------------AA-- --AA----------------------AA-- --AA----------------------AA-- --AA----------------------AA-- -AA------------------------AA- -AA------------------------AA- -AA------------------------AA- -AA------------------------AA- -AA------------------------AA- -AA------------------------AA- AAA------------------------AAA AAA------------------------AAA ------------------------------ ------------------------------ ------------------------------ ------------------------------ ------------------------------ ------------------------------ 
------------------------------ ------------------------------ ------------------------------ ------------------------------ ------------------------------ ------------------------------ ---A----------------------A--- ---A----------------------A--- ---A----------------------A--- --AA----------------------AA-- --AA----------------------AA-- --AA----------------------AA-- --AA----------------------AA-- --AA----------------------AA-- --AA----------------------AA-- --AA----------------------AA-- --AA----------------------AA-- -AA------------------------AA- -AA------------------------AA- -AA------------------------AA- -AA------------------------AA- -AA------------------------AA- -AA------------------------AA- AAA------------------------AAA AAA------------------------AAA ------------------------------ ------------------------------ ------------------------------ ------------------------------ ------------------------------ ------------------------------ 
------------------------------ ------------------------------ ------------------------------ ------------------------------ ------------------------------ ------------------------------ ---A----------------------A--- ---A----------------------A--- ---A----------------------A--- --AA----------------------AA-- --AA----------------------AA-- --AA----------------------AA-- --AA----------------------AA-- --AA----------------------AA-- --AA----------------------AA-- --AA----------------------AA-- --AA----------------------AA-- -AA------------------------AA- -AA------------------------AA- -AA------------------------AA- -AA------------------------AA- -AA------------------------AA- -AA------------------------AA- AAA------------------------AAA AAA------------------------AAA ------------------------------ ------------------------------ ------------------------------ ------------------------------ ------------------------------ ------------------------------ 
------------------------------ ------------------------------ ------------------------------ ------------------------------ ------------------------------ ------------------------------ ------------------------------ ---A----------------------A--- ---A----------------------A--- --AA----------------------AA-- --AA----------------------AA-- --AA----------------------AA-- --AA----------------------AA-- --AA----------------------AA-- --AA----------------------AA-- --AA----------------------AA-- --AA----------------------AA-- -AA------------------------AA- -AA------------------------AA- -AA------------------------AA- -AA------------------------AA- -AA------------------------AA- -AA------------------------AA- AAA------------------------AAA AAA------------------------AAA ------------------------------ ------------------------------ ------------------------------ ------------------------------ ------------------------------ ------------------------------ 
------------------------------ ------------------------------ ------------------------------ ------------------------------ ------------------------------ ------------------------------ ------------------------------ ---A----------------------A--- ---A----------------------A--- --AA----------------------AA-- --AA----------------------AA-- --AA----------------------AA-- --AA----------------------AA-- --AA----------------------AA-- --AA----------------------AA-- --AA----------------------AA-- --AA----------------------AA-- -AA------------------------AA- -AA------------------------AA- -AA------------------------AA- -AA------------------------AA- -AA------------------------AA- -AA------------------------AA- AAA------------------------AAA AAA------------------------AAA ------------------------------ ------------------------------ ------------------------------ ------------------------------ ------------------------------ ------------------------------ 
------------------------------ ------------------------------ ------------------------------ ------------------------------ ------------------------------ ------------------------------ ------------------------------ ---A----------------------A--- ---A----------------------A--- --AA----------------------AA-- --AA----------------------AA-- --AA----------------------AA-- --AA----------------------AA-- --AA----------------------AA-- --AA----------------------AA-- --AA----------------------AA-- --AA----------------------AA-- -AA------------------------AA- -AA------------------------AA- -AA------------------------AA- -AA------------------------AA- -AA------------------------AA- -AA------------------------AA- AAA------------------------AAA AAA------------------------AAA ------------------------------ ------------------------------ ------------------------------ ------------------------------ ------------------------------ ------------------------------ 
------------------------------ ------------------------------ ------------------------------ ------------------------------ ------------------------------ ------------------------------ ------------------------------ ---A----------------------A--- ---A----------------------A--- --AA----------------------AA-- --AA----------------------AA-- --EA----------------------AE-- --EA----------------------AE-- --EA----------------------AE-- --EA----------------------AE-- --AA----------------------AA-- --AA----------------------AA-- -AA------------------------AA- -AA------------------------AA- -EA------------------------AE- -EA------------------------AE- -AA------------------------AA- -AA------------------------AA- AAA------------------------AAA AAA------------------------AAA ------------------------------ ------------------------------ ------------------------------ ------------------------------ ------------------------------ ------------------------------ 
------------------------------ ------------------------------ ------------------------------ ------------------------------ ------------------------------ ------------------------------ ------------------------------ ---A----------------------A--- ---A----------------------A--- --AA----------------------AA-- --EA----------------------AE-- ------------------------------ ------------------------------ ------------------------------ ------------------------------ --EA----------------------AE-- --AA----------------------AA-- -AA------------------------AA- -EA------------------------AE- ------------------------------ ------------------------------ -EA------------------------AE- -AA------------------------AA- AAA------------------------AAA AAA------------------------AAA ------------------------------ ------------------------------ ------------------------------ ------------------------------ ------------------------------ ------------------------------ 
------------------------------ ------------------------------ ------------------------------ ------------------------------ ------------------------------ ------------------------------ ------------------------------ ------------------------------ ---A----------------------A--- --EA----------------------AE-- ------------------------------ ------------------------------ ------------------------------ ------------------------------ ------------------------------ ------------------------------ --EA----------------------AE-- -EA------------------------AE- ------------------------------ ------------------------------ ------------------------------ ------------------------------ -EA------------------------AE- AAA------------------------AAA AAA------------------------AAA ------------------------------ ------------------------------ ------------------------------ ------------------------------ ------------------------------ ------------------------------ 
------------------------------ ------------------------------ ------------------------------ ------------------------------ ------------------------------ ------------------------------ ------------------------------ ------------------------------ ---A----------------------A--- --EA----------------------AE-- ------------------------------ ------------------------------ ------------------------------ ------------------------------ ------------------------------ ------------------------------ --EA----------------------AE-- -EA------------------------AE- ------------------------------ ------------------------------ ------------------------------ ------------------------------ -EA------------------------AE- AAA------------------------AAA AAA------------------------AAA ------------------------------ ------------------------------ ------------------------------ ------------------------------ ------------------------------ ------------------------------ 
------------------------------ ------------------------------ ------------------------------ ------------------------------ ------------------------------ ------------------------------ ------------------------------ ------------------------------ ---A----------------------A--- --EA----------------------AE-- ------------------------------ ------------------------------ ------------------------------ ------------------------------ ------------------------------ ------------------------------ --EA----------------------AE-- -EA------------------------AE- ------------------------------ ------------------------------ ------------------------------ ------------------------------ -EA------------------------AE- AAA------------------------AAA AAA------------------------AAA ------------------------------ ------------------------------ ------------------------------ ------------------------------ ------------------------------ ------------------------------ 
------------------------------ ------------------------------ ------------------------------ ------------------------------ ------------------------------ ------------------------------ ------------------------------ ------------------------------ ---A----------------------A--- --EA----------------------AE-- ------------------------------ ------------------------------ ------------------------------ ------------------------------ ------------------------------ ------------------------------ --EA----------------------AE-- -EA------------------------AE- ------------------------------ ------------------------------ ------------------------------ ------------------------------ -EA------------------------AE- AAA------------------------AAA AAA------------------------AAA ------------------------------ ------------------------------ ------------------------------ ------------------------------ ------------------------------ ------------------------------ 
------------------------------ ------------------------------ ------------------------------ ------------------------------ ------------------------------ ------------------------------ ------------------------------ ------------------------------ ------------------------------ --AA----------------------AA-- --EA----------------------AE-- ------------------------------ ------------------------------ ------------------------------ ------------------------------ --EA----------------------AE-- --AA----------------------AA-- -AA------------------------AA- -EA------------------------AE- ------------------------------ ------------------------------ -EA------------------------AE- -AA------------------------AA- ------------------------------ ------------------------------ ------------------------------ ------------------------------ ------------------------------ ------------------------------ ------------------------------ ------------------------------ 
------------------------------ ------------------------------ ------------------------------ ------------------------------ ------------------------------ ------------------------------ ------------------------------ ------------------------------ ------------------------------ ------------------------------ --AA----------------------AA-- --EA----------------------AE-- --EA----------------------AE-- --EA----------------------AE-- --EA----------------------AE-- --AA----------------------AA-- ------------------------------ ------------------------------ -AA------------------------AA- -EA------------------------AE- -EA------------------------AE- -AA------------------------AA- ------------------------------ ------------------------------ ------------------------------ ------------------------------ ------------------------------ ------------------------------ ------------------------------ ------------------------------ ------------------------------ 
------------------------------ ------------------------------ ------------------------------ ------------------------------ ------------------------------ ------------------------------ ------------------------------ ------------------------------ ------------------------------ ------------------------------ ------------------------------ ------------------------------ ------------------------------ ------------------------------ ------------------------------ ------------------------------ ------------------------------ ------------------------------ ------------------------------ -AA------------------------AA- -AA------------------------AA- ------------------------------ ------------------------------ ------------------------------ ------------------------------ ------------------------------ ------------------------------ ------------------------------ ------------------------------ ------------------------------ ------------------------------ 
