model
size = 16 31 10, scale = 0.05, origin = -y
material 
  colors = A:#6C7BC7 B:#2495CD C:#34ABD4 D:#6646A7 E:#3249B8 F:#A34686 G:#F9496B
voxels
---------------- ---------------- ---------------- ---------------- ---------------- ---------------- ---------------- ---------------- ---------------- ---------------- ---------------- ---------------- ---------------- ---------------- ---------------- ---------------- ---------------- ---------------- ---------------- ---------------- ---------------- ---------------- ---------------- ---------------- ---------------- ---------------- ---------------- ---------------- -------AA------- -------AA------- ---------------- 
---------------- -A-AA------AA-A- -AAA-------AAAA- ---------------- ---------------- ---------------- ---------------- ---------------- ---------------- ---------------- ---------------- ---------------- ---------------- ---------------- ---------------- ---------------- ---------------- ---------------- ---------------- ---------------- -----------AA--- ----A------AA--- ----AA----AAA--- ---AAAA--AAAA--- ---AAAA--AAAA--- ---AAAAAAAAAA--- ---AAAAAAAAAA--- ---AAAAAAAAAA--- ----AAAAAAAAA--- ----AAAAAAAAA--- ----------AA---- 
-A-A------------ AA-AA------AA-AA A-AAA------AAAAA -AAAA------AAACC ---------------- ---------------- ---------------- ---------------- ---------------- ---------------- ---------------- ---------------- ---------------- ---------------- ---------------- ---------------- ---------------- -----------AA--- ---AAA----AAA--- --AAAA----AAAA-- --AAAA---AAAAA-- --AAAAA--AAAAA-- --AAAAAA-AAAAA-- --AA--AAAA--AA-- --AA--AAAA--AA-- --AA--A--A--AA-- --AA---AA---AA-- --A-A-------AA-- ---AA-------AA-- ---AAA-----AA--- ---AA-----DAA--- 
-A-AA------A---- AA-AA------AA-AA AA--A-----AA---A A-AAA-----A-AACA -AAA------AAAAAA -A---------AAAAA ------------A--- ---------------- ---------------- ---------------- ---------------- ---------------- ---------------- ---------------- ---AA------AAA-- --AAA-----AAAA-- --AAAA----AAAA-- --AAAA----AAAA-- --AAAA----A-AA-- --AA-AA--AA--A-- --A--AA--AA--A-- --A---AA-A---A-- --A---A-AA---A-- --A----AA----A-- --A----AA----A-- --A----AA----A-- --A----------A-- --AA---------A-- --AA--------AA-- --AA--------AA-- ---A-------GA--- 
-A-AA------AA--- AA--A------AA-AA A---A------A---A AA-A-A----AA---A A-AAAA----A-AAAA A-AA------A-AAAA AAA-------AAAAAA AAA-------AAAAAA A-A--------AAAAB -AA--------AAAA- -AA---------AAA- -AAA-------AAAA- -AAA-------AAAA- -AAAA-----AAAAA- -AAAA-----AAAAA- -AAAAA----A--AA- -AA-AA----A--AA- -AA--A---AA--AA- -AA--AA--AA--A-- -AA---A--A---A-- -AA---A--A---A-- -AA---AAAA---A-- -AA----A-A---A-- -AA----AA----A-- -AA----AA----A-- -AA----------A-- --A----------A-- --A----------A-- --A----------A-- --AA--------AA-- ---AF------EA--- 
-A-AA------AA--- -A-AA------A--AA BA--A------A---A AA--A------A---A AA--A------A---A A-AAA------A---A A-AAA-----AA---A A-AA-------A--AA AAAA-------A--AA AAAA-------AA-AA AAAA-------AA-AA AAAAA-----AA--AA AA-AA-----AA--A- -AAAA-----AA--A- -AA-AA----A---A- -A---A----A---A- -A---A----A---A- -A---A---AA--AA- -A---AA--A---A-- -AA---A--A---A-- -AA---A--A---A-- -AA---AAAA---A-- -AA---A-A----A-- -AA----AA----A-- -AA----AA----A-- -AA----------A-- --A----------A-- --AA---------A-- --AA--------AA-- ---A--------AA-- ---AF------EA--- 
-A-AA------AA-AA -A-AA------A--AA -A--A------A--AA -A--A------AA-AA -A--A------AA-AA -A--A------A--AA AA-AA------A--AA AA-AA------A--AA A--AA------A--AA A--AA------A--AA A--AA-----AA--AA A---A-----AA--AA AA--A-----AA--A- -A--A-----AA--A- -A--AA----AA-AA- -A---A----A--AA- -A---A----A--AA- -AA--A----A-A-A- -AA--AA--AA-AA-- --A--AA--AA-AA-- --A--AA--AA-AA-- --A---A-AAA-AA-- --A---AAAA--AA-- --A---A-AA--AA-- --A----AAA--AA-- --A---------AA-- --AA--------AA-- --AA--------AA-- ---A--------A--- ---AA------AA--- ---AAEE-DDD-A--- 
AAAAA------AACAA A-AA-------A-A-A -AAAA------AAA-A -A-AA------A-A-A -A-AA------A-A-A -A-AA------AAA-A -A-CA------AAA-B -A-AA------AAA-B AA-AA------AAAA- AA-AA------AAAA- AA-AA------AAAAA AA-AA------AAAA- AA-AA------AAAA- -AAAA------AAAA- -AAAAA----AAAAA- -AAAAA----AAAA-- -AAAAA----AAAA-- --AAAA----AAAA-- --AAAA----AAA--- --AAAA----AAA--- --AAAA----AAA--- --AAAAA---AAA--- --AAAAA--AAAA--- --AAAAAA-AAAA--- --AA--A-AAAAA--- --AA---CA--AA--- ---A-------AA--- ---AA------AA--- ---AA------AA--- ----AAAAAAA-A--- ----AADAAAAA---- 
AAA--------AAC-A A-A--------AAAAA A-A--------AAAAA A-BA--------AAAA A-AA--------AAAA -AAA-------AAAAA -AAA-------AAAA- -AAA--------AAA- -AAA--------AAA- -AAA--------AA-- -AAA--------AA-- -AAA--------AA-- -AAA--------AA-- -AAA------------ ---------------- ---------------- ---------------- ---------------- ---------------- ---------------- ---------------- ---------------- ---------------- ---AAA---------- ---AAAAA-AAA---- ---AAAAAAAAA---- ---AAAAAAAAA---- ----AAAAAAAA---- ----AAAAAAAA---- -----AAAAAAA---- ---------------- 
AAA------------- AAA------------- AAA------------- ABB------------- -BA------------- -A-------------- -A-------------- -A-------------- ---------------- ---------------- ---------------- ---------------- ---------------- ---------------- ---------------- ---------------- ---------------- ---------------- ---------------- ---------------- ---------------- ---------------- ---------------- ---------------- ---------------- ---------------- ------AAAA------ ------AAAA------ ------AAAA------ ---------------- ---------------- 
