model
size = 16 31 10, scale = 0.05, origin = -y
material 
  colors = A:#FBFB92
voxels
---------------- ---------------- ---------------- ---------------- ---------------- ---------------- ---------------- ---------------- ---------------- ---------------- ---------------- ---------------- ---------------- ---------------- ---------------- ---------------- ---------------- ---------------- ---------------- ---------------- ---------------- ---------------- ---------------- ---------------- ---------------- ---------------- ---------------- ---------------- -------AA------- -------AA------- ---------------- 
---------------- -A-AA------AA-A- -AAA-------AAAA- ---------------- ---------------- ---------------- ---------------- ---------------- ---------------- ---------------- ---------------- ---------------- ---------------- ---------------- ---------------- ---------------- ---------------- ---------------- ---------------- ---------------- -----------AA--- ----A------AA--- ----AA----AAA--- ---AAAA--AAAA--- ---AAAA--AAAA--- ---AAAAAAAAAA--- ---AAAAAAAAAA--- ---AAAAAAAAAA--- ----AAAAAAAAA--- ----AAAAAAAAA--- ----------AA---- 
-A-A------------ AA-AA------AA-AA A-AAA------AAAAA -AAAA------AAAAA ---------------- ---------------- ---------------- ---------------- ---------------- ---------------- ---------------- ---------------- ---------------- ---------------- ---------------- ---------------- ---------------- -----------AA--- ---AAA----AAA--- --AAAA----AAAA-- --AAAA---AAAAA-- --AAAAA--AAAAA-- --AAAAAA-AAAAA-- --AA--AAAA--AA-- --AA--AAAA--AA-- --AA--A--A--AA-- --AA---AA---AA-- --A-A-------AA-- ---AA-------AA-- ---AAA-----AA--- ---AA-----AAA--- 
-A-AA------A---- AA-AA------AA-AA AA--A-----AA---A A-AAA-----A-AAAA -AAA------AAAAAA -A---------AAAAA ------------A--- ---------------- ---------------- ---------------- ---------------- ---------------- ---------------- ---------------- ---AA------AAA-- --AAA-----AAAA-- --AAAA----AAAA-- --AAAA----AAAA-- --AAAA----A-AA-- --AA-AA--AA--A-- --A--AA--AA--A-- --A---AA-A---A-- --A---A-AA---A-- --A----AA----A-- --A----AA----A-- --A----AA----A-- --A----------A-- --AA---------A-- --AA--------AA-- --AA--------AA-- ---A-------AA--- 
-A-AA------AA--- AA--A------AA-AA A---A------A---A AA-A-A----AA---A A-AAAA----A-AAAA A-AA------A-AAAA AAA-------AAAAAA AAA-------AAAAAA A-A--------AAAAA -AA--------AAAA- -AA---------AAA- -AAA-------AAAA- -AAA-------AAAA- -AAAA-----AAAAA- -AAAA-----AAAAA- -AAAAA----A--AA- -AA-AA----A--AA- -AA--A---AA--AA- -AA--AA--AA--A-- -AA---A--A---A-- -AA---A--A---A-- -AA---AAAA---A-- -AA----A-A---A-- -AA----AA----A-- -AA----AA----A-- -AA----------A-- --A----------A-- --A----------A-- --A----------A-- --AA--------AA-- ---AA------AA--- 
-A-AA------AA--- -A-AA------A--AA AA--A------A---A AA--A------A---A AA--A------A---A A-AAA------A---A A-AAA-----AA---A A-AA-------A--AA AAAA-------A--AA AAAA-------AA-AA AAAA-------AA-AA AAAAA-----AA--AA AA-AA-----AA--A- -AAAA-----AA--A- -AA-AA----A---A- -A---A----A---A- -A---A----A---A- -A---A---AA--AA- -A---AA--A---A-- -AA---A--A---A-- -AA---A--A---A-- -AA---AAAA---A-- -AA---A-A----A-- -AA----AA----A-- -AA----AA----A-- -AA----------A-- --A----------A-- --AA---------A-- --AA--------AA-- ---A--------AA-- ---AA------AA--- 
-A-AA------AA-AA -A-AA------A--AA -A--A------A--AA -A--A------AA-AA -A--A------AA-AA -A--A------A--AA AA-AA------A--AA AA-AA------A--AA A--AA------A--AA A--AA------A--AA A--AA-----AA--AA A---A-----AA--AA AA--A-----AA--A- -A--A-----AA--A- -A--AA----AA-AA- -A---A----A--AA- -A---A----A--AA- -AA--A----A-A-A- -AA--AA--AA-AA-- --A--AA--AA-AA-- --A--AA--AA-AA-- --A---A-AAA-AA-- --A---AAAA--AA-- --A---A-AA--AA-- --A----AAA--AA-- --A---------AA-- --AA--------AA-- --AA--------AA-- ---A--------A--- ---AA------AA--- ---AAAA-AAA-A--- 
AAAAA------AAAAA A-AA-------A-A-A -AAAA------AAA-A -A-AA------A-A-A -A-AA------A-A-A -A-AA------AAA-A -A-AA------AAA-A -A-AA------AAA-A AA-AA------AAAA- AA-AA------AAAA- AA-AA------AAAAA AA-AA------AAAA- AA-AA------AAAA- -AAAA------AAAA- -AAAAA----AAAAA- -AAAAA----AAAA-- -AAAAA----AAAA-- --AAAA----AAAA-- --AAAA----AAA--- --AAAA----AAA--- --AAAA----AAA--- --AAAAA---AAA--- --AAAAA--AAAA--- --AAAAAA-AAAA--- --AA--A-AAAAA--- --AA---AA--AA--- ---A-------AA--- ---AA------AA--- ---AA------AA--- ----AAAAAAA-A--- ----AAAAAAAA---- 
AAA--------AAA-A A-A--------AAAAA A-A--------AAAAA A-AA--------AAAA A-AA--------AAAA -AAA-------AAAAA -AAA-------AAAA- -AAA--------AAA- -AAA--------AAA- -AAA--------AA-- -AAA--------AA-- -AAA--------AA-- -AAA--------AA-- -AAA------------ ---------------- ---------------- ---------------- ---------------- ---------------- ---------------- ---------------- ---------------- ---------------- ---AAA---------- ---AAAAA-AAA---- ---AAAAAAAAA---- ---AAAAAAAAA---- ----AAAAAAAA---- ----AAAAAAAA---- -----AAAAAAA---- ---------------- 
AAA------------- AAA------------- AAA------------- AAA------------- -AA------------- -A-------------- -A-------------- -A-------------- ---------------- ---------------- ---------------- ---------------- ---------------- ---------------- ---------------- ---------------- ---------------- ---------------- ---------------- ---------------- ---------------- ---------------- ---------------- ---------------- ---------------- ---------------- ------AAAA------ ------AAAA------ ------AAAA------ ---------------- ---------------- 
