model
size = 20 32 16, scale = 0.05, origin = -y
material 
  colors = A:#00E5FF B:#00C4CF C:#00BEB7 D:#3D84C5 E:#059CED F:#62C9CC
voxels
6-A3B4-2C10-2AB5-2B10-3B5-A11-A2B17-2A18-A338-2A4-2AC10-3AC2-5A9-4A2-5A9-4C2-4A11-A6-A113-ACAB3-A2C10-B-2A3-B-B10-A-A2B2-B-C10-A-A2B2-B2A10-A4C2-B2A10-ACA2C2-2A11-ABACB3-A11-ABA2B3-A11-2(3BCA15-)BA2-A117-2(4A15-B)5A13-5A2B2(13-7A)11-BAB6A2C9-BAB4A2-BC9-7A2-2A9-8A-2A10-2A4-4A107-ACA-2B-2A-B2AC6-2BA-CB2(-2A)BC6-3A-2B2-A2B3A7-2A-2B2-AB4A7-2A-B3-5AC7-2C-B3-2ABA2B7-BC-B3-A2B2AB8-C-B3-A2B3A10-B-BA-2B2AB10-A3BC2B2A10-B-A2BAC3A10-4BABC3A10-5ABC2A12-5ABA13-5A2BA12-7A12-9A11-3A3-2AB11-3A4-2A3(11-2A5-BA)10-2B7-2C9-A9-C8-2A9-BA7-4AB3AB2-2A8-3A5-2B2A18-BA86-6A-2A2B-2AB5-B-AB2A2-ACB2-CB5-B-4B2-AC3-BA5-BC2BA3-AC3-DA5-5A3-2C3-CA5-4AB3-2C3-BA5-4AC3-AC3-BA5-2B2AB3-AC3-2A5-BA2BA3-C-B-C2A6-A2BA5-B-2A7-AB2A5-A-CA7-B2A6-A-AB8-B2A5-4A8-ABA5-3A9-2BA2(5-3A9-3A)6-5(2A9-2A7-)2A9-B2(A8-)2A9-A8-2A9-AB7-A11-B7-2A10-A7-2A9-BA18-2A18-A45-2CA6-2A4-2(2A-)CA13-B-2A-CA13-A-A2-CA13-A3(4-CA13-B)4-CB13-A4-C-B12-A2(5-BA11-2A)5-B-C10-2A6-AB4(9-2A7-2A)11(9-A)8-2(2A9-2A7-)3(A11-A7-)A19-A11-A7-A10-2A18-2A24-BA13-2A-2ABC14-2A-2AC14-BA-2AC14-C2ABAC14-C2A-AB2(14-B2A2-A)14-F2A2-AB2(13-BA3-2A)13-A3(5-2A11-2A)6-2(A11-A7-)2A9-2A7-2A6(9-A)9-2A8-A9-2A7-2A9-2A3(7-A11-A)7-A59-A19-2A9-2A18-2A4-A15-5A15-A2-2(2A16-A-)AB16-2A-2B2(15-2A2-B)15-2A2-2(A15-A3-)2A13-2A3-2A13-2A4-A13-B5-B12-2A5-B2(A11-A7-)A10-2A7-2A9-2A8-5(A9-)2A8-A9-2A7-2A10-3(A7-A11-)A87-2A18-2A9-A5-A16-4A16-A-2A16-4A16-5A2(15-2A-AB)15-2A-2A15-A3(3-A14-2A)3-2A13-A4-BC13-A5-A12-2A5-2A11-A7-A11-A7-2A9-2A7-2A2(9-A)8-2A5(9-A)9-2A7-2A9-2A2(7-A11-A)128-A9-A5-C16-A-AB16-2A-3(B16-A2-)A16-A2-BD15-A2-2A15-A2-CA14-2A2-B2(A14-A4-)2A12-2A4-2A12-2A5-2A11-A6-2A11-A7-2A9-2A7-2A8-A-A8-2A7-2A9-2A6-3A3(9-2A7-2A)9-A2(9-2A7-2A)9-2A118-BA8-A9-A5-2C14-AB2-A15-2B2-B15-AB2-BA15-B2-B15-2B2-2A14-CB2-2A2(14-BA3-A)14-B2(4-2A13-A)4-AB12-2A5-2B11-A6-BA10-2A7-2A9-2A7-2A8-2A9-9A-A9-10A11-5AB2A12-5AB3A11-9A10-3A-7A9-3A-2A2B3A9-2A3-6A9-ABA-2ABCABA9-AB8-B10-A8-3(A19-)A9-3(2A8-)A5-2A13-CAC2-AB13-2A3-2B13-A-B2-2A13-BCB2-2A14-C2(4-A14-B)2(4-2A13-B)4-2A13-A5-B12-BC5-2B11-A6-2B10-2A7-2A9-2A7-A-A2-4A2BA9-8A2BA10-7ABA72-2(3A17-)B3A15-5A-A13-2B3AB2A12-B2(19-A)8-B10-A8-A10-A8-B9-2A35-CBA9-3ACE3-2B10-2(A-)C3-BA13-EC3-2A13-EA3-2A13-CB3-2A13-C4-2A2(13-B5-A)C11-2B5-BC11-2A5-2C10-2A6-C-A9-2A7-3A7-2A9-6ABAB2A9-8ABA12-2A334-A-2A-C2A3-ACB2A4-B5-A4-AC2-C4-A5-A4-A2C-C4-A5-A4-2B2CA4-A10-2B2CB4-A6-2(A3-AB2C5-2B5-)D3-2ABC6-AB4-D3-2AB7-2A8-3A7-2(2A8-)4A-2AC-2BA9-6A4B11-5ABA2B368-2C2AC2(3A-)B2C4-BACA-C2A-BAB-BC5-3AB-C2A-B2A-CA5-AB2A-BAC-3B8-A2BA-B2A-A2B8-2AB4A-4B9-9A2B9-A2B-7A9-A2BC7A10-2B8A10-6A4B11-5A4B13-A2-3B389-2A-ACA-BCA-C8-2A-A-C-3B2A8-A2-3C-3B2A11-CFB-3BC12-C2A-BABC12-2(A-)2A-C13-2A17-B2(2A18-)2A458-2C17-A2B2(18-2A)18-A19-B533-
