model
size = 32 25 28, scale = 0.05, origin = -y
material 
  colors = A:#6C7BC7 B:#63CBE2 C:#6646A7 D:#A34686 E:#B64D85 F:#84F4B2 G:#AEFFA2 H:#FBFB92
voxels
467-2(6A26-)7A2(24-8A)25-6A30-2A560-4A3-10A2(14-18A)12-2(14A3-4A11-)14A3-4A14-2B2A3-11A23-9A24-7A25-7A408-5A27-5A17-18A11-20A-A2(10-6A-4A9-2A)9-5A4-3A10-2(3A8-4A3-6A8-)3A8-B3A2B7A8-3A8-14A6-A-2A8-22A10-22A21-10A28-3A345-5A27-5A17-18A11-20A-A2(10-6A-4A9-2A)9-5A4-3A10-2(3A8-4A3-6A8-)3A8-B3A2B7A8-3A8-14A6-A-2A8-22A10-22A21-10A28-3A118-5B27-5B25-9A22-2(11A20-B)11A20-2B10A17-17A15-17A12-13A4-4A10-A-2A17-4A2(7-2A20-3A)3(7-2A21-2A)7-2B21-2(2A7-)3A10-2(3A7-A-12A8-)3A8-17A-6A9-17A3CA78-2B2A10B18-2(3A13B16-)6A4-6A16-4A7-5A2(15-5A9-3A)13-5AB10-4A11-7A11-4A10-7A11-4A9-A-2A17-4A5-2A-A20-3A5-7(3A22-3A4-)4A21-3A4-4A21-3A6-4A7-A10-A2-A6-5A3DC3A4D2E4D3C76-2B2A10B18-2(3A13B16-)6A4-6A16-4A7-5A2(15-5A9-3A)13-5AB10-4A11-7A11-4A10-7A11-4A9-A-2A17-4A5-2A-A20-3A5-7(3A22-3A4-)4A21-3A4-4A21-3A6-4A7-A10-A2-A6-5A3DC3A4D2E4D3C75-7B5-2B3A13-2(3B2A11-A2-A12-)2(5A12-3A12-)3A14-4A11-3A14-4A10-A2-A16-2A9-A-2A17-A-2A7-A-2A17-A-2A5-2A-A20-3A5-3A22-2(3A4-2A23-)3A5(3-3A25-A)2(4-2A25-A)4-3A22-3C4-3AD2E5-3D85-6B11-4A11-2(3B14-3A-B10-)2(3A17-2A10-)3A18-A10-3A18-A9-A-2A18-2(3A7-2A20-)3A5-3A22-3A4-2A23-3A3(3-3A25-A)2(3-A27-A)3-4(3A25-3A-)A2-D24-3D2-2DE95-2(4B17-2B9-2(2B19-B-2B7-)4(2A20-3A7-)2A21-2A5-2(3A22-3A4-)2A23-3A3-3A25-A3-2(3A25-3A-)3(A27-3A-)4(A28-2A-)A2D25-3D100-)2B30-2(2B19-4B7-)2A21-3A6-A5(22-3A4-3A)22-3A3-3A25-A3-3A25-2(3A-A27-)3A3(-A28-2A)-A28-4A28-2(3A-2E25-D)2A-C2E25-3D98-2(4B28-2(3B21-4A4-)2(3A24-A4-)4(2A25-A4-)2A25-A3-3A25-3A-A27-3A2(-A28-2A)-A5(28-4A)27-D2C2A27-D2C130-)3B29-2(2B23-3A4-)4(2A25-A4-)2A25-A3-3(3A25-3A-)2(A28-2A-)A3(28-4A)28-2(3A29-)2(2CAD27-D)2C130-3B22-2(3A4-2B23-)3A4(4-2A25-A)3-3A25-A3-2(3A25-3A-)3(A28-2A-)A28-4A28-3(3A29-)3AD27-D3CD27-3DCD27-3D130-2(3B22-3B2(4-2B25-B)5(4-2A25-A)3-2(3A25-3A-)3(A28-2A-)A28-4A28-3(3A29-)3AD27-3C194-)2BFH20-G3B2(4-2B23-2AB)5(4-2A25-A)2(3-3A25-A)3-A27-3A3(-A28-2A)-A3(28-4A)28-2A2C27-2(3C194-3B3G17-G3B5-2(2BA21-A2-A4-)4(3A22-3A4-)2A23-3A2(3-3A25-A)3-2(3A25-3A-)2(A27-3A-)A2(28-4A)28-2AB-2C26-2A-3C25-)3C196-4BF6-3BF3-G2F2B9-3(2A20-3A7-)2A20-2(3A5-3A21-)3A5-3(3A22-3A4-)2A23-3A3-3A25-A3-5(3A25-3A-)3AD22-2C3A27-5C143-C2A2B2FB24-C2A2B2FB14-4B2F15B11-2(3A8-2BA4-4A10-)3A8-3A4-4A9-A-2A17-2A9-2(2A19-4A7-)2(2A20-3A7-)2A20-3A5-3A21-3A5-3(3A22-3A4-)3(2A23-3A4-)2AC21-C2-C29-2C203-8B3-A3B15-2(9A3B7A13-)19A12-3(21A11-)3A4-15A2(9-4A7-5A3-4A)9-4A8-4A3-6A7-2A6(19-4A5-4A)2C8-4C3-6C235-8B3-A3B15-2(9A3B7A13-)19A12-3(21A11-)3A4-15A2(9-4A7-5A3-4A)9-4A8-4A3-6A7-2A6(19-4A5-4A)2C8-4C3-6C395-4A10-A17-4A10-A15-10A4-5A2(13-12A-6A)12-20A12-4(21A11-)2(22A10-)22A2(589-2(A15-)2(3A11-3A15-)4A9-4A13-2(6A9-6A11-)6B9-6B)165-
