model
size = 32 25 28, scale = 0.05, origin = -y
material 
  colors = A:#FBFB92
voxels
467-2(6A26-)7A2(24-8A)25-6A30-2A560-4A3-10A2(14-18A)12-2(14A3-4A11-)14A3-4A14-4A3-11A23-9A24-7A25-7A408-5A27-5A17-18A11-20A-A2(10-6A-4A9-2A)9-5A4-3A10-2(3A8-4A3-6A8-)3A8-13A8-3A8-14A6-A-2A8-22A10-22A21-10A28-3A345-5A27-5A17-18A11-20A-A2(10-6A-4A9-2A)9-5A4-3A10-2(3A8-4A3-6A8-)3A8-13A8-3A8-14A6-A-2A8-22A10-22A21-10A28-3A118-5A27-5A25-9A22-11A3(20-12A)17-17A15-17A12-13A4-4A10-A-2A17-4A2(7-2A20-3A)4(7-2A21-2A)7-2A7-3A10-2(3A7-A-12A8-)3A8-17A-6A9-21A78-14A18-2(16A16-)6A4-6A16-4A7-5A2(15-5A9-3A)13-6A10-4A11-7A11-4A10-7A11-4A9-A-2A17-4A5-2A-A20-3A5-7(3A22-3A4-)4A21-3A4-4A21-3A6-4A7-A10-A2-A6-25A76-14A18-2(16A16-)6A4-6A16-4A7-5A2(15-5A9-3A)13-6A10-4A11-7A11-4A10-7A11-4A9-A-2A17-4A5-2A-A20-3A5-7(3A22-3A4-)4A21-3A4-4A21-3A6-4A7-A10-A2-A6-25A75-7A5-5A13-2(5A11-A2-A12-)2(5A12-3A12-)3A14-4A11-3A14-4A10-A2-A16-2A9-A-2A17-A-2A7-A-2A17-A-2A5-2A-A20-3A5-3A22-2(3A4-2A23-)3A5(3-3A25-A)2(4-2A25-A)4-3A22-3A4-6A5-3A85-6A11-4A11-2(3A14-3A-A10-)2(3A17-2A10-)3A18-A10-3A18-A9-A-2A18-2(3A7-2A20-)3A5-3A22-3A4-2A23-3A3(3-3A25-A)2(3-A27-A)3-4(3A25-3A-)A2-A24-3A2-3A95-2(4A17-2A9-2(2A19-A-2A7-)4(2A20-3A7-)2A21-2A5-2(3A22-3A4-)2A23-3A3-3A25-A3-2(3A25-3A-)3(A27-3A-)4(A28-2A-)3A25-3A100-)2A30-2(2A19-4A7-)2A21-3A6-A5(22-3A4-3A)22-3A3-3A25-A3-3A25-2(3A-A27-)3A3(-A28-2A)-A28-4A28-3A-2A25-4A-2A25-3A-3A25-3A98-2(4A28-2(3A21-4A4-)2(3A24-A4-)4(2A25-A4-)2A25-A3-3A25-3A-A27-3A2(-A28-2A)-A5(28-4A)27-5A27-3A130-)3A29-2(2A23-3A4-)4(2A25-A4-)2A25-A3-3(3A25-3A-)2(A28-2A-)A3(28-4A)28-2(3A29-)4A27-5A27-3A130-3A22-2(3A4-2A23-)3A4(4-2A25-A)3-3A25-A3-2(3A25-3A-)3(A28-2A-)A28-4A28-3(3A29-)4A2(27-5A)27-3A130-2(3A22-3A7(4-2A25-A)3-2(3A25-3A-)3(A28-2A-)A28-4A28-3(3A29-)4A27-3A194-)4A20-4A2(4-2A23-3A)5(4-2A25-A)2(3-3A25-A)3-A27-3A3(-A28-2A)-A4(28-4A)27-2(3A194-6A17-4A5-2(3A21-A2-A4-)4(3A22-3A4-)2A23-3A2(3-3A25-A)3-2(3A25-3A-)2(A27-3A-)A2(28-4A)28-3A-2A26-2A-3A25-)3A196-5A6-4A3-5A9-3(2A20-3A7-)2A20-2(3A5-3A21-)3A5-3(3A22-3A4-)2A23-3A3-3A25-A3-5(3A25-3A-)4A22-5A27-5A143-8A24-8A14-21A11-2(3A8-3A4-4A10-)3A8-3A4-4A9-A-2A17-2A9-2(2A19-4A7-)2(2A20-3A7-)2A20-3A5-3A21-3A5-3(3A22-3A4-)3(2A23-3A4-)3A21-A2-A29-2A203-8A3-4A15-2(19A13-)19A12-3(21A11-)3A4-15A2(9-4A7-5A3-4A)9-4A8-4A3-6A7-2A5(19-4A5-4A)19-4A5-6A8-4A3-6A235-8A3-4A15-2(19A13-)19A12-3(21A11-)3A4-15A2(9-4A7-5A3-4A)9-4A8-4A3-6A7-2A5(19-4A5-4A)19-4A5-6A8-4A3-6A395-4A10-A17-4A10-A15-10A4-5A2(13-12A-6A)12-20A12-4(21A11-)2(22A10-)22A589-2(A15-)2(3A11-3A15-)4A9-4A13-2(6A9-6A11-)6A9-6A589-2(A15-)2(3A12-2A15-)4A11-2A13-2(6A11-4A11-)6A11-4A165-
