model
size = 13 12 32, scale = 0.05, origin = -y
material 
  colors = A:#FFF B:#111 C:#FFC D:#FCC E:#FF9 F:#222 G:#FC0 H:#C0F I:#F9C J:#FF6 K:#630 L:#66F M:#9C3 N:#6F0 O:#001 P:#396 Q:#777 R:#990 S:#F90 T:#555 U:#69C V:#6F6 W:#008 X:#939 Y:#F63 Z:#93F Aa:#002 Ab:#C93 Ac:#393 Ad:#F99 Ae:#F69 Af:#900 Ag:#003 Ah:#444 Ai:#09C Aj:#EEE Ak:#66C Al:#603 Am:#636 An:#6CF Ao:#FF0 Ap:#9F6 Aq:#CC9 Ar:#069 As:#903 At:#093 Au:#969 Av:#99C Aw:#6C3 Ax:#3FF Ay:#090 Az:#FC6 Ba:#9FF Bb:#700 Bc:#100 Bd:#933 Be:#6C9 Bf:#0C0 Bg:#6CC Bh:#C69 Bi:#009 Bj:#500 Bk:#AAA Bl:#F6F Bm:#0A0 Bn:#600 Bo:#339 Bp:#A00 Bq:#070 Br:#C6F Bs:#CF9 Bt:#004 Bu:#9F3 Bv:#6F3 Bw:#699 Bx:#3CF By:#C96 Bz:#CF0 Ca:#300 Cb:#CF3 Cc:#CF6 Cd:#399 Ce:#639 Cf:#6FC Cg:#3C0 Ch:#00D Ci:#C66 Cj:#C63 Ck:#005 Cl:#306 Cm:#996 Cn:#200 Co:#00E Cp:#693 Cq:#C0C Cr:#F06 Cs:#90C Ct:#30C Cu:#60C Cv:#6FF Cw:#F6C Cx:#3C9 Cy:#906 Cz:#FC3 Da:#3C6 Db:#909 Dc:#6C0 Dd:#036 De:#966 Df:#06F Dg:#099 Dh:#9F0 Di:#3C3 Dj:#CFC Dk:#0F9 Dl:#400 Dm:#FCF Dn:#666 Do:#FF3 Dp:#39C Dq:#633 Dr:#333 Ds:#669 Dt:#C09 Du:#3FC Dv:#63F Dw:#696 Dx:#C90 Dy:#040 Dz:#33F Ea:#369 Eb:#606 Ec:#C3C Ed:#9CC Ee:#0F0 Ef:#BBB Eg:#0F6 Eh:#360 Ei:#CC0 Ej:#09F Ek:#B00 El:#96C Em:#99F En:#FC9 Eo:#C33 Ep:#E00 Eq:#9CF Er:#9F9 Es:#C36 Et:#060 Eu:#F39 Ev:#90F Ew:#9C9 Ex:#390 Ey:#609 Ez:#007 Fa:#3CC Fb:#020 Fc:#F66 Fd:#00B Fe:#888 Ff:#0F3 Fg:#999 Fh:#039 Fi:#00A Fj:#0C6 Fk:#0FC Fl:#0CF Fm:#330 Fn:#3F3 Fo:#066 Fp:#363 Fq:#00C Fr:#0CC Fs:#660 Ft:#930 Fu:#CFF Fv:#9C6 Fw:#309 Fx:#00F Fy:#C6C Fz:#39F Ga:#C39 Gb:#C60 Gc:#CCF Gd:#F60 Ge:#F0C Gf:#F0F Gg:#F3F Gh:#C06 Gi:#F03 Gj:#F00 Gk:#F96 Gl:#C00 Gm:#33C Gn:#03C Go:#03F Gp:#69F Gq:#96F Gr:#9FC Gs:#3F9 Gt:#DDD Gu:#336 Gv:#010 Gw:#36F Gx:#CC3 Gy:#0E0 Gz:#366 Ha:#663 Hb:#F93 Hc:#F33 Hd:#0FF He:#0B0 Hf:#06C Hg:#63C Hh:#030 Hi:#963 Hj:#60F Hk:#960 Hl:#F30 Hm:#6C6 Hn:#6F9 Ho:#C3F Hp:#936 Hq:#C03 Hr:#F36 Hs:#096 Ht:#C9F Hu:#050 Hv:#800 Hw:#033 Hx:#F09
voxels
29-AjBbClAiDlF7-2B3AhF7-2B3FCk9-KEx99-BAlAm2AlAm7-AhBcDnAlAkLBoF5-BF4-2F5-BOCoGoGnFb-Q7-Co4B97-Bf3Am2DvAkDu5-T4-DsL-F3-2B6-2F4-BtT4-FeF6-6B96-QBf2AmL2Bg2LCn3-BT6-AjF3-BT6-2F4-2B4-B-Ah5-7B84-3VAsCy6-ODs2AkVCvAsLVFhAj2-B8-2F2-TGu7-2B2-Bt2B5-BGt5-7B82-AkAfAsAfBgAs3X4-WVCv3-As2Cy2Ax-BO9-Ah-BGy8-EgB2-CpB6-BEf4-8B82-CtL2AfBgAf3Z2Ax-B-A6-X2Ax-B-A8-Q-BCu8-RFl2-IYK4-HbBxAdA3-YH2PEgFjEgCm81-BkClDsVBeAkVXZ2AsAx-B2-3A5-2AaB-A8-2BkEaAq9-2Cd-AdC6-2CA2-CcS5CSC6-Y74-BEhLBg2BeAfX2MZCgWB-5A-2A-2WBA10-QHA9-HTAAd7-AdCA2-AbBvIC3AJAq6-IJ2A71-F2Dq2CfVAfX3MCgWB-2A3-A2-A-WBA2-7A-TH10-EnUJAb7-AvCA2-2AbS2-AJIDe5-YAd2CACA69-EpCtXZHiM2ZFv2MAlAaHh2-3A-2A2-A2Q-E3-A2-3AQAdA9-AR2Ao7-3A2-2N4-SIBrC4-NAe3CBlJ7-Cc62-Fz2BaEdMEsFvEr2EqCgFxBf2-7A2-EkBc-Az7-A-Ez2A9-AAq2C8-C2(A-)N5-AAvC3-Y-CA3C-Au5-AeHlAoCJ-Cm57-CxHoBaCiDjEsGbCiEqBa2AiBf2-7A2-AiBc-A7-A-Bb2A9-2CA9-CA-3A4-4A3-DeP3-JA-Bv4-Ei-AdAeBlJ-FtJ5-AqN4-Bu44-AaEd2Gg2AzGfCiGbHqEjAi-Bm-3AE3A2-CgB-A7-Hp-Bb3A8-2CA9-2A-3A5-3A2-A-A4-A-By4-CbCABlSCA-J4-Cb-CBlSI-Av6-Bh38-DrCq2D2GGfCiEsBf2-Bm3-GdE3A2-Cg-CxDCjGh5-Cf-ChEAz9-2CA9-2A-A7-3A2-3A4-A-Ap4-By4-A2-Cp4-BsGeAoS2C2R5-CBdAeSI-DcBh32-CqG2D2GEuHxBaHw2-Ef4-CiD2A2-Hv-Hu-CjGlEw4-Cf-ChCz-Gj8-AAuAGh8-2A-ACs5-4A2-I-2(A3-)A2-A-2A2-A2-Ap4-Bd-J-I3-I4-Au-DmGkIJBvGk6-U25-Ca3D4GBaHs2-Ef6-AzD-Fw2-Bt-CjLCyEwEr2-HtBn-Cz-Gl8-By-GGi8-2A-AAz6-Dj2A2-G-A3-ACj-Cc3-C2-3A3-Bh4-Ce2-A3-De5-Ce4-I-J5-CCdJAoC-H20-ArG2D4GLAi3-Fb8-Dg2-Co-LFzDuAlErGcFu-Ar-En-Di7-BeEo-GAz6-Hr-2A-EnGi6-Gj2A2-CZ5-Ew-Cc3-A-A3-Du2-Ab3-A2-Di-Ba2-Ab5-K2-Db3-Aq5-YEa2-BlBxBu8-IAe10-Et3D2G2DDn4-Bm8-Ca2-B-ClEpAiAlBgM2-Bk-Cr-Dg6-Gc-Fy-BzCv6-DjGd-A-GeGa5-Eu2-A2-EiAk5-Dj-A3-YBw5-Cj-C3-Y-A3-Di-H4-Fr2-Bn-Et2-P5-N2-Cd-EvAv6-PFeAqBhBy9-Et5D2EDi4-Bm8-O2-B-FhCnFxCtBnDv2-Q-A-Bb6-M-Cc-CsCv7-Ga-A-2Dh5-EuA-A2-HnDa4-2A-Cw3-Ce4-3A-A3-EvBkCz2-A2-Au4-A-YEv-A2-C5-CuAH-HBsDe6-Fj-CmCpEmA8-Ff3E2D2EDg4-Bm7-Dd3-W-WFiBbFw2Da-Ar2-A-Ch6-LDh2-CeAa7-MDh2-Aw8-CqA2-Fs7-AnFy3-U7-Au4-Dc5-AeBtBv4-NO4-IFlAe32-2Bz3E2AFuAg3-Bp8-Ag3-Bq-AjAaEpDgFkEh-Fd2-A-Ch6-DfAn2-HjAh7-DnEo2-U8-HkA2-An7-AwFg3-U7-N4-Cu6-FHm45-Ee4E2AAfW3-Bp8-Ay3-Bt-AaDlAr2DfEj-Q2-A-Cn6-AtBd2-2Ac7-BnEo2-CdDl7-BnA2-Dw7-KEl3-Bx7-K57-BjEe4D2EX4-Ag8-Bi3-Ch-BjFqAtDf2Dd-O2-A-Ek6-BiH2-EmO7-BnA2-BuBc7-DbC2-FaT6-FmBh3-K7-U57-BqEcDE2DEGCf4-Ag7-Ay4-AgBfAgHfAyFoAgBj-Bk2-AHg7-ExH2-BsDy7-AwA2-ACk7-El3-DcF6-EbEm11-Ft57-ArCrE3A2GFn4-Ar7-Ay4-AtEjFqFrDzAtEkAgDy3-AFs7-Eb3-ADd7-El3-ABq6-BiCe3-BlBm6-AcH11-P57-EhCrE3AEHcFn4-Bi7-Ay3-F-Fo2CaDpAtBj-Ck3-ABd6-BjAc3-AFp6-BxDx3-AFp6-HdEi3-IDw6-AwA4-U5-HeK57-AyBzCw3ACzBzCx4-Ay7-Ca3-F-AtGzHaDaFkBj-O3-ADb6-2Ac3-2Cb6-KC3-CbDb6-KA4-Dc5-FmAp5-U5-PAw57-Bo2EcCwECwGxEdCx4-Bi7-At4-Bq-BwBdAnDz2-Fi4-AuEe4-Bi-K4-H6-AvA4-H5-KBr5-2Aw4-NAe5-AvBp3-PAu11-PAv45-ArGqGrCqCrDt2CsCt4-Bp7-Dk4-Aj2-BwGs3-Dy4-H-Dk2-Dz-K5-BhCu4-EaBr5-DxEb3-Bx-Ap5-2Ap3-K-C5-AoAn2-Gv-By7-Gw2-CoPAd45-F2DpGpAnEy2Be5-Fd6-Cl5-Aj6-T5-Ac2-DqDr2-Ff5-DoBuRDtDrBvRAo5-DoBuBrDtAc-Ap7-HFgBwAn-C7-HRBw-Bs8-CpDwU-C10-DxAq36-DkBoGmEy8-BpBqCkOEzO7-AjBoBb2BcAa7-FaBoCmHBdCn8-DmAb2N9-BrAbBsC9-2Fc2C9-RDmC10-RSDo46-
