model
size = 13 12 32, scale = 0.05, origin = -y
material 
  colors = A:#FFF B:#111 C:#FF9 D:#FFC E:#222 F:#FF6 G:#9CF H:#FCC I:#FC9 J:#AAA K:#9FF L:#CCF M:#F99 N:#C03 O:#555 P:#033 Q:#001 R:#F6C S:#F9C T:#FC0 U:#200 V:#39F W:#603 X:#9C6 Y:#9C3 Z:#9F6 Aa:#00D Ab:#F93 Ac:#002 Ad:#63F Ae:#600 Af:#888 Ag:#306 Ah:#F30 Ai:#CF9 Aj:#3C9 Ak:#EEE Al:#00A Am:#636 An:#FF0 Ao:#9F9 Ap:#96C Aq:#CF3 Ar:#BBB As:#400 At:#93F Au:#C66 Av:#930 Aw:#F39 Ax:#FC6 Ay:#360 Az:#444 Ba:#070 Bb:#C96 Bc:#06F Bd:#0C0 Be:#933 Bf:#9F3 Bg:#6F9 Bh:#996 Bi:#6C3 Bj:#099 Bk:#9CC Bl:#C3F Bm:#C36 Bn:#F3F Bo:#F33 Bp:#30C Bq:#500 Br:#CC0 Bs:#777 Bt:#E00 Bu:#F96 Bv:#939 Bw:#3F9 Bx:#CF0 By:#060 Bz:#C9C Ca:#09F Cb:#C99 Cc:#3F3 Cd:#F90 Ce:#008 Cf:#C30 Cg:#CF6 Ch:#669 Ci:#F0C Cj:#969 Ck:#90C Cl:#393 Cm:#309 Cn:#333 Co:#93C Cp:#336 Cq:#C69 Cr:#C0F Cs:#3FC Ct:#00B Cu:#3FF Cv:#CFF Cw:#C00 Cx:#036 Cy:#6F0 Cz:#FCF Da:#FF3 Db:#100 Dc:#0A0 Dd:#66C De:#CCC Df:#9FC Dg:#6F6 Dh:#00F Di:#096 Dj:#3C6 Dk:#906 Dl:#303 Dm:#0D0 Dn:#300 Do:#0F9 Dp:#FC3 Dq:#99C Dr:#CC3 Ds:#C3C Dt:#999 Du:#909 Dv:#CFC Dw:#66F Dx:#6CC Dy:#069 Dz:#C93 Ea:#700 Eb:#C6C Ec:#6C0 Ed:#F09 Ee:#066 Ef:#0FC Eg:#666 Eh:#C09 Ei:#F63 Ej:#99F Ek:#F69 El:#69F Em:#0C6 En:#C6F Eo:#606 Ep:#09C Eq:#6FC Er:#9F0 Es:#C90 Et:#630 Eu:#080 Ev:#36F Ew:#063 Ex:#030 Ey:#993 Ez:#936 Fa:#60C Fb:#F0F Fc:#366 Fd:#800 Fe:#A00 Ff:#0F0 Fg:#990 Fh:#D00 Fi:#339 Fj:#F6F Fk:#663 Fl:#69C Fm:#90F Fn:#007 Fo:#6CF Fp:#CC9 Fq:#004 Fr:#6C6 Fs:#F60 Ft:#96F Fu:#0F6 Fv:#6F3 Fw:#F3C Fx:#6FF Fy:#F03 Fz:#006 Ga:#F00 Gb:#03F Gc:#C9F Gd:#960 Ge:#C33 Gf:#639 Gg:#60F Gh:#660 Gi:#B00 Gj:#696 Gk:#3F6 Gl:#3C0 Gm:#363 Gn:#33C Go:#699 Gp:#C0C Gq:#093 Gr:#F9F Gs:#005 Gt:#039 Gu:#3CF Gv:#C60 Gw:#F66 Gx:#693 Gy:#F06 Gz:#3CC Ha:#020 Hb:#966 Hc:#03C Hd:#609 He:#040 Hf:#090 Hg:#0CC Hh:#690 Hi:#9C0 Hj:#C06
voxels
30-WChAyVUAc7-3EAz2B7-AzEJAk2B111-Ao2GXAmBdAl5-Db-ChGVAm2Bs5-2E4-2B5-BAzQE3B8-2E2B97-AlDg2GX2Y2Ag4-ODbX5-E4-2E5-2B5-EAfE2-B-B6-EAzE3B86-AoGAt2Bv5-Bj2X2GAtBvAtDiAc3-O7-AzB3-2E6-2B3-BArB4-2B6-6B85-4G2YCmQ2-JWAoGX3-DkDiQ2-JO8-B2-2B7-2B3-2ArB4-3B5-6B83-2X2KAoGYAt2Cm2-U2GX6-Q2-J9-BE-BEw8-Ev3-Eu2B4-BxGnAp5-5BDmCn81-AmGAoBm2K2Ao2GBd2-UG8-Bs2JO9-OE-2Cp8-BhE2-FCbDtC4-RAb5-AvEoBiDrDpIAh80-AkAe3N4K2GBd-2Ce8-A-Bs2O8-A-EBCpF8-DCp2-FIC5-RI5-C4AIAbR8-2AI68-AkDx4NKBmKGKVJAk9-A-JO10-AAzBFgA8-ACr2-IAqAiA5-Dp5-4A-S2Av7-2A3I67-AkDx3NBl2LNBkKVQAc10-AOE11-EOEiA8-AAi2-CZDqA5-2F4-3A3-AhAi7-A3CI11-Ci55-AaAt2BmGvL2CvBz2KCu-As9-A-DyE9-2AAcGu2A8-AEb2-AFCq6-AD4-2AhA3-FlDz6-F-ACI2Av7-2ACDp55-UAe2BlLEdBnAwBzBlBkCh-Bd6-3A2-DiBs7-2A2-AsGx2A7-A-A2-FSCj6-AD4-FrF5-S6-I2A2-AhFp7-3ARC11-CiR41-BdAgLBzLEdBn2AwEd2Bk-Bd3-3A2-A2-EaBc4-4A-A-EaBcF2A7-AAn2-A2D6-2A4-ZCg4-A-M4-M-A2-A-Hb6-BrDSC2-Ha8-AbICbBf41-UAgLCvBoT2H2TDsU-PFi-A-2AHAx2-Cx-P3-A4-AuCCc-BhF2D7-AxA2-FAD6-2A4-Z2A3-A-A4-Cd-A2-A-D6-Ah-C-A-Ai7-I-C2-A8-2IA2Bb28-BpLBoAwT2H2THhAc-PCa-3AAxY3-Hg-AsHf-A4-WAu-He-CrMD7-Fy-A2-2DFA5-FwA4-Cd-A4-AxA4-Fr-A2-2AC5-S-A2-A-Fv6-Cr2Ab-A-Aq8-AbCdCDuAi28-PDf2AwAxC2HTDl3-EpA-2ALY3-Fz2-Ee-A4-WCs-Q2-MD7-Fy-A2-2(DA)5-GaA4-DA5-GaA4-Z-A3-A-A4-M2(2-A)-A5-Cf2-FwAx-Cb7-SAb3-Ej9-BoRApEn15-PDfHBnAx2CH2Bx3-P2-AFsG4-Ar2-Bc2A3-2VCs-Ar2-CdF7-Eg-A2-FAD6-HiA4-3A4-HjA4-Z2-4A-A4-Fu2-3A2-A5-Dz-Cw4-A5-Fm5-Fo7-AbS-CDcBf9-Ai6-AeCTH2CHBxCo3-Bj2-CDv4-Ar3-Dy-A2-WVBjP-E2-CdM7-V-A2-MFD6-CuR4-3A4-CwA4-F-Eg4-EzA4-Em-Eg2-2A-A5-CDx-Cw3-A5-Ap-Am4-Cq6-F2-A-Bh8-SM-BbAq3-BpCTH4CBg3-Bt8-By3-Ee-2ABmAdAgBjP-E2-FjM-2A4-Dh-A2-MD-H5-DhA4-A-A4-DdAb4-A-Dv4-DdA5-CjBp2-A-ByA5-FvBa-FxCbA-A5-BrCk-FxBeA-Cq5-Ec-FfCnCrFzFl7-EbAqBfAhEsAq3-BtHCH2CACAm4-Bj7-By3-Hc4-CsEfAsAa-Q2-F2(-A)4-U-De2-MF-H5-AaDe4-ACb5-AjDr5-AhH4-AyA5-DHd4-FnA5-FBa4-OA5-AiCl4-CnA5-AvBhDc3-FgBu6-BbEl7-DbGyC4ACAe4-Ee8-Q3-Gz3-2EfAsAl-Q3-R2-C4-Ac-A2-M2-A5-JDt3-FABo5-BjAp5-2Ft4-CtA5-AqBg4-CtA5-FpEb4-ArAn5-DzR4-FuZ28-FdAe2C3ACFk4-By8-Fq3-Ec3-AjAgPU-Fq3-Ec2-C4-Ac-A2-F2-Fs5-OCo3-SA-C4-BqDt5-ABw4-CtA5-FEv4-JF11-EuZ42-Bw2C3ACFkGs3-Af8-Ba3-Af3-CuBpGtUEaBa3-D2-Cv5-CnA2-D2-Cw6-Fm3-AnD-Au4-FnFo5-AiFc4-JA11-AfGw55-FiTH3AHDsBq4-Fh7-Bq3-B2-AdCuDjCaPVBq3-D-Dw6-ClBr2-A2-Dw5-DyEh3-2DL5-AaFj5-CyAg4-JA11-EDq55-FfAw2BnCHFbLCm4-Fh8-Aa3-Dm-AmAeCcDlBcBp-As3-ErCs6-AyA3-Dr-Dg5-AyA3-D-Dk5-CtA4-ADu5-AfF68-GqBxBnBoGrHFbBzBp4-Ew8-Aa3-Af-WDjCcFc2Do-Fd3-EyAj6-CkA3-BoDw6-BwA3-A-Dk5-FeA4-ABe5-FeA68-CaAu2LDvLAuBmCa4-Dm8-P3-B-W2CcBw2Dn-P3-CqAm6-BkD3-AGp6-CoD3-A-Ez5-FaD4-SBe5-FaD11-Bh56-AgG2BlBz2AuGCa4-Af8-Ex3-Af-WAdBgGoClDo-Ex3-DqAp6-DgAn3-I-Ds5-CoAn4-FEy5-DuCz4-AAp5-CyD5-Av5-Bi56-AaGlAt2G2NBvEp4-Aa8-Bt3-B2-2EqBgClDl-Ba4-BeW5-BfBu4-RBk5-BfAn4-A-Er4-EsBu4-A-Gm3-DnCj6-ZBy3-2Et57-As2AdAtGBvChBt5-Dh6-Aa5-B2-BgGhDj2-Gi4-Em-Ad3-Bw-Cg4-2Ci4-CjEn5-A-Ck3-BiBr6-ACk3-BiBu6-AGj3-GkD7-Bi3-Eo45-QBcAd2AjAeAyBt5-Dc6-Al5-B6-Ce5-E2-AeDdEl-Bu6-DeGdAd-Be-Da6-F-Ap-Ge-Cz6-A-BeYDf-Da7-BfGfYBgAq8-BhGgBcBiZ46-2Cx2AjAy8-BqAl2AkAlAc7-2JCeBaAlQ7-GbCyCfEhCgEi8-FCfEjBrA8-EkBbCfCgD8-CzBbGcEkDa8-2ARS10-AMAn42-
