model
size = 13 32 10, scale = 0.05, origin = -y
material 
  colors = A:#1E3A8D B:#0098FE C:#0011B1 D:#718480 E:#74837E F:#A7685D G:#059CED H:#7C7E79 I:#72837E J:#977168 K:#6C8683 L:#0DA1DD M:#678984 N:#449A9C O:#58C9CC P:#3D9D9F Q:#38A1A2 R:#688884 S:#7E7E77 T:#847B72 U:#3B9FA1 V:#B56254 W:#59908D X:#59908E Y:#539392 Z:#59C9CC Aa:#5DCACE Ab:#10A4D4 Ac:#069CEC Ad:#0BA1DE Ae:#1FACB1 Af:#A16C62 Ag:#3A9FA1 Ah:#5B8E8D Ai:#8B776F Aj:#10A2D4 Ak:#0DA1DB Al:#817C76 Am:#658986 An:#92746A Ao:#58908E Ap:#4C9795 Aq:#B86054 Ar:#77817B As:#678986 At:#5E79A7 Au:#27A9AC Av:#3F9D9D Aw:#5BC9CC Ax:#1AABBB Ay:#17A7C4 Az:#13A6CE Ba:#10A4D3 Bb:#17A9C4 Bc:#1AABBD Bd:#2EA6A9 Be:#409C9D Bf:#459A9A Bg:#628B89 Bh:#5D8E8B Bi:#429C9C Bj:#18A9C0 Bk:#12A6CE Bl:#12A6CF Bm:#17A9C2 Bn:#9C6F65 Bo:#638B88 Bp:#0A9FE5 Bq:#9D6D63 Br:#867972 Bs:#77817C Bt:#35A2A4 Bu:#36A1A4 Bv:#17A7C5 Bw:#3B98AB Bx:#76817C By:#897771 Bz:#987167 Ca:#519393 Cb:#6A769D Cc:#569290 Cd:#4F9595 Ce:#4E9595 Cf:#549290 Cg:#608D89 Ch:#62C9CC Ci:#5EC9CC Cj:#90746C Ck:#31A4A6 Cl:#40BFC4 Cm:#5BC7CA Cn:#5BCACE Co:#62CACE Cp:#5DC9CC Cq:#0B9FE2
voxels
288-3(2A5-2A4-)2A3-4A4-9A4-2(8A5-)3AAkAj3A6-AdBpAkAj2GB6-7B8(6-3A-3A)31-2(3A3-3A4-)3A3-3A5-3(2A3-2A6-)2A2(3-3A4-3A)3-3A2(3-4A)2-4A2(2-5A)-5A2-5A-5A3(2-11A)2-O6A-3A2-O3A4-3A2-2A5-4A2-3A4-L3A2-ALAdG3-L2Ac4-3B3-3B4(4-2A-A-4A)4-4A-4A4-A-2A-4A4-2A-A8(-4A4-4A)-4A3-5A-5A2-5A-3A-A2-5A2(-2A)2(2-3(2A-)2A)2-A2-2A2(-2A2-A)-2A2(3-4A3-3A)3-2AAwA4-2A3-AClAaCm9-2AaAO9-Cn2ACo9-ZA-C9-ZA-Cp8-AAw2-CG7-GCq2-2B7-2B3(2-2(2A-)2(A-)A)2-2(2A-)2(A-)Cc2-2A2-2(A-)AP4-2A2(-A)-2A4-3A3-A-A3-4A2-A2-2A2(2-4A2-A-3A)2-4A2-2(A-)A2-4A4-2AE2-2A-A5-2A2-WA-2(A2-)2Au2-CA-2(A2-)AP2-AeA2-A-A2-AAv2-AgA2-A-A2-ACd-AN3-A-A2-ACe-AY3-A-A3-X-ACf3-A-A3-Am-KAv3-A-A3-RED4-3A3-A2E11-KAs11-CgCh11-CiAl11-XJ11-AhCjA9-AAoFQ9-CkCAF9-OA-At9-Z2-B9-B2-2A2(4-A2(2-2A))4-A2-2A2-AiA4-A2-2Aq2-BxA4-A2-PA2-DA2-A-A2-HA2-YA2-A-A2-UV2-YA2-A-A2-2Ar2-C3-A5-By2-C3-A5-T2-As3-A4-ABz2-H3-A5-E2-An3-A4-CaV2-W3-A4-2F2-C3-A5-A2-F2(3-A-A3-A-2A)5-A3-3(A-2A9-)4A9-3A4(11-2A)10-4A2(9-3AD)9-2A-At9-Cb2-B9-B2-2A2-3(A-)2(A2-2A2-A-A3-)A2-ABn2-A-A2-BoA2-AAi2-A-A2-2J2-2A2-A-A2-AM5(2-A3-A-A3-A)2-A3-A-A3-I2-A3-A-A3-C2-JA2-A-A2-2K2-AfA2-A-A2-2R2-BqA2-A-A2-AS2-2T2-A-A2-AC2-Br3-A-A2-AH2-Al3-A-A2-ABs-AS3-A-A3-H-AI3-A5-I-AAm3-2A4-D-AnBt3-2A4-AoA2Ap9-PASA9-UVMA9-WA2N9-EAFU9-D2-Bu9-K2-D9-X2-Bv9-Bw2-2B7-2B3-4A-4A4-4A2(-4A3-5A)-4A3-AAe3A-4A3-AfBd2(-2A)-MBe2-HA2(-2A)-ABf2-IA2(-2A)-AN2-MA2(-2A)-AQ2-BgA2(-2A)-AAg2-AhA2(-2A)-AQ2-Bh4A-4AI2-Bi4A-4AC2-J-3A-4AC2-5A-5A2-5A-3A-A2-A-3A-4A3-5A-5A2(2-3(2A-)2A)2-2A2-A-A3(2(2-2A)2-3A)2-2A2-A3-3A2-2A3(2-A9-A)2-A8-2A2-2A7-2A2-BjBk7-BlBm2-3B5-3B4-3(2A3-2A6-)2A3-2A5-8(3A3-3A4-)3A3-2A5-3A3-2A6-2A4-A6-2(2A4-)3(3A3-3A4-)4(4A-4A4-)4A-4A3-2(11A2-)3(2A7-2A2-)A-A2-2A-2A4-AxAyAbLAzBaAbBbBc4-9B317-2A3-2A5-4(9A4-)9A5-7A358-3(5A8-)5A30-
