model
size = 16 31 10, scale = 0.05, origin = -y
material 
  colors = A:#FFE21D B:#FFD725 C:#F9496B D:#FF716D E:#FEEA33 F:#D7FD54 G:#FEE528 H:#C5F855 I:#FCFC55 J:#FE4934 K:#FEB50B L:#D6FE64 M:#48D878 N:#48CD68 O:#FDFE68 P:#FFA64B Q:#FFEA46 R:#FBF736 S:#A34686 T:#FDC826 U:#FF4408 V:#3249B8 W:#FDFA49 X:#FE773A Y:#FA555C Z:#FDA308 Aa:#2F38A1 Ab:#74D18D Ac:#84E576 Ad:#FF3F47 Ae:#FC6549 Af:#FF5A45 Ag:#002E6B Ah:#D8B817 Ai:#FF8418 Aj:#FBA715 Ak:#FF7A28 Al:#FF9946 Am:#B64D85 An:#2D1260 Ao:#72F486 Ap:#FF6562 Aq:#206ACC Ar:#FF9726 As:#66E069 At:#6ECF4C Au:#6C489B Av:#2495CD Aw:#3AC6D0 Ax:#4BCBB4 Ay:#FCCA38 Az:#67E377 Ba:#5AAE2E Bb:#FF8848 Bc:#04328A Bd:#E8FA68 Be:#3AA735 Bf:#E2FE49 Bg:#F62934 Bh:#990927 Bi:#0D4C9C Bj:#204BA5 Bk:#8ED347 Bl:#FF692D Bm:#FFB763 Bn:#037695 Bo:#16BAD3 Bp:#BBFA56 Bq:#50D490 Br:#613691 Bs:#6C7BC7 Bt:#B3F467 Bu:#FFB359 Bv:#FF3638 Bw:#2672C5 Bx:#4BB59A By:#B1F549 Bz:#FC5818 Ca:#FBFB92 Cb:#FFB645 Cc:#FD2724 Cd:#CE1B27 Ce:#070B36 Cf:#FEDA37 Cg:#4DB36F Ch:#9ABB1A Ci:#FFA824 Cj:#FFA86F Ck:#7ED656 Cl:#76FA9A Cm:#B5FD76 Cn:#FF892E Co:#FF9368 Cp:#294BB3 Cq:#86E669 Cr:#FEFC28 Cs:#FFB916 Ct:#57E893 Cu:#71EBB6 Cv:#CDFE86 Cw:#B6FE88 Cx:#88F774 Cy:#216AC0 Cz:#39C6A5 Da:#C4C654 Db:#FFB626 Dc:#FB7253 Dd:#AC5276 De:#51346D Df:#012A87 Dg:#3086A9 Dh:#1D95B9 Di:#0A8797 Dj:#68CC86 Dk:#D6EC4B Dl:#93DB38 Dm:#EAF533 Dn:#FE9513 Do:#FFD456 Dp:#DF202C Dq:#5F002D Dr:#330036 Ds:#26338E Dt:#040434 Du:#5FB869 Dv:#CE181D Dw:#52094F Dx:#046DB1 Dy:#017CB5 Dz:#098FB0 Ea:#DCF132 Eb:#FFA78D Ec:#FF6558 Ed:#6F1654 Ee:#90F16C Ef:#6FE7B2 Eg:#84F4B2 Eh:#073399 Ei:#19B3AB Ej:#87E88C Ek:#97E66E El:#A6E465 Em:#ECFF73 En:#98C92B Eo:#CCC610 Ep:#D2395F Eq:#32094E Er:#4A49A7 Es:#FCFF78 Et:#6C9F4E Eu:#D5E336 Ev:#FFB539 Ew:#E34E5D Ex:#6646A7 Ey:#C8E854 Ez:#AEFFA2 Fa:#FFE053 Fb:#FF7B18 Fc:#FF562B Fd:#FC4925 Fe:#B3C31B Ff:#FB1812 Fg:#FF720E Fh:#FF8537 Fi:#635B4C Fj:#FFC74B Fk:#151F70 Fl:#8BD896 Fm:#9B1D4A Fn:#1492C9 Fo:#84FF93 Fp:#A5FB95 Fq:#63CBE2 Fr:#17996A Fs:#6CDC76 Ft:#EB9C2C Fu:#CFF433 Fv:#054A9A Fw:#A5DA67 Fx:#8BB45B Fy:#8AF467 Fz:#66EA98 Ga:#FED848 Gb:#6FD667 Gc:#20C8CC Gd:#F22D15 Ge:#84EF89 Gf:#A74459 Gg:#2E2467 Gh:#23A0A8 Gi:#FD3726 Gj:#C8F96F Gk:#D7D419 Gl:#8EF1A4 Gm:#34ABD4 Gn:#07AFD1 Go:#65CE50 Gp:#48B4CE Gq:#34BEC9 Gr:#93C46E Gs:#B5EB54 Gt:#F3AE39 Gu:#8BE955 Gv:#B72652 Gw:#238594 Gx:#2AC99C Gy:#AD1B2A Gz:#D5D659 Ha:#FFC813 Hb:#FF4E0E Hc:#27739C Hd:#32B4B3 He:#90D377 Hf:#50AA34 Hg:#0997BA Hh:#046B99 Hi:#36D6AD Hj:#A9FC71 Hk:#EAD79E Hl:#95F7A5 Hm:#4DD48E Hn:#96DA68 Ho:#A4DE36 Hp:#6A5570 Hq:#B5D54C Hr:#C99C37 Hs:#F7D423 Ht:#479FAB Hu:#061D62 Hv:#CCD34A Hw:#0BA6C4 Hx:#22C5BB Hy:#5AE095 Hz:#63AC40 Ia:#0180B9 Ib:#1E62A1 Ic:#DEF664 Id:#F43420 Ie:#D2FF8E
voxels
- - - - - - - - - - - - - - - -   - - - - - - - - - - - - - - - -   - - - - - - - - - - - - - - - -   - - - - - - - - - - - - - - - -   - - - - - - - - - - - - - - - -   - - - - - - - - - - - - - - - -   - - - - - - - - - - - - - - - -   - - - - - - - - - - - - - - - -   - - - - - - - - - - - - - - - -   - - - - - - - - - - - - - - - -   - - - - - - - - - - - - - - - -   - - - - - - - - - - - - - - - -   - - - - - - - - - - - - - - - -   - - - - - - - - - - - - - - - -   - - - - - - - - - - - - - - - -   - - - - - - - - - - - - - - - -   - - - - - - - - - - - - - - - -   - - - - - - - - - - - - - - - -   - - - - - - - - - - - - - - - -   - - - - - - - - - - - - - - - -   - - - - - - - - - - - - - - - -   - - - - - - - - - - - - - - - -   - - - - - - - - - - - - - - - -   - - - - - - - - - - - - - - - -   - - - - - - - - - - - - - - - -   - - - - - - - - - - - - - - - -   - - - - - - - - - - - - - - - -   - - - - - - - - - - - - - - - -   - - - - - - - ArFt- - - - - - -   - - - - - - - ArAr- - - - - - -   - - - - - - - - - - - - - - - -   
- - - - - - - - - - - - - - - -   - As- M N - - - - - - AsM - M -   - AsAtGo- - - - - - - AsBqBqCx-   - - - - - - - - - - - - - - - -   - - - - - - - - - - - - - - - -   - - - - - - - - - - - - - - - -   - - - - - - - - - - - - - - - -   - - - - - - - - - - - - - - - -   - - - - - - - - - - - - - - - -   - - - - - - - - - - - - - - - -   - - - - - - - - - - - - - - - -   - - - - - - - - - - - - - - - -   - - - - - - - - - - - - - - - -   - - - - - - - - - - - - - - - -   - - - - - - - - - - - - - - - -   - - - - - - - - - - - - - - - -   - - - - - - - - - - - - - - - -   - - - - - - - - - - - - - - - -   - - - - - - - - - - - - - - - -   - - - - - - - - - - - - - - - -   - - - - - - - - - - - D D - - -   - - - - Aa- - - - - - C C - - -   - - - - AaAa- - - - BrBrAu- - -   - - - CyCyBsAv- - BsBsV V - - -   - - - AvAvGpFq- - BsBsV V - - -   - - - AbGrCzCzCzFrEiGqAwAw- - -   - - - AcHnAcAcEjFsHmBqAxAx- - -   - - - ElElBtGsDaDaDaAbAbEk- - -   - - - - W R GtGtFtFtE EmH - - -   - - - - E E DbDbAyAyE O I - - -   - - - - - - - - - - A A - - - -   
- As- N - - - - - - - - - - - -   GuAs- N At- - - - - - BaM - M Az  Gu- AtAtAt- - - - - - EnBqBqCxCx  - FuH H F - - - - - - EoHoBqF F   - - - - - - - - - - - - - - - -   - - - - - - - - - - - - - - - -   - - - - - - - - - - - - - - - -   - - - - - - - - - - - - - - - -   - - - - - - - - - - - - - - - -   - - - - - - - - - - - - - - - -   - - - - - - - - - - - - - - - -   - - - - - - - - - - - - - - - -   - - - - - - - - - - - - - - - -   - - - - - - - - - - - - - - - -   - - - - - - - - - - - - - - - -   - - - - - - - - - - - - - - - -   - - - - - - - - - - - - - - - -   - - - - - - - - - - - BuP - - -   - - - AfAeAd- - - - X BbP - - -   - - AfAfAdAd- - - - Y Y D Ae- -   - - AfAfAdAd- - - J Y Y D Bv- -   - - AuS BrS Hp- - GvEpC DcBv- -   - - ErErAaAaAaDf- EqDeS DdDd- -   - - BwBw- - BcBcAgBs- - V V - -   - - DgAv- - GwAgAgFv- - V V - -   - - BxAb- - Bx- - Di- - DhDh- -   - - DjDj- - - GxFs- - - AxDj- -   - - Fx- Gs- - - - - - - ElFw- -   - - - BdBd- - - - - - - DkHq- -   - - - Q Q B - - - - - EsQ - - -   - - - A A - - - - - A A B - - -   
- As- BeBe- - - - - - N - - - -   DlDl- BeEn- - - - - - BaN - FzFy  DmBy- - En- - - - - HrBa- - - Fy  Dm- Q I A - - - - - Ah- EoEsF Bf  - ArK B - - - - - - Z T B Q E G   - Ar- - - - - - - - - AjDnAiHsAy  - - - - - - - - - - - - Ak- - -   - - - - - - - - - - - - - - - -   - - - - - - - - - - - - - - - -   - - - - - - - - - - - - - - - -   - - - - - - - - - - - - - - - -   - - - - - - - - - - - - - - - -   - - - - - - - - - - - - - - - -   - - - - - - - - - - - - - - - -   - - - E Eu- - - - - - EtFuF - -   - - EvDbBz- - - - - EuEtFuF - -   - - EvP AkX - - - - DoCaQ I - -   - - AlBbBbX - - - - P BuCbDo- -   - - DcAeAeEw- - - - Bb- BuBu- -   - - D J - DpCc- - J J - - Ae- -   - - D - - CdCd- - J J - - Bv- -   - - Am- - - DeBr- Gy- - - Bv- -   - - Ex- - - Ds- DrDq- - - Am- -   - - Bw- - - - CeDt- - - - V - -   - - Dg- - - - CeCe- - - - Cy- -   - - Bx- - - - HuFr- - - - Ht- -   - - Du- - - - - - - - - - Dj- -   - - FxFx- - - - - - - - - Fw- -   - - GzGz- - - - - - - - DkEy- -   - - HvGa- - - - - - - - CfDk- -   - - - T - - - - - - - A T - - -   
- Gb- BeBe- - - - - - CgN - - -   DlEk- - Ba- - - - - - AtN - FzEz  G - - - Ba- - - - - - Ch- - - Fy  G Fa- Ha- Ha- - - - Z Ah- - - Bf  Ci- DnCiCiZ - - - - Z - Z Z AyB   P - AkAi- - - - - - Fb- Z AiAjAy  FcFcU - - - - - - - CjCjAiAiHbAl  CcCcDv- - - - - - - FcAeFdJ U Hb  Bh- Dw- - - - - - - - DpBgBgFdCd  - DfBi- - - - - - - - AnEqDwAn-   - DyDx- - - - - - - - - FvBiBj-   - HwDzEi- - - - - - - DgFvBiBj-   - CkCkBk- - - - - - - CzCzHxGc-   - CkCkBkDl- - - - - BkGbAcAoCl-   - DmEaEuEu- - - - - FeEtByF Cm-   - DmDmB U U - - - - Fe- - F O -   - CbCb- CnBl- - - - K - - I I -   - AlAl- - Bb- - - X P - - DoQ -   - DcDc- - J J - - X X - - Bm- -   - EcEb- - - Ff- - Gd- - - Co- -   - D D - - - Bh- - Bg- - - Ad- -   - AmAm- - - DqEqDvDv- - - Ad- -   - AuAu- - - - Eq- Dq- - - S - -   - BjBw- - - - CeCe- - - - Cp- -   - HcDg- - - - CeDt- - - - Cp- -   - GwBx- - - - - - - - - - Hd- -   - - Ab- - - - - - - - - - Dj- -   - - He- - - - - - - - - - Fw- -   - - Gr- - - - - - - - - - Ey- -   - - DaCf- - - - - - - - CfDk- -   - - - B A - - - - - - A B - - -   
- Fs- HfBe- - - - - - CgN - - -   - Cq- BeBa- - - - - - Hz- - HyGe  EaE - - Ba- - - - - - Ch- - - By  T E - - K - - - - - - Eo- - - Cr  CiCs- - Ak- - - - - - Fg- - - G   P - U U Ak- - - - - - Fg- - - Ev  X - U DpFd- - - - - FhBz- - - Ev  Cc- DvBh- - - - - - - Fc- - GdAk  EdDrDwDr- - - - - - - Cd- - GdBg  BiDfBcFi- - - - - - - AnDf- AnEd  BiDyDyDy- - - - - - - AnDf- AnDs  AxEiDzDzBx- - - - - DiBn- - IaDx  EfEe- BkBk- - - - - DiGx- - Bo-   - EeEaDlBk- - - - - EtN - - Eg-   - EaEa- AhAh- - - - Fe- - - Cm-   - O - - - Dn- - - - Fe- - - I -   - Fj- - - Fg- - - - K - - - I -   - Bb- - - Bl- - - AjAj- - FaFa-   - Co- - - AfAe- - Bz- - - Bm- -   - EcAp- - - Bg- - Ec- - - Co- -   - Y Y - - - Gy- - Ec- - - Ap- -   - EpEp- - - DrFkEwEw- - - Ap- -   - BrAu- - - Fk- Gf- - - - S - -   - BjCp- - - - BiGg- - - - Cp- -   - IbDh- - - - AgDt- - - - Cp- -   - GhAx- - - - - - - - - - Hd- -   - - Fl- - - - - - - - - - Ab- -   - - FlEl- - - - - - - - - Ek- -   - - AxHe- - - - - - - - IcH - -   - - - Cf- - - - - - - - I O - -   - - - B A - - - - - - A B - - -   
- Ej- GoAt- - - - - - N M - M M   - Ac- ChCh- - - - - - Hf- - ByCx  - G - - Ch- - - - - - Du- - ByBy  - G - - Z - - - - - - DuK - BfCr  - Cs- - Fg- - - - - - K K - A G   - Ci- - Cn- - - - - - Z - - DbCs  X Ai- BhCn- - - - - - Ai- - AlAl  BvBv- BhCd- - - - - - Ae- - AkBl  Bg- - DrDt- - - - - - Ep- - GiCc  Fk- - FiDt- - - - - - Dq- - FmFm  Hg- - FiDi- - - - - BnFi- - FkDs  Hg- - - Di- - - - - BnBn- - BoAq  AoAo- - Gb- - - - - BnBn- - Bo-   - Ao- - En- - - - - DuDu- - Eg-   - L - - EoGk- - - - EyBt- GjCm-   - W - - - T - - - - Ey- - BdBd-   - Fj- - - Ar- - - - B - - O Bd-   - P Bu- - Ak- - - - Cb- X - Do-   - EbEb- - AfY - - FhAl- BmBm- -   - - D - - Y Y - - ApAp- CoCj- -   - - C - - C C - - ApAp- D D - -   - - Am- - - C - GfC C - D D - -   - - Ex- - - AaAaGfDe- - DdAu- -   - - Cy- - - Bj- AgEh- - AqAq- -   - - Gp- - - - AgAgAg- - AvBw- -   - - Ef- - - - - - - - - FlGq- -   - - GlGl- - - - - - - - EkAb- -   - - GjGj- - - - - - - - BtBt- -   - - - Dk- - - - - - - - L - - -   - - - R R - - - - - - G Q - - -   - - - G B A A - A A A - B - - -   
AzAzCqCqBk- - - - - - M M CtCtM   Cq- AhAh- - - - - - - Ac- Ao- Cx  - CrAhAhCh- - - - - - CkCkBp- Bf  - A - K K - - - - - - Gk- Bp- Bf  - Cs- K K - - - - - - K - I - O   - P - CnCn- - - - - - AjAjT - Q   - Bl- GiCn- - - - - - FbFbAi- Aj  - Cc- DvEw- - - - - - U U U - P   DwEd- BcBc- - - - - - FfFfBzJ -   DwEd- BcBc- - - - - - DqBhGvFm-   DyDg- AwAw- - - - - - AnAnGgGgEh  BoBo- HiAw- - - - - - HhDxFnFn-   GcCl- AoCq- - - - - - DzBoFnFn-   - ClFoHjCq- - - - - - ClCuHiCu-   - L L BfR Gk- - - - H H FpGeGe-   - I W I R T - - - - H BfEmL - -   - GaFjFaDoCb- - - - B GaFjEm- -   - - BmBmCjP - - - - CbAlFhFh- -   - - CjCoAfDc- - - - HkHkBm- - -   - - D AdBgC - - - - EbEbCo- - -   - - S C EcC - - - - ApS C - - -   - - AmAmAmDdS - - - C S C - - -   - - ExExErErCp- - BrS AuDd- - -   - - AqAqAqCyDxHh- EhBiBwAq- - -   - - FqFq- - Dz- FrBnGhGmAq- - -   - - EfEg- - - CgCg- - CuFl- - -   - - - Gl- - - - - - - FpFp- - -   - - - CvCa- - - - - - CvCm- - -   - - - EmO - - - - - - L L - - -   - - - - E E E O W Q Cf- W - - -   - - - - E E G G G Q T B - - - -   
AzN Ac- - - - - - - - CtCtCt- Ct  Ee- Da- - - - - - - - HlFoAoAzAz  F - H - - - - - - - - CwBpBpF F   Cr- R Cs- - - - - - - - BpBpF F   B - T Cs- - - - - - - - G CrEsR   - DnDnAr- - - - - - - AjAyAyE B   - BlBlBz- - - - - - - FbBbBzDb-   - J J Dp- - - - - - - - IdFfBu-   - FmEdEh- - - - - - - - DpGiCj-   - DsBjEh- - - - - - - - BhCd- -   - DsBjAw- - - - - - - - DeDe- -   - GnBoGc- - - - - - - - HcDx- -   - ClFoAo- - - - - - - - GnGn- -   - ClFoHj- - - - - - - - - - - -   - - - - - - - - - - - - - - - -   - - - - - - - - - - - - - - - -   - - - - - - - - - - - - - - - -   - - - - - - - - - - - - - - - -   - - - - - - - - - - - - - - - -   - - - - - - - - - - - - - - - -   - - - - - - - - - - - - - - - -   - - - - - - - - - - - - - - - -   - - - - - - - - - - - - - - - -   - - - GmAvDh- - - - - - - - - -   - - - GmAvDhAxEf- EiGhAw- - - -   - - - EgCuBxEfAbCgCgEgCuCu- - -   - - - HlEzEzCwCmEeCwEzFp- - - -   - - - - IeCvCvL BtEjCwCv- - - -   - - - - EsO CaCaBdL L I - - - -   - - - - - W O O W W CfW - - - -   - - - - - - - - - - - - - - - -   
AzFzAc- - - - - - - - - - - - -   BpH H - - - - - - - - - - - - -   F H H - - - - - - - - - - - - -   CrR R - - - - - - - - - - - - -   - R T - - - - - - - - - - - - -   - Ci- - - - - - - - - - - - - -   - Bl- - - - - - - - - - - - - -   - Fd- - - - - - - - - - - - - -   - - - - - - - - - - - - - - - -   - - - - - - - - - - - - - - - -   - - - - - - - - - - - - - - - -   - - - - - - - - - - - - - - - -   - - - - - - - - - - - - - - - -   - - - - - - - - - - - - - - - -   - - - - - - - - - - - - - - - -   - - - - - - - - - - - - - - - -   - - - - - - - - - - - - - - - -   - - - - - - - - - - - - - - - -   - - - - - - - - - - - - - - - -   - - - - - - - - - - - - - - - -   - - - - - - - - - - - - - - - -   - - - - - - - - - - - - - - - -   - - - - - - - - - - - - - - - -   - - - - - - - - - - - - - - - -   - - - - - - - - - - - - - - - -   - - - - - - - - - - - - - - - -   - - - - - - CwCmEeCw- - - - - -   - - - - - - CvL BtEj- - - - - -   - - - - - - CaCaBdL - - - - - -   - - - - - - - - - - - - - - - -   - - - - - - - - - - - - - - - -   
