model
size = 13 12 32, scale = 0.05, origin = -y
material 
  colors = A:#FFF B:#010101 C:#FEFEFE D:#F8F8F8 E:#FDFDFD F:#020202 G:#F4F4F4 H:#BDBDBD I:#F2F2F2 J:#FCFCFC K:#767676 L:#818181 M:#ADADAD N:#8E8E8E O:#0B0B0B P:#606060 Q:#050505 R:#A6A6A6 S:#EEE T:#040404 U:#868686 V:#909090 W:#101010 X:#9D9D9D Y:#E9E9E9 Z:#9F9F9F Aa:#0C0C0C Ab:#CBCBCB Ac:#5F5F5F Ad:#F1F1F1 Ae:#EBEBEB Af:#949494 Ag:#292929 Ah:#030303 Ai:#3E3E3E Aj:#0A0A0A Ak:#808080 Al:#717171 Am:#787878 An:#8D8D8D Ao:#FAFAFA Ap:#B4B4B4 Aq:#D3D3D3 Ar:#373737 As:#959595 At:#3B3B3B Au:#A3A3A3 Av:#AAA Aw:#898989 Ax:#6F6F6F Ay:#3A3A3A Az:#F6F6F6 Ba:#B7B7B7 Bb:#232323 Bc:#1F1F1F Bd:#9B9B9B Be:#8B8B8B Bf:#404040 Bg:#8C8C8C Bh:#C7C7C7 Bi:#2B2B2B Bj:#222 Bk:#070707 Bl:#EDEDED Bm:#1B1B1B Bn:#707070 Bo:#555 Bp:#252525 Bq:#191919 Br:#C9C9C9 Bs:#D9D9D9 Bt:#0D0D0D Bu:#B3B3B3 Bv:#8F8F8F Bw:#858585 Bx:#696969 By:#CCC Bz:#D6D6D6 Ca:#4C4C4C Cb:#D7D7D7 Cc:#D8D8D8 Cd:#616161 Ce:#797979 Cf:#929292 Cg:#646464 Ch:#131313 Ci:#C6C6C6 Cj:#C5C5C5 Ck:#0E0E0E Cl:#4E4E4E Cm:#A8A8A8 Cn:#202020 Co:#141414 Cp:#838383 Cq:#BCBCBC Cr:#DEDEDE Cs:#989898 Ct:#505050 Cu:#747474 Cv:#939393 Cw:#ECECEC Cx:#676767 Cy:#969696 Cz:#F5F5F5 Da:#666 Db:#979797 Dc:#888 Dd:#303030 De:#A2A2A2 Df:#393939 Dg:#3D3D3D Dh:#B2B2B2 Di:#656565 Dj:#DADADA Dk:#494949 Dl:#212121 Dm:#F9F9F9 Dn:#7E7E7E Do:#FBFBFB Dp:#626262 Dq:#777 Dr:#535353 Ds:#7F7F7F Dt:#BBB Du:#6E6E6E Dv:#7B7B7B Dw:#848484 Dx:#CACACA Dy:#171717 Dz:#575757 Ea:#5B5B5B Eb:#727272 Ec:#C2C2C2 Ed:#B0B0B0 Ee:#464646 Ef:#080808 Eg:#484848 Eh:#585858 Ei:#D0D0D0 Ej:#3F3F3F Ek:#262626 El:#A4A4A4 Em:#ABABAB En:#F7F7F7 Eo:#BFBFBF Ep:#282828 Eq:#B1B1B1 Er:#B5B5B5 Es:#C0C0C0 Et:#343434 Eu:#E5E5E5 Ev:#999 Ew:#AFAFAF Ex:#5E5E5E Ey:#737373 Ez:#0F0F0F Fa:#686868 Fb:#161616 Fc:#EAEAEA Fd:#121212 Fe:#060606 Ff:#474747 Fg:#A9A9A9 Fh:#313131 Fi:#111 Fj:#424242 Fk:#4A4A4A Fl:#454545 Fm:#525252 Fn:#6B6B6B Fo:#363636 Fp:#595959 Fq:#2C2C2C Fr:#444 Fs:#7C7C7C Ft:#9A9A9A Fu:#DBDBDB Fv:#AEAEAE Fw:#4F4F4F Fx:#2D2D2D Fy:#C8C8C8 Fz:#636363 Ga:#C1C1C1 Gb:#C4C4C4 Gc:#D5D5D5 Gd:#E8E8E8 Ge:#E0E0E0 Gf:#E1E1E1 Gg:#E7E7E7 Gh:#BABABA Gi:#DDD Gj:#DCDCDC Gk:#F0F0F0 Gl:#B8B8B8 Gm:#565656 Gn:#323232 Go:#333 Gp:#878787 Gq:#A5A5A5 Gr:#B6B6B6 Gs:#6D6D6D Gt:#090909 Gu:#545454 Gv:#151515 Gw:#5D5D5D Gx:#D1D1D1 Gy:#1E1E1E Gz:#5A5A5A Ha:#7D7D7D Hb:#EFEFEF Hc:#E3E3E3 Hd:#4B4B4B He:#1C1C1C Hf:#383838 Hg:#7A7A7A Hh:#2E2E2E Hi:#A1A1A1 Hj:#757575 Hk:#A0A0A0 Hl:#E2E2E2 Hm:#8A8A8A Hn:#919191 Ho:#C3C3C3 Hp:#9C9C9C Hq:#B9B9B9 Hr:#E4E4E4 Hs:#3C3C3C Ht:#CFCFCF Hu:#181818 Hv:#242424 Hw:#2F2F2F Hx:#DFDFDF
voxels
29-AjBbClAiDlF7-2B3AhF7-2B3FCk9-KEx99-BAlAm2AlAm7-AhBcDnAlAkLBoF5-BF4-2F5-BOCoGoGnFb-Q7-Co4B97-Bf3Am2DvAkDu5-T4-DsL-F3-2B6-2F4-BtT4-FeF6-6B96-QBf2AmL2Bg2LCn3-BT6-AjF3-BT6-2F4-2B4-B-Ah5-7B84-3VAsCy6-ODs2AkVCvAsLVFhAj2-B8-2F2-TGu7-2B2-Bt2B5-BGt5-7B82-AkAfAsAfBgAs3X4-WVCv3-As2Cy2Ax-BO9-Ah-BGy8-EgB2-CpB6-BEf4-8B82-CtL2AfBgAf3Z2Ax-B-A6-X2Ax-B-A8-Q-BCu8-RFl2-IYK4-HbBxAdA3-YH2PEgFjEgCm81-BkClDsVBeAkVXZ2AsAx-B2-3A5-2AaB-A8-2BkEaAq9-2Cd-AdC6-2CA2-CcS5CSC6-Y74-BEhLBg2BeAfX2MZCgWB-5A-2A-2WBA10-QHA9-HTAAd7-AdCA2-AbBvIC3AJAq6-IJ2A71-F2Dq2CfVAfX3MCgWB-2A3-A2-A-WBA2-7A-TH10-EnUJAb7-AvCA2-2AbS2-AJIDe5-YAd2CACA69-EpCtXZHiM2ZFv2MAlAaHh2-3A-2A2-A2Q-E3-A2-3AQAdA9-AR2Ao7-3A2-2N4-SIBrC4-NAe3CBlJ7-Cc62-Fz2BaEdMEsFvEr2EqCgFxBf2-7A2-EkBc-Az7-A-Ez2A9-AAq2C8-C2(A-)N5-AAvC3-Y-CA3C-Au5-AeHlAoCJ-Cm57-CxHoBaCiDjEsGbCiEqBa2AiBf2-7A2-AiBc-A7-A-Bb2A9-2CA9-CA-3A4-4A3-DeP3-JA-Bv4-Ei-AdAeBlJ-FtJ5-AqN4-Bu44-AaEd2Gg2AzGfCiGbHqEjAi-Bm-3AE3A2-CgB-A7-Hp-Bb3A8-2CA9-2A-3A5-3A2-A-A4-A-By4-CbCABlSCA-J4-Cb-CBlSI-Av6-Bh38-DrCq2D2GGfCiEsBf2-Bm3-GdE3A2-Cg-CxDCjGh5-Cf-ChEAz9-2CA9-2A-A7-3A2-3A4-A-Ap4-By4-A2-Cp4-BsGeAoS2C2R5-CBdAeSI-DcBh32-CqG2D2GEuHxBaHw2-Ef4-CiD2A2-Hv-Hu-CjGlEw4-Cf-ChCz-Gj8-AAuAGh8-2A-ACs5-4A2-I-2(A3-)A2-A-2A2-A2-Ap4-Bd-J-I3-I4-Au-DmGkIJBvGk6-U25-Ca3D4GBaHs2-Ef6-AzD-Fw2-Bt-CjLCyEwEr2-HtBn-Cz-Gl8-By-GGi8-2A-AAz6-Dj2A2-G-A3-ACj-Cc3-C2-3A3-Bh4-Ce2-A3-De5-Ce4-I-J5-CCdJAoC-H20-ArG2D4GLAi3-Fb8-Dg2-Co-LFzDuAlErGcFu-Ar-En-Di7-BeEo-GAz6-Hr-2A-EnGi6-Gj2A2-CZ5-Ew-Cc3-A-A3-Du2-Ab3-A2-Di-Ba2-Ab5-K2-Db3-Aq5-YEa2-BlBxBu8-IAe10-Et3D2G2DDn4-Bm8-Ca2-B-ClEpAiAlBgM2-Bk-Cr-Dg6-Gc-Fy-BzCv6-DjGd-A-GeGa5-Eu2-A2-EiAk5-Dj-A3-YBw5-Cj-C3-Y-A3-Di-H4-Fr2-Bn-Et2-P5-N2-Cd-EvAv6-PFeAqBhBy9-Et5D2EDi4-Bm8-O2-B-FhCnFxCtBnDv2-Q-A-Bb6-M-Cc-CsCv7-Ga-A-2Dh5-EuA-A2-HnDa4-2A-Cw3-Ce4-3A-A3-EvBkCz2-A2-Au4-A-YEv-A2-C5-CuAH-HBsDe6-Fj-CmCpEmA8-Ff3E2D2EDg4-Bm7-Dd3-W-WFiBbFw2Da-Ar2-A-Ch6-LDh2-CeAa7-MDh2-Aw8-CqA2-Fs7-AnFy3-U7-Au4-Dc5-AeBtBv4-NO4-IFlAe32-2Bz3E2AFuAg3-Bp8-Ag3-Bq-AjAaEpDgFkEh-Fd2-A-Ch6-DfAn2-HjAh7-DnEo2-U8-HkA2-An7-AwFg3-U7-N4-Cu6-FHm45-Ee4E2AAfW3-Bp8-Ay3-Bt-AaDlAr2DfEj-Q2-A-Cn6-AtBd2-2Ac7-BnEo2-CdDl7-BnA2-Dw7-KEl3-Bx7-K57-BjEe4D2EX4-Ag8-Bi3-Ch-BjFqAtDf2Dd-O2-A-Ek6-BiH2-EmO7-BnA2-BuBc7-DbC2-FaT6-FmBh3-K7-U57-BqEcDE2DEGCf4-Ag7-Ay4-AgBfAgHfAyFoAgBj-Bk2-AHg7-ExH2-BsDy7-AwA2-ACk7-El3-DcF6-EbEm11-Ft57-ArCrE3A2GFn4-Ar7-Ay4-AtEjFqFrDzAtEkAgDy3-AFs7-Eb3-ADd7-El3-ABq6-BiCe3-BlBm6-AcH11-P57-EhCrE3AEHcFn4-Bi7-Ay3-F-Fo2CaDpAtBj-Ck3-ABd6-BjAc3-AFp6-BxDx3-AFp6-HdEi3-IDw6-AwA4-U5-HeK57-AyBzCw3ACzBzCx4-Ay7-Ca3-F-AtGzHaDaFkBj-O3-ADb6-2Ac3-2Cb6-KC3-CbDb6-KA4-Dc5-FmAp5-U5-PAw57-Bo2EcCwECwGxEdCx4-Bi7-At4-Bq-BwBdAnDz2-Fi4-AuEe4-Bi-K4-H6-AvA4-H5-KBr5-2Aw4-NAe5-AvBp3-PAu11-PAv45-ArGqGrCqCrDt2CsCt4-Bp7-Dk4-Aj2-BwGs3-Dy4-H-Dk2-Dz-K5-BhCu4-EaBr5-DxEb3-Bx-Ap5-2Ap3-K-C5-AoAn2-Gv-By7-Gw2-CoPAd45-F2DpGpAnEy2Be5-Fd6-Cl5-Aj6-T5-Ac2-DqDr2-Ff5-DoBuRDtDrBvRAo5-DoBuBrDtAc-Ap7-HFgBwAn-C7-HRBw-Bs8-CpDwU-C10-DxAq36-DkBoGmEy8-BpBqCkOEzO7-AjBoBb2BcAa7-FaBoCmHBdCn8-DmAb2N9-BrAbBsC9-2Fc2C9-RDmC10-RSDo46-
