model
size = 32 4 30, scale = 0.05, origin = -y
material 
  colors = A:#AAA B:#EEE C:#FC0
voxels
12-4A123-6A28-A90-11A25-4A87-14A20-AB7A83-17A17-14A80-18A15-15A79-19A15-2A2(8B6A78-20A13-3A)15B77-22A10-5A14B76-25A8-5A15BA23-2C49-9A9-8A7-5A5B5-5B3A19-6C48-8A9-9A6-3A6B7-4BA2B2A15-9C26-4C17-8A9-9A6-3A5B9-3BA2B2A15-C6-3C23-7C15-9A9-10A5-3A5B9-3B5A15-C6-3C23-7C14-10A9-10A5-3A5B9-5B4A14-C6-3C23-6C14-2B9A9-11A3-4A5B9-5B5A13-C6-3C23-6C14-2B9A9-11A2-5A5B9-5B5A13-C6-2C24-6C13-A2B9A9-11A2-5A6B7-6B5A13-2C4-3C25-4C14-A2B9A9-11A2-5A7B5-7B6A13-8C43-32A2-2AB2A19B5A17-C48-31A2-2AB2A19B4A67-30A4-6A17B4A68-29A4-15A8B4A68-28A6-8A2-15A70-27A8-5A3-14A73-7A-B15A18-13A75-2A5-10A3BA21-7A2B88-6A124-3A105-
