model
size = 20 30 30, scale = 0.05, origin = -y
material 
  colors = A:#444 B:#555 C:#666 D:#933 E:#777 F:#800 G:#663 H:#888 I:#930 J:#111 K:#999 L:#333 M:#222 N:#B00 O:#AAA P:#C33 Q:#400 R:#F99 S:#E00
voxels
-------------------- -------------------- -------------------- -------------------- -------------------- -------------------- -------------------- -------------------- -------------------- -------------------- --------DDDD-------- --------D--D-------- --------D--D-------- --------D--D-------- ---------DD--------- -------------------- -------------------- -------------------- -------------------- -------------------- -------------------- -------------------- -------------------- -------------------- -------------------- -------------------- -------------------- -------------------- -------------------- -------------------- 
---------OK--------- --------EHKE-------- ---------HE--------- -------------------- -------------------- -------------------- -------------------- -------------------- -------BBCEBB------- -------ABCEBA------- -------ABCEBA------- --------GGEG-------- --------G--G-------- ---DDD--G--G--DDD--- --DDDDD-CGC--DDDDD-- -DD---PD----DD---PD- DD-----DD--DD-----DD PD-----DR--PD-----DR DD-----DD--DD-----DD -DP---DD----DP---DD- --DDDDD------DDDDD-- ---DDD--------DDD--- -------------------- -------------------- -------------------- -------------------- -------------------- -------------------- -------------------- -------------------- 
-------HKOKKH------- -------EEHKEE------- -------EEHEEE------- -------CCECCC------- -------CCECCC------- -------------------- -------------------- -------------------- ------BBB--BBB------ ------AABCEBAA------ ------AABCEBAA------ -------BGGEGB------- -------BG--GB------- --DDDDDBG--GBDDDDD-- -D----APCGCCDA----P- I------ADCCDA------I I-------DDDD-------D I-------DDDD-------I D-------DBGD-------I I------ADBGDA------I -D-----DBCCBD-----D- --DDDDD-CCCC-DDDDD-- -------------------- -------------------- -------------------- -------------------- -------------------- -------------------- -------------------- -------------------- 
------HHKOKKHH------ ------EEEHKEEE------ ------EEEHEEEE------ ------CCCECCCC------ ------CCCECCCC------ -------BCCCCB------- -------------------- -------------------- ------BBB--BBB------ ------AABCEBAA------ ------AABCEBAA------ ------ABGGEGBA------ -----AABGGEGBAA----- ----AAABGGCGBAAA---- -----AABCGCCBAA----- I------AGCCGA------I I-------B--B-------D D-------B--B-------D D------AA--AA------I I---AAAAB--BAAAA---I ----ABAAB--BAABA---- -----BABCCCCBAB----- ------ABBCCBBA------ -------JMMMMJ------- --------CCCC-------- -------------------- -------------------- -------------------- -------------------- -------------------- 
-----EHH----HHE----- -----EEE----EEE----- -----EEEE--EEEE----- -----CCCC--CCCC----- ------CCC--CCC------ ------BBC--CBB------ -------------------- -------------------- -----BBBB--BBBB----- -----AAAB--BAAA----- ------A-BCEB-A------ -----AA-GGEG-AA----- ---BAAA-GGEG-AAAB--- ---BAAABGGCGBAAAB--- ------ABCGCCBA------ I-------GCCG-------I D-------B--B-------D D-------B--B-------D D--AFFFAA--AAFFFA--D I--BAAAA----AAAAB--I ---AAB--------BAA--- ----BBA------ABB---- ----BBAB----BABB---- -----JJJM--MJJJ----- -----ACCBBBBCCA----- -------COACCC------- -------------------- -------------------- -------------------- -------------------- 
-----EH------HE----- -----EE------EE----- -----EEE----EEE----- -----CCC----CCC----- -----CCCC--CCCC----- ------BB----BB------ -------------------- -------------------- ------BB----BB------ -----AAAB--BAAA----- -----AA-BCEB-AA----- --AAAAA-GGEG-AAAAA-- --GBAA--GGEG--AABG-- --BBAAABGGCGBAAABB-- -------BCGCCB------- I-------GCCG-------I D-------B--B-------D D-BQ---AB--BA---QB-D D-BAFFFAA--AAFFFAB-D I-BB------------BB-I ---AA----------AA--- ---AB----------BA--- ---ABB--------BBA--- ---JJJ--------JJJ--- ----CECA----ACEA---- -----MCKOKLOKKC----- -------ECCCCE------- -------------------- -------------------- -------------------- 
-----EH------HE----- ----EEE------EEE---- ----EEE------EEE---- ----CCCC----CCCC---- ----CCCC----CCCC---- -----BBB----BBB----- -------------------- -------------------- -----BBB----BBB----- -----AAAB--BAAA----- ---BBAA-BCEB-AABB--- -AABBA---GE---ABBAA- -AG-----GGEG-----GG- --BBAAABGGCGBAAABB-- --AB--ABCGCCBA--BA-- I-BA---AG--GA---AB-I D-BQ-S-AB--BA-S-QB-D D-BAFFFAB--BAFFFAB-D D-BALLLA----ALLLAB-D D-BB------------BB-I --BA------------AB-- --AA------------AA-- --AA------------AA-- ---JJ----------JJ--- ---CHE--------EHC--- ----AHKK----KKHM---- -----CCEHKCHECH----- -------CCCCCC------- -------------------- -------------------- 
-----E--------E----- ----EE--------EE---- ----EEE------EEE---- ----C-C------C-C---- ----CCCC----CCCC---- ----BBBB----BBBB---- -------------------- -------------------- -------------------- -------------------- ----------------B--- -AAAAA--------AABAA- -AG--------------GG- -ABBAAA------AAABBB- -AABAAAB----BAAABAA- I-BAQQAAG--GAAQQAB-I D-BAFLFAB--BAFLFAB-D D-BALLAA----AALLAB-D D-BA------------AB-D D-BB------------BB-D --B--------------B-- --A--------------A-- --AA------------AA-- --JJ------------JJ-- --AKH----------HKC-- ---HKH--------HKA--- ----CHEE----EEHC---- -----CCCCCCCCCC----- -------------------- -------------------- 
-----E--------E----- ----EE--------EE---- ----EEE------EEE---- ----CCC------CCC---- ----CCCC----CCCC---- ----BBBB----BBBB---- ----CBBB----BBBC---- -----AAAB--BAAA----- ---BBAA-BCEB-AAB---- -------------------- -------------------- -AAAAAA-AAAA-AAAAAA- -AGBAA--------AABGG- -AB--------------BB- -AA--------------AA- D-BAAAA------AAAAB-I D-BAALA------ALAAB-D D-B--------------B-D D-B--------------B-D D-B--------------B-D --B--------------B-- --A--------------A-- -AA--------------AA- -JJ--------------JJ- --AK------------KC-- --MHK----------KHC-- ---HHH--------HHC--- ----CCCCEEKECCCC---- ------CCCCCCCC------ -------------------- 
-------------------- ----EE--------EE---- ----EE--------EE---- --FFCCC------CCFF--- -FFFCCC------CCFFF-- -FFCBB--------BFFF-- --FCCB--------BFF--- ---CBAAAB--BAAABC--- -----AAABCEBAAA----- -------------------- -------------------- ---AAAAAAAAAAAAAA--- BGGBAAA------AAABGGA BBBB------------BBBA --A--------------A-- D-B--------------B-D D-B--------------B-D D-B--------------B-D D-B--------------B-D DBB--------------BBD -BB--------------BB- -AA--------------AA- -AA--------------AA- -JJ--------------JJ- -CO--------------CC- --HH------------HC-- ---HH----------HC--- ----CEC------CEC---- -----CCCCCCCCCC----- -------------------- 
-------------------- ----EE--------EE---- -FFEEE--------EFFF-- -FFECC--------CFFF-- --CCCC--------CFC--- --CCBB--------BFC--- -FFCCB--------BFFF-- -NFCB----------FFN-- ---BB-AABCEBAA-BB--- -------------------- -------------------- ---AA-AAAAAAAA-AA--- BG-BAAA------AAAB-GA BBBBA----------ABBBA --A--------------A-- D-B--------------B-D DBB--------------BBD DBB--------------BBD DBB--------------BBD DBB--------------BBD -B----------------B- -A----------------A- -A----------------A- -J----------------J- -HO--------------CC- --HH------------HC-- --EHH----------HHE-- ---CEE--------EEC--- ----CCCCBGCBCCCC---- --------CCCC-------- 
-------------------- --NFE----------FN--- -FFEEE--------EFFF-- --CECC--------CFC--- -IFCCC--------CFFI-- -IFCBB--------BFFI-- --CCCB--------BFC--- -FFCB----------FFF-- --FBB----------FF--- -------------------- -------------------- ---AA-AAAAAAAA-AA--- BG--AAAB----BAAA--GA BBBBAA--------AABBBA -AA--------------AA- DBB--------------BBD DBB--------------BBD DB----------------BD DB----------------BD DB----------------BD -B----------------B- -A----------------A- -A----------------A- -J----------------J- -HO--------------CH- -HL--------------LC- --EH------------HE-- ---CE----------EC--- ----CCCBB--BBCCC---- -------CCCCCC------- 
-------------------- -FFF-----------FFF-- --CEE----------FC--- -IFEA----------FFI-- --CCCC--------CFC--- --CCBB--------BFC--- -IFCC----------FFI-- --CCB----------FC--- -FFBB----------FFF-- -------------------- -------------------- ---AA-AAAAAAAA-AA--- BGG-AAAB----BAAA-GGA BBBBAA--------AABBBA -AA--------------AA- DB----------------BD DB----------------BD DB----------------BD DB----------------BD DB----------------BD AB----------------BA AA----------------AA AA----------------AA -J----------------J- -H----------------C- -HL--------------LC- --EH------------HE-- ---CE----------EC--- ----CCEB----BECC---- ------CCCCCCCC------ 
-------------------- -FFF-----------FFF-- --CEE----------FC--- -IFEA----------FFI-- --CCA----------FC--- --CCB----------FC--- -IFCC----------FFI-- --CCB----------FC--- -FFBB---AAAA---FFF-- -------------------- -------------------- --AAA-AAA--AAA-AAA-- BGGBAAA------AAABGGA BBBBA----------ABBBA -A----------------A- DB----------------BD DB----------------BD DB----------------BD D------------------D D------------------D A------------------A A------------------A AA----------------AA MJ----------------JM -H----------------H- -HL--------------LC- --EH------------HE-- ---CE----------EC--- ----CEE------ECC---- ------CCCCCCCC------ 
-------------------- --NF-----------FN--- -FFF-----------FFF-- --CEA----------FC--- -IFCA----------FFI-- -IFCB----------FFI-- --CCC----------FC--- -FFCB----------FFF-- --NBB--AAAAAA--FN--- -------------------- ---B---------------- --AB-AAA----AAA-AA-- BGGBAAA------AAABGGA BBBB------------BBBA AA----------------AA DB----------------BD D------------------D D------------------D D------------------D D------------------D A------------------A A------------------A A------------------A MJ----------------JM -H----------------H- -HL--------------LC- --EH------------HE-- ---CE----------EC--- ----CEE------ECC---- ------CCCCCCCC------ 
-------------------- -------------------- -NFF-----------FFN-- -FFF-----------FFF-- --CF-----------FC--- --CF-----------FC--- -FFF-----------FFF-- -NFF---AA--AA--FFN-- -------AAAAAA---B--- -----AAAB--BAAA----- ---BBAAABAABAAABB--- --ABBAABGGEGBAABBA-- BGGBAA---GE---AABGGA BB----------------BA A------------------A D------------------D D------------------D D------------------D D------------------D D------------------D A------------------A A------------------A A------------------A MJ----------------JM -H----------------H- -HL--------------LC- --EH------------HE-- ---CE----------EC--- ----CEEB----BECC---- ------CCCCCCCC------ 
-------------------- -------------------- -------------------- --NF-----------FN--- -FFF-----------FFF-- -FFF-----------FFF-- --NN-----------NN--- -------------------- -------------------- --AAAAAAA--AAAAAAA-- --ABBA-AB--BA-ABBA-- --AB----GAAG----BA-- BGG-----GGEG-----GGA B-------GGCG-------A A------------------A D------------------D D------------------D D------------------D D------------------D D------------------D A------------------A A------------------A A------------------A MJ----------------JM -H----------------H- -HL--------------LC- --EH------------HE-- ---CE----------EC--- ----CEEB----BCCC---- -------CCCCCC------- 
-------------------- -------------------- -------------------- -------------------- -------------------- -------------------- -------------------- -------------------- -------------------- --AAAAAA----AAAAAA-- --A----AB--BA----A-- --A----BG--GB----A-- BGG-----G--G-----GGA B-------GGCG-------A A------------------A D------------------D D------------------D D------------------D D------------------D I------------------D A------------------A A------------------A A------------------A MJ----------------JM -H----------------H- -HL--------------LC- --EH------------HE-- ---CEE--------EEC--- ----CEEB----BCCC---- -------CCCCCC------- 
-------------------- -------------------- -------------------- -------------------- -------------------- -------------------- -------------------- -------------------- ---A------------A--- --ACAAAAA--AAAAACA-- -AC----AB--BA----CA- -AC-----G--G-----CA- BGG-----G--G-----GGA BB------GGCG------BA A--------GC--------A D------------------D D------------------D D------------------D D------------------D I------------------D A------------------A A------------------A A------------------A MJ----------------JM -H----------------H- -HL--------------LC- --EH------------HE-- ---CEE--------EEC--- -----EEBB--BBCC----- -------CCCCCC------- 
-------------------- -------------------- -------------------- -------------------- -------------------- -------------------- -------------------- -------------------- -------------------- --AAAAAAAAAAAAAAAA-- -AC-----BCEB-----CA- -A------GGEG------A- -A------GGEG------A- BB------GGCG------BA A--------GC--------A D------------------D D------------------D D------------------D D------------------D I------------------D A------------------A A------------------A AA----------------AA MJ----------------JM -H----------------H- -HL--------------LC- --EHH----------HHE-- ---CEE--------EEC--- -----EECBGCBBCC----- --------CCCC-------- 
-------------------- -------------------- -------------------- -------------------- -------------------- -------------------- -------------------- -------------------- -------------------- --AAAAAAAAAAAAAAAA-- -AC------CE------CA- -A-------GE-------A- -A-------GE-------A- BB----------------BA AA----------------AA DB----------------BI DB----------------BD DB----------------BD DB----------------BD I------------------D A------------------A AA----------------AA AA----------------AA -J----------------J- -HO--------------CH- -HLH------------HLC- --EHH----------HHE-- ----EEC------CEE---- -----CECCCCCCCC----- -------------------- 
-------------------- -------------------- -------------------- -------------------- -------------------- -------------------- -------------------- -------------------- -------------------- --AAAAAAAAAAAAAAAA-- -AC--------------CA- -A----------------A- -A----------------A- -A----------------A- -A----------------A- DB----------------AI DB----------------AD DB----------------AD DB----------------BD IB----------------BD AB----------------BA AA----------------AA -A----------------A- -J----------------J- -HO--------------CH- --HH------------HC-- ---HHH--------HHH--- ----ECCC----CCEE---- ------CCCCCCCC------ -------------------- 
-------------------- -------------------- -------------------- -------------------- -------------------- -------------------- -------------------- -------------------- -------------------- --AAAAAAAAAAAAAAAA-- -ACB------------BCA- -AC--------------CA- -A----------------A- -A----------------A- -A----------------A- DB----------------AI DB----------------AD DB----------------AD DB----------------AD IB----------------AD -B----------------A- -A----------------A- -A----------------A- -JJ--------------JJ- -HO--------------CH- --HHK----------KHH-- ---HCHE------EHHH--- -----CCCEEKOCCC----- -------CCCCCC------- -------------------- 
-------------------- -------------------- -------------------- -------------------- -------------------- -------------------- -------------------- -------------------- -------------------- ---AAAAAAAAAAAAAA--- --AB------------BA-- -AC--------------CA- -AG--------------GA- -A----------------A- -A----------------A- IB----------------AI DB----------------AD DB----------------AD DB----------------AD IB----------------AD -B----------------A- -A----------------A- -AA--------------AA- -JJ--------------JJ- --OK------------KC-- --HHKH--------HKHH-- ----CCEE----EEHH---- ------CCCCCCCC------ -------------------- -------------------- 
-------------------- -------------------- -------------------- -------------------- -------------------- -------------------- -------------------- -------------------- -------------------- ---AAAAAAAAAAAAAA--- --ABB----------BBA-- --AB------------BA-- -AG--------------GA- -AB--------------BA- -A----------------A- IB----------------AI DB----------------AD DB----------------AD DB----------------AD IB----------------AD -B----------------A- -AA--------------AA- -AA--------------AA- --JJ------------JJ-- --OKH----------HKC-- ---HKHK------KHKH--- -----CCEHKCCECH----- -------CCCCCC------- -------------------- -------------------- 
-------------------- -------------------- -------------------- -------------------- -------------------- -------------------- -------------------- -------------------- -------------------- ----AAAAAAAAAAAA---- ---BBAA------AABB--- --AB------------BA-- --AB------------BA-- -AB--------------BA- -AA--------------AA- IBB--------------BAI DBB--------------BAI DBB--------------BAD IBB--------------BAD IBB--------------BAI -BB--------------BA- -AAA------------AAA- --AA------------AA-- --JJJ----------JJJ-- ---KHEC------CEHK--- ----KHKKOKLLKKHK---- ------CCCCCCCC------ -------------------- -------------------- -------------------- 
-------------------- -------------------- -------------------- -------------------- -------------------- -------------------- -------------------- -------------------- -------------------- ------AAAAAAAA------ ---AAAAABCEEAAAAA--- ---ABA--------ABA--- --ABA----------ABA-- --AB------------BA-- --AB------------BA-- IDB--------------BDI DDB--------------BDI IBB--------------BAI IBB--------------BAI IDBB------------BBDI --BA------------AB-- --AAB----------BAA-- ---ABB--------BBA--- ---JJJJ------JJJJ--- ----HECABBBEACEH---- ------CCCCCCCK------ -------------------- -------------------- -------------------- -------------------- 
-------------------- -------------------- -------------------- -------------------- -------------------- -------------------- -------------------- -------------------- -------------------- -------------------- -----AAAAAAAAAA----- ----AAABGGEEBAAA---- ---BAAAB----BAAAA--- ---BA----------AA--- --ABA----------ABA-- -IBA------------ABD- -DBA------------ABD- -DBA------------ABD- -DBAL----------LABD- -IBBA----------ABBI- ---AAB--------BAA--- ---ABBA------ABBA--- ----BBABB--CBABB---- -----JJJMMMMJJJ----- ------CCBBBEAC------ -------------------- -------------------- -------------------- -------------------- -------------------- 
-------------------- -------------------- -------------------- -------------------- -------------------- -------------------- -------------------- -------------------- -------------------- -------------------- -------------------- -------AAAAAA------- ----AAAAAAAAAAAA---- ----AAABGGCCBAAA---- ---AAAAB----BAAAA--- -IIAAAA-----DAAAADI- -IDAALA-----DALAADI- -DDALL------DDLLADD- -IDALLL-----DLLLADI- -IIDAAAA----AAAADDI- ----ABAABCCCAABA---- -----BABCCCCBAB----- ------ABBCCCBA------ --------MMMM-------- -------------------- -------------------- -------------------- -------------------- -------------------- -------------------- 
-------------------- -------------------- -------------------- -------------------- -------------------- -------------------- -------------------- -------------------- -------------------- -------------------- -------------------- -------------------- -------------------- -------BGGCCB------- ------ABCGCCBA------ ---IIIIDDDDIIIIII--- ---DDDDDDDDDDDDDI--- ---DDDDDDDDDDDDDD--- ---DDDDDDDDDDDDDD--- ---IIDDDDDDDDDDDI--- -------ABCCCA------- -------------------- -------------------- -------------------- -------------------- -------------------- -------------------- -------------------- -------------------- -------------------- 
