model
size = 26 32 14, scale = 0.05, origin = -y
material 
  colors = A:#111 B:#222 C:#001 D:#EEE E:#700 F:#400
voxels
36-2A2B2A20-2A3BA20-2A2B2A20-A3B2A21-A2BA22-A2BA21-3(2A2B2A20-)BA2B2A20-A6B19-2A2B2A20-BA2BA21-2A2BA22-A2BA-A19-2A2B2A19-3A2B3A17-4A2BAB2A16-3A3B2(AB)16-3A3B4A16-3A-2B-B2A15-4AB2E2B2AB15-2A2B2EB3A16-3AB2EF3A17-AB4-2B19-B4-B173-C3ACAB4AC15-AB-2A2B-2A16-2(2AB)4A16-5A2B3A16-3ABA2(B4A16-5A)B4A17-2ACAB2AB18-4A2(BA)18-4AB3A18-4A2(BA)19-A4B2A19-3A3B2A18-BC4A18-A2B2A2B3A16-5AB4A15-4AB2CB4A14-4AB3AC3A14-8A2(BA)14-10A2B14-12A14-2(3AB)4A14-12A14-4A2BA2B3A15-2AB4EB2A18-B4EB21-4E49-2(2E24-)2E45-4A4-4A14-4A4-4A15-A2(BA-)3A16-4A3B3A16-10A16-8ACA16-10A16-6A2(BA)16-10A16-11A16-4AC3A18-ABA2B5A17-2B2A2B-A16-3ABA2B3A16-ACA3BAB3A15-AC8A15-7AB4A13-13AB12-8AB6A11-11A2B3A10-AB13A11-16A10-15A11-11ABC2A12-7AB2AB3A14-8A18-BD4ADB18-B2D2F2DB19-2D2A2D20-2D2AD22-4D43-6A2B6A12-14A2(12-4AC2AB6A)12-5ABA2B5A12-3ABA2B7A12-6ABAB5A12-6A3B5A13-B2AB8A14-4AB7A14-A-2AB5A-A14-4A2B4A-A13-11ABA13-9AB4A13-2AC2AB6A14-2A2C8A13-4AB9A11-14A2B10-7AB9A9-17A9-14AB2A8-11AB6A7-7AB4AB7A6-4AB5AB9A7-18A8-6AB11A9-14ABA11-8AB5A14-2B6A2B16-2AD4A2DB18-6D41-16A10-6AB9A10-5AC2AB7A10-5A2CAB7A10-5ABA2B7A10-8AB4AB2A11-7AB4ABA12-8A3BAB9-A3-A-10A5-B4-A4-7ABACA2B3-B4-2A3-8AC3A3-AB4-2A3-3AB2A2BCA2B3-AB2(4-AB2-4AB5A2B2A2-2A)4-2A2-5AC3A2B3A2-2B4-BA2-B3A3B2AB4A2-2A3-3A2-4AB2A2B2ABC2A-3A2-AB22A2-2B9A2B3AB7A2-B6AB8AB4ABAC3-6AB8AB6A4-2(6AB)6A2B4-6ABAB2AB3A3B2ABA4-11A2B9A5-AB3A3B2AB9A6-20A6-19AB8-16A11-5A3D6A14-BAD3-DADB18-D4-D41-16A6-2B2-7ABAB6A2-2B2-2A2-7AC8A2-2B2-2A2-16A2-2B2-AB2-7AB6ACA2(2-2A)2-B5AB9A2(2-2A)2-6AB9A2(2-2A)2-5AB3A3B4A2-2B2-ABA-4AB2ABAB6A-3A2-3A-2ABAB4A2B2ABA2(2-3A)2-6AB2AC2A2B2-3A2-2AB2-4A3BAB3ABA2(2-3A)2-2AB6AB2ABA2(2-3A)2-2(4AB)2ABA2-B2C2-4A-4ABAB6AC-A2CB2-2(BA)-4A2(B3A)2B-ABCA-13A3B6A3C4AB9AB7AB3C14A2B3AC4ABC14AB3AB2ABAB2CA-14AB9A2-12A2BC9A2-12AB4AB6A2-12AB11A3-11AB10A4-15AB6A4-10AD9ABC5-8AD-2D8A8-5AD4-D5A12-2BAD5-DBA16-D6-D40-9AB2AB3A5-BAB2-9A2B5A2-3B3A2-7A2B6AC2-2C4A2-7A3B6A2-BC4A2-9AB6A2-4A2BA-6AB9A-4AB3A-2AB11ACA-4A2(BA)-2AB5A4B4A-A2(2BA-)2(2ABAB)6A-A2B-4A-2AB4A4B2A2BA-7AB-2A4BA2B2(2AB)A-A2B4AB-2A3B2AB4AB2A2-8A2-2AB3A2BA3B2A2-9A-2AB3ABA2BAB2A-10A-7A4BA2C-4CA-3AB3A3BCAB4ACA4CA-10ABA6B2A3C14AB3AB6ABC13A2B10ABC12AB3A2(BA)BC8AB22A-21A2BA2-5AB2A2B14A2-5AB6A2BAC8A3-4AB6AB10A4-9A2B11A4-2(BA)3B2ABD11A4-2AB6AD-2D9A7-5AD4-D5A11-3ABD5-D3A15-D6-D40-B6ABA5B2A5-B-AB-7ABA3B4A-2B-BA2-A-7A2BAB3A2C-C2-CA2-A-7ACBA2B2ACA-C2-CA2-A-9A3BC3A-C2-AB2-A-9A3B4A-A2-2A2-A-11AB4A-A2-2A2-A-8A4B4A-A2-3A-A-5AB10A-B-4A3-2AB6A5BAB3-4A3-2AB5A2BA5B3-11AB3ABACBC3A3B11A2BA5BAB2A3B3A-3AB3A2BA2BC4B4AB-2A-3AB5AC4B2AC3A2B-2A-9AC2AB3AC5A-5AB3AB4A2B6A2CAC5AB6AB18A2B5A2B8A-8AB4A3B9ABC3AB3A3B2A2B15AB3A3B2A2B4AB6AB12A2B15A-12AB11A2-24A3-11AB10A4-21AB4-10AD11A6-7A4D7A9-6A6D4A14-2D5-D14-B4A6-C4A10-B5A2B8A5-3B2-7AB2A2B2(AB)2-3B4A-7ACBA2B2ACA-A2B5A-7AC2(B2A)CB-A2BA-3A-7ABAB6A-2CB2-3A-10A2B4A-3B2-ABA-3AB2A2(B4A)-2AB2-3A-3AB3A3B6A-A2B2-3A-6A2B8A-3A-4A-2ABAB2A4B5A-2B6A-2AB4A3B2(2AB)-AB4ABA-8A2BCA2BAB-4A-3A-3BA2B2(AB)6A-B2A2-3A-2B2A2BA3B6A-ABA2-3A-AB3AB2A4BACBA-ABA2-9A5B3AC6A2-AB3A3B2(A2B)10A-2AB18A-12AB2A2B8A-12AB9AB24AB21ABAB19A2B15A-24A3-22A4-9A3B10A5-20A7-9AB8A9-16A15-B6A19-6D16-5A3B2AC3A12-5A3B6A12-B4A4B3ABA8-A3-2A2(BA)2B5AC8-A3-6A3B4AC2(12-6A3B5A)11-3A2(B2A)B6A10-3AB4A2B5AB10-3AB2A3B7A10-B2A2B2ABAB6A10-2(3AB)AB4A2B11-9AB4A12-3A4B7A12-2A4B2C6A12-5AC2B2ABACA12-4A2C2B4ACA11-4A5BAB5A10-4AB2AB8A6-2A2-4ABC2B6ABA-3A2-2A2-3A2BC6A2B2A-3A2-AB2-3A2BCA3C6A-3A3-8AB12AB4-A-5A2B13A4-A2-9AB9A6-6AC11A8-7AB10A10-14A14-12A91-4AC2B6A13-4ACB7A12-5ACB3C4A12-3A2BAC2B4ACA11-3ABA2CAB4ACA10-5ABAB8A10-A3BABCA2(B3A)10-4A2BC2(2AB)3A10-4A2BC9A10-3A3BCB3C5A10-2A4B3AB6A11-5B2(3AB)A12-5B4AB4A12-3A2BCB7A12-B2A3B2C6A12-B5AB4AB2A12-BA5B2AB4A11-3AB2AB3A2B4A10-4A2BAB8A10-A3BAB10A10-ABA2B11A10-4AB11A10-2(5AB)4A10-AB4AB8AB10-16A10-8AB7A10-8A2B6A13-10A120-11A-A12-14A11-7A2C6A12-4A2B8A11-5AB9A11-5A2B5AB2A11-B2(3A3B)2A10-5A3B3A2B3A10-4A2BAB8A11-2A5B7A12-2ABAB2AB5AB12-BA2B3A2(BA)2BA12-2BA2B4AB4A12-B3AB7ABA14-11A14-7AB4A13-5AB2AB5A13-7A3B3A12-4AB9A12-4AB10A10-16A10-8AB3A2B2A10-10A4B2A10-3AB11AB10-5AB4AB5A10-10AB5A11-6A3B5A144-4AB7AB13-12AB12-14A12-12ACA12-4A2B8A12-5AB7A13-3AB9A12-5AB7AC12-6AB7A13-AB11A12-6A4B4A12-6A2BAB4A14-4A3BAB2A14-AB3A4B2A16-B9A16-7AB2A16-5A3B2A16-3ACA2B3A17-10A14-A-11A13-3A2B2A2BABA15-2A2B2(2AB)A15-5ABC2B2A15-7A3B18-2(2AB)A199-4AB5A-B14-11AB13-13A12-B12AC13-13A14-4AC6AB13-12A15-11A15-9ABA15-2A2B5ABA15-4ABAB4A15-6AB2ABA14-B5ABA2B2A16-3A2B4A16-10A16-B3AB5A16-3A2B5A16-5A2B3A17-B7A18-3AB3A19-2A2BABA20-A2B2A22-B3A245-
