model
size = 30 31 24, scale = 0.05, origin = -y
material 
  colors = A:#FFAE00 B:#2A4A5B C:#46647C D:#4B4B4B
voxels
------------------------------ ------------------------------ ------------------------------ ------------------------------ ----AAAAAAAAA--AAA------AAA--- ---AAAAAAAAAAA-AAAA----AAAA--- --AAAAAAAAAAAAA-AAAA--AAAA---- -AAAAA------AAA--AAAA-AAA----- -AAAAAA------AAA--AAAAAAA----- -AAAAAAAA----AAA---AAAAA------ -AAA-AAAAA---AAA---AAAA------- -AAA---AAAA--AAA--AAAAAA------ -AAA----AAAA-AAA--AAAAAAA----- -AAA-----AAAAAAA-AAAA-AAAA---- -AAA------AAAAAA-AAA---AAA---- --AAAA-----AAAAAAAA----AAAA--- --AAAAAAAAAAAA---------------- ---AAAAAAAAAA----------AAAA--- ------AAAAA------------AAAA--- --AAA---------------------AA-- -AAAAAA-AAAAAAA-AAAAAAAAAAAAA- -AA--AAAAA-AA-A-AA--A--A--AA-- -AAA-AA-AA-AA-AA-A--A--A--AA-- --A--AA-AA-AA-AA-A--AA-AA-AA-- ----AAA-AA-AA-AA-AA-AA-AA-AA-- ---AAA--AA--A-AA--AAAA--AAAAA- ---AA------------------------- ---AA-DA---------------------- ----AAA----------------------- ------------------------------ ------------------------------ 
------------------------------ ------------------------------ ------------------------------ ------------------------------ ----AAAAAAAAA--AAA------AAA--- ---AAAAAAAAAAA-AAAA----AAAA--- --AAAAAAAAAAAAA-AAAA--AAAA---- -AAAAA------AAA--AAAA-AAA----- -AAAAAA------AAA--AAAAAAA----- -AAAAAAAA----AAA---AAAAA------ -AAA-AAAAA---AAA---AAAA------- -AAA---AAAA--AAA--AAAAAA------ -AAA----AAAA-AAA--AAAAAAA----- -AAA-----AAAAAAABAAAA-AAAA---- -AAA------AAAAAABAAA---AAA---- --AAAA-----AAAAAAAA----AAAA--- --AAAAAAAAAAAABBB------------- ---AAAAAAAAAABBBB------AAAA--- ------AAAAA--BBBB------AAAA--- --AAA--------BBBB---------AA-- -AAAAAA-AAAAAAABAAAAAAAAAAAAA- -AA--AAAAA-AABABAA--A--A--AA-- -AAA-AA-AA-AABAABA--A--A--AA-- --A--AA-AA-AA-AA-A--AA-AA-AA-- ----AAA-AA-AA-AA-AA-AA-AA-AA-- ---AAA--AA--A-AA--AAAA--AAAAA- ---AA------------------------- ---AA-DA---------------------- ----AAA----------------------- ------------------------------ ------------------------------ 
------------------------------ ------------------------------ ------------------------------ ------------------------------ ----AAAAAAAAA--AAA------AAA--- ---AAAAAAAAAAA-AAAA----AAAA--- --AAAAAAAAAAAAA-AAAA--AAAA---- -AAAAA------AAA--AAAA-AAA----- -AAAAAA------AAAB-AAAAAAA----- -AAAAAAAA----AAAB--AAAAA------ -AAA-AAAAA---AAAB--AAAA------- -AAA---AAAA--AAAB-AAAAAA------ -AAA----AAAA-AAAB-AAAAAAA----- -AAA-----AAAA----AAAA-AAAA---- -AAA------AAA----AAA---AAA---- --AAAA----BAA----AAB---AAAA--- --AAAAAAAAAAA----BBB---------- ---AAAAAAAAAA----BBB---AAAA--- ------AAAAABB----BBB---AAAA--- --AAA-----BBB----BBB------AA-- -AAAAAA-AAAAA----AAAAAAAAAAAA- -AA--AAAAABAA----ABBA--A--AA-- -AAA-AA-AABAA----ABBA--A--AA-- --A--AA-AA-AABAABA--AA-AA-AA-- ----AAA-AA-AABAABAA-AA-AA-AA-- ---AAA--AA--ABAAB-AAAA--AAAAA- ---AA------------------------- ---AA-DA---------------------- ----AAA----------------------- ------------------------------ ------------------------------ 
--------------BB-------------- -------------BBBB------------- -------------BBBB------------- -------------BBBB------------- ----AAAAAAAAABBAAA------AAA--- ---AAAAAAAAAAABAAAA----AAAA--- --AAAAAAAAAAAAABAAAA--AAAA---- -AAAAA------AAABBAAAA-AAA----- -AAAAAA---BBB----BAAAAAAA----- -AAAAAAAA-BBB----BBAAAAA------ -AAA-AAAAABBB----BBAAAA------- -AAA---AAAABB----BAAAAAA------ -AAA----AAAAB----BAAAAAAA----- -AAA----BA----------ABAAAA---- -AAA----BB----------BB-AAA---- --AAAA--BB----------BB-AAAA--- --AAAAAAAA----------BB-------- ---AAAAAAA----------BB-AAAA--- ------AAAA----------BB-AAAA--- --AAA---BB----------BB----AA-- -AAAAAA-AA----------AAAAAAAAA- -AA--AAAAA----------AB-A--AA-- -AAA-AA-AA----------AB-A--AA-- --A--AA-AABAA-AA-ABBAA-AA-AA-- ----AAA-AABAA-AA-AABAA-AA-AA-- ---AAA--AABBA-AA-BAAAA--AAAAA- ---AA--------BBBB------------- ---AA-DA-----BBBB------------- ----AAA------BBBB------------- -------------BBBB------------- -------------BBBB------------- 
--------------BB-------------- ------------BBBBBB------------ ----------BBBBBBBBBB---------- ----------BBBB--BBBB---------- ----AAAAAA--------BB----AAA--- ---AAAAAAA---------B---AAAA--- --AAAAAAAA---------A--AAAA---- -AAAAA----BB--------A-AAA----- -AAAAAA-BB-----------AAAA----- -AAAAAAAAB------------AA------ -AAA-AAAAA------------A------- -AAA---AAA------------AA------ -AAA----A-------------AAA----- -AAABBBB--------------AAAA---- -AAABBBB--------------BAAA---- --AAAABB--------------BAAAA--- --AAAAAA--------------BBBB---- ---AAAAA--------------BAAAA--- ----BBAA--------------BAAAA--- --AAABBB--------------BBBBAA-- -AAAAAAB--------------AAAAAAA- -AA-BAAA--------------BABBAA-- -AAABAAB--------------BABBAA-- --A--AA-AA----------AA-AA-AA-- ----AAA-AA----------AA-AA-AA-- ---AAA--AA----------AA--AAAAA- ---AA-----BBB----BBB---------- ---AA-DA--BBBB--BBBB---------- ----AAA---BBBBBBBBBB---------- ----------BBBBBBBBBB---------- ------------BBBBBB------------ 
------------------------------ ------------B----B------------ ----------BBB----BBB---------- --------BBBBB----BBBBB-------- ----AAAA----------BBBB--AAA--- ---AAAAA------------BB-AAAA--- --AAAAAA------------BBAAAA---- -AAAAA--BB-----------B--A----- -AAAAAAB-----------------B---- -AAAAAA-----------------BB---- -AAABAA----------------BBB---- -AAABBB-----------------BB---- -AAABBBB-----------------B---- -AAAB---------------------BBB- -AAA----------------------BBB- -BAA----------------------ABB- -BAA----------------------BBB- BBBA-----------------------BBB BBBB-----------------------BBB BBAA-----------------------ABB BAAA-----------------------AAB BAAB-----------------------ABB BAAA-----------------------ABB --A-BAAB--------------BAABAA-- ----AAAB--------------BAABAA-- ---AAABB--------------BBAAAAA- ---AA---BBBB------BBBB-------- ---AA-DABBBBB----BBBBB-------- ----AAA-BBBBB----BBBBB-------- ----------BBB----BBB---------- ------------B----B------------ 
------------------------------ ------------------------------ ------------------------------ --------BB----------BB-------- ----AAAA------------BBBBAAA--- ---AAAAA------------BBBAAAA--- --AAAAAA--------------AAAA---- -AAAAABB----------------AB---- -AAA--A------------------BB--- -AAA--------------------BBBB-- -AAAB---------------------BB-- -AAAB---------------------BB-- -AAAB---------------------BB-- -AAA----------------------BBB- -AAA----------------------BBB- -BAA----------------------ABB- -BAA----------------------BBB- BBBA-----------------------BBB BBB------------------------BBB BBA------------------------ABB BAA------------------------AAB BAA------------------------ABB BAAA-----------------------ABB BBABB--------------------BAABB BBBBAAAB--------------B--BAABB --BAAABB--------------BBAAAAA- ---AABBBBB----------BBBBBB---- ---AA-DABB----------BBBB------ ----AAA-BB----------BB-------- ------------------------------ ------------------------------ 
------------------------------ ------------------------------ ------------------------------ ------------------------------ ------BB--------------BB------ ----BBBB--------------BBBB---- ---BBBBB--------------BBBBB--- ---BBB------------------BBB--- --------------------------B--- --BB----------------------BB-- --BB----------------------BB-- --BB----------------------BB-- --BB----------------------BB-- --BB----------------------BB-- --BB----------------------BB-- --BB----------------------BB-- --BB----------------------BB-- -BB------------------------BB- -BB------------------------BB- -BB------------------------BB- -BB------------------------BB- -BB------------------------BB- -BB------------------------BB- BBBB----------------------BBBB BBBB----------------------BBBB --BB----------------------BB-- ----BBBB--------------BBBB---- ------BB--------------BB------ ------------------------------ ------------------------------ ------------------------------ 
------------------------------ ------------------------------ ------------------------------ ------------------------------ ------------------------------ ------------------------------ --------------------------B--- ---B----------------------B--- ---B----------------------B--- --BB----------------------BB-- --BB----------------------BB-- --BB----------------------BB-- --BB----------------------BB-- --BB----------------------BB-- --BB----------------------BB-- --BB----------------------BB-- --BB----------------------BB-- -BB------------------------BB- -BB------------------------BB- -BB------------------------BB- -BB------------------------BB- -BB------------------------BB- -BB------------------------BB- BBB------------------------BBB BBB------------------------BBB ------------------------------ ------------------------------ ------------------------------ ------------------------------ ------------------------------ ------------------------------ 
------------------------------ ------------------------------ ------------------------------ ------------------------------ ------------------------------ ------------------------------ ---B----------------------B--- ---B----------------------B--- ---B----------------------B--- --BB----------------------BB-- --BB----------------------BB-- --BB----------------------BB-- --BB----------------------BB-- --BB----------------------BB-- --BB----------------------BB-- --BB----------------------BB-- --BB----------------------BB-- -BB------------------------BB- -BB------------------------BB- -BB------------------------BB- -BB------------------------BB- -BB------------------------BB- -BB------------------------BB- BBB------------------------BBB BBB------------------------BBB ------------------------------ ------------------------------ ------------------------------ ------------------------------ ------------------------------ ------------------------------ 
------------------------------ ------------------------------ ------------------------------ ------------------------------ ------------------------------ ------------------------------ ---B----------------------B--- ---B----------------------B--- ---B----------------------B--- --BB----------------------BB-- --BB----------------------BB-- --BB----------------------BB-- --BB----------------------BB-- --BB----------------------BB-- --BB----------------------BB-- --BB----------------------BB-- --BB----------------------BB-- -BB------------------------BB- -BB------------------------BB- -BB------------------------BB- -BB------------------------BB- -BB------------------------BB- -BB------------------------BB- BBB------------------------BBB BBB------------------------BBB ------------------------------ ------------------------------ ------------------------------ ------------------------------ ------------------------------ ------------------------------ 
------------------------------ ------------------------------ ------------------------------ ------------------------------ ------------------------------ ------------------------------ ---B----------------------B--- ---B----------------------B--- ---B----------------------B--- --BB----------------------BB-- --BB----------------------BB-- --BB----------------------BB-- --BB----------------------BB-- --BB----------------------BB-- --BB----------------------BB-- --BB----------------------BB-- --BB----------------------BB-- -BB------------------------BB- -BB------------------------BB- -BB------------------------BB- -BB------------------------BB- -BB------------------------BB- -BB------------------------BB- BBB------------------------BBB BBB------------------------BBB ------------------------------ ------------------------------ ------------------------------ ------------------------------ ------------------------------ ------------------------------ 
------------------------------ ------------------------------ ------------------------------ ------------------------------ ------------------------------ ------------------------------ ------------------------------ ---B----------------------B--- ---B----------------------B--- --BB----------------------BB-- --BB----------------------BB-- --BB----------------------BB-- --BB----------------------BB-- --BB----------------------BB-- --BB----------------------BB-- --BB----------------------BB-- --BB----------------------BB-- -BB------------------------BB- -BB------------------------BB- -BB------------------------BB- -BB------------------------BB- -BB------------------------BB- -BB------------------------BB- BBB------------------------BBB BBB------------------------BBB ------------------------------ ------------------------------ ------------------------------ ------------------------------ ------------------------------ ------------------------------ 
------------------------------ ------------------------------ ------------------------------ ------------------------------ ------------------------------ ------------------------------ ------------------------------ ---B----------------------B--- ---B----------------------B--- --BB----------------------BB-- --BB----------------------BB-- --BB----------------------BB-- --BB----------------------BB-- --BB----------------------BB-- --BB----------------------BB-- --BB----------------------BB-- --BB----------------------BB-- -BB------------------------BB- -BB------------------------BB- -BB------------------------BB- -BB------------------------BB- -BB------------------------BB- -BB------------------------BB- BBB------------------------BBB BBB------------------------BBB ------------------------------ ------------------------------ ------------------------------ ------------------------------ ------------------------------ ------------------------------ 
------------------------------ ------------------------------ ------------------------------ ------------------------------ ------------------------------ ------------------------------ ------------------------------ ---B----------------------B--- ---B----------------------B--- --BB----------------------BB-- --BB----------------------BB-- --BB----------------------BB-- --BB----------------------BB-- --BB----------------------BB-- --BB----------------------BB-- --BB----------------------BB-- --BB----------------------BB-- -BB------------------------BB- -BB------------------------BB- -BB------------------------BB- -BB------------------------BB- -BB------------------------BB- -BB------------------------BB- BBB------------------------BBB BBB------------------------BBB ------------------------------ ------------------------------ ------------------------------ ------------------------------ ------------------------------ ------------------------------ 
------------------------------ ------------------------------ ------------------------------ ------------------------------ ------------------------------ ------------------------------ ------------------------------ ---B----------------------B--- ---B----------------------B--- --BB----------------------BB-- --BB----------------------BB-- --CB----------------------BC-- --CB----------------------BC-- --CB----------------------BC-- --CB----------------------BC-- --BB----------------------BB-- --BB----------------------BB-- -BB------------------------BB- -BB------------------------BB- -CB------------------------BC- -CB------------------------BC- -BB------------------------BB- -BB------------------------BB- BBB------------------------BBB BBB------------------------BBB ------------------------------ ------------------------------ ------------------------------ ------------------------------ ------------------------------ ------------------------------ 
------------------------------ ------------------------------ ------------------------------ ------------------------------ ------------------------------ ------------------------------ ------------------------------ ---B----------------------B--- ---B----------------------B--- --BB----------------------BB-- --CB----------------------BC-- ------------------------------ ------------------------------ ------------------------------ ------------------------------ --CB----------------------BC-- --BB----------------------BB-- -BB------------------------BB- -CB------------------------BC- ------------------------------ ------------------------------ -CB------------------------BC- -BB------------------------BB- BBB------------------------BBB BBB------------------------BBB ------------------------------ ------------------------------ ------------------------------ ------------------------------ ------------------------------ ------------------------------ 
------------------------------ ------------------------------ ------------------------------ ------------------------------ ------------------------------ ------------------------------ ------------------------------ ------------------------------ ---B----------------------B--- --CB----------------------BC-- ------------------------------ ------------------------------ ------------------------------ ------------------------------ ------------------------------ ------------------------------ --CB----------------------BC-- -CB------------------------BC- ------------------------------ ------------------------------ ------------------------------ ------------------------------ -CB------------------------BC- BBB------------------------BBB BBB------------------------BBB ------------------------------ ------------------------------ ------------------------------ ------------------------------ ------------------------------ ------------------------------ 
------------------------------ ------------------------------ ------------------------------ ------------------------------ ------------------------------ ------------------------------ ------------------------------ ------------------------------ ---B----------------------B--- --CB----------------------BC-- ------------------------------ ------------------------------ ------------------------------ ------------------------------ ------------------------------ ------------------------------ --CB----------------------BC-- -CB------------------------BC- ------------------------------ ------------------------------ ------------------------------ ------------------------------ -CB------------------------BC- BBB------------------------BBB BBB------------------------BBB ------------------------------ ------------------------------ ------------------------------ ------------------------------ ------------------------------ ------------------------------ 
------------------------------ ------------------------------ ------------------------------ ------------------------------ ------------------------------ ------------------------------ ------------------------------ ------------------------------ ---B----------------------B--- --CB----------------------BC-- ------------------------------ ------------------------------ ------------------------------ ------------------------------ ------------------------------ ------------------------------ --CB----------------------BC-- -CB------------------------BC- ------------------------------ ------------------------------ ------------------------------ ------------------------------ -CB------------------------BC- BBB------------------------BBB BBB------------------------BBB ------------------------------ ------------------------------ ------------------------------ ------------------------------ ------------------------------ ------------------------------ 
------------------------------ ------------------------------ ------------------------------ ------------------------------ ------------------------------ ------------------------------ ------------------------------ ------------------------------ ---B----------------------B--- --CB----------------------BC-- ------------------------------ ------------------------------ ------------------------------ ------------------------------ ------------------------------ ------------------------------ --CB----------------------BC-- -CB------------------------BC- ------------------------------ ------------------------------ ------------------------------ ------------------------------ -CB------------------------BC- BBB------------------------BBB BBB------------------------BBB ------------------------------ ------------------------------ ------------------------------ ------------------------------ ------------------------------ ------------------------------ 
------------------------------ ------------------------------ ------------------------------ ------------------------------ ------------------------------ ------------------------------ ------------------------------ ------------------------------ ------------------------------ --BB----------------------BB-- --CB----------------------BC-- ------------------------------ ------------------------------ ------------------------------ ------------------------------ --CB----------------------BC-- --BB----------------------BB-- -BB------------------------BB- -CB------------------------BC- ------------------------------ ------------------------------ -CB------------------------BC- -BB------------------------BB- ------------------------------ ------------------------------ ------------------------------ ------------------------------ ------------------------------ ------------------------------ ------------------------------ ------------------------------ 
------------------------------ ------------------------------ ------------------------------ ------------------------------ ------------------------------ ------------------------------ ------------------------------ ------------------------------ ------------------------------ ------------------------------ --BB----------------------BB-- --CB----------------------BC-- --CB----------------------BC-- --CB----------------------BC-- --CB----------------------BC-- --BB----------------------BB-- ------------------------------ ------------------------------ -BB------------------------BB- -CB------------------------BC- -CB------------------------BC- -BB------------------------BB- ------------------------------ ------------------------------ ------------------------------ ------------------------------ ------------------------------ ------------------------------ ------------------------------ ------------------------------ ------------------------------ 
------------------------------ ------------------------------ ------------------------------ ------------------------------ ------------------------------ ------------------------------ ------------------------------ ------------------------------ ------------------------------ ------------------------------ ------------------------------ ------------------------------ ------------------------------ ------------------------------ ------------------------------ ------------------------------ ------------------------------ ------------------------------ ------------------------------ -BB------------------------BB- -BB------------------------BB- ------------------------------ ------------------------------ ------------------------------ ------------------------------ ------------------------------ ------------------------------ ------------------------------ ------------------------------ ------------------------------ ------------------------------ 
