model
size = 32 32 14, scale = 0.05, origin = -y
material 
  colors = A:#081818 B:#071318
voxels
301-4A27-A3B2A26-ABA2-BA23-A2-2A3-BA21-2A3-BA2-AB20-A2BA2-AB3-2A21-2B3-BA2-2A22-BA2-AB2-BA23-BA2-BA2BA24-2A2-2B2A25-3A-A28-B2A30-BA65-2A30-2A445-2A30-2B2A29-4BA21-4A2-2B23-A3B2A2-BA22-A2(BA2-)BA19-A2-2A3-BA-BA18-2A3-BA2-AB2-BA4-A11-A2BA2-AB3-2A-2A3-3A12-2B3-BA2-2A2-BA18-BA2-AB2-BA2-2A15-2A2(2-BA)2BA18-4A2-2A2-2B2A18-2B-BA2-3A-A20-2B2-BA2-B2A21-AB3-2A2-BA22-AB3-2A26-2B3-3A2-2A20-A2B3-B3-2A21-2AB31-2A30-A357-2A30-2B2A2-A26-4BA-A19-4A2-2B5-A17-A3B2A2-BA4-A17-A2(BA2-)BA4-AB-A11-A2-2A3-BA-BA4-2(AB)A9-2A3-BA2-AB2-BA4-ABA9-A2BA2-AB3-2A-2A3-3A12-2B3-BA2-2A2-BA18-BA2-AB2-BA2-2A15-2A2(2-BA)2BA18-4A2-2A2-2B2A12-4A2-2B-BA2-3A-A17-2A-2B2-BA2-B2A18-BA-AB3-2A2-BA18-AB2-AB3-2A22-A3-2B3-3A2-2A16-2(A-)A2B3-B3-2A21-2AB26-AB3-2A26-BA2-A28-B269-2A30-ABA-A22-2A4-2B2A22-2B2A2-A3B3A20-4BA-A2B2-2A13-4A2-2B5-AB3-B12-A3B2A2-BA4-AB3-B12-A2(BA2-)BA4-AB-AB10-A2-2A3-BA-BA4-2(AB)A9-2A3-BA2-AB2-BA4-ABA9-A2BA2-AB3-2A-2A3-3A12-2B3-BA2-2A2-BA18-BA2-AB2-BA2-2A15-2A2(2-BA)2BA18-4A2-2A2-2B2A12-4A2-2B-BA2-3A-A13-A3B2A-2B2-BA2-B2A14-AB2-BA-AB3-2A2-BA14-2B2(2-AB)3-2A17-B2A2-AB2-2B3-3A2-2A13-A2-ABA-A2B3-B3-2A14-A4B2-2AB26-AB3-2A26-BA2-A27-AB31-A211-A25-2A4-A25-ABA-A22-2A4-2B2A22-2B2A2-A3B3A20-4BA-A2B2-2A13-4A2-2B5-AB3-B12-A3B2A2-BA4-AB3-B12-A2(BA2-)BA4-AB-AB10-A2-2A3-BA-BA4-2(AB)A9-2A3-BA2-AB2-BA4-ABA9-A2BA2-AB3-2A-2A3-3A12-2B3-BA2-2A2-BA18-BA2-AB2-BA2-2A15-2A2(2-BA)2BA18-4A2-2A2-2B2A12-4A2-2B-BA2-3A-A13-A3B2A-2B2-BA2-B2A14-AB2-BA-AB3-2A2-BA14-2B2(2-AB)3-2A17-B2A2-AB2-2B3-3A2-2A12-BA2-ABA-A2B3-B3-2A12-ABA4B2-2AB21-ABA2-AB3-2A21-2A3-BA2-A23-BA2-AB27-BA-BA28-3B29-2B53-B30-AB30-2B30-BA25-2A3-BA25-ABA-AB21-2A4-2B2AB21-2B2A2-A3B3A20-4BA-A2B2-2A13-4A2-2B5-AB3-B12-A3B2A2-BA4-AB3-B12-A2(BA2-)BA4-AB-AB10-A2-2A3-BA-BA4-2(AB)A9-2A3-BA2-AB2-BA4-ABA9-A2BA2-AB3-2A-2A3-3A12-2B3-BA2-2A2-BA18-BA2-AB2-BA2-2A15-2A2(2-BA)2BA18-4A2-2A2-2B2A12-4A2-2B-BA2-3A-A13-A3B2A-2B2-BA2-B2A14-AB2-BA-AB3-2A2-BA14-2B2(2-AB)3-2A17-B2A2-AB2-2B3-3A2-2A12-BA2-ABA-A2B3-B3-2A12-ABA4B2-2AB21-ABA2-AB3-2A21-2A3-BA2-A23-BA2-AB27-BA-BA28-3B29-2B53-B30-AB30-2B30-BA25-2A3-BA25-ABA-AB21-2A4-2B2AB21-2B2A2-A3B3A20-4BA-A2B2-2A13-4A2-2B5-AB3-B12-A3B2A2-BA4-AB3-B12-A2(BA2-)BA4-AB-AB10-A2-2A3-BA-BA4-2(AB)A9-2A3-BA2-AB2-BA4-ABA9-A2BA2-AB3-2A-2A3-3A12-2B3-BA2-2A2-BA18-BA2-AB2-BA2-2A15-2A2(2-BA)2BA18-4A2-2A2-2B2A12-4A2-2B-BA2-3A-A13-A3B2A-2B2-BA2-B2A14-AB2-BA-AB3-2A2-BA14-2B2(2-AB)3-2A17-B2A2-AB2-2B3-3A2-2A12-BA2-ABA-A2B3-B3-2A12-ABA4B2-2AB21-ABA2-AB3-2A21-2A3-BA2-A23-BA2-AB27-BA-BA28-3B29-2B53-B30-AB30-2B30-BA25-2A3-BA25-ABA-AB21-2A4-2B2AB21-2B2A2-A3B3A20-4BA-A2B2-2A13-4A2-2B5-AB3-B12-A3B2A2-BA4-AB3-B12-A2(BA2-)BA4-AB-AB10-A2-2A3-BA-BA4-2(AB)A9-2A3-BA2-AB2-BA4-ABA9-A2BA2-AB3-2A-2A3-3A12-2B3-BA2-2A2-BA18-BA2-AB2-BA2-2A15-2A2(2-BA)2BA18-4A2-2A2-2B2A12-4A2-2B-BA2-3A-A13-A3B2A-2B2-BA2-B2A14-AB2-BA-AB3-2A2-BA14-2B2(2-AB)3-2A17-B2A2-AB2-2B3-3A2-2A12-BA2-ABA-A2B3-B3-2A12-ABA4B2-2AB21-ABA2-AB3-2A21-2A3-BA2-A23-BA2-AB27-BA-BA28-3B29-2B53-B30-AB30-2B30-BA25-2A3-BA25-ABA-AB21-2A4-2B2AB21-2B2A2-A3B3A20-4BA-A2B2-2A13-4A2-2B5-AB3-B12-A3B2A2-BA4-AB3-B12-A2(BA2-)BA4-AB-AB10-A2-2A3-BA-BA4-2(AB)A9-2A3-BA2-AB2-BA4-ABA9-A2BA2-AB3-2A-2A3-3A12-2B3-BA2-2A2-BA18-BA2-AB2-BA2-2A15-2A2(2-BA)2BA18-4A2-2A2-2B2A12-4A2-2B-BA2-3A-A13-A3B2A-2B2-BA2-B2A14-AB2-BA-AB3-2A2-BA14-2B2(2-AB)3-2A17-B2A2-AB2-2B3-3A2-2A12-BA2-ABA-A2B3-B3-2A12-ABA4B2-2AB21-ABA2-AB3-2A21-2A3-BA2-A23-BA2-AB27-BA-BA28-3B29-2B53-B30-AB30-2B30-BA25-2A3-BA25-ABA-AB21-2A4-2B2AB21-2B2A2-A3B3A20-4BA-A2B2-2A13-4A2-2B5-AB3-B12-A3B2A2-BA4-AB3-B12-A2(BA2-)BA4-AB-AB10-A2-2A3-BA-BA4-2(AB)A9-2A3-BA2-AB2-BA4-ABA9-A2BA2-AB3-2A-2A3-3A12-2B3-BA2-2A2-BA18-BA2-AB2-BA2-2A15-2A2(2-BA)2BA18-4A2-2A2-2B2A12-4A2-2B-BA2-3A-A13-A3B2A-2B2-BA2-B2A14-AB2-BA-AB3-2A2-BA14-2B2(2-AB)3-2A17-B2A2-AB2-2B3-3A2-2A12-BA2-ABA-A2B3-B3-2A12-ABA4B2-2AB21-ABA2-AB3-2A21-2A3-BA2-A23-BA2-AB27-BA-BA28-3B29-2B53-B30-AB30-2B30-BA25-2A3-BA25-ABA-AB21-2A4-2B2AB21-2B2A2-A3B3A20-4BA-A2B2-2A13-4A2-2B5-AB3-B12-A3B2A2-BA4-AB3-B12-A2(BA2-)BA4-AB-AB10-A2-2A3-BA-BA4-2(AB)A9-2A3-BA2-AB2-BA4-ABA9-A2BA2-AB3-2A-2A3-3A12-2B3-BA2-2A2-BA18-BA2-AB2-BA2-2A15-2A2(2-BA)2BA18-4A2-2A2-2B2A12-4A2-2B-BA2-3A-A13-A3B2A-2B2-BA2-B2A14-AB2-BA-AB3-2A2-BA14-2B2(2-AB)3-2A17-B2A2-AB2-2B3-3A2-2A12-BA2-ABA-A2B3-B3-2A12-ABA4B2-2AB21-ABA2-AB3-2A21-2A3-BA2-A23-BA2-AB27-BA-BA28-3B29-2B53-B30-AB30-2B30-BA25-2A3-BA25-ABA-AB21-2A4-2B2AB21-2B2A2-A3B3A20-4BA-A2B2-2A13-4A2-2B5-AB3-B12-A3B2A2-BA4-AB3-B12-A2(BA2-)BA4-AB-AB10-A2-2A3-BA-BA4-2(AB)A9-2A3-BA2-AB2-BA4-ABA9-A2BA2-AB3-2A-2A3-3A12-2B3-BA2-2A2-BA18-BA2-AB2-BA2-2A15-2A2(2-BA)2BA18-4A2-2A2-2B2A12-4A2-2B-BA2-3A-A13-A3B2A-2B2-BA2-B2A14-AB2-BA-AB3-2A2-BA14-2B2(2-AB)3-2A17-B2A2-AB2-2B3-3A2-2A12-BA2-ABA-A2B3-B3-2A12-ABA4B2-2AB21-ABA2-AB3-2A21-2A3-BA2-A23-BA2-AB27-BA-BA28-3B29-2B53-B30-AB30-2B30-BA25-2A3-BA25-ABA-AB21-2A4-2B2AB21-2B2A2-A3B3A20-4BA-A2B2-2A13-4A2-2B5-AB3-B12-A3B2A2-BA4-AB3-B12-A2(BA2-)BA4-AB-AB10-A2-2A3-BA-BA4-2(AB)A9-2A3-BA2-AB2-BA4-ABA9-A2BA2-AB3-2A-2A3-3A12-2B3-BA2-2A2-BA18-BA2-AB2-BA2-2A15-2A2(2-BA)2BA18-4A2-2A2-2B2A12-4A2-2B-BA2-3A-A13-A3B2A-2B2-BA2-B2A14-AB2-BA-AB3-2A2-BA14-2B2(2-AB)3-2A17-B2A2-AB2-2B3-3A2-2A12-BA2-ABA-A2B3-B3-2A12-ABA4B2-2AB21-ABA2-AB3-2A21-2A3-BA2-A23-BA2-AB27-BA-BA28-3B29-2B53-B30-AB30-2B30-BA25-2A3-BA25-ABA-AB21-2A4-2B2AB21-2B2A2-A3B3A20-4BA-A2B2-2A13-4A2-2B5-AB3-B12-A3B2A2-BA4-AB3-B12-A2(BA2-)BA4-AB-AB10-A2-2A3-BA-BA4-2(AB)A9-2A3-BA2-AB2-BA4-ABA9-A2BA2-AB3-2A-2A3-3A12-2B3-BA2-2A2-BA18-BA2-AB2-BA2-2A15-2A2(2-BA)2BA18-4A2-2A2-2B2A12-4A2-2B-BA2-3A-A13-A3B2A-2B2-BA2-B2A14-AB2-BA-AB3-2A2-BA14-2B2(2-AB)3-2A17-B2A2-AB2-2B3-3A2-2A12-BA2-ABA-A2B3-B3-2A12-ABA4B2-2AB21-ABA2-AB3-2A21-2A3-BA2-A23-BA2-AB27-BA-BA28-3B29-2B24-
