model
size = 32 32 19, scale = 0.05, origin = -y
material 
  colors = A:#081818 B:#080818
voxels
69-A30-ABA28-B2AB27-BA2-B2A29-3B28-ABA2-A26-B3-A2B27-A2B29-2B3-2(BA29-)2A2-BA26-A2-2A29-2A3-A26-A2-A2BA27-2BA29-A5-B29-ABA27-3BA2-B30-3B27-2BA-BA26-2A2-B31-A2-2B28-A3B27-A2BA28-2BA30-B2A30-5BA28-2A3B2(31-A)69-A30-ABA28-B2AB27-BA2-B2A29-3B28-ABA2-A26-B3-A2B27-A2B29-2B3-2(BA29-)2A2-BA26-A2-2A29-2A3-A26-A2-A2BA27-2BA29-A5-B29-ABA27-3BA2-B30-3B27-2BA-BA26-2A2-B31-A2-2B28-A3B27-A2BA28-2BA30-B2A30-5BA28-2A3B2(31-A)38-ABA28-AB2A27-ABA28-B2AB2-ABA22-BA2-2(B2A)20-2BA3-3B23-2B3-ABA2-A2BA19-2BA2B3-A3B2A19-ABA2-A2B3-2A23-A2B3-BA2-2B20-AB3-BA2-2BA19-AB3-2A2-BA25-2A2-2A4-AB19-2A2-2A3-AB2AB18-A2-BA2-A2BA2-BA19-B2A-2BA4-2A19-2A-BA5-BA22-A2B3-ABA3-BA19-A2B2ABA2-3BA19-B4A3-3BA26-2BA-BA24-AB2A2-B24-B2A4-A2-2A28-A2BA27-A2BA26-2A2BA26-A4B2A29-A5BA25-A2-2A3B23-2A6-A31-A38-ABA28-AB2A27-ABA28-B2AB2-ABA22-BA2-2(B2A)20-2BA3-3B23-2B3-ABA2-A2BA19-2BA2B3-A3B2A19-ABA2-A2B3-2A23-A2B3-BA2-2B20-AB3-BA2-2BA19-AB3-2A2-BA25-2A2-2A4-AB19-2A2-2A3-AB2AB18-A2-BA2-A2BA2-BA19-B2A-2BA4-2A19-2A-BA5-BA22-A2B3-ABA3-BA19-A2B2ABA2-3BA19-B4A3-3BA26-2BA-BA24-AB2A2-B24-B2A4-A2-2A28-A2BA27-A2BA26-2A2BA26-A4B2A29-A5BA25-A2-2A3B23-2A6-A31-A8-2B2A26-ABA3BA24-AB2A2-BA23-ABA4-BA22-B2AB2-AB2A21-BA2-2(B2A)20-2BA3-3B23-2B3-ABA2-A2BA19-2BA2B3-A3B2A2-A16-ABA2-A2B3-2A2-BA19-A2B3-BA2-2B2A18-AB3-BA2-2BA18-2AB3-2A2-BA4-2A15-A3-2A2-2A4-A2BA17-2A2-2A3-AB2ABA16-2(BA2-)A2BA2-BA17-A-B2A-2BA4-2A19-2A-BA5-BA18-2A2-A2B3-ABA3-BA14-2A3-A2B2ABA2-3BA19-5A3-3BA26-2BA-BA24-AB2A2-B23-AB2A4-A2-2A19-2A7-A2BA27-A2BA26-2A2BA23-A-2A4B2A22-2A2B3-A5BA19-BA4-A2-2A3B19-BA2-2A6-A20-3BA7-A8-2B2A26-ABA3BA24-AB2A2-BA23-ABA4-BA22-B2AB2-AB2A21-BA2-2(B2A)20-2BA3-3B23-2B3-ABA2-A2BA19-2BA2B3-A3B2A2-A16-ABA2-A2B3-2A2-BA19-A2B3-BA2-2B2A18-AB3-BA2-2BA18-2AB3-2A2-BA4-2A15-A3-2A2-2A4-A2BA17-2A2-2A3-AB2ABA16-2(BA2-)A2BA2-BA17-A-B2A-2BA4-2A19-2A-BA5-BA18-2A2-A2B3-ABA3-BA14-2A3-A2B2ABA2-3BA19-5A3-3BA26-2BA-BA24-AB2A2-B23-AB2A4-A2-2A19-2A7-A2BA27-A2BA26-2A2BA23-A-2A4B2A22-2A2B3-A5BA19-BA4-A2-2A3B19-BA2-2A6-A20-3BA7-A8-2B2A26-ABA3BA24-AB2A2-BA23-ABA4-BA22-B2AB2-AB2A21-BA2-2(B2A)20-2BA3-3B23-2B3-ABA2-A2BA19-2BA2B3-A3B2A2-A16-ABA2-A2B3-2A2-BA19-A2B3-BA2-2B2A18-AB3-BA2-2BA18-2AB3-2A2-BA4-2A15-A3-2A2-2A4-A2BA17-2A2-2A3-AB2ABA16-2(BA2-)A2BA2-BA17-A-B2A-2BA4-2A19-2A-BA5-BA18-2A2-A2B3-ABA3-BA14-2A3-A2B2ABA2-3BA19-5A3-3BA26-2BA-BA24-AB2A2-B23-AB2A4-A2-2A19-2A7-A2BA27-A2BA26-2A2BA23-A-2A4B2A22-2A2B3-A5BA18-ABA4-A2-2A3B18-ABA2-2A6-A19-A3BA7-A8-2B2A26-ABA3BA24-AB2A2-BA23-ABA4-BA22-B2AB2-AB2A21-BA2-2(B2A)20-2BA3-3B23-2B3-ABA2-A2BA19-2BA2B3-A3B2A2-A16-ABA2-A2B3-2A2-BA19-A2B3-BA2-2B2A18-AB3-BA2-2BA18-2AB3-2A2-BA4-2A15-A3-2A2-2A4-A2BA17-2A2-2A3-AB2ABA16-2(BA2-)A2BA2-BA17-A-B2A-2BA4-2A19-2A-BA5-BA18-2A2-A2B3-ABA3-BA14-2A3-A2B2ABA2-3BA19-5A3-3BA26-2BA-BA24-AB2A2-B23-AB2A4-A2-2A19-2A7-A2BA27-A2BA26-2A2BA23-A-2A4B2A22-2A2B3-A5BA18-ABA4-A2-2A3B18-ABA2-2A6-A19-A3BA7-A8-2B2A26-ABA3BA24-AB2A2-BA23-ABA4-BA22-B2AB2-AB2A21-BA2-2(B2A)20-2BA3-3B23-2B3-ABA2-A2BA19-2BA2B3-A3B2A2-A16-ABA2-A2B3-2A2-BA19-A2B3-BA2-2B2A18-AB3-BA2-2BA18-2AB3-2A2-BA4-2A15-A3-2A2-2A4-A2BA17-2A2-2A3-AB2ABA16-2(BA2-)A2BA2-BA17-A-B2A-2BA4-2A19-2A-BA5-BA18-2A2-A2B3-ABA3-BA14-2A3-A2B2ABA2-3BA19-5A3-3BA26-2BA-BA24-AB2A2-B23-AB2A4-A2-2A19-2A7-A2BA27-A2BA26-2A2BA23-A-2A4B2A22-2A2B3-A5BA18-ABA4-A2-2A3B18-ABA2-2A6-A19-A3BA7-A8-2B2A26-ABA3BA24-AB2A2-BA23-ABA4-BA22-B2AB2-AB2A21-BA2-2(B2A)20-2BA3-3B23-2B3-ABA2-A2BA19-2BA2B3-A3B2A2-A16-ABA2-A2B3-2A2-BA19-A2B3-BA2-2B2A18-AB3-BA2-2BA18-2AB3-2A2-BA4-2A15-A3-2A2-2A4-A2BA17-2A2-2A3-AB2ABA16-2(BA2-)A2BA2-BA17-A-B2A-2BA4-2A19-2A-BA5-BA18-2A2-A2B3-ABA3-BA14-2A3-A2B2ABA2-3BA19-5A3-3BA26-2BA-BA24-AB2A2-B23-AB2A4-A2-2A19-2A7-A2BA27-A2BA26-2A2BA23-A-2A4B2A22-2A2B3-A5BA18-ABA4-A2-2A3B18-ABA2-2A6-A19-A3BA7-A8-2B2A26-ABA3BA24-AB2A2-BA23-ABA4-BA22-B2AB2-AB2A21-BA2-2(B2A)20-2BA3-3B23-2B3-ABA2-A2BA19-2BA2B3-A3B2A2-A16-ABA2-A2B3-2A2-BA19-A2B3-BA2-2B2A18-AB3-BA2-2BA18-2AB3-2A2-BA4-2A15-A3-2A2-2A4-A2BA17-2A2-2A3-AB2ABA16-2(BA2-)A2BA2-BA17-A-B2A-2BA4-2A19-2A-BA5-BA18-2A2-A2B3-ABA3-BA14-2A3-A2B2ABA2-3BA19-5A3-3BA26-2BA-BA24-AB2A2-B23-AB2A4-A2-2A19-2A7-A2BA27-A2BA26-2A2BA23-A-2A4B2A22-2A2B3-A5BA18-ABA4-A2-2A3B18-ABA2-2A6-A19-A3BA7-A8-2B2A26-ABA3BA24-AB2A2-BA23-ABA4-BA22-B2AB2-AB2A21-BA2-2(B2A)20-2BA3-3B23-2B3-ABA2-A2BA19-2BA2B3-A3B2A2-A16-ABA2-A2B3-2A2-BA19-A2B3-BA2-2B2A18-AB3-BA2-2BA18-2AB3-2A2-BA4-2A15-A3-2A2-2A4-A2BA17-2A2-2A3-AB2ABA16-2(BA2-)A2BA2-BA17-A-B2A-2BA4-2A19-2A-BA5-BA18-2A2-A2B3-ABA3-BA14-2A3-A2B2ABA2-3BA19-5A3-3BA26-2BA-BA24-AB2A2-B23-AB2A4-A2-2A19-2A7-A2BA27-A2BA26-2A2BA23-A-2A4B2A22-2A2B3-A5BA18-ABA4-A2-2A3B18-ABA2-2A6-A19-A3BA7-A8-2B2A26-ABA3BA24-AB2A2-BA23-ABA4-BA22-B2AB2-AB2A21-BA2-2(B2A)20-2BA3-3B23-2B3-ABA2-A2BA19-2BA2B3-A3B2A2-A16-ABA2-A2B3-2A2-BA19-A2B3-BA2-2B2A18-AB3-BA2-2BA18-2AB3-2A2-BA4-2A15-A3-2A2-2A4-A2BA17-2A2-2A3-AB2ABA16-2(BA2-)A2BA2-BA17-A-B2A-2BA4-2A19-2A-BA5-BA18-2A2-A2B3-ABA3-BA14-2A3-A2B2ABA2-3BA19-5A3-3BA26-2BA-BA24-AB2A2-B23-AB2A4-A2-2A19-2A7-A2BA27-A2BA26-2A2BA23-A-2A4B2A22-2A2B3-A5BA18-ABA4-A2-2A3B18-ABA2-2A6-A19-A3BA7-A8-2B2A26-ABA3BA24-AB2A2-BA23-ABA4-BA22-B2AB2-AB2A21-BA2-2(B2A)20-2BA3-3B23-2B3-ABA2-A2BA19-2BA2B3-A3B2A2-A16-ABA2-A2B3-2A2-BA19-A2B3-BA2-2B2A18-AB3-BA2-2BA18-2AB3-2A2-BA4-2A15-A3-2A2-2A4-A2BA17-2A2-2A3-AB2ABA16-2(BA2-)A2BA2-BA17-A-B2A-2BA4-2A19-2A-BA5-BA18-2A2-A2B3-ABA3-BA14-2A3-A2B2ABA2-3BA19-5A3-3BA26-2BA-BA24-AB2A2-B23-AB2A4-A2-2A19-2A7-A2BA27-A2BA26-2A2BA23-A-2A4B2A22-2A2B3-A5BA18-ABA4-A2-2A3B18-ABA2-2A6-A19-A3BA7-A8-2B2A26-ABA3BA24-AB2A2-BA23-ABA4-BA22-B2AB2-AB2A21-BA2-2(B2A)20-2BA3-3B23-2B3-ABA2-A2BA19-2BA2B3-A3B2A2-A16-ABA2-A2B3-2A2-BA19-A2B3-BA2-2B2A18-AB3-BA2-2BA18-2AB3-2A2-BA4-2A15-A3-2A2-2A4-A2BA17-2A2-2A3-AB2ABA16-2(BA2-)A2BA2-BA17-A-B2A-2BA4-2A19-2A-BA5-BA18-2A2-A2B3-ABA3-BA14-2A3-A2B2ABA2-3BA19-5A3-3BA26-2BA-BA24-AB2A2-B23-AB2A4-A2-2A19-2A7-A2BA27-A2BA26-2A2BA23-A-2A4B2A22-2A2B3-A5BA18-ABA4-A2-2A3B18-ABA2-2A6-A19-A3BA7-A8-2B2A26-ABA3BA24-AB2A2-BA23-ABA4-BA22-B2AB2-AB2A21-BA2-2(B2A)20-2BA3-3B23-2B3-ABA2-A2BA19-2BA2B3-A3B2A2-A16-ABA2-A2B3-2A2-BA19-A2B3-BA2-2B2A18-AB3-BA2-2BA18-2AB3-2A2-BA4-2A15-A3-2A2-2A4-A2BA17-2A2-2A3-AB2ABA16-2(BA2-)A2BA2-BA17-A-B2A-2BA4-2A19-2A-BA5-BA18-2A2-A2B3-ABA3-BA14-2A3-A2B2ABA2-3BA19-5A3-3BA26-2BA-BA24-AB2A2-B23-AB2A4-A2-2A19-2A7-A2BA27-A2BA26-2A2BA23-A-2A4B2A22-2A2B3-A5BA18-ABA4-A2-2A3B18-ABA2-2A6-A19-A3BA7-A8-2B2A26-ABA3BA24-AB2A2-BA23-ABA4-BA22-B2AB2-AB2A21-BA2-2(B2A)20-2BA3-3B23-2B3-ABA2-A2BA19-2BA2B3-A3B2A2-A16-ABA2-A2B3-2A2-BA19-A2B3-BA2-2B2A18-AB3-BA2-2BA18-2AB3-2A2-BA4-2A15-A3-2A2-2A4-A2BA17-2A2-2A3-AB2ABA16-2(BA2-)A2BA2-BA17-A-B2A-2BA4-2A19-2A-BA5-BA18-2A2-A2B3-ABA3-BA14-2A3-A2B2ABA2-3BA19-5A3-3BA26-2BA-BA24-AB2A2-B23-AB2A4-A2-2A19-2A7-A2BA27-A2BA26-2A2BA23-A-2A4B2A22-2A2B3-A5BA18-ABA4-A2-2A3B18-ABA2-2A6-A19-A3BA7-A8-2B2A26-ABA3BA24-AB2A2-BA23-ABA4-BA22-B2AB2-AB2A21-BA2-2(B2A)20-2BA3-3B23-2B3-ABA2-A2BA19-2BA2B3-A3B2A2-A16-ABA2-A2B3-2A2-BA19-A2B3-BA2-2B2A18-AB3-BA2-2BA18-2AB3-2A2-BA4-2A15-A3-2A2-2A4-A2BA17-2A2-2A3-AB2ABA16-2(BA2-)A2BA2-BA17-A-B2A-2BA4-2A19-2A-BA5-BA18-2A2-A2B3-ABA3-BA14-2A3-A2B2ABA2-3BA19-5A3-3BA26-2BA-BA24-AB2A2-B23-AB2A4-A2-2A19-2A7-A2BA27-A2BA26-2A2BA23-A-2A4B2A22-2A2B3-A5BA18-ABA4-A2-2A3B18-ABA2-2A6-A19-A3BA7-A8-2B2A26-ABA3BA24-AB2A2-BA23-ABA4-BA22-B2AB2-AB2A21-BA2-2(B2A)20-2BA3-3B23-2B3-ABA2-A2BA19-2BA2B3-A3B2A2-A16-ABA2-A2B3-2A2-BA19-A2B3-BA2-2B2A18-AB3-BA2-2BA18-2AB3-2A2-BA4-2A15-A3-2A2-2A4-A2BA17-2A2-2A3-AB2ABA16-2(BA2-)A2BA2-BA17-A-B2A-2BA4-2A19-2A-BA5-BA18-2A2-A2B3-ABA3-BA14-2A3-A2B2ABA2-3BA19-5A3-3BA26-2BA-BA24-AB2A2-B23-AB2A4-A2-2A19-2A7-A2BA27-A2BA26-2A2BA23-A-2A4B2A22-2A2B3-A5BA18-ABA4-A2-2A3B18-ABA2-2A6-A19-A3BA7-A
