model
size = 30 31 24, scale = 0.05, origin = -y
material 
  colors = A:#2A4A5B B:#E57600 C:#FAB700 D:#46647C
voxels
------------------------------ ------------------------------ ------------------------------ ------------------------------ ------------------------------ ------------------------------ ------------------------------ ------------------------------ ------------------------------ ------------------------------ ------------------------------ ----BBBBBBBBBBC-BBBBBBBBBC---- ----BBBBBBBBBBC-BBBBBBBBBC---- ----CCCCCCCCCC--CCCCCCCCCC---- ------------------------------ ----BBC-BBC-BBC-BBC----------- ----BBC-BBC-BBC-BBC----------- ----BBC-BBC-BBC-BBC----------- ----BBC-BBC-BBC-BBC----------- ----BBC-BBC-BBC-BBC----------- ----BBC-BBC-BBC-BBC----------- ----CC--CC--CC--CC------------ ------------------------------ ------------------------------ ------------------------------ ------------------------------ ------------------------------ ------------------------------ ------------------------------ ------------------------------ ------------------------------ 
------------------------------ ------------------------------ ------------------------------ ------------------------------ ------------------------------ ------------------------------ ------------------------------ ------------------------------ ------------------------------ ------------------------------ ------------------------------ ----BBBBBBBBBBC-BBBBBBBBBC---- ----BBBBBBBBBBC-BBBBBBBBBC---- ----CCCCCCCCCCAACCCCCCCCCC---- -------------AAAA------------- ----BBC-BBC-BBCABBC----------- ----BBC-BBC-BBCABBC----------- ----BBC-BBC-BBCABBC----------- ----BBC-BBC-BBCABBC----------- ----BBC-BBC-BBCABBC----------- ----BBC-BBC-BBCABBC----------- ----CC--CC--CCAACC------------ -------------AAAA------------- ------------------------------ ------------------------------ ------------------------------ ------------------------------ ------------------------------ ------------------------------ ------------------------------ ------------------------------ 
------------------------------ ------------------------------ ------------------------------ ------------------------------ ------------------------------ ------------------------------ ------------------------------ ------------------------------ -------------AAAA------------- -------------AAAA------------- -------------AAAA------------- ----BBBBBBBBBBCABBBBBBBBBC---- ----BBBBBBBBBBCABBBBBBBBBC---- ----CCCCCCCCC----CCCCCCCCC---- ----------AAA----AAA---------- ----BBC-BBCAB----BCA---------- ----BBC-BBCAB----BCA---------- ----BBC-BBCAB----BCA---------- ----BBC-BBCAB----BCA---------- ----BBC-BBCAB----BCA---------- ----BBC-BBCAB----BCA---------- ----CC--CCAAC----CAA---------- ----------AAA----AAA---------- -------------AAAA------------- -------------AAAA------------- -------------AAAA------------- ------------------------------ ------------------------------ ------------------------------ ------------------------------ ------------------------------ 
--------------AA-------------- -------------AAAA------------- -------------AAAA------------- -------------AAAA------------- -------------AAAA------------- -------------AAAA------------- -------------AAAA------------- -------------AAAA------------- ----------AAA----AAA---------- ----------AAA----AAA---------- ----------AAA----AAA---------- ----BBBBBB----------BBBBBC---- ----BBBBBB----------BBBBBC---- ----CCCCCC----------CCCCCC---- --------AA----------AA-------- ----BBC-BB----------AA-------- ----BBC-BB----------AA-------- ----BBC-BB----------AA-------- ----BBC-BB----------AA-------- ----BBC-BB----------AA-------- ----BBC-BB----------AA-------- ----CC--CC----------AA-------- --------AA----------AA-------- ----------AAA----AAA---------- ----------AAA----AAA---------- ----------AAA----AAA---------- -------------AAAA------------- -------------AAAA------------- -------------AAAA------------- -------------AAAA------------- -------------AAAA------------- 
--------------AA-------------- ------------AAAAAA------------ ----------AAAAAAAAAA---------- ----------AAAA--AAAA---------- ----------AAA----AAA---------- ----------AAA----AAA---------- ----------AAA----AAA---------- ----------AAA----AAA---------- --------AA----------AA-------- --------AA----------AA-------- --------AA----------AA-------- ----BBBB--------------BBBC---- ----BBBB--------------BBBC---- ----ACCC--------------CCCC---- ----AAAA--------------AAAA---- ----ABCABB------------AAAA---- ----ABCABB------------AAAA---- ----ABCABB------------AAAA---- ----ABCABB------------AAAA---- ----ABCABB------------AAAA---- ----ABCABB------------AAAA---- ----ACAACC------------AAAA---- ----AAAA--------------AAAA---- --------AA----------AA-------- --------AA----------AA-------- --------AA----------AA-------- ----------AAA----AAA---------- ----------AAAA--AAAA---------- ----------AAAAAAAAAA---------- ----------AAAAAAAAAA---------- ------------AAAAAA------------ 
------------------------------ ------------A----A------------ ----------AAA----AAA---------- --------AAAAA----AAAAA-------- --------AAAA------AAAA-------- --------AA----------AA-------- --------AA----------AA-------- --------AA----------AA-------- ----AAAA--------------AAAA---- ----AAAA--------------AAAA---- ----AAAA--------------AAAA---- ----B--------------------C---- ----B--------------------C---- -AAAA---------------------AAA- -AAA----------------------AAA- -AAA----------------------AAA- -AAA----------------------AAA- AAAA----------------------AAAA AAAA----------------------AAAA AAAA----------------------AAAA AAAA----------------------AAAA AAAA----------------------AAAA AAAA----------------------AAAA ----AAAA--------------AAAA---- ----AAAA--------------AAAA---- ----AAAAAA----------AAAAAA---- --------AAAA------AAAA-------- --------AAAAA----AAAAA-------- --------AAAAA----AAAAA-------- ----------AAA----AAA---------- ------------A----A------------ 
------------------------------ ------------------------------ ------------------------------ --------AA----------AA-------- ------AAAA----------AAAA------ ----AAAAAA----------AAAAAA---- ----AAAA--------------AAAA---- ----AAAA--------------AAAA---- ---AAA------------------AAA--- --AAAA------------------AAAA-- --AAA---------------------AA-- --AAA---------------------AA-- --AAA---------------------AA-- -AAA----------------------AAA- -AAA----------------------AAA- -AAA----------------------AAA- -AAA----------------------AAA- AAAA----------------------AAAA AAA------------------------AAA AAA------------------------AAA AAA------------------------AAA AAA------------------------AAA AAAA----------------------AAAA AAAAAA------------------AAAAAA AAAAAAAA--------------AAAAAAAA --AAAAAA--------------AAAAAA-- ----AAAAAA----------AAAAAA---- ------AAAA----------AAAA------ --------AA----------AA-------- ------------------------------ ------------------------------ 
------------------------------ ------------------------------ ------------------------------ ------------------------------ ------AA--------------AA------ ----AAAA--------------AAAA---- ---AAAAA--------------AAAAA--- ---AAA------------------AAA--- ---A----------------------A--- --AA----------------------AA-- --AA----------------------AA-- --AA----------------------AA-- --AA----------------------AA-- --AA----------------------AA-- --AA----------------------AA-- --AA----------------------AA-- --AA----------------------AA-- -AA------------------------AA- -AA------------------------AA- -AA------------------------AA- -AA------------------------AA- -AA------------------------AA- -AA------------------------AA- AAAA----------------------AAAA AAAA----------------------AAAA --AA----------------------AA-- ----AAAA--------------AAAA---- ------AA--------------AA------ ------------------------------ ------------------------------ ------------------------------ 
------------------------------ ------------------------------ ------------------------------ ------------------------------ ------------------------------ ------------------------------ ---A----------------------A--- ---A----------------------A--- ---A----------------------A--- --AA----------------------AA-- --AA----------------------AA-- --AA----------------------AA-- --AA----------------------AA-- --AA----------------------AA-- --AA----------------------AA-- --AA----------------------AA-- --AA----------------------AA-- -AA------------------------AA- -AA------------------------AA- -AA------------------------AA- -AA------------------------AA- -AA------------------------AA- -AA------------------------AA- AAA------------------------AAA AAA------------------------AAA ------------------------------ ------------------------------ ------------------------------ ------------------------------ ------------------------------ ------------------------------ 
------------------------------ ------------------------------ ------------------------------ ------------------------------ ------------------------------ ------------------------------ ---A----------------------A--- ---A----------------------A--- ---A----------------------A--- --AA----------------------AA-- --AA----------------------AA-- --AA----------------------AA-- --AA----------------------AA-- --AA----------------------AA-- --AA----------------------AA-- --AA----------------------AA-- --AA----------------------AA-- -AA------------------------AA- -AA------------------------AA- -AA------------------------AA- -AA------------------------AA- -AA------------------------AA- -AA------------------------AA- AAA------------------------AAA AAA------------------------AAA ------------------------------ ------------------------------ ------------------------------ ------------------------------ ------------------------------ ------------------------------ 
------------------------------ ------------------------------ ------------------------------ ------------------------------ ------------------------------ ------------------------------ ---A----------------------A--- ---A----------------------A--- ---A----------------------A--- --AA----------------------AA-- --AA----------------------AA-- --AA----------------------AA-- --AA----------------------AA-- --AA----------------------AA-- --AA----------------------AA-- --AA----------------------AA-- --AA----------------------AA-- -AA------------------------AA- -AA------------------------AA- -AA------------------------AA- -AA------------------------AA- -AA------------------------AA- -AA------------------------AA- AAA------------------------AAA AAA------------------------AAA ------------------------------ ------------------------------ ------------------------------ ------------------------------ ------------------------------ ------------------------------ 
------------------------------ ------------------------------ ------------------------------ ------------------------------ ------------------------------ ------------------------------ ---A----------------------A--- ---A----------------------A--- ---A----------------------A--- --AA----------------------AA-- --AA----------------------AA-- --AA----------------------AA-- --AA----------------------AA-- --AA----------------------AA-- --AA----------------------AA-- --AA----------------------AA-- --AA----------------------AA-- -AA------------------------AA- -AA------------------------AA- -AA------------------------AA- -AA------------------------AA- -AA------------------------AA- -AA------------------------AA- AAA------------------------AAA AAA------------------------AAA ------------------------------ ------------------------------ ------------------------------ ------------------------------ ------------------------------ ------------------------------ 
------------------------------ ------------------------------ ------------------------------ ------------------------------ ------------------------------ ------------------------------ ------------------------------ ---A----------------------A--- ---A----------------------A--- --AA----------------------AA-- --AA----------------------AA-- --AA----------------------AA-- --AA----------------------AA-- --AA----------------------AA-- --AA----------------------AA-- --AA----------------------AA-- --AA----------------------AA-- -AA------------------------AA- -AA------------------------AA- -AA------------------------AA- -AA------------------------AA- -AA------------------------AA- -AA------------------------AA- AAA------------------------AAA AAA------------------------AAA ------------------------------ ------------------------------ ------------------------------ ------------------------------ ------------------------------ ------------------------------ 
------------------------------ ------------------------------ ------------------------------ ------------------------------ ------------------------------ ------------------------------ ------------------------------ ---A----------------------A--- ---A----------------------A--- --AA----------------------AA-- --AA----------------------AA-- --AA----------------------AA-- --AA----------------------AA-- --AA----------------------AA-- --AA----------------------AA-- --AA----------------------AA-- --AA----------------------AA-- -AA------------------------AA- -AA------------------------AA- -AA------------------------AA- -AA------------------------AA- -AA------------------------AA- -AA------------------------AA- AAA------------------------AAA AAA------------------------AAA ------------------------------ ------------------------------ ------------------------------ ------------------------------ ------------------------------ ------------------------------ 
------------------------------ ------------------------------ ------------------------------ ------------------------------ ------------------------------ ------------------------------ ------------------------------ ---A----------------------A--- ---A----------------------A--- --AA----------------------AA-- --AA----------------------AA-- --AA----------------------AA-- --AA----------------------AA-- --AA----------------------AA-- --AA----------------------AA-- --AA----------------------AA-- --AA----------------------AA-- -AA------------------------AA- -AA------------------------AA- -AA------------------------AA- -AA------------------------AA- -AA------------------------AA- -AA------------------------AA- AAA------------------------AAA AAA------------------------AAA ------------------------------ ------------------------------ ------------------------------ ------------------------------ ------------------------------ ------------------------------ 
------------------------------ ------------------------------ ------------------------------ ------------------------------ ------------------------------ ------------------------------ ------------------------------ ---A----------------------A--- ---A----------------------A--- --AA----------------------AA-- --AA----------------------AA-- --DA----------------------AD-- --DA----------------------AD-- --DA----------------------AD-- --DA----------------------AD-- --AA----------------------AA-- --AA----------------------AA-- -AA------------------------AA- -AA------------------------AA- -DA------------------------AD- -DA------------------------AD- -AA------------------------AA- -AA------------------------AA- AAA------------------------AAA AAA------------------------AAA ------------------------------ ------------------------------ ------------------------------ ------------------------------ ------------------------------ ------------------------------ 
------------------------------ ------------------------------ ------------------------------ ------------------------------ ------------------------------ ------------------------------ ------------------------------ ---A----------------------A--- ---A----------------------A--- --AA----------------------AA-- --DA----------------------AD-- ------------------------------ ------------------------------ ------------------------------ ------------------------------ --DA----------------------AD-- --AA----------------------AA-- -AA------------------------AA- -DA------------------------AD- ------------------------------ ------------------------------ -DA------------------------AD- -AA------------------------AA- AAA------------------------AAA AAA------------------------AAA ------------------------------ ------------------------------ ------------------------------ ------------------------------ ------------------------------ ------------------------------ 
------------------------------ ------------------------------ ------------------------------ ------------------------------ ------------------------------ ------------------------------ ------------------------------ ------------------------------ ---A----------------------A--- --DA----------------------AD-- ------------------------------ ------------------------------ ------------------------------ ------------------------------ ------------------------------ ------------------------------ --DA----------------------AD-- -DA------------------------AD- ------------------------------ ------------------------------ ------------------------------ ------------------------------ -DA------------------------AD- AAA------------------------AAA AAA------------------------AAA ------------------------------ ------------------------------ ------------------------------ ------------------------------ ------------------------------ ------------------------------ 
------------------------------ ------------------------------ ------------------------------ ------------------------------ ------------------------------ ------------------------------ ------------------------------ ------------------------------ ---A----------------------A--- --DA----------------------AD-- ------------------------------ ------------------------------ ------------------------------ ------------------------------ ------------------------------ ------------------------------ --DA----------------------AD-- -DA------------------------AD- ------------------------------ ------------------------------ ------------------------------ ------------------------------ -DA------------------------AD- AAA------------------------AAA AAA------------------------AAA ------------------------------ ------------------------------ ------------------------------ ------------------------------ ------------------------------ ------------------------------ 
------------------------------ ------------------------------ ------------------------------ ------------------------------ ------------------------------ ------------------------------ ------------------------------ ------------------------------ ---A----------------------A--- --DA----------------------AD-- ------------------------------ ------------------------------ ------------------------------ ------------------------------ ------------------------------ ------------------------------ --DA----------------------AD-- -DA------------------------AD- ------------------------------ ------------------------------ ------------------------------ ------------------------------ -DA------------------------AD- AAA------------------------AAA AAA------------------------AAA ------------------------------ ------------------------------ ------------------------------ ------------------------------ ------------------------------ ------------------------------ 
------------------------------ ------------------------------ ------------------------------ ------------------------------ ------------------------------ ------------------------------ ------------------------------ ------------------------------ ---A----------------------A--- --DA----------------------AD-- ------------------------------ ------------------------------ ------------------------------ ------------------------------ ------------------------------ ------------------------------ --DA----------------------AD-- -DA------------------------AD- ------------------------------ ------------------------------ ------------------------------ ------------------------------ -DA------------------------AD- AAA------------------------AAA AAA------------------------AAA ------------------------------ ------------------------------ ------------------------------ ------------------------------ ------------------------------ ------------------------------ 
------------------------------ ------------------------------ ------------------------------ ------------------------------ ------------------------------ ------------------------------ ------------------------------ ------------------------------ ------------------------------ --AA----------------------AA-- --DA----------------------AD-- ------------------------------ ------------------------------ ------------------------------ ------------------------------ --DA----------------------AD-- --AA----------------------AA-- -AA------------------------AA- -DA------------------------AD- ------------------------------ ------------------------------ -DA------------------------AD- -AA------------------------AA- ------------------------------ ------------------------------ ------------------------------ ------------------------------ ------------------------------ ------------------------------ ------------------------------ ------------------------------ 
------------------------------ ------------------------------ ------------------------------ ------------------------------ ------------------------------ ------------------------------ ------------------------------ ------------------------------ ------------------------------ ------------------------------ --AA----------------------AA-- --DA----------------------AD-- --DA----------------------AD-- --DA----------------------AD-- --DA----------------------AD-- --AA----------------------AA-- ------------------------------ ------------------------------ -AA------------------------AA- -DA------------------------AD- -DA------------------------AD- -AA------------------------AA- ------------------------------ ------------------------------ ------------------------------ ------------------------------ ------------------------------ ------------------------------ ------------------------------ ------------------------------ ------------------------------ 
------------------------------ ------------------------------ ------------------------------ ------------------------------ ------------------------------ ------------------------------ ------------------------------ ------------------------------ ------------------------------ ------------------------------ ------------------------------ ------------------------------ ------------------------------ ------------------------------ ------------------------------ ------------------------------ ------------------------------ ------------------------------ ------------------------------ -AA------------------------AA- -AA------------------------AA- ------------------------------ ------------------------------ ------------------------------ ------------------------------ ------------------------------ ------------------------------ ------------------------------ ------------------------------ ------------------------------ ------------------------------ 
