model
size = 5 27 28, scale = 0.05, origin = -y
material 
  colors = A:#EEE B:#111
voxels
----- BBBB- ----- ----- ----- ----- ----- ----- BBBBB BBBBB BBBBB BBBBB BBBBB BBBBB BBBBB BBBBB BBBBB BBBBB BBBBB BBBBB BBBBB BBBBB BBBBB BBBBB BBBBB ----- ----- 
BBBBB AAABB BBBBB ----- ----- ----- ----- BBBBB AAAAA AAAAA AAAAA AAAAA AAAAA AAAAA AAAAA AAAAA AAAAA AAAAA AAAAA AAAAA AAAAA AAAAA AAAAA AAAAA AAAAA BBBBB ----- 
BBBBB AAAAA AAAAA BBBBB ----- ----- BBBBB AAAAA AAAAA AAAAA AAAAA AAAAA AAAAA AAAAA AAAAA AAAAA AAAAA AAAAA AAAAA AAAAA AAAAA AAAAA AAAAA AAAAA AAAAA AAAAA BBBBB 
BBBBB AAAAA AAAAA AAAAA BBBBB ----- BBBBB AAAAA AAAAA BAAAA BAAAA AAAAA BAAAA BAAAA BAAAA BAAAA BAAAA AAAAA AAAAA AAAAB BAAAB BAAAB BAAAB BAAAB AAAAA AAAAA BBBBB 
----- BBBBB AAAAA AAAAA AAAAA BBBBB AAAAB AAAAA AAAAA BAAAA BAAAA AAAAA BAAAA BAAAA BAAAA BAAAA BAAAA AAAAA AAAAA BAAAA AAAAA AAAAB AAAAA AAAAB AAAAA AAAAA BBBBB 
----- ----- BBBBB AAAAA AAAAA AAAAA AAAAA AAAAA AAAAA AAAAA AAAAA AAAAA AAAAA AAAAA AAAAA AAAAA AAAAA AAAAA AAAAA AAAAA BAAAA AAAAA AAAAA AAAAA AAAAA AAAAA BBBBB 
----- ----- BBBBB BAAAA AAAAA AAAAA AAAAA AAAAA AAAAA BAAAA BAAAA AAAAA BAAAA BAAAA AAAAA BAAAA BAAAA AAAAA AAAAA BAAAB AAAAB AAAAB AAAAB AAAAB AAAAA AAAAA BBBBB 
----- ----- ----- BBBBB AAAAA AAAAA AAAAA AAAAA AAAAA BAAAB BAAAB AAAAB BAAAB BAAAB AAAAB BAAAB BAAAB AAAAA AAAAA AAAAB BAAAA BAAAA BAAAA BAAAB AAAAA AAAAA BBBBB 
----- ----- ----- ----- BBBBB AAAAA BAAAA AAAAA AAAAA BAAAB BAAAB BAAAB BAAAB BAAAB BAAAB BAAAB BAAAB AAAAA AAAAA AAAAB AAAAB AAAAB AAAAB AAAAB AAAAA AAAAA BBBBB 
----- ----- ----- ----- ----- BBBBB BAAAA AAAAA AAAAA BAAAA BAAAA BAAAA BAAAA BAAAA BAAAA BAAAB BAAAB AAAAA AAAAA BAAAA BAAAA BAAAA BAAAA BAAAA AAAAA AAAAA BBBBB 
----- ----- ----- ----- ----- ----- BBBBB AAAAA AAAAA AAAAA AAAAA AAAAA AAAAA AAAAA AAAAA AAAAB AAAAB AAAAA AAAAA BAAAB AAAAB AAAAB AAAAB BAAAB AAAAA AAAAA BBBBB 
----- ----- ----- ----- ----- ----- BBBBB AAAAA AAAAA BAAAA BAAAA BAAAA BAAAA BAAAB BAAAB BAAAA BAAAA AAAAA AAAAA BAAAB BAAAA BAAAA BAAAA BAAAA AAAAA AAAAA BBBBB 
----- ----- ----- ----- ----- ----- BBBBB AAAAA AAAAA BAAAA BAAAA BAAAA BAAAA BAAAB BAAAB BAAAA BAAAA AAAAA AAAAA AAAAA AAAAA AAAAA AAAAA AAAAA AAAAA AAAAA BBBBB 
----- ----- ----- ----- ----- ----- BBBBB AAAAA AAAAA AAAAA AAAAA AAAAA AAAAA AAAAA AAAAA BAAAB BAAAB AAAAA AAAAA BAAAB AAAAB AAAAB AAAAB AAAAB AAAAA AAAAA BBBBB 
----- ----- ----- ----- ----- ----- BBBBB AAAAA AAAAA AAAAA AAAAA AAAAA AAAAA AAAAA AAAAA BAAAB BAAAB AAAAA AAAAA BAAAB BAAAA BAAAA BAAAA BAAAA AAAAA AAAAA BBBBB 
----- ----- ----- ----- ----- ----- BBBBB AAAAA AAAAA AAAAB AAAAB AAAAB AAAAB BAAAB BAAAB AAAAB AAAAB AAAAA AAAAA AAAAA AAAAA AAAAA AAAAA AAAAA AAAAA AAAAA BBBBB 
----- ----- ----- ----- ----- ----- BBBBB AAAAA AAAAA AAAAB AAAAB AAAAB AAAAB BAAAB BAAAB AAAAB AAAAB AAAAA AAAAA BAAAB AAAAB AAAAB AAAAB AAAAB AAAAA AAAAA BBBBB 
----- ----- ----- ----- ----- ----- BBBBB AAAAA AAAAA AAAAA AAAAA AAAAA AAAAA AAAAA AAAAA BAAAA BAAAA AAAAA AAAAA BAAAB BAAAA BAAAA BAAAA BAAAB AAAAA AAAAA BBBBB 
----- ----- ----- ----- ----- ----- BBBBB AAAAA AAAAA AAAAB AAAAB AAAAB AAAAB AAAAB AAAAB BAAAB BAAAB AAAAA AAAAA AAAAB AAAAB AAAAB AAAAB AAAAB AAAAA AAAAA BBBBB 
----- ----- ----- ----- ----- ----- BBBBB AAAAA AAAAA BAAAB BAAAB BAAAB BAAAB BAAAB BAAAB BAAAB BAAAB AAAAA AAAAA BAAAA BAAAA BAAAA BAAAA BAAAA AAAAA AAAAA BBBBB 
----- ----- ----- ----- ----- ----- BBBBB AAAAA AAAAA BAAAB BAAAB BAAAA BAAAB BAAAB BAAAA BAAAB BAAAB AAAAA AAAAA BAAAA AAAAB AAAAB AAAAB BAAAB AAAAA AAAAA BBBBB 
----- ----- ----- ----- ----- ----- BBBBB AAAAA AAAAA AAAAB AAAAB AAAAA AAAAB AAAAB AAAAA AAAAB AAAAB AAAAA AAAAA BAAAB BAAAA BAAAA BAAAA BAAAA AAAAA AAAAA BBBBB 
----- ----- ----- ----- ----- ----- BBBBB AAAAA AAAAA AAAAA AAAAA AAAAA AAAAA AAAAA AAAAA AAAAA AAAAA AAAAA AAAAA AAAAA AAAAB AAAAA AAAAA AAAAA AAAAA AAAAA BBBBB 
----- ----- ----- ----- ----- ----- BBBBB AAAAA AAAAA AAAAB AAAAB AAAAA AAAAB AAAAB AAAAB AAAAB AAAAB AAAAA AAAAA AAAAB AAAAA BAAAA AAAAA BAAAA AAAAA AAAAA BBBBB 
----- ----- ----- ----- ----- ----- BBBBB AAAAA AAAAA AAAAB AAAAB AAAAA AAAAB AAAAB AAAAB AAAAB AAAAB AAAAA AAAAA BAAAA BAAAB BAAAB BAAAB BAAAB AAAAA AAAAA BBBBB 
----- ----- ----- ----- ----- ----- BBBBB AAAAA AAAAA AAAAA AAAAA AAAAA AAAAA AAAAA AAAAA AAAAA AAAAA AAAAA AAAAA AAAAA AAAAA AAAAA AAAAA AAAAA AAAAA AAAAA BBBBB 
----- ----- ----- ----- ----- ----- ----- BBBBB AAAAA AAAAA AAAAA AAAAA AAAAA AAAAA AAAAA AAAAA AAAAA AAAAA AAAAA AAAAA AAAAA AAAAA AAAAA AAAAA AAAAA BBBBB ----- 
----- ----- ----- ----- ----- ----- ----- ----- BBBBB BBBBB BBBBB BBBBB BBBBB BBBBB BBBBB BBBBB BBBBB BBBBB BBBBB BBBBB BBBBB BBBBB BBBBB BBBBB BBBBB ----- ----- 
