model
size = 30 31 10, scale = 0.05, origin = -y
material 
  colors = A:#777 B:#CB0FFF C:#004 D:#007 E:#002 F:#005 G:#3C72A2 H:#2E577D I:#888
voxels
------------------------------ ------------------------------ ------------------------------ ------------------------------ ------------------------------ ------------------------------ ------------------------------ ------------------------------ ------------------------------ ----HHHHHHHHH-----HHHHHHHH---- ----BBBBBBBBBBB--GBBBBBBBBB--- --GBBBBBBBBBBBBB-GBBBBBBBBBB-- --GBBBBBBBBBBBBB-GBBBBBBBBBB-- --GBBB-GBBB-GBBB---------BBB-- --GBBB-GBBB-GBBB--HHHHHHHBBB-- --GBBB-GBBB-GBBB--BBBBBBBBBB-- --GBBB-GBBB-GBBB--BBBBBBBBBB-- --GBBB-GBBB-GBBB--BBBBBBBBBB-- --GBBB-GBBB-GBBB---------BBB-- --GBBB-GBBB-GBBB-GBBBBBBBBBB-- --GBBB-GBBB-GBBB-GBBBBBBBBB--- --GBBB-GBBB-GBBB-GBBBBBBBB---- ------------------------------ ------------------------------ ------------------------------ ------------------------------ ------------------------------ ------------------------------ ------------------------------ ------------------------------ ------------------------------ 
------------------------------ ------------------------------ ------------------------------ ------------------------------ ------------------------------ ------------------------------ ------------------------------ ------------------------------ ------------------------------ ----HHHHHHHHH-----HHHHHHHH---- ----BBBBBBBBBBB--GBBBBBBBBB--- --GBBBBBBBBBBBBB-GBBBBBBBBBB-- --GBBBBBBBBBBBBB-GBBBBBBBBBB-- --GBBB-GBBB-GBBB---------BBB-- --GBBB-GBBB-GBBB--HHHHHHHBBB-- --GBBB-GBBB-GBBB--BBBBBBBBBB-- --GBBB-GBBB-GBBB--BBBBBBBBBB-- --GBBB-GBBB-GBBB--BBBBBBBBBB-- --GBBB-GBBB-GBBB---------BBB-- --GBBB-GBBB-GBBB-GBBBBBBBBBB-- --GBBB-GBBB-GBBB-GBBBBBBBBB--- --GBBB-GBBB-GBBB-GBBBBBBBB---- ------------------------------ ------------------------------ ------------------------------ ------------------------------ ------------------------------ ------------------------------ ------------------------------ ------------------------------ ------------------------------ 
--------------AA-------------- ------------AAAAAA------------ ----------AAAAAAAAAA---------- --------AAAAAA--AAAAAA-------- ------AAAAAA------AAAAAA------ ----AAAAAA----------AAAAAA---- ---AAAAA--------------AAAAA--- ---AAA------------------AAA--- ---AAA------------------AAA--- --AAHHHHHHHHH-----HHHHHHHHAA-- --AABBBBBBBBBBB--GBBBBBBBBBA-- --GBBBBBBBBBBBBB-GBBBBBBBBBB-- --GBBBBBBBBBBBBB-GBBBBBBBBBB-- -AGBBB-GBBB-GBBB---------BBBA- -AGBBB-GBBB-GBBB--HHHHHHHBBBA- -AGBBB-GBBB-GBBB--BBBBBBBBBBA- -AGBBB-GBBB-GBBB--BBBBBBBBBBA- AAGBBB-GBBB-GBBB--BBBBBBBBBBAA AAGBBB-GBBB-GBBB---------BBBAA AAGBBB-GBBB-GBBB-GBBBBBBBBBBAA AAGBBB-GBBB-GBBB-GBBBBBBBBBEAA AAGBBB-GBBB-GBBB-GBBBBBBBB-AAA AAAA----------------------AAAA AAAAAA------------------AAAAAA AAAAAAAA--------------AAAAAAAA --AAAAAAAA----------AAAAAAAA-- ----AAAAAAAA------AAAAAAAA---- ------AAAAAAAA--AAAAAAAA------ --------AAAAAAAAAAAAAA-------- ----------AAAAAAAAAA---------- ------------AAAAAA------------ 
--------------AA-------------- ------------AAAAAA------------ ----------AAAAAAAAAA---------- --------AAAAAAFEAAAAAA-------- ------AAAAAAFFDCEEAAAAAA------ ----AAAAAAFFDDDCCCEEAAAAAA---- ---AAAAAFFDDDDDCCCCCEEAAAAA--- ---AAAFFDDDDDDDCCCCCCCEEAAA--- ---AAAFDDDDDDDDCCCCCCCCEAAA--- --AAAAFDDDDDDDDCCCCCCCCCAAAA-- --AAAFDDDDDDDDDCCCCCCCCCECAA-- --AAAFDDDDDDDDDCCCCCCCCCECAA-- --AAAFDDDDDDDDDCCCCCCCCCECAA-- -AAAAFDDDDDDDDDCCCCCCCCCECAAA- -AAAFDDDDDDDDDDCCCCCCCCCCEAAA- -AAAFDDDDDDDDDDCCCCCCCCCCEAAA- -AAAFDDDDDDDDDDCCCCCCCCCCEAAA- AAAAFDDDDDDDDDDCCCCCCCCCCEAAAA AAAFDDDDDDDDDDDCCCCCCCCCCCEAAA AAAFDDDDDDDDDDDCCCCCCCCCCCEAAA AAAFDDDDDDDDDDDCCCCCCCCCCCEAAA AAAFDDDDDDDDDDDCCCCCCCCCCCEAAA AAAAFFDDDDDDDDDCCCCCCCCCEEAAAA AAAAAAFFDDDDDDDCCCCCCCEEAAAAAA AAAAAAAAFFDDDDDCCCCCEEAAAAAAAA --AAAAAAAAFFDDDCCCEEAAAAAAAA-- ----AAAAAAAAFFDCEEAAAAAAAA---- ------AAAAAAAAFEAAAAAAAA------ --------AAAAAAAAAAAAAA-------- ----------AAAAAAAAAA---------- ------------AAAAAA------------ 
--------------AA-------------- ------------AAAAAA------------ ----------AAAAAAAAAA---------- --------AAAAAAAAAAAAAA-------- ------AAAAAAAAAAAAAAAAAA------ ----AAAAAAAAAAAAAAAAAAAAAA---- ---AAAAAAAAAAAAAAAAAAAAAAAA--- ---AAAAAAAAAAAAAAAAAAAAAAAA--- ---AAAAAAAAAAAAAAAAAAAAAAAA--- --AAAAAAAAAAAAAAAAAAAAAAAAAA-- --AAAAAAAAAAAAAAAAAAAAAAAAAA-- --AAAAAAAAAAAAAAAAAAAAAAAAAA-- --AAAAAAAAAAAAAAAAAAAAAAAAAA-- -AAAAAAAAAAAAAAAAAAAAAAAAAAAA- -AAAAAAAAAAAAAAAAAAAAAAAAAAAA- -AAAAAAAAAAAAAAAAAAAAAAAAAAAA- -AAAAAAAAAAAAAAAAAAAAAAAAAAAA- AAAAAAAAAAAAAAAAAAAAAAAAAAAAAA AAAAAAAAAAAAAAAAAAAAAAAAAAAAAA AAAAAAAAAAAAAAAAAAAAAAAAAAAAAA AAAAAAAAAAAAAAAAAAAAAAAAAAAAAA AAAAAAAAAAAAAAAAAAAAAAAAAAAAAA AAAAAAAAAAAAAAAAAAAAAAAAAAAAAA AAAAAAAAAAAAAAAAAAAAAAAAAAAAAA AAAAAAAAAAAAAAAAAAAAAAAAAAAAAA --AAAAAAAAAAAAAAAAAAAAAAAAAA-- ----AAAAAAAAAAAAAAAAAAAAAA---- ------AAAAAAAAAAAAAAAAAA------ --------AAAAAAAAAAAAAA-------- ----------AAAAAAAAAA---------- ------------AAAAAA------------ 
--------------AA-------------- ------------AAAAAA------------ ----------AAAAAAAAAA---------- --------AAAAAAEEAAAAAA-------- ------AAAAAAEECCEEAAAAAA------ ----AAAAAAEEECCFDEEEAAAAAA---- ---AAAAAEECCECCFDECCEEAAAAA--- ---AAAEECCCFECFFDECCCFEEAAA--- ---AAAEECCFFECFFDECCFFEEAAA--- --AAAAEECFFFECFFDECFFFECAAAA-- --AAAECECFFFECFFDECFFFECCCAA-- --AAAECECFFFECFFDECFFFECFCAA-- --AAAECECFFFECFFDECFFFECFCAA-- -AAAAECECFFFECFFDECFFFECFCAAA- -AAAECFECFFFECFFDECFFFECFEAAA- -AAAECFECFFFECFFDECFFFECFEAAA- -AAAECFECFFDECFFDECFFDECFEAAA- AAAAECFECFFDECFFDECFFDECFEAAAA AAAECFDECFFDECFFDECFFDEFFDEAAA AAAECFDECFFDECFFDECFFDEFFDEAAA AAAECFDECFFDECFFDECFFDEFFDEAAA AAAECFDECFFDECFFDECFFDEFFDEAAA AAAAEEDECFFDECFFDECFFDECEEAAAA AAAAAAEECFFDECFFDECFFDEEAAAAAA AAAAAAAAEEFDECFFDECFEEAAAAAAAA --AAAAAAAAEEECFFDEEEAAAAAAAA-- ----AAAAAAAAEEFDEEAAAAAAAA---- ------AAAAAAAAEEAAAAAAAA------ --------AAAAAAAAAAAAAA-------- ----------AAAAAAAAAA---------- ------------AAAAAA------------ 
--------------AA-------------- ------------AAAAAA------------ ----------AAAAAAAAAA---------- --------AAAAAA--AAAAAA-------- ------AAAAAA------AAAAAA------ ----AAAAAA----------AAAAAA---- ---AAAAA--------------AAAAA--- ---AAA------------------AAA--- ---AAA------------------AAA--- --AAAA------------------AAAA-- --AAA--------------------AAA-- --AAA--------------------AAA-- --AAA--------------------AAA-- -AAAA--------------------AAAA- -AAA---EE------------EE---AAA- -AAA---EE------------EE---AAA- -AAA---EE------------EE---AAA- AAAA---EE------------EE---AAAA AAA------------------------AAA AAA------------------------AAA AAA------------------------AAA AAA------------------------AAA AAAA----------------------AAAA AAAAAA------------------AAAAAA AAAAAAAA--------------AAAAAAAA --AAAAAAAA----------AAAAAAAA-- ----AAAAAAAA------AAAAAAAA---- ------AAAAAAAA--AAAAAAAA------ --------AAAAAAAAAAAAAA-------- ----------AAAAAAAAAA---------- ------------AAAAAA------------ 
------------------------------ ------------------------------ ------------------------------ ------------------------------ ------------------------------ ------------------------------ ------------------------------ ------------------------------ ------------------------------ ------------------------------ ------------------------------ ------------------------------ ------------------------------ ------------------------------ --------AA----------AA-------- --------II----------II-------- --------II----------II-------- --------AA----------AA-------- ------------------------------ ------------------------------ ------------------------------ ------------------------------ ------------------------------ ------------------------------ ------------------------------ ------------------------------ ------------------------------ ------------------------------ ------------------------------ ------------------------------ ------------------------------ 
------------------------------ ------------------------------ ------------------------------ ------------------------------ ------------------------------ ------------------------------ ------------------------------ ------------------------------ ------------------------------ ------------------------------ ------------------------------ ------------------------------ ------------------------------ ------------------------------ ---------AAA------AAA--------- ---------III------III--------- ---------III------III--------- ---------AAA------AAA--------- ------------------------------ ------------------------------ ------------------------------ ------------------------------ ------------------------------ ------------------------------ ------------------------------ ------------------------------ ------------------------------ ------------------------------ ------------------------------ ------------------------------ ------------------------------ 
------------------------------ ------------------------------ ------------------------------ ------------------------------ ------------------------------ ------------------------------ ------------------------------ ------------------------------ ------------------------------ ------------------------------ ------------------------------ ------------------------------ ------------------------------ ------------------------------ -----------AAAAAAAA----------- -----------IIIIIIII----------- -----------IIIIIIII----------- -----------AAAAAAAA----------- ------------------------------ ------------------------------ ------------------------------ ------------------------------ ------------------------------ ------------------------------ ------------------------------ ------------------------------ ------------------------------ ------------------------------ ------------------------------ ------------------------------ ------------------------------ 
