model
size = 30 31 10, scale = 0.05, origin = -y
material 
  colors = A:#2A4A5B B:#4B4B4B C:#959595 D:#E3E3E3 E:#5E5E5E F:#BBB G:#46647C
voxels
------------------------------ ------------------------------ ------------------------------ ------------------------------ ------------------------------ ------------------------------ ------------------------------ ------------------------------ ------------------------------ ----BBBBBBBBB-----BBBBBBBB---- ----BBBBBBBBBBB--BBBBBBBBBB--- --BBBBBBBBBBBBBB-BBBBBBBBBBB-- --BBBBBBBBBBBBBB-BBBBBBBBBBB-- --BBBB-BBBB-BBBB---------BBB-- --BBBB-BBBB-BBBB--BBBBBBBBBB-- --BBBB-BBBB-BBBB--BBBBBBBBBB-- --BBBB-BBBB-BBBB--BBBBBBBBBB-- --BBBB-BBBB-BBBB--BBBBBBBBBB-- --BBBB-BBBB-BBBB---------BBB-- --BBBB-BBBB-BBBB-BBBBBBBBBBB-- --BBBB-BBBB-BBBB-BBBBBBBBBBB-- --BBBB-BBBB-BBBB-BBBBBBBBB---- ------------------------------ ------------------------------ ------------------------------ ------------------------------ ------------------------------ ------------------------------ ------------------------------ ------------------------------ ------------------------------ 
------------------------------ ------------------------------ ------------------------------ ------------------------------ ------------------------------ ------------------------------ ------------------------------ ------------------------------ ------------------------------ ----BBBBBBBBB-----BBBBBBBB---- ----BBBBBBBBBBB--BBBBBBBBBB--- --BBBBBBBBBBBBBB-BBBBBBBBBBB-- --BBBBBBBBBBBBBB-BBBBBBBBBBB-- --BBBB-BBBB-BBBB---------BBB-- --BBBB-BBBB-BBBB--BBBBBBBBBB-- --BBBB-BBBB-BBBB--BBBBBBBBBB-- --BBBB-BBBB-BBBB--BBBBBBBBBB-- --BBBB-BBBB-BBBB--BBBBBBBBBB-- --BBBB-BBBB-BBBB---------BBB-- --BBBB-BBBB-BBBB-BBBBBBBBBBB-- --BBBB-BBBB-BBBB-BBBBBBBBBBB-- --BBBB-BBBB-BBBB-BBBBBBBBB---- ------------------------------ ------------------------------ ------------------------------ ------------------------------ ------------------------------ ------------------------------ ------------------------------ ------------------------------ ------------------------------ 
--------------AA-------------- ------------AAAAAA------------ ----------AAAAAAAAAA---------- --------AAAAAA--AAAAAA-------- ------AAAAAA------AAAAAA------ ----AAAAAA----------AAAAAA---- ---AAAAA--------------AAAAA--- ---AAA------------------AAA--- ---AAA------------------AAA--- --AABBBBBBBBB-----BBBBBBBBAA-- --AABBBBBBBBBBB--BBBBBBBBBBA-- --BBBBBBBBBBBBBB-BBBBBBBBBBB-- --BBBBBBBBBBBBBB-BBBBBBBBBBB-- -ABBBB-BBBB-BBBB---------BBBA- -ABBBB-BBBB-BBBB--BBBBBBBBBBA- -ABBBB-BBBB-BBBB--BBBBBBBBBBA- -ABBBB-BBBB-BBBB--BBBBBBBBBBA- AABBBB-BBBB-BBBB--BBBBBBBBBBAA AABBBB-BBBB-BBBB---------BBBAA AABBBB-BBBB-BBBB-BBBBBBBBBBBAA AABBBB-BBBB-BBBB-BBBBBBBBBBBAA AABBBB-BBBB-BBBB-BBBBBBBBB-AAA AAAA----------------------AAAA AAAAAA------------------AAAAAA AAAAAAAA--------------AAAAAAAA --AAAAAAAA----------AAAAAAAA-- ----AAAAAAAA------AAAAAAAA---- ------AAAAAAAA--AAAAAAAA------ --------AAAAAAAAAAAAAA-------- ----------AAAAAAAAAA---------- ------------AAAAAA------------ 
--------------AA-------------- ------------AAAAAA------------ ----------AAAAAAAAAA---------- --------AAAAAAFEAAAAAA-------- ------AAAAAAFFDCEEAAAAAA------ ----AAAAAAFFDDDCCCEEAAAAAA---- ---AAAAAFFDDDDDCCCCCEEAAAAA--- ---AAAFFDDDDDDDCCCCCCCEEAAA--- ---AAAFDDDDDDDDCCCCCCCCEAAA--- --AAAAFDDDDDDDDCCCCCCCCCAAAA-- --AAAFDDDDDDDDDCCCCCCCCCECAA-- --AAAFDDDDDDDDDCCCCCCCCCECAA-- --AAAFDDDDDDDDDCCCCCCCCCECAA-- -AAAAFDDDDDDDDDCCCCCCCCCECAAA- -AAAFDDDDDDDDDDCCCCCCCCCCEAAA- -AAAFDDDDDDDDDDCCCCCCCCCCEAAA- -AAAFDDDDDDDDDDCCCCCCCCCCEAAA- AAAAFDDDDDDDDDDCCCCCCCCCCEAAAA AAAFDDDDDDDDDDDCCCCCCCCCCCEAAA AAAFDDDDDDDDDDDCCCCCCCCCCCEAAA AAAFDDDDDDDDDDDCCCCCCCCCCCEAAA AAAFDDDDDDDDDDDCCCCCCCCCCCEAAA AAAAFFDDDDDDDDDCCCCCCCCCEEAAAA AAAAAAFFDDDDDDDCCCCCCCEEAAAAAA AAAAAAAAFFDDDDDCCCCCEEAAAAAAAA --AAAAAAAAFFDDDCCCEEAAAAAAAA-- ----AAAAAAAAFFDCEEAAAAAAAA---- ------AAAAAAAAFEAAAAAAAA------ --------AAAAAAAAAAAAAA-------- ----------AAAAAAAAAA---------- ------------AAAAAA------------ 
--------------AA-------------- ------------AAAAAA------------ ----------AAAAAAAAAA---------- --------AAAAAAAAAAAAAA-------- ------AAAAAAAAAAAAAAAAAA------ ----AAAAAAAAAAAAAAAAAAAAAA---- ---AAAAAAAAAAAAAAAAAAAAAAAA--- ---AAAAAAAAAAAAAAAAAAAAAAAA--- ---AAAAAAAAAAAAAAAAAAAAAAAA--- --AAAAAAAAAAAAAAAAAAAAAAAAAA-- --AAAAAAAAAAAAAAAAAAAAAAAAAA-- --AAAAAAAAAAAAAAAAAAAAAAAAAA-- --AAAAAAAAAAAAAAAAAAAAAAAAAA-- -AAAAAAAAAAAAAAAAAAAAAAAAAAAA- -AAAAAAAAAAAAAAAAAAAAAAAAAAAA- -AAAAAAAAAAAAAAAAAAAAAAAAAAAA- -AAAAAAAAAAAAAAAAAAAAAAAAAAAA- AAAAAAAAAAAAAAAAAAAAAAAAAAAAAA AAAAAAAAAAAAAAAAAAAAAAAAAAAAAA AAAAAAAAAAAAAAAAAAAAAAAAAAAAAA AAAAAAAAAAAAAAAAAAAAAAAAAAAAAA AAAAAAAAAAAAAAAAAAAAAAAAAAAAAA AAAAAAAAAAAAAAAAAAAAAAAAAAAAAA AAAAAAAAAAAAAAAAAAAAAAAAAAAAAA AAAAAAAAAAAAAAAAAAAAAAAAAAAAAA --AAAAAAAAAAAAAAAAAAAAAAAAAA-- ----AAAAAAAAAAAAAAAAAAAAAA---- ------AAAAAAAAAAAAAAAAAA------ --------AAAAAAAAAAAAAA-------- ----------AAAAAAAAAA---------- ------------AAAAAA------------ 
--------------AA-------------- ------------AAAAAA------------ ----------AAAAAAAAAA---------- --------AAAAAAEEAAAAAA-------- ------AAAAAAEECCEEAAAAAA------ ----AAAAAAEEECCFDEEEAAAAAA---- ---AAAAAEECCECCFDECCEEAAAAA--- ---AAAEECCCFECFFDECCCFEEAAA--- ---AAAEECCFFECFFDECCFFEEAAA--- --AAAAEECFFFECFFDECFFFECAAAA-- --AAAECECFFFECFFDECFFFECCCAA-- --AAAECECFFFECFFDECFFFECFCAA-- --AAAECECFFFECFFDECFFFECFCAA-- -AAAAECECFFFECFFDECFFFECFCAAA- -AAAECFECFFFECFFDECFFFECFEAAA- -AAAECFECFFFECFFDECFFFECFEAAA- -AAAECFECFFDECFFDECFFDECFEAAA- AAAAECFECFFDECFFDECFFDECFEAAAA AAAECFDECFFDECFFDECFFDEFFDEAAA AAAECFDECFFDECFFDECFFDEFFDEAAA AAAECFDECFFDECFFDECFFDEFFDEAAA AAAECFDECFFDECFFDECFFDEFFDEAAA AAAAEEDECFFDECFFDECFFDECEEAAAA AAAAAAEECFFDECFFDECFFDEEAAAAAA AAAAAAAAEEFDECFFDECFEEAAAAAAAA --AAAAAAAAEEECFFDEEEAAAAAAAA-- ----AAAAAAAAEEFDEEAAAAAAAA---- ------AAAAAAAAEEAAAAAAAA------ --------AAAAAAAAAAAAAA-------- ----------AAAAAAAAAA---------- ------------AAAAAA------------ 
--------------AA-------------- ------------AAAAAA------------ ----------AAAAAAAAAA---------- --------AAAAAA--AAAAAA-------- ------AAAAAA------AAAAAA------ ----AAAAAA----------AAAAAA---- ---AAAAA--------------AAAAA--- ---AAA------------------AAA--- ---AAA------------------AAA--- --AAAA------------------AAAA-- --AAA--------------------AAA-- --AAA--------------------AAA-- --AAA--------------------AAA-- -AAAA--------------------AAAA- -AAA---EE------------EE---AAA- -AAA---EE------------EE---AAA- -AAA---EE------------EE---AAA- AAAA---EE------------EE---AAAA AAA------------------------AAA AAA------------------------AAA AAA------------------------AAA AAA------------------------AAA AAAA----------------------AAAA AAAAAA------------------AAAAAA AAAAAAAA--------------AAAAAAAA --AAAAAAAA----------AAAAAAAA-- ----AAAAAAAA------AAAAAAAA---- ------AAAAAAAA--AAAAAAAA------ --------AAAAAAAAAAAAAA-------- ----------AAAAAAAAAA---------- ------------AAAAAA------------ 
------------------------------ ------------------------------ ------------------------------ ------------------------------ ------------------------------ ------------------------------ ------------------------------ ------------------------------ ------------------------------ ------------------------------ ------------------------------ ------------------------------ ------------------------------ ------------------------------ --------AA----------AA-------- --------GG----------GG-------- --------GG----------GG-------- --------AA----------AA-------- ------------------------------ ------------------------------ ------------------------------ ------------------------------ ------------------------------ ------------------------------ ------------------------------ ------------------------------ ------------------------------ ------------------------------ ------------------------------ ------------------------------ ------------------------------ 
------------------------------ ------------------------------ ------------------------------ ------------------------------ ------------------------------ ------------------------------ ------------------------------ ------------------------------ ------------------------------ ------------------------------ ------------------------------ ------------------------------ ------------------------------ ------------------------------ ---------AAA------AAA--------- ---------GGG------GGG--------- ---------GGG------GGG--------- ---------AAA------AAA--------- ------------------------------ ------------------------------ ------------------------------ ------------------------------ ------------------------------ ------------------------------ ------------------------------ ------------------------------ ------------------------------ ------------------------------ ------------------------------ ------------------------------ ------------------------------ 
------------------------------ ------------------------------ ------------------------------ ------------------------------ ------------------------------ ------------------------------ ------------------------------ ------------------------------ ------------------------------ ------------------------------ ------------------------------ ------------------------------ ------------------------------ ------------------------------ -----------AAAAAAAA----------- -----------GGGGGGGG----------- -----------GGGGGGGG----------- -----------AAAAAAAA----------- ------------------------------ ------------------------------ ------------------------------ ------------------------------ ------------------------------ ------------------------------ ------------------------------ ------------------------------ ------------------------------ ------------------------------ ------------------------------ ------------------------------ ------------------------------ 
