model
size = 30 31 24, scale = 0.05, origin = -y
material 
  colors = A:#777 B:#39C C:#888 D:#F3C E:#FF6 F:#FCC G:#FF0 H:#FC6 I:#FCF J:#F3F K:#FFF L:#FF9 M:#FF3 N:#FFC O:#F6F
voxels
------------------------------ ------------------------------ ------------------------------ ------------------------------ ------------------------------ ------------------------------ ------EGL------------EBBBB---- ----BBBBBE--------KBBBBBB----- ----BBBBBD------GBBBBBBBG----- ----BBBBBB-----BBBBBBBH------- ----BBBBBB---HBBBBBBB--------- ----DBBBBBD-BBBBBBBK---------- ----FBBBBBBBBBBBBB------------ -----BBBBBBBBBBBBDE----------- -----BBBBBBBBBBBBBBBJ--------- -----BBBBBBBBBBBBBBBBBBF------ -----FBBBBBBB-EHBBBBBBBBB----- ------BBBBBBB----FBBBBBBBBM--- ------BBBBBBBO-----LBBBBBBB--- ------IBBBBBBB------IBBBBBB--- -------BBBBBBBJ------BBBBBB--- -------HBBBBBBBBBBBBBBBBBB---- --------BBBBBBBBBBBBBBBBB----- ----------IDBBBBBBBBBBBJ------ --------------MNDBBBDG-------- ------------------------------ ------------------------------ ------------------------------ ------------------------------ ------------------------------ ------------------------------ 
------------------------------ ------------------------------ ------------------------------ ------------------------------ ------------------------------ ------------------------------ ------EGL------------EBBBB---- ----BBBBBE--------KBBBBBB----- ----BBBBBD------GBBBBBBBG----- ----BBBBBB-----BBBBBBBH------- ----BBBBBB---HBBBBBBB--------- ----DBBBBBD-BBBBBBBK---------- ----FBBBBBBBBBBBBB------------ -----BBBBBBBBBBBBDE----------- -----BBBBBBBBBBBBBBBJ--------- -----BBBBBBBBBBBBBBBBBBF------ -----FBBBBBBBAEHBBBBBBBBB----- ------BBBBBBBAAAAFBBBBBBBBM--- ------BBBBBBBOAAA--LBBBBBBB--- ------IBBBBBBBAAA---IBBBBBB--- -------BBBBBBBJAA----BBBBBB--- -------HBBBBBBBBBBBBBBBBBB---- --------BBBBBBBBBBBBBBBBB----- ----------IDBBBBBBBBBBBJ------ --------------MNDBBBDG-------- ------------------------------ ------------------------------ ------------------------------ ------------------------------ ------------------------------ ------------------------------ 
------------------------------ ------------------------------ ------------------------------ ------------------------------ ------------------------------ ------------------------------ ------EGL------------EBBBB---- ----BBBBBE--------KBBBBBB----- ----BBBBBD---AAAGBBBBBBBG----- ----BBBBBB---AABBBBBBBH------- ----BBBBBB---HBBBBBBB--------- ----DBBBBBD-BBBBBBBK---------- ----FBBBBBBBBBBBBB------------ -----BBBBBBBBBBBBDEA---------- -----BBBBBBBBBBBBBBBJ--------- -----BBBBBBBBBBBBBBBBBBF------ -----FBBBBBBB-EHBBBBBBBBB----- ------BBBBBBB----FBBBBBBBBM--- ------BBBBBBB----AALBBBBBBB--- ------IBBBBBB----AAAIBBBBBB--- -------BBBBBB----AAA-BBBBBB--- -------HBBBBB----BBBBBBBBB---- --------BBBBB----BBBBBBBB----- ----------IDB----BBBBBBJ------ -------------AMNDBBBDG-------- -------------AAAA------------- ------------------------------ ------------------------------ ------------------------------ ------------------------------ ------------------------------ 
--------------AA-------------- -------------AAAA------------- -------------AAAA------------- -------------AAAA------------- -------------AAAA------------- -------------AAAA------------- ------EGL----AAAA----EBBBB---- ----BBBBBE---AAAA-KBBBBBB----- ----BBBBBDAAA----BBBBBBBG----- ----BBBBBBAAA----BBBBBH------- ----BBBBBBAAA----BBBB--------- ----DBBBBBDAB----BBK---------- ----FBBBBBBBB----BAA---------- -----BBBBB-------DE-AA-------- -----BBBBB-------BBBJA-------- -----BBBBB-------BBBBBBF------ -----FBBBB-------BBBBBBBB----- ------BBBB-------FBBBBBBBBM--- ------BBBB---------LBBBBBBB--- ------IBBB----------IBBBBBB--- -------BBB----------ABBBBBB--- -------HBB----------BBBBBB---- --------BB----------BBBBB----- --------------------BBBJ------ ----------AAA----BBBDG-------- ----------AAA----AAA---------- -------------AAAA------------- -------------AAAA------------- -------------AAAA------------- -------------AAAA------------- -------------AAAA------------- 
--------------AA-------------- ------------AAAAAA------------ ----------AAAAAAAAAA---------- ----------AAAA--AAAA---------- ----------AAA----AAA---------- ----------AAA----AAA---------- ------EGL-AAA----AAA-EBBBB---- ----BBBBBEAAA----AKBBBBBB----- ----BBBB------------BBBBG----- ----BBBB------------BBH------- ----BBBB------------BA-------- ----DBBB------------AA-------- ----FBBB------------AA-------- ----ABB---------------AAAA---- ----ABB---------------AAAA---- ----ABB---------------BFAA---- ----AFB---------------BBBA---- ----AAB---------------BBBBM--- ----AAB---------------BBBBB--- ----AAI---------------BBBBB--- ----AAA---------------BBBBB--- ----AAA---------------BBBB---- ----AAAA--------------BBBA---- --------AA------------BJ------ --------AA----------DG-------- --------AA----------AA-------- ----------AAA----AAA---------- ----------AAAA--AAAA---------- ----------AAAAAAAAAA---------- ----------AAAAAAAAAA---------- ------------AAAAAA------------ 
------------------------------ ------------A----A------------ ----------AAA----AAA---------- --------AAAAA----AAAAA-------- --------AAAA------AAAA-------- --------AA----------AA-------- --------AA----------AA-------- --------AA----------AA-------- ----AAAA--------------AAAA---- ----AAAA--------------AAAA---- ----AAAA--------------AAAA---- ----AAAA--------------AAAA---- ----AAAA--------------AAAA---- -AAAA---------------------AAA- -AAA----------------------AAA- -AAA----------------------AAA- -AAA----------------------AAA- AAAA----------------------AAAA AAAA----------------------AAAA AAAA----------------------AAAA AAAA----------------------AAAA AAAA----------------------AAAA AAAA----------------------AAAA ----AAAA--------------AAAA---- ----AAAA--------------AAAA---- ----AAAAAA----------AAAAAA---- --------AAAA------AAAA-------- --------AAAAA----AAAAA-------- --------AAAAA----AAAAA-------- ----------AAA----AAA---------- ------------A----A------------ 
------------------------------ ------------------------------ ------------------------------ --------AA----------AA-------- ------AAAA----------AAAA------ ----AAAAAA----------AAAAAA---- ----AAAA--------------AAAA---- ----AAAA--------------AAAA---- ---AAA------------------AAA--- --AAAA------------------AAAA-- --AAA---------------------AA-- --AAA---------------------AA-- --AAA---------------------AA-- -AAA----------------------AAA- -AAA----------------------AAA- -AAA----------------------AAA- -AAA----------------------AAA- AAAA----------------------AAAA AAA------------------------AAA AAA------------------------AAA AAA------------------------AAA AAA------------------------AAA AAAA----------------------AAAA AAAAAA------------------AAAAAA AAAAAAAA--------------AAAAAAAA --AAAAAA--------------AAAAAA-- ----AAAAAA----------AAAAAA---- ------AAAA----------AAAA------ --------AA----------AA-------- ------------------------------ ------------------------------ 
------------------------------ ------------------------------ ------------------------------ ------------------------------ ------AA--------------AA------ ----AAAA--------------AAAA---- ---AAAAA--------------AAAAA--- ---AAA------------------AAA--- ---A----------------------A--- --AA----------------------AA-- --AA----------------------AA-- --AA----------------------AA-- --AA----------------------AA-- --AA----------------------AA-- --AA----------------------AA-- --AA----------------------AA-- --AA----------------------AA-- -AA------------------------AA- -AA------------------------AA- -AA------------------------AA- -AA------------------------AA- -AA------------------------AA- -AA------------------------AA- AAAA----------------------AAAA AAAA----------------------AAAA --AA----------------------AA-- ----AAAA--------------AAAA---- ------AA--------------AA------ ------------------------------ ------------------------------ ------------------------------ 
------------------------------ ------------------------------ ------------------------------ ------------------------------ ------------------------------ ------------------------------ ---A----------------------A--- ---A----------------------A--- ---A----------------------A--- --AA----------------------AA-- --AA----------------------AA-- --AA----------------------AA-- --AA----------------------AA-- --AA----------------------AA-- --AA----------------------AA-- --AA----------------------AA-- --AA----------------------AA-- -AA------------------------AA- -AA------------------------AA- -AA------------------------AA- -AA------------------------AA- -AA------------------------AA- -AA------------------------AA- AAA------------------------AAA AAA------------------------AAA ------------------------------ ------------------------------ ------------------------------ ------------------------------ ------------------------------ ------------------------------ 
------------------------------ ------------------------------ ------------------------------ ------------------------------ ------------------------------ ------------------------------ ---A----------------------A--- ---A----------------------A--- ---A----------------------A--- --AA----------------------AA-- --AA----------------------AA-- --AA----------------------AA-- --AA----------------------AA-- --AA----------------------AA-- --AA----------------------AA-- --AA----------------------AA-- --AA----------------------AA-- -AA------------------------AA- -AA------------------------AA- -AA------------------------AA- -AA------------------------AA- -AA------------------------AA- -AA------------------------AA- AAA------------------------AAA AAA------------------------AAA ------------------------------ ------------------------------ ------------------------------ ------------------------------ ------------------------------ ------------------------------ 
------------------------------ ------------------------------ ------------------------------ ------------------------------ ------------------------------ ------------------------------ ---A----------------------A--- ---A----------------------A--- ---A----------------------A--- --AA----------------------AA-- --AA----------------------AA-- --AA----------------------AA-- --AA----------------------AA-- --AA----------------------AA-- --AA----------------------AA-- --AA----------------------AA-- --AA----------------------AA-- -AA------------------------AA- -AA------------------------AA- -AA------------------------AA- -AA------------------------AA- -AA------------------------AA- -AA------------------------AA- AAA------------------------AAA AAA------------------------AAA ------------------------------ ------------------------------ ------------------------------ ------------------------------ ------------------------------ ------------------------------ 
------------------------------ ------------------------------ ------------------------------ ------------------------------ ------------------------------ ------------------------------ ---A----------------------A--- ---A----------------------A--- ---A----------------------A--- --AA----------------------AA-- --AA----------------------AA-- --AA----------------------AA-- --AA----------------------AA-- --AA----------------------AA-- --AA----------------------AA-- --AA----------------------AA-- --AA----------------------AA-- -AA------------------------AA- -AA------------------------AA- -AA------------------------AA- -AA------------------------AA- -AA------------------------AA- -AA------------------------AA- AAA------------------------AAA AAA------------------------AAA ------------------------------ ------------------------------ ------------------------------ ------------------------------ ------------------------------ ------------------------------ 
------------------------------ ------------------------------ ------------------------------ ------------------------------ ------------------------------ ------------------------------ ------------------------------ ---A----------------------A--- ---A----------------------A--- --AA----------------------AA-- --AA----------------------AA-- --AA----------------------AA-- --AA----------------------AA-- --AA----------------------AA-- --AA----------------------AA-- --AA----------------------AA-- --AA----------------------AA-- -AA------------------------AA- -AA------------------------AA- -AA------------------------AA- -AA------------------------AA- -AA------------------------AA- -AA------------------------AA- AAA------------------------AAA AAA------------------------AAA ------------------------------ ------------------------------ ------------------------------ ------------------------------ ------------------------------ ------------------------------ 
------------------------------ ------------------------------ ------------------------------ ------------------------------ ------------------------------ ------------------------------ ------------------------------ ---A----------------------A--- ---A----------------------A--- --AA----------------------AA-- --AA----------------------AA-- --AA----------------------AA-- --AA----------------------AA-- --AA----------------------AA-- --AA----------------------AA-- --AA----------------------AA-- --AA----------------------AA-- -AA------------------------AA- -AA------------------------AA- -AA------------------------AA- -AA------------------------AA- -AA------------------------AA- -AA------------------------AA- AAA------------------------AAA AAA------------------------AAA ------------------------------ ------------------------------ ------------------------------ ------------------------------ ------------------------------ ------------------------------ 
------------------------------ ------------------------------ ------------------------------ ------------------------------ ------------------------------ ------------------------------ ------------------------------ ---A----------------------A--- ---A----------------------A--- --AA----------------------AA-- --AA----------------------AA-- --AA----------------------AA-- --AA----------------------AA-- --AA----------------------AA-- --AA----------------------AA-- --AA----------------------AA-- --AA----------------------AA-- -AA------------------------AA- -AA------------------------AA- -AA------------------------AA- -AA------------------------AA- -AA------------------------AA- -AA------------------------AA- AAA------------------------AAA AAA------------------------AAA ------------------------------ ------------------------------ ------------------------------ ------------------------------ ------------------------------ ------------------------------ 
------------------------------ ------------------------------ ------------------------------ ------------------------------ ------------------------------ ------------------------------ ------------------------------ ---A----------------------A--- ---A----------------------A--- --AA----------------------AA-- --AA----------------------AA-- --CA----------------------AC-- --CA----------------------AC-- --CA----------------------AC-- --CA----------------------AC-- --AA----------------------AA-- --AA----------------------AA-- -AA------------------------AA- -AA------------------------AA- -CA------------------------AC- -CA------------------------AC- -AA------------------------AA- -AA------------------------AA- AAA------------------------AAA AAA------------------------AAA ------------------------------ ------------------------------ ------------------------------ ------------------------------ ------------------------------ ------------------------------ 
------------------------------ ------------------------------ ------------------------------ ------------------------------ ------------------------------ ------------------------------ ------------------------------ ---A----------------------A--- ---A----------------------A--- --AA----------------------AA-- --CA----------------------AC-- ------------------------------ ------------------------------ ------------------------------ ------------------------------ --CA----------------------AC-- --AA----------------------AA-- -AA------------------------AA- -CA------------------------AC- ------------------------------ ------------------------------ -CA------------------------AC- -AA------------------------AA- AAA------------------------AAA AAA------------------------AAA ------------------------------ ------------------------------ ------------------------------ ------------------------------ ------------------------------ ------------------------------ 
------------------------------ ------------------------------ ------------------------------ ------------------------------ ------------------------------ ------------------------------ ------------------------------ ------------------------------ ---A----------------------A--- --CA----------------------AC-- ------------------------------ ------------------------------ ------------------------------ ------------------------------ ------------------------------ ------------------------------ --CA----------------------AC-- -CA------------------------AC- ------------------------------ ------------------------------ ------------------------------ ------------------------------ -CA------------------------AC- AAA------------------------AAA AAA------------------------AAA ------------------------------ ------------------------------ ------------------------------ ------------------------------ ------------------------------ ------------------------------ 
------------------------------ ------------------------------ ------------------------------ ------------------------------ ------------------------------ ------------------------------ ------------------------------ ------------------------------ ---A----------------------A--- --CA----------------------AC-- ------------------------------ ------------------------------ ------------------------------ ------------------------------ ------------------------------ ------------------------------ --CA----------------------AC-- -CA------------------------AC- ------------------------------ ------------------------------ ------------------------------ ------------------------------ -CA------------------------AC- AAA------------------------AAA AAA------------------------AAA ------------------------------ ------------------------------ ------------------------------ ------------------------------ ------------------------------ ------------------------------ 
------------------------------ ------------------------------ ------------------------------ ------------------------------ ------------------------------ ------------------------------ ------------------------------ ------------------------------ ---A----------------------A--- --CA----------------------AC-- ------------------------------ ------------------------------ ------------------------------ ------------------------------ ------------------------------ ------------------------------ --CA----------------------AC-- -CA------------------------AC- ------------------------------ ------------------------------ ------------------------------ ------------------------------ -CA------------------------AC- AAA------------------------AAA AAA------------------------AAA ------------------------------ ------------------------------ ------------------------------ ------------------------------ ------------------------------ ------------------------------ 
------------------------------ ------------------------------ ------------------------------ ------------------------------ ------------------------------ ------------------------------ ------------------------------ ------------------------------ ---A----------------------A--- --CA----------------------AC-- ------------------------------ ------------------------------ ------------------------------ ------------------------------ ------------------------------ ------------------------------ --CA----------------------AC-- -CA------------------------AC- ------------------------------ ------------------------------ ------------------------------ ------------------------------ -CA------------------------AC- AAA------------------------AAA AAA------------------------AAA ------------------------------ ------------------------------ ------------------------------ ------------------------------ ------------------------------ ------------------------------ 
------------------------------ ------------------------------ ------------------------------ ------------------------------ ------------------------------ ------------------------------ ------------------------------ ------------------------------ ------------------------------ --AA----------------------AA-- --CA----------------------AC-- ------------------------------ ------------------------------ ------------------------------ ------------------------------ --CA----------------------AC-- --AA----------------------AA-- -AA------------------------AA- -CA------------------------AC- ------------------------------ ------------------------------ -CA------------------------AC- -AA------------------------AA- ------------------------------ ------------------------------ ------------------------------ ------------------------------ ------------------------------ ------------------------------ ------------------------------ ------------------------------ 
------------------------------ ------------------------------ ------------------------------ ------------------------------ ------------------------------ ------------------------------ ------------------------------ ------------------------------ ------------------------------ ------------------------------ --AA----------------------AA-- --CA----------------------AC-- --CA----------------------AC-- --CA----------------------AC-- --CA----------------------AC-- --AA----------------------AA-- ------------------------------ ------------------------------ -AA------------------------AA- -CA------------------------AC- -CA------------------------AC- -AA------------------------AA- ------------------------------ ------------------------------ ------------------------------ ------------------------------ ------------------------------ ------------------------------ ------------------------------ ------------------------------ ------------------------------ 
------------------------------ ------------------------------ ------------------------------ ------------------------------ ------------------------------ ------------------------------ ------------------------------ ------------------------------ ------------------------------ ------------------------------ ------------------------------ ------------------------------ ------------------------------ ------------------------------ ------------------------------ ------------------------------ ------------------------------ ------------------------------ ------------------------------ -AA------------------------AA- -AA------------------------AA- ------------------------------ ------------------------------ ------------------------------ ------------------------------ ------------------------------ ------------------------------ ------------------------------ ------------------------------ ------------------------------ ------------------------------ 
