model
size = 30 22 17, scale = 0.05, origin = -y
material 
  colors = A:#200 B:#400 C:#888 D:#500 E:#F99 F:#F96 G:#963 H:#960 I:#111 J:#E00 K:#DDD L:#FCF M:#FCC
voxels
------------------------------ ------------------------------ ------------------------------ ------------------------------ ------------------------------ ------------------------------ ------------------------------ --------------A--------------- ---------AA---A---AA---------- --------AIKA-AAA-AKIA--------- --------AKIA-----AIKA--------- ---------AA-------AA---------- ------------------------------ ---------AA-------AA---------- ------------------------------ ------------------------------ ------------------------------ ------------------------------ ------------------------------ ------------------------------ ------------------------------ ------------------------------ 
------------AAAAAA------------ ----------AAFFFFFFAA---------- ---------AFFFFFFFFFFA--------- --------BEEEEEEEEEEEFA-------- -------BBEEEEEEEEEEEFFA------- ---AAAAAEEEEJJJJJEEEFFAAAAA--- --AGG-AEFFEJFFMFFJEEFFFA-GGA-- -AGF--AEFFEEEEAEEEEEFFFA--FGA- AGFF--AEFAAEEEAEEEAAFFFA--FFGA AGF---AEAILAEAAAFALIAFFA---FGA AG----AEALIAEEEEFAILAFFA----GA AG----AEMAAEEEEEFFAAFFFA----GA -AG---AEFFFEEEEEFFFFFFFA---GA- --AGGGAHFAAEEEEEFFAAFFHA-GGA-- ---AAAAHHEEEEEEEFFFFFHHAAAA--- ------AHGHEEEEHFFFFFHGHA------ ------AHGGHEHHHHHHFHGGHA------ -------AHGGHHGGGGHHGGHA------- --------AHHGGGGGGGGHHA-------- ---------AAHHGGGGHHAA--------- -----------AAHHHHAA----------- -------------AAAA------------- 
------------AAAAAA------------ ----------AACCCCCCAA---------- ---------DCCCCCCCCCCA--------- --------DDCCCCCCCCCCCA-------- -------ACCCCCCCCCCCCCCA------- ---AAAACCCCCCCCCCCCCCCCAAAA--- --ACCFCCCCCCCCCCCCCCCCCCECCA-- -ACCEFCCCCCCCCCCCCCCCCCCFECCA- ACCCEFCCCCCCCCCCCCCCCCCCFECCA- DCCEAACCCCCCCCCCCCCCCCCCAAECA- ACEAFACCCCCCCCCCCCCCCCCCAFAEA- ACEAAFCCCCCCCCCCCCCCCCCCFAAEA- -ACEEECCCCCCCCCCCCCCCCCCFEECA- --ACCCCCCCCCCCCCCCCCCCCCECCB-- ---ABACCCCCCCCCCCCCCCCCCAAA--- ------ACCCCCCCCCCCCCCCCB------ ------ACCCCCCCCCCCCCCCCB------ -------ACCCCCCCCCCCCCCA------- --------ACCCCCCCCCCCBB-------- ---------AACCCCCCCCAB--------- -----------AACCCCAA----------- -------------AADD------------- 
------------ABBBBB------------ ----------AAAAAABBBA---------- --------AAAAAAAAAAAAA--------- -------AAAAAAAAAAAAAAA-------- ------AAAAAAAAAAAAAAAAA------- ---AAAAAAAAAAAAAAAAAAAAABAA--- --AAAAAAAAAAAAAAAAAAAAAAAAAB-- -DAAAAAAAAAAAAAAAAAAAAAAAAAAA- AABBAAAAAAAAAAAAAAAAAAAAAAAAA- AABBAAAAAAAAAAAAAAAAAAAAAAAAA- ABAAAAAAAAAAAAAAAAAAAAAAAABAD- ABAAAAAAAAAAAAAAAAAAAAAAAABAD- -BAAAAAAAAAAAAAAAAAAAAAAAAAAD- --AAAAAAAAAAAAAAAAAAAAAAAAAA-- ---ADDAAAAAAAAAAAAAAAAAAADD--- ------AAAAAAAAAAAAAAAAAA------ ------BAAAAAAAAAAAAAAAAA------ -------AAAAAAAAAAAAAAAA------- --------AAAAAAAAAAAABB-------- ---------BAAAAAAAAAAB--------- -----------AABBBAAD----------- -------------BBDD------------- 
------------ABBBB------------- ---------BAAAAAABBBA---------- --------BAAAAAAAAAAAA--------- -------BBAAAAAAAAAAAAA-------- ------DAAAAAAAAAAAAAAAA------- -----DAAAAAAAAAAAAAAAAAB------ -----DAAAAAAAAAAAAAAAAAA------ -----AAAAAAAAAAAAAAAAAAA------ ----AAAAAAAAAAAAAAAAAAAAA----- ----AAAAAAAAAAAAAAAAAAAAA----- ----AAAAAAAAAAAAAAAAAAAAA----- ----AAAAAAAAAAAAAAAAAAAAA----- ----AAAAAAAAAAAAAAAAAAAAA----- -----AAAAAAAAAAAAAAAAAAA------ -----DAAAAAAAAAAAAAAAAAA------ -----AAAAAAAAAAAAAAAAAAA------ ------AAAAAAAAAAAAAAAAA------- -------AAAAAAAAAAAAAAA-------- --------AAAAAAAAAAAAA--------- ---------AAAAAAAAAAA---------- ------------ABBBA------------- ------------------------------ 
-----------BBBBBBA------------ ---------BBBBBBBAAAA---------- --------BBBBBBBBAAAAB--------- -------AAAAAAAAAAAAABB-------- ------AAAAAAAAAAAAAAAAA------- -----DAAAAAAAAAAAAAAAAAA------ -----DAAAAAAAAAAAAAAAAAA------ ----AAAAAAAAAAAAAAAAAAAAA----- ----AAAAAAAAAAAAAAAAAAAAA----- ----AAAAAAAAAAAAAAAAAAAAA----- ----AAAAAAAAAAAAAAAAAAAAA----- ----AAAAAAAAAAAAAAAAAAAAA----- ----BAAAAAAAAAAAAAAAAAAAA----- ----BAAAAAAAAAAAAAAAAAAAA----- -----AAAAAAAAAAAAAAAAAAA------ -----AAAAAAAAAAAAAAAAAAA------ ------AAAAAAAAAAAAAAAAD------- -------AAAAAAAAAAAAAAA-------- --------AAAAAAAAAAAAA--------- ---------AAAAAAAAAAA---------- -----------AABBBAD------------ ------------------------------ 
-----------BBBBBAA------------ ---------BBBBBBBAAAA---------- --------BBBBBBBBAAAAA--------- -------AAAAAAAAAAAAAAA-------- ------AAAAAAAAAAAAAAAAA------- -----AAAAAAAAAAAAAAAAAAB------ -----AAAAAAAAAAAAAAAAAAA------ ----AAAAAAAAAAAAAAAAAAAAA----- ----BAAAAAAAAAAAAAAAAAAAA----- ----BAAAAAAAAAAAAAAAABBBB----- ----BAAAAAAAAAAAAAAAABBBB----- ----AAAAAAAAAAAAAAAAAAAAA----- ----BAAAAAAAAAAAAAAAAAAAA----- ----BAAAAAAAAAAAAAAAAAAAA----- -----BAAAAAAAAAAAAAAAAAA------ -----BAAAAAAAAAAAAAAAAAD------ ------AAAAAAAAAAAAAAAAA------- -------AAAAAAAAAAAAAAA-------- --------AAAAAAAAAAAAA--------- ---------BBBAAAAAAAA---------- -----------BAADDAA------------ ------------------------------ 
-----------BBBBBAA------------ ---------BBBBBBBAAAA---------- --------BBBBBBBBAAABB--------- -------AAAAAAAAAAAABBB-------- ------DAAAAAAAAAAAABBBB------- -----AAAAAAAAAAAAAAAAAAA------ -----AAAAAAAAAAAAAAAAAAA------ ----AAAAAAAAAAAAAAAAAAAAA----- ----DAAAAAAAAAAAAAAAAAAAA----- ----DAAAAAAAAAAAAAAAABBBB----- ----BAAAAAAAAAAAAAAAABBBB----- ----AAAAAAAAAAAAAAAAAAAAA----- ----AAAAAAAAAAAAAAAAAAAAA----- ----AAAAAAAAAAAAAAAAAAAAA----- -----BAAAAAAAAAAAAAAAAAA------ -----BAAAAAAAAAAAAAAAAAD------ ------AAAAAAAAAAAAAAAAA------- -------DAAAAAAAAAAAAAA-------- --------AAAAAAAAAAAAA--------- ---------BBBAAAAAAAB---------- -----------BAAAAAA------------ ------------------------------ 
------------BBBBB------------- ---------BBBBBBBBBBA---------- --------DBBBBBBBBBBBB--------- -------BAAAAAAAAAAABBB-------- ------BBAAAAAAAAAAABBBB------- -----AAAAAAAAAAAAAAAAAAA------ -----AAAAAAAAAAAAAAAAAAA------ -----DAAAAAAAAAAAAAAAAAA------ ----DAAAAAAAAAAAAAAAAAAAA----- ----AAAAAAAAAAAAAAAAABBBB----- ----AAAAAAAAAAAAAAAAABBBB----- ----AAAAAAAAAAAAAAAAAAAAA----- ----AAAAAAAAAAAAAAAAAAAAA----- -----AAAAAAAAAAAAAAAAAAA------ -----BAAAAAAAAAAAAAAAAAA------ -----BAAAAAAAAAAAAAAAABB------ ------AAAAAAAAAAAAAAAAB------- -------DDDAAAAAAAAAABB-------- --------DDAAAAAAAAAAB--------- ---------BBBAAAAAAAA---------- ------------AABBB------------- ------------------------------ 
-------------AAA-------------- ----------AAAAAABBB----------- --------DDBAAAAABBBBB--------- -------BAAAAAAAAAAABBB-------- ------BBAAAAAAAAAAABBBB------- ------AAAAAAAAAAAAAAAAA------- -----AAAAAAAAAAAAAAAAAAA------ -----AAAAAAAAAAAAAAAAAAA------ -----AAAAAAAAAAAAAAAAAAA------ ----AAAAAAAAAAAAAAAAABBBB----- ----AAAAAAAAAAAAAAAAABBBB----- ----AAAAAAAAAAAAAAAAAAAAA----- -----AAAAAAAAAAAAAAAAAAA------ -----DAAAAAAAAAAAAAAAAAA------ -----DAAAAAAAAAAAAAAAAAA------ ------AAAAAAAAAAAAAAAAA------- ------AAAAAAAAAAAAAAAAA------- -------DDDAAAAAAAAAABB-------- --------DDAAAAAAAAAAB--------- ----------AABBAAADD----------- -------------BAA-------------- ------------------------------ 
------------------------------ -----------AAAAABB------------ ---------DBAAAAABBBB---------- --------AAAAAAAAAAABB--------- -------DAAAAAAAAAAABBB-------- ------DDAAAAAAAAAAAAAAA------- ------AAAAAAAAAAAAAAAAA------- -----AAAAAAAAAAAAAAAAAAA------ -----AAAAAAAAAAAAAAAAAAA------ -----AAAAAAAAAAAAAAAABBB------ -----AAAAAAAAAAAAAAAABBB------ -----AAAAAAAAAAAAAAAAAAA------ -----AAAAAAAAAAAAAAAAAAA------ -----DAAAAAAAAAAAAAAAAAD------ ------AAAAAAAAAAAAAAAAA------- ------AAAAAAAAAAAAAAAAA------- -------DAAAAAAAAAAAAAA-------- --------DDAAAAAAAAAAA--------- ---------DAAAAAAAAAA---------- -----------ABBAAAD------------ ------------------------------ ------------------------------ 
------------------------------ ------------AAAAB------------- ----------AAAAAABBB----------- --------AAAAAAAAAAAAA--------- -------DAAAAAAAAAAAAAA-------- -------DAAAAAAAAAAAAAA-------- ------DDDAAAAAAAAAAAAAA------- ------DDDAAAAAAAAAAAAAA------- -----DDDDAAAAAAAAAAAAAAA------ -----DDDDAAAAAAAAAAAABBB------ -----DAAAAAAAAAAAAAAABBB------ -----DAAAAAAAAAAAAAAAAAD------ -----DAAAAAAAAAAAAAAAAAD------ ------BAAAAAAAAAAAAAAAA------- ------BAAAAAAAAAAAAAAAA------- -------BAAAAAAAAAAAAAA-------- -------DAAAAAAAAAAABBA-------- --------AAAAAAAAAAABB--------- ----------DDDAAAAAA----------- ------------DAAAA------------- ------------------------------ ------------------------------ 
------------------------------ ------------------------------ -----------BBAAAAA------------ ---------AABBAAAAAAA---------- --------AAAAAAAAAAAAA--------- -------AAAAAAAAAAAAABB-------- -------DDAAAAAAAAAAABB-------- ------DDDAAAAAAAAAABBBB------- ------DDDAAAAAAAAAABBBB------- ------DDDAAAAAAAAAABBBB------- ------AAAAAAAAAAAAAAABB------- ------AAAAAAAAAAAAABBBB------- ------AAAAAAAAAAAAABBBB------- ------BAAAAAAAAAAAABBBB------- -------AAAAAAAAAAAAAAB-------- -------BAAAAAAAAAAAAAB-------- --------AAAAAAAAAAABB--------- ---------AAADDAAABBB---------- -----------DDDAAAB------------ ------------------------------ ------------------------------ ------------------------------ 
------------------------------ ------------------------------ ------------------------------ -----------BBAABBB------------ ---------AAAAAAAAAAA---------- --------AAAAAAAAAAAAB--------- --------DAAAAAAAAAADD--------- -------DDAAAAAAAAAABBB-------- -------DDAAAAAAAAAABBB-------- -------DDAAAAAAAAAABBB-------- -------BBAAAAAAAAAAAAB-------- -------BBAAAAAAAAAABBB-------- -------AAAAAAAAAAAABBB-------- -------ADDAAAAAAAAABBB-------- --------DDAAAAAAAAAAA--------- --------AAAAAAAAAAAAA--------- ---------AAAAAAAAADA---------- -----------ADDAAAA------------ ------------------------------ ------------------------------ ------------------------------ ------------------------------ 
------------------------------ ------------------------------ ------------------------------ ------------------------------ -----------BBABAAA------------ ----------AAAABAAAA----------- ---------AAAAAAAAAAD---------- --------ABAAAAAAAAABB--------- --------BBAAAAAAAAABB--------- --------BAAAAAAAAAABB--------- --------BAAAAAAAAAABB--------- --------BAAAAAAAAAABB--------- --------AAAAAAAAAAABB--------- --------DDAAAAAAAABBB--------- ---------DAAAAAAAABB---------- ----------AAAAAAAAA----------- -----------AADAAAA------------ ------------------------------ ------------------------------ ------------------------------ ------------------------------ ------------------------------ 
------------------------------ ------------------------------ ------------------------------ ------------------------------ ------------------------------ ------------AABAA------------- -----------AAABBBD------------ ----------AAAABBBAA----------- ---------BBBAABBBAAB---------- ---------ABBAAAAAAAB---------- ---------AAAAAAAAAAB---------- ---------AAAAAAAAAAB---------- ---------ABBBAADDAAB---------- ----------BBBAADDAB----------- -----------BAAADDA------------ ------------AAAAD------------- ------------------------------ ------------------------------ ------------------------------ ------------------------------ ------------------------------ ------------------------------ 
------------------------------ ------------------------------ ------------------------------ ------------------------------ ------------------------------ ------------------------------ ------------------------------ -------------DDB-------------- ------------ADDBB------------- -----------BADDADA------------ -----------BAAAADA------------ -----------AAAAADA------------ ------------BAADD------------- -------------AAD-------------- ------------------------------ ------------------------------ ------------------------------ ------------------------------ ------------------------------ ------------------------------ ------------------------------ ------------------------------ 
