model
size = 32 16 5, scale = 0.05, origin = -y
material 
  colors = A:#CCC B:#3098CC C:#202020 D:#FCCC00 E:#FCFCFC F:#A80000 G:#ECECEC H:#545454 I:#747474 J:#444 K:#B8B8B8 L:#888
voxels
5-2E2A2E24-E8AE21-E10AE6-4C-6C2-E5A2-5AE5-4C-6C2-4AE4-E4A15-B-E3AE6-E3AE2(-H)-F3(-H)-2H-E3A8-3AE10-3J3-2(3A10-3A-J2-G2I2-J3-J2-)E3A8-3AE10-3J3-E3AE6-E3AE2(-H)-F3(-H)-2H2-4AE4-E4A15-B2-E5A2-5AE5-4C-6C3-E10AE6-4C-6C4-E8AE24-2E2A2E25-E2-2A2-E22-E-8A-E2-15D2-E-10A-E-7C8BC2-12A2-7C8BCE4A-4F-4AE12D4B-3A-F4-F-3A-4B2D2K8B-3AF6-F3A-4B2D2K8B2(4AF6-F4AB4G2I2G7B)-3AF6-F3A-4B2D2K8B-3A-F4-F-3A-4B2D2K8BE4A-4F-4AE12D4B2-12A2-7C8BC-E-10A-E-7C8BC2-E-8A-E2-15D5-E2-2A2-E24-E2-2A2-E22-E-8A-E19-E-10A-E-7C8BC2-12A2-7C8BCE4A-4F-4AED-10D4B-3A-F4-F-3A-4BDL2K6BF2-3AF6-F3A-B3IJL2K6B2(F-4AF6-F4AB4G2I2G5B)F2-3AF6-F3A-B3IJL2K6BF2-3A-F4-F-3A-4BDL2K6BF-E4A-4F-4AE12D4B2-12A2-7C8BC-E-10A-E-7C8BC2-E-8A-E22-E2-2A2-E24-E2-2A2-E22-E-8A-E2-15D2-E-10A-E-7C8BC2-12A2-7C8BCE4A-4F-4AE12D4B-3A-F4-F-3A-4B2D2K8B-3AF6-F3A-4B2D2K8B2(4AF6-F4AB4G2I2G7B)-3AF6-F3A-4B2D2K8B-3A-F4-F-3A-4B2D2K8BE4A-4F-4AE12D4B2-12A2-7C8BC-E-10A-E-7C8BC2-E-8A-E2-15D5-E2-2A2-E25-2E2A2E24-E8AE21-E10AE5-5C-6C2-E5A2-5AE4-5C-6C2-4AE4-E4A15-B-E3AE6-E3AE2(-H)-F3(-H)-2H-E3A8-3AE10-3J3-2(3A10-3A-J2-G2I2-J3-J2-)E3A8-3AE10-3J3-E3AE6-E3AE2(-H)-F3(-H)-2H2-4AE4-E4A15-B2-E5A2-5AE4-5C-6C3-E10AE5-5C-6C4-E8AE24-2E2A2E21-
