model
size = 32 16 7, scale = 0.05, origin = -y
material 
  colors = A:#CCC B:#747474 C:#98CCFC D:#FCFCFC E:#B80000 F:#DCDCDC G:#ECECEC
voxels
176-15F210-14G102-2D2A2D24-D8AD21-D10AD19-D12AD-16B-4AD4-D4A-16BD3AD6-D3AD15FBD3A8-3AD2(15EB4A8-4A)16BD3A8-3ADB14CBD3AD6-D3ADB14CB-4AD4-D4A-B14CB-D12AD-B14CB2-D10AD2-16B3-D8AD24-2D2A2D25-D2-2A2-D22-D-8A-D19-D-10A-D19-12A2-B15-D4A-4D-4AD16B-3A-D4-D-3A16-B-3AD6-D3A-15E-4AD6-D4A15EB4AD6-D4A15B2-3AD6-D3A-B14CB-3A-D4-D-3A-B14C-D4A-4D-4ADB14CB2-12A2-B14CB-D-10A-D-B17-D-8A-D22-D2-2A2-D24-D2-2A2-D22-D-8A-D19-D-10A-D19-12A2-16BD4A-4D-4AD16B-3A-D4-D-3A18-3AD6-D3A-14E2-4AD6-D4A15E-4AD6-D4A14B3-3AD6-D3A-B14C2-3A-D4-D-3A-B13C2-D4A-4D-4ADB14C3-12A2-B14CB-D-10A-D-16B2-D-8A-D22-D2-2A2-D24-D2-2A2-D22-D-8A-D19-D-10A-D19-12A2-B15-D4A-4D-4AD16B-3A-D4-D-3A16-B-3AD6-D3A-15E-4AD6-D4A15EB4AD6-D4A15B2-3AD6-D3A-B14CB-3A-D4-D-3A-B14C-D4A-4D-4ADB14CB2-12A2-B14CB-D-10A-D-B17-D-8A-D22-D2-2A2-D25-2D2A2D24-D8AD21-D10AD19-D12AD-16B-4AD4-D4A-16BD3AD6-D3AD15FBD3A8-3AD2(15EB4A8-4A)16BD3A8-3ADB14CBD3AD6-D3ADB14CB-4AD4-D4A-B14CB-D12AD-B14CB2-D10AD2-16B3-D8AD24-2D2A2D197-15F210-14G97-
