model
size = 32 16 7, scale = 0.05, origin = -y
material 
  colors = A:#545454 B:#747474 C:#30CCFC D:#888 E:#EC0000
voxels
86-2A56-15A17-2(A2-8A2-A18-)2(A2-A6-A2-A18-)2(A2-8A2-A18-)15A55-2A77-2D2B2D24-D8BD21-D10BD8-2A9-D5B2-5BD-15A2-4BD4-D4B-15A-D3BD6-D3BDA2E11A2-D3B8-3BDA2E11A2(2-3B10-3BA2EA6C4A)2-D3B8-3BDA2E11A2-D3BD6-D3BDA2E11A3-4BD4-D4B-15A2-D5B2-5BD-15A3-D10BD8-2A11-D8BD24-2D2B2D25-D2-2B2-D22-D-8B-D19-D-10B-D7-2A10-12B7-4A7-D4B-4C-4BD5C4A7C-3B-C4-C-3B-16A-3BC6-C3B-2(16A4BC6-C4B)16A-3BC6-C3B-16A-3B-C4-C-3B-16AD4B-4C-4BD5C4A7C2-12B7-4A8-D-10B-D7-2A10-D-8B-D22-D2-2B2-D24-D2-2B2-D22-D-8B-D19-D-10B-D7-2A10-12B7-4A7-D4B-4C-4BD5C4A7C-3B-C4-C-3B-14AE2-3BC6-C3B-2(14AE-4BC6-C4B)14AE2-3BC6-C3B-14AE2-3B-C4-C-3B-14AE-D4B-4C-4BD5C4A7C2-12B7-4A8-D-10B-D7-2A10-D-8B-D22-D2-2B2-D24-D2-2B2-D22-D-8B-D19-D-10B-D7-2A10-12B7-4A7-D4B-4C-4BD5C4A7C-3B-C4-C-3B-16A-3BC6-C3B-2(16A4BC6-C4B)16A-3BC6-C3B-16A-3B-C4-C-3B-16AD4B-4C-4BD5C4A7C2-12B7-4A8-D-10B-D7-2A10-D-8B-D22-D2-2B2-D25-2D2B2D24-D8BD21-D10BD8-2A9-D5B2-5BD-15A2-4BD4-D4B-15A-D3BD6-D3BDA2E11A2-D3B8-3BDA2E11A2(2-3B10-3BA2EA6C4A)2-D3B8-3BDA2E11A2-D3BD6-D3BDA2E11A3-4BD4-D4B-15A2-D5B2-5BD-15A3-D10BD8-2A11-D8BD24-2D2B2D107-2A56-15A17-2(A2-8A2-A18-)2(A2-A6-A2-A18-)2(A2-8A2-A18-)15A55-2A72-
