model
size = 32 16 8, scale = 0.05, origin = -y
material 
  colors = A:#545454 B:#888 C:#747474 D:#30CCFC E:#EC0000
voxels
112-15A17-8(A10-2A19-)15A103-4C26-8C23-10C21-2(5C2-)15A2-4C6-4C-15A2-3C8-3C-15A2-3C8-4C2A8-3A3-2(3C10-3C2A8-5A-)4C8-4C2A8-3A4-3C8-4C15A2-4C6-4C-15A3-2(5C2-)15A4-10C23-8C26-4C27-2C2B2C24-C8BC21-C10BC2-16D-C12BC-15A2-4BC4-C4B-15A-C3BC6-C3BC15A-C3B8-3BC2A8-3A3-2(4B8-4B15A-)C3B8-3BC2A8-3A3-C3BC6-C3BC15A2-4BC4-C4B-15A2-C12BC-15A3-C10BC2-16D3-C8BC24-2C2B2C25-C2-2B2-C22-C-8B-C19-C-10B-C6-3D10-12B2-15A-C4B-4D-4BC15AE-3B-D4-D-3B-15AE-3BD6-D3B-2A8E2(5AE4BD6-D4B2A8D)5AE-3BD6-D3B-2A8E5AE-3B-D4-D-3B-15AEC4B-4D-4BC15AE2-12B2-15A2-C-10B-C6-3D10-C-8B-C22-C2-2B2-C24-C2-2B2-C22-C-8B-C19-C-10B-C6-3D10-12B2-15A-C4B-4D-4BC15AE-3B-D4-D-3B-15AE-3BD6-D3B-2A8E2(5AE4BD6-D4B2A8D)5AE-3BD6-D3B-2A8E5AE-3B-D4-D-3B-15AEC4B-4D-4BC15AE2-12B2-15A2-C-10B-C6-3D10-C-8B-C22-C2-2B2-C25-2C2B2C24-C8BC21-C10BC2-16D-C12BC-15A2-4BC4-C4B-15A-C3BC6-C3BC15A-C3B8-3BC2A8-3A3-2(4B8-4B15A-)C3B8-3BC2A8-3A3-C3BC6-C3BC15A2-4BC4-C4B-15A2-C12BC-15A3-C10BC2-16D3-C8BC24-2C2B2C27-4C26-8C23-10C21-2(5C2-)15A2-4C6-4C-2(15A2-3C8-4C)2A8-3A3-2(3C10-3C2A8-5A-)4C8-4C2A8-3A4-3C8-4C15A2-4C6-4C-15A3-2(5C2-)15A4-10C23-8C26-4C134-15A17-8(A10-2A19-)15A97-
