model
size = 32 16 7, scale = 0.05, origin = -y
material 
  colors = A:#CCC B:#0CC C:#DCDCDC D:#90F E:#FF0 F:#C93 G:#0C9 H:#F0F
voxels
16-B31-3(2B30-)2B-GC27-2B-2C27-2B-B28-3B-2C2G5-2C17-2B2-4C2-B21-2B-3C4-2CB19-2B-C8-3C17-3(2B30-)2B11-C18-B20-2B2A2B5-D18-B8AB3-2D16-B10AB2-2D15-B5A2-5AB-DC3-B-C9-4AB4-B4A-DGC-G3C8-B3AB6-B3ABD6C5-CD2-B3A8-3AB2D5BG8-3A10-3A3DC-2C2-2D2C3-3A10-3A2D5C2F6B-B3A8-3AB2D7C2E2B3-B3AB6-B3AB2D-3C-2CE5C2-4AB4-B4A-2D3-2C5-EC2E-B5A2-5AB-2D3-3C4-3EC2-B10AB2-2D3-H-2H4-C5-B8AB3-2D19-2B2A2B5-D19-B2-2A2-B4-D17-B-8A-B2-2D15-B-10A-B-2D16-12A2-2D5-H8-B4A-4B-4AB2D15-3A-B4-B-3A-2DC2-F-C4-2D3-3AB6-B3AB2D5BG3-EG3-4AB6-B4A3D3-F-DEDC4-4AB6-B4ADFC2-3FC4B4-3AB6-B3AFDF3C-4C2B5-3A-B4-B-3ACD2F2C2FC2F5C-B4A-4B-4ABDE-4C4-4C3-12AH-2D2-E2C5-2C3-B-10A-B-2D16-B-8A-B2-2D10-C7-B2-2A2-B4-D12-HC5-B2-2A2-B4-D17-B-8A-B2-2D15-B-10A-B-2D16-12A2-2D14-B4A-4B-4AB2D2-2E11-3A-B4-B-3A-2D3-C-E9-3AB6-B3A-2D3-B5-G4-4AB6-B4A3D4-4D5-4AB6-B4AD2C4-3C2B5-3AB6-B3ACD3C2-F2C3B3-B-3A-B4-B-3ACD3C2FC2F4C3-B4A-4B-4ABDE-2F5-FC6-12AH-2D-BE5-2F5-B-10A-B-2D2-C6-2F5-B-8A-B2-2D2-E6-EC7-B2-2A2-B4-D19-B2-2A2-B4-D17-B-8A-B2-2D15-B-10A-B-2D16-12A2-2D-CE11-B4A-4B-4AB2D2-EC11-3A-B4-B-3A-2D3-C11-3AB6-B3A-2D-B12-4AB6-B4A2D3C4-D6-4AB6-B4ADHC-C4FC7-3AB6-B3ACD8C4B-2B-3A-B4-B-3ACD7C5-2C-B4A-4B-4ABDC3-6C7-12AH-2D2-E2-4C6-B-10A-B-2D2-E2-3HC7-B-8A-B2-2D2-E5-H9-B2-2A2-B4-D20-2B2A2B5-D18-B8AB3-2D16-B10AB2-2D15-B5A2-5AB-2D15-4AB4-B4A-2D14-B3AB6-B3AB2D-C5-2D5-B3A8-3AB2D-B4-FG6-3A10-3A2DH2-C2(-2G)3C-3A10-3A2D5-4C4B-B3A8-3AB2D-2H-2C4-5B3AB6-B3AB2DH2-B3C-5GC-4AB4-B4A-2D3-B3E4C4-B5A2-5AB-2D2-B2-6C5-B10AB2-2D5-4CF2C5-B8AB3-2D6-C4E2F6-2B2A2B5-D31-B31-2(2B30-)2(2B8-C21-)2B-C5-CD21-2B7-CG21-2B5-6G2F17-2B5-6C2B17-2B5-2C23-2B4-2C2G22-2B5-3E4C18-2B-C3-6C19-2B5-4C2-2C17-2B6-H6E17-B9-C2-2C-
