model
size = 32 16 7, scale = 0.05, origin = -y
material 
  colors = A:#98CCFC B:#CCC C:#9800FC D:#FCFC00 E:#0CC F:#CC9830 G:#30FCFC H:#00CC98 I:#FC00FC
voxels
16-G31-14(2G30-)G21-4A6-C19-8A4-2C17-10A3-2C16-2(5A2-)2C15-4A6-4A-2C3-E4-FH5-3A8-3A-2C2-DE5-D5-3A8-4A2C2D3-E2-D5-3A10-3A2C3-4EH3-H2-3A10-3A2C4E2-EH6-4A8-4A2C3-E11-3A8-4A2C15-4A6-4A-2C16-2(5A2-)2C17-10A3-2C18-8A4-2C20-4A6-C20-2A2B2A5-C18-A8BA3-2C16-A10BA2-2C9-H5-A12BA-2C7-2(H-)HF2-4BA4-A4B-2C5-A-2H-H2A-A3BA6-A3BA2C2-3CD3-C4-A3B8-3BA5C4-4C3-4B8-4B5C3-F-CDC3-4B8-4BCF3CA-2A2-2CA2-A3B8-3BACFE-CD2A2H4-3A3BA6-A3BACF-D4-2HA6-4BA4-A4B-CD6-H8-A12BA-2C16-A10BA2-2C17-A8BA3-2C19-2A2B2A5-C19-A2-2B2-A4-C17-A-8B-A2-2C15-A-10B-A-2C7-H-A2-A3-12B2-2C7-2(A-)AE-A4B-4D-4BA2C7-4A2E2-3B-D4-D-3BI2C5I4FA5-3BD6-D3BA2C4A3-3AE3-4BD6-D4B2C2FA2-3FA3E2-4BD6-D4BCA2-5A2F5E-3BD6-D3B-CAD-2D4A2-E4-3B-D4-D-3BDCADA5-2A5-A4B-4D-4BACD-D14-12B2-2C15-A-10B-A-2C16-A-8B-A2-2C18-A2-2B2-A4-C19-A2-2B2-A4-C17-A-8B-A2-2C15-A-10B-A-2C7-H-A6-12B2-2C7-A6-A4B-4D-4BA2C6-EA3-2E2-3B-D4-D-3BE2C6E3A3E-E-3BD6-D3BA2C4A2-F2A2E3-4BD6-D4B2C2F3A-4AE3-4BD6-D4BCI2-7A2DE3-3BD6-D3BAC2A2-3A-D2-AE3-3B-D4-D-3BACAD2(4-2A)-A4B-4D-4BACA6-A9-12B2-2C15-A-10B-A-2C16-A-8B-A2-2C18-A2-2B2-A4-C20-2A2B2A5-C18-A8BA3-2C16-A10BA2-2C7-H-H5-A12BA-2C6-EA-H5-4BA4-A4B-2C6-3A-3H-A3BA6-A3BA2C6F2A4-3A3B8-3BA2C4A2FA2F3A2-4B8-4B2C-2F2A2FA2F4A4B8-4B2C2-D3A-2AD5A3B8-3BA2CI2-A-D5-4A3BA6-A3BA2C3-D-2D5-A2-4BA4-A4B-2C3-D-AD8-A12BA-2C16-A10BA2-2C17-A8BA3-2C19-2A2B2A5-C21-4A6-E19-8A4-2E17-10A3-2E7-D-D2-A3-2(5A2-)2E7-2(D-)2A2-4A6-4A-2E6-3D3A3-3A8-4A2E2A2I-6A4-3A8-4A2ED-I2F5-F3-3A10-3A2E3-4A2-I-6A10-3A2E3-2I2A3-IDAD4A8-4A2E3-D-D9-3A8-4A2E15-4A6-4A-2E16-2(5A2-)2E17-10A3-2E18-8A4-2E20-4A6-E15-
