model
size = 32 16 7, scale = 0.05, origin = -y
material 
  colors = A:#36563C B:#0F4C3A C:#535953 D:#777 E:#227D51 F:#465D4C
voxels
147-5E-E31-E30-E31-2E69-E26-4E-E25-E2-2E135-2B2F2B24-B8AB21-B10AB19-B12AB18-4AB4-B4A-12B-BE-B3AB6-B3A15B-2B3A8-3A3BE2-7B2-2BF3A8-4A2B-E-7BE-2BF3A8-4A2B-E-12B3A8-3A6BE-10B3AB6-B3A6B2-9B-4AB4-B4A-6BE-7B2-B12AB19-B10AB21-B8AB24-2B2F2B25-B2-2F2-B22-B-8A-B19-B-10A-B19-12A18-B4A-4B-4AB17-3A-B4-B-3A-15C2-3AB6-B3A-2(15C-F3AB6-B4A)15C2-3AB6-B3A-15C2-3A-B4-B-3A-15C-B4A-4B-4AB18-12A19-B-10A-B19-B-8A-B22-B2-2F2-B24-B2-2F2-B22-B-8A-B19-B-10A-B19-12A18-B4A-4B-4AB15D2-3A-B4-B-3A-16D-3AB6-B3A-2(16DF3AB6-B4A)16D-3AB6-B3A-16D-3A-B4-B-3A-16DB4A-4B-4AB15D3-12A19-B-10A-B19-B-8A-B22-B2-2F2-B24-B2-2F2-B22-B-8A-B19-B-10A-B19-12A18-B4A-4B-4AB17-3A-B4-B-3A-15C2-3AB6-B3A-2(15C-F3AB6-B4A)15C2-3AB6-B3A-15C2-3A-B4-B-3A-14C2-B4A-4B-4AB18-12A19-B-10A-B19-B-8A-B22-B2-2F2-B25-2B2F2B24-B8AB21-B10AB19-B12AB18-4AB4-B4A-12B-BE-B3AB6-B3A15B-2B3A8-3A3BE2-7B2-2BF3A8-4A2B-E-7BE-2BF3A8-4A2B-E-12B3A8-3A6BE-10B3AB6-B3A6B2-9B-4AB4-B4A-6BE-7B2-B12AB19-B10AB21-B8AB24-2B2F2B168-5E-E31-E30-E31-2E69-E26-4E-E25-E2-2E130-
