model
size = 32 16 7, scale = 0.05, origin = -y
material 
  colors = A:#5DAC81 B:#0F4C3A C:#535953 D:#777 E:#227D51 F:#465D4C
voxels
145-E10-E55-2E27-2E2-E3-4E20-2E-2E3-2E-2E27-2(E-)E27-E2-2E27-3E137-2B2F2B24-B8AB21-B10AB19-B12AB18-4AB4-B4A-3B-2B-E2B-3B2-B3AB6-B3A7BE-6BE2B3A8-3A7B-E6B-BF3A8-4A6B2E8BF3A8-4A6BE-9B3A8-3A7B2-9B3AB6-B3A17B-4AB4-B4A-15B2-B12AB19-B10AB21-B8AB24-2B2F2B25-B2-2F2-B22-B-8A-B19-B-10A-B19-12A18-B4A-4B-4A2B16-3A-B4-B-3A-B14C2-3AB6-B3A-2(B14C-F3AB6-B4A)B14C2-3AB6-B3A-B14C2-3A-B4-B-3A-B14C-B4A-4B-4A2B17-12A19-B-10A-B19-B-8A-B22-B2-2F2-B24-B2-2F2-B22-B-8A-B19-B-10A-B19-12A18-B4A-4B-4AB15D2-3A-B4-B-3A-16D-3AB6-B3A-2(16DF3AB6-B4A)16D-3AB6-B3A-16D-3A-B4-B-3A-16DB4A-4B-4AB15D3-12A19-B-10A-B19-B-8A-B22-B2-2F2-B24-B2-2F2-B22-B-8A-B19-B-10A-B19-12A18-B4A-4B-4A2B16-3A-B4-B-3A-B13C3-3AB6-B3A-2(B13C2-F3AB6-B4A)B14C2-3AB6-B3A-B14C2-3A-B4-B-3A-B14C-B4A-4B-4A2B17-12A19-B-10A-B19-B-8A-B22-B2-2F2-B25-2B2F2B24-B8AB21-B10AB19-B12AB18-4AB4-B4A-3B-2B-E2B-3B2-B3AB6-B3A7BE-6BE2B3A8-3A7B-E6B-BF3A8-4A6B2E8BF3A8-4A6BE-9B3A8-3A7B2-9B3AB6-B3A17B-4AB4-B4A-15B2-B12AB19-B10AB21-B8AB24-2B2F2B166-E10-E55-2E27-2E2-E3-4E20-2E-2E3-2E-2E27-2(E-)E27-E2-2E27-3E132-
