model
size = 32 16 8, scale = 0.05, origin = -y
material 
  colors = A:#444 B:#747474 C:#545454 D:#30FCFC E:#00FC64 F:#EC0000 G:#CCCC98
voxels
210-2(2A2-)2A22-A32-A6-2A22-2(2A2-)2A340-2(16A16-)4(4A2(2-2A)2E2A16-)16A16-16A133-2C2B2C24-C8BC21-C10BC19-C5B2-5BC18-4BC4-C4B-16AC3BC6-C3BC15A-C3B8-3BC2(4A2(2-2A)2EA-3B10-3B)4A2(2-2A)2EA-C3B8-3BC4A2(2-2A)2EA-C3BC6-C3BC15A2-4BC4-C4B-16A-C5B2-5BC19-C10BC21-C8BC24-2C2B2C25-C2-2B2-C22-C-8B-C19-C-10B-C3-2(2A2-)2A6-12B4-2(2A2-)2A4-C4B-4A-4BC4A2F2(2A2-)2A-3B-A4-A-3B-4A2F2(2A2-)A2-3BA6-A3B-4A2(2D2A)2G2A4BA6-A4B4A2(2D2A)GF2-4BA6-A4B4A2(2D2A)GF3-3BA6-A3B-4A2(2D2A)2G2A-3B-A4-A-3B-4A2F2(2A2-)A-C4B-4A-4BC4A2F3(2A2-)12B4-2(2A2-)2A5-C-10B-C3-2(2A2-)2A6-C-8B-C22-C2-2B2-C24-C2-2B2-C22-C-8B-C19-C-10B-C3-2(2A2-)2A6-12B4-2(2A2-)2A4-C4B-4A-4BC4A2F2(2A2-)2A-3B-A4-A-3B-4A2F2(2A2-)A2-3BA6-A3B-4A2(2D2A)2G2A4BA6-A4B4A2(2D2A)GF2-4BA6-A4B4A2(2D2A)GF3-3BA6-A3B-4A2(2D2A)2G2A-3B-A4-A-3B-4A2F2(2A2-)A-C4B-4A-4BC4A2F3(2A2-)12B4-2(2A2-)2A5-C-10B-C3-2(2A2-)2A6-C-8B-C22-C2-2B2-C25-2C2B2C24-C8BC21-C10BC19-C5B2-5BC18-4BC4-C4B-16AC3BC6-C3BC15A-C3B8-3BC2(4A2(2-2A)2EA-3B10-3B)4A2(2-2A)2EA-C3B8-3BC4A2(2-2A)2EA-C3BC6-C3BC15A2-4BC4-C4B-16A-C5B2-5BC19-C10BC21-C8BC24-2C2B2C165-2(16A16-)4(4A2(2-2A)2E2A16-)16A16-16A338-2(2A2-)2A27-A2-2A26-A27-2(2A2-)2A196-
