model
size = 32 16 7, scale = 0.05, origin = -y
material 
  colors = A:#724832 B:#555 C:#C46243 D:#222 E:#566C73 F:#3C2F41 G:#AAA H:#51A8DD I:#7DB9DE J:#994639 K:#6699A1 L:#EEE
voxels
156-L-F358-2C2A2C24-C8AC21-C10AC19-C12AC-D-2D2-2D-D-5D-4AC4-C4A-16DC3AC6-C3AC16DC3A8-3AC2(D2K2F2J2I2H2C2GD4A8-4A)D2K2F2J2I2H2C2GDC3A8-3ACD2K2F2J2I2H2C2GDC3AC6-C3ACD2K2F2J2I2H2C2GD-4AC4-C4A-D2K2F2J2I2H2C2GD-C12AC-16D2-C10AC21-C8AC24-2C2A2C25-C2-2A2-C22-C-8A-C19-C-10A-C19-12A2-B-2B2-2B-B-5BC4A-4C-4AC15B2-3A-C4-C-3A-15B2-3AC6-C3A-16B4AC6-C4A15B-4AC6-C4A15B2-3AC6-C3A-16B-3A-C4-C-3A-15B-C4A-4C-4AC15B3-12A2-B-2B-B2-B3-B2-B-C-10A-C19-C-8A-C22-C2-2A2-C24-C2-2A2-C22-C-8A-C19-C-10A-C19-12A2-E-2E2-2E-E-5EC4A-4C-4AC15E2-3A-C4-C-3A-15E2-3AC6-C3A-16E4AC6-C4A15E-4AC6-C4A15E2-3AC6-C3A-16E-3A-C4-C-3A-15E-C4A-4C-4AC15E3-12A2-E-2E-E2-E3-E2-E-C-10A-C19-C-8A-C22-C2-2A2-C24-C2-2A2-C22-C-8A-C19-C-10A-C19-12A2-B-2B2-2B-B-5BC4A-4C-4AC15B2-3A-C4-C-3A-15B2-3AC6-C3A-16B4AC6-C4A15B-4AC6-C4A15B2-3AC6-C3A-16B-3A-C4-C-3A-15B-C4A-4C-4AC15B3-12A2-B-2B-B2-B3-B2-B-C-10A-C19-C-8A-C22-C2-2A2-C25-2C2A2C24-C8AC21-C10AC19-C12AC-D-2D2-2D-D-5D-4AC4-C4A-16DC3AC6-C3AC16DC3A8-3AC2(D2K2F2J2I2H2C2GD4A8-4A)D2K2F2J2I2H2C2GDC3A8-3ACD2K2F2J2I2H2C2GDC3AC6-C3ACD2K2F2J2I2H2C2GD-4AC4-C4A-D2K2F2J2I2H2C2GD-C12AC-16D2-C10AC21-C8AC24-2C2A2C177-L-F353-
