model
size = 32 18 7, scale = 0.05, origin = -y
material 
  colors = A:#050 B:#CCC C:#960 D:#FFF E:#070 F:#C09
voxels
16-A31-2A2(2-A-2E)18-2A2-2AE3-2AE19-2(2A30-)2A2-C-C3-C-C19-3A-CAC-A2(-C)-A17-16A16-2(2A30-)16A16-3A-CAC-A2(-C)-A17-2A2-C-C3-C-C19-2(2A30-)2A2-2AE3-2AE19-2A2(2-A-2E)18-A31-A20-2D2B2D5-2A2(-A)3-A-2(A3-)D8BD3-2A2-2A-5A-3A2-D10BD2-5AC-C3AC-C3-D12BD-2A2-A5-A6-4BD4-D4B-2A-CA-C2-CA-C3-D3BD6-D3BD2A-CA4-CA5-D3B8-3BD16A2(4B8-4B2A13C-)D3B8-3BD16AD3BD6-D3BD2A-CA4-CA6-4BD4-D4B-2A-CA-C2-CA-C4-D12BD-2A2-A5-A7-D10BD2-5AC-C3AC-C5-D8BD3-2A2-2A-5A-3A5-2D2B2D5-2A2(-A)3-A-A3-A16-A31-A19-D2-2B2-D4-2A2(-A)E2-A-AE5-D-8B-D2-2AE2ACA-E2ACA2-A-D-10B-D-3A5C2A4C2A2-12B2-2A2(3-C-C)2-D4B-4D-4BD2A-C2(-5C)-3B-D4-D-3B-2A3-2(3C-C-)3BD6-D3B17A2(4BD6-D4B16A)-3BD6-D3B17A-3B-D4-D-3BE2A3-3C-C-3C-CD4B-4D-4BD2A-C2(-5C)2-12B2-2A2(3-C-C)3-D-10B-D-3A5C2A4C2A2-D-8B-D2-2AE2ACA-E2ACA2-A4-D2-2B2-D4-2A2(-A)E2-A-AE19-A31-A19-D2-2B2-D4-2A-E5-E8-D-8B-D2-2A4E-3A2E-3A-D-10B-D-2A2(2-4E)4-12B2-3A3-C-A3-C3-D4B-4D-4BD2A12C3-3B-D4-D-3B-2A-C2(-3C-A)-3BD6-D3B17A4BD6-D4B14AF-4BD6-D4B14AF2-3BD6-D3B17A-3B-D4-D-3B3A-C2(-3C-A)D4B-4D-4BD2A12C4-12B2-3A3-C-A3-C4-D-10B-D-2A2(2-4E)4-D-8B-D2-2A4E-3A2E-3A4-D2-2B2-D4-2A-E5-E22-A31-A19-D2-2B2-D4-2A2(-A)E2-A-AE5-D-8B-D2-2AE2ACA-E2ACA2-A-D-10B-D-3A5C2A4C2A2-12B2-2A2(3-C-C)2-D4B-4D-4BD2A-C2(-5C)-3B-D4-D-3B-2A3-2(3C-C-)3BD6-D3B17A2(4BD6-D4B16A)-3BD6-D3B17A-3B-D4-D-3BE2A3-3C-C-3C-CD4B-4D-4BD2A-C2(-5C)2-12B2-2A2(3-C-C)3-D-10B-D-3A5C2A4C2A2-D-8B-D2-2AE2ACA-E2ACA2-A4-D2-2B2-D4-2A2(-A)E2-A-AE19-A31-A20-2D2B2D5-2A2(-A)3-A-2(A3-)D8BD3-2A2-2A-5A-3A2-D10BD2-5AC-C3AC-C3-D12BD-2A2-A5-A6-4BD4-D4B-2A-CA-C2-CA-C3-D3BD6-D3BD2A-CA4-CA5-D3B8-3BD16A2(4B8-4B2A13C-)D3B8-3BD16AD3BD6-D3BD2A-CA4-CA6-4BD4-D4B-2A-CA-C2-CA-C4-D12BD-2A2-A5-A7-D10BD2-5AC-C3AC-C5-D8BD3-2A2-2A-5A-3A5-2D2B2D5-2A2(-A)3-A-A3-A16-2(A31-)2A2(2-A-2E)18-2A2-2AE3-2AE19-2(2A30-)2A2-C-C3-C-C19-3A-CAC-A2(-C)-A17-16A16-2(2A30-)16A16-3A-CAC-A2(-C)-A17-2A2-C-C3-C-C19-2(2A30-)2A2-2AE3-2AE19-2A2(2-A-2E)18-A15-
