model
size = 32 16 8, scale = 0.05, origin = -y
material 
  colors = A:#444 B:#888 C:#30FCFC D:#00FC64 E:#545454 F:#EC0000 G:#CCCC98
voxels
210-2(2A2-)2A22-A32-A6-2A22-2(2A2-)2A340-2(16A16-)4(4A2(2-2A)2D2A16-)16A16-16A133-2A2E2A24-A8BA21-A10BA19-A12BA18-4BA4-A4B-17A3BA6-A3B16A-A3B8-3B5A2(2(2-2A)2DA-E3B8-4B4A)2(2-2A)2DA-A3B8-3B5A2(2-2A)2DA-A3BA6-A3B16A2-4BA4-A4B-16A-A12BA19-A10BA21-A8BA24-2A2E2A25-A2-2E2-A22-A-8B-A19-A-10B-A3-2(2A2-)2A6-12B4-2(2A2-)2A4-A4B-4A-4B5A2F2(2A2-)2A-3B-A4-A-3B-4A2F2(2A2-)A2-3BA6-A3B-4A2(2C2A)2G2AE3BA6-A4B4A2(2C2A)GF2-E3BA6-A4B4A2(2C2A)GF3-3BA6-A3B-4A2(2C2A)2G2A-3B-A4-A-3B-4A2F2(2A2-)A-A4B-4A-4B5A2F3(2A2-)12B4-2(2A2-)2A5-A-10B-A3-2(2A2-)2A6-A-8B-A22-A2-2E2-A24-A2-2E2-A22-A-8B-A19-A-10B-A3-2(2A2-)2A6-12B4-2(2A2-)2A4-A4B-4A-4B5A2F2(2A2-)2A-3B-A4-A-3B-4A2F2(2A2-)A2-3BA6-A3B-4A2(2C2A)2G2AE3BA6-A4B4A2(2C2A)GF2-E3BA6-A4B4A2(2C2A)GF3-3BA6-A3B-4A2(2C2A)2G2A-3B-A4-A-3B-4A2F2(2A2-)A-A4B-4A-4B5A2F3(2A2-)12B4-2(2A2-)2A5-A-10B-A3-2(2A2-)2A6-A-8B-A22-A2-2E2-A25-2A2E2A24-A8BA21-A10BA19-A12BA18-4BA4-A4B-17A3BA6-A3B16A-A3B8-3B5A2(2(2-2A)2DA-E3B8-4B4A)2(2-2A)2DA-A3B8-3B5A2(2-2A)2DA-A3BA6-A3B16A2-4BA4-A4B-16A-A12BA19-A10BA21-A8BA24-2A2E2A165-2(16A16-)4(4A2(2-2A)2D2A16-)16A16-16A338-2(2A2-)2A27-A2-2A26-A27-2(2A2-)2A196-
