model
size = 32 16 8, scale = 0.05, origin = -y
material 
  colors = A:#500 B:#800 C:#A00 D:#B00 E:#D00 F:#09F
voxels
69-6B118-3(2B10-2B18-)2B10-2B118-6B91-4B26-8B23-10B3-C5-3D-2E6-12B2-C6-2D3-E4-4B6-4B-C2-C6-5E2-3B8-4B4C-2D6-2E2-3B8-4BC2-CD3-D7-4B8-4BC-2C4-D-E2-2E-4B8-4B3C3(-D)2E3-E-4B8-4B4C2(D2-)E6-3B8-4BC2-C-4D-2E2-E2-4B6-4B-C-2C3-2D9-12B2-C-C2-2D12-10B23-8B26-4B27-2B2A2B24-B8AB21-B10AB2-C3-3(D-)E-E4-B12AB2(-C)6-E-E5-4AB4-B4A2(-C)3-2D2(-E)3-FB3AB6-B3AB4CD4-2E3-EFB3A8-3AB3C12-F4A8-4A3C2(2-D)2E5-4A8-4A2C2-2D2-D2-E4-B3A8-3AB2C4-3D-E2-E-FB3AB6-B3ABC-2C-2D-D2(2-E)2-4AB4-B4A-C3-2D4-E-E4-B12AB-C3-D-D2-E-E6-B10AB21-B8AB24-2B2A2B25-B2-2A2-B22-B-8A-B19-B-10A-B-C-2C-D2-D3-E5-12A2(2-C)2(D3-)2E2-B4A-4F-4ABC2-C3D-D3(E-)F-3A-F4-F-3A-2C-C5-2(E3-)3AF6-F3A-2C-C5-2E2-2EF4AF6-F4A2C2-2D-D2-2E4-4AF6-F4A3C2-2D-D2(-E)2-F-3AF6-F3A-3C2-D-D3-E-2E2-3A-F4-F-3A2(-C)5-D3-2E2-B4A-4F-4ABC2-C-3D2-E7-12A2-2(C-)2(D-)DE2-E4-B-10A-B19-B-8A-B22-B2-2A2-B24-B2-2A2-B22-B-8A-B19-B-10A-B-C-2C-D2-D3-E5-12A2(2-C)2(D3-)2E2-B4A-4F-4ABC2-C3D-D3(E-)F-3A-F4-F-3A-2C-C5-2(E3-)3AF6-F3A-2C-C5-2E2-2EF4AF6-F4A2C2-2D-D2-2E4-4AF6-F4A3C2-2D-D2(-E)2-F-3AF6-F3A-3C2-D-D3-E-2E2-3A-F4-F-3A2(-C)5-D3-2E2-B4A-4F-4ABC2-C-3D2-E7-12A2-2(C-)2(D-)DE2-E4-B-10A-B19-B-8A-B22-B2-2A2-B25-2B2A2B24-B8AB21-B10AB2-C3-3(D-)E-E4-B12AB2(-C)6-E-E5-4AB4-B4A2(-C)3-2D2(-E)3-FB3AB6-B3AB2C-CD4-2E3-EFB3A8-3AB3C12-F4A8-4A3C2(2-D)2E5-4A8-4A2C2-2D2-D2-E4-B3A8-3AB2C4-3D-E2-E-FB3AB6-B3ABC-2C-2D-D2(2-E)2-4AB4-B4A-C3-2D4-E-E4-B12AB-C3-D-D2-E-E6-B10AB21-B8AB24-2B2A2B27-4B26-8B23-10B3-C5-3D-2E6-12B2-C6-2D3-2E3-4B6-4B-C2-C6-4E3-3B8-4B2C3-2D6-2E-4B8-4B3C-D3-D7-4B8-4BC-2C4-D-E2-2E-4B8-4B3C3(-D)2E3-E-4B8-4B4C2(D2-)E6-3B8-4BC-C2-4D-2E2-E2-4B6-4B-C2-C3-2D9-12B2-C-C2-2D12-10B23-8B26-4B91-6B118-3(2B10-2B18-)2B10-2B118-6B85-
