model
size = 32 16 7, scale = 0.05, origin = -y
material 
  colors = A:#3064CC B:#CCC C:#EC0000 D:#DCDCDC E:#FCFCFC F:#B8B8B8 G:#888
voxels
81-A6-2(A-)AD19-12A3D29-3D17-11A2-4(2D16-2A4(-A)-2A-)2D17-5(A-)2A-2D17-11A2-2D29-3D17-12A3D17-A6-2(A-)AD39-2E2C2E24-E8BE21-E10BE3-8A2(-A)D3-E5B2-5BE2-12A3D-4BE4-E4B2-12FDC-E3BE6-E3BE-6GA4G2FC-E3B8-3BE8A2(CA)D2(FC-C2B10-3B8A2(CA)-)FC-E3B8-3BE8A2(CA)DFC-E3BE6-E3BE8A2(CA)DFC2-4BE4-E4B2-11A2FC2-E5B2-5BE2-12FDC3-E10BE3-12A3D3-E8BE4-8A2(-A)D7-2E2C2E25-E2-2C2-E22-E-8B-E19-E-10B-E2-4A4(-A)D4-12B3-12A3DE4B-4C-4BE-12ADC2-3B-C4-C-3B2-12A3D-3BC6-C3B-2(13ADC-C3BC6-C4B)13A3D-3BC6-C3B-13ADC2-3B-C4-C-3B-13ADC-E4B-4C-4BE-12A3D2-12B3-12ADC2-E-10B-E2-12A3D2-E-8B-E3-A2-4(A-)AD6-E2-2C2-E24-E2-2C2-E22-E-8B-E19-E-10B-E2-4A4(-A)D4-12B3-12A3DE4B-4C-4BE-12ADC2-3B-C4-C-3B2-12A3D-3BC6-C3B-2(13ADC-C3BC6-C4B)13A3D-3BC6-C3B-13ADC2-3B-C4-C-3B-13ADC-E4B-4C-4BE-12A3D2-12B3-12ADC2-E-10B-E2-12A3D2-E-8B-E3-A2-4(A-)AD6-E2-2C2-E24-E2-2C2-E22-E-8B-E19-E-10B-E2-4A4(-A)D4-12B3-12A3DE4B-4C-4BE-12ADC2-3B-C4-C-3B2-12A3D-3BC6-C3B-2(13ADC-C3BC6-C4B)13A3D-3BC6-C3B-13ADC2-3B-C4-C-3B-13ADC-E4B-4C-4BE-12A3D2-12B3-12ADC2-E-10B-E2-12A3D2-E-8B-E3-A2-4(A-)AD6-E2-2C2-E25-2E2C2E24-E8BE21-E10BE3-8A2(-A)D3-E5B2-5BE2-12A3D-4BE4-E4B2-8A3CADC-E3BE6-E3BE-8A3CADC-E3B8-3BE2(9A3CADC-C2B10-3B)9A3CADC-E3B8-3BE9A3CADC-E3BE6-E3BE9A3CADC2-4BE4-E4B2-8A3CADC2-E5B2-5BE2-8A3CADC3-E10BE3-12A3D3-E8BE4-8A2(-A)D7-2E2C2E102-A6-2(A-)AD19-12A2(3D17-A-A2-A-A3-A)5(3D16-2A-A2-A-A3-A)2(3D17-A-A2-A-A3-A)3D17-12A3D17-A6-2(A-)AD34-
