model
size = 32 9 7, scale = 0.05, origin = -y
material 
  colors = A:#FF3 B:#444 C:#111 D:#EEE E:#BBB F:#0F6
voxels
141-F-2F-F2-F4-F-F15-2(F-F2-)F2-F-F202-3(5D-8B-2B2-4B9-)5D-8B-2B2-4B67-37C7A19B6C26A4(6CA5EA8BA2B2A4B2A)6C26A38C26AC13A17D194A5C26A38C7A19B6C26A4(6CA5EA8BA2B2A4B2A)6C26A33C102-3(5D-8B-2B2-4B9-)5D-8B-2B2-4B208-F-2F-F2-F4-F-F15-2(F-F2-)F2-F-F100-
