model
size = 32 16 7, scale = 0.05, origin = -y
material 
  colors = A:#CCC B:#36F C:#FFF D:#007 E:#777 F:#09F
voxels
145-F9-F2-F18-F9-F2-2F27-F54-2F31-F4-4F22-2F4-2F-2F27-2(F-)F136-2C2A2C24-C8AC21-C10AC19-C12AC18-4AC4-C4A-15B-C3AC6-C3AC5B2-2B-6BC3A8-3AC5B-F2B-3B-2B4A8-4A5BF-6BF2B4A8-4A5B-F6B-2BC3A8-3AC5B2F9BC3AC6-C3AC5BF-9B-4AC4-C4A-5B2-8B2-C12AC19-C10AC21-C8AC24-2C2A2C25-C2-2A2-C22-C-8A-C19-C-10A-C19-12A18-C4A-4C-4ACB16-3A-C4-C-3A-B13D3-3AC6-C3A-2(B14D-4AC6-C4A)B14D2-3AC6-C3A-B14D2-3A-C4-C-3A-B14D-C4A-4C-4ACB17-12A19-C-10A-C19-C-8A-C22-C2-2A2-C24-C2-2A2-C22-C-8A-C19-C-10A-C19-12A18-C4A-4C-4AC15E2-3A-C4-C-3A-16E-3AC6-C3A-2(16E4AC6-C4A)16E-3AC6-C3A-16E-3A-C4-C-3A-16EC4A-4C-4AC15E3-12A19-C-10A-C19-C-8A-C22-C2-2A2-C24-C2-2A2-C22-C-8A-C19-C-10A-C19-12A18-C4A-4C-4ACB16-3A-C4-C-3A-B13D3-3AC6-C3A-2(B14D-4AC6-C4A)B14D2-3AC6-C3A-B14D2-3A-C4-C-3A-B14D-C4A-4C-4ACB17-12A19-C-10A-C19-C-8A-C22-C2-2A2-C25-2C2A2C24-C8AC21-C10AC19-C12AC18-4AC4-C4A-15B-C3AC6-C3AC5B2-2B-6BC3A8-3AC5B-F2B-3B-2B4A8-4A5BF-6BF2B4A8-4A5B-F6B-2BC3A8-3AC5B2F9BC3AC6-C3AC5BF-9B-4AC4-C4A-5B2-8B2-C12AC19-C10AC21-C8AC24-2C2A2C166-F9-F2-F18-F9-F2-2F27-F54-2F31-F4-4F22-2F4-2F-2F27-2(F-)F131-
