model
size = 32 16 7, scale = 0.05, origin = -y
material 
  colors = A:#CCC B:#36F C:#FFF D:#007 E:#777 F:#09F
voxels
145-F5-2F3-F21-F7-F25-2F27-2F2-2(F-)4F20-2F-2F3-2F-2F27-2(F-)F19-F-2F4-F2-2F23-2(F-)3F137-2C2A2C24-C8AC21-C10AC19-C12AC18-4AC4-C4A-3B-2B-F2B-3B2-C3AC6-C3AC6BF-6BFBC3A8-3AC6B-F6B-B4A8-4A6B2F8B4A8-4A6BF-8BC3A8-3AC6B2-8BC3AC6-C3AC16B-4AC4-C4A-15B2-C12AC19-C10AC21-C8AC24-2C2A2C25-C2-2A2-C22-C-8A-C19-C-10A-C19-12A18-C4A-4C-4ACB16-3A-C4-C-3A-B13D3-3AC6-C3A-B13D2-4AC6-C4AB14D-4AC6-C4AB14D2-3AC6-C3A-B14D2-3A-C4-C-3A-B14D-C4A-4C-4ACB17-12A19-C-10A-C19-C-8A-C22-C2-2A2-C24-C2-2A2-C22-C-8A-C19-C-10A-C19-12A18-C4A-4C-4AC15E2-3A-C4-C-3A-16E-3AC6-C3A-2(16E4AC6-C4A)16E-3AC6-C3A-16E-3A-C4-C-3A-16EC4A-4C-4AC15E3-12A19-C-10A-C19-C-8A-C22-C2-2A2-C24-C2-2A2-C22-C-8A-C19-C-10A-C19-12A18-C4A-4C-4ACB16-3A-C4-C-3A-B13D3-3AC6-C3A-2(B14D-4AC6-C4A)B14D2-3AC6-C3A-B14D2-3A-C4-C-3A-B14D-C4A-4C-4ACB17-12A19-C-10A-C19-C-8A-C22-C2-2A2-C25-2C2A2C24-C8AC21-C10AC19-C12AC18-4AC4-C4A-3B-2B-F2B-3B2-C3AC6-C3AC6BF-6BFBC3A8-3AC6B-F6B-B4A8-4A6B2F8B4A8-4A6BF-8BC3A8-3AC6B2-8BC3AC6-C3AC16B-4AC4-C4A-15B2-C12AC19-C10AC21-C8AC24-2C2A2C166-F10-F21-F7-F25-2F3-F23-2F2-F3-4F20-2F-2F3-2F-2F27-2(F-)F18-F2-F-F2(2-2F)20-2F-F3-3F132-
