model
size = 32 16 7, scale = 0.05, origin = -y
material 
  colors = A:#CCC B:#FC3000 C:#FC6400 D:#FC9800 E:#FCFCFC
voxels
83-2(2B2-)BD-D20-B2-B-4B3D22-3B2-5B19-3B2-4B3-B18-B2-B-2B-4B-2B17-5B2(2-B)2(-B)16-2B-9B-2B17-2B-B4-B2-5B18-5B-4B3-B20-B2CB-BC4BC20-C4-D-DB-2D21-2C3B2-D-D26-2B-2D39-2E2A2E24-E8AE21-E10AE7-2B5D2B3-E12AE6-2B5D2BD2-4AE4-E4A5-8B2CBDE3AE6-E3AE3-B8C2BCDE3A8-3AE10BC3BC-2(4A8-4A10BC3BCD)E3A8-3AE10BCB3CDE3AE6-E3AE10BCB3CD-4AE4-E4AB2-B-3CB2CB4C2-E12AE5-B5CBC2DC3-E10AE14-2BD4-E8AE15-2B7-2E2A2E25-E2-2A2-E22-E-8A-E19-E-10A-E8-3C4D4-12A9-3C5D-E4A-4E-4AE2-6B2-4CD2-3A-E4-E-3A6B2D3B5C2-3AE6-E3A5B7CB2CD-4AE6-E4A4B7CB2CD-4AE6-E4A10BCB3D2-3AE6-E3ACB3C2(3BC)4D-3A-E4-E-3ACB3C2(3BC)3D-E4A-4E-4AE4B3C4-B3D3-12A13-B3D2-E-10A-E13-2C4-E-8A-E14-2CD5-E2-2A2-E24-E2-2A2-E22-E-8A-E19-E-10A-E8-3C5D3-12A9-3C5D-E4A-4E-4AE2-6B2-4C2D-3A-E4-E-3A6B2D3B5CD-3AE6-E3A5B7CB2CD-4AE6-E4A4B7CB2CD-4AE6-E4A10BCB3D2-3AE6-E3ACB3C2(3BC)4D-3A-E4-E-3ACB3C2(3BC)4DE4A-4E-4AE-3B3C4-B3D3-12A13-B3D2-E-10A-E13-2C4-E-8A-E15-CD5-E2-2A2-E24-E2-2A2-E22-E-8A-E19-E-10A-E7-2B2-C3D4-12A7-3B2-C3D2-E4A-4E-4AE3-4B-B-C4D2-3A-E4-E-3AB5C2B-B2-C4D-3AE6-E3A5B3C2B-C4D-4AE6-E4A4B3C2B-C4D-4AE6-E4A9B-B4D2-3AE6-E3A6B-BC3BC3D2-3A-E4-E-3A8BC3BC3D-E4A-4E-4AE5C2B-3B4D3-12A7-3B2-B-2C3-E-10A-E9-3B3-D3-E-8A-E12-B9-E2-2A2-E25-2E2A2E24-E8AE21-E10AE12-4D3-E12AE11-4D3-4AE4-E4A2-2BC6-C3D2-E3AE6-E3AE3C2-7CB2D-E3A8-3AE4-C5BC2B2D-4A8-4A5C5BC2B2D-4A8-4A4C-5BC2B3DE3A8-3AE4C-5BCBC3DE3AE6-E3AE4C-5BCBC3D-4AE4-E4A4D2-2(2CB)2C2D2-E12AE12-C6-E10AE14-2C5-E8AE15-2C7-2E2A2E111-2D30-2D26-2(B-)C3D24-5BD-D24-2B-4BD19-2B-2B2(2-B)2D18-B-2B-7B2D-D16-BC2-2B2-B2-2B-D18-3C-2B-4BD-D22-2CB-BC2BD30-2CD30-CD29-C-D33-
