model
size = 32 16 5, scale = 0.05, origin = -y
material 
  colors = A:#3098CC B:#ECECEC C:#30CCFC D:#202020 E:#A80000 F:#B8B8B8 G:#FCCC30 H:#0030CC I:#A8A8A8 J:#444 K:#747474
voxels
5-2C2A2C24-C8AC21-C10AC19-C5A2-5AC18-4AC4-C4A17-C3AC6-C3AC16-C3A8-3AC2(16-3A10-3A)16-C3A8-3AC16-C3AC6-C3AC17-4AC4-C4A18-C5A2-5AC19-C10AC21-C8AC24-2C2A2C25-C2-2A2-C22-C-8A-C4-2E2-EI2-I3(H-)C-10A-C3-14B2-12A4-B6DB5DBC4A-4C-4AC2-B6DB5DB-3A-C4-C-3A-A16-3AC6-C3A-A4B2G8BE4AC6-C8A4GA3J8AC6-C8A4GA3J4A-3AC6-C3A-A4B2G8BE-3A-C4-C-3A-A15-C4A-4C-4AC2-B6DB5DB2-12A4-B6DB5DB-C-10A-C3-14B2-C-8A-C4-2(E-)EI-2IH2-2H4-C2-2A2-C24-C2-2A2-C22-C-8A-C4-2E2-EI2-I3(H-)C-10A-C3-14B2-12A4-D8A5DC4A-4C-4AC2-D8A5D-3A-C4-C2(-3A)B12A-3AC6-C3A-3A2(B9A3F4AC6-C4AJKA)B9A3F-3AC6-C3A-3AB9A3F-3A-C4-C2(-3A)B12AC4A-4C-4AC2-D8A5D2-12A4-D8A5D-C-10A-C3-2BF8BF2B2-C-8A-C4-2(E-)EI-2IH2-2H4-C2-2A2-C24-C2-2A2-C22-C-8A-C4-2E2-EI2-I3(H-)C-10A-C3-14B2-12A4-D8A5DC4A-4C-4AC2-D8A5D-3A-C4-C2(-3A)B12A-3AC6-C3A-3A2(B9A3F4AC6-C4AJKA)B9A3F-3AC6-C3A-3AB9A3F-3A-C4-C2(-3A)B12AC4A-4C-4AC2-D8A5D2-12A4-D8A5D-C-10A-C3-14B2-C-8A-C4-2(E-)EI-2IH2-2H4-C2-2A2-C25-2C2A2C24-C8AC5-2E2-EI2-I2(H-)H2-C10AC4-14B-C5A2-5AC3-B6DB4D2B-4AC4-C4A3-B6DB4D2BC3AC6-C3AC2A14-C3A8-3ACA4B2G7BAE3A10-7A4GA3J7A10-7A4GA3J4AC3A8-3ACA4B2G7BAEC3AC6-C3ACA16-4AC4-C4A3-B6DB4D2B-C5A2-5AC3-B6DB4D2B2-C10AC4-14B3-C8AC5-2(E-)EI-2IH2-2H5-2C2A2C21-
