model
size = 32 16 7, scale = 0.05, origin = -y
material 
  colors = A:#444 B:#3098CC C:#A8A8A8 D:#ECECEC E:#202020 F:#A80000 G:#0030CC H:#B8B8B8 I:#FCCC30 J:#747474
voxels
6-4C26-8C6-F2-2FC2-C2(G-)G3-10C5-14D2(2-5C)4-D6ED5ED-4C6-4C3-D6ED5ED-3C8-3C-15B2-3C8-4CB4D2I8DF2(3C10-3C4B4IB3A3B-)4C8-4CB4D2I8DF-3C8-4C15B2-4C6-4C3-D6ED5ED2(2-5C)4-D6ED5ED3-10C5-14D4-8C6-2(F-)FC2-C2(G-)G6-4C27-2C2A2C24-C8AC5-F2-2FC2-C2(G-)G2-C10AC4-14D-C12AC3-E8B5E-4AC4-C4A3-E8B5EC3AC6-C3AC15B-C3A8-3ACD14BF2(4A8-4A8B2A5B-)C3A8-3ACD14BFC3AC6-C3AC15B2-4AC4-C4A3-E8B5E-C12AC3-E8B5E2-C10AC4-14D3-C8AC5-2(F-)FC2-C2(G-)G5-2C2A2C25-C2-2A2-C22-C-8A-C4-F2-2FC2-C3(G-)C-10A-C3-14D2-12A4-E8B5EC4A-4C-4AC2-E8B5E-3A-C4-C-3A-3BD3-8B2-3AC6-C3A-3B2(D3-6B3H4AC6-C5AJB)D3-6B3H-3AC6-C3A-3BD3-6B3H-3A-C4-C-3A-3BD3-8B-C4A-4C-4AC2-E8B5E2-12A4-E8B5E-C-10A-C3-2DH8DH2D2-C-8A-C4-2(F-)FC2-C2(G-)G4-C2-2A2-C24-C2-2A2-C22-C-8A-C4-F2-2FC2-C3(G-)C-10A-C3-14D2-12A4-E8B5EC4A-4C-4AC2-E8B5E-3A-C4-C-3A-3BD3-8B2-3AC6-C3A-3BD3-6B3H4AC6-C5AJBD3-6B2H-4AC6-C5AJBD3-6B2H2-3AC6-C3A-3BD3-6B3H-3A-C4-C-3A-3BD3-8B-C4A-4C-4AC2-E8B5E2-12A4-E8B5E-C-10A-C3-14D2-C-8A-C4-2(F-)FC2-C2(G-)G4-C2-2A2-C24-C2-2A2-C22-C-8A-C4-F2-2FC2-C3(G-)C-10A-C3-14D2-12A4-E8B5EC4A-4C-4AC2-E8B5E-3A-C4-C-3A-3BD3-8B2-3AC6-C3A-3B2(D3-6B3H4AC6-C5AJB)D3-6B3H-3AC6-C3A-3BD3-6B3H-3A-C4-C-3A-3BD3-8B-C4A-4C-4AC2-E8B5E2-12A4-E8B5E-C-10A-C3-14D2-C-8A-C4-2(F-)FC2-C2(G-)G4-C2-2A2-C25-2C2A2C24-C8AC5-F2-2FC2-C2(G-)G2-C10AC4-14D-C12AC3-E8B5E-4AC4-C4A3-E8B5EC3AC6-C3AC15B-C3A8-3ACD14BF2(4A8-4A8B2A5B-)C3A8-3ACD14BFC3AC6-C3AC15B2-4AC4-C4A3-E8B5E-C12AC3-E8B5E2-C10AC4-14D3-C8AC5-2(F-)FC2-C2(G-)G5-2C2A2C27-4C26-8C6-F2-2FC2-C2(G-)G3-10C5-14D2(2-5C)4-D6ED4E2D-4C6-4C3-D6ED4E2D-3C8-4C15B2-3C8-4CB4D2I7DBF2(3C10-3C4B4IB3A3B-)4C8-4CB4D2I7DBF-3C8-4C15B2-4C6-4C3-D6ED4E2D2(2-5C)4-D6ED4E2D3-10C5-14D4-8C6-2(F-)FC2-C2(G-)G6-4C22-
