model
size = 32 16 7, scale = 0.05, origin = -y
material 
  colors = A:#2B5F75 B:#FFF C:#E8B647 D:#CA7A2C E:#F4A7B9 F:#DB8E71 G:#4A593D H:#3A8FB7 I:#554236
voxels
16-G31-14(2G30-)G21-4B6-C19-8B4-2C17-10B3-2C16-12B2-2C15-4B6-4B-2C3-A4-FH5-3B8-3B-2C2-EA5-E5-3B8-4B2C2E3-A2-E5-4B8-4B2C3-4AH3-H2-4B8-4B2C4A2-AH6-4B8-4B2C3-A11-3B8-4B2C15-4B6-4B-2C16-12B2-2C17-10B3-2C18-8B4-2C20-4B6-C20-2B2A2B5-C18-B8AB3-2C16-B10AB2-2C9-H5-B12AB-2C7-2(H-)HF2-4AB4-B4A-2C5-D-2H-H2D-B3AB6-B3AB2C2-3CE3-C4-B3A8-3AB5C4-4C3-4A8-4A5C3-F-CEC3-4A8-4ACF3CD-2D2-2CD2-B3A8-3ABCFA-CE2D2H4-2DB3AB6-B3ABCF-E4-2HD6-4AB4-B4A-CE6-H8-B12AB-2C16-B10AB2-2C17-B8AB3-2C19-2B2A2B5-C19-B2-2A2-B4-C17-B-8A-B2-2C15-B-10A-B-2C7-H-D2-D3-12A2-2C7-2(D-)DA-B4A-4B-4AB2C7-4D2A2-3A-B4-B-3AI2C5I4FD5-3AB6-B3AD2C4D3-3DA3-4AB6-B4A2C2FD2-3FD3A2-4AB6-B4ACD2-5D2F5A-3AB6-B3A-CDE-2E4D2-A4-3A-B4-B-3AECDED5-2D5-B4A-4B-4ABCE-E14-12A2-2C15-B-10A-B-2C16-B-8A-B2-2C18-B2-2A2-B4-C19-B2-2A2-B4-C17-B-8A-B2-2C15-B-10A-B-2C7-H-D6-12A2-2C7-D6-B4A-4B-4AB2C6-AD3-2A2-3A-B4-B-4A2C6A3D3A-A-3AB6-B3AD2C4D2-F2D2A3-4AB6-B4A2C2F3D-4DA3-4AB6-B4ACI2-7D2EA3-3AB6-B3ADC2D2-3D-E2-DA3-3A-B4-B-3ADCDE2(4-2D)-B4A-4B-4ABCD6-D9-12A2-2C15-B-10A-B-2C16-B-8A-B2-2C18-B2-2A2-B4-C20-2B2A2B5-C18-B8AB3-2C16-B10AB2-2C7-H-H5-B12AB-2C6-AD-H5-4AB4-B4A-2C6-3D-3H-B3AB6-B3AB2C6F2D4-2DB3A8-3AB2C4D2FD2F3D2-4A8-4A2C-2F2D2FD2F4D4A8-4A2C2-E3D-2DE4DB3A8-3AB2CI2-D-E5-3DB3AB6-B3AB2C3-E-2E5-D2-4AB4-B4A-2C3-E-DE8-B12AB-2C16-B10AB2-2C17-B8AB3-2C19-2B2A2B5-C21-4B6-A19-8B4-2A17-10B3-2A7-E-E2-D3-12B2-2A7-2(E-)2D2-4B6-4B-2A6-3E3D3-3B8-4B2A2D2I-6D4-3B8-4B2AE-I2F5-F3-4B8-4B2A3-4D2-I-3D4B8-4B2A3-2I2D3-IEDE4B8-4B2A3-E-E9-3B8-4B2A15-4B6-4B-2A16-12B2-2A17-10B3-2A18-8B4-2A20-4B6-A15-
