model
size = 32 16 7, scale = 0.05, origin = -y
material 
  colors = A:#2B5F75 B:#F4A7B9 C:#E8B647 D:#CA7A2C E:#DB8E71 F:#4A593D G:#3A8FB7 H:#554236
voxels
16-F31-14(2F30-)F21-4B6-C19-8B4-2C17-10B3-2C16-2(5B2-)2C15-4B6-4B-2C3-A4-EG5-3B8-3B-2C2-BA5-B5-3B8-4B2C2B3-A2-B5-3B10-3B2C3-4AG3-G2-3B10-3B2C4A2-AG6-4B8-4B2C3-A11-3B8-4B2C15-4B6-4B-2C16-2(5B2-)2C17-10B3-2C18-8B4-2C20-4B6-C20-2B2A2B5-C18-B8AB3-2C16-B10AB2-2C9-G5-B12AB-2C7-2(G-)GE2-4AB4-B4A-2C5-D-2G-G2D-B3AB6-B3AB2C2-3CB3-C4-B3A8-3AB5C4-4C3-4A8-4A5C3-E-CBC3-4A8-4ACE3CD-2D2-2CD2-B3A8-3ABCEA-CB2D2G4-2DB3AB6-B3ABCE-B4-2GD6-4AB4-B4A-CB6-G8-B12AB-2C16-B10AB2-2C17-B8AB3-2C19-2B2A2B5-C19-B2-2A2-B4-C17-B-8A-B2-2C15-B-10A-B-2C7-G-D2-D3-12A2-2C7-2(D-)DA-B4A-4C-4AB2C7-4D2A2-3A-C4-C-3AH2C5H4ED5-3AC6-C3AD2C4D3-3DA3-4AC6-C4A2C2ED2-3ED3A2-4AC6-C4ACD2-5D2E5A-3AC6-C3A-CDB-2B4D2-A4-3A-C4-C-3ABCDBD5-2D5-B4A-4C-4ABCB-B14-12A2-2C15-B-10A-B-2C16-B-8A-B2-2C18-B2-2A2-B4-C19-B2-2A2-B4-C17-B-8A-B2-2C15-B-10A-B-2C7-G-D6-12A2-2C7-D6-B4A-4C-4AB2C6-AD3-2A2-3A-C4-C-4A2C6A3D3A-A-3AC6-C3AD2C4D2-E2D2A3-4AC6-C4A2C2E3D-4DA3-4AC6-C4ACH2-7D2BA3-3AC6-C3ADC2D2-3D-B2-DA3-3A-C4-C-3ADCDB2(4-2D)-B4A-4C-4ABCD6-D9-12A2-2C15-B-10A-B-2C16-B-8A-B2-2C18-B2-2A2-B4-C20-2B2A2B5-C18-B8AB3-2C16-B10AB2-2C7-G-G5-B12AB-2C6-AD-G5-4AB4-B4A-2C6-3D-3G-B3AB6-B3AB2C6E2D4-2DB3A8-3AB2C4D2ED2E3D2-4A8-4A2C-2E2D2ED2E4D4A8-4A2C2-B3D-2DB4DB3A8-3AB2CH2-D-B5-3DB3AB6-B3AB2C3-B-2B5-D2-4AB4-B4A-2C3-B-DB8-B12AB-2C16-B10AB2-2C17-B8AB3-2C19-2B2A2B5-C21-4B6-A19-8B4-2A17-10B3-2A7-B-B2-D3-2(5B2-)2A7-2(B-)2D2-4B6-4B-2A6-3B3D3-3B8-4B2A2D2H-6D4-3B8-4B2AB-H2E5-E3-3B10-3B2A3-4D2-H-3D3B10-3B2A3-2H2D3-HBD5B8-4B2A3-B-B9-3B8-4B2A15-4B6-4B-2A16-2(5B2-)2A17-10B3-2A18-8B4-2A20-4B6-A15-
