model
size = 32 16 8, scale = 0.05, origin = -y
material 
  colors = A:#555 B:#777 C:#14AC00 D:#DD0003
voxels
86-2A59-7A2(25-A5-A)22-2(4A5-6A17-)4A5-6A20-A5-A25-7A60-2A78-4A26-8A23-10A9-2A10-2(5A2-)14A3-4A6-4A3-9A2-A3-3A8-3A-4A5C7A-3A8-8A2(5C10A10-7A)5C11A8-8A5C7A-3A8-8A5C7A-4A6-4A3-9A2-A4-5A2-5A4-9A2-A5-10A9-2A12-8A26-4A27-2A2C2A24-A8BA21-A10BA8-2A9-A12BA-14A3-4BA4-A4B-2C9A2CA2-A3BA6-A3B18A3B8-3B17A2(C3B8-4B14AD-)A3B8-3B15AD-A3BA6-A3B17A-4BA4-A4B-2C9A2CA3-A12BA-2C9A2CA4-A10BA8-2A11-A8BA24-2A2C2A25-A2-2C2-A22-A-8B-A19-A-10B-A7-2A10-12B7-9A2-A4B-3C2-4B13A-A3-3B-C4-C-3B-16A-3BC6-C3B-16AC3BC6-C4B14A2-C3BC6-C4B14A3-3BC6-C3B-14A3-3B-C4-C-3B-17A4B-4A-4B13A-A4-12B2-5C4A3C-A3-A-10B-A7-2A10-A-8B-A22-A2-2C2-A24-A2-2C2-A22-A-8B-A19-A-10B-A7-2A10-12B7-9A2-A4B-4C-4B13A-A3-3B-C4-C-3B-16A-3BC6-C3B-16AC3BC6-C4B14A2-C3BC6-C4B14A3-3BC6-C3B-14A3-3B-C4-C-3B-17A4B-4C-4B13A-A4-12B2-5C4A3C-A3-A-10B-A7-2A10-A-8B-A22-A2-2C2-A25-2A2C2A24-A8BA21-A10BA8-2A9-A12BA-14A3-4BA4-A4B-2C9A2CA2-A3BA6-A3B18A3B8-3B17A2(C3B8-4B14AD-)A3B8-3B15AD-A3BA6-A3B17A-4BA4-A4B-2C9A2CA3-A12BA-2C9A2CA4-A10BA8-2A11-A8BA24-2A2C2A27-4A26-8A23-10A9-2A10-2(5A2-)14A3-4A6-4A3-9A2-A3-3A8-8A5C7A-3A8-8A2(5C10A10-7A)5C11A8-8A5C7A-3A8-8A5C7A-4A6-4A3-9A2-A4-5A2-5A4-9A2-A5-10A9-2A12-8A26-4A108-2A59-7A2(25-A5-A)22-2(4A5-6A17-)4A5-6A20-A5-A25-7A60-2A72-
