model
size = 32 16 7, scale = 0.05, origin = -y
material 
  colors = A:#CCC B:#FCFCFC C:#9800FC D:#98CCFC E:#0CC F:#FCFC00 G:#CC9830 H:#30FCFC I:#00CC98 J:#FC00FC
voxels
16-H31-14(2H30-)H21-4B6-C19-8B4-2C17-10B3-2C16-2(5B2-)2C15-4B6-4B-2C3-E4-GI5-3B8-3B-2C2-FE5-F5-3B8-4B2C2F3-E2-F5-3B10-3B2C3-4EI3-I2-3B10-3B2C4E2-EI6-4B8-4B2C3-E11-3B8-4B2C15-4B6-4B-2C16-2(5B2-)2C17-10B3-2C18-8B4-2C20-4B6-C20-2B2A2B5-C18-B8AB3-2C16-B10AB2-2C9-I5-B12AB-2C7-2(I-)IG2-4AB4-B4A-2C5-D-2I-I2D-B3AB6-B3AB2C2-3CF3-C4-B3A8-3AB5C4-4C3-4A8-4A5C3-G-CFC3-4A8-4ACG3CD-2D2-2CD2-B3A8-3ABCGE-CF2D2I4-2DB3AB6-B3ABCG-F4-2ID6-4AB4-B4A-CF6-I8-B12AB-2C16-B10AB2-2C17-B8AB3-2C19-2B2A2B5-C19-B2-2A2-B4-C17-B-8A-B2-2C15-B-10A-B-2C7-I-D2-D3-12A2-2C7-2(D-)DE-B4A-4B-4AB2C7-4D2E2-3A-B4-B-3AJ2C5J4GD5-3AB6-B3AD2C4D3-3DE3-4AB6-B4A2C2GD2-3GD3E2-4AB6-B4ACD2-5D2G5E-3AB6-B3A-CDF-2F4D2-E4-3A-B4-B-3AFCDFD5-2D5-B4A-4B-4ABCF-F14-12A2-2C15-B-10A-B-2C16-B-8A-B2-2C18-B2-2A2-B4-C19-B2-2A2-B4-C17-B-8A-B2-2C15-B-10A-B-2C7-I-D6-12A2-2C7-D6-B4A-4B-4AB2C6-ED3-2E2-3A-B4-B-3AE2C6E3D3E-E-3AB6-B3AD2C4D2-G2D2E3-4AB6-B4A2C2G3D-4DE3-4AB6-B4ACJ2-7D2FE3-3AB6-B3ADC2D2-3D-F2-DE3-3A-B4-B-3ADCDF2(4-2D)-B4A-4B-4ABCD6-D9-12A2-2C15-B-10A-B-2C16-B-8A-B2-2C18-B2-2A2-B4-C20-2B2A2B5-C18-B8AB3-2C16-B10AB2-2C7-I-I5-B12AB-2C6-ED-I5-4AB4-B4A-2C6-3D-3I-B3AB6-B3AB2C6G2D4-2DB3A8-3AB2C4D2GD2G3D2-4A8-4A2C-2G2D2GD2G4D4A8-4A2C2-F3D-2DF4DB3A8-3AB2CJ2-D-F5-3DB3AB6-B3AB2C3-F-2F5-D2-4AB4-B4A-2C3-F-DF8-B12AB-2C16-B10AB2-2C17-B8AB3-2C19-2B2A2B5-C21-4B6-E19-8B4-2E17-10B3-2E7-F-F2-D3-2(5B2-)2E7-2(F-)2D2-4B6-4B-2E6-3F3D3-3B8-4B2E2D2J-6D4-3B8-4B2EF-J2G5-G3-3B10-3B2E3-4D2-J-3D3B10-3B2E3-2J2D3-JFDF4B8-4B2E3-F-F9-3B8-4B2E15-4B6-4B-2E16-2(5B2-)2E17-10B3-2E18-8B4-2E20-4B6-E15-
