model
size = 32 16 7, scale = 0.05, origin = -y
material 
  colors = A:#CCC B:#DCDCDC C:#FFF D:#90F E:#0CC F:#FF0 G:#C93 H:#0C9 I:#F0F
voxels
16-E31-3(2E30-)2E-HB27-2E-2B27-2E-E28-3E-2B2H5-2B17-2E2-4B2-E21-2E-3B4-2BE19-2E-B8-3B17-3(2E30-)2E11-B18-E20-2C2A2C5-D18-C8AC3-2D16-C10AC2-2D15-C5A2-5AC-DB3-E-B9-4AC4-C4A-DHB-H3B8-C3AC6-C3ACD6B5-BD2-C3A8-3AC2D5EH8-3A10-3A3DB-2B2-2D2B3-3A10-3A2D5B2G6E-C3A8-3AC2D7B2F2E3-C3AC6-C3AC2D-3B-2BF5B2-4AC4-C4A-2D3-2B5-FB2F-C5A2-5AC-2D3-3B4-3FB2-C10AC2-2D3-I-2I4-B5-C8AC3-2D19-2C2A2C5-D19-C2-2A2-C4-D17-C-8A-C2-2D15-C-10A-C-2D16-12A2-2D5-I8-C4A-4C-4AC2D15-3A-C4-C-3A-2DB2-G-B4-2D3-3AC6-C3AE2D5EH3-FH3-4AC7-4A3D3-G-DFDB4-4AC6-C4ADGB2-3GB4E4-3AC6-C3AGDG3B-4B2E5-3A-C4-C-3ABD2G2B2GB2G5B-C4A-4C-4ACDF-4B4-4B3-12AI-2D2-F2B5-2B3-C-10A-C-2D16-C-8A-C2-2D10-B7-C2-2A2-C4-D12-IB5-C2-2A2-C4-D17-C-8A-C2-2D15-C-10A-C-2D16-12A2-2D14-C4A-4C-4AC2D2-2F11-3A-C4-C-3A-2D3-B-F9-3AC6-C3A-2D3-E5-H4-4AC6-C4A3D4-4D5-4AC6-C4AD2B4-3B2E5-3AC6-C3ABD3B2-G2B3E3-E-3A-C4-C-3ABD3B2GB2G4B3-C4A-4C-4ACDF-2G5-GB6-12AI-2D-EF5-2G5-C-10A-C-2D2-B6-2G5-C-8A-C2-2D2-F6-FB7-C2-2A2-C4-D19-C2-2A2-C4-D17-C-8A-C2-2D15-C-10A-C-2D16-12A2-2D-BF11-C4A-4C-4AC2D2-FB11-3A-C4-C-3A-2D3-B11-3AC6-C3A-2D-E12-4AC6-C4A2D3B4-D6-4AC6-C4ADIB-B4GB7-3AC6-C3ABD8B4E-2E-3A-C4-C-3ABD7B5-2B-C4A-4C-4ACDB3-6B7-12AI-2D2-F2-4B6-C-10A-C-2D2-F2-3IB7-C-8A-C2-2D2-F5-I9-C2-2A2-C4-D20-2C2A2C5-D18-C8AC3-2D16-C10AC2-2D15-C5A2-5AC-2D15-4AC4-C4A-2D14-C3AC6-C3AC2D-B5-2D5-C3A8-3AC2D-E4-GH6-3A10-3A2DI2-B2(-2H)3B-3A10-3A2D5-4B4E-C3A8-3AC2D-2I-2B4-4EC3AC6-C3AC2DI2-E3B-5HB-4AC4-C4A-2D3-E3F4B4-C5A2-5AC-2D2-E2-6B5-C10AC2-2D5-4BG2B5-C8AC3-2D6-B4F2G6-2C2A2C5-D31-E31-2(2E30-)2(2E8-B21-)2E-B5-BD21-2E7-BH21-2E5-6H2G17-2E5-6B2E17-2E5-2B23-2E4-2B2H22-2E5-3F4B18-2E-B3-6B19-2E5-4B2-2B17-2E6-I6F17-E9-B2-2B-
