model
size = 5 16 28, scale = 0.05, origin = -y
material 
  colors = A:#EEE B:#111
voxels
----- BBBB- ----- ----- ----- ----- ----- BB-BB BBBBB BBBBB BBBBB BBBBB BBBBB BBBBB BBBBB BBB-- 
BBBBB AAABB BBBBB ----- ----- ----- ----- BBBBB AAAAA AAAAA AAAAA AAAAA AAAAA AAAAA AAAAA BBBBB 
BBBBB AAAAA AAAAA BBBBB ----- ----- BBBBB AAAAA AAAAA BAAAA BAAAA AAAAB BAAAB BAAAB AAAAA BBBBB 
BBBBB AAAAA AAAAA AAAAA BBBBB ----- BBBBB AAAAA AAAAA AAAAB AAAAB BAAAA AAAAA AAAAA AAAAA BBBBB 
----- BBBBB AAAAA AAAAA AAAAA BBBBB AAAAB AAAAA AAAAA BAAAA BAAAA BAAAB BAAAB BAAAB AAAAA BBBBB 
----- ----- BBBBB AAAAA AAAAA AAAAA AAAAA AAAAA AAAAA AAAAA AAAAA AAAAA AAAAA AAAAA AAAAA BBBBB 
----- ----- BBBBB BAAAA AAAAA AAAAA AAAAA AAAAA AAAAA AAAAB BAAAB BAAAB BAAAB AAAAB AAAAA BBBBB 
----- ----- ----- BBBBB AAAAA AAAAA AAAAA AAAAA AAAAA BAAAB AAAAA AAAAB AAAAA BAAAB AAAAA BBBBB 
----- ----- ----- ----- BBBBB AAAAA BAAAA AAAAA AAAAA AAAAA BAAAA BAAAA BAAAA AAAAA AAAAA BBBBB 
----- ----- ----- ----- ----- BBBBB BAAAA AAAAA AAAAA AAAAB AAAAB AAAAB AAAAB AAAAA AAAAA BBBBB 
----- ----- ----- ----- ----- ----- BBBBB AAAAA BAAAA BAAAA AAAAA AAAAB AAAAA AAAAB AAAAA BBBBB 
----- ----- ----- ----- ----- ----- BBBBB AAAAA AAAAA AAAAB AAAAB AAAAB AAAAB AAAAA AAAAA BBBBB 
----- ----- ----- ----- ----- ----- BBBBB AAAAA AAAAA BAAAA BAAAA BAAAA BAAAA BAAAA AAAAA BBBBB 
----- ----- ----- ----- ----- ----- BBBBB AAAAA AAAAA AAAAB AAAAB BAAAB AAAAB AAAAB AAAAA BBBBB 
----- ----- ----- ----- ----- ----- BBBBB AAAAA AAAAA BAAAA BAAAA BAAAB BAAAA BAAAA AAAAA BBBBB 
----- ----- ----- ----- ----- ----- BBBBB AAAAA AAAAA AAAAB AAAAB AAAAB AAAAB AAAAB AAAAA BBBBB 
----- ----- ----- ----- ----- ----- BBBBB AAAAA AAAAA BAAAA BAAAA BAAAA BAAAA AAAAA AAAAA BBBBB 
----- ----- ----- ----- ----- ----- BBBBB AAAAA AAAAB AAAAB AAAAA BAAAA AAAAA BAAAA AAAAA BBBBB 
----- ----- ----- ----- ----- ----- BBBBB AAAAA AAAAA BAAAA BAAAA BAAAA BAAAA AAAAA AAAAA BBBBB 
----- ----- ----- ----- ----- ----- BBBBB AAAAA AAAAA AAAAA AAAAB AAAAB AAAAB AAAAA AAAAA BBBBB 
----- ----- ----- ----- ----- ----- BBBBB AAAAA AAAAA BAAAB AAAAA BAAAA AAAAA BAAAB AAAAA BBB-B 
----- ----- ----- ----- ----- ----- BBBBB AAAAA AAAAA BAAAA BAAAB BAAAB BAAAB BAAAA AAAAA BBBBB 
----- ----- ----- ----- ----- ----- BBBBB AAAAA AAAAA AAAAA AAAAA AAAAA AAAAA AAAAA AAAAA BBBBB 
----- ----- ----- ----- ----- ----- BBBBB AAAAA AAAAA AAAAB AAAAB BAAAB BAAAB BAAAB AAAAA BBBBB 
----- ----- ----- ----- ----- ----- BBBBB AAAAA AAAAA BAAAA BAAAA AAAAB AAAAA AAAAA AAAAA BBBBB 
----- ----- ----- ----- ----- ----- BBBBB AAAAA AAAAA AAAAB AAAAB BAAAA BAAAB BAAAB AAAAA BBBBB 
----- ----- ----- ----- ----- ----- ----- BBBBB AAAAA AAAAA AAAAA AAAAA AAAAA AAAAA AAAAA BBBBB 
----- ----- ----- ----- ----- ----- ----- BB-BB BBBBB BBBBB BBBBB BBBBB BBBBB BBBBB BBBBB BBBBB 
