model
size = 32 16 7, scale = 0.05, origin = -y
material 
  colors = A:#FF0 B:#CCC C:#FFF
voxels
112-2A30-4A2(-A)-2A2(-A)17-2(16A48-)16A16-3A2(-A-2A)-A17-2A147-2C2B2C24-C8BC21-C10BC2-2A15-C12BC-2A15-4BC4-C4B-3A13-C3BC6-C3BC16AC3B8-3BC2(16A4B8-4B)16AC3B8-3BC16AC3BC6-C3BC2A15-4BC4-C4B-2A15-C12BC-2A16-C10BC21-C8BC24-2C2B2C25-C2-2B2-C22-C-8B-C19-C-10B-C-2A16-12B2-2A14-C4B-4C-4BC6A2(-2A-A)-3B-C4-C-3B-16A-3BC6-C3B-2(15A-4BC6-C4B)15A2-3BC6-C3B-16A-3B-C4-C-3B2(-3A)3(-2A)C4B-4C-4BC2A16-12B2-2A15-C-10B-C19-C-8B-C22-C2-2B2-C24-C2-2B2-C22-C-8B-C19-C-10B-C-2A16-12B2-2A14-C4B-4C-4BC3A14-3B-C4-C-3B-16A-3BC6-C3B-16A4BC6-C4B10A6-4BC6-C4B16A-3BC6-C3B-16A-3B-C4-C-3B-2A14-C4B-4C-4BC2A16-12B2-2A15-C-10B-C19-C-8B-C22-C2-2B2-C24-C2-2B2-C22-C-8B-C19-C-10B-C-2A16-12B2-2A14-C4B-4C-4BC4A2(-2A)3(-A)-3B-C4-C-3B-16A-3BC6-C3B-2(15A-4BC6-C4B)15A2-3BC6-C3B-16A-3B-C4-C-3B-4A-2A-3A-2A-AC4B-4C-4BC2A16-12B2-2A15-C-10B-C19-C-8B-C22-C2-2B2-C25-2C2B2C24-C8BC21-C10BC2-2A15-C12BC-2A15-4BC4-C4B-3A13-C3BC6-C3BC16AC3B8-3BC2(16A4B8-4B)16AC3B8-3BC16AC3BC6-C3BC2A15-4BC4-C4B-2A15-C12BC-2A16-C10BC21-C8BC24-2C2B2C133-2A30-4A3(-2A)-A17-2(16A48-)16A16-3A3(-A)2(-2A)17-2A142-
