model
size = 31 32 17, scale = 0.05, origin = -y
material 
  colors = A:#999 B:#000 C:#8D8D8D D:#EDEDED E:#FFF F:#A0A0A0 G:#7F7F7F H:#353535 I:#B3B3B3 J:#555 K:#666 L:#CCC M:#333 N:#EAEAEA
voxels
9-13B18-3D7B3D18-13B18-2FGM6B3E18-3IKM2B3GEFE18-I2AFGMBG2BEFE18-AFA2FMBG2B3E18-7BG5B18-3J4B4GBE18-3F7BGBE18-3L7B2GE18-3N9BE18-2B2(E9BE18-EB)E2K2B3A2BL18-2BE2K2B3A2BF18-3E2K7BJ18-2KEK9B18-3EK8BM18-2KEK9B18-2MEK8BE17-BKBEK5B4EK15-5E6B6E14-7BDBD7B15-5BDB-BD5B17-3BDB3-BD3B202-2B13-2B14-2D13-2D14-2B13-2B14-2F2(13-2E14-2I)13-2F14-2A13-2E14-2B13-2B14-2K13-2E14-2F13-2B14-2L13-2B14-2N2(13-2B14-EB)F11-M2E14-EBF11-M2L15-BF11-BF16-EF11-BJ16-KF11-2B16-EF11-LM16-MF11-LB14-BEKF11-L2EM11-ABEG13-FEMA10-A2B15-BMA10-A2B15-2BA11-2B15-2(2B13-)2B15-4BDB3-BD4B16-3BDB5-BD3B138-B17-B12-D17-D12-B17-B4(12-B17-M)12-B17-B12-B17-4(E12-BA15-G)E13-B15-E14-B15-L14-EN13-LF14-EN13-LJ2(14-EN13-LB)14-EN13-LM10-3A2-N13-L2-3A6-2AG19-F2(2A6-2AB19-B)2A7-2A19-2A8-2A2B15-2B2A9-A2B15-2BA12-2(B15-)3BDB5-BD3B106-B19-B10-D19-D7(10-B19-B)11-4(B17-B12-)B17-E12-B17-L13-B15-F14-B15-J3(14-B15-B)9-A4-B15-B2(4-A)2(25-A4-A)B23-BA4-2AB21-B2A5-2AB19-B2A6-3AB17-B3A7-2A2B15-2B2A10-2B15-2B14-2BDB7-BD2B75-B19-B10-D19-D7(10-B19-B)3(10-BA17-IB)11-3(B17-B12-)BN15-GB12-BN15-GB13-2(B15-B14-)B15-B8-A5-B15-B5-2(A2-A27-)A2-AB25-BA3-AB23-BA4-2AB21-B2A4-3AB19-B3A5-3AB17-B3A7-2A2B15-2B2A11-2B13-2B16-2DB7-B2D45-B19-B10-D19-D13(10-B19-B)11-3(B17-B12-)B17-B13-B15-B8-A5-B15-B5-3(A2-A27-)A2-AB25-BA2-2AB23-B2A3-2AB21-B2A4-3AB19-B3A5-3AB17-B3A8-A2B15-2BA2(13-D)17-2B9-2B14-B19-B10-D19-D13(10-B19-B)2(10-BN17-2B)11-2(B17-B12-)BA15-DB6-A6-B15-B6-3(2A28-B)A-A26-BA2-AB25-BA2-2AB23-B2A3-2AB21-B2A5-2AB19-B2A7-2A2B15-2B2A11-2(D15-)2(B13-)B19-B10-D19-D13(10-B19-B)3(10-BN17-2B)11-B17-B12-BA15-DB6-A5-BA15-LB5-4(2A28-B)A-A26-BA2-AB25-BA3-AB23-BA4-2AB21-B2A6-2A19-2A10-BD15-DB14-2(B13-)B19-B10-D19-D13(10-B19-B)4(10-BI17-2B)10-B2A15-BAB5-A5-BA15-2B5-5(2A28-B)A-A26-BA2-AB25-BA3-AB23-BA5-3A19-3A9-BD15-DB14-2(B13-)B19-B10-D19-D10-B19-B12(10-A19-A)3(10-2A17-2A)11-A17-A12-2A15-2A6-A5-2A15-2A5-2A4(28-3A)28-2A-A26-2A2-2A25-2A3-2A23-2A5-3A19-3A9-BD15-DB14-2(B13-)B19-B10-D19-D10-B19-B12(10-A19-A)2(10-2A17-2A)11-2(A17-A12-)2A15-2A2(6-A)15-A6-2A3(28-3A)28-2A-A26-2A2-2A25-2A3-2A23-2A4-3A21-3A6-2A19-2A10-BD15-DB14-2(B13-)B19-B10-D19-D10-B19-B12(10-C19-C)11-3(C17-C12-)C17-C13-C15-C7-C6-C15-C6-3(2C28-A)C-C26-AC2-CA25-AC2-C2A23-2AC3-C2A21-2AC5-C3A17-3AC7-2CBA15-AB2C11-2D14-D16-B12-B13-B19-B10-D19-D10-B19-B6(10-C19-C)3(10-CA17-AC)11-2(C17-C12-)C17-C13-4(C15-C14-)C15-C8-C5-C15-C5-2(C2-C27-)C2-C26-AC2-CA25-AC2-C2A23-2AC3-C2A21-2AC4-C3A19-3AC5-2C2A17-2A2C8-C2B15-2BC2(13-D)17-B11-B14-B19-B10-D19-D10-B19-B6(10-C19-C)11-5(C17-C12-)C17-C13-4(C15-C14-)C15-C8-C5-C15-C5-2(C2-C27-)C2-CA25-AC3-CA23-AC4-C2A21-2AC4-C3A19-3AC5-C3A17-3AC7-3CA15-A3C11-2(B15-)D13-D17-2B9-2B15-B17-B12-D17-D12-B17-B6(12-A17-A)4(12-2A15-2A)13-5(A15-A14-)2(A15-)A13-A10-A5-A13-A5-2(A4-)2A13-2A2(4-A)25-A4-2A23-2A4-3A21-3A5-3A19-3A6-4A17-4A7-4A16-3A10-2A15-2A14-BA11-AB17-2D9-2D20-B7-B18-B15-B14-D15-D14-B15-B12(14-17A)15-4(B13AB16-)B13AB11-4A-20A3(6-25A)7-23A8-23A9-21A12-17A15-AC11ACA17-B11AB19-2D7A2D22-7B20-15B16-15D16-15B7(16-A2C2A5C2A2CA)16-A2C2A5B2A2CA16-A2C2BI2(JA)2B2CA16-ACBIJ5HIJBCA17-BJA2HFIF2HAIB18-BI2HF3GF2HJB18-J2HFGFIF2G2HI18-JHFGI3BGIFHJ18-AHIGFBEBIFGHA18-JHFIG3BFGFHJ18-I2H2(FIG)F2HA18-BI2HGF2GI2HIB17-ABJA2HGIF2HAJBA14-3ACBJI5HJIBC3A12-3A2C2BAIAJI2B2C3A12-3A2C2A5B2A2C3A13-2A2C2A5C2A2C2A15-A2C2A5C2A2CA16-A2C2A5C2A2CA18-C2A5C2AC20-11B21-9D42-
