model
size = 26 29 26, scale = 0.05, origin = -y
material 
  colors = A:#8D8D8D B:#999 C:#000
voxels
-------------------------- -------------------------- -------------------------- -------------------------- -------------------------- -------------------------- -------------------------- -------------------------- -------------------------- -------------------------- -------------------------- -------------------------- -------------------------- ---------BBAAAABB--------- ---------BBAAAABB--------- ---------BBAAAABB--------- ---------BBAAAABB--------- ---------BBAAAABB--------- ---------BBAAAABB--------- ---------BBAAAABB--------- ---------BBAAAABB--------- ---------BBAAAABB--------- ---------BBAAAABB--------- ---------BBAAAABB--------- ---------BBAAAABB--------- ---------BBAAAABB--------- ---------BBAAAABB--------- ---------BBAAAABB--------- ---------BBAAAABB--------- 
-------------------------- -------------------------- -------------------------- -------------------------- -------------------------- -------------------------- -------------------------- -------------------------- -------------------------- -------------------------- ---------BBAAAABB--------- ---------BBAAAABB--------- ---------BBAAAABB--------- -------AB--------BA------- -------AB--------BA------- -------AB--------BA------- -------AB--------BA------- -------AB--------BA------- -------AB--------BA------- -------AB--------BA------- -------AB--------BA------- -------AB--------BA------- -------AB--------BA------- -------AB--------BA------- -------AB--------BA------- -------AB--------BA------- -------AB--------BA------- -------AB--------BA------- -------AB--------BA------- 
-------------------------- -------------------------- -------------------------- -------------------------- -------------------------- -------------------------- -------------------------- ---------BBAAAABB--------- ---------BBAAAABB--------- ---------BBAAAABB--------- -------AB--------BA------- -------AB--------BA------- -------AB--------BA------- -----AA------------AA----- -----AA------------AA----- -----AA------------AA----- -----AA------------AA----- -----AA------------AA----- -----AA------------AA----- -----AA------------AA----- -----AA------------AA----- -----AA------------AA----- -----AA------------AA----- -----AA------------AA----- -----AA------------AA----- -----AA------------AA----- -----AA------------AA----- -----AA------------AA----- -----AA------------AA----- 
-------------------------- -------------------------- -------------------------- -------------------------- ---------CCCCCCCC--------- ---------CCCCCCCC--------- ---------CCCCCCCC--------- -------AB--------BA------- -------AB--------BA------- -------AB--------BA------- -----AA------------AA----- -----AA------------AA----- -----AA------------AA----- ----B----------------B---- ----B----------------B---- ----B----------------B---- ----B----------------B---- ----B----------------B---- ----B----------------B---- ----B----------------B---- ----B----------------B---- ----B----------------B---- ----B----------------B---- ----B----------------B---- ----B----------------B---- ----B----------------B---- ----B----------------B---- ----B----------------B---- ----B----------------B---- 
-------------------------- -------------------------- ---------CCCCCCCC--------- ---------CCCCCCCC--------- -------CC--------CC------- -------CC--------CC------- -------CC--------CC------- -----AA------------AA----- -----AA------------AA----- -----AA------------AA----- ----B----------------B---- ----B----------------B---- ----B----------------B---- ---B------------------B--- ---B------------------B--- ---B------------------B--- ---B------------------B--- ---B------------------B--- ---B------------------B--- ---B------------------B--- ---B------------------B--- ---B------------------B--- ---B------------------B--- ---B------------------B--- ---B------------------B--- ---B------------------B--- ---B------------------B--- ---B------------------B--- ---B------------------B--- 
-------------------------- ---------CCCCCCCC--------- -------CC--------CC------- -------CC--------CC------- ------C------------C------ ------C------------C------ ------C------------C------ ----AB--------------BA---- ----A----------------A---- ----A----------------A---- ---A------------------A--- ---A------------------A--- ---A------------------A--- --A--------------------A-- --A--------------------A-- --A--------------------A-- --A--------------------A-- --A--------------------A-- --A--------------------A-- --A--------------------A-- --A--------------------A-- --A--------------------A-- --A--------------------A-- --A--------------------A-- --A--------------------A-- --A--------------------A-- --A--------------------A-- --A--------------------A-- --A--------------------A-- 
---------CCCCCCCC--------- -------CC--------CC------- ------C------------C------ ------C------------C------ -----C--------------C----- -----C--------------C----- -----C--------------C----- ----A----------------A---- ----A----------------A---- ----A----------------A---- ---A------------------A--- ---A------------------A--- ---A------------------A--- --A--------------------A-- --A--------------------A-- --A--------------------A-- --A--------------------A-- --A--------------------A-- --A--------------------A-- --A--------------------A-- --A--------------------A-- --A--------------------A-- --A--------------------A-- --A--------------------A-- --A--------------------A-- --A--------------------A-- --A--------------------A-- --A--------------------A-- --A--------------------A-- 
--------C--------C-------- ------CC----------CC------ -----C--------------C----- -----C--------------C----- ----C----------------C---- ----C----------------C---- ----C----------------C---- ---A------------------A--- ---A------------------A--- ---A------------------A--- --A--------------------A-- --A--------------------A-- --A--------------------A-- -A----------------------A- -A----------------------A- -A----------------------A- -A----------------------A- -A----------------------A- -A----------------------A- -A----------------------A- -A----------------------A- -A----------------------A- -A----------------------A- -A----------------------A- -A----------------------A- -A----------------------A- -A----------------------A- -A----------------------A- -A----------------------A- 
-------C----------C------- ------C------------C------ -----C--------------C----- -----C--------------C----- ----C----------------C---- ----C----------------C---- ----C----------------C---- ---B------------------B--- ---B------------------B--- ---B------------------B--- --B--------------------B-- --B--------------------B-- --B--------------------B-- -B----------------------B- -B----------------------B- -B----------------------B- -B----------------------B- -B----------------------B- -B----------------------B- -B----------------------B- -B----------------------B- -B----------------------B- -B----------------------B- -B----------------------B- -B----------------------B- -B----------------------B- -B----------------------B- -B----------------------B- -B----------------------B- 
------C------------C------ -----C--------------C----- ----C----------------C---- ----C----------------C---- ---C------------------C--- ---C------------------C--- ---C------------------C--- --B--------------------B-- --B--------------------B-- --B--------------------B-- -B----------------------B- -B----------------------B- -B----------------------B- B------------------------B B------------------------B B------------------------B B------------------------B B------------------------B B------------------------B B------------------------B B------------------------B B------------------------B B------------------------B B------------------------B B------------------------B B------------------------B B------------------------B B------------------------B B------------------------B 
------C------------C------ -----C--------------C----- ----C----------------C---- ----C----------------C---- ---C------------------C--- ---C------------------C--- ---C------------------C--- --B--------------------B-- --B--------------------B-- --B--------------------B-- -B----------------------B- -B----------------------B- -B----------------------B- B------------------------B B------------------------B B------------------------B B------------------------B B------------------------B B------------------------B B------------------------B B------------------------B B------------------------B B------------------------B B------------------------B B------------------------B B------------------------B B------------------------B B------------------------B B------------------------B 
------C------------C------ -----C--------------C----- ----C----------------C---- ----C----------------C---- ---C------------------C--- ---C------------------C--- ---C------------------C--- --A--------------------A-- --A--------------------A-- --A--------------------A-- -A----------------------A- -A----------------------A- -A----------------------A- A------------------------A A------------------------A A------------------------A A------------------------A A------------------------A A------------------------A A------------------------A A------------------------A A------------------------A A------------------------A A------------------------A A------------------------A A------------------------A A------------------------A A------------------------A A------------------------A 
------C------------C------ -----C--------------C----- ----C----------------C---- ----C----------------C---- ---C------------------C--- ---C------------------C--- ---C------------------C--- --A--------------------A-- --A--------------------A-- --A--------------------A-- -A----------------------A- -A----------------------A- -A----------------------A- A------------------------A A------------------------A A------------------------A A------------------------A A------------------------A A------------------------A A------------------------A A------------------------A A------------------------A A------------------------A A------------------------A A------------------------A A------------------------A A------------------------A A------------------------A A------------------------A 
------C------------C------ -----C--------------C----- ----C----------------C---- ----C----------------C---- ---C------------------C--- ---C------------------C--- ---C------------------C--- --A--------------------A-- --A--------------------A-- --A--------------------A-- -A----------------------A- -A----------------------A- -A----------------------A- A------------------------A A------------------------A A------------------------A A------------------------A A------------------------A A------------------------A A------------------------A A------------------------A A------------------------A A------------------------A A------------------------A A------------------------A A------------------------A A------------------------A A------------------------A A------------------------A 
------C------------C------ -----C--------------C----- ----C----------------C---- ----C----------------C---- ---C------------------C--- ---C------------------C--- ---C------------------C--- --A--------------------A-- --A--------------------A-- --A--------------------A-- -A----------------------A- -A----------------------A- -A----------------------A- A------------------------A A------------------------A A------------------------A A------------------------A A------------------------A A------------------------A A------------------------A A------------------------A A------------------------A A------------------------A A------------------------A A------------------------A A------------------------A A------------------------A A------------------------A A------------------------A 
------C------------C------ -----C--------------C----- ----C----------------C---- ----C----------------C---- ---C------------------C--- ---C------------------C--- ---C------------------C--- --B--------------------B-- --B--------------------B-- --B--------------------B-- -B----------------------B- -B----------------------B- -B----------------------B- B------------------------B B------------------------B B------------------------B B------------------------B B------------------------B B------------------------B B------------------------B B------------------------B B------------------------B B------------------------B B------------------------B B------------------------B B------------------------B B------------------------B B------------------------B B------------------------B 
------C------------C------ -----C--------------C----- ----C----------------C---- ----C----------------C---- ---C------------------C--- ---C------------------C--- ---C------------------C--- --B--------------------B-- --B--------------------B-- --B--------------------B-- -B----------------------B- -B----------------------B- -B----------------------B- B------------------------B B------------------------B B------------------------B B------------------------B B------------------------B B------------------------B B------------------------B B------------------------B B------------------------B B------------------------B B------------------------B B------------------------B B------------------------B B------------------------B B------------------------B B------------------------B 
-------C----------C------- ------C------------C------ -----C--------------C----- -----C--------------C----- ----C----------------C---- ----C----------------C---- ----C----------------C---- ---B------------------B--- ---B------------------B--- ---B------------------B--- --B--------------------B-- --B--------------------B-- --B--------------------B-- -B----------------------B- -B----------------------B- -B----------------------B- -B----------------------B- -B----------------------B- -B----------------------B- -B----------------------B- -B----------------------B- -B----------------------B- -B----------------------B- -B----------------------B- -B----------------------B- -B----------------------B- -B----------------------B- -B----------------------B- -B----------------------B- 
--------C--------C-------- ------CC----------CC------ -----C--------------C----- -----C--------------C----- ----C----------------C---- ----C----------------C---- ----C----------------C---- ---A------------------A--- ---A------------------A--- ---A------------------A--- --A--------------------A-- --A--------------------A-- --A--------------------A-- -A----------------------A- -A----------------------A- -A----------------------A- -A----------------------A- -A----------------------A- -A----------------------A- -A----------------------A- -A----------------------A- -A----------------------A- -A----------------------A- -A----------------------A- -A----------------------A- -A----------------------A- -A----------------------A- -A----------------------A- -A----------------------A- 
---------CCCCCCCC--------- -------CC--------CC------- ------C------------C------ ------C------------C------ -----C--------------C----- -----C--------------C----- -----C--------------C----- ----A----------------A---- ----A----------------A---- ----A----------------A---- ---A------------------A--- ---A------------------A--- ---A------------------A--- --A--------------------A-- --A--------------------A-- --A--------------------A-- --A--------------------A-- --A--------------------A-- --A--------------------A-- --A--------------------A-- --A--------------------A-- --A--------------------A-- --A--------------------A-- --A--------------------A-- --A--------------------A-- --A--------------------A-- --A--------------------A-- --A--------------------A-- --A--------------------A-- 
-------------------------- ---------CCCCCCCC--------- -------CC--------CC------- -------CC--------CC------- ------C------------C------ ------C------------C------ ------C------------C------ ----AB--------------BA---- ----A----------------A---- ----A----------------A---- ---A------------------A--- ---A------------------A--- ---A------------------A--- --A--------------------A-- --A--------------------A-- --A--------------------A-- --A--------------------A-- --A--------------------A-- --A--------------------A-- --A--------------------A-- --A--------------------A-- --A--------------------A-- --A--------------------A-- --A--------------------A-- --A--------------------A-- --A--------------------A-- --A--------------------A-- --A--------------------A-- --A--------------------A-- 
-------------------------- -------------------------- ---------CCCCCCCC--------- ---------CCCCCCCC--------- -------CC--------CC------- -------CC--------CC------- -------CC--------CC------- -----AA------------AA----- -----AA------------AA----- -----AA------------AA----- ----B----------------B---- ----B----------------B---- ----B----------------B---- ---B------------------B--- ---B------------------B--- ---B------------------B--- ---B------------------B--- ---B------------------B--- ---B------------------B--- ---B------------------B--- ---B------------------B--- ---B------------------B--- ---B------------------B--- ---B------------------B--- ---B------------------B--- ---B------------------B--- ---B------------------B--- ---B------------------B--- ---B------------------B--- 
-------------------------- -------------------------- -------------------------- -------------------------- ---------CCCCCCCC--------- ---------CCCCCCCC--------- ---------CCCCCCCC--------- -------AB--------BA------- -------AB--------BA------- -------AB--------BA------- -----AA------------AA----- -----AA------------AA----- -----AA------------AA----- ----B----------------B---- ----B----------------B---- ----B----------------B---- ----B----------------B---- ----B----------------B---- ----B----------------B---- ----B----------------B---- ----B----------------B---- ----B----------------B---- ----B----------------B---- ----B----------------B---- ----B----------------B---- ----B----------------B---- ----B----------------B---- ----B----------------B---- ----B----------------B---- 
-------------------------- -------------------------- -------------------------- -------------------------- -------------------------- -------------------------- -------------------------- ---------BBAAAABB--------- ---------BBAAAABB--------- ---------BBAAAABB--------- -------AB--------BA------- -------AB--------BA------- -------AB--------BA------- -----AA------------AA----- -----AA------------AA----- -----AA------------AA----- -----AA------------AA----- -----AA------------AA----- -----AA------------AA----- -----AA------------AA----- -----AA------------AA----- -----AA------------AA----- -----AA------------AA----- -----AA------------AA----- -----AA------------AA----- -----AA------------AA----- -----AA------------AA----- -----AA------------AA----- -----AA------------AA----- 
-------------------------- -------------------------- -------------------------- -------------------------- -------------------------- -------------------------- -------------------------- -------------------------- -------------------------- -------------------------- ---------BBAAAABB--------- ---------BBAAAABB--------- ---------BBAAAABB--------- -------AB--------BA------- -------AB--------BA------- -------AB--------BA------- -------AB--------BA------- -------AB--------BA------- -------AB--------BA------- -------AB--------BA------- -------AB--------BA------- -------AB--------BA------- -------AB--------BA------- -------AB--------BA------- -------AB--------BA------- -------AB--------BA------- -------AB--------BA------- -------AB--------BA------- -------AB--------BA------- 
-------------------------- -------------------------- -------------------------- -------------------------- -------------------------- -------------------------- -------------------------- -------------------------- -------------------------- -------------------------- -------------------------- -------------------------- -------------------------- ---------BBAAAABB--------- ---------BBAAAABB--------- ---------BBAAAABB--------- ---------BBAAAABB--------- ---------BBAAAABB--------- ---------BBAAAABB--------- ---------BBAAAABB--------- ---------BBAAAABB--------- ---------BBAAAABB--------- ---------BBAAAABB--------- ---------BBAAAABB--------- ---------BBAAAABB--------- ---------BBAAAABB--------- ---------BBAAAABB--------- ---------BBAAAABB--------- ---------BBAAAABB--------- 
