model
size = 31 32 17, scale = 0.05, origin = -y
material 
  colors = A:#FFF B:#F8F8F8 C:#C1C1C1 D:#070707 E:#100 F:#333 G:#111 H:#3CF I:#AAA J:#7EBDFD K:#CCC L:#666 M:#888 N:#FF0 O:#060606 P:#FF9 Q:#FF53A9 R:#FF74CC S:#F69DFF T:#999 U:#F3F V:#066 W:#033 X:#603 Y:#606 Z:#C09 Aa:#099 Ab:#303 Ac:#0FF Ad:#0CC Ae:#F0C Af:#906 Ag:#777
voxels
8-2(15D16-15A16-)AB4AB2A3B3A16-6A5B2A2B16-2A5B3AB2A2B16-4A3BA2B2A2BA16-I13FT16-2(GFL)GLG2FDLFG16-OIAFIBFAFKCFACE16-EIAFTBFAFKCGACE16-EIAFGFD2(FG)FACE17-IAB2KBKB2KBAC18-IA2(CI)3CICAC18-CKEO5EOEIK18-CTEW2VGXYAbEMK18-CIEVAcAdFZAeYEMK18-CIEW2AaFAfZXEMK18-CI2(E3O)ETK18-IAAg8LBC17-EI11ACE14-2AFE5GD5GOF2A12-2AK4MFOMGF4MKAB12-7ATOIDM5A2B13-B2A4BLEF4B3A15-A2(B3A)B2A2BA16-ABA2B3A5BAB18-2AB8A20-11D21-9A49-D15-D14-A15-A14-D15-D2(14-A15CA)14-A15CB14-B15CB14-A15CA14-A3(15CB14-B)2(15CB14-A)E13CEA14-AE13CEB15-4(E13CE16-)E13CE11-B3A-E13CE-4A6-2AB2A15C5A6-2AB2A15C3A2B6-2AB2A15C5A7-4A15C2ABA8-2ABA15C3AB9-B2A15CA2B12-A15CB15-2A11C2A17-13D19-11A22-7D18-2(D17-D12-A17-A12-)2(A17-A12-)2(B17-B12-)A17-2(B12-2A15-A)B12-BA15-AB12-2A15-AB13-A15-A14-B15-A2(14-A15-B14-B15-B)15-A13-A10-A5-A13-A5-A4-B4-2A13-2A2(4-A)25-A4-BA23-AB4-3A21-2AB5-B2A19-2AB6-2B2A17-2A2B7-A2BA16-3B10-2A15-2A14-2D11-2D17-2A9-2A20-D7-D16-2(D19-D10-A19-A10-)A19-B10-B19-A10-A19-B10-B19-B10-A19-A11-2(A17-A12-)2(A17-B12-)B17-A12-B17-A13-B15-A14-B2(15-B14-A)15-B14-B15-A8-A5-A15-A5-A2-A27-B2-B27-B2-2A25-2B3-2A23-2A4-B2A21-2AB4-4A19-3AB5-4A17-3AB7-4A15-4A11-2(D15-)A13-A17-2D9-2D14-2(D19-D10-A19-A10-)A19-A10-B19-A10-A19-B10-B19-A10-A19-A2(10-2A17-2A)10-2A17-AB11-A17-B12-B17-A12-B17-B13-2(B15-B14-)2(A15-B14-)A15-A8-A5-A15-A5-2(A2-A27-)A2-B26-AB2-BA25-2B2-B2A23-A2B3-3A21-2AB4-4A19-3AB5-4A17-3AB8-A2D15-2D2(A13-)A17-D11-D14-2(D19-D10-A19-A10-)3(A19-A10-)A19-B5(10-A19-A)2(10-A19-B)11-B17-B3(12-B17-A)13-B15-A7-A6-B15-A6-BA28-ABA28-2AB28-AB-B26-AB2-BA25-BA2-B2A23-ABA3-3A21-2AB5-4A17-3AB7-2A2D15-2DAB11-2A14-A16-D12-D13-2(D19-D10-A19-A10-)A19-B3(10-A19-A)10-A19-B2(10-B19-A)3(10-A19-B)10-A19-A10-BA17-AB10-2A17-AB11-B17-A12-B17-B12-BA15-AB2(6-A)15-A6-2A3(28-3A)28-2A-A26-BA2-2A25-AB3-BA23-2A4-3A21-ABA6-AB19-2B10-DA15-AD14-2(D13-)2(D19-D10-A19-A10-)A19-A10-A19-B4(10-A19-A)10-A2(19-B10-B)2(19-A10-A)19-A10-BA2(17-2A10-2A)17-AB11-A17-A12-2A15-2A6-A5-2A15-2A5-2A28-3A28-A2B28-2AB28-B2A28-2B-A26-AB2-BA25-AB3-2A23-2A5-B2A19-3B9-DA15-AD14-2(D13-)2(D19-D10-A19-A10-)A2(19-B10-B)2(19-A10-A)19-B3(10-A19-A)2(10-B19-A)10-B19-B4(10-2A17-2A)10-3A15-3A5-A5-2A15-2A5-2A2(28-A2B)28-B2A28-2BA28-2A-A26-2A2-2A25-AB3-2A23-2A5-3A19-2BA9-DA15-AD14-2(D13-)2(D19-D10-A19-A10-)2(B19-A10-A19-B10-)A19-B10-A2(19-A10-B)3(19-B10-A)19-B2(10-2A17-2A)10-BA17-2A11-A17-B12-2A15-2A6-A5-2A15-2A5-2A2(28-2AB)28-3B28-BA-A26-2B2-2A25-AB3-2A23-2A4-3A21-3A6-BA19-AB10-DA15-AD14-2(D13-)D19-D10-A19-A10-D19-D2(10-B19-A)2(10-A19-B10-A19-A)2(10-A19-A)10-B19-A10-B2(19-B10-A)19-B10-BA17-AB10-BA17-2A11-2(B17-A12-)BA15-2A6-B6-A15-A6-AB28-3B28-B2A28-2B-A26-AB2-BA25-2A2-B2A23-2AB3-B2A21-3A5-3A19-2AB7-2ADA15-ADAB11-2(A15-)2(D13-)D19-D10-A19-A10-D19-D10-B19-B10-A19-B2(10-B19-A)10-B19-B10-B4(19-A10-A)19-B2(10-A19-A)11-B17-A12-A17-A12-B17-B12-A17-A13-B15-A8-B5-B15-A5-A3(2-A27-B)2-2A25-2A2-3A23-3A3-3A21-2AB4-4A19-4A5-4A17-2A2B8-A2D15-2D2(A13-)A17-2D9-2D14-D19-D10-A19-A10-D19-D10-B19-A10-A19-B10-B3(19-A10-A)19-A3(10-2A17-2A)11-3(A17-A12-)2A15-2A12-2A15-2A13-A15-B2(14-A15-A)8-A5-A15-A5-2(A2-A27-)A2-2A25-2A3-2A23-2A4-3A21-3A4-4A19-3AB5-4A17-3AB7-AB2A15-2A2B11-2D13-2D16-2AD7-D2A45-2(D19-D10-A19-A10-)A19-A10-B19-J10-B19-H2(10-A19-A)11-5(A17-A12-)A17-A13-4(A15-A14-)B15-A9-A4-A15-2(A4-)A25-A4-A25-B4-2A23-AB4-B2A21-A2B5-B2A19-2AB6-B3A17-3AB7-B3A15-A2BA10-2A15-2A14-2DAD7-DA2D76-2(D17-D12-A17-A12-)A17-H12-B17-J12-A17-J12-B17-A12-B17-B12-BA15-2A12-2A15-AS12-NA15-AR12-NA15-2A13-A15-A14-B15-A14-HA13-2A14-JA2(13-2A14-2A)13-AP15-B13-A11-3A2-A13-A2-B2A2(6-3A19-A2B)6-2PA19-A2B7-NP19-2A8-AN2A15-4A9-NPA15-2AB12-A15-B15-A2DAD5-DA2DA108-2D13-2D14-2A13-2A14-2D13-2D14-AB13-2A14-AB13-AH14-2A13-AH14-BA13-2A2(14-BA13-AB)14-2A13-QS14-2A13-QR14-NP13-2R14-AN13-AR14-3A11-3A14-3A11-2AB15-JA11-2A16-JA11-AB16-HA11-2A2(16-2A11-AN)14-S2BA11-3AB11-2SRA13-2A2B10-ASA15-3A10-3A15-2AB11-2A15-HA13-2A13-2H15-AB2(AD)3-DAD3A16-2BDAD5-DAD2A141-13D18-2A3G3D3G2A18-13D18-6AD6A18-BA3BADA4BA18-4ABADA3BAB18-AHJABAD6A18-A2JHBAD2AB3A18-2A2HBAD2AB2AQ18-2B2ABAD4A2U18-A3B2ADA2B2AQ18-ANP3AD6A18-NPAP2AD2ABA2B18-6ADA2B3A18-A2B3AD2AJH2A18-2A2(BA)DAH2J2A18-HA3BADA2H2AB18-H2A3BD6A18-AB4AD4ANA18-A3B2ADAB2A2P18-3A2BADA2B3A17-QS5AD2A3B2A15-2RQUQ2A3D4AB2A14-AQUQ2A2(DA)D3AHJA15-4ADAD-DAD2A2J17-B2(AD)3-DAD2A195-
