model
size = 31 32 17, scale = 0.05, origin = -y
material 
  colors = A:#FFF B:#100 C:#060606 D:#111 E:#F8F8F8 F:#777 G:#CCC H:#888 I:#666 J:#AAA K:#C1C1C1 L:#999 M:#070707 N:#333
voxels
9-13B18-13A18-E12A18-I2A2EI3CHE2A18-2DFMBD3L2CHA18-ND2BDE4AGCI18-C2BC7AGC18-3BI8AG18-2BMCJ8A18-2BFGCG7A18-2BLALC7A18-2BJ2ADH6A18-BDK2AEDK5A18-BDK3AKCE4A18-BDK4AHC4A18-2BJ5AID2AE18-2BH5AECGNM18-2BC6AJD2B18-CBDF6AF2B18-ECBD6A2DB18-AEIBD5FB2D17-4AK6BIJLI15-15AGF14-8AB6AEC15-6AB-B6A17-4AB3-B4A202-2B13-2B14-2A13-2A14-EF13-2A14-AG13-2A14-AH13-2A14-2A13-2A14-AE13-FA14-AF13-JA14-GM13-2A14-HB13-2A14-C3(B13-2A14-D)BA11-3A14-DBA11-3A15-BA11-2A16-MA11-AF16-HA11-AB16-2A11-AD16-2A11-AF14-3BA11-AK2B11-4A13-AG2A2(10-3A15-3A)11-2A15-2(2A13-)2A15-5AB3-B5A16-4AB5-B4A138-B17-B8(12-A17-A)4(12-2A15-2A)13-2(A15-A14-)DA13-2A14-HA13-AE14-2A13-AL14-2A13-AJ15-A13-A11-3B2-B13-B2-3B3(6-3A19-3A)7-2A19-2A8-4A15-4A9-3A15-3A12-2(A15-)4AB5-B4A106-B19-B8(10-A19-A)11-5(A17-A12-)A17-A13-4(A15-A14-)A15-A9-B4-B15-2(B4-)2(A25-A4-)2A23-2A4-3A21-3A5-3A19-3A6-4A17-4A7-4A15-4A10-2A15-2A14-3AB7-B3A75-B19-B8(10-A19-A)3(10-2A17-2A)11-3(A17-A12-)2A15-2A12-2A15-2A13-2(A15-A14-)A15-A8-B5-B15-B5-B2(2-A27-A)2-2A25-2A3-2A23-2A4-3A21-3A4-4A19-4A5-4A17-4A7-4A15-4A11-2A13-2A16-2AB7-B2A45-B19-B14(10-A19-A)11-3(A17-A12-)A17-A13-A15-A8-B5-B15-B5-B3(2-A27-A)2-2A25-2A2-3A23-3A3-3A21-3A4-4A19-4A5-4A17-4A8-3A15-3A2(13-A)17-2B9-2B14-B19-B14(10-A19-A)2(10-2A17-2A)11-2(A17-A12-)2A15-2A2(6-B)15-B6-BA2(28-3A)28-2A-A26-2A2-2A25-2A2-3A23-3A3-3A21-3A5-3A19-3A7-4A15-4A11-2(A15-)2(B13-)B19-B14(10-A19-A)3(10-2A17-2A)11-A17-A12-2A15-2A6-B5-BA15-AB5-BA3(28-3A)28-2A-A26-2A2-2A25-2A3-2A23-2A4-3A21-3A6-2A19-2A10-2A15-2A14-2(B13-)B19-B14(10-A19-A)4(10-2A17-2A)10-3A15-3A2(5-B)A15-AB5-BA4(28-3A)28-2A-A26-2A2-2A25-2A3-2A23-2A5-3A19-3A9-2A15-2A14-2(B13-)B19-B14(10-A19-A)3(10-2A17-2A)11-A17-A12-2A15-2A6-B5-BA15-AB5-BA4(28-3A)28-2A-A26-2A2-2A25-2A3-2A23-2A5-3A19-3A9-2A15-2A14-2(B13-)B19-B14(10-A19-A)2(10-2A17-2A)11-2(A17-A12-)2A15-2A2(6-B)15-B6-BA3(28-3A)28-2A-A26-2A2-2A25-2A3-2A23-2A4-3A21-3A6-2A19-2A10-2A15-2A14-2(B13-)B19-B14(10-A19-A)11-3(A17-A12-)A17-A13-A15-A7-B6-B15-B6-BA2(28-3A)28-2A-A26-2A2-2A25-2A2-3A23-3A3-3A21-3A5-4A17-4A7-4A15-4A11-2A14-A16-B12-B13-B19-B8(10-A19-A)3(10-2A17-2A)11-2(A17-A12-)A17-A13-4(A15-A14-)A15-A8-B5-B15-B5-B2(2-A27-A)2-A26-2A2-2A25-2A2-3A23-3A3-3A21-3A4-4A19-4A5-4A17-4A8-3A15-3A2(13-A)17-B11-B14-B19-B8(10-A19-A)11-5(A17-A12-)A17-A13-4(A15-A14-)A15-A8-B5-B15-B5-B2(2-A27-A)2-2A25-2A3-2A23-2A4-3A21-3A4-4A19-4A5-4A17-4A7-4A15-4A11-2(A15-)A13-A17-2B9-2B15-B17-B8(12-A17-A)4(12-2A15-2A)13-5(A15-A14-)2(A15-)A13-A10-B4-2B13-2B4-B4-A4-2A13-2A2(4-A)25-A4-2A23-2A4-3A21-3A5-3A19-3A6-4A17-4A7-4A16-3A10-2A15-2A14-2A11-2A17-2A9-2A20-B7-B18-B15-B2(14-A15-A)12(14-17A)15-4(15A16-)15A11-4B-B13AB-4B3(6-25A)7-23A8-23A9-21A12-17A15-15A17-13A19-11A22-7B20-15B16-15A16-6A2C3(7A16-7AC)7A16-5A5C5A16-7AC7A16-15A4(16-5AC3AC5A)17-5A4C4A18-8AC4A18-13A18-5A3C5A18-4AC3AC4A18-8AC4A18-5A4C4A18-4AC3AC4A17-6A3C6A14-19A12-7A4C8A12-11AC7A13-10AC6A15-9AC5A16-9AC5A18-3A4C4A20-11A21-9A42-
