model
size = 19 32 31, scale = 0.05, origin = -y
material 
  colors = A:#6E75A4 B:#211E55
voxels
484-A17-3A15-5A15-3A547-2A-2A13-2A3-2A12-A5-A13-A3-A15-3A526-2A5-2A10-A7-A9-2A7-2A8-A-A5-A-A10-2A3-2A14-3A506-A9-A7-2A9-2A6-A11-A6-2(A-A7-)3A5-3A11-5A446-2(A13-A4-)2A11-2A4-2A11-2A5-A11-A5-A13-A4-A13-A5-2A9-2A8-2A2-2A-2A12-5A293-2(2A13-2A2-)2A13-2A40-2(2A13-2A2-)3(A15-A2-)A15-A3-3(A13-A4-)2A11-2A6-2A7-2A10-7A273-2A13-2A2(2-A15-A)-A17-A-2A13-2A2-2A13-2A-A4(17-2A)17-A-3(A15-A2-)A15-A3-2A11-2A6-2A7-2A10-7A273-2A13-2A2-A15-A-A8(17-2A)17-A-3(A15-A2-)A15-A3-A13-A5-2A9-2A8-9A291-2A13-2A2(-A)13-A-8(2A17-)3A16-2A17-A-A15-A2-A15-A3-A13-A5-2A9-2A8-9A310-A15-2(A-)A13-A-10(2A17-)A-A15-A3-2A11-2A6-2(A9-)9A235-5A5-5A3-5A7-4A3-3(2A13-2A2-)A15-A-A8(17-2A)17-A-A15-A2-A15-A3-2A11-2A6-2(A9-)9A217-6A-6A5-2(A4-A3-)A15-A2-A15-A-A16-A-A10(17-2A)17-A-A15-A3-A13-A5-A11-A7-2(A9-)9A199-11A7-A4-3A4-A5-2(A4-A3-)A15-A2-A15-A-A10(17-2A)17-A-A15-A2-A15-A3-A13-A5-A11-A7-2(A9-)9A182-7A10-2(2A7-)A11-A5-A4-5A4-A3-A15-A2-A15-A-A16-A-A8(17-2A)17-A-A15-A2-A15-A3-A13-A4-A13-A5-A11-A2(7-2A)10-7A182-9A2(9-A)7-A11-2(A5-)3A5-A4-A13-A3-A15-A2-A15-A-A7(17-2A)17-A-2(A15-A2-)A15-A3-A13-A5-A11-A7-2(A9-)2A5-2A12-5A184-7A10-2(2A7-)A11-A6-A11-A5-A13-A3-2(A15-A2-)A15-A-A3(17-2A)17-A-4(A15-A2-)A15-A3-A13-A4-A13-A5-A11-A7-2(A9-)9A14-A186-7A10-2A7-A8-A10-2A6-A11-A5-A13-A4-A13-A3-9(A15-A2-)A15-A3-A13-A4-A13-A5-A11-A6-2A9-2A8-2A5-2A12-5A204-5A12-2A5-2A2(9-A)7-A11-A6-A11-A5-A13-A4-A13-A3-6(A15-A2-)A15-A3-2(A13-A4-)A13-A5-A11-A6-A11-A2(7-2A)10-7A15-A207-3A14-2A3-2A10-2A7-2A8-A9-A7-A11-A5-10(A13-A4-)A13-A5-A11-A6-A11-A2(7-2A)9-4A-4A12-5A242-B4A13-A5-A11-A7-2(A9-)A7-2(A11-A6-)A11-A5-2A11-2A2(4-A13-A)5-4(A11-A6-)A10-2A7-A9-A8-2A7-2A10-3A-3A13-5A16-A263-5B13-2A3-2A11-A7-2(A9-)3(A8-A9-)A7-2(2A9-2A6-)2A9-2A7-2(A9-A8-)2A7-2A8-3A5-2A10-4A-4A11-7A15-A169-3A16-3A15-5(5A14-)B3-B14-B3-B13-7A11-8(9A10-)9A11-7A13-5A16-A188-3A15-A3-A13-2A3-2A6(12-A5-A)13-B3-B14-B3-B15-B-B2(16-3A)15-3(5A14-)5A15-3A17-A226-3A15-A3-A13-8(A5-A12-)A5-A13-2A-2A16-B359-3A15-A3-A13-9(A5-A12-)2A3-A15-3A377-3A15-A3-A13-8(A5-A12-)A5-A13-5A377-A17-A-A15-2(A3-A14-)A3-A13-3(A5-A12-)2A3-2A12-2A3-2A13-5A14-5A395-3A16-A-A15-A3-A5(14-5A)15-3A16-3A434-2(3A16-)3A568-A18-A588-A18-A579-
