model
size = 29 32 21, scale = 0.05, origin = -y
material 
  colors = A:#F90 B:#111 C:#888 D:#050 E:#EEE F:#AAA
voxels
593-6A22-2AEAE3A21-A5E2A21-2AE3AEA21-2(2AE)2A21-2AE3AEA21-A5E2A22-2(AE)2A82-4B604-6A22-8A20-10A10-C8-4(10A19-)10A20-8A22-6A25-2A24-2B4A2B22-6A545-6A22-8A20-10A18-2(12A9-C7-)3(12A17-)12A18-10A20-8A21-8A18-3B8A3B18-8A75-2(3(4A9-4A12-)4A9-4A70-)3(4A9-4A12-)4A3-2A4-4A16-8A20-10A18-12A17-12A9-C7-12A9-C6-14A15-14A16-2(12A17-)12A18-10A19-10A15-2B14A2B12-16A12-2(6A7-6A10-6A7-6A9-3(8A5-8A8-)8A5-8A9-)6A7-6A10-6A7-6A9-3(8A5-8A8-)12A-8A9-19A11-17A14-12A17-12A16-2(14A8-C6-)14A15-14A16-3A6-3A17-3A6-3A16-4A6-4A14-5A6-5A11-B6A6-6AB9-7A6-7A9-2(8A5-8A8-8A5-8A7-3(10A3-10A6-)10A3-10A7-)8A5-8A8-8A5-8A7-3(10A3-10A6-)23A7-21A9-19A11-17A13-15A14-15A7-C6-14A8-C6-2(14A15-)4A6-4A15-4A6-4A13-6A6-6A10-7A6-7A7-2B7A6-7AB7-7A8-7A7-2A6-17(2A3-3(2A6-))7A2(6-2A)6-7A6-2A7-A6-7A6-A9-2(2A4-7A4-2A10-)19A11-17A6-C6-15A7-C6-15A13-5A6-6A12-5A6-6A10-7A6-7A9-7A6-7A7-B6A9-7AB6-5A12-5A7-2(2A6-2A3-3(2A6-)2A3-2A6-2A5-3(3A6-3A-3A6-3A4-)3A6-3A-3A6-3A5-)2A6-2A3-3(2A6-)2A3-2A6-2A5-3(3A6-3A-3A6-3A4-)3A6-7A6-3A5-2A6-7A2(6-2A)6-7A6-2A7-2(A6-7A6-A8-)21A9-19A5-C5-17A6-C4-19A9-2(7A6-8A8-)7A6-8A7-6A8-8A6-B5A12-5AB5-5A15-4A2(6-2A)2(3-3(2A6-)2A3-2A6-2A5-3(3A6-3A-3A6-3A4-)3A6-3A-3A6-3A5-2A6-2A)3-3(2A6-)2A3-2A6-2A5-3(3A6-3A-3A6-3A4-)3A6-7A6-3A5-2A6-7A2(6-2A)6-7A6-2A7-2(A19-A8-)A18-2A8-A18-2A4-C3-2A17-2A4-F3-A18-2A4-C2-4A16-3A6-2(3A17-3A5-B)3A17-2A5-B4A17-3AB4-4A17-3A2(6-2A)2(3-3(2A6-)2A3-2A6-2A5-3(3A6-3A-3A6-3A4-)3A6-3A-3A6-3A5-2A6-2A)3-3(2A6-)2A3-2A6-2A5-3(3A6-3A-3A6-3A4-)3A6-3A-3A6-3A5-2A2(6-7A2(6-2A))2(19-2A6-2A)18-3A7-A18-2A4-C3-A18-2A4-F2-2A18-3A3-C-B3A17-3A5-B2(3A17-3A6-)3A17-3A4-B4A17-3AB4-4A17-3A2(6-2A)2(3-3(2A6-)2A3-2A6-2A5-3(3A6-3A-3A6-3A4-)3A6-3A-3A6-3A5-2A6-2A)3-3(2A6-)2A3-2A6-2A5-3(3A6-3A-3A6-3A4-)3A6-7A6-3A5-2A2(6-7A2(6-2A))2(19-2A6-2A)18-3A-4B2-A18-2A5-2B2A18-3A3-C-B2A18-3A3-FB4A17-4A2-C-4A17-4A4-4A17-4A5-3A17-3A4-B4A17-3AB4-4A17-3A2(6-2A)11(3-3(2A6-)2A)5(3-2A6-2A2-2D2-2A6-2A)3-2A3(6-2A2-2D2-2A6-7A)6-2(2A2-2D2-2A19-)2A2-2D2-2A18-3A-B2(2D2-2A18-3A2-)DCB3A18-4A2-F-4A17-4A2-C-3(4A17-4A4-)B3A17-3AB4-4A17-3A2(7-8A5-8A8-8A5-8A7-3(10A3-10A6-)10A3-10A)7-8A5-8A8-8A5-8A7-3(10A3-10A6-)23A7-21A7-23A3(6-2A18-3A)-2B3-2A18-3A3-C2-2A18-3A3-C-3A18-4A2-FB4A17-4A2-C-3(4A17-4A4-)B3A17-3AB5-3A17-3A8-2(6A7-6A10-6A7-6A9-3(8A5-8A8-)8A5-8A9-)6A7-6A10-6A7-6A9-3(8A5-8A8-)3(21A8-)2(A18-2A8-)A18-2A7-2A18-3A3-C2-2A18-3A3-F-3A18-4A2-C-4A17-4A3-B3(4A17-4A4-)B3A17-3AB5-3A17-3A67-2(3(4A9-4A12-)4A9-4A70-)2(4A9-4A12-)5A7-5A12-6A-3A-6A11-19A9-3(21A8-)21A4-C3-21A4-2(F2-23A3-)C-25A4-25A3-B25A4-B23A5-B23AB6-21A504-4A7-4A13-17A11-3(19A10-)19A5-C3-21A4-F3-21A4-C2-5(23A6-)B21AB7-21A539-3A20-3(15A14-)15A7-C4-19A5-F3-21A4-C3-21A7-2(23A6-)23A7-21A7-B21AB8-19A569-3A25-5A23-7A21-9A10-C6-15A7-C5-17A11-19A9-2(21A8-)9A3-9A9-7A5-7A8-3B5A7B5A2B11-3A9-3A629-3A13-C11-5A12-F11-5A12-C11-5A19-2(3A3-)3A13-2(5A7-5A12-)5A7-5A13-3A9-3A13-5B7-5B673-C28-C898-C287-
