model
size = 32 17 20, scale = 0.05, origin = -y
material 
  colors = A:#111 B:#EEE
voxels
44-2(8A24-)8A23-2ABA2BAB2A22-2A6B2A23-A2B2A2BA26-4B312-2A8-2A20-12A2(20-2A-6A-2A)20-B2-6A2-B20-B10-B20-AB8-BA21-A2B4-2BA23-BA4BAB25-2A2B2A246-3A8-3A3(18-A2-A6-A2-A)17-2A2-A6-A2-2A16-AB3-6A3-BA17-A12-A18-2A10-2A19-2A8-3A19-2AB6-B2A21-A8BA23-A6B180-5A8-5A3(14-2A-2A8-2A-2A)14-A2-2A8-2A2-A14-A3-2(2A2-)2A3-A15-A4-2A2-2A4-A16-A14-A16-2A13-A17-A12-A19-A10-A20-AB7-ABA21-10A25-A2-A115-5A12-5A10-2A2-A12-A2-2A11-6(A2-A12-)A3-A4-2A4-A3-A13-A3-2(2A2-)2A3-A14-A5-2A2-2A5-A14-A16-A15-A14-A16-2A12-2A17-A12-A19-B10-B21-3A-2A-3A24-6A80-7A12-7A6-2A4-A12-A4-2A7-2(2A3-A12-A3-2A8-)2A3-A12-A3-2A9-A3-A5-2A5-A3-A11-A3(3-2A)3-A12-A5-A2-2A2-A5-A12-A6-2A2-2A6-A13-A16-A14-A16-A15-A14-A17-B12-B19-B10-BA19-3A6-3A23-6A46-8A14-8A2-2A5-A14-A5-2A3-2A4-A14-A4-2A5-A4-A14-A4-A6-A4-A14-A4-A7-A4-A5-2A5-A4-A9-2(A4-)2A2(4-A)10-A5-A3-2A3-A5-A11-A5-A2-2A2-A5-A12-A6-6A6-A13-A6-3A7-A14-A16-A15-A14-A17-A12-A18-2A11-A20-2A6-3A23-7A12-9A14-10A7-A14-A7-3A6-A14-A6-2A-2A5-A14-A5-2A4-A3-A16-A3-A7-A3-A14-A3-A9-A3-A12-A3-2(A10-A4-)A11-A4-A8-A4-A12-A5-A6-A5-A13-A5-A3-2A6-A13-A6-3A8-A14-A15-2A14-A14-3A15-A12-A19-A10-A21-10A11-5A-2A16-2A-6A4-A-A16-A-A4-2A6-A16-A6-A-3A3-A16-A3-3A4-2A2-A16-A2-2A7-2A2-A14-A3-A9-2A2-A12-A3-A10-2A3-A10-A4-A11-2A3-A8-A5-A11-2A4-2(A6-)A12-2A4-A5-A6-A12-2A5-A2-2A7-A13-2A5-2A9-A13-3A12-4A14-3A8-3A19-12A21-10A11-2(5A-2A16-2A-6A4-A-A16-A-A4-5A3-A16-A3-4A4-A2-A16-A2-A9-A-A16-A-A11-A-5A6-5A2-A12-A2-3A6-3A4-A12-A3-2A6-2A5-2(A13-A3-2(A6-))A14-A2-2(A6-)A14-A3-A4-A7-A15-A3-4A8-A16-A8-7A17-8A76-)5A-2A16-2A-6A4-A-A16-A-A4-2A6-A16-A6-A-3A3-A16-A3-3A4-2A2-A16-A2-2A7-2A2-A14-A3-A9-2A2-A12-A3-A10-2A3-A10-A4-A11-2A3-A8-A5-A11-2A4-2(A6-)A12-2A3-A5-A7-A12-2A4-2A2-A8-A13-2A5-2A9-A13-3A12-4A14-3A8-3A19-12A21-10A11-9A14-10A7-A14-A7-3A6-A14-A6-2A-2A5-A14-A5-2A2(4-A)14-A4-A7-A3-A14-A3-A9-A3-A12-A3-2(A10-A4-)A11-A4-A8-A4-A12-A5-A6-A5-A13-A5-2A3-A6-A13-A7-3A7-A14-A15-2A14-A14-3A15-A12-A19-A10-A21-10A12-8A14-8A2-2A5-A14-A5-2A3-2A4-A14-A4-2A5-A4-A14-A4-A6-A4-A14-A4-A7-A4-A5-2A5-A4-A9-2(A4-)2A2(4-A)10-A5-A3-2A3-A5-A11-A5-A2-2A2-A5-A12-A6-6A6-A13-A7-3A6-A14-A16-A15-A14-A17-A12-A18-A12-A19-3A6-3A23-6A16-7A12-7A6-2A4-A12-A4-2A7-2(2A3-A12-A3-2A8-)2A3-A12-A3-2A9-A3-A5-2A5-A3-A11-A3(3-2A)3-A12-A5-A2-2A2-A5-A12-A6-2A2-2A6-A13-A16-A14-A16-A15-A14-A17-A12-A19-A10-A20-3A6-3A23-6A50-5A12-5A10-2A2-A12-A2-2A11-6(A2-A12-)A3-A4-2(2A3-)A13-A3-2(2A2-)A4-A14-A5-2A2-2A5-A14-A16-A15-A14-A16-2A12-2A17-2A10-2A19-A10-A21-10A24-6A84-5A8-5A4(14-2A-2A8-2A-2A)14-A3-2(2A2-)A4-A15-A4-2A2-2A4-A16-A14-A16-2A12-2A17-A12-A19-A10-A21-2A6-2A22-10A148-3A8-3A4(18-A2-2A4-2A2-A)17-2A3-6A3-2A17-A12-A18-2A10-2A19-2A8-2A20-3A6-3A21-10A24-6A183-2A8-2A20-12A3(20-2A2-4A2-2A)20-A10-A20-2A8-2A21-3A4-3A23-8A25-6A281-3(8A24-)8A23-10A23-8A26-4A302-
