model
size = 16 29 12, scale = 0.05, origin = -y
material 
  colors = A:#700
voxels
---------------- ---------------- ---------------- ---------------- ---------------- ---------------- ---------------- ---------------- ---------------- ---------------- ---------------- ---------------- ---------------- ---------------- ---------------- ---------------- ---------------- ---------------- ---------------- ----AAAAAAAA---- ---AAAAAAAAAA--- ---AAAAAAAAAA--- ---AAAAAAAAAA--- ---------------- ---------------- ---------------- ---------------- ---------------- ---------------- 
---------------- ---------------- ---------------- ---------------- ---------------- ---------------- -------AAA------ -----AAAAAA----- -----AAAAAA----- -----AAAAAA----- -----AAAAAA----- -----AAAAAA----- ------AAAAA----- ------AAAA------ ------AAAA------ ------AAAA------ -----AAAAAA----- -----AAAAAA----- ----AAAAAAAA---- ---A-AAAAAA-A--- --A-A------A-A-- --AA--------AA-- --A-AAAAAAAA-A-- ---AAAAAAAAAA--- ---------------- ---------------- ---------------- ---------------- ---------------- 
-AAAAAAAAAAAAAA- -AAAAAAAAAAAAAA- -AAAAAAAAAAAAAA- -AAAAAAAAAAAAAA- -AAAAAAAAAAAAAA- --AAAAAAAAAAAA-- --AAAAAAAAAAAA-- ---AAAAAAAAAA--- ---AAA----AAA--- ---AAA----AAA--- ---AAA----AAA--- ---AAAA--AAAA--- ----AAA--AAA---- ----AAA--AAA---- ----AAA--AAA---- ----AAA--AAA---- ----AAA--AAA---- ---AAA----AA---- ---AAA----A-A--- --A-A------A-A-- --AA--------AA-- --A----------A-- --AA--------AA-- --A-AAAAAAAA-A-- ---AAAAAAAAAA--- ---------------- ---------------- ---------------- ---------------- 
AAA----------AAA A-A----------AAA A-A----------AAA A-A----------AAA A-A----------A-A -AA----------AAA -AAA--------AAA- -AAA--------AAA- -AAA--------AAA- -AAA--------AAA- --AA--------AA-- --A-A------A-A-- ---AA------AA--- ---AA-----A-A--- ---AA-----A-A--- ---AA------AA--- ---AA------AA--- ---AA------AA--- ---A-------AA--- --AA--------AA-- --A----------A-- --A----------A-- --A----------A-- --AA--------AA-- --A-A------A-A-- ---A--------A--- ---------------- ---------------- ---------------- 
AA------------AA AA-------------A AA-------------A AA-------------A AA------------AA AA------------AA AA------------AA AA------------AA -A------------A- -AA----------AA- -AA----------AA- --AA--------AA-- --AA--------AA-- ---A-------AA--- ---AA------AA--- ---A--------A--- ---A--------A--- ---A--------A--- --AA--------AA-- --AA--------AA-- --A----------A-- --A----------A-- --A----------A-- --A----------A-- ---A--------A--- ---A--------A--- ---A--------A--- ---------------- ---------------- 
A--------------A A--------------A A--------------A A--------------A A--------------A A--------------A A--------------A AA------------AA -A------------A- -A------------A- -AA----------AA- --A----------A-- --AA--------AA-- --AA--------A--- --AA--------A--- ---A--------A--- ---A--------A--- --AA--------AA-- --AA--------AA-- --A----------A-- --A----------A-- --A----------A-- --A----------A-- --A----------A-- ---------------- ---A--------A--- ---A--------A--- ---A--------A--- ---------------- 
A--------------A A--------------A A--------------A A--------------A A--------------A A--------------A A--------------A AA------------AA -A------------A- -A------------A- -AA----------AA- --A----------A-- --AA--------AA-- --AA--------AA-- ---A--------A--- ---A--------A--- ---A--------A--- --AA--------AA-- --AA--------AA-- --A----------A-- --A----------A-- --A----------A-- --A----------A-- ---------------- ---------------- ---------------- ---------------- ---AA-------A--- ---AA-------A--- 
AA------------AA AA------------AA A--------------A A--------------A A--------------A AA------------AA AA------------AA AA------------AA -A------------A- -AA----------AA- -AA----------AA- --AA--------AA-- --AA--------AA-- ---AA------AA--- ---AA------AA--- ---AA------AA--- ---AA------AA--- ---A--------A--- --AA--------AA-- --AA--------AA-- --A----------A-- --A----------A-- --A----------A-- ---------------- ---------------- ---------------- ---------------- ---A--------A--- ---AA-------A--- 
AAA-----------AA AA------------AA AA------------AA AA------------AA AA------------AA AA------------AA AA------------AA -A------------A- -AA----------AA- -AA----------AA- --AA--------AA-- --A-A------A-A-- ---AAA----AAAA-- ---AAAAAAAA-A--- ----AAAAAAAA---- ---AAAAAAAAAA--- ---A-A----A-A--- ---AA------AA--- ---AA------AA--- --AA--------AA-- --AA--------AA-- --A----------A-- --A----------A-- ---------------- ---------------- ---------------- ---------------- ---------------- ---AA-------A--- 
-AAAAAAAAAAAAAA- -AAAAAAAAAAAAAA- -AAAAAAAAAAAAAA- -AAA--------AAA- -AA----------AA- -AA----------AA- -AA----------AA- -AA----------AA- -A-A---------AA- --AA--------AA-- --A-AAAAAAAA-A-- ---AAAAAAAAAA--- ----AAAAAAAA---- -----AAAAAAA---- -----AAAAAA----- -----AAAAAA----- ----AAAAAAAA---- ----AAAAAAAA---- ---AAAAAAAAAA--- ---AAA----AAA--- --A-A------A-A-- --AA--------AA-- ---------------- ---------------- ---------------- ---------------- ---------------- ---------------- ---AA------AA--- 
---------------- ---AAAAAAAAAA--- ---AAAAAAAAAA--- --AAAAAAAAAAAA-- --AAAAAAAAAAAA-- --AA--------AA-- --AA--------AA-- --AA--------AA-- --A-A------AAA-- --AAAAAAAAAAAA-- ---AAAAAAAAAA--- -----AAA-------- ---------------- ---------------- ---------------- ---------------- ---------------- ---------------- -----AAAAAA----- ----AAAAAAAA---- ---AAAAAAAAAA--- ---AAAAAAAAAA--- ---AA------A---- ---------------- ---------------- ---------------- ---------------- ---AA------AA--- ---AA------AA--- 
---------------- ---------------- ---------------- ---------------- ---AAAAAAAAAA--- ---AAAAAAAAAA--- ---AAAAAAAAAA--- ---AAAAAAAAAA--- ---AAAAAAAAAA--- ----AAAAAAAA---- ---------------- ---------------- ---------------- ---------------- ---------------- ---------------- ---------------- ---------------- ---------------- ---------------- ---------------- ----AAAAAAAA---- ----AAAAAAAA---- ----A------A---- ---AA------A---- ---AA------AA--- ---AA------AA--- ---AA------AA--- ---------------- 
