model
size = 32 11 32, scale = 0.05, origin = -y
material 
  colors = A:#D477AC B:#74415E C:#BEBEBE
voxels
12-8A341-14A336-18A333-20A331-22A329-24A327-10A6B10A16-6B26-6B27-4B240-9A2B6-2B9A13-2(10B22-)10B23-8A25-6A175-8AB10-B8A12-2(3B6-3B20-)4B4-4B20-2A8B2A21-2A6B2A23-8A27-2A112-8AB12-B8A2(10-2B)2(18-2B10-2B)18-A2B8-2BA19-A2B6-2BA21-A8BA23-8A27-2A80-7AB14-B7A9-3(2B12-2B16-)AB12-BA17-AB10-BA19-AB8-BA21-A8BA23-8A77-6AB16-B6A8-5(2B14-)2B15-AB12-BA16-AB12-BA17-AB10-BA19-A2B6-2BA21-2A6B2A24-6A45-7AB16-B7A7-6(2B14-)AB14-BA15-AB12-BA16-AB12-BA17-A2B8-2BA19-2A8B2A22-8A44-6AC18-C6A6-2B16-2B12-2B16-2B13-2B14-CB2(14-AB14-BA)15-AB12-BA17-AB10-CA19-A2CB4-B2CA21-3AB3C3A25-4A14-6AC18-C6A6-2(2B16-2B12-)2B16-2B13-AB14-CA14-AB14-BA15-AB12-BA17-AC10-BA19-A2B6-CBA21-2A3(CB)2A24-6A13-6AC18-B6A6-2B16-CB2(12-2B16-2B)13-AB14-BA14-AB14-BA15-AB12-BA16-2AC10-B2A17-2A2B6-2C2A20-2ACB2C2B2A24-6A13-6AC18-C6A6-2B16-CB2(12-2B16-2B)13-AB14-BA14-AB14-BA15-AB12-BA16-2AC10-B2A17-2A2B6-CB2A20-2ACB2C2B2A24-6A13-6AC18-C6A6-2(2B16-2B12-)2B16-2B13-AB14-CA14-AB14-BA15-AB12-BA17-AC10-BA19-A2B6-CBA21-2A3(CB)2A24-6A13-6AC18-C6A6-BC16-2B12-2B16-2B13-BC14-CB2(14-AB14-BA)15-AB12-BA17-AB10-CA19-A2CB4-B2CA21-3A2(BC)3A25-4A14-7AB16-B7A7-6(2B14-)AB14-BA15-AB12-BA16-AB12-BA17-A2B8-2BA19-2A8B2A22-8A45-6AB16-B6A8-5(2B14-)2B15-AB12-BA16-AB12-BA17-AB10-BA19-A2B6-2BA21-2A6B2A24-6A46-7AB14-B7A9-3(2B12-2B16-)AB12-BA17-AB10-BA19-AB8-BA21-A8BA23-8A77-8AB12-B8A2(10-2B)2(18-2B10-2B)18-A2B8-2BA19-A2B6-2BA21-A8BA23-8A27-2A81-8AB10-B8A12-2(3B6-3B20-)4B4-4B20-2A8B2A21-2A6B2A23-8A27-2A113-9A2B6-2B9A13-2(10B22-)10B23-8A25-6A176-10A6B10A16-6B26-6B27-4B242-24A329-22A331-20A333-18A336-14A341-8A332-
