model
size = 32 8 32, scale = 0.05, origin = -y
material 
  colors = A:#D477AC B:#74415E C:#BEBEBE
voxels
77-6A24-10A22-10A24-6A151-12A19-14A18-14A19-12A114-16A16-16A15-18A14-18A15-16A16-16A48-16A16-16A15-18A13-20A12-20A13-18A15-16A16-16A15-18A14-18A13-20A11-22A10-22A11-20A13-18A14-18A13-20A12-20A11-22A9-24A8-24A9-22A11-20A12-20A11-8A6B8A10-8A6B8A9-9A6B9A7-10A6B10A6-10A6B10A7-9A6B9A9-8A6B8A10-8A6B8A9-7A2B6-2B7A8-7A2B6-2B7A7-8A2B6-2B8A5-9A2B6-2B9A4-9A2B6-2B9A5-8A2B6-2B8A7-7A2B6-2B7A8-7A2B6-2B7A7-7AB10-B7A5-5(8AB10-B8A4-)8AB10-B8A5-7AB10-B7A6-6AB12-B6A5-7AB12-B7A4-7AB12-B7A3-8AB12-B8A2-8AB12-B8A3-7AB12-B7A4-7AB12-B7A5-6AB12-B6A6-5AB14-B5A5-6AB14-B6A3-3(7AB14-B7A2-)7AB14-B7A3-6AB14-B6A5-5AB14-B5A2(6-4AB16-B4A5-5AB16-B5A3-6AB16-B6A-7AB16-B14AB16-B7A-6AB16-B6A3-5AB16-B5A5-4AB16-B4A)6(6-3AB18-B3A5-4AB18-B4A2-6A3(B18-B12A)B18-B6A2-4AB18-B4A5-3AB18-B3A)6-4AB16-B4A5-5AC16-C5A3-6AC16-C6A-7AC16-B14AC16-B7A-6AC16-C6A3-5AC16-C5A5-4AB16-B4A6-4AB16-B4A5-5AC16-B5A3-6AB16-B6A-7AB16-C14AB16-C7A-6AB16-B6A3-5AB16-B5A5-4AB16-B4A6-5AB14-B5A5-6AC14-C6A3-7AB14-C2(7A2-7AB14-B)7A2-7AB14-C7A3-6AB14-C6A5-5AB14-B5A6-6AB12-B6A5-7AB12-B7A4-7AB12-B7A3-8AB12-B8A2-8AB12-B8A3-7AB12-B7A4-7AB12-B7A5-6AB12-B6A6-7AB10-B7A5-8AB10-C4(8A4-8AC10-B)8A4-8AB10-C8A5-7AB10-B7A7-7A2B6-2B7A8-7A2C6-2C7A7-8A2B6-CB8A5-9A2B6-CB9A4-9A2B6-2C9A5-8A2B6-CB8A7-7A2C6-2C7A8-7A2B6-2B7A9-8A6B8A10-8A2B2(CB)8A9-9A3(CB)9A7-10ACB2C2B10A6-10ACB2C2B10A7-9A3(CB)9A9-8A2B3CB8A10-8A6B8A11-20A12-20A11-22A9-24A8-24A9-22A11-20A12-20A13-18A14-18A13-20A11-22A10-22A11-20A13-18A14-18A15-16A16-16A15-18A13-20A12-20A13-18A15-16A16-16A48-16A16-16A15-18A14-18A15-16A16-16A114-12A19-14A18-14A19-12A151-6A24-10A22-10A24-6A77-
