model
size = 31 32 17, scale = 0.05, origin = -y
material 
  colors = A:#FFF B:#FFFFDC C:#FFFFA5 D:#FFFF6E E:#FFFF37 F:#007A30 G:#FF0
voxels
9-13G2(18-13F)2(18-13G)5(18-13E)5(18-13D)5(18-13C)18-13B17-15B15-17B14-8BF8B15-6BF-F6B17-4AF3-F4A202-2G13-2G2(14-2F13-2F)2(14-2G13-2G)5(14-2E13-2E)3(14-2D13-2D)2(14-3D11-3D)15-4(2C11-2C16-)2C11-2C14-2(4B11-)3FB13-B3F2(10-3B15-3B)11-2B15-2B2(13-2A)15-5AF3-F5A16-4AF5-F4A138-G17-G2(12-F17-F)2(12-G17-G)4(12-E17-E)12-2E15-2E3(12-2D15-2D)13-2(D15-D14-)3(2C13-2C14-)2C13-2C15-C13-C11-3B2-B13-B2-3B6-2FB19-B2F2(6-3B19-3B)7-2B19-2B8-4A15-4A9-3A15-3A12-2(A15-)4AF5-F4A106-G19-G2(10-F19-F)2(10-G19-G)4(10-E19-E)11-E17-E5(12-D17-D)13-4(C15-C14-)C15-C9-B4-B15-2(B4-)F25-F4-B25-B4-2B23-2B4-3B21-3B5-3A19-3A6-4A17-4A7-4A15-4A10-2A15-2A14-3AF7-F3A75-G19-G2(10-F19-F)10-G2(19-G10-E)3(19-E10-E)19-E10-2E17-2E2(10-2D17-2D)11-3(D17-D12-)2C15-2C12-2C15-2C13-2(C15-C14-)C15-C8-B5-B15-B5-B2-F27-F2-B27-B2-2B25-2B3-2B23-2B4-3A21-3A4-4A19-4A5-4A17-4A7-4A15-4A11-2A13-2A16-2AF7-F2A45-G19-G2(10-F19-F)10-G2(19-G10-E)4(19-E10-E)19-E5(10-D19-D)11-3(C17-C12-)C17-C13-C15-C8-B5-B15-B5-B2-F27-F2(2-B27-B)2-2B25-2B2-3A23-ABA3-3A21-3A4-4A19-4A5-4A17-4A8-3A15-3A2(13-A)17-2F9-2F14-G19-G2(10-F19-F)10-G2(19-G10-E)4(19-E10-E)19-E5(10-D19-D)2(10-2C17-2C)11-2(C17-C12-)2C15-2C2(6-B)15-B6-BF28-BFB28-3B28-2B-B26-2B2-2A25-2A2-3A23-3A3-3A21-3A5-3A19-3A7-4A15-4A11-2(A15-)2(F13-)G19-G2(10-F19-F)10-G2(19-G10-E)4(19-E10-E)19-E5(10-D19-D)3(10-2C17-2C)11-C17-C12-2C15-2C6-B5-2B15-2B5-BF28-BFB2(28-3B)28-2B-A26-2A2-2A25-2A3-2A23-2A4-3A21-3A6-2A19-2A10-2A15-2A14-2(F13-)G19-G2(10-F19-F)10-G2(19-G10-E)4(19-E10-E)19-E5(10-D19-D)4(10-2C17-2C)10-3C15-3C5-B5-2B15-2B5-BF4(28-B2F)28-AF-F26-AF2-FA25-AF3-FA23-AF5-3F19-3F9-2F15-2F14-2(F13-)G19-G2(10-F19-F)10-G2(19-G10-E)4(19-E10-E)19-E5(10-D19-D)3(10-2C17-2C)11-C17-C12-2C15-2C6-B5-2B15-2B5-BF4(28-B2F)28-AF-F26-AF2-FA25-AF3-FA23-AF5-3F19-3F9-2F15-2F14-2(F13-)G19-G2(10-F19-F)2(10-G19-G)5(10-E19-E)5(10-D19-D)2(10-2C17-2C)11-2(C17-C12-)2C15-2C2(6-B)15-B6-BF28-BFB2(28-3B)28-2B-A26-2A2-2A25-2A3-2A23-2A4-3A21-3A6-2A19-2A10-2A15-2A14-2(F13-)G19-G2(10-F19-F)2(10-G19-G)5(10-E19-E)5(10-D19-D)11-3(C17-C12-)C17-C13-C15-C7-B6-B15-B6-BF28-BFB28-3B28-2B-B26-2B2-2A25-2A2-3A23-3A3-3A21-3A5-4A17-4A7-4A15-4A11-2A14-A16-F12-F13-G19-G2(10-F19-F)2(10-G19-G)4(10-E19-E)10-2E17-2E2(10-2D17-2D)11-2(D17-D12-)D17-D13-4(C15-C14-)C15-C8-B5-B15-B5-B2-F27-F2-B27-B2-B26-2B2-2B25-2B2-3A23-3A3-3A21-3A4-4A19-4A5-4A17-4A8-3A15-3A2(13-A)17-F11-F14-G19-G2(10-F19-F)2(10-G19-G)4(10-E19-E)11-E17-E5(12-D17-D)13-4(C15-C14-)C15-C8-B5-B15-B5-B2-F27-F2-B27-B2-2B25-2B3-2B23-2B4-3A21-3A4-4A19-4A5-4A17-4A7-4A15-4A11-2(A15-)A13-A17-2F9-2F15-G17-G2(12-F17-F)2(12-G17-G)4(12-E17-E)12-2E15-2E3(12-2D15-2D)13-2(D15-D14-)3(C15-C14-)2(C15-)C13-C10-B5-B13-B5-B4-F4-2B13-2B4-F4-B25-B4-2B23-2B4-3B21-3B5-3A19-3A6-4A17-4A7-4A16-3A10-2A15-2A14-2A11-2A17-2A9-2A20-F7-F18-G15-G2(14-F15-F)2(14-17G)5(14-17E)5(14-17D)15-4(15C16-)15C11-4B-15B-4B6-5F15B5F2(6-25B)7-23B8-23A9-21A12-17A15-15A17-13A19-11A22-7F20-15G2(16-15F)2(16-15G)5(16-15E)3(16-15D)17-2(13D18-)5(13C18-)13B17-F13BF14-2(19B12-)19B13-17A15-15A16-15A18-11A20-11A21-9A42-
