model
size = 31 32 17, scale = 0.05, origin = -y
material 
  colors = A:#777 B:#111 C:#EEE
voxels
9-6(13A18-)3A7B3A18-2AB7CB2A18-2A2(B2C)BC6(B2A18-2ABC2(B2C))B2A18-2A2(B2C)BCB2A18-2AB7CB2A18-A11BA18-AB9CBA18-2A9B2A18-4AB3AB4A17-6A3B6A15-17A14-8AB8A15-6AB-B6A17-4AB3-B4A202-13(2A13-2A14-)3A11-3A14-3A11-3A15-4(2A11-2A16-)2A11-2A14-2B2A11-2A2B11-4A13-4A2(10-3A15-3A)11-2A15-2(2A13-)2A15-5AB3-B5A16-4AB5-B4A138-9(A17-A12-)3(2A15-2A12-)2A15-2A13-2(A15-A14-)3(2A13-2A14-)2A13-2A15-A13-A11-3B2-A13-A2-3B3(6-3A19-3A)7-2A19-2A8-4A15-4A9-3A15-3A12-2(A15-)4AB5-B4A106-8(A19-A10-)A19-A11-5(A17-A12-)A17-A13-4(A15-A14-)A15-A9-B4-A15-A4-B2(4-A25-A)4-2A23-2A4-3A21-3A5-3A19-3A6-4A17-4A7-4A15-4A10-2A15-2A14-3AB7-B3A75-9(A19-A10-)2(2A17-2A10-)2A17-2A11-3(A17-A12-)2A15-2A12-2A15-2A13-2(A15-A14-)A15-A8-B5-A15-A5-B2(2-A27-A)2-2A25-2A3-2A23-2A4-3A21-3A4-4A19-4A5-4A17-4A7-4A15-4A11-2A13-2A16-2AB7-B2A45-14(A19-A10-)A19-A11-3(A17-A12-)A17-A13-A15-A8-B5-A15-A5-B3(2-A27-A)2-2A25-2A2-3A23-3A3-3A21-3A4-4A19-4A5-4A17-4A8-3A15-3A2(13-A)17-2B9-2B14-15(A19-A10-)2A17-2A10-2A17-2A11-2(A17-A12-)2A15-2A6-B6-A15-A6-BA2(28-3A)28-2A-A26-2A2-2A25-2A2-3A23-3A3-3A21-3A5-3A19-3A7-4A15-4A11-2(A15-)2(B13-)15(A19-A10-)2(2A17-2A10-)2A17-2A11-A17-A12-2A15-2A6-B5-2A15-2A5-BA3(28-3A)28-2A-A26-2A2-2A25-2A3-2A23-2A4-3A21-3A6-2A19-2A10-2A15-2A14-2(B13-)15(A19-A10-)4(2A17-2A10-)3A15-3A5-B5-2A15-2A5-BA4(28-3A)28-2A-A26-2A2-2A25-2A3-2A23-2A5-3A19-3A9-2A15-2A14-2(B13-)15(A19-A10-)2(2A17-2A10-)2A17-2A11-A17-A12-2A15-2A6-B5-2A15-2A5-BA4(28-3A)28-2A-A26-2A2-2A25-2A3-2A23-2A5-3A19-3A9-2A15-2A14-2(B13-)15(A19-A10-)2A17-2A10-2A17-2A11-2(A17-A12-)2A15-2A6-B6-A15-A6-BA3(28-3A)28-2A-A26-2A2-2A25-2A3-2A23-2A4-3A21-3A6-2A19-2A10-2A15-2A14-2(B13-)14(A19-A10-)A19-A11-3(A17-A12-)A17-A13-A15-A7-B6-A15-A6-BA2(28-3A)28-2A-A26-2A2-2A25-2A2-3A23-3A3-3A21-3A5-4A17-4A7-4A15-4A11-2A14-A16-B12-B13-9(A19-A10-)2(2A17-2A10-)2A17-2A11-2(A17-A12-)A17-A13-4(A15-A14-)A15-A8-B5-A15-A5-B2(2-A27-A)2-A26-2A2-2A25-2A2-3A23-3A3-3A21-3A4-4A19-4A5-4A17-4A8-3A15-3A2(13-A)17-B11-B14-8(A19-A10-)A19-A11-5(A17-A12-)A17-A13-4(A15-A14-)A15-A8-B5-A15-A5-B2(2-A27-A)2-2A25-2A3-2A23-2A4-3A21-3A4-4A19-4A5-4A17-4A7-4A15-4A11-2(A15-)A13-A17-2B9-2B15-9(A17-A12-)3(2A15-2A12-)2A15-2A13-5(A15-A14-)2(A15-)A13-A10-B5-A13-A5-B4-A4-2A13-2A2(4-A)25-A4-2A23-2A4-3A21-3A5-3A19-3A6-4A17-4A7-4A16-3A10-2A15-2A14-2A11-2A17-2A9-2A20-B7-B18-3(A15-A14-)11(17A14-)17A15-4(15A16-)15A11-4B-15A-4B3(6-25A)7-23A8-23A9-21A12-17A15-15A17-13A19-11A22-7B20-12(15A16-)15A17-7(13A18-)13A17-15A14-4A2(3BA)3B4A2(12-5AB2ABAB2AB5A)13-4AB2ABAB2AB4A15-3A2BA3B2A2B2A16-15A18-11A20-11A21-9A42-
