model
size = 31 32 17, scale = 0.05, origin = -y
material 
  colors = A:#000 B:#FF0
voxels
9-5(2(13A18-)2(13B18-))13A17-15A15-17B14-17B15-7A-7A17-5A3-5A202-3(2(2A13-2A14-)2(2B13-2B14-))2A13-2A14-3A11-3A14-3B11-3B15-2B11-2B2(16-2A11-2A)2(16-2B11-2B)14-2(4A11-)4A13-4A2(10-3B15-3B)11-2A15-2(2A13-)2A15-6B3-6B16-5B5-5B138-2(2(A17-A12-)2(B17-B12-))A17-A12-2A15-2A2(12-2B15-2B)12-2A15-2A13-A15-A14-B15-B14-2B13-2B2(14-2A13-2A)14-2B13-2B15-B13-B11-3A2-A13-A2-3A6-3A19-3A2(6-3B19-3B)7-2A19-2A8-4A15-4A9-3B15-3B12-2(B15-)5A5-5A106-2(2(A19-A10-)2(B19-B10-))A19-A11-A17-A2(12-B17-B)2(12-A17-A)12-B17-B13-B15-B2(14-A15-A)2(14-B15-B)9-A4-A15-2(A4-)A25-A4-B25-B4-2B23-2B4-3A21-3A5-ABA19-ABA6-4B17-4B7-4B15-4B10-2A15-2A14-4A7-4A75-2(2(A19-A10-)2(B19-B10-))A19-A10-2A17-2A2(10-2B17-2B)11-2(A17-A12-)B17-B12-2B15-2B12-2A15-2A13-A15-A2(14-B15-B)8-A5-A15-A5-A2-A27-A2-B27-B2-2B25-2B3-2A23-2A4-ABA21-ABA4-4B19-4B5-4B17-4B7-4A15-4A11-2A13-2A16-3B7-3B45-3(2(A19-A10-)2(B19-B10-))2(A19-A10-)B19-B11-B17-B2(12-A17-A)12-B17-B13-B15-B8-A5-A15-A5-A2-A27-A2(2-B27-B)2-2A25-2A2-ABA23-ABA3-3B21-3B4-4B19-4B5-2ABA17-AB2A8-3A15-3A2(13-B)17-2B9-2B14-3(2(A19-A10-)2(B19-B10-))2(A19-A10-)B19-B10-2B17-2B10-2A17-2A11-A17-A12-B17-B12-2B15-2B2(6-A)15-A6-2A28-2AB28-3B28-2B-A26-2A2-2A25-2A2-3B23-3B3-3B21-3B5-ABA19-ABA7-4A15-4A11-2(B15-)2(B13-)3(2(A19-A10-)2(B19-B10-))2(A19-A10-)B19-B10-2B17-2B2(10-2A17-2A)11-B17-B12-2B15-2B6-A5-2A15-2A5-2A28-2AB28-3B28-2BA28-2A-A26-2A2-2B25-2B3-2B23-2B4-3A21-3A6-2A19-2A10-2B15-2B14-2(B13-)3(2(A19-A10-)2(B19-B10-))2(A19-A10-)B19-B10-2B17-2B2(10-2A17-2A)10-2B17-2B10-3B15-3B5-A5-2A15-2A5-2A28-2AB28-3B28-2BA28-3A28-2A-B26-2B2-2B25-2B3-2A23-2A5-3A19-3A9-2B15-2B14-2(B13-)3(2(A19-A10-)2(B19-B10-))2(A19-A10-)B19-B10-2B17-2B2(10-2A17-2A)11-B17-B12-2B15-2B6-A5-2A15-2A5-2A28-2AB28-3B28-2BA28-3A28-2A-B26-2B2-2B25-2B3-2A23-2A5-3A19-3A9-2B15-2B14-2(B13-)3(2(A19-A10-)2(B19-B10-))2(A19-A10-)B19-B10-2B17-2B10-2A17-2A11-A17-A12-B17-B12-2B15-2B2(6-A)15-A6-2A28-2AB28-3B28-2BA28-2A-A26-2A2-2B25-2B3-2B23-2B4-3A21-3A6-2A19-2A10-2B15-2B14-2(B13-)3(2(A19-A10-)2(B19-B10-))2(A19-A10-)B19-B11-B17-B2(12-A17-A)12-B17-B13-B15-B7-A6-A15-A6-2A28-2AB28-3B28-2B-A26-2A2-2A25-2A2-3B23-3B3-3B21-3B5-AB2A17-2ABA7-4A15-4A11-2B14-B16-B12-B13-2(2(A19-A10-)2(B19-B10-))A19-A10-2A17-2A2(10-2B17-2B)11-2(A17-A12-)B17-B13-B15-B2(14-A15-A)2(14-B15-B)8-A5-A15-A5-A2-A27-A2-B27-B2-B26-2B2-2A25-2A2-ABA23-ABA3-3B21-3B4-4B19-4B5-2ABA17-AB2A8-3A15-3A2(13-B)17-B11-B14-2(2(A19-A10-)2(B19-B10-))A19-A11-A17-A2(12-B17-B)2(12-A17-A)12-B17-B13-B15-B2(14-A15-A)2(14-B15-B)8-A5-A15-A5-A2-A27-A2-B27-B2-2B25-2B3-2A23-2A4-ABA21-ABA4-4B19-4B5-4B17-4B7-4A15-4A11-2(A15-)B13-B17-2B9-2B15-2(2(A17-A12-)2(B17-B12-))A17-A12-2A15-2A2(12-2B15-2B)12-2A15-2A13-A15-A2(14-B15-B)2(14-A15-A)14-2(B15-)B13-B10-A5-A13-A5-2(A4-)2A13-2A4-A4-B25-B4-2B23-2B4-3A21-3A5-ABA19-ABA6-4B17-4B7-4B16-3B10-2A15-2A14-2A11-2A17-2B9-2B20-B7-B18-2(A15-A14-)B15-B14-17B2(2(14-17A)2(14-17B))2(14-17A)14-17B15-15B2(16-15A)2(16-15B)11-4A-15A-4A6-5AB13AB5A2(6-25B)7-23A8-23A9-21B12-17B15-15A17-13A19-11B22-7B20-3(2(15A16-)2(15B16-))15A17-13A2(18-13B)2(18-13A)2(18-13B)18-13A17-15A14-2(19B12-)19A13-17A15-15B16-15B18-11A20-11A21-9B42-
