model
size = 31 32 17, scale = 0.05, origin = -y
material 
  colors = A:#FF0 B:#C00 C:#CF0 D:#9F3 E:#F90 F:#6FC G:#F00 H:#3FF I:#FFF J:#E00 K:#0FF L:#F60 M:#9CF N:#6FF O:#F06 P:#F3F Q:#66F R:#FF53A9 S:#C30 T:#9F6 U:#60C V:#CCF W:#6F3 X:#0E0 Y:#C60 Z:#6CF Aa:#F99 Ab:#CFF Ac:#939 Ad:#90C Ae:#66C Af:#F03 Ag:#F66 Ah:#6F0 Ai:#9FF Aj:#3F3 Ak:#9FC Al:#7EBDFD Am:#CC0 An:#FC6 Ao:#30F Ap:#639 Aq:#0F0 Ar:#0F3 As:#CF3 At:#FCF Au:#36F Av:#C06 Aw:#900 Ax:#303 Ay:#9F0 Az:#C09 Ba:#669 Bb:#6F6 Bc:#903 Bd:#00D Be:#03F Bf:#D00 Bg:#FF6 Bh:#3CF Bi:#C6F Bj:#30C Bk:#3093F5 Bl:#636 Bm:#C36 Bn:#C9C928 Bo:#777 Bp:#96F Bq:#CFC Br:#906 Bs:#CC3 Bt:#3F0 Bu:#3C6 Bv:#09F Bw:#C0C Bx:#007A28 By:#6CC Bz:#39C Ca:#09C Cb:#F0C Cc:#6C6 Cd:#60F Ce:#3F9 Cf:#0CF Cg:#C03 Ch:#0F9 Ci:#005 Cj:#300 Ck:#3FC Cl:#969
voxels
9-2Bg2Br4K2A3R18-2Bg2Br4K2A2GR2(18-Bq3Br4Aq2G3Ai)18-2Bq2M2Aq4C3Ai18-4M2Aq4C3Ai2(18-2BoI3Ai4C3O)2(18-2An3P2Ai2Ay4O)18-2An3PG2Ay4LI18-2An3P2(3G4LBw18-Bz4E)3C4LBw18-Bz4EC4S3Bw18-Bz4E2H3(3S3Bb18-3Ad4H)2CU3Bb18-4AdBd4C4U18-2X2Bd4AC4U17-3Ba4Q2A3Ca2TBf15-Bl3Ba4Q4AyCa2T2Bf14-Bl3Ba4Q4AyCaCfCi2Bf15-3Ba4Q-3AyCaCf2Ci17-3Cj2Ce3-2Ay3Cf202-2(2Bg13-2Aa14-)2Bq13-2Aa2(14-2Bq13-2A)3(14-2Bo13-2G)3(14-2An13-2N)14-2Y13-BwN14-2Y13-BwAj2(14-3Y11-3Ah)15-2Bz2(11-2Ah16-2C)11-2Bb16-2C11-2Bb16-IAd11-UT14-2Ce2X11-U3Bf11-Bh2BlBa13-4Bf10-Bh2Bl15-Bf2Ac10-3Bl15-Bf2Ac11-2Bl15-CiAc13-2Bv13-2Al15-2Bv3BxCe3-3Cd3Al16-2Bv3Bx5-2Cd3Al138-3(Bu17-Aa12-)2(N17-A12-)2(N17-G12-)Bs17-G12-Bs17-Cl12-BsAn15-2At12-IAn2(15-2At12-2Y)15-2At13-2(Y15-Ah14-)CBz2(13-2Ah14-2C)13-2K14-2N13-2K15-N13-K11-3Bh2-N13-Bf2-2(Ab2Ar6-3Bh19-)Ac2Ar6-3Af19-3G7-2Af19-2G8-2Af2Bv15-AlAc2G9-3D15-AlIG12-D15-Al15-4ApBx5-4BtAl106-3(Bu19-Aa10-)3(N19-Bp10-)N2(19-An10-Bs)19-An11-Bs17-At12-I3(17-At12-Y)17-Bg12-Y17-Bg13-2(Bj15-Ah14-)Bj2(15-Bk14-N)15-K9-Bh4-N15-T4-2(Ar4-Bh25-)Ar4-2Af23-2G4-3Af21-3G5-3Af19-3G6-Af3D17-H3G7-4D15-3HI10-2D15-2H14-3KAp7-3BtH75-2(Bu19-Aa10-)By19-Aa3(10-N19-Bp)10-N2(19-An10-Bs)19-An3(10-2Aq17-2At)11-Aa17-At2(12-Aa17-Bg)2(12-2Bj15-AhBk)13-Bj2(15-Bk14-N)15-K8-P5-N15-I5-2(Ar2-P27-)Ar2-PAf25-GCh3-2Af23-2G4-3Af21-3G4-2Af2D19-4G5-Ai3D17-2H2Be7-4D15-B2HBe11-DK13-2B16-2KAp7-Bt2B45-3(Ae19-A10-)N19-A2(10-N19-Bp)10-N19-Aj2(10-Bs19-An)3(10-Aq19-At)10-Aa19-At2(10-Aa19-Bg)11-3(Bj17-Bk12-)Bj17-Bk13-N15-K8-P5-N15-I5-3(Ar2-A27-)Ch2-AAf25-GCh2-Ai2Af23-2GCh3-2AfD21-3G4-2Ai2D19-H3Be5-I3D17-2H2Be8-3D15-B2H13-K13-B17-2K9-2I14-3(Ae19-A10-)By19-A2(10-By19-Bp)10-G19-Aj2(10-G19-An)10-G2(19-Al10-Aq)2(19-Al10-Aa)19-Cc10-Aa19-Cc2(10-2Ah17-2Cc)11-2(E17-Bk12-)2E15-2Av6-P6-E15-Av6-IA28-2I2(A28-2L)-A26-2L2-2Ai25-2L2-Ai2J23-2BeI3-3J21-3Be5-2JA19-A2Be7-J3A15-3AI11-2(A15-)K13-I13-2(B19-A10-)Ae2(19-A10-By)19-Cg10-By19-Cg10-G19-Aj2(10-G19-Cb)4(10-H19-Al)2(10-Aa19-Ap)2(10-2Ah17-2Ap)10-2E17-2Av11-E17-Av12-2E15-2Av6-P5-2E15-2Av5-2A28-3A2(28-2LE)28-2M-H26-2M2-2H25-OM3-2H23-2O4-3H21-3O6-JA19-AO10-2A15-2A14-Ab13-F13-2(B19-W10-)Ae19-W10-Bi19-A2(10-Bi19-Cg)10-Bi19-Aj2(10-G19-Cb)3(10-H19-Al)10-Aw19-Al2(10-Aw19-Ap)10-2Aw17-2Ap10-2Ah17-2Ap2(10-2E17-2Av)10-3E15-3Av5-Ae5-2E15-2Av5-AAe28-2A2(Ae28-2L)2(E28-2M)-H26-OM2-2H25-OM3-2H23-2O5-2JA19-A2O9-2A15-2A14-Ab13-F13-2(B19-W10-)D19-W3(10-Bi19-Ae)10-Bi2(19-M10-G)19-Cb2(10-H19-Ao)10-H3(19-Q10-Aw)19-Q10-2Aw17-2Ap10-2Ah17-2Ap10-2E17-NAv11-E17-N12-2E15-2N6-Ae5-2E15-2Av5-AAe28-2AAe28-2TAe2(28-2JE)28-2J-H26-2J2-2H25-OM3-2H23-2O5-2JA19-A2O9-2A15-2A14-Ab13-F13-2(B19-W10-)D19-W10-Bi19-F2(10-Bi19-Ae)2(10-E19-M)10-E19-Cb2(10-Q19-Ba)10-Q19-Q10-Q2(19-J10-Am)19-J10-2Am17-2J10-2I17-2Ap11-2(E17-N12-)2E15-2N6-Ae6-E15-I6-BmAe28-2BmAe28-2TAe28-2JE28-2J-D26-2J2-2D25-2J3-2D23-2O4-3D21-3O6-2Z19-2O10-2W15-2Al14-Ab13-F13-3(D19-P10-)Bi19-P2(10-Bi19-Ae)3(10-E19-E)10-Q19-E10-Q19-Ba10-Q19-Q10-Q2(19-J10-Am)19-J11-Am17-J3(12-F17-N)13-Af15-N7-Ae6-Af15-I6-BmAe28-2BmAe28-KTAe28-2J-D26-2J2-2D25-PJ2-3D23-2PJ3-2DF21-3P5-D3F17-2L2P7-2Z2W15-3LI11-2W14-Al16-I12-D13-3(D19-P10-)K19-P2(10-K19-Ae)10-K2(19-E10-D)19-E10-2D17-RE10-2D17-TBa10-2Q17-TQ11-Q2(17-T12-O)17-J13-Am15-J2(14-F15-As)14-F15-N14-Z15-N8-Ac5-Z15-I5-2(Bm2-Ac27-)K2-Ac26-2J2-DB25-2J2-3D23-AjPJ3-2DF21-2AjP4-2D2F19-L2AjP5-D3F17-2L2Aj8-Z2W15-3L13-W13-D17-I11-D14-3(F19-P10-)K19-P2(10-K19-D)10-K2(19-E10-D)19-E11-D17-R12-D2(17-T12-Q)2(17-T12-O)17-J13-Am15-J2(14-F15-As)14-F15-I14-Z15-I8-Ac5-Z15-I5-2(Bm2-Ac27-)K2-2Ac25-AsI3-2B23-2I4-2DF21-2AjP4-2D2F19-L2AjP5-D2FAu17-2L2Aj7-2F2Au15-3LAj11-W15-L15-W13-D17-2A9-2D15-F4(17-P12-Bd)2(17-D12-K)3(17-R12-D)C15-2R12-D2(B15-2T12-O)B15-2T13-B15-T14-O4(15-As14-F)15-I15-Af13-Ax10-Ac5-Af13-I5-K4-Ac4-ZI13-2Bc4-K4-Ac25-K4-2Ac23-2As4-3B21-3I5-B2F19-3Aj6-I2FAu17-2L2Aj7-2F2Au16-2LAj10-2Au15-2L14-IA11-CL17-2A9-2D20-A7-D18-F2(15-A14-Bd)15-A14-2Bd4Ag3AaG4W3A14-2Bd4Ag4G3W4Ao14-2K4Ag3G4X4Ao14-2C4AgT2F4X4Ao14-4C2HT2F4X3VAo14-4C2HAw2F4X3VR14-4C2HAw4FI4VR14-4B2H2Aw4R4VT14-4B2I2Aw2(4R4BT14-3B4SK)4R4BT14-2OI4S3K2Q4BAs15-2Az4S3K4Q2As16-4Az4A2T3Ab2Ax16-4Az4AFT3Ab2Ax16-Az4C4FTI4Ax16-I4C4FTI4Ax11-Ac3Z-I4C2E2FAd4BI-I3As6-Ac4ZI4C2E3Ad4B4Bc2As6-Ac4Z2AmI4E3Ad4B4Bc2As6-2AcB3Am4U2E3Ad3B4MBc2As7-2B3Am4U3Ab2Ar2ZCk4MBcI8-2B3Au4U3Ab2Ar3Z4M2Aj9-I3Au4UD2Ab2JZ2C4MAj12-3Au4D4JZ5C15-Au4A4Ak2Y4C17-4A4Ak2Y3C19-3A4Ak3YI22-A4Ak2Y20-2(3Bn4Ac4V3BA16-)4Bn3Aa4V2WBA16-Bd4Ag3AaG4W2A16-Bd4Ag4G3W3Ao16-I4Ag3G4X3Ao16-C4AgT2F4X3Ao16-3C2HT2(2F4X3V16-3C2HAw)4FI4V16-3B2H2Aw4R4V16-3B2I2Aw4R4B16-2B4SK4R4B17-B4SK4R3B18-I4S3K2Q3B18-Az4S3K4QI18-3Az4A2T3AbAx18-3Az4AFT3AbAx2(18-4C4FTI3Ax)18-4C2E2FAd4B17-I4C2E3Ad4BBc14-4AmI4E3Ad4B3Bc12-3Am4U2E3Ad3B4M12-3Am4U3Ab2Ar2ZCk4M13-2Au4U3Ab2Ar3Z3M15-Au4UD2Ab2JZ2C2M16-2Au4D4JZ4C18-3A4Ak2Y2C20-3A4Ak2Y2C21-2A4Ak3Y42-
