model
size = 31 32 17, scale = 0.05, origin = -y
material 
  colors = A:#FFF B:#D00 C:#A00 D:#B00 E:#800 F:#700 G:#E00 H:#500 I:#400 J:#200
voxels
9-FIE3HIEH4C18-2IFJ3HE2HI2C18-E2C2HJE2I2FJC18-FIFC2FE6C18-5F2EJD3CD18-IFCJF3CDE2CD18-I2FCF2D3CEAD18-JF3CD2CDCDBC18-ED4CDC3DBC18-CDE2DEAC2D2CB18-CD2EDCEBCDBDA18-2D2ECDEBA3BA18-2D2EC2DBA2B2A18-3DACED2EBAEA18-C3D2A2EB2AEB18-DB4DE4ADB18-DB2(2DA)B4A18-DA3BA2D2AB2A18-D2ABAB6AB18-2ABAB7AB18-5A2(B3A)17-2A2B7AB3A15-4A2B4AB6A14-11AB5A15-7A-7A17-5A3-5A202-2F13-2C14-2H13-CE14-EF13-2C14-FI13-2C14-2I13-2C14-2F13-EC14-EF13-AD14-EC13-CA14-2C13-CB14-DJ13-2B14-DF13-AB14-EF13-AD14-ED13-2A14-2EA11-ADA14-2DA11-3A15-DA11-AE2(16-DA11-2A)2(16-2A11-2A)14-4A11-AB2A11-A2BA13-4A10-ABA15-3A10-3A15-3A11-2A15-2(2A13-)2A15-6A3-6A16-5A5-5A138-I17-C12-F17-C12-I17-C12-E17-E12-F17-B12-F17-C12-D17-D2(12-E17-A)12-CA15-2A12-BA15-AB12-EA15-AB12-FA15-AB13-2(A15-A14-)2(DA13-2A14-)DA13-AB14-BA13-2A15-B13-A11-3A2-A13-A2-3(3A6-3A19-)3A7-2A19-2A8-4A15-4A9-3A15-3A12-2(A15-)5A5-5A106-J19-H10-F19-C10-H19-D10-I19-C10-E19-G2(10-I19-B)10-E19-A10-E19-B11-3(C17-A12-)2(F17-A12-)C17-B13-2(A15-A14-)D2(15-A14-A)15-A9-A4-A15-2(A4-)2(A25-A4-)2A23-2A4-3A21-3A5-3A19-3A6-4A17-4A7-4A15-4A10-2A15-2A14-4A7-4A75-E19-H10-F19-C10-H19-C10-I2(19-G10-E)19-A10-E19-A2(10-C19-B)10-EA17-2A10-CA17-AB10-CA17-2A11-C2(17-A12-A)17-A12-CA15-2A12-2A15-2A13-A15-A14-B15-A14-A15-A8-A5-A15-A5-2(A2-A27-)A2-2A25-2A3-2A23-2A4-3A21-3A4-4A19-4A5-4A17-4A7-4A15-4A11-2A13-2A16-3A7-3A45-E19-H10-H19-C10-F19-G10-C19-G2(10-E19-A10-C19-A)10-C19-B2(10-C19-A)10-B19-A10-C19-B10-C19-A10-A19-A11-3(A17-A12-)A17-A13-A15-A8-A5-A15-A5-3(A2-A27-)A2-2A25-2A2-3A23-3A3-3A21-3A4-4A19-4A5-4A17-4A8-3A15-3A2(13-A)17-2A9-2A14-H19-F10-E19-B10-I19-G10-I19-B10-D19-A10-D19-B10-C19-A10-E4(19-A10-C)2(19-G10-C)19-A10-C19-A2(10-2A17-2A)11-2(A17-A12-)2A15-2A2(6-A)15-A6-2A2(28-3A)28-2A-A26-2A2-2A25-2A2-3A23-3A3-3A21-3A5-3A19-3A7-4A15-4A11-2(A15-)2(A13-)H19-C10-H19-B10-E19-C10-C19-A10-I19-A10-D2(19-A10-C)19-A10-E2(19-A10-C)19-G10-C19-A10-A3(19-A10-D)A2(17-2A10-2A)17-2A11-A17-A12-2A15-2A6-A5-2A15-2A5-2A3(28-3A)28-2A-A26-2A2-2A25-2A3-2A23-2A4-3A21-3A6-2A19-2A10-2A15-2A14-2(A13-)H19-C10-F2(19-G10-E)19-G10-C2(19-A10-D)19-A10-C19-A10-J19-A10-E3(19-A10-C)19-A10-B19-A10-C19-A2(10-DA17-2A)2(10-2A17-2A)10-3A15-3A5-A5-2A15-2A5-2A4(28-3A)28-2A-A26-2A2-2A25-2A3-2A23-2A5-3A19-3A9-2A15-2A14-2(A13-)H19-D10-I19-G10-J19-B2(10-E19-A)5(10-C19-A)10-B19-A10-C19-A10-F19-A10-D19-A10-A19-A3(10-2A17-2A)11-A17-A12-2A15-2A6-A5-2A15-2A5-2A4(28-3A)28-2A-A26-2A2-2A25-2A3-2A23-2A5-3A19-3A9-2A15-2A14-2(A13-)F19-G10-F19-C10-J19-A10-E19-A10-D19-A10-E19-A10-F19-A10-E19-A10-C19-A10-D19-A10-C19-A10-B19-A10-A2(19-A10-D)19-A2(10-2A17-2A)11-2(A17-A12-)2A15-2A2(6-A)15-A6-2A3(28-3A)28-2A-A26-2A2-2A25-2A3-2A23-2A4-3A21-3A6-2A19-2A10-2A15-2A14-2(A13-)F2(19-G10-B)19-A10-F2(19-A10-E)19-A10-B19-A10-F19-A10-A3(19-A10-C)3(19-A10-A)19-A11-3(A17-A12-)A17-A13-A15-A7-A6-A15-A6-2A2(28-3A)28-2A-A26-2A2-2A25-2A2-3A23-3A3-3A21-3A5-4A17-4A7-4A15-4A11-2A14-A16-A12-A13-J19-G8(10-B19-A)10-BA17-2A10-2A17-2A10-CA17-2A11-C2(17-A12-A)17-A13-4(A15-A14-)A15-A8-A5-A15-A5-2(A2-A27-)A2-A26-2A2-2A25-2A2-3A23-3A3-3A21-3A4-4A19-4A5-4A17-4A8-3A15-3A2(13-A)17-A11-A14-3(E19-A10-)5(B19-A10-)B19-A11-5(A17-A12-)A17-A13-A15-D2(14-A15-C)2(14-A15-A)8-A5-A15-A5-2(A2-A27-)A2-2A25-2A3-2A23-2A4-3A21-3A4-4A19-4A5-4A17-4A7-4A15-4A11-2(A15-)A13-A17-2A9-2A15-E17-A12-B2(17-A12-E)17-A12-B17-A12-E2(17-A12-A)2(17-A12-B)A3(15-2A12-2A)15-2A13-A15-A14-A15-B14-C15-D14-C15-C14-C15-A14-2(A15-)A13-A10-A5-A13-A5-2(A4-)2A13-2A2(4-A)25-A4-2A23-2A4-3A21-3A5-3A19-3A6-4A17-4A7-4A16-G2A10-2A15-GA14-2A11-2A17-2A9-2A20-A7-A18-H2(15-A14-B)15-A2(14-E16A)14-F16A14-E15AB14-16AB14-17A14-16A2(B14-B15A)B14-B13A3B14-BE12AB2D14-2C12ABCD15-D12ABC16-B14A3(16-15A)11-4A-14AG-4A6-25A6-4AC17AG2A6-22AG2A7-21ACA8-20ABGA9-2AG15A3G12-C15AG15-14AG17-13A19-11A22-7A20-H3D11A16-2B13A16-B14A16-9AG5A16-E8AG5A16-9AG3AGA16-AG7AB3AGA16-AB6ADB3ABA16-AB3AB2ADB3ABA16-A2B2ABC2B2(DBA)16-2AB3CE2DCDB2DA16-A2BECDBD3E2DBA16-2DC3D3BC2B3D17-D2B7A2CE18-D10A2B2(18-13A)18-8AG2(4A18-G7AB)4A18-G4ABA2D3AD17-A2D2A3BCDBAGCD14-3AB2C3B2C2BD2C3A12-AG2AC3B3A2CECD3A12-AG2AB2FD3ADFED4A13-DABE2BDBABECGCBGA15-3DA3B2C2GEGDG16-2D3A3BDC2ADGC18-4ABAD4A20-11A21-9A42-
