model
size = 31 32 17, scale = 0.05, origin = -y
material 
  colors = A:#000 B:#0E0 C:#0A0 D:#444
voxels
9-11(13A18-)5A2BC5A18-4A2BABC4A18-3A6BC3A18-2A8BC2A18-2A2B2(2AB)C2A18-2A2(B3A)C2A18-2A2(BADA)C2A18-2A2B2(2AB)C2A18-3A6BC3A18-4A4BC4A17-15A15-17A14-8AB8A15-6AB-B6A17-4AB3-B4A202-13(2A13-2A14-)3A11-3A14-3A11-3A15-4(2A11-2A16-)2A11-2A14-2B2A11-2A2B11-4A13-4A2(10-3A15-3A)11-2A15-2(2A13-)2A15-5AB3-B5A16-4AB5-B4A138-9(A17-A12-)3(2A15-2A12-)2A15-2A13-2(A15-A14-)3(2A13-2A14-)2A13-2A15-A13-A11-3B2-B13-B2-3B3(6-3A19-3A)7-2A19-2A8-4A15-4A9-3A15-3A12-2(A15-)4AB5-B4A106-8(A19-A10-)A19-A11-5(A17-A12-)A17-A13-4(A15-A14-)A15-A9-B4-B15-2(B4-)2(A25-A4-)2A23-2A4-3A21-3A5-3A19-3A6-4A17-4A7-4A15-4A10-2A15-2A14-3AB7-B3A75-9(A19-A10-)2(2A17-2A10-)2A17-2A11-3(A17-A12-)2A15-2A12-2A15-2A13-2(A15-A14-)A15-A8-B5-B15-B5-B2(2-A27-A)2-2A25-2A3-2A23-2A4-3A21-3A4-4A19-4A5-4A17-4A7-4A15-4A11-2A13-2A16-2AB7-B2A45-14(A19-A10-)A19-A11-3(A17-A12-)A17-A13-A15-A8-B5-B15-B5-B3(2-A27-A)2-2A25-2A2-3A23-3A3-3A21-3A4-4A19-4A5-4A17-4A8-3A15-3A2(13-A)17-2B9-2B14-15(A19-A10-)2A17-2A10-2A17-2A11-2(A17-A12-)2A15-2A2(6-B)15-B6-BA2(28-3A)28-2A-A26-2A2-2A25-2A2-3A23-3A3-3A21-3A5-3A19-3A7-4A15-4A11-2(A15-)2(B13-)15(A19-A10-)2(2A17-2A10-)2A17-2A11-A17-A12-2A15-2A6-B5-BA15-AB5-BA3(28-3A)28-2A-A26-2A2-2A25-2A3-2A23-2A4-3A21-3A6-2A19-2A10-2A15-2A14-2(B13-)15(A19-A10-)4(2A17-2A10-)3A15-3A2(5-B)A15-AB5-BA4(28-3A)28-2A-A26-2A2-2A25-2A3-2A23-2A5-3A19-3A9-2A15-2A14-2(B13-)15(A19-A10-)2(2A17-2A10-)2A17-2A11-A17-A12-2A15-2A6-B5-BA15-AB5-BA4(28-3A)28-2A-A26-2A2-2A25-2A3-2A23-2A5-3A19-3A9-2A15-2A14-2(B13-)15(A19-A10-)2A17-2A10-2A17-2A11-2(A17-A12-)2A15-2A2(6-B)15-B6-BA3(28-3A)28-2A-A26-2A2-2A25-2A3-2A23-2A4-3A21-3A6-2A19-2A10-2A15-2A14-2(B13-)14(A19-A10-)A19-A11-3(A17-A12-)A17-A13-A15-A7-B6-B15-B6-BA2(28-3A)28-2A-A26-2A2-2A25-2A2-3A23-3A3-3A21-3A5-4A17-4A7-4A15-4A11-2A14-A16-B12-B13-9(A19-A10-)2(2A17-2A10-)2A17-2A11-2(A17-A12-)A17-A13-4(A15-A14-)A15-A8-B5-B15-B5-B2(2-A27-A)2-A26-2A2-2A25-2A2-3A23-3A3-3A21-3A4-4A19-4A5-4A17-4A8-3A15-3A2(13-A)17-B11-B14-8(A19-A10-)A19-A11-5(A17-A12-)A17-A13-4(A15-A14-)A15-A8-B5-B15-B5-B2(2-A27-A)2-2A25-2A3-2A23-2A4-3A21-3A4-4A19-4A5-4A17-4A7-4A15-4A11-2(A15-)A13-A17-2B9-2B15-9(A17-A12-)3(2A15-2A12-)2A15-2A13-5(A15-A14-)2(A15-)A13-A10-B5-B13-B5-B4-A4-2A13-2A2(4-A)25-A4-2A23-2A4-3A21-3A5-3A19-3A6-4A17-4A7-4A16-3A10-2A15-2A14-2A11-2A17-2A9-2A20-B7-B18-3(A15-A14-)11(17A14-)17A15-4(15A16-)15A11-4B-15A-4B3(6-25A)7-23A8-23A9-21A12-17A15-15A17-13A19-11A22-7B20-15A16-5AB3AB5A16-5A2B2AB5A16-5A2(BA)B5A16-5AB2A2B5A16-5AB3AB5A16-15A16-5A5B5A16-9AB5A16-7A3B5A16-9AB5A16-5A5B5A16-15A17-5(6AB6A18-)13A18-4A5B4A18-8AB4A17-9AB5A14-2(11AB7A12-)19A13-6AB3AB6A15-5A5B5A16-5AB3AB5A18-2(3AB)3A20-4A3B4A21-9A42-
