model
size = 14 7 17, scale = 0.05, origin = -y
material 
  colors = A:#F6C555 B:#7DB9DE C:#1E88A8 D:#BBB E:#00896C F:#2EA9DF G:#0089A7 H:#005CAF I:#D0104C J:#006284 K:#24936E L:#336774
voxels
----AAA------- ---AJEEA------ ---ABEEA------ ---ABCEA------ ---ABECA------ ---ABCCA------ ----AAA------- 
-A-AAAAA-A---- -A-AAAAA-A---- -A-AAAAA-A---- -A-AAAAA-A---- -AAAAAAAAA---- --AAAAAAA----- --AAAAAAA----- 
-AA-----AAA--- AAA-----AAA--- AAA-----AAA--- AAA-----AAA--- AAA-----AAA--- AAA-----AAA--- -AA-----AAA--- 
----------AA-- ----------AA-- ----------AA-- ----------AA-- ----------AA-- ----------AA-- ----------AA-- 
-----------AA- -----------AA- -----------AA- -----------AA- -----------A-- -----------A-- -----------A-- 
-----------A-- -----------A-- -----------A-- -----------AA- -----------AA- -----------AA- -----------AA- 
------------A- ------------AA ------------AA ------------AA ------------AA ------------AA ------------A- 
------------AA ------------DK ------------DH ------------DC ------------AC ------------DC ------------AA 
------------AA ------------AH ------------II ------------AI ------------AC ------------AB ------------AA 
------------AA ------------AH ------------DH ------------DC ------------DB ------------DB ------------AA 
------------A- ------------AA ------------AA ------------AA ------------AA ------------AA ------------A- 
-----------A-- -----------A-- -----------A-- -----------AA- -----------AA- -----------AA- -----------AA- 
-----------AA- -----------AA- -----------AA- -----------AA- -----------A-- -----------A-- -----------A-- 
----------AA-- ----------AA-- ----------AA-- ----------AA-- ----------AA-- ----------AA-- ----------AA-- 
-AA-----AAA--- AAA-----AAA--- AAA-----AAA--- AAA-----AAA--- AAA-----AAA--- AAA-----AAA--- -AA-----AAA--- 
-A-AAAAA-A---- -A-AAAAA-A---- -A-AAAAA-A---- -A-AAAAA-A---- -AAAAAAAAA---- --AAAAAAA----- --AAAAAAA----- 
----AAA------- ---AGGLA------ ---AGGFA------ ---AGFFA------ ---AFBBA------ ---AFFBA------ ----AAA------- 
