model
size = 20 16 21, scale = 0.05, origin = -y
material 
  colors = A:#FFAB2D B:#8B0000 C:#36BF36 D:#F00 E:#FFFF4B
voxels
-------------------- -------------------- -------------------- -------------------- -------------------- ----------CCCCC----- -------------------- -------------------- -------------------- -------------------- -------------------- -------------------- -------------------- -------------------- -------------------- -------------------- 
-------------------- -------------------- -------------------- -------------------- -------------------- -------CCCCCCCC----- -------------------- -------------------- -------------------- -------------------- -------DDDDDDD------ -------------------- -------------------- -------------------- -------------------- -------------------- 
-------------------- -------------------- -------------------- -------------------- -------------------- -----CCCCCCCCCCC---- --------BBBBB------- --------BBBBB------- --------BBBBB------- -------------------- ------DDDDDDDDD----- -------------------- -------------------- -------------------- -------------------- -------------------- 
-------------------- -------------------- -------------------- -------------------- --------AAAAA------- ----CCCCCCCCCCCCC--- ------BBBBBBBBB----- ------BBBBBBBBB----- ------BBBBBBBBB----- --EEEEEEEEEEEEEEEEE- -----DDDDDDDDDDD---- --------AAAAA------- -------------------- -------------------- -------------------- -------------------- 
-------------------- -------------------- -------------------- --------AAAAA------- ------AAAAAAAAA----- ---CCCCCCCCCCCCCCCCC ----BBBBBBBBBBBBB--- ----BBBBBBBBBBBBB--- ----BBBBBBBBBBBBB--- --EEEEEEEEEEEEEEEEE- ----DDDDDDDDDDDDD--- ------AAAAAAAAA----- --------AAAAA------- -------------------- -------------------- -------------------- 
-------------------- -------------------- --------AAAAA------- ------AAAAAAAAA----- -----AAAAAAAAAAA---- --CCCCCCCCCCCCCCCCCC ----BBBBBBBBBBBBB--- ----BBBBBBBBBBBBB--- ----BBBBBBBBBBBBB--- --EEEEEEEEEEEEEEEEE- ---DDDDDDDDDDDDDDD-- -----AAAAAAAAAAA---- ------AAAAAAAAA----- --------AAAAA------- -------------------- -------------------- 
-------------------- --------AAAAA------- -------AAAAAAA------ -----AAAAAAAAAAA---- ----AAAAAAAAAAAAA--- --CCCCCCCCCCCCCCCCCC ---BBBBBBBBBBBBBBB-- ---BBBBBBBBBBBBBBB-- ---BBBBBBBBBBBBBBB-- --EEEEEEEEEEEEEEEEE- --DDDDDDDDDDDDDDDDD- ----AAAAAAAAAAAAA--- -----AAAAAAAAAAA---- -------AAAAAAA------ --------AAAAA------- -------------------- 
---------AAA-------- -------AAAAAAA------ ------AAAAAAAAA----- -----AAAAAAAAAAA---- ----AAAAAAAAAAAAA--- -CCCCCCCCCCCCCCCCCCC ---BBBBBBBBBBBBBBB-- ---BBBBBBBBBBBBBBB-- ---BBBBBBBBBBBBBBB-- --EEEEEEEEEEEEEEEEE- -DDDDDDDDDDDDDDDDDDD ----AAAAAAAAAAAAA--- -----AAAAAAAAAAA---- ------AAAAAAAAA----- -------AAAAAAA------ ---------AAA-------- 
--------AAAAA------- ------AAAAAAAAA----- -----AAAAAAAAAAA---- ----AAAAAAAAAAAAA--- ---AAAAAAAAAAAAAAA-- -CCCCCCCCCCCCCCCCCCC --BBBBBBBBBBBBBBBBB- --BBBBBBBBBBBBBBBBB- --BBBBBBBBBBBBBBBBB- --EEEEEEEEEEEEEEEEE- -DDDDDDDDDDDDDDDDDDD ---AAAAAAAAAAAAAAA-- ----AAAAAAAAAAAAA--- -----AAAAAAAAAAA---- ------AAAAAAAAA----- --------AAAAA------- 
-------AAAAAAA------ ------AAAAAAAAA----- -----AAAAAAAAAAA---- ----AAAAAAAAAAAAA--- ---AAAAAAAAAAAAAAA-- -CCCCCCCCCCCCCCCCCCC --BBBBBBBBBBBBBBBBB- --BBBBBBBBBBBBBBBBB- --BBBBBBBBBBBBBBBBB- --EEEEEEEEEEEEEEEEE- -DDDDDDDDDDDDDDDDDDD ---AAAAAAAAAAAAAAA-- ----AAAAAAAAAAAAA--- -----AAAAAAAAAAA---- ------AAAAAAAAA----- -------AAAAAAA------ 
-------AAAAAAA------ ------AAAAAAAAA----- -----AAAAAAAAAAA---- ----AAAAAAAAAAAAA--- ---AAAAAAAAAAAAAAA-- CCCCCCCCCCCCCCCCCCCC --BBBBBBBBBBBBBBBBB- --BBBBBBBBBBBBBBBBB- --BBBBBBBBBBBBBBBBB- --EEEEEEEEEEEEEEEEE- -DDDDDDDDDDDDDDDDDDD ---AAAAAAAAAAAAAAA-- ----AAAAAAAAAAAAA--- -----AAAAAAAAAAA---- ------AAAAAAAAA----- -------AAAAAAA------ 
-------AAAAAAA------ ------AAAAAAAAA----- -----AAAAAAAAAAA---- ----AAAAAAAAAAAAA--- ---AAAAAAAAAAAAAAA-- CCCCCCCCCCCCCCCCCCCC --BBBBBBBBBBBBBBBBB- --BBBBBBBBBBBBBBBBB- --BBBBBBBBBBBBBBBBB- --EEEEEEEEEEEEEEEEE- -DDDDDDDDDDDDDDDDDDD ---AAAAAAAAAAAAAAA-- ----AAAAAAAAAAAAA--- -----AAAAAAAAAAA---- ------AAAAAAAAA----- -------AAAAAAA------ 
--------AAAAA------- ------AAAAAAAAA----- -----AAAAAAAAAAA---- ----AAAAAAAAAAAAA--- ---AAAAAAAAAAAAAAA-- CCCCCCCCCCCCCCCCCCCC --BBBBBBBBBBBBBBBBB- --BBBBBBBBBBBBBBBBB- --BBBBBBBBBBBBBBBBB- --EEEEEEEEEEEEEEEEE- -DDDDDDDDDDDDDDDDDDD ---AAAAAAAAAAAAAAA-- ----AAAAAAAAAAAAA--- -----AAAAAAAAAAA---- ------AAAAAAAAA----- --------AAAAA------- 
---------AAA-------- -------AAAAAAA------ ------AAAAAAAAA----- -----AAAAAAAAAAA---- ----AAAAAAAAAAAAA--- CCCCCCCCCCCCCCCCCCCC ---BBBBBBBBBBBBBBB-- ---BBBBBBBBBBBBBBB-- ---BBBBBBBBBBBBBBB-- --EEEEEEEEEEEEEEEEE- -DDDDDDDDDDDDDDDDDDD ----AAAAAAAAAAAAA--- -----AAAAAAAAAAA---- ------AAAAAAAAA----- -------AAAAAAA------ ---------AAA-------- 
-------------------- --------AAAAA------- -------AAAAAAA------ -----AAAAAAAAAAA---- ----AAAAAAAAAAAAA--- -CCCCCCCCCCCCCCCCCC- ---BBBBBBBBBBBBBBB-- ---BBBBBBBBBBBBBBB-- ---BBBBBBBBBBBBBBB-- --EEEEEEEEEEEEEEEEE- --DDDDDDDDDDDDDDDDD- ----AAAAAAAAAAAAA--- -----AAAAAAAAAAA---- -------AAAAAAA------ --------AAAAA------- -------------------- 
-------------------- -------------------- --------AAAAA------- ------AAAAAAAAA----- -----AAAAAAAAAAA---- --CCCCCCCCCCCCCCCCC- ----BBBBBBBBBBBBB--- ----BBBBBBBBBBBBB--- ----BBBBBBBBBBBBB--- --EEEEEEEEEEEEEEEEE- ---DDDDDDDDDDDDDDD-- -----AAAAAAAAAAA---- ------AAAAAAAAA----- --------AAAAA------- -------------------- -------------------- 
-------------------- -------------------- -------------------- --------AAAAA------- ------AAAAAAAAA----- ---CCCCCCCCCCCCCCC-- ----BBBBBBBBBBBBB--- ----BBBBBBBBBBBBB--- ----BBBBBBBBBBBBB--- --EEEEEEEEEEEEEEEEE- ----DDDDDDDDDDDDD--- ------AAAAAAAAA----- --------AAAAA------- -------------------- -------------------- -------------------- 
-------------------- -------------------- -------------------- -------------------- --------AAAAA------- ----CCCCCCCCCCCCCC-- ------BBBBBBBBB----- ------BBBBBBBBB----- ------BBBBBBBBB----- --EEEEEEEEEEEEEEEEE- -----DDDDDDDDDDD---- --------AAAAA------- -------------------- -------------------- -------------------- -------------------- 
-------------------- -------------------- -------------------- -------------------- -------------------- -----CCCCCCCCCCCCC-- --------BBBBBB------ --------BBBBBB------ --------BBBBBB------ -------------------- ------DDDDDDDDD----- -------------------- -------------------- -------------------- -------------------- -------------------- 
-------------------- -------------------- -------------------- -------------------- -------------------- -----CCCCCCCCCCC---- -------------------- -------------------- -------------------- -------------------- -------DDDDDDD------ -------------------- -------------------- -------------------- -------------------- -------------------- 
-------------------- -------------------- -------------------- -------------------- -------------------- ------CCCCC--------- -------------------- -------------------- -------------------- -------------------- -------------------- -------------------- -------------------- -------------------- -------------------- -------------------- 
