model
size = 31 32 18, scale = 0.05, origin = -y
material 
  colors = A:#FFFAFA B:#FFF C:#F00 D:#00F E:#FF0 F:#F5F5F5
voxels
768-C959-2(C31-)C895-C31-C63-C31-C831-C31-C127-C31-C767-C31-C191-C31-C95-16B6(15-B6C2B6CB)15-16B31-8B6(23-B6CB)2(23-8B)6(23-B6CB)23-8B7-16B4(15-B6C2B6CB)12-C2-B6C2B6CB13-C-B6C2B6CB15-16B15-B6D2B6DB6(15-E6A2F6AE)15-B6D2B6DB31-B6DB6(23-E6AE)2(23-B6AB)6(23-E6AE)23-B6DB7-B6D2B6DB5(15-E6A2F6AE)13-C-E6A2F6AE2(15-B6D2B6DB)6(15-E6A2F6AE)15-4(B6D2B6DB31-B6DB6(23-E6AE)2(23-B6AB)6(23-E6AE)23-B6DB7-B6D2B6DB6(15-E6A2F6AE)14-C2(B6D2B6DB15-)6(E6A2F6AE15-))B6D2B6DB31-B6DB6(23-E6AE)2(23-B6AB)6(23-E6AE)23-B6DB7-B6D2B6DB5(15-E6A2F6AE)13-C-E6A2F6AE15-B6D2B6DB15-16B6(15-B6C2B6CB)15-16B31-8B6(23-B6CB)2(23-8B)6(23-B6CB)23-8B7-16B4(15-B6C2B6CB)12-C2-B6C2B6CB13-C-B6C2B6CB15-16B655-C31-C191-C31-C767-C31-C127-C31-C831-C31-C63-C31-C895-2(C31-)C959-C223-
