model
size = 29 14 25, scale = 0.05, origin = -y
material 
  colors = A:#C0C0C0 B:#FFFAFA C:#F00
voxels
----------------------------- ----------------------------- ----------------------------- ----------------------------- ----------------------------- ----------------------------- ------AAAAA--------AAAA------ ------AAAAA--------AAAA------ ----------------------------- ----------------------------- ----------------------------- ----------------------------- ----------------------------- ----------------------------- 
----------------------------- ----------------------------- ----------------------------- ----------------------------- ----------------------------- ----------------------------- -----AAAAAA-------AAAAAA----- -----AAAAAA-------AAAAAA----- ----------------------------- ----------------------------- ----------------------------- ----------------------------- ----------------------------- ----------------------------- 
----------------------------- ----------------------------- ----------------------------- ----------------------------- ----------------------------- ----------------------------- ----AAABBBB-------AABBAA----- ----AAABBBB-------AABBAA----- ----------------------------- ----------------------------- ----------------------------- ----------------------------- ----------------------------- ----------------------------- 
----------------------------- ----------------------------- ----------------------------- ----------------------------- ----------------------------- ----------------------------- ---AAAB-----------AABBAA----- ---AAAB-----------AABBAA----- ----------------------------- ----------------------------- ----------------------------- ----------------------------- ----------------------------- ----------------------------- 
----------------------------- ----------------------------- ----------------------------- ----------------------------- ----------------------------- ----------------------------- --AAAB-----------AAB--BAA---- --AAAB-----------AAB--BAA---- ----------------------------- ----------------------------- ----------------------------- ----------------------------- ----------------------------- ----------------------------- 
----------------------------- ----------------------------- ----------------------------- ----------------------------- ----------------------------- ----------------------------- -AAAB------------AAB--BAA---- -AAAB------------AAB--BAA---- ----------------------------- ----------------------------- ----------------------------- ----------------------------- ----------------------------- ----------------------------- 
----------------------------- ----------------------------- ----------------------------- ----------------------------- ----------------------------- ----------------------------- -AAB-------------AAB--BAA---- -AAB-------------AAB--BAA---- ----------------------------- ----------------------------- ----------------------------- ----------------------------- ----------------------------- ----------------------------- 
----------------------------- ----------------------------- ----------------------------- ----------------------------- ----------------------------- ----------------------------- AAB-------------AAB----BAA--- AAB-------------AAB----BAA--- ----------------------------- ----------------------------- ----------------------------- ----------------------------- ----------------------------- ----------------------------- 
----------------------------- ----------------------------- ----------------------------- ----------------------------- ----------------------------- ----------------------------- AAB-------------AAB----BAA--- AAB-------------AAB----BAA--- ----------------------------- ----------------------------- ----------------------------- ----------------------------- ----------------------------- ----------------------------- 
----------------------------- ----------------------------- ----------------------------- ----------------------------- ----------------------------- ----------------------------- AAB-------------AAB----BAA--- AAB-------------AAB----BAA--- ----------------------------- ----------------------------- ----------------------------- ----------------------------- ----------------------------- ----------------------------- 
----------------------------- ----------------------------- ----------------------------- ----------------------------- ----------------------------- ----------------------------- AAB------------AAB------BAA-- AAB------------AAB------BAA-- ----------------------------- ----------------------------- ----------------------------- ----------------------------- ----------------------------- ----------------------------- 
----------------------------- ----------------------------- ----------------------------- ----------------------------- ----------------------------- ----------------------------- -AAB-----------AAB------BAA-- -AAB-----------AAB------BAA-- ----------------------------- ----------------------------- ----------------------------- ----------------------------- ----------------------------- ----------------------------- 
----------------------------- ----------------------------- ----------------------------- ----------------------------- ----------------------------- ----------------------------- -AAAB----------AAB------BAA-- -AAAB----------AAB------BAA-- ----------------------------- ----------------------------- ----------------------------- ----------------------------- ----------------------------- ----------------------------- 
----------------------------- ----------------------------- ----------------------------- ----------------------------- ----------------------------- ----------------------------- --AAAB--------AAB--------BAA- --AAAB--------AAB--------BAA- ----------------------------- ----------------------------- ----------------------------- ----------------------------- ----------------------------- ----------------------------- 
----------------------------- ----------------------------- ----------------------------- ----------------------------- ----------------------------- ----------------------------- ---AAAB-------AAB--------BAA- ---AAAB-------AAB--------BAA- ----------------------------- ----------------------------- ----------------------------- ----------------------------- ----------------------------- ----------------------------- 
----------------------------- ----------------------------- ----------------------------- ----------------------------- ----------------------------- ----------------------------- ----AAABBBBB--AAB--------BAA- ----AAABBBBB--AAB--------BAA- ----------------------------- ----------------------------- ----------------------------- ----------------------------- ----------------------------- ----------------------------- 
----------------------------- ----------------------------- ----------------------------- ----------------------------- -----------C----------------- -----------C----------------- -----AAAAAABBAAB----------BAA -----AAAAAABBAAB----------BAA -----------C----------------- -----------C----------------- ----------------------------- ----------------------------- ----------------------------- ----------------------------- 
----------------------------- ----------------------------- ----------------------------- ----------C------------------ ----------C------------------ ----------------------------- ------AAAAABBAAB----------BAA ------AAAAABBAAB----------BAA ----------------------------- ----------C------------------ ----------C------------------ ----------------------------- ----------------------------- ----------------------------- 
----------------------------- ----------------------------- ---------C------------------- ---------C------------------- ----------------------------- ----------------------------- -------------BB-------------- -------------BB-------------- ----------------------------- ----------------------------- ---------C------------------- ---------C------------------- ----------------------------- ----------------------------- 
----------------------------- --------C-------------------- --------C-------------------- ----------------------------- ----------------------------- ----------------------------- ----------------------------- ----------------------------- ----------------------------- ----------------------------- ----------------------------- --------C-------------------- --------C-------------------- ----------------------------- 
-------C--------------------- -------C--------------------- ----------------------------- ----------------------------- ----------------------------- ----------------------------- ----------------------------- ----------------------------- ----------------------------- ----------------------------- ----------------------------- ----------------------------- -------C--------------------- -------C--------------------- 
----------------------------- ------C---------------------- ------C---------------------- ----------------------------- ----------------------------- ----------------------------- ----------------------------- ----------------------------- ----------------------------- ----------------------------- ----------------------------- ------C---------------------- ------C---------------------- ----------------------------- 
----------------------------- ----------------------------- -----C----------------------- ----CC----------------------- ----C------------------------ ----------------------------- ----------------------------- ----------------------------- ----------------------------- ----C------------------------ ----CC----------------------- -----C----------------------- ----------------------------- ----------------------------- 
----------------------------- ----------------------------- ----------------------------- ----------------------------- ---C------------------------- ---C------------------------- ----------------------------- ----------------------------- ---C------------------------- ---C------------------------- ----------------------------- ----------------------------- ----------------------------- ----------------------------- 
----------------------------- ----------------------------- ----------------------------- ----------------------------- ----------------------------- --C-------------------------- --C-------------------------- --C-------------------------- --C-------------------------- ----------------------------- ----------------------------- ----------------------------- ----------------------------- ----------------------------- 
