model
size = 19 31 24, scale = 0.05, origin = -y
material 
  colors = A:#AAA B:#0F6 C:#090 D:#0F3 E:#888 F:#FF0 G:#0C0 H:#FF9 I:#111 J:#9CF K:#6F3 L:#FF6
voxels
------------------- ------------------- ------------------- ------------------- ------------------- ------------------- ------------------- ------------------- ------------------- ------------------- ------------------- ------------------- ------------------- ------------------- ------------------- ------------------- ------------------- ------------------- ------------------- ------------------- ------------------- ------------------- ------------------- ------------------- ------------------- ------------------- --------AAA-------- ------AAAAAAA------ ------------------- ------------------- ------------------- 
------------------- ------------------- ------------------- ------------------- ------------------- ------------------- ------------------- ------------------- ------------------- ------------------- ------------------- ------------------- ------------------- ------------------- ------------------- ------------------- ------------------- ------------------- ------------------- ------------------- ------------------- ------------------- ------------------- ------------------- ------------------- ------AAAAAAA------ -----AAAAAAAAA----- ----AAAAAAAAAAA---- ------------------- ------------------- ------------------- 
------------------- ------------------- ------------------- ------------------- ------------------- ------------------- ------------------- ------------------- ------------------- ------------------- ------------------- ------------------- ------------------- ------------------- ------------------- ------------------- ------------------- ------------------- ------------------- ------------------- ------------------- ------------------- ------------------- ------------------- ------AAAAAAA------ -----ACCCCCCCA----- ----AABBBBBBBAAA--- ---AAA-------AAA--- ------------------- ------------------- ------------------- 
------------------- ------------------- ------------------- ------------------- ------------------- ------------------- ------------------- ------------------- ------------------- ------------------- ------------------- ------------------- ------------------- ------------------- ------------------- ------------------- ------------------- ------------------- ------------------- ------------------- ------------------- ------------------- ------------------- ------AAAAAAA------ -----AAAAAAAAA----- ----ACCAAAAAAAAA--- ---AABBCCCCCCAAAA-- --AAA--------AAAA-- ------------------- ------------------- ------------------- 
------------------- ------------------- ------------------- ------------------- ------------------- ------------------- ------------------- ------------------- ------------------- ------------------- ------------------- ------------------- ------------------- ------------------- ------------------- ------------------- ------------------- ------------------- ------------------- ------------------- ------------------- --------AAA-------- ------AAAAAAA------ -----AAAAAAAAA----- ----AAAAA-AAAAA---- ---AACCCC-CCCCAA--- --AABBBBB-DDDDBAA-- -AAA-----------AAA- ------------------- ------------------- ------------------- 
--------AAA-------- ------------------- ------------------- ------------------- ------------------- ------------------- ------------------- ------------------- ------------------- ------------------- ------------------- ------------------- ------------------- ------------------- ------------------- ------------------- ------------------- ------------------- ------------------- ------------------- -------AAAAA------- ------AAAAAAA------ ----AAAAAAAAAA----- ----AAAAAGGAAAA---- ---AAAA--DDGGAAA--- --AACCC----DDCCAA-- -AABBBB------DDBAA- -AA-------------AA- ------------------- ------------------- ------------------- 
------AAAAAAA------ ------------------- ------------------- ------------------- ------------------- ------------------- ------------------- ------------------- ------------------- ------------------- ------------------- ------------------- ------------------- ------------------- ------------------- ------------------- ------------------- ------------------- ------------------- -------AAAAA------- ------AAAAAAA------ -----AAAAAAAAA----- ----AAAABBBAAAA---- ---AAAA-BBBBAAAA--- ---AAAB-BBBBGGAAA-- --AACCB-BBBBDDCCAA- -ABBBBB-------DDBA- AA---------------AA ------------------- ------------------- ------------------- 
------AAAAAAAA----- -------EEEEE------- ------------------- ------------------- ------------------- ------------------- ------------------- ------------------- ------------------- ------------------- ------------------- ------------------- ------------------- ------------------- ------------------- ------------------- ------------------- --------AAA-------- -------AAAAA------- ------AAAAAAA------ -----AAAAAAAAA----- -----AAABBBAAAA---- ----AAAGBBBBAAA---- ---AAA--BBBBBAAA--- --AAAB--BBBBBGAAA-- -AAACB--BBBBBDCCAA- -ABBBB--------DDBAA AA---------------AA ------------------- ------------------- ------------------- 
-----AAA---AAA----- -------EAAAE------- --------EEE-------- ------------------- ------------------- ------------------- ------------------- ------------------- ------------------- ------------------- ------------------- ------------------- ------------------- ------------------- --------A-A-------- --------AAA-------- --------AAA-------- -------AAAAA------- -------AAAAAA------ ------AAADAAA------ -----AAADBBAAA----- ----AAACDBBCAAA---- ----AABDDBBGBAAA--- ---AAABDDBBBBBAA--- --AAABBDDBBBBBBAA-- -AAACBBDDBBBBBBCAA- AABBBBB--------DBAA AA---------------AA ------------------- ------------------- ------------------- 
-----AAA---AAA----- -------EA-AEE------ --------EAE-------- ---------I--------- ---------I--------- ---------I--------- ---------I--------- ---------I--------- ---------I--------- ---------I--------- ---------I--------- ---------I--------- ---------I--------- ---------I--------- ---------I--------- --------AJA-------- --------AJA-------- -------AAAAA------- -------AADAAA------ ------AA-DGAA------ -----AAADBBCAA----- ----AAACDBBCAAA---- ----AABDDBBGBAAA--- ---AABBDDBBBBBAA--- --AABBBDDBBBBBBAA-- -AACBBBDDBBBBBBCAA- AABD-BB--------DBBA AA----------------A ------------------- ------------------- ------------------- 
-----AAA---AAA----- -------EAAAE------- --------EEE-------- ------------------- ------------------- ------------------- ------------------- ------------------- ------------------- ------------------- ------------------- ------------------- ------------------- ------------------- --------A-A-------- --------AAA-------- --------AAA-------- -------AAAAA------- -------AAAAAA------ ------AAAGGAA------ -----AAABBBAAA----- ----AAACBBBCAAA---- ----AAB-BBBGBAAA--- ---AABB-BBBBBBAA--- --AAABB-BBBBBBBAA-- -AACCBB-BBBBBBBCAA- AABDDBB--------DBAA AA---------------AA ------------------- ------------------- ------------------- 
------AAAAAAAA----- -------EEEEE------- ------------------- ------------------- ------------------- ------------------- ------------------- ------------------- ------------------- ------------------- ------------------- ------------------- ------------------- ------------------- ------------------- ------------------- ------------------- --------AAA-------- -------AAAAA------- ------AAAAAAA------ -----AAAAGAAAA----- -----AAABBBCAAA---- ----AAA-BBBCAAA---- ---AAAB-BBB-BAAA--- --AAACB-BBB-BCAAA-- -AACCDB-BBB-B-BAAA- -ABDD-B--------BBAA AA---------------AA ------------------- ------------------- ------------------- 
------AAAAAAA------ ---------E--------- ------------------- ------------------- ------------------- ------------------- ------------------- ------------------- ------------------- ------------------- ------------------- ------------------- ------------------- ------------------- ------------------- ------------------- ------------------- ------------------- --------AAA-------- -------AAAAA------- ------AAAAAAA------ -----AAAAAAAAA----- ----AAAABBBAAAA---- ---AAAA-BBBBBAAA--- ---AACC-BBBBBCAAA-- --ACCDD-BBBBB-BAAA- -ABDD----------BBA- AA---------------AA ------------------- ------------------- ------------------- 
-------AAAAA------- ------------------- ------------------- ------------------- ------------------- ------------------- ------------------- ------------------- ------------------- ------------------- ------------------- ------------------- ------------------- ------------------- ------------------- ------------------- ------------------- ------------------- ------------------- ------------------- -------AAAAA------- ------AAAAAAA------ -----AAAAAAAAA----- ----AAAABBBAAAA---- ---AAACCBBBCCAAA--- --AACCDDBBB--BAAA-- -AABDD--------BBAA- -AA-------------AAA ------------------- ------------------- ------------------- 
------------------- ------------------- ------------------- ------------------- ------------------- ------------------- ------------------- ------------------- ------------------- ------------------- ------------------- ------------------- ------------------- ------------------- ------------------- ------------------- ------------------- ------------------- ------------------- ------------------- ------------------- -------AAAAA------- ------AAAAAAA------ -----AAAAAAAAAA---- ----AAAABBBAAAAA--- ---AACCCBBBBBAAAA-- --AABDDD-----BBBAA- -AAA------------AA- ------------------- ------------------- ------------------- 
------------------- ------------------- ------------------- ------------------- ------------------- ------------------- ------------------- ------------------- ------------------- ------------------- ------------------- ------------------- ------------------- ------------------- ------------------- ------------------- ------------------- ------------------- ------------------- ------------------- ------------------- ------------------- --------AAA-------- ------AAAAAAA------ -----AAAAAAAAAA---- ---AAACACCCAAAAA--- --AAABDB---BBBBAA-- --AAA----------AA-- ------------------- ------------------- ------------------- 
------------------- ------------------- ------------------- ------------------- ------------------- ------------------- ------------------- ------------------- ------------------- ------------------- ------------------- ------------------- ------------------- ------------------- ------------------- ------------------- ------------------- ------------------- ------------------- ------------------- ------------------- ------------------- ------------------- ------------------- ------AAAAAAA------ -----AAAAAAAAAA---- ---AAABBBBBBBAAA--- ---AAA-------AAAA-- ------------------- ------------------- ------------------- 
------------------- ------------------- ------------------- ------------------- ------------------- ------------------- ------------------- ------------------- ------------------- ------------------- ------------------- ------------------- ------------------- ------------------- ------------------- ------------------- ------------------- ------------------- ------------------- ------------------- ------------------- ------------------- ------------------- ------------------- ------------------- ------AAAAAAA------ -----ABBBHBBBAA---- ----AA---H---AA---- ---------H--------- ------------------- ------------------- 
------------------- ------------------- ------------------- ------------------- ------------------- ------------------- ------------------- ------------------- ------------------- ------------------- ------------------- ------------------- ------------------- ------------------- ------------------- ------------------- ------------------- ------------------- ------------------- ------------------- ------------------- ------------------- ------------------- ------------------- ------------------- ---------F--------- ------AAAKAAA------ ------AAAKAAAA----- ---------H--------- ---------H--------- ------------------- 
------------------- ------------------- ------------------- ------------------- ------------------- ------------------- ------------------- ------------------- ------------------- ------------------- ------------------- ------------------- ------------------- ------------------- ------------------- ------------------- ------------------- ------------------- ------------------- ------------------- ------------------- ------------------- ------------------- ------------------- ---------H--------- ---------F--------- ---------H--------- ---------F--------- ---------F--------- ---------F--------- ---------H--------- 
------------------- ------------------- ------------------- ------------------- ------------------- ------------------- ------------------- ------------------- ------------------- ------------------- ------------------- ------------------- ------------------- ------------------- ------------------- ------------------- ------------------- ------------------- ------------------- ------------------- ------------------- ------------------- ------------------- ------------------- ---------F--------- ---------F--------- ---------F--------- ------------------- ---------F--------- ---------H--------- ---------F--------- 
------------------- ------------------- ------------------- ------------------- ------------------- ------------------- ------------------- ------------------- ------------------- ------------------- ------------------- ------------------- ------------------- ------------------- ------------------- ------------------- ------------------- ------------------- ------------------- ------------------- ------------------- ------------------- ------------------- ------------------- ---------H--------- ---------F--------- ---------L--------- ---------F--------- ---------F--------- ---------F--------- ---------H--------- 
------------------- ------------------- ------------------- ------------------- ------------------- ------------------- ------------------- ------------------- ------------------- ------------------- ------------------- ------------------- ------------------- ------------------- ------------------- ------------------- ------------------- ------------------- ------------------- ------------------- ------------------- ------------------- ------------------- ------------------- ------------------- ---------F--------- ---------F--------- ---------F--------- ---------H--------- ---------F--------- ------------------- 
------------------- ------------------- ------------------- ------------------- ------------------- ------------------- ------------------- ------------------- ------------------- ------------------- ------------------- ------------------- ------------------- ------------------- ------------------- ------------------- ------------------- ------------------- ------------------- ------------------- ------------------- ------------------- ------------------- ------------------- ------------------- ------------------- ---------H--------- ---------F--------- ---------H--------- ------------------- ------------------- 
