model
size = 19 31 24, scale = 0.05, origin = -y
material 
  colors = A:#AAA B:#E00 C:#A00 D:#888 E:#9CF F:#6F3 G:#111 H:#6C3 I:#0C0 J:#D00 K:#3F6
voxels
------------------- ------------------- ------------------- ------------------- ------------------- ------------------- ------------------- ------------------- ------------------- ------------------- ------------------- ------------------- ------------------- ------------------- ------------------- ------------------- ------------------- ------------------- ------------------- ------------------- ------------------- ------------------- ------------------- ------------------- ------------------- ------------------- --------AAA-------- ------AAAAAAA------ ------------------- ------------------- ------------------- 
------------------- ------------------- ------------------- ------------------- ------------------- ------------------- ------------------- ------------------- ------------------- ------------------- ------------------- ------------------- ------------------- ------------------- ------------------- ------------------- ------------------- ------------------- ------------------- ------------------- ------------------- ------------------- ------------------- ------------------- ------------------- ------AAAAAAA------ -----AAAAAAAAA----- ----AAAAAAAAAAA---- ------------------- ------------------- ------------------- 
------------------- ------------------- ------------------- ------------------- ------------------- ------------------- ------------------- ------------------- ------------------- ------------------- ------------------- ------------------- ------------------- ------------------- ------------------- ------------------- ------------------- ------------------- ------------------- ------------------- ------------------- ------------------- ------------------- ------------------- ------AAAAAAA------ -----ACCCCCCCA----- ----AACCCCCCCAAA--- ---AAA-------AAA--- ------------------- ------------------- ------------------- 
------------------- ------------------- ------------------- ------------------- ------------------- ------------------- ------------------- ------------------- ------------------- ------------------- ------------------- ------------------- ------------------- ------------------- ------------------- ------------------- ------------------- ------------------- ------------------- ------------------- ------------------- ------------------- ------------------- ------AAAAAAA------ -----AAAAAAAAA----- ----ACCAAAAAAAAA--- ---AACCCCCCCCAAAA-- --AAA--------AAAA-- ------------------- ------------------- ------------------- 
------------------- ------------------- ------------------- ------------------- ------------------- ------------------- ------------------- ------------------- ------------------- ------------------- ------------------- ------------------- ------------------- ------------------- ------------------- ------------------- ------------------- ------------------- ------------------- ------------------- ------------------- --------AAA-------- ------AAAAAAA------ -----AAAAAAAAA----- ----AAAAABAAAAA---- ---AACCCC-BBBBAA--- --AACCCCC-BBBBBAA-- -AAA-----------AAA- ------------------- ------------------- ------------------- 
--------DDD-------- ------------------- ------------------- ------------------- ------------------- ------------------- ------------------- ------------------- ------------------- ------------------- ------------------- ------------------- ------------------- ------------------- ------------------- ------------------- ------------------- ------------------- ------------------- ------------------- -------AAAAA------- ------AAAAAAA------ ----AAAAAAAAAA----- ----AAAAABBAAAA---- ---AAAABBBBBBAAA--- --AACCCCCBBBBBBAA-- -AACCCCCCBBBBBBBAA- -AA-------------AA- ------------------- ------------------- ------------------- 
------DDDDDDD------ ------------------- ------------------- ------------------- ------------------- ------------------- ------------------- ------------------- ------------------- ------------------- ------------------- ------------------- ------------------- ------------------- ------------------- ------------------- ------------------- ------------------- ------------------- -------AAAAA------- ------AAAAAAA------ -----AAAAAAAAA----- ----AAAABBBAAAA---- ---AAAABBBB-AAAA--- ---AAAC--BBBBBAAA-- --AACCC--BBBBBBBAA- -ACCCC---BBBBBBBCA- AA---------------AA ------------------- ------------------- ------------------- 
------DEEEEBDD----- -------DDDDD------- ------------------- ------------------- ------------------- ------------------- ------------------- ------------------- ------------------- ------------------- ------------------- ------------------- ------------------- ------------------- ------------------- ------------------- ------------------- --------AAA-------- -------AAAAA------- ------AAAAAAA------ -----AAAAAAAAA----- -----AAABBBAAAA---- ----AAABBBBBAAA---- ---AAAB-BBBBBAAA--- --AAAB--BBBBBBAAA-- -AAACB--BBBBBBBBAA- -ACCCB--BBBBBBBBCAA AA---------------AA ------------------- ------------------- ------------------- 
-----DDE---BDD----- -------DEEED------- --------DDD-------- ------------------- ------------------- ------------------- ------------------- ------------------- ------------------- ------------------- ------------------- ------------------- ------------------- ------------------- --------A-A-------- --------AAA-------- --------AAA-------- -------AAAAA------- -------AAAAAA------ ------AAABAAA------ -----AAABBBAAA----- ----AAABBBB-AAA---- ----AABBBBBBCAAA--- ---AAABBBBBB-BAA--- --AAABBBBBBB-BBAA-- -AAACBBBBBB--BBBAA- AACCCBBBBBB--BBBCAA AA---------------AA ------------------- ------------------- ------------------- 
-----DDE---BED----- -------DE-EDD------ --------DED-------- ---------G--------- ---------G--------- ---------G--------- ---------G--------- ---------G--------- ---------G--------- ---------G--------- ---------G--------- ---------G--------- ---------G--------- ---------G--------- ---------G--------- --------AEA-------- --------AEA-------- -------AAAAA------- -------AABAAA------ ------AABBBAA------ -----AAABBB-AA----- ----AAABBBB-AAA---- ----AABBBBBBCAAA--- ---AABBBBBBB-BAA--- --AABBBBBBBB-BBAA-- -AAC-BBBBBB--BBBAA- AACC-BBBBBB--BBBCCA AA----------------A ------------------- ------------------- ------------------- 
-----DDE---BDD----- -------DEEED------- --------DDD-------- ------------------- ------------------- ------------------- ------------------- ------------------- ------------------- ------------------- ------------------- ------------------- ------------------- ------------------- --------A-A-------- --------AAA-------- --------AAA-------- -------AAAAA------- -------AAAAAA------ ------AAABBAA------ -----AAABBBAAA----- ----AAABBBBBAAA---- ----AABBBBBBCAAA--- ---AABBBBBBB-BAA--- --AAABBBBBBB-BBAA-- -AACCBBBBBBB-BBBAA- AACCCBBBBBBB-BBBCAA AA---------------AA ------------------- ------------------- ------------------- 
------DEEEEBDD----- -------DDDDD------- ------------------- ------------------- ------------------- ------------------- ------------------- ------------------- ------------------- ------------------- ------------------- ------------------- ------------------- ------------------- ------------------- ------------------- ------------------- --------AAA-------- -------AAAAA------- ------AAAAAAA------ -----AAAABAAAA----- -----AAABBBBAAA---- ----AAABBBBBAAA---- ---AAABBBBBBBAAA--- --AAACBBBBBBBBAAA-- -AACCCBBBBBBBBBAAA- -ACCCCBBBBBBBB-CCAA AA---------------AA ------------------- ------------------- ------------------- 
------DDDEDDD------ ---------D--------- ------------------- ------------------- ------------------- ------------------- ------------------- ------------------- ------------------- ------------------- ------------------- ------------------- ------------------- ------------------- ------------------- ------------------- ------------------- ------------------- --------AAA-------- -------AAAAA------- ------AAAAAAA------ -----AAAAAAAAA----- ----AAAAJJJAAAA---- ---AAAABBBBBBAAA--- ---AACCBBBBBBBAAA-- --ACCCCBBBBBBBBAAA- -ACCCCCBBBBBBB-CCA- AA---------------AA ------------------- ------------------- ------------------- 
-------DDDDD------- ------------------- ------------------- ------------------- ------------------- ------------------- ------------------- ------------------- ------------------- ------------------- ------------------- ------------------- ------------------- ------------------- ------------------- ------------------- ------------------- ------------------- ------------------- ------------------- -------AAAAA------- ------AAAAAAA------ -----AAAAAAAAA----- ----AAAABBBAAAA---- ---AAACCBBBBBAAA--- --AACCCCBBBBBBAAA-- -AABCCCCBBBBBBCCAA- -AA-------------AAA ------------------- ------------------- ------------------- 
------------------- ------------------- ------------------- ------------------- ------------------- ------------------- ------------------- ------------------- ------------------- ------------------- ------------------- ------------------- ------------------- ------------------- ------------------- ------------------- ------------------- ------------------- ------------------- ------------------- ------------------- -------AAAAA------- ------AAAAAAA------ -----AAAAAAAAAA---- ----AAAABBBAAAAA--- ---AACCCBBBBBAAAA-- --AABCCCBBBBBCCCAA- -AAA------------AA- ------------------- ------------------- ------------------- 
------------------- ------------------- ------------------- ------------------- ------------------- ------------------- ------------------- ------------------- ------------------- ------------------- ------------------- ------------------- ------------------- ------------------- ------------------- ------------------- ------------------- ------------------- ------------------- ------------------- ------------------- ------------------- --------AAA-------- ------AAAAAAA------ -----AAAAAAAAAA---- ---AAACAJJJAAAAA--- --AAABCC---CCCCAA-- --AAA----------AA-- ------------------- ------------------- ------------------- 
------------------- ------------------- ------------------- ------------------- ------------------- ------------------- ------------------- ------------------- ------------------- ------------------- ------------------- ------------------- ------------------- ------------------- ------------------- ------------------- ------------------- ------------------- ------------------- ------------------- ------------------- ------------------- ------------------- ------------------- ------AAAAAAA------ -----AAAAAAAAAA---- ---AAACCCCCCCAAA--- ---AAA-------AAAA-- ------------------- ------------------- ------------------- 
------------------- ------------------- ------------------- ------------------- ------------------- ------------------- ------------------- ------------------- ------------------- ------------------- ------------------- ------------------- ------------------- ------------------- ------------------- ------------------- ------------------- ------------------- ------------------- ------------------- ------------------- ------------------- ------------------- ------------------- ------------------- ------AAAAAAA------ -----ACCCHCCCAA---- ----AA---H---AA---- ---------H--------- ------------------- ------------------- 
------------------- ------------------- ------------------- ------------------- ------------------- ------------------- ------------------- ------------------- ------------------- ------------------- ------------------- ------------------- ------------------- ------------------- ------------------- ------------------- ------------------- ------------------- ------------------- ------------------- ------------------- ------------------- ------------------- ------------------- ------------------- ---------F--------- ------AAAFAAA------ ------AAAFAAAA----- ---------I--------- ---------I--------- ------------------- 
------------------- ------------------- ------------------- ------------------- ------------------- ------------------- ------------------- ------------------- ------------------- ------------------- ------------------- ------------------- ------------------- ------------------- ------------------- ------------------- ------------------- ------------------- ------------------- ------------------- ------------------- ------------------- ------------------- ------------------- ---------H--------- ---------F--------- ---------I--------- ---------F--------- ---------F--------- ---------F--------- ---------H--------- 
------------------- ------------------- ------------------- ------------------- ------------------- ------------------- ------------------- ------------------- ------------------- ------------------- ------------------- ------------------- ------------------- ------------------- ------------------- ------------------- ------------------- ------------------- ------------------- ------------------- ------------------- ------------------- ------------------- ------------------- ---------F--------- ---------F--------- ---------F--------- ------------------- ---------F--------- ---------I--------- ---------F--------- 
------------------- ------------------- ------------------- ------------------- ------------------- ------------------- ------------------- ------------------- ------------------- ------------------- ------------------- ------------------- ------------------- ------------------- ------------------- ------------------- ------------------- ------------------- ------------------- ------------------- ------------------- ------------------- ------------------- ------------------- ---------H--------- ---------F--------- ---------I--------- ---------F--------- ---------F--------- ---------F--------- ---------H--------- 
------------------- ------------------- ------------------- ------------------- ------------------- ------------------- ------------------- ------------------- ------------------- ------------------- ------------------- ------------------- ------------------- ------------------- ------------------- ------------------- ------------------- ------------------- ------------------- ------------------- ------------------- ------------------- ------------------- ------------------- ------------------- ---------F--------- ---------F--------- ---------K--------- ---------I--------- ---------F--------- ------------------- 
------------------- ------------------- ------------------- ------------------- ------------------- ------------------- ------------------- ------------------- ------------------- ------------------- ------------------- ------------------- ------------------- ------------------- ------------------- ------------------- ------------------- ------------------- ------------------- ------------------- ------------------- ------------------- ------------------- ------------------- ------------------- ------------------- ---------H--------- ---------F--------- ---------H--------- ------------------- ------------------- 
