model
size = 19 31 24, scale = 0.05, origin = -y
material 
  colors = A:#AAA B:#60F C:#66F D:#888 E:#9CF F:#6F3 G:#111 H:#6C3 I:#0C0 J:#E00 K:#3F6
voxels
------------------- ------------------- ------------------- ------------------- ------------------- ------------------- ------------------- ------------------- ------------------- ------------------- ------------------- ------------------- ------------------- ------------------- ------------------- ------------------- ------------------- ------------------- ------------------- ------------------- ------------------- ------------------- ------------------- ------------------- ------------------- ------------------- --------AAA-------- ------AAAAAAA------ ------------------- ------------------- ------------------- 
------------------- ------------------- ------------------- ------------------- ------------------- ------------------- ------------------- ------------------- ------------------- ------------------- ------------------- ------------------- ------------------- ------------------- ------------------- ------------------- ------------------- ------------------- ------------------- ------------------- ------------------- ------------------- ------------------- ------------------- ------------------- ------AAAAAAA------ -----AAAAAAAAA----- ----AAAAAAAAAAA---- ------------------- ------------------- ------------------- 
------------------- ------------------- ------------------- ------------------- ------------------- ------------------- ------------------- ------------------- ------------------- ------------------- ------------------- ------------------- ------------------- ------------------- ------------------- ------------------- ------------------- ------------------- ------------------- ------------------- ------------------- ------------------- ------------------- ------------------- ------AAAAAAA------ -----ABBBBBBBA----- ----AACCCCCCCAAA--- ---AAA-------AAA--- ------------------- ------------------- ------------------- 
------------------- ------------------- ------------------- ------------------- ------------------- ------------------- ------------------- ------------------- ------------------- ------------------- ------------------- ------------------- ------------------- ------------------- ------------------- ------------------- ------------------- ------------------- ------------------- ------------------- ------------------- ------------------- ------------------- ------AAAAAAA------ -----AAAAAAAAA----- ----ABBAAAAAAAAA--- ---AACCBBBBBBAAAA-- --AAA--------AAAA-- ------------------- ------------------- ------------------- 
------------------- ------------------- ------------------- ------------------- ------------------- ------------------- ------------------- ------------------- ------------------- ------------------- ------------------- ------------------- ------------------- ------------------- ------------------- ------------------- ------------------- ------------------- ------------------- ------------------- ------------------- --------AAA-------- ------AAAAAAA------ -----AAAAAAAAA----- ----AAAAABAAAAA---- ---AABBBBBBBBBAA--- --AA-CCCCCCCCCBAA-- -AAA-----------AAA- ------------------- ------------------- ------------------- 
--------DDD-------- ------------------- ------------------- ------------------- ------------------- ------------------- ------------------- ------------------- ------------------- ------------------- ------------------- ------------------- ------------------- ------------------- ------------------- ------------------- ------------------- ------------------- ------------------- ------------------- -------AAAAA------- ------AAAAAAA------ ----AAAAAAAAAA----- ----AAAAABBAAAA---- ---AAAABBBBBBAAA--- --AABBBBBBBBBBBAA-- -AACCCCCCCCCCCCBAA- -AA-------------AA- ------------------- ------------------- ------------------- 
------DDDDDDD------ ------------------- ------------------- ------------------- ------------------- ------------------- ------------------- ------------------- ------------------- ------------------- ------------------- ------------------- ------------------- ------------------- ------------------- ------------------- ------------------- ------------------- ------------------- -------AAAAA------- ------AAAAAAA------ -----AAAAAAAAA----- ----AAAABBBAAAA---- ---AAAABBBBBAAAA--- ---AAABBBBBBBBAAA-- --AABBBBBBBBBBBBAA- -ACCCCCCCCCCCCCCBA- AA---------------AA ------------------- ------------------- ------------------- 
------DEEEEJDD----- -------DDDDD------- ------------------- ------------------- ------------------- ------------------- ------------------- ------------------- ------------------- ------------------- ------------------- ------------------- ------------------- ------------------- ------------------- ------------------- ------------------- --------AAA-------- -------AAAAA------- ------AAAAAAA------ -----AAAAAAAAA----- -----AAABBBAAAA---- ----AAABBBB-AAA---- ---AAABBBBBBBAAA--- --AAABBBBBBBBBAAA-- -AAABBBBBBBBBBBBAA- -ACCCCCCCCCCCCCCBAA AA---------------AA ------------------- ------------------- ------------------- 
-----DDE---JDD----- -------DEEED------- --------DDD-------- ------------------- ------------------- ------------------- ------------------- ------------------- ------------------- ------------------- ------------------- ------------------- ------------------- ------------------- --------A-A-------- --------AAA-------- --------AAA-------- -------AAAAA------- -------AAAAAA------ ------AAABAAA------ -----AAABBBAAA----- ----AAABBBBBAAA---- ----AABBBBBBBAAA--- ---AAABBBBBBBBAA--- --AAABBBBBBBBBBAA-- -AAABBBBBBBBBBBBAA- AACCCCCCCCCCCCCCBAA AA---------------AA ------------------- ------------------- ------------------- 
-----DDE---JED----- -------DE-EDD------ --------DED-------- ---------G--------- ---------G--------- ---------G--------- ---------G--------- ---------G--------- ---------G--------- ---------G--------- ---------G--------- ---------G--------- ---------G--------- ---------G--------- ---------G--------- --------AEA-------- --------AEA-------- -------AAAAA------- -------AABAAA------ ------AABBBAA------ -----AAABBBBAA----- ----AAABBBBBAAA---- ----AABBBBBBBAAA--- ---AABBBBBBBBBAA--- --AABBBBBBBBBBBAA-- -AACBBBBBBBBBBBBAA- AACCCCCCCCCCCCCCBBA AA----------------A ------------------- ------------------- ------------------- 
-----DDE---JDD----- -------DEEED------- --------DDD-------- ------------------- ------------------- ------------------- ------------------- ------------------- ------------------- ------------------- ------------------- ------------------- ------------------- ------------------- --------A-A-------- --------AAA-------- --------AAA-------- -------AAAAA------- -------AAAAAA------ ------AAABBAA------ -----AAABBBAAA----- ----AAABBBBBAAA---- ----AABBBBBBBAAA--- ---AABBBBBBBBBAA--- --AAABBBBBBBBBBAA-- -AACCBBBBBBBBBBBAA- AACCCCCCCCCCCCCCBAA AA---------------AA ------------------- ------------------- ------------------- 
------DEEEEJDD----- -------DDDDD------- ------------------- ------------------- ------------------- ------------------- ------------------- ------------------- ------------------- ------------------- ------------------- ------------------- ------------------- ------------------- ------------------- ------------------- ------------------- --------AAA-------- -------AAAAA------- ------AAAAAAA------ -----AAAABAAAA----- -----AAABBBBAAA---- ----AAABBBBBAAA---- ---AAABBBBBBBAAA--- --AAABBBBBBBBBAAA-- -AACCBBBBBBBBBBAAA- -ACCCCCCCCCCCCCBBAA AA---------------AA ------------------- ------------------- ------------------- 
------DDDEDDD------ ---------D--------- ------------------- ------------------- ------------------- ------------------- ------------------- ------------------- ------------------- ------------------- ------------------- ------------------- ------------------- ------------------- ------------------- ------------------- ------------------- ------------------- --------AAA-------- -------AAAAA------- ------AAAAAAA------ -----AAAAAAAAA----- ----AAAABBBAAAA---- ---AAAABBBBBBAAA--- ---AABBBBBBBBBAAA-- --ACCBBBBBBBBBBAAA- -ACCCCCCCCCCCCCBBA- AA---------------AA ------------------- ------------------- ------------------- 
-------DDDDD------- ------------------- ------------------- ------------------- ------------------- ------------------- ------------------- ------------------- ------------------- ------------------- ------------------- ------------------- ------------------- ------------------- ------------------- ------------------- ------------------- ------------------- ------------------- ------------------- -------AAAAA------- ------AAAAAAA------ -----AAAAAAAAA----- ----AAAABBBAAAA---- ---AAABBBBBBBAAA--- --AACCBBBBB--BAAA-- -AA-CCCCCCC--CBBAA- -AA-------------AAA ------------------- ------------------- ------------------- 
------------------- ------------------- ------------------- ------------------- ------------------- ------------------- ------------------- ------------------- ------------------- ------------------- ------------------- ------------------- ------------------- ------------------- ------------------- ------------------- ------------------- ------------------- ------------------- ------------------- ------------------- -------AAAAA------- ------AAAAAAA------ -----AAAAAAAAAA---- ----AAAA---AAAAA--- ---AACCCCCCBBAAAA-- --AA-CCCCCCCCBBBAA- -AAA------------AA- ------------------- ------------------- ------------------- 
------------------- ------------------- ------------------- ------------------- ------------------- ------------------- ------------------- ------------------- ------------------- ------------------- ------------------- ------------------- ------------------- ------------------- ------------------- ------------------- ------------------- ------------------- ------------------- ------------------- ------------------- ------------------- --------AAA-------- ------AAAAAAA------ -----AAAAAAAAAA---- ---AAACACCCAAAAA--- --AAA-CBCCCBBBBAA-- --AAA----------AA-- ------------------- ------------------- ------------------- 
------------------- ------------------- ------------------- ------------------- ------------------- ------------------- ------------------- ------------------- ------------------- ------------------- ------------------- ------------------- ------------------- ------------------- ------------------- ------------------- ------------------- ------------------- ------------------- ------------------- ------------------- ------------------- ------------------- ------------------- ------AAAAAAA------ -----AAAAAAAAAA---- ---AAABBBBBBBAAA--- ---AAA-------AAAA-- ------------------- ------------------- ------------------- 
------------------- ------------------- ------------------- ------------------- ------------------- ------------------- ------------------- ------------------- ------------------- ------------------- ------------------- ------------------- ------------------- ------------------- ------------------- ------------------- ------------------- ------------------- ------------------- ------------------- ------------------- ------------------- ------------------- ------------------- ------------------- ------AAAAAAA------ -----ABBBHBBBAA---- ----AA---H---AA---- ---------H--------- ------------------- ------------------- 
------------------- ------------------- ------------------- ------------------- ------------------- ------------------- ------------------- ------------------- ------------------- ------------------- ------------------- ------------------- ------------------- ------------------- ------------------- ------------------- ------------------- ------------------- ------------------- ------------------- ------------------- ------------------- ------------------- ------------------- ------------------- ---------F--------- ------AAAFAAA------ ------AAAFAAAA----- ---------I--------- ---------I--------- ------------------- 
------------------- ------------------- ------------------- ------------------- ------------------- ------------------- ------------------- ------------------- ------------------- ------------------- ------------------- ------------------- ------------------- ------------------- ------------------- ------------------- ------------------- ------------------- ------------------- ------------------- ------------------- ------------------- ------------------- ------------------- ---------H--------- ---------F--------- ---------I--------- ---------F--------- ---------F--------- ---------F--------- ---------H--------- 
------------------- ------------------- ------------------- ------------------- ------------------- ------------------- ------------------- ------------------- ------------------- ------------------- ------------------- ------------------- ------------------- ------------------- ------------------- ------------------- ------------------- ------------------- ------------------- ------------------- ------------------- ------------------- ------------------- ------------------- ---------F--------- ---------F--------- ---------F--------- ------------------- ---------F--------- ---------I--------- ---------F--------- 
------------------- ------------------- ------------------- ------------------- ------------------- ------------------- ------------------- ------------------- ------------------- ------------------- ------------------- ------------------- ------------------- ------------------- ------------------- ------------------- ------------------- ------------------- ------------------- ------------------- ------------------- ------------------- ------------------- ------------------- ---------H--------- ---------F--------- ---------I--------- ---------F--------- ---------F--------- ---------F--------- ---------H--------- 
------------------- ------------------- ------------------- ------------------- ------------------- ------------------- ------------------- ------------------- ------------------- ------------------- ------------------- ------------------- ------------------- ------------------- ------------------- ------------------- ------------------- ------------------- ------------------- ------------------- ------------------- ------------------- ------------------- ------------------- ------------------- ---------F--------- ---------F--------- ---------K--------- ---------I--------- ---------F--------- ------------------- 
------------------- ------------------- ------------------- ------------------- ------------------- ------------------- ------------------- ------------------- ------------------- ------------------- ------------------- ------------------- ------------------- ------------------- ------------------- ------------------- ------------------- ------------------- ------------------- ------------------- ------------------- ------------------- ------------------- ------------------- ------------------- ------------------- ---------H--------- ---------F--------- ---------H--------- ------------------- ------------------- 
