model
size = 9 32 9, scale = 0.05, origin = -y
material 
  colors = A:#040 B:#030 C:#FF0 D:#EEE E:#001
voxels
2-10(5A4-)5C4-5D4(4-2(ED)E)4-2(DE)D4-5D4-5C2(4-5A)5-3A94-2A3B9(2A2-2A3-)2A2-2C3-2C2-CD3-DC5(2-DA3-AD)2-CA3-AC2-2C3-2C2-2A3-2A2-3A-3A2-7A4-4A83-2A5B10(4A5-)2AC6(A5-A2C)A5-2(AC)2(5-4A)5-2A-2A3-2A2-6A4-5A5-3A7-A58-A7B19(2A7-)3A5-4A5-2A-2(2A3-)2A-2A4-2(A-)A5-6(3A6-)3B3-A7B20(2A7-)3A5-2A-2(2A3-)A3-A2(4-2A-2A)5-5(A-A6-)B-B3-A7B19(2A7-)3A5-4A5-2A-2(2A3-)2A-2A4-2(A-)A5-6(3A6-)3B3-2A5B20(4A5-)2A-2(2A3-)6A3-5A5-3A7-A59-2A3B19(2A2-2A3-)2A2-3A-3A2-7A3-4A86-20(5A4-)5A5-3A93-
