model
size = 32 30 32, scale = 0.05, origin = -y
material 
  colors = A:#BBFA8B B:#EDFFE8 C:#360 D:#FF0 E:#100 F:#070 G:#040 H:#0F0 I:#0C0 J:#050 K:#FFF L:#111 M:#060
voxels
320-32C928-C6A4(C5A)C-6AC4A8-5AC5A897-C6A4(C5A)C-10A10-10A3-5AC3A10-4AC4A866-C6A4(C5A)C-10A4-2A4-10A3-8A5-2C5-8A5-4AC2A12-3AC3A18-HI29-H2-I28-I-BH29-IH62-2C655-C6A4(C5A)C-10A3-4A3-10A3-8A3-6C3-8A5-6A5-B2FB5-6A7-5C4-BF2-F5-5C17-FE2-EF26-FB2EGF27-F2JF29-2F28-6C28-2A623-C6A4(C5A)C-10A2-6A2-10A3-8A2-C-B2-2BC2-8A5-6A2-C-BG2EGB-C2-6A7-C3AC2-2BFE3-FBK2-C3AC9-4A2-BFAE3-BFB2-4A16-BF2AELEBFB23-BF4AFB23-C-BG3AB-C23-2C5AC26-4A622-C6A4(C5A)C-10A-8A-10A3-8A7-4A-8A5-6A2-A2B-2E-AB2A-6A7-C3AC-CB2AE2-EA2BC-C3AC9-4AC2-2AE2-E3A-C4A11-3AC2-3AEL4A-C3A16-CB2A2-4ABC21-CB6ABC23-AC-2A-AC26-4A622-32C-C8AC-6A-A-C8AC3-C6AC2(-A)3-4A-C6AC5-C4AC-A7-4A-C4AC7-C5AB4-2E-9AC9-4A2B4-2E4AB5A11-3A-B2-2AB5AK-3A13-8A2-8A17-CA-6A-AC22-A-4A-C25-C5A28-2A591-C6A4(C5A)C-30A3-13A2-13A5-11A4-11A7-C9A4-9AC9-4AB5A2-10A11-16A-3A13-3A2-C2A2F2AC2-3A15-3C10A3C19-2A-4A-CA24-C4-A27-4A590-C6A4(C5A)C-14A2B14A3-10A3B2-2B11A5-9A2B3-EB10A7-C7A2B3-EB8AC9-7A3B-E2B8A11-6A7B3A-3A13-3A2-A2B2G2BA2-3A15-CA3-6A3-AC17-4A-5A-3A21-AC4-AC26-4A590-C6A4(C5A)C-10A10B10A3-9A4B2A4B9A5-7A4B-2A-3B2AC5A7-C5A4B-2A-3B6AC9-C5A4BAE4B5AC11-C4A10BA-2AC13-C2A-A8BA-2AC15-CA2-8A2-AC17-4AB-2A2B4A19-5AC3AC2A23-C5A28-2C559-C6A4(C5A)C-9A12B9A3-9A11B8A5-7A5B2A5B7A7-C5A5B2A5B5AC9-5A5BA5B6A11-4A11B5A13-4A10B4A15-C14AC17-5A-2AB5A19-12A21-2AC5ACA25-4C558-C6A4(C5A)C-9A12B9A3-8A12B8A5-6A14B6A7-C4A14B4AC9-5A12B5A11-4A12B4A13-4A10B4A15-C-2A8B3AC17-A12CA19-12A21-10A23-8C556-32C-C7A14B7AC3-C6A14B6AC5-C5A14B5AC7-C4A14B4AC9-4A14B4A11-3A14B3A13-3A12B3A15-C-A10B2AC17-CAM8B2AC19-C4AM5AC21-C8AC23-C6AC25-3AC2A220-8(D31-)D48-C6A4(C5A)C-8A14B8A3-7A14B7A5-6A14B6A7-C4A14B4AC9-4A14B4A11-3A14B3A13-3A12B3A15-C-A10B2AC17-3A8B3A19-4A3B5A21-10A23-C6AC25-6A27-2ACA217-D7-D23-D7-D24-2(D5-D25-)D5-D26-D3-D27-D3-D78-C6A4(C5A)C-9A12B9A3-7A14B7A5-6A14B6A7-C4A14B4AC9-4A14B4A11-4A12B4A13-3A12B3A15-C-A10B2AC17-3A8B3A19-4A3B5A21-10A19-D3-C6AC3-D15-D5-6A5-D13-D7-4A7-D11-D9-2A2(9-D)22-D7-D24-D5-D26-D354-C6A4(C5A)C-9A12B9A3-8A12B8A5-6A14B6A7-C4A14B4AC9-C4A12B4AC11-C3A12B3AC13-C2A12B2AC15-C2A10B2AC17-3A8B3A19-5A2B5A15-2D4-10A4-2D9-D7-C6AC2(7-D)9-C4AC9-D4-2D6-D4-C2AC4-D6-2D10-D5-2A5-D17-D14-D15-D16-D13-D18-D12-D18-D326-C6A4(C5A)C-9A12B9A3-8A12B8A5-7A12B7A7-C5A12B5AC9-5A12B5A11-4A12B4A13-4A10B4A15-C3A8B3AC17-4A6B4A19-12A21-10A23-C6AC25-6A27-2ACA494-C6A4(C5A)C-10A10B10A3-9A10B4A-4A5-8A10B4A-3A7-C6A10B6AC9-6A10B6A11-5A10B5A13-5A8B5A15-C4A6B4AC17-14A19-12A21-10A23-C6AC25-3AC2A525-32C-C10A8B5A-4AC3-C9A8B5A-3AC5-C8A8B5A-2AC7-C7A8B7AC9-7A8B7A11-6A8B6A13-6A6B6A15-C6A-7AC17-C5A-6AC19-C10AC21-C8AC23-8C556-C6A4(C5A)C-14A2B14A3-12A4B12A5-10A6B10A7-C8A6B8AC9-9A4B9A11-9A2B9A13-8A-9A15-C6A-7AC17-14A19-12A21-2AC5ACA587-C6A4(C5A)C-30A3-28A5-26A7-C22AC9-22A11-20A13-18A15-C14AC17-14A19-3AC5AC2A618-C6A4(C5A)C-30A3-28A5-26A7-C22AC9-C20AC11-C18AC13-C16AC15-C14AC17-4AC5AC3A649-C6A4(C5A)C-30A3-28A5-26A7-C22AC9-22A11-20A13-18A15-16C680-C6A4(C5A)C-30A3-28A5-26A7-C22AC9-22A11-20A13-3A2(C5A)C2A711-32C-C28AC3-C26AC5-C24AC7-C22AC9-22A11-4A2(C5A)C3A742-C6A4(C5A)C-30A3-28A5-26A7-C22AC9-3(5AC)4A773-C6A4(C5A)C-30A3-28A5-26A7-24C804-C6A4(C5A)C-30A3-28A5-4A3(C5A)C3A835-C6A4(C5A)C-30A3-4(5AC)4A866-C6A4(C5A)C-6A4(C5A)897-32C608-
