model
size = 10 11 9, scale = 0.05, origin = -y
material 
  colors = A:#777 B:#888 C:#DDD D:#EEE E:#AAA F:#555 G:#960 H:#F96 I:#FCF J:#FFF K:#111 L:#F90 M:#BBB
voxels
---------- ---------- ---------- ----II---- ---K--K--- ---------- ---------- ---------- ---------- ---------- ---------- 
---------- ----DD---- --GHHHHG-- --DDIIDD-- --CECCMC-- --CCCCCD-- ---------- ---------- ---------- ---------- ---------- 
-J------J- -A------A- -A------A- -A------B- -ACBBBBCB- -ACLB-LCB- --ABBBBB-- ---------- ---------- ---------- ---------- 
---------- ---------- -A------B- ---------- -AC----CB- --B----B-- -AA----BB- ---ABBB--- ---------- ---------- ---------- 
---------- ---------- -A------B- -A------B- --B----B-- -A------B- -AA----BB- AA-ABBB-BB BE------EE GE------EG FF------FF 
---------- -A-------- -A------B- ---------- -A------B- --A----B-- -AA----AB- ---ABBB--- ---------- ---------- ---------- 
---------- ---------- -AF----BA- -A------B- -A------B- -A------B- --AABAAA-- ---------- ---------- ---------- ---------- 
---------- ---B--B--- ---A--A--- --A-AA-A-- --A----A-- --AAAAAA-- ---------- ---------- ---------- ---------- ---------- 
---------- ---B--B--- ---A--A--- ---AAAA--- ---AAAA--- ---------- ---------- ---------- ---------- ---------- ---------- 
