model
size = 15 16 30, scale = 0.05, origin = -y
material 
  colors = A:#D00 B:#222 C:#EEE D:#3FF E:#E00 F:#C3F
voxels
--------------- --------------- --------------- ----EEEEEEEE--- --------------- --------------- ----EEEEEEEE--- --------------- --------------- ----EEEEEEEE--- --------------- --------------- ----EEEEEEEE--- --------------- --------------- --------------- 
----C-C-C-C-C-- ----BBBBBBBBB-- ----AAAAAAAA--- ----AAAAAAAA--- ----AAAAAAAA--- ----AAAAAAAA--- ----AAAAAAAA--- ----AAAAAAAA--- ----AAAAAAAA--- ----AAAAAAAA--- ----AAAAAAAA--- ----AAAAAAAA--- ----AAAAAAEA--- -----AAAAAA---- ------AAAA----- --------------- 
---CCCCCCCCCC-- ---BBBBBBBBBB-- ---AAAAAAAAAA-- ---AAAAAAAAAA-- ---AAAAAAAAAA-- ---AAAAAAAAAA-- ---AAAAAAAAAA-- ---AAAAAAAAAA-- ---AAAAAAAAAA-- ---AAAAAAAAAA-- ---AAAAAAAAAA-- ---AAAAAAAAAA-- ---AAAAAAAAAAA- ---AA-AAAAAA--- ---AAAAAAAA---- --------------- 
--CCCCCCCCCCCC- --BBBBBBBBBBBB- --AAAAAAAAAAA-- --AAAAAAAAAAA-- --AAAAAAAAAAA-- --AAAAA-AAAAA-- --AAAAA-AAAAA-- --AAAAAAAAAAA-- --AAAABBBBAAA-- --ABBBBBBBAAA-- --ABBBBBBBAAA-- --ABBBBBBBAAAA- --ABBBBBBBAAAA- --ABBBBBBBAA--- --ABBBBBBBAA--- --------------- 
--CCCCCCCCCCCC- --BBBBBBBBBBBB- -AAAAAAAAAAAAA- -A-AAAAAAAAAA-- -AAAAAAAAAAAA-- -AAAAA-AAAAAA-- -AAAAA-AA-AAA-- -AAAAAAAAAAAA-- -AABBBBBBBBAA-- -ABB-----BBAA-- -ABB-----BBAAA- -ABB-----BAAAA- -ABB-----BAAAA- -ABB-----BAA--- -ABB-----BBA--- --------------- 
-CCCCCCCCCCCCCC -BBBBBBBBBBBBBB -AAAAAAAAAAAAA- -AAAAAAAAAAAAA- -AAAAAAAAAAAA-- -AAAAAAAAAAAA-- -AAAAAAAAAAAA-- -AAAAAAAAAAAA-- -AABBBBBBBBAA-- -AB-------BAAA- -AB-------BAAA- -AB-------BAAA- -AB-------BAA-- -AB-------BA--- -AB-------BA--- --------------- 
CCCCCCCCCCCCCC- BBBBBBBBBBBBBBB AAAAAAAAAAAAAA- AAAAAAAAAAAAAA- AAAAAAAAAAAAAA- AAAAAAAAAAAAA-- AAAAAAAAA-AAA-- AAAAAAAAAAAAA-- AAABBBBBBBBAAA- AAB-------BAAA- AAB-------BAAA- -AB-------BAAA- -AB-------BAA-- -AB-------BA--- -AB-------BA--- --------------- 
-CCCCDDDDDDDCCC BBBBBBBBBBBBBBB AAAAAAAAAAAAAA- AAAAAAAAAAAAAA- AAAAAAAAAAAAAA- AAAAAAAAAAAAAA- AAAAAAAAAAAAA-- AAAAAAAAAAAAAA- AAABBBBBBBBAAA- AAB-------BAAA- AAB-------BAAA- -AB-------BAA-- -AB-------BAA-- -AB-------BA--- -AB-------BA--- --------------- 
CCCCCDDDDDDDCC- BBBBBBBBBBBBBBB AAAAAABBBBBBAA- AAAAAAAAAAAAAA- AAAAAAAAAAAAAA- AAAA-AAAAAAAAA- AAAAAAAAAAAAAA- AAAAAAAAAAAAFA- AAABBBBBBBBAAA- AAA-------BAAA- -AB-------BAAA- -AB-------BAA-- -AB-------BAA-- -AB-------BA--- -AB-------BA--- --------------- 
-CCCDDDDDDDDDCC BBBBBDDBDDDDBBB AAAAABBBBBBBAA- AAAAAAAAAAAAAA- AAAAAAAAAAAAAA- AAAAAAAAAAAAFA- AAAAAAAAAAAAAA- AAAAAAAAAAAAFA- AAABBBBBBBBAFA- -AAB-----BBAAA- -AAB-----BBAA-- -ABB-----BBAA-- -ABB-----BBA--- -ABB-----BBA--- -ABB-----BBA--- --------------- 
CCCCDDDDDDDDDC- BBBBBBBBBBBBBBB AAAAABBBBBBBAA- AAAAAAAAAAAAAA- AAAAAAAAAAAAFA- AAAAAAAAAAAAAA- AAA--AAAAAAAAA- AAAAAAAAAAAAAA- -AAAAAAAAAAAAA- -AAAAAAAAAAAA-- -AAAAAAAAA-AA-- -AAAAAAAAAAA--- -AABBBBBBAAA--- -AA-BBBBBAAA--- -AABBBBBBBAA--- ----BBBBBB----- 
-CCCDDDDDDDDDCC BBBBBBBBBBBBBBB AAAAABBBBBBBAA- AAAAAAAAAAAAAA- A-AAAAAAAAAAAA- AAAAAAAAAAAAFA- AAAAAAAAAAAAAA- -AAAAAAAAA-AAA- -AAA-AAAAA-AA-- -AAAAAAAAAAAA-- -AA-AAAAAA-A--- -AAAAAAAAAAA--- -AAAAAAAAAA---- -AAABBBBAAA---- --AABBBBBAA---- ----BBBBB------ 
CCCCDDDDDDDDDC- BBBBBBBBBBBBBBB AAAAABBBBBBBAA- AAAAAAAAAAAAAA- AAAAAAAAAAAAAA- AAAAAAAAAAAAAA- -AAAAAAAAAAAA-- -AAAAAAAAAAAA-- -AAAAAAAAAAAA-- -AAAAAAAAAAA--- --AAAAAAAAA---- --AAAAAAAAA---- --AAAAAAAA----- --AAAAAAAA----- ----AAAAA------ --------------- 
-CCCDDDDDDDDDCC BBBBBBBBBBBBBBB AAAAABBBBBBBAA- AAAAABAAAAAAAA- AAAAAAAAAAAAAA- -AAAAAAAAAAAA-- -AAAAAAAAAAAA-- -AAAAAAAAAAAA-- --AA-AAAAA-A--- ---AAAAAAAAA--- ---AAAAAAAA---- ---AAAAAAAA---- ---AAAAAAAA---- ---AAAAAAA----- --------------- --------------- 
CCCCDDDDDDDDDC- BBBBBBBBBBBBBBB AAAAABBBBBBBAA- AAAAAAAAAAAAAA- -AAAAAAAAAAAA-- -AAAAAAAAAAAA-- -AAAAAAAAAAAA-- -AAAAAA-AAAA--- ---AAA---AAA--- ---AAAAA--A---- ----AA----A---- ----AACCA------ ----AAAAA------ ----AAAAA------ --------------- --------------- 
-CCCDDDDDDDDDCC BBBBBBBBBBBBBBB AAAAABBBBBBBAA- -AAAAAAAAAAAA-- -AAAAAAAAAAAA-- -AAAAAAAAAAAA-- -AAAAAAAAAAA--- ---AAAAAAAAA--- ---AAAAAAAA---- ----AAAAAAA---- ----ACCCCC----- -----AAAAA----- -----CCCCC----- --------------- --------------- --------------- 
CCCCDDDDDDDDDC- BBBBBBBBBBB-BBB AAAAABBBBBAAAA- -AAAAAAAAAAAA-- -AAAAAAAAAAAA-- -AAAAAAAAAAAA-- --AAAAAAAAAA--- ---AAAAAA-A---- ----AAAAAAA---- ----AAAAAAA---- --------------- --------------- --------------- --------------- --------------- --------------- 
-CCCDDDDDDDDDCC BBBBBBBBBBBB-BB AAAAABBBBBBAAA- -AAAAAAAAAAAA-- -AAAAAAAAAAAA-- --AAAAAAAAAAA-- --AAAAAAAAA---- ---AAAAAAAA---- ----AAAAAAA---- -----CCCCC----- --------------- --------------- --------------- --------------- --------------- --------------- 
CCCCDDDDDDDDDC- BBBBBBBBBBBB-BB AAAAABBBBBBAAA- -AAAAAAAAAAAA-- --AAAAAAAAAAA-- --AAAAAAAAAA--- --AAAAAAAAA---- ---AAAAAAAA---- --------------- --------------- --------------- --------------- --------------- --------------- --------------- --------------- 
-CCCDDDDDDDDDCC BBBBBBBBBBBBBBB AAAAABBBBBBAAA- -AAAAAAAAAAAA-- --AAAAAAAAAAA-- --AAAAAAAAAA--- ---AAAAAAAA---- ----AAAAAA----- -----CCCCC----- --------------- --------------- --------------- --------------- --------------- --------------- --------------- 
CCCCDDDDDDDDDC- BBBBBBBBBBBBBBB AAAAABBBBABAAA- -AAAAAAAAAAAA-- --AAAAAAAAAAA-- --AAAAAAAAAA--- ---AAAAAAAA---- -----AAAAA----- --------------- --------------- --------------- --------------- --------------- --------------- --------------- --------------- 
-CCCDDDDDDDDDCC BBBBBBBBBBBBBBB AAAAAAAAAAAAAA- -AAAAAAAAAAAA-- --AAAAAAAAAAA-- --AAAAAAAAAA--- ----AAAAAA----- ------AAA------ --------------- --------------- --------------- --------------- --------------- --------------- --------------- --------------- 
CCCCCDDDDDDDCC- BBBBBBBBBBBBBBB AAAAAAAAAAAAAA- --AAAAAAAAAAA-- ---AAAAAAAAAA-- ---AAAAAAAA---- -----AAAAA----- -----CCCCC----- --------------- --------------- --------------- --------------- --------------- --------------- --------------- --------------- 
-CCCCCDDDDDCCCC BBBBBABBBBBBBBB AAAAAAAAAAAAAA- --AAA-AAAAAAA-- ---AA-A-AAAA--- ---AAAAAAAA---- ------AAA------ --------------- --------------- --------------- --------------- --------------- --------------- --------------- --------------- --------------- 
CCCCCCCCCCCCCC- BBBBBBBBBBBBBBB -AAAAAAAAAAAAA- --AAAAAAAAAAA-- ---AAAAAAAAA--- ---AAAAAAAA---- --------------- --------------- --------------- --------------- --------------- --------------- --------------- --------------- --------------- --------------- 
-CCCCCCCCCCCCCC -BBBBBBBBBBBBBB -AAAAAAAAAAAAA- --AAAAAAAAAAA-- ---AAAAAAAA---- ----AAAAAA----- --------------- --------------- --------------- --------------- --------------- --------------- --------------- --------------- --------------- --------------- 
--CCCCCCCCCCC-- -BBBBBBBBBBBBB- --AAAAAAAAAAA-- ---AAAAAAAAA--- ----AAAAAA----- -----AAAA------ --------------- --------------- --------------- --------------- --------------- --------------- --------------- --------------- --------------- --------------- 
--CCCCCCCCCCCC- --BBBBBBBBBBBB- ---AAAAAAAAAA-- ----AAAAAAA---- -----AAAAA----- --------------- --------------- --------------- --------------- --------------- --------------- --------------- --------------- --------------- --------------- --------------- 
---C-CCCCCCCC-- ---BBBBBBBBBB-- ----AAAAAAAA--- -----AAAAA----- --------------- --------------- --------------- --------------- --------------- --------------- --------------- --------------- --------------- --------------- --------------- --------------- 
-----C-C-C-C--- -----BBBBBBB--- --------------- --------------- --------------- --------------- --------------- --------------- --------------- --------------- --------------- --------------- --------------- --------------- --------------- --------------- 
