model
size = 32, scale = 0.05, origin = -y
material 
  colors = A:#DDD B:#555 C:#0FF
voxels
4-24A7-26A5-28A3-30A-544A-2(30A2-)30A3-2(28A4-)28A5-2(26A6-)26A11-16A19-10A14-26A5-28A3-30A-672A-2(30A2-)30A3-2(28A4-)28A5-26A11-16A41-A28-A-2A24(28-4A)28-2A-2(A28-A2-)30A3-28A5-26A36-A28-A-2A26(28-4A)28-2A-2A26-2A3-28A5-26A131-2A24(28-4A)28-2A-2A26-2A3-28A5-26A323-2A18(28-4A)28-5A26-3A-30A3-28A451-3(A28-A2-)A28-A-2A10(28-4A)28-5A26-3A-30A3-28A579-3(A28-A2-)A28-A-2A6(28-4A)28-5A26-3A-30A3-28A675-2(A28-A2-)A28-A-2A4(28-4A)28-5A26-35A-30A738-2(A28-A2-)A28-A-2A2(28-4A)28-5A26-35A-30A802-2(A28-A2-)A28-A-2A28-5A26-35A-30A866-A28-A-2A28-5A26-35A-30A897-A30-4A26-67A8(928-A30-65A)896-3(A30-2A30-33A-30A897-)A30-4A26-35A-30A897-2(A30-4A26-3A-30A3-28A898-)2A28-5A26-3A-30A3-28A898-2A28-2A-2A26-2A3-28A5-26A900-A28-A3-28A5-26A6-26A817-4A25-10A13-3A3-16A3-3A4-28A5-26A6-26A7-B22AB850-4B25-3AB2CB3A13-3A3-6A4B6A3-3A5-9A2B4A2B9A7-6A2B8A2B6A10-BA2B12A2BAB6-
