model
size = 27 30 19, scale = 0.05, origin = -y
material 
  colors = A:#009 B:#005 C:#111 D:#39C E:#6C6 F:#399 G:#6FC H:#EEE I:#F66
voxels
--------------------------- --------------------------- --------------------------- --------------------------- --------------------------- --------------------------- --------------------------- --------------------------- --------------------------- --------------------------- --------------------------- --------------------------- --------------------------- --------------------------- --------------------------- --------------------------- --------------------------- --------------------------- --------------------------- -----------B--------------- --------------------------- -----------B--------------- --------------------------- --------------------------- --------------------------- --------------------------- --------------------------- --------------------------- --------------------------- --------------------------- 
--------------------------- --------------------------- --------------------------- --------------------------- --------------------------- --------------------------- --------------------------- --------------------------- --------------------------- --------------------------- --------------------------- --------------------------- --------------------------- --------------------------- --------------------------- --------------------------- --------------------------- --------------------------- --------------------------- -----------B--------------- --------------------------- -----------B--------------- --------------------------- --------------------------- --------------------------- --------------------------- --------------------------- --------------------------- --------------------------- --------------------------- 
--------------------------B -------------------------B- ------------------------B-- -----------------------B--- ----------------------B---- ---------------------B----- --------------------B------ -------------------B------- ------------------B-------- -----------------B--------- ----------------B---------- ---------------B----------- --------------B------------ ---------BBBBB------------- --BBB----BBB--------------- --AAA----AAA--------------- --AAAAAAAAAA--------------- --AAAAAAAAAA--------------- --AAAAAAAAAA--------------- --AAAAAAAAAA--------------- --AAAAAAAAAAC-------------- --AAAAAAAAAAC-------------- --AAAAAAAAAA--------------- --AAAAAAAAAA--------------- --AAAAAAAAAA--------------- --AAAAAAAAAA--------------- --ADADAAAAAA--------------- --------AAAA--------------- --------AAAA--------------- --------AAAA--------------- 
--------------------------- --------------------------- --------------------------- --------------------------- --------------------------- --------------------------- --------------------------- --------------------------- --------------------------- --------------------------- --------------------------- --------------------------- --------------------------- --------------------------- --BBB----BBB--------------- --AAA----AAA--------------- --AAAAAAAAAA--------------- --AAAAAAAAAA--------------- --AAAAAAAAAA--------------- --AAAAAAAAAAH-------------- --AAAAAAAAAAC-------------- --AAAAAAAAAA--------------- --AAAAAAAAAF--------------- --AAAAAAACCF--------------- --AAAAAAAAAF--------------- --AAAAAAAAAE--------------- --ADADAAAAAA--------------- --------AAAG--------------- --------AAAA--------------- --------AAAA--------------- 
--------------------------- --------------------------- --------------------------- --------------------------- --------------------------- --------------------------- --------------------------- --------------------------- --------------------------- --------------------------- --------------------------- --------------------------- --------------------------- --------------------------- --BBB----BBB--------------- --AAA----AAA--------------- --AAAAAAAAAA--------------- --AAAAAAAAAA--------------- --AAAAAAAAAAC-------------- --AAAAAAAAAAC-------------- --AAAAAAAAAA--------------- --AAAAAAAAAA--------------- --AAAAAAAAAC--------------- --AAAAAAAAAC--------------- --AAAAAAAAAC--------------- --AAAAAAAAAE--------------- --ADADAAAAAA--------------- --------AAAA--------------- --------AAAG--------------- --------AAAA--------------- 
--------------------------- --------------------------- --------------------------- --------------------------- --------------------------- --------------------------- --------------------------- --------------------------- --------------------------- --------------------------- --------------------------- --------------------------- --------------------------- --------------------------- --BBB----BBB--------------- --AAA----AAA--------------- --AAAAAAAAAA--------------- --AAAAAAAAAA--------------- --AAAAAAAAAAH-------------- --AAAAAAAAAAC-------------- --AAAAAAAAAA--------------- --AAAAAAAAAA--------------- --AAAAAAAAAF--------------- --AAAAAAAAAF--------------- --AAAAAAAAAF--------------- --AAAAAAAAAE--------------- --ADADAAAAAA--------------- --------AAAA--------------- --------AAAG--------------- --------AAAA--------------- 
--------------------------- --------------------------- --------------------------- --------------------------- --------------------------- --------------------------- --------------------------- --------------------------- --------------------------- --------------------------- --------------------------- --------------------------- --------------------------- --------------------------- --BBB----BBB--------------- --AAA----AAA--------------- --AAAAAAAAAA--------------- --AAAAAAAAAAC-------------- --AAAAAAAAAAC-------------- --AAAAAAAAAA--------------- --AAAAAAAAAA--------------- --AAAAAAAAAA--------------- --AAAAAAAAAE--------------- --AAAAAAAAAE--------------- --AAAAAAAAAE--------------- --AAAAAAAAAE--------------- --AAAAAAAAAA--------------- --------AAAG--------------- --------AAAA--------------- --------AAAA--------------- 
--------------------------- --------------------------- --------------------------- --------------------------- --------------------------- --------------------------- --------------------------- --------------------------- --------------------------- --------------------------- --------------------------- --------------------------- --------------------------- --------------------------- --------------------------- --------------------------- --AAAAAAAAAA--------------- --AAAAAAAAAAH-------------- --AAAAAAAAAAC-------------- --AAAAAAAAAA--------------- --AAAAAAAAAA--------------- --AAAAAAAAAA--------------- --AAAAAAAAAA--------------- --AAAAAAAAAA--------------- --AAAAAAAAAA--------------- --AAAAAAAAAA--------------- --AAAAAAAAAA--------------- --------------------------- --------------------------- --------------------------- 
--------------------------- --------------------------- --------------------------- --------------------------- --------------------------- --------------------------- --------------------------- --------------------------- --------------------------- --------------------------- --------------------------- --------------------------- --------------------------- --------------------------- --------------------------- --------------------------- BBAAAAAAAAAAC-------------- BBAAAAAAAAAAH-------------- BBAAAAAAAAAAC-------------- BBAAAAAAAAAA--------------- BBAAAAAAAAAA--------------- BBAAAAAAAAAAI-------------- BBAAAAAAAAAA--------------- BBAAAAAAAAAA--------------- BBAAAAAAAAAA--------------- BBAAAAAAAAAA--------------- BBAAAAAADDDD--------------- BB------------------------- BBBBBBB-------------------- BBBBBBB-------------------- 
--------------------------- --------------------------- --------------------------- --------------------------- --------------------------- --------------------------- --------------------------- --------------------------- --------------------------- --------------------------- --------------------------- --------------------------- --------------------------- --------------------------- --------------------------- --------------------------- BBAAAAAAAAAAC-------------- BBAAAAAAAAAAC-------------- BBAAAAAAAAAAC-------------- BBAAAAAAAAAAC-------------- BBAAAAAAAAAAI-------------- BBAAAAAAAAAAI-------------- BBAAAAAAAAAA--------------- BBAAAAAAAAAA--------------- BBAAAAAAAAAA--------------- BBAAAAAAAAAA--------------- BBAAAAAAAAAA--------------- BB------------------------- BBBBBBB-------------------- BBBBBBB-------------------- 
--------------------------- --------------------------- --------------------------- --------------------------- --------------------------- --------------------------- --------------------------- --------------------------- --------------------------- --------------------------- --------------------------- --------------------------- --------------------------- --------------------------- --------------------------- --------------------------- BBAAAAAAAAAAC-------------- BBAAAAAAAAAAH-------------- BBAAAAAAAAAAC-------------- BBAAAAAAAAAA--------------- BBAAAAAAAAAA--------------- BBAAAAAAAAAAI-------------- BBAAAAAAAAAA--------------- BBAAAAAAAAAA--------------- BBAAAAAAAAAA--------------- BBAAAAAAAAAA--------------- BBAAAAAADDDD--------------- BB------------------------- BBBBBBB-------------------- BBBBBBB-------------------- 
--------------------------- --------------------------- --------------------------- --------------------------- --------------------------- --------------------------- --------------------------- --------------------------- --------------------------- --------------------------- --------------------------- --------------------------- --------------------------- --------------------------- --------------------------- --------------------------- --AAAAAAAAAA--------------- --AAAAAAAAAAH-------------- --AAAAAAAAAAC-------------- --AAAAAAAAAA--------------- --AAAAAAAAAA--------------- --AAAAAAAAAA--------------- --AAAAAAAAAA--------------- --AAAAAAAAAA--------------- --AAAAAAAAAA--------------- --AAAAAAAAAA--------------- --AAAAAAAAAA--------------- --------------------------- --------------------------- --------------------------- 
--------------------------- --------------------------- --------------------------- --------------------------- --------------------------- --------------------------- --------------------------- --------------------------- --------------------------- --------------------------- --------------------------- --------------------------- --------------------------- --------------------------- --BBB----BBB--------------- --AAA----AAA--------------- --AAAAAAAAAA--------------- --AAAAAAAAAAC-------------- --AAAAAAAAAAC-------------- --AAAAAAAAAA--------------- --AAAAAAAAAA--------------- --AAAAAAAAAA--------------- --AAAAAAAAAF--------------- --AAAAAAAAAF--------------- --AAAAAAAAAF--------------- --AAAAAAAAAE--------------- --AAAAAAAAAA--------------- --------AAAG--------------- --------AAAA--------------- --------AAAA--------------- 
--------------------------- --------------------------- --------------------------- --------------------------- --------------------------- --------------------------- --------------------------- --------------------------- --------------------------- --------------------------- --------------------------- --------------------------- --------------------------- --------------------------- --BBB----BBB--------------- --AAA----AAA--------------- --AAAAAAAAAA--------------- --AAAAAAAAAA--------------- --AAAAAAAAAAH-------------- --AAAAAAAAAAC-------------- --AAAAAAAAAA--------------- --AAAAAAAAAA--------------- --AAAAAAAAAC--------------- --AAAAAAAAAC--------------- --AAAAAAAAAC--------------- --AAAAAAAAAE--------------- --ADADAAAAAA--------------- --------AAAA--------------- --------AAAG--------------- --------AAAA--------------- 
--------------------------- --------------------------- --------------------------- --------------------------- --------------------------- --------------------------- --------------------------- --------------------------- --------------------------- --------------------------- --------------------------- --------------------------- --------------------------- --------------------------- --BBB----BBB--------------- --AAA----AAA--------------- --AAAAAAAAAA--------------- --AAAAAAAAAA--------------- --AAAAAAAAAAC-------------- --AAAAAAAAAAC-------------- --AAAAAAAAAA--------------- --AAAAAAAAAA--------------- --AAAAAAAAAF--------------- --AAAAAAAAAF--------------- --AAAAAAAAAF--------------- --AAAAAAAAAE--------------- --ADADAAAAAA--------------- --------AAAA--------------- --------AAAG--------------- --------AAAA--------------- 
--------------------------- --------------------------- --------------------------- --------------------------- --------------------------- --------------------------- --------------------------- --------------------------- --------------------------- --------------------------- --------------------------- --------------------------- --------------------------- --------------------------- --BBB----BBB--------------- --AAA----AAA--------------- --AAAAAAAAAA--------------- --AAAAAAAAAA--------------- --AAAAAAAAAA--------------- --AAAAAAAAAAH-------------- --AAAAAAAAAAC-------------- --AAAAAAAAAA--------------- --AAAAAAAAAE--------------- --AAAAAAACCE--------------- --AAAAAAAAAE--------------- --AAAAAAAAAE--------------- --ADADAAAAAA--------------- --------AAAG--------------- --------AAAA--------------- --------AAAA--------------- 
--------------------------- --------------------------- --------------------------- --------------------------- --------------------------- --------------------------- --------------------------- --------------------------- --------------------------- --------------------------- --------------------------- --------------------------- --------------------------- --------------------------- --BBB----BBB--------------- --AAA----AAA--------------- --AAAAAAAAAA--------------- --AAAAAAAAAA--------------- --AAAAAAAAAA--------------- --AAAAAAAAAA--------------- --AAAAAAAAAAC-------------- --AAAAAAAAAAC-------------- --AAAAAAAAAA--------------- --AAAAAAAAAA--------------- --AAAAAAAAAA--------------- --AAAAAAAAAA--------------- --ADADAAAAAA--------------- --------AAAA--------------- --------AAAA--------------- --------AAAA--------------- 
--------------------------- --------------------------- --------------------------- --------------------------- --------------------------- --------------------------- --------------------------- --------------------------- --------------------------- --------------------------- --------------------------- --------------------------- --------------------------- --------------------------- --------------------------- --------------------------- --------------------------- --------------------------- --------------------------- -----------B--------------- --------------------------- -----------B--------------- --------------------------- --------------------------- --------------------------- --------------------------- --------------------------- --------------------------- --------------------------- --------------------------- 
--------------------------- --------------------------- --------------------------- --------------------------- --------------------------- --------------------------- --------------------------- --------------------------- --------------------------- --------------------------- --------------------------- --------------------------- --------------------------- --------------------------- --------------------------- --------------------------- --------------------------- --------------------------- --------------------------- -----------B--------------- --------------------------- -----------B--------------- --------------------------- --------------------------- --------------------------- --------------------------- --------------------------- --------------------------- --------------------------- --------------------------- 
