model
size = 32 30 14, scale = 0.05, origin = -y
material 
  colors = A:#D44C5C B:#A05CDC C:#A460DC D:#000 E:#A058DC F:#9050C8 G:#9854D4 H:#9450CC I:#9C58D8 J:#A464DC K:#9854D0 L:#A868E0 M:#A864DC N:#9454D0 O:#9C54D8 P:#9C58DC Q:#9C54D4 R:#9454CC
voxels
8-3D10-3D19-3D4-3D25-D2-D21-8D2-8D21-D2-D25-3D4-3D19-3D10-3D9131-D2-D18-3D7-D2-D18-D2-D6-D-D19-D2-D6-2D20-3D7-D-D19-D2-D6-D2-D18-3D616-CFH18-HFC7-HNL2I16-2ILNH6-EGAJB16-BJAGE5-BE2A2CB14-B2C2AEB4-G4AGEGL10-LGEG4AG3-C6AKHIF8-FIHK6AC2-G8AHENH4-HNEH8AG-HE10AHEG2-GEH10AEHKB10ABF4-FB10ABKF10ABF6-FB10AFL8AKIF8-FIK8ALEFO5ABLF10-FLB5AOFEBJ2F2ECNC14-CNC2E2FJB518-IF16-FI10-HCBC16-CBCH7-G-BJMH14-HMJB-G6-KFK-IFI12-IFI-KFK5-E2CFG-BCH10-HCB-GF2CE4-EBJICH-ECK8-KCE-HCIJBE3-PBNJMGBCB2FEI4HIE2FBCBGMJNBP2-FGJ2B2GBEB-IC4BCI-BEB2G2BJGF-BCEPBPIFKCLG2(2-O)2-GLCKFIPBPECBCGFMBMJB2JBQ-E4-E-QB2JBJMBMFGCMNPBEHCMECI-N6-N-ICEMCHEBPNM2BEHQB2E2C-C8-C-2C2EBQHE2BLQB2HMPF-CL10-LC-FPM2HBQLCFHE2CQLE14-ELQ2CEHFC550-BE16-EB10-JH-H16-H-HJ7-GFBE-K14-K-EBFG6-CGEGH-C12-C-HGEGC5-BCJNKCK-J10-J-KCKNJCB4-KOICKGJCOCB6-BCOCJGKCIOK3-BCGIJEBF-2C-H4-H-2C-FBEJIGCB2-JFHJ2CB2J-MJC4-CJM-2JB2CJHFJ-FMICLFKIME-OG6-GO-EMIKFLCIMFRBCBJF2IB2GIB6-BI2GB2IFJBCBRJBIRGF2BCPH10-HPC2BFGRIBJBFICE2L2HB12-B2H2LECIFB3-OGH20-HGO648-O20-O9-LFB18-BFL7-BIBMG16-GMBIB6-BCEBJCH12-HCJBECB5-FECGKHE2K10-2KEHKGCEF4-EKLBGLBEF10-FEBLGBLKE4-BGOGERGJ12-JGREGOGB4-IGINCG16-GCNIGI66-
