model
size = 31 12 32, scale = 0.05, origin = -y
material 
  colors = A:#070 B:#390 C:#100 D:#F00 E:#005 F:#CF0 G:#010
voxels
199-6A2(25-6B)181-6A24-7A24-6A30-2A23-4A-3A23-A6B25-6B26-3B88-2(7A24-)2(9A22-)8A2(22-9A)22-A7B24-7B25-5B86-8A22-9A22-11A21-10A20-11A20-10A22-10A2(21-3B3C4B)23-B3-B84-5A26-5A2(2-3A22-4A)3-4A20-4A-6A20-11A21-10A2(21-10B)22-8B82-3A7-2A19-3A6-3A19-4A5-2A20-4A6-2A20-3A3-5A2(20-3A-7A)2(21-10B)22-8B81-3A8-3A17-3A7-4A17-4A6-3A19-4A6-2A19-4A4-4A19-4A-2A-4A20-3A-8A19-11BA19-11B22-8B81-2A10-2A17-2(3A7-5A16-)3A8-3A17-4A5-5A17-5A4-5A19-3A-2A-5A19-12B19-11B21-9B79-2A12-3A15-2A10-5A14-3A9-5A15-2A9-4A16-3A7-5A16-5A4-6A17-4A4-5A18-5BCBC6B17-5BCBC6B18-4B-B-5B76-2A14-3A13-2A12-2(5A12-3A11-)4A13-4A8-6A13-6A6-5A16-4A6-5A2(16-6BCBC6B)A16-5B2(-B)3C2B74-2A16-2A12-2A13-5A11-3A12-5A11-3A13-4A11-4A10-2(5A12-6A8-)5A13-A2(4B3C)2B15-4B3C4B5CB15-2B3C-4B4C2B72-3A17-2A9-2(4A14-5A8-)4A15-3A9-5A12-5A9-7A9-5A-2A2(9-5A)-2A9-A4B4C3B5C3B2A10-4B4C3B6C2B2A11-2B6C2BC2E3C2B23-4C43-3A18-3A3(7-4A16-4A)7-4A15-5A7-6A12-5A10-6A10-9A6-4B6C3B6C4B2A6-4B6C3B6C4B10-2B7C2BC3E2C-B23-5C41-3A20-2A6-4A18-3A6-4A18-4A6-3A17-5A6-3A16-5A7-6A13-5A8-5A14-7A2(5-4B7C3B7C5B)7-2B3C2E3C2BC3E3C3B13-4C4-2CE2C28-2C11-2A21-3A5-2A20-4A4-4A19-4A5-3A18-5A5-3A18-2(6A4-5A16-)8A4-4B7C3B7C5BA4-4B7C3B7C5B6-3B2C4E2C2BC4E2C3B12-2CE2C4-2CE3C18-2C7-2C35-2A2(4-3A21-3A)4-3A20-4A5-3A19-2(5A4-4A18-)7A2(3-5B7C3B7C6B)5-3B2C2E4C2BC4E2C4B11-C2EC6-C2E2C17-3C7-3C33-2(4A3-2A22-)3A4-3A21-4A4-2A21-4A4-3A20-4A4-4A19-6A2-A4B8C3B8C5B3-4B8C3B8C5B4-3B2C3E4C2B2C3E2C-3B10-2C2EC6-C2E2C17-3C7-3C33-4A3-2A22-4A3-2A23-3A3-2A22-4A3-3A21-4A3-4A21-3A4-3A22-4A2-A4B8C4B7C5B3-4B8C4B7C5BA3-3B2C2E5C3BC3E3C4B9-C2E2C6-2C2EC16-3C9-3C33-3(3A3-2A23-)2(3A3-3A22-)3A3-3A23-5A-A2(3B9C4B7C5BA2-)3B2C3E4C4BC3E3C4B8-2C2EC7-5C16-3C9-3C8-2(2A23-3A3-)2A24-2A3-2A23-2(3A3-3A22-)5A-3A22-5A2-4B9C4B8C5B-4B9C4B8C5B2-3BC4E3C-4B2C2E3C-3B8-C3EC7-5C15-3C21-2(2A23-3A3-)2(2A23-4A2-)2A23-5A2(-3A21-6A)2-4B8C6B7C5B-4B8C6B7C5B2-3B2C2E4C6BCE5C3B8-5C8-4C15-3C21-2(3A28-)2(3A22-4A2-)2(4A19-7A-)4A19-7A2-4B7C8B6C5B-4B7C8B6C5B2-3B3CE3C8B6C3B9-3C53-2A28-3A28-2(4A22-3A2-)2(4A18-8A-)4A18-9A-4B6C2B6D2B4C6B-4B6C2B6D2B4C5B4-2B6C-9B4C4B65-2A28-4A27-4A28-3A22-3A3-4A17-3A-3A2-5A17-8A-5A17-8A2-5B4C3B6D2BG3C6B-5B4C3B6D2BG3C4B5-3B3C-4B3D4B4C3B66-2A29-2(3A28-)4A20-3A4-4A17-2A-4A3-2(4A17-8A2-)A10B8D10B3-10B8D9B5-10B5D9B69-2A28-3A2(27-4A)19-4A4-5A18-4A4-5A16-8A2-8A13-8A2-A9B9D10B3-9B9D10B5-8B3DF3D8B69-2A28-2(6A13-3A9-)5A14-6A6-4A15-6A6-4A16-7A4-9A11-8A3-9B9D10B3-9B9D8B9-6B2D3F2D7B70-2A29-5A13-3A10-7A5-9A10-7A-13A9-6A3-5A-10A6-6A3-2A4-11A5-11A6-10A4-10B8D9B4-10B8D8B10-5B3DF3D6B103-4A13-3A10-8A2-11A10-21A9-24A7-26A6-10A-2A-12A2(5-9B8D9B)10-5B5D6B138-4A2-6A18-13A-3A10-22A9-25A7-25A2(6-10B6D9B)12-5B3D6B173-4A6-2A12-13A-7A2(10-22A)2(10-21B)15-12B216-3A22-2A4-3A13-18A13-A17B14-17B2A20-4B74-
