model
size = 31 32 12, scale = 0.05, origin = -y
material 
  colors = A:#FFC B:#100 C:#F00 D:#005 E:#F33 F:#CF0 G:#010
voxels
422-2B20-2B7-2B19-3B7-3B18-3B7-3B17-3B9-3B16-3B9-3B15-3B28-3B720-4B27-5B18-4B4-2BD2B17-2BD2B4-2BD3B16-B2DB6-B2D2B15-2B2DB6-B2D2B15-B2D2B6-2B2DB14-2B2DB7-5B14-B3DB7-5B14-5B8-4B15-3B129-E29-E-E29-E184-3A27-5A26-A3-A25-2(8A23-)8A22-9A21-4A-A-5A18-5A2(-A)3B2A16-2A3B-4A4B2A14-2A6B2AB2D3B2A12-2A7B2AB3D2B-A11-2A3B2D3B2AB3D3B3A8-3A2B4D2B2AB4D2B3A8-3A2B2D4B2AB4D2B4A6-3A2B3D4B2A2B3D2B-3A6-3A2B2D5B3AB3D3B4A4-3A2B3D4B4AB3D3B4A4-3AB4D3B-4A2B2D3B-3A4-3A2B2D4B6ABD5B3A4-3A3BD3B8A6B3A5-2A6B-9A5B3A5-2A4B-11A4B3A6-24A8-11AF11A9-9AFEF9A11-9AF9A13-17A15-15A18-12A24-4A2(25-6A)24-7A23-3A3B4A2(21-10A)2(20-11A)19-5ABAB6A16-6ABAB7A14-4A3B4A5BA13-4A4B3A6B4A8-4A6B3A6B4A7-4A7B3A7B5A5-4A7B3A7B5A4-5A7B3A7B6A3-4A8B3A8B5A3-4A8B4A7B5A3-3A9B4A7B5A2-4A9B4A8B4A2-4A8B6A7B4A2-4A7B8A6B4A2-4A6B2A6C2A4B5A2-5A4B3A6C2AG3B4A4-10A8C9A4-9A9C10A3-9A9C8A5-10A8C8A6-9A8C9A5-10A6C9A8-21A12-19A18-6A24-7A23-8A23-3A3B4A2(21-10A)20-12A19-12A18-5ABAB6A16-6ABAB6A14-5A3B4A3B2A13-5A4B3A5B5A8-4A6B3A6B6A5-4A7B3A7B5A5-4A7B3A7B6A3-5A7B3A7B7A-5A8B3A8B6A-5A8B2(4A7B6A-4A9B)4A8B5A-4A8B6A7B5A-4A7B8A6B5A-4A6B2A6C2A4B6A-5A4B3A6C2AG3B6A-11A8C10A2-10A9C10A3-9A9C10A3-10A8C9A5-9A8C9A5-10A6C9A8-21A11-18A20-6A24-4A-3A22-9A22-10A21-10A20-11A20-12A19-3A-2A-5A18-4A4-5A17-4A6-5A13-6A8-5A12-5A9-5A-2A8-6A10-10A4-5A14-8A2-5A16-9A-4A18-8A-5A18-7A-4A2(21-10A)20-5A-5A19-6A-5A18-7A-6A16-16A15-8A2-7A14-8A2-8A13-8A3-28A3-12A-14A5-10A-2A-12A5-25A7-22A11-18A56-2A22-9A21-10A21-11A20-3A-7A19-4A-2A-4A18-5A4-5A17-5A4-6A14-6A6-5A13-6A8-5A10-7A9-5A-2A6-6A12-6A-3A3-6A13-9A2-5A16-8A2-5A17-7A2-4A19-6A-5A20-2(5A-4A21-)5A-4A20-6A-5A18-7A-5A17-8A-6A16-8A2-4A17-8A2-5A16-8A3-4A3-2A-A9-7A4-6A3-2A4-12A4-27A4-25A7-22A21-2A4-3A51-6A24-8A21-11A20-4A-6A20-3A3-5A19-4A4-4A18-4A5-5A17-3A7-5A14-4A8-6A12-4A2(10-5A)12-5A-A6-4A15-8A4-3A16-9A2-3A18-8A2-3A19-7A2-3A20-6A-5A19-6A3(-5A20-5A)-5A18-7A-4A18-2(8A2-4A17-)8A2-5A18-5A4-4A7-2A5-7A-A4-6A3-5A-10A6-24A7-22A10-13A-7A28-3A51-7A23-9A21-10A20-4A3-4A2(19-4A6-2A)18-3A8-3A17-2A9-4A14-3A11-4A12-3A13-4A9-4A15-3A2-2A4-4A16-7A4-3A17-7A3-3A18-7A2-3A20-7A-5A19-6A-4A20-6A3(-4A21-5A)-3A21-6A-4A20-6A2-3A20-6A2-4A20-3A4-4A19-4A5-5A14-6A7-7A-15A8-21A13-13A-3A18-4A6-2A85-6A23-9A20-11A20-4A2-3A21-4A5-2A19-4A6-3A18-3A7-5A15-3A9-5A13-3A11-5A11-3A12-9A5-4A14-8A4-4A16-7A3-4A18-6A2-4A19-6A2-3A21-6A-3A-A19-11A2(21-10A)22-4A-4A21-5A-3A22-2(5A-4A21-)4A3-3A21-3A4-4A19-4A5-6A13-7A6-7A5-11A8-8A2-12A13-4A2-6A148-7A22-9A21-5A2-3A21-3A6-3A18-3A7-4A17-3A7-5A15-2A10-5A13-2A12-5A-A9-2A13-8A6-4A14-8A4-4A16-8A2-4A18-7A2-3A19-7A-4A20-2(6A-3A21-)6A4(-3A22-5A)-3A22-A-2A2-4A21-4A3-3A21-3A5-3A19-4A5-6A13-3A-2A7-5A13-5A9-4A13-4A173-7A23-8A21-5A26-3A7-2A18-3A8-3A17-2A10-2A15-2A12-3A13-2A14-5A9-2A16-6A6-3A17-5A5-3A18-6A3-3A20-6A2-2A21-6A-3A22-5A-3A21-6A-A23-6A3(-2A23-5A)-3A24-3A2-2(2A24-2A3-)2A24-A6-2A22-A6-2A20-2A7-2A20-A129-
