model
size = 12 14 32, scale = 0.05, origin = -y
material 
  colors = A:#C7E3F4 B:#1C6DA9 C:#12497D D:#092452 E:#141416 F:#323232 G:#3C3C3C H:#2EB6FF I:#2592D4 J:#000027 K:#021757 L:#FFE7A7 M:#143F77 N:#D7387F O:#BB1313 P:#379D30 Q:#D97708 R:#124BC6 S:#141414 T:#8D1204
voxels
4-4E8-4E151-2EGF2E6-E4LE7-4D139-E2(GF)E6-J4LJ6-6D137-2E2(FG)2E4-J6AJ4-D6-D5-6C124-2E6N2E2-JL6ALJ3-D6-D4-8C123-EFGFNFGNGE2-JL6ALJ3-D6-D2(4-2C)6-4B112-2EGFGNGFNF2EJL8ALJ-D8-D3-C6-C5-6B111-E2(GF)4NGFEJL8ALJ-D8-D3-C6-C4-B6MB110-E5(FG)EJL8ALJ-D8-D3-C6-C4-M6AM6-4A100-EGF6RGFEJL8ALJ-D8-D2-C8-C3-M6-M5-6A99-E5(FG)EJ10AJD10-D-C8-C3-B6-B4-S6OS98-E2(GF2P)GFEJ10AJD10-D-C8-C2-B8-B3-I6-I4-M6AM86-E2(FG)2P2(FG)EJ10AJD10-D-C8-C2-B8-B3-I6-I4-S6QS86-E2(GF)2P2(GF)EJ10AJD10-D-C8-C2-B8-B3-I6-I4-H6-H4-M6AM74-2E2(G2PF)2EJL8ALJ-D8-D2-C8-C2-B8-B3-I6-I4-H6-H4-S6PS75-E4(FG)E2-J8AJ2-D8-D2-C8-C2-B8-B2-I8-I3-2(H6-H4-)M6AM63-EG6QFE2-J8AJ2-D8-D2-C8-C2-B8-B2-I8-I3-2(H6-H4-)S6RS63-EFQ3(FG)E2-J8AJ2-D8-D2-C8-C2-B8-B2-I8-I3-3(H6-H4-)M6AM51-EGQ3(GF)E2-J8AJ2-D8-D2-C8-C2-B8-B2(2-I8-I)3-3(H6-H4-)S6NS39-E4(FG)E2-J3A3B2AJ2-D8-D2-C8-C2-B8-B3(2-I8-I)3-3(H6-H4-)M6AM27-E4(GF)E2-J3A3B2AJ2-D8-D2-C8-C2(2-B8-B)3(2-I8-I)2(2-H8-H)3-2M4A2M5-M4AM6-M4AM3-2E4(FG)2EJL3A2B3ALJ2D8-2D2C8-2C-3(B8-B2-)3(I8-I2-)H8-H2-H8-H16-6K3-E5(FG)EJL3A2B3ALJ2D8-2D2C8-4C8-2C2B8-4B8-2B-B8-B2(2-I8-I)2(2-H8-H)25-EGF6OGFEJL3A2B3ALJ2D8-4D8-2D2C8-4C8-2C2B8-4B8-2B-2(I8-I2-)H8-H37-E2(FG)OGFOFGEJL3A2B3ALJ2D8-4D8-2D2C8-4C8-2C2B8-4B8-2B-I8-I2(2-H8-H)37-E2(GF)OFGOGFEJL3A2B3ALJ2D8-2D2C8-4C8-2C2B8-4B8-2B-B8-B2-I8-I2-H8-H49-E2(FG)4OFGEJL3A2B3ALJ2D8-2D2C8-4C8-2C-2(B8-B2-)2(I8-I2-)H8-H49-E5(GF)EJL2A4B2ALJ2D8-2D-C8-C2(2-B8-B)2(2-I8-I)2(2-H8-H)49-2E3(GF)TF2EJL8ALJ-D8-D2-C8-C2-B8-B2(2-I8-I)2(2-H8-H)62-2E6T2E2-JL6ALJ2-2D6-2D2-2C6-2C2-2B6-2B2-2I6-2I3(2-2H6-2H)63-2E2(GF)2E4-J6LJ4-DK6D4-8C4-8B4-8I3(4-H6KH)6-4K55-6E6-J4EJ6-2D2K2D6-2C2K2C6-2B2K2B6-2I2K2I7-3(4K8-)4K52-
