model
size = 12 14 32, scale = 0.05, origin = -y
material 
  colors = A:#F4D489 B:#F47C19 C:#D72E00 D:#141414 E:#9B1004 F:#323232 G:#3C3C3C H:#FFED2E I:#FFB31A J:#8D1204 K:#490000 L:#FFE7A7 M:#D87D38 N:#D7387F O:#BB1313 P:#379D30 Q:#D97708 R:#124BC6
voxels
4-4D8-4D151-2DGF2D6-D4LD7-4E139-D2(GF)D6-K4LK6-6E137-2D2(FG)2D4-K6AK4-E6-E5-6C124-2D6N2D2-KL6ALK3-E6-E4-8C123-DFGFNFGNGD2-KL6ALK3-E6-E2(4-2C)6-4B112-2DGFGNGFNF2DKL8ALK-E8-E3-C6-C5-6B111-D2(GF)4NGFDKL8ALK-E8-E3-C6-C4-B6MB110-D5(FG)DKL8ALK-E8-E3-C6-C4-M6AM6-4A100-DGF6RGFDKL8ALK-E8-E2-C8-C3-M6-M5-6A99-D5(FG)DK10AKE10-E-C8-C3-B6-B4-D6OD98-D2(GF2P)GFDK10AKE10-E-C8-C2-B8-B3-I6-I4-M6AM86-D2(FG)2P2(FG)DK10AKE10-E-C8-C2-B8-B3-I6-I4-D6QD86-D2(GF)2P2(GF)DK10AKE10-E-C8-C2-B8-B3-I6-I4-H6-H4-M6AM74-2D2(G2PF)2DKL8ALK-E8-E2-C8-C2-B8-B3-I6-I4-H6-H4-D6PD75-D4(FG)D2-K8AK2-E8-E2-C8-C2-B8-B2-I8-I3-2(H6-H4-)M6AM63-DG6QFD2-K8AK2-E8-E2-C8-C2-B8-B2-I8-I3-2(H6-H4-)D6RD63-DFQ3(FG)D2-K8AK2-E8-E2-C8-C2-B8-B2-I8-I3-3(H6-H4-)M6AM51-DGQ3(GF)D2-K8AK2-E8-E2-C8-C2-B8-B2(2-I8-I)3-3(H6-H4-)D6ND39-D4(FG)D2-K3A3B2AK2-E8-E2-C8-C2-B8-B3(2-I8-I)3-3(H6-H4-)M6AM27-D4(GF)D2-K3A3B2AK2-E8-E2-C8-C2(2-B8-B)3(2-I8-I)2(2-H8-H)3-2M4A2M5-M4AM6-M4AM3-2D4(FG)2DKL3A2B3ALK2E8-2E2C8-2C-3(B8-B2-)3(I8-I2-)H8-H2-H8-H16-6J3-D5(FG)DKL3A2B3ALK2E8-2E2C8-4C8-2C2B8-4B8-2B-B8-B2(2-I8-I)2(2-H8-H)25-DGF6OGFDKL3A2B3ALK2E8-4E8-2E2C8-4C8-2C2B8-4B8-2B-2(I8-I2-)H8-H37-D2(FG)OGFOFGDKL3A2B3ALK2E8-4E8-2E2C8-4C8-2C2B8-4B8-2B-I8-I2(2-H8-H)37-D2(GF)OFGOGFDKL3A2B3ALK2E8-2E2C8-4C8-2C2B8-4B8-2B-B8-B2-I8-I2-H8-H49-D2(FG)4OFGDKL3A2B3ALK2E8-2E2C8-4C8-2C-2(B8-B2-)2(I8-I2-)H8-H49-D5(GF)DKL2A4B2ALK2E8-2E-C8-C2(2-B8-B)2(2-I8-I)2(2-H8-H)49-2D3(GF)JF2DKL8ALK-E8-E2-C8-C2-B8-B2(2-I8-I)2(2-H8-H)62-2D6J2D2-KL6ALK2-2E6-2E2-2C6-2C2-2B6-2B2-2I6-2I3(2-2H6-2H)63-2D2(GF)2D4-K6LK4-EJ6E4-8C4-8B4-8I3(4-H6JH)6-4J55-6D6-K4DK6-2E2J2E6-2C2J2C6-2B2J2B6-2I2J2I7-3(4J8-)4J52-
