model
size = 4 32 32, scale = 0.05, origin = -y
material 
  colors = A:#0A0 B:#A1AA00 C:#990089 D:#900 E:#004A99 F:#A09 G:#090 H:#0B0 I:#919900 J:#B00 K:#005ABB L:#A00 M:#BB00A8 N:#0052AA O:#0C0 P:#C00 Q:#0062CC R:#CC00B7 S:#B1BB00 T:#C2CC00 U:#DD00C6 V:#006BDD W:#0D0 X:#0E0 Y:#D2DD00 Z:#D00 Aa:#E00 Ab:#E2EE00 Ac:#EE00D6 Ad:#0073EE Ae:#0F0 Af:#FF00E5 Ag:#007BFF Ah:#F00 Ai:#F2FF00
voxels
64-8D-2(2J2-)2J109-8D12L-2J3(2-2P)2(2-2Z)2-2Aa85-8D8L8J8P4Z8Aa-2Aa3(2-2Ah)69-8D8L12J8P4Z-2Z2(2-2Aa)81-8D8L8J-2(2P2-)2Z93-8D4L-2(2J2-)2P105-8D-2J117-8I-2B2-2B113-8I8B-2B109-8I12B-2S105-4I12B8S-2S2-2T93-8I12B4S12T-2Y89-8I-2B2-2B-4B4S8T8Y-2Ab81-8G-2A10-2(2S2-)2T2(2-2Y)-4Y4Ab-2Ab2-2Ai73-8G4A-2A26-3(2Ab2-)2Ai2-2Ai65-8G8A-2A49-8C44-12G12A4H-2H45-16C28-8E8G12A8H-2H46-2F-4F20C24E-2G-12A12H4O-2O42-2F-12F12C16E4N-2N6-2A2-2A-12H12O-2W38-2M-20F-2F2-2E-16N-2K14-2H2-2H-12O4W-2W42-2M-8M4F-2F6-2N-12N8K-2K18-2O-4O8W4X-2X38-2M-12M-2M10-2K-16K-2Q22-2W2-2W-8X-2X38-2R-4R8M-2M14-2K-8K4Q-2Q30-2X2-2X-4Ae-2Ae34-2R-8R-2R22-2Q-8Q-2Q38-2Ae2-2Ae34-2U-4U4R-2R22-2Q-4Q4V-2V78-2U-8U-2U26-2V-8V-2V74-2Ac-4Ac-2U34-2V-4Ad-2Ad78-2Ac2-2Ac38-2Ad2-2Ad78-2Af2-2Ac38-2Ag2-2Ag78-2Af46-2Ag78-2Af117-
