model
size = 31 32 17, scale = 0.05, origin = -y
material 
  colors = A:#000 B:#353535 C:#0D0D0D D:#1A1A1A E:#282828 F:#434343 G:#505050 H:#5E5E5E I:#F8F8F8 J:#E00
voxels
9-2(13A18-)2(13C18-)2(13D18-)2(13E18-)5B3E5B18-BE3B3IE4B18-FJEFIB2FIE3F18-2FJ2IB2F2IE2F18-3GJIB2G2IB2G18-3GIJB2G2IB2G18-3H2IJBH2IB2H18-3H2IBJB2IB2H18-3G2IBGJ2IB2G18-3G2IB2GJIB2G18-3F2IB2FIJB2F18-4FI3BIBJBF18-5B3I3BJB17-15B15-17E14-17E15-7D-7D17-5D3-5D202-2(2A13-2A14-)2(2C13-2C14-)2(2D13-2D14-)2(2E13-2E14-)2(2B13-2B14-)2(2F13-2F14-)2G13-2G14-3G11-3G14-3H11-3H15-2H11-2H2(16-GA11-2G)2(16-FA11-2F)14-3BA11-A3B11-4B13-A3B2(10-2EA15-3E)11-2D15-2(2D13-)2D15-6C3-6C16-5C5-5C138-2(A17-A12-)2(C17-C12-)2(D17-D12-)2(E17-E12-)B17-B12-2B15-2B12-2F15-AF12-2F15-2F12-2G15-2G13-G15-G14-H15-H14-2H13-AH2(14-2G13-2G)14-FA13-2F15-F13-F11-3B2-B13-A2-3B6-3B19-3B2(6-3E19-3E)7-2D19-2D8-4D15-A3D9-3C15-3C12-2(C15-)5A5-5A106-2(A19-A10-)A19-C10-C19-C2(10-D19-D)2(10-E19-E)10-B19-B11-B17-B2(12-F17-F)2(12-G17-G)12-H17-H13-H15-H2(14-G15-G)2(14-F15-F)9-B4-B15-A2(4-B)25-B4-E25-E4-2E23-AE4-3D21-A2D5-3D19-2AD6-4C17-4C7-4C15-4C10-2A15-2A14-4A7-4A75-2(A19-A10-)A19-C10-C19-C2(10-D19-D)2(10-E19-E)10-B19-B10-2B17-2B2(10-FA17-2F)11-2(G17-G12-)H17-H12-2H15-2H12-2G15-2G13-G15-G2(14-F15-F)8-B5-B15-A5-B2-B27-B2-E27-E2-EA25-2E3-DA23-AD4-D2A21-2AD4-4C19-2A2C5-4C17-3AC7-4A15-4A11-2A13-2A16-3A7-3A45-2(A19-A10-)A19-C10-C19-C2(10-D19-D)2(10-E19-E)2(10-B19-B)2(10-F19-F)2(10-G19-G)10-H19-H11-H17-H2(12-G17-G)12-F17-F13-F15-F8-B5-B15-A5-B2-B27-B2(2-E27-E)2-2D25-2D2-2DA23-A2D3-3C21-A2C4-4C19-2A2C5-4A17-4A8-3A15-3A2(13-A)17-2A9-2A14-2(A19-A10-)A19-C10-C19-C2(10-D19-D)2(10-E19-E)2(10-B19-B)2(10-F19-F)2(10-G19-G)10-H19-H10-2H17-2H10-2G17-2G11-G17-G12-F17-F12-FA15-AF2(6-B)15-A6-2B28-2BE28-3E28-2E-D26-2D2-2D25-2D2-2CA23-3C3-C2A21-A2C5-3A19-3A7-4A15-4A11-2(A15-)2(A13-)2(A19-A10-)A19-C10-C19-C2(10-D19-D)2(10-E19-E)2(10-B19-B)2(10-F19-F)2(10-G19-G)10-H19-H10-2H17-2H2(10-2G17-2G)11-F17-F12-FA15-AF6-B5-2B15-2A5-2B28-2BE28-A2E28-AED28-2D-D26-CD2-2C25-2C3-CA23-2C4-3A21-3A6-2A19-2A10-2A15-2A14-2(A13-)2(A19-A10-)A19-C10-C19-C2(10-D19-D)2(10-E19-E)2(10-B19-B)2(10-F19-F)2(10-G19-G)10-H19-H10-2H17-2H2(10-2G17-2G)10-2F17-2F10-2FA15-A2F5-B5-2B15-2A5-2B28-2BE28-A2E28-AED28-3D28-2D-C26-2C2-2C25-2C3-2A23-2A5-3A19-3A9-2A15-2A14-2(A13-)2(A19-A10-)A19-C10-C19-C2(10-D19-D)2(10-E19-E)2(10-B19-B)2(10-F19-F)2(10-G19-G)10-H19-H10-2H17-2H2(10-2G17-2G)11-F17-F12-FA15-AF6-B5-2B15-2A5-2B28-2BE28-A2E28-AED28-3D28-2D-C26-2C2-2C25-2C3-2A23-2A5-3A19-3A9-2A15-2A14-2(A13-)2(A19-A10-)A19-C10-C19-C2(10-D19-D)2(10-E19-E)2(10-B19-B)2(10-F19-F)2(10-G19-G)10-H19-H10-2H17-2H10-2G17-2G11-G17-G12-F17-F12-2F15-AF2(6-B)15-A6-2B28-2BE28-A2E28-AED28-2D-D26-CD2-2C25-2C3-CA23-AC4-3A21-3A6-2A19-2A10-2A15-2A14-2(A13-)2(A19-A10-)A19-C10-C19-C2(10-D19-D)2(10-E19-E)2(10-B19-B)2(10-F19-F)2(10-G19-G)10-H19-H11-H17-H2(12-G17-G)12-F17-F13-F15-F7-B6-B15-A6-2B28-2BE28-A2E28-AE-D26-2D2-2D25-2D2-3C23-A2C3-3C21-2AC5-4A17-4A7-4A15-4A11-2A14-A16-A12-A13-2(A19-A10-)A19-C10-C19-C2(10-D19-D)2(10-E19-E)10-B19-B10-2B17-2B2(10-2F17-2F)11-2(G17-G12-)H17-H13-H15-H2(14-G15-G)2(14-F15-F)8-B5-B15-A5-B2-B27-B2-E27-E2-E26-AE2-2D25-2D2-2DA23-A2D3-3C21-2AC4-4C19-3AC5-4A17-4A8-3A15-3A2(13-A)17-A11-A14-2(A19-A10-)A19-C10-C19-C2(10-D19-D)2(10-E19-E)10-B19-B11-B17-B2(12-F17-F)2(12-G17-G)12-H17-H13-H15-H2(14-G15-G)2(14-F15-F)8-B5-B15-B5-B2-B27-B2-E27-E2-2E25-AE3-DA23-AD4-D2A21-2AD4-4C19-A3C5-4C17-2A2C7-4A15-4A11-2(A15-)A13-A17-2A9-2A15-2(A17-A12-)2(C17-C12-)2(D17-D12-)2(E17-E12-)B17-B12-2B15-AB2(12-2F15-2F)12-2G15-2G13-G15-G2(14-H15-H)2(14-G15-G)14-2(F15-)F13-F10-B5-B13-B5-2(B4-)2A13-2A4-B4-E25-E4-2E23-2E4-3D21-3D5-3D19-3D6-4C17-4C7-3CA16-3C10-2A15-2A14-2A11-2A17-2A9-2A20-A7-A18-2(A15-A14-)C15-C14-17C2(14-17D)2(14-17E)2(14-17B)2(14-3FA13F)14-G13A3G14-2G12A3G14-17H15-15H2(16-15G)2(16-15F)11-4B-B12A2B-4B6-6B12A7B2(6-4E18A3E)7-3D17A3D8-3D17A3D9-21C12-17C15-15A17-13A19-11A22-7A20-2(15A16-)2(15C16-)2(15D16-)2(15E16-)2(15B16-)2(15F16-)15G17-13G2(18-13H)2(18-13G)2(18-13F)18-13B17-15B14-2(19E12-)19D13-17D15-15C16-15C18-11A20-11A21-9A42-
