model
size = 24 32 26, scale = 0.05, origin = -y
material 
  colors = A:#CFC B:#383838 C:#A5CFA5 D:#399 E:#FF0 F:#1C5639 G:#39C H:#222 I:#0F3 J:#C00
voxels
319-5A18-A5DA16-A2D3G2DA14-A2D2GD2G2DA13-AD2G3D2GDA13-ADG5DGDA13-AD2G3D2GDA13-A2D2GD2G2DA14-A2D3G2DA16-A5DA18-5A213-6C17-7C16-C7A2(16-2(CA)3CA16-2(CA)C3A)16-2(CA)C3A16-2(3(CA)18-)C5A18-5CA18-6C18-5AC17-C5AC16-2C6AC14-4(3C7AC13-)3C7AC14-2C6AC16-C5AC18-5C213-9C15-9C5(13-C10A)13-7C4A156-C22-2C6AC14-4(3C7AC13-)3C7AC14-2C6AC16-C5AC18-5C213-2C5B3C14-2C5B3C12-C4A3B4A12-C11A12-2C8B2(2A12-CB8-)2A12-C9-2A155-C22-2C6AC14-4(3C7AC13-)3C7AC14-2C6AC16-C2(6A18-)6A188-9B2C13-9B2C11-CA9B2A11-C2A7B3A11-C3A7B2(2A11-C7A3-)2A11-8C3-2A11-8C5(16-7CA)16-A7C14-9A4(C13-10A)C13-9A4(2C14-8A)2C15-3A5C16-A7C17-6C114-A11B2C9-2A11B2C8-3A11B2A6-6A9B3A6-7A9B2A6-8A5BA2-2A6-14A2(2-2A6-11A2CA)2(10-13AC)10-18A6-3AC14A6-2A2C14A6-A2C15A6-AC16A6-18A6-3(12A2C10-)4(14A10-)14A11-2(12A12-)12A13-10A15-8A64-A13B2C8-A13B2C7-2A13B2A4-6A11B3A4-7A11B2A4-8A7BC2-2A4-9A5BAC2(2-2A4-16A)2(8-14A2C)8-19A5-4(17AF6-)19A5-2(15AC8-)5(16A8-)16A9-2(14A10-)14A11-12A13-10A15-8A39-2A13B3C7-A13B3C6-2A13B3A3-5A13B3A3-6A14BA3-7A9B4-A3-8A7BC2(4-A3-16A)2(8-14A2C)8-19A5-2(17AF6-)17AI6-17AF6-19A5-2(15AC8-)8(16A8-)16A9-14A11-12A13-10A15-8A16-15B2C6-A15B2C6-2A13B3A3-5A13B3A2-6A15BA2-7A11B3-A2-8A9BC3-A2-11A3B4A3-A2-18A2(6-15A3C)6-20A4-18AF5-18AI2(5-18AF)5-20A4-17AC7(6-18A)7-3(16A8-)16A9-14A11-12A13-10A15-15B2C5-2A15B2C4-3A15B2A3-5A13B3A2-6A15BA2-7A11B3-A2-8A9BC3-A2-10A5B3A3-A2-18A2(6-15A3C)6-20A4-18AF5-18AI2(5-18AF)5-20A4-17AC9(6-18A)7-2(16A8-)16A9-14A11-12A14-15B2AC4-2A15B3C3-3A15B3A2-5A13B4A-6A15B10A11BC2-11A9B2C2-13A5B4A2-22A2(4-16A4C)4-21A3-2(19AF4-)19AI4-19AF4-21A3-2(20A4-)19AE2(4-18A2E)4-19AE2(4-20A)5-2(18A6-)18A7-16A8-16A9-14A11-12A14-15B2AC4-2A15B3C3-3A15B3A2-5A13B4A-6A15B10A11BC2-2AH8A9B2C2-13A5B4A2-22A4-H15A4C4-16A4C4-21A3-4(19AF4-)21A3-20A4-19AE4-18A2E4-H16A2EJ4-17A3E4-18A2E4-H18AE4-20A5-2(18A6-)18A7-16A8-16A9-14A11-12A14-15B2AC4-2A15B3C3-4A13B4A2-5A13B4A-6A15B10A11BC2-2AH8A9B2C2-2AH11A3B5A2-2AH19A2(4-H15A4C)4-H20A3-4(H18AF4-)H20A3-H19A4-H17A2E4-H16A3E3(4-H16A2EJ)4-H17A2E4-20A5-2(18A6-)18A7-16A8-16A9-14A11-12A14-15B2AC4-2A15B3C3-4A13B4A2-5A13B4A-6A15B10A11BC2-11A9B2C2-14A3B5A2-22A2(4-16A4C)4-21A3-4(19AF4-)21A3-20A4-18A2E2(4-17A2EJ)4-17A3E4-17A2EJ4-18A2E4-20A5-2(18A6-)18A7-16A8-16A9-14A11-12A14-15B2AC4-2A15B3C3-3A15B3A2-5A13B4A-6A15B10A11BC2-2AH8A9B2C2-2AH10A5B4A2-2AH19A2(4-H15A4C)4-H20A3-4(H18AF4-)H20A3-H19A4-H18AE4-H17A2E4-H16A2EJ4-H16A3E4-H17A2E4-H18AE4-20A5-2(18A6-)18A7-16A8-16A9-14A11-12A14-15B2AC4-2A15B3C3-3A15B3A2-5A13B4A-6A15B10A11BC2-11A9B2C2-13A5B4A2-22A2(4-16A4C)4-21A3-2(19AF4-)19AI4-19AF4-21A3-2(20A4-)19AE2(4-18A2E)4-19AE2(4-20A)5-2(18A6-)18A7-16A8-16A9-14A11-12A14-15B2C5-2A15B2C4-3A15B2A3-5A13B3A2-6A15BA2-7A11B3-A2-8A9BC3-A2-10A5B3A3-A2-18A2(6-15A3C)6-20A4-18AF5-18AI2(5-18AF)5-20A4-17AC9(6-18A)7-2(16A8-)16A9-14A11-12A14-15B2C6-A15B2C6-2A13B3A3-5A13B3A2-6A15BA2-7A11B3-A2-8A9BC3-A2-11A3B4A3-A2-18A2(6-15A3C)6-20A4-18AF5-18AI2(5-18AF)5-20A4-17AC7(6-18A)7-3(16A8-)16A9-14A11-12A13-10A14-2A13B3C7-A13B3C6-2A13B3A3-5A13B3A3-6A14BA3-7A9B4-A3-8A7BC2(4-A3-16A)2(8-14A2C)8-19A5-2(17AF6-)17AI6-17AF6-19A5-2(15AC8-)8(16A8-)16A9-14A11-12A13-10A15-8A16-A13B2C8-A13B2C7-2A13B2A4-6A11B3A4-7A11B2A4-8A7BC2-2A4-9A5BAC2(2-2A4-16A)2(8-14A2C)8-19A5-4(17AF6-)19A5-2(15AC8-)5(16A8-)16A9-2(14A10-)14A11-12A13-10A15-8A41-A11B2C9-2A11B2C8-3A11B2A6-6A9B3A6-7A9B2A6-8A5BA2-2A6-14A2(2-2A6-11A2CA)2(10-13AC)10-18A6-3AC14A6-2A2C14A6-A2C15A6-AC16A6-18A6-3(12A2C10-)4(14A10-)14A11-2(12A12-)12A13-10A15-8A67-9B2C13-9B2C11-CA9B2A11-C2A7B3A11-C3A7B2(2A11-C7A3-)2A11-8C3-2A11-8C5(16-7CA)16-A7C14-9A4(C13-10A)C13-9A4(2C14-8A)2C15-3A5C16-A7C17-6C116-2C5B3C14-2C5B3C12-C4A3B4A12-C11A12-2C8B2(2A12-CB8-)2A12-C9-2A155-C22-2C6AC14-4(3C7AC13-)3C7AC14-2C6AC16-C2(6A18-)6A188-9C15-9C5(13-C10A)13-7C4A156-C22-2C6AC14-4(3C7AC13-)3C7AC14-2C6AC16-C5AC18-5C213-6C17-7C16-C7A2(16-2(CA)3CA16-2(CA)C3A)16-2(CA)C3A16-2(3(CA)18-)C5A18-5CA18-6C18-5AC17-C5AC16-2C6AC14-4(3C7AC13-)3C7AC14-2C6AC16-C5AC18-5C523-5A18-A5DA16-A2D3G2DA14-A2D2GD2G2DA13-AD2G3D2GDA13-ADG5DGDA13-AD2G3D2GDA13-A2D2GD2G2DA14-A2D3G2DA16-A5DA18-5A204-
