model
size = 31 31 9, scale = 0.05, origin = -y
material 
  colors = A:#09C B:#111 C:#FF3 D:#063
voxels
------------------------------- ------------------------------- ------------------------------- ------------------------------- ------------------------------- ------------------------------- ------------------------------- ------------------------------- ------------------------------- ------------------------------- ------------------------------- ------------------------------- ---------B-----------B--------- ---------BBBBBBBBBBBBB--------- ---------BAAAAAAAAAAAB--------- ---------BBBBBBBBBBBBB--------- ---------BAAAAAAAAAAAB--------- ---------BBBBBBBBBBBBB--------- ---------B-----------B--------- ------------------------------- ------------------------------- ------------------------------- ------------------------------- ------------------------------- ------------------------------- ------------------------------- ------------------------------- ------------------------------- ------------------------------- ------------------------------- ------------------------------- 
------------------------------- ------------------------------- ------------------------------- ------------------------------- ------------------------------- ------------------------------- ------------------------------- ------------------------------- ------------------------------- ------------------------------- ------------------------------- ------------------------------- ---------B-----------B--------- ---------A-----------A--------- ---------A-----------A--------- ---------A-----------A--------- ---------A-----------A--------- ---------A-----------A--------- ---------B-----------B--------- ------------------------------- ------------------------------- ------------------------------- ------------------------------- ------------------------------- ------------------------------- ------------------------------- ------------------------------- ------------------------------- ------------------------------- ------------------------------- ------------------------------- 
------------------------------- ------------------------------- ------------------------------- ------------------------------- ------------------------------- ------------------------------- ------------------------------- ------------------------------- ------------------------------- ------------------------------- ------------------------------- ------------------------------- ---------B-----------B--------- ---------A-----------A--------- ---------A-----------A--------- ---------A-----------A--------- ---------A-----------A--------- ---------A-----------A--------- ---------B-----------B--------- ------------------------------- ------------------------------- ------------------------------- ------------------------------- ------------------------------- ------------------------------- ------------------------------- ------------------------------- ------------------------------- ------------------------------- ------------------------------- ------------------------------- 
------------AAAAAAA------------ ---------AAA-------AAA--------- -------AA-------------AA------- ------A-----------------A------ -----A-------------------A----- ----A---------------------A---- ---A-----------------------A--- --A-------------------------A-- --A-------------------------A-- -A---------------------------A- -A---------------------------A- -A---------------------------A- A--------B-----------B--------A A--------A-----------A--------A A--------A-----------A--------A A--------A-----------A--------A A--------A-----------A--------A A--------A-----------A--------A A--------B-----------B--------A -A---------------------------A- -A---------------------------A- -A---------------------------A- --A-------------------------A-- --A-------------------------A-- ---A-----------------------A--- ----A---------------------A---- -----A-------------------A----- ------A-----------------A------ -------AA-------------AA------- ---------AAA-------AAA--------- ------------AAAAAAA------------ 
------------AAAAAAA------------ ---------AAAAAAAAAAAAA--------- -------AAAAA-------AAAAA------- ------AAA-------------AAA------ -----AAA---------------AAA----- ----AA-------------------AA---- ---AA---------------------AA--- --AAA---------------------AAA-- --AA-----------------------AA-- -AA-------------------------AA- -AA-------------------------AA- -AA-------------------------AA- AA-------B-----------B-------AA AA-------A-----------A-------AA AA-------A-----------A-------AA AA-------A-----------A-------AA AA-------A-----------A-------AA AA-------A-----------A-------AA AA-------B-----------B-------AA -AA-------------------------AA- -AA-------------------------AA- -AA-------------------------AA- --AA-----------------------AA-- --AAA---------------------AAA-- ---AA---------------------AA--- ----AA-------------------AA---- -----AAA---------------AAA----- ------AAA-------------AAA------ -------AAAAA-------AAAAA------- ---------AAAAAAAAAAAAA--------- ------------AAAAAAA------------ 
------------AAAAAAA------------ ---------AAAAAAAAAAAAA--------- -------AAAAAAAAAAAAAAAAA------- ------AAAAAAAAAAAAAAAAAAA------ -----AAAAAAAAAAAAAAAAAAAAA----- ----AAAAAAAAAAAAAAAAAAAAAAA---- ---AAAAAAAAAAAAAAAAAAAAAAAAA--- --AAAAAAAAAAAAAAAAAAAAAAAAAAA-- --AAAAAAAAAAAAAAAAAAAAAAAAAAA-- -AAAAAAAAAAAAAAAAAAAAAAAAAAAAA- -AAAAAAAAAAAAAAAAAAAAAAAAAAAAA- -AAAAAAAAAAAAAAAAAAAAAAAAAAAAA- AAAAAAAAAAAAAAAAAAAAAAAAAAAAAAA AAAAAAAAAAAAAAAAAAAAAAAAAAAAAAA AAAAAAAAAAAAAAAAAAAAAAAAAAAAAAA AAAAAAAAAAAAAAAAAAAAAAAAAAAAAAA AAAAAAAAAAAAAAAAAAAAAAAAAAAAAAA AAAAAAAAAAAAAAAAAAAAAAAAAAAAAAA AAAAAAAAAAAAAAAAAAAAAAAAAAAAAAA -AAAAAAAAAAAAAAAAAAAAAAAAAAAAA- -AAAAAAAAAAAAAAAAAAAAAAAAAAAAA- -AAAAAAAAAAAAAAAAAAAAAAAAAAAAA- --AAAAAAAAAAAAAAAAAAAAAAAAAAA-- --AAAAAAAAAAAAAAAAAAAAAAAAAAA-- ---AAAAAAAAAAAAAAAAAAAAAAAAA--- ----AAAAAAAAAAAAAAAAAAAAAAA---- -----AAAAAAAAAAAAAAAAAAAAA----- ------AAAAAAAAAAAAAAAAAAA------ -------AAAAAAAAAAAAAAAAA------- ---------AAAAAAAAAAAAA--------- ------------AAAAAAA------------ 
------------AAAAAAA------------ ---------AAAAAAAAAAAAA--------- -------AAAAAAAAAAAAAAAAA------- ------AAAAAAAAAAAAAAAAAAA------ -----AAAAAAAAAAAAAAAAAAAAA----- ----AAAAAAAAAAAAAAAAAAAAAAA---- ---AAAAAAAAAAAAAAAAAAAAAAAAA--- --AAAAAAAAAAAAAAAAAAAAAAAAAAA-- --AAAAAAAAAAAAAAAAAAAAAAAAAAA-- -AAAAAAAAAAAAAAAAAAAAAAAAAAAAA- -AAAAAAAAAAAAAAAAAAAAAAAAAAAAA- -AAAAAAAAAAAAAAAAAAAAAAAAAAAAA- AAAAAAAAAAAAAAAAAAAAAAAAAAAAAAA AAAAAAAAAAAAAAAAAAAAAAAAAAAAAAA AAAAAAAAAAAAAAAAAAAAAAAAAAAAAAA AAAAAAAAAAAAAAAAAAAAAAAAAAAAAAA AAAAAAAAAAAAAAADAAAAAAAAAAAAAAA AAAAAAAAAAAAAAAAAAAAAAAAAAAAAAA AAAAAAAAAAAAAAAAAAAAAAAAAAAAAAA -AAAAAAAAAAAAAAAAAAAAAAAAAAAAA- -AAAAAAAAAAAAAAAAAAAAAAAAAAAAA- -AAAAAAAAAAAAAAAAAAAAAAAAAAAAA- --AAAAAAAAAAAAAAAAAAAAAAAAAAA-- --AAAAAAAAAAAAAAAAAAAAAAAAAAA-- ---AAAAAAAAAAAAAAAAAAAAAAAAA--- ----AAAAAAAAAAAAAAAAAAAAAAA---- -----AAAAAAAAAAAAAAAAAAAAA----- ------AAAAAAAAAAAAAAAAAAA------ -------AAAAAAAAAAAAAAAAA------- ---------AAAAAAAAAAAAA--------- ------------AAAAAAA------------ 
------------------------------- ------------------------------- --------------CBC-------------- --------------CBC-------------- -------------CCBCC------------- -------------CCBCC------------- -------------CCBCC------------- -------------CCBCC------------- ------------CCCBCCC------------ ------------CCCBCCC------------ ------------CCCBCCC------------ ------------CCCBCCC------------ ------------CCCBCCC------------ ------------CCCBCCC------------ -----------CCCCBCCCC----------- -----------CCCCBCCCC----------- -----------CCCCBCCCC----------- -----------CCCCBCCCC----------- -----------CCCCBCCCC----------- -----------CCCCBCCCC----------- ---------BBBBBBBBBBBBB--------- ---------BBBBBBBBBBBBB--------- ------------BBBBBBB------------ ------------BBBBBBB------------ ------------BBBBBBB------------ ------------B--B--B------------ ------------B-----B------------ -------------B---B------------- --------------BBB-------------- ------------------------------- ------------------------------- 
------------------------------- ------------------------------- --------------CBC-------------- --------------CBC-------------- -------------CCBCC------------- -------------CCBCC------------- -------------CCBCC------------- -------------CCBCC------------- ------------CCCBCCC------------ ------------CCCBCCC------------ ------------CCCBCCC------------ ------------CCCBCCC------------ ------------CCCBCCC------------ ------------CCCBCCC------------ -----------CCCCBCCCC----------- -----------CCCCBCCCC----------- -----------CCCCBCCCC----------- -----------CCCCBCCCC----------- -----------CCCCBCCCC----------- -----------CCCCBCCCC----------- ---------BBBBBBBBBBBBB--------- ---------BBBBBBBBBBBBB--------- ------------BBBBBBB------------ ------------BBBBBBB------------ ------------BBBBBBB------------ ------------B--B--B------------ ------------B-----B------------ -------------B---B------------- --------------BBB-------------- ------------------------------- ------------------------------- 
