model
size = 32 13 10, scale = 0.05, origin = -y
material 
  colors = A:#111 B:#32FFEA C:#C33 D:#E00
voxels
195-AB3A27-AB3A347-AB3A26-2AB4A25-BAB4A26-AB3A283-AB3A26-2AB4A24-3AB5A23-2(AB)5A24-2AB4A26-AB3A219-AB3A26-2AB4A23-D3AB5A19-A2-D3AB7A17-2A2-2(AB)7A17-2A2-3AB5A19-A4-2AB4A26-AB3A90-C31-C30-2C31-2AB4A23-2D2AB5A23-3AB7A17-2A-D3AB29ABAB27A-3AB7A17-2A2-3AB5A23-C2AB4A24-4C31-4C26-C31-C30-2C31-2AB4A23-2D2AB5A23-3AB7A17-2A-D3AB29ABAB27A-3AB7A17-2A2-3AB5A23-C2AB4A24-4C31-4C123-AB3A26-2AB4A23-D3AB5A19-A2-D3AB7A17-2A2-2(AB)7A17-2A2-3AB5A19-A4-2AB4A26-AB3A219-AB3A26-2AB4A24-3AB5A23-2(AB)5A24-2AB4A26-AB3A283-AB3A26-2AB4A25-BAB4A26-AB3A347-AB3A27-AB3A184-
