model
size = 30 31 24, scale = 0.05, origin = -y
material 
  colors = A:#2A4A5B B:#F00 C:#C80000 D:#960000 E:#46647C F:#4B4B4B
voxels
------------------------------ ------------------------------ ------------------------------ ------------------------------ ------------------------------ ------------------------------ ------------------------------ ------------------------------ ------------------------------ ------------------------------ ---DDDDDDDDD------DDDDDDDD---- ---BBBBBBBBBBB---CBBBBBBBBB--- -CBBBBBBBBBBBBB--CBBBBBBBBBB-- -CBBBBBBBBBBBBB--CBBBBBBBBBB-- -CBBB-CBBB-CBBB----------BBB-- -CBBB-CBBB-CBBB---DDDDDDDBBB-- -CBBB-CBBB-CBBB---BBBBBBBBBB-- -CBBB-CBBB-CBBB---BBBBBBBBBB-- -CBBB-CBBB-CBBB---BBBBBBBBBB-- -CBBB-CBBB-CBBB----------BBB-- -CBBB-CBBB-CBBB--CBBBBBBBBBB-- -CBBB-CBBB-CBBB--CBBBBBBBBBF-- -CBBB-CBBB-CBBB--CBBBBBBBB---- ------------------------------ ------------------------------ ------------------------------ ------------------------------ ------------------------------ ------------------------------ ------------------------------ ------------------------------ 
------------------------------ ------------------------------ ------------------------------ ------------------------------ ------------------------------ ------------------------------ ------------------------------ ------------------------------ ------------------------------ ------------------------------ ---DDDDDDDDD------DDDDDDDD---- ---BBBBBBBBBBB---CBBBBBBBBB--- -CBBBBBBBBBBBBB--CBBBBBBBBBB-- -CBBBBBBBBBBBBBAACBBBBBBBBBB-- -CBBB-CBBB-CBBBAA--------BBB-- -CBBB-CBBB-CBBBAA-DDDDDDDBBB-- -CBBB-CBBB-CBBBAA-BBBBBBBBBB-- -CBBB-CBBB-CBBBAA-BBBBBBBBBB-- -CBBB-CBBB-CBBBAA-BBBBBBBBBB-- -CBBB-CBBB-CBBBAA--------BBB-- -CBBB-CBBB-CBBBAACBBBBBBBBBB-- -CBBB-CBBB-CBBBAACBBBBBBBBBF-- -CBBB-CBBB-CBBBAACBBBBBBBB---- ------------------------------ ------------------------------ ------------------------------ ------------------------------ ------------------------------ ------------------------------ ------------------------------ ------------------------------ 
------------------------------ ------------------------------ ------------------------------ ------------------------------ ------------------------------ ------------------------------ ------------------------------ ------------------------------ -------------AAAA------------- -------------AAAA------------- ---DDDDDDDDD-AAAA-DDDDDDDD---- ---BBBBBBBBBBBAAACBBBBBBBBB--- -CBBBBBBBBBBBBBAACBBBBBBBBBB-- -CBBBBBBBBBBB----CBBBBBBBBBB-- -CBBB-CBBBACB----AAA-----BBB-- -CBBB-CBBBACB----ADDDDDDDBBB-- -CBBB-CBBBACB----ABBBBBBBBBB-- -CBBB-CBBBACB----ABBBBBBBBBB-- -CBBB-CBBBACB----ABBBBBBBBBB-- -CBBB-CBBBACB----AAA-----BBB-- -CBBB-CBBBACB----CBBBBBBBBBB-- -CBBB-CBBBACB----CBBBBBBBBBF-- -CBBB-CBBBACB----CBBBBBBBB---- -------------AAAA------------- -------------AAAA------------- -------------AAAA------------- ------------------------------ ------------------------------ ------------------------------ ------------------------------ ------------------------------ 
--------------AA-------------- -------------AAAA------------- -------------AAAA------------- -------------AAAA------------- -------------AAAA------------- -------------AAAA------------- -------------AAAA------------- -------------AAAA------------- ----------AAA----AAA---------- ----------AAA----AAA---------- ---DDDDDDDDDA----ADDDDDDDD---- ---BBBBBBBBBB-------BBBBBBB--- -CBBBBBBBBBBB-------BBBBBBBB-- -CBBBBBBBB----------BBBBBBBB-- -CBBB-CBBB----------AA---BBB-- -CBBB-CBBB----------DDDDDBBB-- -CBBB-CBBB----------BBBBBBBB-- -CBBB-CBBB----------BBBBBBBB-- -CBBB-CBBB----------BBBBBBBB-- -CBBB-CBBB----------AA---BBB-- -CBBB-CBBB----------BBBBBBBB-- -CBBB-CBBB----------BBBBBBBF-- -CBBB-CBBB----------BBBBBB---- ----------AAA----AAA---------- ----------AAA----AAA---------- ----------AAA----AAA---------- -------------AAAA------------- -------------AAAA------------- -------------AAAA------------- -------------AAAA------------- -------------AAAA------------- 
--------------AA-------------- ------------AAAAAA------------ ----------AAAAAAAAAA---------- ----------AAAA--AAAA---------- ----------AAA----AAA---------- ----------AAA----AAA---------- ----------AAA----AAA---------- ----------AAA----AAA---------- --------AA----------AA-------- --------AA----------AA-------- ---DDDDDDD----------DDDDDD---- ---BBBBBBB------------BBBBB--- -CBBBBBBBB------------BBBBBB-- -CBBBBBB--------------BBBBBB-- -CBBBACB--------------AAABBB-- -CBBBACB--------------DDDBBB-- -CBBBACB--------------BBBBBB-- -CBBBACB--------------BBBBBB-- -CBBBACB--------------BBBBBB-- -CBBBACB--------------AAABBB-- -CBBBACB--------------BBBBBB-- -CBBBACB--------------BBBBBF-- -CBBBACB--------------BBBB---- --------AA----------AA-------- --------AA----------AA-------- --------AA----------AA-------- ----------AAA----AAA---------- ----------AAAA--AAAA---------- ----------AAAAAAAAAA---------- ----------AAAAAAAAAA---------- ------------AAAAAA------------ 
------------------------------ ------------A----A------------ ----------AAA----AAA---------- --------AAAAA----AAAAA-------- --------AAAA------AAAA-------- --------AA----------AA-------- --------AA----------AA-------- --------AA----------AA-------- ----AAAA--------------AAAA---- ----AAAA--------------AAAA---- ----AAAA--------------AAAA---- ----AAAA--------------AAAA---- ----AAAA--------------AAAA---- -AAAA---------------------AAA- -AAA----------------------AAA- -AAA----------------------AAA- -AAA----------------------AAA- AAAA----------------------AAAA AAAA----------------------AAAA AAAA----------------------AAAA AAAA----------------------AAAA AAAA----------------------AAAA AAAA----------------------AAAA ----AAAA--------------AAAA---- ----AAAA--------------AAAA---- ----AAAAAA----------AAAAAA---- --------AAAA------AAAA-------- --------AAAAA----AAAAA-------- --------AAAAA----AAAAA-------- ----------AAA----AAA---------- ------------A----A------------ 
------------------------------ ------------------------------ ------------------------------ --------AA----------AA-------- ------AAAA----------AAAA------ ----AAAAAA----------AAAAAA---- ----AAAA--------------AAAA---- ----AAAA--------------AAAA---- ---AAA------------------AAA--- --AAAA------------------AAAA-- --AAA---------------------AA-- --AAA---------------------AA-- --AAA---------------------AA-- -AAA----------------------AAA- -AAA----------------------AAA- -AAA----------------------AAA- -AAA----------------------AAA- AAAA----------------------AAAA AAA------------------------AAA AAA------------------------AAA AAA------------------------AAA AAA------------------------AAA AAAA----------------------AAAA AAAAAA------------------AAAAAA AAAAAAAA--------------AAAAAAAA --AAAAAA--------------AAAAAA-- ----AAAAAA----------AAAAAA---- ------AAAA----------AAAA------ --------AA----------AA-------- ------------------------------ ------------------------------ 
------------------------------ ------------------------------ ------------------------------ ------------------------------ ------AA--------------AA------ ----AAAA--------------AAAA---- ---AAAAA--------------AAAAA--- ---AAA------------------AAA--- ---A----------------------A--- --AA----------------------AA-- --AA----------------------AA-- --AA----------------------AA-- --AA----------------------AA-- --AA----------------------AA-- --AA----------------------AA-- --AA----------------------AA-- --AA----------------------AA-- -AA------------------------AA- -AA------------------------AA- -AA------------------------AA- -AA------------------------AA- -AA------------------------AA- -AA------------------------AA- AAAA----------------------AAAA AAAA----------------------AAAA --AA----------------------AA-- ----AAAA--------------AAAA---- ------AA--------------AA------ ------------------------------ ------------------------------ ------------------------------ 
------------------------------ ------------------------------ ------------------------------ ------------------------------ ------------------------------ ------------------------------ ---A----------------------A--- ---A----------------------A--- ---A----------------------A--- --AA----------------------AA-- --AA----------------------AA-- --AA----------------------AA-- --AA----------------------AA-- --AA----------------------AA-- --AA----------------------AA-- --AA----------------------AA-- --AA----------------------AA-- -AA------------------------AA- -AA------------------------AA- -AA------------------------AA- -AA------------------------AA- -AA------------------------AA- -AA------------------------AA- AAA------------------------AAA AAA------------------------AAA ------------------------------ ------------------------------ ------------------------------ ------------------------------ ------------------------------ ------------------------------ 
------------------------------ ------------------------------ ------------------------------ ------------------------------ ------------------------------ ------------------------------ ---A----------------------A--- ---A----------------------A--- ---A----------------------A--- --AA----------------------AA-- --AA----------------------AA-- --AA----------------------AA-- --AA----------------------AA-- --AA----------------------AA-- --AA----------------------AA-- --AA----------------------AA-- --AA----------------------AA-- -AA------------------------AA- -AA------------------------AA- -AA------------------------AA- -AA------------------------AA- -AA------------------------AA- -AA------------------------AA- AAA------------------------AAA AAA------------------------AAA ------------------------------ ------------------------------ ------------------------------ ------------------------------ ------------------------------ ------------------------------ 
------------------------------ ------------------------------ ------------------------------ ------------------------------ ------------------------------ ------------------------------ ---A----------------------A--- ---A----------------------A--- ---A----------------------A--- --AA----------------------AA-- --AA----------------------AA-- --AA----------------------AA-- --AA----------------------AA-- --AA----------------------AA-- --AA----------------------AA-- --AA----------------------AA-- --AA----------------------AA-- -AA------------------------AA- -AA------------------------AA- -AA------------------------AA- -AA------------------------AA- -AA------------------------AA- -AA------------------------AA- AAA------------------------AAA AAA------------------------AAA ------------------------------ ------------------------------ ------------------------------ ------------------------------ ------------------------------ ------------------------------ 
------------------------------ ------------------------------ ------------------------------ ------------------------------ ------------------------------ ------------------------------ ---A----------------------A--- ---A----------------------A--- ---A----------------------A--- --AA----------------------AA-- --AA----------------------AA-- --AA----------------------AA-- --AA----------------------AA-- --AA----------------------AA-- --AA----------------------AA-- --AA----------------------AA-- --AA----------------------AA-- -AA------------------------AA- -AA------------------------AA- -AA------------------------AA- -AA------------------------AA- -AA------------------------AA- -AA------------------------AA- AAA------------------------AAA AAA------------------------AAA ------------------------------ ------------------------------ ------------------------------ ------------------------------ ------------------------------ ------------------------------ 
------------------------------ ------------------------------ ------------------------------ ------------------------------ ------------------------------ ------------------------------ ------------------------------ ---A----------------------A--- ---A----------------------A--- --AA----------------------AA-- --AA----------------------AA-- --AA----------------------AA-- --AA----------------------AA-- --AA----------------------AA-- --AA----------------------AA-- --AA----------------------AA-- --AA----------------------AA-- -AA------------------------AA- -AA------------------------AA- -AA------------------------AA- -AA------------------------AA- -AA------------------------AA- -AA------------------------AA- AAA------------------------AAA AAA------------------------AAA ------------------------------ ------------------------------ ------------------------------ ------------------------------ ------------------------------ ------------------------------ 
------------------------------ ------------------------------ ------------------------------ ------------------------------ ------------------------------ ------------------------------ ------------------------------ ---A----------------------A--- ---A----------------------A--- --AA----------------------AA-- --AA----------------------AA-- --AA----------------------AA-- --AA----------------------AA-- --AA----------------------AA-- --AA----------------------AA-- --AA----------------------AA-- --AA----------------------AA-- -AA------------------------AA- -AA------------------------AA- -AA------------------------AA- -AA------------------------AA- -AA------------------------AA- -AA------------------------AA- AAA------------------------AAA AAA------------------------AAA ------------------------------ ------------------------------ ------------------------------ ------------------------------ ------------------------------ ------------------------------ 
------------------------------ ------------------------------ ------------------------------ ------------------------------ ------------------------------ ------------------------------ ------------------------------ ---A----------------------A--- ---A----------------------A--- --AA----------------------AA-- --AA----------------------AA-- --AA----------------------AA-- --AA----------------------AA-- --AA----------------------AA-- --AA----------------------AA-- --AA----------------------AA-- --AA----------------------AA-- -AA------------------------AA- -AA------------------------AA- -AA------------------------AA- -AA------------------------AA- -AA------------------------AA- -AA------------------------AA- AAA------------------------AAA AAA------------------------AAA ------------------------------ ------------------------------ ------------------------------ ------------------------------ ------------------------------ ------------------------------ 
------------------------------ ------------------------------ ------------------------------ ------------------------------ ------------------------------ ------------------------------ ------------------------------ ---A----------------------A--- ---A----------------------A--- --AA----------------------AA-- --AA----------------------AA-- --EA----------------------AE-- --EA----------------------AE-- --EA----------------------AE-- --EA----------------------AE-- --AA----------------------AA-- --AA----------------------AA-- -AA------------------------AA- -AA------------------------AA- -EA------------------------AE- -EA------------------------AE- -AA------------------------AA- -AA------------------------AA- AAA------------------------AAA AAA------------------------AAA ------------------------------ ------------------------------ ------------------------------ ------------------------------ ------------------------------ ------------------------------ 
------------------------------ ------------------------------ ------------------------------ ------------------------------ ------------------------------ ------------------------------ ------------------------------ ---A----------------------A--- ---A----------------------A--- --AA----------------------AA-- --EA----------------------AE-- ------------------------------ ------------------------------ ------------------------------ ------------------------------ --EA----------------------AE-- --AA----------------------AA-- -AA------------------------AA- -EA------------------------AE- ------------------------------ ------------------------------ -EA------------------------AE- -AA------------------------AA- AAA------------------------AAA AAA------------------------AAA ------------------------------ ------------------------------ ------------------------------ ------------------------------ ------------------------------ ------------------------------ 
------------------------------ ------------------------------ ------------------------------ ------------------------------ ------------------------------ ------------------------------ ------------------------------ ------------------------------ ---A----------------------A--- --EA----------------------AE-- ------------------------------ ------------------------------ ------------------------------ ------------------------------ ------------------------------ ------------------------------ --EA----------------------AE-- -EA------------------------AE- ------------------------------ ------------------------------ ------------------------------ ------------------------------ -EA------------------------AE- AAA------------------------AAA AAA------------------------AAA ------------------------------ ------------------------------ ------------------------------ ------------------------------ ------------------------------ ------------------------------ 
------------------------------ ------------------------------ ------------------------------ ------------------------------ ------------------------------ ------------------------------ ------------------------------ ------------------------------ ---A----------------------A--- --EA----------------------AE-- ------------------------------ ------------------------------ ------------------------------ ------------------------------ ------------------------------ ------------------------------ --EA----------------------AE-- -EA------------------------AE- ------------------------------ ------------------------------ ------------------------------ ------------------------------ -EA------------------------AE- AAA------------------------AAA AAA------------------------AAA ------------------------------ ------------------------------ ------------------------------ ------------------------------ ------------------------------ ------------------------------ 
------------------------------ ------------------------------ ------------------------------ ------------------------------ ------------------------------ ------------------------------ ------------------------------ ------------------------------ ---A----------------------A--- --EA----------------------AE-- ------------------------------ ------------------------------ ------------------------------ ------------------------------ ------------------------------ ------------------------------ --EA----------------------AE-- -EA------------------------AE- ------------------------------ ------------------------------ ------------------------------ ------------------------------ -EA------------------------AE- AAA------------------------AAA AAA------------------------AAA ------------------------------ ------------------------------ ------------------------------ ------------------------------ ------------------------------ ------------------------------ 
------------------------------ ------------------------------ ------------------------------ ------------------------------ ------------------------------ ------------------------------ ------------------------------ ------------------------------ ---A----------------------A--- --EA----------------------AE-- ------------------------------ ------------------------------ ------------------------------ ------------------------------ ------------------------------ ------------------------------ --EA----------------------AE-- -EA------------------------AE- ------------------------------ ------------------------------ ------------------------------ ------------------------------ -EA------------------------AE- AAA------------------------AAA AAA------------------------AAA ------------------------------ ------------------------------ ------------------------------ ------------------------------ ------------------------------ ------------------------------ 
------------------------------ ------------------------------ ------------------------------ ------------------------------ ------------------------------ ------------------------------ ------------------------------ ------------------------------ ------------------------------ --AA----------------------AA-- --EA----------------------AE-- ------------------------------ ------------------------------ ------------------------------ ------------------------------ --EA----------------------AE-- --AA----------------------AA-- -AA------------------------AA- -EA------------------------AE- ------------------------------ ------------------------------ -EA------------------------AE- -AA------------------------AA- ------------------------------ ------------------------------ ------------------------------ ------------------------------ ------------------------------ ------------------------------ ------------------------------ ------------------------------ 
------------------------------ ------------------------------ ------------------------------ ------------------------------ ------------------------------ ------------------------------ ------------------------------ ------------------------------ ------------------------------ ------------------------------ --AA----------------------AA-- --EA----------------------AE-- --EA----------------------AE-- --EA----------------------AE-- --EA----------------------AE-- --AA----------------------AA-- ------------------------------ ------------------------------ -AA------------------------AA- -EA------------------------AE- -EA------------------------AE- -AA------------------------AA- ------------------------------ ------------------------------ ------------------------------ ------------------------------ ------------------------------ ------------------------------ ------------------------------ ------------------------------ ------------------------------ 
------------------------------ ------------------------------ ------------------------------ ------------------------------ ------------------------------ ------------------------------ ------------------------------ ------------------------------ ------------------------------ ------------------------------ ------------------------------ ------------------------------ ------------------------------ ------------------------------ ------------------------------ ------------------------------ ------------------------------ ------------------------------ ------------------------------ -AA------------------------AA- -AA------------------------AA- ------------------------------ ------------------------------ ------------------------------ ------------------------------ ------------------------------ ------------------------------ ------------------------------ ------------------------------ ------------------------------ ------------------------------ 
