model
size = 10 8 18, scale = 0.05, origin = -y
material 
  colors = A:#555 B:#777 C:#444 D:#888 E:#AAA F:#EEE
voxels
---------- ---------- ---------- ---------- ---------- ---------- ---------- AAAAAAAAAA 
---------- ----CC---- -----CC--- ------C--- ------B--- -----BB--- ----BB---- AEDDEEDDEA 
----CC---- ------C--- -------C-- -------C-- ------BB-- -BB--BFB-- --BBBBB--- ADAAAAAADA 
-----CC--- -------C-- C------C-- -C-------- -BB------- ---B-BBB-- ---BBBBB-- AAAEADEAAA 
------C--- C------C-- C--------- -CC------- --BB------ ----B----- ----B-BB-- AAADDEDAAA 
C--------- C--------- -C-------- --CC------ ---B------ ----B----- ---------- ADADEADADA 
-C-------- -CC------- --CC------ ---------- ---------- ---------- ---------- ADADDEDADA 
---------- ---------- ---------- ---------- ---------- ---------- ---------- AEAEADEAEA 
---------- ---------- ---------- ---------- ---------- ---------- ---------- AEADEEDAEA 
---------- ---------- ---------- ---------- ---------- ---------- ---------- AEADEEDAEA 
---------- ---------- ---------- ---------- ---------- ---------- ---------- AEADADEAEA 
---------- ----CC---- -----CC--- ------C--- ------B--- -----BB--- ----BB---- ADAEDEDADA 
----CC---- ------C--- -------C-- -------C-- ------BB-- -BB--BFB-- --BBBBB--- ADADEADADA 
-----CC--- -------C-- C------C-- -C-------- -BB------- ---B-BBB-- ---BBBBB-- AAADAEDAAA 
------C--- C------C-- C--------- -CC------- --BB------ ----B----- ----B-BB-- AAAEDDEAAA 
C--------- C--------- -C-------- --CC------ ---B------ ----B----- ---------- ADAAAAAADA 
-C-------- -CC------- --CC------ ---------- ---------- ---------- ---------- AEDDEEDDEA 
---------- ---------- ---------- ---------- ---------- ---------- ---------- AAAAAAAAAA 
