model
size = 32 3 32, scale = 0.05, origin = -y
material 
  colors = A:#000 B:#E9E73A C:#D61E86 D:#761D51 E:#FFF F:#A21966 G:#D7C16E H:#3D98B8 I:#2CE8F4 J:#7D6F3B K:#B8E986 L:#344A57 M:#564B26 N:#63C64D
voxels
5AL2H2I12A2I2HL69A2B4AL2H2I10A2I2HL4A2B64A4B3AL2HI3A4E3AI2HL3A4B64A4BK3ALH2IAEK2AKEA2IHL3AK4B64AJG3BK3A2HIAEAB2AEAI2H3AK3BGJ64AMJG3BKDALH2IE4AE2IHLADK3BGJM65AMJG3BKDL2HIEK2AKEI2HLDK3BGJM67AMJG3BKDLH2I4E2IHLDK3BGJM69AMJG2B2KDLH6IHLD2K2BGJM71A2JG2B2KDL2H2I2HLD2K2BG2J73A2JG3B2K2L2H2L2K3BG2J70AB3AM3J4D2F2L2F4D3JM3AB65A2B4AMJD4EDF2DFD4EDJM4A2B64AB4AMCD2E2A2ED2FD2E2A2EDCM4AB68A2CDAE4AED2CDE4AEAD2C71ACF2DAE2ANAED2CDEAN2AEA2DFC69AC3FDA2E2A2ED2CD2E2A2EAD3FC67AC2AC2FDA4E2A2C2A4EAD2FC2AC71AC2D5AF2CF5A2DC73AC3BCF4D6C4DFC3BC68AC6B5CAC2DCA5C6BC65AC2B2G2C2G2BFCF4DFCF2B2G2C2G2BC64AC2BC5AD2CFDE2AEDF2CD5AC2BC64ACB6ABDCFEAE2AEAEFCDB6ABC65AG2B3ABGDFDE6AEDFDGB3A2BG67AG4BGA2D10A2DAG4BG67ACF4G3AE2AED2CDE2AE3A4GFC65AC2F7A2DAEF2CFEA2D7A2FC64A2F3A2B4A2DEF2CFE2D4A2B3A2F64AF4A2B5ADF4CFD5A2B4AF64AF4ABJ6AD4CD6AJB4AF69ABJ7A4C7AJB69A
