model
size = 28 32 28, scale = 0.05, origin = -y
material 
  colors = A:#0F0 B:#111
voxels
40-4A23-6A21-8A18-12A15-14A13-6AB2AB6A11-18A9-2(20A8-)5A3-4A3-5A7-5A4-4A4-5A6-2(4A5-)4A6-3A5-6A5-3A6-3A4-8A4-3A6-2A4-10A4-2A4(6-22A)7-2(20A8-)20A9-18A10-18A11-16A13-14A15-12A159-6A21-8A18-12A15-14A13-16A11-18A9-20A8-20A7-22A5-7A3B4A3B7A4-6A4B4A4B6A4-5A5B4A5B5A4-4A5B6A5B4A4-4A4B8A4B4A4-3A4B10A4B3A2(4-24A)5-2(22A6-)22A7-2(20A8-)20A9-18A11-16A13-14A15-12A17-10A132-6A21-8A18-12A15-14A13-16A11-18A9-20A7-22A6-22A5-24A3-5(26A2-)26A3-3(24A4-)24A5-2(22A6-)22A7-20A9-18A12-14A15-12A16-12A17-10A78-2A24-6A21-8A18-12A15-14A13-16A11-18A9-20A7-22A6-22A5-24A3-26A2-26A-56A-3(26A2-)26A3-4(24A4-)24A5-22A7-20A10-16A13-14A15-12A16-12A77-2A24-6A21-8A18-12A15-14A13-16A11-18A9-20A7-22A6-22A5-24A3-26A2-26A-140A-4(26A2-)26A3-24A5-22A7-20A9-18A11-16A13-14A15-12A18-8A51-2A24-6A21-8A18-12A15-14A13-16A11-18A9-20A7-22A6-22A5-24A3-26A2-26A-196A-2(26A2-)26A3-24A4-24A5-22A7-20A9-18A11-16A13-14A16-10A50-2A24-6A21-8A18-12A15-14A13-16A11-18A9-20A7-22A6-22A5-24A3-26A2-26A-224A-26A2-26A3-2(24A4-)24A6-20A8-20A9-18A11-16A14-12A18-8A23-2A24-6A21-8A18-12A15-14A13-16A11-18A9-20A7-22A6-22A5-24A3-26A2-26A-224A-26A2-26A3-2(24A4-)24A5-22A7-20A8-20A9-18A12-14A16-10A22-2A24-6A21-8A18-12A15-14A13-16A11-18A9-20A7-22A6-22A5-24A3-26A2-26A-252A-26A2-26A3-24A4-24A5-22A6-22A7-20A9-18A11-2(16A14-12A21-2A24-6A21-8A18-12A15-14A13-16A11-18A9-20A7-22A6-22A5-24A3-26A2-26A-252A-26A2-26A3-24A4-24A5-2(22A6-)22A7-20A10-)2(16A14-12A21-2A24-6A21-8A18-12A15-14A13-16A11-18A9-20A7-22A6-22A5-24A3-26A2-26A-280A-26A3-24A4-24A5-2(22A6-)22A7-20A10-)2(16A14-12A21-2A24-6A21-8A18-12A15-14A13-16A11-18A9-20A7-22A6-22A5-24A3-26A2-26A-252A-26A2-26A3-24A4-24A5-2(22A6-)22A7-20A10-)16A14-12A21-2A24-6A21-8A18-12A15-14A13-16A11-18A9-20A7-22A6-22A5-24A3-26A2-26A-252A-26A2-26A3-24A4-24A5-22A6-22A7-20A9-18A11-16A14-12A21-2A24-6A21-8A18-12A15-14A13-16A11-18A9-20A7-22A6-22A5-24A3-26A2-26A-224A-26A2-26A3-2(24A4-)24A5-22A7-20A8-20A9-18A12-14A16-10A22-2A24-6A21-8A18-12A15-14A13-16A11-18A9-20A7-22A6-22A5-24A3-26A2-26A-224A-26A2-26A3-2(24A4-)24A6-20A8-20A9-18A11-16A14-12A18-8A23-2A24-6A21-8A18-12A15-14A13-16A11-18A9-20A7-22A6-22A5-24A3-26A2-26A-196A-2(26A2-)26A3-24A4-24A5-22A7-20A9-18A11-16A13-14A16-10A50-2A24-6A21-8A18-12A15-14A13-16A11-18A9-20A7-22A6-22A5-24A3-26A2-26A-140A-4(26A2-)26A3-24A5-22A7-20A9-18A11-16A13-14A15-12A18-8A51-2A24-6A21-8A18-12A15-14A13-16A11-18A9-20A7-22A6-22A5-24A3-26A2-26A-56A-3(26A2-)26A3-4(24A4-)24A5-22A7-20A10-16A13-14A15-12A16-12A103-6A21-8A18-12A15-14A13-16A11-18A9-20A7-22A6-22A5-24A3-5(26A2-)26A3-3(24A4-)24A5-2(22A6-)22A7-20A9-18A12-14A15-12A16-12A17-10A104-6A21-8A18-12A15-14A13-16A11-18A9-20A8-20A7-22A5-7A3B4A3B7A4-6A4B4A4B6A4-5A5B4A5B5A4-4A5B6A5B4A4-4A4B8A4B4A4-3A4B10A4B3A2(4-24A)5-2(22A6-)22A7-2(20A8-)20A9-18A11-16A13-14A15-12A17-10A133-4A23-6A21-8A18-12A15-14A13-6AB2AB6A11-18A9-2(20A8-)5A3-4A3-5A7-5A-10A-5A6-4A-12A-4A6-3A-14A-3A6-22A6-2A-16A-2A4(6-22A)7-2(20A8-)20A9-18A10-18A11-16A13-14A15-12A243-6A20-10A16-14A13-16A12-16A11-18A10-18A9-5(20A8-)20A9-18A10-18A11-16A12-16A13-14A16-10A20-6A388-2A23-8A18-12A15-14A14-14A13-2(16A12-)16A11-18A10-18A11-2(16A12-)16A13-14A14-14A15-12A18-8A23-2A473-4A22-8A19-10A17-12A16-12A15-3(14A14-)14A15-12A16-12A17-10A19-8A22-4A612-4A23-6A21-3(8A20-)8A21-6A23-4A404-
