model
size = 27 14 27, scale = 0.05, origin = -y
material 
  colors = A:#4A225D
voxels
----------AAAAAAA---------- ----------AAAAAAA---------- --------------------------- --------------------------- --------------------------- --------------------------- --------------------------- --------------------------- --------------------------- --------------------------- --------------------------- --------------------------- --------------------------- --------------------------- 
-------AAAAAAAAAAAAA------- -------AAAAAAAAAAAAA------- ----------AAAAAAA---------- ----------AAAAAAA---------- --------------------------- --------------------------- --------------------------- --------------------------- --------------------------- --------------------------- --------------------------- --------------------------- --------------------------- --------------------------- 
------AAAAAAAAAAAAAAA------ ------AAAAAAAAAAAAAAA------ --------AAAAAAAAAAA-------- --------AAAAAAAAAAA-------- ----------AAAAAAA---------- ----------AAAAAAA---------- --------------------------- --------------------------- --------------------------- --------------------------- --------------------------- --------------------------- --------------------------- --------------------------- 
----AAAAAAAAAAAAAAAAAAA---- ----AAAAAAAAAAAAAAAAAAA---- ------AAAAAAAAAAAAAAA------ ------AAAAAAAAAAAAAAA------ --------AAAAAAAAAAA-------- --------AAAAAAAAAAA-------- ----------AAAAAAA---------- ----------AAAAAAA---------- --------------------------- --------------------------- --------------------------- --------------------------- --------------------------- --------------------------- 
---AAAAAAAAAAAAAAAAAAAA---- ---AAAAAAAAAAAAAAAAAAAA---- -----AAAAAAAAAAAAAAAAA----- -----AAAAAAAAAAAAAAAAA----- ------AAAAAAAAAAAAAAA------ ------AAAAAAAAAAAAAAA------ --------AAAAAAAAAAA-------- --------AAAAAAAAAAA-------- ----------AAAAAAA---------- ----------AAAAAAA---------- --------------------------- --------------------------- --------------------------- --------------------------- 
---AAAAAAAAAAAAAAAAAAAAA--- ---AAAAAAAAAAAAAAAAAAAAA--- ----AAAAAAAAAAAAAAAAAAA---- ----AAAAAAAAAAAAAAAAAAA---- -----AAAAAAAAAAAAAAAAA----- -----AAAAAAAAAAAAAAAAA----- -------AAAAAAAAAAAAA------- -------AAAAAAAAAAAAA------- --------AAAAAAAAAAA-------- --------AAAAAAAAAAA-------- -----------AAAAA----------- -----------AAAAA----------- --------------------------- --------------------------- 
--AAAAAAAAAAAAAAAAAAAAAAA-- --AAAAAAAAAAAAAAAAAAAAAAA-- ---AAAAAAAAAAAAAAAAAAAAA--- ---AAAAAAAAAAAAAAAAAAAAA--- ----AAAAAAAAAAAAAAAAAAA---- ----AAAAAAAAAAAAAAAAAAA---- ------AAAAAAAAAAAAAAA------ ------AAAAAAAAAAAAAAA------ -------AAAAAAAAAAAAA------- -------AAAAAAAAAAAAA------- ---------AAAAAAAAA--------- ---------AAAAAAAAA--------- -----------AAAAA----------- -----------AAAAA----------- 
-AAAAAAAAAAAAAAAAAAAAAAAAA- -AAAAAAAAAAAAAAAAAAAAAAAAA- ---AAAAAAAAAAAAAAAAAAAAA--- ---AAAAAAAAAAAAAAAAAAAAA--- ----AAAAAAAAAAAAAAAAAAA---- ----AAAAAAAAAAAAAAAAAAA---- -----AAAAAAAAAAAAAAAAA----- -----AAAAAAAAAAAAAAAAA----- ------AAAAAAAAAAAAAAA------ ------AAAAAAAAAAAAAAA------ -------AAAAAAAAAAAAA------- -------AAAAAAAAAAAAA------- ---------AAAAAAAAA--------- ---------AAAAAAAAA--------- 
-AAAAAAAAAAAAAAAAAAAAAAAAA- -AAAAAAAAAAAAAAAAAAAAAAAAA- --AAAAAAAAAAAAAAAAAAAAAAA-- --AAAAAAAAAAAAAAAAAAAAAAA-- ---AAAAAAAAAAAAAAAAAAAAA--- ---AAAAAAAAAAAAAAAAAAAAA--- ----AAAAAAAAAAAAAAAAAAA---- ----AAAAAAAAAAAAAAAAAAA---- -----AAAAAAAAAAAAAAAAA----- -----AAAAAAAAAAAAAAAAA----- -------AAAAAAAAAAAAAA------ -------AAAAAAAAAAAAAA------ --------AAAAAAAAAAA-------- --------AAAAAAAAAAA-------- 
-AAAAAAAAAAAAAAAAAAAAAAAAA- -AAAAAAAAAAAAAAAAAAAAAAAAA- --AAAAAAAAAAAAAAAAAAAAAAA-- --AAAAAAAAAAAAAAAAAAAAAAA-- ---AAAAAAAAAAAAAAAAAAAAA--- ---AAAAAAAAAAAAAAAAAAAAA--- ----AAAAAAAAAAAAAAAAAAA---- ----AAAAAAAAAAAAAAAAAAA---- -----AAAAAAAAAAAAAAAAA----- -----AAAAAAAAAAAAAAAAA----- ------AAAAAAAAAAAAAAA------ ------AAAAAAAAAAAAAAA------ -------AAAAAAAAAAAAA------- -------AAAAAAAAAAAAA------- 
AAAAAAAAAAAAAAAAAAAAAAAAAAA AAAAAAAAAAAAAAAAAAAAAAAAAAA -AAAAAAAAAAAAAAAAAAAAAAAAA- -AAAAAAAAAAAAAAAAAAAAAAAAA- --AAAAAAAAAAAAAAAAAAAAAAA-- --AAAAAAAAAAAAAAAAAAAAAAA-- ---AAAAAAAAAAAAAAAAAAAAA--- ---AAAAAAAAAAAAAAAAAAAAA--- ----AAAAAAAAAAAAAAAAAAA---- ----AAAAAAAAAAAAAAAAAAA---- ------AAAAAAAAAAAAAAA------ ------AAAAAAAAAAAAAAA------ -------AAAAAAAAAAAAA------- -------AAAAAAAAAAAAA------- 
AAAAAAAAAAAAAAAAAAAAAAAAAAA AAAAAAAAAAAAAAAAAAAAAAAAAAA -AAAAAAAAAAAAAAAAAAAAAAAAA- -AAAAAAAAAAAAAAAAAAAAAAAAA- --AAAAAAAAAAAAAAAAAAAAAAA-- --AAAAAAAAAAAAAAAAAAAAAAA-- ---AAAAAAAAAAAAAAAAAAAAA--- ---AAAAAAAAAAAAAAAAAAAAA--- ----AAAAAAAAAAAAAAAAAAA---- ----AAAAAAAAAAAAAAAAAAA---- -----AAAAAAAAAAAAAAAAA----- -----AAAAAAAAAAAAAAAAA----- ------AAAAAAAAAAAAAAA------ ------AAAAAAAAAAAAAAA------ 
AAAAAAAAAAAAAAAAAAAAAAAAAAA AAAAAAAAAAAAAAAAAAAAAAAAAAA -AAAAAAAAAAAAAAAAAAAAAAAAA- -AAAAAAAAAAAAAAAAAAAAAAAAA- --AAAAAAAAAAAAAAAAAAAAAAA-- --AAAAAAAAAAAAAAAAAAAAAAA-- ---AAAAAAAAAAAAAAAAAAAAA--- ---AAAAAAAAAAAAAAAAAAAAA--- ----AAAAAAAAAAAAAAAAAAA---- ----AAAAAAAAAAAAAAAAAAA---- -----AAAAAAAAAAAAAAAAA----- -----AAAAAAAAAAAAAAAAA----- ------AAAAAAAAAAAAAAA------ ------AAAAAAAAAAAAAAA------ 
AAAAAAAAAAAAAAAAAAAAAAAAAAA AAAAAAAAAAAAAAAAAAAAAAAAAAA -AAAAAAAAAAAAAAAAAAAAAAAAA- -AAAAAAAAAAAAAAAAAAAAAAAAA- --AAAAAAAAAAAAAAAAAAAAAAA-- --AAAAAAAAAAAAAAAAAAAAAAA-- ---AAAAAAAAAAAAAAAAAAAAA--- ---AAAAAAAAAAAAAAAAAAAAA--- ----AAAAAAAAAAAAAAAAAAA---- ----AAAAAAAAAAAAAAAAAAA---- -----AAAAAAAAAAAAAAAAA----- -----AAAAAAAAAAAAAAAAA----- ------AAAAAAAAAAAAAAA------ ------AAAAAAAAAAAAAAA------ 
AAAAAAAAAAAAAAAAAAAAAAAAAAA AAAAAAAAAAAAAAAAAAAAAAAAAAA -AAAAAAAAAAAAAAAAAAAAAAAAA- -AAAAAAAAAAAAAAAAAAAAAAAAA- --AAAAAAAAAAAAAAAAAAAAAAA-- --AAAAAAAAAAAAAAAAAAAAAAA-- ---AAAAAAAAAAAAAAAAAAAAA--- ---AAAAAAAAAAAAAAAAAAAAA--- ----AAAAAAAAAAAAAAAAAAA---- ----AAAAAAAAAAAAAAAAAAA---- -----AAAAAAAAAAAAAAAAA----- -----AAAAAAAAAAAAAAAAA----- ------AAAAAAAAAAAAAAA------ ------AAAAAAAAAAAAAAA------ 
AAAAAAAAAAAAAAAAAAAAAAAAAAA AAAAAAAAAAAAAAAAAAAAAAAAAAA -AAAAAAAAAAAAAAAAAAAAAAAAA- -AAAAAAAAAAAAAAAAAAAAAAAAA- --AAAAAAAAAAAAAAAAAAAAAAA-- --AAAAAAAAAAAAAAAAAAAAAAA-- ---AAAAAAAAAAAAAAAAAAAAA--- ---AAAAAAAAAAAAAAAAAAAAA--- ----AAAAAAAAAAAAAAAAAAA---- ----AAAAAAAAAAAAAAAAAAA---- -----AAAAAAAAAAAAAAAAA----- -----AAAAAAAAAAAAAAAAA----- ------AAAAAAAAAAAAAAA------ ------AAAAAAAAAAAAAAA------ 
AAAAAAAAAAAAAAAAAAAAAAAAAAA AAAAAAAAAAAAAAAAAAAAAAAAAAA -AAAAAAAAAAAAAAAAAAAAAAAAA- -AAAAAAAAAAAAAAAAAAAAAAAAA- --AAAAAAAAAAAAAAAAAAAAAAA-- --AAAAAAAAAAAAAAAAAAAAAAA-- ---AAAAAAAAAAAAAAAAAAAAA--- ---AAAAAAAAAAAAAAAAAAAAA--- ----AAAAAAAAAAAAAAAAAAA---- ----AAAAAAAAAAAAAAAAAAA---- ------AAAAAAAAAAAAAAA------ ------AAAAAAAAAAAAAAA------ -------AAAAAAAAAAAAA------- -------AAAAAAAAAAAAA------- 
-AAAAAAAAAAAAAAAAAAAAAAAAA- -AAAAAAAAAAAAAAAAAAAAAAAAA- --AAAAAAAAAAAAAAAAAAAAAAA-- --AAAAAAAAAAAAAAAAAAAAAAA-- ---AAAAAAAAAAAAAAAAAAAAA--- ---AAAAAAAAAAAAAAAAAAAAA--- ----AAAAAAAAAAAAAAAAAAA---- ----AAAAAAAAAAAAAAAAAAA---- -----AAAAAAAAAAAAAAAAA----- -----AAAAAAAAAAAAAAAAA----- ------AAAAAAAAAAAAAAA------ ------AAAAAAAAAAAAAAA------ -------AAAAAAAAAAAAA------- -------AAAAAAAAAAAAA------- 
-AAAAAAAAAAAAAAAAAAAAAAAAA- -AAAAAAAAAAAAAAAAAAAAAAAAA- --AAAAAAAAAAAAAAAAAAAAAAA-- --AAAAAAAAAAAAAAAAAAAAAAA-- ---AAAAAAAAAAAAAAAAAAAAA--- ---AAAAAAAAAAAAAAAAAAAAA--- ----AAAAAAAAAAAAAAAAAAA---- ----AAAAAAAAAAAAAAAAAAA---- -----AAAAAAAAAAAAAAAAA----- -----AAAAAAAAAAAAAAAAA----- -------AAAAAAAAAAAAA------- -------AAAAAAAAAAAAA------- --------AAAAAAAAAAA-------- --------AAAAAAAAAAA-------- 
-AAAAAAAAAAAAAAAAAAAAAAAAA- -AAAAAAAAAAAAAAAAAAAAAAAAA- ---AAAAAAAAAAAAAAAAAAAAA--- ---AAAAAAAAAAAAAAAAAAAAA--- ----AAAAAAAAAAAAAAAAAAA---- ----AAAAAAAAAAAAAAAAAAA---- -----AAAAAAAAAAAAAAAAA----- -----AAAAAAAAAAAAAAAAA----- ------AAAAAAAAAAAAAAA------ ------AAAAAAAAAAAAAAA------ -------AAAAAAAAAAAAA------- -------AAAAAAAAAAAAA------- ---------AAAAAAAAA--------- ---------AAAAAAAAA--------- 
--AAAAAAAAAAAAAAAAAAAAAAA-- --AAAAAAAAAAAAAAAAAAAAAAA-- ---AAAAAAAAAAAAAAAAAAAAA--- ---AAAAAAAAAAAAAAAAAAAAA--- ----AAAAAAAAAAAAAAAAAAA---- ----AAAAAAAAAAAAAAAAAAA---- ------AAAAAAAAAAAAAAA------ ------AAAAAAAAAAAAAAA------ -------AAAAAAAAAAAAA------- -------AAAAAAAAAAAAA------- ---------AAAAAAAAA--------- ---------AAAAAAAAA--------- -----------AAAAA----------- -----------AAAAA----------- 
---AAAAAAAAAAAAAAAAAAAAA--- ---AAAAAAAAAAAAAAAAAAAAA--- ----AAAAAAAAAAAAAAAAAAA---- ----AAAAAAAAAAAAAAAAAAA---- -----AAAAAAAAAAAAAAAAA----- -----AAAAAAAAAAAAAAAAA----- -------AAAAAAAAAAAAA------- -------AAAAAAAAAAAAA------- --------AAAAAAAAAAA-------- --------AAAAAAAAAAA-------- -----------AAAAA----------- -----------AAAAA----------- --------------------------- --------------------------- 
---AAAAAAAAAAAAAAAAAAAAA--- ---AAAAAAAAAAAAAAAAAAAAA--- -----AAAAAAAAAAAAAAAAA----- -----AAAAAAAAAAAAAAAAA----- ------AAAAAAAAAAAAAAA------ ------AAAAAAAAAAAAAAA------ --------AAAAAAAAAAA-------- --------AAAAAAAAAAA-------- ----------AAAAAAA---------- ----------AAAAAAA---------- --------------------------- --------------------------- --------------------------- --------------------------- 
----AAAAAAAAAAAAAAAAAAA---- ----AAAAAAAAAAAAAAAAAAA---- ------AAAAAAAAAAAAAAA------ ------AAAAAAAAAAAAAAA------ --------AAAAAAAAAAA-------- --------AAAAAAAAAAA-------- ----------AAAAAAA---------- ----------AAAAAAA---------- --------------------------- --------------------------- --------------------------- --------------------------- --------------------------- --------------------------- 
------AAAAAAAAAAAAAAA------ ------AAAAAAAAAAAAAAA------ --------AAAAAAAAAAA-------- --------AAAAAAAAAAA-------- ----------AAAAAAA---------- ----------AAAAAAA---------- --------------------------- --------------------------- --------------------------- --------------------------- --------------------------- --------------------------- --------------------------- --------------------------- 
-------AAAAAAAAAAAAA------- -------AAAAAAAAAAAAA------- ----------AAAAAAA---------- ----------AAAAAAA---------- --------------------------- --------------------------- --------------------------- --------------------------- --------------------------- --------------------------- --------------------------- --------------------------- --------------------------- --------------------------- 
----------AAAAAAA---------- ----------AAAAAAA---------- --------------------------- --------------------------- --------------------------- --------------------------- --------------------------- --------------------------- --------------------------- --------------------------- --------------------------- --------------------------- --------------------------- --------------------------- 
