model
size = 31 29 20, scale = 0.05, origin = -y
material 
  colors = A:#A100FF B:#E100FF C:#FF44D6 D:#FAFF7F E:#7F00FF F:#B200FF G:#FF7B1D H:#F3F3F3 I:#D21EFF J:#5900FF K:#172BFF L:#006AFF M:#FF8737 N:#FBFF2B O:#0FB P:#00FEFF Q:#00BFFF R:#FFA113 S:#FFCB2E T:#FFB23F U:#FFF V:#0B0B0B W:#005D72 X:#0A0A0A Y:#FDFDFD Z:#008780 Aa:#00AF7D Ab:#00CE97 Ac:#BCBCBC
voxels
- - - - - U I I I I - - - - - - F F F F F - - - - - - - - - -   - - - - - I - I - I - - - - - - F - F - F - - - - - - - - - -   - - - - - - - - - - - - - - - - - - - - - - - - - - - - - - -   - - - - - - - - - - - - - - - - - - - - - - - - - - - - - - -   - - - - - - - - - - - - - - - - - - - - - - - - - - - - - - -   - - - - - - - - - - - - - - - - - - - - - - - - - - - - - - -   - - - - - - - - - - - - - - - - - - - - - - - - - - - - - - -   - - - - - - - - - - - - - - - - - - - - - - - - - - - - - - -   - - - - - - - - - - - - - - - - - - - - - - - - - - - - - - -   - - - - - - - - - - - - - - - - - - - - - - - - - - - - - - -   - - - - - - - - - - - - - - - - - - - - - - - - - - - - - - -   - - - - - - - - - - - - - - - - - - - - - - - - - - - - - - -   - - - - - - - - - - - - - - - - - - - - - - - - - - - - - - -   - - - - - - - - - - - - - - - - - - - - - - - - - - - - - - -   - - - - - - - - - - - - - - - - - - - - - - - - - - - - - - -   - - - - - - - - - - - - - - - - - - - - - - - - - - - - - - -   - - - - - - - - - - - - - - - - - - - - - - - - - - - - - - -   - - - - - - - - - - - - - - - - - - - - - - - - - - - - - - -   - - - - - - - - - - - - - - - - - - - - - - - - - - - - - - -   - - - - - - - - - - - - - - - - - - - - - - - - - - - - - - -   - - - - - - - - - - - - - - - - - - - - - - - - - - - - - - -   - - - - - - - - - - - - - - - - - - - - - - - - - - - - - - -   - - - - - - - - - - - - - - - - - - - - - - - - - - - - - - -   - - - - - - - - - - - - - - - - - - - - - - - - - - - - - - -   - - - - - - - - - - - - - - - - - - - - - - - - - - - - - - -   - - - - - - - - - - - - - - - - - - - - - - - - - - - - - - -   - - - - - - - - - - - - - - - - - - - - - - - - - - - - - - -   - - - - - - - - - - - - - - - - - - - - - - - - - - - - - - -   - - - - - - - - - - - - - - - - - - - - - - - - - - - - - - -   
- - - - - I I I I I - - - - - - F F F F F - - - - - - - - - -   - - - - - I I I I I - - - - - - F F F F F - - - - - - - - - -   - - - - - - - - - - - - - - - - - - - - - - - - - - - - - - -   - - - - - - - - - - - - - - - - - - - - - - - - - - - - - - -   - - - - - - - - - - - - - - - - - - - - - - - - - - - - - - -   - - - - - - - - - - - - - - - - - - - - - - - - - - - - - - -   - - - - - - - - - - - - - - - - - - - - - - - - - - - - - - -   - - - - - - - - - - - - - - - - - - - - - - - - - - - - - - -   - - - - - - - - - - - - - - - - - - - - - - - - - - - - - - -   - - - - - - - - - - - - - - - - - - - - - - - - - - - - - - -   - - - - - - - - - - - - - - - - - - - - - - - - - - - - - - -   - - - - - - - - - - - - - - - - - - - - - - - - - - - - - - -   - - - - - - - - - - - - - - - - - - - - - - - - - - - - - - -   - - - - - - - - - - - - - - - - - - - - - - - - - - - - - - -   - - - - - - - - - - - - - - - - - - - - - - - - - - - - - - -   - - - - - - - - - - - - - - - - - - - - - - - - - - - - - - -   - - - - - - - - - - - - - - - - - - - - - - - - - - - - - - -   - - - - - - - - - - - - - - - - - - - - - - - - - - - - - - -   - - - - - - - - - - - - - - - - - - - - - - - - - - - - - - -   - - - - - - - - - - - - - - - - - - - - - - - - - - - - - - -   - - - - - - - - - - - - - - - - - - - - - - - - - - - - - - -   - - - - - - - - - - - - - - - - - - - - - - - - - - - - - - -   - - - - - - - - - - - - - - - - - - - - - - - - - - - - - - -   - - - - - - - - - - - - - - - - - - - - - - - - - - - - - - -   - - - - - - - - - - - - - - - - - - - - - - - - - - - - - - -   - - - - - - - - - - - - - - - - - - - - - - - - - - - - - - -   - - - - - - - - - - - - - - - - - - - - - - - - - - - - - - -   - - - - - - - - - - - - - - - - - - - - - - - - - - - - - - -   - - - - - - - - - - - - - - - - - - - - - - - - - - - - - - -   
- - - - - I I I I - - - - - - - - F F F F - - - - - - - - - -   - - - - - I I I I - - - - - - - - F F F F - - - - - - - - - -   - - - - - A A A U - - - - - - - - B B B B - - - - - - - - - -   - - - - - A A A A - - - - - - - - B B B B - - - - - - - - - -   - - - - - - A A A - - - - - - - - B B B - - - - - - - - - - -   - - - - - - U A A - - - - - - - - B B B - - - - - - - - - - -   - - - - - - E E E - - - - - - - - C C C - - - - - - - - - - -   - - - - - - - - - - - - - - - - - - - - - - - - - - - - - - -   - - - - - - - - - - - - - - - - - - - - - - - - - - - - - - -   - - - - - - - - - - - - - - - - - - - - - - - - - - - - - - -   - - - - - - - - - - - - - - - - - - - - - - - - - - - - - - -   - - - - - - - - - - - - - - - - - - - - - - - - - - - - - - -   - - - - - - - - - - - - - - - - - - - - - - - - - - - - - - -   - - - - - - - - - - - - - - - - - - - - - - - - - - - - - - -   - - - - - - - - - - - - - - - - - - - - - - - - - - - - - - -   - - - - - - - - - - - - - - - - - - - - - - - - - - - - - - -   - - - - - - - - - - - - - - - - - - - - - - - - - - - - - - -   - - - - - - - - - - - - - - - - - - - - - - - - - - - - - - -   - - - - - - - - - - - - - - - - - - - - - - - - - - - - - - -   - - - - - - - - - - - - - - - - - - - - - - - - - - - - - - -   - - - - - - - - - - - - - - - - - - - - - - - - - - - - - - -   - - - - - - - - - - - - - - - - - - - - - - - - - - - - - - -   - - - - - - - - - - - - - - - - - - - - - - - - - - - - - - -   - - - - - - - - - - - - - - - - - - - - - - - - - - - - - - -   - - - - - - - - - - - - - - - - - - - - - - - - - - - - - - -   - - - - - - - - - - - - - - - - - - - - - - - - - - - - - - -   - - - - - - - - - - - - - - - - - - - - - - - - - - - - - - -   - - - - - - - - - - - - - - - - - - - - - - - - - - - - - - -   - - - - - - - - - - - - - - - - - - - - - - - - - - - - - - -   
- - - - - I I I I - - - - - - - - F F F F - - - - - - - - - -   - - - - - I I I I - - - - - - - - F F F F - - - - - - - - - -   - - - - - A A A A - - - - - - - - B B B B - - - - - - - - - -   - - - - - A A A A - - - - - - - - B B B B - - - - - - - - - -   - - - - - A A A A - W W W P P P - B B B B - - - - - - - - - -   - - - - - A A A A W - - - - - - P B B B B - - - - - - - - - -   - - - - - - E E E - - W W A A - - C C C - - - - - - - - - - -   - - - - - - - - Z - Z Z Z J J J - P - - - - - - - - - - - - -   - - - - - - - - Aa- AaAaAaL L L - P - - - - - - - - - - - - -   - - - - - - - - Ab- AbAbAbQ Q Q - P - - - - - - - - - - - - -   - - - - - - - - O - - O O P P - - P - - - - - - - - - - - - -   - - - - - - - - - O - - - - - - P - - - - - - - - - - - - - -   - - - - - - - - - - O O O P P P - - - - - - - - - - - - - - -   - - - - - - - - - - - - - - - - - - - - - - - - - - - - - - -   - - - - V V - - - - - - - - - - - - - - V V - - - - - - - - -   - - - - - - V V - - - - - - - - - - V V - - - - - - - - - - -   - - - - - - - - - - - - - - - - - - - - - - - - - - - - - - -   - - - - - V V - - - - - - - - - - - - V V - - - - - - - - - -   - - V V V - - - - - - - V V - - - V - - - V V - - - - - - - -   - - - - - - - - - - - V V V V - - - V - - - - - - - - - - - -   - - - - - - - - U U U - - - - U U U - V V V - - - - - - - - -   - - - - - - - U L Q Q U - - U P P Q U - - - - - - - - - - - -   - - - - - - - U V V L U - - U Q V V U - - - - - - - - - - - -   - - - - - - - L U V U U - - U U V AcU - - - - - - - - - - - -   - - - - - - - - L L L - - - - U U U - - - - - - - - - - - - -   - - - - - - - - - - - - - - - - - - - - - - - - - - - - - - -   - - - - - - - - - - - - - - - - - - - - - - - - - - - - - - -   - - - - - - - - - - - - - - - - - - - - - - - - - - - - - - -   - - - - - - - - - - - - - - - - - - - - - - - - - - - - - - -   
- - - - - I I I I I I I I F F F F F F F F - - - - - - - - - -   - - - - - I I I I I I I I F F F F F F F F - - - - - - - - - -   - - - - - A A A A A A A P B B B B B B B B - - - - - - - - - -   - - - - - A A A A A A A A B B B B B B B B - - - - - - - - - -   - - - - - A A A A A A A A B B B B B B B B - - - - - - - - - -   - - - - - A A A A A A A A B B B B B B B B - - - - - - - - - -   - - - - - E E E E E E E E C C C C C C C C - - - - - - - - - -   - - - - - - E E E E E E E C C C C C C C - - - - - - - - - - -   - - - - - - E E E E E U E C C C C C C C - - - - - - - - - - -   - - - - - - P E E E E E E C C C C C C C - - - - - - - - - - -   - - - - - - J J J J J J J G G G G G G G - - - - - - - - - - -   - - - - - - J J J J J J J G G G G G G G - - - - - - - - - - -   - - - - - - - J J J J P J G G G G G G - - - - - - - - - - - -   - - - - - - - U K K K K K M M M M M M - - - - - - - - - - - -   - - - - - - K K K K K K V V M M M M M M - - - - - - - - - - -   - - - - - - K Y K K K K K M M M M M Y M - - - - - - - - - - -   - - - - L L L L L L L V V V V R R R R R R R - - - - - - - - -   - - - - - L L L L U L L L R R V R R R R R - - - - - - - - - -   - - - - - L L L L L L L L V R R R Y R R R - - - - - - - - - -   - - - - - - Q Q Q Q Q Q Q V V T T T Y T - - - - - - - - - - -   - - - - - - U Q Q Q Q Q Q T T X X X T T - - - - - - - - - - -   - - - - - - P P P P P P P S N N N N S S - - - - - - - - - - -   - - - - - - P P P P P P P S N N N N S S - - - - - - - - - - -   - - - - - - - P P P P P P N N N N N N - - - - - - - - - - - -   - - - - - - - O O O O O O N N X X N N - - - - - - - - - - - -   - - - - - - - - - O U O O D D D D - - - - - - - - - - - - - -   - - - - - - - - - - - - - - - - - - - - - - - - - - - - - - -   - - - - - - - - - - - - - - - - - - - - - - - - - - - - - - -   - - - - - - - - - - - - - - - - - - - - - - - - - - - - - - -   
- - - - I I I I I I I I I F F F F F F F F F - - - - - - - - -   - - - - I I I I I I I I I F F F F F F B B F - - - - - - - - -   - - - - A A A A A A A A A B B B B B B B B B - - - - - - - - -   - - - - U A A A A A A A A B B B B B B B B B - - - - - - - - -   - - - - A A A A A A A A A B B B B B B B B B - - - - - - - - -   - - - - A A A A A A A A A B B B B B B B B B - - - - - - - - -   - - - - - E E E E E E E E C C C C C C C C - - - - - - - - - -   - - - - - E E E E E E E E C C C C C C C C - - - - - - - - - -   - - - - - E E E E E E E E C C C C C C C C - - - - - - - - - -   - - - - - E E E E E E E E C C C C C C C C - - - - - - - - - -   - - - - - J J J J J J J J G G G G G G G G - - - - - - - - - -   - - - - - J J J J J J J J G G G G G G G G - - - - - - - - - -   - - - - - - J J J J J J J G G G G G G G - - - - - - - - - - -   - - - - - - K K K K K K K M M M M M M M - - - - - - - - - - -   - - - - - - K K K K K K K D D D D D D M - - - - - - - - - - -   - - - - - - K K K K K K K D D D D D D M - - - - - - - - - - -   - - - - L L L L L L L L L D D D D D D R R R - - - - - - - - -   - - - - - L L L L L L L H D D D D D D R R - - - - - - - - - -   - - - - - L L L L L L L H D D D D D D R R - - - - - - - - - -   - - - - - - Q Q Q Q Q Q H D D D D D D T - - - - - - - - - - -   - - - - - - Q Q Q Q Q Q H D D D D D D T - - - - - - - - - - -   - - - - - - P P P P P P H N N N N N S S - - - - - - - - - - -   - - - - - - P P P P P P H N N N N N S S - - - - - - - - - - -   - - - - - - - H H H H H H N N N N N N - - - - - - - - - - - -   - - - - - - - O H O O O O D D D D D N - - - - - - - - - - - -   - - - - - - - - O O O O O D D D D D - - - - - - - - - - - - -   - - - - - - - - O - - - - - - - - D - - - - - - - - - - - - -   - - - - - - - - - - - - - - - - - - - - - - - - - - - - - - -   - - - - - - - - - - - - - - - - - - - - - - - - - - - - - - -   
- - - - I I I I I I I I I F F F F F F F F F - - - - - - - - -   - - - - I I I I I I I I I F F F F F F B B F - - - - - - - - -   - - - - A A A A A A A A A D D D D D D B B B - - - - - - - - -   - - - - A A A A A A A A A D D D D D D B B B - - - - - - - - -   - - - - A A A A A A A A A D D D D D D B B B - - - - - - - - -   - - - - A A A A A A A A A D D D D D D B B B - - - - - - - - -   - - - - E E E E E E E E E C C C C C C C C C - - - - - - - - -   - - - - E E E E E E E E E C C C C C C C C C - - - - - - - - -   - - - - E E E E E E E E E C C C C C C C C C - - - - - - - - -   - - - - - E E E E E E E E D D D D D D D C - - - - - - - - - -   - - - - - J J J J J J J J G G G G G G G G - - - - - - - - - -   - - - - - J J J J J J J J G G G G G G G G - - - - - - - - - -   - - - - - J J J J J J J J G G G G G G G G - - - - - - - - - -   - - - - - - K K K K K K K M M M M M M M - - - - - - - - - - -   - - - - - - K K K K K K K D D D D D D M - - - - - - - - - - -   - - - - - - K K K K K K K D D D D D D M - - - - - - - - - - -   - - - - - - L L L L L L L D D D D D D R - - - - - - - - - - -   - - - - - - L L L L L L H D D D D D D R - - - - - - - - - - -   - - - - - - L L L L L L H D D D D D D R - - - - - - - - - - -   - - - - - - Q Q Q Q Q Q H D D D D D D T - - - - - - - - - - -   - - - - - - Q Q Q Q Q Q H D D D D D D T - - - - - - - - - - -   - - - - - - P P P P P P H N N N N N S S - - - - - - - - - - -   - - - - - - P P P P P P H N N N N N S S - - - - - - - - - - -   - - - - - - O H H H H H H N N N N N N N - - - - - - - - - - -   - - - - - O Q O H O O O O D D D D D D S N - - - - - - - - - -   - - - - - O Q Q H O O O O D D D D D S S D - - - - - - - - - -   - - - - - O Q Q O - - - O - - - - D S S D - - - - - - - - - -   - - - - - O Q O O - - - - - - - - D D S D - - - - - - - - - -   - - - - - O O - - - - - - - - - - - - D D - - - - - - - - - -   
- - - - I I I I I I I I I F F F F F F F F F - - - - - - - - -   - - - - I I I I I I I I I F F F F F F B B F - - - - - - - - -   - - - - A A A A A A A A A D D D D D D B B B - - - - - - - - -   - - - - A A A A A A A A A D D D D D D B B B - - - - - - - - -   - - - - A A A A A A A A A D D D D D D B B B - - - - - - - - -   - - - - A A A A A A A A A D D D D D D B B B - - - - - - - - -   - - - - E E E E E E E E E C C C C C C C C C - - - - - - - - -   - - - - E E E E E E E E E C C C C C C C C C - - - - - - - - -   - - - - E E E E E E E E E C C C C C C C C C - - - - - - - - -   - - - - - E E E E E E E E D D D D D D D C - - - - - - - - - -   - - - - - J J J J J J J J G G G G G G G G - - - - - - - - - -   - - - - - J J J J J J J J G G G G G G G G - - - - - - - - - -   - - - - - J J J J J J J J G G G G G G G G - - - - - - - - - -   - - - - - K K K K K K K K M M M M M M M M - - - - - - - - - -   - - - - - - K K K K K K K D D D D D D M - - - - - - - - - - -   - - - - - - K K K K K K K D D D D D D M - - - - - - - - - - -   - - - - - - L L L L L L L D D D D D D R - - - - - - - - - - -   - - - - - - L L L L L L H D D D D D D R - - - - - - - - - - -   - - - - - - U L L L L L H D D D D D D R - - - - - - - - - - -   - - - - - - Q Q Q Q Q Q H D D D D D D T - - - - - - - - - - -   - - - - - - Q Q Q Q Q Q H D D D D D D T - - - - - - - - - - -   - - - - - - P P P P P P H N N N N N S S - - - - - - - - - - -   - - - - - - P P P P P P H N N N N N S S - - - - - - - - - - -   - - - - - - O O O O O O H N N N N N N N - - - - - - - - - - -   - - - - - O O O O O O O O D D D D D D N N - - - - - - - - - -   - - - - - O O O O O O O O D D D D D D D D - - - - - - - - - -   - - - - - O O O O - - O O D D - - D D D D - - - - - - - - - -   - - - - - O O O O - - - O D - - - D D D D - - - - - - - - - -   - - - - - O O - - - - - - - D - - - - D D - - - - - - - - - -   
- - - - I I I I I I I I I F F F F F F F F F - - - - - - - - -   - - - - I I I I I I I I I F F F F F F B B F - - - - - - - - -   - - - - A A A A A A A A A D D D D D D B B B - - - - - - - - -   - - - - A A A A A A A A A D D D D D D B B B - - - - - - - - -   - - - - A A A A A A A A A D D D D D D B B B - - - - - - - - -   - - - - A A A A A A A A A D D D D D D B B B - - - - - - - - -   - - - - E E E E E E E E E C C C C C C C C C - - - - - - - - -   - - - - E E E E E E E E E C C C C C C C C C - - - - - - - - -   - - - - E E E E E E E E E C C C C C C C C C - - - - - - - - -   - - - - - E E E E E E E E D D D D D D D C - - - - - - - - - -   - - - - - J J J J J J J J G G G G G G G G - - - - - - - - - -   - - - - - U J J J J J J J G G G G G G G G - - - - - - - - - -   - - - - - J J J J J J J J G G G G G G G G - - - - - - - - - -   - - - - - K K K K K K K K M M M M M M M M - - - - - - - - - -   - - - - - - K K K K K K K D D D D D D M - - - - - - - - - - -   - - - - - - K K K K K K K D D D D D D M - - - - - - - - - - -   - - - - - - L L L L L L L D D D D D D R - - - - - - - - - - -   - - - - - - L L L L L L H D D D D D D R - - - - - - - - - - -   - - - - - - L L L L L L H D D D D D D R - - - - - - - - - - -   - - - - - - Q Q Q Q Q Q H D D D D D D T - - - - - - - - - - -   - - - - - - Q Q Q Q Q Q H D D D D D D T - - - - - - - - - - -   - - - - - - P P P P P P H N N N N N S S - - - - - - - - - - -   - - - - - - P P P P P P H N N N N N S S - - - - - - - - - - -   - - - - - - - O O O O O H N N N N N N - - - - - - - - - - - -   - - - - - - - O O O O O O N N N N N N - - - - - - - - - - - -   - - - - - - - - - O O O O D D D D - - - - - - - - - - - - - -   - - - - - - - - - - - O O D D - - - - - - - - - - - - - - - -   - - - - - - - - - - - - O D D - - - - - - - - - - - - - - - -   - - - - - - - - - - - - O - D - - - - - - - - - - - - - - - -   
U I I I I I I I I I I I I F F F F F F F F F F F F F - - - - -   I I I I I I I I I I I I I F F F F F F B B F F F F F - - - - -   - - A A A A A A A A A A A H H H H H H B B B B B - - - - - - -   - - A A A A A A A A A A A H H H H H H B B B B B - - - - - - -   - - P A A A A A A A A A A H H H H H H B B B B B - - - - - - -   - - A A A A A A A A A A A H H H H H H B B B B B - - - - - - -   - - - E E E E E E E E E E C C C C C C C C C C - - - - - - - -   - - - - E E E E E E E E E C C C C C C C C C - - - - - - - - -   - - - - E E E E E E E E E C C C C C C C C C - - - - - - - - -   - - - - - E E E E E E E E H H H H H H H C - - - - - - - - - -   - - - - - J J J J J J J J G G G G G G G G - - - - - - - - - -   - - - - - J J J J J J J J G G G G G G G G - - - - - - - - - -   - - - - - J J J J J J J J G G G G G G G G - - - - - - - - - -   - - - - - K K K K K K K K M M M M M M M M - - - - - - - - - -   - - - - - - K K K K K K K H H H H H H M - - - - - - - - - - -   - - - - - - K K K K K K K H H H H H H M - - - - - - - - - - -   - - - - - - L L L L L L L H H H H H H R - - - - - - - - - - -   - - - - - - L L L L L L H H H H H H H R - - - - - - - - - - -   - - - - - - L L L L L L H H H H H H H R - - - - - - - - - - -   - - - - - - Q Q Q Q Q Q H H H H H H H T - - - - - - - - - - -   - - - - - - Q Q Q Q Q Q H H H H H H H T - - - - - - - - - - -   - - - - - - P P P P P P H N N N N N S S - - - - - - - - - - -   - - - - - - P P P P P P H N N N N N S S - - - - - - - - - - -   - - - - - - - O O O O O H N N N N N N - - - - - - - - - - - -   - - - - - - - O O O O O O N N N N N N - - - - - - - - - - - -   - - - - - - - - - O O O O D D D D - - - - - - - - - - - - - -   - - - - - - - - - - - - - - - - - - - - - - - - - - - - - - -   - - - - - - - - - - - - - - - - - - - - - - - - - - - - - - -   - - - - - - - - - - - - - - - - - - - - - - - - - - - - - - -   
I I I I I I I I I I I I I F F F F F F F F F F F F F - - - - -   I I I I I I I I I I I I I F F F F F F B B B B B F F - - - - -   - - A A A A A A A A A A A H H H H H H B B B B B - - - - - - -   - - A A A A A A A A A A A H H H H H H B B B B B - - - - - - -   - - A A A A A A A A A A A H H H H H H B B B B B - - - - - - -   - - A A A A A A A A A A A H H H H H H B B B B B - - - - - - -   - - E E E E E E E E E E E C C C C C C C C C C C - - - - - - -   - - - - E E E E E E E E E C C C C C C C C C - - - - - - - - -   - - - - E E E E E E E E E C C C C C C C C C - - - - - - - - -   - - - - - E E E E E E E E H H H H H H H C - - - - - - - - - -   - - - - - J J J J J J J J G G G G G G G G - - - - - - - - - -   - - - - - J J J J J J J J G G G G G G G G - - - - - - - - - -   - - - - - J J J J J J J J G G G G G G G G - - - - - - - - - -   - - - - - K K K K K K K K H H H H H H H M - - - - - - - - - -   - - - - - - K K K K K K K H H H H H H M - - - - - - - - - - -   - - - - - - K K K K K K K H H H H H H M - - - - - - - - - - -   - - - - - - L L L L L L L H H H H H H R - - - - - - - - - - -   - - - - - - L L L L L L H H H H H H H R - - - - - - - - - - -   - - - - - - L L L L L L H H H H H H H R - - - - - - - - - - -   - - - - - - Q Q Q Q Q Q H H H H H H H T - - - - - - - - - - -   - - - - - - Q Q Q Q Q Q H H H H H H H T - - - - - - - - - - -   - - - - - - P P P P P P H N N N N N S S - - - - - - - - - - -   - - - - - - U P P P P P H N N N N N S S - - - - - - - - - - -   - - - - - - - O O O O O H N N N N N N - - - - - - - - - - - -   - - - - - - - O O O O O O N N N N N N - - - - - - - - - - - -   - - - - - - - - - O O O O D D D D - - - - - - - - - - - - - -   - - - - - - - - - - - - - - - - - - - - - - - - - - - - - - -   - - - - - - - - - - - - - - - - - - - - - - - - - - - - - - -   - - - - - - - - - - - - - - - - - - - - - - - - - - - - - - -   
I I I I I I I I I I I I I F F F F F F F F F F F F F - - - - -   I I I I I I I I I I I I I F F F F F F B B B B B F F - - - - -   - - A A A A A A A A A A A H H H H H H B B B B B - - - - - - -   - - A A A A A A A A A A A H H H H H H B B B B B - - - - - - -   - - A A A A A A A A A A A H H H H H H B B B B B - - - - - - -   - - A A A A A A A A A A A H H H H H H B B B B B - - - - - - -   - - E E E E E E E E E E E C C C C C C C C C C C - - - - - - -   - - - - E E E E E E E E E C C C C C C C C C - - - - - - - - -   - - - - E E E E E E E E E C C C C C C C C C - - - - - - - - -   - - - - - E E E E E E E E C C C C C C C C - - - - - - - - - -   - - - - - J J J J J J J J G G G G G G G G - - - - - - - - - -   - - - - - J J J J J J J J G G G G G G G G - - - - - - - - - -   - - - - - J J J J J J J J G G G G G G G G - - - - - - - - - -   - - - - - U K K K K K K K M M M M M M M M - - - - - - - - - -   - - - - - - K K K K K K K M M M M M M M - - - - - - - - - - -   - - - - - - K K K K K K K M M M M M M M - - - - - - - - - - -   - - - - - - L L L L L L L H H H H H H R - - - - - - - - - - -   - - - - - - L L L L L L H H H H H H H R - - - - - - - - - - -   - - - - - - L L L L L L H H H H H H H R - - - - - - - - - - -   - - - - - - Q Q Q Q Q Q H T T T T T T T - - - - - - - - - - -   - - - - - - Q Q Q Q Q Q H T T T T T T T - - - - - - - - - - -   - - - - - - P P P P P P H S S S S S S S - - - - - - - - - - -   - - - - - - P P P P P P H S S S S S S S - - - - - - - - - - -   - - - - - - - O O O O O H N N N N N N - - - - - - - - - - - -   - - - - - - - O O O O O O N N N N N N - - - - - - - - - - - -   - - - - - - - - - U O O O D D D D - - - - - - - - - - - - - -   - - - - - - - - - - - - - - - - - - - - - - - - - - - - - - -   - - - - - - - - - - - - - - - - - - - - - - - - - - - - - - -   - - - - - - - - - - - - - - - - - - - - - - - - - - - - - - -   
I I I I I I I I I I I I I F F F F F F F F F F F F F - - - - -   I I I I I I I I I I I I I F F F F F F F F F F F F F - - - - -   - - A A A A A A A A A A A H H H H H H B B B B B - - - - - - -   - - A A A A A A A A A A A H H B B B B B B B B B - - - - - - -   - - A A U A A A A A A A A H H B B B B B B B B B - - - - - - -   - - A A A A A A A A A A A B B B B B B B B B B B - - - - - - -   - - - E E E E E E E E E E C C C C C C C C C C - - - - - - - -   - - - - - E E E E E E E E C C C C C C C C - - - - - - - - - -   - - - - - E E E E E E E E C C C C C C C C - - - - - - - - - -   - - - - - U E E E E E E E C C C C C C C C - - - - - - - - - -   - - - - - J J J J J J J J G G G G G G G G - - - - - - - - - -   - - - - - J J J J J J J J G G G G G G G G - - - - - - - - - -   - - - - - J J J J J J J J G G G G G G G G - - - - - - - - - -   - - - - - - K K K K K K K M M M M M M M - - - - - - - - - - -   - - - - - - K K K K K K K M M M M M M M - - - - - - - - - - -   - - - - - - K K K K K K K M M M M M M M - - - - - - - - - - -   - - - - - - L U L L L L L R R R R R R R - - - - - - - - - - -   - - - - - - - L L L L L H R R R R R R - - - - - - - - - - - -   - - - - - - - L L L L L H R R R R R R - - - - - - - - - - - -   - - - - - - - Q Q Q Q Q H T T T T T T - - - - - - - - - - - -   - - - - - - - Q Q Q Q Q H T T T T T T - - - - - - - - - - - -   - - - - - - - P P P P P H S S S S S S - - - - - - - - - - - -   - - - - - - - P P P P P H S S S S S S - - - - - - - - - - - -   - - - - - - - - O O O O O N N N N N - - - - - - - - - - - - -   - - - - - - - - - O O O O N N N N - - - - - - - - - - - - - -   - - - - - - - - - - - - - - - - - - - - - - - - - - - - - - -   - - - - - - - - - - - - - - - - - - - - - - - - - - - - - - -   - - - - - - - - - - - - - - - - - - - - - - - - - - - - - - -   - - - - - - - - - - - - - - - - - - - - - - - - - - - - - - -   
- - - - - - I I I I I U I F F F F F F F - - - - - - - - - - -   - - - - - - I U I I I I I F F F F F F F - - - - - - - - - - -   - - - - - - A A A A A A A H B B B B B B - - - - - - - - - - -   - - - - - - A A A A A A A B B B B B B B - - - - - - - - - - -   - - - - - - A A A A A A A B B B B B B B - - - - - - - - - - -   - - - - - - A A A A A A A B B B B B B B - - - - - - - - - - -   - - - - - - E U E E E E E C C C C C C C - - - - - - - - - - -   - - - - - - E E E E E E E C C C C C C C - - - - - - - - - - -   - - - - - - E E E E E E E C C C C C C C - - - - - - - - - - -   - - - - - - E E E U E E E C C C C C C C - - - - - - - - - - -   - - - - - - J J J J J J J G G G G G G G - - - - - - - - - - -   - - - - - - - J J J J J J G G G G G G - - - - - - - - - - - -   - - - - - - - J J J J J J G G G G G G - - - - - - - - - - - -   - - - - - - - - K K K U K M M M M M - - - - - - - - - - - - -   - - - - - - - - - - - - - - - - - - - - - - - - - - - - - - -   - - - - - - - - - - - - - - - - - - - - - - - - - - - - - - -   - - - - - - - - - - - - - - - - - - - - - - - - - - - - - - -   - - - - - - - - - - L L L R R R - - - - - - - - - - - - - - -   - - - - - - - - - L L L L R R R R - - - - - - - - - - - - - -   - - - - - - - - - Q Q Q Q T T T T - - - - - - - - - - - - - -   - - - - - - - - - Q Q Q Q T T T T - - - - - - - - - - - - - -   - - - - - - - - - P U P P S S S S - - - - - - - - - - - - - -   - - - - - - - - - - P P P S S S - - - - - - - - - - - - - - -   - - - - - - - - - - - - - - - - - - - - - - - - - - - - - - -   - - - - - - - - - - - - - - - - - - - - - - - - - - - - - - -   - - - - - - - - - - - - - - - - - - - - - - - - - - - - - - -   - - - - - - - - - - - - - - - - - - - - - - - - - - - - - - -   - - - - - - - - - - - - - - - - - - - - - - - - - - - - - - -   - - - - - - - - - - - - - - - - - - - - - - - - - - - - - - -   
- - - - - - - - - - - - - - - - - - - - - - - - - - - - - - -   - - - - - - - - - - - - - - - - - - - - - - - - - - - - - - -   - - - - - - - - - - A A A B - - - - - - - - - - - - - - - - -   - - - - - - - - - - U A A B - - - - - - - - - - - - - - - - -   - - - - - - - - - - A A A B - - - - - - - - - - - - - - - - -   - - - - - - - - - - A A A B - - - - - - - - - - - - - - - - -   - - - - - - - - - - - - - - - - - - - - - - - - - - - - - - -   - - - - - - - - - - - - - - - - - - - - - - - - - - - - - - -   - - - - - - - - - - - - - - - - - - - - - - - - - - - - - - -   - - - - - - - - - - - - - - - - - - - - - - - - - - - - - - -   - - - - - - - - - - - - - - - - - - - - - - - - - - - - - - -   - - - - - - - - - - - - - - - - - - - - - - - - - - - - - - -   - - - - - - - - - - - - - - - - - - - - - - - - - - - - - - -   - - - - - - - - - - - - - - - - - - - - - - - - - - - - - - -   - - - - - - - - - - - - - - - - - - - - - - - - - - - - - - -   - - - - - - - - - - - - - - - - - - - - - - - - - - - - - - -   - - - - - - - - - - - - - - - - - - - - - - - - - - - - - - -   - - - - - - - - - - - - - - - - - - - - - - - - - - - - - - -   - - - - - - - - - - - - - - - - - - - - - - - - - - - - - - -   - - - - - - - - - - - - - - - - - - - - - - - - - - - - - - -   - - - - - - - - - - - - - - - - - - - - - - - - - - - - - - -   - - - - - - - - - - - - - - - - - - - - - - - - - - - - - - -   - - - - - - - - - - - - - - - - - - - - - - - - - - - - - - -   - - - - - - - - - - - - - - - - - - - - - - - - - - - - - - -   - - - - - - - - - - - - - - - - - - - - - - - - - - - - - - -   - - - - - - - - - - - - - - - - - - - - - - - - - - - - - - -   - - - - - - - - - - - - - - - - - - - - - - - - - - - - - - -   - - - - - - - - - - - - - - - - - - - - - - - - - - - - - - -   - - - - - - - - - - - - - - - - - - - - - - - - - - - - - - -   
- - - - - - - - - - - - - F F F F F F F - - - - - - - - - - -   - - - - - - - - - - - I I F F F F F F F F F - - - - - - - - -   - - - - - - - - - - A A A B B B B B B B B B B B - - - - - - -   - - - - - - - - - - A A A B - - - - B B B B B B B - - - - - -   - - - - - - - - - - A A A B - - - - - - - B B B B B - - - - -   - - - - - - - - - - A A A B - - - - - - - - - B B B B - - - -   - - - - - - - - - - - - - - - - - - - - - - - - C C C - - - -   - - - - - - - - - - - - - - - - - - - - - - - - - C C C - - -   - - - - - - - - - - - - - - - - - - - - - - - - - - C C C - -   - - - - - - - - - - - - - - - - - - - - - - - - - - - C C - -   - - - - - - - - - - - - - - - - - - - - - - - - - - - G G G -   - - - - - - - - - - - - - - - - - - - - - - - - - - - - G G -   - - - - - - - - - - - - - - - - - - - - - - - - - - - - G G -   - - - - - - - - - - - - - - - - - - - - - - - - - - - - M M -   - - - - - - - - - - - - - - - - - - - - - - - - - - - - M M -   - - - - - - - - - - - - - - - - - - - - - - - - - - - - M M -   - - - - - - - - - - - - - - - - - - - - - - - - - - - R R R -   - - - - - - - - - - - - - - - - - - - - - - - - - - R R R - -   - - - - - - - - - - - - - - - - - - - - - - - - - R R R - - -   - - - - - - - - - - - - - - - - - - - - - - - - T T T - - - -   - - - - - - - - - - - - - - - - - - - - - - - T T T - - - - -   - - - - - - - - - - - - - - - - - - - - - - S S S - - - - - -   - - - - - - - - - - - - - - - - - - - - - - S S - - - - - - -   - - - - - - - - - - - - - - - - - - - - - - - - - - - - - - -   - - - - - - - - - - - - - - - - - - - - - - - - - - - - - - -   - - - - - - - - - - - - - - - - - - - - - - - - - - - - - - -   - - - - - - - - - - - - - - - - - - - - - - - - - - - - - - -   - - - - - - - - - - - - - - - - - - - - - - - - - - - - - - -   - - - - - - - - - - - - - - - - - - - - - - - - - - - - - - -   
- - - - - - - - - - - - - F F F F F F F - - - - - - - - - - -   - - - - - - - - - - - I I F F F F F F F F F F F - - - - - - -   - - - - - - - - - - A A A B B B B B B B B B B B B - - - - - -   - - - - - - - - - - A A A B B B B B B B B B B B B B - - - - -   - - - - - - - - - - A A A B - - - - B B B B B B B B B - - - -   - - - - - - - - - - A A A B - - - - - - - B B B B B B - - - -   - - - - - - - - - - - - - - - - - - - - - - - C C C C C - - -   - - - - - - - - - - - - - - - - - - - - - - - - C C C C C - -   - - - - - - - - - - - - - - - - - - - - - - - - - C C C C C -   - - - - - - - - - - - - - - - - - - - - - - - - - - C C C C -   - - - - - - - - - - - - - - - - - - - - - - - - - - - G G G -   - - - - - - - - - - - - - - - - - - - - - - - - - - - G G G G   - - - - - - - - - - - - - - - - - - - - - - - - - - - G G G G   - - - - - - - - - - - - - - - - - - - - - - - - - - - M M M M   - - - - - - - - - - - - - - - - - - - - - - - - - - - M M M M   - - - - - - - - - - - - - - - - - - - - - - - - - - - M M M -   - - - - - - - - - - - - - - - - - - - - - - - - - - R R R R -   - - - - - - - - - - - - - - - - - - - - - - - - - R R R R R -   - - - - - - - - - - - - - - - - - - - - - - - - R R R R R - -   - - - - - - - - - - - - - - - - - - - - - - - T T T T T - - -   - - - - - - - - - - - - - - - - - - - - - - T T T T T - - - -   - - - - - - - - - - - - - - - - - - - - - - S S S S - - - - -   - - - - - - - - - - - - - - - - - - - - - S S S S - - - - - -   - - - - - - - - - - - - - - - - - - - - - N N - - - - - - - -   - - - - - - - - - - - - - - - - - - - - - - - - - - - - - - -   - - - - - - - - - - - - - - - - - - - - - - - - - - - - - - -   - - - - - - - - - - - - - - - - - - - - - - - - - - - - - - -   - - - - - - - - - - - - - - - - - - - - - - - - - - - - - - -   - - - - - - - - - - - - - - - - - - - - - - - - - - - - - - -   
- - - - - - - - - - - - - F F F F F F F - - - - - - - - - - -   - - - - - - - - - - - I I F F F F F F F F F F F - - - - - - -   - - - - - - - - - - A A A B B B B B B B B B B B B - - - - - -   - - - - - - - - - - A A A B B B B B B B B B B B B B - - - - -   - - - - - - - - - - A A A B - - - - B B B B B B B B B - - - -   - - - - - - - - - - A A A B - - - - - - - B B B B B B B - - -   - - - - - - - - - - - - - - - - - - - - - - - C C C C C - - -   - - - - - - - - - - - - - - - - - - - - - - - - C C C C C - -   - - - - - - - - - - - - - - - - - - - - - - - - - C C C C C -   - - - - - - - - - - - - - - - - - - - - - - - - - - C C C C -   - - - - - - - - - - - - - - - - - - - - - - - - - - G G G G G   - - - - - - - - - - - - - - - - - - - - - - - - - - - G G G G   - - - - - - - - - - - - - - - - - - - - - - - - - - - G G G G   - - - - - - - - - - - - - - - - - - - - - - - - - - - M M M M   - - - - - - - - - - - - - - - - - - - - - - - - - - - M M M M   - - - - - - - - - - - - - - - - - - - - - - - - - - M M M M M   - - - - - - - - - - - - - - - - - - - - - - - - - - R M M R -   - - - - - - - - - - - - - - - - - - - - - - - - - R R R R R -   - - - - - - - - - - - - - - - - - - - - - - - - R R R R R - -   - - - - - - - - - - - - - - - - - - - - - - - T T T T T T - -   - - - - - - - - - - - - - - - - - - - - - - T T T T T T - - -   - - - - - - - - - - - - - - - - - - - - - S S S S S S - - - -   - - - - - - - - - - - - - - - - - - - - - S S S S S - - - - -   - - - - - - - - - - - - - - - - - - - - - N N N - - - - - - -   - - - - - - - - - - - - - - - - - - - - - - - - - - - - - - -   - - - - - - - - - - - - - - - - - - - - - - - - - - - - - - -   - - - - - - - - - - - - - - - - - - - - - - - - - - - - - - -   - - - - - - - - - - - - - - - - - - - - - - - - - - - - - - -   - - - - - - - - - - - - - - - - - - - - - - - - - - - - - - -   
- - - - - - - - - - - - - F F F F F F - - - - - - - - - - - -   - - - - - - - - - - - I I F F F F F F F F F F - - - - - - - -   - - - - - - - - - - A A A B B B B B B B B B B B B - - - - - -   - - - - - - - - - - A A A B B B B B B B B B B B B B - - - - -   - - - - - - - - - - A A A B - - - - - B B B B B B B B - - - -   - - - - - - - - - - A A A B - - - - - - - B B B B B B - - - -   - - - - - - - - - - - - - - - - - - - - - - - C C C C C - - -   - - - - - - - - - - - - - - - - - - - - - - - - C C C C C - -   - - - - - - - - - - - - - - - - - - - - - - - - - C C C C - -   - - - - - - - - - - - - - - - - - - - - - - - - - - C C C C -   - - - - - - - - - - - - - - - - - - - - - - - - - - G G G G -   - - - - - - - - - - - - - - - - - - - - - - - - - - - G G G G   - - - - - - - - - - - - - - - - - - - - - - - - - - - G G G G   - - - - - - - - - - - - - - - - - - - - - - - - - - - M M M M   - - - - - - - - - - - - - - - - - - - - - - - - - - - M M M M   - - - - - - - - - - - - - - - - - - - - - - - - - - M M M M -   - - - - - - - - - - - - - - - - - - - - - - - - - - R R R R -   - - - - - - - - - - - - - - - - - - - - - - - - - R R R R - -   - - - - - - - - - - - - - - - - - - - - - - - - R R R R R - -   - - - - - - - - - - - - - - - - - - - - - - - T T T T T - - -   - - - - - - - - - - - - - - - - - - - - - - T T T T T - - - -   - - - - - - - - - - - - - - - - - - - - - S S S S S - - - - -   - - - - - - - - - - - - - - - - - - - - - S S S S - - - - - -   - - - - - - - - - - - - - - - - - - - - - N N - - - - - - - -   - - - - - - - - - - - - - - - - - - - - - - - - - - - - - - -   - - - - - - - - - - - - - - - - - - - - - - - - - - - - - - -   - - - - - - - - - - - - - - - - - - - - - - - - - - - - - - -   - - - - - - - - - - - - - - - - - - - - - - - - - - - - - - -   - - - - - - - - - - - - - - - - - - - - - - - - - - - - - - -   
- - - - - - - - - - - - - - - - - - - - - - - - - - - - - - -   - - - - - - - - - - - - I F F F F F F - - - - - - - - - - - -   - - - - - - - - - - - A A B B B B B B B B B B - - - - - - - -   - - - - - - - - - - A A A B - - - - B B B B B B B - - - - - -   - - - - - - - - - - U A A - - - - - - - - B B B B B - - - - -   - - - - - - - - - - A A A - - - - - - - - - - B B B B - - - -   - - - - - - - - - - - - - - - - - - - - - - - - C C C - - - -   - - - - - - - - - - - - - - - - - - - - - - - - - C C C - - -   - - - - - - - - - - - - - - - - - - - - - - - - - - C C C - -   - - - - - - - - - - - - - - - - - - - - - - - - - - C C C - -   - - - - - - - - - - - - - - - - - - - - - - - - - - - G G G -   - - - - - - - - - - - - - - - - - - - - - - - - - - - - G G -   - - - - - - - - - - - - - - - - - - - - - - - - - - - - G G -   - - - - - - - - - - - - - - - - - - - - - - - - - - - - M M -   - - - - - - - - - - - - - - - - - - - - - - - - - - - - M M -   - - - - - - - - - - - - - - - - - - - - - - - - - - - M M M -   - - - - - - - - - - - - - - - - - - - - - - - - - - - R R - -   - - - - - - - - - - - - - - - - - - - - - - - - - - R R R - -   - - - - - - - - - - - - - - - - - - - - - - - - - R R R - - -   - - - - - - - - - - - - - - - - - - - - - - - - T T T T - - -   - - - - - - - - - - - - - - - - - - - - - - - T T T T - - - -   - - - - - - - - - - - - - - - - - - - - - - S S S S - - - - -   - - - - - - - - - - - - - - - - - - - - - - S S - - - - - - -   - - - - - - - - - - - - - - - - - - - - - - - - - - - - - - -   - - - - - - - - - - - - - - - - - - - - - - - - - - - - - - -   - - - - - - - - - - - - - - - - - - - - - - - - - - - - - - -   - - - - - - - - - - - - - - - - - - - - - - - - - - - - - - -   - - - - - - - - - - - - - - - - - - - - - - - - - - - - - - -   - - - - - - - - - - - - - - - - - - - - - - - - - - - - - - -   
