model
size = 31 30 19, scale = 0.05, origin = -y
material 
  colors = A:#2B3340 B:#43FFFB C:#CA7A2C D:#00C5ED E:#08192D F:#FFF G:#3A3226 H:#E98B2A I:#000 J:#00D0FF K:#994639 L:#006284 M:#4A593D N:#00E5FF O:#00A4B7 P:#A8D8B9
voxels
-----AAAAA--------------------- -----A-B-A--------------------- ------------------------------- ------------------------------- ------------------------------- ------------------------------- ------------------------------- ------------------------------- ------------------------------- ------------------------------- ------------------------------- ------------------------------- ------------------------------- ------------------------------- ------------------------------- ------------------------------- ------------------------------- ------------------------------- ------------------------------- ------------------------------- ------------------------------- ------------------------------- ------------------------------- ------------------------------- ------------------------------- ------------------------------- ------------------------------- ------------------------------- ------------------------------- ------------------------------- 
-----AAAAA--------------------- -----AABAA--------------------- ------------------------------- ------------------------------- ------------------------------- ------------------------------- ------------------------------- ------------------------------- ----------------A-B-A---------- ----------------AABAA---------- ------------------------------- ------------------------------- ------------------------------- ------------------------------- ------------------------------- ------------------------------- ------------------------------- ------------------------------- ------------------------------- ------------------------------- ------------------------------- ------------------------------- ------------------------------- ------------------------------- ------------------------------- ------------------------------- ------------------------------- ------------------------------- ------------------------------- ------------------------------- 
-----AAAA---------------------- -----AAAA---------------------- -----AABA---------------------- -----AABA---------------------- ------ABA--------AAA----------- ------ABA--------AAA----------- ------BBA--------AAA----------- -----------------AAA----------- ----------------AABAA---------- ----------------AABAA---------- ------------------------------- ------------------------------- ------------------------------- ------------------------------- ------------------------------- ------------------------------- ------------------------------- ------------------------------- ------------------------------- ------------------------------- ------------------------------- ------------------------------- ------------------------------- ------------------------------- ------------------------------- ------------------------------- ------------------------------- ------------------------------- ------------------------------- ------------------------------- 
-----AAAA---------------------- -----AAAA---------------------- -----AAAA--------AAAA---------- -----AAAA--------AAAA---------- -----AAAA--------AABB---------- -----AAAA--------AABB---------- ------AAA--------AAB----------- -----------------AAB----------- ------------------------------- ------------------------------- ------------------------------- ------------------------------- ------------------------------- ------------------------------- ------------------------------- ------------------------------- ------------------------------- ------------------------------- ------------JJ----------------- -------FFF-JJJJ-FFF------------ ------FBNOF----FONBF----------- ------FIILF----FLIIF----------- ------EEEEE----EEEEE----------- -------EEE------EEE------------ ------------------------------- ------------------------------- ------------------------------- ------------------------------- ------------------------------- ------------------------------- 
-----AAAAAAAAAAAAAAAA---------- -----AAAAAAAAAAAAAAAA---------- -----AAAAAAAAAAAAAAAA---------- -----AAAAAABAABAAAAAA---------- -----AAAAAAABBAAAAAAB---------- -----AAAAAAAAAAAAAAAA---------- -----BAAAAABAABAAAHHA---------- ------AAAAAABBAAAAAA----------- ------BBAAAAAAAAAAAA----------- ------AABAAABBAAAAAA----------- ------AAAAABFFBAAAAA----------- ------BBBAAABBAAABBB----------- -------AABAAAAAABAA------------ -------BBBAAAAAABBB------------ ------AAAAAAAAAAAAAA----------- -----BAAAAAIAAIAAAAAB---------- ----AABAAAAAIIAAAAABAA--------- -----AABAAAAAAAAAABAA---------- -----BAAAAAAGGAAAAAAB---------- ------AAAAAGGGGAAAAA----------- ------AAAAABAABAAAAA----------- ------AADDKBAABKDDAA----------- ------AAGGKBBBBKGGAA----------- -------AMGABAABAGMA------------ -------BBBBBAABBBBB------------ ---------AAAAAAAA-------------- ------------------------------- ------------------------------- ------------------------------- ------------------------------- 
----AAAAAAAAAAAAAAAAAA--------- ----AAAAAAAAAAAAAAAAAA--------- ----AAAAAAAAAAAAAAAAAA--------- ----AAAAAAAAAAAAAAAAAA--------- ----AAAAAAAAAAAAAAAABB--------- ----AAAAAAAAAAAAAAAAAA--------- -----BAAAAAAAAAAAAAHA---------- -----AAAAAAAAAAAAAHHA---------- -----BAAAAAAAAAAAAHAB---------- -----AAAAAAAAAAAAAHHA---------- -----BAAAAAAAAAAAAAHB---------- -----APAAAAAAAAAAAAAA---------- ------AACCCCCCCAAAAA----------- ------BBBBCAAAAAABBB----------- ------ACCCCAAAAAAAAA----------- ------ACCCCAAAAAAAAA----------- ----AACCCCCAAAAAAAAAAA--------- -----ACCCCCAAAAAAAAAA---------- -----ACCCCCAAAAAAAAHA---------- ------ACCCCAAAAAAAAA----------- ------ACCCCAAAAAAAAA----------- ------ACDDCAAAAADDAA----------- ------ACCCCAAAAAAAAA----------- -------AAAAAAAAAAAA------------ -------AAAAAAAAAAAA------------ --------AAAAAAAAAA------------- --------A--------A------------- ------------------------------- ------------------------------- ------------------------------- 
----AAAAAAAAAAAAAAAAAA--------- ----AAAAAAAAAAAAAAAAAA--------- ----AAAAAAAAAAAAAAAAAA--------- ----AAAAAAAAAAAAAAAAAA--------- ----AAAAAAAAAAAAAAAAAA--------- ----AAAAAAAAAAAAAAAAAB--------- ----BBAAAAAAAAAAAAAAAA--------- ----AAAAAAAAAAAAAAAAAA--------- ----BBAAAAAAAAAAAAAABB--------- -----AAAAAAAAAAAAAAAA---------- -----BAAAAAAAAAAAAAAB---------- -----APAAAAAAAAAAAAAA---------- -----AAACCCCCCCAAAAAA---------- ------BBBBCAAAAAAAAB----------- ------ACCCCAAAAAAAAA----------- ------ACCCCAAAAAAAAA----------- ------ACCCCAAAAAAAAA----------- ------ACCCCAAAAAAAAA----------- ------ACCCCAAAAAAAAA----------- ------ACCCCAAAAAAAAA----------- ------ACCCCAAAAAAAAA----------- ------ACDDCAAAAADDAA----------- ------ACCCCAAAAAAAAA----------- ------AAAAAAAAAAAAAA----------- -----AAAAAAAAAAAAAAAA---------- -----BABAAAAAAAAAABAB---------- ------ABA---BA---ABA----------- -----A-AA---A----AA-A---------- -----AA------------AA---------- ------------------------------- 
----AAAAAAAAAAAAAAAAAA--------- ----AAAAAAAAAAAAAAAAAA--------- ----AAAAAAAAAAAAAAAAAA--------- ----AAAAAAAAAAAAAAAAAA--------- ----AAAAAAAAAAAAAAAAAA--------- ----AAAAAAAAAAAAAAAAAA--------- ----BBBBBBBBBBBBBBBBBB--------- ----AAAAAAAAAAAAAAAAAA--------- ----BBAAAAAAAAAAAAAABB--------- -----AAAAAAAAAAAAAAAA---------- -----BAAAAAAAAAAAAAAB---------- -----AAAAAAAAAAAAAAAA---------- -----AAAAAAAAAAAAAAAA---------- -----BBBBBAAAAAAAAABB---------- ------AAAAAAAAAAAAAA----------- ------AAAAAAAAAAAAAA----------- ------AAAAAAAAAAAAAA----------- ------AAAAAAAAAAAAAA----------- ------AAAAAAAAAAAAAA----------- ------AAAAAAAAAAAAAA----------- ------AAAAAAAAAAAAAA----------- ------AADDAAAAAADDAA----------- ------AAAAAAAAAAAAAA----------- ------AAAAAAAAAAAAAA----------- -----AAAAAAAAAAAAAAAA---------- -----AAAAAAAAAAAAAAAA---------- -----BAAA--AAAB--AAAB---------- -----ABAA--AAA---AABA---------- -----AA------------AA---------- ------------------------------- 
----AAAAAAAAAAAAAAAAAA--------- ----AAAAAAAAAAAAAAAAAA--------- ----AAAAAAAAAAAAAAAAAA--------- ----AAAAAAAAAAAAAAAAAA--------- ----AAAAAAAAAAAAAAAAAA--------- ----AAAAAAAAAAAAAAAAAA--------- ----BBBBBBBBBBBBBBBBBB--------- ----AAAAAAAAAAAAAAAAAA--------- ----BBAAAAAAAAABBBBBBB--------- -----AAAAAAAAAAAAAAAA---------- -----BBBBBBBBBBBBBBBB---------- -----AAAAAAAAAAAAAAAA---------- -----AAAAAAAAAAAAAAAA---------- -----BAAAAAAAAAAAAABB---------- ------AAAAAAAAAAAAAA----------- ------AAAAAAAAAAAAAA----------- ------AAAAAAAAAAAAAA----------- ------AAAAAAAAAAAAAA----------- ------AAAAAAAAAAAAAA----------- ------AAAAAAAAAAAAAA----------- ------AAAAAAAAAAAAAA----------- ------AADDAAAAAAAAAA----------- ------AAAAAAAAAAAAAA----------- -------AAAAAAAAAAAA------------ -------AAAAAAAAAAAA------------ ---------AAAAAAAA-------------- -----------AAAA---------------- ------------AAB---------------- ------------AB----------------- -------------B----------------- 
AAAAAAAAAAAAAAAAAAAAAAAAAA----- BBBBAAAAAAAAAAAAAAAAAABBBB----- --AAAAAAAAAAAAAAAAAAAAAA------- --AAAAAAAAAAAAAAAAAAAAAA------- --AAAAAAAAAAAAAAAAAAAAAA------- --AAAAAAAAAAAAAAAAAAAAAA------- ---ABBBBBBBBBBBBBBBBBBA-------- ----AAAAAAAAAAAAAAAAAA--------- ----BBBBBBBBBBBBBBBBBB--------- -----AAAAAAAAAAAAAAAA---------- -----BBBBBBBBBBBBBBBB---------- -----AAAAAAAAAAAAAAAA---------- -----AAAAAAAAAAAAAAAA---------- -----BBBBBBBBBBBBBBBB---------- ------AAAAAAAAAAAAAA----------- ------AAAAAAAAAAAAAA----------- ------AAAAAAAAAAAAAA----------- ------AAAAAAAAAAAAAA----------- ------AAAAAAAAAAAAAA----------- ------AAAAAAAAAAAAAA----------- ------AAAAAAAAAAAAAA----------- ------AADDAAAAAAAAAA----------- ------AAAAAAAAAAAAAA----------- -------AAAAAAAAAAAA------------ -------AAAAAAAAAAAA------------ ---------AAAAAAAA-------------- ------------------------------- ------------------------------- ------------------------------- ------------------------------- 
AAAAAAAAAAAAAAAAAAAAAAAAAA----- AAAAAAAAAAAAAAAAAAAAAAAAAA----- --AAAAAAAAAAAAAAAAAAAAAA------- --AAAAAAAAAAAAAAAAAAAAAA------- --AAAAAAAAAAAAAAAAAAAAAA------- --AAAAAAAAAAAAAAAAAAAAAA------- --AABBBBBBBBBBBBBBBBBBAA------- ----AAAAAAAAAAAAAAAAAA--------- ----BBBBBBBBBBBBBBBBBB--------- -----AAAAAAAAAAAAAAAA---------- -----BBBBBBBBBBBBBBBB---------- -----AAAAAAAAAAAAAAAA---------- -----AAAAAAAAAAAAAAAA---------- -----BBBBBBBBBBBBBBBB---------- ------AAAAAAAAAAAAAA----------- ------AAAAAAAAAAAAAA----------- ------AAAAAAAAAAAAAA----------- ------AAAAAAAAAAAAAA----------- ------AAAAAAAAAAAAAA----------- ------AAAAAAAAAAAAAA----------- ------AAAAAAAAAAAAAA----------- ------AADDAAAAAAAAAA----------- ------AAAAAAAAAAAAAA----------- -------AAAAAAAAAAAA------------ -------AAAAAAAAAAAA------------ ---------AAAAAAAA-------------- ------------------------------- ------------------------------- ------------------------------- ------------------------------- 
AAAAAAAAAAAAAAAAAAAAAAAAAA----- AAAAAAAAAAAAAAAAAAAAAAAAAA----- --AAAAAAAAAAAAAAAAAAAAAA------- --AAAAAAAAAAAAAAAAAAAAAA------- --AAAAAAAAAAAAAAAAAAAAAA------- --AAAAAAAAAAAAAAAAAAAAAA------- --AABBBBBBBBBBBBBBBBBBAA------- ----AAAAAAAAAAAAAAAAAA--------- ----BBBBBBBBBBBBBBBBBB--------- -----AAAAAAAAAAAAAAAA---------- -----BBBBBBBBBBBBBBBB---------- -----AAAAAAAAAAAAAAAA---------- -----AAAAAAAAAAAAAAAA---------- -----BBBBBBBBBBBBBBBB---------- ------AAAAAAAAAAAAAA----------- ------AAAAAAAAAAAAAA----------- ------AAAAAAAAAAAAAA----------- ------AAAAAAAAAAAAAA----------- ------AAAAAAAAAAAAAA----------- ------AAAAAAAAAAAAAA----------- ------AAAAAAAAAAAAAA----------- ------AAAAAAAAAAAAAA----------- ------AAAAAAAAAAAAAA----------- -------AAAAAAAAAAAA------------ -------AAAAAAAAAAAA------------ ---------AAAAAAAA-------------- ------------------------------- ------------------------------- ------------------------------- ------------------------------- 
AAAAAAAAAAAAAAAAAAAAAAAAAA----- AAAAAAAAAAAAAAAAAAAAAAAAAA----- --AAAAAAAAAAAAAAAAAAAAAA------- --AAAAAAAAAAAAAAAAAAAAAA------- --AAAAAAAAAAAAAAAAAAAAAA------- --AAAAAAAAAAAAAAAAAAAAAA------- ---ABBBBBBBBBBBBBBBBBBA-------- -----AAAAAAAAAAAAAAAA---------- -----BBBBBBBBBBBBBBBB---------- -----AAAAAAAAAAAAAAAA---------- -----BBBBBBBBBBBBBBBB---------- -----AAAAAAAAAAAAAAAA---------- -----AAAAAAAAAAAAAAAA---------- ------BBBBBBBBBBBBBB----------- ------AAAAAAAAAAAAAA----------- ------AAAAAABBAAAAAA----------- ------AAAAAABBAAAAAA----------- -------AAAAAAAAAAAA------------ -------AAAAAAAAAAAA------------ -------AAAAAAAAAAAA------------ -------AAAAAAAAAAAA------------ -------AAAAAAAAAAAA------------ -------AAAAAAAAAAAA------------ --------AAAABBAAAA------------- ---------AAABBAAA-------------- ------------------------------- ------------------------------- ------------------------------- ------------------------------- ------------------------------- 
------AAABABAABABAAA----------- ------AAABAAAAAAAAAA----------- ------AAABAAAAAAAAAA----------- ------AAABAAAAAAAAAA----------- ------AAABAAAABABAAA----------- ------AAABAAAABABAAA----------- ------BBBBABAABABBBB----------- ------AAAAABAABAAAAA----------- ------BBBBBBAABBBBBB----------- ------AAAAAAAAAAAAAA----------- ------BBBBAAAAAABBBB----------- -------AABAABBAABAA------------ -------AABAABBAABAA------------ --------BBAAAAAABB------------- ------------------------------- ------------------------------- ------------------------------- ----------AAAAAA--------------- ---------AAAAAAAA-------------- ---------AAABBAAA-------------- ---------AAABBAAA-------------- ---------AAAAAAAA-------------- ----------AAAAAA--------------- ------------------------------- ------------------------------- ------------------------------- ------------------------------- ------------------------------- ------------------------------- ------------------------------- 
-------------AAAAAAA----------- -----------AAAAAAAAAAA--------- ----------AAAAAAAAAAAAAA------- ----------AAAA----AAAAAAA------ ----------AAAA-------AABAA----- ----------AAAA---------ABAA---- ------------------------ABA---- -------------------------ABA--- --------------------------ABA-- ---------------------------AB-- ---------------------------ABA- ----------------------------BA- ----------------------------BA- ----------------------------BA- ----------------------------BA- ----------------------------BA- ----------------------------BA- ----------------------------BA- ---------------------------ABA- --------------------------ABAA- -------------------------ABAA-- ------------------------ABAA--- ------------------------AA----- ------------------------------- ------------------------------- ------------------------------- ------------------------------- ------------------------------- ------------------------------- ------------------------------- 
-------------AAAAAAA----------- -----------AAAAAAAAAAAAA------- ----------AAAAAAAAAAAAAAA------ ----------AAAAAAAAAAAAAAAA----- ----------AAAA----AAAAAAAAA---- ----------AAAA-------AAAAAA---- -----------------------AAAAA--- ------------------------AAAAA-- -------------------------AAAAA- --------------------------AAAA- ---------------------------AAA- ---------------------------AAAA ---------------------------AAAA ---------------------------AAAA ---------------------------AAHA ---------------------------AAAA ---------------------------AAAA ---------------------------AAAA --------------------------AAAAA -------------------------AAAAAA ------------------------AAAAAA- -----------------------AAAAAA-- ------------------------AAA---- ------------------------------- ------------------------------- ------------------------------- ------------------------------- ------------------------------- ------------------------------- ------------------------------- 
-------------AAAAAAA----------- -----------AAAAAAAAAAAAA------- ----------AAAAAAAAAAAAAAA------ ----------AAAAAAAAAAAAAAAA----- ----------AAAA----AAAAAAAAA---- ----------AAAA-------AAAAAAA--- -----------------------AAAAA--- ------------------------AAAAA-- -------------------------AAAAA- --------------------------AAAA- --------------------------AAAAA ---------------------------AAAA ---------------------------AAAA ---------------------------AAAA ---------------------------AAHA ---------------------------AAAA ---------------------------AAAA ---------------------------AAAA --------------------------AAAAA -------------------------AAAAAA -----------------------AAAAAAA- -----------------------AAAAAA-- ------------------------AAA---- ------------------------------- ------------------------------- ------------------------------- ------------------------------- ------------------------------- ------------------------------- ------------------------------- 
-------------AAAAAA------------ -----------AAAAAAAAAAAA-------- ----------AAAAAAAAAAAAAAA------ ----------AAAAAAAAAAAAAAAA----- ----------AAAA-----AAAAAAAA---- ----------AAAA-------AAAAAA---- -----------------------AAAAA--- ------------------------AAAAA-- -------------------------AAAA-- --------------------------AAAA- --------------------------AAAA- ---------------------------AAAA ---------------------------AAAA ---------------------------AAAA ---------------------------AAAA ---------------------------AAAA ---------------------------AAAA ---------------------------AAAA --------------------------AAAAA -------------------------AAAAAA -----------------------AAAAAAA- -----------------------AAAAAA-- ------------------------AAA---- ------------------------------- ------------------------------- ------------------------------- ------------------------------- ------------------------------- ------------------------------- ------------------------------- 
------------------------------- ------------AAAAAAA------------ -----------AAAAAAAAAAAA-------- ----------AAAA----AAAAAAA------ ----------AAA--------AAAAA----- ----------AAA----------AAAA---- ------------------------AAA---- -------------------------AAA--- --------------------------AAA-- --------------------------AAA-- ---------------------------AAA- ----------------------------AA- ----------------------------AA- ----------------------------AA- ----------------------------AA- ----------------------------AA- ----------------------------AA- ----------------------------AA- ---------------------------AAA- --------------------------AAAA- -----------------------AAAAAA-- -----------------------AAAA---- ------------------------------- ------------------------------- ------------------------------- ------------------------------- ------------------------------- ------------------------------- ------------------------------- ------------------------------- 
