model
size = 31 32 17, scale = 0.05, origin = -y
material 
  colors = A:#111 B:#27EA68 C:#6FB3FD D:#6F6 E:#00B2FF F:#19BBF2 G:#51CC6C H:#FF0 I:#3EA0E2 J:#FC0 K:#FFFFC2 L:#777 M:#070707 N:#F8F8F8
voxels
9-9AL3A18-B11AB18-G2AL8AB18-D11AD18-D11AG18-D7AL3A3(D18-D11A)I18-I11AI18-F3A5J3AF18-3AJ2HK2HJ3A18-2AJH5AHJ2A18-AJHA5HAHJA18-AHA2HAKA2HAHA18-A2(HJ2HJ)HA18-A11HA18-A3H2JH2J3HA18-2AH7KH2A18-3AH5KH3A18-4AH3KH4A17-B13AB15-8AB5AL2A14-7A2BD7A15-5ADG-BD5A17-4AB3-2B3A202-2A13-2A14-GB13-GB14-GB13-2B14-2B13-DG14-BG13-DB14-DB13-2D14-BD13-DG14-2D13-2D14-ID13-ID14-2I13-2I3(14-2F13-2F)2(14-3E11-3E)15-2E11-2E4(16-2C11-2C)14-G2BC11-C3B11-D2BC13-C3B10-2AC15-3A10-3A15-3A11-2A15-2(2A13-)2A15-4ADB3-BD4A16-3ABG5-GB3A138-A17-A2(12-B17-G)12-B17-B12-G17-B12-B17-D12-D17-G12-D17-D12-I17-D12-2I15-CI3(12-2F15-CF)13-2(E15-E14-)EC13-2E3(14-2C13-2C)15-C13-C11-G2B2-C13-C2-BGB6-3B19-CBD2(6-3A19-3A)7-2A19-2A8-4A15-4A9-3A15-2AL12-L15-A15-3ADB5-2B3A106-A19-A10-G19-G10-B19-G10-G19-G2(10-B19-D)10-D19-B2(10-D19-D)11-I17-I3(12-F17-F)2(12-E17-E)13-E15-E4(14-C15-C)9-B4-B15-C4-G4-D25-B4-A25-A4-2A23-2A4-L2A21-3A5-3A19-3A6-4A17-4A7-4A15-4A10-2A15-2A14-2ABD7-BG2A75-A19-A3(10-B19-B)10-D19-B10-D19-G3(10-D19-D)10-DC17-CB2(10-2F17-2F)11-F17-F2(12-E17-E)12-2E15-2E12-2C15-2C13-2(C15-C14-)C15-C8-B5-B15-C5-G2-B27-B2-A27-A2-2A25-AL3-2A23-2A4-3A21-3A4-4A19-4A5-4A17-4A7-4A15-C3A11-2A13-2A16-D2B7-DBD45-A19-A10-B19-B10-G19-B10-D19-G10-B19-B10-G2(19-B10-D)19-D10-D19-B10-D19-I10-D2(19-F10-F)19-F2(10-E19-E)11-E17-E3(12-C17-C)13-C15-C8-B5-B15-C5-B2-B27-D2(2-A27-A)2-2A25-CA2-3A23-2CA3-3A21-3A4-L3A19-4A5-4A17-4A8-3A15-ALA13-G13-B17-BG9-BD14-A19-A10-B19-G2(10-B19-B)10-D19-G4(10-D19-D)10-D19-I3(10-F19-F)2(10-E19-E)10-2E17-2E10-2C17-2C11-2(C17-C12-)2C15-2C6-D6-B15-C6-2G28-2BA28-C2A28-CA-A26-CA2-2A25-CA2-3A23-2CA3-3A21-3A5-3A19-3A7-3AC15-4A11-2(D15-)D13-B13-A19-A10-B19-B10-G19-B10-D19-B10-B19-B10-G19-B3(10-D19-D)10-I19-I3(10-F19-F)2(10-E19-E)10-2E17-2E2(10-2C17-2C)11-C17-C12-2C15-2C6-B5-2B15-CB5-GB28-2BA2(28-C2A)28-2A-A26-CA2-2A25-CA3-2A23-CA4-3A21-3A6-2A19-2A10-GB15-2B14-B13-G13-15(A19-A10-)AE17-E3(A10-AC17-C)A10-A2C15-2CA5-B5-2A15-2A5-2B28-3B28-BGD28-3B28-2BG28-BG-D26-2B2-GA25-2B3-GB23-BG5-2BG19-3G9-BG15-BG14-2(B13-)A19-A10-B19-G10-G2(19-B10-B)19-B2(10-D19-D)3(10-I19-D)3(10-F19-F)2(10-E19-E)10-2E17-2E2(10-2C17-2C)11-C17-C12-2C15-2C6-D5-2A15-2A5-BG28-BGD2(28-2BG)28-3B28-2B-G26-BG2-BA25-2B3-2B23-2B5-GBG19-2GB9-GB15-BG14-2(D13-)A19-A2(10-B19-B)10-B19-G10-D19-B10-D4(19-D10-I)19-D3(10-F19-F)2(10-E19-E)10-2E17-2E10-2C17-2C11-2(C17-C12-)2C15-2C2(6-B)15-C6-2B28-2BA28-CAL28-C2A28-CA-A26-2A2-2A25-2A3-2A23-2A4-3A21-3A6-2A19-2A10-GB15-2B14-2(B13-)A19-A10-G19-B10-B19-B10-D19-B10-B19-D10-D3(19-B10-I)19-D10-I19-I3(10-F19-F)2(10-E19-E)11-E17-E3(12-C17-C)13-C15-C7-G6-B15-C6-GD28-2BA28-C2A28-CA-A26-2A2-2A25-2A2-3A23-3A3-3A21-3A5-L3A17-C3A7-4A15-C3A11-GB14-D16-B12-G13-A19-A10-B19-B10-B19-G10-G2(19-B10-D)19-D10-D2(19-D10-I)19-D10-2I17-2I2(10-2F17-2F)11-F17-F2(12-E17-E)13-E15-E4(14-C15-C)8-B5-B15-C5-B2-B27-B2-A27-A2-A26-CA2-2A25-2A2-3A23-3A3-3A21-3A4-4A19-4A5-4A17-4A8-3A15-3A13-D13-B17-B11-D14-A19-A10-B19-B10-G19-B10-B19-G10-B2(19-B10-D)19-D10-D19-D10-I19-I11-I17-I3(12-F17-F)2(12-E17-E)13-E15-E4(14-C15-C)8-B5-B15-G5-G2-D27-B2-A27-A2-2A25-CA3-2A23-AL4-L2A21-3A4-4A19-4A5-4A17-4A7-4A15-4A11-2(A15-)B13-D17-GD9-BG15-A17-A12-B17-B12-G17-G2(12-B17-B)12-G17-D12-B17-D2(12-D17-I)12-IC15-2I12-FC2(15-CF12-2F)15-CF13-3(E15-E14-)2(C15-C14-)2(C15-)C13-A10-G5-A13-A5-2(B4-)BA13-AB4-G4-A25-A4-2A23-2A4-3A21-3A5-3A19-3A6-4A17-4A7-4A16-3A10-2A15-AL14-2A11-2A17-2G9-2B20-B7-B18-A15-A14-B15-B14-B15-G14-B15AB14-B13ALAB14-B4A6M5AD14-B4AM4JM5AC14-D4AMJMNJM5AC14-D2ALAMJNMJM5AC14-D4AM4JM5AC14-D2(15AF14-F)15AF14-2E13A2E14-2E4AL8A2E15-E13AE16-C13AC16-CAL11AC16-C8AL4AC16-15A11-BDBG-15A-4B6-GD2BG14AC4BG2(6-25A)7-23A8-6AL16A9-8AL12A12-17A15-13ALA17-7AL5A19-B9AL22-DGBD2BG20-12AL2A16-2B11A2B16-2BAL9A2B16-GB11AGD16-2B11ABG16-2D3AL7A2D16-GD11A2D16-2D11A2I16-2D9ALA2I16-BD11A2I16-DF2(11A2F16-2F)L10A2F17-E7AL3A2(E18-E11A)E2(18-C11AC)18-C3A5J3AC18-3AJ2HK2HJ3A18-2AJH5AHJ2A17-2AJHA5HAHJ2A14-4AHA2HAKA2HAH4A12-4A2(HJ2HJ)H4A12-4A11HAL2A13-3A3H2JH2J3H3A14-L3AH7KH4A14-5AH5KH5A15-5AH3KH5A17-13A20-3(DBG)42-
