model
size = 31 32 17, scale = 0.05, origin = -y
material 
  colors = A:#060606 B:#0F6 C:#C1C1C1
voxels
9-2(13A18-)13B5(18-13A)18-6AB6A2(18-13A)3(18-6AB6A)18-6A3B4A18-8A2B3A18-9AB3A18-3A2B4AB3A18-3AB5AB3A18-2(3A2B)3A18-4A5B4A17-15A15-B15AB14-17A15-7A-7A17-5A3-5A202-2(2A13-2A14-)2B13-2B10(14-2A13-2A)2(14-3A11-3A)15-4(2A11-2A16-)2A11-2A14-2(4A11-)4A13-4A10-2BA15-A2B10-3A15-3A11-2A15-2A13-BA13-AB15-6A3-6A16-5A5-5A138-2(A17-A12-)B17-B6(12-A17-A)4(12-2A15-2A)13-2(A15-A14-)3(2A13-2A14-)2A13-2A15-A13-A11-3A2-A13-A2-3A6-3A19-3A6-2BA19-A2B6-3A19-3A7-2A19-2A8-3BA15-A3B9-3B15-3B12-2(B15-)5A5-5A106-2(A19-A10-)B19-B6(10-A19-A)11-5(A17-A12-)A17-A13-4(A15-A14-)A15-A9-A4-A15-2(A4-)A25-A4-B25-B4-2A23-2A4-3A21-3A5-B2A19-2AB6-2B2A17-2A2B7-3BA15-A3B10-2B15-2B14-4A7-4A75-2(A19-A10-)B19-B6(10-A19-A)3(10-2A17-2A)11-3(A17-A12-)2A15-2A12-2A15-2A13-2(A15-A14-)A15-A8-A5-A15-A5-A2-A27-A2-B27-B2-2A25-2A3-2A23-2A4-B2A21-2AB4-B3A19-3AB5-B3A17-3AB7-3BA15-A3B11-BA13-AB16-3A7-3A45-2(A19-A10-)B19-B12(10-A19-A)11-3(A17-A12-)A17-A13-A15-A8-A5-A15-A5-A2-A27-A2-B27-B2-A27-A2-2A25-2A2-B2A23-2AB3-B2A21-2AB4-B3A19-3AB5-2B2A17-2A2B8-3B15-3B2(13-A)17-2A9-2A14-2(A19-A10-)B19-B12(10-A19-A)2(10-2A17-2A)11-2(A17-A12-)2A15-2A2(6-A)15-A6-2A28-2AB28-ABA28-2A-A26-2A2-BA25-AB2-B2A23-2AB3-B2A21-2AB5-B2A19-2AB7-3BA15-A3B11-2(B15-)2(A13-)2(A19-A10-)B19-B12(10-A19-A)3(10-2A17-2A)11-A17-A12-2A15-2A6-A5-2A15-2A5-2A28-2AB28-ABA28-3A28-2A-B26-AB2-BA25-AB3-BA23-AB4-2BA21-A2B6-2B19-2B10-2B15-2B14-2(A13-)2(A19-A10-)B19-B12(10-A19-A)4(10-2A17-2A)10-3A15-3A5-A5-2A15-2A5-2A28-2AB28-ABA28-3A28-2AB28-AB-B26-AB2-BA25-AB3-BA23-AB5-3B19-3B9-2B15-2B14-2(A13-)2(A19-A10-)B19-B12(10-A19-A)3(10-2A17-2A)11-A17-A12-2A15-2A6-A5-2A15-2A5-2A28-2AB28-ABA28-3A28-2AB28-AB-B26-AB2-BA25-AB3-BA23-AB5-3B19-3B9-2B15-2B14-2(A13-)2(A19-A10-)B19-B12(10-A19-A)2(10-2A17-2A)11-2(A17-A12-)2A15-2A2(6-A)15-A6-2A28-2AB28-ABA28-3A28-2A-B26-AB2-BA25-AB3-BA23-AB4-2BA21-A2B6-2B19-2B10-2B15-2B14-2(A13-)2(A19-A10-)B19-B12(10-A19-A)11-3(A17-A12-)A17-A13-A15-A7-A6-A15-A6-2A28-2AB28-ABA28-2A-A26-2A2-BA25-AB2-B2A23-2AB3-B2A21-2AB5-B3A17-3AB7-3BA15-A3B11-BA14-B16-A12-A13-2(A19-A10-)B19-B6(10-A19-A)3(10-2A17-2A)11-2(A17-A12-)A17-A13-4(A15-A14-)A15-A8-A5-A15-A5-A2-A27-A2-B27-B2-A26-2A2-2A25-2A2-B2A23-2AB3-B2A21-2AB4-B3A19-3AB5-2B2A17-2A2B8-3B15-3B2(13-A)17-A11-A14-2(A19-A10-)B19-B6(10-A19-A)11-5(A17-A12-)A17-A13-4(A15-A14-)A15-A8-A5-A15-A5-A2-A27-A2-B27-B2-2A25-2A3-2A23-2A4-B2A21-2AB4-B3A19-3AB5-B3A17-3AB7-3BA15-A3B11-2(B15-)A13-A17-2A9-2A15-2(A17-A12-)B17-B6(12-A17-A)4(12-2A15-2A)13-2(A15-A14-)A15-B3(14-A15-A)15-A13-A10-A5-A13-A5-2(A4-)2A13-2A4-A4-B25-B4-2A23-2A4-3A21-3A5-B2A19-2AB6-2B2A17-2A2B7-3BA16-3B10-2B15-2B14-2A11-2A17-2A9-2A20-A7-A18-2(A15-A14-)B15-B9(14-17A)14-16A2(B14-AB14A)B15-14AB4(16-15A)11-4A-15A-4A6-25A6-3B19A3B6-25A7-23A8-3B17A3B9-3B15A3B12-B15AB15-15A17-13A19-5AC5A22-7A20-2(15A16-)15B3(16-15A)16-2(4AB)5A2(16-15A)16-3AB6A2B3A16-2A2B7AB3A16-3B8AB3A16-B10AB2AB17-3AB6AB2A18-4B6A2BA18-11A2B2(18-13A)18-3AB9A18-11ABA18-13A17-4AB10A14-2B4AB6AB3A2B12-2(6AB)5A12-2(4A3B)5A13-BA2B6AB5AB15-AB7A2(B2A)16-AB7A2(B2A)18-B2AB3A4B20-4B4A2BA21-9A42-
