model
size = 31 32 17, scale = 0.05, origin = -y
material 
  colors = A:#7DB9DE B:#60373E C:#C1328E D:#005CAF E:#CAAD5F F:#F596AA G:#FBE251 H:#1B813E I:#D0104C J:#BDC0BA K:#2EA9DF L:#6E552F M:#FFFFFB N:#373C38 O:#F7D94C P:#707C74 Q:#986DB2 R:#77428D S:#AB3B3A T:#888 U:#227D51 V:#DDD23B W:#EEE X:#8D742A Y:#58B2DC
voxels
9-10E3D18-8EY4D18-E2A2L2AY2ADAD18-C2A2L8A18-3A2L8A18-C2A2L3ACAC2A18-AHA2LAH2AO3A18-2AH2LH2ACAC2A18-3A2H8A18-HAH2AHAH5A18-AH4AH3ACAC18-11AOA18-F9ACAC18-QF2(AC)7A18-F3AO6AFA18-3ACAC4AFQF18-11AFA18-7ACAC3A18-3AF4AO4A18-2AFQF2ACAC3A18-3AF9A17-15A15-3ACAC3AF7A14-4AO3AFQF2(AC)2A15-2ACAC2A-F3AO2A17-5A3-2ACAC202-2(2E13-2D14-)2E13-AD14-CE13-2A14-AO13-AC14-CA13-2A14-2A13-AC3(14-2A13-2A)14-HA13-AF2(14-2A13-2A)14-AFA11-3A14-3A11-3A15-4(2A11-2A16-)2A11-2A14-2(4A11-)4A13-4A10-3A15-2AF10-3A15-3A11-2A15-2A13-CA13-2A15-6A3-6A16-AF3A5-5A138-2(E17-D12-)E3(17-A12-A)17-O12-H2(17-A12-A)17-A12-2A15-AF12-2A15-AQ12-HA15-AF12-2A15-2A13-2(A15-A14-)2A13-2A14-NA2(13-2A14-2A)13-2A15-A13-A11-F2A2-A13-A2-3A6-QFA19-AFA6-F2A19-AQF6-3A19-AFA7-2A19-2A8-AC2A15-4A9-AOA15-2AF12-C15-A15-FQF2A5-2ACAC106-2(E19-D10-)A19-D2(10-A19-A10-A19-C)10-H19-A10-A19-A11-A17-A12-H17-F4(12-A17-A)13-2(A15-A14-)N2(15-A14-A)15-A9-A4-A15-2(A4-)F25-A4-A25-A4-2A23-2A4-3A21-3A5-3A19-3A6-4A17-4A7-AC2A15-AFQF10-2A15-2A14-AF2A7-2AOA75-2(E19-D10-)6(L19-A10-)H19-A10-HA2(17-2A10-2A)17-2A11-N2(17-A12-A)17-A12-2A15-2A12-NA15-2A13-2(A15-A14-)A15-A8-A5-A15-A5-2(A2-A27-)A2-2A25-2A3-2A23-2A4-3A21-3A4-4A19-4A5-4A17-4A7-4A15-2AFA11-2A13-2A16-3A7-ACA45-2(E19-D10-)L19-D5(10-L19-A)10-H2(19-C10-A19-A10-A)19-A10-N19-A10-A19-A11-3(A17-A12-)A17-A13-A15-A8-A5-A15-A5-3(A2-A27-)A2-2A25-2A2-3A23-3A3-3A21-3A4-4A19-4A5-4A17-4A8-3A15-3A13-A13-C17-2A9-2A14-2(E19-D10-)5(A19-A10-)H19-A10-A19-A10-H19-O2(10-A19-A)10-N2(19-A10-A)19-A10-2A17-AC10-2A17-2A11-A17-C12-A17-A12-2A15-2A2(6-A)15-A6-AN2(28-3A)28-2A-A26-2A2-2A25-2A2-3A23-3A3-3A21-3A5-3A19-3A7-4A15-4A11-2(A15-)2(A13-)2(E19-D10-)A19-D3(10-A19-A)10-H2(19-A10-A)19-C10-A19-A10-H19-C4(10-A19-A)10-2A17-2A10-2A17-AO10-NA17-2A11-A17-A12-2A15-2A6-A5-2A15-2A5-2A28-ACN28-3A28-ACA28-2A-A26-2A2-2A25-2A3-2A23-2A4-3A21-3A6-FA19-2A10-2A15-2A14-2(A13-)2(E19-D10-)2(A19-A10-A19-C10-)5(A19-A10-)H3(19-A10-A)19-A10-2A17-AC10-2A17-2A10-2A17-AC10-NA17-2A10-3A15-3A5-A5-2A15-2A5-2A28-3A28-AON28-3A28-2AC28-2A-A26-2A2-CA25-2A3-2A23-2A5-FQF19-ACA9-2A15-AC14-2(A13-)2(E19-D10-)A19-D10-A19-A10-U19-O3(10-A19-A)10-U19-A10-A19-A10-H19-A10-A19-C10-A19-A10-A19-C10-N19-A2(10-2A17-2A)10-NA17-2A11-A17-A12-2A15-2A6-A5-2A15-2A5-2A28-ACN28-3A28-ACA28-3A28-2A-O26-2A2-2A25-AF3-2A23-2A5-AFA19-O2A9-2A15-2A14-2(A13-)2(E19-D10-)A19-A10-A2(19-C10-A19-A10-U)19-A10-A19-F3(10-A19-A)10-A19-O2(10-A19-A)10-NA17-2A10-2A17-2A11-2(A17-A12-)2A15-2A2(6-A)15-A6-AN3(28-3A)28-2A-C26-2A2-2A25-AF3-CA23-AQ4-3A21-2AF6-2A19-AC10-2A15-AC14-2(A13-)2(E19-D10-)P19-D3(10-X19-A)10-U19-A10-A19-F10-A19-Q10-A19-F2(10-A19-A10-A19-C)10-N19-A11-3(A17-A12-)A17-A13-A15-A7-A6-A15-A6-2A2(28-3A)28-2A-A26-2A2-2A25-2A2-3A23-3A3-3A21-2AF5-4A17-4A7-4A15-4A11-2A14-A16-A12-A13-2(E19-D10-)P2(19-A10-A)2(19-A10-U19-A10-A)19-F3(10-2A17-2A)11-2(A17-A12-)A17-A13-3(A15-A14-)N15-A14-A15-A8-A5-A15-A5-2(A2-A27-)A2-A26-AF2-2A25-2A2-3A23-3A3-3A21-3A4-4A19-4A5-4A17-4A8-3A15-3A2(13-A)17-A11-A14-2(E19-D10-)P19-D10-P4(19-A10-A)19-A10-U19-A11-2(A17-A12-)F17-A12-A17-R12-A17-D12-A17-H13-A15-G14-A15-S2(14-A15-A)14-N15-A8-A5-A15-A5-2(A2-A27-)F2-2A25-AQ3-2A23-AF4-3A21-3A4-4A19-4A5-4A17-4A7-4A15-4A11-2(A15-)A13-A17-2A9-2A15-2(E17-D12-)T2(17-A12-P)17-A12-A17-F3(12-A17-A)12-2A15-2A12-FA15-2A12-QA15-2A12-FA15-AR13-A15-D14-A15-H14-A15-G14-A15-S14-A15-A14-N15-K15-A13-A10-A5-A13-A5-2(A4-)AB13-2A2(4-A)25-A4-2A23-AF4-3A21-3A5-3A19-3A6-AJ2A17-4A7-4A16-3A10-2A15-2A14-2A11-2A17-2A9-2A20-A7-A18-I15-D14-E2(15-D14-T)3B5A2B6A14-PB2A2(BA)2(B2A)BAF14-P2BA3B2(3AB)AQ14-2(AB2AB)2A2(BA)F14-A2(B2A2(BA))BA14-A3BAB3A2B2ABABC14-17A14-5AB3AB6AC14-F4AB3AB7A14-5AB3AB6AR14-5AB3AB5ARD14-5ABA5B3ADH15-K13AH16-14AG16-4(AB)2A4BS16-K5(BA)B3A16-ABA3BA2(2B2A)11-2(CA)-6(AB)3A-2(AK)6-AO4A2BAB2AB3A3B6A6-CAC20AKA6-22AK2A7-K18A2M2J8-2AK5A3BA4B4A2JA9-3J4AB3AB6AJ2A12-J2(4AB)6A15-4A2B4AB4A17-3AB6AB2A19-2A3BA4BA22-7A20-I11E3D16-2I4E5IY3D16-TI3T2I2P2AWADA16-2TIT2I2P2AW4A16-3T2I2P5AW2A16-2P2I2P4AW2AWF16-P3IP6AW3A16-2AI4AFAW4AW16-2(AI)2AFQF4ACA16-I3AI2AF3AK2AO16-2(2AI)7ACA16-AI6ACAC3AK16-3AIRAK2AO2AK2A17-2A2DR2ACAC3A18-AK2HDR6AR18-2A2GHDR2AKARD18-2A2SGHD4RDH18-2AKASGH4DHG18-5ASG4HGS18-3AFAKS4GSA18-KAFQF2A4SKA17-4AF8AKA14-3AKA2(K2A)2M3J3A12-K4AJ6AM4AKA12-2AKA6J2G2AM4J13-2A2J3M2GV2G2A3M15-J4M2GVGV2G2AM16-4MAGV3GVG3A18-M2A2GVGV2GA20-4A2GV2G2A21-4A3G2A42-
