model
size = 13 24 28, scale = 0.05, origin = -y
material 
  colors = A:#6AB3CC B:#62593B C:#111 D:#EEE E:#6F6936 F:#FF0 G:#FF3
voxels
-----BBB----- -----CCC----- ------------- ------------- ------------- ------------- ------------- ------------- ------------- ------------- ------------- ------------- ------------- ------------- ------------- ------------- ------------- ------------- ------------- ------------- ------------- ------------- ------------- ------------- 
---BBBBBBB--- ---CCCBCCC--- -----CFC----- -----AAA----- ------------- ------------- ------------- ------------- ------------- ------------- ------------- ------------- ------------- ------------- ------------- ------------- ------------- ------------- ------------- ------------- ------------- ------------- ------------- ------------- 
--BBBBBBBBB-- --CCCCBCBCC-- ----FCCCF---- ----ACCCA---- -----AAA----- ------------- ------------- ------------- ------------- ------------- ------------- ------------- ------------- ------------- ------------- ------------- ------------- ------------- ------------- ------------- ------------- ------------- ------------- ------------- 
-BBBBBBBBBBB- -CCCCCBCBCCC- ---CCCCCCC--- ---ACCCCCA--- ---AACCCAA--- ----AAAAA---- ------------- ------------- ------------- ------------- ------------- ------------- ------------- ------------- ------------- ------------- ------------- ------------- ------------- ------------- ------------- ------------- ------------- ------------- 
-BBBBBBBBBBB- -CCCCCBCBCCC- --FCCCCCCCF-- --ACCCDDCCA-- ---ACCDDCA--- ---AACDDAA--- -----AAA----- ------------- ------------- ------------- ------------- ------------- ------------- ------------- ------------- ------------- ------------- ------------- ------------- ------------- ------------- ------------- ------------- ------------- 
BBBBBBBBBBBBB CCCCCCBCBBBBC -CCCDCCCCCCC- --ACDDDDCCA-- --ACDDDDCCA-- ---ACDDDCA--- ----AAAAA---- ------------- ------------- ------------- ------------- ------------- ------------- ------------- ------------- ------------- ------------- ------------- ------------- ------------- ------------- ------------- ------------- ------------- 
BBBBBBBBBBBBB CBBBBBBBBBBBC -FCCCCCCCCCF- -ACCDDDDCCCA- --ACDDDDCCA-- ---ACDDDCA--- ----AAAAA---- ------------- ------------- ------------- ------------- ------------- ------------- ------------- ------------- ------------- ------------- ------------- ------------- ------------- ------------- ------------- ------------- ------------- 
BBBBBBBBBBBBB CBBBBBBBBBBBC -CCCCCCCCCCC- -ACCDDDDCCCA- -AACDDDDCCAA- ---ACDDDCA--- ----AAAAA---- ------------- ------------- ------------- ------------- ------------- ------------- ------------- ------------- ------------- ------------- ------------- ------------- ------------- ------------- ------------- ------------- ------------- 
BBBBBBBBBBBBB CBBBBBBBBBBBC -FCCCCCCCCCF- -ACCDDDDCCCA- -AACDDDDCCAA- --AACDDDCAA-- ----AAAAA---- ------------- ------------- ------------- ------------- ------------- ------------- ------------- ------------- ------------- ------------- ------------- ------------- ------------- ------------- ------------- ------------- ------------- 
BBBBBBBBBBBBB CBBBBBBBBBBBC -CCCCCCCCCCC- -AACDDDDCCAA- --ACDDDDCCA-- --AACDDDCAA-- ----AAAAA---- -----AAA----- ------------- ------------- ------------- ------------- ------------- ------------- ------------- ------------- ------------- ------------- ------------- ------------- ------------- ------------- ------------- ------------- 
BBBBBBBBBBBBB CBBBBBBBBBBBC -FCCCCCCCCCF- -ACCDDDDDCAA- --ACDDDDDAA-- ---ADDDDDA--- ---ADDDDDA--- ----AAAAA---- ------------- ------------- ------------- ------------- ------------- ------------- ------------- ------------- ------------- ------------- ------------- ------------- ------------- ------------- ------------- ------------- 
BBBBBBBBBBBBB CBBBBBBBBBBBC CDDCCCCCCCCCC -ACCDDDDDCCA- --ACDDDDDCA-- ---ADDDDDA--- ---ADAAADA--- ---AA---AA--- ----C---C---- ------------- ------------- ------------- ------------- ------------- ------------- ------------- ------------- ------------- ------------- ------------- ------------- ------------- ------------- ------------- 
------------- BBBBBBBBBBBBB CDGCCCCCCCCCC -FCCDDDDDCCF- -AACDDDDDCAA- ---ADDDDDA--- ---ADDDDDA--- ---ADAAADA--- ---ADC-CDA--- ----A-C-A---- -----C-C----- ------------- ------------- ------------- ------------- ------------- ------------- ------------- ------------- ------------- ------------- ------------- ------------- ------------- 
------------- BBBBBBBBBBBBB CDDCCCCCCBBBC -CCCDDDDDCCC- -AACDDDDDCAA- ---ADDDDDA--- ---ADDDDDA--- ---ADDDDDA--- ---ADAAADA--- ---AA---AA--- ----A---A---- ----C---C---- ------------- ------------- ------------- ------------- ------------- ------------- ------------- ------------- ------------- ------------- ------------- ------------- 
------------- BBBBBBBBBBBBB CDGCCCCCCBBBC -FCCDDDDDCCF- -AACDDDDDCAA- ---ACCCCCA--- ---ACAACCA--- ---ACCCCCA--- ---ADDDDDA--- ---ADAAADA--- ---AA---AA--- ---AA---AA--- ----AC-CA---- ----A-C-A---- ----AC-CA---- ----C---C---- ----AC-CA---- ----A-C-A---- ----AC-CA---- ----C---C---- ------------- ------------- ------------- ------------- 
------------- BBBBBBBBBBBBB CDDCCCCCCBBBC -CCCDDDDDCCC- -AACDDDDDCAA- ---AAAAAAA--- ---A-----A--- ---A-----A--- ---A-----A--- ---A-----A--- ---ADAAADA--- ---ADAAADA--- ---AA---AA--- ---AA---AA--- ---AC---CA--- ---AAAAAAA--- ---AAAAAAA--- ---AAAAAAA--- ---AAAAAAA--- ---CAAAAAC--- -----AAA----- ------------- ------------- ------------- 
------------- BBBBBBBBBBBBB CDBCCCCCCCBBC -FCCDDDDDCCF- -AACDDDDDCAA- ---AAAAAAA--- ---A-----A--- ---A-----A--- ---A-----A--- ---A-----A--- ---AAAAAAA--- ---AAAAAAA--- ---AAAAAAA--- ---AAAAAAA--- ---AAAAAAA--- ---AA---AA--- ---AA---AA--- ---AA---AA--- ---AA---AA--- ---CA---AC--- ----A---A---- ------------- ------------- ------------- 
------------- BBBBBBBBBBBBB CDDCCCCCEEEBC CDDDDDDDBCDDC -AACDDDDDCAA- ---AAAAAAA--- ---A-----A--- ---A-----A--- ---A-----A--- ---A-----A--- ---A-----A--- ---A-----A--- ---A-----A--- ---A-----A--- ---A-----A--- ---A-----A--- ---A-----A--- ---A-----A--- ---A-----A--- ---C-----C--- ------------- ------------- ------------- ------------- 
BB----------B BBBBBBBBBBBBB BBBCCCCCEEEEB CDDDDDDDBCDDC -FCCDDDDDCCF- -AAAAAAAAAAA- ---A-----A--- ---A-----A--- ---A-----A--- ---A-----A--- ---A-----A--- ---A-----A--- ---A-----A--- ---A-----A--- ---A-----A--- ---A-----A--- ---A-----A--- ---A-----A--- ---A-----A--- ---C-----C--- ------------- ------------- ------------- ------------- 
BBBB------BBB BBBBBBBBBBBBB BBBCCCCCEEEEB CDDDDDDDBCDDC -CCCDDDDDCCC- -AACAAAAACAA- ---A-----A--- ---A-----A--- ---A-----A--- ---A-----A--- ---A-----A--- ---A-----A--- ---A-----A--- ---A-----A--- ---A-----A--- ---A-----A--- ---A-----A--- ---A-----A--- ---A-----A--- ---C-----C--- ------------- ------------- ------------- ------------- 
BBBBBBBBBBBBB BBBBDDDEEEEEB BBBCCCCCEEEEB CDDDDDDDBBDDC -FCCDDDDDCCF- -ACCAAAAACCA- --AA-----AA-- ---A-----A--- ---A-----A--- ---A-----A--- ---A-----A--- ---A-----A--- ---A-----A--- ---A-----A--- ---A-----A--- ---A-----A--- ---A-----A--- ---A-----A--- ---A-----A--- ---C-----C--- ------------- ------------- ------------- ------------- 
BBBBBBBBBBBBB BBBBDBDEEEEEB BBBCCBCCEEEEB CDDDDBDDBBDDC -CCCDBDDDCCC- -ACCAAAAACCA- --AA-----AA-- --AA-----AA-- ---AA---AA--- ---A-----A--- ---A-----A--- ---A-----A--- ---A-----A--- ---A-----A--- ---A-----A--- ---A-----A--- ---A-----A--- ---A-----A--- ---A-----A--- ---C-----C--- ------------- ------------- ------------- ------------- 
BBBBBBBBBBBBB BBBEBBDEEEEEB BBBCBBCCEEEEB CDCCBBCCCCCCC -FCCBBDDDCCF- -ACCAAAAACCA- --AC-----CA-- --AA-----AA-- ---AA---AA--- ---AA---AA--- ---AA---AA--- ---A-----A--- ---A-----A--- ---A-----A--- ---A-----A--- ---A-----A--- ---A-----A--- ---A-----A--- ---A-----A--- ---C-----C--- ------------- ------------- ------------- ------------- 
-BBBBBBBBBBB- -BBEBBBBBEEB- -BBEBCCCEEEB- -CCCBCCCCCCC- --CCBDDDCCC-- --ACAAAACCA-- --ACA---ACA-- ---AA---AA--- ---AA---AA--- ---AA---AA--- ---AA---AA--- ---AA---A---- ---AA---A---- ---AA---A---- ---AA---A---- ---AA---A---- ---AA---A---- ---AA---A---- ---AA---A---- ---CC---C---- ------------- ------------- ------------- ------------- 
--BBBBBBBBB-- --BEBBBBBEB-- --BEGCCCEEB-- --CCCCCCCCC-- ---FCDDDCF--- ---AADDDAA--- ---AAAAAAA--- -----AAA----- -----AAA----- -----AAA----- -----AAA----- -----AAA----- -----AAA----- ----AAAAA---- ----AAAAA---- ----A---A---- ----A---A---- ----A---A---- ----A---A---- ----C---C---- ------------- ------------- ------------- ------------- 
--BBBBBBBBB-- --BBBBBBBBB-- --BBBBBBBBB-- --CCCCCCCCC-- -----FCF----- -----AAA----- ------A------ ------------- ------------- ------------- ------------- ------A------ -----AAA----- -----AAA----- -----AAA----- -----AAA----- ----AAAAA---- ----AAAAA---- ----AAAAA---- ----CAAAC---- -----CFC----- -----CFC----- ------------- ------------- 
---BBBBBBB--- ---BBBBBBB--- ----BBBBB---- ----CCCCC---- ------------- ------------- ------------- ------------- ------------- ------------- ------------- ------------- ------------- ------------- ------------- ------------- ------------- ------------- ------------- ------------- ------------- -----CFC----- -----CFC----- ------------- 
------------- ------------- ------------- ------------- ------------- ------------- ------------- ------------- ------------- ------------- ------------- ------------- ------------- ------------- ------------- ------------- ------------- ------------- ------------- ------------- ------------- ------------- -----CFC----- -----CFC----- 
