model
size = 9 10 16, scale = 0.05, origin = -y
material 
  colors = A:#EEE B:#444 C:#0B0 D:#00E E:#777 F:#E00
voxels
--------- --------- --BBBB--- --BBBB--- --BBBB--- --------- --------- --------- --------- --------- 
--------- -B----B-- -B----B-- -B----B-- -BB--BB-- --BBBB--- --BBBB--- --AAAA--- --------- --------- 
--------- B------B- B------B- B------B- BB----BB- -B----B-- -A----A-- -CAAAA--- -CCC----- --------- 
B------B- B------B- B------B- B------B- B------B- A------A- -A----A-- --AAAA--- ---C----- --------- 
--------- --------- E------E- E------E- E------E- A------A- -A----A-- --AAAA--- ---C----- --------- 
--------- --------- E------E- E------E- A------A- A------A- A------A- -AAAAAA-- ---C----- ---C----- 
--------- --------- E------E- A------A- A------A- A------A- A------A- -A----A-- --AAAA--- ---C----- 
--------- --------- A------A- F------F- F------AD A------A- A------A- -A----A-- --AAAA--- ---C----- 
--------- --------- F------F- A------A- A------AD A------A- A------A- -A----A-- --AAAA--- ---C----- 
--------- --------- A------A- F------F- F------AD A------A- A------A- -AAAAAA-- ---C----- ---C----- 
--------- --------- -A----A-- -A----A-- -A----ADD -A----A-- -AAAAAA-- ---C----- ---C----- --------- 
--------- --------- --A--A--- --A--A--- --AAAADD- --AAAA--- ---C----- ---C----- --------- --------- 
--------- --------- --A--A--- --AAAA--- --AAAAD-- ---C----- ---C----- --------- --------- --------- 
--------- --------- --AAAA--- --AAAA--- ---C-DD-- ---C----- --------- --------- --------- --------- 
--------- --------- --AAAA--- ---C-D--- ---C-D--- --------- --------- --------- --------- --------- 
---C-D--- ---C-D--- ---C-D--- ---C-D--- --------- --------- --------- --------- --------- --------- 
