model
size = 24 32 30, scale = 0.05, origin = -y
material 
  colors = A:#FC9 B:#EEE C:#010 D:#F96 E:#800 F:#C63 G:#020 H:#E00
voxels
275-A23-A742-3A22-2(A23-)A693-2(AF)A20-3(3A21-)3A22-A21-C3AC15-4C5A4C14-4(7A17-)6A19-4A237-3A19-A5DA17-A5-A17-A5BA17-A5DA16-2A5C2A15-2C5A2C13-2C9A2C15-5A18-7A18-3(5A19-)5A20-3A16-13A12-11A13-13A11-13A2(10-14A)10-13A11-12A14-9A18-3A163-7A16-9A15-2AD3AD2A15-2A5E2A15-2AB3AB2A15-2AD3AD2A15-2AC3AC2A15-2C5A2C13-2C9A2C13-9A13-13A11-7A-5A11-13A10-2A3B3A-A3B2A9-A2BGB2A-2ABG2BA9-A4B5A4BA9-15A9-5A5-5A4(9-4A7-4A)9-4A6-4A11-4A3-6A10-13A14-9A17-5A115-5A17-8A16-4(9A15-)3A-A-3A15-3A3-3A15-AHA3-3A15-4A-4A13-13A10-16A8-5A-10A8-5A2-A-7A8-2A3BA2-A-A2B2(3A8-2A3B2A2-A3B)3A7-7A3-A-5A7-6A5-6A7-4(3A11-2A8-)3A11-2A9-2A10-3A9-3A8-3A12-4A2-5A14-9A17-5A90-7A16-3A4-2A15-3A3-3A15-4A2-3A15-3A3-3A15-2A2-2A-2A15-2A2(-A)-2A15-2A-3A-2(2A15-2A5-)2A13-5A4-4A10-5A2-A2-6A8-4A2-3A2-5A7-6A2-2A2-5A7-3A3BA4-A2B3A7-3A3B2A2-A3B3A7-3A3B-A2-A3B3A7-3A2(3-A)3-3A7-3A-2A5-A-4A2(7-2A-2A)4(7-2A13-2A)8-2A11-2A9-2A11-2A10-2A9-2A12-3A5-3A14-9A17-7A63-9A2(15-2A5-2A)13-4A5-4A11-4A2-2A-4A11-4A-A2-5A11-5A3-A-3A11-3A-A2-2A-3A11-2(3A2-)3A11-3A7-2A11-5A6-4A8-5A3-A3-5A7-2A5-3A5-2A7-2A2-2(A3-)2A-2A7-2A-ABA5-A2B3A6-4A3BA3-A3B4A5-2A-A3B2A2-A3B4A5-2A-3(A3-)A-2A6-2A-3A5-3A-3A6-2A2(13-3A5-3A)14-2A5-2A15-2A5-3A14-2A5-3A13-2A6-3A13-2A8-2A11-2A10-2A9-2A12-3A5-3A14-9A17-5A41-9A15-2(2A2-)2A14-2A6-3A11-3A7-3A11-4A2-2A2-3A11-4A-A2-2(A-3A11-3A-A3-)A-3A11-3A-A2-2A-3A9-5A2-3A3-3A8-4A9-4A6-2A-2A10-A-2A5-2A-2A4-A5-A-2A5-2A-A11-A-2A5-2A-A-2A5-3A-3A5-6ABA3-A3B4A5-3A-A2BCA2-A3B4A6-2A-A2-A4-A2-4A6-2A2-2A6-2A-3A6-2A13-3A5(5-2A15-2A)5-3A13-2A7-2A13-2A8-2A11-2A10-3A7-3A12-5A-5A15-7A20-A19-10A12-13A2(11-3A2(3-2A))11-3A2(2-A)2-2A11-3A-A3-A-3A2(11-3A-A4-4A)11-3A-A-3A-4A8-2A-2A2-3A3-3A8-3A-A8-4A6-2(3A2-A8-A-3A5-)3A-A9-A-3A5-3A2(-A)5-A2-A-2A5-2A2-2ABA3-AB3A-2A6-3A-ABA3-A2B5A5-4A-2A5-9A3-3A13-5A3-3A14-3(4A3-2A15-)3(3A4-2A15-)2A6-2A13-2A7-2A13-2A8-3A9-3A10-4A5-4A13-9A17-5A16-4A4-3A12-6A2-5A11-2A2-6A2-2(2A10-2A3-4A3-)2A10-2A2-A2-2A2-3A10-3A-A4-A-3A10-4A4-2A-3A10-3A-A-3A2-3A8-5A2-4A-A-2A8-3A-A7-A-4A5-4A-A7-A-6A3-2A2(-A)7-A-2A-3A3-3A2-A7-A3-4A3-2A2-A9-2A-4A3-4A2-A5-A2-6A3-4A2-A4-ABA2-5A3-3A9-A3-5A3-3A14-3(4A2-3A15-)4A2-2(2A16-3A3-)2A16-3A4-2A15-2A5-2A15-2A6-2A13-2A8-2A11-3A9-3A7-4A11-11A15-7A15-2A6-A14-5A4-4A10-2A2-3A2-6A3(9-2A3-2(2A2-)2A)2(9-3A-A4-2A2-2A)9-3A2-6A-4A7-3A-A2-6A-4A6-3A-A5-2(A-)4A6-3A2-A6-2(A-)3A4-4A2-A6-A-5A3-3A4-A6-A3-4A2-3A-3A8-2(3A-)5A13-11A9-A4-9A16-8A16-4A-3A16-3A2(2-3A15-4A)3(2-2A17-3A)3-2(2A15-2A5-)2A15-2A6-2A13-2A8-3A9-3A10-13A12-10A37-3A8-2A10-5A6-4A9-2A2-2A4-2A2-2A8-2A3-2A2-3A2-2A8-2A3-2A2-2A3-2(2A8-2A2-A5-2A2-)2A7-2A2-2A4-3A2-2A7-2A-A2-6A-A-3A6-2A-A3-4A-A-4A5-4A-A2-2(A-)A2-4A4-3A-A2-A-2(A4-)2A3-2A-4A8-3(3A-)A14-5A-3A15-4A2-3A16-2A3-3A16-3A2-2A17-3A-3A17-4A-4(2A17-3A2-)2A17-3A3-2A16-2A4-2A15-2A5-2A15-2A6-2A13-2A8-2A11-2A10-6A-7A11-11A36-2A21-4A8-3A9-2A-2A6-5A2(8-2A-3A4-3A-2A)7-2A2-3A4-3A-2A7-2A2-2A5-A-A2-2A6-2A-4A3-4A2-2A6-2A-10A-A-2A6-3A-6A2-2(A-)2A5-4A-5A-2A3-3A4-4A3-5A2-A2-4A3-2A2-3A2-A5-2A-4A-3A16-5A-3A16-2A4-FA16-AF3-2A17-3A2-2A17-3A-3A17-4A-5(2A17-3A2-)2A17-3A3-2A16-2A4-2A15-2A6-2A13-3A6-3A11-3A9-4A5-5A11-11A60-2A10-A10-4A8-4A7-2A-3A7-5A6-2A-3A5-4A-2A6-2A-4A4-4A-2A6-2A-2A8-2A-2A6-2A-2A5-A2-2A-2A6-2A-4A2-4A-A-2A5-2A-A-3A-4A2-A-2A5-2A-A2-2A-3A-A-4A5-2A-13A2-2A3-2A7-A9-3A-3A17-8A16-2(7A17-)7A18-3A-2(2A18-2A2-)5(2A17-3A2-)2A17-2A4-2A15-2A5-3A14-2A6-3A11-3A9-4A5-5A11-11A83-3A11-A8-4A10-3A7-2(2A-2A9-4A6-)2(4A10-4A6-)5A5-A-6A5-2A-3A5-2A3-3A5-2(2A2-)4A-3A-2A5-2A3-6A-3A2(3-2A)5-2A3-3A4-2(3A3-2A16-)3A6(2-2A18-2A)4(2-2A17-3A)2-2A17-2A4-2A16-2A4-2A15-2A6-3A11-3A8-5A5-5A11-11A107-2A12-A8-4(4A11-2A7-)2A-A10-4A6-5A2-3A3-5A6-2A2-10A-3A5-2A4-2A3-3A3-2A5-2(2A16-2A4-)2A16-3A10(2-2A18-2A)2-2A17-2A3-2A17-2A4-2A15-2A6-3A11-3A8-5A5-5A11-11A131-3(2A22-)2A3-2A2-2A4-A8-2(A-)8A-4A6-18A5-3A2-3A3-2A-A2-2A5-2A7-2A2-A3-2A5-2(2A16-2A4-)2A16-3A2-2A17-3A10(2-2A18-2A)2-2A17-2A4-2A15-3A5-3A11-4A7-5A5-5A11-11A203-A2-4A2-3A11-14A-2A6-6A3-2A3-5A5-2A6-4A2(-A)-2A5-2A6-A2-A2(5-2A)2(7-2A)4-2A16-2A3-2A17-3A11(2-2A18-2A)2-2A17-2A4-2A15-3A5-3A11-4A7-5A5-5A11-11A203-A2-4A2-3A2-2A7-18A5-2A-2A3-2(A2-)2A-2(2A5-)A2-A-A5-2A4-2A5-A-3A6-2A4-2A6-2A8-2A4-2A16-2A3-12(2A18-2A2-)2A17-2A4-2A15-2A6-3A11-3A8-5A5-5A11-11A207-2A3-2A12-8A-8A6-6A-A2-A-7A2(5-2A)-2A6-2A4-2A6-3A7-2A4-2A7-A8-2A4-2A16-2A4-2A17-11(2A2-2A18-)2A3-2A16-2A5-2A14-2A7-3A10-3A9-5A4-5A12-10A207-3A-3A13-15A8-5A2-2A-A-5A6-2A6-3A6-2A5-2A7-A8-3(2A4-2A16-)2A4-2A17-9(2A2-2A18-)2A3-2A16-2A4-2A16-2A5-2A14-2A7-3A10-3A9-5A3-6A12-10A206-9A13-13A10-3A4-2A3-4A7-2A13-3A5-2A15-2A5-2(2A16-2A4-)2A17-2A3-2A17-8(2A2-2A18-)2A3-2A17-2A3-2A16-2A5-2A14-2A7-2A12-2(3A8-)4A10-12A14-8A208-A5-2A13-13A10-4A-5A2-3A8-2A13-2A7-2A14-2A5-3(2A16-2A4-)8(2A17-2A3-)2A16-2A4-2A16-2A5-2A14-2A6-2A14-2A7-3A10-3A9-4A6-4A12-10A16-6A231-6A-5A11-14A9-2A6-A5-2A7-2A13-2A7-2A14-2A6-2A15-2A5-2A15-2A4-3A15-3(2A4-2A16-)2A4-2A17-2A3-2(2A16-2A4-)2A16-2A5-2A15-2A5-2A14-2A6-3A13-2A7-2A12-2A9-3A8-3A11-12A14-8A262-2A14-12A11-14A9-3A10-3A8-2A12-2A8-2A13-2A7-2A13-2A6-3A13-3A5-2A14-3A5-2A15-2A2(5-2A14-3A)5-2A14-2A5-3A14-2A6-3A2(13-2A7-2A)12-2A8-3A10-3A9-4A7-3A10-13A14-8A310-2A14-12A11-14A10-3A3-A4-3A10-2(2A11-2A9-)2A5(11-3A7-3A)11-2A2(8-3A10-3A)2(9-3A)9-4A7-3A11-13A11-12A14-8A375-10A13-12A12-14A2(10-2A8-4A)2(9-3A8-4A)9-2(3A8-3A10-)4A6-4A10-5A5-4A2(11-13A)11-12A13-10A16-7A424-3A-4A15-8(11A13-)10A14-10A15-9A16-7A520-5(8A16-)8A17-6A19-5A225-
