model
size = 3 23 32, scale = 0.05, origin = -y
material 
  colors = A:#111 B:#950000 C:#8A0000 D:#141414 E:#AB0000
voxels
-2(C2-)2(E2-)2(B2-)2(E2-)E47-C2-B-B2(C2B)CB3CBC2BCB-2(B2-)E44-B2-B-B4(C2B)CBECEBCB-B2-C44-E2-E-B5(C2B)CB3C-E47-B-B6(C2B)CB-E47-B-B4(C2B)CBEC2ECE-C47-B-ECEB3(C2B)CBECE3C-A47-B-B2(C2B)CBEC2ECE3C3A-A47-C-3CEC2ECE6C6A-A47-C-9C9A-A50-A-12ADAD-A53-D-3ADAD9A-A53-A-12A-A53-A-3ADA2DAD6A-A53-A-3ADA2DAD3A-A56-A-6ADAD-A53-D-15A-A50-A-DAD3ADAD6A-A53-A-DAD3ADA2DAD-A53-A-2(3ADAD)-D50-A-3ADAD9A-D50-A-6ADAD6A-A53-D-3ADA2DAD3A-A53-A-6ADA2DAD-A50-A-9ADA2DAD-D47-A-3A4D2(AD)4ADAD-D47-A-3A9-6A-A47-A-DAD9-3ADAD-A47-A-3A9-6A-A47-A-12ADAD-A53-A2-D-6A-A62-A2-A10-
