model
size = 32 24 18, scale = 0.05, origin = -y
material 
  colors = A:#444 B:#555 C:#111
voxels
579-B24-A2(6-2A22-2A)7-A22-A582-2(2A24-BA4-)2A24-BA5-AB2(22-BA6-BA)22-2B7-A22-B453-2A26-2B2-2B26-2B3-A26-B2(4-AB24-2A)4-AB24-2B4-2B24-AB5-AB22-2A6-AB22-BA6-2A22-AB163-2A28-4A28-2A-A28-A-2A28-B3A28-4A28-B3A28-AB2A28-2A-A28-B2-2A26-2A2-AB26-2A2-2B26-2A2-AB26-AB2-A-A24-A-A3-2A24-2A2(4-2A24-AB)5-AB22-2A6-2A22-AB99-AB28-3AB10(28-4A)28-2A-3(2A26-2A2-)2A26-2A3-2(2A24-2A4-)2A24-2A5-A24-A6-2A22-2A99-C2(B28-3C)B10(28-4C)28-2C-2(2C26-2C2-)2C26-2C3-C26-C2(4-2C24-2C)5-C24-C6-2C22-2C67-C30-3C28-3CA28-3CB9(28-4C)28-2C-C28-C3(2-2C26-2C)3-C26-C2(4-2C24-2C)5-C24-C6-2C22-2C67-2A2(28-2ABA)8(28-4A)28-2ABA28-4A28-2A-A28-A2(2-BA26-2A)2-2A26-2A3-2(2A24-2A4-)2A24-2A5-2A22-2A6-2A22-2A67-BA2(28-4A)28-2ABA2(28-4A)28-3AB28-B2AB28-B3A28-4A2(28-2ABA)28-2A-2A2(26-2A2-BA)26-BA2-2A26-BA2-A-A24-A-A3-BA24-2A4-2A24-2A5-2(2A22-2A6-)2A22-2A36-3(A28-A2-)A28-A-BA28-4A28-B3A28-B2AB28-BA2B28-B2AB28-4A28-2AB-B26-A-2B-B26-2(A-)AB26-BA2-AB26-2A2-B-B24-A-A2-A-B24-A-B3-AB24-AB4-BA24-2A4-A-A22-B-B5-2A22-AB6-BA22-2A7-BA20-2A37-AB26-2A2-AB2(26-BA2-2A)26-B2(A-)A26-A-2A-A26-2(A-)2A26-BA2-2A26-2B2(-A)26-2(A-)2A26-BA2-2A26-2B2-2B26-BA2-AB26-2B2-A-B24-B2(-A2-A-A24-A)-A3-A-A22-B-B4-A-A22-A-B5-AB22-2B6-AB22-AB6-A-B20-B-B7-2B20-AB8-2AB18-3A37-3A24-3A2-B-A24-A-B2-A-B24-A-A2-B-A24-A-B2(2-B-A24-A-A)2-A-A24-A-A2-A-A24-B-B2-B-B24-A-B2-A-A24-A-A2-B-A24-B2(-A2-A-A24-A)-2(A2-)B22-B2-A3-A-A22-B-A4-A-A22-A-A4-A2-A20-B2-A5-A-A20-A-A6-A-B20-A-A7-AB20-2B8-B-B18-A-B9-B2A16-2AB10-3A16-3A39-2(2A24-AB4-)2(2A24-2A4-)2A24-2B4-2A24-BA4-A-A22-A-A3-BA-A22-A-BA3-A-A2(22-A-A4-A-B)2(22-A-A4-A-A)22-A-A4-A2-A20-A2-A5-B-A20-B-A6-A-A20-A-A6-A2-B18-A2-A6-A2-A18-A2-A7-A-A18-A-A8-B2A18-3A9-B-A16-A-A11-2A16-2A12-2A16-2A73-A24-B4(6-2A22-2A)2(6-2A22-AB)6-2A22-2A2(6-3A20-3A)6-3A20-3B6-3A20-2BA2(6-3A20-3A)7-2(3A18-3A8-)B2A18-3A9-BA18-2A11-2A-A12-A-2A12-2A-A12-A-BA12-A18-A170-A22-B8-A22-B14-A10-A14-A5-A10-A5-B8-A5-A10-A5-A14-A10-A19-2A10-BA18-BA10-2A19-A10-A19-BA10-2A18-2A10-2A19-2A8-BA18-4A8-4A16-AB-BA6-2A-2A2(16-2AB10-3A)16-A-B10-A-A16-2AB2A6-B2ABA17-AB3A4-A2B2A19-AB3A2C2A2BA22-3A2C3A150-3A6-3A20-ABA6-ABA20-B2A6-3A20-4A4-4A19-B-2AB4-2AB-A18-2AB3A2-2AB3A19-4AB2-2AB2A20-BAB2A2C2AB2A19-4ABA2-2AB3A18-A-2ABA2C2ABA-B18-A2-3A2CABA2-A17-AB2-3A2C2AB2-2A16-3A2-2A2C2A2-ABA17-2AB3A2CAB4A18-B2A2BA2CA2B2AB18-3A2BA2C4ABA19-2A2BA2C3A2B21-3BA2C3AB23-B2A2C3A25-2A2C2A92-2C27-3A2C3A23-AB2A2CA3B22-4A2C2A2B22-4A2C3AB22-2A-A2CA-AB21-B2A-A2CA-A2B21-3A-2C-BAB22-A3-2C3-B21-2AB6-3A21-BA2-2C2-2A21-4A4-B3A20-3A6-3A20-2ABA4-B3A21-B3A2C4A22-4A2C4A23-3A2CABA25-2B2CAB27-B2CA219-2A2C2A27-2(A2CB28-)A2CB27-2A2C2A26-2A2C2A27-A2CA26-ABA2C2BA25-AB2C2B26-AB2C2A27-A2CA27-BA2CAB27-A2CA270-
