model
size = 13 24 28, scale = 0.05, origin = -y
material 
  colors = A:#D00 B:#62593B C:#111 D:#EEE E:#6F6936 F:#FF0 G:#6AB3CC H:#FF3
voxels
-----BBB----- -----CCC----- ------------- ------------- ------------- ------------- ------------- ------------- ------------- ------------- ------------- ------------- ------------- ------------- ------------- ------------- ------------- ------------- ------------- ------------- ------------- ------------- ------------- ------------- 
---BBBBBBB--- ---CCCBCCC--- -----CFC----- -----AAA----- ------------- ------------- ------------- ------------- ------------- ------------- ------------- ------------- ------------- ------------- ------------- ------------- ------------- ------------- ------------- ------------- ------------- ------------- ------------- ------------- 
--BBBBBBBBB-- --CCCCBCBCC-- ----FCCCF---- ----ACCCA---- -----AAA----- ------------- ------------- ------------- ------------- ------------- ------------- ------------- ------------- ------------- ------------- ------------- ------------- ------------- ------------- ------------- ------------- ------------- ------------- ------------- 
-BBBBBBBBBBB- -CCCCCBCBCCC- ---CCCCCCC--- ---ACCCCAA--- ---AACCCAA--- ----AAAAA---- ------------- ------------- ------------- ------------- ------------- ------------- ------------- ------------- ------------- ------------- ------------- ------------- ------------- ------------- ------------- ------------- ------------- ------------- 
-BBBBBBBBBBB- -CCCCCBCBCCC- --FCCCCCCCF-- --ACCCDACCA-- ---ACCDDAA--- ---AACDAAA--- -----AAA----- ------------- ------------- ------------- ------------- ------------- ------------- ------------- ------------- ------------- ------------- ------------- ------------- ------------- ------------- ------------- ------------- ------------- 
BBBBBBBBBBBBB CCCCCCBCBBBBC -CCCDCCCCCCC- --ACDDDACCA-- --ACDDDACCA-- ---ACDADAA--- ----AAAAA---- ------------- ------------- ------------- ------------- ------------- ------------- ------------- ------------- ------------- ------------- ------------- ------------- ------------- ------------- ------------- ------------- ------------- 
BBBBBBBBBBBBB CBBBBBBBBBBBC -FCCCCCCCCCF- -ACCDDADCCCA- --ACDDDACCA-- ---ACDADAA--- ----AAAAA---- ------------- ------------- ------------- ------------- ------------- ------------- ------------- ------------- ------------- ------------- ------------- ------------- ------------- ------------- ------------- ------------- ------------- 
BBBBBBBBBBBBB CBBBBBBBBBBBC -CCCCCCCCCCC- -ACCDDADCCCA- -AACDDAACCAA- ---ACDADAA--- ----AAAAA---- ------------- ------------- ------------- ------------- ------------- ------------- ------------- ------------- ------------- ------------- ------------- ------------- ------------- ------------- ------------- ------------- ------------- 
BBBBBBBBBBBBB CBBBBBBBBBBBC -FCCCCCCCCCF- -ACCDDADCCCA- -AGCDDADCCGA- --AACDAAAAA-- ----AAAAA---- ------------- ------------- ------------- ------------- ------------- ------------- ------------- ------------- ------------- ------------- ------------- ------------- ------------- ------------- ------------- ------------- ------------- 
BBBBBBBBBBBBB CBBBBBBBBBBBC -CCCCCCCCCCC- -AGCDDADCCGA- --ACDDDACCA-- --AACDAAAAA-- ----AGGGA---- -----AAA----- ------------- ------------- ------------- ------------- ------------- ------------- ------------- ------------- ------------- ------------- ------------- ------------- ------------- ------------- ------------- ------------- 
BBBBBBBBBBBBB CBBBBBBBBBBBC -FCCCCCCCCCF- -ACCDDADDCGA- --ACDDAADGA-- ---ADDDDAA--- ---ADDDDAA--- ----AAAAA---- ------------- ------------- ------------- ------------- ------------- ------------- ------------- ------------- ------------- ------------- ------------- ------------- ------------- ------------- ------------- ------------- 
BBBBBBBBBBBBB CBBBBBBBBBBBC CDDCCCCCCCCCC -ACCDDADDCCA- --ACDDAADCA-- ---ADDDDAA--- ---ADAAAAA--- ---AA---AA--- ----C---C---- ------------- ------------- ------------- ------------- ------------- ------------- ------------- ------------- ------------- ------------- ------------- ------------- ------------- ------------- ------------- 
------------- BBBBBBBBBBBBB CDHCCCCCCCCCC -FCCDDDDDCCF- -AACDDAADCAA- ---ADDDDAA--- ---ADDDDAA--- ---ADAAAAA--- ---ADC-CAA--- ----A-C-A---- -----C-C----- ------------- ------------- ------------- ------------- ------------- ------------- ------------- ------------- ------------- ------------- ------------- ------------- ------------- 
------------- BBBBBBBBBBBBB CDDCCCCCCBBBC -CCCDDDDDCCC- -AACDDAADCAA- ---ADDDDAA--- ---ADDDDAA--- ---ADDDDAA--- ---ADAAAAA--- ---AA---AA--- ----A---A---- ----C---C---- ------------- ------------- ------------- ------------- ------------- ------------- ------------- ------------- ------------- ------------- ------------- ------------- 
------------- BBBBBBBBBBBBB CDHCCCCCCBBBC -FCCDDDDDCCF- -AACDDAADCAA- ---ACCCCAA--- ---ACGGCAA--- ---ACCCCAA--- ---ADDADAA--- ---ADAAAAA--- ---AA---AA--- ---AA---AA--- ----AC-CA---- ----A-C-A---- ----AC-CA---- ----C---C---- ----AC-CA---- ----A-C-A---- ----AC-CA---- ----C---C---- ------------- ------------- ------------- ------------- 
------------- BBBBBBBBBBBBB CDDCCCCCCBBBC -CCCDDDDDCCC- -AACDDAADCAA- ---AAAAAAA--- ---A-----A--- ---A-----A--- ---A-----A--- ---A-----A--- ---ADAAAAA--- ---ADAAAAA--- ---AA---AA--- ---AA---AA--- ---AC---AA--- ---AGAAAAA--- ---AGAAAAA--- ---AGAAAAA--- ---AGAAAAA--- ---CAAAAAC--- -----AAA----- ------------- ------------- ------------- 
------------- BBBBBBBBBBBBB CDBCCCCCCCBBC -FCCDDADDCCF- -AACDDAADCAA- ---AAAAAAA--- ---A-----A--- ---A-----A--- ---A-----A--- ---A-----A--- ---AAAAAAA--- ---AAAAAAA--- ---AAAAAAA--- ---AAAAAAA--- ---AAAAAAA--- ---AA---AA--- ---AA---AA--- ---AA---AA--- ---AA---AA--- ---CA---AC--- ----A---A---- ------------- ------------- ------------- 
------------- BBBBBBBBBBBBB CDDCCCCCEEEBC CADDDDADBCDAC -AACDDAADCAA- ---AAAAAAA--- ---A-----A--- ---A-----A--- ---A-----A--- ---A-----A--- ---A-----A--- ---A-----A--- ---A-----A--- ---A-----A--- ---A-----A--- ---A-----A--- ---A-----A--- ---A-----A--- ---A-----A--- ---C-----C--- ------------- ------------- ------------- ------------- 
BB----------B BBBBBBBBBBBBB BBBCCCCCEEEEB CADDDDADBCDAC -FACDDDADCAF- -AAAAAAAAAAA- ---A-----A--- ---A-----A--- ---A-----A--- ---A-----A--- ---A-----A--- ---A-----A--- ---A-----A--- ---A-----A--- ---A-----A--- ---A-----A--- ---A-----A--- ---A-----A--- ---A-----A--- ---C-----C--- ------------- ------------- ------------- ------------- 
BBBB------BBB BBBBBBBBBBBBB BBBCCCCCEEEEB CADDDDADBCDAC -CCCDDADDCCC- -AAAAAAAAAAA- ---A-----A--- ---A-----A--- ---A-----A--- ---A-----A--- ---A-----A--- ---A-----A--- ---A-----A--- ---A-----A--- ---A-----A--- ---A-----A--- ---A-----A--- ---A-----A--- ---A-----A--- ---C-----C--- ------------- ------------- ------------- ------------- 
BBBBBBBBBBBBB BBBBDDDEEEEEB BBBCCCCCEEEEB CADDDDADBBDAC -FACDDAADCAF- -ACAAAAAAACA- --AA-----AA-- ---A-----A--- ---A-----A--- ---A-----A--- ---A-----A--- ---A-----A--- ---A-----A--- ---A-----A--- ---A-----A--- ---A-----A--- ---A-----A--- ---A-----A--- ---A-----A--- ---C-----C--- ------------- ------------- ------------- ------------- 
BBBBBBBBBBBBB BBBBDBDEEEEEB BBBCCBCCEEEEB CADDDBADBBDAC -CACDBDADCAC- -ACAAAAAAACA- --AA-----AA-- --AA-----GA-- ---AA---AA--- ---A-----A--- ---A-----A--- ---A-----A--- ---A-----A--- ---A-----A--- ---A-----A--- ---A-----A--- ---A-----A--- ---A-----A--- ---A-----A--- ---C-----C--- ------------- ------------- ------------- ------------- 
BBBBBBBBBBBBB BBBEBBDEEEEEB BBBCBBCCEEEEB CDACBBCACCACC -FACBBDADCAF- -ACAAAAAAACA- --AC-----AA-- --AG-----GA-- ---AA---AA--- ---AA---AA--- ---AA---AA--- ---A-----A--- ---A-----A--- ---A-----A--- ---A-----A--- ---A-----A--- ---A-----A--- ---A-----A--- ---A-----A--- ---C-----C--- ------------- ------------- ------------- ------------- 
-BBBBBBBBBBB- -BBEBBBBBEEB- -BBEBCCCEEEB- -CACBCCACCAC- --CABDDDAAC-- --AAAAAAAAA-- --ACA---ACA-- ---AA---AA--- ---AA---AA--- ---AA---AA--- ---AA---AA--- ---AA---A---- ---AA---A---- ---AA---A---- ---AA---A---- ---AA---A---- ---AA---A---- ---AA---A---- ---AA---A---- ---CC---C---- ------------- ------------- ------------- ------------- 
--BBBBBBBBB-- --BEBBBBBEB-- --BEHCCCEEB-- --CACCCCAAC-- ---FCDDDCF--- ---AAAAAAA--- ---AAAAAAA--- -----AAA----- -----AAA----- -----AAA----- -----AAA----- -----AAA----- -----AAA----- ----AAAAA---- ----AAAAA---- ----A---A---- ----A---A---- ----A---A---- ----A---A---- ----C---C---- ------------- ------------- ------------- ------------- 
--BBBBBBBBB-- --BBBBBBBBB-- --BBBBBBBBB-- --CCCCCCCCC-- -----FCF----- -----AAA----- ------A------ ------------- ------------- ------------- ------------- ------A------ -----AAA----- -----AAA----- -----AAA----- -----AAA----- ----AAAAA---- ----AAAAA---- ----AAAAA---- ----CAAAC---- -----CFC----- -----CFC----- ------------- ------------- 
---BBBBBBB--- ---BBBBBBB--- ----BBBBB---- ----CCCCC---- ------------- ------------- ------------- ------------- ------------- ------------- ------------- ------------- ------------- ------------- ------------- ------------- ------------- ------------- ------------- ------------- ------------- -----CFC----- -----CFC----- ------------- 
------------- ------------- ------------- ------------- ------------- ------------- ------------- ------------- ------------- ------------- ------------- ------------- ------------- ------------- ------------- ------------- ------------- ------------- ------------- ------------- ------------- ------------- -----CFC----- -----CFC----- 
