model
size = 30 30 32, scale = 0.05, origin = -y
material 
  colors = A:#4A225D B:#000 C:#FFF D:#C92800
voxels
10-2(11A19-)11A829-2(11A19-)11A822-2(7A11B7A5-)7A11B7A815-2(7A11B7A5-)7A11B7A812-2(3A2(9B7D9B5A)9B7D9B2A95-2(7A7-7A9-)7A7-7A16-2(7A23-)7A551-)2(3A2(7B11D7B5A)7B11D7B2A3-2(9B7-9B5-)2(9B7-)2(7A7B7A9-)7A7B7A16-2(7A23-)7A551-)2(3A2(7B11A7B5A)7B11A7B2A3B2(2A21B2A5B)2A21B2A2B5-2(7A7B7A9-)7A7B7A18-8(3A27-)3A16-2(2B21A2B5-)2B21A2B7-2(5B11-5B9-)2(5B11-)2(5B7-4B14-)5B7-4B97-)3A2(2B21A2B5A)2B21A2B2A3B2(25A5B)25A2B5-3(16A2-3A9-)3(2A7C3A6C3A9-)3(2A3C2B2C3A2C2B2C3A9-)3(2A7C3A6C3A9-)2(21A9-)21A274-3A2(2B21A2B5A)2B21A2B2A3B2(25A5B)25A2B5-3(16A2-3A9-)3(2A7C3A6C3A9-)3(2A3C2B2C3A2C2B2C3A9-)3(2A7C3A6C3A9-)2(21A9-)21A277-2(5(25A5-)25A7-5(21A9-)21A11-5(16A14-)16A19-5(7A23-)7A194-)2(11(25A5-)25A7-5(21A9-)21A14-5(11A19-)11A21-2(7A23-)7A104-)6(11(25A5-)25A7-5(21A9-)21A11-5(16A14-)16A17-2(11A19-)11A21-2(7A23-)7A14-)2(11(25A5-)25A7-5(21A9-)21A14-5(11A19-)11A21-2(7A23-)7A104-)2(5(25A5-)25A7-5(21A9-)21A11-5(16A14-)16A19-5(7A23-)7A194-)5(25A5-)25A9-5(16A14-)16A17-5(11A19-)11A372-5(25A5-)25A9-5(16A14-)16A17-5(11A19-)11A374-5(21A9-)21A14-5(11A19-)11A554-5(21A9-)21A14-5(11A19-)11A559-5(11A19-)11A739-5(11A19-)11A729-
