model
size = 12 14 32, scale = 0.05, origin = -y
material 
  colors = A:#FFF7F0 B:#1E1E1E C:#323232 D:#3C3C3C E:#F60 F:#DB5700 G:#D45400 H:#CF6 I:#CFC J:#ED5F00 K:#D7387F L:#BB1313 M:#F06 N:#F3F O:#F00 P:#379D30 Q:#F09 R:#CFF S:#FF9 T:#F36 U:#CC6 V:#CC3 W:#D97708 X:#F33 Y:#F3C Z:#FFC Aa:#CC0 Ab:#F39 Ac:#124BC6 Ad:#FCF Ae:#FC6 Af:#F90 Ag:#F30 Ah:#CC9 Ai:#F93 Aj:#FC9 Ak:#FC0 Al:#F0F Am:#F9C An:#141414 Ao:#F99 Ap:#FC3 Aq:#FF0 Ar:#8D1204 As:#CCF At:#CF9 Au:#F66 Av:#F03 Aw:#CF0 Ax:#F69 Ay:#FCC Az:#F9F Ba:#FFF Bb:#F6F Bc:#F96 Bd:#FF3 Be:#F0C Bf:#F6C Bg:#FF6 Bh:#F63 Bi:#CF3 Bj:#CCC
voxels
4-4B8-4B151-2BDC2B6-B4AB7-AjAsAhAu139-B2(DC)B6-H4AAd6-RHUAkAmAf137-2B2(CD)2B4-M6AAg4-At6-Aa5-THAfTBfH124-2B6K2B2-Al8AAo3-H6-Ab4-QIAwIZRTAh123-BCDCKCDKDB2-Ah8ABb3-Ao6-M4-AvI4-AgAb6-VIHQ112-2BDCDKDCKC2BT10AM-H8-S3-N6-V5-HAqZAxIAs111-B2(DC)4KDCBAp10AI-Z8-Au3-Ao6-Ad4-S6EAo110-B5(CD)BT10AAi-O8-Aq3-Ba6-Ah4-E6AE6-4A100-BDC6AcDCBY10AAe-R8-Y2-Aw8-M3-E6-E5-6A99-B5(CD)BBc10ARQ10-Ay-T8-Aa3-E6-E4-An6LAn98-B2(DC2P)DCBN10AAsAq10-I-X8-N2-Aj8-At3-E6-E4-E6AE86-B2(CD)2P2(CD)BZ10AAiAo10-X-Bh8-Az2-X8-X3-Ag6-Y4-An6WAn86-B2(DC)2P2(DC)BBd10AAjS10-Am-Bi8-O2-Au8-Af3-Ae6-Az4-E6-E4-E6AE74-2B2(D2PC)2BM10AM-Aq8-R2-Ad8-V2-Ba8-Af3-Ae6-I4-Q6-Aq4-An6PAn75-B4(CD)B2-T8AAa2-H8-Ab2-Y8-Bf2-Ak8-I2-N8-O3-I6-Y4-E6-E4-E6AE63-BD6WCB2-At8AAg2-R8-Ap2-N8-T2-U8-M2-Ai8-Al3-S6-Ak4-U6-S4-An6AcAn63-BCW3(CD)B2-Ag8AAb2-M8-Ab2-Z8-Bc2-E8-Az2-R8-T3-X6-I4-Aj6-E4-E6-Q4-E6AE51-BDW3(DC)B2-Ab8AAh2-O8-Z2-Bd8-Af2-As8-X2-Bb8-R2-Af8-N3-Ae6-Ap4-V6-Q4-E6-E4-E6KAn39-B4(CD)B2-OA6GABe2-Ak8-X2-Az8-Ba2-Ay8-Ad2-Aj8-V2-I8-Bd2-O8-Ai3-U6-Ad4-O6-Az4-E6-E4-E6AE27-B4(DC)B2-IA6GAH2-X8-Az2-H8-Bh2-Y8-H2-O8-R2-I8-Af2-Bi8-Q2-Be8-U2-S8-H2-Bg8-S3-2E4A2E5-E4AE6-E4AE3-2B4(CD)2BBe2AG2A2G3AAkOAl8-UM2Ad8-AmI-O8-S2-Ae8-Ay2-U8-Bj2-Aa8-Bb2-M8-Av2-Aa8-U2-Q8-Aj2-J8-J16-6E3-B5(CD)BAg2AG2A2G3AAsBhAa8-AlApNBf8-AgAwOY8-MHAvN8-AwZBfAy8-AeZ-Ap8-Av2-Ak8-H2-Ao8-X2-Q8-V2-J8-J25-BDC6LDCBN2AG2A2G3AAiXH8-BbAvAiS8-AuNBeBa8-VAm2Ah8-YAjAuX8-BfBcAlU8-YV-Ap8-V2-V8-O2-J8-J37-B2(CD)LDCLCDBAf2A5G3AQZI8-AtOTAl8-Ak2HY8-YIAmBi8-AgHAmAa8-MAbAjS8-AeQ-Z8-Ah2-Aw8-N2-J8-J37-B2(DC)LCDLDCBT5A2G3AAiUQ8-URSAa8-AlTAoAa8-MEAiAv8-UNAdAk8-2R-Bc8-Q2-Y8-Ag2-J8-J49-B2(CD)4LCDBN5A2G3AAqEAa8-RAuAaBb8-MIAqI8-SX-E8-Q2-M8-Ah2-U8-N2-Bc8-M2-J8-J49-B5(DC)BAp4A4G2AHNAs8-AxBa-Ay8-R2-Z8-Av2-E8-S2-H8-Ak2-Y8-Aa2-V8-O2-J8-J49-2B3(DC)ArC2BAt10AAk-O8-Al2-Q8-Ae2-Z8-T2-Bg8-Am2-Bd8-I2-Ai8-Bg2-J8-J62-2B6Ar2B2-Aj-6A-Bd2-HV6-MH2-AbU6-UAd2-NQ6-AdBg2-AyAl6-AgAf2-XV6-AtAb2-HAe6-AbX2-2J6-2J63-2B2(DC)2B4-O6AO4-NAfAdBiAbEAmZ4-AwVAfAoT2AxN4-TAwBgAsMIApM4-BaAjAtBeAmBh2S4-Ah6FAe4-I6FI4-J6FJ6-4F55-6B6-Ax4BAx6-VS2FAaE6-RAb2FAeN6-AuO2FOAb6-QAq2FRAi7-3(4F8-)4F52-
