model
size = 32 28 22, scale = 0.05, origin = -y
material 
  colors = A:#222 B:#F0C C:#0C0 D:#111 E:#777 F:#FC3
voxels
45-2(2A2-2A26-)DA2-2A26-AD2-DE26-2A2-DC26-2A2-2C26-2A2-CD26-A4-D26-A31-E570-4A-2A2-2A5-A15-D3A-A-2A-A3-3A15-A2D2(A-)2A-A3-3A15-3A2(D-)2A-A3-3A15-4A-A-2D-E3-2AD15-A-2A2(-A)E2C4-D16-A-A2-A-E3C4-A16-A-A2-A-4C4-A16-A-A2-2A2CDC4-A18-A2-2A2CDC23-E2-2E-D2C26-2B2-2C2(26-BD2-2A)26-DB2(2-2A26-2B)2-2D26-BD2(30-2B)280-E7A2-A-6A14-D4-6A-3A2-A14-B4-A-3A-4A2-A15-A3-D-3A-A-2A2-A15-A3-A-3A-E-2A2-A15-2A2-A2-2A3CEADA16-2A-2A2-A5CEDA16-2A-2A2-6CD2(2A16-2A-2A2-7C)2A16-EA-2E2-A5C3A16-CE5BED3C3AE16-C6BDE2-3AE2C15-C8B2-2AE2C16-4BD4B2-2ACDC16-4BD4B2-A2D2C16-2D6BD2-DA3C16-7BDB4AD2C17-7B5A2-C18-2D3B5AD23-D6A25-AD5A153-2DFDF2D25-2DFDF2D17-2B-BA-2A5-9AE2C7-2B2-B3A5-2A6-E4C6-D3-B-2A-A3-2A6-2CD2C6-D3-B-2A-A3-3A5-CD3C6-D3-B2(3-2A)E5-D3C11-A3-3A2-3A4-2A3C11-A4-2A-4A4-3A2C11-A4-2A-4A4-4A11-E5-2A-4A4-4A10-CE5-2A-4A4-3A11-2C5-2A-3A5-3A11-D2C-A2-2A-3A5-2E12-D2C2(A-)6A5-AC12-3C2(A-)6A2-2A-C13-2C2A-A-6A2(-A)-C13-C-2A-A-8A-ACD15-2A-A-5A-2A-A2C15-D2(A-)5A2-A-A2C16-2(A-)2A-2A2-2(A-)D16-2(A-)2A-3A2(-A)18-2AD8AD-A20-8ADA22-2AD5ADA22-3AD2ACDC23-4AD4C23-4ACD3C2(23-9D)15-3BD3B9-2A2-3A2-C6-4BD2B-A7-A-7A2C5-7B-A7-A3-3A2-CD5-7B-A7-A3-3A2-2C5-2BD3B-2A7-A3-3A2-C6-2BDB2A2-A7-A2-4A2-C6-3BD3A2-A6-A2-3A3-C6-3AD3A2-A6-A2-2A2(-A)9-ED3A2-A6-A2-3A2-A9-CD3A2-A6-2A-3A2-A9-CDC2A2-A6-2A-3AE2A9-4CA2-A6-2A-2A2E-A9-4C2A-A6-2A2-A-C11-4C-3A6-2A4-C11-3C2-3A6-3A2-CD11-2CA2-3A7-2A-3C12-2A-4A2(2-A)-2A-3C12-AD5A5-2A-A-3C12-D2A-3A5-6A2C13-2A-3A6-5AD14-2A-2A7-3A-2A14-5A7-6A15-5A6-5A17-4A6-4A19-3A6-ACA20-3A6-A2C20-3D6-3D20-3D7-2D14-BA22-C7-BA3-3A8-2A5-A2C6-DA3-3A8-3A3-A-CD6-BA3-3A8-3A3-A-D7-BA3-3A8-3A3-A-C7-BA3-3A8-2A4-A-C7-2A4-2A8-2A3-2A-C7-2A4-2A8-2A3-A-A8-A-A3-2A8-2A3-A-A9-2E3-2A9-A3-2A10-CA3-2(2A9-A3-2A10-C2A2-)2A9-2A-2A11-C2A-2A10-4AD11-C-4A10-4AC12-5A10-4AC12-3A-A9-5AC12-EB12-5AC12-D-2A13-A-A13-B2A13-2A14-B2A12-2AD14-B2A12-A-A15-BA11-3A16-3A10-A-A16-3A10-2A18-2A10-2A2(18-2D10-2D)44-BA22-AC6-DA22-AC6-BA22-AD2(6-BA22-AC)6-2A22-A7-2A21-2(2A8-2A20-)2A8-EA20-2A8-DA20-AD8-CA20-D10-C19-E2(11-2A18-C)11-EA18-C11-B-A17-A12-BA16-2A12-DA16-2A12-BA16-AD12-BA15-AD14-BA14-2A14-BA13-A-A15-2(2A12-2A16-)2D12-2D16-2D12-2D42-BA30-DA24-2C4-BA24-CD4-BA24-C5-2A23-2A6-A23-3(2A6-2A22-)A7-DA22-D8-A21-2(2A8-2A20-)A9-2A20-A10-E20-A10-B19-2(2A10-2B18-)2A11-D18-A12-BA16-2A12-BA16-AD12-BA16-A2(14-BA14-2A)15-A14-A2(16-D14-D)73-DA26-2A2-DA25-2AD2-A-A24-2AD3-2A24-3A3-2(2A24-2A4-)2A23-A-A5-2A22-AD6-DA22-AD6-2A22-2A6-2A21-2A8-A21-2A8-EA20-2A8-BA20-2A8-2B20-A10-B19-2(2A10-2B18-)A11-DB18-E12-B16-CAC12-BA15-CAD13-B15-2C14-BA14-2A14-BA14-A2(16-D14-D)73-A30-D2A27-3A-A27-AD3A26-2(A-)2A26-3A-2A25-A-AD2(-A)24-A-D2-D2A24-ADA3-2A24-2A4-2A23-A-A4-A-A22-3A4-3A22-2A6-EA22-2A6-2B21-A-A7-2(2B20-2A8-)2B19-A-A9-B19-AE10-2B16-C-2C11-B16-3C12-2B15-2CD13-B15-CD14-BA14-2C14-BA14-A2(16-D14-D)104-A27-3AED2A25-A3BA2-A24-A2BDA2-A24-A3BA2-A24-ABD2-A-A24-A2B2-D-A23-A-2A2(2-A)3(22-3A4-A-A)21-A-A6-E-A2(20-3A6-B-B)20-2A8-2B19-A-A8-D-B18-AE10-2B16-C-AC10-2B16-C-2C11-B16-3C12-3B14-3C13-2B14-CD14-2B14-2C14-2B14-C16-D13-2D16-2D12-2D132-A2B-D2A25-A2B2(-A)25-AD2(2-A)24-AB3-A-A24-AB3-D-A23-2AB4-2A23-2AB4-A-A22-A6-A-A22-A7-2A21-2A7-2A21-AD8-2E20-D9-2B20-D9-DB20-D9-2B19-AD10-DB18-AD10-2B16-C-D12-B16-C-D12-3B14-2CD12-3B2(14-CD14-2B)13-AD16-BA12-AC17-D12-2D17-D12-D133-AB3-A26-AB2-DA26-AD2-D-2A24-AB3-A-A24-AD3-D-A23-2AD3-A2-A2(22-2AD4-3A)22-D6-2A-A21-D7-A-2(A20-2A8-D)B20-2A8-B-B19-2A8-3B18-2A10-2B18-AE10-D-B15-C-AC11-D2B14-3C12-3B13-AC-C13-2B13-A2C14-2BA12-ACD15-B2A10-A-C16-B2A10-2AC17-2D9-3D18-2D9-3D133-A2B-4A24-A2B2-E2A24-ABD2-DCA24-2(A2B2-2C-A23-)A2B3-3A23-A2B3-A-A22-2AB6-A21-A-A7-2A20-A-A7-DA19-A2-A8-D19-A-A9-EA18-3A9-2B18-3A10-B17-A-A11-BA16-3A11-BA16-AE13-DB13-AC-C13-2BA10-3ACD14-2B2A10-2AC16-B-A8-3A-D16-B2A2-2C3-5AC17-2AC-2C3-4A20-3D4-5D20-3D5-4D136-B3-EA26-B3-2C22-3A2B4-C22-2A-B5-2C20-3A-D5-2C20-4AB5-2C21-3AB6-2A20-3AB6-2A19-A-2A7-D-A18-4A7-A-A18-3A9-2A18-2A10-2A17-2A11-E-A16-2A12-BA15-A-A12-B-A14-2A13-B-B13-3A14-3B11-2A-E14-DB-3A3C-5A-D16-2D-A5C4A-AC16-BA4D4C5AC17-2A2C2-3C3A23-C2-3CA25-7D26-6D80-3A18-A5B5-E2A18-6B4-C-2A17-7B4-C-CA17-4BD2B5-2CA17-6B6-2CA17-5BD6-2C2A16-4BDB6-2C2A17-5B7-D-A18-4B7-D2A17-A-A9-3A17-2A11-A-A2(16-2A11-3A)15-A-A12-D-A14-A-A12-E-A13-A-A14-B-A12-A-A14-BAB2A7-3A-A16-BAB11ADA16-B2A5-A4-AD19-DE5CE4A27-C209-2A19-3AE7-EA19-2A2B7-C-A18-2(A-D8-2C-A17-)A2B8-DC-2A16-A2B9-C2-A16-ABD9-DA-A16-2AD9-CA-A16-AD12-2A16-2A12-3A14-A-A12-A-A14-A-A13-2(2A14-)2A13-A-A14-D-A5-2A4-2A-A14-A-3A2-4A3-A-A16-16A16-3A-7A2-2A18-2A-A3E4A2D21-AE3CE4A270-5A14-4A9-E4A14-3AE9-C2-2A14-2A-D10-C2-A14-2A-B10-C2(2-A9-A4-2AB11-D)A-A9-A4-3A11-CA-A9-A4-3A12-CA-2A6-2A4-2AD13-2(A-2A4-)2AD13-A2-A4-A-2A4-A-A14-4A3-4A4-3A14-2ADA2-5A3-3A15-2D9A-3A-A16-7A2-7A16-2A2-2A-8A19-10A-A21-7A3D22-A294-2A18-8A4-8A12-8A4-3A2D3A10-E9A3-6A2D11-C3-6A3-8A11-D2(3-7A2-8A11-C)A-8A2-8A11-C10A2-8A13-3A-5A5B4A14-3A-4A7BEAD14-7A9BDA15-2(A-)2D8BDA19-D2A9BA19-3A3B2D4BA19-3A9B20-2A-A2BD4B26-2B2DBA349-3A20-5A4-3A20-3A-A-2A-A-D20-3(A-)2A2(-A)15-4D-D-A-5A2-A15-C3A3(-A)-2A3-A15-C3A3(-A)-2A2-A16-C2A2-3(A-)D3A-A20-3(A-)ED2E-A20-2(A-)AE2BDB-A20-3A-E3BDB-E21-A2(2-BD)-B21-A2-DB2-3BD21-D2-B4-3D21-A8-2B438-3CE6A20-A5C6D20-7C5A20-D2CD3C4A-A19-4CD2C4A-A19-A3CDCA-3A-A19-2A3CD2-5A19-2A2-AD4-A-A20-A2-2A4-E-A20-A2-A5-BE2(30-2B)31-B532-EC2-CD26-DC2-2C5-2D19-2C2-2C5-3A29-4(2A30-)A587-
