model
size = 18 32 13, scale = 0.05, origin = -y
material 
  colors = A:#222 B:#111 C:#20E800 D:#E500B8 E:#555
voxels
77-2B4-2B10-5E3B9-E5DE2B9-7DE2B8-B7D2B7-2D2B5D3E6-4DB4D3C6-5D2B2D3C6-7DBD3C6-A7DB3C6-2A5D2C2BC6-6A5CB2(6-6A6C)6-7A5C6-8A4C6-9A3C7-10A8-10A9-8A11-2A2-2A136-2(11B7-)11B6-12B6-2B2A4B2A2B6-2B3A2E3A2B6-B9A2B5-BE10A2B4-2B10A2B4-13AE5(4-12A2C)4-12ACB2(4-12A2C)3(5-11A2C)3(4-14A)4-6A2B6A5-4AB2-B4A7-3A4-3A96-2B11-2(B4-2B2A7-2A)B4-B3A7-2A3(B4-B12A)B4-B-11AB4-B12A2(B4-13A)CE4(3-13A2C)3-13ACB4(3-13A2C)2-14ACA3(2-16A)2(2-7A)2-6A4-6A3-5AB2-B5A5-3AB4-B3A7-2A6-2A59-6(B14-B2-)BA13-2(B2-BA12-A)B2-2A12-AB2-2A13-A2-2A13-E3(2-2A13-C)2-2A13-B3(2-2A13-C)2(2-2A12-CA)2(2-2A12-2A)2-A14-A39-2A10-2A4-3A8-3A4-2A-A6-4A6-A8-A41-B14-B2-B13-AB-B6(A14-A2B)A4(14-AB2A)14-E2(2-A14-C)2-A14-B2(2-A14-C)2-A14-A2-A13-2(2A2-2A12-)2A2-A13-2A75-A17-3A8-3A4-3A8-3A38-B2(16-2B)3(A15-2B)3(16-2B)3(15-CBA)15-C4(B2A14-A)B2A14-2A-4(A14-A2-)A14-A111-A17-3A8-3A4-3A8-3A20-B5(16-2B)16-BE16-BC16-2B3(15-CBC)15-C2(BA15-A)2(B2A14-A)B2A5(14-4A)14-2A139-3A4-3A8-3A5-2A8-2A4-B14-B-B3(A14-A2B)A14-ABEC2(14-CB2C)14-C2BC3(14-CB2C)14-CBCA4(14-AB2A)5(14-4A)14-2A146-2A9-3A4-3A8-3A4-B12-B3-B14-B2-B14-B-BA14-ABEA14-A3(B2C14-C)B-B14-AB-5(C14-B2-)2(A14-B2-)A14-A-2A4(14-4A)14-2A146-2A9-3A4-4A6-4A4-2B11-B4-B12-B3-B2A10-2AB2-E2A10-2AB2-2C3A5-5A3(B2-2C13A)B2-BC6(13AB2-2C)13AB2-15AB3(2-16A)2-3A3-10A-3A11-7A11-4A-A14-A75-A17-3A8-3A2(4-4A6-4A)5-4A4-4A7-2B6-3B6-2B8A2B5-2B10A2B4-E12AB4-C12AB3-C13AB3-2C12AB3-3C4A2B5AB3-3C4A3B4AB3-B2C4A4B3AB3-3C6A3E2AB3-3C6A3D2AB3-2C9AD2AB3-C10A2D2AB2-C11AD2AB2-12A2BAB2(2-13AD2A)2-16A2-3A3-10A2(2-2A11-3A)2-A14-A75-A17-4A5-5A4-14A6-4A2B4A10-2A2-2A12-6B11-8B9-10B7-2E10B5-3CE9B5-4CE8B5-5CE7B5-6C2-5B5-6C3-4B5-B5C4-3B5-CB4C2E3-3B4-2C2B2C5DE2B4-4CB7DEB4-4CDB7DB4-3CA2D2B5DB7-A4D6B6-2A9DA5-3A9D6-4ADA5D6-6A-2A2D3A2(4-5A)3-5A6-5A2-4A8-4A2-16A3-4(14A4-)14A7-3A2-3A337-2D16-2D14-A5D11-4A4D9-10A7-12A6-12A5-6A2-6A2(4-5A)4-4A6-4A4-3A8-3A92-
