model
size = 23 9 18, scale = 0.05, origin = -y
material 
  colors = A:#1A1A1A B:#A57C1F C:#1D381E D:#1A321B E:#1D351D F:#203D20 G:#182D19 H:#234023 I:#254525
voxels
-AAAAAAA-------AAAAAAA- AAGDDECAA-----AACEDDGAA AGGDEECFAA---AAFCEEDGGA AGDDECCFHAA-AAHFCCEDDGA AGDEECFFHIA-AIHFFCEEDGA AGDECCFHHIA-AIHHFCCEDGA AGDECFFHIIABAIIHFFCEDGA AADECFHHIAA-AAIHHFCEDAA -AAAAAAAAABBBAAAAAAAAA- 
----------------------- ---------B---B--------- ----------B-B---------- ----------------------- ----------------------- ----------------------- B---------------------B ----------------------- ----------------------- 
----------------------- ----------------------- ----------------------- ----------------------- ----------------------- ----------------------- B---------------------B ----------------------- ----------------------- 
----------------------- ----------------------- ----------------------- ----------------------- ----------------------- ----------------------- B---------------------B ----------------------- ----------------------- 
----------------------- ----------------------- ----------------------- ----------------------- ----------------------- ----------------------- B---------------------B ----------------------- ----------------------- 
----------------------- ----------------------- ----------------------- ----------------------- ----------------------- ----------------------- B---------------------B ----------------------- ----------------------- 
----------------------- ----------------------- ----------------------- ----------------------- ----------------------- ----------------------- B---------------------B ----------------------- ----------------------- 
----------------------- ----------------------- ----------------------- ----------------------- ----------------------- ----------------------- B---------------------B ----------------------- ----------------------- 
----------------------- ----------------------- ----------------------- ----------------------- ----------------------- ----------------------- B---------------------B ----------------------- ----------------------- 
----------------------- ----------------------- ----------------------- ----------------------- ----------------------- ----------------------- B---------------------B ----------------------- ----------------------- 
----------------------- ----------------------- ----------------------- ----------------------- ----------------------- ----------------------- B---------------------B ----------------------- ----------------------- 
----------------------- ----------------------- ----------------------- ----------------------- ----------------------- ----------------------- B---------------------B ----------------------- ----------------------- 
----------------------- ----------------------- ----------------------- ----------------------- ----------------------- ----------------------- B---------------------B ----------------------- ----------------------- 
----------------------- ----------------------- ----------------------- ----------------------- ----------------------- ----------------------- B---------------------B ----------------------- ----------------------- 
----------------------- ----------------------- ----------------------- ----------------------- ----------------------- B---------------------B B---------------------B ----------------------- ----------------------- 
----------------------- ----------------------- ----------------------- ----------------------- ----------------------- B---------------------B ----------------------- ----------------------- ----------------------- 
----------------------- ----------------------- ----------------------- ----------------------- ----------------------- B---------------------B ----------------------- ----------------------- ----------------------- 
----------------------- ----------------------- B---------------------B B---------------------B B---------------------B B---------------------B ----------------------- ----------------------- ----------------------- 
