model
size = 23 9 18, scale = 0.05, origin = -y
material 
  colors = A:#111 B:#A57C1F C:#1C1C1C D:#171717 E:#1A1A1A F:#1F1F1F G:#141414 H:#222 I:#252525
voxels
-AAAAAAA-------AAAAAAA- AAGDDECAA-----AACEDDGAA AGGDEECFAA---AAFCEEDGGA AGDDECCFHAA-AAHFCCEDDGA AGDEECFFHIA-AIHFFCEEDGA AGDECCFHHIA-AIHHFCCEDGA AGDECFFHIIABAIIHFFCEDGA AADECFHHIAA-AAIHHFCEDAA -AAAAAAAAABBBAAAAAAAAA- 
----------------------- ---------B---B--------- ----------B-B---------- ----------------------- ----------------------- ----------------------- B---------------------B ----------------------- ----------------------- 
----------------------- ----------------------- ----------------------- ----------------------- ----------------------- ----------------------- B---------------------B ----------------------- ----------------------- 
----------------------- ----------------------- ----------------------- ----------------------- ----------------------- ----------------------- B---------------------B ----------------------- ----------------------- 
----------------------- ----------------------- ----------------------- ----------------------- ----------------------- ----------------------- B---------------------B ----------------------- ----------------------- 
----------------------- ----------------------- ----------------------- ----------------------- ----------------------- ----------------------- B---------------------B ----------------------- ----------------------- 
----------------------- ----------------------- ----------------------- ----------------------- ----------------------- ----------------------- B---------------------B ----------------------- ----------------------- 
----------------------- ----------------------- ----------------------- ----------------------- ----------------------- ----------------------- B---------------------B ----------------------- ----------------------- 
----------------------- ----------------------- ----------------------- ----------------------- ----------------------- ----------------------- B---------------------B ----------------------- ----------------------- 
----------------------- ----------------------- ----------------------- ----------------------- ----------------------- ----------------------- B---------------------B ----------------------- ----------------------- 
----------------------- ----------------------- ----------------------- ----------------------- ----------------------- ----------------------- B---------------------B ----------------------- ----------------------- 
----------------------- ----------------------- ----------------------- ----------------------- ----------------------- ----------------------- B---------------------B ----------------------- ----------------------- 
----------------------- ----------------------- ----------------------- ----------------------- ----------------------- ----------------------- B---------------------B ----------------------- ----------------------- 
----------------------- ----------------------- ----------------------- ----------------------- ----------------------- ----------------------- B---------------------B ----------------------- ----------------------- 
----------------------- ----------------------- ----------------------- ----------------------- ----------------------- B---------------------B B---------------------B ----------------------- ----------------------- 
----------------------- ----------------------- ----------------------- ----------------------- ----------------------- B---------------------B ----------------------- ----------------------- ----------------------- 
----------------------- ----------------------- ----------------------- ----------------------- ----------------------- B---------------------B ----------------------- ----------------------- ----------------------- 
----------------------- ----------------------- B---------------------B B---------------------B B---------------------B B---------------------B ----------------------- ----------------------- ----------------------- 
