model
size = 23 9 18, scale = 0.05, origin = -y
material 
  colors = A:#1A1A1A B:#A57C1F C:#35271C D:#2F231A E:#32251B F:#38291D G:#2D2219 H:#3D2C1F I:#433021
voxels
-AAAAAAA-------AAAAAAA- AAGDDECAA-----AACEDDGAA AGGDEECFAA---AAFCEEDGGA AGDDECCFHAA-AAHFCCEDDGA AGDEECFFHIA-AIHFFCEEDGA AGDECCFHHIA-AIHHFCCEDGA AGDECFFHIIABAIIHFFCEDGA AADECFHHIAA-AAIHHFCEDAA -AAAAAAAAABBBAAAAAAAAA- 
----------------------- ---------B---B--------- ----------B-B---------- ----------------------- ----------------------- ----------------------- B---------------------B ----------------------- ----------------------- 
----------------------- ----------------------- ----------------------- ----------------------- ----------------------- ----------------------- B---------------------B ----------------------- ----------------------- 
----------------------- ----------------------- ----------------------- ----------------------- ----------------------- ----------------------- B---------------------B ----------------------- ----------------------- 
----------------------- ----------------------- ----------------------- ----------------------- ----------------------- ----------------------- B---------------------B ----------------------- ----------------------- 
----------------------- ----------------------- ----------------------- ----------------------- ----------------------- ----------------------- B---------------------B ----------------------- ----------------------- 
----------------------- ----------------------- ----------------------- ----------------------- ----------------------- ----------------------- B---------------------B ----------------------- ----------------------- 
----------------------- ----------------------- ----------------------- ----------------------- ----------------------- ----------------------- B---------------------B ----------------------- ----------------------- 
----------------------- ----------------------- ----------------------- ----------------------- ----------------------- ----------------------- B---------------------B ----------------------- ----------------------- 
----------------------- ----------------------- ----------------------- ----------------------- ----------------------- ----------------------- B---------------------B ----------------------- ----------------------- 
----------------------- ----------------------- ----------------------- ----------------------- ----------------------- ----------------------- B---------------------B ----------------------- ----------------------- 
----------------------- ----------------------- ----------------------- ----------------------- ----------------------- ----------------------- B---------------------B ----------------------- ----------------------- 
----------------------- ----------------------- ----------------------- ----------------------- ----------------------- ----------------------- B---------------------B ----------------------- ----------------------- 
----------------------- ----------------------- ----------------------- ----------------------- ----------------------- ----------------------- B---------------------B ----------------------- ----------------------- 
----------------------- ----------------------- ----------------------- ----------------------- ----------------------- B---------------------B B---------------------B ----------------------- ----------------------- 
----------------------- ----------------------- ----------------------- ----------------------- ----------------------- B---------------------B ----------------------- ----------------------- ----------------------- 
----------------------- ----------------------- ----------------------- ----------------------- ----------------------- B---------------------B ----------------------- ----------------------- ----------------------- 
----------------------- ----------------------- B---------------------B B---------------------B B---------------------B B---------------------B ----------------------- ----------------------- ----------------------- 
