model
size = 32 20 28, scale = 0.05, origin = -y
material 
  colors = A:#111 B:#FFC408 C:#FFB11B D:#1E88A8
voxels
77-6A25-B6AB23-2A6C2A22-A-2C2-2C-A23-2(2C-)2C23-10C22-2C6A2C21-5C2D5C20-2C-C2DBDC-2C20-C-2CDB2D2C-C20-C-3C2D3C-C20-2CA6CA2C20-3C6A3C21-2C-C2AC-2C26-2C30-2C91-8A23-2A6B2A21-3A6B3A19-2A10B2A17-2A12B2A15-2A14B2A12-3A16B3A2(10-B2A16B2AB)2(10-C2A16B2AC10-B2A16B2AB)10-3A16B3A12-2A14B2A15-2A12B2A17-2A10B2A19-3A6B3A22-3A2B3A26-4A210-2A20-2A2(8-2B20-2B8-CB20-BC)2(8-2B20-2B)8-2A20-2A391-2A22-2A2(6-2B22-2B)2(6-CB22-BC6-2B22-2B)6-2A22-2A389-2A24-2A2(4-2B24-2B4-CB24-BC)2(4-2B24-2B)4-2A24-2A387-2A26-2A2(2-2B26-2B)2(2-CB26-BC2-2B26-2B)2-2A26-2A385-2A28-3A5(B28-B2A)B28-B3A28-2A384-A30-AB5(30-2B)2(30-BA30-A384-A30-AB30-2B2(30-BC30-CB)30-BA30-A384-A30-A2(B30-BC30-C)B30-2B)30-BA30-A384-A30-AB5(30-2B)30-BA30-A384-A7(30-2A)30-A384-A30-AB5(30-2B)2(30-BA30-A384-A30-A2(B30-BC30-C)B30-2B30-BA30-A384-A30-AB30-2B2(30-BC30-CB))30-BA30-A384-A30-AB5(30-2B)30-BA30-A384-A7(30-2A)30-A385-7(A28-A2-)A28-A387-7(A26-A4-)A26-A389-7(A24-A6-)A24-A391-7(A22-A8-)A22-A393-7(A20-A10-)A20-A395-7(20A12-)20A396-19A13-6(2AB)A4(13-19A)13-6(2AB)A13-19A199-
