model
size = 31 18 29, scale = 0.05, origin = -y
material 
  colors = A:#FFF B:#FCFAF2 C:#0B1013 D:#EEE E:#62592C F:#876633 G:#78552B H:#947A6D I:#985F2A J:#F9BF45 K:#6E552F L:#43341B M:#222 N:#3C2F41
voxels
------------------------------- ------------------------------- ------------------------------- ------------------------------- ------------------------------- ------------------------------- ------------------------------- ------------------------------- -----------------------------D- -----------------------------D- -----------------------------D- -----------------------------D- -----------------------------D- -----------------------------D- ----------------------------D-- --------------------------DD--- ------------------------------- ------------------------------- 
------------------------------- ------------------------------- ------------------------------- ------------------------------- ------------------------------- ------------------------------- ----------------------------D-- ----------------------------D-- -----------------------------D- -----------------------------D- -----------------------------D- -----------------------------A- -----------------------------D- -----------------------------D- ----------------------------D-- --------------------------DD--- ------------------------DD----- ------------------------------- 
------------------------------- ------------------------------- ------------------------------- ------------------------------- ---------------------------D--- ----------------------------D-- ----------------------------D-- ----------------------------A-- -----------------------------D- -----------------------------D- -----------------------------A- -----------------------------A- -----------------------------A- -----------------------------D- ----------------------------A-- --------------------------DD--- ---------------------DDDDD----- ------------------------------- 
------------------------------- ------------------------------- ------------------------------- --------------------------D---- ---------------------------D--- ----------------------------A-- ----------------------------D-- ----------------------------A-- -----------------------------D- -----------------------------A- -----------------------------A- -----------------------------A- -----------------------------A- -----------------------------A- ----------------------------A-- --------------------------DA--- -------------------DDDAADA----- ------------------------------- 
------------------------------- ------------------------------- ------------------------------- ------------------------DDD---- ---------------------------A--- ----------------------------A-- ----------------------------A-- ----------------------------A-- -----------------------------A- -----------------------------A- -----------------------------A- -----------------------------A- -----------------------------A- -----------------------------A- ----------------------------A-- --------------------------AA--- -------------------DAAAAAA----- ------------------------------- 
------------------------------- ------------------------------- ---------------------DDD------- ------------------------DDA---- ---------------------------A--- ----------------------------A-- ----------------------------A-- ----------------------------A-- -----------------------------A- -----------------------------A- -----------------------------A- -----------------------------A- -----------------------------A- -----------------------------A- ----------------------------A-- --------------------------AA--- ----------------DDDAAAAAAA----- ------------------------------- 
------------------------------- -----------------DDD----------- --------------------DDAA------- ------------------------DAA---- ---------------------------A--- ----------------------------A-- ----------------------------A-- ----------------------------A-- -----------------------------A- -----------------------------A- -----------------------------A- -----------------------------A- -----------------------------A- -----------------------------A- ----------------------------A-- --------------------------AA--- ---------------DDAAAAAAAAA----- ------------------------------- 
------------------------------- ---------------DDDAD----------- --------------------DAAA------- ------------------------DAA---- ---------------------------A--- ----------------------------A-- ----------------------------A-- ----------------------------A-- -----------------------------A- -----------------------------A- -----------------------------A- -----------------------------A- -----------------------------A- -----------------------------A- ----------------------------A-- --------------------------AA--- ---------------DAAAAAAAAAA----- ------------------------------- 
------------------------------- --------------DDADAA----------- --------------------DAAA------- ------------------------AAA---- ---------------------------A--- ----------------------------A-- ----------------------------A-- ----------------------------A-- -----------------------------A- -----------------------------A- -----------------------------A- -----------------------------A- -----------------------------A- -----------------------------A- ----------------------------A-- --------------------------AA--- -------------DDAAAAAAAAAAA----- ------------------------------- 
------------------------------- ------------DDDAADAA----------- --------------------AAAA------- ------------------------AAA---- ---------------------------A--- ----------------------------A-- ----------------------------A-- ----------------------------A-- -----------------------------A- -----------------------------A- -----------------------------A- -----------------------------A- -----------------------------A- -----------------------------A- ----------------------------A-- --------------------------AA--- ------------DAAAAAAAAAAAAA----- ------------------------------- 
------------------------------- ----------DDDDAAAAAA----------- --------------------AAAA------- ------------------------AAA---- ---------------------------A--- ----------------------------A-- ----------------------------A-- ----------------------------A-- -----------------------------A- -----------------------------A- -----------------------------A- -----------------------------A- -----------------------------A- -----------------------------A- ----------------------------A-- --------------------------AA--- ------------DAAAAAAAAAAAAA----- ------------------------------- 
------------------------------- ---------DDAAAAAAAAA----------- --------------------AAAA------- ------------------------AAA---- ---------------------------A--- ----------------------------A-- ----------------------------A-- ----------------------------A-- -----------------------------A- -----------------------------A- -----------------------------A- -----------------------------A- -----------------------------A- -----------------------------A- ----------------------------A-- --------------------------AA--- -----------DDAAAAAAAAAAAAA----- ------------------------------- 
------------------------------- --------DDAAAAAAAAAA----------- --------------------AAAA------- ------------------------AAA---- ---------------------------A--- ----------------------------A-- ----------------------------A-- ----------------------------A-- -----------------------------A- -----------------------------A- -----------------------------A- -----------------------------A- -----------------------------A- -----------------------------A- ----------------------------A-- --------------------------AA--- -----------DAAAAAAAAAAAAAA----- ------------------------------- 
------------------------------- --------DDAAAAAAAAAA----------- --------------------AAAA------- ------------------------AAA---- ---------------------------A--- ----------------------------A-- ----------------------------A-- ----------------------------A-- -----------------------------A- -----------------------------A- -----------------------------A- -----------------------------A- -----------------------------A- -----------------------------A- ----------------------------A-- --------------------------AA--- ----------DDAAAAAAAAAAAAAA----- ------------------------------- 
------------------------------- --------DAAAAAAAAAAA----------- --------------------AAAA------- ------------------------AAA---- ---------------------------A--- ----------------------------A-- ----------------------------A-- ----------------------------A-- -----------------------------A- -----------------------------A- -----------------------------A- -----------------------------A- -----------------------------A- -----------------------------A- ----------------------------A-- --------------------------AA--- ----------DAAAAAAAAAAAAAAA----- ------------------------------- 
------------------------------- --------DAAAAAAAAAAA----------- -------D------------AAAA------- ------------------------AAA---- ---------------------------A--- ----------------------------A-- ----------------------------A-- ----------------------------A-- -----------------------------A- -----------------------------A- -----------------------------A- -----------------------------A- -----------------------------A- -----------------------------A- ----------------------------A-- --------------------------AA--- ---------DAAAAAAAAAAAAAAAA----- ------------------------------- 
------------------------------- --------AAAAAAAAAAAA----------- ------DD------------AAAA------- ------------------------AAA---- ---------------------------A--- ----------------------------A-- ----------------------------A-- ----------------------------A-- -----------------------------A- -----------------------------A- -----------------------------A- -----------------------------A- -----------------------------A- -----------------------------A- ----------------------------A-- --------------------------AA--- ---------DAAAAAAAAAAAAAAAA----- ------------------------------- 
------------------------------- --------AAAAAAAAAAAA----------- ------DA------------AAAA------- ------------------------AAA---- ---------------------------A--- ----------------------------A-- ----------------------------A-- ----------------------------A-- -----------------------------A- -----------------------------A- -----------------------------A- -----------------------------A- -----------------------------A- -----------------------------A- ----------------------------A-- --------------------------AA--- ---------DAAAAAAAAAAAAAAAA----- ------------------------------- 
------------------------------- --------AAAAAAAAAAAA----------- ------AA------------AAAA------- ------------------------AAA---- ---------------------------A--- ----------------------------A-- ----------------------------A-- ----------------------------A-- -----------------------------A- -----------------------------A- -----------------------------A- -----------------------------A- -----------------------------A- -----------------------------A- ----------------------------A-- --------------------------AA--- --------DAAAAAAAAAAAAAAAAA----- ------------------------------- 
------------------------------- --------AAAAAAAAAAAA----------- ------AA------------AAAA------- -----D------------------AAA---- ---------------------------A--- ----------------------------A-- ----------------------------A-- ----------------------------A-- -----------------------------A- -----------------------------A- -----------------------------A- -----------------------------A- -----------------------------A- -----------------------------A- ----------------------------A-- --------------------------AA--- --------DAAAAAAAAAAAAAAAAA----- ------------------------------- 
------------------------------- --------AAAAAAAAAAAA----------- ------BB------------AAAA------- ----DB------------------AAA---- ---------------------------A--- ----------------------------B-- ----------------------------B-- ----------------------------B-- -----------------------------B- -----------------------------B- H----------------------------B- H----------------------------B- H----------------------------B- F----------------------------B- E---------------------------B-- EE------------------------BB--- -E------BBBBBBBBBBBBBBBBBB----- --FGGKLI----------------------- 
------------------------------- --------BBBBBBAAAAAA----------- ------BB------------AAAA------- ----BB------------------AAA---- --E------------------------A--- --H-------------------------B-- -H--------------------------B-- G---------------------------B-- E----------------------------B- E----------------------------B- -----------------------------B- -----------------------------B- -----------------------------B- -----------------------------B- ----------------------------B-- --------------------------BB--- --------BBBBBBBBBBBBBBBBBB----- --IJJMNHIEEFFHG---------------- 
------------------------------- --------BBBBBBBBBBBB----------- ----GGBB------------BBBB------- --EGBB------------------BBB---- ---------------------------B--- ----------------------------B-- ----------------------------B-- ----------------------------B-- -----------------------------B- -----------------------------B- -----------------------------B- -----------------------------B- -----------------------------B- -----------------------------B- ----------------------------B-- --------------------------BB--- ----------BBBBBBBBBBBBBBBB----- ----------CCCCCGGGG------------ 
--------EEEFFF----------------- ------HHBBBBBBBBBBBB----------- ------BB------------BBBB------- ------------------------BBB---- ---------------------------B--- ----------------------------B-- ----------------------------B-- ----------------------------B-- -----------------------------B- -----------------------------B- -----------------------------B- -----------------------------B- -----------------------------B- -----------------------------B- ----------------------------B-- --------------------------BB--- ------------BBBBBBBBBBBBBB----- ------------CCCCCCCEFFFF------- 
--------------GGFFFF----------- --------------BBBBBBEEEE------- --------------------BBBBHHH---- ------------------------BBBGG-- ---------------------------BF-- ----------------------------BH- ----------------------------BH- ----------------------------BH- -----------------------------BE -----------------------------BE -----------------------------BE -----------------------------BE -----------------------------BE -----------------------------BF ----------------------------BF- --------------------------BBG-- -------------BBBBBBBBBBBBBGG--- -------------CCCCCCCCCCCHH----- 
------------------------------- ------------------------------- ------------------------------- ------------------------------- ------------------------------- ----------------------------CC- ----------------------------BC- ----------------------------BC- -----------------------------BC -----------------------------BC -----------------------------BC -----------------------------BC -----------------------------BC -----------------------------BC ----------------------------BC- --------------------------BBC-- ---------------BBBBBBBBBBBCC--- ---------------CCCCCCCCCCC----- 
------------------------------- ------------------------------- ------------------------------- ------------------------------- ------------------------------- ----------------------------CC- ----------------------------BC- ----------------------------BC- -----------------------------BC -----------------------------BC -----------------------------BC -----------------------------BC -----------------------------BC -----------------------------BC ----------------------------BC- --------------------------BBC-- ----------------BBBBBBBBBBCC--- ----------------CCCCCCCCCC----- 
------------------------------- ------------------------------- ------------------------------- ------------------------------- ------------------------------- ----------------------------CC- ----------------------------BC- ----------------------------BC- -----------------------------BC -----------------------------BC -----------------------------BC -----------------------------BC -----------------------------BC -----------------------------BC ----------------------------BC- --------------------------BBC-- ------------------BBBBBBBBCC--- ------------------CCCCCCCC----- 
------------------------------- ------------------------------- ------------------------------- ------------------------------- ------------------------------- ----------------------------CC- ----------------------------CC- ----------------------------CC- -----------------------------CC -----------------------------CC -----------------------------CC -----------------------------CC -----------------------------CC -----------------------------CC ----------------------------BC- --------------------------BBC-- -------------------BBBBBBBCC--- -------------------CCCCCCC----- 
