model
size = 32 24 32, scale = 0.05, origin = -y
material 
  colors = A:#111 B:#222 C:#0B1013 D:#373C38 E:#444 F:#555 G:#405B55 H:#4F4F48 I:#566C73 J:#3A3226 K:#656765 L:#707C74 M:#91989F N:#78552B O:#43341B P:#876633 Q:#3C2F41 R:#6A4028 S:#947A6D T:#62592C U:#877F6C V:#26453D W:#535953 X:#985F2A Y:#888 Z:#646A58 Aa:#7D532C Ab:#777 Ac:#787D7B Ad:#F9BF45 Ae:#577C8A Af:#0F2540 Ag:#7DB9DE Ah:#2EA9DF Ai:#4F726C Aj:#AAA
voxels
117-2B2A3B22-5B2A4BA19-6B2A4B2A18-6B2A4B3A16-7B2(2(2A4B3A15-8B)2(2A4B2AC15-8B))2A4B3A16-7B2(2A4B3A17-6B)2A4B2A19-5B2A4BA23-2B2A3B215-2B6A2B20-4B2(6A4B17-5B)2(6A4BA16-5B)6A4BC16-5B6A5B16-5B6A4BA15-A2(5B6A4BC16-)5B6A4BA16-5B6A5B16-5B6A4BC2(16-5B6A4BA)16-5B6A4B18-4B6A4B20-2B6A2B218-3A3B19-8AC3ACZB15-2B14ABA2(14-2B14A2B14-2B14ABA14-2B14ABC)2(14-2B14ABC14-2B14ABA14-2B14A2B)14-2B14ABA16-8AC3ACZB24-3A3B219-2C2B20-A9C2AC2B14-2(3B15AB13-)3B15AB4-B2AB5-3B15AB4-3A2BA3-3B15AB4-2(3A2B2A2-3B15AC3-D)2(3A2B2A2-3B15AC4-)3A2BA3-3B15AB4-B2AB5-3(3B15AB13-)3B15AB16-A9C2AC2B25-2C2B210-2BA7-A2B18-3B3A2(C5A)12-2A3B16A5-A2BZ-3A3B15AB4-AB7A3B15AZ3-DAB2AC4A3B16A3-BAB2AC4A3B16A2-2BAB2AC4A3B15AB2(2-2(AB)2AC4A3B16A)2-2BAB2AC4A3B15AB3-BAB2AC4A3B16A3-DAB2AC4A3B16A4-AB7A3B15AZ5-A2BZ-3A3B15AB11-2A3B16A13-3B3A2(C5A)15-2BA7-A2B209-B3ABA2(3-B)17-AB15ABA11-3AB15AB2A6-4C3AB15AB2AB4-8AB15AB2AB2-2(AB8AB15AB2AC-D)2(AB8AB15AB2ACXD)2(AB8AB15AB2AC-D)AB8AB15AB2AC2-AB8AB15AB2AC4-8AB15AB2AB5-4C3AB15AB2AB9-3AB15AB2A12-AB15ABA14-B3ABA2(3-B)210-B3A2B2AB3-B15-2ABAB2AC8AC2A3B8-4ABAB15ABAB5-6ABAB15AB2AD4-6ABAB15AB2AB-D2B6ABAB15AB2AB-3B6ABAB15AB2ABN3B2(6ABAB15AB3A4B)6ABAB15AB3AN3B6ABAB15AB3A-3B6ABAB15AB2AB-D2B2(6ABAB15AB2AB4-)6ABAB15AB2AD6-4ABAB15ABAB9-2ABAB2AC8AC2A3B14-B3A2B2AB3-B212-B4A2B19-BACA3B6ACA8C8-CB3A3B9A8C5-3CB3A3B17AD3-2(B3A)3B17AD-QA2(B3A)3B17ADWAeG2(B3A)3B17ADAd2(AeG2(B3A)3B17ABS)AeG2(B3A)3B17ABAdAeG2(B3A)3B17ABWAeG2(B3A)3B17AD-QA2(B3A)3B17AD3-2(B3A)3B17AD4-3CB3A3B17AD6-CB3A3B9A8C8-BACA3B6ACA8C15-B4A2B218-4ABA19-2B2ABAB15A9-A2B2ABAB17A5-2BA2B2ABAB17A4-3BA2B2ABAB17AJT2A3BA2B2ABAB17AJWMK3BA2B2ABAB17ACS2(MK3BA2B2ABAB17A2C)MK3BA2B2ABAB17ACSMK3BA2B2ABAB17ACWMK3BA2B2ABAB17ACT2A3BA2B2ABAB17AJ3-3BA2B2ABAB17AJ4-2BA2B2ABAB17A7-A2B2ABAB17A8-2B2ABAB15A17-4ABA218-5AB19-4AB4AC8AC2A9-6AB4AC12AB6-B6AB4AC13AB3-ZFB6AB4AC14A-2WZFB6AB4AC14AKB4(FZFB6AB4AC14ABC)FZFB6AB4AC14A2BFZFB6AB4AC14AB2WZFB6AB4AC14AK2-ZFB6AB4AC14A5-B6AB4AC13AB6-6AB4AC12AB9-4AB4AC8AC2A18-5AB220-3AB19-16AC4A9-25A5-YB25A4-EYL25A3-DEYL25AB2-DEYL25ABHE2(DEYL25A2BT)DEYL25A2BEDEYL25A2B-DEYL25ABH-DEYL25AB3-EYL25A5-YB25A7-25A9-16AC4A20-3AB221-AB20-B2AC3AC11AC10-HAB6AC14A7-LHAB6AC15A6-LHAB6AC15A5-ELHAB6AC15AB3-BELHAB6AC15AB2-E2(BELHAB6AC15AC2-L)BELHAB6AC15AC2-EBELHAB6AC15AC3-BELHAB6AC15AB4-ELHAB6AC15AB5-LHAB6AC15A6-LHAB6AC15A7-HAB6AC14A10-B2AC3AC11AC22-AB244-4AB2A2C5A6C10-ME4AB2A2C5A7C8-EME4AB2A2C5A7C8-2CE4AB2A2C12AB7-2CE4AB2A2C12AB6-3CE4AB2A2C12A2BJ3-C2(BEME4AB2A2C12A2BJ3-A)BEME4AB2A2C12A2BJ3-CBEME4AB2A2C12A2BJ4-3CE4AB2A2C12A2BJ5-2(2CE4AB2A2C12AB7-)EME4AB2A2C5A7C9-ME4AB2A2C5A7C11-4AB2A2C5A6C268-B19A11-IB19A10-BIB20A10-AfB20A10-AgB21A9-AfB20ABD4-Q2CAhIB20A2BH2(3-C2BAiIB20A3B)3-Q2CAhIB20A2BH7-AfB20ABD8-AgB21A9-AfB20A9-BIB20A10-IB19A12-B19A237-2B29-Q2B5A2C2A8C11-GQ2B6AC2A8C10-BGQ2B6AC2A8C11-2(CQ2B6AC10AB10-)CQ2B6AC11AB5-D3CGQ2B6AC11ABJ2(4-2(CB)GQ2B6AC11A2B)4-D3CGQ2B6AC11ABJ8-CQ2B6AC11AB9-CQ2B6AC10AB10-CQ2B6AC10AB9-BGQ2B6AC2A8C11-GQ2B6AC2A8C12-Q2B5A2C2A8C13-2B135-NX62-3A20-D3B5-3A19-ED3B5ANXO4ABA12-BED3B5ANXO4ABAC10-FIED3B5ANXO4ABAC2(9-D2CED3B5ANXO4AB2A)8-BD2CED3B5ANXO4AB2ABD6-CDFIED3B5ANXO4AB2ABD6-2(ADFIED3B5ANXO4AB2A2BE5-)CDFIED3B5ANXO4AB2ABD6-BD2CED3B5ANXO4AB2ABD7-D2CED3B5ANXO4AB2A9-D2CED3B5ANXO4AB2A10-FIED3B5ANXO4ABAC11-BED3B5ANXO4ABAC12-ED3B5ANXO4ABA14-D3B5-3A29-3A61-NX29-RAaOP60-4A20-E2DB4-4A19-DE3DB3ARAaOP3A3C12-KDE3DB3ARAaOP3A4C10-YKDE3DB3ARAaOP3A4C8-LFYKDE3DB3ARAaOP6AB8-BFYKDE3DB3ARAaOP6AB8-AFYKDE3DB3ARAaOP7ABD4(6-CFYKDE3DB3ARAaOP7ABC)6-AFYKDE3DB3ARAaOP7ABD6-BFYKDE3DB3ARAaOP6AB8-LFYKDE3DB3ARAaOP6AB10-YKDE3DB3ARAaOP3A4C11-KDE3DB3ARAaOP3A4C12-DE3DB3ARAaOP3A3C14-E2DB4-4A28-4A60-RAaOP28-S2-T60-2AC2A27-2AC2A20-EAD2B2ASACTJ5A14-B2E2DB2ASACTJ6A12-EH2E2DB2ASACTJ6A11-BEH2E2DB2ASACTJ6A9-2MKEH2E2DB2ASACTJ6A8-BAM2(KEH2E2DB2ASACTJ6AD7-A2M)2(KEH2E2DB2ASACTJ6ABE6-A2M)KEH2E2DB2ASACTJ6AD7-BAMKEH2E2DB2ASACTJ6AD8-2MKEH2E2DB2ASACTJ6A11-BEH2E2DB2ASACTJ6A12-EH2E2DB2ASACTJ6A13-B2E2DB2ASACTJ6A14-EAD2B2ASACTJ5A22-2AC2A27-2AC2A59-S2-T28-Ad2-R60-2ACAB27-2ACJB21-A2D3BHBCJBA4C13-H2BE3D2BHBCJB5A2(13-A2HE3D2BHBCJB4AB)11-GA3HE3D2BHBCJB5AB10-BU3HE3D2BHBCJB6A9-B2U3HE3D2BHBCJB6A9-2(A2U3HE3D2BHBCJB5ABJ8-)B2U3HE3D2BHBCJB6A10-BU3HE3D2BHBCJB6A10-GA3HE3D2BHBCJB5AB12-2(A2HE3D2BHBCJB4AB13-)H2BE3D2BHBCJB5A16-A2D3BHBCJBA4C22-2ACJB27-2ACAB59-Ad2-R29-X33-B28-3AB28-AJAB22-EAWADBAJAB5A16-H2EFIDBAJAB5A14-AbWH2EFIDBAJAB5A14-AFH2EFIDBAJAB5A13-BAbFH2EFIDBAJAB5A2B10-EUAbFH2EFIDBAJAB5A2B10-B2(UAbFH2EFIDBAJAB5ABC10-T)UAbFH2EFIDBAJAB5ABC10-BUAbFH2EFIDBAJAB5ABC10-EUAbFH2EFIDBAJAB5A2B11-BAbFH2EFIDBAJAB5A2B12-AFH2EFIDBAJAB5A14-AbWH2EFIDBAJAB5A16-H2EFIDBAJAB5A17-EAWADBAJAB5A23-AJAB28-3AB31-B29-X65-B28-DAZ2B27-D2A2B23-TLFBD2A2B3A19-K2CFBD2A2B3A15-GB2WK2LFBD2A2B3A15-2A2FK2LFBD2A2B2AB14-K2U2FK2LFBD2A2B3ABD12-K2U2FK2LFBD2A2B3ABD11-BK2U2FK2LFBD2A2B3ABA11-LK2U2FKAbLFBD2A2B3ABA11-LK2U2FK2LFBD2A2B3ABA11-BK2U2FK2LFBD2A2B3ABA2(12-K2U2FK2LFBD2A2B3ABD)13-2A2FK2LFBD2A2B2AB15-GB2WK2LFBD2A2B3A19-K2CFBD2A2B3A20-TLFBD2A2B3A24-D2A2B27-DAZ2B30-B95-D28-R2ADB27-R2ADB25-2RG2AD2BA23-RAG2ADB2A20-S2RGAG2ADB2A18-MA3IGAG2ADBAB15-AjEDMAc3IGAG2ADBAB15-BEKMAc3IGAG2ADB2ABD13-AEKMAc3IGAG2ADB3AB2(13-VEKMAc3IGAG2ADB2ABA)13-AEKMAc3IGAG2ADB3AB13-BEKMAc3IGAG2ADB2ABD13-AjEDMAc3IGAG2ADBAB18-MA3IGAG2ADBAB20-S2RGAG2ADB2A23-RAG2ADB2A23-2RG2AD2BA25-R2ADB27-R2ADB30-D95-J27-CE2AJ27-CED2A26-ACEDAJ2B23-AECEDAJ2B21-GAGECEDAJ2B20-AGIGECEDAJ2A17-MWD2(IG)ECEDAJ2AJ16-2AK2(IG)ECEDAJ2AB16-PAK2(IG)ECEDAJ2AB16-2(AXK2(IG)ECEDAJ2ABK15-)PAK2(IG)ECEDAJ2AB16-2AK2(IG)ECEDAJ2AB16-MWD2(IG)ECEDAJ2AJ19-AGIGECEDAJ2A21-GAGECEDAJ2B23-AECEDAJ2B24-ACEDAJ2B25-CED2A27-CE2AJ31-J95-D2(27-2NDBA)25-4NDBA24-SEDCADBA23-WGEDCAD2B22-WEGEDCAD2B21-DIEGEDCADBA21-AIEGEDCADBDH20-VIEGEDCAD3BK2(19-TIEGEDCADB2AB)19-VIEGEDCAD3BK19-AIEGEDCADBDH20-DIEGEDCADBA22-WEGEDCAD2B23-WGEDCAD2B24-SEDCADBA25-4N2(DBA27-2N)DBA31-D94-AW27-ABEDE27-ABEDA25-B2ABEDA24-BQBABEDA24-AQBABEDE22-EAIQBABEDB21-T2EIQBABE2B22-2AI6B23-GOAQB3AB2(23-PROQB4A)23-GOAQB3AB23-2AI6B22-T2EIQBABE2B22-EAIQBABEDB24-AQBABEDE24-BQBABEDA25-B2A2(BEDA27-A)BEDE30-AW94-AG28-PBKC26-3PBKC25-4P2(BKC24-SDABV)BKC22-DBFDABVBA22-G3ADABVB26-A4B28-NBAB2(28-B3A)28-NBAB27-A4B24-G3ADABVB24-DBFDABVBA25-SDABVBKC24-SDABVBKC25-4PBKC26-3PBKC28-PBKC30-AG94-F29-D2A27-2AD2A26-2(BAVD2A25-A)BAVDAF23-WBIBAVDAF24-2ABAVDA28-3D157-3D26-2ABAVDA24-WBI2(BAVDAF25-A)BAVD2A26-BAVD2A27-2AD2A29-D2A31-F94-J29-AdBC28-Ad2BC27-S3BC26-S4BC25-BI4BC24-EFI4BJ25-2A4B218-2A4B25-EFI4BJ25-BI4BC26-S4BC27-S3BC28-Ad2BC29-AdBC31-J95-G29-BCA28-ABCA27-AVBCA26-BAVBCA24-MEGAVBCF25-3AVBC282-3AVBC25-MEGAVBCF26-BAVBCA27-AVBCA28-ABCA29-BCA31-G94-Ac30-2C29-B2C28-TB2C27-W2B2C26-QE2BC347-QE2BC28-W2B2C28-TB2C29-B2C30-2C31-Ac94-K31-A30-CA29-BCA27-GQBC412-GQBC30-BCA30-C2(A31-)K94-K30-BK29-GBK29-EBA477-EBA29-GBK30-BK31-K49-
