model
size = 5 29 32, scale = 0.05, origin = -y
material 
  colors = A:#FFBA84 B:#E3916E C:#E16B8C D:#D0104C E:#FBE251 F:#FFFFFB G:#E83015 H:#111 I:#F8C3CD J:#E79460 K:#222
voxels
76-7(A4-)A99-3(A4-)5(B4-)A4-A93-3E2(2-EAE)3-2(A4-)3(B4-)A4-A84-8(A4-)2(B4-)A4-A84-8(A4-)B6(4-A)69-4(A4-)5(AD3-)3(A4-)AF3-A4-AH3-A4-A59-5(A4-)2(AD3-AI3-)AD3-2(A4-)2(AF3-)4(A4-)4(G4-)G24-7(A4-)2(AD3-)AI2(3-AD)3-A4-3(AF3-)2(A4-)AH3-2(A4-)2(G4-)G24-8(A4-)AD3(3-AI)3-AD3-A4-AF2(3-AK)3-2(A4-)AH3-3(A4-)G29-8(A4-)5(AD3-)A4-AF3-AK3-AG3-A4-2(AH3-)3(A4-)A24-7(A4-)AC3-6(A4-)2(AF3-)2(B4-)2(AH3-)4(A4-)A19-7(A4-)AC3-6(A4-)5(B4-)2(AH3-)5(A4-)A14-7(A4-)AC3-6(A4-)4(B4-)8(A4-)A9-2(A4-)B5(4-A)2(C3-A)4(4-A)3(4-B)11(4-A)9-2(A4-)2(B4-)2(A4-)2(A2C2-)AC3-A2C2-A4-3(AE3-)AJ3-2(12(A4-)A9-3(A4-)B3(4-A)2C2-2(AC3-)A3C-A4-AE3-B4-2(AJ3-))12(A4-)A9-2(A4-)2(B4-)2(A4-)2(A2C2-)AC3-A2C2-A4-3(AE3-)AJ3-12(A4-)A9-2(A4-)B5(4-A)2(C3-A)4(4-A)3(4-B)11(4-A)14-7(A4-)AC3-6(A4-)4(B4-)8(A4-)A14-7(A4-)AC3-6(A4-)5(B4-)2(AH3-)5(A4-)A19-7(A4-)AC3-6(A4-)2(AF3-)2(B4-)2(AH3-)4(A4-)A29-14(A4-)AF3-AK3-AG3-A4-2(AH3-)3(A4-)A29-8(A4-)5(AD3-)A4-AF2(3-AK)3-2(A4-)AH3-3(A4-)G34-7(A4-)AD3(3-AI)3-AD3-A4-3(AF3-)2(A4-)AH3-2(A4-)2(G4-)G39-5(A4-)2(AD3-)AI2(3-AD)3-2(A4-)2(AF3-)4(A4-)4(G4-)G39-4(A4-)2(AD3-AI3-)AD3-3(A4-)AF3-A4-AH3-A4-A69-3(A4-)5(AD3-)6(A4-)A79-7(A4-)3(B4-)A4-A103-3E2(2-EAE)3-2(A4-)3(B4-)A4-A104-3(A4-)5(B4-)A4-A109-7(A4-)A33-
