model
size = 30 28 28, scale = 0.05, origin = -y
material 
  colors = A:#F36 B:#FFF C:#6CC D:#F93 E:#F99 F:#F39 G:#EEE H:#FC6 I:#F69 J:#FFC K:#FCC L:#F9C M:#FC3 N:#C36 O:#9CC P:#FC9 Q:#C9C R:#FF9 S:#CFF T:#F96 U:#C69 V:#C99
voxels
---------BBBFGDBFBBHB--------- ----------BBFIBEFBB----------- ----------DBBIIFBBBB---------- ------------BBGHBB------------ ------------------------------ ------------------------------ ------------------------------ ------------------------------ ------------------------------ ------------------------------ ------------------------------ ------------------------------ ------------------------------ ------------------------------ ------------------------------ ------------------------------ ------------------------------ ------------------------------ ------------------------------ ------------------------------ ------------------------------ ------------------------------ ------------------------------ ------------------------------ ------------------------------ ------------------------------ ------------------------------ ------------------------------ 
--------CAAAAAAAAAAAABC------- --------GBAAAAAAAAABGG-------- --------BDAAAAAAAAAAEB-------- ---------BFDAAAAAABCB--------- ----------ADBBJMBBGB---------- ------------BBGBBB------------ ------------------------------ ------------------------------ ------------------------------ ------------------------------ ------------------------------ ------------------------------ ------------------------------ ------------------------------ ------------------------------ ------------------------------ ------------------------------ ------------------------------ ------------------------------ ------------------------------ ------------------------------ ------------------------------ ------------------------------ ------------------------------ ------------------------------ ------------------------------ ------------------------------ ------------------------------ 
---IAOBBAAAAAAAAAAAAAAACIII--- ----CCBBAA---------AAABCCC---- ----CBBBAA----------AABBCC---- -----BBDFAAA------AAAEKBB----- -----BBDKCAAAAAAAAAAGBBBB----- ------BDQBFDAAAAAAECCEBB------ -------FDDDBBCCCBBBELBF------- -------LHGHBCIDPCBBBBBL------- --------EJBBCAGDCBBBBE-------- -----------BOCAICBB----------- -------------OCCB------------- -------------BGGB------------- ------------------------------ ------------------------------ ------------------------------ ------------------------------ ------------------------------ ------------------------------ ------------------------------ ------------------------------ ------------------------------ ------------------------------ ------------------------------ ------------------------------ ------------------------------ ------------------------------ ------------------------------ ------------------------------ 
--IAAAAAA-------------AAAAAI-- ---IAAAA--------------AAAAI--- ---GAAAA--------------AAAAG--- ----GAAAA------------AAAAG---- ----GAAAAA----------AAAAAG---- -----BBAAAAA------AAAAABB----- -------FAAAAAAAAAAAAAAF------- -------BAAAAAAAAAAAAAAB------- --------DAAAAAAAAAAAAD-------- ---------BBAAAAAAAARB--------- ----------EBBAAAABBF---------- ----------CEBAAAABDG---------- -----------EBBBBBBK----------- -------------BBBB------------- ------------------------------ ------------------------------ ------------------------------ ------------------------------ ------------------------------ ------------------------------ ------------------------------ ------------------------------ ------------------------------ ------------------------------ ------------------------------ ------------------------------ ------------------------------ ------------------------------ 
--DAA--------------------AAD-- --CA----------------------AC-- --CA----------------------AC-- ---HA--------------------AH--- ----HA------------------AH---- ----BAA----------------AAB---- -----FBA--------------ABB----- -----EBA--------------AFB----- -----CABAAA----------ABFC----- ------EBBAA--------AABBE------ -------IELAAA----AAADBI------- -------HCBAAA----AAANHH------- ---------ICAAAAAAAAEH--------- ----------ELBAAAABTB---------- -----------BBFIFBBB----------- -----------BFVBEIBP----------- -------------GDBF------------- ------------------------------ ------------------------------ ------------------------------ ------------------------------ ------------------------------ ------------------------------ ------------------------------ ------------------------------ ------------------------------ ------------------------------ ------------------------------ 
-CCA----------------------AAC- --CA----------------------AC-- --BA----------------------AB-- --BAA---------------------AB-- ---BA--------------------AB--- ---BAAA------------------AB--- ----BAA----------------AAB---- ----FAAA---------------AAF---- ----FAAAA-------------AAF----- -----FAAA------------AAAF----- ------BAAA----------AAAB------ ------BAAA----------AAAB------ -------BCAA--------AAFB------- -------BGGAAA----AAAUDB------- --------BGEAAAAAAAADDB-------- --------CGBAAAAAAAAMHC-------- ---------CBBFAAAABBHC--------- -----------BFEBEABB----------- -------------IIFB------------- ------------------------------ ------------------------------ ------------------------------ ------------------------------ ------------------------------ ------------------------------ ------------------------------ ------------------------------ ------------------------------ 
-BAA-----------------------AB- -BA------------------------AB- -BA------------------------AB- --KA----------------------AK-- --BA----------------------AB-- ---BA--------------------AB--- ---BA--------------------AB--- ---BA--------------------AB--- ----BA------------------AB---- -----BA----------------AB----- -----BBA---------------AB----- -----BBAA------------AAAB----- ------BBA------------AAB------ ------JJAA----------AAAJ------ -------BAAA--------AAAB------- -------BAAA--------AAAB------- --------BAAAA----AAAAB-------- --------BBBAAAAAAAABBB-------- ---------BDBBAAAABBBB--------- ------------BBGHBB------------ ------------BBJMBB------------ -------------BBBB------------- ------------------------------ ------------------------------ ------------------------------ ------------------------------ ------------------------------ ------------------------------ 
-BA------------------------AB- -BA------------------------AB- -LA------------------------AL- --EA----------------------AE-- --BA----------------------AB-- ---EA--------------------AE--- ---BA--------------------AB--- ---BA--------------------AB--- ----BA------------------AB---- -----BA----------------AB----- -----BA----------------AB----- -----HAA---------------AH----- ------FA---------------F------ ------DA--------------AD------ -------DA------------AD------- -------HA------------AH------- --------BA----------AB-------- --------BAA--------AAB-------- ---------KAAA----AAAK--------- ----------EDAAAAAABE---------- ----------BDAAAAAASB---------- -----------DBAAAABE----------- ------------BCCCBB------------ -------------FDJC------------- -------------NGDC------------- ------------------------------ ------------------------------ ------------------------------ 
HAA------------------------AAH GAA------------------------AG- -EA------------------------AE- -CA------------------------AC- --GA----------------------AG-- --CA----------------------AC-- ---LA--------------------AL--- ---BA--------------------AB--- ---BA--------------------AB--- ----JA------------------AJ---- -----DA----------------AD----- -----NAA---------------AN----- -----EEA---------------AE----- ------UA--------------AU------ ------DA--------------AD------ ------HAA------------AAH------ -------HHA-----------AH------- --------BA----------AB-------- --------EA----------AE-------- ---------CAA------AAC--------- ---------SAA------AAS--------- ----------CAAAAAAAAC---------- ----------EBBCCCBBBE---------- -----------BCFDJCBB----------- -----------BCNGDCBB----------- ------------CCNKCB------------ -------------CCCB------------- ------------------------------ 
HAA-------------------------AH BAA-------------------------AB BAA-------------------------AB -CA------------------------AC- -BA------------------------AB- --CA----------------------AC-- --EA----------------------AE-- --BA----------------------AB-- ---BA--------------------AB--- ---RAA------------------AAR--- ----DA------------------AD---- ----AA------------------AA---- ----EAAA----------------AE---- -----BBA---------------AB----- -----DDA---------------AD----- -----MMA-------------AAAM----- ------HAA------------AAH------ ------BBA------------ABB------ -------BA------------AB------- --------CA----------AC-------- --------BA----------AB-------- --------CCAAAAAAAAAACC-------- ---------EAAAAAAAAAAE--------- ---------BHAAAAAAAABB--------- ---------BBAAAAAAAABB--------- ----------RBAAAAAABR---------- ----------DBBAAAABBD---------- -----------EBHGHBBD----------- 
BAA-------------------------AB BAA-------------------------AB BAA-------------------------AB BAA-------------------------AB -GA------------------------AG- -EA------------------------AE- --BA----------------------AB-- --BA----------------------AB-- --BA----------------------AB-- ---BAA------------------AAB--- ----BA------------------AB---- ----DA------------------AD---- ----KAA-----------------AK---- -----TA----------------AT----- -----BA----------------AB----- -----PA---------------AAP----- ------BA--------------AB------ ------BA--------------AB------ -------BA------------AB------- -------BA------------AB------- -------SA------------AS------- --------EA---------AAE-------- --------BAA--------AAB-------- ---------BA--------AB--------- ---------BA--------AB--------- ----------BAA-----AAB--------- ----------BAA----AAB---------- ----------DAAAAAAAAD---------- 
BAA-------------------------AB BAA-------------------------AB BAA-------------------------AB BAA-------------------------AB -BA------------------------AB- -BA------------------------AB- --BA----------------------AB-- --BA----------------------AB-- --BA----------------------AB-- ---BA--------------------AB--- ---BA--------------------AB--- ---BA--------------------AB--- ----BA------------------AB---- ----BA------------------AB---- -----BA----------------AB----- -----BA----------------AB----- -----BBA---------------AB----- ------BA--------------AB------ ------BA--------------AB------ -------BA------------AB------- -------BA------------AB------- -------BA------------AB------- --------BAA--------AAB-------- --------BAA--------AAB-------- --------BAA--------AAB-------- ---------BA--------AB--------- ---------BA--------AB--------- ----------BA------AB---------- 
FAA-------------------------AF FAA-------------------------AF BAA-------------------------AB BAA-------------------------AB -BA------------------------AB- -BA------------------------AB- --BA----------------------AB-- --CA----------------------AC-- --CA----------------------AC-- ---CA--------------------AC--- ---BA--------------------AB--- ---BA--------------------AB--- ----BA------------------AB---- ----BA------------------AB---- -----BA----------------AB----- -----IA----------------AI----- -----FA----------------AF----- ------AA--------------AA------ ------BA--------------AB------ -------BA------------AB------- -------BA------------AB------- -------BA------------AB------- --------BAA--------AAB-------- --------CAA--------AAC-------- --------CAA--------AAC-------- ---------CA--------AC--------- ---------BA--------AB--------- ----------BA------AB---------- 
BAA-------------------------AB EAA-------------------------AE FAA-------------------------AF HAA-------------------------AH -MA------------------------AM- -BA------------------------AB- --CA----------------------AC-- --PA----------------------AP-- --DA----------------------AD-- ---IA--------------------AI--- ---CA--------------------AC--- ---GA--------------------AG--- ----BA------------------AB---- ----BA------------------AB---- -----FA----------------AF----- -----EA----------------AE----- -----BA----------------AB----- ------EA--------------AE------ ------FA--------------AF------ -------HA------------AH------- -------MA------------AM------- -------BA------------AB------- --------CAA--------AAC-------- --------JAA--------AAJ-------- --------DAA--------AAD-------- ---------KA--------AK--------- ---------CA--------AC--------- ----------HA------AH---------- 
DAA-------------------------AD BAA-------------------------AB IAA-------------------------AI GAA-------------------------AG -JA------------------------AJ- -GA------------------------AG- --CA----------------------AC-- --DA----------------------AD-- --GA----------------------AG-- ---AA--------------------AA--- ---CA--------------------AC--- ---GA--------------------AG--- ----BA------------------AB---- ----BA------------------AB---- -----IA----------------AI----- -----BA----------------AB----- -----DA----------------AD----- ------BA--------------AB------ ------IA--------------AI------ -------GA------------AG------- -------JA------------AJ------- -------BA------------AB------- --------CAA--------AAC-------- --------DAA--------AAD-------- --------GAA--------AAG-------- ---------NA--------AN--------- ---------CA--------AC--------- ----------GA------AG---------- 
GAA------------------------AAG IAA-------------------------AI IAA-------------------------AI BAA-------------------------AB -BA------------------------AB- -BA------------------------AB- --CA----------------------AC-- --IA----------------------AI-- --AA----------------------AA-- ---CA--------------------AC--- ---OA--------------------AO--- ---BA--------------------AB--- ----BA------------------AB---- ----BA------------------AB---- -----FA----------------AF----- -----VA----------------AV----- -----GA----------------AG----- ------EA--------------AE------ ------IA--------------AI------ -------BA------------AB------- -------BA------------AB------- -------BA----------AAAB------- --------CAA--------AAC-------- --------FAA--------AAF-------- --------NAA--------AAN-------- ---------CA--------AC--------- ---------CA--------AC--------- ----------HA------AH---------- 
FAA------------------------AB- FAA------------------------AB- BAA------------------------AB- BAA------------------------AB- -BA------------------------AB- -BA------------------------AB- --BA----------------------AB-- --CA----------------------AC-- --CA----------------------AC-- ---OAA-------------------AO--- ----BA------------------AB---- ----BA------------------AB---- ----BA------------------AB---- -----BA----------------AB----- -----BA----------------AB----- -----FA----------------AF----- ------FA--------------AF------ ------FA--------------AF------ -------BA------------AB------- -------BA------------AB------- -------BA-----------AAB------- --------BAA--------ABB-------- --------BAA--------AAB-------- ---------CA--------AC--------- ---------CA--------AC--------- ---------CA-------ACC--------- ----------BA------AB---------- ----------BAA----AAB---------- 
BAA------------------------AB- BAA------------------------AB- BAA------------------------AB- -DA------------------------AD- -DA------------------------AD- --DA----------------------AD-- --BA----------------------AB-- --BAA---------------------AB-- ---BA--------------------AB--- ---BAA-------------------AB--- ----BA------------------AB---- ----EA------------------AE---- ----EEA-----------------AE---- -----LA----------------AL----- -----BA----------------AB----- -----BA----------------AB----- ------BA--------------AB------ ------BA--------------AB------ -------BAAA----------AB------- --------DAA---------AD-------- --------DAA---------AD-------- --------DAA--------AD--------- ---------BA--------AB--------- ---------BA--------AB--------- ---------BA--------AB--------- ----------BA------AB---------- ----------BAA----AAB---------- -----------DAAAAAAE----------- 
BAA-----------------------AAH- BAA------------------------AB- DAA------------------------AB- -FA------------------------AF- -AA------------------------AA- --FA----------------------AF-- ---DA--------------------AD--- ---HA--------------------AH--- ---BBA-------------------AB--- ----BAA-----------------AB---- ----EEA-----------------AE---- ----CCA----------------ACC---- -----CA----------------AC----- -----EAA---------------AE----- ------EA--------------AE------ ------BAA-------------AB------ ------BAA-------------AB------ -------BA------------AB------- -------DAAA----------AD------- --------FAA---------AF-------- --------AAA---------AA-------- ---------FAAA------AF--------- ---------DAAA-----AAD--------- ----------HAA----AAH---------- ----------BAA----AAB---------- -----------BAAAAAAB----------- -----------BBAAAABB----------- ------------BBHGHB------------ 
BAA-----------------------AH-- -BA-----------------------AG-- -DA-----------------------AE-- -BA-----------------------AC-- --CA----------------------AC-- --BA----------------------AB-- ---DA--------------------AD--- ---GA--------------------AG--- ---JJA-------------------AJ--- ----JAA-----------------AJ---- -----LA----------------AL----- -----BA----------------AB----- -----IA----------------AI----- ------GA--------------AG------ ------GBA-------------AG------ ------GBBA------------AG------ -------BAA-----------AB------- --------BAA--------AAB-------- --------DAA---------AD-------- ---------BAA------AAB--------- ---------CAA------AAC--------- ----------BAAAAAAAAB---------- ----------DBBAAAAABD---------- -----------BBAAAACB----------- -----------BBAAAACB----------- ------------BCKNCC------------ -------------BCCC------------- ------------------------------ 
-BA-----------------------AB-- -HA-----------------------AB-- -DA-----------------------AL-- --FA----------------------AF-- --KA----------------------AK-- ---QA--------------------AQ--- ---DA--------------------AD--- ---HAAA------------------AH--- ----HAA-----------------AH---- -----BA----------------AB----- -----EA----------------AE----- -----CA---------------ACC----- ------CA--------------AC------ ------GAA-------------AG------ -------EEA-----------AE------- --------BA-----------AB------- --------BAA--------AAB-------- --------HPPA------ABBH-------- ---------DAAA----AAAD--------- ----------FBAAAAAADF---------- ----------KSAAAAAADK---------- -----------EBAAAABDQ---------- -------------BCCCB------------ -------------CJDF------------- -------------CDGN------------- ------------------------------ ------------------------------ ------------------------------ 
-BAA----------------------AB-- --BA----------------------AB-- --BA----------------------AB-- --DA---------------------AAD-- ---DA--------------------AD--- ---DA--------------------AD--- ----BA------------------AB---- ----BAA----------------AAB---- -----BA----------------AB----- -----BA----------------AB----- ------BA--------------AB------ ------EAA-------------AE------ -------EA------------AE------- -------EAA----------AAE------- --------BAA--------AAB-------- --------BAA--------AAB-------- ---------BAAA----AAAB--------- ----------BAAAAAAAAB---------- ----------BBBAAAABBB---------- ------------BBHGBB------------ ------------BBMJBB------------ -------------BBBB------------- ------------------------------ ------------------------------ ------------------------------ ------------------------------ ------------------------------ ------------------------------ 
--BA---------------------AAB-- --BA----------------------AB-- --BA----------------------AB-- ---BAA-------------------AB--- ----BA------------------AB---- ----BAA---------------AAAB---- -----BA---------------AAB----- -----BAAA-------------AAB----- -----AAAA-------------AAA----- ------BAA------------AAB------ -------BAA----------AAB------- -------BAA----------AAB------- --------BAA--------AAB-------- --------BUAAA----AAAGB-------- ---------BDAAAAAAAAEB--------- ---------BMAAAAAAAABB--------- ----------BBBAAAAFBB---------- -----------BBAEBEFB----------- -------------BFII------------- ------------------------------ ------------------------------ ------------------------------ ------------------------------ ------------------------------ ------------------------------ ------------------------------ ------------------------------ ------------------------------ 
--OAA-------------------AAD--- --CA---------------------AC--- --BA---------------------AC--- ---BAA-------------------AB--- ----BA------------------AB---- ----BAA---------------AAAB---- -----BBA--------------ABB----- -----IFAAA------------ABI----- -----EFBBA-----------ABAE----- ------IBBAA--------AABBI------ -------FBDAAA----AAALEF------- -------BHNAAA----AAABCB------- ---------BEAAAAAAAAEB--------- ----------BTBAAAABLB---------- -----------BBBFIFBB----------- -----------PBIEBVFB----------- -------------FBDG------------- ------------------------------ ------------------------------ ------------------------------ ------------------------------ ------------------------------ ------------------------------ ------------------------------ ------------------------------ ------------------------------ ------------------------------ ------------------------------ 
--AAAAAAAA------------AAAAI--- ---FAAAAA-------------AAAAF--- ---CAAAAA-------------AAACC--- ----HAAAA------------AAAAH---- ----BAAAAA----------AAAAAB---- -----BBAAAAA------AAAAABB----- -------FAAAAAAAAAAAAAAF------- -------GBAAAAAAAAAAAAAG------- ---------JAAAAAAAAAAAC-------- ---------JRAAAAAAAAHB--------- ----------DBBAAAABBI---------- ----------ADBAAAABEM---------- -----------KBBBBBBE----------- -------------BBBB------------- ------------------------------ ------------------------------ ------------------------------ ------------------------------ ------------------------------ ------------------------------ ------------------------------ ------------------------------ ------------------------------ ------------------------------ ------------------------------ ------------------------------ ------------------------------ ------------------------------ 
---QIDCBBAAAAAAAAAAAAAABQQQ--- ----ACCBBA---------AAABBAA---- ----CCBBLA----------AABBCC---- -----MBKEAAA------AAAFDBM----- -----BBBBGAAAAAAAAAACKDBB----- ------BBECCEAAAAAADFBQDB------ -------FBLEBBBCCCBBDDDF------- -------BBBBBBCPDICBHGHB------- ---------BBBBCDGACBBJC-------- -----------BBCIACOB----------- -------------BCCO------------- -------------BGGB------------- ------------------------------ ------------------------------ ------------------------------ ------------------------------ ------------------------------ ------------------------------ ------------------------------ ------------------------------ ------------------------------ ------------------------------ ------------------------------ ------------------------------ ------------------------------ ------------------------------ ------------------------------ ------------------------------ 
---------HAAAAAAAAAAABL------- ---------GAAAAAAAAABBA-------- ---------EAAAAAAAAAADC-------- ---------CCBAAAAAADFB--------- ----------BGBBMJBBDB---------- ------------BBBGBB------------ ------------------------------ ------------------------------ ------------------------------ ------------------------------ ------------------------------ ------------------------------ ------------------------------ ------------------------------ ------------------------------ ------------------------------ ------------------------------ ------------------------------ ------------------------------ ------------------------------ ------------------------------ ------------------------------ ------------------------------ ------------------------------ ------------------------------ ------------------------------ ------------------------------ ------------------------------ 
---------HHBBFBDGFBBB--------- ----------BBBFEBIFB----------- ----------BBBBFIIBBB---------- ------------BBHGBB------------ ------------------------------ ------------------------------ ------------------------------ ------------------------------ ------------------------------ ------------------------------ ------------------------------ ------------------------------ ------------------------------ ------------------------------ ------------------------------ ------------------------------ ------------------------------ ------------------------------ ------------------------------ ------------------------------ ------------------------------ ------------------------------ ------------------------------ ------------------------------ ------------------------------ ------------------------------ ------------------------------ ------------------------------ 
