model
size = 25 24 22, scale = 0.05, origin = -y
material 
  colors = A:#EEE B:#9FF C:#FF3 D:#555 E:#0E0 F:#777 G:#00E H:#D00 I:#0F3
voxels
---C-------CCC-------C--- ---C-----------------C--- ---C-----------------C--- ------------------------- ------------------------- ------------------------- ------------------------- ------------------------- ------------------------- ------------------------- ------------------------- ------------------------- ------------------------- ---C-----------------C--- ---C-----------------C--- ---C-----------------C--- ------------------------- ------------------------- ------------------------- ------------------------- ------------------------- ------------------------- ------------------------- ------------------------- 
---D-------DDD-------D--- ---DBBBBBBBBBBBBBBBBBD--- ---DBBBBBBBBBBBBBBBBBD--- ----BBBBBBBBBBBBBBBBB---- ----BBBBBBBBBBBBBBBBB---- ----BBBBBBBBBBBBBBBBB---- ----BBBBBBBBBBBBBBBBB---- ----BBBBBBBBBBBBBBBBB---- ----BBBBBBBBBBBBBBBBB---- ----BBBBBBBBBBBBBBBBB---- ----BBBBBBBBBBBBBBBBB---- ----BBBBBBBBBBBBBBBBB---- ----BBBBBBBBBBBBBBBBB---- ---DBBBBBBBBBBBBBBBBBD--- ---DBBBBBBBBBBBBBBBBBD--- ---DBBBBBBBBBBBBBBBBBD--- ------------------------- ------------------------- ------------------------- ------------------------- ------------------------- ------------------------- ------------------------- ------------------------- 
--AAAAAAAAAAAAAAAAAAAAA-- --AABBBBBBBBBBBBBBBBBAA-- --AABBBBBBBBBBBBBBBBBAA-- --AABBBBBBBBBBBBBBBBBAA-- --AABBBBBBBBBBBBBBBBBAA-- --AABBBBBBBBBBBBBBBBBAA-- --AABBBBBBBBBBBBBBBBBAA-- --AABBBBBBBBBBBBBBBBBAA-- --AABBBBBBBBBBBBBBBBBAA-- --AABBBBBBBBBBBBBBBBBAA-- --AABBBBBBBBBBBBBBBBBAA-- --AABBBBBBBBBBBBBBBBBAA-- --AABBBBBBBBBBBBBBBBBAA-- --AABBBBBBBBBBBBBBBBBAA-- --AABBBBBBBBBBBBBBBBBAA-- ---ABBBBBBBBBBBBBBBBBA--- ----BBBBBBBBBBBBBBBBB---- ------------------------- ------------------------- ------------------------- ------------------------- ------------------------- ------------------------- ------------------------- 
--AAAAAAAAAAAAAAAAAAAAA-- --AA-----------------AA-- --AA-----------------AA-- --AA-----------------AA-- --AA-----------------AA-- --AA-----------------AA-- --AA-----------------AA-- --AA-----------------AA-- --AA-----------------AA-- --AA-----------------AA-- --AA-----------------AA-- --AA-----------------AA-- --AA-----------------AA-- --AA-----------------AA-- --AA-----------------AA-- ---A-----------------A--- ----BBBBBBBBBBBBBBBBB---- ------------------------- ------------------------- ------------------------- ------------------------- ------------------------- ------------------------- ------------------------- 
--AAAAAAAAAAAAAAAAAAAAA-- --AA-----------------AA-- --AA-----------------AA-- -AAA-----------------AAA- -AAA-----------------AAA- -AAA-----------------AAA- -AAA-----------------AAA- -AAA-----------------AAA- -AAA-----------------AAA- -AAA-----------------AAA- -AAA-----------------AAA- -AAA-----------------AAA- -AAA-----------------AAA- --AA-----------------AA-- --AA-----------------AA-- ---A-----------------A--- ----AAAAAAAAAAAAAAAAA---- ------------------------- ------------------------- ------------------------- ------------------------- ------------------------- ------------------------- ------------------------- 
--AAAAAAAAAAAAAAAAAAAAA-- --AA-----------------AA-- --AA-----------------AA-- -AAA-----------------AAA- -AAA-----------------AAA- -AAA-----------------AAA- -AAA-----------------AAA- -AAA-----------------AAA- -AAA-----------------AAA- -AAA-----------------AAA- -AAA-----------------AAA- -AAA-----------------AAA- -AAA-----------------AAA- --AA-----------------AA-- --AA-----------------AA-- ---A-----------------A--- ----AAAAAAAAAAAAAAAAA---- -----AAAAAAAAAAAAAAA----- -----------CCC----------- ------------------------- ------------------------- ------------------------- ------------------------- ------------------------- 
--AAAAAAAAAAAAAAAAAAAAA-- --AA-----------------AA-- --AA-----------------AA-- -AAA-----------------AAA- -AAA-----------------AAA- -AAA-----------------AAA- -AAA-----------------AAA- -AAA-----------------AAA- -AAA-----------------AAA- -AAA-----------------AAA- -AAA-----------------AAA- -AAA-----------------AAA- -AAA-----------------AAA- --AA-----------------AA-- --AA-----------------AA-- ---A-----------------A--- ----AAAAAAAAAAAAAAAAA---- -----AAAAAAAAAAAAAAA----- -----------DDD----------- ------------------------- ------------------------- ------------------------- ------------------------- ------------------------- 
--AAAAAAAAAAAAAAAAAAAAA-- --AA-----------------AA-- --AA-----------------AA-- -AAA-----------------AAA- -AAA-----------------AAA- AAAA-----------------AAAA AAAA-----------------AAAA AAAA-----------------AAAA AAAA-----------------AAAA AAAA-----------------AAAA AAAA-----------------AAAA -AAA-----------------AAA- -AAA-----------------AAA- --AA-----------------AA-- --AA-----------------AA-- ---A-----------------A--- ----AAAAAAAAAAAAAAAAA---- -----AAAAAAAAAAAAAAA----- -------AAAAAAAAAAA------- ------------------------- ------------------------- ------------------------- ------------------------- ------------------------- 
--AAAAAAAAAAAAAAAAAAAAA-- --AA-----------------AA-- --AA-----------------AA-- -AAA-----------------AAA- -AAA-----------------AAA- AAAA-----------------AAAA AAAA-----------------AAAA AAAA-----------------AAAA AAAA-----------------AAAA AAAA-----------------AAAA AAAA-----------------AAAA -AAA-----------------AAA- -AAA-----------------AAA- --AA-----------------AA-- --AA-----------------AA-- ---A-----------------A--- ----AAAAAAAAAAAAAAAAA---- -----AAAAAAAAAAAAAAA----- -------AAAAAAAAAAA------- ------------------------- ------------------------- ------------------------- ------------------------- ------------------------- 
--AAAAAAAAAAAAAAAAAAAAA-- --AA-----------------AA-- --AA-----------------AA-- -AAA-----------------AAA- -AAA-----------------AAA- AAAA-----------------AAAA AAAA-----------------AAAA AAAA-----------------AAAA AAAA-----------------AAAA AAAA-----------------AAAA AAAA-----------------AAAA -AAA-----------------AAA- -AAA-----------------AAA- --AA-----------------AA-- --AA-----------------AA-- ---A-----------------A--- ----AAAAAAAAAAAAAAAAA---- -----AAAAAAAAAAAAAAA----- -------AAAAAAAAAAA------- ------------------------- ------------------------- ------------------------- ------------------------- ------------------------- 
--AAAAAAAAAAAAAAAAAAAAA-- --AA-----------------AA-- --AA-----------------AA-- -AAA-----------------AAA- -AAA-----------------AAA- AAAA-----------------AAAA AAAA-----------------AAAA AAAA-----------------AAAA AAAA-----------------AAAA AAAA-----------------AAAA AAAA-----------------AAAA EAAA-----------------AAA- -AAA-----------------AAA- --AA-----------------AA-- --AA-----------------AA-- ---A-----------------A--- ----AAAAAAAAAAAAAAAAA---- -----AAAAAAAAAAAAAAA----- -------AAAAAAAAAAA------- ------------------------- ------------------------- ------------------------- ------------------------- ------------------------- 
--AAAAAAAAAAAAAAAAAAAAA-- --AA-----------------AA-- --AA-----------------AA-- -AAA-----------------AAA- -AAA-----------------AAA- AAAA-----------------AAAA AAAA-----------------AAAA AAAA-----------------AAAA AAAA-----------------AAAA AAAA-----------------AAAA AAAA-----------------AAAA EAAA-----------------AAAE -AAA-----------------AAA- --AA-----------------AA-- --AA-----------------AA-- ---A-----------------A--- ----AAAAAAAAAAAAAAAAA---- -----AAAAAAAAAAAAAAA----- -------AAAAAAAAAAA------- ------------------------- ------------------------- ------------------------- ------------------------- ------------------------- 
--AAAAAAAAAAAAAAAAAAAAA-- --AA-----------------AA-- --AA-----------------AA-- -AAA-----------------AAA- -AAA-----------------AAA- AAAA-----------------AAAA AAAA-----------------AAAA AAAA-----------------AAAA AAAA-----------------AAAA AAAA-----------------AAAA AAAA-----------------AAAA EAAA-----------------AAAE -AAA-----------------AAA- --AA-----------------AA-- --AA-----------------AA-- ---A-----------------A--- ----AAAAAAAAAAAAAAAAA---- -----AAAAAAAAAAAAAAA----- -------AAAAAAAAAAA------- ------------------------- ------------------------- ------------------------- ------------------------- ------------------------- 
--AAAAAAAAAAAAAAAAAAAAA-- --AA-----------------AA-- --AA-----------------AA-- -AAA-----------------AAA- -AAA-----------------AAA- AAAA-----------------AAAA AAAA-----------------AAAA AAAA-----------------AAAA AAAA-----------------AAAA AAAA-----------------AAAA AAAA-----------------AAAA EAAA-----------------AAAE -AAA-----------------AAA- --AA-----------------AA-- --AA-----------------AA-- ---A-----------------A--- ----AAAAAAAAAAAAAAAAA---- -----AAAAAAAAAAAAAAA----- -------AAAAAAAAAAA------- ------------------------- ------------------------- ------------------------- ------------------------- ------------------------- 
--AAAAAAAAAAAAAAAAAAAAA-- --AA-----------------AA-- --AA-----------------AA-- -AAA-----------------AAA- -AAA-----------------AAA- -AAA-----------------AAAA -AAA-----------------AAAA -AAA-----------------AAAA -AAA-----------------AAAA -AAA-----------------AAAA -AAA-----------------AAAA EAAA-----------------AAAE -AAA-----------------AAA- --AA-----------------AA-- --AA-----------------AA-- ---A-----------------A--- ----AAAAAAAAAAAAAAAAA---- -----AAAAAAAAAAAAAAA----- -------AAAAAAAAAAA------- ------------------------- ------------------------- ------------------------- ------------------------- ------------------------- 
--AAAAAAAAAAAAAAAAAAAAA-- --AA-----------------AA-- --AA-----------------AA-- -AAA-----------------AAA- -AAA-----------------AAA- -AAA-----------------AAA- -AAA-----------------AAA- -AAA-----------------AAA- -AAA-----------------AAA- -AAA-----------------AAA- -AAA-----------------AAA- -AAA-----------------AAAE -AAA-----------------AAA- --AA-----------------AA-- --AA-----------------AA-- ---A-----------------A--- ----AAAAAAAAAAAAAAAAA---- -----AAAAAAAAAAAAAAA----- -------AAAAAAAAAAA------- ------------------------- ------------------------- ------------------------- ------------------------- ------------------------- 
--AAAAAAAAAAAAAAAAAAAAA-- --AA-----------------AA-- --AA-----------------AA-- --AA-----------------AAA- --AA-----------------AAA- --AA-----------------AAA- --AA-----------------AAA- --AA-----------------AAA- --AA-----------------AAA- --AA-----------------AAA- --AA-----------------AAA- --AA-----------------AAA- --AA-----------------AAA- --AA-----------------AA-- --AA-----------------AA-- ---A-----------------A--- ----AAAAAAAAAAAAAAAAA---- -----AAAAAAAAAAAAAAA----- ------------------------- ------------------------- ------------------------- ------------------------- ------------------------- ------------------------- 
--AAAAAAAAAAAAAAAAAAAAA-- --AA-----------------AA-- --AA-----------------AA-- --AA-----------------AA-- --AA-----------------AA-- --AA-----------------AA-- --AA-----------------AA-- --AA-----------------AA-- --AA-----------------AA-- --AA-----------------AA-- --AA-----------------AA-- --AA-----------------AA-- --AA-----------------AA-- --AA-----------------AA-- --AA-----------------AA-- ---A-----------------A--- ----AAAAAAAAAAAAAAAAA---- -----AAAAAAAAAAAAAAA----- ------------------------- ------------------------- ------------------------- ------------------------- ------------------------- ------------------F------ 
--AAAAAAAAAAAAAAAAAAAAA-- ---AAAAAAAAAAAAAAAAAAA--- ---AAAAAAAAAAAAAAAAAAA--- ---AAAAAAAAAAAAAAAAAAA--- ---AAAAAAAAAAAAAAAAAAA--- ---AAAAAAAAAAAAAAAAAAA--- ---AAAAAAAAAAAAAAAAAAA--- ---AAAAAAAAAAAAAAAAAAA--- ---AAAAAAAAAAAAAAAAAAA--- ---AAAAAAAAAAAAAAAAAAA--- ---AAAAAAAAAAAAAAAAAAA--- ---AAAAAAAAAAAAAAAAAAA--- ---AAAAAAAAAAAAAAAAAAA--- ---AAAAAAAAAAAAAAAAAAA--- ---AAAAAAAAAAAAAAAAAAA--- ----AAAAAAAAAAAAAAAAA---- ----AAAAAAAAAAAAAAAAA---- -----AAAAAAAAAAAAAAA----- ------------------F------ ------------------F------ -----------------FF------ ------------------F------ ------------------FF----- ------------------F------ 
--AAAAAAAAAAAAAAAAAAAAA-- ---AAAAAAAAAAAAAAAAAAA--- ---AAAAAAAAAAAAAAAAAAA--- ---AAAAAAAAAAAAAAAAAAA--- ---AAAAAAAAAAAAAAAAAAA--- ---AAAAAAAAAAAAAAAAAAA--- ---AAAAAAAAAAAAAAAAAAA--- ---AAAAAAAAAAAAAAAAAAA--- ---AAAAAAAAAAAAAAAAAAA--- ----AAAAAAAAAAAAAAAAA---- ----AAAAAAAAAAAAAAAAA---- ----AAAAAAAAAAAAAAAAA---- ----AAAAAAAAAAAAAAAAA---- ----AAAAAAAAAAAAAAAAA---- ----AAAAAAAAAAAAAAAAA---- ----AAAAAAAAAAAAAAAAA---- ----AAAAAAAAAAAAAAAAA---- ------------------------- ------------------------- ------------------------- ------------------------- ------------------F------ ------------------------- ------------------------- 
--AAAAAAAAAAAAAAAAAAAAA-- ---AAAAAAAAAAAAAAAAAAA--- ---AAAAAAAAAAAAAAAAAAA--- ---AAAAAAAAAAAAAAAAAAA--- ---AAAAAAAAAAAAAAAAAAA--- ----AAAAAAAAAAAAAAAAA---- ----AAAAAAAAAAAAAAAAA---- ----AAAAAAAAAAAAAAAAA---- ----AAAAAAAAAAAAAAAAA---- ----AAAAAAAAAAAAAAAAA---- ----AAAAAAAAAAAAAAAAA---- ----AAAAAAAAAAAAAAAAA---- ----AAAAAAAAAAAAAAAAA---- ----AAAAAAAAAAAAAAAAA---- ----AAAAAAAAAAAAAAAAA---- ----AAAAAAAAAAAAAAAAA---- ----AAAAAAAAAAAAAAAAA---- ------------------------- ------------------------- ------------------------- ------------------------- ------------------------- ------------------------- ------------------------- 
--AAAAAAAAAAAAAAAAAAAAA-- ------AAAAAAAAAAAAA------ ------AAAAAAAAAAAAA------ ------AA---------AA------ ------AA----I----AA------ ------AA--G---H--AA------ ------AA--H---G--AA------ ------AA--G-I-H--AA------ ------AA--H---G--AA------ ------AA--G---H--AA------ ------AA----I----AA------ ------AAAAAAAAAAAAA------ ------AAAAAAAAAAAAA------ ------------------------- ------------------------- ------------------------- ------------------------- ------------------------- ------------------------- ------------------------- ------------------------- ------------------------- ------------------------- ------------------------- 
