model
size = 27 22 16, scale = 0.05, origin = -y
material 
  colors = A:#111 B:#CF6
voxels
-------------A------------- --------------------------- --------------------------- --------------------------- --------------------------- --------------------------- --------------------------- --------------------------- --------------------------- --------------------------- --------------------------- --------------------------- --------------------------- --------------------------- --------------------------- --------------------------- --------------------------- --------------------------- --------------------------- --------------------------- --------------------------- --------------------------- 
------------B-B------------ --------------------------- --------------------------- --------------------------- --------------------------- --------------------------- --------------------------- --------------------------- --------------------------- --------------------------- --------------------------- --------------------------- --------------------------- --------------------------- --------------------------- --------------------------- --------------------------- --------------------------- --------------------------- --------------------------- --------------------------- --------------------------- 
-----------A---A----------- --------------------------- --------------------------- --------------------------- --------------------------- --------------------------- --------------------------- --------------------------- --------------------------- --------------------------- --------------------------- --------------------------- --------------------------- --------------------------- --------------------------- --------------------------- --------------------------- --------------------------- --------------------------- --------------------------- --------------------------- --------------------------- 
----------B-----B---------- --------------------------- --------------------------- --------------------------- --------------------------- --------------------------- --------------------------- --------------------------- --------------------------- --------------------------- --------------------------- --------------------------- --------------------------- --------------------------- --------------------------- --------------------------- --------------------------- --------------------------- --------------------------- --------------------------- --------------------------- --------------------------- 
----------A-BAB-A---------- -------------A------------- --------------------------- --------------------------- --------------------------- --------------------------- --------------------------- --------------------------- --------------------------- --------------------------- --------------------------- --------------------------- --------------------------- --------------------------- --------------------------- --------------------------- --------------------------- --------------------------- --------------------------- --------------------------- --------------------------- --------------------------- 
----------BA---AB---------- -------------A------------- -------------B------------- --------------------------- --------------------------- --------------------------- --------------------------- --------------------------- --------------------------- --------------------------- --------------------------- --------------------------- --------------------------- --------------------------- --------------------------- --------------------------- --------------------------- --------------------------- --------------------------- --------------------------- --------------------------- --------------------------- 
--------------------------- --------------------------- -------------A------------- -------------A------------- --------------------------- --------------------------- --------------------------- --------------------------- --------------------------- --------------------------- --------------------------- --------------------------- --------------------------- --------------------------- --------------------------- --------------------------- --------------------------- --------------------------- --------------------------- --------------------------- --------------------------- --------------------------- 
--------------------------- --------------------------- --------------------------- -------------A------------- -------------B------------- --------------------------- --------------------------- --------------------------- --------------------------- --------------------------- --------------------------- --------------------------- --------------------------- --------------------------- --------------------------- --------------------------- --------------------------- --------------------------- --------------------------- --------------------------- --------------------------- --------------------------- 
--------------------------- --------------------------- --------------------------- --------------------------- -------------A------------- -------------A------------- --------------------------- --------------------------- --------------------------- --------------------------- --------------------------- --------------------------- --------------------------- --------------------------- --------------------------- --------------------------- --------------------------- --------------------------- --------------------------- --------------------------- --------------------------- --------------------------- 
--------------------------- --------------------------- --------------------------- --------------------------- --------------------------- -------------A------------- -------------B------------- --------------------------- --------------------------- --------------------------- --------------------------- --------------------------- --------------------------- --------------------------- --------------------------- --------------------------- --------------------------- --------------------------- --------------------------- --------------------------- --------------------------- --------------------------- 
--------------------------- --------------------------- --------------------------- --------------------------- --------------------------- --------------------------- -------------A------------- -------------A------------- --------------------------- --------------------------- --------------------------- --------------------------- --------------------------- --------------------------- --------------------------- --------------------------- --------------------------- --------------------------- --------------------------- --------------------------- --------------------------- --------------------------- 
--------------------------- --------------------------- --------------------------- --------------------------- --------------------------- --------------------------- BB-----------------------BB BAA----------A----------ABB BAAA---------B---------AAAB BAAA-------------------AAAB BAAA-------------------AAAB BAAA-------------------AAAB BAAA-------------------AAAB BAAA-------------------AAAB -BAA-------------------AAB- -BAA-------------------AAB- -BAA-------------------AAB- --BB-------------------BB-- --------------------------- --------------------------- --------------------------- ------B-------------B------ 
--------------------------- --------------------------- --------------------------- --------------------------- --------------------------- --------------------------- --------------------------- -BB--AA-------------AA--BB- -AAAAAA------A------AAAAAA- BAAAAAA------A------AAAAAAB BAABAAA-------------AAABAAB BAABAAA-------------AAABAAB -AABAAA-------------AAABAA- -AAAAAA-------------AAAAAA- -BAAAA---------------AAAAB- -BAAAA---------------AAAAB- -BAAAA---------------AAAAB- --BAAA---------------AAAB-- --BAAA---------------AAAB-- ---BBA---------------ABB--- -----AA-------------AA----- -----AB-------------BA----- 
--------------------------- --------------------------- --------------------------- --------------------------- --------------------------- --------------------------- --------------------------- -----BBB-----------BBB----- ---BBBAA-----B-----BBBBB--- ----AAAA-----A-----AAAA---- ----AAAA-----B-----AAAA---- ----AAAA-----A-----AAAA---- ----AAAA-----B-----AAAA---- ----AAAA-----A-----AAAA---- ----AAAA-----------AAAA---- ----BBAA-----------AABB---- ----AAAA-----------AAAA---- ----BAAA-----------AAAA---- ----AAA-------------AAA---- ----BAA-------------AAB---- -----BA-------------AB----- -----BB-------------BB----- 
--------------------------- --------------------------- --------------------------- --------------------------- --------------------------- --------------------------- --------------------------- --------------------------- ------ABBB-------BBBA------ ------AAAA-------AAAA------ ------BAAA-------AAAB------ ------BAAAA-----AAAAB------ ------BAAAAA---AAAAAB------ ------BAAAAAAAAAAAAAB------ ------BAAAAA---AAAAAB------ ------BA-----------AB------ -----ABA-----------ABA----- -----BBA-----------ABB----- -----AA-------------AA----- -----AA-------------AA----- --------------------------- --------------------------- 
--------------------------- --------------------------- --------------------------- --------------------------- --------------------------- --------------------------- --------------------------- --------------------------- -------BBB-------BBB------- -------AAA-------AAA------- -------AAA-------AAA------- -------ABAA-----AABA------- -------AABAA---AABAA------- --------ABBA---ABBA-------- ---------AAA---AAA--------- --------------------------- --------------------------- --------------------------- --------------------------- --------------------------- --------------------------- --------------------------- 
