model
size = 16 14 32, scale = 0.05, origin = -y
material 
  colors = A:#000 B:#0040FC C:#CCC
voxels
22-4A12-3(5A11-)5A12-3A124-5A10-A4-A10-4(A5-A9-)6A11-4B13-2B92-7A4(8-A6-A)8-A-4A-A8-8A9-6B11-5B12-2A75-8A7-3(A8-A6-)A3-2A3-A6-A-6A-A7-8A8-2B4-2B9-2B2-3B10-A2BA73-10A3(6-A8-A)6-A-5A2-A6-10A6-AB8A2(6-2B)7-2B4-B10-A4BA12-2B58-10A5-3(A10-A4-)A2-6A2-A4-4A3-3A-A5-10A4(6-2B)7-A6BA10-5B55-12A3-A11-2(A4-A10-)A4-A-8A-A4-3A5-4A4-12A5-B8-B6-2B7-B6-A3B2-3BA8-6B54-14A2(2-A12-A)2-A4-3A5-2(A2-)8A2(2-A)-2A6-2A-A2-A2B10A4-2B8-2B5-B8-2B5-A2B5-BA7-8B11-B-B39-14A2(-A13-A)-A4-5A4-A2-A-9A2-A2-3A7-2A-A2-14A3-B10-B4-2B8-2B5-2B6-2B7-BC6B9-CA3BAC10-5A21-17A2(14-2A)4-6A4-2A2-10A2-2A-2A7-3A-A-14A2-2B10-2B3-B10-B4-3B7-2B6-9B8-6B37-17A2(14-2A)3-7A4-2A2-3A3-4A2-2A-2A8-2A-3AB13A-2B10-2B3-B10-2B3-2B8-2B5-10B8-C5BC10-5A21-17A2(14-2A)3-8A3-2A2-3A4-3A2-2A-2A8-2A-3AB13A-2B10-2B3-B10-2B3-2B9-B5-4B2-5B6-8B9-3B-2B21-17A14-4A2-5A2-2(2A-)11A2(2-2A)6-2A2-2A-2A8-2A-3AB13A-2B10-2B3-B10-2B3-2B9-2B4-3B4-4B6-8B9-CAB-BAC10-5A5-17A14-2A-A9-2(2A-)3A5-3A2-2A2-A7-2A2-2A-2A8-2A-17A-2B10-2B3-B10-2B3-2B9-2B4-3B5-3B6-9B8-3B-2B21-17A14-2A-A9-A2-2A-2A7-2(2A2-)A7-2A2-2A-2A8-2A-3AB13A2-2(B10-2B3-)2B9-2B4-2B7-2B6-7BCB8-C4BAC10-5A6-16A14-2(2A-2A8-A2-)2A2-A7-2(2A2-)A8-2A2(-A)B13A2-2(2B9-2B3-)2B9-2B4-2B7-2B6-9B8-7B11-B-B7-15A-A13-2(A-)A7-2A2(2-A-3A8-A)2-2(A-)A8-2A-A-2AB12A2-2B9-2B3-2B9-2B4-B9-B5-2B7-2B6-3B4-2B8-2B3-2B21-15A-A13-2(A-)A2(7-2A2-A-3A)8-A2-2(A-)A8-2A-A-15A2-2B9-B5-B9-B5-2B8-B5-2B7-2(2B6-)B8-B5-2B20-15A-A13-A-A9-A3-2(A-)A7-2A2-A-3A8-A2-A-3A8-2A-A-15A3-2(B9-B5-)2B7-2B6-B7-2(2B6-)B8-B6-B20-15A-A13-A-A9-A3-2(A-)2A6-2A2-A-3A8-A2-A-3A8-2A-A-15A3-B9-B5-2B8-B5-2B7-2B6-B7-2(2B6-)B15-B21-13A2-2(A13-A-)A-2A5-3A2-2(A-)A8-A2-A-3A8-2A-A-2AB3-8A4-B9-B5-2B7-2B6-B7-4(2B6-)B37-13A2(2-A12-A)2-A-3A4-3A-A2-A-2A6-2A-A2-3A8-2A-A-2AB8-3A4-B9-B5-2B7-2B6-B7-2(2B6-)B8-B6-B37-13A2(2-A12-A)2(2-A)5-2A2(2-A)-3A4-3A-A2-A-A8-3A3-AB8-3A4-B9-B5-2B7-2B6-B7-2(2B6-)B7-2B6-B37-13A2(2-A12-A)2-A3-A4-A3-A2-A-3A4-3A-A2-A-A8-3A3-4A6-3A4-B9-B5-2B7-2B5-2B7-2(B7-2B6-)B37-13A3(2-A12-A)2-A2-3A2-4A-A2-A-2A6-2A-A3-13A4-B8-2B5-2B7-B6-2B3(7-B)7-2B5-2B37-13A3(3-A11-A)3-A-2(3A2-)A3-4A4-3A-A3-AB11A4-2B7-B6-2B4(7-B)6-2B7-2B5-2B14-B22-12A4-3(A11-A3-)A2(2-2A)2(3-A)-2(3A2-)A3-2AB10A4-2B7-B6-2B2(7-B)6-2(2B7-2B5-)B9-B4-2B22-12A4-4(A11-A3-)A2-7A2-A3-2A2B8A6-2(B6-2B7-)2B5-2B7-2B5-B9-2B3-2B9-6B11-5B8-11A4(4-A10-A)4-A3-A-2A3-A5-A2B8A6-2(2B5-B8-)2B4-2B9-3B-3B10-5B12-3B14-B10-10A6-5(A9-A5-)2AB7A8-2(7B9-)6B11-5B13-B43-8A8-10(A7-)8A10-4B12-4B13-2B76-6A10-5(7A9-)6A117-
