model
size = 12 20 32, scale = 0.05, origin = -y
material 
  colors = A:#FF9 B:#FFF C:#0B0000 D:#F00 E:#FF3 F:#100 G:#FFC H:#FCF I:#FE0000 J:#FF0 K:#F30 L:#FCC M:#FF6
voxels
4-2(6B6-)2(6D6-)5D186-2(8B4-)DG4-BD4-DG3-BGD4-2D2GEGD7-4D173-9B3-2B6-B3-DG2(6-D4-D)5EGD5-D3F2D172-10B2-B7-2B2-D7-BD2-D7-D3-2D5EGD5-5FD171-11B-2B8-B-DB8-D2-D7-GD2-D7ED4-3F2E2F8-2F161-11B-B9-B-D9-D-DG7-GD2-D2E3-2ED4-2F3E2F7-3F160-14B9-B-D9-D-D8-GD-DG2E3-EGD3-2FE-3EF6-5F159-13B10-BD10-D-D8-GD-DGE5-ED3-F6E2F4-6F7-3B149-13B10-BD10-2DG8-GD-D2E6-D3-F7EF4-2C3E2F5-B3CB148-13B10-BD10-2DG8-GD-D8-D2-C3E2-2EC3-2C5EGC4-2CB2JCB7-3B137-13B9-ABD10-2D9-D-DG8-D2-CA6-EC2-CE6AGC3-CJ3AJ2C5-B3CB136-13B8-BABD10-2D9-D-DG8-D2-CA7-C2-C3A2-2AGC2-CJ5AJC4-2C3J2C7-3B125-13B8-AGBD8-AG2DB8-D-D9-C-DA8-C2-F2A4-A-C2-CG6AC4-CJ3AJ2C5-B3CB124-11B-B2(9-B-D)2(9-D-D)A8-F2-FA5-BAF2-C2A3-2AC4-C5AJC4-6CB123-11B-B4(9-B-D)A8-B2-FAB5-BF2-C2A-B2-AF3-CG6AC4-CJ4AB6-C4BC111-11B-B3(9-B-D)9-B2-B8-B2-B7-2B2-CA5-BAF2-C2A3-2AC4-C6AC4-CBJAJCB7-3C101-11B-BA7-A2(B-D9-)2(B2-B8-)B2-B7-AB2-BA5-BAF2-C2A4-AC4-C6AC4-CJ3AJC6-5C100-11B-2B3(8-B2-B)8-B-CA2(8-B2-B)7-2B2-CA5-BC4-CA3-2AC4-C5AGC4-2CJ2ABC7-3B90-10B2-B7-2B2-B7-A2(B2-B8-B-CA8-)B2-B7-AB2-CA6-F4-CA4-AC4-C6AC4-CJ3A2JC5-B3JBC6-B4CB7-4C8-4C53-10B2-B5-2A2B2-B8AB-CA8-B2-B8-B-CA2(8-B-CM)8-B2-B7-AB3-CA4-AGC3-C6AGC3-CJ5A2(C4-CJ4AJ)C4-2CJ2AJ2C4-2C4J2C6-2(AK)8-2(KG)29-10B2-B7A-B2-B8AB-CM7-AB2-B3(7-AB-CM)7-AB2-B7-AB3-DA5-AB3-DA4-AJC3-D6AGC3-C6AC4-C7AC3-CA3-3AC3-C2A2-2AGC4-C4A2C5-CAG2AC6-5C8-3C6-10B2(2-B8AB)2(2-BA6-AB-C2A6-AB)2(2-BA6-AB)2-DA6-AB3-DA5-AC2-DHA4-A-I2-DG7AI3-C6AJI3-C2A2C2AGC3-C6AGC3-C4A-AC5-C3A-C6-C4AC7-4C5-10B2-B8AB2-D8AK2(2-BA6-AB)-C2A3(6-AB2-BA)6-AB2(2-DA6-AI)2-D-A5-AI2-D2A5-AI2-DHA4-2AI2-D2A3-2CAI3-C2A3C2AC3-C2A3CAC5-2C2G2AC5-6C7-C2-C5-10B2-B8AB2-D8AK2-DA6-AK5(2-BA6-AB)2-3(DA6-2AI-)DA6-AI2-D-A5-AI2-D2A5-CI2-C2A3(C3-CA)C4-C3-3C5-C4-C16-10B2-2B7AB3-D7A2(K2-DA6-A)4(B2-BA6-A)B2-DA6-2AI-D2A3(5-A-I-D-A)5-AHI-DHA5-CHC-C2A5-2C3-2C5-2C4-C34-10B2-B7A2B2-D7AB2(K-DA6-AH)K-DA6-2AK2-B6-AB2-B2A5-2A2(B-)A5-A-B4(-D-A5-A-I)-D-A5-AHI-C2A5-2AC-3C5-3C50-10B2-B7A-B2-D7AB3(D2-DA5-A-)2(K2-BA5-A-)2(B-)2A4-A-B-DH2A3(4-A-I-D2-A)4-A-I-D-2A4-AHI-C2A5-A-C-3C5-3C50-10B2-B7A-B2-D7AB2(D2-DA5-A-)D2-D2A4-A-K2-B2A4-2AK2-B3A2-2A2(-B)A-6A-B-DH-7AD2(-D2-7AI)-DA-2A2-2AHI-CH-AC3-AHI-C2AC4-CAC2-2C5-2C51-10B2-B-5A-2B2-DB5A-BD2-D-6AD3-D-2A-3A2(D3-D-6A)K3-B-5A-K3-B2-4A-B3-BH-3A2(2-D)A2(2-4A-I3-D)H-4A-AD-CA2-A2C3AC2-C2A4C2AC2-3C4-2C51-9B3-2B6-B3-D2B3A-BD3-DH-3A2-D3-DL5A-D3-DL-4A-D3-DL-3A2-K3-DA6-K3-BA6-B3-B2H4-AB2(3-DAH4-AI)3-D2H3-2HD3-C2A-4AC3-C7AC4-7C53-8B2(4-2B)4-D6BD4-DH4-HD4-DL4-L2(D4-DL4-H)K4-D2A2-2AK4-BA4HAB4-2B3HAB2(5-2D3AHD)5-2D2AH2D5-2C3A2C5-7C8-2C56-2(6B6-)6D6-LD2LDL6-L2DLDL5-3(DL)D5-DLD4L2(6-6D)7-B2DB2(8-4D)8-3D9-3C76-
