model
size = 12 20 32, scale = 0.05, origin = -y
material 
  colors = A:#E16B8C B:#FFF C:#64363C D:#DC9FB4 E:#F4A7B9 F:#F8C3CD G:#8E354A H:#F596AA
voxels
4-2(6B6-)2(6D6-)5D186-2(8B4-)2D4-BD4-2D3-B2D4-4DF2D7-4D173-9B3-2B6-B3-2D2(6-D4-D)5F2D5-D3F2D172-10B2-B7-2B2-D7-BD2-D7-D3-2D5F2D5-5FD171-11B-2B8-B-DB8-D2-D7-2D2-D7FD4-7F8-2F161-11B-B9-B-D9-D-2D7-2D2-D2F3-2FD4-7F7-3F160-14B9-B-D9-D-D8-2D-2D2F3-F2D3-3F-4F6-5F159-13B10-BD10-D-D8-2D-2DF5-FD3-9F4-6F159-13B10-BD10-3D8-2D-D2F6-D3-9F4-7F7-3F148-13B10-BD10-3D8-2D-D8-D2-D3F2-2FC3-2D5F2D4-7E7-3E137-13B9-ABD10-2D9-D-2D8-D2-DA6-FD2-DF6A2D3-2E3A2ED5-5E136-13B8-BABD10-2D9-D-2D8-D2-DA7-D2-D3A2-2A2D2-DE5AED4-7E7-3E125-13B8-ADBD8-A3DB8-D-A9-D-2A8-D2-D2A4-A-D2-2D6AD4-2E3A2ED5-5E124-11B-B9-B-D2(9-D-A)9-D-2A8-D2-2A5-B2A2-D2A3-2AD4-D5AED4-7E123-11B-B9-B3(-A9-D)-2A8-A2-2AB5-A3-D2A-B2-ADA2-2D6AC4-2E4AE6-6E111-11B-B9-B3(-A9-A)2-A8-A2-A7-A3-2A5-B2A2-D2A3-2AD4-E6AC4-3EA3E7-3E101-11B-BA7-AB2(-A9-A)2(2-A8-A)2-A7-2A2-2A5-B2A2-D2A4-AD4-D6AC4-DE3AED6-5E100-11B-2B8-B3(2-A8-A)-G2(A8-A2-)A7-A3-2A5-BA4-DA3-2AD4-C5ADC4-C2E2A2E7-3A90-10B2-B7-2B2-A7-2A2-A8-A-GA8-A2-G8-A-GA8-A2-A7-2A2-2A6-A4-2A4-AD4-D6AD4-DE3A2EC5-6E6-6E7-4E8-4E53-10B2-B5-2A2B2-10A-GA8-A2-G8-A-GA2(8-A-2G)8-A2-A7-2A3-2A4-ADC3-D6ADC3-DE5A2(D4-DE4AE)D4-D2E2A2ED4-D6ED6-4A8-4D29-10B2-B7A-B2-10A-2G7-2A2-G3(7-2A-2G)7-2A2-A7-2A3-2A5-AC3-CA4-AEC3-D6ADC3-C6AC4-C7AD3-CA3-3AD3-D2A2-2A2D4-7A5-2AD3A6-2A3D8-3D6-10B2-B8AB2-10A2-2A6-2A-G2A6-2A2-GA6-2A-G3(2A6-2A2-)2A6-AC3-2A5-AC2-2CA4-A-C2-CD7AC3-D6AEC3-D6A2D3-C6ADC3-D4A-AD5-4A-A6-6A7-A3D5-10B2-B8AB2-C9A2(2-2A6-2A)-G4(2A6-2A2-)2A6-AC2-CA6-AC2-C-A5-AC2-C2A5-AC2-2CA4-2AC2-C2A3-3AC3-D2AD4AD3-D2(2A2D3A5-)2A2D2A7-A2-D5-10B2-B8AB2-C9A2-CA6(6-2A2-2A)3(6-2AC-CA)6-AC2-C-A5-AC2-C2A5-AC2-4A3(3-3A)4-A3-3A5-A4-A16-10B2-2B7AB3-C7AC2-CA6-AC2-CA5(6-2A2-2A)6-2AC-C2A3(5-A2(-C)-A)5-A2C-2CA5-ACA-3A5-2A3-2A5-2A4-A34-10B2-B7A2B2-C7ABC2(-CA6-A2C)-CA6-3A2-A6-2A2-3A5-3A2(-A)5-3(A-)4(A5-A2(-C)-)A5-A2C2(-3A5-3A)50-10B2-B7A-B2-C7AB3(C2-CA5-A-)C2(2-2A5-A-A)-A-2A4-2(A-)2C2A3(4-A2(-C)2-A)4-A2(-C)-2A4-A2C-3A5-2(A-)3A5-3A50-10B2-B7A-B2-C7AB2(C2-CA5-A-)C2-C2A4-A-C2-3A4-2AC2-4A2-2A-A-2A-6A-A-2C-2(7AC-C2-)7AC-CA-2A2-2A2C-AC-2A3-A2C-4A4-3A2-2A5-2A51-10B2-B-5A-2B2-CB5A-BC2-C-6AC3-C-2A-3A2(C3-C-6A)C3-A-5A-A3-A2-4A-A3-AC-3A2(2-C)A2-4A-C3-C2-4A-C3-2C-4A-AC-2A2-7A2-10A2-3A4-2A51-9B3-2B6-B3-C2B3A-BC3-2C-3A2-C3-CH5A-C3-CH-4A-C3-CH-3A2-C3-CA6-A3-2A6-A3-A2C2(4-AC3-CAC)4-AC2(3-3C)3-3A-5A3-9A4-7A53-8B2(4-2B)4-C6BC2(4-2C)4-CH4-HC2(4-CH4-2C)4-C2A2-2AC4-CA4C2A4-2A3C2A2(5-2C3A2C)5-2C2A3C2(5-7A)8-2A56-2(6B6-)6C6-HC2HCH6-H2CHCH5-3(CH)C5-CHC4H2(6-6C)7-A2CA2(8-4C)8-3C9-3A76-
