model
size = 20 32 29, scale = 0.05, origin = -y
material 
  colors = A:#C03 B:#09F C:#111 D:#939 E:#39F F:#C06 G:#909 H:#36C I:#66C J:#63C K:#639 L:#39C M:#0CF N:#C09
voxels
7-AGBA16-AB3A14-4A2B14-4ABA2(14-6A)14-2B4A13-A2(B2A)13-3A2B2A13-3AB2AB13-5A2B13-BD3AG15-5A15-A2(B2A17-)AE18-AB316-7A13-3(8A12-)B6AB12-7AB2(11-9A)10-10A10-2B8A10-B9A10-9AF10-A2B6AB10-AB8A11-2AB6A12-AD2AB2A14-3AB2A14-4AB15-B2AD17-2A255-3A3-3A11-3A3-4A10-3A3-3AB9-K3A3-3AK9-AE2A3-4A9-AB2A3-4A8-3(5A3-5A7-)2(B4A3-3A2B7-)2(5A3-5A7-)5A2(3-5A8-4A)2-6A8-AH9A10-B6ABAB11-D4AB2A12-BJ5A14-ABH2A16-B2A17-JA194-3A5-3A9-3A5-3A8-2(4A5-4A7-)E3A5-3AE7-B3A5-3AB7-4A5(5-5A)5-B4A5-4AB4(5-5A)2(5-B4A5-4AB)2(5-5A)6-5A3-6A6-H4A3-4A2H7-B4A2-4A2B7-B12A7-AB7A4B8-2B5A4B10-AB7A12-B2ABD2A13-2A2BA16-LBA152-3A7-2A8-3(3A7-)3A6-4A7-4A5-B3A7-3AB4(5-4A7-4A)5-2(4A7-5A4-)2(B3A7-4AB4-)3(4A7-5A4-)4A8-4A4-4A6-A-4A5-D2A7-4AD5-B3A5-5AB6-12AB7-13A7-2AD7A2D9-10A11-6AB14-4AB16-2AB111-2(2A10-2A6-)4(2A10-3A5-)BA10-2AB5-BA10-3AB3(3-2A11-4A)3-DA11-4AD2(2-2A11-5A)3-A11-4AB3-A11-4AD2(3-2A10-5A)3-B3A8-4AB3-J4A7-3AJ4-5A7-4A5-B2(12AB7-)12A8-2B10A9-E6ABA12-2B3ABA13-B2AG2A15-D2B71-2(2A11-2A5-)3(2A12-2A4-)2A12-3A3-BA12-2AB3(3-2A12-3A)3-2(2A12-4A2-)2A12-5A2(-BA12-4AB)2(-2A12-A-3A)2-2A11-A-3A2-2A11-4A3-2A11-3A4-BA11-2AB4-B3A9-2AB4-J3A9-2AJ4-4A7-A-2A6-L2A7-2AL8-B5A2-4A8-B5A-2AE11-B6AG12-B3AB2A14-A2BAFD49-GA12-AG4-BA12-AB4-2A12-2A4-5(2A12-3A3-)BA12-2AB3-BA12-3AB2-2A12-4A2-2(2A12-5A-)2A12-8A12-6AEA12-5AEBA12-5AB2A12-5A2(2-2A11-A-3A)2-HA11-3AH3-2A11-4A3-2A11-3A4-BA11-2AB4-BA11-AB5-4A8-2A7-7A-5A7-G9ABG8-BI7A2B10-9A12-8C14-4C10-BA12-AB2(4-2A12-2A)4-2A13-2A3-3(2A13-3A2-)2(BA13-2AB2-)3(2A13-4A-)2A2(13-7A)13-5ABA13-4A2BA13-4AB2A13-5ADA13-4AD-2(2A12-4A2-)2A11-5A2-BA11-3AB3-BA11-2AB4-2A11-3A4-2A11-2A5-2B3A4-5AB6-2A-2A2-6A7-5A2-6A7-F4A2-4AF9-10C12-6C9-2(2A13-2A3-)2(BA13-AB3-)3(2A13-3A2-)2(2A13-4A-)2A13-5AB14-4ABGA13-4AG2A4(13-7A)13-5ABA13-4A2BA13-4AB2A13-2(5A-2A12-)3A3-DA12-2AD2-2A13-3A2-2A12-3A3-BA12-2AB4-B3A6-4AB5-5A4-3A-2A5-5A4-5A7-D3A4-3AD9-3C4-3C11-2C4-3C7-2A13-2A3-2A14-2A2-BA14-AB3(2-2A14-2A)2-2(2A14-3A-)2A14-4ABA14-3A2BA14-3AB2A5(14-6A)2(14-4ABA14-3AB2A14-6A)14-2A2-2A14-2A2-BA13-2AB2-BA12-2AB3-2A12-3A3-G4A7-3AG5-B3A7-3AB6-2(3A7-)3C7-2C9-2(2C7-)2A12-2A4-3(2A13-2A3-)BA13-AB3-BA13-2AB-2A14-3A-2A3(14-A-4A)14-A-2AFA14-A-AFBA14-A-AB2A5(14-A-4A)14-A-2ABA14-A-A2BA14-A-AB2A14-A-4A2(14-3A-2A)14-2A2-2A13-2A3-EA13-AE3-B2A10-2AB5-BA10-2AB5-2A10-2A6-2C10-2C7-2C8-2C7-2A12-2A4-3(2A13-2A3-)JA13-2AJ2(2-2A13-3A)2-DA13-A-AD-2A13-2(A-4A14-)A-2ABA14-A-AB2A14-A-4A14-A-2ADA14-A-ADFA14-A-AF2A14-A-4A14-A-2AGA14-A-AGBA14-A-AB2A14-6A14-4ABA14-2AB-2A14-3A-2(2A14-2A2-)BA13-AB3-BA12-2AB3-2A12-2A5-BA10-AB6-2C10-2C6-2C9-3C6-2(2A13-2A3-)4(2A13-3A2-)BA13-2AB2-FA13-2AF2(2-2A13-3A)2-2A13-A2(-2A)13-A-4A14-A-2AMA14-A-AMBA14-A-AB2A5(14-A-4A)14-4ABA14-2AB-BA14-A2B-3(2A14-2A2-)2A13-3A2-2A12-3A3-BA12-AB4-BA12-AB5-C11-2C6-2C9-3C6-2A13-2A3-DA13-AD3-7(2A13-3A2-)JA13-2AJ2(2-2A13-3A)2-2A13-2(A-2ABA14-A-AB2A14-A-4A14-)A-4A14-A-2AHA14-3AHBA14-2AB-2(2A14-2A2-)BA14-AB2-2A14-2A2-2A13-3A2-2A12-3A3-B2(A12-AB5-)2C10-2C6-2C9-3C6-BA13-AB3-KA13-AK3-6(2A13-3A2-)BA13-2AB2(2-2A13-3A)2-2A13-3(A-4A14-)A-2ABA14-A-A2BA14-A-AB2A3(14-A-4A)14-6A14-3A-2A14-3A-2(BA14-AB2-)2A14-2A2-2A13-3A2-2A12-3A3-2A12-2A5-2A11-2A5-2C10-2C6-2C9-3C6-2(2A13-2A3-)2A13-3A2-HA13-2AH5(2-2A13-3A)-2A14-3A-GA14-2AG-DA14-A-AD2A2(14-A-4A)14-A-2AEA14-A-AE2A14-A-4A14-A-2ABA14-A-AB2A14-A-4A14-6A14-4ABA14-2AB-EA14-2AE-2A14-2A2-BA14-AB2-BA13-AB3-2A12-3A4-A12-2A5-2A10-2A6-2C10-2C6-2C9-3C6-2(2A12-2A4-)BA13-AB3-2A13-2A3-2A13-3A2-2A13-2(3A-2A14-)2(A-)2A14-A-4A14-A-2ABA14-A-AB2A5(14-A-4A)14-A-2ABA14-A-A2BA14-A-AB2A14-A-4A2(14-6A)14-3A-2A14-3A-KA14-AK2-BA13-AB3-FA13-AF3-3A2(10-3A5-2A)10-2A6-2C10-2C7-2C8-2C6-2(2A13-2A3-)3(2A14-2A2-)BA14-2AB-2A14-3A-2A14-2(A-)2A3(14-A-4A)14-A-2ABA14-A-AB2A3(14-A-4A)14-A-2AFA14-A-AF2A14-A-4A14-A-2ABA14-3AB2A14-6A14-3A-2A14-2A2-BA14-AB2-2(2A12-3A3-)B4A7-3AB5-B3A7-3AB6-2(3A7-)3C7-2C9-2C7-2C6-2(2A13-2A3-)2(2A14-2A2-)BA14-AB2-3(2A14-3A-)2A2(14-6A)14-4AIA14-3AIBA14-3AB2A5(14-6A)14-4ABA14-3AB-LA12-4AL-2A12-4A2-2A12-3A2-2A12-4A2-2A12-3A3-2A12-3A4-BA11-AB5-B4A4-5AB5-5A4-2AC2A7-4A4-2ACA9-3C4-4C10-2C4-3C7-2(2A13-2A3-)4(2A14-2A2-)2A14-3A-IA14-2AI5(-2A14-3A)-2A14-4ABA14-3AB2A3(14-6A)14-4A-2(2A12-4A2-)IA11-4AI2-BA11-3AB3-2(2A11-3A4-)2A11-2A5-B3A6-4AB6-2A-2A2-6A7-5A2-6A7-B4A2-4AB9-10C12-6C9-5(2A13-2A3-)2A13-3A2-BA13-2AB2-2A13-3A2-5(2A13-4A-)BA13-4A2BA13-4AB2A2(13-7A)13-5A-2(2A12-4A2-)2A11-4A3-BA11-3AB3-2(2A11-3A4-)4A9-2A5-4A8-2A7-3A6-4A7-7A-2ABA8-B6A-3AB9-B7AB13-6C15-4C10-2A12-2A4-BA12-AB2(4-2A12-2A)4-4(2A13-2A3-)EA2(13-2AE2-2A)13-3A2-2(2A13-4A-)2A2(13-7A)13-5ABA13-4AB-2(2A12-4A2-)2A12-3A3-2(2A11-3A4-)4A9-3A4-2B2A9-AB6-B2A7-2AB8-3A5-4A8-ABA4-2AB11-B7A12-AHN3AB14-5AB50-DA11-AD5(5-2A11-2A)5-2A11-3A3-3A11-3A3-BA12-2AB3-2A12-3A3-2A12-4A2-2(2A12-5A-)2A12-5A2-2A11-5A2-BA11-4AB2(2-2A11-5A)2-2A11-4A3-2A11-3A4-4A9-3A5-3A9-2A6-F3A7-2AF7-3A6-2AB8-4A3-5A9-9A12-6AB13-B5A16-2AD72-A10-2A7-A11-2A6-A11-2A5-EA11-AE4(5-2A11-2A)5-2(2A11-3A4-)BA11-2AB4-5(2A11-4A3-)4A9-4A3-4A9-4A4-B2A8-4AB4-3A7-5A6-3A5-5A7-B3A3-6A7-B11A9-10A11-AI5A14-B4A15-AB2A112-A-A2(8-2A7-3A)4(8-3A6-3A)3(8-3A5-4A)8-4A5(4-4A7-5A)5-3A5-A-5A5-4A4-A-5A6-3A-A2-5A2B6-3A-A-8A6-AB7A2B2A8-AB6AL2A10-5ABI2A12-5ABA13-2A2B2A15-2AB17-BA134-4A4-3A9-4A5-4(3A8-3A6-)5(3A7-4A6-)3A7-4A5-4A7-B3A5-2A2B7-4A4-5A8-B2(2A-)5A8-12A8-11A10-10A11-2AB5A12-B6A14-5A16-3A17-AF196-7A13-3(8A12-)7AB11-9A10-M9A4(10-10A)10-9AI10-2AB6AB10-7AB2A11-6A2BA12-7A14-3AB2A14-B4A15-AB2A17-2A258-AD2A16-2AB2A14-6A14-AE4A2(14-6A)14-4ABA13-6AI13-3ABE2A13-7A13-2AB4A13-6A15-5A15-4A16-4A17-ABA17-2A311-
