model
size = 5 32 14, scale = 0.05, origin = -y
material 
  colors = A:#808080 B:#949494 C:#525252 D:#303030 E:#000 F:#646464 G:#121212 H:#767676 I:#242424 J:#D0D0D0 K:#BEBEBE L:#ACACAC M:#888 N:#4B4B4B O:#404040 P:#FFF Q:#E2E2E2
voxels
127-4(E4-)E9-E139-2(G9-)G139-2(I9-)I124-5(D4-)D9-D139-O19-O119-A6(4-C)9-C114-A9-F14-F9-3(F4-)21(A4-)A3-AN3(A-)3AN2A2-P9-H14-H4-H114-A9-2(M14-)M124-A8(4-B)124-2(L14-)L129-2(K14-)K129-2(J14-)J129-Q37-
