model
size = 25 31 27, scale = 0.05, origin = -y
material 
  colors = A:#003B5C B:#6C3 C:#DDD D:#888 E:#BBB
voxels
------------------------- ------------------------- ------------------------- ------------------------- ------------------------- ------------------------- ------------------------- ------------------------- ------------AA----------- -----------AAAA---------- ----------AAAAAAA-------- ---------AAAAAAAAA------- --------AAAAAAAAAAA------ --------AAAAAAAAAAA------ -------AAAAA------------- -------AAA--------------- ------AAA---------------- ------AAA---------------- ------AA----------------- ------AA----------------- ------AA----------------- ------A------------------ ------------------------- ------------------------- ------------------------- ------------------------- ------------------------- ------------------------- ------------------------- ------------------------- ------------------------- 
------------------------- ------------------------- ------------------------- ------------------------- ------------AA----------- -----------AAAA---------- ----------AAAAAAA-------- ---------AAAAAAAAA------- --------AAAAAAAAAAA------ --------AAAAAAAAAAA------ -------AAAAAAAAAAAAA----- -------AAAAA---AAAAA----- ------AAAA------AAAAA---- ------AAA--------AAAA---- -----AAAA---------AAA---- -----AAA----------------- -----AA------------------ -----AA------------------ ----AAA------------------ ----AAA------------------ -----AA------------------ -----AA------------------ -----AA------------------ ------A------------------ ------------------------- ------------------------- ------------------------- ------------------------- ------------------------- ------------------------- ------------------------- 
-----------AAAAA--------- -----------AAAAAA-------- ----------AAAAAAA-------- ---------AAAAAAAA-------- --------AAAAAAAAAA------- --------AAAAAAAAAAA------ -------AAAAAAAAAAAA------ -------AAAA----AAAAA----- ------AAAA-------AAA----- ------AAA---------AAA---- ------AAA---------AAA---- -----AAA-----------AA---- -----AAA-----------A-A--- ----AAA------------A-A--- ---AAAA------------AAA--- ---AAA--------------AAA-- ---AAA---------------AA-- ---AAA----------------AA- ---AAA----------------AA- ---AAA-----------------A- ----AA-----------------A- ----AA-----------------A- ----A-A----------------A- -----A-A--------------AA- ------AA--------------AA- ------AAA-------------AA- -------AAA------------AA- --------AAA---------AAA-- ---------AAAA-----AAA---- ----------AAAAAAAAAA----- -------------AAAAA------- 
---------AA----AAAA------ ---------AA----AAAA------ ---------A------AAA------ --------AA------AAA------ --------A-AAAAAAAAAA----- --------A--------AAA----- ------AAA---------AAA---- -----AAA----------AAA---- ----AAAA-----------AAA--- ---AAAA------------AAA--- -BAAAAA-------------AA--- -BAAAAA-------------AA--- -BAAAA--------------A-A-- -BAAAA--------------A-A-- --A-A----------------AA-- --AAA----------------AA-- --AA-----------------AAA- --AA------------------AA- --AA------------------AA- --AA-------------------A- ---AA------------------A- ---AA------------------A- ----AA-----------------A- -----AA---------------AA- ------AA--------------AA- ------A-A-------------AA- -------A-A-----------AAA- --------A-A---------A-A-- ---------A-AA-----AA-A--- ----------AA-AAAAAAAA---- ------------AAAAAA------- 
------AAA--------AAA----- ------AAA---------AA----- -----AAAA---------AA----- ----AAAA----------AA----- ----AAAA----------A-A---- ----AAAA-----------AA---- ---AAAA------------AA---- ---AAAA-------------AA--- --AAAA--------------AA--- -BAAAA---------------A--- -BAAA----------------AA-- -BAAA----------------AA-- -BAAA----------------AA-- -BAA-----------------AA-- -B-A-----------------AA-- -BAA------------------AA- --AA------------------AA- --AA-------------------A- --AA-------------------A- --AA-------------------A- --AA-------------------AA ---AA------------------AA ---A-A-----------------AA ----A-A----------------AA -----A-A---------------A- ------AA--------------AA- -------AA------------A-A- --------AA----------A-A-- --------AAAA-------A-A--- ----------AAAAAAAAAAA---- ------------AAAAAAA------ 
---AAAA------------AA---- ---AAAA------------AA---- ---AAAA------------AA---- ---AAA-------------AA---- ---AAA-------------A-A--- --AAAA--------------AA--- --AAAA--------------AA--- --AAA---------------AA--- -BAAA----------------AA-- -BAA-----------------AA-- -BAA-----------------AA-- -BA-------------------A-- -BA-------------------A-- -BA-------------------A-- -BA-------------------AA- -BAA------------------AA- -BAA-------------------A- --BA-------------------A- --AA-------------------A- --AA-------------------A- --AA-------------------AA --AA-------------------AA ---AA------------------AA ----AA-----------------AA -----AA----------------AA ------AA--------------AA- ------A-A-------------AA- -------A-A-----------AA-- --------A-AA-------AA-A-- ---------AA-AAA--AA-AA--- -----------AAAAAAAAA----- 
--AAAA--------------A---- --AAAA--------------A---- --AAA---------------A---- --AAA---------------AA--- --AAA---------------AA--- --AAA----------------A--- -BAA-----------------A--- -BAA-----------------AA-- -BAA-----------------AA-- BBA-------------------A-- BBA-------------------A-- BBA-------------------A-- BBA-------------------AA- BBA-------------------AA- -BA-------------------AA- -BAA-------------------A- -BAA-------------------A- -BAA-------------------AA -BAA-------------------AA --BA-------------------AA --AA-------------------AA --AA-------------------AA ---AA------------------AA ----AA-----------------AA -----AA----------------AA ------AA--------------AA- ------A-A-------------AA- -------AAA-----------AA-- --------AAAA-------AA-A-- ---------AAAAA---AAAAA--- -----------AAAAAAAAA----- 
--AA----------------AA--- --AA----------------AA--- --AA----------------AA--- --AA----------------AA--- --AA-----------------A--- -BAA-----------------A--- -BAA-----------------AA-- -BAA-----------------AA-- BBA-------------------A-- BBA-------------------A-- BBA-------------------AA- BBA-------------------AA- BBA-------------------AA- BBA-------------------AA- BBA-------------------AA- BBAA-------------------A- -BAA-------------------AA -BAA-------------------AA -BAA--------------------A -BAA--------------------A --BAA-------------------A --AAA-------------------A --A-A------------------AA ---AAA-----------------AA -----AA----------------AA ------AA--------------AA- -------A--------------AA- ---------------------AA-- --------------------AA--- --------------------A---- ------------------------- 
--AA----------------AA--- --AA-----------------A--- --AA-----------------A--- --AA-----------------A--- -BAA-----------------A--- -BA------------------AA-- BBA------------------AA-- BBA-------------------A-- BBA-------------------A-- BBA-------------------A-- BBA-------------------AA- BBA--------------------A- BBA--------------------A- BBA--------------------A- BBA--------------------A- BBAA-------------------A- BBAA-------------------AA -BAA--------------------A -BAA--------------------A -BAA--------------------A --BAA-------------------A --AAA-------------------A --AAA-------------------A ---AAA------------------A ------------------------- ------------------------- ------------------------- ------------------------- ------------------------- ------------------------- ------------------------- 
-AAA-----------------A--- --AA-----------------A--- --A------------------A--- -BA------------------A--- -BA------------------AA-- BBA------------------AA-- BBA-------------------A-- BBA-------------------A-- BBA-------------------A-- BBA-------------------A-- BBA-------------------AA- BBA--------------------A- BBA--------------------A- BBA--------------------A- BBA--------------------A- BBAA-------------------A- BBAA-------------------AA BBAA--------------------A -BAA--------------------A -BAA--------------------A --BAA-------------------A --BAA-------------------A --AA--------------------A ------------------------A ------------------------- ------------------------- ------------------------- ------------------------- ------------------------- ------------------------- ------------------------- 
-AA------------------A--- --A------------------A--- -BA------------------A--- -BA------------------A--- BBA------------------AA-- BBA-------------------A-- BBA-------------------A-- -DA-------------------A-- CBA-------------------A-- CBA-------------------AA- CBA-------------------AA- CBA--------------------A- -DA--------------------A- CBA--------------------A- CBA--------------------A- CBAA-------------------AA BBAA-------------------AA BBAA--------------------A BBAA--------------------A -BAA--------------------A -BBAA-------------------A --BAA-------------------A --B---------------------A ------------------------A ------------------------- ------------------------- ------------------------- ------------------------- ------------------------- ------------------------- ------------------------- 
-AA------------------A--- --A------------------A--- -BA------------------A--- BBA------------------A--- BBA------------------AA-- BBA-------------------A-- -DA-------------------A-- CBA-------------------A-- CBA-------------------A-- CBA-------------------AA- CBA-------------------AA- CBA--------------------A- CBA--------------------A- CBA--------------------A- CBA--------------------A- CBAA-------------------A- CBAA-------------------AA BBAA--------------------A BBAA--------------------A BBAA--------------------A -BBAA-------------------A -BBAA-------------------A --B---------------------A ------------------------A ------------------------- ------------------------- ------------------------- ------------------------- ------------------------- ------------------------- ------------------------- 
-AA------------------A--- -BA------------------A--- -BA------------------A--- BBA------------------A--- BBA------------------AA-- BBA-------------------A-- -DA-------------------A-- CBA-------------------A-- -BA-------------------A-- -BA-------------------A-- -BA-------------------AA- -DA--------------------A- CBA--------------------A- -BA--------------------A- -DA--------------------A- CBAA-------------------A- CBAA-------------------AA BBAA--------------------A BBAA--------------------A BBAA--------------------A -BBAA-------------------A -BBAA-------------------A --B---------------------A ------------------------A ------------------------- ------------------------- ------------------------- ------------------------- ------------------------- ------------------------- ------------------------- 
-AA------------------A--- -BA------------------A--- -BA------------------A--- BBA------------------A--- BBA------------------AA-- BBA-------------------A-- -DA-------------------A-- CBA-------------------A-- -BA-------------------A-- -BA-------------------A-- -BA-------------------AA- -DA--------------------A- CBA--------------------A- -BA--------------------A- -DA--------------------A- CBAA-------------------A- CBAA-------------------AA BBAA--------------------A BBAA--------------------A BBAA--------------------A -BBAA-------------------A -BBAA-------------------A --B---------------------A ------------------------A ------------------------- ------------------------- ------------------------- ------------------------- ------------------------- ------------------------- ------------------------- 
-AA------------------A--- -BA------------------A--- -BA------------------A--- BBA------------------A--- BBA------------------AA-- BBA-------------------A-- -DA-------------------A-- CBA-------------------A-- CBA-------------------A-- CBA-------------------A-- CBA-------------------AA- CBA--------------------A- CBA--------------------A- CBA--------------------A- CBA--------------------A- CBAA-------------------A- CBAA-------------------AA BBAA--------------------A BBAA--------------------A BBAA--------------------A -BBAA-------------------A -BBAA-------------------A --B---------------------A ------------------------A ------------------------- ------------------------- ------------------------- ------------------------- ------------------------- ------------------------- ------------------------- 
-AA------------------A--- -BA------------------A--- -BA------------------A--- BBA------------------A--- BBA------------------AA-- BBA-------------------A-- -DA-------------------A-- CBA-------------------A-- CBA-------------------A-- CBA-------------------AA- CBA-------------------AA- CBA--------------------A- CBA--------------------A- CBA--------------------A- CBA--------------------A- CBAA-------------------A- CBAA-------------------AA BBAA--------------------A BBAA--------------------A BBAA--------------------A -BBAA-------------------A -BBAA-------------------A --B---------------------A ------------------------A ------------------------- ------------------------- ------------------------- ------------------------- ------------------------- ------------------------- ------------------------- 
-AA------------------A--- --A------------------A--- -BA------------------A--- -BA------------------A--- BBA------------------AA-- BBA-------------------A-- -DA-------------------A-- EBA-------------------A-- EBA-------------------A-- EBA-------------------AA- EBA-------------------AA- EBA--------------------A- EBA--------------------A- EBA--------------------A- EBA--------------------A- EBAA-------------------AA BBAA-------------------AA BBAA--------------------A BBAA--------------------A -BAA--------------------A -BBAA-------------------A -BBAA-------------------A --B---------------------A ------------------------A ------------------------- ------------------------- ------------------------- ------------------------- ------------------------- ------------------------- ------------------------- 
-AAA-----------------A--- --AA-----------------A--- -BA------------------A--- -BA------------------A--- -BA------------------AA-- BBA-------------------A-- BBA-------------------A-- BBA-------------------A-- BBA-------------------A-- BBA-------------------A-- BBA-------------------AA- BBA--------------------A- BBA--------------------A- BBA--------------------A- BBA--------------------A- BBAA-------------------A- BBAA-------------------AA BBAA--------------------A -BAA--------------------A -BAA--------------------A -BBAA-------------------A --BAA-------------------A --B---------------------A ------------------------A ------------------------- ------------------------- ------------------------- ------------------------- ------------------------- ------------------------- ------------------------- 
--AA-----------------A--- --AA-----------------A--- --AA-----------------A--- -BAA-----------------A--- -BAA-----------------AA-- -BAA-----------------AA-- BBAA-----------------AA-- BBA-------------------A-- BBA-------------------A-- BBA-------------------A-- BBA-------------------AA- BBA--------------------A- BBA--------------------A- BBA--------------------A- BBA--------------------A- BBAA-------------------A- BBAA-------------------AA -BAA--------------------A -BAA--------------------A -BAA--------------------A --BAA-------------------A --BAA-------------------A --AAA-------------------A ---AAA------------------A ------------------------- ------------------------- ------------------------- ------------------------- ------------------------- ------------------------- ------------------------- 
--AA----------------AA--- --AA----------------AA--- --AA----------------AA--- --AA----------------AA--- -BAA-----------------A--- -BAA-----------------AA-- -BAA-----------------AA-- -BA------------------AA-- BBA-------------------A-- BBA-------------------A-- BBA-------------------AA- BBA-------------------AA- BBA-------------------AA- BBA-------------------AA- BBA--------------------A- BBAA-------------------A- -BAA-------------------AA -BAA-------------------AA -BAA--------------------A -BAA--------------------A --BAA-------------------A --AAA-------------------A --A-A------------------AA ---AAA-----------------AA -----AA----------------AA ------AA--------------AA- -------A--------------AA- ---------------------AA-- --------------------AA--- ------------------------- ------------------------- 
--AAAA--------------A---- --AAAA--------------AA--- --AAAA--------------AA--- --AAA---------------AA--- --AAA---------------AA--- -BAA-----------------A--- -BAA-----------------A--- -BAA-----------------AA-- -BAA------------------A-- BBA-------------------A-- BBA-------------------A-- BBA-------------------AA- BBA-------------------AA- BBA-------------------AA- -BA-------------------AA- -BAA-------------------A- -BAA-------------------A- -BAA-------------------AA -BAA-------------------AA -BAA-------------------AA --BAA-------------------A --AAA------------------AA ---AA------------------AA ----AA-----------------AA -----AA----------------AA ------AA--------------AA- ------AAA-------------AA- -------AAA-----------AA-- --------AAAA-------AA-A-- ---------AAAAA---AAAAA--- -----------AAAAAAAAA----- 
---AAAA------------AA---- ---AAAA------------AA---- ---AAAA------------AA---- ---AAAA------------AA---- ---AAAA-------------AA--- --AAAAA-------------AA--- -BAAAAA-------------AA--- -BAAA----------------AA-- -BA-A----------------AA-- -BAA-----------------AA-- -BAA-----------------AA-- -BA-------------------A-- -BA-------------------A-- -BA-------------------A-- -BA-------------------AA- -BAA------------------AA- -BAA-------------------A- -BAA-------------------A- -BAA-------------------A- --BA-------------------AA --AAA------------------AA --AAA------------------AA ---AA------------------AA ----AA-----------------AA -----AA----------------AA ------AA--------------AA- ------A-A-------------AA- -------A-A-----------AA-- --------A-AA--------A-A-- ---------AA-AAA--AAAAA--- -----------AAAAAAAAA----- 
------AA----------AA----- ------AA----------AA----- -----AAA----------AA----- ----AAAA----------AAA---- ----AAA------------AA---- ----AAA------------AA---- ---AAAA------------A-A--- ---AAA--------------AA--- -BAAAA--------------AA--- -BAAAA---------------A--- -BAAA----------------AA-- -BAAA----------------AA-- -BAA-----------------AA-- -BAA-----------------AA-- -BA-------------------A-- -BAA------------------AA- -BAA------------------AA- --BA-------------------A- --AA-------------------A- --AA-------------------A- --AA-------------------AA ---AA------------------AA ---A-A-----------------AA ----A-A----------------AA -----A-A---------------A- ------AA--------------AA- -------AA------------A-A- --------AA----------A-A-- --------AAAA-------A-A--- ----------AAAAAAAAAAA---- ------------AAAAAAA------ 
-------AAA-----AAAA------ -------AAA------AAA------ -------AAA------AAA------ -------AA-------AAA------ -------AA--------AAA----- ------AAA---------AA----- ------AA----------AAA---- ----AAAA----------AAA---- ----AAAA-----------A-A--- -BAAAAA-------------AA--- -BAAAAA-------------AA--- -BAAAA--------------AA--- -BAAAA---------------AA-- -BAAA----------------AA-- -BAAA----------------AA-- -BAA-----------------AA-- --AA------------------AA- --AA------------------AA- --AA------------------AA- --AA-------------------A- ---AA------------------A- ---AA------------------AA ----AA-----------------A- -----AA---------------AA- ------AA--------------AA- ------A-A-------------AA- -------A-A-----------A-A- --------A-A---------A-A-- ---------A-AA-----AA-A--- ----------AA-AAAAAAAA---- ------------AAAAAA------- 
---------AAAAAAAA-------- ---------AAAAAAAA-------- ---------AAAAAAAA-------- --------AAAAAAAAAA------- -------AAAAAAAAAAAA------ -------AAAAAAAAAAAA------ -------AAAAA---AAAA------ -------AAA------AAAA----- ------AAAA-------AAAA---- ------AAA---------AAA---- -BAA--AA----------AAA---- -BAAAAAA-----------AAA--- -BAAAAA------------AAA--- -BAAAAA------------AAA--- ---AAAA-------------AA--- ---AAA--------------AAA-- ---AAA---------------AAA- ---AAA-----------------A- ---AA------------------A- ---AA------------------A- ---A-A-----------------A- ----AA-----------------A- ----A-A----------------A- -----A-A--------------AA- ------AA--------------AA- ------AAA-------------A-- -------AAA-----------AA-- --------AAA---------AA--- ---------AAAA-----AAA---- ----------AAAAAAAAAA----- -------------AAAAA------- 
------------------------- ------------------------- ------------------------- ------------AA----------- -----------AAAA---------- -----------AAAAA--------- ---------AAAAAAAA-------- --------AAAAAAAAAA------- --------AAAAAAAAAAA------ -------AAAAAAAAAAAA------ -------AAAAA-AAAAAAA----- -------AAAA-----AAAA----- ------AAAA-------AAAA---- ------AAA---------AAA---- -----AAA----------AAA---- ----AAAA----------------- ----AAA------------------ ----AAA------------------ ----AAA------------------ ----AAA------------------ ----A-A------------------ -----AA------------------ -----AA------------------ ------AA----------------- ------------------------- ------------------------- ------------------------- ------------------------- ------------------------- ------------------------- ------------------------- 
------------------------- ------------------------- ------------------------- ------------------------- ------------------------- ------------------------- ------------------------- ------------------------- ------------AA----------- ----------AAAAAA--------- ---------AAAAAAAA-------- --------AAAAAAAAAA------- --------AAAAAAAAAAA------ -------AAAAAAAAAAAA------ -------AAAAA------------- ------AAAA--------------- ------AAA---------------- ------AAA---------------- ------AA----------------- -----AAA----------------- -----AAA----------------- ------A------------------ ------------------------- ------------------------- ------------------------- ------------------------- ------------------------- ------------------------- ------------------------- ------------------------- ------------------------- 
