model
size = 31 28 22, scale = 0.05, origin = -y
material 
  colors = A:#F7A8B8 B:#55CDFC C:#EEE D:#111 E:#FC3
voxels
------------------------------- -------------BB--BB------------ -------------AA--AA------------ -------------AA--AA------------ -------------AA--AA------------ -------------AA--AA------------ -------------CC--BB------------ -------------CC--BB------------ -------------C----B------------ -------------C----------------- -------------A----------------- -------------A----------------- ------------------------------- ------------------------------- ------------------------------- ------------------------------- ------------------------------- ------------------------------- ------------------------------- ------------------------------- ------------------------------- ------------------------------- ------------------------------- ------------------------------- ------------------------------- ------------------------------- ------------------------------- ------------------------------- 
-------BBBBB-BBBBBB-----C------ -------BBBBB-B-BB-B---CCC------ -------AAAAA-A-AA-A---AAA------ -------AAAAA-A-AA-A---AAA------ --------AAAA-A-AA-A---AAA------ --------A-AA-A-AA-A----A------- --------C-C--C-CC-B----B------- --------C-C--C-CC-B----B------- --------C-C--CCCCBB----B------- ----------C--CCCCBB------------ ----------A--AA-AAA------------ -------------AA--AA------------ -------------AA--AA------------ -------------AA--AA------------ -------------BB--BB------------ -------------BB--BB------------ -------------BB--BB------------ -------------BB---------------- -------------AA---------------- -------------AA---------------- ------------------------------- ------------------------------- ------------------------------- ------------------------------- ------------------------------- ------------------------------- ------------------------------- ------------------------------- 
-------BBCCCBBCCCC-CCCCCC------ -------B----BBCCCC-CCC--C------ -------A----A-AAA-AAAA--A------ --------A---A-AAA-A-AA--A------ --------A---A-AAA-A-AA--A------ --------AA--A--AA-A-AAAA------- --------CC-CC--C--B-BBBB------- --------CC-CC--C--B-BBBB------- --------CC-CC--C--B-BBBB------- --------CC-CC--C--B-BBBB------- --------AA-AA--A---AAAAA------- --------AAAAA--AA--AAAAA------- --------AAAAA--AA--AAAAA------- --------AAAAA--AA--AAA-A------- --------BBBBB--BB--BBB-B------- ----------BBB--BB--BBB--------- ----------BBB--BB--BBB--------- -----------BB--BBBBBBB--------- -----------AA--AAAAAA---------- -----------AA--AAAAAA---------- ------------AAAAAAA------------ ------------AAAAAAA------------ ------------------------------- ------------------------------- ------------------------------- ------------------------------- ------------DDEDEDD------------ ------------DDEDEDD------------ 
---BBBBBB-CC-----CCCCCCCCCCCC-- ---BBBBBBCCC-----CC------CCCC-- ---AA--AA-AA-A---AA------AAAA-- ---AA--AA-AA-A---AAA-----AAAA-- ---AA--AA---AA---AAA-----AAAA-- --------A---AAA--AAA----AAAA--- --------C----CC-CCCB----BBBB--- --------C----CC-CCCB----BBBB--- -------C-----CC-CCCB----BBBB--- -------C-----CC-CCCB----BBB---- -------A-----AA-AAA-----AAA---- -------A--A--AA-AAA-----AAA---- -------A-A-A-AAAAAA-----AA----- -------A-A-A-AAAAAA--AA-AA----- --------BB-B-BBBBBB-B-B-B------ --------BB-B-BBBBBBBB-BBB------ --------BB-B-BBBBB-BB-BB------- --------BB-B-BBBBB--B-BB------- ---------A-A-AA-AA--A-A-------- ---------A-A-AA-AAA-A-A-------- ---------AAAAAAAAAAAA-A-------- -----------AAAAAAAAAA---------- -----------BBBBCCCCCC---------- -----------BBBBCCCCC----------- -----------BBBBCCCCC----------- -----------BBBBCCCCC----------- -----------DDDDDDDDD----------- -----------DDDDDDDDD----------- 
---BBBBBB----------CC--CCCCCCC- --BB--BBBC-C-------C-CCCCCCCCC- --AA-AAAAA-A-------A---CCC---A- --AA-AAAAA-A-------A---CCC---A- --AA-AAAA-AA-------A---CCC--A-- ---AAAAAA--A-------A--CCCC--A-- ---BBBBCCC--C------C--BBB---B-- ---BBBBCCC--C------C--BB-B-B--- ---BBBBBCC--C------C--BBB--B--- ----BBBBCC--C------CC-BBB--B--- ----AAAAAA--A------AA-AAA--A--- ----AAA-AA--A------AA-AAA--A--- -----AA-AAA-A------AA--A--A---- -----AA-A-AAA------AA-----A---- -----BBB--BBB------BBB---BB---- -----BBB--BBB-------BB---BB---- ------BB-BBBB-----B-BB--BB----- ------BBBBBBB-----BB-B--BB----- ------CCA-AAC-----CCCAAAAA----- -------CA-AAC------CCAAAA------ -------CA-AA-------CCA-AA------ -------CAAAA-------CCAAAA------ --------BBBBB------CCCCC------- ---------BBBB------CCCC-------- ----------BBB------CCC--------- ----------BBB------CCC--------- ----------DDD------DDD--------- ----------DDD-------DD--------- 
----BB---------------------CCC- ----BB---CCC--------CC-----CCC- ----AC---CCC--------CCC---C--A- ----AC---CCC--------CCC---C-A-- ----AC---CCC--------CCC---C-A-- ----AC---CCC--------CC----C-A-- ----BB----CC--------CB---BB-B-- ----BB----CC--------CB---B-B--- ----B-B---CC--------CB---B-B--- ----B-B---CC---------B---BB---- -----AC---CC---------C---AA---- -----ACC--CC---------C---AA---- -----ACC--CC---------CC-AAA---- -----ACC-CC----------CCCA-A---- -----B-BBBB----------CCCCC----- ------BBBBB----------CCCCC----- ------BBB-B---------CCCCCC----- ------BB------------CCCCCC----- ------C-CC-------------A-A----- -------CCC-------------AA------ -------CCC------------AAA------ -------CCC------------A-A------ --------BB-----------CCC------- --------BBB----------C-C------- --------BBB----------CC-------- ---------BB----------CC-------- ---------DD----------DD-------- ---------DD----------DD-------- 
---BB----------------------CC-- ---BB----------------------CC-- ---AC----------------------CA-- ---AC----------------------CA-- ---AC----------------------CA-- ---AA----------------------CA-- ---BB----------------------B--- ---BB---------------------BB--- ----BB--------------------BB--- ----BB--------------------BB--- ----AA--------------------AA--- ----AA--------------------AA--- ----AA--------------------A---- -----A-------------------AA---- -----BB------------------CC---- -----BB------------------CC---- -----BB------------------CC---- -----B-B-----------------C----- ------CC----------------AA----- ------CC----------------AA----- ------CC----------------AA----- ------CC---------------AA------ -------BB--------------BB------ -------BB-------------B-B------ --------BB------------BB------- --------BB------------BB------- --------DD------------DD------- --------DD------------DD------- 
--BB------------------------CC- --BB------------------------AC- --AA------------------------AA- --AA------------------------AA- --AA------------------------A-- --AA-----------------------CA-- ---B-----------------------BB-- ---BC----------------------BB-- ---BC----------------------BB-- ---BC----------------------B--- ---AA----------------------A--- ----A---------------------AA--- ----AC--------------------AA--- ----AC--------------------A---- ----BB--------------------C---- -----B--------------------C---- -----B-------------------CC---- -----BB------------------CC---- -----CC------------------AA---- ------C------------------A----- ------CC----------------AA----- ------CC----------------AA----- ------BB----------------B------ -------BB--------------BB------ -------BB--------------BB------ --------B--------------B------- --------D--------------D------- --------D--------------D------- 
-BB--------------------------CC -BB--------------------------CC -AA--------------------------AA -AA-------------------------AAA -A-A------------------------AAA --AA------------------------AAA --BB------------------------BB- --BB------------------------BB- --BB-----------------------B-B- ---BC----------------------BB-- ---AA----------------------AA-- ---AA----------------------AA-- ---AA---------------------AA--- ----A---------------------AA--- ----BB--------------------CC--- ----BB--------------------CC--- ----BB--------------------C---- -----B-------------------CC---- -----CC------------------AA---- -----CC------------------A----- -----CC------------------A----- ------C-----------------AA----- ------BB----------------BB----- -------B----------------B------ -------BB--------------BB------ -------BB--------------B------- --------D--------------D------- --------D--------------D------- 
BB----------------------------B BB----------------------------B AA----------------------------A AAA---------------------------A A-A---------------------------A AAA--------------------------A- -BB--------------------------BB -BB-------------------------B-B -B-B------------------------B-B -BBB------------------------BBB --AA------------------------AA- --AA-----------------------A-A- --A-A----------------------AAA- --AAA----------------------AA-- ---BB----------------------CC-- ---BB---------------------C-C-- ----BB--------------------CC--- ----BB--------------------CC--- ----CC-------------------A-A--- -----C-------------------AA---- -----CC------------------AA---- ------C-----------------AA----- ------BB----------------BB----- -------B----------------B------ -------BB--------------BB------ -------BB--------------B------- --------D--------------D------- --------D--------------D------- 
B----------------------------BB B----------------------------BB A----------------------------AA A----------------------------AA AAA-------------------------CAA A--A------------------------CAA B--B------------------------BBB B--B------------------------BBB -B-B------------------------BBB -B-B-----------------------B-BB -A--A----------------------AAA- --A-A----------------------AAA- --A-A----------------------AAA- --A-A---------------------A-A-- ---B-B--------------------CCC-- ---B-B--------------------CCC-- ---B-B--------------------CC--- ----BB-------------------C-C--- ----C-C------------------AA---- -----CC------------------AA---- -----CC------------------AA---- ------C-----------------AA----- ------BB----------------BB----- -------B---------------BB------ -------BB--------------BB------ --------B--------------B------- --------D-------------DD------- --------DD------------DD------- 
B----------------------------B- B----------------------------B- A----------------------------A- A----------------------------A- AAA-------------------------CA- A-A-------------------------A-- B---------------------------B-- -B-B------------------------B-- -B-B-----------------------BB-- --BB-----------------------BB-- --C-C----------------------A--- --C-C----------------------A--- ---CC---------------------AA--- ---CC---------------------AA--- ---B-B--------------------C---- ----BB--------------------C---- ----BB--------------------C---- ----BB-------------------CC---- -----CC------------------AA---- -----CC------------------A----- ------C------------------A----- ------CC----------------AA----- ------BB---------------BB------ -------BB--------------BB------ -------BB-------------BB------- --------BB------------BB------- --------DD------------DD------- --------DD------------D-------- 
B---------------------------B-- B---------------------------B-- A---------------------------A-- A---------------------------A-- AA--------------------------A-- AA--------------------------A-- B-BB------------------------B-- -B-B------------------------B-- -B-B-----------------------BB-- -B--B----------------------BB-- --CCC----------------------AA-- --CCC----------------------A--- --CC-C---------------------A--- ---C-C--------------------AA--- ---BBB--------------------CC--- ----BB--------------------CC--- ----B-B-------------------CC--- ----BBB------------------CC---- -----CC------------------AA---- -----C-C-----------------AA---- -----CCC----------------AA----- ------CC--------------AA-A----- -------BB-------------BBB------ -------B-B------------B-B------ --------BBB----------B-B------- --------BBB----------BB-------- ---------DD---------DDD-------- ---------DD---------DDD-------- 
B----------------------------B- B----------------------------B- A----------------------------A- AA---------------------------A- AA-A------------------------CA- AAAA------------------------CA- -BBB------------------------BB- -BB-B-----------------------BB- -BB-B-----------------------BB- --BBB-----------------------BB- --C-C----------------------AA-- ----C---------------------A-A-- ----CC--------------------A-A-- ----CC-------------------A--A-- -----B-------------------C-C--- -----BB------------------CCC--- -----BB------------------CCC--- ------B-----------------C-C---- ------CC----------------AAA---- ------CC----------------AA----- -------CA-------------AA-A----- -------CAA----------AAA-A------ -------B-BB----------BBB------- --------B-BB-------BBB-B------- ---------BBBBB----BBBBB-------- ----------BBBBB--BBBBB--------- ----------DDDDD--DDDDD--------- ----------DDDD----DDDD--------- 
-BC--------------------------B- -BC--------------------------B- -AA--------------------------C- -AA--------------------------C- --AA-------------------------C- --AA----------------------CCCC- ---B----------------------BB-B- ---B---------------------BBB-B- ---BB--------------------BBBBB- ---BB---------------------BBBB- ----CC--------------------AAA-- ----CC-------------------A-AA-- ----C-C------------------AAAA-- ----C-C------------------AAA--- -----BB------------------CC---- -----BB-----------------CC----- -----B-B----------------CC----- ------BB---------------C-C----- ------A-A--------------AA------ ------A-A-------------AAA------ -------A-A-----------CA-A------ -------A--AAAAAA-AAACC-A------- --------BB-BBBBBBBBBB-BB------- ---------BBBBBBBBBBBBBB-------- -----------BBBBBBBBBB---------- -------------BBBBBB------------ -------------DDDDDD------------ -------------DDDDDD------------ 
--B----------------------BBBBB- --B----------------------BBBBB- --A----------------------CCCCC- --AACC------------------ACCCCC- --A-CC------------------ACCCCC- --A-CC------------------AC-CCC- ---BBC------------------BB-BBB- ---BBC------------------B-B-B-- ---B-BC-----------------B-B---- ---BBCC-----------------BBB---- ----C-C------------------AA---- ----CCC-----------------A-A---- ----CCC-----------------AA----- -----C-C----------------AA----- -----BBB----------------CC----- -----BBB---------------C-C----- ------B-B--------------C-C----- ------B-B-------------C-C------ -------A-A------------A-A------ -------A-AAA-------AAA-A------- --------A-AAAAAAAAAAAAAA------- --------AAA-----A----AA-------- ----------BBBBBBBBBBBB--------- -----------------B------------- ------------------------------- ------------------------------- ------------------------------- ------------------------------- 
---B---------------------BBB--- ---B---------------------BBB--- ---A---------------------CCC--- ---AA-------------------ACCC--- ---A-A------------------A-C---- ---A--A-----------------A-C---- ---B--C-----------------BBB---- ---B--CC----------------BBB---- ----B--C----------------BBB---- -----B-C----------------BBB---- -----C-C----------------AA----- ------CC----------------AA----- ------CCC--------------C-A----- ------C-C--------------C-A----- -------BB--------------CC------ -------BB-------------C-C------ -------B-B-----CC----CC-C------ -------B-BBB--CCCC---C-C------- --------AAAAAAAAAAAAAAAA------- --------AAA-AAAAAAA--AA-------- ---------AA-AAAAAAAAAA--------- -----------AAAAAAAAAA---------- ------------------------------- ------------------------------- ------------------------------- ------------------------------- ------------------------------- ------------------------------- 
---B------------------BB-B----- ---B------------------BB-B----- ---A------------------CC-C----- ---AAAAA--------------CCAC----- ---A--AA--------------CC-C----- ----A--A--------------CC-C----- ----B--C---------C----BBB------ ----B--C---------C----BBB------ -----B-C---------C----BBB------ -----B-C---------C----BBB------ ------C-AA------AA----AAA------ ------C-AA----A-AA----AAA------ ------C--A----A-AA----A-A------ -------CAAA---AAAA----AAA------ -------BBBB--BCCCC---CCC------- -------BBBBBBBCCCC-CCC-C------- --------BBBBBBC--CCCCCCC------- --------BB--BB-CCCCCCCC-------- ----------AAAAAAAAAA-A--------- -----------AAAAAAAAAA---------- -----------A------------------- ------------------------------- ------------------------------- ------------------------------- ------------------------------- ------------------------------- ------------------------------- ------------------------------- 
----BBBBBBBBB-----BB-BBBBB----- ----BBBBBBBBB-----BB-BBBBB----- ----AAAAAAAAAC----CC-CCCCC----- ----AAAAAAAAAC----CC-CCCCC----- ----AAAAAAAAAC---CCCCCCCC------ ----A---AAAAAC---CCCCCCCC------ ----B---BCCCBCC--CCCCBBBB------ ----B---BCCCBCC--CCBBBBBB------ -----B-BBCCCBCC--CCCCBBBB------ -----BBBBCCCBCC--CCCCBBBB------ ------CCA-AAAAA--AAAAAAA------- ------CCA-AAAA-AA-AAAAAA------- ------CCAAAAAA-AA-AAAAAA------- -------C-A-AAA-AA-AAAAA-------- ----------BBB-CCCCCCCCC-------- ----------BBBBCCCCC--CC-------- ----------BBBBCCCCCCC---------- ----------BB-BC---CCC---------- --------------------A---------- ------------------------------- ------------------------------- ------------------------------- ------------------------------- ------------------------------- ------------------------------- ------------------------------- ------------------------------- ------------------------------- 
------B--BBBBB----BBB---------- ------B--BBBBB----BBB---------- ------A--AAAAA----CCC---------- ---------AAA-A-AC-C-C---------- ---------A-A-A-AC-C-C---------- ----AAAA-A-A-AAACC--C---------- ----BBBB-B-B-B-BB---B---------- -----BBB-B-B-B-BB--B----------- -----BB--B-B-B-BBBB-B---------- ---------B-B-B-BBBB-B---------- ---------A-A-AAAAAA-A---------- ---------AAA-AAAAAA-A---------- ----------A--AA--AA-A---------- ----------A--AA--AAAA---------- ----------B--B----CCC---------- ----------B--------CC---------- ------------------------------- ------------------------------- ------------------------------- ------------------------------- ------------------------------- ------------------------------- ------------------------------- ------------------------------- ------------------------------- ------------------------------- ------------------------------- ------------------------------- 
---------BB--BBBBBB------------ ---------BB--BBBBBB------------ ---------AA--AAACCC------------ ---------AA--AAACCCCC---------- ---------AA--AAACCCC-C--------- ---------AA--AAACCCC-C--------- ---------BB--BBB-BBB-B--------- ---------BB--BB--BBBBB--------- ---------BB--BB----B-B--------- ----------B--BB----B----------- ----------A--A-----A----------- -------------------A----------- -------------------A----------- ------------------------------- ------------------------------- ------------------------------- ------------------------------- ------------------------------- ------------------------------- ------------------------------- ------------------------------- ------------------------------- ------------------------------- ------------------------------- ------------------------------- ------------------------------- ------------------------------- ------------------------------- 
---------BB--BB---------------- ---------BB--BB---------------- ---------AA--AA---------------- ---------AA--AA---------------- ------------------------------- ------------------------------- ------------------------------- ------------------------------- ------------------------------- ------------------------------- ------------------------------- ------------------------------- ------------------------------- ------------------------------- ------------------------------- ------------------------------- ------------------------------- ------------------------------- ------------------------------- ------------------------------- ------------------------------- ------------------------------- ------------------------------- ------------------------------- ------------------------------- ------------------------------- ------------------------------- ------------------------------- 
