model
size = 31 15 23, scale = 0.05, origin = -y
material 
  colors = A:#777 B:#111 C:#FF0
voxels
------------------AAAAAAAA----- ------------------AAAAAAAA----- ------------------AAAAAAAA----- ------------------AAAAAAA------ -------------------AAAAAA------ --------------------AAAA------- ------------------------------- ------------------------------- ------------------------------- ------------------------------- ------------------------------- ------------------------------- ------------------------------- ------------------------------- ------------------------------- 
----AAAAAAAAAAAAAAAA---AAAAA--- ----AAAAAAAAAAAAAAAA---AAAAA--- ----------AAAAAAAAAAAAAAAAAA--- ---------------AAAAAAAAAAAA---- ----------------AAAAAAAAAAA---- ----------------AAAAAAAAAAA---- -----------------AAAAAAAAA----- ------------------AAAAAAAA----- --------------------AAAA------- ------------------------------- ------------------------------- ------------------------------- ------------------------------- ------------------------------- ------------------------------- 
---A----------------------AAA-- ---AAAAAAAAAAAA-----------AAA-- ---AAAAAAAAAAAAAA--------AAAA-- -----------AAAAAAA-------AAAA-- -------------AAAAAA-----AAAAA-- --------------AAAAAAA-AAAAAA--- --------------AAAAAAAAAAAAAA--- ---------------AAAAAAAAAAAA---- ----------------AAAAAAAAAAA---- ------------------AAAAAAA------ ------------------------------- ------------------------------- ------------------------------- ------------------------------- ------------------------------- 
--A------------------------AAA- --AAAAAA-------------------AAA- --AAAAAAAAAAAA-------------AAA- -----AAAAAAAAAA------------AAA- -----------AAAA-----------AAA-- ------------AAAAA--------AAAA-- -------------AAAAA------AAAAA-- -------------AAAAAAAAAAAAAAA--- --------------AAAAAAAAAAAAAA--- ---------------AAAAAAAAAAAA---- -----------------AAAAAAAAA----- --------------------AAA-------- ------------------------------- ------------------------------- ------------------------------- 
-----------------------------A- -A--------------------------AA- -AAAAAAAAA------------------AA- -AAAAAAAAAAAA---------------AA- --------AAAAAA-------------AAA- -----------AAA------------AAAA- ------------AAA-----------AAAA- ------------AAAAA-------AAAAA-- -------------AAAAAAA--AAAAAAA-- --------------AAAAAAAAAAAAAA--- ---------------AAAAAAAAAAAA---- ----------------AAAAAAAAAA----- ------------------------------- ------------------------------- ------------------------------- 
-----------------------------AA -----------------------------AA -AAA-------------------------AA -AAAAAAAAAA-----------------AAA ----AAAAAAAA----------------AAA ---------AAAA--------------AAA- -----------AAA-------------AAA- -----------AAAA-----------AAAA- ------------AAAAA--------AAAA-- -------------AAAAAA----AAAAAA-- --------------AAAAAAAAAAAAAA--- ---------------AAAAAAAAAAAA---- -----------------AAAAAAAA------ ------------------------------- ------------------------------- 
-----------------------------AA -----------------------------AA -----------------------------AA AAAAAAAA---------------------AA --AAAAAAAAA------------------AA --------AAAA----------------AAA -----------AA--------------AAAA -----------AAA-------------AAA- -----------AAAA-----------AAAA- ------------AAAAA--------AAAA-- -------------AAAAAA----AAAAA--- --------------AAAAAAAAAAAAA---- ---------------AAAAAAAAAAA----- -------------------AAA--------- ------------------------------- 
-----------------------------AA -----------------------------AB -----------------------------AB AAAAA------------------------AB -AAAAAAAAA-------------------AB ------AAAAAA----------------AAB -----------AA---------------AAC -----------AA--------------AAAA -----------AAA-------------AAA- -----------AAAAA----------AAAA- ------------AAAAA-------AAAAA-- -------------AAAAAAA--AAAAAA--- ---------------AAAAAAAAAAAA---- -----------------AAAAAAA------- ------------------------------- 
-----------------------------AA -----------------------------AB -----------------------------AB AAA--------------------------AB AAAAAAAAA--------------------AB -----AAAAAAA-----------------AC -----------CA---------------AAC -----------BA---------------AAA -----------BA--------------AAA- -----------BAAA-----------AAAA- -----------BAAAA---------AAAA-- -------------AAAAA------AAAA--- --------------AAAAAAAAAAAAA---- ----------------AAAAAAAAA------ --------------------A---------- 
-----------------------------AA -----------------------------AA -----------------------------AA AA---------------------------AA AAAAAAAA---------------------AC -----AAAAAAA-----------------AC -----------AA----------------AA -----------CA---------------AAA -----------AA--------------AAAA -----------AAA-------------AAA- -----------AAAAA----------AAA-- -------------AAAA-------AAAAA-- --------------AAAAAAAAAAAAA---- ---------------AAAAAAAAAA------ -------------------AAA--------- 
-----------------------------AA -----------------------------AA -----------------------------AA A----------------------------AC AAAAAAAA---------------------AC -----AAAAAAA-----------------AA -----------AA----------------AA -----------AA---------------AAA -----------CA---------------AAA -----------AAA-------------AAA- -----------AAAA-----------AAAA- -------------AAAA--------AAAA-- --------------AAAAA--AAAAAA---- ---------------AAAAAAAAAA------ ------------------AAAAA-------- 
-----------------------------AA -----------------------------AA -----------------------------AC AA---------------------------AC AAAAAAAA---------------------AA -----AAAAAAA-----------------AA -----------AA----------------AA -----------AA---------------AAA -----------AA--------------AAAA -----------CAA-------------AAA- -----------AAAAA----------AAA-- -------------AAAA-------AAAAA-- --------------AAAAAAAAAAAAA---- ---------------AAAAAAAAAA------ -------------------AAA--------- 
-----------------------------AA -----------------------------AC -----------------------------AC AAA--------------------------AB AAAAAAAAA--------------------AB ------AAAAAA-----------------AB -----------BA---------------AAB -----------BA---------------AAA -----------BA--------------AAA- -----------BAAA-----------AAAA- -----------CAAAA---------AAAA-- -------------AAAAA-----AAAAA--- --------------AAAAAAAAAAAAA---- ----------------AAAAAAAAA------ --------------------A---------- 
-----------------------------AA -----------------------------AC -----------------------------AB AAAAAA-----------------------AB -AAAAAAAAA-------------------AB -------AAAAA----------------AAB -----------AA---------------AAB -----------AA--------------AAAA -----------AAA------------AAAA- -----------AAAAA----------AAAA- ------------AAAAAA------AAAAA-- -------------AAAAAAA-AAAAAAA--- ---------------AAAAAAAAAAAA---- -----------------AAAAAAA------- ------------------------------- 
-----------------------------AA -----------------------------AA -----------------------------AA AAAAAAAA---------------------AA --AAAAAAAAA-----------------AAA --------AAAA----------------AAA -----------AA--------------AAAA -----------AAA-------------AAA- -----------AAAA-----------AAAA- ------------AAAAA--------AAAA-- -------------AAAAAA----AAAAA--- --------------AAAAAAAAAAAAA---- ----------------AAAAAAAAAA----- -------------------AAA--------- ------------------------------- 
-----------------------------AA -----------------------------AA -AAAA------------------------AA -AAAAAAAAAA-----------------AAA -----AAAAAAA----------------AAA ----------AAA--------------AAA- -----------AAA-------------AAA- -----------AAAA-----------AAAA- ------------AAAAA--------AAAA-- -------------AAAAAAA--AAAAAAA-- --------------AAAAAAAAAAAAAA--- ---------------AAAAAAAAAAAA---- -----------------AAAAAAAA------ ------------------------------- ------------------------------- 
-----------------------------A- -A--------------------------AA- -AAAAAAAAA------------------AA- --AAAAAAAAAAA--------------AAA- --------AAAAAA-------------AAA- -----------AAA------------AAAA- ------------AAAA---------AAAA-- ------------AAAAA-------AAAAA-- -------------AAAAAAAAAAAAAAAA-- --------------AAAAAAAAAAAAAA--- ---------------AAAAAAAAAAAA---- ----------------AAAAAAAAAA----- ------------------------------- ------------------------------- ------------------------------- 
--A-------------------------AA- --AAAAAAA------------------AAA- --AAAAAAAAAAAA-------------AAA- -----AAAAAAAAAA-----------AAAA- -----------AAAAA----------AAA-- ------------AAAAA--------AAAA-- -------------AAAAAA-----AAAAA-- --------------AAAAAAAAAAAAAA--- --------------AAAAAAAAAAAAAA--- ---------------AAAAAAAAAAAA---- -----------------AAAAAAAAA----- ------------------------------- ------------------------------- ------------------------------- ------------------------------- 
---A----------------------AAA-- ---AAAAAAAAAAAAA----------AAA-- ----AAAAAAAAAAAAAA-------AAAA-- -----------AAAAAAA-------AAAA-- --------------AAAAA-----AAAA--- --------------AAAAAAAAAAAAAA--- ---------------AAAAAAAAAAAAA--- ---------------AAAAAAAAAAAA---- ----------------AAAAAAAAAA----- ------------------AAAAAAA------ ------------------------------- ------------------------------- ------------------------------- ------------------------------- ------------------------------- 
----AAAAAAAAAAAAAAAAA--AAAA---- ----AAAAAAAAAAAAAAAAA--AAAA---- -----------AAAAAAAAAAAAAAAA---- ---------------AAAAAAAAAAAA---- ----------------AAAAAAAAAAA---- -----------------AAAAAAAAAA---- -----------------AAAAAAAAA----- ------------------AAAAAAA------ ---------------------AA-------- ------------------------------- ------------------------------- ------------------------------- ------------------------------- ------------------------------- ------------------------------- 
-------------------AAAAAA------ -------------------AAAAAA------ -------------------AAAAAA------ -------------------AAAAAA------ --------------------AAAA------- ---------------------AA-------- ------------------------------- ------------------------------- ------------------------------- ------------------------------- ------------------------------- ------------------------------- ------------------------------- ------------------------------- ------------------------------- 
------------------------------- ------------------------------- ------------------------------- ------------------------------- ------------------------------- ------------------------------- ------------------------------- ------------------------------- ------------------------------- ------------------------------- ------------------------------- ------------------------------- ------------------------------- ------------------------------- ------------------------------- 
------------------------------- ------------------------------- ------------------------------- ------------------------------- ------------------------------- ------------------------------- ------------------------------- ------------------------------- ------------------------------- ------------------------------- ------------------------------- ------------------------------- ------------------------------- ------------------------------- A------------------------------ 
