model
size = 8 6 22, scale = 0.05, origin = -y
material 
  colors = A:#FFF B:#FCFAF2 C:#EEE D:#B28FCE E:#FEDFE1 F:#986DB2 G:#70649A
voxels
-------- -------- ---GG--- ---GG--- -------- -------- 
-------- ---FF--- --GFFG-- --GFFG-- ---FF--- -------- 
-------- --FFFF-- -GFFFFG- -GFFFFG- --FFFF-- -------- 
-------- -DFDDFD- -FDDDDF- -FDDDDF- -DFDDFD- -------- 
-------- -DDDDDD- -DDDDDD- -DDDDDD- -DDDDDD- -------- 
-------- -EDDDDE- -EEEEEE- -EEEEEE- -EDDDDE- -------- 
-------- -EEDEDE- -EEEEEE- -EEEEEE- -EEDEDE- -------- 
-------- -CEEEEC- -CCCCCC- -CCCCCC- -CEEEEC- -------- 
-------- -CBCBCC- -CCCCCC- -CCCCCC- -CBCBCC- -------- 
-------- -CBCCBC- -CCCCCC- -CCCCCC- -BBCCBB- -------- 
-------- -ACCBCA- -AAAAAA- -AAAAAA- -ACCBCA- -------- 
-------- -BBAAAB- -BAAAAB- -BAAAAB- -BBAABB- -------- 
-------- -AAAAAA- -AAAAAA- -AAAAAA- -AAAAAA- -------- 
-------- -BAAAAA- -BAAAAA- -AAAAAA- -BAABAA- -------- 
-AAA-AA- AAAAAAAA AAAAAAAA AAAAAABA ABABAABA -AAA-AA- 
AAAAAAAA AAAAAAAA AAAAAAAA AAAAAAAA AAAAAAAA AAAAAAAA 
AABAAAAB AAAAAAAA BAAAAAAA BBAAAAAA ABAAAABA AABAAAAB 
BBAAAAAB AAAAAAAA AAAAAAAB AAAAAAAB AAAAAABA BBAAAAAB 
BBABAAAA AAAAAAAA AAAAAAAA AAAAAABA ABAABAAA BBABAAAA 
AAAAAAAA AAAAAAAA BAAAAAAA BAAAAAAA AAAAAAAA AAAAAAAA 
-AAABBA- AAAAAAAA AAAAAAAA AAAAAAAA AAAAAAAA -AAABBA- 
--AAAA-- -AAAAAA- AAAAAAAA AAAAAAAA -AAAAAA- --AAAA-- 
