model
size = 32 27 32, scale = 0.05, origin = -y
material 
  colors = A:#FFF B:#7B90D2 C:#B28FCE D:#FCFAF2 E:#EEE F:#4E4F97 G:#A5DEE4
voxels
362-4E26-6ED2E23-ED4ED2E25-3ED762-4AD4A22-E9A2E20-10A2D21-AD7A751-2D5-2ADA2-6A13-2E3-2E4AD7AE12-2E3-E6AD4A3D12-2E5-D3A2-2(DA)2D685-2(2D30-)2DE-3D2A5-2A2(DA)12-2AE-16AE11-2AE-16AD11-2AD-AD3A5-2AD3A12-2E30-ED606-AD30-2A2E28-2A2ED27-3AE3AD8-5A11-3AE3AD-AG2-8AE10-3AE4A-A3-8AE10-3AE4A8-5A11-2A2ED27-AD2E28-AD542-A31-A2D29-3A2D27-5A27-7AG9-3A2D10-8A7-7AE9-8A7-2AD4AE9-7A10-2(DA)D10-2(5A27-)A2D29-A511-2A30-2ADA28-2(5A27-)6A12-5A2(9-7A)E8-7A9-AD5AE8-6A12-5A9-2(5A27-)2A2D28-2A510-2A30-4A28-4ADG26-5A6-G20-6AG11-5A9-7A10-6AD8-7A10-7A8-6AG11-3ADA9-5A27-5AG26-4A28-2A11-G15-A482-AD30-2ADA28-2(5A27-)6A12-5A9-2(6A11-7A8-)6A12-AD3A9-2(5A27-)4A28-2A510-2A30-3A29-4A28-5A27-5A13-2(AD)A9-6A10-8A8-6A2-G7-8A8-5A13-3ADA9-5A27-4A28-3A29-2A510-A31-3A29-4AG27-4A28-5A12-2AD3A9-2(5A11-8A8-)5A12-3AD2A9-4A28-4AG27-3A29-A543-2A30-3A29-4A28-4A12-6A10-2(5A10-8A9-)4A12-4ADA10-4A28-3A29-2A574-A31-2(3A29-)4A12-6A10-4A11-8A9-4AG10-8A9-4A12-A2D3A10-2(3A29-)A133-G473-2(2A30-)3A13-5A11-2(3A12-7A10-)3A13-5A11-2A30-2A580-G52-A36-A31-2A13-2AD3A11-2A13-7A10-2AG12-7A10-2A13-4ADA11-A400-A334-A14-5A12-2(A13-7A11-)A14-AD3A763-5A26-7A25-7A10-A15-5A734-A28-5A26-7A25-7A26-5A30-A152-A551-A2(26-6A)2(CA24-6A)31-A704-A2(25-2AC4A)C24-2AC4AC24-2AC5A30-A196-A503-A-A26-4A2(CA)24-2(4ACAC2A23-)4A2(CA)27-2(A-)A479-A220-A-2A25-4AC2A24-5AC2ACA22-5AC2ACA23-4AC2A28-A-2A701-A2CA26-3A2CAC23-AC3A2CACA22-AC3A2CACA24-3A2CAC27-A2CA175-G173-A349-CA2CAC25-AC2(A2C)23-2AC2(A2C)A22-2AC2(A2C)A23-AC2(A2C)25-CA2CAC699-CA3CA24-2(3CA)C23-2(3CA)2C22-A2CA3CA2C22-2(3CA)CA4-A19-CA3CA699-2C-3C24-4CB4C22-5CB4C2B20-2(5CB)21-4CB3CA25-2C-3C698-2(B-)2BAB23-2BCBC4BC21-A2BCBC4B2C20-C2BCBC4BCB21-2BCBC4BC23-2(B-)BA2B534-A162-2BA3-2B23-A3BCBC3B21-C4BCBC3BA20-C4BCBC4B21-A3BCBC3B23-BAB3-2B697-7B23-BF7BF21-2BF7B2F20-2BF7BFB21-BF7BF24-7B697-3(B-)B24-2B2(2(FB)F2B22-3B)2(FB)F2B23-2B2(FB)F2B24-3(B-)B50-A647-2(B-)B26-5FBF24-B5FB2F23-B5FBFB24-5FBF26-2(B-)B732-FBF28-FB3FB26-3(BF)2-A24-FBF389-
