model
size = 20 33 14, scale = 0.05, origin = -y
material 
  colors = A:#800 B:#080 C:#111 D:#FF0 E:#700 F:#500 G:#050 H:#F00 I:#070 J:#C00 K:#EEE L:#FC0 M:#E00
voxels
484-I3F4-3FI8-IFMF4-FMFI8-I3F4-3FI8-4I4-4I568-4I4-4I7-3(D4AG2-G4AD6-)I4AI2-I4AI53-F19-F453-BAMA4-AMAB7-DB3AB2-B3ABD5-2B4A4B4A2B4-B2A2-2A2F2A2-2AB4-BA4-A2FA4-AB4-B2A2-2A2F2A2-2AB4-B6A2B6AB4-BDB3AB2FB3ABDB5-14B6-F-3AB2AB3AF7-F6-F4-F428-B3A4-3AB7-D4AB2-B4AD5-B2A2-2A2L2A2-2AB3-B2A4-4A4-2AB3(2-2A14-2A)2-BA14-AB2-3A12-3A3-B3A8-3AB4-BAB10ABAB5-F14C25-ELG2EG2-G2EGLE6-JLG2JG2-G2JGLJ288-B8-B9-3B6-3B8-B2A6-2AB7-2(4B6-)D4AB2-B4AD5-B2A2-2A2L2A2-2AB3-B2(2A5-)2AB2-BA14-AB-B2(A16-A2B)A16-AB-B16-2(B2-BA14-A)B3-B14ABF3-2C-12C2F23-GE3AED2-DE3AEG4-G5AD2-D5AG5-BDB2AB2-B2(2ABDB6-BDBAH4-HABDB2(6-BDB2A4-2ABDB6-5B4-5B)6-BDB2A4-)2ABDB6-BDBAHB2-BHABDB5-ABD3AB2-B3ADBA4-2BA-A2B2-2BA-A2B4-BDA-2AB2-B2A-ADB4-B2A-A2B2-2BA-2AB4-BA2-2AD2-D2A2-AB3-3A4-4A4-3A2-2A14-2A-BA16-AB2A16-3A18-3A16-2ABA16-AB2A16-2A-BA14-AB2-5A8-5A2-18C22-2(E6AE2-)J3A-2AD2-D2A-3AJ3-2A3-AD2-D2(A3-2A4-HA3-AB2-BA3-AH2(4-2A3-AB2-BA3-2A4-BA3-AB2-BA3-AB)4-2A3-AB2-B)A3-2A4-HA3-AD2-DA3-AH4-2A4-D2-D4-2A4-B5-B2-B5-B4-A5-D2-D5-A3-BA5-B2-B5-AB2-2A5-A2-A5-2A2-HA6-2A6-AH2-A16-A-BA16-ABA18-AH18-HA18-AB18-B2A16-2A-B16-B2-2A14-2A2-18C22-2(E6AE2-)JA5-E2-E5-AJ3-3(A5-D2-D5-A4-)B5-B2-B5-B3-2A5-D2-D5-2A3-B5-D2-D5-B3-2A5-D2-D5-2A2-2A5-D2-D5-2A3-2(A5-D2-D5-A4-B5-B2-B5-B4-)A5-A2-A5-A3-2(2A5-A2-A5-2A2-)BA14-AB2-2A14-2A2-BA14-AB2-A7-2F7-A2-A7-2A7-A2-A16-A-BA16-ABA2(18-2A)18-AB18-B2A16-2A-B16-B-2F2A12-3A-2F17C21-GE6AE2-E6AE2G2A5-E2-E5-2AG-14(BA14-AB2-)5(B16-B2-)B7-2A7-B2-B16-B-B2(A16-A2B)2(18-2B)A16-A2BA16-AB-B16-B2-B2A12-2AB2-18C21-LE6AE2-E6AE2L2A5-E2-E5-2AL-3(DA5-A2-A5-AD2-)2(BA5-B2-B5-AB2-DA5-A2-A5-AD2-)DA5-A2-A5-AD2-DA5-D2-D5-AD2-BA14-AB2-DA5-D2-D5-AD2-BA5-B2-B5-AB2(2-DA5-A2-A5-AD)2-DA14-A2(D2-B16-B2-D16-)2(D2-D7-2A7-)D2-B16-B-D2(A16-A2D)A16-ADBA16-AB-D16-D2-BA14-AB2-D2A12-2AD2-18C22-G6AE2-E6AG2-G2A3-AE2-EA3-2AG3-3(B5-A2-A5-B4-)2(B5-B2-B5-B4-B5-A2-A5-B4-)2(B5-A2-A5-B4-)2(B5-B2-B5-B4-B5-A2-A5-B4-)B5-A2-A5-B3-2(BA5-A2-A5-AB2-BA5-B2-B5-AB2-)BA5-B2-B5-AB2-BA5-A2-A5-AB2-BA5-4A5-7(AB2-BA14-)AB3-4A8-4AF3-16CF22-E6AE2-8E2-J6AE2-7EJ2(3-2A)2-2A3-2A4-HA3-AH2-HA3-AH4-2A3-2A2-2A3-2A4-2B3-AB2-BA3-2B4-3A2(2-2A)2-3A4-2BA2-AB2-BA2-A2B4-3A2(2-2A)2-3A4-H2A2-AH2-HA2-2AH4-3A2(2-2A)2-3A4-2B3-AB2-BA3-2B4-3A2(2-2A)2-3A4-2BA-2AB2-B2A-A2B4-3A-3A2-3A-3A4-HA3-AH2-HA3-AH4-2A3-2A2-2A3-2A4-BA3-2B2-2B3-AB4-2A3-2A2-2A3-2A4-BA3-AB2-BA3-AB4-2A3-2A2-2A3-2A4-HA3-2A2-2A3-AH4-2A4-4A4-2A4-BA12-AB4-2A12-2A4-HA12-AH2(4-2A12-2A4-BA12-AB)4-F15A4-F15C24-2E4AE2-7E4-2J4AJ2-J4E2J6-3(BDBA4-ABDB8-)2(4B4-4B8-BDBA4-ABDB8-)2(BDBA4-ABDB8-)4B4-4B8-BDBA4-ABDB8-4B4-4B8-BDBA4-ABDB7-2(ABDBA4-ABDBA6-)2(5B4-5B6-ABDBA4-ABDBA6-)ABD3A2-3ADBA6-ABDB6ABDBA6-3BA2B2A2BA3B6-ABDBAH2AHABDBA6-ABDBAM2AMABDBA6-ABDB6ABDBA6-6B2A6B6-2ADB6ABD2A6-2BA3B2A3BA2B6-ABDAC4ACADBA6-3CF6CF3C10-5K12-GLGE4-EGLG8-GLGJ4-JGLG390-BAM2-MAB13-F-2F-F13-B2-2G2-B15-2(FA18-)FA12-B5-2G5-B7-B4-FA4-B9-B3-2G3-B11-B5K-B12-BK3-K-B13-5K8-
