model
size = 12 11 9, scale = 0.05, origin = -y
material 
  colors = A:#33C B:#DDD C:#AAA D:#369 E:#888 F:#EEE G:#004 H:#777 I:#111 J:#F96 K:#FCF L:#C60 M:#555 N:#FFF O:#960 P:#3CF Q:#BBB R:#09C S:#09F
voxels
------------ ------------ ------------ -----KK----- ----I--I---- ------------ ------------ ------------ ------------ ------------ ------------ 
------------ -----FF----- ---OJJJJO--- ---FFKKFF--- ---BCBBQB--- ---BBBBBF--- ------------ ------------ ------------ ------------ ------------ 
--N------N-- --A------A-- --A------A-- --A------A-- --ABEEEEBA-- --ABII-IBA-- ---AAAAAA--- ------------ ------------ ------------ ------------ 
------------ ------------ --A------A-- ------------ --AB----BA-- ---E----A--- --AG----GA-- ----AAAA---- ------------ ------------ ------------ 
------------ ------------ --A------A-- --A------A-- ---A----A--- --A------A-- --AG----GA-- -HH-RPPS-EE- CLC------CLC CLC------CLC CCM------MCC 
------------ --A------A-- --A------A-- ------------ --A------A-- ---H----A--- --AG----GA-- ----AAAA---- ------------ ------------ ------------ 
------------ ------------ --AM----EA-- --A------A-- --A------A-- --A------A-- ---AAAAAA--- ------------ ------------ ------------ ------------ 
------------ ----E--E---- ----H--H---- ---A-AA-A--- ---A----A--- ---AAAAAA--- ------------ ------------ ------------ ------------ ------------ 
------------ ----D--D---- ----D--D---- ----DDDD---- ----DDDD---- ------------ ------------ ------------ ------------ ------------ ------------ 
