model
size = 12 24 12, scale = 0.05, origin = -y
material 
  colors = A:#EBB471 B:#E16B8C C:#AF5F3C D:#00AA90 E:#FFF F:#FBE251 G:#2EA9DF
voxels
------------ ------------ ------------ ------------ ------------ ------------ ------------ ------------ ------------ ------------ ------------ ------------ ------------ ------------ -----BB----- ------------ ------------ ------------ -----GG----- ------------ ------------ ------------ ------------ ------------ 
------------ ------------ ------------ ------------ ------------ ------------ ------------ ------------ ------------ ------------ ------------ ------------ ------B----- -----BB----- ----AAAA---- -----BB----- -----BB----- ----BBBB---- ---BBBBBE--- ----BBBB---- ------------ ------------ ------------ ------------ 
------------ ------------ ------------ ------------ ------------ ------------ ------------ ------------ ------------ ------------ -----AA----- -----AA----- -----AA----- -----CC----- ---AA--AA--- -----BB----- ---BBBBBB--- ---BB--BB--- --BBB--BBB-- ---BB--BE--- -----BB----- ------------ ------------ ------------ 
------------ ------------ ------------ ------------ -----AA----- -----AA----- -----AA----- -----AA----- ---CCCCCC--- ---AAAAAA--- ---AAAAAA--- ---AAAAAA--- ---AAAAAA--- ---CCCCCC--- --AAA--AAA-- ---BBBBBB--- --BBB--BBB-- -FBB----BBB- -BBB----BBF- -BBB----BBB- ---EBBBBB--- ----EBBB---- ------------ ------------ 
------------ ------------ ----AAAA---- ----CCCC---- ----AAAA---- ----AAAA---- ----AAAA---- ----AAAA---- ---CAAAAC--- ---AAAAAA--- ---AAAAAA--- ---AAAAAA--- ---AAAAAA--- ---CCCAAC--- -AA------AA- --BB----BB-- --BB----BB-- -B--------F- -F--------B- -BBB----BBB- --BBB--BBG-- --DBBBBBBG-- ----BBBD---- ------------ 
-----AA----- -----AA----- ----AAAA---- ----CAAC---- ---AAAAAA--- ---AAAAAA--- ---AAAAAA--- ---AAAAAA--- ---CAAAAC--- ---AAAAAA--- --AAAAAAAA-- --AAAAAAAA-- --AAAAAAAA-- --CCCCAACC-- -AA------AA- --B------B-- --B------B-- -B--------B- BB--------BB -BBB----BBB- --BB----BB-- --BBBBBBBB-- ---DBBBDB--- -----BB----- 
-----AA----- -----AA----- ----AAAA---- ----CAAC---- ---AAAAAA--- ---AAAAAA--- ---AAAAAA--- ---AAAAAA--- ---CAAAAC--- ---AAAAAA--- --AAAAAAAA-- --AAAAAAAA-- --AAAAAAAA-- --CCAAAACC-- -AA------AA- --B------F-- --D------B-- -D--------B- BB--------BD -BBB----BBB- --GB----BE-- --GBBBBBBB-- ---BBBBBB--- -----BB----- 
------------ ------------ ----AAAA---- ----CCCC---- ----AAAA---- ----AAAA---- ----AAAA---- ----AAAA---- ---CAAAAC--- ---AAAAAA--- ---AAAAAA--- ---AAAAAA--- ---AAAAAA--- ---CAAAAC--- -AA------AA- --BB----BF-- --BB----BB-- -B--------B- -B--------D- -BBB----BBB- --BBB--BBE-- --BBBBBBFB-- ----BBBF---- ------------ 
------------ ------------ ------------ ------------ -----AA----- -----AA----- -----AA----- -----AA----- ---CCCCCC--- ---AAAAAA--- ---AAAAAA--- ---AAAAAA--- ---AAAAAAB-- ---CACCCCB-- --AAA--AAAB- ---BBBBBBBB- --BBB--BBBB- -BBB----BFB- -EBB----BBB- -BBB----BBB- ---BBBBBB--- ----EEBB---- ------------ ------------ 
------------ ------------ ------------ ------------ ------------ ------------ ------------ ------------ ------------ ----B------- ----BAA----- ----BAA----- ----BAA----- ----BCC----- ---AA--AA--- ---BBBB----- ---BBBBDB--- ---BB--BB--- --EBB--BBF-- ---BD--BB--- -----BB----- ------------ ------------ ------------ 
------------ ------------ ------------ ------------ ------------ ------------ ------------ ------------ ------------ ------------ ------------ ------------ ------------ ----B------- ---BBAAA---- ---BB------- ---GB------- ---BGBDB---- ---BBBBEB--- ----DBBE---- ------------ ------------ ------------ ------------ 
------------ ------------ ------------ ------------ ------------ ------------ ------------ ------------ ------------ ------------ ------------ ------------ ------------ ------------ ------------ ------------ ------------ ------------ -----BB----- ------------ ------------ ------------ ------------ ------------ 
