model
size = 32 32 27, scale = 0.05, origin = -y
material 
  colors = A:#1A1A1A B:#B3391D C:#B2381D D:#E67A20 E:#BF471E F:#B2371D G:#C44C1F H:#B63C1D I:#B33A1D J:#BD451E K:#BA411E L:#DF7120 M:#DC6C20 N:#E47820 O:#B53A1E P:#E67B20 Q:#C0481E R:#D15C1F S:#BF461E T:#E87E20 U:#D15D1F V:#C1491E W:#B63B1D X:#C64E1F Y:#D66320 Z:#E17420 Aa:#BC431E Ab:#D86620 Ac:#B4391D Ad:#E37820 Ae:#DB6A20 Af:#C0471E Ag:#BA3F1E Ah:#BE461E Ai:#ED8720 Aj:#CD561F Ak:#BC451E Al:#EB8320 Am:#C34E1F An:#B3381E Ao:#DE6F20 Ap:#D35F1F Aq:#D96820 Ar:#D66420 As:#CE581F At:#BA401E Au:#BB411E Av:#B1361D Aw:#B83F1E Ax:#BB431E Ay:#BE471E Az:#BF481E Ba:#CB551F Bb:#C24A1F Bc:#CF5A1F Bd:#CD581F Be:#B83E1E Bf:#EA8120 Bg:#CA531F Bh:#E17320 Bi:#B2391D Bj:#E77D20 Bk:#D46020 Bl:#CE591F Bm:#BB421E Bn:#B0351D Bo:#B1371D Bp:#B53B1E Bq:#B3381D Br:#B53B1D Bs:#C54D1F Bt:#E07220 Bu:#B2381E Bv:#B83E1D
voxels
334-5A25-8A23-10A5(21-11A)21-10A23-9A23-8A25-7A26-4A509-5A25-9A22-10A21-12A19-2B3A5-4A17-CTBA8-3A16-2TAgN10-2A16-BeAbBf8-5A16-3A7-6A16-3A7-5A17-3A6-6A17-3A5-3A2(-A)17-3A5-2A3-2A17-4A9-3A17-3A8-3A18-4A7-3A19-4A4-5A20-10A24-6A379-7A24-10A20-6A-7A17-3A9-3A16-Bb2A10-3A15-HBBd12-3A13-2XC14-2A13-2I15-2A13-I11-7A12-AD5-12A13-2A3-12A15-2A3-11A2(16-2A2-12A)16-2A2-13A15-2A3-14A14-2A2-9A-A-2A14-2A3-8A3-2A14-3A4-5A4-2A15-3A10-2A18-4A6-3A20-5ABHBi3A22-2ALHEL2BC256-2A26-8A20-4A5-4A16-4A10-3A15-2A14-2A13-2A15-2A12-2A16-2A12-A17-2A11-A5-6A7-3A10-A3-14A2-2A9-2A2-17A11-A3-12A3-A12-4(A2-13A16-)A2-14A15-A2-15A14-2A-18A11-2A2-13A3-A12-A2-13A3-A12-2A2-11A2-2A14-2A3-8A2-2A15-3A11-3A17-2A9-BBjA19-11A24-5A194-5A23-4A4-3A17-5A8-2A14-4A-2A10-2A11-2A4-5A9-A10-2A4-7A8-2A9-A4-9A7-2A9-A3-12A3-A-2A8-A3-3A6-6A-4A8-A2-2A11-8A7-A3-A16-A10-A2-2A27-5(A2-A28-)A2-A15-A12-A2-A15-3A10-A2-2A13-A3-A10-A2-A13-2A2-A10-A2-2A11-A3-A11-2A2-3A8-2A2-A13-A3-11A3-A14-2A4-5A5-A16-2A11-2A19-3A5-3A24-AL2MAq133-3A26-3A2-3A20-5A6-A16-9A6-2A12-13A6-A9-7A5-5A5-2A7-A4-2A7-5A5-A7-A3-2A9-4A5-Bc7-A2-2A12-2A2-4A6-A3-A15-3A2-A6-A2-A21-A6-A2-A27-7(A2-A28-)A2-A17-3A8-A2-A16-5A8-A2-A15-A3-A8-A2-A14-A3-A9-A3-A13-A2-A11-A2-2A11-A3-A12-A3-3A5-3A3-A14-A5-5A5-A16-2A11-TR19-3ALAoAeYUR2Y101-A28-5A24-3A5-A20-6A5-A15-12A5-A11-3A9-4A4-A8-4A12-3A4-A7-A2-2A13-3A4-Ab5-A3-A15-2A2-2AW5-A2-A16-7A5-A2-A21-2A4-3(A2-A28-)A4(-A28-2A)2(-A29-A)-A19-3A7-A-A18-5A6-A2-A17-A2-A7-A2-A16-A2-A9-A2-A15-A2-A9-A2-A14-A2-A11-A2-2A11-A2-A13-A2(3-4A)3-A14-2A5-3A5-ApAs17-2A8-2VG21-ALAeU2AjVO71-2A27-3A2-A23-5A4-A25-2A4-AB25-2A4-B26-A4-Z26-3A2-Z5-4A18-A3-Ab5-A2-A18-A3-Ao4-A2-A19-5A4-A2-A23-A4-A3(-A28-2A)-A28-6(3A29-)2A-A19-4A5-2A-A19-A2-A6-A-A18-A2-A7-A2-A16-A2-A9-A-A16-A2-N9-A2-2A12-2A2-M11-A3-2A9-A3-U13-2A3-9A3-X16-2A11-AcBm19-2ALAs2Aa4BO68-4A28-A3-A25-3A4-A26-2A3-B27-A4-Am26-A4-K27-A3-H4-3A20-A3-S3-A2-A20-3A-H3-A2-A20-5A3-A-A25-A2-2(2A-A28-)2(3A29-)3A28-A2-A28-A-A29-A-A30-2A30-3A29-3A21-4A4-3A20-A2-A5-3A20-A2-A6-A-A18-A2-P7-A2-A16-A2-P9-A2-A14-A3-M9-A3-2A11-A3-R11-2A3-2A6-3A2-2At14-2A3-6A4-C18-2DY6-FBo2F22-VBpBq2CBr39-5A28-A3-A27-A3-A28-A3-A27-A3-Am2(27-A3-K)3-2A22-2A2-S3-A-A21-3A-A3-A-A21-5A2-2A-A25-A2-3A29-3A2(28-A2-A)28-A-D29-A-A29-A-N29-A-Aj29-A-An29-A-X29-A-Bh23-3A4-2A22-A-A5-AD21-A2-A5-3A20-A-D7-A-A18-A2-D7-A2-A16-A2-M9-A2-2A12-2A2-R11-A3-2A8-2A3-Af13-2A3-8A3-BnI16-TN9-KJW20-2GCAvCJ2AwAx39-5A28-A2-A28-2(A3-A27-)A4-A26-A4-A27-A3-A2-2A23-A3-A2-3A22-2A2-A-2A-A22-5A-3A27-A-3A2(28-4A)28-A-A29-A-U2(29-A-A)29-3A29-A-J2(29-A-A)23-4A2-A-A22-A2-A4-AU22-A-A5-3A20-A2-P5-2A-A18-A2-Z7-A2-A16-A2-Bk9-A2-A14-A2-Af11-A2-2A10-2A2-Af13-A3-4A2-4A3-B15-DAiM4-2A4-2JH19-2GCAvC2J3E39-4A28-A3-A27-A3-A28-A3-R27-A3-Ba2(27-A3-G)2-2A23-2A2-A2-3A22-2A2-A-3A23-5A-3A27-A-3A28-4A28-2(3A29-)A-S3(29-3A)29-2ABg29-3A29-A-A23-4A2-3A23-A-A3-2AS22-A-D5-3A20-A2-Ad5-2A-A18-A2-Ad7-A2-A16-A2-Ae9-A2-A14-A3-Bl9-2A2-2A10-2A2-2Au12-A3-3A4-3A3-C15-AD4-4A3-2AkW18-BsCFHKAy2E2QAh39-4A29-A2-A28-A2-Al32-Al31-Ag31-C31-Aa2-A25-2(A2-)2A24-A2-A-3A24-4A-3A27-5A28-3(3A29-)2AAc29-3A29-2AAi29-2AAq29-2ABu29-2AX29-2ABh23-4A2-3A23-A-AdA2-2AAc22-A-D5-3A20-A2-P5-3A20-A-P7-3A18-A-Ar8-A-3A14-2A2-Ar9-2A-2A12-A2-AO11-3A-3A6-3A2-2I14-AN3-6A3-KW18-O2FAxAhE2QEAz2E38-4A29-4A31-2(2A30-)AAh2(30-AAn)2-A27-AAi2-2A26-2A-3A25-3A-3A27-5A28-3(3A29-)2AB6(29-3A)23-4A2-3A23-4A2-2AB22-3AN4-3A20-3AD5-3A20-2AD7-2A19-3AAq7-2A18-3ABg9-3A14-4AO11-4A9-5A2B14-AN12AAkBv18-3F2E3QEAz2Ay38-4A29-A2-A28-A2-Al32-Al31-Ag31-C31-Aa2-A25-2(A2-)2A24-A2-A-3A24-4A-3A27-5A28-3(3A29-)2AAc29-3A29-2AAi29-3A29-2AAn29-2AS29-2AC23-4A2-3A23-A-AdA2-2AAc22-A-D5-3A20-A2-P5-3A20-A-P7-3A18-A-Ar8-A-3A14-2A2-Ar9-2A-2A12-A2-AO11-3A-3A6-3A2-2I14-AN3-6A3-KW18-O2FAxAhE2QEAz2E38-4A28-A3-A27-A3-A28-A3-R27-A3-Ba2(27-A3-G)2-2A23-2A2-A2-3A22-2A2-A-3A23-5A-3A27-A-3A28-4A28-2(3A29-)A-S29-3A29-2ABt29-3A29-2AS29-3A29-A-Ag23-4A2-3A23-A-A3-2AS22-A-D5-3A20-A2-Ad5-2A-A18-A2-Ad7-A2-A16-A2-Ae9-A2-A14-A3-Bl9-2A2-2A10-2A2-2Au12-A3-3A4-3A3-C15-AD4-4A3-2AkW18-BsCFHKAy2E2QAh38-5A28-A2-A28-2(A3-A27-)A4-A26-A4-A27-A3-A2-2A23-A3-A2-3A22-2A2-A-2A-A22-5A-3A27-A-3A2(28-4A)28-A-A29-A-U29-A-A29-A-Ap29-3A29-A-I29-A-A29-A-Ap23-4A2-A-A22-A2-A4-AU22-A-A5-3A20-A2-P5-2A-A18-A2-Z7-A2-A16-A2-Bk9-A2-A14-A2-Af11-A2-2A10-2A2-Af13-A3-4A2-4A3-B15-DAiM4-2A4-2JH19-2GCAvC2J3E37-5A28-A3-A27-A3-A28-A3-A27-A3-Am2(27-A3-K)3-2A22-2A2-S3-A-A21-3A-A3-A-A21-5A2-2A-A25-A2-3A29-3A2(28-A2-A)28-A-D29-A-A29-A-V2(29-A-O)29-A-A29-A-P23-3A4-2A22-A-A5-AD21-A2-A5-3A20-A-D7-A-A18-A2-D7-A2-A16-A2-M9-A2-2A12-2A2-R11-A3-2A8-2A3-Af13-2A3-8A3-BnI16-TN9-KJW20-2GCAvCJ2AwAx38-4A28-A3-A25-3A4-A26-2A3-B27-A4-Am26-A4-K27-A3-H4-3A20-A3-S3-A2-A20-3A-H3-A2-A20-5A3-A-A25-A2-2(2A-A28-)2(3A29-)3A28-A2-A28-A-A29-A-A30-2A30-3A29-3A21-4A4-3A20-A2-A5-3A20-A2-A6-A-A18-A2-P7-A2-A16-A2-P9-A2-A14-A3-M9-A3-2A11-A3-R11-2A3-2A6-3A2-2At14-2A3-6A4-C18-2DY6-FBo2F22-VBpBq2CBr40-2A27-3A2-A23-5A4-A25-2A4-AB25-2A4-B26-A4-Z26-3A2-Z5-4A18-A3-Ab5-A2-A18-A3-Ao4-A2-A19-5A4-A2-A23-A4-A3(-A28-2A)-A28-6(3A29-)2A-A19-4A5-2A-A19-A2-A6-A-A18-A2-A7-A2-A16-A2-A9-A-A16-A2-N9-A2-2A12-2A2-M11-A3-2A9-A3-U13-2A3-9A3-X16-2A11-AcBm19-2ALAs2Aa4BO69-A28-5A24-3A5-A20-6A5-A15-12A5-A11-3A9-4A4-A8-4A12-3A4-A7-A2-2A13-3A4-Ab5-A3-A15-2A2-2AW5-A2-A16-7A5-A2-A21-2A4-3(A2-A28-)A4(-A28-2A)2(-A29-A)-A19-3A7-A-A18-5A6-A2-A17-A2-A7-A2-A16-A2-A9-A2-A15-A2-A9-A2-A14-A2-A11-A2-2A11-A2-A13-A2(3-4A)3-A14-2A5-3A5-ApAs17-2A8-2VG21-ALAeU2AjVO100-3A26-3A2-3A20-5A6-A16-9A6-2A12-13A6-A9-7A5-5A5-2A7-A4-2A7-5A5-A7-A3-2A9-4A5-Bc7-A2-2A12-2A2-4A6-A3-A15-3A2-A6-A2-A21-A6-A2-A27-7(A2-A28-)A2-A17-3A8-A2-A16-5A8-A2-A15-A3-A8-A2-A14-A3-A9-A3-A13-A2-A11-A2-2A11-A3-A12-A3-3A5-3A3-A14-A5-5A5-A16-2A11-TR19-3ALAoAeYUR2Y159-5A23-4A4-3A17-5A8-2A14-4A-2A10-2A11-2A4-5A9-A10-2A4-7A8-2A9-A4-9A7-2A9-A3-12A3-A-2A8-A3-3A6-6A-4A8-A2-2A11-8A7-A3-A16-A10-A2-2A27-5(A2-A28-)A2-A15-A12-A2-A15-3A10-A2-2A13-A3-A10-A2-A13-2A2-A10-A2-2A11-A3-A11-2A2-3A8-2A2-A13-A3-11A3-A14-2A4-5A5-A16-2A11-2A19-3A5-3A24-AL2MAq162-2A26-8A20-4A5-4A16-4A10-3A15-2A14-2A13-2A15-2A12-2A16-2A12-A17-2A11-A5-6A7-3A10-A3-14A2-2A9-2A2-17A11-A3-12A3-A12-4(A2-13A16-)A2-14A15-A2-15A14-2A-18A11-2A2-13A3-A12-A2-13A3-A12-2A2-11A2-2A14-2A3-8A2-2A15-3A11-3A17-2A9-BBjA19-11A24-5A252-7A24-10A20-6A-7A17-3A9-3A16-Bb2A10-3A15-HBBd12-3A13-2XC14-2A13-2I15-2A13-I11-7A12-AD5-12A13-2A3-12A15-2A3-11A2(16-2A2-12A)16-2A2-13A15-2A3-14A14-2A2-9A-A-2A14-2A3-8A3-2A14-3A4-5A4-2A15-3A10-2A18-4A6-3A20-5ABHBi3A22-2ALHEL2BC379-5A25-9A22-10A21-12A19-2B3A5-4A17-CTBA8-3A16-2TAgN10-2A16-BeAbBf8-5A16-3A7-6A16-3A7-5A17-3A6-6A17-3A5-3A2(-A)17-3A5-2A3-2A17-4A9-3A17-3A8-3A18-4A7-3A19-4A4-5A20-10A24-6A572-5A25-8A23-10A5(21-11A)21-10A23-9A23-8A25-7A26-4A303-
