model
size = 20 33 14, scale = 0.05, origin = -y
material 
  colors = A:#369 B:#111 C:#3CF D:#09C E:#EEE F:#A00 G:#09F
voxels
484-3(4D4-4D8-)4D4-2D2F568-4D4-4D7-3(D4AD2-D4AD6-)D4AD2-D4AD53-D19-D453-4A4-4A7-6A2-6A5-16A4-3A2-6A2-3A4-2A4-4A4-2A4-3A2-6A2-3A2(4-16A)5-14A6-D-10AD7-D6-D4-D428-4A4-4A7-6A2-6A5-3A2-6A2-3A3-3A4-4A4-3A4(2-2A14-2A)2-3A12-3A3-4A8-4A4-16A5-D14B25-6C2-6C6-6C2-6C288-A8-A9-3A6-3A8-3A6-3A7-2(4A6-)6A2-6A5-3A2-6A2-3A3-3A5-2A5-3A2-2A14-2A-2A2(16-4A)16-2A-A16-A2(2-2A14-2A)3-16AD3-2B-12B2D23-2C3A2C2-2C3A2C4-C5AC2-C5AC5-6A2-6A12(6-5A4-5A)6-6A2-6A5-7A2-7A3(4-3A-3A2-3A-3A)4-2A2(2-3A)2-2A3-3A4-4A4-3A2-2A14-2A-2A16-4A16-3A18-3A2(16-4A)16-2A-2A14-2A2-5A8-5A2-18B22-2(C6AC2-)C3A-2AC2-C2A-3AC2(3-2A)13(2-2A3-2A4-2A3-2A)2-2A3-2(2A4-)A2-A4-2A2(4-A5-A2-A5-A)3-2(2A5-A2-A5-2A2-)2(2A6-)2A2-A16-A-2A16-3A3(18-2A)18-3A16-2A-A16-A2-2A14-2A2-18B22-2(C6AC2-)CA5-C2-C5-AC3-3(A5-A2-A5-A4-)A5-A2-A5-A3-2A5-A2-A5-2A3-A5-A2-A5-A3-2A5-A2-A5-2A2-2A5-A2-A5-2A3-4(A5-A2-A5-A4-)A5-A2-A5-A3-2(2A5-A2-A5-2A2-)3(2A14-2A2-)2(A7-2A7-A2-)A16-A-2A16-3A3(18-2A)18-3A16-2A-A16-A-2D2A12-3A-2D17B21-2C6AC2-C6A3C2A5-C2-C5-2AC-14(2A14-2A2-)5(A16-A2-)A7-2A7-A2-A16-A-2A16-4A16-3A18-2A18-3A16-4A16-2A-A16-A2-3A12-3A2-18B21-2C6AC2-C6A3C2A5-C2-C5-2AC-9(2A5-A2-A5-2A2-)2A14-4(2A2-2A5-A2-A5-)2A2-2A14-2A4(2-A16-A)2(2-A7-2A7-A)2-A16-A-2A3(16-4A)16-2A-A16-A2-2A14-2A2-3A12-3A2-18B22-2(C6AC2-)C2A3-AC2-CA3-2AC3-13(A5-A2-A5-A4-)A5-A2-A5-A3-6(2A5-A2-A5-2A2-)2A5-4A5-7(2A2-2A14-)2A3-4A8-4AD3-16BD22-C6AC2-8C2-C6AC2-8C2(3-2A)3(2-2A3-2A4-2A3-2A)2-2A3-2A5(4-3A2(2-2A)2-3A)4-2A3-2A2-2A3-2A4-3A2(2-2A)2-2(3A4-3A-3A2-3A-)3A7(4-2A3-2A2-2A3-2A)4-2A4-4A2(4-2A)3(12-2A4-2A)12-2A4-DA12-AD2(4-2A12-2A)4-D15A4-D15B24-2C4AC2-7C4-2C4AC2-7C6-12(4A4-4A8-)4A4-4A7-5(5A4-5A6-)5A4-D4A6-6A2-6A5(6-14A)6-13AG3(6-14A)6-3BD6BD3B10-5E12-4C4-4C8-4C4-4C390-3D2-D2A13-D-2D-D13-D2-DA2-D15-2(DA18-)DA12-D5-DA5-D7-D4-DA4-D9-D3-DA3-D11-D5E-D12-DE3-E-D13-5E8-
