model
size = 22 15 32, scale = 0.05, origin = -y
material 
  colors = A:#FFF B:#111 C:#777
voxels
6-10B319-12B12-8B297-14B10-10B295-16B8-12B294-16B7-14B292-18B6-14B292-18B5-16B290-20B4-16B33-2C19-C2-C18-2(C21-)C2-C19-2C145-20B3-18B32-2C2-B16-C2-CB-B15-2(C2-B3-B14-)C2-C3-B15-2CB3-B140-B18AB3-2(18A4-)18A5-16A6-16A7-14A9-12A11-10A13-8A118-3(20A2-)20A3-18A5-16A6-16A7-14A9-12A11-10A14-6A97-4(20A2-)20A3-2(18A4-)18A5-16A8-12A11-10A15-4A75-110A-20A2-20A3-18A4-18A5-16A8-12A12-8A73-132A-20A2-20A3-18A5-16A7-14A9-12A13-6A52-154A-20A2-20A3-18A5-16A7-14A10-10A50-176A-20A2-20A3-18A6-14A9-12A13-6A30-198A-20A3-18A5-16A8-12A12-8A29-220A-20A4-16A7-2(14A10-10A28-220A-20A3-18A6-)2(14A10-10A16-2B10-220A-20A3-18A6-)14A10-10A28-220A-20A4-16A7-14A10-10A28-198A-20A3-18A5-16A8-12A12-8A29-176A-20A2-20A3-18A6-14A9-12A13-6A30-154A-20A2-20A3-18A5-16A7-14A10-10A50-132A-20A2-20A3-18A5-16A7-14A9-12A13-6A52-110A-20A2-20A3-18A4-18A5-16A8-12A12-8A74-4(20A2-)20A3-2(18A4-)18A5-16A8-12A11-10A15-4A77-3(18A4-)18A5-2(16A6-)16A7-14A9-12A11-10A14-6A99-3(16A6-)16A7-14A8-14A9-12A11-10A13-8A16-4A123-2(14A8-)14A9-12A10-12A11-10A13-8A15-6A162-
