model
size = 18 24 10, scale = 0.05, origin = -y
material 
  colors = A:#EEE B:#111 C:#700 D:#0CF E:#009 F:#00B G:#00A
voxels
------------------ ------------------ ------------------ ------------------ ------------------ ------------------ ------------------ ------------------ ------------------ ------------------ --------AA-------- --------AA-------- ------------------ ------------------ ----B-B----B-B---- ------------------ ------------------ ------------------ ------------------ ------------------ ------------------ ------------------ ------------------ ------------------ 
--------AA-------- --------AA-------- ------------------ ------------------ -------CCCC------- ------------------ ------CCCCCC------ -------CAAC------- ------------------ ------------------ --------AA-------- --------AA-------- --------AA-------- --------AA-------- --B-B-B----B-B-B-- ------------------ ------BB--BB------ ------------------ ------------------ ------------------ ------------------ ------------------ ------------------ ------------------ 
-------AAAA------- --------AA-------- --------AA-------- -------CCCC------- ------CCCCCC------ -----C------C----- -----CCCCCCCC----- -------CAAC------- --------AA-------- --------BB-------- ------BAAAAB------ -------AAAA------- --------AA-------- ----DF--AA--DG---- --B-B-B-AA-B-B-B-- --------AA-------- -----BAA--AAB----- -------B--B------- ------------------ ------------------ ------------------ ------------------ ------------------ ------------------ 
------AAAAAA------ -------AAAA------- --------AA-------- -------AAAA------- -----ACCCCCCA----- -----A------A----- -----ACCCCCCA----- ----A--AAAA--A---- ---AA-AAAAAA-AA--- ---AAABBAABBAAA--- ---AAAAAAAAAAAA--- -----AAAAAAAA----- --BBBBBAAAABBBBB-- ---ADEABAABAEDA--- --BBBBBAAAABBBBB-- --------AA-------- --BBBAAAAAAAABBB-- -------A--A------- -------A--A------- ------------------ ------------------ ------------------ ------------------ ------------------ 
------AAAAAA------ ------AAAAAA------ -------AAAA------- -------AAAA------- -----AAAAAAAA----- ----AABBBBBBAA---- ----AAAAAAAAAA---- ---AAAAAAAAAAAA--- ---AAAAAAAAAAAA--- --AAAAAAAAAAAAAA-- --AAAAAAAAAAAAAA-- --AAAAAAAAAAAAAA-- --AAAAAAAAAAAAAA-- ---AAAAAAAAAAAA--- --BAAAAAAAAAAAAB-- ----AAAAAAAAAA---- -AAAAAAAAAAAAAAAA- -------AAAA------- -------A--A------- ------------------ ------------------ ------------------ ------------------ ------------------ 
-----AAAAAAAA----- ----A-AAAAAA-A---- ------AAAAAA------ -----AAAAAAAA----- ---AAAAAAAAAAAA--- --AAAAAAAAAAAAAA-- --AAAAAAAAAAAAAA-- -AAAAAAAAAAAAAAAA- -AAAAAAAAAAAAAAAA- -AAAAAAAAAAAAAAAA- AAAAAAAAAAAAAAAAAA AAAAAAAAAAAAAAAAAA -AAAAAAAAAAAAAAAA- -ABAAAAAAAAAAAABA- -AAAAAAAAAAAAAAAA- -AAAAAAAAAAAAAAAA- -AAAAAAAAAAAAAAAA- ---AAAAAAAAAAAA--- -----AAAAAAAA----- --------AA-------- ------------------ ------------------ ------------------ ------------------ 
-----AAAAAAAA----- ----AAAAAAAAAA---- ----AAAAAAAAAA---- --AAAAAAAAAAAAAA-- -AAAAAAAAAAAAAAAA- -AAAAAAAAAAAAAAAA- AAAAAAAAAAAAAAAAAA AAAAAAAAAAAAAAAAAA AAAAAAAAAAAAAAAAAA AAAAAAAAAAAAAAAAAA AAAAAAAAAAAAAAAAAA AAAAAAAAAAAAAAAAAA AAAAAAAAAAAAAAAAAA AAAAAAAAAAAAAAAAAA AAAAAAAAAAAAAAAAAA AAAAAAAAAAAAAAAAAA -AAAAAAAAAAAAAAAA- -AAAAAAAAAAAAAAAA- --AAAAAAAAAAAAAA-- ----AAAAAAAAAA---- ------AAAAAA------ ------------------ ------------------ ------------------ 
-----AAAAAAAA----- ---AAAAAAAAAAAA--- --AAAAAAAAAAAAAA-- -AAAAAAAAAAAAAAAA- AAAAAAAAAAAAAAAAAA AAAAAAAAAAAAAAAAAA AAAAAAAAAAAAAAAAAA AAAAAAAAAAAAAAAAAA AAAAAAAAAAAAAAAAAA AAAAAAAAAAAAAAAAAA AAAAAAAAAAAAAAAAAA AAAAAAAAAAAAAAAAAA AAAAAAAAAAAAAAAAAA AAAAAAAAAAAAAAAAAA AAAAAAAAAAAAAAAAAA AAAAAAAAAAAAAAAAAA AAAAAAAAAAAAAAAAAA AAAAAAAAAAAAAAAAAA -AAAAAAAAAAAAAAAA- --AAAAAAAAAAAAAA-- ---AAAAAAAAAAAA--- -----AAAAAAAA----- ------------------ ------------------ 
------------------ ------------------ ------------------ ------------------ ------------------ ------------------ ------------------ ------------------ ------------------ ------------------ ------------------ ------------------ AAAAAAAAAAAAAAAAAA AAAAAAAAAAAAAAAAAA AAAAAAAAAAAAAAAAAA AAAAAAAAAAAAAAAAAA AAAAAAAAAAAAAAAAAA AAAAAAAAAAAAAAAAAA AAAAAAAAAAAAAAAAAA AAAAAAAAAAAAAAAAAA --AAAAAAAAAAAAAA-- ---AAAAAAAAAAAA--- -----AAAAAAAA----- ------------------ 
------------------ ------------------ ------------------ ------------------ ------------------ ------------------ ------------------ ------------------ ------------------ ------------------ ------------------ ------------------ ------------------ ------------------ ------------------ ------------------ ------------------ AA--------------AA AA--------------AA AA--------------AA AA--------------AA --AAAA------AAAA-- ---AAA------AAA--- ------AAAAAA------ 
