model
size = 32 32 30, scale = 0.05, origin = -y
material 
  colors = A:#AE9F73 B:#3A1D00 C:#454C53 D:#847F67 E:#920000 F:#600 G:#630 H:#E2D5A4 I:#FDDB00 J:#9B8600 K:#9CF
voxels
3-3(FEFACDCA2(FE)2F2(EF)ACDCAFEF6-EFEADCDA2(EF)2E2(FE)ADCDAEFE6-)3AH4AH8AH4AH3A6-DCDA2(DC)ACDC2DCDCA2(CD)ADCD6-2(CD)2(ADCD)2C2(DCDA)2(DC)6-2(DC)2(ACDC)2D2(CDCA)2(CD)6-4AH3AH8AH3AH4A6-2(FE)ADCDAEFE2FEFEADCDA2(EF)7-FEFACDCAFEF2EFEFACDCAFEF8-EFEADCDAEFE2FEFEADCDAEFE8-FEFACDCAFEF2EFEFACDCAFEF9-FEFACDAEFE2FEFEADCAFEF11-FEADCAFEF2EFEFACDAEF13-FACDAEFE2FEFEADCAF15-ADCAFEF2EFEFACDA19-H8AH23-CDC2DCDC366-6(A26-A4-)H4-A16-A4-H3(4-A26-A)4-H26-H4-A26-A4-AE24-EA4-AF24-FA4-AE24-EA5-FE22-EF6-EFE20-EFE7-EFE18-EFE9-EFE16-EFE12-AH2A10-2AHA15-ACDA8-ADCA17-DCADCD2CDCDACD20-H8AH300-3(D28-D2-C28-C2-)A28-A2-D28-D2-C28-C2-D28-D2-A28-A2-D28-D3-C26-C4-D26-D4-C26-C2(4-A26-A)4-AF24-FA5-EF22-FE7-3A18-3A10-DC16-CD12-CDA13-2ADC13-AH2A10-2AHA16-CDAFEF2EFEFADC20-DAFE2FEFAD88-2I2(JI)25-IJ4-JI24-I6-I24-IJ4-JI25-6I14-3(C28-C2-D28-D2-)2(A28-A2-C28-C2-D28-D2-C28-C2-)D28-D3-C26-C4-D26-D2(4-A26-A)5-H24-H6-ADC20-CDA7-CD20-DC9-2A18-2A10-FEFA14-AFEF11-FEADC10-CDAEF14-EADCA6EACDAE48-GBG10BGBG16-BG2BK2BIJ2BK3BG16-3G4BIJ5B2G16-GBG4BJI4BGBG16-B3G2B2G3B2(GB)G9-3(D28-D2-C28-C2-)2(A28-A2-D28-D2-C28-C2-D28-D2-)C28-C2-D28-D2-C28-C3-D26-D4-C26-C5-A24-A6-D24-D6-A24-A7-H22-H8-A22-A9-E20-E11-2EF14-F2E13-2EA3CA4EA3CA2E14-18B14-17BG14-G16BG14-18B14-G4BG5BG2B2GBG7-3(C30-CD30-D)2(A30-AC30-CD30-DC30-C)-D28-D2-C28-C2-D28-D2-C28-C3-D26-D4-A26-A5-C24-C6-D24-D7-A22-A8-C22-C8-A22-A9-A20-A11-A18-A12-G4B10-4BG2(12-5B10-5B)12-5B10-4BG12-BG3B10-4BG6-A5(30-2A)2(30-AH30-HA2(30-2A))30-AC30-CD30-D-C28-C2-D28-D2-C28-C3-A26-A4-D26-D5-C24-C6-A24-A7-C22-C8-C22-C9-2(C20-C10-)2(4B14-4B10-)G3B14-3BG10-G3B14-4B10-4B14-2BGB5-3(E30-EF30-F)A30-AD30-DC30-CD30-DA30-AE30-EF30-2F30-FA2(30-2A)30-A-A31-A28-A3-H26-H2(4-A26-A)5-A24-A6-C24-C7-C22-C8-D22-D8-C22-C2(8-G2B18-2BG)2(8-3B18-3B)8-G2B18-2BG4-3(F30-FE30-E)A30-AC30-CD30-DC30-CA30-A3(F30-FE30-E)F30-F-E28-E2-A28-A2-DF26-FD4-A24-A5-H26-H5-A24-A6-A24-A7-A22-A8-A22-A7-3B20-2BG6-G2B2(20-2BG6-3B)20-2BG6-2BG20-2GB3-3(E30-EF30-F)A30-AD30-DC30-CD30-DA30-A3(E30-EF30-F)E30-E-F28-F2-A28-A2-C28-C3-D26-D4-A26-A5-E24-E6-F24-F7-E22-E8-E22-E7-2(2B22-2B6-)GB22-2B6-BG22-2B6-2G22-2G3-3(F30-FE30-E)A30-AC30-CD30-DC30-CA30-A3(F30-FE30-E)F30-F-E28-E2-A28-A2-D28-D3-C26-C4-A26-A5-F24-F6-E24-E7-E22-E8-E22-E7-GB22-BG6-2B2(22-BG6-GB)22-2B6-GB22-BG3-3(E30-EF30-F)A30-AD30-DC30-CD30-DA30-A3(E30-EF30-F)E30-E-F28-F2-A28-A2-C28-C3-D26-D4-A26-A5-E24-E6-F24-F7-E22-E8-E22-E7-2(2B22-2B6-)2B22-BG6-2B22-2B6-BG22-2B3-A5(30-2A)2(30-AH30-HA2(30-2A))2(30-2A)2-A27-AF30-2F30-F-E-A26-E2-A28-A2-D28-D3-C26-C4-A26-A5-F24-F6-E24-E7-E22-E8-E22-E7-GB22-BG6-2B22-2B6-GB22-2B6-2B22-2B6-2G22-BG3-3(D30-DC30-C)A30-AC30-CD30-DC30-CA30-A2(D30-DC30-C)D30-DA30-2A30-A-A28-A2-H28-H2-A28-A3-A26-A4-H26-H5-A24-A6-A24-A7-A22-A8-A22-A7-3(2B22-2B6-)2B22-BG6-GB22-BG3-3(C30-CD30-D)A30-AD30-DC30-CD30-DA30-A3(C30-CD30-D)C30-C-D28-D2-A28-A2-C28-C3-D26-D4-A26-A5-C24-C6-D24-D7-C22-C8-C22-C7-GB22-BG6-2B22-BG6-GB22-BG6-2B22-2B6-2G22-BG3-3(C30-CD30-D)A30-AD30-DC30-CD30-DA30-A3(C30-CD30-D)C30-C-D28-D2-A28-A2-C28-C3-D26-D4-A26-A5-C24-C6-D24-D7-C22-C8-C22-C7-GB22-BG4(6-2B22-2B)3-3(D30-DC30-C)A30-AC30-CD30-DC30-CA30-A2(D30-DC30-C)D2-A27-DA2-A27-2A30-A-A28-A2-H28-H2-A28-A3-A26-A4-H26-H5-A24-A6-A24-A7-A22-A8-A22-A7-2(2B22-2B6-)GB22-2B2(6-GB22-BG)3-A5(30-2A)2(30-AH30-HA2(30-2A))2(30-2A)30-AF30-2F30-F-E28-E2-A28-A2-D28-D3-C26-C4-A26-A5-F24-F6-E24-E7-E22-E8-E22-E7-GB22-BG6-2B22-2B6-GB22-2B6-2B22-2B6-GB22-2G3-3(E30-EF30-F)A30-AD30-DC30-CD30-DA30-A2(E30-EF30-F)E2-A27-EF30-FE30-E-F28-F2-A28-A2-C28-C3-D26-D4-A26-A5-E24-E6-F24-F7-E22-E8-E22-E7-2B22-2B6-GB2(22-BG6-2B)22-2B6-2B22-2G3-3(F30-FE30-E)A30-AC30-CD30-DC30-CA30-A3(F30-FE30-E)F30-F-E28-E2-A28-A2-D28-D3-C26-C4-A26-A5-F24-F6-E24-E7-E22-E8-E22-E7-2(GB22-BG6-2B22-2B6-)2G22-BG3-3(E30-EF30-F)A30-AD30-DC30-CD30-DA30-A3(E30-EF30-F)E30-E-F28-F2-A28-A2-C28-C3-D26-D4-A26-A5-E24-E6-F24-F7-E22-E8-E22-E7-2(2B22-2B6-)2B22-BG6-2B22-2B6-2G22-2G3-3(F30-FE30-E)A30-AC30-CD30-DC30-CA30-A3(F30-FE30-E)F30-F-E28-E2-A28-A2-DF26-FD3-D26-D4-H26-H5-A24-A6-A24-A7-A22-A8-A22-A7-3B20-3B6-G2B2(20-3B6-3B)20-3B6-BGB20-G2B3-3(E30-EF30-F)A30-AD30-DC30-CD30-DA30-AE30-EF30-2F30-FA2(30-2A)30-A-2(A28-A2-)H28-H3-A26-A4-A26-A5-A24-A6-C24-C6-DC22-CD7-D22-D8-C22-C8-G2B18-2BG3(8-3B18-3B)8-2GB18-B2G4-A5(30-2A)2(30-AH30-HA2(30-2A))30-AC30-CD30-D-C28-C2-D28-D2-C28-C2-A28-A3-D26-D5-C24-C6-A24-A6-DC22-CD7-C22-C9-2(C20-C10-)4B14-4B10-G3B14-4B10-4B2(14-3BG10-G3B)14-2BGB5-3(C30-CD30-D)2(A30-AC30-CD30-DC30-C)-2(D28-D2-C28-C2-)2D26-2D3-A26-A4-2C24-2C5-D24-D7-A22-A8-C22-C8-A22-A9-A20-A11-A18-A12-G4B10-4BG2(12-5B10-5B)12-G4B10-4BG12-G4B10-3BGB7-3(D28-D2-C28-C2-)2(A28-A2-D28-D2-C28-C2-D28-D2-)C28-C2-D28-D2-C28-C2-2D26-2D3-C26-C4-A26-A5-D24-D6-A24-A7-H22-H8-A22-A9-F20-F11-3E14-3E13-2EA3CA4EA3CA2E2(14-18B)14-17BG14-18B14-B2G2BG4B2(GB)2G2B8-3(C28-C2-D28-D2-)2(A28-A2-C28-C2-D28-D2-C28-C2-)D28-D2-2C26-2C3-D26-D2(4-A26-A)4-H26-H5-ADC20-CDA7-CD20-DC9-2A18-2A10-EFEA14-AEFE11-EFADC10-CDAFE15-ADCA6EACDA49-GBG10BGBG16-2B2(G3B)2G4B16-BG3BG2B2G4B2G16-G2B2(GBG3B)G16-2BG2(B2G)4BG2B9-3(D28-D2-C28-C2-)A28-A2-D28-D2-C28-C2-D28-D2-A28-A2-D28-D2-2C26-2C2-2D26-2D3-C26-C2(4-A26-A)4-AF24-FA5-EF22-FE6-4A18-4A7-2(DC)16-2(CD)10-CDA14-ADC13-AH2A10-2AHA16-CDAFEF2EFEFADC20-DAFE2FEFAD237-6(A26-A4-)H4-A16-A4-H3(4-A26-A)4-H26-H4-A26-A4-AE24-EA4-AF24-FA4-AE24-EA5-FE22-EF6-EFE20-EFE7-EFE18-EFE9-EFE16-EFE12-AH2A10-2AHA15-ACDA8-ADCA17-DCADCD2CDCDACD20-H8AH302-3(FEFACDCA2(FE)2F2(EF)ACDCAFEF6-EFEADCDA2(EF)2E2(FE)ADCDAEFE6-)3AH4AH8AH4AH3A6-DCD2ACDCACDC2DCDCA2(CD)ADCD6-2(CD)2(ADCD)2C2(DCDA)2(DC)6-2(DC)2(ACDC)2D2(CDCA)2(CD)6-4AH3AH8AH3AH4A6-2(FE)ADCDAEFE2FEFEADCDA2(EF)7-FEFACDCAFEF2EFEFACDCAFEF8-EFEADCDAEFE2FEFEADCDAEFE8-FEFACDCAFEF2EFEFACDCAFEF9-FEFACDAEFE2FEFEADCAFEF11-FEADCAFEF2EFEFACDAEF13-FACDAEFE2FEFEADCAF15-ADCAFEF2EFEFACDA19-H8AH23-CDC2DCDC364-
