model
size = 17 32 19, scale = 0.05, origin = -y
material 
  colors = A:#69C B:#C33 C:#630 D:#FC6 E:#699 F:#F93 G:#F99 H:#39C I:#C36 J:#F9C K:#FC3 L:#C63 M:#C96 N:#FC9 O:#399 P:#660 Q:#C66
voxels
5-HG15-AD15-BC-2A12-FA2-2A11-BA2-2A12-G2-3A14-EA15-A419-5AEA9-6ACA9-B7AB8-F3AB2A2F8-B3AE3AB8-A-7A8-A-AD5A10-BAH3A2B9-FAB2AFA11-C3AQA11-G2ACA13-3A350-G9AG6-D9A2D5-C9A2C5-12A5-11A6-GE7AG7-D8A2D6-2A-6A-A6-2A-8A6-CAB4AC-C7-G2A-3A2GA8-DHM3A2D10-DAB4A12-B2A188-D11-C3ABCAC9-AB2AFAB2A7-BAB2ADAEA9-G4ANAG10-2ACA2D12-2ABC24-2A7-4A4-2A7-5A3-BA7-3AB4-FB7-3AF4-2B7-3AB4-2A7-5A3-2A7-4A4-B-A6-3AB4-BA-A6-2AB4-2A-A5-4A5-A-2A4-A-A6-A2-A3-4A6-BAD4AB-B9-FAB2A2B11-C4A167-AC-2A10-C2A-5A8-3A3-2AB7-B-A5-AB8-G6-A9-DA2-A-2A10-H5A12-2AFB6-E2A10-2A2-C2A4(10-2A2-3A)2(10-2A3-2A)10-2A3-A-A8-A-A3-A-A8-2A4-A-A7-3A4-2A-A6-3A2(5-A-A)6-2A-2A2-A-A9-AC3A-A11-G2ACG12-C3A14-BA100-3A13-DA2-4A8-EC8A7-FAB5-2A8-A6-2A8-GA5-A9-EA4-2A10-3A-AP12-2AFA6-2A11-A3-2A11-2A2-2A11-AC2-3A10-2A2-3A10-2(A-)E2A10-A-E-3A10-3(A-)A10-A-A2-2A10-2A2(3-2A9-A-A)3-A-A8-2A4-3A7-3A2(5-A-A)6-2E-A3-A-E9-5A-A10-B3A-A11-D5A11-ICE2A12-AD2AC11-EAJ2AC11-ABHB3A10-ADAB3A10-ABC3ABA8-2E6A-E7-5A-3A-A6-5A4-2A7-ABA5-2A8-A-A4-2A9-DA3-2A11-2A2-2A12-2AFA6-H12-H3-2A11-2A2-BA11-AB2-F2A10-AF2-B2A10-A-B-2(3A10-2(A-))B2A10-A-B-F2A10-A-F-B-A10-AB2-A-A10-2A3-HA9-A-H3-DA9-AD4-F2A7-2AF2(5-A-A)7-2A4-A-A7-B2A3-A2B9-DA3-AD10-IA3-AI10-2A3-2A9-2A4-2A9-BA4-AB9-DA4-A-D8-BA5-AB8-A7-2A7-E7-AE7-FA7-F8-BA6-B9-2A5-A10-2A4-A11-A3-B13-C10-G11-AG3-D11-AD3-C11-2AC2-2A10-3A2-2A10-2(A-)G2A10-A-GD-2A10-A-D-2(3A10-2(A-))C2A10-A-C-G2A10-AG2-M-A10-AM3-2A9-2A4-A-A8-2A5-C-A6-AC6-G2A5-AG7-C2A4-AC8-2A5-A9-CA5-C9-DA5-D9-J6-J8-HA6-AH7-2A6-2A7-CA7-C7-DA7-AD7-C8-C7-2A7-A8-2A6-A73-2A12-AC3A12-AF3A11-3A2B2A10-2ABEAE11-2AE4A10-3A-3A10-3AH3A10-A-HB3A10-2AB4A10-3A-3A10-2(A-)3A10-2A2-B2A10-AB3-BA9-AB4-3A7-2(2A6-)2A7-2A5-2A8-BA5-AB8-EA5-AE8-A6-2A7-2A6-2A2(7-BA6-AB)7-2A7-A2(7-2A)7-A8-2(A7-B)8-B81-2A12-2A-2A12-5A11-7A4(10-3A-3A)3(10-7A)10-3A-3A10-2A2-3A10-2A3-2A9-2A4-2A8-2A6-A8-A7-A6-A-A7-A6-2A8-A5(6-2A7-2A)7-A2(7-2A)7-A8-A7-2A7-A8-A81-2A12-2A-C13-AF-2A11-3(7A10-)2AE-E2A10-2AE4A10-A-5A10-7A10-3A-C2A10-2AC-3A10-2A2-3A10-2A3-2A9-2A5-2A7-2A6-CA6-AC7-2A5-A-A7-2(2A5-2A8-)C6-AC7-CA6-AC2(7-2A6-2A)7-2A7-A7-CA7-AC7-A8-A7-2A7-A8-A82-E11-AE3-A11-2A3-B11-2AB2-F11-2AF2-B11-A-B-3A10-A2(-2A)10-2(A-)L2A10-A-L-F2A10-A-F-B2A10-A-B-3A10-2A2-A-A10-2A3-DA9-AD4-F-A8-AF5-E-A6-AE6-3A5-2A7-B2A4-AB8-DA5-D9-BA5-B9-2A5-A9-A6-A8-BA6-AB7-DA6-AD7-BA7-B8-A7-2A7-B8-B7-FA7-F8-DA6-D74-C11-C4-D11-AD3-C11-AC3-2A10-3A2-2A10-2(A-)G2A10-A-G-D2A10-A-D-2(3A10-2(A-))C-A10-AC2-2GA10-AG3-CA9-A-C3-2A9-2A4-3A7-3A5-CEA5-A-C7-2A4-A-G7-CAB3-A-C9-ADA-3A10-CICE2AC10-DAD2ACD9-G2AJ2ACG9-2ABHB3A9-2ADAB2A-A8-CABC3-AC8-DEA5-AD7-CA6-AC7-2A7-A8-AB6-A9-2A5-N10-2A4-D11-C3-C13-A9-A12-A3-A12-2A2-B12-2A2-F2A10-2AB-B2A2(10-2(A-)3A)10-3(A-)A10-A-A2-BA10-AB2(3-2A9-A-A)3-A-A8-2A4-L2A7-2AL5-3A5-A-A6-4A3-A-A9-AC3A-A10-BC4A11-DABHAB11-ICE2AC11-AD2AC11-2AJ2AC11-OBHB2AO10-BDAB2AB10-ABC5A8-AE6A-A7-A2(-3A)-A6-B-3A4-AB7-E2B5-AE8-A-A4-2A9-EA3-2A11-2A2-2A12-2AFB6-3(A12-2A2-)2(3A10-2A2-)3A2(10-2A3-2A)10-2A3-A-A8-A-A3-A-A8-2A4-A-A7-3A4-2A-A6-3A5-A-A5-A-B6-2AF2A2-A-B9-A-5A11-G2ACA12-C3A14-BH99-C3A13-DA2-3A9-EC-7A7-F2A5-2A8-A6-2A8-GA5-A9-DA4-2A10-3A-AP12-2AFA7-2A7-5A3-2C7-4AC3-2H7-ABAH4-2A7-AF2A4-2A7-AB2A4-2C7-3A2C3-2C7-3AC4-A-A6-4A4-2A-A6-3A4-EA-A5-2A2E5-C-2A4-C-C6-E2-A3-2(AE)6-2A-5A-A9-F6A11-C3AC167-ACA2C10-C2A2-A-AE8-3A3-3A7-B-A5-2A8-G6-A9-DA2-A-AC10-H5A13-AFA8-2(12A5-)B7ABA2B5-F7AFA2F5-B7ABAB6-AE8A7-11A6-K8A-K6-FA-4AFABF6-BAB4AB-B7-3A-6A8-AHM5A10-DAB2A2D13-2A188-A12-3ABCAB9-AB2AFABAF7-BAB2ADAED9-G4AN2A10-2ACADA12-2A2B25-C6AC9-D5ACD9-C7AC8-4AB4A8-4AE4A8-G-6AG8-K-AD4AK10-BAH5A9-FAB4A11-C3A2C11-G2ACG13-3A352-HG15-AD15-BC-2A12-FA2-AE11-BA2-2A12-G2-3A14-E2A14-A415-
