model
size = 12 11 9, scale = 0.05, origin = -y
material 
  colors = A:#96C B:#93F C:#DDD D:#93C E:#888 F:#AAA G:#939 H:#EEE I:#960 J:#F96 K:#777 L:#FCF M:#F3F N:#111 O:#FFF P:#444 Q:#001 R:#555 S:#BBB
voxels
------------ ------------ ------------ -----LL----- ----Q--Q---- ------------ ------------ ------------ ------------ ------------ ------------ 
------------ -----HH----- ---IJJJJI--- ---HHLLHH--- ---CFCCSC--- ---CCCCCH--- ------------ ------------ ------------ ------------ ------------ 
--O------O-- --A------A-- --A------A-- --A------A-- --ACEEEECA-- --BCNN-NCA-- ---DDDDDD--- ------------ ------------ ------------ ------------ 
------------ ------------ --A------A-- ------------ --AC----CA-- ---E----B--- --BB----GA-- ----DDGG---- ------------ ------------ ------------ 
------------ ------------ --A------A-- --A------A-- ---B----B--- --B------A-- --BB----GB-- -KK-DDDG-EE- FMF------FMF FMF------FMF IIR------RII 
------------ --B------A-- --A------A-- ------------ --A------A-- ---A----B--- --AA----GA-- ----BGGG---- ------------ ------------ ------------ 
------------ ------------ --AP----PA-- --B------A-- --B------A-- --B------A-- ---BBBBBB--- ------------ ------------ ------------ ------------ 
------------ ----E--E---- ----K--K---- ---A-BB-A--- ---A----A--- ---AAAAAA--- ------------ ------------ ------------ ------------ ------------ 
------------ ----A--A---- ----A--A---- ----AAAA---- ----AAAA---- ------------ ------------ ------------ ------------ ------------ ------------ 
