model
size = 32 30 3, scale = 0.05, origin = -y
material 
  colors = A:#F9F9F9 B:#FFF C:#000 D:#ACACAC E:#F0F0F0 F:#EAEAEA G:#ABABAB H:#EFEFEF I:#F7F7F7 J:#F4F4F4 K:#ECECEC L:#F2F2F2 M:#EDEDED N:#F5F5F5 O:#A9A9A9 P:#B0B0B0 Q:#FAFAFA R:#E2E2E2 S:#E7E7E7 T:#FEFEFE U:#B1B1B1 V:#AEAEAE W:#BABABA X:#E5E5E5 Y:#9F9F9F Z:#E3E3E3 Aa:#CCC Ab:#E8E8E8 Ac:#FCFCFC Ad:#DBDBDB Ae:#B3B3B3 Af:#C9C9C9 Ag:#D4D4D4 Ah:#D3D3D3 Ai:#A6A6A6 Aj:#CFCFCF Ak:#A7A7A7 Al:#DDD Am:#E0E0E0 An:#DEDEDE Ao:#BBB Ap:#9C9C9C Aq:#BFBFBF Ar:#A1A1A1 As:#9D9D9D At:#D6D6D6 Au:#D1D1D1 Av:#CACACA Aw:#D8D8D8 Ax:#D9D9D9 Ay:#CECECE Az:#A4A4A4 Ba:#C7C7C7 Bb:#BDBDBD Bc:#8D8D8D Bd:#626262 Be:#B8B8B8 Bf:#494949 Bg:#A2A2A2 Bh:#C5C5C5 Bi:#959595 Bj:#8E8E8E Bk:#C2C2C2 Bl:#B5B5B5 Bm:#6D6D6D Bn:#929292 Bo:#898989 Bp:#444 Bq:#838383 Br:#727272 Bs:#6F6F6F Bt:#242424 Bu:#565656 Bv:#363636 Bw:#7B7B7B Bx:#181818 By:#333 Bz:#909090 Ca:#939393 Cb:#C0C0C0 Cc:#B6B6B6 Cd:#888 Ce:#989898 Cf:#C4C4C4 Cg:#797979 Ch:#868686 Ci:#454545 Cj:#545454 Ck:#9A9A9A Cl:#4E4E4E Cm:#6C6C6C Cn:#5D5D5D Co:#030303 Cp:#222 Cq:#313131 Cr:#212121 Cs:#515151 Ct:#1D1D1D Cu:#3D3D3D Cv:#5E5E5E Cw:#121212 Cx:#4C4C4C Cy:#272727 Cz:#303030 Da:#979797 Db:#818181
voxels
10-2DUO4GOU2D18-CaOVAeBbAfAu2AgAjAfAqUVDBi14-BcArDCbAtZKH4EHFRAhAqDArBj11-ApAkAqAlKLJIABkBmCgAgINLHFAdAqAkAs9-YVAjFLNAAcTCh4CPAcQILHSAyDY7-YCcAdMJAT2BR6CTBTANEFAgAeY5-OPAdHJQ4BBn6CAy3BQNEFAgVO3-DGAjMJQ5BBo6CAf4BQNHAbAvGD2-DBbAbLA6BAn6C6BQJMZAoG-AzDAwEIT7BBd4CAs6BTIEFAhGAzOWAbLQ9BPCiCjAa8BQJMRBeOPAaMNAc21BAcNHSAfPDAwHIT21BTIEAbAhDVAnEI10BBpAtBBpCk8BIEFAxVUREI10B2CClCBq8BIEFAlUAeREI10BBi3C8BTIEAbAdUVAnHNT2BKApCmBrP3BQ4BBlBsBdBoAhBAcNHSAxVDAwMJAcACn3CBt2CAa4BKCoCCp3CCqRJMXAuDPAaFLABf3CBfBu2CCr4BCs2CBrBv3CCtHFZBaPOWXHJCu3CBjW2CBuAo2BTCv2CAtBw3CCwFSAlBeOBgDAgFEJAzBxCBv2BMBfAr2BZCxM2BBt2CBqSFZAjGBg-AiAoRKLIQBnCCyBsByCBa3BCByBmBxCBdHEKXAdWAk2-DGAvXKLIQW4C4BCz3CDaNEKXAnBhGD3-AeVAhSKENAAi2CDb4BW2CBzJEKSAmAaDBl5-AkAeAuXFMLNAeBwI3AcQABzApEMFXAnAaPAk7-YDBaAmSFMH2L3JLEHMFSRAdBhGAs9-ApAiWAhAmXAbF4KFAbSXRAlAjWAiAs11-CdYGAoAyAxAmR3ZRAmAlAtAvWGYBc14-CeYPUAoCfAf2AaAfBkWPDArAp18-PDUAiO2GOAiU2D20-2DUO4GOU2D18-CaOVAeBbAfAu2AgAjAfAqUVDBi14-BcArDCbAtZKH4EHFRAhAqDArBj11-ApAkAqAlKLJIABkBmCgAgINLHFAdAqAkAs9-YVAjFLNAAcTCh4CPAcQILHSAyDY7-YCcAdMJAT2BR6CTBTANEFAgAeY5-OPAdHJQ4BBn6CAy3BQNEFAgVO3-DGAjMJQ5BBo6CAf4BQNHAbAvGD2-DBbAbLA6BAn6C6BQJMZAoG-AzDAwEIT7BBd4CAs6BTIEFAhGAzOWAbLQ9BPCiCjAa8BQJMRBeOPAaMNAc21BAcNHSAfPDAwHIT21BTIEAbAhDVAnEI10BBpAtBBpCk8BIEFAxVUREI10B2CClCBq8BIEFAlUAeREI10BBi3C8BTIEAbAdUVAnHNT2BKApCmBrP3BQ4BBlBsBdBoAhBAcNHSAxVDAwMJAcACn3CBt2CAa4BKCoCCp3CCqRJMXAuDPAaFLABf3CBfBu2CCr4BCs2CBrBv3CCtHFZBaPOWXHJCu3CBjW2CBuAo2BTCv2CAtBw3CCwFSAlBeOBgDAgFEJAzBxCBv2BMBfAr2BZCxM2BBt2CBqSFZAjGBg-AiAoRKLIQBnCCyBsByCBa3BCByBmBxCBdHEKXAdWAk2-DGAvXKLIQW4C4BCz3CDaNEKXAnBhGD3-AeVAhSKENAAi2CDb4BW2CBzJEKSAmAaDBl5-AkAeAuXFMLNAeBwI3AcQABzApEMFXAnAaPAk7-YDBaAmSFMH2L3JLEHMFSRAdBhGAs9-ApAiWAhAmXAbF4KFAbSXRAlAjWAiAs11-CdYGAoAyAxAmR3ZRAmAlAtAvWGYBc14-CeYPUAoCfAf2AaAfBkWPDArAp18-PDUAiO2GOAiU2D20-2DUO4GOU2D18-CaOVAeBbAfAu2AgAjAfAqUVDBi14-BcArDCbAtZKH4EHFRAhAqDArBj11-ApAkAqAlKLJI6ANLHFAdAqAkAs9-YVAjFLNAAcT6AAcQILHSAyDY7-YCcAdMJAT9A2(TA)NEFAgAeY5-OPAdHJQ15AQNEFAgVO3-DGAjMJQ17AQNHAbAvGD2-DBbAbL20AQJMZAoG-AzDAwEAT19ATIEFAhGAzOWAbL23AJMRBeOPAaMN23ANHSAfPDAwHI23AIEAbAhDVAnEI23AIEFAxVUREI23AIEFAlUAeREI23AIEAbAdUVAnHN23ANHSAxVDAwMJ23AJMXAuDPAaFL23AHFZBaPOWXHJ21AHFSAlBeOBgDAgFEJ19AHSFZAjGBg-AiAoRKLIQ16AHEKXAdWAk2-DGAvXKLIQ14ANEKXAnBhGD3-AeVAhSKEN13AJEKSAmAaDBl5-AkAeAuXFML7AQ3AEMFXAnAaPAk7-YDBaAmSFMH2L3JLEHMFSRAdBhGAs9-ApAiWAhAmXAbF4KFAbSXRAlAjWAiAs11-CdYGAoAyAxAmR3ZRAmAlAtAvWGYBc14-CeYPUAoCfAf2AaAfBkWPDArAp18-PDUAiO2GOAiU2D10-
