model
size = 32 32 30, scale = 0.05, origin = -y
material 
  colors = A:#252525 B:#3A3A3A C:#5E5E5E D:#535353 E:#AEAEAE F:#D7D7D7 G:#6F6F6F H:#8A8A8A I:#FFF
voxels
11-IFE4-EFI1012-EF10-FE20-FIFE2-EFIF979-2E12-2E18-EF3H2-3HFE22-FIF2EFIF347-EF3(30-2F30-2E)30-2F30-IF30-FI310-E16-E15-H2E4H2-4H2EH19-2EF4HF2E25-4F221-2E30-2E29-EF2E28-E2AE27-2(2E2A2E26-)FE2AEF25-2EF2AF2E24-2FE2AE2F24-2EF2AF2E24-FEF2AFEF24-E2F2A2FE24-FEF2AFEF24-3FI4F27-FI245-2G16-2G13-2H2G4A2-4A2G2H16-2E10A2E20-3E4H3E23-H2E2F2EH123-EH30-HE29-E2AE27-EH2AHE25-EH4AHE23-EHE4AEHE22-HE6AEH2(22-2E6A2E)21-2(2E8A2E20-)EF8AFE20-2E8A2E20-EF8AFE20-FE8AEF20-EI8AIE20-2FIFE2AEFI2F25-2F212-2G18-2G11-3G6A2-6A3G14-7G2A7G17-GH10GHG20-H8GH24-DC2DCD26-2CEH2C26-E2HEHE26-GH2AHG25-GEH2AHEG24-EH4AHE23-GH6AHG21-EH8AHE19-2G10A2G18-GE10AEG18-2H10A2H17-GHE10AEHG16-EH12AHE15-G2H12A2HG2(14-EHE12AEHE)14-HEH12AHEH14-H2E12A2EH14-EHE12AEHE15-EF12AFE17-FEIFEF2EFEFIEF18-E3FE4-E3FE173-DC20-CD9-DC8A2-8ACD12-8G2A8G15-16G17-2G10A2G20-DC6ACD22-CE6AEC22-EC6ACE22-EG6AGE21-2G8A2G20-CE8AEC19-2G10A2G17-EG12AGE16-G14AG15-18C14-GE14AEG14-E16AE13-EG16AGE4(12-G18AG)12-E18AE12-G18AG12-GH16AHG12-BGE5AF2AF5AEGB9-HC2-BG4AF-EF-F4AGB2-CH7-HC2-BGE2F6-2FEGB2-CH9-HC18-CH11-2HC14-C2H74-D22-D9-D9A2-9AD11-D8C2A8CD13-18C15-16C18-C10AC20-E10AE20-G10AG19-GC10ACG18-E12AE17-2E12A2E15-2(18C14-)18C13-D18AD12-20C12-G18AG11-6(22C10-)D20AD10-B20AB10-22A7-H10A2E2A2E10AH5-G7A2F-EF2E-2F7AG6-HG4ABF3-4F3-FB4AGH7-2(HG)AB12-BA2(GH)12-H14-H43-AB22-BA8-B9A2-9AB11-9D2A9D13-D16CD15-C14AC17-D12AD18-C12AC18-G12AG17-16C16-16C15-D16AD2(14-G16AG)13-20C12-G18AG12-D18AD11-D20C7(D10-D20A)D10-B20AB10-22A6-H13A2-13AH3-G9A2EA2-A2E9AG4-E2D5A2F-EA2-AE-2F7AE5-2E4AG3-F4-F3-G4A2E8-E2HAB12-BA2HE13-H14-H11-BA22-AB7-10A4-10A9-9A4-9A11-B7C4-7CB13-D6C4-6CD15-D5C4-5CD16-G5C4-5CG16-D5A4-5AD2(16-G5A4-5AG)15-G6A4-6AG14-D6A4-6AD13-D7C4-7CD12-D7A4-7AD11-2(D8A4-8AD10-)B8A4-8AB9-8(B9A4-9AB8-)2(10A4-)H13A4-13AH-G12A4-12AG3-H8AFEA4-AEF8AH4-2E6AF-EA4-AE-F6A2E6-4EAC2-F6-F2-CA4E12-E14-E10-DA24-AD5-B9A6-9AB7-BA7B6-7BAB10-7B6-6BA13-B5C6-5CB15-5D6-5D16-C4A6-4AC16-C4D6-4DC15-2(6D6-6D14-)C5A6-5AC13-D6A6-6AD12-B6A6-6AB11-2(B7A6-7AB10-)B7A6-7AB9-9A6-9A2(8-D8A6-8AD)8-D8B6-9B8-9A6-9A9-4(8A6-8A10-)8A6-8A5-H12A6-12AH-G11A6-11AH2-ED10A6-11AE3-E7AFEA6-AEF7AE5-2E2AEAC-EA6-AE-CAE2A2E8-FE-E2-F8-F2-E-EF7-DA24-AD5-D8A8-8AD7-B7A8-7AB9-B6A8-6AB12-5A8-5A15-C3A8-3AC16-C3A8-3AD16-D3A8-3AD15-D4A8-4AD14-D4A8-4AD13-6A8-6A12-B5A8-5AB12-6A8-6A11-B6A8-6AB2(10-D6A8-6AD)9-2D6A8-6A2D2(8-D7B8-7BD)2(8-8A)9-7A8-7A138-7A8-7A5-H11A8-11AH-G10A8-10AH2(2-E10A8-10AE)3-EF5ACEA8-AEC5AFE6-3FEF2-F8-F2-FE3F5-D28-D3-D9A8-9AD5-D8B8-8BD7-DB6A8-6ABD9-DB5A8-5ABD13-B3A8-3AB2(16-4A8-4A)15-B4A8-4AB14-B4A8-4AB13-B5A8-5AB2(12-D5A8-5AD)11-2D5A8-5A2D10-D6A8-6AD10-D6B8-6BD9-2D6B8-6B2D8-D7B8-7BD2(8-8A)233-7A8-7A5-E11A8-11AE-H10A8-10AH2-E10A8-10AE3-2F5AC2A8-2AC5A2F6-FIFEF-F10-F-FEFIF5-C28-C3-C9A8-9AC5-D2C6B8-6B2CD7-DC6B8-6BCD9-DC5B8-5BCD12-D3(4B8-4BD14-C)4B8-4BD13-2C4B8-4BCD2(12-C5B8-5BC)11-3(2C5B8-5B2C10-)2C5B8-5B2C9-D7B8-7BD8-B7A8-7AB2(8-8A)233-7A8-7A7-10A8-10A2-E11A8-11AE-E10A8-10AE3-F6AC2A8-2AC6AF5-2(FI)EF-F10-F-FE2(IF)4-G28-G3-G9A8-9AG5-G2C6D8-6D2CG7-GC6D8-6DCG9-G6D8-6DG12-2(C4D8-4DC14-)H4D8-4DH14-G4D8-4DG13-HC4D8-4DCH12-GC4D8-4DCG12-HC4D8-4DCH11-G2C4D8-4D2CG10-H2C4D8-4D2CH10-G2C4D8-4D2CG9-H3C4D8-4D3CH2(8-B7A8-7AB)265-7A8-7A7-10A8-10A2-E11A8-11AE-F10A8-10AF3-I6AC2A8-2AC6AI5-2(FI)EI-F10-F-IE2(IF)4-F28-F3-F9A8-9AF5-E2G6D8-6D2GE7-EG6D8-6DGE9-HG5D8-5DGH12-5D8-5D14-G4D8-4DG2(14-E4D8-4DE)13-2E4D8-4D2E12-EG4D8-4DGE12-FG4D8-4DGF11-2(2FG4D8-4DG2F10-)F2G4D8-4D2GF9-HE2G4D8-4D2GEH2(8-B7A8-7AB)265-7A8-7A7-10A8-10A2-E11A8-11AE-I10A8-10AI3-F6AC2A8-2AC6AF5-2(IF)EI-F10-F-IE2(FI)4-G28-G3-G9A8-9AG5-G2C6D8-6D2CG7-GC6D8-6DCG9-G6D8-6DG12-2(C4D8-4DC14-)G4D8-4DG14-H4D8-4DH13-GC4D8-4DCG12-HC4D8-4DCH12-GC4D8-4DCG11-H2C4D8-4D2CH10-G2C4D8-4D2CG10-H2C4D8-4D2CH9-G3C4D8-4D3CG2(8-B7A8-7AB)265-7A8-7A7-10A8-10A2-E11A8-11AE-F10A8-10AF3-I6AC2A8-2AC6AI5-2(FI)EI-F10-F-IE2(IF)4-C28-C3-C9A8-9AC5-D2C6B8-6B2CD7-DC6B8-6BCD9-D6B8-6BD12-D3(4B8-4BD14-C)4B8-4BD13-2C4B8-4BCD2(12-2C4B8-4B2C)11-2(3C4B8-4B3C10-)2C5B8-5B2C10-2C5B8-5B2C9-D7B8-7BD8-B7A8-7AB2(8-8A)234-6A8-6A10-8A8-8A4-E11A8-11AE-E10A8-10AE3-F6AC2A8-2AC6AF5-2(FI)EF-F10-F-FE2(IF)4-D28-D3-D10A6-10AD5-D9B6-9BD7-9B6-9B9-2BA5B6-5BA2B13-5B6-5B16-5A6-5A16-B4A6-5A15-B5A6-5AB14-6A6-6A13-B6A6-6AB2(12-D6A6-6AD)11-2(2D6A6-6A2D10-)2D6B6-6B2D9-2(D8B6-8BD8-)9A6-9A233-8A6-8A5-EA2-9A6-9A2-AE-H11A6-11AH2-E10A8-10AE3-2F5AC2A8-2AC5A2F6-FIFEF-2F8-2F-FEFIF6-D26-D4-DB10A4-10ABD6-B9A4-9AB9-9A4-9A11-8A4-8A14-D5A4-5AD16-C5A4-5AD16-D5A4-5AD15-D6A4-6AD14-D6A4-6AD13-2(8A4-8A12-)B7A4-7AB11-B8A4-8AB2(10-D8A4-8AD)9-2D8A4-8A2D2(8-D9B4-9BD)8-10A4-10A169-9A4-9A5-HA3-9A4-9A3-AH-G11A6-11AH2(2-E11A6-11AE)3-EF5ACE2A6-2AEC5AFE6-3FEF2-EF6-FE2-FE3F6-D26-D5-B24AB7-24A9-22A11-B18AB14-D14AD16-G14AG3(16-D14AD)15-D16AD13-C18AC12-D18AD11-22A2(10-B20AB)9-AB20ABA8-DB20ABD8-D22AD8-D23B8-24A9-4(22A10-)22A5-H30AH-G28AH2-E28AE3-F26AF5-2E2AEAC3EA4-A3ECAE2A2E8-2F-H3-2F4-2F3-H-2F7-2A24-2A5-26A7-B22AB9-BC18ACB12-C16AC15-C14AC17-C12AC18-G12AG17-GE12AEG16-2G12A2G15-2G14A2G14-G16AG13-C18AC12-D18AD11-2(C20AC10-)D20AD9-2(2B20A2B8-)6(B22AB8-)24A4-H30AH-G28AG2-E28AE3-EF6A3EA4-A3E6AFE6-2EFEAC3-6E3-CAEF2E12-H4-6F4-H11-BA22-AB7-C22AC9-C20AC11-C18AC13-C16AC15-D14AD17-C12AC19-2E2H4A2H2E20-2GEH4AHE2G20-E2H6A2HE19-E2H8A2HE17-2HE10AE2H15-EHE12AEHE13-2G16A2G2(12-C18AC)11-C20AC7(10-D20AD)10-B20AB10-22A6-H28AH3-G26AG4-E26AE5-2E5A2EFEI2EFEF2E5A2E8-3EAC12-CA3E13-H14-H11-2CA20-A2C8-C20AC11-C18AC12-C18AC13-HG14AGH16-2(CE)6A2(EC)19-GE2C4ACHEG24-H2EH28-E2HE27-EH2EHE25-2E4A2E23-2E6A2E21-2HE6AE2H18-G2EH8AH2EG15-2(EH)10A2(HE)13-GH2E12A2EHG12-EH16AHE11-CG18AGC10-G20AG10-C20AC10-G20AG3(10-D20AD)10-B20AB10-22A7-H26AH5-E24AE6-2(HE)GAC3EFEFIEF3ECAG2(EH)8-E2HAC12-CA2HE13-H14-H44-CA20-AC9-C20AC11-C18AC13-H2D12A2DH15-2H2EG6AG2E2H21-CE2CEC27-G2EG124-4E27-HEF2EH26-3EF2E25-EFE2FEFE23-2E6A2E21-2E8A2E18-H2E10A2EH15-GE14AEG13-GEH14AHEG12-E2H14A2HE12-HE16AEH12-2H16A2H12-HE16AEH12-DG16AGD12-2B16A2B12-2ABD12ADB2A9-H5ABE10AEB5AH7-3GCAB2EFEFI2FEF2EBAC3G12-H14-H16-H14-H77-C2A16-2AC11-HD16ADH13-H2D12A2DH15-H2E10A2EH19-4E2F4E312-2E2F2E25-8E23-2E6A2E20-H2E8A2EH2(18-EF10AFE)17-EFE10AEFE16-2EF10AF2E16-EFE10AEFE16-HEF10AFEH16-DHE10AEHD18-HEF6AFEH14-4H3-FE2F2I2FEF3-4H11-HC14-CH140-GHDA14-ADHG12-ED14ADE15-3E10A3E19-2E2FI3F2E408-2E2F2E25-2(2EF)2E23-2EFE2FEF2E22-2(EF)2E2(FE)22-3FE2FE3F22-2(EF)2E2(FE)22-FE6FEF22-E8FE22-4FI5F24-FI2FIF212-EDA12-ADE15-2E12A2E18-2E4FI3F2E946-2E12A2E17-4E2FI3F4E979-2E4FI3F2E1002-
