model
size = 28 30 32, scale = 0.05, origin = -y
material 
  colors = A:#555 B:#222 C:#FCFAF2 D:#111 E:#FFB11B
voxels
62-11(5(B2-)B12-)4B2(2-B)2-4B18-4B24-4B438-5(B2-)B11-18B11-11(2(4B2-)4B12-)2(4B2-)4B18-4B24-4B409-2(18B10-)3(2B14A2B10-)2B14A2B11-7(B14AB12-)B14AB13-14A14-14A19-4B17-B16-B10-2B14-2B289-3(20B8-)2(3B14A3B8-)4B13A3B9-18AB9-11(18A10-)B16AB10-2B14A2B16-6B294-22B6-22B7-2(3B14A3B8-)4B13A3B9-18AB10-2(E16A11-)5(E15A12-)E15A11-C16A11-18A9-B18AB8-2B17AB8-3B14A3B8-4B3-6B3-4B16-4B239-2(22B6-)22B7-2(3B14A3B8-)4B13A3B9-18AB10-E16A10-C17A10-7(C16A11-)18A9-B18AB9-B16AB10-2B14A2B12-B3-2B2C2B3-B19-B2-B267-22B6-22B7-2(3B14A3B8-)4B13A3B9-18AB9-CE16A10-C17A11-16A11-C16A5(12-E15A)11-18A9-B18AB9-B16AB10-2B14A2B12-B3-2B2C2B3-B19-B2-B239-2(22B6-)22B7-2(3B14A3B8-)4B13A3B9-18AB9-CE16A10-C17A11-16A11-C16A5(12-E15A)11-18A9-B18AB8-2B17AB8-3B14A3B8-4B3-6B3-4B16-4B267-22B6-22B7-2(3B14A3B8-)4B13A3B9-18AB10-E16A10-C17A10-7(C16A11-)2(18A10-)B16AB10-2B14A2B16-6B265-3(24B4-)5B14A5B4-5B14A5B6-4B13A3B9-18AB10-2(E16A11-)5(E15A12-)E15A11-C16A11-18A10-18A11-16A13-14A287-91B14A7B-6B14A6B5-B18AB9-18A9-10(20A8-)20A9-18A10-18A12-14A259-92B12A8B-6B14A6B4-2(2B18A2B6-)5(B20AB6-)B5(20A8-)20A9-18A10-18A12-14A287-64B12A8B-6B14A6B4-2(2B18A2B6-)5(B20AB6-)B6(20A8-)2(B18AB8-)3B14A3B266-8B10-63B14A7B-6B14A6B5-B18AB9-18A9-11(20A8-)2(B18AB8-)3B14A3B15-6B235-9B-8B-72B14A7B-6B14A6B5-B18AB9-18A9-9(20A8-)20A7-B20AB2(6-2B18A2B)6-4B14A4B6-5B3-6B3-5B15-4B208-9B-2B4-2B-21B4C47B14A7B-6B14A6B5-B18AB9-18A9-9(20A8-)2(20A7-B20AB7-2(B18AB8-)3B14A3B11-B3-2B2C2B3-B19-B2-B218-2B4-2B10-12B4C48B12A8B-6B14A6B3-2(3B18A3B4-)2B20A2B4-2B5(20AB6-B)3(20A8-))20A7-B20AB7-2(B18AB8-)3B14A3B11-B3-6B3-B19-4B208-9B-2B4-2B-21B4C47B14A7B-6B14A6B5-B18AB9-18A9-9(20A8-)20A7-B20AB2(6-2B18A2B)6-4B14A4B6-5B3-6B3-5B182-6B22-6B11-9B-8B-72B14A7B-6B14A6B5-B18AB9-18A9-20A7-2(B20AB6-)B20AB7-7(20A8-)2(B18AB8-)3B14A3B127-6B50-6B21-2(8B20-)8B10-63B14A7B-6B14A6B5-B18AB9-18A9-20A7-B20AB5-2B20A2B5-B20AB7-7(20A8-)2(B18A9-)3B14A17-4(8B20-)8B22-4B22-8B19-2B6-2B18-2B6-2B37-63B14A7B-6B14A6B5-B18AB9-18A9-20A7-B20AB5-2B20A2B5-B20AB7-6(20A8-)20A9-18A10-18A12-14A16-4(10B18-)10B20-6B20-3B4D3B17-2B8-2B16-2(2B8-)91B14A7B-6B14A6B5-B18AB9-18A9-20A7-B20AB5-2B20A2B5-B20AB7-6(20A8-)20A9-18A10-18A12-14A16-3(10B18-)10B17-12B18-8B18-3B6D3B15-2B10-2B14-2B10-2B7-91B14A7B-6B14A6B5-B18AB9-18A9-20A7-B20AB5-2B20A2B5-B20AB7-6(20A8-)20A9-18A10-18A12-14A16-3(10B18-)10B17-12B17-10B17-2B8D2B15-2B10-2B14-2B10-2B35-63B14A7B-6B14A6B4-2(2B18A2B6-)B20AB6-B20AB5-2B20A2B5-2(B20AB6-)B3(20AB7-)2(20A8-)20A9-18A10-18A12-14A16-4B2C4B3(18-10B)17-12B17-10B17-2B8D2B15-2B10-2B14-2B10-2B35-63B14A7B-6B14A6B4-2(2B18A2B6-)B20AB6-B20AB5-2B20A2B5-B20AB2(6-B19A2B)7-19A2B7-20AB7-2(20A8-)20A7-2B18A2B8-18A12-14A16-4B2C4B3(18-10B)17-12B17-10B17-2B8D2B15-2B10-2B14-2B10-2B9-3(25B3-)A2B18A2B2A2(3-25A)3-24A4-24A3(5-23A)6-3(B18AB8-)21A7-2(20A8-)20A7-B20AB8-18A10-18A14-3(10B18-)10B17-12B17-10B17-2B8D2B15-2B10-2B14-2B10-2B37-2(25B3-)A2B18A2B2A2(3-25A)3-24A4-24A3(5-23A)6-3(B18AB8-)21A7-3(20A8-)20A9-18A10-18A14-3(10B18-)10B17-12B18-8B18-3B6D3B15-2B10-2B14-2B10-2B9-3(25B3-)A2B18A2B2A2(3-25A)3-24A3(5-23A)5-22A8-2(18A10-)18A9-21A7-3(20A8-)20A9-18A10-18A14-4(10B18-)10B20-6B20-3B4D3B17-2B8-2B16-2B8-2B40-2B2-2B3-3B3-2B2-2B5-25B3(3-25A)3-24A3(5-23A)5-22A8-7(18A10-)18A11-16A12-16A16-4(8B20-)8B22-4B22-8B19-2B6-2B18-2B6-2B41-2B2-2B3-3B3-2B2-2B5-25B3(3-8A3B2A4B8A)3-8A4(3B2A4B7A5-7A)3B2A4B6A9-5(4A3B2A4B3A12-)2(16A12-)16A14-12A16-12A131-6B50-6B21-8B20-8B42-B27-6(2B2-2B3-3B3-2B2-2B7-)2B2-2B3-3B3-2B2-2B11-7(2B3-3B3-2B15-)13B15-13B17-9B272-6B22-6B11-
