model
size = 32 19 30, scale = 0.05, origin = -y
material 
  colors = A:#90C B:#D00 C:#777 D:#6F6 E:#444 F:#FFF G:#100
voxels
237-5D601-2D5A2D597-2D9A2D594-D13AD593-D13AD592-D15AD591-D15AD590-D17AD460-3F16-3F9-F31-F30-F31-F2-D17AD10-F419-2F14-2F65-F31-F43-D17AD9-F31-F357-3F10-3F131-F31-F10-D17AD2-F16-7A8-F5-2F10-5A27-5A28-3A249-2F7-2F209-D6A5E6AD17-D2A2-E2-2AD7-F4-F8-D2A2-E2-2AD7-F4-F9-2A2-E2-2A9-F13-9A9-F14-7A10-F16-3A187-2F3-2F211-D4A2E5-2E4AD16-2A9-2A19-4A5-4A19-AD2A2-E2-2ADA11-F8-D9AD12-F8-D9AD22-9A9-F15-5A11-F32-F111-3F213-D2A2E9-2E2AD15-DA11-A2(D17-D2A9-2A)D18-4A2-E2-4A12-F6-4A2-E2-4A12-F7-D9AD13-F8-9A14-F10-5A44-F80-F214-D2AE11-E2AD14-2A13-2A15-3A11-3A16-2A11-2A17-D2A9-2AD17-D2A4-E4-2AD18-13A20-D9AD22-9A14-F11-3A14-F291-C2-DAE13-EAD10-C3-A15-A2(11-C3-2A13-2A)10-3C2-3A11-3A2-3C2(11-2A)17-D4A2-E2-4AD18-4A2-E2-4A20-D9AD23-7A12-F2-F32-F190-3C21-3C6-C30-3B-DAE13-EAD-3B5-3B2-A15-A2(2-3B5-3B2-2A13-2A)2-3B4-C3BC-3A11-3A-C3BC4-3B2-3A11-3A2-3B5-3B3-D3A7-3AD3-3B5-3B4-3A7-3A4-3B13-D3A-E-3AD22-9A11-F14-3A13-F4-F189-5C19-5C4-3B21-3B4-5BDAE13-EAD3(5B3-5B-A15-A-)5B2-C5BC2A13-2AC5BC2-5B-2A13-2A-5B3-5B2-3A9-3A2-5B3-5B2-D2A9-2AD2-5B4-3B4-AD2A2-E2-2ADA4-3B14-9A25-5A10-2F5-F188-7C17-7C2-5BC17-C5B2-7BCE13-E3(C7B-7BC15-)C2(7B-7B2A13-2A)7B-7B4A9-4A7B-2B3G2BC3A9-3AC2B3G2B2-B-F-B2-C3A2-3E2-3AC2-B-F-B5-F5-CD10AC5-F7-F6-3C5A3C6-F17-5C174-7C17-7C2-5BC17-C5B2-4(6B2CE13-E2C6B-)6BC2AE11-E2AC6B-6BC2A2E9-2E2AC6B-6BC4AE7-E4AC6B-2B3G2BC3AE7-E3AC2B3G2B2-2B-2B2-C3A7E3AC2-2B-2B11-C11AC20-3C5A3C24-5C174-7C17-7C2-5BC17-C5B2-7BCE13-E3(C7B-7BC15-)C2(7B-7B2A13-2A)7B-7B4A9-4A7B-7BC3A9-3AC7B2-5B2-C3A2-3E2-3AC2-5B11-CD10AC20-3C5A3C24-5C175-5C19-5C4-3B21-3B4-5BDAE13-EAD3(5B3-5B-A15-A-)5B2-C5BC2A13-2AC5BC2-5B-2A13-2A-5B3-5B2-3A9-3A2-5B3-5B2-D2A9-2AD2-5B4-3B4-AD2A2-E2-2ADA4-3B14-9A25-5A208-3C21-3C6-C23-C6-3B-DAE13-EAD-3B5-3B2-A15-A2(2-3B5-3B2-2A13-2A)2-3B4-C3BC-3A11-3A-C3BC4-3B2-3A11-3A2-3B5-3B3-D3A7-3AD3-3B5-3B4-3A7-3A4-3B13-D3A-E-3AD22-9A26-2A275-C2-DAE13-EAD2-C7-C3-A15-A2(3-C7-C3-2A13-2A)3-C6-3C2-3A11-3A2-3C2(11-2A)17-D4A2-E2-4AD18-4A2-E2-4A20-D9AD23-7A307-D2AE11-E2AD14-2A13-2A15-3A11-3A16-2A11-2A17-D2A9-2AD17-D2A4-E4-2AD18-13A20-D9AD22-9A26-3A310-DA2E9-2EAD16-DA11-A2(D17-D2A9-2A)D18-4A2-E2-4A19-4A2-E2-4A20-D9AD22-9A25-5A342-D2A2E5-2E2AD18-2A9-2A19-4A5-4A19-AD2A2-E2-2ADA20-D9AD21-D9AD22-9A25-5A375-D3A5E3AD20-D2A2-E2-2AD21-D2A2-E2-2AD22-DA2-E2-AD23-D7AD24-2D3A2D27-3D409-2D7A2D23-7A26-5A27-5A28-3A475-7D365-
