model
size = 16 13 11, scale = 0.05, origin = -y
material 
  colors = A:#FFC96B B:#FE8E8E C:#90713B D:#4D2A0A E:#FFF
voxels
--ABBAAAAAABBA-- -CCBBAAAAAABBCC- --ADDAEEEEADDA-- --ADDAEEEEADDA-- --AAAAAAAAAAAA-- --AAAAAAAAAAAA-- --AAAAAAAAAAAA-- --AAAAAAAAAAAA-- --AAAAAAAAAAAA-- --AAAAAAAAAAAA-- --AAAAAAAAAAAA-- ---------------- ---------------- 
--AAAAAAAABBAA-- CCAAAAAAAAAA--CC --AAAAAAAAAA-A-- --AAAAAAAAAA-A-- --AAAAAAAAAAAA-- --A---------AA-- --A----------A-- --A----------A-- --A----------A-- --AAAAAAAAAAAA-- --AAAAAAAAAAAA-- ---------------- ---------------- 
--AAAAAAAAAAAA-- --AAAAAAAAAAAA-- --AAAAAAAAAAAA-- --AAAAAAAAAAAA-- --AAAAAAAAAAAA-- --A---------AA-- --A----------A-- --A----------A-- --A----------A-- --AAAAAAAAAAAA-- --AAAAAAAAAAAA-- ---------------- ---------------- 
--AAAAAAAAAAAA-- --AAAAAAAAAAAA-- --AAAAAAAAAAAA-- --AAAAAAAAAAAA-- --AAAAAAAAAAAA-- --A---------AA-- --A----------A-- --A----------A-- --A----------A-- --AAAAAAAAAAAA-- --AAAAAAAAAAAA-- ---------------- ---------------- 
--AAAAAAAAAAAA-- --AAAAAAAAAAAA-- --AAAAAAAAAAAA-- --AAAAAAAAAAAA-- --AAAAAAAAAAAA-- --AAAAAAAAA-AA-- --AAAAAAAAA-AA-- --A----------A-- --A----------A-- --AAAAAAAAAAAA-- --AAAAAAAAAAAA-- ------------AA-- ------------AA-- 
--AAAAAAAAAAAA-- --AAAAAAAAAAAA-- --AAAAAAAAAAAA-- --AAAAAAAAAAAA-- --AAAAAAAAAAAA-- --AAAAAAAAA-AA-- --AAAAAAAAA-AA-- --A----------A-- --A----------A-- --AAAAAAAAAAAA-- --AAAAAAAAAAAA-- ------------AA-- ------------AA-- 
--AAAAAAAAAAAA-- --AAAAAAAAAAAA-- --AAAAAAAAAAAA-- --AAAAAAAAAAAA-- --AAAAAAAAAAAA-- --AAAAAAAAA-AA-- --AAAAAAAAAAAA-- --AAAAAAAAAAAA-- --AAAAAAAAAAAA-- --AAAAAAAAAAAA-- --AAAAAAAAAAAA-- --AA------------ --AA------------ 
--AAAAAAAAAAAA-- --AAAAAAAAAAAA-- --AAAAAAAAAAAA-- --AAAAAAAAAAAA-- --AAAAAAAAAAAA-- --AAAAAAAAA-AA-- --AAAAAAAAAAAA-- --AAAAAAAAAAAA-- --AAAAAAAAAAAA-- --AAAAAAAAAAAA-- --AAAAAAAAAAAA-- --AA------------ --AA------------ 
--AAAAAAAAAAAA-- --AAAAAAAAAAAA-- --AAAAAAAAAAAA-- --AAAAAAAAAAAA-- --AAAAAAAAAAAA-- --AAAAAAAAA-AA-- --AAAAAAAAAAAA-- --AAAAAAAAAAAA-- --AAAAAAAAAAAA-- --AAAAAAAAAAAA-- --AAAAAAAAAAAA-- ---------------- ---------------- 
--AAAAAAAAAAAA-- --AAAAAAAAAAAA-- --AAAAAAAAAAAA-- --AAAAAAAAAAAA-- --AAAAAAAAAA-A-- --AAAAAAAAA-AA-- --AAAAAAAAAAAA-- --AAAAAAAAAAAA-- --AAAAAAAAAAAA-- --AAAAAAAAAAAA-- --AAAAAAAAAAAA-- ---------------- ---------------- 
--AAAAAAAAAAAA-- --AAAAAAAAAAAA-- --AAAAAAAAAAAA-- --AAAAAAAAAAAA-- --AAAAAAAAAAAA-- --AAAAAAAAAAAA-- --AAAAAAAAAAAA-- --AAAAAAAAAAAA-- --AAAAAAAAAAAA-- --AAAAAAAAAAAA-- --AAAAAAAAAAAA-- ---------------- ---------------- 
