model
size = 8 25 5, scale = 0.05, origin = -y
material 
  colors = A:#3CF B:#003 C:#399 D:#0F6 E:#050 F:#6F0 G:#6C0 H:#093 I:#3F3 J:#0F0 K:#080 L:#0F9 M:#060
voxels
CCCCC--- CCCCC--- -------- -------- -------- -------- -------- -------- -------- -------- ----BBBB ----BBBB -------- -------- -------- -------- -------- -------- -------- -------- -------- -------- -------- -------- -------- 
CCCCC--- CCCCC--- --A----- --A----- --A----- --A--A-- --A--B-- --A--B-- --A--BB- --A--BB- --A-BDJB --A-BHLB --A--FI- --A----- --A----- --A----- --A----- --A----- --A----- --A----- --A----- --A----- --A----- --A----- --A----- 
CCCCC--- CACAC--- -A-A---- -A-AAA-- -A-A-A-- -A-A-AA- -A-A-BB- -A-A-BB- -A-A-BB- -A-A-BB- -A-AB-KB -A-ABDFB -A-A-DG- -A-A---- -A-A---- -A-A---- -A-A---- -A-A---- -A-A---- -A-A---- -A-A---- -A-A---- -A-A---- -A-A---- -A-A---- 
CCCCC--- CCCCC--- --A----- --A----- --A----- --A--A-- --A--B-- --A--B-- --A--BB- --A--BB- --A-B-EB --A-BGEB --A--MD- --A----- --A----- --A----- --A----- --A----- --A----- --A----- --A----- --A----- --A----- --A----- --A----- 
CCCCC--- CCCCC--- -------- -------- -------- -------- -------- -------- -------- -------- ----BBBB ----BBBB -------- -------- -------- -------- -------- -------- -------- -------- -------- -------- -------- -------- -------- 
