model
size = 3 32 12, scale = 0.05, origin = -y
material 
  colors = A:#003 B:#06F C:#960 D:#630
voxels
-3(C2-)2(D3(2-C)2-)5(D2-C-3A-C2-)D40-4(3A9-)3A4-C41-16(B2-)B-6A40-16(A2-)A5-C41-10(A2-)2(B2-)A2(2-B)2(2-A)5-D41-10(A2-)3(B2-A2-)A5-C41-4(A2-)B2(2-A)2(2-B)2(2-A)2(2-B2-A)2(2-A)-6A40-10(A2-)3(B2-A2-)A5-C41-10(A2-)2(B2-)A2(2-B)2(2-A)5-D41-16(A2-)A5-C41-16(B2-)B-6A94-C-
