model
size = 3 28 4, scale = 0.05, origin = -y
material 
  colors = A:#400 B:#E00 C:#EEE D:#111 E:#222 F:#888
voxels
--- --- --- --- --- --- --- --- --- -A- --- --- --- --- --- --- --- --- --- --- --- --- --- --- --- --- --- --- 
-A- -A- -A- -C- -A- -A- -A- -C- -A- AAA -D- -A- -A- -A- -A- -A- -A- -A- -E- -F- -B- -B- -B- -B- -B- -B- -B- -B- 
-A- -C- -A- -A- -A- -C- -A- -A- -A- AAA -D- -B- -B- -B- -B- -B- -B- -B- -F- -E- -A- -A- -A- -A- -A- -A- -A- --- 
--- --- --- --- --- --- --- --- --- -A- --- --- --- --- --- --- --- --- --- --- --- --- --- --- --- --- --- --- 
