model
size = 30 32 18, scale = 0.05, origin = -y
material 
  colors = A:#090909 B:#070707 C:#060606 D:#090 E:#FF0 F:#09F G:#F30 H:#F60 I:#C9C928 J:#007A28 K:#036 L:#C92800
voxels
9-12C18-12A18-C6A2B3A18-AB2CB4ACAC18-3B3A2(BA)2B18-3AC2BC2(AB)A18-2BAC2B3ABAB18-BAB2ABA2BACB18-3AB2(A2B)AB18-2AB2A2G5A18-AB3A2G5A18-A3B2(A2B)2A18-B3(A2H)2A18-2A3(2HA)C18-2A2B8A18-2A2EA2(CB)ACA18-2A2E2A2CB3A18-2A3(2BA)C18-2A2(2DA)2D2A18-2A2(2DA)2DCA18-5A2BC4A17-3A2BA2F2A2C2A15-4A2BA2F2ABAB2A14-B3ABAB4A2(BA)B15-BA2(B2A)2B2ABA17-2(A2B)4ABA21-6A169-2C12-2C14-BA3(12-2A14-2A)12-2A14-CA12-BC14-BA12-AB14-AB12-AB14-BA12-CA14-BA12-2A14-2B12-2A14-AB12-AC14-AB12-2A14-B2A10-2AC14-2BA10-2AC15-2(2A10-AC16-)2(2A10-2A16-)2A10-2A14-3CA10-A4C10-4A12-4A10-3A14-3A10-B2A14-A2B11-BA14-2A13-BA12-2A15-2B2A6-3AB16-4A6C4A134-C16-C12-B16-A12-A16-C2(12-A16-A)12-B16-A2(12-B16-C)12-B16-B12-BA14-AB12-2A14-2A2(12-BA14-AB)13-2(B14-A14-)3(2A12-AB14-)BA12-2A15-A12-A11-3C2-A12-A2-A2C3(6-3A18-3A)7-BA18-2B8-2(BA)14-A3B9-B2A14-B2A12-A14-B15-A3C6-3CA103-C18-C10-B18-A10-B18-C10-A18-A10-A18-C10-B18-B2(10-A18-A)10-A18-B11-5(B16-A12-)B16-B13-2(B14-)4(A14-)B3(14-A)9-C4-A14-A3-AC2(4-B23-2A)4-CA22-AB4-BCA20-2AB5-3A18-3A6-C3A16-2ABA7-4A14-3AB10-2(2A14-)2C10-2C73-C18-C10-B3(18-A10-A)2(18-B10-A18-A10-A)18-B10-BA16-AB10-CA16-2A10-2A16-AB11-2(A16-B12-)A16-A12-BA14-AB12-2A14-2A13-5(A14-)A8-C5-A14-A4-AC2(2-A25-2A)2-BA24-AB3-CA22-2A4-3A20-2AB4-4A18-3AB5-4A16-4A7-4A14-2A2B11-A14-A15-C12-C42-C20-B8-A20-A8-B2(20-A8-A)20-B8-A20-A8-A20-B9-2(A18-A10-)A18-B10-B2(18-B10-A18-A10-A)18-A11-A16-A12-B16-B12-B16-A12-A16-B13-B14-A8-C5-A14-A5-C2(2-A26-A)2-A26-B2-CA24-AB2-C2A22-3A3-3A20-3A4-4A18-3AB5-B3A16-4A8-BCA14-3A13-C12-C42-C20-C8-A20-B8-A2(20-A8-C)20-B8-C20-A8-B3(20-A8-A)20-B9-A18-B10-C18-B10-A18-A10-A18-B10-A18-A10-2A16-2A10-BA16-AB11-B16-A12-A16-B12-2A14-AB6-C6-A14-B6-CA28-2A28-AB28-B-A26-A2-2A24-2A2-B2A22-3A3-C2A20-3A5-B2A18-3A7-4A14-3AB11-C14-C41-C20-C8-A20-A8-A20-B8-C2(20-A8-A)20-B8-B20-A8-C20-C8-A20-A8-A20-B2(8-B20-A)8-2A18-2A8-2A18-AB9-A18-A10-CA16-AB10-2A16-2A10-BA16-2A11-A16-A12-BA14-2A6-C5-2A14-2A5-CA28-2A28-AC28-2A28-B-B26-B2-2A24-2A3-2A22-AB4-3A20-A2B6-2A18-CA10-AC14-CB40-C20-C2(8-A20-A)8-C20-B8-B20-A8-A20-B8-B20-A8-B20-B8-C20-A8-B20-B2(8-B20-A)2(8-A20-A)8-BA18-AB2(8-3A16-3A)9-2A16-2A10-BA16-AB10-3A14-2AB5-C5-2A14-2A5-C2(A28-B)A28-AC28-AB28-B-B26-B2-BA24-AB3-BA22-AB5-CA20-CB8-CAC14-C2A39-C20-C2(8-A20-A)8-C20-B8-A20-A8-B20-A2(8-A20-B)8-A20-A8-C20-A8-A2(20-C8-B)A18-2A8-BA18-2A9-B18-B10-2A16-2A10-2A16-AC10-2A16-2A11-A16-B12-2A14-2A6-C5-2A14-2A5-CA2(28-2A)28-BA28-AB28-A-A26-A2-CA24-AB3-BA22-2A5-2A20-CA8-BAC14-2CA39-C20-C2(8-A20-A)8-C20-A8-A20-B8-B20-A8-A20-A8-C2(20-B8-B)20-A9-A18-C10-A18-B2(10-C18-A)10-A18-B10-BA16-CA10-BA16-2A11-2(A16-C12-)2A14-2A6-C6-A14-B6-CA2(28-2A)28-BA28-A-C26-B2-CA24-AB3-2A22-2A4-ABA20-2AB6-CB18-2B10-BC14-CA40-C20-C8-B2(20-A8-A)20-C8-C20-A2(8-C20-B)9-2(A18-B10-)2(A18-A10-)B18-A10-B18-B2(10-B18-A)11-A2(16-B12-B)16-A12-A16-A13-A14-A7-C6-A14-A6-CA28-2A28-AB28-B-A26-A2-CA24-2A2-3A22-2AB3-B2A20-3A5-4A16-4A7-2ACA14-3AC11-AC13-C42-C18-C10-B2(18-A10-A)2(18-C10-A)18-A10-A18-B10-B18-C10-A18-C3(10-BA16-2A)11-A16-B12-A16-A12-B16-A13-B2(14-A3(14-B))14-A8-C5-A14-A5-C2(2-A26-A)2-A26-B2-2A24-2A2-C2A22-2AB3-3A20-2AB4-C3A18-3AB5-C3A16-2A2B8-3A14-2AB13-C12-C43-C18-C10-A18-A10-B18-A10-A18-C3(10-B18-A)10-A18-C10-B18-B11-2(A16-A12-B16-A12-)A16-B12-A16-C13-7(A14-)B2(14-A)8-C5-A14-A4-AC2(2-A25-2A)2-BA24-AB3-2A22-AB4-3A20-2AB4-4A18-4A5-4A16-4A7-2B2A14-2A2C11-A14-A15-C12-C44-C16-C12-A16-A12-B16-A12-A16-A12-B16-C12-B2(16-A12-A)16-A12-B16-2(B12-2A14-A)C12-BA14-AC12-2A14-2A13-A14-B14-A14-C14-2A12-AB14-2A12-AC14-BA12-AB14-2A12-AB15-2(2A10-)C5-A12-A4-AC2(4-A)14-A3-2A4-A23-2A4-BA22-2A4-3A20-3A5-B2A18-3A6-CB2A16-2ACB7-AB2A14-ABAC10-2(2A14-)2A10-2A17-2C8-2C46-CA12-AC2(14-2A12-2A)14-2A12-AB14-2A12-AC14-2A12-2A14-2A12-AB14-BA12-A2(B14-B2A10-2A)B14-3A10-2AB2(14-B2A10-3A)14-3A10-3A14-ABA10-ABC15-BA10-AC16-2A10-AC16-BA2(10-AB16-2A)10-AB11-3C2-A12-A2-3C6-5A14-5A6-2BA18-3A6-BAB18-2AB7-2A18-2A8-B3A14-A2CB9-2BA14-2CB12-A14-B15-2A10-2A17-2A8-2A19-CA6-AC21-C6-C19-C12AC2(16-14A)16-B13A16-14A2(16-C13A)16-B12AB16-13AB2(16-14A)16-B13A16-2B10A2B17-12A18-11AC18-B10AC18-B11A18-12A18-11AB18-B10AB18-12A15-3C12A3C12-18A12-B16AB12-18A13-15AB15-13AC16-AB10A2B18-10A20-10A21-8A23-6C21-12C18-11AB18-B3ABAB5A18-B3ABLGA2B2A18-A2B2ALG2AB2A18-3ABALG3A2B18-C3ABLG3ABA18-C2BCALGBAC2A18-CBA6GC2B18-CA2B2(A3B)18-ABAIE2BIEA2B18-3CI2EAIEABA19-2B3(IE)AB20-BAIEAI2E2A20-ABIE2AIEBC20-2(AB)3A2BA20-BAJ5D2A20-AB2A2BJD2A20-2ABJ4D2B20-BA3BCJD2A20-ABJ5DBA20-AB4A2(BA)17-2AB2AK5F5A14-BAB2A2B2AKF2B2AB15-2A2(2BA)KF2A2B17-2BC2ABAKF2BA18-3BK5F2AB19-5B4CB21-2B2A3BA23-3A3B72-
