model
size = 28 28 14, scale = 0.05, origin = -y
material 
  colors = A:#444 B:#F0C C:#E00
voxels
------------AAAAAAAA-------- ------------AAAAAAAA-------- ----------AAAAAA------------ ----------AAAAAA------------ --------AAAAAAAA------------ --------AAAAAAAA------------ --------AAAAAAAAAA---------- --------AAAAAAAAAA---------- ----------AAAAAAAA---------- ----------AAAAAAAA---------- ------------AAAA------------ ------------AAAA------------ ---------------------------- ---------------------------- ------------------AAAA--AAAA ------------------AAAA--AAAA ------------------AAAAAAAA-- ------------------AAAAAAAA-- ---------------------------- ---------------------------- ---------------------------- ---------------------------- ---------------------------- ---------------------------- ---------------------------- ---------------------------- ---------------------------- ---------------------------- 
------------AAAAAAAA-------- ------------AAAAAAAA-------- ----------AAAAAA------------ ----------AAAAAA------------ --------AAAAAAAA------------ --------AAAAAAAA------------ --------AAAAAAAAAA---------- --------AAAAAAAAAA---------- ----------AAAAAAAA---------- ----------AAAAAAAA---------- ------------AAAA------------ ------------AAAA------------ ---------------------------- ---------------------------- ------------------AAAA--AAAA ------------------AAAA--AAAA ------------------AAAAAAAA-- ------------------AAAAAAAA-- ---------------------------- ---------------------------- ---------------------------- ---------------------------- ---------------------------- ---------------------------- ---------------------------- ---------------------------- ---------------------------- ---------------------------- 
---------------------------- ---------------------------- ---------------------------- ---------------------------- --------AAAAAAAAAA---------- --------AAAAAAAAAA---------- --------AAAAAAAAAA---------- --------AAAAAAAAAA---------- --------AAAAAAAAAA---------- --------AAAAAAAAAA---------- ----------AAAAAAAAAA-------- ----------AAAAAAAAAA-------- ----------AAAAAAAAAAAA------ ----------AAAAAAAAAAAA------ ------------AAAAAAAAAA------ ------------AAAAAAAAAA------ --------------AAAAAAAA------ --------------AAAAAAAA------ ------------------AAAA------ ------------------AAAA------ ---------------------------- ---------------------------- --------------------------AA --------------------------AA ------------------------AAAA ------------------------AAAA ------------------------AAAA ------------------------AAAA 
---------------------------- ---------------------------- ---------------------------- ---------------------------- --------AAAAAAAAAA---------- --------AAAAAAAAAA---------- --------AAAAAAAAAA---------- --------AAAAAAAAAA---------- --------AAAAAAAAAA---------- --------AAAAAAAAAA---------- ----------AAAAAAAAAA-------- ----------AAAAAAAAAA-------- ----------AAAAAAAAAAAA------ ----------AAAAAAAAAAAA------ ------------AAAAAAAAAA------ ------------AAAAAAAAAA------ --------------AAAAAAAA------ --------------AAAAAAAA------ ------------------AAAA------ ------------------AAAA------ ---------------------------- ---------------------------- --------------------------AA --------------------------AA ------------------------AAAA ------------------------AAAA ------------------------AAAA ------------------------AAAA 
---------------------------- ---------------------------- ----------AAAAAA------------ ----------AAAAAA------------ ----AAAAAAAAAAAAAA---------- ----AAAAAAAAAAAAAA---------- --------AAAAAAAAAAAA-------- --------AAAAAAAAAAAA-------- --------AAAAAAAAAAAAAA------ --------AAAAAAAAAAAAAA------ --------AAAAAAAAAAAAAA------ --------AAAAAAAAAAAAAA------ ----------AAAAAAAAAAAA------ ----------AAAAAAAAAAAA------ ----------AAAAAAAAAAAA------ ----------AAAAAAAAAAAA------ ------------AAAAAAAAAAAA---- ------------AAAAAAAAAAAA---- --------------AAAAAAAAAA---- --------------AAAAAAAAAA---- ------------------AAAAAAAA-- ------------------AAAAAAAA-- ----------------AAAACCAAAA-- ----------------AAAACCAAAA-- ----------------AAAAAAAAAA-- ----------------AAAAAAAAAA-- ---------------------------- ---------------------------- 
---------------------------- ---------------------------- ----------AAAAAA------------ ----------AAAAAA------------ ----AAAAAAAAAAAAAA---------- ----AAAAAAAAAAAAAA---------- --------AAAAAAAAAAAA-------- --------AAAAAAAAAAAA-------- --------AAAAAAAAAAAAAA------ --------AAAAAAAAAAAAAA------ --------AAAAAAAAAAAAAA------ --------AAAAAAAAAAAAAA------ ----------AAAAAAAAAAAA------ ----------AAAAAAAAAAAA------ ----------AAAAAAAAAAAA------ ----------AAAAAAAAAAAA------ ------------AAAAAAAAAAAA---- ------------AAAAAAAAAAAA---- --------------AAAAAAAAAA---- --------------AAAAAAAAAA---- ------------------AAAAAAAA-- ------------------AAAAAAAA-- ----------------AAAACCAAAA-- ----------------AAAACCAAAA-- ----------------AAAAAAAAAA-- ----------------AAAAAAAAAA-- ---------------------------- ---------------------------- 
---------------------------- ---------------------------- --AAAAAA--AAAAAA------------ --AAAAAA--AAAAAA------------ AAAAAAAABBAAAAAAAA---------- AAAAAAAABBAAAAAAAA---------- AAAA--AAAAAAAAAAAAAA-------- AAAA--AAAAAAAAAAAAAA-------- AAAA----AAAAAAAAAAAAAA------ AAAA----AAAAAAAAAAAAAA------ --AA----AAAAAAAAAAAAAA------ --AA----AAAAAAAAAAAAAA------ --AA------AAAAAAAAAAAA------ --AA------AAAAAAAAAAAA------ --AAAA----AAAAAAAAAAAAAA---- --AAAA----AAAAAAAAAAAAAA---- ----AA------AAAAAAAAAAAA---- ----AA------AAAAAAAAAAAA---- ----AA--------AAAAAAAAAA---- ----AA--------AAAAAAAAAA---- --AAAA------------AAAAAAAA-- --AAAA------------AAAAAAAA-- --AA------------AAAAAAAAAA-- --AA------------AAAAAAAAAA-- AAAA----------AAAAAAAAAAAA-- AAAA----------AAAAAAAAAAAA-- ------------BBAAAA---------- ------------BBAAAA---------- 
---------------------------- ---------------------------- --AAAAAA--AAAAAA------------ --AAAAAA--AAAAAA------------ AAAAAAAABBAAAAAAAA---------- AAAAAAAABBAAAAAAAA---------- AAAA--AAAAAAAAAAAAAA-------- AAAA--AAAAAAAAAAAAAA-------- AAAA----AAAAAAAAAAAAAA------ AAAA----AAAAAAAAAAAAAA------ --AA----AAAAAAAAAAAAAA------ --AA----AAAAAAAAAAAAAA------ --AA------AAAAAAAAAAAA------ --AA------AAAAAAAAAAAA------ --AAAA----AAAAAAAAAAAAAA---- --AAAA----AAAAAAAAAAAAAA---- ----AA------AAAAAAAAAAAA---- ----AA------AAAAAAAAAAAA---- ----AA--------AAAAAAAAAA---- ----AA--------AAAAAAAAAA---- --AAAA------------AAAAAAAA-- --AAAA------------AAAAAAAA-- --AA------------AAAAAAAAAA-- --AA------------AAAAAAAAAA-- AAAA----------AAAAAAAAAAAA-- AAAA----------AAAAAAAAAAAA-- ------------BBAAAA---------- ------------BBAAAA---------- 
---------------------------- ---------------------------- ----------AAAA-------------- ----------AAAA-------------- ----AAAAAAAAAAAA------------ ----AAAAAAAAAAAA------------ --------AAAAAAAAAAAA-------- --------AAAAAAAAAAAA-------- --------AAAAAAAAAAAAAA------ --------AAAAAAAAAAAAAA------ --------AAAAAAAAAAAAAA------ --------AAAAAAAAAAAAAA------ ----------AAAAAAAAAAAA------ ----------AAAAAAAAAAAA------ ----------AAAAAAAAAAAA------ ----------AAAAAAAAAAAA------ ------------AAAAAAAAAAAA---- ------------AAAAAAAAAAAA---- --------------AAAAAAAAAA---- --------------AAAAAAAAAA---- ------------------AAAAAAAA-- ------------------AAAAAAAA-- ----------------AAAACCAAAA-- ----------------AAAACCAAAA-- ----------------AAAAAAAAAA-- ----------------AAAAAAAAAA-- ---------------------------- ---------------------------- 
---------------------------- ---------------------------- ----------AAAA-------------- ----------AAAA-------------- ----AAAAAAAAAAAA------------ ----AAAAAAAAAAAA------------ --------AAAAAAAAAAAA-------- --------AAAAAAAAAAAA-------- --------AAAAAAAAAAAAAA------ --------AAAAAAAAAAAAAA------ --------AAAAAAAAAAAAAA------ --------AAAAAAAAAAAAAA------ ----------AAAAAAAAAAAA------ ----------AAAAAAAAAAAA------ ----------AAAAAAAAAAAA------ ----------AAAAAAAAAAAA------ ------------AAAAAAAAAAAA---- ------------AAAAAAAAAAAA---- --------------AAAAAAAAAA---- --------------AAAAAAAAAA---- ------------------AAAAAAAA-- ------------------AAAAAAAA-- ----------------AAAACCAAAA-- ----------------AAAACCAAAA-- ----------------AAAAAAAAAA-- ----------------AAAAAAAAAA-- ---------------------------- ---------------------------- 
---------------------------- ---------------------------- ---------------------------- ---------------------------- ---------------------------- ---------------------------- ------------AAAAAAAAAAAA---- ------------AAAAAAAAAAAA---- ----------AAAAAAAAAAAA------ ----------AAAAAAAAAAAA------ ----------AAAAAAAAAA--AAAA-- ----------AAAAAAAAAA--AAAA-- ------------AAAAAA--AAAA---- ------------AAAAAA--AAAA---- --------------AAAAAAAA------ --------------AAAAAAAA------ ----------------AAAAAA------ ----------------AAAAAA------ ----------------AAAA-------- ----------------AAAA-------- ---------------------------- ---------------------------- ------------------------AAAA ------------------------AAAA ----------------------AAAAAA ----------------------AAAAAA ----------------------AAAA-- ----------------------AAAA-- 
---------------------------- ---------------------------- ---------------------------- ---------------------------- ---------------------------- ---------------------------- ------------AAAAAAAAAAAA---- ------------AAAAAAAAAAAA---- ----------AAAAAAAAAAAA------ ----------AAAAAAAAAAAA------ ----------AAAAAAAAAA--AAAA-- ----------AAAAAAAAAA--AAAA-- ------------AAAAAA--AAAA---- ------------AAAAAA--AAAA---- --------------AAAAAAAA------ --------------AAAAAAAA------ ----------------AAAAAA------ ----------------AAAAAA------ ----------------AAAA-------- ----------------AAAA-------- ---------------------------- ---------------------------- ------------------------AAAA ------------------------AAAA ----------------------AAAAAA ----------------------AAAAAA ----------------------AAAA-- ----------------------AAAA-- 
---------------------------- ---------------------------- ----------------------AAAAAA ----------------------AAAAAA --------------------AAAA---- --------------------AAAA---- --------------AAAAAAAAAA---- --------------AAAAAAAAAA---- --------------AAAAAAAA------ --------------AAAAAAAA------ ----------------AAAA-------- ----------------AAAA-------- ---------------------------- ---------------------------- ---------------------------- ---------------------------- ---------------------------- ---------------------------- ---------------------------- ---------------------------- ---------------------------- ---------------------------- ---------------------------- ---------------------------- ---------------------------- ---------------------------- ---------------------------- ---------------------------- 
---------------------------- ---------------------------- ----------------------AAAAAA ----------------------AAAAAA --------------------AAAA---- --------------------AAAA---- --------------AAAAAAAAAA---- --------------AAAAAAAAAA---- --------------AAAAAAAA------ --------------AAAAAAAA------ ----------------AAAA-------- ----------------AAAA-------- ---------------------------- ---------------------------- ---------------------------- ---------------------------- ---------------------------- ---------------------------- ---------------------------- ---------------------------- ---------------------------- ---------------------------- ---------------------------- ---------------------------- ---------------------------- ---------------------------- ---------------------------- ---------------------------- 
