model
size = 21 26 23, scale = 0.05, origin = -y
material 
  colors = A:#800 B:#E00 C:#96C D:#700 E:#060808 F:#0D1111 G:#000 H:#400 I:#FFFA00 J:#C66 K:#000124 L:#0D0 M:#F08E00
voxels
--------------------- --------------------- --------------------- --------------------- --------------------- --------------------- -------MC------------ --------------------- --------------------- --------------------- --------------------- --------------------- --------------------- --------------------- --------------------- --------------------- --------------------- --------------------- --------------------- --------------------- --------------------- --------------------- --------------------- --------------------- --------------------- --------------------- 
--------------------- --------------------- --------------------- --------------------- --------------------- --------M------------ -------CC------------ --------------------- --------------------- --------------------- --------------------- --------------------- --------------------- --------------------- --------------------- --------------------- --------------------- --------------------- --------------------- --------------------- --------------------- --------------------- --------------------- --------------------- --------------------- --------------------- 
--------------------- --------------------- --------------------- --------------------- --------------------- -------CC------------ -------CC------------ --------------------- --------------------- --------------------- --------------------- --------------------- --------------------- --------------------- ------A-K------------ -----AAAGL----------- -----BBAAG----------- -----BBABB----------- ------BBBB----------- -------E------------- -------EE------------ -------FF------------ --------F------------ --------------------- --------------------- --------------------- 
--------------------- --------------------- --------------------- --------------------- --------------------- -------CC------------ -------CC------------ --------------------- --------------------- --------------------- --------------------- --------------------- --------------------- ------BBBBB---------- -----AAAAAB---------- ----BAAAAAA---------- ----AAAAAAA---------- ----AAAAAAA---------- ----BAAAAAB---------- -----AAAAAB---------- -------A------------- --------------------- --------------------- --------------------- --------------------- --------------------- 
----D-----D---------- --------------------- --------------------- --------------------- --------------------- -------CC------------ --------------------- --------------------- --------------------- --------------------- --------------------- --------------------- -----AAAAA----------- -----AAAAAB---------- ----AAAAAAI---------- ---BAAAAAAAB--------- ---BAAAAAAAB--------- ---BAAAAAAAB--------- ----AAAAAAAB--------- ----BAAAAAA---------- -----AAAAA----------- --------------------- --------------------- --------------------- --------------------- --------------------- 
----D-----D---------- ----D-----D---------- --------------------- --------------------- --------------------- -------CC------------ --------------------- --------------------- --------------------- --------------------- --------B------------ --------B------------ -----AAAABB---------- ----BAAAAAA---------- ----AAAAAAI---------- ---BAAAAAAAG--------- ---BAAAAAAAAB-------- ---BAAAAAAAAB-------- ---AAAAAAAAB--------- ----AAAAAAA---------- -----BBBBB----------- --------------------- --------------------- --------------------- --------------------- --------------------- 
----J-----J---------- ----D-----D---------- --------------------- --------------------- --------------------- -------CC------------ --------------------- --------------------- --------------------- --------------------- --------BBBB--------- --------BBBA--------- -----AAAABB---------- ----BAAAAAA---------- ----AAAAAAI---------- ---BAAAAAAAG--------- ---BAAAAAAAAB-------- ---BAAAAAAAAB-------- ---AAAAAAAAB--------- ----AAAAAAA---------- -----BBBBB----------- --------------------- --------------------- --------------------- --------------------- --------------------- 
----J-----J---------- ----D-----D---------- --------------------- --------------------- ----AAAAAAA---------- ----AAACCAA---------- --------------------- --------------------- --------------------- ----------BB--------- ---------BBA--------- ---------BBB--------- -----BBBBB----------- -----BBAABB---------- ----AAAAAAI---------- ----AAAAAAAB--------- ----AAAAAAAB--------- ----AAAAAAAB--A-K---- ----AAAAAAA--AAAGL--- ----BAAAAAB--BBAAG--- -----HHHHH---BBABB--- --------------BBBB--- ---------------E----- ---------------EE---- ---------------FF---- ----------------F---- 
--------------------- ----D-----D---------- ---BAABAABAA--------- --ABAABAABAAB-------- -BBBBBBBBBBBBB------- -AABAABAABAABA------- -AABAABAABAABA------- --BBBBBBBBBBB-------- ----------BB--------- ----------BA--------- ----------BB--------- --------------------- --------------------- ------BBBB----------- -----AAAAAB---------- ----BAAAAAA---------- ----AAAAAAA---BBBBB-- ----AAAAAAA--AAAAAB-- ----BAAAAAB-BAAAAAA-- -----AAAAAB-AAAAAAA-- -------A----AAAAAAA-- ------------BAAAAAB-- -------------AAAAAB-- ---------------A----- --------------------- --------------------- 
--------------------- ------BBBBBB--------- -BBBBBBBBBBBBB------- -BBB-------BBB------- BBB---------BBA------ BB-----------BA------ BBB---------BBA------ -BBBBBBBBBBBBB------- ----BBBBBBBA--------- ----------BB--------- --------------------- --------------------- --------------------- --------------------- ------AAK------------ -----AAAGL---AAAAA--- -----BBAAG---AAAAAB-- -----BBABB--AAAAAAI-- ------BBBB-BAAAAAAAB- -------E---BAAAAAAAB- -------EE--BAAAAAAAB- -------FF---AAAAAAAB- --------F---BAAAAAA-- -------------AAAAA--- --------------------- --------------------- 
--------------------- --BBBBBBBBBBB-------- -AAB-------ABA------- BA-----------AA------ BB-----------BA------ B-------------A------ BA-----------AA------ BBB---------BBA------ ---BAABAABAAA-------- ------------B-------- ------------B-------- ------------B-------- ------------BBBB----- --------------BB----- ---------------B----- -------------AAAABB-- ------------BAAAAAA-- ------------AAAAAAI-- -----------BAAAAAAAG- -----------BAAAAAAAAB -----------BAAAAAAAAB -----------AAAAAAAAB- ------------AAAAAAA-- -------------BBBBB--- --------------------- --------------------- 
--------------------- --BBBBBBBBBBB-------- -AA---------BA------- BA-----------AA------ B-------------A------ B-------------A------ B-------------A------ BB-----------BA------ --ABAABAABAABA------- ----AABAABABA-------- -----------BA-------- -----------BA-------- -----------BBBBA----- --------------BA----- ---------------A----- -------------AAAABB-- ------------BAAAAAA-- ------------AAAAAAI-- -----------BAAAAAAAG- -----------BAAAAAAAAB -----------BAAAAAAAAB -----------AAAAAAAAB- ------------AAAAAAA-- -------------BBBBB--- --------------------- --------------------- 
--------------------- --BBBBBBBBBBB-------- -BB---------BB------- BB-----------BA------ B-------------A------ B-------------A------ BB-----------BA------ BBB---------BBA------ -BBBBBBBBBBBBB------- ----BBBBBBBBB-------- -----------BB-------- -----------BB-------- -----------BBBBB----- --------------BB----- ---------------B----- -------------BBBBB--- -------------BBAABB-- ------------AAAAAAI-- ------------AAAAAAAB- ------------AAAAAAAB- ------------AAAAAAAB- ------------AAAAAAA-- ------------BAAAAAB-- -------------HHHHH--- --------------------- --------------------- 
--------------------- -----BBBBBBB--------- -AABAABAABAA-A------- BAA---------BA------- BB-----------BA------ BA-----------AA------ BA-----------A------- -BBB-------BBB------- --ABAABAABAAB-------- --------------------- --------------------- --------------------- --------------------- --------------------- --------------------- --------------------- --------------BBBB--- -------------AAAAAB-- ------------BAAAAAA-- ------------AAAAAAA-- ------------AAAAAAA-- ------------BAAAAAB-- -------------AAAAAB-- ---------------A----- --------------------- --------------------- 
--------------------- ----D-----D---------- --ABAABAABAAB-------- -AABAABAABAABA------- -BB---------BB------- -AA---------BA------- -AAB-------ABA------- -BBBBBBBBBBBBA------- ---BAABAAB----------- --------BB----------- --------------------- --------------------- --------------------- --------------------- --------------------- --------------------- --------------------- --------------AAK---- -------------AAAGL--- -------------BBAAG--- -------------BBABB--- --------------BBBB--- ---------------E----- ---------------EE---- ---------------FF---- ----------------F---- 
----J-----J---------- ----D-----D---------- --------------------- ------BBBBB---------- ---BBBBBBBBB--------- --BBBBBCCBBBB-------- --BBBBB--BBB--------- -----BB--BB---------- ---------A----------- --------BA----------- --------BB----------- --------------------- --------------------- --------------------- --------------------- ----------A-K-------- ---------AAAGL------- ---------BBAAG------- ---------BBABB------- ----------BBBB------- -----------E--------- -----------EE-------- -----------FF-------- ------------F-------- --------------------- --------------------- 
----J-----J---------- ----D-----D---------- --------------------- --------------------- --------------------- -------CC------------ --------------------- --------------------- --------------------- --------BB----------- --------BA----------- --------BBB---------- --------------------- --------------------- ----------BBBBB------ ---------AAAAAB------ --------BAAAAAA------ --------AAAAAAA------ --------AAAAAAA------ --------BAAAAAB------ ---------AAAAAB------ -----------A--------- --------------------- --------------------- --------------------- --------------------- 
----D-----D---------- ----D-----D---------- --------------------- --------------------- --------------------- -------CC------------ --------------------- --------------------- --------------------- --------------------- --------BB----------- --------BBA---------- ---------BB---------- ---------BBB--------- ---------AAAAAB------ --------AAAAAAI------ -------BAAAAAAAB----- -------BAAAAAAAB----- -------BAAAAAAAB----- --------AAAAAAAB----- --------BAAAAAA------ ---------AAAAA------- --------------------- --------------------- --------------------- --------------------- 
----D-----D---------- --------------------- --------------------- --------------------- --------------------- -------CC------------ --------------------- --------------------- --------------------- --------------------- --------------------- ---------BB---------- ---------BA---------- ---------AA---------- --------BAAAAAA------ --------AAAAAAI------ -------BAAAAAAAG----- -------BAAAAAAAAB---- -------BAAAAAAAAB---- -------AAAAAAAAB----- --------AAAAAAA------ ---------BBBBB------- --------------------- --------------------- --------------------- --------------------- 
--------------------- --------------------- --------------------- --------------------- --------------------- -------CC------------ -------CC------------ --------------------- --------------------- --------------------- --------------------- --------------------- ---------BB---------- ---------AB---------- --------BAAAAAA------ --------AAAAAAI------ -------BAAAAAAAG----- -------BAAAAAAAAB---- -------BAAAAAAAAB---- -------AAAAAAAAB----- --------AAAAAAA------ ---------BBBBB------- --------------------- --------------------- --------------------- --------------------- 
--------------------- --------------------- --------------------- --------------------- --------------------- -------CC------------ -------CC------------ --------------------- --------------------- --------------------- --------------------- --------------------- --------------------- ---------A----------- --------ABBAABB------ --------AAAAAAI------ --------AAAAAAAB----- --------AAAAAAAB----- --------AAAAAAAB----- --------AAAAAAA------ --------BAAAAAB------ ---------HHHHH------- --------------------- --------------------- --------------------- --------------------- 
--------------------- --------------------- --------------------- --------------------- --------------------- --------M------------ -------CC------------ --------------------- --------------------- --------------------- --------------------- --------------------- --------------------- --------------------- ----------BBBB------- ---------AAAAAB------ --------BAAAAAA------ --------AAAAAAA------ --------AAAAAAA------ --------BAAAAAB------ ---------AAAAAB------ -----------A--------- --------------------- --------------------- --------------------- --------------------- 
--------------------- --------------------- --------------------- --------------------- --------------------- --------------------- -------MC------------ --------------------- --------------------- --------------------- --------------------- --------------------- --------------------- --------------------- --------------------- ----------AAK-------- ---------AAAGL------- ---------BBAAG------- ---------BBABB------- ----------BBBB------- -----------E--------- -----------EE-------- -----------FF-------- ------------F-------- --------------------- --------------------- 
