model
size = 16 31 31, scale = 0.05, origin = -y
material 
  colors = A:#222 B:#333 C:#444 D:#555 E:#666 F:#777 G:#888 H:#999 I:#AAA J:#BBB K:#CCC L:#663 M:#996 N:#DDD O:#FFF P:#966 Q:#EEE R:#99C
voxels
---------------- ---------------- ---------------- ---------------- ---------------- ---------------- ---------------- ---------------- ---------------- ---------------- ---------------- ---------------- ---------------- ---------------- ---------------- ---------------- ---------------- ---------------- ----CCCCC------- ----CCCCCC------ ----CCCCCC------ -----CCCC------- ---------------- ---------------- ---------------- ---------------- ---------------- ---------------- ---------------- ---------------- ---------------- 
---------------- ---------------- ---------------- ---------------- ---------------- ---------------- ---------------- ---------------- ---------------- ---------------- ---------------- ---------------- ---------------- ---------------- ---------------- ---------------- ---------------- ---DDDD--------- ---CCCCCCC------ ---BBBBBBB------ ---BBBBBBB------ ---BBBBBBB------ ---BBBBBBB------ ---BBBBBBB------ ----AAAAAA------ ---------------- ---------------- ---------------- ---------------- ---------------- ---------------- 
---------------- ---------------- ---------------- ---------------- ---------------- ---------------- ---------------- ---------------- ---------------- ---------------- ---------------- ---------------- ---------------- ---------------- ---------------- ---------------- ---------------- --EEEEEE-------- --CCCCCCCCC----- --CCCCCCCCC----- --BBBBBBBBB----- --BBBBBBBBB----- --BBBBBBBBB----- --BBBBBBBBB----- --BBBBBBBBB----- ---AAAAAAAA----- ---AAAAAAA------ ---------------- ---------------- ---------------- ---------------- 
---------------- ---------------- ---------------- ---------------- ---------------- ---------------- ---------------- ---------------- ---------------- ---------------- ---------------- ---------------- ---------------- ---------------- ---------------- ---------------- ---------------- ---DDDDDDD------ --EEEEEEEEE----- -DDDDDDDDDD----- -CCCCCCCCCC----- -CCCCCCCCCC----- -CCCCCCCCCC----- -BBBBBBBBBB----- --CCCCCCCCC----- --AAAAAAAAA----- ---AAAAAAAA----- ---AAAAAAA------ ---------------- ---------------- ---------------- 
---------------- ---------------- ---------------- ---------------- ---------------- ---------------- ---------------- ---------------- ---------------- ---------------- ---------------- ---------------- ---------------- ---------------- ---------------- ---------------- ---------------- ---EEE-EEEE----- --EEEEEEEEE----- -LLLLLLLLLLL---- -DDDDDDDDDDD---- -CCCCCCCCCCC---- -CCCCCCCCCCC---- -CCCCCCCCCC----- -BBBBBBBBBB----- -BBBBBBBBBB----- --AAAAAAAAA----- ---EEEEEEEE----- ----AAAAA------- ---------------- ---------------- 
-----BBBBBBB---- -----AAAAAA----- ------AAAAA----- -----BBBBBB----- -----BBBBBB----- -----BBBBBB----- -----BBBBB------ -----BBBBB------ -----CCCC------- ---------------- ---------------- ---------------- ---------------- ---EEEEEEE------ --GGGGGGGGG----- --GGGGGGGGG----- --FFFFFFFFF----- --FFFFFFFFF----- -GGGGGGGGGGG---- -FFFFFFFFFFFF--- -EEEEEEEEEEEE--- -CCCCC-CCCCC---- -CCCCC-CCCCCCC-- -CCCCCCCCCCCCC-- -BBBBBBBBBBB---- -BBBBBBBBBBB---- -AAAAAAAAAAA---- --AAAAAAAAA----- ---AAAAAAA------ ---------------- ---------------- 
---AAAAAAAAAAA-- ---AAAAAAAAAA--- ----AAAAAAAAA--- ---BBBBBBBBBB--- ---BBBBBBBBBB--- ---BBBBBBBBBB--- ---BBBBBBBBB---- ---BBBBBBBBB---- --CCCCCCCCCC---- --CCCCCCCCCC---- --DDDDDDDDDD---- --EEEEEEEEEEE--- --FFFFFFFFFFFFF- --FFFFFFFFFFFFF- --FFFFFFFFFFFFFF -HHHHHHHHHHHHHHH -GGGGGGGGGGGGGGG -GGGGGGGGGGGGGGG HHHHHHHHHHHHHHHH GGGGGGGGGGGGGGGG FFFFFFFFFFFFFFFF EEEEEE--EEEEEEE- DDDDD---DDDDDD-- EEEEEE-EEEEEE--- CCCCCCCCCCCCCC-- -BBBBBBBBBBB---- -BBBBBBBBBBB---- --AAAAAAAAA----- ---AAAAAAA------ -----AAA-------- ---------------- 
--AAAAAAAAAAAA-- --AAAAAAAAAAAA-- ---AAAAAAAAAAAA- --AAAAAAAAAAAAAA --AAAAAAAAAAAAAA --BBBBBBBBBBBBB- --BBBBBBBBBBBBB- --BBBBBBBBBBBB-- --BBBBBBBBBBBB-- -CCCCCCCCCCCCC-- -DDDDDDDDDDDDDD- -EEEEEEEEEEEEEE- -EEEEEEEEEEEEEEE -GGGGGGGGGGGGGGG -GGGGGGGGGGGGGGG HHHHHHHHHHHHHHHH IIIIIIIIIIIIIIII IIIIIIIIIIIIIIII IIIIIIIIIIIIIIII HHHHHHHHHHHHHHHH GGGGGGGGGGGGGGGG LLLLLL--LLLLLLLL BBBBB---BBBBBBBB CCCCC---CCCCCC-- CCCCCC-CCCCCCC-- CCCCCCCCCCCCCC-- -BBBBBBBBBBB---- --DDDDDDDDDD---- --AAAAAAAA------ ----AAAAA------- ---------------- 
--AAAAAAAAAAAAA- --AAAAAAAAAAAAA- --AAAAAAAAAAAAAA -AAAAAAAAAAAAAAA -AAAAAAAAAAAAAAA --BBBBBBBBBBBBBB --BBBBBBBBBBBBBB --BBBBBBBBBBBBBB --BBBBBBBBBBBBBB -CCCCCCCCCCCCCCC -DDDDDDDDDDDDDDD EEEEEEEEEEEEEEEE -FFFFFFFFFFFFFFF GGGGGGGGGGGGGGGG HHHHHHHHHHHHHHHH IIIIIIIIIIIIIIII JJJJJJJJJJJJJJJJ JJJJJJJJJJJJJJJJ JJJJJJJJJJJJJJJJ IIIIIIIIIIIIIIII MMMMMMMMMMMMMMMM EEEEE---EEEEEEEE LLLL----LLLLLLLL CCCCC---CCCCCCC- CCCCCC-CCCCCCC-- CCCCCCCCCCCCCC-- -BBBBBBBBBBBBB-- --AAAAAAAAAA---- --AAAAAAAAA----- ---AAAAAA------- ---------------- 
-AAAAAAA-AAAAAA- AAAAAAAA-AAAAAA- AAAAAAAA-AAAAAAA -AAAAAAAAAAAAAAA -AAAAAAAAAAAAAAA -BBBBBBBBBBBBBBB -BBBBBBBBBBBBBBB -BBBBBBBBBBBBBBB -BBBBBBBBBBBBBBB -CCCCCCCCCCCCCCC DDDDDDDDDDDDDDDD EEEEEEEEEEEEEEEE EEEEEEEEEEEEEEEE GGGGGGGGGGGGGGGG HHHHHHHHHHHHHHHH IIIIII-IIIIIIIII JJJJJJ--JJJJJJJJ KKKKK---KKKKKKKK KKKKK----KKKKKKK KKKKK----KKKKKKK IIII------IIIIII MMMM-----MMMMMMM PPPP-----PPPPPPP CCCCC---CCCCCCCC CCCCC---CCCCCC-- CCCCCC-CCCCCCC-- -CCCCCCCCCCCCC-- -BBBBBBBBBBB---- --AAAAAAAAA----- ---AAAAAAA------ ----AAAAA------- 
-AAAAA----AAAAAA AAAAAAA---AAAAAA AAAAAAA---AAAAAA AAAAAAA---AAAAAA -AAAAAA---AAAAAA -BBBBBB---BBBBBB BBBBBBB---BBBBBB BBBBBBB---BBBBBB CCCCCCC---CCCCCC CCCCCC---CCCCCCC CCCCCC---CCCCCCC DDDDD----DDDDDDD EEEEE----EEEEEEE FFFFF----FFFFFFF IIII------IIIIII IIII------IIIIII KKKK------KKKKKK NNNN------NNNNNN QQQQ------QQQQQQ NNNN-------NNNNN KKK--------KKKKK HHH-------HHHHHH MMMM------MMMMMM LLLL-----LLLLLLL CCCCC---CCCCCCC- CCCCCC-CCCCCCC-- -CCCCCCCCCCCCC-- -BBBBBBBBBBBB--- --AAAAAAAAAA---- ---CCC---------- ---AA----------- 
-AAAAA-----AAAAA AAAAAA-----AAAAA AAAAAA-----AAAAA -AAAAA-----AAAAA -AAAAA-----AAAAA AAAAAA-----AAAAA BBBBBB-----BBBBB BBBBBB-----BBBBB BBBBBB-----BBBBB CCCCCC-----CCCCC CCCCC------CCCCC DDDDD------DDDDD EEEEE------EEEEE FFFF-------FFFFF GGGG-------GGGGG IIII-------IIIII KKKK-------KKKKK NNNN-------NNNNN QQQ---------QQQQ OOO---------OOOO NNN--------NNNNN JJJ--------JJJJJ MMMM------MMMMMM PPPP-----PPPPPPP CCCCC---CCCCCCC- DDDDDD-DDDDDDD-- -CCCCCCCCCCCCC-- -CCCCCCCCCCCC--- --AAAAAAAAAA---- --AAA----------- ---B------------ 
-AAAA------AAAAA AAAAAA-----AAAAA DDDDDD-----DDDDD -AAAAA-----AAAAA -AAAAA-----AAAAA AAAAA------AAAAA BBBBB------BBBBB BBBBB------BBBBB BBBBB------BBBBB BBBBB------BBBBB CCCCC-------CCCC DDDDD-------DDDD DDDDD-------DDDD EEEE--------EEEE GGGG--------GGGG HHHH--------HHHH IIII--------IIII NNNN--------NNNN OOO---------OOOO OOO---------OOOO OOO---------OOOO KKK--------KKKKK IIII------IIIIII MMMM------MMMMMM LLLLL----LLLLLL- CCCCC--CCCCCCC-- -CCCCCCCCCCCCC-- -CCCCCCCCCCCC--- --BBBBBBBBBB---- --AAA----------- ---A------------ 
AAAAA-------AAAA AAAAA-------AAAA AAAAA-------AAAA -CCCC-------CCCC -AAAA-------AAAA AAAAA-------AAAA BBBBB-------BBBB BBBB--------BBBB BBBB--------BBBB BBBB--------BBBB CCCC--------CCCC CCCC--------CCCC DDDD--------DDDD DDDD--------DDDD EEEE--------EEEE GGGG--------GGGG HHHH---------HHH JJJ----------JJJ QQQ----------QQQ OOO---------OOOO QQQ---------QQQQ NNNN-------NNNNN JJJJ-------JJJJJ HHHH------HHHHHH PPPPP----PPPPPP- CCCCC---CCCCCC-- -CCCCC-CCCCCCC-- -CCCCCCCCCCCC--- --BBBB---BBB---- --AAA----------- ---A------------ 
AAAAA-------AAAA AAAAA-------AAAA AAAAA-------AAAA -AAAA-------AAAA -AAAA-------AAAA AAAAA-------AAAA AAAAA-------AAAA BBBB--------BBBB EEEE--------EEEE BBBB--------BBBB CCC---------CCCC CCC---------CCCC CCC---------CCCC DDD---------DDDD EEE---------EEEE FFF---------FFFF GGG----------GGG III----------III KKK----------KKK NNN---------NNNN NNN---------NNNN NNNN-------NNNNN JJJJ-------JJJJJ HHHH------HHHHHH MMMMM-----MMMMM- CCCCC---CCCCCC-- -CCCCC--CCCCCC-- -DDDDD--DDDDD--- --CCCC---CCC---- --AAA----------- ---A------------ 
BBBBB-------BBBB AAAAA-------AAAA AAAAAA------AAAA -AAAAA------AAAA -AAAAA------AAAA AAAAAA------AAAA AAAAA-------AAAA AAAA--------AAAA BBBB--------BBBB BBBB--------BBBB BBB----------BBB CCC----------CCC CCC----------CCC DDD----------DDD DDD----------DDD EEE----------EEE FFF----------FFF HHH----------HHH RRR----------RRR KKK---------KKKK KKK---------KKKK KKKK-------KKKKK JJJJ-------JJJJJ IIII------IIIIII MMMMM-----MMMMM- LLLLL---LLLLLL-- -LLLLL--LLLLLL-- -DDDDD--DDDDD--- --CCCC---CCC---- --BBB----------- ---A------------ 
AAAAA-------AAAA AAAAA-------AAAA AAAAAA------AAAA AAAAAA------AAAA -AAAAA------AAAA AAAAAA------AAAA AAAAAA------AAAA AAAAA-------AAAA BBBB--------BBBB DDDD--------DDDD BBB----------BBB CCC----------CCC BBB----------BBB CCC----------CCC DDD----------DDD DDD----------DDD FFF----------FFF GGG----------GGG HHH----------HHH III---------IIII JJJ---------JJJJ JJJJ-------JJJJJ JJJJ-------JJJJJ IIII------IIIIII HHHHH----HHHHHH- FFFFF---FFFFFF-- -DDDDD-DDDDDDD-- -DDDDDDDDDDDD--- --DDDD---DDD---- --CCC----------- ---A------------ 
AAAAA------AAAAA AAAAA------AAAAA AAAAAA-----AAAAA AAAAAA-----AAAAA -AAAAA-----AAAAA AAAAAA-----AAAAA AAAAAA-----AAAAA AAAAA------AAAAA AAAA-------AAAAA BBBB-------BBBBB BBBB--------BBBB BBBB--------BBBB BBBB--------BBBB DDDD--------DDDD CCC---------CCCC DDD---------DDDD EEE---------EEEE FFF---------FFFF GGG---------GGGG HHH---------HHHH III---------IIII III--------IIIII HHHH------HHHHHH HHHH------HHHHHH HHHHH----HHHHHH- GGGGG---GGGGGG-- -LLLLLLLLLLLLL-- -CCCCCCCCCCCC--- --CCCCCCCCCC---- --CCC----------- ---B------------ 
AAAAA------AAAAA AAAAAA-----AAAAA AAAAAA-----AAAAA AAAAAA-----AAAAA -AAAAA-----AAAAA -AAAAA-----AAAAA AAAAAA----AAAAAA AAAAAA----AAAAAA AAAAAA----AAAAAA AAAAAA----AAAAAA BBBBBB-----BBBBB DDDDD------DDDDD BBBBB-------BBBB BBBB-------BBBBB CCCC-------CCCCC CCCC-------CCCCC DDDD-------DDDDD EEE--------EEEEE FFF---------FFFF GGG---------GGGG III--------IIIII HHH--------HHHHH HHHH------HHHHHH GGGG-----GGGGGGG GGGGG---GGGGGGG- GGGGGG-GGGGGGG-- -EEEEEEEEEEEEE-- -CCCCCCCCCCCC--- --DDDDDDDDDD---- --CCC----------- ---B------------ 
AAAAAA----AAAAAA AAAAAA----AAAAAA BBBBBBB---BBBBBB AAAAAAA---AAAAAA -AAAAAA---AAAAAA -AAAAAA---AAAAAA BBBBBBB--BBBBBBB AAAAAAA--AAAAAAA AAAAAAA--AAAAAAA AAAAAAA--AAAAAAA BBBBBBB--BBBBBBB BBBBBB----BBBBBB CCCCC-----CCCCCC BBBBB-----BBBBBB BBBBB-----BBBBBB CCCC------CCCCCC DDDD------DDDDDD DDDD------DDDDDD EEEE-------EEEEE GGGG-------GGGGG GGG--------GGGGG GGG-------GGGGGG GGGG------GGGGGG FFFF-----FFFFFFF FFFFF---FFFFFFF- GGGGGG-GGGGGGG-- -EEEEEEEEEEEEE-- -CCCCCCCCCCCC--- --CCCCCCCCCC---- ---CCC---------- ---BB----------- 
AAAAAAA--A-AAAAA AAAAAAAA-A-AAAAA -AAAAAAA-A-AAAAA CCCCCCCC-C-CCCCC AAAAAAAAAA-AAAAA -AAAAAAAAAAAAAAA -AAAAAAAAAAAAAAA AAAAAAAAAAAAAAAA AAAAAAAAAAAAAAAA CCCCCCCCCCCCCCCC AAAAAAAAAAAAAAAA BBBBBBBBBBBBBBBB BBBBBBBBBBBBBBBB BBBBBBBBBBBBBBBB BBBBBBBBBBBBBBBB CCCCCC-CCCCCCCCC CCCCCC--CCCCCCCC CCCCC---CCCCCCCC DDDDD----DDDDDDD EEEE----EEEEEEEE FFFF----FFFFFFFF FFFF--FFFFFFFFFF GGGG--GGGGGGGGGG FFFFF---FFFFFFFF FFFFF---FFFFFFF- FFFFFF-FFFFFFF-- -FFFFFFFFFFFFF-- -CCCCCCCCCCCC--- --CCCCCCCCCC---- ---BBBBBBBB----- ----BBBBB------- 
AAAAAAAA-AAAAAA- -AAAAAAA-AAAAAAA -AAAAAAA-AAAAAAA -AAAAAAAAAAAAAAA CCCCCCCCCCCCCCCC -AAAAAAAAAAAAAA- AAAAAAAAAAAAAAA- AAAAAAAAAAAAAAA- AAAAAAAAAAAAAAA- AAAAAAAAAAAAAAA- AAAAAAAAAAAAAAAA AAAAAAAAAAAAAAAA BBBBBBBBBBBBBBBB BBBBBBBBBBBBBBBB DDDDDDDDDDDDDDDD BBBBBB-BBBBBBBBB CCCCCC--CCCCCCCC CCCCC---CCCCCCCC DDDDD----DDDDDDD DDDDD---DDDDDDDD EEEEE---EEEEEEEE FFFFF-FFFFFFFFFF FFFFF-FFFFFFFFFF FFFFF---FFFFFFF- FFFFF---FFFFFF-- FFFFFF-FFFFFFF-- --FFFFFFFFFFF--- --DDDDDDDDDD---- --BBBBBBBBB----- ---CCCCCCC------ ----CCCCC------- 
-AAAAAAAAAAAAA-- -AAAAAAAAAAAAAA- -AAAAAAAAAAAAAA- -AAAAAAAAAAAAAA- -AAAAAAAAAAAAAA- -AAAAAAAAAAAAAA- -AAAAAAAAAAAAA-- -AAAAAAAAAAAAA-- -AAAAAAAAAAAAA-- -AAAAAAAAAAAAA-- -BBBBBBBBBBBBBB- -AAAAAAAAAAAAAA- -AAAAAAAAAAAAAAA BBBBBBBBBBBBBBBB DDDDDDDDDDDDDDDD BBBBBBBBBBBBBBBB BBBBBBBBBBBBBBBB EEEEEEEEEEEEEEEE CCCCCCCCCCCCCCCC DDDDDDDDDDDDDDDD FFFFFFFFFFFFFFFF EEEEE---EEEEEEEE EEEE----EEEEEEE- EEEEE---EEEEEEE- FFFFFF-FFFFFFF-- FFFFFFFFFFFFF--- -EEEEEEEEEEEE--- --DDDDDDDDDD---- --CCCCCCCCC----- ---CCCCCC------- ---------------- 
-AAAAAAAAAAAA--- -AAAAAAAAAAAAA-- ---AAAAAAAAAAA-- -AAAAAAAAAAAAA-- -AAAAAAAAAAAAA-- -AAAAAAAAAAAAA-- -AAAAAAAAAAAAA-- -AAAAAAAAAAAA--- -AAAAAAAAAAAA--- -AAAAAAAAAAAA--- -AAAAAAAAAAAA--- -AAAAAAAAAAAAA-- -AAAAAAAAAAAA--- -BBBBBBBBBBBBB-- -BBBBBBBBBBBBB-- BBBBBBBBBBBBBB-- BBBBBBBBBBBBBBB- DDDDDDDDDDDDDDD- EEEEEEEEEEEEEEE- DDDDDDDDDDDDDDD- DDDDDDDDDDDDDDD- DDDDDD--DDDDDDD- EEEEE---EEEEEEE- EEEEE---EEEEEE-- FFFFFF-FFFFFFF-- FFFFFFFFFFFFF--- -EEEEEEEEEEE---- --DDDDDDDDDD---- --BBBBBBBB------ ----CCCCC------- ---------------- 
---AAAAAAAAAA--- ---AAAAAAAAAA--- ----AAAAAAAAA--- ---AAAAAAAAAA--- ---AAAAAAAAAA--- ---CCCCCCCCCC--- ---AAAAAAAAA---- ---AAAAAAAAA---- -AAAAAAAAAAA---- -AAAAAAAAAAA---- -AAAAAAAAAAA---- -AAAAAAAAAA----- -BBBBBBBBBBB---- -BBBBBBBBBBB---- -BBBBBBBBBBB---- -CCCCCCCCCCCC--- -BBBBBBBBBBBB--- -BBBBBBBBBBBBB-- DDDDDDDDDDDDD--- CCCCCCCCCCCCCC-- CCCCCCCCCCCCCC-- DDDDDD--DDDDDD-- DDDDD---DDDDDD-- EEEEEE-EEEEEE--- EEEEEEEEEEEEE--- -FFFFFFFFFFF---- -EEEEEEEEEEE---- --EEEEEEEEE----- ---CCCCCCC------ -----BBB-------- ---------------- 
-----AAAAAAA---- -----AAAAAA----- ------AAAAA----- -----AAAAAA----- -----AAAAAA----- -----AAAAAA----- -----AAAAA------ -----BBBBB------ -----AAAA------- ---------------- ---------------- ---------------- ---------------- ---BBBBBBB------ -BBBBBBBBBB----- -BBBBBBBBBB----- -BBBBBBBBBB----- -BBBBBBBBBB----- -DDDDDDDDDDD---- -BBBBBBBBBBBB--- -CCCCCCCCCCCC--- -CCCCC-CCCCCC--- -DDDDD-DDDDDD--- -DDDDDDDDDDDD--- -EEEEEEEEEEE---- -EEEEEEEEEEE---- -EEEEEEEEEEE---- --FFFFFFFFF----- ---CCCCCCC------ ---------------- ---------------- 
---------------- ---------------- ---------------- ---------------- ---------------- ---------------- ---------------- ---------------- ---------------- ---------------- ---------------- ---------------- ---------------- ---------------- ---------------- ---------------- ---------------- ---BBB-BBBB----- --BBBBBBBBB----- -BBBBBBBBBBB---- -BBBBBBBBBBB---- -CCCCCCCCCCC---- -DDDDDDDDDDD---- -DDDDDDDDDD----- -DDDDDDDDDD----- -EEEEEEEEEE----- --DDDDDDDDD----- ---EEEEEEEE----- ----CCCCC------- ---------------- ---------------- 
---------------- ---------------- ---------------- ---------------- ---------------- ---------------- ---------------- ---------------- ---------------- ---------------- ---------------- ---------------- ---------------- ---------------- ---------------- ---------------- ---------------- ---BBBBBBB------ --BBBBBBBBB----- -BBBBBBBBBB----- -BBBBBBBBBB----- -BBBBBBBBBB----- -CCCCCCCCCC----- -CCCCCCCCCC----- --CCCCCCCCC----- --DDDDDDDDD----- ---DDDDDDDD----- ---DDDDDDD------ ---------------- ---------------- ---------------- 
---------------- ---------------- ---------------- ---------------- ---------------- ---------------- ---------------- ---------------- ---------------- ---------------- ---------------- ---------------- ---------------- ---------------- ---------------- ---------------- ---------------- --BBBBBB-------- --BBBBBBBBB----- --BBBBBBBBB----- --BBBBBBBBB----- --BBBBBBBBB----- --CCCCCCCCC----- --CCCCCCCCC----- --CCCCCCCCC----- ---EEEEEEEE----- ---DDDDDDD------ ---------------- ---------------- ---------------- ---------------- 
---------------- ---------------- ---------------- ---------------- ---------------- ---------------- ---------------- ---------------- ---------------- ---------------- ---------------- ---------------- ---------------- ---------------- ---------------- ---------------- ---------------- ---BBBB--------- ---BBBBBBB------ ---BBBBBBB------ ---BBBBBBB------ ---BBBBBBB------ ---BBBBBBB------ ---BBBBBBB------ ----CCCCCC------ ---------------- ---------------- ---------------- ---------------- ---------------- ---------------- 
---------------- ---------------- ---------------- ---------------- ---------------- ---------------- ---------------- ---------------- ---------------- ---------------- ---------------- ---------------- ---------------- ---------------- ---------------- ---------------- ---------------- ---------------- ----BBBBB------- ----BBBBBB------ ----BBBBBB------ -----BBBB------- ---------------- ---------------- ---------------- ---------------- ---------------- ---------------- ---------------- ---------------- ---------------- 
