model
size = 32, scale = 0.05, origin = -y
material 
  colors = A:#D00 B:#DDD C:#BBB D:#EEE
voxels
524-8C24-8A25-6A27-4A919-3C8-3C18-ACA8-A2D19-2AC-4C4A20-3AD8A21-10A23-3A2D3A26-A2DA821-2C14-2C15-A14-A16-A2C3-2(C-)3CACA16-3A3D2(AD)6A17-14A18-14A19-12A22-AC6A27-2A757-C18-C12-2D17-A12-2D2C6-C4-4CA13-3A6DA4D4A14-18A15-16A16-16A17-14A20-10A24-2AC3A722-2(C20-C10-)A3C-2(C5-)C2-CA10-4AD2(A5D)A2D2A11-18A2D12-18A2D13-18A15-D14AC17-14A19-12A22-6A2D688-C22-C8-A22-A8-AC5-2(C4-)C3-2CA8-2A5D2(A4D)A3D3A9-22A10-22A11-20A13-2D16A14-2D16A16-14A19-C7A2D2A22-A2D3A2D655-C24-C6-C24-A6-A-C5-3(C4-)2CA7-DA5D3(A4D)2A8-24A8-C23A9-22A11-20A12-20A13-18A16-14A19-12A23-2D4A623-C26-C37-C8-2(C3-)C5-C-C6-A8D2(A3D)A5DADA6-26A7-24A8-24A9-21AD10-21AD11-20A13-18A16-14A20-10A26-2A593-C26-C4-C26-A4-A-C7-C3-C2-C4-2C2-CA4-ADA7DA3DA2DA4D2A2D2A5-2(26A6-)26A7-23AD9-21AD11-20A13-18A15-15AD17-13AD21-5A2DA589-C28-C2-A28-A3-C2-C7-C2-C-C4-C5-C4-A2DA7DA2DADA4DA5DA2(4-28A)5-D25A6-D25A7-24A9-22A11-20A13-D17A15-D13A2D18-7A2D3A24-3AD60-8(2BC2B27-)7(3BCB27-)3BCB14-C12-5C11-C2-A12-5C11-A2-AC3-C7-2CACA3-C6-CA2-2A3DA7D5A3DA6D2A3-2(28A4-)D27A5-D25A7-24A8-24A9-22A11-AD18A14-D15A17-8A2D4A21-5A2DA56-8(BC7B23-)7(C8B23-)C8B12-C2(10-2C5A2C9-C2-A)2(C4-)2C5A3C6-C-A2-2A4DA4D10A6DADA2-30A3-28A4-27AC5-26A6-26A7-24A9-21AC11-20A13-18A16-14A20-2C8A54-15(10BC21-)10B2(C10-)C9AC9-CA10-C9AC9-A-AC4-C3-C9AC2-C-2C2-C2-2A4DA3D11A2DAD2A2DA2(2-30A)3-28A4-28A5-26A7-24A8-24A9-22A12-C17A15-16A18-12A24-4A25-15(11B21-)11B2(10-C)9AC9-CD10-C9AC9-ADAC5-C2-C10A2C-C4-CA-2A5DA2D13ADA4DA2(2-30A)3-28A4-28A5-26A6-26A7-24A9-22A11-20A14-16A18-12A23-AC4A23-7BC5B7(19-13B)8(19-C12B)2(9-C)11AC8-CD9-C11AC8-CDAC6-2C11AC7-CD3A6D14A7DAD-2(30A2-)30A3-28A5-26A6-26A7-24A9-21AC11-18ADA14-15AD17-10A2D2A21-7AD22-C6BC5B7(19-C12B)8(19-13B)2(9-C)11AC8-CA9-C11AC8-2AC8-C11AC5-3CD2A8D13A5D3AD-30A2-C29A2-30A3-28A4-C26AD5-25AD7-24A9-22A11-C19A13-16A2D16-A2D7A2D2A21-7AD22-4BC2BC5B15(19-13B)2(9-C)11AC8-CA9-C11AC8-2A4C5-C12A5C2-C6A5D18A2D2A-2(30A2-)29AC3-28A4-27AD5-25AD7-24A9-22A11-20A13-18A16-A2D11A21-3A2D3A22-2(3BC)5B15(19-13B)2(9-C)11AC8-CA9-C11AC8-2A-C2-5C13AC6-C2ADA2D19A6D2A-2(30A2-)30A3-28A5-26A6-26A7-24A9-22A11-20A14-16A17-14A21-3A2D3A22-2B2(C4B)15(C19-12B)2(C9-)C11AC8-CA9-C11AC8-2A9-C12AC7-A-9D14A7D2(2-30A)3-28A4-28A5-26A6-26A7-D23A9-2D20A11-20A14-16A18-12A23-6A24-C5BC4B7(21-C10B)8(21-11B)2(10-C)9AC9-CA10-C9AC9-A11-C9AC2-C5-C2-10D11A2DA5DA2-D29A2-30A3-28A4-28A5-26A7-24A8-D23A9-2D20A12-18A15-16A18-12A24-4A25-6BC4B7(21-11B)8(21-C10B)11-C9-C9AC8-C2-A9-C9AC8-A2-AC5-3C10AC2-3C3-A2-DA5D14A2D3A3DA2-D29A3-28A4-28A5-26A6-26A7-24A9-22A11-20A13-15A2DA16-13AD20-10A55-5BC3B15(23-9B)12-C2(10-2C5A2C9-C2-A)C3-2C4-C6A3C5-3CA2-2A3D2A4D10A5D4A3-2(27AD4-)28A5-26A7-24A8-23AC9-22A11-20A14-14A2D17-13AD21-AC6A58-8(3BCB27-)7(4BC27-)4BC14-C12-5C11-C2-A12-5C11-C5-2C7-3C3A3-C6-C4-2D2A7D6A3DA6DA2(4-27AD)5-26A6-26A7-24A9-22A11-20A13-18A15-D15A18-12A24-2ACA560-C2(26-C4-A)C8-C3-CDC4-2C3-CA4-2A8DA3D3A4D2A3D2A5-2(26A6-)26A7-24A9-22A11-20A13-18A15-D15A17-D13A21-8A590-C26-C37-AC6-C4-C2DC5-2C-C6-2A6DA4D4A5D2ADA6-26A7-24A8-24A9-22A10-C21A11-20A13-18A16-D13A20-10A26-2A594-C24-C6-A24-A6-A2C4-C5-C2DC6-2CA7-2A4DA5D4A6D2A2(8-D23A)9-22A11-20A12-20A13-16A2D16-14A19-5A2D5A23-2A2D2A625-C22-C8-A22-A8-A3C-C6-C3DC-4C2A8-4ADA6D5AD6A9-D21A10-D21A11-20A13-18A14-16A2D16-14A19-10ACA22-3A2D3A657-C20-C10-A20-A10-2(AC)7-C4D2(2CA)10-4A7D11A11-19AC12-19AC13-18A15-16A17-14A19-9AC2A22-8A690-C18-C12-A18-A12-AC6-3CD2CDCAC2A13-A6D11A14-18A15-16A16-16A17-2A2D10A20-2D8A24-C5A724-2C14-2C15-A14-A16-A-3C-5CA3CA16-AD3AD10A17-14A18-14A19-12A22-D7A27-2A760-3C8-3C18-3A8-3A19-3A2C2(AC)3A20-12A21-7A2DA23-6A2D26-4A826-8C24-8A25-6A27-4A398-
