model
size = 19 21 11, scale = 0.05, origin = -y
material 
  colors = A:#FFC96B B:#FCDFAC C:#FE8E8E D:#90713B E:#4D2A0A F:#FFF
voxels
------------------- ------------------- ------------------- ------------------- ------------------- ------------------- ------------------- ------------------- --ACCAAAAAACCA----- -DDCCAAAAAACCDD---- --AEEAFFFFAEEA----- --AEEAFFFFAEEA----- --AAAAAAAAAAAA----- --AAAAAAAAAAAA----- --AAAAAAAAAAAA----- --AAAAAAAAAAAA----- --AAAAAAAAAAAA----- --AAAAAAAAAAAA----- --AAAAAAAAAAAA----- ------------------- ------------------- 
------------------- ------------------- ------------------- ------------------- ------------------- ------------------- ------------------- ------------------- --AAAAAAAACCAA----- DDAAAAAAAAAA--DD--- --AAAAAAAAAA-A----- --AAAAAAAAAA-A----- --AAAAAAAAAAAA----- --A---------AA----- --A----------A----- --A----------A----- --A----------A----- --AAAAAAAAAAAA----- --AAAAAAAAAAAA----- ------------------- ------------------- 
----AA---------AA-- ----AA---------AA-- ----AABBBBBBBBBAA-- ----AABBBBBBBBBAA-- ----AAAAAAAAAAAAA-- ----AAAAAAAAAAAAA-- ----AAAAAAAAAAAAA-- ----AAAAAAAAAAAAA-- --AAAAAAAAAAAA----- --AAAAAAAAAAAA----- --AAAAAAAAAAAA----- --AAAAAAAAAAAA----- --AAAAAAAAAAAA----- --A---------AA----- --A----------A----- --A----------A----- --A----------A----- --AAAAAAAAAAAA----- --AAAAAAAAAAAA----- ------------------- ------------------- 
----AA---------AA-- ----AA---------AA-- ----AABBBBBBBBBAA-- ----AAAAAAAAAAAAA-- ----AAAAAAAAAAAAA-- ----AAAAAAAAAAAAA-- ----AAAAAAAAAAAAA-- ----AAAAAAAAAAAAA-- --AAAAAAAAAAAA----- --AAAAAAAAAAAA----- --AAAAAAAAAAAA----- --AAAAAAAAAAAA----- --AAAAAAAAAAAA----- --A---------AA----- --A----------A----- --A----------A----- --A----------A----- --AAAAAAAAAAAA----- --AAAAAAAAAAAA----- ------------------- ------------------- 
------------------- ------------------- ----BBBBBBBBBBBBB-- ----BAAAAAAAAAAAB-- ----BAAAAAAAAAAAA-- ----BAAAAAAAAAAAA-- ----BAAAAAAAAAAA-AA ----BAAAAAAAAAAAAAA --AAAAAAAAAAAA----- --AAAAAAAAAAAA----- --AAAAAAAAAAAA-AAAA --AAAAAAAAAAAA-AAAA --AAAAAAAAAAAA-BB-- --AAAAAAAAA-AA-BB-- --AAAAAAAAA-AA----- --A----------A----- --A----------A----- --AAAAAAAAAAAA----- --AAAAAAAAAAAA----- ------------AA----- ------------AA----- 
------------------- ------------------- ----BBBBBBBBBBBBB-- ----BAAAAAAAAAAAB-- ----BAAAAAAAAAAAA-- ----BAAAAAAAAAAAA-- ----BAAAAAAAAAAA-AA ----BAAAAAAAAAAAAAA --AAAAAAAAAAAA----- --AAAAAAAAAAAA----- --AAAAAAAAAAAA-AAAA --AAAAAAAAAAAA-AAAA --AAAAAAAAAAAA-BB-- --AAAAAAAAA-AA-BB-- --AAAAAAAAA-AA----- --A----------A----- --A----------A----- --AAAAAAAAAAAA----- --AAAAAAAAAAAA----- ------------AA----- ------------AA----- 
------------------- ------------------- ----BBBBBBBBBBBBB-- ----BAAAAAAAAAAAB-- ----BAAAAAAAAAAAA-- ----BAAAAAAAAAAAA-- ----BAAAAAAAAAAAAAA ----BAAAAAAAAAAAAAA --AAAAAAAAAAAA---AA --AAAAAAAAAAAA---AA --AAAAAAAAAAAA---AA --AAAAAAAAAAAA---AA --AAAAAAAAAAAA----- --AAAAAAAAA-AA----- --AAAAAAAAAAAA----- --AAAAAAAAAAAA----- --AAAAAAAAAAAA----- --AAAAAAAAAAAA----- --AAAAAAAAAAAA----- --AA--------------- --AA--------------- 
------------------- ------------------- ----BBBBBBBBBBBBB-- ----BAAAAAAAAAAAB-- ----BAAAAAAAAAAAA-- ----BAAAAAAAAAAAA-- ----BAAAAAAAAAAAAAA ----BAAAAAAAAAAAAAA --AAAAAAAAAAAA---AA --AAAAAAAAAAAA---AA --AAAAAAAAAAAA---AA --AAAAAAAAAAAA---AA --AAAAAAAAAAAA----- --AAAAAAAAA-AA----- --AAAAAAAAAAAA----- --AAAAAAAAAAAA----- --AAAAAAAAAAAA----- --AAAAAAAAAAAA----- --AAAAAAAAAAAA----- --AA--------------- --AA--------------- 
-------AA----AA---- -------AA----AA---- ----AAABABBBBAAAA-- ----ABBAAAAAAAAAA-- ----AAAAAAAAAAAAA-- ----AAAAAAAAAAAAA-- ----AAAAAAAAAAAAA-- ----AAAAAAAAAAAAA-- --AAAAAAAAAAAA----- --AAAAAAAAAAAA----- --AAAAAAAAAAAA----- --AAAAAAAAAAAA----- --AAAAAAAAAAAA----- --AAAAAAAAA-AA----- --AAAAAAAAAAAA----- --AAAAAAAAAAAA----- --AAAAAAAAAAAA----- --AAAAAAAAAAAA----- --AAAAAAAAAAAA----- ------------------- ------------------- 
-------AA----AA---- -------AA----AA---- ----AAAAABBBBAAAA-- ----AAAAABBBBAAAA-- ----AAAAAAAAAAAAA-- ----AAAAAAAAAAAAA-- ----AAAAAAAAAAAAA-- ----AAAAAAAAAAAAA-- --AAAAAAAAAAAA----- --AAAAAAAAAAAA----- --AAAAAAAAAAAA----- --AAAAAAAAAAAA----- --AAAAAAAAAA-A----- --AAAAAAAAA-AA----- --AAAAAAAAAAAA----- --AAAAAAAAAAAA----- --AAAAAAAAAAAA----- --AAAAAAAAAAAA----- --AAAAAAAAAAAA----- ------------------- ------------------- 
------------------- ------------------- ------------------- ------------------- ------------------- ------------------- ------------------- ------------------- --AAAAAAAAAAAA----- --AAAAAAAAAAAA----- --AAAAAAAAAAAA----- --AAAAAAAAAAAA----- --AAAAAAAAAAAA----- --AAAAAAAAAAAA----- --AAAAAAAAAAAA----- --AAAAAAAAAAAA----- --AAAAAAAAAAAA----- --AAAAAAAAAAAA----- --AAAAAAAAAAAA----- ------------------- ------------------- 
