model
size = 10 7 8, scale = 0.05, origin = -y
material 
  colors = A:#9CF B:#FFF C:#1E1414 D:#FFEFEF
voxels
----BB---- ----BB---- --AAAAAA-- --AAAAAA-- ---------- ---------- ---------- 
---------- -A-C--C-A- -A-A-AA-A- -A------A- --AAAAAA-- --A-AA-A-- --A-AA-A-- 
-A------A- --A----A-- -A------A- -AA----AA- -AA----AA- ---BAAB--- ---------- 
-A------A- -A------A- --A----A-- -A------A- -AA----AA- AA-AAAA-AA A--------A 
-A------A- -A------A- -A------A- --A----A-- -AA----AA- ---DAAD--- ---------- 
---------- -A------A- -A------A- -A------A- --AAAAAA-- --A-AA-A-- --A-AA-A-- 
---A--A--- --A-AA-A-- --A----A-- --AAAAAA-- ---------- ---------- ---------- 
---A--A--- ---AAAA--- ---AAAA--- ---------- ---------- ---------- ---------- 
