model
size = 29 24 31, scale = 0.05, origin = -y
material 
  colors = A:#CFB53B B:#FF3 C:#DDD D:#F09 E:#111 F:#FFF
voxels
-AA------------------------AA -AAA----------------------AA- --AA--------------------AAA-- --AAAAA---------------AAA---- ----AAAAA-----------AAA------ -------AAAAAAAAAAAAAAA------- ----------------------------- ----------------------------- ----------------------------- ----------------------------- ----------------------------- ----------------------------- ----------------------------- ----------------------------- ----------------------------- ----------------------------- ----------------------------- ----------------------------- ----------------------------- ----------------------------- ----------------------------- ----------------------------- ----------------------------- ----------------------------- 
-AA------------------------AA -AAA----------------------AA- --AA--------------------AAA-- --AAAAA---------------AAA---- -------AA-----------AA------- -------AAAAAAAAAAAAAAA------- ----------------------------- ----------------------------- ----------------------------- ----------------------------- ----------------------------- ----------------------------- ----------------------------- ----------------------------- ----------------------------- ----------------------------- ----------------------------- ----------------------------- ----------------------------- ----------------------------- ----------------------------- ----------------------------- ----------------------------- ----------------------------- 
-AA------------------------AA -AAA----------------------AA- --AA--------------------AAA-- --AAAAA---------------AAA---- ----AAAAA-----------AAA------ -------AAAAAAAAAAAAAAA------- ----------------------------- ----------------------------- ----------------------------- ----------------------------- ----------------------------- ----------------------------- ----------------------------- ----------------------------- ----------------------------- ----------------------------- ----------------------------- ----------------------------- ----------------------------- ----------------------------- ----------------------------- ----------------------------- ----------------------------- ----------------------------- 
-AA------------------------AA -AAA----------------------AA- --AA--------------------AAA-- --AAAAA---------------AAA---- ----AAAAA-----------AAA------ -------AAAAAAAAAAAAAAA------- ----------------------------- ----------------------------- ----------------------------- ----------------------------- ----------------------------- ----------------------------- ----------------------------- ----------------------------- ----------------------------- ----------------------------- ----------------------------- ----------------------------- ----------------------------- ----------------------------- ----------------------------- ----------------------------- ----------------------------- ----------------------------- 
-AA------------------------AA -AAA----------------------AA- --AA--------------------AAA-- --AAAAA---------------AAA---- ----AAAAA-----------AAA------ -------AAAAAAAAAAAAAAA------- ----------------------------- ----------------------------- ----------------------------- ----------------------------- ----------------------------- ----------------------------- ----------------------------- ----------------------------- ----------------------------- ----------------------------- ----------------------------- ----------------------------- ----------------------------- ----------------------------- ----------------------------- ----------------------------- ----------------------------- ----------------------------- 
-AA------------------------AA -AAA----------------------AA- --AA--------------------AAA-- --AAAAA---------------AAA---- ----AAAAA-----------AAA------ -------AAAAAAAAAAAAAAA------- ----------------------------- ----------------------------- ----------------------------- ----------------------------- ----------------------------- ----------------------------- ----------------------------- ----------------------------- ----------------------------- ----------------------------- ----------------------------- ----------------------------- ----------------------------- ----------------------------- ----------------------------- ----------------------------- ----------------------------- ----------------------------- 
-AA------------------------AA -AAA----------------------AA- --AA--------------------AAA-- --AAAAA---------------AAA---- ----AAAAA-----------AAA------ -------AAAAAAAAAAAAAAA------- ----------------------------- ----------------------------- ----------------------------- ----------------------------- ----------------------------- ----------------------------- ----------------------------- ----------------------------- ----------------------------- ----------------------------- ----------------------------- ----------------------------- ----------------------------- ----------------------------- ----------------------------- ----------------------------- ----------------------------- ----------------------------- 
-AA------------------------AA -AAA----------------------AA- --AA--------------------AAA-- --AAAAA---------------AAA---- ----AAAAA-----------AAA------ -------AAAAAAAAAAAAAAA------- ----------------------------- ----------------------------- ----------------------------- ----------------------------- ----------------------------- ----------------------------- ----------------------------- ----------------------------- ----------------------------- ----------------------------- ----------------------------- ----------------------------- ----------------------------- ----------------------------- ----------------------------- ----------------------------- ----------------------------- ----------------------------- 
-AA------------------------AA -AAA----------------------AA- --AA--------------------AAA-- --AAAAA---------------AAA---- ----AAAAA-----------AAA------ -------AAAAAAAAAAAAAAA------- ----------------------------- ----------------------------- ----------------------------- ----------------------------- ----------------------------- ----------------------------- ----------------------------- ----------------------------- ----------------------------- ----------------------------- ----------------------------- ----------------------------- ----------------------------- ----------------------------- ----------------------------- ----------------------------- ----------------------------- ----------------------------- 
-AA------------------------AA -AAA----------------------AA- --AA--------------------AAA-- --AAAAA---------------AAA---- ----AAAAA-----------AAA------ -------AAAAAAAAAAAAAAA------- ----------------------------- ----------------------------- ----------------------------- ----------------------------- --------EEEEE---EEEEE-------- ----------E-------EE--------- ----------EE-----EE---------- -----------E-----EE---------- -----------EE---EE----------- ------------E---EE----------- ------------EE-EE------------ -------------E-EE------------ -------------E-E------------- --------------EE------------- ----------------------------- ----------------------------- ----------------------------- ----------------------------- 
-AA------------------------AA -AAA----------------------AA- --AA--------------------AAA-- --AAAAA---------------AAA---- ----AAAAA-----------AAA------ -------AAAAAAAAAAAAAAA------- ----------------------------- ------------CCCCC------------ -----------CCCCCCC----------- ---------CCCCCCCCCCC--------- --------CCCCCCCCCCCCC-------- --------CCCCCCCCCCCCC-------- -------CCCCCCCCCCCCCCC------- -------CCCCCCCCCCCCCCC------- -------CCCCCCCCCCCCCCC------- -------CCCCCCCCCCCCCCC------- --------CCCCCCCCCCCCC-------- ---------CCCCCCCCCCC--------- ----------CCCCCCCCC---------- -----------CCCCCCC----------- ------------CCCCC------------ ----------------------------- ----------------------------- ----------------------------- 
-AA------------------------AA -AAA----------------------AA- --AA--------------------AAA-- --AAAAA---------------AAA---- ----AAAAA-----------AAA------ -------AAAAAAAAAAAAAAA------- ----------------------------- --------------AA------------- -----AAAAAAAAAAAAAAAAAAA----- ----AAAAAAAAAAAAAAAAAAAAA---- ---AAAAAAAAAAAAAAAAAAAAAAA--- ---AAAAAAAAAAAAAAAAAAAAAAA--- ---AAAAAAAAAAAAAAAAAAAAAAA--- ---AAAAAAAAAAAAAAAAAAAAAAA--- ---AAAAAAAAAAAAAAAAAAAAAAA--- ---AAAAAAAAAAAAAAAAAAAAAAA--- ---AAAAAAAAAAAAAAAAAAAAAAA--- ----AAAAAAAAAAAAAAAAAAAAA---- ------------AAAAA------------ ----------------------------- ----------------------------- ----------------------------- ----------------------------- ----------------------------- 
-AA------------------------AA -AAA----------------------AA- --AA--------------------AAA-- --AAAAA---------------AAA---- ----AAAAA-----------AAA------ -------AAAAAAAAAAAAAAA------- -------AAAAAAAAAAAAAAA------- -----AAAAAAAAAAAAAAAAAAA----- ----ABBBBBBBBBBBBBBBBBBBAA--- ---ABBBBBBBBBBBBBBBBBBBBBAA-- ---ABBBBBBBBBBBBBBBBBBBBBBA-- --ABBBBBBBBBBBBBBBBBBBBBBBA-- --ABBBBBBBBBBBBBBBBBBBBBBBA-- --ABBBBBBBBBBBBBBBBBBBBBBBA-- --ABBBBBBBBBBBBBBBBBBBBBBBA-- --ABBBBBBBBBBBBBBBBBBBBBBBA-- --ABBBBBBBBBBBBBBBBBBBBBBBA-- --AAAAAAAAAAAAAAAAAAAAAAAAA-- ---AAAAAAAAAAAAAAAAAAAAAAA--- ----------------------------- ----------------------------- ----------------------------- ----------------------------- ----------------------------- 
-AA------------------------AA -AAA----------------------AA- --AA--------------------AAA-- --AAAAA---------------AAA---- ----AAAAA-----------AAA------ -------AAAAAAAAAAAAAAA------- ------A---------AAAAAAA------ -----AAAAAAAAAAAAAAAAAAA----- ----ABBBBBBBBBBBBBBBBBBBAA--- ---ABBBBBBBBBBBBBBBBBBBBBAA-- --AB-BBBBBBBBBBBBBBBBBBBBBA-- --ABBBBBBBBBBBBBBBBBBBBBBBAA- -AABBBBBBBBBBBBBBBBBBBBBBBAA- -AAAAAAAAAAAAAAAAAAAAAAAAAAA- -AABBBBBBBBBBBBBBBBBBBBBBBAA- -AABBBBBBBBBBBBBBBBBBBBBBBAA- -AABBBBBBBBBBBBBBBBBBBBBBBAA- -AAAAAAAAAAAAAAAAAAAAAAAAAAA- --AAAAAAAAAAAAAAAAAAAAAAAAA-- ---AAAAAAAAAAAAAAAAAAAAAAA--- ----------------------------- ----------------------------- ----------------------------- ----------------------------- 
-AA------------------------AA -AAA----------------------AA- --AA--------------------AAA-- --AAAAA---------------AAA---- ----AAAAA-----------AAA------ -------AAAAAAAAAAAAAAA------- ------AAAAAAAAAAAAAAAAA------ -----AAAAAAAAAAAAAAAAAAA----- ----ABBBBBBBBBBBBBBBBBBBAA--- ---ABBBBBBBBBBBBBBBBBBBBBAA-- --ABBBBBBBBBBBBBBBBBBBBBBBAA- -AABBBBBBBBBBBBBBBBBBBBBBBAA- -AABBBBBBBBBBBBBBBBBBBBBBBAA- -AABBBBBBBBBBBBBBBBBBBBBBBAA- -AABBBBBBBBBBBBBBBBBBBBBBBAA- -AABBBBBBBBBBBBBBBBBBBBBBBAA- -AABBBBBBBBBBBBBBBBBBBBBBBAA- -ABBBBBBBBBBBBBBBBBBBBBBBBBA- -AAAAAAAAAAAAAAAAAAAAAAAAAAA- --AAAAAAAAAAAAAAAAAAAAAAAAA-- ----------------------------- ----------------------------- ----------------------------- ----------------------------- 
-AA------------------------AA -AAA----------------------AA- --AA--------------------AAA-- --AAAAA---------------AAA---- ----AAAAA-----------AAA------ -------AAAAAAAAAAAAAAA------- ------AAAAAAAAAAAAAAAAA------ -----AAAAAAAAAAAAAAAAAAA----- ----ABBBBBBBBBBBBBBBBBBBAA--- ---ABBBBBBBBBBBBBBBBBBBBBAA-- --ABBBBBBBBBBBBBBBBBBBBBBBAA- -AA-AAAAAAAAAAAAAAAAAAAAAAAA- AAAAAAAAAAAAAAAAAAAAAAAAAAAAA AAADDDDDBB-BBBBBBDDBBBDDDDAAA AAADDDDDBBBBBBBB-DDBBBDDDDAAA AAADDDDDBBBBBBBBBDDBBBDDDDAAA AAADDDDDBBBBBBBBBDDBBBDDDDAAA AAAAAAAAAAAAAAAA-AAAAAAAAAAAA -AA-AAAAAAAAAAAAAAAAAAAAAAAA- --AAAAAAAAAAAAAAAAAAAAAAAAAA- ---AAAAAAAAAAAAAAAAAAAAAAA--- ----------------------------- ----------------------------- ----------------------------- 
-AA------------------------AA -AAA----------------------AA- --AA--------------------AAA-- --AAAAA---------------AAA---- ----AAAAA-----------AAA------ -------AAAAAAAAAAAAAAA------- ------AAAAAAAAAAAAAAAAA------ -----AAAAAAAAAAAAAAAAAAA----- ----ABBBBBBBBBBBBBBBBBBBAA--- ---ABBBBBBBBBBBBBBBBBBBBBAA-- --ABBBBBBBBBBBBBBBBBBBBBBBAA- AAAAAAAAAAAAAAAAAAAAAAAAAAAAA AAAAAAAAAAAAAAAAAAAAAAAAAAAAA AAADDDDDDDBDDDDDDDDDDDDDDDAAA AAADDDDDDDDDDDDDBBDDDDDDDDAAA AAABBBBBBBBBBBBBBBBBBBBBBBAAA AAABBBBBBBBBBBBBBBBBBBBBBBAAA AABBBBBBBBBBBBBB-BBBBBBBBBBAA AAAAAAAAAAAAAAAAAAAAAAAAAAAAA -AAAAAAAAAAAAAAAAAAAAAAAAAAA- --AAAAAAAAAAAAAAAAAAAAAAAAA-- ----------------------------- ----------------------------- ----------------------------- 
-AA------------------------AA -AAA----------------------AA- --AA--------------------AAA-- --AAAAA---------------AAA---- ----AAAAA-----------AAA------ -------AAAAAAAAAAAAAAA------- ------AAAAAAAAAAAAAAAAA------ -----AAAAAAAAAAAAAAAAAAA----- ----ABBBBBBBBBBBBBBBBBBBAA--- ---ABBBBBBBBBBBBBBBBBBBBBAA-- --ABBBBBBBBBBBBBBBBBBBBBBBAA- AAAAAAAAAAAAAAAAAAAAAAAAAAAAA AAAAAAAAAAAAAAAAAAAAAAAAAAAAA AAABBBBBBBBBBBBBBBBBBBBBBBAAA AAABBBBBBBBBBBBBBBBBBBBBBBAAA AAABBBBBBBBBBBBBBBBBBBBBBBAAA AAABBBBBBBBBBBBBBBBBBBBBBBAAA AADDDDDDDDDDDDDDBDDDDDDDDDDAA AAAAAAAAAAAAAAAAAAAAAAAAAAAAA -AAAAAAAAAAAAAAAAAAAAAAAAAAA- --AAAAAAAAAAAAAAAAAAAAAAAAAA- ---AAAAAAAAAAAAAAAAAAAAAAAA-- ----------------------------- ----------------------------- 
-AA------------------------AA -AAA----------------------AA- --AA--------------------AAA-- --AAAAA---------------AAA---- ----AAAAA-----------AAA------ -------AAAAAAAAAAAAAAA------- ------AAAAAAAAAAAAAAAAA------ -----AAAAAAAAAAAAAAAAAAA----- ----ABBBBBBBBBBBBBBBBBBBAA--- ---ABBBBBBBBBBBBBBBBBBBBBAA-- --ABBBBBBBBBBBBBBBBBBBBBBBAA- AAAAAAAAAAAAAAAAAAAAAAAAAAAAA AAAAAAAAAAAAAAAAAAAAAAAAAAAAA AAABBBBBBBBBBBBBBBBBBBBBBBAAA AAABBBBBBBBBBBBBBBBBBBBBBBAAA AAABBBBBBBBBBBBBBBBBBBBBBBAAA AAABBBBBBBBBBBBBBBBBBBBBBBAAA AABBBBBBBBBBBBBBBBBBBBBBBBBAA AAAAAAAAAAAAAAAAAAAAAAAAAAAAA -AAAAAAAAAAAAAAAAAAAAAAAAAAA- --AAAAAAAAAAAAAAAAAAAAAAAAAA- ---AAAAAAAAAAAAAAAAAAAAAAAA-- ----AAAAAAAAAAAAAAAAAAAAAA--- ----------------------------- 
-AA------------------------AA -AAA----------------------AA- --AA--------------------AAA-- --AAAAA---------------AAA---- ----AAAAA-----------AAA------ -------AAAAAAAAAAAAAAA------- ------AAAAAAAAAAAAAAAAA------ -----AAAAAAAAAAAAAAAAAAA----- ----ABBBBBBBBBBBBBBBBBBBAA--- ---ABBBBBBBBBBBBBBBBBBBBBAA-- --ABBBBBBBBBBBBBBBBBBBBBBBAA- AAAAAAAAAAAAAAAAAAAAAAAAAAAAA AAAAAAAAAAAAAAAAAAAAAAAAAAAAA AAABBBBBBBBBBBBBBBBBBBBBBBAAA AAABBBBBBBBBBBBBBBBBBBBBBBAAA AAABBBBBBBBBBBBBBBBBBBBBBBAAA AAABBBBBBBBBBBBBBBBBBBBBBBAAA AABBBBBBBBBBBBBBBBBBBBBBBBBAA AAAAAAAAAAAAAAAAAAAAAAAAAAAAA -AAAAAAAAAAAAAAAAAAAAAAAAAAA- --AAAAAAAAAAAAAAAAAAAAAAAAAA- ---AAAAAAAAAAAAAAAAAAAAAAAA-- ----AAAAAAAAAAAAAAAAAAAAAA--- -------------FC-------------- 
-AA------------------------AA -AAA----------------------AA- --AA--------------------AAA-- --AAAAA---------------AAA---- ----AAAAA-----------AAA------ -------AAAAAAAAAAAAAAA------- ------AAAAAAAAAAAAAAAAA------ -----AAAAAAAAAAAAAAAAAAA----- ----ABBBBBBBBBBBBBBBBBBBAA--- ---ABBBBBBBBBBBBBBBBBBBBBAA-- --ABBBBBBBBBBBBBBBBBBBBBBBAA- AAAAAAAAAAAAAAAAAAAAAAAAAAAAA AAAAAAAAAAAAAAAAAAAAAAAAAAAAA AAABBBBBBBBBBBBBBBBBBBBBBBAAA AAABBBBBBBBBBBBBBBBBBBBBBBAAA AAABBBBBBBBBBBBBBBBBBBBBBBAAA AAABBBBBBBBBBBBBBBBBBBBBBBAAA AABBBBBBBBBBBBBBBBBBBBBBBBBAA AAAAAAAAAAAAAAAAAAAAAAAAAAAAA -AAAAAAAAAAAAAAAAAAAAAAAAAAA- --AAAAAAAAAAAAAAAAAAAAAAAAAA- ---AAAAAAAAAAAAAAAAAAAAAAAA-- ----AAAAAAAAAAAAAAAAAAAAAA--- -------------CF-------------- 
-AA------------------------AA -AAA----------------------AA- --AA--------------------AAA-- --AAAAA---------------AAA---- ----AAAAA-----------AAA------ -------AAAAAAAAAAAAAAA------- ------AAAAAAAAAAAAAAAAA------ -----AAAAAAAAAAAAAAAAAAA----- ----ABBBBBBBBBBBBBBBBBBBAA--- ---ABBBBBBBBBBBBBBBBBBBBBAA-- --ABBBBBBBBBBBBBBBBBBBBBBBAA- AAAAAAAAAAAAAAAAAAAAAAAAAAAAA AAAAAAAAAAAAAAAAAAAAAAAAAAAAA AAABBBBBBBBBBBBBBBBBBBBBBBAAA AAABBBBBBBBBBBBBBBBBBBBBBBAAA AAABBBBBBBBBBBBBBBBBBBBBBBAAA AAABBBBBBBBBBBBBBBBBBBBBBBAAA AABBBBBBBBBBBBBBBBBBBBBBBBBAA AAAAAAAAAAAAAAAAAAAAAAAAAAAAA -AAAAAAAAAAAAAAAAAAAAAAAAAAA- --AAAAAAAAAAAAAAAAAAAAAAAAAA- ---AAAAAAAAAAAAAAAAAAAAAAAA-- ----AAAAAAAAAAAAAAAAAAAAAA--- ----------------------------- 
-AA------------------------AA -AAA----------------------AA- --AA--------------------AAA-- --AAAAA---------------AAA---- ----AAAAA-----------AAA------ -------AAAAAAAAAAAAAAA------- ------AAAAAAAAAAAAAAAAA------ -----AAAAAAAAAAAAAAAAAAA----- ----ABBBBBBBBBBBBBBBBBBBAA--- ---ABBBBBBBBBBBBBBBBBBBBBAA-- --ABBBBBBBBBBBBBBBBBBBBBBBAA- AAAAAAAAAAAAAAAAAAAAAAAAAAAAA AAAAAAAAAAAAAAAAAAAAAAAAAAAAA AAABBBBBBBBBBBBBBBBBBBBBBBAAA AAABBBBBBBBBBBBBBBBBBBBBBBAAA AAABBBBBBBBBBBBBBBBBBBBBBBAAA AAABBBBBBBBBBBBBBBBBBBBBBBAAA AABBBBBBBBBBBBBBBBBBBBBBBBBAA AAAAAAAAAAAAAAAAAAAAAAAAAAAAA -AAAAAAAAAAAAAAAAAAAAAAAAAAA- --AAAAAAAAAAAAAAAAAAAAAAAAAA- ---AAAAAAAAAAAAAAAAAAAAAAAA-- ----AAAAAAAAAAAAAAAAAAAAAA--- ----------------------------- 
-AA------------------------AA -AAA----------------------AA- --AA--------------------AAA-- --AAAAA---------------AAA---- ----AAAAA-----------AAA------ -------AAAAAAAAAAAAAAA------- ------AAAAAAAAAAAAAAAAA------ -----AAAAAAAAAAAAAAAAAAA----- ----ABBBBBBBBBBBBBBBBBBBAA--- ---ABBBBBBBBBBBBBBBBBBBBBAA-- --ABBBBBBBBBBBBBBBBBBBBBBBAA- AAAAAAAAAAAAAAAAAAAAAAAAAAAAA AAAAAAAAAAAAAAAAAAAAAAAAAAAAA AAABBBBBBBBBBBBBBBBBBBBBBBAAA AAABBBBBBBBBBBBBBBBBBBBBBBAAA AAABBBBBBBBBBBBBBBBBBBBBBBAAA AAABBBBBBBBBBBBBBBBBBBBBBBAAA AABBBBBBBBBBBBBBBBBBBBBBBBBAA AAAAAAAAAAAAAAAAAAAAAAAAAAAAA -AAAAAAAAAAAAAAAAAAAAAAAAAAA- --AAAAAAAAAAAAAAAAAAAAAAAAAA- ---AAAAAAAAAAAAAAAAAAAAAAAA-- ----------------------------- ----------------------------- 
-AA------------------------AA -AAA----------------------AA- --AA--------------------AAA-- --AAAAA---------------AAA---- ----AAAAA-----------AAA------ -------AAAAAAAAAAAAAAA------- ------AAAAAAAAAAAAAAAAA------ -----AAAAAAAAAAAAAAAAAAA----- ----ABBBBBBBBBBBBBBBBBBBAA--- ---ABBBBBBBBBBBBBBBBBBBBBAA-- --ABBBBBBBBBBBBBBBBBBBBBBBAA- AAAAAAAAAAAAAAAAAAAAAAAAAAAAA AAAAAAAAAAAAAAAAAAAAAAAAAAAAA AAABBBBBBBBBBBBBBBBBBBBBBBAAA AAABBBBBBBBBBBBBBBBBBBBBBBAAA AAABBBBBBBBBBBBBBBBBBBBBBBAAA AAABBBBBBBBBBBBBBBBBBBBBBBAAA AABBBBBBBBBBBBBBBBBBBBBBBBBAA AAAAAAAAAAAAAAAAAAAAAAAAAAAAA -AAAAAAAAAAAAAAAAAAAAAAAAAAA- --AAAAAAAAAAAAAAAAAAAAAAAAAA- ----------------------------- ----------------------------- ----------------------------- 
-AA------------------------AA -AAA----------------------AA- --AA--------------------AAA-- --AAAAA---------------AAA---- ----AAAAA-----------AAA------ -------AAAAAAAAAAAAAAA------- ------AAAAAAAAAAAAAAAAA------ -----AAAAAAAAAAAAAAAAAAA----- ----ABBBBBBBBBBBBBBBBBBBAA--- ---ABBBBBBBBBBBBBBBBBBBBBAA-- --ABBBBBBBBBBBBBBBBBBBBBBBAA- AAAAAAAAAAAAAAAAAAAAAAAAAAAAA AAAAAAAAAAAAAAAAAAAAAAAAAAAAA AAABBBBBBBBBBBBBBBBBBBBBBBAAA AAABBBBBBBBBBBBBBBBBBBBBBBAAA AAABBBBBBBBBBBBBBBBBBBBBBBAAA AAABBBBBBBBBBBBBBBBBBBBBBBAAA AABBBBBBBBBBBBBBBBBBBBBBBBBAA AAAAAAAAAAAAAAAAAAAAAAAAAAAAA -AAAAAAAAAAAAAAAAAAAAAAAAAAA- --AAAAAAAAAAAAAAAAAAAAAAAAAA- ----------------------------- ----------------------------- ----------------------------- 
-AA------------------------AA -AAA----------------------AA- --AA--------------------AAA-- --AAAAA---------------AAA---- ----AAAAA-----------AAA------ -------AAAAAAAAAAAAAAA------- ------AAAAAAAAAAAAAAAAA------ -----AAAAAAAAAAAAAAAAAAA----- ----ABBBBBBBBBBBBBBBBBBBAA--- ---ABBBBBBBBBBBBBBBBBBBBBAA-- --ABBBBBBBBBBBBBBBBBBBBBBBAA- AAAAAAAAAAAAAAAAAAAAAAAAAAAAA AAAAAAAAAAAAAAAAAAAAAAAAAAAAA AAABBBBBBBBBBBBBBBBBBBBBBBAAA AAABBBBBBBBBBBBBBBBBBBBBBBAAA AAABBBBBBBBBBBBBBBBBBBBBBBAAA AAABBBBBBBBBBBBBBBBBBBBBBBAAA AABBBBBBBBBBBBBBBBBBBBBBBBBAA AAAAAAAAAAAAAAAAAAAAAAAAAAAAA -AAAAAAAAAAAAAAAAAAAAAAAAAAA- ----------------------------- ----------------------------- ----------------------------- ----------------------------- 
-AA------------------------AA -AAA----------------------AA- --AA--------------------AAA-- --AAAAA---------------AAA---- ----AAAAA-----------AAA------ -------AAAAAAAAAAAAAAA------- -------AAAAAAAAAAAAAAAA------ -----A-AAAAAAAAAAAAAAAAA----- ----AB-BBBBBBBBBBBBBBBBBAA--- ---ABB-BBBBBBBBBBBBBBBBBBAA-- --ABBB-BBBBBBBBBBBBBBBBBBBAA- AAAAAA-AAAAAAAAAAAAAAAAAAAAAA AAAAAA-AAAAAAAAAAAAAAAAAAAAAA AAABBB-BBBBBBBBBBBBBBBBBBBAAA AAABBB-BBBBBBBBBBBBBBBBBBBAAA AAABBB-BBBBBBBBBBBBBBBBBBBAAA AAABBB-BBBBBBBBBBBBBBBBBBBAAA AABBBB-BBBBBBBBBBBBBBBBBBBBAA -AAAAAAAAAAAAAAAAAAAAAAAAAAA- ----------------------------- ----------------------------- ----------------------------- ----------------------------- ----------------------------- 
----------------------------- -AAA----------------------AA- --AA--------------------AAA-- --AAAAA---------------AAA---- ----AAAAA-----------AAA------ -------AAAAAAAAAAAAAAA------- ----------------------------- -----AAAAAAAAAAAAAAAAAAA----- ----ABBBBBBBBBBBBBBBBBBBAA--- ---ABBBBBBBBBBBBBBBBBBBBBAA-- --ABBBBBBBBBBBBBBBBBBBBBBBAA- -AAAAAAAAAAAAAAAAAAAAAAAAAAA- AAAAAAAAAAAAAAAAAAAAAAAAAAAAA AAABBBBBBBBBBBBBBBBBBBBBBBAAA AAABBBBBBBBBBBBBBBBBBBBBBBAAA AAABBBBBBBBBBBBBBBBBBBBBBBAAA AAABBBBBBBBBBBBBBBBBBBBBBBAAA -AAAAAAAAAAAAAAAAAAAAAAAAAAA- ----------------------------- ----------------------------- ----------------------------- ----------------------------- ----------------------------- ----------------------------- 
----------------------------- --AA------------------------- --AA--------------------AAA-- --AAAAA---------------AAA---- ----AAAAA-----------AAA------ -------AAAAAAAAAAAAAAA------- ----------------------------- ----------------------------- ----AAAAAAAAAAAAAAAAAAAAAA--- ---ABBBBBBBBBBBBBBBBBBBBBAA-- --AAAAAAAAAAAAAAAAAAAAAAAAAA- ----------------------------- -AAAAAAAAAAAAAAAAAAAAAAAAAAA- AAAAAAAAAAAAAAAAAAAAAAAAAAAAA AAAAAAAAAAAAAAAAAAAAAAAAAAAAA AAAAAAAAAAAAAAAAAAAAAAAAAAAAA -AAAAAAAAAAAAAAAAAAAAAAAAAAA- ----------------------------- ----------------------------- ----------------------------- ----------------------------- ----------------------------- ----------------------------- ----------------------------- 
----------------------------- ----------------------------- ----------------------------- --AAAAA---------------AAA---- ----------------------------- ----------------------------- ----------------------------- ----------------------------- ----------------------------- ---AAAAAAAAAAAAAAAAAAAAAAAA-- ----------------------------- ----------------------------- ----------------------------- ----------------------------- ----------------------------- ----------------------------- ----------------------------- ----------------------------- ----------------------------- ----------------------------- ----------------------------- ----------------------------- ----------------------------- ----------------------------- 
