model
size = 10 10 9, scale = 0.05, origin = -y
material 
  colors = A:#555 B:#888 C:#F9C D:#777 E:#444 F:#222 G:#111
voxels
-C-------- ---------- ---------- ---------- ---------- ---------- ---------- ---------- ---------- ---------- 
CC-------- ---------- ---------- ---------- ---------- ---------- ---------- ---------- ---------- ---------- 
C----AAE-- -----AE--- ---------- ------AAE- ------A--- ---------- ---------- ---------- -----A---- -----A---- 
CC--AAA--- ----AAA--- ----AAA--- -----AA--- -----AA--- ------A--- ---------- ---------- -----A---- -----A---- 
-CCAAABD-- ---AAABD-- ---AAABD-- ---AAAB--- ----AAA--- ----AAA--- ----AAAA-- -----AFA-- -----AA--- ---------- 
---AAABD-- ---AAABD-- ---AAABD-- ---AAABD-- ----AAB--- ----AAA--- ----AAAA-- ----AAFAAC ----AAA--- ---------- 
----AAB--- ----AAB--- ----AAB--- ----AAA--- ----AAA--- ----AAA--- -----AAA-- -----AGA-- -----AA--- ---------- 
-----AAE-- -----AE--- ---------- ------AAE- ------A--- ------A--- ---------- ---------- -----A---- -----A---- 
---------- ---------- ---------- ---------- ---------- ---------- ---------- ---------- -----A---- -----A---- 
