model
size = 20 32 24, scale = 0.05, origin = -y
material 
  colors = A:#CB1B45 B:#AF173A C:#DB1233 D:#572A32 E:#FFB11B F:#BA9132 G:#F7C242 H:#555 I:#AAA J:#E87A90 K:#222 L:#DB4D6D
voxels
149-2C17-4C15-2C2-2C13-8(C-C2-C-C12-)C-C2-C-C11-4C2B4C12-2C2-2C15-2(C2-C16-)C2-C277-2D17-D2BD15-DB2CBD13-DB4CBD10-2DB2C2-2CB2D8-2BC6-C2B8(8-C10-C)8-12C8-5C2E5C8-2D3C2E3C2D9-2D2C2E2C2D11-D2C2-2CD13-2C2-2C15-C2EC17-2E178-2A17-4A15-3(6A14-)6A10-D3-6B3-D6-B12-B6-C12-C126-C12-C6-BC10-CB6-D12-D71-2(C2-C16-)C2EC16-E2-E97-2D17-4D16-D2BD15-DB2-BD13-2B4-2B4(12-A6-A)8-D3-B6-B3-D4-B14-B8(4-C14-C)4-B14-B4-D14-D110-C2-C16-C2-C15-2E2-2E13-GEF2-FEG92-2D4-2D10-3D6-3D2(8-2B)8(8-2A)5-D2-2B8-2B2-D2-B16-B8(2-C16-C)2-B2-12B2-B2-D2-ABDB4ABDBA2-D5-ABDB4ABDBA9-BDB4ABDB11-DB4ABD15-2A95-GEF2-FEG110-D10-D8-B10-B3(8-A10-A)7-A12-A6-B12-B3-D18-DB18-BC6(18-2C)18-CB2-B12-B2-BD2-A12-A2-D3-A12-A7-A10-A9-BD6-DB11-DB4ABD15-2A76-E4-E13-GEF2-FEG89-D12-D6-B12-B3(6-A12-A)5-A14-A4-B14-B2-D18-DB18-BC6(18-2C)18-CB-B14-B-BD-A14-A-D2-A14-A5-A12-A7-A10-A9-B8-B11-DB4ABD15-2A75-GEF2-FEG13-EF2-FE70-D12-D6-B12-B3(6-A12-A)5-A14-A4-B14-B2-D18-DB18-BC6(18-2C)18-CB-B14-B-BD-A14-A-D2-A14-A4-A14-A5-A12-A7-A10-A9-B8-B11-DB4ABD71-2GEF2-FE2G12-EF2-FE69-D14-D4-B14-B3(4-A14-A)3-A16-A2-B16-B-D18-DB18-BC6(18-2C)18-C2B16-2BD2A14-2AD-2A14-2A2-JA14-AJ3-A14-A5-A12-A7-A10-A9-BD6-DB12-B4AB52-2GEF2-FE2G11-GEF2-FEG68-D14-D4-B14-B3(4-A14-A)3-A16-A2-B16-B21-D18-DB18-BC4(18-2C)B16-B2CB16-BC2B16-2BD2A14-2AD-2(2A14-2A2-)JA14-AJ3-A14-A5-A12-A7-2A8-2A9-BDB4ABDB50-2GEF2-FE2G11-GEF2-FEG68-D14-D4-B14-B3(4-A14-A)3-A16-A2-B16-B41-D18-DB3(18-2B)18-3B16-3BA16-A2BA16-ABD2A14-2AD-2(2A14-2A2-)JA14-AJ3-A14-A4-2A12-2A5-2A10-2A8-BD6ADB12-B4AB32-2GEF2-FE2G11-GEF2-FEG68-2(D14-D4-)B14-B2(4-A14-A)3-A16-A2(2-B16-B)21-D5(18-2D)B16-B2D2A14-2A2DLA14-AL2DKA14-AKD-2(2A14-2A2-)JA14-AJ3-A14-A4-2A12-2A5-2A10-2A8-BD6ADB12-B4AB32-2GEF2-FE2G11-GEF2-FEG88-D14-D4-B14-B2(4-A14-A)3-2A14-2A2-A16-A6(2-B16-B)-H2(B16-B2H)2A14-2A2H2A14-2AHD2A14-2AD-2(2A14-2A2-)JA14-AJ3-A14-A4-A14-A5-2A10-2A8-BD6ADB12-BA2BAB32-2GEF2-FE2G11-GEF2-FEG88-2(D14-D4-)B14-B4-A14-A3-6(2A14-2A2-)BA14-AB-H2A14-2AHI3(2A14-2A2I)2A14-2AIH2A14-2AH-BA14-AB2-2A14-2A2-JA14-AJ3-A14-A4-A14-A5-2A10-2A8-BD6ADB12-BA2BAB32-2GEF2-FE2G11-GEF2-FEG108-D14-D4-B14-B4-A14-A3-6(2A14-2A2-)BA14-AB-H2A14-2AHI3(2A14-2A2I)2A14-2AIH2A14-2AH-BA14-AB2-2A14-2A2-JA14-AJ3-A14-A4-2A12-2A5-2A10-2A8-BD6ADB12-BA2BAB32-2GEF2-FE2G11-GEF2-FEG108-2(D14-D4-)B14-B3-6(2A14-2A2-)BA14-AB-H2A14-2AHI3(2A14-2A2I)2A14-2AIH2A14-2AH-BA14-AB2-2A14-2A2-JA14-AJ3-A14-A4-2A12-2A5-2A10-2A8-BD6ADB12-B4AB33-GEF2-FEG12-GEF2-FEG128-D14-D4-B14-B3-6(2A14-2A2-)BA14-AB-H2A14-2AHI3(2A14-2A2I)2A14-2AIH2A14-2AH-BA14-AB2-2A14-2A2-JA14-AJ3-A14-A5-A12-A7-2A8-2A9-BDB4ABDB52-EF2-FE14-EF2-FE129-D14-D4-B14-B3-7(2A14-2A2-)BA14-AB-H3(2A14-2A2H)2A14-2AH-BA14-AB2(2-2A14-2A)2-JA14-AJ4-A-B8-B-A7-ABD6-DBA9-BD6-DB11-DB4ABD53-EF2-FE15-F2-F131-D12-D6-B12-B5-2A12-2A3-7(2A14-2A2-)4(BA14-AB2-)2(2A14-2A2-)2A14-2A3-2A12-2A6-AB8-BA9-BD6-DB11-DB4ABD74-F2-F16-F2-F132-D10-D8-B10-B7-2A10-2A5-2(A14-A4-)A14-A3-6(2A14-2A2-)2A14-2A3-2(A14-A4-)A14-A5-A12-A7-AB8-BA9-BD6-DB11-DB4ABD94-F2-F16-F2-F133-D8-D10-B8-B9-AB8-BA7-2(A12-A6-)A12-A5-6(A14-A4-)A14-A5-2(A12-A6-)A12-A7-A10-A9-BD6-DB11-DB4ABD114-F2-F154-8D12-D6BD11-BD6-DB9-AB8-B2(A8-A10-)A7-6(2A10-2A6-)2A10-2A7-2(A10-A8-)AB8-BA9-BD6-DB11-DB4ABD333-BA2BAB13-DB4ABD11-10(BDB4ABDB10-)BDB4ABDB11-DB4ABD13-BA2BAB394-6(BA2BAB14-)B4A2(B14-BA2BA)B14-B4AB14-BA2BAB227-
