model
size = 29 20 29, scale = 0.05, origin = -y
material 
  colors = A:#CC0 B:#CF0 C:#03C
voxels
--------AAAAAAAAAAAAA-------- --------AAAAAACAAAAAA-------- --------AAAAACCCAAAAA-------- ------------ACCCA------------ -------------ACA------------- --------------A-------------- ----------------------------- ----------------------------- ----------------------------- ----------------------------- ----------------------------- ----------------------------- ----------------------------- ----------------------------- ----------------------------- ----------------------------- ----------------------------- ----------------------------- ----------------------------- ----------------------------- 
--------AAAAAAAAAAAAA-------- --------AAAAAAAAAAAAA-------- --------AAAAAAAAAAAAA-------- -------------AAA------------- --------------A-------------- ----------------------------- ----------------------------- ----------------------------- ----------------------------- ----------------------------- ----------------------------- ----------------------------- ----------------------------- ----------------------------- ----------------------------- ----------------------------- ----------------------------- ----------------------------- ----------------------------- ----------------------------- 
------AAAAAAAAAAAAAAAAA------ ------AAAAAAAAAAAAAAAAA------ ------AAAAAAAAAAAAAAAAA------ ----------------------------- ----------------------------- ----------------------------- ----------------------------- ----------------------------- ----------------------------- ----------------------------- ----------------------------- ----------------------------- ----------------------------- ----------------------------- ----------------------------- ----------------------------- ----------------------------- ----------------------------- ----------------------------- ----------------------------- 
-----AAAAAAAAAAAAAAAAAAAA---- -----AAAAAAAAAAAAAAAAAAAA---- -----AAAAAAAAAAAAAAAAAAAA---- ---------AAAAAAAAAA---------- ---------AAAAAAAAAA---------- ---------AAAAAAAAAA---------- ---------AAAAAAAAAA---------- ---------AAAAAAAAAA---------- ---------AAAAAAAAAA---------- ---------BBBBBBBBBB---------- ---------AAAAAAAAAA---------- ---------AAAAAAAAAA---------- ---------AAAAAAAAAA---------- ---------AAAAAAAAAA---------- ---------AAAAAAAAAA---------- ---------AAAAAAAAAA---------- ---------AAAAAAAAAA---------- ---------BBBBBBBBBB---------- ---------BBBBBBBBBB---------- ----------------------------- 
-----AAAAAAAAAAAAAAAAAAAA---- -----AAAAAAAAAAAAAAAAAAAA---- -----AAAAAAAAAAAAAAAAAAAA---- ---------AAAAAAAAAA---------- ---------AAAAAAAAAA---------- ---------AAAAAAAAAA---------- ---------AAAAAAAAAA---------- ---------AAAAAAAAAA---------- ---------AAAAAAAAAA---------- ---------BBBBBBBBBB---------- ---------AAAAAAAAAA---------- ---------AAAAAAAAAA---------- ---------AAAAAAAAAA---------- ---------AAAAAAAAAA---------- ---------AAAAAAAAAA---------- ---------AAAAAAAAAA---------- ---------AAAAAAAAAA---------- ---------BBBBBBBBBB---------- ---------BBBBBBBBBB---------- ----------------------------- 
---AAAAAA----------AAAAAAA--- ---AAAAAA----------AAAAAAA--- ---AAAAAA----------AAAAAAA--- ------AAA----------AAAA------ ------AAA----------AAAA------ ------AAA----------AAAA------ ------AAA----------AAAA------ ------AAA----------AAAA------ ------AAA----------AAAA------ ------BBB----------BBBB------ ------AAA----------AAAA------ ------AAA----------AAAA------ ------AAA----------AAAA------ ------AAA----------AAAA------ ------AAA----------AAAA------ ------AAA----------AAAA------ ------AAA----------AAAA------ ------BBB----------BBBB------ ------BBB----------BBBB------ ---------AAAAAAAAAA---------- 
--AAAA-----------------AAAAA- --AAAA-----------------AAAAA- --AAAA-----------------AAAAA- -----A-----------------AA---- -----A-----------------AA---- -----A-----------------AA---- -----A-----------------AA---- -----A-----------------AA---- -----A-----------------AA---- -----B-----------------BB---- -----A-----------------AA---- -----A-----------------AA---- -----A-----------------AA---- -----A-----------------AA---- -----A-----------------AA---- -----A-----------------AA---- -----A-----------------AA---- -----B-----------------BB---- -----B-----------------BB---- ------AAAAAAAAAAAAAAAAA------ 
--AAAA-----------------AAAAA- --AAAA-----------------AAAAA- --AAAA-----------------AAAAA- -----A-----------------AA---- -----A-----------------AA---- -----A-----------------AA---- -----A-----------------AA---- -----A-----------------AA---- -----A-----------------AA---- -----B-----------------BB---- -----A-----------------AA---- -----A-----------------AA---- -----A-----------------AA---- -----A-----------------AA---- -----A-----------------AA---- -----A-----------------AA---- -----A-----------------AA---- -----B-----------------BB---- -----B-----------------BB---- ------AAAAAAAAAAAAAAAAA------ 
AAAAAA-----------------AAAAAA AAAAAA-----------------AAAAAA AAAAAA-----------------AAAAAA -----A-----------------AA---- -----A-----------------AA---- -----A-----------------AA---- -----A-----------------AA---- -----A-----------------AA---- -----A-----------------AA---- -----B-----------------BB---- -----A-----------------AA---- -----A-----------------AA---- -----A-----------------AA---- -----A-----------------AA---- -----A-----------------AA---- -----A-----------------AA---- -----A-----------------AA---- -----B-----------------BB---- -----B-----------------BB---- ------AAAAAAAAAAAAAAAAA------ 
AAAAA--------------------AAAA AAAAA--------------------AAAA AAAAA--------------------AAAA ---AA--------------------A--- ---AA--------------------A--- ---AA--------------------A--- ---AA--------------------A--- ---AA--------------------A--- ---AA--------------------A--- ---BB--------------------B--- ---AA--------------------A--- ---AA--------------------A--- ---AA--------------------A--- ---AA--------------------A--- ---AA--------------------A--- ---AA--------------------A--- ---AA--------------------A--- ---BB--------------------B--- ---BB--------------------B--- -----AAAAAAAAAAAAAAAAAAAA---- 
AAAAA--------------------AAAA AAAAA--------------------AAAA AAAAA--------------------AAAA ---AA--------------------A--- ---AA--------------------A--- ---AA--------------------A--- ---AA--------------------A--- ---AA--------------------A--- ---AA--------------------A--- ---BB--------------------B--- ---AA--------------------A--- ---AA--------------------A--- ---AA--------------------A--- ---AA--------------------A--- ---AA--------------------A--- ---AA--------------------A--- ---AA--------------------A--- ---BB--------------------B--- ---BB--------------------B--- -----AAAAAAAAAAAAAAAAAAAA---- 
AAAAA--------------------AAAA AAAAA--------------------AAAA AAAAA--------------------AAAA ---AA--------------------A--- ---AA--------------------A--- ---AA--------------------A--- ---AA--------------------A--- ---AA--------------------A--- ---AA--------------------A--- ---BB--------------------B--- ---AA--------------------A--- ---AA--------------------A--- ---AA--------------------A--- ---AA--------------------A--- ---AA--------------------A--- ---AA--------------------A--- ---AA--------------------A--- ---BB--------------------B--- ---BB--------------------B--- -----AAAAAAAAAAAAAAAAAAAA---- 
AAAAA--------------------AAAA AAAAA--------------------AAAA AAAAA--------------------AAAA ---AA--------------------A--- ---AA--------------------A--- ---AA--------------------A--- ---AA--------------------A--- ---AA--------------------A--- ---AA--------------------A--- ---BB--------------------B--- ---AA--------------------A--- ---AA--------------------A--- ---AA--------------------A--- ---AA--------------------A--- ---AA--------------------A--- ---AA--------------------A--- ---AA--------------------A--- ---BB--------------------B--- ---BB--------------------B--- -----AAAAAAAAAAAAAAAAAAAA---- 
AAAAA--------------------AAAA AAAAA--------------------AAAA AAAAA--------------------AAAA ---AA--------------------A--- ---AA--------------------A--- ---AA--------------------A--- ---AA--------------------A--- ---AA--------------------A--- ---AA--------------------A--- ---BB--------------------B--- ---AA--------------------A--- ---AA--------------------A--- ---AA--------------------A--- ---AA--------------------A--- ---AA--------------------A--- ---AA--------------------A--- ---AA--------------------A--- ---BB--------------------B--- ---BB--------------------B--- -----AAAAAAAAAAAAAAAAAAAA---- 
AAAAA--------------------AAAA AAAAA--------------------AAAA AAAAA--------------------AAAA ---AA--------------------A--- ---AA--------------------A--- ---AA--------------------A--- ---AA--------------------A--- ---AA--------------------A--- ---AA--------------------A--- ---BB--------------------B--- ---AA--------------------A--- ---AA--------------------A--- ---AA--------------------A--- ---AA--------------------A--- ---AA--------------------A--- ---AA--------------------A--- ---AA--------------------A--- ---BB--------------------B--- ---BB--------------------B--- -----AAAAAAAAAAAAAAAAAAAA---- 
AAAAA--------------------AAAA AAAAA--------------------AAAA AAAAA--------------------AAAA ---AA--------------------A--- ---AA--------------------A--- ---AA--------------------A--- ---AA--------------------A--- ---AA--------------------A--- ---AA--------------------A--- ---BB--------------------B--- ---AA--------------------A--- ---AA--------------------A--- ---AA--------------------A--- ---AA--------------------A--- ---AA--------------------A--- ---AA--------------------A--- ---AA--------------------A--- ---BB--------------------B--- ---BB--------------------B--- -----AAAAAAAAAAAAAAAAAAAA---- 
AAAAA--------------------AAAA AAAAA--------------------AAAA AAAAA--------------------AAAA ---AA--------------------A--- ---AA--------------------A--- ---AA--------------------A--- ---AA--------------------A--- ---AA--------------------A--- ---AA--------------------A--- ---BB--------------------B--- ---AA--------------------A--- ---AA--------------------A--- ---AA--------------------A--- ---AA--------------------A--- ---AA--------------------A--- ---AA--------------------A--- ---AA--------------------A--- ---BB--------------------B--- ---BB--------------------B--- -----AAAAAAAAAAAAAAAAAAAA---- 
AAAAA--------------------AAAA AAAAA--------------------AAAA AAAAA--------------------AAAA ---AA--------------------A--- ---AA--------------------A--- ---AA--------------------A--- ---AA--------------------A--- ---AA--------------------A--- ---AA--------------------A--- ---BB--------------------B--- ---AA--------------------A--- ---AA--------------------A--- ---AA--------------------A--- ---AA--------------------A--- ---AA--------------------A--- ---AA--------------------A--- ---AA--------------------A--- ---BB--------------------B--- ---BB--------------------B--- -----AAAAAAAAAAAAAAAAAAAA---- 
AAAAA--------------------AAAA AAAAA--------------------AAAA AAAAA--------------------AAAA ---AA--------------------A--- ---AA--------------------A--- ---AA--------------------A--- ---AA--------------------A--- ---AA--------------------A--- ---AA--------------------A--- ---BB--------------------B--- ---AA--------------------A--- ---AA--------------------A--- ---AA--------------------A--- ---AA--------------------A--- ---AA--------------------A--- ---AA--------------------A--- ---AA--------------------A--- ---BB--------------------B--- ---BB--------------------B--- -----AAAAAAAAAAAAAAAAAAAA---- 
AAAAAA-----------------AAAAAA AAAAAA-----------------AAAAAA AAAAAA-----------------AAAAAA -----A-----------------AA---- -----A-----------------AA---- -----A-----------------AA---- -----A-----------------AA---- -----A-----------------AA---- -----A-----------------AA---- -----B-----------------BB---- -----A-----------------AA---- -----A-----------------AA---- -----A-----------------AA---- -----A-----------------AA---- -----A-----------------AA---- -----A-----------------AA---- -----A-----------------AA---- -----B-----------------BB---- -----B-----------------BB---- ------AAAAAAAAAAAAAAAAA------ 
AAAAAA-----------------AAAAAA AAAAAA-----------------AAAAAA AAAAAA-----------------AAAAAA -----A-----------------AA---- -----A-----------------AA---- -----A-----------------AA---- -----A-----------------AA---- -----A-----------------AA---- -----A-----------------AA---- -----B-----------------BB---- -----A-----------------AA---- -----A-----------------AA---- -----A-----------------AA---- -----A-----------------AA---- -----A-----------------AA---- -----A-----------------AA---- -----A-----------------AA---- -----B-----------------BB---- -----B-----------------BB---- ------AAAAAAAAAAAAAAAAA------ 
--AAAA-----------------AAAAA- --AAAA-----------------AAAAA- --AAAA-----------------AAAAA- -----A-----------------AA---- -----A-----------------AA---- -----A-----------------AA---- -----A-----------------AA---- -----A-----------------AA---- -----A-----------------AA---- -----B-----------------BB---- -----A-----------------AA---- -----A-----------------AA---- -----A-----------------AA---- -----A-----------------AA---- -----A-----------------AA---- -----A-----------------AA---- -----A-----------------AA---- -----B-----------------BB---- -----B-----------------BB---- ------AAAAAAAAAAAAAAAAA------ 
--AAAA-----------------AAAAA- --AAAA-----------------AAAAA- --AAAA-----------------AAAAA- -----A-----------------AA---- -----A-----------------AA---- -----A-----------------AA---- -----A-----------------AA---- -----A-----------------AA---- -----A-----------------AA---- -----B-----------------BB---- -----A-----------------AA---- -----A-----------------AA---- -----A-----------------AA---- -----A-----------------AA---- -----A-----------------AA---- -----A-----------------AA---- -----A-----------------AA---- -----B-----------------BB---- -----B-----------------BB---- ------AAAAAAAAAAAAAAAAA------ 
---AAAAAA----------AAAAAAA--- ---AAAAAA----------AAAAAAA--- ---AAAAAA----------AAAAAAA--- ------AAA----------AAAA------ ------AAA----------AAAA------ ------AAA----------AAAA------ ------AAA----------AAAA------ ------AAA----------AAAA------ ------AAA----------AAAA------ ------BBB----------BBBB------ ------AAA----------AAAA------ ------AAA----------AAAA------ ------AAA----------AAAA------ ------AAA----------AAAA------ ------AAA----------AAAA------ ------AAA----------AAAA------ ------AAA----------AAAA------ ------BBB----------BBBB------ ------BBB----------BBBB------ ---------AAAAAAAAAA---------- 
---AAAAAA----------AAAAAAA--- ---AAAAAA----------AAAAAAA--- ---AAAAAA----------AAAAAAA--- ------AAA----------AAAA------ ------AAA----------AAAA------ ------AAA----------AAAA------ ------AAA----------AAAA------ ------AAA----------AAAA------ ------AAA----------AAAA------ ------BBB----------BBBB------ ------AAA----------AAAA------ ------AAA----------AAAA------ ------AAA----------AAAA------ ------AAA----------AAAA------ ------AAA----------AAAA------ ------AAA----------AAAA------ ------AAA----------AAAA------ ------BBB----------BBBB------ ------BBB----------BBBB------ ---------AAAAAAAAAA---------- 
-----AAAAAAAAAAAAAAAAAAAA---- -----AAAAAAAAAAAAAAAAAAAA---- -----AAAAAAAAAAAAAAAAAAAA---- ---------AAAAAAAAAA---------- ---------AAAAAAAAAA---------- ---------AAAAAAAAAA---------- ---------AAAAAAAAAA---------- ---------AAAAAAAAAA---------- ---------AAAAAAAAAA---------- ---------BBBBBBBBBB---------- ---------AAAAAAAAAA---------- ---------AAAAAAAAAA---------- ---------AAAAAAAAAA---------- ---------AAAAAAAAAA---------- ---------AAAAAAAAAA---------- ---------AAAAAAAAAA---------- ---------AAAAAAAAAA---------- ---------BBBBBBBBBB---------- ---------BBBBBBBBBB---------- ----------------------------- 
------AAAAAAAAAAAAAAAAA------ ------AAAAAAAAAAAAAAAAA------ ------AAAAAAAAAAAAAAAAA------ ----------------------------- ----------------------------- ----------------------------- ----------------------------- ----------------------------- ----------------------------- ----------------------------- ----------------------------- ----------------------------- ----------------------------- ----------------------------- ----------------------------- ----------------------------- ----------------------------- ----------------------------- ----------------------------- ----------------------------- 
------AAAAAAAAAAAAAAAAA------ ------AAAAAAAAAAAAAAAAA------ ------AAAAAAAAAAAAAAAAA------ ----------------------------- ----------------------------- ----------------------------- ----------------------------- ----------------------------- ----------------------------- ----------------------------- ----------------------------- ----------------------------- ----------------------------- ----------------------------- ----------------------------- ----------------------------- ----------------------------- ----------------------------- ----------------------------- ----------------------------- 
--------AAAAAAAAAAAAA-------- --------AAAAAAAAAAAAA-------- --------AAAAAAAAAAAAA-------- ----------------------------- ----------------------------- ----------------------------- ----------------------------- ----------------------------- ----------------------------- ----------------------------- ----------------------------- ----------------------------- ----------------------------- ----------------------------- ----------------------------- ----------------------------- ----------------------------- ----------------------------- ----------------------------- ----------------------------- 
