model
size = 24 16 29, scale = 0.05, origin = -y
material 
  colors = A:#930 B:#555 C:#444 D:#EEE E:#E00 F:#F3F
voxels
------------------------ ------------------------ ------------------------ ----------E------------- ----------E------------- ----------E------------- ----------E------------- ----------E------------- ----------E------------- ----------E------------- ---------E-E------------ --------E---E----------- -------E-----E---------- ------E-------E--------- ------------------------ ------------------------ 
-----BBBBBBBBBBBBBB----- -----BCCCCCCCCCCCBB----- -----BCCCCCCCCCCCBB----- -----BCCCCCCCCCCCBB----- -----BCCCCCCCCCCCBB----- -----BCCCCCCCCCCCBB----- -----BCCCCCCCCCCCBB----- -----BCCCCCCCCCCCBB----- -----BCCCCCCCCCCCBB----- -----BCCCCCCCCCCCBB----- -----BCCCCCCCCCCCBB----- -----BCCCCCCCCCCCBB----- -----BCCCCCCCCCCCBB----- -----BCCCCCCCCCCCBB----- -----BBBBBBBBBBBBBB----- -----BBBBBBBBBBBBBB----- 
-----BBBBBBBBBBBBBB----- -----BCCCCCCCCCCCDB----- -----BCCCCCCCCCCCDB----- -----BCCCCCCCCCCCDB----- -----BCCCCCCCCCCCDB----- -----BCCCCCCCCCCCDB----- -----BCCCCCCCCCCCDB----- -----BCCCCCCCCCCCDB----- -----BCCCCCCCCCCCDB----- -----BCCCCCCCCCCCDB----- -----BCCCCCCCCCCCDB----- -----BCCCCCCCCCCCDB----- -----BCCCCCCCCCCCDB----- -----BCCCCCCCCCCCDB----- -----BBBBBBBBBBBBBB----- -----BBBBBBBBBBBBBB----- 
---BBBBBBBBBBBBBBBBBB--- ---BBBCCCCCCCCCCC-BBB--- ---BBBCCCCCCCCCCC-BBB--- ---BBBCCCCCCCCCCC-BBB--- ---BBBCCCCCCCCCCC-BBB--- ---BBBCCCCCCCCCCC-BBB--- ---BBBCCCCCCCCCCC-BBB--- ---BBBCCCCCCCCCCC-BBB--- ---BBBCCCCCCCCCCCDBBB--- ---BBBCCCCCCCCCCCDBBB--- ---BBBCCCCCCCCCCCDBBB--- ---BBBCCCCCCCCCCCDBBB--- ---BBBCCCCCCCCCCCDBBB--- ---BBBCCCCCCCCCCCDBBB--- ---BBBBBBBBBBBBBBBBBB--- ---BBBBBBBBBBBBBBBBBB--- 
---BBBBBBBBBBBBBBBBBB--- ---BBAAAAAAAAAAAAABBB--- ---BBAAAAAAAAAAAAABBB--- ---BBAAAAAAAAAAAAABBB--- ---BBAAAAAAAAAAAAABBB--- ---BBAAAAAAAAAAAAABBB--- ---BBAAAAAAAAAAAAAABB--- ---BBAAAAAAAAAAAA--BB--- ---BBAAAAAAAAAAAA--BB--- ---BBBCCCCCCCCCCCABBB--- ---BBBCCCCCCCCCCCABBB--- ---BBBCCCCCCCCCCCABBB--- ---BBBCCCCCCCCCCCABBB--- ---BBBCCCCCCCCCCCABBB--- ---BBBBBBBBBBBBBBBBDB--- ---BBBBBBBBBBBBBBBBBB--- 
-BBBBBBBBBBBBBBBBBBBBBB- -BBBBAAAAAAAAAAAAABBBBB- -BBBBAAAAAAAAAAAAABBBBB- -BBBBAAAAAAAAAAAAABBBBB- -BBBBAAAAAAAAAAAAAABBBB- -BBBBAAAAAAAAAAAAAABBBB- -BBBBAAAAAAAAAAAAAABBBB- -BBBBAAAAAAAAAAAA-ABBBB- -BBBBAAAAAAAAAAAA-ABBBB- -BBBBAAAAAAAAAAAAAABBBB- -BBBBAAAAAAAAAAAAAABBBB- -BBBBAAAAAAAAAAAAAABBBB- -BBBBAAAAAAAAAAAAAABBBB- -BBBBAAAAAAAAAAAAAABBBB- -BBBB--------------BBBB- -BBBB--------------BBBB- 
-BBBBBBBBBBBBBBBBBBBBBC- -BAAAAAAAAAAAAAAAABBBBC- -BAAAAAAAAAAAAAAAAABBBC- -BAAAAAAAAAAAAAAAAABBBC- -BA-AAAAAAAAAAAAAAABBBC- -BAAAAAAAAAAAAAAAAABBBC- -BAAAAAAAAAAAAAAAAABBBC- -BAAAAAAAAAAAAAAA--BBBC- -BAAAAAAAAAAAAAAA-ABBBC- -BAAAAAAAAAAAAAAA-ABBBC- -BAAAAAAAAAAAAAAA-ABBBC- -BAAAAAAAAAAAAAAA-ABBBC- -B--AAAAAAAAAAAAAAABBBC- -BD--AAAAAAAAAAAAAABBBC- -BDDB--------------BBBB- -BBBB--------------BBBB- 
-BBBBBBBBBBBBBBBBBBBBBC- -BAAAAAAAAAAAAAAAAAAACC- -BAAAAAAAAAAAAAAAAAAACC- -BAAAAAAAAAAAAAAAAAAACC- -B--AAAAAAAAAAAAAAAAACC- -BAAAAAAAAAAAAAAAAAAACC- -BAAAAAAAAAAAAAAAAAAACC- -BAAAAAAAAAAAAAAA--AACC- -BAAAAAAAAAAAAAAA-AAACC- -BAAAAAAAAAAAAAAA-AAACC- -BAAAAAAAAAAAAAAA-AAACC- -BAAAAAAAAAAAAAAA-AAACC- -B--AAAAAAAAAAAAAAAAACC- -BD--AAAAAAAAAAAAAAAACC- -BDDB--------------BBBB- -BBBB--------------BBBB- 
-BBBBBBBBBBBBBBBBBBBBBC- -CCAAAAAAAAAAAAAAAAAACC- -CCAAAAAAAAAAAAAAAAAACC- -CCAAAAAAAAAAAAAAAAAACC- -CC-AAAAAAAAAAAAAAAAACC- -CCAAAAAAAAAAAAAAAAAACC- -CCAAAAAAAAAAAAAAAAAACC- -CCAAAAAAAAAAAAAA--AACC- -CCAAAAAAAAAAAAAA-AAACC- -CCAAAAAAAAAAAAAA-AAACC- -CCAAAAAAAAAAAAAA-AAACC- -CCAAAAAAAAAAAAAA-AAACC- ECCAAAAAAAAAAAAAAAAAACCE -CCAAAAAAAAAAAAAAAAAACC- -BDDB--------------BBBB- -BBBB--------------BBBB- 
-BBBBBBBBBBBBBBBBBBBBBC- -CCAAAAAAAAAAAAAAAAAACC- -CCAAAAAAAAAAAAAAAAAACC- -CCAAAAAAAAAAAAAAAAAACC- -CC-AAAAAAAAAAAAAAAAACC- -CCAAAAAAAAAAAAAAAAAACC- -CCAAAAAAAAAAAAAAAAAACC- -CC----------------AACC- -CCAAAAAAAAA------AAACC- -CCAAAAAAAAA------AAACC- -CC--------AAAAAA-AAACC- ECCAAAAAAAAAAAAAA-AAACCE -CCAAAAAAAAAAAAAAAAAACC- -CCAAAAAAAAAAAAAAAAAACC- -BDDB--------------BBBB- -BBBB--------------BBBB- 
-BBBBBBBBBBBBBBBBBBBBBC- -CCAAAAAAAAAAAAAAAAAACC- -CCAAAAAAAAAAAAAAAAAACC- -CCAAAAAAAAAAAAAAAAAACC- -CC-AAAAAAAAAAAAAAAAACC- -CCAAAAAAAAAAAAAAAAAACC- -CCAAAAAAAAAAAAAAAAAACC- -CCAAAAAAA---------AACC- -CCAAAAAAA--------AAACC- -CCAAAAAAA--------AAACC- ECCAAAAAAA-AAAAAA-AAACCE -CCAAAAAAA-AAAAAA-AAACC- -CCAAAAAAAAAAAAAAAAAACC- -CC-AAAAAAAAAAAAAAAAACC- -BDDB--------------BBBB- -BBBB--------------BBBB- 
-BBBBBBBBBBBBBBBBBBBBBC- -CCAAAAAAAAAAAAAAAAAACC- -CCAAAAAAAAAAAAAAAAAACC- -CCAAAAAAAAAAAAAAAAAACCE -CC-AAAAAAAAAAAAAAAAACCE -CCAAAAAAAAAAAAAAAAAACCE -CCAAAAAAAAAAAAAAAAAACCE -CCAAAAAAAAAAAAAAA-AACCE -CCAAAAAAAAAAAAAAAAAACCE ECCAAAAAAAAAAAAAAAAAACCE -CCAAAAAAAAAAAAAAAAAACC- -CCAAAAAAAAAAAAAAAAAACC- -CCAAAAAAAAAAAAAAAAAACC- -CC--AAAAAAAAAAAAAAAACC- -BDDB--------------BBBB- -BBBB--------------BBBB- 
-BBBBBBBBBBBBBBBBBBBBBC- -CCAAAAAAAAAAAAAAAAAACC- -CCAAAAAAAAAAAAAAAAAACC- -CCAAAAAAAAAAAAAAAAAACC- ECC-AAAAAAAAAAAAAAAAACC- ECCAAAAAAAAAAAAAAAAAACC- ECCAAAAAAAAAAAAAAAAAACC- ECC-AAAAAAAAAAAAAA-AACC- ECC-AAAAAAAAAAAAAAAAACC- -CC-AAAAAAAAAAAAAAAAACC- -CC-AAAAAAAAAAAAAAAAACCE -CC-AAAAAAAAAAAAAAAAACC- -CC-AAAAAAAAAAAAAAAAACC- -CC-AAAAAAAAAAAAAAAAACC- -BDDB--------------BBBB- -BBBB--------------BBBB- 
-BBBBBBBBBBBBBBBBBBBBBC- -CCAAAAAAAAAAAAAAAAAACC- -CCAAAAAAAAAAAAAAAAAACC- -CCAAAAAAAAAAAAAAAAAACC- -CC-AAAAAAAAAAAAAAAAACC- -CCAAAAAAAAAAAAAAAAAACC- -CCAAAAAAAAAAAAAAAAAACC- -CCAAAAAAAAAAAAAA--AACC- -CCAAAAAAAAAAAAAA-AAACC- ECCAAAAAAAAAAAAAA-AAACC- -CCAAAAAAAAAAAAAA-AAACC- -CCAAAAAAAAAAAAAA-AAACCE -CCAAAAAAAAAAAAAAAAAACC- -CCAAAAAAAAAAAAAAAAAACC- -BDDB--------------BBBB- -BBBB--------------BBBB- 
-BBBBBBBBBBBBBBBBBBBBBC- -CCAAAAAAAAAAAAAAAAAACC- -CCAAAAAAAAAAAAAAAAAACC- -CCAAAAAAAAAAAAAAAAAACC- -CC-AAAAAAAAAAAAAAAAACC- -CCAAAAAAAAAAAAAAAAAACC- -CCAAAAAAAAAAAAAAAAAACC- -CCAAAAAAAAAAAAAA--AACC- -CCAAAAAAAAAAAAAA-AAACC- -CCAAAAAAAAAAAAAA-AAACC- ECCAAAAAAAAAAAAAA-AAACC- -CCAAAAAAAAAAAAAA-AAACC- -CCAAAAAAAAAAAAAAAAAACCE -CCAAAAAAAAAAAAAAAAAACC- -BDDB--------------BBBB- -BBBB--------------BBBB- 
-BBBBBBBBBBBBBBBBBBBBBC- -CCAAAAAAAAAAAAAAAAAACC- -CCAAAAAAAAAAAAAAAAAACC- -CCAAAAAAAAAAAAAAAAAACC- -CC-AAAAAAAAAAAAAAAAACC- -CCAAAAAAAAAAAAAAAAAACC- -CCAAAAAAAAAAAAAAAAAACC- -CCAAAAAAAAAAAAAA--AACC- -CCAAAAAAAAAAAAAA-AAACC- -CCAAAAAAAAAAAAAA-AAACC- -CCAAAAAAAAAAAAAA-AAACC- ECCAAAAAAAAAAAAAA-AAACC- -CCAAAAAAAAAAAAAAAAAACC- -CCAAAAAAAAAAAAAAAAAACC- -BDDB--------------BBBB- -BBBB--------------BBBB- 
-BBBBBBBBBBBBBBBBBBBBBB- -CCAAAAAAAAAAAAAAAAAAAB- -CCAAAAAAAAAAAAAAAAAAAB- -CCAAAAAAAAAAAAAAAAAAAB- -CC-AAAAAAAAAAAAAAAAAAB- -CCAAAAAAAAAAAAAAAAAAAB- -CCAAAAAAAAAAAAAAAAAAAB- -CC----------------AAAB- -CC---------------AAAAB- -CC---------------AAAAB- -CC---------------AAAAB- -CCAAAAAAAAAAAAAA-AAAAB- ECCAAAAAAAAAAAAAAAAAAAB- -CCAAAAAAAAAAAAAAAAAAAB- -BDDB--------------BBBB- -BBBB--------------BBBB- 
-BBBBBBBBBBBBBBBBBBBBBB- -CBBAAAAAAAAAAAAAAAAAAB- -CBBAAAAAAAAAAAAAAAAAAB- -CBBAAAAAAAAAAAAAAAAAAB- -CBBAAAAAAAAAAAAAAAAAAB- -CBBAAAAAAAAAAAAAAAAAAB- -CBBAAAAAAAAAAAAAAAAAAB- -CBB---------------AAAB- -CBBAAAAAAAAAAAAA-AAAAB- -CBBAAAAAAAAAAAAA-AAAAB- -CBBAAAAAAAAAAAAA-AAAAB- -CBBAAAAAAAAAAAAA-AAAAB- -CBBAAAAAAAAAAAAAAAAAAA- -CBBAAAAAAAAAAAAAAAAAAB- -BDDB--------------BBBB- -BBBB--------------BBBB- 
-BBBBBBBBBBBBBBBBBBBBBB- -BBBAAAAAAAAAAAAAAABBBB- -BBBAAAAAAAAAAAAAAABBBB- -BBBAAAAAAAAAAAAAAABBBB- -BBBAAAAAAAAAAAAAAABBBB- -BBBAAAAAAAAAAAAAAABBBB- -BBBAAAAAAAAAAAAAAABBBB- -BBBAAAAAAAAAAAAAAABBBB- -BBBAAAAAAAAAAAAAAABBBB- -BBBAAAAAAAAAAAAAAABBBB- -BBBAAAAAAAAAAAAAAABBBB- -BBBAAAAAAAAAAAAAAABBBB- -BBBAAAAAAAAAAAAAAABBBB- -BBBAAAAAAAAAAAAAAABBBB- -BBFB--------------BBBB- -BBBB--------------BBBB- 
---BBBBBBBBBBBBBBBBBB--- ---BBBBBBBBBBBBBBBBBB--- ---BBBBBBBBBBBBBBBBBB--- ---B-----BBBBBBBBBBBB--- ---BBBBBBBBBBBBBBBBBB--- ---BBBBBBBBBBBBBBBBBB--- ---BBBBBBBBBBBBBBBBBB--- ---BBBBBBBBBBBBBBBBBB--- ---BBBBBBBBBBBBBBBBBB--- ---BBBBBBBBBBBBBBBBBB--- ---BBBBBBBBBBBBBBBBBB--- ---BABBBBBBBBBBBBBBBB--- ---BBABBBBBBBBBBBBBBB--- ---BBBBBBBBBBBBBBBBBB--- ---BBBBBBBBBBBBBBBBBB--- ---BBBBBBBBBBBBBBBBBB--- 
---BBBBBBBBBBBBBBBBBB--- ---BBBBBBBBBBBBBBBBBB--- ---BBBBBBBBBBBBBBBBBB--- ---BBBBBBBBBBBBBBBBBB--- ---BBBBBBBBBBBBBBBBBB--- ---BBBBBBBBBBBBBBBBBB--- ---BBBBBBBBBBBBBBBBBB--- ---BBBBBBBBBBBBBBBBBB--- ---BBBBBBBBBBBBBBBBBB--- ---BBBBBBBBBBBBBBBBBB--- ---BBBBBBBBBBBBBBBBBB--- ---BBBBBBBBBBBBBBBBBB--- ---BBBBBBBBBBBBBBBBBB--- ---BBBBBBBBBBBBBBBBBB--- ---BBBBBBBBBBBBBBBBBB--- ---BBBBBBBBBBBBBBBBBB--- 
-------BBBBBBBBBB------- -------BBBBBBBBBB------- -------BBBBBBBBBB------- -------BBBBBBBBBB------- -------BBBBBBBBBB------- -------BBBBBBBBBB------- -------BBBBBBBBBB------- -------BBBBBBBBBB------- -------BBBBBBBBBB------- -------BBBBBBBBBB------- -------BBBBBBBBBB------- -------BBBBBBBBBB------- -------BBBBBBBBBB------- -------BBBBBBBBBB------- -------BBBBBBBBBB------- -------BBBBBBBBBB------- 
-------BBBBBBBBBB------- -------BBBBBBBBBB------- -------BBBBBBBBBB------- -------BBBBBBBBBB------- -------BBBBBBBBBB------- -------BBBBBBBBBB------- -------BBBBBBBBBB------- -------BBBBBBBBBB------- -------BBBBBBBBBB------- -------BBBBBBBBBB------- -------BBBBBBBBBB------- -------BBBBBBBBBB------- -------BBBBBBBBBB------- -------BBBBBBBBBB------- -------BBBBBBBBBB------- -------BBBBBBBBBB------- 
------------------------ ------------------------ ------------------------ ------------------------ ---------BBBBBB--------- ---------BBBBBB--------- ------------------------ ------------------------ ------------------------ ------------------------ ------------------------ ------------------------ ---------BBBBBB--------- ---------BBBBBB--------- ------------------------ ------------------------ 
------------------------ ------------------------ ------------------------ ------------------------ ---------BBBBBB--------- ---------BBBBBB--------- ------------------------ ------------------------ ------------------------ ------------------------ ------------------------ ------------------------ ---------BBBBBB--------- ---------BBBBBB--------- ------------------------ ------------------------ 
------------------------ ------------------------ ------------------------ ------------------------ ---------BBBBBB--------- ---------BBBBBB--------- ------------------------ ------------------------ ------------------------ ------------------------ ------------------------ ------------------------ ---------BBBBBB--------- ---------BBBBBB--------- ------------------------ ------------------------ 
------------------------ ------------------------ ------------------------ ------------------------ ---------BBBBBB--------- ---------BBBBBB--------- ------------------------ ------------------------ ------------------------ ------------------------ ------------------------ ------------------------ ---------BBBBBB--------- ---------BBBBBB--------- ------------------------ ------------------------ 
------------------------ ------------------------ ------------------------ ------------------------ ---------BBBBBB--------- ---------BBBBBB--------- ---------BBBBBB--------- ---------BBBBBB--------- ---------BBBBBB--------- ---------BBBBBB--------- ---------BBBBBB--------- ---------BBBBBB--------- ---------BBBBBB--------- ---------BBBBBB--------- ------------------------ ------------------------ 
------------------------ ------------------------ ------------------------ ------------------------ ---------BBBBBB--------- ---------BBBBBB--------- ---------BBBBBB--------- ---------BBBBBB--------- ---------BBBBBB--------- ---------BBBBBB--------- ---------BBBBBB--------- ---------BBBBBB--------- ---------BBBBBB--------- ---------BBBBBB--------- ------------------------ ------------------------ 
