model
size = 22 24 21, scale = 0.05, origin = -y
material 
  colors = A:#FCFAF2 B:#D0104C C:#222 D:#111 E:#CB1B45
voxels
---------------------- ---------------------- ---------------------- ---------------------- ---------------------- ---------------------- ---------------------- ---------------------- ---------------------- ---------------------- ---------------------- ---------------------- ---------------------- ---------------------- ---------------------- ---------------------- ---------------------- ---------------------- ----------BB---------- ----------BB---------- ----------BB---------- ----------BB---------- ----------EE---------- ----------BB---------- 
---------------------- ---------------------- ---------------------- ---------------------- ---------------------- ---------------------- ---------------------- ---------------------- ----------AA---------- ----------AA---------- ----------AA---------- ---------------------- ---------------------- ---------------------- ---------------------- ---------------------- ---------------------- ----------EE---------- ----------EE---------- ----------EE---------- ----------EE---------- ----------EE---------- ----------EE---------- ---------------------- 
---------------------- ---------------------- ---------------------- ----------AA---------- -------AAAAAAAA------- ------AADDDDDDAA------ -----AADAAAAAADAA----- -----AAAAAAAAAAAA----- -----AAAAAAAAAAAA----- ----AAADAAAAAADAAA---- ----AADDDAAAADDDAA---- -----AAAAAAAAAAAA----- -----AAAAAAAAAAAA----- -----AAAAAAAAAAAA----- ------AAAAAAAAAA------ -------AAAAAAAA------- ----------AA---------- ----------EE---------- ----------EE---------- ----------EE---------- ----------EE---------- ----------EE---------- ----------EE---------- ----------EE---------- 
---------------------- ---------------------- ----------AA---------- -------AAAAAAAA------- ------AAAAAAAAAA------ -----AAAAAAAAAAAA----- ----AAAAAAAAAAAAAA---- ----AAAAAAAAAAAAAA---- ----AAAAAAAAAAAAAA---- ---AAAAAAAAAAAAAAAA--- ---AAAAAAAAAAAAAAAA--- ----AAAAAAAAAAAAAA---- ----AAAAAAAAAAAAAA---- ----AAAAAAAAAAAAAA---- -----AAAAAAAAAAAA----- ------AAAAAAAAAA------ -------AAAAAAAA------- ----------AA---------- ----------BB---------- ----------BB---------- ----------BB---------- ----------BB---------- ----------BB---------- ---------------------- 
---------------------- ---------------------- -------AAAAAAAA------- ------AAAAAAAAAA------ -----AAAAAAAAAAAA----- ----AAAAAAAAAAAAAA---- ---AAAAAAAAAAAAAAAA--- ---AAAAAAAAAAAAAAAA--- ---AAAAAAAAAAAAAAAA--- ---AAAAAAAAAAAAAAAA--- ---AAAAAAAAAAAAAAAA--- ---AAAAAAAAAAAAAAAA--- ---AAAAAAAAAAAAAAAA--- ---AAAAAAAAAAAAAAAA--- ----AAAAAAAAAAAAAA---- -----AAAAAAAAAAAA----- ------AAAAAAAAAA------ -------AAAAAAAA------- ----------BB---------- ----------BB---------- ----------BB---------- ----------BB---------- ----------BB---------- ----------BB---------- 
---------------------- --------AAAAAA-------- ------AAAAAAAAAA------ -----AAAAAAAAAAAA----- ----AAAAAAAAAAAAAA---- ---AAAAAAAAAAAAAAAA--- ---AAAAAAAAAAAAAAAA--- --AAAAAAAAAAAAAAAAAA-- --AAAAAAAAAAAAAAAAAA-- --AAAAAAAAAAAAAAAAAA-- --AAAAAAAAAAAAAAAAAA-- --AAAAAAAAAAAAAAAAAA-- --AAAAAAAAAAAAAAAAAA-- ---AAAAAAAAAAAAAAAA--- ---AAAAAAAAAAAAAAAA--- ----AAAAAAAAAAAAAA---- -----AAAAAAAAAAAA----- ------AAAAAAAAAA------ --------AAAAAA-------- ----------EE---------- ----------EE---------- ----------EE---------- ----------EE---------- ---------------------- 
---------------------- -------AAAAAAAA------- -----AAAAAAAAAAAA----- ----AAAAAAAAAAAAAA---- ---AAAAAAAAAAAAAAAA--- ---AAAAAAAAAAAAAAAA--- --AAAAAAAAAAAAAAAAAA-- --AAAAAAAAAAAAAAAAAA-- --AAAAAAAAAAAAAAAAAA-- --AAAAAAAAAAAAAAAAAA-- --AAAAAAAAAAAAAAAAAA-- --AAAAAAAAAAAAAAAAAA-- --AAAAAAAAAAAAAAAAAA-- --AAAAAAAAAAAAAAAAAA-- ---AAAAAAAAAAAAAAAA--- ---AAAAAAAAAAAAAAAA--- ----AAAAAAAAAAAAAA---- -----AAAAAAAAAAAA----- -------AAAAAAAA------- ----------EE---------- ----------EE---------- ----------EE---------- ----------EE---------- ----------EE---------- 
---------AAAA--------- ------AAAAAAAAAA------ -----AAAAAAAAAAAA----- ----AAAAAAAAAAAAAA---- ---AAAAAAAAAAAAAAAA--- --AAAAAAAAAAAAAAAAAA-- --AAAAAAAAAAAAAAAAAA-- --AAAAAAAAAAAAAAAAAA-- CDAAAAAAAAAAAAAAAAAADC CDAAAAAAAAAAAAAAAAAADC CDAAAAAAAAAAAAAAAAAADC CDAAAAAAAAAAAAAAAAAADC --AAAAAAAAAAAAAAAAAA-- --AAAAAAAAAAAAAAAAAA-- --AAAAAAAAAAAAAAAAAA-- ---AAAAAAAAAAAAAAAA--- ----AAAAAAAAAAAAAA---- -----AAAAAAAAAAAA----- ------AAAAAAAAAA------ ---------AAAA--------- ----------BB---------- ----------BB---------- ----------BB---------- ---------------------- 
--------AAAAAA-------- ------AAAAAAAAAA------ -----AAAAAAAAAAAA----- ----AAAAAAAAAAAAAA---- ---AAAAAAAAAAAAAAAA--- --AAAAAAAAAAAAAAAAAA-- --AAAAAAAAAAAAAAAAAA-- CDAAAAAAAAAAAAAAAAAADC CDAAAAAAAAAAAAAAAAAADC CDAAAAAAAAAAAAAAAAAADC CDAAAAAAAAAAAAAAAAAADC CDAAAAAAAAAAAAAAAAAADC CDAAAAAAAAAAAAAAAAAADC --AAAAAAAAAAAAAAAAAA-- --AAAAAAAAAAAAAAAAAA-- ---AAAAAAAAAAAAAAAA--- ----AAAAAAAAAAAAAA---- -----AAAAAAAAAAAA----- ------AAAAAAAAAA------ --------AAAAAA-------- ----------BB---------- ----------BB---------- ----------BB---------- ----------BB---------- 
--------AAAAAA-------- ------AAAAAAAAAA------ ----AAAAAAAAAAAAAA---- ---AAAAAAAAAAAAAAAA--- ---AAAAAAAAAAAAAAAA--- --AAAAAAAAAAAAAAAAAA-- --AAAAAAAAAAAAAAAAAA-- CDAAAAAAAAAAAAAAAAAADC CDAAAAAAAAAAAAAAAAAADC CDAAAAAAAAAAAAAAAAAADC CDAAAAAAAAAAAAAAAAAADC CDAAAAAAAAAAAAAAAAAADC CDAAAAAAAAAAAAAAAAAADC -CAAAAAAAAAAAAAAAAAAC- -CAAAAAAAAAAAAAAAAAAC- --CAAAAAAAAAAAAAAAAC-- --CAAAAAAAAAAAAAAAAC-- ---CAAAAAAAAAAAAAAC--- ----CCAAAAAAAAAACC---- -----CCCAAAAAACCC----- --------CCCCCC-------- ----------BB---------- ----------BB---------- ---------------------- 
--------AAAAAA-------- ------AAAAAAAAAA------ ----AAAAAAAAAAAAAA---- ---AAAAAAAAAAAAAAAA--- ---AAAAAAAAAAAAAAAA--- --AAAAAAAAAAAAAAAAAA-- --AAAAAAAAAAAAAAAAAA-- CDAAAAAAAAAAAAAAAAAADC CDAAAAAAAAAAAAAAAAAADC CDAAAAAAAAAAAAAAAAAADC CDAAAAAAAAAAAAAAAAAADC CDAAAAAAAAAAAAAAAAAADC CDAAAAAAAAAAAAAAAAAADC -CAAAAAAAAAAAAAAAAAAC- -CAAAAAAAAAAAAAAAAAAC- --CAAAAAAAAAAAAAAAAC-- --CAAAAAAAAAAAAAAAAC-- ---CAAAAAAAAAAAAAAC--- ----CCAAAAAAAAAACC---- -----CCCAAAAAACCC----- --------CCCCCC-------- ----------BB---------- ----------BB---------- ----------BB---------- 
--------AAAAAA-------- ------AAAAAAAAAA------ -----AAAAAAAAAAAA----- ----AAAAAAAAAAAAAA---- ---AAAAAAAAAAAAAAAA--- --AAAAAAAAAAAAAAAAAA-- --AAAAAAAAAAAAAAAAAA-- CDAAAAAAAAAAAAAAAAAADC CDAAAAAAAAAAAAAAAAAADC CDAAAAAAAAAAAAAAAAAADC CDAAAAAAAAAAAAAAAAAADC CDAAAAAAAAAAAAAAAAAADC CDAAAAAAAAAAAAAAAAAADC --AAAAAAAAAAAAAAAAAA-- --AAAAAAAAAAAAAAAAAA-- ---AAAAAAAAAAAAAAAA--- ----AAAAAAAAAAAAAA---- -----AAAAAAAAAAAA----- ------AAAAAAAAAA------ --------AAAAAA-------- ----------BB---------- ----------BB---------- ----------BB---------- ---------------------- 
---------AAAA--------- ------AAAAAAAAAA------ -----AAAAAAAAAAAA----- ----AAAAAAAAAAAAAA---- ---AAAAAAAAAAAAAAAA--- --AAAAAAAAAAAAAAAAAA-- --AAAAAAAAAAAAAAAAAA-- --AAAAAAAAAAAAAAAAAA-- CDAAAAAAAAAAAAAAAAAADC CDAAAAAAAAAAAAAAAAAADC CDAAAAAAAAAAAAAAAAAADC CDAAAAAAAAAAAAAAAAAADC --AAAAAAAAAAAAAAAAAA-- --AAAAAAAAAAAAAAAAAA-- --AAAAAAAAAAAAAAAAAA-- ---AAAAAAAAAAAAAAAA--- ----AAAAAAAAAAAAAA---- -----AAAAAAAAAAAA----- ------AAAAAAAAAA------ ---------AAAA--------- ----------BB---------- ----------BB---------- ----------BB---------- ----------BB---------- 
---------------------- -------AAAAAAAA------- -----AAAAAAAAAAAA----- ----AAAAAAAAAAAAAA---- ---AAAAAAAAAAAAAAAA--- ---AAAAAAAAAAAAAAAA--- --AAAAAAAAAAAAAAAAAA-- --AAAAAAAAAAAAAAAAAA-- --AAAAAAAAAAAAAAAAAA-- --AAAAAAAAAAAAAAAAAA-- --AAAAAAAAAAAAAAAAAA-- --AAAAAAAAAAAAAAAAAA-- --AAAAAAAAAAAAAAAAAA-- --AAAAAAAAAAAAAAAAAA-- ---AAAAAAAAAAAAAAAA--- ---AAAAAAAAAAAAAAAA--- ----AAAAAAAAAAAAAA---- -----AAAAAAAAAAAA----- -------AAAAAAAA------- ----------BB---------- ----------BB---------- ----------BB---------- ----------BB---------- ---------------------- 
---------------------- --------AAAAAA-------- ------AAAAAAAAAA------ -----AAAAAAAAAAAA----- ----AAAAAAAAAAAAAA---- ---AAAAAAAAAAAAAAAA--- ---AAAAAAAAAAAAAAAA--- --AAAAAAAAAAAAAAAAAA-- --AAAAAAAAAAAAAAAAAA-- --AAAAAAAAAAAAAAAAAA-- --AAAAAAAAAAAAAAAAAA-- --AAAAAAAAAAAAAAAAAA-- --AAAAAAAAAAAAAAAAAA-- ---AAAAAAAAAAAAAAAA--- ---AAAAAAAAAAAAAAAA--- ----AAAAAAAAAAAAAA---- -----AAAAAAAAAAAA----- ------AAAAAAAAAA------ --------AAAAAA-------- ----------BB---------- ----------BB---------- ----------BB---------- ----------BB---------- ----------BB---------- 
---------------------- ---------------------- -------AAAAAAAA------- ------AAAAAAAAAA------ -----AAAAAAAAAAAA----- ----AAAAAAAAAAAAAA---- ---AAAAAAAAAAAAAAAA--- ---AAAAAAAAAAAAAAAA--- ---AAAAAAAAAAAAAAAA--- ---AAAAAAAAAAAAAAAA--- ---AAAAAAAAAAAAAAAA--- ---AAAAAAAAAAAAAAAA--- ---AAAAAAAAAAAAAAAA--- ---AAAAAAAAAAAAAAAA--- ----AAAAAAAAAAAAAA---- -----AAAAAAAAAAAA----- ------AAAAAAAAAA------ -------AAAAAAAA------- ----------BB---------- ----------BB---------- ----------BB---------- ----------BB---------- ----------BB---------- ---------------------- 
---------------------- ---------------------- ----------AA---------- -------AAAAAAAA------- ------AAAAAAAAAA------ -----AAAAAAAAAAAA----- ----AAAAAAAAAAAAAA---- ----AAAAAAAAAAAAAA---- ----AAAAAAAAAAAAAA---- ---AAAAAAAAAAAAAAAA--- ---AAAAAAAAAAAAAAAA--- ----AAAAAAAAAAAAAA---- ----AAAAAAAAAAAAAA---- ----AAAAAAAAAAAAAA---- -----AAAAAAAAAAAA----- ------AAAAAAAAAA------ -------AAAAAAAA------- ----------AA---------- ----------BB---------- ----------BB---------- ----------BB---------- ----------BB---------- ----------BB---------- ----------BB---------- 
---------------------- ---------------------- ---------------------- ----------AA---------- -------AAAAAAAA------- ------AAAAAAAAAA------ -----AAAAAAAAAAAA----- -----AAAAAAAAAAAA----- -----AAAAAAAAAAAA----- ----AAAAAAAAAAAAAA---- ----AAAAAAAAAAAAAA---- -----AAAAAAAAAAAA----- -----AAAAAAAAAAAA----- -----AAAAAAAAAAAA----- ------AAAAAAAAAA------ -------AAAAAAAA------- ----------AA---------- ----------BB---------- ----------BB---------- ----------BB---------- ----------BB---------- ----------BB---------- ----------BB---------- ---------------------- 
---------------------- ---------------------- ---------------------- ---------------------- ---------------------- --------AAAAAA-------- -------AAAAAAAA------- ------AAAAAAAAAA------ ------AAAAAAAAAA------ ------AAAAAAAAAA------ ------AAAAAAAAAA------ ------AAAAAAAAAA------ ------AAAAAAAAAA------ -------AAAAAAAA------- --------AAAAAA-------- ----------BB---------- ----------BB---------- ----------BB---------- ----------BB---------- ----------BB---------- ----------BB---------- ----------BB---------- ----------BB---------- ----------BB---------- 
---------------------- ---------------------- ---------------------- ---------------------- ---------------------- ---------------------- ---------------------- ---------AAAA--------- --------AAAAAA-------- --------AAAAAA-------- --------AAAAAA-------- --------AAAAAA-------- ---------AAAA--------- ----------BB---------- ----------BB---------- ----------BB---------- ----------BB---------- ----------BB---------- ----------BB---------- ----------BB---------- ----------BB---------- ----------BB---------- ----------BB---------- ---------------------- 
---------------------- ---------------------- ---------------------- ---------------------- ---------------------- ---------------------- ---------------------- ---------------------- ---------------------- ---------------------- ---------------------- ---------------------- ---------------------- ---------------------- ---------------------- ---------------------- ---------------------- ----------BB---------- ----------BB---------- ----------BB---------- ----------BB---------- ----------BB---------- ----------BB---------- ----------BB---------- 
