model
size = 16 24 18, scale = 0.05, origin = -y
material 
  colors = A:#FCFAF2 B:#E2943B C:#FFB11B D:#FFC408 E:#BDC0BA F:#F9BF45 G:#222 H:#F7D94C I:#D0104C J:#CB1B45 K:#111
voxels
-----AA--AA----- -----AA--AA----- ----AAAAAAAA---- ----AAAAAAAA---- ----EAAAAAAE---- --AAAAA--AAAAA-- --AAAAA--AAAAA-- --AA--AAAA--AA-- --A----AA----A-- --A----AA----A-- --A----AA----A-- --AAAAAAAAAAAA-- --AAAAAAAAAAAA-- --AAAAAAAAAAAA-- ---AAAAAAAAAA--- ----AAAAAAAA---- -------AA------- ---------------- ---------------- ---------------- ---------------- ---------------- ---------------- ---------------- 
---A--------A--- ---A--------A--- ---A---AA---A--- ---AAAAAAAAAA--- ---EAAAAAAAAE--- -AAAAAAKKAAAAAA- -AAAAAAKKAAAAAA- -AAAGGAAAAGGAAA- -AAG--GAAG--GAA- -AAG--GAAG--GAA- -AAGGGGAAGGGGAA- -AAAAAAAAAAAAAA- -AAAAAAAAAAAAAA- -AAAAAAAAAAAAAA- --AAAAAAAAAAAA-- ---AAAAAAAAAA--- ----AAAAAAAA---- -------BB------- -------CC------- -------CC------- -------CC------- ---------------- -------DD------- -------DD------- 
---A--------A--- ---A--------A--- ---AAAAAAAAAA--- ---AAAAAAAAAA--- ---EAAAAAAAAE--- -AAAAAAAAAAAAAA- -AAAAAAAAAAAAAA- -AAAAAAAAAAAAAA- -AAAIJAAAAJIAAA- AAAAIIAAAAIIAAAA AAAAAAAAAAAAAAAA -AAAAAAAAAAAAAA- -AAAAAAAAAAAAAA- -AAAAAAAAAAAAAA- -AAAAAAAAAAAAAA- --AAAAAAAAAAAA-- ---AAAAAAAAAA--- ----BBBBBBBB---- ----CCCCCCCC---- ----CFFCCFFC---- ----C--CC--C---- ----C------C---- -------DD------- -------DD------- 
---------------- ---------------- ---AAAAAAAAAA--- ---AAAAAAAAAA--- ---EAAAAAAAAE--- AAAAAAAAAAAAAAAA AAAAAAAAAAAAAAAA AAAAAAAAAAAAAAAA AAAAAAAAAAAAAAAA AAAAAAAAAAAAAAAA AAAAAAAAAAAAAAAA AAAAAAAAAAAAAAAA AAAAAAAAAAAAAAAA AAAAAAAAAAAAAAAA AAAAAAAAAAAAAAAA -AAAAAAAAAAAAAA- --AAAAAAAAAAAA-- ---BBBBBBBBBB--- ---FHAAAAAAHF--- ---FC------CF--- ---FC------CF--- ---FC------CF--- ---J--------J--- ---------------- 
---------------- ---------------- ---AAAAAAAAAA--- ---AAAAAAAAAA--- ---EAAAAAAAAE--- AAAAAAAAAAAAAAAA AAAAAAAAAAAAAAAA AAAAAAAAAAAAAAAA AAAAAAAAAAAAAAAA AAAAAAAAAAAAAAAA AAAAAAAAAAAAAAAA AAAAAAAAAAAAAAAA AAAAAAAAAAAAAAAA AAAAAAAAAAAAAAAA AAAAAAAAAAAAAAAA AAAAAAAAAAAAAAAA -AAAAAAAAAAAAAA- --BBBBBBBBBBBB-- --CHAAAAAAAAHC-- --CC--------CC-- --CC--------CC-- --CC--------CC-- ---------------- ---------------- 
---A--------A--- ---A--------A--- ---A--------A--- ---AAAAAAAAAA--- ---EAAAAAAAAE--- AAAAAAAAAAAAAAAA AAAAAAAAAAAAAAAA AAAAAAAAAAAAAAAA AAAAAAAAAAAAAAAA AAAAAAAAAAAAAAAA AAAAAAAAAAAAAAAA AAAAAAAAAAAAAAAA AAAAAAAAAAAAAAAA AAAAAAAAAAAAAAAA AAAAAAAAAAAAAAAA AAAAAAAAAAAAAAAA -AAAAAAAAAAAAAA- --BBBBBBBBBBBB-- --CAAAAAAAAAAC-- --F---AAAA---F-- ---------------- ---------------- ---------------- ---------------- 
---A--------A--- ---A--------A--- ---A--------A--- ---AAAAAAAAAA--- ---EAAAAAAAAE--- AAAAAAAAAAAAAAAA AAAAAAAAAAAAAAAA AAAAAAAAAAAAAAAA AAAAAAAAAAAAAAAA AAAAAAAAAAAAAAAA AAAAAAAAAAAAAAAA AAAAAAAAAAAAAAAA AAAAAAAAAAAAAAAA AAAAAAAAAAAAAAAA AAAAAAAAAAAAAAAA AAAAAAAAAAAAAAAA -AAAAAAAAAAAAAA- --BBBBBBBBBBBB-- --CAAAAAAAAAAC-- --F--AAAAAA--F-- ---------------- ---------------- ---------------- ---------------- 
---------------- ---------------- ---------------- ---AAAAAAAAAA--- ---EAAAAAAAAE--- AAAAAAAAAAAAAAAA AAAAAAAAAAAAAAAA AAAAAAAAAAAAAAAA AAAAAAAAAAAAAAAA AAAAAAAAAAAAAAAA AAAAAAAAAAAAAAAA AAAAAAAAAAAAAAAA AAAAAAAAAAAAAAAA AAAAAAAAAAAAAAAA AAAAAAAAAAAAAAAA AAAAAAAAAAAAAAAA AAAAAAAAAAAAAAAA -BBBBBBBBBBBBBB- -CCAAAAAAAAAACC- -CC--AAAAAA--CC- -CC----------CC- ---------------- -DD----------DD- -DD----------DD- 
---------------- ---------------- ---------------- ---AAAAAAAAAA--- ---EAAAAAAAAE--- AAAAAAAAAAAAAAAA AAAAAAAAAAAAAAAA AAAAAAAAAAAAAAAA AAAAAAAAAAAAAAAA AAAAAAAAAAAAAAAA AAAAAAAAAAAAAAAA AAAAAAAAAAAAAAAA AAAAAAAAAAAAAAAA AAAAAAAAAAAAAAAA AAAAAAAAAAAAAAAA AAAAAAAAAAAAAAAA AAAAAAAAAAAAAAAA -BBBBBBBBBBBBBB- -CCAAAAAAAAAACC- -CC--AAAAAA--CC- -CC----------CC- ---------------- -DD----------DD- -DD----------DD- 
---------------- ---------------- ---------------- ---AAAAAAAAAA--- ---EAAAAAAAAE--- AAAAAAAAAAAAAAAA AAAAAAAAAAAAAAAA AAAAAAAAAAAAAAAA AAAAAAAAAAAAAAAA AAAAAAAAAAAAAAAA AAAAAAAAAAAAAAAA AAAAAAAAAAAAAAAA AAAAAAAAAAAAAAAA AAAAAAAAAAAAAAAA AAAAAAAAAAAAAAAA AAAAAAAAAAAAAAAA -AAAAAAAAAAAAAA- --BBBBBBBBBBBB-- --CAAAAAAAAAAC-- --C--AAAAAA--C-- ---------------- ---------------- ---------------- ---------------- 
---------------- ---------------- ---------------- ---AAAAAAAAAA--- ---EAAAAAAAAE--- AAAAAAAAAAAAAAAA AAAAAAAAAAAAAAAA AAAAAAAAAAAAAAAA AAAAAAAAAAAAAAAA AAAAAAAAAAAAAAAA AAAAAAAAAAAAAAAA AAAAAAAAAAAAAAAA AAAAAAAAAAAAAAAA AAAAAAAAAAAAAAAA AAAAAAAAAAAAAAAA AAAAAAAAAAAAAAAA -AAAAAAAAAAAAAA- --BBBBBBBBBBBB-- --CAAAAAAAAAAC-- --C---AAAA---C-- ---------------- ---------------- ---------------- ---------------- 
---------------- ---------------- ---------------- ---AAAAAAAAAA--- ---EAAAAAAAAE--- AAAAAAAAAAAAAAAA AAAAAAAAAAAAAAAA AAAAAAAAAAAAAAAA AAAAAAAAAAAAAAAA AAAAAAAAAAAAAAAA AAAAAAAAAAAAAAAA AAAAAAAAAAAAAAAA AAAAAAAAAAAAAAAA AAAAAAAAAAAAAAAA AAAAAAAAAAAAAAAA AAAAAAAAAAAAAAAA -AAAAAAAAAAAAAA- --BBBBBBBBBBBB-- --CHAAAAAAAAHC-- --CC--------CC-- --CC--------CC-- --CC--------CC-- ---------------- ---------------- 
---------------- ---------------- ---------------- ---AAAAAAAAAA--- ---EAAAAAAAAE--- AAAAAAAAAAAAAAAA AAAAAAAAAAAAAAAA AAAAAAAAAAAAAAAA AAAAAAAAAAAAAAAA AAAAAAAAAAAAAAAA AAAAAAAAAAAAAAAA AAAAAAAAAAAAAAAA AAAAAAAAAAAAAAAA AAAAAAAAAAAAAAAA AAAAAAAAAAAAAAAA -AAAAAAAAAAAAAA- --AAAAAAAAAAAA-- ---BBBBBBBBBB--- ---FHAAAAAAHF--- ---FC------CF--- ---FC------CF--- ---FC------CF--- ---J--------J--- ---------------- 
---------------- ---------------- ---------------- ---AAAAAAAAAA--- ---EAAAAAAAAE--- -AAAAAAAAAAAAAA- AAAAAAAAAAAAAAAA AAAAAAAAAAAAAAAA AAAAAAAAAAAAAAAA AAAAAAAAAAAAAAAA AAAAAAAAAAAAAAAA AAAAAAAAAAAAAAAA AAAAAAAAAAAAAAAA AAAAAAAAAAAAAAAA -AAAAAAAAAAAAAA- --AAAAAAAAAAAA-- ---AAAAAAAAAA--- ----BBBBBBBB---- ----CCCCCCCC---- ----CCCCCCCC---- ----C--CC--C---- ----C------C---- -------DD------- -------DD------- 
---------------- ---------------- ---------------- ----AAAAAAAA---- ---EAAAAAAAAE--- --AAAAAAAAAAAA-- -AAAAAAAAAAAAAA- -AAAAAAAAAAAAAA- -AAAAAAAAAAAAAA- AAAAAAAAAAAAAAAA AAAAAAAAAAAAAAAA -AAAAAAAAAAAAAA- -AAAAAAAAAAAAAA- -AAAAAAAAAAAAAA- --AAAAAAAAAAAA-- ---AAAAAAAAAA--- ----AAAAAAAA---- -------BB------- -------CC------- -------CC------- -------CC------- ---------------- -------DD------- -------DD------- 
---------------- ---------------- ---------------- -------AA------- ----AAAAAAAA---- ---AAAAAAAAAA--- --AAAAAAAAAAAA-- --AAAAAAAAAAAA-- --AAAAAAAAAAAA-- -AAAAAAAAAAAAAA- -AAAAAAAAAAAAAA- --AAAAAAAAAAAA-- --AAAAAAAAAAAA-- --AAAAAAAAAAAA-- ---AAAAAAAAAA--- ----AAAAAAAA---- -------AA------- ---------------- ---------------- ---------------- ---------------- ---------------- ---------------- ---------------- 
---------------- ---------------- ---------------- ---------------- ---------------- -----AAAAAA----- ----AAAAAAAA---- ---AAAAAAAAAA--- ---AAAAAAAAAA--- ---AAAAAAAAAA--- ---AAAAAAAAAA--- ---AAAAAAAAAA--- ---AAAAAAAAAA--- ----AAAAAAAA---- -----AAAAAA----- ---------------- ---------------- ---------------- ---------------- ---------------- ---------------- ---------------- ---------------- ---------------- 
---------------- ---------------- ---------------- ---------------- ---------------- ---------------- ---------------- ------AAAA------ -----AAAAAA----- -----AAAAAA----- -----AAAAAA----- -----AAAAAA----- ------AAAA------ ---------------- ---------------- ---------------- ---------------- ---------------- ---------------- ---------------- ---------------- ---------------- ---------------- ---------------- 
