model
size = 16 20 18, scale = 0.05, origin = -y
material 
  colors = A:#FCFAF2 B:#222
voxels
-----AA--AA----- -----AA--AA----- ----AAAAAAAA---- ----AAAAAAAA---- ----AAAAAAAA---- --AAAAA--AAAAA-- --AAAAA--AAAAA-- --AA--AAAA--AA-- --A----AA----A-- --A----AA----A-- --A----AA----A-- --AAAAAAAAAAAA-- --AAAAAAAAAAAA-- --AAAAAAAAAAAA-- ---AAAAAAAAAA--- ----AAAAAAAA---- -------AA------- ---------------- ---------------- ---------------- 
---A--------A--- ---A--------A--- ---A---AA---A--- ---AAAAAAAAAA--- ---AAAAAAAAAA--- -AAAAAABBAAAAAA- -AAAAAAAAAAAAAA- -AAABBAAAABBAAA- -AAB--BAAB--BAA- -AAB--BAAB--BAA- -AABBBBAABBBBAA- -AAAAAAAAAAAAAA- -AAAAAAAAAAAAAA- -AAAAAAAAAAAAAA- --AAAAAAAAAAAA-- ---AAAAAAAAAA--- ----AAAAAAAA---- -------AA------- ---------------- ---------------- 
---A--------A--- ---A--------A--- ---AAAAAAAAAA--- ---AAAAAAAAAA--- ---AAAAAAAAAA--- -AAAAAAAAAAAAAA- -AAAAAAAAAAAAAA- -AAAAAAAAAAAAAA- -AAAAAAAAAAAAAA- AAAAAAAAAAAAAAAA AAAAAAAAAAAAAAAA -AAAAAAAAAAAAAA- -AAAAAAAAAAAAAA- -AAAAAAAAAAAAAA- -AAAAAAAAAAAAAA- --AAAAAAAAAAAA-- ---AAAAAAAAAA--- ----AAAAAAAA---- ---------------- ---------------- 
---------------- ---A-AAAAAA-A--- ---AAAAAAAAAA--- ---AAAAAAAAAA--- ---AAAAAAAAAA--- AAAAAAAAAAAAAAAA AAAAAAAAAAAAAAAA AAAAAAAAAAAAAAAA AAAAAAAAAAAAAAAA AAAAAAAAAAAAAAAA AAAAAAAAAAAAAAAA AAAAAAAAAAAAAAAA AAAAAAAAAAAAAAAA AAAAAAAAAAAAAAAA AAAAAAAAAAAAAAAA -AAAAAAAAAAAAAA- --AAAAAAAAAAAA-- ---AAAAAAAAAA--- -----AAAAAA----- ---------------- 
---------------- ---AAAAAAAAAA--- ---AAAAAAAAAA--- ---AAAAAAAAAA--- ---AAAAAAAAAA--- AAAAAAAAAAAAAAAA AAAAAAAAAAAAAAAA AAAAAAAAAAAAAAAA AAAAAAAAAAAAAAAA AAAAAAAAAAAAAAAA AAAAAAAAAAAAAAAA AAAAAAAAAAAAAAAA AAAAAAAAAAAAAAAA AAAAAAAAAAAAAAAA AAAAAAAAAAAAAAAA AAAAAAAAAAAAAAAA -AAAAAAAAAAAAAA- --AAAAAAAAAAAA-- ----AAAAAAAA---- ---------------- 
---A--------A--- ---A--------A--- ---A--------A--- ---AAAAAAAAAA--- ---AAAAAAAAAA--- AAAAAAAAAAAAAAAA AAAAAAAAAAAAAAAA AAAAAAAAAAAAAAAA AAAAAAAAAAAAAAAA AAAAAAAAAAAAAAAA AAAAAAAAAAAAAAAA AAAAAAAAAAAAAAAA AAAAAAAAAAAAAAAA AAAAAAAAAAAAAAAA AAAAAAAAAAAAAAAA AAAAAAAAAAAAAAAA -AAAAAAAAAAAAAA- --AAAAAAAAAAAA-- ---AAAAAAAAAA--- ------AAAA------ 
---A--------A--- ---A--------A--- ---A--------A--- ---AAAAAAAAAA--- ---AAAAAAAAAA--- AAAAAAAAAAAAAAAA AAAAAAAAAAAAAAAA AAAAAAAAAAAAAAAA AAAAAAAAAAAAAAAA AAAAAAAAAAAAAAAA AAAAAAAAAAAAAAAA AAAAAAAAAAAAAAAA AAAAAAAAAAAAAAAA AAAAAAAAAAAAAAAA AAAAAAAAAAAAAAAA AAAAAAAAAAAAAAAA -AAAAAAAAAAAAAA- --AAAAAAAAAAAA-- ---AAAAAAAAAA--- -----AAAAAA----- 
---------------- ---------------- ---------------- ---AAAAAAAAAA--- ---AAAAAAAAAA--- AAAAAAAAAAAAAAAA AAAAAAAAAAAAAAAA AAAAAAAAAAAAAAAA AAAAAAAAAAAAAAAA AAAAAAAAAAAAAAAA AAAAAAAAAAAAAAAA AAAAAAAAAAAAAAAA AAAAAAAAAAAAAAAA AAAAAAAAAAAAAAAA AAAAAAAAAAAAAAAA AAAAAAAAAAAAAAAA AAAAAAAAAAAAAAAA -AAAAAAAAAAAAAA- ---AAAAAAAAAA--- -----AAAAAA----- 
---------------- ---------------- ---------------- ---AAAAAAAAAA--- ---AAAAAAAAAA--- AAAAAAAAAAAAAAAA AAAAAAAAAAAAAAAA AAAAAAAAAAAAAAAA AAAAAAAAAAAAAAAA AAAAAAAAAAAAAAAA AAAAAAAAAAAAAAAA AAAAAAAAAAAAAAAA AAAAAAAAAAAAAAAA AAAAAAAAAAAAAAAA AAAAAAAAAAAAAAAA AAAAAAAAAAAAAAAA AAAAAAAAAAAAAAAA -AAAAAAAAAAAAAA- ---AAAAAAAAAA--- -----AAAAAA----- 
---------------- ---------------- ---------------- ---AAAAAAAAAA--- ---AAAAAAAAAA--- AAAAAAAAAAAAAAAA AAAAAAAAAAAAAAAA AAAAAAAAAAAAAAAA AAAAAAAAAAAAAAAA AAAAAAAAAAAAAAAA AAAAAAAAAAAAAAAA AAAAAAAAAAAAAAAA AAAAAAAAAAAAAAAA AAAAAAAAAAAAAAAA AAAAAAAAAAAAAAAA AAAAAAAAAAAAAAAA -AAAAAAAAAAAAAA- --AAAAAAAAAAAA-- ---AAAAAAAAAA--- -----AAAAAA----- 
---------------- ---------------- ---------------- ---AAAAAAAAAA--- ---AAAAAAAAAA--- AAAAAAAAAAAAAAAA AAAAAAAAAAAAAAAA AAAAAAAAAAAAAAAA AAAAAAAAAAAAAAAA AAAAAAAAAAAAAAAA AAAAAAAAAAAAAAAA AAAAAAAAAAAAAAAA AAAAAAAAAAAAAAAA AAAAAAAAAAAAAAAA AAAAAAAAAAAAAAAA AAAAAAAAAAAAAAAA -AAAAAAAAAAAAAA- --AAAAAAAAAAAA-- ---AAAAAAAAAA--- ------AAAA------ 
---------------- ---------------- ---------------- ---AAAAAAAAAA--- ---AAAAAAAAAA--- AAAAAAAAAAAAAAAA AAAAAAAAAAAAAAAA AAAAAAAAAAAAAAAA AAAAAAAAAAAAAAAA AAAAAAAAAAAAAAAA AAAAAAAAAAAAAAAA AAAAAAAAAAAAAAAA AAAAAAAAAAAAAAAA AAAAAAAAAAAAAAAA AAAAAAAAAAAAAAAA AAAAAAAAAAAAAAAA -AAAAAAAAAAAAAA- --AAAAAAAAAAAA-- ----AAAAAAAA---- ---------------- 
---------------- ---------------- ---------------- ---AAAAAAAAAA--- ---AAAAAAAAAA--- AAAAAAAAAAAAAAAA AAAAAAAAAAAAAAAA AAAAAAAAAAAAAAAA AAAAAAAAAAAAAAAA AAAAAAAAAAAAAAAA AAAAAAAAAAAAAAAA AAAAAAAAAAAAAAAA AAAAAAAAAAAAAAAA AAAAAAAAAAAAAAAA AAAAAAAAAAAAAAAA -AAAAAAAAAAAAAA- --AAAAAAAAAAAA-- ---AAAAAAAAAA--- -----AAAAAA----- ---------------- 
---------------- ---------------- ---------------- ---AAAAAAAAAA--- ---AAAAAAAAAA--- -AAAAAAAAAAAAAA- AAAAAAAAAAAAAAAA AAAAAAAAAAAAAAAA AAAAAAAAAAAAAAAA AAAAAAAAAAAAAAAA AAAAAAAAAAAAAAAA AAAAAAAAAAAAAAAA AAAAAAAAAAAAAAAA AAAAAAAAAAAAAAAA -AAAAAAAAAAAAAA- --AAAAAAAAAAAA-- ---AAAAAAAAAA--- ----AAAAAAAA---- ---------------- ---------------- 
---------------- ---------------- ---------------- ----AAAAAAAA---- ---AAAAAAAAAA--- --AAAAAAAAAAAA-- -AAAAAAAAAAAAAA- -AAAAAAAAAAAAAA- -AAAAAAAAAAAAAA- AAAAAAAAAAAAAAAA AAAAAAAAAAAAAAAA -AAAAAAAAAAAAAA- -AAAAAAAAAAAAAA- -AAAAAAAAAAAAAA- --AAAAAAAAAAAA-- ---AAAAAAAAAA--- ----AAAAAAAA---- -------AA------- ---------------- ---------------- 
---------------- ---------------- ---------------- -------AA------- ----AAAAAAAA---- ---AAAAAAAAAA--- --AAAAAAAAAAAA-- --AAAAAAAAAAAA-- --AAAAAAAAAAAA-- -AAAAAAAAAAAAAA- -AAAAAAAAAAAAAA- --AAAAAAAAAAAA-- --AAAAAAAAAAAA-- --AAAAAAAAAAAA-- ---AAAAAAAAAA--- ----AAAAAAAA---- -------AA------- ---------------- ---------------- ---------------- 
---------------- ---------------- ---------------- ---------------- ---------------- -----AAAAAA----- ----AAAAAAAA---- ---AAAAAAAAAA--- ---AAAAAAAAAA--- ---AAAAAAAAAA--- ---AAAAAAAAAA--- ---AAAAAAAAAA--- ---AAAAAAAAAA--- ----AAAAAAAA---- -----AAAAAA----- ---------------- ---------------- ---------------- ---------------- ---------------- 
---------------- ---------------- ---------------- ---------------- ---------------- ---------------- ---------------- ------AAAA------ -----AAAAAA----- -----AAAAAA----- -----AAAAAA----- -----AAAAAA----- ------AAAA------ ---------------- ---------------- ---------------- ---------------- ---------------- ---------------- ---------------- 
