model
size = 14 32 26, scale = 0.05, origin = -y
material 
  colors = A:#070 B:#0B0
voxels
76-2A2(11-3A)390-A11-6A8-6A7-7A2(8-6A)8-5AB344-5A8-7A6-9A5-3(10A4-)9A6-8A7-6A9-3A306-A10-7A6-9A5-10A4-10A3-11A3(4-10A)5-8A6-B6A302-6A6-9A5-10A3-11A3-3(12A2-)11AB2-11A4-10A5-8A7-5A277-2A10-6A6-10A4-10A3-12A2-12A2(-13A)2-12A2-11A4-10A4-9A6-8A7-6A9-3A249-3A9-7A6-10A3-11A3-12A3(-13A)-B12A2-12A3-2(10A4-)10A5-8A7-6A-B6-6A8-5A220-3A10-6A6-10A4-10A3-12A3(-13A)3(2-12A)2-11A3-11A2(4-10A)4-9A6-8A7-6A9-3A11-3A192-6A6-9A5-10A3-11A3-3(12A2-)12A2(-13A)2-12A2-2(11A3-)B2(10A4-)10A5-8A6-7AB7-2(6A8-)5A9-B153-5A8-8A5-10A2(3-11A)3-12A2-12A3(-13A)4(2-12A)2-11A3-11A3(4-10A)4-9A6-8A7-6A9-3A150-6A7-8A5-2(10A4-)10A3-12A3(-13A)2(2-12A)2(-13A)2-12A2-11A4-10A3-11A3(4-10A)5-8A7-2(6A8-)5A122-3A10-6A7-8A5-9A5-10A3-11A3-3(12A2-)12A3(-13A)5(2-12A)2-11A3-11A2(4-10A)4-9A6-8A7-6A9-3A12-B109-5A8-8A5-10A2(3-11A)3-2(12A2-)12A3(-13A)3(2-12A)2(-13A)2-12A2-11A3-11A2(4-10A)B3-10A5-8A7-6A8-5A121-6A7-8A5-3(10A4-)10A3-11A3-12AB-3(12A2-)12A3(-13A)4(2-12A)2-11A3-11A4-10A4-9A6-8A7-6A9-3A95-3A10-6A7-8A2(5-9A)5-10A2(3-11A)3-2(12A2-)11A3-12A3(-13A)2(2-12A)2(-13A)2-12A2-11A3(4-10A)5-8A7-6A121-3A10-5A9-6A7-8A5-4(10A4-)10A3-11A3-2(12A2-)12AB-12A3(-13A)3(2-12A)2-11A3-11A4-10A5-8A8-3A137-3A10-6A7-8A3(5-9A)5-10A2(3-11A)3-2(12A2-)12A3(-13A)2-12A2(-13A)2-12AB-11A4-10A4-9A7-5A151-B12-3A10-5A9-6A8-6A7-8A5-3(10A4-)10A3-11A3-2(12A2-)12A3(-13A)2(2-12A)3-10A4-9A7-6A205-3A10-6A7-8A2(5-9A)5-10A2(3-11A)3-12A2-12A3(-13A)2(2-12A)3-10A4-9A7-6A233-3A10-5A9-6A7-8A5-10A4-10A3-11A3-12A3(-13A)2(2-12A)3-10A4-9A7-6A261-3A-B8-6A7-8A5-10A4-10A3-12A3(-13A)2(2-12A)3-10A4-9A7-6A288-6A6-9A5-10A3-11A3-12A2-12AB-2(12A2-)11A4-10A5-8A8-4A289-5A8-8A5-10A2(3-11A)3-2(12A2-)11A4-10A4-9A6-7A10-2A304-6A7-8A5-5(10A4-)9A6-7A8-5A318-3A10-6AB6-8A3(5-9A)6-8A6-7A8-5A360-3A10-5A9-6A8-6A9-4A11-2A48-
