model
size = 25 30 31, scale = 0.05, origin = -y
material 
  colors = A:#BBB B:#001
voxels
------------------------- ------------------------- ------------------------- ------------------------- ------------------------- ------------------------- ------------------------- ------------------------- ------------------------- ------------------------- ------------------------- ------------------------- ------------------------- ------------------------- ------------------------- ------------------------- ------------------------- ------------------------- ------------------------- ------------------------- ------------------------- ------------------------- ------------------------- ------------------------- ------------------------- ---------BBBBB----------- ------------------------- ------------------------- ------------------------- ------------------------- 
------------------------- ------------------------- ------------------------- ------------------------- ------------------------- ------------------------- ------------------------- ------------------------- ------------------------- ------------------------- ------------------------- ------------------------- ------------------------- ------------------------- ------------------------- ------------------------- ------------------------- ------------------------- ------------------------- ------------------------- ------------------------- ------------------------- ------------------------- ------------------------- ------------------------- ---------BBBBB----------- ------------------------- ------------------------- ------------------------- ------------------------- 
------------------------- ------------------------- ------------------------- ------------------------- ------------------------- ------------------------- ------------------------- ------------------------- ------------------------- ------------------------- ------------------------- ------------------------- ------------------------- ------------------------- ------------------------- ------------------------- ------------------------- ------------------------- ------------------------- ------------------------- ------------------------- ------------------------- ------------------------- ------------------------- ------------------------- -----------B------------- ------------------------- ------------------------- ------------------------- ------------------------- 
------------------------- AAAAAAAAAAAAAAAAAAAAAAA-- AAAAAAAAAAAAAAAAAAAAAAA-- AAAAAAAAAAAAAAAAAAAAAAA-- AAAAAAAAAAAAAAAAAAAAAAA-- AAAAAAAAAAAAAAAAAAAAAAA-- AAAAAAAAAAA-AAAAAAAAAAA-- AAAAAAAAAAA-AAAAAAAAAAA-- AAAAAAAAAAA-AAAAAAAAAAA-- AAAAAAAAAAA-AAAAAAAAAAA-- AAAAAAAAAAA-AAAAAAAAAAA-- AAAAAAAAAAA-AAAAAAAAAAA-- AAAAAAAAAAA-AAAAAAAAAAA-- AAAAAAAAAAA-AAAAAAAAAAA-- AAAAAAAAAAA-AAAAAAAAAAA-- AAAAAAAAAAA-AAAAAAAAAAA-- AAAAAAAAAAA-AAAAAAAAAAA-- AAAAAAAAAAA-AAAAAAAAAAA-- AAAAAAAAAAA-AAAAAAAAAAA-- AAAAAAAAAAA-AAAAAAAAAAA-- AAAAAAAAAAA-AAAAAAAAAAA-- AAAAAAAAAAA-AAAAAAAAAAA-- AAAAAAAAAAA-AAAAAAAAAAA-- AAAAAAAAAAA-AAAAAAAAAAA-- AAAAAAAAAAA-AAAAAAAAAAA-- AAAAAAAAAAABAAAAAAAAAAA-- AAAAAAAAAAA-AAAAAAAAAAA-- AAAAAAAAAAA-AAAAAAAAAAA-- AAAAAAAAAAAAAAAAAAAAAAA-- AAAAAAAAAAAAAAAAAAAAAAA-- 
-BB-----------------BB--- AAAAAAAAAAAAAAAAAAAAAAA-- AAAAAAAAAAAAAAAAAAAAAAA-- AAAAAAAAAAAAAAAAAAAAAAA-- AAAAAAAAAAAAAAAAAAAAAAA-- AAAAAAAAAAAAAAAAAAAAAAA-- AAAAAAAAAAAAAAAAAAAAAAA-- AAAAAAAAAAAAAAAAAAAAAAA-- AAAAAAAAAAAAAAAAAAAAAAA-- AAAAAAAAAAAAAAAAAAAAAAA-- AAAAAAAAAAAAAAAAAAAAAAA-- AAAAAAAAAAAAAAAAAAAAAAA-- AAAAAAAAAAAAAAAAAAAAAAA-- AAAAAAAAAAAAAAAAAAAAAAA-- AAAAAAAAAAAAAAAAAAAAAAA-- AAAAAAAAAAAAAAAAAAAAAAA-- AAAAAAAAAAAAAAAAAAAAAAA-- AAAAAAAAAAAAAAAAAAAAAAA-- AAAAAAAAAAAAAAAAAAAAAAA-- AAAAAAAAAAAAAAAAAAAAAAA-- AAAAAAAAAAAAAAAAAAAAAAA-- AAAAAAAAAAAAAAAAAAAAAAA-- AAAAAAAAAAAAAAAAAAAAAAA-- AAAAAAAAAAAAAAAAAAAAAAA-- AAAAAAAAAAAAAAAAAAAAAAA-- AAAAAAAAAAAAAAAAAAAAAAA-- AAAAAAAAAAAAAAAAAAAAAAA-- AAAAAAAAAAAAAAAAAAAAAAA-- AAAAAAAAAAAAAAAAAAAAAAA-- AAAAAAAAAAAAAAAAAAAAAAA-- 
-BB-----------------BB--- AAAAAAAAAAAAAAAAAAAAAAA-- AAAAAAAAAAAAAAAAAAAAAAA-- AAAAAAAAAAAAAAAAAAAAAAA-- AAAAAAAAAAAAAAAAAAAAAAA-- AAAAAAAAAAAAAAAAAAAAAAA-- AAAAAAAAAAAAAAAAAAAAAAA-- AAAAAAAAAAAAAAAAAAAAAAA-- AAAAA----AAAAA----AAAAA-- AAAAA----AAAAA----AAAAA-- AAAAA----AAAAA----AAAAA-- AAAAA----AAAAA----AAAAA-- AAAAA----AAAAA----AAAAA-- AAAAA----AAAAA----AAAAA-- AAAAA----AAAAA----AAAAA-- AAAAA----AAAAA----AAAAA-- AAAAA----AAAAA----AAAAA-- AAAAA----AAAAA----AAAAA-- AAAAA----AAAAA----AAAAA-- AAAAA----AAAAA----AAAAA-- AAAAA----AAAAA----AAAAA-- AAAAA----AAAAA----AAAAA-- AAAAA----AAAAA----AAAAA-- AAAAA----AAAAA----AAAAA-- AAAAA----AAAAA----AAAAA-- AAAAA----AAAAA----AAAAA-- AAAAA----AAAAA----AAAAA-- AAAAA----AAAAA----AAAAA-- AAAAA----AAAAA----AAAAA-- AAAAA----AAAAA----AAAAA-- 
------------------------- AAAAAA---AAAAAAAAAAAAAA-- AAAAAAAAAAAAAAAAAAAAAAA-- AAAAAAAAAAAAAAAAAAAAAAA-- AAAAAAAAAAAAAAAAAAAAAAA-- AAAAAAAAAAAAAAAAAAAAAAA-- AAAAAAAAAAAAAAAAAAAAAAA-- AAAAAAAAAAAAAAAAAAAAAAA-- AAAAA----AAAAA----AAAAA-- AAAAA-----AAA-----AAAAA-- AAAAA-----AAA-----AAAAA-- AAAAA-----AAA-----AAAAA-- AAAAA-----AAA-----AAAAA-- AAAAA-----AAA-----AAAAA-- AAAAA-----AAA-----AAAAA-- AAAAA-----AAA-----AAAAA-- AAAAA-----AAA-----AAAAA-- AAAAA-----AAA-----AAAAA-- AAAAA-----AAA-----AAAAA-- AAAAA-----AAA-----AAAAA-- AAAAA-----AAA-----AAAAA-- AAAAA-----AAA-----AAAAA-- AAAAA-----AAA-----AAAAA-- AAAAA-----AAA-----AAAAA-- AAAAA-----AAA-----AAAAA-- AAAAA-----AAA-----AAAAA-- AAAAA-BBBAAAABBBB-AAAAA-- AAAAA----AAAA-----AAAAA-- AAAAA----AAAAA----AAAAA-- AAAAA----AAAAA----AAAAA-- 
------------------------- AAAAAAA-AA-----AAAAAAAA-- AAAAAAAAAAAAAAAAAAAAAAA-- AAAAAAAAAAAAAAAAAAAAAAA-- AAAAAAAAAAAAAAAAAAAAAAA-- AAAAAAAAAAAAAAAAAAAAAAA-- AAAAAAAAAAAAAAAAAAAAAAA-- AAAAAAAAAAAAAAAAAAAAAAA-- AAAAA----AAAAA----AAAAA-- AAAAA----AAAAA----AAAAA-- AAAAA----AAAAA----AAAAA-- AAAAA----AAAAA----AAAAA-- AAAAA----AAAAA----AAAAA-- AAAAA----AAAAA----AAAAA-- AAAAA----AAAAA----AAAAA-- AAAAA----AAAAA----AAAAA-- AAAAA----AAAAA----AAAAA-- AAAAA----AAAAA----AAAAA-- AAAAA----AAAAA----AAAAA-- AAAAA----AAAAA----AAAAA-- AAAAA----AAAAA----AAAAA-- AAAAA----AAAAA----AAAAA-- AAAAA----AAAAA----AAAAA-- AAAAA----AAAAA----AAAAA-- AAAAA----AAAAA----AAAAA-- AAAAA----AAAAA----AAAAA-- AAAAA--B-AAAAA-B--AAAAA-- AAAAA----AAAAA----AAAAA-- AAAAA----AAAAA----AAAAA-- AAAAA----AAAAA----AAAAA-- 
------------------------- AAAAAAA-AA-AAAAAAAAAAAA-- AAAAAAAAAAAAAAAAAAAAAAA-- AAAAAAAAAAAAAAAAAAAAAAA-- AAAAAAAAAAAAAAAAAAAAAAA-- AAAAAAAAAAAAAAAAAAAAAAA-- AAAAAAAAAAAAAAAAAAAAAAA-- AAAAAAAAAAAAAAAAAAAAAAA-- AAAAA----AAAAA----AAAAA-- AAAAA----AAAAA----AAAAA-- AAAAA----AAAAA----AAAAA-- AAAAA----AAAAA----AAAAA-- AAAAA----AAAAA----AAAAA-- AAAAA----AAAAA----AAAAA-- AAAAA----AAAAA----AAAAA-- AAAAA----AAAAA----AAAAA-- AAAAA----AAAAA----AAAAA-- AAAAA----AAAAA----AAAAA-- AAAAA----AAAAA----AAAAA-- AAAAA----AAAAA----AAAAA-- AAAAA----AAAAA----AAAAA-- AAAAA----AAAAA----AAAAA-- AAAAA----AAAAA----AAAAA-- AAAAA----AAAAA----AAAAA-- AAAAA----AAAAA----AAAAA-- AAAAA----AAAAA----AAAAA-- AAAAA--B-AAAAA-B--AAAAA-- AAAAA----AAAAA----AAAAA-- AAAAA----AAAAA----AAAAA-- AAAAA----AAAAA----AAAAA-- 
------------------------- AAAAAAA-AA-AAAAAAAAAAAA-- AAAAAAAAAAAAAAAAAAAAAAA-- AAAAAAAAAAAAAAAAAAAAAAA-- AAAAAAAAAAAAAAAAAAAAAAA-- AAAAAAAAAAAAAAAAAAAAAAA-- AAAAAAAAAAAAAAAAAAAAAAA-- AAAAAAAAAAAAAAAAAAAAAAA-- AAAAA----AAAAA----AAAAA-- AAAAA----AAAAA----AAAAA-- AAAAA----AAAAA----AAAAA-- AAAAA----AAAAA----AAAAA-- AAAAA----AAAAA----AAAAA-- AAAAA----AAAAA----AAAAA-- AAAAA----AAAAA----AAAAA-- AAAAA----AAAAA----AAAAA-- AAAAA----AAAAA----AAAAA-- AAAAA----AAAAA----AAAAA-- AAAAA----AAAAA----AAAAA-- AAAAA----AAAAA----AAAAA-- AAAAA----AAAAA----AAAAA-- AAAAA----AAAAA----AAAAA-- AAAAA----AAAAA----AAAAA-- AAAAA----AAAAA----AAAAA-- AAAAA----AAAAA----AAAAA-- AAAAA----AAAAA----AAAAA-- AAAAA-BB-AAAAA-BB-AAAAA-- AAAAA----AAAAA----AAAAA-- AAAAA----AAAAA----AAAAA-- AAAAA----AAAAA----AAAAA-- 
------------------------- AAAAAAA-AAAAAAAA-----AA-- AAAAAAAAAAAAAAAAAAAA-AA-- AAAAAAAAAAAAAAAAAAAAAAA-- AAAAAAAAAAAAAAAAAAAAAAA-- AAAAAAAAAAAAAAAAAAAAAAA-- AAAAAAAAAAAAAAAAAAAAAAA-- AAAAAAAAAAAAAAAAAAAAAAA-- AAAAA----AAAAA----AAAAA-- AAAAA----AAAAA----AAAAA-- AAAAA----AAAAA----AAAAA-- AAAAA----AAAAA----AAAAA-- AAAAA----AAAAA----AAAAA-- AAAAA----AAAAA----AAAAA-- AAAAA----AAAAA----AAAAA-- AAAAA----AAAAA----AAAAA-- AAAAA----AAAAA----AAAAA-- AAAAA----AAAAA----AAAAA-- AAAAA----AAAAA----AAAAA-- AAAAA----AAAAA----AAAAA-- AAAAA----AAAAA----AAAAA-- AAAAA----AAAAA----AAAAA-- AAAAA----AAAAA----AAAAA-- AAAAA----AAAAA----AAAAA-- AAAAA----AAAAA----AAAAA-- AAAAA----AAAAA----AAAAA-- AAAAA-B--AAAAA--B-AAAAA-- AAAAA----AAAAA----AAAAA-- AAAAA----AAAAA----AAAAA-- AAAAA----AAAAA----AAAAA-- 
------------------------- AAAAAAA-AA-----A-A-A-AA-- AAAAAAAAAAAAAAAAAAAA-AAB- AAAAAAAAAAAAAAAAAAAAAAAB- AAAAAAAAAAAAAAAAAAAAAAAB- AAAAAAAAAAAAAAAAAAAAAAA-- AAAAAAAAAAAAAAAAAAAAAAA-- AAAAAAAAAAAAAAAAAAAAAAA-- AAAAA----AAAAA----AAAAA-- AAAAA----AAAAA----AAAAA-- AAAAA----AAAAA----AAAAA-- AAAAA----AAAAA----AAAAA-- AAAAA----AAAAA----AAAAA-- AAAAA----AAAAA----AAAAA-- AAAAA----AAAAA----AAAAA-- AAAAA----AAAAA----AAAAA-- AAAAA----AAAAA----AAAAA-- AAAAA----AAAAA----AAAAA-- AAAAA----AAAAA----AAAAA-- AAAAA----AAAAA----AAAAA-- AAAAA----AAAAA----AAAAA-- AAAAA----AAAAA----AAAAA-- AAAAA----AAAAA----AAAAA-- AAAAA----AAAAA----AAAAA-- AAAAA----AAAAA----AAAAA-- AAAAA----AAAAA----AAAAA-- AAAAA-B--AAAAA--B-AAAAA-- AAAAA----AAAAA----AAAAA-- AAAAA----AAAAA----AAAAA-- AAAAA----AAAAA----AAAAA-- 
------------------------- AAAAAAA-AA-A-A-AA-A-AAA-- AAAAAAAAAAAAAAAAAAAAAAAB- AAAAAAAAAAAAAAAAAAAAAAABA AAAAAAAAAAAAAAAAAAAAAAAB- AAAAAAAAAAAAAAAAAAAAAAA-- AAAAAAAAAAAAAAAAAAAAAAA-- AAAAAAAAAAAAAAAAAAAAAAA-- AAAAA----AAAAA----AAAAA-- AAAAA----AAAAA----AAAAA-- AAAAA----AAAAA----AAAAB-- AAAAA----AAAAA----AAAAA-- AAAAA----AAAAA----AAAAA-- AAAAA----AAAAA----AAAAA-- AAAAA----AAAAA----AAAAA-- AAAAA----AAAAA----AAAAA-- AAAAA----AAAAA----AAAAA-- AAAAA----AAAAA----AAAAA-- AAAAA----AAAAA----AAAAA-- AAAAA----AAAAA----AAAAA-- AAAAA----AAAAA----AAAAA-- AAAAA----AAAAA----AAAAA-- AAAAA----AAAAA----AAAAA-- AAAAA----AAAAA----AAAAA-- AAAAA----AAAAA----AAAAA-- AAAAA----AAAAA----AAAAA-- AAAAA-BB-AAAAA-BB-AAAAA-- AAAAA----AAAAA----AAAAA-- AAAAA----AAAAA----AAAAA-- AAAAA----AAAAA----AAAAA-- 
------------------------- AAAAAAA-AAAAAAAAAAAAAAA-- AAAAAAAAAAAAAAAAAAAAAAAB- AAAAAAAAAAAAAAAAAAAAAAABA AAAAAAAAAAAAAAAAAAAAAAAB- AAAAAAAAAAAAAAAAAAAAAAA-- AAAAAAAAAAAAAAAAAAAAAAA-- AAAAAAAAAAAAAAAAAAAAAAA-- AAAAA----AAAAA----AAAAA-- AAAAA----AAAAA----AAAAA-- AAAAA----AAAAA----AAAAA-- AAAAA----AAAAA----AAAAA-- AAAAA----AAAAA----AAAAA-- AAAAA----AAAAA----AAAAB-- AAAAA----AAAAA----AAAAA-- AAAAA----AAAAA----AAAAA-- AAAAA----AAAAA----AAAAA-- AAAAA----AAAAA----AAAAA-- AAAAA----AAAAA----AAAAA-- AAAAA----AAAAA----AAAAA-- AAAAA----AAAAA----AAAAA-- AAAAA----AAAAA----AAAAA-- AAAAA----AAAAA----AAAAA-- AAAAA----AAAAA----AAAAA-- AAAAA----AAAAA----AAAAA-- AAAAA----AAAAA----AAAAA-- AAAAA--B-AAAAA-B--AAAAA-- AAAAA----AAAAA----AAAAA-- AAAAA----AAAAA----AAAAA-- AAAAA----AAAAA----AAAAA-- 
------------------------- AAAAAAA-AA-----A-----AA-- AAAAAAAAAAAAAAAAAAAAAAAB- AAAAAAAAAAAAAAAAAAAAAAAB- AAAAAAAAAAAAAAAAAAAAAAAB- AAAAAAAAAAAAAAAAAAAAAAA-- AAAAAAAAAAAAAAAAAAAAAAA-- AAAAAAAAAAAAAAAAAAAAAAA-- AAAAA----AAAAA----AAAAA-- AAAAA----AAAAA----AAAAAB- AAAAA----AAAAA----AAAAAB- AAAAA----AAAAA----AAAAA-- AAAAA----AAAAA----AAAAA-- AAAAA----AAAAA----AAAAA-- AAAAA----AAAAA----AAAAA-- AAAAA----AAAAA----AAAAA-- AAAAA----AAAAA----AAAAA-- AAAAA----AAAAA----AAAAA-- AAAAA----AAAAA----AAAAA-- AAAAA----AAAAA----AAAAA-- AAAAA----AAAAA----AAAAA-- AAAAA----AAAAA----AAAAA-- AAAAA----AAAAA----AAAAA-- AAAAA----AAAAA----AAAAA-- AAAAA----AAAAA----AAAAA-- AAAAA----AAAAA----AAAAA-- AAAAA--B-AAAAA-B--AAAAA-- AAAAA----AAAAA----AAAAA-- AAAAA----AAAAA----AAAAA-- AAAAA----AAAAA----AAAAA-- 
------------------------- AAAAAAA-AA-A-A-A-A-A-AA-- AAAAAAAAAAAAAAAAAAAAAAAB- AAAAAAAAAAAAAAAAAAAAAAAB- AAAAAAAAAAAAAAAAAAAAAAAB- AAAAAAAAAAAAAAAAAAAAAAA-- AAAAAAAAAAAAAAAAAAAAAAA-- AAAAAAAAAAAAAAAAAAAAAAA-- AAAAA----AAAAA----AAAAAB- AAAAA----AAAAA----AAAAA-- AAAAA----AAAAA----AAAAAB- AAAAA----AAAAA----AAAAAB- AAAAA----AAAAA----AAAAA-- AAAAA----AAAAA----AAAAA-- AAAAA----AAAAA----AAAAA-- AAAAA----AAAAA----AAAAA-- AAAAA----AAAAA----AAAAA-- AAAAA----AAAAA----AAAAA-- AAAAA----AAAAA----AAAAA-- AAAAA----AAAAA----AAAAA-- AAAAA----AAAAA----AAAAA-- AAAAA----AAAAA----AAAAA-- AAAAA----AAAAA----AAAAA-- AAAAA----AAAAA----AAAAA-- AAAAA----AAAAA----AAAAA-- AAAAA----AAAAA----AAAAA-- AAAAA-BB-AAAAA-BB-AAAAA-- AAAAA----AAAAA----AAAAA-- AAAAA----AAAAA----AAAAA-- AAAAA----AAAAA----AAAAA-- 
------------------------- AAAAAAA-AAAAAAAAAAAAAAA-- AAAAAAAAAAAAAAAAAAAAAAAB- AAAAAAAAAAAAAAAAAAAAAAABA AAAAAAAAAAAAAAAAAAAAAAAB- AAAAAAAAAAAAAAAAAAAAAAA-- AAAAAAAAAAAAAAAAAAAAAAA-- AAAAAAAAAAAAAAAAAAAAAAAB- AAAAA----AAAAA----AAAAA-- AAAAA----AAAAA----AAAAA-- AAAAA----AAAAA----AAAAA-- AAAAA----AAAAA----AAAAAB- AAAAA----AAAAA----AAAAAB- AAAAA----AAAAA----AAAAA-- AAAAA----AAAAA----AAAAB-- AAAAA----AAAAA----AAAAA-- AAAAA----AAAAA----AAAAA-- AAAAA----AAAAA----AAAAA-- AAAAA----AAAAA----AAAAA-- AAAAA----AAAAA----AAAAA-- AAAAA----AAAAA----AAAAA-- AAAAA----AAAAA----AAAAA-- AAAAA----AAAAA----AAAAA-- AAAAA----AAAAA----AAAAA-- AAAAA----AAAAA----AAAAA-- AAAAA----AAAAA----AAAAA-- AAAAA-B--AAAAA--B-AAAAA-- AAAAA----AAAAA----AAAAA-- AAAAA----AAAAA----AAAAA-- AAAAA----AAAAA----AAAAA-- 
------------------------- AAAAAAA-AAA----A-----AA-- AAAAAAAAAAAAAAAAAAAAAAAB- AAAAAAAAAAAAAAAAAAAAAAABA AAAAAAAAAAAAAAAAAAAAAAAB- AAAAAAAAAAAAAAAAAAAAAAA-- AAAAAAAAAAAAAAAAAAAAAAA-- AAAAAAAAAAAAAAAAAAAAAAA-- AAAAA----AAAAA----AAAABB- AAAAA----AAAAA----AAAAA-- AAAAA----AAAAA----AAAAAB- AAAAA----AAAAA----AAAAAB- AAAAA----AAAAA----AAAAA-- AAAAA----AAAAA----AAAAA-- AAAAA----AAAAA----AAAAA-- AAAAA----AAAAA----AAAAA-- AAAAA----AAAAA----AAAAA-- AAAAA----AAAAA----AAAAA-- AAAAA----AAAAA----AAAAA-- AAAAA----AAAAA----AAAAA-- AAAAA----AAAAA----AAAAA-- AAAAA----AAAAA----AAAAA-- AAAAA----AAAAA----AAAAA-- AAAAA----AAAAA----AAAAA-- AAAAA----AAAAA----AAAAA-- AAAAA----AAAAA----AAAAA-- AAAAA-B--AAAAA--B-AAAAA-- AAAAA----AAAAA----AAAAA-- AAAAA----AAAAA----AAAAA-- AAAAA----AAAAA----AAAAA-- 
------------------------- AAAAAAA-AA-AAAAAAA-A-AA-- AAAAAAAAAAAAAAAAAAAAAAAB- AAAAAAAAAAAAAAAAAAAAAAAB- AAAAAAAAAAAAAAAAAAAAAAAB- AAAAAAAAAAAAAAAAAAAAAAA-- AAAAAAAAAAAAAAAAAAAAAAA-- AAAAAAAAAAAAAAAAAAAAAAA-- AAAAA----AAAAA----AAAAA-- AAAAA----AAAAA----AAAAAB- AAAAA----AAAAA----AAAAAB- AAAAA----AAAAA----AAAAA-- AAAAA----AAAAA----AAAAA-- AAAAA----AAAAA----AAAAA-- AAAAA----AAAAA----AAAAA-- AAAAA----AAAAA----AAAAA-- AAAAA----AAAAA----AAAAA-- AAAAA----AAAAA----AAAAA-- AAAAA----AAAAA----AAAAA-- AAAAA----AAAAA----AAAAA-- AAAAA----AAAAA----AAAAA-- AAAAA----AAAAA----AAAAA-- AAAAA----AAAAA----AAAAA-- AAAAA----AAAAA----AAAAA-- AAAAA----AAAAA----AAAAA-- AAAAA----AAAAA----AAAAA-- AAAAA-BB-AAAAA-BB-AAAAA-- AAAAA----AAAAA----AAAAA-- AAAAA----AAAAA----AAAAA-- AAAAA----AAAAA----AAAAA-- 
------------------------- AAAAAAA-AA-AAAAA--A-AAA-- AAAAAAAAAAAAAAAAAAAAAAAB- AAAAAAAAAAAAAAAAAAAAAAAB- AAAAAAAAAAAAAAAAAAAAAAAB- AAAAAAAAAAAAAAAAAAAAAAA-- AAAAAAAAAAAAAAAAAAAAAAA-- AAAAAAAAAAAAAAAAAAAAAAA-- AAAAA----AAAAA----AAAAA-- AAAAA----AAAAA----AAAAA-- AAAAA----AAAAA----AAAAA-- AAAAA----AAAAA----AAAAA-- AAAAA----AAAAA----AAAAA-- AAAAA----AAAAA----AAAAB-- AAAAA----AAAAA----AAAAA-- AAAAA----AAAAA----AAAAA-- AAAAA----AAAAA----AAAAA-- AAAAA----AAAAA----AAAAA-- AAAAA----AAAAA----AAAAA-- AAAAA----AAAAA----AAAAA-- AAAAA----AAAAA----AAAAA-- AAAAA----AAAAA----AAAAA-- AAAAA----AAAAA----AAAAA-- AAAAA----AAAAA----AAAAA-- AAAAA----AAAAA----AAAAA-- AAAAA----AAAAA----AAAAA-- AAAAA--B-AAAAA-B--AAAAA-- AAAAA----AAAAA----AAAAA-- AAAAA----AAAAA----AAAAA-- AAAAA----AAAAA----AAAAA-- 
------------------------- AAAAAAA-AAA----AAAAAAAA-- AAAAAAAAAAAAAAAAAAAAAAAB- AAAAAAAAAAAAAAAAAAAAAAABA AAAAAAAAAAAAAAAAAAAAAAAB- AAAAAAAAAAAAAAAAAAAAAAA-- AAAAAAAAAAAAAAAAAAAAAAA-- AAAAAAAAAAAAAAAAAAAAAAA-- AAAAA----AAAAA----AAAAA-- AAAAA----AAAAA----AAAAA-- AAAAA----AAAAA----AAAAB-- AAAAA----AAAAA----AAAAA-- AAAAA----AAAAA----AAAAA-- AAAAA----AAAAA----AAAAA-- AAAAA----AAAAA----AAAAA-- AAAAA----AAAAA----AAAAA-- AAAAA----AAAAA----AAAAA-- AAAAA----AAAAA----AAAAA-- AAAAA----AAAAA----AAAAA-- AAAAA----AAAAA----AAAAA-- AAAAA----AAAAA----AAAAA-- AAAAA----AAAAA----AAAAA-- AAAAA----AAAAA----AAAAA-- AAAAA----AAAAA----AAAAA-- AAAAA----AAAAA----AAAAA-- AAAAA----AAAAA----AAAAA-- AAAAA--B-AAAAA-B--AAAAA-- AAAAA----AAAAA----AAAAA-- AAAAA----AAAAA----AAAAA-- AAAAA----AAAAA----AAAAA-- 
------------------------- AAAAAAA-AAAAAAAAA---AAA-- AAAAAAAAAAAAAAAAAAAAAAAB- AAAAAAAAAAAAAAAAAAAAAAABA AAAAAAAAAAAAAAAAAAAAAAAB- AAAAAAAAAAAAAAAAAAAAAAA-- AAAAAAAAAAAAAAAAAAAAAAA-- AAAAAAAAAAAAAAAAAAAAAAA-- AAAAA----AAAAA----AAAAA-- AAAAA----AAAAA----AAAAA-- AAAAA----AAAAA----AAAAA-- AAAAA----AAAAA----AAAAA-- AAAAA----AAAAA----AAAAA-- AAAAA----AAAAA----AAAAA-- AAAAA----AAAAA----AAAAA-- AAAAA----AAAAA----AAAAA-- AAAAA----AAAAA----AAAAA-- AAAAA----AAAAA----AAAAA-- AAAAA----AAAAA----AAAAA-- AAAAA----AAAAA----AAAAA-- AAAAA----AAAAA----AAAAA-- AAAAA----AAAAA----AAAAA-- AAAAA----AAAAA----AAAAA-- AAAAA----AAAAA----AAAAA-- AAAAA----AAAAA----AAAAA-- AAAAA----AAAAA----AAAAA-- AAAAA-BB-AAAAA-BB-AAAAA-- AAAAA----AAAAA----AAAAA-- AAAAA----AAAAA----AAAAA-- AAAAA----AAAAA----AAAAA-- 
------------------------- AAAAAAA-AAA----A-AAA-AA-- AAAAAAAAAAAAAAAAAAAAAAAB- AAAAAAAAAAAAAAAAAAAAAAAB- AAAAAAAAAAAAAAAAAAAAAAAB- AAAAAAAAAAAAAAAAAAAAAAA-- AAAAAAAAAAAAAAAAAAAAAAA-- AAAAAAAAAAAAAAAAAAAAAAA-- AAAAA----AAAAA----AAAAA-- AAAAA----AAAAA----AAAAA-- AAAAA----AAAAA----AAAAA-- AAAAA----AAAAA----AAAAA-- AAAAA----AAAAA----AAAAA-- AAAAA----AAAAA----AAAAA-- AAAAA----AAAAA----AAAAA-- AAAAA----AAAAA----AAAAA-- AAAAA----AAAAA----AAAAA-- AAAAA----AAAAA----AAAAA-- AAAAA----AAAAA----AAAAA-- AAAAA----AAAAA----AAAAA-- AAAAA----AAAAA----AAAAA-- AAAAA----AAAAA----AAAAA-- AAAAA----AAAAA----AAAAA-- AAAAA----AAAAA----AAAAA-- AAAAA----AAAAA----AAAAA-- AAAAA----AAAAA----AAAAA-- AAAAA-B--AAAAA--B-AAAAA-- AAAAA----AAAAA----AAAAA-- AAAAA----AAAAA----AAAAA-- AAAAA----AAAAA----AAAAA-- 
------------------------- AAAAAAA-AA-AAAAA--AA-AA-- AAAAAAAAAAAAAAAAAAAAAAA-- AAAAAAAAAAAAAAAAAAAAAAA-- AAAAAAAAAAAAAAAAAAAAAAA-- AAAAAAAAAAAAAAAAAAAAAAA-- AAAAAAAAAAAAAAAAAAAAAAA-- AAAAAAAAAAAAAAAAAAAAAAA-- AAAAA----AAAAA----AAAAA-- AAAAA----AAAAA----AAAAA-- AAAAA----AAAAA----AAAAA-- AAAAA----AAAAA----AAAAA-- AAAAA----AAAAA----AAAAA-- AAAAA----AAAAA----AAAAA-- AAAAA----AAAAA----AAAAA-- AAAAA----AAAAA----AAAAA-- AAAAA----AAAAA----AAAAA-- AAAAA----AAAAA----AAAAA-- AAAAA----AAAAA----AAAAA-- AAAAA----AAAAA----AAAAA-- AAAAA----AAAAA----AAAAA-- AAAAA----AAAAA----AAAAA-- AAAAA----AAAAA----AAAAA-- AAAAA----AAAAA----AAAAA-- AAAAA----AAAAA----AAAAA-- AAAAA----AAAAA----AAAAA-- AAAAA-B--AAAAA--B-AAAAA-- AAAAA----AAAAA----AAAAA-- AAAAA----AAAAA----AAAAA-- AAAAA----AAAAA----AAAAA-- 
------------------------- AAAAAAA-AA---AAAAAAAAAA-- AAAAAAAAAA---AAAAAAAAAA-- AAAAAAAAAAAAAAAAAAAAAAA-- AAAAAAAAAAAAAAAAAAAAAAA-- AAAAAAAAAAAAAAAAAAAAAAA-- AAAAAAAAAAAAAAAAAAAAAAA-- AAAAAAAAAAAAAAAAAAAAAAA-- AAAAA----AAAAA----AAAAA-- AAAAA----AAAAA----AAAAA-- AAAAA----AAAAA----AAAAA-- AAAAA----AAAAA----AAAAA-- AAAAA----AAAAA----AAAAA-- AAAAA----AAAAA----AAAAA-- AAAAA----AAAAA----AAAAA-- AAAAA----AAAAA----AAAAA-- AAAAA----AAAAA----AAAAA-- AAAAA----AAAAA----AAAAA-- AAAAA----AAAAA----AAAAA-- AAAAA----AAAAA----AAAAA-- AAAAA----AAAAA----AAAAA-- AAAAA----AAAAA----AAAAA-- AAAAA----AAAAA----AAAAA-- AAAAA----AAAAA----AAAAA-- AAAAA----AAAAA----AAAAA-- AAAAA----AAAAA----AAAAA-- AAAAA-BB-AAAAA-BB-AAAAA-- AAAAA----AAAAA----AAAAA-- AAAAA----AAAAA----AAAAA-- AAAAA----AAAAA----AAAAA-- 
------------------------- AAAAAAA-AA-AAAAAAAAAAAA-- AAAAAAAAAAAAAAAAAAAAAAA-- AAAAAAAAAAAAAAAAAAAAAAA-- AAAAAAAAAAAAAAAAAAAAAAA-- AAAAAAAAAAAAAAAAAAAAAAA-- AAAAAAAAAAAAAAAAAAAAAAA-- AAAAAAAAAAAAAAAAAAAAAAA-- AAAAA----AAAAA----AAAAA-- AAAAA----AAAAA----AAAAA-- AAAAA----AAAAA----AAAAA-- AAAAA----AAAAA----AAAAA-- AAAAA----AAAAA----AAAAA-- AAAAA----AAAAA----AAAAA-- AAAAA----AAAAA----AAAAA-- AAAAA----AAAAA----AAAAA-- AAAAA----AAAAA----AAAAA-- AAAAA----AAAAA----AAAAA-- AAAAA----AAAAA----AAAAA-- AAAAA----AAAAA----AAAAA-- AAAAA----AAAAA----AAAAA-- AAAAA----AAAAA----AAAAA-- AAAAA----AAAAA----AAAAA-- AAAAA----AAAAA----AAAAA-- AAAAA----AAAAA----AAAAA-- AAAAA----AAAAA----AAAAA-- AAAAA--B-AAAAA-B--AAAAA-- AAAAA----AAAAA----AAAAA-- AAAAA----AAAAA----AAAAA-- AAAAA----AAAAA----AAAAA-- 
------------------------- AAAAAAA-AAA----AAAAAAAA-- AAAAAAAAAAAAAAAAAAAAAAA-- AAAAAAAAAAAAAAAAAAAAAAA-- AAAAAAAAAAAAAAAAAAAAAAA-- AAAAAAAAAAAAAAAAAAAAAAA-- AAAAAAAAAAAAAAAAAAAAAAA-- AAAAAAAAAAAAAAAAAAAAAAA-- AAAAA----AAAAA----AAAAA-- AAAAA----AAAAA----AAAAA-- AAAAA----AAAAA----AAAAA-- AAAAA----AAAAA----AAAAA-- AAAAA----AAAAA----AAAAA-- AAAAA----AAAAA----AAAAA-- AAAAA----AAAAA----AAAAA-- AAAAA----AAAAA----AAAAA-- AAAAA----AAAAA----AAAAA-- AAAAA----AAAAA----AAAAA-- AAAAA----AAAAA----AAAAA-- AAAAA----AAAAA----AAAAA-- AAAAA----AAAAA----AAAAA-- AAAAA----AAAAA----AAAAA-- AAAAA----AAAAA----AAAAA-- AAAAA----AAAAA----AAAAA-- AAAAA----AAAAA----AAAAA-- AAAAA----AAAAA----AAAAA-- AAAAA--B-AAAAA-B--AAAAA-- AAAAA----AAAAA----AAAAA-- AAAAA----AAAAA----AAAAA-- AAAAA----AAAAA----AAAAA-- 
------------------------- AAAAAA---AAAAAAAAAAAAAA-- AAAAAAAAAAAAAAAAAAAAAAA-- AAAAAAAAAAAAAAAAAAAAAAA-- AAAAAAAAAAAAAAAAAAAAAAA-- AAAAAAAAAAAAAAAAAAAAAAA-- AAAAAAAAAAAAAAAAAAAAAAA-- AAAAAAAAAAAAAAAAAAAAAAA-- AAAAA----AAAAA----AAAAA-- AAAAA----AAAAA----AAAAA-- AAAAA----AAAAA----AAAAA-- AAAAA----AAAAA----AAAAA-- AAAAA----AAAAA----AAAAA-- AAAAA----AAAAA----AAAAA-- AAAAA----AAAAA----AAAAA-- AAAAA----AAAAA----AAAAA-- AAAAA----AAAAA----AAAAA-- AAAAA----AAAAA----AAAAA-- AAAAA----AAAAA----AAAAA-- AAAAA----AAAAA----AAAAA-- AAAAA----AAAAA----AAAAA-- AAAAA----AAAAA----AAAAA-- AAAAA----AAAAA----AAAAA-- AAAAA----AAAAA----AAAAA-- AAAAA----AAAAA----AAAAA-- AAAAA----AAAAA----AAAAA-- AAAAA-BB-AAAAA-BB-AAAAA-- AAAAA----AAAAA----AAAAA-- AAAAA----AAAAA----AAAAA-- AAAAA----AAAAA----AAAAA-- 
-BB-----------------BB--- AAAAAAAAAAAAAAAAAAAAAAA-- AAAAAAAAAAAAAAAAAAAAAAA-- AAAAAAAAAAAAAAAAAAAAAAA-- AAAAAAAAAAAAAAAAAAAAAAA-- AAAAAAAAAAAAAAAAAAAAAAA-- AAAAAAAAAAAAAAAAAAAAAAA-- AAAAAAAAAAAAAAAAAAAAAAA-- AAAAA----AAAAA----AAAAA-- AAAAA----AAAAA----AAAAA-- AAAAA----AAAAA----AAAAA-- AAAAA----AAAAA----AAAAA-- AAAAA----AAAAA----AAAAA-- AAAAA----AAAAA----AAAAA-- AAAAA----AAAAA----AAAAA-- AAAAA----AAAAA----AAAAA-- AAAAA----AAAAA----AAAAA-- AAAAA----AAAAA----AAAAA-- AAAAA----AAAAA----AAAAA-- AAAAA----AAAAA----AAAAA-- AAAAA----AAAAA----AAAAA-- AAAAA----AAAAA----AAAAA-- AAAAA----AAAAA----AAAAA-- AAAAA----AAAAA----AAAAA-- AAAAA----AAAAA----AAAAA-- AAAAA----AAAAA----AAAAA-- AAAAA----AAAAA----AAAAA-- AAAAA----AAAAA----AAAAA-- AAAAA----AAAAA----AAAAA-- AAAAA----AAAAA----AAAAA-- 
-BB-----------------BB--- AAAAAAAAAAAAAAAAAAAAAAA-- AAAAAAAAAAAAAAAAAAAAAAA-- AAAAAAAAAAAAAAAAAAAAAAA-- AAAAAAAAAAAAAAAAAAAAAAA-- AAAAAAAAAAAAAAAAAAAAAAA-- AAAAAAAAAAAAAAAAAAAAAAA-- AAAAAAAAAAAAAAAAAAAAAAA-- AAAAA----AAAAAAAAAAAAAA-- AAAAA----AAAAAAAAAAAAAA-- AAAAA----AAAAAAAAAAAAAA-- AAAAA----AAAAAAAAAAAAAA-- AAAAA----AAAAAAAAAAAAAA-- AAAAA----AAAAAAAAAAAAAA-- AAAAA----AAAAAAAAAAAAAA-- AAAAAAAAAAAAAAAAAAAAAAA-- AAAAAAAAAAAAAAAAAAAAAAA-- AAAAAAAAAAAAAAAAAAAAAAA-- AAAAAAAAAAAAAAAAAAAAAAA-- AAAAAAAAAAAAAAAAAAAAAAA-- AAAAAAAAAAAAAAAAAAAAAAA-- AAAAAAAAAAAAAAAAAAAAAAA-- AAAAAAAAAAAAAAAAAAAAAAA-- AAAAAAAAAAAAAAAAAAAAAAA-- AAAAAAAAAAAAAAAAAAAAAAA-- AAAAAAAAAAAAAAAAAAAAAAA-- AAAAAAAAAAAAAAAAAAAAAAA-- AAAAAAAAAAAAAAAAAAAAAAA-- AAAAAAAAAAAAAAAAAAAAAAA-- AAAAAAAAAAAAAAAAAAAAAAA-- 
------------------------- AAAAAAAAAAAAAAAAAAAAAAA-- AAAAAAAAAAAAAAAAAAAAAAA-- AAAAAAAAAAAAAAAAAAAAAAA-- AAAAAAAAAAAAAAAAAAAAAAA-- AAAAAAAAAAAAAAAAAAAAAAA-- AAAAAAAAAAAAAAAAAAAAAAA-- AAAAAAAAAAAAAAAAAAAAAAA-- AAAAAAAAAAAAAAAAAAAAAAA-- AAAAAAAAAAAAAAAAAAAAAAA-- AAAAAAAAAAAAAAAAAAAAAAA-- AAAAAAAAAAAAAAAAAAAAAAA-- AAAAAAAAAAAAAAAAAAAAAAA-- AAAAAAAAAAAAAAAAAAAAAAA-- AAAAAAAAAAAAAAAAAAAAAAA-- AAAAAAAAAAAAAAAAAAAAAAA-- AAAAAAAAAAAAAAAAAAAAAAA-- AAAAAAAAAAAAAAAAAAAAAAA-- AAAAAAAAAAAAAAAAAAAAAAA-- AAAAAAAAAAAAAAAAAAAAAAA-- AAAAAAAAAAAAAAAAAAAAAAA-- AAAAAAAAAAAAAAAAAAAAAAA-- AAAAAAAAAAAAAAAAAAAAAAA-- AAAAAAAAAAAAAAAAAAAAAAA-- AAAAAAAAAAAAAAAAAAAAAAA-- AAAAAAAAAAAAAAAAAAAAAAA-- AAAAAAAAAAAAAAAAAAAAAAA-- AAAAAAAAAAAAAAAAAAAAAAA-- AAAAAAAAAAAAAAAAAAAAAAA-- AAAAAAAAAAAAAAAAAAAAAAA-- 
