model
size = 32 32 9, scale = 0.05, origin = -y
material 
  colors = A:#3A2D0B B:#E7FFF7 C:#FFF D:#FF3 E:#F09 F:#0C9 G:#F60 H:#00E
voxels
47-2B26-10B20-3BG4BF6B16-3BGBD2BCBFD4B15-2BF2BDBE2BCBEBG3B13-4BCBFE2BHBEBGBC3B11-3BH2BC8BDCBF3B9-3BHBE4B4-3BDFHD3B8-2BCBE3B8-2BHBCBFB7-4BCBDB10-3BGC3B6-2BDFBDB12-BD2BE2B6-2BEBF2B12-3BE3B5-4BEBG14-2BFBH2B4-2BFCBGB14-BFBHBDB4-BF2BCDB14-3BDG2B4-2BEBD2B14-2BGCBGB4-3BE3B14-BG2BC2B5-2BCBHB14-3BE2B6-BCFH3B12-3BEF2B6-3BF3B12-2BG2BHB6-3BCG3B10-2BGBC3B7-3BC4B8-2BDBEBCB8-2BD2BH4B4-3BDBE4B8-BE5BG9BCGBD2B9-2BEBFCG5BG3BHBCF2B11-4BFCBE2BG2BDH5B13-4BD2BEDBCD2BE3B16-7BCF2BE3B20-4BF5B25-4B61-2A26-10A20-14A16-18A13-AB15A2BA11-22A9-AB22A8-23AB7-25AB6-11A4-10AB5-11A6-11A4-10A8-10A4-9A10-9A4-8A12-8A3-3(B8A12-9A2-)9A12-9A3-8A12-8A4-9A10-9A4-10A8-10A4-11A6-11A5-B10A4-10AB7-B24A7-B23A8-24A9-22A11-20A12-2AB16A16-12ABA20-10A55-8A21-14A17-16A14-17AB2A11-18A2B2A9-24A8-24A7-26A5-2(28A4-)12A4-12A3-2(11A8-11A2-)2(10A10-10A2-)2(9A12-9A2-)2(10A10-10A2-)11A8-11A2-11A8-11A3-2(12A4-)28A4-28A6-25A7-24A8-24A9-22A11-20A14-16A17-14A21-8A23-10A20-14A17-16A14-20A11-22A9-24A8-24A7-26A5-28A4-28A3-13A4-13A2-12A6-12A2-11A8-11A-11A5(10-22A)10-11A-11A8-11A2-12A6-12A2-13A4-13A3-28A4-28A5-26A7-24A8-24A9-22A11-20A14-16A17-14A20-10A22-10A20-14A16-18A13-20A11-22A9-24A7-26A6-26A5-28A4-28A3-13A4-13A2-12A6-12A-12A8-23A5(10-22A)10-23A8-12A-12A6-12A2-13A4-13A3-28A4-28A5-26A6-26A7-24A9-22A11-20A13-18A16-14A20-10A22-10A20-14A17-16A14-20A11-22A9-24A8-24A7-26A5-28A4-28A3-13A4-13A2-12A6-12A2-11A8-11A-11A5(10-22A)10-11A-11A8-11A2-12A6-12A2-13A4-13A3-28A4-28A5-26A7-24A8-24A9-22A11-20A14-16A17-14A20-10A23-8A21-14A17-16A14-20A11-22A9-24A8-24A7-26A5-2(28A4-)12A4-12A3-2(11A8-11A2-)2(10A10-10A2-)2(9A12-9A2-)2(10A10-10A2-)11A8-11A2-11A8-11A3-2(12A4-)28A4-28A5-26A7-24A8-24A9-22A11-20A14-16A17-14A21-8A27-2A26-10A20-14A16-18A13-20A11-22A9-24A8-24A7-26A6-11A4-11A5-11A6-11A4-10A8-10A4-9A10-9A4-8A12-8A3-3(9A12-9A2-)9A12-9A3-8A12-8A4-9A10-9A4-10A8-10A4-11A6-11A5-11A4-11A6-26A7-24A8-24A9-22A11-20A13-18A16-14A20-10A89-4A25-10A20-14A17-16A15-18A13-20A11-22A9-10A4-10A2(8-8A)7-8A10-8A2(6-7A12-7A)5-5(7A14-7A4-)7A14-7A5-2(7A12-7A6-)8A10-8A7-2(8A8-)10A4-10A9-22A11-20A13-18A15-16A17-14A20-10A25-4A46-
