model
size = 12 32 32, scale = 0.05, origin = -y
material 
  colors = A:#FFF B:#C66 C:#F96 D:#996 E:#F99 F:#FAFAFA G:#3F3F3F H:#1F1F1F I:#000 J:#CC9 K:#D0D0D0 L:#CC6 M:#7E7E7E N:#966 O:#EDEDED P:#9D9D9D Q:#888 R:#CCC S:#BBB T:#EEE U:#969696 V:#633 W:#666 X:#B3B3B3 Y:#555 Z:#999 Aa:#333 Ab:#FC9 Ac:#5C5C5C Ad:#777 Ae:#663 Af:#963 Ag:#797979 Ah:#AAA Ai:#444
voxels
248-Ai8-5X6-7OA4-7FA2(4-8A)5-6FA6-P3T295-5A6-7A4-4(9A3-)9A4-7A6-5A154-3H9-3D3(9-3J)2(9-3E)2(9-3C)9-3B5-4O3N4-5A3AeA3-9A5(2-10A)3-9A4-8A5-5A118-3Ae9-3B9-3E2(9-3B)2(9-3C)9-3E9-3C9-3L9-3E6-3K3Ab4-5A3EA2-6A3CA2-6A3BA-7A3AeA4(-11A)2-10A3-9A4-8A5-5A94-3D9-3C2(9-3B)2(9-3D)3(9-3E)2(9-3D)7-2K3E5-4F3AbA2-6A3EA2-6A3CA-7A3EA8O3EA8R3NA11R13A-10FA-11A2-10A3-9A4-7A7-4F58-3V9-3B9-3C2(9-3B)9-3C9-3E9-3J2(9-3L)9-3C9-3D9-3L6-3Z3E4-5A3CA2-6A3CA-7F3CA8X3C2(A7GW3E)A7GW3BA7MAd3AaA11ZA-6P4TA-11A2-10A3-9A5-7A44-3Aa9-3B9-3C4(9-3B)9-3C9-3E2(9-3L)9-3D9-3J7-KJ3Ab5-4S3L4-5A3LA2-6A3JA-7S3JAM6GW2(3CA7HAc)3BAH6GW3CAH6MAd3NA7MAd3AaA11UA-10FA2-10A3-9A4-8A44-3N9-3C5(9-3B)2(9-3C)3(9-3E)9-3J7-2K3E5-4S3L4-5A3CA2-5PT3CA-6MAg3CA7HAc3CA7IY3BAI6HAc3CA7HAc3BAH6GW3EA7GW3AfA7G4WA-11A2-10A3-9A4-8A32-3V9-3C9-3D9-3N9-3D9-3B9-3E9-3B9-3C9-3B9-3Ab9-3J9-3Ab9-3E7-2K3E5-2K2J3L4-5A3LA2-6A3BA-6GW3CA7HAc2(3CA7IY)3BA7IY2(3BA7HAc)3BA7GW3VA-10KA2-10A3-9A4-8A32-3N9-3C2(9-3D)9-3N9-3D2(9-3B)2(9-3D)9-3C9-3L9-3D2(9-3E)5-4K3C4-5F3BA2-6O3BA-6MAd3BA7HAc3BAH6IY3DA7IY3JA7IY3DAM6HAc3NA7GW3ZA7GW3NA-11A2-10A3-9A4-8A20-3V2(9-3C)5(9-3D)9-3N9-3B9-3C3(9-3J)2(9-3E)6-3K3D4-5K3BA2-6F3BA2-6X3BA-6GW3(3BA7HAc)3DA7HAc3DA7GW3DA-7Q3LA2-6F3VA3-9A4-7A6-5O22-3Af4(9-3C)9-3D3(9-3N)2(9-3B)9-3E2(9-3J)2(9-3E)9-3D5-3KJ3B4-3P2T3BA2-6O3BA2-6X3BA-7Q3BA-7U3DA-5M2Ad3DA-5G2W3NA-5M2Ag2(3BA2-6A)3AfA3-9A5-5F34-3B9-3C9-3B9-3D4(9-3B)9-3N2(9-3B)3(9-3C)9-3L9-3E9-3D7-2K3B5-K3Ah3B4-3P2T3BA2-6O3(3BA2-6K)3BA2-6R3BA2-6O3BA2-6A3BA3-5A3BA4-7F33-3Aa3(9-3D)2(9-3L)2(9-3B)9-3N3(9-3B)9-3L2(9-3J)2(9-3E)9-3D9-3B7-2K3B5-3KZ3B4-5A3(3BA3-5F)2(3BA3-5A)3BA4-4A3CA5-3A3C9-3Aa33-3V3(9-3D)9-3B9-3C6(9-3B)9-3C4(9-3J)9-3D3(9-3B)6-3K3B5-K3Z3B5-4A3B5-2P2T3C5-4F3C6-3O3E7-2F2(3C9-)3V33-3V3(9-3C)9-3B9-3C7(9-3B)4(9-3C)7(9-3B)9-3C9-3B3(9-3C)9-3V33-3V2(9-3C)9-3E2(9-3C)6(9-3B)9-3D4(9-3J)9-3C6(9-3B)9-3C9-3B3(9-3D)9-3V33-3Aa2(9-3C)9(9-3B)9-3D2(9-3E)2(9-3J)9-3L2(9-3B)6-3K3B5-3KD3N4-2K3Z3B4-5A3B4-3P2T3L4-5F3L4-5O3D6-3F3D7-2F3D9-3Aa45-11(3B9-)3D9-3E9-3L3(9-3C)9-K2B5-4K3B4-2K3Z3N4-5A3B3-4P2T3BA2-6F2(3BA2-6A)3DA2-6A3BA3-5F3C5-4R3B6-5F46-3Af2(9-3B)9-3N2(9-3D)5(9-3B)9-3D2(9-3E)2(9-3J)9-3E6-3K3B4-2K3J3B3-4P2T3NA2-6A3NA-7R3NA-7U3DA-7U3CA-7S3CA-5P2T3CA2-6A3CA3-5F3AfA4-7O6-5F34-3V9-3L3(9-3D)6(9-3B)9-3D2(9-3E)2(9-3J)7-2K3J5-2K2J3C3-4P2T3BA2-6S3NA-7Q2(3DA6G2W)3DA6M2Ad3DA6M2Ag3DA-7U3CA-5P2T3CA2-6A3VA3-9A4-2P5T7-4F34-3N9-3Z9-3N9-3D9-3J9-3D4(9-3B)9-3C2(9-3E)9-3D9-3L6-3K3C4-5O3DA2-6A3DA-7Q3BA6G2W3BA6H2Ac3DA6I2Y3NA6H2Ac3DA6G2W3DA6M2Ag3CA-7X3NA-11A2-10A3-8A6-6F33-3V4(9-3B)3(9-3C)9-3B2(9-3L)2(9-3E)9-3Ab7-2K3J5-2K2J3Ab4-5F3BA2-6R3CA-5G2W3BA6I2Y3EA6I2Y3BA6I2Y3DAM5I2Y3NA6H2Ac3DA6G2W3CA8Q3VA-5P5TA2-10A3-9A4-7FA44-3Af9-3E2(9-3B9-3C)3(9-3C)9-3L9-3E9-3J9-3E7-2K3E5-4R3E4-5F3CA2-6S3CA-5H2Ac3BAH5I4(2Y3BA6I)2Y3CA6G2W3NA6G5WA-11A2-10A3-9A4-8A44-3Aa9-3N9-3C9-3B2(9-3C)2(9-3J)2(9-3L)9-3Ab9-3J9-3D7-2K3L5-4K3L4-5F3EA2-6R3CA-5H2Ac3BAH5I3(2Y3BA6I)2Y3CA6H2Ac3BA6G2W3AaA6M5AgA-5P5TA2-10A3-9A4-8A56-3Aa9-3B2(9-3E)4(9-3C)9-3E9-3L9-3D9-3C9-3L5-4A3L4-5A3JA2-6O3EA-7Q3C2(AH5I2Y3B)A6I2Y3CA6H2Ac3BAH5M2Ad3VA6M5AgA11XA-11A2-10A3-9A4-8A80-3N2(9-3E)9-3C9-3E9-3Ab9-3E2(9-3D)2(9-3E)6-3R3E4-5A3DA2-6A3DA2-6K3BA-5M2Ad3BA6G2W3CA6M2Ad3DA6M5AdA6G5WA11QA-5P5TA2-10A3-9A4-8A5-5A-A92-3Ae9-3B9-3C9-3E9-3Ab9-3E9-3L9-3C9-3E2(9-3C)5-4A3BA3-5A3BA2-6A3EA2-6O3BA-7S3AeA-10UA-10QA-10SA-5P5TA2(2-10A)3-9A5-5A130-3Ae9-3N9-3B2(9-3C)2(9-3E)2(9-3J)7-2O3J5-4AD2KA3-5A3HA7(2-10A)3-9A4-8A248-J9-3A7-8A6(3-9A)4-8A5-7A293-5A-A4(4-8A)5-7A6-4A-A330-2(3A9-)3A75-
