model
size = 31 31 16, scale = 0.05, origin = -y
material 
  colors = A:#007 B:#FF3 C:#F90 D:#F93
voxels
----------AAAAAAAAAAA---------- ----------AAAAAAAAAAAA--------- --------AAAAAAAAAAAAAA--------- -------AAAAAAAAAAAAAAA--------- -------AAAAAAAAAAAAAAA--------- --------AAAAAAAAAAAAA---------- --------BBBBBBBBBBBBB---------- --------BAAAAAAAAAAAA---------- --------BAAAADACAAAAA---------- --------BAACCDDDDDAAA---------- --------BAADDAAACDCAAB--------- --------BAADCAAAACCAAB--------- -------ABAADCAAAADCAABA-------- -------ABAADDAAAACDAABA-------- ------AABAACDAAACCDAABA-------- ------AABAACDCCDCCAAABA-------- ------AABAADDDDCCAAAABA-------- ------AABAACDAACCCAAABA-------- ------AABAACCAAACDAAABA-------- ------AABAACDAAADDAAABA-------- ------AABAACCAACDCAAABA-------- -------ABAACCDCCCAAAABA-------- -------ABAAAADADAAAAAB--------- ---------AAAAAAAAAAAA---------- ------------------------------- ------------------------------- ------------------------------- ------------------------------- ------------------------------- ------------------------------- ------------------------------- 
--------AAAAAAAAAAAAAA--------- --------AAAAAAAAAAAAAAA-------- -------AAAAAAAAAAAAAAAA-------- -------AAAAAAAAAAAAAAAA-------- -------AAAAAAAAAAAAAAAA-------- -------AAAAAAAAAAAAAAAA-------- -------AAAAAAAAAAAAAAB--------- --------AAAAAAAAAAAAAB--------- --------AAAAAAAAAAAAAB--------- --------AAAAAAAAAAAAAB--------- -------AAAAAAAAAAAAAAAA-------- -------AAAAAADAAAAAAAAA-------- ------AAAAAAACAAAAAAAAA-------- ------AAAAAAADAAAAAAAAA-------- ------AAAAAAADAAAAAAAAA-------- ------AAAAAAAAAAAAAAAAA-------- ------AAAAAAAAAAAAAAAAAA------- ------AAAAAAADAAAAAAAAAA------- ------AAAAAAACAAAAAAAAAA------- ------AAAAAAACAAAAAAAAAA------- ------AAAAAAADAAAAAAAAAA------- ------AAAAAAAAAAAAAAAAAA------- -------AAAAAAAAAAAAAAAAA------- --------BAAAAAAAAAAAABA-------- ----------BBBBBBBBBBB---------- ------------------------------- ------------------------------- ------------------------------- ------------------------------- ------------------------------- ------------------------------- 
------AAAAAAAAAAAAAAAAA-------- -------AAAAAAAAAAAAAAAAA------- -------AAAAAAAAAAAAAAAAA------- -------AAAAAAAAAAAAAAAAA------- -------AAAAAAAAAAAAAAAAA------- -------AAAAAAAAAAAAAAAAA------- -------AAAAAAAAAAAAAAAAA------- -------AAAAAAAAAAAAAAAA-------- -------AAAAAAAAAAAAAAAA-------- -------AAAAAAAAAAAAAAAA-------- -------AAAAAAAAAAAAAAAA-------- -------AAAAAAAAAAAAAAAAA------- ------AAAAAAAAAAAAAAAAA-------- ------AAAAAAAAAAAAAAAAAA------- ------AAAAAAAAAAAAAAAAAA------- ------AAAAAAAAAAAAAAAAAA------- ------AAAAAAAAAAAAAAAAAA------- ------AAAAAAAAAAAAAAAAAAA------ ------AAAAAAAAAAAAAAAAAA------- ------AAAAAAAAAAAAAAAAAAA------ ------AAAAAAAAAAAAAAAAAAA------ ------AAAAAAAAAAAAAAAAAAA------ -----AAAAAAAAAAAAAAAAAAAA------ -----A-AAAAAAAAAAAAAAAAA------- ------AABBAAAAAAAAAAABAA------- -------AAAAAAAAAAAAAAA--------- --------AAAAAAAAAAAAA---------- ------------------------------- ------------------------------- ------------------------------- ------------------------------- 
------AAAAAAAAAAAAAAAAAAA------ ------AAAAAAAAAAAAAAAAAAA------ ------AAAAAAAAAAAAAAAAAAA------ ------AAAAAAAAAAAAAAAAAAA------ ------AAAAAAAAAAAAAAAAAAA------ ------AAAAAAAAAAAAAAAAAAA------ -------AAAAAAAAAAAAAAAAA------- -------AAAAAAAAAAAAAAAAA------- -------AAAAAAAAAAAAAAAAA------- -------AAAAAAAAAAAAAAAAA------- -------AAAAAAAA--AAAAAAA------- ------AAAAAAAAA--AAAAAAA------- ------AAAAAAAAA--AAAAAAA------- ------AAAAAAAAA--AAAAAAA------- ------AAAAAAAAA--AAAAAAA------- ------AAAAAAAAA--AAAAAAAA------ ------AAAAAAA----AAAAAAAA------ ------AAAAAAA----AAAAAAAA------ ------AAAAAAA----AAAAAAAA------ -----AAAAAAAAAAAAAAAAAAAAA----- -----AAAAAAAAAAAAAAAAAAAAA----- ------AAAAAAAAAAAAAAAAAAAA----- -----AAAAAAAAAAAAAAAAAAAAA----- -----AAAAAAAAAAAAAAAAAAAAA----- ------AAAAAAAAAAAAAAAAAAA------ -------AAAAAAAAAAAAAAAAA------- --------AAAAAAAAAAAAAAA-------- ----------AAAAAAAAAAA---------- ------------------------------- ------------------------------- ------------------------------- 
-----AAAAAAAA----AAAAAAAAA----- ------AAAAAAA----AAAAAAAA------ ------AAAAAAA----AAAAAAAA------ ------AAAAAAA----AAAAAAAA------ ------AAAAAAA----AAAAAAAA------ ------AAAAAAA----AAAAAAAA------ ------AAAAAAA----AAAAAAAA------ ------AAAAAAA----AAAAAAAA------ ------AAAAAAA----AAAAAAAA------ ------AAAAAAA----AAAAAAAA------ ------AAAAAA------AAAAAAA------ ------AAAAAA------AAAAAA------- ------AAAAAA-------AAAAAA------ ------AAAAAA------AAAAAAA------ ------AAAAAA------AAAAAAA------ ------AAAAAA------AAAAAAA------ ------AAAAAA------AAAAAAA------ ------AAAAAA------AAAAAAA------ -----AAAAAA--------AAAAAAA----- ----AAAAAAA--------AAAAAAAA---- ----AAAAAAAA------AAAAAAAAA---- ----AAAAAAAAAAAAAAAAAAAAAAA---- ----AAAAAAAAAAAAAAAAAAAAAAA---- -----AAAAAAAAAAAAAAAAAAAAA----- -----AAAAAAAAAAAAAAAAAAAAA----- -----AAAAAAAAAAAAAAAAAAAAA----- -----AAAAAAAAAAAAAAAAAAAAA----- -------AAAAAAAAAAAAAAAAA------- ----------AAAAAAAAAAA---------- ------------------------------- ------------------------------- 
-----AAAAAA--------A-AAAAA----- -----AAAAAA--------A-AAAAA----- -----AAAAAA--------A-AAAAA----- -----AAAAAA--------A-AAAAA----- -----AAAAAA--------A-AAAAA----- -----AAAAAA--------AAAAAAA----- ------AAAAA-------AAAAAAA------ ------AAAAA-------AAAAAAA------ ------AAAAA-------AAAAAAA------ ------AAAAA-------AAAAAAA------ ------AAAAA--------AAAAAA------ ------AAAAA--------AAAAAA------ ------AAAAA--------AAAAAA------ ------AAAAA--------AAAAAA------ -----AAAAAA--------AAAAAAA----- -----AAAAAA--------AAAAAAA----- -----AAAAAA--------AAAAAAA----- ----AAAAAAA--------AAAAAAAA---- ---AAAAAAAA---------AAAAAAAA--- ---AAAAAAA----------AAAAAAAAA-- --AAAAAAAA----------AAAAAAAAA-- --AAAAAAAAA--------AAAAAAAAAA-- --AAAAAAAAAAA----AAAAAAAAAAAA-- --AAAAAAAAAAAAAAAAAAAAAAAAAAA-- --AAAAAAAAAAAAAAAAAAAAAAAAAAA-- --AAAAAAAAAAAAAAAAAAAAAAAAAAA-- ---AAAAAAAAAAAAAAAAAAAAAAAAA--- ----AAAAAAAAAAAAAAAAAAAAAAA---- --------AAAAAAAAAAAAAAA-------- --------------------A---------- ------------------------------- 
-----AAAAA----------AAAAAA----- -----AAAAA----------AAAAAA----- -----AAAAA----------AAAAAA----- -----AAAAA----------AAAAAA----- -----AAAAA----------AAAAAA----- -----AAAAA----------AAAAAA----- -----AAAAA---------AAAAAAA----- -----AAAAA---------AAAAAAA----- ------AAAA---------AAAAAA------ ------AAAAA--------AAAAAA------ ------AAAAA--------AAAAAA------ ------AAAAA---------AAAAA------ ------AAAAA---------AAAAA------ -----AAAAAA---------AAAAAA----- -----AAAAA----------AAAAAA----- -----AAAAA----------AAAAAA----- -----AAAAA----------AAAAAA----- ----AAAAAA----------AAAAAAA---- ---AAAAAAA----------AAAAAAAA--- --AAAAAAAA----------AAAAAAAAAA- -AAAAAAAA-----------AAAAAAAAAAA -AAAAAAAAA----------AAAAAAAAAA- -AAAAAAAAA----------AAAAAAAAAA- -AAAAAAAAAAA------AAAAAAAAAAAA- -AAAAAAAAAAAAA--AAAAAAAAAAAAAA- --AAAAAAAAAAAAAAAAAAAAAAAAAAA-- --AAAAAAAAAAAAAAAAAAAAAAAAAAA-- ---AAAAAAAAAAAAAAAAAAAAAAAAA--- -----AAAAAAAAAAAAAAAAAAAAA----- ---------A----------AA--------- ------------------------------- 
-----AAAA-------------AAAA----- -----AAAA-------------AAAA----- -----AAAA-------------AAAA----- -----AAAAA-----------AAAAA----- -----AAAAA----------AAAAAA----- -----AAAAA----------AAAAAA----- -----AAAAA----------AAAAAA----- -----AAAAA----------AAAAAA----- -----AAAAA----------AAAAAA----- ------AAAA----------AAAAA------ ------AAAA----------AAAAA------ ------AAAA----------AAAAA------ ------AAAA----------AAAAA------ -----AAAAA----------AAAAAA----- -----AAAAA----------AAAAAA----- -----AAAAA----------AAAAAA----- -----AAAAA----------AAAAAA----- ----AAAAAA----------AAAAAAAA--- ---AAAAAA-------------AAAAAAA-- -AAAAAAAA-----------AAAAAAAAAAA -AAAAAAAA-----------AAAAAAAAAAA -AAAAAAAA-----------AAAAAAAAAAA -AAAAAAAA-----------AAAAAAAAAA- -AAAAAAAAA----------AAAAAAAAAA- -AAAAAAAAAAA------AAAAAAAAAAAA- --AAAAAAAAAAAAAAAAAAAAAAAAAAA-- --AAAAAAAAAAAAAAAAAAAAAAAAAAA-- ---AAAAAAAAAAAAAAAAAAAAAAAAA--- ----AAAAAAAAA----AAAAAAAAAA---- -------AAA----------AAAA------- ---------A----------AA--------- 
-----AAAAA-----------AAAAA----- -----AAAAA----------AAAAAA----- -----AAAAA----------AAAAAA----- -----AAAAA----------AAAAAA----- -----AAAAA----------AAAAAA----- -----AAAAA----------AAAAAA----- -----AAAAA----------AAAAAA----- -----AAAAA----------AAAAAA----- -----AAAAA----------AAAAAA----- ------AAAA----------AAAAA------ ------AAAA----------AAAAA------ ------AAAA----------AAAAA------ ------AAAA----------AAAAA------ -----AAAAA----------AAAAAA----- -----AAAAA----------AAAAAA----- -----AAAAA----------AAAAAA----- -----AAAA-------------AAAA----- ----AAAAA-------------AAAAAA--- -AAAAAAAA-------------AAAAAAA-- -AAAAAAAA-------------AAAAAAAAA -AAAAAAAA-------------AAAAAAAAA -AAAAA--------------AA---AAAAAA -AAAAA--------------AA---AAAAA- -AAAAAA-----------------AAAAAA- -AAAAAAAA-------------AAAAAAAA- --AAAAAAAAAAA-----AAAAAAAAAAA-- --AAAAAAAAAAAA--AAAAAAAAAAAAA-- ---AAAAAAAAAAA--AAAAAAAAAAAA--- ----AAAAAAAAA----AAAAAAAAAA---- ------AAAA----------AAAAA------ ---------A----------AA--------- 
-----AAAAA----------AAAAAA----- -----AAAAAA---------AAAAAA----- -----AAAAAA--------AAAAAAA----- -----AAAAAA--------AAAAAAA----- -----AAAAAA--------AAAAAAA----- -----AAAAAA--------AAAAAAA----- -----AAAAAA--------AAAAAAA----- -----AAAAAA--------AAAAAAA----- -----AAAAAA--------AAAAAAA----- ------AAAA---------AAAAAA------ ------AAAA---------AAAAAA------ ------AAAA----------AAAAA------ ------AAAA----------AAAAA------ -----AAAAA----------AAAAAA----- -----AAAAA----------AAAAAA----- -----AAAA-------------AAAA----- -----AAAA-------------AAAA----- ---A-AAAA-------------AAAA-A--- -AAAAAAAA-------------AAAAAAA-- -AAAAAAAA-------------AAAAAAAAA AAAAAAAAA-------------AAAAAAAAA -AAAA---------------AA----AAAAA -AAAA---------------AA----AAAA- -AAAAA-------------------AAAAA- -AAAAAA-----------------AAAAAA- --AAAAAAA-------------AAAAAAA-- --AAAAAAAAAAA----AAAAAAAAAAAA-- ---AAAAAAAAAAA--AAAAAAAAAAAA--- ----AAAAAAAAA----AAAAAAAAAA---- ------AAAA----------AAAAA------ ---------A----------AA--------- 
-----AAAAAAA-------AAAAAAA----- -----AAAAAAAA-----AAAAAAAA----- ------AAAAAAA--AAAAAAAAAA------ -----AAAAAAAA--AAAAAAAAAAA----- -----AAAAAAAA--AAAAAAAAAAA----- -----AAAAAAA---AAAAAAAAAAA----- -----AAAAAAA----AAAAAAAAAA----- -----AAAAAAA------AAAAAAAA----- -----AAAAAAA------AAAAAAAA----- ------AAAAAA------AAAAAAA------ ------AAAAA-------AAAAAAA------ ------AAAA---------AAAAAA------ ------AAAA----------AAAAA------ -----AAAAA----------AAAAAA----- -----AAAAA----------AAAAAA----- -----AAAAA----------AAAAAA----- -----AAAAA----------AAAAAA----- ---AAAAAA-------------AAAAAA--- -AAAAAAAA-------------AAAAAAA-- AAAAAAAAA-------------AAAAAAAA- AAAAAAAAA-------------AAAAAAAAA AAAAAAAA---------------AAAAAAAA -AAAAA-------------------AAAAA- -AAAAAA-----------------AAAAAA- -AAAAAAAA-------------AAAAAAAA- --AAAAAAAAAA------AAAAAAAAAAA-- --AAAAAAAAAAAAAAAAAAAAAAAAAAA-- ---AAAAAAAAAAAAAAAAAAAAAAAAA--- ----AAAAAAAAAAAAAAAAAAAAAAA---- ------AAAAA--------AAAAAA------ ---------A----------AA--------- 
------AAAAAAAAAAAAAAAAAAA------ ------AAAAAAAAAAAAAAAAAAA------ ------AAAAAAAAAAAAAAAAAAA------ ------AAAAAAAAAAAAAAAAAAA------ ------AAAAAAAAAAAAAAAAAAA------ ------AAAAAAAAAAAAAAAAAAA------ ------AAAAAAAAAAAAAAAAAAA------ ------AAAAAAA---AAAAAAAAA------ ------AAAAAAA-----AAAAAAA------ ------AAAAAAA-----AAAAAAA------ ------AAAAAAA-----AAAAAAA------ ------AAAAAAA-----AAAAAAA------ ------AAAAAAA-----AAAAAAA------ -----AAAAAA--------AAAAAAA----- -----AAAAA---------AAAAAAA----- -----AAAAA----------AAAAAA----- -----AAAAA----------AAAAAA----- --AAAAAAAA----------AAAAAAAAA-- AAAAAAAAAA----------AAAAAAAAAA- AAAAAAAAAA-----------AAAAAAAAAA AAAAAAAAA------------AAAAAAAAAA -AAAAAAAA------------AAAAAAAAA- -AAAAAAA-------------A-AAAAAAA- -AAAAAAAAA----------AAAAAAAAAA- -AAAAAAAAAAAAAAAAAAAAAAAAAAAAA- --AAAAAAAAAAAAAAAAAAAAAAAAAAA-- --AAAAAAAAAAAAAAAAAAAAAAAAAAA-- ---AAAAAAAAAAAAAAAAAAAAAAAAA--- ----AAAAAAAAAAAAAAAAAAAAAAA---- -------AAAAAAAAAAAAAAAAA------- ---------AA--------AAA--------- 
------AAAAAAAAAAAAAAAAAAA------ ------AAAAAAAAAAAAAAAAAAA------ -------AAAAAAAAAAAAAAAAA------- ------AAAAAAAAAAAAAAAAAAA------ ------AAAAAAAAAAAAAAAAAAA------ ------AAAAAAAAAAAAAAAAAAA------ ------AAAAAAAAAAAAAAAAAAA------ ------AAAAAAAAAAAAAAAAAAA------ ------AAAAAAAAAAAAAAAAAAA------ ------AAAAAAAAAAAAAAAAAAA------ ------AAAAAAAA---AAAAAAAA------ ------AAAAAAAA---AAAAAAAA------ ------AAAAAAAA---AAAAAAAA------ -----AAAAAAAAA---AAAAAAAAA----- -----AAAAAAAAA----AAAAAAAA----- -----AAAAAAAAA----AAAAAAAA----- -----AAAAAAAAA----AAAAAAAA----- -AAAAAAAAAAAA------AAAAAAAAAA-- -AAAAAAAAAA--------AAAAAAAAAAA- -AAAAAAAAAA--------AAAAAAAAAAA- -AAAAAAAAA----------AAAAAAAAAA- -AAAAAAAAA---AAAA---AAAAAAAAAA- -AAAAAAAAAAAAAAAAAAAAAAAAAAAAA- -AAAAAAAAAAAAAAAAAAAAAAAAAAAAA- --AAAAAAAAAAAAAAAAAAAAAAAAAAA-- --AAAAAAAAAAAAAAAAAAAAAAAAAAA-- --AAAAAAAAAAAAAAAAAAAAAAAAAAA-- ---AAAAAAAAAAAAAAAAAAAAAAAAA--- -----AAAAAAAAAAAAAAAAAAAAA----- --------AAAAAAAAAAAAAAA-------- ----------AAAAAAAAAA----------- 
-------AAAAAAAAAAAAAAAAA------- -------AAAAAAAAAAAAAAAAA------- --------AAAAAAAAAAAAAAA-------- -------AAAAAAAAAAAAAAAAA------- -------AAAAAAAAAAAAAAAAA------- -------AAAAAAAAAAAAAAAAA------- -------AAAAAAAAAAAAAAAAA------- -------AAAAAAAAAAAAAAAAA------- ------AAAAAAAAAAAAAAAAAAA------ ------AAAAAAAAAAAAAAAAAAA------ ------AAAAAAAAAAAAAAAAAAA------ ------AAAAAAAAAAAAAAAAAAA------ ------AAAAAAAAAAAAAAAAAAA------ ------AAAAAAAAAAAAAAAAAAA------ -----AAAAAAAAAAAAAAAAAAAAA----- -----AAAAAAAAAAAAAAAAAAAAA----- -----AAAAAAAAAAAAAAAAAAAAA----- --A--AAAAAAAAAAAAAAAAAAAAA--A-- --AAAAAAAAAAAAAAAAAAAAAAAAAAA-- --AAAAAAAAAAAAAAAAAAAAAAAAAAA-- --AAAAAAAAAAAAAAAAAAAAAAAAAAA-- --AAAAAAAAAAAAAAAAAAAAAAAAAAA-- --AAAAAAAAAAAAAAAAAAAAAAAAAAA-- --AAAAAAAAAAAAAAAAAAAAAAAAAAA-- --AAAAAAAAAAAAAAAAAAAAAAAAAAA-- ---AAAAAAAAAAAAAAAAAAAAAAAAA--- ----AAAAAAAAAAAAAAAAAAAAAAA---- -----AAAAAAAAAAAAAAAAAAAAA----- -------AAAAAAAAAAAAAAAAA------- -----------AAAAAAAA------------ ------------------------------- 
---------AAAAAAAAAAAAAAA------- ---------AAAAAAAAAAAAAAA------- ---------AAAAAAAAAAAAAA-------- --------AAAAAAAAAAAAAAAA------- --------AAAAAAAAAAAAAAAA------- ---------AAAAAAAAAAAAAAA------- ---------AAAAAAAAAAAAAAA------- ---------AAAAAAAAAAAAAAA------- ---------AAAAAAAAAAAAAAAA------ -------AAAAAAAAAAAAAAAAAA------ -------AAAAAAAAAAAAAAAAAA------ -------AAAAAAAAAAAAAAAAAA------ -------AAAAAAAAAAAAAAAAAA------ -------AAAAAAAAAAAAAAAAAA------ -------AAAAAAAAAAAAAAAAAAA----- ------AAAAAAAAAAAAAAAAAAAA----- ------AAAAAAAAAAAAAAAAAAAA----- ------AAAAAAAAAAAAAAAAAAAA----- -----AAAAAAAAAAAAAAAAAAAAA----- ---AAAAAAAAAAAAAAAAAAAAAAAAA--- ---AAAAAAAAAAAAAAAAAAAAAAAAA--- ---AAAAAAAAAAAAAAAAAAAAAAAAA--- ---AAAAAAAAAAAAAAAAAAAAAAAAA--- ---AAAAAAAAAAAAAAAAAAAAAAAAA--- ----AAAAAAAAAAAAAAAAAAAAAAA---- ----AAAAAAAAAAAAAAAAAAAAAAA---- -----AAAAAAAAAAAAAAAA-AAAA----- ---------AAAAAAAAAAAA---------- ------------------------------- ------------------------------- ------------------------------- 
-------------AAAAAAAAA--------- ---------AAAAAAAAAAAA---------- ---------AAAAAAAAAAA----------- ----------A-----AAAAA---------- --------------------AA--------- -----------AAAAAAA------------- ----------AAAAAAAAAA-A--------- ----------AAAAAAAAAAAA--------- ----------AAAAAAAAAAAA--------- ----------AAAAAAAAAAAA--------- ---------AAAAAAAAAAAAA--------- --------AAAAAAAAAAAAAA--------- ---------AAAAAAAAAAAAA--------- --------AAAAAAAAAAAAAAA-------- --------AAAAAAAAAAAAAAA-------- -------AAAAAAAAAAAAAAAAA------- -------AAAAAAAAAAAAAAAAA------- -------AAAAAAAAAAAAAAAAA------- ------AAAAAAAAAAAAAAAAAAA------ ------AAAAAAAAAAAAAAAAAAA------ ------AAAAAAAAAAAAAAAAAAA------ ------AAAAAAAAAAAAAAAAAAA------ ------AAAAAAAAAAAAAAAAAAA------ ------AAAAAAAAAAAAAAAAAAA------ ------AAAAAAAAAAAAAAAAAAA------ -------AAAAAAAAAAAAAAAAA------- ------------------------------- ------------------------------- ------------------------------- ------------------------------- ------------------------------- 
