model
size = 24 4 19, scale = 0.05, origin = -y
material 
  colors = A:#222 B:#111 C:#AAA
voxels
------------------------ ------------------------ -----------------------A -----------------------A 
------------------------ ------------------------ A----------------------- A----------------------A 
------------------------ ------------------------ ------------------------ A----------------------A 
------------------------ ------------------------ ------------------------ A----------------------A 
------------------------ ------------------------ ------------------------ A----------------------A 
------------------------ ------------------------ ------------------------ A----------------------A 
------------------------ ------------------------ ------------------------ A----------------------A 
------------------------ ------------------------ ------------------------ A----------------------A 
------------------------ ------------------------ ------------------------ A----------------------A 
------------------------ ------------------------ ------------------------ A----------------------A 
------------------------ ------------------------ ------------------------ A----------------------A 
------------------------ ------------------------ ------------------------ A----------------------A 
------------------------ ------------------------ ------------------------ A----------------------A 
------------------------ ------------------------ ------------------------ A----------------------A 
------------------------ ------------------------ ------------------------ A----------------------A 
------------------------ ------------------------ ------------------------ A----------------------A 
------------------------ ------------------------ ------------------------ A----------------------A 
------------------------ ------------------------ ------------------------ A----------------------A 
ABBCBCBBBBB--BBBCBCBBBBA ABCBCBBBBBB--BBCBCBBBBBA ABBBBBBBBBB--BBBBBBBBBBA AAAAAAAAAAAAAAAAAAAAAAAA 
