model
size = 24 7 19, scale = 0.05, origin = -y
material 
  colors = A:#111 B:#069 C:#036 D:#AAA
voxels
------------------------ ------------------------ -----------------------C -----------------------C ------------------------ ------------------------ ------------------------ 
------------------------ ------------------------ C----------------------- C----------------------C ------------------------ ------------------------ ------------------------ 
------------------------ ------------------------ ------------------------ C----------------------C ------------------------ ------------------------ ------------------------ 
------------------------ ------------------------ ------------------------ C----------------------C ------------------------ ------------------------ ------------------------ 
------------------------ ------------------------ ------------------------ C----------------------C ------------------------ ------------------------ ------------------------ 
------------------------ ------------------------ ------------------------ C----------------------C ------------------------ ------------------------ ------------------------ 
------------------------ ------------------------ ------------------------ C----------------------C ------------------------ ------------------------ ------------------------ 
------------------------ ------------------------ ------------------------ C----------------------C ------------------------ ------------------------ ------------------------ 
------------------------ ------------------------ ------------------------ C----------------------C ------------------------ ------------------------ ------------------------ 
------------------------ ------------------------ ------------------------ C----------------------C ------------------------ ------------------------ ------------------------ 
------------------------ ------------------------ ------------------------ C----------------------C ------------------------ ------------------------ ------------------------ 
------------------------ ------------------------ ------------------------ C----------------------C ------------------------ ------------------------ ------------------------ 
------------------------ ------------------------ ------------------------ C----------------------C ------------------------ ------------------------ ------------------------ 
------------------------ ------------------------ ------------------------ C----------------------C ------------------------ ------------------------ ------------------------ 
------------------------ ------------------------ ------------------------ C----------------------C ------------------------ ------------------------ ------------------------ 
------------------------ ------------------------ ------------------------ C----------------------C ------------------------ ------------------------ ------------------------ 
------------------------ ------------------------ ------------------------ C----------------------C ------------------------ ------------------------ ------------------------ 
------------------------ ------------------------ ------------------------ C----------------------C ------------------------ ------------------------ ------------------------ 
CBBDBDBBBBA--ABBDBDBBBBC CBDBDBBBBBA--ABDBDBBBBBC CBBBBBBBBBA--ABBBBBBBBBC CAAAAAAAAAAAAAAAAAAAAAAC AAAAA-----AAAA-----AAAAA AAA--------AA--------AAA AA--------------------AA 
