model
size = 24 7 19, scale = 0.05, origin = -y
material 
  colors = A:#111 B:#400 C:#700
voxels
------------------------ ------------------------ -----------------------A -----------------------A ------------------------ ------------------------ ------------------------ 
------------------------ ------------------------ A----------------------- A----------------------A ------------------------ ------------------------ ------------------------ 
------------------------ ------------------------ ------------------------ A----------------------A ------------------------ ------------------------ ------------------------ 
------------------------ ------------------------ ------------------------ A----------------------A ------------------------ ------------------------ ------------------------ 
------------------------ ------------------------ ------------------------ A----------------------A ------------------------ ------------------------ ------------------------ 
------------------------ ------------------------ ------------------------ A----------------------A ------------------------ ------------------------ ------------------------ 
------------------------ ------------------------ ------------------------ A----------------------A ------------------------ ------------------------ ------------------------ 
------------------------ ------------------------ ------------------------ A----------------------A ------------------------ ------------------------ ------------------------ 
------------------------ ------------------------ ------------------------ A----------------------A ------------------------ ------------------------ ------------------------ 
------------------------ ------------------------ ------------------------ A----------------------A ------------------------ ------------------------ ------------------------ 
------------------------ ------------------------ ------------------------ A----------------------A ------------------------ ------------------------ ------------------------ 
------------------------ ------------------------ ------------------------ A----------------------A ------------------------ ------------------------ ------------------------ 
------------------------ ------------------------ ------------------------ A----------------------A ------------------------ ------------------------ ------------------------ 
------------------------ ------------------------ ------------------------ A----------------------A ------------------------ ------------------------ ------------------------ 
------------------------ ------------------------ ------------------------ A----------------------A ------------------------ ------------------------ ------------------------ 
------------------------ ------------------------ ------------------------ A----------------------A ------------------------ ------------------------ ------------------------ 
------------------------ ------------------------ ------------------------ A----------------------A ------------------------ ------------------------ ------------------------ 
------------------------ ------------------------ ------------------------ A----------------------A ------------------------ ------------------------ ------------------------ 
ABBCBCBBBBA--ABBCBCBBBBA ABCBCBBBBBA--ABCBCBBBBBA ABBBBBBBBBA--ABBBBBBBBBA AAAAAAAAAAAAAAAAAAAAAAAA AAAAA-----AAAA-----AAAAA AAA--------AA--------AAA AA--------------------AA 
