model
size = 29 7 7, scale = 0.05, origin = -y
material 
  colors = A:#EEE B:#D9D9D9 C:#382400 D:#717171 E:#C9C9C9 F:#555 G:#800 H:#700 I:#9CF J:#3D2814 K:#A00
voxels
----------------------------- ----------------------------- ----------------------------- -------------------------BABA ----------------------------- ----------------------------- ----------------------------- 
----------------------------- ----------------------------- ----------------------------- ----F------------------ABEAE- ----------------------------- ----------------------------- ----------------------------- 
----------------------------- ----------------------------- ----------------------------- --HDD-----------------AAAEA-- ----------------------------- ----------------------------- ----------------------------- 
-K-----------------------ABEA -K-FD------------------BBBBE- -GGDF-----------------BAABA-- HGIIDJCCCCCCCCCCCCCCCJICCCCJ- -HHFD-----------------ABBEA-- ---DF------------------AABBA- -------------------------ABAE 
----------------------------- ----------------------------- ----------------------------- --GFD-----------------BAABA-- ----------------------------- ----------------------------- ----------------------------- 
----------------------------- ----------------------------- ----------------------------- ----D------------------EBAAA- ----------------------------- ----------------------------- ----------------------------- 
----------------------------- ----------------------------- ----------------------------- -------------------------ABBA ----------------------------- ----------------------------- ----------------------------- 
