model
size = 29 7 7, scale = 0.05, origin = -y
material 
  colors = A:#EEE B:#D9D9D9 C:#382400 D:#717171 E:#555 F:#C9C9C9 G:#3D2814 H:#9CF
voxels
----------------------------- ----------------------------- ----------------------------- -------------------------BABA ----------------------------- ----------------------------- ----------------------------- 
----------------------------- ----------------------------- ----------------------------- ----E------------------ABFAF- ----------------------------- ----------------------------- ----------------------------- 
----------------------------- ----------------------------- ----------------------------- --DDD-----------------AAAFA-- ----------------------------- ----------------------------- ----------------------------- 
-------------------------ABFA ---ED------------------BBBBF- -EDDE-----------------BAABA-- DDHHDGCCCCCCCCCCCCCCCGHCCCCG- -EDED-----------------ABBFA-- ---DE------------------AABBA- -------------------------ABAF 
----------------------------- ----------------------------- ----------------------------- --DED-----------------BAABA-- ----------------------------- ----------------------------- ----------------------------- 
----------------------------- ----------------------------- ----------------------------- ----D------------------FBAAA- ----------------------------- ----------------------------- ----------------------------- 
----------------------------- ----------------------------- ----------------------------- -------------------------ABBA ----------------------------- ----------------------------- ----------------------------- 
