model
size = 15 20 18, scale = 0.05, origin = -y
material 
  colors = A:#E00 B:#111 C:#C90 D:#CC0
voxels
--------------- --------------- --------------- --------------- --------------- --------------- --------------- -------A------- ------AAA------ ------AAA------ --------------- --------------- --------------- --------------- --------------- --------------- --------------- --------------- --------------- --------------- 
--------------- --------------- --------------- --------------- --------------- --------------- --------------- -------A------- -----AAAAA----- -----AAAAA----- ------AAA------ --------------- --------------- --------------- --------------- --------------- --------------- --------------- --------------- --------------- 
--------------- --------------- --------------- --------------- --------------- --------------- --------------- -------A------- -----AAAAA----- -----AAAAA----- -----AAAAA----- ------AAA------ --------------- --------------- --------------- --------------- --------------- --------------- --------------- --------------- 
--------------- --------------- --------------- --------------- --------------- --------------- --------------- -------A------- -----AAAAA----- -----AAAAA----- ------AAA------ --------------- --------------- --------------- --------------- --------------- --------------- --------------- --------------- --------------- 
--------------- --------------- --------------- --------------- --------------- --------------- --------------- -------A------- ------AAA------ ------AAA------ -------A------- --------------- --------------- --------------- --------------- --------------- --------------- --------------- --------------- --------------- 
--------------- --------------- --------------- --------------- --------------- --------------- --------------- -------A------- ------AAA------ ------AAA------ -------A------- --------------- --------------- --------------- --------------- --------------- --------------- --------------- --------------- --------------- 
--------------- --------------- --------------- --------------- --------------- --------------- --------------- -------A------- ------AAA------ ------AAA------ -------A------- --------------- --------------- --------------- --------------- --------------- --------------- --------------- --------------- --------------- 
--------------- --------------- --------------- --------------- --------------- --------------- --------------- -------A------- ------AAA------ ------AAA------ -------A------- --------------- --------------- --------------- --------------- --------------- --------------- --------------- --------------- --------------- 
--------------- --------------- --------------- --------------- --------------- --------------- --------------- -------A------- ------AAA------ ------AAA------ -------A------- --------------- --------------- --------------- --------------- --------------- --------------- --------------- --------------- --------------- 
--------------- --------------- --------------- --------------- --------------- --------------- --------------- -------A------- ------AAA------ ------AAA------ -------A------- --------------- --------------- --------------- --------------- --------------- --------------- --------------- --------------- --------------- 
--------------- --------------- --------------- --------------- --------------- --------------- --------------- -------A------- ------AAA------ ------AAA------ -------A------- --------------- --------------- --------------- --------------- --------------- --------------- --------------- --------------- --------------- 
--------------- --------------- --------------- --------------- --------------- --------------- --------------- -------A------- ------AAA------ ------AAA------ -------A------- --------------- --------------- --------------- --------------- --------------- --------------- --------------- --------------- --------------- 
--------------- --------------- --------------- --------------- --------------- --------------- --------------- -------A------- -----AAAAA----- -----AAAAA----- -------A------- --------------- --------------- --------------- --------------- --------------- --------------- --------------- --------------- --------------- 
--------------- --------------- --------------- --------------- ----AAA-AAA---- ---A-------A--- ----AAAAAAA---- ----BBB-BBB---- -----AAAAA----- -----AAAAA----- ------AAA------ ---CCC---CCC--- ---C-C---C-C--- ---CCC---CCC--- ------B-B------ -----B---B----- ----B-----B---- ---B-------B--- --------------- --------------- 
--------------- -----BB-BB----- ---AABB-BBAA--- --AAAAA-AAAAA-- --AAAAAAAAAAA-- -AAA-CDCDC-AAA- -AAAAAAAAAAAAA- -AABBBBABBBBAA- -AABAAAAAAABAA- -AAAAAAAAAAAAA- -A-AAAAAAAAA-A- -AACCCAAACCCAA- ---C-CAAAC-C--- -AACCCAAACCCAA- -A-AABAAABAA-A- --AABAB-BABAA-- --ABAB-A-BABA-- ---AAAA-AAAA--- -----A-A-A----- --------------- 
--------------- -----AAAAA----- ---AAAAAAAAA--- --AAAAAAAAAAA-- --AAAAAAAAAAA-- -AAA-AAAAA-AAA- -AAAAAAAAAAAAA- -AAAAAAAAAAAAA- -AAAAAAAAAAAAA- -AAAAAAAAAAAAA- -AAAAAAAAAAAAA- -AAAAAAAAAAAAA- -AAA-AAAAA-AAA- -AAAAAAAAAAAAA- -AAAAAAAAAAAAA- --AAAAAAAAAAA-- --AAAAAAAAAAA-- ---AAAAAAAAA--- -----AAAAA----- --------------- 
-----AAAAA----- ---AAAAAAAAA--- --AAAA---AAAA-- -AAA-------AAA- -AA---------AA- AAA---------AAA AAA---------AAA AAA---------AAA AAA---------AAA AAA---------AAA AAA---------AAA AAA---------AAA AAA---------AAA AAA---------AAA AAA---------AAA -AA---------AA- -AAA-------AAA- --AAAA---AAAA-- ---AAAAAAAAA--- -----AAAAA----- 
-----AAAAA----- ---AAA---AAA--- --AA-------AA-- -AA---------AA- -A-----------A- AA-----------AA AA-----------AA AA-----------AA AA-----------AA AA-----------AA AA-----------AA AA-----------AA AA-----------AA AA-----------AA AA-----------AA -A-----------A- -AA---------AA- --AA-------AA-- ---AAA---AAA--- -----AAAAA----- 
