model
size = 23 12 23, scale = 0.05, origin = -y
material 
  colors = A:#30F B:#DDD C:#E00
voxels
--------BBBBBBB-------- --------CCBBBBB-------- ----------------------- ----------------------- ----------------------- ----------------------- ----------------------- ----------------------- ----------------------- ----------------------- ----------------------- ----------------------- 
------ABAAAAAAABA------ ------ABCCAAAAABA------ --------CCCCCBB-------- --------CCCCCBB-------- ----------------------- ----------------------- ----------------------- ----------------------- ----------------------- ----------------------- ----------------------- ----------------------- 
----AAABAAAAAAABAAA---- ----AAABCCAAAAABAAA---- ------ABCCAAAAABA------ ------ABCCAAAAABA------ --------CCBBBBB-------- --------CCBCBCB-------- ----------------------- ----------------------- ----------------------- ----------------------- ----------------------- ----------------------- 
---AAAABAAAAAAABAAAA--- ---AAAABAAAAAAABAAAA--- -----AABAAAAAAABAA----- -----AABAAAAAAABAA----- ------ABAAAAAAABA------ ------ABBAAAAABBA------ ---------BBCBC--------- ---------BBBBB--------- ----------------------- ----------------------- ----------------------- ----------------------- 
--AAAAAAAAAAAAAAAAAAA-- --AAAAAAAAAAAAAAAAAAA-- ----AAAAAAAAAAAAAAA---- ----AAAAAAAAAAAAAAA---- -----AAAAAAAAAAAAA----- -----AAAAAAAAAAAAA----- -------ABAAAAABA------- -------AAAAAAAAA------- ---------AAAAA--------- ---------AAAAA--------- ----------------------- ----------------------- 
--AAAAAAAAAAAAAAAAAAA-- --AAAAAAAAAAAAAAAAAAA-- ---AAAAAAAAAAAAAAAAA--- ---AAAAAAAAAAAAAAAAA--- ----AAAAAAAAAAAAAAA---- ----AAAAAAAAAAAAAAA---- -----AAAAAAAAAAAAA----- -----AAAAAAAAAAAAA----- -------AAAAAAAAA------- -------AAAAAAAAA------- ---------AAAAA--------- ---------AAAAA--------- 
-AAAAAAAAAAAAAAAAAAAAA- -AAAAAAAAAAAAAAAAAAAAA- --AAAAAAAAAAAAAAAAAAA-- --AAAAAAAAAAAAAAAAAAA-- ---AAAAAAAAAAAAAAAAA--- ---AAAAAAAAAAAAAAAAA--- -----AAAAAAAAAAAAA----- -----AAAAAAAAAAAAA----- ------AAAAAAAAAAA------ ------AAAAAAAAAAA------ -------AAAAAAAAA------- -------AAAAAAAAA------- 
-AAAAAAAAAAAAAAAAAAAAA- -AAAAAAAAAAAAAAAAAAAAA- --AAAAAAAAAAAAAAAAAAA-- --AAAAAAAAAAAAAAAAAAA-- ---AAAAAAAAAAAAAAAAA--- ---AAAAAAAAAAAAAAAAA--- ----AAAAAAAAAAAAAAA---- ----AAAAAAAAAAAAAAA---- -----AAAAAAAAAAAAA----- -----AAAAAAAAAAAAA----- ------AAAAAAAAAAA------ ------AAAAAAAAAAA------ 
AAAAAAAAAAAAAAAAAAAAAAA AAAAAAAAAAAAAAAAAAAAAAA -AAAAAAAAAAAAAAAAAAAAA- -AAAAAAAAAAAAAAAAAAAAA- --AAAAAAAAAAAAAAAAAAA-- --AAAAAAAAAAAAAAAAAAA-- ----AAAAAAAAAAAAAAA---- ----AAAAAAAAAAAAAAA---- -----AAAAAAAAAAAAA----- -----AAAAAAAAAAAAA----- ------AAAAAAAAAAA------ ------AAAAAAAAAAA------ 
AAAAAAAAAAAAAAAAAAAAAAA AAAAAAAAAAAAAAAAAAAAAAA -AAAAAAAAAAAAAAAAAAAAA- -AAAAAAAAAAAAAAAAAAAAA- --AAAAAAAAAAAAAAAAAAA-- --AAAAAAAAAAAAAAAAAAA-- ---AAAAAAAAAAAAAAAAA--- ---AAAAAAAAAAAAAAAAA--- ----AAAAAAAAAAAAAAA---- ----AAAAAAAAAAAAAAA---- -----AAAAAAAAAAAAA----- -----AAAAAAAAAAAAA----- 
AAAAAAAAAAAAAAAAAAAAAAA AAAAAAAAAAAAAAAAAAAAAAA -AAAAAAAAAAAAAAAAAAAAA- -AAAAAAAAAAAAAAAAAAAAA- --AAAAAAAAAAAAAAAAAAA-- --AAAAAAAAAAAAAAAAAAA-- ---AAAAAAAAAAAAAAAAA--- ---AAAAAAAAAAAAAAAAA--- ----AAAAAAAAAAAAAAA---- ----AAAAAAAAAAAAAAA---- -----AAAAAAAAAAAAA----- -----AAAAAAAAAAAAA----- 
AAAAAAAAAAAAAAAAAAAAAAA AAAAAAAAAAAAAAAAAAAAAAA -AAAAAAAAAAAAAAAAAAAAA- -AAAAAAAAAAAAAAAAAAAAA- --AAAAAAAAAAAAAAAAAAA-- --AAAAAAAAAAAAAAAAAAA-- ---AAAAAAAAAAAAAAAAA--- ---AAAAAAAAAAAAAAAAA--- ----AAAAAAAAAAAAAAA---- ----AAAAAAAAAAAAAAA---- -----AAAAAAAAAAAAA----- -----AAAAAAAAAAAAA----- 
AAAAAAAAAAAAAAAAAAAAAAA AAAAAAAAAAAAAAAAAAAAAAA -AAAAAAAAAAAAAAAAAAAAA- -AAAAAAAAAAAAAAAAAAAAA- --AAAAAAAAAAAAAAAAAAA-- --AAAAAAAAAAAAAAAAAAA-- ---AAAAAAAAAAAAAAAAA--- ---AAAAAAAAAAAAAAAAA--- ----AAAAAAAAAAAAAAA---- ----AAAAAAAAAAAAAAA---- -----AAAAAAAAAAAAA----- -----AAAAAAAAAAAAA----- 
AAAAAAAAAAAAAAAAAAAAAAA AAAAAAAAAAAAAAAAAAAAAAA -AAAAAAAAAAAAAAAAAAAAA- -AAAAAAAAAAAAAAAAAAAAA- --AAAAAAAAAAAAAAAAAAA-- --AAAAAAAAAAAAAAAAAAA-- ---AAAAAAAAAAAAAAAAA--- ---AAAAAAAAAAAAAAAAA--- ----AAAAAAAAAAAAAAA---- ----AAAAAAAAAAAAAAA---- -----AAAAAAAAAAAAA----- -----AAAAAAAAAAAAA----- 
AAAAAAAAAAAAAAAAAAAAAAA AAAAAAAAAAAAAAAAAAAAAAA -AAAAAAAAAAAAAAAAAAAAA- -AAAAAAAAAAAAAAAAAAAAA- --AAAAAAAAAAAAAAAAAAA-- --AAAAAAAAAAAAAAAAAAA-- ----AAAAAAAAAAAAAAA---- ----AAAAAAAAAAAAAAA---- -----AAAAAAAAAAAAA----- -----AAAAAAAAAAAAA----- ------AAAAAAAAAAA------ ------AAAAAAAAAAA------ 
-AAAAAAAAAAAAAAAAAAAAA- -AAAAAAAAAAAAAAAAAAAAA- --AAAAAAAAAAAAAAAAAAA-- --AAAAAAAAAAAAAAAAAAA-- ---AAAAAAAAAAAAAAAAA--- ---AAAAAAAAAAAAAAAAA--- ----AAAAAAAAAAAAAAA---- ----AAAAAAAAAAAAAAA---- -----AAAAAAAAAAAAA----- -----AAAAAAAAAAAAA----- ------AAAAAAAAAAA------ ------AAAAAAAAAAA------ 
-AAAAAAAAAAAAAAAAAAAAA- -AAAAAAAAAAAAAAAAAAAAA- --AAAAAAAAAAAAAAAAAAA-- --AAAAAAAAAAAAAAAAAAA-- ---AAAAAAAAAAAAAAAAA--- ---AAAAAAAAAAAAAAAAA--- -----AAAAAAAAAAAAA----- -----AAAAAAAAAAAAA----- ------AAAAAAAAAAA------ ------AAAAAAAAAAA------ -------AAAAAAAAA------- -------AAAAAAAAA------- 
--AAAAAAAAAAAAAAAAAAA-- --AAAAAAAAAAAAAAAAAAA-- ---AAAAAAAAAAAAAAAAA--- ---AAAAAAAAAAAAAAAAA--- ----AAAAAAAAAAAAAAA---- ----AAAAAAAAAAAAAAA---- -----AAAAAAAAAAAAA----- -----AAAAAAAAAAAAA----- -------AAAAAAAAA------- -------AAAAAAAAA------- ---------AAAAA--------- ---------AAAAA--------- 
--AAAAAAAAAAAAAAAAAAA-- --AAAAAAAAAAAAAAAAAAA-- ----AAAAAAAAAAAAAAA---- ----AAAAAAAAAAAAAAA---- -----AAAAAAAAAAAAA----- -----AAAAAAAAAAAAA----- -------AAAAAAAAA------- -------AAAAAAAAA------- ---------AAAAA--------- ---------AAAAA--------- ----------------------- ----------------------- 
---AAAAAAAAAAAAAAAAA--- ---AAAAAAAAAAAAAAAAA--- -----AAAAAAAAAAAAA----- -----AAAAAAAAAAAAA----- ------AAAAAAAAAAA------ ------AAAAAAAAAAA------ ---------AAAAA--------- ---------AAAAA--------- ----------------------- ----------------------- ----------------------- ----------------------- 
----AAAAAAAAAAAAAAA---- ----AAAAAAAAAAAAAAA---- ------AAAAAAAAAAA------ ------AAAAAAAAAAA------ --------AAAAAAA-------- --------AAAAAAA-------- ----------------------- ----------------------- ----------------------- ----------------------- ----------------------- ----------------------- 
------AAAAAAAAAAA------ ------AAAAAAAAAAA------ --------AAAAAAA-------- --------AAAAAAA-------- ----------------------- ----------------------- ----------------------- ----------------------- ----------------------- ----------------------- ----------------------- ----------------------- 
--------AAAAAAA-------- --------AAAAAAA-------- ----------------------- ----------------------- ----------------------- ----------------------- ----------------------- ----------------------- ----------------------- ----------------------- ----------------------- ----------------------- 
