model
size = 31 22 31, scale = 0.05, origin = -y
material 
  colors = A:#444 B:#1B813E C:#111 D:#FCFAF2 E:#DDD F:#ADFF2F G:#777
voxels
------------------------------- ------------------------------- ------------------------------- ------------------------------- ------------------------------- ------------------------------- ------------------------------- ------------------------------- ------------AAAAAAA------------ ------------BBFFFBB------------ ------------AAAAAAA------------ ------------------------------- ------------------------------- ------------------------------- ------------------------------- ------------------------------- ------------------------------- ------------------------------- ------------------------------- ------------------------------- ------------------------------- ------------------------------- 
------------------------------- ------------------------------- ------------------------------- ------------------------------- ------------------------------- ------------------------------- ------------------------------- ------------AAAAAAA------------ ---------AAAAAAAAAAAAA--------- ---------BBBBBBBBBBBBB--------- ---------AAAAAAAAAAAAA--------- ------------AAAAAAA------------ ------------------------------- ------------------------------- ------------------------------- ------------------------------- ------------------------------- ------------------------------- ------------------------------- ------------------------------- ------------------------------- ------------------------------- 
------------------------------- ------------------------------- ------------------------------- ------------------------------- ------------------------------- ------------------------------- ------------------------------- ---------AAAAAAAAAAAAA--------- -------AAAAAAAAAAAAAAAAA------- -------BBBBBBBBBBBBBBBBB------- -------AAAAAAAAAAAAAAAAA------- ---------AAAAAAAAAAAAA--------- ------------------------------- ------------------------------- ------------------------------- ------------------------------- ------------------------------- ------------------------------- ------------------------------- ------------------------------- ------------------------------- ------------------------------- 
------------------------------- ------------------------------- ------------------------------- ------------------------------- ------------------------------- ------------CCCCCCC------------ ------------CCCCCCC------------ -------AAAAAAAAAAAAAAAAA------- ------AAAAAAAAAAAAAAAAAAA------ ------BBBBBBBBBBBBBBBBBBB------ ------AAAAAAAAAAAAAAAAAAA------ -------AAAAAAAAAAAAAAAAA------- ------------CCCCCCC------------ ------------CCCCCCC------------ ------------------------------- ------------------------------- ------------------------------- ------------------------------- ------------------------------- ------------------------------- ------------------------------- ------------------------------- 
------------------------------- ------------------------------- ------------------------------- ------------------------------- ------------------------------- ----------CCCCCCCCCCC---------- ----------CCCCCCCCCCC---------- ------AAAAAAAAAAAAAAAAAAA------ -----AAAAAAAAAAAAAAAAAAAAA----- -----FBBBBBBBBBBBBBBBBBBBF----- -----AAAAAAAAAAAAAAAAAAAAA----- ------AAAAAAAAAAAAAAAAAAA------ ----------CCCCCCCCCCC---------- ----------CCCCCCCCCCC---------- ------------------------------- ------------------------------- ------------------------------- ------------------------------- ------------------------------- ------------------------------- ------------------------------- ------------------------------- 
------------------------------- ------------------------------- ------------------------------- ------------------------------- ------------------------------- --------CCCCCCEEECCCCCC-------- --------CCCCCCCCCCCCCCC-------- -----AAAAAAAAAAAAAAAAAAAAA----- ----AAAAAAAAAAAAAAAAAAAAAAA---- ----FBBBBBBBBBBBBBBBBBBBBBF---- ----AAAAAAAAAAAAAAAAAAAAAAA---- -----AAAAAAAAAAAAAAAAAAAAA----- --------CCCCCCCCCCCCCCC-------- --------CCCCCCEEECCCCCC-------- ------------------------------- ------------------------------- ------------------------------- ------------------------------- ------------------------------- ------------------------------- ------------------------------- ------------------------------- 
------------------------------- ------------------------------- ------------------------------- ------------BBBEBBB------------ ------------BBBBBBB------------ -------CCCCCCCCCCCCCCCCC------- -------CCCCCCCCCCCCCCCCC------- ----AAAAAAAAAAAAAAAAAAAAAAA---- ---AAAAAAAAAAAAAAAAAAAAAAAAA--- ---BBBBBBBBBBBBBBBBBBBBBBBBB--- ---AAAAAAAAAAAAAAAAAAAAAAAAA--- ----AAAAAAAAAAAAAAAAAAAAAAA---- -------CCCCCCCCCCCCCCCCC------- -------CCCCCCCCCCCCCCCCC------- ------------BBBBBBB------------ ------------------------------- ------------------------------- ------------------------------- ------------------------------- ------------------------------- ------------------------------- ------------------------------- 
------------------------------- ------------------------------- -------------BBBBB------------- ----------BBBBBBBBBBB---------- ----------BBBBBBBBBBB---------- ------CCCCCCCCCCCCCCCCCCC------ ------CCCCCCCCCCCCCCCCCCC------ ---AAAAAAAAAAAAAAAAAAAAAAAAA--- --AAAAAAAAAAAAAAAAAAAAAAAAAAA-- --BBBBBBBBBBBBBBBBBBBBBBBBBBB-- --AAAAAAAAAAAAAAAAAAAAAAAAAAA-- ---AAAAAAAAAAAAAAAAAAAAAAAAA--- ------CCCCCCCCCCCCCCCCCCC------ ------CCCCCCCCCCCCCCCCCCC------ ----------BBBBBBBBBBB---------- ------------------------------- ------------------------------- ------------------------------- ------------------------------- ------------------------------- ------------------------------- ------------------------------- 
------------------------------- -------------BBEBB------------- -----------BBBBBBBBB----------- ---------BBBBBBBBBBBBB--------- ---------BBBBBBBBBBBBB--------- -----CCCCCCCCCCCCCCCCCCCCC----- -----CCCCCCCCCCCCCCCCCCCCC----- ---AAAAAAAAAAAAAAAAAAAAAAAAA--- --AAAAAAAAAAAAAAAAAAAAAAAAAAA-- --BBBBBBBBBBBBBBBBBBBBBBBBBBB-- --AAAAAAAAAAAAAAAAAAAAAAAAAAA-- ---AAAAAAAAAAAAAAAAAAAAAAAAA--- -----CCCCCCCCCCCCCCCCCCCCC----- -----CCCCCCCCCCCCCCCCCCCCC----- ---------BBBBBBBBBBBBB--------- ------------------------------- ------------------------------- ------------------------------- ------------------------------- ------------------------------- ------------------------------- ------------------------------- 
-------------BBBBB------------- -----------BBBBBBBBB----------- ---------BBBBBBBBBBBBB--------- --------BBBBBBBBBBBBBBB-------- --------BBBBBBBBBBBBBBB-------- -----CCCCCCCCCCCCCCCCCCCCC----- -----CCCCCCCCCCCCCCCCCCCCC----- --AAAAAAAAAAAAAAAAAAAAAAAAAAA-- -AAAAAAAAAAAAAAAAAAAAAAAAAAAAA- -BBBBBBBBBBBBBBBBBBBBBBBBBBBBB- -AAAAAAAAAAAAAAAAAAAAAAAAAAAAA- --AAAAAAAAAAAAAAAAAAAAAAAAAAA-- -----CCCCCCCCCCCCCCCCCCCCC----- -----CCCCCCCCCCCCCCCCCCCCC----- --------BBBBBBBBBBBBBBB-------- -------------DDDDD------------- -------------CD---------------- ------------------------------- ------------------------------- ------------------------------- ------------------------------- ------------------------------- 
-----------BBBEBEBBB----------- ----------BBBBBBBBBBB---------- ---------BBBBBBBBBBBBB--------- -------BBBBBBBBBBBBBBBBB------- -------BBBBBBBBBBBBBBBBB------- ----CCCCCCCCCCCCCCCCCCCCCCC---- ----CCCCCCCCCCCCCCCCCCCCCCC---- --AAAAAAAAAAAAAAAAAAAAAAAAAAA-- -AAAAAAAAAAAAAAAAAAAAAAAAAAAAA- -BBBBBBBBBBBBBBBBBBBBBBBBBBBBB- -AAAAAAAAAAAAAAAAAAAAAAAAAAAAA- --AAAAAAAAAAAAAAAAAAAAAAAAAAA-- ----CCCCCCCCCCCCCCCCCCCCCCC---- ----CCCCCCCCCCCCCCCCCCCCCCC---- -------BBBBBBBBBBBBBBBBB------- -----------DDDDDDDDD----------- -----------DDCD---DD----------- -------------CDDDD------------- -------------CDDDD------------- ------------------------------- ------------------------------- ------------------------------- 
----------BBBBBEBBBBB---------- ---------BBBBBBBBBBBBB--------- --------BBBBBBBBBBBBBBB-------- -------BBBBBBBBBBBBBBBBB------- -------BBBBBBBBBBBBBBBBB------- ----CCCCCCCCCCCCCCCCCCCCCCC---- ----CCCCCCCCCCCCCCCCCCCCCCC---- --AAAAAAAAAAAAAAAAAAAAAAAAAAA-- -AAAAAAAAAAAAAAAAAAAAAAAAAAAAA- -BBBBBBBBBBBBBBBBBBBBBBBBBBBBB- -AAAAAAAAAAAAAAAAAAAAAAAAAAAAA- --AAAAAAAAAAAAAAAAAAAAAAAAAAA-- ----CCCCCCCCCCCCCCCCCCCCCCC---- ----CCCCCCCCCCCCCCCCCCCCCCC---- -------BBBBBBBBBBBBBBBBB------- ----------DDDCDDDDDDD---------- ----------DDDCD---DDD---------- ------------DCDDDDD------------ ------------DCDFDFD------------ -------------CDDDD------------- -------------CCCCC------------- ------------------------------- 
----------BBBBBBBBBBB---------- ---------BBBBBBBBBBBBB--------- --------BBBBBBBBBBBBBBB-------- ------BBBBBBBBBBBBBBBBBBB------ ------BBBBBBBBBBBBBBBBBBB------ ---CCCCCCCCCCCCCCCCCCCCCCCCC--- ---CCCCCCCCCCCCCCCCCCCCCCCCC--- -AAAAAAAAAAAAAAAAAAAAAAAAAAAAA- AAAAAAAAAAAAAAAAAAAAAAAAAAAAAAA BBBBBBBBBBBBBBBBBBBBBBBBBBBBBBB AAAAAAAAAAAAAAAAAAAAAAAAAAAAAAA -AAAAAAAAAAAAAAAAAAAAAAAAAAAAA- ---CCCCCCCCCCCCCCCCCCCCCCCCC--- ---CCCCCCCCCCCCCCCCCCCCCCCCC--- ------BBBBBBBBBBBBBBBBBBB------ ----------DDDCDDDDDDD---------- ----------DDDCD---------------- -----------DDCD---------------- -----------DDCD---------------- ------------DCD---------------- ------------DCD---------------- --------------F---------------- 
---------BBBBEBBBEBBBB--------- --------BBBBBBBBBBBBBBB-------- -------BBBBBBBBBBBBBBBBB------- ------BBBBBBBBBBBBBBBBBBB------ ------BBBBBBBBBBBBBBBBBBB------ ---CCCCCCCCCCCCCCCCCCCCCCCCC--- ---CCCCCCCCCCCCCCCCCCCCCCCCC--- -AAAAAAAAAAAAAAAAAAAAAAAAAAAAA- AAAAAAAAAAAAAAAAAAAAAAAAAAAAAAA BBBBBBBBBBBBBBBBBBBBBBBBBBBBBBB AAAAAAAAAAAAAAAAAAAAAAAAAAAAAAA -AAAAAAAAAAAAAAAAAAAAAAAAAAAAA- ---CCCCCCCCCCCCCCCCCCCCCCCCC--- ---CCCCCCCCCCCCCCCCCCCCCCCCC--- ------BBBBBBBBBBBBBBBBBBB------ ---------DDDDCDCCCCCDD--------- ---------DDDDC-------D--------- ----------DDDC----------------- ----------DDDC----------------- -----------DDC----------------- -----------DDC----------------- -------------C----------------- 
---------BEBBBEBEBBBEB--------- --------BBBBBBBBBBBBBBB-------- -------BBBBBBBBBBBBBBBBB------- ------BBBBBBBBBBBBBBBBBBB------ ------BBBBBBBBBBBBBBBBBBB------ ---CCECCCCCCCCCCCCCCCCCCCECC--- ---CCCCCCCCCCCCCCCCCCCCCCCCC--- -AAAAAAAAAAAAAAAAAAAAAAAAAAAAA- AAAAAAAAAAAAAAAAAAAAAAAAAAAAAAA FBBBBBBBBBBBBBBBBBBBBBBBBBBBBBF AAAAAAAAAAAAAAAAAAAAAAAAAAAAAAA -AAAAAAAAAAAAAAAAAAAAAAAAAAAAA- ---CCCCCCCCCCCCCCCCCCCCCCCCC--- ---CCECCCCCCCCCCCCCCCCCCCECC--- ------BBBBBBBBBBBBBBBBBBB------ ---------DDDDCDCCCCCDD--------- ---------DDDDC-------D--------- ----------DDDC----------------- ----------DDDC----------------- -----------DDC----------------- -----------DDC----------------- ------------DC----------------- 
---------BBEBBBEBBBEBB--------- --------EBBBBBBBBBBBBBE-------- -------BBBBBBBBBBBBBBBBB------- ------EBBBBBBBBBBBBBBBBBE------ ------BBBBBBBBBBBBBBBBBBB------ ---CCECCCCCCCCCCCCCCCCCCCECC--- ---CCCCCCCCCCCCCCCCCCCCCCCCC--- -AAAAAAAAAAAAAACAAAAAAAAAAAAAA- AAAAAAAAAAAAAAAAAAAAAAAAAAAAAAA FBBBBBBBBBBBBBBGBBBBBBBBBBBBBBF AAAAAAAAAAAAAAAAAAAAAAAAAAAAAAA -AAAAAAAAAAAAAAAAAAAAAAAAAAAAA- ---CCCCCCCCCCCCCCCCCCCCCCCCC--- ---CCECCCCCCCCCCCCCCCCCCCECC--- ------BBBBBBBBBBBBBBBBBBB------ ---------CDDDCDCCCCCDD--------- ---------CDDDC-------D--------- ----------CDDC----------------- ----------CDDC----------------- -----------CDC----------------- -----------CDC----------------- ------------CC----------------- 
---------BEBBBEBEBBBEB--------- --------BBBBBBBBBBBBBBB-------- -------BBBBBBBBBBBBBBBBB------- ------BBBBBBBBBBBBBBBBBBB------ ------BBBBBBBBBBBBBBBBBBB------ ---CCECCCCCCCCCCCCCCCCCCCECC--- ---CCCCCCCCCCCCCCCCCCCCCCCCC--- -AAAAAAAAAAAAAAAAAAAAAAAAAAAAA- AAAAAAAAAAAAAAAAAAAAAAAAAAAAAAA FBBBBBBBBBBBBBBBBBBBBBBBBBBBBBF AAAAAAAAAAAAAAAAAAAAAAAAAAAAAAA -AAAAAAAAAAAAAAAAAAAAAAAAAAAAA- ---CCCCCCCCCCCCCCCCCCCCCCCCC--- ---CCECCCCCCCCCCCCCCCCCCCECC--- ------BBBBBBBBBBBBBBBBBBB------ ---------DDDDDDCCCCCDD--------- ---------DDDDC-------D--------- ----------DDDC----------------- ----------DDDC----------------- -----------DDC----------------- -----------DDC----------------- ------------DC----------------- 
---------BBBBEBBBEBBBB--------- --------BBBBBBBBBBBBBBB-------- -------BBBBBBBBBBBBBBBBB------- ------BBBBBBBBBBBBBBBBBBB------ ------BBBBBBBBBBBBBBBBBBB------ ---CCCCCCCCCCCCCCCCCCCCCCCCC--- ---CCCCCCCCCCCCCCCCCCCCCCCCC--- -AAAAAAAAAAAAAAAAAAAAAAAAAAAAA- AAAAAAAAAAAAAAAAAAAAAAAAAAAAAAA BBBBBBBBBBBBBBBBBBBBBBBBBBBBBBB AAAAAAAAAAAAAAAAAAAAAAAAAAAAAAA -AAAAAAAAAAAAAAAAAAAAAAAAAAAAA- ---CCCCCCCCCCCCCCCCCCCCCCCCC--- ---CCCCCCCCCCCCCCCCCCCCCCCCC--- ------BBBBBBBBBBBBBBBBBBB------ ---------DDDDDDCCCCCDD--------- ---------DDDDC-------D--------- ----------DDDC----------------- ----------DDDC----------------- -----------DDC----------------- -----------DDC----------------- -------------C----------------- 
----------BBBBBBBBBBB---------- ---------BBBBBBBBBBBBB--------- --------BBBBBBBBBBBBBBB-------- ------BBBBBBBBBBBBBBBBBBB------ ------BBBBBBBBBBBBBBBBBBB------ ---CCCCCCCCCCCCCCCCCCCCCCCCC--- ---CCCCCCCCCCCCCCCCCCCCCCCCC--- -AAAAAAAAAAAAAAAAAAAAAAAAAAAAA- AAAAAAAAAAAAAAAAAAAAAAAAAAAAAAA BBBBBBBBBBBBBBBBBBBBBBBBBBBBBBB AAAAAAAAAAAAAAAAAAAAAAAAAAAAAAA -AAAAAAAAAAAAAAAAAAAAAAAAAAAAA- ---CCCCCCCCCCCCCCCCCCCCCCCCC--- ---CCCCCCCCCCCCCCCCCCCCCCCCC--- ------BBBBBBBBBBBBBBBBBBB------ ----------DDDDDDDDDDD---------- ----------DDDDD---------------- -----------DDCD---------------- -----------DDCD---------------- ------------DCD---------------- ------------DCD---------------- --------------F---------------- 
----------BBBBBEBBBBB---------- ---------BBBBBBBBBBBBB--------- --------BBBBBBBBBBBBBBB-------- -------BBBBBBBBBBBBBBBBB------- -------BBBBBBBBBBBBBBBBB------- ----CCCCCCCCCBCCCCCCCCCCCCC---- ----CCCCCCCCCCCCCCCCCCCCCCC---- --AAAAAAAAAAAAAAAAAAAAAAAAAAA-- -AAAAAAAAAAAAAAAAAAAAAAAAAAAAA- -BBBBBBBBBBBBBBBBBBBBBBBBBBBBB- -AAAAAAAAAAAAAAAAAAAAAAAAAAAAA- --AAAAAAAAAAAAAAAAAAAAAAAAAAA-- ----CCCCCCCCCCCCCCCCCCCCCCC---- ----CCCCCCCCCCCCCCCCCCCCCCC---- -------BBBBBBBBBBBBBBBBB------- ----------DDDDDDDDDDD---------- ----------DDDDD---DDD---------- ------------DDDDDDD------------ ------------DDDFDFD------------ -------------CCCCC------------- -------------CDDDD------------- ------------------------------- 
-----------BBBEBEBBB----------- ----------BBBBBBBBBBB---------- ---------BBBBBBBBBBBBB--------- -------BBBBBBBBBBBBBBBBB------- -------BBBBBBBBBBBBBBBBB------- ----CCCCCCCCCCCCCCCCCCCCCCC---- ----CCCCCCCCCCCCCCCCCCCCCCC---- --AAAAAAAAAAAAAAAAAAAAAAAAAAA-- -AAAAAAAAAAAAAAAAAAAAAAAAAAAAA- -BBBBBBBBBBBBBBBBBBBBBBBBBBBBB- -AAAAAAAAAAAAAAAAAAAAAAAAAAAAA- --AAAAAAAAAAAAAAAAAAAAAAAAAAA-- ----CCCCCCCCCCCCCCCCCCCCCCC---- ----CCCCCCCCCCCCCCCCCCCCCCC---- -------BBBBBBBBBBBBBBBBB------- -----------DDDDDDDDD----------- -----------DDDD---DD----------- -------------CDDDD------------- -------------CDDDD------------- ------------------------------- ------------------------------- ------------------------------- 
-------------BBBBB------------- -----------BBBBBBBBB----------- ---------BBBBBBBBBBBBB--------- --------BBBBBBBBBBBBBBB-------- --------BBBBBBBBBBBBBBB-------- -----CCCCCCCCCCCCCCCCCCCCC----- -----CCCCCCCCCCCCCCCCCCCCC----- --AAAAAAAAAAAAAAAAAAAAAAAAAAA-- -AAAAAAAAAAAAAAAAAAAAAAAAAAAAA- -BBBBBBBBBBBBBBBBBBBBBBBBBBBBB- -AAAAAAAAAAAAAAAAAAAAAAAAAAAAA- --AAAAAAAAAAAAAAAAAAAAAAAAAAA-- -----CCCCCCCCCCCCCCCCCCCCC----- -----CCCCCCCCCCCCCCCCCCCCC----- --------BBBBBBBBBBBBBBB-------- -------------CDDDD------------- -------------CD---------------- ------------------------------- ------------------------------- ------------------------------- ------------------------------- ------------------------------- 
------------------------------- -------------BBEBB------------- -----------BBBBBBBBB----------- ---------BBBBBBBBBBBBB--------- ---------BBBBBBBBBBBBB--------- -----CCCCCCCCCCCCCCCCCCCCC----- -----CCCCCCCCCCCCCCCCCCCCC----- ---AAAAAAAAAAAAAAAAAAAAAAAAA--- --AAAAAAAAAAAAAAAAAAAAAAAAAAA-- --BBBBBBBBBBBBBBBBBBBBBBBBBBB-- --AAAAAAAAAAAAAAAAAAAAAAAAAAA-- ---AAAAAAAAAAAAAAAAAAAAAAAAA--- -----CCCCCCCCCCCCCCCCCCCCC----- -----CCCCCCCCCCCCCCCCCCCCC----- ---------BBBBBBBBBBBBB--------- ------------------------------- ------------------------------- ------------------------------- ------------------------------- ------------------------------- ------------------------------- ------------------------------- 
------------------------------- ------------------------------- -------------BBBBB------------- ----------BBBBBBBBBBB---------- ----------BBBBBBBBBBB---------- ------CCCCCCCCCCCCCCCCCCC------ ------CCCCCCCCCCCCCCCCCCC------ ---AAAAAAAAAAAAAAAAAAAAAAAAA--- --AAAAAAAAAAAAAAAAAAAAAAAAAAA-- --BBBBBBBBBBBBBBBBBBBBBBBBBBB-- --AAAAAAAAAAAAAAAAAAAAAAAAAAA-- ---AAAAAAAAAAAAAAAAAAAAAAAAA--- ------CCCCCCCCCCCCCCCCCCC------ ------CCCCCCCCCCCCCCCCCCC------ ----------BBBBBBBBBBB---------- ------------------------------- ------------------------------- ------------------------------- ------------------------------- ------------------------------- ------------------------------- ------------------------------- 
------------------------------- ------------------------------- ------------------------------- ------------BBBEBBB------------ ------------BBBBBBB------------ -------CCCCCCCCCCCCCCCCC------- -------CCCCCCCCCCCCCCCCC------- ----AAAAAAAAAAAAAAAAAAAAAAA---- ---AAAAAAAAAAAAAAAAAAAAAAAAA--- ---BBBBBBBBBBBBBBBBBBBBBBBBB--- ---AAAAAAAAAAAAAAAAAAAAAAAAA--- ----AAAAAAAAAAAAAAAAAAAAAAA---- -------CCCCCCCCCCCCCCCCC------- -------CCCCCCCCCCCCCCCCC------- ------------BBBBBBB------------ ------------------------------- ------------------------------- ------------------------------- ------------------------------- ------------------------------- ------------------------------- ------------------------------- 
------------------------------- ------------------------------- ------------------------------- ------------------------------- ------------------------------- --------CCCCCCEEECCCCCC-------- --------CCCCCCCCCCCCCCC-------- -----AAAAAAAAAAAAAAAAAAAAA----- ----AAAAAAAAAAAAAAAAAAAAAAA---- ----FBBBBBBBBBBBBBBBBBBBBBF---- ----AAAAAAAAAAAAAAAAAAAAAAA---- -----AAAAAAAAAAAAAAAAAAAAA----- --------CCCCCCCCCCCCCCC-------- --------CCCCCCEEECCCCCC-------- ------------------------------- ------------------------------- ------------------------------- ------------------------------- ------------------------------- ------------------------------- ------------------------------- ------------------------------- 
------------------------------- ------------------------------- ------------------------------- ------------------------------- ------------------------------- ----------CCCCCCCCCCC---------- ----------CCCCCCCCCCC---------- ------AAAAAAAAAAAAAAAAAAA------ -----AAAAAAAAAAAAAAAAAAAAA----- -----FBBBBBBBBBBBBBBBBBBBF----- -----AAAAAAAAAAAAAAAAAAAAA----- ------AAAAAAAAAAAAAAAAAAA------ ----------CCCCCCCCCCC---------- ----------CCCCCCCCCCC---------- ------------------------------- ------------------------------- ------------------------------- ------------------------------- ------------------------------- ------------------------------- ------------------------------- ------------------------------- 
------------------------------- ------------------------------- ------------------------------- ------------------------------- ------------------------------- ------------CCCCCCC------------ ------------CCCCCCC------------ -------AAAAAAAAAAAAAAAAA------- ------AAAAAAAAAAAAAAAAAAA------ ------BBBBBBBBBBBBBBBBBBB------ ------AAAAAAAAAAAAAAAAAAA------ -------AAAAAAAAAAAAAAAAA------- ------------CCCCCCC------------ ------------CCCCCCC------------ ------------------------------- ------------------------------- ------------------------------- ------------------------------- ------------------------------- ------------------------------- ------------------------------- ------------------------------- 
------------------------------- ------------------------------- ------------------------------- ------------------------------- ------------------------------- ------------------------------- ------------------------------- ---------AAAAAAAAAAAAA--------- -------AAAAAAAAAAAAAAAAA------- -------BBBBBBBBBBBBBBBBB------- -------AAAAAAAAAAAAAAAAA------- ---------AAAAAAAAAAAAA--------- ------------------------------- ------------------------------- ------------------------------- ------------------------------- ------------------------------- ------------------------------- ------------------------------- ------------------------------- ------------------------------- ------------------------------- 
------------------------------- ------------------------------- ------------------------------- ------------------------------- ------------------------------- ------------------------------- ------------------------------- ------------AAAAAAA------------ ---------AAAAAAAAAAAAA--------- ---------BBBBBBBBBBBBB--------- ---------AAAAAAAAAAAAA--------- ------------AAAAAAA------------ ------------------------------- ------------------------------- ------------------------------- ------------------------------- ------------------------------- ------------------------------- ------------------------------- ------------------------------- ------------------------------- ------------------------------- 
------------------------------- ------------------------------- ------------------------------- ------------------------------- ------------------------------- ------------------------------- ------------------------------- ------------------------------- ------------AAAAAAA------------ ------------BBFFFBB------------ ------------AAAAAAA------------ ------------------------------- ------------------------------- ------------------------------- ------------------------------- ------------------------------- ------------------------------- ------------------------------- ------------------------------- ------------------------------- ------------------------------- ------------------------------- 
