model
size = 32 20 32, scale = 0.05, origin = -y
material 
  colors = A:#FBE251 B:#28C15B C:#111 D:#E83015
voxels
204-8B568-8D24-8A21-3B8A3B21-8C472-ABA2DABA24-8A21-3D8-3D18-3A8-3A16-2B3A8-3A2B16-3C8-3C405-8A24-3A2D3A22-2D8-2D20-2A8-2A18-2D12-2D16-2A12-2A14-2B2A12-2A2B14-2C12-2C402-12A20-2DA6-A2D18-BA12-AB16-2A12-2A14-2D16-2D12-2A16-2A11-B2A16-2AB11-2C16-2C398-16A16-2A12-2A15-A16-A14-A16-A12-2D18-2D10-2A18-2A9-B2A18-2AB9-2C18-2C396-18A14-DA14-AD13-D18-D12-A18-A10-2D20-2D8-2A20-2A7-B2A20-2AB7-2C20-2C394-20A12-DA16-AD11-A20-A10-A20-A9-D22-D8-A22-A6-2BA22-A2B6-C22-C393-22A10-2A6-6A6-2A9-B8-6A8-B8-A8-6A8-A7-D24-D6-A24-A5-BA24-AB5-C24-C392-8A6-8A10-A5-2A6-2A5-A9-A2(6-2A)6-A8-A6-10A6-A6-2D9-6B9-2D4-2A9-6B9-2A3-B2A9-6B9-2AB3-2C9-6B9-2C390-2(8A8-)D5-2A8-2A5-D7-D6-2A8-2A6-D6-A6-4A4-4A6-A5-D9-2B4-2B9-D4-A9-2B4-2B9-A3-BA9-2B4-2B9-AB3-C9-8B9-C16-2(4C28-)4C306-7A10-7A8-D4-2A10-2A4-D7-D5-2A10-2A5-D6-A5-3A8-3A5-A5-D2(8-B)8-D4-A2(8-B)8-A3-BA2(8-B)8-AB3-C8-3B4-3B8-C14-2(2C4-2C24-)8C303-7A12-7A6-2A4-A12-A4-2A5-A6-A12-A6-A4-A6-2A10-2A6-A3-D8-B10-B8-D2-A8-B10-B8-A-BA8-B10-B8-AB-C2(8-2B)8-C12-2(C8-C22-)10C25-2(4D28-)4A28-4A177-6A14-6A6-A4-A14-A4-A5-B5-A14-A5-B4-A5-3A10-3A5-A3-D7-2B10-2B7-D2-A7-2B10-2B7-A-BA7-2B10-2B7-AB-C7-3B8-3B7-C12-2(C8-C22-)3C4-3C24-2(D4-D26-)A4-A26-6A27-4B28-4B113-6A14-6A6-A4-A14-A4-2(A5-)A14-A5-A4-A5-2A12-2A5-A3-D7-B12-B7-D2-A7-B12-B7-A-BA7-B12-B7-AB-C7-2B10-2B7-C11-2(C10-C20-)3C6-3C22-2(D6-D24-)A6-A24-3A2-3A25-2B2-2B26-6B28-2C30-2C50-2(6A14-6A6-D4-A14-A4-2(D5-)A14-A5-D4-A5-2A12-2A5-A3-D7-B12-B7-D2-A7-B12-B7-A-BA7-B12-B7-AB-C7-2B10-2B7-C11-2(C10-C20-)3C6-3C22-2(D6-D24-)A6-A24-2A4-2A25-B4-B26-6B27-C2AC28-C2AC29-2C18-)6A14-6A6-A4-A14-A4-2(A5-)A14-A5-A4-A5-2A12-2A5-A3-D7-B12-B7-D2-A7-B12-B7-A-BA7-B12-B7-AB-C7-2B10-2B7-C11-2(C10-C20-)3C6-3C22-2(D6-D24-)A6-A24-3A2-3A25-2B2-2B26-6B28-2C30-2C50-6A14-6A6-A4-A14-A4-A5-B5-A14-A5-B4-A5-3A10-3A5-A3-D7-2B10-2B7-D2-A7-2B10-2B7-A-BA7-2B10-2B7-AB-C7-3B8-3B7-C12-2(C8-C22-)2CA4-A2C24-2(D4-D26-)A4-A26-6A27-4B28-4B113-7A12-7A6-2A4-A12-A4-2A5-A6-A12-A6-A4-A6-2A10-2A6-A3-D8-B10-B8-D2-A8-B10-B8-A-BA8-B10-B8-AB-C2(8-2B)8-C12-2(C8-C22-)3C4A3C25-2(4D28-)4A28-4A178-7A10-7A8-D4-2A10-2A4-D7-D5-2A10-2A5-D6-A5-3A8-3A5-A5-D2(8-B)8-D4-A2(8-B)8-A3-BA2(8-B)8-AB3-C8-3B4-3B8-C14-2(2C4-2C24-)8C304-2(8A8-)D5-2A8-2A5-D7-D6-2A8-2A6-D6-A6-4A4-4A6-A5-D9-2B4-2B9-D4-A9-2B4-2B9-A3-BA9-2B4-2B9-AB3-C9-8B9-C16-2(4C28-)4C307-8A6-8A10-A5-2A6-2A5-A9-A2(6-2A)6-A8-A6-10A6-A6-2D9-6B9-2D4-2A9-6B9-2A3-B2A9-6B9-2AB3-2C9-6B9-2C391-22A10-2A6-6A6-2A9-B8-6A8-B8-A8-6A8-A7-D24-D6-A24-A5-BA24-AB5-C24-C393-20A12-DA16-AD11-A20-A10-A20-A9-D22-D8-A22-A6-2BA22-A2B6-C22-C395-18A14-DA14-AD13-D18-D12-A18-A10-2D20-2D8-2A20-2A7-B2A20-2AB7-2C20-2C396-16A16-2A12-2A15-A16-A14-A16-A12-2D18-2D10-2A18-2A9-B2A18-2AB9-2C18-2C399-12A20-2DA6-A2D18-BA12-AB16-2A12-2A14-2D16-2D12-2A16-2A11-B2A16-2AB11-2C16-2C402-8A24-3A2D3A22-2D8-2D20-2A8-2A18-2D12-2D16-2A12-2A14-2B2A12-2A2B14-2C12-2C468-ABA2DABA24-8A21-3D8-3D18-3A8-3A16-2B3A8-3A2B16-3C8-3C533-8D24-8A21-3B8A3B21-8C600-8B428-
