model
size = 6 10 31, scale = 0.05, origin = -y
material 
  colors = A:#111 B:#EEE C:#222 D:#E00
voxels
AACCAA ACCCCA AAAAAA ADAADA ADADDA ADDADA ADAADA AAAAAA ACCCCA AACCAA 
AACCAA AAAAAA AAAAAA BAAAAB BAAAAB BAAAAB BAAAAB AAAAAA AAAAAA AACCAA 
AACCAA AAAAAA BAAAAB AAAAAA AAAAAA AAAAAA AAAAAA BAAAAB AAAAAA AACCAA 
AACCAA AAAAAA BAAAAB BAAAAA BAAAAA BAAAAA BAAAAA BAAAAB AAAAAA AACCAA 
AACCAA AAAAAA AAAAAA AAAAAA AAAAAA AAAAAA AAAAAA AAAAAA AAAAAA AACCAA 
AACCAA AAAAAA BAAAAB AAAAAB AAAAAB BAAAAB AAAAAB BAAAAB AAAAAA AACCAA 
AACCAA AAAAAA BAAAAB BAAAAA BAAAAA BAAAAB BAAAAA BAAAAB AAAAAA AACCAA 
AACCAA AAAAAA AAAAAA AAAAAA AAAAAA AAAAAA AAAAAA AAAAAA AAAAAA AACCAA 
AACCAA AAAAAA BAAAAB AAAAAB BAAAAB BAAAAB BAAAAB BAAAAB AAAAAA AACCAA 
AACCAA AAAAAA AAAAAA BAAAAA AAAAAA AAAAAB AAAAAA BAAAAA AAAAAA AACCAA 
AACCAA AAAAAA BAAAAA BAAAAA BAAAAB BAAAAA BAAAAA BAAAAA AAAAAA AACCAA 
AACCAA AAAAAA AAAAAB AAAAAB AAAAAB AAAAAB AAAAAB AAAAAB AAAAAA AACCAA 
AACCAA AAAAAA BAAAAA BAAAAA BAAAAA BAAAAA BAAAAA BAAAAA AAAAAA AACCAA 
AACCAA AAAAAA BAAAAB AAAAAA AAAAAA AAAAAB AAAAAB BAAAAB AAAAAA AACCAA 
AACCAA AAAAAA BAAAAB BAAAAB BAAAAB BAAAAA BAAAAA BAAAAB AAAAAA AACCAA 
AACCAA AAAAAA AAAAAA AAAAAA AAAAAA AAAAAA AAAAAA AAAAAA AAAAAA AACCAA 
AACCAA AAAAAA BAAAAB BAAAAB BAAAAB AAAAAB AAAAAB BAAAAB AAAAAA AACCAA 
AACCAA AAAAAA BAAAAB AAAAAA AAAAAA BAAAAA BAAAAA BAAAAB AAAAAA AACCAA 
AACCAA AAAAAA AAAAAB AAAAAB AAAAAB AAAAAB AAAAAB AAAAAB AAAAAA AACCAA 
AACCAA AAAAAA BAAAAA BAAAAA BAAAAA BAAAAA BAAAAA BAAAAA AAAAAA AACCAA 
AACCAA AAAAAA AAAAAB AAAAAB BAAAAB AAAAAB AAAAAB AAAAAB AAAAAA AACCAA 
AACCAA AAAAAA AAAAAA AAAAAB AAAAAA BAAAAA AAAAAA AAAAAB AAAAAA AACCAA 
AACCAA AAAAAA BAAAAB BAAAAA BAAAAB BAAAAB BAAAAB BAAAAB AAAAAA AACCAA 
AACCAA AAAAAA AAAAAA AAAAAA AAAAAA AAAAAA AAAAAA AAAAAA AAAAAA AACCAA 
AACCAA AAAAAA BAAAAB AAAAAB AAAAAB BAAAAB AAAAAB BAAAAB AAAAAA AACCAA 
AACCAA AAAAAA BAAAAB BAAAAA BAAAAA BAAAAB BAAAAA BAAAAB AAAAAA AACCAA 
AACCAA AAAAAA AAAAAA AAAAAA AAAAAA AAAAAA AAAAAA AAAAAA AAAAAA AACCAA 
AACCAA AAAAAA BAAAAB AAAAAB AAAAAB AAAAAB AAAAAB BAAAAB AAAAAA AACCAA 
AACCAA AAAAAA BAAAAB AAAAAA AAAAAA AAAAAA AAAAAA BAAAAB AAAAAA AACCAA 
AACCAA AAAAAA AAAAAA BAAAAB BAAAAB BAAAAB BAAAAB AAAAAA AAAAAA AACCAA 
AACCAA ACCCCA AAAAAA AADDAA ADAADA ADAADA AADDAA AAAAAA ACCCCA AACCAA 
