model
size = 23 32 21, scale = 0.05, origin = -y
material 
  colors = A:#960 B:#C60 C:#001 D:#300 E:#444 F:#EEE
voxels
122-5C18-5C19-4C18-5A18-A2B2A18-2BABA18-BAB2A17-4ABA17-AB4A2(18-2AB2A)18-2(AB)A19-3AB2(18-5C)294-2(AB)A19-B2A19-3ABA18-5A17-7A15-2C5-3C13-2C5-3C14-2C4-2C14-BA5-2A14-2A5-3A13-AB5-3A13-BA5-3A13-A6-B2A13-B6-2AB13-2A5-3A13-BA5-2AB13-2A5-BAB14-2A4-2A14-2C5-3C13-2C5-3C14-3A2(BA)16-AB4AB17-2A3B19-B3A18-5A18-2A3B155-A5-2B15-AB3-3A14-BA5-2A14-2A5-3A13-B7-BA12-C9-C11-2C9-C12-2C8-C2(12-A9-A)11-2A9-A11-2A10-A10-B2(A10-)BA10-B10-2A9-A12-B9-A12-A9-A12-2A8-B2(11-2C9-C)13-B7-2A13-A7-AB13-2A5-ABA14-2B4-AB15-A5-2A15-2(AB)4A150-3A8-BA10-3A8-2A10-2A9-2(2A10-)A2(10-2A)8-2C11-3C7-C12-3C8-C11-2C8-2A11-2A8-2A11-3A7-A12-3A7-A13-AB7-A13-BA7-A13-2A7-B12-3A7-2A11-B2A7-2A11-A2B8-B11-2A8-C12-3C7-C12-3C8-AB10-BA9-2A10-A10-B2(A10-)A2B8-AB10-3A8-2AE9-3B7-3A148-A12-A9-A12-B2(9-A12-A)8-A13-A8-C14-C6-C15-C7-C14-C7-A14-B7-A14-A6-B2(15-A6-A15-B6-A)15-A6-A15-A7-B14-A7-A14-A2(6-C15-C)7-A14-A8-B12-B9-B2(12-A8-EA)11-2E-E5-D-3A8-3AED5-2D14-2D6-D14-D8-D12-D10-2D8-2D12-4D2-4D16-4D13-3(A14-A7-)B14-A7-A14-A3(6-C15-C)2(6-A15-A)2(6-B15-A6-A15-B6-A15-A)6-A15-A6-A15-B2(6-C15-C)3(7-A14-A)6-EB14-A6-EB22-2A11-3A22-D6-D16-D6-D14-D8-D12-2(D10-)D12-3D4-3D9-2(A15-A6-)A15-B6-A15-A6-A15-B5-3(C17-C4-)4(A17-A4-)2(A17-B2(4-A17-A)4-)C17-C4-C17-C5-A15-A6-A15-B3(6-A15-A)6-2A13-2A144-B15-B6-B15-A2(6-A15-B)5-B17-A3(4-C17-C)4-B17-B2(4-B17-A4-A17-A)4-A17-A4-B17-A4-A17-B4-B17-A4-B17-B2(4-C17-C)4-A17-A4-A16-A6-B15-A6-A15-B6-B15-A6-BA14-A143-B16-B6-A15-A5-A16-B5-2(A17-A4-)A17-C4-C18-C3-C17-C4-A17-A4-A17-B4-B2(18-A3-A18-B3-A)2(18-A3-A)17-A4-A17-A4-2(C18-C3-)A17-B4-A17-A4-B17-A5-A15-A5-A16-B5-3A14-A143-A17-B4-A16-A5-2(A17-A4-)A17-B4-A2(18-C3-C)17-C4-A18-B3-A18-A3-B18-A3-A19-A2-A19-B2-A19-A2-A18-B2(3-A18-A)3-B18-B2(3-C18-C)3-3(A17-A4-)B17-A4-A17-A4-2A15-2A142-A17-A4-A16-B5-A17-A3-FA17-A4FB17-A2-E-A2(18-C3-C)18-C3-A18-B2(3-A18-A)3-B19-A2-A19-A2-B19-A2-A18-A3-A18-B3-B18-B3-A18-B2(3-C18-C)3-A17-A4-A17-B2(4-A17-A)4-A17-B4-2A16-B142-A17-A4-A16-B5-A17-A2(4-A17-B)4-A2(18-C3-C)17-C4-A18-B3-A18-A3-B18-A3-2(A19-A2-)A19-B2-A18-A3-B18-B2(3-A18-A)2(3-C18-C)3-B17-A2(4-A17-B)2(4-A17-A)4-2A15-BA142-A16-A6-A15-A5-A16-B5-2(A17-A4-)A2(17-C4-C)17-C4-A17-B4-A17-A4-2(A18-A3-)A18-B2(3-A18-A)3-A17-A4-B17-A4-A17-A2(4-C17-C)4-A17-A4-B17-B4-A17-A5-B15-A5-B16-A6-2A14-A144-A15-B2(6-A15-A)6-A15-B5-A16-A5-3(C17-C4-)2(B17-A4-)2(A17-A4-)A17-B4-B2(17-A4-A)17-B4-B17-A4-B17-B2(4-C17-C)4-A17-A4-A16-A6-A15-B6-B15-A6-A15-A6-2A13-2A144-B2(15-A6-A)15-A6-B15-B6-A15-B5-3(C17-C4-)B2(17-B4-A)17-A2(4-A17-A4-B17-B)4-A17-B2(4-A17-A)2(4-C17-C)5-B2(15-A6-A)15-B6-B15-A6-A15-A6-2A13-2AE21-D6-D16-D6-D14-D8-D12-2(D10-)D12-2D5-3D10-A14-A7-B13-B8-2(A14-A7-)A14-A3(6-C15-C)6-A15-A6-B15-A6-A15-B2(6-B15-A6-A15-A)3(6-A15-A)2(6-C15-C)7-A14-A7-B14-B7-A14-A6-EB14-B5-2EA14-A2E4-DABA10-3ADE4-2D14-2D6-D14-D8-D12-D10-2D8-2D12-4D2-4D16-4D14-2(A12-A9-)B12-A9-A12-B9-A12-A8-3(C14-C7-)A14-A7-A14-B7-A14-3(A6-A15-)3(A7-A14-)A7-B14-A2(7-C14-C)7-A13-2(A9-A12-)B9-A12-A8-EB12-AE8-3A8-ABAE146-2BA8-BA2(10-3A8-2A)10-2A10-B2(10-2A)8-CA11-3C7-2C11-3C8-C11-2C9-B11-2B8-2A11-A2B7-2B11-ABA7-AB12-AB7-A13-BA7-A13-2A7-BA11-ABA7-AB11-3A7-BA11-B2A8-A11-2A8-2C11-3C7-2C11-3C8-2A10-2A9-A2(B10-)AB10-A10-BAB8-2A10-3A8-BA10-B2A6-3AB151-A5-AB15-2A3-3A15-B5-2A14-BA5-ABA13-B7-2A2(12-C9-C)12-2C8-C12-B9-A12-A9-A12-B9-B12-A10-B10-2B10-A10-BA10-A11-B9-A12-A9-B12-A9-A12-2A8-A2(12-C9-C)13-A7-BA13-A7-AB13-2A5-B2A14-2B4-2A15-A5-2A15-B2AB4A154-AB2AB19-3A19-BAB2A18-2B3A17-4AB2A15-2C5-3C13-2C5-3C14-2C4-2C14-2A5-2A14-AB5-B2A13-AB5-3A13-2A5-2(2AB13-A6-)2BA13-BA2(5-3A13-2A)5-B2A14-BA4-2A14-2C5-3C13-2C5-3C14-5ABA16-2AB3AB17-3A2B19-B2AB18-2(AB)A18-3ABA271-5C18-5C19-4C18-5A18-2ABAB18-B3AB18-5A17-2A2(BA)17-B5A18-4AB18-4BA18-A2B2A19-2(BA)2(18-5C)287-
