model
size = 28 14 15, scale = 0.05, origin = -y
material 
  colors = A:#330 B:#111 C:#555 D:#444 E:#222 F:#960 G:#660 H:#888 I:#777 J:#3CF K:#EEE L:#300 M:#F9C N:#C90 O:#630 P:#BBB Q:#06F R:#A00 S:#E00
voxels
------BBB-----------BBB----- -----BBDBB---------BBDBB---- ---A-BDPDB---------BDPDB---- ---A-BBDBB-A-----A-BBDBB-A-- ----A-BBB-A-------A-BBB-A--- -----AAAAA---D-----AAAAA---- ------AAA------------------- ---------------------------- ---------------------------- ---------------------------- ---------------------------- ---------------------------- ---------------------------- ---------------------------- 
---------------------------- ---------------------------- -AAA---------------------AA- -AAAABBBBBAAGAAAAAGBBABBAAA- -AAAAABBBAAAGAAAAAGABBBAAAA- -AAAAAAAAAAAGAAAAAGAAAAAAA-- -------------------D-------- -------------------D-------- ---------------------------- ---------------------------- ---------------------------- ---------------------------- ---------------------------- ---------------------------- 
---------------------------- ---------------------------- DAAA---------------------AAD -KAAABBBBBAAAAAAAAABBABBAAE- -SAAAABBBAAAAAAAAAABBBBBAAA- -AAAAAAAAAAAAAAAAAAAAAAAAK-- -AAAAAAAAAAAGAAAAAGAD---DN-- -------------------D-------- ---------------------------- ---------------------------- ---------------------------- ---------------------------- ---------------------------- ---------------------------- 
---------------------------- ---------------------------- DAAA---------------------AAD -AABBBKBBBAAAAAAAAABBABBAAH- -AB----DFAAAAAAAAAABBBBBAAA- -A-----DFAAAAAAAAAAABAAAAN-- -A-----DFFOLLLBBDIIAA---DN-- -------D-----------B-------- -------D-----------B-------- -------------------B-------- -------------------B-------- ---------------------------- ---------------------------- ---------------------------- 
---------------------------- ---------------------------- HAAA---------------------AAD HAAEEEEEBBAAAAAAAAABBABBAAE- -AB-----FAACCDAAAAABBBBBAAA- -A------FAACDAAAAAAABBBAAA-- -A------FFOLAAABDRIAAAAAAA-- ------------CCD----J-------- -------D----C------K-------- -------------------J-------- -------------------B-------- ---------------------------- -----------C---------------- -----------C---------------- 
---------------------------- ---------------------------- DAAA---------------------AAD -AABBBBBBBAAAAAAAAABBABBAAH- -KB-----FACCCAAAAAABBBBBAAA- -A------FACCCAAAAAAABBBAAE-- -A------FFCCCLBBDCIAAAAAAA-- -----------CC---B--J-------- -------D---CC------J-------- ------------C------K-------- -------------------B-------- ---------------------------- -----------H---------------- -----------C---------------- 
---------------------------- ---------------------------- DAAA---------------------AAD -AAEEMMEBBAAAAAAAAABBABBAAE- -QB-----FCCCHIAAAAABBBBBAAA- -A------FCCCHIAAAAAABBBAAE-- -A------FCCCHIBBDCIAAAGGGA-- ---------CCCH---BE-K-------- -------D--CCC---B--J-------- ----------CCC------J-------- ----------CCCC-----B-------- -----------CEC-------------- -----------CC--------------- ---------------------------- 
---------------------------- ---------------------------- DAAA---------------------AAD -AABMBBMBBAAAAAAAAABBABBAAH- -QB-----FCCCHIAAAAABBBBBAAA- -A------FCCCHIAAAAAABBBAAE-- -A------MCCCHIBBDCIAAAAAAA-- ---------CCCHI--BE-J-------- -------D--CCH---B--K-------- ----------CCC------J-------- ----------CCCC-----B-------- ----------CCECCM------------ ----------CCC--------------- ---------------------------- 
---------------------------- ---------------------------- DAAA---------------------AAD -AAEEEEEBBAAAAAAAAABBABBAAE- -QB-----MACCHAAAAAABBBBBAAA- -A------MACCHAAAAAAABBBAAE-- -A------FFCCHLBBDCIAAAGGGA-- ----------CCC---B--J-------- -------D--CCC------J-------- ----------CCC------K-------- -----------CCC-----B-------- -----------CBC-------------- -----------CC--------------- ---------------------------- 
---------------------------- ---------------------------- DAAA---------------------AAD -AABBBBBBBAAAAAAAAABBABBAAC- -KB-----FAACCDAAAAABBBBBAAA- -A------FAACDAAAAAAABBBAAE-- -A------FFOLAAABDRIAAAAAAA-- ------------CCD----J-------- -------D----C------J-------- ------------C------J-------- -------------------B-------- ---------------------------- -----------H---------------- -----------C---------------- 
---------------------------- ---------------------------- HAAA---------------------AAD HAAEEEEEBBAAAAAAAAABBABBAAE- -AB-----FAAAAAAAAAABBBBBAAA- -A------FAAAAAAAAAAABBBAAA-- -A------FFOLLLBBDCIAAAAAAA-- -------------------J-------- -------D-----------J-------- -------------------J-------- -------------------B-------- ---------------------------- -----------C---------------- -----------C---------------- 
---------------------------- ---------------------------- DAAA---------------------AAD -AABBBKBBBAAAAAAAAABBABBAAC- -AB----DFAAAAAAAAAABBBBBAAA- -A-----DFAAAAAAAAAAAAAAAAK-- -A-----DFFOLLLBBDIIAA---DN-- -------D-----------B-------- -------D-----------B-------- -------------------B-------- -------------------B-------- ---------------------------- ---------------------------- ---------------------------- 
---------------------------- ---------------------------- DAAA---------------------AAD -KAAABBBBBAAAAAAAAABBABBAAE- -SAAAABBBAAAAAAAAAABBBBBAAA- -AAAAAAAAAAAAAAAAAAAAAAAAN-- -AAAAAAAAAAAGAAAAAGAD---DN-- -------------------D-------- ---------------------------- ---------------------------- ---------------------------- ---------------------------- ---------------------------- ---------------------------- 
---------------------------- ---------------------------- -AAA---------------------AA- -AAAABBBBBAAGAAAAAGBBABBAAA- -AAAAABBBAAAGAAAAAGABBBAAAA- -AAAAAAAAAAAGAAAAAGAAAAAAA-- -------------------D-------- -------------------D-------- ---------------------------- ---------------------------- ---------------------------- ---------------------------- ---------------------------- ---------------------------- 
------BBB-----------BBB----- -----BBDBB---------BBDBB---- ---A-BDPDB---------BDPDB---- ---A-BBDBB-A-----A-BBDBB-A-- ----A-BBB-A-------A-BBB-A--- -----AAAAA---D-----AAAAA---- ------AAA------------------- ---------------------------- ---------------------------- ---------------------------- ---------------------------- ---------------------------- ---------------------------- ---------------------------- 
