model
size = 29 21 29, scale = 0.05, origin = -y
material 
  colors = A:#FFC B:#F9C C:#F99 D:#FCF E:#800 F:#F9F G:#630
voxels
----------------------------- ----------------------------- ----------------------------- ----------------------------- ----------------------------- ----------------------------- ----------------------------- ----------------------------- ----------------------------- ----------------------------- ---------------B------------- ------------B--BB------------ -----------BBBBBBB----------- -----------BBBBBBB----------- ----------------------------- ----------------------------- ----------------------------- ----------------------------- ----------------------------- ----------------------------- ----------------------------- 
-----------CAAAAAA----------- -----------ACAAAAA----------- -----------AACAAAA----------- -----------AAACCAA----------- -----------AAAAACA----------- -----------CAAAAAC----------- -----------ACCAAAA----------- -----------AAACAAA----------- -----------AAAACCA----------- -----------AAAAAAC----------- ---------B-AAAAAAA----------- ---------BBAAAAAAAB---------- --------BBBAAAAAAABBB-------- --------BBBBBBBBBBBBB-------- -----------BBDBBBB----------- ----------------------------- ----------------------------- ----------------------------- ----------------------------- ----------------------------- ----------------------------- 
--------AACAAAAAAAACC-------- --------AAAAAAAAAAAAC-------- --------AAAAAAAAAAAAA-------- --------CAAAAAAAAAAAA-------- --------ACAAAAAAAAAAA-------- --------AACAAAAAAACAA-------- --------AAAAAAAAAAACA-------- --------AAAAAAAAAAAAC-------- --------CAAAAAAAAAAAA-------- --------CCAAAAAAAACAA-------- --------AAAAAAAAAACAA-------- --------AAAAAAAAAAAAA-------- -------BAAAAAAAAAAAAAB------- ------BBBBBBBBBBBBBBBBB------ --------BBBBBBBBBBBBB-------- ----------------------------- ----------------------------- ----------------------------- ----------------------------- ----------------------------- ----------------------------- 
-------AAAAAAAAAAAAAAA------- -------AAAAAAAAAAAAAAC------- -------CAAAAAAAAAAAAAA------- -------CAAAAAAAAAAAAAA------- -------AAAAAAAAAAAAAAA------- -------AAAAAAAAAAAAAAA------- -------AAAAAAAAAAAAAAA------- -------CAAAAAAAAAAAAAC------- -------CAAAAAAAAAAAAAC------- -------AAAAAAAAAAAAAAA------- -----B-AAAAAAAAAAAAAAA------- -----BBAAAAAAAAAAAAAAA------- -----BBAAAAAAAAAAAAAAABB----- -----BBBBBBBBBBBBBBBBBBB----- -------BBBDDDDDDDDBBBB------- ----------------------------- ----------------------------- ----------------------------- ----------------------------- ----------------------------- ----------------------------- 
-----AAAAAAAAAAAAAAAAAAA----- -----CAAAAAAAAAAAAAAAACA----- -----ACAAAAAAAAAAAAAAAAC----- -----AAAAAAAAAAAAAAAAAAA----- -----AAAAAAAAAAAAAAAAAAA----- -----AAAAAAAAAAAAAAAAAAA----- -----CAAAAAAAAAAAAAAAAAA----- -----CCAAAAAAAAAAAAAAAAA----- -----AAAAAAAAAAAAAAAAACA----- -----AAAAAAAAAAAAAAAAAAC----- -----AAAAAAAAAAAAAAAAAAAB---- -----AAAAAAAAAAAAAAAAAAAB---- ----BAAAAAAAAAAAAAAAAAAAB---- ----BBBBBBBBBBBBBBBBBBBBB---- -----BBBBDDBBBBBBDBBBBBB----- ------------------E---------- ----------------------------- ----------------------------- ----------------------------- ----------------------------- ----------------------------- 
----CAAAAAAAAAAAAAAAAAAAA---- ----CAAAAAAAAAAAAAAAAAAAA---- ----AAAAAAAAAAAAAAAAAAAAC---- ----AAAAAAAAAAAAAAAAAAAAC---- ----AAAAAAAAAAAAAAAAAAAAA---- ----AAAAAAAAAAAAAAAAAAAAA---- ----CAAAAAAAAAAAAAAAAAAAA---- ----AAAAAAAAAAAAAAAAAAAAA---- ----AAAAAAAAAAAAAAAAAAAAA---- ----AAAAAAAAAAAAAAAAAAAAC---- ----AAAAAAAAAAAAAAAAAAAAA---- ----AAAAAAAAAAAAAAAAAAAAAB--- ---BAAAAAAAAAAAAAAAAAAAAAB--- ---BBBBBBBBBBBBBBBBBBBBBBB--- ----BBBBBDBBBBBBBBBBBDBBD---- -----------E----------------- ----------------------------- ----------------------------- ----------------------------- ----------------------------- ----------------------------- 
----AAAAAAAAAAAAAAAAAAAAA---- ----AAAAAAAAAAAAAAAAAAAAA---- ----AAAAAAAAAAAAAAAAAAAAA---- ----AAAAAAAAAAAAAAAAAAAAA---- ----CAAAAAAAAAAAAAAAAAAAC---- ----CAAAAAAAAAAAAAAAAAAAA---- ----AAAAAAAAAAAAAAAAAAAAA---- ----AAAAAAAAAAAAAAAAAAAAA---- ----AAAAAAAAAAAAAAAAAAAAA---- ----AAAAAAAAAAAAAAAAAAAAA---- ---BAAAAAAAAAAAAAAAAAAAAA---- ---BAAAAAAAAAAAAAAAAAAAAA---- ---BAAAAAAAAAAAAAAAAAAAAAB--- --BBBBBBBBBBBBBBBBBBBBBBBBB-- ----BBBBBBBBBBBBBDBBBBBBB---- ------E---------------E------ ----------------------------- ----------------------------- ----------------------------- ----------------------------- ----------------------------- 
---CAAAAAAAAAAAAAAAAAAAAAA--- ---AAAAAAAAAAAAAAAAAAAAAAA--- ---AAAAAAAAAAAAAAAAAAAAAAA--- ---CAAAAAAAAAAAAAAAAAAAAAA--- ---CAAAAAAAAAAAAAAAAAAAAAC--- ---AAAAAAAAAAAAAAAAAAAAAAA--- ---AAAAAAAAAAAAAAAAAAAAAAA--- ---AAAAAAAAAAAAAAAAAAAAAAA--- ---AAAAAAAAAAAAAAAAAAAAAAA--- ---AAAAAAAAAAAAAAAAAAAAAAA--- ---AAAAAAAAAAAAAAAAAAAAAAA--- ---AAAAAAAAAAAAAAAAAAAAAAA--- --BAAAAAAAAAAAAAAAAAAAAAAAB-- --BBBBBBBBBBBBBBBBBBBBBBBBB-- ---BBBBBBBBBBBDBBBBBBBBBBB--- --------------------E-------- ----------------------------- ----------------------------- ----------------------------- ----------------------------- ----------------------------- 
--AAAAAAAAAAAAAAAAAAAAAAAAA-- --AAAAAAAAAAAAAAAAAAAAAAAAA-- --AAAAAAAAAAAAAAAAAAAAAAAAA-- --CAAAAAAAAAAAAAAAAAAAAAAAA-- --AAAAAAAAAAAAAAAAAAAAAAAAC-- --AAAAAAAAAAAAAAAAAAAAAAAAC-- --AAAAAAAAAAAAAAAAAAAAAAAAA-- --AAAAAAAAAAAAAAAAAAAAAAAAA-- --AAAAAAAAAAAAAAAAAAAAAAAAA-- --AAAAAAAAAAAAAAAAAAAAAAAAA-- --AAAAAAAAAAAAAAAAAAAAAAAAA-- --AAAAAAAAAAAAAAAAAAAAAAAAA-- -BAAAAAAAAAAAAAAAAAAAAAAAAAB- -BBBBBBBBBBBBBBBBBBBBBBBBBBB- --BBBDBBDDDDBBBBBBBBBBBBBBB-- -----------------E----------- ----------------------------- ----------------------------- ----------------------------- ----------------------------- ----------------------------- 
--AAAAAAAAAAAAAAAAAAAAAAAAA-- --AAAAAAAAAAAAAAAAAAAAAAAAA-- --CAAAAAAAAAAAAAAAAAAAAAAAA-- --AAAAAAAAAAAAAAAAAAAAAAAAA-- --AAAAAAAAAAAAAAAAAAAAAAAAA-- --AAAAAAAAAAAAAAAAAAAAAAAAA-- --AAAAAAAAAAAAAAAAAAAAAAAAC-- --AAAAAAAAAAAAAAAAAAAAAAAAA-- --AAAAAAAAAAAAAAAAAAAAAAAAA-- --AAAAAAAAAAAAAAAAAAAAAAAAA-- --CAAAAAAAAAAAAAAAAAAAAAAAA-- -BAAAAAAAAAAAAAAAAAAAAAAAAAB- -BAAAAAAAAAAAAAAAAAAAAAAAAAB- -BBBBBBBBBBBBBBBBBBBBBBBBBBB- --BBFBBDDBBBBBBBBBBBBBBBBBB-- -------------E--------------- ----------------------------- ----------------------------- ----------------------------- ----------------------------- ----------------------------- 
--AAAAAAAAAAAAAAAAAAAAAAAAA-- --CAAAAAAAAAAAAAAAAAAAAAAAA-- --AAAAAAAAAAAAAAAAAAAAAAAAA-- --AAAAAAAAAAAAAAAAAAAAAAAAA-- --AAAAAAAAAAAAAAAAAAAAAAAAA-- --AAAAAAAAAAAAAAAAAAAAAAAAA-- --AAAAAAAAAAAAAAAAAAAAAAAAC-- --AAAAAAAAAAAAAAAAAAAAAAAAA-- --AAAAAAAAAAAAAAAAAAAAAAAAA-- --CAAAAAAAAAAAAAAAAAAAAAAAA-- --AAAAAAAAAAAAAAAAAAAAAAAAA-- --AAAAAAAAAAAAAAAAAAAAAAAAA-- -BAAAAAAAAAAAAAAAAAAAAAAAAAB- -BBBBBBBBBBBBBBBBBBBBBBBBBBB- --BBFFBDBBBBBBBBBBBBBBBBBBD-- ----------------------------- ----------------------------- ----------------------------- ----------------------------- ----------------------------- ----------------------------- 
-AAAAAAAAAAAAAAAAAAAAAAAAAAC- -CAAAAAAAAAAAAAAAAAAAAAAAAAA- -AAAAAAAAAAAAAAAAAAAAAAAAAAA- -AAAAAAAAAAAAAAAAAAAAAAAAAAA- -AAAAAAAAAAAAAAAAAAAAAAAAAAA- -AAAAAAAAAAAAAAAAAAAAAAAAAAA- -AAAAAAAAAAAAAAAAAAAAAAAAAAC- -AAAAAAAAAAAAAAAAAAAAAAAAAAC- -AAAAAAAAAAAAAAAAAAAAAAAAAAA- -CAAAAAAAAAAAAAAAAAAAAAAAAAA- -AAAAAAAAAAAAAAAAAAAAAAAAAAA- -AAAAAAAAAAAAAAAAAAAAAAAAAAA- BAAAAAAAAAAAAAAAAAAAAAAAAAAAB BBBBBBBBBBBBBBBBBBBBBBBBBBBBB -BBBBFDDBBBBBBBBBBBBBBDDBBBB- ---E------E------------------ ----------------------------- ----------------------------- ----------------------------- ----------------------------- ----------------------------- 
-AAAAAAAAAAAAAAAAAAAAAAAAAAA- -CAAAAAAAAAAAAAAAAAAAAAAAAAC- -AAAAAAAAAAAAAAAAAAAAAAAAAAA- -AAAAAAAAAAAAAAAAAAAAAAAAAAA- -AAAAAAAAAAAAAAAAAAAAAAAAAAA- -AAAAAAAAAAAAAAAAAAAAAAAAAAA- -AAAAAAAAAAAAAAAAAAAAAAAAAAA- -AAAAAAAAAAAAAAAAAAAAAAAAAAA- -CAAAAAAAAAAAAAAAAAAAAAAAAAC- -AAAAAAAAAAAAAAAAAAAAAAAAAAA- -AAAAAAAAAAAAAAAAAAAAAAAAAAAB BAAAAAAAAAAAAAAAAAAAAAAAAAAAB BAAAAAAAAAAAAAAAAAAAAAAAAAAAB BBBBBBBBBBBBBBBBBBBBBBBBBBBBB -BBBDBDFBBBBBBBBBBBBBBBDDBBB- --------------E-----------E-- -------------EEE------------- --------------E-------------- ----------------------------- ----------------------------- ----------------------------- 
-CAAAAAAAAAAAAAAAAAAAAAAAAAA- -AAAAAAAAAAAAAAAAAAAAAAAAAAC- -AAAAAAAAAAAAAAAAAAAAAAAAAAA- -AAAAAAAAAAAAAAAAAAAAAAAAAAA- -AAAAAAAAAAAAAAAAAAAAAAAAAAA- -AAAAAAAAAAAAAAAAAAAAAAAAAAA- -AAAAAAAAAAAAAAAAAAAAAAAAAAA- -CAAAAAAAAAAAAAAAAAAAAAAAAAA- -AAAAAAAAAAAAAAAAAAAAAAAAAAC- BAAAAAAAAAAAAAAAAAAAAAAAAAAA- BAAAAAAAAAAAAAAAAAAAAAAAAAAA- BAAAAAAAAAAAAAAAAAAAAAAAAAAAB BAAAAAAAAAAAAAAAAAAAAAAAAAAAB BBBBBBBBBBBBBBBBBBBBBBBBBBBBB -BBBBBDDFBBBBBBBBBBBBBBBDBBB- -------------EEE------------- ------------EEEEE------------ -------------EEE------------- --------------E-------------- ----------------------------- ----------------------------- 
-AAAAAAAAAAAAA-AAAAAAAAAAAAA- -AAAAAAAAAAAAA-AAAAAAAAAAAAA- -AAAAAAAAAAAAA-AAAAAAAAAAAAC- -AAAAAAAAAAAAA-AAAAAAAAAAAAA- -AAAAAAAAAAAAA-AAAAAAAAAAAAA- -AAAAAAAAAAAAA-AAAAAAAAAAAAA- -AAAAAAAAAAAAA-AAAAAAAAAAAAA- -CAAAAAAAAAAAA-AAAAAAAAAAAAA- BAAAAAAAAAAAAA-AAAAAAAAAAAAA- BAAAAAAAAAAAAA-AAAAAAAAAAAAC- BAAAAAAAAAAAAA-AAAAAAAAAAAAA- BAAAAAAAAAAAAA-AAAAAAAAAAAAA- BAAAAAAAAAAAAABAAAAAAAAAAAAAB BBBBBBBBBBBBBBBBBBBBBBBBBBBBB -BBDBBBDFFBBBBEBBBBBBBBBDBBB- ------------EEEEE-----E------ ------------EEEEE------------ ------------EEEEE------------ -------------EGE------------- --------------G-------------- -------------GG-------------- 
-AAAAAAAAAAAAAAAAAAAAAAAAAAA- -AAAAAAAAAAAAAAAAAAAAAAAAAAA- -AAAAAAAAAAAAAAAAAAAAAAAAAAC- -AAAAAAAAAAAAAAAAAAAAAAAAAAA- -AAAAAAAAAAAAAAAAAAAAAAAAAAA- -AAAAAAAAAAAAAAAAAAAAAAAAAAA- -CAAAAAAAAAAAAAAAAAAAAAAAAAA- -AAAAAAAAAAAAAAAAAAAAAAAAAAA- -AAAAAAAAAAAAAAAAAAAAAAAAAAA- -AAAAAAAAAAAAAAAAAAAAAAAAAAC- -CAAAAAAAAAAAAAAAAAAAAAAAAAA- -AAAAAAAAAAAAAAAAAAAAAAAAAAA- BAAAAAAAAAAAAAAAAAAAAAAAAAAAB BBBBBBBBBBBBBBBBBBBBBBBBBBBBB -BBDBBBBBBBBBBBBBBBBBBBBDBBB- -------------EEE--E---------- ------------EEEEE------------ -------------EEE------------- --------------E-------------- ----------------------------- ----------------------------- 
-AAAAAAAAAAAAAAAAAAAAAAAAAAA- -AAAAAAAAAAAAAAAAAAAAAAAAAAA- -AAAAAAAAAAAAAAAAAAAAAAAAAAA- -AAAAAAAAAAAAAAAAAAAAAAAAAAC- -AAAAAAAAAAAAAAAAAAAAAAAAAAA- -CAAAAAAAAAAAAAAAAAAAAAAAAAA- -AAAAAAAAAAAAAAAAAAAAAAAAAAA- -AAAAAAAAAAAAAAAAAAAAAAAAAAA- -AAAAAAAAAAAAAAAAAAAAAAAAAAA- -CAAAAAAAAAAAAAAAAAAAAAAAAAA- -AAAAAAAAAAAAAAAAAAAAAAAAAAC- -AAAAAAAAAAAAAAAAAAAAAAAAAAAB BAAAAAAAAAAAAAAAAAAAAAAAAAAAB BBBBBBBBBBBBBBBBBBBBBBBBBBBBB -BBDBBBBDBBBBBBBBBBBBBDDDBBB- -----E--------E-------------- -------------E-E------------- --------------E-------------- ----------------------------- ----------------------------- ----------------------------- 
-AAAAAAAAAAAAAAAAAAAAAAAAAAA- -AAAAAAAAAAAAAAAAAAAAAAAAAAA- -AAAAAAAAAAAAAAAAAAAAAAAAAAA- -CAAAAAAAAAAAAAAAAAAAAAAAAAC- -CAAAAAAAAAAAAAAAAAAAAAAAAAA- -AAAAAAAAAAAAAAAAAAAAAAAAAAA- -AAAAAAAAAAAAAAAAAAAAAAAAAAA- -AAAAAAAAAAAAAAAAAAAAAAAAAAA- -CAAAAAAAAAAAAAAAAAAAAAAAAAA- -AAAAAAAAAAAAAAAAAAAAAAAAAAA- -AAAAAAAAAAAAAAAAAAAAAAAAAAC- BAAAAAAAAAAAAAAAAAAAAAAAAAAAB BAAAAAAAAAAAAAAAAAAAAAAAAAAAB BBBBBBBBBBBBBBBBBBBBBBBBBBBBB -BBDDBBBBBBBBBBBBBBBDDDDBBBB- ---------E------------------- ----------------------------- ----------------------------- ----------------------------- ----------------------------- ----------------------------- 
--AAAAAAAAAAAAAAAAAAAAAAAAA-- --AAAAAAAAAAAAAAAAAAAAAAAAA-- --AAAAAAAAAAAAAAAAAAAAAAAAA-- --CAAAAAAAAAAAAAAAAAAAAAAAC-- --AAAAAAAAAAAAAAAAAAAAAAAAA-- --AAAAAAAAAAAAAAAAAAAAAAAAA-- --AAAAAAAAAAAAAAAAAAAAAAAAA-- --AAAAAAAAAAAAAAAAAAAAAAAAA-- --CAAAAAAAAAAAAAAAAAAAAAAAA-- --AAAAAAAAAAAAAAAAAAAAAAAAA-- --AAAAAAAAAAAAAAAAAAAAAAAAA-- --AAAAAAAAAAAAAAAAAAAAAAAAA-- -BAAAAAAAAAAAAAAAAAAAAAAAAAB- -BBBBBBBBBBBBBBBBBBBBBBBBBBB- --BBDDBBBBBBBBBBBBDDDBBBBDB-- ----------------------------- ----------------------------- ----------------------------- ----------------------------- ----------------------------- ----------------------------- 
--AAAAAAAAAAAAAAAAAAAAAAAAA-- --AAAAAAAAAAAAAAAAAAAAAAAAA-- --CAAAAAAAAAAAAAAAAAAAAAAAA-- --AAAAAAAAAAAAAAAAAAAAAAAAA-- --AAAAAAAAAAAAAAAAAAAAAAAAC-- --AAAAAAAAAAAAAAAAAAAAAAAAA-- --CAAAAAAAAAAAAAAAAAAAAAAAA-- --CAAAAAAAAAAAAAAAAAAAAAAAA-- --AAAAAAAAAAAAAAAAAAAAAAAAA-- --AAAAAAAAAAAAAAAAAAAAAAAAA-- -BAAAAAAAAAAAAAAAAAAAAAAAAA-- -BAAAAAAAAAAAAAAAAAAAAAAAAAB- -BAAAAAAAAAAAAAAAAAAAAAAAAAB- -BBBBBBBBBBBBBBBBBBBBBBBBBBB- --BBBDDBDBBBBBBBBDDBBBBBBBB-- ----------------------------- ----------------------------- ----------------------------- ----------------------------- ----------------------------- ----------------------------- 
--AAAAAAAAAAAAAAAAAAAAAAAAC-- --CAAAAAAAAAAAAAAAAAAAAAAAA-- --AAAAAAAAAAAAAAAAAAAAAAAAA-- --AAAAAAAAAAAAAAAAAAAAAAAAA-- --AAAAAAAAAAAAAAAAAAAAAAAAA-- --CAAAAAAAAAAAAAAAAAAAAAAAC-- --AAAAAAAAAAAAAAAAAAAAAAAAA-- --AAAAAAAAAAAAAAAAAAAAAAAAA-- --AAAAAAAAAAAAAAAAAAAAAAAAA-- -BCAAAAAAAAAAAAAAAAAAAAAAAA-- -BAAAAAAAAAAAAAAAAAAAAAAAAA-- -BAAAAAAAAAAAAAAAAAAAAAAAAA-- -BAAAAAAAAAAAAAAAAAAAAAAAAAB- -BBBBBBBBBBBBBBBBBBBBBBBBBBB- --BBBBBBBBBBBBBBBBBBDBBBBBB-- -----------------------E----- ----------------------------- ----------------------------- ----------------------------- ----------------------------- ----------------------------- 
---CAAAAAAAAAAAAAAAAAAAAAC--- ---AAAAAAAAAAAAAAAAAAAAAAC--- ---AAAAAAAAAAAAAAAAAAAAAAA--- ---AAAAAAAAAAAAAAAAAAAAAAA--- ---CAAAAAAAAAAAAAAAAAAAAAA--- ---CAAAAAAAAAAAAAAAAAAAAAC--- ---AAAAAAAAAAAAAAAAAAAAAAC--- ---AAAAAAAAAAAAAAAAAAAAAAA--- ---CAAAAAAAAAAAAAAAAAAAAAA--- ---CAAAAAAAAAAAAAAAAAAAAAA--- ---AAAAAAAAAAAAAAAAAAAAAAA--- ---AAAAAAAAAAAAAAAAAAAAAAA--- --BAAAAAAAAAAAAAAAAAAAAAAAB-- --BBBBBBBBBBBBBBBBBBBBBBBBB-- ---BBBDBBBBBBBBBBBBDDBBBBB--- --------E-------------------- ----------------------------- ----------------------------- ----------------------------- ----------------------------- ----------------------------- 
----AAAAAAAAAAAAAAAAAAAAA---- ----AAAAAAAAAAAAAAAAAAAAC---- ----AAAAAAAAAAAAAAAAAAAAA---- ----AAAAAAAAAAAAAAAAAAAAA---- ----CAAAAAAAAAAAAAAAAAAAA---- ----AAAAAAAAAAAAAAAAAAAAA---- ----AAAAAAAAAAAAAAAAAAAAC---- ----AAAAAAAAAAAAAAAAAAAAA---- ----CAAAAAAAAAAAAAAAAAAAA---- ----AAAAAAAAAAAAAAAAAAAAA---- ----AAAAAAAAAAAAAAAAAAAAA---- ----AAAAAAAAAAAAAAAAAAAAA---- ---BAAAAAAAAAAAAAAAAAAAAAB--- --BBBBBBBBBBBBBBBBBBBBBBBBB-- ----BBBBBBBDBBBBBBBBBBDDB---- --------------E--E----------- ----------------------------- ----------------------------- ----------------------------- ----------------------------- ----------------------------- 
----AAAAAAAAAAAAAAAAAAAAA---- ----AAAAAAAAAAAAAAAAAAAAA---- ----CAAAAAAAAAAAAAAAAAAAC---- ----CAAAAAAAAAAAAAAAAAAAC---- ----AAAAAAAAAAAAAAAAAAAAA---- ----AAAAAAAAAAAAAAAAAAAAA---- ----AAAAAAAAAAAAAAAAAAAAA---- ----CAAAAAAAAAAAAAAAAAAAC---- ----AAAAAAAAAAAAAAAAAAAAC---- ----AAAAAAAAAAAAAAAAAAAAA---- ----AAAAAAAAAAAAAAAAAAAAA---- ---BAAAAAAAAAAAAAAAAAAAAA---- ---BAAAAAAAAAAAAAAAAAAAAAB--- ---BBBBBBBBBBBBBBBBBBBBBBB--- ----BBBBBDBBBBBBBBBBBDDBB---- -------------------E--------- ----------------------------- ----------------------------- ----------------------------- ----------------------------- ----------------------------- 
-----AAAAAAAAAAAAAAAAACA----- -----CCAAAAAAAAAAAAAAAAA----- -----CAAAAAAAAAAAAAAAAAA----- -----AAAAAAAAAAAAAAAAAAC----- -----AAAAAAAAAAAAAAAAAAC----- -----ACAAAAAAAAAAAAAAACA----- -----CAAAAAAAAAAAAAAAAAA----- -----CAAAAAAAAAAAAAAAAAA----- -----AAAAAAAAAAAAAAAAAAC----- -----AAAAAAAAAAAAAAAAACA----- -----ACAAAAAAAAAAAAAAAAA----- -----CAAAAAAAAAAAAAAAAAA----- ----BAAAAAAAAAAAAAAAAAAAB---- ----BBBBBBBBBBBBBBBBBBBBB---- -----BBBBBBBDBDBBBBDDDBB----- ----------------------------- ----------------------------- ----------------------------- ----------------------------- ----------------------------- ----------------------------- 
-------CAAAAAAAAAAAAAC------- -------AAAAAAAAAAAAAAA------- -------AAAAAAAAAAAAAAA------- -------AAAAAAAAAAAAAAA------- -------CAAAAAAAAAAAAAA------- -------CAAAAAAAAAAAAAC------- -------AAAAAAAAAAAAAAC------- -------AAAAAAAAAAAAAAA------- -------AAAAAAAAAAAAAAA------- -------CAAAAAAAAAAAAAA------- -------CAAAAAAAAAAAAAA-B----- ------BAAAAAAAAAAAAAAA-B----- -----BBAAAAAAAAAAAAAAABB----- -----BBBBBBBBBBBBBBBBBBB----- -------BBBBBBBDDBBDDBB------- ----------------------------- ----------------------------- ----------------------------- ----------------------------- ----------------------------- ----------------------------- 
--------AAAAAAAAAAAAC-------- --------AACAAAAAAAACA-------- --------ACAAAAAAAACAA-------- --------ACAAAAAAAAAAA-------- --------CAAAAAAAAAAAA-------- --------AAAAAAAAAAAAA-------- --------AAAAAAAAAAAAC-------- --------AACAAAAAAAACA-------- --------CCAAAAAAAACAA-------- --------CAAAAAAAAAAAA-------- -------BAAAAAAAAAAAAA-------- -------BAAAAAAAAAAAAAB------- -------BAAAAAAAAAAAAAB------- ------BBBBBBBBBBBBBBBBB------ --------BBBBBBBDDDBBB-------- ------------E---------------- ----------------------------- ----------------------------- ----------------------------- ----------------------------- ----------------------------- 
-----------AACAAAA----------- -----------CCAAAAA----------- -----------AAAAAAC----------- -----------AAAACCA----------- -----------AAACAAA----------- -----------ACCAAAA----------- -----------CAAAAAA----------- -----------CAAAAAA----------- -----------AAAAAAC----------- -----------AAAAACA----------- -----------AAAACAA----------- ---------BBAAAAAAABB--------- --------BBBAAAAAAABBB-------- --------BBBBBBBBBBBBB-------- -----------BBBBBBB----------- ----------------------------- ----------------------------- ----------------------------- ----------------------------- ----------------------------- ----------------------------- 
----------------------------- ----------------------------- ----------------------------- ----------------------------- ----------------------------- ----------------------------- ----------------------------- ----------------------------- ----------------------------- ----------------------------- -------------B--------------- ------------BBB-------------- -----------BBBBBBB----------- -----------BBBBBBB----------- ----------------------------- ----------------------------- ----------------------------- ----------------------------- ----------------------------- ----------------------------- ----------------------------- 
