model
size = 10 10 9, scale = 0.05, origin = -y
material 
  colors = A:#444 B:#699 C:#888 D:#F9C E:#777 F:#999 G:#222 H:#111 I:#E00 J:#960
voxels
-B-------- ---------- ---------- ---------- ---------- ---------- ---------- ---------- ---------- ---------- 
DD-------- ---------- ---------- ---------- ---------- ---------- ---------- ---------- ---------- ---------- 
D----AAA-- -----AA--- ---------- ------BBA- ------B--- ---------- ---------- ---------- -----A---- -----A---- 
DD--AAA--- ----AAA--- ----AAA--- -----AA--- -----AA--- ------A--- ---------- ------BF-- -----ABF-- -----A---- 
-DDAAACE-- ---AAACE-- ---AAACE-- ---AAAC--- ----AAA--- ----AAA--- ----AABA-- -----AI--- -----ABF-- ---------- 
---AAACE-- ---AAACE-- ---AAACE-- ---AAACE-- ---GAAC--- ---GAAA--- ---JAAAA-- ----AAGAAD ----AABB-- ---------- 
----AAC--- ----AAC--- ----AAC--- ----AAA--- ----AAA--- ----AAA--- -----AAA-- -----AH--- -----AA--- ---------- 
-----AAA-- -----AA--- ---------- ------AHA- ------A--- ------A--- ---------- ---------- -----B---- -----B---- 
---------- ---------- ---------- ---------- ---------- ---------- ---------- ---------- -----A---- -----B---- 
