model
size = 13 21 13, scale = 0.05, origin = -y
material 
  colors = A:#03C B:#888 C:#B00 D:#EEE E:#DDD F:#AAA G:#555
voxels
------------- ----BBBBB---- ----AAAAA---- ----BABBB---- ----AAAAA---- ----BBABB---- ----AAAAA---- ----DDDDD---- ----AAAAA---- ----AAAAA---- ----ADDDA---- ----ADAAA---- ----ACCCA---- ----AAAAA---- ----AAAAA---- ----DDDDD---- ----CCCCC---- ----ECFFF---- ----CCCCC---- ----BBBBB---- ------------- 
----BBBBB---- --BBBBBBBBB-- --AAAAAAAAA-- --AAAAAAAAA-- --AAAAAAAAA-- --AAAAAAAAA-- --AAAAAAAAA-- --DDAAAAADD-- --AAAAAAAAA-- --AAAAAAAAA-- --AAAAAAAAA-- --AAAAAAAAA-- --AAAAAAAAA-- --AAAAAAAAA-- --AAAAAAAAA-- --DDAAAAADD-- --CCCCCCCCC-- --EEECCCCCE-- --CCCCCCCCC-- --BBBBBBBBB-- ----BBBBB---- 
---BBBBBBB--- -BBBBBBBBBBB- -AAAAAAAAAAA- -AAAAAAAAAAA- -AAAAAAAAAAA- -AAAAAAAAAAA- -AAAAAAAAAAA- -DAAAAAAAAAD- -AAAAAAAAAAA- -AAAAAAAAAAA- -AAAAAAAAAAA- -AAAAAAAAAAA- -AAAAAAAAAAA- -AAAAAAAAAAA- -AAAAAAAAAAA- -DAAAAAAAAAD- -CCCCCCCCCCC- -EEEECCCCCCC- -CCACCCCCCCC- -BBBBBGBBBBB- ---B-----B--- 
--BBBBBBBBB-- -BBBBBBBBBBB- -AAAAAAAAAAA- -AAAAAAAAAAA- -AAAAAAAAAAA- -AAAAAAAAAAA- -AAAAAAAAAAA- -DAAAAAAAAAD- -AAAAAAAAAAA- -AAAAAAAAAAA- -AAAAAAAAAAA- -AAAAAAAAAAA- -AAAAAAAAAAA- -AAAAAAAAAAA- -AAAAAAAAAAA- -DAAAAAAAAAD- -CCCCCCCCCCC- -CCACCCCCCCC- -CCACCCCCCCC- -BBBBGBGBBBB- --B-------B-- 
-BBBBBBBBBBB- BBBBBBBBBBBBB AAAAAAAAAAAAA AAAAAAAAAAAAB AAAAAAAAAAAAA BAAAAAAAAAAAB AAAAAAAAAAAAA DAAAAAAAAAAAD AAAAAAAAAAAAA BAAAAAAAAAAAB AAAAAAAAAAAAA AAAAAAAAAAAAB BAAAAAAAAAAAA BAAAAAAAAAAAA AAAAAAAAAAAAA DAAAAAAAAAAAD CCCCCCCCCCCCC CCCACCCCCCCEF CCCACCCCCCCCC BBBBBGGGBBBBB -B---------B- 
-BBBBBBBBBBB- BBBBBBBBBBBBB AAAAAAAAAAAAA BAAAAAAAAAAAA AAAAAAAAAAAAB BAAAAAAAAAAAA AAAAAAAAAAAAA DAAAAAAAAAAAD AAAAAAAAAAAAA AAAAAAAAAAAAB BAAAAAAAAAAAB BAAAAAAAAAAAB AAAAAAAAAAAAB BAAAAAAAAAAAA AAAAAAAAAAAAA DAAAAAAAAAAAD CCCCCCCACCCCC CCCAAAAACCCEF CCCAAAAACCCCC BBBBBBBBBBBBB -B----B----B- 
-BBBBB-BBBBB- BBBBBBBBBBBBB AAAAAAAAAAAAA AAAAAAAAAAAAB BAAAAAAAAAAAA AAAAAAAAAAAAB AAAAAAAAAAAAA DAAAAAAAAAAAD AAAAAAAAAAAAA AAAAAAAAAAAAA BAAAAAAAAAAAA BAAAAAAAAAAAB AAAAAAAAAAAAB AAAAAAAAAAAAB AAAAAAAAAAAAA DAAAAAAAAAAAD CCCCCCCACCCCC FCCAAAAACCCEF CCCAAAAACCCCC BBBBBBBBBBBBB -B---B-B---B- 
-BBBBBBBBBBB- BBBBBBBBBBBBB AAAAAAAAAAAAA BAAAAAAAAAAAA AAAAAAAAAAAAB BAAAAAAAAAAAA AAAAAAAAAAAAA DAAAAAAAAAAAD AAAAAAAAAAAAA BAAAAAAAAAAAB AAAAAAAAAAAAB AAAAAAAAAAAAB BAAAAAAAAAAAB BAAAAAAAAAAAA AAAAAAAAAAAAA DAAAAAAAAAAAD CCCCCCCACCCCC CCCAAAAACCCEF CCCAAAAACCCCC BBBBBBBBBBBBB -B---BBB---B- 
-BBBBBBBBBBB- BBBBBBBBBBBBB AAAAAAAAAAAAA AAAAAAAAAAAAB AAAAAAAAAAAAA BAAAAAAAAAAAB AAAAAAAAAAAAA DAAAAAAAAAAAD AAAAAAAAAAAAA BAAAAAAAAAAAB BAAAAAAAAAAAA AAAAAAAAAAAAB BAAAAAAAAAAAA BAAAAAAAAAAAA AAAAAAAAAAAAA DAAAAAAAAAAAD CCCCCCCCCCCCC FCCCCCCCCCCEF CCCCCCCCCCCCC BBBBBBBBBBBBB -B---B-B---B- 
--BBBBBBBBB-- -BBBBBBBBBBB- -AAAAAAAAAAA- -AAAAAAAAAAA- -AAAAAAAAAAA- -AAAAAAAAAAA- -AAAAAAAAAAA- -DAAAAAAAAAD- -AAAAAAAAAAA- -AAAAAAAAAAA- -AAAAAAAAAAA- -AAAAAAAAAAA- -AAAAAAAAAAA- -AAAAAAAAAAA- -AAAAAAAAAAA- -DAAAAAAAAAD- -CCCCCCCCCCC- -CCCCCCCCCFF- -CCCCCCCCCCC- -BBBBBBBBBBB- --B---B---B-- 
---BBBBBBB--- -BBBBBBBBBBB- -AAAAAAAAAAA- -AAAAAAAAAAA- -AAAAAAAAAAA- -AAAAAAAAAAA- -AAAAAAAAAAA- -DAAAAAAAAAD- -AAAAAAAAAAA- -AAAAAAAAAAA- -AAAAAAAAAAA- -AAAAAAAAAAA- -AAAAAAAAAAA- -AAAAAAAAAAA- -AAAAAAAAAAA- -DAAAAAAAAAD- -CCCCCCCCCCC- -ECCCCCCCCFF- -CCCCCCCCCCC- -BBBBBBBBBBB- ---B-----B--- 
----BBBBB---- --BBBBBBBBB-- --AAAAAAAAA-- --ADDDDDDDA-- --ADDDDDDDA-- --ADDDDDDDA-- --AAAAAAAAA-- --DDAAAAADD-- --AAAAAAAAA-- --ADDDDDDDA-- --ADDDDDDDA-- --ADDDDDDDA-- --ADDDDDDDA-- --ADDDDDDDA-- --AAAAAAAAA-- --DDAAAAADD-- --CCCCCCCCC-- --EEEEECCCF-- --CCCCCCCCC-- --BBBBBBBBB-- ----BBBBB---- 
------------- ----BBBBB---- ----AAAAA---- ----DDDDD---- ----BBBBB---- ----DDDDD---- ----AAAAA---- ----DDDDD---- ----AAAAA---- ----DDDDD---- ----BBBBB---- ----BFBFB---- ----BBBBB---- ----DDDDD---- ----AAAAA---- ----DDDDD---- ----CCCCC---- ----EEEEC---- ----CCCCC---- ----BBBBB---- ------------- 
