model
size = 28 30 28, scale = 0.05, origin = -y
material 
  colors = A:#EEE B:#CC6 C:#111 D:#555 E:#F0C F:#3CF G:#F06 H:#FC9 I:#FF3 J:#F63 K:#CFF L:#CCC M:#F9F N:#CC9 O:#FF6 P:#F9C Q:#F3F R:#FF0 S:#F30 T:#FCF U:#F90 V:#FFC W:#FC0 X:#F99 Y:#CCF Z:#FC3 Aa:#F0F Ab:#CF3 Ac:#F66 Ad:#CFC Ae:#F39 Af:#CC0 Ag:#FF9 Ah:#F36 Ai:#F6C Aj:#F03 Ak:#FFF Al:#F09 Am:#F96 An:#F69 Ao:#F60 Ap:#F00 Aq:#F3C Ar:#F33 As:#CF6 At:#CC3 Au:#CF9 Av:#F93 Aw:#FCC Ax:#CF0 Ay:#FC6 Az:#F6F
voxels
D D D D D D D D D D D D D D D D D D D D D D D D D D D D   D A A A A A A A A A A A A A A A A A A A A A A A A A A D   D A A A A A A A A A A A A A A A A A A A A A A A A A A D   D A A A A A A A A A A A A A A A A A A A A A A A A A A D   D A A A A A A A A A A A A A A A A A A A A A A A A A A D   D A A A A A A A A A A A A A A A A A A A A A A A A A A D   D A A A A A A A A A A A A A A A A A A A A A A A A A A D   D A A A A A A A A A A A A A A A A A A A A A A A A A A D   D A A A A A A A A A A A A A A A A A A A A A A A A A A D   D A A A A A A A A A A A A A A A A A A A A A A A A A A D   D A A A A A A A A A A A A A A A A A A A A A A A A A A D   D A A A A A A A A A A A A A A A A A A A A A A A A A A D   D A A A A A A A A A A A A A A A A A A A A A A A A A A D   D A A A A A A A A A A A A A A A A A A A A A A A A A A D   D A A A A A A A A A A A A A A A A A A A A A A A A A A D   D A A A A A A A A A A A A A A A A A A A A A A A A A A D   D A A A A A A A A A A A A A A A A A A A A A A A A A A D   D A A A A A A A A A A A A A A A A A A A A A A A A A A D   D A A A A A A A A A A A A A A A A A A A A A A A A A A D   D A A A A A A A A A A A A A A A A A A A A A A A A A A D   D A A A A A A A A A A A A A A A A A A A A A A A A A A D   D A A A A A A A A A A A A A A A A A A A A A A A A A A D   D A A A A A A A A A A A A A A A A A A A A A A A A A A D   D A A A A A A A A A A A A A A A A A A A A A A A A A A D   D A A A A A A A A A A A A A A A A A A A A A A A A A A D   D A A A A A A A A A A A A A A A A A A A A A A A A A A D   D A A A A A A A A A A A A A A A A A A A A A A A A A A D   D D D D D D D D D D D D D D D D D D D D D D D D D D D D   - - - - - - - - - - - - - - - - - - - - - - - - - - - -   - - - - - - - - - - - - - - - - - - - - - - - - - - - -   
D A A A A A A A A A A A A A A A A A A A A A A A A A A D   A A A A A A A A A A A A A A A A A A A A A A A A A A A A   A A A A A A A A A A A A A A A A A A A A A A A A A A A A   A A A A A A A A A A A A A A A A A A A A A A A A A A A A   A A A A A A A A A A A A A A A A A A A A A A A A A A A A   A A A A A A A A A A A A A A A A A A A A A A A A A A A A   A A A A A A A A A A A A A A A A A A A A A A A A A A A A   A A A A A A A A A A A A A A A A A A A A A A A A A A A A   A A A A A A A A A A A A A A A A A A A A A A A A A A A A   A A A A A A A A A A A A A A A A A A A A A A A A A A A A   A A A A A A A A A A A A A A A A A A A A A A A A A A A A   A A A A A A A A A A A A A A A A A A A A A A A A A A A A   A A A A A A A A A A A A A A A A A A A A A A A A A A A A   A A A A A A A A A A A A A A A A A A A A A A A A A A A A   A A A A A A A A A A A A A A A A A A A A A A A A A A A A   A A A A A A A A A A A A A A A A A A A A A A A A A A A A   A A A A A A A A A A A A A A A A A A A A A A A A A A A A   A A A A A A A A A A A A A A A A A A A A A A A A A A A A   A A A A A A A A A A A A A A A A A A A A A A A A A A A A   A A A A A A A A A A A A A A A A A A A A A A A A A A A A   A A A A A A A A A A A A A A A A A A A A A A A A A A A A   A A A A A A A A A A A A A A A A A A A A A A A A A A A A   A A A A A A A A A A A A A A A A A A A A A A A A A A A A   A A A A A A A A A A A A A A A A A A A A A A A A A A A A   A A A A A A A A A A A A A A A A A A A A A A A A A A A A   A A A A A A A A A A A A A A A A A A A A A A A A A A A A   A A A A A A A A A A A A A A A A A A A A A A A A A A A A   D A A A A A A A A A A A A A A A A A A A A A A A A A A D   - - - - - - - - - - - - - - - - - - - - - - - - - - - -   - - - - - - - - - - - - - - - - - - - - - - - - - - - -   
D A A A A A A A A A A A A A A A A A A A A A A A A A A D   A A A A A A A A A A A A A A A A A A A A A A A A A A A A   A A A A A A A A A A A A A A A A A A A A A A A A A A A A   A A A A A A A A A A A A A A A A A A A A A A A A A A A A   A A A A A A A A A A A A A A A A A A A A A A A A A A A A   A A A A A A A A A A A A A A A A A A A A A A A A A A A A   A A A A A A A A A A A A A A A A A A A A A A A A A A A A   A A A A A A A A A A A A A A A A A A A A A A A A A A A A   A A A A A A A A A A A A A A A A A A A A A A A A A A A A   A A A A A A A A A A A A A A A A A A A A A A A A A A A A   A A A A A A A A A A A A A A A A A A A A A A A A A A A A   A A A A A A A A A A A A A A A A A A A A A A A A A A A A   A A A A A A A A A A A A A A A A A A A A A A A A A A A A   A A A A A A A A A A A A A A A A A A A A A A A A A A A A   A A A A A A A A A A A A A A A A A A A A A A A A A A A A   A A A A A A A A A A A A A A A A A A A A A A A A A C - -   A A A A A A A A A A A A A A A A A A A A A A A A A C - -   A A A A A A A A A A A A A A A A A A A A A A A A A C - -   A A A A A A A A A A A A A A A A A A A A A A A A A C - -   A A A A A A A A A A A A A A A A A A A A A A A A A C - -   A A A A A A A A A A A A A A A A A A A A A A A A A C - -   A A A A A A A A A A A A A A A A A A A A A A A A A C - -   A A A A A A A A A A A A A A A A A A A A A A A A A C - -   A A A A A A A A A A A A A A A A A A A A A A A A A C - -   A A A A A A A A A A A A A A A A A A A A A A A A A A A A   A A A A A A A A A A A A A A A A A A A A A A A A A A A A   A A A A A A A A A A A A A A A A A A A A A A A A A A A A   D A A A A A A A A A A A A A A A A A A A A A A A A A A D   - - - - - - - - - - - - - - - - - - - - - - - - - - - -   - - - - - - - - - - - - - - - - - - - - - - - - - - - -   
D A A A A A A A A A A A A A A A A A A A A A A A A A A D   A A A A B B B B B B B B B B B B B B B B B B B B A A A A   A A A A B B B B B B B B B B B B B B B B B B B B A A A A   A A A A B B B B B B B B B B B B B B B B B B B B A A A A   A A A A B B B B B B B B B B B B B B B B B B B B A A A A   A A A A B B B B B B B B B B B B B B B B B B B B A A A A   A A A A B B B B B B B B B B B B B B B B B B B B A A A A   A A A A B B B B B B B B B B B B B B B B B B B B A A A A   A A A A B B B B B B B B B B B B B B B B B B B B A A A A   A A A A B B B B B B B B B B B B B B B B B B B B A A A A   A A A A B B B B B B B B B B B B B B B B B B B B A A A A   A A A A B B B B B B B B B B B B B B B B B B B B A A A A   A A A A B B B B B B B B B B B B B B B B B B B B A A A A   A A A A B B B B B B B B B B B B B B B B B B B B A A A A   A A A A B B B B B B B B B B B B B B B B B B B B A C - -   A A A A B B B B B B B B B B B B B B B B B B B B A C - -   A A A A B B B B B B B B B B B B B B B B B B B B A C - -   A A A A B B B B B B B B B B B B B B B B B B B B A C - -   A A A A A A A A A A A A A A A A A A A A A A A A A C - -   A A A A A A A A A A A A A A A A A A A A A A A A A C - -   A A A A A A A A A A A A A A A A A A A A A A A A A C - -   A A A A A A A A A A A A A A A A A A A A A A A A A C - -   A A A A A A A A A A A A A A A A A A A A A A A A A C - -   A A A A A A A A A A A A A A A A A A A A A A A A A C - -   A A A A A A A A A A A A A A A A A A A A A A A A A C - -   A A A A A A A A A A A A A A A A A A A A A A A A A A A A   A A A A A A A A A A A A A A A A A A A A A A A A A A A A   D A A A A A A A A A A A A A A A A A A A A A A A A A A D   - - - - - - - - - - - - - - - - - - - - - - - - - - - -   - - - - - - - - - - - - - - - - - - - - - - - - - - - -   
D A A A - - - - - - - - - - - - - - - - - - - - A A A D   A A A B - - - - - - - - - - - - - - - - - - - - B A C -   A A A B - - - - - - - - - - - - - - - - - - - - B A C -   A A A B - - - - - - - - - - - - - - - - - - - - B A C -   A A A B - - - - - - - - - - - - - - - - - - - - B A C -   A A A B - - - - - - - - - - - - - - - - - - - - B A C -   A A A B - - - - - - - - - - - - - - - - - - - - B A C -   A A A B - - - - - - - - - - - - - - - - - - - - B A C -   A A A B - - - - - - - - - - - - - - - - - - - - B A A A   A A A B - - - - - - - - - - - - - - - - - - - - B A A A   A A A B - - - - - - - - - - - - - - - - - - - - B A A A   A A A B - - - - - - - - - - - - - - - - - - - - B A A A   A A A B - - - - - - - - - - - - - - - - - - - - B A A A   A A A B - - - - - - - - - - - - - - - - - - - - B C - -   A A A B - - - - - - - - - - - - - - - - - - - - B C - -   A A A B - - - - - - - - - - - - - - - - - - - - B C - -   A A A B - - - - - - - - - - - - - - - - - - - - B C - -   A A A B - - - - - - - - - - - - - - - - - - - - B C - -   A A A A X AwQ I P ArAaR AoY K AiW AaS H J H H AdA C - -   A A A A A A A A A A A A A A A A A A A A A A A A A C - -   A A A A A A A A A A A A A A A A A A A A A A A A A C - -   A A A A A A A A A A A A A A A A A A A A A A A A A C - -   A A A A A A A A A A A A A A A A A A A A A A A A A C - -   A A A A A A A A A A A A A A A A A A A A A A A A A C - -   A A A A A A A A A A A A A A A A A A A A A A A A A C - -   A A A A A A A A A A A A A A A A A A A A A A A A A C - -   A A A A A A A A A A A A A A A A A A A A A A A A A A A A   D A A A A A A A A A A A A A A A A A A A A A A A A A A D   - - - - - - - - - - - - - - - - - - - - - - - - - - - -   - - - - - - - - - - - - - - - - - - - - - - - - - - - -   
D A A A - - - - - - - - - - - - - - - - - - - - A A A D   A A A B - - - - - - - - - - - - - - - - - - - - B A A A   A A A B - - - - - - - - - - - - - - - - - - - - B A A A   A A A B - - - - - - - - - - - - - - - - - - - - B A A A   A A A B - - - - - - - - - - - - - - - - - - - - B A A A   A A A B - - - - - - - - - - - - - - - - - - - - B A A A   A A A B - - - - - - - - - - - - - - - - - - - - B A A A   A A A B - - - - - - - - - - - - - - - - - - - - B A C -   A A A B - - - - - - - - - - - - - - - - - - - - B A A A   A A A B - - - - - - - - - - - - - - - - - - - - B A A A   A A A B - - - - - - - - - - - - - - - - - - - - B A A A   A A A B - - - - - - - - - - - - - - - - - - - - B A A A   A A A B - - - - - - - - - - - - - - - - - - - - B A A A   A A A B - - - - - - - - - - - - - - - - - - - - B C - -   A A A B - - - - - - - - - - - - - - - - - - - - B C - -   A A A B - - - - - - - - - - - - - - - - - - - - B C - -   A A A B - - - - - - - - - - - - - - - - - - - - B C - -   A A A B - - - - - - - - - - - - - - - - - - - - B C - -   A A A A I O X N U AzT AwP J AtU AmI AzJ J R AsApA C - -   A A A A A A A A A A A A A A A A A A A A A A A A A C - -   A A A A A A A A A A A A A A A A A A A A A A A A A C - -   A A A A A A A A A A A A A A A A A A A A A A A A A C - -   A A A A A A A A A A A A A A A A A A A A A A A A A C - -   A A A A A A A A A A A A A A A A A A A A A A A A A C - -   A A A A A A A A A A A A A A A A A A A A A A A A A C - -   A A A A A A A A A A A A A A A A A A A A A A A A A C - -   A A A A A A A A A A A A A A A A A A A A A A A A A A A A   D A A A A A A A A A A A A A A A A A A A A A A A A A A D   - - - - - - - - - - - - - - - - - - - - - - - - - - - -   - - - - - - - - - - - - - - - - - - - - - - - - - - - -   
D A A A - - - - - - - - - - - - - - - - - - - - A A A D   A A A B - - - - - - - - - - - - - - - - - - - - B A A A   A A A B - - - - - - - - - - - - - - - - - - - - B A A A   A A A B - - - - - - - - - - - - - - - - - - - - B A A A   A A A B - - - - - - - - - - - - - - - - - - - - B A A A   A A A B - - - - - - - - - - - - - - - - - - - - B A A A   A A A B - - - - - - - - - - - - - - - - - - - - B A A A   A A A B - - - - - - - - - - - - - - - - - - - - B A C -   A A A B - - - - - - - - - - - - - - - - - - - - B A A A   A A A B - - - - - - - - - - - - - - - - - - - - B A A A   A A A B - - - - - - - - - - - - - - - - - - - - B A A A   A A A B - - - - - - - - - - - - - - - - - - - - B A A A   A A A B - - - - - - - - - - - - - - - - - - - - B A A A   A A A B - - - - - - - - - - - - - - - - - - - - B C - -   A A A B - - - - - - - - - - - - - - - - - - - - B C - -   A A A B - - - - - - - - - - - - - - - - - - - - B C - -   A A A B - - - - - - - - - - - - - - - - - - - - B C - -   A A A B - - - - - - - - - - - - - - - - - - - - B C - -   A A A A N T AfV G AuAlO U J AxI ArAiP O Q L AcK A C - -   A A A A A A A A A A A A A A A A A A A A A A A A A C - -   A A A A A A A A A A A A A A A A A A A A A A A A A C - -   A A A A A A A A A A A A A A A A A A A A A A A A A C - -   A A A A A A A A A A A A A A A A A A A A A A A A A C - -   A A A A A A A A A A A A A A A A A A A A A A A A A C - -   A A A A A A A A A A A A A A A A A A A A A A A A A C - -   A A A A A A A A A A A A A A A A A A A A A A A A A C - -   A A A A A A A A A A A A A A A A A A A A A A A A A A A A   D A A A A A A A A A A A A A A A A A A A A A A A A A A D   - - - - - - - - - - - - - - - - - - - - - - - - - - - -   - - - - - - - - - - - - - - - - - - - - - - - - - - - -   
D A A A - - - - - - - - - - - - - - - - - - - - A A A D   A A A B - - - - - - - - - - - - - - - - - - - - B A A A   A A A B - - - - - - - - - - - - - - - - - - - - B A A A   A A A B - - - - - - - - - - - - - - - - - - - - B A A A   A A A B - - - - - - - - - - - - - - - - - - - - B A A A   A A A B - - - - - - - - - - - - - - - - - - - - B A A A   A A A B - - - - - - - - - - - - - - - - - - - - B A A A   A A A B - - - - - - - - - - - - - - - - - - - - B A C -   A A A B - - - - - - - - - - - - - - - - - - - - B A A A   A A A B - - - - - - - - - - - - - - - - - - - - B A A A   A A A B - - - - - - - - - - - - - - - - - - - - B A A A   A A A B - - - - - - - - - - - - - - - - - - - - B A A A   A A A B - - - - - - - - - - - - - - - - - - - - B A A A   A A A B - - - - - - - - - - - - - - - - - - - - B C - -   A A A B - - - - - - - - - - - - - - - - - - - - B C - -   A A A B - - - - - - - - - - - - - - - - - - - - B C - -   A A A B - - - - - - - - - - - - - - - - - - - - B C - -   A A A B - - - - - - - - - - - - - - - - - - - - B C - -   A A A A V AlN AhP O M T G Q AwAhAtY AaAdX T S H A C - -   A A A A A A A A A A A A A A A A A A A A A A A A A C F -   A A A A A A A A A A A A A A A A A A A A A A A A A C F -   A A A A A A A A A A A A A A A A A A A A A A A A A C - -   A A A A A A A A A A A A A A A A A A A A A A A A A C - -   A A A A A A A A A A A A A A A A A A A A A A A A A C - -   A A A A A A A A A A A A A A A A A A A A A A A A A C - -   A A A A A A A A A A A A A A A A A A A A A A A A A C - -   A A A A A A A A A A A A A A A A A A A A A A A A A A A A   D A A A A A A A A A A A A A A A A A A A A A A A A A A D   - - - - - - - - - - - - - - - - - - - - - - - - - - - -   - - - - - - - - - - - - - - - - - - - - - - - - - - - -   
D A A A - - - - - - - - - - - - - - - - - - - - A A A D   A A A B - - - - - - - - - - - - - - - - - - - - B A A A   A A A B - - - - - - - - - - - - - - - - - - - - B A A A   A A A B - - - - - - - - - - - - - - - - - - - - B A A A   A A A B - - - - - - - - - - - - - - - - - - - - B A A A   A A A B - - - - - - - - - - - - - - - - - - - - B A A A   A A A B - - - - - - - - - - - - - - - - - - - - B A A A   A A A B - - - - - - - - - - - - - - - - - - - - B A C -   A A A B - - - - - - - - - - - - - - - - - - - - B A A A   A A A B - - - - - - - - - - - - - - - - - - - - B A A A   A A A B - - - - - - - - - - - - - - - - - - - - B A A A   A A A B - - - - - - - - - - - - - - - - - - - - B A A A   A A A B - - - - - - - - - - - - - - - - - - - - B A A A   A A A B - - - - - - - - - - - - - - - - - - - - B C - -   A A A B - - - - - - - - - - - - - - - - - - - - B C - -   A A A B - - - - - - - - - - - - - - - - - - - - B C - -   A A A B - - - - - - - - - - - - - - - - - - - - B C - -   A A A B - - - - - - - - - - - - - - - - - - - - B C - -   A A A A AhAxG AkAbB W AlP X AlAvAeJ I ApAfB AzR A C F -   A A A A A A A A A A A A A A A A A A A A A A A A A C F -   A A A A A A A A A A A A A A A A A A A A A A A A A C F -   A A A A A A A A A A A A A A A A A A A A A A A A A C F -   A A A A A A A A A A A A A A A A A A A A A A A A A C - -   A A A A A A A A A A A A A A A A A A A A A A A A A C - -   A A A A A A A A A A A A A A A A A A A A A A A A A C - -   A A A A A A A A A A A A A A A A A A A A A A A A A C - -   A A A A A A A A A A A A A A A A A A A A A A A A A A A A   D A A A A A A A A A A A A A A A A A A A A A A A A A A D   - - - - - - - - - - - - - - - - - - - - - - - - - - - -   - - - - - - - - - - - - - - - - - - - - - - - - - - - -   
D A A A - - - - - - - - - - - - - - - - - - - - A A A D   A A A B - - - - - - - - - - - - - - - - - - - - B A C -   A A A B - - - - - - - - - - - - - - - - - - - - B A C -   A A A B - - - - - - - - - - - - - - - - - - - - B A C -   A A A B - - - - - - - - - - - - - - - - - - - - B A C -   A A A B - - - - - - - - - - - - - - - - - - - - B A C -   A A A B - - - - - - - - - - - - - - - - - - - - B A C -   A A A B - - - - - - - - - - - - - - - - - - - - B A C -   A A A B - - - - - - - - - - - - - - - - - - - - B A A A   A A A B - - - - - - - - - - - - - - - - - - - - B A A A   A A A B - - - - - - - - - - - - - - - - - - - - B A A A   A A A B - - - - - - - - - - - - - - - - - - - - B A A A   A A A B - - - - - - - - - - - - - - - - - - - - B A A A   A A A B - - - - - - - - - - - - - - - - - - - - B C - -   A A A B - - - - - - - - - - - - - - - - - - - - B C - -   A A A B - - - - - - - - - - - - - - - - - - - - B C - -   A A A B - - - - - - - - - - - - - - - - - - - - B C - -   A A A B - - - - - - - - - - - - - - - - - - - - B C F -   A A A A AkZ M AiAhAgG AxAbAfJ AuB J AiK N AeP L A C F -   A A A A A A A A A A A A A A A A A A A A A A A A A C F -   A A A A A A A A A A A A A A A A A A A A A A A A A C F -   A A A A A A A A A A A A A A A A A A A A A A A A A C F -   A A A A A A A A A A A A A A A A A A A A A A A A A C F -   A A A A A A A A A A A A A A A A A A A A A A A A A C - -   A A A A A A A A A A A A A A A A A A A A A A A A A C - -   A A A A A A A A A A A A A A A A A A A A A A A A A C - -   A A A A A A A A A A A A A A A A A A A A A A A A A A A A   D A A A A A A A A A A A A A A A A A A A A A A A A A A D   - - - - - - - - - - - - - - - - - - - - - - - - - - - -   - - - - - - - - - - - - - - - - - - - - - - - - - - - -   
D A A A - - - - - - - - - - - - - - - - - - - - A A A D   A A A B - - - - - - - - - - - - - - - - - - - - B A C -   A A A B - - - - - - - - - - - - - - - - - - - - B A C -   A A A B - - - - - - - - - - - - - - - - - - - - B A C -   A A A B - - - - - - - - - - - - - - - - - - - - B A C -   A A A B - - - - - - - - - - - - - - - - - - - - B A C -   A A A B - - - - - - - - - - - - - - - - - - - - B A C -   A A A B - - - - - - - - - - - - - - - - - - - - B A C -   A A A B - - - - - - - - - - - - - - - - - - - - B A A A   A A A B - - - - - - - - - - - - - - - - - - - - B A A A   A A A B - - - - - - - - - - - - - - - - - - - - B A A A   A A A B - - - - - - - - - - - - - - - - - - - - B A A A   A A A B - - - - - - - - - - - - - - - - - - - - B A A A   A A A B - - - - - - - - - - - - - - - - - - - - B C - -   A A A B - - - - - - - - - - - - - - - - - - - - B C - -   A A A B - - - - - - - - - - - - - - - - - - - - B C - -   A A A B - - - - - - - - - - - - - - - - - - - - B C - -   A A A B - - - - - - - - - - - - - - - - - - - - B C F -   A A A A AiAeAqB AnX ApZ AhN V V O Q Y H G Y AaT A C F -   A A A A A A A A A A A A A A A A A A A A A A A A A C F -   A A A A A A A A A A A A A A A A A A A A A A A A A C F -   A A A A A A A A A A A A A A A A A A A A A A A A A C F -   A A A A A A A A A A A A A A A A A A A A A A A A A C F -   A A A A A A A A A A A A A A A A A A A A A A A A A C - -   A A A A A A A A A A A A A A A A A A A A A A A A A C - -   A A A A A A A A A A A A A A A A A A A A A A A A A C - -   A A A A A A A A A A A A A A A A A A A A A A A A A A A A   D A A A A A A A A A A A A A A A A A A A A A A A A A A D   - - - - - - - - - - - - - - - - - - - - - - - - - - - -   - - - - - - - - - - - - - - - - - - - - - - - - - - - -   
D A A A - - - - - - - - - - - - - - - - - - - - A A A D   A A A B - - - - - - - - - - - - - - - - - - - - B A A A   A A A B - - - - - - - - - - - - - - - - - - - - B A A A   A A A B - - - - - - - - - - - - - - - - - - - - B A A A   A A A B - - - - - - - - - - - - - - - - - - - - B A A A   A A A B - - - - - - - - - - - - - - - - - - - - B A A A   A A A B - - - - - - - - - - - - - - - - - - - - B A A A   A A A B - - - - - - - - - - - - - - - - - - - - B A C -   A A A B - - - - - - - - - - - - - - - - - - - - B A A A   A A A B - - - - - - - - - - - - - - - - - - - - B A A A   A A A B - - - - - - - - - - - - - - - - - - - - B A A A   A A A B - - - - - - - - - - - - - - - - - - - - B A A A   A A A B - - - - - - - - - - - - - - - - - - - - B A A A   A A A B - - - - - - - - - - - - - - - - - - - - B C - -   A A A B - - - - - - - - - - - - - - - - - - - - B C - -   A A A B - - - - - - - - - - - - - - - - - - - - B C - -   A A A B - - - - - - - - - - - - - - - - - - - - B C - -   A A A B - - - - - - - - - - - - - - - - - - - - B C - -   A A A A B AgK AlW AuAgAeAnG E S L X J R M I I B A C F -   A A A A A A A A A A A A A A A A A A A A A A A A A C F -   A A A A A A A A A A A A A A A A A A A A A A A A A C F -   A A A A A A A A A A A A A A A A A A A A A A A A A C F -   A A A A A A A A A A A A A A A A A A A A A A A A A C - -   A A A A A A A A A A A A A A A A A A A A A A A A A C - -   A A A A A A A A A A A A A A A A A A A A A A A A A C - -   A A A A A A A A A A A A A A A A A A A A A A A A A C - -   A A A A A A A A A A A A A A A A A A A A A A A A A A A A   D A A A A A A A A A A A A A A A A A A A A A A A A A A D   - - - - - - - - - - - - - D - - - - - - - - - - - - - -   - - - - - - - - - - - - - D - - - - - - - - - - - - - -   
D A A A - - - - - - - - - - - - - - - - - - - - A A A D   A A A B - - - - - - - - - - - - - - - - - - - - B A A A   A A A B - - - - - - - - - - - - - - - - - - - - B A A A   A A A B - - - - - - - - - - - - - - - - - - - - B A A A   A A A B - - - - - - - - - - - - - - - - - - - - B A A A   A A A B - - - - - - - - - - - - - - - - - - - - B A A A   A A A B - - - - - - - - - - - - - - - - - - - - B A A A   A A A B - - - - - - - - - - - - - - - - - - - - B A C -   A A A B - - - - - - - - - - - - - - - - - - - - B A A A   A A A B - - - - - - - - - - - - - - - - - - - - B A A A   A A A B - - - - - - - - - - - - - - - - - - - - B A A A   A A A B - - - - - - - - - - - - - - - - - - - - B A A A   A A A B - - - - - - - - - - - - - - - - - - - - B A A A   A A A B - - - - - - - - - - - - - - - - - - - - B C - -   A A A B - - - - - - - - - - - - - - - - - - - - B C - -   A A A B - - - - - - - - - - - - - - - - - - - - B C - -   A A A B - - - - - - - - - - - - - - - - - - - - B C - -   A A A B - - - - - - - - - - - - - - - - - - - - B C - -   A A A A AlAmAjAnK Q AoAgW M AkM Z AfJ L AqH AiAeA C - -   A A A A A A A A A A A A A A A A A A A A A A A A A C F -   A A A A A A A A A A A A A A A A A A A A A A A A A C F -   A A A A A A A A A A A A A A A A A A A A A A A A A C - -   A A A A A A A A A A A A A A A A A A A A A A A A A C - -   A A A A A A A A A A A A A A A A A A A A A A A A A C - -   A A A A A A A A A A A A A A A A A A A A A A A A A C - -   A A A A A A A A A A A A A A A A A A A A A A A A A C - -   A A A A A A A A A A A A A A A A A A A A A A A A A A A A   D A A A A A A A A A A A A A A A A A A A A A A A A A A D   - - - - - - - - - - - - - - - - - - - - - - - - - - - -   - - - - - - - - - - - - - D - - - - - - - - - - - - - -   
D A A A - - - - - - - - - - - - - - - - - - - - A A A D   A A A B - - - - - - - - - - - - - - - - - - - - B A A A   A A A B - - - - - - - - - - - - - - - - - - - - B A A A   A A A B - - - - - - - - - - - - - - - - - - - - B A A A   A A A B - - - - - - - - - - - - - - - - - - - - B A A A   A A A B - - - - - - - - - - - - - - - - - - - - B A A A   A A A B - - - - - - - - - - - - - - - - - - - - B A A A   A A A B - - - - - - - - - - - - - - - - - - - - B A C -   A A A B - - - - - - - - - - - - - - - - - - - - B A A A   A A A B - - - - - - - - - - - - - - - - - - - - B A A A   A A A B - - - - - - - - - - - - - - - - - - - - B A A A   A A A B - - - - - - - - - - - - - - - - - - - - B A A A   A A A B - - - - - - - - - - - - - - - - - - - - B A A A   A A A B - - - - - - - - - - - - - - - - - - - - B C - -   A A A B - - - - - - - - - - - - - - - - - - - - B C - -   A A A B - - - - - - - - - - - - - - - - - - - - B C - -   A A A B - - - - - - - - - - - - - - - - - - - - B C - -   A A A B - - - - - - - - - - - - - - - - - - - - B C - -   A A A A AnAvAcL AgAxAaAmK AqAmAcO N Q T K I Y Y A C - -   A A A A A A A A A A A A A A A A A A A A A A A A A C - -   A A A A A A A A A A A A A A A A A A A A A A A A A C - -   A A A A A A A A A A A A A A A A A A A A A A A A A C - -   A A A A A A A A A A A A A A A A A A A A A A A A A C - -   A A A A A A A A A A A A A A A A A A A A A A A A A C - -   A A A A A A A A A A A A A A A A A A A A A A A A A C - -   A A A A A A A A A A A A A A A A A A A A A A A A A C - -   A A A A A A A A A A A A A A A A A A A A A A A A A A A A   D A A A A A A A A A A A A A A A A A A A A A A A A A A D   - - - - - - - - - - - - - - - - - - - - - - - - - - - -   - - - - - - - - - - - - - D - - - - - - - - - - - - - -   
D A A A - - - - - - - - - - - - - - - - - - - - A A A D   A A A B - - - - - - - - - - - - - - - - - - - - B A A A   A A A B - - - - - - - - - - - - - - - - - - - - B A A A   A A A B - - - - - - - - - - - - - - - - - - - - B A A A   A A A B - - - - - - - - - - - - - - - - - - - - B A A A   A A A B - - - - - - - - - - - - - - - - - - - - B A A A   A A A B - - - - - - - - - - - - - - - - - - - - B A A A   A A A B - - - - - - - - - - - - - - - - - - - - B A C -   A A A B - - - - - - - - - - - - - - - - - - - - B A A A   A A A B - - - - - - - - - - - - - - - - - - - - B A A A   A A A B - - - - - - - - - - - - - - - - - - - - B A A A   A A A B - - - - - - - - - - - - - - - - - - - - B A A A   A A A B - - - - - - - - - - - - - - - - - - - - B A A A   A A A B - - - - - - - - - - - - - - - - - - - - B C - -   A A A B - - - - - - - - - - - - - - - - - - - - B C - -   A A A B - - - - - - - - - - - - - - - - - - - - B C - -   A A A B - - - - - - - - - - - - - - - - - - - - B C - -   A A A B - - - - - - - - - - - - - - - - - - - - B C - -   A A A A L W L G R AxP AvAgK AoAyAbG X B AjAsJ I A C - -   A A A A A A A A A A A A A A A A A A A A A A A A A C - -   A A A A A A A A A A A A A A A A A A A A A A A A A C - -   A A A A A A A A A A A A A A A A A A A A A A A A A C - -   A A A A A A A A A A A A A A A A A A A A A A A A A C - -   A A A A A A A A A A A A A A A A A A A A A A A A A C - -   A A A A A A A A A A A A A A A A A A A A A A A A A C - -   A A A A A A A A A A A A A A A A A A A A A A A A A C - -   A A A A A A A A A A A A A A A A A A A A A A A A A A A A   D A A A A A A A A A A A A A A A A A A A A A A A A A A D   - - - - - - - - - - - - - - - - - - - - - - - - - - - -   - - - - - - - - - - - - - D - - - - - - - - - - - - - -   
D A A A - - - - - - - - - - - - - - - - - - - - A A A D   A A A B - - - - - - - - - - - - - - - - - - - - B A A A   A A A B - - - - - - - - - - - - - - - - - - - - B A A A   A A A B - - - - - - - - - - - - - - - - - - - - B A A A   A A A B - - - - - - - - - - - - - - - - - - - - B A A A   A A A B - - - - - - - - - - - - - - - - - - - - B A A A   A A A B - - - - - - - - - - - - - - - - - - - - B A A A   A A A B - - - - - - - - - - - - - - - - - - - - B A C -   A A A B - - - - - - - - - - - - - - - - - - - - B A A A   A A A B - - - - - - - - - - - - - - - - - - - - B A A A   A A A B - - - - - - - - - - - - - - - - - - - - B A A A   A A A B - - - - - - - - - - - - - - - - - - - - B A A A   A A A B - - - - - - - - - - - - - - - - - - - - B A A A   A A A B - - - - - - - - - - - - - - - - - - - - B C - -   A A A B - - - - - - - - - - - - - - - - - - - - B C - -   A A A B - - - - - - - - - - - - - - - - - - - - B C - -   A A A B - - - - - - - - - - - - - - - - - - - - B C - -   A A A B - - - - - - - - - - - - - - - - - - - - B C - -   A A A A G H AbQ AnT W W R AjY W AeM AfAeAcU J H A C - -   A A A A A A A A A A A A A A A A A A A A A A A A A C E -   A A A A A A A A A A A A A A A A A A A A A A A A A C E -   A A A A A A A A A A A A A A A A A A A A A A A A A C - -   A A A A A A A A A A A A A A A A A A A A A A A A A C - -   A A A A A A A A A A A A A A A A A A A A A A A A A C - -   A A A A A A A A A A A A A A A A A A A A A A A A A C - -   A A A A A A A A A A A A A A A A A A A A A A A A A C - -   A A A A A A A A A A A A A A A A A A A A A A A A A A A A   D A A A A A A A A A A A A A A A A A A A A A A A A A A D   - - - - - - - - - - - - - - - - - - - - - - - - - - - -   - - - - - - - - - - - - - D - - - - - - - - - - - - - -   
D A A A - - - - - - - - - - - - - - - - - - - - A A A D   A A A B - - - - - - - - - - - - - - - - - - - - B A A A   A A A B - - - - - - - - - - - - - - - - - - - - B A A A   A A A B - - - - - - - - - - - - - - - - - - - - B A A A   A A A B - - - - - - - - - - - - - - - - - - - - B A A A   A A A B - - - - - - - - - - - - - - - - - - - - B A A A   A A A B - - - - - - - - - - - - - - - - - - - - B A A A   A A A B - - - - - - - - - - - - - - - - - - - - B A C -   A A A B - - - - - - - - - - - - - - - - - - - - B A A A   A A A B - - - - - - - - - - - - - - - - - - - - B A A A   A A A B - - - - - - - - - - - - - - - - - - - - B A A A   A A A B - - - - - - - - - - - - - - - - - - - - B A A A   A A A B - - - - - - - - - - - - - - - - - - - - B A A A   A A A B - - - - - - - - - - - - - - - - - - - - B C - -   A A A B - - - - - - - - - - - - - - - - - - - - B C - -   A A A B - - - - - - - - - - - - - - - - - - - - B C - -   A A A B - - - - - - - - - - - - - - - - - - - - B C - -   A A A B - - - - - - - - - - - - - - - - - - - - B C - -   A A A A Q J V G AwY AdH AnAcX AmQ AqN Y L E Q I A C E -   A A A A A A A A A A A A A A A A A A A A A A A A A C E -   A A A A A A A A A A A A A A A A A A A A A A A A A C E -   A A A A A A A A A A A A A A A A A A A A A A A A A C E -   A A A A A A A A A A A A A A A A A A A A A A A A A C - -   A A A A A A A A A A A A A A A A A A A A A A A A A C - -   A A A A A A A A A A A A A A A A A A A A A A A A A C - -   A A A A A A A A A A A A A A A A A A A A A A A A A C - -   A A A A A A A A A A A A A A A A A A A A A A A A A A A A   D A A A A A A A A A A A A A A A A A A A A A A A A A A D   - - - - - - - - - - - - - D - - - - - - - - - - - - - -   - - - - - - - - - - - - - D - - - - - - - - - - - - - -   
D A A A - - - - - - - - - - - - - - - - - - - - A A A D   A A A B - - - - - - - - - - - - - - - - - - - - B A C -   A A A B - - - - - - - - - - - - - - - - - - - - B A C -   A A A B - - - - - - - - - - - - - - - - - - - - B A C -   A A A B - - - - - - - - - - - - - - - - - - - - B A C -   A A A B - - - - - - - - - - - - - - - - - - - - B A C -   A A A B - - - - - - - - - - - - - - - - - - - - B A C -   A A A B - - - - - - - - - - - - - - - - - - - - B A C -   A A A B - - - - - - - - - - - - - - - - - - - - B A A A   A A A B - - - - - - - - - - - - - - - - - - - - B A A A   A A A B - - - - - - - - - - - - - - - - - - - - B A A A   A A A B - - - - - - - - - - - - - - - - - - - - B A A A   A A A B - - - - - - - - - - - - - - - - - - - - B A A A   A A A B - - - - - - - - - - - - - - - - - - - - B C - -   A A A B - - - - - - - - - - - - - - - - - - - - B C - -   A A A B - - - - - - - - - - - - - - - - - - - - B C - -   A A A B - - - - - - - - - - - - - - - - - - - - B C - -   A A A B - - - - - - - - - - - - - - - - - - - - B C E -   A A A A G O M AgAvAnH J AwL I ArAaK G I AbAoX AsA C E -   A A A A A A A A A A A A A A A A A A A A A A A A A C E -   A A A A A A A A A A A A A A A A A A A A A A A A A C E -   A A A A A A A A A A A A A A A A A A A A A A A A A C E -   A A A A A A A A A A A A A A A A A A A A A A A A A C E -   A A A A A A A A A A A A A A A A A A A A A A A A A C - -   A A A A A A A A A A A A A A A A A A A A A A A A A C - -   A A A A A A A A A A A A A A A A A A A A A A A A A C - -   A A A A A A A A A A A A A A A A A A A A A A A A A A A A   D A A A A A A A A A A A A A A A A A A A A A A A A A A D   - - - - - - - - - - - - - - - - - - - - - - - - - - - -   - - - - - - - - - - - - - - - - - - - - - - - - - - - -   
D A A A - - - - - - - - - - - - - - - - - - - - A A A D   A A A B - - - - - - - - - - - - - - - - - - - - B A C -   A A A B - - - - - - - - - - - - - - - - - - - - B A C -   A A A B - - - - - - - - - - - - - - - - - - - - B A C -   A A A B - - - - - - - - - - - - - - - - - - - - B A C -   A A A B - - - - - - - - - - - - - - - - - - - - B A C -   A A A B - - - - - - - - - - - - - - - - - - - - B A C -   A A A B - - - - - - - - - - - - - - - - - - - - B A C -   A A A B - - - - - - - - - - - - - - - - - - - - B A A A   A A A B - - - - - - - - - - - - - - - - - - - - B A A A   A A A B - - - - - - - - - - - - - - - - - - - - B A A A   A A A B - - - - - - - - - - - - - - - - - - - - B A A A   A A A B - - - - - - - - - - - - - - - - - - - - B A A A   A A A B - - - - - - - - - - - - - - - - - - - - B C - -   A A A B - - - - - - - - - - - - - - - - - - - - B C - -   A A A B - - - - - - - - - - - - - - - - - - - - B C - -   A A A B - - - - - - - - - - - - - - - - - - - - B C - -   A A A B - - - - - - - - - - - - - - - - - - - - B C E -   A A A A AgAdAkAfAmAdAzO AvAbN AtT AjM H V P AfU A C E -   A A A A A A A A A A A A A A A A A A A A A A A A A C E -   A A A A A A A A A A A A A A A A A A A A A A A A A C E -   A A A A A A A A A A A A A A A A A A A A A A A A A C E -   A A A A A A A A A A A A A A A A A A A A A A A A A C E -   A A A A A A A A A A A A A A A A A A A A A A A A A C - -   A A A A A A A A A A A A A A A A A A A A A A A A A C - -   A A A A A A A A A A A A A A A A A A A A A A A A A C - -   A A A A A A A A A A A A A A A A A A A A A A A A A A A A   D A A A A A A A A A A A A A A A A A A A A A A A A A A D   - - - - - - - - - - - - - - - - - - - - - - - - - - - -   - - - - - - - - - - - - - - - - - - - - - - - - - - - -   
D A A A - - - - - - - - - - - - - - - - - - - - A A A D   A A A B - - - - - - - - - - - - - - - - - - - - B A A A   A A A B - - - - - - - - - - - - - - - - - - - - B A A A   A A A B - - - - - - - - - - - - - - - - - - - - B A A A   A A A B - - - - - - - - - - - - - - - - - - - - B A A A   A A A B - - - - - - - - - - - - - - - - - - - - B A A A   A A A B - - - - - - - - - - - - - - - - - - - - B A A A   A A A B - - - - - - - - - - - - - - - - - - - - B A C -   A A A B - - - - - - - - - - - - - - - - - - - - B A A A   A A A B - - - - - - - - - - - - - - - - - - - - B A A A   A A A B - - - - - - - - - - - - - - - - - - - - B A A A   A A A B - - - - - - - - - - - - - - - - - - - - B A A A   A A A B - - - - - - - - - - - - - - - - - - - - B A A A   A A A B - - - - - - - - - - - - - - - - - - - - B C - -   A A A B - - - - - - - - - - - - - - - - - - - - B C - -   A A A B - - - - - - - - - - - - - - - - - - - - B C - -   A A A B - - - - - - - - - - - - - - - - - - - - B C - -   A A A B - - - - - - - - - - - - - - - - - - - - B C - -   A A A A AfApArAjAuAyAtAdAmV V AeAlAcAqI M U N E A C E -   A A A A A A A A A A A A A A A A A A A A A A A A A C E -   A A A A A A A A A A A A A A A A A A A A A A A A A C E -   A A A A A A A A A A A A A A A A A A A A A A A A A C E -   A A A A A A A A A A A A A A A A A A A A A A A A A C - -   A A A A A A A A A A A A A A A A A A A A A A A A A C - -   A A A A A A A A A A A A A A A A A A A A A A A A A C - -   A A A A A A A A A A A A A A A A A A A A A A A A A C - -   A A A A A A A A A A A A A A A A A A A A A A A A A A A A   D A A A A A A A A A A A A A A A A A A A A A A A A A A D   - - - - - - - - - - - - - - - - - - - - - - - - - - - -   - - - - - - - - - - - - - - - - - - - - - - - - - - - -   
D A A A - - - - - - - - - - - - - - - - - - - - A A A D   A A A B - - - - - - - - - - - - - - - - - - - - B A A A   A A A B - - - - - - - - - - - - - - - - - - - - B A A A   A A A B - - - - - - - - - - - - - - - - - - - - B A A A   A A A B - - - - - - - - - - - - - - - - - - - - B A A A   A A A B - - - - - - - - - - - - - - - - - - - - B A A A   A A A B - - - - - - - - - - - - - - - - - - - - B A A A   A A A B - - - - - - - - - - - - - - - - - - - - B A C -   A A A B - - - - - - - - - - - - - - - - - - - - B A A A   A A A B - - - - - - - - - - - - - - - - - - - - B A A A   A A A B - - - - - - - - - - - - - - - - - - - - B A A A   A A A B - - - - - - - - - - - - - - - - - - - - B A A A   A A A B - - - - - - - - - - - - - - - - - - - - B A A A   A A A B - - - - - - - - - - - - - - - - - - - - B C - -   A A A B - - - - - - - - - - - - - - - - - - - - B C - -   A A A B - - - - - - - - - - - - - - - - - - - - B C - -   A A A B - - - - - - - - - - - - - - - - - - - - B C - -   A A A B - - - - - - - - - - - - - - - - - - - - B C - -   A A A A AjK Z O AdAsH ApAuM AhB M L K AsAkG G AoA C - -   A A A A A A A A A A A A A A A A A A A A A A A A A C E -   A A A A A A A A A A A A A A A A A A A A A A A A A C E -   A A A A A A A A A A A A A A A A A A A A A A A A A C - -   A A A A A A A A A A A A A A A A A A A A A A A A A C - -   A A A A A A A A A A A A A A A A A A A A A A A A A C - -   A A A A A A A A A A A A A A A A A A A A A A A A A C - -   A A A A A A A A A A A A A A A A A A A A A A A A A C - -   A A A A A A A A A A A A A A A A A A A A A A A A A A A A   D A A A A A A A A A A A A A A A A A A A A A A A A A A D   - - - - - - - - - - - - - - - - - - - - - - - - - - - -   - - - - - - - - - - - - - - - - - - - - - - - - - - - -   
D A A A - - - - - - - - - - - - - - - - - - - - A A A D   A A A B - - - - - - - - - - - - - - - - - - - - B A A A   A A A B - - - - - - - - - - - - - - - - - - - - B A A A   A A A B - - - - - - - - - - - - - - - - - - - - B A A A   A A A B - - - - - - - - - - - - - - - - - - - - B A A A   A A A B - - - - - - - - - - - - - - - - - - - - B A A A   A A A B - - - - - - - - - - - - - - - - - - - - B A A A   A A A B - - - - - - - - - - - - - - - - - - - - B A C -   A A A B - - - - - - - - - - - - - - - - - - - - B A A A   A A A B - - - - - - - - - - - - - - - - - - - - B A A A   A A A B - - - - - - - - - - - - - - - - - - - - B A A A   A A A B - - - - - - - - - - - - - - - - - - - - B A A A   A A A B - - - - - - - - - - - - - - - - - - - - B A A A   A A A B - - - - - - - - - - - - - - - - - - - - B C - -   A A A B - - - - - - - - - - - - - - - - - - - - B C - -   A A A B - - - - - - - - - - - - - - - - - - - - B C - -   A A A B - - - - - - - - - - - - - - - - - - - - B C - -   A A A B - - - - - - - - - - - - - - - - - - - - B C - -   A A A A O H AyN S U AsK AdAkAkO W AbAjU ArP M P A C - -   A A A A A A A A A A A A A A A A A A A A A A A A A C - -   A A A A A A A A A A A A A A A A A A A A A A A A A C - -   A A A A A A A A A A A A A A A A A A A A A A A A A C - -   A A A A A A A A A A A A A A A A A A A A A A A A A C - -   A A A A A A A A A A A A A A A A A A A A A A A A A C - -   A A A A A A A A A A A A A A A A A A A A A A A A A C - -   A A A A A A A A A A A A A A A A A A A A A A A A A C - -   A A A A A A A A A A A A A A A A A A A A A A A A A A A A   D A A A A A A A A A A A A A A A A A A A A A A A A A A D   - - - - - - - - - - - - - - - - - - - - - - - - - - - -   - - - - - - - - - - - - - - - - - - - - - - - - - - - -   
D A A A - - - - - - - - - - - - - - - - - - - - A A A D   A A A B - - - - - - - - - - - - - - - - - - - - B A A A   A A A B - - - - - - - - - - - - - - - - - - - - B A A A   A A A B - - - - - - - - - - - - - - - - - - - - B A A A   A A A B - - - - - - - - - - - - - - - - - - - - B A A A   A A A B - - - - - - - - - - - - - - - - - - - - B A A A   A A A B - - - - - - - - - - - - - - - - - - - - B A A A   A A A B - - - - - - - - - - - - - - - - - - - - B A C -   A A A B - - - - - - - - - - - - - - - - - - - - B A A A   A A A B - - - - - - - - - - - - - - - - - - - - B A A A   A A A B - - - - - - - - - - - - - - - - - - - - B A A A   A A A B - - - - - - - - - - - - - - - - - - - - B A A A   A A A B - - - - - - - - - - - - - - - - - - - - B A A A   A A A B - - - - - - - - - - - - - - - - - - - - B C - -   A A A B - - - - - - - - - - - - - - - - - - - - B C - -   A A A B - - - - - - - - - - - - - - - - - - - - B C - -   A A A B - - - - - - - - - - - - - - - - - - - - B C - -   A A A B - - - - - - - - - - - - - - - - - - - - B C - -   A A A A N R I S AaS AcH S ArAiL G V AcE Z AbAqU A C - -   A A A A A A A A A A A A A A A A A A A A A A A A A C - -   A A A A A A A A A A A A A A A A A A A A A A A A A C - -   A A A A A A A A A A A A A A A A A A A A A A A A A C - -   A A A A A A A A A A A A A A A A A A A A A A A A A C - -   A A A A A A A A A A A A A A A A A A A A A A A A A C - -   A A A A A A A A A A A A A A A A A A A A A A A A A C - -   A A A A A A A A A A A A A A A A A A A A A A A A A C - -   A A A A A A A A A A A A A A A A A A A A A A A A A A A A   D A A A A A A A A A A A A A A A A A A A A A A A A A A D   - - - - - - - - - - - - - - - - - - - - - - - - - - - -   - - - - - - - - - - - - - - - - - - - - - - - - - - - -   
D A A A - - - - - - - - - - - - - - - - - - - - A A A D   A A A B - - - - - - - - - - - - - - - - - - - - B A C -   A A A B - - - - - - - - - - - - - - - - - - - - B A C -   A A A B - - - - - - - - - - - - - - - - - - - - B A C -   A A A B - - - - - - - - - - - - - - - - - - - - B A C -   A A A B - - - - - - - - - - - - - - - - - - - - B A C -   A A A B - - - - - - - - - - - - - - - - - - - - B A C -   A A A B - - - - - - - - - - - - - - - - - - - - B A C -   A A A B - - - - - - - - - - - - - - - - - - - - B A A A   A A A B - - - - - - - - - - - - - - - - - - - - B A A A   A A A B - - - - - - - - - - - - - - - - - - - - B A A A   A A A B - - - - - - - - - - - - - - - - - - - - B A A A   A A A B - - - - - - - - - - - - - - - - - - - - B A A A   A A A B - - - - - - - - - - - - - - - - - - - - B C - -   A A A B - - - - - - - - - - - - - - - - - - - - B C - -   A A A B - - - - - - - - - - - - - - - - - - - - B C - -   A A A B - - - - - - - - - - - - - - - - - - - - B C - -   A A A B - - - - - - - - - - - - - - - - - - - - B C - -   A A A A S L R Z AtT S R AaZ B Z ApM L AoAyAhK G A C - -   A A A A A A A A A A A A A A A A A A A A A A A A A C - -   A A A A A A A A A A A A A A A A A A A A A A A A A C - -   A A A A A A A A A A A A A A A A A A A A A A A A A C - -   A A A A A A A A A A A A A A A A A A A A A A A A A C - -   A A A A A A A A A A A A A A A A A A A A A A A A A C - -   A A A A A A A A A A A A A A A A A A A A A A A A A C - -   A A A A A A A A A A A A A A A A A A A A A A A A A C - -   A A A A A A A A A A A A A A A A A A A A A A A A A A A A   D A A A A A A A A A A A A A A A A A A A A A A A A A A D   - - - - - - - - - - - - - - - - - - - - - - - - - - - -   - - - - - - - - - - - - - - - - - - - - - - - - - - - -   
D A A A A A A A A A A A A A A A A A A A A A A A A A A D   A A A A B B B B B B B B B B B B B B B B B B B B A A A A   A A A A B B B B B B B B B B B B B B B B B B B B A A A A   A A A A B B B B B B B B B B B B B B B B B B B B A A A A   A A A A B B B B B B B B B B B B B B B B B B B B A A A A   A A A A B B B B B B B B B B B B B B B B B B B B A A A A   A A A A B B B B B B B B B B B B B B B B B B B B A A A A   A A A A B B B B B B B B B B B B B B B B B B B B A A A A   A A A A B B B B B B B B B B B B B B B B B B B B A A A A   A A A A B B B B B B B B B B B B B B B B B B B B A A A A   A A A A B B B B B B B B B B B B B B B B B B B B A A A A   A A A A B B B B B B B B B B B B B B B B B B B B A A A A   A A A A B B B B B B B B B B B B B B B B B B B B A A A A   A A A A B B B B B B B B B B B B B B B B B B B B A A A A   A A A A B B B B B B B B B B B B B B B B B B B B A C - -   A A A A B B B B B B B B B B B B B B B B B B B B A C - -   A A A A B B B B B B B B B B B B B B B B B B B B A C - -   A A A A B B B B B B B B B B B B B B B B B B B B A C - -   A A A A A A A A A A A A A A A A A A A A A A A A A C - -   A A A A A A A A A A A A A A A A A A A A A A A A A C - -   A A A A A A A A A A A A A A A A A A A A A A A A A C - -   A A A A A A A A A A A A A A A A A A A A A A A A A C - -   A A A A A A A A A A A A A A A A A A A A A A A A A C - -   A A A A A A A A A A A A A A A A A A A A A A A A A C - -   A A A A A A A A A A A A A A A A A A A A A A A A A C - -   A A A A A A A A A A A A A A A A A A A A A A A A A A A A   A A A A A A A A A A A A A A A A A A A A A A A A A A A A   D A A A A A A A A A A A A A A A A A A A A A A A A A A D   - - - - - - - - - - - - - - - - - - - - - - - - - - - -   - - - - - - - - - - - - - - - - - - - - - - - - - - - -   
D A A A A A A A A A A A A A A A A A A A A A A A A A A D   A A A A A A A A A A A A A A A A A A A A A A A A A A A A   A A A A A A A A A A A A A A A A A A A A A A A A A A A A   A A A A A A A A A A A A A A A A A A A A A A A A A A A A   A A A A A A A A A A A A A A A A A A A A A A A A A A A A   A A A A A A A A A A A A A A A A A A A A A A A A A A A A   A A A A A A A A A A A A A A A A A A A A A A A A A A A A   A A A A A A A A A A A A A A A A A A A A A A A A A A A A   A A A A A A A A A A A A A A A A A A A A A A A A A A A A   A A A A A A A A A A A A A A A A A A A A A A A A A A A A   A A A A A A A A A A A A A A A A A A A A A A A A A A A A   A A A A A A A A A A A A A A A A A A A A A A A A A A A A   A A A A A A A A A A A A A A A A A A A A A A A A A A A A   A A A A A A A A A A A A A A A A A A A A A A A A A A A A   A A A A A A A A A A A A A A A A A A A A A A A A A A A A   A A A A A A A A A A A A A A A A A A A A A A A A A C - -   A A A A A A A A A A A A A A A A A A A A A A A A A C - -   A A A A A A A A A A A A A A A A A A A A A A A A A C - -   A A A A A A A A A A A A A A A A A A A A A A A A A C - -   A A A A A A A A A A A A A A A A A A A A A A A A A C - -   A A A A A A A A A A A A A A A A A A A A A A A A A C - -   A A A A A A A A A A A A A A A A A A A A A A A A A C - -   A A A A A A A A A A A A A A A A A A A A A A A A A C - -   A A A A A A A A A A A A A A A A A A A A A A A A A C - -   A A A A A A A A A A A A A A A A A A A A A A A A A A A A   A A A A A A A A A A A A A A A A A A A A A A A A A A A A   A A A A A A A A A A A A A A A A A A A A A A A A A A A A   D A A A A A A A A A A A A A A A A A A A A A A A A A A D   - - - - - - - - - - - - - - - - - - - - - - - - - - - -   - - - - - - - - - - - - - - - - - - - - - - - - - - - -   
D A A A A A A A A A A A A A A A A A A A A A A A A A A D   A A A A A A A A A A A A A A A A A A A A A A A A A A A A   A A A A A A A A A A A A A A A A A A A A A A A A A A A A   A A A A A A A A A A A A A A A A A A A A A A A A A A A A   A A A A A A A A A A A A A A A A A A A A A A A A A A A A   A A A A A A A A A A A A A A A A A A A A A A A A A A A A   A A A A A A A A A A A A A A A A A A A A A A A A A A A A   A A A A A A A A A A A A A A A A A A A A A A A A A A A A   A A A A A A A A A A A A A A A A A A A A A A A A A A A A   A A A A A A A A A A A A A A A A A A A A A A A A A A A A   A A A A A A A A A A A A A A A A A A A A A A A A A A A A   A A A A A A A A A A A A A A A A A A A A A A A A A A A A   A A A A A A A A A A A A A A A A A A A A A A A A A A A A   A A A A A A A A A A A A A A A A A A A A A A A A A A A A   A A A A A A A A A A A A A A A A A A A A A A A A A A A A   A A A A A A A A A A A A A A A A A A A A A A A A A A A A   A A A A A A A A A A A A A A A A A A A A A A A A A A A A   A A A A A A A A A A A A A A A A A A A A A A A A A A A A   A A A A A A A A A A A A A A A A A A A A A A A A A A A A   A A A A A A A A A A A A A A A A A A A A A A A A A A A A   A A A A A A A A A A A A A A A A A A A A A A A A A A A A   A A A A A A A A A A A A A A A A A A A A A A A A A A A A   A A A A A A A A A A A A A A A A A A A A A A A A A A A A   A A A A A A A A A A A A A A A A A A A A A A A A A A A A   A A A A A A A A A A A A A A A A A A A A A A A A A A A A   A A A A A A A A A A A A A A A A A A A A A A A A A A A A   A A A A A A A A A A A A A A A A A A A A A A A A A A A A   D A A A A A A A A A A A A A A A A A A A A A A A A A A D   - - - - - - - - - - - - - - - - - - - - - - - - - - - -   - - - - - - - - - - - - - - - - - - - - - - - - - - - -   
D D D D D D D D D D D D D D D D D D D D D D D D D D D D   D A A A A A A A A A A A A A A A A A A A A A A A A A A D   D A A A A A A A A A A A A A A A A A A A A A A A A A A D   D A A A A A A A A A A A A A A A A A A A A A A A A A A D   D A A A A A A A A A A A A A A A A A A A A A A A A A A D   D A A A A A A A A A A A A A A A A A A A A A A A A A A D   D A A A A A A A A A A A A A A A A A A A A A A A A A A D   D A A A A A A A A A A A A A A A A A A A A A A A A A A D   D A A A A A A A A A A A A A A A A A A A A A A A A A A D   D A A A A A A A A A A A A A A A A A A A A A A A A A A D   D A A A A A A A A A A A A A A A A A A A A A A A A A A D   D A A A A A A A A A A A A A A A A A A A A A A A A A A D   D A A A A A A A A A A A A A A A A A A A A A A A A A A D   D A A A A A A A A A A A A A A A A A A A A A A A A A A D   D A A A A A A A A A A A A A A A A A A A A A A A A A A D   D A A A A A A A A A A A A A A A A A A A A A A A A A A D   D A A A A A A A A A A A A A A A A A A A A A A A A A A D   D A A A A A A A A A A A A A A A A A A A A A A A A A A D   D A A A A A A A A A A A A A A A A A A A A A A A A A A D   D A A A A A A A A A A A A A A A A A A A A A A A A A A D   D A A A A A A A A A A A A A A A A A A A A A A A A A A D   D A A A A A A A A A A A A A A A A A A A A A A A A A A D   D A A A A A A A A A A A A A A A A A A A A A A A A A A D   D A A A A A A A A A A A A A A A A A A A A A A A A A A D   D A A A A A A A A A A A A A A A A A A A A A A A A A A D   D A A A A A A A A A A A A A A A A A A A A A A A A A A D   D A A A A A A A A A A A A A A A A A A A A A A A A A A D   D D D D D D D D D D D D D D D D D D D D D D D D D D D D   - - - - - - - - - - - - - - - - - - - - - - - - - - - -   - - - - - - - - - - - - - - - - - - - - - - - - - - - -   
