model
size = 14 23 10, scale = 0.05, origin = -y
material 
  colors = A:#FFC408 B:#BEC23F C:#EEE D:#FFFFFB
voxels
----AAAAAC---- -----ACAA----- ------AA------ -------------- -------------- -------------- -------------- -------------- -------------- -------------- -------------- -------------- -------------- -------------- -------------- -------------- -------------- -------------- -------------- -------------- -------------- -------------- -------------- 
---A------A--- ---AA----AA--- ---ACAAAAAA--- ----AAAAAA---- -------------- -------------- -------------- -------------- -------------- -------------- -------------- -------------- -------------- -------------- -------------- -------------- -------------- -------------- -------------- -------------- -------------- -------------- -------------- 
--A--------A-- --A--------A-- --A--------A-- ---AAAAAAAA--- ----ACAAAA---- -------------- -------------- -------------- -------------- -------------- -------------- -------------- -------------- -------------- -------------- -------------- -------------- -------------- -------------- -------------- -------------- -------------- -------------- 
-A----------A- -A----------A- -A----------A- --A--------C-- ---AAAAACAA--- ----AAAAAA---- -------------- -------------- -------------- -------------- -------------- -------------- -------------- -------------- -------------- -------------- -------------- -------------- -------------- -------------- -------------- -------------- -------------- 
A-----------AA -A----------C- -A----------A- -C----------A- --A--------A-- ---AAAAAAAA--- ------AC------ -------------- -------------- -------------- -------------- -------------- -------------- -------------- -------------- -------------- -------------- -------------- -------------- -------------- -------------- -------------- -------------- 
A------------A AA----------AA -A----------A- -A----------A- --A--------A-- ---AAAAAAAA--- -----AAAA----- -----AAAA----- ------AA------ ------AA------ ------AA------ ------AA------ -----CAAC----- ----A----A---- ---C--A---C--- --A-AAAAC--A-- -A---C---A--A- -C---AAAAA--C- -A---A---A--A- --A-AAACA--A-- ---C--A---C--- ----A----A---- -----CAAC----- 
C------------A AA----------AA AA----------AC -A----------A- --A--------A-- ---AAAAAAAA--- ----AAAAAA---- -----AAAA----- ------AA------ ------AA------ ------AA------ ------AA------ -----BBBB----- ----BBBBBB---- ---BBBBBBBB--- --BBBBBBBBBB-- -BBBBBBBBBBBB- -BBBBBBBBBBBB- -BBBBBBBBBBBB- --BBBBBBBBBB-- ---BBBBBBBB--- ----BBBBBB---- -----BBBB----- 
A------------A AA----------AA AA----------AA -A----------A- --A--------A-- ---AAAAAAAA--- ----AAAAAA---- -----CAAA----- ------AA------ ------AA------ ------AC------ ------AA------ -----DAAD----- ----A----A---- ---D---A--D--- --A--DAAAA-A-- -A--A---D---A- -D---AAAA---D- -A--A---A---A- --A--ADAAA-A-- ---D---A--D--- ----A----A---- -----DAAD----- 
A------------A AA----------AA -A----------A- -A----------A- --A--------A-- ---AAAAAAAA--- -----AAAA----- -------------- -------------- -------------- -------------- -------------- -------------- -------------- -------------- -------------- -------------- -------------- -------------- -------------- -------------- -------------- -------------- 
A------------C -C----------A- -A----------C- -A----------A- --C--------A-- ---AAAAAAAC--- ------CA------ -------------- -------------- -------------- -------------- -------------- -------------- -------------- -------------- -------------- -------------- -------------- -------------- -------------- -------------- -------------- -------------- 
