model
size = 16 29 30, scale = 0.05, origin = -y
material 
  colors = A:#CF6 B:#222 C:#444 D:#111 E:#777 F:#555 G:#888 H:#AAA I:#CFC J:#CF3 K:#CF9 L:#00D M:#00E N:#693 O:#DDD P:#D00 Q:#E00
voxels
---------------- --DDD----------- --D-D----------- --DDD----------- ---------------- ---------------- ---------------- ---------------- ---------------- ---------------- ---------------- ---------------- ---------------- ---------------- ---------------- ---------------- ---------------- ---------------- ---------------- ---------------- ---------------- ---------------- ---------------- ---------------- ---------------- ------DDDD------ ------DMMD------ ------DMMD------ ------DDDD------ 
---------------- --DDD----------- --DDD-----Q----- --DDD----------- ---------------- ---------------- ---------------- ---------------- ---------------- ---------------- ---------------- ---------------- ---------------- ---------------- ---------------- ---------------- ---------------- ---------------- ---------------- ---------------- ---------------- ---------------- ---------------- ---------------- ---------------- ------EDDE------ ------EMME------ ------EMME------ ------EEEE------ 
---------------- ---------------- ---G------O----- ---------------- ---------------- ---------------- ---------------- ---------------- ---------------- ---------------- ---------------- ---------------- ---------------- ---------------- ---------------- ---------------- ---------------- ---------------- ---------------- ---------------- ---------------- ---------------- ---------------- ---------------- ---------------- ------DDDD------ ------DMMD------ ------DMMD------ ------DDDD------ 
---------------- ---------------- ---G------O----- ---------------- ---------------- ---------------- ---------------- ---------------- ---------------- ---------------- ---------------- ---------------- ---------------- ---------------- ---------------- ---------------- ---------------- ---------------- ---------------- ---------------- ---------------- ---------------- ---------------- ---------------- ---------------- ---------------- -------EE------- -------EE------- ---------------- 
---------------- ---------------- ---G------O----- ---------------- ---------------- ---------------- ---------------- ---------------- ---------------- ---------------- ---------------- ---------------- ---------------- ---------------- ---------------- ---------------- ---------------- ---------------- ---------------- ---------------- ---------------- ---------------- ---------------- ---------------- ---------------- ---------------- -------EE------- -------EE------- ---------------- 
---------------- ---------------- ---G------O----- ---------------- ---------------- ---------------- ---------------- ---------------- ---------------- ---------------- ---------------- ---------------- ---------------- ---------------- ---------------- ---------------- ---------------- ---------------- ---------------- ---------------- ---------------- ---------------- ---------------- ---------------- ---------------- ------HDDH------ ------HLLH------ ------HLLH------ ------HHHH------ 
---------------- ---------------- ---G------O----- ---------------- ---------------- ---------------- ---------------- ---------------- ---------------- ---------------- ---------------- ---------------- ---------------- ---------------- ---------------- ---------------- ---------------- ---------------- ---------------- ---------------- ---------------- ---------------- ---------------- ---------------- ---------------- ------FFFF------ ------FLLF------ ------FLLF------ ------FFFF------ 
---------------- ---------FFF---- ---G-----FOF---- ---------FFF---- ---------------- ---------------- ---------------- ---------------- ---------------- ---------------- ---------------- ---------------- ---------------- ---------------- ---------------- ---------------- ---------------- ---------------- ---------------- ---------------- ---------------- ---------------- ---------------- ---------------- ---------------- ------HDDH------ ------HLLH------ ------HLLH------ ------HHHH------ 
---------------- ---------KKK---- ---G-----KKK---- ---------KKK---- ---------------- ---------------- ---------------- ---------------- ---------------- ---------------- ---------------- ---------------- ---------------- ---------------- ---------------- ---------------- ---------------- ---------------- ---------------- ---------------- ---------------- ---------------- ---------------- ---------------- ---------------- ---------------- -------HH------- -------HH------- ---------------- 
----AAAAAAAA---- --IIIAAAAAAA---- --IIIAAAAKKK---- --III----KKK---- ---------------- ---------------- ---------------- ---------------- ---------------- ---------------- ---------------- ---------------- ---------------- ---------------- ---------------- ---------------- ---------------- ---------------- ---------------- ---------------- ---------------- ---------------- ---------------- ---------------- ---------------- ---------------- -------HH------- -------HH------- ---------------- 
---AAAAAAAAAA--- --IAAAAAAAAAA--- --IIIAAAAKKKA--- --IIIAAAAKKK---- ---------------- ---------------- ---------------- ---------------- ---------------- ---------------- ---------------- ---------------- ---------------- ---------------- ---------------- ---------------- ---------------- ---------------- ---------------- ---------------- ---------------- ---------------- ---------------- ---------------- ---------------- ---------------- -------HH------- -------HH------- ---------------- 
--AAAAAAAAAAAA-- --AAAAAAAAAAAA-- --IIIAAAAAAAAA-- --IIIAAAAAAK---- -----ANNNNA----- -----NNNNNN----- -----CCCCCC----- -----CGGGGC----- -----CGGGGC----- -----CCCCCC----- -----DDDDDD----- ---------------- ---------------- -----DDDDDD----- ---------------- ---------------- -----DDDDDD----- ---------------- ---------------- ---------------- ---------------- ---------------- ---------------- ---------------- ---------------- ---------------- -------HH------- -------HH------- ---------------- 
AAAAAAAAAAAAAAAA AAAAAAAAAAAAAAAA AAAAAAAAAAAAAAAA AAIIKAAAAAAKIIAA --CCC------CCC-- --CGC------CGC-- --CGC------CGC-- --CGC------CGC-- --CGC------CGC-- --CCC------CCC-- --DDDEEEEEEDDD-- -----EEEEEE----- -----BBBBBB----- --DDDGGGGGGDDD-- -----EEEEEE----- -----BBBBBB----- --DDDDDDDDDDDD-- -----FFFFFF----- -----FFFFFF----- ---------------- -----BBBBBB----- -----BBBBBB----- -----BBBBBB----- ---------------- ---------------- ---------------- -------HH------- -------HH------- ---------------- 
AAAAAAAAAAAAAAAA AAAAAAAAAAAAAAAA AAAAAAAAAAAAAAAA AAAAAAAAAAAAAAAA -C------------C- -C------------C- -C------------C- -C------------C- -C-G--------G-C- -C------------C- -DEEE------EEED- --EEE------EEE-- --BBB------BBB-- -DGGG------GGGD- --EEE------EEE-- --BBB------BBB-- -DDDD------DDDD- ---FFCCCCCCFF--- ---FFCCCCCCFF--- -----CCCCCC----- --BBBBBBBBBBBB-- --BBBBBBBBBBBB-- --BBBBBBBBBBBB-- -----BBBBBB----- -----BBBBBB----- -----CCCCCC----- ------CCCC------ -------CC------- -------CC------- 
AAA----------AAA AAA----------AAA AAA----------AAA AAA----------AAA -C------------C- -G------------G- -G------------G- -G------------G- -G------------G- -C------------C- -DE----------ED- --E----------E-- --B----------B-- -DG----------GD- --E----------E-- --B----------B-- -DD----------DD- --FCC------CCF-- --FCC------CCF-- ---CC------CC--- --BBB------BBB-- --BBB------BBB-- --BBB------BBB-- ----B------B---- ----BBBBBBBB---- -----BBBBBB----- -------CC------- -------CC------- -------CC------- 
AAA----------AAA AAA----------AAA AAA----------AAA AAA----------AAA -C------------C- -C------------C- -C------------C- -C------------C- -C------------C- -C------------C- -DE----------ED- --E----------E-- --B----------B-- -DG----------GD- --E----------E-- --B----------B-- -DD----------DD- --FC--------CF-- --FC--------CF-- ---C--------C--- --BB--------BB-- --BB--------BB-- --BB--------BB-- ---B--------B--- ---BB------BB--- ----BBBBBBBB---- ------BBBB------ -------CC------- -------CC------- 
AAA----------AAA AAA----------AAA AAA----------AAA AAA----------AAA -D------------D- -D------------D- -D------------D- -D------------D- -D------------D- -D------------D- -DE----------ED- --E----------E-- --B----------B-- -DG----------GD- --E----------E-- --B----------B-- -DD----------DD- --FC--------CF-- --FC--------CF-- ---C--------C--- --BB--------BB-- --BB--------BB-- --BB--------BB-- ---B--------B--- ---BB------BB--- ----BBB--BBB---- -----BBBBBB----- ------BBBB------ -------CC------- 
AAA----------AAA AAA----------AAA AAAC--------CAAA AAAB--------BAAA -CB----------BC- -CB----------BC- -C------------C- -C------------C- -C------------C- -C------------C- -DE----------ED- --E----------E-- --B----------B-- -DG----------GD- --E----------E-- --B----------B-- -DD----------DD- --FC--------CF-- --FC--------CF-- ---C--------C--- --BB--------BB-- --BB--------BB-- --BB--------BB-- ---B--------B--- ---BB------BB--- ----BB----BB---- -----BB--BB----- ------BBBB------ -------BB------- 
AAA----------AAA AAA----------AAA AAA----------AAA AAA----------AAA -C------------C- -G------------G- -G------------G- -G------------G- -G------------G- -C------------C- -DE----------ED- --E----------E-- --B----------B-- -DG----------GD- --E----------E-- --B----------B-- -DD----------DD- --FC--------CF-- --FC--------CF-- ---C--------C--- --BB--------BB-- --BB--------BB-- --BB--------BB-- ---B--------B--- ---BBB----BBB--- ----BB----BB---- -----BB--BB----- ------BBBB------ -------BB------- 
AAA----------AAA AAA----------AAA AAA----------AAA AAA----------AAA -C------------C- -C------------C- -C------------C- -C------------C- -C------------C- -C------------C- -DE----------ED- --E----------E-- --B----------B-- -DG----------GD- --E----------E-- --B----------B-- -DD----------DD- --FC--------CF-- --FC--------CF-- ---C--------C--- --BBB------BBB-- --BBB------BBB-- --BBB------BBB-- ---BB------BB--- ---BBB----BBB--- ---JBB----BBJ--- --JJJBBBBBBJJJ-- --JJ--BBBB--JJ-- ---------------- 
AA-A--------AAAA AAAA--------AAAA AAAA--------AAAA AAAA--------AAAA --D----------D-- --D----------D-- --D----------D-- --D----------D-- --D----------D-- --D----------D-- --DE--------ED-- ---E--------E--- ---B--------B--- --DG--------GD-- ---E--------E--- ---B--------B--- --DD--------DD-- ---FC------CF--- ---FC------CF--- ----C------C---- ---BB------BB--- ---BB------BB--- ---BB------BB--- ---BBB----BBB--- ---BBB----BBB--- ---JJBB--BBJJ--- --JJJBBBBBBJJJ-- --JJ---BB---JJ-- ---------------- 
AAAA--------AAAA AAAA--------AAAA AAAA--------AAAA AAAA--------AAAA --C----------C-- --C----------C-- --C----------C-- --C----------C-- --C----------C-- --C----------C-- --DE--------ED-- ---E--------E--- ---B--------B--- --DG--------GD-- ---E--------E--- ---B--------B--- --DD--------DD-- ---FC------CF--- ---FC------CF--- ----C------C---- ---BB------BB--- ---BB------BB--- ---BB------BB--- ----B------B---- ----BBB--BBB---- -----BBBBBB----- ------BBBB------ ---------------- ---------------- 
-AAA--------AAA- -AAA--------AAA- -AAA--------AAA- -AAA--------AAA- --C----------C-- --G----------G-- --G----------G-- --G----------G-- --G----------G-- --C----------C-- --DE--------ED-- ---E--------E--- ---B--------B--- --DG--------GD-- ---E--------E--- ---B--------B--- --DD--------DD-- ---FC------CF--- ---FC------CF--- ----C------C---- ---BB------BB--- ---BB------BB--- ---BB------BB--- ----B------B---- ----BBBBBBBB---- ------BPPB------ ---------------- ---------------- ---------------- 
-AAA--------AAA- -AAA--------AAA- -AAA--------AAA- -AAA--------AAA- --C----------C-- --C----------C-- --C----------C-- --C----------C-- --C----------C-- --C----------C-- --DE--------ED-- ---E--------E--- ---B--------B--- --DG--------GD-- ---E--------E--- ---B--------B--- --DD--------DD-- ---FC------CF--- ---FC------CF--- ----C--BB--C---- ---BBBBBBBBBB--- ---BBBBBBBBBB--- ---BBBBBBBBBB--- -----BBPPBB----- -----BBPPBB----- ---------------- ---------------- ---------------- ---------------- 
--AAAAAAAAAAAA-- --AAAAAAAAAAAA-- --AAAAAAAAAAAA-- --AAAAAAAAAAAA-- ---D--------D--- ---D--------D--- ---D--------D--- ---D--------D--- ---D--------D--- ---D--------D--- ---DE------ED--- ----E------E---- ----B------B---- ---DG------GD--- ---ED------DE--- ---B--------B--- --DD-C----C-DD-- ---FCC----CCF--- ---FCC----CCF--- ----CC-BB-CC---- ----BBBBBBBB---- ----BBBBBBBB---- ----BBBBBBBB---- ---------------- ---------------- ---------------- ---------------- ---------------- ---------------- 
--AAAAAAAAAAAA-- --AAAAAAAAAAAA-- --AAAAAAAAAAAA-- --AAAAAAAAAAAA-- ---CG------GC--- ---C--------C--- ---C--------C--- ---C--------C--- ---C--------C--- ---C--------C--- ---DE------ED--- ----E------E---- ----B------B---- ---DGD----DGD--- ----E------E---- ----BDF--FDB---- ---DDFC--CFDD--- ----FFCCCCFF---- ----FFCCCCFF---- ------CCCC------ ------BBBB------ ------BBBB------ ------BBBB------ ---------------- ---------------- ---------------- ---------------- ---------------- ---------------- 
---AAAAAAAAAA--- ---AAAAAAAAAA--- ---AAAAAAAAAA--- ---AAAAAAAAAA--- ----C------C---- ----G------G---- ----G------G---- ----G------G---- ----G------G---- ----C------C---- ----DE----ED---- -----E----E----- -----B----B----- ----DG----GD---- -----E----E----- -----B----B----- ----DDF--FDD---- -----FFFFFF----- -----FFFFFF----- ---------------- ---------------- ---------------- ---------------- ---------------- ---------------- ---------------- ---------------- ---------------- ---------------- 
----AAAAAAAA---- ----AAAAAAAA---- ----AAAAAAAA---- ----AAAAAAAA---- -----C----C----- -----C----C----- -----C----C----- -----C----C----- -----C----C----- -----C----C----- -----DEEEED----- ------EEEE------ ------BBBB------ -----DGGGGD----- ------EEEE------ ------BBBB------ -----DDDDDD----- ------FFFF------ ------FFFF------ ---------------- ---------------- ---------------- ---------------- ---------------- ---------------- ---------------- ---------------- ---------------- ---------------- 
----AAAAAAAA---- ----AAAAAAAA---- ----AAAAAAAA---- ----AAAAAAAA---- ------CCCC------ ------CGGC------ ------CGGC------ ------CGGC------ ------CGGC------ ------CCCC------ ------DDDD------ ---------------- ---------------- ------DDDD------ ---------------- ---------------- ------DDDD------ ---------------- ---------------- ---------------- ---------------- ---------------- ---------------- ---------------- ---------------- ---------------- ---------------- ---------------- ---------------- 
-----AAAAAA----- -----AAAAAA----- -----AAAAAA----- -----AAAAAA----- ---------------- ---------------- ---------------- ---------------- ---------------- ---------------- ---------------- ---------------- ---------------- ---------------- ---------------- ---------------- ---------------- ---------------- ---------------- ---------------- ---------------- ---------------- ---------------- ---------------- ---------------- ---------------- ---------------- ---------------- ---------------- 
