model
size = 26 32 32, scale = 0.05, origin = -y
material 
  colors = A:#444 B:#111 C:#222 D:#CF9 E:#CF0 F:#555 G:#CF6 H:#CC3 I:#9C0 J:#666 K:#EEE L:#3CF M:#777 N:#00F O:#E00 P:#F90 Q:#CC0 R:#CCF S:#B00 T:#0C0 U:#00E V:#800
voxels
12-2(2A24-)2A776-6A2(20-F4AF)772-10A2(16-AF6AFA)20-2A24-2A720-14A12-F12AF12-F2AF6AF2AF16-6A20-6A74-2D24-2H615-16A2(10-F14AF)12-12A14-12A18-4B22-4B19-2G-4B-2G16-2H-4B-2H610-18A8-F16AF8-2F14A2F10-14A12-14A14-3(10B16-)10B46-2D24-2H535-20A6-F18AF6-2F16A2F8-16A10-16A13-3(10B16-)2BC7B19-2(4B22-)3BC22-4B507-22A4-F20AF4-2F18A2F7-16A10-16A12-2(12B14-)F10BH14-12B17-6B18-2G6B2G16-2H6B2H18-6B48-2D24-2Q430-2(F20AF4-)F20AF6-18A8-18A10-14B2(12-F13B)12-F12BC15-8B17-G8BG16-G8BH17-8B20-A3B22-4B22-A2CB22-3BA402-24A2(2-F22AF)4-20A6-20A8-3(16B10-)16B12-2(F11B14-)12B14-12B17-AB2CBA18-2G2B2CBA2G16-2HA4CB2H18-AB2CBA48-2Q24-2Q325-F22AF2(2-24A)3-22A4-22A6-18B8-17BC2(8-18B)10-2(14B12-)13BC12-14B15-2B4C2B17-GCB4CBCG16-G2B4C2BH17-CBC2ACBC21-2B2(24-2A)24-2B21-3(8E18-)8E192-24A2-F22AF2-24A3-22A4-22A6-18B7-G18BG6-H18BH7-18B9-3(16B10-)16B12-FB8C2B14-12C14-2B8C2B14-2B7C3B18-4A19-2G-B2AB-2G16-2H-B3A-2H19-4A19-3(I8DI16-)I3EDE2DEI9-3F4-I3-B-2N-I4-3F2-4F7-B-2N5-4F2-4F7-V8-4F106-2(24A2-)24A3-22A4-22A6-18B7-G18BG6-H18BH7-18B9-16B9-G16BG8-H16BH9-F15B11-B12CF12-14C2(12-B12CB)14-BAB7A16-10A16-2AB6AB16-B5AS2AB15-E6D2S2DI12-2FE3D2TO2L2DI2F10-F-EDL8DI-F10-F-3ED3E2U3E-F5-P3K2F4-B3-2N4-2F3K2P3KF5-B3-2N5-F3K2P4F5-O10-4FP105-2(24A2-)24A3-22A4-AF18AFA6-3(18B8-)18B9-16B9-G16BG8-H16BH9-16B11-B12CB11-G14CG10-HB12CBH11-B12CB13-B2LAL6AB14-B2ALARALR2AB14-B6A-4A14-3A4O-S3A13-EDLT6-3DI12-EDLT6-R2DI12-EDL8-RDI12-2E10-2E189-2(7A10-7A2-)7A10-7A3-6A10-6A4-6A10-6A6-3(4B10-4B8-)4B10-4B9-7(3B10-)3B11-BC10-CB11-G2C10-2CG10-GBC10-CBH11-BC10-CB13-A10-A13-GA10-AG12-HA10-AH13-A10-A13-3(ED10-DI12-)2E10-2E189-2(7A10-7A2-)7A10-7A3-6A10-6A4-6A10-6A6-4B10-4B7-G4B10-4BG6-H4B10-4BH7-4B10-4B9-7(3B10-)2BF11-BC10-CB12-2C10-2C12-FC10-CB12-BC10-CB13-A10-A13-GA10-AG12-HA10-AH13-A10-B13-3(ED10-DI12-)2E10-2E189-7A10-7A2-F6A10-6AF2-7A10-7A3-6A10-6A4-6A10-6A6-4B10-4B7-G4B10-4BG6-H4B10-4BH7-4B10-4B9-3B10-3B9-G3B10-3BG8-H3B10-3BH9-F2B10-3B11-2(BC10-CB12-)FC10-2C12-BC10-CB13-B10-A14-A10-B14-A10-A14-A10-B13-3(ED10-DI12-)2E10-2E189-7A10-7A2-F6A10-6AF2-7A10-7A3-6A10-6A4-6A10-6A6-3(4B10-4B8-)4B10-4B9-3B10-3B9-G3B10-3BG8-H3B10-3BH9-3B10-3B11-2C10-2C11-GBC10-CBG10-G2C10-2CH11-BC10-CB13-A10-B14-B10-A14-B10-B14-B10-A13-3(ED10-DI12-)2E10-2E189-7A10-7A2-F6A10-6AF2-7A10-7A3-6A10-6A4-6A10-6A6-F3B10-4B8-4B10-3BF8-4B10-4B8-4B10-3BF9-F2B7(10-3B)11-2C10-2C11-GBC10-CBG10-HBC10-CBH11-BC10-CB13-A10-A13-GA10-AG12-GA10-AG13-B10-B13-3(ED10-DI12-)2E10-2E189-7A10-7A2-F6A10-6AF2-7A10-7A3-6A10-6A4-6A10-6A6-3(4B10-4B8-)F3B10-4B9-4(3B10-)F2B10-3B10-F2B10-2BF11-2C10-2C12-BC10-CB12-2C10-2C12-BC10-CB13-A10-A13-GA10-AG12-HA10-AG13-B10-A13-3(ED10-DI12-)2E10-2E189-2(8A8-8A2-)F7A8-7AF3-7A8-7A4-7A8-7A6-7(5B8-)5B9-4B8-3BF3(10-4B8-4B)11-F2(2C8-2CB12-B)2C8-2CB12-3C8-3C13-2(2A8-AB14-)BA8-2B14-2A8-2A13-2(E2D8-2DI12-)EDE8-EDI12-2E10-2E189-2(9A6-9A2-)F8A6-8AF3-8A6-8A4-2(8A6-)3(6B6-6B8-)F5B6-6B9-3(5B6-5B10-)5B6-5B11-4C6-4C2(12-2B2C6-2C2B)12-4C6-4C15-A6-A18-B6-2(A25-)B15-2(E2D8-2DI12-)EDE8-EDI12-2E10-2E189-2(9A6-9A2-)F8A6-8AF3-8A6-8A4-2(8A6-)6B6-6B7-G6B6-6BG6-G6B6-6BH7-6B6-5BF9-5B6-5B9-G5B6-5BG8-H5B6-5BH9-5B6-5B12-B2C6-2CB14-G2B6-2BG14-H2B6-2BH15-BC6-CB17-B6-B17-G7-AG16-H7-AH24-B16-2(2D8-DI14-)2E8-2E216-2(10A4-10A2-)F9A4-9AF3-3(9A4-)9A6-7B4-7B7-G7B4-7BG6-H7B4-7BH7-7B4-7B10-5B4-5B10-2G5B4-5B2G8-2H5B4-5BGH10-BF3B4-5B14-3B4-3B15-G3B4-3BG14-H3B4-3BH15-2B6-2B24-B17-G7-AG16-H7-AH24-B16-2(ED8-DI14-)2E8-2E216-2(24A2-)F22AF4-20A6-20A7-18B9-F15B10-16B10-F14BF12-2(12B14-)11BF14-F11B15-3(10B16-)10B18-B5A20-B4AB20-6A20-B4AB18-2(4D2B3EI16-)3ED2B4E19-5(E2BE22-)2(4B22-)4B13-22A4-F20AF4-22A6-18A8-F16AF9-16B11-2(14B12-)14B13-12B14-F11B14-12B14-11BF16-8B17-G8BG16-G8BH17-8B19-5AB19-G6AG18-H6AH19-B5A18-2(2E7DI16-)3E4D3E19-5(E3D22-)2(3JI22-)4I14-20A6-F18AF6-20A8-F14AF10-16A11-14B12-13BF2(12-14B)13-12B14-11BF2(14-12B)17-6B18-2G6B2G16-2H6BGH18-6B21-B3A20-2G4A2G18-HG4A2H20-B3A20-2(E6DI18-)2E4D2E20-5(E3D22-)2(3JI22-)4I15-2(18A8-)18A10-2(14A12-)3(3B-6B-3B12-)14B14-10B15-G10BG14-H10BG15-10B18-6B20-5BF20-F5B20-6B21-3AB22-B2AB22-4A22-3AB21-2(5DI20-)E4DE21-5(E3D22-)2(3JI22-)4I16-2(16A10-)16A11-14A13-12A14-4B4-4B13-G4B4-4BG12-H4B4-4BH13-4B4-4B16-8B16-2G8B2G14-HG8B2H16-F7B20-F2BF2(22-4B)22-3BF49-2G24-GH48-8(6E20-)2(6I20-)6I16-14A2(12-F12AF)14-2(10A16-)10B14-2G10B2G12-2H10BGH14-8BFB18-F5B20-F4BF20-6B20-5BF48-2G24-HG435-2(12A14-)12A16-8A18-AM2AM3A2(18-8B18-F5BFB)47-2G24-2H540-4AM5A16-7AM2A16-2A2M2(AM)2A98-2G24-GH636-
