model
size = 31 31 16, scale = 0.05, origin = -y
material 
  colors = A:#CF3 B:#C36 C:#66C D:#09F
voxels
------------C-C-C-C------------ ----------C-CACACAC--C--------- --------C-CACACACACAAC--------- --------CACABBBBBBBACAAAC------ ------CAACBBBBBBBBBBBAACA------ ------ACBBBBBBBBBBBBBBBAAAC---- ----CAABBBBBBBBBBBBBBBBBACA---- ----ACBBBBBBBBBBBBBBBBBBBAAAC-- --CCCBBBBBBBBBBBBBBBBBBBBBCC--- ---AABBBBBBBBBBBBBBBBBBBBBAA--- -CCCBBBBBBBBBBBBBBBBBBBBBBBCCC- --AABBBBBBBBBDDDDDBBBBBBBBBAA-- CCCBBBBBBBBBDDDDDDDBBBBBBBBBCCC -AABBBBBBBBDDDDDDDDDBBBBBBBBAA- CCCBBBBBBBBDDDDDDDDDBBBBBBBBCCC -AABBBBBBBBDDDDDDDDDBBBBBBBBAA- CCCBBBBBBBBDDDDDDDDDBBBBBBBBCCC -AABBBBBBBBDDDDDDDDDBBBBBBBBAA- -ACBBBBBBBBBDDDDDDDBBBBBBBBBCCC -CAABBBBBBBBBDDDDDBBBBBBBBBAA-- --AABBBBBBBBBBBBBBBBBBBBBBBCCC- --ACABBBBBBBBBBBBBBBBBBBBBAAA-- --CAABBBBBBBBBBBBBBBBBBBBBCCC-- ---AACBBBBBBBBBBBBBBBBBBBACA--- ---CCAABBBBBBBBBBBBBBBBBCAACC-- ----CACABBBBBBBBBBBBBBBCACA---- ------CACABBBBBBBBBBBACACAC---- ------CACACABBBBBBBACACAC------ --------C-CACACACACACAC-C------ ----------C-CACACAC-C---------- ------------C-C-C-C------------ 
------------------------------- ------------AAAAAAA------------ ----------AAAAAAAAAAAA--------- --------AAAAAAAAAAAAAAAA------- -------AAAAAAAAAAAAAAAAAA------ ------AAAAAAAAAAAAAAAAAAAA----- -----AAAAAAAAAAAAAAAAAAAAAA---- ----AAAAAAAAAAAAAAAAAAAAAAAA--- ---AAAAAAAAAAAAAAAAAAAAAAAAA--- ---AAAAAAAAAAAAAAAAAAAAAAAAA--- --AAAAAAAAAAAAAAAAAAAAAAAAAAA-- --AAAAAAAAAAAAAAAAAAAAAAAAAAA-- -AAAAAAAAAAAAAAAAAAAAAAAAAAAAA- -AAAAAAAAAAAAAAAAAAAAAAAAAAAAA- -AAAAAAAAAAAAAAAAAAAAAAAAAAAAA- -AAAAAAAAAAAAAAAAAAAAAAAAAAAAA- -AAAAAAAAAAAAAAAAAAAAAAAAAAAAA- -AAAAAAAAAAAAAAAAAAAAAAAAAAAAA- -AAAAAAAAAAAAAAAAAAAAAAAAAAAAA- --AAAAAAAAAAAAAAAAAAAAAAAAAAA-- --AAAAAAAAAAAAAAAAAAAAAAAAAAA-- --AAAAAAAAAAAAAAAAAAAAAAAAAAA-- ---AAAAAAAAAAAAAAAAAAAAAAAAA--- ---AAAAAAAAAAAAAAAAAAAAAAAAA--- ----AAAAAAAAAAAAAAAAAAAAAAAA--- -----AAAAAAAAAAAAAAAAAAAAAA---- ------AAAAAAAAAAAAAAAAAAAA----- -------AAAAAAAAAAAAAAAAAA------ ----------AAAAAAAAAAAA--------- ------------AAAAAAA------------ ------------------------------- 
-------------C-C-C------------- -----------CAAAAAAAC----------- ---------CAAAAAAAAAAAAC-------- -------C-AAAAAAAAAAAAAA-------- -------AAAAAAAAAAAAAAAAAAC----- -----CAAAAAAAAAAAAAAAAAAAA----- -----AAAAAAAAAAAAAAAAAAAAAAC--- ---CAAAAAAAAAAAAAAAAAAAAAAAA--- ----AAAAAAAAAAAAAAAAAAAAAAAA--- --CAAAAAAAAAAAAAAAAAAAAAAAAAC-- --AAAAAAAAAAAAAAAAAAAAAAAAAAA-- -CAAAAAAAAAAAAAAAAAAAAAAAAAAAC- -AAAAAAAAAAAAAAAAAAAAAAAAAAAAA- CAAAAAAAAAAAAAAAAAAAAAAAAAAAAAC -AAAAAAAAAAAAAAAAAAAAAAAAAAAAA- CAAAAAAAAAAAAAAAAAAAAAAAAAAAAAC -AAAAAAAAAAAAAAAAAAAAAAAAAAAAA- -AAAAAAAAAAAAAAAAAAAAAAAAAAAAAC CAAAAAAAAAAAAAAAAAAAAAAAAAAAAA- --AAAAAAAAAAAAAAAAAAAAAAAAAAAC- --AAAAAAAAAAAAAAAAAAAAAAAAAAA-- -CAAAAAAAAAAAAAAAAAAAAAAAAAAAC- ---AAAAAAAAAAAAAAAAAAAAAAAAA--- ---CAAAAAAAAAAAAAAAAAAAAAAAAC-- ----AAAAAAAAAAAAAAAAAAAAAAAA--- -----AAAAAAAAAAAAAAAAAAAAAAC--- -----CAAAAAAAAAAAAAAAAAAAA----- -------AAAAAAAAAAAAAAAAAAC----- -------C-CAAAAAAAAAAAA-C------- -----------CAAAAAAAC-C--------- -------------C-C-C------------- 
------------------------------- -------------AAAAAA------------ ----------AAAAAAAAAAA---------- ---------AAAAAAAAAAAAAA-------- -------AAAAAAAAAAAAAAAAAA------ ------AAAAAAAAAAAAAAAAAAAA----- -----AAAAAAAAAAAAAAAAAAAAAA---- ----AAAAAAAAAAAAAAAAAAAAAAAA--- ----AAAAAAAAAAAAAAAAAAAAAAAA--- ---AAAAAAAAAAAAAAAAAAAAAAAAA--- --AAAAAAAAAAAAAAAAAAAAAAAAAAA-- --AAAAAAAAAAAAAAAAAAAAAAAAAAA-- --AAAAAAAAAAAAAAAAAAAAAAAAAAA-- -AAAAAAAAAAAAAAAAAAAAAAAAAAAAA- -AAAAAAAAAAAAAAAAAAAAAAAAAAAAA- -AAAAAAAAAAAAAAAAAAAAAAAAAAAAA- -AAAAAAAAAAAAAAAAAAAAAAAAAAAAA- -AAAAAAAAAAAAAAAAAAAAAAAAAAAAA- -AAAAAAAAAAAAAAAAAAAAAAAAAAAAA- --AAAAAAAAAAAAAAAAAAAAAAAAAAA-- --AAAAAAAAAAAAAAAAAAAAAAAAAAA-- ---AAAAAAAAAAAAAAAAAAAAAAAAA--- ---AAAAAAAAAAAAAAAAAAAAAAAAA--- ----AAAAAAAAAAAAAAAAAAAAAAAA--- ----AAAAAAAAAAAAAAAAAAAAAAAA--- -----AAAAAAAAAAAAAAAAAAAAAA---- ------AAAAAAAAAAAAAAAAAAAA----- -------AAAAAAAAAAAAAAAAAA------ ----------AAAAAAAAAAA---------- -------------AAAAAA------------ ------------------------------- 
------------------------------- ------------C-C-C-C------------ ----------CAAAAAAAAAC---------- --------C-AAAAAAAAAAAA-C------- --------AAAAAAAAAAAAAAAA------- ------CAAAAAAAAAAAAAAAAAAC----- -----CAAAAAAAAAAAAAAAAAAAA----- -----AAAAAAAAAAAAAAAAAAAAAA---- ---CAAAAAAAAAAAAAAAAAAAAAAAAC-- ----AAAAAAAAAAAAAAAAAAAAAAAA--- --CAAAAAAAAAAAAAAAAAAAAAAAAAC-- --AAAAAAAAAAAAAAAAAAAAAAAAAAA-- -CAAAAAAAAAAAAAAAAAAAAAAAAAAAC- --AAAAAAAAAAAAAAAAAAAAAAAAAAA-- -CAAAAAAAAAAAAAAAAAAAAAAAAAAAC- --AAAAAAAAAAAAAAAAAAAAAAAAAAA-- --AAAAAAAAAAAAAAAAAAAAAAAAAAAC- -CAAAAAAAAAAAAAAAAAAAAAAAAAAA-- --AAAAAAAAAAAAAAAAAAAAAAAAAAAC- --AAAAAAAAAAAAAAAAAAAAAAAAAAA-- --CAAAAAAAAAAAAAAAAAAAAAAAAAC-- ---AAAAAAAAAAAAAAAAAAAAAAAAA--- ---CAAAAAAAAAAAAAAAAAAAAAAAAC-- ----AAAAAAAAAAAAAAAAAAAAAAAA--- ----CAAAAAAAAAAAAAAAAAAAAAAC--- ------AAAAAAAAAAAAAAAAAAAA----- ------CAAAAAAAAAAAAAAAAAAC----- --------AAAAAAAAAAAAAAAAC------ --------C-CAAAAAAAAAC-C-------- ------------C-C-C-C------------ ------------------------------- 
------------------------------- ------------------------------- ------------AAAAAAA------------ ----------AAAAAAAAAAAA--------- ---------AAAAAAAAAAAAAA-------- -------AAAAAAAAAAAAAAAAAA------ ------AAAAAAAAAAAAAAAAAAAA----- -----AAAAAAAAAAAAAAAAAAAAAA---- -----AAAAAAAAAAAAAAAAAAAAAA---- ----AAAAAAAAAAAAAAAAAAAAAAAA--- ---AAAAAAAAAAAAAAAAAAAAAAAAA--- ---AAAAAAAAAAAAAAAAAAAAAAAAA--- --AAAAAAAAAAAAAAAAAAAAAAAAAAA-- --AAAAAAAAAAAAAAAAAAAAAAAAAAA-- --AAAAAAAAAAAAAAAAAAAAAAAAAAA-- --AAAAAAAAAAAAAAAAAAAAAAAAAAA-- --AAAAAAAAAAAAAAAAAAAAAAAAAAA-- --AAAAAAAAAAAAAAAAAAAAAAAAAAA-- --AAAAAAAAAAAAAAAAAAAAAAAAAAA-- ---AAAAAAAAAAAAAAAAAAAAAAAAA--- ---AAAAAAAAAAAAAAAAAAAAAAAAA--- ---AAAAAAAAAAAAAAAAAAAAAAAAA--- ----AAAAAAAAAAAAAAAAAAAAAAAA--- -----AAAAAAAAAAAAAAAAAAAAAA---- -----AAAAAAAAAAAAAAAAAAAAAA---- ------AAAAAAAAAAAAAAAAAAAA----- -------AAAAAAAAAAAAAAAAAA------ ---------AAAAAAAAAAAAAA-------- ------------AAAAAAA------------ ------------------------------- ------------------------------- 
------------------------------- ---------------C-C------------- -----------C-CAAAA-C----------- ---------CAAAAAAAAAAAC--------- ---------AAAAAAAAAAAAAA-------- -------CAAAAAAAAAAAAAAAAC------ -------AAAAAAAAAAAAAAAAAA------ -----CAAAAAAAAAAAAAAAAAAAAC---- -----AAAAAAAAAAAAAAAAAAAAAA---- ---CAAAAAAAAAAAAAAAAAAAAAAAAC-- ---AAAAAAAAAAAAAAAAAAAAAAAAA--- ---AAAAAAAAAAAAAAAAAAAAAAAAAC-- ---AAAAAAAAAAAAAAAAAAAAAAAAA--- --CAAAAAAAAAAAAAAAAAAAAAAAAAC-- --AAAAAAAAAAAAAAAAAAAAAAAAAAA-- --AAAAAAAAAAAAAAAAAAAAAAAAAAAC- -CAAAAAAAAAAAAAAAAAAAAAAAAAAA-- --AAAAAAAAAAAAAAAAAAAAAAAAAAAC- ---AAAAAAAAAAAAAAAAAAAAAAAAA--- --CAAAAAAAAAAAAAAAAAAAAAAAAAC-- ---AAAAAAAAAAAAAAAAAAAAAAAAA--- ---CAAAAAAAAAAAAAAAAAAAAAAAAC-- ----AAAAAAAAAAAAAAAAAAAAAAAA--- ----CAAAAAAAAAAAAAAAAAAAAAAC--- -----CAAAAAAAAAAAAAAAAAAAA----- -------AAAAAAAAAAAAAAAAAAC----- -------CAAAAAAAAAAAAAAAA------- ---------AAAAAAAAAAAAAAC------- ---------C-C-CAAAA-C-C--------- ---------------C-C------------- ------------------------------- 
------------------------------- ------------------------------- ------------------------------- ------------AAAAAAA------------ ----------AAAAAAAAAAAA--------- --------CAAAAAAAAAAAAAA-------- --------AAAAAAAAAAAAAAAA------- ------CAAAAAAAAAAAAAAAAAA------ ------AAAAAAAAAAAAAAAAAAAA----- -----AAAAAAAAAAAAAAAAAAAAAA---- ----AAAAAAAAAAAAAAAAAAAAAAAA--- ----AAAAAAAAAAAAAAAAAAAAAAAA--- ---AAAAAAAAAAAAAAAAAAAAAAAAA--- ---AAAAAAAAAAAAAAAAAAAAAAAAA--- ---AAAAAAAAAAAAAAAAAAAAAAAAA--- --CAAAAAAAAAAAAAAAAAAAAAAAAA--- ---AAAAAAAAAAAAAAAAAAAAAAAAA--- ---AAAAAAAAAAAAAAAAAAAAAAAAA--- ---AAAAAAAAAAAAAAAAAAAAAAAAA--- ----AAAAAAAAAAAAAAAAAAAAAAAA--- ----AAAAAAAAAAAAAAAAAAAAAAAA--- ----AAAAAAAAAAAAAAAAAAAAAAAA--- -----AAAAAAAAAAAAAAAAAAAAAA---- ------AAAAAAAAAAAAAAAAAAAA----- -------AAAAAAAAAAAAAAAAAA------ --------AAAAAAAAAAAAAAAA------- ---------AAAAAAAAAAAAAA-------- ----------AAAAAAAAAAAA--------- ------------------------------- ------------------------------- ------------------------------- 
------------------------------- ------------------------------- ----------------C-------------- ------------C-CAA-C------------ ----------CAAAAAAAAAC---------- ----------AAAAAAAAAAAAC-------- --------AAAAAAAAAAAAAAAA------- -------AAAAAAAAAAAAAAAAAAC----- ------AAAAAAAAAAAAAAAAAAAA----- ------AAAAAAAAAAAAAAAAAAAAC---- ----CAAAAAAAAAAAAAAAAAAAAAA---- ----AAAAAAAAAAAAAAAAAAAAAAAA--- ---CAAAAAAAAAAAAAAAAAAAAAAAAC-- ----AAAAAAAAAAAAAAAAAAAAAAAA--- ----AAAAAAAAAAAAAAAAAAAAAAAAC-- ---AAAAAAAAAAAAAAAAAAAAAAAAA--- ---AAAAAAAAAAAAAAAAAAAAAAAAAC-- ----AAAAAAAAAAAAAAAAAAAAAAAA--- ---CAAAAAAAAAAAAAAAAAAAAAAAAC-- ----AAAAAAAAAAAAAAAAAAAAAAAA--- ----CAAAAAAAAAAAAAAAAAAAAAAC--- -----AAAAAAAAAAAAAAAAAAAAAA---- ------AAAAAAAAAAAAAAAAAAAAC---- -----CAAAAAAAAAAAAAAAAAAAA----- -------AAAAAAAAAAAAAAAAAAC----- -------CAAAAAAAAAAAAAAAAC------ ---------CAAAAAAAAAAAA-C------- ----------CAAAAAAAAA-C--------- ------------C-C-C-C------------ ------------------------------- ------------------------------- 
------------------------------- ------------------------------- ------------------------------- ------------------------------- -------------AAAAAA------------ ----------AAAAAAAAAAA---------- --------C-AAAAAAAAAAAAC-------- --------AAAAAAAAAAAAAAAAC------ ------CAAAAAAAAAAAAAAAAAA------ -------AAAAAAAAAAAAAAAAAA------ -----AAAAAAAAAAAAAAAAAAAAAA---- -----AAAAAAAAAAAAAAAAAAAAAA---- -----AAAAAAAAAAAAAAAAAAAAAA---- ----AAAAAAAAAAAAAAAAAAAAAAAA--- ---CAAAAAAAAAAAAAAAAAAAAAAAA--- ----AAAAAAAAAAAAAAAAAAAAAAAA--- ---CAAAAAAAAAAAAAAAAAAAAAAAA--- ----AAAAAAAAAAAAAAAAAAAAAAAA--- ----AAAAAAAAAAAAAAAAAAAAAAAA--- -----AAAAAAAAAAAAAAAAAAAAAA---- -----AAAAAAAAAAAAAAAAAAAAAA---- -----CAAAAAAAAAAAAAAAAAAAA----- -------AAAAAAAAAAAAAAAAAA------ -------AAAAAAAAAAAAAAAAAA------ --------AAAAAAAAAAAAAAAA------- ---------CAAAAAAAAAAAAC-------- ----------AAAAAAAAAAA---------- -----------C-AAAAAA------------ ------------------------------- ------------------------------- ------------------------------- 
------------------------------- ------------------------------- ------------------------------- ------------------------------- -----------------C------------- ------------AAAAAAAC----------- ----------AAAAAAAAAAAC--------- ----------AAAAAAAAAAAA--------- --------AAAAAAAAAAAAAAAA------- --------AAAAAAAAAAAAAAAAC------ ------AAAAAAAAAAAAAAAAAAAA----- -----CAAAAAAAAAAAAAAAAAAAAC---- -----AAAAAAAAAAAAAAAAAAAAAAC--- -----AAAAAAAAAAAAAAAAAAAAAA---- -----AAAAAAAAAAAAAAAAAAAAAA---- -----AAAAAAAAAAAAAAAAAAAAAA---- -----AAAAAAAAAAAAAAAAAAAAAA---- -----AAAAAAAAAAAAAAAAAAAAAAC--- -----AAAAAAAAAAAAAAAAAAAAAA---- -----CAAAAAAAAAAAAAAAAAAAA----- ------AAAAAAAAAAAAAAAAAAAAC---- -------AAAAAAAAAAAAAAAAAA------ --------AAAAAAAAAAAAAAAAC------ -------CAAAAAAAAAAAAAAAAC------ ----------AAAAAAAAAAAA--------- ----------AAAAAAAAAAAC--------- ------------AAAAAAAC----------- -------------C-C-C------------- ------------------------------- ------------------------------- ------------------------------- 
------------------------------- ------------------------------- ------------------------------- ------------------------------- ------------------------------- -------------C--C-------------- -----------CAAAAAAA------------ ----------AAAAAAAAAAA---------- --------C-AAAAAAAAAAAAC-------- ---------AAAAAAAAAAAAAA-------- -------AAAAAAAAAAAAAAAAAA------ -------AAAAAAAAAAAAAAAAAAC----- ------AAAAAAAAAAAAAAAAAAAA----- -----CAAAAAAAAAAAAAAAAAAAA----- ------AAAAAAAAAAAAAAAAAAAAC---- ------AAAAAAAAAAAAAAAAAAAA----- -----CAAAAAAAAAAAAAAAAAAAAC---- ------AAAAAAAAAAAAAAAAAAAA----- ------AAAAAAAAAAAAAAAAAAAA----- -------AAAAAAAAAAAAAAAAAAC----- -------AAAAAAAAAAAAAAAAAA------ --------AAAAAAAAAAAAAAAA------- ---------AAAAAAAAAAAAAA-------- ----------AAAAAAAAAAAA--------- ----------AAAAAAAAAAA---------- -----------CAAAAAAA------------ ----------------C-------------- ------------------------------- ------------------------------- ------------------------------- ------------------------------- 
------------------------------- ------------------------------- ------------------------------- ------------------------------- ------------------------------- ------------------------------- -----------------C------------- -------------AAAAAAC----------- -----------AAAAAAAAA----------- ----------AAAAAAAAAAAAC-------- ---------AAAAAAAAAAAAAA-------- -------CAAAAAAAAAAAAAAAA------- --------AAAAAAAAAAAAAAAA------- ------CAAAAAAAAAAAAAAAAAAC----- -------AAAAAAAAAAAAAAAAAA------ -------AAAAAAAAAAAAAAAAAA------ -------AAAAAAAAAAAAAAAAAA------ ------CAAAAAAAAAAAAAAAAAA------ -------AAAAAAAAAAAAAAAAAA------ -------CAAAAAAAAAAAAAAAA------- ---------AAAAAAAAAAAAAA-------- ---------AAAAAAAAAAAAAAC------- ----------AAAAAAAAAAAA--------- ----------CAAAAAAAAAC---------- -------------AAAAAA------------ --------------C---------------- ------------------------------- ------------------------------- ------------------------------- ------------------------------- ------------------------------- 
------------------------------- ------------------------------- ------------------------------- ------------------------------- ------------------------------- ------------------------------- ------------------------------- --------------C-C-------------- -----------C------------------- -------------C-C-C-C----------- ---------C--AAAAAAA------------ -----------AAAAAAAAAC-C-------- ----------AAAAAAAAAAA---------- --------C-AAAAAAAAAAAC-C------- ----------AAAAAAAAAAAA--------- -------C--AAAAAAAAAAAAC-C------ ---------CAAAAAAAAAAAA--------- ----------AAAAAAAAAAAAC-C------ ---------CAAAAAAAAAAA---------- ---------C-AAAAAAAAAC-C-------- ------------AAAAAAA------------ ---------C-C-CAAAA-C-C--------- ------------------------------- -------------C--C-------------- ------------------C------------ ------------------------------- ------------------------------- ------------------------------- ------------------------------- ------------------------------- ------------------------------- 
------------------------------- ------------------------------- ------------------------------- ------------------------------- ------------------------------- ------------------------------- ------------------------------- ------------------------------- ------------------------------- ------------------------------- ------------C------------------ --------------C-C-C------------ ----------C-C-AAAA------------- -------------AAAAAAC----------- -----------CAAAAAAA------------ ------------AAAAAAA-C---------- ------------AAAAAAA------------ -----------CAAAAAAAC----------- -------------AAAAAA------------ ------------C-C-C-C------------ ------------------------------- ---------------C-C------------- ------------------------------- ------------------------------- ------------------------------- ------------------------------- ------------------------------- ------------------------------- ------------------------------- ------------------------------- ------------------------------- 
------------------------------- ------------------------------- ------------------------------- ------------------------------- ------------------------------- ------------------------------- ------------------------------- ------------------------------- ------------------------------- ------------------------------- ------------------------------- ------------------------------- ------------------------------- -------------C-C-C------------- ------------------------------- ------------C-C-C-C------------ ------------------------------- -------------C-C-C------------- ------------------------------- ------------------------------- ------------------------------- ------------------------------- ------------------------------- ------------------------------- ------------------------------- ------------------------------- ------------------------------- ------------------------------- ------------------------------- ------------------------------- ------------------------------- 
