model
size = 29 27 27, scale = 0.05, origin = -y
material 
  colors = A:#111 B:#FC6 C:#222 D:#F4C874 E:#888 F:#AAA G:#EEE H:#DAAF57 I:#202424 J:#B69248 K:#000 L:#404848 M:#BBB N:#777 O:#819191 P:#600 Q:#E00 R:#92763A S:#DDD T:#D3BDA0 U:#996 V:#26200E W:#A2B6B6
voxels
----------------------------- ----------------------------- ----------------------------- ----------------------------- ----------------------------- ----------------------------- ----------------------------- ----------------------------- ----------------------------- ----------------------------- ----------------------------- ----------------------------- --------A-------------------- -------A--------------------- --------AA------------------- ----------------------------- ----------------------------- ----------------------------- ----------------------------- ----------------------------- ----------------------------- ----------------------------- ----------------------------- ----------------------------- ----------------------------- ----------------------------- ----------------------------- 
----------------------------- ----------------------------- ----------------------------- ----------------------------- ----------------------------- ----------------------------- ----------------------------- ----------------------------- ----------------------------- ----------------------------- ----------------------------- --------C-------------------- ------AAAAC------------------ ----------AA----------------- --------A-AA----C------------ -------C-AA----AA------------ ------C---CAC-A-C------------ -------A---AA--AA------------ ---------AAA----------------- --------CAAA-A--A------------ ----------AA--A-------------- ----------------------------- ----------------------------- ----------------------------- ----------------------------- ----------------------------- ----------------------------- 
----------------------------- ----------------------------- ----------------------------- ----------------------------- ----------------------------- ----------------------------- ----------------------------- ----------------------------- ----------------------------- --------A-------------------- -------CA-A------------------ -------AAA-AA---------------- -----ACCAA--A---------------- -------AAAACA-A-------------- ----AAAAAAAACC--AA----------- ------AAAAACAA-AC------------ ------CA-CAAAAAAC------------ ------CAACCAACAAC------------ ------AA-AACA-CAA------------ --------AAAACAA-C------------ ---------ACC-C--A------------ --------------C-------------- ----------------------------- ----------------------------- ----------------------------- ----------------------------- ----------------------------- 
----------------------------- ----------------------------- ----------------------------- ----------------------------- ----------------------------- ----------------------------- ----------------------------- ----------------------------- ---------A------------------- --------AA------------------- -------AAAA---AA------------- ------AAACAAC-C-------------- -----CAAAAAAAAA-------------- -----ACCACAAAACCA------------ ----CAAAAACACAA-AA----------- ----CAACAAAAAAAAC--G--------- ----ACCAACAAACAAA------------ -----AAAAACAACCAA------------ -----CCCCCACAACAA------------ -----CAAAAAAAAAAC------------ -------AAACAAAC-A------------ ---------CAC--AAA------------ -----------A----------------- -----------A----------------- ----------------------------- ----------------------------- ----------------------------- 
----------------------------- ----------------------------- ----------------------------- ----------------------------- ----------------------------- ----------------------------- ----------------------------- ----------C------------------ --------AAC------------------ ------CAAAC------------------ -----CAAAAAAA-DD------------- -----AACAAAAAAACB------------ ----AACAACAACACAA------------ ----ACAACAAAAAACAA----------- ---AAAAAAAACAAAAAE----------- ----CACCACAAAAAAAG-A--------- ----ACACAAACACCAC--G--------- ----CAAACAAAAACA-AG---------- ----CCAACAAACCAC------------- ----AAAAAACACAC-------------- -----CACCCAAAA--A------------ ------AAAAAAC-CCC------------ -------C-ACA--ACA------------ -----------AA-A-------------- ----------------------------- ----------------------------- ----------------------------- 
----------------------------- ----------------------------- ----------------------------- ----------------------------- ----------------------------- ----------------------------- ----------------------------- -------AAA------NN----------- -----AAAAAC------C----------- ----CAAAACAC----DAC---------- ----AAAAAAAAAA-BBCCB--------- -----ACAAAAAACAAAFA---------- ----CAAAAAACAACAAEA---------- ----ACAAAACCAAAABEA---------- ---CAACAAAAAAAAABECC--------- ---AAAAAAAAACCCAFEFF--------- ---AAAAAAACCAAAA-A----------- ---AACACACAAAACF-C-F--------- ---AACACAAAACAAE-A----------- ----AAAAAAACAAC--F-G--------- ----CACCCAAAAAA--E--GG------- -----AAAACCAAF--------------- ------CCCCAAF--E------------- ---------AACCACCC------------ -----------AF---------------- ----------------------------- ----------------------------- 
----------------------------- ----------------------------- ----------------------------- ----------------------------- --------AA----A-------------- ---------------A------------- -----------A----------------- -----AACAAA-----AA----------- ----AACAAACA----BBA---------- -C-CAAAAACAAAA-CCDBD--------- ----AACCAACAACCBDACBB-------- -AAAAAACAACCACCABBBAD-------- --AAAAAAACAAAAACDBDBA-------- --AAACCADBBAAACADBFMMMM------ --CCAAAABDBBACCCBDBBJ-------- --AAAACAADBDAAAABBDDD-------- --ACAAAAADBDDBDDBDFFC-------- ---AAAACCBBBDBBBEBEBCF------- ---ACCAAACAAACCCCAF-FAG------ ---CAACACAACAAAACACAGE------- ----AAAAAAAAACAAA-AAACEF----- ----AACCAAACAAA---AGGNGGF---- ------AAAAACA---AA------G---- -------AAAAAAAAAA----E------- ---------AA-AA--------------- ------------C---------------- ----------------------------- 
----------------------------- --------BBBDH---------------- ---------BBBDDH-------------- -----------BDDB-J------------ -------A-CC-----A------------ ---------ACA--AAA----B------- ----AAACAA-CAAA-A-RHHH-BH---- ---CCCAAAACC-A--BBBBHBDBJ---- --AACAAAAAACACADABDHABBDJ---- ---AAACACAAAAAABBDDDBDBJ----- -A-AAAACAAAACCADBBBBBDD------ --AACAACAACAAAABBDBBBBB----N- --AAAAAABBBBBBBDBDBBDBD----M- --ACCACADBBBDBBBDBBBBBBSMSSS- --AAAAACBDDBBBBBBBDBBDJ------ -AAAAAAABDBBBBDBDBBBDDD------ --AAAACADBDBDBDBBDBBDBD------ --AACCAAACACACACAAABDB-C----- ---ACACACAAAAAAAAAAFDBFF----- ---CAACAAACACCAAAAABEDE------ ---ACCAAAAAACCCAAAADB-CF-EG-- ----AAACCCAACAAAAAAAE-NAF---- -----CAAACCAAACCCAAA---FF---- ------CAAAAAACCAAAA---F------ -------ACAAAAACCAA----A------ --------AACACCA-------------- ------------C---------------- 
----------------------------- --------DBBBBDBBH------------ --------BDBBBDDJ------------- ---------BBBBDDBBJ-----J----- ------AAACACAA-BBADDBBB--J--- -----A---ACC-CBDDAABBD-DBJ--- ---ACACAAAAA--DDDRBBDBBBDR--- -A-AACCCAAAAABBBBDBDDDBBR---- --CAAAAAAAAA-DDBBBDBBBDBJ---- --AAAAACCCAAADDBDDDDBBDDJ---- -AAAACAAAAAACBBBBDBDBDBJJB-N- -CACAAABBBDBBDBDDDBBDBBBBB--- --AAAACDBBDBBBBBBBBBDBBBB---- -AACAAADDBBBDBDBBBDDBBBQQ---- -AACAAADBBBBDBBDBDBBBBDBBBT-- -ACCACABBBBBBDBBBDBBBDBDVJ--- -AAACACBBDDDDDDDDBBBDBBBB---- -ACAACAAAAAAAACAACABBBDG----- --ACACAAACCAAAAACAADBBBBAG--- --AAACCAACACACACCACBBBDE-UG-- ---AAAACAAAAAAAAAACBDB--FFG-- ----CCAAACCACAAAACABDA--FEG-- ----CCAACACCAAAAACCAN---F---- -----AAAAACAAAACCAAA---E----- ------ACACCACAAAAAA---A------ -------AAAAAAAAAAA----A------ -------A-AAA-AA-A------------ 
--------BDDBDBBBB------------ -------DBBDDBBBBDHJ---------- --------BBBBBBBBBDDD--BD-D--- --------DBBBBBDBBBBBBDDBDDH-- ------AACACAABBDBDBAABDBDDH-- ----AA--AAAACBBBBDDDDDBBBBH-- ---ACACCCCC-ABDBDBBBDBBDBJ--- -AAAAACAAAACCBBBBBBBDDBBDJ--- --AAAAACAAAAADDBDDDBDBDBJ---- -CCAACACCCACABBBBBBBBBDBJ---- -C-AAAAAAACAADBBDDBBBBBDB--N- -ACACCACAAAAABDBDDBBBBBBB-BJ- -CAAAABDBBBDBBDDBBBDBBBBB-D-- -AAAAACCBDBDDBDDBBDBDBDBQ---- -AAAAAAABBDBBBBBDBBBDBBADBBT- -CAAAAAABBDDDBBBBDBBBBBCBBA-- -AACACCABBBBBDDBDBBDDBBBDB--- -AAACAAACACACCCACCCBBDDBB---- --CAAAAAAAAAAAAAAAADBBDDD---- --AACACCCAACACACCAADBBBBAG--- ---AACAAAACAAAAAACCBDBBEC---- --ACACAACCAAAACAACABDFEFAE--- ---AAACAAAACACAAAAABF--F----- ----CAAAAACACAAAAAA-----F---- -----AAAAAAAAAAAAACA--C-E---- ------AAACAACAAAAA--CC------- ------A-A---AAAACC----------- 
-------BBBDDDBBBBB----------- -------DDBBBBBBBDBDDD--DDH--- --------BDDBBDDBBDBBBDDB-H--- --------BBBDBDBBBDBBDDBBBP--- -----AACAAAAABDDBBDBBBBDBP--- ---AAACAACAAADDBBDDBDBDBDDH-- -A-AAACCCAAAABBDBBBBDDBDBBH-- --CAAAAAAAACCBBBDBBDBDBB-R--- --AAAAACCAAAABBDDBBDBDDBBH--- -AAAACAAACACCDDDBDDDDDBDDJ--- -AAACAAAAAAAADBBDBDBBBBBBB-N- -CAAAACCCAAACDBBBBBBDDBBDBBJ- -CAAACDBBDBDBBDDBBBDDDBDDDB-- CACAACAABBBBDDDBBBBBBDDBQ---- CCAACAACDBBDBBDDDBDDBBBBBBBT- -AACCCAADBDDBBDDBBBDBBBABBV-- -AAAAAAABBBBDDBBBBBBDDBBDDB-- -AAAAAAACAAACAAAAACBBDDDBB--- --CAAACACCCCAAAAACCDBBBBB---- -AACAAAAAAAAAACCAAABDBBBB---- --CCAAAAAAACACCCAACBDBBB-E--- --AACACCCAAAAAAAACABDBDEG---- ---ACCAACAAAAAACCAABDE-AFG--- ----CACAAACAAACACACFE-------- -----AAAAAAAAAAAAAA-CE------- -------AAACAAAAAAAAAAA------- -------C---AAACAAAAC--------- 
-------DDBBBBBDBDDB---------- ------DBDBBBDBDDDDBBB--DHDH-- -------BDDDDBBBDBDBDDBBBBBD-- -----A--BDDDDBBBDDDDBBBBBBH-- ------AAAACCCBBBDBBBBBDDP---- ---AAA--CCAAABBDDBBBBBDBDP--- --CAACAAAAAAABDBBBBBBDBBDBB-- --AAAACAAACAADBDBBBBBDBBDD--- -CACAAAAACAACBDBDDBDBBBBBD--- -AAAACAACACAABBBDDBBBBDBDD--- -ACCAAAAAAAAABBBBBBBBDDBDBBN- -AAAAACAACCCABDBBDDDBBBBDBBE- CAAAABDBDDBDBBBDBBBBBDBBBDBM- AAACCAAABDBBDDBBBBDDDBBBQ---- AAAAACCABDBDBDBDDBBBBBDBDDJL- AAAAAAACDBBBBBBBDDBBDBBADDJ-- ACAAAACAACACAADDBDDDBBBBBBA-- -CCAACCCAAAAAAACAACDBDBDBB--- -AAAAAAACAAACCCAAAADBBDBBD--- -AAAACAAAACCAAAACCCBBDDBB---- --AACACAAAAAAAAAACCBBBBBD---- --CACCAAAACAAAAAACCDDDBBEE--- ---AAAAAAACAAACAAAADDDFF----- ---ACCAAAAACACAAAACDFG------- ----AAAAAAAAAAAAAAF----E----- -----A-ACAACCAAACCAAAA-F----- -------A--AAAAAAACAA-A------- 
-------BBBDBBDDBDBBB--------- ------DDBDDBBBBBBBBBB--DDBD-- -------BBDDBBBBBBBDDBDBDDDD-- -----A--BBDBDBDBDBBBBDDDBDD-- -------CCCAAABDBBBDDBDBBP---- ---AAA--AAAAADDDBBBBBDBBDP--- --AAACCCCCACABDBDBBDBBBBBBB-- -CAAACCAAAAAABBDBBBBDBBDBB--- -AAAAAAACAAAABBBBDBDBBBBDD--- -CCAAACACAAAABBDBBDBDBBBBBB-- AACAAAAAACACABBBBDBBBDBBDBDBB AAAAACAACAACABDDDBDBBDDBDDDDB AAACCDDDBDBBBBDBBBBBDBBBBBL-- ACAAADBDBBBBBDBBBBDBBDDBBDL-- CCCAACAADBBDBBDBBBDBBBBBBBB-- AAACAAAABDDBBDBBDBBBDBBBDBB-- CAAACACCACAAACAAAAABBBDDBDD-- -AACACACAACACCAAAAABBDBBBD--- -CAACAAAAAACAAAAAAADBDBDDK--- --AACAACAAACCAAAAACBBDDBDI--- -AAAAACAAAACCCAAACABDBBDD---- --ACCCACAACAAAAACACBBDBB-F--- ---AAACAAAAAAACAAACBBBBFA---- ---AAAACAAACAAAAAAAFFEG------ ----AACCAACAACCCAAF----E----- -----A-AAAAAACCAAAA---------- -------C-CACAAAAAAA---------- 
-------DBBBBBDBDDBBB--------- ------DBBDBBDBDBBBDBB--DDDD-- -------BBBBDBBBBDDBBDBDDDDD-- --------BBBBBBDBBDBBBBBDDBB-- -----A--CCAAABBDBBDDBDDBP---- --CAAC--AACAABBBBDBBBBBBDP--- --AACAAAAAAAABBBBBBBBBBBBDB-- -AAAACAACAACABBBBBDBDBBDBB--- -CAACAACAAAAADDBBBBBBDBBBD--- -ACCACCAAAAAABBDBDBBDBDBDBB-- AAAACCACAAAAADDBBDBDDDBDBBDBB -CACCACCACAAABBDBDBDBDDDBBBBB -AACADBDDBBBBBDDDBDBBBBDBBK-- -AAAADBBBBBBBDDBBDBDBBDDBBK-- -AAAAACABBBBDBBBBBBBBBDBBBI-- -AAAACACDBBDDBBBBBBBBDBBBBK-- -ACAAAAAACAAAAAACAABBBBBBBK-- AAAAAACAAAAAACCAACADDBDBBI--- AAAACAACAAAAAAACAACBBBBDBK--- --CAAAAACCCAAAAAAAABBBDDI---- -AAACAAAAACCAAACACCBBBDBD---- --ACAACCACAAACCAAAABDBBD----- ---ACACAAAAACCAACCCCABB-U---- ---AAAAACCAACAAACCAAC--E----- ----AAAAACCACCAAAACAA-A------ -----CCAAAAAAAACCAACAA------- -------AC---ACAACAAA--------- 
-------BBDBBDBBBDBDJ--------- ------DBDBBBDDDBBBBBB--DDDH-- -------DBBDBDBBBDBBBBBBDDBH-- -------AACAABDBBBBDBDBBBDBH-- -----C-ACAAAABBBBBDBBDDBP---- --AAAC-CCAAAABDBBBDDDBBDBP--- --ACCAAAAACACBBBBBDDDBBBBBD-- -CAAAAAACAACABDBDDBBBBDBB---- -AAAAAACAAAACBDDBBDDBBBBDB--- -AACAAAAAAAAABBBDBDBBDBBDK--- CCAAAACCCCAAABBDBBDBDBBDBO--- AACCACCAAAAAABBBDBBBBBBBDDOI- -CAAABBDBBBDDBDDDBBDBBDBBBL-- -AAACBDBBBDBBDBBBDDBDDBBBQ--- -CACACCADBBDBBBDBDDBDBBBBBL-- AAAAACAACBBBDBBBDBBBDBBBDBL-- AACAAAAAACCCAACAAAABDBDBDBI-- ACACCAAACAAAAAACAAABBDBBDK--- -AAACAAAAAAACAAAAAABBBBDBI--- -ACAAAAAAACCAAAAAACBBBBBI---- -AACAAACACAAAAACAAABBBDDB---- ---AAAAACAAACCACAAAACABB----- --AAACCAACAAACACAAAAAABF----- ---AAACAAAAAAAAAAACAAF-C----- ----CAACAAAAAAAACAAA--------- -----A-CAAAAACACAACA--------- -------A---ACAAC------------- 
-------BBBBBBBDBBDJ---------- ------DBBDBBBBDDBBBJJ---DH--- --------BBBBBBBBBBDBBDDDBB--- -------CAAAABDBBBBDDBBDBBP--- ---A---AAAAAACBBBBDBDDDBBP--- ---AAA-AAAAAAADBBDDDDBDBBDH-- --CAACAAACCAACBBBBBBDBDDBDH-- ---AAAAAACAAAABBDBDBBDBBBK--- -ACAACAAAAAAABDBBBDDBDDBDK--- -ACCAAACAAAAADDBDBDDDDDDBK--- -AAAAACAAAAAABDDBBBDBBDDDO--- AAACAAAAACACABDBDBBBDBBDBO-L- AAAACDBBCAAACBBDBBDBDDBDBDL-- CCACCBBBBDDDBBBBDDDDBDDBBQ--- AAAAAACAABDBDBBDBBBDBDDBBBDL- CCAAACAAADBDBBBBBDBDDDBABBL-- ACCAAAACAAAAAAACAAADBBBBDBI-- CAAACACAAAACAAAACAABBDBDDL--- -ACAAAACAAAAACAAACADBDBDDI--- AAACACAAAACACCCAACADBDDBB---- -AAAAACAAAAAAAAAAABDDBDDB---- --AAAAAACAAACCAAAAAAACBBD---- ---AACACACCACAAAAAAAADBG----- ---CAACAAAAAACACAAACA-G------ ----A-AAAACAAAAAACAAC-------- -----C-ACAAACACCAA-A--------- -------A---AACA--A----------- 
--------DDDDBBBDDD----------- -------BBBBDBDDBBBBJ--------- --------DBBBBBDBBBDBB--BDR--- -------AAAAABBBBBBDBDBD-DDH-- ------AAAAACAABDBBDDBDDDBBH-- ---AACAAAACAAABBDBBDBBDBDDH-- --AAAAAACACACABDBBBDBBBBBK--- --AACCACAAAACADDDBDBBBDBBI--- -AACAACCCAAAABDBDDDBBDDBI---- -CAACAACCCAACBBBBBBDBDDBLO--- -AAAAAAAAAAAABBBBDBDBBBBDO--- -AAAAACAACAAABDDBBBDDBBBDOOL- -AAAAAACAAAACBBBBBBDDBDDBBL-- AAAAADBBDBDBBBDBBDDBBBDBDQ--- AAACCAAAADBBBDBBBBDDBDBDBDBL- -AAAACCAAACACAACAAADBBBABDL-- -CCAACACCAAAAACCACADBDBBDI--- --AAAACCAAAACAAAAAABDBBDDK--- ACAAAAACAACAAAAACAABBBDBI---- CAAAAAACAAAAAAACAADDBDDBB---- --AACCAACCAAAAAACAAAABBD----- --ACACCAAACAAAACACACAABN----- ---AAAAAAAAAAAAAAAAAABG------ ----AAACAACACAACAAAABG------- ----CCAAACAAAAAACA--G-------- -----AC-AACAACAAC------------ --------CCA----AA------------ 
----------D-----D------------ --------DBBDDDDDBDJ---------- --------BDBBBDBDJJJ---------- -------ACCAADBBJJDDBB---B---- --------AAAAAABBBHBDBBDBBK--- ----CAC-AAACAADHDBDDDBBDBI--- ---AAAAAACACACBDBBDBBDBBI---- --ACCAACAACAAABDDBBBBDDBL---- --AAAACAACAAADBBBBBDDBDDLO--- --CACCAACCCAABBBDBBBBDBBLO--- --ACCAAAAAAAADBBDBBBDBBBW---- -AAAAACAAAAAADBDBBBBBBBDO-OO- -AACACCAAACAADBBBBBBBBBBILL-- -AAAAABBBBDDBBBBDDDDDDDBDQ--- -CAAAACACDBDDBDBBBBBDDDADIIL- -ACACAAAAAAACACAAACBDDBABI--- -ACAACCAAAAAAAAACAABBBBDKK--- AAAACCAAAAAAAACAACABBDDIK---- AAAAACCAAAAAACCAAABBDBBBI---- --CCCAAAACCCACAAAADBDBDK----- ---AAAAAAAAAAAAAACCACDBN----- ---ACAAAAAAAACACAAAAADG------ ----CCCCAACACACAAACCAG------- ----AACAACACACCACAAFG-------- -----AAAAAACAAAAAA----------- ------CA-C-AAAA--A----------- ----------CAAACA------------- 
----------------------------- --------B-DBBBBDH------------ --------BBBBBBBH------------- --------CAAAD---------------- --------AAAAAA-------DBDK---- ----A-----ACAC---HBBDBDKI---- ----AAAAAACAAACABBDBBBDKI---- ---AAAAAACAAACAABDBDBBKKI---- ---CAAAAAAAAABDBDBDDDDKII---- --ACACCCAAACABBDDDDBDBKI----- --AAAAAAAAAAABDDDBBBBBBI----- --ACCAAAAAAAABBBBBBBBBBI---N- --AAAAAAAAAAABDDBBBDBBBI---L- --AAAACDBBDDBBBBDBBBDDDB-MML- -CACACACADBBDDBBBBBBDBIII---- -AAAAAACAACACCAAAAABBDIII---- -AAAACCAAAAAACAAACADBKII----- --ACAAAAAAAAAAACAABDBBK-I---- ---CACAACCACCCAAAABBDBBK----- --AAAACCAAAAAAACACBBBBDN----- ---CCAAAAAAACCAAACAACBG------ ---ACACAAAACCAACAAAEEG------- ----AAAACAACACCAAAAE--------- -----ACACACAACAACC----------- ------AAAAACAAAAAC----------- ---------CCAACAA------------- ----------------------------- 
----------------------------- ----------------------------- ----------------------------- ---------AAA----------------- ---------ACC----------------- ----------------------------- -----CACAA--AA--C-----H------ ----AAAACCAAC-A-A-DHH-------- ---AACCAAACCAABBABDBHH------- ---ACAAAACAAAABABBBDBB------- ---CAAAAACAAABBBBBDBBDK------ ---AACACAACCCBDDBBBBBBK------ --ACCACACAAACDBBDBBBBDK------ --AACCAABBBBDBBBBBBDBDBDM---- --AAACAABBBBBBDBDDDBDK------- --AAAACCAAAAAAAAACCDBK------- --ACAAAAAACACACCAAADD-------- --AAACAAAAACAAAACCBBBK------- --AAAAAAAACACAAAAADBBC------- --AAAAAAAACACACCCABFFE------- ---AAAAAACACAAAACACEG-------- ----AACAAAACCAACCCE---------- -----AAACACAAAACACC---------- ------AAA-CCACAAAA----------- --------ACA---AAA------------ ----------------------------- ----------------------------- 
----------------------------- ----------------------------- ----------------------------- ----------------------------- ----------------------------- ----------------------------- -------C---A----------------- -----AAAAAA-----A------------ ----AACAAAACC-ACAAA---------- ----CAACAAACA-ABCBA---------- ----ACAAACAACC-BBABG--------- ---AAAAAACAAAABBDAA---------- ---AAAACAAAAACDDBDAC--------- ---AACAAABBDBBDDDBCMMMMM----- --AACACAAACAAABBDBMA--------- --AAAAAACAAAACAAEAEC--------- --CAAACACCAACAAAECBE--------- --AAAACAAAACAAAAAADE--------- ---CAAACAAAAAACAAABFG-------- ---ACCAAACACAAACAAFGG-------- ----AAAAAAAACCAACAE---------- ----AAAACAACACACAE----------- ------AAACCAAAAAA------------ --------ACAACAAAC------------ ----------AAAA--------------- ----------------------------- ----------------------------- 
----------------------------- ----------------------------- ----------------------------- ----------------------------- ----------------------------- ----------------------------- ----------------------------- -------CAC------------------- ------CACAAA-----A----------- -----CAAAAAAA--AAAA---------- -----AAAAACCA-ABB-A---------- ----CCCCCAAAAACAD-AG--------- ----AACCACAAACDDB--G--------- ---AAAAAAAAABBBBBE----------- ---AAAAAAAACACAACE----------- ---CACAAAAAAAAAE------------- ---AAAACAACAACCC--G---------- ---AAAAACACCCAAAGGG---------- ---CCCAAACACCAAA-AEG--------- ----AACACAAAAACAAAE---------- ----ACAAAAAAACAAAA----------- -----AAAACCAAAAAA------------ -------AAAACCAAAC------------ ----------AAACAA------------- ----------------------------- ----------------------------- ----------------------------- 
----------------------------- ----------------------------- ----------------------------- ----------------------------- ----------------------------- ----------------------------- ----------------------------- ----------------------------- ---------C------------------- -------AAACA----------------- ------AAAAAAAA-A------------- -----AAAAAAAA-AD------------- -----ACAAAAACAAD------------- ----AAACAAAAACACD------------ ----CCACCCAAAAFFG------------ ----AACAAAAACAA-------------- ----AAAAAAAAAACG------------- ----AAACACACACA-C------------ ----AACAAAAACAC-AA----------- ----AACAACAAAACCAA----------- -----CAAACACCCCAA------------ ------AAAAACAAAAC------------ ----------AAACAA------------- ----------------------------- ----------------------------- ----------------------------- ----------------------------- 
----------------------------- ----------------------------- ----------------------------- ----------------------------- ----------------------------- ----------------------------- ----------------------------- ----------------------------- ----------------------------- ----------------------------- --------CC------------------- ------CACAA----A------------- ------AAAAACF-AA------------- ------ACCAACE---------------- -----AAAAAAAEE--------------- ----CAAAAAAACFE-------------- ----CAACAAAAAAAA------------- -----CAAAAACCA-C------------- -----AAAACAAAC-AE------------ ------AAAAAAACACA------------ -------AAAAAAACA------------- ----------AAAAC-------------- ----------------------------- ----------------------------- ----------------------------- ----------------------------- ----------------------------- 
----------------------------- ----------------------------- ----------------------------- ----------------------------- ----------------------------- ----------------------------- ----------------------------- ----------------------------- ----------------------------- ----------------------------- ----------------------------- ----------------------------- --------AAA------------------ ------AACAAC----------------- ------AAAAAC----------------- -----AAACACAF---------------- -----AAAAACAAEEE------------- ------ACACAAAAECE------------ ------CAACCACAAE------------- -------AAAAAAACC------------- ----------AAAA--------------- -------------A--------------- ----------------------------- ----------------------------- ----------------------------- ----------------------------- ----------------------------- 
----------------------------- ----------------------------- ----------------------------- ----------------------------- ----------------------------- ----------------------------- ----------------------------- ----------------------------- ----------------------------- ----------------------------- ----------------------------- ----------------------------- ----------------------------- ----------------------------- --------CA------------------- -------CAAAA----------------- --------AACAC---------------- ---------AAA----------------- --------CA-A----------------- ------------A---------------- ----------------------------- ----------------------------- ----------------------------- ----------------------------- ----------------------------- ----------------------------- ----------------------------- 
----------------------------- ----------------------------- ----------------------------- ----------------------------- ----------------------------- ----------------------------- ----------------------------- ----------------------------- ----------------------------- ----------------------------- ----------------------------- ----------------------------- ----------------------------- ----------------------------- --------AA-A----------------- --------AACAF---------------- ----------AA----------------- ----------------------------- ----------------------------- ----------------------------- ----------------------------- ----------------------------- ----------------------------- ----------------------------- ----------------------------- ----------------------------- ----------------------------- 
