model
size = 29 27 27, scale = 0.05, origin = -y
material 
  colors = A:#111 B:#FC6 C:#222 D:#F4C874 E:#888 F:#DAAF57 G:#AAA H:#B69248 I:#EEE J:#777 K:#BBB L:#92763A M:#4A3D1D N:#D3BDA0 O:#DDD P:#633 Q:#26200E R:#996
voxels
----------------------------- ----------------------------- ----------------------------- ----------------------------- ----------------------------- ----------------------------- ----------------------------- ----------------------------- ----------------------------- ----------------------------- ----------------------------- ----------------------------- --------A-------------------- -------A--------------------- --------AA------------------- ----------------------------- ----------------------------- ----------------------------- ----------------------------- ----------------------------- ----------------------------- ----------------------------- ----------------------------- ----------------------------- ----------------------------- ----------------------------- ----------------------------- 
----------------------------- ----------------------------- ----------------------------- ----------------------------- ----------------------------- ----------------------------- ----------------------------- ----------------------------- ----------------------------- ----------------------------- ----------------------------- --------C-------------------- ------AAAAC------------------ ----------AA----------------- --------A-AA----C------------ -------C-AA----AA------------ ------C---CAC-A-C------------ -------A---AA--AA------------ ---------AAA----------------- --------CAAA-A--A------------ ----------AA--A-------------- ----------------------------- ----------------------------- ----------------------------- ----------------------------- ----------------------------- ----------------------------- 
----------------------------- ----------------------------- ----------------------------- ----------------------------- ----------------------------- ----------------------------- ----------------------------- ----------------------------- ----------------------------- --------A-------------------- -------CA-A------------------ -------AAA-AA---------------- -----ACCAA--A---------------- -------AAAACA-A-------------- ----AAAAAAAACC--AA----------- ------AAAAACAA-AC------------ ------CA-CAAAAAAC------------ ------CAACCAACAAC------------ ------AA-AACA-CAA------------ --------AAAACAA-C------------ ---------ACC-C--A------------ --------------C-------------- ----------------------------- ----------------------------- ----------------------------- ----------------------------- ----------------------------- 
----------------------------- ----------------------------- ----------------------------- ----------------------------- ----------------------------- ----------------------------- ----------------------------- ----------------------------- ---------A------------------- --------AA------------------- -------AAAA---AA------------- ------AAACAAC-C-------------- -----CAAAAAAAAA-------------- -----ACCACAAAACCA------------ ----CAAAAACACAA-AA----------- ----CAACAAAAAAAAC--I--------- ----ACCAACAAACAAA------------ -----AAAAACAACCAA------------ -----CCCCCACAACAA------------ -----CAAAAAAAAAAC------------ -------AAACAAAC-A------------ ---------CAC--AAA------------ -----------A----------------- -----------A----------------- ----------------------------- ----------------------------- ----------------------------- 
----------------------------- ----------------------------- ----------------------------- ----------------------------- ----------------------------- ----------------------------- ----------------------------- ----------C------------------ --------AAC------------------ ------CAAAC------------------ -----CAAAAAAA-DD------------- -----AACAAAAAAACB------------ ----AACAACAACACAA------------ ----ACAACAAAAAACAA----------- ---AAAAAAAACAAAAAE----------- ----CACCACAAAAAAAI-A--------- ----ACACAAACACCAC--I--------- ----CAAACAAAAACA-AI---------- ----CCAACAAACCAC------------- ----AAAAAACACAC-------------- -----CACCCAAAA--A------------ ------AAAAAAC-CCC------------ -------C-ACA--ACA------------ -----------AA-A-------------- ----------------------------- ----------------------------- ----------------------------- 
----------------------------- ----------------------------- ----------------------------- ----------------------------- ----------------------------- ----------------------------- ----------------------------- -------AAA------JJ----------- -----AAAAAC------C----------- ----CAAAACAC----DAC---------- ----AAAAAAAAAA-BBCC---------- -----ACAAAAAACAAAGA---------- ----CAAAAAACAACAAEA---------- ----ACAAAACCAAAABEA---------- ---CAACAAAAAAAAABECC--------- ---AAAAAAAAACCCAGEGG--------- ---AAAAAAACCAAAA-A----------- ---AACACACAAAACG-C-G--------- ---AACACAAAACAAE-A----------- ----AAAAAAACAAC--G-I--------- ----CACCCAAAAAA--E--II------- -----AAAACCAAG--------------- ------CCCCAAG--E------------- ---------AACCACCC------------ -----------AA---------------- ----------------------------- ----------------------------- 
----------------------------- ----------------------------- ----------------------------- ----------------------------- --------AA------------------- ---------------A------------- -----------A----------------- -----AACAAA-----AA----------- ----AACAAACA----BBA---------- -C-CAAAAACAAAA-CCDBD--------- ----AACCAACAACCBDACBB-------- -AAAAAACAACCACCABBBAD-------- --AAAAAAACAAAAACDBDBD-------- --AAACCADBBAAACADBGKKKK------ --CCAAAABDBBACCCBDBBH-------- --AAAACAADBDAAAABBDDD-------- --ACAAAAADBDDBDDBDGGC-------- ---AAAACCBBBDBBBEBEBCG------- ---ACCAAACAAACCCCAG-GAI------ ---CAACACAACAAAACACAIE------- ----AAAAAAAAACAAA-AAACEG----- ----AACCAAACAAA---AIIJIIG---- ------AAAAACA---AA------I---- -------AAAAAAAAAA----E------- ---------AA-AA--------------- ------------C---------------- ----------------------------- 
----------------------------- ---------BBDF---------------- ---------BBBDDF-------------- ----------------H------------ -------A-CC-----D------------ ---------ACA--AAA------------ ----AAACAA-CAAA-A-LFFFDBF---- ---CCCAAAACC-A--BBBBDBDBH---- --AACAAAAAACACADABDFABBDH---- ---AAACACAAAAAABBDDDBDBH----- -A-AAAACAAAACCADBBBBBDD------ --AACAACAACAAAABBDBBBBB----J- --AAAAAABBBBBBBDBDBBDBD----K- --ACCACADBBBDBBBDBBBBBBOKOOO- --AAAAACBDDBBBBBBBDBBDH------ -AAAAAAABDBBBBDBDBBBDDD------ --AAAACADBDBDBDBBDBBDBD------ --AACCAAACACACACAAABDB-C----- ---ACACACAAAAAAAAAAGDBGG----- ---CAACAAACACCAAAAABEDE------ ---ACCAAAAAACCCAAAADB-CG-EI-- ----AAACCCAACAAAAAAAE-JAG---- -----CAAACCAAACCCAAA---GG---- ------CAAAAAACCAAAA---G------ -------ACAAAAACCAA----A------ --------AACACCA-------------- ------------C---------------- 
----------------------------- --------DBBBBDBBF------------ --------BDBBBDDH------------- ------------BDDBBH-----H----- ------AAACACAA-BBDDDBBBDDH--- -----A---ACC-CBDDADBBDDDBH--- ---ACACAAAAA--DADLBBDBBBDL--- -A-AACCCAAAAABBBBDBDDDBBL---- --CAAAAAAAAA-DDBBBDBBBDBH---- --AAAAACCCAAADDBDDDDBBDDH---- -AAAACAAAAAACBBBBDBDBDBHHB-J- -CACAAABBBDBBDBDDDBBDBBBBB--- --AAAACDBBDBBBBBBBBBDBBBB-M-- -AACAAADDBBBDBDBBBDDBBBBB-B-- -AACAAADBBBBDBBDBDBBBBDBBBN-- -ACCACABBBBBBDBBBDBBBDBDQH--- -AAACACBBDDDDDDDDBBBDBBBB---- -ACAACAAAAAAAACAACABBBDD----- --ACACAAACCAAAAACAADBBBBA---- --AAACCAACACACACCACBBBDE-R--- ---AAAACAAAAAAAAAACBDB--GGI-- ----CCAAACCACAAAACABDA--GEI-- ----CCAACACCAAAAACCAJ---G---- -----AAAAACAAAACCAAA---E----- ------ACACCACAAAAAA---A------ -------AAAAAAAAAAA----A------ -------A-AAA-AA-A------------ 
--------BDDBDBBBB------------ --------BBDDBBBBDFH---------- --------BBBBBBBBBDDD--BDDD--- --------DBBBBBDBBBBBBDDBDDF-- ------AACACAABBDBDBAABDDDDF-- ----AA--AAAACBBBBDDDDDBBBBF-- ---ACACCCCC-ABDBDBBBDBBDBH--- -AAAAACAAAACCBBBBBBBDDBBDH--- --AAAAACAAAAADDBDDDBDBDBH---- -CCAACACCCACABBBBBBBBBDBH---- -C-AAAAAAACAADBBDDBBBBBDB--J- -ACACCACAAAAABDBDDBBBBBBB-BH- -CAAAABDBBBDBBDDBBBDBBBBB-DF- -AAAAACCBDBDDBDDBBDBDBDBBDBM- -AAAAAAABBDBBBBBDBBBDBBADBBN- -CAAAAAABBDDDBBBBDBBBBBCBBA-- -AACACCABBBBBDDBDBBDDBBBDB--- -AAACAAACACACCCACCCBBDDBB---- --CAAAAAAAAAAAAAAAADBBDDD---- --AACACCCAACACACCAADBBBBAI--- ---AACAAAACAAAAAACCBDBBEC---- --ACACAACCAAAACAACABDGEGAE--- ---AAACAAAACACAAAAABG--G----- ----CAAAAACACAAAAAA-----G---- -----AAAAAAAAAAAAACA--C-E---- ------AAACAACAAAAA--CC------- ------A-A---AAAACC----------- 
-------BBBDDDBBBBB----------- -------DDBBBBBBBDBDDD--DDF--- --------BDDBBDDBBDBBBDDB-F--- --------BBBDBDBBBDBBDDBBBF--- -----AACAAAAABDDBBDBBBBDBPL-- ---AAACAACAAADDBBDDBDBDBDDF-- -A-AAACCCAAAABBDBBBBDDBDBBF-- --CAAAAAAAACCBBBDBBDBDBB-L--- --AAAAACCAAAABBDDBBDBDDBBF--- -AAAACAAACACCDDDBDDDDDBDDH--- -AAACAAAAAAAADBBDBDBBBBBBB-J- -CAAAACCCAAACDBBBBBBDDBBDBBH- -CAAACDBBDBDBBDDBBBDDDBDDDBF- CACAACAABBBBDDDBBBBBBDDBBBBM- CCAACAACDBBDBBDDDBDDBBBBBBBN- -AACCCAADBDDBBDDBBBDBBBABBQ-- -AAAAAAABBBBDDBBBBBBDDBBDDB-- -AAAAAAACAAACAAAAACBBDDDBB--- --CAAACACCCCAAAAACCDBBBBB---- -AACAAAAAAAAAACCAAABDBBBB---- --CCAAAAAAACACCCAACBDBBB-E--- --AACACCCAAAAAAAACABDBDEI---- ---ACCAACAAAAAACCAABDE-AGI--- ----CACAAACAAACACACGE-------- -----AAAAAAAAAAAAAA-CE------- -------AAACAAAAAAAAAAA------- -------C---AAACAAAAC--------- 
-------DDBBBBBDBDDB---------- -------BDBBBDBDDDDBBB--DFDF-- -------BDDDDBBBDBDBDDBBBBBF-- -----A--BDDDDBBBDDDDBBBBBBF-- ------AAAACCCBBBDBBBBBDDDBF-- ---AAA--CCAAABBDDBBBBBDBDPL-- --CAACAAAAAAABDBBBBBBDBBDBF-- --AAAACAAACAADBDBBBBBDBBDDF-- -CACAAAAACAACBDBDDBDBBBBBDB-- -AAAACAACACAABBBDDBBBBDBDD--- -ACCAAAAAAAAABBBBBBBBDDBDBBJ- -AAAAACAACCCABDBBDDDBBBBDBBE- CAAAABDBDDBDBBBDBBBBBDBBBDBK- AAACCAAABDBBDDBBBBDDDBBBBBBK- AAAAACCABDBDBDBDDBBBBBDBDDH-- AAAAAAACDBBBBBBBDDBBDBBADDH-- ACAAAACAACACAADDBDDDBBBBBBA-- -CCAACCCAAAAAAACAACDBDBDBB--- -AAAAAAACAAACCCAAAADBBDBBD--- -AAAACAAAACCAAAACCCBBDDBB---- --AACACAAAAAAAAAACCBBBBBD---- --CACCAAAACAAAAAACCDDDBBEE--- ---AAAAAAACAAACAAAADDDGG----- ---ACCAAAAACACAAAACDGI------- ----AAAAAAAAAAAAAAG----E----- -----A-ACAACCAAACCAAAA-G----- -------A--AAAAAAACAA-A------- 
-------BBBDBBDDBDBBB--------- -------DBDDBBBBBBBBBB--DDBF-- -------BBDDBBBBBBBDDBDBDDDF-- -----A--BBDBDBDBDBBBBDDDBDD-- -------CCCAAABDBBBDDBDBBDBD-- ---AAA--AAAAADDDBBBBBDBBDPL-- --AAACCCCCACABDBDBBDBBBBBBB-- -CAAACCAAAAAABBDBBBBDBBDBBF-- -AAAAAAACAAAABBBBDBDBBBBDDB-- -CCAAACACAAAABBDBBDBDBBBBBB-- AACAAAAAACACABBBBDBBBDBBDBDBB AAAAACAACAACABDDDBDBBDDBDDDDB AAACCDDDBDBBBBDBBBBBDBBBBBD-- ACAAADBDBBBBBDBBBBDBBDDBBDJ-- CCCAACAADBBDBBDBBBDBBBBBBBB-- AAACAAAABDDBBDBBDBBBDBBBDBB-- CAAACACCACAAACAAAAABBBDDBDD-- -AACACACAACACCAAAAABBDBBBD--- -CAACAAAAAACAAAAAAADBDBDDD--- --AACAACAAACCAAAAACBBDDBDB--- -AAAAACAAAACCCAAACABDBBDD---- --ACCCACAACAAAAACACBBDBB-G--- ---AAACAAAAAAACAAACBBBBGA---- ---AAAACAAACAAAAAAAGGEI------ ----AACCAACAACCCAAG----E----- -----A-AAAAAACCAAAA---------- -------C-CACAAAAAAA---------- 
-------DBBBBBDBDDBBB--------- -------BBDBBDBDBBBDBB--DDDF-- -------BBBBDBBBBDDBBDBDDDDF-- --------BBBBBBDBBDBBBBBDDBD-- -----A--CCAAABBDBBDDBDDBBDD-- --CAAC--AACAABBBBDBBBBBBDPL-- --AACAAAAAAAABBBBBBBBBBBBDB-- -AAAACAACAACABBBBBDBDBBDBBF-- -CAACAACAAAAADDBBBBBBDBBBDB-- -ACCACCAAAAAABBDBDBBDBDBDBB-- AAAACCACAAAAADDBBDBDDDBDBBDBB -CACCACCACAAABBDBDBDBDDDBBBBB -AACADBDDBBBBBDDDBDBBBBDBBB-- -AAAADBBBBBBBDDBBDBDBBDDBBJ-- -AAAAACABBBBDBBBBBBBBBDBBBB-- -AAAACACDBBDDBBBBBBBBDBBBBB-- -ACAAAAAACAAAAAACAABBBBBBBB-- AAAAAACAAAAAACCAACADDBDBBB--- AAAACAACAAAAAAACAACBBBBDBD--- --CAAAAACCCAAAAAAAABBBDDBB--- -AAACAAAAACCAAACACCBBBDBD---- --ACAACCACAAACCAAAABDBBD----- ---ACACAAAAACCAACCCCABB-R---- ---AAAAACCAACAAACCAAC--E----- ----AAAAACCACCAAAACAA-A------ -----CCAAAAAAAACCAACAA------- -------AC---ACAACAAA--------- 
-------BBDBBDBBBDBDH--------- -------BDBBBDDDBBBBBB--DDDF-- -------DBBDBDBBBDBBBBBBDDBF-- -------AACAABDBBBBDBDBBBDBF-- -----C-ACAAAABBBBBDBBDDBBDD-- --AAAC-CCAAAABDBBBDDDBBDBPL-- --ACCAAAAACACBBBBBDDDBBBBBF-- -CAAAAAACAACABDBDDBBBBDBBBF-- -AAAAAACAAAACBDDBBDDBBBBDBB-- -AACAAAAAAAAABBBDBDBBDBBDH--- CCAAAACCCCAAABBDBBDBDBBDBDDJ- AACCACCAAAAAABBBDBBBBBBBDDDG- -CAAABBDBBBDDBDDDBBDBBDBBBDE- -AAACBDBBBDBBDBBBDDBDDBBBDBO- -CACACCADBBDBBBDBDDBDBBBBBH-- AAAAACAACBBBDBBBDBBBDBBBDBH-- AACAAAAAACCCAACAAAABDBDBDBA-- ACACCAAACAAAAAACAAABBDBBDD--- -AAACAAAAAAACAAAAAABBBBDBB--- -ACAAAAAAACCAAAAAACBBBBBD---- -AACAAACACAAAAACAAABBBDDB---- ---AAAAACAAACCACAAAACABB----- --AAACCAACAAACACAAAAAABG----- ---AAACAAAAAAAAAAACAAG-C----- ----CAACAAAAAAAACAAA--------- -----A-CAAAAACACAACA--------- -------A---ACAAC------------- 
-------BBBBBBBDBBDH---------- -------BBDBBBBDDBBBHH---DF--- --------BBBBBBBBBBDBBDDDBB--- -------CAAAABDBBBBDDBBDBBF--- ---A---AAAAAACBBBBDBDDDBBPL-- ---AAA-AAAAAAADBBDDDDBDBBDF-- --CAACAAACCAACBBBBBBDBDDBDF-- ---AAAAAACAAAABBDBDBBDBBBL--- -ACAACAAAAAAABDBBBDDBDDBDF--- -ACCAAACAAAAADDBDBDDDDDDBH--- -AAAAACAAAAAABDDBBBDBBDDDB-J- AAACAAAAACACABDBDBBBDBBDBBBB- AAAACDBBCAAACBBDBBDBDDBDBDDF- CCACCBBBBDDDBBBBDDDDBDDBBBBM- AAAAAACAABDBDBBDBBBDBDDBBBDN- CCAAACAAADBDBBBBBDBDDDBABBQ-- ACCAAAACAAAAAAACAAADBBBBDBH-- CAAACACAAAACAAAACAABBDBDDB--- -ACAAAACAAAAACAAACADBDBDDB--- AAACACAAAACACCCAACADBDDBB---- -AAAAACAAAAAAAAAAABDDBDDB---- --AAAAAACAAACCAAAAAAACBBD---- ---AACACACCACAAAAAAAADBI----- ---CAACAAAAAACACAAACA-I------ ----A-AAAACAAAAAACAAC-------- -----C-ACAAACACCAA-A--------- -------A---AACA--A----------- 
--------DDDDBBBDDD----------- -------BBBBDBDDBBBBH--------- --------DBBBBBDBBBDBB--BDF--- -------AAAAABBBBBBDBDBDDDDF-- ------AAAAACAABDBBDDBDDDBBF-- ---AACAAAACAAABBDBBDBBDBDDF-- --AAAAAACACACABDBBBDBBBBBL--- --AACCACAAAACADDDBDBBBDBBH--- -AACAACCCAAAABDBDDDBBDDBF---- -CAACAACCCAACBBBBBBDBDDBD---- -AAAAAAAAAAAABBBBDBDBBBBDD-J- -AAAAACAACAAABDDBBBDDBBBDBDB- -AAAAAACAAAACBBBBBBDDBDDBBBF- AAAAADBBDBDBBBDBBDDBBBDBDDBM- AAACCAAAADBBBDBBBBDDBDBDBDBN- -AAAACCAAACACAACAAADBBBABDQ-- -CCAACACCAAAAACCACADBDBBDD--- --AAAACCAAAACAAAAAABDBBDDB--- ACAAAAACAACAAAAACAABBBDBB---- CAAAAAACAAAAAAACAADDBDDBB---- --AACCAACCAAAAAACAAAABBD----- --ACACCAAACAAAACACACAABJ----- ---AAAAAAAAAAAAAAAAAABI------ ----AAACAACACAACAAAABI------- ----CCAAACAAAAAACA--I-------- -----AC-AACAACAAC------------ --------CCA----AA------------ 
----------D-----D------------ --------DBBDDDDDBDH---------- --------BDBBBDBDHHH---------- -------ACCAADBBHHDDBBB--BB--- --------AAAAAABBBFBDBBDBBL--- ----CAC-AAACAADFDBDDDBBDBH--- ---AAAAAACACACBDBBDBBDBBBL--- --ACCAACAACAAABDDBBBBDDBL---- --AAAACAACAAADBBBBBDDBDDH---- --CACCAACCCAABBBDBBBBDBBF---- --ACCAAAAAAAADBBDBBBDBBBB--J- -AAAAACAAAAAADBDBBBBBBBDB-B-- -AACACCAAACAADBBBBBBBBBBBDM-- -AAAAABBBBDDBBBBDDDDDDDBDBBB- -CAAAACACDBDDBDBBBBBDDDADDN-- -ACACAAAAAAACACAAACBDDBABH--- -ACAACCAAAAAAAAACAABBBBDDD--- AAAACCAAAAAAAACAACABBDDBB---- AAAAACCAAAAAACCAAABBDBBBA---- --CCCAAAACCCACAAAADBDBDA----- ---AAAAAAAAAAAAAACCACDBJ----- ---ACAAAAAAAACACAAAAADI------ ----CCCCAACACACAAACCAI------- ----AACAACACACCACAAGI-------- -----AAAAAACAAAAAA----------- ------CA-C-AAAA--A----------- ----------CAAACA------------- 
----------------------------- --------B-DBBBBDF------------ --------BBBBBBBF------------- --------CAAAD---------------- --------AAAAAA-------DBDB---- ----A-----ACAC---FBBDBDBF---- ----AAAAAACAAACABBDBBBDBH---- ---AAAAAACAAACAABDBDBBBBH---- ---CAAAAAAAAABDBDBDDDDFBF---- --ACACCCAAACABBDDDDBDBFDF---- --AAAAAAAAAAABDDDBBBBBBH----- --ACCAAAAAAAABBBBBBBBBBB---E- --AAAAAAAAAAABDDBBBDBBBK---K- --AAAACDBBDDBBBBDBBBDDDB-KKO- -CACACACADBBDDBBBBBBDBBBH---- -AAAAAACAACACCAAAAABBDBBD---- -AAAACCAAAAAACAAACADBDBB----- --ACAAAAAAAAAAACAABDBBD-A---- ---CACAACCACCCAAAABBDBBA----- --AAAACCAAAAAAACACBBBBDJ----- ---CCAAAAAAACCAAACAACBI------ ---ACACAAAACCAACAAAEEI------- ----AAAACAACACCAAAAE--------- -----ACACACAACAACC----------- ------AAAAACAAAAAC----------- ---------CCAACAA------------- ----------------------------- 
----------------------------- ----------------------------- ----------------------------- ---------AAA----------------- ---------ACC----------------- ----------------------------- -----CACAA--AA--C------------ ----AAAACCAAC-A-A-DFF-------- ---AACCAAACCAABBABDBFF------- ---ACAAAACAAAABABBBDBB------- ---CAAAAACAAABBBBBDBBDB------ ---AACACAACCCBDDBBBBBBBF----- --ACCACACAAACDBBDBBBBDB------ --AACCAABBBBDBBBBBBDBDBDK---- --AAACAABBBBBBDBDDDBDB------- --AAAACCAAAAAAAAACCDBB------- --ACAAAAAACACACCAAADDB------- --AAACAAAAACAAAACCBBBC------- --AAAAAAAACACAAAAADBBC------- --AAAAAAAACACACCCABGGE------- ---AAAAAACACAAAACACEI-------- ----AACAAAACCAACCCE---------- -----AAACACAAAACACC---------- ------AAA-CCACAAAA----------- --------ACA---AAA------------ ----------------------------- ----------------------------- 
----------------------------- ----------------------------- ----------------------------- ----------------------------- ----------------------------- ----------------------------- -------C---A----------------- -----AAAAAA-----A------------ ----AACAAAACC-ACAAA---------- ----CAACAAACA-ABCBA---------- ----ACAAACAACC-BBABI--------- ---AAAAAACAAAABBDAA---------- ---AAAACAAAAACDDBDAC--------- ---AACAAABBDBBDDDBCKKKKK----- --AACACAAACAAABBDBKA--------- --AAAAAACAAAACAAEAEC--------- --CAAACACCAACAAAECBE--------- --AAAACAAAACAAAAAADE--------- ---CAAACAAAAAACAAABGI-------- ---ACCAAACACAAACAAGII-------- ----AAAAAAAACCAACAE---------- ----AAAACAACACACAE----------- ------AAACCAAAAAA------------ --------ACAACAAAC------------ ----------AAAA--------------- ----------------------------- ----------------------------- 
----------------------------- ----------------------------- ----------------------------- ----------------------------- ----------------------------- ----------------------------- ----------------------------- -------CAC------------------- ------CACAAA-----A----------- -----CAAAAAAA--AAAA---------- -----AAAAACCA-ABB-A---------- ----CCCCCAAAAACAD-AI--------- ----AACCACAAACDDB--I--------- ---AAAAAAAAABBBBBE----------- ---AAAAAAAACACAACE----------- ---CACAAAAAAAAAE------------- ---AAAACAACAACCC--I---------- ---AAAAACACCCAAAIII---------- ---CCCAAACACCAAA-AEI--------- ----AACACAAAAACAAAE---------- ----ACAAAAAAACAAAA----------- -----AAAACCAAAAAA------------ -------AAAACCAAAC------------ ----------AAACAA------------- ----------------------------- ----------------------------- ----------------------------- 
----------------------------- ----------------------------- ----------------------------- ----------------------------- ----------------------------- ----------------------------- ----------------------------- ----------------------------- ---------C------------------- -------AAACA----------------- ------AAAAAAAA-A------------- -----AAAAAAAA-AD------------- -----ACAAAAACAAD------------- ----AAACAAAAACACD------------ ----CCACCCAAAAGGI------------ ----AACAAAAACAA-------------- ----AAAAAAAAAACI------------- ----AAACACACACA-C------------ ----AACAAAAACAC-AA----------- ----AACAACAAAACCAA----------- -----CAAACACCCCAA------------ ------AAAAACAAAAC------------ ----------AAACAA------------- ----------------------------- ----------------------------- ----------------------------- ----------------------------- 
----------------------------- ----------------------------- ----------------------------- ----------------------------- ----------------------------- ----------------------------- ----------------------------- ----------------------------- ----------------------------- ----------------------------- --------CC------------------- ------CACAA----A------------- ------AAAAACG-AA------------- ------ACCAACE---------------- -----AAAAAAAEE--------------- ----CAAAAAAACGE-------------- ----CAACAAAAAAAA------------- -----CAAAAACCA-C------------- -----AAAACAAAC-AE------------ ------AAAAAAACACA------------ -------AAAAAAACA------------- ----------AAAAC-------------- ----------------------------- ----------------------------- ----------------------------- ----------------------------- ----------------------------- 
----------------------------- ----------------------------- ----------------------------- ----------------------------- ----------------------------- ----------------------------- ----------------------------- ----------------------------- ----------------------------- ----------------------------- ----------------------------- ----------------------------- --------AAA------------------ ------AACAAC----------------- ------AAAAAC----------------- -----AAACACAG---------------- -----AAAAACAAEEE------------- ------ACACAAAAECE------------ ------CAACCACAAE------------- -------AAAAAAACC------------- ----------AAAA--------------- -------------A--------------- ----------------------------- ----------------------------- ----------------------------- ----------------------------- ----------------------------- 
----------------------------- ----------------------------- ----------------------------- ----------------------------- ----------------------------- ----------------------------- ----------------------------- ----------------------------- ----------------------------- ----------------------------- ----------------------------- ----------------------------- ----------------------------- ----------------------------- --------CA------------------- -------CAAAA----------------- --------AACAC---------------- ---------AAA----------------- --------CA-A----------------- ------------A---------------- ----------------------------- ----------------------------- ----------------------------- ----------------------------- ----------------------------- ----------------------------- ----------------------------- 
----------------------------- ----------------------------- ----------------------------- ----------------------------- ----------------------------- ----------------------------- ----------------------------- ----------------------------- ----------------------------- ----------------------------- ----------------------------- ----------------------------- ----------------------------- ----------------------------- --------AA-A----------------- --------AACAG---------------- ----------AA----------------- ----------------------------- ----------------------------- ----------------------------- ----------------------------- ----------------------------- ----------------------------- ----------------------------- ----------------------------- ----------------------------- ----------------------------- 
