model
size = 15 20 8, scale = 0.05, origin = -y
material 
  colors = A:#FF4364 B:#FFC86B C:#F3E1C9 D:#FCDFAC E:#1A222F F:#FFF
voxels
--------------- --------------- --------------- --------------- --------------- --------------- --------------- --------------- --------------- --------------- --AAAAAAAAAA--- --AAAAAAAAAA--- BBBBBBAAEEAA--- BBBBBBAAEEAA--- --AAAAAAAAAA--- --AAAAAAAAAA--- --AAAAAAAAAA--- --AAAAAAAAAA--- --AAAAAAAAAA--- --------------- 
--------------- --------------- --------------- ------AAA------ --------------- --------------- --------------- --------------- --------------- --------------- --AAAAAAAAAA--- --AAAAAAAAAA--- BBAAAAAAAAAA--- BBAAAAAAAAAA--- --AAAAAAAAAA--- --AAAAAAAAAA--- --AAAAAAAAAA--- --AAAAAAAAAA--- --AAAAAAAAAA--- --------------- 
--------------- --------------- ----AAAAAAA---- ----AAAAAAA---- ----AAAAAAA---- ----AAAAAAA---- ----AAAAAAA---- ----AAAAAAA---- ----AAAAAAA---- ----AAAAAAA---- --AAAAAAAAAA--- --AAAAAAAAAA--- BBAAAAAAAAAA--- BBAAAAAAAAAA--- --AAAAAAAAAA--- --AAAAAAAAAA--- --AAAAAAAAAA--- --AAAAAAAAAA--- --AAAAAAAAAA--- --------------- 
----BB---BB---- ----BB---BB---- ----ACCCCAA---- ----ACCCCAA---- --AAAADDDDDAA-- --AAAAAAAAAAA-- AAAAAAAAAAAAAAA AAAAAAAAAAAAAAA ----AAAAAAA---- ----AAAAAAA---- --AAAAAAAAAA--- --AAAAAAAAAA--- BBAAAAAAAAAA--- BBAAAAAAAAAA--- --AAAAAAAAAA--- --AAAAAAAAAA--- --AAAAAAAAAA--- --AAAAAAAAAA--- --AAAAAAAAAAAA- ------------AA- 
----BB---BB---- ----BB---BB---- ----ACCCCAA---- ----ACCCCAA---- --AAAADDDDDAA-- --AAAAAAAAAAA-- AAAAAAAAAAAAAAA AAAAAAAAAAAAAAA ----AAAAAAA---- ----AAAAAAA---- --AAAAAAAAAA--- --AAAAAAAAAA--- BBAAAAAAAAAA--- BBAAAAAAAAAA--- --AAAAAAAAAA--- --A----AAAAA--- --AAAAAAAAAA--- --AAAAAAAAAA--- --AAAAAAAAAAAA- ------------AA- 
--------------- --------------- ----CCCCCAA---- ----CCCCCAA---- ----CCCCCAA---- ----CCCCCAA---- ----CCCCCAA---- ----CCCCCAA---- ----CCCCCAA---- ----CCCCCAA---- --AAAAAAAAAA--- --AAAAAAAAAA--- BBAAAAFAAAAA--- BBAAAAFAAAAA--- --AAAAAAAAAA--- --A-----AAAA--- --AAAAAAAAAA--- --AAAAAAAAAA--- --AAAAAAAAAA--- --------------- 
--------------- --------------- --------------- --------------- --------------- --------------- --------------- --------------- --------------- --------------- --AAAAAAAAAA--- --AAAAAA-AAA--- BBAAAAFA-AAA--- BBAAAAFA-AAA--- --AAAAAAAAAA--- --A-----AAAA--- --AAAAAAAAAA--- --AAAAAAAAAA--- --AAAAAAAAAA--- --------------- 
--------------- --------------- --------------- --------------- --------------- --------------- --------------- --------------- --------------- --------------- --AAAAAAAAAA--- --AAAAAAAAAA--- BBBBBBAAEEAA--- BBBBBBAAEEAA--- --AAAAAAAAAA--- --AAAAAAAAAA--- --AAAAAAAAAA--- --AAAAAAAAAA--- --AAAAAAAAAA--- --------------- 
