model
size = 24 20 13, scale = 0.05, origin = -y
material 
  colors = A:#4E70A0 B:#71A0CA C:#4EBAD6 D:#823B39 E:#FFF F:#261B21 G:#F7F48D H:#823A2E I:#B67464
voxels
------------------------ ------------------------ ------------------------ ------------------------ ------------------------ ------------------------ ------------------------ ------------------------ ------------------------ --AAAAAAAAAAAAAAA------- --AAAAAAAAAAAAAAA------- --AAAAAAAAAAAAAAA------- --AAAAAAAAAAAAAAA------- --AAAAAAAAAAAAAAA------- --AAAAAAAAAAAAAAA------- --AAAAAAAAAAAAAAA------- --AAAAAAAAAAAAAAA------- --AAAAAAAAAAAAAAA------- --AAAAAAAAAAAAAAA------- --AAAAAAAAAAAAAAA------- 
------------------------ ------------------------ ------------------------ ------------------------ ------------------------ ------------------------ ------------------------ ------------------------ ------------------------ --AAAAAAAAAAAAAAA------- --AAAAAAAAAAAAAAA------- --AAAAAAAAAAAAAAA------- --AAAAAAAAAAAAAAA------- --AAAAAAAAAAAAAAA------- --AAAAAAAAAAAAAAA------- --AAAAAAAAAAAAAAA------- --AAAAAAAAAAAAAAA------- --AAAAAAAAAAAAAAA------- --AAAAAAAAAAAAAAA------- --AAAAAAAAAAAAAAA------- 
----------AA----AA------ ----------AA----AA------ ------AAAAAABBBBAAAAAA-- ------AAAAAABBBBAAAAAA-- ------AAAAAAAAAAAAAAAA-- ------AAAAAAAAAAAAAAAA-- ------AAAAAAAAAAAAAAAA-- ------DDDDDDDDDDAAAAAA-- ------DDDDDDDDDDAAAAAA-- --AAAAAAAAAAAAAAAAAAAA-- --AAAAEAAAAAAAAAAAAAAA-- --AAAAEAAAAAAAAAA------- --AAAAEAAAAAAAAAA------- --AAAAAAAAAAAAAAA------- --AAAAAAAAAAAAAAA------- --AAAAAAAAAAAAAAA------- --AAAAAAAAAAAAAAA------- --AAAAAAAAAAAAAAA------- --AAAAAAAAAAAAAAA------- --AAAAAAAAAAAAAAA------- 
----------AA----AA------ ----------AA----AA------ ------AAAAAABBBBAAAAAA-- ------AAAAABBBBAAAAAAA-- ------AAAAABBBBAAAAAAA-- ------AAAAAAAAAAAAAAAA-- ------AAAAAAAAAAAAAAAA-- ------DDDDDDDDDDAAAAAA-- ------DDDDDDDDDDAAAAAA-- --AAAAAAAAAAAAAAAAAAAA-- --AAAA-AAAAAAAAAAAAAAA-- --AAAAEAAAAAAAAAA------- --AAAAEAAAAAAAAAA------- --AAAAAAAAAAAA-AA------- --AAAAAAAAAAA-AAA------- --AAAAAAAAAAAAAAA------- --AAAAAAAAAAAAAAA------- --AAAAAAAAAAAAAAA------- --AAAAAAAAAAAAAAA------- --AAAAAAAAAAAAAAA------- 
------------------------ ------------------------ ------BBBBBBBBBBBBBBBB-- ------BAABABBBBAAAAAAB-- ------BBBAAAAAAAAAAAAB-- ------BAAAAAAAAAAAAAAB-- ------BAAAAAAAAAAAAAAA-- ------DAAAAAAAAAAAAAAA-- ------DAAAAAAAAAAAAAAA-- --AAAAAAAAAAAAAAAAAAAA-- --AAAAAAAAAAAAAAAAAAAA-- --AAAAEAAAAAAAAAA------- --AAAAEAAAAAAAAAA------- --AAAAAAAAAAAAAAA------- --AAAAAAAAAAA-AAA------- --AAAAAAAAAAAAAAA------- --AAAAAAAAAAAAAAA------- --AAAAAAAAAAAAAAA------- --AAAAAAAAAAAAAAA------- --AAAAAAAAAAAAAAA------- 
------------------------ ------------------------ ------BBBBBBBBBBBBBBBB-- ------BBBBBBBBBBBBBAAB-- ------BAAAAAAAAAAABAAB-- ------BAAAAAAAAAAAAAAB-- ------BAAAAAAAAAAAAAAA-- ------DAAAAAAAAAAAAAAA-- CC----DAAAAAAAAAAAAAAA-- CCAAAAAAAAAAAAAAAAAAAA-- CCAAAAAAAAAAAAAAACCCAA-- CCAAAAEAAAAAAAAAACCCC--- CCAAAAEAAAAAAAAAACCCC--- CCAAAAAAAAAAAAAAACC----- CCAAAAAAAAAAA-AAACC----- CCAAAAAAAAAAAAAAACC----- CCAAAAAAAAAAAAAAACC----- CCAAAAAAAAAAAAAAACC----- --AAAAAAAAAAAAAAA------- --AAAAAAAAAAAAAAA------- 
------------------------ ------------------------ ------BBBBBBBBBBBBBBBB-- ------BBBBBBBBBBBBBAAB-- ------BAAAAAAAAAAABAAB-- ------BAAAAAAAAAAAAAAB-- ------BAAAAAAAAAAAAAAA-- ------DAAAAAAAAAAAAAAA-- CC----DAAAAAAAAAAAAAAA-- CCAAAA-AAAAAAAAAAACCAA-- CCAAAAAAAAAAAAAAACCCCAAA CCAAAAEAAAAAAAAAACCCC-AA CCAAAAEAAAAAAAAAACCCC--- CCAAAAAAAAAAAAAAACC----- CCAAAAA-AAAAA-AAACC----- CCAAAAA-AAAAAAAAACC----- CCAAAAA-AAAAAAAAACC----- CCAAAAA-AAAAAAAAACC----- --AAAAA-AAAAAAAAA------- --AAAAAAAAAAAAAAA------- 
------------------------ ------------------------ ------BBBBBBBBBBBBBBBB-- ------BBBBBBBBBBBBBAAB-- ------BAAAAAAAAAAABAAB-- ------BAAAAAAAAAAAAAAB-- ------BAAAAAAAAAAAAAAA-- ------DAAAAAAAAAAAAAAA-- CC----DAAAAAAAAAAAAAAA-- CCAAAA-AAAAAAAAAAACCAA-- CCAAAAAAAAAAAAAAACCCCAAA CCAAAAEAAAAAAAAAACCCC-AA CCAAAAEAAAAAAAAAACCCC--- CCAAAAAAAAAAAAAAACC----- CCAAAAAAAAAAA-AAACC----- CCAAAAAAAAAAA-AAACC----- CCAA--A--------AACC----- CCAA--A--------AACC----- --AAAAAAAAAAAAAAA------- --AAAAAAAAAAAAAAA------- 
------------------------ ------------------------ ------BBBBBBBBBBBBBBBB-- ------BBBBBBBBBBBBBAAB-- ------BAAAAAAAAAAABAAB-- ------BAAAAAAAAAAAAAAB-- ------BAAAAAAAAAAAAAAA-- ------DAAAAAAAAAAAAAAA-- ------DAAAAAAAAAAAAAAA-- --AAAA-AAAAAAAAAAAAAAA-- --AAAAAAAAAAAAAAAAAAAA-- --AAAAEAAAAAAAAAA------- --AAAAEAAAAAAAAAA------- --AAAAAAAAAAAAAAA------- --AAAAAAAAAAA-AAA------- --AAAAAAAAAAA-AAA------- --AA--A--------AA------- --AA--A--------AA------- --AAAAAAAAAAAAAAA------- --AAAAAAAAAAAAAAA------- 
------AA------------AA-- ------AA------------AA-- ------AABBBBBBBBBBBBAA-- ------AABBBBBBBBBAAAAA-- ------AAAAAAAAAAAAAAAA-- ------AAAAAAAAAAAAAAAA-- ------AAAAAAAAAAAAAAAA-- ------DAAAAAAAAAAAAAAA-- ------DAAAAAAAAAAAAAAA-- --AAAA-AAAAAAAAAAAAAAA-- --AAAAAAAAAAAAAAAAAAAA-- --AAAAEAAAAAAAAAA------- --AAAAEAAAAAAAAAA------- --AAAAAAAAAAAAAAA------- --AA--A-------AAA------- --AA--A--------AA------- --AA--A--------AA------- --AA--A--------AA------- --AAAAAAAAAAAAAAA------- --AAAAAAAAAAAAAAA------- 
------AA------------AA-- ------AA------------AA-- ------AABBBBBBBBBBBBAA-- ------AABBBBBBBBBBBBAA-- ------AAAAAAAAAAAAAAAA-- ------AAAAAAAAAAAAAAAA-- ------AAGGAAAAAAAAAAAA-- ------DDGGDDDDDDAAAAAA-- ------DDDDDDDDDDAAAAAA-- --AAAA-AAAAAAAAAAAAAAA-- --AAAAAAAAAAAAAAAAAAAA-- --AAAAEAAAAAEAAAA------- --AAAAEAAAAAEAAAA------- --AAAAAAAAAAAAAAA------- --AA--A-------AAA------- --AA--A--------AA------- --AA--A--------AA------- --AA--A--------AA------- --AAAAAAAAAAAAAAA------- --AAAAAAAAAAAAAAA------- 
------------------------ ------------------------ ------------------------ ------------------------ ------------------------ ------------------------ ------------------------ ------------------------ ------------------------ --AAAAAAAAAABBAAA------- --AAAAAAAAAAAA-AA------- --AAAAEAAAAAEA-AA------- --AAAAEAAAAAEA-AA------- --AAAAAAAAAAAAAAA------- --AA--A-------AAA------- --AA--A--------AA------- --AA--A--------AA------- --AA--A--------AA------- --AAAAAAAAAAAAAAA------- --AAAAAAAAAAAAAAA------- 
------------------------ ------------------------ ------------------------ ------------------------ ------------------------ ------------------------ ------------------------ ------------------------ ------------------------ --ABBAAAAAAIIABBA------- --ABBAAAAAAIIABBA------- --AFFAEEEEEEEAFFA------- --AFFAEEEEEEEAFFA------- --AAAAAAHHAAAAAAA------- --AAAAAAHHAAAAAAA------- --AAAAAAAAAAAAAAA------- --AAAAAAAAAAAAAAA------- --AAAAAAAAAAAAAAA------- --AAAAAAAAAAAAAAA------- --AAAAAAAAAAAAAAA------- 
