model
size = 32 32 7, scale = 0.05, origin = -y
material 
  colors = A:#C93 B:#E00 C:#111 D:#444 E:#800
voxels
79-2A28-6A23-12A18-16A15-18A14-18A19-9A17-A4-11A3-A11-3A3-11A2-3A10-3A3-10A3-3A9-5A3-9A2-5A8-5A3-8A3-5A8-6A3-7A2-6A7-7A3-6A3-7A6-8A2-6A3-7A7-7A3-4A3-7A8-8A2-4A3-7A8-8A3-2A3-8A9-8A2-2A3-7A10-8A6-8A11-7A6-7A12-8A4-8A13-7A4-7A14-8A2-8A15-7A2-7A18-12A23-6A28-2A157-4A24-12A18-16A15-18A13-20A11-22A10-A6-9A5-A9-3A4-11A3-3A8-4A3-11A2-4A7-5A3-10A3-5A6-6A3-9A2-6A6-6A3-8A3-6A5-8A3-7A2-8A4-8A3-6A3-8A4-9A2-6A3-8A4-9A3-4A3-9A5-9A2-4A3-8A6-9A3-2A3-9A6-10A2-2A3-9A7-9A6-9A8-9A6-9A9-9A4-9A10-9A4-9A11-9A2-9A13-8A2-8A15-16A18-12A24-4A124-5A23-12A18-16A14-20A11-22A9-24A8-24A7-3A6B9A5B3A6-4A4B11A3B4A5-6A3B11A2B6A4-6A3B10A3B6A4-7A3B9A2B7A3-2(8A3B)8A2-9A3B7A2B9A2-9A3B6A3B9A2-10A2B6A3B9A2-10A3B4A3B10A2-11A2B4A3B10A3-10A3B2A3B10A4-11A2B2A3B10A4-11A6B11A5-10A6B10A6-11A4B11A7-10A4B10A8-11A2B11A9-10A2B10A11-20A14-16A18-13A22-6A59-5C23-4C5A3C18-2C12A2C14-2C16A2C11-C20AC9-C22AC7-C24AC6-C24AC5-C3A6B9A5B3AC4-C4A4B11A3B4AC3-C6A3B11A2B6AC2-C6A3B10A3B6AC2-C7A3B9A2B7AC-C2(8A3B)8A2C9A3B7A2B9A2C9A3B6A3B9A2C10A2B6A3B9A2C10A3B4A3B10A2C11A2B4A3B10AC-C10A3B2A3B10AC2-C11A2B2A3B10AC2-C11A6B11AC3-C10A6B10AC4-C11A4B11AC5-C10A4B10AC6-C11A2B11AC7-C10A2B10AC9-C20AC11-2C16A2C14-2C13AC18-3C6A4C22-6C438-2(D12-E146-D12-E850-)5(D12-E18-)D12-E425-
