model
size = 25 32 32, scale = 0.05, origin = -y
material 
  colors = A:#F06 B:#F0F C:#F93 D:#FF0 E:#66F F:#6F0 G:#3FF H:#9CF
voxels
311-3E20-9E14-2E8-E113-E10-2E12-13E13-11E16-7E519-5B19-7B16-11B14-12B12-4B5-4B12-2(4B5-3B13-)4B5-5B10-15B10-12B-2B11-14B12-12B14-9B17-6B21-3B420-7A16-11A13-13A12-14A2(10-3AH7AH3A)10-3AH2A3-2AH2A11-3AH-A3-A-H2A10-4AH-5A-H4A8-4AH6-AH4A8-4AHA5-AHA-2A9-3AH3A-3AH3A10-3AH7AH3A11-13A13-11A15-9A17-7A345-3C20-7C16-11C13-13C11-15C9-6C4-2C2H3C8-5C7-2H3C8-4C8-2H3C9-2(3C3-)H3C9-2C4-3C4-2C8-4C11-4C6-4C10-H4C6-5C9-H3C8-4C8-2H3C9-5C5-C2H2C10-7C-3C2H2C11-10C2HC12-13C13-11C16-7C245-3D21-4D20-6D18-8D16-5D-4D14-13D11-15D9-6D5-6D8-4D9-4D7-4D10-5D6-4D11-4D6-3D12-4D7-2D13-HD6-4D13-H2D5-4D13-H2D6-3D12-4D6-4D11-3D8-4D9-4D8-4DH7-5D9-3DH2D3-2H4D10-3DH5D2H4D11-2DH5D2H3D13-7D2H2D16-7D120-3F21-2(5F20-)5F19-2F3H2F18-2FH-H2F17-3F2-H3F15-3F4-3F14-3F-F3H4F13-5F3H5F11-5F5-5F2(9-4F)7-4F11-4F2(5-3FH13-3F)5-3FH13-4F3(4-3F15-3F)4-3FH13-2HF6-2FH13-3F6-2F2H11-4F6-2F3H9-4F8-F4H7-5F8-F6H3-2H4F10-4F7H4F11-3FH5-H3F13-10F17-6F71-3G21-5G19-3G-3G2(18-2G3-2G)17-3G3-3G16-2G5-2G15-3G5-3G13-3G7-2G13-13G11-6G3-6G2(9-4G)7-4G11-3G7-3G13-3G5-4G13-3G4-2(4G15-3G3-)3G16-4G2-3G16-4G3-3G15-3G4-3G15-2G5-3G15-2G6-3G13-3G6-4G11-4G6-5G9-5G7-4GH7-5G9-3G8H4G10-3G-7H3G13-G2H4-2H2G15-9G68-5E19-2EH-H2E17-3E3-3E2(16-2E5-2E)15-3E5-3E14-2E7-2E13-3E7-2E13-2E2-E3HE2-2E11-6E3H6E9-5E7-4E9-3E10-4E7-3E13-3E5-3E14-3E5-3E15-3E3-4E15-4E2-E-E2(17-3E2-3E)17-3E3-2(2E17-2E4-)2(3E15-3E4-)4E13-3E6-4E11-4E6-5E9-5E7-6E5-6E9-15E11-3E7-3E14-9E18-5E44-6B18-B2H3-3B16-BH5-2B15-2B7-2B14-2B7-2B13-3B7-2B13-2B9-2B12-2B9-2B11-2B2-5H2B-3B10-4B2H3-6B2(9-4B)7-4B11-3B7-3B13-3B5-3B15-3B4-3B15-3B3-3(3B17-3B2-)3B3(17-2B4-2B)17-2B4-3B15-3B4-3B14-4B4-4B13-3B6-4B10-5B7-4BH7-H4B8-4B9H3B10-3BH-5H-H2B13-2B2H3-2H2B16-7B43-7A17-2A4-H2A15-2A7-2A14-2A7-2A13-2A9-2A12-2A9-2A11-2A10-2(2A11-)2A10-2A-2A5HA2-2A9-6A5-3A-2A8-4A9-4A7-3A12-4A6-2A14-3A6-2A15-2H2(A4-2A17-H)A4-A18-HA4-3(A19-2A3-)3(2A17-HA4-)3A15-2HA4-4A13-4A5-4A11-4A6-2A-2A9-5A7-2A-4A3-7A9-3A2-5A2-3A11-4A5-4A14-9A42-6C17-4C3-4C14-2C7-HC13-2C9-2C12-2C9-2(2C11-)2C10-2C11-2C10-C12-2C9-2C2-C8H2-2C8-5C6-2H4C7-4C10-5C6-3C13-3C6-2C15-2C5-3C15-3C2(4-2C17-2C)4-C19-C3-2(2C19-2C2-)2C19-2C3-C18-2(2C4-2C17-)2C4-3C15-3C4-4C13-4C5-C-2C11-2C-C6-2C-2C9-2C-2C7-2C-4C3-4C-2C9-2C2-7C2-2C11-3C7-3C14-9C20-C22-5D17-5D-5D13-DH9-2D12-DH9-2(2D11-)2D10-2D11-2D10-D13-D9-2D13-2D8-2D2-7H2D2-2D7-2D-D2H7-3D-D7-4D10-5D6-3D13-3D6-2D15-2D5-3D15-3D2(4-2D17-2D)3-4(2D19-2D2-)2D19-2D3-2D17-3D3-2D17-2D4-3D15-3D4-4D13-4D4-2D-2D11-2D-2D5-2D-2D9-2D-2D7-2D-3D4-4D-2D8-3D2-7D2-2D11-3D7-3D13-11D17-5D21-3F18-11F13-3F7-H2F12-2(F11-)2F11-2F10-F13-F9-2(2F13-2F8-)F3-3F6H3-F7-2F-4F5-2HF2-2F6-F-3F9-5F5-4F13-3F5-3F14-3F5-3F15-3F2(4-2F17-2F)3-2F18-3F3(2-2F19-2F)2(2-3F17-3F)3-2F17-2F4-3F15-3F4-F-2F13-2F-F4-2F-2F11-2F-2F5-2F-2F9-2F-2F6-2F2-4F3-4F-2F8-3F2-6F3-2(3F9-)3F12-4F3-4F16-6F43-9G14-2G2H4-3H2G11-2G10-2(2G11-)2G10-G13-G9-2G13-2G8-G15-G8-G4-7H4-G7-2G2-G3H3-3HG2-2G6-G-3G9-3G-G5-5G11-2G-G5-4G13-3G5-3G15-3G4-2G16-3G4-2G17-2G3-2(3G17-3G2-)2G18-3(3G2-3G17-)3G3-2(3G15-3G4-)G-2G13-2G-G4-2G-2G11-2G-2G5-G2-G2H7-3G-2G6-2G2-8H3G2-2G7-2G4-5H4-2G9-2GH9-3G11-4G4-4G16-7G43-6E16-12E13-2E9-2(2E11-)2E9-2E13-E9-2E13-2E8-E15-E8-E5-5E5-E7-2E2-11E2-2E6-E2-3E7-3E2-E5-2E-2E11-2E-E5-4E13-3E5-3E14-3E5-3E15-3E4-2E16-3E3-5(3E17-3E2-)4E15-4E3-3E15-3E4-E-2E13-2E-E4-E-3E11-3E-E4-2E-3E9-3E-2E5-E2-4E5-4E2-E6-2E3-9E3-2E7-2E13-2E9-2E10-3E11-4E5-4E15-7E66-11B13-3B7-3B2(11-2B)10-B13-B9-2B13-2B2(8-B15-B)7-2B3-9B3-2B6-B2-4B5-4B2-B5-2B-3B9-3B-B5-5B11-2B-B5-4B13-3B5-3B14-4B3-4B15-3B3-3B16-4B2(2-3B17-3B)2-3B16-2(4B2-4B15-)4B3-B-2B13-2B-B4-B-2B12-3B-B4-B2-2B10-3B2-B4-2B2-3B7-3B2-2B5-B3-5B-5B3-B6-2B4-7B4-2B7-2B13-2B9-2(2B11-)4B5-4B14-9B66-9A14-6A-6A11-2A10-H2A10-A13-A9-2(2A13-2A8-)A15-A7-2A4-7H4-2A5-3A2-A10H2-3A4-2A2-2AH7-2HA2-2A4-2A-3A9-H2A-A5-5A11-2A-2A4-A-2A13-4A3-5A13-2A-A3-4(4A15-2H2A2-)4A15-H-2A2-2A-2A13-2H-2A3-A-2A12-3H-A4-A2-2A11-2H2-A4-A2-3AH7-3H3-A4-2A2-5A3-4A3-2A5-A4-9A4-A6-2A6-3A6-2A7-2A13-2A9-2(2A11-)3A7-3A14-9A69-3C17-12C12-4C7-4C2(10-C13-C)9-2C13-2C8-C15-C7-2C15-3C4-3C3-2C5H2C3-3C4-2C3-3C5H3C2-3C4-3C-3C6-4C-3C3-7C9-6C3-3C-2C11-2C-2C3-6C11-6C5(2-2C-2C13-2C-2C)2-2C-3C11-3C-2C3-C2-3C9-3C2-C4-C2-4C7-3C3-C4-C3-3CH5-4C3-C4-2C4-C5H3C4-2C5-C6-4H2(C6-)2C15-2C7-2C13-2C9-2(2C11-)3C7-3C14-9C91-9D13-6D3-6D10-2D11-2D10-D13-D9-2D13-2D8-D15-D7-2D15-3D4-3D7-D7-3D4-2D4-8D5-2D3-3D3-11D3-2D3-3D2-4D5-4D2-2D3-3D2-3D7-3D2-2D3-3D-3D9-2(3D-)3D2-2D11-2D2-2D-3D2-2D11-2D2-6D2-2(2D11-3(2D2-))2D10-3D2(2-2D)2-3D9-3D2-2D3-D3-3D7-3D3-2(D4-)4D3-4D2(4-D)5-9D5-D4-2D5-7D5-2D5-D17-D6-2D15-2D7-2D13-2D9-2(2D11-)4D5-4D14-9D93-5F16-13F11-2F10-3F10-F13-F9-2F13-2F8-F14-2F8-F15-F6-3F15-3F3-3F16-4F2-3F5-7F5-3F2-2F5-9F4-3F-3F4-5F-5F4-2F-3F3-2F2H5-4F3(3-6F3-2FH7-3F)2(3-2F2-2F3-2FH7-3F)3-2F2-2F3-2FHF4-4F4-2F3-F4-FH9F2(4-F)5-H8F5-F4-2F6-5F6-2F4-2F17-2F5-F16-2F6-2F15-2F7-2F13-2F9-2F10-3F11-2FHF5-4F15-7F115-12G12-3G9-3G10-G2(13-G9-2G)13-2G8-G15-G7-2G15-G5-4G15-4G2-3G17-3G-4G7-3G7-8G5-G5HG5-7G5-2G5H2G4-7G5-2G2(H6G5-6G4-3G)HG-5G4-2(G3-2G5-2GH6G5-)G4-G5-2GH6G5-G4-G6-GH4G7-G4-G19-G4-2G17-2G5-G17-G6-2G15-2G6-2G14-2G8-2G12-2(3G9-)3G11-4GH3-4G16-7G116-11E12-4E7-4E10-E12-2E10-E13-E9-2(2E13-2E8-)E15-E7-2E15-2E6-E17-E3-2E-E2(17-E-6E)17-7E9-E9-6E2(8-3E8-E3-2E)8-3E8-3(E4-E19-)E2(4-2E17-2E)5-E17-E6-2E15-2E7-2E13-2E8-3E11-2E10-3E8-3E13-5E-5E17-5E118-9B13-6B3-5B2(11-2B)10-2B11-2B10-B13-B9-2B13-2B8-2B13-2B7-2(2B15-2B6-)B17-B6-B17-B5-2(2B17-2B4-)5(B19-B4-)2B17-2B4-2B17-2B5-B17-B2(6-2B15-2B)7-2B13-2B9-2(2B11-)3B7-3B13-10B19-3B121-5A16-6A-6A12-2A9-2(2A11-)2(2A10-2A11-)2A9-2A13-2A8-2A13-2A7-2(2A15-2A6-)A17-A6-A17-A5-3(2A17-2A4-)A18-3(2A4-2A17-)2A5-A17-A2(6-2A15-2A)7-2A13-2A8-3A11-3A9-2AH9-3A11-5A3-5A14-9A144-3C18-11C13-3C7-3C2(12-2C9-2C)2(11-2C)10-2C11-2C9-2C13-2C8-2C13-2C7-2(2C15-2C6-)C16-2C2(6-C17-C)3(5-2C17-C)2(6-C17-C)2(6-2C15-2C)7-2C13-2C8-2C12-2(3C9-)3C11-3C7-3C13-11C17-5C168-9D15-3D4-4D14-2D7-2D13-3D7-3D12-2D9-2D11-3D9-3D10-2D11-2D9-2D13-2D8-DH13-2D7-2D15-D7-3(2D15-2D6-)2(D16-2D6-)3(2D15-2D6-)2D15-2D7-2D13-2D8-2D13-2D9-2D11-2D10-4D7-3D13-4D2-5D15-9D192-6F18-9F16-9F15-3F5-3F14-2F7-2F13-2F8-3F11-F2H9-3F10-FH11-2F9-3(2F13-2F8-)F4(15-F7-2F)2(15-F8-F)H13-2F8-2F13-2F8-3F11-3F9-2F11-HF10-4F7-3HF11-5F3-5F14-9F18-4F245-7G17-9G15-4G3-3G15-3G5-3G13-3G7-3G11-3G9-3G10-2G11-2G10-GH11-2G9-7(2G13-2G8-)2G12-3G9-2G11-2G10-3G9-3G11-3G7-3G12-5G3-5G14-9G18-5G295-5E19-7E17-9E15-3E5-3E13-3E7-3E12-2E9-2E11-3E9-3E7(10-2E11-2E)10-3E9-3E10-3E8-3E12-4E5-4E13-5E-5E15-9E18-5E369-7B17-9B15-11B14-3B5-3B13-3B7-3B12-2B8-3B5(12-2B9-2B)12-3B7-3B12-4B5-4B13-4B3-4B14-6BH3B17-7B20-3B421-5A19-7A17-9A15-10A15-4AH-5A14-4A3-4A3(14-3A5-3A)14-4A3-4A14-11A15-9A17-7A19-5A546-3C21-5C19-4(7C18-)7C19-5C260-
