model
size = 32 27 21, scale = 0.05, origin = -y
material 
  colors = A:#111 B:#222 C:#001 D:#444 E:#555 F:#0F3 G:#FF3 H:#FFF I:#3CF J:#F0C K:#777 L:#0F6 M:#FF0 N:#E00 O:#EEE P:#0FF
voxels
262-F18-F11-F20-F9-F22-F7-F24-F644-H28-H3-H26-H3-H28-H4-H2-F18-F2-H8-2F18-2F9-2F20-2F7-2F22-2F486-H91-2H27-H36-2H26-3H-3H25-2H2-3H25-2H3-2H2-F18-F2-2H6-HF2C16-2CF9-2F2CM14-M2C2F7-F3C2G14-2G3CF7-2C2G16-2G2C644-2H28-2H-2H26-2H3-H3-F18-F3-H7-2FC16-C2F9-3FGC14-CG3F7-F2CFGC14-CGF2CF7-2CEGC14-CGE2C9-MG2C14-2CGM11-3C14-3C684-2C16-2C11-2CGC14-CG2C9-3C2GC12-C2G3C8-3C2GC12-C2G3C9-5C12-5C11-4C12-4C13-3C12-3C684-4C4-D4GD4-4C10-3CGC2-D6AD2-CG3C10-3CG2C-D6AD-2CG3C10-3CG2C2D6A2D2CG3C11-2CG2C2D6A2D2CG2C13-4C2D3(OB)2D4C19-D3(BO)D6-L17-8D7-L17-D4PD572-2A28-AC2ACA19-4C3-AD4A3-4C12-2CG2C-2AD5A-2(2CG2C12-2CG2C3AD6A)2CG2C13-4C3AD6A4C2D16-3AD6A4-DAD16-2AD5A6-DAD16-6A8-2DJ15-6A9-2J16-I2AI29-2A475-2(2AC)2A24-2(2AC)2A23-3AD6A21-E3AD6AE12-2(EC)-4EA2-D3A2-A4E9-2(EC)-3E2A-AD4A-2A3E2D11-2ECE2A-AD4A-2A3E3D10-2J-2EA-AD4A-A3-5D9-2N-2J3AD6A4-4DJ11-2N-A-4A-A6-2D3J14-6A8-4J15-I2AI10-3J15-I2-I29-2A412-6A25-K-4A-K23-KA-4A-AK22-A2-4A2-A21-A-8A-A11-2ECEC-3EA-8A-A3E8-2ECEC-3EB-8A-B3ED12-2ECEB-8A-B3E2D11-2J-EB-8A-B2-4D10-2N-JB-8A-B4-3D12-2NB-6A-B6-2DJ13-IB-4A-BI7-2J15-BI2AIB26-B-2A-B27-I2-I29-2B379-8K23-KA-4A-AK19-A2-K-6A-K2-A14-A-3A-8A-3A-A12-2(4A-10A-4A7-2C3-)2(4A-10A-4A12-)4A-10A-4A13-3A-10A-3A16-14A18-2A-8A-2A19-A3(I2A)IA21-IA-I2AI-AI23-2(2A-)2A25-AI2-IA27-I2AI315-6K25-B-4A-B23-B-6A-B18-A-2B-8A-2B-A13-3A3-8A3-3A12-20A7-2E2-22A6-2E-24A9-22A13-16A14-B2-14A2-B12-2BI-12A-I2B14-I-AI8AIA-I17-B2-8A2-B19-B2-6A2-B21-IB-4A-BI24-B-2A-B26-B4AB27-4B283-6B25-B6AB22-2B8A2B17-2A3-8A3-2A13-20A12-20A7-2C-24A5-2C-3(24A8-)A-B18AB-A10-B18AB12-2B-14A-2B14-I-12A-I17-B-10A-B19-3B6A3B23-B4AB26-B4AB27-4B29-2B252-6B24-2B2A2-2A2B21-B-8A-B17-18A13-20A12-20A7-3M24A5-3M3(24A8-)24A10-B18AB12-2B16A2B14-B14AB17-B12AB19-2B8A2B22-B6AB25-B4AB27-4B29-2B252-6B23-3B6A3B20-12A17-18A13-20A12-20A8-2M24A6-2M3(24A8-)24A10-B18AB12-2B16A2B14-B14AB17-B12AB19-2B8A2B22-B6AB25-B4AB27-4B29-2B252-6B23-3B6A3B20-12A17-18A13-20A12-20A10-4(24A8-)24A10-B18AB12-2B16A2B14-B14AB17-B12AB19-2B8A2B22-B6AB25-B4AB27-4B29-2B281-12B20-12A17-18A13-20A12-20A10-4(24A8-)24A10-B18AB12-2B16A2B14-3B10A3B17-2B10A2B19-4B4A4B22-3B2A3B25-2B2A2B27-4B312-12B20-5B2A5B17-18A13-20A12-20A10-2AB18AB2A3(8-24A)8-2AB18AB2A10-B18AB12-5B10A5B17-B8AB22-10B25-4B29-2B30-2B345-12B25-2A23-A6B2A6BA14-A-16A-A12-20A10-4(24A8-)A2-B16AB2-A11-B16AB15-3B10A3B19-10B473-4B24-4B-2A-4B19-B4AB2AB4AB18-B12AB15-A-AB12ABA-A10-A-3AB12AB3A-A8-3AB16AB3A2(8-A-20A-A)11-B16AB14-3BA2L9A3B17-5L2BL3BL504-4B26-2B4A2B22-2B-6A-2B2(20-B10AB)14-A-A3-B10AB3-A-A8-2(A-)2B12A2B2(-A)2(8-A-AB16ABA-A)11-B16AB14-2(5BL)BL4B533-4B26-8B23-10B21-2BJ6BJ2B20-12B20-2BJ6BJ2B18-16B15-2(5BL6BL5B14-)5BL6BL5B295-
