model
size = 32, scale = 0.05, origin = -y
material 
  colors = A:#09F B:#F3C C:#03C D:#FC0 E:#F90 F:#30F G:#009 H:#FF3 I:#F93 J:#36C K:#CC0
voxels
203-2(2A30-)2(3A29-)3A28-4(5A27-)6A26-6A25-7A25-11(8A24-)6C2A185-2(4A28-)4A26-2(7A25-)8A24-8A23-2(10A22-)10A21-3(13A19-)13(14A18-)A2C11A21-8C55-2(7A25-)7A24-8A24-10A21-11A21-2(12A20-)13A2(18-14A)17-3(17A15-)15(18A14-)2AC15A17-13C23-5C22-3A5-4AJ19-2A7B3AC19-12AJ18-14A18-15A16-16A16-17A15-17A14-5(19A13-)16(20A12-)AC18A14-2C12A3C19-7A3C17-3A11-ACJGCG12-2A2B10-BHC15-3A11BACJ15-3A11B3A15-3A4(11B4A13-4A)11B4A13-20A12-20A3(11-21A)11-15(22A10-)AC20A12-C16A2C16-12A2C15-A16-AG3CE9-AB13-2BA14-A3B10-3BA14-A16BA13-2A16B2A2(12-2A13B5A)12-4A11B6A10-5A11B6A3(10-22A)10-18(23A9-)2C19A2C12-16A2C12-A18-AG3CE7-FB15-2BD12-2AB13-2B2A12-2A3B10-3B2A12-2A16B3A11-2A13B6A10-3A13B2(6A10-5A11B)6A10-22A10-2(23A9-)23AE8-22AE2(8-24A)8-14(25A7-)2C21A2C10-19A2C10-A18-A2G3CE6-FB16-BE12-A2B14-2B2A10-2A2B13-3B2A10-3A3B10-3B3A2(10-3A15B4A)10-2(5A13B5A9-)8A6B9A9-23A8-24AE7-24A2DH5-24AE7(7-25A)7-9(26A6-)C25A8-22A2C7-2A19-A2G2CIE4-2FB17-BA10-2AB16-B2A10-2A2B14-2B2A10-2A2B13-2B3A10-3A3B10-2B5A9-3A15B5A9-5A13B5A8-6A13B5A8-2(8A8B8A-D6-)9A7B8A-D6-24AE7-24AK4(7-25A)6-12(27A5-)C26A7-24AC7-2A19-2AG3CI3-3F2(B17-B2A9-2A)B16-B3A9-2A2B14-B4A8-4A2B12-B5A-D6-6AB10-2B5A-D6-6AB9-3B5A-D6-6A2B7-4B5A-D6-6A3B5-3B7A-D6-8A8B9A7-9A7B9A3(7-25A)6-26A6-7(27A5-)7(28A4-)C27A5-25A2C6-2A20-A2G2CIE2-2FB19-BA9-AB18-B2A8-2A2B16-B3A-D6-3A2B15-B3A-D6-4A2B12-2B4A-D6-6AB11-B2(5A8-6AB10-2B)5A8-6A2B8-2B6A8-7A3B4-3B8A7-7A9B9A6-8A8B10A2(6-26A)6-5(27A5-)10(28A4-)C27A5-9A6-11AC5-A22-AC2G2CI-F2A20-BAC7-2AB18-B2A-D6-2A2B17-B2A-D6-3A2B15-B3A8-4A2B13-B4A8-5A2B11-B2(5A8-6AB10-2B)6A7-6A2B8-2B7A6-8A2B6-2B8A6-8A4B2-3B9A6-8A8B10A6-7(27A5-)6(28A4-)4(29A3-)C28A3-C7A10-9A2C3-FA22-A2CG2CIEFAB20-BACD6-2AB18-B2A-DE5-2A2B17-B2A8-3A2B15-B3A8-4A2B13-B4A8-5AB12-2B5A6-7AB11-B6A2(6-7AB10-B7A)6-8AB8-2B7A3-H2-8A3B5-B9A6-8A8B11A5(5-27A)5-6(28A4-)4(29A3-)2(30A2-)12A2-16A2-C5A14-8A2C2-FA22-A5CDEFAB20-BACDE5-2AB18-B2A8-2A2B17-B2A7-4A2B15-B4A6-5AB14-B5A6-6AB13-B5A2(6-7AB11-B6A)6-7AB10-2B6A6-8AB8-3B7A2-H2-8A2B6-4B7A2-D2-8A12B7A5-27A5-28A4-27A5-28AE3-27A5-4(28A4-)3(29A3-)5(30A2-)11A4-15A2-C4A16-8AC2-FA22-2A4CDEFAB20-B2AGD5-2AB18-B3A7-2A2B17-B3A6-4A2B15-B4A6-5AB14-B5A6-6AB13-B5A6-7AB11-B6A6-7AB11-B7A5-7AB10-2B7A5-8AB8-3B7A5-8A2B7-3B7A2-D2-8A12B7A2-D2-27A5-28A4-27A2-D2-28AE3-27A-2(E3-28A)4-28A4-2(29A3-)6(30A2-)31A-9A8-14A-C2A20-6A2C-FA22-2A4CDEFAB20-B2AGD5-2AB18-B3A7-2A2B17-B3A6-4A2B15-B4A6-5AB14-B5A6-6AB13-B5A6-7AB11-B6A6-7AB11-B7A5-7AB10-2B7A5-8AB9-2B7A5-8A2B7-3B7A5-8A12B7A2-D2-27A2-D2-28AED2-27A-ED2-28AED2-27A2-D2-28A-D2-28AE2(3-29A)3-4(30A2-)4(31A-)7A12-12A-C24-5AC-FA22-2A4CHEFAB20-B2AGD5-2AB18-B3A7-2A2B17-B3A6-4A2B15-B4A6-5AB14-B5A6-6AB13-B5A6-7AB11-B6A6-7AB11-B7A5-7AB10-2B7A5-8AB9-2B7A5-8A2B7-3B7A5-8A12B7A5-27A5-28AE3-27A-ED2-28A4-27A5-2(28AED2-)2(29A3-)4(30A2-)4(31A-)7A12-12A-C24-5AC-FA22-2A4CHEFAB20-B2AGD5-2AB18-B3A7-2A2B17-B3A6-4A2B15-B4A6-5AB14-B5A6-6AB13-B5A6-7AB11-B6A6-7AB11-B7A5-7AB10-2B7A5-8AB9-2B7A5-8A2B7-3B7A5-8A12B7A5-27A5-28A4-27A2-H2-28AE3-27A-2(E3-28A)-D2-28A-H2-2(29A3-)6(30A2-)31A-9A8-14A-C2A20-6A2C-FA22-A5CHEFAB20-BACDE5-2AB18-B2A8-2A2B17-B2A7-4A2B15-B4A6-5AB14-B5A6-6AB13-B5A2(6-7AB11-B6A)6-7AB10-2B6A6-8AB8-3B7A5-8A2B7-3B7A5-8A12B7A5-27A5-28A4-27A5-28AE3-27A-E3-2(28A4-)28A-H2-28A4-3(29A3-)5(30A2-)11A4-15A2-C4A16-8AC2-FA22-A2CG2CIEFAB20-BACD6-2AB18-B2A-DE5-2A2B17-B2A8-3A2B15-B3A8-4A2B13-B4A8-5AB12-2B5A6-7AB11-B6A2(6-7AB10-B7A)6-8AB8-2B7A6-8A2B6-B9A6-8A8B11A5(5-27A)5-6(28A4-)4(29A3-)2(30A2-)12A2-16A2-C5A14-8A2C3-A22-AC2GCDI-F2A20-BAC7-2AB18-B2A-D6-2A2B17-B2A-D6-3A2B15-B3A8-4A2B13-B4A8-5A2B2(11-B5A8-6AB)10-2B6A7-6AB10-B7A6-8AB8-B8A6-8A3B5-B9A6-8A8B10A6-7(27A5-)6(28A4-)4(29A3-)C28A3-C7A10-9A2C5-2A20-A2G2CIE2-2FB19-BA9-AB18-B2A8-2A2B16-B3A-D6-3A2B15-B3A-D6-4A2B13-B4A-D6-6AB11-B2(5A8-6AB10-2B)5A8-6A2B9-B6A8-7A2B6-2B8A7-7A4B2-3B9A6-8A8B10A2(6-26A)6-5(27A5-)10(28A4-)C27A5-9A6-11AC6-2A19-2AG3CI3-3F2(B17-B2A9-2A)B16-B3A9-2A2B15-B3A8-4A2B12-3B3A-D6-6AB11-B2(5A-D6-6AB10-2B)5A-D6-6A2B8-B7A-D6-8A2B4-2B9A7-9A7B9A3(7-25A)6-26A6-7(27A5-)7(28A4-)C27A5-25A2C6-2A19-AG3CIE4-2FB17-BA10-2AB16-B2A10-2A2B15-B2A10-2A2B14-B3A10-3A2B12-B5A9-3A3B10-2B5A9-5AB10-2B5A8-6A2B8-3B5A8-8AB6-B8A-D6-8A8B8A-D6-9A7B8A-D6-24AE7-24AK4(7-25A)6-12(27A5-)C26A7-24AC8-A18-A2G3CE6-FB16-BE12-A2B15-B2A10-2A2B14-2B2A10-3AB13-2B3A10-3A3B10-2B4A10-3A15B4A10-2(5A13B5A9-)8A6B9A9-23A8-24AE7-24A2DH5-24AE7(7-25A)7-9(26A6-)C25A8-22A2C8-A18-AG3CE7-FB15-2BD12-2AB14-B2A12-2A2B12-2B2A12-2A4B8-4B3A11-2A13B6A10-3A13B2(6A10-5A11B)6A10-22A10-2(23A9-)23AE8-22AE2(8-24A)8-14(25A7-)2C21A2C10-19A2C11-A16-AG3CE9-AB13-2BA14-A4B8-4BA14-A16BA13-2A16B2A2(12-2A13B5A)12-4A11B6A10-5A11B6A3(10-22A)10-18(23A9-)2C19AC13-16A2C13-3A11-ACJ2CG12-2A3B8-2BHC15-3A11BACJ15-3A11B3A15-3A4(11B4A13-4A)11B4A13-20A12-20A3(11-21A)11-15(22A10-)AC20A12-C16A2C16-12A2C17-3A5-4AJ19-3A6B3AC19-12AJ18-14A18-15A16-16A16-17A15-17A14-5(19A13-)16(20A12-)AC18A14-2C12A3C19-7A3C21-2(7A25-)7A24-8A24-10A21-11A21-2(12A20-)13A2(18-14A)18-2(16A16-)16A15-15(18A14-)2AC15A17-4C5A4C23-5C122-2(4A28-)4A26-2(7A25-)8A24-8A23-3(10A22-)2(12A20-)12A19-13(14A18-)A2C11A21-8C250-2(2A30-)3A29-3A28-4A28-4(5A27-)6A2(25-7A)25-11(8A24-)6C2A79-
