model
size = 8 29 8, scale = 0.05, origin = -y
material 
  colors = A:#B00 B:#A00 C:#C30 D:#222 E:#930 F:#996 G:#CC0 H:#CC6 I:#396 J:#111
voxels
--CCCC-- --AAAA-- --AAAA-- --BBBB-- --BBBB-- --AAAA-- --AAAA-- --AAAA-- --AAAA-- --AAAA-- --AAAA-- --AAAA-- --AAAA-- --AAAA-- --AAAA-- --AAAA-- --AAAA-- --BBBB-- --BBBB-- --AAAA-- --AAAA-- --AAAA-- -------- -------- -------- -------- -------- -------- -------- 
-ECCCCE- -AAAAAA- -AAAAAA- -BBBBBB- -BBBBBB- -AAAAAA- -AAAAAA- -AAAAAA- -AAAAAA- -AAAAAA- -AAAAAA- -AAAAAA- -AAAAAA- -AAAAAA- -AAAAAA- -AAAAAA- -AAAAAA- -BBAABB- -BBBBBB- -AAAAAA- -AADDAA- -AA--AA- -------- -------- -------- -------- -------- -------- -------- 
CCECCECC AAAAAAAA AAAAAAAA BBBBBBBB BBBBBBAB AAAAAAAA AAAAAAAA AAAAAAAA AAAAAAAA AAAAAAAA AAAAAAAA AAAAAAAA AAAAAAAA AAAAAAAA AAAAAAAA AAAAAAAA AAAAAAAA BBBAABBB BBBBBBBB AAAAAAAA AADDDDAA AA----AA -------- -------- -------- -------- -------- -------- -------- 
CCCEECCC AAAAAAAA AAAAAAAA BBBAAAAB BBBAAAAB AAAAAAAA AAAAAAAA AAAAAAAA AAAAAAAA AAAAAAAA AAAAAAAA AAAAAAAA AAAAAAAA AAAAAAAA AAAAAAAA AAAAAAAA AAAAAAAA BBBAABBB BBBAAAAB AAAAAAAA ADDDDDDA A------A -------- -------- -------- -------- -------- -------- ---G---- 
CCEEEECC AAAAAAAA AAAAAAAA BBBAAAAB BBBAAAAB AAAAAAAA AAAAAAAA AAAAAAAA AAAAAAAA AAAAAAAA AAAAAAAA AAAAAAAA AAAAAAAA AAAAAAAA AAAAAAAA AAAAAAAA AAAAAAAA BBBAABBB BBBAAAAB AAAAAAAA ADDDJDDA A---I--A ----F--- ----F--- ---F---- -------- -------- ---F---- --GHG--- 
CECCCCEC AAAAAAAA AAAAAAAA BBBAAAAB BBBAAAAB AAAAAAAA AAAAAAAA AAAAAAAA AAAAAAAA AAAAAAAA AAAAAAAA AAAAAAAA AAAAAAAA AAAAAAAA AAAAAAAA AAAAAAAA AAAAAAAA BBBAABBB BBBBBBBB AAAAAAAA AADDDDAA AA----AA -------- -------- -------- ---F---- ---F---- -------- ---G---- 
-CCCCCC- -AAAAAA- -AAAAAA- -BBAAAB- -BBBBBB- -AAAAAA- -AAAAAA- -AAAAAA- -AAAAAA- -AAAAAA- -AAAAAA- -AAAAAA- -AAAAAA- -AAAAAA- -AAAAAA- -AAAAAA- -AAAAAA- -BBAABB- -BBBBBB- -AAAAAA- -AADDAA- -AA--AA- -------- -------- -------- -------- -------- -------- -------- 
--CCCC-- --AAAA-- --AAAA-- --BBBB-- --BBBB-- --AAAA-- --AAAA-- --AAAA-- --AAAA-- --AAAA-- --AAAA-- --AAAA-- --AAAA-- --AAAA-- --AAAA-- --AAAA-- --AAAA-- --BBBB-- --BBBB-- --AAAA-- --AAAA-- --AAAA-- -------- -------- -------- -------- -------- -------- -------- 
