model
size = 31 25 29, scale = 0.05, origin = -y
material 
  colors = A:#630
voxels
------------------------------- ------------------------------- ------------------------------- ------------------------------- ------------------------------- ---------A-A--AA--------------- -----------AA-AA--------------- -----------AAAAA--------------- -----------AAAAA--------------- ---------A-AAAAAA-------------- ---------A--AAAAAA------------- ---------A--AAAAAA------------- ------------AAAAAAA------------ --------------AA--A------------ ------------------A------------ ------------------------------- ------------------------------- ------------------------------- ------------------------------- ------------------------------- ------------------------------- ------------------------------- ------------------------------- ------------------------------- ------------------------------- 
------------------------------- ------------------------------- ----------A-------------------- ---------AA-------------------- ---------AA------A------------- ---------AAAA-AA-A------------- ---------AAAA-AA-A---A--------- --------AAAAAAAAAAA--A--------- --------AAAAAAAAAAAAAA--------- --------AAAAAAAA-AAAAA--------- ---------AAA-AAAAAAAAA--------- -------A-AAAAAAAAAAAAA--------- ---------AAAAAAAAAAAA---------- ---------AAAAAAAAAAAA---------- ---------AAAAAAAAAAAA---------- ----------AAAAAAAAAAA---------- ----------A-AAAAAAAAA---------- ------------AAAAAAA-A---------- --------------------A---------- ------------------------------- ------------------------------- ------------------------------- ------------------------------- ------------------------------- ------------------------------- 
------------------------------- ------------------------------- ------------------------------- ---------AA-------------------- --------AAA-------------------- --------AAA-------------------- -------AAA--------------------- -------AA------------A--------- -------AA------------A--------- -------AA------------AA-------- -------AA------------AAAA------ -------AAA----A-----AAAAA------ -------AAAA---A----AAAAAA------ --------AAAA------AAAA-AA------ ---------AAAAAAAAAAAAA--------- ---------AAAAAAAAAAAAA--------- ---------AAAAAAAAAAAAA--------- ----------AAAAAAAAAAAA--------- ----------AAAAAAAAAAAA--------- --------A-AA----A-------------- -----------A------------------- ------------------------------- ------------------------------- ------------------------------- ------------------------------- 
------------------------------- ------------------------------- ------------------------------- -------A----------------------- -----AAAA---------------------- -----AAAA---------------------- -----AAA----------------------- ------AA----------------------- ------A----------------A------- ------A----------------A------- -----AAA--------------AAA------ -----AAA--------------AAA------ ------AAA------------AAAAA----- ------AAAA----------AAAAAA----- ------AAAAA--------AAAAAA------ -------AAAAAA----AAAAAAA------- --------AAAAAAAAAAAAAAAA------- --------AAAAAAAAAAAAAAA-------- --------AAAAAAAAAAAAAAA-------- -------AAAAAA------------------ ---------AAA------------------- ----------AA------------------- ------------------------------- ------------------------------- ------------------------------- 
------------------------------- ------------------------------- -----A------------------------- -----AA------------------------ ----AAA------------------------ ----AAA------------------------ ----AAA------------------------ ----AA------------------A------ -----A-----------------AA------ -----A-----------------AA------ ----AA-----------------AA------ ----AAA----------------AA------ ----AAA----------------AA------ -----AAA--------------AAAA----- -----AAAA------------AAAAA----- -----AAAAA----------AAAA------- -----AAAAAAA------AAAAAAA------ ------AAAAAAAAAAAAAAAAA-------- ------AAAAAAAAAAAAAAAAA-------- --------AAAAAAAAAAAAAA--------- ---------AAAAAA---------------- ----------AA------------------- ------------------------------- ------------------------------- ------------------------------- 
------------------------------- ------------------------------- ------------------------------- -----A------------------------- ----AA------------------------- ----AA------------------------- ----AA------------------------- --A-A-------------------------- ----A------------------A------- ----A------------------A------- ----A-------------------------- ----AA------------------------- ----AA------------------------- -----AA----------------AA------ -----AAA--------------AAA------ -----AAAA------------AAA------- -----AAAAA----------AAAA------- -----AAAAAAA------AAAAA-------- ------AAAAAAAAAAAAAAAAA-------- ------AAAAAAAAAAAAAAA---------- ---------AAAAAAAAAAAA---------- ----------AA------------------- ------------------------------- ------------------------------- ------------------------------- 
------------------------------- ----AA------------------------- -----A------------------------- ----AA------------------------- ----AA------------------------- ---AA-------------------------- --AAA-------------------------- --AAA-------------------------- --AA--------------------------- ---A--------------------------- ---AA-------------------------- ---AA-------------------------- ----A-------------------------- ----AA------------------AA----- ----AAA----------------AAA----- ----AAA----------------AAA----- -----AAAA------------AAAAA----- -----AAAAA----------AAAA------- ------AAAAAAA----AAAAAA-------- ------AAAAAAAAAAAAAAA---------- --------AAAAAAAAAAAAA---------- ---------AAA-AAAAA------------- ------------------------------- ------------------------------- ------------------------------- 
------------------------------- -----A------------------------- ----AA------------------------- ----AA------------------------- ---AA-------------------------- ---AA-------------------------- --AA--------------------------- --AA--------------------------- --AA--------------------------- ---A--------------------------- ---A--------------------------- ---A--------------------------- ---AA---------------------A---- ---AA--------------------AAA--- ---AAA------------------AAAA--- ----AAA----------------AAAAA--- -----AAA--------------AAAAAA--- -----AAAA------------AAAA------ ------AAAAA--------AAAA-------- ------AAAAAAAAAAAAAAAAA-------- -------AAAAAAAAAAAAAAA--------- ---------AAAAAAAAAA------------ ------------AAAAAAA------------ ------------------------------- ------------------------------- 
------------------------------- ------------------------------- ----A-------------------------- --AAA-------------------------- --AAA-------------------------- --AAA-------------------------- --AAA-------------------------- --AAA-------------------------- --AAA-------------------------- --AAA-------------------------- --AAA-------------------------- --AAA-------------------------- --AA--------------------------- --AAA--------------------A--A-- --AAA--------------------AAAA-- --AAAA------------------AAAAAA- ----AAA----------------AAAA---- -----AAA--------------AAAA----- -----AAAAA-----------AAA------- ------AAAAAA------AAAAAA------- -------AAAAAAAAAAAAAAAA-------- ---------AAAAAAAAAAAA---------- ------------AAAAAAA------------ ----------------A-------------- ------------------------------- 
---A--------------------------- ---AA-------------------------- ---AA-------------------------- --AAA-------------------------- --AAA-------------------------- --AAA-------------------------- --AAA-------------------------- --AA--------------------------- --AA--------------------------- --AA--------------------------- --AA--------------------------- --AAA-------------------------- -AAA--------------------------- --AA--------------------------- --AAA--------------------A----- --AAA--------------------AAAA-- ---AAA------------------AAAA--- ----AAA----------------AAA----- -----AAAA------------AAAA------ ------AAAAA--------AAAAAA------ -------AAAAAAAAAAAAAAAAA------- ---------AAAAAAAAAAAA---------- ----------AAAAAAAAA------------ ------------------------------- ------------------------------- 
---AA-------------------------- ---AA-------------------------- ---AA-------------------------- --AA--------------------------- --AA--------------------------- -AA---------------------------- -AAA--------------------------- AAAA--------------------------- -AAA--------------------------- -AAA--------------------------- -AAA--------------------------- --AA--------------------------- --AA--------------------------- --AAA-------------------------- --AAA--------------------AAA--- --AAA--------------------AAA--- ---AAA------------------AAA---- ----AAA----------------AAA----- ----AAAA--------------AAA------ ----AAAAAA---AAAA-AAAAAAA------ ----A-AAAAAAAAAAAAAAAAAA------- --------AAAAAAAAAAAAAAA-------- ----------AAAAAAAAAAA---------- --------------AA--------------- ------------------------------- 
------------------------------- ------------------------------- --A---------------------------- --AA--------------------------- --AA--------------------------- -AAA--------------------------- -AAA--------------------------- -AAA--------------------------- -AAA--------------------------- -AAA--------------------------- -AAA--------------------------- -AAA--------------------------- -AAA--------------------------- --AAA-------------------------- --AAA---------------------A---- --AAA--------------------AA---- --AAA--------------------AA---- ----AA------------------AA----- ----AAAA---------------AAA----- ----AAAAA------A--AAAAAAA------ ------AAAAAAAAAAAAAAAAAA------- --------AAAAAAAAAAAAAAA-------- ---------AAAAAAAAAAAA---------- ------------AAAAAA------------- ------------------------------- 
------------------------------- ------------------------------- ------------------------------- ---A--------------------------- --AA--------------------------- -AAA--------------------------- -AAA--------------------------- -AA---------------------------- -AA---------------------------- -AA---------------------------- -AAA--------------------------- -AAA--------------------------- -AAA--------------------------- -AAAA-------------------------- --AAA-------------------------- --AA----------------------AAA-- --AAA--------------------AAAA-- ---AAA------------------AAAA--- ----AAA----------------AAA----- ----AAAAA----AAAA--AAAAAA------ ------AAAAAAAAAAAAAAAAAAA------ -------AAAAAAAAAAAAAAAA-------- ---------AAAAAAAAAAAA---------- ---------AAAAAAAAA------------- -----------A------------------- 
------------------------------- ---A--------------------------- --AA--------------------------- --AA--------------------------- -AAA--------------------------- -AAA--------------------------- -AAA--------------------------- -AAA--------------------------- -AAA--------------------------- -AAA--------------------------- -AAA--------------------------- -AAA--------------------------- -AAA--------------------------- -AA---------------------------- --AA--------------------------- --AA----------------------AAAA- --AAA--------------------AAAAA- ---AAA------------------AAA---- ---AAAA----------------AAA----- ---AAAAAAAA---------AAAAA------ ------AAAAAAAAAAAAAAAAAAA------ ------AAAAAAAAAAAAAAAAA-------- ---------AAAAAAAAAAAA---------- ----------AAAAAAAAA------------ ------------------------------- 
------------------------------- ---A--------------------------- --AA--------------------------- A-AA--------------------------- AAAA--------------------------- -AAA--------------------------- -AAA--------------------------- -AAA--------------------------- -AAA--------------------------- -AAA--------------------------- -AAA--------------------------- -AAA--------------------------- -AAA--------------------------- -AAA--------------------------- --AA--------------------------- --AA----------------------AAAAA --AAA--------------------AAAAAA ---AAA------------------AAAAA-- ---AAAA----------------AAAAA--- ---A-AAAAA---AAA----AAAAA------ ------AAAAAAAAAAAAAAAAAAA------ -------AAAAAAAAAAAAAAAA-------- ---------AAAAAAAAAAAAA--------- ----------AAAAAAAAA------------ ------------------------------- 
------------------------------- ------------------------------- ------------------------------- --AA--------------------------- -AAA--------------------------- -AAA--------------------------- -AAA--------------------------- -AAA--------------------------- -AAA--------------------------- -AAA--------------------------- -AAA--------------------------- -AAA--------------------------- -AAA--------------------------- -AAA--------------------------- --AA--------------------------A --AA----------------------AAAAA --AAA--------------------AAAAAA ---AAA------------------AAAAAA- ---AAAA----------------AAAAAA-- -----AAAA-----A-A---AAAAA------ ------AAAAAAAAAAAAAAAAAA------- -------AAAAAAAAAAAAAAAA-------- ---------AAAAAAAAAAAA---------- ----------AAAAAAAAA------------ ------------------------------- 
------------------------------- ---A--------------------------- ---A--------------------------- --AA--------------------------- -AAA--------------------------- -AAA--------------------------- AAAA--------------------------- AAAA--------------------------- AAAA--------------------------- AAAA--------------------------- AAA---------------------------- AAA---------------------------- -AA---------------------------- --A---------------------------- --AA----------------------AA--- --AAA--------------------AAA--- ---AA--------------------AAAA-- ---AAA------------------AAAAA-- ----AAAA--------------AAAAA---- -----AAAA----AAA-----AAAA------ ------AAAAAAAAAAAAAAAAAA------- --------AAAAAAAAAAAAAAA-------- ---------AAAAAAAAAAAA---------- -----------AAAAAAAA------------ ------------------------------- 
------------------------------- ---A--------------------------- --AA--------------------------- --AA--------------------------- -AAA--------------------------- -AAA--------------------------- AAAA--------------------------- AAAA--------------------------- AAAA--------------------------- AAAA--------------------------- AAAA--------------------------- AAAA--------------------------- --A---------------------------- --AA-----------------------A--- --AA----------------------AA--- ---AA--------------------AAAA-- ---AAA------------------AAAAA-- ----AAA-----------------AAAAA-- ----AAAA---------AAAA-AAAAA---- -----AAAAA-A-----AAAAAAA------- -------AAAAAAAAAAAAAAAA-------- --------AAAAAAAAAAAAAAA-------- ----------AAAAAAAAAAAA--------- --------------AA--------------- ------------------------------- 
------------------------------- ------------------------------- ---A--------------------------- ---A--------------------------- -AAA--------------------------- -AAA--------------------------- AAAA--------------------------- AAAA--------------------------- AAAA--------------------------- AAAA--------------------------- -AAA--------------------------- -AAA--------------------------- --AAAA------------------------- --AAAA------------------------- -AAAAA------------------------- ---AA--------------------AAAA-- ---AAA------------------AAAAA-- ----AAA-----------------AAAA--- -----AAAA--------AAAAAAAAAA---- ------AAAA-------AAAAAAA------- -------AAAAAAAAAAAAAAAA-------- --------AAAAAAAAAAAAAA--------- ----------AAAAAAAAAAAA--------- ------------------------------- ------------------------------- 
------------------------------- ----A-------------------------- ----A-------------------------- ----A-------------------------- ---AA-------------------------- --AA--------------------------- -AAA--------------------------- -AAA--------------------------- -AAA--------------------------- -AAA--------------------------- -AAA--------------------------- -AAA--------------------------- -AAAAA------------------------- -AAAAA------------------------- --AAAA-------------------A----- ---AAA------------------AAAA--- ----AAA----------------AAAAAAA- -----AAA--------------AAAAAA--- ------AAAA-------AAAAAAAA------ -------AAA-A-----AAAAAA-------- --------AAAAAAAAAAAAAAA-------- --------AAAAAAAAAAAAAA--------- ----------AAAAAAAAAAAA--------- ------------------------------- ------------------------------- 
------------------------------- ------------------------------- ---AAA------------------------- ---AAA------------------------- --AAA-------------------------- --AAA-------------------------- -AAA--------------------------- -AAA--------------------------- -AAA--------------------------- -AAA--------------------------- -AAA--------------------------- -AAA--------------------------- -AAAA-------------------------- -AAAA-------------------------- ---AAA------------------AA----- ---AAAA----------------AAA----- ----AAAA--------------AAAAAAA-- -----AAAA------------AAAAAAA--- ------AAAAA--------AAAAAA------ -------AAAAAAAAAAAAAAAA-------- --------AAAAAAAAAAAAAAA-------- ---------AAAAAAAAAAA----------- ------------A------------------ ------------------------------- ------------------------------- 
------------------------------- -----AA------------------------ ----AAA------------------------ ---AAAA------------------------ ---AAA------------------------- --AAAA------------------------- -AAAAA------------------------- --AAA-------------------------- --AA-A------------------------- -AAA-A------------------------- AAAAA-------------------------- -AAAA-------------------------- --AAA-------------------------- --AAA--------------------A----- ---AAAA----------------AAA----- -----AA----------------AAAA---- ------AAA------------AAAAAA---- ------AAAA----------AAAAAA----- ------AAAAAAA----AAAAAAAA------ ---------AAAAAAAAAAAAAA-------- ----------AAAAAAAAAAAAA-------- ----------AAAAAAA-------------- ------------------------------- ------------------------------- ------------------------------- 
------------------------------- ------------------------------- ---A--------------------------- ---A--------------------------- ---A--------------------------- --AA-AA------------------------ --AAAAA------------------------ ---AAAA------------------------ ---AAAAAA---------------------- ---AAAAAA---------------------- ---AAAAAA---------------------- ---AAAAAA---------------------- ---AAAAAA---------------------- ----AAAAA---------------------- ----AAAAA-------------A-------- ------AAA------------AAAAAA---- ------AAAA----------AAAAAAA---- -------AAAAA------AAAAAAAA----- ---------AAAAAAAAAAAAAA-------- ---------AAAAAAAAAAA----------- ---------AAAAAAAAAAA----------- ------------A----A------------- ------------------------------- ------------------------------- ------------------------------- 
------------------------------- ------------------------------- -------A----------------------- -------A----------------------- ------AAAAA-------------------- -----AAAAAA-------------------- -----AAAAAA-------------------- -----AAAAAA-------------------- -----AAAAAA-------------------- -----AAAAAA-------------------- -----AAAAAA-------------------- -----AAAAAA------------A------- -----AAAAAA------------AA------ ------AAAAA-----------AAAA----- ------AAAAA----------AAAAA----- ------AAAAA---------AAAAA------ -------AAAAA------AAAAAAA------ -------AAAAAAAAAAAAAAAA-------- ----------AAAAAAAAAAAAA-------- ----------AAAAAAAAAA----------- -----------AAAAAAAAA----------- ------------A------------------ ------------------------------- ------------------------------- ------------------------------- 
------------------------------- ------------------------------- --------AA--------------------- -----A-AAA--------------------- -----A--AA--------------------- -----AAAA---------------------- -----AAA----------------------- -----AAA----------------A------ -----AA-----------------A------ ------A----------------AA------ ------AA---------------AA------ -----AAA--------------AAA------ ------AAA------------AAAA------ -------AAA----------AAAAA------ -------AAAA--------AAAAAA------ -------AAAAAA----AAAAAAA------- ---------AAAAAAAAAAAAAAA------- ---------AAAAAAAAAAAAAA-------- ---------AAAAAAAAAAAAAA-------- ------------AAAAAAAA----------- --------------AAAAAA----------- ------------------------------- ------------------------------- ------------------------------- ------------------------------- 
------------------------------- ------------------------------- ---------A--------------------- --------AAA--------AA---------- --------AAA--------AA---------- --------AAA--------AA---------- -------AAA--------------------- -------AA---------------------- -------AA---------------------- -------AA-------------A-------- -------AA-------AA----A-------- -------AAA------AA--AAAA------- --------AAA--------AAA--------- --------AAAA------AAAA--------- ---------AAAAAAAAAAAAAA-------- ---------AAAAAAAAAAAAAAAA------ ---------AAAAAAAAAAAAAAA------- -------------AAAAAAAAAA-------- -------------AAAAAAAAA--------- -------------AAAAAAA----------- ---------------A--------------- ------------------------------- ------------------------------- ------------------------------- ------------------------------- 
------------------------------- ------------------------------- ------------------------------- -----------A-A-A--A------------ ----------AA-AAA-AAAA---------- ---------AAA-AAA-AAAAA--------- ---------AAAAAAAAAAAA---------- ---------AAAAAAAAAAAA---------- ---------AA--AAAAAAAAA--------- ---------AA--AAAAAAAAAA-------- -------A-AAAAAAAAAAAAAA-------- ---------AAAAAAAAAAA----------- ---------AAAAAAAAAAA----------- ----------AAAAAAAAAA----------- ----------AAAAAAAAAAAA--------- ---------A-AAAAAAAAAAA--------- -------------AAAAAAAAA--------- -------------AAAAAAAA---------- ---------------A-AAAA---------- ---------------A--------------- ------------------------------- ------------------------------- ------------------------------- ------------------------------- ------------------------------- 
------------------------------- ------------------------------- ---------------A--------------- ---------------A--------------- -------------A-AA-A------------ ------------AA-AA-------------- -----------AAAAAA-A------------ -----------AAAAAAAA------------ -----------AAAAAAAA------------ -----------AAAAAAAA------------ -----------AAAAAAAA------------ -----------AAAAAAA------------- ------------AAAAAA-A----------- -------------AAAA-------------- --------------AAAAA------------ --------------AAAAA------------ --------------AAAAA------------ --------------AAAA------------- ------------------------------- ------------------------------- ------------------------------- ------------------------------- ------------------------------- ------------------------------- ------------------------------- 
------------------------------- ------------------------------- ------------------------------- ------------------------------- ------------------------------- ------------------------------- ------------------------------- ------------------------------- ------------------------------- -----------A------------------- ------------------------------- ------------------------------- ------------------------------- ------------------------------- ------------------------------- --------------A---------------- ------------------------------- ------------------------------- ------------------------------- ------------------------------- ------------------------------- ------------------------------- ------------------------------- ------------------------------- ------------------------------- 
