model
size = 32, scale = 0.05, origin = -y
material 
  colors = A:#111 B:#3F0 C:#0F3
voxels
33A29(30-2A)30-65A80-24(B31-)B17-27B67-2(A30-33A960-)A30-33A65-24(B31-)B99-23C4-A30-33A65-B767-B100-C25-A30-33A65-B767-B101-C24-A30-33A65-B767-B102-C23-A30-33A65-B767-B103-C22-A30-33A65-B767-B104-C21-A30-33A65-B767-B105-C20-A30-33A65-B767-B106-C19-A30-33A65-B767-B107-C18-A30-33A65-B767-B108-C17-A30-33A65-B767-B109-C16-2(A30-33A65-B767-B110-C15-)A30-33A65-B767-B111-C14-A30-33A65-B767-B112-C13-A30-33A65-B767-B113-C12-A30-33A65-B767-B114-C11-A30-33A65-B767-B115-C10-A30-33A65-B767-B116-C9-A30-33A65-B767-B117-C8-A30-33A65-B767-B118-C7-A30-33A65-B767-B119-C6-A30-33A65-B767-B120-C5-A30-33A65-B767-B99-23C4-A30-33A65-24(B31-)B126-A30-33A960-A30-33A99-27B19-21(B31-)B17-26B99-A30-34A29(30-2A)30-33A
