model
size = 7 32 3, scale = 0.05, origin = -y
material 
  colors = A:#AAA B:#FC3 C:#00D D:#FF9
voxels
2-3B5(4-B-B)3-5B2(2-B3-B)-2B3-10B5-B142-3B5(4-BCB)3-B3D2(B2-B3C)B-BD3CD2B5D2B5AB-9(2AC2A2-)2AC2A-3A6(C6A)C3A-5A3-3A5-A5-3B5(4-B-B)3-5B2(2-B3-B)-2B3-10B5-B140-
