model
size = 5 10 14, scale = 0.05, origin = -y
material 
  colors = A:#9CF
voxels
---AA ---AA ---AA ---AA ----A ----A ----- ----- ----- ----- 
--A-- --A-- --A-- --AA- --AAA ---AA ---AA ----A ----- ----- 
-A--- -A--- -A--- -AA-- --AA- --AAA --AAA ---AA ----A ----- 
-A--- -A--- -A--- -A--- -AA-- -AAA- --AAA --AAA ---AA ----- 
A---- A---- A---- A---- -A--- -AA-- -AAA- --AAA ---AA ----A 
A---- A---- A---- A---- A---- -A--- -AA-- --AA- --AAA ----A 
A---- A---- A---- A---- A---- A---- -A--- -AA-- --AA- ---AA 
A---- A---- A---- A---- A---- A---- -A--- -AA-- --AA- ---AA 
A---- A---- A---- A---- A---- -A--- -AA-- --AA- --AAA ----A 
A---- A---- A---- A---- -A--- -AA-- -AAA- --AAA ---AA ----A 
-A--- -A--- -A--- -A--- -AA-- -AAA- --AAA --AAA ---AA ----- 
-A--- -A--- -A--- -AA-- --AA- --AAA --AAA ---AA ----A ----- 
--A-- --A-- --A-- --AA- --AAA ---AA ---AA ----A ----- ----- 
---AA ---AA ---AA ---AA ----A ----A ----- ----- ----- ----- 
