model
size = 24 31 28, scale = 0.05, origin = -y
material 
  colors = A:#C6C6C6 B:#FFDB2D C:#FFF D:#ECECEC E:#B4B4B4 F:#D9D9D9 G:#ECC711 H:#C6AE35 I:#FFD400 J:#A1A1A1 K:#FFE25C L:#D9BA23 M:#FFE573 N:#FFEDA1 O:#FFE98A P:#FFD716 Q:#A19558 R:#FFDE44 S:#B4A146
voxels
------------------------ ------------------------ ------------------------ ------------------------ ------------------------ ------------------------ ------------------------ ------------------------ ------------------------ ------------------------ ------------------------ ------------------------ ------------------------ ------------------------ ------------------------ ------------------------ ------------------------ ------------------------ ------------------------ ------------------------ ------------------------ ------------------------ ------------------------ -----------CC----------- -----------CC----------- -----------CC----------- -----------CC----------- ------------------------ ------------------------ ------------------------ ------------------------ 
------------------------ ------------------------ ------------------------ ------------------------ ------------------------ ------------------------ ------------------------ ------------------------ ------------------------ ------------------------ ------------------------ ------------------------ ------------------------ ------------------------ ------------------------ ------------------------ ------------------------ ------------------------ ------------------------ ------------------------ ------------------------ -----------CC----------- -----------CC----------- ----------DCCD---------- ----------DCCD---------- ----------DCCD---------- ----------DCCD---------- ----------DDDD---------- -----------DD----------- ------------------------ ------------------------ 
------------------------ ------------------------ ------------------------ ------------------------ ------------------------ ------------------------ ------------------------ ------------------------ ------------------------ -----------HG----------- -----------GH----------- ------------------------ ------------------------ ------------------------ ------------------------ ------------------------ ------------------------ ------------------------ ------------------------ ------------------------ -----------DD----------- ----------DCCD---------- ----------DCCD---------- ----------DCCD---------- -----------CC----------- -----------CC----------- -----------CC----------- -----------CN----------- -----------NC----------- -----------DN----------- ------------------------ 
------------------------ ------------------------ ------------------------ ------------------------ ------------------------ ------------------------ ------------------------ ------------------------ ---------MONNOM--------- ---------BBBBBB--------- ---------BBBBBB--------- ---------IIIIII--------- ------------------------ ------------------------ ------------------------ ------------------------ ------------------------ ------------------------ ------------------------ -----------FF----------- ----------DCCD---------- ---------DCCCCD--------- ----------DCCD---------- -----------CC----------- ------------------------ ------------------------ ------------------------ ------------------------ ------------------------ -----------CN----------- -----------NC----------- 
------------------------ ------------------------ ------------------------ ------------------------ ------------------------ ------------------------ ------------------------ ------------------------ -------KMAAAAAAMK------- -------BBAAAAAABB------- -------BBAAAAAABB------- -------GGAAAAAAGG------- ---------FFAAFF--------- ----------AAAA---------- ------------------------ ------------------------ -----------HG----------- -----------GH----------- -----------AA----------- ----------DCCD---------- ---------DCCCCD--------- ----------DCCD---------- -----------CC----------- ------------------------ ------------------------ ------------------------ ------------------------ ------------------------ ------------------------ ------------------------ ------------------------ 
------------------------ ------------------------ ------------------------ ------------------------ ------------------------ ------------------------ ------------------------ ------------------------ -----BKAA------AAKB----- ---HGBBAA------AABBGH--- ---GHBBAA------AABBHG--- -----LGAA------AAGL----- -------AA------AA------- -------FAA----AAF------- --------AAAEEAAA-------- ---------JEEEEJ--------- ---------BBBBBB--------- ---------BBCCBB--------- ----------ACCA---------- ---------FCCCCF--------- ---------FFCCFF--------- -----------FF----------- -----------DD----------- ------------------------ ------------------------ ------------------------ ------------------------ ------------------------ ------------------------ ------------------------ ------------------------ 
------------------------ ------------------------ ------------------------ ------------------------ ------------------------ ------------------------ ------------------------ ------------------------ ----KAA----------AAK---- ---GBAA----------AABG--- ---HBAA----------AABH--- ----LHA----------AHL---- ------E----------E------ ------F----------F------ ------AA--------AA------ -------EE------EE------- --------JAAAAAAJ-------- --------BBCAACBB-------- --------BBCAACBB-------- ---------ACAACA--------- ----------FCCF---------- -----------FF----------- ------------------------ ------------------------ ------------------------ ------------------------ ------------------------ ------------------------ ------------------------ ------------------------ ------------------------ 
------------------------ ------------------------ ------------------------ ------------------------ ------------------------ ------------------------ ------------------------ ------------------------ ---KA--------------AK--- ---BA--------------AB--- ---BA--------------AB--- ---LH--------------HL--- -----E------------E----- -----A------------A----- -----F------------F----- ------A----------A------ -------J--------J------- -------BAAA--AAAB------- -------HQCAAAACQG------- -------GBNCAACNBH------- ----------AAAA---------- ------------------------ ------------------------ ------------------------ ------------------------ ------------------------ ------------------------ ------------------------ ------------------------ ------------------------ ------------------------ 
------------------------ ------------------------ ------------------------ ------------------------ ------------------------ ------------------------ ------------------------ ------------------------ ---MA--------------AM--- ---BA--------------AB--- ---BA--------------AB--- ---LA--------------AL--- ----E--------------E---- ----A--------------A---- ----D--------------D---- -----F------------F----- ------E----------E------ -------J--------J------- -------BAAA--AAAB------- -------BBBBAABBBB------- ---------BICCIB--------- -----------GH----------- ------------------------ ------------------------ ------------------------ ------------------------ ------------------------ ------------------------ ------------------------ ------------------------ ------------------------ 
------------------------ ------------------------ ------------------------ ------------------------ ------------------------ ------------------------ ------------------------ ------------------------ --MA----------------AM-- --BA----------------AB-- --BA----------------AB-- --LA----------------AL-- ---E----------------E--- ---A----------------A--- ----F--------------F---- ----D--------------D---- -----F------------F----- ------E----------E------ -------JA------AJ------- --------BAA--AAB-------- --------BBBAABBB-------- ----------RHGR---------- ------------------------ ------------------------ ------------------------ ------------------------ ------------------------ ------------------------ ------------------------ ------------------------ ------------------------ 
------------------------ ------------------------ ------------------------ ------------------------ ------------------------ ------------------------ ------------------------ ------------------------ --OA----------------AO-- --BA----------------AB-- --BA----------------AB-- --GA----------------AG-- ---J----------------J--- ---E----------------E--- ---A----------------A--- ----A--------------A---- ----A--------------A---- -----F------------F----- ------EE--------EE------ --------J------J-------- ---------JE--EJ--------- -----------EE----------- ------------------------ ------------------------ ------------------------ ------------------------ ------------------------ ------------------------ ------------------------ ------------------------ ------------------------ 
------------------------ ------------------------ -S---------------------- -H---------------------- ------------------------ ------------------------ ------------------------ ------------------------ -BA------------------AO- -BA------------------AB- -BA------------------AB- -GA------------------AG- --J------------------J-- ---J----------------J--- ---E----------------E--- ---E----------------E--- ----E--------------E---- -----A------------A----- ------A----------A------ -------F--------F------- --------FA----AF-------- ----------AAAA---------- ------------------------ ------------------------ ------------------------ ------------------------ ------------------------ ------------------------ ------------------------ ------------------------ ------------------------ 
------------------------ -L---------------------- -I---------------------- -I---------------------- -H---------------------- -Q---------------------- -Q---------------------- -H---------------------- -BA------------------AO- -BA------------------AB- -BA------------------AB- -IA------------------AI- -HA------------------AH- --H------------------H-- --HA----------------AH-- ---G----------------G--- ---GA--------------AG--- ----IA------------AI---- -----IA----------AI----- ------IA--------AI------ -------IA------AI------- --------PBA--ABP-------- ----------KOOK---------- ------------------------ ------------------------ ------------------------ ------------------------ ------------------------ ------------------------ ------------------------ ------------------------ 
-L---------------------- -I---------------------- -K---------------------- -M---------------------- -M---------------------- -K---------------------- -I---------------------- -B---------------------- -BA------------------AN- HBA------------------ABH GBA------------------ABG -IA------------------AI- -MA------------------AM- -MA------------------AM- --KA----------------AK-- --KA----------------AK-- ---KA--------------AK--- ---RA--------------AR--- ----BA------------AB---- -----PA----------AP----- ------PA--------AP------ -------IAA----AAI------- --------GLLBBLLG-------- -----------GH----------- ------------------------ ------------------------ ------------------------ ------------------------ ------------------------ ------------------------ ------------------------ 
-L---------------------- -I---------------------- -K---------------------- -N---------------------- -M---------------------- -K---------------------- -I---------------------- -B---------------------- -BA------------------AN- GBA------------------ABG HBA------------------ABH -IA------------------AI- -MA------------------AM- -MA------------------AM- --KA----------------AK-- --KA----------------AK-- ---KA--------------AK--- ---RA--------------AR--- ----BA------------AB---- -----PA----------AP----- ------PA--------AP------ -------IAA----AAI------- --------GLLBBLLG-------- -----------HG----------- ------------------------ ------------------------ ------------------------ ------------------------ ------------------------ ------------------------ ------------------------ 
------------------------ -L---------------------- -I---------------------- -I---------------------- -H---------------------- -Q---------------------- -Q---------------------- -H---------------------- -BA------------------AO- -BA------------------AB- -BA------------------AB- -IA------------------AI- -HA------------------AH- --H------------------H-- --HA----------------AH-- ---G----------------G--- ---GA--------------AG--- ----IA------------AI---- -----IA----------AI----- ------IA--------AI------ -------IA------AI------- --------PBA--ABP-------- ----------KOOK---------- ------------------------ ------------------------ ------------------------ ------------------------ ------------------------ ------------------------ ------------------------ ------------------------ 
------------------------ ------------------------ -S---------------------- -H---------------------- ------------------------ ------------------------ ------------------------ ------------------------ -BA------------------AO- -BA------------------AB- -BA------------------AB- -GA------------------AG- --J------------------J-- ---J----------------J--- ---E----------------E--- ---E----------------E--- ----E--------------E---- -----A------------A----- ------A----------A------ -------F--------F------- --------FA----AF-------- ----------AAAA---------- ------------------------ ------------------------ ------------------------ ------------------------ ------------------------ ------------------------ ------------------------ ------------------------ ------------------------ 
------------------------ ------------------------ ------------------------ ------------------------ ------------------------ ------------------------ ------------------------ ------------------------ --OA----------------AO-- --BA----------------AB-- --BA----------------AB-- --GA----------------AG-- ---J----------------J--- ---E----------------E--- ---A----------------A--- ----A--------------A---- ----A--------------A---- -----F------------F----- ------EE--------EE------ --------J------J-------- ---------JE--EJ--------- -----------EE----------- ------------------------ ------------------------ ------------------------ ------------------------ ------------------------ ------------------------ ------------------------ ------------------------ ------------------------ 
------------------------ ------------------------ ------------------------ ------------------------ ------------------------ ------------------------ ------------------------ ------------------------ --MA----------------AM-- --BA----------------AB-- --BA----------------AB-- --LA----------------AL-- ---E----------------E--- ---A----------------A--- ----F--------------F---- ----D--------------D---- -----F------------F----- ------E----------E------ -------JA------AJ------- --------BAA--AAB-------- --------BBBAABBB-------- ----------RGHR---------- ------------------------ ------------------------ ------------------------ ------------------------ ------------------------ ------------------------ ------------------------ ------------------------ ------------------------ 
------------------------ ------------------------ ------------------------ ------------------------ ------------------------ ------------------------ ------------------------ ------------------------ ---MA--------------AM--- ---BA--------------AB--- ---BA--------------AB--- ---LA--------------AL--- ----E--------------E---- ----A--------------A---- ----D--------------D---- -----F------------F----- ------E----------E------ -------J--------J------- -------BAAA--AAAB------- -------BBBBAABBBB------- ---------BICCIB--------- -----------HG----------- ------------------------ ------------------------ ------------------------ ------------------------ ------------------------ ------------------------ ------------------------ ------------------------ ------------------------ 
------------------------ ------------------------ ------------------------ ------------------------ ------------------------ ------------------------ ------------------------ ------------------------ ---KA--------------AK--- ---BA--------------AB--- ---BA--------------AB--- ---LH--------------HL--- -----E------------E----- -----A------------A----- -----F------------F----- ------A----------A------ -------J--------J------- -------BAAA--AAAB------- -------HQCAAAACQG------- -------GBNCAACNBH------- ----------AAAA---------- ------------------------ ------------------------ ------------------------ ------------------------ ------------------------ ------------------------ ------------------------ ------------------------ ------------------------ ------------------------ 
------------------------ ------------------------ ------------------------ ------------------------ ------------------------ ------------------------ ------------------------ ------------------------ ----KAA----------AAK---- ---GBAA----------AABG--- ---HBAA----------AABH--- ----LHA----------AHL---- ------E----------E------ ------F----------F------ ------AA--------AA------ -------EE------EE------- --------JAAAAAAJ-------- --------BBCAACBB-------- --------BBCAACBB-------- ---------ACAACA--------- ----------FCCF---------- -----------FF----------- ------------------------ ------------------------ ------------------------ ------------------------ ------------------------ ------------------------ ------------------------ ------------------------ ------------------------ 
------------------------ ------------------------ ------------------------ ------------------------ ------------------------ ------------------------ ------------------------ ------------------------ -----BKAA------AAKB----- ---HGBBAA------AABBGH--- ---GHBBAA------AABBHG--- -----LGAA------AAGL----- -------AA------AA------- -------FAA----AAF------- --------AAAEEAAA-------- ---------JEEEEJ--------- ---------BBBBBB--------- ---------BBCCBB--------- ----------ACCA---------- ---------FCCCCF--------- ---------FFCCFF--------- -----------FF----------- -----------DD----------- ------------------------ ------------------------ ------------------------ ------------------------ ------------------------ ------------------------ ------------------------ ------------------------ 
------------------------ ------------------------ ------------------------ ------------------------ ------------------------ ------------------------ ------------------------ ------------------------ -------KMAAAAAAMK------- -------BBAAAAAABB------- -------BBAAAAAABB------- -------GGAAAAAAGG------- ---------FFAAFF--------- ----------AAAA---------- ------------------------ ------------------------ -----------HG----------- -----------GH----------- -----------AA----------- ----------DCCD---------- ---------DCCCCD--------- ----------DCCD---------- -----------CC----------- ------------------------ ------------------------ ------------------------ ------------------------ ------------------------ ------------------------ ------------------------ ------------------------ 
------------------------ ------------------------ ------------------------ ------------------------ ------------------------ ------------------------ ------------------------ ------------------------ ---------MONNOM--------- ---------BBBBBB--------- ---------BBBBBB--------- ---------IIIIII--------- ------------------------ ------------------------ ------------------------ ------------------------ ------------------------ ------------------------ ------------------------ -----------FF----------- ----------DCCD---------- ---------DCCCCD--------- ----------DCCD---------- -----------CC----------- ------------------------ ------------------------ ------------------------ ------------------------ ------------------------ -----------NC----------- -----------CN----------- 
------------------------ ------------------------ ------------------------ ------------------------ ------------------------ ------------------------ ------------------------ ------------------------ ------------------------ -----------HG----------- -----------GH----------- ------------------------ ------------------------ ------------------------ ------------------------ ------------------------ ------------------------ ------------------------ ------------------------ ------------------------ -----------DD----------- ----------DCCD---------- ----------DCCD---------- ----------DCCD---------- -----------CC----------- -----------CC----------- -----------CC----------- -----------NC----------- -----------CN----------- -----------ND----------- ------------------------ 
------------------------ ------------------------ ------------------------ ------------------------ ------------------------ ------------------------ ------------------------ ------------------------ ------------------------ ------------------------ ------------------------ ------------------------ ------------------------ ------------------------ ------------------------ ------------------------ ------------------------ ------------------------ ------------------------ ------------------------ ------------------------ -----------CC----------- -----------CC----------- ----------DCCD---------- ----------DCCD---------- ----------DCCD---------- ----------DCCD---------- ----------DDDD---------- -----------DD----------- ------------------------ ------------------------ 
------------------------ ------------------------ ------------------------ ------------------------ ------------------------ ------------------------ ------------------------ ------------------------ ------------------------ ------------------------ ------------------------ ------------------------ ------------------------ ------------------------ ------------------------ ------------------------ ------------------------ ------------------------ ------------------------ ------------------------ ------------------------ ------------------------ ------------------------ -----------CC----------- -----------CC----------- -----------CC----------- -----------CC----------- ------------------------ ------------------------ ------------------------ ------------------------ 
