model
size = 17 30 11, scale = 0.05, origin = -y
material 
  colors = A:#AF7754 B:#F3E1C9 C:#5B4224 D:#4D2A0A E:#3D3123 F:#E8B8AA G:#FFF
voxels
----------------- ----------------- ----------------- ----------------- ----------------- ----------------- ----------------- ----------------- ----------------- BFFBBBBBBFFB----- BFFBBBBBBFFB----- BDDBGGGGBDDB----- BEEBGGGGBEEB----- BBBBAEAABBBB----- AAAAEEEAAAAA----- AAAAAAAAAAAA----- AAAAAAAAAAAA----- AAAAAAAAAAAA----- AAAAAAAAAAAA----- AAAAAAAAAAAA----- ----------------- ----------------- ----------------- ----------------- ----------------- ----------------- ----------------- ----------------- ----------------- ----------------- 
----------------- ----------------- ----------------- ----------------- ----------------- ----------------- ----------------- ----------------- ----------------- ABBBBBBBBBBA----- AAAAAAAAAAAA----- AAAAAAAAAA-A----- AAAAAAAAAA-A----- AAAAAAAAAAAA----- A---------AA----- A----------A----- A----------A----- A----------A----- AAAAAAAAAAAA----- AAAAAAAAAAAA----- ----------------- ----------------- ----------------- ----------------- ----------------- ----------------- ----------------- ----------------- ----------------- ----------------- 
---D----------D-- ---A----------A-- --AA---------AA-- --AABBBBBBBBBAA-- --AABBBBBBBBBAA-- --AAAAAAAAAAAAB-- --AAAAAAAABAAAA-- --AAAAAAAAAAAAA-- --AAAAAAAAAAABA-- AAAAAAAAAAAA----- AAAAAAAAAAAA----- AAAAAAAAAAAA----- AAAAAAAAAAAA----- AAAAAAAAAAAA----- A---------AA----- A----------A----- A----------A----- A----------A----- AAAAAAAAAAAA----- AAAAAAAAAAAA----- ----------------- ----------------- ----------------- ----------------- ----------------- ----------------- ----------------- ----------------- ----------------- ----------------- 
---D----------D-- ---A----------A-- --AA---------AA-- --AABBBBBBBBBAA-- --AAAAAAAAAAAAA-- --AAAAAAAAAAAAA-- --AAAAAAAAAAAAA-- --AAAAAAAAAAAAA-- --AAAAAAAAAAAAA-- AAAAAAAAAAAA----- AAAAAAAAAAAA----- AAAAAAAAAAAA----- AAAAAAAAAAAA----- AAAAAAAAAAAA----- A---------AA----- A----------A----- A----------A----- A----------A----- AAAAAAAAAAAA----- AAAAAAAAAAAA----- ----------------- ----------------- ----------------- ----------------- ----------------- ----------------- ----------------- ----------------- ----------------- ----------------- 
----------------- ----------------- ----------------- --BBBBBBBBBBBBB-- --BAAAAAAAAAAAB-- --BAAAAAAAAAAAA-- --BAAAAAAAAAAAA-- --BAAAAAAAAAAAA-- --BAAAAAAAAAAAA-- AAAAAAAAAAAA----- AAAAAAAAAAAA----- AAAAAAAAAAAA----- AAAAAAAAAAAA----- AAAAAAAAAAAA----- AAAAAAAAA-AA----- AAAAAAAAA-AA----- A----------A----- A----------A----- AAAAAAAAAAAA----- AAAAAAAAAAAA----- ---------BBA----- ---------AAA----- ---------AAA----- ----------------- ----------------- ----------------- ----------------- ----------------- ----------------- ----------------- 
----------------- ----------------- ----------------- --BBBBBBBBBBBBB-- --BAAAAAAAAAAAB-- --BAAAAAAAAAAAA-- --BAAAAAAAAAAAA-- --BAAAAAAAAAAAABB --BAAAAAAAAAAAAAA AAAAAAAAAAAA----- AAAAAAAAAAAA----- AAAAAAAAAAAA----- AAAAAAAAAAAA----- AAAAAAAAAAAA----- AAAAAAAAA-AA----- AAAAAAAAA-AA----- A----------A----- A----------A----- AAAAAAAAAAAA----- AAAAAAAABAAA----- --------CAAA----- --------CAAA----- --------CAAA----- --------CEE------ --------C-------- --------CCC------ --------C-C------ --------C-C------ --------C-------- --------C-------- 
----------------- ----------------- ----------------- --BBBBBBBBBBBBB-- --BAAAAAAAAAAAB-- --BAAAAAAAAAAAA-- --BAAAAAAAAAAAA-- --BAAAAAAAAAAAABB --BAAAAAAAAAAAAAA AAAAAAAAAAAA----- AAAAAAAAAAAA----- AAAAAAAAAAAA----- AAAAAAAAAAAA----- AAAAAAAAAAAA----- AAAAAAAAA-AA----- AAAAAAAAAAAA----- AAAAAAAAAAAA----- AAAAAAAAAAAA----- AAAAAAAAAAAA----- AAAAAAAAAAAA----- ABBC------------- AAAC------------- AAAC------------- -EEC------------- ---C------------- -CCC------------- -C-C------------- -C-C------------- ---C------------- ---C------------- 
----------------- ----------------- ----------------- --BBBBBBBBBBBBB-- --BAAAAAAAAAAAB-- --BAAAAAAAAAAAA-- --BAAAAAAAAAAAA-- --BAAAAAAAAAAAA-- --BAAAAAAAAAAAA-- AAAAAAAAAAAA----- AAAAAAAAAAAA----- AAAAAAAAAAAA----- AAAAAAAAAAAA----- AAAAAAAAAAAA----- AAAAAAAAA-AA----- AAAAAAAAAAAA----- AAAAAAAAAAAA----- AAAAAAAAAAAA----- AAAAAAAAAAAA----- AAAAAAAAAAAA----- AAA-------------- AAA-------------- AAA-------------- ----------------- ----------------- ----------------- ----------------- ----------------- ----------------- ----------------- 
------D-----D---- ------A-----A---- -----AA----AA---- --AAABABBBBAAAA-- --ABBAAAAAAAAAA-- --AAAAAAAAAAAAA-- --AAAAAAAAAAAAA-- --AAAAAAAAAAAAA-- --AAAAAAAAAAAAA-- AAAAAAAAAAAA----- AAAAAAAAAAAA----- AAAAAAAAAAAA----- AAAAAAAAAAAA----- AAAAAAAAAAAA----- AAAAAAAAA-AA----- AAAAAAAAAAAA----- AAAAAAAAAAAA----- AAAAAAAAAAAA----- AAAAAAAAAAAA----- AAAAAAAAAAAA----- ----------------- ----------------- ----------------- ----------------- ----------------- ----------------- ----------------- ----------------- ----------------- ----------------- 
------D-----D---- ------A-----A---- -----AA----AA---- --AAAAABBBBAAAA-- --AAAAABBBBAAAA-- --AAAAAAAAAAABA-- --AAAAAAAAAAAAA-- --AAAAAAABAAAAA-- --AAAAAAAAAABAA-- AAAAAAAAAAAA----- AAAAAAAAAAAA----- AAAAAAAAAAAA----- AAAAAAAAAAAA----- AAAAAAAAAA-A----- AAAAAAAAA-AA----- AAAAAAAAAAAA----- AAAAAAAAAAAA----- AAAAAAAAAAAA----- AAAAAAAAAAAA----- AAAAAAAAAAAA----- ----------------- ----------------- ----------------- ----------------- ----------------- ----------------- ----------------- ----------------- ----------------- ----------------- 
----------------- ----------------- ----------------- ----------------- ----------------- ----------------- ----------------- ----------------- ----------------- AAAAAAAAAAAA----- AAAAAAAAAAAA----- AAAAAAAAAAAA----- AAAAAAAAAAAA----- AAAAAAAAAAAA----- AAAAAAAAAAAA----- AAAAAAAAAAAA----- AAAAAAAAAAAA----- AAAAAAAAAAAA----- AAAAAAAAAAAA----- AAAAAAAAAAAA----- ----------------- ----------------- ----------------- ----------------- ----------------- ----------------- ----------------- ----------------- ----------------- ----------------- 
