model
size = 14 19 19, scale = 0.05, origin = -y
material 
  colors = A:#9CE33B B:#6C3 C:#1A222F D:#FFF E:#F3E1C9 F:#FCDFAC G:#FFC86B H:#FB807B
voxels
-------------- -------------- -------------- -------------- -------------- -------------- -------------- -------------- -------------- -------------- AHHAAAAAAAAHHA AHHAAAAAAAAHHA ACCADDDDDDACCA ACCADDDDDDACCA AAAAAAAAAAAAAA AAAAAAAAAAAAAA AAAAAAAAAAAAAA AAAAAAAAAAAAAA -------------- 
-------------- -------------- -------------- -------------- -------------- -------------- -------------- -------------- -------------- -------------- AAAAAAAAAAAAAA AAAAAAAAAAA-AA ACCAAAAAADA-AA ACCAAAAAADA-AA AAAAAAAAAAAAAA AAAAAAAAAAAAAA AAAAAAAAAAAAAA AAAAAAAAAAAAAA -------------- 
-------------- -------------- -------------- -------------- -------------- -------------- -------------- -------------- -------------- -------------- AAAAAAAAAAAAAA AAAAAAAAAAAAAA AAAAAAAAADAAAA AAAAAAAAADAAAA AAAAAAAAAAAAAA AAAAAAAAAAAAAA AAAAAAAAAAAAAA AAAAAAAAAAAAAA -------------- 
-------------- -------------- -------------- -------------- -------------- -------------- -------------- -------------- -------------- -------------- AAAAAAAAAAAAAA AAAAAAAAAAAAAA AAAAAAAAAAAAAA AAAAAAAAAAAAAA AAAAAAAAAAAAAA AAAAAAAAAAAAAA AAAAAAAAAAAAAA AAAAAAAAAAAAAA -------------- 
-------------- -------------- -------------- -------------- -------------- -------------- -------------- -------------- -------------- -------------- AAAAAAAAAAAAAA AAAAAAAAAAAAAA AAAAAAAAAAAAAA AAAAAAAAAAAAAA AAAAAAAAAAAAAA AAAAAAAAAAAAAA AAAAAAAAAAAAAA AAAAAAAAAAAAAA -------------- 
-------------- -------------- ---AAAAAAAA--- ---AAAAAAAA--- ---AAAAAAAA--- ---AAAAAAAA--- ---AAAAAAAA--- ---AAAAAAAA--- ---AAAAAAAA--- ---AAAAAAAA--- AAAAAAAAAAAAAA AAAAAAAAAAAAAA AAAAAAAAAAAAAA AAAAAAAAAAAAAA AAAAAAAAAAAAAA AAAAAAAAAAAAAA AAAAAAAAAAAAAA AAAAAAAAAAAAAA -------------- 
-------------- -------------- ---AAAAAAAA--- ---AEEEEAAA--- ---AAFFFFAA--- ---AAAAAAAA--- ---AAAAAAAA--- ---AAAAAAAA--- ---AAAAAAAA--- ---AAAAAAAA--- AAAAAAAAAAAAAA AAAA-AAAAAAAAA AAAAAAAAAAAAAA AAAAAAAAAAAAAA AAAAAAAAAAAAAA AAAAAAAAAAAAAA AAAAAAAAAAAAAA AAAAAAAAAAAAAA -------------- 
---AA----AA--- ---AA----AA--- ---AEAAAAAA--- ---AEEEEAAA--- ---AAFFFFAA--- ---AAAAAAAA--- -AAAAAAAAAAAA- -AAAAAAAAAAAA- ---AAAAAAAA--- ---AAAAAAAA--- AAAAAAAAAAAAAA AAAAAAAAAAAAAA AAAAAGGGGAACCA AAAAAGGGGAACCA AAAAAAAAAAAAAA AAAAAAAAAAAAAA AAAAAAAAAAAAAA AAAAAAAAAAAAAA -------------- 
---AA----AA--- ---AA----AA--- ---AAAAAAAA--- ---AAAAAAAA--- ---AAAAAAAA--- ---AAAAAAAA--- -AAAAAAAAAAAA- -AAAAAAAAAAAA- ---AAAAAAAA--- ---AAAAAAAA--- AAAAAAAAAAAAAA AAAAAAAAAAAAAA AAAAAAAAAAAAAA AAAAAAAAAAAAAA AAAAAAAAAAAAAA AAAAAAAAAAAAAA AAAAAAAAAAAAAA AAAAAAAAAAAAAA -------------- 
-------------- -----BBBB----- ---AAAAAAAA--- ---AAAAAAAA--- ---AAAAAAAA--- ---AAAAAAAA--- ---AAAAAAAA--- ---AAAAAAAA--- ---AAAAAAAA--- ---AAAAAAAA--- AAAAAAAAAAAAAA AAAAAAAAAAAAAA AAAAAAAAAAAAAA AAAAAAAAAAAAAA AAAAAAAAAAAAAA AAAAAAAAAAAAAA AAAAAAAAAAAAAA AAAAAAAAAAAAAA -------------- 
-----BBBB----- -----BBBB----- ---AAAAAAAA--- ---AAAAAAAA--- ---AAAAAAAA--- ---AAAAAAAA--- ---AAAAAAAA--- ---AAAAAAAA--- ---AAAAAAAA--- ---AAAAAAAA--- AAAAAAAAAAAAAA AAAAAAAABAAAAA AAAAAAAABAAAAA AAAAAAAAAAAAAA AAAAAAAAAAAAAA AAAAAAAAAAAAAA AAAAAAAAAAAAAA AAAAAAAAAAAAAA -------------- 
-----BBBB----- -----BBBB----- -----BBBB----- -----BBBB----- -------------- -----BBBB----- -----BBBB----- -------------- -----BBBB----- -----BBBB----- -------------- -----BBBB----- -----BBBB----- -------------- -------------- -------------- -------------- ------AA------ ------AA------ 
-----BBBB----- -----BBBB----- -----BBBB----- -----BBBB----- -------------- -----BBBB----- -----BBBB----- -------------- -----BBBB----- -----BBBB----- -------------- -------------- -------------- -------------- -------------- -------------- -------------- ------AA------ ------AA------ 
-----BBBB----- -----BBBB----- -----BBBB----- -----BBBB----- -------------- -----BBBB----- -----BBBB----- -------------- -------------- -------------- -------------- -------------- -------------- -------------- -------------- -------------- -------------- -------------- -------------- 
-----BBBB----- -----BBBB----- -----BBBB----- -----BBBB----- -------------- -------------- -------------- -------------- -------------- -------------- -------------- -------------- -------------- -------------- -------------- -------------- -------------- -------------- -------------- 
-----BBBB----- -----BBBB----- -------------- -------------- -------------- -------------- -------------- -------------- -------------- -------------- -------------- -------------- -------------- -------------- -------------- -------------- -------------- -------------- -------------- 
-----BBBB----- -----BBBB----- -------------- -------------- -------------- -------------- -------------- -------------- -------------- -------------- -------------- -------------- -------------- -------------- -------------- -------------- -------------- -------------- -------------- 
-----BBBB----- -------------- -------------- -------------- -------------- -------------- -------------- -------------- -------------- -------------- -------------- -------------- -------------- -------------- -------------- -------------- -------------- -------------- -------------- 
-----BBBB----- -------------- -------------- -------------- -------------- -------------- -------------- -------------- -------------- -------------- -------------- -------------- -------------- -------------- -------------- -------------- -------------- -------------- -------------- 
