model
size = 20 27 14, scale = 0.05, origin = -y
material 
  colors = A:#D65D7E B:#B2E097 C:#FFF D:#F17A98 E:#1A222F
voxels
-------------------- -------------------- -------------------- -------------------- -------------------- -------------------- -------------------- -------------------- -------------------- -------------------- -------------------- -------------------- -------------------- -------------------- -------------------- -------------------- BBBBBBBBBBB--------- BBBBBBBBBBB--------- -BBBBBBBBBB--------- -BBBBBBBBBBBB------- -BBBBBBBBBBBB------- -------------------- -------------------- -------------------- -------------------- -------------------- -------------------- 
-------------------- -------------------- -------------------- -------------------- -------------------- -------------------- -------------------- -------------------- -------------------- -------------------- -ADDAAAAAADDA------- -ADDAAAAAADDA------- -AEEACCCCAEEA------- -AEEACCCCAEEA------- -AAAAAAAAAAAA------- -AAAAAAAAAAAA------- BAAAAAAAAAAAA------- BBAAAAAAAAAAA------- -BAAAAAAAAAAA------- -BAAAAAAAAABB------- -BBBBBBBBBBBB------- ------C------------- ------C------------- ------C------------- ------C------------- ------C------------- ------C------------- 
-------------------- -------------------- -------------------- -------------------- -------------------- -------------------- -------------------- -------------------- -------------------- -------------------- -AAAAAAAAAAAA------- -AAAAAAAAAAAA------- -AAAAAAAAAA-A------- -AAAAAAAAAA-A------- -AAAAAAAAAAAA------- -A---------AA------- BABBBBBBBBB-A------- BB----------A------- -B----------A------- -BAAAAAAAAABB------- -BBAAAAAAAABB------- ---BBBCBBBB--------- ---BBBCBBBB--------- ------C------------- ------C------------- -------------------- -------------------- 
---BB---------BB---- ---BB---------BB---- ---AA---------AA---- ---AA---------AA---- ---AAAAAAAAAAAAA---- ---AAAAAAAAAAAAA---- ---AAAAAAAAAAAAA---- ---AAAAAAAAAAAAA---- ---AAAAAAAAAAAAA---- ---AAAAAAAAAAAAA---- -AAAAAAAAAAAA------- -AAAAAAAAAAAA------- -AAAAAAAAAAAA------- -AAAAAAAAAAAA------- -AAAAAAAAAAAA------- -A---------AA------- BABBBBBBBBB-A------- BB----------A------- -B----------A------- -BAAAAAAAAABB------- -BBAAAAAAAABB------- ---BBBBBBBB--------- ---BBBBBBBB--------- -------------------- -------------------- -------------------- -------------------- 
---BB---------BB---- ---BB---------BB---- ---AA---------AA---- ---AA---------AA---- ---AAAAAAAAAAAAA---- ---AAAAAAAAAAAAA---- ---AAAAAAAAAAAAA---- ---AAAAAAAAAAAAA---- ---AAAAAAAAAAAAA---- ---AAAAAAAAAAAAA---- -AAAAAAAAAAAA------- -AAAAAAAAAAAA------- -AAAAAAAAAAAA------- -AAAAAAAAAAAA------- -AAAAAAAAAAAA------- -A---------AA------- BABBBBBBBBB-A------- BB----------A------- -B----------A------- -BAAAAAAAAABB------- -BBAAAAAAAABB------- ---BBBBBBBB--------- ---BBBBBBBB--------- -------------------- -------------------- -------------------- -------------------- 
-------------------- -------------------- -------------------- -------------------- ---AAAAAAAAAAAAA---- ---AAAAAAAAAAAAA---- ---AAAAAAAAAAAAA---- ---AAAAAAAAAAAAA---- ---AAAAAAAAAAAAA---- ---AAAAAAAAAAAAA---- -AAAAAAAAAAAA------- -AAAAAAAAAAAA------- -AAAAAAAAAAAA------- -AAAAAAAAAAAA------- -AAAAAAAAAAAA------- -AAAAAAAAA-AA------- BAAAAAAAAA-AA------- BB----------A------- -B----------A------- -BAAAAAAAAAAA------- -BBAAAAAAAAAA------- ---BBBBBBBBAA------- ---BBBBBBBB--------- -------------------- -------------------- -------------------- -------------------- 
-------------------- -------------------- -------------------- -------------------- ---AAAAAAAAAAAAA---- ---AAAAAAAAAAAAA---- ---AAAAAAAAAAAAA---- ---AAAAAAAAAAAAA-BB- ---AAAAAAAAAAAAA-BBB ---AAAAAAAAAAAAA-BBB -AAAAAAAAAAAA-BBBBBB -AAAAAAAAAAAA-BBBBBB -AAAAAAAAAAAA-BBBBBB -AAAAAAAAAAAA---BBBB -AAAAAAAAAAAA---BBB- -AAAAAAAAA-AA------- BAAAAAAAAA-AA------- BB----------A------- -B----------A------- -BAAAAAAAAAAA------- -BBAAAAAAAAAA------- ---BBBBBBBBAA------- ---BBBBBBBB--------- -------------------- -------------------- -------------------- -------------------- 
-------------------- -------------------- -------------------- -------------------- ---AAAAAAAAAAAAA---- ---AAAAAAAAAAAAA---- ---AAAAAAAAAAAAA---- ---AAAAAAAAAAAAA-BB- ---AAAAAAAAAAAAA-BBB ---AAAAAAAAAAAAA-BBB -AAAAAAAAAAAA-BBBBBB -AAAAAAAAAAAA-BBBBBB -AAAAAAAAAAAA-BBBBBB -AAAAAAAAAAAA---BBBB -AAAAAAAAAAAA---BBB- -AAAAAAAAA-AA------- -AAAAAAAAAAAA------- -AAAAAAAAAAAA------- -AAAAAAAAAAAA------- -AAAAAAAAAAAB------- -AAAAAAAAAABB------- -AABBBBBBBBBB------- ---BBBBBBBB--------- -------------------- -------------------- -------------------- -------------------- 
-------------------- -------------------- -------------------- -------------------- ---AAAAAAAAAAAAA---- ---AAAAAAAAAAAAA---- ---AAAAAAAAAAAAA---- ---AAAAAAAAAAAAA---- ---AAAAAAAAAAAAA---- ---AAAAAAAAAAAAA---- -AAAAAAAAAAAA------- -AAAAAAAAAAAA------- -AAAAAAAAAAAA------- -AAAAAAAAAAAA------- -AAAAAAAAAAAA------- -AAAAAAAAA-AA------- -AAAAAAAAAAAA------- -AAAAAAAAAAAA------- -AAAAAAAAAAAA------- -AAAAAAAAAAAB------- -AAAAAAAAAABB------- -AABBBBBBBBBB------- ---BBBBBBBB--------- -------------------- -------------------- -------------------- -------------------- 
------BB----BB------ ------BB----BB------ ------AA----AA------ ------AA----AA------ ---AAAAAAAAAAAAA---- ---AAAAAAAAAAAAA---- ---AAAAAAAAAAAAA---- ---AAAAAAAAAAAAA---- ---AAAAAAAAAAAAA---- ---AAAAAAAAAAAAA---- -AAAAAAAAAAAA------- -AAAAAAAAAAAA------- -AAAAAAAAAAAA------- -AAAAAAAAAAAA------- -AAAAAAAAAAAB------- -AAAAAAAAA-AB------- -AAAAAAAAAAAB------- -BAAAAAAAAAAB------- -BAAAAAAAAAAB------- -BAAAAAAAAAAB------- -BBAAAAAAAABB------- -BBBBBBBBBBBB------- ---BBBBBBBB--------- -------------------- -------------------- -------------------- -------------------- 
------BB----BB------ ------BB----BB------ ------AA----AA------ ------AA----AA------ ---AAAAAAAAAAAAA---- ---AAAAAAAAAAAAA---- ---AAAAAAAAAAAAA---- ---AAAAAAAAAAAAA---- ---AAAAAAAAAAAAA---- ---AAAAAAAAAAAAA---- -BAAAAAAAAAAA------- -BAAAAAAAAAAA------- -BAAAAAAAAAAA------- -BAAAAAAAAAAA------- -BAAAAAAAAA-B------- -BAAAAAAAA-AB------- -BAAAAAAAAAAB------- -BAAAAAAAAAAB------- -BAAAAAAAAAAB------- -BAAAAAAAAAAB------- -BBAAAAAAAABB------- -BBBBBBBBBBBB------- ---BBBBBBBB--------- -------------------- -------------------- -------------------- -------------------- 
-------------------- -------------------- -------------------- -------------------- -------------------- -------------------- -------------------- -------------------- -------------------- ---BBBBBBBB--------- -BBBBBBBBBBBB------- -BBBBBBBBBBBB------- -BBBBBBBBBBBB------- -BBBBBBBBBBBB------- -BBBBBBBBBBBB------- -BBBBBBBBBBBB------- -BBBBBBBBBBBB------- -BBBBBBBBBBBB------- -BBBBBBBBBBBB------- -BBBBBBBBBBBB------- -BBBBBBBBBBBB------- -BBBBBBBBBBBB------- ---BBBBBBBB--------- -------------------- -------------------- -------------------- -------------------- 
-------------------- -------------------- -------------------- -------------------- -------------------- -------------------- -------------------- -------------------- -------------------- ---BBBBBBBB--------- -BBBBBBBBBBBB------- ---BBBBBBBB--------- ---BBBBBBBB--------- ---BBBBBBBB--------- ---BBBBBBBB--------- ---BBBBBBBB--------- ---BBBBBBBB--------- ---BBBBBBBB--------- ---BBBBBBBB--------- ---BBBBBBBB--------- ---BBBBBBBB--------- ---BBBBBBBB--------- ---BBBBBBBB--------- -------------------- -------------------- -------------------- -------------------- 
-------------------- -------------------- -------------------- -------------------- -------------------- -------------------- -------------------- -------------------- -------------------- ---BBBBBBBB--------- ---BBBBBBBB--------- -------------------- -------------------- -------------------- -------------------- -------------------- -------------------- -------------------- -------------------- -------------------- -------------------- -------------------- -------------------- -------------------- -------------------- -------------------- -------------------- 
