model
size = 26 32 30, scale = 0.05, origin = -y
material 
  colors = A:#EEE B:#111
voxels
472-2B14-2B8-2B14-2B762-2(3A12-3A8-)3A12-3A762-3B12-3B8-BAB12-BAB8-3B12-3B736-3(4A10-4A8-)4A10-4A328-2B2(24-2A)154-2B23-4B171-4B10-4B2(8-B2AB10-B2AB)8-4B10-4B327-4A22-4A23-2A19-A-2AB2-B2A-A14-A2-A4BA2-A14-2A-2A2B2A-A16-9A19-5A22-4A2(22-4B)145-4A10-4A3(8-6A6-6A)327-4A21-6A20-6A18-B3A2B3AB16-2BA4BA2B16-ABA4BABA2(16-10A)19-2(4B22-)4B75-2A24-2A23-4A16-5A-B2AB-5A10-5A-A2BA-5A10-5A2-2A2-5A10-5A6-5A328-A2-A21-2A2-2A19-3A2-3A17-4A2B4A16-10A16-3A-2A-3A16-2A-4A-2A16-2A-A2-A-2A3(16-10A)18-6A19-3B2-3B17-2B6A2B16-B8AB17-8A15-2(6A2-6A12-)2A-8A-2A12-14A14-2(2AB)4A16-2A2BA3B2A16-2(2AB)AB2A18-6B229-A2-A21-2A2-2A18-4A2-4A16-4A2-4A15-12A15-10A16-2A-4A-2A16-2A-A2-A-2A3(16-10A)17-B6AB18-3B2-3B16-3B6A3B13-2B10A2B12-3B8A3B12-14A12-6A2-6A12-2A-8A-2A12-14A14-2(10A16-)10A18-6A254-2A2-2A18-4A2-4A16-4A2-4A15-12A15-10A13-B6A2-6AB10-AB3A-A2-A-3ABA8-AB2AB4A2-4AB2ABA6-2AB6A2-6AB2A6-B2AB-10A-B2AB11-2B6A2B16-10B15-B10AB12-3B10A3B10-4B8A4B10-16A10-3A-2A4-2A-3A10-3A2(2-2A)2-3A10-7A2-7A11-14A12-14A14-10A17-8A18-8A250-3(5A2-5A14-)5A2-5A12-7A2-7A10-7A2-7A8-20A5-B20AB4-2B18A2B4-3BA-A2B6A2BA-A3B2(4-2B)6A2(2B4-)2B5-8A5-2B7-B2A-8A-2AB10-4B8A4B2(10-16A)10-5A2-2A2-5A2(10-3A)10-5A6-5A10-16A12-12A16-8A18-8A250-3A6-3A14-3A6-3A13-4A6-4A11-2(6A4-6A10-)3A-2A4-2A-3A8-5A2-6A2-5A5-2B18A2B4-2B2A-12A-2A2B4-2B2A-5A2-5A-2A2B4-2B3-B4A2-4AB3-2B4-2B3-2B2A4-2A2B3-2B6-7A4-7A8-5B3A2-3A5B8-8A2-8A8-3A-4A2-4A-3A8-18A8-4A2-6A2-4A9-3A4-2A4-3A10-5A2-2A2-5A10-6A4-6A13-10A17-8A301-2A10-2A11-5A6-5A10-6A4-6A11-2A-2A4-2A-2A13-2(A2(2-2A)2-A14-)5A2-5A14-4A4-4A2(14-A-2A4-2A-A)12-3A-2A4-2A-3A9-4B-2A4-2A-4B8-7A4-7A8-3A-3A4-3A-3A8-8A2-8A8-4A2(2-2A)2-4A9-3A4-2A4-3A10-5A2-2A2-5A10-6A4-6A14-2A4-2A18-8A300-2(3A10-)5A6-5A2(10-6A4-6A)11-2(2A-3A2-3A-2A12-)6A2-6A13-2(4A4-4A14-)4A4-4A12-6A4-6A8-A5B2A4-2A5BA7-2(7A4-7A8-)8A2-8A8-4A-3A2-3A-4A9-3A2-6A2-3A2(10-16A)13-10A17-8A300-3A10-3A9-4A10-4A2(8-6A6-6A)8-7A4-7A7-2(8A4-8A6-)7A6-7A7-BA-3A6-3A-AB11-3A6-3A14-3A6-3A10-4(7A6-)2(8A4-8A6-)9A2-9A10-A-3A2-3A-A14-12A15-2(10A16-)10A18-6A300-3A12-3A2(8-4A10-4A)4-AB6A10-6AB2AB8A6-8A2(B2A)-5A6-5A-2(2AB)2A-3A10-3A-2(2AB)2(6A10-6AB2AB)6A10-6ABA3-2(5A10-5A6-)5(7A6-)7A9-2(5A4-5A12-)5A4-5A13-A-8A-A15-10A17-8A20-4A275-2(3A12-3A8-)3A12-3A4-AB2A2-2A10-2A2-2ABAB3A2-2A10-2A2-4(3A2B3A3-A10-A3-)3AB8A10-9AB6A10-6ABA4-4A10-4A8-2(4A10-)2(4A6-4A12-)2A-A6-A-2A12-4A6-4A12-5A4-5A13-A-8A-A15-10A17-8A19-6A274-2(3A12-3A8-)3A12-3A4-AB6A10-6ABAB3A-3A10-3A-3A2B3A2-2A10-2A2-3AB4A3-A10-A3-4AB3A3-A10-A3-3AB4A3-A10-A3-4AB7A10-7ABAB6A10-6ABA3-2(5A10-5A6-)3(7A6-)7A7-2B4A6-4A2B8-2B4A6-4A2B10-5A4-5A12-14A13-12A15-10A18-6A327-3A10-3A5-AB6A10-6ABAB3A-3A10-3A-3AB4A-3A10-3A-4AB3A2-2A10-2A2-3AB4A3-A10-A3-4AB3A3-A10-A3-3AB4A3-A10-A3-4A2B2A-3A10-3A-2A2BAB6A10-6ABA3-2(5A10-5A6-)5A10-5A7-2B2A10-2A2(2B8-2B4A6-4A)2B10-6A2-6A13-12A15-10A17-8A326-3A10-3A5-AB6A10-6ABAB7A10-7A2B3A-3A10-3A-3AB4A-3A10-3A-4AB3A2-2A10-2A2-3AB4A2-2A10-2A2-4AB3A2-2A10-2A2-3A3B2A2-2A10-2A2-2A2BAB6A10-6ABA3-2(5A10-5A6-)A2-2A10-2A2-A7-2B2A10-2A2B8-2B4A6-4A2B8-B5A6-5AB8-8A2-8A8-18A8-2B14A2B13-8A326-3A10-3A5-AB6A10-6ABAB7A10-7A2(B4A-3A10-3A-4AB3A-3A10-3A-3A)B4A-3A10-3A-4A2B2A-3A10-3A-2A2BAB6A10-6ABA3-5A10-5A5-6A10-6A4-6A10-6A7-B2A10-2AB10-B4A6-4AB9-2B4A6-4A2B2(8-18A)8-2B14A2B8-A3-10A3-2(A8-A16-)A269-3A10-3A5-AB6A10-6ABAB7A10-7A2B3A-3A10-3A4(-3A2B3A-2A12-2A)-3A3B2A-3A10-3A-2A2BAB6A10-6ABA3-5A10-5A5-2A2-2A10-2A2-2A4-6A10-6A8-2A10-2A2(12-4A6-4A)2(12-14A)10-B2-12A2-B8-A3-10A3-2(A8-A16-)A8-B16-B243-3A10-3A5-A3(B6A10-6AB2A)B2(2A-3A10-3A-2(2AB))3(6A10-6AB2AB)6A10-6ABA2-6A10-6A4-2A2-2A10-2A2-2A4-6A10-6A7-2(5A6-5A10-)6A4-6A10-16A11-14A13-12A15-10A64-2(B16-B8-)B16-B166-2A10-2A11-3A10-3A9-5(4A10-4A8-)4A10-4A9-3A10-3A9-4A10-4A8-4A10-4A6-6A10-6A4-2A2-2A10-2A2-2A5-5A10-5A7-6A6-6A8-7A4-7A8-8A2-8A9-16A11-14A13-12A15-10A275-4A4-4A13-5A4-5A11-5A6-5A12(10-3A)9-2(4A10-4A8-)4A10-4A7-2(5A10-5A6-)5A10-5A7-6A6-6A8-7A4-7A8-18A9-16A11-14A13-12A300-12A13-2(14A12-)6A2-6A11-6A4-6A10-5A6-5A6(10-3A)9-3(4A10-4A8-)4A10-4A7-5A10-5A6-3A-A10-A-3A7-6A6-6A2(8-18A)9-16A11-14A325-2(12A14-)12A13-6A2-6A12-5A4-5A12-4A6-4A2(12-2A10-2A)11-3A10-3A9-4A10-4A5(8-2A-A10-A-2A)9-3A-A6-A-3A9-18A9-16A13-10A357-4A20-8A18-8A16-12A14-12A13-14A12-14A11-9(16A10-)16A11-14A458-6A18-10A15-12A13-6A2B6A11-6AB2AB6A10-4A2(2BA)2B4A10-3AB8AB3A10-3ABA6BAB3A10-2AB10AB2A10-2ABA8BAB2A10-AB12ABA10-A14BA2(10-16A)510-4A20-2A4B2A17-3AB2AB3A14-4ABA2BAB4A12-3AB6AB3A12-2ABA6BAB2A12-2AB8AB2A12-ABA8BABA12-AB10ABA12-BA10BAB12-B12AB12-14B292-
