model
size = 13 21 32, scale = 0.05, origin = -y
material 
  colors = A:#EEE B:#111
voxels
33-A9-3(6A7-)6A8-4A178-4B8-6A7-7A5-8A5-2(9A4-)8A5-8A6-6A48-2A11-2A99-8B5-7A2B3-4A-4AB3-9A2(B2-10A)2(B3-9A)B4-8A6-2(5A8-)3(6A7-)5A9-4A2(9-4B)45-10B3-BA6-AB2-2(3A6-3A-)3(4A4-4A-)4A4-2AB2(3-3A)5-3A2-3A5-4(7A6-)7A7-6A2(6-7B)43-12B-2A8-2A-2A2(8-5A)8-6A7-6A6-3A-3A6-AB2-3A6-AB3-BA5-2AB3-B3A2-3A4-B2A3-3A4-2(B2(2A4-))B2A3-3A5-2A3-3A2(4-9B)42-12B-A10-3A9-4A9-3(5A8-)2(2A-2A8-)2A-AB7-AB3-BA6-AB3-B2(2A4-)BA6-A2(4-BA5-2A)4-BA6-A4-3B3-4B3-3B3-4B40-13B2A10-3A9-4A3(9-2ABA)9-4A9-2A-A9-2A-2A8-B2-2A7-3(AB2-3A6-)AB3-BA6-AB3-B7-AB2(2-3B5-3B)40-13BA11-3(ABA10-3A10-)A-A9-2A-A9-B2-2A8-3(B2-2A7-A)B3-B7-AB2-AB8-2(B2-3B6-A)B11-AB27-13BA11-3A10-3A9-2A2(BA10-3A10-A)-A9-2A-2(A9-B2-)2(2A7-AB2-)2A6-2AB3-B6-2AB2-AB8-B2(2-3B6-2B)11-AB27-13BA2(11-AB)A9-2A2(BA10-A)BA10-3A10-A-A9-2A-A9-2(B2-2A7-A)B2-3A6-AB2-3A2(5-2AB3-BA)5-2AB2-3B5-A2B2-3B6-2B2-3A6-AB10-2AB14-13BA11-2A11-3A9-3A11-3A10-ABA10-3A9-2A-A9-2A-2A8-B2-ABA5-2(2AB3-B2A4-)2AB3-BA5-2AB3-2(B2(2A4-))2BA4-AB4-2B5-2B4-2A5-2AB3-2A5-2AB10-2A2-13BA10-2AB10-4A9-2AB10-3A10-2ABA9-4A9-2A-A9-2A-3A7-5(B3-B2A4-2A)4-B2(2A4-)2BA4-AB4-3B4-2B3(4-3A4-2A)2-13BA10-3A2(10-4A9-2AB)A9-4A9-2A-A9-2A-2B2A5-A2(B3-B8A)2(4-B8A)5-3A-4A5-3A2-3A5-B2A2-2AB5-2B4-2B5-2(2A4-)3A4-2A4-3A4-2A2-12B-A2(10-B-B)A9-B-B9-A2(B-BA9-)B-2A9-B2-2A8-B2-2B2A4-2AB3-B8AB4-4(8A5-)A7B6-B6A5-B12-2(2A11-)2A8-12B2(-A10-B)4(-2A9-B)2-A9-B2-2A-A5-AB3-9AB4-8A6-7A6-7B6-7A93-12B2(-A10-B)3(-2A9-B)A-A9-BA-2A8-B2-4A4-2AB3-10A5-7B132-12B2(-A10-B)2(-2A9-B)3A9-BA-A9-BA-2A-A5-AB3-9AB5-7A145-13B2A3(9-4A)9-2A-A9-2A-2A8-2A-4A4-3A3-10A6-5A147-12B2A3(9-4A)9-2A-2A8-2A-4A4-4A2-10A5-7B159-12B2A9-4A10-3A9-2A-A10-A-2A8-2A2-2(4A3-)9A171-12B-A2(10-3A)9-2A-2A9-A-9A-2A2-11A4-7BA171-12B3(-A10-A)-2A9-A2-3A7-A3-10A183-12B3(-A10-A)-2A9-A2-4A5-2A4-9A183-12B-A11B2(-2A9-A)-3A8-A2-11A5-6BA184-12B-A11B2(-2A9-A)2-2A8-A3-10A196-12B-A11B2(-2A9-A)2-3A7-A3-10A196-12B-2A9-B-2A9-A2-A9-A2-4A6-A4-9A197-11B2-A7-2AB2-2A6-3A2-2A8-A2-4A5-2A5-8A197-9B4-2A3-3A3B2-2A7-2A2-3A6-2A3-3A5-2A5-7A199-5B8-10B2(3-3A4-3A)4-3A3-2A6-7A213-8B5-A6BA5-3A2-3A6-7A7-5A215-5B8-5B2(9-4B)211-
