model
size = 14 21 32, scale = 0.05, origin = -y
material 
  colors = A:#EEE B:#111
voxels
34-A11-3(6A8-)6A9-4A192-4B9-6A7-7A7-8A2(5-9A)2(6-8A)7-6A52-2A12-2A107-8B5-2B7A5-B4A-4A4-B9A4-2(B10A3-)B9A4-B9A5-8A8-5A9-5A3(8-6A)9-5A9-4A2(10-4B)49-10B4-BA6-AB3-2(3A6-3A2-)2(4A4-4A2-)4A4-4A3-B2A4-4A4-3A3-3A5-3A2-3A5(7-7A)7-6A8-7B7-7B46-12B2(2-2A8-2A)2-2(2A8-3A-)2A7-4A-3A6-4A2-2(BA6-3A3-)B2A5-AB5-3A2-3AB5-3A3-2(2AB5-2A4-)2(2AB5-3A3-)2A6-9B5-9B45-12B2-A10-A2-2A2(9-5A)8-6A2(8-3A-2A)8-2A2-2A8-2A3-BA7-BA3-BA6-AB5-2A4-2AB5-A6-2(AB5-2A5-)AB5-A6-AB2(4-4B3-3B)45-13B-A10-2A-2A3(9-AB3A)2(9-AB-2A)9-2A-2A9-A3-B8-2A3-BA7-2A3(3-BA6-3A)3-BA6-AB4-BA7-B4-3B5-3B3-3B5-3B44-13B-A11-A-A2(10-4A)10-AB2A10-2A-A10-AB-A10-2A-2A2(9-A3-B)8-4(2A3-BA7-)B4-B8-BA2(3-BA6-3B)3-BA39-13B-A11-A-A10-AB-2A9-4A10-AB-A10-2A-A10-AB-A10-2A-2A3(9-A3-B)2(A7-2A3-B)2A6-2A3-B2A6-B4-B8-BA2(3-2B6-3B)3-BA39-13B2(-A11-A)-2A9-3(2A-A10-)AB-A10-2A-2A2(9-A3-B)2(A7-2A3-B)A6-2(3A3-B2A5-)AB4-B2A5-AB4-2BA5-3B3-2B6-3B3-BA6-3A3-B2A24-13B-A11-A-A11-B-2A9-AB-A11-2(B-A10-A)B-2A9-2A-2A9-A3-B8-2A3-B2A5-ABA3-2(B2A4-2AB4-)B2A5-A2(B5-2A4-2A)B5-BA4-A2(2B5-)2B2(4-B2A5-2A)5-2A10-13B2(-2A10-A)-2A9-2A-2A10-B-2A10-A-2A9-AB-2A9-2A-2A9-A3-B7-3A3-3(B2A4-2AB4-)B3(2A4-2AB5-)BA4-A2B5-2B4-3B3(5-2A4-3A)3-13B-2A10-A2(-2A10-B-2A9-2A)-2A9-AB-2A9-2A-2A9-A3-BA5-2A2B3-B4(8AB5-)4A-3A6-3A2-3A6-B2A2-2AB6-2B4-2B6-2A4-2A6-2A4-3A5-2A4-3A4-12B2(2-B10-A)2-B9-2A2-BA9-2(B2-B9-A)B2-B9-2A2-B8-2A3-B2A4-2A2B3-B8AB5-4(8A6-)7BA6-6AB14-B3(12-2A)5-12B2(2-B10-A)4(2-B9-2A)2-B9-A3-BA5-A-2A3-B9A5-8A6-7A7-7B7-7A104-12B2(2-B10-A)2(2-B9-2A)-AB9-2A-AB9-A3-B8-2A3-B2A4-4A3-10A5-7B146-12B2(2-B10-A)2-3(B9-2A-A)B9-A3-BA5-A-2A3-B9A5-7A159-13B4(-2A9-2A)-2A9-A2-2A8-2A3-3A4-4A3-10A6-5A160-12B2-4(2A9-2A-)2A8-2A2-4A4-4A3-10A5-7B173-12B2-2A9-2A-A10-2A-2A9-2A-A10-A2-2A8-2A2-4A3-4A4-9A186-12B2-A10-A2-A10-2A-2A9-2A-A9-2A2-2A-9A2-11A4-A7B187-12B3(2-A10-A)2-A9-2A2-A7-3A3-10A200-12B3(2-A10-A)2-A9-2A2-2A5-4A3-9A201-12B2-11BA2(2-A9-2A)2-A8-3A2-11A4-A6B202-12B2-11BA2(2-A9-2A)2-A8-2A3-10A214-12B2-11BA2(2-A9-2A)2-A7-3A3-10A214-12B2-B2(9-2A2-A)9-A3-A6-4A3-9A215-11B3-B2A7-A3-3A6-2A3-A8-2A3-2A5-4A3-8A218-9B3-3B3A2(3-2A)7-2A3-2A6-3A3-2A5-3A5-7A221-5B4-10B4(4-3A)5-2A3-3A6-7A231-8B6-A6BA6-3A2-3A6-7A8-5A234-2(5B9-)4B10-4B230-
