model
size = 24 12 9, scale = 0.05, origin = -y
material 
  colors = A:#111 B:#E00 C:#040
voxels
----BBBBBBBBBBBBBBBBB--- ----CCCCCCCCCCCCCCCCC--- ----AAAACCBBCCAAAAAAA--- ----AAAAACCBBCCAAAAAA--- ------AAAACCBBCCAAAAA--- -------AAAACCBBCCAAAA--- --------AAAACCBBCCAAA--- ---------AAAACCBBCCAA--- --------------CCBBCCA--- -----------------BBCC--- -----------------CBBC--- -----------------CC----- 
-BBBBBBBBBBBBBBBBBBBBB-- -CCCCCCCAAAAAAAAAAAAAC-- -AAAAAAAAAAAAAAAAAAAAA-- -AAACCAAAAAAAAAAAAAAAA-- ----CC-AAAAAAAAAAAAAAA-- -------AAAAAAAAAAAAAAA-- ---------AAAAAAAAAAAAA-- ----------AAAAAAAAAAAA-- ----------------AAAAAA-- -----------------AAAAA-- -----------------AAAA--- -----------------AA----- 
-BBBBBBBBBBBBBBBBBBBBBB- -CCCCCCAAAAAAAAAAAAAAAC- -ACBAAAAAAAAAAAAAAAAAAA- -AACCCAAAAAAAAAAAAAAAAA- ---CCCCBAAAAAAAAAAAAAAA- -----CCB-AAAAAAAAA---AA- -------B-AAAAAAAAA---AA- ---------A-AAABBAA---AA- -----------A-ABBAA---AA- ---------------BAA---AA- ----------------AA------ ----------------A------- 
BBBBBBBBCBCCCBBBBBBBBBBB CCCCCCCAAAAAAAAAAAAAAAAC ACCBAAAAAAAAAAAAAAAAAAAA AACCCCAAAAAAAAAAAAAAAAAB --CCCCCABAAAAAAAAAAAAAAB ----CCBBBAAAAAAAAA-----A ------BBBABAAAAAAA-----B --------BABABABAAA-----B ----------BABABAAA-----B ------------BABBAA-----B ----------------AA-----A ----------------A------- 
BBBBBBBBCBBBBCBBBBBBBBBB CCCCCCCAAAAAAAAAAAAAAAAC ACCBAAAAAAAAAAAAAAAAAAAB AACCCCAAAAAAAAAAAAAAAAAA --CCCCCBAAAAAAAAAAAAAAAA ----CCBBABAAAAAAAA-----A ------BBABABAAAAAA-----B --------ABABABAAAA-----A ----------ABABAAAA-----A ------------ABABAA-----A ----------------CC-----A ----------------C------- 
BBBBBCCCCBCCCBBBBBBBBBBB CCCCCCCAAAAAAAAAAAAAAAAC ACCBAAAAAAAAAAAAAAAAAAAA AACCCCAAAAAAAAAAAAAAAAAB --CCCCCABAAAAAAAAAAAAAAB ----CCBBBAAAAAAAAA-----A ------BBBABAAAAAAA-----B --------BABABABAAA-----A ----------BABABAAA-----A ------------BABBAA-----A ----------------AA-----A ----------------A------- 
-BBBBBBBBBBBBBBBBBBBBBB- -CCCCCCAAAAAAAAAAAAAAAC- -ACBBAAAAAAAAAAAAAAAAAA- -AACCCAAAAAAAAAAAAAAAAA- ---CCCCBAAAAAAAAAAAAAAA- -----CCB-AAAAAAAAA---AA- -------B-AAAAAAAAA---AA- ---------A-AAABBAA---AA- -----------A-ABBAA---AA- ---------------BAA---AA- ----------------AA------ ----------------A------- 
-BBBBBBBBBBBBBBBBBBBBB-- -CCCCCCCAAAAAAAAAAAAAC-- -AAAAAAAAAAAAAAAAAAAAA-- -AAACCAAAAAAAAAAAAAAAA-- ----CC-AAAAAAAAAAAAAAA-- -------AAAAAAAAAAAAAAA-- ---------AAAAAAAAAAAAA-- ----------AAAAAAAAAAAA-- ----------------AAAAAA-- -----------------AAAAA-- -----------------AAAA--- -----------------AA----- 
----BBBBBBBBBBBBBBBBB--- ----CCCCCCCCCCCCCCCCC--- ----AAAACCBBCCAAAAAAA--- ----AAAAACCBBCCAAAAAA--- ------AAAACCBBCCAAAAA--- -------AAAACCBBCCAAAA--- --------AAAACCBBCCAAA--- ---------AAAACCBBCCAA--- --------------CCBBCCA--- -----------------BBCC--- -----------------CBBC--- -----------------CC----- 
