model
size = 14 25 14, scale = 0.05, origin = -y
material 
  colors = A:#EDCC48 B:#9CF C:#97C770 D:#827357
voxels
-------------- -------------- -------------- -----AAAA----- ----AAAAAA---- ----AAAAAA---- ----A----A---- ----AAAAAA---- ----AAAAAA---- ----AA--AA---- ----AA--AA---- ------AA------ ------AA------ ----AAAAAA---- ----AAAAAA---- -------------- -------------- -------------- -------------- -------------- -------------- -------------- -------------- -------------- -------------- 
-------------- -------------- -----AAAA----- ---AAAAAAAA--- ---AAAAAAAA--- ---AAAAAAAA--- ---AA----AA--- ---AAAAAAAA--- ---AAAAAAAA--- ---AAA--AAA--- ---AAA--AAA--- ---A--AA--A--- ---A--AA--A--- ---AAAAAAAA--- ---AAAAAAAA--- -----AAAA----- -------------- -------------- -------------- -------------- -------------- -------------- -------------- -------------- -------------- 
-------------- -----AAAA----- ---AAAAAAAA--- --AAAAAAAAAA-- --AAAAAAAAAA-- --AAAAAAAAAA-- --AAA----AAA-- --AAAAAAAAAA-- --AAAAAAAAAA-- --AAAA--AAAA-- --AAAA--AAAA-- --AA--AA--AA-- --AA--AA--AA-- --AAAAAAAAAA-- --AAAAAAAAAA-- ---AAABBBAA--- -----AAAA----- -------------- -------------- -------------- -------------- -------------- -------------- -------------- -------------- 
-----AAAA----- ---AAAAAAAA--- --AAAAAAAAAA-- --AAAAAAAAAA-- -AAAAAAAAAAAA- -AAAAAAAAAAAA- -AAAA----AAAA- -AAAAAAAAAAAA- -AAAAA--AAAAA- -AAAAA--AAAAA- -AAAAA--AAAAA- -AAA--AA--AAA- -AAA--AA--AAA- -AAAAAAAAAAAA- --AAAAAAAAAA-- --AAAABBBAAA-- ----AABBBA---- -----AAAA----- -------------- -------------- -------------- -------------- -------------- -------------- -------------- 
-------------- ---A------A--- --AA------AA-- -AAA------AAA- AAAA------AAAA AAAA------AAAA AAAA------AAAA AAAA------AAAA AAAA------AAAA AAAA------AAAA AAAA------AAAA AAAA------AAAA AAAA------AAAA AAAA------AAAA -AAA------AAA- --AAAAAAAAAA-- ---AAABBBAA--- ----AABBBA---- -----AAAA----- -------------- -------------- -------------- -------------- -------------- -------------- 
---A------A--- --AA------AA-- -AAA------AAA- AAAA------AAAA AAAA------AAAA AAAA------AAAA AAAA------AAAA AAAA------AAAA AAAA------AAAA AAAA------AAAA AAAA------AAAA AAAA------AAAA AAAA------AAAA AAAA------AAAA AAAA------AAAA -AAAAAAAAAAAA- --AAAABBBAAA-- ---AAABBBAA--- ----AABBAA---- ------AA------ -------------- -------------- -------------- -------------- -------------- 
---A------A--- --AA------AA-- -AAA------AAA- AAAA------AAAA AAAA------AAAA AAAA------AAAA AAAA------AAAA AAAA------AAAA AAAA------AAAA AAAA------AAAA AAAA------AAAA AAAA------AAAA AAAA------AAAA AAAA------AAAA AAAA------AAAA -AAAAAAAAAAAA- --AABBBBBAAA-- ---ABBBBBAA--- ----ABBBBA---- -----AAAA----- ------AA------ -------------- -------------- -------------- -------------- 
---A------A--- --AA------AA-- -AAA------AAA- AAAA------AAAA AAAA------AAAA AAAA------AAAA AAAA------AAAA AAAA------AAAA AAAA------AAAA AAAA------AAAA AAAA------AAAA AAAA------AAAA AAAA------AAAA AAAA------AAAA AAAA------AAAA -AAAAAAAAAAAA- --AABBBBBAAA-- ---ABBBBBAA--- ----ABBBBA---- -----ABBA----- ------AA------ ------D------- ---CC-D------- --CCCDD------- --CC---------- 
---A------A--- --AA------AA-- -AAA------AAA- AAAA------AAAA AAAA------AAAA AAAA------AAAA AAAA------AAAA AAAA------AAAA AAAA------AAAA AAAA------AAAA AAAA------AAAA AAAA------AAAA AAAA------AAAA AAAA------AAAA AAAA------AAAA -AAAAAAAAAAAA- --AABBBBBAAA-- ---ABBBBBAA--- ----AABBAA---- ------AA------ -------------- -------------- -------------- -------------- -------------- 
-------------- ---A------A--- --AA------AA-- -AAA------AAA- AAAA------AAAA AAAA------AAAA AAAA------AAAA AAAA------AAAA AAAA------AAAA AAAA------AAAA AAAA------AAAA AAAA------AAAA AAAA------AAAA AAAA------AAAA -AAA------AAA- --AAAAAAAAAA-- ---AABBBBAA--- ----ABBBBA---- -----AAAA----- -------------- -------------- -------------- -------------- -------------- -------------- 
-----AAAA----- ---AAAAAAAA--- --AAAAAAAAAA-- --AAAAAAAAAA-- -AAAAAAAAAAAA- -AAAAAAAAAAAA- -AAAAAAAAAAAA- -AAAAAAAAAAAA- -AAAAAAAAAAAA- -AAAAAAAAAAAA- -AAAAAAAAAAAA- -AAAAAAAAAAAA- -AAAAAAAAAAAA- -AAAAAAAAAAAA- --AAAAAAAAAA-- --AAAAAAAAAA-- ----AAAAAA---- -----AAAA----- -------------- -------------- -------------- -------------- -------------- -------------- -------------- 
-------------- -----AAAA----- ---AAAAAAAA--- --AAAAAAAAAA-- --AAAAAAAAAA-- --AAAAAAAAAA-- --AAAAAAAAAA-- --AAAAAAAAAA-- --AAAAAAAAAA-- --AAAAAAAAAA-- --AAAAAAAAAA-- --AAAAAAAAAA-- --AAAAAAAAAA-- --AAAAAAAAAA-- --AAAAAAAAAA-- ---AAAAAAAA--- -----AAAA----- -------------- -------------- -------------- -------------- -------------- -------------- -------------- -------------- 
-------------- -------------- -----AAAA----- ----AAAAAA---- ---AAAAAAAA--- ---AAAAAAAA--- ---AAAAAAAA--- ---AAAAAAAA--- ---AAAAAAAA--- ---AAAAAAAA--- ---AAAAAAAA--- ---AAAAAAAA--- ---AAAAAAAA--- ---AAAAAAAA--- ----AAAAAA---- -----AAAA----- -------------- -------------- -------------- -------------- -------------- -------------- -------------- -------------- -------------- 
-------------- -------------- -------------- -----AAAA----- ----AAAAAA---- ----AAAAAA---- ----AAAAAA---- ----AAAAAA---- ----AAAAAA---- ----AAAAAA---- ----AAAAAA---- ----AAAAAA---- ----AAAAAA---- ----AAAAAA---- -----AAAA----- -------------- -------------- -------------- -------------- -------------- -------------- -------------- -------------- -------------- -------------- 
