model
size = 31 31 8, scale = 0.05, origin = -y
material 
  colors = A:#7C3B0B B:#989898 C:#712F00 D:#884617 E:#945222 F:#7E7E7E G:#646464 H:#B1B1B1 I:#CBCBCB J:#E5E5E5 K:#FFF L:#9F5D2E M:#4B4B4B
voxels
------------------------------- ------------------------------- ------------------------------- ------------------------------- ------------------------------- ------------------------------- ------------------------------- ------------------------------- ------------------------------- ------------------------------- ------------------------------- ------------------------------- ------------------------------- --------------BBB-------------- -------------HHBBB------------- -------------HHHBB------------- -------------JHHHB------------- --------------JHH-------------- ------------------------------- ------------------------------- ------------------------------- ------------------------------- ------------------------------- ------------------------------- ------------------------------- ------------------------------- ------------------------------- ------------------------------- ------------------------------- ------------------------------- ------------------------------- 
------------------------------- ------------------------------- ------------------------------- ------------------------------- ------------------------------- ------------------------------- ------------------------------- ------------------------------- ------------------------------- ------------------------------- ------------------------------- ------------------------------- -------------FGGGF------------- ------------BBBBBFF------------ ------------IBBBBBG------------ ------------JBBBBBG------------ ------------JBBBBBG------------ ------------IKBBBBF------------ -------------IJJIB------------- ------------------------------- ------------------------------- ------------------------------- ------------------------------- ------------------------------- ------------------------------- ------------------------------- ------------------------------- ------------------------------- ------------------------------- ------------------------------- ------------------------------- 
------------------------------- ------------------------------- ------------------------------- ------------------------------- ---------------M--------------- ------------------------------- ------------------------------- ------------------------------- ---------------M--------------- ------------------------------- ------------------------------- -------------BBBBB------------- ------------BBBBBBB------------ -----------BBBBBBBBB----------- -----------BBBBBBBBB----------- ----M---M--BBBBBBBBB--M---M---- -----------BBBBBBBBB----------- -----------BBBBBBBBB----------- ------------BBBBBBB------------ -------------BBBBB------------- ------------------------------- ------------------------------- ---------------M--------------- ------------------------------- ------------------------------- ------------------------------- ---------------M--------------- ------------------------------- ------------------------------- ------------------------------- ------------------------------- 
------------BBBBBBB------------ ---------BBFFFFFFFFFBB--------- -------BBFFG--IBG--GFFBB------- ------BBG-----IBG-----GBB------ -----BFG------IMG------GFB----- ----BF--------IFG--------FB---- ---BF---------IBG---------FB--- --BFG---------IBG---------GFB-- --FG----------IMG----------GF-- -BF-----------IFG-----------FB- -BF-----------FFF-----------FB- -FG---------GBBBBBG---------GF- BF---------GBBBBBBBG---------FB BF---------BBBBBBBBB---------FB HFGGGGGGGGFBBBBBBBBBFGGGGGGGGFB HFBBMFBBMFFBBBBBBBBBFBMFBBMFBFB HFIIIIIIIIFBBBBBBBBBFIIIIIIIIFB BF---------BBBBBBBBB---------FB BF---------GBBBBBBBG---------FB -FG---------GBBBBBG---------GF- -BF-----------FFF-----------FB- -BF-----------IBG-----------FB- --BG----------IMG----------GB-- --BBG---------IFG---------GBB-- ---BF---------IBG---------FB--- ----BF--------IBG--------FB---- -----BFG------IMG------GFB----- ------BBG-----IFG-----GBB------ -------BBFFG--IBG--GFFBB------- ---------BBFFFFFFFFFBB--------- ------------BBHHHBB------------ 
------------BBBBBHB------------ ---------BHBDDACLDDHHH--------- -------HHACLCCACECCACLHH------- ------HDDCCAAAACECACCCDDH------ -----HLDCACEDAACECDACACAAI----- ----HCCCDACEAAACECDACEACCCI---- ---IACADDACEAAACECDACEAAACLI--- --IDAAEDDACECAACECAACEDDACLDI-- --IDCCEDAACEAAACECDACEDAACADJ-- -IACACEDDACEAAACECAACEDAACEADJ- -JACACEDDACEDCACECAACEDAACECDJ- -JDCACEDAACEDAACEDACCEDDACECAK- JDCDACEDCACEDAACEDEACEDAACEDCDK KDCCCCECCCCEDDACEDDACECECCECCDK KDADACEDAACEADACEDAACEDDACEDADK KDCDACEDDACEDAACEADACEDAACEDCDK KDCDACEDAACEDAACEDDACEDCACEDCDK KDCDACEDAECEACACEDAACEDAACEDCDK KDCEACEADACEDAACEDDACEDAACEDCDJ -KACACEDDACEADACEDACCEDAACECDJ- -JACACEADACEDCACECAACEDDACECDJ- -JDCACECDACEDDACECDACEDAACECDI- --JDCCEADACEDDACECDACEADACEDI-- --IDACEDDACEADACECEACEDAACLDI-- ---IAAEADACEADACECDACEDAACLI--- ----ICACAACEDDACECEACEADCCH---- -----ILDCACEDAACECDACEADAH----- ------HDDCCCDAACECACCADDH------ -------HHACLCCACECCACLHH------- ---------BHBDDACLDDBHB--------- ------------BBBBBBB------------ 
------------BBBBBBH------------ ---------HBBDDACLDDBHH--------- -------HBACLDDACEDDACLHH------- ------HDDACAAEACEDAACLDDH------ -----HLDAACEDDACEDDACADAAI----- ----HCLADACEAAACEDDACEAEACI---- ---IACADDACEACACEDDACEAAACLI--- --IDAAEDDACECAACEDAACEDDACLDI-- --IDACEDAACEADACEDDACEDAACADJ-- -IADACEDDACEADACEDAACEDAACEADJ- -JADACEDDACEDDACEDAACEDAACEDDJ- -JDEACEDAACEDAACEDAACEDDACEDAK- JDDDACEDEACEDAACEDEACEDAACEDDDK KDADACEDAACEDDACEDDACEDEACEDEDK KDADACEDAACEADACEDAACEDDACEDADK KDCDACEDDACEDAACEADACEDAACEDCDK KDCDACEDAACEDAACEDDACEDCACEDCDK KDDDACEDAECEACACEDAACEDAACEDADK KDDEACEADACEDAACEDDACEDAACEDADJ -KADACEDDACEADACEDAACEDAACEDDJ- -JADACEADACEDAACEDAACEDDACEDDJ- -JDDACECDACEDDACEADACEDAACEDDI- --JDACEADACEDDACEADACEADACEDI-- --IDACEDDACEADACECEACEDAACLDI-- ---IAAEADACEADACEADACEDAACLI--- ----ICADAACEDDACEDEACEADACH---- -----ILDDACEDAACEDDACEADAH----- ------HDDACLDAACEDAACADDH------ -------HHACLDDACEDDACLBH------- ---------HBBDDACLDDBBH--------- ------------BBBBBBB------------ 
------------BBBBBBB------------ ---------BHFFFFFFFFFHB--------- -------BBFFG-------GFFBB------- ------BBG-------------GBB------ -----BFG---------------GFB----- ----BF-------------------FB---- ---BF---------------------FB--- --BFG---------------------GFB-- --FG-----------------------GF-- -BF------AA-----------------FB- -BF-----CCCA----------------FB- -FG-----CCCC----------------GF- BF-------CC------------------FB BF---------------------------FB HF---------------------------FB HF---------------------------FB HF---------------------------FB BF---------------------------FB BF---------------------------FB -FG----------------CA-------GF- -BF---------------CCCA------FB- -BF---------------CCCA------FB- --BG---------------CC------GB-- --BBG---------------------GBB-- ---BF---------------------FB--- ----BF-------------------FB---- -----BFG---------------GFB----- ------BBG-------------GBB------ -------BBFFG-------GFFBB------- ---------BHFFFFFFFFFHB--------- ------------BBHHHBB------------ 
------------------------------- ------------------------------- ------------------------------- ------------------------------- ------------------------------- ------------------------------- ------------------------------- ------------------------------- ------------------------------- ------------------------------- ---------M--------------------- -----------A------------------- ----------CCA------------------ -----------CCA----------------- ------------CCA---------------- -------------CCA--------------- --------------CCA-------------- ---------------CCA------------- ----------------CCA------------ -----------------CCA----------- ------------------C------------ --------------------M---------- ------------------------------- ------------------------------- ------------------------------- ------------------------------- ------------------------------- ------------------------------- ------------------------------- ------------------------------- ------------------------------- 
