model
size = 32, scale = 0.05, origin = -y
material 
  colors = A:#200 B:#100 C:#340000 D:#3C0000
voxels
654-3A29-3A27-3(7A25-)8A5(23-9A)22-10A567-9A23-9A22-4(12A20-)13A8(18-14A)215-5(6A26-)6A22-2(12A20-)12A18-4(16A16-)2(17A15-)17A9(14-18A)14-17AC17-8(13A19-)13A17-2(16A16-)16A15-18A14-18A13-19A13-16(20A12-)19A2C13-17AC14-16A2C14-17AC14-5A2(6-6AC13-6A)3(6-6AC12-7A)2(6-7AC11-7A)2(6-7AC10-8A)3(6-8A10-8A)6-8A9(10-2A16-4A)3(10-3A15-4A)10-4A14-4A10-8A10-5A9-23A9-21A2(2C10-20A)2(2C10-2A12-6A)4(2C9-3A12-6A)2C2(9-3A12-7AC)5(8-4A12-7AC)8-4A11-8A2(C8-3A16-4A)C9(8-3A16-5A)8-3A16-6A7-4A15-6A7-6A13-6A7-25A7-23ABAB7-6A8-9A2(C8-3A13-7A)4(C7-4A13-7A)C7-4A13-6AC8-4A3(13-6AC7-5A)4(13-7AC6-5A)13-8A2(6-4A16-6A)6-3A17-6A5(6-3A22-A)5(6-4A21-A)6-5A17-5A5-27A4-28AC2(5-4A15-6ACA)4-4A16-8A4(4-4A16-6A2C)2(4-4A16-5A3C)2(4-4A16-8A)6(3-5A16-8A)3-5A16-7A4-4A19-5A7(4-4A23-A)4-2(5A22-2A3-)5A21-3A3-6A19-4A2-31A2-14A2C13AC3-2(4A18-6A4-)3(4A16-8A4-)4A11(16-8A3-5A)17-7A3-5A17-A-5A3-4A20-5A3-4A23-A4-4A28-B3A3(28-4A)23-2A3-4A23-2(2A3-5A22-)3A2-5A22-3A2-5A21-4A-31A2-14A2C4A4-5AC2-2(5A18-6A3-)2(4A17-8A3-)4A22-3A8(3-4A24-A)5(3-5A23-A)3-4A23-2A3-2(4A28-)B3A3(28-4A)25-A2-4A25-A2(2-5A23-2A)2-5A22-3A2-5A21-36A2-14ACAB3A6-3AC2-3A22-4A3-3A20-6A3-3A18-8A3-3A23-3A3-3A25-A3-3A25-2A2-3A3(25-2A-4A)2(25-A2-4A)25-A2-5A24-5(A2-6A23-)A3-4A23-2A3-5(4A28-)2(4A25-A2-)5A23-2A2(2-5A22-3A)2-5A20-37A-11A2CAB6A6-4A-4A22-5A-4A20-7A-4A19-8A-4A23-4A-4A25-AB7(-4A25-2A)-5A24-2(2A-6A23-)3(2A-5A24-)2A-5A23-3A-5(5A27-)2(5A25-A-)6A23-2A-6A22-3A-6A21-4A-6A19-38A-5AB4A2CBA2B11-B3A-4A22-5A-4A20-7A-4A20-6A3(B-4A25-2A-4A25-A)B3(-4A25-2A)-5A24-2A-6A23-9A23-4(8A24-)8A2(26-6A)26-B5A2(26-6A)25-7A25-8A23-9A22-3AB6A20-12A19-43A2B4A2BABAC11-4A-4A22-5A-4A20-7A-4A22-4A2(B-4A25-A)B3(-4A25-2A)3(-4A25-AB)5A25-8A24-2(9A23-)4(8A24-)8A2(26-6A)2(26-B5A)26-6A24-8A24-9A23-9A22-3AB6A20-12A19-42A3B4A2B4C11-4A-4A22-5A-4A20-6AB-4A22-4A5(B-4A25-A)B2(-4A25-2A)-4A25-7A25-8A24-2(9A23-)3(8A24-)3A-4A24-8A3(26-6A)26-B5A26-6A24-A-6A24-9A23-9A22-3AB6A20-12A19-42A4B5A4C11-B3A-4A22-5A-4A20-7A-4A22-4A6(B-4A25-A)B-4A25-2A-4A25-2(8A24-)2(9A23-)3(8A24-)3A-4A24-8A3(26-6A)2(26-B5A)24-A-6A24-9A2(22-10A)20-5AB6A19-41ABA3B6A3C11-4A-4A22-5A-4A20-7A-4A22-4A5(B-4A25-A)B-4A2(25-2A-B3A)25-2(8A24-)2(9A23-)3(8A24-)3A-4A24-AC4(6A26-)B5A26-B5A24-A-6A24-9A2(22-10A)20-5AB6A19-40A4B11A9-6A-4A22-4AB-4A20-6AB-4A22-4AB-4A5(25-AB-B3A)2(25-2A-4A)25-2(2AB5A24-)2(2AB6A23-)2AB5A24-ACB5A24-2AB5A24-ACB-4A24-AC5(B5A26-)B5A24-A-B5A23-2(2A-B6A22-)2A-B6A20-5AB6A19-6AB31A-3BAB3AB7A9-6A-4A22-4AB-4A20-6AB-4A22-4A4(B-4A25-A)3(B-B3A25-A)B-B3A25-2(2A-B4A24-)2A-B5A23-2AB6A23-2A2(B5A24-AC)B5A24-ADB5A24-AC2(B5A26-)B5A3(27-B4A)24-A2-B4A23-2(2A2-B5A22-)2A2-B5A20-5A-B5A19-6AB31A-2B2AB11A9-6A2-3A22-4AB2-3A20-6AB2-3A22-4A4(B2-3A25-A)B2-3A25-2A2-B2A25-2(2A2-B3A24-)2(2A-B4A24-)A2-B5A23-A-B6A23-A2(-B5A24-C)-B5A24-D2-B4A23-AC2-5(B4A27-)B5A23-A3(2-B5A22-2A)2-B5A20-5A-B5A19-6A2B30A2-2B2(2AB)4AB2A5-10A2-5A19-5AB2-5A18-6AB2-4A19-6A2(B2-4A24-A)B2-4A24-B5(3-4A24-A)2(2-B4A24-C)2(2-B5A23-C)2(2-B4A24-C)2-B4A24-D2-B4A23-AD2-5(B4A27-)B5A23-A2(2-B5A22-2A)2-B5A21-3A2-B5A20-5A-B5A19-6A-B30A2-3BAB3AB5AC5-10A3-4A19-5A2(4-4A18-5AB)4-4A22-2A3(4-4A23-B)4-2(3A24-B3-B)3A24-A3-B3A2(24-A2-B4A)24-A2(2-6A23-C)2(2-5A24-C)2-B4A24-D2-B4A23-AD2-B4A24-C2-B4A27-B4A2(28-B3A)28-B4A23-A2(3-B4A22-2A)3-B4A21-3A3-B4A20-5A2-B4A19-6A-B30A2-5B3AB21A3-5A18-5A4-5A17-5AB4-4A18-5AB4-4A21-3A4(4-4A22-AB)3-B4A22-AB2(3-B4A22-2A)4(2-B5A22-2A)3(2-B4A23-2A)2(3-B3A23-AD)3-B3A28-3(B4A27-)2(B4A22-2A3-)B4A21-3A3-B4A20-4A3-B4A20-5A2-B4A19-6A-B5A17-7A3-8B14A2C6A4-5A17-4A6-4A17-6A2(5-4A17-5AB)2(5-A-A22-AB)4-BA-A22-AB4-BA-A9(22-2A3-B4A)22-2A3-B3A2(23-2A3-BA-A)22-A2C3-B4A21-A5-B2A-3(A21-A5-BA2-)A21-2A4-BA2-A20-3A4-BA2-A19-4A4-2(B4A18-6A3-)2(B4A17-7A3-)4B17A2C6A5-5A17-3A2(7-5A16-4A)B6-4A17-4AB6-A-2A21-B6-A2(-A22-B5-2A)-A22-B8(5-B3A22-A)4-B4A22-3(A4-B3A23-)A6(4-B4A20-3A)4-B4A19-4A2(4-B4A18-5A)4-B4A17-6A4-B4A16-8A3-4B15A3C6AC5-5A15-4A3(8-5A16-3A)8-A-2A17-3AB7-A-2A19-AB7-3A20-AB7-B-A20-AB7-B2A20-AB11(6-B3A20-2A)6-B3A17-A2-3(2A6-B3A20-)2A3(6-B3A19-3A)2(6-B3A18-4A)6-B3A17-5A6-B4A15-6A6-2B13A5CA2C2A2C6-5A15-3A9-6A12-A2-2(2A9-6A15-)2A9-A-4A15-3A8-A-2A2(17-3A8-B3A)17-3A8-2B2A17-2AB8-2B2A17-4(3A8-2BA18-)14(3A8-B2A18-)3A8-B2A17-4A8-B2A16-5A8-B3A14-6A8-2BAB2AB8ACA5CA2C8-6A11-4A2(11-6A11-A2-A)11-6A10-2A2-A11-5A11-2A2-A11-3A17-A12-2A17-A12-BA17-2(2A11-B18-)2A4(11-B16-4A)10-2B16-4A2(10-2B18-2A)8(10-BA18-2A)10-3(BA18-3A9-)BA17-4A9-BA16-5A9-B2A14-6A9-3B9A11C10-4(19A13-)4A-5A-8A14-3A-5A2-7A14-3A-5A2(5-4A14-9A)5-5A13-A-7A6-4A13-A2-6A6-4A13-A2-2A10-2(4A13-A14-)2(4A12-BA14-)4A12-BA15-3A3(12-BA16-2A)12-B17-2A12-4(B17-3A11-)A17-3(3A11-2A16-)3A11-2A14-5A11-3A12-6A11-10A11C12-4(17A15-)9A-7A15-9A2-6A16-8A4-4A16-2(8A4-5A15-)2A-2(5A5-4A15-A2-)5A5-3(4A15-A12-)4A14-2A12-4A14-2A-A12-5(2A14-)4(A15-2A14-)5(A15-3A13-)2A13-4A13-2A12-5A13-5A8-6A14-9A2CA6C16-3(10A22-)3(11A21-)3(13A19-)13A3(18-14A)18-5(15A17-)15A2(16-16A)16-10(17A15-)12AC3A278-2(3A29-)4A28-4A3(27-5A)27-2(6A26-)6A25-13(8A24-)10A10-
