model
size = 22 30 30, scale = 0.05, origin = -y
material 
  colors = A:#69A5FF B:#2F2F2F C:#EEE D:#A00
voxels
-----CCCCCCCCCCCC----- -----CCCCDDDDCCCC----- -----CCDD----DDCC----- -----DD--------DD----- -----DC--------CD----- -----D----------D----- -----DC--------CD----- -----D----------D----- -----DC--------CD----- -----D----------D----- -----DC--------CD----- -----D----------D----- -----DC--------CD----- -----CD--------DC----- -----CCDC----CDCC----- ------CD------DC------ ------CCDC--CDCC------ -------CD----DC------- -------CCDCCDCC------- --------CDDDDC-------- --------CCCCCC-------- ---------CCCC--------- ----------CC---------- ---------------------- ---------------------- ---------------------- ---------------------- ---------------------- ---------------------- ---------------------- 
----CAAAAAAAAAAAAC---- ----CAAAABBBBAAAAC---- ----CAABB----BBAAC---- ----CAB--------BAC---- ----CB----------BC---- ----CB----------BC---- ----CB----------BC---- ----CB----------BC---- ----CB----------BC---- ----CB----------BC---- ----CB----------BC---- ----CB----------BC---- ----CB----------BC---- ----CAB--------BAC---- ----CAAB------BAAC---- ----CCAB------BACC---- ----CCAAB----BAACC---- ----CCCAB----BACCC---- -----CCAAB--BAACC----- -----CCCAABBAACCC----- ------CCAAAAAACC------ ------CCCAAAACCC------ --------CCAACC-------- ---------CCCC--------- ---------------------- ---------------------- ---------------------- ---------------------- ---------------------- ---------------------- 
----AAAAAAAAAAAAAA---- ---AAAAAABBBBAAAAAA--- ---AAAABB----BBAAAA--- ---AAAB--------BAAA--- ---AAB----------BAA--- ---AAB----------BAA--- ---AAB----------BAA--- ---AAB----------BAA--- ---AAB----------BAA--- ---AAB----------BAA--- ---AAB----------BAA--- ---AAB----------BAA--- ---AAB----------BAA--- ---AAAB--------BAAA--- ---AAAAB------BAAAA--- ---AAAAB------BAAAA--- ---AAAAAB----BAAAAA--- ---AAAAAB----BAAAAA--- ---AAAAAAB--BAAAAAA--- ---AAAAAAABBAAAAAAA--- -----AAAAAAAAAAAA----- -----AAAAAAAAAAAA----- ------CCAAAAAACC------ -------CCAAAACC------- --------CCCCCC-------- ---------------------- ---------------------- ---------------------- ---------------------- ---------------------- 
--AAAAABBBBBBBBAAAAA-- --AAAAAAABBBBAAAAAAA-- --AAAAABB----BBAAAAA-- --AAAAB--------BAAAA-- --AAAB----------BAAA-- --AAAB----------BAAA-- --AAAB----------BAAA-- --AAAB----------BAAA-- --AAAB----------BAAA-- --AAAB----------BAAA-- --AAAB----------BAAA-- --AAAB----------BAAA-- --AAAB----------BAAA-- --AAAAB--------BAAAA-- --AAAAAB------BAAAAA-- --AAAAAB------BAAAAA-- --AAAAAAB----BAAAAAA-- --AAAAAAB----BAAAAAA-- --AAAAAAAB--BAAAAAAA-- ---AAAAAAABBAAAAAAA--- ---AAAAAAAAAAAAAAAA--- ----AAAAAAAAAAAAAA---- ----AAAAAAAAAAAAAA---- -----AAAAAAAAAAAA----- --------AAAAAA-------- --------AACCAA-------- ---------------------- ---------------------- ---------------------- ---------------------- 
-AAAABBBBBBBBBBBBAAAA- -AAAAAAAABBBBAAAAAAAA- -AAAAAABB----BBAAAAAA- -AAAAAB--------BAAAAA- -AAAAB----------BAAAA- -AAAAB----------BAAAA- -AAAAB----------BAAAA- -AAAAB----------BAAAA- -AAAAB----------BAAAA- -AAAAB----------BAAAA- -AAAAB----------BAAAA- -AAAAB----------BAAAA- -AAAAB----------BAAAA- -AAAAAB--------BAAAAA- -AAAAAAB------BAAAAAA- -AAAAAAB------BAAAAAA- -AAAAAAAB----BAAAAAAA- --AAAAAAB----BAAAAAA-- --AAAAAAAB--BAAAAAAA-- ---AAAAAAABBAAAAAAA--- ---AAAAAAAAAAAAAAAA--- ----AAAAAAAAAAAAAA---- ----AAAAAAAAAAAAAA---- -----AAAAAAAAAAAA----- ------AAAAAAAAAA------ --------AAAAAA-------- --------AAAAAA-------- ---------------------- ---------------------- ---------------------- 
AAAABBBBBBBBBBBBBBAAAA AAAAAAAAABBBBAAAAAAAAA AAAAAAABB----BBAAAAAAA AAAAAAB--------BAAAAAA AAAAAB----------BAAAAA AAAAAB----------BAAAAA AAAAAB----------BAAAAA AAAAAB----------BAAAAA AAAAAB----------BAAAAA AAAAAB----------BAAAAA AAAAAB----------BAAAAA -AAAAB----------BAAAA- -AAAAB----------BAAAA- -AAAAAB--------BAAAAA- -AAAAAAB------BAAAAAA- -AAAAAAB------BAAAAAA- -AAAAAAAB----BAAAAAAA- --AAAAAAB----BAAAAAA-- --AAAAAAAB--BAAAAAAA-- ---AAAAAAABBAAAAAAA--- ---AAAAAAAAAAAAAAAA--- ----AAAAAAAAAAAAAA---- ----AAAAAAAAAAAAAA---- -----AAAAAAAAAAAA----- ------AAAAAAAAAA------ -------AAAAAAAA------- -------AAAAAAAA------- --------AAAAAA-------- ---------------------- ---------------------- 
AAAABBBBBBBBBBBBBBAAAA -BAAAAAAABBBBAAAAAAAB- AAAAAAABB----BBAAAAAAA AAAAAAB--------BAAAAAA -BAAAB----------BAAAB- AAAAAB----------BAAAAA AAAAAB----------BAAAAA -BAAAB----------BAAAB- AAAAAB----------BAAAAA AAAAAB----------BAAAAA AAAAAB----------BAAAAA -AAAAB----------BAAAA- -AAAAB----------BAAAA- -AAAAAB--------BAAAAA- -AAAAAAB------BAAAAAA- -AAAAAAB------BAAAAAA- -AAAAAAAB----BAAAAAAA- --BAAAAAB----BAAAAAB-- --BAAAAAAB--BAAAAAAB-- ---BAAAAAABBAAAAAAB--- ---BAAAAAAAAAAAAAAB--- ----BAAAAAAAAAAAAB---- ----BAAAAAAAAAAAAB---- -----BAAAAAAAAAAB----- ------BAAAAAAAAB------ -------BAAAAAAB------- -------AAAAAAAA------- --------AAAAAA-------- ---------AAAA--------- ---------------------- 
AAABBBBBBBBBBBBBBBBAAA -BAAAAAAABBBBAAAAAAAB- AAAAAAABB----BBAAAAAAA AAAAAAB--------BAAAAAA -BAAAB----------BAAAB- AAAAAB----------BAAAAA AAAAAB----------BAAAAA -BAAAB----------BAAAB- AAAAAB----------BAAAAA AAAAAB----------BAAAAA AAAAAB----------BAAAAA -AAAAB----------BAAAA- -AAAAB----------BAAAA- -AAAAAB--------BAAAAA- -AAAAAAB------BAAAAAA- -AAAAAAB------BAAAAAA- -AAAAAAAB----BAAAAAAA- --BAAAAAB----BAAAAAB-- --BAAAAAAB--BAAAAAAB-- ---CAAAAAABBAAAAAAC--- ---CAAAAAAAAAAAAAAC--- ----CAAAAAAAAAAAAC---- ----BAAAAAAAAAAAAB---- -----BAAAAAAAAAAB----- ------BAAAAAAAAB------ -------BAAAAAAB------- -------AAAAAAAA------- --------AAAAAA-------- ---------AAAA--------- ----------AA---------- 
AAABBBBBBBBBBBBBBBBAAA -BAAAAAAABBBBAAAAAAAB- AAAAAAABB----BBAAAAAAA AAAAAAB--------BAAAAAA -BAAAB----------BAAAB- AAAAAB----------BAAAAA AAAAAB----------BAAAAA -BAAAB----------BAAAB- AAAAAB----------BAAAAA AAAAAB----------BAAAAA AAAAAB----------BAAAAA -AAAAB----------BAAAA- -AAAAB----------BAAAA- -AAAAAB--------BAAAAA- -AAAAAAB------BAAAAAA- -AAAAAAB------BAAAAAA- -BAAAAAAB----BAAAAAAB- --BAAAAAB----BAAAAAB-- --CAAAAAAB--BAAAAAAC-- ---CAAAAAABBAAAAAAC--- ---CAAAAAAAAAAAAAAC--- ----CAAAAAAAAAAAAC---- ----BAAAAAAAAAAAAB---- -----CAAAAAAAAAAC----- ------BAAAAAAAAB------ -------BAAAAAAB------- -------BAAAAAAB------- --------BAAAAB-------- ---------AAAA--------- ----------AA---------- 
AAABBBBBBBBBBBBBBBBAAA -BAAAAAAABBBBAAAAAAAB- AAAAAAABB----BBAAAAAAA AAAAAAB--------BAAAAAA -BAAAB----------BAAAB- AAAAAB----------BAAAAA AAAAAB----------BAAAAA -BAAAB----------BAAAB- AAAAAB----------BAAAAA AAAAAB----------BAAAAA AAAAAB----------BAAAAA -BAAAB----------BAAAB- -BAAAB----------BAAAB- -BAAAAB--------BAAAAB- -BAAAAAB------BAAAAAB- -BAAAAAB------BAAAAAB- -BAAAAAAB----BAAAAAAB- --BAAAAAB----BAAAAAB-- --CAAAAAAB--BAAAAAAC-- ---CAAAAAABBAAAAAAC--- ---CAAAAAAAAAAAAAAC--- ----BAAAAAAAAAAAAB---- ----BAAAAAAAAAAAAB---- -----BAAAAAAAAAAB----- ------BAAAAAAAAB------ -------BAAAAAAB------- -------BAAAAAAB------- --------AAAAAA-------- ---------AAAA--------- ----------AA---------- 
AAABBBBBBBBBBBBBBBBAAA -BAAAAAAABBBBAAAAAAAB- AAAAAAABB----BBAAAAAAA AAAAAAB--------BAAAAAA -BAAAB----------BAAAB- AAAAAB----------BAAAAA AAAAAB----------BAAAAA -BAAAB----------BAAAB- AAAAAB----------BAAAAA AAAAAB----------BAAAAA AAAAAB----------BAAAAA -AAAAB----------BAAAA- -AAAAB----------BAAAA- -AAAAAB--------BAAAAA- -AAAAAAB------BAAAAAA- -AAAAAAB------BAAAAAA- -AAAAAAAB----BAAAAAAA- --BAAAAAB----BAAAAAB-- --BAAAAAAB--BAAAAAAB-- ---CAAAAAABBAAAAAAC--- ---CAAAAAAAAAAAAAAC--- ----CAAAAAAAAAAAAC---- ----CAAAAAAAAAAAAC---- -----CAAAAAAAAAAC----- ------BAAAAAAAAB------ -------BAAAAAAB------- -------AAAAAAAA------- --------AAAAAA-------- ---------AAAA--------- ----------AA---------- 
AAAABBBBBBBBBBBBBBAAAA --BAAAAAABBBBAAAAAAB-- AAAAAAABB----BBAAAAAAA ABAAAAB--------BAAAABA --BAAB----------BAAB-- AAAAAB----------BAAAAA ABAAAB----------BAAABA --BAAB----------BAAB-- AAAAAB----------BAAAAA AAAAAB----------BAAAAA AAAAAB----------BAAAAA -AAAAB----------BAAAA- -AAAAB----------BAAAA- -AAAAAB--------BAAAAA- -AAAAAAB------BAAAAAA- -AAAAAAB------BAAAAAA- -AAAAAAAB----BAAAAAAA- --BAAAAAB----BAAAAAB-- --BAAAAAAB--BAAAAAAB-- ---BAAAAAABBAAAAAAB--- ---BAAAAAAAAAAAAAAB--- ----BAAAAAAAAAAAAB---- ----BAAAAAAAAAAAAB---- -----BAAAAAAAAAAB----- ------BAAAAAAAAB------ -------BAAAAAAB------- -------AAAAAAAA------- --------AAAAAA-------- ---------AAAA--------- ----------AA---------- 
AAAABBBBBBBBBBBBBBAAAA ABAAAAAAABBBBAAAAAAABA -BAAAAABB----BBAAAAAB- AAAAAAB--------BAAAAAA ABAAAB----------BAAABA -BAAAB----------BAAAB- AAAAAB----------BAAAAA ABAAAB----------BAAABA -BAAAB----------BAAAB- AAAAAB----------BAAAAA AAAAAB----------BAAAAA -AAAAB----------BAAAA- -AAAAB----------BAAAA- -AAAAAB--------BAAAAA- -AAAAAAB------BAAAAAA- -AAAAAAB------BAAAAAA- -AAAAAAAB----BAAAAAAA- --AAAAAAB----BAAAAAA-- --AAAAAAAB--BAAAAAAA-- ---AAAAAAABBAAAAAAA--- ---AAAAAAAAAAAAAAAA--- ----AAAAAAAAAAAAAA---- ----AAAAAAAAAAAAAA---- -----AAAAAAAAAAAA----- ------AAAAAAAAAA------ -------AAAAAAAA------- -------AAAAAAAA------- --------AAAAAA-------- ---------AAAA--------- ---------------------- 
-AAABBBBBBBBBBBBBBAAA- -AAAAAAAABBBBAAAAAAAA- --BAAAABB----BBAAAAB-- --BAAAB--------BAAAB-- -AAAAB----------BAAAA- --BAAB----------BAAB-- --BAAB----------BAAB-- -AAAAB----------BAAAA- --BAAB----------BAAB-- --BAAB----------BAAB-- -AAAAB----------BAAAA- -AAAAB----------BAAAA- -AAAAB----------BAAAA- -AAAAAB--------BAAAAA- -AAAAAAB------BAAAAAA- -AAAAAAB------BAAAAAA- -AAAAAAAB----BAAAAAAA- --AAAAAAB----BAAAAAA-- --AAAAAAAB--BAAAAAAA-- ---AAAAAAABBAAAAAAA--- ---AAAAAAAAAAAAAAAA--- ----AAAAAAAAAAAAAA---- ----AAAAAAAAAAAAAA---- -----AAAAAAAAAAAA----- ------AAAAAAAAAA------ -------AAAAAAAA------- -------AAAAAAAA------- ---------AAAA--------- ---------------------- ---------------------- 
--AAAABBBBBBBBBBAAAA-- --AAAAAAAAAAAAAAAAAA-- --AAAAAAABBBBAAAAAAA-- ---BAAABBBBBBBBAAAB--- --AAAABBBBBBBBBBAAAA-- --AAAABBBBBBBBBBAAAA-- ---BAABBBBBBBBBBAAB--- --AAAABBBBBBBBBBAAAA-- --AAAABBBBBBBBBBAAAA-- ---BAABBBBBBBBBBAAB--- --AAAABBBBBBBBBBAAAA-- --AAAABBBBBBBBBBAAAA-- --AAAABBBBBBBBBBAAAA-- --AAAAABBBBBBBBAAAAA-- --AAAAAABBBBBBAAAAAA-- --AAAAAABBBBBBAAAAAA-- --AAAAAAABBBBAAAAAAA-- --AAAAAAABBBBAAAAAAA-- --AAAAAAAABBAAAAAAAA-- ---AAAAAAAAAAAAAAAA--- ---AAAAAAAAAAAAAAAA--- ----AAAAAAAAAAAAAA---- ----AAAAAAAAAAAAAA---- -----AAAAAAAAAAAA----- ------AAAAAAAAAA------ -------AAAAAAAA------- ---------------------- ---------------------- ---------------------- ---------------------- 
---AAAAABBBBBBAAAAA--- ---AAAAAAAAAAAAAAAA--- ---AAAAAAAAAAAAAAAA--- ---AAAAAAAAAAAAAAAA--- ---AAAAAAAAAAAAAAAA--- ---AAAAAAAAAAAAAAAA--- ---AAAAAAAAAAAAAAAA--- ---AAAAAAAAAAAAAAAA--- ---AAAAAAAAAAAAAAAA--- ---AAAAAAAAAAAAAAAA--- ---AAAAAAAAAAAAAAAA--- ---AAAAAAAAAAAAAAAA--- ---AAAAAAAAAAAAAAAA--- ---AAAAAAAAAAAAAAAA--- ---AAAAAAAAAAAAAAAA--- ---AAAAAAAAAAAAAAAA--- ---AAAAAAAAAAAAAAAA--- ---AAAAAAAAAAAAAAAA--- ---AAAAAAAAAAAAAAAA--- ---AAAAAAAAAAAAAAAA--- ---AAAAAAAAAAAAAAAA--- ----AAAAAAAAAAAAAA---- ----AAAAAAAAAAAAAA---- ------AAAAAAAAAA------ ---------------------- ---------------------- ---------------------- ---------------------- ---------------------- ---------------------- 
----AAAAAAAAAAAAAA---- ----AAAAAAAAAAAAAA---- ----AAAAAAAAAAAAAA---- ----AAAAAAAAAAAAAA---- ----AAAAAAAAAAAAAA---- ----AAAAAAAAAAAAAA---- ----AAAAAAAAAAAAAA---- ----AAAAAAAAAAAAAA---- ----AAAAAAAAAAAAAA---- ----AAAAAAAAAAAAAA---- ----AAAAAAAAAAAAAA---- ----AAAAAAAAAAAAAA---- ----AAAAAAAAAAAAAA---- ----AAAAAAAAAAAAAA---- ----AAAAAAAAAAAAAA---- ----AAAAAAAAAAAAAA---- ----AAAAAAAAAAAAAA---- ----AAAAAAAAAAAAAA---- ----AAAAAAAAAAAAAA---- -----AAAAAAAAAAAA----- -----AAAAAAAAAAAA----- -------AAAAAAAA------- ---------------------- ---------------------- ---------------------- ---------------------- ---------------------- ---------------------- ---------------------- ---------------------- 
-----AAAAAAAAAAAA----- -----AAAAAAAAAAAA----- -----AAAAAAAAAAAA----- -----AAAAAAAAAAAA----- -----AAAAAAAAAAAA----- -----AAAAAAAAAAAA----- -----AAAAAAAAAAAA----- -----AAAAAAAAAAAA----- -----AAAAAAAAAAAA----- -----AAAAAAAAAAAA----- -----AAAAAAAAAAAA----- -----AAAAAAAAAAAA----- -----AAAAAAAAAAAA----- -----AAAAAAAAAAAA----- -----AAAAAAAAAAAA----- -----AAAAAAAAAAAA----- -----AAAAAAAAAAAA----- ------AAAAAAAAAA------ -------AAAAAAAA------- --------AAAAAA-------- ---------AAAA--------- ---------------------- ---------------------- ---------------------- ---------------------- ---------------------- ---------------------- ---------------------- ---------------------- ---------------------- 
------AAAAAAAAAA------ ------AAAAAAAAAA------ ------AAAAAAAAAA------ ------AAAAAAAAAA------ ------AAAAAAAAAA------ ------AAAAAAAAAA------ ------AAAAAAAAAA------ ------AAAAAAAAAA------ ------AAAAAAAAAA------ ------AAAAAAAAAA------ ------AAAAAAAAAA------ ------AAAAAAAAAA------ ------AAAAAAAAAA------ -------AAAAAAAA------- --------AAAAAA-------- ---------AAAA--------- ---------AAAA--------- ----------AA---------- ---------------------- ---------------------- ---------------------- ---------------------- ---------------------- ---------------------- ---------------------- ---------------------- ---------------------- ---------------------- ---------------------- ---------------------- 
---------------------- ---------------------- ----------AA---------- ----------AA---------- ----------AA---------- ----------AA---------- ----------AA---------- ----------AA---------- ----------AA---------- ----------AA---------- ----------AA---------- ----------AA---------- ----------AA---------- ----------AA---------- ----------AA---------- ---------------------- ---------------------- ---------------------- ---------------------- ---------------------- ---------------------- ---------------------- ---------------------- ---------------------- ---------------------- ---------------------- ---------------------- ---------------------- ---------------------- ---------------------- 
---------------------- ---------------------- ---------------------- ----------AA---------- ----------AA---------- ----------AA---------- ----------AA---------- ----------AA---------- ----------AA---------- ----------AA---------- ----------AA---------- ----------AA---------- ----------AA---------- ----------AA---------- ---------------------- ---------------------- ---------------------- ---------------------- ---------------------- ---------------------- ---------------------- ---------------------- ---------------------- ---------------------- ---------------------- ---------------------- ---------------------- ---------------------- ---------------------- ---------------------- 
---------------------- ---------------------- ---------------------- ----------AA---------- ----------AA---------- ----------AA---------- ----------AA---------- ----------AA---------- ----------AA---------- ----------AA---------- ----------AA---------- ----------AA---------- ----------AA---------- ----------AA---------- ---------------------- ---------------------- ---------------------- ---------------------- ---------------------- ---------------------- ---------------------- ---------------------- ---------------------- ---------------------- ---------------------- ---------------------- ---------------------- ---------------------- ---------------------- ---------------------- 
---------------------- ---------------------- ---------------------- ---------------------- ----------AA---------- ----------AA---------- ----------AA---------- ----------AA---------- ----------AA---------- ----------AA---------- ----------AA---------- ----------AA---------- ----------AA---------- ---------------------- ---------------------- ---------------------- ---------------------- ---------------------- ---------------------- ---------------------- ---------------------- ---------------------- ---------------------- ---------------------- ---------------------- ---------------------- ---------------------- ---------------------- ---------------------- ---------------------- 
---------------------- ---------------------- ---------------------- ---------------------- ----------AA---------- ----------AA---------- ----------AA---------- ----------AA---------- ----------AA---------- ----------AA---------- ----------AA---------- ----------AA---------- ---------------------- ---------------------- ---------------------- ---------------------- ---------------------- ---------------------- ---------------------- ---------------------- ---------------------- ---------------------- ---------------------- ---------------------- ---------------------- ---------------------- ---------------------- ---------------------- ---------------------- ---------------------- 
---------------------- ---------------------- ---------------------- ---------------------- ----------AA---------- ----------AA---------- ----------AA---------- ----------AA---------- ----------AA---------- ----------AA---------- ----------AA---------- ---------------------- ---------------------- ---------------------- ---------------------- ---------------------- ---------------------- ---------------------- ---------------------- ---------------------- ---------------------- ---------------------- ---------------------- ---------------------- ---------------------- ---------------------- ---------------------- ---------------------- ---------------------- ---------------------- 
---------------------- ---------------------- ---------------------- ----------AA---------- ----------AA---------- ----------AA---------- ----------AA---------- ----------AA---------- ----------AA---------- ----------AA---------- ----------AA---------- ---------------------- ---------------------- ---------------------- ---------------------- ---------------------- ---------------------- ---------------------- ---------------------- ---------------------- ---------------------- ---------------------- ---------------------- ---------------------- ---------------------- ---------------------- ---------------------- ---------------------- ---------------------- ---------------------- 
---------------------- ---------------------- ---------------------- ----------AA---------- ----------AA---------- ----------AA---------- ----------AA---------- ----------AA---------- ----------AA---------- ----------AA---------- ---------------------- ---------------------- ---------------------- ---------------------- ---------------------- ---------------------- ---------------------- ---------------------- ---------------------- ---------------------- ---------------------- ---------------------- ---------------------- ---------------------- ---------------------- ---------------------- ---------------------- ---------------------- ---------------------- ---------------------- 
---------------------- ---------------------- ----------AA---------- ----------AA---------- ----------AA---------- ----------AA---------- ----------AA---------- ----------AA---------- ---------------------- ---------------------- ---------------------- ---------------------- ---------------------- ---------------------- ---------------------- ---------------------- ---------------------- ---------------------- ---------------------- ---------------------- ---------------------- ---------------------- ---------------------- ---------------------- ---------------------- ---------------------- ---------------------- ---------------------- ---------------------- ---------------------- 
---------------------- ---------------------- ----------AA---------- ----------AA---------- ----------AA---------- ----------AA---------- ---------------------- ---------------------- ---------------------- ---------------------- ---------------------- ---------------------- ---------------------- ---------------------- ---------------------- ---------------------- ---------------------- ---------------------- ---------------------- ---------------------- ---------------------- ---------------------- ---------------------- ---------------------- ---------------------- ---------------------- ---------------------- ---------------------- ---------------------- ---------------------- 
---------------------- ----------AA---------- ----------AA---------- ----------AA---------- ---------------------- ---------------------- ---------------------- ---------------------- ---------------------- ---------------------- ---------------------- ---------------------- ---------------------- ---------------------- ---------------------- ---------------------- ---------------------- ---------------------- ---------------------- ---------------------- ---------------------- ---------------------- ---------------------- ---------------------- ---------------------- ---------------------- ---------------------- ---------------------- ---------------------- ---------------------- 
