model
size = 32 4 32, scale = 0.05, origin = -y
material 
  colors = A:#FFF B:#111
voxels
12-3(8A24-)8A21-3(14A18-)14A16-3(18A14-)18A13-3(20A12-)20A11-3(22A10-)22A9-3(24A8-)24A7-3(26A6-)26A5-7(28A4-)28A3-11(30A2-)30A-130AB2ABA3BA4BAB2ABA4B2A3B68A3B2A4BAB2ABA4BA3BAB2AB4AB2AB3A2(B4ABAB2A)B68A2(B2ABAB4A)B3AB2AB5A3B2A2B4ABA4B3A2BAB2AB68AB2ABA2B3A4BAB4A2B2A3B5AB2AB3A2(B4ABAB2A)B68A2(B2ABAB4A)B3AB2AB4AB2AB3A2(B4ABAB2A)B68A2(B2ABAB4A)B3AB2AB5A3BA3B4AB2A2B3A3B2A3B68A3B2A3B3A2B2AB4A3BA3B131A-11(30A2-)30A3-7(28A4-)28A5-3(26A6-)26A7-3(24A8-)24A9-3(22A10-)22A11-3(20A12-)20A13-3(18A14-)18A16-3(14A18-)14A21-3(8A24-)8A12-
