model
size = 10, scale = 0.05, origin = -y
material 
  colors = A:#91989F B:#707C74 C:#0D5661 D:#33A6B8 E:#211E55
voxels
ABAAAAAAAA ABABBBBBBB ABAAAAAAAA ---AAAAEBA ----AAAABA DD---AAABA CCDD--AABA CCCD---ABA CCCCD--ABA CCCCD--AAA 
ABABBBBBBA BAAAAAAAAB ABAAAAAABA --ABAAAAAB ----BAAAAB DD---BAAAB CDD---BAAB CCCD--BAAB CCCDD--BAB CCCCD--BBB 
ABAEAA---- BAAAAAA--- AAAAAAAA-- -BAAAAAABA ----AAAAAA -----AAAAA DDD---AAAA CCDD--AAAA CCCD--AAAA CCCD---AAA 
ABAAA----- BAAAA----- AAAAA----- ABAAAA---- ---AAAAABA ----AAAAAA D----AAAAA DDD---AAAE CDD---BAAB CCDD--AABA 
ABAA---DDD BAAA---DDD AAAA------ AAAAA----- ABAAAA---- ---AAAAABA ----AAAAAA -----AAAAA DD---BAAAB DD---AAABA 
ABA--DDCCC BAA---DDCC AAA---DDDD AAAA----DD AAAAA----- ABAAAA---- ---AAAAABA ----AAAAAA ----BAAAAB ----AAAABA 
AB---DCCCC BAA--DCCCC AAA--DDCCC AAA---DDDD AAAA------ AAAAA----- ABAAAAAA-- -BAAAAAABA --ABAAAAAB ---AAAAABA 
AB--DCCCCC BA--DDCCCC AAA--DCCCC EAA---DDCC AAAA---DDD AAAAA----- AAAAAAA--- AAAAAAAABA BBAAAAAAAB ABAAAAEABA 
AB--DCCCCC BA--DCCCCC AA---DCCCC BAA--DDCCC BAAA---DDD BAAAA----- BAAAAA---- AAAAAAAABA BAAAAAAAAB ABABBBBABA 
AB--DCCCCC AB--DCCCCC AB---DCCCC ABA--DDCCC ABAA---DDD ABAAA----- ABAAAA---- ABAEAAAABA ABABBBBABA ABAAAAAABA 
