model
size = 9 19 15, scale = 0.05, origin = -y
material 
  colors = A:#E1B400 B:#BBB C:#AAA D:#F93 E:#FC3 F:#DDD G:#EEE H:#F99 I:#222 J:#F90 K:#FC9 L:#FF9 M:#F96 N:#888 O:#FFC P:#F60
voxels
--------- --------- ----A---- ----A---- ----E---- --------- --------- --------- --------- --------- --------- --------- --------- --------- --------- --------- --------- --------- --------- 
--------- ----E---- --------- --------- ----A---- --------- --------- --------- --------- --------- --------- --------- --------- --------- --------- --------- --------- --------- --------- 
--------- ----A---- --------- --------- ----A---- --------- --------- --------- --------- --------- --------- --------- --------- --------- --------- --------- --------- --------- --------- 
AAAAAAAAE EAAAAAEAA ----A---- ----A---- ----E---- --------- --------- --------- --------- --------- --------- --------- --------- --------- --------- --------- --------- --------- --------- 
ADHDMDDDA A-------A --------- --------- --------- --------- --------- --------- --------- --------- --------- --------- --------- --------- --------- --------- --------- --------- --------- 
ADDDDDHDE E-------A --------- --------- --------- --------- --------- --------- --------- --------- --------- --------- --------- --------- --------- --------- --------- --------- --------- 
ADDBNBDDA A--BCC--E ---BCC--- ---BCC--- ---BBC--- ---BBC--- ---BBB--- ---BBB--- ----BF--- ----FG--- --------- --------- --------- ----J---- ----E---- ----L---- --------- --------- --------- 
ADDBBBDDA A--CCC--A ---CCC--- ---CCC--- ---CCB--- ---CCC--- --BCCB--- --CCCB--- --FBCB--- ---GIF--- ----IG--- ----I---- ----P---- ---EA---- ---KKE--- -----L--- ----O---- --------- ----G---- 
ADDBBBDHE A--CCB--A ---CCB--- ---CCC--- ---BCC--- ---BCB--- ---BCB--- ---BCF--- ----BF--- ----GG--- --------- --------- --------- ----J---- ----E---- --------- --------- --------- --------- 
EBBBBDDDA AFCBB---A ----C---- ----B---- ----F---- --------- --------- --------- --------- --------- --------- --------- --------- --------- --------- --------- --------- --------- --------- 
EBBBBDHDA ABCCC---A --------- --------- --------- --------- --------- --------- --------- --------- --------- --------- --------- --------- --------- --------- --------- --------- --------- 
AAAAAEAAA AEAA-AEEA --------- --------- --------- --------- --------- --------- --------- --------- --------- --------- --------- --------- --------- --------- --------- --------- --------- 
----A---- ---A-A--- --------- --------- --------- --------- --------- --------- --------- --------- --------- --------- --------- --------- --------- --------- --------- --------- --------- 
----A---- ---A-E--- --------- --------- --------- --------- --------- --------- --------- --------- --------- --------- --------- --------- --------- --------- --------- --------- --------- 
--------- ---EDA--- --------- --------- --------- --------- --------- --------- --------- --------- --------- --------- --------- --------- --------- --------- --------- --------- --------- 
