model
size = 24 32 22, scale = 0.05, origin = -y
material 
  colors = A:#555 B:#222 C:#EEE D:#600 E:#FC3 F:#F90 G:#DDD H:#00B
voxels
625-7A16-5A3-3A24-12A16-8A79-B3-B20-B-B45-B-B20-B3-B379-13A9-4A2C6D2C3A6-5ACD6CDC4A5-5A3CD2CD3C4A5-5A10C4A5-19A2-A2-2A3-14A5-5A3-11A5-2A3-3A4-8A12-4A23-7A-A8-3B20-5B2-5A11-7B-5A11-3BG3B-5A11-7B-5A12-5B-6A13-3B-7A16-8A13(13-11A)10-17A6-4(19A5-)19A2-A2-2(19A5-)2A3-15A12-11A16-7A-A31-19(13A11-)13A9-17A6-4(19A5-)19A2-A2-19A3-21A5-2A3-15A12-11A16-7A-A30-19(15A9-)15A7-5(19A5-)19A2-A2-19A5-20A4-2A3-15A12-11A16-7A-A29-19(17A7-)17A6-E18A5(5-19A)2-A2-2(20A4-)2A3-15A12-11A16-7A-A29-19(17A7-)17A6-F18A5-E18A3(5-19A)5-20A-A2-2(20A4-)2A3-16A11-11A16-7A-A29-6(16A8-)13(17A7-)17A6-E18A5-F18A5-E18A2(5-19A)5-22A2-21A3-20A4-2A3-15A12-11A16-7A-A29-7(16A8-)12(17A7-)17A6-2(F18A5-E18A5-)19A5-20A-A2-20A2-22A4-2A3-15A12-11A16-7A-A29-11(16A8-)16AG7-3(16A8-)4(17A7-)17A6-E18A5-F2(18A5-C)18A5-E18A5-20A-A2-20A2-22A4-2A3-16A11-11A16-7A-A29-11(16A8-)16AG7-3(16A8-)4(17A7-)17A6-F18A5-C2(18A5-H)18A5-C18A5-E21A2-21A-22A4-2A3-15A12-11A16-7A-A29-11(16A8-)16AG7-3(16A8-)4(17A7-)17A6-E18A5-C2(18A5-H)18A5-C18A5-E21A2-21A-22A4-2A3-15A12-11A16-7A-A29-11(16A8-)16AG7-3(16A8-)4(17A7-)17A6-F18A5-E2(18A5-C)18A5-E18A5-20A-A2-20A2-22A4-2A3-16A11-11A16-7A-A29-7(16A8-)12(17A7-)17A6-2(E18A5-F18A5-)19A5-20A-A2-20A2-22A4-2A3-15A12-11A16-7A-A29-6(16A8-)13(17A7-)17A6-F18A5-E18A5-F18A2(5-19A)5-22A2-21A3-20A4-2A3-15A12-11A16-7A-A29-19(17A7-)17A6-E18A5-F18A3(5-19A)5-20A-A2-2(20A4-)2A3-16A11-11A16-7A-A29-19(17A7-)17A6-F18A5(5-19A)2-A2-2(20A4-)2A3-15A12-11A16-7A-A30-19(15A9-)15A7-5(19A5-)19A2-A2-19A5-20A4-2A3-15A12-11A16-7A-A31-19(13A11-)13A9-17A6-4(19A5-)19A2-A2-19A3-21A5-2A3-15A12-11A16-7A-A8-3B20-5B2-5A11-7B-5A11-3BG3B-5A11-7B-5A12-5B-6A13-3B-7A16-8A13(13-11A)10-17A6-4(19A5-)19A2-A2-2(19A5-)2A3-15A12-11A16-7A-A31-B3-B20-B-B45-B-B20-B3-B379-13A9-4A2C6D2C3A6-5ACD6CDC4A5-5A3CD2CD3C4A5-5A10C4A5-19A2-A2-2A3-14A5-5A3-11A5-2A3-3A4-8A12-4A23-7A-A626-7A16-5A3-3A24-12A16-8A49-
