model
size = 24 32 22, scale = 0.05, origin = -y
material 
  colors = A:#3CC B:#F0F C:#F0C D:#39F E:#30F F:#9CC G:#C6C H:#06F
voxels
625-7B16-5B3-3B24-12B16-8B79-B3-B20-B-B45-B-B20-B3-B379-13A9-4A2C6D2C3A6-5ACD6CDC4A5-5A3CD2CD3C4A5-5A10C4A5-19A2-B2-2A3-14A5-2A3B3-11A5-2A3-3B4-7AB12-4B23-7B-B8-3B20-5B2-5A11-7B-5A11-3BH3B-5A11-7B-5A12-5B-6A13-3B-7A16-8A13(13-11A)10-17A6-4(19A5-)19A2-B2-2(19A5-)2A3-14AB12-11A16-6AB-B31-19(13A11-)13A9-17A6-4(19A5-)19A2-B2-19A3-B20A5-2A3-14AB12-11A16-6AB-B30-19(15A9-)15A7-5(19A5-)19A2-B2-19A5-19AB4-2A3-14AB12-11A16-6AB-B29-19(17A7-)17A6-E18A5(5-19A)2-B2-2(19AB4-)2A3-14AB12-11A16-6AB-B29-19(17A7-)17A6-F18A5-E18A4(5-19A)B-B2-2(19AB4-)2A3-16A11-11A16-6AB-B29-6(16A8-)13(17A7-)17A6-E18A5-F18A5-E18A2(5-19A)5-21AB2-21A3-19AB4-2A3-14AB12-11A16-6AB-B29-7(16A8-)12(17A7-)17A6-2(F18A5-E18A5-)19A5-19AB-B2-19AB2-B20AB4-2A3-14AB12-11A16-6AB-B29-11(16A8-)16AG7-3(16A8-)4(17A7-)17A6-E18A5-F2(18A5-C)18A5-E18A5-19AB-B2-19AB2-B20AB4-2A3-16A11-11A16-6AB-B29-11(16A8-)16AG7-3(16A8-)4(17A7-)17A6-F18A5-C2(18A5-D)18A5-C18A5-E20AB2-21A-B20AB4-2A3-14AB12-11A16-6AB-B29-11(16A8-)16AG7-3(16A8-)4(17A7-)17A6-E18A5-C2(18A5-D)18A5-C18A5-F20AB2-21A-B20AB4-2A3-14AB12-11A16-6AB-B29-11(16A8-)16AG7-3(16A8-)4(17A7-)17A6-F18A5-E2(18A5-C)18A5-F18A5-19AB-B2-19AB2-B20AB4-2A3-16A11-11A16-6AB-B29-7(16A8-)12(17A7-)17A6-2(E18A5-F18A5-)19A5-19AB-B2-19AB2-B20AB4-2A3-14AB12-11A16-6AB-B29-6(16A8-)13(17A7-)17A6-F18A5-E18A5-F18A2(5-19A)5-21AB2-21A3-19AB4-2A3-14AB12-11A16-6AB-B29-19(17A7-)17A6-E18A5-F18A4(5-19A)B-B2-2(19AB4-)2A3-16A11-11A16-6AB-B29-19(17A7-)17A6-F18A5(5-19A)2-B2-2(19AB4-)2A3-14AB12-11A16-6AB-B30-19(15A9-)15A7-5(19A5-)19A2-B2-19A5-19AB4-2A3-14AB12-11A16-6AB-B31-19(13A11-)13A9-17A6-4(19A5-)19A2-B2-19A3-B20A5-2A3-14AB12-11A16-6AB-B8-3B20-5B2-5A11-7B-5A11-3BH3B-5A11-7B-5A12-5B-6A13-3B-7A16-8A13(13-11A)10-17A6-4(19A5-)19A2-B2-2(19A5-)2A3-14AB12-11A16-6AB-B31-B3-B20-B-B45-B-B20-B3-B379-13A9-4A2C6D2C3A6-5ACD6CDC4A5-5A3CD2CD3C4A5-5A10C4A5-19A2-B2-2A3-14A5-2A3B3-11A5-2A3-3B4-7AB12-4B23-7B-B626-7B16-5B3-3B24-12B16-8B49-
