model
size = 22 30 9, scale = 0.05, origin = -y
material 
  colors = A:#EEE B:#B00 C:#33C D:#222 E:#3F6 F:#33F G:#BBB H:#A00
voxels
---------------------- ---------------------- ---------------------- ---------------------- ---------------------- ---------------------- ---------------------- ---------------------- ---------------------- ---------------------- ---------------------- ---------------------- ---------------------- ---------------------- -----------C---------- -----------C---------- -----------C---------- ---------------------- ---------------------- ---------------------- ---------------------- ---------------------- ---------------------- ---------------------- ----D------------D---- ---DDD----------DDD--- ----D------------D---- ---------------------- ---------------------- ---------------------- 
---------------------- ---------------------- ---------------------- ---------------------- ---------------------- ---------------------- ---------------------- ---------------------- ---------------------- ---------------------- ---------------------- ---------------------- ---------------------- ----------CC---------- ----------CC---------- ----------FC---------- ----------CC---------- ----------CC---------- ----------CC---------- ----------C----------- ---------------------- ---------------------- --EEEEE--------EEEEE-- -EEDDDEE------EEDDDEE- -EDDDDDE------EDDDDDE- -EDDDDDE------EDDDDDE- -EDDDDDE------EDDDDDE- -EEDDDEE------EEDDDEE- --EEEEE--------EEEEE-- ---------------------- 
---------------------- ---------------------- ---------------------- ---------------------- ---------------------- ---------------------- ---------------------- ---------------------- ---------------------- ---------------------- ---------------------- ---------------------- ----------CC---------- -------CCCCCCCC------- -------FCCCCCCF------- --------FCCCCC-------- --------FCCCCC-------- --------CCCCCC-------- ---------CCCF--------- ---------CCCF--------- ---------CCFF--------- --AAAAA----C---AAAAA-- -AAAAAAA------AAAAAAA- AAAAAAAAA----AAAAAAAAA AAAAAAAAA----AAAAAAAAA AAAAAAAAA----AAAAAAAAA AAAAAAAAA----AAAAAAAAA AAAAAAAAA----AAAAAAAAA -AAAAAAA------AAAAAAA- --AAAAA--------AAAAA-- 
--------BBBBB--------- -------BHHHBBB-------- -----BBBBBBBBBBB------ -----B---------B------ ----BB---------BB----- -----B---------B------ -----BBBBBBBBBBB------ ------HHHBBBBBB------- --------BB-BB--------- ---------------------- ---------------------- ----------CC---------- -------C--CC--C------- ------CCCCCCCCCC------ ------CCCCCCCCCC------ -------CCCCCCCC------- -------CCCCCCCC------- --------CCCCCC-------- ---------CCCF--------- ---------CCCF--------- ---------CCCF--------- --AAAAA--CCCF--AAAAA-- -AAAAAAA--C---AAAAAAA- AAAAAAAAA----AAAAAAAAA AAAAAAAAA----AAAAAAAAA AAAAAAAAA----AAAAAAAAA AAAAAAAAA----AAAAAAAAA AAAAAAAAA----AAAAAAAAA -AAAAAAA------AAAAAAA- --AAAAA--------AAAAA-- 
--------BBBBB--------- -------BBBBBBB-------- -----BBBBBBBBBBB------ ----B-GAGAGAGAG-B----- ----B---BBBBB---B----- ----B-AGAGAGAGA-B----- ----BBBBBBBBBBBB------ -----BBBBBBBBBBB------ ------BHBBBBBBB------- ---------------------- ---------------------- ------C---CC---C------ ------CC--CC--CC------ ------CCCCCCCCCC------ ------CCCCCCCCCC------ -------CCCCCCCC------- -------CCCCCCCC------- --------CCCCCC-------- ---------CCCF--------- ---------CCCF--------- ---------CCCF--------- --AAAAA--CCCF--AAAAA-- -AAAAAAA-CCCF-AAAAAAA- AAAAAAAAA-CC-AAAAAAAAA AAAAAAAAA-CC-AAAAAAAAA AAAAAAAAA----AAAAAAAAA AAAAAAAAA----AAAAAAAAA AAAAAAAAA----AAAAAAAAA -AAAAAAA------AAAAAAA- --AAAAA--------AAAAA-- 
-------BBBBBBB-------- -------BBBBBBB-------- -----BBBBBBBBBBB------ ----BBGAG---GAGBB----- ----BB-BBBBBBB-BB----- ----BBAGAGAGAGABB----- ----BBBBBBBBBBBB------ ----BBBBBBBBBBBB------ -----BBBBBBBBBBB------ -------BBB-BBB-------- ---------------------- ------C---CC---C------ ------CC--CC--CC------ ------CCCCCCCCCC------ ------CCCCCCCCCC------ -------CCCCCCCC------- -------CCCCCCCC------- --------CCCCCC-------- ---------CCCF--------- ---------CCCF--------- ---------CCCF--------- ---AAA---CCCF---AAA--- -AAAAAAA-CCCF-AAAAAAA- AAAAAAAA--CC-AAAAAAAA- AAAAAAAAA-CC-AAAAAAAAA AAAAAAAAA----AAAAAAAAA AAAAAAAAA----AAAAAAAAA -AAAAAAA-----AAAAAAAA- -AAAAAAA------AAAAAAA- ---AAA----------AAA--- 
------BBBBBBBBB------- ------BBBBBBBBB------- ----BBBBBBBBBBBBB----- ----BBGAGAGAGAGBB----- ----BBBBBBBBBBBBB----- ---BBBAGAGAGAGABBB---- ---BBBBBBBBBBBBBBB---- ----BBBBBBBBBBBBB----- -----BBBBBBBBBBB------ ------BBBBBBBBB------- --------B----B-------- ------C---CC---C------ ------CC--CC--CC------ ------CCCCCCCCCC------ ------CCCCCCCCCC------ -------CCCCCCCC------- -------CCCCCCCC------- --------CCCCCC-------- ---------CCCF--------- ---------CCCF--------- ---------CCCF--------- ----A----CCCF----A---- --AAAAA--CCCF--AAAAA-- -AAAAAAA--CC--AAAAAAA- AAAAAAAA--CC--AAAAAAA- AAAAAAAAA----AAAAAAAAA -AAAAAAA------AAAAAAA- -AAAAAAA------AAAAAAA- --AAAAA--------AAAAA-- ----A------------A---- 
------BBBBBBBBB------- ------BBBBBBBBB------- ----BBBBBBBBBBBBB----- ----BB---------BB----- ----BBBBBBBBBBBBB----- ---BBB---------BBB---- ---BBBBBBBBBBBBBBB---- ----BBBBBBBBBBBBB----- -----BBBBBBBBBBB------ ------BBBBBBBBB------- --------B----B-------- ------C---CC---C------ ------CC--CC--CC------ ------CCCCCCCCCC------ ------CCCCCCCCCC------ -------CCCCCCCC------- -------CCCCCCCC------- --------CCCCCC-------- ---------CCC---------- ---------CCC---------- ---------CCC---------- ----A----CCC-----A---- --AAAAA--CCC---AAAAA-- -AAAAAAA--CC--AAAAAAA- AAAAAAAA--CC--AAAAAAA- AAAAAAAAA----AAAAAAAAA -AAAAAAA------AAAAAAA- -AAAAAAA------AAAAAAA- --AAAAA--------AAAAA-- ----A------------A---- 
------BBBBBBBBB------- ------BBBBBBBBB------- ----BBBBBBBBBBBBB----- ----BB---------BB----- ----BBBBBBBBBBBBB----- ---BBB---------BBB---- ---BBBBBBBBBBBBBBB---- ----BBBBBBBBBBBBB----- -----BBBBBBBBBBB------ ------BBBBBBBBB------- --------B----B-------- ------C---CC---C------ ------CC--CC--CC------ ------CCCCCCCCCC------ ------CCCCCCCCCC------ -------CCCCCCCC------- -------CCCCCCCC------- --------CCCCCC-------- ---------CCC---------- ---------CCC---------- ---------CCC---------- ----A----CCC-----A---- --AAAAA--CCC---AAAAA-- -AAAAAAA--CC--AAAAAAA- AAAAAAAA--CC--AAAAAAA- AAAAAAAAA----AAAAAAAAA -AAAAAAA------AAAAAAA- -AAAAAAA------AAAAAAA- --AAAAA--------AAAAA-- ----A------------A---- 
