model
size = 10 32 32, scale = 0.05, origin = -y
material 
  colors = A:#0FC B:#6FC C:#FF3
voxels
2-C4AC2(4-6A)263-2(B6AB2-)C6AC3-A4CA3(4-6A)243-3(B6AB2-)BA4CAB3-6A4-A4CA3(4-6A)223-3(B6AB2-)BA4CAB2-B6AB3-2(A4-)6A4-A4CA3(4-6A)203-3(B6AB2-)BA4CAB2-B6AB2-BA4-AB23-6A4-A4CA3(4-6A)183-3(B6AB2-)BA4CAB2-B6AB53-6A4-A4CA2(4-6A)183-2(B6AB2-)BA4CAB2-B6AB73-6A4-A4CA2(4-6A)163-2(B6AB2-)BA4CAB2-B6AB83-2(6A4-)A4CA2(4-6A)143-2(B6AB2-)BA4CA2(B2-B6A)B93-2(6A4-)A4CA2(4-6A)123-2(B6AB2-)BA4CA2(B2-B6A)B113-2(6A4-)A4CA2(4-6A)103-2(B6AB2-)BA4CA2(B2-B6A)B133-2(6A4-)A4CA2(4-6A)15-3(C2-C6-)4C2(6-C2-C)14-2(B6AB2-)BA4CA2(B2-B6A)B153-2(6A4-)A4CA4-6A2-B2(8A2B)8AB2-6A4-6A2-B2(8A2B)8AB-B6AB2-BA4CA2(B2-B6A)B173-2(6A4-)A4CA2-B2(8A2B)8AB2-6A3-B6AB-B2(8A2B)8AB-BA4CA2(B2-B6A)B193-6A4-6A2-B2(8A2B)8AB2-6A3-B6AB-B2(8A2B)8AB-B6AB2-B6AB222-2(C6AC2-)C6AC13-B4-B2-C2(B6AB2C)B6ABC242-6A4-6A3-C6AC21-CB6ABC-B6AB2-B6AB243-6A4-6A3-C6AC21-CB6ABC-B6AB2-B6AB242-2(C6AC2-)C6AC13-B4-B2-C2(B6AB2C)B6ABC222-6A4-6A2-B2(8A2B)8AB2-6A3-B6AB-B2(8A2B)8AB-B6AB2-B6AB193-2(6A4-)A4CA2-B2(8A2B)8AB2-6A3-B6AB-B2(8A2B)8AB-BA4CA2(B2-B6A)B173-2(6A4-)A4CA4-6A2-B2(8A2B)8AB2-6A4-6A2-B2(8A2B)8AB-B6AB2-BA4CA2(B2-B6A)B153-2(6A4-)A4CA2(4-6A)15-3(C2-C6-)4C2(6-C2-C)14-2(B6AB2-)BA4CA2(B2-B6A)B133-2(6A4-)A4CA2(4-6A)103-2(B6AB2-)BA4CA2(B2-B6A)B113-2(6A4-)A4CA2(4-6A)123-2(B6AB2-)BA4CA2(B2-B6A)B93-2(6A4-)A4CA2(4-6A)143-2(B6AB2-)BA4CA2(B2-B6A)B83-6A4-A4CA2(4-6A)163-2(B6AB2-)BA4CAB2-B6AB73-6A4-A4CA2(4-6A)183-2(B6AB2-)BA4CAB2-B6AB53-6A4-A4CA3(4-6A)183-3(B6AB2-)BA4CAB2-B6AB23-2(A4-)6A4-A4CA3(4-6A)203-3(B6AB2-)BA4CAB2-B6AB2-BA4-AB3-6A4-A4CA3(4-6A)223-3(B6AB2-)BA4CAB2-B6AB3-A4CA3(4-6A)243-3(B6AB2-)BA4CAB3-C4AC2(4-6A)263-2(B6AB2-)C6AC-
