model
size = 15 30 4, scale = 0.05, origin = -y
material 
  colors = A:#7E7E7E B:#646464 C:#4B1D00 D:#6F2A00 E:#712F00 F:#884617 G:#4B4B4B H:#989898 I:#7C3B0B J:#B1B1B1 K:#945222
voxels
--------------- --------------- --------------- --------------- --------------- --------------- --------------- --------------- --------------- --------------- --------------- --------------- --------------- --------------- --------------- --------------- --------------- --------------- --------------- --------------- --------------- --------------- --------------- --------------- --CC----------- --BD----------- --DB----------- --CC----------- --------------- --------------- 
--FE----------- --CC----------- --DD----------- --CC----------- --DD----------- --CC----------- --DD----------- --CC----------- --DD----------- --FE----------- --FE----------- --CD----------- --DC----------- --KE----------- --FE----------- --FI----------- --CD--------A-- --DC--------AG- --FE--------AB- --FE-------GAA- --KE-------BAAG --CD-------AAAB --DC------BAAHA --FE------AAAHA GBFEBG--GBAAJHA BAFEAAAAAAAAJHB BAFEAABBBAAHHAG GBFEBBGGGBBAAB- --FE-------BAB- ------------B-- 
--EF----------- --CC----------- --DD----------- --CC----------- --DD----------- --CC----------- --DD----------- --CC----------- --ED----------- --EF----------- --IF----------- --DC----------- --CD----------- --EF----------- --IF----------- --EF----------- --DC--------A-- --CD--------AG- --IF--------AB- --EK-------GAA- --EF-------BAAG --DC-------AAAB --CD------BAAHA --EF------AAAHA GBEFBG--GBAAJHA BAEFAAAAAAAAJHB BAEFAABBBAAHHAG GBEFBBGGGBBAAB- --EF-------BAB- ------------B-- 
--------------- --------------- --------------- --------------- --------------- --------------- --------------- --------------- --------------- --------------- --------------- --------------- --------------- --------------- --------------- --------------- --------------- --------------- --------------- --------------- --------------- --------------- --------------- --------------- --CC----------- --BD----------- --DB----------- --CC----------- --------------- --------------- 
