model
size = 32 32 28, scale = 0.05, origin = -y
material 
  colors = A:#444 B:#AAA C:#EEE D:#222 E:#888 F:#F06 G:#DDD H:#555
voxels
5-C20-2(C10-C2-16B2-)C6(10-A2-16B2-A)7(10-A20-A)521-2C-F16EF2(-2C8-2C-18B)-2C6(8-2A-18B-2A)8-2A-F16BF-6(2A8-2A20-)2A519-3C2F16E2F2(3C6-3CF18BF)3C6(6-3AF18BF3A)6-3A-F16BF-6(3A6-3A20-)3A517-4C20A2(4C4-4C20B)4C5(4-4A20B4A)4-4AF18BF4A4-4A-F16BF-6(4A4-4A20-)4A516-4C20A2(4C4-4C20B)4C5(4-4A20B4A)4-4AF18BF4A4-4A-F16BF-5(4A4-4A20-)4A4-A2-A20-A2-A515-5C20A2(5C2-5C20B)5C5(2-5A20B5A)2-5AF18BF5A2-5A-F16BF-5(5A2-5A20-)5A2-2A2-A20-A2-2A514-5C20A2(5C2-5C20B)5C5(2-5A20B5A)2-5AF18BF5A2-5A-F16BF-6(5A2-5A20-)5A514-C24A2(5C2-C4A20B)5C5(2-5A20B5A)2-5AF18BF5A2-5A-F16BF-8(5A2-5A20-)5A3-3A22-3A3-2(A-)A20-2(A-)A2-2A-2A20-2A-2A2-2(A-)A20-2(A-)A3-3A22-3A3-8(5A20-5A2-)5D20-5D-E30A2(2E5A20B5A)E6A5(20B12A)F18BF12A-F16BF-8(12A20-)7AC3AC20-2(C3A)2(CA)20-2(AC)5AC2A20-2AC5A2(CA)20-2(AC)2(3AC)20-C3AC7A7(20-12A)20-6A6D20-6DE30A2(2E5A20B5A)E6A5(20B12A)F18BF12A-F16BF-21(12A20-)6A6D20-6DE30A2(2E6A18B6A)E7A18-5(14A18B)14AF16BF19(14A2-14B2-)2(14A18-)7A7D18-7DE30A2(2E7A16B7A)E8A16-6(16A16B)15A7(GB5-4B5-BG14A)12(G16BG14A)F-14B-F14A2F14-2F7A9D15-8DE30A2(2E8A14B8A)E9A14-5(18A14B)17A16B7(16AB5-4B5-B)17A11(14B18A)14B17AF14BF16AF14-F8A9D15-8DE30A2(2E9A12B9A)E10A12-6(20A12B)7(20A4-4B4-)11(20A12B)19A14B17AG14BG16AF14-F8A10D13-9DE30A2(2E10A10B10A)E11A10-6(22A10B)7(22A3-4B3-)11(22A10B)20A14B17AG14BG16AF14-F8A11D11-10DE30A2(2E11A8B11A)E12A8-6(24A8B)7(24A2-4B2-)11(24A8B)21A14H17AG14-G16AF14-F8A12D9-11D-30A2(2-11CA5B13C)2-12A6-24(12A2-12A6B)12A2-8A14H8A2-7AG14-G7A2-7AF14-F7A2-30D2-30A2(2-11C2A4B13C)2-13A4-24(13A2-13A4B)13A2-8A14H8A2-7AG14-G7A2-7AF14-F7A2-11D-7D-10D2-30A2(2-11C6A13C)26(2-30A)2-8A14G8A2-8A4FC5HC3F8A2-12D-5D-11D3-28A2(4-10C6A12C)27(4-28A)4-12AC3AC11A4-12D-3D-11D4-28A2(4-10C6A12C)27(4-28A)4-13ACAC12A4-13D-D-12D5-26A2(6-9C6A11C)27(6-26A)6-13AC12A6-13D-12D7-24A2(8-8C6A10C)27(8-24A)8-11ACAC10A8-11D-D-10D9-22A2(10-7C6A9C)27(10-22A)10-9AC3AC8A10-9D-3D-8D11-20A2(12-6C6A8C)27(12-20A)12-7AC5AC6A12-7D-5D-6D13-18A2(14-5C6A7C)27(14-18A)14-5AC7AC4A14-5D-7D-4D16-14A2(18-3C6A5C)11(18-14A)18-3AC5AC4A18-4AC3AC5A18-5ACAC6A18-6AC7A18-5ACAC6A18-4AC3AC5A18-3AC5AC4A10(18-14A)18-14D21-3(7E25-)10(7A25-)7A26-5A26-A-3A-A25-2A-A-2A25-3A-3A25-2A-A-2A25-A-3A-A26-5A26-10(7A25-)7D13-
