model
size = 31 32 31, scale = 0.05, origin = -y
material 
  colors = A:#444 B:#555
voxels
12-2(7A24-)7A920-2(3A7-3A18-)3A7-3A21-7B2(24-7A)825-2(2A13-2A14-)2A13-2A16-3B7-3B2(18-3A7-3A)21-2(7A24-)7A731-2(A17-A12-)A17-A2(13-2B)2(14-2A13-2A)16-2(3A7-3A18-)3A7-3A21-7B2(24-7A)637-2(A19-A10-)A19-A11-B17-B12-A17-A12-2A15-2A14-2(A13-A16-)2A11-2A18-2B7-2B2(20-2A7-2A)22-3(7B24-)7B512-2(A21-A8-)A21-A9-B19-B2(10-A19-A)11-2(2A15-2A12-)2A15-2A14-2B11-2B2(16-2A11-2A)18-3(2B7-2B20-)2B7-2B22-4(7A24-)7A356-2(A23-A6-)A23-A7-B21-B2(8-A21-A)9-2(A19-A10-)2A17-2A12-B15-B2(14-A15-A)15-3(2B11-2B16-)2B11-2B18-4(2A7-2A20-)2A7-2A22-5(7B24-)7B169-2(A25-A4-)A25-A5-B23-B6-A23-A6-2A21-2A8-2(A19-A10-)A19-A11-B17-B2(12-A17-A)13-3(B15-B14-)2B13-2B16-4(A11-A18-)A11-A19-5(2B7-2B20-)3B5-3B23-4(5A26-)5A15-2(A25-A4-)A25-A5-B23-B2(6-A23-A)7-2(A21-A8-)A21-A9-B19-B2(10-A19-A)11-3(B17-B12-)2B15-2B14-4(A13-A16-)A13-A17-5(B11-B18-)2B9-2B20-4(2A5-2A22-)2A5-2A12-2(A27-A2-)A27-A3-B25-B2(4-A25-A)5-2(A23-A6-)2A21-2A8-B19-B2(10-A19-A)11-3(B17-B12-)B17-B13-4(A15-A14-)2(A15-)5(B13-B16-)B13-B17-4(2A9-2A18-)2A9-2A10-2(A27-A2-)A27-A3-B25-B2(4-A25-A)5-2(A23-A6-)A23-A7-B21-B2(8-A21-A)9-3(B19-B10-)B19-B11-4(A17-A12-)A17-A13-5(B15-B14-)2B13-2B16-4(A11-A18-)A11-A10-2(A27-A2-)A27-A3-B25-B2(4-A25-A)5-2(A23-A6-)A23-A7-B21-B2(8-A21-A)9-3(B19-B10-)B19-B11-4(A17-A12-)A17-A13-5(B15-B14-)2(B15-)4(A13-A16-)A13-A8-A2(29-2A)29-A-B27-B2(2-A27-A)3-2(A25-A4-)A25-A5-B23-B2(6-A23-A)7-3(B21-B8-)B21-B9-4(A19-A10-)A19-A11-5(B17-B12-)2B15-2B14-4(A13-A16-)A13-A8-5(A2(29-2A)29-A-B27-B2(2-A27-A)3-2(A25-A4-)A25-A5-B23-B2(6-A23-A)7-3(B21-B8-)B21-B9-4(A19-A10-)A19-A11-5(B17-B12-)B17-B13-4(A15-A14-)A15-A7-)A2(29-2A)29-A-B27-B2(2-A27-A)3-2(A25-A4-)A25-A5-B23-B2(6-A23-A)7-3(B21-B8-)B21-B9-4(A19-A10-)A19-A11-5(B17-B12-)2B15-2B14-4(A13-A16-)A13-A9-2(A27-A2-)A27-A3-B25-B2(4-A25-A)5-2(A23-A6-)A23-A7-B21-B2(8-A21-A)9-3(B19-B10-)B19-B11-4(A17-A12-)A17-A13-5(B15-B14-)2(B15-)4(A13-A16-)A13-A9-2(A27-A2-)A27-A3-B25-B2(4-A25-A)5-2(A23-A6-)A23-A7-B21-B2(8-A21-A)9-3(B19-B10-)B19-B11-4(A17-A12-)A17-A13-5(B15-B14-)2B13-2B16-4(A11-A18-)A11-A10-2(A27-A2-)A27-A3-B25-B2(4-A25-A)5-2(A23-A6-)2A21-2A8-B19-B2(10-A19-A)11-3(B17-B12-)B17-B13-4(A15-A14-)2(A15-)5(B13-B16-)B13-B17-4(2A9-2A18-)2A9-2A11-2(A25-A4-)A25-A5-B23-B2(6-A23-A)7-2(A21-A8-)A21-A9-B19-B2(10-A19-A)11-3(B17-B12-)2B15-2B14-4(A13-A16-)A13-A17-5(B11-B18-)2B9-2B20-4(2A5-2A22-)2A5-2A13-2(A25-A4-)A25-A5-B23-B6-A23-A6-2A21-2A8-2(A19-A10-)A19-A11-B17-B2(12-A17-A)13-3(B15-B14-)2B13-2B16-4(A11-A18-)A11-A19-5(2B7-2B20-)3B5-3B23-4(5A26-)5A16-2(A23-A6-)A23-A7-B21-B2(8-A21-A)9-2(A19-A10-)2A17-2A12-B15-B2(14-A15-A)15-3(2B11-2B16-)2B11-2B18-4(2A7-2A20-)2A7-2A22-5(7B24-)7B171-2(A21-A8-)A21-A9-B19-B2(10-A19-A)11-2(2A15-2A12-)2A15-2A14-2B11-2B2(16-2A11-2A)18-3(2B7-2B20-)2B7-2B22-4(7A24-)7A358-2(A19-A10-)A19-A11-B17-B12-A17-A12-2A15-2A14-2(A13-A16-)2A11-2A18-2B7-2B2(20-2A7-2A)22-3(7B24-)7B514-2(A17-A12-)A17-A2(13-2B)2(14-2A13-2A)16-2(3A7-3A18-)3A7-3A21-7B2(24-7A)639-2(2A13-2A14-)2A13-2A16-3B7-3B2(18-3A7-3A)21-2(7A24-)7A734-2(3A7-3A18-)3A7-3A21-7B2(24-7A)830-2(7A24-)7A911-
