model
size = 21 31 21, scale = 0.05, origin = -y
material 
  colors = A:#777
voxels
--------------------- --------------------- --------------------- --------------------- --------------------- --------------------- --------------------- --------------------- --------------------- --------------------- --------------------- --------------------- --------------------- --------------------- --------------------- --------------------- --------------------- ------AAAAAAAAA------ ------AAAAAAAAA------ ------AAAAAAAAA------ ------AAAAAAAAA------ ------AAAAAAAAA------ ------AAAAAAAAA------ ------AAAAAAAAA------ ------AAAAAAAAA------ ------AAAAAAAAA------ --------------------- --------------------- --------------------- --------------------- --------------------- 
--------------------- --------------------- --------------------- --------------------- --------------------- --------------------- --------------------- --------------------- --------------------- --------------------- --------------------- -------AAAAAAA------- -------AAAAAAA------- -------AAAAAAA------- -------AAAAAAA------- -------AAAAAAA------- -------AAAAAAA------- ----AAA-------AA----- ----AA--------AA----- ----AA--------AA----- ----AA--------AA----- ----AA--------AA----- ----AAAAAAAAAAAA----- ----AAAAAAAAAAAA----- ----AAAAAAAAAAAA----- ----AAAAAAAAAAAA----- --------------------- --------------------- --------------------- --------------------- --------------------- 
--------------------- --------------------- --------------------- --------------------- --------AAAAA-------- --------AAAAA-------- --------AAAAA-------- --------AAAAA-------- --------AAAAA-------- --------AAAAA-------- --------AAAAA-------- -----AAA-----AAA----- -----AA-------AA----- -----AA-------AA----- -----AA-------AA----- -----AA-------AA----- -----AA-------AA----- ---AA-----------A---- ---A------------A---- ---A------------A---- ---A------------A---- ---A------------A---- ---A------------A---- ---AAAAAAAAAAAAAA---- ---AAAAAAAAAAAAAA---- ---AAAAAAAAAAAAAA---- ---AAAAAAAAAAAAA----- --------------------- --------------------- --------------------- --------------------- 
--------AAAAA-------- --------AAAAA-------- --------AAAAA-------- --------AAAAA-------- ------AA-----AA------ ------AA-----AA------ ------AA-----AA------ ------AA-----AA------ ------AA-----AA------ ------AA-----AA------ ------AA-----AA------ ----AA---------AA---- ----A-----------A---- ----A-----------A---- ----A-----------A---- ----A-----------A---- ----A-----------A---- --AA-------------A--- --A--------------A--- --A--------------A--- --A--------------A--- --A--------------A--- --A--------------A--- --AAAAAAAAAAAA---A--- --AAAAAAAAAAAA---A--- --AAAAAAAAAAAA---A--- --AAAAAAAAAAAA--AA--- ---AAAAAAAAAAAAAAA--- --------------------- --------------------- --------------------- 
------AA-----AA------ ------AA-----AA------ ------AA-----AA------ ------AA-----AA------ ----AA---------AA---- ----AA---------AA---- ----AA---------AA---- ----AA---------AA---- ----AA---------AA---- ----AA---------AA---- ----AA---------AA---- ---A-------------A--- ---A-------------A--- ---A-------------A--- ---A-------------A--- ---A-------------A--- ---A-------------A--- -AA---------------A-- -A----------------A-- -A----------------A-- -A----------------A-- -A----------------A-- -A----------------A-- -AA----------A----A-- -AA----------A----A-- -AA----------A----A-- -AA----------A----A-- -AA----------A----A-- -AAAAAAAAAAAAAAAAAA-- --------------------- --------------------- 
-----A---------A----- -----A---------A----- -----A---------A----- -----A---------A----- ----A-----------A---- ----A-----------A---- ----A-----------A---- ----A-----------A---- ----A-----------A---- ----A-----------A---- ----A-----------A---- --AA-------------AA-- --A---------------A-- --A---------------A-- --A---------------A-- --A---------------A-- --A---------------A-- -A-----------------A- -A-----------------A- -A-----------------A- -A-----------------A- -A-----------------A- -------------------A- -------------AAAAAAA- -------------AAAAAAA- -------------AAAAAAA- -------------AAAAAAA- -------------AAAAAA-- -AAAAAAAAAAAAAAAAAA-- --------------------- --------------------- 
----A-----------A---- ----A-----------A---- ----A-----------A---- ----A-----------A---- ---A-------------A--- ---A-------------A--- ---A-------------A--- ---A-------------A--- ---A-------------A--- ---A-------------A--- ---A-------------A--- --A---------------A-- --A---------------A-- --A---------------A-- --A---------------A-- --A---------------A-- --A---------------A-- -A-----------------A- -A-----------------A- -A-----------------A- -A-----------------A- -A-----------------A- -------------------A- -------------------A- -------------------A- -------------------A- -------------------A- -------------------A- -------------------A- -AAAAAAAAAAAAAAAAAAAA --------------------- 
----A-----------A---- ----A-----------A---- ----A-----------A---- ----A-----------A---- ---A-------------A--- ---A-------------A--- ---A-------------A--- ---A-------------A--- ---A-------------A--- ---A-------------A--- ---A-------------A--- -AA---------------AA- -A-----------------A- -A-----------------A- -A-----------------A- -A-----------------A- -A-----------------A- A-------------------A A-------------------A A-------------------A A-------------------A A-------------------A --------------------- --------------------- --------------------- --------------------- --------------------- --------------------- --------------------- -AAAAAA-------AAAAAAA --------------------- 
---A-------------A--- ---A-------------A--- ---A-------------A--- ---A-------------A--- --A---------------A-- --A---------------A-- --A---------------A-- --A---------------A-- --A---------------A-- --A---------------A-- --A---------------A-- -A-----------------A- -A-----------------A- -A-----------------A- -A-----------------A- -A-----------------A- -A-----------------A- A-------------------A A-------------------A A-------------------A A-------------------A --------------------- --------------------- --------------------- --------------------- --------------------- --------------------- --------------------- --------------------- --------------------- -AAAAA---------AAAAAA 
---A-------------A--- ---A-------------A--- ---A-------------A--- ---A-------------A--- --A---------------A-- --A---------------A-- --A---------------A-- --A---------------A-- --A---------------A-- --A---------------A-- --A---------------A-- -A-----------------A- -A-----------------A- -A-----------------A- -A-----------------A- -A-----------------A- -A-----------------A- A-------------------A A-------------------A A-------------------A --------------------- --------------------- --------------------- --------------------- --------------------- --------------------- --------------------- --------------------- --------------------- --------------------- -AAAA-----------AAAAA 
---A-------------A--- ---A-------------A--- ---A-------------A--- ---A-------------A--- --A---------------A-- --A---------------A-- --A---------------A-- --A---------------A-- --A---------------A-- --A---------------A-- --A---------------A-- -A-----------------A- -A-----------------A- -A-----------------A- -A-----------------A- -A-----------------A- -A-----------------A- A-------------------A A-------------------A --------------------- --------------------- --------------------- --------------------- --------------------- --------------------- --------------------- --------------------- --------------------- --------------------- --------------------- -AAAA-----------AAAAA 
---A-------------A--- ---A-------------A--- ---A-------------A--- ---A-------------A--- --A---------------A-- --A---------------A-- --A---------------A-- --A---------------A-- --A---------------A-- --A---------------A-- --A---------------A-- -A-----------------A- -A-----------------A- -A-----------------A- -A-----------------A- -A-----------------A- -A-----------------A- A-------------------A A-------------------A A-------------------A --------------------- --------------------- --------------------- --------------------- --------------------- --------------------- --------------------- --------------------- --------------------- --------------------- -AAAA-----------AAAAA 
---A-------------A--- ---A-------------A--- ---A-------------A--- ---A-------------A--- --A---------------A-- --A---------------A-- --A---------------A-- --A---------------A-- --A---------------A-- --A---------------A-- --A---------------A-- -A-----------------A- -A-----------------A- -A-----------------A- -A-----------------A- -A-----------------A- -A-----------------A- A-------------------A A-------------------A A-------------------A A-------------------A --------------------- --------------------- --------------------- --------------------- --------------------- --------------------- --------------------- --------------------- --------------------- -AAAAA---------AAAAAA 
----A-----------A---- ----A-----------A---- ----A-----------A---- ----A-----------A---- ---A-------------A--- ---A-------------A--- ---A-------------A--- ---A-------------A--- ---A-------------A--- ---A-------------A--- ---A-------------A--- -AA---------------AA- -A-----------------A- -A-----------------A- -A-----------------A- -A-----------------A- -A-----------------A- A-------------------A A-------------------A A-------------------A A-------------------A A-------------------A --------------------- --------------------- --------------------- --------------------- --------------------- --------------------- --------------------- -AAAAAA-------AAAAAAA --------------------- 
----A-----------A---- ----A-----------A---- ----A-----------A---- ----A-----------A---- ---A-------------A--- ---A-------------A--- ---A-------------A--- ---A-------------A--- ---A-------------A--- ---A-------------A--- ---A-------------A--- --A---------------A-- --A---------------A-- --A---------------A-- --A---------------A-- --A---------------A-- --A---------------A-- -------------------A- -------------------A- -------------------A- -------------------A- -------------------A- --------------------- --------------------- --------------------- --------------------- --------------------- --------------------- --------------------- -AAAAAAA-----AAAAAAAA --------------------- 
-----A---------A----- -----A---------A----- -----A---------A----- -----A---------A----- ----A-----------A---- ----A-----------A---- ----A-----------A---- ----A-----------A---- ----A-----------A---- ----A-----------A---- ----A-----------A---- --AA-------------AA-- --A---------------A-- --A---------------A-- --A---------------A-- --A---------------A-- --A---------------A-- -------------------A- -------------------A- -------------------A- -------------------A- -------------------A- -------------------A- -------------------A- -------------------A- -------------------A- -------------------A- -------------------A- --AAAAAAAAAAAAAAAAAA- --------------------- --------------------- 
------AA-----AA------ ------AA-----AA------ ------AA-----AA------ ------AA-----AA------ ----AA---------AA---- ----AA---------AA---- ----AA---------AA---- ----AA---------AA---- ----AA---------AA---- ----AA---------AA---- ----AA---------AA---- ---A-------------A--- ---A-------------A--- ---A-------------A--- ---A-------------A--- ---A-------------A--- ---A-------------A--- --A---------------A-- --A---------------A-- --A---------------A-- --A---------------A-- --A---------------A-- --A---------------A-- --A---------------A-- --A---------------A-- --A---------------A-- --A---------------A-- --A---------------AA- --AAAAAAAAAAAAAAAAAA- --------------------- --------------------- 
--------AAAAA-------- --------AAAAA-------- --------AAAAA-------- --------AAAAA-------- ------AA-----AA------ ------AA-----AA------ ------AA-----AA------ ------AA-----AA------ ------AA-----AA------ ------AA-----AA------ ------AA-----AA------ ----AA---------AA---- ----A-----------A---- ----A-----------A---- ----A-----------A---- ----A-----------A---- ----A-----------A---- ---AA------------A--- ---AA------------A--- ---AA------------A--- ---AA------------A--- ---AA------------A--- ---AA------------A--- ---AAAAAAAAAAAAAAA--- ---AAAAAAAAAAAAAAA--- ---AAAAAAAAAAAAAAA--- ---AAAAAAAAAAAAAAA--- --AAAAAAAAAAAAAAAAA-- --------------------- --------------------- --------------------- 
--------------------- --------------------- --------------------- --------------------- --------AAAAA-------- --------AAAAA-------- --------AAAAA-------- --------AAAAA-------- --------AAAAA-------- --------AAAAA-------- --------AAAAA-------- -----AAA-----AAA----- -----AA-------AA----- -----AA-------AA----- -----AA-------AA----- -----AA-------AA----- -----AA-------AA----- -----A----------A---- -----A----------A---- -----A----------A---- -----A----------A---- -----A----------A---- -----AA---------A---- -----AAAAAAAAAAAA---- ----AAAAAAAAAAAAA---- ----AAAAAAAAAAAAAA--- ----AAAAAAAAAAAAAA--- --------------------- --------------------- --------------------- --------------------- 
--------------------- --------------------- --------------------- --------------------- --------------------- --------------------- --------------------- --------------------- --------------------- --------------------- --------------------- -------AAAAAAA------- -------AAAAAAA------- -------AAAAAAA------- -------AAAAAAA------- -------AAAAAAA------- -------AAAAAAA------- -----AAAAAAAAAAA----- -----AAAAAAAAAAA----- -----AAAAAAAAAAA----- -----AAAAAAAAAAA----- -----AAAAAAAAAAA----- -----AAAAAAAAAAA----- -----AAAAAAAAAAA----- -----AAAAAAAAAAA----- -----AAAAAAAAAAA----- --------------------- --------------------- --------------------- --------------------- --------------------- 
--------------------- --------------------- --------------------- --------------------- --------------------- --------------------- --------------------- --------------------- --------------------- --------------------- --------------------- --------------------- --------------------- --------------------- --------------------- --------------------- --------------------- ------AAAAAAAA------- ------AAAAAAAA------- ------AAAAAAAA------- ------AAAAAAAA------- ------AAAAAAAA------- ------AAAAAAAA------- ------AAAAAAAA------- ------AAA---AA------- ------AAA---AA------- --------------------- --------------------- --------------------- --------------------- --------------------- 
