model
size = 30 10 30, scale = 0.05, origin = -y
material 
  colors = A:#111 B:#FF6
voxels
----------AAAAAAAAAA---------- ------------------------------ ------------------------------ ------------------------------ ------------------------------ ------------------------------ ------------------------------ ------------------------------ ------------------------------ ------------------------------ 
--------AAAAAAAAAAAAAA-------- ------------------------------ ------------------------------ ------------------------------ ------------------------------ ------------------------------ ------------------------------ ------------------------------ ------------------------------ ------------------------------ 
------AAAAAAAAAAAAAAAAAA------ ------------------------------ ------------------------------ ------------------------------ ------------------------------ ------------------------------ ------------------------------ ------------------------------ ------------------------------ ------------AAAAAA------------ 
-----AAAAAAAAAAAAAAAAAAAA----- ------------------------------ ------------------------------ ------------------------------ ------------------------------ ------------------------------ ------------------------------ -------------AAAA------------- -----------AAAAAAAA----------- ---------AAAAAAAAAAAA--------- 
----AAAAAAAAAAAAAAAAAAAAAA---- ------------------------------ ------------------------------ ------------------------------ ------------------------------ -------------AAAA------------- -----------AAAAAAAA----------- ----------AAA----AAA---------- ---------AA--------AA--------- --------AAAAAAAAAAAAAA-------- 
---AAAAAAAAAAAAAAAAAAAAAAAA--- ------------------------------ ------------------------------ -------------AAAA------------- -----------AAAAAAAA----------- ----------AAA----AAA---------- ---------AA--------AA--------- --------AA----------AA-------- -------AA------------AA------- ------AAAAAAAAAAAAAAAAAA------ 
--AAAAAAAAAAAAAAAAAAAAAAAAAA-- -------------BBBB------------- -----------AAAAAAAA----------- ----------AAA----AAA---------- ---------AA--------AA--------- --------AA----------AA-------- --------A------------A-------- -------A--------------A------- ------A----------------A------ -----AAAAAAAAAAAAAAAAAAAA----- 
--AAAAAAAAAAA----AAAAAAAAAAA-- ----------BBB----BBB---------- ----------A--------A---------- ---------A----------A--------- --------A------------A-------- -------A--------------A------- -------A--------------A------- ------A----------------A------ -----A------------------A----- -----AAAAAAAAAAAAAAAAAAAA----- 
-AAAAAAAAA----------AAAAAAAAA- ---------B----------B--------- --------AA----------AA-------- --------A------------A-------- -------A--------------A------- ------A----------------A------ ------A----------------A------ -----A------------------A----- -----A------------------A----- ----AAAAAAAAAAAAAAAAAAAAAA---- 
-AAAAAAAA------------AAAAAAAA- --------B------------B-------- --------A------------A-------- -------A--------------A------- ------A----------------A------ ------A----------------A------ -----A------------------A----- -----A------------------A----- ----A--------------------A---- ---AAAAAAAAAAAAAAAAAAAAAAAA--- 
AAAAAAAA--------------AAAAAAAA -------B--------------B------- -------A--------------A------- ------A----------------A------ ------A----------------A------ -----A------------------A----- -----A------------------A----- ----A--------------------A---- ----A--------------------A---- ---AAAAAAAAAAAAAAAAAAAAAAAA--- 
AAAAAAAA--------------AAAAAAAA -------B--------------B------- ------A----------------A------ ------A----------------A------ -----A------------------A----- -----A------------------A----- ----A--------------------A---- ----A--------------------A---- ---A----------------------A--- ---AAAAAAAAAAAAAAAAAAAAAAAA--- 
AAAAAAAA--------------AAAAAAAA -------B--------------B------- ------A----------------A------ ------A----------------A------ -----A------------------A----- -----A------------------A----- ----A--------------------A---- ----A--------------------A---- ---A----------------------A--- --AAAAAAAAAAAAAAAAAAAAAAAAAA-- 
AAAAAAA----------------AAAAAAA ------B----------------B------ ------A----------------A------ -----A------------------A----- -----A------------------A----- ----A--------------------A---- ----A--------------------A---- ---A----------------------A--- ---A----------------------A--- --AAAAAAAAAAAAAAAAAAAAAAAAAA-- 
AAAAAAA----------------AAAAAAA ------B----------------B------ ------A----------------A------ -----A------------------A----- -----A------------------A----- ----A--------------------A---- ----A--------------------A---- ---A----------------------A--- ---A----------------------A--- --AAAAAAAAAAAAAAAAAAAAAAAAAA-- 
AAAAAAA----------------AAAAAAA ------B----------------B------ ------A----------------A------ -----A------------------A----- -----A------------------A----- ----A--------------------A---- ----A--------------------A---- ---A----------------------A--- ---A----------------------A--- --AAAAAAAAAAAAAAAAAAAAAAAAAA-- 
AAAAAAA----------------AAAAAAA ------B----------------B------ ------A----------------A------ -----A------------------A----- -----A------------------A----- ----A--------------------A---- ----A--------------------A---- ---A----------------------A--- ---A----------------------A--- --AAAAAAAAAAAAAAAAAAAAAAAAAA-- 
AAAAAAAA--------------AAAAAAAA -------B--------------B------- ------A----------------A------ ------A----------------A------ -----A------------------A----- -----A------------------A----- ----A--------------------A---- ----A--------------------A---- ---A----------------------A--- --AAAAAAAAAAAAAAAAAAAAAAAAAA-- 
AAAAAAAA--------------AAAAAAAA -------B--------------B------- ------A----------------A------ ------A----------------A------ -----A------------------A----- -----A------------------A----- ----A--------------------A---- ----A--------------------A---- ---A----------------------A--- ---AAAAAAAAAAAAAAAAAAAAAAAA--- 
AAAAAAAA--------------AAAAAAAA -------B--------------B------- -------A--------------A------- ------A----------------A------ ------A----------------A------ -----A------------------A----- -----A------------------A----- ----A--------------------A---- ----A--------------------A---- ---AAAAAAAAAAAAAAAAAAAAAAAA--- 
-AAAAAAAA------------AAAAAAAA- --------B------------B-------- --------A------------A-------- -------A--------------A------- ------A----------------A------ ------A----------------A------ -----A------------------A----- -----A------------------A----- ----A--------------------A---- ---AAAAAAAAAAAAAAAAAAAAAAAA--- 
-AAAAAAAAA----------AAAAAAAAA- ---------B----------B--------- --------AA----------AA-------- --------A------------A-------- -------A--------------A------- ------A----------------A------ ------A----------------A------ -----A------------------A----- -----A------------------A----- ----AAAAAAAAAAAAAAAAAAAAAA---- 
--AAAAAAAAAAA----AAAAAAAAAAA-- ----------BBB----BBB---------- ----------A--------A---------- ---------A----------A--------- --------A------------A-------- -------A--------------A------- -------A--------------A------- ------A----------------A------ -----A------------------A----- -----AAAAAAAAAAAAAAAAAAAA----- 
--AAAAAAAAAAAAAAAAAAAAAAAAAA-- -------------BBBB------------- -----------AAAAAAAA----------- ----------AAA----AAA---------- ---------AA--------AA--------- --------AA----------AA-------- --------A------------A-------- -------A--------------A------- ------A----------------A------ -----AAAAAAAAAAAAAAAAAAAA----- 
---AAAAAAAAAAAAAAAAAAAAAAAA--- ------------------------------ ------------------------------ -------------AAAA------------- -----------AAAAAAAA----------- ----------AAA----AAA---------- ---------AA--------AA--------- --------AA----------AA-------- -------AA------------AA------- ------AAAAAAAAAAAAAAAAAA------ 
----AAAAAAAAAAAAAAAAAAAAAA---- ------------------------------ ------------------------------ ------------------------------ ------------------------------ -------------AAAA------------- -----------AAAAAAAA----------- ----------AAA----AAA---------- ---------AA--------AA--------- --------AAAAAAAAAAAAAA-------- 
-----AAAAAAAAAAAAAAAAAAAA----- ------------------------------ ------------------------------ ------------------------------ ------------------------------ ------------------------------ ------------------------------ -------------AAAA------------- -----------AAAAAAAA----------- ---------AAAAAAAAAAAA--------- 
------AAAAAAAAAAAAAAAAAA------ ------------------------------ ------------------------------ ------------------------------ ------------------------------ ------------------------------ ------------------------------ ------------------------------ ------------------------------ ------------AAAAAA------------ 
--------AAAAAAAAAAAAAA-------- ------------------------------ ------------------------------ ------------------------------ ------------------------------ ------------------------------ ------------------------------ ------------------------------ ------------------------------ ------------------------------ 
----------AAAAAAAAAA---------- ------------------------------ ------------------------------ ------------------------------ ------------------------------ ------------------------------ ------------------------------ ------------------------------ ------------------------------ ------------------------------ 
