model
size = 28 30 31, scale = 0.05, origin = -y
material 
  colors = A:#777
voxels
---------------------------- ---------------------------- ---------------------------- ----A------------------A---- ---A--------------------A--- --A----------------------A-- -A------------------------A- -A------------------------A- A--------------------------A A--------------------------A A--------------------------A A--------------------------A A--------------------------A A--------------------------A A--------------------------A A--------------------------A A--------------------------A A--------------------------A A--------------------------A A--------------------------A A--------------------------A A--------------------------A -A------------------------A- -A------------------------A- --A----------------------A-- ---A--------------------A--- ----A------------------A---- -----AA--------------AA----- -------AA----------AA------- ---------AAAAAAAAAA--------- 
---------------------------- ---------------------------- ---------------------------- -----A----------------A----- ----A------------------A---- ---A--------------------A--- --A----------------------A-- -A------------------------A- -A------------------------A- A--------------------------A A--------------------------A A--------------------------A A--------------------------A A--------------------------A A--------------------------A A--------------------------A A--------------------------A A--------------------------A A--------------------------A A--------------------------A A--------------------------A -A------------------------A- -A------------------------A- --A----------------------A-- ---A--------------------A--- ----A------------------A---- -----A----------------A----- ------AA------------AA------ --------AAA------AAA-------- -----------AAAAAA----------- 
---------------------------- ---------------------------- ---------------------------- ---------------------------- ----AA----------------AA---- ---A--------------------A--- ---A--------------------A--- --A----------------------A-- -A------------------------A- -A------------------------A- A--------------------------A A--------------------------A A--------------------------A A--------------------------A A--------------------------A A--------------------------A A--------------------------A A--------------------------A A--------------------------A A--------------------------A -A------------------------A- -A------------------------A- --A----------------------A-- ---A--------------------A--- ---A--------------------A--- ----AA----------------AA---- ------A--------------A------ -------AA----------AA------- ---------AAAAAAAAAA--------- ---------------------------- 
---------------------------- ---------------------------- ---------------------------- ---------------------------- -----A----------------A----- ----A------------------A---- ---A--------------------A--- --A----------------------A-- --A----------------------A-- -A------------------------A- -A------------------------A- -A------------------------A- A--------------------------A A--------------------------A A--------------------------A A--------------------------A A--------------------------A A--------------------------A -A------------------------A- -A------------------------A- -A------------------------A- --A----------------------A-- --A----------------------A-- ---A--------------------A--- ----A------------------A---- -----A----------------A----- ------AA------------AA------ --------AAA------AAA-------- -----------AAAAAA----------- ---------------------------- 
---------------------------- ---------------------------- ---------------------------- ---------------------------- ------A--------------A------ -----A----------------A----- ----A------------------A---- ---A--------------------A--- --A----------------------A-- --A----------------------A-- --A----------------------A-- -A------------------------A- -A------------------------A- -A------------------------A- -A------------------------A- -A------------------------A- -A------------------------A- -A------------------------A- -A------------------------A- --A----------------------A-- --A----------------------A-- --A----------------------A-- ---A--------------------A--- ----A------------------A---- -----A----------------A----- ------A--------------A------ -------AAA--------AAA------- ----------AAAAAAAA---------- ---------------------------- ---------------------------- 
---------------------------- ---------------------------- ---------------------------- ---------------------------- ---------------------------- -----AA--------------AA----- ----A------------------A---- ----A------------------A---- ---A--------------------A--- --A----------------------A-- --A----------------------A-- --A----------------------A-- -A------------------------A- -A------------------------A- -A------------------------A- -A------------------------A- -A------------------------A- -A------------------------A- --A----------------------A-- --A----------------------A-- --A----------------------A-- ---A--------------------A--- ----A------------------A---- ----A------------------A---- -----AA--------------AA----- -------A------------A------- --------AAA------AAA-------- -----------AAAAAA----------- ---------------------------- ---------------------------- 
---------------------------- ---------------------------- ---------------------------- ---------------------------- ---------------------------- ------AA------------AA------ -----A----------------A----- ----A------------------A---- ----A------------------A---- ---A--------------------A--- ---A--------------------A--- --A----------------------A-- --A----------------------A-- --A----------------------A-- --A----------------------A-- --A----------------------A-- --A----------------------A-- --A----------------------A-- --A----------------------A-- ---A--------------------A--- ---A--------------------A--- ----A------------------A---- ----A------------------A---- -----A----------------A----- ------AA------------AA------ --------AA--------AA-------- ----------AAAAAAAA---------- ---------------------------- ---------------------------- ---------------------------- 
---------------------------- ---------------------------- ---------------------------- ---------------------------- ---------------------------- -------AA----------AA------- ------A--------------A------ -----A----------------A----- ----A------------------A---- ----A------------------A---- ---A--------------------A--- ---A--------------------A--- ---A--------------------A--- --A----------------------A-- --A----------------------A-- --A----------------------A-- --A----------------------A-- ---A--------------------A--- ---A--------------------A--- ---A--------------------A--- ----A------------------A---- ----A------------------A---- -----A----------------A----- ------A--------------A------ -------AA----------AA------- ---------AAA----AAA--------- ------------AAAA------------ ---------------------------- ---------------------------- ---------------------------- 
---------------------------- ---------------------------- ---------------------------- ---------------------------- ---------------------------- --------AA--------AA-------- -------A------------A------- ------A--------------A------ -----A----------------A----- ----A------------------A---- ----A------------------A---- ---A--------------------A--- ---A--------------------A--- ---A--------------------A--- ---A--------------------A--- ---A--------------------A--- ---A--------------------A--- ---A--------------------A--- ---A--------------------A--- ----A------------------A---- ----A------------------A---- -----A----------------A----- ------A--------------A------ -------A------------A------- --------AA--------AA-------- ----------AAAAAAAA---------- ---------------------------- ---------------------------- ---------------------------- ---------------------------- 
---------------------------- ---------------------------- ---------------------------- ---------------------------- ---------------------------- ---------AA------AA--------- -------AA----------AA------- ------A--------------A------ -----A----------------A----- -----A----------------A----- ----A------------------A---- ----A------------------A---- ----A------------------A---- ---A--------------------A--- ---A--------------------A--- ---A--------------------A--- ---A--------------------A--- ----A------------------A---- ----A------------------A---- ----A------------------A---- -----A----------------A----- -----A----------------A----- ------A--------------A------ -------AA----------AA------- ---------AAA----AAA--------- ------------AAAA------------ ---------------------------- ---------------------------- ---------------------------- ---------------------------- 
---------------------------- ---------------------------- ---------------------------- ---------------------------- ---------------------------- ----------AA----AA---------- --------AA--------AA-------- -------A------------A------- ------A--------------A------ -----A----------------A----- -----A----------------A----- ----A------------------A---- ----A------------------A---- ----A------------------A---- ----A------------------A---- ----A------------------A---- ----A------------------A---- ----A------------------A---- ----A------------------A---- -----A----------------A----- -----A----------------A----- ------A--------------A------ -------A------------A------- --------AA--------AA-------- ----------AAAAAAAA---------- ---------------------------- ---------------------------- ---------------------------- ---------------------------- ---------------------------- 
---------------------------- ---------------------------- ---------------------------- ---------------------------- ---------------------------- ------------AAAA------------ ---------AAA----AAA--------- --------A----------A-------- -------A------------A------- ------A--------------A------ -----A----------------A----- -----A----------------A----- -----A----------------A----- ----A------------------A---- ----A------------------A---- ----A------------------A---- ----A------------------A---- -----A----------------A----- -----A----------------A----- -----A----------------A----- ------A--------------A------ -------A------------A------- --------A----------A-------- ---------AAA----AAA--------- ------------AAAA------------ ---------------------------- ---------------------------- ---------------------------- ---------------------------- ---------------------------- 
---------------------------- ---------------------------- ---------------------------- ---------------------------- ---------------------------- ---------------------------- ----------AAAAAAAA---------- ---------A--------A--------- -------AA----------AA------- -------A------------A------- ------A--------------A------ -----A----------------A----- -----A----------------A----- -----A----------------A----- -----A----------------A----- -----A----------------A----- -----A----------------A----- -----A----------------A----- -----A----------------A----- ------A--------------A------ -------A------------A------- -------AA----------AA------- ---------A--------A--------- ----------AAAAAAAA---------- ---------------------------- ---------------------------- ---------------------------- ---------------------------- ---------------------------- ---------------------------- 
---------------------------- ---------------------------- ---------------------------- ---------------------------- ---------------------------- ---------------------------- ------------AAAA------------ ---------AAA----AAA--------- --------A----------A-------- -------A------------A------- ------A--------------A------ ------A--------------A------ ------A--------------A------ -----A----------------A----- -----A----------------A----- -----A----------------A----- -----AA--------------AA----- ------A--------------A------ ------AA------------AA------ ------AAA----------AAA------ -------AAAA------AAAA------- --------AAAAAAAAAAAA-------- ---------AAAAAAAAAA--------- ------------AAAA------------ ---------------------------- ---------------------------- ---------------------------- ---------------------------- ---------------------------- ---------------------------- 
---------------------------- ---------------------------- ---------------------------- ---------------------------- ---------------------------- -----------AAAAAA----------- ---------AAA----AAA--------- --------A----------A-------- -------A------------A------- -------A------------A------- ------A--------------A------ ------A--------------A------ ------A--------------A------ ------A--------------A------ ------A--------------A------ ------A--------------A------ -------A------------A------- -------A------------A------- --------A----------A-------- ---------AA------AA--------- -----------AAAAAA----------- -------------AA------------- ---------------------------- ---------------------------- ---------------------------- ---------------------------- ---------------------------- ---------------------------- ---------------------------- ---------------------------- 
---------------------------- ---------------------------- ---------------------------- ---------------------------- -----------AAAAAA----------- ---------AA------AA--------- --------A----------A-------- -------A------------A------- -------A------------A------- ------A--------------A------ ------A--------------A------ ------A--------------A------ ------A--------------A------ ------A--------------A------ ------A--------------A------ -------A------------A------- -------A------------A------- --------A----------A-------- ---------AA------AA--------- -----------AAAAAA----------- ---------------------------- ---------------------------- ---------------------------- ---------------------------- ---------------------------- ---------------------------- ---------------------------- ---------------------------- ---------------------------- ---------------------------- 
---------------------------- ---------------------------- ---------------------------- ---------------------------- -----------AAAAAA----------- ---------AA------AA--------- --------A----------A-------- -------A------------A------- -------A------------A------- ------A--------------A------ ------A--------------A------ ------A--------------A------ ------A--------------A------ ------A--------------A------ ------A--------------A------ -------A------------A------- -------A------------A------- --------A----------A-------- ---------AA------AA--------- -----------AAAAAA----------- ---------------------------- ---------------------------- ---------------------------- ---------------------------- ---------------------------- ---------------------------- ---------------------------- ---------------------------- ---------------------------- ---------------------------- 
---------------------------- ---------------------------- ---------------------------- -----------AAAAAA----------- ---------AA------AA--------- --------A----------A-------- -------A------------A------- -------A------------A------- ------A--------------A------ ------A--------------A------ ------A--------------A------ ------A--------------A------ ------A--------------A------ ------A--------------A------ -------A------------A------- -------A------------A------- --------A----------A-------- ---------AA------AA--------- -----------AAAAAA----------- -------------AA------------- ---------------------------- ---------------------------- ---------------------------- ---------------------------- ---------------------------- ---------------------------- ---------------------------- ---------------------------- ---------------------------- ---------------------------- 
---------------------------- ---------------------------- ---------------------------- -----------AAAAAA----------- ---------AA------AA--------- --------A----------A-------- -------A------------A------- -------A------------A------- ------A--------------A------ ------A--------------A------ ------A--------------A------ ------A--------------A------ ------A--------------A------ ---------------------A------ -------A------------A------- -------AA----------AA------- --------AAA------AAA-------- ---------AAAAAAAAAA--------- -----------AAAAAA----------- ---------------------------- ---------------------------- ---------------------------- ---------------------------- ---------------------------- ---------------------------- ---------------------------- ---------------------------- ---------------------------- ---------------------------- ---------------------------- 
---------------------------- -----------AAAAAA----------- ---------AAAAAAAAAA--------- --------AAA------AAA-------- -------AA----------AA------- -------A------------A------- ------A--------------A------ ------A--------------A------ ------A--------------A------ ------A--------------A------ ------A--------------A------ ------A--------------A------ -------A------------A------- -------A------------A------- --------A----------A-------- ---------AA------AA--------- -----------AAAAAA----------- ------------AAA------------- ---------------------------- ---------------------------- ---------------------------- ---------------------------- ---------------------------- ---------------------------- ---------------------------- ---------------------------- ---------------------------- ---------------------------- ---------------------------- ---------------------------- 
---------------------------- -----------AAAAAA----------- ---------AA------AA--------- --------A----------A-------- -------AA-----------A------- -------A------------A------- -------A-------------------- ------AA-------------A------ ------AA-------------A------ ------AA-------------A------ ------AAA-----------AA------ -------AA-----------A------- -------AAA---------AA------- -------AAAAA-----AAAA------- --------AAAAAAAAAAAA-------- ---------AAAAAAAAAA--------- -----------AAAAAA----------- ---------------------------- ---------------------------- ---------------------------- ---------------------------- ---------------------------- ---------------------------- ---------------------------- ---------------------------- ---------------------------- ---------------------------- ---------------------------- ---------------------------- ---------------------------- 
---------------------------- ------------AAAAA----------- ----------AA-----AA--------- ---------A---------A-------- ---------A---------A-------- --------A-----------A------- --------A-----------A------- --------A-----------A------- --------A-----------A------- --------AA---------AA------- ---------AA-------AA-------- ---------AAA-----AAA-------- ----------AAAAAAAAA--------- ------------AAAAA----------- -------------AAA------------ --------------A------------- ---------------------------- ---------------------------- ---------------------------- ---------------------------- ---------------------------- ---------------------------- ---------------------------- ---------------------------- ---------------------------- ---------------------------- ---------------------------- ---------------------------- ---------------------------- ---------------------------- 
---------------------------- ------------AAAAA----------- -----------A-----A---------- ----------A-------A--------- ---------A---------A-------- ---------A---------A-------- ---------A---------A-------- ---------A---------A-------- ---------AA-------AA-------- ----------AA-----AA--------- -----------AAAAAAA---------- ------------AAAAA----------- -------------AAA------------ --------------A------------- ---------------------------- ---------------------------- ---------------------------- ---------------------------- ---------------------------- ---------------------------- ---------------------------- ---------------------------- ---------------------------- ---------------------------- ---------------------------- ---------------------------- ---------------------------- ---------------------------- ---------------------------- ---------------------------- 
---------------------------- ------------AAAAA----------- -----------A-----A---------- ----------A-------A--------- ----------A-------A--------- ----------A-------A--------- ----------AA-----AA--------- ----------AAA---AAA--------- -----------AAAAAAA---------- ------------AAAAA----------- -------------AAA------------ --------------A------------- ---------------------------- ---------------------------- ---------------------------- ---------------------------- ---------------------------- ---------------------------- ---------------------------- ---------------------------- ---------------------------- ---------------------------- ---------------------------- ---------------------------- ---------------------------- ---------------------------- ---------------------------- ---------------------------- ---------------------------- ---------------------------- 
---------------------------- -------------AAA------------ ------------A---A----------- -----------A-----A---------- -----------A-----A---------- -----------AA---AA---------- ------------AAAAA----------- -------------AAA------------ --------------A------------- --------------A------------- ---------------------------- ---------------------------- ---------------------------- ---------------------------- ---------------------------- ---------------------------- ---------------------------- ---------------------------- ---------------------------- ---------------------------- ---------------------------- ---------------------------- ---------------------------- ---------------------------- ---------------------------- ---------------------------- ---------------------------- ---------------------------- ---------------------------- ---------------------------- 
---------------------------- -------------AAA------------ ------------A---A----------- ------------A---A----------- ------------A---A----------- -------------AAA------------ --------------A------------- --------------A------------- ---------------------------- ---------------------------- ---------------------------- ---------------------------- ---------------------------- ---------------------------- ---------------------------- ---------------------------- ---------------------------- ---------------------------- ---------------------------- ---------------------------- ---------------------------- ---------------------------- ---------------------------- ---------------------------- ---------------------------- ---------------------------- ---------------------------- ---------------------------- ---------------------------- ---------------------------- 
---------------------------- ---------------------------- -------------AAA------------ -------------A-A------------ -------------AAA------------ --------------A------------- ---------------------------- ---------------------------- ---------------------------- ---------------------------- ---------------------------- ---------------------------- ---------------------------- ---------------------------- ---------------------------- ---------------------------- ---------------------------- ---------------------------- ---------------------------- ---------------------------- ---------------------------- ---------------------------- ---------------------------- ---------------------------- ---------------------------- ---------------------------- ---------------------------- ---------------------------- ---------------------------- ---------------------------- 
---------------------------- -------------AAA------------ -------------A-A------------ -------------AAA------------ --------------A------------- ---------------------------- ---------------------------- ---------------------------- ---------------------------- ---------------------------- ---------------------------- ---------------------------- ---------------------------- ---------------------------- ---------------------------- ---------------------------- ---------------------------- ---------------------------- ---------------------------- ---------------------------- ---------------------------- ---------------------------- ---------------------------- ---------------------------- ---------------------------- ---------------------------- ---------------------------- ---------------------------- ---------------------------- ---------------------------- 
---------------------------- -------------A-A------------ --------------A------------- ---------------------------- ---------------------------- ---------------------------- ---------------------------- ---------------------------- ---------------------------- ---------------------------- ---------------------------- ---------------------------- ---------------------------- ---------------------------- ---------------------------- ---------------------------- ---------------------------- ---------------------------- ---------------------------- ---------------------------- ---------------------------- ---------------------------- ---------------------------- ---------------------------- ---------------------------- ---------------------------- ---------------------------- ---------------------------- ---------------------------- ---------------------------- 
---------------------------- --------------A------------- ---------------------------- ---------------------------- ---------------------------- ---------------------------- ---------------------------- ---------------------------- ---------------------------- ---------------------------- ---------------------------- ---------------------------- ---------------------------- ---------------------------- ---------------------------- ---------------------------- ---------------------------- ---------------------------- ---------------------------- ---------------------------- ---------------------------- ---------------------------- ---------------------------- ---------------------------- ---------------------------- ---------------------------- ---------------------------- ---------------------------- ---------------------------- ---------------------------- 
--------------A------------- ---------------------------- ---------------------------- ---------------------------- ---------------------------- ---------------------------- ---------------------------- ---------------------------- ---------------------------- ---------------------------- ---------------------------- ---------------------------- ---------------------------- ---------------------------- ---------------------------- ---------------------------- ---------------------------- ---------------------------- ---------------------------- ---------------------------- ---------------------------- ---------------------------- ---------------------------- ---------------------------- ---------------------------- ---------------------------- ---------------------------- ---------------------------- ---------------------------- ---------------------------- 
