model
size = 32 32 4, scale = 0.05, origin = -y
material 
  colors = A:#FC6 B:#C90 C:#C93 D:#111 E:#FC3 F:#222 G:#FC9 H:#606 I:#FFC
voxels
173-6D21-16D15-4D2FDF3C2DF4D13-GD2A11C5D11-3G3A12CF3D10-4G3A11C2DFD10-5G3A10CDF2D10-I5G3A10C3D10-AI5G3A9C3D10-CAI5G2A10CFD10-2CAI5G2A9C2D10-3CAI5GAD8C2D10-3C2AI4G2D8C2D10-4C2AI2G2DG8CFD10-5C2AI3D2G6CF2D10-3C2DCA3D4GA4C3D10-AC8D5GA3CDFD10-2A6D2AI5GA2CF2D11-A5D2C2AIC3G2AF2D13-A3D4C2AICDF3DF15-AC2DFDF2DF3DF2D21-2(2DF)250-2F2H2F21-H4F6C4FH15-F16CH13-F6C6A6CF11-F18A2CF9-F20A2CF7-H22A2CH5-6(F24A2CF4-)H2(24A2CH4-F)4(24A2CF4-F)24A2CF4-H24A2CF5-H22A2CH7-F20A2CF9-F18A2CF11-F5C7A6CF13-H16CF15-5F6C4FH21-2F2H2F121-8A20-16A15-18A13-20A11-22A9-24A7-26A5-28A4-28A3-2(30A2-)9(29AC2-)29AC3-28A4-28A5-26A7-24A9-22A11-20A13-18A15-15A21-8A56-8E21-4E6B4E16-3E12B3E13-2E16B2E11-2E18B2E9-2E20B2E7-2E22B2E5-2E24B2E4-E26BE3-2E26B2E2(2-E28BE)-2E28B3E5(30B2E)30B3E28B2E-2(E28BE2-)2E26B2E3-E26BE4-2E24B2E5-2E22B2E7-2E20B2E9-2E18B2E11-2E16B2E13-3E12B3E16-4E6B4E21-8E12-
