model
size = 32, scale = 0.05, origin = -y
material 
  colors = A:#444 B:#383838 C:#171717 D:#222 E:#111 F:#5B5B5B G:#A60 H:#FC0 I:#FFFC7C J:#FFFA00 K:#EEE
voxels
6-F18BF12-4F12B4F15-4F6B4F21-8F888-8F16-2F20A2F8-2F20-2F943-10F14-F3A18B3AF6-F24-F940-14F11-F2A22B2AF4-F9-8E9-F14-4(8C24-)8E728-8D24-8D19-18F8-F3A22B3AF2-F8-12E8-F11-4(12C20-)12E22-3AFAF2A24-F7A24-3AFAF2A568-5BFBF24-2(BF)4B22-12D20-12D16-7F6-7F7-FA26BAF9-16E4(16-5C8E3C)16-16E18-12A20-F11A20-11AF22-F7A24-5AFAF408-5BFBF24-8B24-2(BF)4B22-12B20-11BF18-16D16-16D13-6F10-6F5-F2A26B2AF7-18E4(14-6C8E4C)14-18E15-2(16A16-)15AF18-F11A20-11AF22-8A24-AF3AFAF24-8A24-AF6A24-3AFAF2A24-8A24-3AFAF2A2(24-8B24-4(BF))24-8B22-11BF20-12B20-11BF18-F15B16-15BF15-4D2B6A2B4D14-18D12-3F16-3F5-FA28BAF6-20E4(12-7C12EC)12-20E13-18A14-F17A14-18A15-F15A16-15AF18-12A20-AF10A20-12A20-AF9AF20-12A20-11AF20-12A2(20-12B20-BF10B)20-12B18-3B10A2BF16-3B10A3B16-3B10A2BF15-4B10A4B14-5B8A5B13-5DB8AB5D12-20D10-3F18-3F4-FA28BAF5-E20AE4(10-8C12A2C)10-E20AE11-20A12-19AF12-20A13-17AF14-18A15-4(16A16-)F15A16-16A16-F15A2(16-14BFB16-BF14B)16-16B15-2(4B10A4B14-)4B10A4B13-F4B10A5B12-6B8A5BF11-6DB8AB6D10-22D9-3F18-3F4-FA28BAF5-E20AE4(10-8C12A2C)10-E20AE11-20A12-F19A12-20A13-F17A14-18A15-15AF16-16A2(16-15AF)16-16A16-15AF16-16A16-15BF16-16B16-F14BF16-16B16-F15B15-2(4B10A4B14-)4B10A4B13-5B10A5B12-6B8A6B11-6DB8AB6D10-22D8-3F20-3F3-FA28BAF4-2E20A2E4(8-9C12A3C)8-2E20A2E9-22A10-21AF10-22A11-19AF12-20A13-3(F17A14-18A14-)F17A4(14-18B)14-17BF13-5B10A5B12-5B10A4BF12-5B10A5B11-6B10A6B10-7B8A6BF9-7DB8AB7D8-24D7-3F20-3F3-FA28BAF4-2E20A2EGJ4(6-9C12A3CGH)6-2E20A2EGH7-2(22A10-)22A11-20A12-20A13-2(17AF14-18A14-)3(18A14-)2(B16AB14-)F16AB14-B16AB14-F16AB13-F18AB12-B18AB12-F18AB11-2B18A2B10-7B8A7B9-7DB8AB7D8-24D6-3F22-3F2-FA28BAF3-3E20A3EI4(5-10C12A4CG)5-3E20A2EGH6-F23A2(8-24A)9-22A10-22A11-2(F19A12-20A12-)2(20A12-)19AF12-2B16A2B12-2B16ABF2(12-2B16A2B)12-2B16ABF11-B20AB10-B20AF10-B20AB9-2B20A2B8-2B20A2B7-8D10A8D6-26D4-4F22-4F-FA28BAF3-3E20A3EK5-4(6C16A4C6-)3E20A2EGH6-2(24A8-)24A9-22A10-22A11-2(20A12-F18AF12-)20A12-F19A12-20A12-FB4(16A2B12-2B)16A2B11-F20AB10-B20AB10-F20AB9-2B20A2B8-2B20A2B7-8D10A8D6-26D4-3F24-3F-FA28BAF3-3E20A3EI5-4(6C16A4C6-)3E20A2EGH6-F23A8-23AF8-F23A9-21AF10-F21A11-6(20A12-)19A2(F12-2B16A2B12-2B16AB)F12-2B16A2B11-B20AF10-B20AB10-B20AF9-2B20A2B8-2B20A2B7-8D10A8D6-26D4-3F24-3F-FA28BAF3-3E20A3EJ5-4(6C16A4C6-)3E20A2EGJ6-2(24A8-)24A9-22A10-22A11-2(20A12-F18AF12-)20A12-F19A12-20A12-FB4(16A2B12-2B)16A2B11-2(B20AB10-)F20AB9-2B20ABF8-FB20A2B7-8D10A8D6-26D4-3F24-3F-FA28BAF3-3E20A3EH5-4(6C16A4C6-)3E20A2EGI6-24A8-23AF8-F23A9-21AF10-F21A11-7(20A12-)2(2B16A2B12-)FB16A2B12-2B16ABF12-FB16A2B11-B20AF10-B20AB10-B20AF9-2B20A2B8-2B20A2B7-8D10A8D6-26D4-3F24-3F-FA28BAF3-3E20A3EH5-4(6C16A4C6-)3E20A2EGI6-24A8-F23A8-24A9-22A10-22A11-3(19AF12-F19A12-)19AF12-FB2(16A2B12-2B)16ABF12-2B16A2B12-2B16ABF11-2(B20AB10-)F20AB9-2B20ABF8-FB20A2B7-8D10A8D6-26D4-3F24-3F-FA28BAF3-3E20A3EH5-4(6C16A4C6-)3E20A2EHK6-2(24A8-)24A9-22A10-22A11-7(20A12-)2(2B16A2B12-)FB16A2B12-2B16A2B12-FB16A2B11-B20AB10-F20AB10-B20AB9-2B20A2B8-2B20A2B7-8D10A8D6-26D4-3F24-3F-FA28BAF3-3E20A3EH4(5-6C16A4CG)5-3E20A2EHI6-24A8-F22AF8-24A9-21AF10-22A11-3(19AF12-F19A12-)19AF12-FB2(16A2B12-2B)16ABF12-2B16A2B12-2B16ABF11-2(B20AB10-)B20AB9-FB20A2B8-2B20A2B7-8D10A8D6-26D4-4F22-4F-FA28BAF4-2E20A2E4(GH6-5C16A3C)GH6-2E20A2EGJ7-2(22A10-)22A11-20A12-20A13-7(18A14-)2(B16AB14-)F16AB14-B16AB14-F16AB13-B18AB12-F18AF12-B18AB11-2B18ABF10-7B8A7B9-7DB8AB7D8-24D6-3F22-3F2-FA28BAF4-2E20A2E4(8-5C12A7C)8-2E20A2E9-F21A10-21AF10-F21A11-19AF12-20A13-2(17AF14-18A14-)17AF14-F17A14-17AF14-F17B4(14-18B)13-2(5B10A5B12-)5B10A5B11-F5B10A6B10-7B8A7B9-7DB8AB7D8-24D7-3F20-3F3-FA28BAF5-E20AE4(10-4C12A6C)10-E20AE11-2(20A12-)20A13-18A14-18A15-7(16A16-)2(16B16-)F15B16-15BF16-F15B15-4B10A4B14-F3B10A3BF14-4B10A4B13-F4B10A4BF12-6B8A6B11-6DB8AB6D10-22D8-3F20-3F3-FA28BAF5-E20AE4(10-4C12A6C)10-E20AE11-F19A12-19AF12-F19A13-18A14-18A15-F14A2(F16-16A16-15A)F16-F15A16-14A2F16-F15B16-14BFB16-BF14B16-16B16-BF14B15-4B10A3BF2(14-4B10A4B)13-5B10A5B12-6B8A6B11-6DB8AB6D10-22D9-3F18-3F4-FA28BAF6-20E4(12-3C12E5C)12-20E13-2(18A14-)18A15-F13AFA16-16A18-F10AF3(20-12A)20-AF10A20-12A20-AF8AFA20-12B20-10BFB20-BF10B20-11BF20-BF10B18-3B10ABFB16-F2B10A3B16-3B10A3B15-F3B10A4B14-5B8A5B13-5DB8AB5D12-20D10-3F18-3F4-F2A26B2AF7-18E4(14-2C12E4C)14-18E15-16A16-15AF16-16A18-F9AFA20-12A22-FAF4AF24-4A2(FA)24-FAF5A2(24-4A2(FA)24-AF6A)24-4B2(FB)24-8B24-2(BF)4B24-5BFBF24-2(BF)4B22-2(12B20-)12B18-15BF16-16B15-4D2B6A2B4D14-18D12-3F16-3F6-FA26BAF9-16E4(16-16C)16-16E18-2(12A20-)12A22-8A24-8A408-5BFBF24-8B24-FBF5B22-11BF20-12B18-16D16-16D13-6F10-6F6-F3A22B3AF2-F8-12E8-F11-4(12C20-)12E22-FAF2AFAF24-8A24-FAF2AFAF568-4B2(FB)24-FBF5B22-12D20-12D16-7F6-7F8-F2A22B2AF4-F9-8E9-F14-4(8E24-)8E728-8D24-8D19-18F10-F3A18B3AF6-F24-F940-14F13-2F20A2F8-2F20-2F943-10F17-F18BF12-4F12B4F15-4F6B4F21-8F888-8F12-
