model
size = 24 31 28, scale = 0.05, origin = -y
material 
  colors = A:#FC9 B:#FC6 C:#222 D:#B00 E:#0CF F:#EEE G:#111
voxels
------------------------ ------------------------ ------------------------ ------------------------ ------------------------ ------------------------ ------------------------ ------------------------ ------------------------ ------------------------ ------------------------ ------------------------ ------------------------ ------------------------ -----------B------------ -----------B------------ ------------------------ ------------------------ ------------------------ ------------------------ ------------------------ ------------------------ ------------------------ ------------------------ ------------------------ ------------------------ ------------------------ ------------------------ ------------------------ ------------------------ ------------------------ 
------------------------ ------------------------ ------------------------ ------------------------ ------------------------ ------------------------ ------------------------ ------------------------ ------------------------ ------------------------ ------------------------ ------------------------ ------------------------ -----------BB----------- ----------BBBB---------- -----------BB----------- -----------BB----------- -----------B------------ ------------------------ ------------------------ ------------------------ ------------------------ ------------------------ ------------------------ ------------------------ ------------------------ ------------------------ ------------------------ ------------------------ ------------------------ ------------------------ 
------------------------ ------------------------ ------------------------ ------------------------ ------------------------ ------------------------ ------------------------ ------------------------ ------------------------ ------------------------ ------------------------ ------------------------ ------------------------ ---------BBBBBB--------- ---------B-BB-B--------- ----------BBBB---------- -----------BB----------- -----------BB----------- -----------BB----------- -----------BB----------- ------------------------ ------------------------ ------------------------ ------------------------ ------------------------ ------------------------ ------------------------ ------------------------ ------------------------ ------------------------ ------------------------ 
------------------------ ------------------------ ------------------------ ------------------------ ------------------------ ------------------------ ------------------------ ------------------------ ------------------------ ------------------------ ------------------------ ------------------------ ------------------------ ---------B-BB-B--------- ---------B-BB-B--------- ----------BBBB---------- ----------BBBB---------- ----------BBBB---------- -----------BB----------- -----------BB----------- -------CCCCCCCCCC------- ------------------------ ------------------------ ------------------------ ------------------------ ------------------------ ------------------------ ------------------------ ------------------------ ------------------------ ------------------------ 
------------------------ ------------------------ ------------------------ ------------------------ ------------------------ ------------------------ ------------------------ ------------------------ --------DDDDDDDD-------- --------DFFFFCFD-------- --------DDDDDDDD-------- ------------------------ ------------------------ ---------B-BB-B--------- ---------BBBBBB--------- ----------BBBB---------- ----------BBBB---------- -------EEEBBBBEEE------- -------EGEBBBBEGE------- -------EEEEBBEEEE------- ------BBBBBBBBBBBC------ -------CCCC---CCCC------ ------------------------ ------------------------ ------------------------ ------------------------ ------------------------ ------------------------ ------------------------ ------------------------ ------------------------ 
------------------------ ------------------------ ------------------------ ------------------------ ------------------------ ------------------------ ------------------------ ----------DDDDD--------- --------DDAAAAAD-------- -------DAAAAAAAADA------ ------ADAAAAAAAADAA----- -----AAADDDAADDDAAA----- -----AAAAAAAAAAAAAA----- -----AAAAAAAAAAAAAA----- ----AAAAAAAAAAAAAAAA---- ----AAAAAAAAAAAAAAAA---- ----AAAAAAAAAAAAAAAA---- ----AAAAAAAAAAAAAAAA---- -----AAAAAAAAAAAAAA----- ------AAAAAAAAAAAAA----- ------AAAAAAAAAAAAA----- -------AAAAAAAAAAA------ ----------AAAAA--------- ------------------------ ------------------------ ------------------------ ------------------------ ------------------------ ------------------------ ------------------------ ------------------------ 
------------------------ ------------------------ ------------------------ ------------------------ -----------BB----------- ----------BBBB---------- ---------BBBBBB--------- ---------DAAAAA--------- --------DAAAAAAD-------- -------DAAAAAAAADA------ ------AAAAAAAAAAAAA----- -----AAAAAAAAAAAAAA----- -----AAAAAAAAAAAAAA----- ----AAAAAAAAAAAAAAAA---- ----AAAAAAAAAAAAAAAA---- ----AAAAAAAAAAAAAAAA---- ----AAAAAAAAAAAAAAAA---- ----AAAAAAAAAAAAAAAA---- -----AAAAAAAAAAAAAA----- ------AAAAAAAAAAAAA----- ------AAAAAAAAAAAAA----- -------AAAAAAAAAAAA----- -------AAAAAAAAAAA------ -------AAAAAAAAAA------- ---------AAAAAA--------- ------------------------ ------------------------ ------------------------ ------------------------ ------------------------ ------------------------ 
------------------------ ------------------------ ------------------------ ------------------------ ------------BB---------- ----------AAAA---------- -------AAAAAAAAAAA------ -----AAADAAAAAAAAAA----- ----AAADAAAAAAAADAAA---- ----AAAAAAAAAAAAAAAA---- ----AAAAAAAAAAAAAAAA---- ----AAAAAAAAAAAAAAAA---- ---AAAAAAAAAAAAAAAAAA--- ---AAAAAAAAAAAAAAAAAA--- ---AAAAAAAAAAAAAAAAAA--- ---AAAAAAAAAAAAAAAAAA--- ---AAAAAAAAAAAAAAAAAA--- ---AAAAAAAAAAAAAAAAAA--- ---AAAAAAAAAAAAAAAAAA--- ----AAAAAAAAAAAAAAAAA--- ----AAAAAAAAAAAAAAAA---- ----AAAAAAAAAAAAAAAA---- -----AAAAAAAAAAAAAA----- -------AAAAAAAAAAA------ -------AAAAAAAAAA------- ----------AAAAA--------- ------------------------ ------------------------ ------------------------ ------------------------ ------------------------ 
------------------------ ------------------------ ------------------------ ------------------------ -----------AA----------- --------AAAAAAA--------- -----AAAAAAAAAAAAAA----- -----AAAAAAAAAAAAAAA---- ----AAAAAAAAAAAAAAAA---- ----AAAAAAAAAAAAAAAA---- ---AAAAAAAAAAAAAAAAA---- ---AAAAAAAAAAAAAAAAAA--- ---AAAAAAAAAAAAAAAAAA--- ---AAAAAAAAAAAAAAAAAA--- ---AAAAAAAAAAAAAAAAAA--- ---AAAAAAAAAAAAAAAAAA--- ---AAAAAAAAAAAAAAAAAA--- ---AAAAAAAAAAAAAAAAAA--- ---AAAAAAAAAAAAAAAAAA--- ---AAAAAAAAAAAAAAAAAA--- ---AAAAAAAAAAAAAAAAAA--- ----AAAAAAAAAAAAAAAA---- ----AAAAAAAAAAAAAAAA---- -----AAAAAAAAAAAAAA----- -------AAAAAAAAAAA------ -------CAAAAAAAA-------- -------C--C-C-C--------- -------C--C-C-C--------- ------------C-C--------- ------------------------ ------------------------ 
------------------------ ------------------------ ------------------------ ------------------------ ---------AAAAAA--------- -------AAAAAAAAAAA------ -----AAAAAAAAAAAAAA----- ----AAAAAAAAAAAAAAAA---- ----AAAAAAAAAAAAAAAA---- ---AAAAAAAAAAAAAAAAA---- ---AAAAAAAAAAAAAAAAAA--- ---AAAAAAAAAAAAAAAAAA--- ---AAAAAAAAAAAAAAAAAA--- ---AAAAAAAAAAAAAAAAAA--- ---AAAAAAAAAAAAAAAAAA--- ---AAAAAAAAAAAAAAAAAA--- ---AAAAAAAAAAAAAAAAAA--- ---AAAAAAAAAAAAAAAAAA--- ---AAAAAAAAAAAAAAAAAA--- ---AAAAAAAAAAAAAAAAAA--- ---AAAAAAAAAAAAAAAAAA--- ---AAAAAAAAAAAAAAAAAA--- ----AAAAAAAAAAAAAAAA---- -----AAAAAAAAAAAAAA----- ------AAAAAAAAAAAAA----- -------AAAAAAAAAAA------ --------C--C----C------- --------C--C----C------- -----------C----C------- ------------------------ ------------------------ 
---------BBBBBB--------- ---------BBBBBB--------- ---------BBBBBB--------- ---------AAAAAA--------- -------AAAAAAAAAAA------ ------AAAAAAAAAAAAA----- -----AAAAAAAAAAAAAA----- ----AAAAAAAAAAAAAAAA---- ----AAAAAAAAAAAAAAAA---- ---AAAAAAAAAAAAAAAAAA--- ---AAAAAAAAAAAAAAAAAA--- ---AAAAAAAAAAAAAAAAAA--- ---AAAAAAAAAAAAAAAAAA--- ---AAAAAAAAAAAAAAAAAA--- ---AAAAAAAAAAAAAAAAAA--- ---AAAAAAAAAAAAAAAAAA--- ---AAAAAAAAAAAAAAAAAA--- ---AAAAAAAAAAAAAAAAAA--- ---AAAAAAAAAAAAAAAAAA--- ---AAAAAAAAAAAAAAAAAA--- ---AAAAAAAAAAAAAAAAAA--- ---AAAAAAAAAAAAAAAAAA--- ---AAAAAAAAAAAAAAAAAA--- ----AAAAAAAAAAAAAAAAA--- ----AAAAAAAAAAAAAAAA---- ------AAAAAAAAAAAAA----- ------C--AAAAAA--------- ------C--C---C---------- ------C--C---C---------- -------------C---------- ------------------------ 
--------BBBBBBBB-------- --------BBBBBBBB-------- --------BBBBBBBB-------- --------AAAAAAAA-------- -------AAAAAAAAAAA------ -----AAAAAAAAAAAAAA----- -----AAAAAAAAAAAAAA----- ----AAAAAAAAAAAAAAAA---- ---AAAAAAAAAAAAAAAAA---- ---AAAAAAAAAAAAAAAAA---- ---AAAAAAAAAAAAAAAAAA--- ---AAAAAAAAAAAAAAAAAA--- ---AAAAAAAAAAAAAAAAAA--- ---AAAAAAAAAAAAAAAAAA--- ---AAAAAAAAAAAAAAAAAA--- ---AAAAAAAAAAAAAAAAAA--- ---AAAAAAAAAAAAAAAAAA--- ---AAAAAAAAAAAAAAAAAA--- ---AAAAAAAAAAAAAAAAAA--- ---AAAAAAAAAAAAAAAAAA--- ---AAAAAAAAAAAAAAAAAA--- ---AAAAAAAAAAAAAAAAAA--- ---AAAAAAAAAAAAAAAAAA--- ---AAAAAAAAAAAAAAAAA---- ----AAAAAAAAAAAAAAA----- -----AAAAAAAAAAAAAA----- -------CAAAAAAAA-------- -------C---C---C-------- -------C---C---C-------- -----------C---C-------- ------------------------ 
-------BBBBBBBBBB------- -------BBBBBBBBBB------- -------BBBBBBBBBB------- -------AAAAAAAAAA------- ------AAAAAAAAAAAAA----- -----AAAAAAAAAAAAAA----- -----AAAAAAAAAAAAAA----- ----AAAAAAAAAAAAAAAA---- ---AAAAAAAAAAAAAAAAAA--- ---AAAAAAAAAAAAAAAAAA--- ---AAAAAAAAAAAAAAAAAA--- ---AAAAAAAAAAAAAAAAAA--- ---AAAAAAAAAAAAAAAAAA--- ---AAAAAAAAAAAAAAAAAA--- ---AAAAAAAAAAAAAAAAAA--- ---AAAAAAAAAAAAAAAAAA--- ---AAAAAAAAAAAAAAAAAA--- --BAAAAAAAAAAAAAAAAAAB-- --BAAAAAAAAAAAAAAAAAAB-- ---AAAAAAAAAAAAAAAAAA--- ---AAAAAAAAAAAAAAAAAA--- ---AAAAAAAAAAAAAAAAAA--- ---AAAAAAAAAAAAAAAAAA--- ---AAAAAAAAAAAAAAAAAA--- ---AAAAAAAAAAAAAAAAA---- -----AAAAAAAAAAAAAA----- -------AAAAAAAAAAC------ ---------C-AAA---C------ ---------C--C----C------ ------------C----------- ------------C----------- 
-------BBBBBBBBBB------- -------BBBBBBBBBB------- -------BBBBBBBBBB------- -------AAAAAAAAAA------- ------AAAAAAAAAAAAA----- -----AAAAAAAAAAAAAAA---- ----AAAAAAAAAAAAAAAA---- ---AAAAAAAAAAAAAAAAA---- ---AAAAAAAAAAAAAAAAAA--- ---AAAAAAAAAAAAAAAAAA--- ---AAAAAAAAAAAAAAAAAA--- ---AAAAAAAAAAAAAAAAAA--- ---AAAAAAAAAAAAAAAAAA--- ---AAAAAAAAAAAAAAAAAA--- ---AAAAAAAAAAAAAAAAAA--- --BAAAAAAAAAAAAAAAAAAB-- --BAAAAAAAAAAAAAAAAAAB-- -BBAAAAAAAAAAAAAAAAAABB- --BAAAAAAAAAAAAAAAAAAB-- --BAAAAAAAAAAAAAAAAAAB-- ---AAAAAAAAAAAAAAAAAA--- ---AAAAAAAAAAAAAAAAAA--- ---AAAAAAAAAAAAAAAAAA--- ---AAAAAAAAAAAAAAAAAA--- ----AAAAAAAAAAAAAAAAA--- ----AAAAAAAAAAAAAAAA---- -----C-AAAAAAAAAA------- -----C-C--AAAAA--------- -----C-C--C---C--------- -------C--C---C--------- --------------C--------- 
-------BBBBBBBBBBB------ -------BBBBBBBBBBB------ -------BBBBBBBBBBB------ -------AAAAAAAAAAA------ ------AAAAAAAAAAAAA----- ----AAAAAAAAAAAAAAAA---- ---AAAAAAAAAAAAAAAAA---- ---AAAAAAAAAAAAAAAAA---- ---AAAAAAAAAAAAAAAAAA--- ---AAAAAAAAAAAAAAAAAA--- ---AAAAAAAAAAAAAAAAAA--- ---AAAAAAAAAAAAAAAAAA--- ---AAAAAAAAAAAAAAAAAA--- ---AAAAAAAAAAAAAAAAAA--- ---AAAAAAAAAAAAAAAAAA--- -BBAAAAAAAAAAAAAAAAAABB- --BAAAAAAAAAAAAAAAAAAB-- --BAAAAAAAAAAAAAAAAAAB-- -BBAAAAAAAAAAAAAAAAAABB- -BBAAAAAAAAAAAAAAAAAABB- ---AAAAAAAAAAAAAAAAAA--- ---AAAAAAAAAAAAAAAAAA--- ---AAAAAAAAAAAAAAAAAA--- ---AAAAAAAAAAAAAAAAAA--- ---AAAAAAAAAAAAAAAAA---- ----AAAAAAAAAAAAAAAA---- -------AAAAAAAAAAAC----- ---------AAAAAA-C-C----- ---------C--C---C-C----- ---------C--C---C------- ------------C----------- 
-------BBBBBBBBBBB------ -------BBBBBBBBBBB------ -------BBBBBBBBBBB------ -------AAAAAAAAAAA------ -----AAAAAAAAAAAAAA----- ----AAAAAAAAAAAAAAAA---- ---AAAAAAAAAAAAAAAAAA--- ---AAAAAAAAAAAAAAAAAA--- ---AAAAAAAAAAAAAAAAAA--- ---AAAAAAAAAAAAAAAAAA--- ---AAAAAAAAAAAAAAAAAA--- ---AAAAAAAAAAAAAAAAAA--- ---AAAAAAAAAAAAAAAAAA--- ---AAAAAAAAAAAAAAAAAA--- -B-AAAAAAAAAAAAAAAAAA-B- -BBAAAAAAAAAAAAAAAAAABB- --BAAAAAAAAAAAAAAAAAAB-- --BAAAAAAAAAAAAAAAAAAB-- ---AAAAAAAAAAAAAAAAAA--- -BBAAAAAAAAAAAAAAAAAABB- -B-AAAAAAAAAAAAAAAAAA-B- ---AAAAAAAAAAAAAAAAAA--- ---AAAAAAAAAAAAAAAAAA--- ---AAAAAAAAAAAAAAAAAA--- ---AAAAAAAAAAAAAAAAAA--- ----AAAAAAAAAAAAAAAA---- -------AAAAAAAAAAA------ -------C-AAAAAA--------- -------C--C---C--------- -------C--C---C--------- --------------C--------- 
-------BBBBBBBBBBB------ -------BBBBBBBBBBB------ -------BBBBBBBBBBB------ -------AAAAAAAAAAA------ ------AAAAAAAAAAAAA----- ----AAAAAAAAAAAAAAAA---- ---AAAAAAAAAAAAAAAAAA--- ---AAAAAAAAAAAAAAAAAA--- ---AAAAAAAAAAAAAAAAAA--- ---AAAAAAAAAAAAAAAAAA--- ---AAAAAAAAAAAAAAAAAA--- ---AAAAAAAAAAAAAAAAAA--- ---AAAAAAAAAAAAAAAAAA--- ---AAAAAAAAAAAAAAAAAA--- -B-AAAAAAAAAAAAAAAAAA-B- BB-AAAAAAAAAAAAAAAAAA-BB BB-AAAAAAAAAAAAAAAAAA-BB BB-AAAAAAAAAAAAAAAAAA-BB -B-AAAAAAAAAAAAAAAAAA-B- --BAAAAAAAAAAAAAAAAAAB-- ---AAAAAAAAAAAAAAAAAA--- ---AAAAAAAAAAAAAAAAAA--- ---AAAAAAAAAAAAAAAAAA--- ---AAAAAAAAAAAAAAAAAA--- ----AAAAAAAAAAAAAAAA---- ----AAAAAAAAAAAAAAAA---- -----C-AAAAAAAAAAA------ -----C---AAAAAA-C------- -----C------C---C------- ------------C---C------- ------------------------ 
-------BBBBBBBBBB------- -------BBBBBBBBBB------- -------BBBBBBBBBB------- -------AAAAAAAAAA------- ------AAAAAAAAAAAAA----- ----AAAAAAAAAAAAAAAA---- ---AAAAAAAAAAAAAAAAAA--- ---AAAAAAAAAAAAAAAAAA--- ---AAAAAAAAAAAAAAAAAA--- ---AAAAAAAAAAAAAAAAAA--- ---AAAAAAAAAAAAAAAAAA--- ---AAAAAAAAAAAAAAAAAA--- ---AAAAAAAAAAAAAAAAAA--- ---AAAAAAAAAAAAAAAAAA--- ---AAAAAAAAAAAAAAAAAA--- ---AAAAAAAAAAAAAAAAAA--- ---AAAAAAAAAAAAAAAAAA--- ---AAAAAAAAAAAAAAAAAA--- ---AAAAAAAAAAAAAAAAAA--- ---AAAAAAAAAAAAAAAAAA--- ---AAAAAAAAAAAAAAAAAA--- ---AAAAAAAAAAAAAAAAAA--- ---AAAAAAAAAAAAAAAAAA--- ---AAAAAAAAAAAAAAAAAA--- ---AAAAAAAAAAAAAAAAAA--- ----AAAAAAAAAAAAAAAA---- ------CAAAAAAAAAA-C----- ------C-C-AAAAA---C----- ------C-C-C---C---C----- --------C-C---C--------- --------------C--------- 
--------BBBBBBBB-------- --------BBBBBBBB-------- --------BBBBBBBB-------- --------AAAAAAAA-------- -------AAAAAAAAAAA------ -----AAAAAAAAAAAAAA----- ---AAAAAAAAAAAAAAAAA---- ---AAAAAAAAAAAAAAAAAA--- ---AAAAAAAAAAAAAAAAAA--- ---AAAAAAAAAAAAAAAAAA--- ---AAAAAAAAAAAAAAAAAA--- ---AAAAAAAAAAAAAAAAAA--- ---AAAAAAAAAAAAAAAAAA--- ---AAAAAAAAAAAAAAAAAA--- ---AAAAAAAAAAAAAAAAAA--- ---AAAAAAAAAAAAAAAAAA--- ---AAAAAAAAAAAAAAAAAA--- ---AAAAAAAAAAAAAAAAAA--- ---AAAAAAAAAAAAAAAAAA--- ---AAAAAAAAAAAAAAAAAA--- ---AAAAAAAAAAAAAAAAAA--- ---AAAAAAAAAAAAAAAAAA--- ---AAAAAAAAAAAAAAAAAA--- ---AAAAAAAAAAAAAAAAAA--- ----AAAAAAAAAAAAAAAA---- -----AAAAAAAAAAAAAA----- --------AAAAAAAAC------- ------------C---C------- ------------C---C------- ------------C----------- ------------------------ 
---------BBBBBB--------- ---------BBBBBB--------- ---------BBBBBB--------- ---------AAAAAA--------- -------AAAAAAAAAAA------ ------AAAAAAAAAAAAA----- ----AAAAAAAAAAAAAAAA---- ---AAAAAAAAAAAAAAAAA---- ---AAAAAAAAAAAAAAAAAA--- ---AAAAAAAAAAAAAAAAAA--- ---AAAAAAAAAAAAAAAAAA--- ---AAAAAAAAAAAAAAAAAA--- ---AAAAAAAAAAAAAAAAAA--- ---AAAAAAAAAAAAAAAAAA--- ---AAAAAAAAAAAAAAAAAA--- ---AAAAAAAAAAAAAAAAAA--- ---AAAAAAAAAAAAAAAAAA--- ---AAAAAAAAAAAAAAAAAA--- ---AAAAAAAAAAAAAAAAAA--- ---AAAAAAAAAAAAAAAAAA--- ---AAAAAAAAAAAAAAAAAA--- ---AAAAAAAAAAAAAAAAAA--- ----AAAAAAAAAAAAAAAAA--- ----AAAAAAAAAAAAAAAA---- ----AAAAAAAAAAAAAAAA---- ------AAAAAAAAAAAAA----- ------C-CAAAAAA---C----- ------C-C-C---C---C----- ------C-C-C---C---C----- ----------C---C--------- ------------------------ 
-----------BBB---------- -----------BBB---------- -----------BBB---------- -----------AAA---------- -------AAAAAAAAAA------- ------AAAAAAAAAAAAA----- ----AAAAAAAAAAAAAAAA---- ----AAAAAAAAAAAAAAAA---- ---AAAAAAAAAAAAAAAAAA--- ---AAAAAAAAAAAAAAAAAA--- ---AAAAAAAAAAAAAAAAA---- ---AAAAAAAAAAAAAAAAAA--- ---AAAAAAAAAAAAAAAAAA--- ---AAAAAAAAAAAAAAAAAA--- ---AAAAAAAAAAAAAAAAAA--- ---AAAAAAAAAAAAAAAAAA--- ---AAAAAAAAAAAAAAAAAA--- ---AAAAAAAAAAAAAAAAAA--- ---AAAAAAAAAAAAAAAAAA--- ---AAAAAAAAAAAAAAAAAA--- ---AAAAAAAAAAAAAAAAAA--- ---AAAAAAAAAAAAAAAAAA--- ---AAAAAAAAAAAAAAAAA---- ----AAAAAAAAAAAAAAAA---- -----AAAAAAAAAAAAAA----- ------AAAAAAAAAAAAA----- -----------AAA--C------- ------------C---C------- ------------C---C------- ------------C----------- ------------------------ 
------------------------ ------------------------ ------------------------ ------------------------ ---------AAAAAA--------- -------AAAAAAAAAAA------ -----AAAAAAAAAAAAAA----- ----AAAAAAAAAAAAAAAA---- ----AAAAAAAAAAAAAAAAA--- ---AAAAAAAAAAAAAAAAA---- ---AAAAAAAAAAAAAAAAA---- ---AAAAAAAAAAAAAAAAAA--- ---AAAAAAAAAAAAAAAAAA--- ---AAAAAAAAAAAAAAAAAA--- ---AAAAAAAAAAAAAAAAAA--- ---AAAAAAAAAAAAAAAAAA--- ---AAAAAAAAAAAAAAAAAA--- ---AAAAAAAAAAAAAAAAAA--- ---AAAAAAAAAAAAAAAAAA--- ---AAAAAAAAAAAAAAAAAA--- ---AAAAAAAAAAAAAAAAAA--- ---AAAAAAAAAAAAAAAAAA--- ----AAAAAAAAAAAAAAAA---- -----AAAAAAAAAAAAAA----- ------AAAAAAAAAAAAA----- ------CAAAAAAAAAAA------ ------C-C-C---C--------- ------C-C-C---C--------- --------C-C---C--------- ------------------------ ------------------------ 
------------------------ ------------------------ ------------------------ ------------------------ ------------------------ ----------AAAAA--------- -------AAAAAAAAAAA------ -----AAAAAAAAAAAAAA----- ----AAAAAAAAAAAAAAAA---- ----AAAAAAAAAAAAAAAA---- ---AAAAAAAAAAAAAAAAA---- ---AAAAAAAAAAAAAAAAA---- ---AAAAAAAAAAAAAAAAAA--- ---AAAAAAAAAAAAAAAAAA--- ---AAAAAAAAAAAAAAAAAA--- ---AAAAAAAAAAAAAAAAAA--- ---AAAAAAAAAAAAAAAAAA--- ---AAAAAAAAAAAAAAAAAA--- ---AAAAAAAAAAAAAAAAAA--- ---AAAAAAAAAAAAAAAAAA--- ---AAAAAAAAAAAAAAAAA---- ----AAAAAAAAAAAAAAAA---- -----AAAAAAAAAAAAAA----- -------AAAAAAAAAAA------ -------AAAAAAAAAA------- ----------AAAAA-C------- ------------C---C------- ------------C---C------- ------------C----------- ------------------------ ------------------------ 
------------------------ ------------------------ ------------------------ ------------------------ ------------------------ ------------------------ -------AAAAAAAAAA------- -------AAAAAAAAAAA------ -----AAAAAAAAAAAAAA----- -----AAAAAAAAAAAAAA----- ----AAAAAAAAAAAAAAAA---- ---AAAAAAAAAAAAAAAAA---- ---AAAAAAAAAAAAAAAAA---- ---AAAAAAAAAAAAAAAAAA--- ---AAAAAAAAAAAAAAAAAA--- ---AAAAAAAAAAAAAAAAA---- ---AAAAAAAAAAAAAAAAAA--- ---AAAAAAAAAAAAAAAAAA--- ---AAAAAAAAAAAAAAAAA---- ---AAAAAAAAAAAAAAAAAA--- ----AAAAAAAAAAAAAAAA---- -----AAAAAAAAAAAAAA----- -------AAAAAAAAAAA------ -------AAAAAAAAAA------- ---------AAAAAA--------- ---------C-C--C--------- ---------C-C--C--------- ---------C-C--C--------- ------------------------ ------------------------ ------------------------ 
------------------------ ------------------------ ------------------------ ------------------------ ------------------------ ------------------------ ---------AAAAAA--------- -------AAAAAAAAAA------- -------AAAAAAAAAAA------ ------AAAAAAAAAAAAA----- ----AAAAAAAAAAAAAAAA---- ----AAAAAAAAAAAAAAAA---- ---AAAAAAAAAAAAAAAAA---- ----AAAAAAAAAAAAAAAA---- ---AAAAAAAAAAAAAAAAA---- ---AAAAAAAAAAAAAAAAA---- ---AAAAAAAAAAAAAAAAA---- ----AAAAAAAAAAAAAAAA---- ----AAAAAAAAAAAAAAAA---- ----AAAAAAAAAAAAAAAA---- -----AAAAAAAAAAAAAA----- ------AAAAAAAAAAAAA----- -------AAAAAAAAAA------- ---------AAAAAA--------- ------------------------ ------------------------ ------------------------ ------------------------ ------------------------ ------------------------ ------------------------ 
------------------------ ------------------------ ------------------------ ------------------------ ------------------------ ------------------------ ------------------------ ----------AAAAA--------- --------AAAAAAAA-------- -------AAAAAAAAAAA------ ------AAAAAAAAAAAAA----- -----AAAAAAAAAAAAAA----- -----AAAAAAAAAAAAAA----- ----AAAAAAAAAAAAAAAA---- ----AAAAAAAAAAAAAAAA---- ----AAAAAAAAAAAAAAAA---- ----AAAAAAAAAAAAAAAA---- ----AAAAAAAAAAAAAAAA---- -----AAAAAAAAAAAAAA----- ------AAAAAAAAAAAAA----- ------AAAAAAAAAAAAA----- -------AAAAAAAAAAA------ ----------AAAAA--------- ------------------------ ------------------------ ------------------------ ------------------------ ------------------------ ------------------------ ------------------------ ------------------------ 
------------------------ ------------------------ ------------------------ ------------------------ ------------------------ ------------------------ ------------------------ ------------------------ ------------------------ ------------------------ ---------AAAAAA--------- --------AAAAAAAA-------- -------AAAAAAAAAA------- -------AAAAAAAAAA------- -------AAAAAAAAAAA------ -------AAAAAAAAAAA------ -------AAAAAAAAAAA------ -------AAAAAAAAAA------- --------AAAAAAAA-------- ---------AAAAAA--------- -----------AAA---------- ------------------------ ------------------------ ------------------------ ------------------------ ------------------------ ------------------------ ------------------------ ------------------------ ------------------------ ------------------------ 
------------------------ ------------------------ ------------------------ ------------------------ ------------------------ ------------------------ ------------------------ ------------------------ ------------------------ ------------------------ ------------------------ ------------------------ -----------AAA---------- ----------AAAAA--------- ---------AAAAAA--------- ---------AAAAAA--------- ---------AAAAAA--------- ----------AAAAA--------- ------------------------ ------------------------ ------------------------ ------------------------ ------------------------ ------------------------ ------------------------ ------------------------ ------------------------ ------------------------ ------------------------ ------------------------ ------------------------ 
