model
size = 28 32 18, scale = 0.05, origin = -y
material 
  colors = A:#1C1D20 B:#CF6 C:#9C6 D:#693 E:#690 F:#336 G:#339 H:#993 I:#9C3 J:#996 K:#30C L:#9F6 M:#CC6 N:#888 O:#366 P:#555 Q:#696 R:#66C S:#666
voxels
6-28(8(BA)12-)CDHIM5(AB)A12-3E2DL5(BA)12-S3FGQC4(AB)A12-RPG2KOEDCHC2JCBA9-29(AB17ABAB6-)ABI16ABAB6-ABC16ABAB6-ABN16ABAB5-31(B23A4-)B23A3-31(4A18-3AB2-)4A18-3AB-5A31(18-10A)18-9A223(20-8A)20-9A31(18-10A)18-5A-31(4A18-4A2-)4A18-4A3-31(4A16-4A4-)4A16-4A5-31(5A12-5A6-)5A12-5A7-31(20A8-)20A10-28(16A12-)3(8(BA)12-)8(BA)6-
