model
size = 32 16 32, scale = 0.05, origin = -y
material 
  colors = A:#D6752E B:#9A4C1E
voxels
12-8A501-14A21-8B467-18A16-14B21-8A434-20A14-16B18-12A22-8B401-22A11-20B14-16A18-12B23-6A369-24A9-22B12-18A15-16B18-12A23-6B336-26A7-24B10-20A13-18B16-14A19-12B23-6A303-28A6-24B9-22A11-20B14-16A17-14B20-10A24-6B271-28A5-26B7-24A9-22B12-18A15-16B17-14A20-10B24-6A238-8A14-8A3-7B14-7B6-5A14-5A9-4B14-4B11-3A14-3A13-2B14-2B15-16A18-12B21-10A24-6B206-8A14-8A3-7B14-7B5-6A14-6A7-5B14-5B9-4A14-4A11-2(3B14-)2A12-2A17-B12-B19-12A22-8B26-4A175-8A14-8A3-7B14-7B5-6A14-6A7-5B14-5B9-4A14-4A11-3B14-3B13-3A12-3A15-2B12-2B17-2A10-2A20-10B23-8A26-4B142-9A14-9A-8B14-8B3-7A14-7A5-6B14-6B8-4A14-4A11-3B14-3B13-3A12-3A15-2B12-2B17-2A10-2A19-12B21-10A23-8B26-4A110-9A14-9A-8B14-8B3-7A14-7A5-6B14-6B7-5A14-5A9-4B14-4B11-4A12-4A13-3B12-3B15-3A10-3A17-14B20-10A23-8B25-6A27-4B78-9A14-9A-8B14-8B3-7A14-7A5-6B14-6B7-5A14-5A9-4B14-4B11-4A12-4A13-3B12-3B15-3A10-3A17-14B19-12A21-10B23-8A25-6B28-2A47-2(9A14-9A-8B14-8B3-7A14-7A5-6B14-6B7-5A14-5A9-4B14-4B11-4A12-4A13-3B12-3B15-3A10-3A17-14B19-12A21-10B23-8A25-6B27-4A29-2B15-)9A14-9A-8B14-8B3-7A14-7A5-6B14-6B7-5A14-5A9-4B14-4B11-4A12-4A13-3B12-3B15-3A10-3A17-14B19-12A21-10B23-8A25-6B28-2A47-9A14-9A-8B14-8B3-7A14-7A5-6B14-6B7-5A14-5A9-4B14-4B11-4A12-4A13-3B12-3B15-3A10-3A17-14B20-10A23-8B25-6A27-4B78-9A14-9A-8B14-8B3-7A14-7A5-6B14-6B8-4A14-4A11-3B14-3B13-3A12-3A15-2B12-2B17-2A10-2A19-12B21-10A23-8B26-4A111-8A14-8A3-7B14-7B5-6A14-6A7-5B14-5B9-4A14-4A11-3B14-3B13-3A12-3A15-2B12-2B17-2A10-2A20-10B23-8A26-4B143-8A14-8A3-7B14-7B5-6A14-6A7-5B14-5B9-4A14-4A11-2(3B14-)2A12-2A17-B12-B19-12A22-8B26-4A175-8A14-8A3-7B14-7B6-5A14-5A9-4B14-4B11-3A14-3A13-2B14-2B15-16A18-12B21-10A24-6B207-28A5-26B7-24A9-22B12-18A15-16B17-14A20-10B24-6A239-28A6-24B9-22A11-20B14-16A17-14B20-10A24-6B272-26A7-24B10-20A13-18B16-14A19-12B23-6A305-24A9-22B12-18A15-16B18-12A23-6B338-22A11-20B14-16A18-12B23-6A371-20A14-16B18-12A22-8B403-18A16-14B21-8A437-14A21-8B472-8A492-
