model
size = 18 10 3, scale = 0.05, origin = -y
material 
  colors = A:#000
voxels
------------------ ------------------ ------------------ ------------------ ------------------ -AAAA--------AAAA- ---AAAAA--AAAAA--- ----AAAA--AAAA---- -----AAA--AAA----- ------A----A------ 
------------------ ------------------ ------------------ ------------------ ------------------ -AAAA--------AAAA- ---AAAAA--AAAAA--- ----AAAA--AAAA---- -----AAA--AAA----- ------A----A------ 
--------AA-------- --------AA-------- -------AAAA------- ------AA--AA------ ------------------ AAAAAA------AAAAAA ---AAAAAAAAAAAA--- ----AAAAAAAAAA---- -----AAAAAAAA----- ------AA--AA------ 
