model
size = 30 12 3, scale = 0.05, origin = -y
material 
  colors = A:#000
voxels
------------------------------ ------------------------------ ------------------------------ ---AA--------------------AA--- --AAAA------------------AAAA-- -AA--AA----------------AA--AA- AA----AAA------------AAA----AA AA--A--AAAA--------AAAA--A--AA -AAAA----AAAAA--AAAAA----AAAA- --AA------AAAA--AAAA------AA-- -----------AAA--AAA----------- ------------A----A------------ 
-------------AAAA------------- ------------AAAAAA------------ -------------AAAA------------- ---AA--------AAAA--------AA--- --AAAA--------AA--------AAAA-- -AA--AA-------AA-------AA--AA- AA----AAA------------AAA----AA AA--A--AAAA--------AAAA--A--AA -AAAA----AAAAA--AAAAA----AAAA- --AA------AAAA--AAAA------AA-- -----------AAA--AAA----------- ------------A----A------------ 
-------------AAAA------------- ------------AAAAAA------------ -------------AAAA------------- ---AA--------AAAA--------AA--- --AAAA--------AA--------AAAA-- -AA--AA-------AA-------AA--AA- AA----AAA------------AAA----AA AA--A--AAAA--------AAAA--A--AA -AAAA----AAAAA--AAAAA----AAAA- --AA------AAAA--AAAA------AA-- -----------AAA--AAA----------- ------------A----A------------ 
