model
size = 30 15 9, scale = 0.05, origin = -y
material 
  colors = A:#0E0
voxels
------------------------------ -------A--------------A------- ------A-A------------A-A------ ---------A----------A--------- ------------------------------ ----------A--------A---------- ----------A--------A---------- ----------A--------A---------- ----------A--------A---------- ----------A--------A---------- ----------A--------A---------- -----------AA----AA----------- ------------AA--AA------------ ------------------------------ ------------------------------ 
-------AAA----------AAA------- ------AAAA----------AAAA------ ------AAAAA--------AAAAA------ -----AAAAAA--------AAAAAA----- ---------AA--------AA--------- ---------AA--------AA--------- ---------AA--------AA--------- ---------AA--------AA--------- ---------AA--------AA--------- ---------AA--------AA--------- ---------AAAAA--AAAAA--------- ----------AAAAAAAAAA---------- -----------AAAAAAAA----------- ------------AA--AA------------ ------------------------------ 
-------AAA----------AAA------- ------AAAA----------AAAA------ ------AAAAA--------AAAAA------ -----AAAAAA--------AAAAAA----- ----A----AA--------AA----A---- ---------AA--------AA--------- ---------AA--------AA--------- ---------AA--------AA--------- ---------AA--------AA--------- ---------AA--------AA--------- ---------AAAAA--AAAAA--------- ----------AAAAAAAAAA---------- -----------AAAAAAAA----------- ------------AA--AA------------ ------------------------------ 
-------AA------------AA------- ------AAAA----------AAAA------ ------AAAAA--------AAAAA------ -----AAAAAA--------AAAAAA----- ----A----AA--------AA----A---- ----A----AA--------AA----A---- ---AA----AA--------AA----AA--- --AAA----AA--------AA----AAA-- -AAA-----AA--------AA-----AAA- -AAA-----AA--------AA-----AAA- ---------AAAAA--AAAAA--------- ----------AAAAAAAAAA---------- -----------AAAAAAAA----------- ------------AA--AA------------ ------------------------------ 
------------------------------ ------A----------------A------ ------A----------------A------ -----AA----------------AA----- ----A--------------------A---- ----A--------------------A---- ---AA--------------------AA--- --AAA--------------------AAA-- -AAA----------------------AAA- -AAA----------------------AAA- -AA------------------------AA- AAA------------------------AAA ------------------------------ ------------------------------ ------------------------------ 
------------------------------ ------------------------------ ------------------------------ ------------------------------ ------------------------------ ----A--------------------A---- ----A--------------------A---- ---AA--------------------AA--- -AAA----------------------AAA- -AAA----------------------AAA- -AA------------------------AA- AAA------------------------AAA AA--------------------------AA AA--------------------------AA ------------------------------ 
------------------------------ ------------------------------ ------------------------------ ------------------------------ ------------------------------ ----A--------------------A---- ----A--------------------A---- --AAA--------------------AAA-- --AA----------------------AA-- -AAA----------------------AAA- -AA------------------------AA- AAA------------------------AAA AA--------------------------AA AA--------------------------AA A----------------------------A 
------------------------------ ------------------------------ ------------------------------ ------------------------------ ------------------------------ ------------------------------ ------------------------------ ----A--------------------A---- --AA----------------------AA-- --AA----------------------AA-- --A------------------------A-- AAA------------------------AAA AA--------------------------AA AA--------------------------AA A----------------------------A 
------------------------------ ------------------------------ ------------------------------ ------------------------------ ------------------------------ ------------------------------ ------------------------------ ------------------------------ ------------------------------ --AA----------------------AA-- --A------------------------A-- -AA------------------------AA- -A--------------------------A- AA--------------------------AA A----------------------------A 
