model
size = 32, scale = 0.05, origin = -y
material 
  colors = A:#E00 B:#00E C:#EEE D:#A00 E:#200
voxels
43-3(10A22-)10A886-A8-A20-3(14A18-)14A880-3A-A8-A-3A14-8A2E8A3(14-18A)757-3(4C28-)4D19-2(6A10-)7A3E12A3(10-22A)753-3(8A24-)8D15-7A12-7A6-7AE-3EA2E2A-8A6-15A3E8A2(6-26A)17-2(4B28-)2(CB)28-B3C28-4C28-B3C28-2(CB)28-4B11(28-4C)26-3(2A4C2A24-)2A4C2A23-10A23-2(8A24-)8D15-3AEAE14-6A6-8AE17A5-2(28A4-)28A14-2(8B24-)3(6BCB24-8B24-)10(8A24-)8A23-3(10A22-)10A21-C10AC21-2(10A22-)10D14-2AEA2-3A3-2A3-E2A2-E3A6-4AE21A5-2(28A4-)28A13-8(10B22-)10(10A22-)10A20-3(2C10A2C18-)2C10A2C17-2C12A2C17-2(2C10A2C18-)14D12-2AE-3A2-3E2(2-3A)-3A6-4AE7A2-12A5-2(13A2-13A4-)13A2-13A11-2(6B2-6B18-)BC4B2-5BC18-C5B2-6B18-2C4B2-5BC18-C5B2-6B18-BC4B2-5BC18-6B2-6B11(18-2C4A2-4A2C)15-4(A2C6A2-6A2CA12-)AC16ACA14-2(C14AC16-)16D10-2(2AE)2-E-A6-A-A2-AE4A4-5AE5A6-11A3-2(12A6-12A2-)12A6-12A8-2(6B6-6B14-)BC4B6-5BC3(14-2C4B6-4B2C)14-BC4B6-5BC14-6B6-6B11(14-2C4A6-4A2C)13-3(7A6-7A12-)7A6-7A11-22A11-2(AC16ACA12-)20D8-AE2A2-2A12-2A2-4A4-4AE4A10-4AE4A3-2(10A10-10A2-)10A10-10A7-2(5B10-5B12-)C4B10-5B12-5B10-4BC12-C4B10-4BC12-5B10-4BC12-C4B10-5B12-5B10-5B11(12-5A10-5A)11-7(6A10-)6A9-3(24A8-)24D6-3A2-A-A12-A-A2-3A4-4AE3A12-4AE3A3-2(9A12-9A2-)9A12-9A6-2(5B12-5B10-)3(5B12-4BC10-5B12-5B10-)14(5A12-5A10-)5A12-5A9-3(24A8-)24D6-E2A-A2-A12-A2-A-3A4-4AEA-A12-A-2AE3A3-2(9A12-9A2-)9A12-9A6-8(5B12-5B10-)14(5A12-5A10-)5A12-5A9-3(24A8-)24D6-E2A2(-A)14-2(A-)3A4-4AE-A14-A-AE3A3-2(8A14-8A2-)8A14-8A6-2(4B14-4B10-)3(4B14-3BC10-4B14-4B10-)9(C3A14-3AC10-)C3A14-3AC9-4(C4A14-4AC8-)C4A14-4AC7-3(C24AC6-)26D5-E2A-A18-A-3A4-3AEA-A14-A-5A3-2(8A14-8A2-)8A14-8A5-2(5B14-5B8-)C4B14-5B8-5B14-4BC8-C4B14-4BC8-5B14-4BC8-C4B14-5B8-5B14-5B15(8-C4A14-4AC)7-3(C24AC6-)26D4-AE2A-2A16-2A-4A2-4AE3A14-8A-9A2(14-18A)14-9A4-2(5B14-5B8-)5B3(14-4BC8-C4B)2(14-4BC8-5B)14-5B15(8-C4A14-4AC)7-3(C24AC6-)26D4-AE2A2-A16-A2-4A3-3AE2A16-6A2-8A2(16-16A)16-8A4-2(4B16-4B8-)C3B16-4B3(8-C3B16-3BC)8-C3B16-4B8-4B16-4B15(8-C3A16-3AC)7-3(C24AC6-)26D4-2AEA2-A16-A2-E3A2-4AE2A16-7A-8A2(16-16A)16-8A4-2(4B16-4B8-)4B16-3BC8-C3B16-4B8-C3B16-3BC8-C3B16-4B8-4B16-3BC8-4B16-4B15(8-4A16-4A)7-3(26A6-)26D4-2AEA22-E3A3-5A18-5A2-6AE2(18-14A)18-7A4-2(3B18-3B8-)3(C2B18-3B8-3B18-3B8-)14(3A18-3A8-)3A18-3A7-3(26A6-)26D5-AE2A20-AE2A5-3A20-3A4-5AE2(18-6A2-6A)18-6A5-2(3B18-3B8-)3(3B18-2BC8-3B18-3B8-)14(3A18-3A8-)3A18-3A7-3(26A6-)26D5-AE2A20-E3A5-3A20-3A4-5AE2(18-6A2-6A)18-6A6-3(2B18-2B10-)3(2B18-BC10-)2(2B18-2B10-)9(2A18-2A10-)2A18-2A9-4(3A18-3A8-)3A18-3A7-3(26A6-)26D5-AE2A2-A14-A2-E3A5-3A-2A14-2A-3A4-2(8A14-8A2-)8A14-8A6-2(4B14-4B10-)C3B14-4B10-4B14-E2BC10-C3B14-3BC10-4B14-3BC10-C3B14-3BC10-4B14-4B15(10-C3A14-3AC)9-3(C22AC8-)24D5-6AE-A12-A-7A4-7A12-7A4-2(9A12-9A2-)9A12-9A6-3(5B12-5B10-)3(C4B12-4BC10-)2(5B12-5B10-)14(C4A12-4AC10-)C4A12-4AC9-3(C22AC8-)24D6-AE4AE-A10-A-7A5-8A10-8A4-2(10A10-10A2-)10A10-10A7-2(5B10-5B12-)2(C4B10-4BC12-C4B10-5B12-)C4B10-4BC12-5B10-5B11(12-C4A10-4AC)11-3(C5A10-5AC10-)C5A10-5AC9-C22AC2(8-2C20A2C)8-24D7-AE4AE-2A6-2A-4AE2A2(6-10A)4-2(12A6-12A2-)12A6-12A8-2(6B6-6B14-)BC4B6-4BCB14-C5B6-6B14-2C4B6-4BCB14-C5B6-6B14-BC4B6-4BCB14-6B6-6B11(14-C5A6-5AC)13-3(C6A6-6AC12-)C6A6-6AC11-C20AC11-2(C18AC12-)20D9-AE5AE-2A4-2A-3A2E3A6-11A4-11A5-5(12A4-)12A11-2(5B4-5B18-)5B4-3BCB3(18-5B4-3B2C)18-5B4-3BCB18-5B4-5B11(18-5A4-5A)15-4(8A4-8A12-)20A14-2(16A16-)16D12-6AEA-2A2-2A-3AEAE2A7-12A2-12A5-2(13A2-13A4-)13A2-13A13-3(4B2-4B22-)3(4B2-3BC22-)2(4B2-4B22-)10(C3A2-3AC22-)C3A2-3AC20-3(6A2-6A18-)6A2-6A17-16A17-2(14A18-)14D16-2E2A2E-4A-3A3E9-3(28A4-)28A14-2(8B24-)C6BC24-BC6B24-2C5BC24-BC6B24-C6BC24-8B11(24-2C4A2C)23-3(C8AC22-)C8AC21-C10AC21-2(C8AC22-)10D20-3EA5E2A3E12-3A-9A2E5AEA-3A3(6-26A)17-2(4B28-)2(CB)28-2C2B28-3CB28-2C2B28-2(CB)28-4B11(28-C2AC)26-3(3C2A3C24-)3C2A3C23-C8AC23-2(C6AC24-)8D22-AE2A4-AE2A15-3A-5AE3A3E2A-3A10-16A3E3A2(10-22A)753-3(2C4A2C24-)8D25-A4-E20-7A4-7A3(14-18A)757-3(C2AC28-)4D27-E4-A22-5A4-E4A18-7AE6A2(18-14A)916-A8-A3(22-10A)875-
