model
size = 20 23 3, scale = 0.05, origin = -y
material 
  colors = A:#EEE B:#BBB C:#007 D:#004
voxels
-------------------- -------------------- -------------------- -------------------- ---A------------A--- -------------------- -------------------- -------------------- -------------------- -------------------- -------------------- -------------------- -------------------- -------------------- -------------------- -------------------- -------------------- -------------------- -------------------- -------------------- -------------------- -------------------- -------------------- 
---------AA--------- -------------------- ------A------A------ -------------------- ---A------------A--- -------------------- -------------------- -------------------- ---------AA--------- -------------------- -------------------- -------------------- -------------------- -------------------- -------------------- -------------------- -------------------- -------------------- -------------------- -------------------- -------------------- -------------------- -------------------- 
--------AAAA-------- -------ABAAAA------- ------ABBAAAAA------ ---A--ABBAAAAA--A--- -AAA--ABBAAAAA--AAA- AABAAABBBAAAAAAAAAAA ABBBBBBBBAAAAAAAAAAA -ABBBBBBBAAAAAAAAAA- -ABBBBBBBAAAAAAAAAA- --ABBBBBAAAAAAAAAA-- --ABBBAADACCAAAAAA-- ---AAADDDACCCCAAA--- ---ADDDDDACCCCCCA--- ----ADDDDACCCCCA---- ----ADDDDACCCCCA---- -----ADDDACCCCA----- -----ADDDACCCCA----- ------ADDACCCA------ -------ADACCA------- -------ADACCA------- --------AACA-------- --------AAAA-------- ---------AA--------- 
