model
size = 28 18 29, scale = 0.05, origin = -y
material 
  colors = A:#222 B:#444 C:#111 D:#EEE E:#555 F:#DDD
voxels
--ABBBBBBBBBBBBBBBBBBBBBBA-- -BBAAAAAAAAAAAAAAAAAAAAAABB- BBAAAAAAAAAAAAAAAAAAAAAAAABB CAAAAAAAAAAAAAAAAAAAAAAAAAAC BAAAAAAAAAAAAAAAAAAAAAAAAAAB CAAAAAAAAAAAAAAAAAAAAAAAAAAC CAAAAAAAAAAAAAAAAAAAAAAAAAAC BAAAAAAAAAAAAAAAAAAAAAAAAAAB BBAAAAAAAAAAAAAAAAAAAAAAAABB -BBAAAAAAAAAAAAAAAAAAAAAABB- --BBBAABBBBBBBBBBBBBBAABBB-- ---------------------------- ---------------------------- ---------------------------- ---------------------------- ---------------------------- ---------------------------- ---------------------------- 
--AAAAAAAAAAAAAAAAAAAAAAAA-- -ACCCCCCCCCCCCCCCCCCCCCCCCA- AA------------------------AA AA----EE------------EE----AA BA---EDDE----------EDDE---AB BA--EDFFDE--------EDFFDE--AB BA--EDFFDE--------EDFFDE--AB BA---EDDE----------EDDE---AB BA----EE-----AA-----EE----AB -A----------AAAA----------A- --BAAAAAAAAAAAAAAAAAAAAAAB-- ---------------------------- ---------------------------- ---------------------------- ---------------------------- ---------------------------- ---------------------------- ---------------------------- 
--AAAAAAAAAA----AAAAAAAAAA-- -ACCCCCCCCCC----CCCCCCCCCCA- AA------------------------AA AA------------------------AA BA----DD------------DD----AB AA---DDDD----------DDDD---AA AA---DDDD----------DDDD---AA AA----DD------------DD----AA AA------------------------AA -A----------AAAA----------A- --BAAAAAAAABAAAABAAAAAAAAB-- ---------------------------- ---------------------------- ---------------------------- ---------------------------- ---------------------------- ---------------------------- ---------------------------- 
--AAAAAAAAAA----AAAAAAAAAA-- -AAAAAAAAAAB----BAAAAAAAAAA- AA------------------------AA AA------------------------AA BA----DD------------DD----AB AA---DDDD----------DDDD---AA AA---DDDD----------DDDD---AA AA----DD------------DD----AA AA------------------------AA -A------------------------A- --BAAAAABBBBBBBBBBBBAAAAAB-- ------------AAAA------------ ------------AAAA------------ ---------------------------- ---------------------------- ---------------------------- ---------------------------- ---------------------------- 
--AAAAAAAAAA----AAAAAAAAAA-- -AAAAAAAAAB------BAAAAAAAAA- AA------------------------AA AA------------------------AA BA------------------------AB AA------------------------AA AA------------------------AA CA------------------------AC CA------------------------AC -B------------------------B- --BAAABBB----------BBBAAAB-- ---------------------------- ------------AAAA------------ ------------AAAA------------ ---------------------------- ---------------------------- ---------------------------- ---------------------------- 
--AAAAAAAAA------AAAAAAAAA-- -AAAAAAB------------BAAAAAA- A-A----------------------A-A A-A----------------------A-A B-A----------------------A-B A-A----------------------A-A A-A----------------------A-A C-A----------------------A-C C-A----------------------A-C -ABB--------------------BBA- --BAABB--------------BBAAB-- ---------------------------- ---------------------------- ------------AAAA------------ ------------AAAA------------ ---------------------------- ---------------------------- ---------------------------- 
--AAAAAA------------AAAAAA-- ---AAAB--------------BAAA--- ---A--------------------A--- ---------------------------- ---------------------------- ---------------------------- A--------------------------A C--------------------------C C--------------------------C -BBB--------------------BBB- --BAAB----------------BAAB-- ---------------------------- ---------------------------- ---------------------------- ------------AAAA------------ ------------AAAA------------ ---------------------------- ---------------------------- 
---AAAA--------------AAAA--- ----AB----------------BA---- ---------------------------- ---------------------------- ---------------------------- ---------------------------- A--------------------------A C--------------------------C C--------------------------C -BAAB------------------BAAB- --BBBB----------------BBBB-- ---------------------------- ---------------------------- ---------------------------- ---------------------------- ------------AAAA------------ ------------AAAA------------ ---------------------------- 
----AB----------------BA---- ---------------------------- ---------------------------- ---------------------------- ---------------------------- ---------------------------- A--------------------------A C--------------------------C C--------------------------C ---------------------------- ---------------------------- ---------------------------- ---------------------------- ---------------------------- ---------------------------- ---------------------------- ------------AAAA------------ ------------AAAA------------ 
---------------------------- ---------------------------- ---------------------------- ---------------------------- ---------------------------- ---------------------------- A--------------------------A C--------------------------C C--------------------------C ---------------------------- ---------------------------- ---------------------------- ---------------------------- ---------------------------- ---------------------------- ---------------------------- ---------------------------- ------------AAAA------------ 
---------------------------- ---------------------------- ---------------------------- ---------------------------- ---------------------------- ---------------------------- A--------------------------A A--------------------------A A--------------------------A ---------------------------- ---------------------------- ---------------------------- ---------------------------- ---------------------------- ---------------------------- ---------------------------- ---------------------------- ------------AAAA------------ 
---------------------------- ---------------------------- ---------------------------- ---------------------------- ---------------------------- ---------------------------- A--------------------------A A--------------------------A A--------------------------A ---------------------------- ---------------------------- ---------------------------- ---------------------------- ---------------------------- ---------------------------- ---------------------------- ---------------------------- ------------AAAA------------ 
---------------------------- ---------------------------- ---------------------------- ---------------------------- ---------------------------- ---------------------------- A--------------------------A A--------------------------A A--------------------------A ---------------------------- ---------------------------- ---------------------------- ---------------------------- ---------------------------- ---------------------------- ---------------------------- ---------------------------- ------------AAAA------------ 
---------------------------- ---------------------------- ---------------------------- ---------------------------- ---------------------------- ---------------------------- A--------------------------A A--------------------------A A--------------------------A ---------------------------- ---------------------------- ---------------------------- ---------------------------- ---------------------------- ---------------------------- ---------------------------- ---------------------------- ------------AAAA------------ 
---------------------------- ---------------------------- ---------------------------- ---------------------------- ---------------------------- ---------------------------- A--------------------------A A--------------------------A A--------------------------A ---------------------------- ---------------------------- ---------------------------- ---------------------------- ---------------------------- ---------------------------- ---------------------------- ---------------------------- ------------AAAA------------ 
---------------------------- ---------------------------- ---------------------------- ---------------------------- ---------------------------- ---------------------------- A--------------------------A A--------------------------A A--------------------------A ---------------------------- ---------------------------- ---------------------------- ---------------------------- ---------------------------- ---------------------------- ---------------------------- ---------------------------- ------------AAAA------------ 
---------------------------- ---------------------------- ---------------------------- ---------------------------- ---------------------------- ---------------------------- A--------------------------A A--------------------------A A--------------------------A ---------------------------- ---------------------------- ---------------------------- ---------------------------- ---------------------------- ---------------------------- ---------------------------- ---------------------------- ------------AAAA------------ 
---------------------------- ---------------------------- ---------------------------- ---------------------------- ---------------------------- ---------------------------- A--------------------------A A--------------------------A A--------------------------A ---------------------------- ---------------------------- ---------------------------- ---------------------------- ---------------------------- ---------------------------- ---------------------------- ---------------------------- ------------AAAA------------ 
---------------------------- ---------------------------- ---------------------------- ---------------------------- ---------------------------- ---------------------------- A--------------------------A A--------------------------A A--------------------------A ---------------------------- ---------------------------- ---------------------------- ---------------------------- ---------------------------- ---------------------------- ---------------------------- ---------------------------- ------------AAAA------------ 
---------------------------- ---------------------------- ---------------------------- ---------------------------- ---------------------------- ---------------------------- A--------------------------A A--------------------------A A--------------------------A ---------------------------- ---------------------------- ---------------------------- ---------------------------- ---------------------------- ---------------------------- ---------------------------- ---------------------------- ------------A--A------------ 
---------------------------- ---------------------------- ---------------------------- ---------------------------- ---------------------------- ---------------------------- A--------------------------A A--------------------------A A--------------------------A ---------------------------- ---------------------------- ---------------------------- ---------------------------- ---------------------------- ---------------------------- ----------A------A---------- ----------AA----AA---------- -----------AA--AA----------- 
---------------------------- ---------------------------- ---------------------------- ---------------------------- ---------------------------- ---------------------------- A--------------------------A AA------------------------AA AA------------------------AA ---------------------------- ---------------------------- ---------------------------- ------AA------------AA------ -------AA----------AA------- --------AA--------AA-------- ---------AA------AA--------- ---------------------------- ---------------------------- 
---------------------------- ---------------------------- ---------------------------- ---------------------------- ---------------------------- ---------------------------- ---------------------------- -AA----------------------AA- -AA----------------------AA- ---------------------------- ---------------------------- -----A----------------A----- -----AA--------------AA----- ---------------------------- ---------------------------- ---------------------------- ---------------------------- ---------------------------- 
---------------------------- ---------------------------- ---------------------------- ---------------------------- ---------------------------- ---------------------------- ---------------------------- --AA--------------------AA-- --AA--------------------AA-- ---------------------------- ---------------------------- ----AA----------------AA---- ---------------------------- ---------------------------- ---------------------------- ---------------------------- ---------------------------- ---------------------------- 
---------------------------- ---------------------------- ---------------------------- ---------------------------- ---------------------------- -----A----------------A----- ----AA----------------AA---- ---AA------------------AA--- ---A--------------------A--- ---A--------------------A--- ---AA------------------AA--- ----A------------------A---- ---------------------------- ---------------------------- ---------------------------- ---------------------------- ---------------------------- ---------------------------- 
---------------------------- ---------------------------- ---------------------------- ---------------------------- -----A----------------A----- -----A----------------A----- ---------------------------- ---------------------------- ---------------------------- ---------------------------- ---------------------------- ---------------------------- ---------------------------- ---------------------------- ---------------------------- ---------------------------- ---------------------------- ---------------------------- 
---------------------------- -------AAA--------AAA------- ------AAAA--------AAAA------ -----AAA------------AAA----- -----AA--------------AA----- ---------------------------- ---------------------------- ---------------------------- ---------------------------- ---------------------------- ---------------------------- ---------------------------- ---------------------------- ---------------------------- ---------------------------- ---------------------------- ---------------------------- ---------------------------- 
---------------------------- ---------AAA----AAA--------- ---------AAA----AAA--------- ---------------------------- ---------------------------- ---------------------------- ---------------------------- ---------------------------- ---------------------------- ---------------------------- ---------------------------- ---------------------------- ---------------------------- ---------------------------- ---------------------------- ---------------------------- ---------------------------- ---------------------------- 
---------------------------- -----------AAAAAA----------- -----------AAAAAA----------- ---------------------------- ---------------------------- ---------------------------- ---------------------------- ---------------------------- ---------------------------- ---------------------------- ---------------------------- ---------------------------- ---------------------------- ---------------------------- ---------------------------- ---------------------------- ---------------------------- ---------------------------- 
