model
size = 32 32 29, scale = 0.05, origin = -y
material 
  colors = A:#6F9 B:#966 C:#FFF D:#633 E:#C69 F:#500 G:#F93 H:#FC0 I:#CF9 J:#CC0 K:#EEE L:#AAA M:#111
voxels
21-18(A2-3A26-)5(A2-8A21-)8(A2-3A26-)A2-8(3A23-2(A2-))3A13-11A2-3(A2-3A13-A12-)A2-3A13-6A6(7-A2-3A18-A)7-2(A2-8A13-A7-4(A2-8A21-)27(A2-3A26-))A2-8A13-A7-A2-2AD5A3(21-A2-8A)21-14(A2-3A26-)A2-3A22-D3-A2-3A24-D-5(A2-3A26-)5(A2-3A12-A13-)A2-3A2-D9-A13-A2-3AD4A7-7A7-A2-2ABD4A21-A2-ADB5A2(21-A2-8A)21-14(A2-3A26-)A2-3A21-2B3-A2-3A17-2DB3-DB-A2-3A17-D2B6-A2-3A26-A2-3A18-D7-A2-3A17-F8-A2-3A16-E9-A2-3A12-A4-E8-4(A2-3A26-)A2-3A-DF23-A2-3A2B3A13-A7-A2-2A2B4A21-A2-D2B5A21-A-F2(8A21-A2-)13(3A26-A2-)3A22-B3-A2-3A17-3E5B-A2-3A17-D2BD4B-A2-3A17-3B-D2B2-A2-3A17-DBD2-2D2-A2-3A17-3B6-A2-3A3-BD12-F8-A2-3A4-D7-A2-ED4-E4-A2-3A12-A3-ED8-A2-3A16-D2E7-A2-3A18-2E6-A2-3A19-E6-A2-3A2-F17-E5-A2-3A-BF23-A2-3ABF3A13-2A6-A2-4BF3A14-A6-A-D4B4A21-2F2D7A21-A2-8A21-12(A2-3A26-)A2-3A22-2(D-)A2-3A19-E-2B3-B2-3A18-7B-B2-3A16-D8BFB-D3A16-D8B-FBD3A4-B8-EB2-7B2FA2B3A13-2D-FB-4BDF2B2-3A3-2B4-E2-D2F-FB3FB2F3B2-3A3-BD7-2F4B3-2FD3B2-3ABD2-D5-ADAFB-2BE4-DBFB2-2ADB10-2A-F3BF2D2BDB-A2-3A11-A2-4F2(2BD)B-A2-3A11-A3-5B5D-A2-3A-2B15-3B2D3-A2-3A3B14-2ADE5-ADB2A3B3A7-D4-3AE5-AB-4BF3A13-2A6-A5BF4A12-D-A6-2BD2B6A21-A2-8A21-9(A2-3A26-)3(A2-3A4-A21-)A2-3A4-A15-3BDBDA2-3A4-A14-7B2D-3A4-A11-D-10BD3A4-A10-15BDA4-A9-BDB-7BFA2BADA4-A7-E15B-ABD-D2-A5-5BF4B-7B-BA2DB-BF4-D19BABA2B-BF4-D17BFBDADBF-2F4-2DBF5B2D7BFB2A2B3-F3-E2DBFB-B2D7BF2D-A2D2B2-D5-DB2F2-8BF-D2BAD3B2-A6-DB2F9BF-D8BD8-DB2FBF4BD3B2D6BD7-5DE3DB2D-D2BD6BD3A6-D2(B-)2B4DB3D6BD4A7-D3-DBED3B2F7BD4A10-D-DABF-F2-2B2D2B6A10-2D2-AF5-A2-8A18-B2-9(A2-3A26-)2(A2-3A4-A21-)A2-3A4-A17-D2E-A2-3A4-A14-2D2B3DA2-3A4-A13-8B2D-3A4-A11-12B2D2A4-A10-16BD4-A8-E8B4-7B3-A7-7B7-8BD-B7-3B11-A7B-2B6-3B10-9BF2-B5-2B12-9BF2-A5-B12-11B-2B3-2E13-C10B-2B5-D13-10B-2B5-D2B10-14B6-D2B6-15B8-D3B6-14B2A7-3B-2B2-12BD4A8-5B2-11BD5A9-D2BF2-BF5BD2BD6A10-D2B-A4B2-A-D8A15-4B2-9(A2-3A26-)2(A2-3A4-A21-)A2-3A4-A15-EBFE2-A2-3A4-A14-4B2FDA2-3A4-A12-D8B2D-3A4-A11-D11B3DA4-A9-D4B-B-9BDB3-A8-D6B3-B2-8B2-B7-D3B2-B7-9B-B4-F-4B11-8B-2B5-D4B11-A-6B2-B5-DB14-A-7B-B5-DB14-A2-8B3-2EDB11-C2-A2-2A6B5-2B14-A2-A4B-BA5-3B13-A2-8B5-4B12-A-5B-2B7-D4B10-A8B2A7-D3B6-4BA7B3A7-D5B3-5BA5B5A8-D4BF3-8BD6A10-5B2-6BDB7A12-B4-3B-9(A2-3A26-)A2-3A4-A21-A2-3A4-A17-E3-A2-3A4-A14-2D2BD2-A2-3A4-A11-D-6BDFA2-3A4-A9-D-10B2F-3A4-A10-D7B-4B3DA4-A9-4B2-2B2-7B2D3-A7-7B-B4-2B-5BD2-A6-7B8-A-6BD-A3-F5B-B10-A2-8B4-D2B-2B11-A2-A5B-D5-DB-B12-A2-2A4B-D4-D2B14-A2-2A3B-BD4-3B14-A2-3A4BD5-2B14-A2-3A3BDA4-5B12-A2-2A4BD6-5B11-A2-A6B7-3B12-A2-6B2A7-4B8-2BA7B3A7-4B5-5B2(A2B)5A8-7B2-7BDAD5A10-2(6B-)D7A11-9B-2B-3A19-B6-7(A2-3A26-)A2-3A5-12A2(9-A2-3A4-13A)4-2E3-A2-3A4-13A-3F3D2-A2-3A4-10A4F8BA2-3A4-9AF7B-6BF3A4-9A5B8-3BFBA4-8A5B3-C5-A6B3-8A5B9-A6B2D-6A4B2AB9-A-6BD-4A7B2A9-A2-8B3AD4B4A9-A2-8B3A4B5A9-A2-A7B3AD2B6A9-A2-3A5B3AD3B5A9-A2-3A-4B3AD2B6A9-A2-2(3A5B)4A9-A2-2A5BD4A6B2A9-A2-2A4BD-5A3BAB2A9-A2-A4BD7A6BA7-B-A-BA2B2D9A5BA6-2B-A2BA2D13A6B4-6BD17A13BD19A13B3A5-12AD-2B5-7(A2-3A26-)2(A2-3A5-12A9-)A2-3A5-12A4-E4-A2-3A5-12AD2BFB2DF-A2-3A5-8AD11BFA2-3A5-7AD2BA10B3F3A5-7A7B6-4B3F5-6A6B9-A2-A3BD3-6A7B8-A2-A4BD2-5A2B2A3B9-A2-A5BD-3AD4BAB2A9-A2-A6BD2AD6B3A9-5C5BD3A5B4A2(9-5C6B2A4B6A)9-5CA2-3B2AD3B6A9-5CA-4B2AD6B3A9-5CA-4B3AD5B3A9-5CA-3B-4AD6BA9-5CA2B8AD5BA9-4C3BD9AD5B6-4B-BABD12AD7B4-3B-BD15A9B-5BD18A13B-3A5-11A2B4D4-7(A2-3A26-)2(A2-3A5-12A9-)A2-3A5-12A3-2E4-A2-3A5-10A2B3D2B2F2-A2-3A5-8A13BA2-3A5-7AD2BA4B5-3BD3A5-6AD5B9-3BD2F5-7AD3BA9-A-4B2D3-6AD4BA9-A-B3A3B2-3AD4BA2BA9-A2-3A4B-2AD4B2AB2A9-A2-3A5BAD4B6A9-5CA2(-B)D2AD4B5A9-5CA-B2-D2ADB8A9-5CA4-D2AD5B4A9-5CA2-2BDAD5B5A9-5CA2-2BD2AD4B5A9-5CA2-B2D2A7B3A9-5CA-BD2-4A4B4A9-5C2BD8A4B3A9-4C3B10AD6B6-B-A2-3B12AD4B7-3B-BD15AD15B18AD8B5D3A5-12A-6B2-A2-3A21-2E3-6(A2-3A26-)2(A2-3A5-12A9-)A2-3A5-12A2-2E5-A2-3A5-11AD2BF2B2FB-A2-3A5-9AD3B-2B2-3BA2-3A5-7A6B7-4B3A5-7A4BA9-A3B3D4-5AD3B3A9-A6BD3-4AD4B3A9-A-B2A3BD2-3AD3BAB3A9-A2-2A2(2B-)3AD3B5A9-A2-2A6B3A5B4A9-5CA-B2-B2A2BA2B5A9-5CA-B2-B2A3B7A9-5CA-B2-B2A6B4A9-7C3-D2A6B4A9-5CA2-3B3AD2B6A9-5CA2-2BD3A3B6A9-5C5B-4A4B4A9-4C3BD8A4B3A9-4C2BD10A4B2A9-A-4B12A4BA9-4B15A9B2-4B2D17A13B-3A5-12A-6BD-A2-3A21-2E3-6(A2-3A26-)2(A2-3A5-12A9-)A2-3A5-12A-F4-E2-A2-3A5-11A5BFBFE-A2-3A5-9AD5B2-2B2FA2-3A5-7AD4B6-B-B3F3A5-6A4B2A7-B-3B3FD4-5AF3B3A9-A7B3-5AF4B2A9-ABC2A3B2D-4AF5B2A9-A2-2A5BD3A3BA2B3A9-A2-2AB-3BFA3B8A9-5C2(B-)BFA4B7A9-5CA-B2-FADB9A9-5CA-B2-FA3BC7A9-5CA2-3BAF2B8A9-5CA2-2BF2AF2B7A9-5CA-4B3AD2B6A9-5CA4B-4A3B5A9-4C4B8A2BAB3A9-4C2BD10A2B4A9-A2-2BD12A2B2A2B3-B4-A3B15A9B2-3BD-18A11BD2-3A5-12AD4B4DA2-3A22-E3-6(A2-3A26-)2(A2-3A5-12A9-)A2-3A5-10ADA-3B3-E-A2-3A5-9AD10B-A2-3A5-8A12BED2-3A5-7A9B-5B3D2A5-7A3BA4B4-6BD2F4-6A4B2AB8-A7B3-5A6BA9-A2C2A5B-3AF4BAB2A9-A2-3A4BFADF5B4A9-A2-2A2C3BFAD4B6A9-7CB-2BAD5B5A9-7CB2-FAD2B8A9-7CB2-BF2BAC7A9-5CA2-2BFAF2BC7A9-5CA-3BFA4B7A9-5CA-3BD2AD3B6A9-5CA4B-3AD3B5A9-4C4B7AD5B2A9-4C3B9AD6B9-A-3BD11AD7B2-B4-4B15AD15B18AD12B-3A5-12AD9B2-3A18-4B3-DA2-3A20-E5-7(A2-3A26-)A2-3A16-2D-3D4-A2-3A14-D7B3D-A2-3A13-D11B2DB-3A12-D6B-10B2A12-D3B8-7BDB10-D4B9-BA7B8-D5B10-A2-2A4BF3-F7B11-A2-3A3BF2-F6B13-A2-2A2C4B-F5B14-6C2B-2BF3B-B15-6C3B-2F3B17-7CB-5B-C16-5CA2-7BC16-5CA2(-4B)16-5CA-4B2-4B15-5C5B5-3B9-E4-4C4B8-6B10-3C4B10-7B4-A3-A-4B13-9B4-A3B2A14-14B-3A18-8BA2-3A20-5B-A2-3A20-2B4-9(A2-3A26-)A2-3A18-B7-A2-3A17-2B5E2-A2-3A14-5ELC2L4EB-3A13-2EB10-3EB2A12-2E12C2B4EF10-BE15CL2C3E8-2EL17C2AB2E5-B2E2B17CA2CB2E3-2E3B22CL2E-2E2CB24CL3EB26CK2(BE)B23CA2-K2E-2EB22CA-B2E4-2E21CA-2E6-2E20CA2E8-2E2B-16C2E10-2E3B14C2EB11-2EKB12CB2EA14-3E4B5CB2EB2A16-12E-3A18-7EB13(A2-3A26-)A2-3A20-L5-A2-3A15-5L3C3LA2-3A14-L12CL-3A13-L13C2-3A13-15C-A2CL10-L17CA3CL7-L17C-6C6-L25C5-L26C-K3-K25CK6-2K22C2K8-K21CK10-K20CK11-K18CA13-2K16CA15-K11C2K3A15-11KC16(2-3A26-A)2-3A19-5C2-A2-3A17-2C5G2CA2-3A16-C9GA2-3A14-2C11GC-3A13-3C11GC-3A13-2C3(13GC3A11-4C)13GC3A12-3C13GC3A13-3C11GC-3A15-C11GC-3A16-C9GA2-3A17-2C5G2CA2-3A19-5C2-17(A2-3A26-)A2-3A23-C2-A2-3A25-CA2-3A19-5H2-A2-3A18-7H-A2-3A17-9HA2(2-3A16-11H)2-3A16-5HI5H2(2-3A16-11H)2-3A17-9HA2-3A18-7H-A2-3A19-5H2-14(A2-3A26-)8(A31-)A24-5I2-A23-7I-2(A22-9I)A22-4IJ4I2(A22-9I)A23-7I-A24-5I2-24(A31-)A25-3J3-A24-5J2-A23-7J-A23-3JM3J-A23-7J-A24-5J2-A25-3J3-26(A31-)A25-3M3-A24-5M2-A24-2M-2M2-A24-MC3M2-A25-3M3-112(A31-)A10-
