model
size = 14 25 14, scale = 0.05, origin = -y
material 
  colors = A:#1C1D20
voxels
----AAAAAA---- ----AAAAAA---- ----AAAAAA---- ----AAAAAA---- ----AAAAAA---- ----AAAAAA---- ----AAAAAA---- ----AAAAAA---- ----AAAAAA---- ----AAAAAA---- ----AAAAAA---- ----AAAAAA---- ----AAAAAA---- ----AAAAAA---- -------AAA---- -------AAA---- -------AAA---- -------AAA---- -------AAA---- -------AAA---- -------------- -------------- -------------- -------------- -------------- 
--AA------AA-- --AA------AA-- --AA------AA-- --AA------AA-- --AA------AA-- --AA------AA-- --AA------AA-- --AA------AA-- --AA------AA-- --AA------AA-- --AA------AA-- --AA------AA-- --AA------AA-- --AA------AA-- ----------AA-- ----------AA-- ----------AA-- ----------AA-- ---------AAA-- ---------AA--- -------AAAA--- -------AAA---- -------------- -------------- -------------- 
-A----------A- -A----------A- -A----------A- -A----------A- -A----------A- -A----------A- -A----------A- -A----------A- -A----------A- -A----------A- -A----------A- -A----------A- -A----------A- -A----------A- ------------A- ------------A- ------------A- -----------AA- ----------AA-- ---------AAA-- ---------AAA-- ---------AA--- -------AAA---- -------------- -------------- 
-A----------A- -A----------A- -A----------A- -A----------A- -A----------A- -A----------A- -A----------A- -A----------A- -A----------A- -A----------A- -A----------A- -A----------A- -A----------A- -A----------A- ------------A- ------------A- ------------A- ------------A- -----------AA- ----------AAA- ---------AAA-- ---------AAA-- -------AAAA--- -------------- -------------- 
A------------A A------------A A------------A A------------A A------------A A------------A A------------A A------------A A------------A A------------A A------------A A------------A A------------A A------------A -------------A -------------A -------------A -------------A ------------A- -----------AA- ----------AAA- ---------AAA-- ---------AA--- -------AAA---- -------------- 
A------------A A------------A A------------A A------------A A------------A A------------A A------------A A------------A A------------A A------------A A------------A A------------A A------------A A------------A -------------A -------------A -------------A -------------A -------------A ------------A- -----------AA- ----------AA-- ---------AAA-- -------AAA---- -------A------ 
A------------A A------------A A------------A A------------A A------------A A------------A A------------A A------------A A------------A A------------A A------------A A------------A A------------A A------------A -------------A -------------A -------------A -------------A -------------A -------------A ------------A- -----------AA- ----------AA-- -------AAAA--- -------AA----- 
A------------A A------------A A------------A A------------A A------------A A------------A A------------A A------------A A------------A A------------A A------------A A------------A A------------A A------------A -------------A -------------A -------------A -------------A -------------A -------------A ------------A- -----------AA- ----------AA-- -------AAAA--- -------AA----- 
A------------A A------------A A------------A A------------A A------------A A------------A A------------A A------------A A------------A A------------A A------------A A------------A A------------A A------------A -------------A -------------A -------------A -------------A -------------A ------------A- -----------AA- ----------AA-- ---------AAA-- -------AAA---- -------A------ 
A------------A A------------A A------------A A------------A A------------A A------------A A------------A A------------A A------------A A------------A A------------A A------------A A------------A A------------A -------------A -------------A -------------A -------------A ------------A- -----------AA- ----------AAA- ---------AAA-- ---------AA--- -------AAA---- -------------- 
-A----------A- -A----------A- -A----------A- -A----------A- -A----------A- -A----------A- -A----------A- -A----------A- -A----------A- -A----------A- -A----------A- -A----------A- -A----------A- -A----------A- ------------A- ------------A- ------------A- ------------A- -----------AA- ----------AAA- ---------AAA-- ---------AAA-- -------AAAA--- -------------- -------------- 
-A----------A- -A----------A- -A----------A- -A----------A- -A----------A- -A----------A- -A----------A- -A----------A- -A----------A- -A----------A- -A----------A- -A----------A- -A----------A- -A----------A- ------------A- ------------A- ------------A- -----------AA- ----------AA-- ---------AAA-- ---------AAA-- ---------AA--- -------AAA---- -------------- -------------- 
--AA------AA-- --AA------AA-- --AA------AA-- --AA------AA-- --AA------AA-- --AA------AA-- --AA------AA-- --AA------AA-- --AA------AA-- --AA------AA-- --AA------AA-- --AA------AA-- --AA------AA-- --AA------AA-- ----------AA-- ----------AA-- ----------AA-- ----------AA-- ---------AAA-- ---------AA--- -------AAAA--- -------AAA---- -------------- -------------- -------------- 
----AAAAAA---- ----AAAAAA---- ----AAAAAA---- ----AAAAAA---- ----AAAAAA---- ----AAAAAA---- ----AAAAAA---- ----AAAAAA---- ----AAAAAA---- ----AAAAAA---- ----AAAAAA---- ----AAAAAA---- ----AAAAAA---- ----AAAAAA---- -------AAA---- -------AAA---- -------AAA---- -------AAA---- -------AAA---- -------AAA---- -------------- -------------- -------------- -------------- -------------- 
