model
size = 24 16 22, scale = 0.05, origin = -y
material 
  colors = A:#F6C B:#F0C C:#FF0 D:#FC6 E:#FF6 F:#F60 G:#FC0 H:#F06 I:#FFF J:#FC3 K:#CCC L:#F9F M:#FF9 N:#F9C O:#F33 P:#CF3 Q:#F09 R:#F90 S:#F96 T:#FFC U:#F30 V:#F63 W:#CF0 X:#F0F Y:#FC9 Z:#F3C Aa:#F36 Ab:#F93 Ac:#F99 Ad:#CF6 Ae:#CC3 Af:#CC6 Ag:#F6F Ah:#F00 Ai:#CCF Aj:#FCC Ak:#FF3 Al:#F03 Am:#F3F An:#CFC Ao:#F66 Ap:#FCF Aq:#CC0 Ar:#F69 As:#F39 At:#CC9 Au:#CF9 Av:#CFF Aw:#111
voxels
- - - - - - - - - - - - - - - - - - - - - - - -   - - - - A - - - - - - - - - - - - - - A - - - -   - - - - A - - - - - - - - - - - - - - A - - - -   - - - - A - - - - - - - - - - - - - - A - - - -   - - - - A - - - - - - - - - - - - - - A - - - -   - - - - A - - - - - - - - - - - - - - A - - - -   - - - - A - - - - - - - - - - - - - - A - - - -   - - - - A - - - - - - - - - - - - - - A - - - -   - - - - - - - - - - - - - - - - - - - - - - - -   - - - - - - - - - - - - - - - - - - - - - - - -   - - - - - - - - - - - - - - - - - - - - - - - -   - - - - - - - - - - - - - - - - - - - - - - - -   - - - - - - - - - - - - - - - - - - - - - - - -   - - - - - - - - - - - - - - - - - - - - - - - -   - - - - - - - - - - - - - - - - - - - - - - - -   - - - - - - - - - - - - - - - - - - - - - - - -   
- - - - - - - - - - - - - - - - - - - - - - - -   - - - - - - - - - - - - - - - - - - - - - - - -   - - - - - - - - - - - - - - - - - - - - - - - -   - - - - - - - - - - - - - - - - - - - - - - - -   - - - - - - - - - - - - - - - - - - - - - - - -   - - - - - - - - - - - - - - - - - - - - - - - -   - - - - - - - - - - B - - B - - - - - - - - - -   - - - - A - - - - - B - - B - - - - - A - - - -   - - - - - - - - - - B - - B - - - - - - - - - -   - - - - - - - - - - B - - B - - - - - - - - - -   - - - - - - - - - - - - - - - - - - - - - - - -   - - - - - - - - - - - - - - - - - - - - - - - -   - - - - - - - - - - - - - - - - - - - - - - - -   - - - - - - - - - - - - - - - - - - - - - - - -   - - - - - - - - - - - - - - - - - - - - - - - -   - - - - - - - - - - - - - - - - - - - - - - - -   
- - - - - - - - - - - - - - - - - - - - - - - -   - - - - - - - - - - - - - - - - - - - - - - - -   - - - - - - - - - - - - - - - - - - - - - - - -   - - - - - - - - - - - - - - - - - - - - - - - -   - - - - - - - - - - - - - - - - - - - - - - - -   - - - - - - - - - - - - - - - - - - - - - - - -   - - - - - - - - - - - - - - - - - - - - - - - -   - - - - A - - - - B AaD I E B - - - - A - - - -   - - - - - - - - - B B AtC B B - - - - - - - - -   - - - - - - - - - B B W M B B - - - - - - - - -   - - - - - - - - - B B AjW B B - - - - - - - - -   - - - - - - - - - B B B B B B - - - - - - - - -   - - - - - - - - - - - - - - - - - - - - - - - -   - - - - - - - - - Aw- - - - Aw- - - - - - - - -   - - - - - - - - - - - - - - - - - - - - - - - -   - - - - - - - - - - - - - - - - - - - - - - - -   
- - - - - - - - - - - - - - - - - - - - - - - -   - - - - - - - - - - - - - - - - - - - - - - - -   - - - - - - - - - - - - - - - - - - - - - - - -   - - - - - - - - - - - - - - - - - - - - - - - -   - - - - - - - - - - - - - - - - - - - - - - - -   - - - - - - - - - - - - - - - - - - - - - - - -   - - - - - - - - - - - - - - - - - - - - - - - -   - - - - A - - - - - F AjC H - - - - - A - - - -   - - - - - - - - - F K AmAcH G - - - - - - - - -   - - - - - - - - - Y O AiAeP Ao- - - - - - - - -   - - - - - - - - - Y D AaL AfAh- - - - - - - - -   - - - - - - - - - M H I AaC G - - - - - - - - -   - - - - - - - - - AtB B B B Q - - - - - - - - -   - - - - - - - - - B B B B B B - - - - - - - - -   - - - - - - - - - - - - - - - - - - - - - - - -   - - - - - - - - - - - - - - - - - - - - - - - -   
- - - - - - - - - - - - - - - - - - - - - - - -   - - - - - - - - - - - - - - - - - - - - - - - -   - - - - - - - - - - - - - - - - - - - - - - - -   - - - - - - - - - - - - - - - - - - - - - - - -   - - - - - - - - - - - - - - - - - - - - - - - -   - - - - - - - - - - - - - - - - - - - - - - - -   - - - - - - - - - - - - - - - - - - - - - - - -   - - - - A - - - - AeG I AcD F - - - - A - - - -   - - - - - - - - - Y F AaG AqK - - - - - - - - -   - - - - - - - - - E K V AhI O - - - - - - - - -   - - - - - - - - - AnO U AqC D - - - - - - - - -   - - - - - - - - - I D M AbM H - - - - - - - - -   - - - - - - - - - AoH AcJ W V - - - - - - - - -   - - - - - - - - - J B AdR B Ad- - - - - - - - -   - - - - - - - - - - - - - - - - - - - - - - - -   - - - - - - - - - - - - - - - - - - - - - - - -   
- A - - - - - - - - - - - - - - - - - - - - A -   - A - - - - - - - - - - - - - - - - - - - - A -   - A - - - - - - - - - - - - - - - - - - - - A -   - A - - - - - - - - - - - - - - - - - - - - A -   - A - - - - - - - - - - - - - - - - - - - - A -   - A - - - - - - - - - - - - - - - - - - - - A -   - A - - - - - - - - - - - - - - - - - - - - A -   - A - - A - - - - C C U AoAkG - - - - A - - A -   - - - - - - - - - G Y P AeZ F - - - - - - - - -   - - - - - - - - - F AdAaY AlK - - - - - - - - -   - - - - - - - - - K X AmE J O - - - - - - - - -   - - - - - - - - - O ArArAnO D - - - - - - - - -   - - - - - - - - - D U B I AaH - - - - - - - - -   - - - - - - - Aw- H P AsAoC V - Aw- - - - - - -   - - - - - - - - - - Aw- - Aw- - - - - - - - - -   - - - - - - - - - - Aw- - Aw- - - - - - - - - -   
- - - - - - - - - - - - - - - - - - - - - - - -   - - - - - - - - - - - - - - - - - - - - - - - -   - - - - - - - - - - - - - - - - - - - - - - - -   - - - - - - - - - - - - - - - - - - - - - - - -   - - - - - - - - - - - - - - - - - - - - - - - -   - - - - - - - - - - - - - - - - - - - - - - - -   - - - - - - - - - - - - - - - - - - - - - - - -   - A - - A A A B B AbX V G AkC B B A A A - - A -   - - - - - - - B B W AgU AoN Y B B - - - - - - -   - - - - - - - B B AgF M AhApAdB B - - - - - - -   - - - - - - - B B Z N AcG U X B B - - - - - - -   - - - - - - - B B Y L AdQ AiArB B - - - - - - -   - - - - - - - B B AkAvAhD E U B B - - - - - - -   - - - - - - - B B AdAjS H AbP B B - - - - - - -   - - - - - - - - - B AbB B AkB - - - - - - - - -   - - - - - - - - - B B B B B B - - - - - - - - -   
- - - - - - - - - - - - - - - - - - - - - - - -   - - - - - - - - - - - - - - - - - - - - - - - -   - - - - - - - - - - - - - - - - - - - - - - - -   - - - - - - - - - - - - - - - - - - - - - - - -   - - - - - - - - - - - - - - - - - - - - - - - -   - - - - - - - - - - - - - - - - - - - - - - - -   - - - - - - - - - - - - - - - - - - - - - - - -   - A - - - - - U O - - - - - - O P - - - - - A -   - - - - - - - AiAaA A A A A A AiAl- - - - - - -   - - - - - - - E C S AjX O K F B W - - - - - - -   - - - - - - - AbJ AhAeAgD AiN AdAb- - - - - - -   - - - - - - - AkAuN C A AtS L AsY - - - - - - -   - - - - - - - Z E D P U W AhAvAoAs- - - - - - -   - - - - - - - B B B B B B B B F Ap- - - - - - -   - - - - - - - - - B B B B B B - - - - - - - - -   - - - - - - - - - B B B B B B - - - - - - - - -   
- - - - - - - - - - - - - - - - - - - - - - - -   - - - - - - - - - - - - - - - - - - - - - - - -   - - - - - - - - - - - - - - - - - - - - - - - -   - - - - - - - - - - - - - - - - - - - - - - - -   - - - - - - - - - - - - - - - - - - - - - - - -   - - - - - - - - - - - - - - - - - - - - - - - -   - - - - - - - - - - - - - - - - - - - - - - - -   - A - - - - - A F - - - - - - AhR - - - - - A -   - - - - - - - M N A A A A A A AgZ - - - - - - -   - - - - - - - L L AcAlX I E AjT S - - - - - - -   - - - - - - - AcAvB M ArAsAbAeH R - - - - - - -   - - - - - - - B AjR T U C AkC E T - - - - - - -   - - - - - - - R AbQ AeP AcZ P T Am- - - - - - -   - - - - - - - Q W P AgAaAeAlAkK Q - - - - - - -   - - - - - - - - - B B AmL B B - - - - - - - - -   - - - - - - - - - - - - - - - - - - - - - - - -   
- - - - - - - - - - - - - - - - - - - - - - - -   - - - - - - - - - - - - - - - - - - - - - - - -   - - - - - - - - - - - - - - - - - - - - - - - -   - - - - - - - - - - - - - - - - - - - - - - - -   - - - - - - - - - - - - - - - - - - - - - - - -   - - - - - - - - - - - - - - - - - - - - - - - -   - - - - - - - - - - - - - - - - - - - - - - - -   - A - - - - - AcP - - - - - - B Ad- - - - - A -   - - - - - - - AiAvA - A A - A AkAh- - - - - - -   - - - - - - - AtL AnU M U L AlApS - - - - - - -   - - - - - - - N Q I D T AmAcM AcAn- - - - - - -   - - - - - - - AfA AoC AeAmB T AiAs- - - - - - -   - - - - - - - X Z J G AgE R AeAtL - - - - - - -   - - - - - - - AgM F F I AfQ AgN A - - - - - - -   - - - - - - - - AfB B L Q B B Af- - - - - - - -   - - - - - - - - - - - - - - - - - - - - - - - -   
- - - - - - - - - - - - - - - - - - - - - - - -   - - - - - - - - - - - - - - - - - - - - - - - -   - - - - - - - - - - - - - - - - - - - - - - - -   - - - - - - - - - - - - - - - - - - - - - - - -   - - - - - - - - - - - - - - - - - - - - - - - -   - - - - - - - - - - - - - - - - - - - - - - - -   - - - - - - - - - - - - - - - - - - - - - - - -   - A A A A A A AjM - - - - - - O AqA A A A A A -   - - - - - - - AbAtA - A A - A AaG - - - - - - -   - - - - - - - W J AjH L AjAtU C T - - - - - - -   - - - - - - - K A H V AaAmN D J I - - - - - - -   - - - - - - - AiV AtAdG AiAfC AuV - - - - - - -   - - - - - - - S U AvN AoAaX G E B - - - - - - -   - - - - - - - AhD AjA AhI AgF V An- - - - - - -   - - - - - - - - C B B G AsB B X - - - - - - - -   - - - - - - - - - - - - - - - - - - - - - - - -   
- - - - - - - - - - - - - - - - - - - - - - - -   - - - - - - - - - - - - - - - - - - - - - - - -   - - - - - - - - - - - - - - - - - - - - - - - -   - - - - - - - - - - - - - - - - - - - - - - - -   - - - - - - - - - - - - - - - - - - - - - - - -   - - - - - - - - - - - - - - - - - - - - - - - -   - - - - - - - - - - - - - - - - - - - - - - - -   - - - - - - - E D - - - - - - F Ai- - - - - - -   - - - - - - - V C A - A A - A N E - - - - - - -   - - - - - - - X G AiH C AiW H L Ab- - - - - - -   - - - - - - - S F B H G S K V AvAk- - - - - - -   - - - - - - - AlK AdP F AhAiAdAjZ - - - - - - -   - - - - - - - AnO AsAfK N S N AbAl- - - - - - -   - - - - - - - ArD AoC O D AhA W J - - - - - - -   - - - - - - - - H B B D AqB B K - - - - - - - -   - - - - - - - - - - - - - - - - - - - - - - - -   
- - - - - - - - - - - - - - - - - - - - - - - -   - - - - - - - - - - - - - - - - - - - - - - - -   - - - - - - - - - - - - - - - - - - - - - - - -   - - - - - - - - - - - - - - - - - - - - - - - -   - - - - - - - - - - - - - - - - - - - - - - - -   - - - - - - - - - - - - - - - - - - - - - - - -   - - - - - - - - - - - - - - - - - - - - - - - -   - - - - - - - F S - - - - - - P T - - - - - - -   - - - - - - - AuR A - A A - A AvAv- - - - - - -   - - - - - - - K T AnO F T X H L G - - - - - - -   - - - - - - - I AmArAaAeAvS H Q Al- - - - - - -   - - - - - - - AaQ S C ApG AlP A M - - - - - - -   - - - - - - - V Z AcJ AkAlAnAfZ T - - - - - - -   - - - - - - - U R G AuAjM ArC M Ae- - - - - - -   - - - - - - - - O B B AmT B B Af- - - - - - - -   - - - - - - - - - - - - - - - - - - - - - - - -   
- - - - - - - - - - - - - - - - - - - - - - - -   - - - - - - - - - - - - - - - - - - - - - - - -   - - - - - - - - - - - - - - - - - - - - - - - -   - - - - - - - - - - - - - - - - - - - - - - - -   - - - - - - - - - - - - - - - - - - - - - - - -   - - - - - - - - - - - - - - - - - - - - - - - -   - - - - - - - - - - - - - - - - - - - - - - - -   - - - - - - - I Ap- - - - - - M Ag- - - - - - -   - - - - - - - V AqA - A A - A AtT - - - - - - -   - - - - - - - B ApP J AiArK O J H - - - - - - -   - - - - - - - AnR AkAuE B I AaA E - - - - - - -   - - - - - - - AjZ ApE AbAsAaC V T - - - - - - -   - - - - - - - J S AqV AkAoV J U K - - - - - - -   - - - - - - - N R ApX Z F U AuD D - - - - - - -   - - - - - - - - T B B AlAuB B C - - - - - - - -   - - - - - - - - - - - - - - - - - - - - - - - -   
- - - - - - - - - - - - - - - - - - - - - - - -   - - - - - - - - - - - - - - - - - - - - - - - -   - - - - - - - - - - - - - - - - - - - - - - - -   - - - - - - - - - - - - - - - - - - - - - - - -   - - - - - - - - - - - - - - - - - - - - - - - -   - - - - - - - - - - - - - - - - - - - - - - - -   - - - - - - - - - - - - - - - - - - - - - - - -   A A A A A A A Q D - - - - - - D E A A A A A A A   - - - - - - - E H A - A A - A C An- - - - - - -   - - - - - - - X V O AhH AgB J G I - - - - - - -   - - - - - - - AgAdAvN P A AnAuF Ao- - - - - - -   - - - - - - - F N K D AfU AjE K J - - - - - - -   - - - - - - - N A AbAqC AmJ V O F - - - - - - -   - - - - - - - L M W I Y AmN X D Ae- - - - - - -   - - - - - - - - L B B AdE B B H - - - - - - - -   - - - - - - - - - - - - - - - - - - - - - - - -   
- - - - - - - - - - - - - - - - - - - - - - - -   - - - - - - - - - - - - - - - - - - - - - - - -   - - - - - - - - - - - - - - - - - - - - - - - -   - - - - - - - - - - - - - - - - - - - - - - - -   - - - - - - - - - - - - - - - - - - - - - - - -   - - - - - - - - - - - - - - - - - - - - - - - -   - - - - - - - - - - - - - - - - - - - - - - - -   A - - - - - - AmAf- - - - - - S J - - - - - - A   - - - - - - - AmC A - A A - A R O - - - - - - -   - - - - - - - E Y R AbAhZ X AhT Aa- - - - - - -   - - - - - - - AfAdZ W S M AgN AmC - - - - - - -   - - - - - - - Q X S K AnAfF D Q J - - - - - - -   - - - - - - - E ArR AiAsB N AqZ Au- - - - - - -   - - - - - - - X U T S L AkL I R E - - - - - - -   - - - - - - - - P B B A ApB B O - - - - - - - -   - - - - - - - - - - - - - - - - - - - - - - - -   
- - - - - - - - - - - - - - - - - - - - - - - -   - - - - - - - - - - - - - - - - - - - - - - - -   - - - - - - - - - - - - - - - - - - - - - - - -   - - - - - - - - - - - - - - - - - - - - - - - -   - - - - - - - - - - - - - - - - - - - - - - - -   - - - - - - - - - - - - - - - - - - - - - - - -   - - - - - - - - - - - - - - - - - - - - - - - -   A - - - - - - AcM - - - - - - ApAo- - - - - - A   - - - - - - - B T A A A A A A AqF - - - - - - -   - - - - - - - R AeAcAjAfD E AbApY - - - - - - -   - - - - - - - Q AgAeAbQ AcAfW R Y - - - - - - -   - - - - - - - P I L W E AqQ K Z M - - - - - - -   - - - - - - - AlL AaK X G E AiS At- - - - - - -   - - - - - - - W AqG AiAgT X S R J - - - - - - -   - - - - - - - - AhB B F I B B T - - - - - - - -   - - - - - - - - - - - - - - - - - - - - - - - -   
A - - - - - - - - - - - - - - - - - - - - - - A   A - - - - - - - - - - - - - - - - - - - - - - A   A - - - - - - - - - - - - - - - - - - - - - - A   A - - - - - - - - - - - - - - - - - - - - - - A   A - - - - - - - - - - - - - - - - - - - - - - A   A - - - - - - - - - - - - - - - - - - - - - - A   A - - - - - - - - - - - - - - - - - - - - - - A   A - A A A A A AdG A A A A A A D AeA A A A A - A   - - - - - - - N Q A A A A A A H Y - - - - - - -   - - - - - - - A D C W Y AaR AjV E - - - - - - -   - - - - - - - M H P AgAkI Q AbAdAn- - - - - - -   - - - - - - - L H AkZ AdAsP W N I - - - - - - -   - - - - - - - AcP ApY AlC AlK A Ao- - - - - - -   - - - - - - - B AfAqAkArAcW AiM J - - - - - - -   - - - - - - - - - B B B B B B - - - - - - - - -   - - - - - - - - - - - - - - - - - - - - - - - -   
- - - - - - - - - - - - - - - - - - - - - - - -   - - - - - - - - - - - - - - - - - - - - - - - -   - - - - - - - - - - - - - - - - - - - - - - - -   - - - - - - - - - - - - - - - - - - - - - - - -   - - - - - - - - - - - - - - - - - - - - - - - -   - - - - - - - - - - - - - - - - - - - - - - - -   - - - - - - - - - - - - - - - - - - - - - - - -   - - A - - - - - Q I X AnZ AdK Af- - - - - A - -   - - - - - - - J P AsAoArAlN AbC G - - - - - - -   - - - - - - - A AlC AeS J A W Y F - - - - - - -   - - - - - - - V W AcY AcO M AgAdK - - - - - - -   - - - - - - - U AbAeE G AaL Z X O - - - - - - -   - - - - - - - D Y L AnAhC AcY ArD - - - - - - -   - - - - - - - - B B B B B B B B - - - - - - - -   - - - - - - - - - - - - - - - - - - - - - - - -   - - - - - - - - - - - - - - - - - - - - - - - -   
- - - - - - - - - - - - - - - - - - - - - - - -   - - - - - - - - - - - - - - - - - - - - - - - -   - - - - - - - - - - - - - - - - - - - - - - - -   - - - - - - - - - - - - - - - - - - - - - - - -   - - - - - - - - - - - - - - - - - - - - - - - -   - - - - - - - - - - - - - - - - - - - - - - - -   - - - - - - - - - - - - - - - - - - - - - - - -   - - A - - - - - - - - - - - - - - - - - - A - -   - - - - - - - - - R R AhT J Ao- - - - - - - - -   - - - - - - - - ApAuZ G AmA AeAe- - - - - - - -   - - - - - - - - AkAfS Q Q V Y Ag- - - - - - - -   - - - - - - - - AjO R D Z U E I - - - - - - - -   - - - - - - - - - B B B B B B - - - - - - - - -   - - - - - - - - - - - - - - - - - - - - - - - -   - - - - - - - - - - - - - - - - - - - - - - - -   - - - - - - - - - - - - - - - - - - - - - - - -   
- - - - - - - - - - - - - - - - - - - - - - - -   - - - - - - - - - - - - - - - - - - - - - - - -   - - - - - - - - - - - - - - - - - - - - - - - -   - - - - - - - - - - - - - - - - - - - - - - - -   - - - - - - - - - - - - - - - - - - - - - - - -   - - - - - - - - - - - - - - - - - - - - - - - -   - - - - - - - - - - - - - - - - - - - - - - - -   - - A - - - - - - - - - - - - - - - - - - A - -   - - - - - - - - - - - - - - - - - - - - - - - -   - - - - - - - - - - - - - - - - - - - - - - - -   - - - - - - - - - - - - - - - - - - - - - - - -   - - - - - - - - - - - - - - - - - - - - - - - -   - - - - - - - - - - - - - - - - - - - - - - - -   - - - - - - - - - - - - - - - - - - - - - - - -   - - - - - - - - - - - - - - - - - - - - - - - -   - - - - - - - - - - - - - - - - - - - - - - - -   
- - A - - - - - - - - - - - - - - - - - - A - -   - - A - - - - - - - - - - - - - - - - - - A - -   - - A - - - - - - - - - - - - - - - - - - A - -   - - A - - - - - - - - - - - - - - - - - - A - -   - - A - - - - - - - - - - - - - - - - - - A - -   - - A - - - - - - - - - - - - - - - - - - A - -   - - A - - - - - - - - - - - - - - - - - - A - -   - - A - - - - - - - - - - - - - - - - - - A - -   - - - - - - - - - - - - - - - - - - - - - - - -   - - - - - - - - - - - - - - - - - - - - - - - -   - - - - - - - - - - - - - - - - - - - - - - - -   - - - - - - - - - - - - - - - - - - - - - - - -   - - - - - - - - - - - - - - - - - - - - - - - -   - - - - - - - - - - - - - - - - - - - - - - - -   - - - - - - - - - - - - - - - - - - - - - - - -   - - - - - - - - - - - - - - - - - - - - - - - -   
