model
size = 24 16 22, scale = 0.05, origin = -y
material 
  colors = A:#3F3 B:#3C3 C:#393 D:#360 E:#30C F:#036
voxels
------------------------ ----A--------------A---- ----A--------------A---- ----D--------------A---- ----D--------------D---- ----D--------------D---- ----A--------------D---- ----A--------------A---- ------------------------ ------------------------ ------------------------ ------------------------ ------------------------ ------------------------ ------------------------ ------------------------ 
------------------------ ------------------------ ------------------------ ------------------------ ------------------------ ------------------------ ----------E--E---------- ----A-----E--E-----A---- ----------E--E---------- ----------E--E---------- ------------------------ ------------------------ ------------------------ ------------------------ ------------------------ ------------------------ 
------------------------ ------------------------ ------------------------ ------------------------ ------------------------ ------------------------ ------------------------ ----A----AAAAAA----A---- ---------AAAAAA--------- ---------AAAAAA--------- ---------AAAAAA--------- ---------AAAAAA--------- ------------------------ ---------F----F--------- ------------------------ ------------------------ 
------------------------ ------------------------ ------------------------ ------------------------ ------------------------ ------------------------ ------------------------ ----A-----AAAA-----A---- ---------AAAAAA--------- ---------AAAAAA--------- ---------AAAAAA--------- ---------AAAAAA--------- ---------AAAAAA--------- ---------AAAAAA--------- ------------------------ ------------------------ 
------------------------ ------------------------ ------------------------ ------------------------ ------------------------ ------------------------ ------------------------ ----A----AAAAAA----A---- ---------AAAAAA--------- ---------AAAAAA--------- ---------AAAAAA--------- ---------AAAAAA--------- ---------AAAAAA--------- ---------AAAAAA--------- ------------------------ ------------------------ 
-A--------------------A- -A--------------------A- -A--------------------A- -A--------------------A- -D--------------------A- -D--------------------D- -D--------------------D- -D--A----AAAAAA----A--A- ---------AAAAAA--------- ---------AAAAAA--------- ---------AAAAAA--------- ---------AAAAAA--------- ---------AAAAAA--------- -------F-AAAAAA-F------- ----------F--F---------- ----------F--F---------- 
------------------------ ------------------------ ------------------------ ------------------------ ------------------------ ------------------------ ------------------------ -A--AAAACCCCCCCCAAAA--A- -------AAAAAAAAAA------- -------AAAAAAAAAA------- -------AAAAAAAAAA------- -------AAAAAAAAAA------- -------AAAAAAAAAA------- -------AAAAAAAAAA------- ---------AAAAAA--------- ---------AAAAAA--------- 
------------------------ ------------------------ ------------------------ ------------------------ ------------------------ ------------------------ ------------------------ -A-----AC------CA-----A- -------AABBBBBBAA------- -------AAAAAAAAAA------- -------AAAAAAAAAA------- -------AAAAAAAAAA------- -------AAAAAAAAAA------- -------AAAAAAAAAA------- ---------AAAAAA--------- ---------AAAAAA--------- 
------------------------ ------------------------ ------------------------ ------------------------ ------------------------ ------------------------ ------------------------ -A-----AC------CA-----A- -------AABBBBBBAA------- -------AAAAAAAAAA------- -------AAAAAAAAAA------- -------AAAAAAAAAA------- -------AAAAAAAAAA------- -------AAAAAAAAAA------- ---------AAAAAA--------- ------------------------ 
------------------------ ------------------------ ------------------------ ------------------------ ------------------------ ------------------------ ------------------------ -A-----AC------CA-----A- -------AAB-BB-BAA------- -------AAAAAAAAAA------- -------AAAAAAAAAA------- -------AAAAAAAAAA------- -------AAAAAAAAAA------- -------AAAAAAAAAA------- --------AAAAAAAA-------- ------------------------ 
------------------------ ------------------------ ------------------------ ------------------------ ------------------------ ------------------------ ------------------------ -AAAAAAAC------CAAAAAAA- -------AAB-BB-BAA------- -------AAAAAAAAAA------- -------AAAAAAAAAA------- -------AAAAAAAAAA------- -------AAAAAAAAAA------- -------AAAAAAAAAA------- --------AAAAAAAA-------- ------------------------ 
------------------------ ------------------------ ------------------------ ------------------------ ------------------------ ------------------------ ------------------------ -------AC------CA------- -------AAB-BB-BAA------- -------AAAAAAAAAA------- -------AAAAAAAAAA------- -------AAAAAAAAAA------- -------AAAAAAAAAA------- -------AAAAAAAAAA------- --------AAAAAAAA-------- ------------------------ 
------------------------ ------------------------ ------------------------ ------------------------ ------------------------ ------------------------ ------------------------ -------AC------CA------- -------AAB-BB-BAA------- -------AAAAAAAAAA------- -------AAAAAAAAAA------- -------AAAAAAAAAA------- -------AAAAAAAAAA------- -------AAAAAAAAAA------- --------AAAAAAAA-------- ------------------------ 
------------------------ ------------------------ ------------------------ ------------------------ ------------------------ ------------------------ ------------------------ -------AC------CA------- -------AAB-BB-BAA------- -------AAAAAAAAAA------- -------AAAAAAAAAA------- -------AAAAAAAAAA------- -------AAAAAAAAAA------- -------AAAAAAAAAA------- --------AAAAAAAA-------- ------------------------ 
------------------------ ------------------------ ------------------------ ------------------------ ------------------------ ------------------------ ------------------------ AAAAAAAAC------CAAAAAAAA -------AAB-BB-BAA------- -------AAAAAAAAAA------- -------AAAAAAAAAA------- -------AAAAAAAAAA------- -------AAAAAAAAAA------- -------AAAAAAAAAA------- --------AAAAAAAA-------- ------------------------ 
------------------------ ------------------------ ------------------------ ------------------------ ------------------------ ------------------------ ------------------------ A------AC------CA------A -------AAB-BB-BAA------- -------AAAAAAAAAA------- -------AAAAAAAAAA------- -------AAAAAAAAAA------- -------AAAAAAAAAA------- -------AAAAAAAAAA------- --------AAAAAAAA-------- ------------------------ 
------------------------ ------------------------ ------------------------ ------------------------ ------------------------ ------------------------ ------------------------ A------AC------CA------A -------AABBBBBBAA------- -------AAAAAAAAAA------- -------AAAAAAAAAA------- -------AAAAAAAAAA------- -------AAAAAAAAAA------- -------AAAAAAAAAA------- --------AAAAAAAA-------- ------------------------ 
A----------------------A A----------------------A A----------------------A A----------------------A A----------------------D D----------------------D D----------------------D A-AAAAAACCCCCCCCAAAAAA-A -------AAAAAAAAAA------- -------AAAAAAAAAA------- -------AAAAAAAAAA------- -------AAAAAAAAAA------- -------AAAAAAAAAA------- -------AAAAAAAAAA------- ---------AAAAAA--------- ------------------------ 
------------------------ ------------------------ ------------------------ ------------------------ ------------------------ ------------------------ ------------------------ --A-----AAAAAAAA-----A-- -------AAAAAAAAAA------- -------AAAAAAAAAA------- -------AAAAAAAAAA------- -------AAAAAAAAAA------- -------AAAAAAAAAA------- --------AAAAAAAA-------- ------------------------ ------------------------ 
------------------------ ------------------------ ------------------------ ------------------------ ------------------------ ------------------------ ------------------------ --A------------------A-- ---------AAAAAA--------- --------AADAADAA-------- --------AADAADAA-------- --------AADAADAA-------- ---------AAAAAA--------- ------------------------ ------------------------ ------------------------ 
------------------------ ------------------------ ------------------------ ------------------------ ------------------------ ------------------------ ------------------------ --A------------------A-- ------------------------ ------------------------ ------------------------ ------------------------ ------------------------ ------------------------ ------------------------ ------------------------ 
--A------------------A-- --A------------------A-- --A------------------A-- --A------------------D-- --A------------------D-- --D------------------A-- --D------------------A-- --D------------------A-- ------------------------ ------------------------ ------------------------ ------------------------ ------------------------ ------------------------ ------------------------ ------------------------ 
