model
size = 24 32 22, scale = 0.05, origin = -y
material 
  colors = A:#080 B:#00E C:#FF0 D:#B00 E:#111 F:#A5A520 G:#EEE
voxels
625-3A4D16-4AD3-3D24-12D16-8D79-A3-A20-A-2(A22-)A-A7-C12-A3-A5-2C21-3C20-4C20-4F22-2A21-3A20-4A19-4A18-B4A19-2B2A19-4B20-3B21-3B89-13A9-17A6-3(19A5-)2A3D14A2(2-A)D3-3D11A5-2A3D3-4D7A4-2AG3-3D4-8D3-2AG6-4D12-2A9-9D8-3A20-5A2-3(5C11-7A-)6C11-5A-7C12-3A-8C15-9C12-7C2F2CF12-11CA12-3(11B13-)2(4B3A4B13-)3B4A4B2(13-3B3A5B)3(13-11B)10-17A6-4(19A5-)19A2-A2-2A3E14A5-5A3E11A4-2AG3-3A4E7AD3-2AE6-4A7E5-2A9-6A3D31-13C3(11-C5A7C)11-C4A8C11-C3A9C11-13C11-12CF11-13C11(11-13B)9-17A6-4(19A5-)19A2-A2-19A3-21A4-2AE3-14AD3-2AE6-10AE5-2A9-6A3D30-15C3(9-C7A7C)2(9-2C6A7C)9-7CA7C9-7CA6CF9-15C11(9-15B)7-5(19A5-)19A2-A2-19A5-19AD3-2AE3-14AD3-2AE6-10AE5-2A9-6A3D29-17C7(7-C8A8C)7-17C11(7-17B)6-5(19A5-)19A2-A2-19AD4-19AD3-2AE3-14AD3-2AG6-10AE5-2A9-6A3D29-17C8(7-C14A2C)11(7-B13A3B)6-5(19A5-)19AD-A2-19AD4-19AD3-2AG3-14A2D2-2AE6-10AE5-2A9-6A3D29-16C5(8-C14AC)8-3(C14A2C7-)10(B13A3B7-)B13A3B6-5(19A5-)20ADA2-20AD3-19AD3-2AG3-14AD3-2AG6-10AE5-2A9-6A3D29-16C6(8-C14AC)8-2(C14A2C7-)10(B13A3B7-)B13A3B6-5(19A5-)19AD-A2-19AD2-21AD4-2A3-14AD12-10AE16-6A3D29-16C8(8-C14AC)2(8-B13A2B)8-B13A3B7-3(B13A2B8-)4(B13A3B7-)B13A3B6-5(19A5-)19AD-A2-19AD2-21AD4-2A3-14A2D11-2(10AE16-6A3D29-16C8(8-C14AC)2(8-B13A2B)8-B13A3B7-3(B13A2B8-)4(B13A3B7-)B13A3B6-5(19A5-)20ADA2-20AD-21AD4-2A3-14AD12-)10AE16-6A3D29-16C8(8-C14AC)2(8-B13A2B)8-B13A3B7-3(B13A2B8-)4(B13A3B7-)B13A3B6-5(19A5-)19AD-A2-19AD2-21AD4-2A3-14A2D11-10AE16-6A3D29-16C6(8-C14AC)8-2(C14A2C7-)10(B13A3B7-)B13A3B6-5(19A5-)19AD-A2-19AD2-21AD4-2A3-14AD12-10AE16-6A3D29-16C5(8-C14AC)8-3(C14A2C7-)4(B13A3B7-)2(B13A3BA6-B13A3B7-)2(B13A3B7-)B13A3B6-5(19A5-)20ADA2-20AD3-19AD3-2AG3-14AD3-2AG6-10AE5-2A9-6A3D29-17C8(7-C14A2C)4(7-B13A3B)A6-3(B13A3B7-)B13A3BA6-2(B13A3B7-)B13A3B6-5(19A5-)19AD-A2-19AD4-19AD3-2AG3-14A2D2-2AE6-10AE5-2A9-6A3D29-17C7(7-C8A8C)7-17C4(7-17B)A6-3(17B7-)17BA6-2(17B7-)17B6-5(19A5-)19A2-A2-19AD4-19AD3-2AE3-14AD3-2AG6-10AE5-2A9-6A3D30-15C3(9-C7A7C)2(9-2C6A7C)9-7CA7C9-7CA6CF9-15C3(9-15B)9-3(13B3A8-)14B2A3(8-15BA)8-15B7-5(19A5-)19A2-A2-19A5-19AD3-2AE3-14AD3-2AE6-10AE5-2A9-6A3D31-13C3(11-C5A7C)11-C4A8C11-C3A9C11-13C11-12CF11-13C3(11-13B)11-12B2A10-3(12B3A9-)3(13BA10-)13B9-17A6-4(19A5-)19A2-A2-19A3-21A4-2AE3-14AD3-2AE6-10AE5-2A9-6A3D8-3A20-5A2-3(5C11-7A-)5C12-5A-6C13-3A-7C16-8C13-7C4F13-11C3(13-11B)13-4B8A12-4B9A11-3B10A11-2(3B3A5BA12-)2(11BA12-)11B10-17A6-4(19A5-)19A2-A2-2A3E14A5-5A3E11A4-2AG3-3A4E7AD3-2AE6-4A7E5-2A9-6A3D31-A3-A20-A-2(A22-)A-A20-A3-A192-B6A17-2B6A15-4B5A15-3B21-3B89-13A9-17A6-3(19A5-)A4D14A2(2-A)D3-3D11A5-2A3D3-4D7A4-2AG3-3D4-8D3-2AG6-4D12-2A9-9D626-3A4D16-4AD3-3D24-12D16-8D49-
