model
size = 32 31 32, scale = 0.05, origin = -y
material 
  colors = A:#D7C4BB B:#0B1013 C:#4A225D D:#52433D E:#005CAF F:#656765 G:#574C57 H:#111 I:#0F2540 J:#113285 K:#E03C8A L:#FFC408 M:#E83015 N:#F05E1C O:#D0104C P:#00896C Q:#91B493 R:#096148 S:#0B346E T:#CA7A2C U:#36563C
voxels
783-GB2(31-F)798-3(BG30-)BG29-4B62-F31-HF733-BG30-BG124-6B94-F31-H669-BH30-BG155-BG-2B-GB124-HF857-2(2B2-)2B123-F857-BG3-2B3-GB121-FH856-2(2B4-)2B120-H856-BG5-2B5-GB119-F31-FH47-3C2(-C)-P-O-L-O2(C-)P-C-L-O-2C4-C26-C36-2C-O-L-P-OP2(-C)-L-PC-O-L2-2C36-C3-DA21-C5-CO-AD-L-C-P2(-C)-OL2(-C)O-2C5-C3-DA21-C8-AD26-2C2-DA2(-C)-2C-L2(-C)-P2(-C)-2C8-AD2(26-C)5-2C3-P-O-C-L-C-O2(L-)C-O2-C32-C4-C30-3C-C-L-P2(-C)-O-CL-C-P-O-L-2C266-2(2B6-)2B151-F48-C31-N58-R8-DA26-N3-AD21-M8-3A29-D2A25-K3-3A20-M8-DAD29-3A20-K4-K3-2AD29-DA21-K8-AD26-Q26-K36-C292-BG7-2B7-GB150-F30-FH43-C31-M4-K3-AD26-C3-3A20-C8-D2A25-Q3-D3A19-C4-C3-4A19-C8-D2AD24-N3-4A19-C4-C3-D3A28-D2AD19-C4-N3-3A25-C3-2AD20-M8-DA26-K26-S31-C264-2(2B8-)2B180-H17-C31-K3-DA30-ADA20-R11-D24-N6-D19-C11-2A30-2D23-C6-2A10-E7-R11-DA10-E19-2A18-R4-K6-2D30-A19-R11-D24-N3-3A20-S8-AD21-M4-C290-BG9-2B9-GB179-FH43-C4-Q3-2A21-S4-C3-DAD25-C6-A19-C4-K6-AD23-Q6-D2A17-S4-C6-3A9-E7-C4-K6-D2A2(DA)D3-IEI11-C6-4(AD)3-ITI6-C4-Q6-D2A9-J12-N6-ADA17-C4-Q6-2D23-C6-A19-K4-K3-2AD20-M4-N3-DA53-C262-2(2B10-)2B179-F16-C3-AD26-N3-D2A29-AD2A19-M11-DA18-C4-C6-ADA17-M13-D9-J21-3(AD)3-3E6-K4-C8-3(DA)2-J3EJ5-S13-3(AD)2-J3EJ19-3(DA)3-3E6-S4-C8-A9-E19-3A17-C11-DA18-C4-U3-D2AD28-3A20-R4-C3-AD283-BG10-G2BG10-GB177-FH20-CA21-C8-2AD20-S4-K3-2(DA)24-C6-AD18-M11-D2A9-I7-C4-U8-3(AD)3-3E6-R4-N16-I3TI12-I13-2E3T2E4-C4-U-I13-7E4-R4-C16-I3EI19-3(AD)3-3E6-C4-K6-D2A9-I7-M4-C6-AD27-4A19-C4-Q3-2AD29-DA21-C260-2B10-G4BG10-2B66-HF31-FH75-HF16-C3-AD26-K3-D2A29-3AD19-R11-2A10-E12-N6-8A3-JEJ20-3(DA)2-5E12-I13-7E4-S4-CEIE2(J3E)J10EI9-EI3(J3E)J6ETI10-I13-7E4-S4-K8-3(DA)2-5E17-2AD5A3-JEJ18-DA10-E7-R4-N3-D2AD28-D2A20-M4-C3-AD92-H24-B5-2G24-2B3-2G26-2B3(2-G28-B)-15B2G14BGF31-HF31-F33-FHF18-2FH12-FHF14-H16-F-4(FH)-HFH14-AD21-C4-Q3-D2A29-3AD19-K11-2A10-E12-Q6-8A3-JEJ20-3(DA)2-5E12-I13-7E4-C4-KEI2E2(J3E)J9EI9-EI3(3EJ)7ETI10-I13-7E4-K4-C8-3(DA)2-5E17-2AD5A3-JEJ18-DA10-E7-M4-C3-D2AD28-D2A20-S8-AD21-C70-B24-H5-2B24-2G3-2B26-2G3(2-B28-G)-G14B2G15B31-F30-2F30-H6-H2F18-FHF10-H14-FHF16-HFH-4(HF)-F10-C3-DA30-2AD20-M4-Q3-2(DA)24-C6-AD18-C11-D2A9-I7-M4-C8-3(AD)3-3E6-S4-N16-I3EI12-I13-7E4-R4-U-I13-7E4-C4-N16-I3EI19-3(AD)3-3E6-C4-N6-D2A9-I7-K4-C6-AD27-4A19-C4-Q3-2AD25-C3-DA282-2B10-G4BG10-2B94-2F29-HF49-FH20-AD21-C4-N3-D2A29-AD2A19-S11-DA18-M4-K6-ADA17-C13-D9-J21-3(AD)3-3E6-C4-N8-3(DA)2-J3EJ5-C13-3(AD)2-J3EJ19-3(DA)3-3E6-M4-Q8-A9-E19-3A17-C11-DA18-C4-N3-D2AD28-3A20-M8-AD21-C261-2B10-G2BG10-GB177-HF16-C31-C3-2A21-R4-K3-DAD25-C6-A19-C4-C6-AD23-K6-D2A17-K4-Q6-3A9-E7-S4-C6-D2A2(DA)D3-IEI11-Q6-4(AD)3-IEI6-S4-C6-D2A9-J12-C6-ADA17-R4-Q6-2D23-C6-A19-K4-U3-2AD20-C4-Q3-DA26-C289-2(2B10-)2B178-F44-C4-Q3-DA30-ADA20-M11-D24-C6-D19-K11-2A30-2D23-N6-2A10-E7-M11-DA10-E19-2A18-K4-Q6-2D30-A19-M11-D24-N3-3A20-M8-AD21-S4-C26-C263-2(2B9-)GB179-HF75-R4-C3-AD26-Q3-3A20-M8-D2A25-N3-D3A19-C4-C3-4A19-M8-D2AD24-C3-4A19-C4-U3-D3A28-D2AD19-M4-C3-3A25-N3-2AD20-R8-DA26-K26-R296-2(2B8-)2B181-H16-C26-C4-K58-S8-DA26-N3-AD21-R8-3A29-D2A25-K3-3A20-M8-DAD29-3A20-R4-Q3-2AD29-DA21-S8-AD26-K26-M36-C26-C265-2(2B7-)GB149-F31-HF15-3C-P-L2(-C)-O-PC-L-C-P-L-C-2C4-C26-C36-C-L2(-C)-O-C-P-2C-C-L-O-C-2C32-C4-C3-DA27-C2-AD2(-2C)2(-C)LC-CP2(-C)-2C4-C3-DA30-AD21-C4-2CP-DA-L-O-PC-L2(-C)-P-LC-C10-AD21-C4-C32-C-C2-L2C-CLC-2C-CO-CL-C-3C36-C26-C3-3C-P2(-O)3(-C)-2C-C-P-L-C-2C266-2(2B6-)2B150-F824-2(2B5-)GB120-F30-HF824-2(2B4-)2B121-H857-2(2B3-)GB121-HF858-2(2B2-)2B122-F671-HB30-GB155-2(2B-)GB122-FH703-GB30-GB124-6B91-F31-H736-3(GB30-)GB29-4B61-F30-2F895-BG30-F31-F144-
