model
size = 32 31 18, scale = 0.05, origin = -y
material 
  colors = A:#EEE B:#161C30 C:#14192D D:#1D2541 E:#8A92B1 F:#62678F
voxels
7-18B18-2B4-2(B2-)B943-18B14-17B18-B-2(B2-)B23-B5-2(B-)2B2(31-B)20-B10-B785-18B14-17B16-12B2CB18-5B2C7B4(18-14B)18-12BCB18-BC10BCB18-14B18-BC12B18-14B18-6BC7B18-14B18-8BC3B2C18-BC4BC7B18-14B16-18B14-D16BD14-7BC2BC7B15-6BC2BC6B16-7BC5BC2B16-6B2C5BC2B16-5B3C2BC5B16-C12BC2B12-5BC18B9-7BC3BC10B14-11B2CB18-6B2F6B20-2(EF)2EF3E18-18B15-16B17-B2(12AB18-C)3(12AB18-B)3AF8A6(B18-B12A)B18-C2(12AB18-B)12AB16-2B14A2B14-D16AD8-5B-D16AD-5B2-4BD-D16AD-D4B2-BC3B2-B14AB2-2BC2B2-6B-B14AB-5BC-2BC4B-B14AB-2BC7BC3B-B14AB-4BC9B-BA12BAB-7B-4B2ACAB12-BAC2A4B3-3B4AB12-B4A3B6-5BAB10-BA5B10-B-BCB10-BCB-B16-E10-E17-18B15-17B15-2B12A2B17-C12AC18-C3(12AB18-B)3AF8A9(B18-B12A)B16-DC14ACD14-D16AD8-B3-B-D16AD-B3-B2-4BD-D16AD-D4B2-B3AD2-C14AC2-D3AB2-B4AB-C14AC-B4AB-7B2(-C14AC-14B)-CA12BAC-7B-6BCAB12-BAC6B3-5B2AB12-B2A5B6-3B3AB10-B3A3B10-2B2AB10-B2A2B13-3BE10-E3B14-18B14-17B17-B12A2B17-B12AC18-C3(12AB18-B)4(12AB18-C)12AC5(18-B12AB)16-DC14ACD14-D16AD8-B3-B-D16AD-B3-B2-4BD-D16AD-D4B2-C3AD2-C14AC2-D3AB2-B4AC-C14AC-C4AB-7B2(-B14AB-14B)-CA4BC2BC4BAC-7B-6BCAB12-BAC6B3-5B2AB12-B2A5B6-3B3AB10-B3A3B2(10-B3AB)13-BCBE10-EBCB14-18B14-17B2(17-B12A2B)17-C3(12AB18-B)3(12AB18-C)12AC18-C2(12AB18-B)12AB18-C12AC18-C12AB18-B12AB16-BC14ACB14-D16AD8-B3-B-B16AB-B3-B2-4BD-D16AD-D4B2-C3AD2-C14AC2-D3AB2-B4AC-B14AB-C4AB-C6B-B14AB-7BC6B-C14AC-14B-CA12BAC-7B-6BCAB12-BAC6B3-C4B2AB12-B2A4BC6-3B3AB10-B3A3B10-2C2AB10-B2A2C13-2CBF10-FB2C14-18B15-16B16-2B12AB18-B12A2B17-3(B12AB18-)2(B12AC18-)5(B12AB18-)C12AC18-C12AB18-B12AB16-DC14ACD14-D16AD8-B3-B-D16AD-B3-B2-4BD-D16AD-D4B2-B3AD2-C14AC2-D3AB2-B4AC-C14AC-C4AB-C6B-C14AC-7BC6B-C14AC-14B-CA5B2C5BAC-7B-6BCAB12-BAC6B3-5B2AB12-B2A5B6-B2C3AB10-B3A2CB10-C3AB10-B3AC13-BCBE10-EBCB14-18B15-16B17-B12A2B17-B12AB3(18-B12AC)10(18-B12AB)16-BC14ACB14-B16AB8-B3-B-D16AD-B3-B2-4BD-C16AC-D4B2-C3AD2-B14AB2-D3AB2-B4AC-C14AC-C4AB-7B-B14AB-7BC6B-C14AC-14B-CA4BC2BC4BAC-7B-6BCAB12-BAC6B3-5B2AB12-B2A5B6-C2B3AB10-B3A2BC2(10-B3AB)13-3BF10-F3B14-18B15-16B17-2(B12AC18-)3(B12AB18-)C3(12AB18-B)2(12AB18-C)4(12AB18-B)12AB16-DC14ACD14-D16AD8-B3-B-D16AD-B3-B2-4BD-D16AD-D4B2-C3AD2-C14AC2-D3AB2-C4AC-C14AC-C4AB-7B2(-C14AC-14B)-CA3B6C3BAC-7B-6BCAB12-BAC6B3-C4B2AB12-B2A4BC6-C2B3AB10-B3A2BC2(10-B3AB)13-3BE10-E3B14-18B15-16B17-3(C12AB18-)11(B12AB18-)B12AB16-DC14ACD14-B16AB8-B3-B-D16AD-B3-B2-4BD-D16AD-D4B2-B3AD2-C14AC2-D3AB2-C4AC-B14AB-C4AB-7B-C14AC-14B-C14AC-7BC6B-CA12BA2(C-6B)CAB12-BAC6B3-C4B2AB12-B2A4BC6-3B3AB10-B3A3B2(10-B3AB)13-3BE10-F3B14-18B15-16B16-2B2(12AB18-B)12AC2(18-B12AB)2(18-B12AC)2(18-B12AB)18-B12AC5(18-B12AB)16-DC14ACD14-D16AD8-B3-B-D16AD-B3-B2-4BD-D16AD-D4B2-B3AD2-C14AC2-D3AB2-B4AC-C14AC-C4AB-C6B2(-C14AC-14B)-CA12BAC-7B-6BCAB12-BAC6B3-5B2AB12-B2A5B6-BCB3AB10-B3ABCB10-C3AB10-B3AC13-2BCE10-EC2B2(14-18B)16-B12AB17-2B12AB18-B12AC2(18-B12AB)3(18-C12AB)3(18-B12AB)18-C3(12AB18-B)12AB16-DC14ACD14-D16AD8-B3-B-D16AD-B3-B2-4BD-D16AD-D4B2-B3AD2-C14AC2-D3AB2-B4AC-C14AC-C4AB-C6B-C14AC-14B-C14AC-15BCA2B8C2BAC8B-6B2AB12-B2A6B3-5B2AB12-B2A5B6-3B3AB10-B3A3B2(10-B3AB)13-3BE10-E3B14-18B15-16B17-C14(12AB18-B)12AB16-BC14ACB14-B16AB8-2(5B-B16AB-5B2-)5B2-C14AC2-5B2-6B-C14AC-6B-7B-C14AC-14B2C14A2C14B-CAB10CBAC2(-7B)2AB10CB2A7B3-5B3AB10CB3A5B6-3BACAB10-BACA3B10-B2CAB10-BA2CB13-3BF10-F3B14-18B15-16B17-C12A2B17-6(B12AB18-)2(B12AC18-)5(B12AB18-)B12AB16-BC14AC3(B14-B16A)B9-4B-B16AB-4B4-4BCB16ABC4B3-5BCB16ABC5B3-4BC-B14AB-C4B4-5B-B14AB-C4B4-13BFE13B4-11B4EFE11B6-4B-3BE6-E3B-4B10-B2-B2E8-2EB2-B45-18B15-16B16-15B6(18-14B)18-13BC18-BD11BC6(18-14B)16-2(BD)12BDB14-B2D4A3BD4A2DB14-2D6ABD6AD3(B14-B16A)B10-5B16AB9-B5-B14A2(B5-)B4-16B4-B7-5B14-5B9-4B14-4B108-18B15-16B17-3B4-B2-2B20-2B9-B-B467-4B4-4B19-6B2-6B17-2(16B16-)16B11-21B16-16B207-18B17-3B7-B686-7B246-
