model
size = 30 32 23, scale = 0.05, origin = -y
material 
  colors = A:#EEE B:#002 C:#222 D:#111 E:#006 F:#001 G:#00F H:#0B0
voxels
820-2E-6G2E19-2E2-G4-2E19-2E2G-G-2G2E19-2E4-G2-2E19-2E6G-2E890-E23-20F10-20E9-7A7-8A8-2C5A7-8A8-A3C3A7-5A3C8-4A3C7-4A2CAC8-A4C2A7-4C4A8-2C5A7-CAC5A8-C6A7-8A8-7A7-AC6A8-4AB2A7-A3C2A2C8-4AB3AD8A2C2AC8-B8A3DAC4AC3A8-B9ACD4C6A8-B10A5CD5A8-B10A2C2AC3D3A8-2AD4A4CA2CAC2AD3A8-2A9D7A2D2A8-10A3D9A8-3D6A3CA8DA8-2A4D6A10C8-18A2C2A8-16A3D3C8-D6A10D3C2A8-2D2A4D6A4C4A8-A4D17A8-19A3D8-11A9D2C8-5A7D6A3CA8-2A4D16A8-3D19A8-10AEAE9A8-F20BF8-22E6-7A-A7-A2-A-5A4-2C5A-A7-A2-A-5A4-C6A-A7-A2-A-3A2C4-7A-C7-A2-A-5A4-7A-A7-A2-A-4AC4-7A-A7-C2-A-5A4-AC5A2(-A7-A2-B-5A4-7A)-A7-A2-B-5A4-6AB-9A2-B-3ACA4-5AB15-3ACA4-5A16-3ABA4-5A16-B2ABA4-5A17-2ABA4-2(2AB2A17-3A5-)2AB2A17-2AC5-2D3(B2A17-3A5-2A)B2A17-2AC5-2D2(B2A17-3A5-2A)2(B2A17-2AD5-2A)4(B2A17-3A5-2A)B2A17-3A7-F2B17-BF8-3E17-2E4-7A3-A7-A4-3A-10A3-A7-A4-3A-4AC5A3-A2(7-A4-3A-10A3-C)7-A4-3A-2AC7A3-A7-C3(4-3A-2A-7A3-A7-A)4-3A-2A-7A3-9A4-2(3A-2A-7A16-)3A-2A-5ABA16-B2(2A-)7A17-2(2A-)2(2A3B2A17-2AB2A-)2A3B2A17-2AB3C-D3B2A17-2AB3A-A3B2A17-2AB2AC-A3B2A17-2AB2A2-D3B2A17-2ABCA2(2-A3B2A17-2AB2A)2-A3B2A17-2ABD3(3-A3B2A17-2ABA)3-A3B2A17-2ABC2(3-A3B2A17-2ABA)3-3F3B17-2B2F3-6E17-4E2-4A6-A7-AH3(A6-7A6-A7-A-)A6-7A6-C7-A8-2AC2ABA6-A7-C3(8-2A-2ABA6-A7-A)8-2A-2ABA6-9A8-4(2A-2ABA23-)2(2A-2A2B22-B)2A2-2(D2B22-B2AC-)A2B22-B2AC-A2B22-B2A2-D4(2B22-B2A2-A)2B22-BD3-A2B22-BA3-D2B22-BA3-A2B22-BD2(3-A2B22-BA)2-F3B22-2BF-4E22-3E-3A3(2(7-A)4-A3-6A)2(7-A)4-H3-2AC3A7-C7-A8-2AC3A7-A7-C2(8-2A-C2A2(7-A))8-2A-3A2(7-A)4-H3-2A-C2A7-9A8-2A-C2A20-B3-3(2A-2AB24-)2A-CA24-B2A-2A24-B2A2-D24-B2A-C2(A24-B2AC-)A24-B2A2-D3(24-B2A2-A)24-BD2(3-A24-BA)3-D24-BC3-A24-BD2(3-A24-BA)2-FB24-2BF-2E24-3E-3A3(2(7-A)4-A3-6A)2(7-A)4-A3-2A2C2A2(7-A)4-A3-BA-C2A2(7-C)3(4-A3-BA-3A2(7-A))4-A3-BA-C2A7-9A4-2(A3-BA-3A20-)2(B3-BA-2AB20-)B2-2BA-CA24-B2A-2A24-B2A2-D24-B2A-CA24-B2A2-A24-B2AC-A24-B3D-D3(24-B2A2-A)24-BD2(3-A24-BA)3-D2(24-BC3-A)24-BA3-A24-BA2-FB24-2BF-2E24-3E-4A2(6-A7-A9-6A)6-A7-A9-5A2(2(7-A)9-AC3A)7-C7-A2(9-A-3A2(7-A))9-A-C2A2(7-A)9-A-C2A7-9A9-AC3(3A25-A-)CAB25-A-CA24-BAC-2A24-B2A2-D24-B2A-CA24-B2AC-A24-B3A-A24-B3D-D3(24-B2A2-A)24-BD2(3-A24-BA)3-D2(24-BC3-A)24-BA3-A24-BA2-FB24-2BF-2E24-3E-2A4(8-2(A7-)A-4A)8-2(A7-)A-AC2A8-C2(7-A)-A-2A2(8-2(A7-)2(A-)CA)8-2(A7-)2(A-)2A8-9A7-B-AC2A24-B-2(A-2A26-)A-CA26-A2(C2A24-B2A)2-D24-B2A-CA24-B2A2-A24-BD3-A24-B3D-D3(24-B2A2-A)24-BD3-A2(24-BA3-D)2(24-BC3-A)24-BA3-A24-BA2-FB24-2BF-2E24-3E-2A4(8-2(A7-)5AB)8-2(A7-)3ACAB8-C7-A7-2(3A-CB8-2(A7-))3A-AB8-2(A7-)3A-AB8-9A7-3AC2(AB24-3A-)CB24-3A-AB24-3AC3(2A24-B2A-)CA24-B2A2-A24-B2D2-A24-B2A2-D3(24-B2A2-A)24-BD3-A24-BA3-D24-BA2(3-A24-BC)2(3-A24-BA)2-FB24-2BF-2E24-3E-3A4(2(7-A)7-7A)2(7-A)7-3AC3A2(7-A)7-3A2C2A7-C7-A7-3A-C2A2(2(7-A)7-3A-3A)7-9A7-3AC2(2AB23-3A-)CA2(B23-3AC2A)2(B23-B2A-2A)24-B2A-CA24-B2A2-A24-BCD2-A24-B2A2-D2(24-B2A2-A)24-BA2C-A24-BD3-A24-BA3-D24-BA2(3-A24-BC)2(3-A24-BA)2-FB24-2BF-2E24-3E-3A5(2(7-A)7-7A)2(7-A)7-BA2C3A7-C7-A7-B2A-C2A2(7-A)7-B2A-3A2(7-A)7-B2A-C2A7-9A7-2(B2AC3A23-)B2A2CAB23-B2AC2AB23-2BA-2AB23-2(B2A-2A24-)B2A-CA24-B2A2(2-A24-B2D)2-A24-B2A2-D24-B2A2-A24-BA2C-A24-BD2(3-D24-BA)3-A24-BC3(3-A24-BA)2-FB24-2BF-2E24-3E-3A2(7-A)7-2A2-3A2(7-A)7-H3(A2-2A8-A7-A8-)A2-3A2(7-A)8-C2-3A2(7-A)8-A2-C2A7-C7-A8-A2-C2A2(7-A)7-2A2-C2A7-9A7-2A2(2-C2A23-AC)2-CA2(B23-B3-2A)24-BA2-2A25-D2-CA25-2A-C2(A25-2A2-)A24-A2D2-A24-3A2-D24-3A2-2(A24-AD3-)D2(24-2A3-A)24-AD3(3-A24-2A)2-FB24-BF2-2E24-3E-2(4A6-A7-A5-B3A2-)3(4A6-A7-A5-BA-A2-)4A6-A7-A5-BH-C2-4A6-A7-A5-B2(2-C)3A6-C7-A5-B2-A2-4A6-A7-A5-B-2A2-C3A6-9A5-2(B-AC2-C3A20-)B-AC2(2-4A20-B-2A)2-4A22-A3-CABA22-D2(3-C3A22-A)4-ABA22-A4-ABA22-D4-A2(BA22-A4-D)BA22-A4-ABA22-D4-DBA22-A4-D2(BA22-D4-A)2(BA22-A4-A)BA22-A3-F2BA22-BF2-4E22-3E-3(5A5-2(A7-)2A2-)3(4A6-2(A7-)2A2-)4A6-2(A7-)AC2-C3A6-C2(7-A)C2-2ABA6-2(A7-)2A2-4A6-9A7-2(AC2-CABA22-)AC2(2-2ABA22-2A)2-2ABA22-A3-CABA22-D3-C3(ABA22-A4-)ABA22-D3(4-DBA22-A)4-ABA22-D4-ABA22-A4-DBA22-D4(4-ABA22-A)3-F2BA22-BF2-4E22-3E-5(5A5-2(A7-)2A2-)2(5A5-2(A7-)AC2-)C4A5-2(A7-)AC2-5A5-2(A7-)2A2-5A5-9A7-2(AC2-C4A21-)AC2-5A21-2A2-2A2BA21-2A2-2AB-A21-A3-CAB-A21-D3-C3(AB-A21-A4-)AB-A21-D4-D3(B-A21-A4-A)B-A21-D4-AB-A21-A4-DB-A21-D4-D3(B-A21-A4-A)B-A21-A3-F2B-A21-BF2-5E21-3E-6A-A2-2(A7-)2A2-6A-A2-H7-A7-2(2A2-6A-A2-2(A7-))2(2A2-6A4-2(A7-))AC2-6A4-2(A7-)2A2-C5A4-2(A7-)2A2-6A4-2(A7-)AC2-6A4-9A7-AB2-6A20-AB2-C5A20-AB2-6A20-AB2-5AB20-AB2-5A21-BA2-C4A21-BD2-C3(4A21-BA3-)4A21-BD3-2DCA21-BD3(3-4A21-BA)2(3-4A21-BD)3-3DA3(21-BA3-4A)21-BA2-4FA21-BF3-4E21-3E-2(6A12-A5-4A2-)5(6A4-A7-A5-4A2-)3C3A2(4-A7-A5-4A2-6A)4-9A5-4A2-A2C2AB18-4A2-AC3A3(B18-4A2-5A)19-3BA2-3C2A19-3BD2-2C3A19-3BD3(3-4A19-3BA)6-C3(19-3BD6-A)19-3BA6-A19-3BD6-A19-3BC6-D3(19-3BA6-A)19-3BA6-F19-3BF6-2E18-4E5-3(3A-2A-A7-2(A-)5A6-)2CA-2A-A7-2(A-)3(5A6-C2(2A-)A7-A-B-)5A6-C2A-A2-B7-A-B-5A6-3A-A2-B7-A-B2-4A6-3A-A2-9A-B2-4A6-C2A2(-A15-4A6-3A)17-B3A6-2AB18-3A6-2A19-3B6-CA19-2BC6-2A19-2BD3(6-2A19-2BA)7-C2(19-2BC7-A)19-2BD2(7-A19-2BC)7-A19-2BA7-D3(19-2BA7-A)19-2BA7-F19-2B2F6-2E18-4E7-3(A16-5A8-)A16-2A3C8-A12-A3-4AC2(8-A16-5A)2(8-A17-4A)8-A2(17-2ABA8-B)17-2A2(B9-B18-A)B7-2A19-2B7-CA4(19-2B7-2A)19-2B8-C2(19-2B8-A)2(19-2BD7-A)19-2BA7-A2(19-2BA7-D)2(19-2BA7-A)19-2BA27-B2F8-E18-3E6-3(9A6-6A9-)9A6-2A4C2(9-9A6-6A)9-7ABA6-6A9-7AB13A9-3AC3AB13A9-A2C18A9-2C19A9-C9A3D2C6A9-3AB4A2D4C3D4A9-A2C4A6C3A2D3A9-2C4A4C13A7-C4A2C16A7-23A7-8A2D13A7-2A6C7D3A2D3A7-6C2D3A-2A5D4A9-2C7D12A9-8A6D7A9-13A3D5A9-3A3D2C2D6A5D9-5A3CAD11A9-6D5C10A9-D4A6D3C2D5A9-3A2D10A4D2A2(9-21A)9-F18B3F8-21E910-19F11-19E5-
