model
size = 32, scale = 0.05, origin = -y
material 
  colors = A:#333 B:#33F C:#F3C D:#E00 E:#111 F:#0C0 G:#004 H:#DDD I:#CC9 J:#390 K:#0E0 L:#AAA M:#FF0 N:#500 O:#36F P:#003 Q:#3FF R:#3F0
voxels
2(3AG)2(AH)5AK3AH3AG5A3E3(AG)2(AH)2BA2C2(BA)HAH2GAGA3EAE2(AG)5AHA2(B5A)2(GA)2(EA)5G-3HAHA2B2C3BA4H-4GAF3AG3AH11AB7AG3A2BGA3GA4E2(BA)2R3BA5E2GA2GB3(AG)3AE3A3(RA)R7A2(GA)BAGA3GA3EA2R5DARA5EA3GAB5AQ3AE2(3AD)AR3AEAE3ABAB4HAQA3EA2P2(DA)2D2P5EQ5HAH5A2(D3AP3A)D5A3(HA)2HN4DAPA6D2PDA3DN3(HA)H3AN5APAP5AP3A2(DA)H3AHA3HANA4D4P2N3P3(AD)NHA3H3ABANAD3AP3A2(NA)P2(AD)3A2(BA)3BABA-A2-PA3P4N2(AP)A-A2-3BAB5A-2(3AP)2(AN)2(AP)2(A-)3(AB)A4BNA3DA3P2(AN)3P3(DA)BA3BAH7AD2(AP)3APAP7AH3A5HAN2DA2D4PNA3PADA3DN5H2(AH)AN2(3AD)2(AD)APA2(D3A)HA5HAQ5D2P3(DA)2P3DADA5H3AHAQ3AE3ADAD3AP5AEAH3AH3BQAQ4EA2R3(DA)RA5E2QA3B3AGAG5AR3A2(DA)R7A2(GA)2BGA3G2EAEARA3RA4R5E4GAB9AE2(AB)AR3AB5AE2(AG)A2B5GA5HA2B2R3BAHA2H-A4GB3(AG)2(AH)2(3AB)3A2(HA)-2(AG)AFAEAGA3G2(AH)3B2CBAB4H4G2(AE)3AG5AH9ABAH3AG5A4E5G4HB6KB4H5G3EA2E5G2HAHA5KAB4H4GA6E5G4H3B2C3B4H5G5EA5G2(AH)2BACA3B4HAGA2GEAEF5G-5H3B2C3B5H-5GFA3GAG-3HAHA2B2C3B5H-2GA2G2B5G5E4B2-4B5E5GBA3GAG5E-A3-2(A-)A5E5G2B5G5E2-6D2-5E5G3BA3QA3EA2-2(DA)2D-A3EAE3QBAB5HQ5E2-6D2-5EQ5H2(AH)AQ2(AD)ALA6DLADA3DQHA8HN5D2L6D2L5DN7HA2HNA4D4LNA4L5DA10HN5D4L2N4L5DN5H5BNADA2DLA2LNA4LDA3DN3BA6B8-6N8-5BA3BA3-A4-5NA3-A4-3BA6BN5D4L2N4L5DN5B4HAN5D2(LA)2N2(LA)DA3DNHA8HN5D4L2N4L5DN5H2(AH)AN4DA2L3DA2D2L5DA3HA6HQ5D2L6D2L5DQ7HAHAQAEA2E2-6D-AEA3EA5H3B3Q5E2-6D2-5E3Q3BA3GAG5E2-3DA2D2-EA3E2GAGA2B5G5E10-5E5G2B5G2EA2E3BA2-4BEA3E2(AG)A2B5G-5H3B2C3B5H-5GB3(AG)-3HAH3BCA3B2HAHA-A4GF3E5G4H3B2C3B4H5G5EAGA3G4H2BA2C3B2(AH)2(AG)AEA4E5G4HB6KB4H5G3E3AGAG5AH3AKAK9AGAEA4EGA3G4HA2BCA3B2(AH)2GAG3(AE)3A2(GA)2(HA)BAC3AB2(AH)2(AG)2(AE)AGA3G-5HA2B2C3B5H-4GAF3AG3A2(HA)H3AC2(AB)3AHA-3AGA2BGA3G2EA2E4B2-BA2B3EAEA3GAB3(AG)11A-A-7A2(GA)BA3GAG5E2-6D2-5E2GA2G2(BA)2(QA)2(EA)-3(AD)5A2(EA)Q2(AB)4HAQ2EA2E-A6D2-5E5(AH)AQ2(AD)ALAD5AL3(AD)2(AH)A6HN5DLADA4D2L3DADN5HAH3AN5AL7AL3(AD)3(AH)A4HN5D3LANA3L3(AD)N3HAH3ABAN5A2(LA)N3ALAD3ADAB3A3BABA5-A-A6N-A5-A5BAB5A3(-A)2(NA)N2(3A-)3A2(BA)3BAN5DLA2L2NLA2L5DA3BAB3AHAN3AD2(AL)AN3ALA2(D3A)3(HA)2HNA4DLA2L2N4L5DA5H2(AH)7AL2(AD)5A2(D3A)HA3HA2HQ5D2LDA4D2LDA3DQ3HAH3AHAQAE9ADA-3(AE)3(AH)A2B3Q5E2-6D2-5EAQA3BA2(G3A)E5ADAD5A2(EA)G3A2BGA3G2EA2E-A8-3EAEAGA2GB5AG3AE2(AB)A-AB7AE3AGABA3GAGA3HAH2BACA3B5H-5GB3(AG)2(AH)7AB3AH3A-AG3AF3E5G2(AH)3B2C3B4H2GA2GEAE3AG7AH5AB5AH2(AG)AEA4E5G4HB6KB4H5G6EGA3GA3HB3KAKAB4H4GAEA4E5G4H3B2C3B4H5G5EA3GAGA3HA2B2C2(BA)3H5GEAE6F-5H3B2C3B5H-12F-HA3HA2BC2(AB)A4H-12F5E4B2-4B5E6FA5F4EA10-EA3E2FA9F5E10-5E6F2CF3-AEA2E2(-A)3-A2-3EAE3-FA4C3-5E10-5E3-6C7-A3LA2-5LA3-A2-6C7-5L2-5L7-3CAC2(A-)A3-5L2-3LAL4-A-A6CO6-5L2-5L6-O3CA3O6-5L2-5LA5-A7O24-8O2(A9-A-)8O6-5L2-5L6-4OA2CO4-A-ALA2L2-LA3L6-OCA4C7-5L2-5L7-3CACA-A5-A4L-A5L7-6C7-5L2-5L7-6C2(-A)4E7-A2-3EAE3-CA3CF3-5E10-5E3-F2C6F5E-A3-A-A2-5E2FA9F5E10-5E10FAF2EA2EBA2B2-3BAEA3E12F-5H3B2C3B5H-8FA3FAHA3H3B2CBAB5H-2F2(AF)3E5G4H3B2C3B4H5G3EA2E2(GA)G4H3BC2(AB)2(AH)AGA2G6E5G4HB6KB4H5G3E3AHAG5A2(DA)2(KA)DAD7AHA3HAH5G3(DA)2CB2DA2D3GAGA3H2(AH)AG3A3(DA)CABAD2(3AG)2(AH)A3HA4GDA3DA3CA4D3GAGA3H5AF3ADAD3ACAC5AHA-AF3A2(3FA)9-A7-A-6F3(AF)2(3A-)7A-7AF2(A3F)4-A3-A5-A3-A-4FAF2(AC)10(A-)3AC3A3CACA11-A3-A-A4-5C3AC3A2(-A)2(LA)-2(AL)5A-AC3A3CACA5-5L2-LA3L4-ACA3C2(AC)AK5AL3A-AL3AL2(AK)2(AC)A6C5K2LA2L-A5LA4K3CAC7AK2(5AL)3AK3A-AOA5O-3KAK2-2(A-)A5-AKA2K-2OAO7AK3(3A-)3A2(KA)-3A3OAO-3KAK5L-A5L4KA-4O2(AC)2(AK)7A-2(AL)3AK3AC3A6C2(KA)K4LA2-3LALA3KACA3C2(AC)3(A-)3ALA-3A2(LA)-A-3ACA3CA2C2(-A)-5L2-5L4-A3CA2(C3A)-A-7A2(-A)-5A3(CA)4C4(-A)5-3(A-)A2-3CAC3A2(FA)3(-A)2(-3A-A)-3AFA5FAF4-2(A3-)A-A3-A-4F2(AF)3AF3(A-)3A5(-A)-5AFA5FA2H2(DA)D2CAC2DA2D2H-2FA3F2(AH)3AG2(AD)3A2(CA)2(DA)3(GA)HA5H4GADA3DBCABA3DAGA3G2HAH3AH2(AG)3AD3AC3A2(DA)2(GA)G3A5H5G5D4K5D5G8H4GA3DAD4M4DA5G8H5G5D4-5D5G8H5G5D2-A-2DA2D5G2HA5H5G5D4-5D5G4H2JA3JA2JDA3D2-A-2DADA5JA13J12-10JA3CA3JAJ2-A7-A-AJA2J3CA6CF20-F5CA4C2(-A3-A)3-A6-CA8C22-10C3-A-ALA2L2-LA3LA3-ACA3C4IC5-5L2-5L5-C6IAICKA3K5L2-LA3L2KA2KC10I4K2L8F2L4K6I3(AI)4K2LA7F2L2(AK)2(AI)A7I4K2-8F2-4K12I4K2-A5FAFA-4K2IA9I4K2L8F2L4K6I3(AI)4K2L2FAFA3F2L4K10IC5K5L2-5L5KC6IAIC5-5L-A3LAL2-A-AC2IAI5C5-5L2-5L5-9CA7-A3-A-A8-CA8C22-10CF12-A-A5-F10C5J12-5J5CA9J2-A9-6JA12J5D4-5D9J2HAHA3GA5D2(A-)A4D3GAG8H5G5D4-5D5G8H5G5D2(A-)4DA5GAHA5H5G5D4M5D5G4H2(AH)3AGAD3ADAM3A2(DA)3(GA)HA3HAHA4GDA3DA3-2(AD)3(AG)2HAH3AH2(AG)9A-2(AD)5AG4(AH)A4G5D4-A4D5G2HAH2(AJ)3AJ3(AD)2(A-)2(AD)AJ3A2(JA)3JAJA3JAJ2-A-2(A3-)6JA3J2(AC)3(AJ)2(3A-A-)2(AJ)2(AC)A3CA2C-A7-3(A3-)ACA3C2(AC)3(A-)2(3A-)3(A-)2(3AC)A3CA3-A5-A-A10-5CAC7A-A-3A4(-A)-5A2(CA)3IA15-A3-A2-C2I3(AI)2(AK)3A2(-5A)KAK3AIA7I4K2-A3F2(AF)2-4KA3I4(AI)2(AK)A-AF7A-2(AK)AI3A7I2(AK)A-8F2-4K6IAI5A2(KA)-AF3A2(FA)-2(AK)4(AI)A3I2(AK)A-2(A3F)2-2(AK)A3I3(AI)5AKA-3(AF)3A-2(AK)2(AI)A5IC5K4-2(A3-)2(AK)ACA3I3AI3(A-)5A-A2(-3A)-AC2(AI)4C3(A-)A11-A4-5C9A-A-3A3(-A)-5AC3A5CA15-A-A4-5C2(AC)2(A-)5A3(-A)-9A4(CA)JA3J2-A7-A-2JA2J5CA3(J3A)4(-A)-2(3AJ)A7JA2J5D2(A-)4DAJA5JAJ3AH3AG3AD3A2(-A)2(DA)GAG5A3HAH5GDA3DA3-A4D3(GA)3H3AH7A2(DA)2(-A)2(DA)3(GA)HA5H5G5D4M5D5G4HA3H5G5D2MAM2DADA3GAGA7H5G5D4-5D5G4HA3HAGA2G2(DA)D4-5D5GA7H5G5D4-5D5G4HA8J5D4-5D3JA18J6-13J2CA3CA6J2(-A)2-6J15C5J6-5J8CA7CAJA2J6-5J2CA13C16-10CA5CA7-A5-A-ACA5C4I4C16-4C4IA3IC3KAKA3-A5-A-A3KAC10I4K2-8F2-4K6IA3IAIA3K2-A7F2-2KAK12I4K2-8F2-4K6IA5I4K2-AFA5FA-4K2IAIA7I4K2-8F2-4K12I4KA-A5FAF2-4K4IA5IC5K12-5KC8I2CAC2-A13-A3CA3I8C16-8C2(A3C)A3-A-A9-6CA9C5J6-5J8CA7C5J2(-A)2-5JA5CA8C6J6-6J7C4J2(A3J)A-A3-A3JAJA5JA10J5D4-5D9J4H5G5D2(A-)2DADAGA3G8H5G5D4-5D5G6HAH5G2(DA)D2-A-2DADAGA3GA7H5G5D4M5D5G4H5AG7ADAM3A2(DA)G3A3(DA)4DGA2G5DA3B4DAGA2G4(DA)D3AG3A2(DA)B5AD2(AG)5AD2HAH4GA5DA3B5D3GAGA3H5A2(JA)D7AB9A2(JA)7JA3JAJ8BA9JAJ3AC2(3AJ)A-3A-3(AJ)2(AC)3ACA7CA3JA-A3-A3JAJ2C3(AC)2(3AC)2(AJ)3A-3AJAJ5A2(CA)2(3CA)C6-A3-3(A-)2CACA3C2(AI)AC2(3A-)A-3A3(-A)C2(AI)A5IA3CA11-A3-3C3I2(AI)2(3AK)A-3A4(-A)KAK3AIA7I3K9FA4FKAK6I3(AI)5AF3AF9AK3AIA7I3K7FA6F3K4I2(AI)3AI5A3(FA)F5AK3A2(IA)5IAIA2K7FAFA4FKAK6I3A2(IA)K2(3AFAF)3AK3AI3A3IAI3(AK)4-A3-2(A-)2KA2K3(IA)I3A2(CA)8(-A)C3A4(IA)2(CA)7-A3-2(A-)3C3(IA)4(CA)-3A2(-A)2(-3A)3(CA)3CA5C5J5-A3JAJ2CACA3C2(AC)3AC2(AJ)3A-A-3A2(JA)C5ACA6C2(JA)2J3(-A)6J7C3A5(JA)2(BA)B3A6(JA)3JAJA2JDA3D4B5D3JAJA3J2(AH)AG5A2(DA)BAB3AD3(AG)3AH2DA2D2(GA)3DAD4B5D4G5D3AD2(AG)5AD3AB3ADAG3AD3A6D4G5D4M5D4G10D3BABA2B5MABA3BABA10D6BJ8BJ6B5DA3DA3BA2BJ6BABJBA4BDA3D6J5BJ8BJ5B8JAJA7J4BA3BA9JA13J8B12J2CA3CAC5J6-5JA3CA11C5J6-5J10CA5C5J2(-A)2-2(JA)J2CA14C14-9CA3IA4C3-A10-3CA3IA6I4C14-4C10ICA2C7-A-A4-CA2C3IA7I3C14F3C8IA3IA7FA11FA11I20F6IA5IA5FAFA3FA7F4IA7I20F10IAIA2C5FA3FAFA2F3CA3IA6I4C14-4C7IA2I2(CA)2(-A)3-A5-A4C3IA6I4C14-4C5I2CA5CA5-A-A5-A17C5J6-5J8C2(A3C)5J3-A-A5J2CA13C5J6-5J8C6JA5J2(A3B)6JAJA15J8B12JA5J2BA2BJ2BA3BABJ3BAB6J5D6BJ8BJ6B5D2(AD)A6BJA7BA3BA2B3DA6D8B6M8B5D2(AD)AM3A2(KA)B3A2(BA)K3AMAD3A3(DA)M2(A3BAB)A6BM5(AD)AM2(AB)3A4(BA)B3AM3(AD)2JA4M4BJ4BA3B2(AB)A5M2JAJ2(AM)9ABAB3AJAB3(AM)AJA3JABA7BA3BA8BJA3J3AC3(AB)3A2(-A)-2(3AB)AC3A5CA3CABA2B2(-A)2-5B6(AC)3AC5A2(-A)-3A2(BA)4(CA)3CA3C4BA6-BA3B8C5ACAC3A2(-A)2(-3A)C3A2(IA)6ICA2C-A3-A-A6-4CIA3IAI3AC2(3A-A-)3A-5AI3A5IA3CA3FAF2-A-A3F2(AC)AIA3IAI5AFAF3AF2(A-)4(AF)3(AI)A2-5FA3FAF4-2FA8F-AQA-AF3A4(FA)-A-11A-AQ2IA2I5FA3F2-A-9F5IAI3A2(CA)FAF3A-3A2(FA)C3A2(IA)6I3C2(A-)A3-A-A3-A4CIA3I3AI3ACA-5A-A-5AC5AIA5IA4C14-CA2C5I2(3AC)AB5A2(-A)B3ABAC5A3(CA)3C5B5-A5B2CA3C4(AC)5AB3A2(-A)3(BA)3(CA)3CA2C5BA2B6-4(BA)CA3C2(AJ)3A3(BA)3(B3A)BAJ3AJAJ5M3BAJA3B2(AB)2J2BAMA3M2JAJAM5ABAJ2(AB3AB)2(AM)3AJ2DA2D2M2(BA)9BA4BMA3D2(AD)3AM2(5AB)3AB7ADA6D2M5K8B5K2M7DA2D2MKA3KA3EA2EB5KMA10D2M6B6E6B2M10D2M3BA2BEA3EA3BA2B2M3DAD2J5M6B6E6B5M2JAJ2MAMA6BEA3EA6B2(MA)M7J22B5J5C2(3BA)3-A-A3BA4B2(CA)9C5B6-5B12CA3C6B4-ABA3B6CA9C6B4-6B8C2IA2I3CABA3B2-A-5B4C2(IA)6I4C14B4C5IA4I4C9BABA2BCA2CIA8I4C3F8B3F4C10I7FA7B7FIA3I12F8B24F2(A3B)8F2(AF)5I7F8B7F5IAIA2I4C3F4BA3BA2F4C10I4C14B4C5IA3IA4C3BA10B4C10I4C5B4-5B4C5I2(A3C)4BAB2-A-2BA3BA5CA9C6B4-6B8CACA3CAC4BA-A4-2(BA)B4CA8C8B6-8B5C5J3BA9BA8B7J5M6B6E6B5M4J4MA5BA6E2(BA)2B5M2J5D2M6B6E6B2M5DA3DA2M6B6E5BA2M10D2M5KB6EB5K2M5D2(AD)AM5AKAE3AEAB3AKAMAD3A5DA2M5BA5EA5BA2MDA3D2(AD)AM3ABAB3AEAE3ABAB3A3(DA)JAMA2M6B3EAEA6BMA3M2JAJ2(AM)AB3AB3(AE)A2(B3A)2(MA)JA2J2-5BAB2(A3B)A6B2-JAJ7A2(B3A)2(-A)B3AB5ACA3CA5C5B3-A2-3BAB4CA3C3(AC)5AB5A-3(AB)AC3ACA7CACA5B2-A-A5BA7C3AI2(AC)3(AB)3A-3AB3AC3(AI)A3IACA2C3BA10B2(CA)5IAI5AC7A2(BA)B3AC5AIA3IA2I3C2(AF)8B3F2(CA)3IAI9AFAF3ABAB2(3AF)3(AI)4FAFA5F4B2(AB)2F2(AF)A3F2(AF)3A2(FA)F5A3(BA)6(FA)4I2(FA)3F6BAB2(AF)A2FIA3I3AI3ACAF5ABAB3AF2(AC)2(AI)A6ICA2CB2(A3B)A4B4C5I2(AI)AC3A3(BA)B3A2(BA)C3AI3A3IA2ICA2CBA3BA3-2BA2B4C3(IA)2(C3A)3(BA)-A-7AC3ACA9CA5B2-A-6B2CA3C3(AC)3AC3AB2(A-)3A2(BA)B5A2(CA)4C2(BA)4B6-5BABA5C3A-3(AB)3AB7A3(BA)-3AJAJ5M3BA2B3(EA)3BA2B3(MA)J5AMAB3AB3(AE)3ABAB3A2(MA)J2DA2D2MBA3B2(AE)A2E3BA2BMA3D3(AD)AM3AB3A2(EA)E3A2(BA)M3ADA6D2M5KB6EB5K2M5DAEA2E2MKAGA3G2EAE2GA2GKA2MEA8E2M6B6E6B2M9EA2MBA4B6E5BA2M10E2M6B6E6B2M7EA2E2MBA4B6E2(BA)2B2M2(EA)E3J2O8B6-8B2O3J4CA5BA2B3-A-A7BA13C5B6-5B8CACA5CA3BABA3-4BAB16C6B4-6B10CA6C5B4-A4B18C14B9CACA6CBA5BA3BA2B3CA14C14B9C2FAFA4F11BA2B7FA10F14B9FA8F3BABA8B7FA10F14B9F6CACA3B3(AB)A4B2(3CA)10C14B9CACA3CA2CB2(A5B)ACA16C5B4-5B11CA5C6BA3-6B2CACA11C6B4-6B8CA5CAC4BA3-A2-5B13C8B6-8B5CA2JOA8B-A4-5BA2BOA3J5E2M6B6E6B2M7EA2E2M3BABA3EAEA3BA2B2M3EA6E2M6B6E6B2M7EA2EMA6B6EBA4B2M3EA6E2M2K5G4E5G2K2M5E2(AE)3AK2(AG)3AE7AK2(3AE)A4EMA5BA5EA6BMA5E2(AE)AM5AB5AE3(AB)AMAE3A2(EA)2EMA6B6E6B2M5E2(AE)5A2(BA)E3AE3(AB)3A3(EA)JAOA7BA-A3-3(AB)A2B2O2(JA)CAC5ABAB3A2(-A)4(BA)4(CA)3CAC2BABA6-5B2(A3C)3A3(CA)3(BA)-A-3ABAB3A2(CA)5C2(AC)2BA3B2(A-)6B6CAC5A2(CA)3(BA)-3AB5A3(CA)8C-A3BA9BA-ACA3CAC3A2(CA)F3A6(BA)F3AC3A5CACA2F3BABA3BA4B2F5CAC3AF5A3(BA)B3AB5AFAF3A5FA4F2(BA)3BA6BFA7FAF3A2(FA)6(BA)B3AFAF3A7FAFABA7BA4B9F2(AC)3AF6(AB)3AF3AC3A3CA4CFABA11BAFA3C4(AC)3A-3AB9ABA-AC3A2(CA)2(3CA)3BAB4-5B5C5(AC)3A3(BA)-3A3(BA)3(CA)2(3CA)C6B2(A-)2BA3BA7C3(AC)3ABAB3A2(-A)BAB3A3(CA)6C3BABA2B5-A7BACA3CAJAO4(AB)5A-4(AB)AO2(AJ)A3EAMA3BA2B5EA3BA2B2M5EAE3AM3ABAB3A2(EA)2(BA)B3AE3A6EMA5BAEA4E3(BA)MA5E7AB3ABAE5A3(BA)M3AEA6E2M2K5G4E5G2K2M10E4B5G2EAE2GA2G2(BA)2(EA)2(6E8B)9EA7BA3EA2E2(BA)4BEA8E8B6E8B10E3(BA)2B6E3(BA)2BEA3E5O8B6-8B5O2CA5C5B5-A5B2CACA11C5B6-5B12CA4CBA3BA3-A4BCA5CA10C5B4-5B13CA3CA5B2-A-4BA5CACA8C2-14B2-7CA6C2F3B2(AB)A6B2F14C2F14B2F7C2F2(AF)A2F3BA10B3FA14F14B18F7BA3BABA3FAFA12F14B9FA3CA2C2F3BA7BA2B2F14C2F14B2F9CA3CA2-5BABA3BA2B-A3CACA10C5B4-5B11CA3CA2CBA3B4-A3BA5CA12C5B4-5B9C2(A3C)5B5-3(AB)4CACA9C5B6-5B8C2OA2O8B2(-A)2-BA5BA3OAO5E8B6E8B10EBA3BA2BEA3EA5BABA3EA2(6E8B)5E2(AE)A3BA4B6EBA3BA2BEA8E4B5G4E5G4B5E2(AE)AB5A2(GA)2(EA)2(GA)BAB3A4(EA)2(BA)4BEA4E2(3BA)4(EA)2(E3A3(BA)2(EA))EA4E8BEA3EA8B5EAE3ABAB3AB5AE3ABAB2(3AE)AOA2O8B6-5BABAOA3O5ACAC5A3(-A)B5A3(CA)7CAC2BA2B6-3BAB6CA3(C3A)BAB3A-AB2(3ACAC)A8CBA3B4-A3B2(AC)A5CA2(C3A)B3ABA-3AB2(3AC)ACA5CA2C-ABA3BA7BA2-7C3(AC)AF4(AB)5ABAF3(AC)2(A3C)AFA5BA3BA4BFACA5C4(AF)2(AB)3A2(BA)B7A3(FA)8FBA5BABA3BA3FAFA3F3A2(FA)F3AB7A2(BA)F3A2(FA)5FAFA2F3(3BA)2B3FAFA3F5ACAF5AB7AB3ACAC3A5CACA2FB2(A3B)A4B2F7C3A2(CA)-3A4(BA)B3A-AC3ACA9CA3BAB2-A-2BA2BCA7C2(AC)3AC3ABAB3A-2(AB)5(AC)A8C3BAB4-4BACA5C2(AC)3ACAC5A2(-A)-3AB3A4(CA)5CAC5B2(-A)2-5B4C2(AC)2(AO)4(AB)3A2(-A)2(B3A)O3AO2EA2E3BABA2B3EAEABA5BA5E3AE3A3(BA)3(EA)4(BA)E3AEA4E2(BA)3BA5E2(A3B)A3E3(AE)2(AB)3AB3AE7A2(BA)2(EA)6E4B5G4E5G4B5EA4E2MKA3GAG2(AE)A3GAKAMA3EA6E2M6B6E6B2M7EA2E2M3BAB3(AE)3(AB)A2M2(EA)6E2M6B6E6B2M10E2M6B6EBA4B2M5E3J2O8B6-8B2O3JA4C8B3(-A)3BA4B13C5B6-5B10CA3CACA3BAB4-6BA5CA9C6B4-6B8CA7CABA3BA3-5B5CA10C2-14B2-13CAFA3BA10B2F3CACA8C2F14B2F7CA8FBA7BA4B2(3FA)10F14B11FA6F3(BA)8B4(FA)10F14B9F4CACAFA5BA7BA2F3CA10C2F14B2F14C2-3BA7BABA2-16C5B4-5B13C2(AC)6BA3-A3BABACA13C6B4-6B8CACA5C5B-A4-3BAB2CA3CA6C8B6-8B5CA2JOABA5BA5-ABA5BAOA3J5E2M6B6E6B2M5E2(AE)A2M5BA5EA3BA2BMAEA8E2M6B6E6B2M7EAEAMABA4B5EABA4B2M10E2M2K5G4E5G2K2M5E2(AE)3AKAG5A2(EA)G5AM2(AE)A3EA2E2M3BABA5EA6BMAEA3E3AE2(3AB)2(AE)3ABAB3AM2(AE)A3EAEA2MBA3B2(AE)A2E6B2M3EA2(E3A)BAB3AEAE3AB9A2(EA)2J2O5BABA6-7BA2OJAJ7A3(BA)2(-3A)BAB3A2(CA)3CA5C5B3-A2-5B2CACA3C2(3AC)3(AB)A-5A2(BA)3(CA)3CA5C2B2(AB)A3-4BAB8C2(AC)5AB3ABA-3AB3AC5ACA10C14BCA7C4(AC)4(AB)3AB3(3AC)A8CB3(A3B)A9C5A2(FA)6(BA)B5AF3A5F2(AF)A3BA7BA2B9F4(AF)AB3A2(BA)2(B3A)5(FA)3FA2F2(3BA)BA4B3FA5F5A2(CA)B3AB5AB2(3AC)ACA10C7BA3BA2B7CAC5ACAC9AB3AB2(AC)3A2(CA3CA)5B4-2BA2B2(CA)5C4(AC)2(AB)3A-2(3AB)3A2(CA)9C2BA3B4-A5BA3C3(AC)5AC2(AB)3A2(-A)2(BA)B5ACA3CACA3BABA2B6-2(BA)3BA5C3AO2(3AB)5A-3(AB)7AJ5E2M5BA3EA2E6B2M5E2(AE)AM5AB3A2(EA)2(BA)B3A3(EA)4EMA5BA6E2(BA)2B2M3E3(AE)AM5AB2(AE)3ABAB5A2(EA)6E2M2K5G4E5G2K2M5EA4DMA3KAKB5EABA3KA2MDA8D2M6B6E6B2M9DA2M6B2(EA)2EBA4B2M3DAD2J5M6B6E6B5M4J4MA6B5EA6B5M5J2-22B2-3J2CA2C3BA4B3-A2-5BA2BCA11C5B6-5B8CA7C2BA3B4-6B16C6B4-6B8C5I4C5BA3-A3BA3CA3IA6I4C14B4C5I2(AI)A4C7BA5BA4CIA8I4C3F8B3F4C10I2(FA)3F2BABA3B7FIA3I12F8B18FA3FAFA7B8F2(AF)5I7F8B7F5IA4I4C2(FA)3BA3B3FCA2C3IA6I4C14B4C10ICA2C5BA3BA4BCA2C10I4C5B4-5B4C5IA7C6B4-A5BA3CA11C6B4-6B12CA3CA3B2(A-)A2-BA3BA5CA6C8B6-8B5CA2J2-9BA7BA4B2-5J5M6B6E6B5M4J2MAMA5BA3EA2E2(BA)2B3(MA)J5D2M6B6E6B2M10D2M2(BA)2BEA3EABA4BMADA8D2M5KB6EB5K2M5DAD3AM7AEAE7AKAM3ADA3DADA2M3BABAEA4E5BA2M3D3(AD)AM5AB3(AE)2(AB)3AMAD3AD2JA4M3BA2B5EA3BA2BMA3M2(AJ)2(AM)2(AB)7AEA2(B3A)2(MA)JA3JABA3BA7BABA3BA2BJA3JAC2(3AB)AB3A-2(3AB)AB4(AC)A3CAC5B-A4-BA3B2CA3C3(AC)3AC2(5AB)AB5A2(CA)9C4BAB4-6B4CA3C2(AI)3ACAB3AB2(A-)2(AB)3AC2(AI)A3IAIA3CA7BABA4B3C5(AI)5AB3A2(B5A)C2(AI)A3IA2ICA2CFAF8B3F3C3(AI)3AI3(AF)3AB5ABA2(F3A)2(IA)7FA3F2(A3B)4FAFA5FAF3A4(FA)BAB3ABAF5A3(FA)2(IA)3FA3F2BABA3B2(AF)A2F3IAI3AIAC5AF2(AB)5AF2(AC)5A6I4C5BA8B4C5I3AIAC9AB5ABAC3AI3A3IAIA4C5B2(A-)4BA4C5I4(AC)AB5A-A-3AB3AC5A3CACA3CA5B2(A-)4BAB2CA5C4(AC)2(AB)3(A-)AB3AB3(AC)A6C2(BA)4B3-A-ABA3BA2BCA3C2(AJ)3AB5A7(BA)2(JA)3JA4M2(BA)2B6E5B3(AM)AJ3A2(MA)2(BA)B3AE3A3(BA)MAM3AJ5D2MBA3BA3EA2E3BA2B2M3D2(AD)7ABAB3A2(EA)2(BA)B3AD3A6D2M5KB6EB5K2M5DADA2DMA3KAK2B3(AB)5KM2(AD)A6D2M18B2M5DA4DM2(A5B)A3BA2BMA5D2J5M4BJ8BJ4B5M4JAMA2MBAB2J4B2(AB)2JA2B5M7J22B5J2CA2CBA3BABA5-ABA6B2(CA)9C5B6-5B8CA7C4B2(A-)A2-3BAB16C5B6-5B8CA4I4C2(-A3-A)-A4C3IA6I4C14-4C10ICA2C14-4C2(IA)6I4C5F4-5F4C9I2(AF)A5F2(A-)2FAFA3FAIA3IQ2-11F4-11F2-QA2-3FA7FA3-A3FAFA4F-AQ5I9F4-9F10I4CFA3FA3-A4F3CA10I4C14-4C7IAIA4C11-A2-4CIA8I4C14-4C5IA5CAC5B3-A2-3BAB2CA13C5B6-5B8CACA3CAC2BA2B5-A3BABA3CA8C8B6-8B5CAJA2J19BAB2(AJ)A3J5M3B2J8B2J3B5M2JAJ4MA4BJA5BABJ4B3MAM2J5D2M18B2M5DA4D2M2(BA)13BA2M10D2M5K8B5K2M5DAD5A2(BA)B3A2(MA)4(BA)5(DA)3BA2BJ8BA3BA2B5D3ADA3(B3A)2(BAB3A)DAD6JA4BJ4B2(A3B)AB4J4(AJ)3A2(JA)4(BA)J5A2(JA)11JAJ2BABA3B8J2(AJ)2(AC)3AC7A2(-A)JAJ5A3(CA)7CA4J6-3JAJ4CA3C3(AC)3A2(JA)3(-A)J3AJ2(AC)3A3CACA3C2(A-)A5-A3-A5CA3C3AIAC3A4(-A)-5ACAC3A2(IA)4I4C5-A8-4C5I3AI2(AC)3(3A-)A-2(AC)6(AI)3CFA9FA2F3CA5IAI3AI3(AF)2(3AFAF)AFAI3A3(IA)I14FA3FAF2IA3I3(AI)4(AF)2(3AFAF)5A3IA3I2F2(AF)A11FAF2I2(AI)3AI7AFAF3AF5A2(CA)2(IA)6I2(CA)3-2(A-)A6-4C5I3AI2(AC)5A4(-A)-3AC3AIA5IA4C9-A3-ACA2CIA3IAC3AC11A-3A-3(AC)3ACA7C2JA2J5-AJA3J2CACA3C2(3AC)3AJ3A-3A3(JA)4(CA)7C2JAJA-A4-JA3J8C4(AJ)3AJAB3A2(BA)J3A3(JA)5JA7J8B12J3A2(JA)BAB7A2(BA)B5A3(JA)3DA6BJA7B2(AB)A2B3D2(AD)7ABAJ3(AB)3A2(BA)B5A6D8B6M8B9DA4G5DA3M2DADA4G10D4G5D4B5D4G5DA3DAGA2GDA3D2BAB5D4G5D4H5G5D4B5D5G4HA7JA3DAD4B4DA7JA13J8B12J4CA2C5JA3-A2-3JAJA3CACA9C5J6-5J16CAJA2J6-3JAJ2(AC)A11C16-8CA3IA3C2(A3-)A-A5-A2C3IA6I3C16-3C10I2(KA)K4-A-A5-AKA2K11I3K14F3K12I3K14F3KA3IA7I3K14F3K6IA3IAIAKA3FA7FA2F2(KA)2(IA)7I3K14F3K6IA3IAI3K3F2(AF)A6F3K11I5K12-5K9IA3C4-A-A3-A5-ACA3IA6I3C16-3C5IACA5C14-A-4CA11C5J6-5J14CAC2JAJA5-A3JAJ6CA8C6J6-6J7C2JA3JA5J6BAB21J5D4B5D9J4H4GA5DA3B2DADAGA3G2HAH5D4G5D4B5D4G5DA3DA4G5D2(AB)5DGA2G3DA6D4G5D4M5D4G5DAH3AG5ADAD3AM2(AD)3A2(GA)HA3HAH2GAGA5D4-A3DA5G4(AH)2(AG)2(AD)5A-AD2(3AG)3AHA3H5GDA3D4-4DAGA3GA3HAJ7AD5A-3A2(DA)2(JA)J3A3JA5JA4J3-A-A7JA5J3AC3A2(JA)J3A-A-5AJAC3A2(CA)7C2JA2J5-A5J2CA3CA2(C3A)CAJ5A2(-A)2(JA)J3A2(CA)9C16-A5CAC3ACAC3(3A-)A-3A-AC5AC4IA3C2-A5-2(A3-)2(AC)2I2(AI)2(3AK)A3(-3A)K5A2(IA)3IAI4K2-8FA-2(AK)6I3(AI)AK7AF3AFA-2(AK)2(AI)2(A3I)A3K2-2(A3F)A-4K6IAI3AI2(AK)3AF5AFA-2(AK)2(AI)A7I4K2-2FA5F2-4K4I4(AI)AK5A4(FA)-5A3(IA)3IC5K10-A-A4KC4IAI5ACA3(-3A)2(-A)CAC3AI4CA3CA7-A-A3-A-4CA3C4(AC)3(A-)3A4(-A)C3ACA5C2(AC)2(AJ)A-A4-JA3JA5CAC3A2(CA)C3AJA-3A-5AJ2(AC)3ACA6C3JAJ2(A-)A2-5JA3C2(AC)2(AJ)7AJ2(A-)9AJ3AJA7JA2J5D4-2DA2D2(3JA)JAH3A2(GA)D5A-3A2(DA)2(G3A)HA3H2(AG)A3DADA3-A4D5G4H2(AH)2(AG)AD3AD2(A-)2(AD)3AGAG3A5H5G5D4M5D5G4HA3HAGA2G3DAD2MAMA4D3GAG2HA5H5G5D4-5D5G6HAH4GA5D4-2DA2D5G2HA5H5G5D4-5D5G4H2JA3JA2J5D2(A-)2DA2DJA5JA11J12-10J4CA5J4-2(A3-)4JA10C22-7CACA-A9-2(A3-)A2-CA8C22-7CA2C7-A-A7-A4-2(CA)C4IC22-C4I2(AI)CKA3K6-A3-A-4KAC10I4K2-8F2-4K6IA3IAI2KAK2-2FA5FA-4K2IAIA7I4K2-8F2-4K8IA3I4K2-2FA5FA-A3K12I4K2-8F2-4K8IA3IA3K2-2FA3FAF2-A3K2IAIA5IC5K12-5KC8IC7-A5-A7-AC4I5C22-9CA21-A10C22-5CA4C-2(A3-A5-)2(AC)A6C5J12-5J5C2JA7J2-A7-A-4JAJA12J5D4-5D9JA3H5G5D2-A-A4D5GAHA5H5G5D4-5D5G4H2(AH)4GA5D2-A-2DA2D3GAG2HA5H5G5D4M5D5G4H5AG7AD2(AM)5A2(GA)G3AHA3H5GDA3DA3-A4D2(GA)G4H2(AH)5AD7A-AD3A2(GA)G3A5H5GDA3D4-5D2(GA)G4H3AJ5ADAD3A-5AD3AJAJ3A11JA11-2J2(AJ)A3J5AJ3AJA2(-3A)-A-3AJAC3A6CFA13-A5-F5C5A4(-A)2(-3A)3(-A)2(CA)5CA7-3(A-)A3-2(A-)A3C3(AC)A2(-3A)LA-A2(L3A)-3(AC)4IC-A3-5L2-LA3LA3-AC4I3AI2(AK)11A2(LA)2(KA)C3A5IAI4K2L4FA3F2L4K4I2(AI)3AI2(AK)AL3A3(FA)L2(AK)3A2(IA)5IA3KA-6FAF2-2(AK)AIA3I3AI3A2(KA)-3A3(FA)-5AI3AIA3IAI2KAK2L4F2(AF)AL2(AK)2IA3I3A2(IA)K7AF3AFAL2(AK)3(AI)A3ICKA3K5L2-3LALA3KAC4I2(AI)2(A-)3AL5A3(LA)2(-A)C3AI2CACA-A3-A4L2-5LA-A2-CA3C3ACA-3A-A-5A3(-A)-5A3(CA)2C-A3-A-A11-A-A3C2(AC)5A-A-5A2(-3A)2(-A)3(CA)4C3(JA)11-AJA2J5CAJ5A2(JA)-A2(-3A)-4(AJ)A10J3DAD2-A-4DA7JAJ2(AH)3AG3(AD)2(A-)2(AD)2(AG)3AHA3HAH5G5D2(A-)A3DAGA3G4H2(AH)3AG3AD5A-3ADAG7A5H5G5D4M5D5G4HA3H2GAGADA3D4KA4D5GA7H5G5DB2CB5D5G8H5G5DACAB2DA2D5G8H5G5D4C5D5G4H6FA2H5D4C5D2H-2(AF)A7F20-8FA3F2(A7-)2(A-)2FAFA7F20-6FA4C3-3(A-)2(A3-)A4-10C22-5CA4C5-5L-A5LA3-A10C5-5L2-5L5-10C5KALA2L-ALA3L2KA2K2(CA)6C5K5L2-5L5K5C2OAOAKA3KA3LA2-5L4KA-2OA5O-5K12-5K-8O-KA3K2(A5-)2KA2K-A7O-5K5L2-5L5K-4OA4C3KAK2LALA-A3LAL4KA10C5K5L2-5L5K10C3-A-5L-A5L2-A2-CA8C5-5L2-5L5-5CA4C-A3-2(A-)A3-A-A6-10C22-5CAFA3FA-A9-A7-4FA7F20-8FA3FA-A9-A7-2(AF)A7F-2H5D4C5D2H-6F4HA3G3(AD)4CADA2D3(GA)HA5H5G5DB2CB5D5G4H2(AH)A3GA3DADB2CBADA2D5GA7H5G5D4K5D5G4H2(3AG)AH3AK5AB5AG5AEA2E5G4H3BC2(AB)A3H4GA3E3AG5A2(HA)BAC2(AB)5AGAG3AEA5FA3HAHA2B2C3BA4H-A5FAF5AH3AHABAC2(AB)3AHA-2(AF)A7F2EA2E2(BA)2-BA2B5E6F5AF2(AE)3(A-)5A3(EA)2(FA)2(3FA)3EA-A5-A2-3EAEA5FACA-3AE3A3(-A)-3A2(EA)E3AFA4C3-2EA2E5-A4-3EAEA2-2(CA)C3A2(-A)-5A-2(AL)5A2(-A)3(CA)3-A3-2LA2L2-LA3LA5-A3CAC3A-A-3AL3A-2(AL)5A-3A2(CA)2COA-A3-A4L2-5L6-O3C3AOA-3A-2(AL)A-2(AL)2(3A-)2(AO)A3O3(A3-)2(A-)A5-A-4(AO)6(A-)5A4(-A)OA3OAO4-A-2LALA2-5LA5-2OAOACAOA2(-3A)L3AL7A-A-3A3CA-A5-5L2-5L7-3CAC3A3(-A)2(LA)-AL5A2(-3A)2(CA)2(3-A)2(LA)2-LA3L2-A4-3CAC3A-AE3A2(-A)-7AE3A-ACA3CF-A-4EA5-A4-3EAE2-AFAC3(AF)AE2(3A-)A-3A3(EA)F3AFA3FAF5E-A7-AEA3EA5F3(AF)AE2(3ABAB)3AE3A3(FA)5F-3HAHA2BCA3B5H-6FAF3AF7ABAC2(AB)2(AH)A-3(AF)2EA5G2HAH2BACA3B2HAHA4G3E3AGAG5AH3AC3AB2(AH)AG5A4E5G4HB6KB4H5G6E5GA3HBKA4KB2HAH2GA2G6E5G4H3B2C3B4H5G3EA2E5G4H3B2C3BA3H4G2(AE)F5G-5H3B2C3B5H-5GFBGA3G-5H3BC2(AB)2HAHA-A4G2B5G5E4B2-4B5E5G2B3(GA)EA2E2(3-A)2-5EA4G2B5G5E2-6D2-5E5GBA2BQAQ2EAEA2-3DA2D2-5EA2QBAB5HQ5E2-6D2-5EQ5HA4HQ4DAL3(AD)A2LDA3DQ2(HA)6HN5D2L6D2L5DN10HNADA2D2(LA)NA3LA5DN2(HA)6HN5D4L2N4L5DN5HA4BN4DA3LA2N4L5DNBA8B8-6N8-10B7-A3NA2N7-A10BN5D4L2N4L5DN5B5HNA4D3LA2N4LDA3DN10HN5D4L2N4L5DN5HAHA2HN5D2L3DADA2L5DA10HQ5D2L6D2L5DQ5H2(AH)AQ4EA2-3DA2D-A3EAEQ5H3B3Q5E2-6D2-5E3Q4B5G2EA2E-A5DA2-5E5G2B5G5E10-5E5G2B3GAGA3EA4B-A3BA5EA4G2B5G-5H3B2C3B5H-5GBF5G-5H3B2C3BA4H-5GF3E5G4H3B2C3B4H5G3EA2EGA3G2HAHA2BCA3B2(AH)A4GEA4E5G4HB6KB4H5G3E7AG2(AH)7AB3AH3AG3A4E2(GA)G2HAH2BA2C3B4H4GA3EAE3AGAG3AH3AC5AH3A2(GA)EAEF3GAG-3HAH2BACA3B2HA2H-AGA2GF5AG3AH3ABACAB3AHAH3A2(GA)2B5G2EAEABA2B2-3BA3EAE4GAB3AGAG3AE2(A-)3A2(-A)2(E3A)GA2B5G2EAEA2-6D2-3EAE4GAB3AQAQ3AEA-2(AD)3A-3A2(EA)Q3AB5HQ2EA2E-ADA4D2-EA3EQHA3H3AHAQ3ADAL3(AD)AL7A2(HA)5HAN4DA2L6D2L5DA5H2(AH)3A2(DA)2(LA)NAL5AD3A5(HA)N5D4LNA3L3(AD)A3HAH3AB5AD3ALAN3AL3(AD)4(AB)A2B8-5NA3-A4-3B3(AB)2(A-)5A2(NA)N3A-A-5A2(BA)3BANA4D3LA2N4L3DADN3(BA)H7AD5AN5ADAD3A3(HA)3HANA4D4LN2(AL)A5DN3H3(AH)AN2(AD)3A3(DA)LA2(D3A)HA6HQ2DADA2LDA4D2LDA3DQ5H2(AH)AQ5A-3ADAD5AE2(3AH)3B3Q5E-A6D2-EA3E2Q2(AB)2(AG)5AEA-AD5A-AE5A2(GA)BAGA3G4EA9-A5E2GA2GBAG3AGAE3AB3A-AB5AEAE3AGABAGA3G-HA3HA2B2C3BA3HA-4GAB5AG5AH5AB7A-3AGAFAEA3GAGA3HA2B2C3B4H4G3(AE)3A2(GA)H5ACAB5AHAG5A4E2(5G4HB6KB4H5G6E)5G4H3B2C3B4H5G6E5G4H3B2C3B4H5G3EF5G-5H3B2C3B5H-5GFB5G-5H3B2R3B5H-5G2B5G5E4B2R4B5E5G2B5G5E10R5E5G2B5G5E2R6D2R5E5G4B3Q5E2R6D2R5E3Q3B5HQ5E2P6D2P5EQ10HQ5D2P6D2P5DQ10HN5D2P6D2P2(5DN10HN5D4P2N4P)5DN5H5BN5D3P4N3P5DN2(10B4-5P4N5P4-)10BN5D3P4N3P5DN5B5H2(N5D4P2N4P5DN10H)N5D2P6D2P5DN10HQ5D2P6D2P5DQ10HQ5E2P6D2P5EQ5H3B3Q5E2R6D2R5E3Q4B5G5E2R6D2R5E5G2B5G5E10R5E5G2B5G5E4B2R4B5E5G2B5G-5H3B2R3B5H-5GBF5G-5H3B2C3B5H-5GF3E2(5G4H3B2C3B4H5G6E)5G4HB6KB4H5G3E
