model
size = 21 28 23, scale = 0.05, origin = -y
material 
  colors = A:#001
voxels
--------------------- --------------------- --------------------- --------------------- --------------------- --------------------- --------------------- --------------------- --------------------- --------------------- --------------------- --------------------- --------------------- --------------------- --------------------- --------------------- --------------------- --------------------- --------------------- --------------------- --------------------- --------------------- --------------------- -----------------AAA- ----------------AAAAA -----------------AAA- ----------------AAAAA --------------------- 
--------------------- --------------------- --------------------- --------------------- --------------------- --------------------- --------------------- --------------------- --------------------- --------------------- --------------------- --------------------- --------------------- --------------------- --------------------- --------------------- --------------------- --------------------- --------------------- --------------------- --------------------- --------------------- ----------------AA--- ---------------AAAAA- ---------------AAA-AA ---------------AAAAAA ---------------AAAAAA ----------------AAAA- 
--------------------- --------------------- --------------------- --------------------- --------------------- --------------------- --------------------- --------------------- --------------------- --------------------- --------------------- --------------------- --------------------- --------------------- --------------------- --------------------- --------------------- --------------------- --------------------- --------------------- --------------------- --------------AAAAA-- ---------------AAAAA- --------------AA---AA ---------------AA---A ---------------AA---A ---------------AAAAAA ----------------AAAA- 
--------------------- --------------------- --------------------- --------------------- --------------------- --------------------- --------------------- --------------------- --------------------- --------------------- --------------------- --------------------- --------------------- --------------------- --------------------- --------------------- --------------------- --------------------- --------------------- --------------AAA---- --------------AAAAA-- --------------AAAAA-- --------------AAAAAA- --------------AA---A- --------------AA---AA --------------AA---AA ---------------AAAAAA ----------------AAAA- 
--------------------- --------------------- --------------------- --------------------- --------------------- --------------------- --------------------- --------------------- --------------------- --------------------- --------------------- --------------------- --------------------- --------------------- --------------------- --------------------- --------------------- --------------------- --------------------- -------------AAAA---- -------------AAAAA--- -------------AA--AA-- -------------AA---AA- -------------AA---AA- --------------AA---AA --------------AA---AA ---------------AAAAAA ----------------AAAA- 
--------------------- --------------------- --------------------- --------------------- --------------------- --------------------- --------------------- --------------------- --------------------- --------------------- --------------------- --------------------- --------------------- --------------------- --------------------- --------------------- --------------------- ------------AAA------ ------------AAAAA---- ------------AA--AA--- ------------AA---AA-- ------------AA---AA-- -------------A----AA- -------------AA---AA- --------------AA-AAA- ---------------AAAAA- -----------------AA-- --------------------- 
--------------------- --------------------- --------------------- --------------------- --------------------- --------------------- --------------------- --------------------- --------------------- --------------------- --------------------- --------------------- --------------------- --------------------- --------------------- --------------------- -----------AAAA------ -----------AAAAAA---- -----------AAAAAA---- ------------AA--AA--- ------------A----A--- ------------AA---AA-- -------------AA--AA-- --------------AAAAA-- ---------------AAA--- ---------------AAAAA- --------------------- --------------------- 
--------------------- --------------------- --------------------- --------------------- --------------------- --------------------- --------------------- --------------------- --------------------- --------------------- --------------------- --------------------- --------------------- --------------------- --------------------- --------------------- ----------AAAAA------ -----------AA-AAA---- -----------A---AA---- -----------AA---AA--- ------------AA-AAA--- ------------AA--AA--- ------------AAAAAA--- --------------AAAAA-- --------------------- --------------------- --------------------- --------------------- 
--------------------- --------------------- --------------------- --------------------- --------------------- --------------------- --------------------- --------------------- --------------------- --------------------- --------------------- --------------------- --------------------- --------------------- ----------AAAA------- ----------AAAAA------ ----------A---AA----- ----------AA---A----- ----------AA---A----- -----------AA--AA---- -----------AAAAAA---- ------------AAAAA---- --------------------- --------------------- --------------------- --------------------- --------------------- --------------------- 
--------------------- --------------------- --------------------- --------------------- --------------------- --------------------- --------------------- --------------------- --------------------- --------------------- --------------------- --------------------- ---------AAA--------- ---------AAAAA------- ---------AAAAA------- ---------AAA-AA------ ---------AA--AA------ ----------AA--AA----- ----------AAAAAA----- -----------AAAAA----- -------------AAA----- -------------AAA----- --------------------- --------------------- --------------------- --------------------- --------------------- --------------------- 
--------------------- --------------------- --------------------- --------------------- --------------------- --------------------- --------------------- --------------------- --------------------- --------------------- --------------------- --------------------- ---------AAA--------- --------AAAAA-------- ---------AA-AA------- ---------A---A------- ---------AA--AA------ ----------AAAAA------ ----------AAAAAA----- -----------AAAA------ --------------------- --------------------- --------------------- --------------------- --------------------- --------------------- --------------------- --------------------- 
--------------------- --------------------- --------------------- --------------------- --------------------- --------------------- --------------------- --------------------- --------------------- --------------------- --------------------- -------AAAAA--------- --------AA-AA-------- --------A--AA-------- --------AA--AA------- --------AA--AA------- ---------AAAAA------- ----------AAAA------- --------------------- --------------------- --------------------- --------------------- --------------------- --------------------- --------------------- --------------------- --------------------- --------------------- 
--------------------- --------------------- --------------------- --------------------- --------------------- --------------------- --------------------- --------------------- --------------------- -------AAA----------- --------AA----------- -------AAAA---------- -------AA-AA--------- -------AA-AA--------- --------AAAAA-------- ---------AAAA-------- --------------------- --------------------- --------------------- --------------------- --------------------- --------------------- --------------------- --------------------- --------------------- --------------------- --------------------- --------------------- 
--------------------- --------------------- --------------------- --------------------- --------------------- --------------------- --------------------- --------------------- --------------------- -------AAA----------- ------AAAAA---------- -------A--AA--------- -------AAAAA--------- --------AAAA--------- --------AAAA--------- ---------AAAA-------- --------------------- --------------------- --------------------- --------------------- --------------------- --------------------- --------------------- --------------------- --------------------- --------------------- --------------------- --------------------- 
--------------------- --------------------- --------------------- --------------------- --------------------- --------------------- --------------------- ------AA------------- -----AAAA------------ ------AAAA----------- ------AAAA----------- ------AA-AA---------- -------AAAA---------- --------AAA---------- --------------------- --------------------- --------------------- --------------------- --------------------- --------------------- --------------------- --------------------- --------------------- --------------------- --------------------- --------------------- --------------------- --------------------- 
--------------------- --------------------- --------------------- --------------------- --------------------- -----AA-------------- ----AAAA------------- -----AAA------------- -----AAAA------------ -----AA-AA----------- ------AAAA----------- -------AAA----------- --------------------- --------------------- --------------------- --------------------- --------------------- --------------------- --------------------- --------------------- --------------------- --------------------- --------------------- --------------------- --------------------- --------------------- --------------------- --------------------- 
--------------------- --------------------- --------------------- --------------------- --------------------- ----AAA-------------- ----AAAA------------- ----AA-AA------------ -----AAAA------------ ------AAA------------ ------AAA------------ --------------------- --------------------- --------------------- --------------------- --------------------- --------------------- --------------------- --------------------- --------------------- --------------------- --------------------- --------------------- --------------------- --------------------- --------------------- --------------------- --------------------- 
--------------------- --------------------- --------------------- ---AAA--------------- ---AAAA-------------- ---AA-A-------------- ----AAAA------------- ----AAAA------------- -----AAAA------------ --------------------- --------------------- --------------------- --------------------- --------------------- --------------------- --------------------- --------------------- --------------------- --------------------- --------------------- --------------------- --------------------- --------------------- --------------------- --------------------- --------------------- --------------------- --------------------- 
-AAA----------------- AAAA----------------- --AAAA--------------- --AAAA--------------- --AAAAA-------------- --AA-AA-------------- ---AAAA-------------- -----AA-------------- --------------------- --------------------- --------------------- --------------------- --------------------- --------------------- --------------------- --------------------- --------------------- --------------------- --------------------- --------------------- --------------------- --------------------- --------------------- --------------------- --------------------- --------------------- --------------------- --------------------- 
-AAAA---------------- AAAAA---------------- AAAAA---------------- AAA-AA--------------- --AAAA--------------- ---AAA--------------- --------------------- --------------------- --------------------- --------------------- --------------------- --------------------- --------------------- --------------------- --------------------- --------------------- --------------------- --------------------- --------------------- --------------------- --------------------- --------------------- --------------------- --------------------- --------------------- --------------------- --------------------- --------------------- 
--AAA---------------- -AAAA---------------- AAAAA---------------- AAAAA---------------- --AAAA--------------- --------------------- --------------------- --------------------- --------------------- --------------------- --------------------- --------------------- --------------------- --------------------- --------------------- --------------------- --------------------- --------------------- --------------------- --------------------- --------------------- --------------------- --------------------- --------------------- --------------------- --------------------- --------------------- --------------------- 
----A---------------- -AAAA---------------- -AAAA---------------- AAAAA---------------- --------------------- --------------------- --------------------- --------------------- --------------------- --------------------- --------------------- --------------------- --------------------- --------------------- --------------------- --------------------- --------------------- --------------------- --------------------- --------------------- --------------------- --------------------- --------------------- --------------------- --------------------- --------------------- --------------------- --------------------- 
--------------------- --AAA---------------- --AAA---------------- -AAAA---------------- --------------------- --------------------- --------------------- --------------------- --------------------- --------------------- --------------------- --------------------- --------------------- --------------------- --------------------- --------------------- --------------------- --------------------- --------------------- --------------------- --------------------- --------------------- --------------------- --------------------- --------------------- --------------------- --------------------- --------------------- 
