model
size = 26 28 18, scale = 0.05, origin = -y
material 
  colors = A:#555 B:#888 C:#111 D:#777 E:#444
voxels
-------CCCCCCCCCCCC------- -------CDDDDCCDDDDC------- ------ECDDDECCEDDDCE------ -----EECDEECCCCEEDCEE----- ------CCECCBCCBCCECC------ ------CBCBBBCCBBBCBC------ ------CBBBBECCEBBBBC------ ------CBBBBECCEBBBBC------ ------BBBBBECCEBBBBB------ ------BBBBBECCEBBBBB------ ------BBBBEECCEEBBBB------ ------BEEECCCCCCEEEB------ ------ECCCC----CCCCE------ ------C------------C------ ------CCCCCCCCCCCCCC------ ------CAAAAACCAAAAAC------ -----CABBBBACCABBBBAC----- ----CABBBBBACCABBBBBAC---- ---CABBBBBBBCCBBBBBBBAC--- -CCABBBBBBBBCCBBBBBBBBACC- CCABBBBBBBBBCCBBBBBBBBBACC --ABBBBBBBBBCCBBBBBBBBBA-- ---BBBBBBBBBCCBBBBBBBBB--- -----BBBB--------BBBB----- -------------------------- -------------------------- -------------------------- -------------------------- 
-------CBBBBBBBBBBC------- ------DAAAAAAAAAAAAD------ -----DAAAAAAAAAAAAAAD----- ----CAAAAAAAAAAAAAAAAC---- -----CAAAAAAAAAAAAAAC----- -----DAAAAAAAAAAAAAAD----- -----EAAAAAAAAAAAAAAE----- -----CAAAAAAAAAAAAAAC----- -----CAAAAAAAAAAAAAAC----- -----CAAAAAAAAAAAAAAC----- -----CAAAAAAAAAAAAAAC----- -----EAAAAAABBAAAAAAE----- -----CAAAABD--DBAAAAC----- ------CDDD------DDDC------ ------CAAAAACCAAAAAC------ -----AAAAAAACCAAAAAAA----- ----AAAAAAAACCAAAAAAAA---- ---AAAAA----------AAAAA--- --AAABAA----CC----AABAAA-- -BAAABAAAAAACCAAAAAABAAAB- AAABBBAAAAAACCAAAAAABBBAAA CAABBBAAAAAACCAAAAAABBBAAC --ABBBAAAAAACCAAAAAABBBA-- ---BBBAAABBBCCBBBAAABBB--- -----BBBB--------BBBB----- -------------------------- -------------------------- -------------------------- 
------CBBBBBBBBBBBBC------ -----DAAAAAAAAAAAAAAD----- ----DAAAAAAAAAAAAAAAAD---- ---CAAAAAAAAAAAAAAAAAAC--- ----DAAAAAAAAAAAAAAAAD---- ----DAAAAAAAAAAAAAAAAD---- ----DAAAAAAAAAAAAAAAAD---- ----DAAAAAAAAAAAAAAAAD---- ----DAAAAAAAAAAAAAAAAD---- ----DAAAAAAAAAAAAAAAAD---- ----EAAAAAAAAAAAAAAAAE---- ----CAAAAAAAAAAAAAAAAC---- -----BAAAAAAAAAAAAAAB----- ------CAAAAAAAAAAAAC------ -----CAAAAAACCAAAAAAC----- ----AAAAAAAACCAAAAAAAA---- --BAAAAAA--------AAAAAAB-- --AAAAAA----------AAAAAA-- -BAAABA------------ABAAAB- -BAAAB------CC------BAAAB- BAAAABAAAAAACCAAAAAABAAAAB AAAAABAAAAAACCAAAAAABAAAAA CCAAABAAAAAACCAAAAAABAAACC --AAABAAABBBCCBBBAAABAAA-- ---AABBBBBBBCCBBBBBBBAA--- -----BBBB--------BBBB----- -------------------------- -------------------------- 
-----CBB----------BBC----- ----DAAA----------AAAD---- ---CAAAA----------AAAAC--- ---AAAAA----------AAAAA--- ---EAAAA----------AAAAE--- ---CAAAA----------AAAAC--- ---CAAAA----------AAAAC--- ---DAAAA----------AAAAD--- ---EAAAA----------AAAAE--- ---EAAAA----------AAAAE--- ---CAAAA----------AAAAC--- ----BAAA----------AAAB---- -----BAA----------AAB----- ------CA----------AC------ ----CBAA----------AABC---- ---AAAAA----------AAAAA--- --BAAAAA----------AAAAAB-- -BAAAAA------------AAAAAB- -BAAAA--------------AAAAB- -BAAA----------------AAAB- BAAA--------CC--------AAAB BAAAAAAAAAAACCAAAAAAAAAAAB AAAAAAAAAAAACCAAAAAAAAAAAA ACAAAAAAAAAACCAAAAAAAAAACA --CAAABBAAAACCAAAABBAAAC-- ---CAABBABBBCCBBBABBAAC--- -----ABBA--------ABBA----- -------------------------- 
----CBB------------BBC---- ---CAAA------------AAAC--- ---AAAA------------AAAA--- ---BAAA------------AAAB--- --CAAAA------------AAAAC-- --CAAAA------------AAAAC-- --CAAAA------------AAAAC-- --CAAAA------------AAAAC-- --CAAAA------------AAAAC-- --CAAAA------------AAAAC-- --CBAAA------------AAABC-- ----BAA------------AAB---- -----BA------------AB----- ------C------------C------ ---CBBA------------ABBC--- --BAAAA------------AAAAB-- -BAAAAA------------AAAAAB- -BAAAA--------------AAAAB- -BAAA----------------AAAB- -BAA------------------AAB- BAA--------------------AAB BA----------CC----------AB BAAAAAAAAAAACCAAAAAAAAAAAB BAAAAAAAAAAACCAAAAAAAAAAAB --CAAAAAAAAACCAAAAAAAAAC-- ---CCAAAABBBCCBBBAAAACC--- -----CBBA--------ABBC----- -------------------------- 
---CBB--------------BBC--- ---AAA--------------AAA--- ---BAA--------------AAB--- ---BAA--------------AAB--- --BAAA--------------AAAB-- --BAAA--------------AAAB-- --BAAA--------------AAAB-- --BAAA--------------AAAB-- --BAAA--------------AAAB-- --BAAA--------------AAAB-- --BBAA--------------AABB-- ----BA--------------AB---- -----B--------------B----- -------------------------- --CBBB--------------BBBC-- --CAAC--------------CAAC-- -CCCCC--------------CCCCC- -CCCC----------------CCCC- -CCC------------------CCC- -CC--------------------CC- CC----------------------CC C------------------------C C-----------CC-----------C CAAAAAAAAAAACCAAAAAAAAAAAC BBAAAAAAAAAACCAAAAAAAAAABB --AAAAAAAAAACCAAAAAAAAAA-- ---AAAAAAAAACCAAAAAAAAA--- -----CCCA--------ACCC----- 
---BBB--------------BBB--- ---BAA--------------AAB--- ---BAA--------------AAB--- ---BAA--------------AAB--- ---AAA--------------AAA--- --BAAA--------------AAAB-- --BAAA--------------AAAB-- --BAAA--------------AAAB-- --BAAA--------------AAAB-- --BAAA--------------AAAB-- ---AAA--------------AAA--- ----BA--------------AB---- -----B--------------B----- -------------------------- --BBBB--------------BBBB-- --CCCC--------------CCCC-- -------------------------- -------------------------- -------------------------- -------------------------- -------------------------- -------------------------- -------------------------- CAAAAAAAAAAACCAAAAAAAAAAAC CCCCCCAAAAAACCAAAAAACCCCCC --CCCCAAAAAACCAAAAAACCCC-- ---CCCAAACCCCCCCCAAACCC--- -----CCCA--------ACCC----- 
---ABB--------------BBA--- ---AAA--------------AAA--- ---BAA--------------AAB--- ---BAA--------------AAB--- ---AAA--------------AAA--- --BAAA--------------AAAB-- --BAAA--------------AAAB-- --BAAA--------------AAAB-- --BAAA--------------AAAB-- --BAAA--------------AAAB-- ---AAA--------------AAA--- ----BA--------------AB---- -----B--------------B----- -------------------------- --BBBB--------------BBBB-- ---CC----------------CC--- -------------------------- -------------------------- -------------------------- -------------------------- -------------------------- -------------------------- -------------------------- CAAAAAAAAA------AAAAAAAAAC BBAAAAAAAA------AAAAAAAABB --AAAAAAAA------AAAAAAAA-- ---AAAAAAC------CAAAAAA--- -----ACCA--------ACCA----- 
----CB--------------BC---- ---AAA--------------AAA--- ---BAA--------------AAB--- ---BAA--------------AAB--- ---AAA--------------AAA--- ---CAA--------------AAC--- --BAAA--------------AAAB-- --BAAA--------------AAAB-- --BAAA--------------AAAB-- ---CAA--------------AAC--- ---AAA--------------AAA--- ----BA--------------AB---- -----B--------------B----- -------------------------- --BBBB--------------BBBB-- ---CC----------------CC--- -------------------------- -------------------------- -------------------------- -------------------------- -------------------------- -------------------------- -------------------------- CAAAAAAAAA------AAAAAAAAAC BBAAAAAAAA------AAAAAAAABB --AAAAAAAA------AAAAAAAA-- ---AAAAAAC------CAAAAAA--- -----ACCA--------ACCA----- 
----CB--------------BC---- ---AAA--------------AAA--- ---BAA--------------AAB--- ---BAA--------------AAB--- ---AAA--------------AAA--- ---CAA--------------AAC--- --BAAA--------------AAAB-- --BAAA--------------AAAB-- --BAAA--------------AAAB-- ---CAA--------------AAC--- ---AAA--------------AAA--- ----BA--------------AB---- -----B--------------B----- -------------------------- --BBBB--------------BBBB-- ---CC----------------CC--- -------------------------- -------------------------- -------------------------- -------------------------- -------------------------- -------------------------- -------------------------- CAAAAAAAAA------AAAAAAAAAC BBAAAAAAAA------AAAAAAAABB --AAAAAAAA------AAAAAAAA-- ---AAAAAAC------CAAAAAA--- -----ACCA--------ACCA----- 
----CB--------------BC---- ---AAA--------------AAA--- ---BAA--------------AAB--- ---BAA--------------AAB--- ---AAA--------------AAA--- ---CAA--------------AAC--- --BAAA--------------AAAB-- --BAAA--------------AAAB-- --BAAA--------------AAAB-- ---CAA--------------AAC--- ---AAA--------------AAA--- ----BA--------------AB---- -----B--------------B----- -------------------------- --BBBB--------------BBBB-- ---CC----------------CC--- -------------------------- -------------------------- -------------------------- -------------------------- -------------------------- -------------------------- -------------------------- CAAAAAAAAA------AAAAAAAAAC BBAAAAAAAA------AAAAAAAABB --AAAAAAAA------AAAAAAAA-- ---AAAAAAC------CAAAAAA--- -----ACCA--------ACCA----- 
---ABB--------------BBA--- ---AAA--------------AAA--- ---BAA--------------AAB--- ---BAA--------------AAB--- ---AAA--------------AAA--- --BAAA--------------AAAB-- --BAAA--------------AAAB-- --BAAA--------------AAAB-- --BAAA--------------AAAB-- --BAAA--------------AAAB-- ---AAA--------------AAA--- ----BA--------------AB---- -----B--------------B----- -------------------------- --BBBB--------------BBBB-- ---CC----------------CC--- -------------------------- -------------------------- -------------------------- -------------------------- -------------------------- -------------------------- -------------------------- CAAAAAAAAA------AAAAAAAAAC BBAAAAAAAA------AAAAAAAABB --AAAAAAAA------AAAAAAAA-- ---AAAAAAC------CAAAAAA--- -----ACCA--------ACCA----- 
---BBB--------------BBB--- ---BAA--------------AAB--- ---BAA--------------AAB--- ---BAA--------------AAB--- ---AAA--------------AAA--- --BAAA--------------AAAB-- --BAAA--------------AAAB-- --BAAA--------------AAAB-- --BAAA--------------AAAB-- --BAAA--------------AAAB-- ---AAA--------------AAA--- ----BA--------------AB---- -----B--------------B----- -------------------------- --BBBB--------------BBBB-- --CCCC--------------CCCC-- -------------------------- -------------------------- -------------------------- -------------------------- -------------------------- -------------------------- -------------------------- CAAAAAAAAAAACCAAAAAAAAAAAC CCCCCCAAAAAACCAAAAAACCCCCC --CCCCAAAAAACCAAAAAACCCC-- ---CCCAAACCCCCCCCAAACCC--- -----CCCA--------ACCC----- 
---CCB--------------BCC--- ---CAA--------------AAC--- ---AAA--------------AAA--- ---BAA--------------AAB--- --BAAA--------------AAAB-- --BAAA--------------AAAB-- --BAAA--------------AAAB-- --BAAA--------------AAAB-- --BAAA--------------AAAB-- --BAAA--------------AAAB-- --BBAA--------------AABB-- ----BA--------------AB---- -----B--------------B----- -------------------------- --CBBB--------------BBBC-- --CAAC--------------CAAC-- -CCCCC--------------CCCCC- -CCCC----------------CCCC- -CCC------------------CCC- -CC--------------------CC- CC----------------------CC C------------------------C C-----------CC-----------C CAAAAAAAAAAACCAAAAAAAAAAAC BBAAAAAAAAAACCAAAAAAAAAABB --AAAAAAAAAACCAAAAAAAAAA-- ---ACAAAAAAACCAAAAAAACA--- -----CCCA--------ACCC----- 
-----CB------------BC----- ----DDD------------DDD---- ---CAAA------------AAAC--- ---AAAA------------AAAA--- --CAAAA------------AAAAC-- --CAAAA------------AAAAC-- --CAAAA------------AAAAC-- --CAAAA------------AAAAC-- --CAAAA------------AAAAC-- --CAAAA------------AAAAC-- --CBAAA------------AAABC-- ----BAA------------AAB---- -----BA------------AB----- ------A------------A------ --CBBBA------------ABBBC-- --CAAAA------------AAAAC-- -BAAAAA------------AAAAAB- -BAAAAA------------AAAAAB- -BAAAA--------------AAAAB- -BAAA----------------AAAB- BBAA------------------AABB BBA---------CC---------ABB BBAAAAAAAAAACCAAAAAAAAAABB BBAAAAAAAAAACCAAAAAAAAAABB --AAAAAAAAAACCAAAAAAAAAA-- ---CAAAAAAAACCAAAAAAAAC--- -----AAAA--------AAAA----- -------------------------- 
------CB----------BC------ -----DDA----------ADD----- ----DDAA----------AADD---- ---CAAAA----------AAAAC--- ---ADAAA----------AAADA--- ---CDAAA----------AAADC--- ---CDAAA----------AAADC--- ---DDAAA----------AAADD--- ---ADAAA----------AAADA--- ---ADAAA----------AAADA--- ---CAAAA----------AAAAC--- ----CAAA----------AAAC---- -----BAA----------AAB----- ------CA----------AC------ ---CBBAA----------AABBC--- ---DAAAA----------AAAAD--- --CAAAAA----------AAAAAC-- --DAAAAA----------AAAAAD-- -BAAAAAA----------AAAAAAB- -BAAAAA------------AAAAAB- BBAAAA------CC------AAAABB BBAAAAAAAAAACCAAAAAAAAAABB BBAAAAAAAAAACCAAAAAAAAAABB BBAAAAAAAAAACCAAAAAAAAAABB --CAAAAAAAAACCAAAAAAAAAC-- ---ABAAAAAAACCAAAAAAABA--- -----AAAA--------AAAA----- -------------------------- 
-------CBBBBCCBBBBC------- ------DAAAAACCAAAAAD------ -----DAAAAAACCAAAAAAD----- ----CAAAAAAACCAAAAAAAC---- -----CAAAAAACCAAAAAAC----- -----DAAAAAACCAAAAAAD----- -----AAAAAAACCAAAAAAA----- -----CAAAAAACCAAAAAAC----- -----CAAAAAACCAAAAAAC----- -----CAAAAAACCAAAAAAC----- -----CAAAAAACCAAAAAAC----- -----AAAAAAACCAAAAAAA----- -----CAAAAAACCAAAAAAC----- ------CAAAAACCAAAAAC------ ----CCAAAAAACCAAAAAACC---- ----DAAAAAAACCAAAAAAAD---- ---DAAAAAAAACCAAAAAAAAD--- ---DAAAAAAAACCAAAAAAAAD--- --DAAAAAAAABCCBAAAAAAAAD-- -BAAAAAAAAABCCBAAAAAAAAAB- BAAAAAAAAAABCCBAAAAAAAAAAB BAAAAAAAAAABCCBAAAAAAAAAAB BAAAAAAAAAABCCBAAAAAAAAAAB CCAAAAAAAAABCCBAAAAAAAAACC --CABBBBBBBBCCBBBBBBBBAC-- ---ABBBBB--------BBBBBA--- -------------------------- -------------------------- 
--------CCCCCCCCCC-------- -------CBBBBCCBBBBC------- ------ACBBBACCABBBCA------ -----AACBAACCCCAABCAA----- ------CCACCBCCBCCACC------ ------CBCBBBCCBBBCBC------ ------CBBBBACCABBBBC------ ------CBBBBACCABBBBC------ ------BBBBBACCABBBBB------ ------BBBBBACCABBBBB------ ------BBBBAACCAABBBB------ ------BAAACCCCCCAAAB------ ------ACCCC----CCCCA------ ------C------------C------ ------CCCCCCCCCCCCCC------ -----DCAAAAACCAAAAACD----- ----DCABBBBACCABBBBACD---- ----CABBBBBACCABBBBBAC---- ---CABBBBBBBCCBBBBBBBAC--- --CABBBBBBBBCCBBBBBBBBAC-- CCABBBBBBBBBCCBBBBBBBBBACC CABBBBBBBBBBCCBBBBBBBBBBAC CABBBBBBBBBBCCBBBBBBBBBBAC CAABBBBBBBBBCCBBBBBBBBBAAC ---ABBBBBBBBCCBBBBBBBBA--- -------------------------- -------------------------- -------------------------- 
