model
size = 19 25 13, scale = 0.05, origin = -y
material 
  colors = A:#2F2F2F B:#444
voxels
-------AAAAA------- ------------------- ------------------- ------------------- ------------------- ------------------- ------------------- ------------------- ------------------- ------------------- -------AABAA------- -------AABAA------- -------ABBBA------- -------AABAA------- ------------------- ------------------- ------------------- ------------------- ------------------- ------------------- ------------------- ------------------- ------------------- ------------------- ------------------- 
------AAAAAAA------ --------AAA-------- ------------------- ------------------- ------------------- ------------------- ------------------- ------------------- ---------A--------- -------AAAAA------- ------A--A--A------ ------A-----A------ ------A-----A------ ------AAAAAAA------ ------------------- ------------------- ------------------- ------------------- ------------------- ------------------- ------------------- ------------------- ------------------- ------------------- ------------------- 
-----AAAAAAAAA----- ------AAAAAA------- --------AAA-------- ------------------- ------------------- ------------------- ------------------- ---------A--------- --------AAA-------- ------AA---AA------ -----A-------A----- -----A-------A----- -----A-------A----- -----AA-----AA----- -------AAAAA------- ------------------- ------------------- ------------------- ------------------- ------------------- ------------------- ------------------- ------------------- ------------------- -------AAAAA------- 
----AAAAAAAAAAA---- -----AAAA-AAA------ -------AAAAA------- ---------A--------- ------------------- ------------------- ---------A--------- --------AAA-------- -------AAAAA------- -----AA----AAA----- ----A---------A---- ----A---------A---- ----A---------A---- ----AA-------AA---- ------AA---AA------ --------AAA-------- --------AAA-------- --------AAA-------- --------AAA-------- --------AAA-------- --------AAA-------- --------AAA-------- --------AAA-------- --------AAA-------- ------AA---AA------ 
---AAAAAAAAAAAAA--- -----AAAAAAAAA----- ------AAAAAAA------ --------AAA-------- ---------A--------- ---------A--------- --------AAA-------- -------A--AA------- ------A----AA------ ----AA-------AA---- ---A-----------A--- ---A-----------A--- ---A-----------A--- ---AA---------AA--- -----AA-----AA----- -------A---A------- -------A---A------- -------A---A------- -------A---A------- -------A---A------- -------A---A------- -------A---A------- -------A---A------- -------A---A------- -----AA-----AA----- 
---AAAAAAAAAAAAA--- ----AAAAAAAAAAA---- -----AAAAAAAAA----- -------AAAAA------- --------AAA-------- --------AAA-------- -------AAAAA------- ------AA---AA------ -----AA----AAA----- ----A---------A---- ---A-----------A--- ---A-----------A--- ---A-----------A--- ---AA---------AA--- -----A-------A----- ------A-----A------ ------A-----A------ ------A-----A------ ------A-----A------ ------A-----A------ ------A-----A------ ------A-----A------ ------A-----A------ ------A-----A------ -----A-------A----- 
---AAAAAAAAAAAAA--- ----AAAAAA---AA---- -----AAAAAA-AA----- ------AAAAAAA------ -------AAAAA------- -------AAAAA------- ------AAAAAAA------ -----AAA---AAA----- ----AAA----AAAA---- ----A---------A---- ---AA---------AA--- ---A-----------A--- ---A-----------A--- -AAAA---------AAAA- --A--A-------A--A-- --A---A-----A---A-- AA----A-----A----A- A-----A-----A-----A A-----A-----A-----A A-----A-----A-----A AA----A-----A----AA -AA--AA-----AA--AA- --AAA-A-----A-AAA-- ------A-----A------ -----A-------A----- 
---AAAAAAAAAAAAA--- ----AAAAAAAAAAA---- -----AAAAAAAAA----- -------AAAAA------- --------AAA-------- --------AAA-------- -------AAAAA------- ------AA---AA------ -----AA----AAA----- ----A--------AA---- ---A-----------A--- ---A-----------A--- ---A-----------A--- ---AA---------AA--- -----A-------A----- ------A-----A------ ------A-----A------ ------A-----A------ ------A-----A------ ------A-----A------ ------A-----A------ ------A-----A------ ------A-----A------ ------A-----A------ -----A-------A----- 
---AAAAAAAAAAAAA--- -----AAAAA---A----- ------AAAAAAA------ --------AAA-------- ---------A--------- ---------A--------- --------AAA-------- -------AAAAA------- ------A----AA------ ----AA-------AA---- ---A-----------A--- ---A-----------A--- ---A-----------A--- ---AA---------AA--- -----AA-----AA----- -------A---A------- -------A---A------- -------A---A------- -------A---A------- -------A---A------- -------A---A------- -------A---A------- -------A---A------- ------AA---A------- -----AA-----AA----- 
----AAAAAAAAAAA---- ------AAAAAAA------ -------AAAAA------- ---------A--------- ------------------- ------------------- ---------A--------- --------AAA-------- -------AAAAA------- -----AA-----AA----- ----A---------A---- ----A---------A---- ----A---------A---- ----AA-------AA---- ------AA---AA------ --------AAA-------- --------AAA-------- --------AAA-------- --------AAA-------- --------AAA-------- --------AAA-------- --------AAA-------- --------AAA-------- --------AAA-------- ------AA---AA------ 
-----AAAAAAAAA----- -------AAAAA------- --------AAA-------- ------------------- ------------------- ------------------- ------------------- ---------A--------- --------AAA-------- ------AA---AA------ -----A-------A----- -----A-------A----- -----A-------A----- -----AA-----AA----- -------AAAAA------- ------------------- ------------------- ------------------- ------------------- ------------------- ------------------- ------------------- ------------------- ------------------- -------AAAAA------- 
------AAAAAAA------ --------AAA-------- ------------------- ------------------- ------------------- ------------------- ------------------- ------------------- ---------A--------- -------AAAAA------- ------A--A--A------ ------A-----A------ ------A-----A------ ------AAAAAAA------ ------------------- ------------------- ------------------- ------------------- ------------------- ------------------- ------------------- ------------------- ------------------- ------------------- ------------------- 
-------AAAAA------- ------------------- ------------------- ------------------- ------------------- ------------------- ------------------- ------------------- ------------------- ------------------- -------AABAA------- -------AABAA------- -------ABBBA------- -------AABAA------- ------------------- ------------------- ------------------- ------------------- ------------------- ------------------- ------------------- ------------------- ------------------- ------------------- ------------------- 
