model
size = 32 22 24, scale = 0.05, origin = -y
material 
  colors = A:#001 B:#C00
voxels
109-4A26-BAB2A2(BA)22-B2(3A2B)A19-2(2B3A)2B2A19-2(AB)2ABAB2AB22-B4AB2A24-AB2A2(BA)2(24-2A2B3AB)25-B2ABAB343-B3A2B3A22-2(2ABAB)2A19-2(4AB)4A18-B2ABAB2-BAB2ABAB15-2A2BA-A2B2A-2B4A14-2A2(2B3A)2B4A16-2(2ABAB)2ABA18-3A2(B4A)B18-2(2ABAB)2ABA2(18-2(2B3A)2B2A)19-2(AB)2ABAB2AB20-2A2(B4A)22-AB2A2(BA)27-BA215-A2(2B3A)2B18-2A2(2B3A)2B2A16-3(AB2AB)2A14-A3(B4A)3B13-3(BAB2A)BA3B11-2B2A2(2B3A)2BA-4A10-4A2B3A3-2A2B6A12-AB2ABA6-2AB3A14-B4A8-2A3B14-AB2AB8-ABA2B14-2A2BA8-B4A14-2A2B2A6-2B4A15-B2ABAB4-2(B2A)16-2(4AB)4A2B17-2(2ABAB)2ABA19-B2(3A2B)23-2A2B3AB178-3A2BA5-2A2B2AB14-2(2BA)5-2A2B4A12-3AB2AB6-B2ABA3B11-3B3A8-3AB4A9-4AB2A9-AB5A9-5AB11-2A5B8-4BAB11-7A9-3ABA12-A4B10-3BA14-4A10-3AB14-4A10-4AB12-A4B11-2BAB12-4A12-2AB2A10-BA3B13-B4A8-2AB2A15-B2ABAB4-2(B2A)17-2(2B3A)2B2A19-B2(3A2B)A22-AB2A2(BA)145-4A12-AB2A11-5A12-BA3B10-4BA12-B5A8-6A13-B5A7-5A15-5A7-2A-2A15-6A6-5A16-5B7-4B3(16-4A8-4A)16-4A9-3A15-4B10-3BA14-4A11-3AB12-B3A13-AB2A10-4A15-AB2AB6-B2ABA17-A2(2B3A)2BA19-2(2B3A)2B22-BAB2ABAB27-2A83-3A16-4B8-4B16-5A7-4A16-5B7-4B2(17-5A5-2A-2A)18-5B4-5B18-5A5-3A19-4B6-3B20-3A6-3A20-3A6-4A18-4B7-3B18-3A8-4A16-4B9-3BA14-4A11-2ABA12-4A13-2ABA10-A3B15-2A2B8-2B2A17-A2B3A2-3A2BA20-2(AB)2A2(BA)23-AB4ABA79-3B19-3A7-3A2(19-4A5-4A)19-5B4-4B20-4B3-2B-2B20-5A2-5A20-5A4-2A21-3A6-2A22-2B6-2B21-3B6-3B20-3A6-3A20-3A6-4A18-4A7-4A16-4B9-4B14-4B11-2BAB12-B3A13-3AB10-B3A15-2A2BA6-A2B2A18-2ABAB2-BAB2A22-AB4ABA25-AB2ABA48-2B21-3A5-2(3A21-4A4-)A-A21-4B3-4B22-4B2-4B22-4A2-4A22-4A3-3A22-3A4-3A2(22-3B4-3B)22-3A4-3A22-3A5-3A20-3A6-4A18-4B7-4B16-4B9-3BA14-4A11-4AB10-B4A13-3A2B8-2B3A16-B2ABA4-AB2AB20-2AB4AB2A24-AB2ABA48-2A22-3B4-3B22-3A4-3A22-4B2-4B22-4A2-4A22-4A2-A-A24-2(B-)4B24-4A2-2A24-2B4-2B2(24-2A4-2A)24-2B4-3B22-3A4-3A22-3B5-3B20-3A6-4A18-4A7-4A16-4B9-3B2A12-5A11-4AB10-5B14-AB2AB6-B4A19-2ABA2-AB2A24-AB2ABA28-2B18-A24-2A4-2A24-3B2-3B24-3A2-3A24-A-A2-A-A24-A-4A-A24-8A24-4B-3B3(24-3A2-3A)24-2A4-2A24-2B4-3B22-3A4-3A22-3A5-3A20-3A7-3A18-3A8-4A16-4B9-3B2A12-5A12-2(2AB)6-B5A15-B4ABA2-AB5A21-AB2ABA27-3A43-2B4-2B24-3A2-3A24-3B2-B-B24-6A-A24-8A24-2B-5B25-3A-2A26-2B2-2B26-2A2-2A26-2A2-3A24-3B3-2B24-2A4-2A24-2B4-3B22-3A5-3A20-3A6-3A20-3B7-3B18-3A9-4A14-4B11-2BABA10-5A13-AB4ABA2-AB6A16-2(B2ABA)B2AB23-4A43-2A3-2A24-3A2-3A24-3A2-A-A25-7B25-B2(-2B)25-A-4A26-3A-2A26-2A2-2A2(26-2B2-2B)26-2A2-3A24-2A4-2A24-2A4-3A22-3B5-2B22-2B6-3B20-3A7-3A18-3A9-3A16-3A11-3A14-3B13-2B3A8-2A3B16-2(B2ABA)B3A22-6A42-2A3-2A24-3A2-3A24-3A2-A-A24-6B-B25-7B25-A-4A26-3A-2A26-2A2-2A2(26-2B2-2B)25-3A3-2(2A24-2A4-)3A22-3B5-2B22-2B6-3B20-3A7-3A18-3A9-3A16-3A11-3AB12-4B13-2B4AB4-B3A3B16-2(B2ABA)B3A22-6A16-A24-2B4-2B24-3A2-3A24-B-B2-B-B24-3A2-A-A24-8A24-8B24-4A-2A26-2B2-2B26-2A2-3A24-3A2-3A24-3B3-2B24-2A4-2A24-2B4-3B22-3A5-3A20-3A6-4A18-4B7-4B16-4A9-4A14-4B11-2BAB2A8-6A14-B4ABA2-AB5A19-2(AB)2A2(BA)25-3A18-A23-3A4-3A22-4B2-4B22-4A2-3A24-3A2-A-A24-2(A-)2A-A24-A-6A24-4B-3B2(24-3A2-3A)2(24-2A4-2A)24-2B4-3B22-3A5-3A20-3A6-3A20-3A7-3A17-4A9-4A14-4B11-3BAB10-B4A13-2(2AB)6-B5A17-3ABA2-AB3A23-AB2ABA27-3A18-2A21-3B5-3B21-4A4-3A21-4B3-4B22-4A2-4A22-4A2-A-2A22-2B-B2-3B23-4A3-2A24-2B4-2B24-2A4-2A24-2A4-3A22-3B4-3B22-3A5-3A20-3B6-3B20-3A7-3A18-3A8-5A14-5B9-4BA12-5A12-3A2B8-5B16-B2AB6-B3A20-2ABA2-AB2A24-AB2ABA28-2B18-3B19-4A6-3A19-4A5-4A19-5A4-4A20-4B3-2B-B21-5B2-4B21-2A-2A2-4A22-4A3-3A22-3A4-3A2(22-3B4-3B)22-3A5-3A20-3A6-3A20-3A7-3A18-3B8-4B16-4B9-5B12-5A11-4AB10-B4A14-2A2B8-2B2A18-2ABA4-AB2A22-AB4ABA25-AB2ABA49-2B18-3A8-4A17-4A7-4A17-5A5-5A18-4B5-4B19-5B4-4B19-5A4-4A20-4A5-3A20-3A6-3A2(20-3B6-3B)20-3A6-4A18-4A7-3A18-3A8-4A16-4B9-4B14-4B11-4BA10-5A13-3A2B8-2B3A16-A2BA6-A2BA19-2(2ABAB)2A22-AB4ABA26-B2AB50-4A14-4B10-4B14-5A8-5A14-6B7-5B15-5A7-5A15-6A5-5A17-5B5-5B17-6A6-3A18-3B8-3B2(18-3A8-3A)18-3B8-4B16-4A9-4A14-4B10-4B14-4A11-4A12-4A13-2AB2A8-2A3B15-BA2BA6-A2B2A18-2(2B3A)2B21-2(AB)2A2(BA)24-B4AB83-3AB9-B5A12-5A9-A6B10-5BA10-B6A9-5AB11-6A9-5A12-7A7-6A13-3A-3A6-6A14-6B8-4B14-4A2(10-3A16-3A)10-4A14-4A10-4A14-4B11-3BA12-4A12-3ABA10-5A13-5A8-5A15-AB2ABA4-AB4A17-A2(2B3A)3B20-B3A2B3AB24-AB2ABA116-2(2AB)AB2A2(BA)B16-3BA2(2B3A)B3A14-4A2(2B3A)5B12-5B2(2ABAB)6A11-8A4-AB8A9-3A-AB2A7-BA6B9-5BAB9-B7A10-4AB10-5B12-4B11-5A2(12-4A)12-3ABA10-5B12-3BAB10-5A13-3A2B8-5B15-2B2ABA4-AB4A16-5A2(B4A)19-2(2ABAB)AB21-B3A2B3AB24-2A2B2A151-2ABAB2ABA21-2A2(2B3A)B19-2A2(2B3A)B2A16-2(2AB)AB2A2(BA)3B14-3B2(4AB)2A4B13-4B2(2ABAB)6A12-4A2(2B3A)B5A14-2A2(2B3A)B3A15-2(2AB)AB2-2(BA)3B15-2B4AB4-B2A3B16-2B2ABA4-AB4A2(16-2A2(2B3A)B3A)17-2(B2ABA)BA2B19-3AB4AB2AB22-BAB2ABAB279-B3A2B2A23-2(2ABAB)A20-2(4AB)2AB18-2B2(2ABAB)3A17-2A2B2A4-2AB3A17-A2(2B3A)B2A19-2(2ABAB)AB20-3AB4AB2AB20-2(2ABAB)2A20-2(2B3A)BA21-B3A2B3AB23-BAB2ABAB440-BAB2ABA24-B3A2B3AB22-B3A2B3AB459-
