model
size = 32 15 21, scale = 0.05, origin = -y
material 
  colors = A:#306 B:#609 C:#C30 D:#0E0 E:#CF0 F:#E00 G:#009
voxels
50-8B24-8A24-7A26-6A27-4A301-5B26-B5A10B3-5B14-7AB10A19-12A2(21-11A)22-9A24-8A26-4A235-12B11-3B6-14A8-4A14-7A7-4A16-6A5-5A17-7A-6A18-14A19-12A21-11A23-7A195-2B4-6B19-B2A4-12A13-3A7-10A12-3A13-4A11-3A15-5A8-4A16-5A6-5A16-15A18-14A19-12A22-9A26-3A133-2B30-2A3-B8A18-2A3-B11A15-2A10-6A2(13-3A)12-4A14-3A11-4A14-5A7-5A16-7A2-7A17-14A19-12A21-10A131-2B30-2A2-B2A25-2A2-B9A17-3A5-8A16-3A10-4A14-3(3A13-)4A11-4A14-5A8-4A16-6A4-6A17-14A19-12A22-8A101-B2(30-2A)-B7A21-2A3-9A18-2A9-4A16-3A11-3A14-4A12-2(3A13-)4A11-4A14-5A8-4A16-6A4-5A18-13A20-11A25-3A72-B2(31-A)-B4A24-2A2-9A19-2A7-5A17-3A10-3A16-3A11-3A14-4A12-2(3A13-)5A10-4A14-5A7-5A16-7A2-6A19-12A22-7A70-B2(31-A)-B2A27-BEB8A20-ABE5-6A18-ABE9-2A17-3A11-2A16-3A12-2A14-3A13-4A11-4A14-4A9-4A16-5A6-4A18-13A21-9A69-B31-A31-BCBA28-A-B7A22-A6-6A18-2A10-2A18-ABD10-2A16-3A11-3A14-4A12-3A13-3A14-4A10-3A16-4A7-5A17-13A20-10A29-2A38-B31-BF30-BC30-A-B7A22-A6-5A19-2A10-2A18-ABD10-2A16-2ABG10-3A15-3A12-3A13-3A14-3A11-4A14-5A8-4A17-5A2-6A20-10A29-2A38-B31-A31-BCBA28-A-B7A22-A6-6A18-2A10-2A18-ABD10-2A16-3A11-3A14-4A12-3A13-3A14-4A10-3A16-4A7-5A17-13A20-10A29-2A38-B2(31-A)-B2A27-BCB8A20-2A7-5A18-ABD9-3A16-3A11-2A16-3A12-2A14-3A13-4A11-4A14-4A9-4A16-5A5-5A18-13A21-9A69-B2(31-A)-B5A23-2A2-9A19-2A8-4A17-3A11-2A16-3A11-3A14-4A12-3A12-4A14-4A10-4A14-6A6-5A16-7A-7A19-12A22-7A70-B2(30-2A)-B7A21-2A3-9A17-3A9-4A16-3A11-3A14-4A12-2(3A13-)4A11-4A14-5A8-4A16-6A4-5A18-13A21-10A25-3A71-2B30-2A2-B3A24-2A2-B9A17-3A6-7A16-3A11-3A14-3(3A13-)4A11-4A14-5A8-4A16-7A2-7A17-14A19-12A22-8A99-2B30-2A3-B8A18-2A4-11A14-3A10-6A2(13-3A)12-4A14-4A9-4A15-5A7-5A16-16A17-14A19-12A21-10A130-B5-7B18-BAB4-12A13-3A7-10A11-4A13-5A10-3A15-5A8-4A16-6A5-5A17-14A18-14A19-12A22-9A139-3B27-2B3A8B10-3B7-14A7-4A14-7A7-4A17-5A5-4A18-14A19-13A19-12A21-10A24-7A172-5B26-B5A11B2-4B16-4AB11A20-12A21-11A22-10A22-9A24-7A28-2A252-6B2(26-6A)27-4A29-2A297-
