model
size = 24 27 32, scale = 0.05, origin = -y
material 
  colors = A:#EEE B:#D00 C:#000 D:#B00 E:#444 F:#001 G:#500 H:#700
voxels
343-7BDBD612-2(D4B)2D3B9-2B10HD2B607-2B4D3BD2BD5B7-D2HBD3BD2BDB3H606-7B2D4BDB2DBHB6-H2BD4B2(DB)D3B582-2(D2B)3D2(4BD)B4-BH16ABH6-3D3BDBD6BD581-BD5BD3BDBD2B2DBD2B2-BHD16ABHB5-2(DB)2DB2D7B581-DBD3BD6B6D3B2-BHD16ADBH5-2BD13B581-2BDBD5BDB2D3BDB2DB2-DHB16ABDH5-3(2BD)5BDB580-3BD5B2D7BD5BDBHB16A2BHD4-B3D2B4A2BD3B14-4A562-10BD3BD4BD5BH2B16A2DHB4-2B12ABD10-12A12-12A13-10A15-8A17-6A19-4A442-2(BD)4BD5B3D4B2(DB)HDB16ADBHB4-16A8-3A10-3A8-4A8-3A10-4A6-4A11-4A4-4A12-5A2-4A14-9A17-6A417-2B2D4BD7BD4B2DBDB20AHB2-20A5-2A13-3A6-3A12-3A7-3A10-3A8-3A9-4A9-3A7-4A11-4A4-4A13-10A17-4A394-2(5BD)BD3B2DB2D2BDB20ABD2-20A4-2A16-2A4-3A14-3A5-2A14-2A6-3A12-3A7-3A10-3A9-3A8-3A11-5A2-5A14-8A392-2BDBD7BD2B2D8B22AB-2A18-2A2-2A18-2A3-2A16-2A4-2A16-2A5-2A14-2A6-3A12-3A7-3A10-3A9-4A6-4A12-10A17-4A370-5BD2B3D5BD3BD2BD23AB2A20-A2(2-2A18-2A)2-3A16-2A4-2A16-2A5-2A14-2A7-2A12-2A9-3A8-3A11-12A15-6A369-6BD4B2D6BD4B26A20-4A20-A2-A19-2A2-2A18-2A3-2A16-2A4-3A14-3A5-3A12-3A7-2(3A10-)4A4-4A14-8A153-AE2C14-2C4(EA2-AE3C12-3C)EA2-AE2C14-2CEA73-D22-BA22-2A21-4A20-2A-A20-A2-2A18-2A2-2A18-A4-2A16-2A5-2A14-2A7-3A10-3A9-4A6-4A12-10A128-AE3C12-3CEA2-AE3C12-3CEA-GAE3C12-3C2(EA2GAEC-C12-C-C)EAG-2(AE3C12-3CEA2-)AE3C12-3CEA49-B22-BA22-2A22-3A20-2A-A20-A2-A19-2A2-2A18-2A3-2A16-2A5-2A14-2A7-2A11-3A9-3A8-3A12-10A104-AE3C12-3CEA2-AE3C12-3CEA-G4(AEC-C12-C-CEA2G)AEC-C12-C-CEAG-AEC-C12-C-C2(EA2-AE3C12-3C)EA25-D22-BA22-2A22-3A20-2A-2(A20-A2-)2A18-2A3-2A16-2A5-2A14-2A7-2A12-2A9-3A8-3A12-10A17-3A62-2C14-2C4-AE3C12-3CEA-G6(AEC-C12-C-CEA2G)AEC-C12-C-CEAG-AEC-C12-C-CEA-2AE3C12-3CE4AE2C14-2CE4(4A20-)5A2(18-6A)18-3A-3A16-3A2-4A14-4A3-4A12-4A4-6A8-6A5-18A7-16A10-12A14-8A9-AE3C12-3CEA2-AE3C12-3CEA-G2(AEC-C12-C-CEA2G)4(AE3C12-3CEA2G)AEC-C12-C-CEAG-AEC-C12-C-CEA-2AE3C12-3CEA3FE2C14-2CE4(A3F20-)A3(3FA18-2A)F-F2A16-A2F2-F2AD14-BA2F3-F2AD12-BA2F4-3FA2B8-DBA3F5-3F2A4B2D2B2A3F7-2F10A4F10-2FA-4A-3F14-8F9-2A3C12-3C2A2-AE3C12-3CEA-G2(AEC-C12-C-CEA2G)4(AE3C12-3CEA2G)AEC-C12-C-CEAG-AEC-C12-C-CEA-2AE3C12-3CEA3FE2C14-2CE4(A3F20-)A3(3FA18-2A)F-F2A16-A2F2-F2AB14-BA2F3-F2AD12-BA2F4-3FA2D8-DBA3F5-3F2A8B2A3F7-2F5A2B3A4F10-2F7A3F14-8F11-2C14-2C4-AE3C12-3CEA-G3(AEC-C12-C-CEA2G)2(AE3C12-3CEA2G)AEC-C12-C-CEA2GAEC-C12-C-CEAG-AEC-C12-C-CEA2-AE3C13-2CEA2-A-2C14-C2(2-A)4(20-A2-A)B18-BA2-2A18-2A2-2AD16-B2A2-2AD15-BD2A2-3AB14-B3A3-3ABD10-2B3A5-3ABDB6-3B3A6-4ABD3BDBD2B4A8-5A4-5A11-12A15-6A34-AE3C12-3CEA2-AE3C12-3CEA-G4(AEC-C12-C-CEA2G)AEC-C12-C-CEAG-AEC-C12-C-C2(EA2-AE3C12-3C)EA26-D19-2B2-B19-2B2-2B18-DB2-BD18-BD2-2D18-DB3-BD16-BD4-2B16-2D5-2B14-2B6-3B12-2B8-2DB10-3B10-BDB6-3B14-2BD5B107-2C14-2C4-AE3C12-3CEA2-AE3C12-3CEA-G2(AEC-C12-C-CEA2G)AEC-C12-C-CEAG-AEC-C12-C-C2(EA2-AE3C12-3C)EA4-2C14-2C28-2B18-2B2-2D18-2B2-2B18-D4-B18-B4-2B16-BD4-2B16-DB5-2B14-2B6-DB14-DB7-2B12-BD9-3B8-3B11-D3B4-BD2B14-3BD2B2D155-3C12-3C4-3(AE3C12-3CEA2-)AE3C12-3CEA4-3C12-3C77-2B16-2B4-BD16-2B4-2B16-2D4-2B16-2B4-BD16-2B5-2B14-BD6-2B14-DB7-BD12-BD8-2BD10-2BD9-3B8-DBD12-2DB2D5B16-4B2D371-2B16-B5-BD16-B6-B16-D6-B15-DB6-2B14-2D6-2B14-2B7-2B12-2B8-D2B10-B2D9-BDB8-3B11-3B5-2D2B13-BD5BD2B18-BD374-2B14-BD6-BD14-2B6-DB14-DB6-2B14-BD6-3B12-BD8-2B12-2B8-BDB10-3D9-2B10-2B11-3B6-DBD13-B3D2-D2BD15-7BD396-2B11-2BD8-2B12-BD8-BD12-DB8-2B12-2B8-3B10-BDB9-2B10-DB10-3B8-BDB11-BDB6-2BD12-BD2B4-4B14-3(BD)2B18-2B2D399-3B8-BDB10-2BD8-3B10-D2B8-DBD10-D2B8-BDB10-3B8-3B11-2B8-BD12-BDB6-3B13-3B3-4B15-6BDB17-4B2D424-3BD2-4B13-2BDB4-BDB13-BD2B4-2BD14-3B4-2BD14-2BD4-3B14-2(DB)2-4B14-B2(D3B)D15-2BD5B17-5B451-BD3BD18-2(B2D)18-2D2B2D18-6B18-4BDB18-6B19-D3B202-
