model
size = 32 15 21, scale = 0.05, origin = -y
material 
  colors = A:#60F B:#F90 C:#C30
voxels
50-2(8A24-)7A26-6A27-4A301-5A26-16A3-5A14-18A19-12A2(21-11A)22-9A24-8A26-4A235-12A11-3A6-14A8-4A14-7A7-4A16-6A5-5A17-7A-6A18-14A19-12A21-11A23-7A195-2A4-6A19-3A4-12A13-3A7-10A12-3A13-4A11-3A15-5A8-4A16-5A6-5A16-15A18-14A19-12A22-9A26-3A133-2A30-2A3-9A18-2A3-12A15-2A10-6A2(13-3A)12-4A14-3A11-4A14-5A7-5A16-7A2-7A17-14A19-12A21-10A131-2A30-2A2-3A25-2A2-10A17-3A5-8A16-3A10-4A14-3(3A13-)4A11-4A14-5A8-4A16-6A4-6A17-14A19-12A22-8A101-A2(30-2A)-8A21-2A3-9A18-2A9-4A16-3A11-3A14-4A12-2(3A13-)4A11-4A14-5A8-4A16-6A4-5A18-13A20-11A25-3A72-2(A31-)A-5A24-2A2-9A19-2A7-5A17-3A10-3A16-3A11-3A14-4A12-2(3A13-)5A10-4A14-5A7-5A16-7A2-6A19-12A22-7A70-2(A31-)A-3A27-A-9A20-2A6-6A18-2A10-2A17-3A11-2A16-3A12-2A14-3A13-4A11-4A14-4A9-4A16-5A6-4A18-13A21-9A69-2(A31-)AB2A28-AB8A22-AB5-6A18-2AB9-2A18-2AB10-2A16-3A11-3A14-4A12-3A13-3A14-4A10-3A16-4A7-5A17-13A20-10A29-2A38-A31-AC30-AB30-A-8A22-AB5-5A19-2A10-2A18-2AB10-2A16-3AC10-3A15-3A12-3A13-3A14-3A11-4A14-5A8-4A17-5A2-6A20-10A29-2A38-2(A31-)A-2A28-AB8A22-A6-6A18-2AB9-2A18-2A11-2A16-3A11-3A14-4A12-3A13-3A14-4A10-3A16-4A7-5A17-13A20-10A29-2A38-2(A31-)A-3A27-A-9A20-2A7-5A18-2A10-3A16-3A11-2A16-3A12-2A14-3A13-4A11-4A14-4A9-4A16-5A5-5A18-13A21-9A69-2(A31-)A-6A23-2A2-9A19-2A8-4A17-3A11-2A16-3A11-3A14-4A12-3A12-4A14-4A10-4A14-6A6-5A16-7A-7A19-12A22-7A70-A2(30-2A)-8A21-2A3-9A17-3A9-4A16-3A11-3A14-4A12-2(3A13-)4A11-4A14-5A8-4A16-6A4-5A18-13A21-10A25-3A71-2A30-2A2-4A24-2A2-10A17-3A6-7A16-3A11-3A14-3(3A13-)4A11-4A14-5A8-4A16-7A2-7A17-14A19-12A22-8A99-2A30-2A3-9A18-2A4-11A14-3A10-6A2(13-3A)12-4A14-4A9-4A15-5A7-5A16-16A17-14A19-12A21-10A130-A5-7A18-3A4-12A13-3A7-10A11-4A13-5A10-3A15-5A8-4A16-6A5-5A17-14A18-14A19-12A22-9A139-3A27-13A10-3A7-14A7-4A14-7A7-4A17-5A5-4A18-14A19-13A19-12A21-10A24-7A172-5A26-17A2-4A16-16A20-12A21-11A22-10A22-9A24-7A28-2A252-2(6A26-)6A27-4A29-2A297-
