model
size = 32 15 21, scale = 0.05, origin = -y
material 
  colors = A:#E00 B:#D00 C:#B00 D:#111 E:#EEE F:#9FC G:#9F6 H:#555 I:#200 J:#9F9 K:#888 L:#444 M:#777
voxels
50-2(8C24-)7B26-6B27-4B301-5C26-16C3-5C14-18C19-12B2(21-11B)22-9B24-8A26-4A235-12C11-3C6-14C8-4C14-7B7-4B16-6B5-5B17-7B-6B18-14B19-12A21-11A23-7A195-2C4-6C19-3C4-12C13-3C7-10B12-3B13-4B11-3B15-5B8-4B16-5B6-5B16-15A18-14A19-12A22-9A26-3A133-AC30-AC3-9C18-AC3-12B15-2A10-6B13-3A13-3B12-4A14-3B11-4A14-5A7-5A16-7A2-7A17-14A19-12A21-10A131-AC30-AC2-3C25-AC2-10B17-3A5-8B16-3A10-4B14-3A13-3B13-3A13-4A11-4A14-5A8-4A16-6A4-6A17-14A19-12A22-8A101-2(C30-A)C-8B21-2A3-9B18-2A9-4B16-3D11-3B14-4A12-E2A13-3A13-E3A11-4A13-E5A8-4A16-6A4-5A18-13A20-11A25-3A72-2(AC30-)AC5B24-3A-9B19-HI7-5B17-3D11-2B16-3D12-2A14-4A12-E2A13-3A13-5A10-4A14-5A7-5A16-7A2-6A19-12A22-7A70-2(AC30-)AC3B27-HI9B20-3J5-6B18-3D10-B17-3D12-E16-3D12-EA14-3A13-E3A11-4A14-4A9-4A16-5A6-4A18-13A21-9A69-2(AC30-)HI2B28-2K8B22-2G5-6B18-3D10-B18-2D12-A16-3F12-2A14-4D12-E2A13-3A14-4A10-3A16-4A7-5A17-13A20-10A29-2A39-C30-HI30-2M30-2G8B22-2G5-5B19-3D10-B18-2D12-E16-3F12-EA15-3D12-E2A13-3D14-3A11-4A14-5A8-4A17-5A2-6A20-10A29-2A38-2(AC30-)HI2B28-2K8B22-2G5-6B18-3D10-B18-2D12-A16-3F12-2A14-4D12-E2A13-3A14-4A10-3A16-4A7-5A17-13A20-10A29-2A38-2(AC30-)AC3B27-HI9B20-3J6-5B18-2D11-2B16-3D12-E16-3D12-LA14-3A13-E3A11-4A14-4A9-4A16-5A5-5A18-13A21-9A69-2(AC30-)AC6B23-3A-9B19-HI8-4B17-3D11-2B16-3D12-EA14-4A12-L2A12-4A13-E4A10-4A14-6A6-5A16-7A-7A19-12A22-7A70-2(C30-A)C-8B21-2A3-9B17-3A9-4B16-3D11-3B14-4A12-2(3A13-)4A11-4A13-6A8-4A16-6A4-5A18-13A21-10A25-3A71-2C30-2C2-4C24-2C2-10B17-3B6-7B16-3B11-3B14-3(3B13-)4A11-4A14-5A8-4A16-7A2-7A17-14A19-12A22-8A99-2C30-2C3-9C18-2C4-11B14-3B10-6B2(13-3B)12-4B14-4B9-4B15-5A7-5A16-16A17-14A19-12A21-10A130-C5-7C18-3C4-12C13-3C7-10B11-4B13-5B10-3B15-5B8-4B16-6B5-5B17-14A18-14A19-12A22-9A139-3C27-13C10-3C7-14C7-4C14-7B7-4B17-5B5-4B18-14B19-13B19-12A21-10A24-7A172-5C26-17C2-4C16-16C20-12B21-11B22-10B22-9B24-7A28-2A252-2(6C26-)6B27-4B29-2B297-
