model
size = 17 32 32, scale = 0.05, origin = -y
material 
  colors = A:#EEE B:#111 C:#222 D:#555 E:#00F F:#002 G:#E00
voxels
229-2B15-2G14-5B11-6F11-BA-B-A12-2(BA)B12-4B422-2(2B15-)2B14-B2-AB11-F4-F11-B4-B12-A3-B12-B-2B14-B407-2B14-B2-B13-B2-B12-B4-B11-F5-F10-A5-B10-B4-B12-B2-2B13-2B406-2B14-B2-B13-B2-B12-B4-B11-F5-F10-A5-A10-A4-B12-B2-BA13-2B389-BA15-B-BA2(12-B3-B)11-B5-B2(9-A6-A)10-A5-A10-A4-A12-2B2A388-2A15-B-2A2(12-B3-A)11-B5-2(A9-A6-)A10-A5-A10-A4-A12-2B-A15-A371-3B2A2(12-A3-A)11-B5-A9-A6-A9-A7-A8-A7-B8-A6-A9-B6-A10-BA2-2B13-BA371-B4A2(12-A3-A)11-A5-A9-A6-A9-2(A7-B8-)2(B6-A9-)3A2-BA13-BA338-AB15-BA13-2A2-2A2(11-A4-A)10-A6-A9-A2(7-B)8-A7-B2(8-A)7-A8-A7-A9-A5-B11-2(AB)A319-2B2(15-AB)13-2A2-2A2(11-A4-A)10-B6-B9-2(B7-)A8-A7-2(A8-)A7-A8-B7-B9-A5-B11-2(A-)A13-B-B302-B3A13-A2-AB12-B2-2B10-2B4-B10-A5-A10-B6-B9-2(B7-)A8-B7-2(A9-B6-)A8-B7-2(B8-)B7-A9-2A3-BA12-BAB302-B4A2(12-A3-A)10-BA4-B10-A5-B10-B6-B9-2(A7-)A8-A7-2(A9-A6-)A8-A7-B2(8-A)7-B9-AB3-BA12-3A269-AB15-2B13-BA2-3B2(10-A5-A)2(9-B6-A)9-2(A7-)A8-A7-A9-2(A5-A10-)2(A6-B9-)B7-A7-B9-A5-2A10-B4A250-3A2(14-A-A)13-A3-BA2(B10-B5-)B9-A6-B9-B6-A9-B7-A7-B8-A7-A9-A5-A10-A5-B10-A6-B9-B6-A9-B2(7-A)9-A5-A11-2A-2A14-A168-B31-B16-A33-6A11-B3-2A11-A5-2A9-A6-A9-B6-A9-A6-B8-A2(7-B)8-B6-B2(10-B5-A)11-A2(4-A11-B)4-2B9-A2(7-E)8-E7-E8-3A3-3A11-3B150-2B13-2AB31-4B12-5A14-3A13-A3-2A11-B4-A11-A5-2A9-A6-A9-B6-B9-A6-A8-2(A7-)A8-A6-2(B10-A5-)2(B11-B4-)B11-A4-BA9-B2(7-E)8-E7-E8-EAB3-2BE11-2BA147-B2-3B11-A3-2B12-B2A13-A3-AB11-A4-A11-2A3-A11-A5-2A9-B6-A9-2(A7-A8-)B7-B8-B7-A7-B8-A6-B10-A5-A11-A4-A11-2(B3-B12-)A3-A12-B4-A11-B4-AE9-E6-E9-E7-A6-BA9-6A146-2B5-B9-A4-A12-B2-2A10-2A4-B11-A4-B12-A3-A11-A5-2A9-B6-A9-B7-A8-A7-A8-B7-B8-2(A7-)B8-A6-B10-A5-A11-B4-A11-2(B3-A12-)B3-B12-B4-B11-A4-B10-A6-A9-A7-A6-2A9-2A2B2A145-B-B5-B8-B6-2A8-2A5-AB8-A6-2B8-B6-BA8-2A5-AB8-B7-A2(8-A7-A8-B)7-A8-B7-B8-A7-A9-B5-A11-2(B3-A12-)A3-B13-A2-A13-B2-A13-A2-A12-A4-A11-A4-B10-A6-B8-A8-3B3-AB12-3A138-2B5-B2(9-A6-A)9-B6-A9-A6-B9-B2(6-B9-A)6-A9-A6-A9-B2(6-B9-A)7-A9-B5-A11-A3-A12-A3-B12-A3-A13-A2-A13-B2-A13-A2-A12-A4-A11-A4-A10-A5-D2(A8-)B2A3-AB12-3A144-3(A11-B4-A11-A4-)B2(11-A4-A)11-B4-B11-A4-A11-B4-2A11-B3-A12-A3-2(A13-A2-)A13-B-B14-B2(2-A13-A)2-A12-A4-A11-B4-A10-B5-DA8-BD5-3D6A3(3D5-3D6-)3D4-2(C2-D6-D2-C3-)C2-D6-D2-C4-2D8-2D21-A11-B4-A11-A4-A11-B4-B4(11-A4-A)11-B4-A11-B4-B2(11-B4-A)12-B3-A12-A3-B13-A2-A13-A-A14-B2(-A14-A)2-A13-A2-A12-B4-A11-B4-A10-A6-A9-D5-2C-2A3-A3C5-3C2-3B-3C5-3C6-3C4-4C6-3C4-3(C2AC6-C2AC3-)4C6-4C19-B13-A2(2-A13-B)2-A13-AB-B2(13-2A-A)13-2A-B13-AB-A13-2A-B13-2A-A13-2A2-A13-A2-A12-A3-B13-A2-A13-B-A2(14-A-B)14-A2-A13-B3-2(A11-B4-)A10-A6-A7-2A8-D2A3-A13-B-B15-2B26-2(2C8-2C5-)2C8-2C36-B14-A-B14-B-A14-A-A15-2B15-BA15-2A15-AB15-BA15-3(A-A14-)A2-A12-A3-B13-A2-A13-2(A-A14-)B-A14-B2-B13-A3-B11-A5-A10-B4-A10-A6-2A6-AB9-2A3-A13-B-B15-B109-A14-B-B14-B-A14-A-A14-B-B2(14-A-A)14-A-B14-B-A14-A-B14-A2-A13-B2-A13-A3-A12-A3-B13-A2-A13-A2(-A14-B)-A14-A2-A13-A3-B11-B5-A10-A4-B4-A5-A6-2B6-AB9-BA2-2B13-2B126-A14-B2(-B14-A)-A14-B-B14-A-A14-A-B14-B-B14-A-A14-A2(2-A13-B)2-A13-A3-B12-A3-B13-A2-A13-A-A14-B2(-A14-A)2-A13-A3-A11-B5-A10-A4-A10-A6-B2A4-3A10-B-2B14-B125-B2-A13-B2-B2(13-A2-A)B12-B2-B2(13-A2-A)13-B2(2-A13-A)2-B13-B2-A13-2(A3-B12-)A3-B13-A2-B13-2(B-A14-)A-A14-A2-A13-A3-B11-B5-A10-A4-AB8-2A7-B2A3-2A12-3B140-B3-2A11-A3-BA11-A3-2A11-A4-A11-B3-2B11-A3-2A11-A3-AB11-B3-2B11-A3-BA11-A3-2A11-B3-2B11-A3-2A11-2(A3-A12-)A3-B13-B2-A13-A-A14-A2-A13-A2-B12-A4-B11-B5-A9-A6-2A2B3-3A11-B-B15-B147-2A8-A6-BA2(8-A6-2B8-A6-2A)8-A6-2A8-A6-BA2(8-A6-2A)8-B6-2B8-A6-2A8-A5-3A8-A4-4A9-A3-BA2B9-A3-2B2A9-A3-A12-A3-B11-2A3-BA10-2A4-2A8-2A6-3B2A2-3A11-B-B2(15-2B)148-2A4-2A9-2A4-BA9-2B4-2B9-2A2(4-2A9-BA)4-AB9-2A4-2B9-2A4-2A9-BA4-BA9-AB4-AB9-BA4-AB9-2A4-2A9-2A3-3A9-2A3-4A8-AB4-3A8-2A3-4A5-B2A2B6-A5-6A2-A-A7-4A3-ABA8-4A2-AB13-2B15-2B16-B167-A2-A13-B5(2-A13-A)2-B5(13-A2-A)13-2(A-A14-)B2-A13-A-A14-A2-3A12-2B-A12-A-B2(15-2B)15-B169-20(2B15-)B194-
