model
size = 3 28 3, scale = 0.05, origin = -y
material 
  colors = A:#111 B:#EEE C:#93F
voxels
--- --- --- --- --- --- --- --- --- --- --- --- --- --- --- --- --- --- --- --- --- --- --- --- --- BBB BCB BBB 
-A- -A- -A- -A- -A- -A- -A- -A- -A- -A- -A- -A- -A- -A- -A- -A- -A- -A- -A- -A- -A- -A- -A- -A- -A- BBB CBC BCB 
--- --- --- --- --- --- --- --- --- --- --- --- --- --- --- --- --- --- --- --- --- --- --- --- --- BBB BCB BBB 
