model
size = 20 29 17, scale = 0.05, origin = -y
material 
  colors = A:#630 B:#0E0 C:#070 D:#0F3 E:#050 F:#080
voxels
-------------------- -------------------- -------------------- -------------------- -------------------- -------------------- -------------------- -------------------- -------------------- -------------------- -------------------- -------------------- -------------------- -------------------- -------------------- -------------------- -------E------------ ------EEE----------- ------EEE----------- ------EEE----------- ------EEE----------- -------------------- -------------------- -------------------- -------------------- -------------------- -------------------- -------------------- -------------------- 
-------------------- -------------------- -------------------- -------------------- -------------------- -------------------- -------------------- -------------------- -------------------- -------------------- -------------------- -------------------- -------------------- -------------------- -------------------- -------------------- -------------------- -------------------- -------------------- -------------------- ------EEE----------- -------------------- -------------------- -------------------- -------------------- -------------------- -------------------- -------------------- -------------------- 
-------AAAAA-------- -------AAAAA-------- -------------------- -------------------- -------------------- -------------------- -------------------- -------------------- -------------------- -------------------- -------------------- -------------------- -------------------- -------------------- -------------------- -------------------- -------------------- -------------------- -------------------- -------------------- ------EEE----------- -------------------- -------------------- -------------------- -------------------- -------------------- -------------------- -------------------- -------------------- 
-----AAAAAAAAA------ -----AAAAAAAAA------ -------------------- -------------------- -------------------- -------------------- -------------------- -------------------- -------------------- -------------------- -------------------- -------------------- -------------------- -------------------- -------------------- -------------------- -------------------- -------------------- -------------------- -------------------- ------EEE----------- -------------------- -------------------- -------------------- -------------------- -------------------- -------------------- -------------------- -------------------- 
----AAAAAAAAAAA----- ----AAAAAAAAAAA----- ------AAAAA--------- -------------------- -------------------- -------------------- -------------------- -------------------- -------------------- -------------------- -------------------- -------------------- -------------------- -------------------- -------------------- ------AAAA-----F---- -----AAAA------F---- -----AAA-FFFFFFF---- -------------------- -------------------- ------EEE----------- -------------------- -------------------- -------------------- -------------------- -------------------- -------------------- -------------------- -------------------- 
---AAAAAAAAAAAAA---- ----AAAAAAAAAAA----- -----AAAAAAA-------- -------AAAAA-------- ------AAAAA--------- -------AAAAA-------- -------------------- -------------------- -------------------- -------------------- -------------------- -------------------- -------------------- -------AAAA--------- ------AAAA---------- -----AAAAAA----F---- ----AAAAAA-----F---- ----AAAAAFFFFFFF---- -------------------- -------------------- ------EEE----------- -------------------- -------------------- -------------------- -------------------- -------------------- -------------------- -------------------- -------------------- 
---AAAAAAAAAAAAA---- ---AAAAAAAAAAAAA---- ----AAAAAAAAA------- ------AAAAAAA------- -----AAAAAAA-------- -------AA---A------- -------A------------ -------------------- -------------------- -------------------- -------A------------ -------AA----------- ------AAAA---------- -----AAAAAAA-------- -----AAAAAA--------- -----AAAAAAA---F---- ---AAAAAAAA----F---- ---AAAAAAA-----F---- ----AAAAAAA--------- -------------------- -------EE----------- ----C--------------B ----C--------------B C---C--------------B C---C--------------B C---C--------------B CCCCC--------------B -------------------B -------------------- 
--AAAAAAAAAAAAAAA--- ---AAAAAAAAAAAAA---- ---AAAAAAAAAAA------ -----AAAAAAAAA------ ----AAAAAAAAA------- ------AAAAAAAA------ -------AAAA--------- ------AAAA---------- -------AAA--A------- -------AAA---------- -------AAAA--------- -------AAAAA-------- ------AAAAA--------- -----AAAAAAAA------- ----AAAAAAAA-------- ----AAAAAAAA-------- ---AAAAAAAA--------- ---AAA-AAA---------- ----AAAEAAA--------- ----C--E--B--------- ----C--EE-B--------B ----C-----B--------B C---C-----B--------B C---C-----B--------B C---C-----B--------B C---C-----B--------B CCCCC-----B--------B ----------B-------BB ----------BBBBBBBBB- 
--AAAAAAAAAAAAAAA--- ---AAAAAA-AAAAAA---- ---AAAAAAAAAAA------ -----AAAAAAAAA------ ----AAAAAAAAA------- -----AAAAAAAAA------ -------AAAAAA------- ------AAA-AAAA------ -------AAAAAA------- ------AAAAAA-------- ------AAAAAAA------- ------AAAAAA-------- -----AAAAAAA-------- -----AAA------------ ----AAAAAAAA-------- ---AAAA-AAAA-------- --AAAA-AAAA--------- ---AAAAAAA---------- ----AAAEAAA--------- -------------------- -------------------- ----C-----B--------B ----C-----B--------B C---C-----B--------B C---C-----B--------B C---C-----B--------B CCCCC-----B--------B ----------B--------B ----------BBBBBBBBB- 
--AAAAAAA-AAAAAAA--- ---AAAAAAAAAAAAA---- ---AAAAA-AAAAA------ -----AAAA-AAAA------ ----AAAA-AAAA------- ------AAA-AAAA------ ------AA-AAAA------- ------AAAAAAAA------ -------A-AAAA------- ------A-AAAA-------- ------AAAAAAA------- ------A-AAAA-------- -----AAAAAAA-------- ----AAA------------- ----AAA-AAAA-------- ---AAAAAAAAA-------- --AAAAAAAAA--------- ----AAAAA----------- -----AAAAA---------- -------------------- -------------------- -------------------- -------------------- -------------------- -------------------- -------------------- -------------------- -------------------- -------------------- 
--AAAAAAAAAAAAAAA--- ---AAAAAAAAAAAAA---- ---AAAAAAAAAAA------ -----AAAAAAAAA------ ----AAAAAAAAA------- ------AAAAAAAA------ ------AAAAAAA------- ------AAAAAAAA------ -------AAAAAA------- ------AAAAAA-------- ------AA-AAAA------- ------AAAAAA-------- -----AA-AAAA-------- ----AA-------------- ----AAAAAAAA-------- ---AAAAAAAAA-------- --AAAAAAAAA--------- -----AAA------------ ------AAA----------- -------D------------ -------D------------ -------D------------ -------D------------ ------DDD----------- -------------------- -------------------- -------------------- -------------------- -------------------- 
--AAAAAAAAAAAAAAA--- ----AAAAAAAAAAA----- ---AAAAAAAAAAA------ -----AAAAAAAAA------ ----AAAAAAAAA------- -----AAAAAAAAA------ ------AAAAAAA------- ------AAAAAAA------- -------AAAAAA------- ------AAAAAA-------- ------AA---AA------- -----AAAAAAA-------- -----AAAAAAA-------- ----A--------------- ----AAAAAAAA-------- ----AAAAAAA--------- -------------------- -------------------- -------------------- -------------------- -------------------- -------------------- -------------------- ------DDD----------- -------------------- -------------------- -------------------- -------------------- -------------------- 
---AAAAAAAAAAAAA---- ----AAAAAAAAAAA----- ----AAAAAAAAA------- ------AAAAAAA------- -----AAAAAAA-------- ------AAAAAAA------- ------AAAAAA-------- -------AAAAA-------- --------AAAA-------- -------------------- -------------------- -------------------- -------------------- -------------------- -------AAAA--------- ---------A---------- -------------------- -------------------- -------------------- -------------------- -------------------- -------------------- -------------------- ------DDD----------- -------------------- -------------------- -------------------- -------------------- -------------------- 
---AAAAAAAAAAAAA---- -----AAAAAAAAA------ -----AAAAAAA-------- -------AAAAA-------- ------AAAAA--------- -------AAAAA-------- ------AAAAA--------- -------------------- -------------------- -------------------- -------------------- -------------------- -------------------- -------------------- -------------------- -------------------- -------------------- -------------------- -------------------- -------------------- -------------------- -------------------- -------------------- ------DDD----------- -------------------- -------------------- -------------------- -------------------- -------------------- 
----AAAAAAAAAAA----- -------AAAAA-------- ------AAAAA--------- -------------------- -------------------- -------------------- -------------------- -------------------- -------------------- -------------------- -------------------- -------------------- -------------------- -------------------- -------------------- -------------------- -------------------- -------D------------ ------DDD----------- ------DDD----------- ------DDD----------- ------DDD----------- ------DDD----------- ------DDD----------- -------------------- -------------------- -------------------- -------------------- -------------------- 
-----AAAAAAAAA------ -------------------- -------------------- -------------------- -------------------- -------------------- -------------------- -------------------- -------------------- -------------------- -------------------- -------------------- -------------------- -------------------- -------------------- -------------------- -------------------- -------------------- -------------------- -------------------- -------------------- -------------------- -------------------- -------------------- -------------------- -------------------- -------------------- -------------------- -------------------- 
-------AAAAA-------- -------------------- -------------------- -------------------- -------------------- -------------------- -------------------- -------------------- -------------------- -------------------- -------------------- -------------------- -------------------- -------------------- -------------------- -------------------- -------------------- -------------------- -------------------- -------------------- -------------------- -------------------- -------------------- -------------------- -------------------- -------------------- -------------------- -------------------- -------------------- 
