model
size = 23 24 32, scale = 0.05, origin = -y
material 
  colors = A:#66BAB7 B:#FCFAF2 C:#FB9966 D:#B5495B E:#8A6BBE F:#00AA90 G:#A5A051 H:#0B1013
voxels
4-9(19(A2BAB2A6B2A8-)A2BAB2A6B2A100-)3(19(15A8-)15A100-)10(2A4-3A4-2A8-)2A4-3A4-2A4-G4(3-2A4-3A4-2A3-2G)3-2A4-3A4-2A3-G4-3(2A4-3A4-2A8-)2A4-3A4-2A100-10(2A4C3A4C2A8-)2A4C3A4C2A4-G3-2A4C3A4C2A3-G4E2(2A4C3A4C2A8E)2A4C3A4C2A4EG3-2A4C3A4C2A3-G4-3(2A4C3A4C2A8-)2A4C3A4C2A100-10(2A4C3A4C2A8-)2A4C3A4C2A4-G3-2A4C3A4C2A3-G4E2A4C3A4C2A4E23-4E2A4C3A4C2A4EG3-2A4C3A4C2A3-G4-3(2A4C3A4C2A8-)2A4C3A4C2A100-10(2A4C3A4C2A8-)2A4C3A4C2A4-G3-2A4C3A4C2A3-G4E2(2A4C3A4C2A8E)2A4C3A4C2A4EG3-2A4C3A4C2A3-G4-3(2A4C3A4C2A8-)2A4C3A4C2A100-10(2A4C3A4C2A8-)2A4C3A4C2A4-G4(3-2A4C3A4C2A3-2G)3-2A4C3A4C2A3-G4-3(2A4C3A4C2A8-)2(2A4C3A4C2A100-19(2A4C3A4C2A8-))2A4C3A4C2A100-19(6D3A6D8-)6D3A6D2(238-13(15A8-)15A)82-5H151-13(15A8-)15A14-2(3F20-)3F19-H3FH151-13(7A-7A8-)7A-7A14-2(F-F20-)F-F19-HF-FH152-13(13A10-)13A15-2(3F20-)3F19-H3FH152-13(13A10-)13A83-5H152-13(13A10-)13A241-13(11A12-)11A242-13(11A12-)11A243-13(9A14-)9A246-13(5A18-)5A250-13(A22-)A103-
