model
size = 30 31 29, scale = 0.05, origin = -y
material 
  colors = A:#22224B B:#141438 C:#700 D:#D79D2A E:#400 F:#001 G:#500 H:#FFBB32 I:#FC0 J:#F90
voxels
------------------------------ ------------------------------ ------------------------------ ------------------------------ ------------------------------ ------------------------------ ------------------------------ ------------------------------ ------------------------------ ------------------------------ ------------------------------ ------------------------------ ------------------------------ ------------------------------ ------------------------------ ------------------------------ ------------------------------ ------------------------------ ------------------------------ -----------JJ-JJ-JJ----------- ------------------------------ ------------------------------ ------------------------------ ------------------------------ ------------------------------ ------------------------------ ------------------------------ ------------------------------ ------------C-CC-C------------ ------------------------------ ------------------------------ 
------------------------------ ------------------------------ ----------CCCCCCCCCC---------- ----------CAAAAAAAAC---------- ----------CAAAAAAAAC---------- ----------CAAAAAAAAC---------- ---------CCAAAAAAAACC--------- ---------CAAGGGGGGAAC--------- ---------CAAGIGGIGAAC--------- ---------CAAGGGGGGAAC--------- ---------CAAAAAAAAAAC--------- ---------CAAGGGGGGAAC--------- ---------CCAGIGGIGACC--------- ----------CAGGGGGGAC---------- ----------CAAAAAAAAC---------- ----------CAGGGGGGAC---------- ----------CAGIGGIGAC---------- ----------CAGGGGGGAC---------- ----------CAAAAAAAAC---------- ----------CJJAJJAJJC---------- ----------CAAAAAAAAC---------- -----------CCCCCCCC----------- ------------------------------ ------------------------------ ------------------------------ ------------------------------ -----------AAAAAAAA----------- -----------AAAAAAAA----------- -----------ACACCACA----------- ----------FAAAAAAAAF---------- ------------------------------ 
-----------DDDDDDDD----------- -----------BBCCCCBB----------- --------ABAAAAAAAAAABA-------- --------ABAAAAAAAAAABA-------- --------EBAAAAAAAAAABE-------- --------DBAAAAAAAAAABD-------- ------AAAAAAAAAAAAAAAAAA------ ------AAAAAAAAAAAAAAAAAA------ ------AAAAAAAAAAAAAAAAAA------ ------AAAAAAAAAAAAAAAAAA------ ------GGGAAAAAAAAAAAAGGG------ ------GIGAAAAAAAAAAAAGIG------ ------HHHAAAAAAAAAAAAHHH------ --------ABAAAAAAAAAABA-------- --------ABAAAAAAAAAABA-------- --------ABAAAAAAAAAABA-------- --------ABAAAAAAAAAABA-------- --------FFAAAAAAAAAAFF-------- ----------AAAAAAAAAA---------- ---------FAAAAAAAAAAF--------- --------FFAAAAAAAAAAFF-------- --------FGGAAAAAAAAGGF-------- --------FGAAAAAAAAAAGF-------- --------FGAABBBBBBAAGF-------- --------FGABBBBBBBBAGF-------- --------FGBBBBBBBBBBGF-------- --------FFBAAAAAAAABFF-------- ---------FFAAAAAAAAFF--------- ----------FAAAAAAAAF---------- ---------AAAFFFFFFAAA--------- ---------FFF------FFF--------- 
---------DDDDDDDDDDDD--------- ---------ABAAAAAAAABA--------- -------AAAAAAAAAAAAAAAA------- -------AAAAAAAAAAAAAAAA------- -------EEAAAAAAAAAAAAEE------- -------DAAAAAAAAAAAAAAD------- -----AAAAAAAAAAAAAAAAAAAA----- -----AAAAAAAAAAAAAAAAAAAA----- -----AAAAAAAAAAAAAAAAAAAA----- -----AAAAAAAAAAAAAAAAAAAA----- -----AAAAAAAAAAAAAAAAAAAA----- -----CAAAAAAAAAAAAAAAAAAC----- -----HHAAAAAAAAAAAAAAAAHH----- -------AAAAAAAAAAAAAAAA------- -------AAAAAAAAAAAAAAAA------- -------AAAAAAAAAAAAAAAA------- -------AAAAAAAAAAAAAAAA------- -------F--AAAAAAAAAA--F------- ----------AAAAAAAAAA---------- ----------AAAAAAAAAA---------- ----------AAAAAAAAAA---------- ---------AAAAAAAAAAAA--------- ---------AAAAAAAAAAAA--------- ---------AAAAAAAAAAAA--------- ---------AAAAAAAAAAAA--------- ---------AAAAAAAAAAAA--------- ----------AAAAAAAAAA---------- -----------AAAAAAAA----------- ---------BAAAAAAAAAAB--------- --------AAAAAAAAAAAAAA-------- --------FAAA------AAAF-------- 
--------DDDDDDDDDDDDDD-------- --------ABBBBBBBBBBBBA-------- -----AAAABBBBBBBBBBBBAAAA----- -----AAAABBBBBBBBBBBBAAAA----- -----EEEEBBBBBBBBBBBBEEEE----- -----DDDABBBBBBBBBBBBADDD----- ----AAAAABBBBBBBBBBBBAAAAA---- ----AAAAABBBBBBBBBBBBAAAAA---- ----AAAAABBBBBBBBBBBBAAAAA---- ----AAAAABBBBBBBBBBBBAAAAA---- ----AAAAABBBBBBBBBBBBAAAAA---- ----CCAAABBBBBBBBBBBBAAACC---- ----HAAABBBBBBBBBBBBBBAAAH---- -----AAABBBBBBBBBBBBBBAAA----- -----AAABBBBBBBBBBBBBBAAA----- -----AAABBBBBBBBBBBBBBAAA----- -----AAABBBBBBBBBBBBBBAAA----- -----FFF--BBBBBBBBBB--FFF----- ----------BBBBBBBBBB---------- ----------BBBBBBBBBB---------- ----------BBBBBBBBBB---------- ---------BBBBBBBBBBBB--------- ---------BBBBBBBBBBBB--------- ---------BBBBBBBBBBBB--------- ---------BBBBBBBBBBBB--------- ---------BBBBBBBBBBBB--------- ----------BBBBBBBBBB---------- -----------BBBBBBBB----------- --------BABBBBBBBBBBAB-------- -------AAABBBBBBBBBBAAA------- -------FFABB------BBAFF------- 
------DDB------------BDD------ ------AAB------------BAA------ ----AAAAB------------BAAAA---- ----AAAAB------------BAAAA---- ----EEEEE------------EEEEE---- ----DDDDB------------BDDDD---- ---AAAAAB------------BAAAAA--- ---AAAAAB------------BAAAAA--- ---AAAAAB------------BAAAAA--- ---AAAAAB------------BAAAAA--- ---AAAAAB------------BAAAAA--- ---CCCAAB------------BAACCC--- ---HAAAA--------------AAAAH--- ----AAAA--------------AAAA---- ----AAAA--------------AAAA---- ----AAAA--------------AAAA---- ----AAAA--------------AAAA---- ----FFFF--------------FFFF---- ------------------------------ ------------------------------ ------------------------------ ------------------------------ ------------------------------ ------------------------------ ------------------------------ ------------------------------ ------------------------------ ------------------------------ --------BA----------AB-------- -------AAA----------AAA------- -------FAA----------AAF------- 
-----DDB--------------BDD----- -----AAB--------------BAA----- ----AAAB--------------BAAA---- ----AAAB--------------BAAA---- ----EEEE--------------EEEE---- ----DDDD--------------DDDD---- ---AAAAB--------------BAAAA--- ---AAAAB--------------BAAAA--- ---AAAAB--------------BAAAA--- ---AAAAB--------------BAAAA--- ---AAAAB--------------BAAAA--- ---CCCBB--------------BBCCC--- ---HA--------------------AH--- ----A--------------------A---- ----A--------------------A---- ----A--------------------A---- ----A--------------------A---- ----F--------------------F---- ------------------------------ ------------------------------ ------------------------------ ------------------------------ ------------------------------ ------------------------------ ------------------------------ ------------------------------ ------------------------------ ------------------------------ --------BA----------AB-------- -------AAA----------AAA------- -------FAA----------AAF------- 
-----DB----------------BD----- -----AB----------------BA----- ---AAAB----------------BAAA--- ---AAAB----------------BAAA--- ---EEEE----------------EEEE--- ---DDDD----------------DDDD--- --AAAAB----------------BAAAA-- --AAAAB----------------BAAAA-- --AAAAB----------------BAAAA-- --AAAAB----------------BAAAA-- --AAAAB----------------BAAAA-- --CCCCB----------------BCCCC-- --HAA--------------------AAH-- ---AA--------------------AA--- ---AA--------------------AA--- ---AA--------------------AA--- ---AA--------------------AA--- ---FF--------------------FF--- ------------------------------ ------------------------------ ------------------------------ ------------------------------ ------------------------------ ------------------------------ ------------------------------ ------------------------------ ------------------------------ ------------------------------ --------BA----------AB-------- -------AAA----------AAA------- -------FAA----------AAF------- 
---DDB------------------BDD--- ---AAB------------------BAA--- ---BAB------------------BAB--- --BBAB------------------BABB-- --EEEE------------------EEEE-- --DAAB------------------BAAD-- -AAAAB------------------BAAAA- -AAAAB------------------BAAAA- -AAAAB------------------BAAAA- -AAAAB------------------BAAAA- -AAAAB------------------BAAAA- -CCCCC------------------CCCCC- -HAA----------------------AAH- --AA----------------------AA-- --AA----------------------AA-- --AA----------------------AA-- --AA----------------------AA-- --FF----------------------FF-- ------------------------------ ------------------------------ ------------------------------ ------------------------------ ------------------------------ ------------------------------ ------------------------------ ------------------------------ ------------------------------ ------------------------------ --------BA----------AB-------- -------AAA----------AAA------- -------FAA----------AAF------- 
---DB--------------------BD--- ---AB--------------------BA--- ---BB--------------------BB--- --BBB--------------------BBB-- --EEE--------------------EEE-- --DAB--------------------BAD-- -AAAB--------------------BAAA- -AAAB--------------------BAAA- -AAAB--------------------BAAA- -AAAB--------------------BAAA- -AAAB--------------------BAAA- -CCCC--------------------CCCC- -HA------------------------AH- --A------------------------A-- --A------------------------A-- --A------------------------A-- --A------------------------A-- --F------------------------F-- ------------------------------ ------------------------------ ------------------------------ ------------------------------ ------------------------------ ------------------------------ ------------------------------ ------------------------------ ------------------------------ ------------------------------ --------BA----------AB-------- -------AAA----------AAA------- -------FAA----------AAF------- 
---DB--------------------BD--- ---AB--------------------BA--- ---BB--------------------BB--- --BBB--------------------BBB-- --EEE--------------------EEE-- --DAB--------------------BAD-- -AAAB--------------------BAAA- -AAAB--------------------BAAA- -AAAB--------------------BAAA- -AAAB--------------------BAAA- -AAAB--------------------BAAA- -CCCC--------------------CCCC- -HA------------------------AH- --A------------------------A-- --A------------------------A-- --A------------------------A-- --A------------------------A-- --F------------------------F-- ------------------------------ ------------------------------ ------------------------------ ------------------------------ ------------------------------ ------------------------------ ------------------------------ ------------------------------ ------------------------------ ------------------------------ --------BA----------AB-------- -------AAA----------AAA------- -------FAA----------AAF------- 
---D----------------------D--- ---B----------------------B--- ---B----------------------B--- -AAB----------------------BAA- -EEE----------------------EEE- -DDB----------------------BDD- AAAB----------------------BAAA AAAB----------------------BAAA AAAB----------------------BAAA AAAB----------------------BAAA AAAB----------------------BAAA CCCC----------------------CCCC HAA------------------------AAH -AA------------------------AA- -AA------------------------AA- -AA------------------------AA- -AA------------------------AA- -FF------------------------FF- ------------------------------ ------------------------------ ------------------------------ ------------------------------ ------------------------------ ------------------------------ ------------------------------ ------------------------------ ------------------------------ ------------------------------ ------------------------------ ------------------------------ ------------------------------ 
--DD----------------------DD-- --AB----------------------BA-- --BB----------------------BB-- -AAB----------------------BAA- -EEE----------------------EEE- -DDB----------------------BDD- AAAB----------------------BAAA AAAB----------------------BAAA AAAB----------------------BAAA AAAB----------------------BAAA AAAB----------------------BAAA CCCC----------------------CCCC HA--------------------------AH -A--------------------------A- -A--------------------------A- -A--------------------------A- -A--------------------------A- -F--------------------------F- ------------------------------ ------------------------------ ------------------------------ ------------------------------ ------------------------------ ------------------------------ ------------------------------ ------------------------------ ------------------------------ ------------------------------ ------------------------------ ------------------------------ ------------------------------ 
--DD----------------------DD-- --AB----------------------BA-- --BB----------------------BB-- -AAB----------------------BAA- -EEE----------------------EEE- -DDB----------------------BDD- AAAB----------------------BAAA AAAB----------------------BAAA IAAB----------------------BAAI AAAB----------------------BAAA AAAB----------------------BAAA CCCC----------------------CCCC HA--------------------------AH -A--------------------------A- -A--------------------------A- -A--------------------------A- -A--------------------------A- -F--------------------------F- ------------------------------ ------------------------------ ------------------------------ ------------------------------ ------------------------------ ------------------------------ ------------------------------ ------------------------------ ------------------------------ ------------------------------ ------------------------------ ------------------------------ ------------------------------ 
--DD----------------------DD-- --AB----------------------BA-- --BB----------------------BB-- -AAB----------------------BAA- -EEE----------------------EEE- -DDB----------------------BDD- AAAB----------------------BAAA AAAB----------------------BAAA AAAB----------------------BAAA AAAB----------------------BAAA AAAB----------------------BAAA CCCC----------------------CCCC HA--------------------------AH -A--------------------------A- -A--------------------------A- -A--------------------------A- -A--------------------------A- -F--------------------------F- ------------------------------ ------------------------------ ------------------------------ ------------------------------ ------------------------------ ------------------------------ ------------------------------ ------------------------------ ------------------------------ ------------------------------ ------------------------------ ------------------------------ ------------------------------ 
--DD----------------------DD-- --AB----------------------BA-- --BB----------------------BB-- -AAB----------------------BAA- -EEE----------------------EEE- -DDB----------------------BDD- AAAB----------------------BAAA AAAB----------------------BAAA AAAB----------------------BAAA AAAB----------------------BAAA AAAB----------------------BAAA CCCC----------------------CCCC HA--------------------------AH -A--------------------------A- -A--------------------------A- -A--------------------------A- -A--------------------------A- -F--------------------------F- ------------------------------ ------------------------------ ------------------------------ ------------------------------ ------------------------------ ------------------------------ ------------------------------ ------------------------------ ------------------------------ ------------------------------ ------------------------------ ------------------------------ ------------------------------ 
--DD----------------------DD-- --AB----------------------BA-- --BB----------------------BB-- -AAB----------------------BAA- -EEE----------------------EEE- -DDB----------------------BDD- AAAB----------------------BAAA AAAB----------------------BAAA IAAB----------------------BAAI AAAB----------------------BAAA AAAB----------------------BAAA CCCC----------------------CCCC HA--------------------------AH -A--------------------------A- -A--------------------------A- -A--------------------------A- -A--------------------------A- -F--------------------------F- ------------------------------ ------------------------------ ------------------------------ ------------------------------ ------------------------------ ------------------------------ ------------------------------ ------------------------------ ------------------------------ ------------------------------ ------------------------------ ------------------------------ ------------------------------ 
--DD----------------------DD-- --AB----------------------BA-- --BB----------------------BB-- -AAB----------------------BAA- -EEE----------------------EEE- -DDB----------------------BDD- AAAB----------------------BAAA AAAB----------------------BAAA AAAB----------------------BAAA AAAB----------------------BAAA AAAB----------------------BAAA CCCC----------------------CCCC HA--------------------------AH -A--------------------------A- -A--------------------------A- -A--------------------------A- -A--------------------------A- -F--------------------------F- ------------------------------ ------------------------------ ------------------------------ ------------------------------ ------------------------------ ------------------------------ ------------------------------ ------------------------------ ------------------------------ ------------------------------ ------------------------------ ------------------------------ ------------------------------ 
---DB--------------------BD--- ---AB--------------------BA--- ---BB--------------------BB--- -AAAB--------------------BAAA- -EEEE--------------------EEEE- -DDAB--------------------BADD- AAAAB--------------------BAAAA AAAAB--------------------BAAAA AAAAB--------------------BAAAA AAAAB--------------------BAAAA AAAAB--------------------BAAAA CCCCC--------------------CCCCC HAA------------------------AAH -AA------------------------AA- -AA------------------------AA- -AA------------------------AA- -AA------------------------AA- -FF------------------------FF- ------------------------------ ------------------------------ ------------------------------ ------------------------------ ------------------------------ ------------------------------ ------------------------------ ------------------------------ ------------------------------ ------------------------------ ------------------------------ ------------------------------ ------------------------------ 
---DB--------------------BD--- ---AB--------------------BA--- ---BB--------------------BB--- --AAB--------------------BAA-- --EEE--------------------EEE-- --DDD--------------------DDD-- -AAAB--------------------BAAA- -AAAB--------------------BAAA- -AAAB--------------------BAAA- -AAAB--------------------BAAA- -AAAB--------------------BAAA- -CCCC--------------------CCCC- -HA------------------------AH- --A------------------------A-- --A------------------------A-- --A------------------------A-- --A------------------------A-- --F------------------------F-- ------------------------------ ------------------------------ ------------------------------ ------------------------------ ------------------------------ ------------------------------ ------------------------------ ------------------------------ ------------------------------ ------------------------------ ------------------------------ ------------------------------ ------------------------------ 
---DDB------------------BDD--- ---AAB------------------BAA--- ---BAB------------------BAB--- --AAAB------------------BAAA-- --EEEB------------------BEEE-- --DDDD------------------DDDD-- -AAAAB------------------BAAAA- -AAAAB------------------BAAAA- -AAAAB------------------BAAAA- -AAAAB------------------BAAAA- -AAAAB------------------BAAAA- -CCCCC------------------CCCCC- -HA------------------------AH- --A------------------------A-- --A------------------------A-- --A------------------------A-- --A------------------------A-- --F------------------------F-- ------------------------------ ------------------------------ ------------------------------ ------------------------------ ------------------------------ ------------------------------ ------------------------------ ------------------------------ ------------------------------ ------------------------------ ------------------------------ ------------------------------ ------------------------------ 
----DDB----------------BDD---- ----AAB----------------BAA---- ----BBB----------------BBB---- --AAAAB----------------BAAAA-- --EEEAB----------------BAEEE-- --DDDDD----------------DDDDD-- -AAAAAB----------------BAAAAA- -AAAAAB----------------BAAAAA- -AAAAAB----------------BAAAAA- -AAAAAB----------------BAAAAA- -AAAAAB----------------BAAAAA- -CCCCCC----------------CCCCCC- -HA------------------------AH- --A------------------------A-- --A------------------------A-- --A------------------------A-- --A------------------------A-- --F------------------------F-- ------------------------------ ------------------------------ ------------------------------ ------------------------------ ------------------------------ ------------------------------ ------------------------------ ------------------------------ ------------------------------ ------------------------------ ------------------------------ ------------------------------ ------------------------------ 
-----DDB--------------BDD----- -----AAB--------------BAA----- -----BAB--------------BAB----- ---AAAAB--------------BAAAA--- ---EEAAB--------------BAAEE--- ---DDDDD--------------DDDDD--- --AAAAAB--------------BAAAAA-- --AAAAAB--------------BAAAAA-- --AAAAAB--------------BAAAAA-- --AAAAAB--------------BAAAAA-- --AAAAAB--------------BAAAAA-- --CCCCCC--------------CCCCCC-- --HAA--------------------AAH-- ---AA--------------------AA--- ---AA--------------------AA--- ---AA--------------------AA--- ---AA--------------------AA--- ---FF--------------------FF--- ------------------------------ ------------------------------ ------------------------------ ------------------------------ ------------------------------ ------------------------------ ------------------------------ ------------------------------ ------------------------------ ------------------------------ ------------------------------ ------------------------------ ------------------------------ 
-----DDDB------------BDDD----- -----AAAB------------BAAA----- -----BAAB------------BAAB----- ----AAAAB------------BAAAA---- ----EAAAB------------BAAAE---- ----DDDDB------------BDDDD---- ---AAAAAB------------BAAAAA--- ---AAAAAB------------BAAAAA--- ---AAAAAB------------BAAAAA--- ---AAAAAB------------BAAAAA--- ---AAAAAB------------BAAAAA--- ---CCCCCB------------BCCCCC--- ---HA--------------------AH--- ----A--------------------A---- ----A--------------------A---- ----A--------------------A---- ----A--------------------A---- ----F--------------------F---- ------------------------------ ------------------------------ ------------------------------ ------------------------------ ------------------------------ ------------------------------ ------------------------------ ------------------------------ ------------------------------ ------------------------------ ------------------------------ ------------------------------ ------------------------------ 
------DDDBB--------BBDDD------ ------AAABB--------BBAAA------ ------BBBBB--------BBBBB------ ----AAAAABB--------BBAAAAA---- ----EEEEEEB--------BEEEEEE---- ----DDDDABB--------BBADDDD---- ---AAAAAABB--------BBAAAAAA--- ---AAAAAABB--------BBAAAAAA--- ---AAAAAABB--------BBAAAAAA--- ---AAAAAABB--------BBAAAAAA--- ---AAAAAABB--------BBAAAAAA--- ---CCCCCBBB--------BBBCCCCC--- ---HAA------------------AAH--- ----AA------------------AA---- ----AA------------------AA---- ----AA------------------AA---- ----AA------------------AA---- ----FF------------------FF---- ------------------------------ ------------------------------ ------------------------------ ------------------------------ ------------------------------ ------------------------------ ------------------------------ ------------------------------ ------------------------------ ------------------------------ ------------------------------ ------------------------------ ------------------------------ 
--------DDDDDDDDDDDDDD-------- --------AAABBBBBBBBAAA-------- --------BBBBBBBBBBBBBB-------- -----AAAAAABBBBBBBBAAAAAA----- -----EEEEEABBBBBBBBAEEEEE----- -----DDDAAABBBBBBBBAAADDD----- ----AAAAAAABBBBBBBBAAAAAAA---- ----AAAAAAABBBBBBBBAAAAAAA---- ----AAAAAAABBBBBBBBAAAAAAA---- ----AAAAAAABBBBBBBBAAAAAAA---- ----AAAAAAABBBBBBBBAAAAAAA---- ----CCCCBBBBBBBBBBBBBBCCCC---- ----HAAA--------------AAAH---- -----AAA--------------AAA----- -----AAA--------------AAA----- -----AAA--------------AAA----- -----AAA--------------AAA----- -----FFF--------------FFF----- ------------------------------ ------------------------------ ------------------------------ ------------------------------ ------------------------------ ------------------------------ ------------------------------ ------------------------------ ------------------------------ ------------------------------ ------------------------------ ------------------------------ ------------------------------ 
---------DDDDDDDDDDDD--------- ---------AABAAAAAABAA--------- ---------BBBAAAAAABBB--------- -------AAAAAAAAAAAAAAAA------- -------EEEAAAAAAAAAAEEE------- -------DAAAAAAAAAAAAAAD------- -----AAAAAAAAAAAAAAAAAAAA----- -----AAAAAAAAAAAAAAAAAAAA----- -----AAAAAAAAAAAAAAAAAAAA----- -----AAAAAAAAAAAAAAAAAAAA----- -----AAAAAAAAAAAAAAAAAAAA----- -----CCCAAABBBBBBBBAAACCC----- -----HHAAAA--------AAAAHH----- -------AAAA--------AAAA------- -------AAAA--------AAAA------- -------AAAA--------AAAA------- -------AAAA--------AAAA------- -------FFFF--------FFFF------- ------------------------------ ------------------------------ ------------------------------ ------------------------------ ------------------------------ ------------------------------ ------------------------------ ------------------------------ ------------------------------ ------------------------------ ------------------------------ ------------------------------ ------------------------------ 
------------EEEEEE------------ ------------EEEEEE------------ ------------EEEEEE------------ --------AABBAAAAAABBAA-------- --------EEBAAAAAAAABEE-------- --------BBBAAAAAAAABBB-------- -------AAAAAAAAAAAAAAAA------- -------AAAAAAAAAAAAAAAA------- -------AAAAAAAAAAAAAAAA------- -------AAAAAAAAAAAAAAAA------- -------AAAAAAAAAAAAAAAA------- -------CAAAAAAAAAAAAAAC------- -------HAAAAAAAAAAAAAAH------- --------AAAAAAAAAAAAAA-------- --------AAAAAAAAAAAAAA-------- --------AIAAAAAAAAAAIA-------- --------AAAAAAAAAAAAAA-------- --------FFFFFFFFFFFFFF-------- ------------------------------ ------------------------------ ------------------------------ ------------------------------ ------------------------------ ------------------------------ ------------------------------ ------------------------------ ------------------------------ ------------------------------ ------------------------------ ------------------------------ ------------------------------ 
------------------------------ ------------------------------ ------------------------------ -----------GGGGGGGG----------- -----------GAAAAAAG----------- -----------GAIAAIAG----------- --------GGGGAAAAAAGGGG-------- --------GAAAAAAAAAAAAG-------- --------GAAAAAAAAAAAAG-------- --------GAIAAIAAIAAIAG-------- --------GAAAAAAAAAAAAG-------- --------GAAAAAAAAAAAAG-------- --------GGGGAAAAAAGGGG-------- -----------GAIAAIAG----------- -----------GAAAAAAG----------- -----------GAAAAAAG----------- -----------GGGGGGGG----------- -----------FFFFFFFF----------- ------------------------------ ------------------------------ ------------------------------ ------------------------------ ------------------------------ ------------------------------ ------------------------------ ------------------------------ ------------------------------ ------------------------------ ------------------------------ ------------------------------ ------------------------------ 
