model
size = 23 13 9, scale = 0.05, origin = -y
material 
  colors = A:#FFD700 B:#EAC300
voxels
--------AAAAA---------- ----------------------- ----------------------- ----------------------- ----------------------- ----------------------- ----------------------- ----------------------- ----------------------- ----------------------- ----------------------- ----------------------- ----------------------- 
-------AA---AA--------- ---------BBB----------- ----------------------- ----------------------- ----------------------- ----------------------- ----------------------- ----------------------- ----------------------- ----------------------- ----------------------- ----------------------- ----------------------- 
------AA-----AA-------- --------BAAAB---------- ----------------------- ----------------------- ----------------------- ----------------------- ----------------------- ----------------------- ----------------------- ----------------------- ----------------------- ----------------------- ----------------------- 
------A-------A-------- -------BAAAAAB--------- ---------AAA----------- --------BBBBB---------- -------AAAAAAAA-------- -----BBBBBBBBBBB------- --AAAAAAAAAAAAAAAA----- -A---BBBBBBBBBBBBBBB--- A---AAAAAAAAAAAAAAAAA-- A--A---BBBBBBB-------AA A--A----ABABA---------- AAA------ABA----------- ----------A------------ 
------A-------A-------- -------BAA-AAB--------- ---------BAB----------- --------BBABB---------- -------BBBABBBB-------- -----BBBBBABBBBB------- --BBBBBBBBABBBBBBB----- -B---BBBBBABBBBBBBBB--- B---BBBBBBAAAABBBBBBB-- B--B---AAAAAAA-------BB B--B----BAAAB---------- BBB------BAB----------- ----------B------------ 
------A-------A-------- -------BAAAAAB--------- ---------AAA----------- --------BBBBB---------- -------AAAAAAAA-------- -----BBBBBBBBBBB------- --AAAAAAAAAAAAAAAA----- -A---BBBBBBBBBBBBBBB--- A---AAAAAAAAAAAAAAAAA-- A--A---BBBBBBB-------AA A--A----ABABA---------- AAA------ABA----------- ----------A------------ 
------AA-----AA-------- --------BAAAB---------- ----------------------- ----------------------- ----------------------- ----------------------- ----------------------- ----------------------- ----------------------- ----------------------- ----------------------- ----------------------- ----------------------- 
-------AA---AA--------- ---------BBB----------- ----------------------- ----------------------- ----------------------- ----------------------- ----------------------- ----------------------- ----------------------- ----------------------- ----------------------- ----------------------- ----------------------- 
--------AAAAA---------- ----------------------- ----------------------- ----------------------- ----------------------- ----------------------- ----------------------- ----------------------- ----------------------- ----------------------- ----------------------- ----------------------- ----------------------- 
