model
size = 17 26 11, scale = 0.05, origin = -y
material 
  colors = A:#FFC B:#FC6 C:#930 D:#C60 E:#C00
voxels
----------------- ----------------- ----------------- ----------------- ----------------- ----------------- ----------------- ----------------- ----------------- ----------------- ----------------- ----------------- ----------------- ----------------- ----------------- ----------------- ----------------- DD-------------DD DD-------------DD DD-------------DD DC-------------CD CC-------------CC ----------------- ----------------- ----------------- ----------------- 
----------------- ----------------- ----------------- ----------------- ----------------- ----------------- ----------------- ----------------- ----------------- ----------------- ----------------- ----------------- ----------------- -E-------------E- -E-------------E- -E-------------E- -B-------------B- -B-------------B- -B-------------B- -B-------------B- DD-------------DD DD-------------DD CC-------------CC ----------------- ----------------- ----------------- 
----CC-----CC---- ----AA-----AA---- ----AA-----AA---- ----AA-----AA---- ----AA-----AA---- ----AA-----AA---- ----AA-----AA---- ----AA-----AA---- ----AA-----AA---- -E--AA-----AA--E- -E--AA-----AA--E- -B--AA-----AA--B- -B--AA-----AA--B- -B--AA-----AA--B- -B--AA-----AA--B- -B--AA-----AA--B- -E--AA-----AA--E- -B--AA-----AA--B- -B--AA-----AA--B- -B--AAAAAAAAA--B- -B--ACAAAAACA--B- DD--CACAAACAC--DD DD--CACAAACAC--DD CC--CCCAAACCC--CC ----AAAAAAAAA---- ----CCCCCCCCC---- 
---CAAC---CAAC--- ---AAAA---AAAA--- ---AAAA---AAAA--- ---AAAA---AAAA--- ---AAAA---AAAA--- -B-AAAA---AAAA-B- -B-AAAA---AAAA-B- -E-AAAA---AAAA-E- -B-AAAA---AAAA-B- -B-AAAA---AAAA-B- -B-AAAA---AAAA-B- -B-AAAA---AAAA-B- -B-AAAA---AAAA-B- -B-AAAA---AAAA-B- -E-AAAA---AAAA-E- -E-AAAA---AAAA-E- -E-AAAA---AAAA-E- -E-AAAA---AAAA-E- -E-AAAA---AAAA-E- -B-AAAAAAAAAAA-B- -B-AAAAAAAAAAA-B- -B-AAAAAAAAAAA-B- DD-AAAAAAAAAAA-DD DC-AAAAAAAAAAA-CD CC-A---------A-CC ---C---------C--- 
--CAAAC---CAAAC-- -EAAAAA---AAAAAE- -BAAAAA---AAAAAB- -BAAAAA---AAAAAB- -EAAAAA---AAAAAE- -BAAAAA---AAAAAB- -BAAAAA---AAAAAB- -EAAAAA---AAAAAE- -BAAAAA---AAAAAB- -BAAAAA---AAAAAB- -BAAAAA---AAAAAB- -EAAAAA---AAAAAE- -BAAAAA---AAAAAB- -BAAAAA---AAAAAB- -BAAAAA---AAAAAB- -BAAAAA---AAAAAB- -EAAAAA---AAAAAE- -BAAAAA---AAAAAB- -BAAAAA---AAAAAB- -BAAAAAAAAAAAAAB- -BAAAAAAAAAAAAAB- -BAAAAAAAAAAAAAB- DDAAAAAAAAAAAAADD DCAAAAAAAAAAAAACD DDA-----------ADD CCC-----------CCC 
-BAAAAAC-CAAAAAB- -BAAAAAA-AAAAAAB- -BAAAAAA-AAAAAAB- -BAAAAAA-AAAAAAB- -BAAAAAA-AAAAAAB- -BAAAAAA-AAAAAAB- -BAAAAAA-AAAAAAB- -BAAAAAA-AAAAAAB- -BAAAAAA-AAAAAAB- -BAAAAAA-AAAAAAB- -BAAAAAA-AAAAAAB- -EAAAAAA-AAAAAAE- -BAAAAAA-AAAAAAB- -BAAAAAA-AAAAAAB- -BAAAAAA-AAAAAAB- -BAAAAAA-AAAAAAB- -BAAAAAA-AAAAAAB- -BAAAAAA-AAAAAAB- -BAAAAAA-AAAAAAB- -BAAAAAAAAAAAAAB- -BAAAAAAAAAAAAAB- -BAAAAAAAAAAAAAB- DDAAAAAAAAAAAAADD DDAAAAAAAAAAAAADD DDA-----------ADD CCC-----------CCC 
--CAAAAC-CAAAAC-- -BAAAAAA-AAAAAAB- -EAAAAAA-AAAAAAE- -EAAAAAA-AAAAAAE- -EAAAAAA-AAAAAAE- -BAAAAAA-AAAAAAB- -BAAAAAA-AAAAAAB- -BAAAAAA-AAAAAAB- -BAAAAAA-AAAAAAB- -BAAAAAA-AAAAAAB- -EAAAAAA-AAAAAAE- -BAAAAAA-AAAAAAB- -BAAAAAA-AAAAAAB- -BAAAAAA-AAAAAAB- -EAAAAAA-AAAAAAE- -EAAAAAA-AAAAAAE- -EAAAAAA-AAAAAAE- -BAAAAAA-AAAAAAB- -BAAAAAA-AAAAAAB- -EAAAAAA-AAAAAAE- -BAAAAAAAAAAAAAB- -BAAAAAAAAAAAAAB- DDAAAAAAAAAAAAADD DCAAAAAAAAAAAAACD DDA-----------ADD CCC-----------CCC 
--CAAAAC-CAAAAC-- --AAAAAA-AAAAAA-- --AAAAAA-AAAAAA-- --AAAAAA-AAAAAA-- --AAAAAA-AAAAAA-- -BAAAAAA-AAAAAAB- -EAAAAAA-AAAAAAE- -EAAAAAA-AAAAAAE- -EAAAAAA-AAAAAAE- -EAAAAAA-AAAAAAE- -BAAAAAA-AAAAAAB- -BAAAAAA-AAAAAAB- -BAAAAAA-AAAAAAB- -BAAAAAA-AAAAAAB- -BAAAAAA-AAAAAAB- -EAAAAAA-AAAAAAE- -BAAAAAA-AAAAAAB- -BAAAAAA-AAAAAAB- -BAAAAAA-AAAAAAB- -BAAAAAA-AAAAAAB- -BAAAAAAAAAAAAAB- -BAAAAAAAAAAAAAB- DDCAAAAAAAAAAACDD DCAAAAAAAAAAAAACD CCA-----------ACC --C-----------C-- 
---CAAAC-CAAAC--- ---AAAAA-AAAAA--- ---AAAAA-AAAAA--- ---AAAAA-AAAAA--- ---AAAAA-AAAAA--- ---AAAAA-AAAAA--- ---AAAAA-AAAAA--- ---AAAAA-AAAAA--- ---AAAAA-AAAAA--- -B-AAAAA-AAAAA-B- -E-AAAAA-AAAAA-E- -B-AAAAA-AAAAA-B- -B-AAAAA-AAAAA-B- -B-AAAAA-AAAAA-B- -B-AAAAA-AAAAA-B- -B-AAAAA-AAAAA-B- -B-AAAAA-AAAAA-B- -E-AAAAA-AAAAA-E- -E-AAAAA-AAAAA-E- -E-AAAAA-AAAAA-E- -B-AAAAAAAAAAA-B- DD-AAAAAAAAAAA-DD DD-AAAAAAAAAAA-DD CC-CAAAAAAAAAC-CC ---A---------A--- ---C---------C--- 
----CCC---CCC---- ----AAA---AAA---- ----AAA---AAA---- ----AAA---AAA---- ----AAA---AAA---- ----AAA---AAA---- ----AAA---AAA---- ----AAA---AAA---- ----AAA---AAA---- ----AAA---AAA---- ----AAA---AAA---- ----AAA---AAA---- ----AAA---AAA---- -E--AAA---AAA--E- -E--AAA---AAA--E- -E--AAA---AAA--E- -B--AAA---AAA--B- -B--AAA---AAA--B- -B--AAA---AAA--B- -B--AAA---AAA--B- DD--AAAACAAAA--DD DD--AAACAAAAA--DD CC--AAACAAAAA--CC ----AAACAAAAA---- ----CAACAAAAC---- ----CCCCCCCCC---- 
----------------- ----------------- ----------------- ----------------- ----------------- ----------------- ----------------- ----------------- ----------------- ----------------- ----------------- ----------------- ----------------- ----------------- ----------------- ----------------- ----------------- DD-------------DD DD-------------DD DD-------------DD DC-------------CD CC-------------CC ----------------- ----------------- ----------------- ----------------- 
