model
size = 21 26 11, scale = 0.05, origin = -y
material 
  colors = A:#AAA B:#FC6 C:#555 D:#C60 E:#C00 F:#930
voxels
--------------------- --------------------- --------------------- --------------------- --------------------- --------------------- --------------------- --------------------- --------------------- --------------------- --------------------- --------------------- --------------------- --------------------- --------------------- --------------------- --------------------- D-------------------D D-------------------D DD-----------------DD DDD---------------DDD FDDDDD---------DDDDDF -FFDDDDDDDDDDDDDDDFF- ---FFDDDDDDDDDDDFF--- -----FFFDDDDDFFF----- --------FFFFF-------- 
---------BBB--------- --------EBBBB-------- --------BBBBE-------- -------BBBBEEE------- -------BEBBBEE------- ------BBBBBBBBB------ ------BBBBBBBBE------ -----BEBEBBBBEEE----- -----BBBBEBBBEEE----- ----EEBBBBBBBBEEB---- ----EEBBBEBBEBBBE---- ---BBBBBEEEBBBBBBB--- ---BBBBBBEBBBBBEBB--- --EEBBBBBBBBBBBBBEE-- --EEBBEBBBBBEEBBBEE-- -EEBBEEEBBBEEEEBBBEE- -BBBEEEEEBBBEEBBBBBB- DBBBBEEEBBBBBBBBEBBBD DBBBBBEBBBBEBBBEEEBBD DDBBBBBBBBBEEBBBEBBDD FDDBBBBBBBBBBBBBBBDDF FDDDDDBBBBBBBBBDDDDDF -FFDDDDDDDDDDDDDDDFF- ---FFFFFFFDFFFFFFF--- -----FFFDDDDDFFF----- --------FFFFF-------- 
---CCCCCCAAACCCCCC--- ---AAAAAAAAAAAAAAA--- ---AAAAAAAAAAAAAAA--- ---AAAAAAAAAAAAAAA--- ---AAAAAAAAAAAAAAA--- ---AAAAAAAAAAAAAAA--- ---AAAAAAAAAAAAAAA--- --AAAAAAAAAAAAAAAAA-- --AAAAAAAAAAAAAAAAA-- -AAAAAAAAAAAAAAAAAAA- AAAAAAAAAAAAAAAAAAAAA CAAAAAAAAAAAAAAAAAAAC CAAAAAAAAAAAAAAAAAAAC CAAAAAAAAAAAAAAAAAAAC CAAAAAAAAAAAAAAAAAAAC CAAAAAAAAAAAAAAAAAAAC CAAAAAAAAAAAAAAAAAAAC CAAAAAAAAAAAAAAAAAAAC CAAAAAAAAAAAAAAAAAAAC AAAAAAAAAAAAAAAAAAAAA AAAAAAAAAAAAAAAAAAAAA AAAAAAAAAAAAAAAAAAAAA -AAAAAAAAAAAAAAAAAAA- ---AAAAAAAAAAAAAAA--- -----AAAAAAAAAAA----- ------CCCCCCCCC------ 
---CAAA-------AAAC--- ---AAAA-------AAAA--- ---AAAA-------AAAA--- ---AAAA-------AAAA--- ---AAAA-------AAAA--- ---AAAA-------AAAA--- ---A-------------A--- --A---------------A-- --A---------------A-- -AA---------------AA- CAA---------------AAC --------------------- --------------------- --------------------- --------------------- --------------------- --------------------- --------------------- --------------------- CAAAAAA-------AAAAAAC AAAAAAA-------AAAAAAA AAAAAAA-------AAAAAAA -AAAAAA-------AAAAAA- ---AAAA-------AAAA--- -----AA-------AA----- ------C-------C------ 
---CAAA-------AAAC--- ---AAAA-------AAAA--- ---AAAA-------AAAA--- ---AAAA-------AAAA--- ---AAAA-------AAAA--- ---AAAA-------AAAA--- ---A-------------A--- --A---------------A-- --A---------------A-- -AA---------------AA- CAA---------------AAC --------------------- --------------------- --------------------- --------------------- --------------------- --------------------- --------------------- --------------------- --------------------- CAAAAAA-------AAAAAAC AAAAAAA-------AAAAAAA -AAAAAA-------AAAAAA- ---AAAA-------AAAA--- -----AA-------AA----- ------C-------C------ 
---CAAA-------AAAC--- ---AAAA-------AAAA--- ---AAAA-------AAAA--- ---AAAA-------AAAA--- ---AAAA-------AAAA--- ---AAAA-------AAAA--- ---A-------------A--- --A---------------A-- --A---------------A-- -AA---------------AA- CAA---------------AAC --------------------- --------------------- --------------------- --------------------- --------------------- --------------------- --------------------- --------------------- --------------------- CAAAAAA-------AAAAAAC AAAAAAA-------AAAAAAA -AAAAAA-------AAAAAA- ---AAAA-------AAAA--- -----AA-------AA----- ------C-------C------ 
---CAAA-------AAAC--- ---AAAA-------AAAA--- ---AAAA-------AAAA--- ---AAAA-------AAAA--- ---AAAA-------AAAA--- ---AAAA-------AAAA--- ---A-------------A--- --A---------------A-- --A---------------A-- -AA---------------AA- CAA---------------AAC --------------------- --------------------- --------------------- --------------------- --------------------- --------------------- --------------------- --------------------- --------------------- CAAAAAA-------AAAAAAC AAAAAAA-------AAAAAAA -AAAAAA-------AAAAAA- ---AAAA-------AAAA--- -----AA-------AA----- ------C-------C------ 
---CAAA-------AAAC--- ---AAAA-------AAAA--- ---AAAA-------AAAA--- ---AAAA-------AAAA--- ---AAAA-------AAAA--- ---AAAA-------AAAA--- ---A-------------A--- --A---------------A-- --A---------------A-- -AA---------------AA- CAA---------------AAC --------------------- --------------------- --------------------- --------------------- --------------------- --------------------- --------------------- --------------------- --------------------- CAAAAAA-------AAAAAAC AAAAAAA-------AAAAAAA -AAAAAA-------AAAAAA- ---AAAA-------AAAA--- -----AA-------AA----- ------C-------C------ 
---CAAA-------AAAC--- ---AAAA-------AAAA--- ---AAAA-------AAAA--- ---AAAA-------AAAA--- ---AAAA-------AAAA--- ---AAAA-------AAAA--- ---A-------------A--- --A---------------A-- --A---------------A-- -AA---------------AA- CAA---------------AAC --------------------- --------------------- --------------------- --------------------- --------------------- --------------------- --------------------- --------------------- --------------------- CAAAAAA-------AAAAAAC AAAAAAA-------AAAAAAA -AAAAAA-------AAAAAA- ---AAAA-------AAAA--- -----AA-------AA----- ------C-------C------ 
---CAAA-------AAAC--- ---AAAA-------AAAA--- ---AAAA-------AAAA--- ---AAAA-------AAAA--- ---AAAA-------AAAA--- ---AAAA-------AAAA--- ---A-------------A--- --A---------------A-- --A---------------A-- -AA---------------AA- CAA---------------AAC --------------------- --------------------- --------------------- --------------------- --------------------- --------------------- --------------------- --------------------- CAAAAAA-------AAAAAAC AAAAAAA-------AAAAAAA AAAAAAA-------AAAAAAA -AAAAAA-------AAAAAA- ---AAAA-------AAAA--- -----AA-------AA----- ------C-------C------ 
---CCCCCCCCCCCCCCC--- ---AAAAAAAAAAAAAAA--- ---AAAAAAAAAAAAAAA--- ---AAAAAAAAAAAAAAA--- ---AAAAAAAAAAAAAAA--- ---AAAAAAAAAAAAAAA--- ---AAAAAAAAAAAAAAA--- --AAAAAAAAAAAAAAAAA-- --AAAAAAAAAAAAAAAAA-- -AAAAAAAAAAAAAAAAAAA- AAAAAAAAAAAAAAAAAAAAA CAAAAAAAAAAAAAAAAAAAC CAAAAAAAAAAAAAAAAAAAC CAAAAAAAAAAAAAAAAAAAC CAAAAAAAAAAAAAAAAAAAC CAAAAAAAAAAAAAAAAAAAC CAAAAAAAAAAAAAAAAAAAC CAAAAAAAAAAAAAAAAAAAC CAAAAAAAAAAAAAAAAAAAC AAAAAAAAAAAAAAAAAAAAA AAAAAAAAAAAAAAAAAAAAA AAAAAAAAAAAAAAAAAAAAA -AAAAAAAAAAAAAAAAAAA- ---AAAAAAAAAAAAAAA--- -----AAAAAAAAAAA----- ------CCCCCCCCC------ 
