model
size = 21 14 26, scale = 0.05, origin = -y
material 
  colors = A:#930 B:#FC6 C:#C60 D:#C00 E:#600
voxels
--------------------- --------------------- --------------------- --------------------- --------------------- --------------------- --------------------- --------------------- --------------------- --------------------- --------------------- --------------------- ---------BBB--------- --------------------- 
--------------------- --------------------- --------------------- --------------------- --------------------- --------------------- --------------------- --------------------- --------------------- --------------------- --------------------- --------------------- --------DBBBB-------- --------------------- 
--------------------- --------------------- --------------------- --------------------- --------------------- --------------------- --------------------- --------------------- --------------------- --------------------- --------------------- --------------------- --------BBBBD-------- --------------------- 
--------------------- --------------------- --------------------- --------------------- --------------------- --------------------- --------------------- --------------------- --------------------- --------------------- --------------------- --------------------- -------BBBBDDD------- --------------------- 
--------------------- --------------------- --------------------- --------------------- --------------------- --------------------- --------------------- --------------------- --------------------- --------------------- --------------------- --------------------- -------BDBBBDD------- --------------------- 
--------------------- --------------------- --------------------- --------------------- --------------------- --------------------- --------------------- --------------------- --------------------- --------------------- --------------------- --------------------- ------BBBBBBBBB------ --------------------- 
--------------------- --------------------- --------------------- --------------------- --------------------- --------------------- --------------------- --------------------- --------------------- --------------------- --------------------- --------------------- ------BBBBBBBBD------ --------------------- 
--------------------- --------------------- --------------------- --------------------- --------------------- --------------------- --------------------- --------------------- --------------------- --------------------- --------------------- --------------------- -----BDBDBBBBDDD----- --------------------- 
--------------------- --------------------- --------------------- --------------------- --------------------- --------------------- --------------------- --------------------- --------------------- --------------------- --------------------- --------------------- -----BBBBDBBBDDD----- --------------------- 
--------------------- --------------------- --------------------- --------------------- --------------------- --------------------- --------------------- --------------------- --------------------- --------------------- --------------------- --------------------- ----DDBBBBBBBBDDB---- --------------------- 
--------------------- --------------------- --------------------- --------------------- --------------------- --------------------- --------------------- --------------------- --------------------- --------------------- --------------------- --------------------- ----DDBBBDBBDBBBD---- --------------------- 
--------------------- --------------------- ------E-------E------ ------A-------A------ ------A-------A------ ------A-------A------ ------A-------A------ ------A-------A------ ------AE-----EA------ ------AAE---EAA------ ------AAAEEEAAA------ ------AAAAAAAAA------ ---BBBBBDDDBBBBBBB--- --------------------- 
-----E---------E----- -----A---------A----- -----A---------A----- -----A---------A----- -----A---------A----- -----A---------A----- -----A---------A----- -----A---------A----- -----A---------A----- -----A---------A----- -----A---------A----- -----AAAAAAAAAAA----- ---BBBBBBDBBBBBDBB--- --------------------- 
--------------------- --------------------- ----E-----------E---- ----A-----------A---- ----A-----------A---- ----A-----------A---- ----A-----------A---- ----A-----------A---- ----A-----------A---- ----A-----------A---- ----A-----------A---- ----AAAAAAAAAAAAA---- --DDBBBBBBBBBBBBBDD-- --------------------- 
--------------------- --------------------- --------------------- --------------------- ---E-------------E--- ---A-------------A--- ---A-------------A--- ---A-------------A--- ---A-------------A--- ---A-------------A--- ---A-------------A--- ---AAAAAAAAAAAAAAA--- --DDBBDBBBBBDDBBBDD-- --------------------- 
--------------------- --------------------- --------------------- --------------------- --------------------- --------------------- --------------------- ---A-------------A--- ---A-------------A--- ---A-------------A--- ---A-------------A--- ---AAAAAAAAAAAAAAA--- -DDBBDDDBBBDDDDBBBDD- --------------------- 
--------------------- --------------------- --------------------- --------------------- --------------------- --------------------- --------------------- --------------------- ---E-------------E--- ---A-------------A--- ---A-------------A--- ---AAAAAAAAAAAAAAA--- -BBBDDDDDBBBDDBBBBBB- --------------------- 
--------------------- --------------------- --------------------- --------------------- --------------------- --------------------- --------------------- --------------------- ---E-------------E--- ---A-------------A--- ---A-------------A--- ---AAAAAAAAAAAAAAA--- CBBBBDDDBBBBBBBBDBBBC C-------------------C 
--------------------- --------------------- --------------------- --------------------- --------------------- --------------------- --------------------- ---A-------------A--- ---A-------------A--- ---A-------------A--- ---A-------------A--- ---AAAAAAAAAAAAAAA--- CBBBBBDBBBBDBBBDDDBBC C-------------------C 
--------------------- --------------------- --------------------- --------------------- ---E-------------E--- ---A-------------A--- ---A-------------A--- ---A-------------A--- ---A-------------A--- ---A-------------A--- ---A-------------A--- ---AAAAAAAAAAAAAAA--- CCBBBBBBBBBDDBBBDBBCC CC-----------------CC 
--------------------- --------------------- --------------------- ----E-----------E---- ----A-----------A---- ----A-----------A---- ----A-----------A---- ----A-----------A---- ----A-----------A---- ----A-----------A---- ----A-----------A---- ----AAAAAAAAAAAAA---- ACCBBBBBBBBBBBBBBBCCA CCC---------------CCC 
--------------------- --------------------- -----E---------E----- -----A---------A----- -----A---------A----- -----A---------A----- -----A---------A----- -----A---------A----- -----A---------A----- -----A---------A----- -----A---------A----- -----AAAAAAAAAAA----- ACCCCCBBBBBBBBBCCCCCA ACCCCC---------CCCCCA 
--------------------- ------EAA---AAE------ ------AAA---AAA------ ------AAA---AAA------ ------AAA---AAA------ ------AAA---AAA------ ------AAA---AAA------ ------AAA---AAA------ ------AAA---AAA------ ------AAA---AAA------ ------AAA---AAA------ ------AAAAAAAAA------ -AACCCCCCCCCCCCCCCAA- -AACCCCCCCCCCCCCCCAA- 
----------E---------- ---------AAA--------- ---------AAA--------- ---------AAA--------- ---------AAA--------- ---------AAA--------- ---------AAA--------- ---------AAA--------- ---------AAA--------- ---------AAA--------- ---------AAA--------- ---------AAA--------- ---AAAAAAACAAAAAAA--- ---AACCCCCCCCCCCAA--- 
--------------------- --------------------- --------------------- --------------------- --------------------- --------------------- --------------------- --------------------- --------------------- --------------------- --------------------- --------------------- -----AAAAACAAAAA----- -----AAACCCCCAAA----- 
--------------------- --------------------- --------------------- --------------------- --------------------- --------------------- --------------------- --------------------- --------------------- --------------------- --------------------- --------------------- --------AAAAA-------- --------AAAAA-------- 
