model
size = 10 32 11, scale = 0.05, origin = -y
material 
  colors = A:#E00 B:#03C C:#FC0 D:#00E E:#EEE F:#888 G:#444 H:#00F I:#111
voxels
254-2(2F8-)2F308-2(2F8-)2F155-G-G2-G-G145-2F8-2F16-I4-I143-G-G2-G-G14-4A5-6A4-6A3-5(8A2-)8A3-2(6A4-)6A5-4A6-4A4-2E4A2E2-3E2A2(3E2-)3E133-4(G4-)6A4-6A2-C5(8A2C)8AC-2(8A2-)8A3-6A5-3(4A6-)4A7-2A126-G4-G24-6A4-6A2-D8ADC6(8A2C)8AC-8A3-6A5-3(4A6-)4A7-2A156-6A2-D-6A-2(2D8A)DC4(8A2C)8AC-8A2-8A3-6A5-3(4A6-)4A163-D2-4A2-2(2D-6A-)2D8ADC3(8A2C)8AC-8A2-8A3-6A5-4A6-4A115-AB2-BA4-AB2-BA3-4(A2B2-2BA2-)A2B2A2BA2-A2B2A2BA-D2(A2B2A2BA2D)-2B2A2B-2D2-B2AB2-2D3-2A3-DC8-2C8-C133-H2-H6-B2-B5-AB2-BA4-AB2-BA5-B2-B7-5(2A8-)2A14-D3(8-2D)8-D134-8(2A8-)2A234-
