model
size = 16 12 17, scale = 0.05, origin = -y
material 
  colors = A:#EEE B:#630
voxels
---------------- ---------------- ---------------- ---------------- ---------------- ---------------- ---------------- ---------------- ------------A--- ---------------- ---------------- ---------------- 
---------------- ---------------- ---------------- ---------------- ---------------- ---------------- ---------------- ---------------- ------------A--- ---------------- ---------------- ---------------- 
---------------- ---------------- ---------------- ---------------- ---------------- ---------------- ---------------- ---------------- ------------AA-- ---------------- ---------------- A--------------- 
---------------- ---------------- ---------------- ---------------- ---------------- ---------------- ---------------- ---------------- -------------A-- ---------------- AA-------------- A--------------- 
---------------- ---------------- ---------------- ---------------- ---------------- ---------------- ---------------- -------------A-- -------------A-- ---------------- -A-------------- ---------------- 
---------------- ---------------- ---------------- ---------------- ---------------- ---------------- ---------------- ------------AAA- --------------A- --------------A- -AA-----------AA ---------------A 
---------------- ---------------- ---------------- ---------------- ---------------- ---------------- ------------A--- ------------A--- ---------------- --A------------- --A------------- ---------------- 
---------------- ---------------- ---------------- ---------------- ---------------- ---------------- ------------A--- ---------------- ---------------- --A------------- ---------------- ---------------- 
---------------- ---------------- ---------------- ---------------- ---------------- ------------A--- ------------A--- ---------------- --AA------------ --A------------- ---------------- ---------------- 
---------------- ---------------- ---------------- -----------A---- -----------A---- -----------AA--- ----A----------- ---AA----------- ---A------------ ---------------- ---------------- ---------------- 
---------------- ---------------- ---------------- -----A-----A---- -----A---------- ----AA---------- -AAAA----------- -A-------------- ---------------- ---------------- ---------------- ---------------- 
---------------- ---------------- ---------------- -----AA---AA---- ---------------- ---------------- ---------------- ---------------- ---------------- ---------------- ---------------- ---------------- 
---------------- ---------------- ------A---A----- ------A---A----- ---------------- ---------------- ---------------- ---------------- ---------------- ---------------- ---------------- ---------------- 
---------------- ---------------- ------AA-AA----- ---------------- ---------------- ---------------- ---------------- ---------------- ---------------- ---------------- ---------------- ---------------- 
---------------- ---------------- -------A-A------ ---------------- ---------------- ---------------- ---------------- ---------------- ---------------- ---------------- ---------------- ---------------- 
---------------- ---------------- -------A-A------ ---------------- ---------------- ---------------- ---------------- ---------------- ---------------- ---------------- ---------------- ---------------- 
-------BBB------ -------BBB------ -------BBB------ ---------------- ---------------- ---------------- ---------------- ---------------- ---------------- ---------------- ---------------- ---------------- 
