model
size = 18 31 15, scale = 0.05, origin = -y
material 
  colors = A:#111 B:#444 C:#FC0 D:#C66
voxels
-----------AA----- -----------AA----- ----------AAA----- ----------AAA----- ----------AA------ ---------AAA------ --------AAA------- --------AA-------- --------AA-------- ------------------ ------------------ ------------------ ------------------ ------------------ ------------------ ------------------ ------------------ ------------------ ------------------ ------------------ ------------------ ------------------ ------------------ ------------------ ------------------ ------------------ ------------------ ------------------ ------------------ ------------------ ------------------ 
-----------AA----- -----------AA----- ----------AAA----- ----------AAA----- ----------AA------ ---------AAA------ --------AAA------- --------AA-------- --------AA-------- --------AA-------- ------------------ ------------------ ------------------ ------------------ ------------------ ------------------ ------------------ ------------------ ------------------ ------------------ ------------------ ------------------ ------------------ ------------------ ------------------ ------------------ ------------------ ------------------ ------------------ ------------------ ------------------ 
------------------ ------------------ ------------------ ------------------ ------------------ ------------------ ------------------ ------------------ --------AA-------- --------AA-------- ------------------ ------------------ ------------------ ------------------ ------------------ ------------------ ------------------ ------------------ ------------------ ------------------ ------------------ ------------------ ------------------ ------------------ ------------------ ------------------ ------------------ ------------------ ------------------ ------------------ ------------------ 
------------------ ------------------ ------------------ ------------------ ------------------ ------------------ ------------------ ------------------ --------AA-------- --------AA-------- ------------------ ------------------ ------------------ ------------------ ------------------ ------------------ ------------------ ------------------ ------------------ ------------------ ------------------ ------------------ ------------------ ------------------ ------------------ ------------------ ------------------ ------------------ ------------------ ------------------ ------------------ 
------------------ ------------------ ------------------ ------------------ ------------------ ------------------ ------------------ ------------------ ------AAAAAA------ ------AAAAAA------ ------AAAAAA------ ------AAAAAA------ ------------------ ------------------ ------------------ ------------------ ------------------ ------------------ ------------------ ------------------ ------------------ ------------------ ------------------ ------------------ ------------------ ------------------ ------------------ ------------------ ------------------ ------------------ ------------------ 
------------------ ------------------ ------------------ ------------------ ------------------ ------------------ ------------------ ------------------ ------AAAAAA------ ------AAAAAA------ -----AAAAAAAA----- -----AAAAAAAA----- -----AAAAAAAA----- -----AAAAAAAA----- ------------------ ------------------ ------------------ ------------------ ------------------ ------------------ ------------------ ------------------ ------------------ ------------------ ------------------ ------------------ ------------------ ------------------ ------------------ ------------------ ------------------ 
------------------ ------------------ ------------------ ------------------ ------------------ ------------------ ------------------ ------------------ -----AAAAAAAA----- ----AAAAAAAAAA---- ----AAAAAAAAAA---- ----AAAAAAAAAA---- ----AAAAAAAAAA---- -----AAAAAAAA----- -----AAAAAAAA----- ------AAAAAA------ ------AAAAAA------ -------AAAA------- ------------------ ------------------ ------------------ ------------------ ------------------ ------------------ ------------------ ------------------ ------------------ ------------------ ------------------ ------------------ ------------------ 
------------------ ------------------ ------------------ ------------------ ------------------ ------------------ ------------------ ------------------ ----AAAAAAAAAA---- ----AAAAAAAAAA---- ----AAAAAAAAAA---- ----AAAAAAAAAA---- ----AAAAAAAAAA---- ----AAAAAAAAAA---- -----AAAAAAAA----- -----AAAAAAAA----- -----AAAAAAAA----- ------AAAAAA------ ------------------ ------------------ ------------------ ------------------ ------------------ ------------------ ------------------ ------------------ ------------------ ------------------ ------------------ ------------------ ------------------ 
------------------ ------------------ ------------------ ------------------ ------------------ ------------------ ------------------ ------------------ ----AAAAAAAAAA---- ----AAAAAAAAAA---- -----AAAAAAAA----- ----AAAAAAAAAA---- ----AAAAAAAAAA---- ----AAAAAAAAAA---- -----AAAAAAAA----- -----AAAAAAAA----- -----AAAAAAAA----- -----AAAAAAAA----- -----AAAAAAAA----- ------AAAAAA------ -------AAAA------- -------AAAA------- ------------------ -------AAAA------- ------AAAAAA------ ------AAAAAA------ ------AAAAAA------ ------------------ ------------------ ------------------ ------------------ 
------------------ ------------------ ------------------ ------------------ ------------------ ------------------ ------------------ ------------------ ----AAAAAAAAAA---- -----AAAAAAAA----- -----AAAAAAAA----- -----AAAAAAAA----- -----AAAAAAAA----- -----AAAAAAAA----- -----AAAAAAAA----- -----AAAAAAAA----- -----AAAAAAAA----- -----AAAAAAAA----- -----AAAAAAAA----- -----AAAAAAAA----- -----AAAAAAAA----- ------AAAAAA------ ------AAAAAA------ ------AAAAAA------ ------AAAAAA------ ------AAAAAA------ ------AAAAAA------ ------AAAAAA------ ------A----A------ ------------------ ------------------ 
------------------ ------------------ ------------------ ------------------ ------------------ ------------------ ------------------ ------------------ ----AA------AA---- ------------------ ------------------ ------------------ ------------------ ------------------ ------------------ ------------------ -----AAAAAAAA----- -----AAAAAAAA----- -----AAAAAAAA----- -----AAAAAAAA----- -----AAAAAAAA----- -----AAAAAAAA----- ------AAAAAA------ ------AAAAAA------ ------AAAAAA------ ------AAAAAA------ ------AAAAAA------ -----AAAAAAAA----- -----AA----AA----- -----AA----AA----- ------A----A------ 
------------------ ------------------ ------------------ ------------------ ------------------ ------------------ ------------------ ------------------ -----AA----AA----- -----AA----AA----- -----AA----AA----- -----AA----AA----- -----AA----AA----- -----AA----AA----- -----AA----AA----- -----AA----AA----- -----AA----AA----- -----AAAAAAAA----- -----AAAAAAAA----- -----AAAAAAAA----- -----AAAAAAAA----- -----AAAAAAAA----- ------AAAAAA------ ------AAAAAA------ ------AAAAAA------ ------AAAAAA------ ------AAAAAA------ ------AAAAAA------ ------------------ ------------------ ------------------ 
------------------ ------------------ ------------------ ------------------ ------------------ ------------------ ------------------ ------------------ -----AA----AA----- -----AA----AA----- -----AA----AA----- -----AA----AA----- -----AA----AA----- -----AA----AA----- -----AA----AA----- -----AA----AA----- -----AA----AA----- -----AAAAAAAA----- -----AAAAAAAA----- ------AAAAAA------ ------AAAAAA------ -------AAAA------- ------------------ ------AAAAAA------ ------AAAAAA------ ------AAAAAA------ -----CCCAACCC----- -----C-CAAC-C----- -----CCC--CCC----- ------------------ ------------------ 
------------------ ------------------ ------------------ ------------------ ------------------ ------------------ ------------------ ------------------ -----AA----AA----- ------------------ ------------------ ------------------ ------------------ ------------------ ------------------ ------------------ ------------------ ------------------ ------------------ ------------------ ------------------ ------------------ ------------------ ------AAAAAA------ ------AAAAAA------ BBBBBBAAAAAABBBBBB --------AA-------- ------A-AA-A------ ------------------ ------------------ ------------------ 
------------------ ------------------ ------------------ ------------------ ------------------ ------------------ ------------------ ------------------ -----AA----AA----- ------------------ ------------------ ------------------ ------------------ ------------------ ------------------ ------------------ ------------------ ------------------ ------------------ ------------------ ------------------ ------------------ ------------------ -BBBBBBAAAABBBBBB- -------AAAA------- --------DD-------- --------DD-------- ------------------ ------------------ ------------------ ------------------ 
