model
size = 3 29 18, scale = 0.05, origin = -y
material 
  colors = A:#EEE B:#6FC C:#E00 D:#FF0 E:#06F F:#9CF G:#3F6 H:#306 I:#636 J:#9F0 K:#F0C L:#F6C M:#F30 N:#C96 O:#C3C
voxels
--- --- --- --- --- --- --- --- --- --- --- --- --- --- --- --- --- -B- -B- -B- -C- -D- -E- --- --- --- --- --- --- 
--- --- --- --- --- --- --- --- --- --- --- --- --- --- --- -B- -B- -K- -K- -C- -D- -E- -G- -H- -B- --- --- --- --- 
--- --- --- --- --- --- --- --- --- --- --- --- --- --- -B- -K- -K- -O- -C- -D- -E- -G- -H- -L- -L- -B- --- --- --- 
--- --- --- --- --- --- --- --- --- --- --- --- --- -B- -K- -K- -O- -C- -D- -E- -G- -H- -I- -I- -I- -L- -B- --- --- 
--- --- --- --- --- --- --- --- --- --- --- --- -B- -K- -K- -O- -C- -D- -E- -G- -H- -C- -I- -I- -I- -I- -L- -B- --- 
--- --- --- --- --- --- --- --- --- --- --- --- -B- -K- -O- -C- -D- -E- -G- -H- -C- -D- -C- -I- -I- -I- -L- -B- --- 
--- --- --- --- --- --- --- --- --- --- --- -B- -K- -O- -C- -D- -E- -G- -H- -C- -D- -E- -D- -C- -I- -I- -I- -L- -B- 
-A- -A- -A- -A- -A- -A- -A- -A- -A- -A- -A- -B- -K- -C- -D- -E- -G- -H- -C- -D- -E- -G- -E- -D- -C- -I- -I- -L- -B- 
AFA AFA AFA AFA AFA AFA AFA AFA AFA AFA AFA AFA -C- -D- -E- -G- -H- -C- -D- -E- -G- -H- -G- -E- -D- -C- -I- -L- -B- 
AFA AFA AFA AFA AFA AFA AFA AFA AFA AFA AFA AFA -C- -D- -E- -G- -H- -M- -C- -D- -C- -M- -H- -G- -E- -D- -C- -L- -B- 
-A- -A- -A- -A- -A- -A- -A- -A- -A- -A- -A- -B- -J- -C- -D- -E- -G- -H- -M- -C- -M- -M- -M- -H- -G- -E- -D- -C- -B- 
--- --- --- --- --- --- --- --- --- --- --- -B- -J- -J- -C- -D- -E- -G- -H- -M- -M- -M- -H- -G- -E- -D- -C- -B- -B- 
--- --- --- --- --- --- --- --- --- --- --- --- -B- -J- -J- -C- -D- -E- -G- -H- -H- -H- -G- -E- -D- -C- -N- -B- --- 
--- --- --- --- --- --- --- --- --- --- --- --- -B- -J- -J- -J- -C- -D- -E- -G- -G- -G- -E- -D- -C- -N- -N- -B- --- 
--- --- --- --- --- --- --- --- --- --- --- --- --- -B- -J- -J- -J- -C- -D- -E- -E- -E- -D- -C- -N- -N- -B- --- --- 
--- --- --- --- --- --- --- --- --- --- --- --- --- --- -B- -J- -J- -J- -C- -D- -D- -D- -C- -N- -N- -B- --- --- --- 
--- --- --- --- --- --- --- --- --- --- --- --- --- --- --- -B- -B- -J- -J- -C- -C- -C- -N- -B- -B- --- --- --- --- 
--- --- --- --- --- --- --- --- --- --- --- --- --- --- --- --- --- -B- -B- -B- -B- -B- -B- --- --- --- --- --- --- 
