model
size = 32 32 23, scale = 0.05, origin = -y
material 
  colors = A:#9CF B:#0E0 C:#090 D:#EEE E:#AAA F:#DDD G:#39F H:#111 I:#888 J:#777 K:#002 L:#0D0 M:#222 N:#3C9 O:#0C9 P:#3F6
voxels
527-B95-B31-B63-B31-NL126-LO62-2L2(30-2I)511-B63-N63-P158-L63-L95-2L2(30-2I)1022-2I17-2(28C4-)BCF20EHEFCB4-2BF20EHEFBC4-2BF7EH14EF2B4-2BF7EHE2H3EH5EHEF2B4-2BFE3H3(EH)2E2(HE)H3EHEF2B4-2BFEM3EMH2E2HE2HMEM3EHEF2B4-2BFEM3E2(HE)H2E5(HE)F2B4-2BF2(E3H)E2HE3HE2H2MHEF2B4-2BF22EF2B4-2BF5EH6EHE2H6EF2B4-2BFEM4(EH)2EHE2H6EF2B4-2BFEKEHEKHKEHE2H2(EH)5EF2B4-2BFEH2KEKJKE2H3(EH)5EF2B4-2BFEHEKE3KEHEIHE2H6EF2B4-2BFEH8EI3EH7EF2B4-2BF2E17F3BF2B4-2A2F2E3FE11F2IJ2F2A4-3AF3E13F4IF3A6-2A3F2EF6I2F3I4FA8-G4A4F5I5F5A12-4A6F6A19-7A-2A250-2I17-28C4-C2(26AB4-B)26AC14(4-B26AB)4-28A4-D27A6-24A8-G23A10-20A14-A-G11A-A247-2I17-28C4-C2(26AB4-B)26AC14(4-B26AB)2(4-28A)5-26A6-AG24A8-22A13-2AG13A247-2I16-30C2-C28AC2-B28AB2-C28AC2(2-C28AB2-B28AB)10(2-B28AB)2(2-30A)4-26A6-G25A7-2G22A11-3AG13AG20-2(6D26-)5DE26-6D124-2I16-30C2-C28AC2-B28AB2-B28AC2(2-C28AB2-B28AB)9(2-B28AB)2-29AB2-D29A2-30A3-28A4-AG25AG6-AG22A10-4AG14AG18-E7D24-8D24-E6DE24-8D123-2I16-30C2(2-C28AC2-B28AB)2-C11(28AB2-B)28AB3(2-30A)3-28A4-27AG5-GAG23A9-3AG15AG18-E7D24-8D24-7DE24-8D26-4I93-2I16-30C2-C28AC2-B28AB2-B28AC2-B28AB2-C11(28AB2-B)28AB3(2-30A)3-28A4-D26AG5-2AG20AD2A9-AEAG13AGAD17-E9D22-10D22-E8DE22-10D24-6I28-2(2I30-)2H15-33C30A2C2(30ACB)2(30ABC)10(30A2B)30AB31A2D63A2-D27A4-D26AG5-DAG20AD2A9-AEAG13ADAG17-10D22-9DE22-E8DE22-10D24-6I28-2(2I30-)2H15-32CB30ABC30A2B30ACB30ABC11(30A2B)30AB31ABD63A2-D27A4-27AG5-DG22ADA9-E2AG13ADAG17-10D2(22-E8DE)22-10D24-6I28-2(2I30-)2H15-32CB30ABC30A2B30ACB30A2B30ABC10(30A2B)30AB31ABD61ADA2-D26AG4-28A5-AG22ADA9-3AG15AG17-10D22-E8DE22-E9D22-10D25-4I110-32CB30ABC2(30ACB)30A2B30ABC10(30A2B)30AB32AD62AG2-D26AG4-28A5-AG23AD9-3AG15AG18-8D2(24-E6DE)24-8D140-32CB30ABC30A2C30ACB30A2B30ABC10(30A2B)30AB95AG2-27AG4-26ADA6-G23A10-2AG13AD2AG18-2(8D24-)7DE24-8D140-32CB30ABC30A2C13(30A2B)30AB63AD31AG2-27AG4-28A6-24A11-AG15AG20-3D2ED26-D2E3D26-6E26-6D142-30C2-C28AC15(2-B28AB)2(2-30A)2-29AG3-28A4-28A7-22A12-AGAD11AG2A264-30C2-C28AC2-B28AB2-C13(28AB2-B)28AB2(2-30A)2-D27ADG4-25AD6-25AG8-22A13-G2AD9AD2A265-30C2-B28AC2(2-C28AB)2-B28AB2-C11(28AB2-B)28AB2(2-30A)2-D28AG4-25AD6-23A2GA9-20A14-3AD2A3D3AD3A265-30C2-B28AB2(2-C28AC)2-B28AB2-C11(28AB2-B)28AB2(2-30A)2-AD27AD4-25AD6-26A9-19AG14-5A8G3A266-28C4-C26AB4-B26AB4-C26AC13(4-B26AB)2(4-28A)4-D27A6-D23A8-3D21A11-D2AD13AG297-28C4-C26AB4-B26AB4-C26AB4-B26AC12(4-B26AB)3(4-28A)7-22A10-21AD12-16A2G297-28C4-13C11BCB2C4-2BC4B3C3B11C3BC4-CBC13B8C2BCB4-3B3C2B8C12B4-28B4-18BJ9B4-17BJ10B4-8B4JB3J2B2J8B4-4B2J4B3J2BJ2B3J7B4-19BJBJ6B4-9B2JB5J4BJ6B4-5BJ22B4-4BJ2B2J4B3J2B2J8B4-20B2J6B4-2(4BJ)B4J2BJ3BJ6B4-6B3J13BJ5B4-10A2J5A2J2AJ6A4-2AG7A2JA2J13A4-A2G4AJA2J6A3J3A5D8-11AD8A12-AG2AG3AGADG4AD2AD14-2G3AG4-3GADA296-
