model
size = 32 23 8, scale = 0.05, origin = -y
material 
  colors = A:#200 B:#FBBBFF C:#111 D:#400 E:#C69 F:#100
voxels
333-3B29-3B30-2B509-A127-3B28-5B27-5B28-3B30-B31-B310-4A28-5A11-3A13-A3CA-CA4-4AC2A14-2A2C-2C4-4C5A11-2AC-4C2A-2C2FC2A19-3C2A2CFCF3A22-C-AC60-4B2(27-5B)28-4B28-2(3B29-)2B30-2B246-D-2A-A8-3A14-2D-3A-A9-C4A10-6A-CA4-8A-2A8-2C3AC-2A4-6AD2A-A9-3ACA2(C4A-2A)-A9-4A-C12A21-C8A28-3A24-2(BE)3B25-7B25-6B27-2(4B28-)3(3B29-)3B30-B181-D6A8-4A12-7A-2A6-8A8-7A-2A2-9A2-DA5-2A2-4AC-2A2-A-6AD2A-2A4-2A2-5AC12A2(-2A)3-3A2-A-AC-D12A9-2A5-A3-C-8A11-A10-A-A3-4A22-2BEB2E2B2(24-8B)25-6B27-3(4B28-)2(3B29-)3B30-2B30-B86-5A11-5A10-D4A-A8-5A-3A8-6A2-2A5-9A6-8A-10A2D7A3-8AC-11AD7A2-10AC8A2D10A-3A4-AC-13A4-4A-3A4-3A-8A-A8-4A7-3A2-A-6A9-3A9-2B2E2BE3B11-3A8-10B10-2A11-9B23-8B25-5B27-2B-2B2(28-4B)28-3(3B29-)3B30-B54-5A11-5A9-8A7-10A6-8A2C2A4-11A4-21AD7A2-10AC11AD7A2-20AD10A-5A3-AC10AD2A3D-8A5-A-C8A-A2D6-5A8-9A2-A9-2A9-B-8B11-A10-B-8B22-B-8B23-8B25-2(6B26-)2B-2B28-B-2B3(28-4B)28-3B29-3B30-B85-2A11-2A17-3A6-A-2A4-4A12-2A-4A-A-2A-7A15-7A-3A-A-DA18-7A-3A2D2A19-2A2(-A)2-A-A20-7A24-2(10B22-)10B23-8B25-3(6B26-)5B4(28-4B)28-3B30-2B16-
