model
size = 28 26 28, scale = 0.05, origin = -y
material 
  colors = A:#111 B:#222 C:#444 D:#555 E:#777 F:#888 G:#AAA H:#FCFAF2 I:#BBB J:#DDD K:#EEE L:#FFFFFB M:#BDC0BA
voxels
--A----------------------A-- ---------------------------- ---------------------------- ---------------------------- ---------------------------- ---------------------------- ---------------------------- ---------------------------- ---------------------------- ---------------------------- ---------------------------- ---------------------------- ---------------------------- ---------------------------- ---------------------------- ---------------------------- ---------------------------- ---------------------------- ---------------------------- ---------------------------- ---------------------------- ---------------------------- ---------------------------- ---------------------------- ---------------------------- ---------------------------- 
-AAA--------------------AAA- --B----------------------B-- --C----------------------C-- ---------------------------- ---------------------------- ---------------------------- ---------------------------- ---------------------------- ---------------------------- ---------------------------- ---------------------------- ---------------------------- ---------------------------- ---------------------------- ---------------------------- ---------------------------- ---------------------------- ---------------------------- ---------------------------- ---------------------------- ---------------------------- ---------------------------- ---------------------------- ---------------------------- ---------------------------- ---------------------------- 
-AAA---AA----AA----AA---AAA- -BBB---B------------B---BBB- -CCC---C------------C---CCC- --D----------------------D-- --E----------------------E-- ---------------------------- ---------------------------- ---------------------------- ---------------------------- ---------------------------- ---------------------------- ---------------------------- ---------------------------- ---------------------------- ---------------------------- ---------------------------- ---------------------------- ---------------------------- ---------------------------- ---------------------------- ---------------------------- ---------------------------- ---------------------------- ---------------------------- ---------------------------- ---------------------------- 
-AAA---AAA--AAAA--AAA---AAA- -BBB---BB----AB----BB---BBB- -CCC---CC----AB----CC---CCC- -DDD---D------------D---DDD- -EEE--------------------EEE- --F----------------------F-- ---------------------------- ---------------------------- ---------------------------- ---------------------------- ---------------------------- ---------------------------- ---------------------------- ---------------------------- ---------------------------- ---------------------------- ---------------------------- ---------------------------- ---------------------------- ---------------------------- ---------------------------- ---------------------------- ---------------------------- ---------------------------- ---------------------------- ---------------------------- 
-AAAA--AAAA-AAAA-AAAA--AAAA- --BB----BB--BABB--BB----BB-- --CC----CC--BABC--CC----CC-- ---D----D----AB----D----D--- ---E---------AB---------E--- ---F--------------------F--- ---G--------------------G--- ---------------------------- ---------------------------- ---------------------------- ---------------------------- ---------------------------- ---------------------------- ---------------------------- ---------------------------- ---------------------------- ---------------------------- ---------------------------- ---------------------------- ---------------------------- ---------------------------- ---------------------------- ---------------------------- ---------------------------- ---------------------------- ---------------------------- 
--AAAA---AAAAAAAAAA---AAAA-- --BBB----BBBBABBBBB----BBB-- --CCC----CCCBABCCCC----CCC-- --DD-----DD-BABC-DD-----DD-- --EE-----ED-BABC-EE-----EE-- ---F------D--AB--E------F--- ---G------D--AB--E------G--- ---------------------------- ---------------------------- ---------------------------- ---------------------------- ---------------------------- ---------------------------- ---------------------------- ---------------------------- ---------------------------- ---------------------------- ---------------------------- ---------------------------- ---------------------------- ---------------------------- ---------------------------- ---------------------------- ---------------------------- ---------------------------- ---------------------------- 
AAAAAAAAAAAAAAAAAAAAAAAAAAAA -BBBBBB-BBBBBABBBBBB-BBBBBB- -CCCCCC-CCCCBABCCCCC-CCCCCC- --DDDD---DDCBABCDDD---DDDD-- --EEEE---EDCBABCDEE---EEEE-- --FF-F---EDCBABCDEF---F-FF-- --GG-G---EDCBABCDEF---G-GG-- ---I--------BABC--------I--- ------------BABC------------ ---------------------------- ---------------------------- ---------------------------- ---------------------------- ---------------------------- ---------------------------- ---------------------------- ---------------------------- ---------------------------- ---------------------------- ---------------------------- ---------------------------- ---------------------------- ---------------------------- ---------------------------- ---------------------------- ---------------------------- 
AAAAA------------------AAAAA -BBBBBBBBBBBBABBBBBBBBBBBBB- -CCCCCCCCCCCBABCCCCCCCCCCCC- -DDDDDD-DDDCBABCDDDD-DDDDDD- -EEEEEE-FEDCBABCDEEE-EEEEEE- ---FFF---EDCBABCDEF---FFF--- ---GGG---EDCBABCDEF---GGG--- ----II----DCBABCDE----II---- ----------DCBABCDE---------- -----------CB--CD----------- -----------CB--CH----------- ---------------------------- ---------------------------- ---------------------------- ---------------------------- ---------------------------- ---------------------------- ---------------------------- ---------------------------- ---------------------------- ---------------------------- ---------------------------- ---------------------------- ---------------------------- ---------------------------- ---------------------------- 
---AA------------------AA--- ----BB----------------BB---- ----CCCCCCCCBABCCCCCCCCC---- -----D-DDDDCBABCDDDDD-D----- -----E-EFEDCBABCDEEEE-E----- -----F--FEDCBABCDEFF--F----- -----G--FEDCBABCDEFG--G----- -----I---EDCBABCDEF---I----- ---------EDCBABCDEJ--------- ----------DCBABCDK---------- ----------HCBABCHH---------- -------------AB------------- -------------AM------------- -------------AA------------- ---------------------------- ---------------------------- ---------------------------- ---------------------------- ---------------------------- ---------------------------- ---------------------------- ---------------------------- ---------------------------- ---------------------------- ---------------------------- ---------------------------- 
---AA------------------AA--- ----BB----------------BB---- ----CCC--------------CCC---- ----DDD--------------DDD---- ----EEE--------------EEE---- -----F-FFEDCBABCDEFFF-F----- -----G-GFEDCBABCDEFGG-G----- -----I--FEDCBABCDEFG--I----- --------JEDCBABCDEJJ-------- ---------KDCBABCDKK--------- ---------HHCBABCHHH--------- -----------LBABLL----------- -----------MMAMMM----------- -----------AAAAAA----------- -------------AB------------- -------------AB------------- ---------------------------- ---------------------------- ---------------------------- ---------------------------- ---------------------------- ---------------------------- ---------------------------- ---------------------------- ---------------------------- ---------------------------- 
-AAAA------------------AAAA- --BBBB----------------BBBB-- --CCCCC--------------CCCCC-- --DDDDD--------------DDDDD-- --EEEEE--------------EEEEE-- ---FFFFF------------FFFFF--- ---GGGGG------------GGGGG--- ----III-FEDCBABCDEFG-III---- ------J-JEDCBABCDEJJ-J------ --------KKDCBABCDKKK-------- --------HHHCBABCHHHH-------- ----------LLBABLLL---------- ----------MMMAMMMM---------- ----------AAAAAAAA---------- ------------BABC------------ ------------BABC------------ -------------AB------------- -------------AB------------- -------------AG------------- ------------FF-------------- -----------EE--------------- ---------------------------- ---------------------------- ---------------------------- ---------------------------- ---------------------------- 
-AAAA------------------AAAA- --BBBB----------------BBBB-- --CCCCC--------------CCCCC-- ---DDDD--------------DDDD--- ---EEEE--------------EEEE--- ----FF-F------------F-FF---- ----GG-G------------G-GG---- -------IFEDCBABCDEFGI------- -------JJEDCBABCDEJJJ------- ---------KDCBABCDKK--------- ---------HHCBABCHHH--------- ---------LLLBABLLLL--------- ---------MMMMAMMMMM--------- ---------AAAAAAAAAA--------- -----------EBABCD----------- -----------CBABCD----------- ------------BABC------------ ------------BABI------------ ------------GAGG------------ -----------FFFF------------- ----------EEEE-------------- -----------DD--------------- ---------------------------- ---------------------------- ---------------------------- ---------------------------- 
---AA------------------AA--- ----BB----------------BB---- ----CCC--------------CCC---- -----DD--------------DD----- -----EE--------------EE----- ------FF------------FF------ ------GG------------GG------ --------FEDCBABCDEFG-------- --------JEDCBABCDEJJ-------- --------KKDCBABCDKKK-------- --------HHHCBABCHHHH-------- ---------LLLBABLLLL--------- ---------CCCCCCCCCC--------- ---------AAAAAAAAAA--------- -----------EBABCE----------- -----------CBABCD----------- -----------CBABCJ----------- -----------IBABII----------- -----------GGAGGG----------- ----------FFFFFF------------ ---------EEEEEE------------- ----------DDDD-------------- -----------CC--------------- ---------------------------- ---------------------------- ---------------------------- 
----A------------------A---- -----B----------------B----- -----CC--------------CC----- ------D--------------D------ ------E--------------E------ -------F------------F------- -------G------------G------- -------IFEDCBABCDEFGI------- -------JJEDCBABCDEJJJ------- ---------KDCBABCDKK--------- ---------HHCBABCHHH--------- ---------BBBBBBBBBB--------- ---------BBBBBBBBBB--------- ---------AAAAAAAAAA--------- ----------EEBABCDE---------- ----------DCBABCDK---------- -----------CBABCJ----------- -----------IBABII----------- -----------GGAGGG----------- ----------FFFFFF------------ ---------EEEEEE------------- ---------DDDDD-------------- ----------CCCC-------------- ----------BB---------------- ---------------------------- ---------------------------- 
----A------------------A---- -----B----------------B----- -----CC--------------CC----- ------D--------------D------ ------E--------------E------ -------F------------F------- -------G------------G------- -------IFEDCBABCDEFGI------- -------JJEDCBABCDEJJJ------- ---------KDCBABCDKK--------- ---------AAAAAAAAAA--------- ---------AAAAAAAAAA--------- ---------AAAAAAAAAA--------- ---------AAAAAAAAAA--------- ----------EEBABCDE---------- ----------DCBABCDK---------- -----------CBABCJ----------- -----------IBABII----------- -----------GGAGGG----------- ----------FFFFFF------------ ---------EEEEEE------------- ---------DDDDD-------------- ---------CCCCC-------------- ---------BBB---------------- ---------AA----------------- ---------A------------------ 
---AA------------------AA--- ----BB----------------BB---- ----CCC--------------CCC---- -----DD--------------DD----- -----EE--------------EE----- ------FF------------FF------ ------GG------------GG------ --------FEDCBABCDEFG-------- --------JEDCBABCDEJJ-------- --------KKDCBABCDKKK-------- --------HHHCBABCHHHH-------- ---------BBBBBBBBBB--------- ---------BBBBBBBBBB--------- ---------AAAAAAAAAA--------- -----------EBABCE----------- -----------CBABCD----------- -----------CBABCJ----------- -----------IBABII----------- -----------GGAGGG----------- ----------FFFFFF------------ ---------EEEEEE------------- ----------DDDD-------------- -----------CC--------------- ---------------------------- ---------------------------- ---------------------------- 
-AAAA------------------AAAA- --BBBB----------------BBBB-- --CCCCC--------------CCCCC-- ---DDDD--------------DDDD--- ---EEEE--------------EEEE--- ----FF-F------------F-FF---- ----GG-G------------G-GG---- -------IFEDCBABCDEFGI------- -------JJEDCBABCDEJJJ------- ---------KDCBABCDKK--------- ---------HHCBABCHHH--------- ---------LLLBABLLLL--------- ---------CCCCCCCCCC--------- ---------AAAAAAAAAA--------- -----------CBABCD----------- -----------CBABCD----------- ------------BABC------------ ------------BABI------------ ------------GAGG------------ -----------FFFF------------- ----------EEEE-------------- -----------DD--------------- ---------------------------- ---------------------------- ---------------------------- ---------------------------- 
-AAAA------------------AAAA- --BBBB----------------BBBB-- --CCCCC--------------CCCCC-- --DDDDD--------------DDDDD-- --EEEEE--------------EEEEE-- ---FFFFF------------FFFFF--- ---GGGGG------------GGGGG--- ----III-FEDCBABCDEFG-III---- ------J-JEDCBABCDEJJ-J------ --------KKDCBABCDKKK-------- --------HHHCBABCHHHH-------- ----------LLBABLLL---------- ----------MMMAMMMM---------- ----------AAAAAAAA---------- ------------BABC------------ ------------BABC------------ -------------AB------------- -------------AB------------- -------------AG------------- ------------FF-------------- -----------EE--------------- ---------------------------- ---------------------------- ---------------------------- ---------------------------- ---------------------------- 
---AA------------------AA--- ----BB----------------BB---- ----CCC--------------CCC---- ----DDD--------------DDD---- ----EEE--------------EEE---- -----F-FFEDCBABCDEFFF-F----- -----G-GFEDCBABCDEFGG-G----- -----I--FEDCBABCDEFG--I----- --------JEDCBABCDEJJ-------- ---------KDCBABCDKK--------- ---------HHCBABCHHH--------- -----------LBABLL----------- -----------MMAMMM----------- -----------AAAAAA----------- -------------AB------------- -------------AB------------- ---------------------------- ---------------------------- ---------------------------- ---------------------------- ---------------------------- ---------------------------- ---------------------------- ---------------------------- ---------------------------- ---------------------------- 
---AA------------------AA--- ----BB----------------BB---- ----CCCCCCCCBABCCCCCCCCC---- -----D-DDDDCBABCDDDDD-D----- -----E-EFEDCBABCDEEEE-E----- -----F--FEDCBABCDEFF--F----- -----G--FEDCBABCDEFG--G----- -----I---EDCBABCDEF---I----- ---------EDCBABCDEJ--------- ----------DCBABCDK---------- ----------HCBABCHH---------- -------------AB------------- -------------AM------------- -------------AA------------- ---------------------------- ---------------------------- ---------------------------- ---------------------------- ---------------------------- ---------------------------- ---------------------------- ---------------------------- ---------------------------- ---------------------------- ---------------------------- ---------------------------- 
AAAAA------------------AAAAA -BBBBBBBBBBBBABBBBBBBBBBBBB- -CCCCCCCCCCCBABCCCCCCCCCCCC- -DDDDDD-DDDCBABCDDDD-DDDDDD- -EEEEEE-FEDCBABCDEEE-EEEEEE- ---FFF---EDCBABCDEF---FFF--- ---GGG---EDCBABCDEF---GGG--- ----II----DCBABCDE----II---- ----------DCBABCDE---------- -----------CB--CD----------- -----------CB--CH----------- ---------------------------- ---------------------------- ---------------------------- ---------------------------- ---------------------------- ---------------------------- ---------------------------- ---------------------------- ---------------------------- ---------------------------- ---------------------------- ---------------------------- ---------------------------- ---------------------------- ---------------------------- 
AAAAAAAAAAAAAAAAAAAAAAAAAAAA -BBBBBB-BBBBBABBBBBB-BBBBBB- -CCCCCC-CCCCBABCCCCC-CCCCCC- --DDDD---DDCBABCDDD---DDDD-- --EEEE---EDCBABCDEE---EEEE-- --FF-F---EDCBABCDEF---F-FF-- --GG-G---EDCBABCDEF---G-GG-- ---I--------BABC--------I--- ------------BABC------------ ---------------------------- ---------------------------- ---------------------------- ---------------------------- ---------------------------- ---------------------------- ---------------------------- ---------------------------- ---------------------------- ---------------------------- ---------------------------- ---------------------------- ---------------------------- ---------------------------- ---------------------------- ---------------------------- ---------------------------- 
--AAAA---AAAAAAAAAA---AAAA-- --BBB----BBBBABBBBB----BBB-- --CCC----CCCBABCCCC----CCC-- --DD-----DD-BABC-DD-----DD-- --EE-----ED-BABC-EE-----EE-- ---F------D--AB--E------F--- ---G------D--AB--E------G--- ---------------------------- ---------------------------- ---------------------------- ---------------------------- ---------------------------- ---------------------------- ---------------------------- ---------------------------- ---------------------------- ---------------------------- ---------------------------- ---------------------------- ---------------------------- ---------------------------- ---------------------------- ---------------------------- ---------------------------- ---------------------------- ---------------------------- 
-AAAA--AAAA-AAAA-AAAA--AAAA- --BB----BB--BABB--BB----BB-- --CC----CC--BABC--CC----CC-- ---D----D----AB----D----D--- ---E---------AB---------E--- ---F--------------------F--- ---G--------------------G--- ---------------------------- ---------------------------- ---------------------------- ---------------------------- ---------------------------- ---------------------------- ---------------------------- ---------------------------- ---------------------------- ---------------------------- ---------------------------- ---------------------------- ---------------------------- ---------------------------- ---------------------------- ---------------------------- ---------------------------- ---------------------------- ---------------------------- 
-AAA---AAA--AAAA--AAA---AAA- -BBB---BB----AB----BB---BBB- -CCC---CC----AB----CC---CCC- -DDD---D------------D---DDD- -EEE--------------------EEE- --F----------------------F-- ---------------------------- ---------------------------- ---------------------------- ---------------------------- ---------------------------- ---------------------------- ---------------------------- ---------------------------- ---------------------------- ---------------------------- ---------------------------- ---------------------------- ---------------------------- ---------------------------- ---------------------------- ---------------------------- ---------------------------- ---------------------------- ---------------------------- ---------------------------- 
-AAA---AA----AA----AA---AAA- -BBB---B------------B---BBB- -CCC---C------------C---CCC- --D----------------------D-- --E----------------------E-- ---------------------------- ---------------------------- ---------------------------- ---------------------------- ---------------------------- ---------------------------- ---------------------------- ---------------------------- ---------------------------- ---------------------------- ---------------------------- ---------------------------- ---------------------------- ---------------------------- ---------------------------- ---------------------------- ---------------------------- ---------------------------- ---------------------------- ---------------------------- ---------------------------- 
-AAA--------------------AAA- --B----------------------B-- --C----------------------C-- ---------------------------- ---------------------------- ---------------------------- ---------------------------- ---------------------------- ---------------------------- ---------------------------- ---------------------------- ---------------------------- ---------------------------- ---------------------------- ---------------------------- ---------------------------- ---------------------------- ---------------------------- ---------------------------- ---------------------------- ---------------------------- ---------------------------- ---------------------------- ---------------------------- ---------------------------- ---------------------------- 
--A----------------------A-- ---------------------------- ---------------------------- ---------------------------- ---------------------------- ---------------------------- ---------------------------- ---------------------------- ---------------------------- ---------------------------- ---------------------------- ---------------------------- ---------------------------- ---------------------------- ---------------------------- ---------------------------- ---------------------------- ---------------------------- ---------------------------- ---------------------------- ---------------------------- ---------------------------- ---------------------------- ---------------------------- ---------------------------- ---------------------------- 
