model
size = 32 30 23, scale = 0.05, origin = -y
material 
  colors = A:#111 B:#960 C:#600 D:#630 E:#930 F:#400 G:#963 H:#EEE I:#03F J:#BBB K:#3F0 L:#E00 M:#444 N:#AAA O:#93F P:#C3F Q:#FF3 R:#222 S:#555 T:#0F3
voxels
171-9A3(23-2(A3J)A)23-9A18-2(5A3(27-A3JA)27-)5A32-9A3(23-2(A3J)A)23-9A375-9A6-3A14-3(2(A3J)A23-)9A18-5A2(27-A3JA)15-3A9-A3JA27-5A3(27-A3JA)27-5A15-L-T14-9A3(23-2(A3J)A)23-9A6-3N259-33G30A2GALAIKIAL2(IK)LIALKOLAIKLA5MA2G2AOAOLIK2(AI)A2(KI)AIKAI2AM3RMA2GAKL2(IA)QIKILIOAIAKALIKIA2(MN)MA2G2A3(KA)L2(IA)LIKIL2(IA)LA2(MN)MA2GAIAOIL2(IA)LA2(KI)A3(IK)A2(MN)MA2GAKILAIKILKAPIA2(IK)3(IA)2(MN)MA2GALAIKQ2(AP)IAKIOILIAKLIKA2(MN)MA2G2A2(IA)LA2I2(LIA)QKP2(AI)A2(MN)MA2GAIKLAIKIL2(AI)KAKIAILKILAM3RMA2G2AIALAIAKIALAOILAKPAIK2A5MA2GALAIKIALIAKAOKAIPIALAIKAM3NMA2G2AIKIAIKAIPLIAKLA2(KI)LIA5MA2GAKPIAKI2(AIK)P2(IA)PIAOKAM3NMA2GAIALOILIALIKAIALKILAKI2A5MA2GALIKA2(KI)AOAILI2(KIA)LKA2(MN)MA2G2AQA2I2(AI)AL2(AI)KOIKIP2A5MA2GAIALAKLOKL2(IK)I2(LA)ILAKAM3AMA2GALQ3(AI)QAIALK2(AI)PAKIAM3AMA2G2AIKPLAIQIKLIOAKAILAIAKAM3AMA2GAOA2IAIL2(IA)LAIOLAIKLI2AM3NMA2GA2(LK)ILIALIOQIKL2(IKA)LA5MA2G30A33G160-B2C2B4D2B4E2C4E2B4D2B2CBF3(30A2F)2(30AEF)30AFD30AB3(D30AC)B30ACF30AB2(F30AE)B30AEB2(30A2E)2(30ABE)3(30A2F)30AF3C2B4D2B4E2C4E2B4D2B2CD98-2A24-2A4-2A24-2A2-2EB2F5E3C6B3C5E2FB2EB30ABC2(30A2C)30ABC30A2B30AFB30A2F30ADF2(30ADB)30AD2(C30AF)C30ABC30A2B2(30A2C)30A2B30ACB2(30ACF)30ACD30ABDEB2F5E3C6B3C5E2FBEB98-2A24-2A4-2A24-2A2-4DB5E3B6D3B5EB5D30A2D2(30ACD)3(30A2D)30AD2(F30AB)2(D30AB)D4(30A2D)2(30A2C)4(30A2D)2(30ADB)3DB5E3B6D3B5EB4D160-B6CB4D2B4E2B4DB6CBF30A2F2(30AFB)2(30ACB)30ABE3(30A2E)3(30AEB)30A2B2(30ACF)2(30A2F)2(30AFC)30A2B3(30ABE)6CB4D2B4E2B4DB6CE160-2D2E3B5FB2F2B2FB5F3B2E2DC2(30A2C)3(30ABF)3(30ACE)30ABE30AB3(F30AC)F30A2F30AFC30ABC3(30ACB)30A2C2(30AFC)30AFBD2E3B5FB2F2B2FB5F3B2EDE160-2B3C5D3BE4DE3B5D3C2BE3(30A2E)30ABE6(30ADB)4(30ADE)30ABE2(30A2E)30AEB4(30AED)30ABDB3C5D3BE4DE3B5D3C2B160-2D2B4E3B4C2B4C3B4E2B2DF30A2F4(30ABF)2(30A2C)2(30ABC)2(30ABF)2(30ACF)2(30ABF)2(30A2B)2(30AFB)2(30AFC)2(30AFB)D2B4E3B4C2B4C3B4E2BDC160-2D2F3C3B2FB6DB2F3B3C2F2DB2(30A2B)2(30A2C)30AEC30A2E30AB3(E30AD)C30ADC30ABC2(30AEB)2(30ACB)2(30ABC)2(30ABE)30ACB30ACD30AC2D2F3C3B2FB6DB2F3B3C2FDE7-3A12-3A16-A12-A18-14A73-2(2C2B3C3B3C2B)2CF30A2F30AFB2(30A2B)30AB2(E30AF)E3(30A2E)30AE2(B30AF)B30ABF4(30A2F)30AFB2(30ABF)30ABE30A2EC2B3C3B3C2B2C2B3C3B3C2BCE7-3A12-3A15-SA12-AS17-14A73-2E5D3B3C2F2B2F3C3B5D2EB30A2B30AB3(C30AD)2(F30AD)2(B30AE)2(F30AE)3(C30AD)2(B30AD)B3(30ABD)2(30ACD)30ACE30AF2E5D3B3C2F2B2F3C3B5DEF7-3A12-3A16-A12-A18-14A73-2E2F9B6E9B2F2EF30A2F30AFC2(30A2C)30ACB30A2B30ABC30A2C2(30ACB)30A2C2(30ABC)3(30ACB)3(30ABC)2(30ACB)30A2C30ABCE2F9B6E9B2FEB7-3A12-3A15-SA12-AS17-14A73-2DB2E2C4B3C4E3C4B2C2EB2DB30A2B30AB2(F30AC)B30AC2(D30AF)D3(30A2D)30ADB2(30A2F)30ACF4(30A2F)30AFC2(30A2F)30ABD30A3DB2E2C4B3C4E3C4B2C2EB2D7-3A12-3A16-A12-A18-14A73-2B2C4B6F4C6F4B2C3B30A2B30AEB3(30AEC)30ABC30A2B30ADB3(30ADC)30ABC30A2B2(30AEB)2(30A2E)2(30ABE)30A2B30ACB2(30ACD)B2C4B6F4C6F4B2CBC160-5DB7E6B7EB6D30A2D3(30ADB)30ACE2(30ACD)2(30ABD)30ABE30A2B2(30ACB)30ACD4(30A2D)30AD2(C30AB)C30A2B30AEB4DB7E6B7EB5D160-B3C3B4C3F4E3F4C3B3CBF2(30A2F)30ABF30A2B30AB2(F30AE)2(B30AD)2(F30AD)B2(30AEF)3(30ABF)3(30AFB)2(30AFE)30ABD30AFD3C3B4C3F4E3F4C3B3CF160-3EB2C4F4B4E4B4F2CB3ED30A2D30AB2(D30AC)2(B30AC)2(E30AC)E30ABE30A2B30ACB4(30ACD)30ACB30AB4(C30AD)C30ABC30A2B2EB2C4F4B4E4B4F2CB3E98-2A24-2A4-2A24-2A2-2B4D2C7D2F7D2C4D2BE30A2E3(30AEB)30ABD5(30A2D)3(30ADB)30ABE4(30A2E)30AEB3(30ABD)30A2DB4D2C7D2F7D2C4DBD98-2A24-2A4-2A24-2A2-2D2F2B2CB4C2B2F2B4CB2C2B2F2DE30A2E3(30AEC)2(30AFB)30A2B3(30AEB)30AEC30AB2(C30AF)E4(30A2E)30AE2(F30AC)B30ACE30ABED2F2B2CB4C2B2F2B4CB2C2B2FDB160-2CB5E2B3FB4DB3F2B5EB2CD30ADF3(30A2F)30AFE30ABE2(30A2C)2(30ABE)2(30ACE)2(30A2B)30ADF6(30A2F)30AFC30AEBCB5E2B3FB4DB3F2B5EBCE160-33G2(30A2G)A28H2(A2GAH26AH)A2GAH7AH3AH2A5H7AHA2GAH7A2H2AH4AH9AHA2GAH7A2(HA)H4AH9AHA2GAH7AH2A2H4AH9AHA2GAH7AH3AH2A5H7A3(HA2GAH26A)HA2GAHA4H2AH3AH2A4H4AH3AHA2GAH4AH2A2H3(2AH)4AH3AHA2GAH2A3H2A2(HA)2(H2A)H4AH3AHA2GAH4A2(H2A)2H2(2AH)4AH3AHA2GAHA4H2AH3A3(H2A)5HA2(HA2GAH26A)HA2GA28HA2(2G30A)33G96-
