model
size = 17 27 10, scale = 0.05, origin = -y
material 
  colors = A:#272727 B:#343434 C:#414141 D:#EEA9A9 E:#E83015
voxels
-----AAAAAAAAA--- -----AAAAAAAA---- -----AAAA-------- ------AAAA------- -----AAAAAA------ -----AAAAAAA----- -----AAAAAAA----- -----AAAAAA------ ------AAAA------- -------AA-------- ----------------- ----------------- ----------------- ----------------- ----------------- ----------------- ----------------- ----------------- ----------------- ----------------- ----------------- --------------B-- ----------------- ----------------- ----------------- ----------------- ----------------- 
----AAAAAAAAAA--- ----AAAAAAAAA---- ----AAAAAA------- -----AAAAAA------ ----AAAAAAAA----- ----AAAAAAAAA---- ----AAAAAAAAA---- ----AAAAAAAA----- -----AAAAAA------ ------AAAA------- -------AA-------- ----------------- ----------------- ----------------- ----------------- ----------------- ----------------- ----------------- ----------------- ----------------- ---------------C- ---------------B- -----------A----- -----------A----- -----------A----- ----------------- ----------------- 
----AAAAAA--AAAA- ----AAAAAA--AAA-- ----AAAAAA--AA--- ----AAAAAAA-AA--- ----AAAAAAAAAA--- ----AAAAAAAAAA--- ----AAAAAAAAAA--- ----AAAAAAAAAA--- -----AAAAAAAAA--- -----AAAAAAAAA--- -----AAAAAAAAA--- -----AAAAAAAAA--- ------AAAAAAAAA-- -------AAAAAAAA-- --------AAAAAAAA- ---------AAAAAA-- ---------AAA----- ---------AAAA---- ----------AAAA--- ----------AAAAA-- ----------AAAAAAC ----------AAAAAAB ----------AAAAA-- ----------AB----- -----------A----- -----------A----- ----------------- 
----AAAAAA--AAAA- ----AAAAAA--AAA-- ----AAAAAA--AA--- ----AAAAAAA-AA--- ----AAAAAAAAAA--- ----AAAAAAAAAA--- ----AAAAAAAAAA--- ----AAAAAAAAAA--- ----AAAAAAAAAA--- ----AAAAAAAAAA--- ----AAAAAAAAAA--- -----AAAAAAAAAA-- ------AAAAAAAAA-- ------AAAAAAAAAA- -------AAAAAAAAA- --------AAAAAAAA- --------AAAAAA--- --------AAAAAA--- --------AAAAAAA-- ---------AAAAAAA- ---------AAAAAAA- ----------AAAAAAA ----------AAAE--- ----------AAAAA-- ----------AAA---- -----------AA---- -----------A----- 
AAAAAAAAAA------- AAAAAAAAAA------- AA-AAAAAAA------- AA-AAAAAAAA------ AA-AAAAAAAAA----- AA-AAAAAAAAA----- AA-AAAAAAAAA----- AA-AAAAAAAAA----- AA-AAAAAAAAA----- AA--AAAAAAAAA---- AA--AAAAAAAAAA--- AA--AAAAAAAAAAA-- AA---AAAAAAAAAAA- AA----AAAAAAAAAA- AAA----AAAAAAAAB- AAAA----AAAAAAAA- -AAABA--AAAAAAA-- --AABA--AAAAAA--- --------AAAAAAA-- --------AAAAAADAA ---------AAAAAD-- ---------AAAAAAAA ----------AAAAAAB -----------AAAA-- ----------------- ----------------- ----------------- 
AAAAAAAAAA------- AAAAAAAAAA------- AA-AAAAAAA------- AA-AAAAAAAA------ AA-AAAAAAAAA----- AA-AAAAAAAAA----- AA-AAAAAAAAA----- AA-AAAAAAAAA----- AA-AAAAAAAAA----- AA--AAAAAAAAA---- AA--AAAAAAAAAA--- AA--AAAAAAAAAAA-- AA---AAAAAAAAAAA- AA----AAAAAAAAAA- AAA----AAAAAAAAB- AAAA----AAAAAAAA- -AAABA--AAAAAAA-- --AABA--AAAAAA--- --------AAAAAAA-- --------AAAAAADAA ---------AAAAAD-- ---------AAAAAAAA ----------AAAAAAB -----------AAAA-- ----------------- ----------------- ----------------- 
----AAAAAA--AAAA- ----AAAAAA--AAA-- ----AAAAAA--AA--- ----AAAAAAA-AA--- ----AAAAAAAAAA--- ----AAAAAAAAAA--- ----AAAAAAAAAA--- ----AAAAAAAAAA--- ----AAAAAAAAAA--- ----AAAAAAAAAA--- ----AAAAAAAAAA--- -----AAAAAAAAAA-- ------AAAAAAAAA-- ------AAAAAAAAAA- -------AAAAAAAAA- --------AAAAAAAA- --------AAAAAA--- --------AAAAAA--- --------AAAAAAA-- ---------AAAAAAA- ---------AAAAAAA- ----------AAAAAAA ----------AAAE--- ----------AAAAA-- ----------AAA---- -----------AA---- -----------A----- 
----AAAAAA--AAAA- ----AAAAAA--AAA-- ----AAAAAA--AA--- ----AAAAAAA-AA--- ----AAAAAAAAAA--- ----AAAAAAAAAA--- ----AAAAAAAAAA--- ----AAAAAAAAAA--- -----AAAAAAAAA--- -----AAAAAAAAA--- -----AAAAAAAAA--- -----AAAAAAAAA--- ------AAAAAAAAA-- -------AAAAAAAA-- --------AAAAAAAA- ---------AAAAAA-- ---------AAA----- ---------AAAA---- ----------AAAA--- ----------AAAAA-- ----------AAAAAAC ----------AAAAAAB ----------AAAAA-- ----------AB----- -----------A----- -----------A----- ----------------- 
----AAAAAAAAAA--- ----AAAAAAAAA---- ----AAAAAA------- -----AAAAAA------ ----AAAAAAAA----- ----AAAAAAAAA---- ----AAAAAAAAA---- ----AAAAAAAA----- -----AAAAAA------ ------AAAA------- -------AA-------- ----------------- ----------------- ----------------- ----------------- ----------------- ----------------- ----------------- ----------------- ----------------- ---------------C- ---------------B- -----------A----- -----------A----- -----------A----- ----------------- ----------------- 
-----AAAAAAAAA--- -----AAAAAAAA---- -----AAAA-------- ------AAAA------- -----AAAAAA------ -----AAAAAAA----- -----AAAAAAA----- -----AAAAAA------ ------AAAA------- -------AA-------- ----------------- ----------------- ----------------- ----------------- ----------------- ----------------- ----------------- ----------------- ----------------- ----------------- ----------------- --------------B-- ----------------- ----------------- ----------------- ----------------- ----------------- 
