model
size = 19 24 10, scale = 0.05, origin = -y
material 
  colors = A:#5B4230 B:#8F5A3C C:#E87A90 D:#F9BF45 E:#111
voxels
------AAAAAAAAA---- ------AAAAAAAA----- ------AAAA--------- -------AAAA-------- ------AAAAAA------- ------AAAAAAA------ ------AAAAAAA------ ------AAAAAA------- -------AAAA-------- --------AA--------- ------------------- ------------------- ------------------- ------------------- ------------------- ------------------- ------------------- ------------------- ------------------- ------------------- ------------------- ------------------- ------------------- ------------------- 
-----AAAAAAAAAA---- -----AAAAAAAAA----- -----AAAAAA-------- -----AAAAAAA------- -----AAAAAAAA------ -----AAAAAAAA------ -----AAAAAAAA------ -----AAAAAAAA------ -------AAAAA------- -------AAAA-------- ------------------- ------------------- ------------------- ------------------- ------------------- ------------------- ------------------- ------------------- -------------A----- ------------AA----- ------------AA----- ------------AA----- ------------AA----- ------------------- 
-----AAAAAA--AAAA-- -----AAAAAA--AAA--- -----AAAAAA--AA---- -----AAAAAAA-AA---- -----AAAAAAAAAA---- -----AAAAAAAAAA---- -----AAAAAAAAAA---- -----AAAAAAAAAA---- ------AAAAAAAAA---- ------AAAAAAAAA---- ------AAAAAAAAA---- ------AAAAAAAAA---- -------AAAAAAAAA--- --------AAAAAAAAA-- ---------AAAAAAAA-- ----------AAAAAA--- ------------------- ------------A------ -----------AA------ -----------AAAAAA-- -----------AAAAAA-- -----------AAAAA--- ------------AAA---- -------------AA---- 
----AAAAAAA--AAAA-- ----AAAAAAA--AAA--- ----AAAAAAA--AA---- ----AAAAAAAA-AA---- ----AAAAAAAAAAA---- ----AAAAAAAAAAA---- -----AAAAAAAAAA---- -----AAAAAAAAAA---- -----AAAAAAAAAA---- -----AAAAAAAAAA---- -----AAAAAAAAAA---- ------AAAAAAAAAA--- ------AAAAAAAAAAA-- -------AAAAAAAAAB-- --------AAAAAAAAB-- --------AAAAAAAAA-- ---------AAAAAA---- ---------AAAAAAA--- ---------AAAAAAAA-- ----------AAAAACA-- ----------AAAAAAAA- -----------AAAAAA-- -----------AAAD---- ------------AAAA--- 
-AAAAAAAAAA-------- AAAAAAAAAAA-------- AA--AAAAAAA-------- ----AAAAAAAA------- ----AAAAAAAAA------ ----AAAAAAAAA------ -----AAAAAAAA------ -----AAAAAAAA------ -----AAAAAAAA------ -----AAAAAAAAA----- -----AAAAAAAAAA---- ------AAAAAAAAAA--- ------AAAAAAAAAAB-- -------AAAAAAAAAB-- -------AAAAAAAAAB-- --------AAAAAAAAB-- --------AAAAAAA---- --------AAAAAAAA--- ---------AAAAAACAA- ---------AAAAAC---- ----------AAAAAAAAA ----------AAAAAAAAE -----------AAAAA--- ------------AAAA--- 
-AAAAAAAAAA-------- AAAAAAAAAAA-------- AA--AAAAAAA-------- ----AAAAAAAA------- ----AAAAAAAAA------ ----AAAAAAAAA------ -----AAAAAAAA------ -----AAAAAAAA------ -----AAAAAAAA------ -----AAAAAAAAA----- -----AAAAAAAAAA---- ------AAAAAAAAAA--- ------AAAAAAAAAAB-- -------AAAAAAAAAB-- -------AAAAAAAAAB-- --------AAAAAAAAB-- --------AAAAAAA---- --------AAAAAAAA--- ---------AAAAAACAA- ---------AAAAAC---- ----------AAAAAAAAA ----------AAAAAAAAE -----------AAAAA--- ------------AAAA--- 
----AAAAAAA--AAAA-- ----AAAAAAA--AAA--- ----AAAAAAA--AA---- ----AAAAAAAA-AA---- ----AAAAAAAAAAA---- ----AAAAAAAAAAA---- -----AAAAAAAAAA---- -----AAAAAAAAAA---- -----AAAAAAAAAA---- -----AAAAAAAAAA---- -----AAAAAAAAAA---- ------AAAAAAAAAA--- ------AAAAAAAAAAA-- -------AAAAAAAAAB-- --------AAAAAAAAB-- --------AAAAAAAAA-- ---------AAAAAA---- ---------AAAAAAA--- ---------AAAAAAAC-- ----------AAAAACC-- ----------AAAAAAAA- -----------AAAAAA-- -----------AAAD---- ------------AAAA--- 
-----AAAAAA--AAAA-- -----AAAAAA--AAA--- -----AAAAAA--AA---- -----AAAAAAA-AA---- -----AAAAAAAAAA---- -----AAAAAAAAAA---- -----AAAAAAAAAA---- -----AAAAAAAAAA---- ------AAAAAAAAA---- ------AAAAAAAAA---- ------AAAAAAAAA---- ------AAAAAAAAA---- -------AAAAAAAAA--- --------AAAAAAAAA-- ---------AAAAAAAA-- ----------AAAAAA--- ------------------- ------------A------ -----------AA------ -----------AAAAAA-- -----------AAAAAA-- -----------AAAAA--- ------------AAA---- -------------AA---- 
-----AAAAAAAAAA---- -----AAAAAAAAA----- -----AAAAAA-------- -----AAAAAAA------- -----AAAAAAAA------ -----AAAAAAAA------ -----AAAAAAAA------ -----AAAAAAAA------ -------AAAAA------- -------AAAA-------- ------------------- ------------------- ------------------- ------------------- ------------------- ------------------- ------------------- ------------------- -------------A----- ------------AA----- ------------AA----- ------------AA----- ------------AA----- ------------------- 
------AAAAAAAAA---- ------AAAAAAAA----- ------AAAA--------- -------AAAA-------- ------AAAAAA------- ------AAAAAAA------ ------AAAAAAA------ ------AAAAAA------- -------AAAA-------- --------AA--------- ------------------- ------------------- ------------------- ------------------- ------------------- ------------------- ------------------- ------------------- ------------------- ------------------- ------------------- ------------------- ------------------- ------------------- 
