model
size = 31 13 12, scale = 0.05, origin = -y
material 
  colors = A:#FFF B:#000 C:#BDBDBD D:#DEDEDE E:#838383 F:#CDCDCD G:#414141 H:#F6F6F6 I:#E6E6E6 J:#A4A4A4 K:#9C9C9C
voxels
--AAAAAAAAA--------AAAAAAAAA--- --AAAAAAAAA--------AAAAAAAAA--- --AAAAAAAAA--------CCC--------- --CCCCCCCCC-------------------- ------------------------------- ------------------------------- ------------------------------- ------------------------------- ------------------------------- ------------------------------- ------------------------------- ------------------------------- ------------------------------- 
-AAADAADAAAAAAAAAAADAADAADAAA-- -A---------AAAAAAAA---------A-- -A---------AAAAAAAA---CCCCCCC-- -A--------ACCCCCCCCAAAAAAFAAI-- -AAAAAAABB---------AAAAAFAAA--- --AAAAAA------------AAAAFA----- --AAAAA-------------AAAF------- --EAE----------------A--------- --BB--------------------------- ------------------------------- ------------------------------- ------------------------------- ------------------------------- 
AADAADAADAADAADAADAADAADAADAAA- A----------------------------A- A----------------------------C- -A---------------CC---------A-- -A--------ACBBACBBA---------A-- -A------CBBACBBACBBA------AA--- -A-----AACBBACBBACBB---AAA----- -B---BBBAACBBACBBACBB-A-------- --B-BBBA---CBBACBBACBA--------- --BBGKA-----CBBACBBA----------- ---GA--------CAA--------------- ------------------------------- ------------------------------- 
AAADAADAADAADAADAADAADAADAADAAA A-----------------------------A A-----------------------------C A----------------------------A- A----------------------------A- -A-------------------------AA-- -G----------A-----------AAA---- -B---------------------E------- -B-------------------EE-------- --B----------------EE---------- --B-----------AAAEE------------ ---GA----------AE-------------- ------------------------------- 
ADAADAADAADAADAADAADAADAADAADAA A-----------------------------A A-----------------------------C A-----------------------------I A----------------------------F- A---------------------------AF- -B----------------------EAAA--- -B---------------------A------- -H--------------------A-------- --B-----------------AA--------- --H---------------BA----------- ---B------------BA------------- ----A---------KA--------------- 
AAADAADAADAADAADAADAADAADAADAAA A-----------------------------A A-----------------------------C A-----------------------------A A----------------------------A- A---------------------------FA- -B----------------------FIFF--- -H---------------------A------- -B--------------------J-------- --B-----------------JA--------- --B---------------AB----------- ---B------------AB------------- ----A---------AB--------------- 
AADAADAADAADAADAADAADAADAADAADA A-----------------------------A A-----------------------------C A-----------------------------A A----------------------------A- A---------------------------FA- -B----------------------FIFF--- -H---------------------A------- -B--------------------J-------- --B-----------------JA--------- --B---------------AB----------- ---B------------AB------------- ----A---------AB--------------- 
ADAADAADAADAADAADAADAADAADAADAA A-----------------------------A A-----------------------------C A-----------------------------I A----------------------------F- A---------------------------AF- -B----------------------EAAA--- -B---------------------A------- -H--------------------A-------- --B-----------------AA--------- --H---------------BA----------- ---B------------BA------------- ----A---------KA--------------- 
AADAADAADAADAADAADAADAADAADAADA A-----------------------------A A-----------------------------C A----------------------------A- A----------------------------A- -A-------------------------AA-- -G----------A-----------AAA---- -B---------------------E------- -B-------------------EE-------- --B----------------EE---------- --B-----------AAAEE------------ ---GA----------AE-------------- ------------------------------- 
AAADAADAADAADAADAADAADAADAADAA- A----------------------------A- A----------------------------C- -A---------------CC---------A-- -A--------ACBBACBBA---------A-- -A------CBBACBBACBBA------AA--- -A-----AACBBACBBACBB---AAA----- -B---BBBAACBBACBBACBB-A-------- --B-BBBA---CBBACBBACBA--------- --BBGKA-----CBBACBBA----------- ---GA--------CAA--------------- ------------------------------- ------------------------------- 
-AAADAADAADAAAAAAAADAADAADAAA-- -A---------AAAAAAAA---------A-- -A---------AAAAAAAA---CCCCCCC-- -A--------ACCCCCCCCAAAAAAFAAI-- -AAAAAAABB---------AAAAAFAAA--- --AAAAAA------------AAAAFA----- --AAAAA-------------AAAF------- --EAE----------------A--------- --BB--------------------------- ------------------------------- ------------------------------- ------------------------------- ------------------------------- 
--AAAAAAAAA--------AAAAAAAAA--- --AAAAAAAAA--------AAAAAAAAA--- --AAAAAAAAA--------CCC--------- --CCCCCCCCC-------------------- ------------------------------- ------------------------------- ------------------------------- ------------------------------- ------------------------------- ------------------------------- ------------------------------- ------------------------------- ------------------------------- 
