model
size = 25 25 19, scale = 0.05, origin = -y
material 
  colors = A:#03F B:#111 C:#96F D:#96C E:#C6F F:#F9F G:#66F H:#36F I:#008 J:#00C K:#30C L:#93F M:#60F N:#009 O:#00A P:#93C Q:#90C R:#99F S:#C9F T:#00B U:#309 V:#63F W:#66C
voxels
---------BBBBBBB--------- -------BB-------BB------- -----BB-----------BB----- ----B---------------B---- ---B-----------------B--- --B-------------------B-- --B-------------------B-- -B---------------------B- -B---------------------B- B-----------------------B B-----------------------B B-----------------------B B-----------------------B B-----------------------B B-----------------------B B-----------------------B -B---------------------B- -B---------------------B- --B-------------------B-- --B-------------------B-- ---B-----------------B--- ----B---------------B---- -----BB-----------BB----- -------BB-------BB------- ---------BBBBBBB--------- 
---------AAAAAAA--------- -------AA-------AA------- -----AA-----------AA----- ----A---------------A---- ---A-----------------A--- --A-------------------A-- --A-------------------A-- -A---------------------A- -A---------------------A- A-----------------------A A-----------------------A A-----------------------A A-----------------------A A-----------------------A A-----------------------A A-----------------------A -A---------------------A- -A---------------------A- --A-------------------A-- --A-------------------A-- ---AA----------------A--- ----A---------------A---- -----AA-----------AA----- -------AA-------AA------- ---------AAAAAAA--------- 
---------AAAAAAA--------- -------AA-------AA------- -----AA-----------AA----- ----A---------------A---- ---A-----------------A--- --A-------------------A-- --A-------------------A-- -A---------------------A- -A---------------------A- A-----------------------A A-----------------------A A-----------------------A A-----------------------A A-----------------------A A-----------------------A A-----------------------A -A---------------------A- -A---------------------A- --A-------------------A-- --A-------------------A-- ---AA----------------A--- ----A---------------A---- -----AA-----------AA----- -------AA-------AA------- ---------AAAAAAA--------- 
---------AAAAAAA--------- -------AA-------AA------- -----AA-----------AA----- ----A---------------A---- ---A-----------------A--- --A-------------------A-- --A-------------------A-- -A---------------------A- -A---------------------A- A-----------------------A A-----------------------A A-----------------------A A-----------------------A A-----------------------A A-----------------------A A-----------------------A -A---------------------A- -A---------------------A- --A-------------------A-- --A-------------------A-- ---AA----------------A--- ----A---------------A---- -----AA-----------AA----- -------AA-------AA------- ---------AAAAAAA--------- 
---------AAAAAAA--------- -------AA-------AA------- -----AA-----------AA----- ----A---------------A---- ---A-----------------A--- --A-------------------A-- --A-------------------A-- -A---------------------A- -A---------------------A- A-----------------------A C-----------------------D C-----------------------D C-----------------------D C-----------------------C C-----------------------C C-----------------------D -C---------------------D- -A---------------------A- --A-------------------A-- --A-------------------A-- ---AA----------------A--- ----A---------------A---- -----AA-----------AA----- -------AD-------AA------- ---------DCCDDDA--------- 
---------AAAAAAA--------- -------AA-------AA------- -----AA-----------AA----- ----A---------------A---- ---A-----------------A--- --A-------------------A-- --A-------------------A-- -A---------------------A- -A---------------------A- A-----------------------A D-----------------------D D-----------------------C C-----------------------E C-----------------------E C-----------------------E C-----------------------C -D---------------------D- -A---------------------A- --A-------------------A-- --A-------------------A-- ---AA----------------A--- ----A---------------A---- -----AA-----------AA----- -------AD-------AA------- ---------CEEECDA--------- 
---------AAAAAAA--------- -------AA-------AA------- -----AA-----------AA----- ----A---------------A---- ---A-----------------A--- --A-------------------A-- --A-------------------A-- -A---------------------A- -A---------------------W- D-----------------------D H-----------------------I H-----------------------I H-----------------------U S-----------------------F E-----------------------F E-----------------------E -E---------------------R- -D---------------------D- --A-------------------A-- --A-------------------A-- ---AA----------------A--- ----A---------------A---- -----AA-----------AA----- -------DR-------WA------- ---------EFFUIID--------- 
---------AAAAAAA--------- -------AA-------AA------- -----AA-----------AA----- ----A---------------A---- ---A-----------------A--- --A-------------------A-- --A-------------------A-- -A---------------------A- -D---------------------D- D-----------------------C H-----------------------O G-----------------------J G-----------------------J G-----------------------N E-----------------------I L-----------------------F -P---------------------F- -C---------------------C- --A-------------------A-- --A-------------------A-- ---AA----------------A--- ----A---------------A---- -----AA-----------AA----- -------CF-------DA------- ---------FINJJOC--------- 
---------AAAAAAA--------- -------AA-------AA------- -----AA-----------AA----- ----A---------------A---- ---A-----------------A--- --A-------------------A-- --A-------------------A-- -A---------------------A- -D---------------------D- C-----------------------C H-----------------------V G-----------------------J G-----------------------J L-----------------------A L-----------------------K K-----------------------I -Q---------------------F- -E---------------------C- --A-------------------A-- --A-------------------A-- ---AA----------------A--- ----A---------------A---- -----AA-----------AA----- -------CF-------DA------- ---------IKAJJVC--------- 
---------AAAAAAA--------- -------AA-------AA------- -----AA-----------AA----- ----A---------------A---- ---A-----------------A--- --A-------------------A-- --A-------------------A-- -A---------------------A- -D---------------------D- C-----------------------C M-----------------------M M-----------------------M M-----------------------M T-----------------------T O-----------------------O N-----------------------N -K---------------------K- -E---------------------E- --A-------------------A-- --A-------------------A-- ---AA----------------A--- ----A---------------A---- -----AA-----------AA----- -------EK-------DA------- ---------NOTMMMC--------- 
---------AAAAAAA--------- -------AA-------AA------- -----AA-----------AA----- ----A---------------A---- ---A-----------------A--- --A-------------------A-- --A-------------------A-- -A---------------------A- -D---------------------D- C-----------------------C V-----------------------H J-----------------------G J-----------------------G A-----------------------L K-----------------------L I-----------------------K -F---------------------Q- -C---------------------E- --A-------------------A-- --A-------------------A-- ---AA----------------A--- ----A---------------A---- -----AA-----------AA----- -------EQ-------DA------- ---------KLLGGHC--------- 
---------AAAAAAA--------- -------AA-------AA------- -----AA-----------AA----- ----A---------------A---- ---A-----------------A--- --A-------------------A-- --A-------------------A-- -A---------------------A- -D---------------------D- C-----------------------D O-----------------------H J-----------------------G J-----------------------G N-----------------------G I-----------------------E F-----------------------L -F---------------------P- -C---------------------C- --A-------------------A-- --A-------------------A-- ---AA----------------A--- ----A---------------A---- -----AA-----------AA----- -------CP-------DA------- ---------LEGGGHD--------- 
---------AAAAAAA--------- -------AA-------AA------- -----AA-----------AA----- ----A---------------A---- ---A-----------------A--- --A-------------------A-- --A-------------------A-- -A---------------------A- -W---------------------A- D-----------------------D I-----------------------H I-----------------------H U-----------------------H F-----------------------S F-----------------------E E-----------------------E -R---------------------E- -D---------------------D- --A-------------------A-- --A-------------------A-- ---AA----------------A--- ----A---------------A---- -----AA-----------AA----- -------DE-------AA------- ---------EESHHHD--------- 
---------AAAAAAA--------- -------AA-------AA------- -----AA-----------AA----- ----A---------------A---- ---A-----------------A--- --A-------------------A-- --A-------------------A-- -A---------------------A- -A---------------------A- A-----------------------A D-----------------------D C-----------------------D E-----------------------C E-----------------------C E-----------------------C C-----------------------C -D---------------------D- -A---------------------A- --A-------------------A-- --A-------------------A-- ---AA----------------A--- ----A---------------A---- -----AA-----------AA----- -------AD-------AA------- ---------CCCCDDA--------- 
---------AAAAAAA--------- -------AA-------AA------- -----AA-----------AA----- ----A---------------A---- ---A-----------------A--- --A-------------------A-- --A-------------------A-- -A---------------------A- -A---------------------A- A-----------------------A D-----------------------C D-----------------------C D-----------------------C C-----------------------C C-----------------------C D-----------------------C -D---------------------C- -A---------------------A- --A-------------------A-- --A-------------------A-- ---AA----------------A--- ----A---------------A---- -----AA-----------AA----- -------AC-------AA------- ---------CCCCCCA--------- 
---------AAAAAAA--------- -------AA-------AA------- -----AA-----------AA----- ----A---------------A---- ---A-----------------A--- --A-------------------A-- --A-------------------A-- -A---------------------A- -A---------------------A- A-----------------------A A-----------------------A A-----------------------A A-----------------------A A-----------------------A A-----------------------A A-----------------------A -A---------------------A- -A---------------------A- --A-------------------A-- --A-------------------A-- ---AA----------------A--- ----A---------------A---- -----AA-----------AA----- -------AA-------AA------- ---------AAAAAAA--------- 
---------AAAAAAA--------- -------AA-------AA------- -----AA-----------AA----- ----A---------------A---- ---A-----------------A--- --A-------------------A-- --A-------------------A-- -A---------------------A- -A---------------------A- A-----------------------A A-----------------------A A-----------------------A A-----------------------A A-----------------------A A-----------------------A A-----------------------A -A---------------------A- -A---------------------A- --A-------------------A-- --A-------------------A-- ---AA----------------A--- ----A---------------A---- -----AA-----------AA----- -------AA-------AA------- ---------AAAAAAA--------- 
---------AAAAAAA--------- -------AA-------AA------- -----AA-----------AA----- ----A---------------A---- ---A-----------------A--- --A-------------------A-- --A-------------------A-- -A---------------------A- -A---------------------A- A-----------------------A A-----------------------A A-----------------------A A-----------------------A A-----------------------A A-----------------------A A-----------------------A -A---------------------A- -A---------------------A- --A-------------------A-- --A-------------------A-- ---AA----------------A--- ----A---------------A---- -----AA-----------AA----- -------AA-------AA------- ---------AAAAAAA--------- 
---------BBBBBBB--------- -------BB-------BB------- -----BB-----------BB----- ----B---------------B---- ---B-----------------B--- --B-------------------B-- --B-------------------B-- -B---------------------B- -B---------------------B- B-----------------------B B-----------------------B B-----------------------B B-----------------------B B-----------------------B B-----------------------B B-----------------------B -B---------------------B- -B---------------------B- --B-------------------B-- --B-------------------B-- ---BA----------------B--- ----B---------------B---- -----BB-----------BB----- -------BB-------BB------- ---------BBBBBBB--------- 
