model
size = 9 14 9, scale = 0.05, origin = -y
material 
  colors = A:#EEE B:#0FC C:#6C0 D:#99C E:#0C6 F:#9CF G:#6C3 H:#00E
voxels
--------- --------- --------- --------- --------- --------- --------- --------- --------- --------- --------- --------- --AA-AA-- --------- 
--------- --------- --------- --------- --------- --------- --------- --------- --------- --------- --------- --------- --AAAAA-- ---B-B--- 
--------- --------- --------- --------- --------- --------- --------- --------- --------- --------- --------- --------- AA-AAA-AA ---BBB--- 
--------- --------- --------- --------- --------- --------- --------- --------- --------- --------- ----E---- --------- AAADDDAAA -BB---BB- 
---E----- ---E----- ---C----- ---C----- ---C----- ---CC---- ----C---- ----C---- ----C---- ----C---- ---GFG--- ----C---- -AADFDAA- --B-H-B-- 
--------- --------- --------- --------- --------- --------- --------- --------- --------- --------- ----E---- --------- AAADDDAAA -BB---BB- 
--------- --------- --------- --------- --------- --------- --------- --------- --------- --------- --------- --------- AA-AAA-AA ---BBB--- 
--------- --------- --------- --------- --------- --------- --------- --------- --------- --------- --------- --------- --AAAAA-- ---B-B--- 
--------- --------- --------- --------- --------- --------- --------- --------- --------- --------- --------- --------- --AA-AA-- --------- 
