model
size = 28 11 24, scale = 0.05, origin = -y
material 
  colors = A:#111 B:#96F C:#96C D:#C6F E:#36F F:#66F G:#F9F H:#008 I:#00C J:#60F K:#93F L:#30C M:#444 N:#555 O:#00A P:#009 Q:#66C R:#63F S:#309 T:#03F U:#00B V:#C9F W:#99F X:#90C Y:#93C
voxels
---QCCCCC---------QCCCCC---- --BCBBBBCC--------CBBBBCC--- -CCHORJEEECB----CCHORJEEECB- -CBHIIJFFECB----CBHIIJFFECB- -CDSIIJFFEBB----CDSIIJFFEBB- ABDGPTUKFVBBN--NBDGPTUKFVBBA ABDGHLOKDDBB-NN-BDGHLOKDDBBA MCBDGHPLKDBBA--ACBDGHPLKDBBM ACCWGGLXYDCBA--ACCWGGLXYDCBA -AACBBDDBCAA----AACBBDDBCAA- ---AAAAAAA--------AAAAAAA--- 
---------------------------- ---------------------------- ---------------------------- ---------------------------- ---------------------------- ---------------------------- ---------------------------- M--------------------------M ---------------------------- ---------------------------- ---------------------------- 
---------------------------- ---------------------------- ---------------------------- ---------------------------- ---------------------------- ---------------------------- ---------------------------- A--------------------------A ---------------------------- ---------------------------- ---------------------------- 
---------------------------- ---------------------------- ---------------------------- ---------------------------- ---------------------------- ---------------------------- ---------------------------- A--------------------------A ---------------------------- ---------------------------- ---------------------------- 
---------------------------- ---------------------------- ---------------------------- ---------------------------- ---------------------------- ---------------------------- ---------------------------- A--------------------------A ---------------------------- ---------------------------- ---------------------------- 
---------------------------- ---------------------------- ---------------------------- ---------------------------- ---------------------------- ---------------------------- ---------------------------- A--------------------------A ---------------------------- ---------------------------- ---------------------------- 
---------------------------- ---------------------------- ---------------------------- ---------------------------- ---------------------------- ---------------------------- ---------------------------- A--------------------------A ---------------------------- ---------------------------- ---------------------------- 
---------------------------- ---------------------------- ---------------------------- ---------------------------- ---------------------------- ---------------------------- ---------------------------- A--------------------------A ---------------------------- ---------------------------- ---------------------------- 
---------------------------- ---------------------------- ---------------------------- ---------------------------- ---------------------------- ---------------------------- ---------------------------- A--------------------------A ---------------------------- ---------------------------- ---------------------------- 
---------------------------- ---------------------------- ---------------------------- ---------------------------- ---------------------------- ---------------------------- ---------------------------- A--------------------------A ---------------------------- ---------------------------- ---------------------------- 
---------------------------- ---------------------------- ---------------------------- ---------------------------- ---------------------------- ---------------------------- ---------------------------- A--------------------------A ---------------------------- ---------------------------- ---------------------------- 
---------------------------- ---------------------------- ---------------------------- ---------------------------- ---------------------------- ---------------------------- ---------------------------- A--------------------------A ---------------------------- ---------------------------- ---------------------------- 
---------------------------- ---------------------------- ---------------------------- ---------------------------- ---------------------------- ---------------------------- ---------------------------- A--------------------------A ---------------------------- ---------------------------- ---------------------------- 
---------------------------- ---------------------------- ---------------------------- ---------------------------- ---------------------------- ---------------------------- ---------------------------- A--------------------------A ---------------------------- ---------------------------- ---------------------------- 
---------------------------- ---------------------------- ---------------------------- ---------------------------- ---------------------------- ---------------------------- ---------------------------- A--------------------------A ---------------------------- ---------------------------- ---------------------------- 
---------------------------- ---------------------------- ---------------------------- ---------------------------- ---------------------------- ---------------------------- ---------------------------- A--------------------------A ---------------------------- ---------------------------- ---------------------------- 
---------------------------- ---------------------------- ---------------------------- ---------------------------- ---------------------------- ---------------------------- ---------------------------- A--------------------------A ---------------------------- ---------------------------- ---------------------------- 
---------------------------- ---------------------------- ---------------------------- ---------------------------- ---------------------------- ---------------------------- ---------------------------- A--------------------------A ---------------------------- ---------------------------- ---------------------------- 
---------------------------- ---------------------------- ---------------------------- ---------------------------- ---------------------------- ---------------------------- ---------------------------- A--------------------------A ---------------------------- ---------------------------- ---------------------------- 
---------------------------- ---------------------------- ---------------------------- ---------------------------- ---------------------------- ---------------------------- ---------------------------- A--------------------------A ---------------------------- ---------------------------- ---------------------------- 
---------------------------- ---------------------------- ---------------------------- ---------------------------- ---------------------------- ---------------------------- ---------------------------- A--------------------------A ---------------------------- ---------------------------- ---------------------------- 
---------------------------- ---------------------------- ---------------------------- ---------------------------- ---------------------------- ---------------------------- ---------------------------- A--------------------------A ---------------------------- ---------------------------- ---------------------------- 
---------------------------- ---------------------------- ---------------------------- ---------------------------- ---------------------------- ---------------------------- A--------------------------A ---------------------------- ---------------------------- ---------------------------- ---------------------------- 
---------------------------- ---------------------------- ---------------------------- ---------------------------- A--------------------------A A--------------------------A ---------------------------- ---------------------------- ---------------------------- ---------------------------- ---------------------------- 
