model
size = 22 31 22, scale = 0.05, origin = -y
material 
  colors = A:#111 B:#03F C:#96C D:#96F E:#333 F:#C6F G:#F9F H:#36F I:#30C J:#00A K:#008 L:#66F M:#60F N:#C9F O:#93F P:#00C Q:#66C R:#F6F S:#93C T:#99F U:#009 V:#33C W:#C6C X:#90C Y:#00B Z:#639 Aa:#00D Ab:#309 Ac:#63F Ad:#555
voxels
- B B B B B B B B B B B B B B B B B B B B -   - A A A A A A A A A A A A A A A A A A A A -   - A A A A A Q C C C C C C C C Q A A A A B -   - A A A A C C C D D O D D D C C C A A A A -   - A A A Q C D D J I M V L H D D C Q A A B -   - A A C C S K J J AcM M V H H H H C C A A -   - A A C C R K J P P I M L L H H H D C A A -   - B A C D G K J P P I M M L L H H D C A A -   - A A C F G AbJ P P B M M L L L H H D A B -   - A A D F G G K I AaB I M D L N N D D A A -   - A A D F G G Z U B B Y J O L L N N D A A -   - B A D F F G G K I B I J O F D N N D A A -   - A A D F F G G K I I J J O F F F N D A B -   - A A C D F F G G K J U J I O F F F D A A -   - A A C D T F G G K K K K I O F F D C A A -   - B A C C H T F G G G I I X S F F D C A A -   - A A A C D D D G G G G G R F G F C A A B -   - A A A A C C D D D F F W F D C C A A A A -   - A A A A A C C C D D D D C C C A A A A A -   - A A A A A A A A A A A A A A A A A A A A -   - A A A A A A A A A A A A A A A A A A A A -   - A A A A A A A A B B B B A A A A A A A A -   - A A A A A A A B - - - - B A A A A A A A -   - B A B A B A B - - - - - - B A B A B A B -   - - B A B A B - - - - - - - - B A B A B - -   - - B A B A B - - - - - - - - B A B A B - -   - - - - - - - - - - - - - - - - - - - - - -   - - - - - - - - - - - - - - - - - - - - - -   - - - - - - - - - - - - - - - - - - - - - -   - - - - - - - - - - - - - - - - - - - - - -   - - - - - - - - - - - - - - - - - - - - - -   
B - - - - - - - - - - - - - - - - - - - - B   A - - - - - - - - - - - - - - - - - - - - A   A - - - - - - - - - - - - - - - - - - - - A   A - - - - - - - - - - - - - - - - - - - - A   B - - - - - - - - - - - - - - - - - - - - A   A - - - - - - - - - - - - - - - - - - - - B   A - - - - - - - - - - - - - - - - - - - - A   A - - - - - - - - - - - - - - - - - - - - A   B - - - - - - - - - - - - - - - - - - - - A   A - - - - - - - - - - - - - - - - - - - - B   A - - - - - - - - - - - - - - - - - - - - A   A - - - - - - - - - - - - - - - - - - - - A   B - - - - - - - - - - - - - - - - - - - - A   A - - - - - - - - - - - - - - - - - - - - B   A - - - - - - - - - - - - - - - - - - - - A   A - - - - - - - - - - - - - - - - - - - - A   B - - - - - - - - - - - - - - - - - - - - A   A - - - - - - - - - - - - - - - - - - - - B   A - - - - - - - - - - - - - - - - - - - - A   A - - - - - - - - - - - - - - - - - - - - A   A - - - - - - - - - - - - - - - - - - - - A   A - - - - - - - - - - - - - - - - - - - - A   B - - - - - - - - - - - - - - - - - - - - B   - - - - - - - - - - - - - - - - - - - - - -   - - - - - - - - - - - - - - - - - - - - - -   - - - - - - - - - - - - - - - - - - - - - -   - - B A B A B - - - - - - - - B A B A B - -   - - - - - - - - - - - - - - - - - - - - - -   - - - - - - - - - - - - - - - - - - - - - -   - - - - - - - - - - - - - - - - - - - - - -   - - - - - - - - - - - - - - - - - - - - - -   
B - - - - - - - - - - - - - - - - - - - - B   A - - - - - - - - - - - - - - - - - - - - A   A - - - - - - - - - - - - - - - - - - - - A   B - - - - - - - - - - - - - - - - - - - - A   A - - - - - - - - - - - - - - - - - - - - B   B - - - - - - - - - - - - - - - - - - - - A   A - - - - - - - - - - - - - - - - - - - - B   A - - - - - - - - - - - - - - - - - - - - A   A - - - - - - - - - - - - - - - - - - - - A   B - - - - - - - - - - - - - - - - - - - - A   A - - - - - - - - - - - - - - - - - - - - B   A - - - - - - - - - - - - - - - - - - - - A   A - - - - - - - - - - - - - - - - - - - - A   B - - - - - - - - - - - - - - - - - - - - A   A - - - - - - - - - - - - - - - - - - - - B   A - - - - - - - - - - - - - - - - - - - - A   A - - - - - - - - - - - - - - - - - - - - A   B - - - - - - - - - - - - - - - - - - - - A   A - - - - - - - - - - - - - - - - - - - - B   A - - - - - - - - - - - - - - - - - - - - A   A - - - - - - - - - - - - - - - - - - - - A   B - - - - - - - - - - - - - - - - - - - - A   - - - - - - - - - - - - - - - - - - - - - B   - - - - - - - - - - - - - - - - - - - - - -   - - - - - - - - - - - - - - - - - - - - - -   - - - - - - - - - - - - - - - - - - - - - -   - - - - - - - - - - - - - - - - - - - - - -   - - B A B A B - - - - - - - - B A B A B - -   - - - - - - - - - - - - - - - - - - - - - -   - - - - - - - - - - - - - - - - - - - - - -   - - - - - - - - - - - - - - - - - - - - - -   
B - - - - - - - - - - - - - - - - - - - - B   A - - - - - - - - - - - - - - - - - - - - A   B - - - - - - - - - - - - - - - - - - - - A   A - - - - - - - - - - - - - - - - - - - - B   B - - - - - - - - - - - - - - - - - - - - A   A - - - - - - - - - - - - - - - - - - - - B   B - - - - - - - - - - - - - - - - - - - - A   A - - - - - - - - - - - - - - - - - - - - B   A - - - - - - - - - - - - - - - - - - - - A   A - - - - - - - - - - - - - - - - - - - - A   B - - - - - - - - - - - - - - - - - - - - A   A - - - - - - - - - - - - - - - - - - - - B   A - - - - - - - - - - - - - - - - - - - - A   A - - - - - - - - - - - - - - - - - - - - A   B - - - - - - - - - - - - - - - - - - - - A   A - - - - - - - - - - - - - - - - - - - - B   A - - - - - - - - - - - - - - - - - - - - A   A - - - - - - - - - - - - - - - - - - - - A   B - - - - - - - - - - - - - - - - - - - - A   A - - - - - - - - - - - - - - - - - - - - B   B - - - - - - - - - - - - - - - - - - - - A   - - - - - - - - - - - - - - - - - - - - - B   - - - - - - - - - - - - - - - - - - - - - -   - - - - - - - - - - - - - - - - - - - - - -   - - - - - - - - - - - - - - - - - - - - - -   - - - - - - - - - - - - - - - - - - - - - -   - - - - - - - - - - - - - - - - - - - - - -   - - - - - - - - - - - - - - - - - - - - - -   - - B A B A B - - - - - - - - B A B A B - -   - - - - - - - - - - - - - - - - - - - - - -   - - - - - - - - - - - - - - - - - - - - - -   
B - - - - - - - - - - - - - - - - - - - - B   B - - - - - - - - - - - - - - - - - - - - A   A - - - - - - - - - - - - - - - - - - - - B   A - - - - - - - - - - - - - - - - - - - - A   B - - - - - - - - - - - - - - - - - - - - A   A - - - - - - - - - - - - - - - - - - - - B   A - - - - - - - - - - - - - - - - - - - - A   B - - - - - - - - - - - - - - - - - - - - A   A - - - - - - - - - - - - - - - - - - - - B   A - - - - - - - - - - - - - - - - - - - - A   A - - - - - - - - - - - - - - - - - - - - A   B - - - - - - - - - - - - - - - - - - - - A   A - - - - - - - - - - - - - - - - - - - - B   A - - - - - - - - - - - - - - - - - - - - A   A - - - - - - - - - - - - - - - - - - - - A   B - - - - - - - - - - - - - - - - - - - - A   A - - - - - - - - - - - - - - - - - - - - B   A - - - - - - - - - - - - - - - - - - - - A   A - - - - - - - - - - - - - - - - - - - - A   B - - - - - - - - - - - - - - - - - - - - A   - - - - - - - - - - - - - - - - - - - - - B   - - - - - - - - - - - - - - - - - - - - - -   - - - - - - - - - - - - - - - - - - - - - -   - - - - - - - - - - - - - - - - - - - - - -   - - - - - - - - - - - - - - - - - - - - - -   - - - - - - - - - - - - - - - - - - - - - -   - - - - - - - - - - - - - - - - - - - - - -   - - - - - - - - - - - - - - - - - - - - - -   - - - - - - - - - - - - - - - - - - - - - -   - - B A B A B - - - - - - - - B A B A B - -   - - - - - - - - - - - - - - - - - - - - - -   
B - - - - - - - - - - - - - - - - - - - - B   A - - - - - - - - - - - - - - - - - - - - B   A - - - - - - - - - - - - - - - - - - - - A   A - - - - - - - - - - - - - - - - - - - - A   B - - - - - - - - - - - - - - - - - - - - A   A - - - - - - - - - - - - - - - - - - - - B   A - - - - - - - - - - - - - - - - - - - - A   A - - - - - - - - - - - - - - - - - - - - A   B - - - - - - - - - - - - - - - - - - - - A   A - - - - - - - - - - - - - - - - - - - - B   A - - - - - - - - - - - - - - - - - - - - A   A - - - - - - - - - - - - - - - - - - - - A   B - - - - - - - - - - - - - - - - - - - - A   A - - - - - - - - - - - - - - - - - - - - B   A - - - - - - - - - - - - - - - - - - - - A   A - - - - - - - - - - - - - - - - - - - - A   B - - - - - - - - - - - - - - - - - - - - A   A - - - - - - - - - - - - - - - - - - - - B   B - - - - - - - - - - - - - - - - - - - - A   - - - - - - - - - - - - - - - - - - - - - B   - - - - - - - - - - - - - - - - - - - - - -   - - - - - - - - - - - - - - - - - - - - - -   - - - - - - - - - - - - - - - - - - - - - -   - - - - - - - - - - - - - - - - - - - - - -   - - - - - - - - - - - - - - - - - - - - - -   - - - - - - - - - - - - - - - - - - - - - -   - - - - - - - - - - - - - - - - - - - - - -   - - - - - - - - - - - - - - - - - - - - - -   - - - - - - - - - - - - - - - - - - - - - -   - - B A B A B - - - - - - - - B A B A B - -   - - - - - - - - - - - - - - - - - - - - - -   
B - - - - - - - - - - - - - - - - - - - - B   A - - - - - - - - - - - - - - - - - - - - A   A - - - - - - - - - - - - - - - - - - - - A   A - - - - - - - - - - - - - - - - - - - - A   B - - - - - - - - - - - - - - - - - - - - B   A - - - - - - - - - - - - - - - - - - - - B   A - - - - - - - - - - - - - - - - - - - - B   A - - - - - - - - - - - - - - - - - - - - A   A - - - - - - - - - - - - - - - - - - - - A   B - - - - - - - - - - - - - - - - - - - - A   A - - - - - - - - - - - - - - - - - - - - B   A - - - - - - - - - - - - - - - - - - - - A   A - - - - - - - - - - - - - - - - - - - - A   B - - - - - - - - - - - - - - - - - - - - A   A - - - - - - - - - - - - - - - - - - - - B   A - - - - - - - - - - - - - - - - - - - - A   A - - - - - - - - - - - - - - - - - - - - A   B - - - - - - - - - - - - - - - - - - - - A   - - - - - - - - - - - - - - - - - - - - - B   - - - - - - - - - - - - - - - - - - - - - -   - - - - - - - - - - - - - - - - - - - - - -   - - - - - - - - - - - - - - - - - - - - - -   - - - - - - - - - - - - - - - - - - - - - -   - - - - - - - - - - - - - - - - - - - - - -   - - - - - - - - - - - - - - - - - - - - - -   - - - - - - - - - - - - - - - - - - - - - -   - - - - - - - - - - - - - - - - - - - - - -   - - - - - - - - - - - - - - - - - - - - - -   - - - - - - - - - - - - - - - - - - - - - -   - - - - - - - - - - - - - - - - - - - - - -   - - B A B A B - - - - - - - - B A B A B - -   
B - - - - - - - - - - - - - - - - - - - - B   A - - - - - - - - - - - - - - - - - - - - A   A - - - - - - - - - - - - - - - - - - - - A   A - - - - - - - - - - - - - - - - - - - - B   B - - - - - - - - - - - - - - - - - - - - A   B - - - - - - - - - - - - - - - - - - - - B   A - - - - - - - - - - - - - - - - - - - - A   A - - - - - - - - - - - - - - - - - - - - B   A - - - - - - - - - - - - - - - - - - - - A   A - - - - - - - - - - - - - - - - - - - - A   B - - - - - - - - - - - - - - - - - - - - A   A - - - - - - - - - - - - - - - - - - - - B   A - - - - - - - - - - - - - - - - - - - - A   A - - - - - - - - - - - - - - - - - - - - A   B - - - - - - - - - - - - - - - - - - - - A   A - - - - - - - - - - - - - - - - - - - - B   B - - - - - - - - - - - - - - - - - - - - A   - - - - - - - - - - - - - - - - - - - - - B   - - - - - - - - - - - - - - - - - - - - - -   - - - - - - - - - - - - - - - - - - - - - -   - - - - - - - - - - - - - - - - - - - - - -   - - - - - - - - - - - - - - - - - - - - - -   - - - - - - - - - - - - - - - - - - - - - -   - - - - - - - - - - - - - - - - - - - - - -   - - - - - - - - - - - - - - - - - - - - - -   - - - - - - - - - - - - - - - - - - - - - -   - - - - - - - - - - - - - - - - - - - - - -   - - - - - - - - - - - - - - - - - - - - - -   - - - - - - - - - - - - - - - - - - - - - -   - - - - - - - - - - - - - - - - - - - - - -   - - B A B A B - - - - - - - - B A B A B - -   
B - - - - - - - - - - - - - - - - - - - - B   A - - - - - - - - - - - - - - - - - - - - A   A - - - - - - - - - - - - - - - - - - - - B   A - - - - - - - - - - - - - - - - - - - - A   B - - - - - - - - - - - - - - - - - - - - A   A - - - - - - - - - - - - - - - - - - - - B   B - - - - - - - - - - - - - - - - - - - - A   A - - - - - - - - - - - - - - - - - - - - A   A - - - - - - - - - - - - - - - - - - - - B   A - - - - - - - - - - - - - - - - - - - - A   A - - - - - - - - - - - - - - - - - - - - A   B - - - - - - - - - - - - - - - - - - - - A   A - - - - - - - - - - - - - - - - - - - - B   A - - - - - - - - - - - - - - - - - - - - A   A - - - - - - - - - - - - - - - - - - - - A   B - - - - - - - - - - - - - - - - - - - - A   - - - - - - - - - - - - - - - - - - - - - B   - - - - - - - - - - - - - - - - - - - - - -   - - - - - - - - - - - - - - - - - - - - - -   - - - - - - - - - - - - - - - - - - - - - -   - - - - - - - - - - - - - - - - - - - - - -   - - - - - - - - - - - - - - - - - - - - - -   - - - - - - - - - - - - - - - - - - - - - -   - - - - - - - - - - - - - - - - - - - - - -   - - - - - - - - - - - - - - - - - - - - - -   - - - - - - - - - - - - - - - - - - - - - -   - - - - - - - - - - - - - - - - - - - - - -   - - - - - - - - - - - - - - - - - - - - - -   - - - - - - - - - - - - - - - - - - - - - -   - - - - - - - - - - - - - - - - - - - - - -   - - B A B A B - - - - - - - - B A B A B - -   
B - - - - - - - - - - - - - - - - - - - - B   A - - - - - - - - - - - - - - - - - - - - B   A - - - - - - - - - - - - - - - - - - - - A   A - - - - - - - - - - - - - - - - - - - - A   B - - - - - - - - - - - - - - - - - - - - A   A - - - - - - - - - - - - - - - - - - - - B   A - - - - - - - - - - - - - - - - - - - - A   B - - - - - - - - - - - - - - - - - - - - A   A - - - - - - - - - - - - - - - - - - - - A   A - - - - - - - - - - - - - - - - - - - - B   A - - - - - - - - - - - - - - - - - - - - A   A - - - - - - - - - - - - - - - - - - - - A   B - - - - - - - - - - - - - - - - - - - - A   A - - - - - - - - - - - - - - - - - - - - B   B - - - - - - - - - - - - - - - - - - - - A   - - - - - - - - - - - - - - - - - - - - - B   - - - - - - - - - - - - - - - - - - - - - -   - - - - - - - - - - - - - - - - - - - - - -   - - - - - - - - - - - - - - - - - - - - - -   - - - - - - - - - - - - - - - - - - - - - -   - - - - - - - - - - - - - - - - - - - - - -   - - - - - - - - - - - - - - - - - - - - - -   - - - - - - - - - - - - - - - - - - - - - -   - - - - - - - - - - - - - - - - - - - - - -   - - - - - - - - - - - - - - - - - - - - - -   - - - - - - - - - - - - - - - - - - - - - -   - - - - - - - - - - - - - - - - - - - - - -   - - - - - - - - - - - - - - - - - - - - - -   - - - - - - - - - - - - - - - - - - - - - -   - - - - - - - - - - - - - - - - - - - - - -   - - B A B A B - - - - - - - - B A B A B - -   
B - - - - - - - - - - - - - - - - - - - - B   B - - - - - - - - - - - - - - - - - - - - B   B - - - - - - - - - - - - - - - - - - - - B   B - - - - - - - - - - - - - - - - - - - - B   B - - - - - - - - - - - - - - - - - - - - B   B - - - - - - - - - - - - - - - - - - - - B   B - - - - - - - - - - - - - - - - - - - - B   B - - - - - - - - - - - - - - - - - - - - B   B - - - - - - - - - - - - - - - - - - - - B   B - - - - - - - - - - - - - - - - - - - - B   B - - - - - - - - - - - - - - - - - - - - B   B - - - - - - - - - - - - - - - - - - - - B   B - - - - - - - - - - - - - - - - - - - - B   B - - - - - - - - - - - - - - - - - - - - B   B - - - - - - - - - - - - - - - - - - - - B   - - - - - - - - - - - - - - - - - - - - - B   - - - - - - - - - - - - - - - - - - - - - -   - - - - - - - - - - - - - - - - - - - - - -   - - - - - - - - - - - - - - - - - - - - - -   - - - - - - - - - - - - - - - - - - - - - -   - - - - - - - - - - - - - - - - - - - - - -   - - - - - - - - - - - - - - - - - - - - - -   - - - - - - - - - - - - - - - - - - - - - -   - - - - - - - - - - - - - - - - - - - - - -   - - - - - - - - - - - - - - - - - - - - - -   - - - - - - - - - - - - - - - - - - - - - -   - - - - - - - - - - - - - - - - - - - - - -   - - - - - - - - - - - - - - - - - - - - - -   - - - - - - - - - - - - - - - - - - - - - -   - - - - - - - - - - - - - - - - - - - - - -   - - B A B A B - - - - - - - - B A B A B - -   
B - - - - - - - - - - - - - - - - - - - - B   A - - - - - - - - - - - - - - - - - - - - B   A - - - - - - - - - - - - - - - - - - - - A   A - - - - - - - - - - - - - - - - - - - - A   B - - - - - - - - - - - - - - - - - - - - A   A - - - - - - - - - - - - - - - - - - - - B   A - - - - - - - - - - - - - - - - - - - - A   B - - - - - - - - - - - - - - - - - - - - A   A - - - - - - - - - - - - - - - - - - - - A   A - - - - - - - - - - - - - - - - - - - - B   A - - - - - - - - - - - - - - - - - - - - A   A - - - - - - - - - - - - - - - - - - - - A   B - - - - - - - - - - - - - - - - - - - - A   A - - - - - - - - - - - - - - - - - - - - B   B - - - - - - - - - - - - - - - - - - - - A   - - - - - - - - - - - - - - - - - - - - - B   - - - - - - - - - - - - - - - - - - - - - -   - - - - - - - - - - - - - - - - - - - - - -   - - - - - - - - - - - - - - - - - - - - - -   - - - - - - - - - - - - - - - - - - - - - -   - - - - - - - - - - - - - - - - - - - - - -   - - - - - - - - - - - - - - - - - - - - - -   - - - - - - - - - - - - - - - - - - - - - -   - - - - - - - - - - - - - - - - - - - - - -   - - - - - - - - - - - - - - - - - - - - - -   - - - - - - - - - - - - - - - - - - - - - -   - - - - - - - - - - - - - - - - - - - - - -   - - - - - - - - - - - - - - - - - - - - - -   - - - - - - - - - - - - - - - - - - - - - -   - - - - - - - - - - - - - - - - - - - - - -   - - B A B A B - - - - - - - - B A B A B - -   
B - - - - - - - - - - - - - - - - - - - - B   A - - - - - - - - - - - - - - - - - - - - A   A - - - - - - - - - - - - - - - - - - - - B   A - - - - - - - - - - - - - - - - - - - - A   B - - - - - - - - - - - - - - - - - - - - A   A - - - - - - - - - - - - - - - - - - - - B   B - - - - - - - - - - - - - - - - - - - - A   A - - - - - - - - - - - - - - - - - - - - A   A - - - - - - - - - - - - - - - - - - - - B   A - - - - - - - - - - - - - - - - - - - - A   A - - - - - - - - - - - - - - - - - - - - A   B - - - - - - - - - - - - - - - - - - - - A   A - - - - - - - - - - - - - - - - - - - - B   A - - - - - - - - - - - - - - - - - - - - A   A - - - - - - - - - - - - - - - - - - - - A   B - - - - - - - - - - - - - - - - - - - - A   - - - - - - - - - - - - - - - - - - - - - B   - - - - - - - - - - - - - - - - - - - - - -   - - - - - - - - - - - - - - - - - - - - - -   - - - - - - - - - - - - - - - - - - - - - -   - - - - - - - - - - - - - - - - - - - - - -   - - - - - - - - - - - - - - - - - - - - - -   - - - - - - - - - - - - - - - - - - - - - -   - - - - - - - - - - - - - - - - - - - - - -   - - - - - - - - - - - - - - - - - - - - - -   - - - - - - - - - - - - - - - - - - - - - -   - - - - - - - - - - - - - - - - - - - - - -   - - - - - - - - - - - - - - - - - - - - - -   - - - - - - - - - - - - - - - - - - - - - -   - - - - - - - - - - - - - - - - - - - - - -   - - B A B A B - - - - - - - - B A B A B - -   
B - - - - - - - - - - - - - - - - - - - - B   A - - - - - - - - - - - - - - - - - - - - A   A - - - - - - - - - - - - - - - - - - - - A   A - - - - - - - - - - - - - - - - - - - - B   B - - - - - - - - - - - - - - - - - - - - A   B - - - - - - - - - - - - - - - - - - - - B   A - - - - - - - - - - - - - - - - - - - - A   A - - - - - - - - - - - - - - - - - - - - B   A - - - - - - - - - - - - - - - - - - - - A   A - - - - - - - - - - - - - - - - - - - - A   B - - - - - - - - - - - - - - - - - - - - A   A - - - - - - - - - - - - - - - - - - - - B   A - - - - - - - - - - - - - - - - - - - - A   A - - - - - - - - - - - - - - - - - - - - A   B - - - - - - - - - - - - - - - - - - - - A   A - - - - - - - - - - - - - - - - - - - - B   B - - - - - - - - - - - - - - - - - - - - A   - - - - - - - - - - - - - - - - - - - - - B   - - - - - - - - - - - - - - - - - - - - - -   - - - - - - - - - - - - - - - - - - - - - -   - - - - - - - - - - - - - - - - - - - - - -   - - - - - - - - - - - - - - - - - - - - - -   - - - - - - - - - - - - - - - - - - - - - -   - - - - - - - - - - - - - - - - - - - - - -   - - - - - - - - - - - - - - - - - - - - - -   - - - - - - - - - - - - - - - - - - - - - -   - - - - - - - - - - - - - - - - - - - - - -   - - - - - - - - - - - - - - - - - - - - - -   - - - - - - - - - - - - - - - - - - - - - -   - - - - - - - - - - - - - - - - - - - - - -   - - B A B A B - - - - - - - - B A B A B - -   
B - - - - - - - - - - - - - - - - - - - - B   A - - - - - - - - - - - - - - - - - - - - A   A - - - - - - - - - - - - - - - - - - - - A   A - - - - - - - - - - - - - - - - - - - - A   B - - - - - - - - - - - - - - - - - - - - B   A - - - - - - - - - - - - - - - - - - - - B   A - - - - - - - - - - - - - - - - - - - - B   A - - - - - - - - - - - - - - - - - - - - A   A - - - - - - - - - - - - - - - - - - - - A   B - - - - - - - - - - - - - - - - - - - - A   A - - - - - - - - - - - - - - - - - - - - B   A - - - - - - - - - - - - - - - - - - - - A   A - - - - - - - - - - - - - - - - - - - - A   B - - - - - - - - - - - - - - - - - - - - A   A - - - - - - - - - - - - - - - - - - - - B   A - - - - - - - - - - - - - - - - - - - - A   A - - - - - - - - - - - - - - - - - - - - A   B - - - - - - - - - - - - - - - - - - - - A   - - - - - - - - - - - - - - - - - - - - - B   - - - - - - - - - - - - - - - - - - - - - -   - - - - - - - - - - - - - - - - - - - - - -   - - - - - - - - - - - - - - - - - - - - - -   - - - - - - - - - - - - - - - - - - - - - -   - - - - - - - - - - - - - - - - - - - - - -   - - - - - - - - - - - - - - - - - - - - - -   - - - - - - - - - - - - - - - - - - - - - -   - - - - - - - - - - - - - - - - - - - - - -   - - - - - - - - - - - - - - - - - - - - - -   - - - - - - - - - - - - - - - - - - - - - -   - - - - - - - - - - - - - - - - - - - - - -   - - B A B A B - - - - - - - - B A B A B - -   
B - - - - - - - - - - - - - - - - - - - - B   A - - - - - - - - - - - - - - - - - - - - B   A - - - - - - - - - - - - - - - - - - - - A   A - - - - - - - - - - - - - - - - - - - - A   B - - - - - - - - - - - - - - - - - - - - A   A - - - - - - - - - - - - - - - - - - - - B   A - - - - - - - - - - - - - - - - - - - - A   A - - - - - - - - - - - - - - - - - - - - A   B - - - - - - - - - - - - - - - - - - - - A   A - - - - - - - - - - - - - - - - - - - - B   A - - - - - - - - - - - - - - - - - - - - A   A - - - - - - - - - - - - - - - - - - - - A   B - - - - - - - - - - - - - - - - - - - - A   A - - - - - - - - - - - - - - - - - - - - B   A - - - - - - - - - - - - - - - - - - - - A   A - - - - - - - - - - - - - - - - - - - - A   B - - - - - - - - - - - - - - - - - - - - A   A - - - - - - - - - - - - - - - - - - - - B   B - - - - - - - - - - - - - - - - - - - - A   - - - - - - - - - - - - - - - - - - - - - B   - - - - - - - - - - - - - - - - - - - - - -   - - - - - - - - - - - - - - - - - - - - - -   - - - - - - - - - - - - - - - - - - - - - -   - - - - - - - - - - - - - - - - - - - - - -   - - - - - - - - - - - - - - - - - - - - - -   - - - - - - - - - - - - - - - - - - - - - -   - - - - - - - - - - - - - - - - - - - - - -   - - - - - - - - - - - - - - - - - - - - - -   - - - - - - - - - - - - - - - - - - - - - -   - - B A B A B - - - - - - - - B A B A B - -   - - - - - - - - - - - - - - - - - - - - - -   
B - - - - - - - - - - - - - - - - - - - - B   B - - - - - - - - - - - - - - - - - - - - A   A - - - - - - - - - - - - - - - - - - - - B   A - - - - - - - - - - - - - - - - - - - - A   B - - - - - - - - - - - - - - - - - - - - A   A - - - - - - - - - - - - - - - - - - - - B   A - - - - - - - - - - - - - - - - - - - - A   B - - - - - - - - - - - - - - - - - - - - A   A - - - - - - - - - - - - - - - - - - - - B   A - - - - - - - - - - - - - - - - - - - - A   A - - - - - - - - - - - - - - - - - - - - A   B - - - - - - - - - - - - - - - - - - - - A   A - - - - - - - - - - - - - - - - - - - - B   A - - - - - - - - - - - - - - - - - - - - A   A - - - - - - - - - - - - - - - - - - - - A   B - - - - - - - - - - - - - - - - - - - - A   A - - - - - - - - - - - - - - - - - - - - B   A - - - - - - - - - - - - - - - - - - - - A   A - - - - - - - - - - - - - - - - - - - - A   B - - - - - - - - - - - - - - - - - - - - A   - - - - - - - - - - - - - - - - - - - - - B   - - - - - - - - - - - - - - - - - - - - - -   - - - - - - - - - - - - - - - - - - - - - -   - - - - - - - - - - - - - - - - - - - - - -   - - - - - - - - - - - - - - - - - - - - - -   - - - - - - - - - - - - - - - - - - - - - -   - - - - - - - - - - - - - - - - - - - - - -   - - - - - - - - - - - - - - - - - - - - - -   - - - - - - - - - - - - - - - - - - - - - -   - - B A B A B - - - - - - - - B A B A B - -   - - - - - - - - - - - - - - - - - - - - - -   
B - - - - - - - - - - - - - - - - - - - - B   A - - - - - - - - - - - - - - - - - - - - A   B - - - - - - - - - - - - - - - - - - - - A   A - - - - - - - - - - - - - - - - - - - - B   B - - - - - - - - - - - - - - - - - - - - A   A - - - - - - - - - - - - - - - - - - - - B   B - - - - - - - - - - - - - - - - - - - - A   A - - - - - - - - - - - - - - - - - - - - B   A - - - - - - - - - - - - - - - - - - - - A   A - - - - - - - - - - - - - - - - - - - - A   B - - - - - - - - - - - - - - - - - - - - A   A - - - - - - - - - - - - - - - - - - - - B   A - - - - - - - - - - - - - - - - - - - - A   A - - - - - - - - - - - - - - - - - - - - A   B - - - - - - - - - - - - - - - - - - - - A   A - - - - - - - - - - - - - - - - - - - - B   A - - - - - - - - - - - - - - - - - - - - A   A - - - - - - - - - - - - - - - - - - - - A   B - - - - - - - - - - - - - - - - - - - - A   A - - - - - - - - - - - - - - - - - - - - B   B - - - - - - - - - - - - - - - - - - - - A   - - - - - - - - - - - - - - - - - - - - - B   - - - - - - - - - - - - - - - - - - - - - -   - - - - - - - - - - - - - - - - - - - - - -   - - - - - - - - - - - - - - - - - - - - - -   - - - - - - - - - - - - - - - - - - - - - -   - - - - - - - - - - - - - - - - - - - - - -   - - - - - - - - - - - - - - - - - - - - - -   - - B A B A B - - - - - - - - B A B A B - -   - - - - - - - - - - - - - - - - - - - - - -   - - - - - - - - - - - - - - - - - - - - - -   
B - - - - - - - - - - - - - - - - - - - - B   A - - - - - - - - - - - - - - - - - - - - A   A - - - - - - - - - - - - - - - - - - - - A   B - - - - - - - - - - - - - - - - - - - - A   A - - - - - - - - - - - - - - - - - - - - B   B - - - - - - - - - - - - - - - - - - - - A   A - - - - - - - - - - - - - - - - - - - - B   A - - - - - - - - - - - - - - - - - - - - A   A - - - - - - - - - - - - - - - - - - - - A   B - - - - - - - - - - - - - - - - - - - - A   A - - - - - - - - - - - - - - - - - - - - B   A - - - - - - - - - - - - - - - - - - - - A   A - - - - - - - - - - - - - - - - - - - - A   B - - - - - - - - - - - - - - - - - - - - A   A - - - - - - - - - - - - - - - - - - - - B   A - - - - - - - - - - - - - - - - - - - - A   A - - - - - - - - - - - - - - - - - - - - A   B - - - - - - - - - - - - - - - - - - - - A   A - - - - - - - - - - - - - - - - - - - - B   A - - - - - - - - - - - - - - - - - - - - A   A - - - - - - - - - - - - - - - - - - - - A   B - - - - - - - - - - - - - - - - - - - - A   - - - - - - - - - - - - - - - - - - - - - B   - - - - - - - - - - - - - - - - - - - - - -   - - - - - - - - - - - - - - - - - - - - - -   - - - - - - - - - - - - - - - - - - - - - -   - - - - - - - - - - - - - - - - - - - - - -   - - B A B A B - - - - - - - - B - B A B - -   - - - - - - - - - - - - - - - - - - - - - -   - - - - - - - - - - - - - - - - - - - - - -   - - - - - - - - - - - - - - - - - - - - - -   
B - - - - - - - - - - - - - - - - - - - - B   A - - - - - - - - - - - - - - - - - - - - A   A - - - - - - - - - - - - - - - - - - - - A   A - - - - - - - - - - - - - - - - - - - - A   B - - - - - - - - - - - - - - - - - - - - A   A - - - - - - - - - - - - - - - - - - - - B   A - - - - - - - - - - - - - - - - - - - - A   A - - - - - - - - - - - - - - - - - - - - A   B - - - - - - - - - - - - - - - - - - - - A   A - - - - - - - - - - - - - - - - - - - - B   A - - - - - - - - - - - - - - - - - - - - A   A - - - - - - - - - - - - - - - - - - - - A   B - - - - - - - - - - - - - - - - - - - - A   A - - - - - - - - - - - - - - - - - - - - B   A - - - - - - - - - - - - - - - - - - - - A   A - - - - - - - - - - - - - - - - - - - - A   B - - - - - - - - - - - - - - - - - - - - A   A - - - - - - - - - - - - - - - - - - - - B   A - - - - - - - - - - - - - - - - - - - - A   A - - - - - - - - - - - - - - - - - - - - A   A - - - - - - - - - - - - - - - - - - - - A   A - - - - - - - - - - - - - - - - - - - - A   B - - - - - - - - - - - - - - - - - - - - B   - - - - - - - - - - - - - - - - - - - - - -   - - - - - - - - - - - - - - - - - - - - - -   - - - - - - - - - - - - - - - - - - - - - -   - - B A B A B - - - - - - - - B A B A B - -   - - - - - - - - - - - - - - - - - - - - - -   - - - - - - - - - - - - - - - - - - - - - -   - - - - - - - - - - - - - - - - - - - - - -   - - - - - - - - - - - - - - - - - - - - - -   
- B B B B B B B B B B B B B B B B B B B B -   - E E E E E E E AdA A A A AdE E E E E E A -   - E E E E E Q C C C C C C C C Q E E E E A -   - E E E E C C C D D D O D D C C C E E E A -   - E E E Q C D D H L V M I J D D C Q E E A -   - E E C C H H H H V M M AcJ J K S C C E B -   - E A C D H H H L L M I P P J K R C C A A -   - B A C D H H L L M M I P P J K G D C A A -   - A A D H H L L L M M B P P J AbG F C A A -   - A A D D N N L D M I B AaI K G G F D A B -   - A A D N N L L O J Y B B U Z G G F D A A -   - B A D N N D F O J I B I K G G F F D A A -   - A A D N F F F O J J I I K G G F F D A A -   - A A D F F F O I J U J K G G F F D C A B -   - E A C D F F O I K K K K G G F T D C A A -   - B A C D F F S X I I G G G F T H C C A A -   - E E A C F G F R G G G G G D D D C A E A -   - E E E A C C D F W F F D D D C C A E E B -   - E E E E A C C C D D D D C C C A E E E A -   - E E E E E A A A A A A A A A A E E E E A -   - A A A B A A A A A A A A A A A A B A A A -   - A A A A B A A A A A A A A A A B A A A A -   - A A A A A B A A A A A A A A B A A A A A -   - B A A A A A B A B B B B A B A A A A A B -   - - B A A A A A B - - - - B A A A A A B - -   - - B A B A B B - - - - - - B B A B A B - -   - - - - - - - - - - - - - - - - - - - - - -   - - - - - - - - - - - - - - - - - - - - - -   - - - - - - - - - - - - - - - - - - - - - -   - - - - - - - - - - - - - - - - - - - - - -   - - - - - - - - - - - - - - - - - - - - - -   
- - - - - - - - - - - - - - - - - - - - - -   - - - - - - - - - - - - - - - - - - - - - -   - - - - - - - - - - - - - - - - - - - - - -   - - - - - - - - - - - - - - - - - - - - - -   - - - - - - - - - - - - - - - - - - - - - -   - - - - - - - - - - - - - - - - - - - - - -   - - - - - - - - - - - - - - - - - - - - - -   - - - - - - - - - - - - - - - - - - - - - -   - - - - - - - - - - - - - - - - - - - - - -   - - - - - - - - - - - - - - - - - - - - - -   - - - - - - - - - - - - - - - - - - - - - -   - - - - - - - - - - - A - - - - - - - - - -   - - - - - - - - - - A A A - - - - - - - - -   - - - - - - - - - - - - - - - - - - - - - -   - - - - - - - - - - - - - - - - - - - - - -   - - - - - - - - - - - - - - - - - - - - - -   - - - - - - - - - - - - - - - - - - - - - -   - - - - - - - - - - - - - - - - - - - - - -   - - - - - - - - - - - - - - - - - - - - - -   - - - - - - - - - - - - - - - - - - - - - -   - - - - - - - - - - - - - - - - - - - - - -   - - - - - - - - - - - - - - - - - - - - - -   - - - - - - - - - - - - - - - - - - - - - -   - - - - - - - - - - - - - - - - - - - - - -   - - - - - - - - - - - - - - - - - - - - - -   - - - - - - - - - - - - - - - - - - - - - -   - - - - - - - - - - - - - - - - - - - - - -   - - - - - - - - - - - - - - - - - - - - - -   - - - - - - - - - - - - - - - - - - - - - -   - - - - - - - - - - - - - - - - - - - - - -   - - - - - - - - - - - - - - - - - - - - - -   
