model
size = 29 21 29, scale = 0.05, origin = -y
material 
  colors = A:#222 B:#111 C:#FF6 D:#F9F E:#C6F F:#30C G:#00A H:#66F I:#008 J:#36F K:#60F L:#00C M:#96F N:#03F O:#93F P:#C9F Q:#33C R:#009 S:#00D T:#90C U:#93C V:#309 W:#63F X:#F6F Y:#639 Z:#00B
voxels
-----------AAAAAAA----------- ----------------------------- ----------------------------- ----------------------------- ----------------------------- ----------------------------- ----------------------------- ----------------------------- ----------------------------- ----------------------------- ----------------------------- ----------------------------- ----------------------------- ----------------------------- ----------------------------- ----------------------------- ----------------------------- ----------------------------- ----------------------------- ----------------------------- ----------------------------- 
--------AAAAAAAAAAAAA-------- -----------BBBBBBB----------- ----------------------------- ----------------------------- ----------------------------- ----------------------------- ----------------------------- ----------------------------- ----------------------------- ----------------------------- ----------------------------- ----------------------------- ----------------------------- ----------------------------- ----------------------------- ----------------------------- ----------------------------- ----------------------------- ----------------------------- ----------------------------- ----------------------------- 
------AAAAAAAAAAAAAAAAA------ --------BBBBBBBBBBBBB-------- ----------------------------- ----------------------------- ----------------------------- ----------------------------- ----------------------------- ----------------------------- ----------------------------- ----------------------------- ----------------------------- ----------------------------- ----------------------------- ----------------------------- ----------------------------- ----------------------------- ----------------------------- ----------------------------- ----------------------------- ----------------------------- ----------------------------- 
-----AAAAAAAAAAAAAAAAAAA----- ------BBBBBBBBBBBBBBBBB------ ----------------------------- ----------------------------- ----------------------------- ----------------------------- ----------------------------- ----------------------------- ----------------------------- ----------------------------- ----------------------------- ----------------------------- ----------------------------- ----------------------------- ----------------------------- ----------------------------- ----------------------------- ----------------------------- ----------------------------- ----------------------------- ----------------------------- 
----AAAAAAAAAAAAAAAAAAAAA---- -----BBBBBBBBBBBBBBBBBBB----- ----------------------------- ----------------------------- ----------------------------- ----------------------------- ----------------------------- ----------------------------- ----------------------------- ----------------------------- ----------------------------- ----------------------------- ----------------------------- ----------------------------- ----------------------------- ----------------------------- ----------------------------- ----------------------------- ----------------------------- ----------------------------- ----------------------------- 
---AAAAAAAA-------AAAAAAAA--- ----BBBBBBB-------BBBBBBB---- -----------AAAAAAA----------- -----------CCCCCCC----------- -----------AAAAAAA----------- -----------AAAAAAA----------- -----------GFKQHJM----------- -----------GWKKQJJ----------- -----------LLFKHHJ----------- -----------LLFKKHH----------- -----------LLNKKHH----------- -----------FSNFKMH----------- -----------RNNZGOH----------- -----------IFNFGOE----------- -----------IFFGGOE----------- -----------DIGRGFO----------- -----------DIIIIFO----------- -----------DDDFFTU----------- -----------DDDDDXE----------- -----------AAAAAAA----------- -----------AAAAAAA----------- 
--AAAAAAA-----------AAAAAAA-- ---BBBBBB-----------BBBBBB--- ---------AA-------AA--------- ---------CC-------CC--------- ---------AA-------AA--------- ---------AA-------AA--------- --------AAM-------AA--------- ---------IG-------JA--------- ---------IG-------JJ--------- ---------IG-------JJ--------- ---------VG-------HJ--------- ---------DI-------PP--------- ---------DY-------HP--------- ---------DD-------MP--------- ---------DD-------EE--------- ---------ED-------EE--------- ---------ED-------EE--------- ---------AE-------EA--------- ---------AM-------AA--------- ---------AA-------AA--------- ---------AAAAAAAAAAA--------- 
--AAAAAA-------------AAAAAA-- ---BBBBB-------------BBBBBB-- --------A-----------A-------- --------C-----------C-------- --------A-----------A-------- --------A-----------A-------- --------A-----------A-------- --------A-----------A-------- --------A-----------A-------- --------A-----------A-------- --------A-----------A-------- --------A-----------A-------- --------A-----------A-------- --------A-----------A-------- --------A-----------A-------- --------A-----------A-------- --------A-----------A-------- --------A-----------A-------- --------A-----------A-------- --------A-----------A-------- --------AAAAAAAAAAAAA-------- 
-AAAAAA---------------AAAAAA- --BBBBB---------------BBBBB-- -------A-------------A------- -------C-------------C------- -------A-------------A------- -------A-------------A------- -------A-------------A------- -------A-------------A------- -------A-------------A------- -------A-------------A------- -------A-------------A------- -------A-------------A------- -------A-------------A------- -------A-------------A------- -------A-------------A------- -------A-------------A------- -------A-------------A------- -------A-------------A------- -------A-------------A------- -------A-------------A------- -------AAAAAAAAAAAAAAA------- 
-AAAAA-----------------AAAAA- --BBBB-----------------BBBB-- ------A---------------A------ ------C---------------C------ ------A---------------A------ ------A---------------A------ ------A---------------A------ ------A---------------A------ ------A---------------A------ ------A---------------B------ ------A---------------B------ ------A---------------A------ ------A---------------A------ ------A---------------A------ ------A---------------A------ ------A---------------A------ ------A---------------A------ ------A---------------A------ ------A---------------A------ ------A---------------A------ ------AAAAAAAAAAAAAAAAA------ 
-AAAAA------------------AAAA- --BBBB------------------BBB-- ------A----------------B----- ------C---------------C------ ------A---------------A------ ------A---------------A------ ------A---------------A------ ------A---------------B------ ------A---------------B------ ------A---------------B------ ------A---------------B------ ------A---------------B------ ------A---------------B------ ------A---------------B------ ------A---------------B------ ------A---------------B------ ------A---------------B------ ------A---------------B------ ------A---------------A------ ------A---------------A------ ------AAAAAAAAAAAAAAAAA------ 
AAAAA-------------------AAAAA -BBBB-------------------BBBB- -----A-----------------A----- -----C-----------------C----- -----A-----------------A----- -----A-----------------A----- -----A-----------------A----- -----A-----------------A----- -----B-----------------A----- -----B-----------------A----- -----B-----------------A----- -----B-----------------A----- -----A-----------------A----- -----A-----------------A----- -----A-----------------A----- -----A-----------------A----- -----A-----------------A----- -----A-----------------A----- -----A-----------------A----- -----A-----------------A----- -----AAAAAAAAAAAAAAAAAAA----- 
AAAAA-------------------AAAAA -BBBB-------------------BBBB- -----A-----------------A----- -----C-----------------C----- -----A-----------------A----- -----A-----------------A----- -----A-----------------A----- -----A-----------------A----- -----A-----------------A----- -----A-----------------A----- -----A-----------------A----- -----A-----------------A----- -----B-----------------A----- -----B-----------------A----- -----B-----------------A----- -----B-----------------A----- -----B-----------------A----- -----B-----------------A----- -----A-----------------A----- -----A-----------------A----- -----AAAAAAAAAAAAAAAAAAA----- 
AAAAA-------------------AAAAA -BBBB-------------------BBBB- -----A-----------------A----- -----C-----------------C----- -----A-----------------A----- -----A-----------------A----- -----A-----------------A----- -----A-----------------A----- -----A-----------------A----- -----A-----------------A----- -----A-----------------A----- -----A-----------------A----- -----A-----------------A----- -----A-----------------A----- -----A-----------------A----- -----A-----------------A----- -----A-----------------A----- -----A-----------------A----- -----A-----------------A----- -----A-----------------A----- -----AAAAAAAAAAAAAAAAAAA----- 
AAAAA-------------------AAAAA -BBBB-------------------BBBB- -----A--------A--------A----- -----C-----------------C----- -----A-----------------A----- -----A-----------------A----- -----A-----------------A----- -----A-----------------A----- -----A-----------------A----- -----A-----------------A----- -----A-----------------A----- -----A-----------------A----- -----A-----------------A----- -----A-----------------A----- -----A-----------------A----- -----A-----------------A----- -----A-----------------A----- -----A-----------------A----- -----A-----------------A----- -----A-----------------A----- -----AAAAAAAAAAAAAAAAAAA----- 
AAAAA-------------------AAAAA -BBBB-------------------BBBB- -----A-----------------A----- -----C-----------------C----- -----A-----------------A----- -----A-----------------A----- -----A-----------------A----- -----A-----------------A----- -----A-----------------A----- -----A-----------------A----- -----A-----------------A----- -----A-----------------A----- -----A-----------------A----- -----A-----------------A----- -----A-----------------A----- -----A-----------------A----- -----A-----------------A----- -----A-----------------A----- -----A-----------------A----- -----A-----------------A----- -----AAAAAAAAAAAAAAAAAAA----- 
AAAAA-------------------AAAAA -BBBB-------------------BBBB- -----A-----------------A----- -----C-----------------C----- -----A-----------------A----- -----A-----------------A----- -----A-----------------A----- -----A-----------------A----- -----A-----------------A----- -----A-----------------A----- -----A-----------------B----- -----A-----------------B----- -----A-----------------B----- -----A-----------------B----- -----A-----------------B----- -----A-----------------B----- -----A-----------------B----- -----A-----------------B----- -----A-----------------A----- -----A-----------------A----- -----AAAAAAAAAAAAAAAAAAA----- 
AAAAA-------------------AAAAA -BBBB-------------------BBBB- -----A-----------------A----- -----C-----------------C----- -----A-----------------A----- -----A-----------------A----- -----A-----------------A----- -----A-----------------A----- -----A-----------------A----- -----A-----------------A----- -----A-----------------A----- -----A-----------------A----- -----A-----------------A----- -----A-----------------A----- -----A-----------------A----- -----A-----------------A----- -----A-----------------A----- -----A-----------------B----- -----A-----------------B----- -----A-----------------B----- -----AAAAAAAAAAAAAAAAAAA----- 
-AAAAA-----------------AAAAA- --BBBB-----------------BBBB-- ------A---------------A------ ------C---------------C------ ------A---------------A------ ------A---------------A------ ------A---------------A------ ------A---------------A------ ------A---------------A------ ------A---------------A------ ------A---------------A------ ------A---------------A------ ------A---------------A------ ------A---------------A------ ------A---------------A------ ------A---------------A------ ------A---------------A------ ------A---------------A------ ------A---------------A------ ------A---------------A------ ------AAAAAAAAAAAAAAAAA------ 
-AAAAA-----------------AAAAA- --BBBB-----------------BBBB-- ------A---------------A------ ------C---------------C------ ------A---------------A------ ------A---------------A------ ------A---------------A------ ------A---------------A------ ------A---------------A------ ------A---------------A------ ------A---------------A------ ------A---------------A------ ------A---------------A------ ------A---------------A------ ------A---------------A------ ------A---------------A------ ------A---------------A------ ------A---------------A------ ------A---------------A------ ------A---------------A------ ------AAAAAAAAAAAAAAAAA------ 
-AAAAAA---------------AAAAAA- --BBBBB---------------BBBBB-- -------A-------------A------- -------C-------------C------- -------A-------------A------- -------A-------------A------- -------A-------------A------- -------A-------------A------- -------B-------------A------- -------B-------------A------- -------B-------------A------- -------B-------------A------- -------B-------------A------- -------B-------------A------- -------B-------------A------- -------B-------------A------- -------A-------------A------- -------A-------------A------- -------A-------------A------- -------A-------------A------- -------AAAAAAAAAAAAAAA------- 
--AAAAAA-------------AAAAAA-- ---BBBBB-------------BBBBB--- --------A-----------A-------- --------C-----------C-------- --------A-----------A-------- --------A-----------A-------- --------A-----------A-------- --------A-----------A-------- --------A-----------A-------- --------A-----------A-------- --------A-----------A-------- --------A-----------A-------- --------A-----------A-------- --------A-----------A-------- --------A-----------A-------- --------A-----------A-------- --------B-----------A-------- --------B-----------A-------- --------B-----------A-------- --------A-----------A-------- --------AAAAAAAAAAAAA-------- 
--AAAAAAA-----------AAAAAAA-- ---BBBBBB-----------BBBBBB--- ---------AA-------AA--------- ---------CC-------CC--------- ---------AA-------AA--------- ---------AA-------AA--------- ---------AA-------AA--------- ---------AA-------AA--------- ---------AA-------AA--------- ---------AA-------AA--------- ---------AA-------BA--------- ---------AA-------BA--------- ---------AA-------BA--------- ---------AA-------BA--------- ---------AA-------BA--------- ---------AA-------AA--------- ---------AA-------AA--------- ---------AA-------AA--------- ---------AA-------AA--------- ---------AA-------AA--------- ---------AAAAAAAAAAA--------- 
---AAAAAAAA-------AAAAAAAA--- ----BBBBBBB-------BBBBBBB---- -----------AAAAAAA----------- -----------CCCCCCC----------- -----------AAAAAAA----------- -----------AAAAAAA----------- -----------AAAAAAA----------- -----------AAAAAAA----------- -----------AAAAAAB----------- -----------AAAAAAB----------- -----------AAAAAAB----------- -----------AAAAAAA----------- -----------AAAAAAA----------- -----------AAAAAAA----------- -----------AAAAAAA----------- -----------AAAAAAB----------- -----------AAAAAAB----------- -----------AAAAAAA----------- -----------AAAAAAA----------- -----------AAAAAAA----------- -----------AAAAAAA----------- 
----AAAAAAAAAAAAAAAAAAAAA---- -----BBBBBBBBBBBBBBBBBBB----- ----------------------------- ----------------------------- ----------------------------- ----------------------------- ----------------------------- ----------------------------- ----------------------------- ----------------------------- ----------------------------- ----------------------------- ----------------------------- ----------------------------- ----------------------------- ----------------------------- ----------------------------- ----------------------------- ----------------------------- ----------------------------- ----------------------------- 
-----AAAAAAAAAAAAAAAAAAA----- ------BBBBBBBBBBBBBBBBB------ ----------------------------- ----------------------------- ----------------------------- ----------------------------- ----------------------------- ----------------------------- ----------------------------- ----------------------------- ----------------------------- ----------------------------- ----------------------------- ----------------------------- ----------------------------- ----------------------------- ----------------------------- ----------------------------- ----------------------------- ----------------------------- ----------------------------- 
------AAAAAAAAAAAAAAAAA------ --------BBBBBBBBBBBBB-------- ----------------------------- ----------------------------- ----------------------------- ----------------------------- ----------------------------- ----------------------------- ----------------------------- ----------------------------- ----------------------------- ----------------------------- ----------------------------- ----------------------------- ----------------------------- ----------------------------- ----------------------------- ----------------------------- ----------------------------- ----------------------------- ----------------------------- 
--------AAAAAAAAAAAAA-------- -----------BBBBBBB----------- ----------------------------- ----------------------------- ----------------------------- ----------------------------- ----------------------------- ----------------------------- ----------------------------- ----------------------------- ----------------------------- ----------------------------- ----------------------------- ----------------------------- ----------------------------- ----------------------------- ----------------------------- ----------------------------- ----------------------------- ----------------------------- ----------------------------- 
-----------AAAAAAA----------- ----------------------------- ----------------------------- ----------------------------- ----------------------------- ----------------------------- ----------------------------- ----------------------------- ----------------------------- ----------------------------- ----------------------------- ----------------------------- ----------------------------- ----------------------------- ----------------------------- ----------------------------- ----------------------------- ----------------------------- ----------------------------- ----------------------------- ----------------------------- 
