model
size = 27 26 27, scale = 0.05, origin = -y
material 
  colors = A:#600 B:#800 C:#400 D:#888 E:#555 F:#500
voxels
--------------------------- --------------------------- --------------------------- --------------------------- --------------------------- --------------------------- --------------------------- --------------------------- --------------------------- --------------------------- --------------------------- --------------------------- --------------------------- --------------------------- --------------------------- --------------------------- --------------------------- --------------------------- --------------------------- ----------------C---------- -----------CCCCCE---------- ---------CCCCCEE----------- ---------CCDEE------------- ---------EE---------------- --------------------------- --------------------------- 
--------------------------- --------------------------- --------------------------- --------------------------- --------------------------- ---------AB---------------- -----CCC-ABBB-------------- -----EDC-AABBBB------------ -----EDC-AABBBBB----------- -----EDC-AABBBBBB---------- -----EDCCAABBBBBB---------- ------DCCAAAABBBB---------- ------DCCAAAABBBB---------- ------DCCAAAABBBB---------- ------DCCAAAABBBB---------- ------DCCAAAAAABB---------- ------DCCAAAAAABB---------- ------DCCAAAAAAAB---------- ------DCCAAAAAAAA---------- ------DCCAAAAAAAACC-------- ------DCCAAAAAAAAEE-------- -------ECAAAAAAAA---------- -------ECAAAAAAAA---------- -------CDAAAAAA------------ -------E-AAAAAA------------ ---------AAAA-------------- 
--------------------------- --------------------------- --------------------------- --------------------------- ----C--AAB----------------- ----C--AAA----------------- ----FDDAAA----------------- ----CEDAAA----------------- ----CEDAAA----------------- ----CEDAAA------BBB-------- -----EDAAA------BBB-------- -----EDAAA------BBB-------- -----EDAAA------BBB-------- -----EDAAA------BBB-------- -----EDAAA------BBB-------- -----EDAAA------AAB-------- -----EDAAA------AAA-------- -----EDAAA------AAA-------- -----EDAAA------AAA-C------ -----EDAAA------AAACC------ -----EDAAA------AAAED------ -----DDAAA------AAA-------- -----DDAAA------AAA-------- -----CCCAA----------------- -----EDAAA----------------- -------AAA----------------- 
--------------------------- --------------------------- --------------------------- ---C-AAA------------------- ---CDAAA------------------- ---CDAAA------------------- ---DDAAA------------------- ---DCAAA------------------- ---DCAAA------------------- ----CAAA----------BBB------ ----CAAA----------BBB------ ----CAAA----------BBB------ ----CAAA----------BBB------ ----CAAA----------BBB------ ----CAAA----------BBB------ ----CAAA----------BBB------ ----CAAA----------AAA------ ----CAAA----------AAA------ ----CAAA----------AAAC----- ----CAAA----------AAAE----- ----CAAA----------AAA------ ----EAAA----------AAA------ ----DAAA----------AAA------ ----CAAA------------------- ----EAAA------------------- -----AAA------------------- 
--------------------------- --------------------------- ----AA--------------------- -CCDAA--------------------- -CCDAA--------------------- -CCDAA--------------------- -CEDAA--------------------- --EDAA--------------------- ---DAA--------------------- ---DAA--------------BB----- ---DAA--------------BB----- ---DAA--------------BB----- ---DAA--------------BB----- ---DAA--------------BB----- ---DAA--------------BB----- ---DAA--------------BB----- ---DAA--------------AA----- ---DAA--------------AA----- ---DAA--------------ACC---- ---DAA--------------AAE---- ---DAA--------------AA----- ---DAA--------------AA----- ---DAA--------------AA----- ---DAA--------------------- ---CAA--------------------- ---EAA--------------------- 
--------------------------- --------------------------- ---AA---------------------- -CDAA---------------------- -CDAA---------------------- -CDAA---------------------- -CEAA---------------------- -CEAA---------------------- -CEAA---------------------- -CEAA----------------B----- -CEAA----------------BB---- -CEAA----------------BB---- -CEAA----------------BB---- -CEAA----------------BB---- -CEAA----------------BA---- -CEA-----------------BA---- -CEA-----------------AA---- -CEAA----------------AA---- -CEAA----------------CCC--- -CEAA----------------AAE--- -CEAA----------------AA---- -CEAA----------------AA---- -EDAA----------------A----- -EDAA---------------------- -CCCA---------------------- --EAA---------------------- 
--------------------------- --A------------------------ --AA----------------------- -CAA----------------------- -CAA----------------------- -CAA----------------------- -CAA----------------------- -CAA----------------------- -CAA----------------------- -CAA----------------------- -CAA------------------BB--- -CAA------------------BB--- -CAA------------------BB--- -CAA------------------BB--- -CAA------------------AA--- -CAA------------------AA--- -CAA------------------AA--- -CAA------------------AA--- -CAA------------------CCC-- -CAA------------------AAE-- -CAA------------------AA--- -CAA------------------AA--- -CAA----------------------- -CAA----------------------- -CCC----------------------- --AA----------------------- 
--------------------------- --A------------------------ --A------------------------ -CA------------------------ -CA------------------------ -CA------------------------ -CA------------------------ -CA------------------------ -BB------------------------ -BB------------------------ -BB--------------------B--- -CA--------------------A--- -CA--------------------A--- -CA--------------------A--- -CA--------------------A--- -CA--------------------A--- -CA--------------------A--- -CA--------------------A--- -CA--------------------CC-- -CA--------------------AE-- -CA--------------------A--- -CA--------------------A--- -CA------------------------ -CA------------------------ -CC------------------------ -CA------------------------ 
--------------------------- -AA------------------------ -AA------------------------ CCA------------------------ CCA------------------------ CCA------------------------ CCA------------------------ CCA------------------------ BBB------------------------ BBB------------------------ BBB--------------------B--- CCA--------------------AB-- CCA--------------------AA-- CCA--------------------AA-- CCA--------------------AA-- CCA--------------------AA-- CCA--------------------AA-- CCA--------------------AA-- CCA--------------------CCC- CCA--------------------AAE- CCA--------------------AA-- CCA--------------------AA-- CCA------------------------ CAA------------------------ BAA------------------------ CAA------------------------ 
--------------------------- -A------------------------- -A------------------------- CC------------------------- CC------------------------- CC------------------------- CA------------------------- CA------------------------- BB------------------------- BB------------------------- BB------------------------- CA----------------------B-- CA----------------------A-- CA----------------------A-- CA----------------------A-- CA----------------------A-- CA----------------------A-- CA----------------------A-- CA----------------------CC- CA----------------------AD- CA----------------------A-- CA----------------------A-- CA------------------------- CA------------------------- CA------------------------- CA------------------------- 
AA------------------------- AA------------------------- AA------------------------- AA------------------------- AA------------------------- AA------------------------- AA------------------------- AA------------------------- BB------------------------- BB------------------------- BB------------------------- AA----------------------AB- AA----------------------AB- AA----------------------AB- AA----------------------AA- AA----------------------AA- AA----------------------AA- AA----------------------AA- AA----------------------CCC AA----------------------AAC AA----------------------AAE AA----------------------AA- AA------------------------- BA------------------------- BA------------------------- AA------------------------- 
A-------------------------- A-------------------------- A-------------------------- A-------------------------- A-------------------------- A-------------------------- A-------------------------- A-------------------------- B-------------------------- B-------------------------- B-------------------------- A-------------------------- A------------------------B- A------------------------B- A------------------------B- A------------------------B- A------------------------B- A------------------------A- A------------------------A- A------------------------AC A------------------------AE A------------------------A- A------------------------A- A-------------------------- A-------------------------- A-------------------------- 
A-------------------------- A-------------------------- A-------------------------- A-------------------------- A-------------------------- A-------------------------- A-------------------------- A-------------------------- B-------------------------- B-------------------------- B-------------------------- A-------------------------- A------------------------B- A------------------------B- A------------------------B- A------------------------B- A------------------------B- A------------------------A- A------------------------A- A------------------------AC A------------------------AC B------------------------AE B------------------------A- B-------------------------- A-------------------------- A-------------------------- 
B-------------------------- B-------------------------- B-------------------------- B-------------------------- B-------------------------- B-------------------------- B-------------------------- B-------------------------- B-------------------------- B-------------------------- B-------------------------- B-------------------------- B-------------------------- B------------------------B- B------------------------B- B------------------------B- B------------------------B- B------------------------B- B------------------------B- A------------------------A- A------------------------A- A------------------------A- A------------------------A- A-------------------------- A-------------------------- A-------------------------- 
B-------------------------- B-------------------------- B-------------------------- B-------------------------- B-------------------------- B-------------------------- B-------------------------- B-------------------------- B-------------------------- B-------------------------- B-------------------------- B-------------------------- B-------------------------- B------------------------B- B------------------------B- B------------------------B- B------------------------B- B------------------------B- B------------------------B- A------------------------A- B------------------------A- B------------------------A- A------------------------A- A------------------------A- A-------------------------- A-------------------------- 
B-------------------------- B-------------------------- B-------------------------- B-------------------------- B-------------------------- B-------------------------- B-------------------------- B-------------------------- B-------------------------- B-------------------------- B-------------------------- B-------------------------- B-------------------------- B------------------------B- B------------------------B- B------------------------B- B------------------------B- B------------------------B- B------------------------B- A------------------------B- A------------------------B- A------------------------B- A------------------------B- A------------------------A- A-------------------------- A-------------------------- 
B-------------------------- B-------------------------- B-------------------------- B-------------------------- B-------------------------- B-------------------------- B-------------------------- B-------------------------- B-------------------------- B-------------------------- B-------------------------- B-------------------------- B-------------------------- B------------------------B- B------------------------B- B------------------------B- B------------------------B- B------------------------B- B------------------------B- A------------------------B- A------------------------B- A------------------------B- A------------------------B- A------------------------A- A------------------------A- B-------------------------- 
BB------------------------- BB------------------------- BB------------------------- BB------------------------- BB------------------------- BB------------------------- BB------------------------- BB------------------------- BB------------------------- BB------------------------- BB------------------------- BB------------------------- BB------------------------- BB----------------------BB- BB----------------------BB- BB----------------------BB- BB----------------------BB- BB----------------------BB- BB----------------------BB- AA----------------------AB- AA----------------------AB- AA----------------------AB- AA----------------------BB- AA----------------------BB- BA----------------------BB- BA------------------------- 
-C------------------------- -A------------------------- -B------------------------- -B------------------------- -B------------------------- -A------------------------- -A------------------------- -A------------------------- -A----------------------A-- -B----------------------A-- -B----------------------A-- -B----------------------A-- -B----------------------A-- -B----------------------A-- -B----------------------A-- -B----------------------A-- -B----------------------A-- -A----------------------A-- -A----------------------A-- -A----------------------A-- -A----------------------A-- -A----------------------A-- -A----------------------B-- -A----------------------B-- -B----------------------B-- -B------------------------- 
-CA------------------------ -AA------------------------ -BB------------------------ -BB------------------------ -BB------------------------ -BB------------------------ -BB------------------------ -AA------------------------ -AA--------------------CC-- -BB--------------------CC-- -BB--------------------CC-- -BB--------------------CC-- -BB--------------------CC-- -BB--------------------CC-- -BB--------------------AA-- -BB--------------------AA-- -BB--------------------AA-- -AA--------------------AA-- -AA--------------------AA-- -AA--------------------AA-- -AA--------------------AA-- -AA--------------------AA-- -AA--------------------BB-- -BB--------------------BB-- -BB--------------------BB-- --------------------------- 
--C------------------------ --C------------------------ --B------------------------ --B------------------------ --B------------------------ --B------------------------ --B------------------------ --A------------------------ --A--------------------C--- --B--------------------C--- --B--------------------C--- --B--------------------C--- --B--------------------C--- --B--------------------C--- --B--------------------A--- --B--------------------A--- --B--------------------A--- --A--------------------A--- --A--------------------A--- --A--------------------A--- --A--------------------A--- --A--------------------A--- --B--------------------B--- --B--------------------B--- --B--------------------B--- --------------------------- 
--CC----------------------- --CC----------------------- --AA----------------------- --AA----------------------- --AA----------------------- --BA----------------------- --BB------------------CC--- --BB------------------CC--- --BB------------------CC--- --BB------------------CC--- --BB------------------CC--- --BB------------------CC--- --BA------------------CC--- --BA------------------CC--- --BA------------------AA--- --BA------------------AA--- --BA------------------AA--- --AA------------------AA--- --AA------------------AA--- --AA------------------AA--- --AA------------------AA--- --BB------------------AA--- --BB------------------AB--- --BA------------------AB--- --A-------------------AB--- ----------------------AA--- 
---CC---------------------- ---CC---------------------- ---AA---------------------- ---AA---------------------- ---AA---------------------- ---AA---------------------- ---BB----------------CC---- ---BB----------------CC---- ---BB----------------CC---- ---BB----------------CC---- ---BB----------------CC---- ---BB----------------AC---- ---AA----------------AC---- ---AA----------------AC---- ---AA----------------AA---- ---AA----------------AA---- ---AA----------------AA---- ---AA----------------AA---- ---AA----------------AA---- ---BB----------------AA---- ---BB----------------AA---- ---BA----------------AA---- ---BA----------------AA---- ---AA----------------AA---- ---------------------AA---- ---------------------AA---- 
----CC--------------------- ----CC--------------------- ----AA--------------------- ----BB--------------------- ----BB--------------------- ----BB--------------C------ ----BB--------------CC----- ----BB--------------CC----- ----BB--------------CC----- ----BA--------------CC----- ----BA--------------CC----- ----BA--------------AA----- ----AA--------------AA----- ----AA--------------AA----- ----AA--------------AA----- ----AA--------------AA----- ----AA--------------AA----- ----B---------------AA----- ----BB--------------AA----- ----BB--------------AA----- ----BA--------------AA----- ----AA--------------AA----- ----AA--------------AA----- ----AA--------------AA----- --------------------AA----- --------------------AA----- 
-----CCC------------------- -----CCC------------------- -----CCC------------------- -----BAA------------------- -----BAA------------------- -----BAA----------CCC------ -----BAA----------CCC------ -----BAA----------CCC------ -----BAA----------CCC------ -----AAA----------CCC------ -----AAA----------CCC------ -----AAA----------ABB------ -----AAA----------BBA------ -----AAA----------AAA------ -----AAA----------AAA------ -----AAA----------AAA------ -----BBB----------AAA------ -----BBB----------AAA------ -----BAA----------AAA------ -----BAA----------AAA------ -----AAA----------AAA------ -----AAA----------AAA------ -----AAA----------AAA------ -----AA-----------AAA------ ------------------AAA------ ------------------AAA------ 
--------------------------- --------------------------- -------CCC----------------- -------ACC----------------- -------ACC------CC--------- -------AAA------CCC-------- -------AAA------CCC-------- -------AAA------CCC-------- -------AAA------AAC-------- -------AAA------AAC-------- -------AAA------AAC-------- -------AAA------BBB-------- -------AAA------BBB-------- -------AAA------BBB-------- -------BBB------AAA-------- -------BBB------AAA-------- -------BBB------AAA-------- -------BAA------AAA-------- -------AAA------AAA-------- -------AAA------AAA-------- -------AAA------AAA-------- -------BBA------AAA-------- -------B--------AAA-------- ----------------AAA-------- ----------------AAA-------- ------------------A-------- 
--------------------------- --------------------------- ---------C----------------- ---------CCCC-------------- ---------CCCCCCCC---------- ---------AAACCCCC---------- ---------AAAAACCC---------- ---------AAAAACCC---------- ---------AAAAABBA---------- ---------AAABBBBA---------- ---------AAABBBAA---------- ---------AABBBBAB---------- ---------BBBBAAAB---------- ---------BBBAAABB---------- ---------BBBABBBB---------- ---------BAAABBBA---------- ---------BAABBAAA---------- ---------ABBBBAAA---------- ---------ABBBBAAA---------- ---------ABBBAAAA---------- ---------BBBBAAAA---------- ---------BBBAAAAA---------- --------------AAA---------- ---------------AA---------- ----------------A---------- --------------------------- 
