model
size = 7, scale = 0.05, origin = -y
material 
  colors = A:#FCFAF2 B:#E83015 C:#111 D:#EEE
voxels
AAAAAAA AAAAAAA AACCCAA AACACAA AACCCAA AAAAAAA AAAAAAA 
AABBBAA CAAAAAA CAAAAAA CAAAAAB DAAAAAA DAAAAAB AAACAAA 
AAAAAAA CAAAAAA AAAAAAA CAAAAAB AAAAAAA DAAAAAB AAACAAA 
AABBBAA CAAAAAB CAAAAAB CAAAAAB CAAAAAB CAAAAAB AAACAAA 
AAAAAAA DAAAAAA AAAAAAA CAAAAAB AAAAAAA CAAAAAB AACCCAA 
AABBBAA DAAAAAB DAAAAAB CAAAAAB CAAAAAB CAAAAAB AAACAAA 
AAAAAAA AAAAAAA ABBBABA ABABBBA ABBBABA AAAAAAA AAAAAAA 
