model
size = 7, scale = 0.05, origin = -y
material 
  colors = A:#D9AB42 B:#111
voxels
AAAAAAA ABAAABA AAAAAAA AAAAAAA AAAAAAA ABAAABA AAAAAAA 
ABABABA AAAAAAB AAAAAAA BAAAAAA AAAAAAA AAAAAAB AAAAAAA 
AAAAAAA AAAAAAA AAAAAAA AAAAAAA AAAAAAA AAAAAAA AAAAAAA 
AAAAAAA AAAAAAA AAAAAAA AAAAAAB AAAAAAA AAAAAAA AAABAAA 
AAAAAAA AAAAAAA AAAAAAA AAAAAAA AAAAAAA AAAAAAA AAAAAAA 
ABABABA AAAAAAB AAAAAAA BAAAAAA AAAAAAA AAAAAAB AAAAAAA 
AAAAAAA ABAAAAA AAAAAAA AAABAAA AAAAAAA AAAAABA AAAAAAA 
