model
size = 23 26 14, scale = 0.05, origin = -y
material 
  colors = A:#FF797A B:#91989F C:#86C166 D:#FFFFFB E:#222 F:#FFF G:#DDD H:#F4A7B9 I:#64363C J:#A35E47 K:#C73E3A L:#9E7A7A M:#CC543A N:#F596AA O:#884C3A P:#CB4042 Q:#C46243 R:#CB1B45 S:#904840 T:#8E354A U:#9A5034 V:#D7C4BB W:#787D7B X:#F19483 Y:#F8C3CD Z:#EEA9A9 Aa:#9F353A Ab:#D0104C Ac:#DB4D6D Ad:#FEDFE1 Ae:#724832 Af:#B54434 Ag:#A96360 Ah:#E16B8C Ai:#AB3B3A Aj:#B19693 Ak:#854836 Al:#BF6766 Am:#734338 An:#EB7A77 Ao:#F75C2F Ap:#954A45 Aq:#B5495B Ar:#E87A90 As:#DC9FB4 At:#D05A6E Au:#86473F Av:#B55D4C Aw:#B9887D Ax:#6A4028 Ay:#E83015 Az:#554236 Ba:#D75455 Bb:#994639
voxels
- - - - - - - - - - - - - - - - - - - - - - -   - - - - - - - - - - - A A - - - - - - - - - -   - - - - - - - - - - A A A A - - - - - - - - -   - - - - - - - - - A A A A A A - - - - - - - -   - - - - - - - - A A A A A A A A - - - - - - -   - - - - - - - A A A A A A A A A A - - - - - -   - - - D - - - A A A A A A A A A A - - - D - -   - - - - A A A A A A A A A A A A A A A A - - -   - - - - - - A A A A A A A A A A A A - - - - -   - - - - - - - A A A A A A A A A A - - - - - -   - - - - - - - A A A A A A A A A A - - - - - -   - - - - - - - A A A A A A A A A A - - - - - -   - - - - - - - A A A A A A A A A A - - - - - -   - - - - - - - A A A A A A A A A A - - - - - -   - - - - - - - A A A A A A A A A A - - - - - -   - - - - - - A A A A A A A A A A A A - - - - -   - - - - - - A A A A A A A A A A A A - - - - -   - - - - - - A A E E A A A A E E A A - - - - -   - - - - - - A E G G E A A E G G E A - - - - -   - - - - - - A A E E A A A A E E A A - - - - -   - - - - - - A A A A A A A A A A A A - - - - -   - - - - - - - - A A A A A A A A - - - - - - -   - - - - - - - - - A A A A A A - - - - - - - -   - - - - - - - - - - - - - - - - - - - - - - -   - - - - - - - - - - - - - - - - - - - - - - -   - - - - - - - - - - - - - - - - - - - - - - -   
- - - - - - - - - - - - - - - - - - - - - - -   - - - - - - - - - - - A A - - - - - - - - - -   - - - - - - - - - - A B B A - - - - - - - - -   - - - - - - - - - A B B B B A - - - - - - - -   - - - - - - - - - B B B B B B - - - - - - - -   - - - - - - - - A B B B B B B A - - - - - - -   - - A A D D D A A A A A A A A A A D D D A A -   - - - A A A A A A A A A A A A A A A A A A - -   - - - - A A A A A A A A A A A A A A A A - - -   - - - - - - A A A A A A A A A A A A - - - - -   - - - - - - A A A A A A A A A A A A - - - - -   - - - - - - A A A A A A A A A A A A - - - - -   - - - - - - A A A A A A A A A A A A - - - - -   - - - - - - A A A A A A A A A A A A - - - - -   - - - - - - A A A A A A A A A A A A - - - - -   - - - - - - A A A A A A A A A A A A - - - - -   - - - - - - A A A A A A A A A A A A - - - - -   - - - - - - A A E E A A A A E E A A - - - - -   - - - - - - A E G G E A A E G G E A - - - - -   - - - - - - A A E E A A A A E E A A - - - - -   - - - - - - A A A A A A A A A A A A - - - - -   - - - - - - A A A A A A A A A A A A - - - - -   - - - - - - - A A A A A A A A A A - - - - - -   - - - - - - - - A A A A A A A A - - - - - - -   - - - - - - - - - - - - - - - - - - - - - - -   - - - - - - - - - - - - - - - - - - - - - - -   
- - - - - - - - - - - - - - - - - - - - - - -   - - - - - - - - - - - - - - - - - - - - - - -   - - - - - - - - - - - - - - - - - - - - - - -   - - - - - - - - - - - - - - - - - - - - - - -   - - - - - - - - - - - - - - - - - - - - - - -   - - A A A A A A A - - - - - - A A A A A A A A   - A A A A A A A AnH I Y AjQ K BaA A A A A A A   - - D A A A A A AtAkK L Y F AhAeA A A A A D -   - - - D A A A A AgY M I L H AbF A A A A D - -   - - - - A A A A U I T K I AhAvS A A A - - - -   - - - - - A A A I Q R M K J A ApA A A - - - -   - - - - - A A A N AxP AyR X Z ArA A A - - - -   - - - - - A A A P X M F J AiAsQ A A A - - - -   - - - - - A A A M T S AnAeZ P F A A A - - - -   - - - - - A A A S AzF AtM AmX H A A A - - - -   - - - - - A A A F AlV AgAaO AiAhA A A - - - -   - - - - - A A A V AgH U A AeZ J A A A - - - -   - - - - - A A A H L AbI L R AmN A A A - - - -   - - - - - A A A AbAdU Y ArJ O AfA A A - - - -   - - - - - A A A U O AdN Q AlAeAoA A A - - - -   - - - - - A A A AdN S P F AiR O A A A - - - -   - - - - - - A A S R AcM H AqJ N A A - - - - -   - - - - - - A A B B B B B B B B A A - - - - -   - - - - - - - A A B B B B B B A A - - - - - -   - - - - - - - - - A A A A A A - - - - - - - -   - - - - - - - - - - - - - - - - - - - - - - -   
- - - - - - - - - - - - - - - - - - - - - - -   - - - - - - - - - - - - - - - - - - - - - - -   - - - - - - - - - - - - - - - - - - - - - - -   - - - - - - - - - - - - - - - - - - - - - - -   - - - - - - - - - - - - - - - - - - - - - - A   A A A A A A A A - - - - - - - - A A A A A A A   A A A A A A A B - - - - - - - - B A A A A A A   - A A A A A A B - - - - - - - - B A A A A A -   - - - A A - - B - - - - - - - - B - - A A - -   - - - - A A A B - - - - - - - - B A A A - - -   - - - - - A A B - - - - - - - - B A A - - - -   - - - - - A A B - - - - - - - - B A A - - - -   - - - - - A A B - - - - - - - B A A A - - - -   - - - - - A A A B - - - - - - B A A A - - - -   - - - - - A A A B - - - - - - B A A A - - - -   - - - - - A A A B - - - - - - B A A A - - - -   - - - - A A A A B - - - - - - B A A A A - - -   - - - - A A A A B - - - - - - B A A A A - - -   - - - - A A A A B - - - - - - B A A A A - - -   - - - - - A A A B - - - - - - B A A A - - - -   - - - - - A A A B - - - - - - B A A A - - - -   - - - - - A A A B - - - - - - B A A A - - - -   - - - - - - A A W F Z AaX AfU W A A - - - - -   - - - - - - - A A A A A A A A A A - - - - - -   - - - - - - - - A A A A A A A A - - - - - - -   - - - - - - - - - - A A A A - - - - - - - - -   
- - - - - - - - - - - - - - - - - - - - - - -   - - - - - - - - - - - - - - - - - - - - - - -   - - - - - - - - - - - - - - - - - - - - - - -   - - - - - - - - - - - - - - - - - - - - - - A   A A - - - - - - - - - - - - - - - - - - - - A   A A A A - - - - - - - - - - - - - - - - - A A   A A A A C C C B - - - - - - - - C C C C C A A   - A A A C C C B - - - - - - - - B A A A A A -   - - - D C - - B - - - - - - - - B - - A D - -   - - - - A C C B - - - - - - - - B A A A - - -   - - - - A C C B - - - - - - - - B A A - - - -   - - - - - A A B - - - - - - - - B A A - - - -   - - - - - A A B - - - - - - - B A A A - - - -   - - - - - A A A B - - - - - - B A A A - - - -   - - - - - A A A B - - - - - - B A A A - - - -   - - - - - A A A B - - - - - - B A A A - - - -   - - - - - - - - B - - - - - - B - - - - - - -   - - - - - A A A B - - - - - - B A A A - - - -   - - - - - - - - B - - - - - - B - - - - - - -   - - - - - A A A B - - - - - - B A A A - - - -   - - - - - A A A B - - - - - - B A A A - - - -   - - - - - A A A B - - - - - - B A A A - - - -   - - - - - - A A W O AkBbK H AcW A A - - - - -   - - - - - - - A A A A A A A A A A - - - - - -   - - - - - - - - A A A A A A A A - - - - - - -   - - - - - - - - - A A A A A A - - - - - - - -   
- - - - - - - - - - - - - - - - - - - - - - -   - - - - - - - - - - - - - - - - - - - - - - -   - - - - - - - - - - - - - - - - - - - - - - A   A - - - - - - - - - - - - - - - - - - - - - A   A A - - - - - - - - - - - - - - - - - - - - A   A A A A - - - - - - - - - - - - - - - - - A A   A A A A C C C B - - - - - - - - C C C C C A A   - A A A C C C B - - - - - - - - B A A A A A -   - - - D C - - B - - - - - - - - B - - A D - -   - - - - A C C B - - - - - - - - B A A A - - -   - - - - A C C B - - - - - - - - B A A - - - -   - - - - - A A B - - - - - - - - B A A - - - -   - - - - - A A B - - - - - - - B A A A A - - -   - - - - A A A A B - - - - - - B A A A A - - -   - - - - A A A A B - - - - - - B A A A A - - -   - - - - A A - A B - - - - - - B A - A A - - -   - - - - - A A A B - - - - - - B A A A - - - -   - - - - - A A A B - - - - - - B A A A - - - -   - - - - - A - A B - - - - - - B A A A - - - -   - - - - - A A A B - - - - - - B A A A - - - -   - - - - - A A A B - - - - - - B A A A - - - -   - - - - - A A A B - - - - - - B A A A - - - -   - - - - - - A A N AqL V AlAnA W A A - - - - -   - - - - - - - A A A A A A A A A A - - - - - -   - - - - - - - - A A A A A A A A - - - - - - -   - - - - - - - - - A A A A A A - - - - - - - -   
- - - - - - - - - - - - - - - - - - - - - - -   - - - - - - - - - - - - - - - - - - - - - - A   A - - - - - - - - - - - - - - - - - - - - - A   A - - - - - - - - - - - - - - - - - - - - - A   A A - - - - - - - - - - - - - - - - - - - - A   A A A A - - - - - - - - - - - - - - - - - A A   A A A A C C C B - - - - - - - - C C C C C A A   - A A A C C C B - - - - - - - - B A A A A A -   - - - A C - - B - - - - - - - - B - - A A - -   - - - - A C C B - - - - - - - - B A A A - - -   - - - - A C C B - - - - - - - - B A A - - - -   - - - - - A A B - - - - - - - - B A A A - - -   - - - - A A A B - - - - - - - - B A A A - - -   - - - - A A A B - - - - - - - - B A A A - - -   - - - - A A A B - - - - - - - - B A A A - - -   - - - - A A A B - - - - - - - - B A A A - - -   - - - - A A A B - - - - - - - - B A A A - - -   - - - - A A A B - - - - - - - - B A A A - - -   - - - - A A A B - - - - - - - - B A A A - - -   - - - - A A A B - - - - - - - - B A A A - - -   - - - - A A A B - - - - - - - - B A A A - - -   - - - - - A A B - - - - - - - - B A A - - - -   - - - - - - A B V T AbP ApAsAgJ B A - - - - -   - - - - - - - A A A A A A A A A A - - - - - -   - - - - - - - - A A A A A A A A - - - - - - -   - - - - - - - - - A A A A A A - - - - - - - -   
- - - - - - - - - - - - - - - - - - - - - - -   - - - - - - - - - - - - - - - - - - - - - - A   A - - - - - - - - - - - - - - - - - - - - - A   A - - - - - - - - - - - - - - - - - - - - - A   A A - - - - - - - - - - - - - - - - - - - - A   A A A A - - - - - - - - - - - - - - - - - A A   A A A A C C C B - - - - - - - - C C C C C A A   - A A A C C C B - - - - - - - - B A A A A A -   - - - A C - - B - - - - - - - - B - - A A - -   - - - - A C C B - - - - - - - - B A A A - - -   - - - - A C C B - - - - - - - - B A A - - - -   - - - - - A A B - - - - - - - - B A A A - - -   - - - - A A A B - - - - - - - - B A A A - - -   - - - - - D A B - - - - - - - - B A D - - - -   - - - - A A A B - - - - - - - - B A A A - - -   - - - - - D A B - - - - - - - - B A D - - - -   - - - - A A A B - - - - - - - - B A A A - - -   - - - - - D A B - - - - - - - - B A D - - - -   - - - - A A A B - - - - - - - - B A A A - - -   - - - - - D A B - - - - - - - - B A D - - - -   - - - - A A A B - - - - - - - - B A A A - - -   - - - - - A A B - - - - - - - - B A A - - - -   - - - - - - A B P H AmT Z AfAdAaB A - - - - -   - - - - - - - A A A A A A A A A A - - - - - -   - - - - - - - - A A A A A A A A - - - - - - -   - - - - - - - - - A A A A A A - - - - - - - -   
- - - - - - - - - - - - - - - - - - - - - - -   - - - - - - - - - - - - - - - - - - - - - - -   - - - - - - - - - - - - - - - - - - - - - - A   A - - - - - - - - - - - - - - - - - - - - - A   A A - - - - - - - - - - - - - - - - - - - - A   A A A A - - - - - - - - - - - - - - - - - A A   A A A A C C C B - - - - - - - - C C C C C A A   - A A A C C C B - - - - - - - - B A A A A A -   - - - D C - - B - - - - - - - - B - - A D - -   - - - - A C C B - - - - - - - - B A A A - - -   - - - - A C C B - - - - - - - - B A A - - - -   - - - - - A A B - - - - - - - - B A A A - - -   - - - - A A A B - - - - - - - - B A A A - - -   - - - - A A A B - - - - - - - - B A A A - - -   - - - - A A A B - - - - - - - - B A A A - - -   - - - - A A - B - - - - - - - - B - A A - - -   - - - - A A A B - - - - - - - - B A A A - - -   - - - - A A A B - - - - - - - - B A A A - - -   - - - - A A A B - - - - - - - - B A A A - - -   - - - - A A A B - - - - - - - - B A A A - - -   - - - - A A A B - - - - - - - - B A A A - - -   - - - - - A A B - - - - - - - - B A A - - - -   - - - - - - A B T Q AuAoK L J I B A - - - - -   - - - - - - - A A A A A A A A A A - - - - - -   - - - - - - - - A A A A A A A A - - - - - - -   - - - - - - - - - A A A A A A - - - - - - - -   
- - - - - - - - - - - - - - - - - - - - - - -   - - - - - - - - - - - - - - - - - - - - - - -   - - - - - - - - - - - - - - - - - - - - - - -   - - - - - - - - - - - - - - - - - - - - - - A   A A - - - - - - - - - - - - - - - - - - - - A   A A A A - - - - - - - - - - - - - - - - - A A   A A A A C C C B - - - - - - - - C C C C C A A   - A A A C C C B - - - - - - - - B A A A A A -   - - - A C - - B - - - - - - - - B - - A A - -   - - - - A C C B - - - - - - - - B A A A - - -   - - - - A C C B - - - - - - - - B A A - - - -   - - - - - A A B - - - - - - - - B A A A - - -   - - - - A A A B - - - - - - - - B A A A - - -   - - - - A A A B - - - - - - - - B A A A - - -   - - - - A A A B - - - - - - - - B A A A - - -   - - - - A A A B - - - - - - - - B A A A - - -   - - - - A A A B - - - - - - - - B A A A - - -   - - - - A A A B - - - - - - - - B A A A - - -   - - - - A A A B - - - - - - - - B A A A - - -   - - - - A A A B - - - - - - - - B A A A - - -   - - - - A A A B - - - - - - - - B A A A - - -   - - - - - A A B - - - - - - - - B A A - - - -   - - - - - - A B AcO K F AkAaV AwB A - - - - -   - - - - - - - A A A A A A A A A A - - - - - -   - - - - - - - - A A A A A A A A - - - - - - -   - - - - - - - - - A A A A A A - - - - - - - -   
- - - - - - - - - - - - - - - - - - - - - - -   - - - - - - - - - - - - - - - - - - - - - - -   - - - - - - - - - - - - - - - - - - - - - - -   - - - - - - - - - - - - - - - - - - - - - - -   - - - - - - - - - - - - - - - - - - - - - - A   A A A A A A A A - - - - - - - - A A A A A A A   A A A A A A A B - - - - - - - - B A A A A A A   - A A A A A A B - - - - - - - - B A A A A A -   - - - A A - - B - - - - - - - - B - - A A - -   - - - - A A A B - - - - - - - - B A A A - - -   - - - - - A A B - - - - - - - - B A A - - - -   - - - - - A A B - - - - - - - - B A A - - - -   - - - - - A A B - - - - - - - - B A A D - - -   - - - - D A A B - - - - - - - - B A A D - - -   - - - - D A A B - - - - - - - - B A A D - - -   - - - - D A A B - - - - - - - - B A A D - - -   - - - - D A A B - - - - - - - - B A A D - - -   - - - - D A A B - - - - - - - - B A A D - - -   - - - - D A A B - - - - - - - - B A A D - - -   - - - - D A A B - - - - - - - - B A A D - - -   - - - - - A A B - - - - - - - - B A A - - - -   - - - - - A A B - - - - - - - - B A A - - - -   - - - - - - A B Aj- - - - - - Y B A - - - - -   - - - - - - - A A A AcF AjX AfL A - - - - - -   - - - - - - - - A A A A A A A A - - - - - - -   - - - - - - - - - - A A A A - - - - - - - - -   
- - - - - - - - - - - A A - - - - - - - - - -   - - - - - - - - - - A A A A - - - - - - - - -   - - - - - - - - - A A A A A A - - - - - - - -   - - - - - - - - - A A A A A A - - - - - - - -   - - - - - - - - - - - - - - - - - - - - - - -   - - - A A A A A - - - - - - - - A A A A A A A   - A A A A A A A A A A A A A A A A A A A A A A   - - A A A A A A B B B B B B B B A A A A A A -   - - - A A A A B - - - - - - - - B A A A A - -   - - - - A A A B - - - - - - - - B A A - - - -   - - - - - A A B - - - - - - - - B A - - - - -   - - - - - A A B - - - - - - - - B A A - - - -   - - - - - A A B - - - - - - - - B A A - - - -   - - - - - A A B - - - - - - - - B A A - - - -   - - - - - A A B - - - - - - - - B A A - - - -   - - - - - A A B - - - - - - - - B A A - - - -   - - - - - A A B - - - - - - - - B A A - - - -   - - - - - A A B - - - - - - - - B A A - - - -   - - - - - A A B - - - - - - - - B A A - - - -   - - - - - A A B - - - - - - - - B A A - - - -   - - - - - A A A B B B B B B B B A A A - - - -   - - - - - - A A B B B B B B B B A A - - - - -   - - - - - - A A B - - - - - - B A A - - - - -   - - - - - - - A A B B B B B B A A - - - - - -   - - - - - - - - - A A A A A A - - - - - - - -   - - - - - - - - - - - - - - - - - - - - - - -   
- - - - - - - - - - - A A - - - - - - - - - -   - - - - - - - - - - A A A - - - - - - - - - -   - - - - - - - - - - A A A A - - - - - - - - -   - - - - - - - - - - A A A A - - - - - - - - -   - - - - - - - - - A A A A A A - - - - - - - -   - - - - - - - - A A A A A A A A - - - - - - -   - - - A A A A A A - - - - - - A A A A A A - -   - - - A A A A A B B B B B B B B A A A A A - -   - - - - A A A B - - - - - - - - B A A A - - -   - - - - - - A B - - - - - - - - B A - - - - -   - - - - - - A B - - - - - - - - B A - - - - -   - - - - - - A B - - - - - - - - B A - - - - -   - - - - - - A B - - - - - - - - B A - - - - -   - - - - - - A B - - - - - - - - B A - - - - -   - - - - - - A B - - - - - - - - B A - - - - -   - - - - - - A B - - - - - - - - B A - - - - -   - - - - - - A B - - - - - - - - B A - - - - -   - - - - - - A B - - - - - - - - B A - - - - -   - - - - - - A B - - - - - - - - B A - - - - -   - - - - - - A B - - - - - - - - B A - - - - -   - - - - - - A A B B B B B B B B A A - - - - -   - - - - - - A A A A A A A A A A A A - - - - -   - - - - - - - A A - - - - - - A A - - - - - -   - - - - - - - - A A A A A A A A - - - - - - -   - - - - - - - - - - - - - - - - - - - - - - -   - - - - - - - - - - - - - - - - - - - - - - -   
- - - - - - - - - - - A A - - - - - - - - - -   - - - - - - - - - - - A A - - - - - - - - - -   - - - - - - - - - - A A A A - - - - - - - - -   - - - - - - - - - - A A A A - - - - - - - - -   - - - - - - - - - A A A A A A - - - - - - - -   - - - - - - - - A A A A A A A A - - - - - - -   - - - - - - A A A - - - - - - A A A - - - - -   - - - - - A A A A A A A A A A A A A A - - - -   - - - - - - - A - - - - - - - - A - - - - - -   - - - - - - - A - - - - - - - - A - - - - - -   - - - - - - - A - - - - - - - - A - - - - - -   - - - - - - - A - - - - - - - - A - - - - - -   - - - - - - - A - - - - - - - - A - - - - - -   - - - - - - - A - - - - - - - - A - - - - - -   - - - - - - - A - - - - - - - - A - - - - - -   - - - - - - - A - - - - - - - - A - - - - - -   - - - - - - - A - - - - - - - - A - - - - - -   - - - - - - - A - - - - - - - - A - - - - - -   - - - - - - - A - - - - - - - - A - - - - - -   - - - - - - - A - - - - - - - - A - - - - - -   - - - - - - - A A A A A A A A A A - - - - - -   - - - - - - - - A A A A A A A A - - - - - - -   - - - - - - - - - - - - - - - - - - - - - - -   - - - - - - - - - - - - - - - - - - - - - - -   - - - - - - - - - - - - - - - - - - - - - - -   - - - - - - - - - - - - - - - - - - - - - - -   
