model
size = 20 25 14, scale = 0.05, origin = -y
material 
  colors = A:#FFF B:#111 C:#A00 D:#444 E:#777 F:#800 G:#888
voxels
-------------------- -------------------- --------BBBB-------- -------AABBAA------- ------AABGGBAA------ ------ABGGGGBA------ -----AAAAAAAAAA----- -----AAAAAAAAAA----- --------AAAA-------- ---------AA--------- ---------AA--------- ---------AA--------- ---------AA--------- -------CCAACC------- -------CAAAAC------- --------AAAA-------- -------------------- -------------------- -------------------- -------------------- -------------------- -------------------- -------------------- -------------------- -------------------- 
-------------------- --------AAAA-------- ------ABAAAABA------ -----AAAAAAAAAA----- -----AAAAAAAAAA----- ----AAAAAAAAAAAA---- ----AAAAAAAAAAAA---- ----AAAAAAAAAAAA---- -----AAAAAAAAAA----- -------AAAAAA------- ---------AA--------- --------CAAC-------- ----C-CCAAAACC-C---- -----CCAAAAAACC----- -----AAAAAAAAAA----- -------AAAAAA------- --------AAAA-------- -------------------- -------------------- -------------------- -------------------- -------------------- -------------------- -------------------- -------------------- 
---------AA--------- ------BBAAAABB------ ------AAAAAAAA------ -----AAAAAAAAAA----- ----AAAAAAAAAAAA---- ----AAAAAAAAAAAA---- ---CAAAAAAAAAAAAC--- ---AAAAAAAAAAAAAA--- ---AAAAAAAAAAAAAA--- -----CCCCAACCCC----- ---------CC--------- ---C----CAAC----C--- ---CC-FCAAAACF-CC--- ---ACCAAAAAAAACCA--- ----AAAAAAAAAAAA---- ----AAAAAAAAAAAA---- ------AAAAAAAA------ ------CCAAAACC------ -------------------- -------------------- -------------------- -------------------- -------------------- -------------------- -------------------- 
-------AAAAAA------- ------AAAAAAAA------ -----BAAAAAAAAB----- ----BAAAAAAAAAAB---- ----AAAAAAAAAAAA---- ---CAAAAAAAAAAAAC--- ---CAAAAAAAAAAAAC--- ---AAAAAAAAAAAAAA--- --AAAAAAAAAAAAAAAA-- --AFFFFFFAAFFFFFFA-- --C------FF------C-- --CF----FAAF----FC-- --CAF-FFFAAFFF-FAC-- --AAAFAAAAAAAAFAAA-- --AAAAAAAAAAAAAAAA-- ---AAAAAAAAAAAAAA--- ----AAAAAAAAAAAA---- -----CCAAAAAACC----- --------AAAA-------- -------------------- -------------------- -------------------- -------------------- -------------------- -------------------- 
-------AAAAAA------- ------AAAAAAAA------ -----AAAAAAAAAA----- ----AAAAAAAAAAAA---- ----CAAAAAAAAAAC---- ---CAAAAAAAAAAAAC--- ---CAAAAAAAAAAAAC--- --AAAAAAAAAAAAAAAA-- --AAAAAAAAAAAAAAAA-- --AAAAAAAAAAAAAAAA-- --ABBBBBBAABBBBBBA-- --AABBBBBAABBBBBAA-- --CAABAAAAAAAABAAC-- --AAAAAAAAAAAAAAAA-- --AAAAAAAAAAAAAAAA-- --AAAAAAAAAAAAAAAA-- --AAAAAAAAAAAAAAAA-- ---AAAAAAAAAAAAAA--- -----CCAAAAAACC----- --------AAAA-------- -------------------- -------------------- -------------------- -------------------- -------------------- 
-------AAAAAA------- ------AAAAAAAA------ -----AAAAAAAAAA----- ----AAAAAAAAAAAA---- ----CAAAAAAAAAAC---- ---CAAAAAAAAAAAAC--- ---CAAAAAAAAAAAAC--- --AAAAAAAAAAAAAAAA-- -AAAAAAAAAAAAAAAAAA- -AAAAAAAAAAAAAAAAAA- -AAAAAAAAAAAAAAAAAA- -AAAAAAAAAAAAAAAAAA- -CAAAAAAAAAAAAAAAAC- -AAAAAAAAAAAAAAAAAA- -AAAAAAAAAAAAAAAAAA- -AAAAAAAAAAAAAAAAAA- -AAAAAAAAAAAAAAAAAA- -AAAAAAAAAAAAAAAAAA- --AACAAAAAAAAAACAA-- -----CCAAAAAACC----- --------AAAA-------- -------------------- -------------------- -------------------- -------------------- 
-------AAAAAA------- ------AAAAAAAA------ -----AAAAAAAAAA----- ----AAAAAAAAAAAA---- ----CAAAAAAAAAAC---- ---CAAAAAAAAAAAAC--- ---CAAAAAAAAAAAAC--- --AAAAAAAAAAAAAAAA-- -AAAAAAAAAAAAAAAAAA- -AAAAAAAAAAAAAAAAAA- AAAAAAAAAAAAAAAAAAAA AAAAAAAAAAAAAAAAAAAA CAAAAAAAAAAAAAAAAAAC CAAAAAAAAAAAAAAAAAAC AAAAAAAAAAAAAAAAAAAA AAAAAAAAAAAAAAAAAAAA AAAAAAAAAAAAAAAAAAAA AAAAAAAAAAAAAAAAAAAA -AAAAAAAAAAAAAAAAAA- ---CCAAAAAAAAAACC--- -----CCCAAAACCC----- --------AAAA-------- -------------------- -------------------- -------------------- 
------AAAAAAAA------ ------AAAAAAAA------ -----AAAAAAAAAA----- ----AAAAAAAAAAAA---- ----CAAAAAAAAAAC---- ---CAAAAAAAAAAAAC--- ---CAAAAAAAAAAAAC--- --AAAAAAAAAAAAAAAA-- -AAAAAAAAAAAAAAAAAA- -AAAAAAAAAAAAAAAAAA- AAAAAAAAAAAAAAAAAAAA CAAAAAAAAAAAAAAAAAAC CAAAAAAAAAAAAAAAAAAC CAAAAAAAAAAAAAAAAAAC AAAAAAAAAAAAAAAAAAAA AAAAAAAAAAAAAAAAAAAA AAAAAAAAAAAAAAAAAAAA AAAAAAAAAAAAAAAAAAAA AAAAAAAAAAAAAAAAAAAA --AAAAAAAAAAAAAAAA-- -----AAAAAAAAAA----- --------AAAA-------- -------------------- -------------------- -------------------- 
------AAAAAAAA------ ------AAAAAAAA------ -----AAAAAAAAAA----- ----AAAAAAAAAAAA---- ----AAAAAAAAAAAA---- ---AAAAAAAAAAAAAA--- ---CAAAAAAAAAAAAC--- --AAAAAAAAAAAAAAAA-- -AAAAAAAAAAAAAAAAAA- -AAAAAAAAAAAAAAAAAA- AAAAAAAAAAAAAAAAAAAA CAAAAAAAAAAAAAAAAAAC CAAAAAAAAAAAAAAAAAAC CAAAAAAAAAAAAAAAAAAC AAAAAAAAAAAAAAAAAAAA AAAAAAAAAAAAAAAAAAAA AAAAAAAAAAAAAAAAAAAA AAAAAAAAAAAAAAAAAAAA AAAAAAAAAAAAAAAAAAAA -AAAAAAAAAAAAAAAAAA- -----AAAAAAAAAA----- --------AAAA-------- -------------------- -------------------- -------------------- 
------AAAAAAAA------ ------AAAAAAAA------ -----AAAAAAAAAA----- ----AAAAAAAAAAAA---- ----AAAAAAAAAAAA---- ---AAAAAAAAAAAAAA--- ---AAAAAAAAAAAAAA--- --AAAAAAAAAAAAAAAA-- -AAAAAAAAAAAAAAAAAA- -AAAAAAAAAAAAAAAAAA- AAAAAAAAAAAAAAAAAAAA AAAAAAAAAAAAAAAAAAAA CAAAAAAAAAAAAAAAAAAC CAAAAAAAAAAAAAAAAAAC AAAAAAAAAAAAAAAAAAAA AAAAAAAAAAAAAAAAAAAA AAAAAAAAAAAAAAAAAAAA AAAAAAAAAAAAAAAAAAAA AAAAAAAAAAAAAAAAAAAA -AAAAAAAAAAAAAAAAAA- -----AAAAAAAAAA----- --------AAAA-------- -------------------- -------------------- -------------------- 
------AAAAAAAA------ ------AAAAAAAA------ -----AAAAAAAAAA----- ----AAAABBBBAAAA---- ----AAAABBBBAAAA---- ---AAAAABBBBAAAAA--- ---AAABBBBBBBBAAA--- --AAAABBBBBBBBAAAA-- -AAAAABBBBBBBBAAAAA- -AAAABBBBBBBBBBAAAA- AAAAABBBBBBBBBBAAAAA AAAABBBBBBBBBBBBAAAA AAAABBBBBBBBBBBBAAAA CAAABBBBBBBBBBBBAAAC AAAABBBBBBBBBBBBAAAA AAAABBBBBBBBBBBBAAAA AAAAABBBBBBBBBBAAAAA AAAAABBBBBBBBBBAAAAA AAAAAAAAAAAAAAAAAAAA -AAAAAAAAAAAAAAAAAA- -----AAAAAAAAAA----- --------AAAA-------- -------------------- -------------------- -------------------- 
------DDDDDDDD------ ------DAAAAAAD------ -----DDDDDDDDDD----- ----DDDDD--DDDDD---- ----DDDDD--DDDDD---- ---ADDDD----DDDDA--- ---ADDD------DDDA--- --AADDD------DDDAA-- -AAADD--------DDAAA- -AAAD----------DAAA- AAADD----------DDAAA AAAD------------DAAA AAAD------------DAAA AAAD------------DAAA AAAD------------DAAA AAAD------------DAAA AAADD----------DDAAA AAADD----------DDAAA AAADDDDDDDDDDDDDDAAA AAAAAAAAAAAAAAAAAAAA A---AAAAAAAAAAAA---A A---A---AAAA---A---A -A--A----------A--A- --A-A----------A-A-- --AAA----------AAA-- 
------EEEEEEEE------ ------EEEEEEEE------ -----EEE----EEE----- ----EEEE----EEEE---- ----EEE------EEE---- ---EEE--------EEE--- ---EEE--------EEE--- --AEE----------EEA-- -AAE------------EAA- -AEE------------EEA- AAE--------------EAA AAE--------------EAA AAE--------------EAA AAE--------------EAA AAE--------------EAA AAE--------------EAA AAE--------------EAA AAEE------------EEAA AAEE------------EEAA AAAAEEEEEEEEEEEEAAAA ACCCAAAAAAAAAAAACCCA ACCCA---AAAA---ACCCA -ACCA----------ACCA- --ACA----------ACA-- --AAA----------AAA-- 
------AAAAAAAA------ ------A------A------ -----AA------AA----- ----AA--------AA---- ----A----------A---- ---AA----------AA--- ---A------------A--- --A--------------A-- -AA--------------AA- -A----------------A- AA----------------AA AA----------------AA AA----------------AA AA----------------AA AA----------------AA AA----------------AA AA----------------AA AA----------------AA AA----------------AA AAAA------------AAAA AAAAAAAAAAAAAAAAAAAA AAAAA---AAAA---AAAAA -AAAA----------AAAA- --AAA----------AAA-- --AAA----------AAA-- 
