model
size = 22 28 21, scale = 0.05, origin = -y
material 
  colors = A:#E2943B B:#74673E C:#7D532C D:#AB3B3A E:#78552B F:#6A4028 G:#C7802D H:#855B32
voxels
---C--------------C--- ---C--------------C--- ---AC------------CA--- ---AC------------CA--- ---AAC----------CAA--- ---AAAC--------CAAA--- --AAAAAC--CC--CAAAAA-- --AEAAAC--CC--CAAAEA-- --AAEAAC-CCCC-CAAEAA-- --AAAAAC--CC--CAAAAA-- ---AAACC--CC--CCAAA--- ----------CC---------- ----------CC---------- ---------CAAC--------- --------CAAAAC-------- ----------CC---------- ----------CC---------- ----------CC---------- ----------CC---------- ----------CC---------- ----------CC---------- ----------CC---------- ---------------------- ---------------------- ---------------------- ---------------------- ---------------------- ---------------------- 
---------------------- --CA--------------AC-- -CAAA------------AAAC- CAAAA------------AAAAC AAAAAA----------AAAAAA -AAAAAA--------AAAAAA- -AAAAAAA------AAAAAAA- -AAAAAAA------AAAAAAA- -AAAAAAA------AAAAAAA- -CAAAAAA------AAAAAAC- --AAAACC------CCAAAA-- --CCCC----------CCCC-- ---------------------- ---------------------- ------CCAAAAAACC------ ------AAAAAAAAAA------ ------AAAAAAAAAA------ ------AAAAAAAAAA------ ------CCCAAAACCC------ ---------CAAC--------- ---------CAAC--------- ---------------------- ---------------------- ---------------------- ---------------------- ---------------------- ---------------------- ---------------------- 
---------------------- ---------------------- -C------------------C- CA------------------AC AA------------------AA -A------------------A- -A------------------A- -A------------------A- -A------------------A- -C------------------C- --A----------------A-- --C----------------C-- ---------------------- ---------------------- ------AAAAAAAAAA------ ---CCCAAAAAAAAAACCC--- ---AAAAAAAAAAAAAAAA--- ----AAAAAAAAAAAAAA---- -----CAAAAAAAAAAC----- --------AAAAAA-------- ---------------------- ---------------------- ---------------------- ---------------------- ---------------------- ---------------------- ---------------------- ---------------------- 
---------------------- ---------------------- -C------------------C- CA------------------AC AA------------------AA -A------------------A- -A------------------A- -A------------------A- -A------------------A- -C------------------C- --A----------------A-- --C----------------C-- ---------------------- ---------------------- ------AAAAAAAAAA------ --CAAAAAAAAAAAAAAAAC-- ---AAAAAAAAAAAAAAAA--- ---CAAAAAAAAAAAAAAC--- ----CAAA--AA--AAAC---- ------AA------AA------ ---------------------- ---------------------- ---------------------- ---------------------- ---------------------- ---------------------- ---------------------- ---------------------- 
---------------------- ---------------------- ---------------------- CA------------------AC AA------------------AA -A------------------A- -A------------------A- -A------------------A- -A------------------A- -C------------------C- --A----------------A-- --C----------------C-- ---------------------- ---------------------- --C---BBBBBBBBBB---C-- --AABBBBBBBBBBBBBBAA-- ---AAAAAAAAAAAAAAAA--- ---CAAAAAAAAAAAAAAC--- ----AA----AA----AA---- -----A----------A----- ---------------------- ---------------------- ---------------------- ---------------------- ---------------------- ---------------------- ----------DD---------- ----------DD---------- 
---------------------- ---------------------- ---------------------- CA------------------AC AA------------------AA -A------------------A- -A------------------A- -A------------------A- -A------------------A- -C------------------C- --A----------------A-- --C----------------C-- ---------------------- ---------------------- --C---BBBBBBBBBB---C-- --AABBBBBBBBBBBBBBAA-- ---CAAAAAAAAAAAAAAC--- ----AAAAAAAAAAAAAA---- ----AA---AAAA---AA---- ----AA----------AA---- ---------------------- ---------------------- ---------------------- ---------------------- ---------------------- ----------DD---------- ----------DD---------- ----------DD---------- 
---------------------- ---------------------- ---------------------- CA------------------AC CA------------------AC -C------------------C- -A------------------A- -A------------------A- -A------------------A- -C------------------C- --A----------------A-- --CB--------------BC-- --C----------------C-- --C----------------C-- --A---BBBBBBBBBB---A-- --AABBBBBBBBBBBBBBAA-- ---CAAAAAAAAAAAAAAC--- ----AAAAAAAAAAAAAA---- ----A---AAAAAA---A---- ---------AEEA--------- ---------EEEE--------- ---------EEEE--------- ---------EEEE--------- ---------EEEE--------- ----------DD---------- ----------DD---------- ----------DD---------- ----------DD---------- 
---------------------- ---------------------- ---------------------- ---------------------- ---------------------- ---------------------- -CB----------------BC- -CB----------------BC- -CB----------------BC- -CB----------------BC- --A----------------A-- --AB--------------BA-- --A----------------A-- --A----------------A-- --A---BBBBBBBBBB---A-- --AABBBBBBBBBBBBBBAA-- ---CAAAAAAAAAAAAAAC--- ----AAAAAAAAAAAAAA---- -------AAAAAAAA------- --------AADDAA-------- ---------EDDE--------- ---------EDDE--------- ---------EDDE--------- ---------EDDE--------- ----------DD---------- ----------DD---------- ----------DD---------- ----------DD---------- 
---------------------- ---------------------- ---------------------- ---------------------- ---------------------- ---------------------- ---------------------- ---------------------- ---------------------- -CA----------------AC- --A----------------A-- --AB--------------BA-- --A----------------A-- --A----------------A-- --A---BBBBBBBBBB---A-- --AABBBBBBBBBBBBBBAA-- ---CAAAAAAAAAAAAAAC--- ----AAAAAAAAAAAAAA---- ------AAAAAAAAAA------ -------AAADDAAA------- --------AADDAA-------- ---------EDDE--------- ---------EDDE--------- ----------DD---------- ----------DD---------- ----------DD---------- ----------DD---------- ---------------------- 
---------------------- ---------------------- ---------------------- ---------------------- ---------------------- ---------------------- ---------------------- ---------------------- ---------------------- -FA----------------AF- --A----------------A-- --AB--------------BA-- --A----------------A-- --A----------------A-- --A---BBBBBBBBBB---A-- --AABBBBBBBBBBBBBBAA-- ---CAAAAAAAAAAAAAAC--- ----AAAAAAAAAAAAAA---- -----AAAAAAAAAAAA----- ------AAAADDAAAA------ --------AADDAA-------- ---------HDDH--------- ---------EDDE--------- ----------DD---------- ----------DD---------- ----------DD---------- ----------DD---------- ---------------------- 
---------------------- ---------------------- ---------------------- ---------------------- ---------------------- ---------------------- ---------------------- ---------------------- -FA----------------AF- -FA----------------AF- --A----------------A-- --AB--------------BA-- --A----------------A-- --A----------------A-- --A---BBBBBBBBBB---A-- ---ABBBBBBBBBBBBBBA--- ---CAAAAAAAAAAAAAAC--- ----AAAAAAAAAAAAAA---- -----AAAAAAAAAAAA----- ------AAAADDAAAA------ -------AAADDAAA------- ---------HDDH--------- ---------EDDE--------- ----------DD---------- ----------DD---------- ----------DD---------- ----------DD---------- ---------------------- 
---------------------- ---------------------- ---------------------- ---------------------- ---------------------- ---------------------- ---------------------- ---------------------- -FA----------------AF- -FA----------------AF- --A----------------A-- --AB--------------BA-- --A----------------A-- --A----------------A-- --AABBBBBBBBBBBBBBAA-- ---ABBBBBBBBBBBBBBA--- ----AAAAAAAAAAAAAA---- ----AAAAAAAAAAAAAA---- -----AAAAAAAAAAAA----- ------AAAADDAAAA------ -------AAADDAAA------- ---------HDDH--------- ---------EDDE--------- ----------DD---------- ----------DD---------- ----------DD---------- ---------------------- ---------------------- 
---------------------- ---------------------- ---------------------- ---------------------- ---------------------- ---------------------- ---------------------- ---------------------- -FA----------------AF- --A----------------A-- --A----------------A-- --AB--------------BA-- --A----------------A-- --AABB----------BBAA-- --AABBBBBBBBBBBBBBAA-- ---ABBBBBBBBBBBBBBA--- ----AAAAAAAAAAAAAA---- ----GAAAAAAAAAAAAG---- -----AAAAAAAAAAAA----- ------AAAADDAAAA------ --------AADDAA-------- ---------HDDH--------- ---------EDDE--------- ----------DD---------- ----------DD---------- ----------DD---------- ---------------------- ---------------------- 
---------------------- ---------------------- ---------------------- ---------------------- ---------------------- ---------------------- ---------------------- ---------------------- -FA----------------AF- --A----------------A-- --A----------------A-- --AB--------------BA-- --AABB----------BBAA-- --AABB----------BBAA-- --AABBBBBBBBBBBBBBAA-- ---ABBBBBBBBBBBBBBA--- ----AAAAAAAAAAAAAA---- ----GAAAAAAAAAAAAG---- ------AAAAAAAAAA------ ------AAAADDAAAA------ --------AADDAA-------- ---------EDDE--------- ----------DD---------- ----------DD---------- ----------DD---------- ----------DD---------- ---------------------- ---------------------- 
---------------------- ---------------------- ---------------------- ---------------------- ---------------------- ---------------------- ---------------------- -FA----------------AF- -FA----------------AF- --A----------------A-- --A----------------A-- ---B--------------B--- --AABB----------BBAA-- --AABB----------BBAA-- --AABBBBBBBBBBBBBBAA-- ---ABBBBBBBBBBBBBBA--- ----AAAAAAAAAAAAAA---- ----GGAAAAAAAAAAGG---- ------AAAAAAAAAA------ -------AAADDAAA------- ---------EDDE--------- ----------DD---------- ----------DD---------- ----------DD---------- ----------DD---------- ---------------------- ---------------------- ---------------------- 
---------------------- ---------------------- ---------------------- ---------------------- ---------------------- ---------------------- ---------------------- -FA----------------AF- --A----------------A-- --A----------------A-- --A----------------A-- ---B--------------B--- --AAAB----------BAAA-- --AAAB----------BAAA-- --AAABBBBBBBBBBBBAAA-- ---AABBBBBBBBBBBBAA--- -----AAAAAAAAAAAA----- -----GAAAAAAAAAAG----- -------AAAAAAAA------- --------AADDAA-------- ---------EDDE--------- ----------DD---------- ----------DD---------- ----------DD---------- ---------------------- ---------------------- ---------------------- ---------------------- 
---------------------- ---------------------- ---------------------- ---------------------- ---------------------- ---------------------- ---------------------- -FA----------------AF- --AA--------------AA-- ---AA------------AA--- ---AA------------AA--- ---AABB--------BBAA--- --AAABB--------BBAAA-- --AAABBBBBBBBBBBBAAA-- ----ABBBBBBBBBBBBA---- ----ABBBBBBBBBBBBA---- -----AAAAAAAAAAAA----- -----GAAAAAAAAAAG----- --------AAAAAA-------- ---------EDDE--------- ----------DD---------- ----------DD---------- ----------DD---------- ---------------------- ---------------------- ---------------------- ---------------------- ---------------------- 
---------------------- ---------------------- ---------------------- ---------------------- ---------------------- ---------------------- ---------------------- --FAA------------AAF-- ---AA------------AA--- ---AA------------AA--- ---AABB--------BBAA--- ---AABB--------BBAA--- --AAABB--------BBAAA-- ----AAABBBBBBBBAAA---- ----AAAAAAAAAAAAAA---- ----AAAAAAAAAAAAAA---- ------AAAAAAAAAA------ ------GAAAAAAAAG------ ---------HAAH--------- ---------EDDE--------- ----------DD---------- ----------DD---------- ---------------------- ---------------------- ---------------------- ---------------------- ---------------------- ---------------------- 
---------------------- ---------------------- ---------------------- ---------------------- ---------------------- ---------------------- ----A------------A---- --FAA------------AAF-- ---AA------------AA--- ---AA------------AA--- ---AABBBBBBBBBBBBAA--- ---AAAABBBBBBBBAAAA--- --AAAAABBBBBBBBAAAAA-- ----AAABBBBBBBBAAA---- -----AAAAAAAAAAAA----- -----AAAAAAAAAAAA----- ------AAAAAAAAAA------ ------GAAAAAAAAG------ ---------EAAE--------- ----------DD---------- ----------DD---------- ----------DD---------- ---------------------- ---------------------- ---------------------- ---------------------- ---------------------- ---------------------- 
---------------------- ---------------------- ---------------------- ---------------------- ---------------------- ---------------------- -------AAAAAAAA------- -----AABBBBBBBBAA----- -----BBBBBBBBBBBB----- ----ABBBBBBBBBBBBA---- ---AAAAAAAAAAAAAAAA--- ---AAAAAAAAAAAAAAAA--- ---AAAAAAAAAAAAAAAA--- ----AAAAAAAAAAAAAA---- -----AAAAAAAAAAAA----- -----AAAAAAAAAAAA----- -------AAAAAAAA------- -------GGGAAGGG------- ---------EEEE--------- ----------DD---------- ----------DD---------- ---------------------- ---------------------- ---------------------- ---------------------- ---------------------- ---------------------- ---------------------- 
---------------------- ---------------------- ---------------------- ---------------------- ---------------------- ---------------------- ---------AAAA--------- ------AAAAAAAAAA------ ------AAAAAAAAAA------ -----AAAAAAAAAAAA----- -----AAAAAAAAAAAA----- ---AAAAAAAAAAAAAAAA--- ---AAAAAAAAAAAAAAAA--- -----AAAAAAAAAAAA----- ------AAAAAAAAAA------ --------AAAAAA-------- ---------AAAA--------- ---------EEEE--------- ---------------------- ---------------------- ---------------------- ---------------------- ---------------------- ---------------------- ---------------------- ---------------------- ---------------------- ---------------------- 
