model
size = 22 23 21, scale = 0.05, origin = -y
material 
  colors = A:#E2943B B:#74673E C:#7D532C D:#C7802D E:#6A4028 F:#78552B
voxels
---C--------------C--- ---C--------------C--- ---AC------------CA--- ---AC------------CA--- ---AAC----------CAA--- ---AAAC--------CAAA--- --AAAAAC--CC--CAAAAA-- --AFAAAC--CC--CAAAFA-- --AAFAAC-CCCC-CAAFAA-- --AAAAAC--CC--CAAAAA-- ---AAACC--CC--CCAAA--- ----------CC---------- ----------CC---------- ---------CAAC--------- --------CAAAAC-------- ----------CC---------- ----------CC---------- ----------CC---------- ----------CC---------- ----------CC---------- ----------CC---------- ----------CC---------- ---------------------- 
---------------------- --CA--------------AC-- -CAAA------------AAAC- CAAAA------------AAAAC AAAAAA----------AAAAAA -AAAAAA--------AAAAAA- -AAAAAAA------AAAAAAA- -AAAAAAA------AAAAAAA- -AAAAAAA------AAAAAAA- -CAAAAAA------AAAAAAC- --AAAACC------CCAAAA-- --CCCC----------CCCC-- ---------------------- ---------------------- ------CCAAAAAACC------ ------AAAAAAAAAA------ ------AAAAAAAAAA------ ------AAAAAAAAAA------ ------CCCAAAACCC------ ---------CAAC--------- ---------CAAC--------- ---------------------- ---------------------- 
---------------------- ---------------------- -C------------------C- CA------------------AC AA------------------AA -A------------------A- -A------------------A- -A------------------A- -A------------------A- -C------------------C- --A----------------A-- --C----------------C-- ---------------------- ---------------------- ------AAAAAAAAAA------ ---CCCAAAAAAAAAACCC--- ---AAAAAAAAAAAAAAAA--- ----AAAAAAAAAAAAAA---- -----CAAAAAAAAAAC----- --------AAAAAA-------- ---------------------- ---------------------- ---------------------- 
---------------------- ---------------------- -C------------------C- CA------------------AC AA------------------AA -A------------------A- -A------------------A- -A------------------A- -A------------------A- -C------------------C- --A----------------A-- --C----------------C-- ---------------------- ---------------------- ------AAAAAAAAAA------ --CAAAAAAAAAAAAAAAAC-- ---AAAAAAAAAAAAAAAA--- ---CAAAAAAAAAAAAAAC--- ----CAAA--AA--AAAC---- ------AA------AA------ ---------------------- ---------------------- ---------------------- 
---------------------- ---------------------- ---------------------- CA------------------AC AA------------------AA -A------------------A- -A------------------A- -A------------------A- -A------------------A- -C------------------C- --A----------------A-- --C----------------C-- ---------------------- ---------------------- --C---BBBBBBBBBB---C-- --AABBBBBBBBBBBBBBAA-- ---AAAAAAAAAAAAAAAA--- ---CAAAAAAAAAAAAAAC--- ----AA----AA----AA---- -----A----------A----- ---------------------- ---------------------- ---------------------- 
---------------------- ---------------------- ---------------------- CA------------------AC AA------------------AA -A------------------A- -A------------------A- -A------------------A- -A------------------A- -C------------------C- --A----------------A-- --C----------------C-- ---------------------- ---------------------- --C---BBBBBBBBBB---C-- --AABBBBBBBBBBBBBBAA-- ---CAAAAAAAAAAAAAAC--- ----AAAAAAAAAAAAAA---- ----AA---AAAA---AA---- ----AA----AA----AA---- ---------------------- ---------------------- ---------------------- 
---------------------- ---------------------- ---------------------- CA------------------AC CA------------------AC -C------------------C- -A------------------A- -A------------------A- -A------------------A- -C------------------C- --A----------------A-- --CB--------------BC-- --C----------------C-- --C----------------C-- --A---BBBBBBBBBB---A-- --AABBBBBBBBBBBBBBAA-- ---CAAAAAAAAAAAAAAC--- ----AAAAAAAAAAAAAA---- ----A---AAAAAA---A---- ---------AAAA--------- ---------------------- ---------------------- ---------------------- 
---------------------- ---------------------- ---------------------- ---------------------- ---------------------- ---------------------- -CB----------------BC- -CB----------------BC- -CB----------------BC- -CB----------------BC- --A----------------A-- --AB--------------BA-- --A----------------A-- --A----------------A-- --A---BBBBBBBBBB---A-- --AABBBBBBBBBBBBBBAA-- ---CAAAAAAAAAAAAAAC--- ----AAAAAAAAAAAAAA---- -------AAAAAAAA------- --------AAAAAA-------- ----------AA---------- ---------------------- ---------------------- 
---------------------- ---------------------- ---------------------- ---------------------- ---------------------- ---------------------- ---------------------- ---------------------- ---------------------- -CA----------------AC- --A----------------A-- --AB--------------BA-- --A----------------A-- --A----------------A-- --A---BBBBBBBBBB---A-- --AABBBBBBBBBBBBBBAA-- ---CAAAAAAAAAAAAAAC--- ----AAAAAAAAAAAAAA---- ------AAAAAAAAAA------ -------AAAAAAAA------- --------AAAAAA-------- ---------------------- ---------------------- 
---------------------- ---------------------- ---------------------- ---------------------- ---------------------- ---------------------- ---------------------- ---------------------- ---------------------- -EA----------------AE- --A----------------A-- --AB--------------BA-- --A----------------A-- --A----------------A-- --A---BBBBBBBBBB---A-- --AABBBBBBBBBBBBBBAA-- ---CAAAAAAAAAAAAAAC--- ----AAAAAAAAAAAAAA---- -----AAAAAAAAAAAA----- ------AAAAAAAAAA------ --------AAAAAA-------- ---------AAAA--------- ---------------------- 
---------------------- ---------------------- ---------------------- ---------------------- ---------------------- ---------------------- ---------------------- ---------------------- -EA----------------AE- -EA----------------AE- --A----------------A-- --AB--------------BA-- --A----------------A-- --A----------------A-- --A---BBBBBBBBBB---A-- ---ABBBBBBBBBBBBBBA--- ---CAAAAAAAAAAAAAAC--- ----AAAAAAAAAAAAAA---- -----AAAAAAAAAAAA----- ------AAAAAAAAAA------ -------AAAAAAAA------- ---------AAAA--------- ----------DD---------- 
---------------------- ---------------------- ---------------------- ---------------------- ---------------------- ---------------------- ---------------------- ---------------------- -EA----------------AE- -EA----------------AE- --A----------------A-- --AB--------------BA-- --A----------------A-- --A----------------A-- --AABBBBBBBBBBBBBBAA-- ---ABBBBBBBBBBBBBBA--- ----AAAAAAAAAAAAAA---- ----AAAAAAAAAAAAAA---- -----AAAAAAAAAAAA----- ------AAAAAAAAAA------ -------AAAAAAAA------- ---------AAAA--------- ----------DD---------- 
---------------------- ---------------------- ---------------------- ---------------------- ---------------------- ---------------------- ---------------------- ---------------------- -EA----------------AE- --A----------------A-- --A----------------A-- --AB--------------BA-- --A----------------A-- --AABB----------BBAA-- --AABBBBBBBBBBBBBBAA-- ---ABBBBBBBBBBBBBBA--- ----AAAAAAAAAAAAAA---- ----DAAAAAAAAAAAAD---- -----AAAAAAAAAAAA----- ------AAAAAAAAAA------ --------AAAAAA-------- ---------AAAA--------- ---------------------- 
---------------------- ---------------------- ---------------------- ---------------------- ---------------------- ---------------------- ---------------------- ---------------------- -EA----------------AE- --A----------------A-- --A----------------A-- --AB--------------BA-- --AABB----------BBAA-- --AABB----------BBAA-- --AABBBBBBBBBBBBBBAA-- ---ABBBBBBBBBBBBBBA--- ----AAAAAAAAAAAAAA---- ----DAAAAAAAAAAAAD---- ------AAAAAAAAAA------ ------AAAAAAAAAA------ --------AAAAAA-------- ---------------------- ---------------------- 
---------------------- ---------------------- ---------------------- ---------------------- ---------------------- ---------------------- ---------------------- -EA----------------AE- -EA----------------AE- --A----------------A-- --A----------------A-- ---B--------------B--- --AABB----------BBAA-- --AABB----------BBAA-- --AABBBBBBBBBBBBBBAA-- ---ABBBBBBBBBBBBBBA--- ----AAAAAAAAAAAAAA---- ----DDAAAAAAAAAADD---- ------AAAAAAAAAA------ -------AAAAAAAA------- ----------AA---------- ---------------------- ---------------------- 
---------------------- ---------------------- ---------------------- ---------------------- ---------------------- ---------------------- ---------------------- -EA----------------AE- --A----------------A-- --A----------------A-- --A----------------A-- ---B--------------B--- --AAAB----------BAAA-- --AAAB----------BAAA-- --AAABBBBBBBBBBBBAAA-- ---AABBBBBBBBBBBBAA--- -----AAAAAAAAAAAA----- -----DAAAAAAAAAAD----- -------AAAAAAAA------- --------AAAAAA-------- ---------------------- ---------------------- ---------------------- 
---------------------- ---------------------- ---------------------- ---------------------- ---------------------- ---------------------- ---------------------- -EA----------------AE- --AA--------------AA-- ---AA------------AA--- ---AA------------AA--- ---AABB--------BBAA--- --AAABB--------BBAAA-- --AAABBBBBBBBBBBBAAA-- ----ABBBBBBBBBBBBA---- ----ABBBBBBBBBBBBA---- -----AAAAAAAAAAAA----- -----DAAAAAAAAAAD----- --------AAAAAA-------- ----------AA---------- ---------------------- ---------------------- ---------------------- 
---------------------- ---------------------- ---------------------- ---------------------- ---------------------- ---------------------- ---------------------- --EAA------------AAE-- ---AA------------AA--- ---AA------------AA--- ---AABB--------BBAA--- ---AABB--------BBAA--- --AAABB--------BBAAA-- ----AAABBBBBBBBAAA---- ----AAAAAAAAAAAAAA---- ----AAAAAAAAAAAAAA---- ------AAAAAAAAAA------ ------DAAAAAAAAD------ ---------AAAA--------- ---------------------- ---------------------- ---------------------- ---------------------- 
---------------------- ---------------------- ---------------------- ---------------------- ---------------------- ---------------------- ----A------------A---- --EAA------------AAE-- ---AA------------AA--- ---AA------------AA--- ---AABBBBBBBBBBBBAA--- ---AAAABBBBBBBBAAAA--- --AAAAABBBBBBBBAAAAA-- ----AAABBBBBBBBAAA---- -----AAAAAAAAAAAA----- -----AAAAAAAAAAAA----- ------AAAAAAAAAA------ ------DAAAAAAAAD------ ----------AA---------- ---------------------- ---------------------- ---------------------- ---------------------- 
---------------------- ---------------------- ---------------------- ---------------------- ---------------------- ---------------------- -------AAAAAAAA------- -----AABBBBBBBBAA----- -----BBBBBBBBBBBB----- ----ABBBBBBBBBBBBA---- ---AAAAAAAAAAAAAAAA--- ---AAAAAAAAAAAAAAAA--- ---AAAAAAAAAAAAAAAA--- ----AAAAAAAAAAAAAA---- -----AAAAAAAAAAAA----- -----AAAAAAAAAAAA----- -------AAAAAAAA------- -------DDDAADDD------- ---------------------- ---------------------- ---------------------- ---------------------- ---------------------- 
---------------------- ---------------------- ---------------------- ---------------------- ---------------------- ---------------------- ---------AAAA--------- ------AAAAAAAAAA------ ------AAAAAAAAAA------ -----AAAAAAAAAAAA----- -----AAAAAAAAAAAA----- ---AAAAAAAAAAAAAAAA--- ---AAAAAAAAAAAAAAAA--- -----AAAAAAAAAAAA----- ------AAAAAAAAAA------ --------AAAAAA-------- ---------AAAA--------- ----------DD---------- ---------------------- ---------------------- ---------------------- ---------------------- ---------------------- 
