model
size = 15 24 32, scale = 0.05, origin = -y
material 
  colors = A:#EEE B:#66F C:#919191 D:#BBB E:#FCC F:#B28065 G:#202020 H:#2D2D2D I:#F90 J:#100 K:#F0F L:#633
voxels
48-2B5C2B7-7B309-5C8-9C5-3B5E3B5-2A5B2A7-7A9-5A264-7C7-9C5-C9FC3-2B9E2B3-A8B2A5-A6BA8-2A3B2A10-3A249-C7-C5-11C3-2B9E2B3-2(A9BA4-)A8BA6-2A4B2A9-5A247-11C3-3C5(FC)-2B11E2B-A11BA3-A9BA4-A9BA5-2A4B3A8-5A246-C11-C2-13C-2B11E2B-A11BA2-A11BA3-A9BA5-A6B2A7-7A245-13C-2B5(EC)E2B-2(A11BA2-)A11BA3-A9B2A4-A7BA7-7A245-C11-C-2B11C2B-2(A11BA2-)A11BA3-A9B2A4-A7BA7-7A245-13C-2B5(EC)E2B-A11BA2-A11BA3-A10BA3-A9B2A4-A7BA7-7A246-C10-C2-2B10C2B2-3(A10BA3-)A9B2A4-A7BA7-7A246-12C2-2B5(CE)2B2-2(A10BA3-)A10BA4-A9BA4-A7B2A6-7A247-C9-C3-2B9C2B3-3(A9BA4-)2(A8BA5-)9A246-11C3-2B4(EC)EB2(4-A9BA)4-3(A8BA5-)9A22-5G219-C8-C4-2B8C2B4-4(A8BA5-)7AB2A5-A7BA6-I6AI13-G9-4G87-3A11-5A99-10C5-4(CF)2C4-2B8E2B4-2(A8BA5-)A7B2A5-A6-A7-8A7-G6AG7-I6-I11-2G10-G88-6A11-5A98-10C4-2B8E2B4-2(A8BA5-)A7B2(A6-)A7-A6-A7-8A7-G6-2G6-I4-2GI9-G28-3G56-A15-6A98-10C4-2B8E2B4-2(A8BA5-)A7B2(A6-)2A2(6-A)7-A6-A7-8A7-7A2G6-G2-2G2-A7-I4-2GI10-3G55-6A8-3A102-10C5-C8FC4-2B8E2B4-A8BA5-A7B2(A6-)2A2(6-A)3(7-A6-A)7-8A7-7AG7-8A7-G4-2GA7-I6-I8-6A9-3A12-A118-10C4-2B8E2B4-A8BA5-A7B2(A6-)2A6-A6-2A4-2(I-A6-A5-)3(G-A6-A5-)G-A6-A7-7A3G5-8AG5-GA6-A7-A6-I7-I119-9C5-2B7E2B5-2(A7BA6-)2(A6-2A6-)4(A6-A7-)2(A6-)GA6-A2-G3-GA6-A-G4-GA6-A7-A14-A6-A14-2(A7-A6-)I7-I6-I67-9C6-B7E2B5-A7BAB5-A7B2(A6-)3(2A6-A6-)3(A7-A6-)A3-G3-A6-A2-G4-5(A6-A7-)A14-2(A6-A7-)I6-I52-9C6-C7FC5-2B7E2B5-A7B2(A6-)3(2A6-A6-)A7-2(A6-A3-G3-)6(A6-A7-)4(H6-H7-)H6-H22-2C2(-C)-2C6-9C2(6-C7FC)5-2B7E2B5-A7B2(A6-)3(2A6-A6-)2(A3-G3-A6-)2(K7-A6-)3(A7-A6-)A2(7-H6-H)4(7-D6-D)22-C13-CF8C2(5-C8FC)4-2B8E2B4-A8BA5-2(2A6-)A6-2A6-A6-2A2-G3-A6-2A2(6-A)7-A6-A3(7-A6-K)2(7-A6-A)2(6-2H)5(5-2D6-2D)20-3C2-C2-2C5-CF8C2(5-C8FC)4-2B8E2B4-A8BA5-2A6-2A2-G2-2A6-2A2-G3-2(A6-2A6-)3(A6-A7-)A6-K7-A6-A7-A6-K7-2(A6-)2H6-2H5(5-2D6-2D)21-C2-C-C8-CF8C5-C5FL2FC5-C8FC2-I-2B8E2B-I2-A8BA2(2-G2-2A6-2A)5-2(2A6-)2(A6-2A6-)A6-A3(7-A6-K)2(7-A6-A)2(6-2H)5(5-2D6-2D)5-D8-D5-2C2-3C2-C5-CF8C5-C2FLFL3FC5-C8FC4-2B8E2B4-A8BA4(5-2A6-2A)6-A6-2A6-2(A6-K7-)3(A6-A7-)2(A6-)2H6-2H5(5-2D6-2D)5-D8-D6-C2(-2C)7-CF5CL2C5-C6FLFC5-C8FC4-2B8E2B4-A8BA4(5-2A6-2A)6-A6-2A2(6-A)5(7-A6-A)2(6-2H)5(5-2D6-2D)5-D8-D5-2C-C3-C-C5-CF8C5-C5FL2FC5-C8FC4-2B8E2B4-2A6B2A5-3A4-B2A4(5-3A4-3A)6-5(2A4-2A7-)2A4-2A6-3H4-3H4(5-DJD4-DJD)5-DGD4-DGD5-2(2D6-)2C4-C8-6CF2(C7-C6F)C7-B6E2B6-2A4B2A5(7-8A)8-3(6A9-)6A8-7A8-AB5A8-6HJH7-DJ4DH3(D7-DB4DB)D7-DG4DGD7-2D4-2D8-6C3(9-C4FC)9-B4E2B8-3(A3B2A9-)2(2A2B2A9-)2A2B2A10-4(4A11-)4A10-6A9-6H9-D4J3(D9-D4B)D9-D4GD9-6D10-C-C11-3(5C10-)6B10-5(4A11-)4A100-5H5(10-5D)11-3D7-
