model
size = 16 30 16, scale = 0.05, origin = -y
material 
  colors = A:#603
voxels
---------------- ---------------- ---------------- ---------------- ---------------- ---------------- AAAAAAAAAAAAAAAA AAAAAAAAAAAAAAAA AAAAAAAAAAAAAAAA AAAAAAA---AAAAAA AAAAA-------AAAA AAAA--------AAAA AAAA---------AAA AAA----------AAA AAA----------AAA AAA----------AAA AAAA---------AAA AAAA--------AAAA AAAAAA-----AAAAA AAAAAAAAAAAAAAAA AAAAAAAAAAAAAAAA AAAAAAAAAAAAAAAA AAAAAAAAAAAAAAAA ---------------- ---------------- ---------------- ---------------- ---------------- ---------------- ---------------- 
---------------- ---------------- ---------------- ---------------- ---------------- ---------------- AAAAAAAAAAAAAAAA AAAAAAAAAAAAAAAA AAAAAAAAAAAAAAAA AAAAAAA--AAAAAAA AAAAA------AAAAA AAAA--------AAAA AAAA---------AAA AAA----------AAA AAA----------AAA AAAA---------AAA AAAA---------AAA AAAAA-------AAAA AAAAAA-----AAAAA AAAAAAAAAAAAAAAA AAAAAAAAAAAAAAAA AAAAAAAAAAAAAAAA AAAAAAAAAAAAAAAA -AAAAAAAAAAAAAA- ---------------- ---------------- ---------------- ---------------- ---------------- ---------------- 
---------------- ---------------- ---------------- ---------------- ---AAAAAAAAAA--- --AAAAAAAAAAAA-- AAAAAAAAAAAAAAAA AAAAAAAAAAAAAAAA AAAAAAAAAAAAAAAA AAAAAAAAAAAAAAAA AAAAAA-----AAAAA AAAAA-------AAAA AAAA--------AAAA AAAA---------AAA AAAA---------AAA AAAA---------AAA AAAA--------AAAA AAAAA------AAAAA AAAAAAA---AAAAAA AAAAAAAAAAAAAAAA AAAAAAAAAAAAAAAA AAAAAAAAAAAAAAAA AAAAAAAAAAAAAAAA -AAAAAAAAAAAAAA- --AAAAAAAAAAAA-- ---AAAAAAAAAA--- ---------------- ---------------- ---------------- ---------------- 
---------------- ---------------- ---------------- ----AAAAAAAA---- ---AAAAAAAAAA--- --AAAAAAAAAAAA-- AAAAAAAAAAAAAAAA AAAAAAA--AAAAAAA AAAAAAAAAAAAAAAA AAAAAAAAAAAAAAAA AAAAA------AAAAA AAAA--------AAAA AAAA---------AAA --AA---------AA- --AA---------AA- -AAA---------AA- AAAA--------AAAA AAAAA-------AAAA AAAAAA----AAAAAA AAAAAAAAAAAAAAAA AAAAAAAAAAAAAAAA AAAAAAAAAAAAAAAA AAAAAAAAAAAAAAAA -AAAAAAAAAAAAAA- --AAAAAAAAAAAA-- ---AAAAAAAAAA--- ----AAAAAAAA---- ---------------- ---------------- ---------------- 
---------------- ---------------- -----AAAAAA----- ----AAAAAAAA---- ---AAAAAAAAAA--- --AAAAAAAAAAAA-- AAAAAAAAAAAAAAAA AAAAA------AAAAA AAAAAA-----AAAAA AAAAAAA---AAAAAA AAAAA------AAAAA --AA--------AA-- ---A------------ ---------------- ---------------- ---------------- ---A---------A-- -AAAA-------AAAA AAAAAA-----AAAAA AAAAAAAAAAAAAAAA AAAAAAAAAAAAAAAA AAAAAAAAAAAAAAAA AAAAAAAAAAAAAAAA -AAAAAAAAAAAAAA- --AAAAAAAAAAAA-- ---AAAAAAAAAA--- ----AAAAAAAA---- -----AAAAAA----- ---------------- ---------------- 
---------------- ------AAAA------ -----AAAAAA----- ----AAAAAAAA---- ---AAAAAAAAAA--- --AAAAAAAAAAAA-- AAAAAAAAAAAAAAAA AAAA--------AAAA AAAAA-------AAAA AAAAAA-----AAAAA --AAA-------AA-- ---A--------A--- ---------------- ---------------- ---------------- ---------------- ---------------- ---A--------AA-- AAAAAA-----AAAAA AAAAAAAAAAAAAAAA AAAAAAAAAAAAAAAA AAAAAAAAAAAAAAAA AAAAAAAAAAAAAAAA -AAAAAAAAAAAAAA- --AAAAAAAAAAAA-- ---AAAAAAAAAA--- ----AAAAAAAA---- -----AAAAAA----- ------AAAA------ ---------------- 
-------AA------- ------AAAA------ -----AAAAAA----- ----AAAAAAAA---- ---AAAAAAAAAA--- --AAAAAAAAAAAA-- AAAAAAAAAAAAAAAA AAAA---------AAA AAAA--------AAAA AAAAA-------AAAA ---AA------AA--- ---------------- ---------------- ---------------- ---------------- ---------------- ---------------- ----A-------A--- --AAAA-----AAA-- AAAAAAAAAAAAAAAA AAAAAAAAAAAAAAAA AAAAAAAAAAAAAAAA AAAAAAAAAAAAAAAA -AAAAAAAAAAAAAA- --AAAAAAAAAAAA-- ---AAAAAAAAAA--- ----AAAAAAAA---- -----AAAAAA----- ------AAAA------ -------AA------- 
-------AA------- ------AAAA------ -----AAAAAA----- ----AAAAAAAA---- ---AAAAAAAAAA--- --AAAAAAAAAAAA-- AAAAAAAAAAAAAAAA AAA----------AAA AAAA---------AAA --AAA-------AAA- ---AAA-----AA--- ---------------- ---------------- ---------------- ---------------- ---------------- ---------------- ----A------AA--- ---AAAA---AAAA-- AAAAAAAAAAAAAAAA AAAAAAAAAAAAAAAA AAAAAAAAAAAAAAAA AAAAAAAAAAAAAAAA -AAAAAAAAAAAAAA- --AAAAAAAAAAAA-- ---AAAAAAAAAA--- ----AAAAAAAA---- -----AAAAAA----- ------AAAA------ -------AA------- 
-------AA------- ------AAAA------ -----AAAAAA----- ----AAAAAAAA---- ---AAAAAAAAAA--- --AAAAAAAAAAAA-- AAAAAAAAAAAAAAAA AAA----------AAA AAAA---------AAA --AA--------AAA- ----AA-----AA--- ---------------- ---------------- ---------------- ---------------- ---------------- ---------------- ----AA----AA---- ---AAAAAAAAAAA-- AAAAAAAAAAAAAAAA AAAAAAAAAAAAAAAA AAAAAAAAAAAAAAAA AAAAAAAAAAAAAAAA -AAAAAAAAAAAAAA- --AAAAAAAAAAAA-- ---AAAAAAAAAA--- ----AAAAAAAA---- -----AAAAAA----- ------AAAA------ -------AA------- 
---------------- ------AAAA------ -----AAAAAA----- ----AAAAAAAA---- ---AAAAAAAAAA--- --AAAAAAAAAAAA-- AAAAAAAAAAAAAAAA AAAA---------AAA AAAA---------AAA -AAAA-------AAA- ---AA-------A--- ---------------- ---------------- ---------------- ---------------- ---------------- ---------------- ----A------AA--- ---AAAAAAAAAAA-- AAAAAAAAAAAAAAAA AAAAAAAAAAAAAAAA AAAAAAAAAAAAAAAA AAAAAAAAAAAAAAAA -AAAAAAAAAAAAAA- --AAAAAAAAAAAA-- ---AAAAAAAAAA--- ----AAAAAAAA---- -----AAAAAA----- ------AAAA------ ---------------- 
---------------- ---------------- -----AAAAAA----- ----AAAAAAAA---- ---AAAAAAAAAA--- --AAAAAAAAAAAA-- AAAAAAAAAAAAAAAA AAAA---------AAA AAAA--------AAAA AAAAA------AAAAA ---AA-------AA-- ---------------- ---------------- ---------------- ---------------- ---------------- ---------------- ---AA------AA--- --AAAAA---AAAAA- AAAAAAAAAAAAAAAA AAAAAAAAAAAAAAAA AAAAAAAAAAAAAAAA AAAAAAAAAAAAAAAA -AAAAAAAAAAAAAA- --AAAAAAAAAAAA-- ---AAAAAAAAAA--- ----AAAAAAAA---- -----AAAAAA----- ---------------- ---------------- 
---------------- ---------------- ---------------- ----AAAAAAAA---- ---AAAAAAAAAA--- --AAAAAAAAAAAA-- AAAAAAAAAAAAAAAA AAAAA-------AAAA AAAAA------AAAAA AAAAAA-----AAAAA -AAA--------AAAA ---A---------A-- ---------------- ---------------- ---------------- ---------------- ---A--------A--- --AAA-------AA-- AAAAAAA---AAAAAA AAAAAAAAAAAAAAAA AAAAAAAAAAAAAAAA AAAAAAAAAAAAAAAA AAAAAAAAAAAAAAAA -AAAAAAAAAAAAAA- --AAAAAAAAAAAA-- ---AAAAAAAAAA--- ----AAAAAAAA---- ---------------- ---------------- ---------------- 
---------------- ---------------- ---------------- ---------------- ---AAAAAAAAAA--- --AAAAAAAAAAAA-- AAAAAAAAAAAAAAAA AAAAAA-----AAAAA AAAAAAA---AAAAAA AAAAAA-----AAAAA AAAAA-------AAAA AAAA---------AAA --AA---------A-- -------------A-- -------------A-- ---A---------A-- --AA--------AAA- AAAAA------AAAAA AAAAAAA--AAAAAAA AAAAAAAAAAAAAAAA AAAAAAAAAAAAAAAA AAAAAAAAAAAAAAAA AAAAAAAAAAAAAAAA -AAAAAAAAAAAAAA- --AAAAAAAAAAAA-- ---AAAAAAAAAA--- ---------------- ---------------- ---------------- ---------------- 
---------------- ---------------- ---------------- ---------------- ---------------- --AAAAAAAAAAAA-- AAAAAAAAAAAAAAAA AAAAAAAAAAAAAAAA AAAAAAAAAAAAAAAA AAAAAAA---AAAAAA AAAAA------AAAAA AAAA--------AAAA AAAA---------AAA AAAA---------AAA AAAA---------AAA AAAA--------AAAA AAAAA-------AAAA AAAAAA-----AAAAA AAAAAAAAAAAAAAAA AAAAAAAAAAAAAAAA AAAAAAAAAAAAAAAA AAAAAAAAAAAAAAAA AAAAAAAAAAAAAAAA -AAAAAAAAAAAAAA- --AAAAAAAAAAAA-- ---------------- ---------------- ---------------- ---------------- ---------------- 
---------------- ---------------- ---------------- ---------------- ---------------- ---------------- AAAAAAAAAAAAAAAA AAAAAAAAAAAAAAAA AAAAAAAAAAAAAAAA AAAAAA----AAAAAA AAAAA-------AAAA AAAA--------AAAA AAAA---------AAA AAAA---------AAA AAAA---------AAA AAAA---------AAA AAAA--------AAAA AAAAA------AAAAA AAAAAAAAAAAAAAAA AAAAAAAAAAAAAAAA AAAAAAAAAAAAAAAA AAAAAAAAAAAAAAAA AAAAAAAAAAAAAAAA -AAAAAAAAAAAAAA- ---------------- ---------------- ---------------- ---------------- ---------------- ---------------- 
---------------- ---------------- ---------------- ---------------- ---------------- ---------------- AAAAAAAAAAAAAAAA AAAAAAAAAAAAAAAA AAAAAAAAAAAAAAAA AAAAAA-----AAAAA AAAAA-------AAAA AAAA---------AAA AAA----------AAA AAA----------AAA AAA----------AAA AAAA---------AAA AAAA--------AAAA AAAAA------AAAAA AAAAAAA---AAAAAA AAAAAAAAAAAAAAAA AAAAAAAAAAAAAAAA AAAAAAAAAAAAAAAA AAAAAAAAAAAAAAAA ---------------- ---------------- ---------------- ---------------- ---------------- ---------------- ---------------- 
