model
size = 32, scale = 0.05, origin = -y
material 
  colors = A:#444 B:#700 C:#500 D:#800 E:#A00 F:#400 G:#B00 H:#60C I:#60F J:#609 K:#606 L:#200 M:#603 N:#600 O:#D00 P:#63C Q:#222 R:#639 S:#63F T:#636 U:#111 V:#AAA
voxels
12-8L24-8L632-8I24-P2A2-3A24-S2A4-A24-R2(2A29-T)2A29-R2A29-P2A2(29-3A)30-2U58-14L18-14F562-14H18-14I18-4P-2A3-2A2P18-4S-2A3-4A18-4R-2Q5-2A18-2(4T28-)4R28-2A2P28-4A122-18L14-18F14-18C494-18J14-18H14-18I14-2P5-2A7-2P14-2S5-2A7-2S14-2R5-2Q7-2A14-2T14-2A14-2T2(30-2A)157-20L12-20F12-20C12-20B428-14K2-4K12-14J2-4J12-5H2-5H4-4H12-4I3-5I4-4I12-P8-2A8-P12-S8-2A8-S12-R8-2A8-R12-T8-2Q8-A12-A18-A12-A222-22F10-22C10-22B10-22D362-8M-5M3-M-3M10-8K-5K3-K-3K10-8J-5J3-J-3J10-6H3-5H3-H-3H10-3I6-5I5-3I10-2P8-2A8-2P10-2S8-2A8-2S10-2R8-2A8-2R10-2T8-2Q8-2A10-2A18-2A10-2A221-24F8-24C8-24B8-24D8-24E296-4N3-2N2-5N2-N-4N8-4M3-2M2-4M5-4M8-4K3-2K2-4K5-4K8-4J3-2J2-4J5-4J8-4H7-4H5-4H8-4I7-4I5-4I8-P11-2A9-P8-S11-2A9-S8-R11-2A9-R8-A11-2A9-T8-A11-2Q9-A31-A199-22F-3F6-22C-3C6-22B-3B6-22D-3D7-21E-2E9-20G-G234-L5-2L2-5L6-L9-2N5-2N2-5N6-2N7-3M5-2M2-5M6-3M6-3K5-2K2-5K6-3K6-3J5-2J2-5J6-3J6-3H9-5H6-3H6-3I9-5I6-3I6-2P11-2A9-2P6-2S11-2A9-2S6-2R11-2A9-2R6-2A11-2A9-2T6-2A11-2Q9-2A30-2A197-6F3-14F-4F4-6C3-14C-4C4-6B3-14B-4B5-5D5-12D-3D7-4E5-12E-2E9-3G5-12G-G11-2O5-12O173-2F7-5F17-L9-5L6-L9-2N9-5N6-2N7-3M9-5M6-3M5-4K9-5K6-4K4-4J9-5J6-4J4-4H9-5H6-4H4-4I9-5I6-4I4-P14-2A10-P4-S14-2A10-S4-A14-2A10-R4-A14-2(2A10-T19-)2Q10-A31-A196-2C7-14C-4C4-2B7-14B-4B5-D9-12D-3D16-12E-2E17-12G-G18-12O21-11G117-11C21-11F21-11L-L19-11N-2N7-M10-11M2-2M5-2K10-11K2-3K4-2J10-11J3-2J4-2H10-7H2-H4-2H4-2I10-7I7-2I4-P14-2A10-P4-S14-2A10-S4-A14-2A10-R4-A14-2(2A10-T19-)2Q10-A31-A195-16C-7C-5C3-15B-7B-4B5-14D-7D-3D7-13E-7E-2E9-3G4-5G-7G-G11-2O4-5O-7O14-G4-5G-7G19-5E-6E52-5B-6B20-5C-7C19-5F-7F19-5L-7L-L17-5N-7N-2N16-5M-7M2-2M5-K9-5K-7K2-3K3-2J9-5J-3J7-3J2-2H9-5H-3H7-3H2-3I8-5I-3I7-3I2-A13-2A-2A10-P2-A13-2A-2A10-S2-A13-2A-2A10-R2(16-2A-2A10-T)16-2A-2A10-R16-2A-2Q10-A16-2A13-A16-2A30-2Q112-16C-2(5C3-)15B-5B3-4B5-14D-5D3-3D7-13E-5E3-2E9-12G-5G3-G11-11O-5O16-G2-7G-5G19-7E-5E19-7D-5D19-7B-5B19-7C-5C19-7F-5F19-7L-5L3-L15-7N-5N3-2N14-7M-5M11-K7-7K-5K6-K3-2J7-7J-5J6-2J2-2H7-7H-5H6-2H2-2I7-7I-4I7-2I2-A11-4A-2A10-P2-A11-4A-2A10-S2-A11-4A-2A10-R2(14-4A-2A10-T)14-4A-2A10-R14-4A-2Q10-A14-4A13-A14-2Q2A30-2U112-14C4-5C2-5C3-13B4-5B2-4B5-12D4-5D2-3D7-11E4-5E2-2E9-10G4-5G2-G11-9O4-5O15-8G4-5G16-7E4-5E17-6D4-4D17-7B4-5B15-8C4-5C14-9F4-5F13-10L4-5L2-L9-11N4-3N4-2N7-12M2(4-3M)5-13K4-3K4-4K3-14J4-3J4-5J2-2H4-8H4-3H7-2H2-2I5-7I4-3I7-2I2-A9-4A4-2A9-P2-A9-4A4-2A9-S12-4A4-2A9-R2(12-4A4-2A9-T)12-4A4-2A9-R12-4A4-2A9-P12-2Q2A4-2Q9-A14-2Q145-13C6-5C2-6C2-11B6-5B2-4B5-10D6-5D2-3D7-9E6-5E2-2E9-8G6-5G2-G11-7O6-5O15-6G6-5G16-5E6-5E17-4D6-4D17-5B6-5B15-6C6-5C14-7F6-5F13-8L6-5L12-9N6-5N11-10M6-5M10-11K6-5K5-K3-12J6-5J5-2J-3H3-7H6-5H5-3H3I3-7I6-4I6-3I2A7-4A6-2A9-2P2A7-4A6-2A9-2S9-4A6-2A9-2R2(9-4A6-2A9-2T)9-4A6-2A9-2R9-2Q2A6-2A9-2P11-2Q6-2Q9-2A31-A162-9B9-4B-5B5-8D9-4D-4D7-7E9-4E-3E9-6G9-4G2-G11-5O9-4O15-4G9-4G16-3E9-4E17-2D9-3D17-3B9-4B15-4C9-4C14-5F9-4F13-6L9-4L12-7N9-4N3-N7-8M9-4M3-2M5-9K9-3K4-3K3-10J9-3J4-4J-3H-7H9-3H4-5H3I-7I9-3I5-4IA6-5(4A9-2A9-A7-)2Q2(2A9-)A9-2Q9-2(2A9-A20-)2Q9-A31-U130-7B11-4B-5B5-6D11-4D-4D7-5E11-4E-3E9-4G11-4G2-G11-3O11-4O15-2G11-4G16-E11-4E28-3D17-B11-4B15-2C11-4C14-3F11-4F13-4L11-4L2-L9-5N11-4N2-2N7-6M11-4M2-3M5-7K11-4K2-4K3-8J11-4J2-5J-9H11-4H2-6H9I11-4I2-6IA4-2(4A11-2A7-3A5-)4A11-2A7-2QA5-4A11-2A9-A5-2Q2A11-2A9-A7-2Q11-3(2A9-A20-)2Q9-A31-U130-9B10-9B5-8D10-8D7-7E10-7E9-6G10-6G11-5O10-5O13-4G10-4G15-3E10-3E17-2D10-2D17-3B10-3B15-4C10-4C13-5F10-5F11-6L10-6L9-7N10-7N7-8M10-8M5-9K10-9K3-10J10-10J-11H10-11H11I10-11I3-4A2-2A10-2A4-2P2VA3-4A2-2A10-2A2(4-4A)2-2A10-2A4-2A2Q4-2Q2A2-2A10-2A4-2Q8-2Q2-5(2A10-2A18-)QU10-UQ139-9B10-9B5-8D10-8D7-7E10-7E9-6G10-6G11-5O10-5O13-4G10-4G15-3E10-3E17-2D10-2D17-3B10-3B15-4C10-4C13-5F10-5F11-6L10-6L9-7N10-7N7-8M10-8M5-9K10-9K3-10J10-10J-11H10-11H11I10-11I-4A4-2A10-2A2-6PA-4A4-2A10-2A2-4A4-2Q2A4-2A10-2A2-4A6-2Q4-2A10-2A2-2A2Q12-2A10-2A2-2Q14-4(2A10-2A18-)QU10-UQ139-10B11-7B5-9D11-6D7-8E11-5E9-7G11-4G11-6O11-3O13-5G11-2G15-4E11-E17-3D28-4B11-B15-5C11-2C13-6F11-3F11-7L11-4L9-8N11-5N7-9M11-6M5-10K11-7K3-5J2-4J11-8J-6H2-4H11-9H6I2-4I11-9I3A7-2A11-AP2V4P4A7-2A11-4A5-A2Q7-2(2A11-4A5-A9-)2A11-2A2Q5-A9-2A11-2Q7-2(A9-2A20-)A9-2Q20-U161-10B9-9B5-9D9-8D7-8E9-7E9-7G9-6G11-6O9-5O13-5G9-4G15-4E9-3E17-3D9-2D17-4B9-3B15-5C9-4C13-6F9-5F12-6L9-6L12-N-3N9-7N7-M3-M-3M9-8M5-2K3-K-3K9-9K3-3J5-3J9-10J-4H5-3H9-11H4I5-3I9-7I2-2IA2(9-2A)2V3P2-P2(2A9-)4A6-2(2A9-)3(4A7-A9-2A9-)2A2Q7-A9-2A9-2Q9-A9-2A20-A9-2Q20-U127-13C6-13C2-11B6-11B5-10D6-10D7-9E6-9E9-8G6-8G11-7O6-7O13-6G6-6G15-5E6-5E17-4D6-4D17-5B6-5B15-6C6-6C13-7F6-7F12-7L6-8L11-2N-4N6-9N7-M2-2M-4M6-10M5-K4-K-4K6-11K3-2J6-4J6-12J-3H6-4H6-13H3I6-4I6-7I-I-3I2P9-2A6-3AV3P3-2PA2S9-2A6-4A8-A2(2R9-2A6-4A9-)2T9-2A6-4A9-2R9-2A6-4A9-2P9-2A6-2A2Q9-2A9-2Q6-2Q11-2A159-12C4-14C3-11B4-13B5-10D4-12D7-9E4-11E9-8G4-10G11-7O4-9O13-6G4-8G15-5E4-7E17-4D4-6D17-5B4-7B15-6C4-8C13-7F4-9F12-7L4-10L11-2N-4N4-11N10-2M-4M4-12M5-K4-K-4K4-13K3-2J6-4J4-7J2-5J2-2H6-4H4-7H4-3H2-2I7-3I4-7I5-2I2-P9-2A4-2A5P5-2P2-S2(9-2A4-4A9-A2-R)9-2A4-4A12-T9-2A4-4A12-R9-2A4-4A12-P9-2A4-4A12-A9-2Q4-2A2Q12-A15-2Q142-5C2-6C-16C3-4B2-6B-15B5-3D2-6D-14D7-2E2-6E-13E9-G2-6G-12G13-6O-11O14-6G-10G15-6E-9E17-5D-8D17-6B-9B16-6C-7C-2C15-6F-7F-3F14-6L-7L-4L14-5N-7N-5N13-5M-7M-6M5-K6-5K-7K3-5K3-2J6-5J-7J6-3J2-2H6-5H-7H6-3H2-2I7-4I-7I6-3I2-P10-2A-4A3P6-3P2-S2(10-2A-4A11-A2-R)10-2A-4A14-T10-2A-4A14-R10-2A-4A14-A10-2Q-4A14-A13-4A28-2A2Q28-2U112-2(6C-)7C6-3C3-5B-6B-7B6-2B5-4D-6D-7D6-D7-3E-6E-7E15-2G-6G-7G16-O-6O-7O18-6G-7G18-6E-7E50-6B-7B18-6C-7C16-F4-3F-7F16-L4-3L-7L16-N4-3N-7N13-M7-3M-7M6-M5-2K7-3K-7K6-2K3-3J7-3J-5J8-3J2-3H7-3H-5H8-3H2-3I7-3I-5I8-3I2-P10-2A-2A3P8-3P2-S2(10-2A-2A12-2A2-R)10-2A-2A12-2A2-T10-2A-2A16-R10-2A-2A16-A10-2Q-2A16-A13-2(2A30-)2Q113-20C3-5C4-5B-14B3-5B5-4D-14D3-4D7-3E-14E3-3E9-2G-10G7-2G11-O-10O7-O14-10G118-10C20-F-10F20-L3-8L8-L11-N3-8N8-2N7-M6-8M8-3M5-2K6-8K8-4K4-2J6-8J8-4J4-2H6-8H10-2H4-2I7-7I10-2I4-P10-2A3P10-2P4-S2(10-2A14-A4-R)10-2A14-A4-T10-2A19-A10-2Q19-A191-18F5-5F4-18C5-5C4-5B-12B6-4B5-4D-12D6-3D7-3E-12E6-2E9-2G-12G6-G11-O-12O178-F-9F20-2L3-7L9-L9-3N3-7N9-2N7-3M6-5M9-3M5-4K6-5K9-4K4-4J6-5J9-4J4-4H6-5H9-4H4-4I6-5I9-4I4-P10-2A2P9-4P4-S2(10-2A14-A4-R)10-2A14-A4-T10-2A19-A10-2Q19-A192-17F2-7F6-17C2-7C6-17B2-7B6-17D2-7D7-16E2-6E9-15G2-5G234-2L3-7L9-L9-3N3-7N9-2N7-3M6-5M9-3M6-3K6-5K9-3K6-3J6-5J9-3J6-3H6-5H9-3H6-3I6-5I9-3I6-2P9-2AP9-3P6-2S9-2A11-2S6-2R9-2A11-2R6-2R9-2A11-2A6-2A9-2Q11-2A6-2A223-24F8-24C8-24B8-24D8-24E296-4N2-9N2-7N8-4M3-8M5-4M8-4K4-7K5-4K8-4J5-6J5-4J8-4H5-5H6-4H8-4I5-5I6-4I8-P9-2A2P6-4P8-S9-2A11-S8-R9-2A11-R8-R9-2A11-A8-A9-2Q11-A8-A224-22F10-22C10-22B10-22D362-3M3-8M5-3M10-3K3-8K5-3K10-3J5-6J5-3J10-3H5-5H6-3H10-3I5-5I6-3I10-2P8-2AP6-3P10-2S8-2A8-2S10-2R8-2A8-2R10-2A8-2Q8-2T10-2A18-2A30-A172-20L12-20F12-20C12-20B428-13K2-5K12-5J2-6J2-5J12-4H4-5H3-4H12-4I4-5I3-4I12-P8-2A2P3-4P12-S8-2A8-S12-R8-2A8-R12-A8-2Q8-T12-A18-A31-A173-18L14-18F14-18C494-18J14-18H14-18I14-2P7-AV7P14-2S7-2A5-2S14-2A7-2Q5-2R14-2A14-2T30-2R2(30-2A)144-14L18-14F562-14H18-14I18-2P2A3-AV5P18-4A3-2A-4S18-2A5-2Q-4R28-4T28-4R28-4P2(28-4A)85-8L24-8L632-8I24-3A2-2AP24-A4-2AS29-2AR29-2AT29-2AR29-2AP3(29-3A)29-2U13-
