model
size = 22 12 19, scale = 0.05, origin = -y
material 
  colors = A:#EEE B:#963 C:#960 D:#FF0 E:#0C0
voxels
--------------------AA --------------------AA --------------------AA --------------------AA --------------------AA --------------------AA --------------------AA --------------------AA --------------------AA --------------------AA --------------------AA --------------------AA 
-------------------AA- -------------------AA- -------------------AA- -------------------AA- -------------------CA- -------------------AA- -------------------AA- -------------------AA- -------------------AA- -------------------AA- -------------------AA- -------------------AA- 
------------------AA-- ------------------AA-- ------------------AA-- ------------------CA-- ------------------CA-- ------------------AA-- ------------------AA-- ------------------AA-- ------------------AA-- ------------------AA-- ------------------AA-- ------------------AA-- 
-----------------AA--- -----------------AA--- -----------------AA--- -----------------CA--- -----------------AA--- -----------------AA--- -----------------AA--- -----------------AA--- -----------------AA--- -----------------AA--- -----------------AA--- -----------------AA--- 
----------------AA---- ----------------AA---- ----------------AA---- ----------------CA---- ----------------AA---- ----------------AA---- -------------C-CCA---- ------------CCC-CA---- ------------DC--CA---- ----------------AA---- ----------------AA---- ----------------AA---- 
--------------AA------ --------------AA------ --------------AA------ --------------AC------ --------------AA------ --------------AA------ ------------CCAA------ ------------CCCA------ ------------CCCC------ --------------CA------ --------------AA------ --------------AA------ 
------AAAAAAAA-------- ------AAAAAAAA-------- ------AAAAAAAA-------- ------AAAAAAAA-------- ------AAAAAAAA-------- ------AAAAAAAA-------- ------AAAAAAAA-------- ------AAAAAACCC------- ------AAAAAAAC-------- ------AAAAACCC-------- ------AAAAAAAA-------- ------AAAAAAAAA------- 
----AAAAAAAAC--------- ----AAAAAAAAA--------- ----AAAAAAAAA--------- ----AAAAAAAAC--------- ----AAAAAAAAA--------- ----AAAAAAAAA--------- ----AAAAAAAAA--------- ----AAAAAAAAA--------- ----AAAAAAAAA--------- ----AAAAAAAAA--------- ----AAAAAAAAA--------- ----AAAAAAAAA--------- 
---AAAAAAAAAA--------- ---AAAAAAAAAA--------- ---AAAAAAAAAC--------- ---AAAAAAAAAA--------- ---AAAAAAAAAA--------- ---AAAAAAAAAA--------- ---AAAAAAAAAA--------- ---AAAAAAAAAC--------- ---AAAAAAAAAA--------- ---AAAAAAAAAA--------- ---AAAAAAAAAA--------- ---AAAAAAAAAA--------- 
---AAAAAAAAAAA-------- ---AAAAAAAAAAA-------- ---AAAAAAAAAAA-------- ---AAAAAAAAAAA-------- ---AAAAAAAAAAA-------- ---AAAAAAAAAAA-------- ---AAAAAAAAAAA-------- ---AAAAAAAAAAA-------- ---AAAAAAAAAAC-------- ---AAAAAAAAAAA-------- ---AAAAAAAAAAA-------- ---AAAAAAAAAAA-------- 
--AAAAAAAAAAAAA------- --AAAAAAAAAAAAA------- --AAAAAAAAAAAAA------- --AAAAAAAAAAAAA------- --AAAAAAAAAAAAA------- --AAAAAAAAAAAAA------- --AAAAAAAAAAAAA------- -CAAAAAAAAAAAAA------- DCAAAAAAAAAAAAA------- -CAAAAAAAAAAAAA------- --AAAAAAAAAAAAA------- --AAAAAAAAAAAAA------- 
--AAAAABBBAAAAA------- --AAAAABBBAAAAA------- --AAAAABBBAAAAA------- --AAAAABBBAAAAA------- --AAAAABBBAAAAA------- --AAAAABBBAAAAA------- --AAAAABBBAAAAA------- -CAAAAABBBAAAAA------- -CAAAAABBBAAAAA------- CCAAAAABBBAAAAA------- --AAAAABBBAAAAA------- --AAAAABBBAAAAA------- 
--AAAAAB-BAAAAA------- --AAAAAB-BAAAAA------- --AAAAAB-BAAAAA------- --AAAAAB-BAAAAA------- --AAAAAB-BAAAAA------- --AAAAAB-BAAAAA------- --AAAAAB-BAAAAA------- ECAAAAAB-BAAAAA------- -CAAAAAB-BAAAAA------- -CAAAAAB-BAAAAA------- --AAAAAB-BAAAAA------- --AAAAAB-BAAAAA------- 
--AAAAABBBAAAAA------- --AAAAABBBAAAAA------- --AAAAABBBAAAAA------- --AAAAABBBAAAAA------- --AAAAABBBAAAAA------- --AAAAABBBAAAAA------- --AAAAABBBAAAAA------- --AAAAABBBAAAAA------- --AAAAABBBAAAAA------- --AAAAABBBAAAAA------- --AAAAABBBAAAAA------- --AAAAABBBAAAAA------- 
--AAAAAAAAAAAAA------- --AAAAAAAAAAAAA------- --AAAAAAAAAAAAA------- --AAAAAAAAAAAAA------- --AAAAAAAAAAAAA------- --AAAAAAAAAAAAA------- --AAAAAAAAAAAAA------- --AAAAAAAAAAAAA------- --AAAAAAAAAAAAA------- --AAAAAAAAAAAAA------- --AAAAAAAAAAAAA------- --AAAAAAAAAAAAA------- 
---AAAAAAAAAAA-------- ---AAAAAAAAAAA-------- ---AAAAAAAAAAA-------- ---AAAAAAAAAAA-------- ---AAAAAAAAAAA-------- ---AAAAAAAAAAA-------- ---AAAAAAAAAAA-------- ---AAAAAAAAAAA-------- ---AAAAAAAAAAA-------- ---AAAAAAAAAAA-------- ---AAAAAAAAAAA-------- ---AAAAAAACCCA-------- 
---AAAAAAAAAAA-------- ---AAAAAAAAAAA-------- ---CAAAAAAAAAA-------- ---CAAAAAAAAAA-------- ---AAAAAAAAAAA-------- ---AAAAAAAAAAA-------- ---CAAAAAAAAAA-------- ---AAAAAAAAAAA-------- ---AAAAAAAAAAA-------- ---AAAAAAAAAAA-------- ---AAAAAAAAAAA-------- ---AAAAAACAAAA-------- 
----AAAAAAAAA--------- ----AAAAAAAAA--------- ----ACAAAAAAA--------- ----CCAAAAAAA--------- ----CCAAAAAAA--------- ----CCAAAAAAA--------- ----CAAAAAAAA--------- ----AAAAAAAAA--------- ----AAAAAAAAA--------- ----AAAAAAAAA--------- ----AAAAAAAAA--------- ----AAAAACCAA--------- 
------AAAAA----------- ------AAAAA----------- ------CAAAA----------- ------CCAAA----------- ------ACAAA----------- ------ACAAA----------- ------AAAAA----------- ------AAAAA----------- ------AAAAA----------- ------AACAA----------- ------AACCA----------- ------AAACC----------- 
