model
size = 13 25 18, scale = 0.05, origin = -y
material 
  colors = A:#111 B:#FF0
voxels
------------- ------------- ------------- ------------- ------------- ------------- ------------- ------------- ------------- ------------A ------------A ------------A ------------A ------------A ------------- ------------- ------------- ------------- ------------- ------------- ------------- ------------- ------------- ------------- ------------- 
------------- ------------- ------------- ------------- ------------- ------------- ------------- ------------A ------------A ------------A ------------A ------------A ------------A ------------A ------------- ------------- ------------- ------------- ------------- ------------- ------------- ------------- ------------- ------------- ------------- 
------------A ------------A ------------A ------------- ------------- ------------- ------------- ------------A ------------A ------------A ------------A ------------A ------------A ------------A ------------A ------------- ------------- ------------- ------------- ------------- ------------- ------------- ------------- ------------- ------------- 
------------A ------------A ------------A ------------- ------------- ------------- ------------A ------------A ------------A ------------A ------------A ------------A ------------A ------------A ------------A ------------- ------------- ------------- ------------- ------------- ------------- ------------- ------------- ------------- ------------- 
------------A ------------A ------------A ------------- ------------- ------------- ------------A ------------A ------------A ------------A ------------- ------------- ------------A ------------A ------------A ------------A ------------- ------------- ------------- ------------- ------------- ------------- ------------- ------------- ------------- 
------------A ------------A ------------A ------------- ------------- ------------- ------------A ------------A ------------A ------------A ------------- ------------- ------------A ------------A ------------A ------------A ------------- ------------- ------------- ------------- ------------- ------------- ------------- ------------- ------------- 
------------A ------------A ------------A ------------A ------------- ------------- ------------A ------------A ------------A ------------- ------------- ------------- ------------A ------------A ------------A ------------A ------------- ------------- ------------- ------------- ------------- ------------- ------------- ------------- ------------- 
------------A ------------A ------------A ------------A ------------- ------------- ------------A ------------A ------------A ------------- ------------- ------------- ------------- ------------A ------------A ------------A ------------- ------------- ------------- ------------- ------------- ------------- ------------- ------------- ------------- 
------------A ------------A ------------A ------------A ------------- ------------- ------------A ------------A ------------A ------------- ------------- ------------- ------------- ------------A ------------A ------------A ------------- ------------- ------------- ----A--B----- ----A--B----- ----A--B----- ------------- ------------- ------------- 
------------- ------------A ------------A ------------A ------------- ------------- ------------A ------------A ------------A ------------- ------------- ------------- ------------- ------------A ------------A ------------A ------------- ------------- -------B----- --A-A--AA---A --AAAAAAA---A --AAAAAAA---A ---A-AAB----A ------------- ------------- 
------------- ------------A ------------A ------------A ------------- ------------- ------------A ------------A ------------A ------------- ------------- ------------- ------------- ------------A ------------A ------------A ------------- ------------- -------B----- -AA-A--AAAAAA -AAAAAAAAAAAA AAAAAAAAAAAAA A-AA-AAB---AA A----------A- ------------- 
------------- ------------A ------------A ------------A ------------- ------------A ------------A ------------A ------------A ------------- ------------- ------------- ------------- ------------A ------------A ------------A ------------- ------------- -------B----- -AA-A--AAAAAA -AAAAAAAAAAAA AAAAAAAAAAAAA AAAAAAAB---AA AA---------A- -----------A- 
------------- ------------A ------------A ------------A ------------A ------------A ------------A ------------A ------------A ------------- ------------- ------------- ------------- ------------A ------------A ------------A ------------A ------------- ------------- -AA-A--B-AAA- -AAAAA-B-AAAA AAAAAA-B-AAAA AAAAAA-----AA AA---------AA -----------A- 
------------- ------------A ------------A ------------A ------------A ------------A ------------A ------------A ------------A ------------- ------------- ------------- ------------- ------------A ------------A ------------A ------------A ------------- ------------- ----A-----AA- ----A-----AAA -A--A-----AAA -A--A------AA -A---------AA -----------A- 
------------- ------------- ------------A ------------A ------------A ------------A ------------A ------------A ------------- ------------- ------------- ------------- ------------- ------------A ------------A ------------A ------------A ------------A ------------- ----------AAA ----------AAA ----------AAA -----------AA -----------AA -----------A- 
------------- ------------- ------------A ------------A ------------A ------------A ------------A ------------A ------------- ------------- ------------- ------------- ------------- ------------- ------------A ------------A ------------A ------------A ------------A ----------A-A ----------AAA ----------AAA -----------AA -----------AA ------------- 
------------- ------------- ------------- ------------A ------------A ------------A ------------A ------------A ------------- ------------- ------------- ------------- ------------- ------------- ------------A ------------A ------------A ------------A ------------A ------------A ------------A ------------A ------------A ------------A ------------- 
------------- ------------- ------------- ------------- ------------- ------------- ------------- ------------- ------------- ------------- ------------- ------------- ------------- ------------- ------------- ------------A ------------A ------------A ------------A ------------A ------------A ------------A ------------- ------------- ------------- 
