model
size = 32 16 31, scale = 0.05, origin = -y
material 
  colors = A:#F09 B:#F3C C:#F3F D:#777 E:#111 F:#EEE G:#555 H:#444
voxels
9-14A19-12A21-10A24-6A27-3A374-18A15-16A17-14A19-12A21-10A24-6A27-3A309-20A13-18A14-18A15-16A17-14A19-12A22-8A25-6A27-3A244-22A10-22A11-20A-A11-18A15-16A17-14A19-12A-A19-10A23-8A25-6A27-3A179-25A7-24A9-23A10-21A11-20A13-18A15-16A17-14A-A17-12A-A19-10A23-8A25-6A144-3A21-2A6-3A21-2A7-2A21-BA8-A21BA9-6A-15A11-5A-14A13-4A-13A-A13-3A-13A15-3A-8A-4A16-2A-13A16-15A20-8A24-8D3(24-8A)14-4A21-3A5-3A21-2A6-3A21-2A7-2A21BA8-3A-17B3A9-2A2-2(16B2A11-3A)16B2A12-2A2(16BA14-A)15BA16-3A6C7A18-D6C2A5D2(18-A6C7A)18-13A9-5A21-4A3-4A21-3A4-4A21-3A5-3A3B15-3B2A7-4AB15-B3A8-3A-B15-B3A9-2A-B15-B2A11-2AB15-BA12-2AB15-B2A12-AB15-BA13-AB15-BA14-A15CA16-2DA12CD2(16-3A12CA)16-3A9-4A8-5A21-4A2-5A21-4A3-4A21-3A4-4A3B15-3B3A5-5AB15-B4A7-3A-B15-B3A8-3A-B15-B-2A9-2A-B15-B-A10-2A-B15-B2A11-A-B15-BA13-AB15-BA14-A4C7-4CA15-D3AC7-4CD15-4AC7-4CA15-2A3C7-4CA15-2A13-2A7-6A21-5A-5A21-4A2-5A21-4A3-4A3B15-3B3A4-6AB15-B5A5-5AB15-B4A7-4AB15-B3A8-4AB15-B3A9-3AB15-B2A10-3AB15-B2A11-2AB15-BA13-A4C9-3C2A13-D4C9-3C2D2(13-A4C9-3C2A)13-2A14-3A6-6A21-11A21-5A-5A21-4A2-5A3B15-3B4A3-6AB15-B5A4-6AB15-B5A5-5AB15-B4A7-4AB15-B3A8-4AB15-B3A9-3AB15-B2A10-3AB15-BA12-2A2C12-2C2A12-DA2C12-2C2D2(12-2A2C12-2C2A)12-2A16-2A6-6A2(21-11A)21-5A-5A3B15-3B4A2-7AB15-BA-4A3-6AB15-BA-3A5-5AB15-BA-2A6-5AB15-BA-2A7-4AB15-BA-A8-4AB15-BA-A9-3AB15-BA11-3AC14-C2A12-DAC14-C2D11-D2(2AC14-C2A12-)2A16-2A6-6A2(21-11A)21-5A-5A3B15-3B4A2-7AB15-B6A3-6AB15-B5A4-6AB15-B5A5-5AB15-B4A6-5AB15-B4A7-4AB15-B3A8-4AB15-B3A9-3AC15-C2A10-D2AC15-C2D11-2AC15-C2A10-G2AC15-C2A11-2A17-2A5-6A3(21-11A)3B15-3B5A-7AB15-B6A2-7AB15-B6A3-6AB15-B5A4-6AB15-B5A5-5AB15-B4A6-5AB15-B4A7-4AB15-B3A8-4AC15-C3A9-D2AC15-C2D9-E-2AC15-C2A10-2(E2AC15-C2A11-2A17-2A5-6A3(21-11A)3B15-3B13AB15-B7A-7AB15-B6A2-7AB15-B6A3-6AB15-B5A4-6AB15-B5A5-5AB15-B4A6-5AB15-B4A7-4AC15-C3A9-3AC15-C2DH8-FE2AC15-C2A9-F)E2AC15-C2A11-2A17-2A5-6A3(21-11A)3B15-3B5A-7AB15-B6A2-7AB15-B6A3-6AB15-B5A4-6AB15-B5A5-5AB15-B4A6-5AB15-B4A7-4AB15-B3A8-4AC15-C3A9-D2AC15-C2D9-2E2AC15-C2A10-E2AC15-C2A11-2A17-2A5-6A2(21-11A)21-5A-5A3B15-3B4A2-7AB15-B6A3-6AB15-B5A4-6AB15-B5A5-5AB15-B4A6-5AB15-B4A7-4AB15-B3A8-4AB15-B3A9-3AC15-C2A10-D2AC15-C2D11-2AC15-C2A10-GDAC15-C2A11-2A17-2A5-6A2(21-11A)21-5A-5A3B15-3B4A2-7AB15-B6A3-6AB15-B5A5-5AB15-B4A6-5AB15-B4A7-4AB15-B3A8-4AB15-B3A9-3AB15-B2A10-3A2C13-C3A11-DA2C13-CA2D12-A2C13-C3A12-D2C13-C3A11-2A16-3A5-6A21-11A21-5A-5A21-4A2-5A3B15-3B4A3-6AB15-BA-3A4-6AB15-BA-3A5-5AB15-BA-2A7-4AB15-BA-A8-4AB15-BA-A9-3AB15-BA11-3AB15-BA12-2A3C11-2C2A13-D3C11-2CAD13-D3C11-2C2A13-A3C11-2C2A12-3A14-3A6-6A21-5A-5A21-4A2-5A21-4A3-4A3B15-3B3A4-6AB15-B5A5-5AB15-B4A7-4AB15-B3A8-4AB15-B3A9-3AB15-B2A10-3AB15-BA12-2AB15-BA13-A4C9-3C2A13-D4C9-3CAD2(13-A4C9-3C2A)2(13-3A)7-5A21-4A2-5A21-4A3-4A21-3A4-4A3B15-3B3A5-5AB15-B4A7-3A-B15-B3A8-3A-B15-B3A9-2A-B15-B2A10-2A-B15-B2A11-2AB15-BA13-AB15-BA14-A15C2A14-4D12C2D2(14-4A12C2A)14-4A10-4A7-5A21-4A3-4A21-3A4-4A21-3A5-3A21B2A7-3A-16B4A8-4A16B4A9-3A16BA-A11-2A16BA13-2A2(16BA14-A)16BA15-17A15-17D3(15-17A)9-4A21-3A5-3A21-2A6-3A21-2A7-2A21BA8-24A9-20A-A11-A-17A14-18A13-A-17A14-18A15-17A16-16A16-16D3(16-16A)10-3A21-2A6-3A21-2A7-2A21-A9-A21BA9-22A11-2(A-)16A15-A-14A15-A2-13A17-A-13A16-A-14A2(19-13A)19-13D3(19-13A)12-24A8-24A9-22A11-16A2-3A11-15A3-A14-14A2-A16-13A20-12A21-11A22-10A23-9A24-8A25-7D3(25-7A)16-22A10-22A11-20A13-18A15-16A17-14A19-12A21-10A23-8A25-6A27-3A181-20A13-18A14-18A15-16A17-14A19-12A22-8A25-6A27-3A246-18A15-16A17-14A19-12A21-10A24-6A27-3A312-14A19-12A21-10A24-6A27-3A378-10A24-6A27-3A431-
