model
size = 23 26 14, scale = 0.05, origin = -y
material 
  colors = A:#EEE B:#86BCDE C:#222 D:#FFF E:#F4A7B9 F:#9F353A G:#0089A7 H:#C46243 I:#9E7A7A J:#F596AA K:#C73E3A L:#A35E47 M:#64363C N:#FFFFFB O:#CB4042 P:#D0104C Q:#E16B8C R:#B54434 S:#B19693 T:#884C3A U:#F8C3CD V:#EEA9A9 W:#8E354A X:#E87A90 Y:#724832 Z:#D7C4BB Aa:#F75C2F Ab:#DB4D6D Ac:#86473F Ad:#CB1B45 Ae:#904840 Af:#9A5034 Ag:#FEDFE1 Ah:#BF6766 Ai:#A96360 Aj:#787D7B Ak:#DDD Al:#B55D4C Am:#B5495B An:#734338 Ao:#AB3B3A Ap:#554236 Aq:#FF797A Ar:#6A4028 As:#994639 At:#EB7A77 Au:#854836 Av:#B9887D Aw:#E83015 Ax:#DC9FB4 Ay:#D05A6E Az:#D75455
voxels
- - - - - - - - - - - - - - - - - - - - - - -   - - - - - - - - - - - A A - - - - - - - - - -   - - - - - - - - - - A A A A - - - - - - - - -   - - - - - - - - - A A A A A A - - - - - - - -   - - - - - - - - A A A A A A A A - - - - - - -   - - - - - - - A A A A A A A A A A - - - - - -   - - - B - - - A A A A A A A A A A - - - B - -   - - - - A A A A A A A A A A A A A A A A - - -   - - - - - - A A A A A A A A A A A A - - - - -   - - - - - - - A A A A A A A A A A - - - - - -   - - - - - - - A A A A A A A A A A - - - - - -   - - - - - - - A A A A A A A A A A - - - - - -   - - - - - - - A A A A A A A A A A - - - - - -   - - - - - - - A A A A A A A A A A - - - - - -   - - - - - - - A A A A A A A A A A - - - - - -   - - - - - - A A A A A A A A A A A A - - - - -   - - - - - - A A A A A A A A A A A A - - - - -   - - - - - - A A C C A A A A C C A A - - - - -   - - - - - - A C G G C A A C G G C A - - - - -   - - - - - - A A C C A A A A C C A A - - - - -   - - - - - - A A A A A A A A A A A A - - - - -   - - - - - - - - A A A A A A A A - - - - - - -   - - - - - - - - - A A A A A A - - - - - - - -   - - - - - - - - - - - - - - - - - - - - - - -   - - - - - - - - - - - - - - - - - - - - - - -   - - - - - - - - - - - - - - - - - - - - - - -   
- - - - - - - - - - - - - - - - - - - - - - -   - - - - - - - - - - - A A - - - - - - - - - -   - - - - - - - - - - A B B A - - - - - - - - -   - - - - - - - - - A B B B B A - - - - - - - -   - - - - - - - - - B B B B B B - - - - - - - -   - - - - - - - - A B B B B B B A - - - - - - -   - - A A B B B A A A A A A A A A A B B B A A -   - - - A A A A A A A A A A A A A A A A A A - -   - - - - A A A A A A A A A A A A A A A A - - -   - - - - - - A A A A A A A A A A A A - - - - -   - - - - - - A A A A A A A A A A A A - - - - -   - - - - - - A A A A A A A A A A A A - - - - -   - - - - - - A A A A A A A A A A A A - - - - -   - - - - - - A A A A A A A A A A A A - - - - -   - - - - - - A A A A A A A A A A A A - - - - -   - - - - - - A A A A A A A A A A A A - - - - -   - - - - - - A A A A A A A A A A A A - - - - -   - - - - - - A A C C A A A A C C A A - - - - -   - - - - - - A C AkAkC A A C AkAkC A - - - - -   - - - - - - A A C C A A A A C C A A - - - - -   - - - - - - A A A A A A A A A A A A - - - - -   - - - - - - A A A A A A A A A A A A - - - - -   - - - - - - - A A A A A A A A A A - - - - - -   - - - - - - - - A A A A A A A A - - - - - - -   - - - - - - - - - - - - - - - - - - - - - - -   - - - - - - - - - - - - - - - - - - - - - - -   
- - - - - - - - - - - - - - - - - - - - - - -   - - - - - - - - - - - - - - - - - - - - - - -   - - - - - - - - - - - - - - - - - - - - - - -   - - - - - - - - - - - - - - - - - - - - - - -   - - - - - - - - - - - - - - - - - - - - - - -   - - B B B B B B B - - - - - - B B B B B B B B   - A A A A A A A B B B B B B B B A A A A A A A   - - B A A A A A AyAuK I U D Q Y A A A A A B -   - - - B A A A A AiU B M I E P D A A A A B - -   - - - - A A A A AfM W K M Q AlAeA A A - - - -   - - - - - A A A M H AdB K L A B A A A - - - -   - - - - - A A A J ArO AwAdG V X A A A - - - -   - - - - - A A A O G B D L AoAxH A A A - - - -   - - - - - A A A B W AeAtY V O D A A A - - - -   - - - - - A A A AeApD AyB AnG E A A A - - - -   - - - - - A A A D AhZ AiF T AoQ A A A - - - -   - - - - - A A A Z AiE AfA Y V L A A A - - - -   - - - - - A A A E I P M I AdAnJ A A A - - - -   - - - - - A A A P AgAfU X L T R A A A - - - -   - - - - - A A A AfT AgJ H AhY AaA A A - - - -   - - - - - A A A AgJ AeO D AoAdT A A A - - - -   - - - - - - A A AeAdAbB E AmL J A A - - - - -   - - - - - - A A B B B B B B B B A A - - - - -   - - - - - - - A A B B B B B B A A - - - - - -   - - - - - - - - - A A A A A A - - - - - - - -   - - - - - - - - - - - - - - - - - - - - - - -   
- - - - - - - - - - - - - - - - - - - - - - -   - - - - - - - - - - - - - - - - - - - - - - -   - - - - - - - - - - - - - - - - - - - - - - -   - - - - - - - - - - - - - - - - - - - - - - -   - - - - - - - - - - - - - - - - - - - - - - A   A A A A A A A A B - - - - - - B A A A A A A A   A A A A A A A B - - - - - - - - B A A A A A A   - A A A A A A B - - - - - - - - B A A A A A -   - - - B A - - B - - - - - - - - B - - A B - -   - - - - A A A B - - - - - - - - B A A A - - -   - - - - - A A B - - - - - - - - B A A - - - -   - - - - - A A B - - - - - - - - B A A - - - -   - - - - - A A B - - - - - - - ArA A A - - - -   - - - - - A A A Ai- - - - - - ApA A A - - - -   - - - - - A A A Y - - - - - - AhA A A - - - -   - - - - - A A A An- - - - - - AcA A A - - - -   - - - - B A A A X - - - - - - K A A A B - - -   - - - - B A A A R - - - - - - O A A A B - - -   - - - - B A A A B - - - - - - O A A A B - - -   - - - - - A A A Al- - - - - - W A A A - - - -   - - - - - A A A I - - - - - - ArA A A - - - -   - - - - - A A A Ac- - - - - - G A A A - - - -   - - - - - - A A AjD V F G R AfAjA A - - - - -   - - - - - - - A A A A A A A A A A - - - - - -   - - - - - - - - A A A A A A A A - - - - - - -   - - - - - - - - - - A A A A - - - - - - - - -   
- - - - - - - - - - - - - - - - - - - - - - -   - - - - - - - - - - - - - - - - - - - - - - -   - - - - - - - - - - - - - - - - - - - - - - -   - - - - - - - - - - - - - - - - - - - - - - A   A A - - - - - - - - - - - - - - - - - - - - A   A A A - - - - - - - - - - - - - - - - - - A A   A A A B B B B B - - - - - - - - B B B B B A A   - A A A B B B B - - - - - - - - B A A A A A -   - - - B B - - B - - - - - - - - B - - A B - -   - - - - A B B B - - - - - - - - B A A A - - -   - - - - A B B B - - - - - - - - B A A - - - -   - - - - - A A B - - - - - - - - B A A - - - -   - - - - - A A B - - - - - - - ApA A A - - - -   - - - - - A A A Ah- - - - - - F A A A - - - -   - - - - - A A A Ao- - - - - - AvA A A - - - -   - - - - - A A A Am- - - - - - AwA A A - - - -   - - - - - - - - U - - - - - - S - - - - - - -   - - - - - A A A Al- - - - - - F A A A - - - -   - - - - - - - - Av- - - - - - P - - - - - - -   - - - - - A A A S - - - - - - AbA A A - - - -   - - - - - A A A Aa- - - - - - AqA A A - - - -   - - - - - A A A F - - - - - - H A A A - - - -   - - - - - - A A AjT AuAsK E AbAjA A - - - - -   - - - - - - - A A A A A A A A A A - - - - - -   - - - - - - - - A A A A A A A A - - - - - - -   - - - - - - - - - A A A A A A - - - - - - - -   
- - - - - - - - - - - - - - - - - - - - - - -   - - - - - - - - - - - - - - - - - - - - - - -   - - - - - - - - - - - - - - - - - - - - - - A   A - - - - - - - - - - - - - - - - - - - - - A   A A - - - - - - - - - - - - - - - - - - - - A   A A A - - - - - - - - - - - - - - - - - - A A   A A A B B B B B - - - - - - - - B B B B B A A   - A A A B B B B - - - - - - - - B A A A A A -   - - - B B - - B - - - - - - - - B - - A B - -   - - - - A B B B - - - - - - - - B A A A - - -   - - - - A B B B - - - - - - - - B A A - - - -   - - - - - A A B - - - - - - - - B A A - - - -   - - - - - A A B - - - - - - - Y A A A A - - -   - - - - A A A A F - - - - - - B A A A A - - -   - - - - A A A A Aq- - - - - - F A A A A - - -   - - - - A A - A I - - - - - - AqA - A A - - -   - - - - - A A A X - - - - - - I A A A - - - -   - - - - - A A A H - - - - - - X A A A - - - -   - - - - - A - A D - - - - - - H A A A - - - -   - - - - - A A A E - - - - - - D A A A - - - -   - - - - - A A A Q - - - - - - E A A A - - - -   - - - - - A A A L - - - - - - Q A A A - - - -   - - - - - - A A J AmI Z AhAtA AjA A - - - - -   - - - - - - - A A A A A A A A A A - - - - - -   - - - - - - - - A A A A A A A A - - - - - - -   - - - - - - - - - A A A A A A - - - - - - - -   
- - - - - - - - - - - - - - - - - - - - - - -   - - - - - - - - - - - - - - - - - - - - - - A   A - - - - - - - - - - - - - - - - - - - - - A   A - - - - - - - - - - - - - - - - - - - - - A   A A - - - - - - - - - - - - - - - - - - - - A   A A A - - - - - - - - - - - - - - - - - - A A   A A A B B B B B - - - - - - - - B B B B B A A   - A A A B B B B - - - - - - - - B A A A A A -   - - - B B - - B - - - - - - - - B - - A B - -   - - - - A B B B - - - - - - - - B A A A - - -   - - - - A B B B - - - - - - - - B A A - - - -   - - - - - A A B - - - - - - - - B A A A - - -   - - - - A A A B - - - - - - - - B A A A - - -   - - - - A A A B - - - - - - - - B A A A - - -   - - - - A A A B - - - - - - - - B A A A - - -   - - - - A A A B - - - - - - - - B A A A - - -   - - - - A A A B - - - - - - - - B A A A - - -   - - - - A A A B - - - - - - - - B A A A - - -   - - - - A A A B - - - - - - - - B A A A - - -   - - - - A A A B - - - - - - - - B A A A - - -   - - - - A A A B - - - - - - - - B A A A - - -   - - - - - A A B - - - - - - - - B A A - - - -   - - - - - - A B Z W P O B AxAiL B A - - - - -   - - - - - - - A A A A A A A A A A - - - - - -   - - - - - - - - A A A A A A A A - - - - - - -   - - - - - - - - - A A A A A A - - - - - - - -   
- - - - - - - - - - - - - - - - - - - - - - -   - - - - - - - - - - - - - - - - - - - - - - A   A - - - - - - - - - - - - - - - - - - - - - A   A - - - - - - - - - - - - - - - - - - - - - A   A A - - - - - - - - - - - - - - - - - - - - A   A A A - - - - - - - - - - - - - - - - - - A A   A A A B B B B B - - - - - - - - B B B B B A A   - A A A B B B B - - - - - - - - B A A A A A -   - - - B B - - B - - - - - - - - B - - A B - -   - - - - A B B B - - - - - - - - B A A A - - -   - - - - A B B B - - - - - - - - B A A - - - -   - - - - - A A B - - - - - - - - B A A A - - -   - - - - A A A B - - - - - - - - B A A A - - -   - - - - - N A B - - - - - - - - B A N - - - -   - - - - A A A B - - - - - - - - B A A A - - -   - - - - - N A B - - - - - - - - B A N - - - -   - - - - A A A B - - - - - - - - B A A A - - -   - - - - - N A B - - - - - - - - B A N - - - -   - - - - A A A B - - - - - - - - B A A A - - -   - - - - - N A B - - - - - - - - B A N - - - -   - - - - A A A B - - - - - - - - B A A A - - -   - - - - - A A B - - - - - - - - B A A - - - -   - - - - - - A B O E AnW V R AgF B A - - - - -   - - - - - - - A A A A A A A A A A - - - - - -   - - - - - - - - A A A A A A A A - - - - - - -   - - - - - - - - - A A A A A A - - - - - - - -   
- - - - - - - - - - - - - - - - - - - - - - -   - - - - - - - - - - - - - - - - - - - - - - -   - - - - - - - - - - - - - - - - - - - - - - A   A - - - - - - - - - - - - - - - - - - - - - A   A A - - - - - - - - - - - - - - - - - - - - A   A A A - - - - - - - - - - - - - - - - - - A A   A A A B B B B B - - - - - - - - B B B B B A A   - A A A B B B B - - - - - - - - B A A A A A -   - - - B B - - B - - - - - - - - B - - A B - -   - - - - A B B B - - - - - - - - B A A A - - -   - - - - A B B B - - - - - - - - B A A - - - -   - - - - - A A B - - - - - - - - B A A A - - -   - - - - A A A B - - - - - - - - B A A A - - -   - - - - A A A B - - - - - - - - B A A A - - -   - - - - A A A B - - - - - - - - B A A A - - -   - - - - A A - B - - - - - - - - B - A A - - -   - - - - A A A B - - - - - - - - B A A A - - -   - - - - A A A B - - - - - - - - B A A A - - -   - - - - A A A B - - - - - - - - B A A A - - -   - - - - A A A B - - - - - - - - B A A A - - -   - - - - A A A B - - - - - - - - B A A A - - -   - - - - - A A B - - - - - - - - B A A - - - -   - - - - - - A B W H AcAaK I L M B A - - - - -   - - - - - - - A A A A A A A A A A - - - - - -   - - - - - - - - A A A A A A A A - - - - - - -   - - - - - - - - - A A A A A A - - - - - - - -   
- - - - - - - - - - - - - - - - - - - - - - -   - - - - - - - - - - - - - - - - - - - - - - -   - - - - - - - - - - - - - - - - - - - - - - -   - - - - - - - - - - - - - - - - - - - - - - A   A A - - - - - - - - - - - - - - - - - - - - A   A A A - - - - - - - - - - - - - - - - - - A A   A A A B B B B B - - - - - - - - B B B B B A A   - A A A B B B B - - - - - - - - B A A A A A -   - - - B B - - B - - - - - - - - B - - A B - -   - - - - A B B B - - - - - - - - B A A A - - -   - - - - A B B B - - - - - - - - B A A - - - -   - - - - - A A B - - - - - - - - B A A B - - -   - - - - B A A B - - - - - - - - B A A B - - -   - - - - B A A B - - - - - - - - B A A B - - -   - - - - B A A B - - - - - - - - B A A B - - -   - - - - B A A B - - - - - - - - B A A B - - -   - - - - B A A B - - - - - - - - B A A B - - -   - - - - B A A B - - - - - - - - B A A B - - -   - - - - B A A B - - - - - - - - B A A B - - -   - - - - B A A B - - - - - - - - B A A B - - -   - - - - B A A B - - - - - - - - B A A B - - -   - - - - - A A B - - - - - - - - B A A - - - -   - - - - - - A B AbT K D AuF Z AvB A - - - - -   - - - - - - - A A A A A A A A A A - - - - - -   - - - - - - - - A A A A A A A A - - - - - - -   - - - - - - - - - A A A A A A - - - - - - - -   
- - - - - - - - - - - - - - - - - - - - - - -   - - - - - - - - - - - - - - - - - - - - - - -   - - - - - - - - - - - - - - - - - - - - - - -   - - - - - - - - - - - - - - - - - - - - - - -   - - - - - - - - - - - - - - - - - - - - - - A   A A A A A A A A - - - - - - - - A A A A A A A   A A A A A A A B - - - - - - - - B A A A A A A   - A A A A A A B - - - - - - - - B A A A A A -   - - - B A - - B - - - - - - - - B - - A B - -   - - - - A A A B - - - - - - - - B A A A - - -   - - - - - A A B - - - - - - - - B A A - - - -   - - - - - A A B - - - - - - - - B A A - - - -   - - - - B A A B - - - - - - - - B A A B - - -   - - - - B A A B - - - - - - - - B A A B - - -   - - - - B A A B - - - - - - - - B A A B - - -   - - - - B A A B - - - - - - - - B A A B - - -   - - - - B A A B - - - - - - - - B A A B - - -   - - - - B A A B - - - - - - - - B A A B - - -   - - - - B A A B - - - - - - - - B A A B - - -   - - - - B A A B - - - - - - - - B A A B - - -   - - - - - A A B - - - - - - - - B A A - - - -   - - - - - A A B - - - - - - - - B A A - - - -   - - - - - - A B S - - - - - - U B A - - - - -   - - - - - - - A A A AbD S G R I A - - - - - -   - - - - - - - - A A A A A A A A - - - - - - -   - - - - - - - - - - A A A A - - - - - - - - -   
- - - - - - - - - - - A A - - - - - - - - - -   - - - - - - - - - - A A A A - - - - - - - - -   - - - - - - - - - A A A A A A - - - - - - - -   - - - - - - - - - A A A A A A - - - - - - - -   - - - - - - - - - - - - - - - - - - - - - - -   - - - A A A A A - - - - - - - - A A A A A A A   - A A A A A A A A A A A A A A A A A A A A A A   - - A A A A A A H J S AzAwT M E A A A A A A -   - - - B A A A B - - - - - - - - B A A A B - -   - - - - B A A B - - - - - - - - B A B - - - -   - - - - - A A B - - - - - - - - B A - - - - -   - - - - - A A B - - - - - - - - B A A - - - -   - - - - - A A B - - - - - - - - B A A - - - -   - - - - - A A B - - - - - - - - B A A - - - -   - - - - - A A B - - - - - - - - B A A - - - -   - - - - - A A B - - - - - - - - B A A - - - -   - - - - - A A B - - - - - - - - B A A - - - -   - - - - - A A B - - - - - - - - B A A - - - -   - - - - - A A B - - - - - - - - B A A - - - -   - - - - - A A B - - - - - - - - B A A - - - -   - - - - - A A A ApS AmZ K AsU G A A A - - - -   - - - - - - A A AtAsQ AgQ V J AcA A - - - - -   - - - - - - A A B - - - - - - B A A - - - - -   - - - - - - - A A B B B B B B A A - - - - - -   - - - - - - - - - A A A A A A - - - - - - - -   - - - - - - - - - - - - - - - - - - - - - - -   
- - - - - - - - - - - A A - - - - - - - - - -   - - - - - - - - - - A A A - - - - - - - - - -   - - - - - - - - - - A A A A - - - - - - - - -   - - - - - - - - - - A A A A - - - - - - - - -   - - - - - - - - - A A A A A A - - - - - - - -   - - - - - - - - A A A A A A A A - - - - - - -   - - - A A A A A A - - - - - - A A A A A A - -   - - - A A A A A H H E K M E S AcA A A A A - -   - - - - A A A B - - - - - - - - B A A A - - -   - - - - - - A B - - - - - - - - B A - - - - -   - - - - - - A B - - - - - - - - B A - - - - -   - - - - - - A B - - - - - - - - B A - - - - -   - - - - - - A B - - - - - - - - B A - - - - -   - - - - - - A B - - - - - - - - B A - - - - -   - - - - - - A B - - - - - - - - B A - - - - -   - - - - - - A B - - - - - - - - B A - - - - -   - - - - - - A B - - - - - - - - B A - - - - -   - - - - - - A B - - - - - - - - B A - - - - -   - - - - - - A B - - - - - - - - B A - - - - -   - - - - - - A B - - - - - - - - B A - - - - -   - - - - - - A A AaU R D F AxX L A A - - - - -   - - - - - - A A F AlAaB P R P J A A - - - - -   - - - - - - - A A - - - - - - A A - - - - - -   - - - - - - - - A A A A A A A A - - - - - - -   - - - - - - - - - - - - - - - - - - - - - - -   - - - - - - - - - - - - - - - - - - - - - - -   
- - - - - - - - - - - A A - - - - - - - - - -   - - - - - - - - - - - A A - - - - - - - - - -   - - - - - - - - - - A A A A - - - - - - - - -   - - - - - - - - - - A A A A - - - - - - - - -   - - - - - - - - - A A A A A A - - - - - - - -   - - - - - - - - A A A A A A A A - - - - - - -   - - - - - - A A A - - - - - - A A A - - - - -   - - - - - A A A A A A A A A A A A A A - - - -   - - - - - - - A - - - - - - - - A - - - - - -   - - - - - - - A - - - - - - - - A - - - - - -   - - - - - - - A - - - - - - - - A - - - - - -   - - - - - - - A - - - - - - - - A - - - - - -   - - - - - - - A - - - - - - - - A - - - - - -   - - - - - - - A - - - - - - - - A - - - - - -   - - - - - - - A - - - - - - - - A - - - - - -   - - - - - - - A - - - - - - - - A - - - - - -   - - - - - - - A - - - - - - - - A - - - - - -   - - - - - - - A - - - - - - - - A - - - - - -   - - - - - - - A - - - - - - - - A - - - - - -   - - - - - - - A - - - - - - - - A - - - - - -   - - - - - - - A A A A A A A A A A - - - - - -   - - - - - - - - A A A A A A A A - - - - - - -   - - - - - - - - - - - - - - - - - - - - - - -   - - - - - - - - - - - - - - - - - - - - - - -   - - - - - - - - - - - - - - - - - - - - - - -   - - - - - - - - - - - - - - - - - - - - - - -   
