model
size = 23 26 14, scale = 0.05, origin = -y
material 
  colors = A:#A67C00 B:#FFBF00 C:#BF9B30 D:#222 E:#FFF F:#F4A7B9 G:#9F353A H:#F19483 I:#C46243 J:#9E7A7A K:#F596AA L:#C73E3A M:#A35E47 N:#64363C O:#FFFFFB P:#CB4042 Q:#D0104C R:#E16B8C S:#B54434 T:#B19693 U:#884C3A V:#F8C3CD W:#EEA9A9 X:#8E354A Y:#E87A90 Z:#724832 Aa:#D7C4BB Ab:#F75C2F Ac:#DB4D6D Ad:#86473F Ae:#CB1B45 Af:#904840 Ag:#9A5034 Ah:#FEDFE1 Ai:#BF6766 Aj:#A96360 Ak:#787D7B Al:#DDD Am:#B55D4C An:#B5495B Ao:#734338 Ap:#AB3B3A Aq:#554236 Ar:#FF797A As:#6A4028 At:#994639 Au:#EB7A77 Av:#854836 Aw:#B9887D Ax:#E83015 Ay:#DC9FB4 Az:#D05A6E Ba:#D75455
voxels
- - - - - - - - - - - - - - - - - - - - - - -   - - - - - - - - - - - A A - - - - - - - - - -   - - - - - - - - - - A A A A - - - - - - - - -   - - - - - - - - - A A A A A A - - - - - - - -   - - - - - - - - A A A A A A A A - - - - - - -   - - - - - - - A A A A A A A A A A - - - - - -   - - - C - - - A A A A A A A A A A - - - C - -   - - - - A A A A A A A A A A A A A A A A - - -   - - - - - - A A A A A A A A A A A A - - - - -   - - - - - - - A A A A A A A A A A - - - - - -   - - - - - - - A A A A A A A A A A - - - - - -   - - - - - - - A A A A A A A A A A - - - - - -   - - - - - - - A A A A A A A A A A - - - - - -   - - - - - - - A A A A A A A A A A - - - - - -   - - - - - - - A A A A A A A A A A - - - - - -   - - - - - - A A A A A A A A A A A A - - - - -   - - - - - - A A A A A A A A A A A A - - - - -   - - - - - - A A D D A A A A D D A A - - - - -   - - - - - - A D H H D A A D H H D A - - - - -   - - - - - - A A D D A A A A D D A A - - - - -   - - - - - - A A A A A A A A A A A A - - - - -   - - - - - - - - A A A A A A A A - - - - - - -   - - - - - - - - - A A A A A A - - - - - - - -   - - - - - - - - - - - - - - - - - - - - - - -   - - - - - - - - - - - - - - - - - - - - - - -   - - - - - - - - - - - - - - - - - - - - - - -   
- - - - - - - - - - - - - - - - - - - - - - -   - - - - - - - - - - - A A - - - - - - - - - -   - - - - - - - - - - A C C A - - - - - - - - -   - - - - - - - - - A C C C C A - - - - - - - -   - - - - - - - - - C C C C C C - - - - - - - -   - - - - - - - - A C C C C C C A - - - - - - -   - - A A C C C A A A A A A A A A A C C C A A -   - - - A A A A A A A A A A A A A A A A A A - -   - - - - A A A A A A A A A A A A A A A A - - -   - - - - - - A A A A A A A A A A A A - - - - -   - - - - - - A A A A A A A A A A A A - - - - -   - - - - - - A A A A A A A A A A A A - - - - -   - - - - - - A A A A A A A A A A A A - - - - -   - - - - - - A A A A A A A A A A A A - - - - -   - - - - - - A A A A A A A A A A A A - - - - -   - - - - - - A A A A A A A A A A A A - - - - -   - - - - - - A A A A A A A A A A A A - - - - -   - - - - - - A A D D A A A A D D A A - - - - -   - - - - - - A D AlAlD A A D AlAlD A - - - - -   - - - - - - A A D D A A A A D D A A - - - - -   - - - - - - A A A A A A A A A A A A - - - - -   - - - - - - A A A A A A A A A A A A - - - - -   - - - - - - - A A A A A A A A A A - - - - - -   - - - - - - - - A A A A A A A A - - - - - - -   - - - - - - - - - - - - - - - - - - - - - - -   - - - - - - - - - - - - - - - - - - - - - - -   
- - - - - - - - - - - - - - - - - - - - - - -   - - - - - - - - - - - - - - - - - - - - - - -   - - - - - - - - - - - - - - - - - - - - - - -   - - - - - - - - - - - - - - - - - - - - - - -   - - - - - - - - - - - - - - - - - - - - - - -   - - C C C C C C C - - - - - - C C C C C C C C   - A A A A A A A C C C C C C C C A A A A A A A   - - C A A A A A AzAvL J V E R Z A A A A A C -   - - - C A A A A AjV B N J F Q E A A A A C - -   - - - - A A A A AgN X L N R AmAfA A A - - - -   - - - - - A A A N I AeB L M A C A A A - - - -   - - - - - A A A K AsP AxAeH W Y A A A - - - -   - - - - - A A A P H B E M ApAyI A A A - - - -   - - - - - A A A B X AfAuZ W P E A A A - - - -   - - - - - A A A AfAqE AzB AoH F A A A - - - -   - - - - - A A A E AiAaAjG U ApR A A A - - - -   - - - - - A A A AaAjF AgA Z W M A A A - - - -   - - - - - A A A F J Q N J AeAoK A A A - - - -   - - - - - A A A Q AhAgV Y M U S A A A - - - -   - - - - - A A A AgU AhK I AiZ AbA A A - - - -   - - - - - A A A AhK AfP E ApAeU A A A - - - -   - - - - - - A A AfAeAcB F AnM K A A - - - - -   - - - - - - A A B B B B B B B B A A - - - - -   - - - - - - - A A B B B B B B A A - - - - - -   - - - - - - - - - A A A A A A - - - - - - - -   - - - - - - - - - - - - - - - - - - - - - - -   
- - - - - - - - - - - - - - - - - - - - - - -   - - - - - - - - - - - - - - - - - - - - - - -   - - - - - - - - - - - - - - - - - - - - - - -   - - - - - - - - - - - - - - - - - - - - - - -   - - - - - - - - - - - - - - - - - - - - - - A   A A A A A A A A C - - - - - - C A A A A A A A   A A A A A A A B - - - - - - - - B A A A A A A   - A A A A A A B - - - - - - - - B A A A A A -   - - - C A - - B - - - - - - - - B - - A C - -   - - - - A A A B - - - - - - - - B A A A - - -   - - - - - A A B - - - - - - - - B A A - - - -   - - - - - A A B - - - - - - - - B A A - - - -   - - - - - A A B - - - - - - - AsA A A - - - -   - - - - - A A A Aj- - - - - - AqA A A - - - -   - - - - - A A A Z - - - - - - AiA A A - - - -   - - - - - A A A Ao- - - - - - AdA A A - - - -   - - - - C A A A Y - - - - - - L A A A C - - -   - - - - C A A A S - - - - - - P A A A C - - -   - - - - C A A A C - - - - - - P A A A C - - -   - - - - - A A A Am- - - - - - X A A A - - - -   - - - - - A A A J - - - - - - AsA A A - - - -   - - - - - A A A Ad- - - - - - H A A A - - - -   - - - - - - A A AkE W G H S AgAkA A - - - - -   - - - - - - - A A A A A A A A A A - - - - - -   - - - - - - - - A A A A A A A A - - - - - - -   - - - - - - - - - - A A A A - - - - - - - - -   
- - - - - - - - - - - - - - - - - - - - - - -   - - - - - - - - - - - - - - - - - - - - - - -   - - - - - - - - - - - - - - - - - - - - - - -   - - - - - - - - - - - - - - - - - - - - - - A   A A - - - - - - - - - - - - - - - - - - - - A   A A A - - - - - - - - - - - - - - - - - - A A   A A A B B B B B - - - - - - - - B B B B B A A   - A A A C C C B - - - - - - - - B A A A A A -   - - - C C - - B - - - - - - - - B - - A C - -   - - - - A C C B - - - - - - - - B A A A - - -   - - - - A C C B - - - - - - - - B A A - - - -   - - - - - A A B - - - - - - - - B A A - - - -   - - - - - A A B - - - - - - - AqA A A - - - -   - - - - - A A A Ai- - - - - - G A A A - - - -   - - - - - A A A Ap- - - - - - AwA A A - - - -   - - - - - A A A An- - - - - - AxA A A - - - -   - - - - - - - - V - - - - - - T - - - - - - -   - - - - - A A A Am- - - - - - G A A A - - - -   - - - - - - - - Aw- - - - - - Q - - - - - - -   - - - - - A A A T - - - - - - AcA A A - - - -   - - - - - A A A Ab- - - - - - ArA A A - - - -   - - - - - A A A G - - - - - - I A A A - - - -   - - - - - - A A AkU AvAtL F AcAkA A - - - - -   - - - - - - - A A A A A A A A A A - - - - - -   - - - - - - - - A A A A A A A A - - - - - - -   - - - - - - - - - A A A A A A - - - - - - - -   
- - - - - - - - - - - - - - - - - - - - - - -   - - - - - - - - - - - - - - - - - - - - - - -   - - - - - - - - - - - - - - - - - - - - - - A   A - - - - - - - - - - - - - - - - - - - - - A   A A - - - - - - - - - - - - - - - - - - - - A   A A A - - - - - - - - - - - - - - - - - - A A   A A A B B B B B - - - - - - - - B B B B B A A   - A A A C C C B - - - - - - - - B A A A A A -   - - - C C - - B - - - - - - - - B - - A C - -   - - - - A C C B - - - - - - - - B A A A - - -   - - - - A C C B - - - - - - - - B A A - - - -   - - - - - A A B - - - - - - - - B A A - - - -   - - - - - A A B - - - - - - - Z A A A A - - -   - - - - A A A A G - - - - - - B A A A A - - -   - - - - A A A A Ar- - - - - - G A A A A - - -   - - - - A A - A J - - - - - - ArA - A A - - -   - - - - - A A A Y - - - - - - J A A A - - - -   - - - - - A A A I - - - - - - Y A A A - - - -   - - - - - A - A E - - - - - - I A A A - - - -   - - - - - A A A F - - - - - - E A A A - - - -   - - - - - A A A R - - - - - - F A A A - - - -   - - - - - A A A M - - - - - - R A A A - - - -   - - - - - - A A K AnJ AaAiAuA AkA A - - - - -   - - - - - - - A A A A A A A A A A - - - - - -   - - - - - - - - A A A A A A A A - - - - - - -   - - - - - - - - - A A A A A A - - - - - - - -   
- - - - - - - - - - - - - - - - - - - - - - -   - - - - - - - - - - - - - - - - - - - - - - A   A - - - - - - - - - - - - - - - - - - - - - A   A - - - - - - - - - - - - - - - - - - - - - A   A A - - - - - - - - - - - - - - - - - - - - A   A A A - - - - - - - - - - - - - - - - - - A A   A A A B B B B B - - - - - - - - B B B B B A A   - A A A C C C B - - - - - - - - B A A A A A -   - - - C C - - B - - - - - - - - B - - A C - -   - - - - A C C B - - - - - - - - B A A A - - -   - - - - A C C B - - - - - - - - B A A - - - -   - - - - - A A B - - - - - - - - B A A A - - -   - - - - A A A B - - - - - - - - B A A A - - -   - - - - A A A B - - - - - - - - B A A A - - -   - - - - A A A B - - - - - - - - B A A A - - -   - - - - A A A B - - - - - - - - B A A A - - -   - - - - A A A B - - - - - - - - B A A A - - -   - - - - A A A B - - - - - - - - B A A A - - -   - - - - A A A B - - - - - - - - B A A A - - -   - - - - A A A B - - - - - - - - B A A A - - -   - - - - A A A B - - - - - - - - B A A A - - -   - - - - - A A B - - - - - - - - B A A - - - -   - - - - - - A B AaX Q P C AyAjM B A - - - - -   - - - - - - - A A A A A A A A A A - - - - - -   - - - - - - - - A A A A A A A A - - - - - - -   - - - - - - - - - A A A A A A - - - - - - - -   
- - - - - - - - - - - - - - - - - - - - - - -   - - - - - - - - - - - - - - - - - - - - - - A   A - - - - - - - - - - - - - - - - - - - - - A   A - - - - - - - - - - - - - - - - - - - - - A   A A - - - - - - - - - - - - - - - - - - - - A   A A A - - - - - - - - - - - - - - - - - - A A   A A A B B B B B - - - - - - - - B B B B B A A   - A A A C C C B - - - - - - - - B A A A A A -   - - - C C - - B - - - - - - - - B - - A C - -   - - - - A C C B - - - - - - - - B A A A - - -   - - - - A C C B - - - - - - - - B A A - - - -   - - - - - A A B - - - - - - - - B A A A - - -   - - - - A A A B - - - - - - - - B A A A - - -   - - - - - O A B - - - - - - - - B A O - - - -   - - - - A A A B - - - - - - - - B A A A - - -   - - - - - O A B - - - - - - - - B A O - - - -   - - - - A A A B - - - - - - - - B A A A - - -   - - - - - O A B - - - - - - - - B A O - - - -   - - - - A A A B - - - - - - - - B A A A - - -   - - - - - O A B - - - - - - - - B A O - - - -   - - - - A A A B - - - - - - - - B A A A - - -   - - - - - A A B - - - - - - - - B A A - - - -   - - - - - - A B P F AoX W S AhG B A - - - - -   - - - - - - - A A A A A A A A A A - - - - - -   - - - - - - - - A A A A A A A A - - - - - - -   - - - - - - - - - A A A A A A - - - - - - - -   
- - - - - - - - - - - - - - - - - - - - - - -   - - - - - - - - - - - - - - - - - - - - - - -   - - - - - - - - - - - - - - - - - - - - - - A   A - - - - - - - - - - - - - - - - - - - - - A   A A - - - - - - - - - - - - - - - - - - - - A   A A A - - - - - - - - - - - - - - - - - - A A   A A A B B B B B - - - - - - - - B B B B B A A   - A A A C C C B - - - - - - - - B A A A A A -   - - - C C - - B - - - - - - - - B - - A C - -   - - - - A C C B - - - - - - - - B A A A - - -   - - - - A C C B - - - - - - - - B A A - - - -   - - - - - A A B - - - - - - - - B A A A - - -   - - - - A A A B - - - - - - - - B A A A - - -   - - - - A A A B - - - - - - - - B A A A - - -   - - - - A A A B - - - - - - - - B A A A - - -   - - - - A A - B - - - - - - - - B - A A - - -   - - - - A A A B - - - - - - - - B A A A - - -   - - - - A A A B - - - - - - - - B A A A - - -   - - - - A A A B - - - - - - - - B A A A - - -   - - - - A A A B - - - - - - - - B A A A - - -   - - - - A A A B - - - - - - - - B A A A - - -   - - - - - A A B - - - - - - - - B A A - - - -   - - - - - - A B X I AdAbL J M N B A - - - - -   - - - - - - - A A A A A A A A A A - - - - - -   - - - - - - - - A A A A A A A A - - - - - - -   - - - - - - - - - A A A A A A - - - - - - - -   
- - - - - - - - - - - - - - - - - - - - - - -   - - - - - - - - - - - - - - - - - - - - - - -   - - - - - - - - - - - - - - - - - - - - - - -   - - - - - - - - - - - - - - - - - - - - - - A   A A - - - - - - - - - - - - - - - - - - - - A   A A A - - - - - - - - - - - - - - - - - - A A   A A A B B B B B - - - - - - - - B B B B B A A   - A A A C C C B - - - - - - - - B A A A A A -   - - - B C - - B - - - - - - - - B - - A B - -   - - - - A C C B - - - - - - - - B A A A - - -   - - - - A C C B - - - - - - - - B A A - - - -   - - - - - A A B - - - - - - - - B A A B - - -   - - - - B A A B - - - - - - - - B A A B - - -   - - - - B A A B - - - - - - - - B A A B - - -   - - - - B A A B - - - - - - - - B A A B - - -   - - - - B A A B - - - - - - - - B A A B - - -   - - - - B A A B - - - - - - - - B A A B - - -   - - - - B A A B - - - - - - - - B A A B - - -   - - - - B A A B - - - - - - - - B A A B - - -   - - - - B A A B - - - - - - - - B A A B - - -   - - - - B A A B - - - - - - - - B A A B - - -   - - - - - A A B - - - - - - - - B A A - - - -   - - - - - - A B AcU L E AvG AaAwB A - - - - -   - - - - - - - A A A A A A A A A A - - - - - -   - - - - - - - - A A A A A A A A - - - - - - -   - - - - - - - - - A A A A A A - - - - - - - -   
- - - - - - - - - - - - - - - - - - - - - - -   - - - - - - - - - - - - - - - - - - - - - - -   - - - - - - - - - - - - - - - - - - - - - - -   - - - - - - - - - - - - - - - - - - - - - - -   - - - - - - - - - - - - - - - - - - - - - - A   A A A A A A A A - - - - - - - - A A A A A A A   A A A A A A A B - - - - - - - - B A A A A A A   - A A A A A A B - - - - - - - - B A A A A A -   - - - B A - - B - - - - - - - - B - - A B - -   - - - - A A A B - - - - - - - - B A A A - - -   - - - - - A A B - - - - - - - - B A A - - - -   - - - - - A A B - - - - - - - - B A A - - - -   - - - - B A A B - - - - - - - - B A A B - - -   - - - - B A A B - - - - - - - - B A A B - - -   - - - - B A A B - - - - - - - - B A A B - - -   - - - - B A A B - - - - - - - - B A A B - - -   - - - - B A A B - - - - - - - - B A A B - - -   - - - - B A A B - - - - - - - - B A A B - - -   - - - - B A A B - - - - - - - - B A A B - - -   - - - - B A A B - - - - - - - - B A A B - - -   - - - - - A A B - - - - - - - - B A A - - - -   - - - - - A A B - - - - - - - - B A A - - - -   - - - - - - A B T - - - - - - V B A - - - - -   - - - - - - - A A A AcE T H S J A - - - - - -   - - - - - - - - A A A A A A A A - - - - - - -   - - - - - - - - - - A A A A - - - - - - - - -   
- - - - - - - - - - - A A - - - - - - - - - -   - - - - - - - - - - A A A A - - - - - - - - -   - - - - - - - - - A A A A A A - - - - - - - -   - - - - - - - - - A A A A A A - - - - - - - -   - - - - - - - - - - - - - - - - - - - - - - -   - - - A A A A A - - - - - - - - A A A A A A A   - A A A A A A A A A A A A A A A A A A A A A A   - - A A A A A A I K T BaAxU N F A A A A A A -   - - - B A A A B - - - - - - - - B A A A B - -   - - - - B A A B - - - - - - - - B A B - - - -   - - - - - A A B - - - - - - - - B A - - - - -   - - - - - A A B - - - - - - - - B A A - - - -   - - - - - A A B - - - - - - - - B A A - - - -   - - - - - A A B - - - - - - - - B A A - - - -   - - - - - A A B - - - - - - - - B A A - - - -   - - - - - A A B - - - - - - - - B A A - - - -   - - - - - A A B - - - - - - - - B A A - - - -   - - - - - A A B - - - - - - - - B A A - - - -   - - - - - A A B - - - - - - - - B A A - - - -   - - - - - A A B - - - - - - - - B A A - - - -   - - - - - A A A AqT AnAaL AtV H A A A - - - -   - - - - - - A A AuAtR AhR W K AdA A - - - - -   - - - - - - A A B - - - - - - B A A - - - - -   - - - - - - - A A B B B B B B A A - - - - - -   - - - - - - - - - A A A A A A - - - - - - - -   - - - - - - - - - - - - - - - - - - - - - - -   
- - - - - - - - - - - A A - - - - - - - - - -   - - - - - - - - - - A A A - - - - - - - - - -   - - - - - - - - - - A A A A - - - - - - - - -   - - - - - - - - - - A A A A - - - - - - - - -   - - - - - - - - - A A A A A A - - - - - - - -   - - - - - - - - A A A A A A A A - - - - - - -   - - - A A A A A A - - - - - - A A A A A A - -   - - - A A A A A I I F L N F T AdA A A A A - -   - - - - A A A B - - - - - - - - B A A A - - -   - - - - - - A B - - - - - - - - B A - - - - -   - - - - - - A B - - - - - - - - B A - - - - -   - - - - - - A B - - - - - - - - B A - - - - -   - - - - - - A B - - - - - - - - B A - - - - -   - - - - - - A B - - - - - - - - B A - - - - -   - - - - - - A B - - - - - - - - B A - - - - -   - - - - - - A B - - - - - - - - B A - - - - -   - - - - - - A B - - - - - - - - B A - - - - -   - - - - - - A B - - - - - - - - B A - - - - -   - - - - - - A B - - - - - - - - B A - - - - -   - - - - - - A B - - - - - - - - B A - - - - -   - - - - - - A A AbV S E G AyY M A A - - - - -   - - - - - - A A G AmAbC Q S Q K A A - - - - -   - - - - - - - A A - - - - - - A A - - - - - -   - - - - - - - - A A A A A A A A - - - - - - -   - - - - - - - - - - - - - - - - - - - - - - -   - - - - - - - - - - - - - - - - - - - - - - -   
- - - - - - - - - - - A A - - - - - - - - - -   - - - - - - - - - - - A A - - - - - - - - - -   - - - - - - - - - - A A A A - - - - - - - - -   - - - - - - - - - - A A A A - - - - - - - - -   - - - - - - - - - A A A A A A - - - - - - - -   - - - - - - - - A A A A A A A A - - - - - - -   - - - - - - A A A - - - - - - A A A - - - - -   - - - - - A A A A A A A A A A A A A A - - - -   - - - - - - - A - - - - - - - - A - - - - - -   - - - - - - - A - - - - - - - - A - - - - - -   - - - - - - - A - - - - - - - - A - - - - - -   - - - - - - - A - - - - - - - - A - - - - - -   - - - - - - - A - - - - - - - - A - - - - - -   - - - - - - - A - - - - - - - - A - - - - - -   - - - - - - - A - - - - - - - - A - - - - - -   - - - - - - - A - - - - - - - - A - - - - - -   - - - - - - - A - - - - - - - - A - - - - - -   - - - - - - - A - - - - - - - - A - - - - - -   - - - - - - - A - - - - - - - - A - - - - - -   - - - - - - - A - - - - - - - - A - - - - - -   - - - - - - - A A A A A A A A A A - - - - - -   - - - - - - - - A A A A A A A A - - - - - - -   - - - - - - - - - - - - - - - - - - - - - - -   - - - - - - - - - - - - - - - - - - - - - - -   - - - - - - - - - - - - - - - - - - - - - - -   - - - - - - - - - - - - - - - - - - - - - - -   
