model
size = 14 12 6, scale = 0.05, origin = -y
material 
  colors = A:#111 B:#F0C C:#222 D:#EEE E:#444 F:#00E G:#007
voxels
-------------- -BA--AAAA--AB- ABA-AABBAA-ABA ABA-ABBBBA-ABA -BA--ABBA--AB- ------AA------ -------------- -------------- -------------- -------------- -------------- -------------- 
-BA--------AB- AFA--AAAA--AFA AFA-AEEEAA-AFA AFA-AEEECA-AFA AFA-AEEECA-AFA -BA--AAAA--AB- ------CC------ -------------- -------------- -------------- -------------- -------------- 
ABA--------ABA AFA--AAAA--AEA BFEBACEEAABEEB BFEBEEEECCBEEB AFA-AEEEEA-AEA ABA--AAAA--ABA -----CAAC----- ---CCDDDDCC--- --CDDDDDDDDC-- --CDDDDDDDDC-- --CDDDDDDDDC-- ---CCCCCCCC--- 
ABA--------ABA AFA--AAAA--AEA BFEBAAAAAABEEB BFEBCAAAAABEEB AFEBGGAAAGBEEA ABA-CAAAAC-ABA ----CAAAAC---- ---BADDDDAB--- --BBDDDDDDBB-- --BBDDDDDDBB-- --BBDDDDDDBB-- ---BBBBBBBB--- 
-BA--------AB- AFA--AAAA--AFA AFEBA----ABEFA AFEBA----ABEFA AFEBAA--AGBEFA -BA-CAAAAC-AB- ----CACCAC---- ---BA----AB--- --B--------B-- --B--------B-- --B--------B-- ---BBBBBBBB--- 
-------------- -BA--CCCC--AB- ABA-C----C-ABA ABA-C----C-ABA -BA-C----C-AB- ----CC--CC---- ----CC--CC---- ---CC----CC--- --C--------C-- --C--------C-- --C--------C-- ---CCCCCCCC--- 
