model
size = 24 30 16, scale = 0.05, origin = -y
material 
  colors = A:#080 B:#111 C:#555 D:#050 E:#800 F:#DDD G:#00E H:#EEE I:#777 J:#444 K:#AAA
voxels
------------------------ ------------------------ ------------------------ ------------------------ ------------------------ -------BBBB--BBBB------- ------BB---BB---BB------ -----BB----------BB----- ----BB--EEEEEEEE--BB---- ---BB----EKEEKE----BB--- ---B----------------B--- -----------BB----------- ----------BAAB---------- ----------AAAA---------- -----------AA----------- -----------AA----------- ------FF---AA---FF------ -----FGGF------FGGF----- -----HGGH------HGGH----- ------HH--------HH------ --------BB----BB-------- -----BBB--------BBB----- ------------------------ ---BB--------------BB--- ----B--------------B---- ----B-B-B-B--B-B-B-B---- ----BBBBBBBBBBBBBBBB---- -----BBBBBBBBBBBBBB----- ------BBBBBBBBBBBB------ ------------------------ 
------------------------ ------------------------ ------------------------ ------------------------ ------------------------ -------BBBBBBBBBB------- ------BBDAABBAADBB------ -----BBDAAAAAAAADBB----- ----BBDAAAAAAAAAADBB---- ---BBDAAAAAAAAAAAADBB--- ---BDAAAAAAAAAAAAAADB--- ---BAAAAAAAAAAAAAAAAB--- ---AAAAAAAAAAAAAAAAAA--- ---AAAAAAAAAAAAAAAAAA--- ---AAAAAAAAAAAAAAAAAA--- ---AAAAAAAAAAAAAAAAAA--- ---AAAAAAAAAAAAAAAAAA--- ---AAAAAAAAAAAAAAAAAA--- ---AAAAAAAAAAAAAAAAAA--- ---AAAAAAAAAAAAAAAAAA--- ---AAAAABBAAAABBAAAAA--- ---DBBBBAAAAAAAABBBBD--- ---BBAAAAAAAAAAAAAABB--- ---BBAIAIAIAAIAIAIABB--- ----BAAAAAAAAAAAAAAB---- ----BAAAAAAAAAAAAAAB---- ----BBAAAAAAAAAAAABB---- -----BAAAAAAAAAAAAB----- ------BAAAAAAAAAAB------ ------BBBBBBBBBBBB------ 
------------------------ ------------------------ ------------------------ ------------------------ ------------------------ -------BBBBBBBBBB------- ------BBAAABBAAABB------ -----BBAAAAAAAAAABB----- ----BBAAAAAAAAAAAABB---- ---BBAAAAAAAAAAAAAABB--- ---BAAAAAAAAAAAAAAAAB--- ---BAAAAAAAAAAAAAAAAB--- ---BAAAAAAAAAAAAAAAAB--- ---AAAAAAAAAAAAAAAAAA--- ---AAAAAAAAAAAAAAAAAA--- ---AAAAAAAAAAAAAAAAAA--- ---AAAAAAAAAAAAAAAAAA--- ---AAAAAAAAAAAAAAAAAA--- ---AAAAAAAAAAAAAAAAAA--- ---AAAAAAAAAAAAAAAAAA--- ---AAAAABBAAAABBAAAAA--- ---BBBBBAAAAAAAABBBBB--- ---BBAAAAAAAAAAAAAABB--- ---BBAAAAAAAAAAAAAABB--- ----BAAAAAAAAAAAAAAB---- ----BAAAAAAAAAAAAAAB---- ----BBAAAAAAAAAAAABB---- -----BAAAAAAAAAAAAB----- ------BAAAAAAAAAAB------ ------BBBBBBBBBBBB------ 
------------------------ ------------------------ ------------------------ ------------------------ ------------------------ -------BBBBBBBBBB------- ------BBAAABBAAABB------ -----BBAAAAAAAAAABB----- ----BBAAAAAAAAAAAABB---- ---BBAAAAAAAAAAAAAABB--- ---BAAAAAAAAAAAAAAAAB--- ---BAAAAAAAAAAAAAAAAB--- ---BAAAAAAAAAAAAAAAAB--- ---AAAAAAAAAAAAAAAAAA--- ---AAAAAAAAAAAAAAAAAA--- ---AAAAAAAAAAAAAAAAAA--- ---AAAAAAAAAAAAAAAAAA--- ---AAAAAAAAAAAAAAAAAA--- ---AAAAAAAAAAAAAAAAAA--- ---AAAAAAAAAAAAAAAAAA--- ---BAAAABBAAAABBAAAAB--- ---BBBBBAAAAAAAABBBBB--- ---BBAAAAAAAAAAAAAABB--- ---BBAAAAAAAAAAAAAABB--- ----BAAAAAAAAAAAAAAB---- ----BAAAAAAAAAAAAAAB---- ----BBAAAAAAAAAAAABB---- -----BAAAAAAAAAAAAB----- ------BAAAAAAAAAAB------ ------BBBBBBBBBBBB------ 
-------AAAAAAAAAA------- -------AAAAAAAAAA------- -------AAAAAAAAAA------- -------AAAAAAAAAA------- -------AAAAAAAAAA------- -------BBBBAABBBB------- ------BBAAABBAAABB------ -----BBAAAAAAAAAABB----- ----BBAAAAAAAAAAAABB---- ---BBAAAAAAAAAAAAAABB--- ---BAAAAAAAAAAAAAAAAB--- ---BAAAAAAAAAAAAAAAAB--- ---BAAAAAAAAAAAAAAAAB--- ---AAAAAAAAAAAAAAAAAA--- ---AAAAAAAAAAAAAAAAAA--- --AAAAAAAAAAAAAAAAAAAA-- --AAAAAAAAAAAAAAAAAAAA-- --AAAAAAAAAAAAAAAAAAAA-- --AAAAAAAAAAAAAAAAAAAA-- --DAAAAAAAAAAAAAAAAAAD-- ---BAAAABBAAAABBAAAAB--- ---BBBBBAAAAAAAABBBBB--- ---BBAAAAAAAAAAAAAABB--- ---BBAAAAAAAAAAAAAABB--- ----BAAAAAAAAAAAAAAB---- ----BAAAAAAAAAAAAAAB---- ----BBAAAAAAAAAAAABB---- -----BAAAAAAAAAAAAB----- ------BAAAAAAAAAAB------ ------BBBBBBBBBBBB------ 
-------AAAAAAAAAA------- -------AAAAAAAAAA------- -------AAAAAAAAAA------- -------AAAAAAAAAA------- -------AAAAAAAAAA------- -------BBBBAABBBB------- ------BBAAABBAAABB------ -----BBAAAAAAAAAABB----- ----BBAAAAAAAAAAAABB---- ---BBAAAAAAAAAAAAAABB--- ---BAAAAAAAAAAAAAAAAB--- ---BAAAAAAAAAAAAAAAAB--- ---BAAAAAAAAAAAAAAAAB--- --DAAAAAAAAAAAAAAAAAAD-- --AAAAAAAAAAAAAAAAAAAA-- --DAAAAAAAAAAAAAAAAAAD-- --AAAAAAAAAAAAAAAAAAAA-- --AAAAAAAAAAAAAAAAAAAA-- --AAAAAAAAAAAAAAAAAAAA-- --DAAAAAAAAAAAAAAAAAAD-- --DBAAAABBAAAABBAAAABD-- ---BBBBBAAAAAAAABBBBB--- ---BBAAAAAAAAAAAAAABB--- C--BBAAAAAAAAAAAAAABB--C C---BAAAAAAAAAAAAAAB---C C---BAAAAAAAAAAAAAAB---C C---BBAAAAAAAAAAAABB---C -----BAAAAAAAAAAAAB----- ------BAAAAAAAAAAB------ ------BBBBBBBBBBBB------ 
-------AAAAAAAAAA------- -------AAAAAAAAAA------- -------AAAAAAAAAA------- -------AAAAAAAAAA------- -------AAAAAAAAAA------- -------BBBBAABBBB------- ------BBAAABBAAABB------ -----BBAAAAAAAAAABB----- ----BBAAAAAAAAAAAABB---- ---BBAAAAAAAAAAAAAABB--- ---BAAAAAAAAAAAAAAAAB--- ---BAAAAAAAAAAAAAAAAB--- ---BAAAAAAAAAAAAAAAAB--- --DAAAAAAAAAAAAAAAAAAD-- --AAAAAAAAAAAAAAAAAAAA-- --AAAAAAAAAAAAAAAAAAAA-- --DAAAAAAAAAAAAAAAAAAD-- --AAAAAAAAAAAAAAAAAAAA-- --AAAAAAAAAAAAAAAAAAAA-- --AAAAAAAAAAAAAAAAAAAA-- --DBAAAABBAAAABBAAAABD-- ---BBBBBAAAAAAAABBBBB--- ---BBAAAAAAAAAAAAAABB--- C--BBAAAAAAAAAAAAAABB--C JCCCBAAAAAAAAAAAAAABCCCJ JCCCBAAAAAAAAAAAAAABCCCJ C---BBAAAAAAAAAAAABB---C -----BAAAAAAAAAAAAB----- ------BAAAAAAAAAAB------ ------BBBBBBBBBBBB------ 
-------AAAAAAAAAA------- -------AAAAAAAAAA------- -------AAAAAAAAAA------- -------AAAAAAAAAA------- -------AAAAAAAAAA------- -------BBBBAABBBB------- ------BBAAABBAAABB------ -----BBAAAAAAAAAABB----- ----BBAAAAAAAAAAAABB---- ---BBAAAAAAAAAAAAAABB--- ---BAAAAAAAAAAAAAAAAB--- ---BAAAAAAAAAAAAAAAAB--- ---BAAAAAAAAAAAAAAAAB--- ---BAAAAAAAAAAAAAAAAB--- --DAAAAAAAAAAAAAAAAAAD-- --AAAAAAAAAAAAAAAAAAAA-- --AAAAAAAAAAAAAAAAAAAA-- --DAAAAAAAAAAAAAAAAAAD-- --AAAAAAAAAAAAAAAAAAAA-- --AAAAAAAAAAAAAAAAAAAA-- --DBAAAABBAAAABBAAAABD-- ---BBBBBAAAAAAAABBBBB--- ---BBAAAAAAAAAAAAAABB--- C--BBAAAAAAAAAAAAAABB--C CCCCBAAAAAAAAAAAAAABCCCJ CCCCBAAAAAAAAAAAAAABCCCJ C---BBAAAAAAAAAAAABB---C -----BAAAAAAAAAAAAB----- ------BAAAAAAAAAAB------ ------BBBBBBBBBBBB------ 
-------AAAAAAAAAA------- -------AAAAAAAAAA------- -------AAAAAAAAAA------- -------AAAAAAAAAA------- -------AAAAAAAAAA------- -------BBBBAABBBB------- ------BBAAABBAAABB------ -----BBAAAAAAAAAABB----- ----BBAAAAAAAAAAAABB---- ---BBAAAAAAAAAAAAAABB--- ---BAAAAAAAAAAAAAAAAB--- ---BAAAAAAAAAAAAAAAAB--- ---BAAAAAAAAAAAAAAAAB--- ---BAAAAAAAAAAAAAAAAB--- ---BAAAAAAAAAAAAAAAAB--- --DAAAAAAAAAAAAAAAAAAD-- --AAAAAAAAAAAAAAAAAAAA-- --AAAAAAAAAAAAAAAAAAAA-- --AAAAAAAAAAAAAAAAAAAA-- --AAAAAAAAAAAAAAAAAAAA-- --DBAAAABBAAAABBAAAABD-- ---BBBBBAAAAAAAABBBBB--- ---BBAAAAAAAAAAAAAABB--- C--BBAAAAAAAAAAAAAABB--C C---BAAAAAAAAAAAAAAB---C C---BAAAAAAAAAAAAAAB---C C---BBAAAAAAAAAAAABB---C -----BAAAAAAAAAAAAB----- ------BAAAAAAAAAAB------ ------BBBBBBBBBBBB------ 
-------AAAAAAAAAA------- -------AAAAAAAAAA------- -------AAAAAAAAAA------- -------AAAAAAAAAA------- -------AAAAAAAAAA------- -------BBBBAABBBB------- ------BBAAABBAAABB------ -----BBAAAAAAAAAABB----- ----BBAAAAAAAAAAAABB---- ---BBAAAAAAAAAAAAAABB--- ---BAAAAAAAAAAAAAAAAB--- ---BAAAAAAAAAAAAAAAAB--- ---BAAAAAAAAAAAAAAAAB--- ---BAAAAAAAAAAAAAAAAB--- ---BAAAAAAAAAAAAAAAAB--- --DAAAAAAAAAAAAAAAAAAD-- --DAAAAAAAAAAAAAAAAAAD-- --DAAAAAAAAAAAAAAAAAAD-- --DAAAAAAAAAAAAAAAAAAD-- --DAAAAAAAAAAAAAAAAAAD-- ---BAAAABBAAAABBAAAAB--- ---BBBBBAAAAAAAABBBBB--- ---BBAAAAAAAAAAAAAABB--- ---BBAAAAAAAAAAAAAABB--- ----BAAAAAAAAAAAAAAB---- ----BAAAAAAAAAAAAAAB---- ----BBAAAAAAAAAAAABB---- -----BAAAAAAAAAAAAB----- ------BAAAAAAAAAAB------ ------BBBBBBBBBBBB------ 
-------AAAAAAAAAA------- -------AAAAAAAAAA------- -------AAAAAAAAAA------- -------AAAAAAAAAA------- -------AAAAAAAAAA------- -------BBBBAABBBB------- ------BBAAABBAAABB------ -----BBAAAAAAAAAABB----- ----BBAAAAAAAAAAAABB---- ---BBAAAAAAAAAAAAAABB--- ---BAAAAAAAAAAAAAAAAB--- ---BAAAAAAAAAAAAAAAAB--- ---BAAAAAAAAAAAAAAAAB--- ---BAAAAAAAAAAAAAAAAB--- ---BAAAAAAAAAAAAAAAAB--- ---BAAAAAAAAAAAAAAAAB--- ---BAAAAAAAAAAAAAAAAB--- ---BAAAAAAAAAAAAAAAAB--- ---BAAAAAAAAAAAAAAAAB--- ---BAAAAAAAAAAAAAAAAB--- ---BAAAABBAAAABBAAAAB--- ---BBBBBAAAAAAAABBBBB--- ---BBAAAAAAAAAAAAAABB--- ---BBAAAAAAAAAAAAAABB--- ----BAAAAAAAAAAAAAAB---- ----BAAAAAAAAAAAAAAB---- ----BBAAAAAAAAAAAABB---- -----BAAAAAAAAAAAAB----- ------BAAAAAAAAAAB------ ------BBBBBBBBBBBB------ 
-------AAAAAAAAAA------- -------AAAAAAAAAA------- -------AAAAAAAAAA------- -------AAAAAAAAAA------- -------AAAAAAAAAA------- -------BBBBAABBBB------- ------BBAAABBAAABB------ -----BBAAAAAAAAAABB----- ----BBAAAAAAAAAAAABB---- ---BBAAAAAAAAAAAAAABB--- ---BAAAAAAAAAAAAAAAAB--- ---BAAAAAAAAAAAAAAAAB--- ---BAAAAAAAAAAAAAAAAB--- ---BAAAAAAAAAAAAAAAAB--- ---BAAAAAAAAAAAAAAAAB--- ---BAAAAAAAAAAAAAAAAB--- ---BAAAAAAAAAAAAAAAAB--- ---BAAAAAAAAAAAAAAAAB--- ---BAAAAAAAAAAAAAAAAB--- ---BAAAAAAAAAAAAAAAAB--- ---BAAAABBAAAABBAAAAB--- ---BBBBBAAAAAAAABBBBB--- ---BBAAAAAAAAAAAAAABB--- ---BBAAAAAAAAAAAAAABB--- ----BAAAAAAAAAAAAAAB---- ----BAAAAAAAAAAAAAAB---- ----BBAAAAAAAAAAAABB---- -----BAAAAAAAAAAAAB----- ------BAAAAAAAAAAB------ ------BBBBBBBBBBBB------ 
------------------------ ------------------------ ------------------------ ------------------------ ------------------------ -------BBBBAABBBB------- ------BBAAABBAAABB------ -----BBAAAAAAAAAABB----- ----BBAAAAAAAAAAAABB---- ---BBAAAAAAAAAAAAAABB--- ---BAAAAAAAAAAAAAAAAB--- ---BAAAAAAAAAAAAAAAAB--- ---BAAAAAAAAAAAAAAAAB--- ---BAAAAAAAAAAAAAAAAB--- ---BAAAAAAAAAAAAAAAAB--- ---BAAAAAAAAAAAAAAAAB--- ---BAAAAAAAAAAAAAAAAB--- ---BAAAAAAAAAAAAAAAAB--- ---BAAAAAAAAAAAAAAAAB--- ---BAAAAAAAAAAAAAAAAB--- ---BAAAABBAAAABBAAAAB--- ---BBBBBAAAAAAAABBBBB--- ---BBAAAAAAAAAAAAAABB--- ---BBAAAAAAAAAAAAAABB--- ----BAAAAAAAAAAAAAAB---- ----BAAAAAAAAAAAAAAB---- ----BBAAAAAAAAAAAABB---- -----BAAAAAAAAAAAAB----- ------BAAAAAAAAAAB------ ------BBBBBBBBBBBB------ 
------------------------ ------------------------ ------------------------ ------------------------ ------------------------ -------BBBBBBBBBB------- ------BBBBBBBBBBBB------ -----BBAAAAAAAAAABB----- ----BBAAAAAAAAAAAABB---- ---BBAAAAAAAAAAAAAABB--- ---BAAAAAAAAAAAAAAAAB--- ---BAAAAAAAAAAAAAAAAB--- ---BAAAAAAAAAAAAAAAAB--- ---BAAAAAAAAAAAAAAAAB--- ---BAAAAAAAAAAAAAAAAB--- ---BAAAAAAAAAAAAAAAAB--- ---BAAAAAAAAAAAAAAAAB--- ---BAAAAAAAAAAAAAAAAB--- ---BAAAAAAAAAAAAAAAAB--- ---BAAAAAAAAAAAAAAAAB--- ---BAAAABBAAAABBAAAAB--- ---BBBBBAAAAAAAABBBBB--- ---BBAAAAAAAAAAAAAABB--- ---BBAAAAAAAAAAAAAABB--- ----BAAAAAAAAAAAAAAB---- ----BAAAAAAAAAAAAAAB---- ----BBAAAAAAAAAAAABB---- -----BAAAAAAAAAAAAB----- ------BAAAAAAAAAAB------ ------BBBBBBBBBBBB------ 
------------------------ ------------------------ ------------------------ ------------------------ ------------------------ ------------------------ ------------------------ -----BBBBBBBBBBBBBB----- ----BBAAAAAAAAAAAABB---- ---BBAAAAAAAAAAAAAABB--- ---BAAAAAAAAAAAAAAAAB--- ---BAAAAAAAAAAAAAAAAB--- ---BAAAAAAAAAAAAAAAAB--- ---BAAAAAAAAAAAAAAAAB--- ---BAAAAAAAAAAAAAAAAB--- ---BAAAAAAAAAAAAAAAAB--- ---BAAAAAAAAAAAAAAAAB--- ---BAAAAAAAAAAAAAAAAB--- ---BAAAAAAAAAAAAAAAAB--- ---BAAAAAAAAAAAAAAAAB--- ---BAAAABBAAAABBAAAAB--- ---BBBBBAAAAAAAABBBBB--- ---BBAAAAAAAAAAAAAABB--- ---BBAAAAAAAAAAAAAABB--- ----BAAAAAAAAAAAAAAB---- ----BAAAAAAAAAAAAAAB---- ----BBAAAAAAAAAAAABB---- -----BAAAAAAAAAAAAB----- ------BBBBBBBBBBBB------ ------------------------ 
------------------------ ------------------------ ------------------------ ------------------------ ------------------------ ------------------------ ------------------------ ------------------------ ----BBBBBBBBBBBBBBBB---- ---BBBBBBBBBBBBBBBBBB--- ---BBBBBBBBBBBBBBBBBB--- ---BBBBBBBBBBBBBBBBBB--- ---BBBBBBBBBBBBBBBBBB--- ---BBBBBBBBBBBBBBBBBB--- ---BBBBBBBBBBBBBBBBBB--- ---BBBBBBBBBBBBBBBBBB--- ---BBBBBBBBBBBBBBBBBB--- ---BBBBBBBBBBBBBBBBBB--- ---BBBBBBBBBBBBBBBBBB--- ---BBBBBBBBBBBBBBBBBB--- ---BBBBBBBBBBBBBBBBBB--- ---BBBBBBBBBBBBBBBBBB--- ---BBBBBBBBBBBBBBBBBB--- ---BBBBBBBBBBBBBBBBBB--- ----BBBBBBBBBBBBBBBB---- ----BBBBBBBBBBBBBBBB---- ----BBBBBBBBBBBBBBBB---- -----BBBBBBBBBBBBBB----- ------------------------ ------------------------ 
