model
size = 31 9 31, scale = 0.05, origin = -y
material 
  colors = A:#EEE B:#746039
voxels
------------AAAAAAA------------ ------------AAAAAAA------------ ------------AAAAAAA------------ ------------AAAAAAA------------ ------------AAAAAAA------------ ------------AAAAAAA------------ ------------AAAAAAA------------ ------------AAAAAAA------------ ------------AAAAAAA------------ 
---------AAAAAAAAAAAAA--------- ---------AAAAAAAAAAAAA--------- ---------AAAAAAAAAAAAA--------- ---------AAAAAAAAAAAAA--------- ---------AAAAAAAAAAAAA--------- ---------AAAAAAAAAAAAA--------- ---------AAAAAAAAAAAAA--------- ---------AAAAAAAAAAAAA--------- ---------AAAAAAAAAAAAA--------- 
-------AAAAAAAAAAAAAAAAA------- -------AAAAAAAAAAAAAAAAA------- -------AAAAAAAAAAAAAAAAA------- -------AAAAAAAAAAAAAAAAA------- -------AAAAAAAAAAAAAAAAA------- -------AAAAAAAAAAAAAAAAA------- -------AAAAAAAAAAAAAAAAA------- -------AAAAAAAAAAAAAAAAA------- -------AAAAAAAAAAAAAAAAA------- 
------AAAAAAAAAAAAAAAAAAA------ ------AAAAAAAAAAAAAAAAAAA------ ------AAAAAAAAAAAAAAAAAAA------ ------AAAAAAAAAAAAAAAAAAA------ ------AAAAAAAAAAAAAAAAAAA------ ------AAAAAAAAAAAAAAAAAAA------ ------AAAAAAAAAAAAAAAAAAA------ ------AAAAAAAAAAAAAAAAAAA------ ------AAAAAAAAAAAAAAAAAAA------ 
-----AAAAAAAAAAAAAAAAAAAAA----- -----AAAAAAAAAAAAAAAAAAAAA----- -----AAAAAAAAAAAAAAAAAAAAA----- -----AAAAAAAAAAAAAAAAAAAAA----- -----AAAAAAAAAAAAAAAAAAAAA----- -----AAAAAAAAAAAAAAAAAAAAA----- -----AAAAAAAAAAAAAAAAAAAAA----- -----AAAAAAAAAAAAAAAAAAAAA----- -----AAAAAAAAAAAAAAAAAAAAA----- 
----AAAAAAAAAAAAAAAAAAAAAAA---- ----AAAAAAAAAAAAAAAAAAAAAAA---- ----AAAAAAAAAAAAAAAAAAAAAAA---- ----AAAAAAAAAAAAAAAAAAAAAAA---- ----AAAAAAAAAAAAAAAAAAAAAAA---- ----AAAAAAAAAAAAAAAAAAAAAAA---- ----AAAAAAAAAAAAAAAAAAAAAAA---- ----AAAAAAAAAAAAAAAAAAAAAAA---- ----AAAAAAAAAAAAAAAAAAAAAAA---- 
---AAAAAAAAAAAAAAAAAAAAAAAAA--- ---AAAAAAAAAAAAAAAAAAAAAAAAA--- ---AAAAAAAAAAAAAAAAAAAAAAAAA--- ---AAAAAAAAAAAAAAAAAAAAAAAAA--- ---AAAAAAAAAAAAAAAAAAAAAAAAA--- ---AAAAAAAAAAAAAAAAAAAAAAAAA--- ---AAAAAAAAAAAAAAAAAAAAAAAAA--- ---AAAAAAAAAAAAAAAAAAAAAAAAA--- ---AAAAAAAAAAAAAAAAAAAAAAAAA--- 
--AAAAAAAAAA-----BBAAAAAAAAAA-- --AAAAAAAAAAABBBBBAAAAAAAAAAA-- --AAAAAAAAAAABBBBBAAAAAAAAAAA-- --AAAAAAAAAAABBBBBAAAAAAAAAAA-- --AAAAAAAAAAABBBBBAAAAAAAAAAA-- --AAAAAAAAAAABBBBBAAAAAAAAAAA-- --AAAAAAAAAAABBBBBAAAAAAAAAAA-- --AAAAAAAAAAABBBBBAAAAAAAAAAA-- --AAAAAAAAAAABBBBBAAAAAAAAAAA-- 
--AAAAAAAA---------BBAAAAAAAA-- --AAAAAAAAABB-----BBAAAAAAAAA-- --AAAAAAAAABB-----BBAAAAAAAAA-- --AAAAAAAAABB-----BBAAAAAAAAA-- --AAAAAAAAABB-----BBAAAAAAAAA-- --AAAAAAAAABB-----BBAAAAAAAAA-- --AAAAAAAAABB-----BBAAAAAAAAA-- --AAAAAAAAABB-----BBAAAAAAAAA-- --AAAAAAAAABB-----BBAAAAAAAAA-- 
-AAAAAAA-------------AAAAAAAAA- -AAAAAAAAAB---------BAAAAAAAAA- -AAAAAAAAAB---------BAAAAAAAAA- -AAAAAAAAAB---------BAAAAAAAAA- -AAAAAAAAAB---------BAAAAAAAAA- -AAAAAAAAAB---------BAAAAAAAAA- -AAAAAAAAAB---------BAAAAAAAAA- -AAAAAAAAAB---------BAAAAAAAAA- -AAAAAAAAAB---------BAAAAAAAAA- 
-AAAAAAA-------------BAAAAAAAA- -AAAAAAAAB-----------BAAAAAAAA- -AAAAAAAAB-----------BAAAAAAAA- -AAAAAAAAB-----------BAAAAAAAA- -AAAAAAAAB-----------BAAAAAAAA- -AAAAAAAAB-----------BAAAAAAAA- -AAAAAAAAB-----------BAAAAAAAA- -AAAAAAAAB-----------BAAAAAAAA- -AAAAAAAAB-----------BAAAAAAAA- 
-AAAAAA---------------BAAAAAAA- -AAAAAAAB-------------BAAAAAAA- -AAAAAAAB-------------BAAAAAAA- -AAAAAAAB-------------BAAAAAAA- -AAAAAAAB-------------BAAAAAAA- -AAAAAAAB-------------BAAAAAAA- -AAAAAAAB-------------BAAAAAAA- -AAAAAAAB-------------BAAAAAAA- -AAAAAAAB-------------BAAAAAAA- 
AAAAAAA---------------BAAAAAAAA AAAAAAAAB-------------BAAAAAAAA AAAAAAAAB-------------BAAAAAAAA AAAAAAAAB-------------BAAAAAAAA AAAAAAAAB-------------BAAAAAAAA AAAAAAAAB-------------BAAAAAAAA AAAAAAAAB-------------BAAAAAAAA AAAAAAAAB-------------BAAAAAAAA AAAAAAAAB-------------BAAAAAAAA 
AAAAAA-----------------BAAAAAAA AAAAAAAB---------------BAAAAAAA AAAAAAAB---------------BAAAAAAA AAAAAAAB---------------BAAAAAAA AAAAAAAB---------------BAAAAAAA AAAAAAAB---------------BAAAAAAA AAAAAAAB---------------BAAAAAAA AAAAAAAB---------------BAAAAAAA AAAAAAAB---------------BAAAAAAA 
AAAAAA-----------------BAAAAAAA AAAAAAAB---------------BAAAAAAA AAAAAAAB---------------BAAAAAAA AAAAAAAB---------------BAAAAAAA AAAAAAAB---------------BAAAAAAA AAAAAAAB---------------BAAAAAAA AAAAAAAB---------------BAAAAAAA AAAAAAAB---------------BAAAAAAA AAAAAAAB---------------BAAAAAAA 
AAAAAA-----------------BAAAAAAA AAAAAAAB---------------BAAAAAAA AAAAAAAB---------------BAAAAAAA AAAAAAAB---------------BAAAAAAA AAAAAAAB---------------BAAAAAAA AAAAAAAB---------------BAAAAAAA AAAAAAAB---------------BAAAAAAA AAAAAAAB---------------BAAAAAAA AAAAAAAB---------------BAAAAAAA 
AAAAAA-----------------BAAAAAAA AAAAAAAB---------------BAAAAAAA AAAAAAAB---------------BAAAAAAA AAAAAAAB---------------BAAAAAAA AAAAAAAB---------------BAAAAAAA AAAAAAAB---------------BAAAAAAA AAAAAAAB---------------BAAAAAAA AAAAAAAB---------------BAAAAAAA AAAAAAAB---------------BAAAAAAA 
AAAAAA-----------------BAAAAAAA AAAAAAAB---------------BAAAAAAA AAAAAAAB---------------BAAAAAAA AAAAAAAB---------------BAAAAAAA AAAAAAAB---------------BAAAAAAA AAAAAAAB---------------BAAAAAAA AAAAAAAB---------------BAAAAAAA AAAAAAAB---------------BAAAAAAA AAAAAAAB---------------BAAAAAAA 
AAAAAAA---------------BAAAAAAAA AAAAAAAAB-------------BAAAAAAAA AAAAAAAAB-------------BAAAAAAAA AAAAAAAAB-------------BAAAAAAAA AAAAAAAAB-------------BAAAAAAAA AAAAAAAAB-------------BAAAAAAAA AAAAAAAAB-------------BAAAAAAAA AAAAAAAAB-------------BAAAAAAAA AAAAAAAAB-------------BAAAAAAAA 
-AAAAAA---------------BAAAAAAA- -AAAAAAAB-------------BAAAAAAA- -AAAAAAAB-------------BAAAAAAA- -AAAAAAAB-------------BAAAAAAA- -AAAAAAAB-------------BAAAAAAA- -AAAAAAAB-------------BAAAAAAA- -AAAAAAAB-------------BAAAAAAA- -AAAAAAAB-------------BAAAAAAA- -AAAAAAAB-------------BAAAAAAA- 
-AAAAAAA-------------BAAAAAAAA- -AAAAAAAAB-----------BAAAAAAAA- -AAAAAAAAB-----------BAAAAAAAA- -AAAAAAAAB-----------BAAAAAAAA- -AAAAAAAAB-----------BAAAAAAAA- -AAAAAAAAB-----------BAAAAAAAA- -AAAAAAAAB-----------BAAAAAAAA- -AAAAAAAAB-----------BAAAAAAAA- -AAAAAAAAB-----------BAAAAAAAA- 
-AAAAAAA-------------AAAAAAAAA- -AAAAAAAAAB---------BAAAAAAAAA- -AAAAAAAAAB---------BAAAAAAAAA- -AAAAAAAAAB---------BAAAAAAAAA- -AAAAAAAAAB---------BAAAAAAAAA- -AAAAAAAAAB---------BAAAAAAAAA- -AAAAAAAAAB---------BAAAAAAAAA- -AAAAAAAAAB---------BAAAAAAAAA- -AAAAAAAAAB---------BAAAAAAAAA- 
--AAAAAAAA---------BBAAAAAAAA-- --AAAAAAAAABB-----BBAAAAAAAAA-- --AAAAAAAAABB-----BBAAAAAAAAA-- --AAAAAAAAABB-----BBAAAAAAAAA-- --AAAAAAAAABB-----BBAAAAAAAAA-- --AAAAAAAAABB-----BBAAAAAAAAA-- --AAAAAAAAABB-----BBAAAAAAAAA-- --AAAAAAAAABB-----BBAAAAAAAAA-- --AAAAAAAAABB-----BBAAAAAAAAA-- 
--AAAAAAAAAA-----BBAAAAAAAAAA-- --AAAAAAAAAAABBBBBAAAAAAAAAAA-- --AAAAAAAAAAABBBBBAAAAAAAAAAA-- --AAAAAAAAAAABBBBBAAAAAAAAAAA-- --AAAAAAAAAAABBBBBAAAAAAAAAAA-- --AAAAAAAAAAABBBBBAAAAAAAAAAA-- --AAAAAAAAAAABBBBBAAAAAAAAAAA-- --AAAAAAAAAAABBBBBAAAAAAAAAAA-- --AAAAAAAAAAABBBBBAAAAAAAAAAA-- 
---AAAAAAAAAAAAAAAAAAAAAAAAA--- ---AAAAAAAAAAAAAAAAAAAAAAAAA--- ---AAAAAAAAAAAAAAAAAAAAAAAAA--- ---AAAAAAAAAAAAAAAAAAAAAAAAA--- ---AAAAAAAAAAAAAAAAAAAAAAAAA--- ---AAAAAAAAAAAAAAAAAAAAAAAAA--- ---AAAAAAAAAAAAAAAAAAAAAAAAA--- ---AAAAAAAAAAAAAAAAAAAAAAAAA--- ---AAAAAAAAAAAAAAAAAAAAAAAAA--- 
----AAAAAAAAAAAAAAAAAAAAAAA---- ----AAAAAAAAAAAAAAAAAAAAAAA---- ----AAAAAAAAAAAAAAAAAAAAAAA---- ----AAAAAAAAAAAAAAAAAAAAAAA---- ----AAAAAAAAAAAAAAAAAAAAAAA---- ----AAAAAAAAAAAAAAAAAAAAAAA---- ----AAAAAAAAAAAAAAAAAAAAAAA---- ----AAAAAAAAAAAAAAAAAAAAAAA---- ----AAAAAAAAAAAAAAAAAAAAAAA---- 
-----AAAAAAAAAAAAAAAAAAAAA----- -----AAAAAAAAAAAAAAAAAAAAA----- -----AAAAAAAAAAAAAAAAAAAAA----- -----AAAAAAAAAAAAAAAAAAAAA----- -----AAAAAAAAAAAAAAAAAAAAA----- -----AAAAAAAAAAAAAAAAAAAAA----- -----AAAAAAAAAAAAAAAAAAAAA----- -----AAAAAAAAAAAAAAAAAAAAA----- -----AAAAAAAAAAAAAAAAAAAAA----- 
------AAAAAAAAAAAAAAAAAAA------ ------AAAAAAAAAAAAAAAAAAA------ ------AAAAAAAAAAAAAAAAAAA------ ------AAAAAAAAAAAAAAAAAAA------ ------AAAAAAAAAAAAAAAAAAA------ ------AAAAAAAAAAAAAAAAAAA------ ------AAAAAAAAAAAAAAAAAAA------ ------AAAAAAAAAAAAAAAAAAA------ ------AAAAAAAAAAAAAAAAAAA------ 
-------AAAAAAAAAAAAAAAAA------- -------AAAAAAAAAAAAAAAAA------- -------AAAAAAAAAAAAAAAAA------- -------AAAAAAAAAAAAAAAAA------- -------AAAAAAAAAAAAAAAAA------- -------AAAAAAAAAAAAAAAAA------- -------AAAAAAAAAAAAAAAAA------- -------AAAAAAAAAAAAAAAAA------- -------AAAAAAAAAAAAAAAAA------- 
---------AAAAAAAAAAAAA--------- ---------AAAAAAAAAAAAA--------- ---------AAAAAAAAAAAAA--------- ---------AAAAAAAAAAAAA--------- ---------AAAAAAAAAAAAA--------- ---------AAAAAAAAAAAAA--------- ---------AAAAAAAAAAAAA--------- ---------AAAAAAAAAAAAA--------- ---------AAAAAAAAAAAAA--------- 
------------AAAAAAA------------ ------------AAAAAAA------------ ------------AAAAAAA------------ ------------AAAAAAA------------ ------------AAAAAAA------------ ------------AAAAAAA------------ ------------AAAAAAA------------ ------------AAAAAAA------------ ------------AAAAAAA------------ 
