model
size = 22 32 11, scale = 0.05, origin = -y
material 
  colors = A:#CFAE8F B:#000 C:#CFA986 D:#CFA57E E:#2C2C2C F:#CFB297 G:#DBDBDB H:#95464F I:#FFF J:#CFA176 K:#6C3239 L:#C7C7C7 M:#CFBBA8
voxels
252-2F20-2F635-B2-B40-F2AF18-F2-F18-C2FC19-2(2F20-)2A416-2A19-4A16-K6HK14-H6KH15-6H12-5B-2D-5B10-10B16-2A18-2A2-2A16-A4-A17-A2-A18-A2-A19-2A15-CD3-2A3-DC9-C2JD2-2A2-D2JC11-FA-2F-AF17-2A19-C2-C12-3(C4-)C7-C2-C6-C2-C9-2C8-2C235-2A18-2A2-2A15-2A4-2A3(14-8A)10-4B2-B2DB2-4B5-2B2-B3-2B3-B2-2B4-2B3-E2B2-2BE3-2B4-2B-2A-A4-A-2A-2B4-2B4C6-4C2B4-2B3JCA4-AC3J2B4-EBC2ACA4-AC2ACBE5-B3-ACA2-ACA3-B6-B5AC2-C5AB6-E4-2A2-2A4-E5-B-L2G2(2-A)2-2GL-B5-IG2-GIA2-AIG2-GI6-IG2-GI-2A-IG2-GI6-AL2GL-4A-L2GLA7-A2I2AB2-B2A2IA9-2A2(2-B)2-2A8-B4-EB2-BE4-B7-E2-EB4-BE2-E8-4B6-4B167-4A17-A4-A15-A6-A13-3A4-3A12-2A6-2A12-A8-A9-3B4-2D4-3B5-2B-E10-E-2B4-2B-2A8-2A-2B4-2BA2-A6-A2-A2B6-A12-A7-A14-A5-A16-A4-5A8-5A6-A12-A7-2(A14-A6-)2(M14-M6-)A14-A7-A5-2A5-A7-B-A3(-2A)-A-B6-B-3A2-2A2-3A-B6-EB-A2-4A2-A-BE7-4BA4DA4B9-EB2-4A2-BE14-D2ED19-2B86-2A18-2A2-2A15-A6-A13-A8-A12-A8-A11-2A8-2A4(10-A)9-A12-A8-A12-A7-A14-A6-A14-A5-2(A16-A4-)A16-A5-7(A14-A6-)2A12-2A6-A-A10-A-A7-2A10-2A9-3A6-3A13-6A14-3D4A3D16-2E20-2B63-4A17-A4-A14-2A6-2A12-A8-A11-2A8-2A4(10-A)9-A12-A7-A14-A5-2A14-2A10(4-A16-A)5-3(A14-A6-)2A12-2A7-A12-A9-2(A10-)D2A6-2AD11-D2A4-2AD15-E2AE18-B2DB19-2B40-6A15-A6-A13-A8-A11-2A8-2A2(10-A)9-A12-A7-2A12-2A6-A14-A5-A16-A4-A16-A3-5(A18-A2-)A18-A3-4(A16-A4-)A16-A5-3(A14-A6-)A14-A7-A12-A9-2(A10-)DA8-AD12-2A4-2A15-E4AE17-4B19-2A17-3A2-3A13-A8-A11-2A8-2A9-2A10-2A8-A12-A7-2(A14-A6-)A14-A5-A16-A3-3(A18-A2-)A18-A-A20-2A20-A-3(A18-A2-)A18-A3-2(A16-A4-)A16-A5-2(A14-A6-)A14-A7-A12-A9-A10-A11-A8-A12-A8-A13-8A15-6B17-4A16-2A4-2A13-A8-A11-2A8-2A9-2A10-2A8-A12-A7-A14-A6-A14-A5-A16-A4-A16-A3-2(A18-A2-)A18-A-A4(20-2A)20-A-2(A18-A2-)A18-A3-2(A16-A4-)A16-A5-2(A14-A6-)A14-A7-A12-A9-A10-A11-A8-A13-2A4-2A14-8B15-6A15-A6-A13-A8-A11-A10-A9-A12-A8-A12-A7-A14-A6-A14-A5-A16-A4-A16-A3-A18-A2-A18-A-A7(20-2A)20-A-A18-A2-A18-A3-2(A16-A4-)A16-A5-A14-A6-A14-A7-A12-A9-3(A10-)A11-2A6-2A13-8B7-
