model
size = 21 25 20, scale = 0.05, origin = -y
material 
  colors = A:#331919 B:#111
voxels
--------AAAAAAA------ -------AAAAAAA------- --------------------- --------------------- --------------------- --------------------- --------------------- --------------------- --------------------- --------------------- --------------------- --------------------- --------------------- --------------------- --------------------- --------------------- --------------------- --------------------- --------------------- --------------------- --------------------- --------------------- --------------------- --------------------- --------------------- 
------AAAAAAAAAAA---- -----AAAAAAAAAAA----- ---------AAAAA------- --------------------- --------------------- --------------------- --------------------- --------------------- --------------------- --------------------- --------------------- --------------------- --------------------- --------------------- --------------------- --------------------- --------------------- ------AAAAAAA-------- -------AAAAAAA------- ------AAAAAAA-------- -------AAAAAAA------- ------AAAAAAA-------- -----AAAAAAA--------- ------AAAAAAA-------- -------AAAAAAA------- 
-----AAAAAAAAAAAAA--- ----AAAAAAAAAAAAA---- -------AAAAAAAAA----- --------AAAAA-------- --------------------- --------------------- --------------------- --------------------- --------------------- --------------------- -------AAAAAAA------- --------AAAAAAA------ -------AAAAAAA------- --------------------- --------------------- --------------------- --------------------- ----AAAAAAAAAAA------ -----AAAAAAAAAAA----- ----AAAAAAAAAAA------ -----AAAAAAAAAAA----- ----AAAAAAAAAAA------ ---AAAAAAAAAAA------- ----AAAAAAAAAAA------ -----AAAAAAAAAAA----- 
----AAAAAAAAAAAAAAA-- ---AAAAAAAAAAAAAAA--- -----AAAAAAAAAAAAA--- ------AAAAAAAAA------ --------AAAAA-------- ---------AAAAA------- --------AAAAA-------- ---------AAAAA------- --------AAAAA-------- ---------AAAAA------- -----AAAAAAAAAAA----- ------AAAAAAAAAAA---- -----AAAAAAAAAAA----- -------AAAAAAA------- ------AAAAAAA-------- --------AAAAAAA------ -------AAAAAAA------- --AAAAAAAAAAAAAAA---- ---AAAAAAAAAAAAAAA--- --AAAAAAAAAAAAAAA---- ---AAAAAAAAAAAAAAA--- --AAAAAAAAAAAAAAA---- -AAAAAAAAAAAAAAA----- --AAAAAAAAAAAAAAA---- ---AAAAAAAAAAAAAAA--- 
---AAAAAAAAAAAAAAAAA- --AAAAAAAAAAAAAAAAA-- -----AAAAAAAAAAAAA--- -----AAAAAAAAAAA----- ------AAAAAAAAA------ -------AAAAAAAAA----- ------AAAAAAAAA------ -------AAAAAAAAA----- ------AAAAAAAAA------ -------AAAAAAAAA----- ----AAAAAAAAAAAAA---- -----AAAAAAAAAAAAA--- ----AAAAAAAAAAAAA---- -----AAAAAAAAAAA----- ----AAAAAAAAAAA------ ------AAAAAAAAAAA---- -----AAAAAAAAAAA----- -AAAAAAAAAAAAAAAAA--- --AAAAAAAAAAAAAAAAA-- -AAAAAAAAAAAAAAAAA--- --AAAAAAAAAAAAAAAAA-- -AAAAAAAAAAAAAAAAA--- AAAAAAAAAAAAAAAAA---- -AAAAAAAAAAAAAAAAA--- --AAAAAAAAAAAAAAAAA-- 
---AAAAAAAAAAAAAAAAA- --AAAAAAAAAAAAAAAAA-- ----AAAAAAAAAAAAAAA-- ----AAAAAAAAAAAAA---- -----AAAAAAAAAAA----- ------AAAAAAAAAAA---- -----AAAAAAAAAAA----- ------AAAAAAAAAAA---- ----AAAAAAAAAAAAA---- -----AAAAAAAAAAAAA--- ---AAAAAAAAAAAAAAA--- ----AAAAAAAAAAAAAAA-- ---AAAAAAAAAAAAAAA--- ----AAAAAAAAAAAAA---- ---AAAAAAAAAAAAA----- -----AAAAAAAAAAAAA--- ----AAAAAAAAAAAAA---- AAAAAAAAAAAAAAAAAAA-- -AAAAAAAAAAAAAAAAAAA- AAAAAAAAAAAAAAAAAAA-- -AAAAAAAAAAAAAAAAAAA- AAAAAAAAAAAAAAAAAAA-- AAAAAAAAAAAAAAAAAA--- AAAAAAAAAAAAAAAAAAA-- -AAAAAAAAAAAAAAAAAAA- 
--AAAAAAAAAAAAAAAAAAA -AAAAAAAAAAAAAAAAAAA- ----AAAAAAAAAAAAAAA-- ----AAAAAAAAAAAAA---- ----AAAAAAAAAAAAA---- -----AAAAAAAAAAAAA--- ----AAAAAAAAAAAAA---- -----AAAAAAAAAAAAA--- ----AAAAAAAAAAAAA---- -----AAAAAAAAAAAAA--- --AAAAAAAAAAAAAAAAA-- ---AAAAAAAAAAAAAAAAA- --AAAAAAAAAAAAAAAAA-- ---AAAAAAAAAAAAAAA--- --AAAAAAAAAAAAAAA---- ----AAAAAAAAAAAAAAA-- ---AAAAAAAAAAAAAAA--- AAAAAAAAAAAAAAAAAAA-- -AAAAAAAAAAAAAAAAAAA- AAAAAAAAAAAAAAAAAAA-- -AAAAAAAAAAAAAAAAAAA- AAAAAAAAAAAAAAAAAAA-- AAAAAAAAAAAAAAAAAA--- AAAAAAAAAAAAAAAAAAA-- -AAAAAAAAAAAAAAAAAAA- 
--AAAAAAAAAAAAAAAAAAA -AAAAAAAAAAAAAAAAAAA- ---AAAAAAAAAAAAAAAAA- ---AAAAAAAAAAAAAAA--- ----AAAAAAAAAAAAA---- -----AAAAAAAAAAAAA--- ----AAAAAAAAAAAAA---- -----AAAAAAAAAAAAA--- ---AAAAAAAAAAAAAAA--- ----AAAAAAAAAAAAAAA-- --AAAAAAAAAAAAAAAAA-- ---AAAAAAAAAAAAAAAAA- --AAAAAAAAAAAAAAAAA-- --AAAAAAAAAAAAAAAAA-- -AAAAAAAAAAAAAAAAA--- ---AAAAAAAAAAAAAAAAA- --AAAAAAAAAAAAAAAAA-- AAAAAAAAAAAAAAAAAAAA- AAAAAAAAAAAAAAAAAAAAA AAAAAAAAAAAAAAAAAAAA- AAAAAAAAAAAAAAAAAAAAA AAAAAAAAAAAAAAAAAAAA- AAAAAAAAAAAAAAAAAAA-- AAAAAAAAAAAAAAAAAAAA- AAAAAAAAAAAAAAAAAAAAA 
--AAAAAAAAAAAAAAAAAAA -AAAAAAAAAAAAAAAAAAA- ---AAAAAAAAAAAAAAAAA- ---AAAAAAAAAAAAAAA--- ---AAAAAAAAAAAAAAA--- ----AAAAAAAAAAAAAAA-- ---AAAAAAAAAAAAAAA--- ----AAAAAAAAAAAAAAA-- ---AAAAAAAAAAAAAAA--- ----AAAAAAAAAAAAAAA-- -AAAAAAAAAAAAAAAAAAA- --AAAAAAAAAAAAAAAAAAA -AAAAAAAAAAAAAAAAAAA- --AAAAAAAAAAAAAAAAA-- -AAAAAAAAAAAAAAAAA--- ---AAAAAAAAAAAAAAAAA- --AAAAAAAAAAAAAAAAA-- AAAAAAAAAAAAAAAAAAAA- AAAAAAAAAAAAAAAAAAAAA AAAAAAAAAAAAAAAAAAAA- AAAAAAAAAAAAAAAAAAAAA AAAAAAAAAAAAAAAAAAAA- AAAAAAAAAAAAAAAAAAA-- AAAAAAAAAAAAAAAAAAAA- AAAAAAAAAAAAAAAAAAAAA 
--AAAAAAAAA-AAAAAAAAA -AAAAAAAAA-AAAAAAAAA- ---AAAAAAAA-AAAAAAAA- ---AAAAAAA-AAAAAAA--- ---AAAAAAAAAAAAAAA--- ----AAAAAAAAAAAAAAA-- ---AAAAAAAAAAAAAAA--- ----AAAAAAAAAAAAAAA-- --AAAAAAAAAAAAAAAAA-- ---AAAAAAAAAAAAAAAAA- -AAAAAAAAAAAAAAAAAAA- --AAAAAAAAAAAAAAAAAAA -AAAAAAAAAAAAAAAAAAA- -AAAAAAAAAAAAAAAAAAA- AAAAAAAAAAAAAAAAAAA-- --AAAAAAAAAAAAAAAAAAA -AAAAAAAAAAAAAAAAAAA- AAAAAAAAAAAAAAAAAAAAA AAAAAAAAAAAAAAAAAAAAA AAAAAAAAAAAAAAAAAAAAA AAAAAAAAAAAAAAAAAAAAA AAAAAAAAAAAAAAAAAAAAA AAAAAAAAAAAAAAAAAAAA- -AAAAAAAAAAAAAAAAAAAA AAAAAAAAAAAAAAAAAAAAA 
--AAAAAAAAAAAAAAAAAAA -AAAAAAAAAAAAAAAAAAA- ---AAAAAAAAAAAAAAAAA- ---AAAAAAAAAAAAAAA--- ---AAAAAAA-AAAAAAA--- ----AAAAAAA-AAAAAAA-- ---AAAAAAA-AAAAAAA--- ----AAAAAAA-AAAAAAA-- --AAAAAAAAAAAAAAAAA-- ---AAAAAAAAAAAAAAAAA- -AAAAAAAAAAAAAAAAAAA- --AAAAAAAAAAAAAAAAAAA -AAAAAAAAAAAAAAAAAAA- -AAAAAAAAAAAAAAAAAAA- AAAAAAAAAAAAAAAAAAA-- --AAAAAAAAAAAAAAAAAAA -AAAAAAAAAAAAAAAAAAA- AAAAAAAAAAAAAAAAAAAAA AAAAAAAAAAAAAAAAAAAAA AAAAAAAAAAAAAAAAAAAAA AAAAAAAAAAAAAAAAAAAAA AAAAAAAAAAAAAAAAAAAAA AAAAAAAAAAAAAAAAAAAA- -AAAAAAAAAAAAAAAAAAAA AAAAAAAAAAAAAAAAAAAAA 
--AAAAAAAAAAAAAAAAAAA -AAAAAAAAAAAAAAAAAAA- ---AAAAAAAAAAAAAAAAA- ---AAAAAAAAAAAAAAA--- ---AAAAAAAAAAAAAAA--- ----AAAAAAAAAAAAAAA-- ---AAAAAAAAAAAAAAA--- ----AAAAAAAAAAAAAAA-- --AAAAAAAA-AAAAAAAA-- ---AAAAAAAA-AAAAAAAA- -AAAAAAAAA-AAAAAAAAA- --AAAAAAAAA-AAAAAAAAA -AAAAAAAAA-AAAAAAAAA- -AAAAAAAAAAAAAAAAAAA- AAAAAAAAAAAAAAAAAAA-- --AAAAAAAAAAAAAAAAAAA -AAAAAAAAAAAAAAAAAAA- AAAAAAAAAAAAAAAAAAAAA AAAAAAAAAAAAAAAAAAAAA AAAAAAAAAAAAAAAAAAAAA AAAAAAAAAAAAAAAAAAAAA AAAAAAAAAAAAAAAAAAAAA AAAAAAAAAAAAAAAAAAAA- AAAAAAAAAAAAAAAAAAAAA AAAAAAAAAAAAAAAAAAAAA 
--AAAAAAAAAAAAAAAAAAA -AAAAAAAAAAAAAAAAAAA- ----AAAAAAAAAAAAAAA-- ----AAAAAAAAAAAAA---- ---AAAAAAAAAAAAAAA--- ----AAAAAAAAAAAAAAA-- ---AAAAAAAAAAAAAAA--- ----AAAAAAAAAAAAAAA-- --AAAAAAAAAAAAAAAAA-- ---AAAAAAAAAAAAAAAAA- -AAAAAAAAAAAAAAAAAAA- --AAAAAAAAAAAAAAAAAAA -AAAAAAAAAAAAAAAAAAA- -AAAAAAAAA-AAAAAAAAA- AAAAAAAAA-AAAAAAAAA-- --AAAAAAAAA-AAAAAAAAA -AAAAAAAAA-AAAAAAAAA- AAAAAAAAA-AAAAAAAAAAA AAAAAAAAAA-AAAAAAAAAA AAAAAAAAA-AAAAAAAAAAA AAAAAAAAAA-AAAAAAAAAA AAAAAAAAA-AAAAAAAAAAA AAAAAAAA-AAAAAAAAAAA- AAAAAAAAA-AAAAAAAAAAA AAAAAAAAAAAAAAAAAAAAA 
---AAAAAAAAAAAAAAAAA- --AAAAAAAAAAAAAAAAA-- ----AAAAAAAAAAAAAAA-- ----AAAAAAAAAAAAA---- ----AAAAAAAAAAAAA---- -----AAAAAAAAAAAAA--- ----AAAAAAAAAAAAA---- -----AAAAAAAAAAAAA--- --AAAAAAAAAAAAAAAAA-- ---AAAAAAAAAAAAAAAAA- -AAAAAAAAAAAAAAAAAAA- --AAAAAAAAAAAAAAAAAAA -AAAAAAAAAAAAAAAAAAA- -AAAAAAAAAAAAAAAAAAA- AAAAAAAAAAAAAAAAAAA-- --AAAAAAAAAAAAAAAAAAA -AAAAAAAAAAAAAAAAAAA- AAAAAAAAAAAAAAAAAAAAA AAAAAAAAAAAAAAAAAAAAA AAAAAAAAAAAAAAAAAAAAA AAAAAAAAAAAAAAAAAAAAA AAAAAAAAAAAAAAAAAAAAA AAAAAAAAAAAAAAAAAAAA- AAAAAAAAAAAAAAAAAAAAA AAAAAAAAAAAAAAAAAAAAA 
---AAAAAAAAAAAAAAAAA- --AAAAAAAAAAAAAAAAA-- -----AAAAAAAAAAAAA--- -----AAAAAAAAAAA----- ----AAAAAAAAAAAAA---- -----AAAAAAAAAAAAA--- ----AAAAAAAAAAAAA---- -----AAAAAAAAAAAAA--- ---AAAAAAAAAAAAAAA--- ----AAAAAAAAAAAAAAA-- -AAAAAAAAAAAAAAAAAAA- --AAAAAAAAAAAAAAAAAAA -AAAAAAAAAAAAAAAAAAA- -AAAAAAAAAAAAAAAAAAA- AAAAAAAAAAAAAAAAAAA-- --AAAAAAAAAAAAAAAAAAA -AAAAAAAAAAAAAAAAAAA- AAAAAAAAAAAAAAAAAAAAA AAAAAAAAAAAAAAAAAAAAA AAAAAAAAAAAAAAAAAAAAA AAAAAAAAAAAAAAAAAAAAA AAAAAAAAAAAAAAAAAAAAA AAAAAAAAAAAAAAAAAAAA- AAAAAAAAAAAAAAAAAAAAA AAAAAAAAAAAAAAAAAAAAA 
----AAAAAAAAAAAAAAA-- ---AAAAAAAAAAAAAAA--- -----AAAAAAAAAAAAA--- ------AAAAAAAAA------ -----AAAAAAAAAAA----- ------AAAAAAAAAAA---- -----AAAAAAAAAAA----- ------AAAAAAAAAAA---- ---AAAAAAAAAAAAAAA--- ----AAAAAAAAAAAAAAA-- --AAAAAAAAAAAAAAAAA-- ---AAAAAAAAAAAAAAAAA- --AAAAAAAAAAAAAAAAA-- -AAAAAAAAAAAAAAAAAAA- AAAAAAAAAAAAAAAAAAA-- --AAAAAAAAAAAAAAAAAAA -AAAAAAAAAAAAAAAAAAA- AAAAAAAAAAAAAAAAAAAAA AAAAAAAAAAAAAAAAAAAAA AAAAAAAAAAAAAAAAAAAAA AAAAAAAAAAAAAAAAAAAAA AAAAAAAAAAAAAAAAAAAAA AAAAAAAAAAAAAAAAAAAA- AAAAAAAAAAAAAAAAAAAAA AAAAAAAAAAAAAAAAAAAAA 
-----AAAAAAAAAAAAA--- ----AAAAAAAAAAAAA---- -------AAAAAAAAA----- --------AAAAA-------- ------AAAAAAAAA------ -------AAAAAAAAA----- ------AAAAAAAAA------ -------AAAAAAAAA----- ----AAAAAAAAAAAAA---- -----AAAAAAAAAAAAA--- --AAAAAAAAAAAAAAAAA-- ---AAAAAAAAAAAAAAAAA- --AAAAAAAAAAAAAAAAA-- --AAAAAAAAAAAAAAAAA-- -AAAAAAAAAAAAAAAAA--- ---AAAAAAAAAAAAAAAAA- --AAAAAAAAAAAAAAAAA-- AAAAAAAAAAAAAAAAAAAA- AAAAAAAAAAAAAAAAAAAAA AAAAAAAAAAAAAAAAAAAA- AAAAAAAAAAAAAAAAAAAAA AAAAAAAAAAAAAAAAAAAA- AAAAAAAAAAAAAAAAAAA-- AAAAAAAAAAAAAAAAAAAA- AAAAAAAAAAAAAAAAAAAAA 
------AAAAAAAAAAA---- -----AAAAAAAAAAA----- ---------AAAAA------- --------------------- --------AAAAA-------- ---------AAAAA------- --------AAAAA-------- ---------AAAAA------- ----AAAAAAAAAAAAA---- -----AAAAAAAAAAAAA--- ---AAAAAAAAAAAAAAA--- ----AAAAAAAAAAAAAAA-- ---AAAAAAAAAAAAAAA--- --AAAAAAAAAAAAAAAAA-- -AAAAAAAAAAAAAAAAA--- ---AAAAAAAAAAAAAAAAA- --AAAAAAAAAAAAAAAAA-- AAAAAAAAAAAAAAAAAAAA- AAAAAAAAAAAAAAAAAAAAA AAAAAAAAAAAAAAAAAAAA- AAAAAAAAAAAAAAAAAAAAA AAAAAAAAAAAAAAAAAAAA- AAAAAAAAAAAAAAAAAAA-- AAAAAAAAAAAAAAAAAAAA- AAAAAAAAAAAAAAAAAAAAA 
--------AAAAAAA------ -------AAAAAAA------- --------------------- --------------------- --------------------- --------------------- --------------------- --------------------- ------AAAAAAAAA------ -------AAAAAAAAA----- ----AAAAAAAAAAAAA---- -----AAAAAAAAAAAAA--- ----AAAAAAAAAAAAA---- ---AAAAAAAAAAAAAAA--- --AAAAAAAAAAAAAAA---- ----AAAAAAAAAAAAAAA-- ---AAAAAAAAAAAAAAA--- AAAAAAAAAAAAAAAAAAA-- -AAAAAAAAAAAAAAAAAAA- AAAAAAAAAAAAAAAAAAA-- -AAAAAAAAAAAAAAAAAAA- AAAAAAAAAAAAAAAAAAA-- AAAAAAAAAAAAAAAAAA--- AAAAAAAAAAAAAAAAAAA-- -AAAAAAAAAAAAAAAAAAA- 
--------------------- --------------------- --------------------- --------------------- --------------------- --------------------- --------------------- --------------------- --------AAAAA-------- -------BBBABBB------- -----AABAABAABAA----- ------ABAAAAABAAA---- -----AABBBABBBAA----- ----AAABAAAAABAAA---- ---AAAABBBABBBAA----- -----AABAAAAABAAAA--- ----AAABBBBBBBAAA---- AAAAAAAAAAAAAAAAAAA-- -AAAAAAAAAAAAAAAAAAA- AAAAABBBBBBBBBBBAAA-- -AAAAAAAAABAAAAAAAAA- AAAAAAAAAABAAAAAAAA-- AAAAAAAAAABAAAAAAA--- AAAAAAAAAABAAAAAAAA-- -AAAAAAAAABAAAAAAAAA- 
