model
size = 21, scale = 0.05, origin = -y
material 
  colors = A:#C25100 B:#008945 C:#7100C2 D:#FC6900 E:#41C200 F:#6100A6 G:#000 H:#101010
voxels
--------------------- --------------------- --------------------- --------------------- --------------------- --------------------- --------------------- ---------CDB--------- --------CCDBB-------- -------CCCDBBB------- -------CCCDBBB------- -------CCCDBBB------- --------CCDBB-------- ---------CDB--------- --------------------- --------------------- --------------------- --------------------- --------------------- --------------------- --------------------- 
--------------------- --------------------- --------------------- --------------------- --------------------- --------CCDBB-------- -------CCCDBBB------- ------CCC---BBB------ -----CCC-----BBB----- -----CC-------BB----- -----CC-------BB----- -----CC-------BB----- -----CCC---H-BBB----- ------CCC--HBBB------ -------CCCDBBB------- --------CCDBB-------- --------------------- --------------------- --------------------- --------------------- --------------------- 
--------------------- --------------------- --------------------- --------------------- -------CCCDBBB------- ------CCDDDDABB------ -----CC-----AABB----- ----CC------AAABB---- ----C-----------B---- ----C-----------B---- ----C-----------B---- ----C-----------B---- ----C-----------B---- ----CC---------BB---- -----CC-------BB----- ------CC-----BB------ -------CCCDBBB------- --------------------- --------------------- --------------------- --------------------- 
--------------------- --------------------- --------------------- -------CCCDBBB------- -----CCAAAAAAABB----- ---DCCDDDDDDAAABBD--- ---DC-------AAAABD--- ---D--------AAAAAD--- ---D------------AD--- ---D------------AD--- ---D------------AD--- ---D------------AD--- ---D------------AD--- ---D------------AD--- ---DC-----------BD--- ---DCC---------BBD--- -----CCEEEEEEEBB----- -------CCCDBBB------- --------------------- --------------------- --------------------- 
--------------------- --------------------- -------CCCDBBB------- ----DCCAAAAAAABBD---- ----DAAAAAAAAAAAD---- ---BDDDDDDDDAAAAAC--- ---B--------AAAAAC--- --BA--------AAAAAAC-- --BA------------AAC-- --BA------------AAC-- --BA------------AAC-- --BA------------AAC-- --BA------------AAC-- --BA------------AAC-- ---B------------AC--- ---B------------AC--- ----DEEEEEEEEEEED---- ----DCCAAAAAAABBD---- -------CCCDBBB------- --------------------- --------------------- 
--------------------- --------CCDBB-------- -----DCCAAAAABBD----- ----BAAAAAAAAAAAC---- ---BAAAAAAAAAAAAAC--- ---BDDDDDDDDAAAAAC--- --BA--------AAAAAAC-- --BA--------AAAAAAC-- -BAA------------AAAC- -BAA------------AAAC- -BAA------------AAAC- -BAA------------AAAC- -BAA------------AAAC- --BA------------AAC-- --BA------------AAC-- ---B------------AC--- ---BEEEEEEEEEEEEAC--- ----BGAAAAAAAAAAC---- -----DCCAAAAABBD----- --------CCDBB-------- --------------------- 
--------------------- -------CCCDBBB------- -----BDAAAAAAADC----- ----BAAAAAAAAAAAC---- ---BAAAAAAAAAAAAAC--- --BADDDDDDDDAAAAAAC-- --BA--------AAAAAAC-- -BAA--------AAAAAAAC- -BAA------------AAAC- -BAA------------AAAC- -BAA------------AAAC- -BAA------------AAAC- -BAA------------AAAC- -BAA------------AAAC- --BA------------AAC-- --BA------------AAC-- ---BEEEEEEEEEEEEAC--- ----BAAAAAAAAAAAC---- -----BDGAAAAAGDC----- -------DDDDDDD------- --------------------- 
---------CDB--------- ------DCCAAABBD------ ----BBAAAAAAAAACC---- ---BAAAAAAAAAAAAAC--- --BAAAAAAAAAAAAAAAC-- --BADDDDDDDDAAAAAAC-- -BAA--------AAAAAAAC- -BAA--------AAAAAAAC- -BAA------------AAAC- BAAA------------AAAAC BAAA------------AAAAC BAAA------------AAAAC -BAA------------AAAC- -BAA------------AAAC- -BAA------------AAAC- --BA------------AAC-- --BAEEEEEEEEEEEEAAC-- ---BAAAAAAAAAAAAAC--- ----BBAAAAAAAAACC---- ------BBBAAAFFF------ ---------BDF--------- 
--------CCDBB-------- -----BDCAAAAABDC----- ----BAAAAAAAAAAAC---- ---BAAAAAAAAAAAAAC--- --BAAAAAAAAAAAAAAAC-- -BAADDDDDDDDAAAAAAAC- -BAA--------AAAAAAAC- -BAA--------AAAAAAAC- BAAA------------AAAAC BAAA------------AAAAC BAAA------------AAAAC BAAA------------AAAAC BAAA------------AAAAC -BAA------------AAAC- -BAA------------AAAC- -BAA------------AAAC- --BAEEEEEEEEEEEEAAC-- ---BAAAAAAAAAAAAAC--- ----BAAAAAAAAAAAC---- -----BBBAAAAAFFF----- --------BBDFF-------- 
-------CCCDBBB------- -----BDAAAAAAADC----- ----BAAAAAAAAAAAC---- ---BAAAAAAAAAAAAAC--- --BAAAAAAAAAAAAAAAC-- -BAADDDDDDDDAAAAAAAC- -BAA--------AAAAAAAC- BAAA--------AAAAAAAAC BAAA------------AAAAC BAAA------------AAAAC BAAA------------AAAAC BAAA------------AAAAC BAAA------------AAAAC BAAA------------AAAAC -BAA------------AAAC- -BAA------------AAAC- --BAEEEEEEEEEEEEAAC-- ---BAAAAAAAAAAAAAC--- ----BAAAAAAAAAAAC---- -----BBAAAAAAAFF----- -------BBBDFFF------- 
-------DDDDDDD------- -----DDAAAAAAADD----- ----DAAAAAAAAAAAD---- ---DAAAAAAAAAAAAAD--- --DAAAAAAAAAAAAAAAD-- -DAADDDDDDDDAAAAAAAD- -DAA--------AAAAAAAD- DAAA--------AAAAAAAAD DAAA------------AAAAD DAAA------------AAAAD DAAA------------AAAAD DAAA------------AAAAD DAAA------------AAAAD DAAA------------AAAAD -DAA------------AAAD- -DAA------------AAAD- --DAEEEEEEEEEEEEAAD-- ---DAAAAAAAAAAAAAD--- ----DAAAAAAAAAAAD---- -----DDAAAAAAADD----- -------DDDDDDD------- 
-------BBBDCCC------- -----CDAAAAAAADB----- ----CAAAAAAAAAAAB---- ---CAAAAAAAAAAAAAB--- --FAAAAAAAAAAAAAAAB-- -FAADDDDDDDDAAAAAAAB- -FAA--------AAAAAAAB- FAAA--------AAAAAAAAB FAAA------------AAAAB FAAA------------AAAAB FAAA------------AAAAB FAAA------------AAAAB FAAA------------AAAAB FAAA------------AAAAB -FAA------------AAAB- -FAA------------AAAB- --FAEEEEEEEEEEEEAAB-- ---FAAAAAAAAAAAAAB--- ----FAAAAAAAAAAAB---- -----FFAAAAAAABB----- -------FFFDBBB------- 
--------BBDCC-------- -----CDBAAAAACDB----- ----CAAAAAAAAAAAB---- ---CAAAAAAAAAAAAAB--- --FAAAAAAAAAAAAAAAB-- -FAADDDDDDDDAAAAAAAB- -FAA--------AAAAAAAB- -FAA--------AAAAAAAB- FAAA------------AAAAB FAAA------------AAAAB FAAA------------AAAAB FAAA------------AAAAB FAAA------------AAAAB -FAA------------AAAB- -FAA------------AAAB- -FAA------------AAAB- --FAEEEEEEEEEEEEAAB-- ---FAAAAAAAAAAAAAB--- ----FAAAAAAAAAAAB---- -----FFFAAAAABBB----- --------FFDBB-------- 
---------BDC--------- ------DBBAAACCD------ ----CCAAAAAAAAABB---- ---CAAAAAAAAAAAAAB--- --FAAAAAAAAAAAAAAAB-- --FADDDDDDDDAAAAAAB-- -FAA--------AAAAAAAB- -FAA--------AAAAAAAB- -FAA------------AAAB- FAAA------------AAAAB FAAA------------AAAAB FAAA------------AAAAB -FAA------------AAAB- -FAA------------AAAB- -FAA------------AAAB- --FA------------AAB-- --FAEEEEEEEEEEEEAAB-- ---FAAAAAAAAAAAAAB--- ----FFAAAAAAAAABB---- ------FFFAAABBB------ ---------FDB--------- 
--------------------- -------BBBDCCC------- -----CDAAAAAAADB----- ----CAAAAAAAAAAAB---- ---CAAAAAAAAAAAAAB--- --FADDDDDDDDAAAAAAB-- --FA--------AAAAAAB-- -FAA--------AAAAAAAB- -FAA------------AAAB- -FAA------------AAAB- -FAA------------AAAB- -FAA------------AAAB- -FAA------------AAAB- -FAA------------AAAB- --FA------------AAB-- --FA------------AAB-- ---FEEEEEEEEEEEEAB--- ----FAAAAAAAAAAAB---- -----FDGAAAAAGDB----- -------DDDDDDD------- --------------------- 
--------------------- --------BBDCC-------- -----DBBAAAAACCD----- ----CAAAAAAAAAAAB---- ---CAAAAAAAAAAAAAB--- ---CDDDDDDDDAAAAAB--- --FA--------AAAAAAB-- --FA--------AAAAAAB-- -FAA------------AAAB- -FAA------------AAAB- -FAA------------AAAB- -FAA------------AAAB- -FAA------------AAAB- --FA------------AAB-- --FA------------AAB-- ---F------------AB--- ---FEEEEEEEEEEEEAB--- ----FGAAAAAAAAAAB---- -----DBBAAAAACCD----- --------BBDCC-------- --------------------- 
--------------------- --------------------- -------BBBDCCC------- ----DBBAAAAAAACCD---- ----DAAAAAAAAAAAD---- ---CDDDDDDDDAAAAAB--- ---C--------AAAAAB--- --FA--------AAAAAAB-- --FA------------AAB-- --FA------------AAB-- --FA------------AAB-- --FA------------AAB-- --FA------------AAB-- --FA------------AAB-- ---F------------AB--- ---F------------AB--- ----DEEEEEEEEEEED---- ----DBBAAAAAAACCD---- -------BBBDCCC------- --------------------- --------------------- 
--------------------- --------------------- --------------------- -------BBBDCCC------- -----BBAAAAAAACC----- ---DBBDDDDDDAAACCD--- ---DB-------AAAACD--- ---D--------AAAAAD--- ---D------------AD--- ---D------------AD--- ---D------------AD--- ---D------------AD--- ---D------------AD--- ---D------------AD--- ---DB-----------CD--- ---DBB---------CCD--- -----BBEEEEEEECC----- -------BBBDCCC------- --------------------- --------------------- --------------------- 
--------------------- --------------------- --------------------- --------------------- -------BBBDCCC------- ------BBDDDDACC------ -----BB-----AACC----- ----BB------AAACC---- ----B----------EC---- ----B----------EC---- ----B----------EC---- ----B----------EC---- ----B----------EC---- ----BB--------CCC---- -----BB-------CC----- ------BB-----CC------ -------BBBDCCC------- --------------------- --------------------- --------------------- --------------------- 
--------------------- --------------------- --------------------- --------------------- --------------------- --------BBDCC-------- -------BBBDCCC------- ------BBBAA-CCC------ -----BBBAAA-HCCC----- -----BBAAAA---CC----- -----BBAAAA---CC----- -----BBAAAA---CC----- -----BBBAAA--CCC----- ------BBBAA-CCC------ -------BBBDCCC------- --------BBDCC-------- --------------------- --------------------- --------------------- --------------------- --------------------- 
--------------------- --------------------- --------------------- --------------------- --------------------- --------------------- --------------------- ---------BDC--------- --------BBDCC-------- -------BBBDCCC------- -------BBBDCCC------- -------BBBDCCC------- --------BBDCC-------- ---------BDC--------- --------------------- --------------------- --------------------- --------------------- --------------------- --------------------- --------------------- 
