model
size = 21, scale = 0.05, origin = -y
material 
  colors = A:#C25100 B:#DFDFDF C:#000
voxels
--------------------- --------------------- --------------------- --------------------- --------------------- --------------------- --------------------- ---------ACB--------- --------AACBB-------- -------AAACBBB------- -------AAACBBB------- -------AAACBBB------- --------AACBB-------- ---------ACB--------- --------------------- --------------------- --------------------- --------------------- --------------------- --------------------- --------------------- 
--------------------- --------------------- --------------------- --------------------- --------------------- --------AACBB-------- -------AAACBBB------- ------AAA---BBB------ -----AAA-----BBB----- -----AAA-----ABB----- -----AAA-----ABB----- -----AAA-----ABB----- -----AAA-----BBB----- ------AAA---BBB------ -------AAACBBB------- --------AACBB-------- --------------------- --------------------- --------------------- --------------------- --------------------- 
--------------------- --------------------- --------------------- --------------------- -------AAACBBB------- ------AAAAAAABB------ -----AAAAAAAAABB----- ----AAAA-----AABB---- ----AAAA-----AAAB---- ----AAAA-----AAAB---- ----AAAA-----AAAB---- ----AAAA-----AAAB---- ----AAAA-----AAAB---- ----AAAA-----AABB---- -----AAAAAAAAABB----- ------AAAAAAABB------ -------AAACBBB------- --------------------- --------------------- --------------------- --------------------- 
--------------------- --------------------- --------------------- -------AAACBBB------- -----AAAAAAAAABB----- ---CAAAAAAAAAAABBC--- ---CAAAAAAAAAAAABC--- ---CAAAA-----AAAAC--- ---CAAAA-----AAAAC--- ---CAAAA-----AAAAC--- ---CAAAA---------C--- ---CAAAA-----AAAAC--- ---CAAAA-----AAAAC--- ---CAAAA-----AAAAC--- ---CAAAAAAAAAAAABC--- ---CAAAAAAAAAAABBC--- -----AAAAAAAAABB----- -------AAACBBB------- --------------------- --------------------- --------------------- 
--------------------- --------------------- -------AAACBBB------- ----CAAAAAAAAABBC---- ----CAAAAAAAAAAAC---- ---BAAAAAAAAAAAAAA--- ---BAAAAAAAAAAAAAA--- --BAAAAA---------AA-- --BAAAA----------AA-- --BAAAA----------AA-- --BAAAA----------AA-- --BAAAA----------AA-- --BAAAAA---------AA-- --BAAAAA---------AA-- ---BAAAAAAAAAAAAAA--- ---BAAAAAAAAAAAAAA--- ----CAAAAAAAAAAAC---- ----CAAAAAAAAABBC---- -------AAACBBB------- --------------------- --------------------- 
--------------------- --------AACBB-------- -----CAAAAAAABBC----- ----BAAAAAAAAAAAA---- ---BAAAAAAAAAAAAAA--- ---BAAAAAAAAAAAAAA--- --BAAAAAAAAAAAAAAAA-- --BAAAAA---------AA-- -BAAAAA----------AAA- -BAAAAA----------AAA- -BAAAAA----------AAA- -BAAAAA----------AAA- -BAAAAAA---------AAA- --BAAAAA---------AA-- --BAAAAAAAAAAAAAAAA-- ---BAAAAAAAAAAAAAA--- ---BAAAAAAAAAAAAAA--- ----BCAAAAAAAAAAA---- -----CAAAAAAABBC----- --------AACBB-------- --------------------- 
--------------------- -------AAACBBB------- -----BCAAAAAAACA----- ----BAAAAAAAAAAAA---- ---BAAAAAAAAAAAAAA--- --BAAAAAAAAAAAAAAAA-- --BAAAAAAAAAAAAAAAA-- -BAAA------------AAA- -BAAA------------AAA- -BAAA------------AAA- -BAAA------------AAA- -BAAA------------AAA- -BAAA------------AAA- -BAAA------------AAA- --BAAAAAAAAAAAAAAAA-- --BAAAAAAAAAAAAAAAA-- ---BAAAAAAAAAAAAAA--- ----BAAAAAAAAAAAA---- -----BCCAAAAACCA----- -------CCCCCCC------- --------------------- 
---------ACB--------- ------CAAAAABBC------ ----BBAAAAAAAAAAA---- ---BAAAAAAAAAAAAAA--- --BAAAAAAAAAAAAAAAA-- --BAAAAAAAAAAAAAAAA-- -BAAAAAAAAAAAAAAAAAA- -BAAA------------AAA- -BAAA------------AAA- BAAAA------------AAAA BAAAA------------AAAA BAAAA------------AAAA -BAAA------------AAA- -BAAA------------AAA- -BAAAAAAAAAAAAAAAAAA- --BAAAAAAAAAAAAAAAA-- --BAAAAAAAAAAAAAAAA-- ---BAAAAAAAAAAAAAA--- ----BBAAAAAAAAAAA---- ------BBBAAAAAA------ ---------BCA--------- 
--------AACBB-------- -----BCAAAAAABCA----- ----BAAAAAAAAAAAA---- ---BAAAAAAAAAAAAAA--- --BAAAAAAAAAAAAAAAA-- -BAAAAAAAAAAAAAAAAAA- -BAAAAAAAAAAAAAAAAAA- -BAAA------------AAA- BAAAA------------AAAA BAAAA------------AAAA BAAAA------------AAAA BAAAA------------AAAA BAAAA------------AAAA -BAAA------------AAA- -BAAAAAAAAAAAAAAAAAA- -BAAAAAAAAAAAAAAAAAA- --BAAAAAAAAAAAAAAAA-- ---BAAAAAAAAAAAAAA--- ----BAAAAAAAAAAAA---- -----BBBAAAAAAAA----- --------BBCAA-------- 
-------AAACBBB------- -----BCAAAAAAACA----- ----BAAAAAAAAAAAA---- ---BAAAAAAAAAAAAAA--- --BAAAAAAAAAAAAAAAA-- -BAAAAAAAAAAAAAAAAAA- -BAAAAAAAAAAAAAAAAAA- BAAAA------------AAAA BAAAA------------AAAA BAAAA------------AAAA BAAAA------------AAAA BAAAA------------AAAA BAAAA------------AAAA BAAAA------------AAAA -BAAAAAAAAAAAAAAAAAA- -BAAAAAAAAAAAAAAAAAA- --BAAAAAAAAAAAAAAAA-- ---BAAAAAAAAAAAAAA--- ----BAAAAAAAAAAAA---- -----BBAAAAAAAAA----- -------BBBCAAA------- 
-------CCCCCCC------- -----CCAAAAAAACC----- ----CAAAAAAAAAAAC---- ---CAAAAAAAAAAAAAC--- --CAAAAAAAAAAAAAAAC-- -CAAAAAAAAAAAAAAAAAC- -CAAAAAAAAAAAAAAAAAC- CAAAA------------AAAC CAAAA------------AAAC CAAAA------------AAAC CAAAA------------AAAC CAAAA------------AAAC CAAAA------------AAAC CAAAA------------AAAC -CAAAAAAAAAAAAAAAAAC- -CAAAAAAAAAAAAAAAAAC- --CAAAAAAAAAAAAAAAC-- ---CAAAAAAAAAAAAAC--- ----CAAAAAAAAAAAC---- -----CCAAAAAAACC----- -------CCCCCCC------- 
-------BBBCAAA------- -----ACAAAAAAACB----- ----AAAAAAAAAAAAB---- ---AAAAAAAAAAAAAAB--- --AAAAAAAAAAAAAAAAB-- -AAAAAAAAAAAAAAAAAAB- -AAAAAAAAAAAAAAAAAAB- AAAAA------------AAAB AAAAA------------AAAB AAAAA------------AAAB AAAAA------------AAAB AAAAA------------AAAB AAAAA------------AAAB AAAAA------------AAAB -AAAAAAAAAAAAAAAAAAB- -AAAAAAAAAAAAAAAAAAB- --AAAAAAAAAAAAAAAAB-- ---AAAAAAAAAAAAAAB--- ----AAAAAAAAAAAAB---- -----AAAAAAAAABB----- -------AAACBBB------- 
--------BBCAA-------- -----ACBAAAAAACB----- ----AAAAAAAAAAAAB---- ---AAAAAAAAAAAAAAB--- --AAAAAAAAAAAAAAAAB-- -AAAAAAAAAAAAAAAAAAB- -AAAAAAAAAAAAAAAAAAB- -AAAA------------AAB- AAAAA------------AAAB AAAAA------------AAAB AAAAA------------AAAB AAAAA------------AAAB AAAAA------------AAAB -AAAA------------AAB- -AAAAAAAAAAAAAAAAAAB- -AAAAAAAAAAAAAAAAAAB- --AAAAAAAAAAAAAAAAB-- ---AAAAAAAAAAAAAAB--- ----AAAAAAAAAAAAB---- -----AAAAAAAABBB----- --------AACBB-------- 
---------BCA--------- ------CBBAAAAAC------ ----AAAAAAAAAAABB---- ---AAAAAAAAAAAAAAB--- --AAAAAAAAAAAAAAAAB-- --AAAAAAAAAAAAAAAAB-- -AAAAAAAAAAAAAAAAAAB- -AAAA------------AAB- -AAAA------------AAB- AAAAA------------AAAB AAAAA------------AAAB AAAAA------------AAAB -AAAA------------AAB- -AAAA------------AAB- -AAAAAAAAAAAAAAAAAAB- --AAAAAAAAAAAAAAAAB-- --AAAAAAAAAAAAAAAAB-- ---AAAAAAAAAAAAAAB--- ----AAAAAAAAAAABB---- ------AAAAAABBB------ ---------ACB--------- 
--------------------- -------BBBCAAA------- -----ACAAAAAAACB----- ----AAAAAAAAAAAAB---- ---AAAAAAAAAAAAAAB--- --AAAAAAAAAAAAAAAAB-- --AAAAAAAAAAAAAAAAB-- -AAAA------------AAB- -AAAA------------AAB- -AAAA------------AAB- -AAAA------------AAB- -AAAA------------AAB- -AAAA------------AAB- -AAAA------------AAB- --AAAAAAAAAAAAAAAAB-- --AAAAAAAAAAAAAAAAB-- ---AAAAAAAAAAAAAAB--- ----AAAAAAAAAAAAB---- -----ACCAAAAACCB----- -------CCCCCCC------- --------------------- 
--------------------- --------BBCAA-------- -----CBBAAAAAAAC----- ----AAAAAAAAAAAAB---- ---AAAAAAAAAAAAAAB--- ---AAAAAAAAAAAAAAB--- --AAAAAAAAAAAAAAAAB-- --AAA------------AB-- -AAAA------------AAB- -AAAA------------AAB- -AAAA------------AAB- -AAAA------------AAB- -AAAA------------AAB- --AAA------------AB-- --AAAAAAAAAAAAAAAAB-- ---AAAAAAAAAAAAAAB--- ---AAAAAAAAAAAAAAB--- ----ACAAAAAAAAAAB---- -----CBBAAAAAAAC----- --------BBCAA-------- --------------------- 
--------------------- --------------------- -------BBBCAAA------- ----CBBAAAAAAAAAC---- ----CAAAAAAAAAAAC---- ---AAAAAAAAAAAAAAB--- ---AAAAAAAAAAAAAAB--- --AAA------------AB-- --AAA------------AB-- --AAA------------AB-- --AAA------------AB-- --AAA------------AB-- --AAA------------AB-- --AAA------------AB-- ---AAAAAAAAAAAAAAB--- ---AAAAAAAAAAAAAAB--- ----CAAAAAAAAAAAC---- ----CBBAAAAAAAAAC---- -------BBBCAAA------- --------------------- --------------------- 
--------------------- --------------------- --------------------- -------BBBCAAA------- -----BBAAAAAAAAA----- ---CBBAAAAAAAAAAAC--- ---CBAAAAAAAAAAAAC--- ---CA------------C--- ---CA------------C--- ---CA------------C--- ---CA------------C--- ---CA------------C--- ---CA------------C--- ---CA------------C--- ---CBAAAAAAAAAAAAC--- ---CBBAAAAAAAAAAAC--- -----BBAAAAAAAAA----- -------BBBCAAA------- --------------------- --------------------- --------------------- 
--------------------- --------------------- --------------------- --------------------- -------BBBCAAA------- ------BBAAAAAAA------ -----BBAAAAAAAAA----- ----BB-------AAAA---- ----B--------AAAA---- ----B--------AAAA---- ----B--------AAAA---- ----B--------AAAA---- ----B--------AAAA---- ----BB-------AAAA---- -----BBAAAAAAAAA----- ------BBAAAAAAA------ -------BBBCAAA------- --------------------- --------------------- --------------------- --------------------- 
--------------------- --------------------- --------------------- --------------------- --------------------- --------BBCAA-------- -------BBBCAAA------- ------BBB---AAA------ -----BBB-----AAA----- -----BBA-----AAA----- -----BBA-----AAA----- -----BBA-----AAA----- -----BBB-----AAA----- ------BBB---AAA------ -------BBBCAAA------- --------BBCAA-------- --------------------- --------------------- --------------------- --------------------- --------------------- 
--------------------- --------------------- --------------------- --------------------- --------------------- --------------------- --------------------- ---------BCA--------- --------BBCAA-------- -------BBBCAAA------- -------BBBCAAA------- -------BBBCAAA------- --------BBCAA-------- ---------BCA--------- --------------------- --------------------- --------------------- --------------------- --------------------- --------------------- --------------------- 
