model
size = 21, scale = 0.05, origin = -y
material 
  colors = A:#C25100 B:#0029A6 C:#DF0000 D:#EFEFEF E:#000 F:#101010
voxels
--------------------- --------------------- --------------------- --------------------- --------------------- --------------------- --------------------- ---------BDC--------- --------BBDCC-------- -------BBBDCCC------- -------BBBDCCC------- -------BBBDCCC------- --------BBDCC-------- ---------BDC--------- --------------------- --------------------- --------------------- --------------------- --------------------- --------------------- --------------------- 
--------------------- --------------------- --------------------- --------------------- --------------------- --------BBDCC-------- -------BBBDCCC------- ------BBB---CCC------ -----BBB-B---CCC----- -----BB-------CC----- -----BB-------CC----- -----BB-------CC----- -----BBB---F-CCC----- ------BBB--FCCC------ -------BBBDCCC------- --------BBDCC-------- --------------------- --------------------- --------------------- --------------------- --------------------- 
--------------------- --------------------- --------------------- --------------------- -------BBBDCCC------- ------BBAAAAACC------ -----BB-----AACC----- ----BB------AAACC---- ----B-----------C---- ----B-----------C---- ----B-----------C---- ----B-----------C---- ----B-----------C---- ----BB---------CC---- -----BB-------CC----- ------BB-----CC------ -------BBBDCCC------- --------------------- --------------------- --------------------- --------------------- 
--------------------- --------------------- --------------------- -------BBBDCCC------- -----BBAAAAAAACC----- ---DBBAAAAAAAAACCD--- ---DB-------AAAACD--- ---D--------AAAAAD--- ---D------------AD--- ---D------------AD--- ---D------------AD--- ---D------------AD--- ---D------------AD--- ---D------------AD--- ---DB-----------CD--- ---DBB---------CCD--- -----BBAAAAAAACC----- -------BBBDCCC------- --------------------- --------------------- --------------------- 
--------------------- --------------------- -------BBBDCCC------- ----DBBAAAAAAACCD---- ----DAAAAAAAAAAAD---- ---CAAAAAAAAAAAAAB--- ---C--------AAAAAB--- --CA--------AAAAAAB-- --CA------------AAB-- --CA------------AAB-- --CA------------AAB-- --CA------------AAB-- --CA------------AAB-- --CA------------AAB-- ---C------------AB--- ---C------------AB--- ----DAAAAAAAAAAAD---- ----DBBAAAAAAACCD---- -------BBBDCCC------- --------------------- --------------------- 
--------------------- --------BBDCC-------- -----DBBAAAAACCD----- ----CAAAAAAAAAAAB---- ---CAAAAAAAAAAAAAB--- ---CAAAAAAAAAAAAAB--- --CA--------AAAAAAB-- --CA--------AAAAAAB-- -CAA------------AAAB- -CAA------------AAAB- -CAA------------AAAB- -CAA------------AAAB- -CAA------------AAAB- --CA------------AAB-- --CA------------AAB-- ---C------------AB--- ---CAAAAAAAAAAAAAB--- ----CEAAAAAAAAAAB---- -----DBBAAAAACCD----- --------BBDCC-------- --------------------- 
--------------------- -------BBBDCCC------- -----CDAAAAAAADB----- ----CAAAAAAAAAAAB---- ---CAAAAAAAAAAAAAB--- --CAAAAAAAAAAAAAAAB-- --CA--------AAAAAAB-- -CAA--------AAAAAAAB- -CAA------------AAAB- -CAA------------AAAB- -CAA------------AAAB- -CAA------------AAAB- -CAA------------AAAB- -CAA------------AAAB- --CA------------AAB-- --CA------------AAB-- ---CAAAAAAAAAAAAAB--- ----CAAAAAAAAAAAB---- -----CDEAAAAAEDB----- -------DDDDDDD------- --------------------- 
---------BDC--------- ------DBBAAACCD------ ----CCAAAAAAAAABB---- ---CAAAAAAAAAAAAAB--- --CAAAAAAAAAAAAAAAB-- --CAAAAAAAAAAAAAAAB-- -CAA--------AAAAAAAB- -CAA--------AAAAAAAB- -CAA------------AAAB- CAAA------------AAAAB CAAA------------AAAAB CAAA------------AAAAB -CAA------------AAAB- -CAA------------AAAB- -CAA------------AAAB- --CA------------AAB-- --CAAAAAAAAAAAAAAAB-- ---CAAAAAAAAAAAAAB--- ----CCAAAAAAAAABB---- ------CCCAAABBB------ ---------CDB--------- 
--------BBDCC-------- -----CDBAAAAACDB----- ----CAAAAAAAAAAAB---- ---CAAAAAAAAAAAAAB--- --CAAAAAAAAAAAAAAAB-- -CAAAAAAAAAAAAAAAAAB- -CAA--------AAAAAAAB- -CAA--------AAAAAAAB- CAAA------------AAAAB CAAA------------AAAAB CAAA------------AAAAB CAAA------------AAAAB CAAA------------AAAAB -CAA------------AAAB- -CAA------------AAAB- -CAA------------AAAB- --CAAAAAAAAAAAAAAAB-- ---CAAAAAAAAAAAAAB--- ----CAAAAAAAAAAAB---- -----CCCAAAAABBB----- --------CCDBB-------- 
-------BBBDCCC------- -----CDAAAAAAADB----- ----CAAAAAAAAAAAB---- ---CAAAAAAAAAAAAAB--- --CAAAAAAAAAAAAAAAB-- -CAAAAAAAAAAAAAAAAAB- -CAA--------AAAAAAAB- CAAA--------AAAAAAAAB CAAA------------AAAAB CAAA------------AAAAB CAAA------------AAAAB CAAA------------AAAAB CAAA------------AAAAB CAAA------------AAAAB -CAA------------AAAB- -CAA------------AAAB- --CAAAAAAAAAAAAAAAB-- ---CAAAAAAAAAAAAAB--- ----CAAAAAAAAAAAB---- -----CCAAAAAAABB----- -------CCCDBBB------- 
-------DDDDDDD------- -----DDAAAAAAADD----- ----DAAAAAAAAAAAD---- ---DAAAAAAAAAAAAAD--- --DAAAAAAAAAAAAAAAD-- -DAAAAAAAAAAAAAAAAAD- -DAA--------AAAAAAAD- DAAA--------AAAAAAAAD DAAA------------AAAAD DAAA------------AAAAD DAAA------------AAAAD DAAA------------AAAAD DAAA------------AAAAD DAAA------------AAAAD -DAA------------AAAD- -DAA------------AAAD- --DAAAAAAAAAAAAAAAD-- ---DAAAAAAAAAAAAAD--- ----DAAAAAAAAAAAD---- -----DDAAAAAAADD----- -------DDDDDDD------- 
-------CCCDBBB------- -----BDAAAAAAADC----- ----BAAAAAAAAAAAC---- ---BAAAAAAAAAAAAAC--- --BAAAAAAAAAAAAAAAC-- -BAAAAAAAAAAAAAAAAAC- -BAA--------AAAAAAAC- BAAA--------AAAAAAAAC BAAA------------AAAAC BAAA------------AAAAC BAAA------------AAAAC BAAA------------AAAAC BAAA------------AAAAC BAAA------------AAAAC -BAA------------AAAC- -BAA------------AAAC- --BAAAAAAAAAAAAAAAC-- ---BAAAAAAAAAAAAAC--- ----BAAAAAAAAAAAC---- -----BBAAAAAAACC----- -------BBBDCCC------- 
--------CCDBB-------- -----BDCAAAAABDC----- ----BAAAAAAAAAAAC---- ---BAAAAAAAAAAAAAC--- --BAAAAAAAAAAAAAAAC-- -BAAAAAAAAAAAAAAAAAC- -BAA--------AAAAAAAC- -BAA--------AAAAAAAC- BAAA------------AAAAC BAAA------------AAAAC BAAA------------AAAAC BAAA------------AAAAC BAAA------------AAAAC -BAA------------AAAC- -BAA------------AAAC- -BAA------------AAAC- --BAAAAAAAAAAAAAAAC-- ---BAAAAAAAAAAAAAC--- ----BAAAAAAAAAAAC---- -----BBBAAAAACCC----- --------BBDCC-------- 
---------CDB--------- ------DCCAAABBD------ ----BBAAAAAAAAACC---- ---BAAAAAAAAAAAAAC--- --BAAAAAAAAAAAAAAAC-- --BAAAAAAAAAAAAAAAC-- -BAA--------AAAAAAAC- -BAA--------AAAAAAAC- -BAA------------AAAC- BAAA------------AAAAC BAAA------------AAAAC BAAA------------AAAAC -BAA------------AAAC- -BAA------------AAAC- -BAA------------AAAC- --BA------------AAC-- --BAAAAAAAAAAAAAAAC-- ---BAAAAAAAAAAAAAC--- ----BBAAAAAAAAACC---- ------BBBAAACCC------ ---------BDC--------- 
--------------------- -------CCCDBBB------- -----BDAAAAAAADC----- ----BAAAAAAAAAAAC---- ---BAAAAAAAAAAAAAC--- --BAAAAAAAAAAAAAAAC-- --BA--------AAAAAAC-- -BAA--------AAAAAAAC- -BAA------------AAAC- -BAA------------AAAC- -BAA------------AAAC- -BAA------------AAAC- -BAA------------AAAC- -BAA------------AAAC- --BA------------AAC-- --BA------------AAC-- ---BAAAAAAAAAAAAAC--- ----BAAAAAAAAAAAC---- -----BDEAAAAAEDC----- -------DDDDDDD------- --------------------- 
--------------------- --------CCDBB-------- -----DCCAAAAABBD----- ----BAAAAAAAAAAAC---- ---BAAAAAAAAAAAAAC--- ---BAAAAAAAAAAAAAC--- --BA--------AAAAAAC-- --BA--------AAAAAAC-- -BAA------------AAAC- -BAA------------AAAC- -BAA------------AAAC- -BAA------------AAAC- -BAA------------AAAC- --BA------------AAC-- --BA------------AAC-- ---B------------AC--- ---BAAAAAAAAAAAAAC--- ----BEAAAAAAAAAAC---- -----DCCAAAAABBD----- --------CCDBB-------- --------------------- 
--------------------- --------------------- -------CCCDBBB------- ----DCCAAAAAAABBD---- ----DAAAAAAAAAAAD---- ---BAAAAAAAAAAAAAC--- ---B--------AAAAAC--- --BA--------AAAAAAC-- --BA------------AAC-- --BA------------AAC-- --BA------------AAC-- --BA------------AAC-- --BA------------AAC-- --BA------------AAC-- ---B------------AC--- ---B------------AC--- ----DAAAAAAAAAAAD---- ----DCCAAAAAAABBD---- -------CCCDBBB------- --------------------- --------------------- 
--------------------- --------------------- --------------------- -------CCCDBBB------- -----CCAAAAAAABB----- ---DCCAAAAAAAAABBD--- ---DC-------AAAABD--- ---D--------AAAAAD--- ---D------------AD--- ---D------------AD--- ---D------------AD--- ---D------------AD--- ---D------------AD--- ---D------------AD--- ---DC-----------BD--- ---DCC---------BBD--- -----CCAAAAAAABB----- -------CCCDBBB------- --------------------- --------------------- --------------------- 
--------------------- --------------------- --------------------- --------------------- -------CCCDBBB------- ------CCAAAAABB------ -----CC-----AABB----- ----CC------AAABB---- ----C----------BB---- ----C----------BB---- ----C----------BB---- ----C----------BB---- ----C----------BB---- ----CC--------BBB---- -----CC-------BB----- ------CC-----BB------ -------CCCDBBB------- --------------------- --------------------- --------------------- --------------------- 
--------------------- --------------------- --------------------- --------------------- --------------------- --------CCDBB-------- -------CCCDBBB------- ------CCCAA-BBB------ -----CCCAAA-FBBB----- -----CCAAAA---BB----- -----CCAAAA---BB----- -----CCAAAA---BB----- -----CCCAAA--BBB----- ------CCCAA-BBB------ -------CCCDBBB------- --------CCDBB-------- --------------------- --------------------- --------------------- --------------------- --------------------- 
--------------------- --------------------- --------------------- --------------------- --------------------- --------------------- --------------------- ---------CDB--------- --------CCDBB-------- -------CCCDBBB------- -------CCCDBBB------- -------CCCDBBB------- --------CCDBB-------- ---------CDB--------- --------------------- --------------------- --------------------- --------------------- --------------------- --------------------- --------------------- 
