model
size = 21, scale = 0.05, origin = -y
material 
  colors = A:#C25100 B:#101010 C:#808080 D:#000
voxels
--------------------- --------------------- --------------------- --------------------- --------------------- --------------------- --------------------- ---------BCB--------- --------BBCBB-------- -------BBBCBBB------- -------BBBCBBB------- -------BBBCBBB------- --------BBCBB-------- ---------BCB--------- --------------------- --------------------- --------------------- --------------------- --------------------- --------------------- --------------------- 
--------------------- --------------------- --------------------- --------------------- --------------------- --------BBCBB-------- -------BBBCBBB------- ------BBB---BBB------ -----BBB-----BBB----- -----BB-------BB----- -----BB-------BB----- -----BB-------BB----- -----BBB---B-BBB----- ------BBB--BBBB------ -------BBBCBBB------- --------BBCBB-------- --------------------- --------------------- --------------------- --------------------- --------------------- 
--------------------- --------------------- --------------------- --------------------- -------BBBCBBB------- ------BBAAAAABB------ -----BB-----AABB----- ----BB------AAABB---- ----B-----------B---- ----B-----------B---- ----B-----------B---- ----B-----------B---- ----B-----------B---- ----BB---------BB---- -----BB-------BB----- ------BB-----BB------ -------BBBCBBB------- --------------------- --------------------- --------------------- --------------------- 
--------------------- --------------------- --------------------- -------BBBCBBB------- -----BBAAAAAAABB----- ---CBBAAAAAAAAABBC--- ---CB-------AAAABC--- ---C--------AAAAAC--- ---C------------AC--- ---C------------AC--- ---C------------AC--- ---C------------AC--- ---C------------AC--- ---C------------AC--- ---CB-----------BC--- ---CBB---------BBC--- -----BBAAAAAAABB----- -------BBBCBBB------- --------------------- --------------------- --------------------- 
--------------------- --------------------- -------BBBCBBB------- ----CBBAAAAAAABBC---- ----CAAAAAAAAAAAC---- ---BAAAAAAAAAAAAAB--- ---B--------AAAAAB--- --BA--------AAAAAAB-- --BA------------AAB-- --BA------------AAB-- --BA------------AAB-- --BA------------AAB-- --BA------------AAB-- --BA------------AAB-- ---B------------AB--- ---B------------AB--- ----CAAAAAAAAAAAC---- ----CBBAAAAAAABBC---- -------BBBCBBB------- --------------------- --------------------- 
--------------------- --------BBCBB-------- -----CBBAAAAABBC----- ----BAAAAAAAAAAAB---- ---BAAAAAAAAAAAAAB--- ---BAAAAAAAAAAAAAB--- --BA--------AAAAAAB-- --BA--------AAAAAAB-- -BAA------------AAAB- -BAA------------AAAB- -BAA------------AAAB- -BAA------------AAAB- -BAA------------AAAB- --BA------------AAB-- --BA------------AAB-- ---B------------AB--- ---BAAAAAAAAAAAAAB--- ----BDAAAAAAAAAAB---- -----CBBAAAAABBC----- --------BBCBB-------- --------------------- 
--------------------- -------BBBCBBB------- -----BCAAAAAAACB----- ----BAAAAAAAAAAAB---- ---BAAAAAAAAAAAAAB--- --BAAAAAAAAAAAAAAAB-- --BA--------AAAAAAB-- -BAA--------AAAAAAAB- -BAA------------AAAB- -BAA------------AAAB- -BAA------------AAAB- -BAA------------AAAB- -BAA------------AAAB- -BAA------------AAAB- --BA------------AAB-- --BA------------AAB-- ---BAAAAAAAAAAAAAB--- ----BAAAAAAAAAAAB---- -----BCDAAAAADCB----- -------CCCCCCC------- --------------------- 
---------BCB--------- ------CBBAAABBC------ ----BBAAAAAAAAABB---- ---BAAAAAAAAAAAAAB--- --BAAAAAAAAAAAAAAAB-- --BAAAAAAAAAAAAAAAB-- -BAA--------AAAAAAAB- -BAA--------AAAAAAAB- -BAA------------AAAB- BAAA------------AAAAB BAAA------------AAAAB BAAA------------AAAAB -BAA------------AAAB- -BAA------------AAAB- -BAA------------AAAB- --BA------------AAB-- --BAAAAAAAAAAAAAAAB-- ---BAAAAAAAAAAAAAB--- ----BBAAAAAAAAABB---- ------BBBAAABBB------ ---------BCB--------- 
--------BBCBB-------- -----BCBAAAAABCB----- ----BAAAAAAAAAAAB---- ---BAAAAAAAAAAAAAB--- --BAAAAAAAAAAAAAAAB-- -BAAAAAAAAAAAAAAAAAB- -BAA--------AAAAAAAB- -BAA--------AAAAAAAB- BAAA------------AAAAB BAAA------------AAAAB BAAA------------AAAAB BAAA------------AAAAB BAAA------------AAAAB -BAA------------AAAB- -BAA------------AAAB- -BAA------------AAAB- --BAAAAAAAAAAAAAAAB-- ---BAAAAAAAAAAAAAB--- ----BAAAAAAAAAAAB---- -----BBBAAAAABBB----- --------BBCBB-------- 
-------BBBCBBB------- -----BCAAAAAAACB----- ----BAAAAAAAAAAAB---- ---BAAAAAAAAAAAAAB--- --BAAAAAAAAAAAAAAAB-- -BAAAAAAAAAAAAAAAAAB- -BAA--------AAAAAAAB- BAAA--------AAAAAAAAB BAAA------------AAAAB BAAA------------AAAAB BAAA------------AAAAB BAAA------------AAAAB BAAA------------AAAAB BAAA------------AAAAB -BAA------------AAAB- -BAA------------AAAB- --BAAAAAAAAAAAAAAAB-- ---BAAAAAAAAAAAAAB--- ----BAAAAAAAAAAAB---- -----BBAAAAAAABB----- -------BBBCBBB------- 
-------CCCCCCC------- -----CCAAAAAAACC----- ----CAAAAAAAAAAAC---- ---CAAAAAAAAAAAAAC--- --CAAAAAAAAAAAAAAAC-- -CAAAAAAAAAAAAAAAAAC- -CAA--------AAAAAAAC- CAAA--------AAAAAAAAC CAAA------------AAAAC CAAA------------AAAAC CAAA------------AAAAC CAAA------------AAAAC CAAA------------AAAAC CAAA------------AAAAC -CAA------------AAAC- -CAA------------AAAC- --CAAAAAAAAAAAAAAAC-- ---CAAAAAAAAAAAAAC--- ----CAAAAAAAAAAAC---- -----CCAAAAAAACC----- -------CCCCCCC------- 
-------BBBCBBB------- -----BCAAAAAAACB----- ----BAAAAAAAAAAAB---- ---BAAAAAAAAAAAAAB--- --BAAAAAAAAAAAAAAAB-- -BAAAAAAAAAAAAAAAAAB- -BAA--------AAAAAAAB- BAAA--------AAAAAAAAB BAAA------------AAAAB BAAA------------AAAAB BAAA------------AAAAB BAAA------------AAAAB BAAA------------AAAAB BAAA------------AAAAB -BAA------------AAAB- -BAA------------AAAB- --BAAAAAAAAAAAAAAAB-- ---BAAAAAAAAAAAAAB--- ----BAAAAAAAAAAAB---- -----BBAAAAAAABB----- -------BBBCBBB------- 
--------BBCBB-------- -----BCBAAAAABCB----- ----BAAAAAAAAAAAB---- ---BAAAAAAAAAAAAAB--- --BAAAAAAAAAAAAAAAB-- -BAAAAAAAAAAAAAAAAAB- -BAA--------AAAAAAAB- -BAA--------AAAAAAAB- BAAA------------AAAAB BAAA------------AAAAB BAAA------------AAAAB BAAA------------AAAAB BAAA------------AAAAB -BAA------------AAAB- -BAA------------AAAB- -BAA------------AAAB- --BAAAAAAAAAAAAAAAB-- ---BAAAAAAAAAAAAAB--- ----BAAAAAAAAAAAB---- -----BBBAAAAABBB----- --------BBCBB-------- 
---------BCB--------- ------CBBAAABBC------ ----BBAAAAAAAAABB---- ---BAAAAAAAAAAAAAB--- --BAAAAAAAAAAAAAAAB-- --BAAAAAAAAAAAAAAAB-- -BAA--------AAAAAAAB- -BAA--------AAAAAAAB- -BAA------------AAAB- BAAA------------AAAAB BAAA------------AAAAB BAAA------------AAAAB -BAA------------AAAB- -BAA------------AAAB- -BAA------------AAAB- --BA------------AAB-- --BAAAAAAAAAAAAAAAB-- ---BAAAAAAAAAAAAAB--- ----BBAAAAAAAAABB---- ------BBBAAABBB------ ---------BCB--------- 
--------------------- -------BBBCBBB------- -----BCAAAAAAACB----- ----BAAAAAAAAAAAB---- ---BAAAAAAAAAAAAAB--- --BAAAAAAAAAAAAAAAB-- --BA--------AAAAAAB-- -BAA--------AAAAAAAB- -BAA------------AAAB- -BAA------------AAAB- -BAA------------AAAB- -BAA------------AAAB- -BAA------------AAAB- -BAA------------AAAB- --BA------------AAB-- --BA------------AAB-- ---BAAAAAAAAAAAAAB--- ----BAAAAAAAAAAAB---- -----BCDAAAAADCB----- -------CCCCCCC------- --------------------- 
--------------------- --------BBCBB-------- -----CBBAAAAABBC----- ----BAAAAAAAAAAAB---- ---BAAAAAAAAAAAAAB--- ---BAAAAAAAAAAAAAB--- --BA--------AAAAAAB-- --BA--------AAAAAAB-- -BAA------------AAAB- -BAA------------AAAB- -BAA------------AAAB- -BAA------------AAAB- -BAA------------AAAB- --BA------------AAB-- --BA------------AAB-- ---B------------AB--- ---BAAAAAAAAAAAAAB--- ----BDAAAAAAAAAAB---- -----CBBAAAAABBC----- --------BBCBB-------- --------------------- 
--------------------- --------------------- -------BBBCBBB------- ----CBBAAAAAAABBC---- ----CAAAAAAAAAAAC---- ---BAAAAAAAAAAAAAB--- ---B--------AAAAAB--- --BA--------AAAAAAB-- --BA------------AAB-- --BA------------AAB-- --BA------------AAB-- --BA------------AAB-- --BA------------AAB-- --BA------------AAB-- ---B------------AB--- ---B------------AB--- ----CAAAAAAAAAAAC---- ----CBBAAAAAAABBC---- -------BBBCBBB------- --------------------- --------------------- 
--------------------- --------------------- --------------------- -------BBBCBBB------- -----BBAAAAAAABB----- ---CBBAAAAAAAAABBC--- ---CB-------AAAABC--- ---C--------AAAAAC--- ---C------------AC--- ---C------------AC--- ---C------------AC--- ---C------------AC--- ---C------------AC--- ---C------------AC--- ---CB-----------BC--- ---CBB---------BBC--- -----BBAAAAAAABB----- -------BBBCBBB------- --------------------- --------------------- --------------------- 
--------------------- --------------------- --------------------- --------------------- -------BBBCBBB------- ------BBAAAAABB------ -----BB-----AABB----- ----BB------AAABB---- ----B----------BB---- ----B----------BB---- ----B----------BB---- ----B----------BB---- ----B----------BB---- ----BB--------BBB---- -----BB-------BB----- ------BB-----BB------ -------BBBCBBB------- --------------------- --------------------- --------------------- --------------------- 
--------------------- --------------------- --------------------- --------------------- --------------------- --------BBCBB-------- -------BBBCBBB------- ------BBBAA-BBB------ -----BBBAAA-BBBB----- -----BBAAAA---BB----- -----BBAAAA---BB----- -----BBAAAA---BB----- -----BBBAAA--BBB----- ------BBBAA-BBB------ -------BBBCBBB------- --------BBCBB-------- --------------------- --------------------- --------------------- --------------------- --------------------- 
--------------------- --------------------- --------------------- --------------------- --------------------- --------------------- --------------------- ---------BCB--------- --------BBCBB-------- -------BBBCBBB------- -------BBBCBBB------- -------BBBCBBB------- --------BBCBB-------- ---------BCB--------- --------------------- --------------------- --------------------- --------------------- --------------------- --------------------- --------------------- 
