model
size = 21, scale = 0.05, origin = -y
material 
  colors = A:#C25100 B:#000
voxels
--------------------- --------------------- --------------------- --------------------- --------------------- --------------------- --------------------- ---------ABA--------- --------AABAA-------- -------AAABAAA------- -------AAABAAA------- -------AAABAAA------- --------AABAA-------- ---------ABA--------- --------------------- --------------------- --------------------- --------------------- --------------------- --------------------- --------------------- 
--------------------- --------------------- --------------------- --------------------- --------------------- --------AABAA-------- -------AAABAAA------- ------AAA---AAA------ -----AAA-----AAA----- -----AAA-----AAA----- -----AAA-----AAA----- -----AAA-----AAA----- -----AAA-----AAA----- ------AAA---AAA------ -------AAABAAA------- --------AABAA-------- --------------------- --------------------- --------------------- --------------------- --------------------- 
--------------------- --------------------- --------------------- --------------------- -------AAABAAA------- ------AAAAAAAAA------ -----AAAAAAAAAAA----- ----AAAA-----AAAA---- ----AAAA-----AAAA---- ----AAAA-----AAAA---- ----AAAA-----AAAA---- ----AAAA-----AAAA---- ----AAAA-----AAAA---- ----AAAA-----AAAA---- -----AAAAAAAAAAA----- ------AAAAAAAAA------ -------AAABAAA------- --------------------- --------------------- --------------------- --------------------- 
--------------------- --------------------- --------------------- -------AAABAAA------- -----AAAAAAAAAAA----- ---BAAAAAAAAAAAAAB--- ---BAAAAAAAAAAAAAB--- ---BAAAA-----AAAAB--- ---BAAAA-----AAAAB--- ---BAAAA-----AAAAB--- ---BAAAA---------B--- ---BAAAA-----AAAAB--- ---BAAAA-----AAAAB--- ---BAAAA-----AAAAB--- ---BAAAAAAAAAAAAAB--- ---BAAAAAAAAAAAAAB--- -----AAAAAAAAAAA----- -------AAABAAA------- --------------------- --------------------- --------------------- 
--------------------- --------------------- -------AAABAAA------- ----BAAAAAAAAAAAB---- ----BAAAAAAAAAAAB---- ---AAAAAAAAAAAAAAA--- ---AAAAAAAAAAAAAAA--- --AAAAAA---------AA-- --AAAAA----------AA-- --AAAAA----------AA-- --AAAAA----------AA-- --AAAAA----------AA-- --AAAAAA---------AA-- --AAAAAA---------AA-- ---AAAAAAAAAAAAAAA--- ---AAAAAAAAAAAAAAA--- ----BAAAAAAAAAAAB---- ----BAAAAAAAAAAAB---- -------AAABAAA------- --------------------- --------------------- 
--------------------- --------AABAA-------- -----BAAAAAAAAAB----- ----AAAAAAAAAAAAA---- ---AAAAAAAAAAAAAAA--- ---AAAAAAAAAAAAAAA--- --AAAAAAAAAAAAAAAAA-- --AAAAAA---------AA-- -AAAAAA----------AAA- -AAAAAA----------AAA- -AAAAAA----------AAA- -AAAAAA----------AAA- -AAAAAAA---------AAA- --AAAAAA---------AA-- --AAAAAAAAAAAAAAAAA-- ---AAAAAAAAAAAAAAA--- ---AAAAAAAAAAAAAAA--- ----ABAAAAAAAAAAA---- -----BAAAAAAAAAB----- --------AABAA-------- --------------------- 
--------------------- -------AAABAAA------- -----ABAAAAAAABA----- ----AAAAAAAAAAAAA---- ---AAAAAAAAAAAAAAA--- --AAAAAAAAAAAAAAAAA-- --AAAAAAAAAAAAAAAAA-- -AAAA------------AAA- -AAAA------------AAA- -AAAA------------AAA- -AAAA------------AAA- -AAAA------------AAA- -AAAA------------AAA- -AAAA------------AAA- --AAAAAAAAAAAAAAAAA-- --AAAAAAAAAAAAAAAAA-- ---AAAAAAAAAAAAAAA--- ----AAAAAAAAAAAAA---- -----ABBAAAAABBA----- -------BBBBBBB------- --------------------- 
---------ABA--------- ------BAAAAAAAB------ ----AAAAAAAAAAAAA---- ---AAAAAAAAAAAAAAA--- --AAAAAAAAAAAAAAAAA-- --AAAAAAAAAAAAAAAAA-- -AAAAAAAAAAAAAAAAAAA- -AAAA------------AAA- -AAAA------------AAA- AAAAA------------AAAA AAAAA------------AAAA AAAAA------------AAAA -AAAA------------AAA- -AAAA------------AAA- -AAAAAAAAAAAAAAAAAAA- --AAAAAAAAAAAAAAAAA-- --AAAAAAAAAAAAAAAAA-- ---AAAAAAAAAAAAAAA--- ----AAAAAAAAAAAAA---- ------AAAAAAAAA------ ---------ABA--------- 
--------AABAA-------- -----ABAAAAAAABA----- ----AAAAAAAAAAAAA---- ---AAAAAAAAAAAAAAA--- --AAAAAAAAAAAAAAAAA-- -AAAAAAAAAAAAAAAAAAA- -AAAAAAAAAAAAAAAAAAA- -AAAA------------AAA- AAAAA------------AAAA AAAAA------------AAAA AAAAA------------AAAA AAAAA------------AAAA AAAAA------------AAAA -AAAA------------AAA- -AAAAAAAAAAAAAAAAAAA- -AAAAAAAAAAAAAAAAAAA- --AAAAAAAAAAAAAAAAA-- ---AAAAAAAAAAAAAAA--- ----AAAAAAAAAAAAA---- -----AAAAAAAAAAA----- --------AABAA-------- 
-------AAABAAA------- -----ABAAAAAAABA----- ----AAAAAAAAAAAAA---- ---AAAAAAAAAAAAAAA--- --AAAAAAAAAAAAAAAAA-- -AAAAAAAAAAAAAAAAAAA- -AAAAAAAAAAAAAAAAAAA- AAAAA------------AAAA AAAAA------------AAAA AAAAA------------AAAA AAAAA------------AAAA AAAAA------------AAAA AAAAA------------AAAA AAAAA------------AAAA -AAAAAAAAAAAAAAAAAAA- -AAAAAAAAAAAAAAAAAAA- --AAAAAAAAAAAAAAAAA-- ---AAAAAAAAAAAAAAA--- ----AAAAAAAAAAAAA---- -----AAAAAAAAAAA----- -------AAABAAA------- 
-------BBBBBBB------- -----BBAAAAAAABB----- ----BAAAAAAAAAAAB---- ---BAAAAAAAAAAAAAB--- --BAAAAAAAAAAAAAAAB-- -BAAAAAAAAAAAAAAAAAB- -BAAAAAAAAAAAAAAAAAB- BAAAA------------AAAB BAAAA------------AAAB BAAAA------------AAAB BAAAA------------AAAB BAAAA------------AAAB BAAAA------------AAAB BAAAA------------AAAB -BAAAAAAAAAAAAAAAAAB- -BAAAAAAAAAAAAAAAAAB- --BAAAAAAAAAAAAAAAB-- ---BAAAAAAAAAAAAAB--- ----BAAAAAAAAAAAB---- -----BBAAAAAAABB----- -------BBBBBBB------- 
-------AAABAAA------- -----ABAAAAAAABA----- ----AAAAAAAAAAAAA---- ---AAAAAAAAAAAAAAA--- --AAAAAAAAAAAAAAAAA-- -AAAAAAAAAAAAAAAAAAA- -AAAAAAAAAAAAAAAAAAA- AAAAA------------AAAA AAAAA------------AAAA AAAAA------------AAAA AAAAA------------AAAA AAAAA------------AAAA AAAAA------------AAAA AAAAA------------AAAA -AAAAAAAAAAAAAAAAAAA- -AAAAAAAAAAAAAAAAAAA- --AAAAAAAAAAAAAAAAA-- ---AAAAAAAAAAAAAAA--- ----AAAAAAAAAAAAA---- -----AAAAAAAAAAA----- -------AAABAAA------- 
--------AABAA-------- -----ABAAAAAAABA----- ----AAAAAAAAAAAAA---- ---AAAAAAAAAAAAAAA--- --AAAAAAAAAAAAAAAAA-- -AAAAAAAAAAAAAAAAAAA- -AAAAAAAAAAAAAAAAAAA- -AAAA------------AAA- AAAAA------------AAAA AAAAA------------AAAA AAAAA------------AAAA AAAAA------------AAAA AAAAA------------AAAA -AAAA------------AAA- -AAAAAAAAAAAAAAAAAAA- -AAAAAAAAAAAAAAAAAAA- --AAAAAAAAAAAAAAAAA-- ---AAAAAAAAAAAAAAA--- ----AAAAAAAAAAAAA---- -----AAAAAAAAAAA----- --------AABAA-------- 
---------ABA--------- ------BAAAAAAAB------ ----AAAAAAAAAAAAA---- ---AAAAAAAAAAAAAAA--- --AAAAAAAAAAAAAAAAA-- --AAAAAAAAAAAAAAAAA-- -AAAAAAAAAAAAAAAAAAA- -AAAA------------AAA- -AAAA------------AAA- AAAAA------------AAAA AAAAA------------AAAA AAAAA------------AAAA -AAAA------------AAA- -AAAA------------AAA- -AAAAAAAAAAAAAAAAAAA- --AAAAAAAAAAAAAAAAA-- --AAAAAAAAAAAAAAAAA-- ---AAAAAAAAAAAAAAA--- ----AAAAAAAAAAAAA---- ------AAAAAAAAA------ ---------ABA--------- 
--------------------- -------AAABAAA------- -----ABAAAAAAABA----- ----AAAAAAAAAAAAA---- ---AAAAAAAAAAAAAAA--- --AAAAAAAAAAAAAAAAA-- --AAAAAAAAAAAAAAAAA-- -AAAA------------AAA- -AAAA------------AAA- -AAAA------------AAA- -AAAA------------AAA- -AAAA------------AAA- -AAAA------------AAA- -AAAA------------AAA- --AAAAAAAAAAAAAAAAA-- --AAAAAAAAAAAAAAAAA-- ---AAAAAAAAAAAAAAA--- ----AAAAAAAAAAAAA---- -----ABBAAAAABBA----- -------BBBBBBB------- --------------------- 
--------------------- --------AABAA-------- -----BAAAAAAAAAB----- ----AAAAAAAAAAAAA---- ---AAAAAAAAAAAAAAA--- ---AAAAAAAAAAAAAAA--- --AAAAAAAAAAAAAAAAA-- --AAA------------AA-- -AAAA------------AAA- -AAAA------------AAA- -AAAA------------AAA- -AAAA------------AAA- -AAAA------------AAA- --AAA------------AA-- --AAAAAAAAAAAAAAAAA-- ---AAAAAAAAAAAAAAA--- ---AAAAAAAAAAAAAAA--- ----ABAAAAAAAAAAA---- -----BAAAAAAAAAB----- --------AABAA-------- --------------------- 
--------------------- --------------------- -------AAABAAA------- ----BAAAAAAAAAAAB---- ----BAAAAAAAAAAAB---- ---AAAAAAAAAAAAAAA--- ---AAAAAAAAAAAAAAA--- --AAA------------AA-- --AAA------------AA-- --AAA------------AA-- --AAA------------AA-- --AAA------------AA-- --AAA------------AA-- --AAA------------AA-- ---AAAAAAAAAAAAAAA--- ---AAAAAAAAAAAAAAA--- ----BAAAAAAAAAAAB---- ----BAAAAAAAAAAAB---- -------AAABAAA------- --------------------- --------------------- 
--------------------- --------------------- --------------------- -------AAABAAA------- -----AAAAAAAAAAA----- ---BAAAAAAAAAAAAAB--- ---BAAAAAAAAAAAAAB--- ---BA------------B--- ---BA------------B--- ---BA------------B--- ---BA------------B--- ---BA------------B--- ---BA------------B--- ---BA------------B--- ---BAAAAAAAAAAAAAB--- ---BAAAAAAAAAAAAAB--- -----AAAAAAAAAAA----- -------AAABAAA------- --------------------- --------------------- --------------------- 
--------------------- --------------------- --------------------- --------------------- -------AAABAAA------- ------AAAAAAAAA------ -----AAAAAAAAAAA----- ----AA-------AAAA---- ----A--------AAAA---- ----A--------AAAA---- ----A--------AAAA---- ----A--------AAAA---- ----A--------AAAA---- ----AA-------AAAA---- -----AAAAAAAAAAA----- ------AAAAAAAAA------ -------AAABAAA------- --------------------- --------------------- --------------------- --------------------- 
--------------------- --------------------- --------------------- --------------------- --------------------- --------AABAA-------- -------AAABAAA------- ------AAA---AAA------ -----AAA-----AAA----- -----AAA-----AAA----- -----AAA-----AAA----- -----AAA-----AAA----- -----AAA-----AAA----- ------AAA---AAA------ -------AAABAAA------- --------AABAA-------- --------------------- --------------------- --------------------- --------------------- --------------------- 
--------------------- --------------------- --------------------- --------------------- --------------------- --------------------- --------------------- ---------ABA--------- --------AABAA-------- -------AAABAAA------- -------AAABAAA------- -------AAABAAA------- --------AABAA-------- ---------ABA--------- --------------------- --------------------- --------------------- --------------------- --------------------- --------------------- --------------------- 
