model
size = 4 27 25, scale = 0.05, origin = -y
material 
  colors = A:#F8C3CD B:#EEE C:#FFC408 D:#111 E:#BBB F:#F4A7B9 G:#4A225D
voxels
---- ---- ---- ---- ---- ---- ---- ---- ---- ---- ---- CACA CACD CACC CAAA AAAF AAAA AADA ---- ---- ---- ---- ---- ---- ---- ---- ---- 
---- ---- ---- ---- ---- ---- ---- ---- ---- DDDA DAAA ---- ---- ---- ---- ---- ---- ---- CAAA BBAA ---- ---- ---- ---- ---- ---- ---- 
---- ---- ---- ---- BEBB BBBB BBBB ABAA ABAA ---- ---- ---- ---- ---- ---- ---- ---- ---- ---- ---- BBBA BEBB ---- ---- ---- ---- ---- 
---A A-AA AAAA AAAA BBBB BGGB BBBB ---- ---- ---- ---- ---- ---- ---- ---- ---- ---- ---- ---- ---- ---- ---- BBBB ---- ---- ---- ---- 
---- ---- ---- ---- ---- BBBB ---- ---- ---- ---- ---- ---- ---- ---- ---- ---- ---- ---- ---- ---- ---- ---- ---- BBBA ---- ---- ---- 
---- ---- ---- ---- BBBB ---- ---- ---- ---- ---- ---- ---- ---- ---- ---- ---- ---- ---- ---- ---- ---- ---- ---- ---- ABAA ---- ---- 
---- ---- ---- ---- BBBA ---- ---- ---- ---- ---- ---- ---- ---- ---- ---- ---- ---- ---- ---- ---- ---- ---- ---- ---- ABAA ---- ---- 
---- ---- ---- BBAA ---- ---- ---- ---- ---- ---- ---- ---- ---- ---- ---- ---- ---- ---- ---- ---- ---- ---- ---- ---- ---- DDDA ---- 
---- ---- ---- CAAA ---- ---- ---- ---- ---- ---- ---- ---- ---- ---- ---- ---- ---- ---- ---- ---- ---- ---- ---- ---- ---- DAAA ---- 
---- ---- AADA ---- ---- ---- ---- ---- ---- ---- ---- ---- ---- ---- ---- ---- ---- ---- ---- ---- ---- ---- ---- ---- ---- ---- CACA 
---- ---- AAAA ---- ---- ---- ---- ---- ---- ---- ---- ---- ---- ---- ---- ---- ---- ---- ---- ---- ---- ---- ---- ---- ---- ---- CACD 
---- ---- AAAF ---- ---- ---- ---- ---- ---- ---- ---- ---- ---- ---- ---- ---- ---- ---- ---- ---- ---- ---- ---- ---- ---- ---- CACC 
---- ---- CAAA ---- ---- ---- ---- ---- ---- ---- ---- ---- ---- ---- ---- ---- ---- ---- ---- ---- ---- ---- ---- ---- ---- ---- CAAA 
---- ---- CACC ---- ---- ---- ---- ---- ---- ---- ---- ---- ---- ---- ---- ---- ---- ---- ---- ---- ---- ---- ---- ---- ---- ---- AAAF 
---- ---- CACD ---- ---- ---- ---- ---- ---- ---- ---- ---- ---- ---- ---- ---- ---- ---- ---- ---- ---- ---- ---- ---- ---- ---- AAAA 
---- ---- CACA ---- ---- ---- ---- ---- ---- ---- ---- ---- ---- ---- ---- ---- ---- ---- ---- ---- ---- ---- ---- ---- ---- ---- AADA 
---- ---- ---- DAAA ---- ---- ---- ---- ---- ---- ---- ---- ---- ---- ---- ---- ---- ---- ---- ---- ---- ---- ---- ---- ---- CAAA ---- 
---- ---- ---- DDDA ---- ---- ---- ---- ---- ---- ---- ---- ---- ---- ---- ---- ---- ---- ---- ---- ---- ---- ---- ---- ---- BBAA ---- 
---- ---- ---- ---- ABAA ---- ---- ---- ---- ---- ---- ---- ---- ---- ---- ---- ---- ---- ---- ---- ---- ---- ---- ---- BBBA ---- ---- 
---- ---- ---- ---- ABAA ---- ---- ---- ---- ---- ---- ---- ---- ---- ---- ---- ---- ---- ---- ---- ---- ---- ---- DDDD BEBB ---- ---- 
---- ---- ---- ---- ---- BBBA ---- ---- ---- ---- ---- ---- ---- ---- ---- ---- ---- ---- ---- ---- ---- ---- ---- BBBB ---- ---- ---- 
---- ---- ---- ---- ---- ---- BBBB ---- ---- ---- ---- ---- ---- ---- ---- ---- ---- ---- ---- ---- ---- ---- BBBA ---- ---- ---- ---- 
---- ---- ---- ---- ---- ---- ---- BEBB BBBA ---- ---- ---- ---- ---- ---- ---- ---- ---- ---- ---- ABAA ABAA ---- ---- ---- ---- ---- 
---- ---- ---- ---- ---- ---- ---- ---- ---- BBAA CAAA ---- ---- ---- ---- ---- ---- ---- DAAA DDDA ---- ---- ---- ---- ---- ---- ---- 
---- ---- ---- ---- ---- ---- ---- ---- ---- ---- ---- AADA AAAA AAAF CAAA CACC CACD CACA ---- ---- ---- ---- ---- ---- ---- ---- ---- 
