model
size = 21 19 32, scale = 0.05, origin = -y
material 
  colors = A:#0B1013 B:#18212D C:#99C221 D:#E03C8A
voxels
22-19A-42A21-21A21-42A-19A191-19A2-19A-42A21C21A-19C-63A-19A170-2A2(B3ABA)BAB2A-20A2-24A2(6-A6-8A)6-A6-4A-C2A6-A6-2AC-4A6-2A5-9A5-2A5-25A-2(A2B2(AB))A3BA170-2AB6ABAB2AB4A-2A17-2A-A-15A3-2A3(-2(2A5-)A2-3A)-2(2A5-)A2-A-C-2(2A5-)C3-2A-15A2-3A2-14A2(-2A)2(BA)B6ABAB3A170-2AB3A3(BA)B2AB3A-3A15-5A2-14A-2(A2-)3(14A-4A2-)14A-2A-C2-5A-7A2(C-)2A2-14A-4A17-2A-2(A2BAB)2(AB)3ABA170-2A2(B3ABA)B4A-42A-19A-7A-19A3-4A2-12A2-5A2-25AC2-C40A-11AB3A2(BA)170-2ABA2(B3A)2(BA)B2A-62A2-6A-2A2-15A3-2(A2-)12A2-2A2-A2-15A3-9A-C17AC-21A-A3B4(AB)A2B2ABA170-2(9A-)43A-19A2-5A-12A-A-4A3-4A2-7A-4A2-5A2-7A-19A2-C16AC-21A-AB3AB13A10-3A157-5A10-4A-10A2-12A15-4A-A3-3A3-4A2-4A-A2(2-5A)2-A3-2(A2(2-5A)2-3A-)A2-4A3-4A2-3A-CA4-7A4-AC-21A-2(AB)A3B5ACADABA10-3A18-3A136-2A15-2A-9A3-12A2-4A3-4A2-2(6A15-)3A-2A15-2A-3A15-6A15-3A-CA2-11A2-AC-21A-4A-14A31-2(3A18-)3A115-7A5-16A6-10A2(15-6A)15-2A2-2A15-2A-3A15-3A-C6A5-6AC3-6A5-8A4-4A5-5A75-3A18-3A95-4A9-4A4-4A10-3A4-2A13-2A3-3(3A13-3A2-)3A13-3A3-4A10-3A5-3A9-3A6-3A9-3A96-3A18-3A74-2(2A13-2A4-)2A13-2A3-3(3A13-3A2-)3A13-3A3-2A13-2A4-2A14-A137-3A96-A14-A4-2A14-A3-3(3A14-2A2-)3A14-2A3-2A14-A158-3A18-3A115-3(A17-A2-)A17-A199-3A115-3(2A16-A2-)2A16-A199-3A18-3(3A95-3(A16-A3-)A16-A220-)3A116-2(A16-A3-)A16-A220-2(3A116-3(A15-2A3-)A15-2A199-)2(3A116-3(A15-A4-)A15-A200-)3A116-3(2A14-A4-)A15-A200-3A116-2A14-A4-2A13-2A2(4-2A14-A)200-3A138-A13-2A5-A13-2A4-2A13-2A5-A13-A159-3A18-3A138-2(2A11-2A6-)2A12-A6-2A12-A138-3A18-3A160-2A9-3A7-2A2(10-2A6-3A)10-2A117-3A18-3A161-3A5-3A10-2A7-3A9-2A7-2(3A8-)2A8-3A8-2A9-2A7-3A10-A7-2A56-3A18-3A183-3A3-3A12-2A5-3A11-A7-2A10-2A7-2A10-3A5-3A11-3A3-4A11-10A12-7A16-3A18-3A206-5A16-A3-2A56-A5-A14-7A15-6A16-4A134-
