model
size = 32 24 32, scale = 0.05, origin = -y
material 
  colors = A:#BBB B:#3CF C:#E00 D:#001 E:#111
voxels
10A11-13A6E2A11-3A5E5AE4AE2A11-2(3AE)5AEA4E2A2(11-2(3AE)5AE7A)11-2(3AE)5A6E2A11-3A5E13A11-11A512-10A7(11-21A)11-11A672-A2(30-2A)30-11A2(11-21A)11-11A608-A30-2A30-11A2(11-21A)11-11A640-A30-11A3(11-21A)11-11A640-3(A31-)10A3(11-21A)11-16AE4A11-12AE3AE4A11-10AD2(2AE)4A11-10AD3AEAE4A11-10AD5AE4A11-10AD2(10A11-11A384-5(A31-)2(A2(20-12A)20-10AD))10A11-21A11-11A533-5(11A21-)4(21A11-)11A479-2(A31-)3(D31-)DA30-11A2(11-21A)11-11A32-A15(30-2A)30-DA2(30-2A)30-DA30-2A30-11A11-21A11-11A32-A30-A415-2(A31-)3(D31-)DA30-2A30-11A11-21A11-11A32-A30-A415-5(A31-)2(2A30-)11A11-21A11-11A32-A30-A128-A5(30-2A)30-A95-2(A31-)3(D31-)DA30-2A30-2(11A11-21A11-11A32-2(A30-A128-)A30-A95-2(A31-)D2(31-A)31-2(2A30-))11A11-21A11-11A32-2(A30-A128-)A30-A95-5(A31-)2(2A30-)11A11-21A11-11A32-2(A30-A128-)A30-A95-2(A31-)3(D31-)DA30-2A30-11A11-21A11-11A32-2(A30-A128-)A30-A95-2(A31-)D2(31-A)31-DA30-2A30-11A11-21A11-11A32-2(A30-A128-)A30-A95-3(A31-)2(D31-)2(2A30-)11A11-21A11-11A32-2(A30-A128-)A30-A95-5(A31-)2(2A30-)11A11-21A11-11A32-A30-A128-A30-A32-A3(30-2A)30-A95-2(A31-)D2(31-A)31-DA30-2A30-11A11-21A11-11A32-A30-A128-A30-A32-A30-A191-2(A31-)3(D31-)DA30-2A30-11A11-21A11-11A32-A30-A128-A30-A32-A30-A191-2(A31-)D2(31-A)31-DA30-2A30-11A11-21A11-11A32-A5(30-2A)2(30-A32-A)4(31-A)7(30-2A)30-11A11-21A11-11A192-2(A31-)A30-2A5(31-A)30-2A5(30-DA)30-2A30-11A11-21A11-11A160-3(A31-)A30-2A5(31-A)3(30-2A30-DA)30-2A30-11A11-11A32-8(A31-)A30-2A5(31-A)30-11A6(11-21A)11-11A64-13A5-27A5-16A9-2A5-2A10-4A9-3A3-3A10-4A9-4A-4A3(10-4A9-9A)10-17A-30A3-28A5-26A7-24A9-22A11-21A11-11A288-13A5-27A5-16A9-2A5-2A10-4A9-3A3-3A10-4A9-4A-4A3(10-4A9-9A)10-17A-30A3-28A5-26A7-24A9-22A11-11A320-13A5-27A5-16A9C2A5-2A10B4A9C3A3-3A10B4A9C4A-4A3(10B4A9C9A)10B17A-30A3-28A5-26A7-24A9-12A352-13A5-27A5-16A9-2A5-2A10-4A9-3A3-3A10-4A9-4A-4A3(10-4A9-9A)10-17A-30A3-28A5-26A7-24A9-12A352-
