model
size = 26 10 22, scale = 0.05, origin = -y
material 
  colors = A:#CF0 B:#F60 C:#EEE D:#111
voxels
---------AAAA------------- ----------AA-------------- -------------------------- -------------------------- -------------------------- -------------------------- -------------------------- -------------------------- -------------------------- -------------------------- 
------AAAAAAAAAABB-------- -------AAAAAAAA----------- --------AAAAAA------------ ----------AA-------------- -------------------------- -------------------------- -------------------------- -------------------------- -------------------------- -------------------------- 
-----AAAAAAAAAAAABB------- ------AAAAAAAAAA---------- ------AAAAAAAAAA---------- --------AAAAAA------------ ---------AAAA------------- -------------------------- -------------------------- -------------------------- -------------------------- -------------------------- 
----AAAAAAAAAAAAAABBB----- ----AAAAAAAAAAAAAA-------- -----AAAAAAAAAAAA--------- ------AAAAAAAAAA---------- -------AAAAAAAA----------- ---------AAAA------------- -------------------------- -------------------------- -------------------------- -------------------------- 
---AAAAAAAAAAAAAAAABBB---- ---AAAAAAAAAAAAAAAA------- ----AAAAAAAAAAAAAA-------- -----AAAAAAAAAAAA--------- ------AAAAAAAAAA---------- -------AAAAAAAA----------- ---------AAAA------------- -------------------------- -------------------------- -------------------------- 
--AAAAAA------AAAAAABBB--- ---AAAAA--AAAAAAAAA------- ---AAAAAAAAAAAAAAAA------- ----AAAAAAAAAAAAAA-------- -----AAAAAAAAAAAA--------- ------AAAAAAAAAA---------- --------AAAAAA------------ ----------AA-------------- -------------------------- -------------------------- 
-AAAAAA--------AAAAAABBB-- --AAAAA-------AAAAAA------ --AAAAAA--AAAAAAAAAA------ ---AAAAAAAAAAAAAAAA------- ----AAAAAAAAAAAAAA-------- -----AAAAAAAAAAAA--------- ------AAAAAAAAAA---------- --------AAAAAA------------ -------------------------- -------------------------- 
-AAAAAA--------AAAAAABBBB- -AAAAAA-------AAAAAAA----- --AAAAAA--AAAAAAAAAA------ ---AAAAAAAAAAAAAAAA------- ---AAAAAAAAAAAAAAAA------- ----AAAAAAAAAAAAAAC------- ------AAAAAAAAAAAAC------- -------AAAAAAAA----------- ----------AA-------------- -------------------------- 
-AAAAA----------AAAAABBBBB -AAAAA----------AAAAA----- -AAAAA----------AAAAA----- --AAAA----------AAAA------ ---AAA----------AAA------- ----AA----------AACD------ -----AAAAAAAAAAAAAC------- ------AAAAAAAAAA---------- ---------AAAA------------- -------------------------- 
AAAAAA----------AAAAABBBBB -AAAAA----------AAAAA----- -AAAAA----------AAAAA----- --AAAA----------AAAA------ --AAAA----------AAAA------ ---AAA----------AAC------- ----AAAAAAAAAAAAAAC------- ------AAAAAAAAAA---------- --------AAAAAA------------ -------------------------- 
AAAAAA----------AAAAABBBBB AAAAAA----------AAAAA----- -AAAAA----------AAAAA----- -AAAAA----------AAAAA----- --AAAA----------AAAA------ ---AAA----------AAA------- ----AAAAAAAAAAAAAA-------- -----AAAAAAAAAAAA--------- -------AAAAAAAA----------- ----------AA-------------- 
AAAAAA----------AAAAABBBBB AAAAAA----------AAAAA----- -AAAAA----------AAAAA----- -AAAAA----------AAAAA----- --AAAA----------AAAA------ ---AAA----------AAA------- ----AAAAAAAAAAAAAA-------- -----AAAAAAAAAAAA--------- -------AAAAAAAA----------- ----------AA-------------- 
AAAAAA----------AAAAABBBBB -AAAAA----------AAAAA----- -AAAAA----------AAAAA----- --AAAA----------AAAA------ --AAAA----------AAAA------ ---AAA----------AAC------- ----AAAAAAAAAAAAAAC------- ------AAAAAAAAAA---------- --------AAAAAA------------ -------------------------- 
-AAAAA----------AAAAABBBBB -AAAAA----------AAAAA----- -AAAAA----------AAAAA----- --AAAA----------AAAA------ ---AAA----------AAA------- ----AA----------AACD------ -----AAAAAAAAAAAAAC------- ------AAAAAAAAAA---------- ---------AAAA------------- -------------------------- 
-AAAAAA--------AAAAAABBBB- -AAAAAAA------AAAAAAA----- --AAAAAAAAAAAAAAAAAA------ ---AAAAAAAAAAAAAAAA------- ---AAAAAAAAAAAAAAAA------- ----AAAAAAAAAAAAAAC------- ------AAAAAAAAAAAAC------- -------AAAAAAAA----------- ----------AA-------------- -------------------------- 
-AAAAAA--------AAAAAABBB-- --AAAAAA------AAAAAA------ --AAAAAAAAAAAAAAAAAA------ ---AAAAAAAAAAAAAAAA------- ----AAAAAAAAAAAAAA-------- -----AAAAAAAAAAAA--------- ------AAAAAAAAAA---------- --------AAAAAA------------ -------------------------- -------------------------- 
--AAAAAA------AAAAAABBB--- ---AAAAAAAAAAAAAAAA------- ---AAAAAAAAAAAAAAAA------- ----AAAAAAAAAAAAAA-------- -----AAAAAAAAAAAA--------- ------AAAAAAAAAA---------- --------AAAAAA------------ ----------AA-------------- -------------------------- -------------------------- 
---AAAAAAAAAAAAAAAABBB---- ---AAAAAAAAAAAAAAAA------- ----AAAAAAAAAAAAAA-------- -----AAAAAAAAAAAA--------- ------AAAAAAAAAA---------- -------AAAAAAAA----------- ---------AAAA------------- -------------------------- -------------------------- -------------------------- 
----AAAAAAAAAAAAAABBB----- ----AAAAAAAAAAAAAA-------- -----AAAAAAAAAAAA--------- ------AAAAAAAAAA---------- -------AAAAAAAA----------- ---------AAAA------------- -------------------------- -------------------------- -------------------------- -------------------------- 
-----AAAAAAAAAAAABB------- ------AAAAAAAAAA---------- ------AAAAAAAAAA---------- --------AAAAAA------------ ---------AAAA------------- -------------------------- -------------------------- -------------------------- -------------------------- -------------------------- 
------AAAAAAAAAABB-------- -------AAAAAAAA----------- --------AAAAAA------------ ----------AA-------------- -------------------------- -------------------------- -------------------------- -------------------------- -------------------------- -------------------------- 
---------AAAA------------- ----------AA-------------- -------------------------- -------------------------- -------------------------- -------------------------- -------------------------- -------------------------- -------------------------- -------------------------- 
