model
size = 18 22 18, scale = 0.05, origin = -y
material 
  colors = A:#0B0 B:#FF0 C:#BBB D:#006 E:#EEE
voxels
------------------ --------AA-------- --------AA-------- --------AA-------- --------AA-------- --------AA-------- --------AA-------- --------AA-------- --------AA-------- --------AA-------- --------AA-------- --------AA-------- --------AA-------- --------AA-------- --------AA-------- --------AA-------- --------AA-------- --------AA-------- --------AA-------- --------AA-------- ------CCCCCC------ ------CCCCCC------ 
------------------ ------AAAAAA------ ------AAAAAA------ ------AAAAAA------ ------AAAAAA------ ------AAAAAA------ ------AAAAAA------ ------AAAAAA------ ------AAAAAA------ ------AAAAAA------ ------AAAAAA------ ------AAAAAA------ ------AAAAAA------ ------AAAAAA------ ------AAAAAA------ ------AAAAAA------ ------AAAAAA------ ------AAAAAA------ ------AAAAAA------ ------AAAAAA------ -----CDDDDDDC----- -----CCCCCCCC----- 
------AAAAA------- -----AAAAAAAA----- -----AAAAAAAA----- -----AAAAAAAA----- -----AAAAAAAA----- -----AAAAAAAA----- -----AAAAAAAA----- -----AAAAAAAA----- -----AAAAAAAA----- -----AAAAAAAA----- -----AAAAAAAA----- -----AAAAAAAA----- -----AAAAAAAA----- -----AAAAAAAA----- -----AAAAAAAA----- -----AAAAAAAA----- -----AAAAAAAA----- -----AAAAAAAA----- -----ABBBBBBA----- -----ABBBBBBA----- ----CDBBEBBBDC---- ----CC------CC---- 
-----AA---AA------ ----AAAAAAAAAA---- ----AAAAAAAAAA---- ----AAAAAAAAAA---- ----AAAAAAAAAA---- ----AAAAAAAAAA---- ----AAAAAAAAAA---- ----AAAAAAAAAA---- ----AAAAAAAAAA---- ----AAAAAAAAAA---- ----AAAAAAAAAA---- ----AAAAAAAAAA---- ----AAAAAAAAAA---- ----AAAAAAAAAA---- ----AAAAAAAAAA---- ----AAAAAAAAAA---- ----AAAAAAAAAA---- ----AAAAAAAAAA---- ----ABBBBBBBBA---- ----AB-------A---- ---CDBBBBBBBBDC--- ---CC--------CC--- 
----AA-----AA----- ---AAAAAAAAAAAA--- ---AAAAAAAAAAAA--- ---AAAAAAAAAAAA--- ---AAAAAAAAAAAA--- ---AAAAAAAAAAAA--- ---AAAAAAAAAAAA--- ---AAAAAAAAAAAA--- ---AAAAAAAAAAAA--- ---AAAAAAAAAAAA--- ---AAAAAAAAAAAA--- ---AAAAAAAAAAAA--- ---AAAAAAAAAAAA--- ---AAAAAAAAAAAA--- ---AAAAAAAAAAAA--- ---AAAAAAAAAAAA--- ---AAAAAAAAAAAA--- ---AAAAAAAAAAAA--- ---ABBBBBBBBBBA--- ---ABB-BBBBB--A--- --CDBBBEBBBBBBDC-- --CC----------CC-- 
---AA-------AA---- --AAAAAAAAAAAAAA-- --AAAAAAAAAAAAAA-- --AAAAAAAAAAAAAA-- --AAAAAAAAAAAAAA-- --AAAAAAAAAAAAAA-- --AAAAAAAAAAAAAA-- --AAAAAAAAAAAAAA-- --AAAAAAAAAAAAAA-- --AAAAAAAAAAAAAA-- --AAAAAAAAAAAAAA-- --AAAAAAAAAAAAAA-- --AAAAAAAAAAAAAA-- --AAAAAAAAAAAAAA-- --AAAAAAAAAAAAAA-- --AAAAAAAAAAAAAA-- --AAAAAAAAAAAAAA-- --AAAAAAAAAAAAAA-- --ABBBBBBBBBBBBA-- --ABB-BBBBBBB--A-- -CDBBEBBEBBEBBBDC- -CC------------CC- 
--AA---------AA--- -AAAAAAAAAAAAAAAA- -AAAAAAAAAAAAAAAA- -AAAAAAAAAAAAAAAA- -AAAAAAAAAAAAAAAA- -AAAAAAAAAAAAAAAA- -AAAAAAAAAAAAAAAA- -AAAAAAAAAAAAAAAA- -AAAAAAAAAAAAAAAA- -AAAAAAAAAAAAAAAA- -AAAAAAAAAAAAAAAA- -AAAAAAAAAAAAAAAA- -AAAAAAAAAAAAAAAA- -AAAAAAAAAAAAAAAA- -AAAAAAAAAAAAAAAA- -AAAAAAAAAAAAAAAA- -AAAAAAAAAAAAAAAA- -AAAAAAAAAAAAAAAA- -ABBBBBBBBBBBBBBA- -ABB-BBBBBBBBB-BA- CDBBBBBBBBBBBBBBDC CC--------------CC 
--A-----------AA-- -AAAAAAAAAAAAAAAA- -AAAAAAAAAAAAAAAA- -AAAAAAAAAAAAAAAA- -AAAAAAAAAAAAAAAA- -AAAAAAAAAAAAAAAA- -AAAAAAAAAAAAAAAA- -AAAAAAAAAAAAAAAA- -AAAAAAAAAAAAAAAA- -AAAAAAAAAAAAAAAA- -AAAAAAAAAAAAAAAA- -AAAAAAAAAAAAAAAA- -AAAAAAAAAAAAAAAA- -AAAAAAAAAAAAAAAA- -AAAAAAAAAAAAAAAA- -AAAAAAAAAAAAAAAA- -AAAAAAAAAAAAAAAA- -AAAAAAAAAAAAAAAA- -ABBBBBBBBBBBBBBA- -ABBBBBBBBBBBBBBA- CDBBEBEEBEBBBBBBDC CC--------------CC 
--A------------A-- AAAAAAAAAAAAAAAAAA AAAAAAAAAAAAAAAAAA AAAAAAAAAAAAAAAAAA AAAAAAAAAAAAAAAAAA AAAAAAAAAAAAAAAAAA AAAAAAAAAAAAAAAAAA AAAAAAAAAAAAAAAAAA AAAAAAAAAAAAAAAAAA AAAAAAAAAAAAAAAAAA AAAAAAAAAAAAAAAAAA AAAAAAAAAAAAAAAAAA AAAAAAAAAAAAAAAAAA AAAAAAAAAAAAAAAAAA AAAAAAAAAAAAAAAAAA AAAAAAAAAAAAAAAAAA AAAAAAAAAAAAAAAAAA AAAAAAAAAAAAAAAAAA AABBBBBBBBBBBBBBAA AABBBBBBBBBBBBBBAA CDBBBBBBBBBBBBBBDC CC--------------CC 
--A------------A-- AAAAAAAAAAAAAAAAAA AAAAAAAAAAAAAAAAAA AAAAAAAAAAAAAAAAAA AAAAAAAAAAAAAAAAAA AAAAAAAAAAAAAAAAAA AAAAAAAAAAAAAAAAAA AAAAAAAAAAAAAAAAAA AAAAAAAAAAAAAAAAAA AAAAAAAAAAAAAAAAAA AAAAAAAAAAAAAAAAAA AAAAAAAAAAAAAAAAAA AAAAAAAAAAAAAAAAAA AAAAAAAAAAAAAAAAAA AAAAAAAAAAAAAAAAAA AAAAAAAAAAAAAAAAAA AAAAAAAAAAAAAAAAAA AAAAAAAAAAAAAAAAAA AABBBBBBBBBBBBBBAA AABBBBBBB-BBBBBBAA CDBBBBBBEBEBBBEBDC CC--------------CC 
--AA-----------A-- -AAAAAAAAAAAAAAAA- -AAAAAAAAAAAAAAAA- -AAAAAAAAAAAAAAAA- -AAAAAAAAAAAAAAAA- -AAAAAAAAAAAAAAAA- -AAAAAAAAAAAAAAAA- -AAAAAAAAAAAAAAAA- -AAAAAAAAAAAAAAAA- -AAAAAAAAAAAAAAAA- -AAAAAAAAAAAAAAAA- -AAAAAAAAAAAAAAAA- -AAAAAAAAAAAAAAAA- -AAAAAAAAAAAAAAAA- -AAAAAAAAAAAAAAAA- -AAAAAAAAAAAAAAAA- -AAAAAAAAAAAAAAAA- -AAAAAAAAAAAAAAAA- -ABBBBBBBBBBBBBBA- -ABBBBBBBBBBBBBBA- CDBBBEBBBBBEBBBBDC CC--------------CC 
---AA---------AA-- -AAAAAAAAAAAAAAAA- -AAAAAAAAAAAAAAAA- -AAAAAAAAAAAAAAAA- -AAAAAAAAAAAAAAAA- -AAAAAAAAAAAAAAAA- -AAAAAAAAAAAAAAAA- -AAAAAAAAAAAAAAAA- -AAAAAAAAAAAAAAAA- -AAAAAAAAAAAAAAAA- -AAAAAAAAAAAAAAAA- -AAAAAAAAAAAAAAAA- -AAAAAAAAAAAAAAAA- -AAAAAAAAAAAAAAAA- -AAAAAAAAAAAAAAAA- -AAAAAAAAAAAAAAAA- -AAAAAAAAAAAAAAAA- -AAAAAAAAAAAAAAAA- -ABBBBBBBBBBBBBBA- -ABBBBBBBBBBBBBBA- CDBBEBEBBEBBBBBBDC CC--------------CC 
----AA-------AA--- --AAAAAAAAAAAAAA-- --AAAAAAAAAAAAAA-- --AAAAAAAAAAAAAA-- --AAAAAAAAAAAAAA-- --AAAAAAAAAAAAAA-- --AAAAAAAAAAAAAA-- --AAAAAAAAAAAAAA-- --AAAAAAAAAAAAAA-- --AAAAAAAAAAAAAA-- --AAAAAAAAAAAAAA-- --AAAAAAAAAAAAAA-- --AAAAAAAAAAAAAA-- --AAAAAAAAAAAAAA-- --AAAAAAAAAAAAAA-- --AAAAAAAAAAAAAA-- --AAAAAAAAAAAAAA-- --AAAAAAAAAAAAAA-- --ABBBBBBBBBBBBA-- --ABBBBBBBBBBBBA-- -CDBBBBBBBBBBBBDC- -CC------------CC- 
-----AA-----AA---- ---AAAAAAAAAAAA--- ---AAAAAAAAAAAA--- ---AAAAAAAAAAAA--- ---AAAAAAAAAAAA--- ---AAAAAAAAAAAA--- ---AAAAAAAAAAAA--- ---AAAAAAAAAAAA--- ---AAAAAAAAAAAA--- ---AAAAAAAAAAAA--- ---AAAAAAAAAAAA--- ---AAAAAAAAAAAA--- ---AAAAAAAAAAAA--- ---AAAAAAAAAAAA--- ---AAAAAAAAAAAA--- ---AAAAAAAAAAAA--- ---AAAAAAAAAAAA--- ---AAAAAAAAAAAA--- ---ABBBBBBBBBBA--- ---ABBBBBBBBBBA--- --CDBBBBBBBBBBDC-- --CC----------CC-- 
------AA--AAA----- ----AAAAAAAAAA---- ----AAAAAAAAAA---- ----AAAAAAAAAA---- ----AAAAAAAAAA---- ----AAAAAAAAAA---- ----AAAAAAAAAA---- ----AAAAAAAAAA---- ----AAAAAAAAAA---- ----AAAAAAAAAA---- ----AAAAAAAAAA---- ----AAAAAAAAAA---- ----AAAAAAAAAA---- ----AAAAAAAAAA---- ----AAAAAAAAAA---- ----AAAAAAAAAA---- ----AAAAAAAAAA---- ----AAAAAAAAAA---- ----ABBBBBBBBA---- ----ABBBBBBBBA---- ---CDBBBEBBEBDC--- ---CC--------CC--- 
-------AAAA------- -----AAAAAAAA----- -----AAAAAAAA----- -----AAAAAAAA----- -----AAAAAAAA----- -----AAAAAAAA----- -----AAAAAAAA----- -----AAAAAAAA----- -----AAAAAAAA----- -----AAAAAAAA----- -----AAAAAAAA----- -----AAAAAAAA----- -----AAAAAAAA----- -----AAAAAAAA----- -----AAAAAAAA----- -----AAAAAAAA----- -----AAAAAAAA----- -----AAAAAAAA----- -----ABBBBBBA----- -----ABBBBBBA----- ----CDBBBBBBDC---- ----CC------CC---- 
------------------ ------AAAAAA------ ------AAAAAA------ ------AAAAAA------ ------AAAAAA------ ------AAAAAA------ ------AAAAAA------ ------AAAAAA------ ------AAAAAA------ ------AAAAAA------ ------AAAAAA------ ------AAAAAA------ ------AAAAAA------ ------AAAAAA------ ------AAAAAA------ ------AAAAAA------ ------AAAAAA------ ------AAAAAA------ ------AAAAAA------ ------AAAAAA------ -----CDDDDDDC----- -----CCCCCCCC----- 
------------------ --------AA-------- --------AA-------- --------AA-------- --------AA-------- --------AA-------- --------AA-------- --------AA-------- --------AA-------- --------AA-------- --------AA-------- --------AA-------- --------AA-------- --------AA-------- --------AA-------- --------AA-------- --------AA-------- --------AA-------- --------AA-------- --------AA-------- ------CCCCCC------ ------CCCCCC------ 
