model
size = 18 22 18, scale = 0.05, origin = -y
material 
  colors = A:#006 B:#FF0 C:#BBB D:#EEE
voxels
------------------ --------AA-------- --------AA-------- --------AA-------- --------AA-------- --------AA-------- --------AA-------- --------AA-------- --------AA-------- --------AA-------- --------AA-------- --------AA-------- --------AA-------- --------AA-------- --------AA-------- --------AA-------- --------AA-------- --------AA-------- --------AA-------- --------AA-------- ------CCCCCC------ ------CCCCCC------ 
------------------ ------AAAAAA------ ------AAAAAA------ ------AAAAAA------ ------AAAAAA------ ------AAAAAA------ ------AAAAAA------ ------AAAAAA------ ------AAAAAA------ ------AAAAAA------ ------AAAAAA------ ------AAAAAA------ ------AAAAAA------ ------AAAAAA------ ------AAAAAA------ ------AAAAAA------ ------AAAAAA------ ------AAAAAA------ ------AAAAAA------ ------AAAAAA------ -----CAAAAAAC----- -----CCCCCCCC----- 
------AAAAA------- -----AAAAAAAA----- -----AAAAAAAA----- -----AAAAAAAA----- -----AAAAAAAA----- -----AAAAAAAA----- -----AAAAAAAA----- -----AAAAAAAA----- -----AAAAAAAA----- -----AAAAAAAA----- -----AAAAAAAA----- -----AAAAAAAA----- -----AAAAAAAA----- -----AAAAAAAA----- -----AAAAAAAA----- -----AAAAAAAA----- -----AAAAAAAA----- -----AAAAAAAA----- -----ABBBBBBA----- -----ABBBBBBA----- ----CABBDBBBAC---- ----CC------CC---- 
-----AA---AA------ ----AAAAAAAAAA---- ----AAAAAAAAAA---- ----AAAAAAAAAA---- ----AAAAAAAAAA---- ----AAAAAAAAAA---- ----AAAAAAAAAA---- ----AAAAAAAAAA---- ----AAAAAAAAAA---- ----AAAAAAAAAA---- ----AAAAAAAAAA---- ----AAAAAAAAAA---- ----AAAAAAAAAA---- ----AAAAAAAAAA---- ----AAAAAAAAAA---- ----AAAAAAAAAA---- ----AAAAAAAAAA---- ----AAAAAAAAAA---- ----ABBBBBBBBA---- ----AB-------A---- ---CABBBBBBBBAC--- ---CC--------CC--- 
----AA-----AA----- ---AAAAAAAAAAAA--- ---AAAAAAAAAAAA--- ---AAAAAAAAAAAA--- ---AAAAAAAAAAAA--- ---AAAAAAAAAAAA--- ---AAAAAAAAAAAA--- ---AAAAAAAAAAAA--- ---AAAAAAAAAAAA--- ---AAAAAAAAAAAA--- ---AAAAAAAAAAAA--- ---AAAAAAAAAAAA--- ---AAAAAAAAAAAA--- ---AAAAAAAAAAAA--- ---AAAAAAAAAAAA--- ---AAAAAAAAAAAA--- ---AAAAAAAAAAAA--- ---AAAAAAAAAAAA--- ---ABBBBBBBBBBA--- ---ABB-BBBBB--A--- --CABBBDBBBBBBAC-- --CC----------CC-- 
---AA-------AA---- --AAAAAAAAAAAAAA-- --AAAAAAAAAAAAAA-- --AAAAAAAAAAAAAA-- --AAAAAAAAAAAAAA-- --AAAAAAAAAAAAAA-- --AAAAAAAAAAAAAA-- --AAAAAAAAAAAAAA-- --AAAAAAAAAAAAAA-- --AAAAAAAAAAAAAA-- --AAAAAAAAAAAAAA-- --AAAAAAAAAAAAAA-- --AAAAAAAAAAAAAA-- --AAAAAAAAAAAAAA-- --AAAAAAAAAAAAAA-- --AAAAAAAAAAAAAA-- --AAAAAAAAAAAAAA-- --AAAAAAAAAAAAAA-- --ABBBBBBBBBBBBA-- --ABB-BBBBBBB--A-- -CABBDBBDBBDBBBAC- -CC------------CC- 
--AA---------AA--- -AAAAAAAAAAAAAAAA- -AAAAAAAAAAAAAAAA- -AAAAAAAAAAAAAAAA- -AAAAAAAAAAAAAAAA- -AAAAAAAAAAAAAAAA- -AAAAAAAAAAAAAAAA- -AAAAAAAAAAAAAAAA- -AAAAAAAAAAAAAAAA- -AAAAAAAAAAAAAAAA- -AAAAAAAAAAAAAAAA- -AAAAAAAAAAAAAAAA- -AAAAAAAAAAAAAAAA- -AAAAAAAAAAAAAAAA- -AAAAAAAAAAAAAAAA- -AAAAAAAAAAAAAAAA- -AAAAAAAAAAAAAAAA- -AAAAAAAAAAAAAAAA- -ABBBBBBBBBBBBBBA- -ABB-BBBBBBBBB-BA- CABBBBBBBBBBBBBBAC CC--------------CC 
--A-----------AA-- -AAAAAAAAAAAAAAAA- -AAAAAAAAAAAAAAAA- -AAAAAAAAAAAAAAAA- -AAAAAAAAAAAAAAAA- -AAAAAAAAAAAAAAAA- -AAAAAAAAAAAAAAAA- -AAAAAAAAAAAAAAAA- -AAAAAAAAAAAAAAAA- -AAAAAAAAAAAAAAAA- -AAAAAAAAAAAAAAAA- -AAAAAAAAAAAAAAAA- -AAAAAAAAAAAAAAAA- -AAAAAAAAAAAAAAAA- -AAAAAAAAAAAAAAAA- -AAAAAAAAAAAAAAAA- -AAAAAAAAAAAAAAAA- -AAAAAAAAAAAAAAAA- -ABBBBBBBBBBBBBBA- -ABBBBBBBBBBBBBBA- CABBDBDDBDBBBBBBAC CC--------------CC 
--A------------A-- AAAAAAAAAAAAAAAAAA AAAAAAAAAAAAAAAAAA AAAAAAAAAAAAAAAAAA AAAAAAAAAAAAAAAAAA AAAAAAAAAAAAAAAAAA AAAAAAAAAAAAAAAAAA AAAAAAAAAAAAAAAAAA AAAAAAAAAAAAAAAAAA AAAAAAAAAAAAAAAAAA AAAAAAAAAAAAAAAAAA AAAAAAAAAAAAAAAAAA AAAAAAAAAAAAAAAAAA AAAAAAAAAAAAAAAAAA AAAAAAAAAAAAAAAAAA AAAAAAAAAAAAAAAAAA AAAAAAAAAAAAAAAAAA AAAAAAAAAAAAAAAAAA AABBBBBBBBBBBBBBAA AABBBBBBBBBBBBBBAA CABBBBBBBBBBBBBBAC CC--------------CC 
--A------------A-- AAAAAAAAAAAAAAAAAA AAAAAAAAAAAAAAAAAA AAAAAAAAAAAAAAAAAA AAAAAAAAAAAAAAAAAA AAAAAAAAAAAAAAAAAA AAAAAAAAAAAAAAAAAA AAAAAAAAAAAAAAAAAA AAAAAAAAAAAAAAAAAA AAAAAAAAAAAAAAAAAA AAAAAAAAAAAAAAAAAA AAAAAAAAAAAAAAAAAA AAAAAAAAAAAAAAAAAA AAAAAAAAAAAAAAAAAA AAAAAAAAAAAAAAAAAA AAAAAAAAAAAAAAAAAA AAAAAAAAAAAAAAAAAA AAAAAAAAAAAAAAAAAA AABBBBBBBBBBBBBBAA AABBBBBBB-BBBBBBAA CABBBBBBDBDBBBDBAC CC--------------CC 
--AA-----------A-- -AAAAAAAAAAAAAAAA- -AAAAAAAAAAAAAAAA- -AAAAAAAAAAAAAAAA- -AAAAAAAAAAAAAAAA- -AAAAAAAAAAAAAAAA- -AAAAAAAAAAAAAAAA- -AAAAAAAAAAAAAAAA- -AAAAAAAAAAAAAAAA- -AAAAAAAAAAAAAAAA- -AAAAAAAAAAAAAAAA- -AAAAAAAAAAAAAAAA- -AAAAAAAAAAAAAAAA- -AAAAAAAAAAAAAAAA- -AAAAAAAAAAAAAAAA- -AAAAAAAAAAAAAAAA- -AAAAAAAAAAAAAAAA- -AAAAAAAAAAAAAAAA- -ABBBBBBBBBBBBBBA- -ABBBBBBBBBBBBBBA- CABBBDBBBBBDBBBBAC CC--------------CC 
---AA---------AA-- -AAAAAAAAAAAAAAAA- -AAAAAAAAAAAAAAAA- -AAAAAAAAAAAAAAAA- -AAAAAAAAAAAAAAAA- -AAAAAAAAAAAAAAAA- -AAAAAAAAAAAAAAAA- -AAAAAAAAAAAAAAAA- -AAAAAAAAAAAAAAAA- -AAAAAAAAAAAAAAAA- -AAAAAAAAAAAAAAAA- -AAAAAAAAAAAAAAAA- -AAAAAAAAAAAAAAAA- -AAAAAAAAAAAAAAAA- -AAAAAAAAAAAAAAAA- -AAAAAAAAAAAAAAAA- -AAAAAAAAAAAAAAAA- -AAAAAAAAAAAAAAAA- -ABBBBBBBBBBBBBBA- -ABBBBBBBBBBBBBBA- CABBDBDBBDBBBBBBAC CC--------------CC 
----AA-------AA--- --AAAAAAAAAAAAAA-- --AAAAAAAAAAAAAA-- --AAAAAAAAAAAAAA-- --AAAAAAAAAAAAAA-- --AAAAAAAAAAAAAA-- --AAAAAAAAAAAAAA-- --AAAAAAAAAAAAAA-- --AAAAAAAAAAAAAA-- --AAAAAAAAAAAAAA-- --AAAAAAAAAAAAAA-- --AAAAAAAAAAAAAA-- --AAAAAAAAAAAAAA-- --AAAAAAAAAAAAAA-- --AAAAAAAAAAAAAA-- --AAAAAAAAAAAAAA-- --AAAAAAAAAAAAAA-- --AAAAAAAAAAAAAA-- --ABBBBBBBBBBBBA-- --ABBBBBBBBBBBBA-- -CABBBBBBBBBBBBAC- -CC------------CC- 
-----AA-----AA---- ---AAAAAAAAAAAA--- ---AAAAAAAAAAAA--- ---AAAAAAAAAAAA--- ---AAAAAAAAAAAA--- ---AAAAAAAAAAAA--- ---AAAAAAAAAAAA--- ---AAAAAAAAAAAA--- ---AAAAAAAAAAAA--- ---AAAAAAAAAAAA--- ---AAAAAAAAAAAA--- ---AAAAAAAAAAAA--- ---AAAAAAAAAAAA--- ---AAAAAAAAAAAA--- ---AAAAAAAAAAAA--- ---AAAAAAAAAAAA--- ---AAAAAAAAAAAA--- ---AAAAAAAAAAAA--- ---ABBBBBBBBBBA--- ---ABBBBBBBBBBA--- --CABBBBBBBBBBAC-- --CC----------CC-- 
------AA--AAA----- ----AAAAAAAAAA---- ----AAAAAAAAAA---- ----AAAAAAAAAA---- ----AAAAAAAAAA---- ----AAAAAAAAAA---- ----AAAAAAAAAA---- ----AAAAAAAAAA---- ----AAAAAAAAAA---- ----AAAAAAAAAA---- ----AAAAAAAAAA---- ----AAAAAAAAAA---- ----AAAAAAAAAA---- ----AAAAAAAAAA---- ----AAAAAAAAAA---- ----AAAAAAAAAA---- ----AAAAAAAAAA---- ----AAAAAAAAAA---- ----ABBBBBBBBA---- ----ABBBBBBBBA---- ---CABBBDBBDBAC--- ---CC--------CC--- 
-------AAAA------- -----AAAAAAAA----- -----AAAAAAAA----- -----AAAAAAAA----- -----AAAAAAAA----- -----AAAAAAAA----- -----AAAAAAAA----- -----AAAAAAAA----- -----AAAAAAAA----- -----AAAAAAAA----- -----AAAAAAAA----- -----AAAAAAAA----- -----AAAAAAAA----- -----AAAAAAAA----- -----AAAAAAAA----- -----AAAAAAAA----- -----AAAAAAAA----- -----AAAAAAAA----- -----ABBBBBBA----- -----ABBBBBBA----- ----CABBBBBBAC---- ----CC------CC---- 
------------------ ------AAAAAA------ ------AAAAAA------ ------AAAAAA------ ------AAAAAA------ ------AAAAAA------ ------AAAAAA------ ------AAAAAA------ ------AAAAAA------ ------AAAAAA------ ------AAAAAA------ ------AAAAAA------ ------AAAAAA------ ------AAAAAA------ ------AAAAAA------ ------AAAAAA------ ------AAAAAA------ ------AAAAAA------ ------AAAAAA------ ------AAAAAA------ -----CAAAAAAC----- -----CCCCCCCC----- 
------------------ --------AA-------- --------AA-------- --------AA-------- --------AA-------- --------AA-------- --------AA-------- --------AA-------- --------AA-------- --------AA-------- --------AA-------- --------AA-------- --------AA-------- --------AA-------- --------AA-------- --------AA-------- --------AA-------- --------AA-------- --------AA-------- --------AA-------- ------CCCCCC------ ------CCCCCC------ 
