model
size = 15 8 32, scale = 0.05, origin = -y
material 
  colors = A:#FFAB70 B:#8F8F8F C:#EFEFEF D:#C6FFFA E:#BFBFBF F:#9F9F9F G:#C6FFE2 H:#C6FFCA
voxels
92-5BF3-F5-5BD3-H94-DC4AB2-BAB3-DC4AB3-AB92-BA2C3A3B3AB-BA2C3AB3-2AB91-B2AB2CAB2DCB2AFB2A-2CAB3-B2AD90-B2ABA2C2BACBCA2B2A-A2CB3-BCAB90-BCA6B2AB2C2BCA8-B2CB90-BACB2AD2BCABACDBHC-3AB3-BACD90-B2ABC2A2BACB2ADB2A-C2AB3-B2AD91-F3ACA2B2ABCABDC3ACAB3-BCAB91-FC3ACDB2ABACF-DC3ACD3-BACD92-F3BDEB2A2BDF2-D3B2D3-2B2D96-FCG116-2E-CE115-E3-G114-G5-C97-E7-G110-E9-C109-G9-G108-E11-E107-C11-C92-D11-D107-F11-D107-D11-E107-E11-D92-D11-E107-D11-D107-D11-C108-C2(9-D109-D)9-C95-ED5-DC84-DED11-D3-D95-
