model
size = 15 8 32, scale = 0.05, origin = -y
material 
  colors = A:#FCD200 B:#FF8A36 C:#EFEFEF D:#FC6900 E:#FFE770 F:#FFDE36 G:#FF9B53 H:#FFD91A I:#FFE253
voxels
92-5BG3-B5-5BF3-F94-GC4AG2-BAB3-FE4AB3-AB92-BA2C3ABGB3AB-BA2CE2AB3-2AB91-B2AD2CABG2ED2AGB2A-2CEB3-D2AG90-B2ADA2CGBAEDCA2BEA-AECG3-DCAB90-GCA5DB2AD2CBGCE8-D2CE90-BACD2ACBGEADACGBAC-2ACB3-DACF90-B2ADC2A2BACD2A2BAE-C2AB3-D2AE90-GC3ACA2B2ADCABFC2AECEB3-DCAB91-GC3ACGBEADACG-FC2AECF3-DACF92-G3B2G2BEDB2G2-F3B2F3-DB2F96-HCF116-HF-FH115-C3-C114-F5-A97-A7-E110-H9-A109-E9-E108-A11-A107-E11-H92-H11-H107-C11-F107-A11-C107-A11-I92-A11-I107-C11-A107-F11-I108-F9-A109-A9-C109-E9-F95-CA5-AC84-A2F11-H3-E95-
