model
size = 15 8 32, scale = 0.05, origin = -y
material 
  colors = A:#FCD200 B:#EFEFEF C:#DFBA00 D:#FFE770 E:#A68A00 F:#FFDE36 G:#FFD91A H:#FFE253
voxels
92-6C3-C5-5CF3-F94-CB4AC2-CAC3-FDB3AC3-AC92-CA2B3A3C3AC-CA3B2AC3-BAC91-C2AE2BA2C2DB2A2C2A-2BDC3-EBAC90-C2AEA2B2CAD2BA2CBA-ADBC3-E2BC90-CBA5EC2A3B2C2B8-E2BD90-CABE2AB2CD2(AB)2CAB-2ABC3-EABF90-C2AEB2A2CA2B2A2CAB-B2AC3-E2AB90-CB3ABA2C2A2BACFB2AD2BC3-EBAC91-CB3AB2CD2(AB)C-FB2ADBF3-EABF92-2C2B4CD2(BC)2-B2C3B3-EC2B96-GBF116-GB-BG115-B3-B114-F5-A97-A7-D110-G9-A109-D9-D108-A11-A107-D11-B92-G11-G107-B2(11-B107-A)11-H92-A11-H107-B11-A107-F11-H108-F9-A109-A9-B109-D9-F95-BA5-AB84-A2F11-G3-D95-
