model
size = 15 8 32, scale = 0.05, origin = -y
material 
  colors = A:#DFDFDF B:#8F8F8F C:#EFEFEF D:#E2FFE5 E:#BFBFBF F:#9F9F9F G:#CFCFCF
voxels
92-5BF3-F5-5BF3-G94-DC4AB2-BAB3-DC4AB3-AB92-BA2C3A3B3AB-BA2C3AB3-2AB91-B2AB2CABFDCB2AFB2A-2CAB3-B2AD90-B2ABA2C2BACBCA2B2A-A2CB3-BCAB90-BCA6B2AB2C2BCA8-B2CB90-BACB2AD2BCABACDBDC-3AB3-BACD90-B2ABC2A2BACB2ADB2A-C2AB3-B2AD91-F3ACA2B2ABCABDC3ACAG3-BCAB91-FC3ACDB2ABACF-DC2A2CD3-BADG92-F3BDEBGA2BDF2-D3B2D3-2BDG96-FCD116-2E-CE115-E3-D114-D5-C97-E7-D110-E9-C109-D9-D108-E11-E107-C11-C92-D11-D107-F11-D107-D11-E107-E11-D92-D11-E107-D11-D107-D11-C108-C2(9-D109-D)9-C95-ED5-DC84-DED11-D3-D95-
