model
size = 13 3 21, scale = 0.05, origin = -y
material 
  colors = A:#553A2A B:#1C150B C:#5B544A D:#664731
voxels
--------AA--- -------AAAA-- ------------- 
-------AAAA-- ------AAAAAA- ------------- 
--D---AAAAAA- -----AAAAAAAA ------------- 
--A---AAAAAA- -----A-AAAA-A --------BB--- 
--A---AAAAAA- -----A-A--A-A ------------- 
AAA----AAAA-- ------AA--AA- ------------- 
B-C----AAAA-- -------AAAA-- --------BB--- 
B-C-----AA--- -------AAAA-- --------BB--- 
B-C----AAAA-- ------AAAAAA- --------BB--- 
B-C----AAAA-- ------AAAAAA- --------BB--- 
B-C-----AA--- -------AAAA-- --------BB--- 
B-C---------- ------------- --------BB--- 
B-C---------- ------------- --------BB--- 
B-C---------- ------------- --------BB--- 
B-C---------- ------------- --------BB--- 
B-C---------- ------------- --------BB--- 
B-C---------- ------------- --------BB--- 
B-C---------- ------------- --------BB--- 
B-C---------- ------------- --------AAD-- 
BBB---------- ------------- -------DAA--- 
------------- ------------- --------AAD-- 
