model
size = 18 22 18, scale = 0.05, origin = -y
material 
  colors = A:#FF0 B:#BBB C:#EEE
voxels
------------------ --------AA-------- --------AA-------- --------AA-------- --------AA-------- --------AA-------- --------AA-------- --------AA-------- --------AA-------- --------AA-------- --------AA-------- --------AA-------- --------AA-------- --------AA-------- --------AA-------- --------AA-------- --------AA-------- --------AA-------- --------AA-------- --------AA-------- ------BBBBBB------ ------BBBBBB------ 
------------------ ------AAAAAA------ ------AAAAAA------ ------AAAAAA------ ------AAAAAA------ ------AAAAAA------ ------AAAAAA------ ------AAAAAA------ ------AAAAAA------ ------AAAAAA------ ------AAAAAA------ ------AAAAAA------ ------AAAAAA------ ------AAAAAA------ ------AAAAAA------ ------AAAAAA------ ------AAAAAA------ ------AAAAAA------ ------AAAAAA------ ------AAAAAA------ -----BAAAAAAB----- -----BBBBBBBB----- 
------AAAAA------- -----AAAAAAAA----- -----AAAAAAAA----- -----AAAAAAAA----- -----AAAAAAAA----- -----AAAAAAAA----- -----AAAAAAAA----- -----AAAAAAAA----- -----AAAAAAAA----- -----AAAAAAAA----- -----AAAAAAAA----- -----AAAAAAAA----- -----AAAAAAAA----- -----AAAAAAAA----- -----AAAAAAAA----- -----AAAAAAAA----- -----AAAAAAAA----- -----AAAAAAAA----- -----AAAAAAAA----- -----AAAAAAAA----- ----BAAACAAAAB---- ----BB------BB---- 
-----AA---AA------ ----AAAAAAAAAA---- ----AAAAAAAAAA---- ----AAAAAAAAAA---- ----AAAAAAAAAA---- ----AAAAAAAAAA---- ----AAAAAAAAAA---- ----AAAAAAAAAA---- ----AAAAAAAAAA---- ----AAAAAAAAAA---- ----AAAAAAAAAA---- ----AAAAAAAAAA---- ----AAAAAAAAAA---- ----AAAAAAAAAA---- ----AAAAAAAAAA---- ----AAAAAAAAAA---- ----AAAAAAAAAA---- ----AAAAAAAAAA---- ----AAAAAAAAAA---- ----AA-------A---- ---BAAAAAAAAAAB--- ---BB--------BB--- 
----AA-----AA----- ---AAAAAAAAAAAA--- ---AAAAAAAAAAAA--- ---AAAAAAAAAAAA--- ---AAAAAAAAAAAA--- ---AAAAAAAAAAAA--- ---AAAAAAAAAAAA--- ---AAAAAAAAAAAA--- ---AAAAAAAAAAAA--- ---AAAAAAAAAAAA--- ---AAAAAAAAAAAA--- ---AAAAAAAAAAAA--- ---AAAAAAAAAAAA--- ---AAAAAAAAAAAA--- ---AAAAAAAAAAAA--- ---AAAAAAAAAAAA--- ---AAAAAAAAAAAA--- ---AAAAAAAAAAAA--- ---AAAAAAAAAAAA--- ---AAA-AAAAA--A--- --BAAAACAAAAAAAB-- --BB----------BB-- 
---AA-------AA---- --AAAAAAAAAAAAAA-- --AAAAAAAAAAAAAA-- --AAAAAAAAAAAAAA-- --AAAAAAAAAAAAAA-- --AAAAAAAAAAAAAA-- --AAAAAAAAAAAAAA-- --AAAAAAAAAAAAAA-- --AAAAAAAAAAAAAA-- --AAAAAAAAAAAAAA-- --AAAAAAAAAAAAAA-- --AAAAAAAAAAAAAA-- --AAAAAAAAAAAAAA-- --AAAAAAAAAAAAAA-- --AAAAAAAAAAAAAA-- --AAAAAAAAAAAAAA-- --AAAAAAAAAAAAAA-- --AAAAAAAAAAAAAA-- --AAAAAAAAAAAAAA-- --AAA-AAAAAAA--A-- -BAAACAACAACAAAAB- -BB------------BB- 
--AA---------AA--- -AAAAAAAAAAAAAAAA- -AAAAAAAAAAAAAAAA- -AAAAAAAAAAAAAAAA- -AAAAAAAAAAAAAAAA- -AAAAAAAAAAAAAAAA- -AAAAAAAAAAAAAAAA- -AAAAAAAAAAAAAAAA- -AAAAAAAAAAAAAAAA- -AAAAAAAAAAAAAAAA- -AAAAAAAAAAAAAAAA- -AAAAAAAAAAAAAAAA- -AAAAAAAAAAAAAAAA- -AAAAAAAAAAAAAAAA- -AAAAAAAAAAAAAAAA- -AAAAAAAAAAAAAAAA- -AAAAAAAAAAAAAAAA- -AAAAAAAAAAAAAAAA- -AAAAAAAAAAAAAAAA- -AAA-AAAAAAAAA-AA- BAAAAAAAAAAAAAAAAB BB--------------BB 
--A-----------AA-- -AAAAAAAAAAAAAAAA- -AAAAAAAAAAAAAAAA- -AAAAAAAAAAAAAAAA- -AAAAAAAAAAAAAAAA- -AAAAAAAAAAAAAAAA- -AAAAAAAAAAAAAAAA- -AAAAAAAAAAAAAAAA- -AAAAAAAAAAAAAAAA- -AAAAAAAAAAAAAAAA- -AAAAAAAAAAAAAAAA- -AAAAAAAAAAAAAAAA- -AAAAAAAAAAAAAAAA- -AAAAAAAAAAAAAAAA- -AAAAAAAAAAAAAAAA- -AAAAAAAAAAAAAAAA- -AAAAAAAAAAAAAAAA- -AAAAAAAAAAAAAAAA- -AAAAAAAAAAAAAAAA- -AAAAAAAAAAAAAAAA- BAAACACCACAAAAAAAB BB--------------BB 
--A------------A-- AAAAAAAAAAAAAAAAAA AAAAAAAAAAAAAAAAAA AAAAAAAAAAAAAAAAAA AAAAAAAAAAAAAAAAAA AAAAAAAAAAAAAAAAAA AAAAAAAAAAAAAAAAAA AAAAAAAAAAAAAAAAAA AAAAAAAAAAAAAAAAAA AAAAAAAAAAAAAAAAAA AAAAAAAAAAAAAAAAAA AAAAAAAAAAAAAAAAAA AAAAAAAAAAAAAAAAAA AAAAAAAAAAAAAAAAAA AAAAAAAAAAAAAAAAAA AAAAAAAAAAAAAAAAAA AAAAAAAAAAAAAAAAAA AAAAAAAAAAAAAAAAAA AAAAAAAAAAAAAAAAAA AAAAAAAAAAAAAAAAAA BAAAAAAAAAAAAAAAAB BB--------------BB 
--A------------A-- AAAAAAAAAAAAAAAAAA AAAAAAAAAAAAAAAAAA AAAAAAAAAAAAAAAAAA AAAAAAAAAAAAAAAAAA AAAAAAAAAAAAAAAAAA AAAAAAAAAAAAAAAAAA AAAAAAAAAAAAAAAAAA AAAAAAAAAAAAAAAAAA AAAAAAAAAAAAAAAAAA AAAAAAAAAAAAAAAAAA AAAAAAAAAAAAAAAAAA AAAAAAAAAAAAAAAAAA AAAAAAAAAAAAAAAAAA AAAAAAAAAAAAAAAAAA AAAAAAAAAAAAAAAAAA AAAAAAAAAAAAAAAAAA AAAAAAAAAAAAAAAAAA AAAAAAAAAAAAAAAAAA AAAAAAAAA-AAAAAAAA BAAAAAAACACAAACAAB BB--------------BB 
--AA-----------A-- -AAAAAAAAAAAAAAAA- -AAAAAAAAAAAAAAAA- -AAAAAAAAAAAAAAAA- -AAAAAAAAAAAAAAAA- -AAAAAAAAAAAAAAAA- -AAAAAAAAAAAAAAAA- -AAAAAAAAAAAAAAAA- -AAAAAAAAAAAAAAAA- -AAAAAAAAAAAAAAAA- -AAAAAAAAAAAAAAAA- -AAAAAAAAAAAAAAAA- -AAAAAAAAAAAAAAAA- -AAAAAAAAAAAAAAAA- -AAAAAAAAAAAAAAAA- -AAAAAAAAAAAAAAAA- -AAAAAAAAAAAAAAAA- -AAAAAAAAAAAAAAAA- -AAAAAAAAAAAAAAAA- -AAAAAAAAAAAAAAAA- BAAAACAAAAACAAAAAB BB--------------BB 
---AA---------AA-- -AAAAAAAAAAAAAAAA- -AAAAAAAAAAAAAAAA- -AAAAAAAAAAAAAAAA- -AAAAAAAAAAAAAAAA- -AAAAAAAAAAAAAAAA- -AAAAAAAAAAAAAAAA- -AAAAAAAAAAAAAAAA- -AAAAAAAAAAAAAAAA- -AAAAAAAAAAAAAAAA- -AAAAAAAAAAAAAAAA- -AAAAAAAAAAAAAAAA- -AAAAAAAAAAAAAAAA- -AAAAAAAAAAAAAAAA- -AAAAAAAAAAAAAAAA- -AAAAAAAAAAAAAAAA- -AAAAAAAAAAAAAAAA- -AAAAAAAAAAAAAAAA- -AAAAAAAAAAAAAAAA- -AAAAAAAAAAAAAAAA- BAAACACAACAAAAAAAB BB--------------BB 
----AA-------AA--- --AAAAAAAAAAAAAA-- --AAAAAAAAAAAAAA-- --AAAAAAAAAAAAAA-- --AAAAAAAAAAAAAA-- --AAAAAAAAAAAAAA-- --AAAAAAAAAAAAAA-- --AAAAAAAAAAAAAA-- --AAAAAAAAAAAAAA-- --AAAAAAAAAAAAAA-- --AAAAAAAAAAAAAA-- --AAAAAAAAAAAAAA-- --AAAAAAAAAAAAAA-- --AAAAAAAAAAAAAA-- --AAAAAAAAAAAAAA-- --AAAAAAAAAAAAAA-- --AAAAAAAAAAAAAA-- --AAAAAAAAAAAAAA-- --AAAAAAAAAAAAAA-- --AAAAAAAAAAAAAA-- -BAAAAAAAAAAAAAAB- -BB------------BB- 
-----AA-----AA---- ---AAAAAAAAAAAA--- ---AAAAAAAAAAAA--- ---AAAAAAAAAAAA--- ---AAAAAAAAAAAA--- ---AAAAAAAAAAAA--- ---AAAAAAAAAAAA--- ---AAAAAAAAAAAA--- ---AAAAAAAAAAAA--- ---AAAAAAAAAAAA--- ---AAAAAAAAAAAA--- ---AAAAAAAAAAAA--- ---AAAAAAAAAAAA--- ---AAAAAAAAAAAA--- ---AAAAAAAAAAAA--- ---AAAAAAAAAAAA--- ---AAAAAAAAAAAA--- ---AAAAAAAAAAAA--- ---AAAAAAAAAAAA--- ---AAAAAAAAAAAA--- --BAAAAAAAAAAAAB-- --BB----------BB-- 
------AA--AAA----- ----AAAAAAAAAA---- ----AAAAAAAAAA---- ----AAAAAAAAAA---- ----AAAAAAAAAA---- ----AAAAAAAAAA---- ----AAAAAAAAAA---- ----AAAAAAAAAA---- ----AAAAAAAAAA---- ----AAAAAAAAAA---- ----AAAAAAAAAA---- ----AAAAAAAAAA---- ----AAAAAAAAAA---- ----AAAAAAAAAA---- ----AAAAAAAAAA---- ----AAAAAAAAAA---- ----AAAAAAAAAA---- ----AAAAAAAAAA---- ----AAAAAAAAAA---- ----AAAAAAAAAA---- ---BAAAACAACAAB--- ---BB--------BB--- 
-------AAAA------- -----AAAAAAAA----- -----AAAAAAAA----- -----AAAAAAAA----- -----AAAAAAAA----- -----AAAAAAAA----- -----AAAAAAAA----- -----AAAAAAAA----- -----AAAAAAAA----- -----AAAAAAAA----- -----AAAAAAAA----- -----AAAAAAAA----- -----AAAAAAAA----- -----AAAAAAAA----- -----AAAAAAAA----- -----AAAAAAAA----- -----AAAAAAAA----- -----AAAAAAAA----- -----AAAAAAAA----- -----AAAAAAAA----- ----BAAAAAAAAB---- ----BB------BB---- 
------------------ ------AAAAAA------ ------AAAAAA------ ------AAAAAA------ ------AAAAAA------ ------AAAAAA------ ------AAAAAA------ ------AAAAAA------ ------AAAAAA------ ------AAAAAA------ ------AAAAAA------ ------AAAAAA------ ------AAAAAA------ ------AAAAAA------ ------AAAAAA------ ------AAAAAA------ ------AAAAAA------ ------AAAAAA------ ------AAAAAA------ ------AAAAAA------ -----BAAAAAAB----- -----BBBBBBBB----- 
------------------ --------AA-------- --------AA-------- --------AA-------- --------AA-------- --------AA-------- --------AA-------- --------AA-------- --------AA-------- --------AA-------- --------AA-------- --------AA-------- --------AA-------- --------AA-------- --------AA-------- --------AA-------- --------AA-------- --------AA-------- --------AA-------- --------AA-------- ------BBBBBB------ ------BBBBBB------ 
