model
size = 18 25 31, scale = 0.05, origin = -y
material 
  colors = A:#111 B:#FFF C:#3C3 D:#930 E:#222 F:#888 G:#AAA
voxels
------------------ ------------------ ------------------ ------------------ ------------------ ------------------ ------------------ ------------------ --------AA-------- --------AA-------- --------AA-------- ------------------ ------------------ ------------------ ------------------ ------------------ ------------------ ------------------ ------------------ ------------------ ------------------ ------------------ ------------------ ------------------ ------------------ 
------------------ ------------------ ------------------ ------------------ ------------------ ------------------ --------AA-------- --------AA-------- --------BB-------- --------BB-------- --------BB-------- --------AA-------- --------AA-------- ------------------ ------------------ ------------------ ------------------ ------------------ ------------------ ------------------ ------------------ ------------------ ------------------ ------------------ ------------------ 
------------------ ------------------ ------------------ ------------------ ------------------ --------AA-------- --------BB-------- --------BB-------- ------------------ ------------------ ------------------ --------BB-------- --------BB-------- --------AA-------- ------------------ ------------------ ------------------ ------------------ ------------------ ------------------ ------------------ ------------------ ------------------ ------------------ ------------------ 
------------------ ------------------ ------------------ ------------------ --------AA-------- --------BB-------- ------------------ ------------------ ------------------ ------------------ ------------------ ------------------ ------------------ --------BB-------- --------AA-------- ------------------ ------------------ ------------------ ------------------ ------------------ ------------------ ------------------ ------------------ ------------------ ------------------ 
------------------ ------------------ ------------------ --------AA-------- --------BB-------- ------------------ ------------------ ------------------ ------------------ ------------------ ------------------ ------------------ ------------------ ------------------ --------BB-------- --------AA-------- ------------------ ------------------ ------------------ ------------------ ------------------ ------------------ ------------------ ------------------ ------------------ 
------------------ ------------------ --------AA-------- --------BB-------- ------------------ ------------------ ------------------ ------------------ ------------------ ------------------ ------------------ ------------------ ------------------ ------------------ ------------------ --------BB-------- --------AA-------- ------------------ ------------------ ------------------ ------------------ ------------------ ------------------ ------------------ ------------------ 
------------------ --------AA-------- --------BB-------- ------------------ ------------------ ------------------ ------------------ ------------------ ------------------ ------------------ ------------------ ------------------ ------------------ ------------------ ------------------ ------------------ --------BB-------- --------AA-------- ------------------ ------------------ ------------------ ------------------ ------------------ ------------------ ------------------ 
------------------ --------AA-------- --------BB-------- ------------------ ------------------ ------------------ ------------------ ------------------ ------------------ ------------------ ------------------ ------------------ ------------------ ------------------ ------------------ ------------------ --------BB-------- --------AA-------- ------------------ ------------------ ------------------ ------------------ ------------------ ------------------ ------------------ 
--------AA-------- --------BB-------- ------------------ ------------------ ------------------ ------------------ ------------------ ------------------ ------------------ --------EE-------- ------------------ ------------------ ------------------ ------------------ ------------------ ------------------ ------------------ --------BB-------- --------AA-------- ------------------ ------------------ ------------------ ------------------ ----BB------BB---- -----BB----BB----- 
--------AA-------- --------BB-------- ------------------ ------------------ ------------------ ------------------ ------------------ ------------------ --------EE-------- ------FFGGFF------ ------C-EE-C------ ------C----C------ ------C----C------ ------C----C------ ------C----C------ ------C----C------ ------C----C------ ------C-BB-C------ ------C-AA-C------ ------C----C------ ------CCCCCC------ --------CC-------- D-BB----CC----BB-D ---BB---CC---BB--- ------BBBBBB------ 
--------AA-------- --------BB-------- ------------------ ------------------ ------------------ ------------------ ------------------ ------------------ ------------------ --------EE-------- ------------------ ------------------ ------------------ ------------------ ------------------ ------------------ ------------------ --------BB-------- --------AA-------- ------------------ --------CC-------- ------------------ DBB------------BBD ------------------ ------------------ 
------------------ --------AA-------- --------BB-------- ------------------ ------------------ ------------------ ------------------ ------------------ ------------------ ------------------ ------------------ ------------------ ------------------ ------------------ ------------------ ------------------ --------BB-------- --------AA-------- ------------------ ------------------ --------CC-------- ------------------ D----------------D ------------------ ------------------ 
------------------ --------AA-------- --------BB-------- ------------------ ------------------ ------------------ ------------------ ------------------ ------------------ ------------------ ------------------ ------------------ ------------------ ------------------ ------------------ ------------------ --------BB-------- --------AA-------- ------------------ --------CC-------- ------------------ ------------------ ------------------ ------------------ ------------------ 
------------------ ------------------ --------AA-------- --------BB-------- ------------------ ------------------ ------------------ ------------------ ------------------ ------------------ ------------------ ------------------ ------------------ ------------------ ------------------ --------BB-------- --------AA-------- ------------------ ------------------ --------CC-------- ------------------ ------------------ ------------------ ------------------ ------------------ 
------------------ ------------------ ------------------ --------AA-------- --------BB-------- ------------------ ------------------ ------------------ ------------------ ------------------ ------------------ ------------------ ------------------ ------------------ --------BB-------- --------AA-------- ------------------ ------------------ ------------------ --------CC-------- ------------------ ------------------ ------------------ ------------------ ------------------ 
------------------ ------------------ ------------------ ------------------ --------AA-------- --------BB-------- ------------------ ------------------ ------------------ ------------------ ------------------ ------------------ ------------------ --------BB-------- --------AA-------- ------------------ ------------------ ------------------ --------CC-------- ------------------ ------------------ ------------------ ------------------ ------------------ ------------------ 
------------------ ------------------ ------------------ ------------------ ------------------ --------AA-------- --------BB-------- --------BB-------- ------------------ ------------------ ------------------ --------BB-------- --------BB-------- --------AA-------- ------------------ ------------------ ------------------ --------CC-------- ------------------ ------------------ --------DD-------- ------------------ ------------------ ------------------ ------------------ 
------------------ ------------------ ------------------ ------------------ ------------------ ------------------ --------AA-------- --------AA-------- --------BB-------- --------BB-------- --------BB-------- --------AA-------- --------AA-------- ------------------ ------------------ ------------------ --------CC-------- --------AA-------- --------AA-------- --------AA-------- -------DDDD------- ------------------ ------------------ ------------------ ------------------ 
------------------ ------------------ ------------------ ------------------ ------------------ ------------------ ------------------ ------------------ --------AA-------- --------AA-------- --------AA-------- ------------------ ------------------ ------------------ ------------------ --------CC-------- --------CC-------- ------------------ ------------------ ------------------ -------DDDD------- ------------------ ------------------ ------------------ ------------------ 
------------------ ------------------ ------------------ ------------------ ------------------ ------------------ ------------------ ------------------ ------------------ ------------------ ------------------ ------------------ ------------------ ------------------ --------CC-------- --------CC-------- ------------------ ------------------ ------------------ ------------------ ------DDDDDD------ ------------------ ------------------ ------------------ ------------------ 
------------------ ------------------ ------------------ ------------------ ------------------ ------------------ ------------------ ------------------ ------------------ ------------------ ------------------ ------------------ ------------------ --------CC-------- --------AA-------- --------AA-------- --------AA-------- --------AA-------- --------AA-------- --------AA-------- ------DDDDDD------ ------------------ ------------------ ------------------ ------------------ 
------------------ ------------------ ------------------ ------------------ ------------------ ------------------ ------------------ ------------------ ------------------ ------------------ ------------------ ------------------ --------CC-------- --------CC-------- ------------------ ------------------ ------------------ ------------------ ------------------ ------------------ ------DDDDDD------ ------------------ ------------------ ------------------ ------------------ 
------------------ ------------------ ------------------ ------------------ ------------------ ------------------ ------------------ ------------------ ------------------ ------------------ ------------------ --------CC-------- --------CC-------- ------------------ ------------------ ------------------ ------------------ ------------------ ------------------ ------------------ ------DDDDDD------ ------------------ ------------------ ------------------ ------------------ 
------------------ ------------------ ------------------ --------AA-------- --------AA-------- ------------------ ------------------ ------------------ ------------------ ------------------ --------CC-------- --------CC-------- ------------------ ------------------ ------------------ ------------------ ------------------ ------------------ ------------------ ------------------ ------------------ ------------------ ------------------ ------------------ ------------------ 
------------------ ------------------ --------AA-------- ------------------ ------------------ --------AA-------- ------------------ ------------------ ------------------ ------------------ --------CC-------- ------------------ ------------------ ------------------ ------------------ ------------------ ------------------ ------------------ ------------------ ------------------ ------------------ ------------------ ------------------ ------------------ ------------------ 
------------------ --------AA-------- ------------------ ------------------ ------------------ ------------------ --------AA-------- ------------------ ------------------ --------CC-------- --------CC-------- ------------------ ------------------ ------------------ ------------------ ------------------ ------------------ ------------------ ------------------ ------------------ ------------------ ------------------ ------------------ ------------------ ------------------ 
--------AA-------- ------------------ ------------------ --------EE-------- ------CFEEFC------ ------C----C------ ------C----C------ ------C-AA-C------ ------C----C------ ------CCCCCC------ ------------------ ------------------ ------------------ ------------------ ------------------ ------------------ ------------------ ------------------ ------------------ ------------------ ------------------ ------------------ ------------------ ------------------ ------------------ 
--------AA-------- ------------------ ------------------ --------EE-------- --------EE-------- ------------------ ------------------ --------AA-------- ------------------ ------------------ ------------------ ------------------ ------------------ ------------------ ------------------ ------------------ ------------------ ------------------ ------------------ ------------------ ------------------ ------------------ ------------------ ------------------ ------------------ 
------------------ --------AA-------- ------------------ ------------------ ------------------ ------------------ --------AA-------- ------------------ ------------------ ------------------ ------------------ ------------------ ------------------ ------------------ ------------------ ------------------ ------------------ ------------------ ------------------ ------------------ ------------------ ------------------ ------------------ ------------------ ------------------ 
------------------ ------------------ --------AA-------- ------------------ ------------------ --------AA-------- ------------------ ------------------ ------------------ ------------------ ------------------ ------------------ ------------------ ------------------ ------------------ ------------------ ------------------ ------------------ ------------------ ------------------ ------------------ ------------------ ------------------ ------------------ ------------------ 
------------------ ------------------ ------------------ --------AA-------- --------AA-------- ------------------ ------------------ ------------------ ------------------ ------------------ ------------------ ------------------ ------------------ ------------------ ------------------ ------------------ ------------------ ------------------ ------------------ ------------------ ------------------ ------------------ ------------------ ------------------ ------------------ 
