model
size = 32 25 31, scale = 0.05, origin = -y
material 
  colors = A:#656765 B:#888 C:#555 D:#111 E:#BDC0BA F:#D0104C G:#91989F
voxels
198-A18-A582-A4-A20-A4-A165-2A18-2A5-A30-A424-A14-A104-A4-A20-A4-3A2-2A20-2A2-4A2-2A20-2A2-2A64-2A2-2A20-2A2-4A2-2A20-2A2-3A30-A257-A6-A14-A6-A130-A5-2A14-2A5-A129-2A2-2A20-2A2-8A20-6A-A2FA22-A2FA2-A2FA22-A2FA-6A20-8A2-2A20-2A2-2A289-3A2-3A14-3A2-3A3-2A2-2A16-2A2-2A68-2A2-2A16-2A2-2A3-3A2-2A16-2A2-3A162-D2AD22-D2AD2(2-4A22-4A)2-D2AD22-D2AD323-2A2-2A16-2A2-2A4-6A16-6A5-A2FA18-A2FA6-A2FA18-A2FA5-6A16-6A4-2A2-2A16-2A2-2A163-D2AD22-D2AD2(2-4A22-4A)2-D2AD22-D2AD356-D2AD18-D2AD2(6-4A18-4A)6-D2AD18-D2AD196-D2AD22-D2AD2(2-4A22-4A)2-D2AD22-D2AD356-D2AD18-D2AD2(6-4A18-4A)6-D2AD18-D2AD229-2A24-2A4-2A24-2A389-D2AD18-D2AD2(6-4A18-4A)6-D2AD18-D2AD229-2A24-2A4-2A24-2A422-2A20-2A8-2A20-2A229-2A26-2A2-2A26-2A453-2A20-2A8-2A20-2A229-2A26-2A2-2A26-2A486-2A18-2A10-2A18-2A231-2A24-2A4-2A24-2A455-2A18-2A10-2A18-2A231-2A24-2A4-2A24-2A488-2A16-2A12-2A16-2A169-2A22-2A6-2A22-2A521-2A16-2A12-2A16-2A169-2A22-2A6-2A22-2A552-2A18-2A10-2A18-2A103-2A24-2A4-2A24-2A583-2A18-2A10-2A18-2A103-2A24-2A4-2A24-2A614-2A20-2A8-2A20-2A39-2A22-2A6-2A22-2A647-2A20-2A8-2A20-2A39-2A22-2A6-2A22-2A680-2A18-2A10-2A18-2A39-2A24-2A4-2A24-2A647-2A18-2A10-2A18-2A39-2A24-2A4-2A24-2A614-2A20-2A8-2A20-2A101-2A26-2A2-2A26-2A516-2A22-2A6-2A22-2A7-2A20-2A8-2A20-2A101-2A26-2A2-2A26-2A516-2A22-2A6-2A22-2A197-2A24-2A4-2A24-2A452-2A24-2A4-2A24-2A228-2A24-2A4-2A24-2A389-2A22-2A6-2A22-2A5-2A24-2A4-2A24-2A261-2A22-2A6-2A22-2A294-3(2A22-2A6-)2A22-2A326-2A22-2A6-2A22-2A7-2A20-2A8-2A20-2A168-2A20-2A8-2A20-2A7-2A22-2A6-2A22-2A455-2A20-2A8-4A16-4A10-2A16-2A108-2A16-2A10-4A16-4A8-2A20-2A554-2A16-2A2(12-4A)14-2A12-2A48-2A12-2A14-2(4A12-)2A16-2A565-2C27-2(2B4C2B20-2AEBC2B2C2BCBE2A16-2AE2BCB2CBC2BE2A20-)2B4C2B25-2B2C2B27-B2CB29-2C30-2C3(29-D2GD29-2G)254-2B27-BCB2CBCB22-AECBC2BCBCEA20-AEBCB2CBCBEA22-CBC2BCBC22-AEBCB2CBCBEA20-AECBC2BCBCEA22-BCB2CBCB25-BC2BCB27-B2CB29-2B30-2(2C29-C2BC29-)2C29-C2BC78-
