model
size = 11 15 5, scale = 0.05, origin = -y
material 
  colors = A:#352C27
voxels
----------- ----------- ----------- ---A--A--A- -------A-A- -----A----- ----------- ----------- ----------- ----------- ----------- ----------- ----------- ----------- ----------- 
---------A- -AA----AAA- --A----A--- --AA-AAA--- ---AAAAA-A- -----AA---- ---A--A--A- -------A--- ---A-A----- ------A-A-- ---A------- -----A-A--- ----A------ --------A-- ----------- 
----------- ----------- ----A--A--- ---AAAAAA-- --AAAAAAAA- -AAAAAAAAA- --AAAAAAAAA --AAAAAAAA- -AAAAAAAA-- --AAAAAAAA- --AAAAAAA-- -AAAAAAA--- --AAAAAA-A- ---AA-A-A-- ----A-A---- 
----------- -A--------- AA--------- -A--------- AA------A-- -A------AA- AA------A-- -A------AA- AAA-----A-- -A-----AA-- AA-----AAA- -AA----A--- -AAAAAAAA-- ---AA------ ----------- 
----------- ----------- -A--------- ----------- -A------A-- ----------- -A------A-- ----------- -A------A-- ----------- -A-----AA-- -------A--- -A-A-A-A--- ----------- ----------- 
