model
size = 18 8 9, scale = 0.05, origin = -y
material 
  colors = A:#001 B:#036 C:#960 D:#222 E:#0F6 F:#444 G:#555 H:#111 I:#EEE
voxels
---CCCCCCCCCCCCCCC ---AAAAAAAAAAAAAAA ---AAAAAAAAAAAAAAA ---AAAAAAAAAAAAAAA ---AAAAAAAAAAAAAAA ---AAAAAAAAAAAAAAA ------------------ ------------------ 
--CCCCCCCCCCCCCCCC --AAAAAAAAAAAAAAAA --A-BBBBBBBBBBBBBB --A-BBBBBBBBBBBBBB --AFBBBBBBBBBBBBBB --AFBBBBBBBBBBBBBB ---GDDDDDDDDDDDDDD ------------------ 
-CCCCCCCCCCCCCCCCC -AA-AAAAAAAAAAAAAA -A---------------D -A---------------D -A---------------B -A-BBBBBBBBBB----B --GBBBBBBBBBB----D ---EEE-E-EEEEEE--- 
CCCCCCCCCCCCCCCCCC AAA-AAAAAAAAAAAAAA AAA--------------D AAA--------------D AA---------------B AFBB-------------B -GBBBBBBBBBBB----D -----E-E-E----E--- 
CCCCCCCCCCCCCCCCCC AAA-AAAAAAAAAAAAAA AAA--------------D AAA--------------D AA---------------B AFBB-------------B -GBBHIHIHIHIH----D ---EEE-E-EEE--E--- 
CCCCCCCCCCCCCCCCCC AAA-AAAAAAAAAAAAAA AAA--------------D AAA--------------D AA---------------B AFBB-------------B -GBBBBBBBBBBB----D ---E---E-E----E--- 
-CCCCCCCCCCCCCCCCC -AA-AAAAAAAAAAAAAA -AA--------------D -AA--------------D -A---------------B -A-BBBBBBBBBB----B --GBBBBBBBBBB----D ---EEEEEEEEEEEE--- 
--CCCCCCCCCCCCCCCC --AAAAAAAAAAAAAAAA --AABBBBBBBBBBBBBB --AABBBBBBBBBBBBBB --AFBBBBBBBBBBBBBB --AFBBBBBBBBBBBBBB ---GDDDDDDDDDDDDDD ------------------ 
---CCCCCCCCCCCCCCC ---AAAAAAAAAAAAAAA ---AAAAAAAAAAAAAAA ---AAAAAAAAAAAAAAA ---AAAAAAAAAAAAAAA ---AAAAAAAAAAAAAAA ------------------ ------------------ 
