model
size = 11 4 9, scale = 0.05, origin = -y
material 
  colors = A:#111 B:#222
voxels
----------- ----------- B---------B A---------A 
----------- ----------- ----------- A---------A 
----------- ----------- ----------- A---------A 
----------- ----------- ----------- A---------A 
----------- ----------- ----------- A---------A 
----------- ----------- ----------- A---------A 
----------- ----------- ----------- A---------A 
----------- ----------- ----------- A---------A 
AAAAA-AAAAA A---A-A---A A---A-A---A AAAAAAAAAAA 
