model
size = 25 32 15, scale = 0.05, origin = -y
material 
  colors = A:#EEE B:#D00 C:#050 D:#963 E:#0D0 F:#0A0 G:#0E0 H:#A00 I:#080 J:#600 K:#930 L:#BBB M:#888 N:#AAA
voxels
238-I2CEB18-CHE2CIBC16-3BEI2E4B13-4E2B2H4EB11-HI2CIB2CBI2CIBC10-BI2CEB2CBI2CEBC10-B3EI2BEB3EI2B614-7B15-B2CB5A2C13-2BC8AC2B11-2B11A2B9-FB13A2B8-C15AC9-B14ACB2-2CBH2C15A2B-B3HIE2IHF2B4E2B2H4E587-4E2BE15-3B7AE13-B11ABE11-B13AE9-B15AE8-C15AB8-C16AB-3B2IB17AC-F22AC2-2CBE2CIH2CBE2CEB2CHE2CE562-2I2C2BC15-E2C7AC13-C11ABE11-C13AC9-B15AC8-B15AB-CBF4-B16AB-BA2CIB17AC-F22AC2-C9ABE2CE7AE3-CBE2CEB2C5-2KCHE2C18-2A24-2D23-2D24-2A23-2D24-2(2D23-)2A340-2I2C2BC15-E2C7AC13-C11ABE11-C13AC9-C15AC-3F4-C15AF-BAB4-C16AF-BA2CHB17AF-B22AF2-B9AB4E7AE3-B7AB5-2K4AE5-B2(EI)2B6-LA2BE2J19-2D23-2D24-LA23-2D24-2(2D23-)AL340-BE2HBEB15-E2B7AB13-B11ABE11-B13AE2-HC5-I15AE-GAH4-B15AB-GAB4-B16AB-BAB2IB17AE-F22AE2-G11A4B6AE3-G7AB2K4-B4AF5-G3B2AB-LA5-B3AJ9-2K3-2D5-2FJ10-2A3-2D7-J10-2D4-2A6-J11-2D3-2D4-3J11-AL4-2D18-2D3-2D18-3D3-2D18-2D3-2A19-2D23-LA61-2M8(23-2D)10-2B2CHEC6-AL7-E2C7AC5-2K6-C11AEB3-BC6-C13AE2-FC5-I15AC-CAF4-C15AC-CAB4-C16AEG2A2CIB17AC-F22AC2-C11A2C2B6AB3-C7AC2K4-C4AF5-BG2C2AC-2A5-C3AC9-2K3-2D5-2FC10-2A3-2D18-2D4-LA18-2D3-2D2-3J13-2A4-2D2J16-2D3-2D18-3DJ2-2D18-2D3-AL19-2D23-2A61-2M8(23-2D)10-EB2CHEC6-2A7-I2C7AC5-2K6-C11AEB3-BC6-C13AE2-FC5-I2(15AC-CAB4-C)16AEG2A2CIB17AC-F22AC2-C9A2B2C2B6AE3-C7AC6-C4AF5-HG2CGBC8-C3AC21-2FC115-2J20-J2-J348-2(BE)H2E15-I2E7AE13-B11A2B11-B13AE2-FH5-I15AB-GAH4-B15AB-BAB4-B16AB-BA4B17AE-H22AE2-H9A2(BH)BG6AE3-H7AB6-G4AB5-H2(G2B)8-B3AF21-2BF109-2J24-3J351-2B2C2BC15-B2C7AC13-C11A2B11-C13AC9-B15AC-BCH4-C15AB-GAB4-C16AF-HA2CIB17AF-F22AF2-G9AG2H2BG6AF3-G7AB6-B4AB5-KA5B8-BG3B5-2K23-2A3(23-2D)26-J379-HB2C2HC15-B2C7AC13-C11A2B11-C13AC9-B15AC8-C15AB-C2B4-C16AF-GA2CIB17AC-F22AC2-C9AGB2CHG6AF3-C2B2CBG2C6-2CGB2C5-2(2K23-)2A2(23-2D)22-3D22-2D2-J20-2D3J354-BH4EB15-2HB7AB13-B11ABE11-B13AE9-H2(15AE8-B)16AF-GH2BHB17AC-F22AC2-2(2CBG)2CGB2CHG2CGB2CF153-2D23-2D22-3D22-2D23-2D308-GB2FB2H15-2(B2CG)B2C14-B2C2B2CGB2C2G12-B5F2GB3F2B9-HB2GFB2GBH3G2BHG8-CF2(G2CB)G2CHBFC8-C3(BG2C)HBFCG2-2C2BH2(B3F)B4FHF3G-F3B3GB2GBG3BH3G2B3F227-3D22-2D22-A2D22-2A23-2A773-2A22-3A22-2N798-NA23-
