model
size = 31 29 19, scale = 0.05, origin = -y
material 
  colors = A:#FF9 B:#F66 C:#F33 D:#9CF E:#FCC F:#EEE G:#001 H:#F69 I:#FFF J:#9F9 K:#F0C L:#F30 M:#3FF N:#3C6
voxels
-----BBBBB------BBBBB---------- -----B-B-B------B-B-B---------- ------------------------------- ------------------------------- ------------------------------- ------------------------------- ------------------------------- ------------------------------- ------------------------------- ------------------------------- ------------------------------- ------------------------------- ------------------------------- ------------------------------- ------------------------------- ------------------------------- ------------------------------- ------------------------------- ------------------------------- ------------------------------- ------------------------------- ------------------------------- ------------------------------- ------------------------------- ------------------------------- ------------------------------- ------------------------------- ------------------------------- ------------------------------- 
-----BBBBB------BBBBB---------- -----BBBBB------BBBBB---------- ------------------------------- ------------------------------- ------------------------------- ------------------------------- ------------------------------- ------------------------------- ------------------------------- ------------------------------- ------------------------------- ------------------------------- ------------------------------- ------------------------------- ------------------------------- ------------------------------- ------------------------------- ------------------------------- ------------------------------- ------------------------------- ------------------------------- ------------------------------- ------------------------------- ------------------------------- ------------------------------- ------------------------------- ------------------------------- ------------------------------- ------------------------------- 
-----BBBB--------BBBB---------- -----BAAF--------FAAB---------- -----BBBB--------BBBB---------- -----BBBB--------BBBB---------- ------BBB--------BBB----------- ------BBB--------BBB----------- ------BBB--------BBB----------- ------------------------------- ------------------------------- ------------------------------- ------------------------------- ------------------------------- ------------------------------- ------------------------------- ------------------------------- ------------------------------- ------------------------------- ------------------------------- ------------------------------- ------------------------------- ------------------------------- ------------------------------- ------------------------------- ------------------------------- ------------------------------- ------------------------------- ------------------------------- ------------------------------- ------------------------------- 
-----BBBBEEEEEEEEBBBB---------- -----BAAAEEEEEEEEAAAB---------- -----BAAAEEEEEEEEAAAB---------- -----BAAAEEEEEEEEAAAB---------- -----BAAAEEEEEEEEAAAB---------- -----BAAAEEEEEEEEAAAB---------- ------BBBEEEEEEEEBBB----------- ---------EEEEEEEE-------------- ----------EEEEEE--------------- ----------EEEEEE--------------- -----------EEEE---------------- ------------------------------- ------------------------------- ------------------------------- ----GG--------------GG--------- ------GG----------GG----------- ------------------------------- -----GG------------GG---------- --GGG---G---GG---G---GG-------- -------G---GGGG---G------------ ----GGG-III----III-GGG--------- -------ILLBI--IBLLI------------ -------IGGLI--ILGGI------------ -------HHHHH--HHHHH------------ --------HHH----HHH------------- ------------------------------- ------------------------------- ------------------------------- ------------------------------- 
-----BBBBBBBBBBBBBBBB---------- -----BAAAAAAAAAAAAAAB---------- -----BAAAAAAAAAAAAAAB---------- -----BAAAAAAAAAAAAAAB---------- -----BAAAAAAAAAAAAAAB---------- -----BAAAAAAAAAAAAAAB---------- -----BAAAAAAAAAAAAJJB---------- ------BBBAAAAAAAABBB----------- ------CCBBAAAAAABBCC----------- ------BBBBAAAAAABBBB----------- ------CCCBBAAAABBCCC----------- ------BBBBBBBBBBBBBB----------- -------CBBBBBBBBBBC------------ -------BBBBBCCBBBBB------------ ------BBBBBBBBBBBBBB----------- ------BABBBGGGGBBBAB----------- ----BBBBBBGBGGBGBBBBBB--------- -----BECBBBBBBBBBBCEB---------- -----BCCABBBGGBBBACCB---------- ------BABBBGGGGBBBAB----------- ------BFFFFBBBBFFFFB----------- ------BFKKKFBBFKKKFB----------- ------BFGGKFBBFKGGFB----------- -------BMGFFCCFFGMB------------ -------BBFFBCCBFFBB------------ ---------BCBCCBCB-------------- ------------------------------- ------------------------------- ------------------------------- 
----BBBBBBBBBBBBBBBBBB--------- ----BAAAAAAAAAAAAAAAAB--------- ----BAAAAAAAAAAAAAAAAB--------- ----BAAAAAAAAAAAAAAAAB--------- ----BAAAAAAAAAAAAAAAAB--------- ----BAAAAAAAAAAAAAAAAB--------- -----BAAAAAAAAAAAAAJB---------- -----BAAAAAAAAAAAAJJB---------- -----CCCAAAAAAAAAAJCC---------- -----BAAAAAAAAAAAAJJB---------- -----CCCCAAAAAAAAAAJC---------- -----BNAAAAAAAAAAAAAB---------- ------CCDDDDDDDAAACC----------- ------BDDDDAAAAAAAAB----------- ------BDDDDAAAAAAAAB----------- ------BDDDDAAAAAAAAB----------- ----BBDDDDDAAAAAAAAABB--------- -----BDDDDDAAAAAAAAAB---------- -----BDDDDDAAAAAAAAJB---------- ------BDDDDAAAAAAAAB----------- ------BDDDDFFFFAAAAB----------- ------BDDDDAFFAAAAAB----------- ------BDDDDAFFAAAAAB----------- -------BAAAACCAAAAB------------ -------BAAAFCCFAAAB------------ --------BBCBCCBCBB------------- --------B--------B------------- ------------------------------- ------------------------------- 
----BBBBBBBBBBBBBBBBBB--------- ----BAAAAAAAAAAAAAAAAB--------- ----BAAAAAAAAAAAAAAAAB--------- ----BAAAAAAAAAAAAAAAAB--------- ----BAAAAAAAAAAAAAAAAB--------- ----BAAAAAAAAAAAAAAAAB--------- ----BAAAAAAAAAAAAAAAAB--------- ----BAAAAAAAAAAAAAAAAB--------- ----CCCCAAAAAAAAAAACCC--------- -----BAAAAAAAAAAAAAAB---------- -----CCCCAAAAAAAAAAAC---------- -----BNAAAAAAAAAAAAAB---------- -----CCCDDDDDDDAAACCC---------- ------BDDDDAAAAAAAAB----------- ------BDDDDAAAAAAAAB----------- ------BDDDDAAAAAAAAB----------- ------BDDDDAAAAAAAAB----------- ------BDDDDAAAAAAAAB----------- ------BDDDDAAAAAAAAB----------- ------BDDDDAAAAAAAAB----------- ------BDDDDFFFFAAAAB----------- ------BDDDDAFFAAAAAB----------- ------BDDDDAFFAAAAAB----------- ------BAAAAACCAAAAAB----------- -----BCAAAAFCCFAAAACB---------- -----BCCABCBCCBCBACCB---------- ------CCB---C----BCC----------- -----B-BB--------BB-B---------- -----BB------------BB---------- 
----BBBBBBBBBBBBBBBBBB--------- ----BAAAAAAAAAAAAAAAAB--------- ----BAAAAAAAAAAAAAAAAB--------- ----BAAAAAAAAAAAAAAAAB--------- ----BAAAAAAAAAAAAAAAAB--------- ----BAAAAAAAAAAAAAAAAB--------- ----BAAAAAAAAAAAAAAAAB--------- ----BAAAAAAAAAAAAAAAAB--------- ----CCCCAAAAAAAAAAACCC--------- -----BAAAAAAAAAAAAAAB---------- -----CCCCAAAAAAAAAAAC---------- -----BAAAAAAAAAAAAAAB---------- -----CCCAAAAAAAAAACCC---------- -----BAAAAAAAAAAAAADB---------- ------BAAAAAAAAAAAAB----------- ------BAAAAAAAAAAAAB----------- ------BAAAAAAAAAAAAB----------- ------BAAAAAAAAAAAAB----------- ------BAAAAAAAAAAAAB----------- ------BAAAAAAAAAAAAB----------- ------BAAAAFFFFAAAAB----------- ------BAAAAAFFAAAAAB----------- ------BAAAAAFFAAAAAB----------- ------BAAAAACCAAAAAB----------- -----BBAAAAFCCFAAAABB---------- -----BBBBBCFCCFCBBBBB---------- -----BBBB--BCCB--BBBB---------- -----BBBB---CC---BBBB---------- -----BB------------BB---------- 
----BBBBBBBBBBBBBBBBBB--------- ----BAAAAAAAAAAAAAAAAB--------- ----BAAAAAAAAAAAAAAAAB--------- ----BAAAAAAAAAAAAAAAAB--------- ----BAAAAAAAAAAAAAAAAB--------- ----BAAAAAAAAAAAAAAAAB--------- ----BAAAAAAAAAAAAAAAAB--------- ----BAAAAAAAAAAAAAAAAB--------- ----CCCCAAAAAAAAAAACCC--------- -----BAAAAAAAAAAAAAAB---------- -----CCCCAAAAAAAAAAAC---------- -----BAAAAAAAAAAAAAAB---------- -----CCCAAAAAAAAAACCC---------- -----BAAAAAAAAAAAAADB---------- ------BAAAAAAAAAAAAB----------- ------BAAAAAAAAAAAAB----------- ------BAAAAAAAAAAAAB----------- ------BAAAAAAAAAAAAB----------- ------BAAAAAAAAAAAAB----------- ------BAAAAAAAAAAAAB----------- ------BAAAAAAAAAAAAB----------- ------BAAAAAAAAAAAAB----------- ------BAAAAACCAAAAAB----------- -------BAAAACCAAAAB------------ -------BBAAACCAAABB------------ ---------BCACCACB-------------- -----------BCCB---------------- ------------CCB---------------- -------------B----------------- 
BBBBBBBBBBBBBBBBBBBBBBBBBB----- BBBBAAAAAAAAAAAAAAAAAABBBB----- --BBAAAAAAAAAAAAAAAAAABB------- --BBAAAAAAAAAAAAAAAAAABB------- --BBAAAAAAAAAAAAAAAAAABB------- --BBAAAAAAAAAAAAAAAAAABB------- ---BAAAAAAAAAAAAAAAAAAB-------- ----BAAAAAAAAAAAAAAAAB--------- ----CCCCAAAAAAAAAAACCC--------- -----BAAAAAAAAAAAAAAB---------- -----CCCCAAAAAAAAAAAC---------- -----BAAAAAAAAAAAAAAB---------- -----CCCAAAAAAAAAACCC---------- -----BAAAAAAAAAAAAAAB---------- ------BAAAAAAAAAAAAB----------- ------BAAAAAAAAAAAAB----------- ------BAAAAAAAAAAAAB----------- ------BAAAAAAAAAAAAB----------- ------BAAAAAAAAAAAAB----------- ------BAAAAAAAAAAAAB----------- ------BAAAAAAAAAAAAB----------- ------BAAAAAAAAAAAAB----------- ------BAAAAACCAAAAAB----------- -------BAAAACCAAAAB------------ -------BBACACCAAABB------------ ---------BCBCCBCB-------------- ------------------------------- ------------------------------- ------------------------------- 
BBBBBBBBBBBBBBBBBBBBBBBBBB----- BBAAAAAAAAAAAAAAAAAAAAAABB----- --BAAAAAAAAAAAAAAAAAAAAB------- --BAAAAAAAAAAAAAAAAAAAAB------- --BAAAAAAAAAAAAAAAAAAAAB------- --BAAAAAAAAAAAAAAAAAAAAB------- --BBAAAAAAAAAAAAAAAAAABB------- ----BAAAAAAAAAAAAAAAAB--------- ----CCCCAAAAAAAAAAACCC--------- -----BAAAAAAAAAAAAAAB---------- -----CCCCAAAAAAAAAAAC---------- -----BAAAAAAAAAAAAAAB---------- -----CCCAAAAAAAAAACCC---------- -----BAAAAAAAAAAAAAAB---------- ------BAAAAAAAAAAAAB----------- ------BAAAAAAAAAAAAB----------- ------BAAAAAAAAAAAAB----------- ------BAAAAAAAAAAAAB----------- ------BAAAAAAAAAAAAB----------- ------BAAAAAAAAAAAAB----------- ------BAAAAAAAAAAAAB----------- ------BAAAAAAAAAAAAB----------- ------BAAAAACCAAAAAB----------- -------BAAAACCACAAB------------ -------BBACACCACABB------------ ---------BCBCCBCB-------------- ------------------------------- ------------------------------- ------------------------------- 
BBBBBBBBBBBBBBBBBBBBBBBBBB----- BBAAAAAAAAAAAAAAAAAAAAAABB----- --BAAAAAAAAAAAAAAAAAAAAB------- --BAAAAAAAAAAAAAAAAAAAAB------- --BAAAAAAAAAAAAAAAAAAAAB------- --BAAAAAAAAAAAAAAAAAAAAB------- --BBAAAAAAAAAAAAAAAAAABB------- ----BAAAAAAAAAAAAAAAAB--------- ----CAAAAAAAAAAAAAACCC--------- -----BAAAAAAAAAAAAAAB---------- -----CCCCAAAAAAAAAAAC---------- -----BAAAAAAAAAAAAAAB---------- -----CCCAAAAAAAAAACCC---------- -----BAAAAAAAAAAAAAAB---------- ------BAAAAAAAAAAAAB----------- ------BAAAAAAAAAAAAB----------- ------BAAAAAAAAAAAAB----------- ------BAAAAAAAAAAAAB----------- ------BAAAAAAAAAAAAB----------- ------BAAAAAAAAAAAAB----------- ------BAAAAAAAAAAAAB----------- ------BAAAAAAAAAAAAB----------- ------BAAAAACCAAAAAB----------- -------BAAAACCACAAB------------ -------BBACACCACABB------------ ---------BCBCCBCB-------------- ------------------------------- ------------------------------- ------------------------------- 
BBBBBBBBBBBBBBBBBBBBBBBBBB----- BBBBBBAAAAAAAAAAAAAABBBBBB----- --BBBBAAAAAAAAAAAAAABBBB------- --BBBBAAAAAAAAAAAAAABBBB------- --BBBBAAAAAAAAAAAAAABBBB------- --BBBBAAAAAAAAAAAAAABBBB------- ---BBBAAAAAAAAAAAAAABBB-------- -----BAAAAAAAAAAAAAAB---------- -----BAAAAAAAAAAAAACC---------- -----BAAAAAAAAAAAAAAB---------- -----BAAAAAAAAAAAAAAC---------- -----BBAAAAAAAAAAAABB---------- -----BBAAAAAAAAAAAABC---------- ------BBAAAAAAAAAABB----------- ------BBBBBBBBBBBBBB----------- ------BBBBBBBBBBBBBB----------- ------BBBBBBBBBBBBBB----------- -------BBBAAAAAABBB------------ -------BBAAAAAAAABB------------ -------BBAAAAAAAABB------------ -------BBAAAAAAAABB------------ -------BBAAAAAAAABB------------ -------BBBAACCAABBB------------ --------BBCBCCBCBB------------- ---------BCBCCBCB-------------- ------------------------------- ------------------------------- ------------------------------- ------------------------------- 
------BBBBBBBBBBBBBB----------- ------BBBBBAAAAAAAAB----------- ------BBBBAAAAAAAAAB----------- ------BBBBAAAABBBBAB----------- ------BBBBAAAABBBBBB----------- ------BBBBAAAABBBBBB----------- ------BBBBBBBBBBBBBB----------- ------BBBBBBBBBBBBBB----------- ------BBBBBBBBBBBBBH----------- ------BBBBBBBBBBBBBB----------- ------BBBBBBBBBBBBBB----------- -------BBBBBBBBBBBB------------ -------BBBBBBBBBBBB------------ --------BBBBBBBBBB------------- ------------------------------- ------------------------------- ------------------------------- ----------BBBBBB--------------- ---------BBBBBBBB-------------- ---------BBBBBBBB-------------- ---------BBBBBBBB-------------- ---------BBBBBBBB-------------- ----------BBCCBB--------------- ------------------------------- ------------------------------- ------------------------------- ------------------------------- ------------------------------- ------------------------------- 
-------------BBBBBBB----------- -----------BBAAAAAAABB--------- ----------BAAABBBBAABBBB------- ----------BAAB----BBBBBBB------ ----------BAAB-------BBBBB----- ----------BBBB---------BBBB---- ------------------------BBB---- -------------------------BBB--- --------------------------BBB-- ---------------------------BB-- ---------------------------BBB- ----------------------------BB- ----------------------------BB- ----------------------------BB- ----------------------------BB- ----------------------------BB- ---------------------------BBB- --------------------------BBB-- -------------------------BBB--- ------------------------BBB---- -----------------------BBB----- ----------------------BBB------ ----------------------BB------- ------------------------------- ------------------------------- ------------------------------- ------------------------------- ------------------------------- ------------------------------- 
-------------BBBBBBB----------- -----------BBAAAAAAABBBB------- ----------BAAAAAAAAAAAAAB------ ----------BAAABBBBAAAAAAAB----- ----------BAAB----BBBAAAAAB---- ----------BBBB-------BBAAAB---- -----------------------BAAAB--- ------------------------BAAAB-- -------------------------BAAAB- --------------------------BAAB- ---------------------------BAB- ---------------------------BAAB ---------------------------BAAB ---------------------------BAAB ---------------------------BAJB ---------------------------BAB- --------------------------BAAB- -------------------------BAAAB- ------------------------BAAAB-- -----------------------BAAAB--- ----------------------BAAAB---- ----------------------BAAB----- ---------------------BABB------ ---------------------BB-------- ------------------------------- ------------------------------- ------------------------------- ------------------------------- ------------------------------- 
-------------BBBBBBB----------- -----------BBAAAAAAABBBB------- ----------BAAAAAAAAAAAAAB------ ----------BAAABBBBAAAAAAAB----- ----------BAAB----BBBAAAAAB---- ----------BBBB-------BBAAAAB--- -----------------------BAAAB--- ------------------------BAAAB-- -------------------------BAAAB- --------------------------BAAB- --------------------------BAAAB ---------------------------BAAB ---------------------------BAAB ---------------------------BAAB ---------------------------BAJB --------------------------BAAJB --------------------------BAAB- -------------------------BAAAB- ------------------------BAAAB-- -----------------------BAAAAB-- ----------------------BAAAAB--- ---------------------BAAAAB---- ---------------------BAABB----- ---------------------BBB------- ------------------------------- ------------------------------- ------------------------------- ------------------------------- ------------------------------- 
-------------BBBBBB------------ -----------BBAAAAAABBBB-------- ----------BAAAAAAAAAAAABB------ ----------BAAABBBBBAAAAAAB----- ----------BAAB-----BBAAAAAB---- ----------BBBB-------BBAAAB---- -----------------------BAAAB--- ------------------------BAAAB-- -------------------------BAAB-- --------------------------BAAB- --------------------------BAAB- ---------------------------BAAB ---------------------------BAAB ---------------------------BAAB ---------------------------BAAB --------------------------BAAB- --------------------------BAAB- -------------------------BAAB-- ------------------------BAAAB-- -----------------------BAAAB--- ----------------------BAAAB---- ---------------------BAAAB----- ---------------------BABB------ ---------------------BB-------- ------------------------------- ------------------------------- ------------------------------- ------------------------------- ------------------------------- 
------------------------------- ------------BBBBBBB------------ -----------BBBBBBBBBBBB-------- ----------BBBB----BBBBBBB------ ----------BBB--------BBBBB----- ----------BBB----------BBBB---- ------------------------BBB---- -------------------------BBB--- --------------------------BBB-- --------------------------BBB-- ---------------------------BBB- ----------------------------BB- ----------------------------BB- ----------------------------BB- ----------------------------BB- ---------------------------BBB- ---------------------------BB-- --------------------------BBB-- -------------------------BBB--- ------------------------BBBB--- -----------------------BBBB---- ----------------------BBBB----- ----------------------BB------- ------------------------------- ------------------------------- ------------------------------- ------------------------------- ------------------------------- ------------------------------- 
