model
size = 26 29 14, scale = 0.05, origin = -y
material 
  colors = A:#6C3 B:#CF3 C:#FCC D:#001 E:#6C0 F:#FFF G:#FF9 H:#F6C I:#693 J:#9CF K:#FCF L:#A00 M:#EEE N:#E00 O:#B00 P:#0F6 Q:#F0C R:#3FF S:#FC9
voxels
-----AAAAA------AAAAA----- -----A-A-A------A-A-A----- -------------------------- -------------------------- -------------------------- -------------------------- -------------------------- -------------------------- -------------------------- -------------------------- -------------------------- -------------------------- -------------------------- -------------------------- -------------------------- -------------------------- -------------------------- -------------------------- -------------------------- -------------------------- -------------------------- -------------------------- -------------------------- -------------------------- -------------------------- -------------------------- -------------------------- -------------------------- -------------------------- 
-----AAAAA------AAAAA----- -----AAAAA------AAAAA----- -------------------------- -------------------------- -------------------------- -------------------------- -------------------------- -------------------------- -------------------------- -------------------------- -------------------------- -------------------------- -------------------------- -------------------------- -------------------------- -------------------------- -------------------------- -------------------------- -------------------------- -------------------------- -------------------------- -------------------------- -------------------------- -------------------------- -------------------------- -------------------------- -------------------------- -------------------------- -------------------------- 
-----AAAA--------AAAA----- -----AAAA--------AAAA----- -----AAAA--------AAAA----- -----AAAA--------AAAA----- ------AAA--------AAA------ ------AAA--------AAA------ ------AAA--------AAA------ -------------------------- -------------------------- -------------------------- -------------------------- -------------------------- -------------------------- -------------------------- -------------------------- -------------------------- -------------------------- -------------------------- -------------------------- -------------------------- -------------------------- -------------------------- -------------------------- -------------------------- -------------------------- -------------------------- -------------------------- -------------------------- -------------------------- 
-----AAAABBBBBBBBAAAA----- -----AAAABBBBBBBBAAAA----- -----AAAABBBBBBBBAAAA----- -----AAAABBBBBBBBAAAA----- -----AAAABBBBBBBBAAAA----- -----AAAABBBBBBBBAAAA----- ------AAABBBBBBBBAAA------ ---------BBBBBBBB--------- ---------BBBBBBBB--------- ---------BBBBBBBB--------- ----------OBBBBB---------- ----------BBBBBB---------- -----------BBBN----------- -------------------------- ----DD-------------------- ------DD------------------ -------------------------- -----DD------------------- --DDD---D---DD------------ -------D---DDDD----------- ----DDD-FFF----FFF-------- -------FLLLF--FLLLF------- -------FDDLF--FLDDF------- -------FPDFF--FFDPF------- --------FFF----FFF-------- -------------------------- -------------------------- -------------------------- -------------------------- 
-----AAAAAAAAAAAAAAAA----- -----AAAAAAAAAAAAAAAA----- -----AAAAAAAAAAAAAAAA----- -----AAAAAAAAAAAAAAAA----- -----AAAAAAAAAAAAAAAA----- -----AAAAAAAAAAAAAAAA----- -----AAAAAAAAAAAAAAAA----- ------AAAAAAAAAAAAAA------ ------AAAAAAAAAAAAAA------ ------AAAAAAAAAAAAAA------ ------AAAAAAAAAAAAAA------ ------AAAAJJJJJJAAAA------ -------AAAOJJJJAAAA------- -------ABAAAAANAAAB------- ------EBBBNBOONABBBA------ ------EGBBNDMDMOBBBB------ ----AAABBBDMDMDMBBBBBA---- -----ACIBBBBBBBBBBIBB----- -----BIIBBBBBBBBBDIIB----- ------BGBBBBBBBBBBDB------ ------ABMBBBBBBBBBBB------ ------AMQBBBBBBBBBBB------ ------AMDBBBBBBBBBBB------ -------ARBBBBBBBBBB------- -------AABBBBBBBBB-------- ---------BBBB------------- -------------------------- -------------------------- -------------------------- 
----AAAAAAAAAAAAAAAAAA---- ----AAAAAAAAAAAAAAAAAA---- ----AAAAAAAAAAAAAAAAAA---- ----AAAAAAAAAAAAAAAAAA---- ----AAAAAAAAAAAAAAAAAA---- ----AAAAAAAAAAAAAAAAAA---- -----AAAAAAAAAAAAAAAA----- -----AAAAAAAAAAAAAAAA----- -----AAAAAAAAAAAAAAAA----- -----AAAAAAAAAAAAAAAA----- -----AAAAAAAAAAAAAAAA----- -----AAAAAAAAAAAAAAAA----- ------AAAAAAAAAAAAAA------ ------AAAAAAAAAAAAAA------ ------AAAAAAAAAAAAAA------ ------AAAAAAAAAAAAAA------ ----AAAAAAAAAAAAAAAAAA---- -----AAAAAAAAAAAAAAAA----- -----AAAAAAAAAAAAAAAA----- ------AAAAAAAAAAAAAA------ ------AAAAAAAAAAAAAA------ ------AAAAAAAAAAAAAA------ ------AAAAAAAAAAAAAA------ -------AAAAAAAAAAAA------- -------AGGGGGGGGGA-------- --------AAAAA------------- --------AEEE-------------- -------------------------- -------------------------- 
----AAAAAAAAAAAAAAAAAA---- ----AAAAAAAAAAAAAAAAAA---- ----AAAAAAAAAAAAAAAAAA---- ----AAAAAAAAAAAAAAAAAA---- ----AAAAAAAAAAAAAAAAAA---- ----AAAAAAAAAAAAAAAAAA---- ----AAAAAAAAAAAAAAAAAA---- ----AAAAAAAAAAAAAAAAAA---- ----AAAAAAAAAAAAAAAAAA---- -----AAAAAAAAAAAAAAAA----- -----AAAAAAAAAAAAAAAA----- -----AAAAAAAAAAAAAAAA----- -----AAAAAAAAAAAAAAAA----- ------AAAAAAAAAAAAAA------ ------AAAAAAAAAAAAAA------ ------AAAAAAAAAAAAAA------ ------AAAAAAAAAAAAAA------ ------AAAAAAAAAAAAAA------ ------AAAAAAAAAAAAAA------ ------AAAAAAAAAAAAAA------ ------AAAAAAAAAAAAAA------ ------AAAAAAAAAAAAAA------ ------AAAAAAAAAAAAAA------ ------AAAAAAA---CCCA------ -----AIIGGG-----CCC------- -----AIIEAACCHC-C--------- ------IIEEEK-K------------ -----A-------------------- -------------------------- 
----AAAAAAAAAAAAAAAAAA---- ----AAAAAAAAAAAAAAAAAA---- ----AAAAAAAAAAAAAAAAAA---- ----AAAAAAAAAAAAAAAAAA---- ----AAAAAAAAAAAAAAAAAA---- ----AAAAAAAAAAAAAAAAAA---- ----AAAAAAAAAAAAAAAAAA---- ----AAAAAAAAAAAAAAAAAA---- ----AAAAAAAAAAAAAAAAAA---- -----AAAAAAAAAAAAAAAA----- -----AAAAAAAAAAAAAAAA----- -----AAAAAAAAAAAAAAAA----- -----AAAAAAAAAAAAAAAA----- -----AAAAAAAAAAAAAAAA----- ------AAAAAAAAAAAAAA------ ------AAAAAAAAAAAAAA------ ------AAAAAAAAAAAAAA------ ------AAAAAAAAAAAAAA------ ------AAAAAAAAAAAAAA------ ------AAAAAAAAAAAAAA------ ------AAAAAAAAAAAAAA------ ------AAAAAAAAAACC-------- ------AAAAAAAAAACC-------- ------AAAAAAACCCCCC------- -----AAGGGG-CCCCCC-------- -----AAAAAAHCHHCS--------- -----AAAEEE-K---K--------- -----AA------------------- -----A-------------------- 
----AAAAAAAAAAAAAAAAAA---- ----AAAAAAAAAAAAAAAAAA---- ----AAAAAAAAAAAAAAAAAA---- ----AAAAAAAAAAAAAAAAAA---- ----AAAAAAAAAAAAAAAAAA---- ----AAAAAAAAAAAAAAAAAA---- ----AAAAAAAAAAAAAAAAAA---- ----AAAAAAAAAAAAAAAAAA---- ----AAAAAAAAAAAAAAAAAA---- -----AAAAAAAAAAAAAAAA----- -----AAAAAAAAAAAAAAAA----- -----AAAAAAAAAAAAAAAA----- -----AAAAAAAAAAAAAAAA----- -----AAAAAAAAAAAAAAAA----- ------AAAAAAAAAAAAAA------ ------AAAAAAAAAAAAAA------ ------AAAAAAAAAAAAAA------ ------AAAAAAAAAAAAAA------ ------AAAAAAAAAAAAAA------ ------AAAAAAAAAAAAAA------ ------AAAAAAAAAAAAAA------ ------AAAAAAAAAACH-------- ------AAAAAAAAAACC-------- -------AAAAAACCCCCH------- -------AAAA-CCCCCCC------- ---------AAHCHCHCH-------- --------EEE---K----------- -------------------------- -------------------------- 
AAAAAAAAAAAAAAAAAAAAAAAAAA AAAAAAAAAAAAAAAAAAAAAAAAAA --AAAAAAAAAAAAAAAAAAAAAA-- --AAAAAAAAAAAAAAAAAAAAAA-- --AAAAAAAAAAAAAAAAAAAAAA-- --AAAAAAAAAAAAAAAAAAAAAA-- ---AAAAAAAAAAAAAAAAAAAA--- ----AAAAAAAAAAAAAAAAAA---- ----AAAAAAAAAAAAAAAAAA---- -----AAAAAAAAAAAAAAAA----- -----AAAAAAAAAAAAAAAA----- -----AAAAAAAAAAAAAAAA----- -----AAAAAAAAAAAAAAAA----- -----AAAAAAAAAAAAAAAA----- ------AAAAAAAAAAAAAA------ ------AAAAAAAAAAAAAA------ ------AAAAAAAAAAAAAA------ ------AAAAAAAAAAAAAA------ ------AAAAAAAAAAAAAA------ ------AAAAAAAAAAAAAA------ ------AAAAAAAAAAAAAA------ ------AAAAAAAAAACH-------- ------AAAAAAAAAACC-------- -------AAAAAACCCCCC------- -------AAAAAACCCCC-------- ---------AAACCHCC--------- --------EEEEK--K---------- -------------------------- -------------------------- 
AAAAAAAAAAAAAAAAAAAAAAAAAA AAAAAAAAAAAAAAAAAAAAAAAAAA --AAAAAAAAAAAAAAAAAAAAAA-- --AAAAAAAAAAAAAAAAAAAAAA-- --AAAAAAAAAAAAAAAAAAAAAA-- --AAAAAAAAAAAAAAAAAAAAAA-- --AAAAAAAAAAAAAAAAAAAAAA-- ----AAAAAAAAAAAAAAAAAA---- ----AAAAAAAAAAAAAAAAAA---- -----AAAAAAAAAAAAAAAA----- -----AAAAAAAAAAAAAAAA----- -----AAAAAAAAAAAAAAAA----- -----AAAAAAAAAAAAAAAA----- -----AAAAAAAAAAAAAAAA----- ------AAAAAAAAAAAAAA------ ------AAAAAAAAAAAAAA------ ------AAAAAAAAAAAAAA------ ------AAAAAAAAAAAAAA------ ------AAAAAAAAAAAAAA------ ------AAAAAAAAAAAAAA------ ------AAAAAAAAAAAAAA------ ------AAAAAAAAAAAAAA------ ------AAAAAAAACCCC-------- -------AAAAAAACCCC-------- -------AAAAAACCCCH-------- ---------AAAHCCCHC-------- --------EEEEK-K----------- -------------------------- -------------------------- 
AAAAAAAAAAAAAAAAAAAAAAAAAA AAAAAAAAAAAAAAAAAAAAAAAAAA --AAAAAAAAAAAAAAAAAAAAAA-- --AAAAAAAAAAAAAAAAAAAAAA-- --AAAAAAAAAAAAAAAAAAAAAA-- --AAAAAAAAAAAAAAAAAAAAAA-- --AAAAAAAAAAAAAAAAAAAAAA-- ----AAAAAAAAAAAAAAAAAA---- ----AAAAAAAAAAAAAAAAAA---- -----AAAAAAAAAAAAAAAA----- -----AAAAAAAAAAAAAAAA----- -----AAAAAAAAAAAAAAAA----- -----AAAAAAAAAAAAAAAA----- -----AAAAAAAAAAAAAAAA----- ------AAAAAAAAAAAAAA------ ------AAAAAAAAAAAAAA------ ------AAAAAAAAAAAAAA------ ------AAAAAAAAAAAAAA------ ------AAAAAAAAAAAAAA------ ------AAAAAAAAAAAAAA------ ------AAAAAAAAAAAAAA------ ------AAAAAAAAAAAAAA------ ------AAAAAAAAAAAAA------- -------AAAAAAAAAAAA------- -------AAAAAAAAAAA-------- ---------AAAAAAA---------- --------EEEE-------------- -------------------------- -------------------------- 
AAAAAAAAAAAAAAAAAAAAAAAAAA AAAAAAAAAAAAAAAAAAAAAAAAAA --AAAAAAAAAAAAAAAAAAAAAA-- --AAAAAAAAAAAAAAAAAAAAAA-- --AAAAAAAAAAAAAAAAAAAAAA-- --AAAAAAAAAAAAAAAAAAAAAA-- ---AAAAAAAAAAAAAAAAAAAA--- -----AAAAAAAAAAAAAAAA----- -----AAAAAAAAAAAAAAAA----- -----AAAAAAAAAAAAAAAA----- -----AAAAAAAAAAAAAAAA----- -----AAAAAAAAAAAAAAAA----- -----AAAAAAAAAAAAAAAA----- ------AAAAAAAAAAAAAA------ ------AAAAAAAAAAAAAA------ ------AAAAAAAAAAAAAA------ ------AAAAAAAAAAAAAA------ -------AAAAAAAAAAAA------- -------AAAAAAAAAAAA------- -------AAAAAAAAAAAA------- -------AAAAAAAAAAAA------- -------AAAAAAAAAAAA------- -------AAAAAAAAAAAA------- --------AAAAAAAAAA-------- ---------AAAAAAAA--------- -------------------------- -------------------------- -------------------------- -------------------------- 
------AAAAAAAAAAAAAA------ ------AAAAAAAAAAAAAA------ ------AAAAAAAAAAAAAA------ ------AAAAAAAAAAAAAA------ ------AAAAAAAAAAAAAA------ ------AAAAAAAAAAAAAA------ ------AAAAAAAAAAAAAA------ ------AAAAAAAAAAAAAA------ ------AAAAAAAAAAAAAA------ ------AAAAAAAAAAAAAA------ ------AAAAAAAAAAAAAA------ -------AAAAAAAAAAAA------- -------AAAAAAAAAAAA------- --------AAAAAAAAAA-------- -------------------------- -------------------------- -------------------------- ----------AAAAAA---------- ---------AAAAAAAA--------- ---------AAAAAAAA--------- ---------AAAAAAAA--------- ---------AAAAAAAA--------- ----------AAAAAA---------- -------------------------- -------------------------- -------------------------- -------------------------- -------------------------- -------------------------- 
