model
size = 32 29 22, scale = 0.05, origin = -y
material 
  colors = A:#F9F B:#F9C C:#FFF D:#FF9 E:#F0C F:#001 G:#906 H:#C39 I:#EEE J:#FCF K:#C0C L:#9CF M:#0FF N:#FCC O:#63F P:#F6F Q:#3FF
voxels
228-G6-G23-3G-2G-3G22-3G-2G-3G23-G6-G701-2(2G27-2G-)G26-G2-2(G-)G23-GEG-2G-GJG22-G2JG2PG2JG22-G2J4G2JG22-GJG4-GJG23-G6-G570-5B6-5B16-2(B-)B6-2(B-)B20-2E29-2K2E27-E2K3E25-2EK5E23-3EK6E21-12E19-2(14E18-)14E19-5E2-5E21-3E4-3E534-5B6-5B16-5B6-5B880-4B8-4B16-B2AB8-3DB2(16-4B8-4B)17-2(3B8-3B18-)3B8-3B721-4B8C4B5(16-B3A8C3DB)17-3B8C2AB21-8C25-6C26-6C27-4C117-2F14-2F16-2F10-2F49-2F12-2F13-3F2(3-F3-2F)16-F3-4F3-F17-3F-3C4-3C-3F17-C3HC2-C3HC20-C2FHC2-CH2FC20-CMF2C2-2CFMC21-3C4-3C147-16B6(16-B9A5DB)17-3B8D3B2(18-4B6D4B)18-5B4D5B18-14B19-12B20-12B19-6B2F6B18-BD10BDB16-7B4F7B15-BNH2BF4BF2BHNB16-B2HD3B2F3BD2HB17-BD3B4F3BDB18-BA3I4B3IAB18-BI3EI2BI3EIB18-BI2FEI2BIE2FIB19-DQF2I2B2IFAB20-BA2I4B2IAB22-8B115-18B5(14-B16AB)15-5(B13ADB16-)B13ADB17-3(B12AB18-)B12AB16-B14ADAB15-B13ADB16-B11A3DB17-3(B10A2DB18-)B10A2DB19-11AB20-O10AB21-10B22-B8-B82-18B8(14-B16AB)15-3(B13ADB16-)B13ALB17-5(B12AB18-)5(B10A2DB18-)B10A2DB17-BHO9A2DHB16-B2HA3BA4BD2HB17-2HA3-B4-B2H17-B-2B8-2B-B16-2B12-2B15-18B8(14-B16AB)15-3(B13ADB16-)B13ALB16-B13ALB17-4(B12AB18-)5(B10A2DB18-)B10A2DB17-2B12A2B16-6B4A6B16-4B2-BA2B2-4B16-4B3-2B3-4B16-2B12-2B15-18B8(14-B16AB)15-3(B13ADB16-)B13ALB16-B13ALB17-4(B12AB18-)4(B10A2DB18-)B10A2DB19-B9ADB20-2B8A2B22-2B4A2B26-4B29-3B30-B18-26B6-4B16A2D4B8-3(2B16A2D2B10-)2B16A2D2B11-B16A2DB13-2(B16AB14-B16AB15-4(B14AB16-)B14AB17-8(B12AB18-)B12AB19-B10AB20-2B8A2B22-8B111-26B6-2B18A2DAD2B8-4(B17A2DAB10-)2B16A2D2B12-)B16AB14-B16AB15-4(B14AB16-)B14AB6-C3-C2-C3-B12AB2-C3-C5-2(C2-)B12AB-C3-C5-C-C2-C-B13AC2-2C7-C-C3-B12AB2-C3-C6-C4-B12AB5-C12-3(B12AB18-)B12AB19-B10AB20-2B8A2B22-8B111-26B6-6B14A6B8-3(4B14A4B10-)4B14A4B11-3B14A3B14-4(B14AB16-)2B12A2B16-2B12A2B15-2C2B10A2B2C4-3C2-C2-4C14B9C2-7C14B8C3-7C14B7C4-5C3-3B6A3B3-5C5-3C4-2B8A2B5-2C13-3(2B8A2B20-)3B6A3B21-10B23-8B149-2(14B18-)4(4B4A6B18-)4(14B18-)14B19-12B20-12B21-10B120-6B25-3(8B24-)8B25-6B282-4B2(28-B2AB)28-4B767-7B23-11B20-B3A10B18-B2AB4-7B17-B2AB7-5B16-4B9-4B29-3(3B30-)2B30-3B5(30-2B)29-5(3B28-)3B29-2B213-7B23-2B6AD4B18-B13AB17-B3A4B7AB16-B2AB4-3B5AB15-4B7-2B4(3AB28-B)2AB29-BAB29-4(B2AB28-)BAB28-B2AB27-3(B3AB26-)B3AB27-B2AB27-BA2B28-2B182-7B23-2B7A4B18-B13AB17-B3A4B7AB16-B2AB4-3B5AB15-4B7-2B4AB27-3(B3AB28-)B2AB28-B3A4(B28-B2A)B27-B3AB27-B2AB27-2(B3AB26-)2(B4AB25-)B4AB26-B2A2B27-3B181-6B24-2B6A4B19-B12A2B17-B3A5B6AB16-B2AB5-2B5AB15-4B7-2B3(3AB28-B)2(2AB29-B2AB28-B)2(2AB28-B)2AB27-B2AB28-2(B2AB27-)3(B3AB26-)B3AB27-BA2B28-2B213-7B24-12B19-4B4-7B17-3B8-5B16-3B10-4B29-2(3B30-)3B29-2(3B30-)3(2B30-)2B29-3B29-2B29-2(3B28-)2(4B27-)4B28-2B199-
