model
size = 30 30 11, scale = 0.05, origin = -y
material 
  colors = A:#F9F B:#CFF C:#9FF D:#FF9 E:#036 F:#001 G:#F60 H:#0CF I:#FFF J:#EEE K:#FF0 L:#F0C M:#0CC N:#039 O:#9CF P:#0FF Q:#FCC R:#3FF S:#6FF
voxels
------------------------------ ------------------------------ ------------------------------ ------------------------------ ------------------------------ ------------EEEEEE------------ -----------EEEEEEEE----------- ----------EEEEEEEEEE---------- ----------EEEEEEEEEE---------- ----------EEEEEEEEEE---------- ----------EEEEEEEEEE---------- -----------EEEEEEEE----------- -----------EE-EE-EE----------- ------------------------------ ------------------------------ ------FF--------------FF------ --------FF----------FF-------- ------------------------------ -------FF------------FF------- ----FFF---F---FF---F---FF----- ---------F---FFFF---F--------- ------FFF-III----III-FFF------ ---------INNNI--INNNI--------- ---------IFFNI--INFFI--------- ---------IPFII--IIFPI--------- ----------III----III---------- ------------------------------ ------------------------------ ------------------------------ ------------------------------ 
------------------------------ ------------------------------ ------------------------------ ------------------------------ ------------------------------ ----------CCCCCCCCCC---------- ---------BBBBBBBBDDBBB-------- --------BBBAAAAAADDBBBB------- --------BBBDDDDDDDDBBB-------- --------BBBBDDDDDDBBBB-------- --------BBBBDDDDDDBBBB-------- --------BBBBBDDDDBBBBB-------- --------BBBBBBBBBBBBBB-------- ---------BBBBBBBBBBBB--------- ---------BBBBBMMBBBBB--------- --------BBBBBBBBBBBBBB-------- --------BDBBBBLLBBBBDB-------- ------BBBBBBBFFFFBBBBBBB------ -------BQMBBFBBBBFBBMQB------- -------BMMDBBBFFBBBDMMB------- --------BDBBBFFFFBBBDB-------- --------BBJJJBBBBJJJBB-------- --------BBLLLJBBJLLLJB-------- --------BBFFLJBBJLFFJB-------- ---------BRFJJBBJJFAB--------- ---------BBJJBBBBJJBB--------- -----------BBBBBBBB----------- ------------------------------ ------------------------------ ------------------------------ 
------------------------------ ------------------------------ ------------------------------ ------------------------------ ------------------------------ ---------CCCCCCCCCCCC--------- --------CBBBBBBBBBBBBCC------- --------BBBAAAAAAAABBBB------- -------BBBBAAAAAAAABBBB------- -------BAAAAAAAAAAAAADB------- -------BBAAAAAAAAAAAADB------- -------BBAAAAAAAAAAAADB------- -------BBAAAAAAAAAAAADB------- --------BAAAAAAAAAAAAB-------- --------BAAAAAAAAAAAAB-------- --------BAAAAAAAAAAAAB-------- --------BAAAAAAAAAAAAB-------- ------BBAAAAAAAAAAAAADBB------ -------BAAAAAAAAAAAAADB------- -------BAAAAAAAAAAADDDB------- --------BAAAAAAAAAADDB-------- --------BAAAAAAAAAADDB-------- --------BBAAAAAAAAADDB-------- --------BBAAAAAAAAADDB-------- ---------BAAAAAAAAAAB--------- ---------BBAAAAAAAAAB--------- ----------BBBBBBBBBB---------- ----------B--------B---------- ------------------------------ ------------------------------ 
---------G-G-G--G-G-G--------- ------------------------------ ------------------------------ ------------------------------ ------------------------------ --------CCCCCCCCCCCCCC-------- -------CBBBBBBBBBBBBBBC------- -------CBBBAAAABBBBBBBCB------ -------BBBBAAAABBBBBBBBB------ -------BAAAAAAABBBBBBBB------- -------BAAAAAAAAAAAAADB------- -------BAAAAAAAAAAAAADB------- -------BAAAAAAAAAAAAADB------- -------BAAAAAAAAAAAAAOB------- --------BAAAAAAAAAAAAB-------- --------BAAAAAAAAAAAAB-------- --------BAAAAAAAAAAAAB-------- --------BAAAAAAAAAAAAB-------- --------BAAAAAAAAAAAAB-------- --------BAAAAAAAAAADDB-------- --------BAAAAAAAAAADDB-------- --------BAAAAAAAAAADDB-------- --------BBAAAAAAAAADDB-------- --------BBAAAAAAAAADDB-------- --------BBAAAAAAAAADDB-------- -------BEBBAAAAAAAADDEB------- -------BEEABBBABBBBDEEB------- --------EES---B----REE-------- -------B-BB--------BB-B------- -------BB------------BB------- 
---------G-G-G--G-G-G--------- ------------------------------ ------------------------------ ------------------------------ -----------HH----HH----------- --------CCCBBCCCCBBCCC-------- -------CBBBBBBBBBBBBBBC------- -------BBBBAAAABBBBBBBBB------ -------BBBBAAAABBBBBBBBB------ -------BAAAAAAAAABBBBBBB------ -------BAAAAAAAAAAAAADB------- -------BAAAAAAAAAAAAADB------- -------BAAAAAAAAAAAAADB------- -------BAAAAAAAAAAAAAOB------- -------BAAAAAAAAAAAAAOB------- --------BAAAAAAAAAAAAB-------- --------BAAAAAAAAAAAAB-------- --------BAAAAAAAAAAAAB-------- --------BAAAAAAAAAAAAB-------- --------BAAAAAAAAAADDB-------- --------BAAAAAAAAAADDB-------- --------BAAAAAAAAAADDB-------- --------BBAAAAAAAAADDB-------- --------BBAAAAAAAAADDB-------- --------BBAAAAAAAAADDB-------- -------BBBBAAAAAAAAAABB------- -------BBBBBBAAAABBBBBB------- -------BBBB--BBBB--BBBB------- -------BBBB---BB---BBBB------- -------BB------------BB------- 
---------GGGGG--GGGGG--------- -----------KK----KK----------- -----------GG----GG----------- -----------KK----KK----------- ----------HGGH--HGGH---------- --------CCBBBBCCBBBBCC-------- -------CBBBBBBBBBBBBBBCC------ -------BBBBAAAABBBBBBBBB------ ------BBBBBAAAABBBBBBBBB------ -------BAAAAAAAAABBBBBBB------ -------BAAAAAAAAAAAAADB------- ------CBAAAAAAAAAAAAADBC------ ---CCCCBAAAAAAAAAAAAADBCCCC--- ---CCCBBAAAAAAAAAAAAAOBBCCC--- ---CBBBBAAAAAAAAAAAAAOBBBBC--- ----BBBBBAAAAAAAAAAAABBBBB---- ------BBBAAAAAAAAAAAABBB------ --------BAAAAAAAAAAAAB-------- --------BAAAAAAAAAAAAB-------- --------BAAAAAAAAAADDB-------- --------BAAAAAAAAAADDB-------- --------BAAAAAAAAAADDB-------- --------BBAAAAAAAAADDB-------- --------BBAAAAAAAAADDB-------- ---------BAAAAAAAAADB--------- ---------BBAAAAAAAABB--------- -----------BBAAAABB----------- -------------BBBB------------- --------------BBB------------- ---------------B-------------- 
-----------GG----GG----------- -----------KK----KK----------- -----------GG----GG----------- -----------KK----KK----------- ----------HGGH--HGGH---------- --------CCBBBBCCBBBBCC-------- -------CBBBBBBBBBBBBBBCC------ -------BBBBAAAAAAAABBBBB------ ------BBBBBAAAABBBBBBBBB------ HH----BBAAAAAAAAABBBBBBB----HH HHHH-CCBAAAAAAAAAAAAAABBC-HHHH HHHCCCCBAAAAAAAAAAAAAABCCCCHHH -HCCCCCBAAAAAAAAAAAAAABCCCCCH- -CCCCCCBAAAAAAAAAAAAAABCCCCCC- --CCBBBBAAAAAAAAAAAAAABBBBCC-- ---CBBBCBAAAAAAAAAAAABCBBBC--- ----BBBBBAAAAAAAAAAAABBBBB---- --------BAAAAAAAAAAAAB-------- --------BAAAAAAAAAAAAB-------- --------BAAAAAAAAAAAAB-------- --------BAAAAAAAAAAAAB-------- --------BAAAAAAAAAAAAB-------- --------BBAAAAAAAAAAAB-------- --------BBAAAAAAAAAAAB-------- ---------BAAAAAAAAAAB--------- ---------BBAAAAAAAABB--------- -----------BBBBBBBB----------- ------------------------------ ------------------------------ ------------------------------ 
-----------GG----GG----------- ------------------------------ ------------------------------ ------------------------------ -----------HH----HH----------- --------CCCBBCCCCBBCCC-------- -------CBBBBBBBBBBBBBBCC------ ------BBBBBAAAAAAAABBBBB------ ------BBBBBAAAABBBBBBBBB------ ------BBAAAAAAAAABBBBBBB------ -C-----BAAAAAAAAAAAAAABB----C- -CCC---BAAAAAAAAAAAAAAB---CCC- --CCCCCBAAAAAAAAAAAAAABCCCCC-- --CCCCCBAAAAAAAAAAAAAABCCCCC-- ----CCCBAAAAAAAAAAAAAABCCC---- ----CCCCBAAAAAAAAAAAABCCCC---- --------BAAAAAAAAAAAAB-------- --------BAAAAAAAAAAAAB-------- --------BAAAAAAAAAAAAB-------- --------BAAAAAAAAAAAAB-------- --------BAAAAAAAAAAAAB-------- --------BAAAAAAAAAAAAB-------- --------BBAAAAAAAAAAAB-------- --------BBAAAAAAAAAAAB-------- ---------BAAAAAAAAAAB--------- ---------BBAAAAAAAABB--------- -----------BBBBBBBB----------- ------------------------------ ------------------------------ ------------------------------ 
-----------G------G----------- ------------------------------ ------------------------------ ------------------------------ ------------------------------ --------CCCCCCCCCCCCCC-------- -------CBBBBBBBBBBBBBBCC------ ------BBBBBAAAAAAAABBBBB------ ------BBBBBAAAABBBBBBBBB------ ------BBAAAAAAABBBBBBBBB------ -------BAAAAAAAAAAAAAABB------ -------BAAAAAAAAAAAAAAB------- -------BAAAAAAAAAAAAAAB------- -----CCBAAAAAAAAAAAAAABCC----- -----CCBAAAAAAAAAAAAAABCC----- --------BAAAAAAAAAAAAB-------- --------BAAAAAAAAAAAAB-------- --------BAAAAAAAAAAAAB-------- --------BAAAAAAAAAAAAB-------- --------BAAAAAAAAAAAAB-------- --------BAAAAAAAAAAAAB-------- --------BAAAAAAAAAAAAB-------- --------BAAAAAAAAAAAAB-------- --------BAAAAAAAAAAAAB-------- ---------BAAAAAAAAAAB--------- ---------BBAAAAAAAABB--------- -----------BBBBBBBB----------- ------------------------------ ------------------------------ ------------------------------ 
------------------------------ ------------------------------ ------------------------------ ------------------------------ ------------------------------ ---------CCCCCCCCCCCC--------- -------CCCBBBBBBBBBBCCC------- ------BBBBBBBBBBBBBBBBBB------ -------BAAAAAAAAAAAAAAB------- -------BAAAAAAAAAAAAAAB------- -------BAAAAAAAAAAAAAAB------- -------BAAAAAAAAAAAAAAB------- -------BBAAAAAAAAAAAABB------- -------BBAAAAAAAAAAAABB------- --------BBAAAAAAAAAABB-------- --------BBBBBBBBBBBBBB-------- --------BBBBBBBBBBBBBB-------- --------BBBBBBBBBBBBBB-------- ---------BBBAAAAAABBB--------- ---------BBAAAAAAAABB--------- ---------BBAAAAAAAABB--------- ---------BBAAAAAAAABB--------- ---------BBAAAAAAAABB--------- ---------BBBAAAAAABBB--------- ----------BBBBBBBBBB---------- -----------BBBBBBBB----------- ------------------------------ ------------------------------ ------------------------------ ------------------------------ 
------------------------------ ------------------------------ ------------------------------ ------------------------------ ------------------------------ ------------------------------ ----------BBBBBBBBBB---------- ---------BBBBBBBBBBBB--------- --------BBBBBBBBBBBBBB-------- --------BBBBBBBBBBBBBB-------- --------BBBBBBBBBBBBBB-------- --------BBBBBBBBBBBBBB-------- ---------BBBBBBBBBBBB--------- ---------BBBBBBBBBBBB--------- ----------BBBBBBBBBB---------- ------------------------------ ------------------------------ ------------------------------ ------------BBBBBB------------ -----------BBBBBBBB----------- -----------BBBBBBBB----------- -----------BBBBBBBB----------- -----------BBBBBBBB----------- ------------BBBBBB------------ ------------------------------ ------------------------------ ------------------------------ ------------------------------ ------------------------------ ------------------------------ 
