model
size = 32 32 19, scale = 0.05, origin = -y
material 
  colors = A:#6F6 B:#6C0 C:#FF9 D:#CC9 E:#001 F:#FFC G:#6C3 H:#FFF I:#996 J:#9F0 K:#F93 L:#CC6 M:#F0C N:#9CF O:#FF0 P:#FCC Q:#3FF
voxels
298-3(3B6-3B20-)3B6-3B948-2(JA8-AJ20-)2B8-2B695-F4IF25-2I4F2I24-8F24-2F4I2F24-2I4F2I24-8F24-3F2I3F25-2I2F2I22-3A-6F-3A18-3A2-4F2-3A112-2E14-2E16-2E10-2E49-2E12-2E13-3E2(3-E3-2E)16-E3-4E3-E17-3E-3H4-3H-3E17-H3KH2-H3KH20-H2EKH2-HK2EH20-HOEKH2-HKEOH21-3H4-3H58-2D218-10A20-9A2C3A17-B9A2C3AB16-2B8A2C2A2B16-B9A2C3AB16-2AB7A2CAB2A17-3A8C2AB18-AB2A6C2(AB)18-B3A6C3AB18-2B3A4C3ABA18-B12AB19-2(AB)8A20-12A19-AB3AF2AF5A18-AC2(2A2E)4A16-8A2E8A15-AP5A2E5APA16-3AC3A2E7A17-AC3A2E7A18-14A18-2A3M4A2M3A18-2A2EM4AME3A19-AQE6AE2A20-12A25-2D249-12A18-16A16-16A15-B16AB14-18A15-2(14ACA16-)14ACB16-14ACA16-B13ACA16-14ACA17-3(14A18-)14A16-15AC2A15-14ACA16-12A3CA17-3(11A2CA18-)11AC2A19-12A20-12A21-10A245-12A18-16A15-5(18A14-)18A15-3(14ACA16-)14ANA17-5(14A18-)4(11A2CA18-)2(11AC2A18-)D12AD17-4D8A4D17-3D8-3D17-D-D10-D-D2(16-2D12-2D)17-D12-D18-2G10-2G17-3G10-3G16-2G12A2G15-G16AG6(14-18A)15-3(14ACA16-)14ANA16-14ANA17-4(14A18-)4(11A2CA18-)2(11AC2A18-)D12AD17-4D8A4D16-4D3-2D3-4D16-3D4-2D4-3D2(16-2D12-2D)17-2D10-2D17-2G12-2G16-3G10-3G16-2G12A2G15-G16AG4(14-18A)14-B16AB14-18A15-14ACA16-14ACA8-2(L-)L3-14ACA3-2(L-)L3B-2B2-14ANA2-2B-3B-BA2BAB-14ANA-BA2BAB2-J2AB2A2B14A2B2AB2AJ2-JBA2B2AB14AB2A2BABJ3-JBA4B14A4BABJ6-3B2-14A2-3B9-L3-11A2CA3-L14-3(11A2CA18-)11AC2A19-10ACA20-12A22-8A27-2(2D30-)2D56-2D10-2D80-3G12A3G14-G16AG4(14-16ACA)2(14-18A)15-2(16A16-)B14AB2(16-16A)17-8(14A18-)14A19-12A20-12A22-8A246-12A18-16A15-4(16ACA14-)18A14-18A15-4(16A16-)16A17-8(14A18-)14A19-12A20-12A22-8A246-12A18-15A17-16A15-3(16ACA14-)18A14-18A15-4(16A16-)16A17-8(14A18-)14A19-12A20-12A22-8A246-12A19-13A18-15A16-18A14-B16AB14-18A15-5(16A16-)16A17-3(14A18-)14A19-5(12A20-)12A21-10A23-8A279-10A21-12A19-7(14A18-)14A19-12A20-12A21-10A120-6A25-3(8A24-)8A25-6A378-3(4A28-)4A863-7A23-11A20-14A18-4A5-5AJ17-4A7-A2-2J16-4A863-7A23-8AC4A18-14AJ17-6A3-5A2J16-4A7-2A19-4A12-J63-J786-7A23-13A18-15A17-6A4-6A16-4A7-3A-2A15-4A11-3A30-A30-3A30-A754-6A24-12A19-15A17-7A3-6A16-4A6-4A-2A15-4A12-A63-A817-7A24-12A19-4A4-7A17-3A8-5A16-3A13-A802-
