model
size = 31 29 20, scale = 0.05, origin = -y
material 
  colors = A:#F00 B:#FF9 C:#700 D:#001 E:#FFF F:#F0C G:#9CF H:#0FF I:#FCC J:#EEE K:#A00 L:#3FF
voxels
-----AAAAA------AAAAA---------- -----A-A-A------A-A-A---------- ------------------------------- ------------------------------- ------------------------------- ------------------------------- ------------------------------- ------------------------------- ------------------------------- ------------------------------- ------------------------------- ------------------------------- ------------------------------- ------------------------------- ------------------------------- ------------------------------- ------------------------------- ------------------------------- ------------------------------- ------------------------------- ------------------------------- ------------------------------- ------------------------------- ------------------------------- ------------------------------- ------------------------------- ------------------------------- ------------------------------- ------------------------------- 
-----AAAAA------AAAAA---------- -----AAAAA------AAAAA---------- ------------------------------- ------------------------------- ------------------------------- ------------------------------- ------------------------------- ------------------------------- ------------------------------- ------------------------------- ------------------------------- ------------------------------- ------------------------------- ------------------------------- ------------------------------- ------------------------------- ------------------------------- ------------------------------- ------------------------------- ------------------------------- ------------------------------- ------------------------------- ------------------------------- ------------------------------- ------------------------------- ------------------------------- ------------------------------- ------------------------------- ------------------------------- 
-----AAAA--------AAAA---------- -----AAAA--------ABBA---------- -----AAAA--------AAAA---------- -----AAAA--------AAAA---------- ------AAA--------AAA----------- ------AAA--------AAA----------- ------AAA--------AAA----------- ------------------------------- ------------------------------- ------------------------------- ------------------------------- ------------------------------- ------------------------------- ------------------------------- ------------------------------- ------------------------------- ------------------------------- ------------------------------- ------------------------------- ------------------------------- ------------------------------- ------------------------------- ------------------------------- ------------------------------- ------------------------------- ------------------------------- ------------------------------- ------------------------------- ------------------------------- 
-----AAAACCCCCCCCAAAA---------- -----AAAACCCCCCCCBBBA---------- -----AAAACCCCCCCCBBBA---------- -----AAAACCCCCCCCBBBA---------- -----AAAACCCCCCCCBBBA---------- -----AAAACCCCCCCCBBBA---------- ------AAACCCCCCCCAAA----------- ---------CCCCCCCC-------------- ----------CCCCCC--------------- ----------CCCCCC--------------- -----------CCCC---------------- ------------------------------- ------------------------------- ------------------------------- ----DD--------------DD--------- ------DD----------DD----------- ------------------------------- -----DD------------DD---------- --DDD---D---DD---D---DD-------- -------D---DDDD---D------------ ----DDD-EEE----EEE-DDD--------- -------ECCCE--ECCCE------------ -------EDDCE--ECDDE------------ -------EHDCE--ECDHE------------ --------EEE----EEE------------- ------------------------------- ------------------------------- ------------------------------- ------------------------------- 
-----AAAAAAAAAAAAAAAA---------- -----AAAAAAAAAABBBBBA---------- -----AAAAAAAAAABBBBBA---------- -----AAAAAAAAAABBBBBA---------- -----AAAAAAAAAABBBBBA---------- -----AAAAAAAAAABBBBBA---------- -----AAAAAAAAAABBBBBA---------- ------AAABBBBBBBBAAA----------- ------AAAABBBBBBAAAA----------- ------AAAABBBBBBAAAA----------- ------AAAAABBBBAAAAA----------- ------AAAAAAAAAAAAAA----------- -------AAAAAKKAAAAA------------ -------AAAAAAAAAAAA------------ ------AAAADDDDDDAAAA----------- ------ABAADDDDDDAAAA----------- ----AAAAAADJDDJDAAAAAA--------- -----AICAAAAAAAAAACIA---------- -----ACCBAAADDAAAACCA---------- ------ABAAADDAAAAAAA----------- ------AAAAAAAAAAAAAA----------- ------AAFFFAAAAFFAAA----------- ------AADDFAAAAFDAAA----------- -------ALDAAAAAADAA------------ -------AAAAAAAAAAAA------------ ---------AAAAAAAA-------------- ------------------------------- ------------------------------- ------------------------------- 
----AAAAAAAAAAAAAAAAAA--------- ----AAAAAAAAAAAAAAAAAA--------- ----AAAAAAAAAAAAAAAAAA--------- ----AAAAAAAAAAAAAAAAAA--------- ----AAAAAAAAAAAAAAAAAA--------- ----AAAAAAAAAAAAAAAAAA--------- -----AAAAAAAAAAAAAABA---------- -----AAAAAAAAAAAAAABA---------- -----AAAAAAAAAAAAAABA---------- -----AAAAAAAAAAAAAABA---------- -----AAAAAAAAAAAAAABA---------- -----AAAAAAAAAAAAAABA---------- ------AAAAAAAAAAAAAA----------- ------AAAAAAAAAAAAAA----------- ------AAAAAAAAAAAAAA----------- ------AAAAAAAAAAAAAA----------- ----AAAAAAAAAAAAAAABAA--------- -----AAAAAAAAAAAAAABA---------- -----AAAAAAAAAAAABBBA---------- ------AAAAAAAAAAABBA----------- ------AAAAAAAAAAABBA----------- ------AAAAAAAAAAABBA----------- ------AAAAAAAAAAABAA----------- -------AAAAAAAAAAAA------------ -------CAAAAAAAAAAA------------ --------AAAAAAAAAA------------- --------A--------A------------- ------------------------------- ------------------------------- 
----AAAAAAAAAAAAAAAAAA--------- ----AAAAAAAAAAAAAAAAAA--------- ----AAAAAAAAAAAAAAAAAA--------- ----AAAAAAAAAAAAAAAAAA--------- ----AAAAAAAAAAAAAAAAAA--------- ----AAAAAAAAAAAAAAAAAA--------- ----AAAAAAAAAAAAAAAAAA--------- ----AAAAAAAAAAAAAAAAAA--------- ----AAAAAAAAAAAAAAAAAA--------- -----AAAAAAAAAAAAAABA---------- -----AAAAAAAAAAAAAABA---------- -----AAAAAAAAAAAAAABA---------- -----AAAAAAAAAAAAAAGA---------- ------AAAAAAAAAAAAAA----------- ------AAAAAAAAAAAAAA----------- ------AAAAAAAAAAAAAA----------- ------AAAAAAAAAAAAAA----------- ------AAAAAAAAAAAAAA----------- ------AAAAAAAAAAABBA----------- ------AAAAAAAAAAABBA----------- ------AAAAAAAAAAABBA----------- ------AAAAAAAAAAABBA----------- ------AAAAAAAAAAABAA----------- ------AAAAAAAAAAABAA----------- -----ACCAAAAAAAAAAACA---------- -----ACCAAAAAAAAABCCA---------- ------CCA---A----ACC----------- -----A-AA--------AA-A---------- -----AA------------AA---------- 
----AAAAAAAAAAAAAAAAAA--------- ----AAAAAAAAAAAAAAAAAA--------- ----AAAAAAAAAAAAAAAAAA--------- ----AAAAAAAAAAAAAAAAAA--------- ----AAAAAAAAAAAAAAAAAA--------- ----AAAAAAAAAAAAAAAAAA--------- ----AAAAAAAAAAAAAAAAAA--------- ----AAAAAAAAAAAAAAAAAA--------- ----AAAAAAAAAAAAAAAAAA--------- -----AAAAAAAAAAAAAABA---------- -----AAAAAAAAAAAAAABA---------- -----AAAAAAAAAAAAAABA---------- -----AAAAAAAAAAAAAAGA---------- -----AAAAAAAAAAAAAAGA---------- ------AAAAAAAAAAAAAA----------- ------AAAAAAAAAAAAAA----------- ------AAAAAAAAAAAAAA----------- ------AAAAAAAAAAAAAA----------- ------AAAAAAAAAAABBA----------- ------AAAAAAAAAAABBA----------- ------AAAAAAAAAAABBA----------- ------AAAAAAAAAAABBA----------- ------AAAAAAAAAAABAA----------- ------AAAAAAAAAAABAA----------- -----AAAAAAAAAAAAAAAA---------- -----AAAAAAAAAAAAAAAA---------- -----AAAA--AAAA--AAAA---------- -----AAAA---AA---AAAA---------- -----AA------------AA---------- 
----AAAAAAAAAAAAAAAAAA--------- ----AAAAAAAAAAAAAAAAAA--------- ----AAAAAAAAAAAAAAAAAA--------- ----AAAAAAAAAAAAAAAAAA--------- ----AAAAAAAAAAAAAAAAAA--------- ----AAAAAAAAAAAAAAAAAA--------- ----AAAAAAAAAAAAAAAAAA--------- ----AAAAAAAAAAAAAAAAAA--------- ----AAAAAAAAAAAAAAAAAA--------- -----AAAAAAAAAAAAAABA---------- -----AAAAAAAAAAAAAABA---------- -----AAAAAAAAAAAAAABA---------- -----AAAAAAAAAAAAAAGA---------- -----AAAAAAAAAAAAAAGA---------- ------AAAAAAAAAAAAAA----------- ------AAAAAAAAAAAAAA----------- ------AAAAAAAAAAAAAA----------- ------AAAAAAAAAAAAAA----------- ------AAAAAAAAAAABBA----------- ------AAAAAAAAAAABBA----------- ------AAAAAAAAAAABBA----------- ------AAAAAAAAAAABBA----------- ------AAAAAAAAAAABAA----------- -------AAAAAAAAAABA------------ -------AAAAAAAAAAAA------------ ---------AAAAAAAA-------------- -----------AAAA---------------- ------------AAA---------------- -------------A----------------- 
AAAAAAAAAAAAAAAAAAAAAAAAAA----- AAAAAAAAAAAAAAAAAAAABBAAAA----- --AAAAAAAAAAAAAAAAAABAAA------- --AAAAAAAAAAAAAAAAAABAAA------- --AAAAAAAAAAAAAAAAAABAAA------- --AAAAAAAAAAAAAAAAAABBAA------- ---AAAAAAAAAAAAAAAAABBA-------- ----AAAAAAAAAAAAAAAAAA--------- ----AAAAAAAAAAAAAAAAAA--------- -----AAAAAAAAAAAAAAAA---------- -----AAAAAAAAAAAAAAAA---------- -----AAAAAAAAAAAAAAAA---------- -----AAAAAAAAAAAAAAAA---------- -----AAAAAAAAAAAAAAAA---------- ------AAAAAAAAAAAAAA----------- ------AAAAAAAAAAAAAA----------- ------AAAAAAAAAAAAAA----------- ------AAAAAAAAAAAAAA----------- ------AAAAAAAAAAAAAA----------- ------AAAAAAAAAAAAAA----------- ------AAAAAAAAAAAAAA----------- ------AAAAAAAAAAAAAA----------- ------AAAAAAAAAAAAAA----------- -------AAAAAAAAAAAA------------ -------AAAAAAAAAAAA------------ ---------AAAAAAAA-------------- ------------------------------- ------------------------------- ------------------------------- 
AAAAAAAAAAAAAAAAAAAAAAAAAA----- AAAAAAAAAAAAAAAAAAAABBABAA----- --AAAAAAAAAAAAAAAAAABBAA------- --AAAAAAAAAAAAAAAAAABBAA------- --AAAAAAAAAAAAAAAAAABBAA------- --AAAAAAAAAAAAAAAAAABBAA------- --AAAAAAAAAAAAAAAAAABBAA------- ----AAAAAAAAAAAAAAAAAA--------- ----AAAAAAAAAAAAAAAAAA--------- -----AAAAAAAAAAAAAAAA---------- -----AAAAAAAAAAAAAAAA---------- -----AAAAAAAAAAAAAAAA---------- -----AAAAAAAAAAAAAAAA---------- -----AAAAAAAAAAAAAAAA---------- ------AAAAAAAAAAAAAA----------- ------AAAAAAAAAAAAAA----------- ------AAAAAAAAAAAAAA----------- ------AAAAAAAAAAAAAA----------- ------AAAAAAAAAAAAAA----------- ------AAAAAAAAAAAAAA----------- ------AAAAAAAAAAAAAA----------- ------AAAAAAAAAAAAAA----------- ------AAAAAAAAAAAAAA----------- -------AAAAAAAAAAAA------------ -------AAAAAAAAAAAA------------ ---------AAAAAAAA-------------- ------------------------------- ------------------------------- ------------------------------- 
AAAAAAAAAAAAAAAAAAAAAAAAAA----- AAAAAAAAAAAAAAAAAAAABBABAA----- --AAAAAAAAAAAAAAAAAABBAA------- --AAAAAAAAAAAAAAAAAABBAA------- --AAAAAAAAAAAAAAAAAABBAA------- --AAAAAAAAAAAAAAAAAABBAA------- --AAAAAAAAAAAAAAAAAABBAA------- ----AAAAAAAAAAAAAAAAAA--------- ----AAAAAAAAAAAAAAAAAA--------- -----AAAAAAAAAAAAAAAA---------- -----AAAAAAAAAAAAAAAA---------- -----AAAAAAAAAAAAAAAA---------- -----AAAAAAAAAAAAAAAA---------- -----AAAAAAAAAAAAAAAA---------- ------AAAAAAAAAAAAAA----------- ------AAAAAAAAAAAAAA----------- ------AAAAAAAAAAAAAA----------- ------AAAAAAAAAAAAAA----------- ------AAAAAAAAAAAAAA----------- ------AAAAAAAAAAAAAA----------- ------AAAAAAAAAAAAAA----------- ------AAAAAAAAAAAAAA----------- ------AAAAAAAAAAAAAA----------- -------AAAAAAAAAAAA------------ -------AAAAAAAAAAAA------------ ---------AAAAAAAA-------------- ------------------------------- ------------------------------- ------------------------------- 
AAAAAAAAAAAAAAAAAAAAAAAAAA----- AAAAAAAAAAAAAAAAAAAAAAAAAA----- --AAAAAAAAAAAAAAAAAAAAAA------- --AAAAAAAAAAAAAAAAAAAAAA------- --AAAAAAAAAAAAAAAAAAAAAA------- --AAAAAAAAAAAAAAAAAAAAAA------- ---AAAAAAAAAAAAAAAAAAAA-------- -----AAAAAAAAAAAAAAAA---------- -----AAAAAAAAAAAAAAAA---------- -----AAAAAAAAAAAAAAAA---------- -----AAAAAAAAAAAAAAAA---------- -----AAAAAAAAAAAAAAAA---------- -----AAAAAAAAAAAAAAAA---------- ------AAAAAAAAAAAAAA----------- ------AAAAAAAAAAAAAA----------- ------AAAAAAAAAAAAAA----------- ------AAAAAAAAAAAAAA----------- -------AAAAAAAAAAAA------------ -------AAAAAAAAAAAA------------ -------AAAAAAAAAAAA------------ -------AAAAAAAAAAAA------------ -------AAAAAAAAAAAA------------ -------AAAAAAAAAAAA------------ --------AAAAAAAAAA------------- ---------AAAAAAAA-------------- ------------------------------- ------------------------------- ------------------------------- ------------------------------- 
------AAAAAAAAAAAAAA----------- ------AAAAAAAAAAAAAA----------- ------AAAAAAAAAAAAAA----------- ------AAAAAAAAAAAAAA----------- ------AAAAAAAAAAAAAA----------- ------AAAAAAAAAAAAAA----------- ------AAAAAAAAAAAAAA----------- ------AAAAAAAAAAAAAA----------- ------AAAAAAAAAAAAAA----------- ------AAAAAAAAAAAAAA----------- ------AAAAAAAAAAAAAA----------- -------AAAAAAAAAAAA------------ -------AAAAAAAAAAAA------------ --------AAAAAAAAAA------------- ------------------------------- ------------------------------- ------------------------------- ----------AAAAAA--------------- ---------AAAAAAAA-------------- ---------AAAAAAAA-------------- ---------AAAAAAAA-------------- ---------AAAAAAAA-------------- ----------AAAAAA--------------- ------------------------------- ------------------------------- ------------------------------- ------------------------------- ------------------------------- ------------------------------- 
------------------------------- ------------------------------- ----------AAAA----------------- ----------AAAA----------------- ----------AAAA----------------- ----------AAAA----------------- ------------------------------- ------------------------------- ------------------------------- ------------------------------- ------------------------------- ------------------------------- ------------------------------- ------------------------------- ------------------------------- ------------------------------- ------------------------------- ------------------------------- ------------------------------- ------------------------------- ------------------------------- ------------------------------- ------------------------------- ------------------------------- ------------------------------- ------------------------------- ------------------------------- ------------------------------- ------------------------------- 
-------------AAAAAAA----------- -----------AAAAAAAAAAA--------- ----------AAAAAAAAAAAAAA------- ----------AAAA----AAAAAAA------ ----------AAAA-------AAAAA----- ----------AAAA---------AAAA---- ------------------------AAA---- -------------------------AAA--- --------------------------AAA-- ---------------------------AA-- ---------------------------AAA- ----------------------------AA- ----------------------------AA- ----------------------------AA- ----------------------------AA- ----------------------------AA- ---------------------------AAA- --------------------------AAA-- -------------------------AAA--- ------------------------AAA---- -----------------------AAA----- ----------------------AAA------ ----------------------AA------- ------------------------------- ------------------------------- ------------------------------- ------------------------------- ------------------------------- ------------------------------- 
-------------AAAAAAA----------- -----------AAAAAAAABAAAA------- ----------AAAAAAAAAAAAAAA------ ----------AAAAAAAAAAAAAAAA----- ----------AAAA----AAAAAAAAA---- ----------AAAA-------AAAAAA---- -----------------------AAAAA--- ------------------------AAAAA-- -------------------------AAAAA- --------------------------AAAA- ---------------------------AAA- ---------------------------AAAA ---------------------------AAAA ---------------------------AAAA ---------------------------AAAA ---------------------------AAA- --------------------------AAAA- -------------------------AAAAA- ------------------------AAAAA-- -----------------------AAAAA--- ----------------------AAAAA---- ----------------------AAAA----- ---------------------AAAA------ ---------------------AA-------- ------------------------------- ------------------------------- ------------------------------- ------------------------------- ------------------------------- 
-------------AAAAAAA----------- -----------AAAAAAAAAAAAA------- ----------AAAAAAAAAAAAAAA------ ----------AAAAAAAAAAAAAAAA----- ----------AAAA----AAAAAAAAA---- ----------AAAA-------AAAAAAA--- -----------------------AAAAA--- ------------------------AAAAA-- -------------------------AAAAA- --------------------------AAAA- --------------------------AAAAA ---------------------------AAAA ---------------------------AAAA ---------------------------AAAA ---------------------------AAAA --------------------------AAAAA --------------------------AAAA- -------------------------AAAAA- ------------------------AAAAA-- -----------------------AAAAAA-- ----------------------AAAAAA--- ---------------------AAAAAA---- ---------------------AAAAA----- ---------------------AAA------- ------------------------------- ------------------------------- ------------------------------- ------------------------------- ------------------------------- 
-------------AAAAAA------------ -----------AAAAAAAAAAAA-------- ----------AAAAAAAAAAAAAAA------ ----------AAAAAAAAAAAAAAAA----- ----------AAAA-----AAAAAAAA---- ----------AAAA-------AAAAAA---- -----------------------AAAAA--- ------------------------AAAAA-- -------------------------AAAA-- --------------------------AAAA- --------------------------AAAA- ---------------------------AAAA ---------------------------AAAA ---------------------------AAAA ---------------------------AAAA --------------------------AAAA- --------------------------AAAA- -------------------------AAAA-- ------------------------AAAAA-- -----------------------AAAAA--- ----------------------AAAAA---- ---------------------AAAAA----- ---------------------AAAA------ ---------------------AA-------- ------------------------------- ------------------------------- ------------------------------- ------------------------------- ------------------------------- 
------------------------------- ------------AAAAAAA------------ -----------AAAAAAAAAAAA-------- ----------AAAA----AAAAAAA------ ----------AAA--------AAAAA----- ----------AAA----------AAAA---- ------------------------AAA---- -------------------------AAA--- --------------------------AAA-- --------------------------AAA-- ---------------------------AAA- ----------------------------AA- ----------------------------AA- ----------------------------AA- ----------------------------AA- ---------------------------AAA- ---------------------------AA-- --------------------------AAA-- -------------------------AAA--- ------------------------AAAA--- -----------------------AAAA---- ----------------------AAAA----- ----------------------AA------- ------------------------------- ------------------------------- ------------------------------- ------------------------------- ------------------------------- ------------------------------- 
