model
size = 32, scale = 0.05, origin = -y
material 
  colors = A:#9CF B:#565656 C:#111 D:#C00 E:#FF3 F:#955516 G:#FC3 H:#9CC I:#D00 J:#960 K:#888 L:#B00 M:#690 N:#444 O:#390 P:#6C0 Q:#06F R:#E00 S:#6FF T:#CF3 U:#C63 V:#C60 W:#555
voxels
33-4(30B2-)3BCBC2B2C2(2BCBC)2B2(C3B)2-3BCBC2BC3BCBC2B2C2(3BC)3B2-2(3B3C2BC)BC2B2(CB)C3B2-2(3BCBC2BC)BC2B2CB2C3B2-4BC3B2(C4B)3(C3B)2(2-30B)2-5B2(C2B)3C2BCBC2B4C5B2-5B2(C2B)C4BCBC2BC8B2-5B3C3BC4B3C2BC8B2-5B2(C2B)3C2BCBC2BC8B2-5B2(C2B)C4BCBC2BC8B2-5B2(3C3B)C3BC8B2-2BCBC4B12N4BCBC2B2-2BCBC5B10N5BCBC2B2-10BL8HL10B2-5BI4BL8HL4BI5B2-5B2I3BLHK4HKHL3B2I5B2-5B3I2BLH2K2H2KHL2B3I5B2-5B4IBLH2K2N2KHLB4I5B2-5B4IBLH2K2H2KHLB4I5B2-5B3I2BLHK4HKHL2B3I5B2-5B2I3BL8HL3B2I5B2-5BI5B8L5BI5B2-30B66-30B-2B28A12(3B29A)4(2B-F28A2BEF28A)2B-F28A7(3B29A)B2-30B34-30B-2B28A12(3B29A)9(2B-F28A)7(3B29A)B2-30B17-F16-30B-2B28A3B29A11(22B10A)4(2B-F18B10A2BEF18B10A)2B-F18B6(10A22B)10A3B29AB2-30B19-2F13-30B-20B10A22B10A3(2B20-B9A)3(BC20-B9A)BC-2Q17-B9ABC2(Q19-B9A2B)-Q18-B9A2B-Q18-B9ABC2(20-B9A2B)2(20-B9ABC)3(20-B9A2B)2-R17-B9A2B4-R15-B9ABC4-2R14-B9ABC5-R14-3(B9ABC20-)B9A2B20-B9A22B10AB2-30B20-3F11-30B-20B10A22B10A3(2B20-B9A)2(BC3(20-B9A2B)20-B9A)2(BC20-B9A2B20-B9A)2B2(20-B9ABC3(20-B9A2B))20-B9ABC20-B9A2B20-B9A22B10AB2-30B16-UJ3-F12-30B-20B10A22B10A2B4-12D4-2(B9A2B20-)3(B9ABC20-B9A2B20-)3(B9A2B20-)2(B9ABC20-)2(B9A2B20-)B9ABC4(20-B9A2B)3(20-B9ABC)2(20-B9A2B)20-B9A22B10AB2-30B16-F3J14-30B-20B10A22B10A2B3-14D3-2(B9A2B20-)2(B9ABC3(20-B9A2B)20-)15(B9A2B20-)B9A22B10AB2-30B17-F2J14-30B-20B10A22B10A2B2-16D2-2(B9A2B20-)5(B9ABC20-)8(B9A2B20-)B9ABC4(20-B9A2B)20-3(B9ABC19-E)2(B9A2B20-)B9A22B10AB2-30B17-FJVJ13-30B-20B10A22B10A2B2-16D2-10(B9A2B20-)4(B9ABC20-)2(B9ABC19-E)B9A2B19-E2(B9A2B20-)B9ABC19-E3(B9A2B20-)B9ABC19-EB9A2B20-B9A22B10AB2-30B34-30B-20B10A22B10A2B2-16D2-13(B9A2B20-)B9A2B19-EB9A2B20-B9ABC2(20-B9A2B)19-EB9A2B20-B9A2B3(19-EB9ABC)2(19-EB9A2B)20-B9A22B10AB2-30B34-30B-20B10A22B10A2B2-16D2-13(B9A2B20-)5(B9A2B19-E)7(B9A2B20-)B9A22B10AB2-8B2FBF18B34-30B-20B10A22B10A2B2-16D2-10(B9A2B20-)6(B9ABC20-)3(B9A2B20-)5(B9A2B19-E)B9A2B20-B9A22B10AB2-7B7F16B34-30B-20B10A22B10A2B2-16D2-10(B9A2B20-)B9ABC2(20-B9A2B)20-B9ABC19-EB9A2B20-B9ABC9(20-B9A2B)20-B9A22B10AB2-6B8F16B34-30B-20B10A22B10A2B2-16D2-8(B9A2B20-)2(B9A2B19-E4(B9A2B20-))B9A2B20-B9A2B19-E5(B9A2B20-)B9A22B10AB2-5B8F17B34-30B-20B10A22B10A2B2-16D2-2(B9A2B20-B9ABC20-)3(B9A2B20-)2(B9A2B19-E)B9A2B4(20-B9ABC)19-EB9ABC4(19-EB9A2B)20-B9ABC19-E4(B9ABC20-)B9A2B20-B9A22B10AB2-8BF2BF18B7-3J-2J21-30B-20B10A22B10A2B2-16D2-2(B9A2B20-)B9ABC4(20-B9A2B)5(19-EB9A2B)19-E2(B9ABC2(20-B9A2B)20-)B9A2B20-3(B9A2B19-E)B9ABC2(19-EB9A2B)20-B9A22B10AB2-30B8-4J22-30B-20B10A22B10A2B2-16D2-7(B9A2B20-)2(B9A2B19-E)B9A2B4(20-B9ABC)19-EB9ABC4(19-EB9A2B)2(20-B9A2B)20-B9ABC3(20-B9A2B)20-B9A22B10AB2-30B9-UJ23-30B-20B10A22B10A2B2-16D2-8(B9A2B20-)B9A2B19-E4(B9A2B20-)B9A2B19-E3(B9A2B20-)B9A2B19-EB9A2B20-5(B9ABC19-E)B9A2B20-B9A22B10AB2-30B34-30B-20B10A22B10A2B2-16D2-10(B9A2B20-)3(B9ABC20-)3(B9ABC19-E)2(B9A2B19-E)B9A2B20-B9A2B19-E3(B9A2B20-)B9A2B19-EB9A2B20-B9A22B10AB2-17B2F11B34-30B-20B10A22B10A2B2-16D2-10(B9A2B20-)B9ABC9(20-B9A2B)3(19-EB9ABC)2(19-EB9A2B)20-B9A22B10AB2-13BJ3B2F4BJ6B34-30B-20B10A22B10A2B2-16D2-13(B9A2B20-)2(B9A2B19-E)2(B9A2B20-)B9A2B19-EB9A2B20-B9ABC3(20-B9A2B)20-B9ABC20-B9A2B20-B9A22B10AB2-14B2JB2F2B2J7B34-30B-20B10A22B10A2B2-16D2-2(B9A2B20-)5(B9ABC20-)3(B9A2B20-)B9ABC20-B9A2B2(20-B9ABC)19-E2(B9ABC20-)2(B9A2B20-B9A2B19-E)2(B9ABC19-E)B9ABC20-B9A2B19-EB9A2B20-B9A22B10AB2-14B7JBJ7B34-30B-20B10A22B10A2B2-16D2-2(B9A2B20-)2(B9ABC3(20-B9A2B)20-)3(B9A2B20-)5(B9A2B19-E)3(B9A2B20-B9A2B19-E)B9A2B20-B9A22B10AB2-14BJ2B2FBJ9B34-30B-20B10A22B10A2B3-14D3-2(B9A2B20-)3(B9ABC20-B9A2B20-)2(B9A2B20-)B9ABC20-B9A2B4(20-B9ABC)4(20-B9A2B)19-EB9A2B20-2(B9A2B19-E)B9ABC19-EB9A2B20-B9A22B10AB2-14BJ2B2F11B34-30B-20B10A22B10A2B4-12D4-2(B9A2B20-)2(B9ABC3(20-B9A2B)20-)9(B9A2B20-)5(B9ABC20-)B9A2B20-B9A22B10AB2-18BF11B10-2C2K20-30B-20B10A22B10A3(2B20-B9A)5(BC20-B9A)3(2B20-B9A)BC20-B9A2B4(20-B9ABC)7(20-B9A2B)20-B9ABC20-B9A2B20-B9A22B10AB2-30B9-CWKC-K19-30B-20B10A22B10A26(2B20-B9A)22B10AB2-30B9-C2KC-K19-30B-2B28A3B29A12(23B9A)18BM4B9A9BT2BP10B9A8BTBT3O9B9A7BP5BMO2BM5B9A8BS2BM2OM8B9A6BSBS2MO5MB2M3B9A7BSB2MO6M5B9A6B2(PB)MB2O9B9A5B2(PB)P3BM9B9A23B9A10BP12B3(9A23B)9A3B29AB2-30B10-2C2K20-30B-2B28A28(3B29A)B2-30B34-30B-927B2-30B66-3(30B2-)3B25G2B2(2-30B)2-7B3(2C3B)2C6B4(2-6B3(C2BCB)C2BC5B)2-7B3(2C3B)2C6B2-30B2-3B25G2B2-30B2-4B3CBC3B2C2B2C2(B3C)4B2-4BC3BC4B4(CB)C3BC4B2-4B3CBC3B2C4(BC)3BC4B2-6BCBC4B4(CB)C3BC4B2-4B3CBC3B2C2B2C2(B3C)4B2(2-30B)2-5B9(CB)3C4B2-7B8(CB)C6B2-5BC5(B3C)4B2-5B8(CB)C3BC4B2-5B9(CB)3C4B2(2-30B)65-
