model
size = 18 20 18, scale = 0.05, origin = -y
material 
  colors = A:#F00
voxels
------------------ ------------------ ------------------ ------------------ ------------------ ------------------ ------------------ ------------------ --------AA-------- --------AA-------- --------AA-------- --------AA-------- ------------------ ------------------ ------------------ ------------------ ------------------ ------------------ ------------------ ------------------ 
------------------ ------------------ ------------------ ------------------ ------------------ ------------------ ------------------ ------------------ --------AA-------- --------AA-------- --------AA-------- --------AA-------- ------------------ ------------------ ------------------ ------------------ ------------------ ------------------ ------------------ ------------------ 
------------------ ------------------ ------------------ ------------------ ------------------ ------------------ --------AA-------- --------AA-------- ------AA--AA------ ------AA--AA------ ------AA--AA------ ------AA--AA------ --------AA-------- --------AA-------- ------------------ ------------------ ------------------ ------------------ ------------------ ------------------ 
------------------ ------------------ ------------------ ------------------ ------------------ ------------------ --------AA-------- --------AA-------- ------AA--AA------ ------AA--AA------ ------AA--AA------ ------AA--AA------ --------AA-------- --------AA-------- ------------------ ------------------ ------------------ ------------------ ------------------ ------------------ 
------------------ ------------------ ------------------ ------------------ --------AA-------- --------AA-------- ------AA--AA------ ------AA--AA------ ----AA------AA---- ----AA------AA---- ----AA------AA---- ----AA------AA---- ------AA--AA------ ------AA--AA------ --------AA-------- --------AA-------- ------------------ ------------------ ------------------ ------------------ 
------------------ ------------------ ------------------ ------------------ --------AA-------- --------AA-------- ------AA--AA------ ------AA--AA------ ----AA------AA---- ----AA------AA---- ----AA------AA---- ----AA------AA---- ------AA--AA------ ------AA--AA------ --------AA-------- --------AA-------- ------------------ ------------------ ------------------ ------------------ 
------------------ ------------------ --------AA-------- --------AA-------- ------AA--AA------ ------AA--AA------ ----AA------AA---- ----AA------AA---- --AA----------AA-- --AA----------AA-- --AA----------AA-- --AA----------AA-- ----AA------AA---- ----AA------AA---- ------AA--AA------ ------AA--AA------ --------AA-------- --------AA-------- ------------------ ------------------ 
------------------ ------------------ --------AA-------- --------AA-------- ------AA--AA------ ------AA--AA------ ----AA------AA---- ----AA------AA---- --AA----------AA-- --AA----------AA-- --AA----------AA-- --AA----------AA-- ----AA------AA---- ----AA------AA---- ------AA--AA------ ------AA--AA------ --------AA-------- --------AA-------- ------------------ ------------------ 
--------AA-------- --------AA-------- ------AA--AA------ ------AA--AA------ ----AA------AA---- ----AA------AA---- --AA----------AA-- --AA----------AA-- AA--------------AA AA--------------AA AA--------------AA AA--------------AA --AA----------AA-- --AA----------AA-- ----AA------AA---- ----AA------AA---- ------AA--AA------ ------AA--AA------ --------AA-------- --------AA-------- 
--------AA-------- --------AA-------- ------AA--AA------ ------AA--AA------ ----AA------AA---- ----AA------AA---- --AA----------AA-- --AA----------AA-- AA--------------AA AA--------------AA AA--------------AA AA--------------AA --AA----------AA-- --AA----------AA-- ----AA------AA---- ----AA------AA---- ------AA--AA------ ------AA--AA------ --------AA-------- --------AA-------- 
------------------ ------------------ --------AA-------- --------AA-------- ------AA--AA------ ------AA--AA------ ----AA------AA---- ----AA------AA---- --AA----------AA-- --AA----------AA-- --AA----------AA-- --AA----------AA-- ----AA------AA---- ----AA------AA---- ------AA--AA------ ------AA--AA------ --------AA-------- --------AA-------- ------------------ ------------------ 
------------------ ------------------ --------AA-------- --------AA-------- ------AA--AA------ ------AA--AA------ ----AA------AA---- ----AA------AA---- --AA----------AA-- --AA----------AA-- --AA----------AA-- --AA----------AA-- ----AA------AA---- ----AA------AA---- ------AA--AA------ ------AA--AA------ --------AA-------- --------AA-------- ------------------ ------------------ 
------------------ ------------------ ------------------ ------------------ --------AA-------- --------AA-------- ------AA--AA------ ------AA--AA------ ----AA------AA---- ----AA------AA---- ----AA------AA---- ----AA------AA---- ------AA--AA------ ------AA--AA------ --------AA-------- --------AA-------- ------------------ ------------------ ------------------ ------------------ 
------------------ ------------------ ------------------ ------------------ --------AA-------- --------AA-------- ------AA--AA------ ------AA--AA------ ----AA------AA---- ----AA------AA---- ----AA------AA---- ----AA------AA---- ------AA--AA------ ------AA--AA------ --------AA-------- --------AA-------- ------------------ ------------------ ------------------ ------------------ 
------------------ ------------------ ------------------ ------------------ ------------------ ------------------ --------AA-------- --------AA-------- ------AA--AA------ ------AA--AA------ ------AA--AA------ ------AA--AA------ --------AA-------- --------AA-------- ------------------ ------------------ ------------------ ------------------ ------------------ ------------------ 
------------------ ------------------ ------------------ ------------------ ------------------ ------------------ --------AA-------- --------AA-------- ------AA--AA------ ------AA--AA------ ------AA--AA------ ------AA--AA------ --------AA-------- --------AA-------- ------------------ ------------------ ------------------ ------------------ ------------------ ------------------ 
------------------ ------------------ ------------------ ------------------ ------------------ ------------------ ------------------ ------------------ --------AA-------- --------AA-------- --------AA-------- --------AA-------- ------------------ ------------------ ------------------ ------------------ ------------------ ------------------ ------------------ ------------------ 
------------------ ------------------ ------------------ ------------------ ------------------ ------------------ ------------------ ------------------ --------AA-------- --------AA-------- --------AA-------- --------AA-------- ------------------ ------------------ ------------------ ------------------ ------------------ ------------------ ------------------ ------------------ 
