model
size = 14 29 8, scale = 0.05, origin = -y
material 
  colors = A:#111 B:#BBB C:#EEE
voxels
-------------- -------------- -------------- -------------- -------------- -------------- ------AA------ ------AA------ -------------- -------------- -------------- -------------- -------------- -------------- -------------- -------------- -------------- -------------- -------------- -------------- -------------- -------------- -------------- -------------- -------------- -------------- -------------- -------------- -------------- 
-------------- -------------- -------------- -------------- -------------- -----AAAA----- -----AAAA----- -----AAAA----- -----AAAA----- -----AAAA----- -------------- -------------- -------------- -------------- -------------- -------------- -------------- -------------- -------------- -------------- -------------- -------------- -------------- -------------- -------------- -------------- -------------- -------------- -------------- 
-------------- -------------- -------------- -------------- ------AA------ -----AAAA----- ----AAAAAA---- ----AAAAAA---- ----AAAAAA---- ----AAAAAA---- -----AAAA----- -----AAAA----- -------------- -------------- -------------- -------------- -------------- -------------- -------------- -------------- -------------- -------------- -------------- -------------- -------------- -------------- -------------- -------------- -------------- 
------AA------ -----AAAA----- ----AA--AA---- ----A----A---- ------AA------ -----AAAA----- ----AAAAAA---- ---AAAAAAAA--- ----AAAAAA---- ----AAAAAA---- -----AAAA----- -----AAAA----- ------AA------ -------------- -------------- -------------- -------------- -------------- -------------- -------------- -------------- -------------- -------------- -------------- -------------- -------------- -------------- -------------- -------------- 
------AA------ -----AAAA----- ----AA--AA---- ---AA----AA--- --AA--AA--AA-- -----AAAA----- ----AAAAAA---- ---AAAAAAAA--- ----AAAAAA---- ----AAAAAA---- -----AAAA----- -----AAAA----- ------AA------ -----CBBB----- ----B----B---- ---B------C--- ---B------B--- --C--------B-- --B--------B-- -C----------B- -C----------B- B------------B B------------B C------------B -B----------B- --B--------C-- ---B------B--- ----B----B---- -----CBBB----- 
------AA------ -----AAAA----- ----AA--AA---- ----A----A---- ------AA------ -----AAAA----- ----AAAAAA---- ----AAAAAA---- ----AAAAAA---- ----AAAAAA---- -----AAAA----- -----AAAA----- -------------- -------------- -------------- -------------- -------------- -------------- -------------- -------------- -------------- -------------- -------------- -------------- -------------- -------------- -------------- -------------- -------------- 
-------------- -------------- -------------- -------------- -------------- -----AAAA----- -----AAAA----- -----AAAA----- -----AAAA----- -----AAAA----- -------------- -------------- -------------- -------------- -------------- -------------- -------------- -------------- -------------- -------------- -------------- -------------- -------------- -------------- -------------- -------------- -------------- -------------- -------------- 
-------------- -------------- -------------- -------------- -------------- -------------- ------AA------ ------AA------ -------------- -------------- -------------- -------------- -------------- -------------- -------------- -------------- -------------- -------------- -------------- -------------- -------------- -------------- -------------- -------------- -------------- -------------- -------------- -------------- -------------- 
