model
size = 14 27 3, scale = 0.05, origin = -y
material 
  colors = A:#BEC23F B:#FFC408 C:#FFFFFB D:#EEE
voxels
-----DBBD----- ----B----B---- ---D--B---D--- --B-BBBBD--B-- -B---D---B--B- -D---BBBBB--D- -B---B---B--B- --B-BBBDB--B-- ---D--B---D--- ----B----B---- -----DBBD----- -------------- -------------- -------------- -------------- -------------- -------------- -------------- -------------- -------------- -------------- -------------- -------------- -------------- -------------- -------------- -------------- 
-----AAAA----- ----AAAAAA---- ---AAAAAAAA--- --AAAAAAAAAA-- -AAAAAAAAAAAA- -AAAAAAAAAAAA- -AAAAAAAAAAAA- --AAAAAAAAAA-- ---AAAAAAAA--- ----AAAAAA---- -----AAAA----- -----AAAB----- ----B----A---- ---C------A--- ---A------A--- --B--------A-- --A--------A-- -B----------B- -C----------A- A------------C A------------A A------------B -B----------A- --C--------B-- ---A------A--- ----A----B---- -----ABAA----- 
-----CBBC----- ----B----B---- ---C---B--C--- --B--CBBBB-B-- -B--B---C---B- -C---BBBB---C- -B--B---B---B- --B--BCBBB-B-- ---C---B--C--- ----B----B---- -----CBBC----- -------------- -------------- -------------- -------------- -------------- -------------- -------------- -------------- -------------- -------------- -------------- -------------- -------------- -------------- -------------- -------------- 
