model
size = 32, scale = 0.05, origin = -y
material 
  colors = A:#960 B:#111 C:#930 D:#963 E:#633 F:#C60 G:#C90 H:#C93 I:#777 J:#700 K:#EEE L:#222
voxels
224-17A5D11AD25A3D2AED30AE11A2-4A2-7A2D15A3(8-24A)8D5A3K30AK10AD31AD20AK10AD30ADA5D9A6DK9AD4(7-8A7-10A)2(7-8A)DA2(7-8A)D2A5-10A5-9AD3A3-12A3-10AD31AD6A6D5A8D8A5D22AD30-D224-76A2B4A2B23AB2-4B2-2(B11AE10AB8-)B22AB8-B23A8B145A7B8A6BK9A5(B7-B6AB7-B8A)B7-B6AB7-B9AB5-B8AB5-B11AB3-B10AB3-B13A3B12A3B47AD13A2D8A-D28-D225-76A2B4A2B11AE11AB2-4B2-3(B10AE11AB8-)B23A8B145A7B8A6BK9AB7-B6AB7-B3AD4A4(B7-B6AB7-B8A)B7-B6AB7-B9AB5-B8AB5-B11AB3-B10AB3-B13A3B12A3B44AD3AD9A3D10A2-D26-D226-76A2B4A2B23AB2-4B2-3(B10AD11AB8-)B10AD12A8B145A7B8A7B9AB7-B6AB7-B8A2(B7-B6AB7-B3AD4A)2(B7-B6AB7-B8A)B7-B6AB7-B9AB5-B8AB5-B11AB3-B10AB3-B13A3B12A3B6AE38AD2AD22A3-D24-D227-76A2B4A2B23AB2-4B2-3(B22AB8-)B23A8B11A4(D31A)DE4A7B8A7B4AD4A3(B7-B6AB7-B8A)2(B7-B6AB7-B3AD4A)B7-B6AB7-B9AB5-B8AB5-B11AB3-B10AB3-B13A3B12A3B6AE39AD2A2D2F18A4-D22-D228-76A2B4A2B23AB2-4B2-3(B22AB8-)B10AF12A8B11A3(F31A)FG30AF5A7B8A7B4AFE3AB7-B6AB7-B3AD4AB2-2L3-B6AB3-2L2-B3AD4AB2-L4-B6AB4-L2-2(B3AD4AB7-B6AB7-)B3AF4AB7-B6AB7-B3AD5AB5-B8AB5-B11AB3-B10AB3-B13A3B12A3B6AE40A2(DA)2D4F3AF10A5-D20-D229-76A2B4A2B23AB2-4B2-3(B22AB8-)B23A8B140AG4A7B8A7B4AG4AB7-B6AB7-2(B8AB-4I2-B6AB2-4I-)B8AB2-2I3-B6AB3-2I2-B8AB7-B6AB7-B3AF4AB7-B6AB7-B9AB5-B8AB5-B11AB3-B10AB3-B13A3B12A3B50A2DAD17A5-D20-D101-2C3(28-4C)28-3C2(30A2C)11A2B4A2B11A2C10AB2-4B2-B10A2C10AB8-B10AC11AB8-B22AB8-B23A8B172AG4A7B8A7B4A2G4A7B8A7B4AG5A7B8A7B10A7B8A7B5AD4A7B8A7B4AD5A7B8A7B4AF6A5B10A5B13A3B12A3B72AD9AD17AD2A6-D18-D70-2C4(28-4C)28-3C2(30A2C)11A2B4A2B11A2C10AB2-4J2-3(B10A2C10AB8-)B10A2C11A8B11A2C30AC192AG30AG32AD30AD31AF130ADF6AD17AD3A7-D16-D39-2C5(28-4C)28-3C2(30A2C)11A2B4A2B11A2C10AB2-4J2-3(B10A2C10AB8-)B10A2C11A8B11A2C30AC256AD30AD163AD24AD3A8-D14-D8-2C6(28-4C)28-3C3(30A2C)11A2B4A2B11A2C11A2B4J2B11AC12A3B2J3B24A8B332AD30AD164AD22AD4A9-D12-D9-2C2(28-4C)28-2C128-607AD132AD21AD5A10-12D10-2C2(28-4C)28-2C128-64AE30A6(E31A)E63AFE222AD165AD26A10-D10AD10-2C2(28-4C)28-2C128-64AE287AE30AF191AD161AF4AD20AF4A10-D4A4H2AD10-2C2(28-4C)28-2C128-64AE30AD256AE190AD194AF4AD19AF4A10-D10AD10-2C2(28-4C)28-2C128-32AE94AD32AD30AD95AD31AD192AD30AD95AE3(31AF)3AF23AF3AF10-D3AH6AD10-2C2(28-4C)28-2C128-32AE95AD30A3(D31A)D224AD30AD127AE100AF22AF4A10-D10AD10-2C2(28-4C)28-2C128-448AD30AD64AD196AF26A10-D10AD10-2C2(28-4C)28-2C128-191AE64AD30A2D30AD224AD197AF20ADAF2A11-DF8D11-2C2(28-4C)28-2C128-96A2(E31A)E159AG30A2G30AG128AD95AG30A2G30AG92ADF2A2(10-D)10-2C2(28-4C)28-2C128-383AE128AD227AD23AD3A9-D12-D9-2C6(28-4C)28-3C3(30A2C)30AC255AE128AD224AF2AD8AE15AD2A8-D14-D40-2C5(28-4C)28-3C7(30A2C)30AC95AE128AD258AD8AE4AD12ADA7-D16-D71-2C4(28-4C)28-3C7(30A2C)30AC31AD32AG30AG64AE63AD258AD11AF2AD11ADA7-D16-D103-2C3(28-4C)28-3C3(30A2C)30AC191ADG30AD32AE318AE34AD9AD3A2FAD11AD6-D18-D230-320AG30AGE382AE11AD6AFA2D10A5-D20-D229-288AG30AGE190AF31AF191AE10ADA4F6AD9A4-D22-D228-128AD2(30A2D)30AD32AD31AD30AG2(D31A)2(D30AF)31AF265AD6A3FE3AD8A3-D24-D227-31AF31AE5(31AF)63AD456AD2A3F6AE3AD7A2-D26-D226-96AE126AD31AD447AD31AD7AD6A3F2A2D11A2-D26-D226-96AE94AD11(31AE)95AD31AD96A-D28-D225-8A2E27A3E26A3E2AH2A4D4A3G4AE6A2E2AH3AH5A8D4A2E8AH17A4DAH9AH19AG8AD2AH28AD2AH4AGADEA2G4AG7AE4AD5A2G2ADE8A2G5AE4AD8ADAE5ADAG7AE4AD8AD2AE4ADAG7AE4AD5AH2AD2AE4ADAG6ADE5AD4AE2AD2AE4ADAG3AH2ADE5AD4AEAD3AE4ADAG3AH2ADE5ADAD2AEAD4AE3ADAG7AE5A2D3AE6AE3ADAG5AH7A2D3AH6AEG2ADAG3AGAH7AD4AG6A2G2AD3AG17AG9AD2AG36AG9AG13AE7AG9AG14A2E5AG17A2H12AG15A2H19AD30-D
