model
size = 32 26 32, scale = 0.05, origin = -y
material 
  colors = A:#444 B:#E00 C:#90F D:#0FC
voxels
80-7C21-4C7-C18-2C11-C15-3C13-C15-C13-3C14-2C9-4C17-2C5-4C21-A2C-3C28-C582-10A18-4A8-2A16-2A12-2A13-3A14-2A11-2A16-2A12-A11-6A14-A7-4A20-A5-2A25-5A556-A26-5A-2A20-4A7-A16-6A9-A12-4A15-A11-A17-3A11-A9-8A13-C8-2A21-A6-2A23-C6A555-2B28-2A2-2A24-2A6-A21-4A6-A11-14A6-A9-CA5-2A2-6A-4A10-C8-2A6-A13-A8-A23-C5-2A24-C3-2A27-3A101-C29-2(4C28-)4C29-3C326-6A2(25-A5-A)2(12-A)5-A9-C2A-3A2-2A5-4A-2A9-C6-2A2-4A5-A10-A6-2A-9A13-A5-A2-11A12-A4-2A2-6A4-A12-AC3A5-4A59-3A28-2A-2A3(26-A4-A)27-5A295-2B29-A2-2A3(26-A4-A)9-C4A2-4A7-A2-2A8-A5-2A4-4A4-2A10-A5-2A8-5A10-C6-A-A11-2A10-A4-A-2A6-7A10-AC-2A-4A4-4A16-A3-11A21-3A3-5A22-2(A5-3A23-)A5-2A24-A5-A25-2A3-A28-3A295-4A27-A4-A18-5A3-A4-A16-3B4A3-A4-A11-2A2-A4-3A3-2A3-A8-ACA-2A-A6-A5-3A8-C5-A-A7-6A10-C5-A-A13-A9-C6-A14-A9-C3-A-A12-4A10-3A-2A11-2A18-A11-2A3-2(2CB2C10-2A9-4A2-)2CB2C10-2A8-5A2-2CB2C11-A7-6A2-2CB2C11-A6-4A-2A18-3A3-4A5-2A16-9A2-2AB2A17-7A2-3AB2A26-3AB2A28-AB2A155-6A21-3A-A5-A18-3A2-A-A5-A15-3B5-3A5-A13-2A8-3A5-A7-C4A-2A8-2(2A-)2A8-C4-A-A10-A2-A10-C6-A14-2A8-A22-A8-C21-A10-4A15-2A-2CB2C8-2A14-2A-4BC8-2A15-A-2(4BD9-A14-A2-)4BD9-2A13-A2-4BC9-2A11-A-A2-2CB2C10-A10-4AB2A14-2A9-2A4-A15-2A7-2A5-A15-11A5-A16-9A-2A4-C18-4A5-AB2AC91-3B26-3A3-A22-4A6-A18-3A3-A6-A14-4B13-A12-2A17-A8-3A-A12-A4-2A7-C3-A17-A8-2(A23-A7-)AC21-A2CB2C5-2A19-ABCB2C7-A18-ABCB2C8-A17-A2(BC)D8-A16-A-4BC8-A15-A2-4BD8-A16-B-4BC8-A16-B2A2(13-A17-A)13-2C16-A14-C16-A15-C9-2C5-C15-3C4-2C2-2AB2AC17-5C68-BA2B26-2A4-2A21-3A7-A18-3A10-A14-4B13-A12-2A17-A9-3A19-A6-ACA-A19-2A6-A24-A6-A23-A7-A23-A8-C2A20-A11-A19-A11-C18-2A11-C17-A-4BD7-C16-A2-4BD7-A17-B-4BC7-C18-2A3(12-A18-A)13-A17-A13-2A11-A5-C13-2A9-A-2AB2AC15-9A64-7B24-A7-A21-2A9-A17-3A11-A13-4B14-A10-3A18-A10-A20-2A4-AC2A-A20-2A4-A3-A21-2A4-A23-B3A4-A23-B2A6-CA21-BA9-A20-BA9-A19-2A10-A18-A-2CB2C7-C17-B-2(BCB2C7-C18-A)BCB2C7-C19-A11-C19-A12-A18-A12-A19-C12-A13-A4-C2(12-A)-AB2AC13-12A33-4A26-2B4-2B23-A8-BA19-2A10-A17-3A11-2A11-8B11-2A8-3A5-3A11-2A3-2A3B8-3A12-A2-B4-A8-2(3A12-A2-B13-)3A8-B2-A3-B13-3A8-B-2A3-BA12-3A8-BA7-BA10-3A8-B2(A9-)3A8-2A9-B9-3A7-A11-B9-3A7-2A3(10-B9-3A8-A)11-A8-3A8-A2(11-A8-3A7-2A)12-B7-3A5-AB2AC12-A6-3A4-A18-13A31-7A24-B7-B3A19-A10-2A17-2A11-2A15-4A12-2A9-9B12-2A6-3A4-5A12-C2-A4B7-3(5A11-A2-B12-)5A7-B3-A2-B12-5A7-B2-A3-B12-5A7-B-A5-A11-5A7-B-A5-ABA9-5A2(7-BA)9-5A7-A8-BA9-5A7-BA8-A9-5A7-BA9-B8-5A7-A10-B8-5A7-A11-A7-5A6-2A11-A7-5A5-B13-A7-5A5-B14-B6-5A4-A16-2A4-5A4-A18-B12A30-8A-C21-B8-A-A19-A11-A17-3A11-A15-5A12-A9-3B2-4BA12-A6-3A3-A-5A12-A-5B6-A-5A11-C-2(B11-A-5A10-A2-)B11-A-5A6-B3-A2-B11-A-5A6-B2-A3-B11-2(A-5A6-B2-A4-A10-)A-5A6-B-A6-B9-A-5A6-B2A6-B9-A-5A6-B2(A8-)A-5A6-BA9-B7-2(A-5A6-BA10-A6-)A-5A6-A11-A6-A-5A5-A13-B5-A-5A4-B14-B5-A-5A4-B15-2A3-A-5A3-A18-B12A30-9AC21-B9-C21-A10-A17-4A10-A15-6A11-A9-2B3-4B2A11-A6-3A2-2A-6A11-A-5B5-2A-6A10-C-3(B10-2A-6A9-A2-)B10-2A-6A5-B2-A3-B10-2(2A-6A5-B2-A4-A9-)2(2A-6A5-B-A6-B8-)2A-6A5-B-2(A7-)2A-6A5-B-BA7-B6-2A-6A5-B-BA8-A5-2A-6A5-B-A9-A5-2A-6A5-2A10-A5-2(2A-6A4-A13-B4-)2A-6A3-B15-2A2-2A-6A2-AB17-B12A30-9AC21-A9-C21-A10-A17-4A10-A15-6A11-A9-2B3-4B2A11-A6-3A2-2A-6A11-A-5B5-3(2A-6A10-C-B10-)2(2A-6A9-A2-B10-)2A-6A5-B2(3-A)9-2A-6A5-B2-A4-A9-2A-6A5-B2-A5-B8-2A-6A5-B-A6-B8-2A-6A5-B2-A6-A7-2A-6A5-B2-A7-B6-2A-6A5-B2-A8-2(A5-2A-6A7-A9-)A5-2A-6A5-2A11-B4-2A-6A4-A13-B4-2A-6A4-A14-2A2-2A-6A3-B17-B13A29-9AC21-A9-C21-A10-A17-4A10-A15-6A11-A9-2B3-4B2A11-A6-3A2-2A-6A11-A-5B5-3(2A-6A10-C-B10-)2(2A-6A9-A2-B10-)2A-6A5-B2(3-A)9-2A-6A5-B2-A4-A9-2A-6A5-B2-A5-B8-2A-6A5-B-A6-B8-2A-6A5-B2-A6-A7-2A-6A5-B2-A7-B6-2A-6A5-B2-A8-2(A5-2A-6A7-A9-)A5-2A-6A5-2A11-B4-2A-6A4-A13-B4-2A-6A4-A14-2A2-2A-6A3-B17-B13A29-9AC21-B9-C21-A10-A17-4A10-A15-6A11-A9-2B3-4B2A11-A6-3A2-2A-6A11-A-5B5-2A-6A10-C-3(B10-2A-6A9-A2-)B10-2A-6A5-B2-A3-B10-2(2A-6A5-B2-A4-A9-)2(2A-6A5-B-A6-B8-)2A-6A5-B-2(A7-)2A-6A5-B-BA7-B6-2A-6A5-B-BA8-A5-2A-6A5-B-A9-A5-2A-6A5-2A10-A5-2(2A-6A4-A13-B4-)2A-6A3-B15-2A2-2A-6A2-AB17-B12A30-8A-C21-B8-A-A19-A11-A17-3A11-A15-5A12-A9-3B2-4BA12-A6-3A3-A-5A12-A-5B6-A-5A11-C-2(B11-A-5A10-A2-)B11-A-5A6-B3-A2-B11-A-5A6-B2-A3-B11-2(A-5A6-B2-A4-A10-)A-5A6-B-A6-B9-A-5A6-B2A6-B9-A-5A6-B2(A8-)A-5A6-BA9-B7-2(A-5A6-BA10-A6-)A-5A6-A11-A6-A-5A5-A13-B5-A-5A4-B14-B5-A-5A4-B15-2A3-A-5A3-A18-B12A30-7A24-B7-B3A19-A10-2A17-2A11-2A15-4A12-2A9-9B12-2A6-3A4-5A12-C2-A4B7-3(5A11-A2-B12-)5A7-B3-A2-B12-5A7-B2-A3-B12-5A7-B-A5-A11-5A7-B-A5-ABA9-5A2(7-BA)9-5A7-A8-BA9-5A7-BA8-A9-5A7-BA9-B8-5A7-A10-B8-5A7-A11-A7-5A6-2A11-A7-5A5-B13-A7-5A5-B14-B6-5A4-A16-2A4-5A4-A18-B12A31-4A26-2B4-2B23-A8-BA19-2A10-A17-3A11-2A11-8B11-2A8-3A5-3A11-2A3-2A3B8-3A12-A2-B4-A8-2(3A12-A2-B13-)3A8-B2-A3-B13-3A8-B-2A3-BA12-3A8-BA7-BA10-3A8-B2(A9-)3A8-2A9-B9-3A7-A11-B9-3A7-2A3(10-B9-3A8-A)11-A8-3A8-A2(11-A8-3A7-2A)12-B7-3A5-AB2AC12-A6-3A4-A18-13A62-7B24-A7-A21-2A9-A17-3A11-A13-4B14-A10-3A18-A10-A20-2A4-AC2A-A20-2A4-A3-A21-2A4-A23-B3A4-A23-B2A6-CA21-BA9-A20-BA9-A19-2A10-A18-A-2CB2C7-C17-B-2(BCB2C7-C18-A)BCB2C7-C19-A11-C19-A12-A18-A12-A19-C12-A13-A4-C2(12-A)-AB2AC13-12A65-BA2B26-2A4-2A21-3A7-A18-3A10-A14-4B13-A12-2A17-A9-3A19-A6-ACA-A19-2A6-A24-A6-A23-A7-A23-A8-C2A20-A11-A19-A11-C18-2A11-C17-A-4BD7-C16-A2-4BD7-A17-B-4BC7-C18-2A3(12-A18-A)13-A17-A13-2A11-A5-C13-2A9-A-2AB2AC15-9A67-3B26-3A3-A22-4A6-A18-3A3-A6-A14-4B13-A12-2A17-A8-3A-A12-A4-2A7-C3-A17-A8-2(A23-A7-)AC21-A2CB2C5-2A19-ABCB2C7-A18-ABCB2C8-A17-A2(BC)D8-A16-A-4BC8-A15-A2-4BD8-A16-B-4BC8-A16-B2A2(13-A17-A)13-2C16-A14-C16-A15-C9-2C5-C15-3C4-2C2-2AB2AC17-5C100-6A21-3A-A5-A18-3A2-A-A5-A15-3B5-3A5-A13-2A8-3A5-A7-C4A-2A8-2(2A-)2A8-C4-A-A10-A2-A10-C6-A14-2A8-A22-A8-C21-A10-4A15-2A-2CB2C8-2A14-2A-4BC8-2A15-A-2(4BD9-A14-A2-)4BD9-2A13-A2-4BC9-2A11-A-A2-2CB2C10-A10-4AB2A14-2A9-2A4-A15-2A7-2A5-A15-11A5-A16-9A-2A4-C18-4A5-AB2AC123-4A27-A4-A18-5A3-A4-A16-3B4A3-A4-A11-2A2-A4-3A3-2A3-A8-ACA-2A-A6-A5-3A8-C5-A-A7-6A10-C5-A-A13-A9-C6-A14-A9-C3-A-A12-4A10-3A-2A11-2A18-A11-2A3-2(2CB2C10-2A9-4A2-)2CB2C10-2A8-5A2-2CB2C11-A7-6A2-2CB2C11-A6-4A-2A18-3A3-4A5-2A16-9A2-2AB2A17-7A2-3AB2A26-3AB2A28-AB2A125-2B29-A2-2A3(26-A4-A)9-C4A2-4A7-A2-2A8-A5-2A4-4A4-2A10-A5-2A8-5A10-C6-A-A11-2A10-A4-A-2A6-7A10-AC-2A-4A4-4A16-A3-11A21-3A3-5A22-2(A5-3A23-)A5-2A24-A5-A25-2A3-A28-3A294-6A2(25-A5-A)2(12-A)5-A9-C2A-3A2-2A5-4A-2A9-C6-2A2-4A5-A10-A6-2A-9A13-A5-A2-11A12-A4-2A2-6A4-A12-AC3A5-4A59-3A28-2A-2A3(26-A4-A)27-5A294-2B28-2A2-2A24-2A6-A21-4A6-A11-14A6-A9-CA5-2A2-6A-4A10-C8-2A6-A13-A8-A23-C5-2A24-C3-2A27-3A101-C29-2(4C28-)4C29-3C296-A26-5A-2A20-4A7-A16-6A9-A12-4A15-A11-A17-3A11-A9-8A13-C8-2A21-A6-2A23-C6A581-10A18-4A8-2A16-2A12-2A13-3A14-2A11-2A16-2A12-A11-6A14-A7-4A20-A5-2A25-5A581-7C21-4C7-C18-2C11-C15-3C13-C15-C13-3C14-2C9-4C17-2C5-4C21-A2C-3C28-C502-
