model
size = 32 31 32, scale = 0.05, origin = -y
material 
  colors = A:#BBB B:#888 C:#AAA D:#777 E:#555 F:#444
voxels
2AD7AC4A2C4AC7AD2A960-32A3-3ADAC6A2D6ACAD3A931-B30AB11AC8AC14A26-3A896-E3A24-3AEB30ABC4AB4ACAB6ABAC4AB4A2CDA26-ADC864-4A24-8A24-4AC3A24-3AC2A3D10A2D10A3D4AD26-D2A832-4A2(24-8A)24-4AD3A24-3AD4AD2AC7A2D7AC2AD7A26-3A800-B3A24-3AB4A24-8A24-4AB3A24-3AB4A24-7ADB2AC5AB4AB5AC2ABD6A25-4A769-B2A24-2AB-B3A24-3AB4A24-4AC3A24-3ACE3A24-3AE4A24-8AC3A2CADB6ABDA2C3AC4ACDA26-ADC737-3A24-3A-B3A24-3AB4A2(24-8A)24-4AC3A24-3ACB3A24-3ABC9AF10AF9AC3A25-4A706-2A24-2A2-B3A24-3AB4A5(24-8A)24-10ADADB2ABD4ADB2ABDAD6ABDA25-2ADB674-2A24-A4-E2A24-2AE2-3A24-3A2-B2A24-2AB2(2-3A24-3A)2-E2A24-2AE2(2-3A24-3A)2-5AD4AB3A2C3AB4AD5A2-BA25-2AB642-3A24-2A3-3A24-3A2-D2A24-2AD3(2-3A24-3A)2-B2A24-2AB2-C2A24-2AC2(2-3A24-3A)2-4A2D4AB8AB4A2D4A2-2A26-2A612-A24-A4-6(3A24-3A2-)C2A24-2AC2-E2A24-2AE2-3A24-3A2-B2A24-2AB2-B4AB3A2B2AD2BD2A2B3AB4AB2-2A26-2A579-2A24-A4-3(3A24-3A2-)2(C2A24-2AC3(2-3A24-3A)2-)5AB2AD12AD2AB5A2-2A26-2A579-2A24-A5-2(BA24-AB3(4-2A24-2A)4-)BA24-AB2(4-2A24-2A)4-EB2AC3AD2(2A2C)2AD3AC2ABE4-A26-A580-2A24-A5-CA24-AC4(4-2A24-2A)2(4-CA24-AC)3(4-2A24-2A)4-BA24-AB4-9ABA2C2A2CAB9A4-D26-D549-A30-2A24-A5-2(BA24-AB4-)2A24-2A2(4-EA24-AE)4-CA24-AC4-EA24-AE4-2A24-2A4-CA24-AC2(4-2A24-2A)4-D3ABD3AC8AC3ADB3AD4-A26-A549-D31-A30-BA24-AB3(4-2A24-2A)4-2A24-A5-CA30-2A24-2A4-AC24-CA4-EA24-AE2(4-2A24-2A)4-D2ADCD2BCD8ADC2BDCD2AD5-A24-A614-2(A31-)A63-A31-6(A24-A6-)2(4AB)2A2B2A2(B4A)6-C24-C742-A24-A6-D24-D2(6-A24-A)6-C24-C6-E24-E6-D24-D6-4AB2A2D3A2F3A2D2AB4A6-A24-A710-3(A24-A6-)C24-C3(6-A24-A)6-C24-C6-B10AD2AD10AB6-A24-A742-3(A24-A6-)3(E24-E6-)A24-A7-3AD3ABAC4ACAB3AD3A8-A886-A31-2A30-2A7-A22-2A7-BC2ADAC10ACAD2ACBA7-C22-C895-2A7-A22-2A7-B22-BA7-E2(C4A)2C2(4AC)E8-A22-A872-3(A22-A8-)8AC2A2D2AC8A8-A22-A872-B22-B8-A22-A8-B22-B8-AC2ABA2D8A2DAB2ACA8-A22-A904-2(A22-A8-)BD4A2DA2F2A2FA2D4ADB9-A20-A905-A22-A8-E22-E8-24A9-A20-A873-A22-A8-E22-E8-A22-A8-4AF14AF4A9-A20-A873-A22-A8-B22-B8-BA20-AB9-2AF7A2D7AF2A10-A20-A843-2(A18-A12-)2(20A12-)8AD2AD8A12-DAF14AFAD971-2A18-2A5-
