model
size = 22 28 22, scale = 0.05, origin = -y
material 
  colors = A:#C90 B:#999 C:#996 D:#9C9 E:#CC9 F:#C66 G:#F60 H:#C63 I:#993 J:#990 K:#696 L:#C33 M:#963 N:#AAA O:#C93 P:#966 Q:#663 R:#C96 S:#399 T:#099 U:#396 V:#888 W:#693 X:#933 Y:#699 Z:#444 Aa:#C30 Ab:#936 Ac:#690 Ad:#E00 Ae:#666 Af:#C00 Ag:#F63 Ah:#777 Ai:#C99 Aj:#C36 Ak:#D00 Al:#CC6 Am:#F90 An:#F33 Ao:#C60 Ap:#969 Aq:#369 Ar:#F00 As:#960 At:#366 Au:#363 Av:#C69 Aw:#CC3 Ax:#930 Ay:#F30 Az:#669 Ba:#333 Bb:#360 Bc:#9CF Bd:#CC0 Be:#555 Bf:#C03 Bg:#639 Bh:#909 Bi:#633
voxels
- - - - - - - - A A A J A A - - - - - - - -   - - - - - - - - Q Q A Z M A - - - - - - - -   - - - - - - - - Q Q A Z Q A - - - - - - - -   - - - - - - - - M M A M M J - - - - - - - -   - - - - - - - - I I I I I I - - - - - - - -   - - - - - - - - C C C C C C - - - - - - - -   - - - - - - - - C C C C C C - - - - - - - -   - - - - - - - - I I C C C K - - - - - - - -   - - - - - - - - A C C C C C - - - - - - - -   - - - - - - - - O O O I I C - - - - - - - -   - - - - - - - - C W I I I I - - - - - - - -   - - - - - - - - W BbBbW M Ah- - - - - - - -   - - - - - - - - K W W C O I - - - - - - - -   - - - - - - - - K I I C K K - - - - - - - -   - - - - - - - - S K K AeF N - - - - - - - -   - - - - - - - - K AuAuAeF R - - - - - - - -   - - - - - - - - AhBbQ P P F - - - - - - - -   - - - - - - - - P Q Q P AbF - - - - - - - -   - - - - - - - - F C C - - - - - - - - - - -   - - - - - - - - - R F - - - - - - - - - - -   - - - - - - - - - - - - - - - - - - - - - -   - - - - - - - - - - - - - - - - - - - - - -   - - - - - - - - - - - - - - - - - - - - - -   - - - - - - - - - - - - - - - - - - - - - -   - - - - - - - - - - - - - - - - - - - - - -   - - - - - - - - - - - - - - - - - - - - - -   - - - - - - - - - - - - - - - - - - - - - -   - - - - - - - - - - - - - - - - - - - - - -   
- - - - - J A A - - - - - - A A A - - - - -   - - - - - Z M A - - - - - - A A A - - - - -   - - - - - Z Q J - - - - - - A A A - - - - -   - - - - - M M J - - - - - - J A A - - - - -   - - - - - O H I - - - - - - I I I - - - - -   - - - - - A O C - - - - - - C C C - - - - -   - - - - - A I C - - - - - - C C C - - - - -   - - - - - A C C - - - - - - K Y S - - - - -   - - - - - O C O - - - - - - C C C - - - - -   - - - - - V C C - - - - - - C C C - - - - -   - - - - - D E C - - - - - - I O O - - - - -   - - - - - B E N - - - - - - U C C - - - - -   - - - - - B N Ai- - - - - - AtC C - - - - -   - - - - - B N N - - - - - - AtC C - - - - -   - - - - - B D B - - - - - - V P P - - - - -   - - - - - D D B - - - - - - F AbF - - - - -   - - - - - B B V - - - - - - F AbF - - - - -   - - - - - F P P - - - - - - AbF F - - - - -   - - - - - - AbF D - - - - - - F P - - - - -   - - - - - - AbF P - - - - - - - - - - - - -   - - - - - - - F AbL Ad- - - - - - - - - - -   - - - - - - - - P L Af- - - - - - - - - - -   - - - - - - - - - - Af- - - - - - - - - - -   - - - - - - - - - - - - - - - - - - - - - -   - - - - - - - - - - - - - - - - - - - - - -   - - - - - - - - - - - - - - - - - - - - - -   - - - - - - - - - - - - - - - - - - - - - -   - - - - - - - - - - - - - - - - - - - - - -   
- - - - A - - - - - - - - - - - - A - - - -   - - - - A - - - - - - - - - - - - A - - - -   - - - - A - - - - - - - - - - - - A - - - -   - - - - A - - - - - - - - - - - - A - - - -   - - - - O - - - - - - - - - - - - I - - - -   - - - - K - - - - - - - - - - - - C - - - -   - - - - I - - - - - - - - - - - - K - - - -   - - - - Am- - - - - - - - - - - - S - - - -   - - - - L - - - - - - - - - - - - K - - - -   - - - - V - - - - - - - - - - - - C - - - -   - - - - B - - - - - - - - - - - - O - - - -   - - - - B - - - - - - - - - - - - C - - - -   - - - - B - - - - - - - - - - - - C - - - -   - - - - D - - - - - - - - - - - - C - - - -   - - - - D - - - - - - - - - - - - F - - - -   - - - - D - - - - - - - - - - - - F - - - -   - - - - B D D - - - - - - - - - - P - - - -   - - - - B D D - - - - - - - - - - Ab- - - -   - - - - V F D D - - - - - - - - - F - - - -   - - - - F F F P - - - - - - - - - Aj- - - -   - - - - - H F C - - - - - - - - - - - - - -   - - - - - - H C - - - - - - - - - - - - - -   - - - - - - - N R L Af- - - - - - - - - - -   - - - - - - - - R L Aa- - - - - - - - - - -   - - - - - - - - - - - - - - - - - - - - - -   - - - - - - - - - - - - - - - - - - - - - -   - - - - - - - - - - - - - - - - - - - - - -   - - - - - - - - - - - - - - - - - - - - - -   
- - - A - - - - - - - - - - - - - - A - - -   - - - A - - - - - - - - - - - - - - M - - -   - - - A - - - - - - - - - - - - - - M - - -   - - - A - - - - - - - - - - - - - - M - - -   - - - K - - - - - - - - - - - - - - I - - -   - - - T - - - - - - - - - - - - - - C - - -   - - - I - - - - - - - - - - - - - - K - - -   - - - G - - - - - - - - - - - - - - S - - -   - - - L - - - - - - - - - - - - - - K - - -   - - - Y - - - - - - - - - - - - - - C - - -   - - - B - - - - - - - - - - - - - - I - - -   - - - D - - - - - - - - - - - - - - C - - -   - - - B - - - - - - - - - - - - - - C - - -   - - - B - - - - - - - - - - - - - - C - - -   - - - B - - - - - - - - - - - - - - P - - -   - - - D - - - - - - - - - - - - - - Ab- - -   - - - D D - - - - - - - - - - - - - F - - -   - - - D D - - - - - - - - - - - - - F - - -   - - - V D D - - - - - - - - - - - - F - - -   - - - P D D - - - - - - - - - - - - L - - -   - - - - H G - - - - - - - - - - - - Ad- - -   - - - - G G - - - - - - - - - - - - - - - -   - - - - - G H C - - - - - - - - - - - - - -   - - - - - - R N - - - - - - - - - - - - - -   - - - - - - - - R L Aa- - - - - - - - - - -   - - - - - - - - - - - - - - - - - - - - - -   - - - - - - - - - - - - - - - - - - - - - -   - - - - - - - - - - - - - - - - - - - - - -   
- - A - - - - - - - - - - - - - - - - A - -   - - A - - - - - - - - - - - - - - - - Z - -   - - J - - - - - - - - - - - - - - - - Ba- -   - - J - - - - - - - - - - - - - - - - Q - -   - - K - - - - - - - - - - - - - - - - I - -   - - Aq- - - - - - - - - - - - - - - - C - -   - - F - - - - - - - - - - - - - - - - K - -   - - Ad- - - - - - - - - - - - - - - - S - -   - - X - - - - - - - - - - - - - - - - K - -   - - Y - - - - - - - - - - - - - - - - C - -   - - D - - - - - - - - - - - - - - - - I - -   - - D - - - - - - - - - - - - - - - - N - -   - - B - - - - - - - - - - - - - - - - E - -   - - D - - - - - - - - - - - - - - - - N - -   - - B - - - - - - - - - - - - - - - - F - -   - - D - - - - - - - - - - - - - - - - F - -   - - B D - - - - - - - - - - - - - - - F - -   - - D D - - - - - - - - - - - - - - - P - -   - - B D - - - - - - - - - - - - - - - Ab- -   - - P D - - - - - - - - - - - - - - - L - -   - - - H - - - - - - - - - - - - - - - Ad- -   - - - G - - - - - - - - - - - - - - - X - -   - - - - G G - - - - - - - - - - - - - - - -   - - - - - G - - - - - - - - - - - - - - - -   - - - - - - R N N N Aa- - - - - - - - - - -   - - - - - - - - R L Aa- - - - - - - - - - -   - - - - - - - - - - - - - - - - - - - - - -   - - - - - - - - - - - - - - - - - - - - - -   
- A - - - - - - - - - - - - - - - - - - A -   - A - - - - - - - - - - - - - - - - - - A -   - J - - - - - - - - - - - - - - - - - - A -   - J - - - - - - - - - - - - - - - - - - As-   - K - - - - - - - - - - - - - - - - - - I -   - Ap- - - - - - - - - - - - - - - - - - C -   - Aj- - - - - - - - - - - - - - - - - - K -   - Ar- - - - - - - - - - - - - - - - - - S -   - X - - - - - - - - - - - - - - - - - - C -   - Y - - - - - - - - - - - - - - - - - - C -   - B - - - - - - - - - - - - - - - - - - I -   - Y - - - - - - - - - - - - - - - - - - R -   - Y - - - - - - - - - - - - - - - - - - E -   - B - - - - - - - - - - - - - - - - - - N -   - B - - - - - - - - - - - - - - - - - - F -   - D - - - - - - - - - - - - - - - - - - P -   - D D - - - - - - - - - - - - - - - - - Ab-   - D D - - - - - - - - - - - - - - - - - P -   - B BcD - - - - - - - - - - - - - - - - F -   - - P D - - - - - - - - - - - - - - - - Aj-   - - G G - - - - - - - - - - - - - - - - Ad-   - - - G - - - - - - - - - - - - - - - - X -   - - - G G - - - - - - - - - - - - - - - - -   - - - - G - - - - - - - - - - - - - - - - -   - - - - - G R R - - - - - - - - - - - - - -   - - - - - - - N R L Aa- - - - - - - - - - -   - - - - - - - - - - Af- - - - - - - - - - -   - - - - - - - - - - - - - - - - - - - - - -   
- A - - - - - - - - - - - - - - - - - - A -   - Q - - - - - - - - - - - - - - - - - - A -   - Q - - - - - - - - - - - - - - - - - - A -   - M - - - - - - - - - - - - - - - - - - A -   - K - - - - - - - - - - - - - - - - - - I -   - Ap- - - - - - - - - - - - - - - - - - I -   - L - - - - - - - - - - - - - - - - - - C -   - L - - - - - - - - - - - - - - - - - - Y -   - L - - - - - - - - - - - - - - - - - - C -   - Y - - - - - - - - - - - - - - - - - - C -   - C - - - - - - - - - - - - - - - - - - C -   - U - - - - - - - - - - - - - - - - - - N -   - Y - - - - - - - - - - - - - - - - - - C -   - D - - - - - - - - - - - - - - - - - - C -   - B - - - - - - - - - - - - - - - - - - P -   - B - - - - - - - - - - - - - - - - - - Ab-   - B - - - - - - - - - - - - - - - - - - F -   - D D - - - - - - - - - - - - - - - - - F -   - B D - - - - - - - - - - - - - - - - - P -   - P G - - - - - - - - - - - - - - - - - L -   - - G - - - - - - - - - - - - - - - - - Ad-   - - G - - - - - - - - - - - - - - - - - L -   - - - G - - - - - - - - - - - - - - - - - -   - - - G - - - - - - - - - - - - - - - - - -   - - - - G G G - - - - - - - - - - - - - - -   - - - - - - G N - - - - - - - - - - - - - -   - - - - - - - - R L Af- - - - - - - - - - -   - - - - - - - - - - - - - - - - - - - - - -   
- J - - - - - - - - - - - - - - - - - - A -   - Z - - - - - - - - - - - - - - - - - - A -   - Q - - - - - - - - - - - - - - - - - - A -   - M - - - - - - - - - - - - - - - - - - A -   - K - - - - - - - - - - - - - - - - - - I -   - Ah- - - - - - - - - - - - - - - - - - I -   - X - - - - - - - - - - - - - - - - - - Al-   - Ae- - - - - - - - - - - - - - - - - - E -   - Ak- - - - - - - - - - - - - - - - - - E -   - Ah- - - - - - - - - - - - - - - - - - E -   - I - - - - - - - - - - - - - - - - - - Al-   - T - - - - - - - - - - - - - - - - - - E -   - Y - - - - - - - - - - - - - - - - - - E -   - D - - - - - - - - - - - - - - - - - - E -   - D - - - - - - - - - - - - - - - - - - Ai-   - D - - - - - - - - - - - - - - - - - - R -   - D - - - - - - - - - - - - - - - - - - P -   - D D - - - - - - - - - - - - - - - - - Ab-   - B B - - - - - - - - - - - - - - - - - P -   - P C - - - - - - - - - - - - - - - - - Aj-   - G G - - - - - - - - - - - - - - - - - Ad-   - - G - - - - - - - - - - - - - - - - - L -   - - G G - - - - - - - - - - - - - - - - E -   - - - G - - - - - - - - - - - - - - - - - -   - - - - G G - - - - - - - - - - - - - - - -   - - - - - G G - - - - - - - - - - - - - - -   - - - - - - - N R L Af- - - - - - - - - - -   - - - - - - - - - - - - - - - - - - - - - -   
A - - - - - - - - - - - - - - - - - - - - J   A - - - - - - - - - - - - - - - - - - - - Z   A - - - - - - - - - - - - - - - - - - - - Z   A - - - - - - - - - - - - - - - - - - - - M   C - - - - - - - - - - - - - - - - - - - - I   P - - - - - - - - - - - - - - - - - - - - I   X - - - - - - - - - - - - - - - - - - - - Al  Ae- - - - - - - - - - - - - - - - - - - - E   Ak- - - - - - - - - - - - - - - - - - - - E   Ah- - - - - - - - - - - - - - - - - - - - E   I - - - - - - - - - - - - - - - - - - - - E   T - - - - - - - - - - - - - - - - - - - - E   S - - - - - - - - - - - - - - - - - - - - E   B - - - - - - - - - - - - - - - - - - - - E   D - - - - - - - - - - - - - - - - - - - - E   B - - - - - - - - - - - - - - - - - - - - N   D - - - - - - - - - - - - - - - - - - - - C   D - - - - - - - - - - - - - - - - - - - - F   B - - - - - - - - - - - - - - - - - - - - F   - C - - - - - - - - - - - - - - - - - - - Aj  - H - - - - - - - - - - - - - - - - - - - Ad  - G - - - - - - - - - - - - - - - - - - - L   - - Aa- - - - - - - - - - - - - - - - - - E   - - Aa- - - - - - - - - - - - - - - - - - E   - - - G G - - - - - - - - - - - - - - - - -   - - - - G G - - - - - - - - - - - - - - - -   - - - - - - AoAoR L Af- - - - - - - - - - -   - - - - - - - - - L Af- - - - - - - - - - -   
A - - - - - - - - - - - - - - - - - - - - A   Q - - - - - - - - - - - - - - - - - - - - M   Z - - - - - - - - - - - - - - - - - - - - M   M - - - - - - - - - - - - - - - - - - - - M   C - - - - - - - - - - - - - - - - - - - - I   Aj- - - - - - - - - - - - - - - - - - - - I   X - - - - - - - - - - - - - - - - - - - - Al  At- - - - - - - - - - - - - - - - - - - - E   L - - - - - - - - - - - - - - - - - - - - E   K - - - - - - - - - - - - - - - - - - - - E   I - - - - - - - - - - - - - - - - - - - - E   T - - - - - - - - - - - - - - - - - - - - E   S - - - - - - - - - - - - - - - - - - - - E   B - - - - - - - - - - - - - - - - - - - - E   B - - - - - - - - - - - - - - - - - - - - E   D - - - - - - - - - - - - - - - - - - - - E   D - - - - - - - - - - - - - - - - - - - - E   B - - - - - - - - - - - - - - - - - - - - E   B - - - - - - - - - - - - - - - - - - - - Ai  V B - - - - - - - - - - - - - - - - - - - R   - H - - - - - - - - - - - - - - - - - - - F   - G - - - - - - - - - - - - - - - - - - - R   - - Aa- - - - - - - - - - - - - - - - - - E   - - Aa- - - - - - - - - - - - - - - - - - E   - - - G G - - - - - - - - - - - - - - - - E   - - - - G G - - - - - - - - - - - - - - - -   - - - - - - G G G - - - - - - - - - - - - -   - - - - - - - - G L Af- - - - - - - - - - -   
A - - - - - - - - - - - - - - - - - - - - A   Q - - - - - - - - - - - - - - - - - - - - A   Q - - - - - - - - - - - - - - - - - - - - A   M - - - - - - - - - - - - - - - - - - - - J   K - - - - - - - - - - - - - - - - - - - - I   L - - - - - - - - - - - - - - - - - - - - I   X - - - - - - - - - - - - - - - - - - - - K   Aq- - - - - - - - - - - - - - - - - - - - V   L - - - - - - - - - - - - - - - - - - - - E   K - - - - - - - - - - - - - - - - - - - - E   I - - - - - - - - - - - - - - - - - - - - E   T - - - - - - - - - - - - - - - - - - - - E   S - - - - - - - - - - - - - - - - - - - - E   D - - - - - - - - - - - - - - - - - - - - E   D - - - - - - - - - - - - - - - - - - - - E   D - - - - - - - - - - - - - - - - - - - - E   B - - - - - - - - - - - - - - - - - - - - E   D - - - - - - - - - - - - - - - - - - - - E   B - - - - - - - - - - - - - - - - - - - - E   V B - - - - - - - - - - - - - - - - - - - E   - H - - - - - - - - - - - - - - - - - - - E   - G - - - - - - - - - - - - - - - - - - - E   - G H - - - - - - - - - - - - - - - - - - E   - - G - - - - - - - - - - - - - - - - - - E   - - - G G - - - - - - - - - - - - - - - - E   - - - - H G - - - - - - - - - - - - - - - -   - - - - - G G G - - - - - - - - - - - - - -   - - - - - - - - H H Af- - - - - - - - - - -   
A - - - - - - - - - - - - - - - - - - - - A   A - - - - - - - - - - - - - - - - - - - - H   J - - - - - - - - - - - - - - - - - - - - H   J - - - - - - - - - - - - - - - - - - - - H   K - - - - - - - - - - - - - - - - - - - - H   Bf- - - - - - - - - - - - - - - - - - - - A   X - - - - - - - - - - - - - - - - - - - - A   S - - - - - - - - - - - - - - - - - - - - A   L - - - - - - - - - - - - - - - - - - - - H   K - - - - - - - - - - - - - - - - - - - - H   I - - - - - - - - - - - - - - - - - - - - H   U - - - - - - - - - - - - - - - - - - - - H   S - - - - - - - - - - - - - - - - - - - - A   B - - - - - - - - - - - - - - - - - - - - A   B - - - - - - - - - - - - - - - - - - - - A   B - - - - - - - - - - - - - - - - - - - - O   D - - - - - - - - - - - - - - - - - - - - H   B - - - - - - - - - - - - - - - - - - - - H   B - - - - - - - - - - - - - - - - - - - - H   V B - - - - - - - - - - - - - - - - - - - A   - H - - - - - - - - - - - - - - - - - - - O   - G - - - - - - - - - - - - - - - - - - - E   - G H - - - - - - - - - - - - - - - - - - E   - - G - - - - - - - - - - - - - - - - - - E   - - - G G - - - - - - - - - - - - - - - - E   - - - - R G - - - - - - - - - - - - - - - -   - - - - - R R R - - - - - - - - - - - - - -   - - - - - - - - R R U - - - - - - - - - - -   
A - - - - - - - - - - - - - - - - - - - - H   Q - - - - - - - - - - - - - - - - - - - - H   Q - - - - - - - - - - - - - - - - - - - - A   M - - - - - - - - - - - - - - - - - - - - A   W - - - - - - - - - - - - - - - - - - - - H   Ak- - - - - - - - - - - - - - - - - - - - H   Ax- - - - - - - - - - - - - - - - - - - - A   U - - - - - - - - - - - - - - - - - - - - H   X - - - - - - - - - - - - - - - - - - - - H   Ah- - - - - - - - - - - - - - - - - - - - A   I - - - - - - - - - - - - - - - - - - - - A   U - - - - - - - - - - - - - - - - - - - - H   S - - - - - - - - - - - - - - - - - - - - H   B - - - - - - - - - - - - - - - - - - - - A   B - - - - - - - - - - - - - - - - - - - - A   D - - - - - - - - - - - - - - - - - - - - H   B - - - - - - - - - - - - - - - - - - - - A   B - - - - - - - - - - - - - - - - - - - - A   B - - - - - - - - - - - - - - - - - - - - H   V B - - - - - - - - - - - - - - - - - - - H   - F - - - - - - - - - - - - - - - - - - - O   - H - - - - - - - - - - - - - - - - - - - E   - - H - - - - - - - - - - - - - - - - - - E   - - H - - - - - - - - - - - - - - - - - - E   - - - R G - - - - - - - - - - - - - - - - E   - - - - N N - - - - - - - - - - - - - - - -   - - - - - - N N N - - - - - - - - - - - - -   - - - - - - - - AuAuU - - - - - - - - - - -   
J - - - - - - - - - - - - - - - - - - - - H   Bi- - - - - - - - - - - - - - - - - - - - A   Q - - - - - - - - - - - - - - - - - - - - Aw  M - - - - - - - - - - - - - - - - - - - - A   W - - - - - - - - - - - - - - - - - - - - A   Bf- - - - - - - - - - - - - - - - - - - - L   Ax- - - - - - - - - - - - - - - - - - - - A   U - - - - - - - - - - - - - - - - - - - - H   M - - - - - - - - - - - - - - - - - - - - H   K - - - - - - - - - - - - - - - - - - - - A   J - - - - - - - - - - - - - - - - - - - - A   U - - - - - - - - - - - - - - - - - - - - A   S - - - - - - - - - - - - - - - - - - - - L   N - - - - - - - - - - - - - - - - - - - - A   D - - - - - - - - - - - - - - - - - - - - H   B - - - - - - - - - - - - - - - - - - - - H   B - - - - - - - - - - - - - - - - - - - - Bd  D - - - - - - - - - - - - - - - - - - - - A   D - - - - - - - - - - - - - - - - - - - - A   - V - - - - - - - - - - - - - - - - - - - An  - P - - - - - - - - - - - - - - - - - - - O   - C - - - - - - - - - - - - - - - - - - - N   - - Ai- - - - - - - - - - - - - - - - - - N   - - E - - - - - - - - - - - - - - - - - - N   - - - E E - - - - - - - - - - - - - - - - -   - - - - E E - - - - - - - - - - - - - - - -   - - - - - - AiAiAiAiW - - - - - - - - - - -   - - - - - - - - - T U - - - - - - - - - - -   
- A - - - - - - - - - - - - - - - - - - A -   - A - - - - - - - - - - - - - - - - - - Aw-   - A - - - - - - - - - - - - - - - - - - E -   - A - - - - - - - - - - - - - - - - - - Al-   - K - - - - - - - - - - - - - - - - - - A -   - L - - - - - - - - - - - - - - - - - - An-   - As- - - - - - - - - - - - - - - - - - A -   - U - - - - - - - - - - - - - - - - - - Ag-   - O - - - - - - - - - - - - - - - - - - H -   - K - - - - - - - - - - - - - - - - - - A -   - J - - - - - - - - - - - - - - - - - - A -   - U - - - - - - - - - - - - - - - - - - A -   - K - - - - - - - - - - - - - - - - - - L -   - N - - - - - - - - - - - - - - - - - - A -   - B - - - - - - - - - - - - - - - - - - H -   - B - - - - - - - - - - - - - - - - - - H -   - B - - - - - - - - - - - - - - - - - - A -   - D D - - - - - - - - - - - - - - - - - A -   - D D - - - - - - - - - - - - - - - - - A -   - B D - - - - - - - - - - - - - - - - - Ag-   - V D - - - - - - - - - - - - - - - - - O -   - - P - - - - - - - - - - - - - - - - - E -   - - N N - - - - - - - - - - - - - - - - E -   - - - Ai- - - - - - - - - - - - - - - - - -   - - - - N N - - - - - - - - - - - - - - - -   - - - - - N B - - - - - - - - - - - - - - -   - - - - - - - S S S W - - - - - - - - - - -   - - - - - - - - - - - - - - - - - - - - - -   
- A - - - - - - - - - - - - - - - - - - A -   - Am- - - - - - - - - - - - - - - - - - Al-   - A - - - - - - - - - - - - - - - - - - E -   - A - - - - - - - - - - - - - - - - - - E -   - K - - - - - - - - - - - - - - - - - - O -   - X - - - - - - - - - - - - - - - - - - An-   - Ac- - - - - - - - - - - - - - - - - - A -   - K - - - - - - - - - - - - - - - - - - Ag-   - A - - - - - - - - - - - - - - - - - - H -   - I - - - - - - - - - - - - - - - - - - A -   - J - - - - - - - - - - - - - - - - - - A -   - U - - - - - - - - - - - - - - - - - - A -   - C - - - - - - - - - - - - - - - - - - L -   - B - - - - - - - - - - - - - - - - - - A -   - B - - - - - - - - - - - - - - - - - - H -   - Ap- - - - - - - - - - - - - - - - - - H -   - Av- - - - - - - - - - - - - - - - - - A -   - B Av- - - - - - - - - - - - - - - - - A -   - D Av- - - - - - - - - - - - - - - - - A -   - D B - - - - - - - - - - - - - - - - - Ag-   - - B - - - - - - - - - - - - - - - - - O -   - - C - - - - - - - - - - - - - - - - - E -   - - - N - - - - - - - - - - - - - - - - - -   - - - B - - - - - - - - - - - - - - - - - -   - - - - B B B - - - - - - - - - - - - - - -   - - - - - - B Y - - - - - - - - - - - - - -   - - - - - - - - W Q W - - - - - - - - - - -   - - - - - - - - - - - - - - - - - - - - - -   
- A - - - - - - - - - - - - - - - - - - A -   - J - - - - - - - - - - - - - - - - - - Al-   - M - - - - - - - - - - - - - - - - - - E -   - M - - - - - - - - - - - - - - - - - - E -   - K - - - - - - - - - - - - - - - - - - O -   - X - - - - - - - - - - - - - - - - - - An-   - Ac- - - - - - - - - - - - - - - - - - A -   - W - - - - - - - - - - - - - - - - - - Ag-   - A - - - - - - - - - - - - - - - - - - H -   - A - - - - - - - - - - - - - - - - - - A -   - M - - - - - - - - - - - - - - - - - - A -   - Ae- - - - - - - - - - - - - - - - - - A -   - O - - - - - - - - - - - - - - - - - - L -   - D - - - - - - - - - - - - - - - - - - A -   - B - - - - - - - - - - - - - - - - - - H -   - F - - - - - - - - - - - - - - - - - - H -   - F F - - - - - - - - - - - - - - - - - A -   - B F - - - - - - - - - - - - - - - - - A -   - D BcF - - - - - - - - - - - - - - - - A -   - - D B - - - - - - - - - - - - - - - - Ag-   - - B B - - - - - - - - - - - - - - - - O -   - - - C - - - - - - - - - - - - - - - - E -   - - - T T - - - - - - - - - - - - - - - - -   - - - - T - - - - - - - - - - - - - - - - -   - - - - - T B B - - - - - - - - - - - - - -   - - - - - - - Y C K W - - - - - - - - - - -   - - - - - - - - - - W - - - - - - - - - - -   - - - - - - - - - - - - - - - - - - - - - -   
- - J - - - - - - - - - - - - - - - - A - -   - - Z - - - - - - - - - - - - - - - - Aw- -   - - Ba- - - - - - - - - - - - - - - - E - -   - - Q - - - - - - - - - - - - - - - - Al- -   - - K - - - - - - - - - - - - - - - - A - -   - - M - - - - - - - - - - - - - - - - An- -   - - Ac- - - - - - - - - - - - - - - - A - -   - - J - - - - - - - - - - - - - - - - Ag- -   - - A - - - - - - - - - - - - - - - - H - -   - - A - - - - - - - - - - - - - - - - A - -   - - Ax- - - - - - - - - - - - - - - - A - -   - - Ao- - - - - - - - - - - - - - - - A - -   - - O - - - - - - - - - - - - - - - - L - -   - - B - - - - - - - - - - - - - - - - A - -   - - B - - - - - - - - - - - - - - - - H - -   - - F - - - - - - - - - - - - - - - - H - -   - - F F - - - - - - - - - - - - - - - A - -   - - B F - - - - - - - - - - - - - - - A - -   - - D F - - - - - - - - - - - - - - - A - -   - - D B - - - - - - - - - - - - - - - An- -   - - - B - - - - - - - - - - - - - - - O - -   - - - C - - - - - - - - - - - - - - - E - -   - - - - T T - - - - - - - - - - - - - - - -   - - - - - T - - - - - - - - - - - - - - - -   - - - - - - B E E N Y - - - - - - - - - - -   - - - - - - - - C K U - - - - - - - - - - -   - - - - - - - - - - - - - - - - - - - - - -   - - - - - - - - - - - - - - - - - - - - - -   
- - - A - - - - - - - - - - - - - - A - - -   - - - A - - - - - - - - - - - - - - A - - -   - - - A - - - - - - - - - - - - - - A - - -   - - - J - - - - - - - - - - - - - - A - - -   - - - K - - - - - - - - - - - - - - A - - -   - - - M - - - - - - - - - - - - - - Ag- - -   - - - J - - - - - - - - - - - - - - H - - -   - - - J - - - - - - - - - - - - - - An- - -   - - - A - - - - - - - - - - - - - - A - - -   - - - J - - - - - - - - - - - - - - A - - -   - - - Ak- - - - - - - - - - - - - - A - - -   - - - G - - - - - - - - - - - - - - A - - -   - - - O - - - - - - - - - - - - - - H - - -   - - - B - - - - - - - - - - - - - - Ag- - -   - - - B - - - - - - - - - - - - - - Ag- - -   - - - F - - - - - - - - - - - - - - A - - -   - - - O F - - - - - - - - - - - - - Bd- - -   - - - C F - - - - - - - - - - - - - A - - -   - - - B F F - - - - - - - - - - - - A - - -   - - - D B B - - - - - - - - - - - - Ag- - -   - - - - B B - - - - - - - - - - - - H - - -   - - - - AhS - - - - - - - - - - - - - - - -   - - - - - T Y Az- - - - - - - - - - - - - -   - - - - - - E E - - - - - - - - - - - - - -   - - - - - - - - E N Y - - - - - - - - - - -   - - - - - - - - - - - - - - - - - - - - - -   - - - - - - - - - - - - - - - - - - - - - -   - - - - - - - - - - - - - - - - - - - - - -   
- - - - A - - - - - - - - - - - - A - - - -   - - - - A - - - - - - - - - - - - J - - - -   - - - - A - - - - - - - - - - - - A - - - -   - - - - A - - - - - - - - - - - - A - - - -   - - - - K - - - - - - - - - - - - O - - - -   - - - - M - - - - - - - - - - - - I - - - -   - - - - J - - - - - - - - - - - - H - - - -   - - - - A - - - - - - - - - - - - H - - - -   - - - - J - - - - - - - - - - - - A - - - -   - - - - As- - - - - - - - - - - - A - - - -   - - - - Ad- - - - - - - - - - - - O - - - -   - - - - Am- - - - - - - - - - - - O - - - -   - - - - O - - - - - - - - - - - - H - - - -   - - - - B - - - - - - - - - - - - M - - - -   - - - - B - - - - - - - - - - - - M - - - -   - - - - F - - - - - - - - - - - - O - - - -   - - - - AmF F - - - - - - - - - - O - - - -   - - - - C F F C - - - - - - - - - I - - - -   - - - - B B F C - - - - - - - - - I - - - -   - - - - D D B C - - - - - - - - - A - - - -   - - - - - B B Az- - - - - - - - - - - - - -   - - - - - - S Az- - - - - - - - - - - - - -   - - - - - - - B V BgAq- - - - - - - - - - -   - - - - - - - - E B Aq- - - - - - - - - - -   - - - - - - - - - - - - - - - - - - - - - -   - - - - - - - - - - - - - - - - - - - - - -   - - - - - - - - - - - - - - - - - - - - - -   - - - - - - - - - - - - - - - - - - - - - -   
- - - - - A A A - - - - - - A A J - - - - -   - - - - - A A A - - - - - - A A Z - - - - -   - - - - - A A A - - - - - - Q Q Ba- - - - -   - - - - - A J J - - - - - - A M Q - - - - -   - - - - - I I O - - - - - - I I W - - - - -   - - - - - O A A - - - - - - T T T - - - - -   - - - - - J J J - - - - - - K I I - - - - -   - - - - - A J Ac- - - - - - K A J - - - - -   - - - - - J J M - - - - - - A A J - - - - -   - - - - - AsAaAy- - - - - - L M M - - - - -   - - - - - G AmAo- - - - - - F F Aj- - - - -   - - - - - AmAmA - - - - - - L L Aj- - - - -   - - - - - H F F - - - - - - L F F - - - - -   - - - - - B V F - - - - - - I M Ah- - - - -   - - - - - B V Ah- - - - - - I P S - - - - -   - - - - - F C T - - - - - - K AqAq- - - - -   - - - - - A K K - - - - - - U T Ah- - - - -   - - - - - C V R - - - - - - W U T - - - - -   - - - - - - D B R - - - - - - U U - - - - -   - - - - - - B D B - - - - - - - - - - - - -   - - - - - - - B D B F - - - - - - - - - - -   - - - - - - - - ApApAp- - - - - - - - - - -   - - - - - - - - - - Bh- - - - - - - - - - -   - - - - - - - - - - - - - - - - - - - - - -   - - - - - - - - - - - - - - - - - - - - - -   - - - - - - - - - - - - - - - - - - - - - -   - - - - - - - - - - - - - - - - - - - - - -   - - - - - - - - - - - - - - - - - - - - - -   
- - - - - - - - A J A A A A - - - - - - - -   - - - - - - - - A Q Q A Q Q - - - - - - - -   - - - - - - - - J Z Q A Z Z - - - - - - - -   - - - - - - - - J Q J A M M - - - - - - - -   - - - - - - - - I O A A AoM - - - - - - - -   - - - - - - - - A A G AyL Ae- - - - - - - -   - - - - - - - - A AoAaAaX Ae- - - - - - - -   - - - - - - - - AcW U S T S - - - - - - - -   - - - - - - - - X L BeAbX H - - - - - - - -   - - - - - - - - AdArAdAkArAr- - - - - - - -   - - - - - - - - L X AtBeL Aj- - - - - - - -   - - - - - - - - I S S ApAhAe- - - - - - - -   - - - - - - - - S T S AeL Ak- - - - - - - -   - - - - - - - - P AeX AkAaH - - - - - - - -   - - - - - - - - AeAfArAaAcAc- - - - - - - -   - - - - - - - - AtAkAdAsAcAc- - - - - - - -   - - - - - - - - H AyAoJ AcAc- - - - - - - -   - - - - - - - - F F F I AcAc- - - - - - - -   - - - - - - - - B B B - - - - - - - - - - -   - - - - - - - - - V F - - - - - - - - - - -   - - - - - - - - - - - - - - - - - - - - - -   - - - - - - - - - - - - - - - - - - - - - -   - - - - - - - - - - - - - - - - - - - - - -   - - - - - - - - - - - - - - - - - - - - - -   - - - - - - - - - - - - - - - - - - - - - -   - - - - - - - - - - - - - - - - - - - - - -   - - - - - - - - - - - - - - - - - - - - - -   - - - - - - - - - - - - - - - - - - - - - -   
