model
size = 22 28 22, scale = 0.05, origin = -y
material 
  colors = A:#CC9 B:#C66 C:#C90 D:#C99 E:#966 F:#C63 G:#AAA H:#936 I:#C36 J:#C93 K:#C96 L:#996 M:#F90 N:#F06 O:#CC6 P:#F33 Q:#C00 R:#099 S:#963 T:#C33 U:#E00 V:#CC3 W:#993 X:#663 Y:#399 Z:#777 Aa:#396 Ab:#990 Ac:#690 Ad:#C06 Ae:#F36 Af:#D00 Ag:#696 Ah:#444 Ai:#693 Aj:#933 Ak:#888 Al:#F60 Am:#555 An:#F00 Ao:#F30 Ap:#660 Aq:#999 Ar:#F66 As:#699 At:#C60 Au:#CC0 Av:#F63 Aw:#669
voxels
- - - - - - - - A A O J V A - - - - - - - -   - - - - - - - - A A A O V V - - - - - - - -   - - - - - - - - J O A A A V - - - - - - - -   - - - - - - - - O J O A A A - - - - - - - -   - - - - - - - - D K K O A A - - - - - - - -   - - - - - - - - D D D A A A - - - - - - - -   - - - - - - - - D D D D D D - - - - - - - -   - - - - - - - - D D D D D B - - - - - - - -   - - - - - - - - D D D D D B - - - - - - - -   - - - - - - - - D D D D B B - - - - - - - -   - - - - - - - - A A D D B D - - - - - - - -   - - - - - - - - A A A D B D - - - - - - - -   - - - - - - - - A A A B B A - - - - - - - -   - - - - - - - - A A D B E A - - - - - - - -   - - - - - - - - A A B H B A - - - - - - - -   - - - - - - - - A D E E D A - - - - - - - -   - - - - - - - - A D E B D A - - - - - - - -   - - - - - - - - A D B B D A - - - - - - - -   - - - - - - - - - - - A A D - - - - - - - -   - - - - - - - - - - - A A - - - - - - - - -   - - - - - - - - - - - - - - - - - - - - - -   - - - - - - - - - - - - - - - - - - - - - -   - - - - - - - - - - - - - - - - - - - - - -   - - - - - - - - - - - - - - - - - - - - - -   - - - - - - - - - - - - - - - - - - - - - -   - - - - - - - - - - - - - - - - - - - - - -   - - - - - - - - - - - - - - - - - - - - - -   - - - - - - - - - - - - - - - - - - - - - -   
- - - - - C O A - - - - - - A A O - - - - -   - - - - - O V V - - - - - - A A A - - - - -   - - - - - A A V - - - - - - J O A - - - - -   - - - - - A A A - - - - - - O J V - - - - -   - - - - - K D D - - - - - - D K K - - - - -   - - - - - D D D - - - - - - E E A - - - - -   - - - - - D D D - - - - - - E D A - - - - -   - - - - - D D D - - - - - - E A A - - - - -   - - - - - D D D - - - - - - D A A - - - - -   - - - - - D D D - - - - - - A A A - - - - -   - - - - - A A A - - - - - - A A A - - - - -   - - - - - A A A - - - - - - A A A - - - - -   - - - - - A A A - - - - - - A A A - - - - -   - - - - - A A A - - - - - - A A A - - - - -   - - - - - A A A - - - - - - A A A - - - - -   - - - - - A A A - - - - - - A A D - - - - -   - - - - - A A A - - - - - - A A D - - - - -   - - - - - A A A - - - - - - A A K - - - - -   - - - - - A A - - - - - - A B E - - - - - -   - - - - - - - - - - - - - D I B - - - - - -   - - - - - - - - - - - A A K T - - - - - - -   - - - - - - - - - - - D A A - - - - - - - -   - - - - - - - - - - - D - - - - - - - - - -   - - - - - - - - - - - - - - - - - - - - - -   - - - - - - - - - - - - - - - - - - - - - -   - - - - - - - - - - - - - - - - - - - - - -   - - - - - - - - - - - - - - - - - - - - - -   - - - - - - - - - - - - - - - - - - - - - -   
- - - - O - - - - - - - - - - - - J - - - -   - - - - A - - - - - - - - - - - - A - - - -   - - - - A - - - - - - - - - - - - A - - - -   - - - - O - - - - - - - - - - - - A - - - -   - - - - K - - - - - - - - - - - - O - - - -   - - - - D - - - - - - - - - - - - A - - - -   - - - - D - - - - - - - - - - - - A - - - -   - - - - D - - - - - - - - - - - - A - - - -   - - - - D - - - - - - - - - - - - A - - - -   - - - - D - - - - - - - - - - - - A - - - -   - - - - A - - - - - - - - - - - - A - - - -   - - - - A - - - - - - - - - - - - A - - - -   - - - - A - - - - - - - - - - - - D - - - -   - - - - A - - - - - - - - - - - - K - - - -   - - - - A - - - - - - - - - - - - B - - - -   - - - - A - - - - - - - - - - - - B - - - -   - - - - A - - - - - - - - - - B B B - - - -   - - - - A - - - - - - - - - B B B H - - - -   - - - - A - - - - - - - - - B B D B - - - -   - - - - A - - - - - - - - - B B A I - - - -   - - - - - - - - - - - - - - B F A - - - - -   - - - - - - - - - - - - - - G G - - - - - -   - - - - - - - - - - - G G A Ak- - - - - - -   - - - - - - - - - - - G G D - - - - - - - -   - - - - - - - - - - - - - - - - - - - - - -   - - - - - - - - - - - - - - - - - - - - - -   - - - - - - - - - - - - - - - - - - - - - -   - - - - - - - - - - - - - - - - - - - - - -   
- - - A - - - - - - - - - - - - - - C - - -   - - - A - - - - - - - - - - - - - - V - - -   - - - O - - - - - - - - - - - - - - A - - -   - - - W - - - - - - - - - - - - - - A - - -   - - - K - - - - - - - - - - - - - - A - - -   - - - D - - - - - - - - - - - - - - D - - -   - - - D - - - - - - - - - - - - - - D - - -   - - - D - - - - - - - - - - - - - - K - - -   - - - D - - - - - - - - - - - - - - E - - -   - - - D - - - - - - - - - - - - - - B - - -   - - - A - - - - - - - - - - - - - - B - - -   - - - A - - - - - - - - - - - - - - B - - -   - - - A - - - - - - - - - - - - - - E - - -   - - - A - - - - - - - - - - - - - - B - - -   - - - A - - - - - - - - - - - - - - B - - -   - - - A - - - - - - - - - - - - - - E - - -   - - - A - - - - - - - - - - - - - B E - - -   - - - A - - - - - - - - - - - - - B B - - -   - - - A - - - - - - - - - - - - B B B - - -   - - - A - - - - - - - - - - - - Q Q I - - -   - - - D - - - - - - - - - - - - AfAf- - - -   - - - - - - - - - - - - - - - - A T - - - -   - - - - - - - - - - - - - - G Y A - - - - -   - - - - - - - - - - - - - - G As- - - - - -   - - - - - - - - - - - L G G - - - - - - - -   - - - - - - - - - - - - - - - - - - - - - -   - - - - - - - - - - - - - - - - - - - - - -   - - - - - - - - - - - - - - - - - - - - - -   
- - A - - - - - - - - - - - - - - - - C - -   - - A - - - - - - - - - - - - - - - - C - -   - - S - - - - - - - - - - - - - - - - O - -   - - Z - - - - - - - - - - - - - - - - A - -   - - D - - - - - - - - - - - - - - - - D - -   - - D - - - - - - - - - - - - - - - - B - -   - - D - - - - - - - - - - - - - - - - B - -   - - D - - - - - - - - - - - - - - - - H - -   - - D - - - - - - - - - - - - - - - - B - -   - - D - - - - - - - - - - - - - - - - B - -   - - A - - - - - - - - - - - - - - - - E - -   - - A - - - - - - - - - - - - - - - - H - -   - - A - - - - - - - - - - - - - - - - B - -   - - A - - - - - - - - - - - - - - - - B - -   - - A - - - - - - - - - - - - - - - - E - -   - - A - - - - - - - - - - - - - - - - B - -   - - A - - - - - - - - - - - - - - - B B - -   - - A - - - - - - - - - - - - - - - B B - -   - - A - - - - - - - - - - - - - - - B E - -   - - A - - - - - - - - - - - - - - - Q I - -   - - A - - - - - - - - - - - - - - - U - - -   - - G - - - - - - - - - - - - - - - T - - -   - - - - - - - - - - - - - - - - A T - - - -   - - - - - - - - - - - - - - - - A - - - - -   - - - - - - - - - - - L G G A Ak- - - - - -   - - - - - - - - - - - L G G - - - - - - - -   - - - - - - - - - - - - - - - - - - - - - -   - - - - - - - - - - - - - - - - - - - - - -   
- G - - - - - - - - - - - - - - - - - - C -   - Am- - - - - - - - - - - - - - - - - - C -   - Ah- - - - - - - - - - - - - - - - - - C -   - G - - - - - - - - - - - - - - - - - - O -   - D - - - - - - - - - - - - - - - - - - D -   - D - - - - - - - - - - - - - - - - - - H -   - D - - - - - - - - - - - - - - - - - - E -   - D - - - - - - - - - - - - - - - - - - B -   - D - - - - - - - - - - - - - - - - - - B -   - A - - - - - - - - - - - - - - - - - - H -   - A - - - - - - - - - - - - - - - - - - E -   - A - - - - - - - - - - - - - - - - - - B -   - A - - - - - - - - - - - - - - - - - - B -   - A - - - - - - - - - - - - - - - - - - E -   - A - - - - - - - - - - - - - - - - - - B -   - A - - - - - - - - - - - - - - - - - - B -   - A - - - - - - - - - - - - - - - - - B H -   - A - - - - - - - - - - - - - - - - - B B -   - A - - - - - - - - - - - - - - - - B B - -   - G - - - - - - - - - - - - - - - - Q I - -   - D - - - - - - - - - - - - - - - - Q U - -   - G - - - - - - - - - - - - - - - - T - - -   - - - - - - - - - - - - - - - - - T I - - -   - - - - - - - - - - - - - - - - - B - - - -   - - - - - - - - - - - - - - G AcW - - - - -   - - - - - - - - - - - G G G G - - - - - - -   - - - - - - - - - - - G - - - - - - - - - -   - - - - - - - - - - - - - - - - - - - - - -   
- L - - - - - - - - - - - - - - - - - - C -   - X - - - - - - - - - - - - - - - - - - C -   - Am- - - - - - - - - - - - - - - - - - C -   - Ak- - - - - - - - - - - - - - - - - - J -   - D - - - - - - - - - - - - - - - - - - B -   - D - - - - - - - - - - - - - - - - - - H -   - D - - - - - - - - - - - - - - - - - - B -   - D - - - - - - - - - - - - - - - - - - B -   - D - - - - - - - - - - - - - - - - - - H -   - A - - - - - - - - - - - - - - - - - - B -   - A - - - - - - - - - - - - - - - - - - B -   - A - - - - - - - - - - - - - - - - - - H -   - A - - - - - - - - - - - - - - - - - - E -   - A - - - - - - - - - - - - - - - - - - B -   - A - - - - - - - - - - - - - - - - - - B -   - A - - - - - - - - - - - - - - - - - - H -   - A - - - - - - - - - - - - - - - - - - B -   - A - - - - - - - - - - - - - - - - - B B -   - A - - - - - - - - - - - - - - - - - B E -   - A - - - - - - - - - - - - - - - - - Q I -   - G - - - - - - - - - - - - - - - - - Af- -   - G - - - - - - - - - - - - - - - - - T - -   - - - - - - - - - - - - - - - - - - T - - -   - - - - - - - - - - - - - - - - - - Aj- - -   - - - - - - - - - - - - - - - G AjAj- - - -   - - - - - - - - - - - - - - G D - - - - - -   - - - - - - - - - - - G G G - - - - - - - -   - - - - - - - - - - - - - - - - - - - - - -   
- J - - - - - - - - - - - - - - - - - - C -   - O - - - - - - - - - - - - - - - - - - B -   - G - - - - - - - - - - - - - - - - - - B -   - Z - - - - - - - - - - - - - - - - - - J -   - K - - - - - - - - - - - - - - - - - - F -   - D - - - - - - - - - - - - - - - - - - B -   - D - - - - - - - - - - - - - - - - - - E -   - D - - - - - - - - - - - - - - - - - - E -   - D - - - - - - - - - - - - - - - - - - B -   - D - - - - - - - - - - - - - - - - - - B -   - A - - - - - - - - - - - - - - - - - - H -   - A - - - - - - - - - - - - - - - - - - H -   - A - - - - - - - - - - - - - - - - - - B -   - A - - - - - - - - - - - - - - - - - - B -   - A - - - - - - - - - - - - - - - - - - E -   - A - - - - - - - - - - - - - - - - - - B -   - A - - - - - - - - - - - - - - - - - - B -   - A - - - - - - - - - - - - - - - - - B E -   - A - - - - - - - - - - - - - - - - - B B -   - G - - - - - - - - - - - - - - - - - Q I -   - G - - - - - - - - - - - - - - - - - Q U -   - L - - - - - - - - - - - - - - - - - Q - -   - G - - - - - - - - - - - - - - - - Q Q - -   - - - - - - - - - - - - - - - - - - Q - - -   - - - - - - - - - - - - - - - - Q Q - - - -   - - - - - - - - - - - - - - - Q Q - - - - -   - - - - - - - - - - - G G G Q - - - - - - -   - - - - - - - - - - - - - - - - - - - - - -   
O - - - - - - - - - - - - - - - - - - - - C   A - - - - - - - - - - - - - - - - - - - - B   A - - - - - - - - - - - - - - - - - - - - B   O - - - - - - - - - - - - - - - - - - - - J   K - - - - - - - - - - - - - - - - - - - - F   D - - - - - - - - - - - - - - - - - - - - H   D - - - - - - - - - - - - - - - - - - - - B   D - - - - - - - - - - - - - - - - - - - - B   K - - - - - - - - - - - - - - - - - - - - B   D - - - - - - - - - - - - - - - - - - - - H   A - - - - - - - - - - - - - - - - - - - - E   A - - - - - - - - - - - - - - - - - - - - H   A - - - - - - - - - - - - - - - - - - - - Ar  A - - - - - - - - - - - - - - - - - - - - B   A - - - - - - - - - - - - - - - - - - - - B   A - - - - - - - - - - - - - - - - - - - - B   A - - - - - - - - - - - - - - - - - - - - E   A - - - - - - - - - - - - - - - - - - - - B   A - - - - - - - - - - - - - - - - - - - - B   A - - - - - - - - - - - - - - - - - - - H -   L - - - - - - - - - - - - - - - - - - - Af-   L - - - - - - - - - - - - - - - - - - - U -   G - - - - - - - - - - - - - - - - - - U - -   D - - - - - - - - - - - - - - - - - - U - -   - - - - - - - - - - - - - - - - - U U - - -   - - - - - - - - - - - - - - - - U U - - - -   - - - - - - - - - - - G G U U U - - - - - -   - - - - - - - - - - - G D - - - - - - - - -   
A - - - - - - - - - - - - - - - - - - - - C   G - - - - - - - - - - - - - - - - - - - - B   Z - - - - - - - - - - - - - - - - - - - - B   S - - - - - - - - - - - - - - - - - - - - J   J - - - - - - - - - - - - - - - - - - - - F   D - - - - - - - - - - - - - - - - - - - - B   D - - - - - - - - - - - - - - - - - - - - B   D - - - - - - - - - - - - - - - - - - - - E   K - - - - - - - - - - - - - - - - - - - - E   D - - - - - - - - - - - - - - - - - - - - B   A - - - - - - - - - - - - - - - - - - - - E   A - - - - - - - - - - - - - - - - - - - - I   A - - - - - - - - - - - - - - - - - - - - Ae  A - - - - - - - - - - - - - - - - - - - - K   A - - - - - - - - - - - - - - - - - - - - B   A - - - - - - - - - - - - - - - - - - - - B   A - - - - - - - - - - - - - - - - - - - - B   A - - - - - - - - - - - - - - - - - - - - I   A - - - - - - - - - - - - - - - - - - - - H   A - - - - - - - - - - - - - - - - - - - H B   A - - - - - - - - - - - - - - - - - - - I -   D - - - - - - - - - - - - - - - - - - - F -   G - - - - - - - - - - - - - - - - - - C - -   G - - - - - - - - - - - - - - - - - - C - -   G - - - - - - - - - - - - - - - - C C - - -   - - - - - - - - - - - - - - - - M M - - - -   - - - - - - - - - - - - - C C C - - - - - -   - - - - - - - - - - - G D F - - - - - - - -   
Aq- - - - - - - - - - - - - - - - - - - - C   Ah- - - - - - - - - - - - - - - - - - - - C   Ah- - - - - - - - - - - - - - - - - - - - C   X - - - - - - - - - - - - - - - - - - - - C   K - - - - - - - - - - - - - - - - - - - - F   D - - - - - - - - - - - - - - - - - - - - B   D - - - - - - - - - - - - - - - - - - - - H   D - - - - - - - - - - - - - - - - - - - - B   D - - - - - - - - - - - - - - - - - - - - B   D - - - - - - - - - - - - - - - - - - - - E   A - - - - - - - - - - - - - - - - - - - - H   A - - - - - - - - - - - - - - - - - - - - B   A - - - - - - - - - - - - - - - - - - - - B   A - - - - - - - - - - - - - - - - - - - - K   A - - - - - - - - - - - - - - - - - - - - X   A - - - - - - - - - - - - - - - - - - - - S   A - - - - - - - - - - - - - - - - - - - - I   A - - - - - - - - - - - - - - - - - - - - N   A - - - - - - - - - - - - - - - - - - - - I   A - - - - - - - - - - - - - - - - - - - I E   A - - - - - - - - - - - - - - - - - - - B -   A - - - - - - - - - - - - - - - - - - - F -   D - - - - - - - - - - - - - - - - - - M M -   G - - - - - - - - - - - - - - - - - - M - -   G - - - - - - - - - - - - - - - - M M - - -   - - - - - - - - - - - - - - - - M M - - - -   - - - - - - - - - - - - - - C C C - - - - -   - - - - - - - - - - - G J J - - - - - - - -   
C - - - - - - - - - - - - - - - - - - - - C   F - - - - - - - - - - - - - - - - - - - - C   F - - - - - - - - - - - - - - - - - - - - C   F - - - - - - - - - - - - - - - - - - - - C   C - - - - - - - - - - - - - - - - - - - - F   C - - - - - - - - - - - - - - - - - - - - H   C - - - - - - - - - - - - - - - - - - - - B   C - - - - - - - - - - - - - - - - - - - - B   J - - - - - - - - - - - - - - - - - - - - H   F - - - - - - - - - - - - - - - - - - - - H   F - - - - - - - - - - - - - - - - - - - - H   J - - - - - - - - - - - - - - - - - - - - B   C - - - - - - - - - - - - - - - - - - - - B   C - - - - - - - - - - - - - - - - - - - - K   C - - - - - - - - - - - - - - - - - - - - X   J - - - - - - - - - - - - - - - - - - - - Ai  F - - - - - - - - - - - - - - - - - - - - B   F - - - - - - - - - - - - - - - - - - - - N   J - - - - - - - - - - - - - - - - - - - - Ad  C - - - - - - - - - - - - - - - - - - - AdB   J - - - - - - - - - - - - - - - - - - - B -   G - - - - - - - - - - - - - - - - - - - F -   G - - - - - - - - - - - - - - - - - - M M -   G - - - - - - - - - - - - - - - - - - M - -   G - - - - - - - - - - - - - - - - M M - - -   - - - - - - - - - - - - - - - - M M - - - -   - - - - - - - - - - - - - - C C C - - - - -   - - - - - - - - - - - L J J - - - - - - - -   
F - - - - - - - - - - - - - - - - - - - - C   F - - - - - - - - - - - - - - - - - - - - C   C - - - - - - - - - - - - - - - - - - - - C   C - - - - - - - - - - - - - - - - - - - - C   F - - - - - - - - - - - - - - - - - - - - F   F - - - - - - - - - - - - - - - - - - - - B   C - - - - - - - - - - - - - - - - - - - - B   F - - - - - - - - - - - - - - - - - - - - H   F - - - - - - - - - - - - - - - - - - - - B   C - - - - - - - - - - - - - - - - - - - - E   C - - - - - - - - - - - - - - - - - - - - E   F - - - - - - - - - - - - - - - - - - - - B   F - - - - - - - - - - - - - - - - - - - - B   C - - - - - - - - - - - - - - - - - - - - L   F - - - - - - - - - - - - - - - - - - - - X   F - - - - - - - - - - - - - - - - - - - - Ai  C - - - - - - - - - - - - - - - - - - - - E   C - - - - - - - - - - - - - - - - - - - - H   F - - - - - - - - - - - - - - - - - - - - Ad  F - - - - - - - - - - - - - - - - - - - AdB   J - - - - - - - - - - - - - - - - - - - E -   A - - - - - - - - - - - - - - - - - - - F -   G - - - - - - - - - - - - - - - - - - M - -   A - - - - - - - - - - - - - - - - - - M - -   G - - - - - - - - - - - - - - - - M M - - -   - - - - - - - - - - - - - - - - M M - - - -   - - - - - - - - - - - - - C C C - - - - - -   - - - - - - - - - - - L L J - - - - - - - -   
F - - - - - - - - - - - - - - - - - - - - C   C - - - - - - - - - - - - - - - - - - - - Ab  V - - - - - - - - - - - - - - - - - - - - Ac  Au- - - - - - - - - - - - - - - - - - - - C   C - - - - - - - - - - - - - - - - - - - - F   F - - - - - - - - - - - - - - - - - - - - E   C - - - - - - - - - - - - - - - - - - - - H   T - - - - - - - - - - - - - - - - - - - - B   C - - - - - - - - - - - - - - - - - - - - B   C - - - - - - - - - - - - - - - - - - - - H   C - - - - - - - - - - - - - - - - - - - - E   C - - - - - - - - - - - - - - - - - - - - Ae  F - - - - - - - - - - - - - - - - - - - - B   C - - - - - - - - - - - - - - - - - - - - S   T - - - - - - - - - - - - - - - - - - - - Ai  C - - - - - - - - - - - - - - - - - - - - S   C - - - - - - - - - - - - - - - - - - - - I   C - - - - - - - - - - - - - - - - - - - - E   C - - - - - - - - - - - - - - - - - - - - I   P - - - - - - - - - - - - - - - - - - - H -   J - - - - - - - - - - - - - - - - - - - B -   A - - - - - - - - - - - - - - - - - - - F -   A - - - - - - - - - - - - - - - - - - M - -   A - - - - - - - - - - - - - - - - - - M - -   - - - - - - - - - - - - - - - - - M M - - -   - - - - - - - - - - - - - - - - M M - - - -   - - - - - - - - - - - L M M M M - - - - - -   - - - - - - - - - - - L L - - - - - - - - -   
- C - - - - - - - - - - - - - - - - - - C -   - V - - - - - - - - - - - - - - - - - - Ab-   - A - - - - - - - - - - - - - - - - - - Ac-   - O - - - - - - - - - - - - - - - - - - C -   - J - - - - - - - - - - - - - - - - - - F -   - F - - - - - - - - - - - - - - - - - - H -   - C - - - - - - - - - - - - - - - - - - B -   - P - - - - - - - - - - - - - - - - - - B -   - C - - - - - - - - - - - - - - - - - - H -   - C - - - - - - - - - - - - - - - - - - H -   - C - - - - - - - - - - - - - - - - - - I -   - C - - - - - - - - - - - - - - - - - - Ae-   - P - - - - - - - - - - - - - - - - - - B -   - C - - - - - - - - - - - - - - - - - - E -   - T - - - - - - - - - - - - - - - - - - X -   - C - - - - - - - - - - - - - - - - - - S -   - C - - - - - - - - - - - - - - - - - - I -   - C - - - - - - - - - - - - - - - - - I I -   - C - - - - - - - - - - - - - - - - - I I -   - P - - - - - - - - - - - - - - - - - I B -   - J - - - - - - - - - - - - - - - - - I B -   - G - - - - - - - - - - - - - - - - - S - -   - G - - - - - - - - - - - - - - - - S C - -   - - - - - - - - - - - - - - - - - - C - - -   - - - - - - - - - - - - - - - - M M - - - -   - - - - - - - - - - - - - - - M M - - - - -   - - - - - - - - - - - L L L L - - - - - - -   - - - - - - - - - - - - - - - - - - - - - -   
- C - - - - - - - - - - - - - - - - - - C -   - O - - - - - - - - - - - - - - - - - - C -   - A - - - - - - - - - - - - - - - - - - Ab-   - A - - - - - - - - - - - - - - - - - - C -   - J - - - - - - - - - - - - - - - - - - F -   - F - - - - - - - - - - - - - - - - - - B -   - C - - - - - - - - - - - - - - - - - - B -   - P - - - - - - - - - - - - - - - - - - H -   - C - - - - - - - - - - - - - - - - - - B -   - C - - - - - - - - - - - - - - - - - - E -   - C - - - - - - - - - - - - - - - - - - H -   - C - - - - - - - - - - - - - - - - - - B -   - P - - - - - - - - - - - - - - - - - - B -   - C - - - - - - - - - - - - - - - - - - B -   - T - - - - - - - - - - - - - - - - - - S -   - C - - - - - - - - - - - - - - - - - - S -   - C - - - - - - - - - - - - - - - - - - I -   - C - - - - - - - - - - - - - - - - - I I -   - C - - - - - - - - - - - - - - - - - I I -   - P - - - - - - - - - - - - - - - - - I H -   - J - - - - - - - - - - - - - - - - - B - -   - A - - - - - - - - - - - - - - - - - X - -   - - - - - - - - - - - - - - - - - - Ap- - -   - - - - - - - - - - - - - - - - - - Ap- - -   - - - - - - - - - - - - - - - L AbAb- - - -   - - - - - - - - - - - - - - L C - - - - - -   - - - - - - - - - - - L L L - - - - - - - -   - - - - - - - - - - - - - - - - - - - - - -   
- C - - - - - - - - - - - - - - - - - - C -   - O - - - - - - - - - - - - - - - - - - C -   - A - - - - - - - - - - - - - - - - - - C -   - A - - - - - - - - - - - - - - - - - - C -   - J - - - - - - - - - - - - - - - - - - F -   - F - - - - - - - - - - - - - - - - - - H -   - C - - - - - - - - - - - - - - - - - - E -   - P - - - - - - - - - - - - - - - - - - B -   - C - - - - - - - - - - - - - - - - - - B -   - C - - - - - - - - - - - - - - - - - - H -   - C - - - - - - - - - - - - - - - - - - E -   - C - - - - - - - - - - - - - - - - - - I -   - P - - - - - - - - - - - - - - - - - - Ae-   - C - - - - - - - - - - - - - - - - - - B -   - T - - - - - - - - - - - - - - - - - - B -   - C - - - - - - - - - - - - - - - - - - B -   - C - - - - - - - - - - - - - - - - - N H -   - C - - - - - - - - - - - - - - - - - N I -   - C - - - - - - - - - - - - - - - - I I - -   - P - - - - - - - - - - - - - - - - K E - -   - J - - - - - - - - - - - - - - - - K B - -   - A - - - - - - - - - - - - - - - - E - - -   - - - - - - - - - - - - - - - - - AcX - - -   - - - - - - - - - - - - - - - - - Ac- - - -   - - - - - - - - - - - - - - L L Ab- - - - -   - - - - - - - - - - - L L L L - - - - - - -   - - - - - - - - - - - L - - - - - - - - - -   - - - - - - - - - - - - - - - - - - - - - -   
- - C - - - - - - - - - - - - - - - - C - -   - - V - - - - - - - - - - - - - - - - C - -   - - A - - - - - - - - - - - - - - - - C - -   - - O - - - - - - - - - - - - - - - - C - -   - - J - - - - - - - - - - - - - - - - F - -   - - F - - - - - - - - - - - - - - - - H - -   - - C - - - - - - - - - - - - - - - - B - -   - - P - - - - - - - - - - - - - - - - B - -   - - C - - - - - - - - - - - - - - - - H - -   - - C - - - - - - - - - - - - - - - - B - -   - - C - - - - - - - - - - - - - - - - E - -   - - C - - - - - - - - - - - - - - - - H - -   - - F - - - - - - - - - - - - - - - - B - -   - - C - - - - - - - - - - - - - - - - B - -   - - T - - - - - - - - - - - - - - - - B - -   - - C - - - - - - - - - - - - - - - - K - -   - - C - - - - - - - - - - - - - - - N L - -   - - C - - - - - - - - - - - - - - - N I - -   - - C - - - - - - - - - - - - - - - N I - -   - - P - - - - - - - - - - - - - - - K B - -   - - J - - - - - - - - - - - - - - - K - - -   - - A - - - - - - - - - - - - - - - L - - -   - - - - - - - - - - - - - - - - A L - - - -   - - - - - - - - - - - - - - - - L - - - - -   - - - - - - - - - - - K K K L L - - - - - -   - - - - - - - - - - - K L L - - - - - - - -   - - - - - - - - - - - - - - - - - - - - - -   - - - - - - - - - - - - - - - - - - - - - -   
- - - C - - - - - - - - - - - - - - C - - -   - - - C - - - - - - - - - - - - - - Ag- - -   - - - V - - - - - - - - - - - - - - Aa- - -   - - - C - - - - - - - - - - - - - - J - - -   - - - C - - - - - - - - - - - - - - F - - -   - - - P - - - - - - - - - - - - - - B - - -   - - - C - - - - - - - - - - - - - - E - - -   - - - P - - - - - - - - - - - - - - E - - -   - - - C - - - - - - - - - - - - - - B - - -   - - - C - - - - - - - - - - - - - - B - - -   - - - C - - - - - - - - - - - - - - H - - -   - - - C - - - - - - - - - - - - - - E - - -   - - - P - - - - - - - - - - - - - - H - - -   - - - C - - - - - - - - - - - - - - B - - -   - - - P - - - - - - - - - - - - - - B - - -   - - - C - - - - - - - - - - - - - - I - - -   - - - C - - - - - - - - - - - - - N Ae- - -   - - - C - - - - - - - - - - - - - N N - - -   - - - C - - - - - - - - - - - - N N I - - -   - - - P - - - - - - - - - - - - K K E - - -   - - - J - - - - - - - - - - - - K K - - - -   - - - - - - - - - - - - - - - - A K - - - -   - - - - - - - - - - - - - - A A K - - - - -   - - - - - - - - - - - - - - D L - - - - - -   - - - - - - - - - - - A K K - - - - - - - -   - - - - - - - - - - - - - - - - - - - - - -   - - - - - - - - - - - - - - - - - - - - - -   - - - - - - - - - - - - - - - - - - - - - -   
- - - - C - - - - - - - - - - - - C - - - -   - - - - M - - - - - - - - - - - - Aa- - - -   - - - - Al- - - - - - - - - - - - R - - - -   - - - - C - - - - - - - - - - - - W - - - -   - - - - C - - - - - - - - - - - - F - - - -   - - - - F - - - - - - - - - - - - H - - - -   - - - - F - - - - - - - - - - - - E - - - -   - - - - F - - - - - - - - - - - - B - - - -   - - - - C - - - - - - - - - - - - E - - - -   - - - - C - - - - - - - - - - - - H - - - -   - - - - C - - - - - - - - - - - - B - - - -   - - - - J - - - - - - - - - - - - B - - - -   - - - - F - - - - - - - - - - - - H - - - -   - - - - F - - - - - - - - - - - - B - - - -   - - - - F - - - - - - - - - - - - B - - - -   - - - - C - - - - - - - - - - - - N - - - -   - - - - C - - - - - - - - - - N N N - - - -   - - - - C - - - - - - - - - - N N Ad- - - -   - - - - C - - - - - - - - - E N B H - - - -   - - - - F - - - - - - - - - E K E B - - - -   - - - - - - - - - - - - - - K K K - - - - -   - - - - - - - - - - - - - - A A - - - - - -   - - - - - - - - - - - A A A A - - - - - - -   - - - - - - - - - - - A A A - - - - - - - -   - - - - - - - - - - - - - - - - - - - - - -   - - - - - - - - - - - - - - - - - - - - - -   - - - - - - - - - - - - - - - - - - - - - -   - - - - - - - - - - - - - - - - - - - - - -   
- - - - - C C C - - - - - - C C C - - - - -   - - - - - AoAoAl- - - - - - C J Aa- - - - -   - - - - - AnAnAl- - - - - - C J R - - - - -   - - - - - C C C - - - - - - C C W - - - - -   - - - - - AtJ W - - - - - - F F F - - - - -   - - - - - S AgZ - - - - - - H B B - - - - -   - - - - - S F Z - - - - - - B H B - - - - -   - - - - - S Z R - - - - - - B B E - - - - -   - - - - - L AaR - - - - - - J B E - - - - -   - - - - - S R R - - - - - - F B B - - - - -   - - - - - AaR R - - - - - - B B B - - - - -   - - - - - Y R R - - - - - - E B E - - - - -   - - - - - Y R R - - - - - - B E E - - - - -   - - - - - Y Y R - - - - - - B E E - - - - -   - - - - - E E Z - - - - - - I I I - - - - -   - - - - - B B H - - - - - - I N N - - - - -   - - - - - E B B - - - - - - I N N - - - - -   - - - - - B E B - - - - - - E I I - - - - -   - - - - - E B - - - - - - B B E - - - - - -   - - - - - - - - - - - - - E B E - - - - - -   - - - - - - - - - - - K D K K - - - - - - -   - - - - - - - - - - - A A A - - - - - - - -   - - - - - - - - - - - A - - - - - - - - - -   - - - - - - - - - - - - - - - - - - - - - -   - - - - - - - - - - - - - - - - - - - - - -   - - - - - - - - - - - - - - - - - - - - - -   - - - - - - - - - - - - - - - - - - - - - -   - - - - - - - - - - - - - - - - - - - - - -   
- - - - - - - - C C C C C C - - - - - - - -   - - - - - - - - C C AvP P C - - - - - - - -   - - - - - - - - C C P N N C - - - - - - - -   - - - - - - - - C C C J J C - - - - - - - -   - - - - - - - - W C C J F F - - - - - - - -   - - - - - - - - AgC C C F B - - - - - - - -   - - - - - - - - AgM C C C F - - - - - - - -   - - - - - - - - AaC C C C C - - - - - - - -   - - - - - - - - R W M C C J - - - - - - - -   - - - - - - - - R W M J C B - - - - - - - -   - - - - - - - - Y J C B F F - - - - - - - -   - - - - - - - - Y F C F B B - - - - - - - -   - - - - - - - - Y E F F H B - - - - - - - -   - - - - - - - - AwB H B B E - - - - - - - -   - - - - - - - - E B B E B B - - - - - - - -   - - - - - - - - B E B B H B - - - - - - - -   - - - - - - - - E B E B B E - - - - - - - -   - - - - - - - - B E B E B B - - - - - - - -   - - - - - - - - - - - B E B - - - - - - - -   - - - - - - - - - - - B B - - - - - - - - -   - - - - - - - - - - - - - - - - - - - - - -   - - - - - - - - - - - - - - - - - - - - - -   - - - - - - - - - - - - - - - - - - - - - -   - - - - - - - - - - - - - - - - - - - - - -   - - - - - - - - - - - - - - - - - - - - - -   - - - - - - - - - - - - - - - - - - - - - -   - - - - - - - - - - - - - - - - - - - - - -   - - - - - - - - - - - - - - - - - - - - - -   
