model
size = 28 25 25, scale = 0.05, origin = -y
material 
  colors = A:#C66 B:#CC9 C:#C99 D:#C90 E:#996 F:#966 G:#AAA H:#999 I:#936 J:#C96 K:#993 L:#9C9 M:#963 N:#C33 O:#C36 P:#F60 Q:#696 R:#C63 S:#C93 T:#990 U:#663 V:#CC6 W:#E00 X:#888 Y:#444 Z:#F90 Aa:#699 Ab:#933 Ac:#399 Ad:#C30 Ae:#396 Af:#FFF Ag:#693 Ah:#099 Ai:#777 Aj:#D00 Ak:#CC3 Al:#690 Am:#C00 An:#666 Ao:#F06 Ap:#F36 Aq:#930 Ar:#333 As:#969 At:#F00 Au:#366 Av:#960 Aw:#C06 Ax:#360 Ay:#C03 Az:#555 Ba:#369 Bb:#660 Bc:#363 Bd:#633 Be:#F66 Bf:#C60 Bg:#F63 Bh:#C69 Bi:#F33
voxels
- - - - - - - - - - - - - - - - - - - - - - - - - - - -   - - - - - - - - - - - - - - - - - - - - - - - - - - - -   - - - - - - - - - - - - - AfAf- - - - - - - - - - - - -   - - - - - - - - - - - - - AfAf- - - - - - - - - - - - -   - - - - - - - - - - - - - - - - - - - - - - - - - - - -   - - - - - - - - - - - - - - - - - - - - - - - - - - - -   - - - - - - - - - - - - - - - - - - - - - - - - - - - -   - - - - - - - - - - - - - - - - - - - - - - - - - - - -   - - - - - - - - - - - - - - - - - - - - - - - - - - - -   - - - - - - - - - - - - - - - - - - - - - - - - - - - -   - - - - - - - - - - - - - - - - - - - - - - - - - - - -   - - - - - - - - - - - - - - - - - - - - - - - - - - - -   - - - - - - - - - - - - - AfAf- - - - - - - - - - - - -   - - - - - - - - - - - - - AfAf- - - - - - - - - - - - -   - - - - - - - - - - - - - - - - - - - - - - - - - - - -   - - - - - - - - - - - - - - - - - - - - - - - - - - - -   - - - - - - - - - - - - - - - - - - - - - - - - - - - -   - - - - - - - - - - - - - - - - - - - - - - - - - - - -   - - - - - - - - - - - - - - - - - - - - - - - - - - - -   - - - - - - - - - - - - - - - - - - - - - - - - - - - -   - - - - - - - - - - - - - - - - - - - - - - - - - - - -   - - - - - - - - - - - - - - - - - - - - - - - - - - - -   - - - - - - - - - - - - - AfAf- - - - - - - - - - - - -   - - - - - - - - - - - - - AfAf- - - - - - - - - - - - -   - - - - - - - - - - - - - - - - - - - - - - - - - - - -   
- - - - - - D D D T D D D T D D D D D D D D - - - - - -   - - - - - - U D U BdD Z T Y AeQ D D D T T D - - - - - -   - - - - - - U T U U D D M ArAhAeD D T AlAlD - - - - - -   - - - - - - M T M M D D M U K S D D D D D D - - - - - -   - - - - - - Q Q AgAgQ Q Q Q R R R R R R R R - - - - - -   - - - - - - N AyAjAyN AbAbM I A I I A I F A - - - - - -   - - - - - - AbAbAqAqAvAlAlAlF F A F A A I A - - - - - -   - - - - - - BaAcAeAeAeQ AgT A F A A I A A I - - - - - -   - - - - - - N N AbM S D D D F A I A A I A A - - - - - -   - - - - - - Q Q AiQ Q K D D I A A I F I I F - - - - - -   - - - - - - K K K T T T M AqA I F F I O F F - - - - - -   - - - - - - AhAeAeAeAeAeAnBfA F I O A ApApA - - - - - -   - - - - - - AcAcAcAcQ E S S I I A ApA A A A - - - - - -   - - - - - - L H H G G H L H A A A A A F M E - - - - - -   - - - - - - L H H L H H H H A A A A M U AgU - - - - - -   - - - - - - L H L H H AsA A AoO J A M M M Ag- - - - - -   - - - - - - H L H H H BhA A AoApE I O O O F - - - - - -   - - - - - - L H H L L H H H AwAoO O O O F I - - - - - -   - - - - - - H H H L L L L L I O O O O O O Aw- - - - - -   - - - - - - X X X X H L L L A F A F I A I A - - - - - -   - - - - - - R R A F X H H H J J J A A A A F - - - - - -   - - - - - - P P R E F E E J G J E F U M R R - - - - - -   - - - - - - P P BgC G G AaL E J E U BbD Z Z - - - - - -   - - - - - - P P R B C H AhAhE J E AlBbD Z Z - - - - - -   - - - - - - P P J B G H AhAhE J E T T Z Z Z - - - - - -   
- - - T D D A A A A A A A A A A A A A A A A D D D - - -   - - - Y D U A A A A A A A A A A A A A A A A D D A - - -   - - - U D Y A A A A A A A A A A A A A A A A D D A - - -   - - - M D M A A A A A A A A A A A A A A A A D D S - - -   - - - Q E E A A A A A A A A A A A A A A A A R R R - - -   - - - AiF O A A A A A A A A A A A A A A A A I A A - - -   - - - AbAbAbA A A A A A A A A A A A A A A A A I A - - -   - - - AnAnAuA A A A A A A A A A A A A A A A A A F - - -   - - - AjAjN A A A A A A A A A A A A A A A A I A F - - -   - - - AiAiQ A A A A A A A A A A A A A A A A I F A - - -   - - - K K K A A A A A A A A A A A A A A A A I I F - - -   - - - AhAhAhA A A A A A A A A A A A A A A A A A O - - -   - - - AaAcAcA A A A A A A A A A A A A A A A A A Ap- - -   - - - L H H A A A A A A A A A A A A A A A A J J J - - -   - - - L L H A A A A A A A A A A A A A A A A U U A - - -   - - - L H L A A A A A A A A A A A A A A A A AgM A - - -   - - - L L L A A A A A A A A A A A A A A A A A O A - - -   - - - L L H A A A A A A A A A A A A A A A A AoAoO - - -   - - - H H H A A A A A A A A A A A A A A A A AwO I - - -   - - - F E X A A A A A A A A A A A A A A A A A F A - - -   - - - P R R A A A A A A A A A A A A A A A A A A O - - -   - - - P P P A A A A A A A A A A A A A A A A R R R - - -   - - - P AdAdA A A A A A A A A A A A A A A A Z Z D - - -   - - - P AdAdA A A A A A A A A A A A A A A A Z Z D - - -   - - - P P P A A A A A A A A A A A A A A A A Z Z D - - -   
- - D A A A A A A A A A A A A A A A A A A A A A A D - -   - - U A A A A A A A A A A A A A A A A A A A A A A A - -   - - U A A A A A A A A A A A A A A A A A A A A A A A - -   - - M A A A A A A A A A A A A A A A A A A A A A A S - -   - - Q A A A A A A A A A A A A A A A A A A A A A A R - -   - - AsA A A A A A A A A A A A A A A A A A A A A A I - -   - - N A A A A A A A A A A A A A A A A A A A A A A A - -   - - N A A A A A A A A A A A A A A A A A A A A A A A - -   - - N A A A A A A A A A A A A A A A A A A A A A A A - -   - - AaA A A A A A A A A A A A A A A A A A A A A A I - -   - - E A A A A A A A A A A A A A A A A A A A A A A F - -   - - AeA A A A A A A A A A A A A A A A A A A A A A I - -   - - AaA A A A A A A A A A A A A A A A A A A A A A Be- -   - - L A A A A A A A A A A A A A A A A A A A A A A A - -   - - H A A A A A A A A A A A A A A A A A A A A A A A - -   - - H A A A A A A A A A A A A A A A A A A A A A A A - -   - - H A A A A A A A A A A A A A A A A A A A A A A F - -   - - L A A A A A A A A A A A A A A A A A A A A A A A - -   - - H A A A A A A A A A A A A A A A A A A A A A A A - -   - - F A A A A A A A A A A A A A A A A A A A A A A I - -   - - P A A A A A A A A A A A A A A A A A A A A A A Aj- -   - - P A A A A A A A A A A A A A A A A A A A A A A W - -   - - P A A A A A A A A A A A A A A A A A A A A A A W - -   - - P A A A A A A A A A A A A A A A A A A A A A A W - -   - - P A A A A A A A A A A A A A A A A A A A A A A W - -   
- D A A A - - - - - - - - - - - - - - - - - - A A A D -   - D A A A - - - - - - - - - - - - - - - - - - A A A A -   - T A A A - - - - - - - - - - - - - - - - - - A A A A -   - T A A A - - - - - - - - - - - - - - - - - - A A A S -   - Q A A A - - - - - - - - - - - - - - - - - - A A A R -   - AsA A A - - - - - - - - - - - - - - - - - - A A A A -   - O A A A - - - - - - - - - - - - - - - - - - A A A F -   - AtA A A - - - - - - - - - - - - - - - - - - A A A F -   - AbA A A - - - - - - - - - - - - - - - - - - A A A A -   - AaA A A - - - - - - - - - - - - - - - - - - A A A A -   - H A A A - - - - - - - - - - - - - - - - - - A A A I -   - AaA A A - - - - - - - - - - - - - - - - - - A A A I -   - AaA A A - - - - - - - - - - - - - - - - - - A A A A -   - H A A A - - - - - - - - - - - - - - - - - - A A A A -   - H A A A - - - - - - - - - - - - - - - - - - A A A F -   - L A A A - - - - - - - - - - - - - - - - - - A A A A -   - L A A A - - - - - - - - - - - - - - - - - - A A A A -   - L A A A - - - - - - - - - - - - - - - - - - A A A F -   - H A A A - - - - - - - - - - - - - - - - - - A A A A -   - F A A A - - - - - - - - - - - - - - - - - - A A A O -   - P A A A - - - - - - - - - - - - - - - - - - A A A W -   - P A A A - - - - - - - - - - - - - - - - - - A A A Am-   - P A A A - - - - - - - - - - - - - - - - - - A A A Am-   - P A A A - - - - - - - - - - - - - - - - - - A A A Am-   - P A A A - - - - - - - - - - - - - - - - - - A A A Am-   
D A A A A - - - - - - - - - - - - - - - - - - A A A A D   D A A A A - - - - - - - - - - - - - - - - - - A A A A D   T A A A A - - - - - - - - - - - - - - - - - - A A A A D   T A A A A - - - - - - - - - - - - - - - - - - A A A A S   Q A A A A - - - - - - - - - - - - - - - - - - A A A A A   BaA A A A - - - - - - - - - - - - - - - - - - A A A A I   A A A A A - - - - - - - - - - - - - - - - - - A A A A A   W A A A A - - - - - - - - - - - - - - - - - - A A A A A   AbA A A A - - - - - - - - - - - - - - - - - - A A A A I   AaA A A A - - - - - - - - - - - - - - - - - - A A A A A   L A A A A - - - - - - - - - - - - - - - - - - A A A A A   L A A A A - - - - - - - - - - - - - - - - - - A A A A I   H A A A A - - - - - - - - - - - - - - - - - - A A A A F   L A A A A - - - - - - - - - - - - - - - - - - A A A A A   H A A A A - - - - - - - - - - - - - - - - - - A A A A A   L A A A A - - - - - - - - - - - - - - - - - - A A A A I   H A A A A - - - - - - - - - - - - - - - - - - A A A A A   L A A A A - - - - - - - - - - - - - - - - - - A A A A A   H A A A A - - - - - - - - - - - - - - - - - - A A A A F   F A A A A - - - - - - - - - - - - - - - - - - A A A A O   R A A A A - - - - - - - - - - - - - - - - - - A A A A Aj  P A A A A - - - - - - - - - - - - - - - - - - A A A A N   AdA A A A - - - - - - - - - - - - - - - - - - A A A A N   AdA A A A - - - - - - - - - - - - - - - - - - A A A A Ab  P A A A A - - - - - - - - - - - - - - - - - - A A A A Ab  
D A A A - - - - - - - - - - - - - - - - - - - - A A A D   D A A A - - - - - - - - - - - - - - - - - - - - A A A D   D A A A - - - - - - - - - - - - - - - - - - - - A A A D   D A A A - - - - - - - - - - - - - - - - - - - - A A A V   Q A A A - - - - - - - - - - - - - - - - - - - - A A A C   AhA A A - - - - - - - - - - - - - - - - - - - - A A A I   K A A A - - - - - - - - - - - - - - - - - - - - A A A F   P A A A - - - - - - - - - - - - - - - - - - - - A A A A   N A A A - - - - - - - - - - - - - - - - - - - - A A A A   AaA A A - - - - - - - - - - - - - - - - - - - - A A A I   H A A A - - - - - - - - - - - - - - - - - - - - A A A F   L A A A - - - - - - - - - - - - - - - - - - - - A A A A   H A A A - - - - - - - - - - - - - - - - - - - - A A A A   H A A A - - - - - - - - - - - - - - - - - - - - A A A F   H A A A - - - - - - - - - - - - - - - - - - - - A A A A   L A A A - - - - - - - - - - - - - - - - - - - - A A A A   L A A A - - - - - - - - - - - - - - - - - - - - A A A I   L A A A - - - - - - - - - - - - - - - - - - - - A A A A   X A A A - - - - - - - - - - - - - - - - - - - - A A A A   F A A A - - - - - - - - - - - - - - - - - - - - A A A O   R A A A - - - - - - - - - - - - - - - - - - - - A A A W   P A A A - - - - - - - - - - - - - - - - - - - - A A A N   AdA A A - - - - - - - - - - - - - - - - - - - - A A A O   AdA A A - - - - - - - - - - - - - - - - - - - - A A A A   P A A A - - - - - - - - - - - - - - - - - - - - A A A K   
D A A A - - - - - - - - - - - - - - - - - - - - A A A D   D A A A - - - - - - - - - - - - - - - - - - - - A A A D   D A A A - - - - - - - - - - - - - - - - - - - - A A A V   D A A A - - - - - - - - - - - - - - - - - - - - A A A B   S A A A - - - - - - - - - - - - - - - - - - - - A A A C   Q A A A - - - - - - - - - - - - - - - - - - - - A A A A   K A A A - - - - - - - - - - - - - - - - - - - - A A A A   Z A A A - - - - - - - - - - - - - - - - - - - - A A A I   N A A A - - - - - - - - - - - - - - - - - - - - A A A A   X A A A - - - - - - - - - - - - - - - - - - - - A A A A   H A A A - - - - - - - - - - - - - - - - - - - - A A A F   H A A A - - - - - - - - - - - - - - - - - - - - A A A I   H A A A - - - - - - - - - - - - - - - - - - - - A A A A   L A A A - - - - - - - - - - - - - - - - - - - - A A A A   L A A A - - - - - - - - - - - - - - - - - - - - A A A F   L A A A - - - - - - - - - - - - - - - - - - - - A A A A   H A A A - - - - - - - - - - - - - - - - - - - - A A A A   H A A A - - - - - - - - - - - - - - - - - - - - A A A A   X A A A - - - - - - - - - - - - - - - - - - - - A A A F   A A A A - - - - - - - - - - - - - - - - - - - - A A A O   R A A A - - - - - - - - - - - - - - - - - - - - A A A W   P A A A - - - - - - - - - - - - - - - - - - - - A A A N   P A A A - - - - - - - - - - - - - - - - - - - - A A A N   P A A A - - - - - - - - - - - - - - - - - - - - A A A O   P A A A - - - - - - - - - - - - - - - - - - - - A A A A   
T A A A - - - - - - - - - - - - - - - - - - - - A A A D   Y A A A - - - - - - - - - - - - - - - - - - - - A A A Ak  Y A A A - - - - - - - - - - - - - - - - - - - - A A A B   M A A A - - - - - - - - - - - - - - - - - - - - A A A B   S A A A - - - - - - - - - - - - - - - - - - - - A A A B   D A A A - - - - - - - - - - - - - - - - - - - - A A A C   D A A A - - - - - - - - - - - - - - - - - - - - A A A C   D A A A - - - - - - - - - - - - - - - - - - - - A A A J   S A A A - - - - - - - - - - - - - - - - - - - - A A A F   X A A A - - - - - - - - - - - - - - - - - - - - A A A A   L A A A - - - - - - - - - - - - - - - - - - - - A A A A   H A A A - - - - - - - - - - - - - - - - - - - - A A A A   H A A A - - - - - - - - - - - - - - - - - - - - A A A F   H A A A - - - - - - - - - - - - - - - - - - - - A A A A   H A A A - - - - - - - - - - - - - - - - - - - - A A A A   L A A A - - - - - - - - - - - - - - - - - - - - A A A F   H A A A - - - - - - - - - - - - - - - - - - - - A A A F   A A A A - - - - - - - - - - - - - - - - - - - - A A A A   A A A A - - - - - - - - - - - - - - - - - - - - A A A A   A A A A - - - - - - - - - - - - - - - - - - - - A A A O   R A A A - - - - - - - - - - - - - - - - - - - - A A A Aj  P A A A - - - - - - - - - - - - - - - - - - - - A A A N   P A A A - - - - - - - - - - - - - - - - - - - - A A A W   P A A A - - - - - - - - - - - - - - - - - - - - A A A W   R A A A - - - - - - - - - - - - - - - - - - - - A A A N   
D A A A - - - - - - - - - - - - - - - - - - - - A A A S   M A A A - - - - - - - - - - - - - - - - - - - - A A A B   U A A A - - - - - - - - - - - - - - - - - - - - A A A B   M A A A - - - - - - - - - - - - - - - - - - - - A A A B   R A A A - - - - - - - - - - - - - - - - - - - - A A A V   S A A A - - - - - - - - - - - - - - - - - - - - A A A B   K A A A - - - - - - - - - - - - - - - - - - - - A A A B   E A A A - - - - - - - - - - - - - - - - - - - - A A A B   E A A A - - - - - - - - - - - - - - - - - - - - A A A B   E A A A - - - - - - - - - - - - - - - - - - - - A A A B   B A A A - - - - - - - - - - - - - - - - - - - - A A A B   B A A A - - - - - - - - - - - - - - - - - - - - A A A B   G A A A - - - - - - - - - - - - - - - - - - - - A A A C   G A A A - - - - - - - - - - - - - - - - - - - - A A A J   L A A A - - - - - - - - - - - - - - - - - - - - A A A A   L A A A - - - - - - - - - - - - - - - - - - - - A A A A   H A A A - - - - - - - - - - - - - - - - - - - - A A A A   F A A A - - - - - - - - - - - - - - - - - - - - A A A I   I A A A - - - - - - - - - - - - - - - - - - - - A A A A   I A A A - - - - - - - - - - - - - - - - - - - - A A A O   A A A A - - - - - - - - - - - - - - - - - - - - A A A Aj  R A A A - - - - - - - - - - - - - - - - - - - - A A A N   R A A A - - - - - - - - - - - - - - - - - - - - A A A Ad  J A A A - - - - - - - - - - - - - - - - - - - - A A A At  J A A A - - - - - - - - - - - - - - - - - - - - A A A At  
D A A A - - - - - - - - - - - - - - - - - - - - A A A V   D A A A - - - - - - - - - - - - - - - - - - - - A A A B   T A A A - - - - - - - - - - - - - - - - - - - - A A A B   T A A A - - - - - - - - - - - - - - - - - - - - A A A Ak  K A A A - - - - - - - - - - - - - - - - - - - - A A A J   E A A A - - - - - - - - - - - - - - - - - - - - A A A B   E A A A - - - - - - - - - - - - - - - - - - - - A A A B   E A A A - - - - - - - - - - - - - - - - - - - - A A A B   S A A A - - - - - - - - - - - - - - - - - - - - A A A B   E A A A - - - - - - - - - - - - - - - - - - - - A A A B   E A A A - - - - - - - - - - - - - - - - - - - - A A A B   G A A A - - - - - - - - - - - - - - - - - - - - A A A B   C A A A - - - - - - - - - - - - - - - - - - - - A A A B   G A A A - - - - - - - - - - - - - - - - - - - - A A A B   H A A A - - - - - - - - - - - - - - - - - - - - A A A B   H A A A - - - - - - - - - - - - - - - - - - - - A A A C   X A A A - - - - - - - - - - - - - - - - - - - - A A A C   F A A A - - - - - - - - - - - - - - - - - - - - A A A J   A A A A - - - - - - - - - - - - - - - - - - - - A A A J   A A A A - - - - - - - - - - - - - - - - - - - - A A A A   A A A A - - - - - - - - - - - - - - - - - - - - A A A N   E A A A - - - - - - - - - - - - - - - - - - - - A A A R   G A A A - - - - - - - - - - - - - - - - - - - - A A A S   G A A A - - - - - - - - - - - - - - - - - - - - A A A R   G A A A - - - - - - - - - - - - - - - - - - - - A A A W   
D A A A - - - - - - - - - - - - - - - - - - - - A A A B   U A A A - - - - - - - - - - - - - - - - - - - - A A A B   U A A A - - - - - - - - - - - - - - - - - - - - A A A V   M A A A - - - - - - - - - - - - - - - - - - - - A A A S   K A A A - - - - - - - - - - - - - - - - - - - - A A A J   E A A A - - - - - - - - - - - - - - - - - - - - A A A F   E A A A - - - - - - - - - - - - - - - - - - - - A A A C   K A A A - - - - - - - - - - - - - - - - - - - - A A A B   D A A A - - - - - - - - - - - - - - - - - - - - A A A B   S A A A - - - - - - - - - - - - - - - - - - - - A A A B   E A A A - - - - - - - - - - - - - - - - - - - - A A A B   AgA A A - - - - - - - - - - - - - - - - - - - - A A A B   Q A A A - - - - - - - - - - - - - - - - - - - - A A A B   Q A A A - - - - - - - - - - - - - - - - - - - - A A A B   AcA A A - - - - - - - - - - - - - - - - - - - - A A A B   Q A A A - - - - - - - - - - - - - - - - - - - - A A A B   AiA A A - - - - - - - - - - - - - - - - - - - - A A A B   F A A A - - - - - - - - - - - - - - - - - - - - A A A B   A A A A - - - - - - - - - - - - - - - - - - - - A A A B   F A A A - - - - - - - - - - - - - - - - - - - - A A A B   I A A A - - - - - - - - - - - - - - - - - - - - A A A B   F A A A - - - - - - - - - - - - - - - - - - - - A A A B   J A A A - - - - - - - - - - - - - - - - - - - - A A A B   J A A A - - - - - - - - - - - - - - - - - - - - A A A B   J A A A - - - - - - - - - - - - - - - - - - - - A A A J   
D A A A - - - - - - - - - - - - - - - - - - - - A A A B   U A A A - - - - - - - - - - - - - - - - - - - - A A A B   U A A A - - - - - - - - - - - - - - - - - - - - A A A S   M A A A - - - - - - - - - - - - - - - - - - - - A A A V   K A A A - - - - - - - - - - - - - - - - - - - - A A A C   E A A A - - - - - - - - - - - - - - - - - - - - A A A F   E A A A - - - - - - - - - - - - - - - - - - - - A A A F   K A A A - - - - - - - - - - - - - - - - - - - - A A A F   E A A A - - - - - - - - - - - - - - - - - - - - A A A C   S A A A - - - - - - - - - - - - - - - - - - - - A A A B   AgA A A - - - - - - - - - - - - - - - - - - - - A A A B   AxA A A - - - - - - - - - - - - - - - - - - - - A A A B   AgA A A - - - - - - - - - - - - - - - - - - - - A A A B   K A A A - - - - - - - - - - - - - - - - - - - - A A A B   Q A A A - - - - - - - - - - - - - - - - - - - - A A A B   BcA A A - - - - - - - - - - - - - - - - - - - - A A A B   AxA A A - - - - - - - - - - - - - - - - - - - - A A A B   U A A A - - - - - - - - - - - - - - - - - - - - A A A B   E A A A - - - - - - - - - - - - - - - - - - - - A A A B   J A A A - - - - - - - - - - - - - - - - - - - - A A A B   N A A A - - - - - - - - - - - - - - - - - - - - A A A B   N A A A - - - - - - - - - - - - - - - - - - - - A A A B   N A A A - - - - - - - - - - - - - - - - - - - - A A A B   N A A A - - - - - - - - - - - - - - - - - - - - A A A B   N A A A - - - - - - - - - - - - - - - - - - - - A A A B   
D A A A - - - - - - - - - - - - - - - - - - - - A A A B   D A A A - - - - - - - - - - - - - - - - - - - - A A A Ak  D A A A - - - - - - - - - - - - - - - - - - - - A A A Ak  D A A A - - - - - - - - - - - - - - - - - - - - A A A B   K A A A - - - - - - - - - - - - - - - - - - - - A A A B   E A A A - - - - - - - - - - - - - - - - - - - - A A A B   E A A A - - - - - - - - - - - - - - - - - - - - A A A C   E A A A - - - - - - - - - - - - - - - - - - - - A A A A   E A A A - - - - - - - - - - - - - - - - - - - - A A A A   S A A A - - - - - - - - - - - - - - - - - - - - A A A A   K A A A - - - - - - - - - - - - - - - - - - - - A A A C   AxA A A - - - - - - - - - - - - - - - - - - - - A A A C   AgA A A - - - - - - - - - - - - - - - - - - - - A A A B   K A A A - - - - - - - - - - - - - - - - - - - - A A A B   Q A A A - - - - - - - - - - - - - - - - - - - - A A A B   BcA A A - - - - - - - - - - - - - - - - - - - - A A A B   U A A A - - - - - - - - - - - - - - - - - - - - A A A B   U A A A - - - - - - - - - - - - - - - - - - - - A A A B   E A A A - - - - - - - - - - - - - - - - - - - - A A A B   A A A A - - - - - - - - - - - - - - - - - - - - A A A B   W A A A - - - - - - - - - - - - - - - - - - - - A A A B   AmA A A - - - - - - - - - - - - - - - - - - - - A A A B   AmA A A - - - - - - - - - - - - - - - - - - - - A A A B   AdA A A - - - - - - - - - - - - - - - - - - - - A A A B   AdA A A - - - - - - - - - - - - - - - - - - - - A A A B   
T A A A - - - - - - - - - - - - - - - - - - - - A A A Ak  Y A A A - - - - - - - - - - - - - - - - - - - - A A A Ak  Y A A A - - - - - - - - - - - - - - - - - - - - A A A B   M A A A - - - - - - - - - - - - - - - - - - - - A A A B   K A A A - - - - - - - - - - - - - - - - - - - - A A A B   E A A A - - - - - - - - - - - - - - - - - - - - A A A B   E A A A - - - - - - - - - - - - - - - - - - - - A A A C   E A A A - - - - - - - - - - - - - - - - - - - - A A A C   E A A A - - - - - - - - - - - - - - - - - - - - A A A C   K A A A - - - - - - - - - - - - - - - - - - - - A A A A   K A A A - - - - - - - - - - - - - - - - - - - - A A A A   AgA A A - - - - - - - - - - - - - - - - - - - - A A A A   E A A A - - - - - - - - - - - - - - - - - - - - A A A A   E A A A - - - - - - - - - - - - - - - - - - - - A A A F   AnA A A - - - - - - - - - - - - - - - - - - - - A A A A   AnA A A - - - - - - - - - - - - - - - - - - - - A A A C   F A A A - - - - - - - - - - - - - - - - - - - - A A A C   F A A A - - - - - - - - - - - - - - - - - - - - A A A C   F A A A - - - - - - - - - - - - - - - - - - - - A A A C   N A A A - - - - - - - - - - - - - - - - - - - - A A A B   W A A A - - - - - - - - - - - - - - - - - - - - A A A B   N A A A - - - - - - - - - - - - - - - - - - - - A A A B   AdA A A - - - - - - - - - - - - - - - - - - - - A A A B   AjA A A - - - - - - - - - - - - - - - - - - - - A A A B   AjA A A - - - - - - - - - - - - - - - - - - - - A A A B   
D A A A - - - - - - - - - - - - - - - - - - - - A A A S   M A A A - - - - - - - - - - - - - - - - - - - - A A A V   U A A A - - - - - - - - - - - - - - - - - - - - A A A B   M A A A - - - - - - - - - - - - - - - - - - - - A A A B   K A A A - - - - - - - - - - - - - - - - - - - - A A A V   E A A A - - - - - - - - - - - - - - - - - - - - A A A B   E A A A - - - - - - - - - - - - - - - - - - - - A A A C   E A A A - - - - - - - - - - - - - - - - - - - - A A A C   E A A A - - - - - - - - - - - - - - - - - - - - A A A C   K A A A - - - - - - - - - - - - - - - - - - - - A A A C   K A A A - - - - - - - - - - - - - - - - - - - - A A A C   M A A A - - - - - - - - - - - - - - - - - - - - A A A C   S A A A - - - - - - - - - - - - - - - - - - - - A A A A   Q A A A - - - - - - - - - - - - - - - - - - - - A A A A   A A A A - - - - - - - - - - - - - - - - - - - - A A A I   A A A A - - - - - - - - - - - - - - - - - - - - A A A F   F A A A - - - - - - - - - - - - - - - - - - - - A A A A   I A A A - - - - - - - - - - - - - - - - - - - - A A A A   A A A A - - - - - - - - - - - - - - - - - - - - A A A F   O A A A - - - - - - - - - - - - - - - - - - - - A A A A   W A A A - - - - - - - - - - - - - - - - - - - - A A A R   AqA A A - - - - - - - - - - - - - - - - - - - - A A A G   T A A A - - - - - - - - - - - - - - - - - - - - A A A Ac  AvA A A - - - - - - - - - - - - - - - - - - - - A A A Aa  AdA A A - - - - - - - - - - - - - - - - - - - - A A A X   
D A A A - - - - - - - - - - - - - - - - - - - - A A A V   D A A A - - - - - - - - - - - - - - - - - - - - A A A B   D A A A - - - - - - - - - - - - - - - - - - - - A A A B   T A A A - - - - - - - - - - - - - - - - - - - - A A A V   K A A A - - - - - - - - - - - - - - - - - - - - A A A J   E A A A - - - - - - - - - - - - - - - - - - - - A A A C   E A A A - - - - - - - - - - - - - - - - - - - - A A A C   Q A A A - - - - - - - - - - - - - - - - - - - - A A A C   E A A A - - - - - - - - - - - - - - - - - - - - A A A C   E A A A - - - - - - - - - - - - - - - - - - - - A A A C   K A A A - - - - - - - - - - - - - - - - - - - - A A A C   AiA A A - - - - - - - - - - - - - - - - - - - - A A A B   K A A A - - - - - - - - - - - - - - - - - - - - A A A B   Q A A A - - - - - - - - - - - - - - - - - - - - A A A C   G A A A - - - - - - - - - - - - - - - - - - - - A A A A   J A A A - - - - - - - - - - - - - - - - - - - - A A A F   A A A A - - - - - - - - - - - - - - - - - - - - A A A F   A A A A - - - - - - - - - - - - - - - - - - - - A A A A   A A A A - - - - - - - - - - - - - - - - - - - - A A A A   O A A A - - - - - - - - - - - - - - - - - - - - A A A O   W A A A - - - - - - - - - - - - - - - - - - - - A A A N   N A A A - - - - - - - - - - - - - - - - - - - - A A A G   K A A A - - - - - - - - - - - - - - - - - - - - A A A X   AlA A A - - - - - - - - - - - - - - - - - - - - A A A G   T A A A - - - - - - - - - - - - - - - - - - - - A A A B   
D A A A - - - - - - - - - - - - - - - - - - - - A A A B   D A A A - - - - - - - - - - - - - - - - - - - - A A A B   D A A A - - - - - - - - - - - - - - - - - - - - A A A V   T A A A - - - - - - - - - - - - - - - - - - - - A A A S   K A A A - - - - - - - - - - - - - - - - - - - - A A A J   E A A A - - - - - - - - - - - - - - - - - - - - A A A C   E A A A - - - - - - - - - - - - - - - - - - - - A A A C   Q A A A - - - - - - - - - - - - - - - - - - - - A A A C   E A A A - - - - - - - - - - - - - - - - - - - - A A A C   E A A A - - - - - - - - - - - - - - - - - - - - A A A C   K A A A - - - - - - - - - - - - - - - - - - - - A A A B   AeA A A - - - - - - - - - - - - - - - - - - - - A A A B   AuA A A - - - - - - - - - - - - - - - - - - - - A A A B   AuA A A - - - - - - - - - - - - - - - - - - - - A A A B   X A A A - - - - - - - - - - - - - - - - - - - - A A A B   A A A A - - - - - - - - - - - - - - - - - - - - A A A C   A A A A - - - - - - - - - - - - - - - - - - - - A A A C   I A A A - - - - - - - - - - - - - - - - - - - - A A A C   I A A A - - - - - - - - - - - - - - - - - - - - A A A C   O A A A - - - - - - - - - - - - - - - - - - - - A A A C   W A A A - - - - - - - - - - - - - - - - - - - - A A A J   N A A A - - - - - - - - - - - - - - - - - - - - A A A B   C A A A - - - - - - - - - - - - - - - - - - - - A A A B   E A A A - - - - - - - - - - - - - - - - - - - - A A A C   K A A A - - - - - - - - - - - - - - - - - - - - A A A G   
D A A A - - - - - - - - - - - - - - - - - - - - A A A B   D A A A - - - - - - - - - - - - - - - - - - - - A A A B   D A A A - - - - - - - - - - - - - - - - - - - - A A A S   D A A A - - - - - - - - - - - - - - - - - - - - A A A V   K A A A - - - - - - - - - - - - - - - - - - - - A A A C   E A A A - - - - - - - - - - - - - - - - - - - - A A A C   E A A A - - - - - - - - - - - - - - - - - - - - A A A C   AaA A A - - - - - - - - - - - - - - - - - - - - A A A C   E A A A - - - - - - - - - - - - - - - - - - - - A A A C   E A A A - - - - - - - - - - - - - - - - - - - - A A A C   S A A A - - - - - - - - - - - - - - - - - - - - A A A B   E A A A - - - - - - - - - - - - - - - - - - - - A A A B   E A A A - - - - - - - - - - - - - - - - - - - - A A A B   E A A A - - - - - - - - - - - - - - - - - - - - A A A B   F A A A - - - - - - - - - - - - - - - - - - - - A A A B   I A A A - - - - - - - - - - - - - - - - - - - - A A A B   I A A A - - - - - - - - - - - - - - - - - - - - A A A B   A A A A - - - - - - - - - - - - - - - - - - - - A A A B   A A A A - - - - - - - - - - - - - - - - - - - - A A A B   O A A A - - - - - - - - - - - - - - - - - - - - A A A B   W A A A - - - - - - - - - - - - - - - - - - - - A A A B   N A A A - - - - - - - - - - - - - - - - - - - - A A A B   B A A A - - - - - - - - - - - - - - - - - - - - A A A G   B A A A - - - - - - - - - - - - - - - - - - - - A A A G   B A A A - - - - - - - - - - - - - - - - - - - - A A A G   
D A A A A - - - - - - - - - - - - - - - - - - A A A A B   D A A A A - - - - - - - - - - - - - - - - - - A A A A Ak  D A A A A - - - - - - - - - - - - - - - - - - A A A A Ak  D A A A A - - - - - - - - - - - - - - - - - - A A A A B   K A A A A - - - - - - - - - - - - - - - - - - A A A A C   E A A A A - - - - - - - - - - - - - - - - - - A A A A C   E A A A A - - - - - - - - - - - - - - - - - - A A A A C   AcA A A A - - - - - - - - - - - - - - - - - - A A A A C   E A A A A - - - - - - - - - - - - - - - - - - A A A A C   E A A A A - - - - - - - - - - - - - - - - - - A A A A C   S A A A A - - - - - - - - - - - - - - - - - - A A A A B   E A A A A - - - - - - - - - - - - - - - - - - A A A A B   E A A A A - - - - - - - - - - - - - - - - - - A A A A B   E A A A A - - - - - - - - - - - - - - - - - - A A A A B   F A A A A - - - - - - - - - - - - - - - - - - A A A A B   A A A A A - - - - - - - - - - - - - - - - - - A A A A B   A A A A A - - - - - - - - - - - - - - - - - - A A A A B   A A A A A - - - - - - - - - - - - - - - - - - A A A A B   F A A A A - - - - - - - - - - - - - - - - - - A A A A B   N A A A A - - - - - - - - - - - - - - - - - - A A A A B   W A A A A - - - - - - - - - - - - - - - - - - A A A A B   N A A A A - - - - - - - - - - - - - - - - - - A A A A C   B A A A A - - - - - - - - - - - - - - - - - - A A A A C   B A A A A - - - - - - - - - - - - - - - - - - A A A A G   B A A A A - - - - - - - - - - - - - - - - - - A A A A E   
- D A A A - - - - - - - - - - - - - - - - - - A A A V -   - D A A A - - - - - - - - - - - - - - - - - - A A A Ak-   - D A A A - - - - - - - - - - - - - - - - - - A A A B -   - D A A A - - - - - - - - - - - - - - - - - - A A A B -   - K A A A - - - - - - - - - - - - - - - - - - A A A C -   - E A A A - - - - - - - - - - - - - - - - - - A A A C -   - Q A A A - - - - - - - - - - - - - - - - - - A A A C -   - AcA A A - - - - - - - - - - - - - - - - - - A A A C -   - Q A A A - - - - - - - - - - - - - - - - - - A A A C -   - E A A A - - - - - - - - - - - - - - - - - - A A A C -   - S A A A - - - - - - - - - - - - - - - - - - A A A B -   - E A A A - - - - - - - - - - - - - - - - - - A A A B -   - E A A A - - - - - - - - - - - - - - - - - - A A A B -   - E A A A - - - - - - - - - - - - - - - - - - A A A B -   - A A A A - - - - - - - - - - - - - - - - - - A A A B -   - A A A A - - - - - - - - - - - - - - - - - - A A A B -   - F A A A - - - - - - - - - - - - - - - - - - A A A B -   - I A A A - - - - - - - - - - - - - - - - - - A A A B -   - A A A A - - - - - - - - - - - - - - - - - - A A A B -   - O A A A - - - - - - - - - - - - - - - - - - A A A B -   - W A A A - - - - - - - - - - - - - - - - - - A A A B -   - N A A A - - - - - - - - - - - - - - - - - - A A A G -   - B A A A - - - - - - - - - - - - - - - - - - A A A G -   - B A A A - - - - - - - - - - - - - - - - - - A A A G -   - B A A A - - - - - - - - - - - - - - - - - - A A A E -   
- - D A A A - - - - - - - - - - - - - - - - A A A D - -   - - M A A A - - - - - - - - - - - - - - - - A A A V - -   - - M A A A - - - - - - - - - - - - - - - - A A A B - -   - - M A A A - - - - - - - - - - - - - - - - A A A B - -   - - K A A A - - - - - - - - - - - - - - - - A A A J - -   - - E A A A - - - - - - - - - - - - - - - - A A A C - -   - - Q A A A - - - - - - - - - - - - - - - - A A A C - -   - - AcA A A - - - - - - - - - - - - - - - - A A A C - -   - - Q A A A - - - - - - - - - - - - - - - - A A A C - -   - - E A A A - - - - - - - - - - - - - - - - A A A C - -   - - K A A A - - - - - - - - - - - - - - - - A A A B - -   - - E A A A - - - - - - - - - - - - - - - - A A A B - -   - - E A A A - - - - - - - - - - - - - - - - A A A B - -   - - E A A A - - - - - - - - - - - - - - - - A A A B - -   - - F A A A - - - - - - - - - - - - - - - - A A A B - -   - - I A A A - - - - - - - - - - - - - - - - A A A B - -   - - A A A A - - - - - - - - - - - - - - - - A A A B - -   - - A A A A - - - - - - - - - - - - - - - - A A A B - -   - - A A A A - - - - - - - - - - - - - - - - A A A B - -   - - N A A A - - - - - - - - - - - - - - - - A A A B - -   - - W A A A - - - - - - - - - - - - - - - - A A A B - -   - - N A A A - - - - - - - - - - - - - - - - A A A G - -   - - J A A A - - - - - - - - - - - - - - - - A A A E - -   - - B A A A - - - - - - - - - - - - - - - - A A A G - -   - - B A A A - - - - - - - - - - - - - - - - A A A G - -   
- - - D A A A A - - - - - - - - - - - - A A A A V - - -   - - - Y A A A A - - - - - - - - - - - - A A A A B - - -   - - - ArA A A A - - - - - - - - - - - - A A A A B - - -   - - - U A A A A - - - - - - - - - - - - A A A A V - - -   - - - K A A A A - - - - - - - - - - - - A A A A J - - -   - - - E A A A A - - - - - - - - - - - - A A A A C - - -   - - - Q A A A A - - - - - - - - - - - - A A A A C - - -   - - - AcA A A A - - - - - - - - - - - - A A A A C - - -   - - - Q A A A A - - - - - - - - - - - - A A A A C - - -   - - - E A A A A - - - - - - - - - - - - A A A A C - - -   - - - K A A A A - - - - - - - - - - - - A A A A B - - -   - - - G A A A A - - - - - - - - - - - - A A A A B - - -   - - - B A A A A - - - - - - - - - - - - A A A A B - - -   - - - G A A A A - - - - - - - - - - - - A A A A B - - -   - - - A A A A A - - - - - - - - - - - - A A A A B - - -   - - - A A A A A - - - - - - - - - - - - A A A A B - - -   - - - A A A A A - - - - - - - - - - - - A A A A B - - -   - - - F A A A A - - - - - - - - - - - - A A A A B - - -   - - - I A A A A - - - - - - - - - - - - A A A A B - - -   - - - N A A A A - - - - - - - - - - - - A A A A B - - -   - - - W A A A A - - - - - - - - - - - - A A A A G - - -   - - - AbA A A A - - - - - - - - - - - - A A A A E - - -   - - - F A A A A - - - - - - - - - - - - A A A A G - - -   - - - A A A A A - - - - - - - - - - - - A A A A G - - -   - - - J A A A A - - - - - - - - - - - - A A A A G - - -   
- - - - D D A A A A A A A A A A A A A A A A B B - - - -   - - - - D D A A A A A A A A A A A A A A A A B B - - - -   - - - - D D A A A A A A A A A A A A A A A A M V - - - -   - - - - AvD A A A A A A A A A A A A A A A A AiK - - - -   - - - - K K A A A A A A A A A A A A A A A A C J - - - -   - - - - E K A A A A A A A A A A A A A A A A C C - - - -   - - - - Q E A A A A A A A A A A A A A A A A C C - - - -   - - - - AcAaA A A A A A A A A A A A A A A A C C - - - -   - - - - E E A A A A A A A A A A A A A A A A C C - - - -   - - - - E E A A A A A A A A A A A A A A A A C C - - - -   - - - - K E A A A A A A A A A A A A A A A A B B - - - -   - - - - J G A A A A A A A A A A A A A A A A B B - - - -   - - - - B E A A A A A A A A A A A A A A A A B B - - - -   - - - - G E A A A A A A A A A A A A A A A A B B - - - -   - - - - A F A A A A A A A A A A A A A A A A B B - - - -   - - - - F I A A A A A A A A A A A A A A A A B B - - - -   - - - - I A A A A A A A A A A A A A A A A A B B - - - -   - - - - F A A A A A A A A A A A A A A A A A B B - - - -   - - - - A F A A A A A A A A A A A A A A A A B B - - - -   - - - - O N A A A A A A A A A A A A A A A A B B - - - -   - - - - W W A A A A A A A A A A A A A A A A B C - - - -   - - - - AbN A A A A A A A A A A A A A A A A G G - - - -   - - - - AaC A A A A A A A A A A A A A A A A G G - - - -   - - - - X B A A A A A A A A A A A A A A A A E G - - - -   - - - - J B A A A A A A A A A A A A A A A A G G - - - -   
- - - - - - D T D D T D D K V B H B V S E G - - - - - -   - - - - - - D Y M D Y M D Y K M Y G B V U Az- - - - - -   - - - - - - D Y M D Y U D ArU M Y AiB G AzY - - - - - -   - - - - - - D M M T M M D M M T U M V AiX G - - - - - -   - - - - - - K K K K S J J J S J J S J J C C - - - - - -   - - - - - - K K K K J C C C C C C C C C C C - - - - - -   - - - - - - V V V Q X C J J C C C C C C C C - - - - - -   - - - - - - B B B X AaJ C C C C C C C C C C - - - - - -   - - - - - - B B B B E J C C C C C J J C C C - - - - - -   - - - - - - B B B B G E C C C C C C C C B B - - - - - -   - - - - - - V B B B B E J B B B B B B B B B - - - - - -   - - - - - - B B B B B E E B B B B B B B B B - - - - - -   - - - - - - B B B B B G E G B B B B B B B B - - - - - -   - - - - - - B B B B B B E E B B B B B B B B - - - - - -   - - - - - - C B B B B C F F J B B B B B B B - - - - - -   - - - - - - J G B B B C I O A B B B B B B B - - - - - -   - - - - - - F E B B B C F A F C B B B B B B - - - - - -   - - - - - - I A B B B C A A F C B B B B B B - - - - - -   - - - - - - F A C B B B A I A B B B B B B B - - - - - -   - - - - - - O O J B B B A N A B B B B G B G - - - - - -   - - - - - - W W A B B B J BiA B B B E G G C - - - - - -   - - - - - - N N J B B B B J C B B C E E G G - - - - - -   - - - - - - B B B B B B B G B B C G G G G G - - - - - -   - - - - - - B B B B B B B G B B G G C G C G - - - - - -   - - - - - - B B B B B B B G G B G G G G C G - - - - - -   
