model
size = 32 32 25, scale = 0.05, origin = -y
material 
  colors = A:#C66 B:#AAA C:#C96 D:#C99 E:#CC9 F:#996 G:#C90 H:#966 I:#F66 J:#C33 K:#C36 L:#C63 M:#699 N:#099 O:#963 P:#399 Q:#C93 R:#666 S:#999 T:#069 U:#444 V:#F33 W:#F90 X:#333 Y:#888 Z:#366 Aa:#C00 Ab:#555 Ac:#C30 Ad:#777 Ae:#369 Af:#396 Ag:#993 Ah:#669 Ai:#F60 Aj:#E00 Ak:#696 Al:#663 Am:#C39 An:#F30 Ao:#936 Ap:#F96 Aq:#CC6 Ar:#C60 As:#D00 At:#933 Au:#FFF Av:#939 Aw:#633 Ax:#C69 Ay:#F39 Az:#CC3 Ba:#693 Bb:#690 Bc:#990 Bd:#363 Be:#F36 Bf:#969 Bg:#636 Bh:#6C3 Bi:#960 Bj:#C03 Bk:#C06 Bl:#393 Bm:#639 Bn:#B00 Bo:#9C3 Bp:#C3C Bq:#33C Br:#C09 Bs:#F06
voxels
239-2Au30-2Au286-2Au30-2Au439-LCBEBS2NF2C2G3W16-AiCBDBS2NFCQ4WG16-LCBD2BPNCQ4G2Q16-C2BD2BMPQ2G5Q16-6B2F4G2QAgAk16-8CAg2QAgAkP2N16-8K2NP5N16-4DFAkOL7NP16-3E2C2HC6NPM16-D4C2DE5NP2M16-BD6E4NP3M16-5ED2E4NP2MP16-5EBDE3NP3MP16-7EB3NPMSMP16-7ES3NP3MP16-4E3BMP2NPMSMP16-B2CY2AeMYAAd2PSB2S16-4FAdPYM2A2S2M2S15-5FCYAdZAkYBYR4B13-3FC3FAd2ZM2BYU2YAdRAb10-RAbR2CLACFR2ZM2BSUX2UXUZAb6-RAlRAbRHAdAbZAdHR2Ab2BSYUAo2AmBgAfPAf2U4-2(OAl)RZAb2AoRZAbAlO4AdAbAo2AyAo3AfUX5-2Al2OZ2AoAvAoZAlOAlS3BYBg2AoBg3UX8-2OZAo2AvAoZ2ORMS3BR5X12-RAo2AvAoRAlAdAk2PM2BSAb2U17-BkKHAoH2-3MSB21-2An6-2C144-3Ai16A3W10-AiArAi16A3G10-AiAcAi16A2QL10-2LQ16AQFAk10-3B16APNP10-3C16A2NAf10-3K16APMAk10-OAdF16A2MAk10-FBD16AM2P10-EDC16APNP10-E2F16APNP10-E2B16APN3(P10-3E16A2N)P10-YSB16A3P10-MAeM16A3S10-YAdF16A2SAk9-RAdC18ABAdX4-J3RAbR20AU2XAfMSORAbR24AXAbPSHAl28AAfM2O28AAfM-OAl26AUAf3-2RAd22AXUZ5-F2AkAd18A2ZAkM10-HKBk5AHY5ASYS16-2AnA3An2-A2CACD19-2L8-2I110-3(Ai22AAj8-)L22AAs8-B22ABj8-C22AAs8-K22AAs8-L22AAs8-Ak22ABj8-S4(22AAa8-E)22AAa8-B22AAa8-P22AJ8-Y22AY8-M22AZ4-JAbZ2R22AX4-4Ab24A4X3R26A3Ab3R26A3Af3O26A3Af3L26A3MORA-24A-A2MAdAkF-24A-SBD2-HAAoHAo8AHY8A2SB2D8-3An5AAn2-6AD2B14-6L4-5IC107-Ai2(3A18-3AAa6-Ar)3A18-3AAa6-L2(3A18-3AAa6-F)3A18-3AAs6-K3A18-3AAs6-L3A18-3AAa2(6-Ak3A18-3AAs)6-F3A18-3AAs6-Y2(3A18-3AAa6-M)3A18-3AAa6-P3A18-3AAa6-M3A18-3AJ6-Ad3A18-3AS6-Z3A18-3AAf6-R3A18-3AZ2(6-R3A18-3AX)2(6-Al3A18-3AU)6-Al3A18-3AX3-3R4A18-4A3UF6A18-4A-AM2H5A18-5A2D-HJ3AnA18-ABD2CA7-2LA14-A2D13-6F6-6I73-Ai4A18-4AAt4-Ar4A18-4AAt4-Ac4A18-4AAt4-L4A18-4AAt4-B4A18-4AAt4-D4A18-4AAt4-K4A18-4AAt4-O4A18-4AAt4-Ak4A18-4AAt4-F2(4A18-4AAw4-Am)4A18-4AAt4-Bm4A18-4AJ4-T4A18-4AJ4-M4A18-4AJ4-Y4A18-4AK4-Ad4A18-4AS4-Z4A18-4AM4-Z4A18-4AP4-R4A18-4AAf4-Ab4A18-4AAb4-R4A18-4AU4-O4A18-4AX4-Al4A18-4AU4-R4A18-4AZ2-2F5A18-5A2MH6A18-6ADCHA-3A18-3A-3A2-O3L3A14-3AD3C8-3F14-3I15-Ag2F8-3I43-2(Ai3A20-3ABb4-)Ai3A20-3ABl4-C3A20-3AN4-B3A20-3AN4-C3A20-3AN4-K3A20-3AZ4-H3A20-3ABd4-Y3A20-3AT4-Am2(3A20-3AAe4-Ay)3A20-3AAd4-Bp3A20-3AH4-Bq3A20-4A4-Y3A20-4A4-M3A20-4A4-R3A20-3AD4-Ab3A20-3AB4-Ab2(3A20-3AM4-R)3A20-3AP4-Al2(3A20-3AAf4-O)3A20-3AAf4-R3A20-3AM4-Ak3A20-3AB2-2H5A18-5A2DHA-4A18-6ACBFO-3A18-3A-3C3-6F14-4I2C12-Ag12-I19-R10-I12-C3A20-3AH4-C3A20-3ABc4-C3A20-3ABb4-B3A20-3ABa4-B3A20-3AN4-C3A20-3AN4-K3A20-3AZ4-K3A20-3ABd4-Am3A20-3AT4-Ay3A20-3AP4-Ay3A20-3AY4-Ay3A20-3AM4-Br3A20-3AAd4-Av3A20-3AH4-Y2(3A20-4A4-H)3A20-3AAx4-J3A20-3AD2(4-J3A20-3AS)4-O3A20-3AS4-H3A20-3AM4-O3A20-3AM4-L3A20-3AM4-O3A20-3AM4-Ad3A20-3AD4-H3A20-3AD2-2C4A20-6ABF5A18-5A2C2-CF4A16-3A3C6-2Ag3F14-4I14-At12-I11-2(B3A20-4A4-)B3A20-3AAg4-B3A20-3ABb4-B3A20-3ABa4-C3A20-3AN4-4A20-3AZ4-K3A20-3ABd2(4-K3A20-3AT)4-K3A20-3AS4-K3A20-3AB4-Be3A20-3AS4-K3A20-3AAe4-4A20-3AH4-K4(3A20-4A4-Be)3A20-3AAx4-4A20-3AD4-C3A20-3AS3(4-4A20-3AB)4-4A20-3AD4-F3A20-3AH4-C3A20-3AU2-2B5A18-5A2C-FCF4A16-4A3C5-Q2SYF14-5I13-Q12-I11-B3A20-3AV4-B3A20-3AK4-B3A20-4A4-B3A20-3AAg4-B3A20-3ABb4-B3A20-3ABa4-B3A20-3ABl4-B3A20-3ABd2(4-B3A20-3AT)4-B3A20-3AM2(4-C3A20-3AE)4-C3A20-3AP4-Ap3A20-3AZ4-D3A20-3AQ4-C3A20-3AG4-C3A20-3AL4(4-C3A20-4A)4-D3A20-3AC4-C3A20-3AH4-C3A20-3AC4-C3A20-3AD4-F3A20-3AH4-B3A20-3AAb2-2B5A18-5A5C5A16-5A3C3-Ag3E2Az14-6I12-G12-I11-2(B3A20-3AAj4-)B3A20-3AK4-B3A20-4A4-B3A20-3AH4-B3A20-3ABc4-B3A20-3ABb4-B3A20-3ABd3(4-C3A20-3AT)4-C3A20-3AS4-D3A20-3AE4-C3A20-3AAe4-C3A20-3AZ4-D3A20-3AG4-C3A20-3AW3(4-D3A20-3AG)4-C3(3A20-3AG4-D)3A20-3AAc4-D3A20-3AJ4-C3(3A20-3AC4-B)4A18-4AH2-2C6A16-6A2D2-Ag2EAqQAz16-6I10-At14-I10-4(C3A20-3AC4-)2(F3A20-4A4-)F3A20-3AAl4-C3A20-3ABd3(4-C3A20-3AT)4-C3A2(20-3AY4-4A)20-3AT4-C3A20-3AAf4-C3A20-3AG6(4-C3A20-3AW)4-C3A20-3AG4-C3A20-3AAc4-C3A20-3AJ4-C3A20-3AD4-F3A20-3AC4-B3A20-3AH4-B4A18-4AH2-2F6A16-6A2D-Ag2EAzQAqE16-7I9-G14-I10-5(J3A20-3AE4-)J3A20-4A4-J3A20-3AO4-J3A20-3AZ2(4-Aj3A20-3AT)4-V3A20-3AT4-Aj3A20-3AS4-Aj3A20-3AY4-V3A20-3AT4-V3A20-3AR4-V3A20-3AG4-V6(3A20-3AW4-Aj)3A20-3AG4-Aj3A20-3AAc4-J3A20-3AJ4-C3A20-3AD4-B3A20-3AH4-B3A20-3AU4-B4A18-4AH2-2C6A16-6A2D-QE2Az3E16-6IC9-C14-I10-Ac2(3A20-3AE4-Aa)3A20-3AE4-Bn3A20-3AE4-Aa3A20-3AE4-Ac3A20-3AD4-Ac3A20-3AO4-Ac3A20-3AZ4-Ac3(3A20-3AT4-Aa)3A20-3AY4-Aa3A20-3AM4-Aa3A20-3AAe4-Ac3A20-3AH4-Ac3A20-3AQ2(4-Aa3A20-3AG)4(4-Aa3A20-3AW)4-Aa3A20-3AG4-Aa3A20-3AAc4-V3A20-3AV4-C3A20-3AC4-F3A20-3AC4-B3A20-3AH4-B4A18-4AH2-2F6A16-6A2D-C6G16-6GC9-I14-G10-J2(3A20-3AE4-L)3A20-3AE4-O3A20-3AE4-R3A20-3AE4-Z3A20-3AE4-H3A20-3AF4-K3A20-3AZ3(4-K3A20-3AT)4-K3A20-3AM4-K3A20-3AAe4-K3A20-3AH3(4-K3A20-4A)4-K3A20-3AQ4(4-K3A20-3AW)4-J3A20-3AG4-J3A20-3AAc4-V3A20-3AV4-C3A20-3AC4-C3A20-3AD4-B3A20-3AH4-C4A18-4AH2-2D6A16-6A2Ap-C6G16-6GC9-Ap14-G10-Aj3A20-3AD4-Ar3A20-3AE4-Q3A20-3AD4-Q3A20-3AB4-Ak3A20-3AB4-P3A20-3AB4-Ah3A20-3AB4-4A20-3AM2(4-4A20-3AT)4-L3A2(20-3AAe4-4A)20-3AAd4-4A20-4A4-K3A20-3AK4-4A20-3AJ4-Ax3A20-4A4-Am3A20-4A4-Ax3A20-3AQ4-4A20-3AG2(4-4A20-3AW)4-4A20-3AG4-J3A20-3AAc4-V3A20-3AV2(4-C3A20-3AD)4-F3A20-3AH4-C4A18-4AC2-2C6A16-6A2Ap-CAnArOX2U16-UXAlGAnAjC9-A14-I10-Bi3A20-3AB4-As3A20-3AB4-Aj3A20-3AB4-Ar3A20-3AB4-Q3A20-3AB4-Ag3A20-3AB4-H3A20-3AB4-Am3A20-3AB4-4A20-3AS4-L3A20-3AM4-Q3A20-3AAe4-4A20-3AAh4-4A20-4A4-K3A20-4A4-J3A2(20-3AK4-4A)20-4A2(4-Av3A20-3AK)4-Ae3A20-3AL4-Ad3A20-3AG4-F3A20-3AW4-4A20-3AG4-J3A20-3AAc4-V3A20-3AV4-C3A20-3AAp4-C3A20-3AD4-D3A20-3AC4-C4A18-5A2-2D6A16-6A2Ap2-HAiO4X14-3XAlArAjD11-Ap12-X11-2(Ag3A20-3AB4-)Ar3A20-3AB4-As3A20-3AB4-An3A20-3AB4-Ar3A20-3AB4-L3A2(20-3AB4-4A)20-3AD4-4A20-3AB2(4-4A20-3AF)4(4-4A20-3AC)4-4A20-4A2(4-Ae3A20-3AK)4-Ah3A20-4A4-T3A20-3AQ4-H3A20-3AW4-4A20-3AG4-J3A20-3AAc4-L3A20-3AV2(4-C3A20-3AC)4-D3A20-4A2-2D5A18-7AD2Ai5A16-5AAiQC3-AwBc4O14-3OBiGAp12-I12-O11-2(E3A20-3AB4-)Aq3A20-3AD4-Ag3A20-3AD4-Ac3A20-3AD4-As3A20-3AB4-J3A20-3AB4-4A20-3AD4-Bh3A20-3AD4-F3A3(20-3AB4-4A)20-3AB4-Bh3A20-3AB4-F3A20-3AB4-4A20-3AB4-H3A20-3AB4-T3A20-3AC4-T3A20-4A4-Ah3A20-4A4-Ae3A20-3AQ4-Ah3A20-3AW4-4A20-3AG4-J3A20-3AAc4-Q3A20-3AV4-E3A20-3AAp4-D4A18-4AH2-2D5A18-5A2UD6A18-6AH-ABcQ4A16-4AQAgC5-OQ2BcQ14-2Ag2QC13-I12-Ag11-E4A18-4AF2(4-E4A18-4AB)4-E4A18-4AD4-F4A18-4AB4-Ag4A18-4AB4-L4A18-4AD4-5A18-4AD4-Ba4A18-4AB4-F4A18-4AB4-Ax4A2(18-4AB4-5A)18-4AB4-Ba4A18-4AB4-F4A18-4AB4-5A18-4AF4-Ad4A18-4AF4-T4A18-4AB4-T4A18-4AC4-Ae2(4A18-5A4-Ah)4A18-4AG4-5A18-4AG4-J4A18-4AAc4-G4A18-4AV4-Aq4A18-4AC2-2E5A18-5A2HE6A18-6AAbDU5A18-5ANA2-AHI3A16-3AYPC7-2LXH14-MY2C14-A12-I12-2(E3A18-3AF6-)B3A18-3AB6-F3A18-3AD6-B2(3A18-3AD6-F)3A2(18-3AB6-4A)18-3AD6-4A18-3AD6-Am3A18-3AD6-4A18-3AB2(6-4A18-3AD)6-4A18-3AB6-F3A18-3AB6-H3(3A18-3AB6-T)3A18-3AC6-Ah3A18-4A6-Bf3A18-3AQ6-4A18-3AG6-J3A18-3AAc6-G3A18-3AV3-3Aq4A18-4A3DEA-4A18-4A-AHD6A18-7A-C5A18-5AH3-OAI3A16-AIY2PC9-LAI12-3C17-A10-I14-E3A16-3AB8-E2(3A16-3AF8-B)3A16-3AB8-B3(3A16-3AB8-F)3A16-3AD8-C3A2(16-3AD8-4A)16-3AB8-4A16-3AB8-L3A16-3AB8-4A16-3AD3(8-4A16-3AB)8-Ae2(3A16-3AB8-T)3A16-3AB8-Ae3A16-3AC8-Am3A16-4A8-4A16-3AL8-J3A16-3AAc4-4G4A16-4A4VAq7A16-7A2D2A-4A16-4A-2AC-E6A16-6AU3-C5A16-5AAb5-AwL4A14-AIAp3C11-L2A10-AIC19-AIAQ2A3CA16-C4A12-4AB10-D4A12-4AB10-B4(4A12-4AB10-F)4A12-4AD2(10-B4A12-4AB)10-F4A12-4AD10-C4A4(12-4AB10-5A)12-4AF10-5A12-4AB10-Am4A12-4AD10-Bf4A12-4AE10-Ae4A12-4AB5-2TAeT-T4A12-4AB-CA2B4AhAeAh4A12-4A6C4AmAAm4A12-10A4K6A12-6A4K4J6A12-6A4JQ9A12-9AVEAq8A12-8AApC-2E-6A12-7A2H3-2E6A12-6AUAb5-C6A12-6AU7-2O3L2A10-2A5C13-3LOLA2HCD3CD47-CE3(16A2B12-2B)16ADB12-BF16A2B3(12-2B16ADB)2(12-2B16A2D)12-BF2(16ABD12-2F)16A2D12-CF16A2D12-CB16AED12-CB16ADB12-AB16ABD12-AC16ABD12-18ABD6-AhAe4-H17AFB4-2AAe3Ah2-18A2F2-2A2Q3AhBfAm-Am17AAxA-AQG2W5A2K17AKAKL2A2G2J5AJ16AJ5A2Ac-2G26A2V3-2Aq24ADC5-2E22A2H7-2E20A2Ab8-2CQ18AC2H9-6L10A5CD16-O2LO2AwCAp2C51-D6ED5B2DB16-BEB4E5B3DB16-3B2E2D9B16-2FB2EB3D3BF2BD16-3B2(2ED)6BE16-3B5ED2BDEBDE16-2BD3E3D2BDEDBE16-2BD4E2BFB3E2D16-FB5EB2F3(DE)16-2F2EDCDEF2BDB2DE16-2F3ED2E5B3D16-FB7EBD4BD16-2FBS3ES2B3D3B16-4F2EDF3B4DB16-4F2(B2F)DED3B16-2B5FB3FEDF2B16-3B2FB5FBD3B16-4B6FA3BDB16-CB2FB4F2AC4B16-2AC4FC2AKAYF2B16-5AHF2AKBsK2A2F16-CBo3AHBa2A3K3AAx10-2A4-15AK4-2G4-5J-16J-2J3Ac5-2G2QJ4VJAr4GArJ9V7-2AqE2CD11C7D9-2E3C2ACD4EDA5HCH11-C5OLC4EDAXHCHUC13-4LAr2L6CUHAHU17-3LO2AwCApD3C23-A2HCDC45-
