model
size = 21 31 19, scale = 0.05, origin = -y
material 
  colors = A:#FF6 B:#E00 C:#0D0 D:#555
voxels
--------------------- --------------------- --------------------- --------------------- --------------------- --------------------- --------------------- --------------------- --------------------- --------------------- --------------------- --------ABAAA-------- -------AAAAAAA------- -------AAAAAAA------- -------AAAAAAA------- -------AAAAAAA------- -------AAAAAAA------- -----AAAAABBAAA------ ----AADADDDDDDDB----- ----AADADBBBDBDB----- ----DDDDDDDBDBDB----- ----DBDBBBDBDBDB----- ----DBBBBBDBDBDB----- ----DBBBDDDBDDDB----- ----BBBBBBBBBBBB----- -----BBBBBBBBBB------ --------------------- --------------------- --------------------- --------------------- --------------------- 
--------------------- --------------------- --------------------- --------------------- ---------BBB--------- --------BBBBB-------- --------BBBBB-------- --------BBBBB-------- --------BBBBB-------- --------BBBBB-------- --------BBBBB-------- -----CCC-----CCC----- -----CC-------CC----- -----CA-------CC----- -----CC-------CC----- -----CC-------CC----- -----CC-------CC----- ---CC-----------C---- ---C------------C---- ---C------------C---- ---C------------C---- ---C------------C---- ---C------------C---- ---CAAAAAAAAAAAAC---- ---CAAAAAAAAAAAAC---- ---CCAAAAAAAAAACC---- ----CCCBCCCCCCCC----- --------------------- --------------------- --------------------- --------------------- 
--------AAAAA-------- --------AAAAA-------- --------AAAAA-------- --------ABAAA-------- ------CC-----AA------ ------CC-----AA------ ------CC-----BA------ ------CB-----AA------ ------CC-----AA------ ------CC-----AA------ ------CC-----AA------ ----AA---------AA---- ----A-----------A---- ----A-----------A---- ----A-----------A---- ----A-----------A---- ----A-----------A---- --AA-------------C--- --A--------------C--- --A--------------C--- --A--------------C--- --A--------------C--- --A--------------C--- --AAAAAAAAAAAA---C--- --AAAAAAAAAAAA---C--- --AAAAAAAAAAAA---C--- --AAAAAAAAAAAA--AC--- ---AAAAAAAAAAAAAA---- --------------------- --------------------- --------------------- 
------BA-----AA------ ------BA-----AA------ ------BA-----AB------ ------BA-----AA------ ----CA---------BB---- ----CA---------BB---- ----CA---------BB---- ----CA---------BB---- ----CA---------AB---- ----CA---------BB---- ----CA---------BB---- ---B-------------B--- ---B-------------B--- ---B-------------B--- ---B-------------B--- ---B-------------B--- ---B-------------B--- -CA---------------B-- -C----------------B-- -C----------------B-- -C----------------B-- -C----------------B-- -C----------------B-- -CA----------A----B-- -CA----------A----B-- -CA----------A----B-- -CA----------A----B-- -CA----------A---AB-- -CAAAAAAAAAAAAAAAAB-- --------------------- --------------------- 
-----A---------B----- -----A---------B----- -----A---------B----- -----A---------B----- ----C-----------A---- ----C-----------A---- ----C-----------B---- ----C-----------A---- ----C-----------A---- ----C-----------A---- ----C-----------A---- --AA-------------AC-- --A---------------B-- --A---------------C-- --A---------------C-- --A---------------C-- --A---------------C-- -C-----------------C- -C-----------------C- -C-----------------C- -C-----------------C- -C-----------------C- -------------------C- -------------AAAAAAC- -------------AAAAAAC- -------------AAAAAAC- -------------AAAAAAC- -------------AAAAAB-- -CAAAAAAAAAAAAAAAAB-- --------------------- --------------------- 
----B-----------A---- ----B-----------B---- ----B-----------A---- ----B-----------A---- ---B-------------A--- ---B-------------A--- ---B-------------A--- ---B-------------A--- ---B-------------A--- ---B-------------A--- ---B-------------A--- --A---------------C-- --A---------------C-- --B---------------C-- --A---------------C-- --A---------------C-- --A---------------C-- -C-----------------C- -C-----------------C- -C-----------------C- -C-----------------C- -C-----------------C- -------------------C- -------------------C- -------------------C- -------------------C- -------------------C- -------------------C- -------------------C- -BBBBBBBBBBBBBBBBBBBB --------------------- 
----A-----------A---- ----A-----------A---- ----A-----------A---- ----A-----------A---- ---B-------------A--- ---B-------------A--- ---B-------------A--- ---A-------------A--- ---B-------------A--- ---B-------------A--- ---B-------------A--- -BA---------------AC- -B-----------------C- -B-----------------C- -B-----------------C- -B-----------------C- -B-----------------C- A-------------------B A-------------------B A-------------------B A-------------------B --------------------B --------------------- --------------------- --------------------- --------------------- --------------------- --------------------- --------------------- -BBBBBB-------BBBBBBB --------------------- 
---C-------------B--- ---C-------------B--- ---C-------------B--- ---C-------------B--- --A---------------C-- --B---------------C-- --A---------------C-- --A---------------C-- --A---------------A-- --A---------------C-- --A---------------C-- -B-----------------C- -B-----------------C- -B-----------------C- -B-----------------C- -B-----------------C- -B-----------------C- A-------------------B A-------------------B A-------------------B A-------------------B --------------------- --------------------- --------------------- --------------------- --------------------- --------------------- --------------------- --------------------- --------------------- -BBBBB---------AAABAA 
---C-------------B--- ---C-------------B--- ---C-------------B--- ---C-------------B--- --A---------------A-- --A---------------A-- --A---------------A-- --A---------------A-- --A---------------A-- --A---------------A-- --A---------------A-- -B-----------------C- -B-----------------C- -B-----------------C- -B-----------------C- -B-----------------C- -B-----------------C- A-------------------B A-------------------B A-------------------B --------------------- --------------------- --------------------- --------------------- --------------------- --------------------- --------------------- --------------------- --------------------- --------------------- -BBBB-----------AAAAA 
---C-------------B--- ---C-------------B--- ---C-------------B--- ---C-------------B--- --A---------------B-- --A---------------A-- --A---------------A-- --A---------------A-- --A---------------A-- --A---------------A-- --B---------------A-- -B-----------------C- -B-----------------C- -B-----------------C- -B-----------------C- -B-----------------C- -B-----------------C- A-------------------B A-------------------B --------------------- --------------------- --------------------- --------------------- --------------------- --------------------- --------------------- --------------------- --------------------- --------------------- --------------------- -BBBB-----------AAAAA 
---C-------------B--- ---C-------------B--- ---C-------------B--- ---C-------------B--- --A---------------A-- --A---------------A-- --A---------------A-- --A---------------A-- --A---------------A-- --A---------------A-- --A---------------A-- -B-----------------C- -B-----------------C- -B-----------------C- -B-----------------C- -B-----------------C- -B-----------------C- A-------------------B A-------------------B A-------------------B --------------------- --------------------- --------------------- --------------------- --------------------- --------------------- --------------------- --------------------- --------------------- --------------------- -BBBB-----------AAAAA 
---C-------------B--- ---C-------------B--- ---C-------------B--- ---C-------------B--- --A---------------A-- --A---------------A-- --A---------------A-- --A---------------B-- --A---------------A-- --A---------------A-- --A---------------A-- -B-----------------A- -B-----------------C- -B-----------------C- -B-----------------C- -B-----------------C- -B-----------------C- B-------------------B A-------------------B A-------------------B A-------------------B --------------------- --------------------- --------------------- --------------------- --------------------- --------------------- --------------------- --------------------- --------------------- -BBBBB---------AAABAA 
----A-----------A---- ----A-----------A---- ----A-----------A---- ----A-----------A---- ---A-------------B--- ---A-------------B--- ---A-------------A--- ---A-------------B--- ---A-------------B--- ---A-------------B--- ---A-------------B--- -BA---------------AC- -B-----------------C- -B-----------------C- -B-----------------B- -B-----------------C- -B-----------------C- A-------------------B A-------------------B A-------------------B A-------------------B A-------------------B --------------------- --------------------- --------------------- --------------------- --------------------- --------------------- --------------------- -ABAAAA-------BBBBBBB --------------------- 
----A-----------C---- ----A-----------C---- ----A-----------C---- ----A-----------C---- ---A-------------B--- ---A-------------B--- ---A-------------B--- ---A-------------B--- ---A-------------B--- ---A-------------B--- ---A-------------B--- -BA---------------A-- -BA---------------A-- -BA---------------A-- -BA---------------A-- -BA---------------A-- -BA---------------A-- AAA----------------B- AAA----------------B- AAA----------------B- AAA----------------B- AAA----------------B- AA-----------------B- --------------------- --------------------- --------------------- --------------------- --------------------- --------------------- -AAAAAAA-----BBBBBBBB --------------------- 
-----A---------A----- -----A---------A----- -----A---------A----- -----A---------A----- ----C-----------A---- ----C-----------B---- ----C-----------A---- ----C-----------A---- ----A-----------A---- ----C-----------A---- ----C-----------A---- -BBA-------------AB-- -BB---------------B-- -BB---------------B-- -BB---------------B-- -BB---------------B-- -BB---------------B-- -AA----------------B- -AA----------------B- -AA----------------B- -AA----------------B- -AA----------------B- -AA----------------B- -A-----------------B- -------------------B- -------------------B- -------------------B- -------------------B- -AAAAAAAAAAAAAAABAAB- --------------------- --------------------- 
------AA-----AB------ ------AA-----BB------ ------AA-----AB------ ------AA-----AB------ ----CA---------AA---- ----CA---------AA---- ----CA---------AA---- ----CA---------AA---- ----CA---------AA---- ----CA---------AA---- ----CA---------AA---- ---A-------------B--- ---A-------------B--- ---A-------------B--- ---A-------------B--- ---A-------------B--- ---A-------------B--- -AA---------------A-- -AA---------------A-- -AA---------------A-- -AA---------------A-- -AA---------------A-- -AA---------------A-- -AA---------------B-- -AA---------------A-- -AA---------------A-- -AA---------------A-- -AA---------------AB- -AAAAAAAAAAAAAAAAAAB- --------------------- --------------------- 
--------AAAAB-------- --------AAAAA-------- --------AAAAA-------- --------AAAAA-------- ------AA-----BB------ ------AA-----BB------ ------AA-----BB------ ------AA-----BB------ ------AA-----BB------ ------AA-----BB------ ------AA-----BB------ ----CA---------AA---- ----C-----------A---- ----C-----------B---- ----C-----------A---- ----C-----------A---- ----C-----------A---- ---CC------------B--- ---CC------------B--- ---CC------------B--- ---CC------------B--- ---AC------------B--- ---CC------------B--- ---CCAAAAAAAAAAAAB--- ---CAAAAAAAAAAAAAB--- ---CAAAAAAAAAAAAAA--- ---CCAAAAAAAAAAAAC--- -CCCCCCCCCCCCCCCCCC-- --------------------- --------------------- --------------------- 
--------------------- --------------------- --------------------- --------------------- --------CCCAC-------- --------CCCCC-------- --------ACCCC-------- --------CCCCC-------- --------CCCCB-------- --------CCCCC-------- --------CACCC-------- -----CCC-----CCC----- -----CC-------CC----- -----CC-------CC----- -----CA-------CC----- -----CC-------CC----- -----CC-------CC----- -----A----------C---- -----A----------C---- -----A----------C---- -----A----------C---- -----A----------C---- -----AA---------C---- -----AAAAAAAAAAAC---- ----CAAAAAAAAAAAC---- ----CCAAAAAAAAAACC--- -----CCCCCCCCCCCC---- --------------------- --------------------- --------------------- --------------------- 
--------------------- --------------------- --------------------- --------------------- --------------------- --------------------- --------------------- --------------------- --------------------- --------------------- --------------------- --------AAAAA-------- -------AAAAAAA------- -------AAAAAAA------- -------AAAAAAA------- -------AAAAAAA------- -------AAAAAAA------- -----DDDDDDDADAA----- -----DBDBBBDADAA----- -----DBDBDDDDDDD----- -----DBDBDBBBDBD----- -----DBDBDBBBBBD----- -----DDDBDDDBBBD----- -----BBBBBBBBBBB----- -----BBBBBBBBBBB----- ------BBBBBBBBBB----- --------------------- --------------------- --------------------- --------------------- --------------------- 
