model
size = 11 26 9, scale = 0.05, origin = -y
material 
  colors = A:#100404 B:#FFE11D
voxels
----------- ----------- --------A-- --------A-- --------A-- --------A-- --------A-- --------A-- --------A-- --------A-- --------A-- --------A-- --------A-- --------A-- --------A-- --------A-- --------A-- --------A-- --------A-- --------A-- --------A-- --------A-- --------A-- --------A-- ----------- --BBBBB---- 
----------- --------A-- --------A-- --------AA- --------AA- --------AA- --------AA- --------AA- --------AA- --------AA- --------AA- --------AA- --------AA- --------AA- --------AA- --------AA- --------AA- --------AA- --------AA- --------AA- --------AA- --------AA- --------AA- --------A-- --------A-- -BB---BB--- 
--------A-- --------A-- --------A-- ---------A- ---------A- ---------AA ---------AA ---------AA ---------AA ---------AA ---------AA ---------AA ---------AA ---------AA ---------AA ---------AA ---------AA ---------AA ---------AA ---------A- ---------A- --------AA- --------AA- --------A-- --------A-- BB-----BB-- 
--------A-- --------A-- --------A-- ---------A- ---------A- ---------AA ---------AA ---------AA ---------AA ---------AA ---------AA ---------AA ---------AA ---------AA ---------AA ---------AA ---------AA ---------AA ---------AA ---------A- ---------A- --------AA- --------AA- --------A-- --------A-- B-------B-- 
--------A-- --------A-- --------A-- ---------A- ---------A- ---------AA ---------AA ---------AA ---------AA ---------AA ---------AA ---------AA ---------AA ---------AA ---------AA ---------AA ---------AA ---------AA ---------AA ---------A- ---------A- --------AA- --------AA- --------A-- --------A-- B-------B-- 
--------A-- --------A-- --------A-- ---------A- ---------A- ---------AA ---------AA ---------AA ---------AA ---------AA ---------AA ---------AA ---------AA ---------AA ---------AA ---------AA ---------AA ---------AA ---------AA ---------A- ---------A- --------AA- --------AA- --------A-- --------A-- B-------B-- 
--------A-- --------A-- --------A-- ---------A- ---------A- ---------AA ---------AA ---------AA ---------AA ---------AA ---------AA ---------AA ---------AA ---------AA ---------AA ---------AA ---------AA ---------AA ---------AA ---------A- ---------A- --------AA- --------AA- --------A-- --------A-- BB-----BB-- 
----------- --------A-- --------A-- --------AA- --------AA- --------AA- --------AA- --------AA- --------AA- --------AA- --------AA- --------AA- --------AA- --------AA- --------AA- --------AA- --------AA- --------AA- --------AA- --------AA- --------AA- --------AA- --------AA- --------A-- --------A-- -BB---BB--- 
----------- ----------- --------A-- --------A-- --------A-- --------A-- --------A-- --------A-- --------A-- --------A-- --------A-- --------A-- --------A-- --------A-- --------A-- --------A-- --------A-- --------A-- --------A-- --------A-- --------A-- --------A-- --------A-- --------A-- ----------- --BBBBB---- 
