model
size = 32 10 32, scale = 0.05, origin = -y
material 
  colors = A:#001 B:#CF3 C:#FF3
voxels
6-18AB300-10AB12A296-25AC292-28A291-10AC9AB8A291-2AB27A289-7AB24A2(288-32A)288-31AB8-5AB11A263-AB26AB3A8-17A16-15A232-25AC6A8-17A16-15A18-10AB2A201-32A8-17A16-15A18-13A20-B10A170-4AB27A8-17A16-15A18-13A20-11A22-3AB5A139-10AB21A8-17A16-15A18-13A20-11A22-9A24-7A108-32A8-17A16-15A18-13A20-11A22-9A24-7A26-5A77-16AB15A8-17A16-15A18-13A20-11A22-9A24-7A26-B4A28-2AB30-A15-29AB2A8-17A16-15A18-12AB20-11A22-9A24-6AB26-5A77-32A8-17A16-15A18-B12A20-11A22-9A24-7A108-AC30A8-17A16-15A18-13A20-11A22-9A139-32A8-17A16-15A18-13A20-4AB6A170-32A8-17A16-15A18-11ABA201-32A8-17A16-15A232-4AB22AB4A8-17A263-22AB9A288-12AC18A290-30A291-2AB13AB12A291-5AB22A293-9AB16A295-13AB4AB5A298-20A294-
