model
size = 31 29 20, scale = 0.05, origin = -y
material 
  colors = A:#30C B:#66F C:#FF9 D:#0F6 E:#001 F:#FFF G:#39F H:#EEE I:#30F J:#F0C K:#9CF L:#FCC M:#3FF
voxels
-----BBBAA------AAAAA---------- -----A-B-A------A-A-A---------- ------------------------------- ------------------------------- ------------------------------- ------------------------------- ------------------------------- ------------------------------- ------------------------------- ------------------------------- ------------------------------- ------------------------------- ------------------------------- ------------------------------- ------------------------------- ------------------------------- ------------------------------- ------------------------------- ------------------------------- ------------------------------- ------------------------------- ------------------------------- ------------------------------- ------------------------------- ------------------------------- ------------------------------- ------------------------------- ------------------------------- ------------------------------- 
-----AAAAA------AAAAA---------- -----AAAAA------AAAAA---------- ------------------------------- ------------------------------- ------------------------------- ------------------------------- ------------------------------- ------------------------------- ------------------------------- ------------------------------- ------------------------------- ------------------------------- ------------------------------- ------------------------------- ------------------------------- ------------------------------- ------------------------------- ------------------------------- ------------------------------- ------------------------------- ------------------------------- ------------------------------- ------------------------------- ------------------------------- ------------------------------- ------------------------------- ------------------------------- ------------------------------- ------------------------------- 
-----AAAA--------AAAA---------- -----AAAA--------CCCA---------- -----AAAA--------AAAA---------- -----AAAA--------AAAA---------- ------AAA--------AAA----------- ------AAA--------AAA----------- ------AAA--------AAA----------- ------------------------------- ------------------------------- ------------------------------- ------------------------------- ------------------------------- ------------------------------- ------------------------------- ------------------------------- ------------------------------- ------------------------------- ------------------------------- ------------------------------- ------------------------------- ------------------------------- ------------------------------- ------------------------------- ------------------------------- ------------------------------- ------------------------------- ------------------------------- ------------------------------- ------------------------------- 
-----AAAADDDDDDDDAAAA---------- -----AAAADDDDDDDDCCCA---------- -----AAAADDDDDDDDCCCA---------- -----AAAADDDDDDDDCCCA---------- -----AAAADDDDDDDDCCCA---------- -----AAAADDDDDDDDCCCA---------- ------AAADDDDDDDDAAA----------- ---------DDDDDDDD-------------- ----------DDDDDD--------------- ----------DDDDDD--------------- -----------DDDD---------------- ------------------------------- ------------------------------- ------------------------------- ----EE--------------EE--------- ------EE----------EE----------- ------------------------------- -----EE------------EE---------- --EEE---E---EE---E---EE-------- -------E---EEEE---E------------ ----EEE-FFF----FFF-EEE--------- -------FIIIF--FIIIF------------ -------FEEIF--FIEEF------------ -------FBEFF--FFEBF------------ --------FFF----FFF------------- ------------------------------- ------------------------------- ------------------------------- ------------------------------- 
-----AAAAAAAAAAAAAAAA---------- -----BAAAAAAAAACCCCCA---------- -----BAAAAAAAAACCCCCA---------- -----BAAAAAAAAACCCCCB---------- -----AAAAAAAAAACCCCCB---------- -----AAAAAAAAAACCCCCA---------- -----AAAAAAAAAACCCCCA---------- ------AAACCCCCCCCAAA----------- ------AAAACCCCCCAAAA----------- ------BBAACCCCCCAAAA----------- ------BBAAACCCCAAAAA----------- ------BBAAAAAAAAAAAA----------- -------AAAAAAAAAAAA------------ -------AAAAAAAAABBB------------ ------AAAAAAEEAABBBA----------- ------ACAAAAAAAABBBA----------- ----AAAAAAAEEEEAAAAAAA--------- -----ALGAAEAEEAEAAGLA---------- -----AGGCAAAEEAABBGGA---------- ------ACAAAEEBBBBBBB----------- ------AAHHHAABBHHBBB----------- ------AHJJJHABBJJBBB----------- ------AHEEJHABBJEBBB----------- -------CMEHHABHHEAB------------ -------AAHHAABBBBBB------------ ---------AAAAABBB-------------- ------------------------------- ------------------------------- ------------------------------- 
----BAAAAAAAAAAAAAAAAA--------- ----BAAAAAAAAAAAAAAAAA--------- ----BAAAAAAAAAAAAAAAAA--------- ----BAAAAAAAAAAAAAAAAB--------- ----BAAAAAAAAAAAAAAAAB--------- ----AAAAAAAAAAAAAAAAAA--------- -----AAAAAAAAAAAAAACA---------- -----AAAAAAAAAAAAAACA---------- -----AAAAAAAAAAAAAACA---------- -----AAAAAAAAAAAAAACA---------- -----AAAAAAAAAAAAAACA---------- -----AAAAAAAAAAAAAACA---------- ------AAAAAAAAAAAAAA----------- ------AAAAAAAAAAAAAA----------- ------AAAAAAAAAAAAAA----------- ------AAAAAAAAAAAAAA----------- ----AAAAAAAAAAAAAAACAA--------- -----AAAAAAAAAAAAAACA---------- -----AAAAAAAAAAAACCCA---------- ------AAAAAAAAAAACCA----------- ------AAAAAAAAAAACCB----------- ------AAAAAAAAAAACCB----------- ------AAAAAAAAAAACBB----------- -------AAAAAAAAAAAB------------ -------GAAAAAABBBBB------------ --------AAAAAABBBB------------- --------A--------B------------- ------------------------------- ------------------------------- 
----BAAAAAAAAAAAAAAAAA--------- ----BAAAAAAAAAAAAAAAAA--------- ----BAAAAAAAAAAAAAAAAA--------- ----BAAAAAAAAAAAAAAAAA--------- ----BAAAAAAAAAAAAAAAAA--------- ----AAAAAAAAAAAAAAAAAA--------- ----AAAAAAAAAAAAAAAAAA--------- ----AAAAAAAAAAAAAAAAAA--------- ----AAAAAAAAAAAAAAAAAA--------- -----AAAAAAAAAAAAAACA---------- -----AAAAAAAAAAAAAACA---------- -----AAAAAAAAAAAAAACA---------- -----AAAAAAAAAAAAAAKA---------- ------AAAAAAAAAAAAAA----------- ------AAAAAAAAAAAAAA----------- ------AAAAAAAAAAAAAA----------- ------AAAAAAAAAAAAAA----------- ------AAAAAAAAAAAAAA----------- ------AAAAAAAAAAACCA----------- ------AAAAAAAAAAACCA----------- ------AAAAAAAAAAACCB----------- ------AAAAAAAAAAACCB----------- ------AAAAAAAAAAACBB----------- ------AAAAAAAAAAACBB----------- -----AGGAAAAAAABBBBBB---------- -----AGGAAAAAAABBCGGB---------- ------GGA---A----CGG----------- -----A-AA--------BB-B---------- -----AA------------BB---------- 
----BAAAAAAAAAAAAAAAAA--------- ----BAAAAAAAAAAAAAAAAA--------- ----BAAAAAAAAAAAAAAAAA--------- ----BAAAAAAAAAAAAAAAAA--------- ----BAAAAAAAAAAAAAAAAA--------- ----AAAAAAAAAAAAAAAAAA--------- ----AAAAAAAAAAAAAAAAAA--------- ----AAAAAAAAAAAAAAAAAA--------- ----AAAAAAAAAAAAAAAAAA--------- -----AAAAAAAAAAAAAACA---------- -----AAAAAAAAAAAAAACA---------- -----AAAAAAAAAAAAAACA---------- -----AAAAAAAAAAAAAAKA---------- -----AAAAAAAAAAAAAAKA---------- ------AAAAAAAAAAAAAA----------- ------AAAAAAAAAAAAAA----------- ------AAAAAAAAAAAAAA----------- ------AAAAAAAAAAAAAA----------- ------AAAAAAAAAAACCA----------- ------AAAAAAAAAAACCA----------- ------AAAAAAAAAAACCA----------- ------AAAAAAAAAAACCA----------- ------AAAAAAAAAAACBB----------- ------AAAAAAAAAAACBB----------- -----AAAAAAAAAAABBBBB---------- -----AAAAAAAAAABBBBBB---------- -----AAAA--AAAA--BBBB---------- -----AAAA---AA---BBBB---------- -----AA------------BB---------- 
----AAAAAAAAAAAAAAAAAA--------- ----BAAAAAAAAAAAAAAAAA--------- ----BAAAAAAAAAAAAAAAAA--------- ----BAAAAAAAAAAAAAAAAA--------- ----AAAAAAAAAAAAAAAAAA--------- ----AAAAAAAAAAAAAAAAAA--------- ----AAAAAAAAAAAAAAAAAA--------- ----AAAAAAAAAAAAAAAAAA--------- ----AAAAAAAAAAAAAAAAAA--------- -----AAAAAAAAAAAAAACA---------- -----AAAAAAAAAAAAAACA---------- -----AAAAAAAAAAAAAACA---------- -----AAAAAAAAAAAAAAKA---------- -----AAAAAAAAAAAAAAKA---------- ------BAAAAAAAAAAAAA----------- ------BAAAAAAAAAAAAA----------- ------BAAAAAAAAAAAAA----------- ------AAAAAAAAAAAAAA----------- ------AAAAAAAAAAACCA----------- ------AAAAAAAAAAACCA----------- ------AAAAAAAAAAACCA----------- ------AAAAAAAAAAACCA----------- ------AAAAAAAAAAACBB----------- -------AAAAAAAAAACB------------ -------AAAAAAAAAABB------------ ---------AAAAAAAA-------------- -----------AAAA---------------- ------------AAA---------------- -------------A----------------- 
AAAAAAAAAAAAAAAAAAAAAAAAAA----- AAAAAAAAAAAAAAAAAAAACCAAAA----- --AAAAAAAAAAAAAAAAAACBBB------- --AAAAAAAAAAAAAAAAAACBBB------- --AAAAAAAAAAAAAAAAAACBBB------- --AAAAAAAAAAAAAAAAAACCAA------- ---AAAAAAAAAAAAAAAAACCA-------- ----AAAAAAAAAAAAAAAAAA--------- ----AAAAAAAAAAAAAAAAAA--------- -----AAAAAAAAAAAAAAAA---------- -----AAAAAAAAAAAAAAAA---------- -----AAAAAAAAAAAAAAAA---------- -----AAAAAAAAAAAAAAAA---------- -----ABAAAAAAAAAAAAAA---------- ------BAAAAAAAAAAAAA----------- ------BAAAAAAAAAAAAB----------- ------BAAAAAAAAAAAAB----------- ------BAAAAAAAAAAAAB----------- ------AAAAAAAAAAAAAA----------- ------AAAAAAAAAAAAAA----------- ------AAAAAAAAAAAAAA----------- ------AAAAAAAAAAAAAA----------- ------AAAAAAAAAAAAAA----------- -------AAAAAAAAAAAA------------ -------AAAAAAAAAAAA------------ ---------AAAAAAAA-------------- ------------------------------- ------------------------------- ------------------------------- 
AAAAAAAAAAAAAAAAAAAAAAAAAA----- AAAAAAAAAAAAAAAAAAAACCACAA----- --AAAAAAAAAAAAAAAAAACCAB------- --AAAAAAAAAAAAAAAAAACCAB------- --AAAAAAAAAAAAAAAAAACCAB------- --AAAAAAAAAAAAAAAAAACCAA------- --AAAAAAAAAAAAAAAAAACCAA------- ----AAAAAAAAAAAAAAAAAA--------- ----AAAAAAAAAAAAAAAAAA--------- -----AAAAAAAAAAAAAAAA---------- -----AAAAAAAAAAAAAAAA---------- -----AAAAAAAAAAAAAAAA---------- -----AAAAAAAAAAAAAAAA---------- -----ABAAAAAAAAAAAAAA---------- ------BAAAAAAAAAAAAA----------- ------BAAAAAAAAAAAAB----------- ------BAAAAAAAAAAAAB----------- ------BAAAAAAAAAAAAB----------- ------AAAAAAAAAAAAAA----------- ------AAAAAAAAAAAAAA----------- ------AAAAAAAAAAAAAA----------- ------AAAAAAAAAAAAAA----------- ------AAAAAAAAAAAAAA----------- -------BAAAAAAAAAAA------------ -------BAAAAAAAAAAA------------ ---------AAAAAAAA-------------- ------------------------------- ------------------------------- ------------------------------- 
AAAAAAAAAAAAAAAAAAAAAAAAAA----- AAAAAAAAAAAAAAAAAAAACCACAA----- --AAAAAAAAAAAAAAAAAACCAB------- --AAAAAAAAAAAAAAAAAACCAB------- --AAAAAAAAAAAAAAAAAACCAA------- --AAAAAAAAAAAAAAAAAACCAA------- --AAAAAAAAAAAAAAAAAACCAA------- ----AAAAAAAAAAAAAAAAAA--------- ----AAAAAAAAAAAAAAAAAA--------- -----AAAAAAAAAAAAAAAA---------- -----AAAAAAAAAAAAAAAA---------- -----AAAAAAAAAAAAAAAA---------- -----AAAAAAAAAAAAAAAA---------- -----ABAAAAAAAAAAAAAA---------- ------BAAAAAAAAAAAAA----------- ------BAAAAAAAAAAAAB----------- ------BAAAAAAAAAAAAB----------- ------BAAAAAAAAAAAAB----------- ------AAAAAAAAAAAAAA----------- ------AAAAAAAAAAAAAA----------- ------AAAAAAAAAAAAAA----------- ------AAAAAAAAAAAAAA----------- ------AAAAAAAAAAAAAA----------- -------BAAAAAAAAAAA------------ -------BAAAAAAAAAAA------------ ---------AAAAAAAA-------------- ------------------------------- ------------------------------- ------------------------------- 
AAAAAAAAAAAAAAAAAAAAAAAAAA----- AAAAAAAAAAAAAAAAAAAAAAAAAA----- --AAAAAAAAAAAAAAAAAAAAAA------- --AAAAAAAAAAAAAAAAAAAAAA------- --AAABAAAAAAAAAAAAAAAAAA------- --AAABAAAAAAAAAAAAAAAAAA------- ---AABAAAAAAAAAAAAAABAA-------- -----AAAAAAAAAAAAAAAB---------- -----AAAAAAAAAAAAAAAB---------- -----AAAAAAAAAAAAAAAA---------- -----AAAAAAAAAAAAAAAA---------- -----AAAAAAAAAAAAAAAA---------- -----AAAAAAAAAAAAAAAA---------- ------AAAAAAAAAAAAAA----------- ------BAAAAAAAAAAAAA----------- ------BAAAAAAAAAAAAA----------- ------BAAAAAAAAAAAAA----------- -------AAAAAAAAABAA------------ -------AAAAAAAAAAAA------------ -------AAAAAAAAAAAA------------ -------AAAAAAAAAAAA------------ -------AAAAAAAAAAAA------------ -------AAAAAAAAAAAA------------ --------AAAAAAAAAA------------- ---------AAAAAAAA-------------- ------------------------------- ------------------------------- ------------------------------- ------------------------------- 
------AAAAAAAAAAAAAA----------- ------AAAAAAAAAAAAAA----------- ------AAAAAAAAAAAAAA----------- ------BBBAAAAAAAAAAA----------- ------BBBBAAAAAAAAAA----------- ------BBBBAAAAAAABBB----------- ------BBBBAAAAAABBBB----------- ------BBBAAAAAAABBBB----------- ------AAAAAAAAAABBBB----------- ------AAAAAAAAAAABBB----------- ------AAAAAAAAAAAAAA----------- -------AAAAAAAAAAAA------------ -------AAAAAAAAAAAA------------ --------AAAAAAAAAA------------- ------------------------------- ------------------------------- ------------------------------- ----------AAAABB--------------- ---------AAAABBBB-------------- ---------AAAAABBB-------------- ---------AAAAAABA-------------- ---------AAAAAAAA-------------- ----------AAAAAA--------------- ------------------------------- ------------------------------- ------------------------------- ------------------------------- ------------------------------- ------------------------------- 
------------------------------- ------------------------------- ----------AAAA----------------- ----------AAAA----------------- ----------AAAA----------------- ----------AAAA----------------- ------------------------------- ------------------------------- ------------------------------- ------------------------------- ------------------------------- ------------------------------- ------------------------------- ------------------------------- ------------------------------- ------------------------------- ------------------------------- ------------------------------- ------------------------------- ------------------------------- ------------------------------- ------------------------------- ------------------------------- ------------------------------- ------------------------------- ------------------------------- ------------------------------- ------------------------------- ------------------------------- 
-------------AAAAAAA----------- -----------AAAAAAAAAAA--------- ----------AAAAAAAAAAAAAA------- ----------AAAA----AAAAAAA------ ----------AAAA-------AAABB----- ----------AAAA---------BBBB---- ------------------------BBB---- -------------------------BAA--- --------------------------AAA-- ---------------------------AA-- ---------------------------AAA- ----------------------------AA- ----------------------------AB- ----------------------------BB- ----------------------------BB- ----------------------------BB- ---------------------------AAA- --------------------------AAA-- -------------------------AAA--- ------------------------BBA---- -----------------------BBB----- ----------------------ABB------ ----------------------AA------- ------------------------------- ------------------------------- ------------------------------- ------------------------------- ------------------------------- ------------------------------- 
-------------AAAAAAA----------- -----------AAAAAAAACAAAA------- ----------AAAAAAAAAAAAAAA------ ----------AAAAAAAAAAAAAAAA----- ----------AAAA----AAAAAAAAA---- ----------AAAA-------AAAAAA---- -----------------------BAAAA--- ------------------------BAAAA-- -------------------------AAAAA- --------------------------AAAA- ---------------------------AAA- ---------------------------AAAA ---------------------------AAAA ---------------------------BAAB ---------------------------AAAB ---------------------------AAA- --------------------------AAAA- -------------------------AAAAA- ------------------------AAAAA-- -----------------------BAAAA--- ----------------------AAAAA---- ----------------------AAAB----- ---------------------AAAB------ ---------------------AA-------- ------------------------------- ------------------------------- ------------------------------- ------------------------------- ------------------------------- 
-------------AAAAAAA----------- -----------AAAAAAAAAAAAA------- ----------AAAAAAAAAAAAAAA------ ----------AAAAAAAAAAAAAAAA----- ----------AAAA----AAAAAAAAA---- ----------AAAA-------AAAAAAA--- -----------------------AAAAA--- ------------------------AAAAA-- -------------------------AAAAA- --------------------------AAAA- --------------------------AAAAA ---------------------------AAAA ---------------------------AAAA ---------------------------AAAA ---------------------------AAAA --------------------------AAAAA --------------------------AAAA- -------------------------AAAAA- ------------------------AAAAA-- -----------------------AAAAAA-- ----------------------AAAAAA--- ---------------------AAAAAA---- ---------------------AAAAA----- ---------------------AAA------- ------------------------------- ------------------------------- ------------------------------- ------------------------------- ------------------------------- 
-------------AAAAAA------------ -----------AAAAAAAAAAAA-------- ----------AAAAAAAAAAAAAAA------ ----------AAAAAAAAAAAAAAAA----- ----------AAAA-----AAAAAAAA---- ----------AAAA-------AAAAAA---- -----------------------AAAAA--- ------------------------AAAAA-- -------------------------AAAA-- --------------------------AAAA- --------------------------AAAA- ---------------------------AAAA ---------------------------AAAA ---------------------------AAAA ---------------------------AAAA --------------------------AAAA- --------------------------AAAA- -------------------------AAAA-- ------------------------AAAAA-- -----------------------AAAAA--- ----------------------AAAAA---- ---------------------AAAAA----- ---------------------AAAA------ ---------------------AA-------- ------------------------------- ------------------------------- ------------------------------- ------------------------------- ------------------------------- 
------------------------------- ------------AAAAAAA------------ -----------AAAAAAAAAAAA-------- ----------AAAA----AAAAAAA------ ----------AAA--------AAABB----- ----------AAA----------ABBB---- ------------------------BBB---- -------------------------AAA--- --------------------------AAA-- --------------------------AAA-- ---------------------------AAA- ----------------------------AA- ----------------------------AA- ----------------------------AA- ----------------------------AA- ---------------------------AAA- ---------------------------AA-- --------------------------AAA-- -------------------------AAA--- ------------------------AAAA--- -----------------------AAAA---- ----------------------AAAA----- ----------------------AA------- ------------------------------- ------------------------------- ------------------------------- ------------------------------- ------------------------------- ------------------------------- 
