model
size = 15 32 15, scale = 0.05, origin = -y
material 
  colors = A:#111 B:#F70 C:#FFF D:#DDD E:#06F F:#001 G:#F33
voxels
5-5C145-F-F12-4F11-3(F3-F10-)4F11-2(F3-F10-)4F11-F-F87-5C98-9C8-5D8(10-5B)10-FBF2B9-5FB3(10-F3BF)10-4FB2(10-F3BF)9-5FB10-FBF2B5(10-5B)8-9C8-5D82-11C5-9D6-2B5E2B8(6-9B)6-BF7B6(6-9B)6-BF7B5(6-9B)6-2B5E2B5-11C5-9D8-5B66-13C3-11D5(4-B9EB)4(4-8B2EB)11(4-11B)3(4-B9EB)3-13C3-11D6-B5AB9-5B51-13C3-11D5(4-B9AB)4(4-8B2AB)11(4-11B)3(4-B9AB)3-13C3-11D5-B7AB7-7B49-15C-13D5(2-B11EB)4(2-9B3EB)11(2-13B)3(2-B11EB)-15C-13D3-B9AB5-3B3A3B9-3D36-15C-13D23(2-B11AB)-15C-13D3-B9AB5-2B5A2B8-5D11-3C12-CBC2(6-15C-13D23(2-B11AB)-15C-13D3-B9AB5-2B5A2B8-5D11-3C12-3C)6-15C-13D23(2-B11AB)-15C-13D3-B9AB5-3B3A3B9-3D37-13C3-11D23(4-B9AB)3-13C3-11D5-B7AB7-7B50-13C3-11D23(4-B9AB)3-13C3-11D6-B5AB9-5B52-11C5-9D23(6-2B5A2B)5-11C5-9D8-5B68-9C8-5D2(10-5B)2(10-2(GB)G)10-5G10-5B10-G4B10-5B10-2G2BG10-2(GB)G10-GB3G10-5B10-5G10-2(GB)G10-5G8(10-5B)8-9C8-5D85-5C370-5C95-
