model
size = 15 29 21, scale = 0.05, origin = -y
material 
  colors = A:#BBB B:#0F0
voxels
--------------- --------------- --------------- -A------------- -A------------- -A------------- -A------------- -A------------- -A------------- -A------------- -A------------- -A------------- -A------------- -A------------- -A------------- -A------------- -A------------- -A------------- -AAAAAAAAA----- -A------------- -A------------- -A------------- -A------------- --------------- --------------- --------------- --------------- --------------- --------------- 
--------------- --------------- -A------------- -A------------- -A------------- -A------------- -A------------- -A------------- -A------------- BA------------- BA------------- -A------------- -A------------- -A------------- -A------------- -A------------- -A------------- -A------------- -A-------AAAAAA -A------------- -A------------- -A------------- -A------------- -A------------- --------------- --------------- --------------- --------------- --------------- 
--------------- --------------- -A------------- -A------------- -A------------- -A------------- -A------------- -A------------- BA------------- -A------------- -A------------- -A------------- -A------------- -A------------- -A------------- -A------------- -A------------- -A------------- -A------------A -A------------- -A------------- -A------------- -A------------- -A------------- -A------------- --------------- --------------- --------------- --------------- 
--------------- -A------------- -A------------- -A------------- -A------------- -A------------- -A------------- BA------------- -A------------- -A------------- -A------------- -A------------- -A------------- -A------------- -A------------- -A------------- -A------------- -A------------- -A------------A -A------------- -A------------- -A------------- -A------------- -A------------- -A------------- -A------------- --------------- --------------- --------------- 
--------------- -A------------- -A------------- -A------------- -A------------- BA------------- BA------------- -A------------- -A------------- -A------------- -A------------- -A------------- -A------------- -A------------- -A------------- -A------------- BA------------- -A------------- -A------------A -A------------- -A------------- BA------------- -A------------- -A------------- -A------------- -A------------- -A------------- --------------- --------------- 
-A------------- -A------------- -A------------- -A------------- BA------------- -A------------- -A------------- -A------------- -A------------- -A------------- -A------------- -A------------- -A------------- -A------------- -A------------- -A------------- -A------------- BA------------- -A------------A -A------------- BA------------- -A------------- -A------------- -A------------- -A------------- -A------------- -A------------- -A------------- --------------- 
-A------------- -A------------- BA------------- -A------------- BA------------- -A------------- BA------------- -A------------- -A------------- -A------------- -A------------- -A------------- -A------------- -A------------- -A------------- -A------------- -A------------- -A------------- BA------------A BA------------- -A------------- -A------------- -A------------- -A------------- -A------------- -A------------- -A------------- -A------------- -A------------- 
-A------------- -A------------- -A------------- BA------------- BA------------- BA------------- -A------------- -A------------- -A------------- -A------------- -A------------- -A------------- -A------------- -A------------- -A------------- -A------------- -A------------- -A------------- BA------------A BA------------- -A------------- -A------------- -A------------- -A------------- -A------------- -A------------- -A------------- -A------------- -A------------- 
-A------------- -A------------- BA------------- -A------------- BA------------- -A------------- BA------------- -A------------- -A------------- -A------------- -A------------- -A------------- -A------------- -A------------- -A------------- -A------------- -A------------- BA------------- -A------------A -A------------- BA------------- -A------------- -A------------- -A------------- -A------------- -A------------- -A------------- -A------------- -A------------- 
-A------------- -A------------- -A------------- -A------------- BA------------- -A------------- -A------------- -A------------- -A------------- -A------------- -A------------- BA------------- -A------------- -A------------- -A------------- -A------------- BA------------- -A------------- -A------------A -A------------- -A------------- BA------------- -A------------- -A------------- -A------------- -A------------- -A------------- -A------------- -A------------- 
-A------------- -A------------- -A------------- -A------------- BA------------- -A------------- -A------------- -A------------- -A------------- -A------------- -A------------- -A------------- -A------------- -A------------- -A------------- -A------------- -A------------- -A------------- -A------------A -A------------- -A------------- -A------------- -A------------- -A------------- -A------------- -A------------- -A------------- -A------------- -A------------- 
-A------------- -A------------- BA------------- -A------------- BA------------- -A------------- BA------------- -A------------- -A------------- -A------------- -A------------- -A------------- -A------------- -A------------- -A------------- -A------------- -A------------- -A------------- -A------------A -A------------- -A------------- -A------------- -A------------- -A------------- -A------------- -A------------- -A------------- -A------------- -A------------- 
-A------------- -A------------- -A------------- BA------------- BA------------- BA------------- -A------------- -A------------- -A------------- -A------------- -A------------- BA------------- -A------------- -A------------- -A------------- -A------------- -A------------- -A------------- -A------------A -A------------- -A------------- -A------------- -A------------- -A------------- -A------------- -A------------- -A------------- -A------------- -A------------- 
-A------------- -A------------- BA------------- -A------------- BA------------- -A------------- BA------------- -A------------- -A------------- -A------------- -A------------- -A------------- -A------------- -A------------- -A------------- -A------------- BA------------- -A------------- -A------------A -A------------- -A------------- BA------------- -A------------- -A------------- -A------------- -A------------- -A------------- -A------------- -A------------- 
-A------------- -A------------- -A------------- -A------------- BA------------- -A------------- -A------------- -A------------- -A------------- -A------------- -A------------- -A------------- -A------------- -A------------- -A------------- -A------------- -A------------- BA------------- -A------------A -A------------- BA------------- -A------------- -A------------- -A------------- -A------------- -A------------- -A------------- -A------------- --------------- 
--------------- -A------------- -A------------- -A------------- BA------------- -A------------- -A------------- -A------------- -A------------- -A------------- -A------------- -A------------- -A------------- -A------------- -A------------- -A------------- -A------------- -A------------- BA------------A BA------------- -A------------- -A------------- -A------------- -A------------- -A------------- -A------------- -A------------- --------------- --------------- 
--------------- -A------------- -A------------- -A------------- -A------------- BA------------- BA------------- -A------------- -A------------- -A------------- -A------------- -A------------- -A------------- -A------------- -A------------- -A------------- -A------------- -A------------- BA------------A BA------------- -A------------- -A------------- -A------------- -A------------- -A------------- -A------------- --------------- --------------- --------------- 
--------------- --------------- -A------------- -A------------- -A------------- -A------------- -A------------- BA------------- -A------------- -A------------- -A------------- -A------------- -A------------- -A------------- -A------------- -A------------- -A------------- BA------------- -A------------A -A------------- BA------------- -A------------- -A------------- -A------------- -A------------- --------------- --------------- --------------- --------------- 
--------------- --------------- -A------------- -A------------- -A------------- -A------------- -A------------- -A------------- BA------------- -A------------- -A------------- -A------------- -A------------- -A------------- -A------------- -A------------- BA------------- -A------------- -A-------AAAAAA -A------------- -A------------- BA------------- -A------------- -A------------- --------------- --------------- --------------- --------------- --------------- 
--------------- --------------- --------------- -A------------- -A------------- -A------------- -A------------- -A------------- -A------------- BA------------- BA------------- -A------------- -A------------- -A------------- -A------------- -A------------- -A------------- -A------------- -AAAAAAAAA----- -A------------- -A------------- -A------------- -A------------- --------------- --------------- --------------- --------------- --------------- --------------- 
--------------- --------------- --------------- --------------- --------------- -A------------- -A------------- -A------------- -A------------- -A------------- -A------------- -A------------- -A------------- -A------------- -A------------- -A------------- -A------------- -A------------- -A------------- -A------------- -A------------- -A------------- --------------- --------------- --------------- --------------- --------------- --------------- --------------- 
