model
size = 32 4 32, scale = 0.05, origin = -y
material 
  colors = A:#111 B:#DDD C:#555 D:#500
voxels
35-6A14-6A6-6D14-6D6-6A14-6A16-A4CA15-8A3-AC2BCA3-8A4-8D3-AC2BCA3-8D4-8A3-A4CA3-8A15-6A14-3A4B4A-6A-4A4B3A2-11D-6A-11D2-3A4B4A-6C-4A4B3A14-6A13-3A6B3A-6A-3A6B3A3D9A-6A-9A3D3A6B3A-6C-3A6B3A12-8A12-2A8B12A8B2A2D28A2D2A8B3A6C3A8B2A2(12-8A12-2(2A3B)12A2(3B2A)2D28A2D2(2A3B)3A6C3A2(3B2A))12-8A12-2A8B12A8B2A2D28A2D2A8B3A6C3A8B2A12-8A12-3A6B14A6B3A2D28A2D3A6B14A6B3A12-8A13-3A4B16A4B3A2-D28AD2-3A4B16A4B3A13-8A14-28A4-8D12A8D4-28A14-8A15-6A-12A-6A6-6D-12A-6D6-6A-12A-6A15-8A22-6(12A20-)12A22-A6C4(A22-3A6C3A20-3A6C3A21-2A6C2A23-AC4DC)A22-3A6C3A20-3A6C3A21-2A6D2A23-AC4DCA22-3A6C3A20-3A6C3A21-2A6C2A14-6A3-AC4DCA3-6A6-6D-3A6C3A-6D6-6A-3A6C3A-6A14-2A6C2A13-8A2-AC4DCA2-8A4-8D3A6C3A8D4-11A6C11A13-2A6D2A12-3A4B2A2-AC4DCA2-2A4B3A2-8D4A6C4A8D2-3A4B5A6C5A4B3A12-2A6C2A11-3A6B2A-AC4DCA-2A6B3A9D4A6C4A9D3A6B4A6C4A6B3A11-2A6C2A11-2A8BA-AC4DCA-A8B2A2D11A6C11A2D2A8B3A6C3A8B2A11-2A6D2(2A11-2(2A3B)A-AC4DCA-A2(3B2A)2D11A6C11A2D2(2A3B)3A6C3A2(3B2A)11-2A6C)2A11-2A8BA2-6C2-A8B2A2D9AD-6C-D9A2D2A8B2A-6C-2A8B2A13-6D13-3A6B2A10-2A6B3A2D9AD8-D9A2D3A6B3A8-3A6B3A33-3A4B3A10-3A4B3A2-D7A3D8-3D7AD2-3A4B4A8-4A4B3A35-8A12-8A4-8D12-8D4-8A12-8A37-6A14-6A6-6D14-6D6-6A14-6A35-
