model
size = 30, scale = 0.05, origin = -y
material 
  colors = A:#111 B:#FFF
voxels
BBBBBBBBBBBBBBBBBBBBBBBBBBBBBB BBBBBBBBBBBBBBBBBBBBBBBBBBBBBB BB--BB--BB--BB--BB--BB--BB--BB BB--BB--BB--BB--BB--BB--BB--BB BB--BB--BB--BB--BB--BB--BB--BB BB--BB--BB--BB--BB--BB--BB--BB BB--BB--BB--BB--BB--BB--BB--BB BB--BB--BB--BB--BB--BB--BB--BB BB--BB--BB--BB--BB--BB--BB--BB BB--BB--BB--BB--BB--BB--BB--BB BB--BB--BB--BB--BB--BB--BB--BB BB--BB--BB--BB--BB--BB--BB--BB BB--BB--BB--BB--BB--BB--BB--BB BB--BB--BB--BB--BB--BB--BB--BB BB--BB--BB--BB--BB--BB--BB--BB BB--BB--BB--BB--BB--BB--BB--BB BB--BB--BB--BB--BB--BB--BB--BB BB--BB--BB--BB--BB--BB--BB--BB BB--BB--BB--BB--BB--BB--BB--BB BB--BB--BB--BB--BB--BB--BB--BB BB--BB--BB--BB--BB--BB--BB--BB BB--BB--BB--BB--BB--BB--BB--BB BB--BB--BB--BB--BB--BB--BB--BB BB--BB--BB--BB--BB--BB--BB--BB BB--BB--BB--BB--BB--BB--BB--BB BB--BB--BB--BB--BB--BB--BB--BB BB--BB--BB--BB--BB--BB--BB--BB BB--BB--BB--BB--BB--BB--BB--BB BBBBBBBBBBBBBBBBBBBBBBBBBBBBBB BBBBBBBBBBBBBBBBBBBBBBBBBBBBBB 
BBBBBBBBBBBBBBBBBBBBBBBBBBBBBB BBBBBBBBBBBBBBBBBBBBBBBBBBBBBB BB--BB--BB--BB--BB--BB--BB--BB BB--BB--BB--BB--BB--BB--BB--BB BB--BB--BB--BB--BB--BB--BB--BB BB--BB--BB--BB--BB--BB--BB--BB BB--BB--BB--BB--BB--BB--BB--BB BB--BB--BB--BB--BB--BB--BB--BB BB--BB--BB--BB--BB--BB--BB--BB BB--BB--BB--BB--BB--BB--BB--BB BB--BB--BB--BB--BB--BB--BB--BB BB--BB--BB--BB--BB--BB--BB--BB BB--BB--BB--BB--BB--BB--BB--BB BB--BB--BB--BB--BB--BB--BB--BB BB--BB--BB--BB--BB--BB--BB--BB BB--BB--BB--BB--BB--BB--BB--BB BB--BB--BB--BB--BB--BB--BB--BB BB--BB--BB--BB--BB--BB--BB--BB BB--BB--BB--BB--BB--BB--BB--BB BB--BB--BB--BB--BB--BB--BB--BB BB--BB--BB--BB--BB--BB--BB--BB BB--BB--BB--BB--BB--BB--BB--BB BB--BB--BB--BB--BB--BB--BB--BB BB--BB--BB--BB--BB--BB--BB--BB BB--BB--BB--BB--BB--BB--BB--BB BB--BB--BB--BB--BB--BB--BB--BB BB--BB--BB--BB--BB--BB--BB--BB BB--BB--BB--BB--BB--BB--BB--BB BBBBBBBBBBBBBBBBBBBBBBBBBBBBBB BBBBBBBBBBBBBBBBBBBBBBBBBBBBBB 
BBBBBBBBBBBBBBBBBBBBBBBBBBBBBB BBBBBBBBBBBBBBBBBBBBBBBBBBBBBB B----------------------------B B----------------------------B B----------------------------B B----------------------------B B----------------------------B B----------------------------B B----------------------------B B----------------------------B B----------------------------B B----------------------------B B----------------------------B B----------------------------B B----------------------------B B----------------------------B B----------------------------B B----------------------------B B----------------------------B B----------------------------B B----------------------------B B----------------------------B B----------------------------B B----------------------------B B----------------------------B B----------------------------B B----------------------------B B----------------------------B B----------------------------B BBBBBBBBBBBBBBBBBBBBBBBBBBBBBB 
BBBBBBBBBBBBBBBBBBBBBBBBBBBBBB BB-BBBBBBBBBBBBBBBBBBBBBBBBBBB B------------------------AA--B ---AAAAAAAAAAAAAAAAAAAAAAAA--- ---AAAAAAAAAAAAAAAAAAAAAAAA--- ---AAAAAAAAAAAAAAAAAAAAAAAA--- B--AAAAAAAAAAAAAAAAAAAAAAAA--B B--AAAAAAAAAAAAAAAAAAAAAAAA--B B--AAAAAAAAAAAAAAAAAAAAAAAA--B ---AAAAAAAAAAAAAAAAAAAAAAAA--- ---AAAAAAAAAAAAAAAAAAAAAAAA--- ---AAAAAAAAAAAAAAAAAAAAAAAA--- B--AAAAAAAAAAAAAAAAAAAAAAAA--B B--AAAAAAAAAAAAAAAAAAAAAAAA--B ---AAAAAAAAAAAAAAAAAAAAAAAA--- ---AAAAAAAAAAAAAAAAAAAAAAAA--- ---AAAAAAAAAAAAAAAAAAAAAAAA--- B--AAAAAAAAAAAAAAAAAAAAAAAA--B B--AAAAAAAAAAAAAAAAAAAAAAAA--B ---AAAAAAAAAAAAAAAAAAAAAAAA--- ---AAAAAAAAAAAAAAAAAAAAAAAA--- ---AAAAAAAAAAAAAAAAAAAAAAAA--- B--AAAAAAAAAAAAAAAAAAAAAAAA--B B--AAAAAAAAAAAAAAAAAAAAAAAA--B B--AAAAAAAAAAAAAAAAAAAAAAAA--B ---AAAAAAAAAAAAAAAAAAAAAAAA--- ---AAAAAAAAAAAAAAAAAAAAAAAA--- ------------------------------ B----------------------------B BBBBBBBB--BBBBBBBBBB--BBBBBBBB 
BBBBBBBBBBBBBBBBBBBBBBBBBBBBBB BB-BBBBBBBBBBBBBBBBBBBBBBBBBBB B------------------------AA--B ---AAAAAAAAAAAAAAAAAAAAAAAA--- ---AAAAAAAAAAAAAAAAAAAAAAAA--- ---AAAAAAAAAAAAAAAAAAAAAAAA--- B--AAAAAAAAAAAAAAAAAAAAAAAA--B B--AAAAAAAAAAAAAAAAAAAAAAAA--B B--AAAAAAAAAAAAAAAAAAAAAAAA--B ---AAAAAAAAAAAAAAAAAAAAAAAA--- ---AAAAAAAAAAAAAAAAAAAAAAAA--- ---AAAAAAAAAAAAAAAAAAAAAAAA--- B--AAAAAAAAAAAAAAAAAAAAAAAA--B B--AAAAAAAAAAAAAAAAAAAAAAAA--B ---AAAAAAAAAAAAAAAAAAAAAAAA--- ---AAAAAAAAAAAAAAAAAAAAAAAA--- ---AAAAAAAAAAAAAAAAAAAAAAAA--- B--AAAAAAAAAAAAAAAAAAAAAAAA--B B--AAAAAAAAAAAAAAAAAAAAAAAA--B ---AAAAAAAAAAAAAAAAAAAAAAAA--- ---AAAAAAAAAAAAAAAAAAAAAAAA--- ---AAAAAAAAAAAAAAAAAAAAAAAA--- B--AAAAAAAAAAAAAAAAAAAAAAAA--B B--AAAAAAAAAAAAAAAAAAAAAAAA--B B--AAAAAAAAAAAAAAAAAAAAAAAA--B ---AAAAAAAAAAAAAAAAAAAAAAAA--- ---AAAAAAAAAAAAAAAAAAAAAAAA--- ------------------------------ B----------------------------B BBBBBBBB--BBBBBBBBBB--BBBBBBBB 
BBBBBBBBBBBBBBBBBBBBBBBBBBBBBB BB-BBBBBBBBBBBBBBBBBBBBBBBBBBB B------------------------AA--B ---AAAAAAAAAAAAAAAAAAAAAAAA--- ---AAAAAAAAAAAAAAAAAAAAAAAA--- ---AAAAAAAAAAAAAAAAAAAAAAAA--- B--AAAAAAAAAAAAAAAAAAAAAAAA--B B--AAAAAAAAAAAAAAAAAAAAAAAA--B B--AAAAAAAAAAAAAAAAAAAAAAAA--B ---AAAAAAAAAAAAAAAAAAAAAAAA--- ---AAAAAAAAAAAAAAAAAAAAAAAA--- ---AAAAAAAAAAAAAAAAAAAAAAAA--- B--AAAAAAAAAAAAAAAAAAAAAAAA--B B--AAAAAAAAAAAAAAAAAAAAAAAA--B ---AAAAAAAAAAAAAAAAAAAAAAAA--- ---AAAAAAAAAAAAAAAAAAAAAAAA--- ---AAAAAAAAAAAAAAAAAAAAAAAA--- B--AAAAAAAAAAAAAAAAAAAAAAAA--B B--AAAAAAAAAAAAAAAAAAAAAAAA--B ---AAAAAAAAAAAAAAAAAAAAAAAA--- ---AAAAAAAAAAAAAAAAAAAAAAAA--- ---AAAAAAAAAAAAAAAAAAAAAAAA--- B--AAAAAAAAAAAAAAAAAAAAAAAA--B B--AAAAAAAAAAAAAAAAAAAAAAAA--B B--AAAAAAAAAAAAAAAAAAAAAAAA--B ---AAAAAAAAAAAAAAAAAAAAAAAA--- ---AAAAAAAAAAAAAAAAAAAAAAAA--- ------------------------------ B----------------------------B BBBBBBBB--BBBBBBBBBB--BBBBBBBB 
BBBBBBBBBBBBBBBBBBBBBBBBBBBBBB BB-BBBBBBBBBBBBBBBBBBBBBBBBBBB B------------------------AA--B B--AAAAAAAAAAAAAAAAAAAAAAAA--B B--AAAAAAAAAAAAAAAAAAAAAAAA--B B--AAAAAAAAAAAAAAAAAAAAAAAA--B B--AAAAAAAAAAAAAAAAAAAAAAAA--B B--AAAAAAAAAAAAAAAAAAAAAAAA--B B--AAAAAAAAAAAAAAAAAAAAAAAA--B B--AAAAAAAAAAAAAAAAAAAAAAAA--B B--AAAAAAAAAAAAAAAAAAAAAAAA--B B--AAAAAAAAAAAAAAAAAAAAAAAA--B B--AAAAAAAAAAAAAAAAAAAAAAAA--B B--AAAAAAAAAAAAAAAAAAAAAAAA--B B--AAAAAAAAAAAAAAAAAAAAAAAA--B B--AAAAAAAAAAAAAAAAAAAAAAAA--B B--AAAAAAAAAAAAAAAAAAAAAAAA--B B--AAAAAAAAAAAAAAAAAAAAAAAA--B B--AAAAAAAAAAAAAAAAAAAAAAAA--B B--AAAAAAAAAAAAAAAAAAAAAAAA--B B--AAAAAAAAAAAAAAAAAAAAAAAA--B B--AAAAAAAAAAAAAAAAAAAAAAAA--B B--AAAAAAAAAAAAAAAAAAAAAAAA--B B--AAAAAAAAAAAAAAAAAAAAAAAA--B B--AAAAAAAAAAAAAAAAAAAAAAAA--B B--AAAAAAAAAAAAAAAAAAAAAAAA--B B--AAAAAAAAAAAAAAAAAAAAAAAA--B B----------------------------B B----------------------------B BBBBBBBB--BBBBBBBBBB--BBBBBBBB 
BBBBBBBBBBBBBBBBBBBBBBBBBBBBBB BB-BBBBBBBBBBBBBBBBBBBBBBBBBBB B------------------------AA--B B--AAAAAAAAAAAAAAAAAAAAAAAA--B B--AAAAAAAAAAAAAAAAAAAAAAAA--B B--AAAAAAAAAAAAAAAAAAAAAAAA--B B--AAAAAAAAAAAAAAAAAAAAAAAA--B B--AAAAAAAAAAAAAAAAAAAAAAAA--B B--AAAAAAAAAAAAAAAAAAAAAAAA--B B--AAAAAAAAAAAAAAAAAAAAAAAA--B B--AAAAAAAAAAAAAAAAAAAAAAAA--B B--AAAAAAAAAAAAAAAAAAAAAAAA--B B--AAAAAAAAAAAAAAAAAAAAAAAA--B B--AAAAAAAAAAAAAAAAAAAAAAAA--B B--AAAAAAAAAAAAAAAAAAAAAAAA--B B--AAAAAAAAAAAAAAAAAAAAAAAA--B B--AAAAAAAAAAAAAAAAAAAAAAAA--B B--AAAAAAAAAAAAAAAAAAAAAAAA--B B--AAAAAAAAAAAAAAAAAAAAAAAA--B B--AAAAAAAAAAAAAAAAAAAAAAAA--B B--AAAAAAAAAAAAAAAAAAAAAAAA--B B--AAAAAAAAAAAAAAAAAAAAAAAA--B B--AAAAAAAAAAAAAAAAAAAAAAAA--B B--AAAAAAAAAAAAAAAAAAAAAAAA--B B--AAAAAAAAAAAAAAAAAAAAAAAA--B B--AAAAAAAAAAAAAAAAAAAAAAAA--B B--AAAAAAAAAAAAAAAAAAAAAAAA--B B----------------------------B B----------------------------B BBBBBBBB--BBBBBBBBBB--BBBBBBBB 
BBBBBBBBBBBBBBBBBBBBBBBBBBBBBB BB-BBBBBBBBBBBBBBBBBBBBBBBBBBB B------------------------AA--B B--AAAAAAAAAAAAAAAAAAAAAAAA--B B--AAAAAAAAAAAAAAAAAAAAAAAA--B B--AAAAAAAAAAAAAAAAAAAAAAAA--B B--AAAAAAAAAAAAAAAAAAAAAAAA--B B--AAAAAAAAAAAAAAAAAAAAAAAA--B B--AAAAAAAAAAAAAAAAAAAAAAAA--B B--AAAAAAAAAAAAAAAAAAAAAAAA--B B--AAAAAAAAAAAAAAAAAAAAAAAA--B B--AAAAAAAAAAAAAAAAAAAAAAAA--B B--AAAAAAAAAAAAAAAAAAAAAAAA--B B--AAAAAAAAAAAAAAAAAAAAAAAA--B B--AAAAAAAAAAAAAAAAAAAAAAAA--B B--AAAAAAAAAAAAAAAAAAAAAAAA--B B--AAAAAAAAAAAAAAAAAAAAAAAA--B B--AAAAAAAAAAAAAAAAAAAAAAAA--B B--AAAAAAAAAAAAAAAAAAAAAAAA--B B--AAAAAAAAAAAAAAAAAAAAAAAA--B B--AAAAAAAAAAAAAAAAAAAAAAAA--B B--AAAAAAAAAAAAAAAAAAAAAAAA--B B--AAAAAAAAAAAAAAAAAAAAAAAA--B B--AAAAAAAAAAAAAAAAAAAAAAAA--B B--AAAAAAAAAAAAAAAAAAAAAAAA--B B--AAAAAAAAAAAAAAAAAAAAAAAA--B B--AAAAAAAAAAAAAAAAAAAAAAAA--B B----------------------------B B----------------------------B BBBBBBBB--BBBBBBBBBB--BBBBBBBB 
BBBBBBBBBBBBBBBBBBBBBBBBBBBBBB BB-BBBBBBBBBBBBBBBBBBBBBBBBBBB B------------------------AA--B ---AAAAAAAAAAAAAAAAAAAAAAAA--- ---AAAAAAAAAAAAAAAAAAAAAAAA--- ---AAAAAAAAAAAAAAAAAAAAAAAA--- B--AAAAAAAAAAAAAAAAAAAAAAAA--B B--AAAAAAAAAAAAAAAAAAAAAAAA--B B--AAAAAAAAAAAAAAAAAAAAAAAA--B ---AAAAAAAAAAAAAAAAAAAAAAAA--- ---AAAAAAAAAAAAAAAAAAAAAAAA--- ---AAAAAAAAAAAAAAAAAAAAAAAA--- B--AAAAAAAAAAAAAAAAAAAAAAAA--B B--AAAAAAAAAAAAAAAAAAAAAAAA--B ---AAAAAAAAAAAAAAAAAAAAAAAA--- ---AAAAAAAAAAAAAAAAAAAAAAAA--- ---AAAAAAAAAAAAAAAAAAAAAAAA--- B--AAAAAAAAAAAAAAAAAAAAAAAA--B B--AAAAAAAAAAAAAAAAAAAAAAAA--B ---AAAAAAAAAAAAAAAAAAAAAAAA--- ---AAAAAAAAAAAAAAAAAAAAAAAA--- ---AAAAAAAAAAAAAAAAAAAAAAAA--- B--AAAAAAAAAAAAAAAAAAAAAAAA--B B--AAAAAAAAAAAAAAAAAAAAAAAA--B B--AAAAAAAAAAAAAAAAAAAAAAAA--B ---AAAAAAAAAAAAAAAAAAAAAAAA--- ---AAAAAAAAAAAAAAAAAAAAAAAA--- ------------------------------ B----------------------------B BBBBBBBB--BBBBBBBBBB--BBBBBBBB 
BBBBBBBBBBBBBBBBBBBBBBBBBBBBBB BB-BBBBBBBBBBBBBBBBBBBBBBBBBBB B------------------------AA--B ---AAAAAAAAAAAAAAAAAAAAAAAA--- ---AAAAAAAAAAAAAAAAAAAAAAAA--- ---AAAAAAAAAAAAAAAAAAAAAAAA--- B--AAAAAAAAAAAAAAAAAAAAAAAA--B B--AAAAAAAAAAAAAAAAAAAAAAAA--B B--AAAAAAAAAAAAAAAAAAAAAAAA--B ---AAAAAAAAAAAAAAAAAAAAAAAA--- ---AAAAAAAAAAAAAAAAAAAAAAAA--- ---AAAAAAAAAAAAAAAAAAAAAAAA--- B--AAAAAAAAAAAAAAAAAAAAAAAA--B B--AAAAAAAAAAAAAAAAAAAAAAAA--B ---AAAAAAAAAAAAAAAAAAAAAAAA--- ---AAAAAAAAAAAAAAAAAAAAAAAA--- ---AAAAAAAAAAAAAAAAAAAAAAAA--- B--AAAAAAAAAAAAAAAAAAAAAAAA--B B--AAAAAAAAAAAAAAAAAAAAAAAA--B ---AAAAAAAAAAAAAAAAAAAAAAAA--- ---AAAAAAAAAAAAAAAAAAAAAAAA--- ---AAAAAAAAAAAAAAAAAAAAAAAA--- B--AAAAAAAAAAAAAAAAAAAAAAAA--B B--AAAAAAAAAAAAAAAAAAAAAAAA--B B--AAAAAAAAAAAAAAAAAAAAAAAA--B ---AAAAAAAAAAAAAAAAAAAAAAAA--- ---AAAAAAAAAAAAAAAAAAAAAAAA--- ------------------------------ B----------------------------B BBBBBBBB--BBBBBBBBBB--BBBBBBBB 
BBBBBBBBBBBBBBBBBBBBBBBBBBBBBB BB-BBBBBBBBBBBBBBBBBBBBBBBBBBB B------------------------AA--B ---AAAAAAAAAAAAAAAAAAAAAAAA--- ---AAAAAAAAAAAAAAAAAAAAAAAA--- ---AAAAAAAAAAAAAAAAAAAAAAAA--- B--AAAAAAAAAAAAAAAAAAAAAAAA--B B--AAAAAAAAAAAAAAAAAAAAAAAA--B B--AAAAAAAAAAAAAAAAAAAAAAAA--B ---AAAAAAAAAAAAAAAAAAAAAAAA--- ---AAAAAAAAAAAAAAAAAAAAAAAA--- ---AAAAAAAAAAAAAAAAAAAAAAAA--- B--AAAAAAAAAAAAAAAAAAAAAAAA--B B--AAAAAAAAAAAAAAAAAAAAAAAA--B ---AAAAAAAAAAAAAAAAAAAAAAAA--- ---AAAAAAAAAAAAAAAAAAAAAAAA--- ---AAAAAAAAAAAAAAAAAAAAAAAA--- B--AAAAAAAAAAAAAAAAAAAAAAAA--B B--AAAAAAAAAAAAAAAAAAAAAAAA--B ---AAAAAAAAAAAAAAAAAAAAAAAA--- ---AAAAAAAAAAAAAAAAAAAAAAAA--- ---AAAAAAAAAAAAAAAAAAAAAAAA--- B--AAAAAAAAAAAAAAAAAAAAAAAA--B B--AAAAAAAAAAAAAAAAAAAAAAAA--B B--AAAAAAAAAAAAAAAAAAAAAAAA--B ---AAAAAAAAAAAAAAAAAAAAAAAA--- ---AAAAAAAAAAAAAAAAAAAAAAAA--- ------------------------------ B----------------------------B BBBBBBBB--BBBBBBBBBB--BBBBBBBB 
BBBBBBBBBBBBBBBBBBBBBBBBBBBBBB BB-BBBBBBBBBBBBBBBBBBBBBBBBBBB B------------------------AA--B B--AAAAAAAAAAAAAAAAAAAAAAAA--B B--AAAAAAAAAAAAAAAAAAAAAAAA--B B--AAAAAAAAAAAAAAAAAAAAAAAA--B B--AAAAAAAAAAAAAAAAAAAAAAAA--B B--AAAAAAAAAAAAAAAAAAAAAAAA--B B--AAAAAAAAAAAAAAAAAAAAAAAA--B B--AAAAAAAAAAAAAAAAAAAAAAAA--B B--AAAAAAAAAAAAAAAAAAAAAAAA--B B--AAAAAAAAAAAAAAAAAAAAAAAA--B B--AAAAAAAAAAAAAAAAAAAAAAAA--B B--AAAAAAAAAAAAAAAAAAAAAAAA--B B--AAAAAAAAAAAAAAAAAAAAAAAA--B B--AAAAAAAAAAAAAAAAAAAAAAAA--B B--AAAAAAAAAAAAAAAAAAAAAAAA--B B--AAAAAAAAAAAAAAAAAAAAAAAA--B B--AAAAAAAAAAAAAAAAAAAAAAAA--B B--AAAAAAAAAAAAAAAAAAAAAAAA--B B--AAAAAAAAAAAAAAAAAAAAAAAA--B B--AAAAAAAAAAAAAAAAAAAAAAAA--B B--AAAAAAAAAAAAAAAAAAAAAAAA--B B--AAAAAAAAAAAAAAAAAAAAAAAA--B B--AAAAAAAA-AAAAAAAAAAAAAAA--B B--AAAAAAAAAAAAAAAAAAAAAAAA--B B--AAAAAAAAAAAAAAAAAAAAAAAA--B B----------------------------B B----------------------------B BBBBBBBB--BBBBBBBBBB--BBBBBBBB 
BBBBBBBBBBBBBBBBBBBBBBBBBBBBBB BB-BBBBBBBBBBBBBBBBBBBBBBBBBBB B------------------------AA--B B--AAAAAAAAAAAAAAAAAAAAAAAA--B B--AAAAAAAAAAAAAAAAAAAAAAAA--B B--AAAAAAAAAAAAAAAAAAAAAAAA--B B--AAAAAAAAAAAAAAAAAAAAAAAA--B B--AAAAAAAAAAAAAAAAAAAAAAAA--B B--AAAAAAAAAAAAAAAAAAAAAAAA--B B--AAAAAAAAAAAAAAAAAAAAAAAA--B B--AAAAAAAAAAAAAAAAAAAAAAAA--B B--AAAAAAAAAAAAAAAAAAAAAAAA--B B--AAAAAAAAAAAAAAAAAAAAAAAA--B B--AAAAAAAAAAAAAAAAAAAAAAAA--B B--AAAAAAAAAAAAAAAAAAAAAAAA--B B--AAAAAAAAAAAAAAAAAAAAAAAA--B B--AAAAAAAAAAAAAAAAAAAAAAAA--B B--AAAAAAAAAAAAAAAAAAAAAAAA--B B--AAAAAAAAAAAAAAAAAAAAAAAA--B B--AAAAAAAAAAAAAAAAAAAAAAAA--B B--AAAAAAAAAAAAAAAAAAAAAAAA--B B--AAAAAAAAAAAAAAAAAAAAAAAA--B B--AAAAAAAAAAAAAAAAAAAAAAAA--B B--AAAAAAAAAA-AAAAAAAAAAAAA--B B--AAAAAAA-A--AAAAAAAAAAAAA--B B--AAAAAAAAAAAAAAAAAAAAAAAA--B B--AAAAAAAAAAAAAAAAAAAAAAAA--B B----------------------------B B----------------------------B BBBBBBBB--BBBBBBBBBB--BBBBBBBB 
BBBBBBBBBBBBBBBBBBBBBBBBBBBBBB BB-BBBBBBBBBBBBBBBBBBBBBBBBBBB B------------------------AA--B ---AAAAAAAAAAAAAAAAAAAAAAAA--- ---AAAAAAAAAAAAAAAAAAAAAAAA--- ---AAAAAAAAAAAAAAAAAAAAAAAA--- B--AAAAAAAAAAAAAAAAAAAAAAAA--B B--AAAAAAAAAAAAAAAAAAAAAAAA--B B--AAAAAAAAAAAAAAAAAAAAAAAA--B ---AAAAAAAAAAAAAAAAAAAAAAAA--- ---AAAAAAAAAAAAAAAAAAAAAAAA--- ---AAAAAAAAAAAAAAAAAAAAAAAA--- B--AAAAAAAAAAAAAAAAAAAAAAAA--B B--AAAAAAAAAAAAAAAAAAAAAAAA--B ---AAAAAAAAAAAAAAAAAAAAAAAA--- ---AAAAAAAAAAAAAAAAAAAAAAAA--- ---AAAAAAAAAAAAAAAAAAAAAAAA--- B--AAAAAAAAAAAAAAAAAAAAAAAA--B B--AAAAAAAAAAAAAAAAAAAAAAAA--B ---AAAAAAAAAAAAAAAAAAAAAAAA--- ---AAAAAAAAAA-AAAAAAAAAAAAA--- ---AAAAAAAAAA-AAAAAAAAAAAAA--- B--AAAAAAAAAA-AAAAAAAAAAAAA--B B--AAAAAAAAAA-AAAAAAAAAAAAA--B B--AAAAAAAAAA-AAAAAAAAAAAAA--B ---AAAAAAAAAAAAAAAAAAAAAAAA--- ---AAAAAAAAAAAAAAAAAAAAAAAA--- ------------------------------ B----------------------------B BBBBBBBB--BBBBBBBBBB--BBBBBBBB 
BBBBBBBBBBBBBBBBBBBBBBBBBBBBBB BB-BBBBBBBBBBBBBBBBBBBBBBBBBBB B------------------------AA--B ---AAAAAAAAAAAAAAAAAAAAAAAA--- ---AAAAAAAAAAAAAAAAAAAAAAAA--- ---AAAAAAAAAAAAAAAAAAAAAAAA--- B--AAAAAAAAAAAAAAAAAAAAAAAA--B B--AAAAAAAAAAAAAAAAAAAAAAAA--B B--AAAAAAAAAAAAAAAAAAAAAAAA--B ---AAAAAAAAAAAAAAAAAAAAAAAA--- ---AAAAAAAAAAAAAAAAAAAAAAAA--- ---AAAAAAAAAAAAAAAAAAAAAAAA--- B--AAAAAAAAAAAAAAAAAAAAAAAA--B B--AAAAAAAAAAAAAAAAAAAAAAAA--B ---AAAAAAAAAAAAAAAAAAAAAAAA--- ---AAAAAAAAAAAAAAAAAAAAAAAA--- ---AAAAAAAAAAAAAAAAAAAAAAAA--- B--AAAAAAAAAAAAAAAAAAAAAAAA--B B--AAAAAAAAAAAAAAAAAAAAAAAA--B ---AAAAAAAAAAAAAAAAAAAAAAAA--- ---AAAAAAAAAAAAAAAAAAAAAAAA--- ---AAAAAAAAAAAAAAAAAAAAAAAA--- B--AAAAAAAAAAA-AAAAAAAAAAAA--B B--AAAAAAAAAAA-AAAAAAAAAAAA--B B--AAAAAAAAAAA-AAAAAAAAAAAA--B ---AAAAAAAAAAAAAAAAAAAAAAAA--- ---AAAAAAAAAAAAAAAAAAAAAAAA--- ------------------------------ B----------------------------B BBBBBBBB--BBBBBBBBBB--BBBBBBBB 
BBBBBBBBBBBBBBBBBBBBBBBBBBBBBB BB-BBBBBBBBBBBBBBBBBBBBBBBBBBB B------------------------AA--B ---AAAAAAAAAAAAAAAAAAAAAAAA--- ---AAAAAAAAAAAAAAAAAAAAAAAA--- ---AAAAAAAAAAAAAAAAAAAAAAAA--- B--AAAAAAAAAAAAAAAAAAAAAAAA--B B--AAAAAAAAAAAAAAAAAAAAAAAA--B B--AAAAAAAAAAAAAAAAAAAAAAAA--B ---AAAAAAAAAAAAAAAAAAAAAAAA--- ---AAAAAAAAAAAAAAAAAAAAAAAA--- ---AAAAAAAAAAAAAAAAAAAAAAAA--- B--AAAAAAAAAAAAAAAAAAAAAAAA--B B--AAAAAAAAAAAAAAAAAAAAAAAA--B ---AAAAAAAAAAAAAAAAAAAAAAAA--- ---AAAAAAAAAAAAAAAAAAAAAAAA--- ---AAAAAAAAAAAAAAAAAAAAAAAA--- B--AAAAAAAAAAAAAAAAAAAAAAAA--B B--AAAAAAAAAAAAAAAAAAAAAAAA--B ---AAAAAAAAAAAAAAAAAAAAAAAA--- ---AAAAAAAAAAAAAAAAAAAAAAAA--- ---AAAAAAAAAAAAAAAAAAAAAAAA--- B--AAAAAAAAAAAAAAAAAAAAAAAA--B B--AAAAAAAAAAAAAAAAAAAAAAAA--B B--AAAAAAAAAAAAAAAAAAAAAAAA--B ---AAAAAAAAAAAAAAAAAAAAAAAA--- ---AAAAAAAAAAAAAAAAAAAAAAAA--- ------------------------------ B----------------------------B BBBBBBBB--BBBBBBBBBB--BBBBBBBB 
BBBBBBBBBBBBBBBBBBBBBBBBBBBBBB BB-BBBBBBBBBBBBBBBBBBBBBBBBBBB B------------------------AA--B B--AAAAAAAAAAAAAAAAAAAAAAAA--B B--AAAAAAAAAAAAAAAAAAAAAAAA--B B--AAAAAAAAAAAAAAAAAAAAAAAA--B B--AAAAAAAAAAAAAAAAAAAAAAAA--B B--AAAAAAAAAAAAAAAAAAAAAAAA--B B--AAAAAAAAAAAAAAAAAAAAAAAA--B B--AAAAAAAAAAAAAAAAAAAAAAAA--B B--AAAAAAAAAAAAAAAAAAAAAAAA--B B--AAAAAAAAAAAAAAAAAAAAAAAA--B B--AAAAAAAAAAAAAAAAAAAAAAAA--B B--AAAAAAAAAAAAAAAAAAAAAAAA--B B--AAAAAAAAAAAAAAAAAAAAAAAA--B B--AAAAAAAAAAAAAAAAAAAAAAAA--B B--AAAAAAAAAAAAAAAAAAAAAAAA--B B--AAAAAAAAAAAAAAAAAAAAAAAA--B B--AAAAAAAAAAAAAAAAAAAAAAAA--B B--AAAAAAAAAAAAAAAAAAAAAAAA--B B--AAAAAAAAAAAAAAAAAAAAAAAA--B B--AAAAAAAAAAAAAAAAAAAAAAAA--B B--AAAAAAAAAAAAAAAAAAAAAAAA--B B--AAAAAAAAAA-AAAAAAAAAAAAA--B B--AAAAAAAAAA-AAAAAAAAAAAAA--B B--AAAAAAAAAAAAAAAAAAAAAAAA--B B--AAAAAAAAAAAAAAAAAAAAAAAA--B B----------------------------B B----------------------------B BBBBBBBB--BBBBBBBBBB--BBBBBBBB 
BBBBBBBBBBBBBBBBBBBBBBBBBBBBBB BB-BBBBBBBBBBBBBBBBBBBBBBBBBBB B------------------------AA--B B--AAAAAAAAAAAAAAAAAAAAAAAA--B B--AAAAAAAAAAAAAAAAAAAAAAAA--B B--AAAAAAAAAAAAAAAAAAAAAAAA--B B--AAAAAAAAAAAAAAAAAAAAAAAA--B B--AAAAAAAAAAAAAAAAAAAAAAAA--B B--AAAAAAAAAAAAAAAAAAAAAAAA--B B--AAAAAAAAAAAAAAAAAAAAAAAA--B B--AAAAAAAAAAAAAAAAAAAAAAAA--B B--AAAAAAAAAAAAAAAAAAAAAAAA--B B--AAAAAAAAAAAAAAAAAAAAAAAA--B B--AAAAAAAAAAAAAAAAAAAAAAAA--B B--AAAAAAAAAAAAAAAAAAAAAAAA--B B--AAAAAAAAAAAAAAAAAAAAAAAA--B B--AAAAAAAAAAAAAAAAAAAAAAAA--B B--AAAAAAAAAAAAAAAAAAAAAAAA--B B--AAAAAAAAAAAAAAAAAAAAAAAA--B B--AAAAAAAAAAAAAAAAAAAAAAAA--B B--AAAAAAAAAAAAAAAAAAAAAAAA--B B--AAAAAAAAAAAAAAAAAAAAAAAA--B B--AAAAAAAAAAAAAAAAAAAAAAAA--B B--AAAAAAAAAAAAAAAAAAAAAAAA--B B--AAAAAAAAAAAAAAAAAAAAAAAA--B B--AAAAAAAAAAAAAAAAAAAAAAAA--B B--AAAAAAAAAAAAAAAAAAAAAAAA--B B----------------------------B B----------------------------B BBBBBBBB--BBBBBBBBBB--BBBBBBBB 
BBBBBBBBBBBBBBBBBBBBBBBBBBBBBB BB-BBBBBBBBBBBBBBBBBBBBBBBBBBB B------------------------AA--B ---AAAAAAAAAAAAAAAAAAAAAAAA--- ---AAAAAAAAAAAAAAAAAAAAAAAA--- ---AAAAAAAAAAAAAAAAAAAAAAAA--- B--AAAAAAAAAAAAAAAAAAAAAAAA--B B--AAAAAAAAAAAAAAAAAAAAAAAA--B B--AAAAAAAAAAAAAAAAAAAAAAAA--B ---AAAAAAAAAAAAAAAAAAAAAAAA--- ---AAAAAAAAAAAAAAAAAAAAAAAA--- ---AAAAAAAAAAAAAAAAAAAAAAAA--- B--AAAAAAAAAAAAAAAAAAAAAAAA--B B--AAAAAAAAAAAAAAAAAAAAAAAA--B ---AAAAAAAAAAAAAAAAAAAAAAAA--- ---AAAAAAAAAAAAAAAAAAAAAAAA--- ---AAAAAAAAAAAAAAAAAAAAAAAA--- B--AAAAAAAAAAAAAAAAAAAAAAAA--B B--AAAAAAAAAAAAAAAAAAAAAAAA--B ---AAAAAAAAAAAAAAAAAAAAAAAA--- ---AAAAAAAAAAAAAAAAAAAAAAAA--- ---AAAAAAAAAAAAAAAAAAAAAAAA--- B--AAAAAAAAAAAAAAAAAAAAAAAA--B B--AAAAAAAAAAAAAAAAAAAAAAAA--B B--AAAAAAAAAAAAAAAAAAAAAAAA--B ---AAAAAAAAAAAAAAAAAAAAAAAA--- ---AAAAAAAAAAAAAAAAAAAAAAAA--- ------------------------------ B----------------------------B BBBBBBBB--BBBBBBBBBB--BBBBBBBB 
BBBBBBBBBBBBBBBBBBBBBBBBBBBBBB BB-BBBBBBBBBBBBBBBBBBBBBBBBBBB B------------------------AA--B ---AAAAAAAAAAAAAAAAAAAAAAAA--- ---AAAAAAAAAAAAAAAAAAAAAAAA--- ---AAAAAAAAAAAAAAAAAAAAAAAA--- B--AAAAAAAAAAAAAAAAAAAAAAAA--B B--AAAAAAAAAAAAAAAAAAAAAAAA--B B--AAAAAAAAAAAAAAAAAAAAAAAA--B ---AAAAAAAAAAAAAAAAAAAAAAAA--- ---AAAAAAAAAAAAAAAAAAAAAAAA--- ---AAAAAAAAAAAAAAAAAAAAAAAA--- B--AAAAAAAAAAAAAAAAAAAAAAAA--B B--AAAAAAAAAAAAAAAAAAAAAAAA--B ---AAAAAAAAAAAAAAAAAAAAAAAA--- ---AAAAAAAAAAAAAAAAAAAAAAAA--- ---AAAAAAAAAAAAAAAAAAAAAAAA--- B--AAAAAAAAAAAAAAAAAAAAAAAA--B B--AAAAAAAAAAAAAAAAAAAAAAAA--B ---AAAAAAAAAAAAAAAAAAAAAAAA--- ---AAAAAAAAAAAAAAAAAAAAAAAA--- ---AAAAAAAAAAAAAAAAAAAAAAAA--- B--AAAAAAAAAAAAAAAAAAAAAAAA--B B--AAAAAAAAAAAAAAAAAAAAAAAA--B B--AAAAAAAAAAAAAAAAAAAAAAAA--B ---AAAAAAAAAAAAAAAAAAAAAAAA--- ---AAAAAAAAAAAAAAAAAAAAAAAA--- ------------------------------ B----------------------------B BBBBBBBB--BBBBBBBBBB--BBBBBBBB 
BBBBBBBBBBBBBBBBBBBBBBBBBBBBBB BB-BBBBBBBBBBBBBBBBBBBBBBBBBBB B------------------------AA--B ---AAAAAAAAAAAAAAAAAAAAAAAA--- ---AAAAAAAAAAAAAAAAAAAAAAAA--- ---AAAAAAAAAAAAAAAAAAAAAAAA--- B--AAAAAAAAAAAAAAAAAAAAAAAA--B B--AAAAAAAAAAAAAAAAAAAAAAAA--B B--AAAAAAAAAAAAAAAAAAAAAAAA--B ---AAAAAAAAAAAAAAAAAAAAAAAA--- ---AAAAAAAAAAAAAAAAAAAAAAAA--- ---AAAAAAAAAAAAAAAAAAAAAAAA--- B--AAAAAAAAAAAAAAAAAAAAAAAA--B B--AAAAAAAAAAAAAAAAAAAAAAAA--B ---AAAAAAAAAAAAAAAAAAAAAAAA--- ---AAAAAAAAAAAAAAAAAAAAAAAA--- ---AAAAAAAAAAAAAAAAAAAAAAAA--- B--AAAAAAAAAAAAAAAAAAAAAAAA--B B--AAAAAAAAAAAAAAAAAAAAAAAA--B ---AAAAAAAAAAAAAAAAAAAAAAAA--- ---AAAAAAAAAAAAAAAAAAAAAAAA--- ---AAAAAAAAAAAAAAAAAAAAAAAA--- B--AAAAAAAAAAAAAAAAAAAAAAAA--B B--AAAAAAAAAAAAAAAAAAAAAAAA--B B--AAAAAAAAAAAAAAAAAAAAAAAA--B ---AAAAAAAAAAAAAAAAAAAAAAAA--- ---AAAAAAAAAAAAAAAAAAAAAAAA--- ------------------------------ B----------------------------B BBBBBBBB--BBBBBBBBBB--BBBBBBBB 
BBBBBBBBBBBBBBBBBBBBBBBBBBBBBB BB-BBBBBBBBBBBBBBBBBBBBBBBBBBB B------------------------AA--B B--AAAAAAAAAAAAAAAAAAAAAAAA--B B--AAAAAAAAAAAAAAAAAAAAAAAA--B B--AAAAAAAAAAAAAAAAAAAAAAAA--B B--AAAAAAAAAAAAAAAAAAAAAAAA--B B--AAAAAAAAAAAAAAAAAAAAAAAA--B B--AAAAAAAAAAAAAAAAAAAAAAAA--B B--AAAAAAAAAAAAAAAAAAAAAAAA--B B--AAAAAAAAAAAAAAAAAAAAAAAA--B B--AAAAAAAAAAAAAAAAAAAAAAAA--B B--AAAAAAAAAAAAAAAAAAAAAAAA--B B--AAAAAAAAAAAAAAAAAAAAAAAA--B B--AAAAAAAAAAAAAAAAAAAAAAAA--B B--AAAAAAAAAAAAAAAAAAAAAAAA--B B--AAAAAAAAAAAAAAAAAAAAAAAA--B B--AAAAAAAAAAAAAAAAAAAAAAAA--B B--AAAAAAAAAAAAAAAAAAAAAAAA--B B--AAAAAAAAAAAAAAAAAAAAAAAA--B B--AAAAAAAAAAAAAAAAAAAAAAAA--B B--AAAAAAAAAAAAAAAAAAAAAAAA--B B--AAAAAAAAAAAAAAAAAAAAAAAA--B B--AAAAAAAAAAAAAAAAAAAAAAAA--B B--AAAAAAAAAAAAAAAAAAAAAAAA--B B--AAAAAAAAAAAAAAAAAAAAAAAA--B B--AAAAAAAAAAAAAAAAAAAAAAAA--B B----------------------------B B----------------------------B BBBBBBBB--BBBBBBBBBB--BBBBBBBB 
BBBBBBBBBBBBBBBBBBBBBBBBBBBBBB BB-BBBBBBBBBBBBBBBBBBBBBBBBBBB B------------------------AA--B B--AAAAAAAAAAAAAAAAAAAAAAAA--B B--AAAAAAAAAAAAAAAAAAAAAAAA--B B--AAAAAAAAAAAAAAAAAAAAAAAA--B B--AAAAAAAAAAAAAAAAAAAAAAAA--B B--AAAAAAAAAAAAAAAAAAAAAAAA--B B--AAAAAAAAAAAAAAAAAAAAAAAA--B B--AAAAAAAAAAAAAAAAAAAAAAAA--B B--AAAAAAAAAAAAAAAAAAAAAAAA--B B--AAAAAAAAAAAAAAAAAAAAAAAA--B B--AAAAAAAAAAAAAAAAAAAAAAAA--B B--AAAAAAAAAAAAAAAAAAAAAAAA--B B--AAAAAAAAAAAAAAAAAAAAAAAA--B B--AAAAAAAAAAAAAAAAAAAAAAAA--B B--AAAAAAAAAAAAAAAAAAAAAAAA--B B--AAAAAAAAAAAAAAAAAAAAAAAA--B B--AAAAAAAAAAAAAAAAAAAAAAAA--B B--AAAAAAAAAAAAAAAAAAAAAAAA--B B--AAAAAAAAAAAAAAAAAAAAAAAA--B B--AAAAAAAAAAAAAAAAAAAAAAAA--B B--AAAAAAAAAAAAAAAAAAAAAAAA--B B--AAAAAAAAAAAAAAAAAAAAAAAA--B B--AAAAAAAAAAAAAAAAAAAAAAAA--B B--AAAAAAAAAAAAAAAAAAAAAAAA--B B--AAAAAAAAAAAAAAAAAAAAAAAA--B B----------------------------B B----------------------------B BBBBBBBB--BBBBBBBBBB--BBBBBBBB 
BBBBBBBBBBBBBBBBBBBBBBBBBBBBBB BB-BBBBBBBBBBBBBBBBBBBBBBBBBBB B------------------------AA--B B--AAAAAAAAAAAAAAAAAAAAAAAA--B B--AAAAAAAAAAAAAAAAAAAAAAAA--B B--AAAAAAAAAAAAAAAAAAAAAAAA--B B--AAAAAAAAAAAAAAAAAAAAAAAA--B B--AAAAAAAAAAAAAAAAAAAAAAAA--B B--AAAAAAAAAAAAAAAAAAAAAAAA--B B--AAAAAAAAAAAAAAAAAAAAAAAA--B B--AAAAAAAAAAAAAAAAAAAAAAAA--B B--AAAAAAAAAAAAAAAAAAAAAAAA--B B--AAAAAAAAAAAAAAAAAAAAAAAA--B B--AAAAAAAAAAAAAAAAAAAAAAAA--B B--AAAAAAAAAAAAAAAAAAAAAAAA--B B--AAAAAAAAAAAAAAAAAAAAAAAA--B B--AAAAAAAAAAAAAAAAAAAAAAAA--B B--AAAAAAAAAAAAAAAAAAAAAAAA--B B--AAAAAAAAAAAAAAAAAAAAAAAA--B B--AAAAAAAAAAAAAAAAAAAAAAAA--B B--AAAAAAAAAAAAAAAAAAAAAAAA--B B--AAAAAAAAAAAAAAAAAAAAAAAA--B B--AAAAAAAAAAAAAAAAAAAAAAAA--B B--AAAAAAAAAAAAAAAAAAAAAAAA--B B--AAAAAAAAAAAAAAAAAAAAAAAA--B B--AAAAAAAAAAAAAAAAAAAAAAAA--B B--AAAAAAAAAAAAAAAAAAAAAAAA--B B----------------------------B B----------------------------B BBBBBBBB--BBBBBBBBBB--BBBBBBBB 
BBBBBBBBBBBBBBBBBBBBBBBBBBBBBB BB-BBBBBBBBBBBBBBBBBBBBBBBBBBB B------------------------AA--B ---AAAAAAAAAAAAAAAAAAAAAAAA--- ---AAAAAAAAAAAAAAAAAAAAAAAA--- ---AAAAAAAAAAAAAAAAAAAAAAAA--- B--AAAAAAAAAAAAAAAAAAAAAAAA--B B--AAAAAAAAAAAAAAAAAAAAAAAA--B B--AAAAAAAAAAAAAAAAAAAAAAAA--B ---AAAAAAAAAAAAAAAAAAAAAAAA--- ---AAAAAAAAAAAAAAAAAAAAAAAA--- ---AAAAAAAAAAAAAAAAAAAAAAAA--- B--AAAAAAAAAAAAAAAAAAAAAAAA--B B--AAAAAAAAAAAAAAAAAAAAAAAA--B ---AAAAAAAAAAAAAAAAAAAAAAAA--- ---AAAAAAAAAAAAAAAAAAAAAAAA--- ---AAAAAAAAAAAAAAAAAAAAAAAA--- B--AAAAAAAAAAAAAAAAAAAAAAAA--B B--AAAAAAAAAAAAAAAAAAAAAAAA--B ---AAAAAAAAAAAAAAAAAAAAAAAA--- ---AAAAAAAAAAAAAAAAAAAAAAAA--- ---AAAAAAAAAAAAAAAAAAAAAAAA--- B--AAAAAAAAAAAAAAAAAAAAAAAA--B B--AAAAAAAAAAAAAAAAAAAAAAAA--B B--AAAAAAAAAAAAAAAAAAAAAAAA--B ---AAAAAAAAAAAAAAAAAAAAAAAA--- ---AAAAAAAAAAAAAAAAAAAAAAAA--- ------------------------------ B----------------------------B BBBBBBBB--BBBBBBBBBB--BBBBBBBB 
BBBBBBBBBBBBBBBBBBBBBBBBBBBBBB BB-BBBBBBBBBBBBBBBBBBBBBBBBBBB B------------------------AA--B ---AAAAAAAAAAAAAAAAAAAAAAAA--- ---AAAAAAAAAAAAAAAAAAAAAAAA--- ---AAAAAAAAAAAAAAAAAAAAAAAA--- B--AAAAAAAAAAAAAAAAAAAAAAAA--B B--AAAAAAAAAAAAAAAAAAAAAAAA--B B--AAAAAAAAAAAAAAAAAAAAAAAA--B ---AAAAAAAAAAAAAAAAAAAAAAAA--- ---AAAAAAAAAAAAAAAAAAAAAAAA--- ---AAAAAAAAAAAAAAAAAAAAAAAA--- B--AAAAAAAAAAAAAAAAAAAAAAAA--B B--AAAAAAAAAAAAAAAAAAAAAAAA--B ---AAAAAAAAAAAAAAAAAAAAAAAA--- ---AAAAAAAAAAAAAAAAAAAAAAAA--- ---AAAAAAAAAAAAAAAAAAAAAAAA--- B--AAAAAAAAAAAAAAAAAAAAAAAA--B B--AAAAAAAAAAAAAAAAAAAAAAAA--B ---AAAAAAAAAAAAAAAAAAAAAAAA--- ---AAAAAAAAAAAAAAAAAAAAAAAA--- ---AAAAAAAAAAAAAAAAAAAAAAAA--- B--AAAAAAAAAAAAAAAAAAAAAAAA--B B--AAAAAAAAAAAAAAAAAAAAAAAA--B B--AAAAAAAAAAAAAAAAAAAAAAAA--B ---AAAAAAAAAAAAAAAAAAAAAAAA--- ---AAAAAAAAAAAAAAAAAAAAAAAA--- ------------------------------ B----------------------------B BBBBBBBBBBBBBBBBBBBBBBBBBBBBBB 
BBBBBBBBBBBBBBBBBBBBBBBBBBBBBB BB-BBBBBBBBBBBBBBBBBBBBBBBBBBB B------------------------AA--B ---AAAAAAAAAAAAAAAAAAAAAAAA--- ---AAAAAAAAAAAAAAAAAAAAAAAA--- ---AAAAAAAAAAAAAAAAAAAAAAAA--- B--AAAAAAAAAAAAAAAAAAAAAAAA--B B--AAAAAAAAAAAAAAAAAAAAAAAA--B B--AAAAAAAAAAAAAAAAAAAAAAAA--B ---AAAAAAAAAAAAAAAAAAAAAAAA--- ---AAAAAAAAAAAAAAAAAAAAAAAA--- ---AAAAAAAAAAAAAAAAAAAAAAAA--- B--AAAAAAAAAAAAAAAAAAAAAAAA--B B--AAAAAAAAAAAAAAAAAAAAAAAA--B ---AAAAAAAAAAAAAAAAAAAAAAAA--- ---AAAAAAAAAAAAAAAAAAAAAAAA--- ---AAAAAAAAAAAAAAAAAAAAAAAA--- B--AAAAAAAAAAAAAAAAAAAAAAAA--B B--AAAAAAAAAAAAAAAAAAAAAAAA--B ---AAAAAAAAAAAAAAAAAAAAAAAA--- ---AAAAAAAAAAAAAAAAAAAAAAAA--- ---AAAAAAAAAAAAAAAAAAAAAAAA--- B--AAAAAAAAAAAAAAAAAAAAAAAA--B B--AAAAAAAAAAAAAAAAAAAAAAAA--B B--AAAAAAAAAAAAAAAAAAAAAAAA--B ---AAAAAAAAAAAAAAAAAAAAAAAA--- ---AAAAAAAAAAAAAAAAAAAAAAAA--- ------------------------------ B----------------------------B BBBBBBBBBBBBBBBBBBBBBBBBBBBBBB 
BBBBBBBBBBBBBBBBBBBBBBBBBBBBBB BBBBBBBBBBBBBBBBBBBBBBBBBBBBBB B------------------------AA--B B------------------------AA--B B------------------------AA--B B------------------------AA--B B------------------------AA--B B------------------------AA--B B------------------------AA--B B------------------------AA--B B------------------------AA--B B------------------------AA--B B------------------------AA--B B------------------------AA--B B----------------------------B B----------------------------B B----------------------------B B----------------------------B B----------------------------B B----------------------------B B----------------------------B B----------------------------B B----------------------------B B----------------------------B B----------------------------B B----------------------------B B----------------------------B B----------------------------B B----------------------------B BBBBBBBBBBBBBBBBBBBBBBBBBBBBBB 
BBBBBBBBBBBBBBBBBBBBBBBBBBBBBB BBBBBBBBBBBBBBBBBBBBBBBBBBBBBB BBBBBBBBBBBBBBBBBBBBBBBBBBBBBB BBBBBBBBBBBBBBBBBBBBBBBBBBBBBB BBBBBBBBBBBBBBBBBBBBBBBBBBBBBB BBBBBBBBBBBBBBBBBBBBBBBBBBBBBB BBBBBBBBBBBBBBBBBBBBBBBBBBBBBB BBBBBBBBBBBBBBBBBBBBBBBBBBBBBB BBBBBBBBBBBBBBBBBBBBBBBBBBBBBB BBBBBBBBBBBBBBBBBBBBBBBBBBBBBB BBBBBBBBBBBBBBBBBBBBBBBBBBBBBB BBBBBBBBBBBBBBBBBBBBBBBBBBBBBB BBBBBBBBBBBBBBBBBBBBBBBBBBBBBB BBBBBBBBBBBBBBBBBBBBBBBBBBBBBB BBBBBBBBBBBBBBBBBBBBBBBBBBBBBB BBBBBBBBBBBBBBBBBBBBBBBBBBBBBB BBBBBBBBBBBBBBBBBBBBBBBBBBBBBB BBBBBBBBBBBBBBBBBBBBBBBBBBBBBB BBBBBBBBBBBBBBBBBBBBBBBBBBBBBB BBBBBBBBBBBBBBBBBBBBBBBBBBBBBB BBBBBBBBBBBBBBBBBBBBBBBBBBBBBB BBBBBBBBBBBBBBBBBBBBBBBBBBBBBB BBBBBBBBBBBBBBBBBBBBBBBBBBBBBB BBBBBBBBBBBBBBBBBBBBBBBBBBBBBB BBBBBBBBBBBBBBBBBBBBBBBBBBBBBB BBBBBBBBBBBBBBBBBBBBBBBBBBBBBB BBBBBBBBBBBBBBBBBBBBBBBBBBBBBB BBBBBBBBBBBBBBBBBBBBBBBBBBBBBB BBBBBBBBBBBBBBBBBBBBBBBBBBBBBB BBBBBBBBBBBBBBBBBBBBBBBBBBBBBB 
