model
size = 11 14 22, scale = 0.05, origin = -y
material 
  colors = A:#331919 B:#EEE
voxels
----------- ----------- ----------- ---AAAAA--- --AAAAAAA-- -AAAAAAAAA- AAAAAAAAAAA AAAAAAAAAAA AAAAAAAAAAA AAAAAAAAAAA AAAAAAAAAAA -AAAAAAAAA- --AAAAAAA-- ---AAAAA--- 
----------- ----------- ----------- ----------- ----AAAAA-- ---AAAAAAA- --AAAAAAAAA --AAAAAAAAA --AAAA-AAAA --AAAAAAAAA --AAAAAAAAA ---AAAAAAA- ----AAAAA-- ----------- 
----------- ----------- ----------- ----------- ----------- ----AAA---- ---AAAAA--- --AAAAAAA-- --AAA-AAA-- --AAAAAAA-- ---AAAAA--- ----AAA---- ----------- ----------- 
----------- ----------- ----------- ----------- ----AAAAA-- ---AAAAAAA- --AAAAAAAAA --AAAAAAAAA --AAAA-AAAA --AAAAAAAAA --AAAAAAAAA ---AAAAAAA- ----AAAAA-- ----------- 
----------- ----------- ----------- ----------- ----------- ----AAA---- ---AAAAA--- --AAAAAAA-- --AAA-AAA-- --AAAAAAA-- ---AAAAA--- ----AAA---- ----------- ----------- 
----------- ----------- ----------- ----------- ----------- -----AAA--- ----AAAAA-- ---AAAAAAA- ---AAA-AAA- ---AAAAAAA- ----AAAAA-- -----AAA--- ----------- ----------- 
----------- ----------- ----------- ----------- -----AAA--- ----AAAAA-- ---AAAAAAA- ---AAA-AAA- ---AAAAAAA- ----AAAAA-- -----AAA--- ----------- ----------- ----------- 
----------- ----------- ----AAAAA-- ---AAAAAAA- --AAAAAAAAA --AAAAAAAAA --AAAA-AAAA --AAAAAAAAA --AAAAAAAAA ---AAAAAAA- ----AAAAA-- ----------- ----------- ----------- 
----------- ----AAAAA-- ---AAAAAAA- --AAAAAAAAA --AAAAAAAAA --AAAA-AAAA --AAAAAAAAA --AAAAAAAAA ---AAAAAAA- ----AAAAA-- ----------- ----------- ----------- ----------- 
----------- -----AAA--- ----AAAAA-- ---AAAAAAA- ---AAA-AAA- ---AAAAAAA- ----AAAAA-- -----AAA--- ----------- ----------- ----------- ----------- ----------- ----------- 
-----AAA--- ----AAAAA-- ---AAAAAAA- ---AAA-AAA- ---AAAAAAA- ----AAAAA-- -----AAA--- ----------- ----------- ----------- ----------- ----------- ----------- ----------- 
----------- -----AAA--- ----AAAAA-- ---AAAAAAA- ---AAA-AAA- ---AAAAAAA- ----AAAAA-- -----AAA--- ----------- ----------- ----------- ----------- ----------- ----------- 
----------- ----------- -----AAA--- ----AAAAA-- ---AAAAAAA- ---AAA-AAA- ---AAAAAAA- ----AAAAA-- -----AAA--- ----------- ----------- ----------- ----------- ----------- 
----------- ----------- ----------- -----AAA--- ----AAAAA-- ---AAAAAAA- ---AAA-AAA- ---AAAAAAA- ----AAAAA-- -----AAA--- ----------- ----------- ----------- ----------- 
----------- ----------- ----------- ----------- -----AAA--- ----AAAAA-- ---AAAAAAA- ---AAA-AAA- ---AAAAAAA- ----AAAAA-- -----AAA--- ----------- ----------- ----------- 
----------- ----------- ----------- ----------- ----------- ----------- -----AAA--- ----AAAAA-- ----AA-AA-- ----AAAAA-- -----AAA--- ----------- ----------- ----------- 
----------- ----------- ----------- ----------- ----------- ----------- ----------- -----AAA--- ----AAAAA-- ----AA-AA-- ----AAAAA-- -----AAA--- ----------- ----------- 
----------- ----------- ----------- ----------- ----------- ----------- ----------- ----------- ----------- -----AAA--- -----A-A--- -----AAA--- ----------- ----------- 
----------- ----------- ----------- ----------- ----------- ----------- ----------- ----------- -----AAA--- -----A-A--- -----AAA--- ----------- ----------- ----------- 
----------- ----------- -----BBB--- -----BBB--- -----BBB--- ----------- ----------- ----------- -----A-A--- -----AAA--- ----------- ----------- ----------- ----------- 
----------- ----------- ----------- ----------- -----BBB--- ----------- ----------- -----AAA--- -----AAA--- -----AAA--- -----AAA--- ------A---- ------B---- ------B---- 
----------- ----------- ----------- ----------- -----AAA--- -----AAA--- -----AAA--- -----AAA--- -----AAA--- -----AAA--- ----------- ----------- ----------- ------B---- 
