model
size = 30 16 31, scale = 0.05, origin = -y
material 
  colors = A:#888 B:#200 C:#FC3 D:#DDD E:#F93 F:#555
voxels
------------------------------ ------------------------------ ------------------------------ ------------------------------ ------------------------------ ------------------------------ ------------------------------ ------------------------------ ------------------------------ ------------------------------ ------------------------------ ------------------------------ A----------------------------- A----------------------------- A----------------------------- A----------------------------- 
------------------------------ ------------------------------ ------------------------------ ------------------------------ ------------------------------ ------------------------------ ------------------------------ ------------------------------ ------------------------------ ------------------------------ ------------------------------ ------------------------------ A----------------------------- A----------------------------- A----------------------------- A----------------------------- 
------------------------------ ------------------------------ ------------------------------ ------------------------------ ------------------------------ ------------------------------ ------------------------------ ------------------------------ ------------------------------ ------------------------------ ------------------------------ ------------------------------ AA---------------------------- AA---------------------------- AA---------------------------- AA---------------------------- 
------------------------------ ------------------------------ ------------------------------ ------------------------------ ------------------------------ ------------------------------ ------------------------------ ------------------------------ ------------------------------ ------------------------------ ------------------------------ ------------------------------ AA---------------------------- AA---------------------------- AA---------------------------- AA---------------------------- 
------------------------------ ------------------------------ ------------------------------ ------------------------------ ------------------------------ ------------------------------ ------------------------------ ------------------------------ ------------------------------ ------------------------------ ------------------------------ ------------------------------ AA---------------------------- AA---------------------------- AA---------------------------- AA---------------------------- 
------------------------------ ------------------------------ ------------------------------ ------------------------------ ------------------------------ ------------------------------ ------------------------------ ------------------------------ ------------------------------ ------------------------------ ------------------------------ ------------------------------ AA---------------------------- AA---------------------------- AA---------------------------- AA---------------------------- 
------------------------------ ------------------------------ ------------------------------ ------------------------------ ------------------------------ ------------------------------ ------------------------------ ------------------------------ ------------------------------ ------------------------------ ------------------------------ ------------------------------ AA---------------------------- AA---------------------------- AA---------------------------- AA---------------------------- 
------------------------------ ------------------------------ ------------------------------ ------------------------------ ------------------------------ ------------------------------ ------------------------------ ------------------------------ ------------------------------ ------------------------------ ------------------------------ ------------------------------ AA---------------------------- AA---------------------------- AA---------------------------- AA---------------------------- 
------------------------------ ------------------------------ ------------------------------ ------------------------------ ------------------------------ ------------------------------ ------------------------------ ------------------------------ ------------------------------ ------------------------------ ------------------------------ ------------------------------ AA---------------------------- AA---------------------------- AA---------------------------- AA---------------------------- 
------------------------------ ------------------------------ ------------------------------ ------------------------------ ------------------------------ ------------------------------ ------------------------------ ------------------------------ ------------------------------ ------------------------------ ------------------------------ ------------------------------ -A---------------------------- -A---------------------------- -A---------------------------- -A---------------------------- 
------------------------------ ------------------------------ ------------------------------ ------------------------------ ------------------------------ ------------------------------ ------------------------------ ------------------------------ ------------------------------ ------------------------------ ------------------------------ ------------------------------ -AA--------------------------- -AA--------------------------- -AA--------------------------- -AA--------------------------- 
------------------------------ ------------------------------ ------------------------------ ------------------------------ ------------------------------ ------------------------------ ------------------------------ ------------------------------ ------------------------------ ------------------------------ ------------------------------ ------------------------------ -AA--------------------------- -AA--------------------------- -AA--------------------------- -AA--------------------------- 
------------------------------ ------------------------------ ------------------------------ ------------------------------ ------------------------------ ------------------------------ ------------------------------ ------------------------------ ------------------------------ ------------------------------ ------------------------------ ------------------------------ -AA--------------------------- -AA--------------------------- -AA--------------------------- -AA--------------------------- 
------------------------------ ------------------------------ ------------------------------ ------------------------------ ------------------------------ ------------------------------ ------------------------------ ------------------------------ ------------------------------ ------------------------------ ------------------------------ ------------------------------ -AA--------------------------- -AA--------------------------- -AA--------------------------- -AA--------------------------- 
------------------------------ ------------------------------ ------------------------------ ------------------------------ ------------------------------ ------------------------------ ------------------------------ ------------------------------ ------------------------------ ------------------------------ ------------------------------ ------------------------------ --AA-------------------------- --AA-------------------------- --AA-------------------------- --AA-------------------------- 
------------------------------ ------------------------------ ------------------------------ ------------------------------ ------------------------------ ------------------------------ ------------------------------ ------------------------------ ------------------------------ ------------------------------ ------------------------------ ------------------------------ --AA-------------------------- --AA-------------------------- --AA-------------------------- --AA-------------------------- 
------------------------------ ------------------------------ ------------------------------ ------------------------------ ------------------------------ ------------------------------ ------------------------------ ------------------------------ ------------------------------ ------------------------------ ------------------------------ ------------------------------ --AA-------------------------- --AA-------------------------- --AA-------------------------- --AA-------------------------- 
------------------------------ ------------------------------ ------------------------------ ------------------------------ ------------------------------ ------------------------------ ------------------------------ ------------------------------ ------------------------------ ------------------------------ ------------------------------ ------------------------------ --AA-------------------------- --AA-------------------------- --AA-------------------------- --AA-------------------------- 
------------------------------ ------------------------------ ------------------------------ ------------------------------ ------------------------------ ------------------------------ ------------------------------ ------------------------------ ------------------------------ ------------------------------ ------------------------------ ------------------------------ --AA-------------------------- --AA-------------------------- --AA-------------------------- --AA-------------------------- 
------------------------------ ------------------------------ ------------------------------ ------------------------------ ------------------------------ ------------------------------ ------------------------------ ------------------------------ ------------------------------ ------------------------------ ------------------------------ ------------------------------ --AA-------------------------- --AA-------------------------- --AA-------------------------- --AA-------------------------- 
------------------------------ ------------------------------ ------------------------------ ------------------------------ ------------------------------ ------------------------------ ------------------------------ ------------------------------ ------------------------------ ------------------------------ ------------------------------ ------------------------------ --AA-------------------------- --AA-------------------------- --AA-------------------------- --AA-------------------------- 
------------------------------ ------------------------------ ------------------------------ ------------------------------ ------------------------------ ------------------------------ ------------------------------ ------------------------------ ------------------------------ ------------------------------ ------------------------------ ------------------------------ --AA-------------------------- --AA-------------------------- --AA-------------------------- --AA-------------------------- 
------------------------------ ------------------------------ ------------------------------ ------------------------------ ------------------------------ ------------------------------ ------------------------------ ------------------------------ ------------------------------ ------------------------------ ------------------------------ ------------------------------ --AA-------------------------- --AA-------------------------- --AA-------------------------- --AA-------------------------- 
------------------------------ ------------------------------ ------------------------------ ------------------------------ ------------------------------ ------------------------------ ------------------------------ ------------------------------ ------------------------------ ------------------------------ ------------------------------ ------------------------------ --AA-------------------------- --AA-------------------------- --AA-------------------------- --AA-------------------------- 
------------------------------ ------------------------------ ------------------------------ ------------------------------ ------------------------------ ------------------------------ ------------------------------ ------------------------------ ------------------------------ ------------------------------ ------------------------------ ------------------------------ --AA-------------------------- --AA-------------------------- --AA-------------------------- --AA-------------------------- 
------------------------------ ------------------------------ ------------------------------ ------------------------------ ------------------------------ ------------------------------ ------------------------------ ------------------------------ ------------------------------ ------------------------------ ------------------------------ ------------------------------ --AA-------------------------- --AA-------------------------- --AA-------------------------- --AA-------------------------- 
------------------------------ ------------------------------ ------------------------------ ------------------------------ ------------------------------ ------------------------------ ------------------------------ ------------------------------ ------------------------------ ------------------------------ ------------------------------ ------------------------------ --AA-------------------------- --AA-------------------------- --AA-------------------------- --AA-------------------------- 
------------------------------ ------------------------------ ------------------------------ ------------------------------ ------------------------------ ------------------------------ ------------------------------ ------------------------------ ------------------------------ ------------------------------ ------------------------------ ------------------------------ --AA-------------------------- --CC-------------------------- --CC-------------------------- --AA-------------------------- 
------------------------------ ------------------------------ ------------------------------ ------------------------------ ------------------------------ ------------------------------ ------------------------------ ------------------------------ ------------------------------ ------------------------------ ------------------------------ ------------------------------ --AA-------------------------- --CAC------------------------- --CCC------------------------- --AA-------------------------- 
-------------AAAAAAAA--------- ----------AAAAAAAAAAAAA------- ---------AAAAAAAAAAAAAAA------ ---------AAAAAAAAAAAAAAA------ --------AAAA----------AAA----- --------AAA------------AAA---- --------AA-------------AAA---- --------AA-------------AAA---- --------AA--------------AA---- --------AA--------------AA---- --------AA--------------AAA--- --------AA--------------AAAA-- --CACCAAAAAA------------AAAAAA --CACCAAAAAA------------AAAAAA --CCCCAAAAAAAAAAAAAAAAAAAA---- --CCECAAAAAAAAAAAAAAAAAAAA---- 
------------------------------ -----------AAAAAAAAAAA-------- ----------AAAAAAAAAAAAA------- ---------AAABBBBBBBBBAAA------ ---------AABBBBBBBDDBBAAA----- --------AAABBBBBBBBBDBBAAA---- --------AABBBBBBBBBBBDBAAA---- --------AABBBBBBBBBBBBBBAA---- --------AABBBBBBBBBBBBBBAA---- --------AABBBBBBBBBBBBBBAA---- --------AABBBBBBBBBBBBBBAA---- --------AABBDBBBBBBBBBBBAA---- --CCECAAAABBFDDBBBBBBBBBAAAAAA --CCCCAAAABBBBBBBBBBBBBBAAAAAA --CCCCAAAAAAAAAAAAAAAAAAAA---- --CCECAAAAAAAAAAAAAAAAAAAA---- 
