model
size = 29 16 31, scale = 0.05, origin = -y
material 
  colors = A:#222 B:#200 C:#FC3 D:#BBB E:#F93 F:#DDD G:#555
voxels
----------------------------- ----------------------------- ----------------------------- ----------------------------- ----------------------------- ----------------------------- ----------------------------- ----------------------------- ----------------------------- ----------------------------- ----------------------------- ----------------------------- ----------------------------A ----------------------------A ----------------------------A ----------------------------A 
----------------------------- ----------------------------- ----------------------------- ----------------------------- ----------------------------- ----------------------------- ----------------------------- ----------------------------- ----------------------------- ----------------------------- ----------------------------- ----------------------------- ----------------------------A ----------------------------A ----------------------------A ----------------------------A 
----------------------------- ----------------------------- ----------------------------- ----------------------------- ----------------------------- ----------------------------- ----------------------------- ----------------------------- ----------------------------- ----------------------------- ----------------------------- ----------------------------- ---------------------------AA ---------------------------AA ---------------------------AA ---------------------------AA 
----------------------------- ----------------------------- ----------------------------- ----------------------------- ----------------------------- ----------------------------- ----------------------------- ----------------------------- ----------------------------- ----------------------------- ----------------------------- ----------------------------- ---------------------------AA ---------------------------AA ---------------------------AA ---------------------------AA 
----------------------------- ----------------------------- ----------------------------- ----------------------------- ----------------------------- ----------------------------- ----------------------------- ----------------------------- ----------------------------- ----------------------------- ----------------------------- ----------------------------- ---------------------------AA ---------------------------AA ---------------------------AA ---------------------------AA 
----------------------------- ----------------------------- ----------------------------- ----------------------------- ----------------------------- ----------------------------- ----------------------------- ----------------------------- ----------------------------- ----------------------------- ----------------------------- ----------------------------- ---------------------------AA ---------------------------AA ---------------------------AA ---------------------------AA 
----------------------------- ----------------------------- ----------------------------- ----------------------------- ----------------------------- ----------------------------- ----------------------------- ----------------------------- ----------------------------- ----------------------------- ----------------------------- ----------------------------- ---------------------------AA ---------------------------AA ---------------------------AA ---------------------------AA 
----------------------------- ----------------------------- ----------------------------- ----------------------------- ----------------------------- ----------------------------- ----------------------------- ----------------------------- ----------------------------- ----------------------------- ----------------------------- ----------------------------- ---------------------------AA ---------------------------AA ---------------------------AA ---------------------------AA 
----------------------------- ----------------------------- ----------------------------- ----------------------------- ----------------------------- ----------------------------- ----------------------------- ----------------------------- ----------------------------- ----------------------------- ----------------------------- ----------------------------- ---------------------------AA ---------------------------AA ---------------------------AA ---------------------------AA 
----------------------------- ----------------------------- ----------------------------- ----------------------------- ----------------------------- ----------------------------- ----------------------------- ----------------------------- ----------------------------- ----------------------------- ----------------------------- ----------------------------- ---------------------------A- ---------------------------A- ---------------------------A- ---------------------------A- 
----------------------------- ----------------------------- ----------------------------- ----------------------------- ----------------------------- ----------------------------- ----------------------------- ----------------------------- ----------------------------- ----------------------------- ----------------------------- ----------------------------- --------------------------AA- --------------------------AA- --------------------------AA- --------------------------AA- 
----------------------------- ----------------------------- ----------------------------- ----------------------------- ----------------------------- ----------------------------- ----------------------------- ----------------------------- ----------------------------- ----------------------------- ----------------------------- ----------------------------- --------------------------AA- --------------------------AA- --------------------------AA- --------------------------AA- 
----------------------------- ----------------------------- ----------------------------- ----------------------------- ----------------------------- ----------------------------- ----------------------------- ----------------------------- ----------------------------- ----------------------------- ----------------------------- ----------------------------- --------------------------AA- --------------------------AA- --------------------------AA- --------------------------AA- 
----------------------------- ----------------------------- ----------------------------- ----------------------------- ----------------------------- ----------------------------- ----------------------------- ----------------------------- ----------------------------- ----------------------------- ----------------------------- ----------------------------- --------------------------A-- --------------------------A-- --------------------------A-- --------------------------A-- 
----------------------------- ----------------------------- ----------------------------- ----------------------------- ----------------------------- ----------------------------- ----------------------------- ----------------------------- ----------------------------- ----------------------------- ----------------------------- ----------------------------- -------------------------AA-- -------------------------AA-- -------------------------AA-- -------------------------AA-- 
----------------------------- ----------------------------- ----------------------------- ----------------------------- ----------------------------- ----------------------------- ----------------------------- ----------------------------- ----------------------------- ----------------------------- ----------------------------- ----------------------------- -------------------------AA-- -------------------------AA-- -------------------------AA-- -------------------------AA-- 
----------------------------- ----------------------------- ----------------------------- ----------------------------- ----------------------------- ----------------------------- ----------------------------- ----------------------------- ----------------------------- ----------------------------- ----------------------------- ----------------------------- -------------------------AA-- -------------------------AA-- -------------------------AA-- -------------------------AA-- 
----------------------------- ----------------------------- ----------------------------- ----------------------------- ----------------------------- ----------------------------- ----------------------------- ----------------------------- ----------------------------- ----------------------------- ----------------------------- ----------------------------- -------------------------AA-- -------------------------AA-- -------------------------AA-- -------------------------AA-- 
----------------------------- ----------------------------- ----------------------------- ----------------------------- ----------------------------- ----------------------------- ----------------------------- ----------------------------- ----------------------------- ----------------------------- ----------------------------- ----------------------------- -------------------------AA-- -------------------------AA-- -------------------------AA-- -------------------------AA-- 
----------------------------- ----------------------------- ----------------------------- ----------------------------- ----------------------------- ----------------------------- ----------------------------- ----------------------------- ----------------------------- ----------------------------- ----------------------------- ----------------------------- -------------------------AA-- -------------------------AA-- -------------------------AA-- -------------------------AA-- 
----------------------------- ----------------------------- ----------------------------- ----------------------------- ----------------------------- ----------------------------- ----------------------------- ----------------------------- ----------------------------- ----------------------------- ----------------------------- ----------------------------- -------------------------AA-- -------------------------AA-- -------------------------AA-- -------------------------AA-- 
----------------------------- ----------------------------- ----------------------------- ----------------------------- ----------------------------- ----------------------------- ----------------------------- ----------------------------- ----------------------------- ----------------------------- ----------------------------- ----------------------------- -------------------------AA-- -------------------------AA-- -------------------------AA-- -------------------------AA-- 
----------------------------- ----------------------------- ----------------------------- ----------------------------- ----------------------------- ----------------------------- ----------------------------- ----------------------------- ----------------------------- ----------------------------- ----------------------------- ----------------------------- -------------------------AA-- -------------------------AA-- -------------------------AA-- -------------------------AA-- 
----------------------------- ----------------------------- ----------------------------- ----------------------------- ----------------------------- ----------------------------- ----------------------------- ----------------------------- ----------------------------- ----------------------------- ----------------------------- ----------------------------- -------------------------AA-- -------------------------AA-- -------------------------AA-- -------------------------AA-- 
----------------------------- ----------------------------- ----------------------------- ----------------------------- ----------------------------- ----------------------------- ----------------------------- ----------------------------- ----------------------------- ----------------------------- ----------------------------- ----------------------------- -------------------------AA-- -------------------------AA-- -------------------------AA-- -------------------------AA-- 
----------------------------- ----------------------------- ----------------------------- ----------------------------- ----------------------------- ----------------------------- ----------------------------- ----------------------------- ----------------------------- ----------------------------- ----------------------------- ----------------------------- -------------------------AA-- -------------------------AA-- -------------------------AA-- -------------------------AA-- 
----------------------------- ----------------------------- ----------------------------- ----------------------------- ----------------------------- ----------------------------- ----------------------------- ----------------------------- ----------------------------- ----------------------------- ----------------------------- ----------------------------- -------------------------AA-- -------------------------AA-- -------------------------AA-- -------------------------AA-- 
----------------------------- ----------------------------- ----------------------------- ----------------------------- ----------------------------- ----------------------------- ----------------------------- ----------------------------- ----------------------------- ----------------------------- ----------------------------- ----------------------------- -------------------------AA-- -------------------------CC-- -------------------------CC-- -------------------------AA-- 
----------------------------- ----------------------------- ----------------------------- ----------------------------- ----------------------------- ----------------------------- ----------------------------- ----------------------------- ----------------------------- ----------------------------- ----------------------------- ----------------------------- -------------------------AA-- ------------------------CAC-- ------------------------CCC-- -------------------------AA-- 
--------AAAAAAAA------------- ------AAAAAAAAAAAAA---------- -----AAAAAAAAAAAAAAA--------- -----AAAA------AAAAA--------- ----AAA----------AAAA-------- ---AAA-----------AAAA-------- ---AAA-------------AA-------- ---AAA-------------AA-------- ---AA--------------AA-------- ---AA--------------AA-------- --AAA--------------AA-------- -AAAA--------------AA-------- AAAAA------------AAAAAACCAC-- AAAAA------------AAAAAACCAC-- ---AAAAAAAAAAAAAAAAAAAACCCC-- ---AAAAAAAAAAAAAAAAAAAACECC-- 
----------------------------- -------AAAAAAAAAAA----------- ------AAAAAAAAAAAAA---------- -----AAABBBBBBBBBAAA--------- ----AAABBBBBBBDDBBAA--------- ---AAABBBBBBBBBBDBAAA-------- ---AAABBBBBBBBBBBDBAA-------- ---AABBBBBBBBBBBBBBAA-------- ---AABBBBBBBBBBBBBBAA-------- ---AABBBBBBBBBBBBBBAA-------- ---AABBBBBBBBBBBBBBAA-------- ---AABBFBBBBBBBBBBBAA-------- AAAAABBGDFBBBBBBBBBAAAACECC-- AAAAABBBBBBBBBBBBBBAAAACCCC-- ---AAAAAAAAAAAAAAAAAAAACCCC-- ---AAAAAAAAAAAAAAAAAAAACECC-- 
