model
size = 16 28 29, scale = 0.05, origin = -y
material 
  colors = A:#630 B:#111 C:#0F0 D:#FF0
voxels
---------------- ---------------- ---------------- ---------------- ----AA---------- ----AA---------- ----AA---------- ----AA---------- ---------------- ---------------- ---------------- ---------------- ---------------- ---------------- ---------------- ---------------- ---------------- ---------------- ---------------- ---------------- ---------------- ---------------- ---------------- ---------------- ---------------- ---------------- ---------------- ---------------- 
---------------- ---------------- ----AA---------- ---AAA---------- --AAAA---------- --AAAA---------- --AAAA---------- --AAAA---------- ---AAA---------- ----AA---------- ---------------- ---------------- ---------------- ---------------- ---------------- ---------------- ---------------- ---------------- ---------------- ---------------- ---------------- ---------------- ---------------- ---------------- ---------------- ---------------- ---------------- ---------------- 
---------------- ----AA---------- ---AAA---------- --AAAA---------- -AAAAA---------- -AAAAA---------- -AAAAA---------- -AAAAA---------- --AAAA---------- ---AAA---------- ----AA---------- ---------------- ---------------- ---------------- ---------------- ---------------- ---------------- ---------------- ---------------- ---------------- ---------------- ---------------- ---------------- ---------------- ---------------- ---------------- ---------------- ---------------- 
---------------- ---AAA---------- --AAAA---------- -AAAAA---------- -AAAAA---------- -AAAAA---------- -AAAAA---------- -AAAAA---------- -AAAAA---------- --AAAA---------- ---AAA---------- ---------------- ---------------- ---------------- ---------------- ---------------- ---------------- ---------------- ---------------- ---------------- ---------------- ---------------- ---------------- ---------------- ---------------- ---------------- ---------------- ---------------- 
----AA---------- --AAAA---------- -AAAAA---------- -AAAAA---------- AAAAAA---------- AAAAAA---------- AAAAAA---------- AAAAAA---------- -AAAAA---------- -AAAAA---------- --AAAA---------- ----AA---------- ---------------- ---------------- ---------------- ---------------- ---------------- ---------------- ---------------- ---------------- ---------------- ---------------- ---------------- ---------------- ---------------- ---------------- ---------------- ---------------- 
----AA---------- --AAAA---------- -AAAAA---------- -AAAAA---------- AAAAAA---------- AAAAAA---------- AAAAAA---------- AAAAAA---------- -AAAAA---------- -AAAAA---------- --AAAA---------- ----AA---------- -----B---------- -----B---------- -----BB--------- ------BB-------- -------BB------- --------BB------ ---------BB----- ----------BB---- -----------B---- ---------------- ---------------- ---------------- ---------------- ---------------- ---------------- ---------------- 
----AA---------- --AAAA---------- -AAAAA---------- -AAAAA---------- AAAAAA---------- AAAAAA---------- AAAAAA---------- AAAAAA---------- -AAAAA---------- -AAAAA---------- --AAAA---------- ----AA---------- -----B---------- -----B---------- -----BB--------- ------BB-------- -------BB------- --------BB------ ---------BB----- ----------BB---- -----------B---- ---------------- ---------------- ---------------- ---------------- ---------------- ---------------- ---------------- 
----AA---------- --AAAA---------- -AAAAA---------- -AAAAA---------- AAAAAA---------- AAAAAA---------- AAAAAA---------- AAAAAA---------- -AAAAA---------- -AAAAA---------- --AAAA---------- ----AA---------- ---------------- ---------------- ---------------- ---------------- ---------------- ---------------- ---------------- ---------------- -----------BB--- ------------BB-- ---------------- ---------------- ---------------- ---------------- ---------------- ---------------- 
---------------- ---AAA---------- --AAAA---------- -AAAAA---------- -AAAAA---------- -AAAAA---------- -AAAAA---------- -AAAAA---------- -AAAAA---------- --AAAA---------- ---AAA---------- ---------------- ---------------- ---------------- ---------------- ---------------- ---------------- ---------------- ---------------- ---------------- ---------------- -------------B-- -------------BB- --------------B- ---------------- ---------------- ---------------- ---------------- 
---------------- ----AA---------- ---AAA---------- --AAAA---------- -AAAAA---------- -AAAAA---------- -AAAAA---------- -AAAAA---------- --AAAA---------- ---AAA---------- ----AA---------- ---------------- ---------------- ---------------- ---------------- ---------------- ---------------- ---------------- ---------------- ---------------- ---------------- ---------------- ---------------- --------------B- --------------B- ---------------- ---------------- ---------------- 
---------------- ---------------- ----AA---------- ---AAA---------- --AAAA---------- --AAAA---------- --AAAA---------- --AAAA---------- ---AAA---------- ----AA---------- ---------------- ---------------- ---------------- ---------------- ---------------- ---------------- ---------------- ---------------- ---------------- ---------------- ---------------- ---------------- ---------------- ---------------- --------------B- --------------B- ---------------- ---------------- 
---------------- ---------------- ---------------- ---------------- ----AA---------- ----AA---------- ----AA---------- ----AA---------- ---------------- ---------------- ---------------- ---------------- ---------------- ---------------- ---------------- ---------------- ---------------- ---------------- ---------------- ---------------- ---------------- ---------------- ---------------- ---------------- ---------------- --------------B- --------------B- --------------D- 
---------------- ---------------- ---------------- ---------------- ---------------- -----C---------- -----C---------- ---------------- ---------------- ---------------- ---------------- ---------------- ---------------- ---------------- ---------------- ---------------- ---------------- ---------------- ---------------- ---------------- ---------------- ---------------- ---------------- ---------------- ---------------- ---------------- --------------B- -------------DBD 
---------------- ---------------- ---------------- ---------------- ---------------- -----C---------- -----C---------- ---------------- ---------------- ---------------- ---------------- ---------------- ---------------- ---------------- ---------------- ---------------- ---------------- ---------------- ---------------- ---------------- ---------------- ---------------- ---------------- ---------------- ---------------- ---------------- ---------------- -------------DBD 
---------------- ---------------- ---------------- ---------------- ---------------- -----C---------- -----C---------- ---------------- ---------------- ---------------- ---------------- ---------------- ---------------- ---------------- ---------------- ---------------- ---------------- ---------------- ---------------- ---------------- ---------------- ---------------- ---------------- ---------------- ---------------- ---------------- -------------B-- ------------DBD- 
---------------- ---------------- ---------------- ---------------- ---------------- -----C---------- -----C---------- ---------------- ---------------- ---------------- ---------------- ---------------- ---------------- ---------------- ---------------- ---------------- ---------------- ---------------- ---------------- ---------------- ---------------- ---------------- ---------------- ---------------- ---------------- -------------B-- -------------B-- -------------D-- 
---------------- ---------------- ---------------- ---------------- ---------------- -----C---------- -----C---------- ---------------- ---------------- ---------------- ---------------- ---------------- ---------------- ---------------- ---------------- ---------------- ---------------- ---------------- ---------------- ---------------- ---------------- ---------------- ---------------- ---------------- -------------B-- -------------B-- ---------------- ---------------- 
---------------- ---------------- ---------------- ---------------- ----AA---------- ----AA---------- ----AA---------- ----AA---------- ---------------- ---------------- ---------------- ---------------- ---------------- ---------------- ---------------- ---------------- ---------------- ---------------- ---------------- ---------------- ---------------- ---------------- ---------------- -------------B-- -------------B-- ---------------- ---------------- ---------------- 
---------------- ---------------- ----AA---------- ---AAA---------- --AAAA---------- --AAAA---------- --AAAA---------- --AAAA---------- ---AAA---------- ----AA---------- ---------------- ---------------- ---------------- ---------------- ---------------- ---------------- ---------------- ---------------- ---------------- ---------------- ---------------- ---------------- -------------B-- -------------B-- ---------------- ---------------- ---------------- ---------------- 
---------------- ----AA---------- ---AAA---------- --AAAA---------- -AAAAA---------- -AAAAA---------- -AAAAA---------- -AAAAA---------- --AAAA---------- ---AAA---------- ----AA---------- ---------------- ---------------- ---------------- ---------------- ---------------- ---------------- ---------------- ---------------- ---------------- ---------------- -------------B-- -------------B-- ---------------- ---------------- ---------------- ---------------- ---------------- 
---------------- ---AAA---------- --AAAA---------- -AAAAA---------- -AAAAA---------- -AAAAA---------- -AAAAA---------- -AAAAA---------- -AAAAA---------- --AAAA---------- ---AAA---------- ---------------- ---------------- ---------------- ---------------- ---------------- ---------------- ---------------- ---------------- ---------------- ---------------- ------------BB-- ---------------- ---------------- ---------------- ---------------- ---------------- ---------------- 
----AA---------- --AAAA---------- -AAAAA---------- -AAAAA---------- AAAAAA---------- AAAAAA---------- AAAAAA---------- AAAAAA---------- -AAAAA---------- -AAAAA---------- --AAAA---------- ----AA---------- ---------------- ---------------- ---------------- ---------------- ---------------- ---------------- ---------------- ---------------- -----------BB--- ------------B--- ---------------- ---------------- ---------------- ---------------- ---------------- ---------------- 
----AA---------- --AAAA---------- -AAAAA---------- -AAAAA---------- AAAAAA---------- AAAAAA---------- AAAAAA---------- AAAAAA---------- -AAAAA---------- -AAAAA---------- --AAAA---------- ----AA---------- -----B---------- -----B---------- -----BB--------- ------BB-------- -------BB------- --------BB------ ---------BB----- ----------BB---- -----------B---- ---------------- ---------------- ---------------- ---------------- ---------------- ---------------- ---------------- 
----AA---------- --AAAA---------- -AAAAA---------- -AAAAA---------- AAAAAA---------- AAAAAA---------- AAAAAA---------- AAAAAA---------- -AAAAA---------- -AAAAA---------- --AAAA---------- ----AA---------- -----B---------- -----B---------- -----BB--------- ------BB-------- -------BB------- --------BB------ ---------BB----- ----------BB---- -----------B---- ---------------- ---------------- ---------------- ---------------- ---------------- ---------------- ---------------- 
----AA---------- --AAAA---------- -AAAAA---------- -AAAAA---------- AAAAAA---------- AAAAAA---------- AAAAAA---------- AAAAAA---------- -AAAAA---------- -AAAAA---------- --AAAA---------- ----AA---------- ---------------- ---------------- ---------------- ---------------- ---------------- ---------------- ---------------- ---------------- ---------------- ---------------- ---------------- ---------------- ---------------- ---------------- ---------------- ---------------- 
---------------- ---AAA---------- --AAAA---------- -AAAAA---------- -AAAAA---------- -AAAAA---------- -AAAAA---------- -AAAAA---------- -AAAAA---------- --AAAA---------- ---AAA---------- ---------------- ---------------- ---------------- ---------------- ---------------- ---------------- ---------------- ---------------- ---------------- ---------------- ---------------- ---------------- ---------------- ---------------- ---------------- ---------------- ---------------- 
---------------- ----AA---------- ---AAA---------- --AAAA---------- -AAAAA---------- -AAAAA---------- -AAAAA---------- -AAAAA---------- --AAAA---------- ---AAA---------- ----AA---------- ---------------- ---------------- ---------------- ---------------- ---------------- ---------------- ---------------- ---------------- ---------------- ---------------- ---------------- ---------------- ---------------- ---------------- ---------------- ---------------- ---------------- 
---------------- ---------------- ----AA---------- ---AAA---------- --AAAA---------- --AAAA---------- --AAAA---------- --AAAA---------- ---AAA---------- ----AA---------- ---------------- ---------------- ---------------- ---------------- ---------------- ---------------- ---------------- ---------------- ---------------- ---------------- ---------------- ---------------- ---------------- ---------------- ---------------- ---------------- ---------------- ---------------- 
---------------- ---------------- ---------------- ---------------- ----AA---------- ----AA---------- ----AA---------- ----AA---------- ---------------- ---------------- ---------------- ---------------- ---------------- ---------------- ---------------- ---------------- ---------------- ---------------- ---------------- ---------------- ---------------- ---------------- ---------------- ---------------- ---------------- ---------------- ---------------- ---------------- 
