model
size = 15 29 29, scale = 0.05, origin = -y
material 
  colors = A:#E00 B:#0A0 C:#930
voxels
--------------- --------------- --------------- --------------- ----AAAA------- ----AAAA------- ----AAAA------- ----AAAA------- --------------- --------------- --------------- --------------- --------------- --------------- --------------- --------------- --------------- --------------- --------------- --------------- --------------- --------------- --------------- --------------- --------------- --------------- --------------- --------------- --------------- 
--------------- --------------- ----AAAA------- ---AAAAAA------ --AAAAAAAA----- --AAAAAAAA----- --AAAAAAAA----- --AAAAAAAA----- ---AAAAAA------ ----AAAA------- --------------- --------------- --------------- --------------- --------------- --------------- --------------- --------------- --------------- --------------- --------------- --------------- --------------- --------------- --------------- --------------- --------------- --------------- --------------- 
--------------- ----AAAA------- ---AAAAAA------ --AAAAAAAA----- -AAAAAAAAAA---- -AAAAAAAAAA---- -AAAAAAAAAA---- -AAAAAAAAAA---- --AAAAAAAA----- ---AAAAAA------ ----AAAA------- --------------- --------------- --------------- --------------- --------------- --------------- --------------- --------------- --------------- --------------- --------------- --------------- --------------- --------------- --------------- --------------- --------------- --------------- 
--------------- ---AAAAAA------ --AAAAAAAA----- -AAAAAAAAAA---- -AAAAAAAAAA---- -AAAAAAAAAA---- -AAAAAAAAAA---- -AAAAAAAAAA---- -AAAAAAAAAA---- --AAAAAAAA----- ---AAAAAA------ --------------- --------------- --------------- --------------- --------------- --------------- --------------- --------------- --------------- --------------- --------------- --------------- --------------- --------------- --------------- --------------- --------------- --------------- 
----AAAA------- --AAAAAAAA----- -AAAAAAAAAA---- -AAAAAAAAAA---- AAAAAAAAAAAA--- AAAAAAAAAAAA--- AAAAAAAAAAAA--- AAAAAAAAAAAA--- -AAAAAAAAAA---- -AAAAAAAAAA---- --AAAAAAAA----- ----AAAA------- --------------- --------------- --------------- --------------- --------------- --------------- --------------- --------------- --------------- --------------- --------------- --------------- --------------- --------------- --------------- --------------- --------------- 
----AAAA------- --AAAAAAAA----- -AAAAAAAAAA---- -AAAAAAAAAA---- AAAAAAAAAAAA--- AAAAAAAAAAAA--- AAAAAAAAAAAA--- AAAAAAAAAAAA--- -AAAAAAAAAA---- -AAAAAAAAAA---- --AAAAAAAA----- ----AAAA------- -----B--------- -----B--------- -----BB-------- ------BB------- -------BB------ --------BB----- ---------BB---- ----------BB--- -----------B--- --------------- --------------- --------------- --------------- --------------- --------------- --------------- --------------- 
----AAAA------- --AAAAAAAA----- -AAAAAAAAAA---- -AAAAAAAAAA---- AAAAAAAAAAAA--- AAAAAAAAAAAA--- AAAAAAAAAAAA--- AAAAAAAAAAAA--- -AAAAAAAAAA---- -AAAAAAAAAA---- --AAAAAAAA----- ----AAAA------- -----B--------- -----B--------- -----BB-------- ------BB------- -------BB------ --------BB----- ---------BB---- ----------BB--- -----------B--- --------------- --------------- --------------- --------------- --------------- --------------- --------------- --------------- 
----AAAA------- --AAAAAAAA----- -AAAAAAAAAA---- -AAAAAAAAAA---- AAAAAAAAAAAA--- AAAAAAAAAAAA--- AAAAAAAAAAAA--- AAAAAAAAAAAA--- -AAAAAAAAAA---- -AAAAAAAAAA---- --AAAAAAAA----- ----AAAA------- --------------- --------------- --------------- --------------- --------------- --------------- --------------- --------------- -----------BB-- ------------BB- --------------- --------------- --------------- --------------- --------------- --------------- --------------- 
--------------- ---AAAAAA------ --AAAAAAAA----- -AAAAAAAAAA---- -AAAAAAAAAA---- -AAAAAAAAAA---- -AAAAAAAAAA---- -AAAAAAAAAA---- -AAAAAAAAAA---- --AAAAAAAA----- ---AAAAAA------ --------------- --------------- --------------- --------------- --------------- --------------- --------------- --------------- --------------- --------------- -------------B- -------------BB --------------B --------------- --------------- --------------- --------------- --------------- 
--------------- ----AAAA------- ---AAAAAA------ --AAAAAAAA----- -AAAAAAAAAA---- -AAAAAAAAAA---- -AAAAAAAAAA---- -AAAAAAAAAA---- --AAAAAAAA----- ---AAAAAA------ ----AAAA------- --------------- --------------- --------------- --------------- --------------- --------------- --------------- --------------- --------------- --------------- --------------- --------------- --------------B --------------B --------------- --------------- --------------- --------------- 
--------------- --------------- ----AAAA------- ---AAAAAA------ --AAAAAAAA----- --AAAAAAAA----- --AAAAAAAA----- --AAAAAAAA----- ---AAAAAA------ ----AAAA------- --------------- --------------- --------------- --------------- --------------- --------------- --------------- --------------- --------------- --------------- --------------- --------------- --------------- --------------- --------------B --------------B --------------- --------------- --------------- 
--------------- --------------- --------------- --------------- ----AAAA------- ----AAAA------- ----AAAA------- ----AAAA------- --------------- --------------- --------------- --------------- --------------- --------------- --------------- --------------- --------------- --------------- --------------- --------------- --------------- --------------- --------------- --------------- --------------- --------------B --------------B --------------- --------------- 
--------------- --------------- --------------- --------------- --------------- --------------- --------------- --------------- --------------- --------------- --------------- --------------- --------------- --------------- --------------- --------------- --------------- --------------- --------------- --------------- --------------- --------------- --------------- --------------- --------------- --------------- --------------B -------------CB -------------CC 
--------------- --------------- --------------- --------------- --------------- --------------- --------------- --------------- --------------- --------------- --------------- --------------- --------------- --------------- --------------- --------------- --------------- --------------- --------------- --------------- --------------- --------------- --------------- --------------- --------------- --------------- --------------- -------------CB -------------CC 
--------------- --------------- --------------- --------------- --------------- --------------- --------------- --------------- --------------- --------------- --------------- --------------- --------------- --------------- --------------- --------------- --------------- --------------- --------------- --------------- --------------- --------------- --------------- --------------- --------------- --------------- -------------B- -------------B- --------------- 
--------------- --------------- --------------- --------------- --------------- --------------- --------------- --------------- --------------- --------------- --------------- --------------- --------------- --------------- --------------- --------------- --------------- --------------- --------------- --------------- --------------- --------------- --------------- --------------- --------------- -------------B- -------------B- --------------- --------------- 
--------------- --------------- --------------- --------------- --------------- --------------- --------------- --------------- --------------- --------------- --------------- --------------- --------------- --------------- --------------- --------------- --------------- --------------- --------------- --------------- --------------- --------------- --------------- --------------- -------------B- -------------B- --------------- --------------- --------------- 
--------------- --------------- --------------- --------------- ----AAAA------- ----AAAA------- ----AAAA------- ----AAAA------- --------------- --------------- --------------- --------------- --------------- --------------- --------------- --------------- --------------- --------------- --------------- --------------- --------------- --------------- --------------- -------------B- -------------B- --------------- --------------- --------------- --------------- 
--------------- --------------- ----AAAA------- ---AAAAAA------ --AAAAAAAA----- --AAAAAAAA----- --AAAAAAAA----- --AAAAAAAA----- ---AAAAAA------ ----AAAA------- --------------- --------------- --------------- --------------- --------------- --------------- --------------- --------------- --------------- --------------- --------------- --------------- -------------B- -------------B- --------------- --------------- --------------- --------------- --------------- 
--------------- ----AAAA------- ---AAAAAA------ --AAAAAAAA----- -AAAAAAAAAA---- -AAAAAAAAAA---- -AAAAAAAAAA---- -AAAAAAAAAA---- --AAAAAAAA----- ---AAAAAA------ ----AAAA------- --------------- --------------- --------------- --------------- --------------- --------------- --------------- --------------- --------------- --------------- -------------B- -------------B- --------------- --------------- --------------- --------------- --------------- --------------- 
--------------- ---AAAAAA------ --AAAAAAAA----- -AAAAAAAAAA---- -AAAAAAAAAA---- -AAAAAAAAAA---- -AAAAAAAAAA---- -AAAAAAAAAA---- -AAAAAAAAAA---- --AAAAAAAA----- ---AAAAAA------ --------------- --------------- --------------- --------------- --------------- --------------- --------------- --------------- --------------- --------------- ------------BB- --------------- --------------- --------------- --------------- --------------- --------------- --------------- 
----AAAA------- --AAAAAAAA----- -AAAAAAAAAA---- -AAAAAAAAAA---- AAAAAAAAAAAA--- AAAAAAAAAAAA--- AAAAAAAAAAAA--- AAAAAAAAAAAA--- -AAAAAAAAAA---- -AAAAAAAAAA---- --AAAAAAAA----- ----AAAA------- --------------- --------------- --------------- --------------- --------------- --------------- --------------- --------------- -----------BB-- ------------B-- --------------- --------------- --------------- --------------- --------------- --------------- --------------- 
----AAAA------- --AAAAAAAA----- -AAAAAAAAAA---- -AAAAAAAAAA---- AAAAAAAAAAAA--- AAAAAAAAAAAA--- AAAAAAAAAAAA--- AAAAAAAAAAAA--- -AAAAAAAAAA---- -AAAAAAAAAA---- --AAAAAAAA----- ----AAAA------- -----B--------- -----B--------- -----BB-------- ------BB------- -------BB------ --------BB----- ---------BB---- ----------BB--- -----------B--- --------------- --------------- --------------- --------------- --------------- --------------- --------------- --------------- 
----AAAA------- --AAAAAAAA----- -AAAAAAAAAA---- -AAAAAAAAAA---- AAAAAAAAAAAA--- AAAAAAAAAAAA--- AAAAAAAAAAAA--- AAAAAAAAAAAA--- -AAAAAAAAAA---- -AAAAAAAAAA---- --AAAAAAAA----- ----AAAA------- -----B--------- -----B--------- -----BB-------- ------BB------- -------BB------ --------BB----- ---------BB---- ----------BB--- -----------B--- --------------- --------------- --------------- --------------- --------------- --------------- --------------- --------------- 
----AAAA------- --AAAAAAAA----- -AAAAAAAAAA---- -AAAAAAAAAA---- AAAAAAAAAAAA--- AAAAAAAAAAAA--- AAAAAAAAAAAA--- AAAAAAAAAAAA--- -AAAAAAAAAA---- -AAAAAAAAAA---- --AAAAAAAA----- ----AAAA------- --------------- --------------- --------------- --------------- --------------- --------------- --------------- --------------- --------------- --------------- --------------- --------------- --------------- --------------- --------------- --------------- --------------- 
--------------- ---AAAAAA------ --AAAAAAAA----- -AAAAAAAAAA---- -AAAAAAAAAA---- -AAAAAAAAAA---- -AAAAAAAAAA---- -AAAAAAAAAA---- -AAAAAAAAAA---- --AAAAAAAA----- ---AAAAAA------ --------------- --------------- --------------- --------------- --------------- --------------- --------------- --------------- --------------- --------------- --------------- --------------- --------------- --------------- --------------- --------------- --------------- --------------- 
--------------- ----AAAA------- ---AAAAAA------ --AAAAAAAA----- -AAAAAAAAAA---- -AAAAAAAAAA---- -AAAAAAAAAA---- -AAAAAAAAAA---- --AAAAAAAA----- ---AAAAAA------ ----AAAA------- --------------- --------------- --------------- --------------- --------------- --------------- --------------- --------------- --------------- --------------- --------------- --------------- --------------- --------------- --------------- --------------- --------------- --------------- 
--------------- --------------- ----AAAA------- ---AAAAAA------ --AAAAAAAA----- --AAAAAAAA----- --AAAAAAAA----- --AAAAAAAA----- ---AAAAAA------ ----AAAA------- --------------- --------------- --------------- --------------- --------------- --------------- --------------- --------------- --------------- --------------- --------------- --------------- --------------- --------------- --------------- --------------- --------------- --------------- --------------- 
--------------- --------------- --------------- --------------- ----AAAA------- ----AAAA------- ----AAAA------- ----AAAA------- --------------- --------------- --------------- --------------- --------------- --------------- --------------- --------------- --------------- --------------- --------------- --------------- --------------- --------------- --------------- --------------- --------------- --------------- --------------- --------------- --------------- 
