model
size = 9 14 9, scale = 0.05, origin = -y
material 
  colors = A:#39F B:#909 C:#6C0 D:#0F9 E:#0C6 F:#9CF G:#6C3 H:#CF3
voxels
--------- --------- --------- --------- --------- --------- --------- --------- --------- --------- --------- --------- --AA-AA-- --------- 
--------- --------- --------- --------- --------- --------- --------- --------- --------- --------- --------- --------- --AAAAA-- ---B-B--- 
--------- --------- --------- --------- --------- --------- --------- --------- --------- --------- --------- --------- AA-AAA-AA ---BBB--- 
--------- --------- --------- --------- --------- --------- --------- --------- --------- --------- ----E---- --------- AAADDDAAA -BB---BB- 
---E----- ---E----- ---C----- ---C----- ---C----- ---CC---- ----C---- ----C---- ----C---- ----C---- ---GFG--- ----C---- -AADFDAA- --B-H-B-- 
--------- --------- --------- --------- --------- --------- --------- --------- --------- --------- ----E---- --------- AAADDDAAA -BB---BB- 
--------- --------- --------- --------- --------- --------- --------- --------- --------- --------- --------- --------- AA-AAA-AA ---BBB--- 
--------- --------- --------- --------- --------- --------- --------- --------- --------- --------- --------- --------- --AAAAA-- ---B-B--- 
--------- --------- --------- --------- --------- --------- --------- --------- --------- --------- --------- --------- --AA-AA-- --------- 
