model
size = 16 32 20, scale = 0.05, origin = -y
material 
  colors = A:#0B0 B:#0A0 C:#080 D:#050 E:#111 F:#00E
voxels
182-D14-3D14-D478-2(2BD13-)DBD461-2B2(D12-3B)D12-5B12-3B63-2A13-4A11-3(6A10-)6A11-4A13-2A268-2BD12-2(5B11-)5B12-3B2A12-4A11-6A10-6A9-8A8-8A7-3(10A6-)10A7-8A8-8A9-6A11-4A234-5B11-5BA10-2(5B2A9-)5B6A5-11A3(4-12A)4-10A5-4(12A4-)12A5-10A6-10A7-8A9-6A187-4A11-AB4A9-5B2A9-5B3A7-7B2A6-2C5B6A3-2C5B4A2E3-2C2AB6AEF2(3-12AE)3-14A2-12A3-3(14A2-)14A3-2(12A4-)12A5-10A7-8A9-6A139-4A11-6A10-6A9-A3B4A8-5B3A6-2(C7B3A5-)C7B5A3-2A5B5AE3-3A3B6A2(E3-12A)E2-15A-6(14A2-)14A3-12A4-12A5-10A7-8A9-6A26-CB12-3CB12-4C12-5C12-4CA11-5CA11-4C2A9-A5C2A8-2A4C2A6-2CA3B2C3A5-2C5B4A5-C7B3A5-A7B4A4-A7B4AE3-2A5B5AE3-3A3B6A2(E2-13A)E2-15A-14A-64A-2(14A2-)14A3-12A4-12A5-10A7-8A11-2A12-3C2(11-5C)11-6C10-6CA9-7CA8-7C2AD5-8CAD6-2CA5C3A5-2CA3B2C3A5-2C5B4A2(2-A)2(7B4A4-A)7B4A3-3A5B5AE2-4A3B6A2(E2-13A)E2-111A-2(14A2-)14A3-12A5-10A7-8A10-4A11-2(3C2(11-5C)11-6C10-6C2A8-7CAD7-7C2AD5-8CAD6-2CA5C3A5-2CA3B2C4A4-2A5B7A3(2-A7B6A)-3A5B7A-4A3B8A-15A-143A-14A2-14A3-12A5-10A7-8A9-6A10-)3C2(11-5C)11-6C10-6CA9-7CA8-7C2AD5-8CAD6-2CA5C3A5-2CA3B2C3A5-2C5B4A2(2-A)2(7B4A4-A)7B4A3-3A5B5AE2-4A3B6A2(E2-13A)E2-111A-2(14A2-)14A3-12A5-10A7-8A10-4A11-CB12-3CB12-4C12-5C12-4CA11-5CA11-4C2A9-A5C2A8-2A4C2A6-2CA3B2C3A5-2C5B4A5-C7B3A5-A7B4A4-A7B4AE3-2A5B5AE3-3A3B6A2(E2-13A)E2-15A-14A-64A-2(14A2-)14A3-12A4-12A5-10A7-8A11-2A109-4A11-6A10-6A9-A3B4A8-5B3A6-2(C7B3A5-)C7B5A3-2A5B5AE3-3A3B6A2(E3-12A)E2-15A-6(14A2-)14A3-12A4-12A5-10A7-8A9-6A155-4A11-AB4A9-5B2A9-5B3A7-7B2A6-2C5B6A3-2C5B4A2E3-2C2AB6AEF2(3-12AE)3-14A2-12A3-3(14A2-)14A3-2(12A4-)12A5-10A7-8A9-6A201-5B11-5BA10-2(5B2A9-)5B6A5-11A2(4-12A)4-10A6-10A5-4(12A4-)12A5-10A6-10A7-8A9-6A218-2BD12-2(5B11-)5B12-3B2A12-4A11-6A10-6A9-8A8-8A7-3(10A6-)10A7-8A8-8A9-6A11-4A235-2B2(D12-3B)D12-5B12-3B79-2A13-4A11-2(6A10-)6A11-4A13-2A284-DBD13-2BD13-DBD478-D14-3D14-D297-
