model
size = 31 23 13, scale = 0.05, origin = -y
material 
  colors = A:#EEE B:#F3F C:#008 D:#004 E:#06F
voxels
-------AAAAAAAAAAAAAAAAA------- -------AAAAAAAAAAAAAAAAA------- -------AAAAAAAAAAAAAAAAA------- -------AAAAAAAAAAAAAAAAA------- -------AAAAAAAAAAAAAAAAA------- -------AAAAAAAAAAAAAAAAA------- -------AAAAAAAAAAAAAAAAA------- -------AAAAAAAAAAAAAAAAA------- -------AAAAAAAAAAAAAAAAA------- -------AAAAAAAAAAAAAAAAA------- -------AAAAAAAAAAAAAAAAA------- -------AAAAAAAAAAAAAAAAA------- -------AAAAAAAAAAAAAAAAA------- -------AAAAAAAAAAAAAAAAA------- -------AAAAAAAAAAAAAAAAA------- -------AAAAAAAAAAAAAAAAA------- -------AAAAAAAAAAAAAAAAA------- -------AAAAAAAAAAAAAAAAA------- -------AAAAAAAAAAAAAAAAA------- -------AAAAAAAAAAAAAAAAA------- ------------------------------- ------------------------------- ------------------------------- 
------AA---------------AA------ ------AA---------------AA------ ------AA---------------AA------ ------AA---------------AA------ ------AA---------------AA------ ------AA---------------AA------ ------AA---------------AA------ ------AA---------------AA------ ------AA---------------AA------ ------AA---------------A------- ------AA---------------A------- ------AA---------------A------- ------AA---------------A------- ------AA---------------A------- ------AA---------------A------- ------AA---------------A------- ------AA---------------A------- ------AA---------------A------- ------AA---------------A------- ------AAAAAAAAAAAAAAAAAA------- -------AAAAAAAAAAAAAAAAA------- ------------------------------- ------------------------------- 
-----AAA---------------AAA----- -----AAA---------------AAA----- -----AAA---------------AAA----- -----AAA---------------AAA----- -----AAA---------------AAA----- -----AAA---------------AAA----- -----AAA---------------AAA----- -----AAA---------------AAA----- -----AAA---------------AAA----- -----AAA---------------AAA----- -----AAA---------------AAA----- -----AAA---------------AAA----- -----AAA---------------AAA----- -----AAA---------------AAA----- -----AAA---------------AAA----- AAAAAAAA---------------AAAAAAAA AAAAAAAA---------------AAAAAAAA AAAAAAAA---------------AAAAAAAA -----AAA---------------AAA----- -----AAAA-------------AAAA----- ------AAA-------------AAA------ --------A-------------A-------- ------------------------------- 
----AAAA---------------AAAA---- ----AAAA---------------AAAA---- ----AAAA---------------AAAA---- ----AAAA---------------AAAA---- ----AAAA---------------AAAA---- ----AAAA---------------AAAA---- ----AAAA---------------AAAA---- ----AAAA---------------AAAA---- ----AAAA---------------AAAA---- ----AAAA---------------AAAA---- ----AAAA---------------AAAA---- ----AAAA---------------AAAA---- ----AAAA---------------AAAA---- ----AAAA---------------AAAA---- AAAAAAAA---------------AAAAAAAA AAAAA--A------------------AAAAA ------------------------------- AAAAA---------------------AAAAA AAAAAAAA---------------AAAAAAAA ----AAAAA-------------AAAAA---- -----AAAA-------------AAAA----- -------AA-------------AA------- --------A-------------A-------- 
----AAAA---------------AAAA---- ----AAAA---------------AAAA---- ----AAAA---------------AAAA---- ----AAAA---------------AAAA---- ----AAAA---------------AAAA---- ----AAAA---------------AAAA---- ----AAAA---------------AAAA---- ----AAAA---------------AAAA---- ----AAAA---------------AAAA---- ----AAAA---------------AAAA---- ----AAAA---------------AAAA---- ----AAAA---------------AAAA---- ----AAAA---------------AAAA---- AAAAAAAA---------------AAAAAAAA AAAAA---------------------AAAAA ------------------------------- ------------------------------- ------------------------------- AAAAA---------------------AAAAA AAAAAAAAA-------------AAAAAAAAA ----AAAAA-------------AAAAA---- ------AAA-------------AAA------ --------A-------------A-------- 
----AAAA---------------AAAA---- ----AAAA---------------AAAA---- ----AAAA---------------AAAA---- ----AAAA---------------AAAA---- ----AAAA---------------AAAA---- ----AAAA---------------AAAA---- ----AAAA---------------AAAA---- ----AAAA---------------AAAA---- ----AAAA---------------AAAA---- ----AAAA---------------AAAA---- ----AAAA---------------AAAA---- ----AAAA---------------AAAA---- ----AAAA---------------AAAA---- AAAAAAAA---------------AAAAAAAA ------------------------------- ------------------------------- ------------------------------- ------------------------------- ------------------------------- AAAAAAAAA-------------AAAAAAAAA ----AAAAA-------------AAAAA---- ------AAA-------------AAA------ --------A-------------A-------- 
----AAAA---------------AAAA---- ----AAAA---------------AAAA---- ----AAAA---------------AAAA---- ----AAAA---------------AAAA---- ----AAAA---------------AAAA---- ----AAAA---------------AAAA---- ----AAAA---------------AAAA---- ----AAAA---------------AAAA---- ----AAAA---------------AAAA---- ----AAAA---------------AAAA---- ----AAAA---------------AAAA---- ----AAAA---------------AAAA---- ----AAAA---------------AAAA---- AAAAAAAA---------------AAAAAAAA AAAAA---------------------AAAAA ------------------------------- ------------------------------- ------------------------------- AAAAA---------------------AAAAA AAAAAAAAA-------------AAAAAAAAA ----AAAAA-------------AAAAA---- ------AAA-------------AAA------ ------------------------------- 
----AAAA---------------AAAA---- ----AAAA---------------AAAA---- ----AAAA---------------AAAA---- ----AAAA---------------AAAA---- ----AAAA---------------AAAA---- ----AAAA---------------AAAA---- ----AAAA---------------AAAA---- ----AAAA---------------AAAA---- ----AAAA---------------AAAA---- ----AAAA---------------AAAA---- ----AAAA---------------AAAA---- ----AAAA---------------AAAA---- ----AAAA---------------AAAA---- ----AAAA---------------AAAA---- AAAAAAAA---------------AAAAAAAA AAAAA---------------------AAAAA ------------------------------- AAAAA---------------------AAAAA AAAAAAAA---------------AAAAAAAA ----AAAAA-------------AAAAA---- ----AAAAA-------------AAAAA---- -------AA-------------AA------- ------------------------------- 
-----AAA---------------AAA----- -----AAA---------------AAA----- -----AAA---------------AAA----- -----AAA---------------AAA----- -----AAA---------------AAA----- -----AAA---------------AAA----- -----AAA---------------AAA----- -----AAA---------------AAA----- -----AAA---------------AAA----- -----AAA---------------AAA----- -----AAA---------------AAA----- -----AAA---------------AAA----- -----AAA---------------AAA----- -----AAA---------------AAA----- -----AAA---------------AAA----- AAAAAAAA---------------AAAAAAAA AAAAAAAA---------------AAAAAAAA AAAAAAAA---------------AAAAAAAA -----AAA---------------AAA----- -----AAAA-------------AAAA----- -----AAAA-------------AAAAA---- --------A-------------A-------- ------------------------------- 
------AA---------------AA------ ------AA---------------AA------ ------AA---------------AA------ ------AA---------------AA------ ------AA---------------AA------ ------AA---------------AA------ ------AA---------------AA------ ------AA---------------AA------ ------AA---------------AA------ ------AA---------------AA------ ------AA---------------AA------ ------AA---------------AA------ ------AA---------------AA------ ------AA---------------AA------ ------AA---------------AA------ ------AA---------------AA------ ------AA---------------AA------ ------AA---------------AA------ ------AA---------------AA------ ------AAA-------------AAA------ ------AAA-------------AAAA----- ------------------------------- ------------------------------- 
-------A---------------A------- -------A---------------A------- -------A---------------A------- -------A---------------A------- -------A---------------A------- -------A---------------A------- -------A---------------A------- -------A---------------A------- -------A---------------A------- -------A---------------A------- -------A---------------A------- -------A---------------A------- -------A---------------A------- -------A---------------A------- -------A---------------A------- -------A---------------A------- -------A---------------A------- -------A---------------A------- -------A---------------A------- -------AA-------------AA------- -------AA-------------AAA------ ------------------------------- ------------------------------- 
-------AAAAAAAAAAAAAAAAA------- -------AAAAAAAAAAAAAAAAA------- -------AAAAAAAAAAAAAAAAA------- -------AAAAAAAAAAAAAAAAA------- -------AAAAAAAAAAAAAAAAA------- -------AAAAAAAAAAAAAAAAA------- -------AAAAAAAAAAAAAAAAA------- -------AAAAAAAAAAAAAAAAA------- -------AAAAAAAAAAAAAAAAA------- -------AAAAAAAAAAAAAAAAA------- -------AAAAAAAAAAAAAAAAA------- -------AAAAAAAAAAAAAAAAA------- -------AAAAAAAAAAAAAAAAA------- -------AAAAAAAAAAAAAAAAA------- -------AAAAAAAAAAAAAAAAA------- -------AAAAAAAAAAAAAAAAA------- -------AAAAAAAAAAAAAAAAA------- -------AAAA---------AAAA------- -------AAA-----------AAA------- -------AA-------------AA------- -------AA-------------AA------- ------------------------------- ------------------------------- 
------------------------------- ------------------------------- ------------------------------- ------------------------------- ------------------------------- ------------------------------- -----------B-B--B---BB--------- -----------BBB-B-B---B--------- -----------B-B-B-B-B-B--------- -------------B--B---B---------- ------------------------------- -------E-E-EE--E----E-E-------- -------C-C--C--C--C-C-C-------- --------DD-DD--D--DDD-D-------- -------A-A--A--A--A-A-A-------- -------CCC-CC-CCC-C---C-------- ------------------------------- ------------------------------- ------------------------------- ------------------------------- ------------------------------- ------------------------------- ------------------------------- 
