model
size = 27, scale = 0.05, origin = -y
material 
  colors = A:#FF3
voxels
AAAAAAAAAAAAAAAAAAAAAAAAAAA A-AA-AA-AA-AA-AA-AA-AA-AA-A AAAAAAAAAAAAAAAAAAAAAAAAAAA AAA---AAAAAA---AAAAAA---AAA A-A---A-AA-A---A-AA-A---A-A AAA---AAAAAA---AAAAAA---AAA AAAAAAAAAAAAAAAAAAAAAAAAAAA A-AA-AA-AA-AA-AA-AA-AA-AA-A AAAAAAAAAAAAAAAAAAAAAAAAAAA AAAAAAAAA---------AAAAAAAAA A-AA-AA-A---------A-AA-AA-A AAAAAAAAA---------AAAAAAAAA AAA---AAA---------AAA---AAA A-A---A-A---------A-A---A-A AAA---AAA---------AAA---AAA AAAAAAAAA---------AAAAAAAAA A-AA-AA-A---------A-AA-AA-A AAAAAAAAA---------AAAAAAAAA AAAAAAAAAAAAAAAAAAAAAAAAAAA A-AA-AA-AA-AA-AA-AA-AA-AA-A AAAAAAAAAAAAAAAAAAAAAAAAAAA AAA---AAAAAA---AAAAAA---AAA A-A---A-AA-A---A-AA-A---A-A AAA---AAAAAA---AAAAAA---AAA AAAAAAAAAAAAAAAAAAAAAAAAAAA A-AA-AA-AA-AA-AA-AA-AA-AA-A AAAAAAAAAAAAAAAAAAAAAAAAAAA 
A-AA-AA-AA-AA-AA-AA-AA-AA-A --------------------------- A-AA-AA-AA-AA-AA-AA-AA-AA-A A-A---A-AA-A---A-AA-A---A-A --------------------------- A-A---A-AA-A---A-AA-A---A-A A-AA-AA-AA-AA-AA-AA-AA-AA-A --------------------------- A-AA-AA-AA-AA-AA-AA-AA-AA-A A-AA-AA-A---------A-AA-AA-A --------------------------- A-AA-AA-A---------A-AA-AA-A A-A---A-A---------A-A---A-A --------------------------- A-A---A-A---------A-A---A-A A-AA-AA-A---------A-AA-AA-A --------------------------- A-AA-AA-A---------A-AA-AA-A A-AA-AA-AA-AA-AA-AA-AA-AA-A --------------------------- A-AA-AA-AA-AA-AA-AA-AA-AA-A A-A---A-AA-A---A-AA-A---A-A --------------------------- A-A---A-AA-A---A-AA-A---A-A A-AA-AA-AA-AA-AA-AA-AA-AA-A --------------------------- A-AA-AA-AA-AA-AA-AA-AA-AA-A 
AAAAAAAAAAAAAAAAAAAAAAAAAAA A-AA-AA-AA-AA-AA-AA-AA-AA-A AAAAAAAAAAAAAAAAAAAAAAAAAAA AAA---AAAAAA---AAAAAA---AAA A-A---A-AA-A---A-AA-A---A-A AAA---AAAAAA---AAAAAA---AAA AAAAAAAAAAAAAAAAAAAAAAAAAAA A-AA-AA-AA-AA-AA-AA-AA-AA-A AAAAAAAAAAAAAAAAAAAAAAAAAAA AAAAAAAAA---------AAAAAAAAA A-AA-AA-A---------A-AA-AA-A AAAAAAAAA---------AAAAAAAAA AAA---AAA---------AAA---AAA A-A---A-A---------A-A---A-A AAA---AAA---------AAA---AAA AAAAAAAAA---------AAAAAAAAA A-AA-AA-A---------A-AA-AA-A AAAAAAAAA---------AAAAAAAAA AAAAAAAAAAAAAAAAAAAAAAAAAAA A-AA-AA-AA-AA-AA-AA-AA-AA-A AAAAAAAAAAAAAAAAAAAAAAAAAAA AAA---AAAAAA---AAAAAA---AAA A-A---A-AA-A---A-AA-A---A-A AAA---AAAAAA---AAAAAA---AAA AAAAAAAAAAAAAAAAAAAAAAAAAAA A-AA-AA-AA-AA-AA-AA-AA-AA-A AAAAAAAAAAAAAAAAAAAAAAAAAAA 
AAA---AAAAAA---AAAAAA---AAA A-A---A-AA-A---A-AA-A---A-A AAA---AAAAAA---AAAAAA---AAA --------------------------- --------------------------- --------------------------- AAA---AAAAAA---AAAAAA---AAA A-A---A-AA-A---A-AA-A---A-A AAA---AAAAAA---AAAAAA---AAA AAA---AAA---------AAA---AAA A-A---A-A---------A-A---A-A AAA---AAA---------AAA---AAA --------------------------- --------------------------- --------------------------- AAA---AAA---------AAA---AAA A-A---A-A---------A-A---A-A AAA---AAA---------AAA---AAA AAA---AAAAAA---AAAAAA---AAA A-A---A-AA-A---A-AA-A---A-A AAA---AAAAAA---AAAAAA---AAA --------------------------- --------------------------- --------------------------- AAA---AAAAAA---AAAAAA---AAA A-A---A-AA-A---A-AA-A---A-A AAA---AAAAAA---AAAAAA---AAA 
A-A---A-AA-A---A-AA-A---A-A --------------------------- A-A---A-AA-A---A-AA-A---A-A --------------------------- --------------------------- --------------------------- A-A---A-AA-A---A-AA-A---A-A --------------------------- A-A---A-AA-A---A-AA-A---A-A A-A---A-A---------A-A---A-A --------------------------- A-A---A-A---------A-A---A-A --------------------------- --------------------------- --------------------------- A-A---A-A---------A-A---A-A --------------------------- A-A---A-A---------A-A---A-A A-A---A-AA-A---A-AA-A---A-A --------------------------- A-A---A-AA-A---A-AA-A---A-A --------------------------- --------------------------- --------------------------- A-A---A-AA-A---A-AA-A---A-A --------------------------- A-A---A-AA-A---A-AA-A---A-A 
AAA---AAAAAA---AAAAAA---AAA A-A---A-AA-A---A-AA-A---A-A AAA---AAAAAA---AAAAAA---AAA --------------------------- --------------------------- --------------------------- AAA---AAAAAA---AAAAAA---AAA A-A---A-AA-A---A-AA-A---A-A AAA---AAAAAA---AAAAAA---AAA AAA---AAA---------AAA---AAA A-A---A-A---------A-A---A-A AAA---AAA---------AAA---AAA --------------------------- --------------------------- --------------------------- AAA---AAA---------AAA---AAA A-A---A-A---------A-A---A-A AAA---AAA---------AAA---AAA AAA---AAAAAA---AAAAAA---AAA A-A---A-AA-A---A-AA-A---A-A AAA---AAAAAA---AAAAAA---AAA --------------------------- --------------------------- --------------------------- AAA---AAAAAA---AAAAAA---AAA A-A---A-AA-A---A-AA-A---A-A AAA---AAAAAA---AAAAAA---AAA 
AAAAAAAAAAAAAAAAAAAAAAAAAAA A-AA-AA-AA-AA-AA-AA-AA-AA-A AAAAAAAAAAAAAAAAAAAAAAAAAAA AAA---AAAAAA---AAAAAA---AAA A-A---A-AA-A---A-AA-A---A-A AAA---AAAAAA---AAAAAA---AAA AAAAAAAAAAAAAAAAAAAAAAAAAAA A-AA-AA-AA-AA-AA-AA-AA-AA-A AAAAAAAAAAAAAAAAAAAAAAAAAAA AAAAAAAAA---------AAAAAAAAA A-AA-AA-A---------A-AA-AA-A AAAAAAAAA---------AAAAAAAAA AAA---AAA---------AAA---AAA A-A---A-A---------A-A---A-A AAA---AAA---------AAA---AAA AAAAAAAAA---------AAAAAAAAA A-AA-AA-A---------A-AA-AA-A AAAAAAAAA---------AAAAAAAAA AAAAAAAAAAAAAAAAAAAAAAAAAAA A-AA-AA-AA-AA-AA-AA-AA-AA-A AAAAAAAAAAAAAAAAAAAAAAAAAAA AAA---AAAAAA---AAAAAA---AAA A-A---A-AA-A---A-AA-A---A-A AAA---AAAAAA---AAAAAA---AAA AAAAAAAAAAAAAAAAAAAAAAAAAAA A-AA-AA-AA-AA-AA-AA-AA-AA-A AAAAAAAAAAAAAAAAAAAAAAAAAAA 
A-AA-AA-AA-AA-AA-AA-AA-AA-A --------------------------- A-AA-AA-AA-AA-AA-AA-AA-AA-A A-A---A-AA-A---A-AA-A---A-A --------------------------- A-A---A-AA-A---A-AA-A---A-A A-AA-AA-AA-AA-AA-AA-AA-AA-A --------------------------- A-AA-AA-AA-AA-AA-AA-AA-AA-A A-AA-AA-A---------A-AA-AA-A --------------------------- A-AA-AA-A---------A-AA-AA-A A-A---A-A---------A-A---A-A --------------------------- A-A---A-A---------A-A---A-A A-AA-AA-A---------A-AA-AA-A --------------------------- A-AA-AA-A---------A-AA-AA-A A-AA-AA-AA-AA-AA-AA-AA-AA-A --------------------------- A-AA-AA-AA-AA-AA-AA-AA-AA-A A-A---A-AA-A---A-AA-A---A-A --------------------------- A-A---A-AA-A---A-AA-A---A-A A-AA-AA-AA-AA-AA-AA-AA-AA-A --------------------------- A-AA-AA-AA-AA-AA-AA-AA-AA-A 
AAAAAAAAAAAAAAAAAAAAAAAAAAA A-AA-AA-AA-AA-AA-AA-AA-AA-A AAAAAAAAAAAAAAAAAAAAAAAAAAA AAA---AAAAAA---AAAAAA---AAA A-A---A-AA-A---A-AA-A---A-A AAA---AAAAAA---AAAAAA---AAA AAAAAAAAAAAAAAAAAAAAAAAAAAA A-AA-AA-AA-AA-AA-AA-AA-AA-A AAAAAAAAAAAAAAAAAAAAAAAAAAA AAAAAAAAA---------AAAAAAAAA A-AA-AA-A---------A-AA-AA-A AAAAAAAAA---------AAAAAAAAA AAA---AAA---------AAA---AAA A-A---A-A---------A-A---A-A AAA---AAA---------AAA---AAA AAAAAAAAA---------AAAAAAAAA A-AA-AA-A---------A-AA-AA-A AAAAAAAAA---------AAAAAAAAA AAAAAAAAAAAAAAAAAAAAAAAAAAA A-AA-AA-AA-AA-AA-AA-AA-AA-A AAAAAAAAAAAAAAAAAAAAAAAAAAA AAA---AAAAAA---AAAAAA---AAA A-A---A-AA-A---A-AA-A---A-A AAA---AAAAAA---AAAAAA---AAA AAAAAAAAAAAAAAAAAAAAAAAAAAA A-AA-AA-AA-AA-AA-AA-AA-AA-A AAAAAAAAAAAAAAAAAAAAAAAAAAA 
AAAAAAAAA---------AAAAAAAAA A-AA-AA-A---------A-AA-AA-A AAAAAAAAA---------AAAAAAAAA AAA---AAA---------AAA---AAA A-A---A-A---------A-A---A-A AAA---AAA---------AAA---AAA AAAAAAAAA---------AAAAAAAAA A-AA-AA-A---------A-AA-AA-A AAAAAAAAA---------AAAAAAAAA --------------------------- --------------------------- --------------------------- --------------------------- --------------------------- --------------------------- --------------------------- --------------------------- --------------------------- AAAAAAAAA---------AAAAAAAAA A-AA-AA-A---------A-AA-AA-A AAAAAAAAA---------AAAAAAAAA AAA---AAA---------AAA---AAA A-A---A-A---------A-A---A-A AAA---AAA---------AAA---AAA AAAAAAAAA---------AAAAAAAAA A-AA-AA-A---------A-AA-AA-A AAAAAAAAA---------AAAAAAAAA 
A-AA-AA-A---------A-AA-AA-A --------------------------- A-AA-AA-A---------A-AA-AA-A A-A---A-A---------A-A---A-A --------------------------- A-A---A-A---------A-A---A-A A-AA-AA-A---------A-AA-AA-A --------------------------- A-AA-AA-A---------A-AA-AA-A --------------------------- --------------------------- --------------------------- --------------------------- --------------------------- --------------------------- --------------------------- --------------------------- --------------------------- A-AA-AA-A---------A-AA-AA-A --------------------------- A-AA-AA-A---------A-AA-AA-A A-A---A-A---------A-A---A-A --------------------------- A-A---A-A---------A-A---A-A A-AA-AA-A---------A-AA-AA-A --------------------------- A-AA-AA-A---------A-AA-AA-A 
AAAAAAAAA---------AAAAAAAAA A-AA-AA-A---------A-AA-AA-A AAAAAAAAA---------AAAAAAAAA AAA---AAA---------AAA---AAA A-A---A-A---------A-A---A-A AAA---AAA---------AAA---AAA AAAAAAAAA---------AAAAAAAAA A-AA-AA-A---------A-AA-AA-A AAAAAAAAA---------AAAAAAAAA --------------------------- --------------------------- --------------------------- --------------------------- --------------------------- --------------------------- --------------------------- --------------------------- --------------------------- AAAAAAAAA---------AAAAAAAAA A-AA-AA-A---------A-AA-AA-A AAAAAAAAA---------AAAAAAAAA AAA---AAA---------AAA---AAA A-A---A-A---------A-A---A-A AAA---AAA---------AAA---AAA AAAAAAAAA---------AAAAAAAAA A-AA-AA-A---------A-AA-AA-A AAAAAAAAA---------AAAAAAAAA 
AAA---AAA---------AAA---AAA A-A---A-A---------A-A---A-A AAA---AAA---------AAA---AAA --------------------------- --------------------------- --------------------------- AAA---AAA---------AAA---AAA A-A---A-A---------A-A---A-A AAA---AAA---------AAA---AAA --------------------------- --------------------------- --------------------------- --------------------------- --------------------------- --------------------------- --------------------------- --------------------------- --------------------------- AAA---AAA---------AAA---AAA A-A---A-A---------A-A---A-A AAA---AAA---------AAA---AAA --------------------------- --------------------------- --------------------------- AAA---AAA---------AAA---AAA A-A---A-A---------A-A---A-A AAA---AAA---------AAA---AAA 
A-A---A-A---------A-A---A-A --------------------------- A-A---A-A---------A-A---A-A --------------------------- --------------------------- --------------------------- A-A---A-A---------A-A---A-A --------------------------- A-A---A-A---------A-A---A-A --------------------------- --------------------------- --------------------------- --------------------------- --------------------------- --------------------------- --------------------------- --------------------------- --------------------------- A-A---A-A---------A-A---A-A --------------------------- A-A---A-A---------A-A---A-A --------------------------- --------------------------- --------------------------- A-A---A-A---------A-A---A-A --------------------------- A-A---A-A---------A-A---A-A 
AAA---AAA---------AAA---AAA A-A---A-A---------A-A---A-A AAA---AAA---------AAA---AAA --------------------------- --------------------------- --------------------------- AAA---AAA---------AAA---AAA A-A---A-A---------A-A---A-A AAA---AAA---------AAA---AAA --------------------------- --------------------------- --------------------------- --------------------------- --------------------------- --------------------------- --------------------------- --------------------------- --------------------------- AAA---AAA---------AAA---AAA A-A---A-A---------A-A---A-A AAA---AAA---------AAA---AAA --------------------------- --------------------------- --------------------------- AAA---AAA---------AAA---AAA A-A---A-A---------A-A---A-A AAA---AAA---------AAA---AAA 
AAAAAAAAA---------AAAAAAAAA A-AA-AA-A---------A-AA-AA-A AAAAAAAAA---------AAAAAAAAA AAA---AAA---------AAA---AAA A-A---A-A---------A-A---A-A AAA---AAA---------AAA---AAA AAAAAAAAA---------AAAAAAAAA A-AA-AA-A---------A-AA-AA-A AAAAAAAAA---------AAAAAAAAA --------------------------- --------------------------- --------------------------- --------------------------- --------------------------- --------------------------- --------------------------- --------------------------- --------------------------- AAAAAAAAA---------AAAAAAAAA A-AA-AA-A---------A-AA-AA-A AAAAAAAAA---------AAAAAAAAA AAA---AAA---------AAA---AAA A-A---A-A---------A-A---A-A AAA---AAA---------AAA---AAA AAAAAAAAA---------AAAAAAAAA A-AA-AA-A---------A-AA-AA-A AAAAAAAAA---------AAAAAAAAA 
A-AA-AA-A---------A-AA-AA-A --------------------------- A-AA-AA-A---------A-AA-AA-A A-A---A-A---------A-A---A-A --------------------------- A-A---A-A---------A-A---A-A A-AA-AA-A---------A-AA-AA-A --------------------------- A-AA-AA-A---------A-AA-AA-A --------------------------- --------------------------- --------------------------- --------------------------- --------------------------- --------------------------- --------------------------- --------------------------- --------------------------- A-AA-AA-A---------A-AA-AA-A --------------------------- A-AA-AA-A---------A-AA-AA-A A-A---A-A---------A-A---A-A --------------------------- A-A---A-A---------A-A---A-A A-AA-AA-A---------A-AA-AA-A --------------------------- A-AA-AA-A---------A-AA-AA-A 
AAAAAAAAA---------AAAAAAAAA A-AA-AA-A---------A-AA-AA-A AAAAAAAAA---------AAAAAAAAA AAA---AAA---------AAA---AAA A-A---A-A---------A-A---A-A AAA---AAA---------AAA---AAA AAAAAAAAA---------AAAAAAAAA A-AA-AA-A---------A-AA-AA-A AAAAAAAAA---------AAAAAAAAA --------------------------- --------------------------- --------------------------- --------------------------- --------------------------- --------------------------- --------------------------- --------------------------- --------------------------- AAAAAAAAA---------AAAAAAAAA A-AA-AA-A---------A-AA-AA-A AAAAAAAAA---------AAAAAAAAA AAA---AAA---------AAA---AAA A-A---A-A---------A-A---A-A AAA---AAA---------AAA---AAA AAAAAAAAA---------AAAAAAAAA A-AA-AA-A---------A-AA-AA-A AAAAAAAAA---------AAAAAAAAA 
AAAAAAAAAAAAAAAAAAAAAAAAAAA A-AA-AA-AA-AA-AA-AA-AA-AA-A AAAAAAAAAAAAAAAAAAAAAAAAAAA AAA---AAAAAA---AAAAAA---AAA A-A---A-AA-A---A-AA-A---A-A AAA---AAAAAA---AAAAAA---AAA AAAAAAAAAAAAAAAAAAAAAAAAAAA A-AA-AA-AA-AA-AA-AA-AA-AA-A AAAAAAAAAAAAAAAAAAAAAAAAAAA AAAAAAAAA---------AAAAAAAAA A-AA-AA-A---------A-AA-AA-A AAAAAAAAA---------AAAAAAAAA AAA---AAA---------AAA---AAA A-A---A-A---------A-A---A-A AAA---AAA---------AAA---AAA AAAAAAAAA---------AAAAAAAAA A-AA-AA-A---------A-AA-AA-A AAAAAAAAA---------AAAAAAAAA AAAAAAAAAAAAAAAAAAAAAAAAAAA A-AA-AA-AA-AA-AA-AA-AA-AA-A AAAAAAAAAAAAAAAAAAAAAAAAAAA AAA---AAAAAA---AAAAAA---AAA A-A---A-AA-A---A-AA-A---A-A AAA---AAAAAA---AAAAAA---AAA AAAAAAAAAAAAAAAAAAAAAAAAAAA A-AA-AA-AA-AA-AA-AA-AA-AA-A AAAAAAAAAAAAAAAAAAAAAAAAAAA 
A-AA-AA-AA-AA-AA-AA-AA-AA-A --------------------------- A-AA-AA-AA-AA-AA-AA-AA-AA-A A-A---A-AA-A---A-AA-A---A-A --------------------------- A-A---A-AA-A---A-AA-A---A-A A-AA-AA-AA-AA-AA-AA-AA-AA-A --------------------------- A-AA-AA-AA-AA-AA-AA-AA-AA-A A-AA-AA-A---------A-AA-AA-A --------------------------- A-AA-AA-A---------A-AA-AA-A A-A---A-A---------A-A---A-A --------------------------- A-A---A-A---------A-A---A-A A-AA-AA-A---------A-AA-AA-A --------------------------- A-AA-AA-A---------A-AA-AA-A A-AA-AA-AA-AA-AA-AA-AA-AA-A --------------------------- A-AA-AA-AA-AA-AA-AA-AA-AA-A A-A---A-AA-A---A-AA-A---A-A --------------------------- A-A---A-AA-A---A-AA-A---A-A A-AA-AA-AA-AA-AA-AA-AA-AA-A --------------------------- A-AA-AA-AA-AA-AA-AA-AA-AA-A 
AAAAAAAAAAAAAAAAAAAAAAAAAAA A-AA-AA-AA-AA-AA-AA-AA-AA-A AAAAAAAAAAAAAAAAAAAAAAAAAAA AAA---AAAAAA---AAAAAA---AAA A-A---A-AA-A---A-AA-A---A-A AAA---AAAAAA---AAAAAA---AAA AAAAAAAAAAAAAAAAAAAAAAAAAAA A-AA-AA-AA-AA-AA-AA-AA-AA-A AAAAAAAAAAAAAAAAAAAAAAAAAAA AAAAAAAAA---------AAAAAAAAA A-AA-AA-A---------A-AA-AA-A AAAAAAAAA---------AAAAAAAAA AAA---AAA---------AAA---AAA A-A---A-A---------A-A---A-A AAA---AAA---------AAA---AAA AAAAAAAAA---------AAAAAAAAA A-AA-AA-A---------A-AA-AA-A AAAAAAAAA---------AAAAAAAAA AAAAAAAAAAAAAAAAAAAAAAAAAAA A-AA-AA-AA-AA-AA-AA-AA-AA-A AAAAAAAAAAAAAAAAAAAAAAAAAAA AAA---AAAAAA---AAAAAA---AAA A-A---A-AA-A---A-AA-A---A-A AAA---AAAAAA---AAAAAA---AAA AAAAAAAAAAAAAAAAAAAAAAAAAAA A-AA-AA-AA-AA-AA-AA-AA-AA-A AAAAAAAAAAAAAAAAAAAAAAAAAAA 
AAA---AAAAAA---AAAAAA---AAA A-A---A-AA-A---A-AA-A---A-A AAA---AAAAAA---AAAAAA---AAA --------------------------- --------------------------- --------------------------- AAA---AAAAAA---AAAAAA---AAA A-A---A-AA-A---A-AA-A---A-A AAA---AAAAAA---AAAAAA---AAA AAA---AAA---------AAA---AAA A-A---A-A---------A-A---A-A AAA---AAA---------AAA---AAA --------------------------- --------------------------- --------------------------- AAA---AAA---------AAA---AAA A-A---A-A---------A-A---A-A AAA---AAA---------AAA---AAA AAA---AAAAAA---AAAAAA---AAA A-A---A-AA-A---A-AA-A---A-A AAA---AAAAAA---AAAAAA---AAA --------------------------- --------------------------- --------------------------- AAA---AAAAAA---AAAAAA---AAA A-A---A-AA-A---A-AA-A---A-A AAA---AAAAAA---AAAAAA---AAA 
A-A---A-AA-A---A-AA-A---A-A --------------------------- A-A---A-AA-A---A-AA-A---A-A --------------------------- --------------------------- --------------------------- A-A---A-AA-A---A-AA-A---A-A --------------------------- A-A---A-AA-A---A-AA-A---A-A A-A---A-A---------A-A---A-A --------------------------- A-A---A-A---------A-A---A-A --------------------------- --------------------------- --------------------------- A-A---A-A---------A-A---A-A --------------------------- A-A---A-A---------A-A---A-A A-A---A-AA-A---A-AA-A---A-A --------------------------- A-A---A-AA-A---A-AA-A---A-A --------------------------- --------------------------- --------------------------- A-A---A-AA-A---A-AA-A---A-A --------------------------- A-A---A-AA-A---A-AA-A---A-A 
AAA---AAAAAA---AAAAAA---AAA A-A---A-AA-A---A-AA-A---A-A AAA---AAAAAA---AAAAAA---AAA --------------------------- --------------------------- --------------------------- AAA---AAAAAA---AAAAAA---AAA A-A---A-AA-A---A-AA-A---A-A AAA---AAAAAA---AAAAAA---AAA AAA---AAA---------AAA---AAA A-A---A-A---------A-A---A-A AAA---AAA---------AAA---AAA --------------------------- --------------------------- --------------------------- AAA---AAA---------AAA---AAA A-A---A-A---------A-A---A-A AAA---AAA---------AAA---AAA AAA---AAAAAA---AAAAAA---AAA A-A---A-AA-A---A-AA-A---A-A AAA---AAAAAA---AAAAAA---AAA --------------------------- --------------------------- --------------------------- AAA---AAAAAA---AAAAAA---AAA A-A---A-AA-A---A-AA-A---A-A AAA---AAAAAA---AAAAAA---AAA 
AAAAAAAAAAAAAAAAAAAAAAAAAAA A-AA-AA-AA-AA-AA-AA-AA-AA-A AAAAAAAAAAAAAAAAAAAAAAAAAAA AAA---AAAAAA---AAAAAA---AAA A-A---A-AA-A---A-AA-A---A-A AAA---AAAAAA---AAAAAA---AAA AAAAAAAAAAAAAAAAAAAAAAAAAAA A-AA-AA-AA-AA-AA-AA-AA-AA-A AAAAAAAAAAAAAAAAAAAAAAAAAAA AAAAAAAAA---------AAAAAAAAA A-AA-AA-A---------A-AA-AA-A AAAAAAAAA---------AAAAAAAAA AAA---AAA---------AAA---AAA A-A---A-A---------A-A---A-A AAA---AAA---------AAA---AAA AAAAAAAAA---------AAAAAAAAA A-AA-AA-A---------A-AA-AA-A AAAAAAAAA---------AAAAAAAAA AAAAAAAAAAAAAAAAAAAAAAAAAAA A-AA-AA-AA-AA-AA-AA-AA-AA-A AAAAAAAAAAAAAAAAAAAAAAAAAAA AAA---AAAAAA---AAAAAA---AAA A-A---A-AA-A---A-AA-A---A-A AAA---AAAAAA---AAAAAA---AAA AAAAAAAAAAAAAAAAAAAAAAAAAAA A-AA-AA-AA-AA-AA-AA-AA-AA-A AAAAAAAAAAAAAAAAAAAAAAAAAAA 
A-AA-AA-AA-AA-AA-AA-AA-AA-A --------------------------- A-AA-AA-AA-AA-AA-AA-AA-AA-A A-A---A-AA-A---A-AA-A---A-A --------------------------- A-A---A-AA-A---A-AA-A---A-A A-AA-AA-AA-AA-AA-AA-AA-AA-A --------------------------- A-AA-AA-AA-AA-AA-AA-AA-AA-A A-AA-AA-A---------A-AA-AA-A --------------------------- A-AA-AA-A---------A-AA-AA-A A-A---A-A---------A-A---A-A --------------------------- A-A---A-A---------A-A---A-A A-AA-AA-A---------A-AA-AA-A --------------------------- A-AA-AA-A---------A-AA-AA-A A-AA-AA-AA-AA-AA-AA-AA-AA-A --------------------------- A-AA-AA-AA-AA-AA-AA-AA-AA-A A-A---A-AA-A---A-AA-A---A-A --------------------------- A-A---A-AA-A---A-AA-A---A-A A-AA-AA-AA-AA-AA-AA-AA-AA-A --------------------------- A-AA-AA-AA-AA-AA-AA-AA-AA-A 
AAAAAAAAAAAAAAAAAAAAAAAAAAA A-AA-AA-AA-AA-AA-AA-AA-AA-A AAAAAAAAAAAAAAAAAAAAAAAAAAA AAA---AAAAAA---AAAAAA---AAA A-A---A-AA-A---A-AA-A---A-A AAA---AAAAAA---AAAAAA---AAA AAAAAAAAAAAAAAAAAAAAAAAAAAA A-AA-AA-AA-AA-AA-AA-AA-AA-A AAAAAAAAAAAAAAAAAAAAAAAAAAA AAAAAAAAA---------AAAAAAAAA A-AA-AA-A---------A-AA-AA-A AAAAAAAAA---------AAAAAAAAA AAA---AAA---------AAA---AAA A-A---A-A---------A-A---A-A AAA---AAA---------AAA---AAA AAAAAAAAA---------AAAAAAAAA A-AA-AA-A---------A-AA-AA-A AAAAAAAAA---------AAAAAAAAA AAAAAAAAAAAAAAAAAAAAAAAAAAA A-AA-AA-AA-AA-AA-AA-AA-AA-A AAAAAAAAAAAAAAAAAAAAAAAAAAA AAA---AAAAAA---AAAAAA---AAA A-A---A-AA-A---A-AA-A---A-A AAA---AAAAAA---AAAAAA---AAA AAAAAAAAAAAAAAAAAAAAAAAAAAA A-AA-AA-AA-AA-AA-AA-AA-AA-A AAAAAAAAAAAAAAAAAAAAAAAAAAA 
