model
size = 11 32 11, scale = 0.05, origin = -y
material 
  colors = A:#F00000 B:#00B205 C:#FEEF02 D:#FFE11D E:#1C00EC F:#F1F1F1 G:#FCFCFC H:#E90101
voxels
52-10(B10-)12(A10-)A87-5(B10-)7(2B9-)10(2A9-)3(A10-)A37-5D56-B10-7(2B9-)BC3(9-2C)9-AC9(9-2A)9-3(A10-)A14-2D3-2D13-9(B10-)B9-2B9-2C9-CA3(9-2A)9-CA9-2C5(9-2A)2(9-3(A10-)A)2-2D5-2D56-5(B10-)B9-2B9-2C9-2A9-FG9-2E9-FG9-2A9-2C6(9-2A)9-2(A10-)A9-2A9-2(A10-)A2-D7-D23-8(B10-)B9-2B9-2C9-2A9-2E9-FG9-2E9-2A9-2C7(9-2A)9-A10-A2(9-2A)9-A10-A2-D7-D56-5(B10-)B9-2B9-2C9-2A9-FG9-2E9-FG9-2A9-2C6(9-2A)9-2(A10-)A9-2A9-2(A10-)A2-D7-D12-9(B10-)B9-2B9-2C9-AC3(9-2A)9-AC9-2C5(9-2A)2(9-3(A10-)A)2-2D5-2D54-B10-7(2B9-)5(2C9-)9(2A9-)3(A10-)H14-2D3-2D33-5(B10-)7(2B9-)10(2A9-)3(A10-)A37-5D56-10(B10-)12(A10-)A57-
