model
size = 11 32 11, scale = 0.05, origin = -y
material 
  colors = A:#FB0101 B:#FFF C:#FDFDFD D:#0011EA E:#FFE11D F:#FF220B
voxels
52-D2(10-B3(10-D))14(10-A)87-D10-B3(10-D)10-CB3(9-2D)9-CB9-2D11(9-CB)9-3(B10-)B37-5E56-D10-2(CB3(9-2D)9-)8(2A9-)4(FA9-)2A9-3(A10-)A14-2E3-2E13-2(B2(10-D)10-)D10-B2(10-D)2(9-2D9-CB)9(9-CB)2(9-3(B10-)B)2-2E5-2E56-D10-B3(10-D)10-B3(9-2D)8(9-2A)2(9-FA)2(9-2A9-2(A10-)A)2-E7-E23-2(D10-)B3(10-D)10-B2(10-D)2(9-2D9-2C)11(9-CB)9-B10-B9-CB9-2B9-B10-B2-E7-E56-5(A10-)A11(9-2A)2(9-FA)2(9-2A9-2(A10-)A)2-E7-E12-9(B10-)13(B9-C)2(B9-3(B10-))B2-2E5-2E54-A10-17(2A9-)3(FA9-)2A9-3(A10-)A14-2E3-2E33-4(B10-)C10-17(CB9-)3(B10-)B37-5E56-22(A10-)A57-
