model
size = 18 32 21, scale = 0.05, origin = -y
material 
  colors = A:#039 B:#EEE C:#3CF D:#3CC E:#E00 F:#111 G:#A00 H:#800
voxels
63-G522-A16-A35-A34-2A485-3A15-2A16-2A15-3A16-2A15-AG34-G176-8A10-A6BA10-AB4CBA9-3(2ABC2FCB2A8-)2ABCFBCB2A8-2AB4CB2A9-A6BA10-8A157-A17-2A16-2A15-2A16-3A158-6A10-10A8-2A6-2A7-13(3A6-)3A7-10A10-6D211-2(2A16-)A18-G4-A99-8A8-12A6-12A5-6(14A4-)14A5-12A8-8A12-4A212-A17-2A4-A11-2A3-3A15-2A64-6A10-10A6-2(14A4-)14A3-4(16A2-)16A3-14A4-14A6-10A10-6A14-2A219-A11-A5-2A10-4A-2A11-5A13-4A14-4A12-8A8-12A4-9(16A2-)16A4-12A8-8A12-4D44-2A17-A53-A17-2A2(17-A)74-2(A4-2A11-)A3B-A12-6A10-10A6-14A3-16A2-B7(2-10A2(2-B))2-10A2-B2-16A3-D12AD6-10A10-6A13-4A25-4A15-3A15-4A10-A5-2(2A15-)G2A2(17-A)73-2A5-A10-A6-A10-A2-B3-A10-A2EA2H2A8-12A5-14A3-16A2-B2-10A2-B2-C5(2-10A2(2-C))2-10A2-C2-B2-10A2-B2-16A3-D12AD5-12A8-D6AD11-6A14-2D29-A11-A4-3A10-A5-A10-A24-A29-A5-2A16-G2A9-G6-2A15-3A6-A9-2A6-2AG7-2A6-2A7-3AB5-2A8-3A2EHE3A7-12A5-14A3-16A2-B2-10A2-B2-C2-10A2-C2-F3(2-10A2(2-F))2-10A2-F2-C2-10A2-C2-B2-10A2-B2-16A3-D12AD5-12A7-AD6ADA10-6A13-D2AD22-A17-A5-A11-3A14-2A16-2A5-A11-AG3-GA11-A5-2A10-A6-2A9-A6-A8-4A5-2A6-4A2(6-2A)7-3A6-2A8-2A2B4-2A7-5AE2H3A7-12A5-14A3-16A2-B2-10A2-B2-C2-10A2-C2-F2(2-10A2(2-F))2-10A2-F2-B2-10A2-B2-C2-10A2-C2-B2-10A2-B2-16A3-D12AD5-12A7-AD6ADA10-6A13-D2AD22-A52-2AG16-A17-A53-G6-A8-2A7-A9-2A7-2(A6-A10-)AB2-BH-A10-2A2E4A8-12A5-14A3-16A2-B2-10A2-B2-C5(2-10A2(2-C))2-10A2-C2-B2-10A2-B2-16A3-D12AD5-12A8-D6AD11-6A14-2D59-A17-A132-3A4-A11-2A4-A12-A2-H-A12-A2EAHA10-10A6-14A3-16A2-B7(2-10A2(2-B))2-10A2-B2-16A3-D12AD6-10A10-6A13-4A228-6A13-5A2(14-4A)12-8A8-12A4-9(16A2-)16A4-12A8-8A12-4D249-G2A15-3A16-2A31-6A10-10A6-2(14A4-)14A3-4(16A2-)16A3-14A4-14A6-10A10-6A14-2A180-A4(16-2A)17-A66-8A8-12A2(6-3A)5-6(4A6-4A4-)4A-3B2-4A5-12A8-8A12-4A160-2(A17-)2A16-A18-G16-A18-A85-6A10-10A8-2A6-2A7-12(3A6-)3A-3B2-3A7-10A10-6D177-A17-2A16-2A174-8A10-A6BA10-AB4ABA9-3(2ABA2EAB2A8-)2ABABEAB2A8-2AB4AB2A9-A6BA10-8A104-2(A17-)2A16-3A15-A17-2A16-2AG15-2A193-6B12-B4C3(B12-BC2EC)B12-BCBECB12-B4CB12-6B141-3(A17-)A35-2A16-G467-A548-
