model
size = 26 28 18, scale = 0.05, origin = -y
material 
  colors = A:#444 B:#111 C:#555 D:#888 E:#E00 F:#222 G:#606
voxels
-------BBBBBBBBBBBB------- -------BBBBBBBBBBBB------- ------BBBBBBBBBBBBBB------ -----BBBBBBBBBBBBBBBB----- ------BBBBBBBBBBBBBB------ ------BBBBBBBBBBBBBB------ ------BBBBBBBBBBBBBB------ ------BBBBBBBBBBBBBB------ ------BBBBBBBBBBBBBB------ ------BBBBBEBBEBBBBB------ ------BBBBBEBBEBBBBB------ ------BBBBBEBBEBBBBB------ ------BBBBB----BBBBB------ ------B------------B------ ------BBBBBEBBEBBBBB------ ------BBBBBEBBEBBBBB------ -----BBBBBBEBBEBBBBBB----- ----BBBBBBBBBBBBBBBBBB---- ---BBBBBBBBBBBBBBBBBBBB--- -BBBBBBBBBBBBBBBBBBBBBBBB- BBBBBBBBBBBBBBBBBBBBBBBBBB --BBBBBBBBBBBBBBBBBBBBBB-- ---BBBBBBBBBBBBBBBBBBBB--- -----BBBB--------BBBB----- -------------------------- -------------------------- -------------------------- -------------------------- 
-------AAAAAAAAAAAA------- ------AAAAAAAAAAAAAA------ -----AAAAAAAAAAAAAAAA----- ----AAAAAAAAAAAAAAAAAA---- -----BAAAAAAAAAAAAAAB----- -----AAAAAAAAAAAAAAAA----- -----BAAAAAAAAAAAAAAB----- -----AAAAAAAAAAAAAAAA----- -----AAAAAAAAAAAAAAAA----- -----BAAAAAAAAAAAAAAB----- -----AAAAAAAAAAAAAAAA----- -----AAAAAAAGGAAAAAAA----- -----BAAAAGE--EGAAAAB----- ------AEEE------EEEA------ ------AAAAAAAAAAAAAA------ -----AAAAAAAAAAAAAAAA----- ----AAAAAAAAAAAAAAAAAA---- ---AAAAA----------AAAAA--- --AAAAAA----AA----AAAAAA-- -BAAAAAAAAAAAAAAAAAAAAAAB- BAAAAAAAAAAAAAAAAAAAAAAAAB BDAAAAAAAAAAAAAAAAAAAAAADB --DAAAAAAAAAAAAAAAAAAAAD-- ---DDAAAACBCBBCBCAAAADD--- -----BBBB--------BBBB----- -------------------------- -------------------------- -------------------------- 
------BAAAAAAAAAAAAB------ -----BAAAAAAAAAAAAAAB----- ----BAAAAAAAAAAAAAAAAB---- ---AAAAAAAAAAAAAAAAAAAA--- ----BBAAAAAAAAAAAAAABB---- ----AAAAAAAAAAAAAAAAAA---- ----BBAAAAAAAAAAAAAABB---- ----AAAAAAAAAAAAAAAAAA---- ----AAAAAAAAAAAAAAAAAA---- ----BBAAAAAAAAAAAAAABB---- ----AAAAAAAAAAAAAAAAAA---- ----BAAAAAAAAAAAAAAAAB---- -----AAAAAAAEEAAAAAAA----- ------AAAAEEEEEEAAAA------ -----AAAAAAAAAAAAAAAA----- ----AAAAAAAAAAAAAAAAAA---- --AAAAAAA--------AAAAAAA-- --AAAAAA----------AAAAAA-- -BAAAAA------------AAAAAB- -BAAAA------AA------AAAAB- BAAAAAAAAAAAAAAAAAAAAAAAAB BAAAAAAAAAAAAAAAAAAAAAAAAB BDAAAAAAAAAAAAAAAAAAAAAADB --BAAAAAAABABBABAAAAAAAB-- ---DDAAAACBCBBCBCAAAADD--- -----BBBB--------BBBB----- -------------------------- -------------------------- 
-----AAA----------AAA----- ----BAAA----------AAAB---- ---AAAAA----------AAAAA--- ---BAAAA----------AAAAB--- ---BBBAA----------AABBB--- ---AAAAA----------AAAAA--- ---BBBAA----------AABBB--- ---AAAAA----------AAAAA--- ---AAAAA----------AAAAA--- ---BBBAA----------AABBB--- ---BAAAA----------AAAAB--- ----AAAA----------AAAA---- -----BAA----------AAB----- ------AA----------AA------ ----AAAA----------AAAA---- ---AAAAA----------AAAAA--- --AAAAAA----------AAAAAA-- -BAAAAA------------AAAAAB- -BAAAA--------------AAAAB- -BAAA----------------AAAB- BAAA--------AA--------AAAB BAAAAAAAAAAAAAAAAAAAAAAAAB BAAAAAAAACCCCCCCCAAAAAAAAB BDAAAAAAACBCBBCBCAAAAAAADB --DAAAAAACBCBBCBCAAAAAAD-- ---BDAAAACBCBBCBCAAAADB--- -----BBBB--------BBBB----- -------------------------- 
----BAA------------AAB---- ---AAAA------------AAAA--- ---BAAA------------AAAB--- ---AAAA------------AAAA--- --BAAAA------------AAAAB-- --BAAAA------------AAAAB-- --BAAAA------------AAAAB-- --BAAAA------------AAAAB-- --BAAAA------------AAAAB-- --BAAAA------------AAAAB-- --BAAAA------------AAAAB-- ----BAA------------AAB---- -----AA------------AA----- ------A------------A------ ---AAAA------------AAAA--- --AAAAA------------AAAAA-- -BAAAAA------------AAAAAB- -BAAAA--------------AAAAB- -BAAA----------------AAAB- -BAA------------------AAB- BAA--------------------AAB BA----------AA----------AB BAAAAAAAACCCCCCCCAAAAAAAAB BDAAAAAAACBCBBCBCAAAAAAADB --DAAAAAACBCBBCBCAAAAAAD-- ---DBAAAACBCBBCBCAAAABD--- -----BBBB--------BBBB----- -------------------------- 
---AAA--------------AAA--- ---BAA--------------AAB--- ---AAA--------------AAA--- ---AAA--------------AAA--- --BAAA--------------AAAB-- --BAAA--------------AAAB-- --BAAA--------------AAAB-- --BAAA--------------AAAB-- --BAAA--------------AAAB-- --BAAA--------------AAAB-- --BBAA--------------AABB-- ----AA--------------AA---- -----B--------------B----- -------------------------- --AAAA--------------AAAA-- --AAAA--------------AAAA-- -BBAAA--------------AAABB- -BABA----------------ABAB- -BAA------------------AAB- -BA--------------------AB- BA----------------------AB B------------------------B B-----------AA-----------B BAAAAAAAAABABBABAAAAAAAAAB BBBBBAAAAABABBABAAAAABBBBB --BBBAAAAABABBABAAAAABBB-- ---BBAAAACBCBBCBCAAAABB--- -----BBBB--------BBBB----- 
---BAA--------------AAB--- ---AAA--------------AAA--- ---BAA--------------AAB--- ---AAA--------------AAA--- ---AAA--------------AAA--- --BAAA--------------AAAB-- --BAAA--------------AAAB-- --BAAA--------------AAAB-- --BAAA--------------AAAB-- --BAAA--------------AAAB-- ---AAA--------------AAA--- ----BA--------------AB---- -----A--------------A----- -------------------------- --AAAA--------------AAAA-- --BBBB--------------BBBB-- -------------------------- -------------------------- -------------------------- -------------------------- -------------------------- -------------------------- -------------------------- BAAAAAAAAABCBBCBAAAAAAAAAB BDAAAAAAAABCBBCBAAAAAAAADB --DAAAAAAABCBBCBAAAAAAAD-- ---DDAAAACBCBBCBCAAAADD--- -----BBBB--------BBBB----- 
---AAA--------------AAA--- ---BAA--------------AAB--- ---BAA--------------AAB--- ---BAA--------------AAB--- ---AAA--------------AAA--- --BAAA--------------AAAB-- --BAAA--------------AAAB-- --BAAA--------------AAAB-- --BAAA--------------AAAB-- --BAAA--------------AAAB-- ---BAA--------------AAB--- ----AA--------------AA---- -----B--------------B----- -------------------------- --AAAA--------------AAAA-- ---AA----------------AA--- -------------------------- -------------------------- -------------------------- -------------------------- -------------------------- -------------------------- -------------------------- BAAAAAAAAC------CAAAAAAAAB BBBBBAAAAC------CAAAABBBBB --BBBAAAAC------CAAAABBB-- ---BBAAAAC------CAAAABB--- -----BBBB--------BBBB----- 
----AA--------------AA---- ---AAA--------------AAA--- ---AAA--------------AAA--- ---BAA--------------AAB--- ---AAA--------------AAA--- ---AAA--------------AAA--- --BAAA--------------AAAB-- --BAAA--------------AAAB-- --BAAA--------------AAAB-- ---AAA--------------AAA--- ---AAA--------------AAA--- ----BA--------------AB---- -----A--------------A----- -------------------------- --AAAA--------------AAAA-- ---BB----------------BB--- -------------------------- -------------------------- -------------------------- -------------------------- -------------------------- -------------------------- -------------------------- BAAAAAAAAC------CAAAAAAAAB BDAAAAAAAC------CAAAAAAADB --DAAAAAAC------CAAAAAAD-- ---DDAAAAB------BAAAADD--- -----BBBB--------BBBB----- 
----AA--------------AA---- ---AAA--------------AAA--- ---BAA--------------AAB--- ---AAA--------------AAA--- ---BAA--------------AAB--- ---BAA--------------AAB--- --BAAA--------------AAAB-- --BAAA--------------AAAB-- --BAAA--------------AAAB-- ---BAA--------------AAB--- ---BAA--------------AAB--- ----AA--------------AA---- -----B--------------B----- -------------------------- --AAAA--------------AAAA-- ---AA----------------AA--- -------------------------- -------------------------- -------------------------- -------------------------- -------------------------- -------------------------- -------------------------- BAAAAAAAAC------CAAAAAAAAB BBBBBAAAAC------CAAAABBBBB --BBBAAAAC------CAAAABBB-- ---BBAAAAC------CAAAABB--- -----BBBB--------BBBB----- 
----AA--------------AA---- ---BAA--------------AAB--- ---AAA--------------AAA--- ---AAA--------------AAA--- ---AAA--------------AAA--- ---AAA--------------AAA--- --BAAA--------------AAAB-- --BAAA--------------AAAB-- --BAAA--------------AAAB-- ---AAA--------------AAA--- ---AAA--------------AAA--- ----BA--------------AB---- -----A--------------A----- -------------------------- --AAAA--------------AAAA-- ---BB----------------BB--- -------------------------- -------------------------- -------------------------- -------------------------- -------------------------- -------------------------- -------------------------- BAAAAAAAAC------CAAAAAAAAB BDAAAAAAAC------CAAAAAAADB --DAAAAAAC------CAAAAAAD-- ---DDAAAAB------BAAAADD--- -----BBBB--------BBBB----- 
---BAA--------------AAB--- ---AAA--------------AAA--- ---BAA--------------AAB--- ---AAA--------------AAA--- ---AAA--------------AAA--- --BAAA--------------AAAB-- --BAAA--------------AAAB-- --BAAA--------------AAAB-- --BAAA--------------AAAB-- --BAAA--------------AAAB-- ---BAA--------------AAB--- ----AA--------------AA---- -----B--------------B----- -------------------------- --AAAA--------------AAAA-- ---AA----------------AA--- -------------------------- -------------------------- -------------------------- -------------------------- -------------------------- -------------------------- -------------------------- BAAAAAAAAC------CAAAAAAAAB BBBBBAAAAC------CAAAABBBBB --BBBAAAAC------CAAAABBB-- ---BBAAAAC------CAAAABB--- -----BBBB--------BBBB----- 
---AAA--------------AAA--- ---BAA--------------AAB--- ---AAA--------------AAA--- ---BAA--------------AAB--- ---AAA--------------AAA--- --BAAA--------------AAAB-- --BAAA--------------AAAB-- --BAAA--------------AAAB-- --BAAA--------------AAAB-- --BAAA--------------AAAB-- ---AAA--------------AAA--- ----BA--------------AB---- -----A--------------A----- -------------------------- --BAAA--------------AAAB-- --BBBB--------------BBBB-- -------------------------- -------------------------- -------------------------- -------------------------- -------------------------- -------------------------- -------------------------- BAAAAAAAAACCCCCCAAAAAAAAAB BDAAAAAAAABCBBCBAAAAAAAADB --DAAAAAAABCBBCBAAAAAAAD-- ---DDAAAACBCBBCBCAAAADD--- -----BBBB--------BBBB----- 
---BAA--------------AAB--- ---AAA--------------AAA--- ---BAA--------------AAB--- ---AAA--------------AAA--- --BAAA--------------AAAB-- --BAAA--------------AAAB-- --BAAA--------------AAAB-- --BAAA--------------AAAB-- --BAAA--------------AAAB-- --BAAA--------------AAAB-- --BBAA--------------AABB-- ----AA--------------AA---- -----B--------------B----- -------------------------- --AAAA--------------AAAA-- --BAAA--------------AAAB-- -BBAAA--------------AAABB- -BABA----------------ABAB- -BAA------------------AAB- -BA--------------------AB- BA----------------------AB B------------------------B B-----------AA-----------B BAAAAAAAAAAAAAAAAAAAAAAAAB BBBBBAAAAABABBABAAAAABBBBB --BBBAAAAABABBABAAAAABBB-- ---BBAAAACBCBBCBCAAAABB--- -----BBBB--------BBBB----- 
-----BA------------AB----- ----BAA------------AAB---- ---AAAA------------AAAA--- ---BAAA------------AAAB--- --BAAAA------------AAAAB-- --BAAAA------------AAAAB-- --BAAAA------------AAAAB-- --BAAAA------------AAAAB-- --BAAAA------------AAAAB-- --BAAAA------------AAAAB-- --BAAAA------------AAAAB-- ----BAA------------AAB---- -----AA------------AA----- ------A------------A------ --BBBBB------------AABBB-- --AAABB------------AAAAA-- -BAAABB------------AAAAAB- -BAAABB------------AAAAAB- -BAAAB--------------AAAAB- -BAAA----------------AAAB- BAAA------------------AAAB BAA---------AA---------AAB BAAAABBBBAAAAAAAAAAAAAAAAB BDAAABBBBAAAAAAAAAAAAAAADB --DAABBBBABABBABAAAAAAAD-- ---FFBBBBCBCBBCBCAAAAFF--- -----BBBB--------BBBB----- -------------------------- 
------AA----------AA------ -----AAA----------AAA----- ----AAAA----------AAAA---- ---BAAAA----------AAAAB--- ---ABAAA----------AAABA--- ---BAAAA----------AAAAB--- ---ABAAA----------AAABA--- ---BAAAA----------AAAAB--- ---ABAAA----------AAABA--- ---BAAAA----------AAAAB--- ---ABAAA----------AAABA--- ----AAAA----------AAAA---- -----BAA----------AAB----- ------AA----------AA------ ---BBBBB----------AAABB--- ---AABBB----------AAAAA--- --BBABBB----------AAAABB-- --AAABBB----------AAAAAA-- -BAAABBB----------AAAAAAB- -BAAABB------------AAAAAB- BAAAAB------AA------AAAAAB BAAAABBBBAAAAAAAAAAAAAAAAB BAAAABBBBAAAAAAAAAAAAAAAAB BBAAABBBBAAAAAAAAAAAAAAABB --BAABBBBABABBABAAAAAAAB-- ---FFBBBBCBCBBCBCAAAAFF--- -----BBBB--------BBBB----- -------------------------- 
-------AAAAAAAAAAAA------- ------AAAAAAAAAAAAAA------ -----AAAAAAAAAAAAAAAA----- ----AAAAAAAAAAAAAAAAAA---- -----AAAAAAAAAAAAAAAA----- -----BAAAAAAAAAAAAAAB----- -----AAAAAAAAAAAAAAAA----- -----BAAAAAAAAAAAAAAB----- -----AAAAAAAAAAAAAAAA----- -----BAAAAAAAAAAAAAAB----- -----AAAAAAAAAAAAAAAA----- -----BAAAAAAAAAAAAAAB----- -----AAAAAAAAAAAAAAAA----- ------AAAAAAAAAAAAAA------ ----BAAAAAAAAAAAAAAAAB---- ----AAAAAAAAAAAAAAAAAA---- ---BAAAAAAAAAAAAAAAAAAB--- ---AAAAAAAAAAAAAAAAAAAA--- --AAAAAAAAAAAAAAAAAAAAAA-- -BAAAAAAAAAAAAAAAAAAAAAAB- BAAAAAAAAAAAAAAAAAAAAAAAAB BAAAAAAAAAAAAAAAAAAAAAAAAB BAAAAAAAAAAAAAAAAAAAAAAAAB BDAAAAAAAAAAAAAAAAAAAAAADB --DAAAAAACBCBBCBCAAAAAAD-- ---FFFFFF--------FFFFFF--- -------------------------- -------------------------- 
--------BBBBBBBBBB-------- -------BBBBBBBBBBBB------- ------BBBBBBBBBBBBBB------ -----BBBBBBBBBBBBBBBB----- ------BBBBBBBBBBBBBB------ ------BBBBBBBBBBBBBB------ ------BBBBBBBBBBBBBB------ ------BBBBBBBBBBBBBB------ ------BBBBBBBBBBBBBB------ ------BBBBBBBBBBBBBB------ ------BBBBBBBBBBBBBB------ ------BBBBBBBBBBBBBB------ ------BBBBB----BBBBB------ ------B------------B------ ------BBBBBBBBBBBBBB------ -----BBBBBBBBBBBBBBBB----- ----BBBBBBBBBBBBBBBBBB---- ----BBBBBBBBBBBBBBBBBB---- ---BBBBBBBBBBBBBBBBBBBB--- --BBBBBBBBBBBBBBBBBBBBBB-- BBBBBBBBBBBBBBBBBBBBBBBBBB BBBBBBBBBBBBBBBBBBBBBBBBBB BBBBBBBBBBBBBBBBBBBBBBBBBB BBBBBBBBBBBBBBBBBBBBBBBBBB ---BBBBBBBBBBBBBBBBBBBB--- -------------------------- -------------------------- -------------------------- 
