model
size = 21 17 21, scale = 0.05, origin = -y
material 
  colors = A:#C25100 B:#EFEFEF C:#000
voxels
--------------------- --------------------- --------------------- --------------------- -------BBBCBBB------- -------BBBCBBB------- -------BBBCBBB------- -------BBBCBBB------- --------BBCBB-------- ---------BCB--------- --------------------- --------------------- --------------------- --------------------- --------------------- --------------------- --------------------- 
----------B---------- ----------B---------- --------------------- --------------------- -----BB-------BB----- -----BB-------BB----- -----BB-------BB----- -----BB-------BB----- -----BBB-----BBB----- ------BBB---BBB------ -------BBBCBBB------- --------BBCBB-------- --------------------- --------------------- --------------------- --------------------- --------------------- 
-------BBBBBBB------- ------B-------B------ -----B---------B----- ----BB---------BB---- ----BB----------B---- ----BB----------B---- ----BB----------B---- ----BB----------B---- ----BB----------B---- ----BB---------BB---- -----BB-------BB----- ------BBCCCCCBB------ -------BBBCBBB------- --------------------- --------------------- --------------------- --------------------- 
-----BB-------BB----- ---CBB---------BBC--- ---CB-----------BC--- ---CC-----------BC--- ---CC------------C--- ---CC------------C--- ---CC------------C--- ---CC------------C--- ---CC------------C--- ---CC------------C--- ---CB-----------BC--- ---CBBCCCCCCC-CBBC--- -----BBAAAAAACBB----- -------BBBCBBB------- --------------------- --------------------- --------------------- 
----B-----------B---- ---BC-----------CB--- ---BC-----------CB--- --BAC------------CB-- --BAC------------CB-- --BAC------------CB-- --BAC------------CB-- --BAC------------CB-- --BAC------------CB-- --BAC------------CB-- ---BC------------B--- ---BACCCCCCCCCCCCB--- ----CAAAAAAAAAAAC---- ----CBBAAAAAAABBC---- -------BBBCBBB------- --------------------- --------------------- 
---BB-----------BB--- ---BC-----------CB--- --BAC-----------CAB-- --BAC------------CB-- -BAAC------------CAB- -BAAC------------CAB- -BAAC------------CAB- -BAAC------------CAB- -BAAC------------CAB- --BAC------------CB-- --BAC------------CB-- ---BACCCCCCCCCCCCB--- ---BAAAAAAABAAAAAB--- ----BCAAAAAAAAAAB---- -----CBBAAAAABBC----- --------BBCBB-------- --------------------- 
---BB-----------BB--- --BAC-----------CAB-- --BAC-----------CAB-- -BAAC------------CAB- -BAAC------------CAB- -BAAC------------CAB- -BAAC------------CAB- -BAAC------------CAB- -BAAC------------CAB- -BAAC------------CAB- --BAC------------CB-- --BAACCCCC--CCCCCAB-- ---BAAAAAACCBAAAAB--- ----BAAAAAACAAAAB---- -----BCCAAAAACCB----- -------CCCCCCC------- --------------------- 
--BBB-----------BBB-- --BAC-----------CAB-- -BAAC-----------CAAB- -BAAC------------CAB- -BAAC------------CAB- BAAAC------------CAAB BAAAC------------CAAB BAAAC------------CAAB -BAAC------------CAB- -BAAC------------CAB- -BAAC------------CAB- --BAACCCCCCCCCCCCAB-- --BAAAAAAAABAAAAAAB-- ---BAAAAAAAAAAAAAB--- ----BBAAAAAAAAABB---- ------BBBAAABBB------ ---------BCB--------- 
--BBB-----------BBB-- -BAAC-----------CAAB- -BAAC-----------CAAB- -BAAC------------CAB- BAAAC------------CAAB BAAAC------------CAAB BAAAC------------CAAB BAAAC------------CAAB BAAAC------------CAAB -BAAC------------CAB- -BAAC------------CAB- -BAAACCCCCCCCCCCCAAB- --BAAAAAAAAAAAAAAAB-- ---BAAAAAAAAAAAAAB--- ----BAAAAAAAAAAAB---- -----BBBAAAAABBB----- --------BBCBB-------- 
--BBB-----------BBB-- -BAAC-----------CAAB- -BAAC-----------CAAB- BAAAC------------CAAB BAAAC------------CAAB BAAAC------------CAAB BAAAC------------CAAB BAAAC------------CAAB BAAAC------------CAAB BAAAC------------CAAB -BAAC------------CAB- -BAAACCCCCCCCCCCCAAB- --BAAAAAAAAAAAAAAAB-- ---BAAAAAAAAAAAAAB--- ----BAAAAAAAAAAAB---- -----BBAAAAAAABB----- -------BBBCBBB------- 
--CBB-----------BBC-- -CAAC-----------CAAC- -CAAC-----------CAAC- CAAAC------------CAAC CAAAC------------CAAC CAAAC------------CAAC CAAAC------------CAAC CAAAC------------CAAC CAAAC------------CAAC CAAAC------------CAAC -CAAC------------CAC- -CAAACCCCCCCCCCCCAAC- --CAAAAAAAAAAAAAAAC-- ---CAAAAAAAAAAAAAC--- ----CAAAAAAAAAAAC---- -----CCAAAAAAACC----- -------CCCCCCC------- 
--BBB-----------BBB-- -BAAC-----------CAAB- -BAAC-----------CAAB- BAAAC------------CAAB BAAAC------------CAAB BAAAC------------CAAB BAAAC------------CAAB BAAAC------------CAAB BAAAC------------CAAB BAAAC------------CAAB -BAAC------------CAB- -BAAACCCCCCCCCCCCAAB- --BAAAAAAAAAAAAAAAB-- ---BAAAAAAAAAAAAAB--- ----BAAAAAAAAAAAB---- -----BBAAAAAAABB----- -------BBBCBBB------- 
--BBB-----------BBB-- -BAAC-----------CAAB- -BAAC-----------CAAB- -BAAC------------CAB- BAAAC------------CAAB BAAAC------------CAAB BAAAC------------CAAB BAAAC------------CAAB BAAAC------------CAAB -BAAC------------CAB- -BAAC------------CAB- -BAAACCCCCCCCCCCCAAB- --BAAAAAAAAAAAAAAAB-- ---BAAAAAAAAAAAAAB--- ----BAAAAAAAAAAAB---- -----BBBAAAAABBB----- --------BBCBB-------- 
--BBB-----------BBB-- --BAC-----------CAB-- -BAAC-----------CAAB- -BAAC------------CAB- -BAAC------------CAB- BAAAC------------CAAB BAAAC------------CAAB BAAAC------------CAAB -BAAC------------CAB- -BAAC------------CAB- -BAAC------------CAB- --BAACCCCCCCCCCCCAB-- --BAAAAAAAAAAAAAAAB-- ---BAAAAAAAAAAAAAB--- ----BBAAAAAAAAABB---- ------BBBAAABBB------ ---------BCB--------- 
---BB-----------BB--- --BAC-----------CAB-- --BAC-----------CAB-- -BAAC------------CAB- -BAAC------------CAB- -BAAC------------CAB- -BAAC------------CAB- -BAAC------------CAB- -BAAC------------CAB- -BAAC------------CAB- --BAC------------CB-- --BAACCCCCCCCCCCCAB-- ---BAAAAAAAAAAAAAB--- ----BAAAAAAAAAAAB---- -----BCCAAAAACCB----- -------CCCCCCC------- --------------------- 
---BB-----------BB--- ---BC-----------CB--- --BAC-----------CAB-- --BAC------------CB-- -BAAC------------CAB- -BAAC------------CAB- -BAAC------------CAB- -BAAC------------CAB- -BAAC------------CAB- --BAC------------CB-- --BAC------------CB-- ---BACCCCCCCCCCCCB--- ---BAAAAAAAAAAAAAB--- ----BCAAAAAAAAAAB---- -----CBBAAAAABBC----- --------BBCBB-------- --------------------- 
----CBB-------BBC---- ---BCC---------CCB--- ---BC-----------CB--- --BAC------------CB-- --BAC------------CB-- --BAC------------CB-- --BAC------------CB-- --BAC------------CB-- --BAC------------CB-- --BAC------------CB-- ---BC-----------CB--- ---BACCCCCCCCCCCCB--- ----CAAAAAAAAAAAC---- ----CBBAAAAAAABBC---- -------BBBCBBB------- --------------------- --------------------- 
-----BBBBBBBBBBB----- ---CBBCCCCCCCCCBBC--- ---CBCCCCCCCCCCCBC--- ---CCC---------CCC--- ---CC-----------CC--- ---CC-----------CC--- ---CC-----------CC--- ---CC-----------CC--- ---CC-----------CC--- ---CCC---------CCC--- ---CBCC-------CCBC--- ---CBBCCCCCCCCCBBC--- -----BBAAAAAAABB----- -------BBBCBBB------- --------------------- --------------------- --------------------- 
-------BBBCBBB------- ------BBAAAAABB------ -----BBAACCCAABB----- ----BBCCC---CCCBB---- ----BCCC-----CCCB---- ----BCC------CCCB---- ----BCC------CCCB---- ----BCC------CCCB---- ----BCCC-----CCCB---- ----BBCCC---CCCBB---- -----BBCCCCCCCBB----- ------BBCCCCCBB------ -------BBBCBBB------- --------------------- --------------------- --------------------- --------------------- 
--------------------- --------BBCBB-------- -------BBBCBBB------- ------BBBCCCBBB------ -----BBBCCCCCBBB----- -----BBCCCCCCBBB----- -----BBCCCCCCBBB----- -----BBCCCCCCBBB----- -----BBBCCCCCBBB----- ------BBBCCCBBB------ -------BBBCBBB------- --------BBCBB-------- --------------------- --------------------- --------------------- --------------------- --------------------- 
--------------------- --------------------- --------------------- ---------BCB--------- --------BBCBB-------- -------BBBCBBB------- -------BBBCBBB------- -------BBBCBBB------- --------BBCBB-------- ---------BCB--------- --------------------- --------------------- --------------------- --------------------- --------------------- --------------------- --------------------- 
