model
size = 21 17 21, scale = 0.05, origin = -y
material 
  colors = A:#C25100 B:#50000D C:#000 D:#005049 E:#EFEFEF
voxels
--------------------- --------------------- --------------------- --------------------- -------BBBDBBB------- -------BBBDBBB------- -------BBBDBBB------- -------BBBDBBB------- --------BBDBB-------- ---------BDB--------- --------------------- --------------------- --------------------- --------------------- --------------------- --------------------- --------------------- 
----------B---------- ----------B---------- --------------------- --------------------- -----BB-------BB----- -----BB-------BB----- -----BB-------BB----- -----BB-------BB----- -----BBB-----BBB----- ------BBB---BBB------ -------BBBDBBB------- --------BBDBB-------- --------------------- --------------------- --------------------- --------------------- --------------------- 
-------BBBBBBB------- ------B-------B------ -----B---------B----- ----BB---------BB---- ----BB----------B---- ----BB----------B---- ----BB----------B---- ----BB----------B---- ----BB----------B---- ----BB---------BB---- -----BB-------BB----- ------BBCCCCCBB------ -------BBBDBBB------- --------------------- --------------------- --------------------- --------------------- 
-----BB-------BB----- ---DBB---------BBD--- ---DB-----------BD--- ---DC-----------CD--- ---DC-----------CD--- ---DC-----------CD--- ---DC-----------CD--- ---DC-----------CD--- ---DC-----------CD--- ---DC----------CCD--- ---DB---------CCBD--- ---DBBCCCCCCC-CBBD--- -----BBAAAAAACBB----- -------BBBDBBB------- --------------------- --------------------- --------------------- 
----B-----------B---- ---BC-----------CB--- ---BC-----------CB--- --BAC------------CB-- --BAC------------CB-- --BAC------------CB-- --BAC------------CB-- --BAC------------CB-- --BAC------------CB-- --BAC------------CB-- ---BC-----------CB--- ---BACCCCCCCCCCCCB--- ----DAAAAAAAAAAAD---- ----DBBAAAAAAABBD---- -------BBBDBBB------- --------------------- --------------------- 
---BB-----------BB--- ---BC-----------CB--- --BAC-----------CAB-- --BAC------------CB-- -BAAC------------CAB- -BAAC------------CAB- -BAAC------------CAB- -BAAC------------CAB- -BAAC------------CAB- --BAC------------CB-- --BAC------------CB-- ---BACCCCCCCCCCCCB--- ---BAAAAAAAEAAAAAB--- ----BCAAAAAAAAAAB---- -----DBBAAAAABBD----- --------BBDBB-------- --------------------- 
---BB-----------BB--- --BAC-----------CAB-- --BAC-----------CAB-- -BAAC------------CAB- -BAAC------------CAB- -BAAC------------CAB- -BAAC------------CAB- -BAAC------------CAB- -BAAC------------CAB- -BAAC------------CAB- --BAC------------CB-- --BAACCCCC--CCCCCAB-- ---BAAAAAACCEAAAAB--- ----BAAAAAACAAAAB---- -----BDCAAAAACDB----- -------DDDDDDD------- --------------------- 
--BBB-----------BBB-- --BAC-----------CAB-- -BAAC-----------CAAB- -BAAC------------CAB- -BAAC------------CAB- BAAAC------------CAAB BAAAC------------CAAB BAAAC------------CAAB -BAAC------------CAB- -BAAC------------CAB- -BAAC------------CAB- --BAACCCCCCCCCCCCAB-- --BAAAAAAAAEAAAAAAB-- ---BAAAAAAAAAAAAAB--- ----BBAAAAAAAAABB---- ------BBBAAABBB------ ---------BDB--------- 
--BBB-----------BBB-- -BAAC-----------CAAB- -BAAC-----------CAAB- -BAAC------------CAB- BAAAC------------CAAB BAAAC------------CAAB BAAAC------------CAAB BAAAC------------CAAB BAAAC------------CAAB -BAAC------------CAB- -BAAC------------CAB- -BAAACCCCCCCCCCCCAAB- --BAAAAAAAAAAAAAAAB-- ---BAAAAAAAAAAAAAB--- ----BAAAAAAAAAAAB---- -----BBBAAAAABBB----- --------BBDBB-------- 
--BBB-----------BBB-- -BAAC-----------CAAB- -BAAC-----------CAAB- BAAAC------------CAAB BAAAC------------CAAB BAAAC------------CAAB BAAAC------------CAAB BAAAC------------CAAB BAAAC------------CAAB BAAAC------------CAAB -BAAC------------CAB- -BAAACCCCCCCCCCCCAAB- --BAAAAAAAAAAAAAAAB-- ---BAAAAAAAAAAAAAB--- ----BAAAAAAAAAAAB---- -----BBAAAAAAABB----- -------BBBDBBB------- 
--DBB-----------BBD-- -DAAC-----------CAAD- -DAAC-----------CAAD- DAAAC------------CAAD DAAAC------------CAAD DAAAC------------CAAD DAAAC------------CAAD DAAAC------------CAAD DAAAC------------CAAD DAAAC------------CAAD -DAAC------------CAD- -DAAACCCCCCCCCCCCAAD- --DAAAAAAAAAAAAAAAD-- ---DAAAAAAAAAAAAAD--- ----DAAAAAAAAAAAD---- -----DDAAAAAAADD----- -------DDDDDDD------- 
--BBB-----------BBB-- -BAAC-----------CAAB- -BAAC-----------CAAB- BAAAC------------CAAB BAAAC------------CAAB BAAAC------------CAAB BAAAC------------CAAB BAAAC------------CAAB BAAAC------------CAAB BAAAC------------CAAB -BAAC------------CAB- -BAAACCCCCCCCCCCCAAB- --BAAAAAAAAAAAAAAAB-- ---BAAAAAAAAAAAAAB--- ----BAAAAAAAAAAAB---- -----BBAAAAAAABB----- -------BBBDBBB------- 
--BBB-----------BBB-- -BAAC-----------CAAB- -BAAC-----------CAAB- -BAAC------------CAB- BAAAC------------CAAB BAAAC------------CAAB BAAAC------------CAAB BAAAC------------CAAB BAAAC------------CAAB -BAAC------------CAB- -BAAC------------CAB- -BAAACCCCCCCCCCCCAAB- --BAAAAAAAAAAAAAAAB-- ---BAAAAAAAAAAAAAB--- ----BAAAAAAAAAAAB---- -----BBBAAAAABBB----- --------BBDBB-------- 
--BBB-----------BBB-- --BAC-----------CAB-- -BAAC-----------CAAB- -BAAC------------CAB- -BAAC------------CAB- BAAAC------------CAAB BAAAC------------CAAB BAAAC------------CAAB -BAAC------------CAB- -BAAC------------CAB- -BAAC------------CAB- --BAACCCCCCCCCCCCAB-- --BAAAAAAAAAAAAAAAB-- ---BAAAAAAAAAAAAAB--- ----BBAAAAAAAAABB---- ------BBBAAABBB------ ---------BDB--------- 
---BB-----------BB--- --BAC-----------CAB-- --BAC-----------CAB-- -BAAC------------CAB- -BAAC------------CAB- -BAAC------------CAB- -BAAC------------CAB- -BAAC------------CAB- -BAAC------------CAB- -BAAC------------CAB- --BAC------------CB-- --BAACCCCCCCCCCCCAB-- ---BAAAAAAAAAAAAAB--- ----BAAAAAAAAAAAB---- -----BDCAAAAACDB----- -------DDDDDDD------- --------------------- 
---BB-----------BB--- ---BC-----------CB--- --BAC-----------CAB-- --BAC------------CB-- -BAAC------------CAB- -BAAC------------CAB- -BAAC------------CAB- -BAAC------------CAB- -BAAC------------CAB- --BAC------------CB-- --BAC------------CB-- ---BACCCCCCCCCCCCB--- ---BAAAAAAAAAAAAAB--- ----BCAAAAAAAAAAB---- -----DBBAAAAABBD----- --------BBDBB-------- --------------------- 
----DBB-------BBD---- ---BCC---------CCB--- ---BC-----------CB--- --BAC------------CB-- --BAC------------CB-- --BAC------------CB-- --BAC------------CB-- --BAC------------CB-- --BAC------------CB-- --BAC------------CB-- ---BC-----------CB--- ---BACCCCCCCCCCCCB--- ----DAAAAAAAAAAAD---- ----DBBAAAAAAABBD---- -------BBBDBBB------- --------------------- --------------------- 
-----BB-------BB----- ---DBBCCCCCCCCCBBD--- ---DBCCCCCCCCCCCBD--- ---DCC---------CCD--- ---DC-----------CD--- ---DC-----------CD--- ---DC-----------CD--- ---DC-----------CD--- ---DC-----------CD--- ---DCC---------CCD--- ---DBCC-------CCBD--- ---DBBCCCCCCCCCBBD--- -----BBAAAAAAABB----- -------BBBDBBB------- --------------------- --------------------- --------------------- 
-------BBBDBBB------- ------BBAAAAABB------ -----BBAACCCAABB----- ----BBCCC---CCCBB---- ----BCCC-----CCCB---- ----BCC------CCCB---- ----BCC------CCCB---- ----BCC------CCCB---- ----BCCC-----CCCB---- ----BBCCC---CCCBB---- -----BBCCCCCCCBB----- ------BBCCCCCBB------ -------BBBDBBB------- --------------------- --------------------- --------------------- --------------------- 
--------------------- --------BBDBB-------- -------BBBDBBB------- ------BBBCCCBBB------ -----BBBCCCCCBBB----- -----BBCCCCCCEBB----- -----BBCCCCCCEBB----- -----BBCCCCCCEBB----- -----BBBCCCCCBBB----- ------BBBCCCBBB------ -------BBBDBBB------- --------BBDBB-------- --------------------- --------------------- --------------------- --------------------- --------------------- 
--------------------- --------------------- --------------------- ---------BDB--------- --------BBDBB-------- -------BBBDBBB------- -------BBBDBBB------- -------BBBDBBB------- --------BBDBB-------- ---------BDB--------- --------------------- --------------------- --------------------- --------------------- --------------------- --------------------- --------------------- 
