model
size = 21 17 21, scale = 0.05, origin = -y
material 
  colors = A:#8CFF53 B:#C25100 C:#EFEFEF D:#000
voxels
--------------------- --------------------- --------------------- --------------------- -------AAAAAAA------- -------AAAAAAA------- -------AAAAAAA------- -------AAAAAAA------- --------AAAAA-------- ---------AAA--------- --------------------- --------------------- --------------------- --------------------- --------------------- --------------------- --------------------- 
----------A---------- ----------A---------- --------------------- --------------------- -----AA-------AA----- -----AA-------AA----- -----AA-------AA----- -----AA-------AA----- -----AAA-----AAA----- ------AAA---AAA------ -------AAAAAAA------- --------AAAAA-------- --------------------- --------------------- --------------------- --------------------- --------------------- 
-------AAAAAAA------- ------A-------A------ -----A---------A----- ----AA---------AA---- ----AA----------A---- ----AA----------A---- ----AA----------A---- ----AA----------A---- ----AA----------A---- ----AA---------AA---- -----AA-------AA----- ------AAAAAAAAA------ -------AAAAAAA------- --------------------- --------------------- --------------------- --------------------- 
-----AA-------AA----- ---CAA---------AAC--- ---CA-----------AC--- ---CA-----------AC--- ---CA-----------AC--- ---CA-----------AC--- ---CA-----------AC--- ---CA-----------AC--- ---CA-----------AC--- ---CA-----------AC--- ---CA-----------AC--- ---CAAAAAAAAAAAAAC--- -----AABBBBBBAAA----- -------AAAAAAA------- --------------------- --------------------- --------------------- 
----C-----------C---- ---AA-----------AA--- ---AA-----------AA--- --ABA-----------AAA-- --ABA-----------AAA-- --ABA-----------AAA-- --ABA-----------AAA-- --ABA-----------AAA-- --ABA-----------AAA-- --ABA-----------AAA-- ---AA-----------AA--- ---ABAAAAAAAAAAAAA--- ----CBBBBBBBBBBBC---- ----CAABBBBBBBAAC---- -------AAAAAAA------- --------------------- --------------------- 
---AA-----------AA--- ---AA-----------AA--- --ABA-----------ABA-- --ABA-----------AAA-- -ABBA-----------AABA- -ABBA-----------AABA- -ABBA-----------AABA- -ABBA-----------AABA- -ABBA-----------AABA- --ABA-----------AAA-- --ABA-----------AAA-- ---ABAAAAAAAAAAAAA--- ---ABBBBBBBCBBBBBA--- ----ADBBBBBBBBBBA---- -----CCCBBBBBCCC----- --------CCCCC-------- --------------------- 
---AA-----------AA--- --ABA-----------ABA-- --ABA-----------ABA-- -ABBA-----------AABA- -ABBA-----------AABA- -ABBA-----------AABA- -ABBA-----------AABA- -ABBA-----------AABA- -ABBA-----------AABA- -ABBA-----------AABA- --ABA-----------AAA-- --ABBAAAAAAAAAAAABA-- ---ABBBBBBAACBBBBA--- ----ABBBBBBDBBBBA---- -----AADBBBBBDAA----- -------AAAAAAA------- --------------------- 
--AAA-----------AAA-- --ABA-----------ABA-- -ABBA-----------ABBA- -ABBA-----------AABA- -ABBA-----------AABA- ABBBA-----------AABBA ABBBA-----------AABBA ABBBA-----------AABBA -ABBA-----------AABA- -ABBA-----------AABA- -ABBA-----------AABA- --ABBAAAAAAAAAAAABA-- --ABBBBBBBBCBBBBBBA-- ---ABBBBBBBBBBBBBA--- ----AABBBBBBBBBAA---- ------AAABBBAAA------ ---------AAA--------- 
--AAA-----------AAA-- -ABBA-----------ABBA- -ABBA-----------ABBA- -ABBA-----------AABA- ABBBA-----------AABBA ABBBA-----------AABBA ABBBA-----------AABBA ABBBA-----------AABBA ABBBA-----------AABBA -ABBA-----------AABA- -ABBA-----------AABA- -ABBBAAAAAAAAAAAABBA- --ABBBBBBBBBBBBBBBA-- ---ABBBBBBBBBBBBBA--- ----ABBBBBBBBBBBA---- -----AAABBBBBAAA----- --------AAAAA-------- 
--AAA-----------AAA-- -ABBA-----------ABBA- -ABBA-----------ABBA- ABBBA-----------AABBA ABBBA-----------AABBA ABBBA-----------AABBA ABBBA-----------AABBA ABBBA-----------AABBA ABBBA-----------AABBA ABBBA-----------AABBA -ABBA-----------AABA- -ABBBAAAAAAAAAAAABBA- --ABBBBBBBBBBBBBBBA-- ---ABBBBBBBBBBBBBA--- ----ABBBBBBBBBBBA---- -----AABBBBBBBAA----- -------AAAAAAA------- 
--AAA-----------AAA-- -ABBA-----------ABBA- -ABBA-----------ABBA- ABBBA-----------AABBA ABBBA-----------AABBA ABBBA-----------AABBA ABBBA-----------AABBA ABBBA-----------AABBA ABBBA-----------AABBA ABBBA-----------AABBA -ABBA-----------AABA- -ABBBAAAAAAAAAAAABBA- --ABBBBBBBBBBBBBBBA-- ---ABBBBBBBBBBBBBA--- ----ABBBBBBBBBBBA---- -----AABBBBBBBAA----- -------AAAAAAA------- 
--AAA-----------AAA-- -ABBA-----------ABBA- -ABBA-----------ABBA- ABBBA-----------AABBA ABBBA-----------AABBA ABBBA-----------AABBA ABBBA-----------AABBA ABBBA-----------AABBA ABBBA-----------AABBA ABBBA-----------AABBA -ABBA-----------AABA- -ABBBAAAAAAAAAAAABBA- --ABBBBBBBBBBBBBBBA-- ---ABBBBBBBBBBBBBA--- ----ABBBBBBBBBBBA---- -----AABBBBBBBAA----- -------AAAAAAA------- 
--AAA-----------AAA-- -ABBA-----------ABBA- -ABBA-----------ABBA- -ABBA-----------AABA- ABBBA-----------AABBA ABBBA-----------AABBA ABBBA-----------AABBA ABBBA-----------AABBA ABBBA-----------AABBA -ABBA-----------AABA- -ABBA-----------AABA- -ABBBAAAAAAAAAAAABBA- --ABBBBBBBBBBBBBBBA-- ---ABBBBBBBBBBBBBA--- ----ABBBBBBBBBBBA---- -----AAABBBBBAAA----- --------AAAAA-------- 
--AAA-----------AAA-- --ABA-----------ABA-- -ABBA-----------ABBA- -ABBA-----------AABA- -ABBA-----------AABA- ABBBA-----------AABBA ABBBA-----------AABBA ABBBA-----------AABBA -ABBA-----------AABA- -ABBA-----------AABA- -ABBA-----------AABA- --ABBAAAAAAAAAAAABA-- --ABBBBBBBBBBBBBBBA-- ---ABBBBBBBBBBBBBA--- ----AABBBBBBBBBAA---- ------AAABBBAAA------ ---------AAA--------- 
---AA-----------AA--- --ABA-----------ABA-- --ABA-----------ABA-- -ABBA-----------AABA- -ABBA-----------AABA- -ABBA-----------AABA- -ABBA-----------AABA- -ABBA-----------AABA- -ABBA-----------AABA- -ABBA-----------AABA- --ABA-----------AAA-- --ABBAAAAAAAAAAAABA-- ---ABBBBBBBBBBBBBA--- ----ABBBBBBBBBBBA---- -----AADBBBBBDAA----- -------AAAAAAA------- --------------------- 
---AA-----------AA--- ---AA-----------AA--- --ABA-----------ABA-- --ABA-----------AAA-- -ABBA-----------AABA- -ABBA-----------AABA- -ABBA-----------AABA- -ABBA-----------AABA- -ABBA-----------AABA- --ABA-----------AAA-- --ABA-----------AAA-- ---ABAAAAAAAAAAAAA--- ---ABBBBBBBBBBBBBA--- ----ADBBBBBBBBBBA---- -----CCCBBBBBCCC----- --------CCCCC-------- --------------------- 
----CAA-------AAC---- ---ADA---------ADA--- ---AA-----------AA--- --ABA-----------AAA-- --ABA-----------AAA-- --ABA-----------AAA-- --ABA-----------AAA-- --ABA-----------AAA-- --ABA-----------AAA-- --ABA-----------AAA-- ---AA-----------AA--- ---ABAAAAAAAAAAADA--- ----CBBBBBBBBBBBC---- ----CAABBBBBBBAAC---- -------AAAAAAA------- --------------------- --------------------- 
-----AAAAAAAAAAA----- ---CAAAAAAAAAAAAAC--- ---CAAAAAAAAAAAAAC--- ---CDA---------AAC--- ---CA-----------AC--- ---CA-----------AC--- ---CA-----------AC--- ---CA-----------AC--- ---CA-----------AC--- ---CDA---------AAC--- ---CAAA-------AAAC--- ---CAADAAAAAAADAAC--- -----AABBBBBBBAA----- -------AAAAAAA------- --------------------- --------------------- --------------------- 
-------AAAAAAA------- ------AABBBBBAA------ -----AABBAAABBAA----- ----AAAAA---AAAAA---- ----AAAA-----AAAA---- ----AAA-------AAA---- ----AAA-------AAA---- ----AAA-------AAA---- ----AAAA-----AAAA---- ----AAAAA---AAAAA---- -----AAAAAAAAAAA----- ------AADDDDDAA------ -------AAAAAAA------- --------------------- --------------------- --------------------- --------------------- 
--------------------- --------AAAAA-------- -------AAAAAAA------- ------AAAAAAAAA------ -----AAAAAAAAAAA----- -----AAAAAAAAAAA----- -----AAAAAAAAAAA----- -----AAAAAAAAAAA----- -----AAAAAAAAAAA----- ------AAAAAAAAA------ -------AAAAAAA------- --------AAAAA-------- --------------------- --------------------- --------------------- --------------------- --------------------- 
--------------------- --------------------- --------------------- ---------AAA--------- --------AAAAA-------- -------AAAAAAA------- -------AAAAAAA------- -------AAAAAAA------- --------AAAAA-------- ---------AAA--------- --------------------- --------------------- --------------------- --------------------- --------------------- --------------------- --------------------- 
