model
size = 21 17 21, scale = 0.05, origin = -y
material 
  colors = A:#FF1A40 B:#C25100 C:#DBFF70 D:#EFEFEF E:#000
voxels
--------------------- --------------------- --------------------- --------------------- -------AAAAAAA------- -------AAAAAAA------- -------AAAAAAA------- -------AAAAAAA------- --------AAAAA-------- ---------AAA--------- --------------------- --------------------- --------------------- --------------------- --------------------- --------------------- --------------------- 
----------A---------- ----------A---------- --------------------- --------------------- -----AA-------AA----- -----AA-------AA----- -----AA-------AA----- -----AA-------AA----- -----AAA-----AAA----- ------AAA---AAA------ -------AAAAAAA------- --------AAAAA-------- --------------------- --------------------- --------------------- --------------------- --------------------- 
-------AAAAAAA------- ------A-------A------ -----A---------A----- ----AA---------AA---- ----AA----------A---- ----AA----------A---- ----AA----------A---- ----AA----------A---- ----AA----------A---- ----AA---------AA---- -----AA-------AA----- ------AAAAAAAAA------ -------AAAAAAA------- --------------------- --------------------- --------------------- --------------------- 
-----AA-------AA----- ---DAA---------AAD--- ---DA-----------AD--- ---DA-----------AD--- ---DA-----------AD--- ---DA-----------AD--- ---DA-----------AD--- ---DA-----------AD--- ---DA-----------AD--- ---DA-----------AD--- ---DA-----------AD--- ---DAAAAAAAAAAAAAD--- -----AABBBBBBAAA----- -------AAAAAAA------- --------------------- --------------------- --------------------- 
----D-----------D---- ---CA-----------AC--- ---CA-----------AC--- --CBA------------AC-- --CBA------------AC-- --CBA------------AC-- --CBA------------AC-- --CBA------------AC-- --CBA------------AC-- --CBA------------AC-- ---CA------------C--- ---CBAAAAAAAAAAAAC--- ----DBBBBBBBBBBBD---- ----DAABBBBBBBAAD---- -------AAAAAAA------- --------------------- --------------------- 
---CC-----------CC--- ---CA-----------AC--- --CBA-----------ABC-- --CBA-----------AAC-- -CBBA-----------AABC- -CBBA-----------AABC- -CBBA-----------AABC- -CBBA-----------AABC- -CBBA-----------AABC- --CBA-----------AAC-- --CBA-----------AAC-- ---CBAAAAAAAAAAAAC--- ---CBBBBBBBDBBBBBC--- ----CEBBBBBBBBBBC---- -----DDDBBBBBDDD----- --------DDDDD-------- --------------------- 
---CC-----------CC--- --CBA-----------ABC-- --CBA-----------ABC-- -CBBA-----------AABC- -CBBA-----------AABC- -CBBA-----------AABC- -CBBA-----------AABC- -CBBA-----------AABC- -CBBA-----------AABC- -CBBA-----------AABC- --CBA-----------AAC-- --CBBAAAAAAAAAAAABC-- ---CBBBBBBAADBBBBC--- ----CBBBBBBEBBBBC---- -----CCEBBBBBECC----- -------CCCCCCC------- --------------------- 
--CCC-----------CCC-- --CBA-----------ABC-- -CBBA-----------ABBC- -CBBA-----------AABC- -CBBA-----------AABC- CBBBA-----------AABBC CBBBA-----------AABBC CBBBA-----------AABBC -CBBA-----------AABC- -CBBA-----------AABC- -CBBA-----------AABC- --CBBAAAAAAAAAAAABC-- --CBBBBBBBBDBBBBBBC-- ---CBBBBBBBBBBBBBC--- ----CCBBBBBBBBBCC---- ------CCCBBBCCC------ ---------CCC--------- 
--CCC-----------CCC-- -CBBA-----------ABBC- -CBBA-----------ABBC- -CBBA-----------AABC- CBBBA-----------AABBC CBBBA-----------AABBC CBBBA-----------AABBC CBBBA-----------AABBC CBBBA-----------AABBC -CBBA-----------AABC- -CBBA-----------AABC- -CBBBAAAAAAAAAAAABBC- --CBBBBBBBBBBBBBBBC-- ---CBBBBBBBBBBBBBC--- ----CBBBBBBBBBBBC---- -----CCCBBBBBCCC----- --------CCCCC-------- 
--CCC-----------CCC-- -CBBA-----------ABBC- -CBBA-----------ABBC- CBBBA-----------AABBC CBBBA-----------AABBC CBBBA-----------AABBC CBBBA-----------AABBC CBBBA-----------AABBC CBBBA-----------AABBC CBBBA-----------AABBC -CBBA-----------AABC- -CBBBAAAAAAAAAAAABBC- --CBBBBBBBBBBBBBBBC-- ---CBBBBBBBBBBBBBC--- ----CBBBBBBBBBBBC---- -----CCBBBBBBBCC----- -------CCCCCCC------- 
--CCC-----------CCC-- -CBBA-----------ABBC- -CBBA-----------ABBC- CBBBA-----------AABBC CBBBA-----------AABBC CBBBA-----------AABBC CBBBA-----------AABBC CBBBA-----------AABBC CBBBA-----------AABBC CBBBA-----------AABBC -CBBA-----------AABC- -CBBBAAAAAAAAAAAABBC- --CBBBBBBBBBBBBBBBC-- ---CBBBBBBBBBBBBBC--- ----CBBBBBBBBBBBC---- -----CCBBBBBBBCC----- -------CCCCCCC------- 
--CCC-----------CCC-- -CBBA-----------ABBC- -CBBA-----------ABBC- CBBBA-----------AABBC CBBBA-----------AABBC CBBBA-----------AABBC CBBBA-----------AABBC CBBBA-----------AABBC CBBBA-----------AABBC CBBBA-----------AABBC -CBBA-----------AABC- -CBBBAAAAAAAAAAAABBC- --CBBBBBBBBBBBBBBBC-- ---CBBBBBBBBBBBBBC--- ----CBBBBBBBBBBBC---- -----CCBBBBBBBCC----- -------CCCCCCC------- 
--CCC-----------CCC-- -CBBA-----------ABBC- -CBBA-----------ABBC- -CBBA-----------AABC- CBBBA-----------AABBC CBBBA-----------AABBC CBBBA-----------AABBC CBBBA-----------AABBC CBBBA-----------AABBC -CBBA-----------AABC- -CBBA-----------AABC- -CBBBAAAAAAAAAAAABBC- --CBBBBBBBBBBBBBBBC-- ---CBBBBBBBBBBBBBC--- ----CBBBBBBBBBBBC---- -----CCCBBBBBCCC----- --------CCCCC-------- 
--CCC-----------CCC-- --CBA-----------ABC-- -CBBA-----------ABBC- -CBBA-----------AABC- -CBBA-----------AABC- CBBBA-----------AABBC CBBBA-----------AABBC CBBBA-----------AABBC -CBBA-----------AABC- -CBBA-----------AABC- -CBBA-----------AABC- --CBBAAAAAAAAAAAABC-- --CBBBBBBBBBBBBBBBC-- ---CBBBBBBBBBBBBBC--- ----CCBBBBBBBBBCC---- ------CCCBBBCCC------ ---------CCC--------- 
---CC-----------CC--- --CBA-----------ABC-- --CBA-----------ABC-- -CBBA-----------AABC- -CBBA-----------AABC- -CBBA-----------AABC- -CBBA-----------AABC- -CBBA-----------AABC- -CBBA-----------AABC- -CBBA-----------AABC- --CBA-----------AAC-- --CBBAAAAAAAAAAAABC-- ---CBBBBBBBBBBBBBC--- ----CBBBBBBBBBBBC---- -----CCEBBBBBECC----- -------CCCCCCC------- --------------------- 
---CC-----------CC--- ---CA-----------AC--- --CBA-----------ABC-- --CBA-----------AAC-- -CBBA-----------AABC- -CBBA-----------AABC- -CBBA-----------AABC- -CBBA-----------AABC- -CBBA-----------AABC- --CBA-----------AAC-- --CBA-----------AAC-- ---CBAAAAAAAAAAAAC--- ---CBBBBBBBBBBBBBC--- ----CEBBBBBBBBBBC---- -----DDDBBBBBDDD----- --------DDDDD-------- --------------------- 
----DAA-------AAD---- ---CEA---------AEC--- ---CA-----------AC--- --CBA-----------AAC-- --CBA-----------AAC-- --CBA-----------AAC-- --CBA-----------AAC-- --CBA-----------AAC-- --CBA-----------AAC-- --CBA-----------AAC-- ---CA-----------AC--- ---CBAAAAAAAAAAAEC--- ----DBBBBBBBBBBBD---- ----DAABBBBBBBAAD---- -------AAAAAAA------- --------------------- --------------------- 
-----AAAAAAAAAAA----- ---DAAAAAAAAAAAAAD--- ---DAAAAAAAAAAAAAD--- ---DEA----------AD--- ---DA-----------AD--- ---DA-----------AD--- ---DA-----------AD--- ---DA-----------AD--- ---DA-----------AD--- ---DEA---------AAD--- ---DAAA-------AAAD--- ---DAAEAAAAAAAEAAD--- -----AABBBBBBBAA----- -------AAAAAAA------- --------------------- --------------------- --------------------- 
-------AAAAAAA------- ------AABBBBBAA------ -----AABBBBBBBAA----- ----AAAAA---AAAAA---- ----AAAA-----AAAA---- ----AAA-------AAA---- ----AAA-------AAA---- ----AAA-------AAA---- ----AAAA-----AAAA---- ----AAAAA---AAAAA---- -----AAAAAAAAAAA----- ------AAEEEEEAA------ -------AAAAAAA------- --------------------- --------------------- --------------------- --------------------- 
--------------------- --------AAAAA-------- -------AAAAAAA------- ------AAAAAAAAA------ -----AAAAAAAAAAA----- -----AAAAAAAAAAA----- -----AAAAAAAAAAA----- -----AAAAAAAAAAA----- -----AAAAAAAAAAA----- ------AAAAAAAAA------ -------AAAAAAA------- --------AAAAA-------- --------------------- --------------------- --------------------- --------------------- --------------------- 
--------------------- --------------------- --------------------- ---------AAA--------- --------AAAAA-------- -------AAAAAAA------- -------AAAAAAA------- -------AAAAAAA------- --------AAAAA-------- ---------AAA--------- --------------------- --------------------- --------------------- --------------------- --------------------- --------------------- --------------------- 
