model
size = 19 31 19, scale = 0.05, origin = -y
material 
  colors = A:#C30 B:#7C1F00 C:#922400 D:#872100 E:#222 F:#930 G:#F30 H:#D00 I:#9E2700 J:#960 K:#777 L:#A92A00 M:#B52D00 N:#555
voxels
-------AAAAA------- ------------------- ------------------- ------------------- ------------------- ------------------- ------------------- ------------------- ------------------- ------------------- ------------------- ------------------- ------------------- ------------------- ------------------- ------------------- ------------------- ------------------- ------------------- ------------------- ------------------- ------------------- ------------------- ------------------- ------------------- ------------------- ------------------- ------------------- ------------------- ------------------- ------------------- 
----AAAAAAAAAAH---- --------AAA-------- ------------------- ------------------- ------------------- ------------------- ------------------- ------------------- ------------------- ------------------- ------------------- ------------------- ------------------- ------------------- ------------------- ------------------- ------------------- ------------------- ------------------- ------------------- ---------N--------- --------NEN-------- -------EEEEE------- -------EEEEE------- --------EEE-------- ---------E--------- ------------------- ------------------- ------------------- ------------------- -------JJJJJ------- 
---HAAHHHHHHAHHH--- -----AHHHHHHAH----- ------------------- ------------------- ------------------- ------------------- ------------------- ------------------- ------------------- ------------------- ------------------- ------------------- ------------------- ------------------- ------------------- ------------------- ------------------- ------------------- ------------------- ---------K--------- --------KKK-------- -------KKEKK------- ------KEEEEEK------ ------EEEEEEE------ -------EEEEE------- --------EEE-------- ---------E--------- --------BBB-------- -------BBBBB------- -------FFFFF------- -----JJFFFFFJJ----- 
--AAAAAAHHHHHHHHH-- ----AAAAHHHHHHH---- -------AHHHH------- ------------------- ------------------- ------------------- ------------------- ------------------- ------------------- ------------------- ------------------- ------------------- ------------------- ------------------- ------------------- ------------------- ------------------- ---------C--------- --------CCC-------- -------CCICC------- -------C-K-C------- ------C-KEK-C------ ------KEEEEEK------ ------E-DDDEE------ -------DDDDD------- -------BBBBB------- ------BBBBBBB------ -----BBB---BBB----- -----BB-----BB----- -----FF-----FF----- ----JFF-----FFJ---- 
-AAAAAAAAAAAHHHHHH- ---AAAAAAAAAHHHH--- -----AAAAAAAHH----- ------------------- ------------------- ------------------- ------------------- ------------------- ------------------- ------------------- ------------------- ------------------- ------------------- ------------------- ------------------- ------------------- ------------------- ---------I--------- --------III-------- -------IIIII------- ------IICCCII------ ------IDDDDDI------ ------DDDDDDD------ ------DD---DD------ ------D-----D------ ------B-----B------ -----B-------B----- ----B---------B---- ----B---------B---- ----F---------F---- ---JF---------FJ--- 
-GGAAAAAAAAAAAAGGG- --GAAAAAAAAAAAAGG-- ----AAAAAAAAAAA---- ------------------- ------------------- ------------------- ------------------- ------------------- ------------------- ------------------- ------------------- ------------------- ------------------- ------------------- ------------------- ------------------- ---------C--------- ---------C--------- -------CCCCC------- -------CCCCC------- ------CC---CC------ ------D-----D------ -----D-------D----- -----D-------D----- -----D-------D----- -----B-------B----- ----B---------B---- ---B-----------B--- ---B-----------B--- ---F-----------F--- --JF-----------FJ-- 
-AAAAAAAAAAAAAAAAA- --AAAAAAAAAAAAAAA-- ----AAAAAAAAAAA---- -------AAAAA------- ------------------- ------------------- ------------------- ------------------- ------------------- ------------------- ------------------- ------------------- ------------------- ------------------- ------------------- ------------------- -------CCICC------- -------CC-CC------- ------C-----C------ ------C-----C------ -----C-------C----- -----D-------D----- ----D---------D---- ----D---------D---- ----D---------D---- ----B---------B---- ---B-----------B--- ---B-----------B--- ---B-----------B--- ---F-----------F--- --JF-----------FJ-- 
AAAAAAAAAAAAAAAAAAA --AAAAAAAAAAAAAAA-- ---AAAAAAAAAAAAA--- ------AAAAAAA------ ------------------- ------------------- ------------------- ------------------- ------------------- ------------------- ------------------- ------------------- ------------------- ------------------- ------------------- --------III-------- ------CI---IC------ ------C-----C------ -----C-------C----- -----C-------C----- -----C-------C----- ----D---------D---- ----D---------D---- ----D---------D---- ---D-----------D--- ---B-----------B--- ---B-----------B--- ---B-----------B--- --B-------------B-- --F-------------F-- -JF-------------FJ- 
AAAAAAAAAAAAAAAAAAA -AAAAAAAAAAAAAAAAA- ---AAAAAAAAAAAAA--- ------AAAAAAA------ ---------A--------- ---------M--------- ---------M--------- ---------M--------- ---------M--------- ---------L--------- ---------L--------- ---------L--------- ---------L--------- ---------I--------- --------III-------- -------I---I------- ------C-----C------ ------C-----C------ -----C-------C----- -----C-------C----- ----C---------C---- ----D---------D---- ----D---------D---- ---D-----------D--- ---D-----------D--- ---B-----------B--- ---B-----------B--- --B-------------B-- --B-------------B-- --F-------------F-- -JF-------------FJ- 
AAAAAAAAAAAAAAAAAAA -AAAAAAAAAAAAAAAAA- ---AAAAAAAAAAAAA--- ------AAAAAAA------ --------AAA-------- --------MMM-------- --------MMM-------- --------MMM-------- --------MMM-------- --------LLL-------- --------LLL-------- --------LLL-------- --------LLL-------- --------III-------- --------III-------- -------I---I------- ------I-----I------ -----C-------C----- -----C-------C----- -----C-------C----- ----C---------C---- ----D---------D---- ----D---------D---- ---D-----------D--- ---D-----------D--- ---B-----------B--- ---B-----------B--- --B-------------B-- --B-------------B-- --F-------------F-- -JF-------------FJ- 
AAAAAAAAAAAAAAAAAAA -AAAAAAAAAAAAAAAAA- ---AAAAAAAAAAAAA--- ------AAAAAAA------ ---------A--------- ---------M--------- ---------M--------- ---------M--------- ---------M--------- ---------L--------- ---------L--------- ---------L--------- ---------L--------- ---------I--------- --------III-------- -------I---I------- ------C-----C------ ------C-----C------ -----C-------C----- -----C-------C----- ----C---------C---- ----D---------D---- ----D---------D---- ---D-----------D--- ---D-----------D--- ---B-----------B--- ---B-----------B--- --B-------------B-- --B-------------B-- --F-------------F-- -JF-------------FJ- 
AAAAAAAAAGGGGGGGGGG --AAAAAAAGGGGGGGG-- ---AAAAAAGGGGGGG--- ------AAAGGGG------ ------------------- ------------------- ------------------- ------------------- ------------------- ------------------- ------------------- ------------------- ------------------- ------------------- ------------------- --------III-------- ------CI---IC------ ------C-----C------ -----C-------C----- -----C-------C----- -----C-------C----- ----D---------D---- ----D---------D---- ----D---------D---- ---D-----------D--- ---B-----------B--- ---B-----------B--- ---B-----------B--- --B-------------B-- --F-------------F-- -JF-------------FJ- 
-AAAAAAAAAAAAAAAAA- --AAAAAAAAAAAAAAA-- ----AAAAAAAAAAA---- -------AAAAA------- ------------------- ------------------- ------------------- ------------------- ------------------- ------------------- ------------------- ------------------- ------------------- ------------------- ------------------- ------------------- -------CCICC------- -------CC-CC------- ------C-----C------ ------C-----C------ -----C-------C----- -----D-------D----- ----D---------D---- ----D---------D---- ----D---------D---- ----B---------B---- ---B-----------B--- ---B-----------B--- ---B-----------B--- ---F-----------F--- -JJF-----------FJ-- 
-GGGGGGGGGGGGGAAAA- --GGGGGGGGGGGGAAA-- ----GGGGGGGGGGA---- ------------------- ------------------- ------------------- ------------------- ------------------- ------------------- ------------------- ------------------- ------------------- ------------------- ------------------- ------------------- ------------------- ---------C--------- ---------C--------- -------CCCCC------- -------CCCCC------- ------CC---CC------ ------D-----D------ -----D-------D----- -----D-------D----- -----D-------D----- -----B-------B----- ----B---------B---- ---B-----------B--- ---B-----------B--- ---F-----------F--- --JF-----------FJ-- 
-AAAAAAAAAAAAAAAAA- ---AAAAAAAAAAAAA--- -----AAAAAAAAA----- ------------------- ------------------- ------------------- ------------------- ------------------- ------------------- ------------------- ------------------- ------------------- ------------------- ------------------- ------------------- ------------------- ------------------- ---------I--------- --------III-------- -------IIIII------- ------IICCCII------ -------DDDDD------- ------DDDDDDD------ ------DD---DD------ ------D-----D------ ------B-----B------ -----B-------B----- ----B---------B---- ----B---------B---- ----F---------F---- ---JF---------FJ--- 
--AAAAAAHHHAHHHHH-- ----AAAAHHHAHHH---- -------AHHHA------- ------------------- ------------------- ------------------- ------------------- ------------------- ------------------- ------------------- ------------------- ------------------- ------------------- ------------------- ------------------- ------------------- ------------------- ------------------- ------------------- ---------K--------- --------KKK-------- -------KKEKK------- ------KEEEEEK------ ------EEEEEEE------ -------EEEEE------- -------BEEEB------- ------BBBEBBB------ -----BBB---BBB----- -----BB-----BB----- -----FF-----FF----- ----JFF-----FFJ---- 
---AAAAAAAAAAAAA--- -----AAAAAAAAA----- ------------------- ------------------- ------------------- ------------------- ------------------- ------------------- ------------------- ------------------- ------------------- ------------------- ------------------- ------------------- ------------------- ------------------- ------------------- ------------------- ------------------- ------------------- ---------N--------- --------NEN-------- -------EEEEE------- -------EEEEE------- --------EEE-------- ---------E--------- ------------------- --------BBB-------- -------BBBBB------- -------FFFFF------- -----JJFFFFFJJ----- 
----AAAAAAAAAAA---- --------AAA-------- ------------------- ------------------- ------------------- ------------------- ------------------- ------------------- ------------------- ------------------- ------------------- ------------------- ------------------- ------------------- ------------------- ------------------- ------------------- ------------------- ------------------- ------------------- ------------------- ------------------- ------------------- ------------------- ------------------- ------------------- ------------------- ------------------- ------------------- ------------------- -------JJJJJ------- 
-------AAAAA------- ------------------- ------------------- ------------------- ------------------- ------------------- ------------------- ------------------- ------------------- ------------------- ------------------- ------------------- ------------------- ------------------- ------------------- ------------------- ------------------- ------------------- ------------------- ------------------- ------------------- ------------------- ------------------- ------------------- ------------------- ------------------- ------------------- ------------------- ------------------- ------------------- ------------------- 
