model
size = 32 16 28, scale = 0.05, origin = -y
material 
  colors = A:#000 B:#EEE C:#00B D:#800 E:#00A F:#60C G:#30C H:#03F I:#009 J:#006 K:#00C L:#00E M:#00D N:#008
voxels
3-8D2A6-2A8D5-D8-3A4-3A8-D3-D11-6A11-D2-D28-D-D6(30-2D)29-D2-D28-D2-D27-D4-D26-D5-2D6-10D6-2D2(8-7D)8-8DL2H4-2LH8D5-D8B4L2-4L8BD3-D11BL5F11BD2-D22BA5BD-D4BA7BA11BA5B2D3BA9BA11BA4B2D2B2(A11B)A3B2DBA13BA11BA2B2D2BA13BA9BA3B2D3BA13BA7BA4B2D4BA13BA5BA4BD2-D28BD2-D27BD4-D26BD5-2D6B10D6B2D2(8-7D)8-3L5FL2H4-2LH3L2F3K5-2L-7F-2L2-2L-4L2F2-2K3-2F2-7F2-4F2-4L2F3-2N2-F2-9F2-2F2-7F2N2-N-2H2-8H2F-H2-2H4F2H2M2-2MH2-11H4-8H3M2-MC2-9C2H4-2C4H2C3E2-EC2-11C4-8C3E2-EG2-9G2C4-2G4C2G3J2-JG2-11G4-8G3J-2J2I2-8I2G2(-2I)4G4I2(2-I)2-9I2-2I2-9I-2I2-2C3-5C3-4C2-6C3-C4-2C9-6C8-3C5-3K5-10K5-3K2(8-7K)8-11A4-11A5-13A2-13A3-30A2-30A-64A2(2C28A2E)2G28A2J63A2-30A2-29A4-28A5-26A2(8-7A)197-2(2C28-2E)2G28-2J2(416-2(2C27-3E)2G27-3J)3(416-2(2C28-2E)2G28-2J)2(416-2H28-2M2(2C28-2E))2(416-2(2C28-2E)2G28-2J)446-2E3(2C28-2E2G28-2J448-)2C28-2E2(2G28-2J416-2(2C28-2E))448-2(2C28-2E)416-2H28-2M2(2C28-2E)385-H28-M-2H28-2M2C28-2E385-F28-N2-2H26-2M-2H27-3M2C28-2E385-2F26-2N2-2H26-2M2-H27-2M386-2(2(2F26-2N2-)2H26-2M387-L26-K3-)2F26-2N2-2F26-2N385-
