model
size = 14 32 15, scale = 0.05, origin = -y
material 
  colors = A:#444 B:#EEE C:#E00 D:#111
voxels
311-2(9A5-)2(A2(2B2A)5-)6(2(2AB)3A5-)3B3A4B4-A2B3A2B18(2A4-AB5AB)2A4-2B5A3B4(4-10A)6(4-5AB4A)4-2(2AB)4A3-2B8AB17(3-11A)2-12A2-13A-4B6A3B4(-13A)6(-7AB5A)-4AB2AB5A2-2B8AB17(3-11A)2-12A-14A5B8AB145AB2A2B4A2-15(B9AB3-)10AB2(3-11A)2-12A-14A5B8A10(B13A)B5AB2A6B2-14(11A3-)B10A3-10AB2(3-11A)2-12A-14A11(B13A)6B8A2(2-14(11A3-)B10A3-10AB2(3-11A)2-12A-182A)2-2B8A14(B3-B9A)B3-10AB2(3-11A)2-12A-14AB10(12A2B)12A7B3A5B2(2-2B8AB17(3-11A)2-12A-14A4B7A3B145AB3AB4A)3-3B3A4B4-A2B3A3BA15(4-AB5AB2A)2(3-2AB5AB2A)3-8AB2A3-2B6A3B10(3-11A)3-2(3AB)3A228-3(AB5AB2A4-)7AB2A4-B6A3B10(4-10A)4-2A2(B3A)256-2(AB5ABA5-)2B5A2B4(5-9A)2(5-A2B3A2BA)5(5-2AB3AB2A)315-D2CDC9-5A10-7(3A11-)3A5-
