model
size = 15 6 22, scale = 0.05, origin = -y
material 
  colors = A:#444 B:#222 C:#EEE D:#111
voxels
--------------- --------------- --------------- BB-BB-BB-BB---- BB-BB-BB-BB---- BB-BB-BB-BB---- 
--------------- --------------- --------------- BB-BB-BB-BB---- BB-BB-BB-BB---- BB-BB-BB-BB---- 
--------------- --------------- --------------- BB-BB-BB-BB---- BB-BB-BB-BB---- BB-BB-BB-BB---- 
--------------- --------------- --------------- BB-BB-BB-BB---- BB-BB-BB-BB---- BB-BB-BB-BB---- 
--------------- --------------- --------------- BB-BB-BB-BB---- BB-BB-BB-BB---- BB-BB-BB-BB---- 
--------------- --------------- --------------- BB-BB-BB-BB--BB BB-BB-BB-BB--BB BB-BB-BB-BB--BB 
-AAAAAAAAAA---- -AAAAAAAAAA---- -CAAAAAAAAC---- -AAAAAAAAAABBBB -AAACAACAAABBBB -AAACAACAAABBBB 
-AAAAAAAAAA---- -AAAAAAAAAA---- -CAAAAAAAAC---- -AAAAAAAAAABBBB -AAACAACAAABBBB -AAACAACAAABBBB 
-AAAAAAAAAA---- -AAAAAAAAAA---- -CAAAAAAAAC---- -AAAAAAAAAABBBB -AAACAACAAABBBB -AAACAACAAABBBB 
-AAAAAAAAAA---- -AAAAAAAAAA---- -CAAAAAAAAC---- -AAAAAAAAAABBBB -AAACAACAAABBBB -AAACAACAAABBBB 
-AAAAAAAAAA---- -AAAAAAAAAA---- -CAAAAAAAAC---- -AAAAAAAAAABBBB -AAACAACAAABBBB -AACCAACCAABBBB 
-AAAAAAAAAA---- -AAAAAAAAAA---- -CAAAAAAAAC---- -AAAAAAAAAABB-- -AAAAAAAAAABB-- -AACCAACCAABB-- 
-AAAAAAAAAA---- -AAAAAAAAAA---- -CAAAAAAAAC---- -AAAAAAAAAABB-- -AAAAAAAAAABB-- -AAAAAAAAAABB-- 
-AAAAAAAAAA---- -AAAAAAAAAA---- -CAAAAAAAAC---- -AAAAAAAAAABB-- -AAAAAAAAAABB-- -AAAAAAAAAABB-- 
-AAAAAAAAAA---- -AAAAAAAAAA---- -CAAAAAAAAC---- -AAAAAAAAAA---- -AAAAAAAAAA---- -AAAAAAAAAA---- 
-AAAAAAAAAA---- -AAAAAAAAAA---- -CAAAAAAAAC---- -CAAAAAAAAC---- -CAAAAAAAAC---- -CCCCCCCCCC---- 
-AAAAAAAAAA---- -AAAAAAAAAA---- -AAAAAAAAAA---- -AAAAAAAAAA---- -AAAAAAAAAA---- -AAAAAAAAAA---- 
-CAAAAAAAAC---- -CAAAAAAAAC---- -CAAAAAAAAC---- -CAAAAAAAAC---- -CAAAAAAAAC---- -CCCCAACCCC---- 
-AAAAAAAAAA---- -AAAAAAAAAA---- -AAAAAAAAAA---- -AAAAAAAAAA---- -AAAAAAAAAA---- -AAACAACAAA---- 
-AAAAAAAAAA---- -AAAAAAAAAA---- -AAAAAAAAAA---- -AAAAAAAAAA---- -AAAAAAAAAA---- -AAACAACAAA---- 
-AAAAAAAAAA---- -AAAAAAAAAA---- -AAAAAAAAAA---- -AAAAAAAAAA---- -AAAAAAAAAA---- -AAACAACAAA---- 
-ADDDDDDDDA---- -ADDDDDDDDA---- -ADDDDDDDDA---- -ADDDDDDDDA---- -ADDDDDDDDA---- -AAACAACAAA---- 
