model
size = 6 33 28, scale = 0.05, origin = -y
material 
  colors = A:#FEE900 B:#080202 C:#FFF D:#070701 E:#040000 F:#FC0000 G:#F05661
voxels
75-8(A5-)A191-A5-A182-36B144-18B31A4BA18B120-6B67A4BA6B32-4E2-2E11(4-2A)2-2B2A2B79A4BA6B26-4E2-2E10(4-2A)2-2B2A2B91A4BA6B84-6B41AD17AB10A2(C5A)C12AB7AB4A6B72-6B29A3(D5A)D22ACB3A2(2C4A)2C5ACB19A4BA6B66-6B29AD2(5AF)5AD22ACB3A2(2C4A)2C5ACB19A4BA6B66-6B23AD3(5AF)5AD22AC4A2CB3A2C4A2CB4AC20A4BA6B66-6B23AD5AG2(5AF)5AD28ACB4AC5ACB31A4BA6B60-6B23AD5AG2(5AF)5AD35AB37A2(4BA6B60-6B23AD5AG2(5AF)5AD73A)4BA6B60-6B23AD5AG2(5AF)5AD28AC5ACB4AC32A4BA6B60-6B23AD5AG2(5AF)5AD22AC4A2CB3A2C4A2CB4AC20AB5A4BA6B60-6B29AD2(5AF)5AD22AC4A2CB3A2C4A2CB4AC20AB4A6B66-6B29AD2(5AF)5AD22ACB3A2(2C4A)2C5ACB19A4BA6B66-6B2A3B30A2(D5A)D23AB4A2(C5A)C6AB13A4B2A4BA6B72-6BAB2AB54AB35ABA4B2A4BA6B14-4E2-2E10(4-2A)2-2B2A2BAB2AB80A4B2A4BA6B20-4E2-2E11(4-2A)2-2B2A2B73A4B2A4BA6B108-6BA2(4B2A)4B32A3(4B2A)4BA6B120-18BA5(4B2A)4BA18B144-36B171-A5-A149-8(A5-)A74-
