model
size = 6 33 28, scale = 0.05, origin = -y
material 
  colors = A:#FEE900 B:#080202 C:#FFF D:#040000 E:#0B0505 F:#070701
voxels
75-8(A5-)A191-A5-A182-36B144-18B31A4BA18B120-6B67A4BA6B32-4D2-2D11(4-2A)2-2B2A2B79A4BA6B26-4D2-2D10(4-2A)2-2B2A2B35AE55A4BA6B84-6B35AE34A2(2C4A)2C19AB4A6B72-6B35AE34A2C3(3A3C)4A2C19A4BA6B66-6B29AE40A2C3A3C2(3A2CD)4A2C19A4BA6B66-6B6AD22AE40A2C3A3C3A2CE3A2CF4A2C19A4BA6B66-6B6A2(D5A)D4AED51A2(2C4A)2C31A4BA6B60-6B6AD11AD4A2(E97A4BA6B60-6B23A)E97A4BA6B60-6B6A2(D5A)D4AED51A2(2C4A)2C31A4BA6B60-6B6AD16AED45A2C3(3A3C)4A2C19AB5A4BA6B60-6B6A3(D5A)D4AE40A2C3A3C2(3A2CD)4A2C19AB4A6B66-6B29AE40A2C3A3C3A2CE3A2CF4A2C19A4BA6B66-6B2A3B30AE40A2(2C4A)2C19A4B2A4BA6B72-6BAB2AB30AE61A4B2A4BA6B14-4D2-2D10(4-2A)2-2B2A2BAB2AB30AE49A4B2A4BA6B20-4D2-2D11(4-2A)2-2B2A2B73A4B2A4BA6B108-6BA2(4B2A)4B32A3(4B2A)4BA6B120-18BA5(4B2A)4BA18B144-36B171-A5-A149-8(A5-)A74-
