model
size = 15 29 15, scale = 0.05, origin = -y
material 
  colors = A:#C20000 B:#F9FAEE C:#FFF D:#000 E:#110101
voxels
--------------- --------------- --------------- --------------- --------------- --------------- --------------- --------------- --------------- --------------- --------------- --------------- --------------- --------------- --------------- --------------- --------------- --------------- --------------- ----AAAAAAA---- ----ABAAAAA---- ----AAAAAAA---- ----AAAAAAA---- ----AAAAABA---- -----AAAAA----- --------------- --------------- --------------- --------------- 
--------------- --------------- --------------- --------------- --------------- --------------- --------------- --------------- --------------- --------------- --------------- --------------- --------------- --------------- --------------- --------------- --------------- --------------- --------------- ---ABBBBBBBA--- --AAAAAAAAAAA-- --AAAAAAAAAAB-- --BAAAAAAAAAA-- ---AAAAAAAAA--- ---AAAAAAAAA--- ----AAAAAAA---- ------BAA------ --------------- --------------- 
--------------- --------------- --------------- --------------- --------------- --------------- --------------- --------------- --------------- --------------- --------------- --------------- --------------- --------------- --------------- --------------- --------------- --------------- --------------- --ABBBBBBBBBA-- -AAAAAAAAAAAAA- -AAAAAAAAAAAAA- -AAAAAAAAAAAAA- --AAAAAAAAAAA-- --AAAAAAAAAAA-- ---AAAAAAAAA--- ----AAAAAAB---- ------AAA------ --------------- 
--------------- --------------- --------------- --------------- --------------- --------------- --------------- --------------- --------------- --------------- --------------- --------------- --------------- --------------- --------------- --------------- --------------- --------------- --------------- -ABBBBBCCBBBBA- -AAAAACCCAAAAA- -AAAAACCCAAAAA- -AAAAAAACAAAAA- -AAAAAAAAAAAAA- -AAAAAAAAAAAAA- --BAAAAAAAAAA-- ---AAAAAAAAA--- ----AAAAAAA---- --------------- 
--------------- --------------- --------------- --------------- --------------- --------------- --------------- ------CCC------ ------BBB------ ------BBB------ ------BBB------ ------BBB------ ------BBB------ ------DDD------ -----DBBBD----- -----BBBBB----- -----BDBDB----- ----BBDBDBB---- ----BBBBCCC---- ABBBCCCCCCABBBA AAAAACCCCCAAAAA AAAAACCCCCAAAAA AAAAAACCCCAAAAA AAAAAAAAAAAAAAB -AAAAAAAAAAAAA- -AAAAAAAAAAAAA- --AAAAAAAAAAA-- ---AAAAAAAAA--- -----AABAA----- 
--------------- --------------- --------------- --------------- --------------- --------------- --------------- -----CCCCC----- -----BBBBB----- -----BBBBB----- -----BBBBB----- -----BBBBB----- -----BBBBB----- -----BBBBB----- -----BBBBB----- -----BBBBB----- ----CBBBBBB---- ----BBBBBBB---- ----BBBBCCC---- ABBCCCCCCCABBBA AAAACCCCCCAAAAB AAAACCCCCCAAAAA AAAAACCCCCAAAAA AAAAAACCAAAAAAA AAAAAACCAAAAAAA -AAAAAAAAAAAAA- --AAAAAAAAAAA-- ---AAAAAAAAA--- ----AAAAAAB---- 
------E-E------ --------------- --------------- --------------- --------------- --------------- --------------- ----CCCCCCC---- ----BBBBBBB---- ----BBBBBBB---- ----BBBBBBB---- ----BBBBBBB---- ----BBBBBBB---- ----BBBBBBB---- ----BBBBBBB---- ----BBBBBBB---- ----BBBBBBB---- ----BBBBBBB---- ----BBBBBBB---- ABBCCCCCCCCBBBA AAACCCCCCCCAAAA AAACCCCCCCCAAAA BAAACCCCCCAAAAA AAAAACCCCAAAAAA AAAAACCCCAAAAAA -AAAAAAAAAAAAA- -AAAAAAAAAAAAB- --AAAAAAAAAAA-- ----BAAAAAA---- 
------E-E------ ------E-E------ ------C-C------ ------C-C------ ------C-C------ ------C-C------ ------C-C------ ----CCCCCCC---- ----BBBBBBB---- ----BBBBBBB---- --B-BBBBBBB-B-- --B-BBBBBBB-C-- --C-BBBBBBB-C-- --C-BBBBBBB-C-- --C-BBBBBBB-C-- --CCBBBBBBBCC-- ----BBBBBBB---- ----BBBBBBB---- ----BBBBBBB---- ABBCCCCCCCCBBBA AAACCCCCCCCAAAA AAACCCCCCCCAAAA AAAACCCCCCAAAAA AAAAACCCCAAAAAA AAAAACCCCAAAAAA -AAAAAAAAAAAAA- -AAAAAAAAAAAAA- --AAAAAAAAAAA-- ----AAABAAA---- 
--------------- --------------- --------------- --------------- --------------- --------------- --------------- ----CCCCCCC---- ----BBBBBBB---- ----BBBBBBB---- ----BBBBBBB---- ----BBBBBBB---- ----BBBBBBB---- ----BBBBBBB---- ----BBBBBBB---- ----BBBBBBB---- ----BBBBBBB---- ----BBBBBBB---- ----BBBBBBB---- ABBBCCCCCCABBBA AAAACCCCCCAAAAA AAAACCCCCCAAAAA AAAAACCCCCAAAAA AAAAAACCAAAAAAA AAAAAACCAAAAAAA -AAAAAAAAAAAAA- -BAAAAAAAAAAAA- --AAAAAAAAAAA-- ----AAAAAAA---- 
--------------- --------------- --------------- --------------- --------------- --------------- --------------- -----CCCCC----- -----BBBBB----- -----BBBBB----- -----BBBBB----- -----BBBBB----- -----BBBBB----- -----BBBBB----- -----BBBBB----- -----BBBBB----- ----BBBBBBB---- ----BBBBBBB---- ----BBBBBBB---- ABBBCCCCCCABBBA AAAACCCCCCAAAAA AAAACCCCCAAAAAA AAAAAACCCAAAAAA AAAAAACAAAAAAAA AAAAAACAAAAAAAA -AAAAAAAAAAAAA- --AAAAAAAAAAA-- ---AAAAAAAAA--- ----ABAAABA---- 
--------------- --------------- --------------- --------------- --------------- --------------- --------------- ------CCC------ ------BBB------ ------BBB------ ------BBB------ ------BBB------ ------BBB------ ------BBB------ ------BBB------ ------BBB------ -----BBBBB----- ----BBBBBBB---- ----BBBBBBB---- ABBBAACCCAABBBA BAAAAACCCAAAAAA AAAAAACCAAAAAAA AAAAAAAAAAAAAAB AAAAAAAAAAAAAAA -AAAAAAAAAAAAA- -AAAAAAAAAAAAA- --AAAAAAAAAAA-- ---AAAAAAAAA--- -----AAAAA----- 
--------------- --------------- --------------- --------------- --------------- --------------- --------------- --------------- --------------- --------------- --------------- --------------- --------------- --------------- --------------- --------------- --------------- --------------- --------------- -ABBBBBBBBBBBA- -AAAAAAAAAAAAA- -AAAAAAAAAAAAA- -AAAAAAAAAAAAA- -AAAAAAAAAAAAA- -AAAAAAAAAAAAA- --AAAAAAAAAAA-- ---BAAAAAAAB--- ----AAAAAAA---- --------------- 
--------------- --------------- --------------- --------------- --------------- --------------- --------------- --------------- --------------- --------------- --------------- --------------- --------------- --------------- --------------- --------------- --------------- --------------- --------------- --ABBBBBBBBBA-- -AAAAAAAAAAAAA- -AAAAAAAAAAAAA- -AAAAAAAAAAAAA- --AAAAAAAAAAA-- --AAAAAAAAAAA-- ---AAAAAAAAA--- ----AAAAAAA---- ------AAA------ --------------- 
--------------- --------------- --------------- --------------- --------------- --------------- --------------- --------------- --------------- --------------- --------------- --------------- --------------- --------------- --------------- --------------- --------------- --------------- --------------- ---ABBBBBBBA--- --AAAAAAAAABA-- --AAAAAAAAAAA-- --BAAAAAAAAAA-- ---AAAAAAAAB--- ---AAAAAAAAA--- ----AAAAAAA---- ------ABA------ --------------- --------------- 
--------------- --------------- --------------- --------------- --------------- --------------- --------------- --------------- --------------- --------------- --------------- --------------- --------------- --------------- --------------- --------------- --------------- --------------- --------------- ----AAAAAAA---- ----AAAAAAA---- ----AAABAAA---- ----AAAAAAA---- ----BAAAAAA---- -----AAAAA----- --------------- --------------- --------------- --------------- 
