model
size = 13 24 16, scale = 0.05, origin = -y
material 
  colors = A:#555 B:#C0C C:#DDD D:#C0F E:#BBB F:#222 G:#EEE H:#111
voxels
---FCF-FCF--- ------------- ------------- ------------- ------------- ------------- ------------- ------------- ------------- ------------- ------------- ------------- ------------- ------------- ------------- ------------- ------------- ------------- ------------- ------------- ------------- ------------- ------------- ------------- 
---CCC-CCC--- ---CCC-CCC--- ------------- ------------- ------------- ------------- ------------- ------------- ------------- ------------- ------------- ------------- ------------- ------------- ------------- ------------- ------------- ------------- ------------- ------------- ------------- ------------- ------------- ------------- 
---CCC-CCC--- ---CCC-CCC--- ---CCC-CCC--- ------------- ------------- ------------- ------------- ------------- ------------- ------------- ------------- ------------- ------------- ------------- ------------- ------------- ------------- ------------- ------------- ------------- ------------- ------------- ------------- ------------- 
---CCC-CCC--- ---CCC-CCC--- ---CCC-CCC--- ----C---C---- ----G---G---- ------------- ------------- ------------- ------------- ------------- ------------- ------------- ------------- ------------- ------H------ ------------- ------------- ------------- ------------- ------------- ------------- ------------- ------------- ------------- 
------------- ---CCC-CCC--- ---CCC-CCC--- ------------- ----C---C---- -----CCC----- ----CCECC---- ----CEEEC---- ----CEEEC---- ----CCCCC---- -----CCC----- ------------- ------------- ---FFAAAFF--- --FFAAAAAFF-- ------------- ------------- ------------- ------------- ------------- ------------- ------------- ------------- ------------- 
------------- ------------- ------------- ------------- ----C---C---- ---AAAAAAA--- FE-ABBBBBA-EF EE-ABBBBBA-EE ---ABBBBBA--- --AABBBBBAA-- --AAABBBAAA-- --AAAAAAAAA-- ------------- ---AAAAAAA--- ---AAAAAAA--- ---AAAAAAA--- ---GHGAGHG--- ---GHGAGHG--- ---GGAAAGG--- ------------- ------------- ------------- ------------- ------------- 
------------- ------------- ------------- ------------- ----C---C---- ---ABAAABA--- EE-ABBBBBA-EE EE-ABBBBBA-EE -C-ABBBBBA-C- -CABBBBBBBAC- -CBBBBBBBBBC- --CAABBBAAC-- -----CCC----- ---AABBBAA--- ---ADDDDDA--- ---AAAAAAA--- ---ADDDDDA--- ---ADDDDDA--- ---ADDDDDA--- ---AAAAAAA--- ------------- ------------- ------------- ------------- 
------------- ------------- ------------- ------------- ----C---C---- ---AAAAAAA--- ---ABBBBBA--- ---ABBBBBA--- ---ABBBBBA--- --ABBBBBBBA-- --ABBBBBBBA-- --AAABBBAAA-- -----CCC----- ---AABBBAA--- ---ADDDDDA--- ---ADDDDDA--- ---ADDDDDA--- ---ADDDDDA--- ---ADDDDDA--- --AADAAADA--- --A-A---A-A-- --A-A---A-A-- --A-A---A-A-- ---A-----A--- 
------------- ------------- ------------- ------------- ------------- ---AAAAAAA--- ---ABBBBBA--- ---ABBBBBA--- ---ABBBBBA--- --ABBBBBBBA-- --ABBBBBBBA-- --AAABBBAAA-- -----CCC----- ---AABBBAA--- ---ADDDDDA--- ---ADDDDDA--- ---ADDDDDA--- ---ADDDDDA--- ---ADDDDDA--- --AAAAAAAAA-- --AA-----AA-- --AA-----AA-- --AA-----AA-- ---A-----A--- 
------------- ------------- ------------- ------------- ------------- ----AAAAA---- ---AAAAAAA--- ---AAAAAAA--- ---AAAAAAA--- --AAAAAAAAA-- --AAAAAAAAA-- ---AAAAAAA--- ------------- ----AAAAA---- ---AAAAAAA--- ---AAAAAAA--- ---AAAAAAA--- ---AAAAAAA--- ---AAAAAAA--- ----AAAAA---- ------------- ------------- ------------- ------------- 
------------- ------------- ------------- ------------- ------------- ------A------ ------------- ------------- ------------- ------------- ------------- ------------- ------------- ------------- ------------- ------------- ------------- ------------- ------------- ------------- ------------- ------------- ------------- ------------- 
------------- ------------- ------------- ------------- ------------- ------A------ ------------- ------------- ------------- ------------- ------------- ------------- ------------- ------------- ------------- ------------- ------------- ------------- ------------- ------------- ------------- ------------- ------------- ------------- 
------------- ------------- ------------- ------------- ------------- ------A------ ------------- ------------- ------------- ------------- ------------- ------------- ------------- ------------- ------------- ------------- ------------- ------------- ------------- ------------- ------------- ------------- ------------- ------------- 
------------- -------A----- ------AA----- ------A------ ------A------ ------A------ ------------- ------------- ------------- ------------- ------------- ------------- ------------- ------------- ------------- ------------- ------------- ------------- ------------- ------------- ------------- ------------- ------------- ------------- 
------------- -------A----- ------------- ------------- ------------- ------------- ------------- ------------- ------------- ------------- ------------- ------------- ------------- ------------- ------------- ------------- ------------- ------------- ------------- ------------- ------------- ------------- ------------- ------------- 
------------- -------F----- ------------- ------------- ------------- ------------- ------------- ------------- ------------- ------------- ------------- ------------- ------------- ------------- ------------- ------------- ------------- ------------- ------------- ------------- ------------- ------------- ------------- ------------- 
