model
size = 12 32 12, scale = 0.05, origin = -y
material 
  colors = A:#E00 B:#FF0 C:#EEE D:#C60
voxels
101-8(2A10-)2(AC10-)2C2(10-CA)10-2A9-4B9-2B201-C3A5(8-4A)3(8-3AC)3(8-4A)2(8-C3A)7-6B6-6B7-4B9-2B176-6A2(6-C5A)2(6-6A)2(6-5AC)7(6-6A)5-8B4-8B5-6B7-4B9-2B10-2B151-2(8A4-)C7A4-C6AC4-7AC9(4-8A)3-10B2-10B3-8B5-6B6-6B7-4B9-2B138-10A2(2-9AC)2-10A2(2-C9A)6(2-10A)2(2-9AC)-12B-10B2-10B3-8B5-6B6-6B7-4B9-2B10-2B27-7(D11-)D-2(11AC)48A2(C11A)C34A2(C11A)C12A24B-10B2-10B3-8B4-8B5-6B7-4B8-4B9-2B15-7(D11-)D-96AC3(10A2C)35A24B-10B2-10B3-8B4-8B5-6B7-4B8-4B9-2B102-2(C9A2-)4(10A2-)3(9AC2-)2(10A2-)2(C9A2-)C9A-12B-10B2-10B3-8B5-6B6-6B7-4B9-2B10-2B115-8A3(4-C7A)3(4-7AC)7(4-8A)3-10B2-10B3-8B5-6B6-6B7-4B9-2B140-6A2(6-5AC)6-C4AC6-C5A9(6-6A)5-8B4-8B5-6B7-4B9-2B10-2B153-2(3AC8-)2(4A8-)4(C3A8-)4(4A8-)3AC8-3AC7-6B6-6B7-4B9-2B178-7(2A10-)2(CA10-)2C3(10-AC)10-2A9-4B9-2B101-
