model
size = 11 23 28, scale = 0.05, origin = -y
material 
  colors = A:#EEE B:#111 C:#444 D:#C39 E:#39F F:#222
voxels
----------- ----------- ----------- ----------- ----------- ----------- ----------- ----------- ----------- ----------- ----------- ----------- ----------- ----------- ---CCCCC--- --CC---C--- --C----C--- --C----C--- --C----C--- --C----C--- --C---C---- --CCCC----- ----------- 
----------- ----------- ----------- ----------- ----------- ----------- ----------- ----------- ----------- ----------- ----------- ----------- ----------- --AAAAAA--- --AAA--A--- --A----A--- --A----AA-- --A----AA-- --A----AA-- --A----AA-- --A---AA--- --AAAAA---- ----------- 
----------- ----------- ----------- ----------- ----------- ----------- ----------- ----------- ----------- ----------- ----------- ----------- ----------- --AAAAAA--- --A----A--- --A----A--- --A----A--- --A----AA-- --A----AA-- --A----AA-- ---A--AA--- ----AAA---- ----------- 
----------- ----------- ----------- ----------- ----------- ----------- ----------- ----------- ----------- ----------- ----------- ----------- ----------- --AAAAAA--- --A----A--- --A----A--- --A----A--- --A----AA-- --A----AA-- --A----AA-- ---A--AA--- ----AAA---- ----------- 
----------- ----------- ----------- ----------- ----------- ----------- ----------- ----------- ----------- ----------- ----------- ----------- ----------- ----------- --AAAAAA--- --A----A--- --AAAAAA--- --AAAAAAA-- --AA--AAA-- --AAAAAAA-- ---A-AAA--- ----AAA---- ----------- 
----------- ----------- ----------- ----------- ----------- ----------- ----------- ----------- ----------- ----------- ----------- ----------- ----------- ----------- --A-------- --A-AAAA--- --AAAAAA--- --AAAAAAA-- --AAA-AAA-- --AAAAAAA-- ---AAAAA--- ----AAA---- ----------- 
----------- ----------- ----------- ----------- ----------- ----------- ----------- ----------- ----------- ----------- ----------- ----------- ----------- ----------- ----------- ----AAA---- ---AAAAA--- --AAAAAAA-- --AAA-AAA-- --AAAAAAA-- ---AAAAA--- ----AAA---- ----------- 
---AAAAA--- ---AAAAA--- ---AAAAA--- ---AAAAA--- ---AAAAA--- ---AAAAA--- ---AAAAA--- ---AAAAA--- ---AAAAA--- ---AAAAA--- ---AAAAA--- ---AAAAA--- ---AAAAA--- ---AAAAA--- ---AAAAA--- ---AAAAA--- ---AAAAA--- ---AAAAA--- ---AAAAA--- ---AAAAA--- ---AAAAA--- ----------- ----------- 
-AAA---AAA- -AAA---AAA- -AAA---AAA- -AAA---AAA- -AAA---AAA- -AAA---AAA- -BAA---AAA- -BAA---AAA- -BAA---AAA- -BAA---AAA- -BAA---AAA- -BAA---AAA- -BAA---AAA- -BAA---AAA- -BAA---AAA- -BAA---AAA- -BAA---AAA- -BAA---AAA- -AAA---AAA- -AAA---AAA- -AAA---AAA- -AAAAAAAAA- -CCCCCCCCC- 
AA-------AA AA-------AA AA-------AA AA-------AA AA-------AA BA-------AA AA-------AA AA-------AA AA-------AA AA-------AA AA-------AA AA-------AA AA-------AA AA-------AA AA-------AA AA-------AA AA-------AA AA-------AA BA-------AA AA-------AA AA-------AA AA-------AA CC-------CC 
A---------A A---------A A---------A A---------A A---------A B---------A B---------A B---------A B---------B A---------B A---------B A---------B B---------B B---------A B---------A B---------A A---------A A---------A B---------A A---------A A---------A A---------A C---------C 
A---------A A---------A A---------A A---------A A---------A B---------A A---------A A---------A B---------A A---------A A---------A B---------B A---------A E---------A A---------A A---------A B---------A A---------A B---------A A---------A A---------A A---------A C---------C 
A---------A A---------A A---------A A---------A A---------A B---------A B---------A B---------A B---------A A---------A A---------B B---------A E---------A E---------A E---------A A---------A B---------A A---------A B---------A A---------A A---------A A---------A C---------C 
A---------A A---------A A---------A A---------A A---------A B---------A A---------A A---------A F---------A A---------A A---------A B---------B A---------A E---------A A---------A A---------A B---------A A---------A B---------A A---------A A---------A A---------A C---------C 
A---------A A---------A A---------A A---------A A---------A B---------A A---------A A---------A F---------B A---------B A---------B B---------B A---------B D---------A A---------A A---------A B---------A A---------A B---------A A---------A A---------A A---------A C---------C 
A---------A A---------A A---------B A---------B A---------B B---------B B---------B B---------B B---------B A---------A A---------A B---------A D---------A D---------A D---------A A---------A B---------A A---------A B---------A A---------A A---------A A---------A C---------C 
A---------A A---------A A---------A A---------A A---------A B---------B A---------A A---------A B---------B A---------A A---------A B---------A A---------A D---------A A---------A A---------A B---------A A---------A B---------A A---------A A---------A A---------A C---------C 
A---------A A---------A A---------A A---------A A---------A B---------A B---------A B---------A B---------B A---------A A---------A A---------A B---------A B---------A B---------A B---------A A---------A A---------A B---------A A---------A A---------A A---------A C---------C 
AA-------AA AA-------AA AA-------AA AA-------AA AA-------AA BA-------AA AA-------AA AA-------AA AA-------AA AA-------AA AA-------AA AA-------AA AA-------AA AA-------AA AA-------AA AA-------AA AA-------AA AA-------AA BA-------AA AA-------AA AA-------AA AA-------AA CC-------CC 
-AAA---AAA- -AAA---AAA- -AAA---AAA- -AAA---AAA- -AAA---AAA- -AAA---AAA- -BAA---AAA- -BAA---AAA- -BAA---AAA- -BAA---AAA- -BAA---AAA- -BAA---AAA- -BAA---AAA- -BAA---AAA- -BAA---AAA- -BAA---AAA- -BAA---AAA- -BAA---AAA- -AAA---AAA- -AAA---AAA- -AAA---AAA- -AAAAAAAAA- -CCCCCCCCC- 
---AAAAA--- ---AAAAA--- ---AAAAA--- ---AAAAA--- ---AAAAA--- ---AAAAA--- ---AAAAA--- ---AAAAA--- ---AAAAA--- ---AAAAA--- ---AAAAA--- ---AAAAA--- ---AAAAA--- ---AAAAA--- ---AAAAA--- ---AAAAA--- ---AAAAA--- ---AAAAA--- ---AAAAA--- ---AAAAA--- ---AAAAA--- ----------- ----------- 
----------- ----------- ----------- ----------- ----------- ----------- ----------- ----------- ----------- ----------- ----------- ----------- ----------- ----------- ----------- ----AAA---- ---AAAAA--- ---A--AAA-- ---AA-AAA-- ---AAAAAA-- ---AAAAA--- ----AAA---- ----------- 
----------- ----------- ----------- ----------- ----------- ----------- ----------- ----------- ----------- ----------- ----------- ----------- ----------- ----------- ----------- --AAAAA---- --A----A--- --AA--AAA-- --AAA-AAA-- ---AAAAAA-- ---AAAAA--- ----AAA---- ----------- 
----------- ----------- ----------- ----------- ----------- ----------- ----------- ----------- ----------- ----------- ----------- ----------- ----------- ----------- --AAAA-A--- --A----A--- --A----A--- --A----AA-- --AAA-AAA-- ---AAAAAA-- ---AAAAA--- ----AAA---- ----------- 
----------- ----------- ----------- ----------- ----------- ----------- ----------- ----------- ----------- ----------- ----------- ----------- ----------- --AAAAAA--- --A----A--- --A----A--- --A----A--- --A-----A-- --AA---AA-- ---AAAAAA-- ---AAAAA--- ----AAA---- ----------- 
----------- ----------- ----------- ----------- ----------- ----------- ----------- ----------- ----------- ----------- ----------- ----------- ----------- --AAAAAA--- --A----A--- --A----A--- --A----A--- --A-----A-- --AA---AA-- ---A---AA-- ---AAAAA--- ----AAA---- ----------- 
----------- ----------- ----------- ----------- ----------- ----------- ----------- ----------- ----------- ----------- ----------- ----------- ----------- --AAAAAA--- --AAA--A--- --A----A--- --A-----A-- --A-----A-- --A-----A-- --A-----A-- ---AAAAA--- ----------- ----------- 
----------- ----------- ----------- ----------- ----------- ----------- ----------- ----------- ----------- ----------- ----------- ----------- ----------- ----------- ---CCCCC--- ---C---C--- --C-----C-- --C-----C-- --C-----C-- --C-----C-- --CCCCCC--- ----------- ----------- 
