model
size = 31 32 20, scale = 0.05, origin = -y
material 
  colors = A:#000
voxels
249-29A-6(A4-)6(2A5(4-A)4-)32A559-29A4(2-A3-4(A4-)A3-A)-A29-A217-A29-A467-27A2(4-A6-2(A5-)A6-A)157-A29-A217-A29-A467-A6-2(A5-)A6-A219-A8(29-2A)29-A373-A27-A2-A27-A3-27A4-A6-2(A5-)A6-A219-A29-A217-A29-A311-A27-A2-A27-A96-27A2(4-A25-A)3-4(A27-A2-)A27-A-A29-A217-A29-A249-A27-A2-A27-A158-A6-2(A5-)A6-A219-A29-A217-A29-A187-A27-A2-A27-A220-A6-2(A5-)A6-A219-A8(29-2A)29-A125-A27-A2-A27-A282-27A2(4-A25-A)3-4(A27-A2-)A27-A-A29-A217-A29-A63-A27-A2-A27-A344-A6-2(A5-)A6-A219-A29-A217-A29-A-A27-A2-A27-A406-A6-2(A5-)A6-A219-A29-A217-A29-A-A27-A437-27A2(4-A25-A)3-4(A27-A2-)A27-A-A29-A217-A29-A467-A6-2(A5-)A6-A219-A8(29-2A)29-A467-A6-2(A5-)A6-A219-A29-A217-A29-A467-27A2(4-A25-A)3-4(A27-A2-)A27-A-2(A29-A217-A29-A467-A6-2(A5-)A6-A219-)A8(29-2A)29-A467-27A2(4-A6-2(A5-)A6-A)157-A29-A217-A29-A559-29A4(2-A3-4(A4-)A3-A)-A29-A217-A29-A714-29A-6(A4-)6(2A5(4-A)4-)32A465-
