model
size = 31 32 20, scale = 0.05, origin = -y
material 
  colors = A:#AFAFAF B:#000
voxels
249-29A-6(A4-)6(2A5(4-A)4-)32A559-29A4(2-A3-4(A4-)A3-A)-A29-A217-A29-A467-27A2(4-A6-2(A5-)A6-A)157-A29-A217-A29-A467-A6-2(A5-)A6-A219-A8(29-2A)29-A373-B27-B2-B27-B3-27B4-A6-2(A5-)A6-A219-A29-A217-A29-A311-B27-B2-B27-B96-27A2(4-A25-A)3-4(A27-A2-)A27-A-A29-A217-A29-A249-B27-B2-B27-B158-A6-2(A5-)A6-A219-A29-A217-A29-A187-B27-B2-B27-B220-A6-2(A5-)A6-A219-A8(29-2A)29-A125-B27-B2-B27-B282-27A2(4-A25-A)3-4(A27-A2-)A27-A-A29-A217-A29-A63-B27-B2-B27-B344-A6-2(A5-)A6-A219-A29-A217-A29-A-B27-B2-B27-B406-A6-2(A5-)A6-A219-A29-A217-A29-A-B27-B437-27A2(4-A25-A)3-4(A27-A2-)A27-A-A29-A217-A29-A467-A6-2(A5-)A6-A219-A8(29-2A)29-A467-A6-2(A5-)A6-A219-A29-A217-A29-A467-27A2(4-A25-A)3-4(A27-A2-)A27-A-2(A29-A217-A29-A467-A6-2(A5-)A6-A219-)A8(29-2A)29-A467-27A2(4-A6-2(A5-)A6-A)157-A29-A217-A29-A559-29A4(2-A3-4(A4-)A3-A)-A29-A217-A29-A714-29A-6(A4-)6(2A5(4-A)4-)32A465-
