model
size = 26 4 32, scale = 0.05, origin = -y
material 
  colors = A:#C93 B:#F00 C:#30F D:#FFF E:#6F0 F:#222 G:#FF0 H:#050 I:#960 J:#F0F K:#6F6 L:#3CF
voxels
9-8A18-8A68-12A14-3AI3G5A19-G45-14A12-2A2F2I3G5A14-F3-3G24-G17-16A10-2A4FI3G6A13-2F2-2G42-18A8-2A2H3FAIG8A12-3F24-F20-18A8-A2E2HF12A10-E48-20A6-2A3EH14A8-3E47-20A6-A4E15A8-2E25-E21-22A4-3A2E17A8-E47-22A4-2A3K17A56-22A4-A3DK17A6-D48-24A2-A5D18A4-4D46-24A2-2A4D18A4-4D24-D20-29A2LD20A52-28A2CL21A2-C49-27A4C21A2-2C48-27A4C21A2-3C23-C23-27A5C20A2-3C47-29ACJ21A53-24A2-2A3J19A54-24A2-2AJ2B19A6-B48-22A4-A4B17A5-4B47-11A3-8A4-A5B5A3-8A5-4B23-B23-10A5-7A4-A4B5A5-7A6-2B49-5A-3A5-6A6-A2B2A-3A5-6A8-B49-4A3-2A5-6A6-4A3-2A5-6A59-4A3-2A3-6A8-4A3-2A3-6A60-4A4-10A8-4A4-10A61-4A5-7A10-4A5-7A63-4A5-5A12-4A5-5A65-4A5-2A15-4A5-2A69-3A23-3A66-
