model
size = 30 18 32, scale = 0.05, origin = -y
material 
  colors = A:#C30 B:#930 C:#F30 D:#400 E:#B00 F:#200 G:#500 H:#700 I:#800 J:#A00 K:#F60 L:#E00 M:#C00 N:#F90 O:#D00 P:#F00 Q:#000 R:#FC0 S:#900 T:#111 U:#FF0 V:#600
voxels
79-2DIHG27-4D473-C2I26-2DI2-HGE24-3IHG2E26-HG2D440-3C2I24-2D4-2IHG24-4IH-EJ12-2I11-IHG-2D10-F2L14-E2D10-F-K27-F-N27-FC-C27-F2E27-2FM29-F213-3C27-4K20-3C3-D-2C20-E-E13-EJ11-A2-A13-EJD10-C16-EJ-F9-K-K16-D10-3K28-3O27-O-O27-F3M27-F2-3M25-6F178-2L27-4K21-3N2-D-2N23-K29-C27-2K15-JDF10-2K16-DF10-2K28-2L28-3L27-F3O27-2M2-3M24-6E177-2L24-2F2-3K-K20-F2-3(N-)N20-3F27-3F75-DF134-4M27-3E174-DF-2L2-L21-2D2F-C2-C21-D-2F-N2-N22-D309-2F27-F110-2D2FL2-L22-2DF-L2-L21-JD-F2(-C)26-F99-G29-2(GF28-)F30-F26-2EF27-2F26-G-J25-VFE26-G2F81-2J2D3-L22-J2-DF-I23-2J-DF-P26-D3-C3-HGE27-HG2E2(27-G-E)J28-EJ29-J28-J29-D26-EJD25-G2-J26-GEJ25-2GE25-V2-E26-HGF53-EJD3-P23-E-2DFM21-2I-EJ2D-P3-IHGE13-3L3-D3-C2-I16-K-K11-H2-J12-C-N12-G-J12-2C-C11-GEJ13-3E12-EJ13-3M12-EJ15-M11-EJD2(27-EJ)26-GEJ83-GE4-AE22-V-F53-2EJ2DFP20-2(E2-)2DF2-I2H15-H3-2E-2DF2-IH2-E13-H5-J3-C2-H2-E13-K-K10-2H-E13-3K12-GE14-3O12-E14-O-O27-4M27-M2-3M25-6E155-3A21-GEF4-AI48-2EJD2F2IH20-GE2-D2F2IHGE8-2P8-GE-JD2F2I2-E7-3C5-2K3-E3-F-IHGE7-2L6-2K10-HGE6-3C6-2K19-KCK6-2L19-3C6-H2L19-2C6-4O19-C7-2M2-3M15-M8-6E156-3A27-ABH38-3IO4-OG2EJDFIHG11-6CF-2C-7ADE9-C2-2C2P2F-PG2AJD2A2-E8-P-2P7-AB2EJDFIHGE8-C-C8-2AE3B2A3-B6-3L9-2A3B3A3-2A5-3K9-B3AB2AB2-3A5-3C9-5AB2A-4A6-P11-2(2AB)-3ABA6-L-2L8-4M4-2ABA7-J-2J8-3E4-BAB9-3S16-2A92-A29-A26-3AB28-ID7-3S7IGAB2ABAD3AD7-2C2-6CA2B5ADABAD6-C3-8C4ABA2-3A6-P-P2H5-AB3AJ2AB2-BA7-2CH7-2(AB)6A3BA5-2CH8-B2A2B3A2B6A3-2KH8-BA4B6ABABF3-C2H8-2AB5ABAB4AF4-HP8-B5ABAB4ABAF4-O3H7-3AB6AB2ABF5-H-H3J4-2(2AB)ABA3BAB-G5-4IS5-14AL22-5ABAL24-BAB2AF26-2ABQ27-3AQ24-2(BA)BQ26-2ID7-2O8S2A5-3AD8-3C6-A2BA5-BABD7-5C2-A3C3BA4-3A14-2ABA2BGE2AB-2(AB)15-2B3A2B4AB2A2B14-7A5B2AB2AF12-3AB6AB5ABI12-5A2BA3B6AG12-2B2(5AB)2ABG13-B2(2A2B)2AB3AL8-2HJ4-5AB3AB4AL7-3HI4-2B3A2(B2A)2(BA)Q17-AB8A2BAQ17-2AB3A2(B2A)TQ23-AB2ABTQ24-2ABAL25-AB2A2Q25-2ID10-7O22-2C29-3CB2ABAB21-2A2B3LGE3A18-2A2BAB6ABAB3A14-8AB4AB3AI12-4AB3AB2AB3ABAG12-2A2B2(2AB)7AG12-AB6A3(BA)2BL14-B4AB6A2BAL14-6A2B6ABL15-5ABAB6AL18-7AB5AQ17-4AB2AB5AQ23-2(B2A)Q24-5AQ24-2(AB)2Q25-2ID11-6C24-2C28-4PB3A21-2(BA)3EGE2AB18-AB3ABAGEAB7A14-2(BA)2B6A2B3AI12-8AB6ABAG12-B3A3(BA)2B5AG12-2AB3A2BAB6AL14-A2BAB5AB3ABL14-4AB2A2(B3A)L15-2B2ABA2(B2A)BAL18-2AB3A2B2AB2AQ17-3A2(B4A)Q23-AB4AQ24-4BAQ24-4A2Q25-2ID8-9K2A5-3AD9-3C3-C-4B5-ABAD8-3C4LB2LAB2A4-ABA14-3A4IGABA-B3A15-6AGAB4A3B14-4AB8AB2ABF12-3(2AB)6A2BI12-6AB4ABAB3AG12-AB3A2B2(3AB)2AG9-2M2-AB2AB6A2(BA)L6-4J2S3-2(B6A)L8-2IH4-BA3B8ABAQ17-B4ABAB3A2BQ17-5AB3ABABTQ23-5ATQ24-3BAL25-A2BA2Q25-2ID7-2N8K5ABD3AD8-3K4-C-2B2AB3AD2ABD7-3C6-B2C2AB2A2-3A7-3H6-4AHG2AB2-AB8-3S6-3A2B7ABA6-2C8-B4AB8ABA4-2C8-ABA2B2AB6ABF4-2K8-3A2B2A2BAB3ABF5-L8-11A2B2AF5-7M3-AB5AB4ABAF5-7J3-B7AB5A-G5-5I5-3AB10AL22-7AL24-2AB2AF26-2ABQ27-B2AQ24-3B2AQ26-2ID7-2C8N3AB2AD12-N2CH4K2-3B4AD10-C3-9C2B3A14-2H6-3AHG2B12-H-2H7-4AGBAB3-A6-2C10-3A2B3A3-AB5-2C10-2AB2A2BA2-3A5-CN10-A3B4A-AB2A6-A-H9-6A-3ABA8-2H16-A2BA7-J-4HJ12-B2A9-I4H14-BA92-A29-A26-B2AB28-ID15-4RGEJDF20-N9-E11-CH6-3C2-GE3-E10-J2H8-3H2-JDF11-2H27-2H28-HC28-HN29-H230-3A27-2AH45-5RGEJDF20-R4-GE3-G19-5CGE3-G21-3J2-JDFG360-2AB28-AI45-6N-EJDF18-2U3-2UGEJDFG17-7KGEJ2-G21-DO4-DFG27-DFG330-BE76-5CG23-5R-G2E-DF17-CR-3R-G-E-D-GE16-2C3-C4-DF-E26-DF-E28-GE377-2P-2PG23-3A3-G-J20-R2-R3-G-J-FIHG15-3C3-C4-FI-GE26-I-GE27-HGE28-G350-2PG23-2J2-J-G22-N-N2-N-G24-C9-IHG15-3L9-IHGE29-3(E27-HG)28-H28-IH27-FIH26-2(DFI27-)D29-D84-PGE27-LGE22-2A3-BG22-C-2N26-L-L27-M-M11-HGE14-C12-HGE-DF24-H-EJDF26-E-D24-2(I-G26-F)-H26-D2-H26-D-I26-D-F27-D29-C56-2E27-GE-J26-GE-J20-2ND27-P-D27-L-L15-D11-3K11-HGE-DF11-2N11-HGE2-F24-H2F-D24-F-F26-IF-G26-F-F26-F-2F26-3F26-D2F27-DF28-CF56-2(JDF26-E)-DF79-2PD14-JDF10-N-N14-J-F10-C-2R14-DF11-3K28-2C27-2N-N32-EJD209-DFO26-2DFCI25-D2-M2I31-GEJ27-GE-D28-JDF11-2D15-DF11-C2D27-N-N27-N2-G26-C3-2E26-CG5-F24-2EJ2D179-F2E27-FDCIH25-FD-IHG2E26-HGE-J27-2E-D28-2DF71-GDG28-2GE27-GD2EJ26-2D2-2DF25-4D212-DIH27-2D2-EJ25-4DJD26-G3D395-
