model
size = 32 18 32, scale = 0.05, origin = -y
material 
  colors = A:#C30 B:#F30 C:#B00 D:#500 E:#200 F:#400 G:#A00 H:#800 I:#F60 J:#700 K:#E00 L:#F90 M:#F00 N:#C00 O:#FC0 P:#D00 Q:#900 R:#FF0 S:#600
voxels
367-2(2A30-)2A509-2(4A28-)E2AE29-2E29-4E413-2A29-2(4A28-)3AE28-K2AK2(28-E2AE)209-2E31-2E41-2E29-2(4E28-)4A27-2(6A26-)D4AD26-K4AK27-E2AE28-E2AE176-2F30-F-F9-A2HA17-3F8-H2DH28-D2AD2(28-E2AE)28-4A27-3(6A26-)E4AE26-K4AK26-E4AE26-6A111-2(2G30-)3G8-6A9-3E9-G4-6A7-4E10-G4-6A7-3E11-G4-6A26-6A27-4A27-2(6A26-)6A25-D6AD24-K6AK24-E6AE24-8A25-2F2-2F26-2F2-2F46-3C29-C-C4-CG4-4A11-2F3-2C4-CG3-6A8-4F9-CG3-6A7-2F-F9-2CG3-6A7-F-F10-C-G3-6A7-2F12-GF3-6A20-GF4-4(6A26-)6A24-K-6A-D22-K8AK23-8A25-2A2-2A26-2A2-2A14-CD6-2C2(2-2A)13-2C6-C-C3-A2-A11-2GF-CD5-C-C2-6A12-F10-C-8A8-3G8-D-2C-8A8-G10-D-C2-8A6-G12-D-C2-8A19-C-G2-8A21-G3-6A20-GF4-3(6A26-)6A23-DA2-4A2-AD20-K10AK55-2A2-2A24-C-2A2-2A13-2DJ6-D-C-2A2-2A11-CG2DJ5-D2-C-2A2-2A5-C4-C-G-DJ5-D2-C8A4-2C3-2CG8-3D-8A4-3C13-2D2-2(8A5-3C16-)8A6-2C13-C2-8A21-C2-8A19-C2G2-8A19-CG4-6A26-6A27-4A23-D2A8-2AD19-4A4-4A55-2A2-2A23-JDC2A2-2A13-2JH6-J2-C2A2-2A4-CD5-2C2JH5-J2-DC2A2-2A4-C2D3-D2C-JH5-3JD-6A4-C2D3-D2C13-6A4-CD-D17-8A4-4D2(16-8A5-D-D)2(16-8A6-2D)11-3C2-8A19-C-G3-6A19-C2G4-6A54-2A10-2A84-JDF4-2F22-2J2F4-2FC2D9-H-H6-HJ9-C3DJ5-D-3H6-H2JD-A2-A3-2D2-J4-2D10-2J-6A3-D2-J5-D13-6A4-DJ-J18-6A6-2(3J16-8A5-)J-J16-8A5-J18-8A5-J19-6A6-3J13-C3-6A7-2J10-C-C5-4A153-HJA4-2A3E10-2H7-2H2A4-2A2-2E6-2JH9-2H12-H4-HJ2-2H8-HJ7-4E2H4-2J13-6A3-2E2H19-2(6A26-)6A25-8A25-6A7-2H17-6A6-3H17-6A6-H14-2D3-6A6-H-H11-2D5-4A7-3H10-3C130-2HA4-2A3F10-2H8-H2A4-2A2-2F5-5H9-H2A4-2A3-FE4-3H-2H9-H6A-4FE6-H12-8A2-2F20-2(8A24-)8A25-2(6A26-)6A7-EH17-6A6-2EH18-4A7-E20-4A7-E-H11-2D17-EH11-2C93-3K2M2EA4-2A3G6-PC2-2BI-IBK3-E2A4-2A2-G6-3B-A-B-2L4-E2A4-2A2-G6-N-B8-3B2E7A2G22-4(8A24-)8A25-2(6A26-)6A27-4A7-2FE18-4A7-2FE11-SD16-F-E11-D17-F-E12-2CG15-2B39-B6-2EFA4-2A3C5-2EC3-B2I3-HN2E2A4-2A-3CG3-2EB2-A-BL2-B2M2EF2A2-3A4CG3-E-B13-F7A5(24-8A)25-2(6A26-)6A10-E16-4A28-4A40-2F11-D-C16-2F12-D-C15-2B39-BK5-2FG2A2-3A2D6-2FE3-B3I3-E2F3A2-3A-2DC3-G2FE3-A-2L4-2FG7A3D4-GF-E13-2G3C3D24-4ACDAD4(24-8A)25-6A26-6A17-2N7-6A9-F-E4-3C8-4A11-F16-4A54-SD30-JSD56-B4K2-FGC2A2-3A2OL3D2CG6-3IBKE2F-2(3A2-)R3DC-GF4-AB2-LBE2FG8A-BI3D3-F14-CA3DH3JG22-4AD3A4(24-8A)25-6A26-6A16-3N7-6A9-G-F4-3C8-4A11-2F166-2KE2FG2CDQPB2IL2OLB2MDC8-2I2-2F2(2-3A)2-R3-D2C7-2L2-2F2-6A2B-BI3-D2C10-E2FG2C2AKCH2AJGP2B19-C7A4(24-8A)25-6A26-6A16-3N7-6A9-C-F4-3C23-GF168-EFG2CDHQPB2IL2OLB3M11-2E3-C-2A2-2A4-O-GKD10-2E-G2CD2B2AK4BIO-LAD16-3AKCH2AJGP21-4(8A24-)8A25-6A26-6A10-CG4-N-N7-6A16-2C24-CG167-EFG2C-PHQPB2IL2OLB14-EF-2CD2B9-O13-LE-G2CDM2BAMKA3BIO20-3AKCH2A4(24-8A)25-6A26-6A16-NP8-6A10-2C15-4A17-2C24-2C167-2FG4-HQPB2IL-OLBM12-E2FG2(3-2B)ILO-OA10-BL2-FG4-2BAMA-3BI2O10-CIEF6-6A16-ABE7-3(6A26-)6A15-BP9-6A15-CPK9-4A11-DC3-2NP10-2A11-L-C3-N-N24-DC4-2C200-HQPB2IL2-LBM12-EF6-2(B2-)I2-ROAG9-BL-FG5-BABMK-B2-I2-L11-E8-4A5-3BL7-H2-E8-4A7-K8-K-I9-4A16-3I9-4A16-L2I9-4A10-2O5-PK9-4A10-ILD3-C-K23-B-D3-2NP25-D4-2N24-BD206-HQPB2IL25-2(B2-)I2-ROAG9-BLE7-B-BMK-B2-IO2-A8-C-E8-4A5-2B-2L6-H2-E9-2A8-2KM6-K-I21-NKM7-I22-I2L5-2I22-L2O4-BPK23-I-D3-CPK23-B-D3-2NP23-L-D238-HQP-2IL24-2B-B3-I24-M2(B-)K-B3-2OLA20-2A7-B2-L7-A11-2A2(8-K)B24-M5-2I22-BI-L4-LI23-L-O4-B25-ILD18-2N10-L19-Q2G8-LO238-PHQ2-2IL24-2B2(-B)-I24-M2B2-K-B38-2L30-KM30-NKM30-IL31-O52-2N26-2G2-Q2G25-QH2-J2H216-HQP2-ILO24-B-B2-BIL24-3B2-B-B222-N26-GQ2-3G25-HJ2-3H216-HQP3-LO24-B-B2-BIL24-B-B2-2B26-M5-J190-N25-2GQ2-3G24-QHJ2-3H216-HQ30-3B3-IL26-B2-2B-B23-2M4-2JG29-QJ152-KP4-NC24-2G3-3G24-QHJ3-2H248-2B29-M2-B3-B-B22-B2M4-J-G23-2B4-Q2J126-A24-KP4-NC29-2G25-QH4-2H279-M2B5-B23-B6-J-G22-K-B4-Q-J22-BKB4-B-B22-3I4-B-B22-3B4-I-L22-B-M4-K-B22-K-P4-N24-N2G4-2G343-B2M29-K2B5-J23-BKB4-3B22-3I4-3B22-3B4-I2L22-B2M5-A24-KP445-BKB5-B23-3I5-B23-3B5-L332-
