model
size = 32 28 26, scale = 0.05, origin = -y
material 
  colors = A:#FFF B:#EEE C:#AAA D:#DDD E:#BBB F:#777 G:#888 H:#100 I:#111 J:#555 K:#222 L:#444 M:#001 N:#CCC O:#500 P:#C33 Q:#333 R:#933 S:#F33 T:#C66 U:#400 V:#F69 W:#000
voxels
299-2(F31-)F669-CG2(F29-C-)2F28-C-2F28-C7(G2FJ28-)G2F29-G2F443-EC30-2(E2CGF27-)EC-GF27-EC-GF28-C2-F28-2C-FJ27-2C-F4(J28-C2-)2(J27-2C-F)J27-3(2CGF28-)2CG316-DE30-DE-CGA26-D-2C-FA25-2(D2-CG27-)D2(E2-G28-)EC-G28-E4(C-GF28-)C-GF27-2(EC-GF6-2A19-)2(E2-G7-2A18-D)E-CG27-DE2C28-DEC29-3A253-BD31-DECG3A26-EC-F5A24-C-F5A21-BD-CG-F4A21-B2(DECG28-)D5(ECG29-)ECG7-2A20-2(ECG6-4A18-D)2(ECG6-4A17-BD)-CG7-2A18-B-EC28-B-E29-3A29-4A28-4A29-3A124-B31-BD3-2A26-2DEC5A24-DECG5AJ20-B2DECG2A2-2AK19-B2DE-GF4A2JK18-B2DE5-AK3J18-3(B2D29-)2(B2DE28-)B2DE8-2A19-2DE7-4A19-DE7-4A28-4A19-DE7-4A18-2(2DE7-4A17-B)2DE8-2A18-B2D29-A-A29-A-2A28-2A-AJ28-3A2J28-5K29-MLM57-B31-2BDE3A26-BDEC5A22-2BDECG6A20-2BDECG2A3-2A19-2BDE-GF3A2-2AQ17-2BDE5-5AK16-2B-DE7-4K16-2(2B-DE27-)2B-DE28-B2-E8-2A18-2B-EC6-4A17-2BDEC6-4A18-BDECG4-6A17-BDECG4-6A19-ECG4-6A20-CG4-6A18-2(DEC6-4A17-2B)DE8-4A16-3A10-3A16-4A9-3A16-4AQ8-3A17-3A2J28-A4L29-3M56-2B29-3B-DE3A23-4BD-C3A23-3B2(DE2C5A21-2B)DE-CG4A21-B2-E5-AQ20-2(2B-DE27-)2B-D28-3BDE28-2BDE7-4A17-2BDEC6-2A2V17-2B-EC5-3A3T17-BD-2C4-3A3C17-BDE-C4-3A3F18-DE2C4-6A20-2C4-6A18-DE2C4-6A17-BDEC6-4A18-BDE7-3AO29-2AO30-4A28-3A142-3B29-3B-BD25-6BD2E23-6BDEC24-5BDEC2A24-B2-DE27-2(3BD28-)2(3B29-)3B9-2A19-2B8-4A18-2BD6-3A2S2AS12-5BDE5-3A3RAR10-7BDEC4-3A5H11-4B-BDEC4-3A5H16-BDEC4-3A4K19-EC4-3A3N18-BDEC4-6A18-BDE5-5A28-3AO29-2AO30-4A28-3A142-3B28-6BD23-5B-2BD2E20-6B-2BDEC20-9BDEC19-5B2-3BDE20-4B3-3BD20-4B28-3B29-3B19-A9-4B15-6A7-4B14-8A7-4B3-B9-3A6P6-8B9-3A6H7-7B2-DE5-3A6H8-6B2-DEC3-4A6K10-4B2-DEC3-4A5K18-EC4-3A5H17-DEC4-3A5N24-4AO27-4AO28-6A28-4A173-3B27-7BDAE21-4B2-2BD2E20-2B2-5BDEC19-2B2-6BDEC19-2B-2B3-2BDE19-2B-2B27-4B2(28-B-2B)16-4A8-B-2B15-7A6-2B-B14-10A4-2B-2B13-3A7H5-2B-5B9-3A6HU6-2B-4B8-4A6H8-6B8-10A10-4B8-10A22-4A6I23-3A6C12-2B9-8A13-2B9-4AO15-3A10-6A13-3A11-4A14-3A30-A133-E8-AE12-5B4-E8-2A11-8BD-E2-2A16-9B-EC2-3A14-2B-7BDEC2-3A14-B2-2B4-BDE19-2B-2B15-2A10-B2-B15-4A9-B-2B15-5A8-B-2B15-6A7-B-2B15-7A-A4-4B14-10A4-5B12-4A7IAI3-5B11-4A6GU6-7B8-4A7I7-6B8-2(10A22-)4A6I11-4B7-10A11-4B8-9A11-4B8-8A12-4A9-5A14-A-2A10-2A16-2(3A29-)L2M93-B-B8-2A3-2AE11-5B4-E3-2A3-3A11-6B2-E6A2-2A11-9BDEC5A-3A10-10BDEC5A-3A10-4B9-G3A2-3A9-5B10-3A-5A8-4B13-7A8-4B14-6A8-3B15-8A6-3B15-10A4-4B13-14A2-3B13-14A3-2B13-4A7H2AH4-B13-4A7H2AH18-4A6IA2I9-2B8-4A7I10-4B7-4A6F11-4B7-10A11-B2-B8-9A11-4B8-9A11-4A9-4A15-4A10-2A16-3A29-A-A28-4I28-QLQ62-3B4-6A3-2AE11-5B4-6A3-3A10-8B-E6A2-3A11-7B-DEC5A-3A12-8BDEC5A-3A16-4B-ECG8A23-G9A23-2(9A24-)9A23-11A21-13AW18-15A17-14A18-4A10C7-3B8-4A9F8-4B7-4A7J10-4B7-10A11-B2-B7-10A2(11-4B8-9A)12-2A10-4A16-2A11-2A16-3A29-ALA28-4K28-3I29-2L30-4B3-7A17-5B-D-7A16-6B-DEC5A16-8BDE2C5A14-8B-DE2C7A11-4B2-4BDE2CG7A10-4B3-3B3-CG8A9-4B11-10A7-3B12-11A6-3B14-10A5-3B15-10A4-4B14-12AW-4B14-3A10JW-3B2-3B8-15A2-2B2-4B7-14A7-4B7-13A8-B-2B7-11A10-B2-B2(7-10A11-4B)8-9A23-9A24-4A29-2A79-2LK29-3K29-2L30-4B3-2A21-6B-D-2A20-8BDEC2A2(18-9BDECGA)17-2B-5B-BDECGF17-2(B2-)4BDECG18-B-2B2-4BDE20-B-B22-A6-B-B14-10A5-B-2B13-11A4-B-2B3-2B8-13AW2(-2B)-4B7-15A10B7-14A2-6B-2B7-4A10C3-5B2-B7-4A9F8-B-2B7-4A7J10-4B7-10A11-4B7-10A2(23-9A)24-4A29-2A111-2(2K30-)4B4-6A4-E11-6B2-E7A4-A10-7B2DEC5A15-3B-4B2DECG5A2-A10-2B-6B2DECG6A-2A9-2B-6B2D2-GF8A9-4B2-B-BD-ECGF9A8-B-2B2-3B2DEC2-10A7-B-B3-3B2DE3-10A7-B-B4-2B2D6-9A6-B-2B2-3B2D7-10A4-4B2-3BD7-14A2(-2B)-3BD7-14A-2B-4B2-D7-4A7H2AH2-2B2-4BD7-4A7H2AH3-7BD7-4A6IA2I6-5BD7-4A7I10-3B8-4A6F22-10A2(23-9A)24-4A29-2A178-B4-3AE2A3-2AE11-5B-E2-6A3-3A9-4B3-D-C-6A2-3A9-8BDECG6A-3A10-8BDECGF5A-3A10-8BDECG2F4A-3A9-7B-BD2-G2-9A8-3B3-3BD-CG2-9A8-3B3-3BDEC4-9A7-3B3-3BDE7-7A7-3B3-3BDE7-8A-A4-4B2-B2-D8-10A5-3B2-B2-D7-4A9I3-6B-BD7-4A6GU5-8BD7-4A7I6-7BD7-10A9-5B8-10A22-4A6I22-10A2(23-9A)24-5A28-2A187-2E3-3E24-2A3-3A11-4B5-6A2-2A12-5BD3-G6A-3A12-5BDE2-GF4A2-3A12-5BDEC2-F4A2-3A13-4BDE2C3-3A-5A14-2BDE2CG4-7A14-2BDE2C6-6A14-2BDEC7-7A13-2BDEC8-7A12-2BDE8-10A10-2BDE8-3A7H10-2BDE8-3A6HU9-3BD8-4A6H9-4BD8-10A11-B10-10A22-4A6I19-JB-10A18-FJB2-9A18-FJB2-8A19-2AB3-6A21-A5-4A238-D29-2B29-3BD28-2B-2D28-2B2DE2C26-B2(2DE2C27-)2DE2C11-A15-2DE2C8-6A13-2DE2C7-8A13-DE2CG6-3A6P13-E2CG6-3A6H14-2CGF5-3A6H16-GF4-4A6K20-2B4A5K19-J-2B-3A5H19-2J2B-3A6C18-2J2B-8A19-J-2B-4AO22-2AB3-6A20-2AB4-4A21-JAB245-D30-3D29-D-DE28-3DEC27-3DEC29-2(DE2C28-)DE-CG9-2A16-DE2-GF7-4A16-EC-GF6-3A2S2AS13-E2C-2FJ4-3A3RAR14-2CG2FJA3-3A5H15-CG2FJABA-3A5H17-2FJA2B-3A4K20-JA2B-3A3N21-JA2B-3A5N19-JA2B-7A20-JA2B-4AO22-2AB3-6A20-A-B5-4A19-4K28-3M245-3E29-3EC28-2E-2C28-2E-C28-2E2C29-E2CG28-E2CGF27-E2CGF8-4A16-2C-2F7-2A2V16-2CG-FJA4-3A3T16-CGF-JA4-3A3C17-G2F3-BA-3A3F18-2FJ2A3-6A20-J2ABA-6A21-2ABA-6A22-AB2-4AO23-AB3-3AO22-2AB4-2AO22-2AB5-4A19-4M5-3A20-3M29-KL247-2CG29-2(2C2G28-)2CG31-2G29-C2GF28-C2G2F9-2A18-G2F8-4A17-G2F2J6-4A18-2F3J4-6A18-F4J3-6A19-5J2-6A21-3J2-6A26-5A28-4A28-3AO29-2AO30-4A19-3I6-3A20-3K29-2Q280-GF30-3(G2F29-)GF76-2A29-6(4A28-)2(4A29-)2(3A29-)3A20-LQ30-2L518-2A29-4(4A28-)4A29-2A734-4(2A30-)2A298-
