model
size = 28 27 18, scale = 0.05, origin = -y
material 
  colors = A:#CC0 B:#F66 C:#444 D:#111 E:#100 F:#FFF G:#EEE H:#063 I:#BBB J:#F30 K:#066 L:#DDD M:#010 N:#033 O:#999 P:#B00 Q:#099 R:#699 S:#020 T:#696 U:#F36 V:#AAA W:#CC6 X:#888 Y:#6CC Z:#399 Aa:#555 Ab:#666
voxels
- - - - - - - - - - - - - - - - - - - - - - - - - - - -   - - - - - - - - - - - - - - - - - - - - - - - - - - - -   - - - - - - - - - - - - - - - - - - - - - - - - - - - -   - - - - - - - - - - - - - - - - - - - - - - - - - - - -   - - - - - - - - - - - - - - - - - - - - - - - - - - - -   - - - - - - - - - - - - - - - - - - - - - - - - - - - -   - - - - - - - - - - - - - - - - - - - - - - - - - - - -   - - - - - - - - - - - - - - - - - - - - - - - - - - - -   - - - - - - - - - - - - - - - - - - - - - - - - - - - -   - - - - - - - - - - - - - - - - - - - - - - - - - - - -   - - - - - - - - - - - - - - - - - - - - - - - - - - - -   - - - - - - - - - - - - - - - - - - - - - - - - - - - -   - - - - - - - - - - - - - - - - - - - - - - - A - - - -   - - - - - - - - - - - - - - - - - - - - - - - A - - - -   - - - - - - - - - - - - - - - - - - - - - - - A - - - -   - - - - - - - - - - - - - - - - - - - - - - - A - - - -   - - - - - - - - - - - - - - - - - - - - - - - - - - - -   - - - - - - - - - - - - - - - - - - - - - - - - - - - -   - - - - - - - - - - - - - - - - - - - - - - - - - - - -   - - - - - - - - - - - - - - - - - - - - - - - - - - - -   - - - - - - - - - - - - - - - - - - - - - - - - - - - -   - - - - - - - - - - - - - - - - - - - - - - - - - - - -   - - - - - - - - - - - - - - - - - - - - - - - - - - - -   - - - - - - - - - - - - - - - - - - - - - - - - - - - -   - - - - - - - - - - - - - - - - - - - - - - - - - - - -   - - - - - - - - - - - - - - - - - - - - - - - - - - - -   - - - - - - - - - - - - - - - - - - - - - - - - - - - -   
- - - - - - - - - - - - - - - - - - - - - - - - - - - -   - - - - - - - - - - - - - - - - - - - - - - - - - - - -   - - - - - - - - - - - - - - - - - - - - - - - - - - - -   - - - - - - - - - - - - - - - - - - - - - - - - - - - -   - - - - - - - - - - - - - - - - - - - - - - - - - - - -   - - - - - - - - - - - - - - - - - - - - - - - - - - - -   - - - - - - - - - - - - - - - - - - - - - - - B - - - -   - - - - - - - - - - - - - - - - - - - - - - - - - - - -   - - - - - - - - - - - - - - - - - - - - - - - - - - - -   - - - - - - - - - - - - - - - - - - - - - - - - - - - -   - - - - - - - - - - - - - - - - - - - - - - - - - - - -   - - - - - - - - - - - - - - - - - - - - - - - A - - - -   - - - - - - - - - - - - - - - - - - - - - A A A C - - -   - - - - - - - - - - - - - - - - - - - - - A A A C - - -   - - - - - - - - - - - - - - - - - - - - - A A A C - - -   - - - - - - - - - - - - - - - - - - - - - A A A C - - -   - - - - - - - - - - - - - - - - - - - - - - - A C - - -   - - - - - - - - - - - - - - - - - - - - - - - - - - - -   - - - - - - - - - - - - - - - - - - - - - - - - - - - -   - - - - - - - - - - - - - - - - - - - - - - - - - - - -   - - - - - - - - - - - - - - - - - - - - - - - - - - - -   - - - - - - - - - - - - - - - - - - - - - - - - - - - -   - - - - - - - - - - - - - - - - - - - - - - - - - - - -   - - - - - - - - - - - - - - - - - - - - - - - - - - - -   - - - - - - - - - - - - - - - - - - - - - - - - - - - -   - - - - - - - - - - - - - - - - - - - - - - - - - - - -   - - - - - - - - - - - - - - - - - - - - - - - - - - - -   
- - - - - - - - - - - - - - - - - - - - - - - - - - - -   - - - - - - - - - - - - - - - - - - - - - - - - - - - -   - - - - - - - - - - - - - - - - - - - - - - - - - - - -   - - - - - - - - - - - - - - - - - - - - - - - - - - - -   - - - - - - - - - - - - - - - - - - - - - - - - - - - -   - - - - - - - - - - - - - - - - - - - - - - - A - - - -   - - - - - - - - - - - - - - - - - - - - - - - A A - - -   - - - - - - - - - - - - - - - - - - - - - A A - - - - -   - - - - - - - - - - - - - - - - - - - - - - - - - - - -   - - - - - - - - - - - - - - - - - - - - - - - - - - - -   - - - - - - - - - - - - - - - - - - - - - A A A C - - -   - - - - - - - - - - - - - - - - - - - - A A A A C C - -   - - - - - - - - - - - - - - - - - - - A A A A A F F F -   - - - - - - - - - - - - - - - - - - - A A A A A G G G -   - - - - - - - - - - - - - - - - - - - A A A A A G G G -   - - - - - - - - - - - - - - - - - - - A A A A A F F F -   - - - - - - - - - - - - - - - - - - - - A A A A F C - -   - - - - - - - - - - - - - - - - - - - - - A A A C - - -   - - - - - - - - - - - - - - - - - - - - - - - - - - - -   - - - - - - - - - - - - - - - - - - - - - - - - - - - -   - - - - - - - - - - - - - - - - - - - - - - - - - - - -   - - - - - - - - - - - - - - - - - - - - - - - - - - - -   - - - - - - - - - - - - - - - - - - - - - - - - - - - -   - - - - - - - - - - - - - - - - - - - - - - - - - - - -   - - - - - - - - - - - - - - - - - - - - - - - - - - - -   - - - - - - - - - - - - - - - - - - - - - - - - - - - -   - - - - - - - - - - - - - - - - - - - - - - - - - - - -   
- - - - - - - - - - - - - - - - - - - - - - - - - - - -   - - - - - - - - - - - - - - - - - - - - - - - - - - - -   - - - - - - - - - - - - - - - - - - - - - - - - - - - -   - - - - - - - - - - - - - - - - - - - - - - - - - - - -   - - - - - - - - - - - - - - - - - - - - - - - B - - - -   - - - - - - - - - - - - - - - - - - - - - - - A A - - -   - - - - - - - - - - - - - - - - - - - - - - - A A - - -   - - - - - - - - - - - - - - - - - - - - - A A A - - - -   - - - - - - - - - - - - - - - - - - - - - A A - - - - -   - - - - - - - - - - - - - - - - - - - A A - A A - - - -   - - - - - - - - - - - - - - - - - A A A A A A A AbC - -   - - - - - - - - - - - - - - - - - A A A A A A A F F F -   - - - - - - - - - - - - - - - - A A A A A A A A L L L -   - - - - - - - - - - - - - - - - A A A A A A A A H H H H   - - - - - - - - - - - - - - - - - A A A A A A A M M M H   - - - - - - - - - - - - - - - - - A A A A A A A I I I -   - - - - - - - - - - - - - - - - - - - A A A A A F F F -   - - - - - - - - - - - - - - - - - - - - A A A A F C - -   A - - - - - - - - - - - - - - - - - - - - - A A C - - -   - - - - - - - - - - - - - - - - - - - - - - - - - - - -   - - - - - - - - - - - - - - - - - - - - - - - - - - - -   - - - - - - - - - - - - - - - - - - - - - - - - - - - -   - - - - - - - - - - - - - - - - - - - - - - - - - - - -   - - - - - - - - - - - - - - - - - - - - - - - - - - - -   - - - - - - - - - - - - - - - - - - - - - - - - - - - -   - - - - - - - - - - - - - - - - - - - - - - - - - - - -   - - - - - - - - - - - - - - - - - - - - - - - - - - - -   
- - - - - - - - - - - - - - - - - - - - - - - - - - - -   - - - - - - - - - - - - - - - - - - - - - - - - - - - -   - - - - - - - - - - - - - - - - - - - - - - - - - - - -   - - - - - - - - - - - - - - - - - - - - - - - - - - - -   - - - - - - - - - - - - - - - - - - - - - - - B - - - -   - - - - - - - - - - - - - - - - - - - - - - - B B - - -   - - - - - - - - - - - - - - - - - - - - - - - A A A - -   - - - - - - - - - - - - - - - - - - A A A A A A - - - -   - - - - - - - - - - - - - - - - A A A A A A A A - - - -   - - - - - - - - - - - - - - - A A A A A A A A A A - - -   - - - - - - - - - - - - - - - A A A A A A A A A A V C -   - - - - - - - - - - - - - - B A A A A A A A A A D G G -   - - - - - - - - - - - - - - A A A A A A A A A A D K K K   - - - - - - - - - - - - - - A A A A A A A A A A D E E E   - - - - - - - - - - - - - - A A A A A A A A A A D E E E   - - - - - - - - - - - - - - - A A A A A A A A A D O O E   - - - - - - - - - - - - - - - A A A A A A A A A D T T -   - - A - - - - - - - - - - - - - A A A A A A A A A F F -   - A - - - - - - - - - - - - - - - - A A A A A A C - - -   - - - - - - - - - - - - - - - - - - - - - - - - - - - -   - - - - - - - - - - - - - - - - - - - - - - - - - - - -   - - - - - - - - - - - - - - - - - - - - - - - - - - - -   - - - - - - - - - - - - - - - - - - - - - - - - - - - -   - - - - - - - - - - - - - - - - - - - - - - - - - - - -   - - - - - - - - - - - - - - - - - - - - - - - - - - - -   - - - - - - - - - - - - - - - - - - - - - - - - - - - -   - - - - - - - - - - - - - - - - - - - - - - - - - - - -   
- - - - - - - - - - - - - - - - - - - A - - - - - - - -   - - - - - - - - - - - - - - - - - - B P P A - - - - - -   - - - - - - - - - - - - - - - - - A B B B A A - - - - -   - - - - - - - - - - - - - - - - A A A A A A A - - - - -   - - - - - - - - - - - - - - - - A A A A A A - - - - - -   - - - - - - - - - - - - - - - - A A A A A A A A A - - -   - - - - - - - - - - - - - - - - - A A A A A A A A B - -   - - - - - - - - - - - - - - - A A A A A A A A A A A - -   - - - - - - - - - - - - - - J J A A A A A A A A A A - -   - - - - - - - - - - - - - - B A A A A A A A A A A A - -   - - - - - - - - - - - - - A B A A A A A A A A A A V C -   - - - - - - - - - - - - - A B A A A A A A A A A D G G -   - - - - - - - - - - - - - A A A A A A A A A A A D N N N   - - - - - - - - - - - - - A A A A A A A A A A A D E E E   - - - - - - - - - - - - - A A A A A A A A A A A D E E E   - - - - - A A - - - - - - A A A A A A A A A A A D E E E   - - - - A A - - - - - - - - A A A A A A A A A A D S S -   - - - A A A - - - - - - - - A A A A A A A A A A A F F -   - - - - - - - - - - - - - - - A A A A A A A A A C - - -   - - - - - - - - - - - - - - - - - A A A A A A - - - - -   - - - - - - - - - - - - - - - - - - - - - - - - - - - -   - - - - - - - - - - - - - - - - - - - - - - - - - - - -   - - - - - - - - - - - - - - - - - - - - - - - - - - - -   - - - - - - - - - - - - - - - - - - - - - - - - - - - -   - - - - - - - - - - - - - - - - - - - - - - - - - - - -   - - - - - - - - - - - - - - - - - - - - - - - - - - - -   - - - - - - - - - - - - - - - - - - - - - - - - - - - -   
- - - - - - - - - - - - - - - - - - - - - - - - - - - -   - - - - - - - - - - - - - - - - - - - - - - - - - - - -   - - - - - - - - - - - - - - - - - - - - - A A - - - - -   - - - - - - - - - - - - - - - - - - - - - A A - - - - -   - - - - - - - - - - - - - - - - - - - - A A A A - - - -   - - - - - - - - - - - - - - - - - A A A A A A A A B - -   - - - - - - - - - - - - - - - A A A A A A A A A A B - -   - - - - - - - - - - - - - - A A A A A A A A A A A A A -   - - - - - - - - - - - - - B J J A A A A A A A A A A A -   - - - - - - - - A A A A - A B A A A A A A A A A A A A -   - - - - - - - - A A A A A A B A A A A A A A A A A AaA -   - - - - - - - - - A A - A A B A A A A A A A A A D G C -   - - - - - - - - - A A - A A A A A A A A A A A A D Q Q -   - - - - - - - - A A - - A A A A A A A A A A A A D E E I   - - - - - - A A A A - - A A A A A A A A A A A A D E E E   - - - - - A A A A - - - A A A A A A A A A A A A D E E -   - - - - A A A A A A - - - A A A A A A A A A A A D R R -   - - - - A A A A A A - - - A A A A A A A A A A A A G C -   - - - - - A A A - - - - - - A A A A A A A A A A A C - -   - - - - - - - - - - - - - - - A A A A A A A A A A - - -   - - - - - - - - - - - - - - - - - A A A A A A - - - - -   - - - - - - - - - - - - - - - - - - - - - - - - - - - -   - - - - - - - - - - - - - - - - - - - - - - - - - - - -   - - - - - - - - - - - - - - - - - - - - - - - - - - - -   - - - - - - - - - - - - - - - - - - - - - - - - - - - -   - - - - - - - - - - - - - - - - - - - - - - - - - - - -   - - - - - - - - - - - - - - - - - - - - - - - - - - - -   
- - - - - - - - - - - - - - - - - - - - - - - - - - - -   - - - - - - - - - - - - - - - - - - - - - - - - - - - -   - - - - - - - - - - - - - - - - - - - - - - - - - - - -   - - - - - - - - - - - - - - - - - - - - - - - - - - - -   - - - - - - - - - - - - - - - - - - A A A A - - - - - -   - - - - - - - A - - - - - - - - A A A A A A A A - - - -   - - - - - - - A A - - - - - B B A A A A A A A A A B A -   - - - - - - - - A A A - - A A A A A A A A A A A A A A -   - - - - - - - - A A A A - A B B A A A A A A A A A A A A   - - - - - - - - A A A A A A B A A A A A A A A A A A A -   - - - - - - - - A A A A A A B A A A A A A A A A A A A -   - - - - - - - - A A A A A A A A A A A A A A A A D X A -   - - - - - - - - A A A A A A A A A A A A A A A A D G C -   - - - - - - - - - A A A A A A A A A A A A A A A D Y C -   - - - - - - - A A A A A A A A A A A A A A A A A D Z C -   - - - - - - - A A A A A A A A A A A A A A A A A D I C -   - - - - - - A A A A A A A A A A A A A A A A A A D G A C   - - - - - - A A A A A - - A A A A A A A A A A A D A A -   - - - - - - - - - - - - - A A A A A A A A A A A A A A -   - - - - - - - - - - - - - - A A A A A A A A A A A A - -   - - - - - - - - - - - - - - - - A A A A A A A A - - - -   - - - - - - - - - - - - - - - - - - B B B B - - - - - -   - - - - - - - - - - - - - - - - A A - - - - - - - - - -   - - - - - - - - - - - - - - - - A A A A A - - - - - - -   - - - - - - - - - - - - - - - - B B B B - - - - - - - -   - - - - - - - - - - - - - - - B B - - - - - - - - - - -   - - - - - - - - - - - - - - - - - - - - - - - - - - - -   
- - - - - - - - - - - - - - - - - - - - - - - - - - - -   - - - - - - - - - - - - - - - - - - - - - - - - - - - -   - - - - - - - - - - - - - - - - - - - - - - - - - - - -   - - - - - - - - - - - - - - - - - - - - - - - - - - - -   - - - - - - - - - - - - - - - - - A A A A A A - - - - -   - - - - - - - A A A - - - - - A A A A A A A A A A - - -   - - - - - - - A A A B - - - B B A A A A A A A A A B A -   - - - - - - - - A A A A - A A A A A A A A A A A A A A A   - - - - - - - - - A A A J A B B A A A A A A A A A A W -   - - - - - - - - - - A A A A B A A A A A A A A A A A A A   - - - - - - - - - - A A A A B A A A A A A A A A A A A -   - - - - - - - - - - A A A A A A A A A A A A A A A A A -   - - - - - - - - - - A A A A A A A A A A A A A A A A A A   - - - - - - - - - A A A A A A A A A A A A A A A U A A A   - - - - - - - - - A A A A A A A A A A A A A A A U A A A   - - - - - - - - - A A A A A A A A A A A A A A A A A A A   - - - - - - - - A A A A A A A A A A A A A A A A A A A -   - - - - - - - - A A A - A A A A A A A A A A A A A A A A   - - - - - - - - - - - - - A A A A A A A A A A A A A A -   - - - - - - - - - - - - - - A A A A A A A A A A A A - -   - - - - - - - - - - - - - - A A A A A A A A A A A - - -   - - - - - - - - - - - - - - - A A A A A A A A A A - - -   - - - - - - - - - - - - - - - - A A A A A A A A - - - -   - - - - - - - - - - - - - - - - A A A A A A - - - - - -   - - - - - - - - - - - - - - - - B B B B - - - - - - - -   - - - - - - - - - - - - - - B B B - - - - - - - - - - -   - - - - - - - - - - - - - - B - - - - - - - - - - - - -   
- - - - - - - - - - - - - - - - - - - - - - - - - - - -   - - - - - - - - - - - - - - - - - - - - - - - - - - - -   - - - - - - - - - - - - - - - - - - - - - - - - - - - -   - - - - - - - - - - - - - - - - - - - - - - - - - - - -   - - - - - - - - - - - - - - - - - A A A A A A - - - - -   - - - - - - - - - - - - - - - A A A A A A A A A A - - -   - - - - - - - - - - - - - - B B A A A A A A A A A B A -   - - - - - - - - - - - - - A A A A A A A A A A A A A A A   - - - - - - - - - - - - J A B B A A A A A A A A A A W -   - - - - - - - - - - - - A A B A A A A A A A A A A A A A   - - - - - - - - - - - A A A B A A A A A A A A A A A A -   - - - - - - - - - - - A A A A A A A A A A A A A A A A -   - - - - - - - - - - - A A A A A A A A A A A A A A A A A   - - - - - - - - - - - A A A A A A A A A A A A A U A A A   - - - - - - - - - - - A A A A A A A A A A A A A U A A A   - - - - - - - - - - - A A A A A A A A A A A A A A A A A   - - - - - - - - - - A A A A A A A A A A A A A A A A A -   - - - - - - - - - - - - A A A A A A A A A A A A A A A A   - - - - - - - - - - - - - A A A A A A A A A A A A A A -   - - - - - - - - - - - - - - A A A A A A A A A A A A - -   - - - - - - - - - - - - - - - A A A A A A A A A A - - -   - - - - - - - - - - - - - - - - - A A A A A A A - - - -   - - - - - - - - - - - - - - - - - - - - - - - - - - - -   - - - - - - - - - - - - - - - - - - - - - - - - - - - -   - - - - - - - - - - - - - - - - - - - - - - - - - - - -   - - - - - - - - - - - - - - - - - - - - - - - - - - - -   - - - - - - - - - - - - - - - - - - - - - - - - - - - -   
- - - - - - - - - - - - - - - - - - - - - - - - - - - -   - - - - - - - - - - - - - - - - - - - - - - - - - - - -   - - - - - - - - - - - - - - - - - - - - - - - - - - - -   - - - - - - - - - - - - - - - - - - - - - - - - - - - -   - - - - - - - - - - - - - - - - - - A A A A - - - - - -   - - - - - - - - - - - - - - - - A A A A A A A A A B - -   - - - - - - - - - - - - - - B B A A A A A A A A A B A -   - - - - - - - - - - - A - A A A A A A A A A A A A A A -   - - - - - - - - - - - A J A B B A A A A A A A A A A A A   - - - - - - - - - - A A A A B A A A A A A A A A A A A -   - - - - - - - - - - A A A A B A A A A A A A A A A A A -   - - - - - - - - - A A A A A A A A A A A A A A A D X A -   - - - - - - - - - A A A A A A A A A A A A A A A D G C -   - - - - - - - - - A A A A A A A A A A A A A A A D Y C -   - - - - - - - A A A A A A A A A A A A A A A A A D Z C -   - - - - - - - A A A A A A A A A A A A A A A A A D I C -   - - - - - - - A A A A A A A A A A A A A A A A A D G A C   - - - - - - - - - A A - - A A A A A A A A A A A D A A -   - - - - - - - - - - - - - A A A A A A A A A A A A A A -   - - - - - - - - - - - - - - A A A A A A A A A A A A - -   - - - - - - - - - - - - - - - - A A A A A A A A - - - -   - - - - - - - - - - - - - - - - - - A A A A - - - - - -   - - - - - - - - - - - - - - - - - - - - - - - - - - - -   - - - - - - - - - - - - - - - - - - - - - - - - - - - -   - - - - - - - - - - - - - - - - - - - - - - - - - - - -   - - - - - - - - - - - - - - - - - - - - - - - - - - - -   - - - - - - - - - - - - - - - - - - - - - - - - - - - -   
- - - - - - - - - - - - - - - - - - - - - - - - - - - -   - - - - - - - - - - - - - - - - - - - - - - - - - - - -   - - - - - - - - - - - - - - - - - - - - - - - - - - - -   - - - - - - - - - - - - - - - - - - - - - - - - - - - -   - - - - - - - - - - - - - - - - - - - - - - A A - - - -   - - - - - - - - - - - - - - - - - A A A A A A A A B - -   - - - - - - - - - - B - - - - B A A A A A A A A A B - -   - - - - - - - - A A A A - - A A A A A A A A A A A A A -   - - - - - - - - A A A A - A B B A A A A A A A A A A A -   - - - - - - - - A A A A - A B A A A A A A A A A A A A -   - - - - - - - - A A A A A A B A A A A A A A A A A AaA -   - - - - - - - - - A A - A A B A A A A A A A A A D G C -   - - - - - - - - - A A - A A A A A A A A A A A A D Q Q -   - - - - - - - - A A - - A A A A A A A A A A A A D E E I   - - - - - - A A A A - - A A A A A A A A A A A A D E E E   - - - - - A A A A - - - A A A A A A A A A A A A D E E -   - - - - - A A A A A - - - A A A A A A A A A A A D R R -   - - - - - A A A A A - - - A A A A A A A A A A A A G C -   - - - - - A A A - - - - - - A A A A A A A A A A A C - -   - - - - - - - - - - - - - - - A A A A A A A A A A - - -   - - - - - - - - - - - - - - - - - A A A A A A - - - - -   - - - - - - - - - - - - - - - - - - - - - - - - - - - -   - - - - - - - - - - - - - - - - - - - - - - - - - - - -   - - - - - - - - - - - - - - - - - - - - - - - - - - - -   - - - - - - - - - - - - - - - - - - - - - - - - - - - -   - - - - - - - - - - - - - - - - - - - - - - - - - - - -   - - - - - - - - - - - - - - - - - - - - - - - - - - - -   
- - - - - - - - - - - - - - - - - - - - - - - - - - - -   - - - - - - - - - - - - - - - - - - B P P A - - - - - -   - - - - - - - - - - - - - - - - - - B B B A - - - - - -   - - - - - - - - - - - - - - - - - A A A A A A - - - - -   - - - - - - - - - - - - - - - - A A A A A A A A - - - -   - - - - - - - - - - - - - - - - A A A A A A A A A - - -   - - - - - - - - A A B - - - - - - A A A A A A A A B - -   - - - - - - - - A A A - - - - A A A A A A A A A A A - -   - - - - - - - - - - - - - - B B A A A A A A A A A A - -   - - - - - - - - - - - - - - B A A A A A A A A A A A - -   - - - - - - - - - - - - - A B A A A A A A A A A A V C -   - - - - - - - - - - - - - A B A A A A A A A A A D G G -   - - - - - - - - - - - - - A A A A A A A A A A A D N N N   - - - - - - - - - - - - - A A A A A A A A A A A D E E E   - - - - - - - - - - - - - A A A A A A A A A A A D E E E   - - - - - A - - - - - - - A A A A A A A A A A A D E E E   - - - - A A - - - - - - - - A A A A A A A A A A D S S -   - - - - A A - - - - - - - - A A A A A A A A A A A F F -   - - - - - - - - - - - - - - - A A A A A A A A A C - - -   - - - - - - - - - - - - - - - - - A A A A A A - - - - -   - - - - - - - - - - - - - - - - - - - - - - - - - - - -   - - - - - - - - - - - - - - - - - - - - - - - - - - - -   - - - - - - - - - - - - - - - - - - - - - - - - - - - -   - - - - - - - - - - - - - - - - - - - - - - - - - - - -   - - - - - - - - - - - - - - - - - - - - - - - - - - - -   - - - - - - - - - - - - - - - - - - - - - - - - - - - -   - - - - - - - - - - - - - - - - - - - - - - - - - - - -   
- - - - - - - - - - - - - - - - - - - - - - - - - - - -   - - - - - - - - - - - - - - - - - - B P - - - - - - - -   - - - - - - - - - - - - - - - - - A B - - - - - - - - -   - - - - - - - - - - - - - - - - - A A - - - - - - - - -   - - - - - - - - - - - - - - - - - A - - - - - - - - - -   - - - - - - - - - - - - - - - - - - - - - - - - A - - -   - - - - - - - - A A B - - - - - - - - - - A A A A - - -   - - - - - - - - A A - - - - - - - - A A A A A A - - - -   - - - - - - - - - - - - - - - - A A A A A A A A - - - -   - - - - - - - - - - - - - - - A A A A A A A A A A - - -   - - - - - - - - - - - - - - - A A A A A A A A A A V C -   - - - - - - - - - - - - - - B A A A A A A A A A D G G -   - - - - - - - - - - - - - - A A A A A A A A A A D K K K   - - - - - - - - - - - - - - A A A A A A A A A A D E E E   - - - - - - - - - - - - - - A A A A A A A A A A D E E E   - - - - - - - - - - - - - - - A A A A A A A A A D O O O   - - - A A - - - - - - - - - - A A A A A A A A A D T T -   - - - - A - - - - - - - - - - - A A A A A A A A A F F -   - - - - - - - - - - - - - - - - - - A A A A A A C - - -   - - - - - - - - - - - - - - - - - - - - - - - - - - - -   - - - - - - - - - - - - - - - - - - - - - - - - - - - -   - - - - - - - - - - - - - - - - - - - - - - - - - - - -   - - - - - - - - - - - - - - - - - - - - - - - - - - - -   - - - - - - - - - - - - - - - - - - - - - - - - - - - -   - - - - - - - - - - - - - - - - - - - - - - - - - - - -   - - - - - - - - - - - - - - - - - - - - - - - - - - - -   - - - - - - - - - - - - - - - - - - - - - - - - - - - -   
- - - - - - - - - - - - - - - - - - - - - - - - - - - -   - - - - - - - - - - - - - - - - - - - - - - - - - - - -   - - - - - - - - - - - - - - - - - - - - - - - - - - - -   - - - - - - - - - - - - - - - - - - - - - - - - - - - -   - - - - - - - - - - - - - - - - - - - - - - - A - - - -   - - - - - - - - - - - - - - - - - - - - - - - A A - - -   - - - - - - - - - - - - - - - - - - - - - - - A A B - -   - - - - - - - - - - - - - - - - - - - - - - A A - - - -   - - - - - - - - - - - - - - - - - - - - - - A A - - - -   - - - - - - - - - - - - - - - - - - - A A A A A - - - -   - - - - - - - - - - - - - - - - - A A A A A A A AbC - -   - - - - - - - - - - - - - - - - - A A A A A A A F F F -   - - - - - - - - - - - - - - - - A A A A A A A A L L L -   - - - - - - - - - - - - - - - - A A A A A A A A H H H H   - - - - - - - - - - - - - - - - - A A A A A A A M M M H   - - - - - - - - - - - - - - - - - A A A A A A A I I I -   - - A - - - - - - - - - - - - - - - - A A A A A F F F -   - A - - - - - - - - - - - - - - - - - - A A A A F C - -   - - - - - - - - - - - - - - - - - - - - - - A A C - - -   - - - - - - - - - - - - - - - - - - - - - - - - - - - -   - - - - - - - - - - - - - - - - - - - - - - - - - - - -   - - - - - - - - - - - - - - - - - - - - - - - - - - - -   - - - - - - - - - - - - - - - - - - - - - - - - - - - -   - - - - - - - - - - - - - - - - - - - - - - - - - - - -   - - - - - - - - - - - - - - - - - - - - - - - - - - - -   - - - - - - - - - - - - - - - - - - - - - - - - - - - -   - - - - - - - - - - - - - - - - - - - - - - - - - - - -   
- - - - - - - - - - - - - - - - - - - - - - - - - - - -   - - - - - - - - - - - - - - - - - - - - - - - - - - - -   - - - - - - - - - - - - - - - - - - - - - - - - - - - -   - - - - - - - - - - - - - - - - - - - - - - - - - - - -   - - - - - - - - - - - - - - - - - - - - - - - A - - - -   - - - - - - - - - - - - - - - - - - - - - - - A - - - -   - - - - - - - - - - - - - - - - - - - - - - - A A - - -   - - - - - - - - - - - - - - - - - - - - - - A A - - - -   - - - - - - - - - - - - - - - - - - - - - - - - - - - -   - - - - - - - - - - - - - - - - - - - - - - - - - - - -   - - - - - - - - - - - - - - - - - - - - - A A A C - - -   - - - - - - - - - - - - - - - - - - - - A A A A C C - -   - - - - - - - - - - - - - - - - - - - A A A A A F F F -   - - - - - - - - - - - - - - - - - - - A A A A A G G G -   - - - - - - - - - - - - - - - - - - - A A A A A G G G -   - - - - - - - - - - - - - - - - - - - A A A A A F F F -   - - - - - - - - - - - - - - - - - - - - A A A A F C - -   A - - - - - - - - - - - - - - - - - - - - A A A C - - -   - - - - - - - - - - - - - - - - - - - - - - - - - - - -   - - - - - - - - - - - - - - - - - - - - - - - - - - - -   - - - - - - - - - - - - - - - - - - - - - - - - - - - -   - - - - - - - - - - - - - - - - - - - - - - - - - - - -   - - - - - - - - - - - - - - - - - - - - - - - - - - - -   - - - - - - - - - - - - - - - - - - - - - - - - - - - -   - - - - - - - - - - - - - - - - - - - - - - - - - - - -   - - - - - - - - - - - - - - - - - - - - - - - - - - - -   - - - - - - - - - - - - - - - - - - - - - - - - - - - -   
- - - - - - - - - - - - - - - - - - - - - - - - - - - -   - - - - - - - - - - - - - - - - - - - - - - - - - - - -   - - - - - - - - - - - - - - - - - - - - - - - - - - - -   - - - - - - - - - - - - - - - - - - - - - - - - - - - -   - - - - - - - - - - - - - - - - - - - - - - - - - - - -   - - - - - - - - - - - - - - - - - - - - - - - A - - - -   - - - - - - - - - - - - - - - - - - - - - - - - - - - -   - - - - - - - - - - - - - - - - - - - - - - - - - - - -   - - - - - - - - - - - - - - - - - - - - - - - - - - - -   - - - - - - - - - - - - - - - - - - - - - - - - - - - -   - - - - - - - - - - - - - - - - - - - - - - - - - - - -   - - - - - - - - - - - - - - - - - - - - - - - C - - - -   - - - - - - - - - - - - - - - - - - - - - A A A C - - -   - - - - - - - - - - - - - - - - - - - - - A A A C - - -   - - - - - - - - - - - - - - - - - - - - - A A A C - - -   - - - - - - - - - - - - - - - - - - - - - A A A C - - -   - - - - - - - - - - - - - - - - - - - - - - - - A - - -   - - - - - - - - - - - - - - - - - - - - - - - - - - - -   - - - - - - - - - - - - - - - - - - - - - - - - - - - -   - - - - - - - - - - - - - - - - - - - - - - - - - - - -   - - - - - - - - - - - - - - - - - - - - - - - - - - - -   - - - - - - - - - - - - - - - - - - - - - - - - - - - -   - - - - - - - - - - - - - - - - - - - - - - - - - - - -   - - - - - - - - - - - - - - - - - - - - - - - - - - - -   - - - - - - - - - - - - - - - - - - - - - - - - - - - -   - - - - - - - - - - - - - - - - - - - - - - - - - - - -   - - - - - - - - - - - - - - - - - - - - - - - - - - - -   
- - - - - - - - - - - - - - - - - - - - - - - - - - - -   - - - - - - - - - - - - - - - - - - - - - - - - - - - -   - - - - - - - - - - - - - - - - - - - - - - - - - - - -   - - - - - - - - - - - - - - - - - - - - - - - - - - - -   - - - - - - - - - - - - - - - - - - - - - - - - - - - -   - - - - - - - - - - - - - - - - - - - - - - - - - - - -   - - - - - - - - - - - - - - - - - - - - - - - - - - - -   - - - - - - - - - - - - - - - - - - - - - - - - - - - -   - - - - - - - - - - - - - - - - - - - - - - - - - - - -   - - - - - - - - - - - - - - - - - - - - - - - - - - - -   - - - - - - - - - - - - - - - - - - - - - - - - - - - -   - - - - - - - - - - - - - - - - - - - - - - - - - - - -   - - - - - - - - - - - - - - - - - - - - - - - A - - - -   - - - - - - - - - - - - - - - - - - - - - - - A - - - -   - - - - - - - - - - - - - - - - - - - - - - - A - - - -   - - - - - - - - - - - - - - - - - - - - - - - A - - - -   - - - - - - - - - - - - - - - - - - - - - - - - - - - -   - - - - - - - - - - - - - - - - - - - - - - - - - - - -   - - - - - - - - - - - - - - - - - - - - - - - - - - - -   - - - - - - - - - - - - - - - - - - - - - - - - - - - -   - - - - - - - - - - - - - - - - - - - - - - - - - - - -   - - - - - - - - - - - - - - - - - - - - - - - - - - - -   - - - - - - - - - - - - - - - - - - - - - - - - - - - -   - - - - - - - - - - - - - - - - - - - - - - - - - - - -   - - - - - - - - - - - - - - - - - - - - - - - - - - - -   - - - - - - - - - - - - - - - - - - - - - - - - - - - -   - - - - - - - - - - - - - - - - - - - - - - - - - - - -   
