model
size = 29 18 32, scale = 0.05, origin = -y
material 
  colors = A:#96F B:#969 C:#111 D:#EEE E:#222
voxels
9-4B23-6B22-7B21-8A21-3A129-2A26-3A25-3A219-4B23-7B21-8B20-8A20-4A26-A46-2A26-3A25-4A21-7A22-6A23-5A191-4B25-5B24-5B19-3A3-3A19-3A17-A2(8-2A17-2A)26-3A25-4A20-8A21-7A23-5A193-2(3B26-)3B27-2A18-2(2A17-3A7-)2A17-3A25-3A12-A12-4A21-2A2-3A22-5A24-3A134-A2B26-AB31-3B26-4B25-3B7-2B17-3A7-3A10-A2(B14-3A7-4A)B15-A8-5A27-3A26-3A2(B26-2A2B26-2A)B26-2AB26-A2B26-2A59-4B25-4B5-3B17-4B5-3B11-3A3-3A6-3A10-3A14-2A10-3A25-4A25-A-2A2(27-3A)2(26-4A26-3A)2(27-2A)87-4B4-3B14-B3-4B4-4B11-3B3-4B4-4B11-3A4-2A6-3A11-3(2A27-)2A323-4B4-3B13-3B2(2-5B)11-4B2-4B3-5B11-4A3-2A6-3A11-2A18-AB7-2A18-AB357-15B-B11-19B10-20B9-4A-4A8-4A2(27-2A)2(27-AB)26-2AB25-2AB242-18B10-19B10-20B10-8A6-6A4(27-2A)22-7A22-6A24-4A214-17B12-2(18B11-)10A18-2A25-6A23-6A4-C20-2A6-C28-C5-5A24-5A25-3A215-15B13-16B13-15B13-12A14-11A17-12A-C15-12A-2C15-10A2-CD18-4A5-CD27-C253-15B13-15B11-18B10-18A9-15A14-14AC14-14A2C14-12A-CD15-10A2-2C27-C253-14B13-16B11-17B10-19A9-15A13-15AC13-15A2C13-14A2C14-12A-CE18-4A5-C253-13B14-15B11-18B9-19A9-16A12-17A12-16AC13-15AC14-14AC17-8A257-13B13-16B11-17B10-18A10-15AC2(12-17A)13-16A14-14A18-8A257-13B14-15B11-18B9-19A9-15AC2(12-17A)13-16A14-14A18-8A257-13B14-15B12-17B9-20A8-16A12-17A12-16AC13-15AC14-14AC17-8A257-13B15-14B12-18B9-20A8-15A13-15AC13-15A2C13-14ACD14-12A-CD18-4A5-C252-14B15-15B12-20B7-16A2(-2A)6-13A8-2A2B3-14AC14-14A2C14-12A-CD15-10A2-2C27-C251-15B14-2(19B10-)12A2-6A6-10A8-6A4-12A-C8-2AB4-12A-2C8-AB5-10A2-2C18-4A5-CE27-C251-14B14-18B11-19B10-5A2-14A10-2A10-7A8-6A14-2A7-6A4-C2(9-2A)6-C9-2A17-C9-AB94-AB27-2A2(26-3A)24-4A25-2A31-4B2-9B13-5B2-9B12-6B2-12B9-5A4-3A2-6A9-3A12-7A7-2A48-3(2A27-)AB6-A28-2A27-2AB3(26-3A)24-A3B25-AB37-9B13-3B4-9B12-4B4-9B12-4A5-3A2-A14-2(3A26-)2A27-2A26-3A19-2A5-3A17-4A5-3A19-A7-2(3A26-)2(2AB26-)A2B92-2(4B2-4B19-)4B2-4B11-3A5-4A4-A12-2AB26-A3(B26-2A)B16-4A6-2AB15-4A8-2A16-5A6-2A209-4B3-3B19-4B2-4B19-4B3-4B18-3A5-2A98-A74-4A25-4A219-3B5-2B19-2(4B3-4B18-)3A5-3A424-3B26-3B5-3B18-3B5-4B17-3A5-4A6-2(2A27-)2A101-4A24-5A24-4A193-4B2(23-6B)6-3B9-3A4-3A7-4A6-4A16-3A6-3A17-3A26-3A2(25-4A)2(23-5A)24-2A2B190-5B22-7B20-9B19-10A8-2A8-3A16-3A7-2A17-3A26-3A25-4A25-3AB25-2AB26-2B218-4B22-7B21-8B20-9A20-2A46-A3(B26-2A)302-5B22-7B22-6A424-
