model
size = 9 31 31, scale = 0.05, origin = -y
material 
  colors = A:#EEE B:#555 C:#3C0 D:#300 E:#303 F:#306 G:#309 H:#BBB
voxels
--------- --------- --------- --------- --------- --------- --------- --------- --------- --------- --------- --AAAB--- AAAAABA-- AAAAABA-- AAAAABA-- AAAAABA-- AAAAABADC AAAAABA-- AAAAABA-- AAAAABA-- AAAAABA-- AAAAAB--- AAAAA---- AAAA----- --------- --------- --------- --------- --------- --------- --------- 
--------- --------- --------- --------- --------- --------- --------- --------- --------- --------- --------- --AAABA-- AAAAABADC AAAAABADC AAAAABADC AAAAABADC AAAAABADC AAAAABADC AAAAABA-- AAAAABA-- AAAAABA-- AAAAABA-- AAAAAB--- AAAAA---- --------- --------- --------- --------- --------- --------- --------- 
--------- --------- --------- --------- --------- --------- --------- --------- --------- --------- --------- --AAABA-- AAAAABADC AAAAABA-- AAAAABA-- AAAAABA-- AAAAABADC AAAAABA-- AAAAABA-- AAAAABA-- AAAAABA-- AAAAABA-- AAAAABA-- AAAAAB--- AAAA----- --------- --------- --------- --------- --------- --------- 
--------- --------- --------- --------- --------- --------- --------- --------- --------- --------- --------- --AAABA-- AAAAABA-- AAAAABA-- AAAAABA-- AAAAABA-- AAAAABA-- AAAAABA-- AAAAABA-- AAAAABA-- AAAAABA-- AAAAABA-- AAAAABA-- AAAAABA-- AAAA----- --------- --------- --------- --------- --------- --------- 
--------- --------- --------- --------- --------- --------- --------- --------- --------- --------- AAAAABA-- AAAAABA-- AAAAABADC AAAAABADC AAAAABADC AAAAABADC AAAAABADC AAAAABADC AAAAABH-- AAAAABA-- AAAAABA-- AAAAABA-- AAAAABA-- AAAAABA-- AAAA----- --------- --------- --------- --------- --------- --------- 
--------- --------- --------- --------- --------- --------- --------- --------- --------- --------- AAAAABA-- AAAAABA-- AAAAABA-- AAAAABA-- AAAAABA-- AAAAABA-- AAAAABADC AAAAABA-- AAAAABA-- AAAAABB-- AAAAABB-- AAAAABA-- AAAAABA-- AAAAABA-- AAAA----- --------- --------- --------- --------- --------- --------- 
--------- --------- --------- --------- --------- --------- --------- --------- --------- --------- AAAAABA-- AAAAABA-- AAAAABADC AAAAABADC AAAAABADC AAAAABADC AAAAABA-- AAAAABA-- AAAAABA-- AAAAABB-- AAAAABAE- AAAAABAA- AAAAABA-- AAAAABA-- -----BA-- -----BA-- --------- --------- --------- --------- --------- 
--------- --------- --------- --------- --------- --------- --------- --------- AAAAAB--- AAAAABA-- AAAAABA-- AAAAABA-- AAAAABA-- AAAAABA-- AAAAABA-- AAAAABA-- AAAAABA-- AAAAABA-- AAAAABA-- AAAAABA-- AAAAABAE- AAAAABAE- AAAAABA-- AAAAABA-- -----BA-- -----BA-- -----BA-- --------- --------- --------- --------- 
--------- --------- --------- --------- --------- --------- --------- --------- AAAAAB--- AAAAABA-- AAAAABA-- AAAAABA-- AAAAABADC AAAAABADC AAAAABADC AAAAABADC AAAAABADC AAAAABA-- AAAAABADC AAAAABA-- AAAAABA-- AAAAABA-- AAAAABA-- AAAAABA-- AAAAABA-- -----BA-- -----BA-- -----B--- --------- --------- --------- 
--------- --------- --------- --------- --------- --------- --------- --------- AAAAABA-- AAAAABA-- AAAAABA-- AAAAABA-- AAAAABA-- AAAAABA-- AAAAABA-- AAAAABA-- AAAAABA-- AAAAABA-- AAAAABA-- AAAAABB-- AAAAABB-- AAAAABA-- AAAAABA-- AAAAABA-- AAAAABA-- AAAAABA-- -----B--- -----B--- --------- --------- --------- 
--------- --------- --------- --------- --------- --------- --------- --------- AAAAABA-- AAAAABA-- AAAAABA-- AAAAABA-- AAAAABADC AAAAABADC AAAAABADC AAAAABADC AAAAABA-- AAAAABA-- AAAAABA-- AAAAABB-- AAAAABAF- AAAAABAA- AAAAABA-- AAAAABA-- AAAAABA-- AAAAAB--- AAAAABA-- --AA-BA-- --AA----- --AA----- --------- 
--------- --------- --------- --------- --------- --------- --------- --------- AAAAABA-- AAAAABA-- AAAAABA-- AAAAABA-- AAAAABA-- AAAAABA-- AAAAABA-- AAAAABA-- AAAAABADC AAAAABA-- AAAAABA-- AAAAABA-- AAAAABAF- AAAAABAF- AAAAABA-- AAAAABA-- AAAAABA-- AAAAABA-- AAAAABA-- AAAAABA-- AAAAAB--- AAAAAB--- AAAAA---- 
--------- --------- --------- --------- --------- --------- --------- --------- AAAAABA-- AAAAABA-- AAAAABA-- AAAAABA-- AAAAABA-- AAAAABA-- AAAAABA-- AAAAABA-- AAAAABADC AAAAABA-- AAAAABA-- AAAAABA-- AAAAABA-- AAAAABA-- AAAAABA-- AAAAABA-- AAAAABA-- AAAAABA-- AAAAABA-- AAAAABA-- AAAAAB--- AAAAAB--- AAAAAB--- 
--------- --------- --------- --------- --------- --------- --------- --------- AAAAABA-- AAAAABA-- AAAAABA-- AAAAABA-- AAAAABADC AAAAABADC AAAAABADC AAAAABADC AAAAABA-- AAAAABA-- AAAAABA-- AAAAABB-- AAAAABB-- AAAAABA-- AAAAABA-- AAAAABA-- AAAAABA-- AAAAABA-- AAAAABA-- AAAAABA-- AAAAABA-- AAAAABA-- AAAAAB--- 
--------- --------- --------- --------- --------- --------- --------- --------- AAAAABA-- AAAAABA-- AAAAABA-- AAAAABA-- AAAAABA-- AAAAABA-- AAAAABA-- AAAAABA-- AAAAABA-- AAAAABA-- AAAAABA-- AAAAABB-- AAAAABAG- AAAAABAA- AAAAABA-- AAAAABA-- AAAAABA-- AAAAABA-- AAAAABA-- AAAAABA-- AAAAABA-- AAAAABA-- AAAAAB--- 
--------- --------- --------- --------- --------- --------- --------- --------- AAAAABA-- AAAAABA-- AAAAABA-- AAAAABA-- AAAAABADC AAAAABADC AAAAABADC AAAAABADC AAAAABADC AAAAABA-- AAAAABA-- AAAAABA-- AAAAABAG- AAAAABAG- AAAAABA-- AAAAABA-- AAAAABA-- AAAAABA-- AAAAABA-- AAAAABA-- AAAAAB--- AAAAAB--- AAAAAB--- 
--------- --------- --------- --------- --------- --------- --------- --------- AAAAABA-- AAAAABA-- AAAAABA-- AAAAABA-- AAAAABA-- AAAAABA-- AAAAABADC AAAAABA-- AAAAABA-- AAAAABA-- AAAAABA-- AAAAABA-- AAAAABA-- AAAAABA-- AAAAABA-- AAAAABA-- AAAAABA-- AAAAABA-- AAAAABA-- AAAAAB--- AAAAAB--- AAAAAB--- AAAAA---- 
--------- --------- --------- --------- --------- --------- --------- --------- AAAAABA-- AAAAABA-- AAAAABA-- AAAAABA-- AAAAABA-- AAAAABA-- AAAAABA-- AAAAABADC AAAAABA-- AAAAABA-- AAAAABA-- AAAAABA-- AAAAABA-- AAAAABA-- AAAAABA-- AAAAAB--- AAAAABA-- AAAAABA-- AAAAABA-- AAAAA---- AAAAA---- AAAAA---- -AAAA---- 
--------- --------- --------- --------- ---A----- --AAA---- ---A----- --------- AAAAABA-- AAAAABA-- AAAAABA-- AAAAABA-- AAAAABADC AAAAABADC AAAAABA-- AAAAABA-- AAAAABADC AAAAABA-- AAAAABA-- AAAAABA-- AAAAABA-- AAAAABA-- AAAAABA-- AAAAABA-- AAAAAB--- AAAAAB--- -AAA----- --------- --------- --------- --------- 
--------- --------- --------- --------- --AAA---- --AAA---- --AAA---- --------- --A--BA-- --A--BA-- AAAAABA-- AAAAABA-- AAAAABA-- AAAAABA-- AAAAABA-- AAAAABA-- AAAAABA-- AAAAABA-- AAAAABA-- AAAAABA-- AAAAABA-- AAAAABA-- AAAAABA-- AAAAABA-- AAAAAB--- AAAAA---- -AAAA---- --------- --------- --------- --------- 
--------- --------- --------- --------- ---A----- --AAA---- ---A----- --------- -----BA-- -----BA-- AAAAABA-- AAAAABA-- AAAAABADC AAAAABADC AAAAABADC AAAAABADC AAAAABADC AAAAABA-- AAAAABADC AAAAABA-- AAAAABA-- AAAAABA-- AAAAABA-- AAAAABA-- AAAAAB--- AAAAAB--- AAAAA---- --AA----- --------- --------- --------- 
--------- --------- --------- --------- --------- --------- --------- --------- -----BA-- -----BA-- AAAAABA-- AAAAABA-- AAAAABA-- AAAAABA-- AAAAABA-- AAAAABA-- AAAAABA-- AAAAABA-- AAAAABA-- AAAAABA-- AAAAABA-- AAAAABA-- AAAAABA-- AAAAABA-- AAAAAB--- AAAAAB--- AAAAA---- --AA----- --------- --------- --------- 
--------- --------- --------- --------- --------- --------- --------- --------- -----BA-- -----BA-- AAAAABA-- AAAAABA-- AAAAABADC AAAAABADC AAAAABADC AAAAABADC AAAAABADC AAAAABA-- AAAAABA-- AAAAABA-- AAAAABA-- AAAAABA-- AAAAABA-- AAAAAB--- AAAAAB--- AAAAA---- -AAAA---- --------- --------- --------- --------- 
--------- --------- ---A----- --AAA---- ---A----- --------- --------- --------- -----BA-- -----BA-- AAAAABA-- AAAAABA-- AAAAABA-- AAAAABA-- AAAAABA-- AAAAABA-- AAAAABADC AAAAAB--- AAAAABA-- AAAAABA-- AAAAABA-- AAAAABA-- AAAAAB--- AAAAAB--- AAAAA---- -AAAA---- --A------ --------- --------- --------- --------- 
--------- --------- --AAA---- --AAA---- --AAA---- --------- --------- --------- -----BA-- -----BA-- AAAAABA-- AAAAABA-- AAAAABA-- AAAAABA-- AAAAABA-- AAAAABA-- AAAAABADC AAAAABA-- AAAAAB--- AAAAAB--- AAAAA---- --AA----- --AA----- --AA----- --------- --------- --------- --------- --------- --------- --------- 
--------- --------- ---A----- --AAA---- ---A----- --------- --------- --------- -----B--- -----BA-- AAAAABA-- AAAAABA-- AAAAABADC AAAAABADC AAAAABADC AAAAABADC AAAAABA-- AAAAABA-- AAAAAB--- AAAAAB--- AAAAA---- --------- --------- --------- --------- --------- --------- --------- --------- --------- --------- 
--------- --------- --------- --------- --------- --------- --------- --------- --------- --------- AAAAABA-- AAAAABA-- AAAAABA-- AAAAABA-- AAAAABA-- AAAAABA-- AAAAABA-- AAAAABA-- AAAAAB--- AAAAAB--- AAAAA---- --------- --------- --------- --------- --------- --------- --------- --------- --------- --------- 
--------- --------- --------- --------- --------- --------- --------- --------- --------- --------- AAAAABA-- AAAAABA-- AAAAABA-- AAAAABADC AAAAABADC AAAAABADC AAAAABA-- AAAAAB--- AAAAAB--- AAAAAB--- AAAAA---- --------- --------- --------- --------- --------- --------- --------- --------- --------- --------- 
---A----- --AAA---- ---A----- --------- --------- --------- --------- --------- --------- --------- AAAAABA-- AAAAABA-- AAAAABADC AAAAABA-- AAAAABA-- AAAAABA-- AAAAABADC AAAAAB--- AAAAAB--- AAAAAB--- AAAAA---- --------- --------- --------- --------- --------- --------- --------- --------- --------- --------- 
--AAA---- --AAA---- --AAA---- --------- --------- --------- --------- --------- --------- --------- --------- --AAABA-- --AAABADC -AAAABA-- AAAAABADC AAAAABA-- AAAAABADC AAAAAB--- AAAAA---- AAAAA---- -AAA----- --------- --------- --------- --------- --------- --------- --------- --------- --------- --------- 
---A----- --AAA---- ---A----- --------- --------- --------- --------- --------- --------- --------- --------- --AAAB--- --AAABA-- -AAAABADC AAAAABADC AAAAABA-- AAAAAB--- AAAAAB--- AAAAA---- AAAAA---- -AAA----- --------- --------- --------- --------- --------- --------- --------- --------- --------- --------- 
