model
size = 18 30 23, scale = 0.05, origin = -y
material 
  colors = A:#400 B:#F5B200 C:#800 D:#001 E:#070 F:#EB6B00 G:#E64700 H:#F08E00 I:#D00 J:#DC0000 K:#E12300 L:#7D9100 M:#FAD600
voxels
------------------ ------------------ ------------------ ---------F-------- ------------------ ------------------ ------------------ ------------------ ------------------ ------------------ ------------------ ------------------ ------------------ ------------------ ------------------ ------------------ ------------------ ------------------ ------------------ ------------------ ------------------ ------------------ ------------------ ------------------ ------------------ ------------------ ------------------ ------------------ ------------------ ------------------ 
------------------ ------------------ ------------------ ---------F-------- ---------H-------- ------------------ ------------------ ------------------ ------------------ ------------------ ------------------ ------------------ ------------------ ------------------ ------BB--BB------ -------LBBB------- --------GB-------- -------BBFB------- ------------------ ------------------ ------------------ ------------------ ------------------ ------------------ ------------------ ------------------ ------------------ ------------------ ------------------ ------------------ 
---------J-------- ---------K-------- ---------G-------- ---------F-------- ---------H-------- ---------B-------- ------------------ ------------------ ------------------ ------------------ ------------------ ------------------ ----BB------BL---- -----BB----BB----- ------------------ ------------------ ------------------ ------------------ ------BB--BB------ -----BB----BB----- ------------------ ------------------ ------------------ ------------------ ------------------ ------------------ ------------------ ------------------ ------------------ ------------------ 
---------J-------- ---------K-------- ---------G-------- ---------F-------- ---------H-------- ---------B-------- ---------M-------- ------------------ ------------------ ------------------ ------------------ ---FB--------BG--- ------------------ ------------------ ------------------ ------------------ ------------------ ------------------ ------------------ ------------------ ----BF------BB---- ------------------ ------------------ ------------------ ------------------ ------------------ ------------------ ------------------ ------------------ ------------------ 
---------J-------- ---------K-------- ---------G-------- ---------F-------- ---------H-------- ---------B-------- ------------------ ------------------ ------------------ ------------------ ---G----------B--- ------------------ ------------------ ------------------ ------------------ ------------------ ------------------ ------------------ ------------------ ------------------ ------------------ ----G--------B---- ------------------ ------------------ ------------------ ------------------ ------------------ ------------------ ------------------ ------------------ 
------------------ ------------------ ------------------ ---------F-------- ---------H-------- ------------------ ------------------ ------------------ ------------------ --L------------B-- --B------------B-- ------------------ ------------------ ------------------ ------------------ ------------------ ------AAAAA------- ------AAAAA------- ------------------ ------------------ ------------------ ---L----------B--- ---B----------B--- ------------------ ------------------ ------------------ ------------------ ------------------ ------------------ ------------------ 
------------------ ------------------ ------------------ ---------F-------- ------------------ ------------------ ------------------ ------------------ ------------------ -B--------------B- ------------------ ------------------ ------------------ ------------------ ------AAAAA------- ------AAAAA------- ------CAAAC------- ------CAAAC------- ------AAAAA------- ------AAAAA------- ------------------ ------------------ --B------------B-- ------------------ ------------------ ------------------ ------------------ ------------------ ------------------ ------------------ 
------------------ ------------------ ------------------ ------------------ ------------------ ------------------ ------------------ ------------------ ------------------ -B--------------B- ------------------ ------------------ ------------------ ------------------ ------AAAAA------- ------CAAAC------- ------AAAAA------- ------CAAAC------- ------CAAAC------- ------CAAAC------- ------AAAAA------- ------------------ --B------------B-- ------------------ ------------------ ------------------ ------------------ -------DD--------- ------------------ ------------------ 
------------------ ------------------ ------------------ ---------F-------- ------------------ ------------------ ------------------ ------------------ ------------------ -B--------------B- ------------------ ------------------ ------------------ ------------------ ------AAAAA------- ------IAAAI------- ------CAAAC------- ------AAAAA------- ------CAAAC------- ------CAAAC------- ------CAAAC------- ------AAAAA------- --B------------B-- ------------------ ------------------ -------DD--------- -------DD--------- -------DD--------- -------DD--------- -------DD--------- 
------------------ ------------------ ------------------ ---------F-------- ---------H-------- ------------------ ------------------ ------------------ BB--------------BB ------------------ ------------------ ------------------ ------------------ ------------------ ------AAAAA------- ------AAAAA------- ------IAAAI------- ------CAAAC------- ------AAAAA------- ------CAAAC------- ------CAAAC------- ------AAAAA------- ---------------B-- BB---------------- ------------------ -------DD--------- -------EE--------- -------EE--------- -------EE--------- -------DD--------- 
---------J-------- ---------K-------- ---------G-------- ---------F-------- ---------H-------- ---------B-------- ------------------ ------------------ BB--------------BB ------------------ ------------------ ------------------ ------------------ ------------------ ------AAAAA------- ------CAAAC------- ------AAAAA------- ------IAAAI------- ------AAAAA------- ------CAAAC------- ------IAAAI------- ------AAAAA------- ---------------B-- BB---------------- ------------------ -------DD--------- -------EE--------- -------EE--------- -------EE--------- -------DD--------- 
---------J-------- ---------K-------- ---------G-------- ---------F-------- ---------H-------- ---------B-------- ---------M-------- ------------------ BB--------------BB ------------------ ------------------ ------------------ ------------------ ------------------ ------AAAAA------- ------CAAAC------- ------AAAAA------- ------CAAAC------- ------AAAAA------- ------CAAAC------- ------AAAAA------- ------AAAAA------- ---------------BB- BB---------------- ------------------ -------DD--------- -------EE--------- -------EE--------- -------EE--------- -------DD--------- 
---------J-------- ---------K-------- ---------G-------- ---------F-------- ---------H-------- ---------B-------- ------------------ ------------------ BB--------------BB ------------------ ------------------ ------------------ ------------------ ------AAAAA------- ------CAAAC------- ------CAAAC------- ------AAAAA------- ------CAAAC------- ------CAAAC------- ------CAAAC------- ------CAAAC------- ------AAAAA------- ----------------B- BB---------------- ------------------ -------DD--------- -------EE--------- -------EE--------- -------EE--------- -------DD--------- 
------------------ ------------------ ------------------ ---------F-------- ---------H-------- ------------------ ------------------ ------------------ BB--------------BB ------------------ ------------------ ------------------ ------AAAAA------- ------CAAAC------- ------CAAAC------- ------AAAAA------- ------CAAAC------- ------CAAAC------- ------CAAAC------- ------CAAAC------- ------CAAAC------- ------AAAAA------- ---------------BB- BB---------------- ------------------ -------DD--------- -------EE--------- -------EE--------- -------EE--------- -------DD--------- 
------------------ ------------------ ------------------ ---------F-------- ------------------ ------------------ ------------------ ------------------ BB--------------BB ------------------ ------------------ ------AAAAA------- ------CAAAC------- ------AAAAA------- ------AAAAA------- ------CAAAC------- ------AAAAA------- ------CAAAC------- ------CAAAC------- ------CAAAC------- ------CAAAC------- ------AAAAA------- ---------------B-- BB---------------- ------------------ -------DD--------- -------EE--------- -------EE--------- -------EE--------- -------DD--------- 
------------------ ------------------ ------------------ ------------------ ------------------ ------------------ ------------------ ------------------ ------------------ -B--------------B- ------------------ -------A-A-------- ------AAAAA------- ------IAAAI------- ------AAAAA------- ------CAAAC------- ------IAAAI------- ------AAAAA------- ------CAAAC------- ------CAAAC------- ------AAAAA------- ------------------ --B------------B-- ------------------ ------------------ -------DD--------- -------DD--------- -------DD--------- -------DD--------- -------DD--------- 
------------------ ------------------ ------------------ ---------F-------- ------------------ ------------------ ------------------ ------------------ ------------------ -B--------------B- ------------------ ------------------ ------AAAAA------- ------CAAAC------- ------AAAAA------- ------CAAAC------- ------CAAAC------- ------IAAAI------- ------CAAAC------- ------AAAAA------- ------------------ ------------------ --B------------B-- ------------------ ------------------ ------------------ ------------------ -------DD--------- ------------------ ------------------ 
------------------ ------------------ ------------------ ---------F-------- ---------H-------- ------------------ ------------------ ------------------ ------------------ -B--------------B- ------------------ ------------------ ------------------ ------AAAAA------- -------A-A-------- ------AAAAA------- ------AAAAA------- ------AAAAA------- ------AAAAA------- ------------------ ------------------ ------------------ --B------------B-- ------------------ ------------------ ------------------ ------------------ ------------------ ------------------ ------------------ 
---------J-------- ---------K-------- ---------G-------- ---------F-------- ---------H-------- ---------B-------- ------------------ ------------------ ------------------ --B------------L-- --B------------B-- ------------------ ------------------ ------------------ ------------------ ------------------ ------------------ ------------------ ------------------ ------------------ ------------------ ---B----------L--- ---B----------B--- ------------------ ------------------ ------------------ ------------------ ------------------ ------------------ ------------------ 
---------J-------- ---------K-------- ---------G-------- ---------F-------- ---------H-------- ---------B-------- ---------M-------- ------------------ ------------------ ------------------ ---B----------G--- ------------------ ------------------ ------------------ ------------------ ------------------ ------------------ ------------------ ------------------ ------------------ ------------------ ----B--------G---- ------------------ ------------------ ------------------ ------------------ ------------------ ------------------ ------------------ ------------------ 
---------J-------- ---------K-------- ---------G-------- ---------F-------- ---------H-------- ---------B-------- ------------------ ------------------ ------------------ ------------------ ------------------ ---GB--------BF--- ------------------ ------------------ ------------------ ------------------ ------------------ ------------------ ------------------ ------------------ ----BB------FB---- ------------------ ------------------ ------------------ ------------------ ------------------ ------------------ ------------------ ------------------ ------------------ 
------------------ ------------------ ------------------ ---------F-------- ---------H-------- ------------------ ------------------ ------------------ ------------------ ------------------ ------------------ ------------------ ----LB------BB---- -----BB----BB----- ------------------ ------------------ ------------------ ------------------ ------BB--BB------ -----BB----BB----- ------------------ ------------------ ------------------ ------------------ ------------------ ------------------ ------------------ ------------------ ------------------ ------------------ 
------------------ ------------------ ------------------ ---------F-------- ------------------ ------------------ ------------------ ------------------ ------------------ ------------------ ------------------ ------------------ ------------------ ------------------ ------BB--BB------ -------BBBL------- --------BB-------- -------BFBB------- ------------------ ------------------ ------------------ ------------------ ------------------ ------------------ ------------------ ------------------ ------------------ ------------------ ------------------ ------------------ 
