model
size = 32 17 19, scale = 0.05, origin = -y
material 
  colors = A:#222 B:#333 C:#444 D:#111 E:#DDD F:#555
voxels
6-AB30-2B510-A3B4-B-B21-3B5-A2B87-2B-2A27-3BA28-BA26-A2(30-B2A)255-A3B4-B-2B20-3B4-2A3B20-2B4-3A23-2B4-2A24-5B3A26-3BABA21-A4-B3AB21-4A2-BA2-A22-B3A29-B2(2A31-)BA49-2(D31-)D75-A2B5-B-2B20-2B5-2A3B20-2B4-3A23-2B4-2A25-4B3A25-4BABA20-3A2-2BA-ABA19-B4A-2BA-3A20-A-3A5-D22-AB2AB12-DBFA14-3A12-2C2A14-BA11-AFB2A-D25-BC2A-2CE24-CBDA-2CE25-3A-2CE30-D52-2B30-2B86-2B-B3A20-AD3-4BABA19-B3A2-2B3ABA19-B-2A2-2B4A21-AB2A-2BA2-DA5-BADCBA10-ABA13-ADBF3A24-2AD2C3AD12-BA9-ADAFB3ABE22-2ABC4ACE23-ACBD2ABCE23-BC4ABCE24-4CB2CE30-D144-3A18-2BAD3-B2-BAB3-C16-B3A2-B2-2AB3-B16-B3A-3B-2A3-C2B16-AB2-A2BA-A3-C4BADCBA2B20-B2CBADBF3ABC19-C2B2AD2C3AD2CB17-C2BADAFB3ABECB17-FCB2ABC4ACE22-2ACBD2ABCD22-ABC4ABCE23-B2CACB2CE30-D137-A27-2BAD2A7-2ABC15-2B4A2B3-AB2AC2B15-B4A3B6AC2B16-AB3A2B3ADABC4BADCBA2BC8-B2A2B6CB2CBADBF3AB2CB16-C3B2AD2C3AD2CB17-3BADAFB3ABE2C17-FCB2ABC4ACE20-CB2ACBD2ABCD22-ABC4ABCD23-BC2ACB2CE30-D136-3A6-2A18-2BAD2A5BAB2A2B15-B-4A3B3AB2AC2B15-B4A3B6AC4B14-AB3A2B3ADABC4BADCBA2B3C5-AB2A2B5A2B2CBADBF3AB2CBD10-5A4B2AD2C3AB2C3B15-3BADAFB3AD3C2B15-FCB2ABC4ACE2CA17-CB2ACBD2ABCEB20-CABC4ABCE23-BC3ABCD167-B3A5B3A18-2BAD2A5BAB2ABC15-2B4A3B3AB2AC3B14-B4A3B6AC4B14-AB3A2B3ADABC4BADCBA2B2CD5-AB2A2B5A2B2CBADBF3AB2CBCB5-B8A4B2AD2C3AB2C3B16-2BADAFB3AB3CBA16-CB2ABC4ADF2C2A16-CB2ACBD2ABDFB21-ABC4ABDC23-BC3ABC168-B3A5B3A18-2BAD2A5BAB2ABCB14-2B4A3B3AB2AC4B13-B4A3B6AC4BA13-AB3A2B3ADABC4BADCBA2B2CD4-BAB2A2B5A2B2CBADBF3AB2CBCB4-AB8A4B2AD2C3AB2C3B16-2BADAFB3AB3CBA16-CB2ABC4ACF2C2A16-CB2ACBD2ABCFB21-ABC4AB2CA22-BC3ABC168-B3A5B3A18-2BAD2A5BAB2ABC15-2B4A3B3AB2AC3B14-B4A3B6AC4BA12-BAB3A2B3ADABC4BADCBA2B2CD4-BAB2A2B5A2B2CBADBF3AB2CBCB4-AB8A4B2AD2C3AB2C3B16-2BADAFB3AB3CBA16-CB2ABC4ADF2C2A16-CB2ACBD2ABDFB21-ABC4ABDCA22-BC3ABC168-B3A5B3A18-2BAD2A5BAB2A2B16-B4A3B3AB2AC2B15-B4A3B6AC4BA13-AB3A2B3ADABC4BADCBA2B3C4-BAB2A2B5A2B2CBADBF3AB2CBD5-AB8A4B2AD2C3AB2C3B16-2BADAFB3AD3C2B16-CB2ABC4ACE2CA17-CB2ACBD2ABCEB20-CABC4ABCE23-BC3ABCD167-B3A6-2A19-BAD2A5BAB2A2B16-B4A3B3AB2AC2B15-B4A3B6AC2B16-AB3A2B3ADABC4BADCBA2BC6-BCB2A2B5A2B2CBADBF3AB2CB11-5A4B2AD2C3AD2CB18-2BADAFB3ABE2C18-CB2ABC4ACE20-CB2ACBD2ABCD22-ABC4ABCD23-BC3AB2CE30-D135-BAB29-AD2A7-2A2B16-B4A2B3-AB2ACB16-B4A3B6AC2B16-AB3A2B3ADABC4BA4C2B9-BA5C3A2B2CBADBF3ABC17-A4B2AD2C3AD2CB18-2BADAFB3ABECB18-CB2ABC4ACE22-2ACBD2ABCD22-ABC4ABCE23-BC3AB2CE30-D136-A10-A2B17-ADA8-2A2B16-B2(3A8-2ACB17-)AB10-BCB3-A4C26-ADBF3A25-AD2C3ADC23-DAFB3ABE23-ABC4ACE23-ACBD2ABCE24-C4ABCE25-3A-2CE30-D22-2(3B29-)C49-2A8-2A2B17-ADA8-2A2B17-3A8-2ACB17-3A8-2A2C69-FA28-D2C2A27-AFB2A-D25-BC3A2CE25-BDA-2CE26-A2-2CE30-D38-A2D13-B-2B12-2A13-5B12-BA12-2BC16-B12-2B17-B2A8-2A2B17-ADA8-2A2B17-3A8-2A2C18-2A8-2AC170-2(D31-)D71-3D12-B-2B12-2A2D11-5B13-A12-2BC16-B12-BC18-2A8-2ABC18-DA8-2ABC18-2A8-2AC20-A318-2D12-B-2B12-2AD13-3B90-AB19-DA8-2AB20-A8-2A337-
