model
size = 17 28 31, scale = 0.05, origin = -y
material 
  colors = A:#063 B:#010 C:#111 D:#CF0 E:#100 F:#690 G:#9C0 H:#C60 I:#CC0 J:#EEE K:#F90 L:#C90 M:#633 N:#990 O:#222 P:#FF0 Q:#F96 R:#960 S:#390 T:#360 U:#330 V:#444 W:#DDD X:#888 Y:#AAA Z:#200 Aa:#660 Ab:#020
voxels
- - - - - - - - - - - - - - - - -   - - - - - - - - - - - - - - - - -   - - - - - - - - - - - - - - - - -   - - - - - - - - - - - - - - - - -   - - - - - - - - - - - - - - - - -   - - - - - A A A A A A A - - - - -   - - - - A A A A A A A A A - - - -   - - - A A A A A A A A A A A - - -   - - - A A A A A A A A A A A - - -   - - - A A A A A A A A A A A - - -   - - - - A A A A A A A A A - - - -   - - - - A A A A A A A A A - - - -   - - - - - - - A A A A - - - - - -   - - - - - - - - - - - - - - - - -   - - - - - - - - - - - - - - - - -   - - - - - - - - - - - - - - - - -   - - - - - - - - - - - - - - - - -   - - - - - - - - - - - - - - - - -   - - - - - - - - - - - - - - - - -   - - - - - - - - - - - - - - - - -   - - - - - - - - - - - - - - - - -   - - - - - - - - - - - - - - - - -   - - - - - - - - - - - - - - - - -   - - - - - - - - - - - - - - - - -   - - - - - - - - - - - - - - - - -   - - - - - - - - - - - - - - - - -   - - - - - - - - - - - - - - - - -   - - - - - - - - - - - - - - - - -   
- - - - - - - - - - - - - - - - -   - - - - - - - - - - - - - - - - -   - - - - - - - - - - - - - - - - -   - - - - - - - - - - - - - - - - -   - - - A A A A A A A A A A A - - -   - - - A A A A A A A A A A A - - -   - - - A A A A A A A A A A A - - -   - - A A A A A A A A A A A A A - -   - - - A A A A A A A A A A A - - -   - - - A A A A A A A A A A A - - -   - - - A A A A A A A A A A A - - -   - - - A A A A A A A A A A A - - -   - - - - A A A A A A A A A - - - -   - - - - - - A A A A A A - - - - -   - - - - - - - A A A A - - - - - -   - - - - - - - - - - - - - - - - -   - - - - - - - - - - - - - - - - -   - - - - - - - - - - - - - - - - -   - - - - - - - - - - - - - - - - -   - - - - - - - - - - - - - - - - -   - - - - - - - - - - - - - - - - -   - - - - - - - - - - - - - - - - -   - - - - - - - - - - - - - - - - -   - - - - - - - - - - - - - - - - -   - - - - - - - - - - - - - - - - -   - - - - - - - - - - - - - - - - -   - - - - - - - - - - - - - - - - -   - - - - - - - - - - - - - - - - -   
- - - - - - - - - - - - - - - - -   - - - - - - - - - - - - - - - - -   - - - - - - - - - - - - - - - - -   - - - - A A A A A A A A A - - - -   - - - A A A A A A A A A A A - - -   - - A A A A A A A A A A A A A - -   - - A A A A A A A A A A A A A - -   - - A A A A A A A A A A A A A - -   - - A A A A A A A A A A A A A - -   - - A A A A A A A A A A A A A - -   - - A A A A A A A A A A A A A - -   - - - A A A A A A A A A A A A - -   - - - A A A A A A A A A A A - - -   - - - - A A A A A A A A A - - - -   - - - - - A A A A A A A A - - - -   - - - - - - A A A A A A - - - - -   - - - - - - - - A A - - - - - - -   - - - - - - - - - - - - - - - - -   - - - - - - - - - - - - - - - - -   - - - - - - - - - - - - - - - - -   - - - - - - - - - - - - - - - - -   - - - - - - - - - - - - - - - - -   - - - - - - - - - - - - - - - - -   - - - - - - - - - - - - - - - - -   - - - - - - - - - - - - - - - - -   - - - - - - - - - - - - - - - - -   - - - - - - - - - - - - - - - - -   - - - - - - - - - - - - - - - - -   
- - - - - - - - - - - - - - - - -   - - - - - - - - - - - - - - - - -   - - - - - - - - - - - - - - - - -   - - - A A A A A A A A A A A - - -   - - A A A A A A A A A A A A A - -   - - A A A A A A A A A A A A A - -   - - A A A A A A A A A A A A A - -   - - A A A A A A A A A A A A A - -   - - A A A A A A A A A A A A A - -   - - A A A A A A A A A A A A A - -   - - A A A A A A A A A A A A A - -   - - A A A A A A A A A A A A A - -   - - - A A A A A A A A A A A A - -   - - - A A A A A A A A A A A - - -   - - - - A A A A A A A A A A - - -   - - - - - A A A A A A A A - - - -   - - - - - - A A A A A A - - - - -   - - - - - - - A A A A - - - - - -   - - - - - - - - - - - - - - - - -   - - - - - - - - - - - - - - - - -   - - - - - - - - - - - - - - - - -   - - - - - - - - - - - - - - - - -   - - - - - - - - - - - - - - - - -   - - - - - - - - - - - - - - - - -   - - - - - - - - - - - - - - - - -   - - - - - - - - - - - - - - - - -   - - - - - - - - - - - - - - - - -   - - - - - - - - - - - - - - - - -   
- - - - - - - - - - - - - - - - -   - - - - - - - - - - - - - - - - -   - - - - A A A A A A A A A - - - -   - - - A A A A A A A A A A A - - -   - - A A A A A A A A A A A A A - -   - - A A A A A A A A A A A A A - -   - A A A A A A A A A A A A A A A -   - A A A A A A A A A A A A A A A -   - A A A A A A A A A A A A A A A -   - - A A A A A A A A A A A A A - -   - - A A A A A A A A A A A A A - -   - - A A A A A A A A A A A A A A -   - - A A A A A A A A A A A A A A -   - - - A A A A A A A A A A A A - -   - - - A A A A A A A A A A A - - -   - - - - A A A A A A A A A A - - -   - - - - - A A A A A A A A - - - -   - - - - - - A A A A A A - - - - -   - - - - - - A A A A A A - - - - -   - - - - - - - - A A - - - - - - -   - - - - - - - - - - - - - - - - -   - - - - - - - - - - - - - - - - -   - - - - - - - - - - - - - - - - -   - - - - - - - - - - - - - - - - -   - - - - - - - - - - - - - - - - -   - - - - - - - - - - - - - - - - -   - - - - - - - - - - - - - - - - -   - - - - - - - - - - - - - - - - -   
- - - - - - - - - - - - - - - - -   - - - - - - - - - - - - - - - - -   - - - A A A A A A A A A A A - - -   - - A A A A A A A A A A A A A - -   - - A A A A A A A A A A A A A - -   - A A A A A A A A A A A A A A A -   - A A A A A A A A A A A A A A A -   - A A A A A A A A A A A A A A A -   - A A A A A A A A A A A A A A A -   - A A A A A A A A A A A A A A A -   - A A A A A A A A A A A A A A A -   - A A A A A A A A A A A A A A A -   - - A A A A A A A A A A A A A A -   - - A A A A A A A A A A A A B B -   - - - A A A A A A A A A A A A - -   - - - A A A A A A A A A A A A - -   - - - - A A A A A A A A A A - - -   - - - - - A A A A A A A A - - C -   - - - - - A A A A A A A A - - C -   - - - - - - A A A A A A - - - - -   - - - - - - - A A A A - - - - - -   - - - - - - - - - - - - - - - - -   - - - - - - - - - - - - - - - - -   - - - - - - - - - - - - - - - - -   - - - - - - - - - - - - - - - - -   - - - - - - - - - - - - - - - - -   - - - - - - - - - - - - - - - - -   - - - - - - - - - - - - - - - - -   
- - - - - - - - - - - - - - - - -   - - - - A A A A A A A A A - - - -   - - - A A A A A A A A A A A - - -   - - A A A A A A A A A A A A A - -   - A A A A A A A A A A A A A A A -   - A A A A A A A A A A A A A A A -   - A A A A A A A A A A A A A A A -   - A A A A A A A A A A A A A A A -   - A A A A A A A A A A A A A A A -   - A A A A A A A A A A A A A A A -   - A A A A A A A A A A A A A A A -   - A A A A A A A A A A A A A B B B   - A A A A A A A A A A A A A B B B   - - A A A A A A A A A A A A B B -   - - A A A A A A A A A A A A A A -   - - - A A A A A A A A A A A A - -   - - - A A A A A A A A A A C - - -   - - - - A A A A A A A A A C C - -   - - - - A A A A A A A A A A C C -   - - - - - A A A A A A A A - - - -   - - - - - - A A A A A A - - - - -   - - - - - - A A A A A A - - - - -   - - - - - - - - A A - - - - - - -   - - - - - - - - - - - - - - - - -   - - - - - - - - - - - - - - - - -   - - - - - - - - - - - - - - - - -   - - - - - - - - - - - - - - - - -   - - - - - - - - - - - - - - - - -   
- - - - - - - - - - - - - - - - -   - - - A A A A A A A A A A A - - -   - - A A A A A A A A A A A A A - -   - - A A A A A A A A A A A A A - -   - A A A A A A A A A A A A A A A -   - A A A A A A A A A A A A A A A -   - A A A A A A A A A A A A A A A -   - A A A A A A A A A A A A A A A -   - A A A A A A A A A A A A A A A -   - A A A A A A A A A A A A A B B -   - A A A A A A A A A A A A A B B -   - A A A A A A A A A A A A A E - -   - A A A A A A A A A A A A A B B B   - A A A A A A A A A A A A A A A A   - - A A A A A A A A A A A A A A -   - - A A A A A A A A A A A C - - -   - - - A A A A A A A A A A C W - -   - - - A A A A A A A A A A C Y - -   - - - - A A A A A A A A A C C C -   - - - - A A A A A A A A A A - - -   - - - - - A A A A A A A A - - - -   - - - - - A A A A A A A A - - - -   - - - - - - A A A A A A - - - - -   - - - - - - - - A A - - - - - - -   - - - - - - - - - - - - - - - - -   - - - - - - - - - - - - - - - - -   - - - - - - - - - - - - - - - - -   - - - - - - - - - - - - - - - - -   
- - - - - - - - - - - - - - - - -   - - - A A A A A A A A A A A - - -   - - A A A A A A A A A A A A A - -   - A A A A A A A A A A A A A A A -   - A A A A A A A A A A A A A A A -   - A A A A A A A A A A A A A A A -   - A A A A A A A A A A A A A A A -   - A A A A A A A A A A A A A A A -   - A A A A A A A A A A A A A B B -   - A A A A A A A A A A A A A E - -   - A A A A A A A A A A A A A N - -   A A A A A A A A A A A A A A G - -   - A A A A A A A A A A A A A B B B   - A A A A A A A A A A A A A A A A   - - A A A A A A A A A A A A A A -   - - A A A A A A A A A A A C M M -   - - A A A A A A A A A A A C K K -   - - - A A A A A A A A A A C H K -   - - - A A A A A A A A A A C V C -   - - - - A A A A A A A A A A C C -   - - - - A A A A A A A A A A - - -   - - - - - A A A A A A A A - - - -   - - - - - A A A A A A A A - - - -   - - - - - - - A A A A - - - - - -   - - - - - - - A A A A - - - - - -   - - - - - - - - - - - - - - - - -   - - - - - - - - - - - - - - - - -   - - - - - - - - - - - - - - - - -   
- - - - - - - - - - - - - - - - -   - - - A A A A A A A A A A A - - -   - - A A A A A A A A A A A A A - -   - A A A A A A A A A A A A A A A -   - A A A A A A A A A A A A A A A -   - A A A A A A A A A A A A A A A -   A A A A A A A A A A A A A A A A A   A A A A A A A A A A A A A A B B B   A A A A A A A A A A A A A A I - -   - A A A A A A A A A A A A A E - -   - A A A A A A A A A A A A A E - -   A A A A A A A A A A A A A A B B B   A A A A A A A A A A A A A A A A A   - A A A A A A A A A A A A A A A A   - A A A A A A A A A A A A C J - A   - - A A A A A A A A A A A C R R -   - - A A A A A A A A A A A C N H -   - - A A A A A A A A A A A C L H -   - - - A A A A A A A A A A C O C -   - - - A A A A A A A A A A A C C -   - - - - A A A A A A A A A A - - -   - - - - A A A A A A A A A A - - -   - - - - - A A A A A A A A - - - -   - - - - - A A A A A A A - - - - -   - - - - - - - A A A A - - - - - -   - - - - - - - - A A - - - - - - -   - - - - - - - - - - - - - - - - -   - - - - - - - - - - - - - - - - -   
- - - - A A A A A A A A A - - - -   - - - A A A A A A A A A A A - - -   - - A A A A A A A A A A A A A - -   - A A A A A A A A A A A A A A A -   - A A A A A A A A A A A A A A A -   A A A A A A A A A A A A A A A A A   A A A A A A A A A A A A A A B B B   A A A A A A A A A A A A A A S S -   A A A A A A A A A A A A A A D D -   A A A A A A A A A A A A A A D D -   A A A A A A A A A A A A A A E - -   A A A A A A A A A A A A A A B B B   A A A A A A A A A A A A A A A A A   - A A A A A A A A A A A A A A A A   - A A A A A A A A A A A A C J - A   - A A A A A A A A A A A A C H H -   - - A A A A A A A A A A A C P P -   - - A A A A A A A A A A A C L L -   - - - A A A A A A A A A A C C C -   - - - A A A A A A A A A A A A - -   - - - A A A A A A A A A A A A - -   - - - - A A A A A A A A A A - - -   - - - - A A A A A A A A A A - - -   - - - - - A A A A A A A - - - - -   - - - - - - A A A A A A - - - - -   - - - - - - - A A A A - - - - - -   - - - - - - - - A A - - - - - - -   - - - - - - - - - - - - - - - - -   
- - - - A A A A A A A A A - - - -   - - A A A A A A A A A A A A A - -   - - A A A A A A A A A A A A A - -   - A A A A A A A A A A A A A A A -   - A A A A A A A A A A A A A A A -   A A A A A A A A A A A A A A A A A   A A A A A A A A A A A A A A B B B   A A A A A A A A A A A A A A D D -   A A A A A A A A A A A A A A T T -   A A A A A A A A A A A A A A Z - -   A A A A A A A A A A A A A A D D -   A A A A A A A A A A A A A A F F -   A A A A A A A A A A A A A A B B B   A A A A A A A A A A A A A A A A A   - A A A A A A A A A A A A A - - A   - A A A A A A A A A A A A C J - -   - A A A A A A A A A A A A C Q Q -   - - A A A A A A A A A A A C M C -   - - A A A A A A A A A A A A C - -   - - - A A A A A A A A A A A A - -   - - - A A A A A A A A A A A A - -   - - - A A A A A A A A A A A A - -   - - - - A A A A A A A A A A - - -   - - - - A A A A A A A A A - - - -   - - - - - - A A A A A A - - - - -   - - - - - - A A A A A A - - - - -   - - - - - - - A A A A - - - - - -   - - - - - - - - - - - - - - - - -   
- - - - A A A A A A A A A - - - -   - - A A A A A A A A A A A A A - -   - A A A A A A A A A A A A A A A -   - A A A A A A A A A A A A A A A -   - A A A A A A A A A A A A A A A -   A A A A A A A A A A A A A A A A A   A A A A A A A A A A A A A A T D B   A A A A A A A A A A A A A A E - -   A A A A A A A A A A A A A A E - -   A A A A A A A A A A A A A A E - -   A A A A A A A A A A A A A A F F -   A A A A A A A A A A A A A A D D -   A A A A A A A A A A A A A A B B B   A A A A A A A A A A A A A A A A A   - A A A A A A A A A A A A A A A A   - A A A A A A A A A A A A C J - -   - A A A A A A A A A A A A C X C -   - - A A A A A A A A A A A A C - -   - - A A A A A A A A A A A A A A -   - - A A A A A A A A A A A A A A -   - - - A A A A A A A A A A A A - -   - - - A A A A A A A A A A A A - -   - - - - A A A A A A A A A A - - -   - - - - A A A A A A A A A - - - -   - - - - - A A A A A A A A - - - -   - - - - - - A A A A A A - - - - -   - - - - - - - A A A A - - - - - -   - - - - - - - - - - - - - - - - -   
- - - A A A A A A A A A A A - - -   - - A A A A A A A A A A A A A - -   - A A A A A A A A A A A A A A A -   - A A A A A A A A A A A A A A A -   A A A A A A A A A A A A A A A A A   A A A A A A A A A A A A A A B B B   A A A A A A A A A A A A A A F F -   A A A A A A A A A A A A A A D D -   A A A A A A A A A A A A A A I I -   A A A A A A A A A A A A A A E - -   A A A A A A A A A A A A A A E - -   A A A A A A A A A A A A A A E - -   A A A A A A A A A A A A A A B B B   A A A A A A A A A A A A A A B B B   A A A A A A A A A A A A A A A A A   - A A A A A A A A A A A A C C C -   - A A A A A A A A A A A A A C - -   - - A A A A A A A A A A A A A A -   - - A A A A A A A A A A A A A A -   - - A A A A A A A A A A A A A A -   - - - A A A A A A A A A A A A - -   - - - A A A A A A A A A A A A - -   - - - A A A A A A A A A A A A - -   - - - - A A A A A A A A A - - - -   - - - - - A A A A A A A A - - - -   - - - - - - A A A A A A - - - - -   - - - - - - A A A A A A - - - - -   - - - - - - - - A A - - - - - - -   
- - - A A A A A A A A A A A - - -   - - A A A A A A A A A A A A A - -   - A A A A A A A A A A A A A A A -   - A A A A A A A A A A A A A A A -   A A A A A A A A A A A A A A A A A   A A A A A A A A A A A A A A B B B   A A A A A A A A A A A A A A G G -   A A A A A A A A A A A A A A D D -   A A A A A A A A A A A A A A D D -   A A A A A A A A A A A A A A U U -   A A A A A A A A A A A A A A E - -   A A A A A A A A A A A A A A E - -   A A A A A A A A A A A A A A Ab- -   A A A A A A A A A A A A A A B B B   A A A A A A A A A A A A A A A A A   - A A A A A A A A A A A A A A A A   - A A A A A A A A A A A A A A - A   - A A A A A A A A A A A A A A A A   - - A A A A A A A A A A A A A A -   - - A A A A A A A A A A A A A A -   - - A A A A A A A A A A A A A A -   - - - A A A A A A A A A A A A - -   - - - A A A A A A A A A A A A - -   - - - - A A A A A A A A A - - - -   - - - - - A A A A A A A A - - - -   - - - - - - A A A A A A - - - - -   - - - - - - A A A A A A - - - - -   - - - - - - - A A A A - - - - - -   
- - - A A A A A A A A A A A - - -   - - A A A A A A A A A A A A A - -   - A A A A A A A A A A A A A A A -   - A A A A A A A A A A A A A A A -   A A A A A A A A A A A A A A A A A   A A A A A A A A A A A A A A B B B   A A A A A A A A A A A A A A T - -   A A A A A A A A A A A A A A E - -   A A A A A A A A A A A A A A E - -   A A A A A A A A A A A A A A E - -   A A A A A A A A A A A A A A I I -   A A A A A A A A A A A A A A D D -   A A A A A A A A A A A A A A G G -   A A A A A A A A A A A A A A B B B   A A A A A A A A A A A A A A A A A   - A A A A A A A A A A A A A A A A   - A A A A A A A A A A A A A A A A   - A A A A A A A A A A A A A A A A   - - A A A A A A A A A A A A A A -   - - A A A A A A A A A A A A A A -   - - A A A A A A A A A A A A A A -   - - - A A A A A A A A A A A A - -   - - - A A A A A A A A A A A A - -   - - - A A A A A A A A A A - - - -   - - - - - A A A A A A A A - - - -   - - - - - A A A A A A A A - - - -   - - - - - - A A A A A A - - - - -   - - - - - - - A A A A - - - - - -   
- - - A A A A A A A A A A A - - -   - - A A A A A A A A A A A A A - -   - A A A A A A A A A A A A A A A -   - A A A A A A A A A A A A A A A -   A A A A A A A A A A A A A A A A A   A A A A A A A A A A A A A A B B B   A A A A A A A A A A A A A A N - -   A A A A A A A A A A A A A A U - -   A A A A A A A A A A A A A A E - -   A A A A A A A A A A A A A A E - -   A A A A A A A A A A A A A A F F -   A A A A A A A A A A A A A A D D -   A A A A A A A A A A A A A A G G -   A A A A A A A A A A A A A A B B B   A A A A A A A A A A A A A A A A A   - A A A A A A A A A A A A C C C -   - A A A A A A A A A A A A A C - A   - A A A A A A A A A A A A A A A A   - - A A A A A A A A A A A A A A -   - - A A A A A A A A A A A A A A -   - - A A A A A A A A A A A A A A -   - - - A A A A A A A A A A A A - -   - - - A A A A A A A A A A A A - -   - - - A A A A A A A A A A - - - -   - - - - - A A A A A A A A - - - -   - - - - - A A A A A A A A - - - -   - - - - - - A A A A A A - - - - -   - - - - - - - A A A A - - - - - -   
- - - A A A A A A A A A A A - - -   - - A A A A A A A A A A A A A - -   - A A A A A A A A A A A A A A A -   - A A A A A A A A A A A A A A A -   A A A A A A A A A A A A A A A A A   A A A A A A A A A A A A A A B B B   A A A A A A A A A A A A A A G G -   A A A A A A A A A A A A A A D D -   A A A A A A A A A A A A A A D D -   A A A A A A A A A A A A A A AaAa-   A A A A A A A A A A A A A A E - -   A A A A A A A A A A A A A A E - -   A A A A A A A A A A A A A A B B B   A A A A A A A A A A A A A A B B B   A A A A A A A A A A A A A A A A A   - A A A A A A A A A A A A C J - -   - A A A A A A A A A A A A C X C -   - - A A A A A A A A A A A A C - -   - - A A A A A A A A A A A A A A -   - - A A A A A A A A A A A A A A -   - - - A A A A A A A A A A A A - -   - - - A A A A A A A A A A A A - -   - - - A A A A A A A A A A A A - -   - - - - A A A A A A A A A - - - -   - - - - - A A A A A A A A - - - -   - - - - - - A A A A A A - - - - -   - - - - - - - A A A A - - - - - -   - - - - - - - - - - - - - - - - -   
- - - - A A A A A A A A A - - - -   - - A A A A A A A A A A A A A - -   - A A A A A A A A A A A A A A A -   - A A A A A A A A A A A A A A A -   - A A A A A A A A A A A A A A A -   A A A A A A A A A A A A A A B B B   A A A A A A A A A A A A A A F F -   A A A A A A A A A A A A A A D D -   A A A A A A A A A A A A A A F F -   A A A A A A A A A A A A A A E - -   A A A A A A A A A A A A A A E - -   A A A A A A A A A A A A A A E - -   A A A A A A A A A A A A A A B B B   A A A A A A A A A A A A A A A A A   - A A A A A A A A A A A A A A A A   - A A A A A A A A A A A A C J - -   - A A A A A A A A A A A A C Q Q -   - - A A A A A A A A A A A C M C -   - - A A A A A A A A A A A A C - -   - - A A A A A A A A A A A A A A -   - - - A A A A A A A A A A A A - -   - - - A A A A A A A A A A A A - -   - - - - A A A A A A A A A A - - -   - - - - A A A A A A A A A - - - -   - - - - - - A A A A A A - - - - -   - - - - - - A A A A A A - - - - -   - - - - - - - A A A A - - - - - -   - - - - - - - - - - - - - - - - -   
- - - - A A A A A A A A A - - - -   - - A A A A A A A A A A A A A - -   - - A A A A A A A A A A A A A - -   - A A A A A A A A A A A A A A A -   - A A A A A A A A A A A A A A A -   A A A A A A A A A A A A A A A A A   A A A A A A A A A A A A A A B B B   A A A A A A A A A A A A A A E - -   A A A A A A A A A A A A A A E - -   A A A A A A A A A A A A A A E - -   A A A A A A A A A A A A A A I I -   A A A A A A A A A A A A A A I I -   A A A A A A A A A A A A A A B B B   A A A A A A A A A A A A A A A A A   - A A A A A A A A A A A A C J - A   - A A A A A A A A A A A A C H H -   - A A A A A A A A A A A A C P P -   - - A A A A A A A A A A A C L L -   - - A A A A A A A A A A A O O C -   - - - A A A A A A A A A A A A - -   - - - A A A A A A A A A A A A - -   - - - A A A A A A A A A A A A - -   - - - - A A A A A A A A A A - - -   - - - - A A A A A A A A - - - - -   - - - - - - A A A A A A - - - - -   - - - - - - - A A A A - - - - - -   - - - - - - - - A A - - - - - - -   - - - - - - - - - - - - - - - - -   
- - - - A A A A A A A A A - - - -   - - - A A A A A A A A A A A - - -   - - A A A A A A A A A A A A A - -   - A A A A A A A A A A A A A A A -   - A A A A A A A A A A A A A A A -   A A A A A A A A A A A A A A A A A   A A A A A A A A A A A A A A B B B   A A A A A A A A A A A A A A D D -   A A A A A A A A A A A A A A G G -   A A A A A A A A A A A A A A Z - -   A A A A A A A A A A A A A A D D -   A A A A A A A A A A A A A A S S -   A A A A A A A A A A A A A A B B B   - A A A A A A A A A A A A A A A A   - A A A A A A A A A A A A C J - A   - A A A A A A A A A A A A C R R -   - - A A A A A A A A A A A C N H -   - - A A A A A A A A A A A C L H -   - - - A A A A A A A A A A C O C -   - - - A A A A A A A A A A A C C -   - - - A A A A A A A A A A A A - -   - - - - A A A A A A A A A A - - -   - - - - A A A A A A A A A A - - -   - - - - - A A A A A A A - - - - -   - - - - - - - A A A A - - - - - -   - - - - - - - - A A - - - - - - -   - - - - - - - - - - - - - - - - -   - - - - - - - - - - - - - - - - -   
- - - - - - - - - - - - - - - - -   - - - A A A A A A A A A A A - - -   - - A A A A A A A A A A A A A - -   - A A A A A A A A A A A A A A A -   - A A A A A A A A A A A A A A A -   - A A A A A A A A A A A A A A A -   A A A A A A A A A A A A A A B B B   A A A A A A A A A A A A A A B B B   A A A A A A A A A A A A A A D D -   - A A A A A A A A A A A A A D D -   - A A A A A A A A A A A A A E - -   A A A A A A A A A A A A A A B B B   A A A A A A A A A A A A A A A A A   - A A A A A A A A A A A A A A A A   - A A A A A A A A A A A A A - - A   - - A A A A A A A A A A A C M M -   - - A A A A A A A A A A A C K K -   - - A A A A A A A A A A A C H K -   - - - A A A A A A A A A A C V C -   - - - A A A A A A A A A A A C C -   - - - - A A A A A A A A A A - - -   - - - - A A A A A A A A A A - - -   - - - - - A A A A A A A A - - - -   - - - - - - - A A A A - - - - - -   - - - - - - - A A A A - - - - - -   - - - - - - - - - - - - - - - - -   - - - - - - - - - - - - - - - - -   - - - - - - - - - - - - - - - - -   
- - - - - - - - - - - - - - - - -   - - - A A A A A A A A A A A - - -   - - A A A A A A A A A A A A A - -   - A A A A A A A A A A A A A A A -   - A A A A A A A A A A A A A A A -   - A A A A A A A A A A A A A A A -   - A A A A A A A A A A A A A A A -   - A A A A A A A A A A A A A B B -   - A A A A A A A A A A A A A F - -   - A A A A A A A A A A A A A E - -   - A A A A A A A A A A A A A E - -   A A A A A A A A A A A A A A B B B   - A A A A A A A A A A A A A A A A   - A A A A A A A A A A A A A A A A   - - A A A A A A A A A A A A A A -   - - A A A A A A A A A A A C - - -   - - A A A A A A A A A A A C W - -   - - - A A A A A A A A A A C Y - -   - - - A A A A A A A A A A C C C -   - - - - A A A A A A A A A A - - -   - - - - A A A A A A A A A A - - -   - - - - - A A A A A A A A - - - -   - - - - - A A A A A A A A - - - -   - - - - - - - - A A - - - - - - -   - - - - - - - - - - - - - - - - -   - - - - - - - - - - - - - - - - -   - - - - - - - - - - - - - - - - -   - - - - - - - - - - - - - - - - -   
- - - - - - - - - - - - - - - - -   - - - A A A A A A A A A A A - - -   - - A A A A A A A A A A A A A - -   - - A A A A A A A A A A A A A - -   - A A A A A A A A A A A A A A A -   - A A A A A A A A A A A A A A A -   - A A A A A A A A A A A A A A A -   - A A A A A A A A A A A A A A A -   - A A A A A A A A A A A A A B B -   - A A A A A A A A A A A A A B B -   - A A A A A A A A A A A A A N - -   - A A A A A A A A A A A A A B B B   - A A A A A A A A A A A A A A A A   - A A A A A A A A A A A A A A A A   - - A A A A A A A A A A A A A A -   - - A A A A A A A A A A A A - A -   - - - A A A A A A A A A A C - - -   - - - A A A A A A A A A A C C - -   - - - - A A A A A A A A A A C C -   - - - - A A A A A A A A A A - - -   - - - - - A A A A A A A A - - - -   - - - - - A A A A A A A A - - - -   - - - - - - A A A A A A - - - - -   - - - - - - - - - - - - - - - - -   - - - - - - - - - - - - - - - - -   - - - - - - - - - - - - - - - - -   - - - - - - - - - - - - - - - - -   - - - - - - - - - - - - - - - - -   
- - - - - - - - - - - - - - - - -   - - - - A A A A A A A A A - - - -   - - - A A A A A A A A A A A - - -   - - A A A A A A A A A A A A A - -   - A A A A A A A A A A A A A A A -   - A A A A A A A A A A A A A A A -   - A A A A A A A A A A A A A A A -   - A A A A A A A A A A A A A A A -   - A A A A A A A A A A A A A A A -   - A A A A A A A A A A A A A B B -   - A A A A A A A A A A A A A B B -   - A A A A A A A A A A A A A E - -   - A A A A A A A A A A A A A B B B   - - A A A A A A A A A A A A A A -   - - A A A A A A A A A A A A A A -   - - - A A A A A A A A A A A A - -   - - - A A A A A A A A A A A - - -   - - - - A A A A A A A A A A - C -   - - - - A A A A A A A A A A - C -   - - - - - A A A A A A A A - - - -   - - - - - - A A A A A A - - - - -   - - - - - - A A A A A A - - - - -   - - - - - - - - A A - - - - - - -   - - - - - - - - - - - - - - - - -   - - - - - - - - - - - - - - - - -   - - - - - - - - - - - - - - - - -   - - - - - - - - - - - - - - - - -   - - - - - - - - - - - - - - - - -   
- - - - - - - - - - - - - - - - -   - - - - - - - - - - - - - - - - -   - - - A A A A A A A A A A A - - -   - - A A A A A A A A A A A A A - -   - - A A A A A A A A A A A A A - -   - A A A A A A A A A A A A A A A -   - A A A A A A A A A A A A A A A -   - A A A A A A A A A A A A A A A -   - A A A A A A A A A A A A A A A -   - A A A A A A A A A A A A A A A -   - A A A A A A A A A A A A A A A -   - A A A A A A A A A A A A A B B -   - - A A A A A A A A A A A A B B -   - - A A A A A A A A A A A A B B -   - - - A A A A A A A A A A A A - -   - - - A A A A A A A A A A A A - -   - - - - A A A A A A A A A A - - -   - - - - - A A A A A A A A - - - -   - - - - - A A A A A A A A - - - -   - - - - - - A A A A A A - - - - -   - - - - - - - A A A A - - - - - -   - - - - - - - - - - - - - - - - -   - - - - - - - - - - - - - - - - -   - - - - - - - - - - - - - - - - -   - - - - - - - - - - - - - - - - -   - - - - - - - - - - - - - - - - -   - - - - - - - - - - - - - - - - -   - - - - - - - - - - - - - - - - -   
- - - - - - - - - - - - - - - - -   - - - - - - - - - - - - - - - - -   - - - - A A A A A A A A A - - - -   - - - A A A A A A A A A A A - - -   - - A A A A A A A A A A A A A - -   - - A A A A A A A A A A A A A - -   - A A A A A A A A A A A A A A A -   - A A A A A A A A A A A A A A A -   - A A A A A A A A A A A A A A A -   - - A A A A A A A A A A A A A - -   - - A A A A A A A A A A A A A - -   - - A A A A A A A A A A A A A A -   - - A A A A A A A A A A A A A A -   - - - A A A A A A A A A A A A - -   - - - A A A A A A A A A A A - - -   - - - - A A A A A A A A A A - - -   - - - - - A A A A A A A A - - - -   - - - - - - A A A A A A - - - - -   - - - - - - A A A A A A - - - - -   - - - - - - - - A A - - - - - - -   - - - - - - - - - - - - - - - - -   - - - - - - - - - - - - - - - - -   - - - - - - - - - - - - - - - - -   - - - - - - - - - - - - - - - - -   - - - - - - - - - - - - - - - - -   - - - - - - - - - - - - - - - - -   - - - - - - - - - - - - - - - - -   - - - - - - - - - - - - - - - - -   
- - - - - - - - - - - - - - - - -   - - - - - - - - - - - - - - - - -   - - - - - - - - - - - - - - - - -   - - - A A A A A A A A A A A - - -   - - A A A A A A A A A A A A A - -   - - A A A A A A A A A A A A A - -   - - A A A A A A A A A A A A A - -   - - A A A A A A A A A A A A A - -   - - A A A A A A A A A A A A A - -   - - A A A A A A A A A A A A A - -   - - A A A A A A A A A A A A A - -   - - A A A A A A A A A A A A A - -   - - - A A A A A A A A A A A A - -   - - - A A A A A A A A A A A - - -   - - - - A A A A A A A A A A - - -   - - - - - A A A A A A A A - - - -   - - - - - - A A A A A A - - - - -   - - - - - - - A A A A - - - - - -   - - - - - - - - - - - - - - - - -   - - - - - - - - - - - - - - - - -   - - - - - - - - - - - - - - - - -   - - - - - - - - - - - - - - - - -   - - - - - - - - - - - - - - - - -   - - - - - - - - - - - - - - - - -   - - - - - - - - - - - - - - - - -   - - - - - - - - - - - - - - - - -   - - - - - - - - - - - - - - - - -   - - - - - - - - - - - - - - - - -   
- - - - - - - - - - - - - - - - -   - - - - - - - - - - - - - - - - -   - - - - - - - - - - - - - - - - -   - - - - A A A A A A A A A - - - -   - - - A A A A A A A A A A A - - -   - - A A A A A A A A A A A A A - -   - - A A A A A A A A A A A A A - -   - - A A A A A A A A A A A A A - -   - - A A A A A A A A A A A A A - -   - - A A A A A A A A A A A A A - -   - - A A A A A A A A A A A A A - -   - - - A A A A A A A A A A A A - -   - - - A A A A A A A A A A A - - -   - - - - A A A A A A A A A - - - -   - - - - - A A A A A A A A - - - -   - - - - - - A A A A A A - - - - -   - - - - - - - - A A - - - - - - -   - - - - - - - - - - - - - - - - -   - - - - - - - - - - - - - - - - -   - - - - - - - - - - - - - - - - -   - - - - - - - - - - - - - - - - -   - - - - - - - - - - - - - - - - -   - - - - - - - - - - - - - - - - -   - - - - - - - - - - - - - - - - -   - - - - - - - - - - - - - - - - -   - - - - - - - - - - - - - - - - -   - - - - - - - - - - - - - - - - -   - - - - - - - - - - - - - - - - -   
- - - - - - - - - - - - - - - - -   - - - - - - - - - - - - - - - - -   - - - - - - - - - - - - - - - - -   - - - - - - - - - - - - - - - - -   - - - A A A A A A A A A A A - - -   - - - A A A A A A A A A A A - - -   - - - A A A A A A A A A A A - - -   - - A A A A A A A A A A A A A - -   - - - A A A A A A A A A A A - - -   - - - A A A A A A A A A A A - - -   - - - A A A A A A A A A A A - - -   - - - A A A A A A A A A A A - - -   - - - - A A A A A A A A A - - - -   - - - - - - A A A A A A - - - - -   - - - - - - - A A A A - - - - - -   - - - - - - - - - - - - - - - - -   - - - - - - - - - - - - - - - - -   - - - - - - - - - - - - - - - - -   - - - - - - - - - - - - - - - - -   - - - - - - - - - - - - - - - - -   - - - - - - - - - - - - - - - - -   - - - - - - - - - - - - - - - - -   - - - - - - - - - - - - - - - - -   - - - - - - - - - - - - - - - - -   - - - - - - - - - - - - - - - - -   - - - - - - - - - - - - - - - - -   - - - - - - - - - - - - - - - - -   - - - - - - - - - - - - - - - - -   
- - - - - - - - - - - - - - - - -   - - - - - - - - - - - - - - - - -   - - - - - - - - - - - - - - - - -   - - - - - - - - - - - - - - - - -   - - - - - - - - - - - - - - - - -   - - - - A A A A A A A A A - - - -   - - - A A A A A A A A A A A - - -   - - - A A A A A A A A A A A - - -   - - - A A A A A A A A A A A - - -   - - - A A A A A A A A A A - - - -   - - - - A A A A A A A A A - - - -   - - - - A A A A A A A A A - - - -   - - - - - - - A A A A - - - - - -   - - - - - - - - - - - - - - - - -   - - - - - - - - - - - - - - - - -   - - - - - - - - - - - - - - - - -   - - - - - - - - - - - - - - - - -   - - - - - - - - - - - - - - - - -   - - - - - - - - - - - - - - - - -   - - - - - - - - - - - - - - - - -   - - - - - - - - - - - - - - - - -   - - - - - - - - - - - - - - - - -   - - - - - - - - - - - - - - - - -   - - - - - - - - - - - - - - - - -   - - - - - - - - - - - - - - - - -   - - - - - - - - - - - - - - - - -   - - - - - - - - - - - - - - - - -   - - - - - - - - - - - - - - - - -   
