model
size = 27 4 25, scale = 0.05, origin = -y
material 
  colors = A:#DDD B:#111 C:#E00 D:#777
voxels
---------BACCCCA----------- ---------AACAACA----------- ---------AACAACA----------- ---------BACCCCA----------- 
-------BB-------BA--------- -------BA-------BA--------- -------BA-------BB--------- -------BB-------BA--------- 
-----BA-----------ABDDD---- -----BA-----------BBDDD---- -----BA-----------ABDDD---- -----BA-----------ABDDD---- 
----A---------------ADDAAA- ----B---------------ADDAA-- ----A---------------ADDAAA- ----A---------------ADDAAAA 
---A-----------------A----- ---A-----------------A----- ---B-----------------A----- ---A-----------------A----- 
--B-------------------A---- --B-------------------A---- --B-------------------A---- --B-------------------A---- 
--A-------------------A---- --A-------------------A---- --A-------------------A---- --A-------------------A---- 
-C---------------------A--- -C---------------------A--- -C---------------------A--- -C---------------------A--- 
-C---------------------A--- -A---------------------A--- -A---------------------A--- -C---------------------A--- 
C-----------------------B-- A-----------------------B-- A-----------------------B-- C-----------------------B-- 
C-----------------------A-- C-----------------------A-- C-----------------------B-- C-----------------------A-- 
A-----------------------A-- A-----------------------B-- A-----------------------A-- A-----------------------A-- 
B-----------------------B-- B-----------------------B-- B-----------------------B-- B-----------------------B-- 
A-----------------------A-- B-----------------------A-- A-----------------------A-- A-----------------------A-- 
A-----------------------C-- A-----------------------C-- B-----------------------C-- A-----------------------C-- 
B-----------------------C-- B-----------------------A-- B-----------------------A-- B-----------------------C-- 
-A---------------------C--- -A---------------------A--- -A---------------------A--- -A---------------------C--- 
-A---------------------C--- -A---------------------C--- -A---------------------C--- -A---------------------C--- 
--A-------------------A---- --A-------------------A---- --A-------------------A---- --A-------------------A---- 
--AA------------------B---- --AA------------------B---- --AA------------------B---- --AA------------------B---- 
---A-----------------A----- ---A-----------------A----- ---A-----------------B----- ---A-----------------A----- 
----A---------------A------ ----A---------------B------ ----A---------------A------ ----A---------------A------ 
-----BA-----------AB------- -----BB-----------AB------- -----BA-----------AB------- -----BA-----------AB------- 
-------AB-------BB--------- -------AB-------AB--------- -------BB-------AB--------- -------AB-------BB--------- 
---------ACCCCAB----------- ---------ACAACAA----------- ---------ACAACAA----------- ---------ACCCCAB----------- 
