model
size = 19 31 21, scale = 0.05, origin = -y
material 
  colors = A:#FFF B:#FC6 C:#C60 D:#FC9 E:#EEE F:#930 G:#FFC H:#F93 I:#200 J:#100 K:#FC3 L:#300 M:#500 N:#400 O:#F90 P:#600 Q:#C30 R:#700 S:#800 T:#C93 U:#630 V:#F96 W:#C63 X:#FCC Y:#444 Z:#F33 Aa:#C33 Ab:#F00 Ac:#AAA Ad:#B00 Ae:#F60 Af:#C96 Ag:#960 Ah:#900 Ai:#963 Aj:#CCC
voxels
- - - - - - - - - - - - - - - - - - -   - - - - - - - - - - - - - - - - - - -   - - - - - - - - - - - - - - - - - - -   - - - - - - - - - - - - - - - - - - -   - - - - - - - - - - - - - - - - - - -   - - - - - - - - - - - - - - - - - - -   - - - - - - I - - - - - - - - - - - -   - - - - - - - - - - - - - - - - - - -   - - - - - - - - - - - - - - - - - - -   - - - - - - - - - - - - - - - - - - -   - - - - - - - - - - - - - - - - - - -   - - - - - - - - - - - - - - - - - - -   - - - - - - - - - - - - - - - - - - -   - - - - - - - - - - - - - - - - - - -   - - - - - - - - - - - - - - - - - - -   - - - - - - - - - - - - - - - - - - -   - - - - - - - - - - - - - - - - - - -   - - - - - - - - - - - - - - - - - - -   - - - - - - - - - - - - - - - - - - -   - - - - - - - - - - - - - - - - - - -   - - - - - - - - - - - - - - - - - - -   - - - - - - - - - - - - - - - - - - -   - - - - - - - - - - - - - - - - - - -   - - - - - - - - - - - - - - - - - - -   - - - - - - - - - - - - - - - - - - -   - - - - - - - - - - - - - - - - - - -   - - - - - - - - - - - - - - - - - - -   - - - - - - - - - - - - - - - - - - -   - - - - - - - - - - - - - - - - - - -   - - - - - - - - - - - - - - - - - - -   - - - - - - - - - - - - - - - - - - -   
- - - - - - - - - - - - - - - - - - -   - - - - - - - - - - - - - - - - - - -   - - - - - - - - - - - - - - - - - - -   - - - - - - - - - - - - - - - - - - -   - - - - - - - - - - - - - - - - - - -   - - - - - - N N - - - - - - - - - - -   - - - - - - N N - - - - - - - - - - -   - - - - - - - - - - - - - - - - - - -   - - - - - - - - - - - - - - - - - - -   - - - - - - - - - - - - - - - - I - -   - - - - - - - - - - - - - - - - - - -   - - - - - - - - - - - - - - - - - - -   - - - - - - - - - - - - - - - - - - -   - - - - - - L - - - - - - - - - - - -   - - - - - - I I - - - - - - - - - - -   - - - - - - - I - - - - - - - - - - -   - - - - - - - - - - - - - - - - - - -   - - - - - - - - - - - - - - - - - - -   - - - - - - - - - - - - - - - - - - -   - - - - - - - - - - - - - - - - - - -   - - - - - - - - - - - - - - - - - - -   - - - - - - - - - - - - - - - - - - -   - - - - - - - - - - - - - - - - - - -   - - - - - - - - - - - - - - - - - - -   - - - - - - - - - - - - - - - - - - -   - - - - - - - - - - - - - - - - - - -   - - - - - - - - - - - - - - - - - - -   - - - - - - - - - - - - - - - - - - -   - - - - - - - - - - - - - - - - - - -   - - - - - - - - - - - - - - - - - - -   - - - - - - - - - - - - - - - - - - -   
- - - - - - - - - - - - - - - - - - -   - - - - - - - - - - - - - - - - - - -   - - - - - - - - - - - - - - - - - - -   - - - - - - - - - - - - - - - - - - -   - - - - - - L - - - - - - - - - - - -   - - - - - - N N - - - N - - - M - - -   - - - - - - M M - - - M - - - M - - -   - - - - - - - - - - - - - - - - A - -   - - - - - - - - - - - - - - - - L - -   - - - - - - - - - - - - - - - R J J J   - - - - - - - - - - - - - - - - - - -   - - - - - - - - - - - - - - - - - - -   - - - - - - F - - - - - - - - - - - -   - - - - - - F - - - - - - - - - - - -   - - - - - - N N - - - N - - - - - - -   - - - - - - - I - - - - - - - - - - -   - - - - - - - - - - - - - - - - - - -   - - - - - - - - - - - - - - - - - - -   - - - - - - - - - - - - - - - - - - -   - - - - - - - - - - - - - - - - - - -   - - - - - - - - - - - - - - - - - - -   - - - - - - - - - - - - - - - - - - -   - - - - - - - - - - - - - - - - - - -   - - - - - - - - - - - - - - - - - - -   - - - - - - - - - - - - - - - - - - -   - - - - - - - - - - - - - - - - - - -   - - - - - - - - - - - - - - - - - - -   - - - - - - - - - - - - - - - - - - -   - - - - - - - - - - - - - - - - - - -   - - - - - - - - - - - - - - - - - - -   - - - - - - - - - - - - - - - - - - -   
- - - - - - - - - - - - - - - - - - -   - - - - - - - - - - - - - - - - - - -   - - - - - - - - - - - - - - - - - - -   - - - - - - L L - - - L - - - - - - -   - - - - - - P - - - - - - - - - - - -   - - - - - - P - - - - - - - - - A - -   - - - I I - R - - - - - - - - R A A -   - - - - - - - - - - - - - - - - A A -   - - - L - - - - - - - - - - - - A A -   - - - - - - - - - - - - - - - - J J J   - - - - - - - - - - - - - - - - - - -   - - - - - - - - - - - - - - - - - - -   - - - - L S - - - - - - - - - - S L -   - - - - L M - - - - - - - - - - M L -   - - - - - - AhAh- - - - - - - Ah- - -   - - - - - - - R - - - R - - - R - - -   - - - - - - - P P - - - - - - - - - -   - - - - - - - - - - - - - - - - - - -   - - - - - - - - - - - - - - - - - - -   - - - - - - - - - - - - - - - - - - -   - - - - - - - - - - - - - - - - - - -   - - - - - - - - - - - - - - - - - - -   - - - - - - - - - - - - - - - - - - -   - - - - - - - - - - - - - - - - - - -   - - - - - - - - - - - - - - - - - - -   - - - - - - - - - - - - - - - - - - -   - - - - - - - - - - - - - - - - - - -   - - - - - - - - - - - - - - - - - - -   - - - - - - - - - - - - - - - - - - -   - - - - - - - - - - - - - - - - - - -   - - - - - - - - - - - - - - - - - - -   
- - - - - - - - - - - - - - - - - - -   - - - - - - I I - - - I - - - - - - -   - - - - - - L L - - - - - - - M - - -   - - - - - N P - - - - - - - - P N - -   - - - - L P - - - - - - - - - - P L -   - - - - N N - - - - F F F - - - A N -   - - - - N M - - - C C C C C - - Z - Z   - - - - M - - - - H H H H H - - Ad- Ad  - - - - - - - - - O O O O O - - M Y M   - - - - P - - - - - O O O - - - J J J   - - - - M - - - - - - - - - - - J J J   - - - - N - - - - - - - - - - - - J J   - - - - - - - - - - - - - - - - - - -   - - - - - - - - - - - - - - - - - - -   - - - - I N F - - - - - - - - F N I -   - - - - - I I F - - - - - - - F I I -   - - - - - - - R R - - - R - - R - - -   - - - - - - - - - - - - - - - - - - -   - - - - - - - - - - - - - - - - N - -   - - - - - - - - - - - - - - - - - - -   - - - - - - - - - - - - - - - - - - -   - - - - - - - - - - - - - - - - - - -   - - - - - - - - - - - - - - - - - - -   - - - - - - - - - - - - - - - - - - -   - - - - - - - - - - - - - - - - - - -   - - - - - - - - - - - - - - - - - - -   - - - - - - - - - - - - - - - - - - -   - - - - - - - - - - - - - - - - - - -   - - - - - - - - - - - - - - - - - - -   - - - - - - - - - - - - - - - - - - -   - - - - - - - - - - - - - - - - - - -   
- - - - - - - - - - - - - - - - - - -   - - - - - - L L - - - L - - - L - - -   - - - - - - L - - - - - - - - L - - -   - - - - - N - - - F F F F F - - N - -   - - - - - - - - C C C C C C C - A A -   - - - - - - - O O O O O O O O O Z - Z   - - - - - - - H H H H H H H H H M N M   - - - - - - - H H H H H H H H H J J J   - - - - - - - H H H H H H H H H Y Y Y   - - - - - - - B B B B B B B B B J J J   - - - - - - - - K K K K K K K - J J J   - - - - F - - - - O O O O O - - - - -   - - - - - - - - - - - - - - - - - - -   - - - - - - - - - - - - - - - - - - -   - - - - - N - - - - - - - - - - N - -   - - - - - - I R - - - - - - - R I - -   - - - - - - F P - - - - - - - P - - -   - - - - - R C - - - - - - - - C R - -   - - - - - L Q - - - - - - - - Q L - -   - - - - - - C - C - - - - - - - C - -   - - - - - - - - - - - P - - - - - - -   - - - - - - - I - - - - - - - - - - -   - - - - - - - - - - - - - - - I - - -   - - - - - - - - - - - - - - - - - - -   - - - - - - - - - - - - - - - - - - -   - - - - - - - - - - - - - - - - - - -   - - - - - - - - - - - - - - - - - - -   - - - - - - - - - - - - - - - - - - -   - - - - - - - - - - - - - - - - - - -   - - - - - - - - - - - - - - - - - - -   - - - - - - - - - - - - - - - - - - -   
- - - - - - I I - - - I - - - I - - -   - - - - - - I I - - - - - - I I - - -   - - - - - - - - - S S S S S - - - - -   - - - - - - - - C C C C C C C - - - -   - - - - - - - H H H H H H H H H A A -   - - - - - - B B B B B B B B B B A AaAa  - - - - - - B B B B B B B B B B Aa- -   - - P F - - D D D D D D D D D D N J J   - - - - - - D D D D D D D D D D J J J   - - Q - - - D D D D D D D D D D J J J   - - F C - - - D D D D D D D D D - - -   - - S C - - - - D D D D D D D - - - -   - - - - B - - - - B B B B B - - - - -   - - - - P - - - - - - - - P - - - - -   - - - B O - - - - - - - - - - - - - -   - - - B C O - B - - O C - B - - - - -   - - - - B P F C B - - F - B R R - - -   - - - - R I M P F - - M I L K P N P N   - - - - C I N N C - - N I C C N I N -   - - - - C - M I C - - - U C - I I - -   - - - - - - - F - - - F - - - - F - -   - - - - - - - M - - - M - - - - - - -   - - - - - - - N - - - - - - - N - - -   - - - - - - - M - - - - - - - - - - -   - - - - - - - - - - - - - - - - - - -   - - - - - - - - C F O - B - - - - - -   - - - - - - - - - C C Ae- - - - - - -   - - - - - - - - - T AfC - - - - - - -   - - - - - - - - - F - - - - - - - - -   - - - - - - - - - - - - - - - - - - -   - - - - - - - - - - - - - - - - - - -   
- - - - - - - - I - - - - I - - - - -   - - - - - - N - - F F F F F - N - - -   - - - - - - - - Q Q Q Q Q Q Q - - - -   - - - - - - - H H H H H H H H H - - -   - - - - - - B B B B B B B B B B B - -   - - - - - G G G G G G G G G G G A G -   - - - - - G G G G G G G G G G G A - Ab  - - P - - D D D D D D D D D D D Ab- S   - - - - - E E E E E E E E E E E S - -   - - - - - A A A A A A A A A A A I J J   - P F - - - A A A A A A A A A A J - -   - - S - - - - E E E E E E E E E - - -   - - - - - - - - G G G G G G G - - - -   - - - - - K K - - X X K K X - - - - -   - - - - - - - - - - - - - - - - - - -   - - - B - - - B - - B B - B - - - - -   - - - B - - - - B - - B B B - - B - -   - - - - K C C C K B C C K K - K P - P   - - - - C Q Q Q C B Q Q C C B O N O -   - - - - U - F F U C F F C U - O C - -   - - - - - - - - P F - - - - - - - - -   - - - - - - - C I M - - C - M I C - -   - - - - - - - Q I N - - Q - - - - - -   - - - - - - - F U M - - F - - - - - -   - - - - - - M M P - - - - - - - - - -   - - - - - - - - U F O - B - - - - - -   - - - - - - - - F C C Ae- - - - - - -   - - - - - - - - - T Af- - - - - - - -   - - - - - - - - - - B - - - - - - - -   - - - - - - - - - - - - - - - - - - -   - - - - - - - - - - - - - - - - - - -   
- - - - - - I I - - - I - - - I - - -   - - - - - - P - Q Q Q Q Q Q Q P - - -   - - - - - - - C C C C C C C C C - - -   - - - - - - B B B B B B B B B B B - -   - - - - - D D D D D D D D D D D D D -   - - - - - E E E E E E E E E E E E E -   - - - - - A A A A A A A A A A A A A -   - - - - - A A A A A A A A A A A AcAc-   - - - - - A A A A A A A A A A A J J J   - - - - - A A A A A A A A A A A J J -   - - - - - E E E E E E E E E E E E E -   - - - - - - E E E E E E E E E E E - -   - - - - - - - G G G G G G G G G - - -   - - - - - - K - D D D K D D D - - - -   - - - C - - - - - - - - - - - - - - -   - - - W - - K W - W B - - - - - - - -   - - - - - - - T - - - - - - - - - - -   - - - - B - - F B K B K B B K K - - -   - - - - K - - M V B K C K K B - - - -   - - - - C - - L T B C U C C - - - K -   - - - - - - - T B B - - T - - - - - -   - - - - - - - F F C - - F C C - - - -   - - - - - - - M C Q - - M Q Q - - - -   - - - - - - - - C F - - L F F - - - -   - - - - - - - C M - - F M - - - - - -   - - - - - - - L N C - - - - - - - - -   - - - - - - - - - F - - - - - - - - -   - - - - - - - - - - - - - - - Ai- - -   - - - - - - - - - - - - - - - - - - -   - - - - - - - - - - - - - - - - - - -   - - - - - - - - - - - - - - - - - - -   
- - - - - - I I - - R R I - - I - - -   - - - - - - R C C C C C C C C R - - -   - - - - - - O O O O O O O O O O O - -   - - - - - D D D D D D D D D D D D D -   - - - - - G G G G G G G G G G G G G -   - - - - - E E E E E E E E E E E E E -   - - - - A A A A A A A A A A A A A E -   - - - - A A A A A A A A A A A A AjJ J   - - - - A A A A A A A A A A A A J J J   - - - - - A A A A A A A A A A A A A -   - - - - - A A A A A A A A A A A A A -   - - - - - A A A A A A A A A A A A A -   - - - - - - D D D D D D D D D D D - -   - - P - K K - D D D D D B D B C R - -   - - - O - - - - B - C B B B C Q L - -   - - - B - - - B B - - - - - - - - - -   - - - V - - - - V V - - - - - - - - -   - - - - - - - - - - B - - - - - - - -   - - - - B - - - V B K - B B - - - - -   - - - - K - - - T K C W K K K - - - -   - - - - - - - - - B - - - - - - - - -   - - - - - - - - - K B - - F - - - - -   - - - - - - - V V C K - V M - - - - -   - - - - - - - T T U C - T L - - - - -   - - - - - - - B AgC - B F - - - - - -   - - - - - - - - N W F F - - - - - - -   - - - - - - - - - C C C - - - - - - -   - - - - - - - - - T - - - - - - - - -   - - - - - - - - - F F - - - - - - - -   - - - - - - - - - - - - - - - - - - -   - - - - - - - - - - - - - - - - - - -   
- - - - - - L - - R R R R R - L - - -   - - - - - - - C C C C C C C C C - - -   - - - - - - H H H H H H H H H H H - -   - - - - - D D D D D D D D D D D D D -   - - - - - E E E E E E E E E E E E E I   - - - - A A A A A A A A A A A A A A -   - - - - A A A A A A A A A A A A A A -   - - - - A A A A A A A A A A A A - - -   - - - - A A A A A A A A A A A A A A A   - - - - A A A A A A A A A A A A A A A   - - - - - A A A A A A A A A A A A A -   - - - - - A A A A A A A A A A A A A -   - - - - - - D D D D D D D D D D D - -   - - - - - - - B B B B B B B B B - - -   - - - B - - - - - B B B B B - - - - -   - - - B - - - B B - - - - - - - - - -   - - - - - - - - - V - - - - - - - - -   - - - - - - - - - - B - - - - - - - -   - - - - - - - - V B K - - - - - - B -   - - - - - - - - T K C - B B - - - B -   - - - - - - - - - - - V - - - - - - -   - - - - - - - - - - B - - - - - - - -   - - - - - - - - - - K B V - - - - - -   - - - - - - - - - - C K T - - - - - -   - - - - - - - B - C B B - - - - - - -   - - - - - - - - - - O O - - - - - - -   - - - - - - - - - - C Ae- - - - - - -   - - - - - - - - - T C B - - - - - - -   - - - - - - - - - - B B - - - - - - -   - - - - - - - - - - - - - - - - - - -   - - - - - - - - - - - W - - - - - - -   
- - - - - - L - - R R R R R - L - - -   - - - - - - - C C C C C C C C C - - -   - - - - - - H H H H H H H H H H H - -   - - - - - D D D D D D D D D D D D D -   - - - - - E E E E E E E E E E E E E I   - - - - A A A A A A A A A A A A A A -   - - - - A A A A A A A A A A A A A A -   - - - - A A A A A A A A A A A A - - -   - - - - A A A A A A A A A A A A A A A   - - - - A A A A A A A A A A A A A A A   - - - - - A A A A A A A A A A A A A -   - - - - - E E E E E E E E E E E E E -   - - - - - - G G G G G G G G G G G - -   - - - - - - - D D D D D D D D D - - -   - - - - - - - - - D D D D D - - - - -   - - - - - - K - - W - - - - - - - - -   - - - - - - - T - - - B - - - - - - -   - - - - R C B F B - B K - - - K K - P   - - - - V Q C M V - K C V V - - - - -   - - - - T - - L T - C U T T - - - - -   - - - - - - - - - - - V V - - - - - -   - - - - - - - - - - B - - - - - - - -   - - - - - - - B B - K B V - - - - - -   - - - - - - - K K - C K T - - - - - -   - - - - - - - - - C B B - - - - - - -   - - - - - - - U C B B B B - - - - - -   - - - - - - - - F B B B - - - - - - -   - - - - - - - - - T AfB - - - - - - -   - - - - - - - - - B B B - - - - - - -   - - - - - - - - - B B B - - - - - - -   - - - - - - - - - - - - - - - - - - -   
- - - - - - L L - P P P I P - L - - -   - - - - - - P C C C C C C C C P - - -   - - - - - - H H H H H H H H H H H - -   - - - - - D D D D D D D D D D D D D -   - - - - - E E E E E E E E E E E E E -   - - - - A A A A A A A A A A A A A A -   - - - - A A A A A A A A A A A A A E -   - - - - A A A A A A A A A A A A AjJ J   - - - - A A A A A A A A A A A A J J J   - - - - A A A A A A A A A A A A A A -   - - - - - A A A A A A A A A A A A A -   - - - - - A A A A A A A A A A A A A -   - - - - - - G G G G G G G G G G G - -   - - - - - K K D D D D K K D D D - - -   - - - - - - B - - B B B B B - - - - -   - - - K - - - K - - B B - - - - - - -   - - - T - - - - T - - B B T - - - - -   - - - - F - C C F K - C F F K - - - -   - - - - M - Q Q M - - Q C M - - - - -   - - - - L - F F L - B F C W K - - W -   - - - - - - - - - - - - - T - - - - -   - - - - - - - B B K B - B F - - - - -   - - - - - - - K K C K - V M - - - - -   - - - - - - - C C U C - T L - - - - -   - - - - - - - C AgC - B F - - - - - -   - - - - - - - - N W - - W - - - - - -   - - - - - - - - - C - - - - - - - - -   - - - - - - - - - Ai- B - - - - - - -   - - - - - - - - - - - - - - - - - - -   - - - - - - - - - - - - - - - - - - -   - - - - - - - - - - - - - - - - - - -   
- - - - - - - - - - M M M - - - - - -   - - - - - - M F F F F F F F F M - - -   - - - - - - O O O O O O O O O O O - -   - - - - - B B B B B B B B B B B B B -   - - - - - G G G G G G G G G G G G G -   - - - - - A A A A A A A A A A A A A -   - - - - A A A A A A A A A A A A A A -   - - - - - A A A A A A A A A A - AcAc-   - - - - A A A A A A A A A A A - J J J   - - - - - A A A A A A A A A A A J J -   - - - - - A A A A A A A A A A A A A -   - - - - - E E E E E E E E E E E E E -   - - - - B - H H H H H H H H H H H - -   - N P - P K - C C C C B B P B C R - -   - - N O N O B - - - C B O N C Q L - -   - - - - C O - - - - O C - F - - - - -   - - - - - P F - - - - F P - - - - - -   - - - - C I M - C K - M I C K K - - -   - - - - - - - - Q - - N I Q - - - - -   - - - - F - - B F B B M U F - - - - -   - - - - - - - B B B - - B - - - - - -   - - - - - - - K K C C - K C C - - - -   - - - - - - - C C Q Q - C Q Q - - - -   - - - - - - - U C F F - U - - - - - -   - - - - - - - - M M - AgM M - - - - -   - - - - - - - L N - - - - - - - - - -   - - - - - - - - - - - - - - - - - - -   - - - - - - - - - - - - - - - - - - -   - - - - - - - - - - - - - - - - - - -   - - - - - - - - - - - - - - - - - - -   - - - - - - - - - - - - - - - - - - -   
- - - - - - - - I - - - - I - - - - -   - - - - - - I - S S S S S S S I - - -   - - - - - - - C C C C C C C C C - - -   - - - - - - H H H H H H H H H H H - -   - - - - - D D D D D D D D D D D D D -   - - - - - A A A A A A A A A A A A A -   - - - - - A A A A A A A A A A A Ab- Ab  - - - - - A A A A A A A A A A A Ab- S   - - - - - A A A A A A A A A A A S - -   - - - - - A A A A A A A A A A A I J J   - - - - - E E E E E E E E E E E J J -   - - - - - - G G G G G G G G G G G - -   - - - - - - - B B B B B B C B B - - -   - - - - - - - - H H H H H P N C R - -   - - - - - - - - - - - - - N I Q L - -   - - - - - - - - - - - - - I U - - - -   - - - - - - - - - - - - - F - - B - -   - - - - - - - P - - - - - - - - P - -   - - - - - - - - - - - - - - - - O - -   - - - - - - - B - C O - - B - O - - -   - - - - - - - B - F - - B - F - - - -   - - - - - - - L I M - - - - M - - - -   - - - - - - - C I N - - C - - - - - -   - - - - - - - C U - - - C - - - - - -   - - - - - - - - - - - C - - - - - - -   - - - - - - - - - - - - - - - - - - -   - - - - - - - - - - - - - - - - - - -   - - - - - - - - - - - - - - - - - - -   - - - - - - - - - - - - - - - - - - -   - - - - - - - - - - - - - - - - - - -   - - - - - - - - - - - - - - - - - - -   
- - - - - - - - - - - - - - - - - - -   - - - - - - I I - P P P P P I I - - -   - - - - - - - - F F F F F F F - - - -   - - - - - - - C C C C C C C C C - - -   - - - - - - B B B B B B B B B B B A -   - - - - - G G G G G G G G G G G A A Aa  - - - - - A A A A A A A A A A A AaAa-   - N P F - A A A A A A A A A A A N N J   - P F - - A A A A A A A A A A A J J J   - - - - - A A A A A A A A A A A J J J   I P F C - - A A A A A A A A A A J - -   - P S C - - - A A A A A A A A A - - -   - - - - - - - - E E E E E E E - - - -   - - - - - - - - - E E E E E - - - - -   - - - - - - - - - - - - - - - - - - -   - - - - - - - - - - - - - - - - - - -   - - - - - - C R R - - - - - R R - - -   - - - R C N P B F W - B - - K P - P -   - - - - - - - - - - - - - - - N - - -   - - - - - U I - I - - - B - - I - - -   - - - - - - - - - - - - - - - - - - -   - - - - - - C - - - - C - - - - - - -   - - - - - - C - - - - C - - - - - - -   - - - - - - - U - - - U - - - - - - -   - - - - - - - - - - - - - - - - - - -   - - - - - - - U - - O - - - - - - - -   - - - - - - - - F - C - - - - - - - -   - - - - - - - - - - - - - - - - - - -   - - - - - - - - - - B - - - - - - - -   - - - - - - - - - - - - - - - - - - -   - - - - - - - - - - - - - - - - - - -   
- - - - - - - - - - - - - - - - - - -   - - - - - - L L - - - L - - - L - - -   - - - - - - L - - S S S S S - L - - -   - - - - - N - - Q Q Q Q Q Q Q - N - -   - - - - - - - C C C C C C C C C A A -   - - - - - - K K K K K K K K K K A - Z   - - - - - - D D D D D D D D D D Z N M   - - - - - - G G G G G G G G G G M J J   - - - - - - E E E E E E E E E E J Y Y   - - - - - - E E E E E E E E E E Y J J   - - - - - - - A A A A A A A A A J J J   - - - - F - - - E E E E E E E - - - -   - - - - L S - - - X X X X X - - - - -   - - - - L M - - - - - - - - - - M L -   - - - - - N - - - - - - - - - - N - -   - - - - - - I R - - - - - - - R I - -   - - - - - - F P B - - - B - - P - - -   - - - - - - - - - - - - - - - - - - -   - - - - - - - - - - - - - - - - - - -   - - - - - - F - F - - - F - - - - - -   - - - - - - R R - - - R - - - R - - -   - - - - - - L - - - - L - - - - - - -   - - - - - - - - - - - - - - - - - - -   - - - - - - - - - - - - - - - - - - -   - - - - - - - - - - - - - - - - - - -   - - - - - - - - - - - - - - - - - - -   - - - - - - - - - - - - - - - - - - -   - - - - - - - - - - - - - - - - - - -   - - - - - - - - - - - - - - - - - - -   - - - - - - - - - - - - - - - - - - -   - - - - - - - - - - - - - - - - - - -   
- - - - - - - - - - - - - - - - - - -   - - - - - - - - - - - - - - - - - - -   - - - - - - M M - - - - - - - L - - -   - - - - - N R - - S S S S S - R N - -   - - - - L - - - F F F - - - - - P L -   - - - - - N - - C C C C C C C C A A -   - - - - - - - H - H H H H H H H A - Z   - - - - - - - B B B B B B B B B Ad- Ad  - - - - - - - B B B B B B B B B M - M   - - - - - - - B B B B B B B B B J J J   - - - - M - - - D D D D D D D - J J J   - - - - N - - - - D D D D D - - - - J   - - - I I - Q - - - - - - - - Q - I I   - - - I I - F - - - - - - - - F - I I   - - - I I N - - - - - - - - - - N I -   - - - - - I I - - - - - - - - - I I -   - - - - - - - C C - - - C - - C - - -   - - - - - - - - - - - - - - - - - - -   - - - - - - - - - - - - - - - - Q - -   - - - - - - U - U - - - U - - - U - -   - - - - - - - - - - - - - - - - - - -   - - - - - - - - - - - - - - - - - - -   - - - - - - - - - - - - - - - - - - -   - - - - - - - - - - - - - - - - - - -   - - - - - - - - - - - - - - - - - - -   - - - - - - - - - - - - - - - - - - -   - - - - - - - - - - - - - - - - - - -   - - - - - - - - - - - - - - - - - - -   - - - - - - - - - - - - - - - - - - -   - - - - - - - - - - - - - - - - - - -   - - - - - - - - - - - - - - - - - - -   
- - - - - - - - - - - - - - - - - - -   - - - - - - - - - - - - - - - - - - -   - - - - - - L L - - - L - - - - - - -   - - - - - - M M - - - M - - - M - - -   - - - - - - P - - - - - - - - P - - -   - - - - - - R - - - F F F - - P A - -   - - - - - - - - - F F F F F - F A A -   - - - - - - - - - C C C C C - - A A -   - - - - - - - - - C C C C C - - A A L   - - - - - - - - - - C C C - - - J J J   - - - - - - - - - - - - - - - - - - J   - - - - - - - - - - - - - - - - - - I   - - - - - - S - - - S - - - S S - - -   - - - - - - M - - - M - - - M M - - -   - - - - - - F F - - - - - - - F - - -   - - - - - - - F - - - - - - - F - - -   - - - - - - - F F - - - - - - F - - -   - - - - - - - - - - - - - - - - - - -   - - - - - - - - - - - - - - - - L - -   - - - - - - - - - - - - - - - - - - -   - - - - - - - - - - - - - - - - - - -   - - - - - - - - - - - - - - - - - - -   - - - - - - - - - - - - - - - - - - -   - - - - - - - - - - - - - - - - - - -   - - - - - - - - - - - - - - - - - - -   - - - - - - - - - - - - - - - - - - -   - - - - - - - - - - - - - - - - - - -   - - - - - - - - - - - - - - - - - - -   - - - - - - - - - - - - - - - - - - -   - - - - - - - - - - - - - - - - - - -   - - - - - - - - - - - - - - - - - - -   
- - - - - - - - - - - - - - - - - - -   - - - - - - - - - - - - - - - - - - -   - - - - - - - - - - - - - - - - - - -   - - - - - - N - - - - - - - - - - - -   - - - - - - P P - - - - - - - - - - -   - - - - - - - - - - - - - - - - - - -   - - - - - - - - - - - M - - - - - - -   - - - - - - - - - - - - - - - - A - -   - - - - - - - - - - - - - - - - L - -   - - - - - - - - - - - - - - - - J J J   - - - - - - - - - - - - - - - - - - -   - - - - - - - - - - - - - - - - - - -   - - - - - - L - - - L - - - - - - - -   - - - - - - L - - - - - - - L L - - -   - - - - - - - - - - - - - - - - - - -   - - - - - - - - - - - - - - - - - - -   - - - - - - - - - - - - - - - - - - -   - - - - - - - - - - - - - - - - - - -   - - - - - - - - - - - - - - - - - - -   - - - - - - - - - - - - - - - - - - -   - - - - - - - - - - - - - - - - - - -   - - - - - - - - - - - - - - - - - - -   - - - - - - - - - - - - - - - - - - -   - - - - - - - - - - - - - - - - - - -   - - - - - - - - - - - - - - - - - - -   - - - - - - - - - - - - - - - - - - -   - - - - - - - - - - - - - - - - - - -   - - - - - - - - - - - - - - - - - - -   - - - - - - - - - - - - - - - - - - -   - - - - - - - - - - - - - - - - - - -   - - - - - - - - - - - - - - - - - - -   
- - - - - - - - - - - - - - - - - - -   - - - - - - - - - - - - - - - - - - -   - - - - - - - - - - - - - - - - - - -   - - - - - - - - - - - - - - - - - - -   - - - - - - - - - - - - - - - - - - -   - - - - - - - - - - - - - - - - - - -   - - - - - - - - - - - - - - - - - - -   - - - - - - - - - - - - - - - - - - -   - - - - - - - - - - - - - - - - - - -   - - - - - - - - - - - - - - - - I - -   - - - - - - - - - - - - - - - - - - -   - - - - - - - - - - - - - - - - - - -   - - - - - - - - - - - - - - - - - - -   - - - - - - - - - - - - - - - - - - -   - - - - - - - - - - - - - - - - - - -   - - - - - - - - - - - - - - - - - - -   - - - - - - - - - - - - - - - - - - -   - - - - - - - - - - - - - - - - - - -   - - - - - - - - - - - - - - - - - - -   - - - - - - - - - - - - - - - - - - -   - - - - - - - - - - - - - - - - - - -   - - - - - - - - - - - - - - - - - - -   - - - - - - - - - - - - - - - - - - -   - - - - - - - - - - - - - - - - - - -   - - - - - - - - - - - - - - - - - - -   - - - - - - - - - - - - - - - - - - -   - - - - - - - - - - - - - - - - - - -   - - - - - - - - - - - - - - - - - - -   - - - - - - - - - - - - - - - - - - -   - - - - - - - - - - - - - - - - - - -   - - - - - - - - - - - - - - - - - - -   
