model
size = 32, scale = 0.05, origin = -y
material 
  colors = A:#DDD B:#111 C:#AAA D:#BBB E:#555 F:#EEE G:#888 H:#222 I:#444 J:#777
voxels
143-2A27-8A23-10A21-2(2AIAI)2A20-2(2AGAG)2A20-2(2ACAC)2A19-3ACAC2ACAC3A18-3AGAG2AGAG3A19-2(2AJAJ)2A20-2(2AEAE)2A20-2(2AIAI)2A21-2(AF)2A2(FA)23-8A27-2F606-2A27-8A23-10A21-2(12A20-)12A19-14A18-14A19-2(12A20-)12A21-10A23-8A27-2A571-2D4E2D23-D3E2A3ED21-5D2A5D19-14A17-7(16A16-)16A17-14A19-12A21-10A23-8F474-4E25-10G21-5D2A5D19-6D2A6D17-7D2A7D15-2(18A14-)18A13-3(20A12-)20A13-2(18A14-)18A15-16A17-14A19-12A21-10A25-4F409-10E20-6G2D6G17-2D12A2D15-2D14A2D14-18A13-2(20A12-)20A11-3(22A10-)22A11-2(20A12-)20A13-18A14-18A15-16A17-14A20-10A25-4F345-E8-E20-3EA6-A3E17-4GA6-A4G15-5CA6-A5C13-3D4A6-4A3D12-7A6-7A11-2(8A6-8A10-)8A6-8A9-2(9A6-9A8-)24A8-24A9-2(22A10-)22A11-20A12-20A13-18A15-16A17-14A20-10A25-4F311-3E8-3E17-2E12-2E15-3G12-3G13-4C12-4C11-4DA12-A4D10-5A12-5A9-5(6A12-6A8-)4(24A8-)24A9-22A10-22A11-20A13-18A15-16A17-14A20-10A307-2E12-2E15-2E14-2E13-3G14-3G11-4C14-4C10-4C14-4C9-5A14-5A8-5A14-5A7-4(6A14-6A6-)3(26A6-)26A7-24A8-24A9-22A11-20A12-20A13-18A15-16A18-12A22-2A4F2A275-2E14-2E13-3E14-3E11-2G18-2G10-2C18-2C9-3C18-3C8-3A18-3A7-3(4A18-4A6-)4A18-4A5-5A18-5A4-28A5-3(26A6-)26A7-24A9-22A11-2(20A12-)20A13-18A16-14A20-10A26-2F277-3E14-3E11-2G18-2G9-3C18-3C8-3C18-3C7-4A18-4A6-4A18-4A5-4(5A18-5A4-)3(28A4-)28A5-26A7-24A9-22A10-22A11-20A12-20A13-18A15-16A18-12A22-2A4F2A233-A39-3E16-3E9-3G18-3G8-3C18-3C7-4C18-4C6-4A18-4A5-5(5A18-5A4-)4(28A4-)28A2(6-24A-A)7-22A2-3(A8-20A3-)A9-18A4-A11-14A6-A13-4A2F4A8-5(A31-)G31-E30-3A38-E20-E9-2G20-2G7-3C20-3C6-3C20-3C5-3(4A20-4A4-)E3A20-3AE3-2(5A20-5A2-)30A2-30A3-2(28A4-)28A6-D22AD8-24A9-22A10-22A11-20A12-20A13-18A16-14A19-5A2F5A24-A2FA203-A39-E20-E9-2G20-2G7-3C20-3C6-3C20-3C5-4A20-4A2(4-E3A20-3AE)3-5A20-5A-6A20-12A20-6AF30A2F30AF-30A3-28A4-28A6-D22AD8-24A9-22A10-22A11-20A12-20A13-18A16-14A19-12A23-A4FA241-2E20-2E8-2G20-2G7-3C20-3C6-3C20-3C5-4A20-4A4-E3A20-3AE3-5A20-5A-6A20-6AC2(5A20-5A2C)30ACF30A2F30AF-30A3-28A6-D22AD8-24A9-22A10-22A11-20A12-20A13-18A16-14A19-12A22-A2F2D2FA240-E22-E8-G22-G7-2C22-2C5-D2C22-2CD4-3A22-3A4-E2A22-2AE3-4A22-4A-5A22-5AC4A22-4ACG4A22-4AG10A12-42AF30AF-30A3-28A6-D22AD2(8-24A)9-22A11-20A12-20A13-18A16-14A19-12A22-A2F2A2FA240-E22-E8-G22-G7-2C22-2C5-D2C22-2CD4-3A22-3A4-E2A22-2AE3-4A22-4A-5A22-5AC4A22-4ACG4A22-4AG10A12-42AF30AF-30A3-28A6-2(D22AD8-)24A9-22A11-20A12-20A13-18A16-14A19-12A22-A2F2D2FA240-2E20-2E8-2G20-2G7-3C20-3C6-3C20-3C5-4A20-4A4-E3A20-3AE3-5A20-5A-6A20-6AC2(5A20-5A2C)9A12-9ACF30A2F30AF-30A3-28A6-D22AD2(8-24A)9-22A11-20A12-20A13-18A16-14A19-12A22-2A4F2A241-E20-E9-2G20-2G7-3C20-3C6-3C20-3C5-4A20-4A2(4-E3A20-3AE)3-5A20-5A-6A20-12A20-6AF9A12-9A2F30AF-30A3-28A4-28A6-D22AD8-24A9-22A10-22A11-20A12-20A13-18A16-14A19-12A23-2A2F2A242-E20-E9-2G20-2G7-3C20-3C6-3C20-3C5-4(4A20-4A4-)2E2A20-2A2E3-5A20-5A2-3D6A12-6A3D2-F28AF3-2(28A4-)28A6-D22AD8-24A9-22A10-22A11-20A12-20A13-18A16-14A19-12A24-4A243-2E18-2E9-3G18-3G8-3C18-3C7-4C18-4C6-4A18-4A5-3(4A20-4A4-)2E2A20-2A2E3-5A20-5A2-3D6A12-6A3D2-F28AF3-2(28A4-)28A6-24A8-24A9-22A10-22A11-20A12-20A13-18A16-14A20-10A273-E18-E11-3G16-3G9-4C16-4C8-4C16-4C7-5A16-5A6-3A20-3A5-2(4A20-4A4-)2E2A20-2A2E3-5A20-5A2-3D6A12-6A3D2-F28AF3-28A4-28A5-26A7-24A9-22A10-22A11-20A12-20A13-18A15-16A18-12A22-8A274-E18-E11-3G16-3G10-3C16-3C9-4C16-4C8-2D2A16-2A2D7-3(3A20-3A6-)E2A20-2AE5-4A20-4A4-2D6A12-6A2D4-F26AF7-2(22A10-)D20AD3(10-22A)11-20A12-20A13-18A16-14A20-10A26-2A309-2G16-2G11-3C16-3C10-2DA16-A2D9-2D2A16-2A2D7-3(3A20-3A6-)E2A20-2AE5-4A20-4A4-2D6A12-6A2D4-F26AF7-2(22A10-)D20AD2(10-22A)11-20A12-20A13-18A15-16A18-12A22-8A339-G16-G13-2C16-2C11-2DA16-A2D9-D3A16-3AD8-DA20-AD7-2(3A20-3A6-)E2A20-2AE5-4A20-4A4-2D6A12-6A2D4-F26AF7-2(22A10-)D20AD2(10-22A)11-20A13-18A15-16A17-14A20-10A25-4A373-C16-C13-3D14-3D10-D4A14-4AD8-DA20-AD7-2(3A20-3A6-)E2A20-2AE6-3A20-3A6-D6A12-6AD6-F24AF8-2(22A10-)D20AD2(10-22A)11-20A13-18A15-16A19-10A24-6A27-4A404-3D14-3D10-D4A14-4AD8-D2A2D14-2D2AD7-2(6A14-6A6-)E5A14-5AE6-6A14-6A6-D6A12-6AD6-F24AF8-2(22A10-)D20AD10-22A11-20A12-2AB14AB2A13-2A14B2A15-3A10B3A19-3A4B3A24-6A465-GDG2D14-2DGDG8-GD3E14-3EDG7-2(DGD3A14-3ADGD6-)3E3A14-3A3E6-6A14-6A6-D6A12-6AD6-F24AF8-2(A-18A-A10-)D-18A-D10-22A11-20A12-A4B10A4BA13-A16BA15-3A10B3A19-3A4B3A25-4A501-2E14-2E13-2(E2A14-2AE12-)3A14-3A9-A3H2A14-4ABA6-DH5A12-5ABD6-F24AF8-2(F2-16A2-F10-)F3-14A3-F10-F20AF11-3A2-10A2-3A13-18B15-16B19-10B22-3A4B3A561-2(E2A14-2AE12-)2A16-2A11-2H2A14-2A2H10-B4A12-4AB10-B20A2(B10-B4-12A4-)B10-B5-10A5-B10-F20AF11-20A13-18B15-16B19-10B594-FA14-AF13-3A14-3A12-B2A14-2AB12-H2A14-2AH12-B3A12-3A4(B12-B18A)B12-F18AF12-20A13-18B15-2BCE12B623-F16AF13-20A12-B18AB12-2H16ABH5(12-2B16A2B)12-F18AF12-2FA14-A2F14-B2E13B656-16F15-18B14-B14H3B14-H14BG2B14-16BJB14-BI2B2I12B14-2BEGE13B14-BICJEI12B14-2B2(IE)12B14-18B15-16F456-
