model
size = 10 19 28, scale = 0.05, origin = -y
material 
  colors = A:#F09 B:#9F9 C:#FF0 D:#111
voxels
---------- ---------- ---------- ---------- ---------- ---------- ---------- ---------- ---------- ---------- ---BBBB--- ---BBBB--- ---------- ---------- ---------- ---------- ---------- ---------- ---------- 
---------- ---------- ---------- ---------- ---------- ---------- ---------- ---------- ---------- ---------- ---BBBB--- ---BBBB--- ---------- ---------- ---------- ---------- ---------- --D----D-- ---------- 
---------- ---------- ---------- ---BBBB--- ---BBBB--- ---BBBB--- ---BBBB--- ---BBBB--- ---BBBB--- ---BBBB--- ---BBBB--- ---BBBB--- --BBBBBB-- --B----B-- --B----B-- --B----B-- -CCC--CCC- -CCC--CCC- -CCC--CCC- 
----BB---- ---BBBB--- ---BBBB--- ---BBBB--- ---BBBB--- ---BBBB--- ---BBBB--- ---BBBB--- ---BBBB--- ---BBBB--- ---BBBB--- ---BBBB--- ---BBBB--- ---------- ---------- ---------- -CCC--CCC- -CCC--CCC- -CCC--CCC- 
--BBBBBB-- --BBBBBB-- ---BBBB--- ---BBBB--- ---BBBB--- ---BBBB--- ---BBBB--- ---BBBB--- ---BBBB--- ---BBBB--- ---BBBB--- ----BB---- ---------- ---------- ---------- ---------- ---------- ---------- ---------- 
-BBBBBBBB- --BBBBBB-- ---BBBB--- ---BBBB--- ---BBBB--- ---BBBB--- ---------- ---------- ---------- ---------- ---------- ---------- ---------- ---------- ---------- ---------- ---------- ---------- ---------- 
BBBBBBBBBB --BBBBBB-- ---BBBB--- ---BBBB--- ---BBBB--- ---AAAA--- ---------- ---------- ---------- ---------- ---------- ---------- ---------- ---------- ---------- ---------- ---------- ---------- ---------- 
BBBBBBBBBB --BBBBBB-- ---BBBB--- ---BBBB--- ---AAAA--- ---AAAA--- ---AAAA--- ---AAAA--- ---AAAA--- ---------- ---------- ---------- ---------- ---------- ---------- ---------- ---------- ---------- ---------- 
BBBBBBBBBB --BBBBBB-- ---BBBB--- ---BBBB--- ---AAAA--- ---AAAA--- --AAAAAA-- --AAAAAA-- --AAAAAA-- ---AAAA--- ---------- ---------- ---------- ---------- ---------- ---------- ---------- ---------- ---------- 
BBBBBBBBBB --BBBBBB-- ---BBBB--- ---AAAA--- ---AAAA--- --AAAAAA-- --AAAAAA-- -AAAAAAAA- -AAAAAAAA- --AAAAAA-- ---AAAA--- ---------- ---------- ---------- ---------- ---------- ---------- ---------- ---------- 
BBBBBBBBBB --BBBBBB-- ---BBBB--- ---AAAA--- ---AAAA--- --AAAAAA-- -AAAAAAAA- -AAAAAAAA- -AAAAAAAA- --AAAAAA-- --AAAAAA-- ---AAAA--- ---------- ---------- ---------- ---------- ---------- ---------- ---------- 
BBBBBBBBBB --BBBBBB-- ---BBBB--- ---AAAA--- ---AAAA--- -AAAAAAAA- -AAAAAAAA- -AAAAAAAA- -AAAAAAAA- -AAAAAAAA- -AAAAAAAA- --AAAAAA-- ---AAAA--- ---------- ---------- ---------- ---------- ---------- ---------- 
BBBBBBBBBB --BBBBBB-- ---BBBB--- ---AAAA--- ---AAAA--- -AAAAAAAA- -AAAAAAAA- -AAAAAAAA- -AAAAAAAA- -AAAAAAAA- -AAAAAAAA- --AAAAAA-- --AAAAAA-- ---AAAA--- ---------- ---------- ---------- ---------- ---------- 
BBBBBBBBBB --BBBBBB-- ---BBBB--- ---AAAA--- ---AAAA--- -AAAAAAAA- -AAAAAAAA- -AAAAAAAA- -AAAAAAAA- -AAAAAAAA- -AAAAAAAA- --AAAAAA-- --AAAAAA-- ---AAAA--- ---------- ---------- ---------- ---------- ---------- 
BBBBBBBBBB --BBBBBB-- ---BBBB--- ---AAAA--- ---AAAA--- -AAAAAAAA- -AAAAAAAA- AAAAAAAAAA AAAAAAAAAA -AAAAAAAA- -AAAAAAAA- --AAAAAA-- --AAAAAA-- ---AAAA--- ---------- ---------- ---------- ---------- ---------- 
BBBBBBBBBB --BBBBBB-- ---BBBB--- ---AAAA--- ---AAAA--- -AAAAAAAA- -AAAAAAAA- AAAAAAAAAA AAAAAAAAAA AAAAAAAAAA -AAAAAAAA- --AAAAAA-- --AAAAAA-- ---AAAA--- ---------- ---------- ---------- ---------- ---------- 
BBBBBBBBBB --BBBBBB-- ---BBBB--- ---AAAA--- ---AAAA--- -AAAAAAAA- -AAAAAAAA- AAAAAAAAAA AAAAAAAAAA AAAAAAAAAA -AAAAAAAA- --AAAAAA-- --AAAAAA-- ---AAAA--- ---------- ---------- ---------- ---------- ---------- 
BBBBBBBBBB --BBBBBB-- ---BBBB--- ---AAAA--- ---AAAA--- -AAAAAAAA- -AAAAAAAA- AAAAAAAAAA AAAAAAAAAA AAAAAAAAAA -AAAAAAAA- --AAAAAA-- --AAAAAA-- ---AAAA--- ---------- ---------- ---------- ---------- ---------- 
BBBBBBBBBB --BBBBBB-- ---BBBB--- ---AAAA--- ---AAAA--- -AAAAAAAA- -AAAAAAAA- -AAAAAAAA- -AAAAAAAA- -AAAAAAAA- -AAAAAAAA- --AAAAAA-- --AAAAAA-- ---AAAA--- ---------- ---------- ---------- ---------- ---------- 
BBBBBBBBBB --BBBBBB-- ---BBBB--- ---------- ---AAAA--- -AAAAAAAA- -AAAAAAAA- -AAAAAAAA- -AAAAAAAA- -AAAAAAAA- --AAAAAA-- --AAAAAA-- ---AAAA--- ---------- ---------- ---------- ---------- ---------- ---------- 
-BBBBBBBB- --BBBBBB-- ---BBBB--- ---------- ---------- ---AAAA--- --AAAAAA-- --AAAAAA-- --AAAAAA-- --AAAAAA-- --AAAAAA-- ---AAAA--- ---------- ---------- ---------- ---------- ---------- ---------- ---------- 
-BBBBBBBB- ---BBBB--- ---BBBB--- ---------- ---------- ---------- ---AAAA--- ---AAAA--- ---AAAA--- ---AAAA--- ---AAAA--- ---------- ---------- ---------- ---------- ---------- ---------- ---------- ---------- 
-BBBBBBBB- ---BBBB--- ---BBBB--- ---------- ---------- ---------- ---------- ---------- ---------- ---------- ---------- ---------- ---------- ---------- ---------- ---------- ---------- ---------- ---------- 
--BBBBBB-- ---BBBB--- ---------- ---------- ---------- ---------- ---------- ---------- ---------- ---------- ---------- ---------- ---------- ---------- ---------- ---------- ---------- ---------- ---------- 
--BBBBBB-- ---BBBB--- ---------- ---------- ---------- ---------- ---------- ---------- ---------- ---------- ---------- ---------- ---------- ---------- ---------- ---------- ---------- ---------- ---------- 
---BBBB--- ----BB---- ---------- ---------- ---------- ---------- ---------- ---------- ---------- ---------- ---------- ---------- ---------- ---------- ---------- ---------- ---------- ---------- ---------- 
---BBBB--- ---------- ---------- ---------- ---------- ---------- ---------- ---------- ---------- ---------- ---------- ---------- ---------- ---------- ---------- ---------- ---------- ---------- ---------- 
----BB---- ---------- ---------- ---------- ---------- ---------- ---------- ---------- ---------- ---------- ---------- ---------- ---------- ---------- ---------- ---------- ---------- ---------- ---------- 
