model
size = 32, scale = 0.05, origin = -y
material 
  colors = A:#0B1013 B:#FFF C:#FCFAF2 D:#111
voxels
B3A2C4A12B4A2C3AB3A2C3A4B8A4B3A2C5A2C2A3B14A3B2A2C3A2C2A3B3A10B3A3B2A2CA2C2A2B3A4B6A4B3A2B2A3C2A2B2AD2B12A2BD2A2B2AC2A2B2A3B3A8B3A3B2A2B4A2(2B2A)4B4A4B2(2A2B)3A2(2B2A)3B8A3B2(2A2B)2AB2(2A2B)3A6B3A2(2B2A)BA2B2AB2A2B2(2A4B)2A2B2AB2A4BA2B2A2BA3B6A3BA2B2A2BA3B2A2BA2(2B2A)4B2(2A2B)A2(2B2A)B2A2BA2B2A6B2A2BA2(2B2AB2A)B2A2BA2B4A2BA2(2B2(2AB)2A)B2A2(2BA)2(2B3(2AB)2A)2(2BA)2B3(2AB)2A2B2(2AB)2A2BA2B4A2BA2B2(2AB)2A2B2AB2A2BA2B2A6B2A2BA2B2AB2(2A2B)A2(2B2A)4B2(2A2B)A2B2A3BA2B2A2BA3B6A3BA2B2A2BA4B2AB2A2B2(2A4B)2A2B2AB2A2BAB2(2A2B)3A6B3A2(2B2A)B2(2A2B)2A3B8A3B2(2A2B)3A2BAD2B2A4B4A4B2A2BDA2B4A2B2A3B3A8B3A3B2A2B2AC2A2B3A2B12A2B3A2B2A3C2A2B3A4B6A4B3A2B2A2CA2C2A3B3A10B3A3B2A2C2AD2C2A3B14A3B2A2C5A2C3A4B8A4B3A2C3AB3A2C4A12B4A2C3AB3A2C3A4B8A4B3A2C4A30-2A30-AC30-2C30-CA2(30-2A)30-AB3(30-2B)30-BA7(30-2A)30-AB3(30-2B)30-BA2(30-2A)30-AC30-2C30-CA30-2A30-4A2C3A4B8A4B3A2C5A2C2A3B14A3B2A2C3A30-AC30-2C30-CA30-2A30-AB2(30-2B)30-BA13(30-2A)30-AB2(30-2B)30-BA30-2A30-AC30-2C30-CD30-D2A2C2A3B14A3B2A2C3A2C2A3B3A10B3A3B2A2CAC30-2C30-CA30-2A30-AB2(30-2B)30-BA2(30-2A)30-AB9(30-2B)30-BA2(30-2A)30-AB2(30-2B)30-BA30-2A30-AC30-2C30-CA2C2A3B3A10B3A3B2A2CA2C2A2B3A4B6A4B3A2B2A3C30-CA30-2A30-AB30-2B30-BA2(30-2A)30-AB3(30-2B)30-BA5(30-2A)30-AB3(30-2B)30-BA2(30-2A)30-AB30-2B30-BA30-2A30-AC30-3C2A2B3A4B6A4B3A2B2A3C2A2B2AD2B12A2BD2A2B2ACA30-2A2(30-AB30-2B30-BA2(30-2A))9(30-2A)30-AB30-2B30-BA2(30-2A)30-AB30-2B30-BA30-2A30-AC2A2B2AD2B12A2BD2A2B2AC2A2B2A3B3A8B3A3B2A2B3A30-AB30-2B30-BA30-2A30-AB2(30-2B)30-BA2(30-2A)30-AB7(30-2B)30-BA2(30-2A)30-AB2(30-2B)30-BA30-2A30-AB30-2B30-BA30-3A2B2A3B3A8B3A3B2A2B4A2(2B2A)4B4A4B2(2A2B)3A30-AB30-2B30-BA30-AD30-DB30-2B30-BA30-2A30-AB3(30-2B)30-BA3(30-2A)30-AB3(30-2B)30-BA30-2A30-AB30-2B30-BD30-DA30-AB30-2B30-BA30-3A2(2B2A)4B4A4B2(2A2B)3A2(2B2A)3B8A3B2(2A2B)2(AB30-2B30-BA30-2A30-)AB2(30-2B)30-BA7(30-2A)30-AB2(30-2B)2(30-BA30-2A30-AB30-2B)30-BA2(2B2A)3B8A3B2(2A2B)2AB2(2A2B)3A6B3A2(2B2A)BAB2(30-BA30-2A30-AB30-2B)30-BA2(30-2A)30-AB5(30-2B)30-BA2(30-2A)2(30-AB30-2B30-BA30-2A)30-AB30-BAB2(2A2B)3A6B3A2(2B2A)BA2B2AB2A2B2(2A4B)2A2B2AB2A3B2(30-BA30-2A30-AB)30-2B2(30-BA30-2A30-AB3(30-2B))30-BA30-2A30-AB30-2B2(30-BA30-2A30-AB)30-3B2AB2A2B2(2A4B)2A2B2AB2A4BA2B2A2BA3B6A3BA2B2A2BA3B30-BA30-AB30-2B30-BA30-2A30-AB30-2B30-BA30-AB2(30-2B)30-BA5(30-2A)30-AB2(30-2B)30-BA30-AB30-2B30-BA30-2A30-AB30-2B30-BA30-AB30-3BA2B2A2BA3B6A3BA2B2A2BA3B2A2BA2(2B2A)4B2(2A2B)A2B2ABA30-2A2(30-AB30-2B30-BA)30-2A30-AB30-2B30-BA30-2A30-AB3(30-2B)2(30-BA30-2A30-AB30-2B)30-BA30-AB30-2B30-BA30-2A30-AB2A2BA2(2B2A)4B2(2A2B)A2(2B2A)B2A2BA2B2A6B2A2BA2B2(2AB)A30-2A30-AB30-BA30-2A2(30-AB30-2B30-BA)30-2A30-AB5(30-2B)30-BA30-2A2(30-AB30-2B30-BA)30-2A30-AB30-BA30-2A30-A2(B2A)2BA2B2A6B2A2BA2(2B2AB2A)B2A2BA2B4A2BA2B3(2AB)2(A30-2A30-AB30-B)A30-2A2(30-AB30-2B30-BA)3(30-2A)2(30-AB30-2B30-BA)2(30-2A30-AB30-BA)30-2A30-A3(B2A)2BA2B4A2BA2(2B2(2AB)2A)B2A2(2BA)2B4(2AB)3(A30-2A30-AB30-B)A30-2A3(30-AB30-2B30-BA)3(30-2A30-AB30-BA)30-2A30-A4(B2A)2(2BA)2(2B3(2AB)2A)2(2BA)2B4(2AB)3(A30-2A30-AB30-B)A30-2A3(30-AB30-2B30-BA)3(30-2A30-AB30-BA)30-2A30-A4(B2A)2(2BA)2B3(2AB)2A2B2(2AB)2A2BA2B4A2BA2B3(2AB)2(A30-2A30-AB30-B)A30-2A2(30-AB30-2B30-BA)3(30-2A)2(30-AB30-2B30-BA)2(30-2A30-AB30-BA)30-2A30-A3(B2A)2BA2B4A2BA2B2(2AB)2A2B2AB2A2BA2B2A6B2A2BA2B2(2AB)A30-2A30-AB30-BA30-2A2(30-AB30-2B30-BA)30-2A30-AB5(30-2B)30-BA30-2A2(30-AB30-2B30-BA)30-2A30-AB30-BA30-2A30-A2(B2A)2BA2B2A6B2A2BA2B2AB2(2A2B)A2(2B2A)4B2(2A2B)A2B2ABA30-2A2(30-AB30-2B30-BA)30-2A30-AB30-2B30-BA30-2A30-AB3(30-2B)2(30-BA30-2A30-AB30-2B)30-BA30-AB30-2B30-BA30-2A30-AB2A2BA2(2B2A)4B2(2A2B)A2B2A3BA2B2A2BA3B6A3BA2B2A2BA3B30-BA30-AB30-2B30-BA30-2A30-AB30-2B30-BA30-AB2(30-2B)30-BA5(30-2A)30-AB2(30-2B)30-BA30-AB30-2B30-BA30-2A30-AB30-2B30-BA30-AB30-3BA2B2A2BA3B6A3BA2B2A2BA4B2AB2A2B2(2A4B)2A2B2AB2A3B2(30-BA30-2A30-AB)30-2B2(30-BA30-2A30-AB3(30-2B))30-BA30-2A30-AB30-2B2(30-BA30-2A30-AB)30-3B2AB2A2B2(2A4B)2A2B2AB2A2BAB2(2A2B)3A6B3A2(2B2A)BAB2(30-BA30-2A30-AB30-2B)30-BA2(30-2A)30-AB5(30-2B)30-BA2(30-2A)2(30-AB30-2B30-BA30-2A)30-AB30-BAB2(2A2B)3A6B3A2(2B2A)B2(2A2B)2A3B8A3B2(2A2B)2(AB30-2B30-BA30-2A30-)AB2(30-2B)30-BA7(30-2A)30-AB2(30-2B)2(30-BA30-2A30-AB30-2B)30-BA2(2B2A)3B8A3B2(2A2B)3A2BAD2B2A4B4A4B2A2BDA2B3A2(30-AB30-2B30-BA30-2A)30-AB3(30-2B)30-BA3(30-2A)30-AB3(30-2B)2(30-BA30-2A30-AB30-2B)30-BA30-3A2BAD2B2A4B4A4B2A2BDA2B4A2B2A3B3A8B3A3B2A2B3A30-AB30-2B30-BA30-2A30-AB2(30-2B)30-BA2(30-2A)30-AB7(30-2B)30-BA2(30-2A)30-AB2(30-2B)30-BA30-2A30-AB30-2B30-BA30-3A2B2A3B3A8B3A3B2A2B2AC2A2B3A2B12A2B3A2B2ACA30-2A30-AB30-2B30-BA30-2A30-AD30-DB30-2B30-BA11(30-2A)30-AB30-2B30-BD30-DA30-2A30-AB30-2B30-BA30-2A30-AC2A2B3A2B12A2B3A2B2A3C2A2B3A4B6A4B3A2B2A3C30-CA30-2A30-AB30-2B30-BA2(30-2A)30-AB3(30-2B)30-BA5(30-2A)30-AB3(30-2B)30-BA2(30-2A)30-AB30-2B30-BA30-2A30-AC30-3C2A2B3A4B6A4B3A2B2A2CA2C2A3B3A10B3A3B2A2CAC30-2C30-CA30-2A30-AB2(30-2B)30-BA2(30-2A)30-AB9(30-2B)30-BA2(30-2A)30-AB2(30-2B)30-BA30-2A30-AC30-2C30-CA2C2A3B3A10B3A3B2A2C3A2C2A3B14A3B2A2CD2A30-AC30-2C30-CA30-2A30-AB2(30-2B)30-BA13(30-2A)30-AB2(30-2B)30-BA30-2A30-AC30-2C30-CA30-3A2C2A3B14A3B2A2CD4A2C3A4B8A4B3A2C4A30-2A30-AC30-2C30-CA2(30-2A)30-AB3(30-2B)30-BA7(30-2A)30-AB3(30-2B)30-BA2(30-2A)30-AC30-2C30-CA30-2A30-4A2C3A4B8A4B3A2C3AB3A2C4A12B4A2C3AB3A2C3A4B8A4B3A2C5A2C2A3B14A3B2A2C3A2C2A3B3A10B3A3B2A2CA2C2A2B3A4B6A4B3A2B2A3C2A2B2AD2B12A2BD2A2B2AC2A2B2A3B3A8B3A3B2A2B4A2(2B2A)4B4A4B2(2A2B)3A2(2B2A)3B8A3B2(2A2B)2AB2(2A2B)3A6B3A2(2B2A)BA2B2AB2A2B2(2A4B)2A2B2AB2A4BA2B2A2BA3B6A3BA2B2A2BA3B2A2BA2(2B2A)4B2(2A2B)A2(2B2A)B2A2BA2B2A6B2A2BA2(2B2AB2A)B2A2BA2B4A2BA2(2B2(2AB)2A)B2A2(2BA)2(2B3(2AB)2A)2(2BA)2B3(2AB)2A2B2(2AB)2A2BA2B4A2BA2B2(2AB)2A2B2AB2A2BA2B2A6B2A2BA2B2AB2(2A2B)A2(2B2A)4B2(2A2B)A2B2A3BA2B2A2BA3B6A3BA2B2A2BA4B2AB2A2B2(2A4B)2A2B2AB2A2BAB2(2A2B)3A6B3A2(2B2A)B2(2A2B)2A3B8A3B2(2A2B)3A2BAD2B2A4B4A4B2A2BDA2B4A2B2A3B3A8B3A3B2A2B2AC2A2B3A2B12A2B3A2B2A3C2A2B3A4B6A4B3A2B2A2CA2C2A3B3A10B3A3B2A2C2AD2C2A3B14A3B2A2C5A2C3A4B8A4B3A2C3AB3A2C4A12B4A2C3AB
