model
size = 32 32 16, scale = 0.05, origin = -y
material 
  colors = A:#700 B:#EEE C:#D00 D:#B00 E:#500 F:#BBB G:#A00 H:#F90 I:#111 J:#AAA K:#03F L:#F30 M:#888 N:#009 O:#444 P:#00F Q:#039 R:#00C S:#03C T:#06C U:#003 V:#036 W:#06F X:#006 Y:#00E
voxels
196-2B20-2B8-2B20-2B339-2H61-4F26-8B24-8B26-4A434-2B20-2B7-4B18-4B6-4B18-4B7-2B20-2B274-4J27-2J2C2J25-8J21-5J4A5J16-18B14-18B16-14A21-8A400-2B20-2B7-4B18-4B6-4B18-4B7-2B20-2B115-2B94-2M29-4M27-6C25-8C20-4M9C3M14-3M14A3M11-22B10-22B11-20A14-6A4B6A396-2B20-2B7-4A18-4A3(6-5A16-5A)7-3A6-NR3P7-3A18-4G27-6B27-4D29-2D29-4D27-6D25-8C22-2A9CA16-6A9C5A10-24A7-26B6-11B4F11B7-9A6B9A10-6A8B6A16-A3I5B3I20-I3HI3BI3HI18-I2HY2HIBI2HY2HI17-I3H2OIBI2O3HI17-I2H3OIBI3O2HI18-I3OI3-I3OI20-3I5-3I46-2(2B20-2B8-)2A20-2A8-2A20-2A7-5A16-5A5-2(7A14-7A4-)7A4-2KRPN5-7A4-7A14-7A4-7A2-RX2-2G-NS3-7A5-5A5-6G5-5A6-5A4-8B4-5A7-3A6-6D6-3A17-6D26-6D25-8D23-B9C19-4A9C3A12-8A9C7A7-26A5-12B4F12B4-11B6F11B5-9A8B9A7-7A10B7A12-3A3I5B3I2A18-I3HI3BI3HI18-I5HIBI5HI17-I5HIBI2HB2HI17-I5HIBI5HI18-I3HI3BI3HI20-3I5-3I14-2B20-2B7-2(4B18-4B6-)4A18-4A6-5A16-5A5-7A14-7A3-9A3-S3NV4-9A2-9A12-2(9A2-)K5-K3-9A2-9A12-9A2-9A-R2-4G-S2-9A3-7A3-8G3-7A4-7A3-8B3-7A4-7A3-8D3-7A6-5A4-6D4-5A8-5E3-8D3-5E9-3E3-10D3-3E15-2B9CB16-6A9C5A9-9A9C8A5-28A3-12B6F12B2-11B8F11B3-9A10B9A5-8A10B8A9-5A10B5A17-2(11B21-)11B22-9B24-7B48-2B20-2B7-2(4B18-4B6-)4A18-4A5-7A5-KWT6-7A3-9A12-2(9A2-)Q5-K3-9A-L10A10-10ALH10AQ7-K-10AHL10A4-2G4-10AL-9AP3-4G2-N-2(9A2-)8G2(2-9A)-10B-9A3-7A3-8D3-7A5-7A2-8D2-7A6-7E2-8D2-7E7-5E2-10D2-5E9-7B9C6B10-7A9C6A8-9A9C8A4-13A4B13A-12B8F23B10F11B-10A10B10A4-7A12B7A8-5A12B5A15-13B19-13B20-11B21-11B22-9B25-5B49-2B20-2B8-2B20-2B7-5A16-5A5-7A4-K3-U5-7A3-9A12-9A-L10A-Q5-K2-10ALH10A10-10A2H10AQ7-K-10A2H10A4-2G4-10AHL9AP2-6G-N10AL-9A2-8G2(2-9A)-10B-2(9A2-)8D2-9A4-7A2-8D2-7A2(6-7E-10D-7E)8-7B9C6B10-7A9C6A7-10A9C9A3-13A4B13A-12B8F23B10F11B-10A10B10A3-8A12B8A7-5A12B5A15-13B19-13B20-11B21-11B22-9B25-5B91-K-T18-5A16-5A5-7A4-K3-U5-7A3-9A12-9A-L10A-Q5-K2-10ALH10A10-10A2H10AQ7-K-10A2H10A4-2G4-10AHL9AP2-6G-N10AL-9A2-8G2(2-9A)-10B-2(9A2-)8D2-9A4-7A2-8D2-7A2(6-7E-10D-7E)8-7B9C6B10-7A9C6A7-10A9C9A3-13A4B13A-12B8F23B10F11B-10A10B10A3-8A12B8A7-5A12B5A15-13B19-13B20-11B21-11B22-9B25-5B49-2B20-2B8-2B20-2B7-5A16-5A5-7A4-K3-U5-7A3-9A12-9A-L10A-Q5-K2-10ALH10A10-10A2H10AQ7-K-10A2H10A4-2G4-10AHL9AP3-4G2-N10AL-9A2-8G2(2-9A)-10B-2(9A2-)8D2-9A4-7A2-8D2-7A6-7E2-8D2-7E6-7E-10D-7E8-7B9C6B10-7A9C6A8-9A9C8A4-13A4B13A-12B8F23B10F11B-10A10B10A4-7A12B7A8-5A12B5A15-13B19-13B20-11B21-11B22-9B25-5B17-2B20-2B7-2(4B18-4B6-)4A18-4A5-7A5-KWT6-7A3-9A12-2(9A2-)Q5-K3-9A-L10A10-10ALH10AQ7-K-10AHL10A10-10AL-9AP3-4G2-N-2(9A2-)8G2(2-9A)2-8B2-9A3-7A3-8D3-7A5-7A3-6D3-7A6-7E2-8D2-7E7-5E2-10D2-5E9-7B9C6B11-6A9C5A9-9A9C8A5-28A3-12B6F12B2-11B8F11B3-9A10B9A5-8A10B8A9-5A10B5A17-2(11B21-)11B22-9B24-7B48-2B20-2B7-2(4B18-4B6-)4A18-4A6-5A16-5A5-7A14-7A3-9A3-S3NV4-9A2-9A12-2(9A2-)K5-K3-9A2-9A12-9A2-9A-R3-2G2-S2-9A3-7A4-6G2(4-7A)3-8B3-2(7A4-)6D4-7A6-5A4-6D4-5A8-5E4-6D4-5E9-3E4-8D4-3E16-B9C19-4A9C3A12-8A9C7A7-26A5-12B4F12B4-11B6F11B5-9A8B9A7-7A10B7A12-3A10B3A19-11B21-11B22-9B24-7B26-5B81-2(2B20-2B8-)2A20-2A8-2A20-2A7-5A16-5A5-2(7A14-7A4-)7A4-2KRPN5-7A4-7A14-7A4-7A2-RX5-NS3-7A5-5A6-4G2(6-5A)5-6B5-5A7-3A7-4D7-3A19-2D29-4D27-6D25-8C22-2A9CA16-6A9C5A10-24A7-26B6-11B4F11B7-9A6B9A10-6A8B6A16-2A8B2A22-9B23-9B24-7B26-5B273-3A18-3A7-2(5A16-5A6-)5A16-5A7-3A6-NR3P7-3A51-2B94-2D29-4D27-6C25-8C20-4A9C3A14-20A11-22B10-22B11-20A14-6A4B6A22-4B28-5B27-5B699-4C27-6C25-8C21-14A16-18B14-18B16-14A21-8A827-2C61-4A26-8B24-8B26-4A270-
