model
size = 32, scale = 0.05, origin = -y
material 
  colors = A:#EEE B:#0C0 C:#3F7FFF D:#E00
voxels
B30D30(AC30-)33A29(B30-A960-A30-A)B30-A960-A30-34A29(30-2A)30-33A
