model
size = 23 31 15, scale = 0.05, origin = -y
material 
  colors = A:#3CF B:#CFF C:#C60 D:#D00 E:#BBB F:#360 G:#390
voxels
----------------------- ----------------------- ----------------------- ----------------------- -----AAAAA------------- -----AAAAA------------- ----------------------- ----------------------- ----------------------- ----------------------- ----------------------- ----------------------- ----------------------- ----------------------- ----------------------- ----------------------- ----------------------- ----------------------- ----------------------- ----------------------- ----------------------- ----------------------- ----------------------- ----------------------- ----------------------- ----------------------- ----------------------- ----------------------- ----------------------- ----------------------- ----------------------- 
----------------------- ----------------------- -----AAAAA------------- -----AAAAA------------- ---AAAAAAAAA----------- ---AAAAAAAAA----------- -----AAAAA------------- -----BBBBB------------- ----------------------- ----------------------- ----------------------- ----------------------- ----------------------- ----------------------- ----------------------- ----------------------- ----------------------- ----------------------- ----------------------- ----------------------- ----------------------- ----------------------- ----------------------- ----------------------- ----------------------- ----------------------- ----------------------- ----------------------- ----------------------- ----------------------- ----------------------- 
----------------------- -----AAAAA------------- ---AAAAAAAAA----------- ---AAAAAAAAA----------- --AAAAAAAAAAA---------- --AAAAAAAAAAA---------- ---AAAAAAAAA----------- ---BBBBBBBBB----------- -----BBBBB------------- ----------------------- ----------------------- ----------------------- ----------------------- ----------------------- ----------------------- ----------------------- ----------------------- ----------------------- ----------------------- ----------------------- ----------------------- ----------------------- ----------------------- ----------------------- ----------------------- ----------------------- ----------------------- ----------------------- ----------------------- ----------------------- ----------------------- 
-----BBBBB------------- ----AAAAAAA------------ --AAAAAAAAAAA---------- --AAAAAAAAAAA---------- -AAAAAAAAAAAAA--------- -AAAAAAAAAAAAA--------- --AAAAAAAAAAA---------- --BBBBBBBBBBB---------- ----BBBBBBB------------ -----BBBBB------------- -----BBBBB------------- ----------------------- ----------------------- ----------------------- ----------------------- ----------------------- ----------------------- ----------------------- ----------------------- ----------------------- ----------------------- ----------------------- ----------------------- ----------------------- ----------------------- ----------------------- ----------------------- ----------------------- ----------------------- ----------------------- ----------------------- 
----BBBBBBB------------ ---AAAAAAAAA----------- --AAAAAAAAAAA---------- --AAAAAAAAAAA---------- -AAAAAAAAAAAAA--------- -AAAAAAAAAAAAA--------- --AAAAAAAAAAA---------- --BBBBBBBBBBB---------- ---BBBBBBBBB----------- ----BBBBBBB------------ ----BBBBBBB------------ ------BBB-------------- ----------------------- ----------------------- ----------------------- ------BBB-------------- ------BBB-------------- ----------------------- ------DDD-------------- ----------------------- ----------------------- ----------------------- ----------------------- ----------------------- ----------------------- ----------------------- ------CCC-------------- ------CCC-------------- ------CCC-------------- ------CCC-------------- ----------------------- 
---BBBBBBBBB----------- --AAAAAAAAAAA---------- -AAAAAAAAAAAAA--------- -AAAAAAAAAAAAA--------- AAAAAAAAAAAAAAA-------- AAAAAAAAAAAAAAA-------- -AAAAAAAAAAAAA--------- -BBBBBBBBBBBBB--------- --BBBBBBBBBBB---------- ---BBBBBBBBB----------- ---BBBBBBBBB----------- -----BBBBB------------- ------BBB-------------- ------BBB-------------- ------BBB-------------- -----BBBBB------------- -----BBBBB------------- ------DDD-------------- -----DDDDD------------- ----------------------- ----------------------- ----------------------- ----------------------- ------CCC-------------- ------CCC-------------- ------CCC-------------- -----CCCCC------------- -----CCCCC------------- -----CCCCC------------- -----CCCCC------------- ------CCC-------------- 
---BBBBBBBBB----------- --AAAAAAAAAAA---------- -AAAAAAAAAAAAA--------- -AAAAAAAAAAAAA--------- AAAAAAAAAAAAAAA-------- AAAAAAAAAAAAAAA-------- -AAAAAAAAAAAAA--------- -BBBBBBBBBBBBB--------- --BBBBBBBBBBB---------- ---BBBBBBBBB----------- ---BBBBBBBBB----------- ----BBBBBBB------------ -----BBBBB------------- -----BBBBB------------- -----BBBBB------------- ----BBBBBBB------------ ----BBBBBBB------------ -----DDDDD------------- ----DDDDDDD------------ ----------------------- ----------------------- ----------------------- ------CCC-------------- -----CCCCC------------- -----CCCCC------------- -----CCCCC------------- ----CCCCCCC------------ ----CCCCCCC------------ ----CCCCCCC------------ ----CCCCCCC------------ -----CFGFC------------- 
---BBBBBBBBB----------- --AAAAAAAAAAA---------- -AAAAAAAAAAAAA--------- -AAAAAAAAAAAAA--------- AAAAAAAAAAAAAAA-------- AAAAAAAAAAAAAAA-------- -AAAAAAAAAAAAA--------- -BBBBBBBBBBBBB--------- --BBBBBBBBBBB---------- ---BBBBBBBBB----------- ---BBBBBBBBB----------- ----BBBBBBB------------ -----BBBBB------------- -----BBBBB------------- -----BBBBB------------- ----BBBBBBB------------ ----BBBBBBB------------ -----DDDDD------------- ----DDDDDDD------------ -------E-E------------- -------E-EE------------ -------E--EE----------- ------CCC--EE---------- -----CCCCC--EE------EEE -----CCCCC---EE----EE-- -----CCCCC----EE--EE--- ----CCCCCCC----EEEE---- ----CCCCCCC------------ ----CCCCCCC------------ ----CCCCCCC------------ -----CGFGC------------- 
---BBBBBBBBB----------- --AAAAAAAAAAA---------- -AAAAAAAAAAAAA--------- -AAAAAAAAAAAAA--------- AAAAAAAAAAAAAAA-------- AAAAAAAAAAAAAAA-------- -AAAAAAAAAAAAA--------- -BBBBBBBBBBBBB--------- --BBBBBBBBBBB---------- ---BBBBBBBBB----------- ---BBBBBBBBB----------- ----BBBBBBB------------ -----BBBBB------------- -----BBBBB------------- -----BBBBB------------- ----BBBBBBB------------ ----BBBBBBB------------ -----DDDDD------------- ----DDDDDDD------------ ----------------------- ----------------------- ----------------------- ------CCC-------------- -----CCCCC------------- -----CCCCC------------- -----CCCCC------------- ----CCCCCCC------------ ----CCCCCCC------------ ----CCCCCCC------------ ----CCCCCCC------------ -----CFFGC------------- 
---BBBBBBBBB----------- --AAAAAAAAAAA---------- -AAAAAAAAAAAAA--------- -AAAAAAAAAAAAA--------- AAAAAAAAAAAAAAA-------- AAAAAAAAAAAAAAA-------- -AAAAAAAAAAAAA--------- -BBBBBBBBBBBBB--------- --BBBBBBBBBBB---------- ---BBBBBBBBB----------- ---BBBBBBBBB----------- -----BBBBB------------- ------BBB-------------- ------BBB-------------- ------BBB-------------- -----BBBBB------------- -----BBBBB------------- ------DDD-------------- -----DDDDD------------- ----------------------- ----------------------- ----------------------- ----------------------- ------CCC-------------- ------CCC-------------- ------CCC-------------- -----CCCCC------------- -----CCCCC------------- -----CCCCC------------- -----CCCCC------------- ------CCC-------------- 
----BBBBBBB------------ ---AAAAAAAAA----------- --AAAAAAAAAAA---------- --AAAAAAAAAAA---------- -AAAAAAAAAAAAA--------- -AAAAAAAAAAAAA--------- --AAAAAAAAAAA---------- --BBBBBBBBBBB---------- ---BBBBBBBBB----------- ----BBBBBBB------------ ----BBBBBBB------------ ------BBB-------------- ----------------------- ----------------------- ----------------------- ------BBB-------------- ------BBB-------------- ----------------------- ------DDD-------------- ----------------------- ----------------------- ----------------------- ----------------------- ----------------------- ----------------------- ----------------------- ------CCC-------------- ------CCC-------------- ------CCC-------------- ------CCC-------------- ----------------------- 
-----BBBBB------------- ----AAAAAAA------------ --AAAAAAAAAAA---------- --AAAAAAAAAAA---------- -AAAAAAAAAAAAA--------- -AAAAAAAAAAAAA--------- --AAAAAAAAAAA---------- --BBBBBBBBBBB---------- ----BBBBBBB------------ -----BBBBB------------- -----BBBBB------------- ----------------------- ----------------------- ----------------------- ----------------------- ----------------------- ----------------------- ----------------------- ----------------------- ----------------------- ----------------------- ----------------------- ----------------------- ----------------------- ----------------------- ----------------------- ----------------------- ----------------------- ----------------------- ----------------------- ----------------------- 
----------------------- -----AAAAA------------- ---AAAAAAAAA----------- ---AAAAAAAAA----------- --AAAAAAAAAAA---------- --AAAAAAAAAAA---------- ---AAAAAAAAA----------- ---BBBBBBBBB----------- -----BBBBB------------- ----------------------- ----------------------- ----------------------- ----------------------- ----------------------- ----------------------- ----------------------- ----------------------- ----------------------- ----------------------- ----------------------- ----------------------- ----------------------- ----------------------- ----------------------- ----------------------- ----------------------- ----------------------- ----------------------- ----------------------- ----------------------- ----------------------- 
----------------------- ----------------------- -----AAAAA------------- -----AAAAA------------- ---AAAAAAAAA----------- ---AAAAAAAAA----------- -----AAAAA------------- -----BBBBB------------- ----------------------- ----------------------- ----------------------- ----------------------- ----------------------- ----------------------- ----------------------- ----------------------- ----------------------- ----------------------- ----------------------- ----------------------- ----------------------- ----------------------- ----------------------- ----------------------- ----------------------- ----------------------- ----------------------- ----------------------- ----------------------- ----------------------- ----------------------- 
----------------------- ----------------------- ----------------------- ----------------------- -----AAAAA------------- -----AAAAA------------- ----------------------- ----------------------- ----------------------- ----------------------- ----------------------- ----------------------- ----------------------- ----------------------- ----------------------- ----------------------- ----------------------- ----------------------- ----------------------- ----------------------- ----------------------- ----------------------- ----------------------- ----------------------- ----------------------- ----------------------- ----------------------- ----------------------- ----------------------- ----------------------- ----------------------- 
