model
size = 30 29 9, scale = 0.05, origin = -y
material 
  colors = A:#555 B:#444 C:#111
voxels
------------------------------ ------------------------------ ------------------------------ ------------------------------ --------------------------CC-- ---------A----------------CCC- --------AA----------------CCA- --------AA-------------------A -------AAA------------------A- --------AAAA----------------A- ---------AAAAA-------------A-- -----------AAA------------AA-- ---------------AAA-------AA--- ---------------AAA------AA---- ----------------AAA---AAA----- -----------------AA-AAAA------ ------------------AA-AA------- ---------------B-------------- ---------------BBB------------ ----------------BBB----------- -----------------BBB---------- -----------------BBBB--------- ------------------BBBB-------- -------------------BBB-------- --------------------BBB------- ----------------------B------- ------------------------------ ------------------------------ ------------------------------ 
----------CC------------------ ----------CCC----------------- ----------AA------------------ ---------AA------------------- --------AA----------------CC-- --B-----AA----------------CCC- --BB----AA-----------------CAA ---BB--AAA------------------AA ---BBBBAAAAA---------------AA- ----BBBAAAAAAAA------------A-- -----BBAAAAAAAAAAAAA------AA-- ------BB-AAAAAAAAAAA-----AA--- ----------AAAAAAAAAAA---AAA--- -----------AAAAAAAAAAA-AAA---- -----------BBBAAAAAAAAAAA----- ------------BBBAAAAAAAAAA----- -------------BBBAAAAAAAA------ --------------BBBAAAAAAA------ ---------------BBBBAAAA------- ---------------BBBBAAAA------- ----------------BBBAAAA----AA- ----------------BBBAAAA---AAA- -----------------BAAAAAAAAAA-- -----------------BBAAAAAACA--- ------------------BBAAAAAA---- -------------------BBBAB------ --------------------BBB------- ----------------------B------- ----------------------B------- 
----------CC------------------ ----------CCC----------------- ----------A------------------- -BB------A-------------------- BBB-----AA-------------------- BBBB----AA-------------------- -BBBB-AAAAA------------------- --BBB-AAAAAAA----------------- --BBBBAAAAAAAAAA-------------- ---BBBAAAAAAAAAAAA------------ ---BBBAAAAAAAAAAAAAA---------- ----BBBAAAAAAAAAAAAAA--------- -----BB-AAAAAAAAAAAAAA-------- ---------AAAAAAAAAAAAAA------- ----------BAAAAAAAAAAAAAA----- -----------BBAAAAAAAAAAAA----- -------------BAAAAAAAAAAA----- --------------BAAAAAAAAAA----- --------------BBAAAAAAAA------ --------------BBBAAAAAAA---AA- --------------BBBAAAAAAA--AAAA ---------------BBAAAAAAA-AAAAA ---------------BBAAAAAAAAAAAA- ---------------BBBAAAAAAAAAA-- -------------BBBBBBAAAAAAAA--- ----------------BBBAAAAAAA---- ------------------BBABBB------ --------------------B-B------- ------------------------------ 
------------------------------ ------------------------------ ------------------------------ -B---------------------------- -BB--------------------------- -BBB----A--------------------- -BBBB-AAAAA------------------- --BBB-AAAAAAA----------------- --BBBBAAAAAAAAAA-------------- ---BBBAAAAAAAAAAAA------------ ---BBBAAAAAAAAAAAAAA---------- ----BBBAAAAAAAAAAAAAA--------- -----BB-AAAAAAAAAAAAAA-------- ---------AAAAAAAAAAAAAAA------ -----------AAAAAAAAAAAAAA----- -----------BBAAAAAAAAAAAA----- -------------BAAAAAAAAAAA----- --------------BAAAAAAAAAA----- ---------------BAAAAAAAA------ --------------BBBAAAAAAA---AA- --------------BBBAAAAAAA--AAAA ---------------BBAAAAAAA-AAAAA ---------------BBAAAAAAAAAAAA- ---------------BBBAAAAAAAAAA-- -------------BBBBBBAAAAAAAA--- ----------------BBBAAAAAAA---- ------------------BBABBB------ --------------------B-B------- ------------------------------ 
------------------------------ ------------------------------ ------------------------------ ------------------------------ ------------------------------ -BB--------------------------- --BB-------------------------- --BB---AAA-------------------- ---BBB-AAAAA------------------ ----BB-AAAAAAAA--------------- ----BB-AAAAAAAAAAAAA---A------ -----BBB-AAAAAAAAAAA--A------- ------BB--AAAAAAAAAAA--------- -----------AAAAAAAAAAA-------- --------------AAAAAAAAA------- ---------------AAAAAAAA------- ----------------AAAAAAA------- --------------BBBAAAAAA------- ---------------BBBBAAAA------- ---------------BBBBAAAA------- ----------------BBBAAAA----AA- ----------------BBBAAAA---AAA- -----------------BAAAAAAAAAA-- -----------------BBAAAAAACA--- ------------------BBAAAAAA---- -------------------BBBAB------ --------------------BBB------- ----------------------B------- ----------------------B------- 
------------------------------ ------------------------------ ------------------------------ ------------------------------ ------------------------------ ----------A------------------- ---------A-A--------------CC-- -------A-A----------------AA-- -------AAA---------------AA--- ---------AA-------------AA---- -----B---AAAA-AA------AAAA---- -----------AAAAAA----AAA------ ------------AAAAAA--AAA------- -------------AAAAAAAAA-------- ----------------AAAAA--------- -----------------AAAA--------- ------------------AAAA-------- ---------------BB---AA-------- ----------------BB------------ -----------------BB----------- -----------------BBA---------- ------------------BAAA-------- ------------------BBAA-------- -------------------BB--------- -------------------BBB-------- --------------------B-B------- ------------------------------ ------------------------------ ------------------------------ 
------------------------------ ------------------------------ ----------C------------------- ----------A------------------- ----------AA------------------ ----------AA------------------ ---------AAA--------------CC-- --------AAAA--------------AA-- --------AAA--------------AA--- ---------A--AA----------AAA--- ----------AAAA---------AA----- ------------A-A-------A------- -------------AAA-----A-------- ----------------AA--A--------- ------------------AA---------- -------------------A---------- ------------------------------ ------------------------------ ------------------------------ ------------------------------ ------------------------------ ------------------------------ ------------------------------ ------------------------------ ------------------------------ ------------------------------ ------------------------------ ------------------------------ ------------------------------ 
------------------------------ ------------------------------ ----------CC------------------ ----------AA------------------ ----------AA------------------ ----------A------------------- ----------A------------------- --------AAA------------------- ---------A-------------------- ------------------------------ ------------------------------ ------------------------------ ------------------------------ ------------------------------ ------------------------------ ------------------------------ ------------------------------ ------------------------------ ------------------------------ ------------------------------ ------------------------------ ------------------------------ ------------------------------ ------------------------------ ------------------------------ ------------------------------ ------------------------------ ------------------------------ ------------------------------ 
------------------------------ ------------------------------ ------------------------------ ------------------------------ ----------A------------------- ------------------------------ ------------------------------ ------------------------------ ------------------------------ ------------------------------ ------------------------------ ------------------------------ ------------------------------ ------------------------------ ------------------------------ ------------------------------ ------------------------------ ------------------------------ ------------------------------ ------------------------------ ------------------------------ ------------------------------ ------------------------------ ------------------------------ ------------------------------ ------------------------------ ------------------------------ ------------------------------ ------------------------------ 
