model
size = 30 30 9, scale = 0.05, origin = -y
material 
  colors = A:#DDD B:#636 C:#111 D:#6F6 E:#9CF F:#FF6 G:#06C H:#F60 I:#F33 J:#BBB
voxels
------------------------------ ------------------------------ ------------------------------ ------------------------------ --------------------------CC-- ---------A----------------CCC- --------AA----------------CCA- --------AA-------------------A -------AAA------------------A- --------AAAA----------------A- ---------AAAAA-------------A-- -----------AAA------------AA-- ---------------AAA-------AA--- ---------------AAA------AA---- ----------------AAA---AAA----- -----------------AA-AAAA------ ------------------AA-AA------- ---------------G-------------- ---------------GGG------------ ----------------GGG----------- -----------------GGG---------- -----------------GGGG--------- ------------------GGGG-------- -------------------GGG-------- --------------------GGG------- ----------------------G------- ------------------------------ ------------------------------ ------------------------------ ------------------------------ 
----------CC------------------ ----------CCC----------------- ----------AA------------------ ---------AA------------------- --------AA----------------CC-- --B-----AA----------------CCC- --BB----AA-----------------CAA ---BB--AAA------------------AA ---BBBBAAAAA---------------AA- ----BBBAAAAAAAA------------A-- -----BBAAAAAAAAAAAAA------AA-- ------BB-AAAAAAAAAAA-----AA--- ----------AAAAAAAAAAA---AAA--- -----------AAAAAAAAAAA-AAA---- -----------EEEAAAAAAAAAAA----- ------------EEEAAAAAAAAAA----- -------------EEEAAAAAAAA------ --------------EBEAAAAAAA------ ---------------EBBEAAAA------- ---------------EBBBAAAA------- ----------------EBBAAAA----AA- ----------------EBBAAAA---AAA- -----------------EAAAAAAAAAA-- -----------------EEAAAAAACA--- ------------------EEAAAAAA---- -------------------EEEAE------ --------------------EEE------- ------------------------------ ------------------------------ ------------------------------ 
----------CC------------------ ----------CCC----------------- ----------A------------------- -BB------A-------------------- BBB-----AA-------------------- BBBB----AA-------------------- -BBBB-AAAAA------------------- --BBB-AAAAAAA----------------- --BBBBAAAAAAAAAA-------------- ---BBBAAAAAAAAAAAA------------ ---BBBAAAAAAAAAAAAAA---------- ----BBBAAAAAAAAAAAAAA--------- -----BB-AAAAAAAAAAAAAA-------- ---------AAAAAAAAAAAAAA------- ----------DAAAAAAAAAAAAAA----- -----------DDAAAAAAAAAAAA----- -------------DAAAAAAAAAAA----- --------------DAAAAAAAAAA----- --------------DBAAAAAAAA------ --------------DBBAAAAAAA---AA- --------------DDBAAAAAAA--AAAA ---------------DBAAAAAAA-AAAAA ---------------DDAAAAAAAAAAAA- ---------------DDBAAAAAAAAAA-- -------------DDDDDBAAAAAAAA--- ----------------DDDAAAAAAA---- ------------------DDADBD-J---- --------------------D-D------- ------------------------------ ------------------------------ 
------------------------------ ------------------------------ ------------------------------ -B---------------------------- -BB--------------------------- -BBB----A--------------------- -BBBB-AAAAA------------------- --BBB-AAAAAAA----------------- --BBBBAAAAAAAAAA-------------- ---BBBAAAAAAAAAAAA------------ ---BBBAAAAAAAAAAAAAA---------- ----BBBAAAAAAAAAAAAAA--------- -----BB-AAAAAAAAAAAAAA-------- ---------AAAAAAAAAAAAAAA------ -----------AAAAAAAAAAAAAA----- -----------FFAAAAAAAAAAAA----- -------------FAAAAAAAAAAA----- --------------FAAAAAAAAAA----- ---------------FAAAAAAAA------ --------------FBBAAAAAAA---AA- --------------FFBAAAAAAA--AAAA ---------------FBAAAAAAA-AAAAA ---------------FFAAAAAAAAAAAA- ---------------FFBAAAAAAAAAA-- -------------FFFFFBAAAAAAAA--- ----------------FFFAAAAAAJ---- ------------------FFAFBFJJ---- --------------------F-F--JJ--- --------------------------J--- --------------------------J--- 
------------------------------ ------------------------------ ------------------------------ ------------------------------ ------------------------------ -BB--------------------------- --BB-------------------------- --BB---AAA-------------------- ---BBB-AAAAA------------------ ----BB-AAAAAAAA--------------- ----BB-AAAAAAAAAAAAA---A------ -----BBB-AAAAAAAAAAA--A------- ------BB--AAAAAAAAAAA--------- -----------AAAAAAAAAAA-------- --------------AAAAAAAAA------- ---------------AAAAAAAA------- ----------------AAAAAAA------- --------------HBBAAAAAA------- ---------------HBBHAAAA------- ---------------HHBBAAAA------- ----------------HBBAAAA----AA- ----------------HHBAAAA---AAA- -----------------HAAAAAAAAAA-- -----------------HHAAAAAACA--- ------------------HBAAAAAA---- -------------------HBHAH------ --------------------HHH------- ----------------------H------- ------------------------------ ------------------------------ 
------------------------------ ------------------------------ ------------------------------ ------------------------------ ------------------------------ ----------A------------------- ---------A-A--------------CC-- -------A-A----------------AA-- -------AAA---------------AA--- ---------AA-------------AA---- -----B---AAAA-AA------AAAA---- -----------AAAAAA----AAA------ ------------AAAAAA--AAA------- -------------AAAAAAAAA-------- ----------------AAAAA--------- -----------------AAAA--------- ------------------AAAA-------- ---------------II---AA-------- ----------------II------------ -----------------II----------- -----------------IIA---------- ------------------IAAA-------- ------------------IIAA-------- -------------------II--------- -------------------III-------- --------------------I-I------- ------------------------------ ------------------------------ ------------------------------ ------------------------------ 
------------------------------ ------------------------------ ----------C------------------- ----------A------------------- ----------AA------------------ ----------AA------------------ ---------AAA--------------CC-- --------AAAA--------------AA-- --------AAA--------------AA--- ---------A--AA----------AAA--- ----------AAAA---------AA----- ------------A-A-------A------- -------------AAA-----A-------- ----------------AA--A--------- ------------------AA---------- -------------------A---------- ------------------------------ ------------------------------ ------------------------------ ------------------------------ ------------------------------ ------------------------------ ------------------------------ ------------------------------ ------------------------------ ------------------------------ ------------------------------ ------------------------------ ------------------------------ ------------------------------ 
------------------------------ ------------------------------ ----------CC------------------ ----------AA------------------ ----------AA------------------ ----------A------------------- ----------A------------------- --------AAA------------------- ---------A-------------------- ------------------------------ ------------------------------ ------------------------------ ------------------------------ ------------------------------ ------------------------------ ------------------------------ ------------------------------ ------------------------------ ------------------------------ ------------------------------ ------------------------------ ------------------------------ ------------------------------ ------------------------------ ------------------------------ ------------------------------ ------------------------------ ------------------------------ ------------------------------ ------------------------------ 
------------------------------ ------------------------------ ------------------------------ ------------------------------ ----------A------------------- ------------------------------ ------------------------------ ------------------------------ ------------------------------ ------------------------------ ------------------------------ ------------------------------ ------------------------------ ------------------------------ ------------------------------ ------------------------------ ------------------------------ ------------------------------ ------------------------------ ------------------------------ ------------------------------ ------------------------------ ------------------------------ ------------------------------ ------------------------------ ------------------------------ ------------------------------ ------------------------------ ------------------------------ ------------------------------ 
