model
size = 30 29 9, scale = 0.05, origin = -y
material 
  colors = A:#636 B:#111
voxels
------------------------------ ------------------------------ ------------------------------ ------------------------------ --------------------------BB-- ---------A----------------BBB- --------AA----------------BBA- --------AA-------------------A -------AAA------------------A- --------AAAA----------------A- ---------AAAAA-------------A-- -----------AAA------------AA-- ---------------AAA-------AA--- ---------------AAA------AA---- ----------------AAA---AAA----- -----------------AA-AAAA------ ------------------AA-AA------- ---------------B-------------- ---------------BBB------------ ----------------BBB----------- -----------------BBB---------- -----------------BBBB--------- ------------------BBBB-------- -------------------BBB-------- --------------------BBB------- ----------------------B------- ------------------------------ ------------------------------ ------------------------------ 
----------BB------------------ ----------BBB----------------- ----------AA------------------ ---------AA------------------- --------AA----------------BB-- --B-----AA----------------BBB- --BB----AA-----------------BAA ---BB--AAA------------------AA ---BBBBAAAAA---------------AA- ----BBBAAAAAAAA------------A-- -----BBAAAAAAAAAAAAA------AA-- ------BB-AAAAAAAAAAA-----AA--- ----------AAAAAAAAAAA---AAA--- -----------AAAAAAAAAAA-AAA---- -----------BBBAAAAAAAAAAA----- ------------BBBAAAAAAAAAA----- -------------BBBAAAAAAAA------ --------------BBBAAAAAAA------ ---------------BBBBAAAA------- ---------------BBBBAAAA------- ----------------BBBAAAA----AA- ----------------BBBAAAA---AAA- -----------------BAAAAAAAAAA-- -----------------BBAAAAAABA--- ------------------BBAAAAAA---- -------------------BBBAB------ --------------------BBB------- ----------------------B------- ----------------------B------- 
----------BB------------------ ----------BBB----------------- ----------A------------------- -BB------A-------------------- BBB-----AA-------------------- BBBB----AA-------------------- -BBBB-AAAAA------------------- --BBB-AAAAAAA----------------- --BBBBAAAAAAAAAA-------------- ---BBBAAAAAAAAAAAA------------ ---BBBAAAAAAAAAAAAAA---------- ----BBBAAAAAAAAAAAAAA--------- -----BB-AAAAAAAAAAAAAA-------- ---------AAAAAAAAAAAAAA------- ----------BAAAAAAAAAAAAAA----- -----------BBAAAAAAAAAAAA----- -------------BAAAAAAAAAAA----- --------------BAAAAAAAAAA----- --------------BBAAAAAAAA------ --------------BBBAAAAAAA---AA- --------------BBBAAAAAAA--AAAA ---------------BBAAAAAAA-AAAAA ---------------BBAAAAAAAAAAAA- ---------------BBBAAAAAAAAAA-- -------------BBBBBBAAAAAAAA--- ----------------BBBAAAAAAA---- ------------------BBABBB------ --------------------B-B------- ------------------------------ 
------------------------------ ------------------------------ ------------------------------ -B---------------------------- -BB--------------------------- -BBB----A--------------------- -BBBB-AAAAA------------------- --BBB-AAAAAAA----------------- --BBBBAAAAAAAAAA-------------- ---BBBAAAAAAAAAAAA------------ ---BBBAAAAAAAAAAAAAA---------- ----BBBAAAAAAAAAAAAAA--------- -----BB-AAAAAAAAAAAAAA-------- ---------AAAAAAAAAAAAAAA------ -----------AAAAAAAAAAAAAA----- -----------BBAAAAAAAAAAAA----- -------------BAAAAAAAAAAA----- --------------BAAAAAAAAAA----- ---------------BAAAAAAAA------ --------------BBBAAAAAAA---AA- --------------BBBAAAAAAA--AAAA ---------------BBAAAAAAA-AAAAA ---------------BBAAAAAAAAAAAA- ---------------BBBAAAAAAAAAA-- -------------BBBBBBAAAAAAAA--- ----------------BBBAAAAAAA---- ------------------BBABBB------ --------------------B-B------- ------------------------------ 
------------------------------ ------------------------------ ------------------------------ ------------------------------ ------------------------------ -BB--------------------------- --BB-------------------------- --BB---AAA-------------------- ---BBB-AAAAA------------------ ----BB-AAAAAAAA--------------- ----BB-AAAAAAAAAAAAA---A------ -----BBB-AAAAAAAAAAA--A------- ------BB--AAAAAAAAAAA--------- -----------AAAAAAAAAAA-------- --------------AAAAAAAAA------- ---------------AAAAAAAA------- ----------------AAAAAAA------- --------------BBBAAAAAA------- ---------------BBBBAAAA------- ---------------BBBBAAAA------- ----------------BBBAAAA----AA- ----------------BBBAAAA---AAA- -----------------BAAAAAAAAAA-- -----------------BBAAAAAABA--- ------------------BBAAAAAA---- -------------------BBBAB------ --------------------BBB------- ----------------------B------- ----------------------B------- 
------------------------------ ------------------------------ ------------------------------ ------------------------------ ------------------------------ ----------A------------------- ---------A-A--------------BB-- -------A-A----------------AA-- -------AAA---------------AA--- ---------AA-------------AA---- -----B---AAAA-AA------AAAA---- -----------AAAAAA----AAA------ ------------AAAAAA--AAA------- -------------AAAAAAAAA-------- ----------------AAAAA--------- -----------------AAAA--------- ------------------AAAA-------- ---------------BB---AA-------- ----------------BB------------ -----------------BB----------- -----------------BBA---------- ------------------BAAA-------- ------------------BBAA-------- -------------------BB--------- -------------------BBB-------- --------------------B-B------- ------------------------------ ------------------------------ ------------------------------ 
------------------------------ ------------------------------ ----------B------------------- ----------A------------------- ----------AA------------------ ----------AA------------------ ---------AAA--------------BB-- --------AAAA--------------AA-- --------AAA--------------AA--- ---------A--AA----------AAA--- ----------AAAA---------AA----- ------------A-A-------A------- -------------AAA-----A-------- ----------------AA--A--------- ------------------AA---------- -------------------A---------- ------------------------------ ------------------------------ ------------------------------ ------------------------------ ------------------------------ ------------------------------ ------------------------------ ------------------------------ ------------------------------ ------------------------------ ------------------------------ ------------------------------ ------------------------------ 
------------------------------ ------------------------------ ----------BB------------------ ----------AA------------------ ----------AA------------------ ----------A------------------- ----------A------------------- --------AAA------------------- ---------A-------------------- ------------------------------ ------------------------------ ------------------------------ ------------------------------ ------------------------------ ------------------------------ ------------------------------ ------------------------------ ------------------------------ ------------------------------ ------------------------------ ------------------------------ ------------------------------ ------------------------------ ------------------------------ ------------------------------ ------------------------------ ------------------------------ ------------------------------ ------------------------------ 
------------------------------ ------------------------------ ------------------------------ ------------------------------ ----------A------------------- ------------------------------ ------------------------------ ------------------------------ ------------------------------ ------------------------------ ------------------------------ ------------------------------ ------------------------------ ------------------------------ ------------------------------ ------------------------------ ------------------------------ ------------------------------ ------------------------------ ------------------------------ ------------------------------ ------------------------------ ------------------------------ ------------------------------ ------------------------------ ------------------------------ ------------------------------ ------------------------------ ------------------------------ 
