model
size = 30 29 9, scale = 0.05, origin = -y
material 
  colors = A:#A00 B:#070 C:#111 D:#960
voxels
------------------------------ ------------------------------ ------------------------------ ------------------------------ --------------------------CC-- ---------A----------------CCC- --------AA----------------CCA- --------DA-------------------A -------AAA------------------A- --------AAAA----------------A- ---------ADAAA-------------A-- -----------AAA------------AA-- ---------------AAD-------AA--- ---------------AAA------DA---- ----------------AAA---AAA----- -----------------DA-AAAA------ ------------------AA-AA------- ---------------B-------------- ---------------BBB------------ ----------------BBB----------- -----------------BBB---------- -----------------BBBB--------- ------------------BBBB-------- -------------------BBB-------- --------------------BBB------- ----------------------B------- ------------------------------ ------------------------------ ------------------------------ 
----------CC------------------ ----------CCC----------------- ----------AA------------------ ---------AD------------------- --------AA----------------CC-- --B-----AA----------------CCC- --BB----AA-----------------CAA ---BB--AAA------------------AA ---BBBBAAAAA---------------AA- ----BBBAAAAAAAD------------A-- -----BBAAAAAAAAAAAAA------AA-- ------BB-AAAAAAAAADA-----AA--- ----------AAAAAAAAAAA---AAA--- -----------AADAAAAAAAA-AAA---- -----------BBBAAAAAAAAAAA----- ------------BBBAAAAAAAAAA----- -------------BBBAAAAAAAA------ --------------BBBAAAADAA------ ---------------BBBBAAAA------- ---------------BBBBAAAA------- ----------------BBBAADA----AA- ----------------BBBAAAA---AAA- -----------------BAAAAAAAAAA-- -----------------BBAAAAAACA--- ------------------BBAAAAAA---- -------------------BBBAB------ --------------------BBB------- ----------------------B------- ----------------------B------- 
----------CC------------------ ----------CCC----------------- ----------A------------------- -BB------A-------------------- BBB-----AA-------------------- BBBB----AA-------------------- -BBBB-AAAAA------------------- --BBB-AAAAAAA----------------- --BBBBAAAAAAAAAA-------------- ---BBBAAAAAAAAAAAA------------ ---BBBAAAAAAAAAAAAAA---------- ----BBBAAAAAAAAAAAAAA--------- -----BB-AAAAAAAAAAAAAA-------- ---------AAAAAAAAAAAAAA------- ----------BAAAAAAAAAAAAAA----- -----------BBAAAAAAAAAAAA----- -------------BAAAAAAAAAAA----- --------------BAAAAAAAAAA----- --------------BBAAAAAAAA------ --------------BBBAAAAAAA---AA- --------------BBBAAAAAAA--AAAD ---------------BBAAAAAAA-AAAAA ---------------BBAAAAAAAAAAAA- ---------------BBBAAAAAAAAAA-- -------------BBBBBBAAAAAAAA--- ----------------BBBAAAAAAA---- ------------------BBABBB------ --------------------B-B------- ------------------------------ 
------------------------------ ------------------------------ ------------------------------ -B---------------------------- -BB--------------------------- -BBB----A--------------------- -BBBB-AAAAA------------------- --BBB-AAAAAAA----------------- --BBBBAAAAAAAAAA-------------- ---BBBAAAAAAAAAAAA------------ ---BBBAAAAAAAAAAAAAA---------- ----BBBAAAAAAAAAAAAAA--------- -----BB-AAAAAAAAAAAAAA-------- ---------AAAAAAAAAAAAAAA------ -----------AAAAAAAAAAAAAA----- -----------BBAAAAAAAAAAAA----- -------------BAAAAAAAAAAA----- --------------BAAAAAAAAAA----- ---------------BAAAAAAAA------ --------------BBBAAAAAAA---AA- --------------BBBAAAAAAA--AAAA ---------------BBAAAAAAA-AAAAA ---------------BBAAAAAAAAAAAA- ---------------BBBAAAAAAAAAA-- -------------BBBBBBAAAAAAAD--- ----------------BBBAAAAAAA---- ------------------BBABBB------ --------------------B-B------- ------------------------------ 
------------------------------ ------------------------------ ------------------------------ ------------------------------ ------------------------------ -BB--------------------------- --BB-------------------------- --BB---AAA-------------------- ---BBB-AAAAA------------------ ----BB-AAAAAAAA--------------- ----BB-AAAAAAAAAADAA---A------ -----BBB-AAAAAAAAAAA--A------- ------BB--AAAAAAAAAAA--------- -----------AAAAAAAAAAA-------- --------------AAAAAAADA------- ---------------AAAAAAAA------- ----------------AAAAAAA------- --------------BBBAAAAAA------- ---------------BBBBAAAD------- ---------------BBBBAAAA------- ----------------BBBAAAA----AA- ----------------BBBAAAA---AAA- -----------------BAAAAAAAAAA-- -----------------BBAAAAAACA--- ------------------BBAAAAAA---- -------------------BBBAB------ --------------------BBB------- ----------------------B------- ----------------------B------- 
------------------------------ ------------------------------ ------------------------------ ------------------------------ ------------------------------ ----------A------------------- ---------A-A--------------CC-- -------A-A----------------AA-- -------AAA---------------AA--- ---------AA-------------AA---- -----B---AAAA-AA------AAAA---- -----------AAAAAA----AAD------ ------------DAAAAA--AAA------- -------------AAAAAAAAA-------- ----------------ADAAA--------- -----------------AAAA--------- ------------------AAAA-------- ---------------BB---AA-------- ----------------BB------------ -----------------BB----------- -----------------BBA---------- ------------------BAAA-------- ------------------BBAA-------- -------------------BB--------- -------------------BBB-------- --------------------B-B------- ------------------------------ ------------------------------ ------------------------------ 
------------------------------ ------------------------------ ----------C------------------- ----------A------------------- ----------AA------------------ ----------AA------------------ ---------AAA--------------CC-- --------AAAA--------------AA-- --------DAA--------------AD--- ---------A--DA----------AAA--- ----------AAAA---------AA----- ------------A-A-------A------- -------------AAA-----A-------- ----------------AA--A--------- ------------------AA---------- -------------------A---------- ------------------------------ ------------------------------ ------------------------------ ------------------------------ ------------------------------ ------------------------------ ------------------------------ ------------------------------ ------------------------------ ------------------------------ ------------------------------ ------------------------------ ------------------------------ 
------------------------------ ------------------------------ ----------CC------------------ ----------AA------------------ ----------AA------------------ ----------D------------------- ----------A------------------- --------AAA------------------- ---------A-------------------- ------------------------------ ------------------------------ ------------------------------ ------------------------------ ------------------------------ ------------------------------ ------------------------------ ------------------------------ ------------------------------ ------------------------------ ------------------------------ ------------------------------ ------------------------------ ------------------------------ ------------------------------ ------------------------------ ------------------------------ ------------------------------ ------------------------------ ------------------------------ 
------------------------------ ------------------------------ ------------------------------ ------------------------------ ----------A------------------- ------------------------------ ------------------------------ ------------------------------ ------------------------------ ------------------------------ ------------------------------ ------------------------------ ------------------------------ ------------------------------ ------------------------------ ------------------------------ ------------------------------ ------------------------------ ------------------------------ ------------------------------ ------------------------------ ------------------------------ ------------------------------ ------------------------------ ------------------------------ ------------------------------ ------------------------------ ------------------------------ ------------------------------ 
