model
size = 12 6 28, scale = 0.05, origin = -y
material 
  colors = A:#212689 B:#F7F7F7 C:#FFF
voxels
--AAAAA----- ------------ ------------ ------------ ------------ ------------ 
-AAAAAAAA--- ------------ ------------ ------------ ------------ ------------ 
AAAAAAAAAA-- ------------ ------------ ------------ ------------ ------------ 
AAAAAAAAAAA- ------------ ------------ ------------ ------------ ------------ 
AAAAAAAAAAA- ------------ ------------ ------------ ------------ ------------ 
AAAAAAAAAAAA ------------ ------------ ------------ ------------ ------------ 
AAAAAAAAAAAA B----------B B----------B BB--------BB -BBBBBBBBBB- ------------ 
AAAAAAAAAAAA B----------B B----------B BB--------BB -BBBBBBBBBB- ------------ 
AAAAAAAAAAAA A----------A A----------A AA--------AA -AAAAAAAAAA- ------------ 
AAAAAAAAAAAA A----------A A----------A AA--------AA -AAAAAAAAAA- ------------ 
AAAAAAAAAAAA B----------B B----------B B----------B BB--------BB -BBBBBBBBBB- 
AAAAAAAAAAAA B----------B B----------B B----------B CB--------BC -CCCCCCCCCC- 
AAAAAAAAAAAA A----------A A----------A A----------A AA--------AA -AAAAAAAAAA- 
AAAAAAAAAAAA A----------A A----------A A----------A AA--------AA -AAAAAAAAAA- 
AAAAAAAAAAAA B----------B B----------B B----------B BB--------BB -BBBBBBBBBB- 
AAAAAAAAAAAA B----------B B----------B B----------B BB--------BB -BBBBBBBBBB- 
AAAAAAAAAAAA ------------ ------------ ------------ ------------ ------------ 
AAAAAAAAAAAA ------------ ------------ ------------ ------------ ------------ 
AAAAAAAAAAAA ------------ ------------ ------------ ------------ ------------ 
AAAAAAAAAAAA ------------ ------------ ------------ ------------ ------------ 
AAAAAAAAAAAA ------------ ------------ ------------ ------------ ------------ 
AAAAAAAAAAAA ------------ ------------ ------------ ------------ ------------ 
AAAAAAAAAAAA ------------ ------------ ------------ ------------ ------------ 
AAAAAAAAAAAA ------------ ------------ ------------ ------------ ------------ 
-AAAAAAAAAAA ------------ ------------ ------------ ------------ ------------ 
-AAAAAAAAAA- ------------ ------------ ------------ ------------ ------------ 
--AAAAAAAA-- ------------ ------------ ------------ ------------ ------------ 
---AAAAAA--- ------------ ------------ ------------ ------------ ------------ 
