model
size = 22 30 19, scale = 0.05, origin = -y
material 
  colors = A:#F70 B:#FFDADA C:#1C1C1C
voxels
--------C----C-------- --------C----C-------- --------C----C-------- --------C----C-------- --------C----C-------- --------C----C-------- --------C----C-------- --------C----C-------- --------C----C-------- --------C----C-------- --------C----C-------- --------C----C-------- --------C----C-------- --------C----C-------- --------C----C-------- --------C----C-------- --------C----C-------- --------C----C-------- --------C----C-------- --------C----C-------- ---------------------- ---------------------- ---------------------- ---------------------- ---------------------- ---------------------- ---------------------- ---------------------- ---------------------- ---------------------- 
-----CCC------CCC----- -----AAA------AAA----- -----AAA------AAA----- -----AAA------AAA----- -----BBB------BBB----- -----BBB------BBB----- -----AAA------AAA----- -----AAA------AAA----- -----AAA------AAA----- -----AAA------AAA----- -----AAA------AAA----- -----BBB------BBB----- -----BBB------BBB----- -----AAA------AAA----- -----AAA------AAA----- -----AAA------AAA----- -----AAA------AAA----- -----AAA------AAA----- -----AAA------AAA----- -----AAA------AAA----- -----AAAC----CAAA----- -----AAAC----CAAA----- -----AAAC----CAAA----- ---------------------- ---------------------- ---------------------- ---------------------- ---------------------- ---------------------- ---------------------- 
---CC------------CC--- ---AA------------AA--- ---AA------------AA--- ---AA------------AA--- ---BB------------BB--- ---BB------------BB--- ---AA------------AA--- ---AA------------AA--- ---AA------------AA--- ---AA------------AA--- ---AA------------AA--- ---BB------------BB--- ---BB------------BB--- ---BB------------BB--- ---BB------------BB--- ---BB------------BB--- ---BB------------BB--- ---BB------------BB--- ---BB------------BB--- ---BB------------BB--- ---BB------------BB--- ---BB------------BB--- ---BB------------BB--- ---BBAAAC----CAAABB--- ---------------------- ---------------------- ---------------------- ---------------------- ---------------------- ---------------------- 
--C----------------C-- --A----------------A-- --A----------------A-- --A----------------A-- --B----------------B-- --B----------------B-- --A----------------A-- --A----------------A-- --A----------------A-- --A----------------A-- --A----------------A-- --B----------------B-- --B----------------B-- --A----------------A-- --A----------------A-- --A----------------A-- --A----------------A-- --A----------------A-- --A----------------A-- --A----------------A-- --A----------------A-- --A----------------A-- --A----------------A-- --A----------------A-- ---BBAAC------CAABB--- ---------------------- ---------------------- ---------------------- ---------------------- ---------------------- 
-C------------------C- -A------------------A- -A------------------A- -A------------------A- -B------------------B- -B------------------B- -A------------------A- -A------------------A- -A------------------A- -A------------------A- -A------------------A- -B------------------B- -B------------------B- -A------------------A- -A------------------A- -A------------------A- -A------------------A- -A------------------A- -A------------------A- -A------------------A- -A------------------A- -A------------------A- -A------------------A- -A------------------A- --AB--------------BA-- ----BAAC------CAAB---- -----A----------A----- ---------------------- ---------------------- ---------------------- 
-C------------------C- -A------------------A- -A------------------A- -A------------------A- -B------------------B- -B------------------B- -A------------------A- -A------------------A- -A------------------A- -A------------------A- -A------------------A- -B------------------B- -B------------------B- -A------------------A- -A------------------A- -A------------------A- -A------------------A- -A------------------A- -A------------------A- -A------------------A- -C------------------C- -C------------------C- -C------------------C- -C------------------C- -AAA--------------AAA- ---B--------------B--- ----BAAC------CAAB---- ------A--------A------ ---------------------- ---------------------- 
C--------------------C A--------------------A A--------------------A A--------------------A B--------------------B B--------------------B A--------------------A A--------------------A A--------------------A A--------------------A A--------------------A B--------------------B B--------------------B A--------------------A A--------------------A A--------------------A A--------------------A A--------------------A A--------------------A C--------------------C ---------------------- ---------------------- ---------------------- ---------------------- -C------------------C- --AA--------------AA-- ---BB------------BB--- -----A-C------C-A----- ------C--------C------ ---------------------- 
C--------------------C A--------------------A A--------------------A A--------------------A B--------------------B B--------------------B A--------------------A A--------------------A A--------------------A A--------------------A A--------------------A B--------------------B B--------------------B A--------------------A A--------------------A A--------------------A A--------------------A A--------------------A C--------------------C ---------------------- ---------------------- ---------------------- ---------------------- ---------------------- ---------------------- --C----------------C-- ---B--------------B--- ----BA----------AB---- ------C--------C------ ---------------------- 
C--------------------C A--------------------A A--------------------A A--------------------A B--------------------B B--------------------B A--------------------A A--------------------A A--------------------A A--------------------A A--------------------A B--------------------B B--------------------B A--------------------A A--------------------A A--------------------A A--------------------A A--------------------A C--------------------C ---------------------- ---------------------- ---------------------- ---------------------- ---------------------- ---------------------- --C----------------C-- ---B--------------B--- ----B------------B---- -----C----------C----- ---------------------- 
C--------------------C A--------------------A A--------------------A A--------------------A B--------------------B B--------------------B A--------------------A A--------------------A A--------------------A A--------------------A A--------------------A B--------------------B B--------------------B A--------------------A A--------------------A A--------------------A A--------------------A A--------------------A C--------------------C ---------------------- ---------------------- ---------------------- ---------------------- ---------------------- ---------------------- --C----------------C-- ---B--------------B--- ----B------------B---- -----C----------C----- ---------------------- 
C--------------------C A--------------------A A--------------------A A--------------------A B--------------------B B--------------------B A--------------------A A--------------------A A--------------------A A--------------------A A--------------------A B--------------------B B--------------------B A--------------------A A--------------------A A--------------------A A--------------------A A--------------------A C--------------------C ---------------------- ---------------------- ---------------------- ---------------------- ---------------------- ---------------------- --C----------------C-- ---B--------------B--- ----B------------B---- -----C----------C----- ---------------------- 
C--------------------C A--------------------A A--------------------A A--------------------A B--------------------B B--------------------B A--------------------A A--------------------A A--------------------A A--------------------A A--------------------A B--------------------B B--------------------B A--------------------A A--------------------A A--------------------A A--------------------A A--------------------A C--------------------C ---------------------- ---------------------- ---------------------- ---------------------- ---------------------- ---------------------- --C----------------C-- ---B--------------B--- ----B------------B---- -----C----------C----- ---------------------- 
C--------------------C A--------------------A A--------------------A A--------------------A B--------------------B B--------------------B A--------------------A A--------------------A A--------------------A A--------------------A A--------------------A B--------------------B B--------------------B A--------------------A A--------------------A A--------------------A A--------------------A A--------------------A A--------------------A C--------------------C ---------------------- ---------------------- ---------------------- ---------------------- -C------------------C- --A----------------A-- ---B--------------B--- ----B------------B---- -----A----------A----- ------C--------C------ 
-C------------------C- -A------------------A- -A------------------A- -A------------------A- -B------------------B- -B------------------B- -A------------------A- -A------------------A- -A------------------A- -A------------------A- -A------------------A- -B------------------B- -B------------------B- -A------------------A- -A------------------A- -A------------------A- -A------------------A- -A------------------A- -A------------------A- -A------------------A- -C------------------C- -C------------------C- -C------------------C- -C------------------C- -A------------------A- --A----------------A-- ---B--------------B--- ----B------------B---- -----AA--------AA----- ------C--------C------ 
-C------------------C- -A------------------A- -A------------------A- -A------------------A- -B------------------B- -B------------------B- -A------------------A- -A------------------A- -A------------------A- -A------------------A- -A------------------A- -B------------------B- -B------------------B- -A------------------A- -A------------------A- -A------------------A- -A------------------A- -A------------------A- -A------------------A- -A------------------A- -A------------------A- -A------------------A- -A------------------A- -A------------------A- -A------------------A- --A----------------A-- ---B--------------B--- ----BA----------AB---- ------AA------AA------ -------C------C------- 
--C----------------C-- --A----------------A-- --A----------------A-- --A----------------A-- --B----------------B-- --B----------------B-- --A----------------A-- --A----------------A-- --A----------------A-- --A----------------A-- --A----------------A-- --B----------------B-- --B----------------B-- --A----------------A-- --A----------------A-- --A----------------A-- --A----------------A-- --A----------------A-- --A----------------A-- --A----------------A-- --A----------------A-- --A----------------A-- --A----------------A-- --A----------------A-- --A----------------A-- ---B--------------B--- ----BA----------AB---- -----AAAAAAAAAAAA----- -------AAAAAAAA------- --------CCCCCC-------- 
---CC------------CC--- ---AA------------AA--- ---AA------------AA--- ---AA------------AA--- ---BB------------BB--- ---BB------------BB--- ---AA------------AA--- ---AA------------AA--- ---AA------------AA--- ---AA------------AA--- ---AA------------AA--- ---BB------------BB--- ---BB------------BB--- ---BB------------BB--- ---BB------------BB--- ---BB------------BB--- ---BB------------BB--- ---BB------------BB--- ---BB------------BB--- ---BB------------BB--- ---BB------------BB--- ---BB------------BB--- ---BB------------BB--- ---BB------------BB--- ---BB------------BB--- ----BA----------AB---- -----AAAAAAAAAAAA----- ------AAAAAAAAAA------ ---------------------- ---------------------- 
-----CCCCCCCCCCCC----- -----AAAAAAAAAAAA----- -----AAAAAAAAAAAA----- -----AAAAAAAAAAAA----- -----BBBBBBBBBBBB----- -----BBBBBBBBBBBB----- -----AAAAAAAAAAAA----- -----AAAAAAAAAAAA----- -----AAAAAAAAAAAA----- -----AAAAAAAAAAAA----- -----AAAAAAAAAAAA----- -----BBBBBBBBBBBB----- -----BBBBBBBBBBBB----- -----AAAAAAAAAAAA----- -----AAAAAAAAAAAA----- -----AAAAAAAAAAAA----- -----AAAAAAAAAAAA----- -----AAAAAAAAAAAA----- -----AAAAAAAAAAAA----- -----AAAAAAAAAAAA----- -----AAAAAAAAAAAA----- -----AAAAAAAAAAAA----- -----AAAAAAAAAAAA----- -----AAAAAAAAAAAA----- -----AAAAAAAAAAAA----- ------AAAAAAAAAA------ -------AAAAAAAA------- ---------------------- ---------------------- ---------------------- 
---------------------- ------AAAAAAAAAA------ ------AAAAAAAAAA------ ------AAAAAAAAAA------ ------BBBBBBBBBB------ ------BBBBBBBBBB------ ------AAAAAAAAAA------ ------AAAAAAAAAA------ ------AAAAAAAAAA------ ------AAAAAAAAAA------ ------AAAAAAAAAA------ ------BBBBBBBBBB------ ------BBBBBBBBBB------ ------AAAAAAAAAA------ ------AAAAAAAAAA------ ------AAAAAAAAAA------ ------AAAAAAAAAA------ ------AAAAAAAAAA------ ------AAAAAAAAAA------ ------AAAAAAAAAA------ ------AAAAAAAAAA------ ------AAAAAAAAAA------ ------AAAAAAAAAA------ ------AAAAAAAAAA------ ------AAAAAAAAAA------ -------AAAAAAAA------- ---------------------- ---------------------- ---------------------- ---------------------- 
