model
size = 31, scale = 0.05, origin = -y
material 
  colors = A:#040202 B:#FCFCFC C:#FEFB00 D:#0303FF E:#03FF03 F:#FF8B03 G:#FF0303
voxels
AAAAAAAAAAAAAAAAAAAAAAAAAAAAAAA AEEEEEEEEEAEEEEEEEEEAEEEEEEEEEA AEEEEEEEEEAEEEEEEEEEAEEEEEEEEEA AEEEEEEEEEAEEEEEEEEEAEEEEEEEEEA AEEEEEEEEEAEEEEEEEEEAEEEEEEEEEA AEEEEEEEEEAEEEEEEEEEAEEEEEEEEEA AEEEEEEEEEAEEEEEEEEEAEEEEEEEEEA AEEEEEEEEEAEEEEEEEEEAEEEEEEEEEA AEEEEEEEEEAEEEEEEEEEAEEEEEEEEEA AEEEEEEEEEAEEEEEEEEEAEEEEEEEEEA AAAAAAAAAAAAAAAAAAAAAAAAAAAAAAA AEEEEEEEEEAEEEEEEEEEAEEEEEEEEEA AEEEEEEEEEAEEEEEEEEEAEEEEEEEEEA AEEEEEEEEEAEEEEEEEEEAEEEEEEEEEA AEEEEEEEEEAEEEEEEEEEAEEEEEEEEEA AEEEEEEEEEAEEEEEEEEEAEEEEEEEEEA AEEEEEEEEEAEEEEEEEEEAEEEEEEEEEA AEEEEEEEEEAEEEEEEEEEAEEEEEEEEEA AEEEEEEEEEAEEEEEEEEEAEEEEEEEEEA AEEEEEEEEEAEEEEEEEEEAEEEEEEEEEA AAAAAAAAAAAAAAAAAAAAAAAAAAAAAAA AEEEEEEEEEAEEEEEEEEEAEEEEEEEEEA AEEEEEEEEEAEEEEEEEEEAEEEEEEEEEA AEEEEEEEEEAEEEEEEEEEAEEEEEEEEEA AEEEEEEEEEAEEEEEEEEEAEEEEEEEEEA AEEEEEEEEEAEEEEEEEEEAEEEEEEEEEA AEEEEEEEEEAEEEEEEEEEAEEEEEEEEEA AEEEEEEEEEAEEEEEEEEEAEEEEEEEEEA AEEEEEEEEEAEEEEEEEEEAEEEEEEEEEA AEEEEEEEEEAEEEEEEEEEAEEEEEEEEEA AAAAAAAAAAAAAAAAAAAAAAAAAAAAAAA 
ACCCCCCCCCACCCCCCCCCACCCCCCCCCA FCCCCCCCCCACCCCCCCCCACCCCCCCCCG FCCCCCCCCCACCCCCCCCCACCCCCCCCCG FCCCCCCCCCACCCCCCCCCACCCCCCCCCG FCCCCCCCCCACCCCCCCCCACCCCCCCCCG FFFFFEEEEEAEEEEEEEEEAEEEEEEEEEG FFFFFEEEEEAEEEEEEEEEAEEEEEEEEEG FFFFFEEEEEAEEEEEEEEEAEEEEEEEEEG FFFFFEEEEEAEEEEEEEEEAEEEEEEEEEG FFFFFEEEEEAEEEEEEEEEAEEEEEEEEEG AAAAAAAAAAAAAAAAAAAAAAAAAAAAAAA FFFFFEEEEEAEEEEEEEEEAEEEEEEEEEG FFFFFEEEEEAEEEEEEEEEAEEEEEEEEEG FFFFFEEEEEAEEEEEEEEEAEEEEEEEEEG FFFFFEEEEEAEEEEEEEEEAEEEEEEEEEG FFFFFEEEEEAEEEEEEEEEAEEEEEEEEEG FFFFFEEEEEAEEEEEEEEEAEEEEEEEEEG FFFFFEEEEEAEEEEEEEEEAEEEEEEEEEG FFFFFEEEEEAEEEEEEEEEAEEEEEEEEEG FFFFFEEEEEAEEEEEEEEEAEEEEEEEEEG AAAAAAAAAAAAAAAAAAAAAAAAAAAAAAA FFFFFEEEEEAEEEEEEEEEAEEEEEEEEEG FFFFFEEEEEAEEEEEEEEEAEEEEEEEEEG FFFFFEEEEEAEEEEEEEEEAEEEEEEEEEG FFFFFEEEEEAEEEEEEEEEAEEEEEEEEEG FFFFFEEEEEAEEEEEEEEEAEEEEEEEEEG FBBBBBBBBBABBBBBBBBBABBBBBBBBBG FBBBBBBBBBABBBBBBBBBABBBBBBBBBG FBBBBBBBBBABBBBBBBBBABBBBBBBBBG FBBBBBBBBBABBBBBBBBBABBBBBBBBBG ABBBBBBBBBABBBBBBBBBABBBBBBBBBA 
ACCCCCCCCCACCCCCCCCCACCCCCCCCCA FCCCCCCCCCACCCCCCCCCACCCCCCCCCG FCCCCCCCCCACCCCCCCCCACCCCCCCCCG FCCCCCCCCCACCCCCCCCCACCCCCCCCCG FCCCCCCCCCACCCCCCCCCACCCCCCCCCG FFFFFEEEEEAEEEEEEEEEAEEEEEEEEEG FFFFFEEEEEAEEEEEEEEEAEEEEEEEEEG FFFFFEEEEEAEEEEEEEEEAEEEEEEEEEG FFFFFEEEEEAEEEEEEEEEAEEEEEEEEEG FFFFFEEEEEAEEEEEEEEEAEEEEEEEEEG AAAAAAAAAAAAAAAAAAAAAAAAAAAAAAA FFFFFEEEEEAEEEEEEEEEAEEEEEEEEEG FFFFFEEEEEAEEEEEEEEEAEEEEEEEEEG FFFFFEEEEEAEEEEEEEEEAEEEEEEEEEG FFFFFEEEEEAEEEEEEEEEAEEEEEEEEEG FFFFFEEEEEAEEEEEEEEEAEEEEEEEEEG FFFFFEEEEEAEEEEEEEEEAEEEEEEEEEG FFFFFEEEEEAEEEEEEEEEAEEEEEEEEEG FFFFFEEEEEAEEEEEEEEEAEEEEEEEEEG FFFFFEEEEEAEEEEEEEEEAEEEEEEEEEG AAAAAAAAAAAAAAAAAAAAAAAAAAAAAAA FFFFFEEEEEAEEEEEEEEEAEEEEEEEEEG FFFFFEEEEEAEEEEEEEEEAEEEEEEEEEG FFFFFEEEEEAEEEEEEEEEAEEEEEEEEEG FFFFFEEEEEAEEEEEEEEEAEEEEEEEEEG FFFFFEEEEEAEEEEEEEEEAEEEEEEEEEG FBBBBBBBBBABBBBBBBBBABBBBBBBBBG FBBBBBBBBBABBBBBBBBBABBBBBBBBBG FBBBBBBBBBABBBBBBBBBABBBBBBBBBG FBBBBBBBBBABBBBBBBBBABBBBBBBBBG ABBBBBBBBBABBBBBBBBBABBBBBBBBBA 
ACCCCCCCCCACCCCCCCCCACCCCCCCCCA FCCCCCCCCCACCCCCCCCCACCCCCCCCCG FCCCCCCCCCACCCCCCCCCACCCCCCCCCG FCCCCCCCCCACCCCCCCCCACCCCCCCCCG FCCCCCCCCCACCCCCCCCCACCCCCCCCCG FFFFFEEEEEAEEEEEEEEEAEEEEEEEEEG FFFFFEEEEEAEEEEEEEEEAEEEEEEEEEG FFFFFEEEEEAEEEEEEEEEAEEEEEEEEEG FFFFFEEEEEAEEEEEEEEEAEEEEEEEEEG FFFFFEEEEEAEEEEEEEEEAEEEEEEEEEG AAAAAAAAAAAAAAAAAAAAAAAAAAAAAAA FFFFFEEEEEAEEEEEEEEEAEEEEEEEEEG FFFFFEEEEEAEEEEEEEEEAEEEEEEEEEG FFFFFEEEEEAEEEEEEEEEAEEEEEEEEEG FFFFFEEEEEAEEEEEEEEEAEEEEEEEEEG FFFFFEEEEEAEEEEEEEEEAEEEEEEEEEG FFFFFEEEEEAEEEEEEEEEAEEEEEEEEEG FFFFFEEEEEAEEEEEEEEEAEEEEEEEEEG FFFFFEEEEEAEEEEEEEEEAEEEEEEEEEG FFFFFEEEEEAEEEEEEEEEAEEEEEEEEEG AAAAAAAAAAAAAAAAAAAAAAAAAAAAAAA FFFFFEEEEEAEEEEEEEEEAEEEEEEEEEG FFFFFEEEEEAEEEEEEEEEAEEEEEEEEEG FFFFFEEEEEAEEEEEEEEEAEEEEEEEEEG FFFFFEEEEEAEEEEEEEEEAEEEEEEEEEG FFFFFEEEEEAEEEEEEEEEAEEEEEEEEEG FBBBBBBBBBABBBBBBBBBABBBBBBBBBG FBBBBBBBBBABBBBBBBBBABBBBBBBBBG FBBBBBBBBBABBBBBBBBBABBBBBBBBBG FBBBBBBBBBABBBBBBBBBABBBBBBBBBG ABBBBBBBBBABBBBBBBBBABBBBBBBBBA 
ACCCCCCCCCACCCCCCCCCACCCCCCCCCA FCCCCCCCCCACCCCCCCCCACCCCCCCCCG FCCCCCCCCCACCCCCCCCCACCCCCCCCCG FCCCCCCCCCACCCCCCCCCACCCCCCCCCG FCCCCCCCCCACCCCCCCCCACCCCCCCCCG FFFFFEEEEEAEEEEEEEEEAEEEEEEEEEG FFFFFEEEEEAEEEEEEEEEAEEEEEEEEEG FFFFFEEEEEAEEEEEEEEEAEEEEEEEEEG FFFFFEEEEEAEEEEEEEEEAEEEEEEEEEG FFFFFEEEEEAEEEEEEEEEAEEEEEEEEEG AAAAAAAAAAAAAAAAAAAAAAAAAAAAAAA FFFFFEEEEEAEEEEEEEEEAEEEEEEEEEG FFFFFEEEEEAEEEEEEEEEAEEEEEEEEEG FFFFFEEEEEAEEEEEEEEEAEEEEEEEEEG FFFFFEEEEEAEEEEEEEEEAEEEEEEEEEG FFFFFEEEEEAEEEEEEEEEAEEEEEEEEEG FFFFFEEEEEAEEEEEEEEEAEEEEEEEEEG FFFFFEEEEEAEEEEEEEEEAEEEEEEEEEG FFFFFEEEEEAEEEEEEEEEAEEEEEEEEEG FFFFFEEEEEAEEEEEEEEEAEEEEEEEEEG AAAAAAAAAAAAAAAAAAAAAAAAAAAAAAA FFFFFEEEEEAEEEEEEEEEAEEEEEEEEEG FFFFFEEEEEAEEEEEEEEEAEEEEEEEEEG FFFFFEEEEEAEEEEEEEEEAEEEEEEEEEG FFFFFEEEEEAEEEEEEEEEAEEEEEEEEEG FFFFFEEEEEAEEEEEEEEEAEEEEEEEEEG FBBBBBBBBBABBBBBBBBBABBBBBBBBBG FBBBBBBBBBABBBBBBBBBABBBBBBBBBG FBBBBBBBBBABBBBBBBBBABBBBBBBBBG FBBBBBBBBBABBBBBBBBBABBBBBBBBBG ABBBBBBBBBABBBBBBBBBABBBBBBBBBA 
ACCCCCCCCCACCCCCCCCCACCCCCCCCCA FCCCCCCCCCACCCCCCCCCACCCCCCCCCG FCCCCCCCCCACCCCCCCCCACCCCCCCCCG FCCCCCCCCCACCCCCCCCCACCCCCCCCCG FCCCCCCCCCACCCCCCCCCACCCCCCCCCG FFFFFAAAAAAAAAAAAAAAAAAAAAGGGGG FFFFFAAAAAAAAAAAAAAAAAAAAAGGGGG FFFFFAAAAAAAAAAAAAAAAAAAAAGGGGG FFFFFAAAAAAAAAAAAAAAAAAAAAGGGGG FFFFFAAAAAAAAAAAAAAAAAAAAAGGGGG AAAAAAAAAAAAAAAAAAAAAAAAAAAAAAA FFFFFAAAAAAAAAAAAAAAAAAAAAGGGGG FFFFFAAAAAAAAAAAAAAAAAAAAAGGGGG FFFFFAAAAAAAAAAAAAAAAAAAAAGGGGG FFFFFAAAAAAAAAAAAAAAAAAAAAGGGGG FFFFFAAAAAAAAAAAAAAAAAAAAAGGGGG FFFFFAAAAAAAAAAAAAAAAAAAAAGGGGG FFFFFAAAAAAAAAAAAAAAAAAAAAGGGGG FFFFFAAAAAAAAAAAAAAAAAAAAAGGGGG FFFFFAAAAAAAAAAAAAAAAAAAAAGGGGG AAAAAAAAAAAAAAAAAAAAAAAAAAAAAAA FFFFFAAAAAAAAAAAAAAAAAAAAAGGGGG FFFFFAAAAAAAAAAAAAAAAAAAAAGGGGG FFFFFAAAAAAAAAAAAAAAAAAAAAGGGGG FFFFFAAAAAAAAAAAAAAAAAAAAAGGGGG FFFFFAAAAAAAAAAAAAAAAAAAAAGGGGG FBBBBBBBBBABBBBBBBBBABBBBBBBBBG FBBBBBBBBBABBBBBBBBBABBBBBBBBBG FBBBBBBBBBABBBBBBBBBABBBBBBBBBG FBBBBBBBBBABBBBBBBBBABBBBBBBBBG ABBBBBBBBBABBBBBBBBBABBBBBBBBBA 
ACCCCCCCCCACCCCCCCCCACCCCCCCCCA FCCCCCCCCCACCCCCCCCCACCCCCCCCCG FCCCCCCCCCACCCCCCCCCACCCCCCCCCG FCCCCCCCCCACCCCCCCCCACCCCCCCCCG FCCCCCCCCCACCCCCCCCCACCCCCCCCCG FFFFFAAAAAAAAAAAAAAAAAAAAAGGGGG FFFFFAAAAAAAAAAAAAAAAAAAAAGGGGG FFFFFAAAAAAAAAAAAAAAAAAAAAGGGGG FFFFFAAAAAAAAAAAAAAAAAAAAAGGGGG FFFFFAAAAAAAAAAAAAAAAAAAAAGGGGG AAAAAAAAAAAAAAAAAAAAAAAAAAAAAAA FFFFFAAAAAAAAAAAAAAAAAAAAAGGGGG FFFFFAAAAAAAAAAAAAAAAAAAAAGGGGG FFFFFAAAAAAAAAAAAAAAAAAAAAGGGGG FFFFFAAAAAAAAAAAAAAAAAAAAAGGGGG FFFFFAAAAAAAAAAAAAAAAAAAAAGGGGG FFFFFAAAAAAAAAAAAAAAAAAAAAGGGGG FFFFFAAAAAAAAAAAAAAAAAAAAAGGGGG FFFFFAAAAAAAAAAAAAAAAAAAAAGGGGG FFFFFAAAAAAAAAAAAAAAAAAAAAGGGGG AAAAAAAAAAAAAAAAAAAAAAAAAAAAAAA FFFFFAAAAAAAAAAAAAAAAAAAAAGGGGG FFFFFAAAAAAAAAAAAAAAAAAAAAGGGGG FFFFFAAAAAAAAAAAAAAAAAAAAAGGGGG FFFFFAAAAAAAAAAAAAAAAAAAAAGGGGG FFFFFAAAAAAAAAAAAAAAAAAAAAGGGGG FBBBBBBBBBABBBBBBBBBABBBBBBBBBG FBBBBBBBBBABBBBBBBBBABBBBBBBBBG FBBBBBBBBBABBBBBBBBBABBBBBBBBBG FBBBBBBBBBABBBBBBBBBABBBBBBBBBG ABBBBBBBBBABBBBBBBBBABBBBBBBBBA 
ACCCCCCCCCACCCCCCCCCACCCCCCCCCA FCCCCCCCCCACCCCCCCCCACCCCCCCCCG FCCCCCCCCCACCCCCCCCCACCCCCCCCCG FCCCCCCCCCACCCCCCCCCACCCCCCCCCG FCCCCCCCCCACCCCCCCCCACCCCCCCCCG FFFFFAAAAAAAAAAAAAAAAAAAAAGGGGG FFFFFAAAAAAAAAAAAAAAAAAAAAGGGGG FFFFFAAAAAAAAAAAAAAAAAAAAAGGGGG FFFFFAAAAAAAAAAAAAAAAAAAAAGGGGG FFFFFAAAAAAAAAAAAAAAAAAAAAGGGGG AAAAAAAAAAAAAAAAAAAAAAAAAAAAAAA FFFFFAAAAAAAAAAAAAAAAAAAAAGGGGG FFFFFAAAAAAAAAAAAAAAAAAAAAGGGGG FFFFFAAAAAAAAAAAAAAAAAAAAAGGGGG FFFFFAAAAAAAAAAAAAAAAAAAAAGGGGG FFFFFAAAAAAAAAAAAAAAAAAAAAGGGGG FFFFFAAAAAAAAAAAAAAAAAAAAAGGGGG FFFFFAAAAAAAAAAAAAAAAAAAAAGGGGG FFFFFAAAAAAAAAAAAAAAAAAAAAGGGGG FFFFFAAAAAAAAAAAAAAAAAAAAAGGGGG AAAAAAAAAAAAAAAAAAAAAAAAAAAAAAA FFFFFAAAAAAAAAAAAAAAAAAAAAGGGGG FFFFFAAAAAAAAAAAAAAAAAAAAAGGGGG FFFFFAAAAAAAAAAAAAAAAAAAAAGGGGG FFFFFAAAAAAAAAAAAAAAAAAAAAGGGGG FFFFFAAAAAAAAAAAAAAAAAAAAAGGGGG FBBBBBBBBBABBBBBBBBBABBBBBBBBBG FBBBBBBBBBABBBBBBBBBABBBBBBBBBG FBBBBBBBBBABBBBBBBBBABBBBBBBBBG FBBBBBBBBBABBBBBBBBBABBBBBBBBBG ABBBBBBBBBABBBBBBBBBABBBBBBBBBA 
ACCCCCCCCCACCCCCCCCCACCCCCCCCCA FCCCCCCCCCACCCCCCCCCACCCCCCCCCG FCCCCCCCCCACCCCCCCCCACCCCCCCCCG FCCCCCCCCCACCCCCCCCCACCCCCCCCCG FCCCCCCCCCACCCCCCCCCACCCCCCCCCG FFFFFAAAAAAAAAAAAAAAAAAAAAGGGGG FFFFFAAAAAAAAAAAAAAAAAAAAAGGGGG FFFFFAAAAAAAAAAAAAAAAAAAAAGGGGG FFFFFAAAAAAAAAAAAAAAAAAAAAGGGGG FFFFFAAAAAAAAAAAAAAAAAAAAAGGGGG AAAAAAAAAAAAAAAAAAAAAAAAAAAAAAA FFFFFAAAAAAAAAAAAAAAAAAAAAGGGGG FFFFFAAAAAAAAAAAAAAAAAAAAAGGGGG FFFFFAAAAAAAAAAAAAAAAAAAAAGGGGG FFFFFAAAAAAAAAAAAAAAAAAAAAGGGGG FFFFFAAAAAAAAAAAAAAAAAAAAAGGGGG FFFFFAAAAAAAAAAAAAAAAAAAAAGGGGG FFFFFAAAAAAAAAAAAAAAAAAAAAGGGGG FFFFFAAAAAAAAAAAAAAAAAAAAAGGGGG FFFFFAAAAAAAAAAAAAAAAAAAAAGGGGG AAAAAAAAAAAAAAAAAAAAAAAAAAAAAAA FFFFFAAAAAAAAAAAAAAAAAAAAAGGGGG FFFFFAAAAAAAAAAAAAAAAAAAAAGGGGG FFFFFAAAAAAAAAAAAAAAAAAAAAGGGGG FFFFFAAAAAAAAAAAAAAAAAAAAAGGGGG FFFFFAAAAAAAAAAAAAAAAAAAAAGGGGG FBBBBBBBBBABBBBBBBBBABBBBBBBBBG FBBBBBBBBBABBBBBBBBBABBBBBBBBBG FBBBBBBBBBABBBBBBBBBABBBBBBBBBG FBBBBBBBBBABBBBBBBBBABBBBBBBBBG ABBBBBBBBBABBBBBBBBBABBBBBBBBBA 
ACCCCCCCCCACCCCCCCCCACCCCCCCCCA FCCCCCCCCCACCCCCCCCCACCCCCCCCCG FCCCCCCCCCACCCCCCCCCACCCCCCCCCG FCCCCCCCCCACCCCCCCCCACCCCCCCCCG FCCCCCCCCCACCCCCCCCCACCCCCCCCCG FFFFFAAAAAAAAAAAAAAAAAAAAAGGGGG FFFFFAAAAAAAAAAAAAAAAAAAAAGGGGG FFFFFAAAAAAAAAAAAAAAAAAAAAGGGGG FFFFFAAAAAAAAAAAAAAAAAAAAAGGGGG FFFFFAAAAAAAAAAAAAAAAAAAAAGGGGG AAAAAAAAAAAAAAAAAAAAAAAAAAAAAAA FFFFFAAAAAAAAAAAAAAAAAAAAAGGGGG FFFFFAAAAAAAAAAAAAAAAAAAAAGGGGG FFFFFAAAAAAAAAAAAAAAAAAAAAGGGGG FFFFFAAAAAAAAAAAAAAAAAAAAAGGGGG FFFFFAAAAAAAAAAAAAAAAAAAAAGGGGG FFFFFAAAAAAAAAAAAAAAAAAAAAGGGGG FFFFFAAAAAAAAAAAAAAAAAAAAAGGGGG FFFFFAAAAAAAAAAAAAAAAAAAAAGGGGG FFFFFAAAAAAAAAAAAAAAAAAAAAGGGGG AAAAAAAAAAAAAAAAAAAAAAAAAAAAAAA FFFFFAAAAAAAAAAAAAAAAAAAAAGGGGG FFFFFAAAAAAAAAAAAAAAAAAAAAGGGGG FFFFFAAAAAAAAAAAAAAAAAAAAAGGGGG FFFFFAAAAAAAAAAAAAAAAAAAAAGGGGG FFFFFAAAAAAAAAAAAAAAAAAAAAGGGGG FBBBBBBBBBABBBBBBBBBABBBBBBBBBG FBBBBBBBBBABBBBBBBBBABBBBBBBBBG FBBBBBBBBBABBBBBBBBBABBBBBBBBBG FBBBBBBBBBABBBBBBBBBABBBBBBBBBG ABBBBBBBBBABBBBBBBBBABBBBBBBBBA 
AAAAAAAAAAAAAAAAAAAAAAAAAAAAAAA AAAAAAAAAAAAAAAAAAAAAAAAAAAAAAA AAAAAAAAAAAAAAAAAAAAAAAAAAAAAAA AAAAAAAAAAAAAAAAAAAAAAAAAAAAAAA AAAAAAAAAAAAAAAAAAAAAAAAAAAAAAA AAAAAAAAAAAAAAAAAAAAAAAAAAAAAAA AAAAAAAAAAAAAAAAAAAAAAAAAAAAAAA AAAAAAAAAAAAAAAAAAAAAAAAAAAAAAA AAAAAAAAAAAAAAAAAAAAAAAAAAAAAAA AAAAAAAAAAAAAAAAAAAAAAAAAAAAAAA AAAAAAAAAAAAAAAAAAAAAAAAAAAAAAA AAAAAAAAAAAAAAAAAAAAAAAAAAAAAAA AAAAAAAAAAAAAAAAAAAAAAAAAAAAAAA AAAAAAAAAAAAAAAAAAAAAAAAAAAAAAA AAAAAAAAAAAAAAAAAAAAAAAAAAAAAAA AAAAAAAAAAAAAAAAAAAAAAAAAAAAAAA AAAAAAAAAAAAAAAAAAAAAAAAAAAAAAA AAAAAAAAAAAAAAAAAAAAAAAAAAAAAAA AAAAAAAAAAAAAAAAAAAAAAAAAAAAAAA AAAAAAAAAAAAAAAAAAAAAAAAAAAAAAA AAAAAAAAAAAAAAAAAAAAAAAAAAAAAAA AAAAAAAAAAAAAAAAAAAAAAAAAAAAAAA AAAAAAAAAAAAAAAAAAAAAAAAAAAAAAA AAAAAAAAAAAAAAAAAAAAAAAAAAAAAAA AAAAAAAAAAAAAAAAAAAAAAAAAAAAAAA AAAAAAAAAAAAAAAAAAAAAAAAAAAAAAA AAAAAAAAAAAAAAAAAAAAAAAAAAAAAAA AAAAAAAAAAAAAAAAAAAAAAAAAAAAAAA AAAAAAAAAAAAAAAAAAAAAAAAAAAAAAA AAAAAAAAAAAAAAAAAAAAAAAAAAAAAAA AAAAAAAAAAAAAAAAAAAAAAAAAAAAAAA 
ACCCCCCCCCACCCCCCCCCACCCCCCCCCA FCCCCCCCCCACCCCCCCCCACCCCCCCCCG FCCCCCCCCCACCCCCCCCCACCCCCCCCCG FCCCCCCCCCACCCCCCCCCACCCCCCCCCG FCCCCCCCCCACCCCCCCCCACCCCCCCCCG FFFFFAAAAAAAAAAAAAAAAAAAAAGGGGG FFFFFAAAAAAAAAAAAAAAAAAAAAGGGGG FFFFFAAAAAAAAAAAAAAAAAAAAAGGGGG FFFFFAAAAAAAAAAAAAAAAAAAAAGGGGG FFFFFAAAAAAAAAAAAAAAAAAAAAGGGGG AAAAAAAAAAAAAAAAAAAAAAAAAAAAAAA FFFFFAAAAAAAAAAAAAAAAAAAAAGGGGG FFFFFAAAAAAAAAAAAAAAAAAAAAGGGGG FFFFFAAAAAAAAAAAAAAAAAAAAAGGGGG FFFFFAAAAAAAAAAAAAAAAAAAAAGGGGG FFFFFAAAAAAAAAAAAAAAAAAAAAGGGGG FFFFFAAAAAAAAAAAAAAAAAAAAAGGGGG FFFFFAAAAAAAAAAAAAAAAAAAAAGGGGG FFFFFAAAAAAAAAAAAAAAAAAAAAGGGGG FFFFFAAAAAAAAAAAAAAAAAAAAAGGGGG AAAAAAAAAAAAAAAAAAAAAAAAAAAAAAA FFFFFAAAAAAAAAAAAAAAAAAAAAGGGGG FFFFFAAAAAAAAAAAAAAAAAAAAAGGGGG FFFFFAAAAAAAAAAAAAAAAAAAAAGGGGG FFFFFAAAAAAAAAAAAAAAAAAAAAGGGGG FFFFFAAAAAAAAAAAAAAAAAAAAAGGGGG FBBBBBBBBBABBBBBBBBBABBBBBBBBBG FBBBBBBBBBABBBBBBBBBABBBBBBBBBG FBBBBBBBBBABBBBBBBBBABBBBBBBBBG FBBBBBBBBBABBBBBBBBBABBBBBBBBBG ABBBBBBBBBABBBBBBBBBABBBBBBBBBA 
ACCCCCCCCCACCCCCCCCCACCCCCCCCCA FCCCCCCCCCACCCCCCCCCACCCCCCCCCG FCCCCCCCCCACCCCCCCCCACCCCCCCCCG FCCCCCCCCCACCCCCCCCCACCCCCCCCCG FCCCCCCCCCACCCCCCCCCACCCCCCCCCG FFFFFAAAAAAAAAAAAAAAAAAAAAGGGGG FFFFFAAAAAAAAAAAAAAAAAAAAAGGGGG FFFFFAAAAAAAAAAAAAAAAAAAAAGGGGG FFFFFAAAAAAAAAAAAAAAAAAAAAGGGGG FFFFFAAAAAAAAAAAAAAAAAAAAAGGGGG AAAAAAAAAAAAAAAAAAAAAAAAAAAAAAA FFFFFAAAAAAAAAAAAAAAAAAAAAGGGGG FFFFFAAAAAAAAAAAAAAAAAAAAAGGGGG FFFFFAAAAAAAAAAAAAAAAAAAAAGGGGG FFFFFAAAAAAAAAAAAAAAAAAAAAGGGGG FFFFFAAAAAAAAAAAAAAAAAAAAAGGGGG FFFFFAAAAAAAAAAAAAAAAAAAAAGGGGG FFFFFAAAAAAAAAAAAAAAAAAAAAGGGGG FFFFFAAAAAAAAAAAAAAAAAAAAAGGGGG FFFFFAAAAAAAAAAAAAAAAAAAAAGGGGG AAAAAAAAAAAAAAAAAAAAAAAAAAAAAAA FFFFFAAAAAAAAAAAAAAAAAAAAAGGGGG FFFFFAAAAAAAAAAAAAAAAAAAAAGGGGG FFFFFAAAAAAAAAAAAAAAAAAAAAGGGGG FFFFFAAAAAAAAAAAAAAAAAAAAAGGGGG FFFFFAAAAAAAAAAAAAAAAAAAAAGGGGG FBBBBBBBBBABBBBBBBBBABBBBBBBBBG FBBBBBBBBBABBBBBBBBBABBBBBBBBBG FBBBBBBBBBABBBBBBBBBABBBBBBBBBG FBBBBBBBBBABBBBBBBBBABBBBBBBBBG ABBBBBBBBBABBBBBBBBBABBBBBBBBBA 
ACCCCCCCCCACCCCCCCCCACCCCCCCCCA FCCCCCCCCCACCCCCCCCCACCCCCCCCCG FCCCCCCCCCACCCCCCCCCACCCCCCCCCG FCCCCCCCCCACCCCCCCCCACCCCCCCCCG FCCCCCCCCCACCCCCCCCCACCCCCCCCCG FFFFFAAAAAAAAAAAAAAAAAAAAAGGGGG FFFFFAAAAAAAAAAAAAAAAAAAAAGGGGG FFFFFAAAAAAAAAAAAAAAAAAAAAGGGGG FFFFFAAAAAAAAAAAAAAAAAAAAAGGGGG FFFFFAAAAAAAAAAAAAAAAAAAAAGGGGG AAAAAAAAAAAAAAAAAAAAAAAAAAAAAAA FFFFFAAAAAAAAAAAAAAAAAAAAAGGGGG FFFFFAAAAAAAAAAAAAAAAAAAAAGGGGG FFFFFAAAAAAAAAAAAAAAAAAAAAGGGGG FFFFFAAAAAAAAAAAAAAAAAAAAAGGGGG FFFFFAAAAAAAAAAAAAAAAAAAAAGGGGG FFFFFAAAAAAAAAAAAAAAAAAAAAGGGGG FFFFFAAAAAAAAAAAAAAAAAAAAAGGGGG FFFFFAAAAAAAAAAAAAAAAAAAAAGGGGG FFFFFAAAAAAAAAAAAAAAAAAAAAGGGGG AAAAAAAAAAAAAAAAAAAAAAAAAAAAAAA FFFFFAAAAAAAAAAAAAAAAAAAAAGGGGG FFFFFAAAAAAAAAAAAAAAAAAAAAGGGGG FFFFFAAAAAAAAAAAAAAAAAAAAAGGGGG FFFFFAAAAAAAAAAAAAAAAAAAAAGGGGG FFFFFAAAAAAAAAAAAAAAAAAAAAGGGGG FBBBBBBBBBABBBBBBBBBABBBBBBBBBG FBBBBBBBBBABBBBBBBBBABBBBBBBBBG FBBBBBBBBBABBBBBBBBBABBBBBBBBBG FBBBBBBBBBABBBBBBBBBABBBBBBBBBG ABBBBBBBBBABBAABBABBABBBBBBBBBA 
ACCCCCCCCCACCCCCCCCCACCCCCCCCCA FCCCCCCCCCACCCCCCCCCACCCCCCCCCG FCCCCCCCCCACCCCCCCCCACCCCCCCCCG FCCCCCCCCCACCCCCCCCCACCCCCCCCCG FCCCCCCCCCACCCCCCCCCACCCCCCCCCG FFFFFAAAAAAAAAAAAAAAAAAAAAGGGGG FFFFFAAAAAAAAAAAAAAAAAAAAAGGGGG FFFFFAAAAAAAAAAAAAAAAAAAAAGGGGG FFFFFAAAAAAAAAAAAAAAAAAAAAGGGGG FFFFFAAAAAAAAAAAAAAAAAAAAAGGGGG AAAAAAAAAAAAAAAAAAAAAAAAAAAAAAA FFFFFAAAAAAAAAAAAAAAAAAAAAGGGGG FFFFFAAAAAAAAAAAAAAAAAAAAAGGGGG FFFFFAAAAAAAAAAAAAAAAAAAAAGGGGG FFFFFAAAAAAAAAAAAAAAAAAAAAGGGGG FFFFFAAAAAAAAAAAAAAAAAAAAAGGGGG FFFFFAAAAAAAAAAAAAAAAAAAAAGGGGG FFFFFAAAAAAAAAAAAAAAAAAAAAGGGGG FFFFFAAAAAAAAAAAAAAAAAAAAAGGGGG FFFFFAAAAAAAAAAAAAAAAAAAAAGGGGG AAAAAAAAAAAAAAAAAAAAAAAAAAAAAAA FFFFFAAAAAAAAAAAAAAAAAAAAAGGGGG FFFFFAAAAAAAAAAAAAAAAAAAAAGGGGG FFFFFAAAAAAAAAAAAAAAAAAAAAGGGGG FFFFFAAAAAAAAAAAAAAAAAAAAAGGGGG FFFFFAAAAAAAAAAAAAAAAAAAAAGGGGG FBBBBBBBBBABBBBBBBBBABBBBBBBBBG FBBBBBBBBBABBBBBBBBBABBBBBBBBBG FBBBBBBBBBABBBBBBBBBABBBBBBBBBG FBBBBBBBBBABBBBBBBBBABBBBBBBBBG ABBBBBBBBBABABBBABABABBBBBBBBBA 
ACCCCCCCCCACCCCCCCCCACCCCCCCCCA FCCCCCCCCCACCCCCCCCCACCCCCCCCCG FCCCCCCCCCACCCCCCCCCACCCCCCCCCG FCCCCCCCCCACCCCCCCCCACCCCCCCCCG FCCCCCCCCCACCCCCCCCCACCCCCCCCCG FFFFFAAAAAAAAAAAAAAAAAAAAAGGGGG FFFFFAAAAAAAAAAAAAAAAAAAAAGGGGG FFFFFAAAAAAAAAAAAAAAAAAAAAGGGGG FFFFFAAAAAAAAAAAAAAAAAAAAAGGGGG FFFFFAAAAAAAAAAAAAAAAAAAAAGGGGG AAAAAAAAAAAAAAAAAAAAAAAAAAAAAAA FFFFFAAAAAAAAAAAAAAAAAAAAAGGGGG FFFFFAAAAAAAAAAAAAAAAAAAAAGGGGG FFFFFAAAAAAAAAAAAAAAAAAAAAGGGGG FFFFFAAAAAAAAAAAAAAAAAAAAAGGGGG FFFFFAAAAAAAAAAAAAAAAAAAAAGGGGG FFFFFAAAAAAAAAAAAAAAAAAAAAGGGGG FFFFFAAAAAAAAAAAAAAAAAAAAAGGGGG FFFFFAAAAAAAAAAAAAAAAAAAAAGGGGG FFFFFAAAAAAAAAAAAAAAAAAAAAGGGGG AAAAAAAAAAAAAAAAAAAAAAAAAAAAAAA FFFFFAAAAAAAAAAAAAAAAAAAAAGGGGG FFFFFAAAAAAAAAAAAAAAAAAAAAGGGGG FFFFFAAAAAAAAAAAAAAAAAAAAAGGGGG FFFFFAAAAAAAAAAAAAAAAAAAAAGGGGG FFFFFAAAAAAAAAAAAAAAAAAAAAGGGGG FBBBBBBBBBABBBBBBBBBABBBBBBBBBG FBBBBBBBBBABBBBBBBBBABBBBBBBBBG FBBBBBBBBBABBBBBBBBBABBBBBBBBBG FBBBBBBBBBABBBBBBBBBABBBBBBBBBG ABBBBBBBBBABABBBABABABBBBBBBBBA 
ACCCCCCCCCACCCCCCCCCACCCCCCCCCA FCCCCCCCCCACCCCCCCCCACCCCCCCCCG FCCCCCCCCCACCCCCCCCCACCCCCCCCCG FCCCCCCCCCACCCCCCCCCACCCCCCCCCG FCCCCCCCCCACCCCCCCCCACCCCCCCCCG FFFFFAAAAAAAAAAAAAAAAAAAAAGGGGG FFFFFAAAAAAAAAAAAAAAAAAAAAGGGGG FFFFFAAAAAAAAAAAAAAAAAAAAAGGGGG FFFFFAAAAAAAAAAAAAAAAAAAAAGGGGG FFFFFAAAAAAAAAAAAAAAAAAAAAGGGGG AAAAAAAAAAAAAAAAAAAAAAAAAAAAAAA FFFFFAAAAAAAAAAAAAAAAAAAAAGGGGG FFFFFAAAAAAAAAAAAAAAAAAAAAGGGGG FFFFFAAAAAAAAAAAAAAAAAAAAAGGGGG FFFFFAAAAAAAAAAAAAAAAAAAAAGGGGG FFFFFAAAAAAAAAAAAAAAAAAAAAGGGGG FFFFFAAAAAAAAAAAAAAAAAAAAAGGGGG FFFFFAAAAAAAAAAAAAAAAAAAAAGGGGG FFFFFAAAAAAAAAAAAAAAAAAAAAGGGGG FFFFFAAAAAAAAAAAAAAAAAAAAAGGGGG AAAAAAAAAAAAAAAAAAAAAAAAAAAAAAA FFFFFAAAAAAAAAAAAAAAAAAAAAGGGGG FFFFFAAAAAAAAAAAAAAAAAAAAAGGGGG FFFFFAAAAAAAAAAAAAAAAAAAAAGGGGG FFFFFAAAAAAAAAAAAAAAAAAAAAGGGGG FFFFFAAAAAAAAAAAAAAAAAAAAAGGGGG FBBBBBBBBBABBBBBBBBBABBBBBBBBBG FBBBBBBBBBABBBBBBBBBABBBBBBBBBG FBBBBBBBBBABBBBBBBBBABBBBBBBBBG FBBBBBBBBBABBBBBBBBBABBBBBBBBBG ABBBBBBBBBABABBBABABABBBBBBBBBA 
ACCCCCCCCCACCCCCCCCCACCCCCCCCCA FCCCCCCCCCACCCCCCCCCACCCCCCCCCG FCCCCCCCCCACCCCCCCCCACCCCCCCCCG FCCCCCCCCCACCCCCCCCCACCCCCCCCCG FCCCCCCCCCACCCCCCCCCACCCCCCCCCG FFFFFAAAAAAAAAAAAAAAAAAAAAGGGGG FFFFFAAAAAAAAAAAAAAAAAAAAAGGGGG FFFFFAAAAAAAAAAAAAAAAAAAAAGGGGG FFFFFAAAAAAAAAAAAAAAAAAAAAGGGGG FFFFFAAAAAAAAAAAAAAAAAAAAAGGGGG AAAAAAAAAAAAAAAAAAAAAAAAAAAAAAA FFFFFAAAAAAAAAAAAAAAAAAAAAGGGGG FFFFFAAAAAAAAAAAAAAAAAAAAAGGGGG FFFFFAAAAAAAAAAAAAAAAAAAAAGGGGG FFFFFAAAAAAAAAAAAAAAAAAAAAGGGGG FFFFFAAAAAAAAAAAAAAAAAAAAAGGGGG FFFFFAAAAAAAAAAAAAAAAAAAAAGGGGG FFFFFAAAAAAAAAAAAAAAAAAAAAGGGGG FFFFFAAAAAAAAAAAAAAAAAAAAAGGGGG FFFFFAAAAAAAAAAAAAAAAAAAAAGGGGG AAAAAAAAAAAAAAAAAAAAAAAAAAAAAAA FFFFFAAAAAAAAAAAAAAAAAAAAAGGGGG FFFFFAAAAAAAAAAAAAAAAAAAAAGGGGG FFFFFAAAAAAAAAAAAAAAAAAAAAGGGGG FFFFFAAAAAAAAAAAAAAAAAAAAAGGGGG FFFFFAAAAAAAAAAAAAAAAAAAAAGGGGG FBBBBBBBBBABBBBBBBBBABBBBBBBBBG FBBBBBBBBBABBBBBBBBBABBBBBBBBBG FBBBBBBBBBABBBBBBBBBABBBBBBBBBG FBBBBBBBBBABBBBBBBBBABBBBBBBBBG ABBBBBBBBBABBAABABABABBBBBBBBBA 
ACCCCCCCCCACCCCCCCCCACCCCCCCCCA FCCCCCCCCCACCCCCCCCCACCCCCCCCCG FCCCCCCCCCACCCCCCCCCACCCCCCCCCG FCCCCCCCCCACCCCCCCCCACCCCCCCCCG FCCCCCCCCCACCCCCCCCCACCCCCCCCCG FFFFFAAAAAAAAAAAAAAAAAAAAAGGGGG FFFFFAAAAAAAAAAAAAAAAAAAAAGGGGG FFFFFAAAAAAAAAAAAAAAAAAAAAGGGGG FFFFFAAAAAAAAAAAAAAAAAAAAAGGGGG FFFFFAAAAAAAAAAAAAAAAAAAAAGGGGG AAAAAAAAAAAAAAAAAAAAAAAAAAAAAAA FFFFFAAAAAAAAAAAAAAAAAAAAAGGGGG FFFFFAAAAAAAAAAAAAAAAAAAAAGGGGG FFFFFAAAAAAAAAAAAAAAAAAAAAGGGGG FFFFFAAAAAAAAAAAAAAAAAAAAAGGGGG FFFFFAAAAAAAAAAAAAAAAAAAAAGGGGG FFFFFAAAAAAAAAAAAAAAAAAAAAGGGGG FFFFFAAAAAAAAAAAAAAAAAAAAAGGGGG FFFFFAAAAAAAAAAAAAAAAAAAAAGGGGG FFFFFAAAAAAAAAAAAAAAAAAAAAGGGGG AAAAAAAAAAAAAAAAAAAAAAAAAAAAAAA FFFFFAAAAAAAAAAAAAAAAAAAAAGGGGG FFFFFAAAAAAAAAAAAAAAAAAAAAGGGGG FFFFFAAAAAAAAAAAAAAAAAAAAAGGGGG FFFFFAAAAAAAAAAAAAAAAAAAAAGGGGG FFFFFAAAAAAAAAAAAAAAAAAAAAGGGGG FBBBBBBBBBABBBBBBBBBABBBBBBBBBG FBBBBBBBBBABBBBBBBBBABBBBBBBBBG FBBBBBBBBBABBBBBBBBBABBBBBBBBBG FBBBBBBBBBABBBBBBBBBABBBBBBBBBG ABBBBBBBBBABBBBBBBBBABBBBBBBBBA 
ACCCCCCCCCACCCCCCCCCACCCCCCCCCA FCCCCCCCCCACCCCCCCCCACCCCCCCCCG FCCCCCCCCCACCCCCCCCCACCCCCCCCCG FCCCCCCCCCACCCCCCCCCACCCCCCCCCG FCCCCCCCCCACCCCCCCCCACCCCCCCCCG FFFFFAAAAAAAAAAAAAAAAAAAAAGGGGG FFFFFAAAAAAAAAAAAAAAAAAAAAGGGGG FFFFFAAAAAAAAAAAAAAAAAAAAAGGGGG FFFFFAAAAAAAAAAAAAAAAAAAAAGGGGG FFFFFAAAAAAAAAAAAAAAAAAAAAGGGGG AAAAAAAAAAAAAAAAAAAAAAAAAAAAAAA FFFFFAAAAAAAAAAAAAAAAAAAAAGGGGG FFFFFAAAAAAAAAAAAAAAAAAAAAGGGGG FFFFFAAAAAAAAAAAAAAAAAAAAAGGGGG FFFFFAAAAAAAAAAAAAAAAAAAAAGGGGG FFFFFAAAAAAAAAAAAAAAAAAAAAGGGGG FFFFFAAAAAAAAAAAAAAAAAAAAAGGGGG FFFFFAAAAAAAAAAAAAAAAAAAAAGGGGG FFFFFAAAAAAAAAAAAAAAAAAAAAGGGGG FFFFFAAAAAAAAAAAAAAAAAAAAAGGGGG AAAAAAAAAAAAAAAAAAAAAAAAAAAAAAA FFFFFAAAAAAAAAAAAAAAAAAAAAGGGGG FFFFFAAAAAAAAAAAAAAAAAAAAAGGGGG FFFFFAAAAAAAAAAAAAAAAAAAAAGGGGG FFFFFAAAAAAAAAAAAAAAAAAAAAGGGGG FFFFFAAAAAAAAAAAAAAAAAAAAAGGGGG FBBBBBBBBBABBBBBBBBBABBBBBBBBBG FBBBBBBBBBABBBBBBBBBABBBBBBBBBG FBBBBBBBBBABBBBBBBBBABBBBBBBBBG FBBBBBBBBBABBBBBBBBBABBBBBBBBBG ABBBBBBBBBABBBBBBBBBABBBBBBBBBA 
AAAAAAAAAAAAAAAAAAAAAAAAAAAAAAA AAAAAAAAAAAAAAAAAAAAAAAAAAAAAAA AAAAAAAAAAAAAAAAAAAAAAAAAAAAAAA AAAAAAAAAAAAAAAAAAAAAAAAAAAAAAA AAAAAAAAAAAAAAAAAAAAAAAAAAAAAAA AAAAAAAAAAAAAAAAAAAAAAAAAAAAAAA AAAAAAAAAAAAAAAAAAAAAAAAAAAAAAA AAAAAAAAAAAAAAAAAAAAAAAAAAAAAAA AAAAAAAAAAAAAAAAAAAAAAAAAAAAAAA AAAAAAAAAAAAAAAAAAAAAAAAAAAAAAA AAAAAAAAAAAAAAAAAAAAAAAAAAAAAAA AAAAAAAAAAAAAAAAAAAAAAAAAAAAAAA AAAAAAAAAAAAAAAAAAAAAAAAAAAAAAA AAAAAAAAAAAAAAAAAAAAAAAAAAAAAAA AAAAAAAAAAAAAAAAAAAAAAAAAAAAAAA AAAAAAAAAAAAAAAAAAAAAAAAAAAAAAA AAAAAAAAAAAAAAAAAAAAAAAAAAAAAAA AAAAAAAAAAAAAAAAAAAAAAAAAAAAAAA AAAAAAAAAAAAAAAAAAAAAAAAAAAAAAA AAAAAAAAAAAAAAAAAAAAAAAAAAAAAAA AAAAAAAAAAAAAAAAAAAAAAAAAAAAAAA AAAAAAAAAAAAAAAAAAAAAAAAAAAAAAA AAAAAAAAAAAAAAAAAAAAAAAAAAAAAAA AAAAAAAAAAAAAAAAAAAAAAAAAAAAAAA AAAAAAAAAAAAAAAAAAAAAAAAAAAAAAA AAAAAAAAAAAAAAAAAAAAAAAAAAAAAAA AAAAAAAAAAAAAAAAAAAAAAAAAAAAAAA AAAAAAAAAAAAAAAAAAAAAAAAAAAAAAA AAAAAAAAAAAAAAAAAAAAAAAAAAAAAAA AAAAAAAAAAAAAAAAAAAAAAAAAAAAAAA AAAAAAAAAAAAAAAAAAAAAAAAAAAAAAA 
ACCCCCCCCCACCCCCCCCCACCCCCCCCCA FCCCCCCCCCACCCCCCCCCACCCCCCCCCG FCCCCCCCCCACCCCCCCCCACCCCCCCCCG FCCCCCCCCCACCCCCCCCCACCCCCCCCCG FCCCCCCCCCACCCCCCCCCACCCCCCCCCG FFFFFAAAAAAAAAAAAAAAAAAAAAGGGGG FFFFFAAAAAAAAAAAAAAAAAAAAAGGGGG FFFFFAAAAAAAAAAAAAAAAAAAAAGGGGG FFFFFAAAAAAAAAAAAAAAAAAAAAGGGGG FFFFFAAAAAAAAAAAAAAAAAAAAAGGGGG AAAAAAAAAAAAAAAAAAAAAAAAAAAAAAA FFFFFAAAAAAAAAAAAAAAAAAAAAGGGGG FFFFFAAAAAAAAAAAAAAAAAAAAAGGGGG FFFFFAAAAAAAAAAAAAAAAAAAAAGGGGG FFFFFAAAAAAAAAAAAAAAAAAAAAGGGGG FFFFFAAAAAAAAAAAAAAAAAAAAAGGGGG FFFFFAAAAAAAAAAAAAAAAAAAAAGGGGG FFFFFAAAAAAAAAAAAAAAAAAAAAGGGGG FFFFFAAAAAAAAAAAAAAAAAAAAAGGGGG FFFFFAAAAAAAAAAAAAAAAAAAAAGGGGG AAAAAAAAAAAAAAAAAAAAAAAAAAAAAAA FFFFFAAAAAAAAAAAAAAAAAAAAAGGGGG FFFFFAAAAAAAAAAAAAAAAAAAAAGGGGG FFFFFAAAAAAAAAAAAAAAAAAAAAGGGGG FFFFFAAAAAAAAAAAAAAAAAAAAAGGGGG FFFFFAAAAAAAAAAAAAAAAAAAAAGGGGG FBBBBBBBBBABBBBBBBBBBBBBBBBBBBG FBBBBBBBBBABBBBBBBBBBBBBBBBBBBG FBBBBBBBBBABBBBBBBBBBBBBBBBBBBG FBBBBBBBBBABBBBBBBBBBBBBBBBBBBG ABBBBBBBBBABBBBBBBBBABBBBBBBBBA 
ACCCCCCCCCACCCCCCCCCACCCCCCCCCA FCCCCCCCCCACCCCCCCCCACCCCCCCCCG FCCCCCCCCCACCCCCCCCCACCCCCCCCCG FCCCCCCCCCACCCCCCCCCACCCCCCCCCG FCCCCCCCCCACCCCCCCCCACCCCCCCCCG FFFFFAAAAAAAAAAAAAAAAAAAAAGGGGG FFFFFAAAAAAAAAAAAAAAAAAAAAGGGGG FFFFFAAAAAAAAAAAAAAAAAAAAAGGGGG FFFFFAAAAAAAAAAAAAAAAAAAAAGGGGG FFFFFAAAAAAAAAAAAAAAAAAAAAGGGGG AAAAAAAAAAAAAAAAAAAAAAAAAAAAAAA FFFFFAAAAAAAAAAAAAAAAAAAAAGGGGG FFFFFAAAAAAAAAAAAAAAAAAAAAGGGGG FFFFFAAAAAAAAAAAAAAAAAAAAAGGGGG FFFFFAAAAAAAAAAAAAAAAAAAAAGGGGG FFFFFAAAAAAAAAAAAAAAAAAAAAGGGGG FFFFFAAAAAAAAAAAAAAAAAAAAAGGGGG FFFFFAAAAAAAAAAAAAAAAAAAAAGGGGG FFFFFAAAAAAAAAAAAAAAAAAAAAGGGGG FFFFFAAAAAAAAAAAAAAAAAAAAAGGGGG AAAAAAAAAAAAAAAAAAAAAAAAAAAAAAA FFFFFAAAAAAAAAAAAAAAAAAAAAGGGGG FFFFFAAAAAAAAAAAAAAAAAAAAAGGGGG FFFFFAAAAAAAAAAAAAAAAAAAAAGGGGG FFFFFAAAAAAAAAAAAAAAAAAAAAGGGGG FFFFFAAAAAAAAAAAAAAAAAAAAAGGGGG FBBBBBBBBBABBBBBBBBBBBBBBBBBBBG FBBBBBBBBBABBBBBBBBBBBBBBBBBBBG FBBBBBBBBBABBBBBBBBBBBBBBBBBBBG FBBBBBBBBBABBBBBBBBBBBBBBBBBBBG ABBBBBBBBBABBBBBBBBBABBBBBBBBBA 
ACCCCCCCCCACCCCCCCCCACCCCCCCCCA FCCCCCCCCCACCCCCCCCCACCCCCCCCCG FCCCCCCCCCACCCCCCCCCACCCCCCCCCG FCCCCCCCCCACCCCCCCCCACCCCCCCCCG FCCCCCCCCCACCCCCCCCCACCCCCCCCCG FFFFFAAAAAAAAAAAAAAAAAAAAAGGGGG FFFFFAAAAAAAAAAAAAAAAAAAAAGGGGG FFFFFAAAAAAAAAAAAAAAAAAAAAGGGGG FFFFFAAAAAAAAAAAAAAAAAAAAAGGGGG FFFFFAAAAAAAAAAAAAAAAAAAAAGGGGG AAAAAAAAAAAAAAAAAAAAAAAAAAAAAAA FFFFFAAAAAAAAAAAAAAAAAAAAAGGGGG FFFFFAAAAAAAAAAAAAAAAAAAAAGGGGG FFFFFAAAAAAAAAAAAAAAAAAAAAGGGGG FFFFFAAAAAAAAAAAAAAAAAAAAAGGGGG FFFFFAAAAAAAAAAAAAAAAAAAAAGGGGG FFFFFAAAAAAAAAAAAAAAAAAAAAGGGGG FFFFFAAAAAAAAAAAAAAAAAAAAAGGGGG FFFFFAAAAAAAAAAAAAAAAAAAAAGGGGG FFFFFAAAAAAAAAAAAAAAAAAAAAGGGGG AAAAAAAAAAAAAAAAAAAAAAAAAAAAAAA FFFFFAAAAAAAAAAAAAAAAAAAAAGGGGG FFFFFAAAAAAAAAAAAAAAAAAAAAGGGGG FFFFFAAAAAAAAAAAAAAAAAAAAAGGGGG FFFFFAAAAAAAAAAAAAAAAAAAAAGGGGG FFFFFAAAAAAAAAAAAAAAAAAAAAGGGGG FBBBBBBBBBABBBBBBBBBBBBBBBBBBBG FBBBBBBBBBABBBBBBBBBBBBBBBBBBBG FBBBBBBBBBABBBBBBBBBBBBBBBBBBBG FBBBBBBBBBABBBBBBBBBBBBBBBBBBBG ABBBBBBBBBABBBBBBBBBABBBBBBBBBA 
ACCCCCCCCCACCCCCCCCCACCCCCCCCCA FCCCCCCCCCACCCCCCCCCACCCCCCCCCG FCCCCCCCCCACCCCCCCCCACCCCCCCCCG FCCCCCCCCCACCCCCCCCCACCCCCCCCCG FCCCCCCCCCACCCCCCCCCACCCCCCCCCG FFFFFAAAAAAAAAAAAAAAAAAAAAGGGGG FFFFFAAAAAAAAAAAAAAAAAAAAAGGGGG FFFFFAAAAAAAAAAAAAAAAAAAAAGGGGG FFFFFAAAAAAAAAAAAAAAAAAAAAGGGGG FFFFFAAAAAAAAAAAAAAAAAAAAAGGGGG AAAAAAAAAAAAAAAAAAAAAAAAAAAAAAA FFFFFAAAAAAAAAAAAAAAAAAAAAGGGGG FFFFFAAAAAAAAAAAAAAAAAAAAAGGGGG FFFFFAAAAAAAAAAAAAAAAAAAAAGGGGG FFFFFAAAAAAAAAAAAAAAAAAAAAGGGGG FFFFFAAAAAAAAAAAAAAAAAAAAAGGGGG FFFFFAAAAAAAAAAAAAAAAAAAAAGGGGG FFFFFAAAAAAAAAAAAAAAAAAAAAGGGGG FFFFFAAAAAAAAAAAAAAAAAAAAAGGGGG FFFFFAAAAAAAAAAAAAAAAAAAAAGGGGG AAAAAAAAAAAAAAAAAAAAAAAAAAAAAAA FFFFFAAAAAAAAAAAAAAAAAAAAAGGGGG FFFFFAAAAAAAAAAAAAAAAAAAAAGGGGG FFFFFAAAAAAAAAAAAAAAAAAAAAGGGGG FFFFFAAAAAAAAAAAAAAAAAAAAAGGGGG FFFFFAAAAAAAAAAAAAAAAAAAAAGGGGG FBBBBBBBBBABBBBBBBBBBBBBBBBBBBG FBBBBBBBBBABBBBBBBBBBBBBBBBBBBG FBBBBBBBBBABBBBBBBBBBBBBBBBBBBG FBBBBBBBBBABBBBBBBBBBBBBBBBBBBG ABBBBBBBBBABBBBBBBBBABBBBBBBBBA 
ACCCCCCCCCACCCCCCCCCACCCCCCCCCA FCCCCCCCCCACCCCCCCCCACCCCCCCCCG FCCCCCCCCCACCCCCCCCCACCCCCCCCCG FCCCCCCCCCACCCCCCCCCACCCCCCCCCG FCCCCCCCCCACCCCCCCCCACCCCCCCCCG FFFFFAAAAAAAAAAAAAAAAAAAAAGGGGG FFFFFAAAAAAAAAAAAAAAAAAAAAGGGGG FFFFFAAAAAAAAAAAAAAAAAAAAAGGGGG FFFFFAAAAAAAAAAAAAAAAAAAAAGGGGG FFFFFAAAAAAAAAAAAAAAAAAAAAGGGGG AAAAAAAAAAAAAAAAAAAAAAAAAAAAAAA FFFFFAAAAAAAAAAAAAAAAAAAAAGGGGG FFFFFAAAAAAAAAAAAAAAAAAAAAGGGGG FFFFFAAAAAAAAAAAAAAAAAAAAAGGGGG FFFFFAAAAAAAAAAAAAAAAAAAAAGGGGG FFFFFAAAAAAAAAAAAAAAAAAAAAGGGGG FFFFFAAAAAAAAAAAAAAAAAAAAAGGGGG FFFFFAAAAAAAAAAAAAAAAAAAAAGGGGG FFFFFAAAAAAAAAAAAAAAAAAAAAGGGGG FFFFFAAAAAAAAAAAAAAAAAAAAAGGGGG AAAAAAAAAAAAAAAAAAAAAAAAAAAAAAA FFFFFAAAAAAAAAAAAAAAAAAAAAGGGGG FFFFFAAAAAAAAAAAAAAAAAAAAAGGGGG FFFFFAAAAAAAAAAAAAAAAAAAAAGGGGG FFFFFAAAAAAAAAAAAAAAAAAAAAGGGGG FFFFFAAAAAAAAAAAAAAAAAAAAAGGGGG FBBBBBBBBBABBBBBBBBBBBBBBBBBBBG FBBBBBBBBBABBBBBBBBBBBBBBBBBBBG FBBBBBBBBBABBBBBBBBBBBBBBBBBBBG FBBBBBBBBBABBBBBBBBBBBBBBBBBBBG ABBBBBBBBBABBBBBBBBBABBBBBBBBBA 
ACCCCCCCCCACCCCCCCCCACCCCCCCCCA FCCCCCCCCCACCCCCCCCCACCCCCCCCCG FCCCCCCCCCACCCCCCCCCACCCCCCCCCG FCCCCCCCCCACCCCCCCCCACCCCCCCCCG FCCCCCCCCCACCCCCCCCCACCCCCCCCCG FDDDDDDDDDADDDDDDDDDADDDDDDDDDG FDDDDDDDDDADDDDDDDDDADDDDDDDDDG FDDDDDDDDDADDDDDDDDDADDDDDDDDDG FDDDDDDDDDADDDDDDDDDADDDDDDDDDG FDDDDDDDDDADDDDDDDDDADDDDDDDDDG AAAAAAAAAAAAAAAAAAAAAAAAAAAAAAA FDDDDDDDDDADDDDDDDDDADDDDDDDDDG FDDDDDDDDDADDDDDDDDDADDDDDDDDDG FDDDDDDDDDADDDDDDDDDADDDDDDDDDG FDDDDDDDDDADDDDDDDDDADDDDDDDDDG FDDDDDDDDDADDDDDDDDDADDDDDDDDDG FDDDDDDDDDADDDDDDDDDADDDDDDDDDG FDDDDDDDDDADDDDDDDDDADDDDDDDDDG FDDDDDDDDDADDDDDDDDDADDDDDDDDDG FDDDDDDDDDADDDDDDDDDADDDDDDDDDG AAAAAAAAAAAAAAAAAAAAAAAAAAAAAAA FDDDDDDDDDADDDDDDDDDADDDDDDDDDG FDDDDDDDDDADDDDDDDDDADDDDDDDDDG FDDDDDDDDDADDDDDDDDDADDDDDDDDDG FDDDDDDDDDADDDDDDDDDADDDDDDDDDG FDDDDDDDDDADDDDDDDDDADDDDDDDDDG FBBBBBBBBBABBBBBBBBBBBBBBBBBBBG FBBBBBBBBBABBBBBBBBBBBBBBBBBBBG FBBBBBBBBBABBBBBBBBBBBBBBBBBBBG FBBBBBBBBBABBBBBBBBBBBBBBBBBBBG ABBBBBBBBBABBBBBBBBBABBBBBBBBBA 
ACCCCCCCCCACCCCCCCCCACCCCCCCCCA FCCCCCCCCCACCCCCCCCCACCCCCCCCCG FCCCCCCCCCACCCCCCCCCACCCCCCCCCG FCCCCCCCCCACCCCCCCCCACCCCCCCCCG FCCCCCCCCCACCCCCCCCCACCCCCCCCCG FDDDDDDDDDADDDDDDDDDADDDDDDDDDG FDDDDDDDDDADDDDDDDDDADDDDDDDDDG FDDDDDDDDDADDDDDDDDDADDDDDDDDDG FDDDDDDDDDADDDDDDDDDADDDDDDDDDG FDDDDDDDDDADDDDDDDDDADDDDDDDDDG AAAAAAAAAAAAAAAAAAAAAAAAAAAAAAA FDDDDDDDDDADDDDDDDDDADDDDDDDDDG FDDDDDDDDDADDDDDDDDDADDDDDDDDDG FDDDDDDDDDADDDDDDDDDADDDDDDDDDG FDDDDDDDDDADDDDDDDDDADDDDDDDDDG FDDDDDDDDDADDDDDDDDDADDDDDDDDDG FDDDDDDDDDADDDDDDDDDADDDDDDDDDG FDDDDDDDDDADDDDDDDDDADDDDDDDDDG FDDDDDDDDDADDDDDDDDDADDDDDDDDDG FDDDDDDDDDADDDDDDDDDADDDDDDDDDG AAAAAAAAAAAAAAAAAAAAAAAAAAAAAAA FDDDDDDDDDADDDDDDDDDADDDDDDDDDG FDDDDDDDDDADDDDDDDDDADDDDDDDDDG FDDDDDDDDDADDDDDDDDDADDDDDDDDDG FDDDDDDDDDADDDDDDDDDADDDDDDDDDG FDDDDDDDDDADDDDDDDDDADDDDDDDDDG FBBBBBBBBBABBBBBBBBBBBBBBBBBBBG FBBBBBBBBBABBBBBBBBBBBBBBBBBBBG FBBBBBBBBBABBBBBBBBBBBBBBBBBBBG FBBBBBBBBBABBBBBBBBBBBBBBBBBBBG ABBBBBBBBBABBBBBBBBBABBBBBBBBBA 
ACCCCCCCCCACCCCCCCCCACCCCCCCCCA FCCCCCCCCCACCCCCCCCCACCCCCCCCCG FCCCCCCCCCACCCCCCCCCACCCCCCCCCG FCCCCCCCCCACCCCCCCCCACCCCCCCCCG FCCCCCCCCCACCCCCCCCCACCCCCCCCCG FDDDDDDDDDADDDDDDDDDADDDDDDDDDG FDDDDDDDDDADDDDDDDDDADDDDDDDDDG FDDDDDDDDDADDDDDDDDDADDDDDDDDDG FDDDDDDDDDADDDDDDDDDADDDDDDDDDG FDDDDDDDDDADDDDDDDDDADDDDDDDDDG AAAAAAAAAAAAAAAAAAAAAAAAAAAAAAA FDDDDDDDDDADDDDDDDDDADDDDDDDDDG FDDDDDDDDDADDDDDDDDDADDDDDDDDDG FDDDDDDDDDADDDDDDDDDADDDDDDDDDG FDDDDDDDDDADDDDDDDDDADDDDDDDDDG FDDDDDDDDDADDDDDDDDDADDDDDDDDDG FDDDDDDDDDADDDDDDDDDADDDDDDDDDG FDDDDDDDDDADDDDDDDDDADDDDDDDDDG FDDDDDDDDDADDDDDDDDDADDDDDDDDDG FDDDDDDDDDADDDDDDDDDADDDDDDDDDG AAAAAAAAAAAAAAAAAAAAAAAAAAAAAAA FDDDDDDDDDADDDDDDDDDADDDDDDDDDG FDDDDDDDDDADDDDDDDDDADDDDDDDDDG FDDDDDDDDDADDDDDDDDDADDDDDDDDDG FDDDDDDDDDADDDDDDDDDADDDDDDDDDG FDDDDDDDDDADDDDDDDDDADDDDDDDDDG FBBBBBBBBBABBBBBBBBBBBBBBBBBBBG FBBBBBBBBBABBBBBBBBBBBBBBBBBBBG FBBBBBBBBBABBBBBBBBBBBBBBBBBBBG FBBBBBBBBBABBBBBBBBBBBBBBBBBBBG ABBBBBBBBBABBBBBBBBBABBBBBBBBBA 
ACCCCCCCCCACCCCCCCCCACCCCCCCCCA FCCCCCCCCCACCCCCCCCCACCCCCCCCCG FCCCCCCCCCACCCCCCCCCACCCCCCCCCG FCCCCCCCCCACCCCCCCCCACCCCCCCCCG FCCCCCCCCCACCCCCCCCCACCCCCCCCCG FDDDDDDDDDADDDDDDDDDADDDDDDDDDG FDDDDDDDDDADDDDDDDDDADDDDDDDDDG FDDDDDDDDDADDDDDDDDDADDDDDDDDDG FDDDDDDDDDADDDDDDDDDADDDDDDDDDG FDDDDDDDDDADDDDDDDDDADDDDDDDDDG AAAAAAAAAAAAAAAAAAAAAAAAAAAAAAA FDDDDDDDDDADDDDDDDDDADDDDDDDDDG FDDDDDDDDDADDDDDDDDDADDDDDDDDDG FDDDDDDDDDADDDDDDDDDADDDDDDDDDG FDDDDDDDDDADDDDDDDDDADDDDDDDDDG FDDDDDDDDDADDDDDDDDDADDDDDDDDDG FDDDDDDDDDADDDDDDDDDADDDDDDDDDG FDDDDDDDDDADDDDDDDDDADDDDDDDDDG FDDDDDDDDDADDDDDDDDDADDDDDDDDDG FDDDDDDDDDADDDDDDDDDADDDDDDDDDG AAAAAAAAAAAAAAAAAAAAAAAAAAAAAAA FDDDDDDDDDADDDDDDDDDADDDDDDDDDG FDDDDDDDDDADDDDDDDDDADDDDDDDDDG FDDDDDDDDDADDDDDDDDDADDDDDDDDDG FDDDDDDDDDADDDDDDDDDADDDDDDDDDG FDDDDDDDDDADDDDDDDDDADDDDDDDDDG FBBBBBBBBBABBBBBBBBBBBBBBBBBBBG FBBBBBBBBBABBBBBBBBBBBBBBBBBBBG FBBBBBBBBBABBBBBBBBBBBBBBBBBBBG FBBBBBBBBBABBBBBBBBBBBBBBBBBBBG ABBBBBBBBBABBBBBBBBBABBBBBBBBBA 
AAAAAAAAAAAAAAAAAAAAAAAAAAAAAAA ADDDDDDDDDADDDDDDDDDADDDDDDDDDA ADDDDDDDDDADDDDDDDDDADDDDDDDDDA ADDDDDDDDDADDDDDDDDDADDDDDDDDDA ADDDDDDDDDADDDDDDDDDADDDDDDDDDA ADDDDDDDDDADDDDDDDDDADDDDDDDDDA ADDDDDDDDDADDDDDDDDDADDDDDDDDDA ADDDDDDDDDADDDDDDDDDADDDDDDDDDA ADDDDDDDDDADDDDDDDDDADDDDDDDDDA ADDDDDDDDDADDDDDDDDDADDDDDDDDDA AAAAAAAAAAAAAAAAAAAAAAAAAAAAAAA ADDDDDDDDDADDDDDDDDDADDDDDDDDDA ADDDDDDDDDADDDDDDDDDADDDDDDDDDA ADDDDDDDDDADDDDDDDDDADDDDDDDDDA ADDDDDDDDDADDDDDDDDDADDDDDDDDDA ADDDDDDDDDADDDDDDDDDADDDDDDDDDA ADDDDDDDDDADDDDDDDDDADDDDDDDDDA ADDDDDDDDDADDDDDDDDDADDDDDDDDDA ADDDDDDDDDADDDDDDDDDADDDDDDDDDA ADDDDDDDDDADDDDDDDDDADDDDDDDDDA AAAAAAAAAAAAAAAAAAAAAAAAAAAAAAA ADDDDDDDDDADDDDDDDDDADDDDDDDDDA ADDDDDDDDDADDDDDDDDDADDDDDDDDDA ADDDDDDDDDADDDDDDDDDADDDDDDDDDA ADDDDDDDDDADDDDDDDDDADDDDDDDDDA ADDDDDDDDDADDDDDDDDDADDDDDDDDDA ADDDDDDDDDADDDDDDDDDADDDDDDDDDA ADDDDDDDDDADDDDDDDDDADDDDDDDDDA ADDDDDDDDDADDDDDDDDDADDDDDDDDDA ADDDDDDDDDADDDDDDDDDADDDDDDDDDA AAAAAAAAAAAAAAAAAAAAAAAAAAAAAAA 
