model
size = 31, scale = 0.05, origin = -y
material 
  colors = A:#040202 B:#03FF03 C:#0303FF D:#FF8B03 E:#FCFCFC F:#FEFB00 G:#FF0303
voxels
AAAAAAAAAAAAAAAAAAAAAAAAAAAAAAA ACCCCCCCCCAFFFFFFFFFAFFFFFFFFFA ACCCCCCCCCAFFFFFFFFFAFFFFFFFFFA ACCCCCCCCCAFFFFFFFFFAFFFFFFFFFA ACCCCCCCCCAFFFFFFFFFAFFFFFFFFFA ACCCCCCCCCAFFFFFFFFFAFFFFFFFFFA ACCCCCCCCCAFFFFFFFFFAFFFFFFFFFA ACCCCCCCCCAFFFFFFFFFAFFFFFFFFFA ACCCCCCCCCAFFFFFFFFFAFFFFFFFFFA ACCCCCCCCCAFFFFFFFFFAFFFFFFFFFA AAAAAAAAAAAAAAAAAAAAAAAAAAAAAAA ABBBBBBBBBADDDDDDDDDAEEEEEEEEEA ABBBBBBBBBADDDDDDDDDAEEEEEEEEEA ABBBBBBBBBADDDDDDDDDAEEEEEEEEEA ABBBBBBBBBADDDDDDDDDAEEEEEEEEEA ABBBBBBBBBADDDDDDDDDAEEEEEEEEEA ABBBBBBBBBADDDDDDDDDAEEEEEEEEEA ABBBBBBBBBADDDDDDDDDAEEEEEEEEEA ABBBBBBBBBADDDDDDDDDAEEEEEEEEEA ABBBBBBBBBADDDDDDDDDAEEEEEEEEEA AAAAAAAAAAAAAAAAAAAAAAAAAAAAAAA ADDDDDDDDDADDDDDDDDDAEEEEEEEEEA ADDDDDDDDDADDDDDDDDDAEEEEEEEEEA ADDDDDDDDDADDDDDDDDDAEEEEEEEEEA ADDDDDDDDDADDDDDDDDDAEEEEEEEEEA ADDDDDDDDDADDDDDDDDDAEEEEEEEEEA ADDDDDDDDDADDDDDDDDDAEEEEEEEEEA ADDDDDDDDDADDDDDDDDDAEEEEEEEEEA ADDDDDDDDDADDDDDDDDDAEEEEEEEEEA ADDDDDDDDDADDDDDDDDDAEEEEEEEEEA AAAAAAAAAAAAAAAAAAAAAAAAAAAAAAA 
ADDDDDDDDDABBBBBBBBBABBBBBBBBBA FDDDDDDDDDABBBBBBBBBABBBBBBBBBD FDDDDDDDDDABBBBBBBBBABBBBBBBBBD FDDDDDDDDDABBBBBBBBBABBBBBBBBBD FDDDDDDDDDABBBBBBBBBABBBBBBBBBD FFFFFCCCCCAFFFFFFFFFAFFFFFDDDDD FFFFFCCCCCAFFFFFFFFFAFFFFFDDDDD FFFFFCCCCCAFFFFFFFFFAFFFFFDDDDD FFFFFCCCCCAFFFFFFFFFAFFFFFDDDDD FFFFFCCCCCAFFFFFFFFFAFFFFFDDDDD AAAAAAAAAAAAAAAAAAAAAAAAAAAAAAA EEEEEBBBBBADDDDDDDDDAEEEEEEEEEG EEEEEBBBBBADDDDDDDDDAEEEEEEEEEG EEEEEBBBBBADDDDDDDDDAEEEEEEEEEG EEEEEBBBBBADDDDDDDDDAEEEEEEEEEG EEEEEBBBBBADDDDDDDDDAEEEEEEEEEG EEEEEBBBBBADDDDDDDDDAEEEEEEEEEG EEEEEBBBBBADDDDDDDDDAEEEEEEEEEG EEEEEBBBBBADDDDDDDDDAEEEEEEEEEG EEEEEBBBBBADDDDDDDDDAEEEEEEEEEG AAAAAAAAAAAAAAAAAAAAAAAAAAAAAAA CCCCCDDDDDADDDDDDDDDAEEEEEBBBBB CCCCCDDDDDADDDDDDDDDAEEEEEBBBBB CCCCCDDDDDADDDDDDDDDAEEEEEBBBBB CCCCCDDDDDADDDDDDDDDAEEEEEBBBBB CCCCCDDDDDADDDDDDDDDAEEEEEBBBBB CCCCCDDDDDADDDDDDDDDAEEEEEBBBBB CCCCCDDDDDADDDDDDDDDAEEEEEBBBBB CCCCCDDDDDADDDDDDDDDAEEEEEBBBBB CCCCCDDDDDADDDDDDDDDAEEEEEBBBBB AEEEEEEEEEAFFFFFFFFFAGGGGGGGGGA 
ADDDDDDDDDABBBBBBBBBABBBBBBBBBA FDDDDDDDDDABBBBBBBBBABBBBBBBBBD FDDDDDDDDDABBBBBBBBBABBBBBBBBBD FDDDDDDDDDABBBBBBBBBABBBBBBBBBD FDDDDDDDDDABBBBBBBBBABBBBBBBBBD FFFFFCCCCCAFFFFFFFFFAFFFFFDDDDD FFFFFCCCCCAFFFFFFFFFAFFFFFDDDDD FFFFFCCCCCAFFFFFFFFFAFFFFFDDDDD FFFFFCCCCCAFFFFFFFFFAFFFFFDDDDD FFFFFCCCCCAFFFFFFFFFAFFFFFDDDDD AAAAAAAAAAAAAAAAAAAAAAAAAAAAAAA EEEEEBBBBBADDDDDDDDDAEEEEEEEEEG EEEEEBBBBBADDDDDDDDDAEEEEEEEEEG EEEEEBBBBBADDDDDDDDDAEEEEEEEEEG EEEEEBBBBBADDDDDDDDDAEEEEEEEEEG EEEEEBBBBBADDDDDDDDDAEEEEEEEEEG EEEEEBBBBBADDDDDDDDDAEEEEEEEEEG EEEEEBBBBBADDDDDDDDDAEEEEEEEEEG EEEEEBBBBBADDDDDDDDDAEEEEEEEEEG EEEEEBBBBBADDDDDDDDDAEEEEEEEEEG AAAAAAAAAAAAAAAAAAAAAAAAAAAAAAA CCCCCDDDDDADDDDDDDDDAEEEEEBBBBB CCCCCDDDDDADDDDDDDDDAEEEEEBBBBB CCCCCDDDDDADDDDDDDDDAEEEEEBBBBB CCCCCDDDDDADDDDDDDDDAEEEEEBBBBB CCCCCDDDDDADDDDDDDDDAEEEEEBBBBB CCCCCDDDDDADDDDDDDDDAEEEEEBBBBB CCCCCDDDDDADDDDDDDDDAEEEEEBBBBB CCCCCDDDDDADDDDDDDDDAEEEEEBBBBB CCCCCDDDDDADDDDDDDDDAEEEEEBBBBB AEEEEEEEEEAFFFFFFFFFAGGGGGGGGGA 
ADDDDDDDDDABBBBBBBBBABBBBBBBBBA FDDDDDDDDDABBBBBBBBBABBBBBBBBBD FDDDDDDDDDABBBBBBBBBABBBBBBBBBD FDDDDDDDDDABBBBBBBBBABBBBBBBBBD FDDDDDDDDDABBBBBBBBBABBBBBBBBBD FFFFFCCCCCAFFFFFFFFFAFFFFFDDDDD FFFFFCCCCCAFFFFFFFFFAFFFFFDDDDD FFFFFCCCCCAFFFFFFFFFAFFFFFDDDDD FFFFFCCCCCAFFFFFFFFFAFFFFFDDDDD FFFFFCCCCCAFFFFFFFFFAFFFFFDDDDD AAAAAAAAAAAAAAAAAAAAAAAAAAAAAAA EEEEEBBBBBADDDDDDDDDAEEEEEEEEEG EEEEEBBBBBADDDDDDDDDAEEEEEEEEEG EEEEEBBBBBADDDDDDDDDAEEEEEEEEEG EEEEEBBBBBADDDDDDDDDAEEEEEEEEEG EEEEEBBBBBADDDDDDDDDAEEEEEEEEEG EEEEEBBBBBADDDDDDDDDAEEEEEEEEEG EEEEEBBBBBADDDDDDDDDAEEEEEEEEEG EEEEEBBBBBADDDDDDDDDAEEEEEEEEEG EEEEEBBBBBADDDDDDDDDAEEEEEEEEEG AAAAAAAAAAAAAAAAAAAAAAAAAAAAAAA CCCCCDDDDDADDDDDDDDDAEEEEEBBBBB CCCCCDDDDDADDDDDDDDDAEEEEEBBBBB CCCCCDDDDDADDDDDDDDDAEEEEEBBBBB CCCCCDDDDDADDDDDDDDDAEEEEEBBBBB CCCCCDDDDDADDDDDDDDDAEEEEEBBBBB CCCCCDDDDDADDDDDDDDDAEEEEEBBBBB CCCCCDDDDDADDDDDDDDDAEEEEEBBBBB CCCCCDDDDDADDDDDDDDDAEEEEEBBBBB CCCCCDDDDDADDDDDDDDDAEEEEEBBBBB AEEEEEEEEEAFFFFFFFFFAGGGGGGGGGA 
ADDDDDDDDDABBBBBBBBBABBBBBBBBBA FDDDDDDDDDABBBBBBBBBABBBBBBBBBD FDDDDDDDDDABBBBBBBBBABBBBBBBBBD FDDDDDDDDDABBBBBBBBBABBBBBBBBBD FDDDDDDDDDABBBBBBBBBABBBBBBBBBD FFFFFCCCCCAFFFFFFFFFAFFFFFDDDDD FFFFFCCCCCAFFFFFFFFFAFFFFFDDDDD FFFFFCCCCCAFFFFFFFFFAFFFFFDDDDD FFFFFCCCCCAFFFFFFFFFAFFFFFDDDDD FFFFFCCCCCAFFFFFFFFFAFFFFFDDDDD AAAAAAAAAAAAAAAAAAAAAAAAAAAAAAA EEEEEBBBBBADDDDDDDDDAEEEEEEEEEG EEEEEBBBBBADDDDDDDDDAEEEEEEEEEG EEEEEBBBBBADDDDDDDDDAEEEEEEEEEG EEEEEBBBBBADDDDDDDDDAEEEEEEEEEG EEEEEBBBBBADDDDDDDDDAEEEEEEEEEG EEEEEBBBBBADDDDDDDDDAEEEEEEEEEG EEEEEBBBBBADDDDDDDDDAEEEEEEEEEG EEEEEBBBBBADDDDDDDDDAEEEEEEEEEG EEEEEBBBBBADDDDDDDDDAEEEEEEEEEG AAAAAAAAAAAAAAAAAAAAAAAAAAAAAAA CCCCCDDDDDADDDDDDDDDAEEEEEBBBBB CCCCCDDDDDADDDDDDDDDAEEEEEBBBBB CCCCCDDDDDADDDDDDDDDAEEEEEBBBBB CCCCCDDDDDADDDDDDDDDAEEEEEBBBBB CCCCCDDDDDADDDDDDDDDAEEEEEBBBBB CCCCCDDDDDADDDDDDDDDAEEEEEBBBBB CCCCCDDDDDADDDDDDDDDAEEEEEBBBBB CCCCCDDDDDADDDDDDDDDAEEEEEBBBBB CCCCCDDDDDADDDDDDDDDAEEEEEBBBBB AEEEEEEEEEAFFFFFFFFFAGGGGGGGGGA 
ADDDDDDDDDABBBBBBBBBABBBBBBBBBA FDDDDDDDDDABBBBBBBBBABBBBBBBBBD FDDDDDDDDDABBBBBBBBBABBBBBBBBBD FDDDDDDDDDABBBBBBBBBABBBBBBBBBD FDDDDDDDDDABBBBBBBBBABBBBBBBBBD FFFFFAAAAAAAAAAAAAAAAAAAAADDDDD FFFFFAAAAAAAAAAAAAAAAAAAAADDDDD FFFFFAAAAAAAAAAAAAAAAAAAAADDDDD FFFFFAAAAAAAAAAAAAAAAAAAAADDDDD FFFFFAAAAAAAAAAAAAAAAAAAAADDDDD AAAAAAAAAAAAAAAAAAAAAAAAAAAAAAA EEEEEAAAAAAAAAAAAAAAAAAAAAGGGGG EEEEEAAAAAAAAAAAAAAAAAAAAAGGGGG EEEEEAAAAAAAAAAAAAAAAAAAAAGGGGG EEEEEAAAAAAAAAAAAAAAAAAAAAGGGGG EEEEEAAAAAAAAAAAAAAAAAAAAAGGGGG EEEEEAAAAAAAAAAAAAAAAAAAAAGGGGG EEEEEAAAAAAAAAAAAAAAAAAAAAGGGGG EEEEEAAAAAAAAAAAAAAAAAAAAAGGGGG EEEEEAAAAAAAAAAAAAAAAAAAAAGGGGG AAAAAAAAAAAAAAAAAAAAAAAAAAAAAAA CCCCCAAAAAAAAAAAAAAAAAAAAABBBBB CCCCCAAAAAAAAAAAAAAAAAAAAABBBBB CCCCCAAAAAAAAAAAAAAAAAAAAABBBBB CCCCCAAAAAAAAAAAAAAAAAAAAABBBBB CCCCCAAAAAAAAAAAAAAAAAAAAABBBBB CCCCCEEEEEAFFFFFFFFFAGGGGGBBBBB CCCCCEEEEEAFFFFFFFFFAGGGGGBBBBB CCCCCEEEEEAFFFFFFFFFAGGGGGBBBBB CCCCCEEEEEAFFFFFFFFFAGGGGGBBBBB AEEEEEEEEEAFFFFFFFFFAGGGGGGGGGA 
ADDDDDDDDDABBBBBBBBBABBBBBBBBBA FDDDDDDDDDABBBBBBBBBABBBBBBBBBD FDDDDDDDDDABBBBBBBBBABBBBBBBBBD FDDDDDDDDDABBBBBBBBBABBBBBBBBBD FDDDDDDDDDABBBBBBBBBABBBBBBBBBD FFFFFAAAAAAAAAAAAAAAAAAAAADDDDD FFFFFAAAAAAAAAAAAAAAAAAAAADDDDD FFFFFAAAAAAAAAAAAAAAAAAAAADDDDD FFFFFAAAAAAAAAAAAAAAAAAAAADDDDD FFFFFAAAAAAAAAAAAAAAAAAAAADDDDD AAAAAAAAAAAAAAAAAAAAAAAAAAAAAAA EEEEEAAAAAAAAAAAAAAAAAAAAAGGGGG EEEEEAAAAAAAAAAAAAAAAAAAAAGGGGG EEEEEAAAAAAAAAAAAAAAAAAAAAGGGGG EEEEEAAAAAAAAAAAAAAAAAAAAAGGGGG EEEEEAAAAAAAAAAAAAAAAAAAAAGGGGG EEEEEAAAAAAAAAAAAAAAAAAAAAGGGGG EEEEEAAAAAAAAAAAAAAAAAAAAAGGGGG EEEEEAAAAAAAAAAAAAAAAAAAAAGGGGG EEEEEAAAAAAAAAAAAAAAAAAAAAGGGGG AAAAAAAAAAAAAAAAAAAAAAAAAAAAAAA CCCCCAAAAAAAAAAAAAAAAAAAAABBBBB CCCCCAAAAAAAAAAAAAAAAAAAAABBBBB CCCCCAAAAAAAAAAAAAAAAAAAAABBBBB CCCCCAAAAAAAAAAAAAAAAAAAAABBBBB CCCCCAAAAAAAAAAAAAAAAAAAAABBBBB CCCCCEEEEEAFFFFFFFFFAGGGGGBBBBB CCCCCEEEEEAFFFFFFFFFAGGGGGBBBBB CCCCCEEEEEAFFFFFFFFFAGGGGGBBBBB CCCCCEEEEEAFFFFFFFFFAGGGGGBBBBB AEEEEEEEEEAFFFFFFFFFAGGGGGGGGGA 
ADDDDDDDDDABBBBBBBBBABBBBBBBBBA FDDDDDDDDDABBBBBBBBBABBBBBBBBBD FDDDDDDDDDABBBBBBBBBABBBBBBBBBD FDDDDDDDDDABBBBBBBBBABBBBBBBBBD FDDDDDDDDDABBBBBBBBBABBBBBBBBBD FFFFFAAAAAAAAAAAAAAAAAAAAADDDDD FFFFFAAAAAAAAAAAAAAAAAAAAADDDDD FFFFFAAAAAAAAAAAAAAAAAAAAADDDDD FFFFFAAAAAAAAAAAAAAAAAAAAADDDDD FFFFFAAAAAAAAAAAAAAAAAAAAADDDDD AAAAAAAAAAAAAAAAAAAAAAAAAAAAAAA EEEEEAAAAAAAAAAAAAAAAAAAAAGGGGG EEEEEAAAAAAAAAAAAAAAAAAAAAGGGGG EEEEEAAAAAAAAAAAAAAAAAAAAAGGGGG EEEEEAAAAAAAAAAAAAAAAAAAAAGGGGG EEEEEAAAAAAAAAAAAAAAAAAAAAGGGGG EEEEEAAAAAAAAAAAAAAAAAAAAAGGGGG EEEEEAAAAAAAAAAAAAAAAAAAAAGGGGG EEEEEAAAAAAAAAAAAAAAAAAAAAGGGGG EEEEEAAAAAAAAAAAAAAAAAAAAAGGGGG AAAAAAAAAAAAAAAAAAAAAAAAAAAAAAA CCCCCAAAAAAAAAAAAAAAAAAAAABBBBB CCCCCAAAAAAAAAAAAAAAAAAAAABBBBB CCCCCAAAAAAAAAAAAAAAAAAAAABBBBB CCCCCAAAAAAAAAAAAAAAAAAAAABBBBB CCCCCAAAAAAAAAAAAAAAAAAAAABBBBB CCCCCEEEEEAFFFFFFFFFAGGGGGBBBBB CCCCCEEEEEAFFFFFFFFFAGGGGGBBBBB CCCCCEEEEEAFFFFFFFFFAGGGGGBBBBB CCCCCEEEEEAFFFFFFFFFAGGGGGBBBBB AEEEEEEEEEAFFFFFFFFFAGGGGGGGGGA 
ADDDDDDDDDABBBBBBBBBABBBBBBBBBA FDDDDDDDDDABBBBBBBBBABBBBBBBBBD FDDDDDDDDDABBBBBBBBBABBBBBBBBBD FDDDDDDDDDABBBBBBBBBABBBBBBBBBD FDDDDDDDDDABBBBBBBBBABBBBBBBBBD FFFFFAAAAAAAAAAAAAAAAAAAAADDDDD FFFFFAAAAAAAAAAAAAAAAAAAAADDDDD FFFFFAAAAAAAAAAAAAAAAAAAAADDDDD FFFFFAAAAAAAAAAAAAAAAAAAAADDDDD FFFFFAAAAAAAAAAAAAAAAAAAAADDDDD AAAAAAAAAAAAAAAAAAAAAAAAAAAAAAA EEEEEAAAAAAAAAAAAAAAAAAAAAGGGGG EEEEEAAAAAAAAAAAAAAAAAAAAAGGGGG EEEEEAAAAAAAAAAAAAAAAAAAAAGGGGG EEEEEAAAAAAAAAAAAAAAAAAAAAGGGGG EEEEEAAAAAAAAAAAAAAAAAAAAAGGGGG EEEEEAAAAAAAAAAAAAAAAAAAAAGGGGG EEEEEAAAAAAAAAAAAAAAAAAAAAGGGGG EEEEEAAAAAAAAAAAAAAAAAAAAAGGGGG EEEEEAAAAAAAAAAAAAAAAAAAAAGGGGG AAAAAAAAAAAAAAAAAAAAAAAAAAAAAAA CCCCCAAAAAAAAAAAAAAAAAAAAABBBBB CCCCCAAAAAAAAAAAAAAAAAAAAABBBBB CCCCCAAAAAAAAAAAAAAAAAAAAABBBBB CCCCCAAAAAAAAAAAAAAAAAAAAABBBBB CCCCCAAAAAAAAAAAAAAAAAAAAABBBBB CCCCCEEEEEAFFFFFFFFFAGGGGGBBBBB CCCCCEEEEEAFFFFFFFFFAGGGGGBBBBB CCCCCEEEEEAFFFFFFFFFAGGGGGBBBBB CCCCCEEEEEAFFFFFFFFFAGGGGGBBBBB AEEEEEEEEEAFFFFFFFFFAGGGGGGGGGA 
ADDDDDDDDDABBBBBBBBBABBBBBBBBBA FDDDDDDDDDABBBBBBBBBABBBBBBBBBD FDDDDDDDDDABBBBBBBBBABBBBBBBBBD FDDDDDDDDDABBBBBBBBBABBBBBBBBBD FDDDDDDDDDABBBBBBBBBABBBBBBBBBD FFFFFAAAAAAAAAAAAAAAAAAAAADDDDD FFFFFAAAAAAAAAAAAAAAAAAAAADDDDD FFFFFAAAAAAAAAAAAAAAAAAAAADDDDD FFFFFAAAAAAAAAAAAAAAAAAAAADDDDD FFFFFAAAAAAAAAAAAAAAAAAAAADDDDD AAAAAAAAAAAAAAAAAAAAAAAAAAAAAAA EEEEEAAAAAAAAAAAAAAAAAAAAAGGGGG EEEEEAAAAAAAAAAAAAAAAAAAAAGGGGG EEEEEAAAAAAAAAAAAAAAAAAAAAGGGGG EEEEEAAAAAAAAAAAAAAAAAAAAAGGGGG EEEEEAAAAAAAAAAAAAAAAAAAAAGGGGG EEEEEAAAAAAAAAAAAAAAAAAAAAGGGGG EEEEEAAAAAAAAAAAAAAAAAAAAAGGGGG EEEEEAAAAAAAAAAAAAAAAAAAAAGGGGG EEEEEAAAAAAAAAAAAAAAAAAAAAGGGGG AAAAAAAAAAAAAAAAAAAAAAAAAAAAAAA CCCCCAAAAAAAAAAAAAAAAAAAAABBBBB CCCCCAAAAAAAAAAAAAAAAAAAAABBBBB CCCCCAAAAAAAAAAAAAAAAAAAAABBBBB CCCCCAAAAAAAAAAAAAAAAAAAAABBBBB CCCCCAAAAAAAAAAAAAAAAAAAAABBBBB CCCCCEEEEEAFFFFFFFFFAGGGGGBBBBB CCCCCEEEEEAFFFFFFFFFAGGGGGBBBBB CCCCCEEEEEAFFFFFFFFFAGGGGGBBBBB CCCCCEEEEEAFFFFFFFFFAGGGGGBBBBB AEEEEEEEEEAFFFFFFFFFAGGGGGGGGGA 
AAAAAAAAAAAAAAAAAAAAAAAAAAAAAAA AAAAAAAAAAAAAAAAAAAAAAAAAAAAAAA AAAAAAAAAAAAAAAAAAAAAAAAAAAAAAA AAAAAAAAAAAAAAAAAAAAAAAAAAAAAAA AAAAAAAAAAAAAAAAAAAAAAAAAAAAAAA AAAAAAAAAAAAAAAAAAAAAAAAAAAAAAA AAAAAAAAAAAAAAAAAAAAAAAAAAAAAAA AAAAAAAAAAAAAAAAAAAAAAAAAAAAAAA AAAAAAAAAAAAAAAAAAAAAAAAAAAAAAA AAAAAAAAAAAAAAAAAAAAAAAAAAAAAAA AAAAAAAAAAAAAAAAAAAAAAAAAAAAAAA AAAAAAAAAAAAAAAAAAAAAAAAAAAAAAA AAAAAAAAAAAAAAAAAAAAAAAAAAAAAAA AAAAAAAAAAAAAAAAAAAAAAAAAAAAAAA AAAAAAAAAAAAAAAAAAAAAAAAAAAAAAA AAAAAAAAAAAAAAAAAAAAAAAAAAAAAAA AAAAAAAAAAAAAAAAAAAAAAAAAAAAAAA AAAAAAAAAAAAAAAAAAAAAAAAAAAAAAA AAAAAAAAAAAAAAAAAAAAAAAAAAAAAAA AAAAAAAAAAAAAAAAAAAAAAAAAAAAAAA AAAAAAAAAAAAAAAAAAAAAAAAAAAAAAA AAAAAAAAAAAAAAAAAAAAAAAAAAAAAAA AAAAAAAAAAAAAAAAAAAAAAAAAAAAAAA AAAAAAAAAAAAAAAAAAAAAAAAAAAAAAA AAAAAAAAAAAAAAAAAAAAAAAAAAAAAAA AAAAAAAAAAAAAAAAAAAAAAAAAAAAAAA AAAAAAAAAAAAAAAAAAAAAAAAAAAAAAA AAAAAAAAAAAAAAAAAAAAAAAAAAAAAAA AAAAAAAAAAAAAAAAAAAAAAAAAAAAAAA AAAAAAAAAAAAAAAAAAAAAAAAAAAAAAA AAAAAAAAAAAAAAAAAAAAAAAAAAAAAAA 
ACCCCCCCCCAFFFFFFFFFABBBBBBBBBA DCCCCCCCCCAFFFFFFFFFABBBBBBBBBG DCCCCCCCCCAFFFFFFFFFABBBBBBBBBG DCCCCCCCCCAFFFFFFFFFABBBBBBBBBG DCCCCCCCCCAFFFFFFFFFABBBBBBBBBG DDDDDAAAAAAAAAAAAAAAAAAAAAGGGGG DDDDDAAAAAAAAAAAAAAAAAAAAAGGGGG DDDDDAAAAAAAAAAAAAAAAAAAAAGGGGG DDDDDAAAAAAAAAAAAAAAAAAAAAGGGGG DDDDDAAAAAAAAAAAAAAAAAAAAAGGGGG AAAAAAAAAAAAAAAAAAAAAAAAAAAAAAA CCCCCAAAAAAAAAAAAAAAAAAAAABBBBB CCCCCAAAAAAAAAAAAAAAAAAAAABBBBB CCCCCAAAAAAAAAAAAAAAAAAAAABBBBB CCCCCAAAAAAAAAAAAAAAAAAAAABBBBB CCCCCAAAAAAAAAAAAAAAAAAAAABBBBB CCCCCAAAAAAAAAAAAAAAAAAAAABBBBB CCCCCAAAAAAAAAAAAAAAAAAAAABBBBB CCCCCAAAAAAAAAAAAAAAAAAAAABBBBB CCCCCAAAAAAAAAAAAAAAAAAAAABBBBB AAAAAAAAAAAAAAAAAAAAAAAAAAAAAAA FFFFFAAAAAAAAAAAAAAAAAAAAAFFFFF FFFFFAAAAAAAAAAAAAAAAAAAAAFFFFF FFFFFAAAAAAAAAAAAAAAAAAAAAFFFFF FFFFFAAAAAAAAAAAAAAAAAAAAAFFFFF FFFFFAAAAAAAAAAAAAAAAAAAAAFFFFF FFFFFGGGGGAEEEEEEEEEACCCCCFFFFF FFFFFGGGGGAEEEEEEEEEACCCCCFFFFF FFFFFGGGGGAEEEEEEEEEACCCCCFFFFF FFFFFGGGGGAEEEEEEEEEACCCCCFFFFF AGGGGGGGGGAEEEEEEEEEACCCCCCCCCA 
ACCCCCCCCCAFFFFFFFFFABBBBBBBBBA DCCCCCCCCCAFFFFFFFFFABBBBBBBBBG DCCCCCCCCCAFFFFFFFFFABBBBBBBBBG DCCCCCCCCCAFFFFFFFFFABBBBBBBBBG DCCCCCCCCCAFFFFFFFFFABBBBBBBBBG DDDDDAAAAAAAAAAAAAAAAAAAAAGGGGG DDDDDAAAAAAAAAAAAAAAAAAAAAGGGGG DDDDDAAAAAAAAAAAAAAAAAAAAAGGGGG DDDDDAAAAAAAAAAAAAAAAAAAAAGGGGG DDDDDAAAAAAAAAAAAAAAAAAAAAGGGGG AAAAAAAAAAAAAAAAAAAAAAAAAAAAAAA CCCCCAAAAAAAAAAAAAAAAAAAAABBBBB CCCCCAAAAAAAAAAAAAAAAAAAAABBBBB CCCCCAAAAAAAAAAAAAAAAAAAAABBBBB CCCCCAAAAAAAAAAAAAAAAAAAAABBBBB CCCCCAAAAAAAAAAAAAAAAAAAAABBBBB CCCCCAAAAAAAAAAAAAAAAAAAAABBBBB CCCCCAAAAAAAAAAAAAAAAAAAAABBBBB CCCCCAAAAAAAAAAAAAAAAAAAAABBBBB CCCCCAAAAAAAAAAAAAAAAAAAAABBBBB AAAAAAAAAAAAAAAAAAAAAAAAAAAAAAA FFFFFAAAAAAAAAAAAAAAAAAAAAFFFFF FFFFFAAAAAAAAAAAAAAAAAAAAAFFFFF FFFFFAAAAAAAAAAAAAAAAAAAAAFFFFF FFFFFAAAAAAAAAAAAAAAAAAAAAFFFFF FFFFFAAAAAAAAAAAAAAAAAAAAAFFFFF FFFFFGGGGGAEEEEEEEEEACCCCCFFFFF FFFFFGGGGGAEEEEEEEEEACCCCCFFFFF FFFFFGGGGGAEEEEEEEEEACCCCCFFFFF FFFFFGGGGGAEEEEEEEEEACCCCCFFFFF AGGGGGGGGGAEEEEEEEEEACCCCCCCCCA 
ACCCCCCCCCAFFFFFFFFFABBBBBBBBBA DCCCCCCCCCAFFFFFFFFFABBBBBBBBBG DCCCCCCCCCAFFFFFFFFFABBBBBBBBBG DCCCCCCCCCAFFFFFFFFFABBBBBBBBBG DCCCCCCCCCAFFFFFFFFFABBBBBBBBBG DDDDDAAAAAAAAAAAAAAAAAAAAAGGGGG DDDDDAAAAAAAAAAAAAAAAAAAAAGGGGG DDDDDAAAAAAAAAAAAAAAAAAAAAGGGGG DDDDDAAAAAAAAAAAAAAAAAAAAAGGGGG DDDDDAAAAAAAAAAAAAAAAAAAAAGGGGG AAAAAAAAAAAAAAAAAAAAAAAAAAAAAAA CCCCCAAAAAAAAAAAAAAAAAAAAABBBBB CCCCCAAAAAAAAAAAAAAAAAAAAABBBBB CCCCCAAAAAAAAAAAAAAAAAAAAABBBBB CCCCCAAAAAAAAAAAAAAAAAAAAABBBBB CCCCCAAAAAAAAAAAAAAAAAAAAABBBBB CCCCCAAAAAAAAAAAAAAAAAAAAABBBBB CCCCCAAAAAAAAAAAAAAAAAAAAABBBBB CCCCCAAAAAAAAAAAAAAAAAAAAABBBBB CCCCCAAAAAAAAAAAAAAAAAAAAABBBBB AAAAAAAAAAAAAAAAAAAAAAAAAAAAAAA FFFFFAAAAAAAAAAAAAAAAAAAAAFFFFF FFFFFAAAAAAAAAAAAAAAAAAAAAFFFFF FFFFFAAAAAAAAAAAAAAAAAAAAAFFFFF FFFFFAAAAAAAAAAAAAAAAAAAAAFFFFF FFFFFAAAAAAAAAAAAAAAAAAAAAFFFFF FFFFFGGGGGAEEEEEEEEEACCCCCFFFFF FFFFFGGGGGAEEEEEEEEEACCCCCFFFFF FFFFFGGGGGAEEEEEEEEEACCCCCFFFFF FFFFFGGGGGAEEEEEEEEEACCCCCFFFFF AGGGGGGGGGAEEAAEEAEEACCCCCCCCCA 
ACCCCCCCCCAFFFFFFFFFABBBBBBBBBA DCCCCCCCCCAFFFFFFFFFABBBBBBBBBG DCCCCCCCCCAFFFFFFFFFABBBBBBBBBG DCCCCCCCCCAFFFFFFFFFABBBBBBBBBG DCCCCCCCCCAFFFFFFFFFABBBBBBBBBG DDDDDAAAAAAAAAAAAAAAAAAAAAGGGGG DDDDDAAAAAAAAAAAAAAAAAAAAAGGGGG DDDDDAAAAAAAAAAAAAAAAAAAAAGGGGG DDDDDAAAAAAAAAAAAAAAAAAAAAGGGGG DDDDDAAAAAAAAAAAAAAAAAAAAAGGGGG AAAAAAAAAAAAAAAAAAAAAAAAAAAAAAA CCCCCAAAAAAAAAAAAAAAAAAAAABBBBB CCCCCAAAAAAAAAAAAAAAAAAAAABBBBB CCCCCAAAAAAAAAAAAAAAAAAAAABBBBB CCCCCAAAAAAAAAAAAAAAAAAAAABBBBB CCCCCAAAAAAAAAAAAAAAAAAAAABBBBB CCCCCAAAAAAAAAAAAAAAAAAAAABBBBB CCCCCAAAAAAAAAAAAAAAAAAAAABBBBB CCCCCAAAAAAAAAAAAAAAAAAAAABBBBB CCCCCAAAAAAAAAAAAAAAAAAAAABBBBB AAAAAAAAAAAAAAAAAAAAAAAAAAAAAAA FFFFFAAAAAAAAAAAAAAAAAAAAAFFFFF FFFFFAAAAAAAAAAAAAAAAAAAAAFFFFF FFFFFAAAAAAAAAAAAAAAAAAAAAFFFFF FFFFFAAAAAAAAAAAAAAAAAAAAAFFFFF FFFFFAAAAAAAAAAAAAAAAAAAAAFFFFF FFFFFGGGGGAEEEEEEEEEACCCCCFFFFF FFFFFGGGGGAEEEEEEEEEACCCCCFFFFF FFFFFGGGGGAEEEEEEEEEACCCCCFFFFF FFFFFGGGGGAEEEEEEEEEACCCCCFFFFF AGGGGGGGGGAEAEEEAEAEACCCCCCCCCA 
ACCCCCCCCCAFFFFFFFFFABBBBBBBBBA DCCCCCCCCCAFFFFFFFFFABBBBBBBBBG DCCCCCCCCCAFFFFFFFFFABBBBBBBBBG DCCCCCCCCCAFFFFFFFFFABBBBBBBBBG DCCCCCCCCCAFFFFFFFFFABBBBBBBBBG DDDDDAAAAAAAAAAAAAAAAAAAAAGGGGG DDDDDAAAAAAAAAAAAAAAAAAAAAGGGGG DDDDDAAAAAAAAAAAAAAAAAAAAAGGGGG DDDDDAAAAAAAAAAAAAAAAAAAAAGGGGG DDDDDAAAAAAAAAAAAAAAAAAAAAGGGGG AAAAAAAAAAAAAAAAAAAAAAAAAAAAAAA CCCCCAAAAAAAAAAAAAAAAAAAAABBBBB CCCCCAAAAAAAAAAAAAAAAAAAAABBBBB CCCCCAAAAAAAAAAAAAAAAAAAAABBBBB CCCCCAAAAAAAAAAAAAAAAAAAAABBBBB CCCCCAAAAAAAAAAAAAAAAAAAAABBBBB CCCCCAAAAAAAAAAAAAAAAAAAAABBBBB CCCCCAAAAAAAAAAAAAAAAAAAAABBBBB CCCCCAAAAAAAAAAAAAAAAAAAAABBBBB CCCCCAAAAAAAAAAAAAAAAAAAAABBBBB AAAAAAAAAAAAAAAAAAAAAAAAAAAAAAA FFFFFAAAAAAAAAAAAAAAAAAAAAFFFFF FFFFFAAAAAAAAAAAAAAAAAAAAAFFFFF FFFFFAAAAAAAAAAAAAAAAAAAAAFFFFF FFFFFAAAAAAAAAAAAAAAAAAAAAFFFFF FFFFFAAAAAAAAAAAAAAAAAAAAAFFFFF FFFFFGGGGGAEEEEEEEEEACCCCCFFFFF FFFFFGGGGGAEEEEEEEEEACCCCCFFFFF FFFFFGGGGGAEEEEEEEEEACCCCCFFFFF FFFFFGGGGGAEEEEEEEEEACCCCCFFFFF AGGGGGGGGGAEAEEEAEAEACCCCCCCCCA 
ACCCCCCCCCAFFFFFFFFFABBBBBBBBBA DCCCCCCCCCAFFFFFFFFFABBBBBBBBBG DCCCCCCCCCAFFFFFFFFFABBBBBBBBBG DCCCCCCCCCAFFFFFFFFFABBBBBBBBBG DCCCCCCCCCAFFFFFFFFFABBBBBBBBBG DDDDDAAAAAAAAAAAAAAAAAAAAAGGGGG DDDDDAAAAAAAAAAAAAAAAAAAAAGGGGG DDDDDAAAAAAAAAAAAAAAAAAAAAGGGGG DDDDDAAAAAAAAAAAAAAAAAAAAAGGGGG DDDDDAAAAAAAAAAAAAAAAAAAAAGGGGG AAAAAAAAAAAAAAAAAAAAAAAAAAAAAAA CCCCCAAAAAAAAAAAAAAAAAAAAABBBBB CCCCCAAAAAAAAAAAAAAAAAAAAABBBBB CCCCCAAAAAAAAAAAAAAAAAAAAABBBBB CCCCCAAAAAAAAAAAAAAAAAAAAABBBBB CCCCCAAAAAAAAAAAAAAAAAAAAABBBBB CCCCCAAAAAAAAAAAAAAAAAAAAABBBBB CCCCCAAAAAAAAAAAAAAAAAAAAABBBBB CCCCCAAAAAAAAAAAAAAAAAAAAABBBBB CCCCCAAAAAAAAAAAAAAAAAAAAABBBBB AAAAAAAAAAAAAAAAAAAAAAAAAAAAAAA FFFFFAAAAAAAAAAAAAAAAAAAAAFFFFF FFFFFAAAAAAAAAAAAAAAAAAAAAFFFFF FFFFFAAAAAAAAAAAAAAAAAAAAAFFFFF FFFFFAAAAAAAAAAAAAAAAAAAAAFFFFF FFFFFAAAAAAAAAAAAAAAAAAAAAFFFFF FFFFFGGGGGAEEEEEEEEEACCCCCFFFFF FFFFFGGGGGAEEEEEEEEEACCCCCFFFFF FFFFFGGGGGAEEEEEEEEEACCCCCFFFFF FFFFFGGGGGAEEEEEEEEEACCCCCFFFFF AGGGGGGGGGAEAEEEAEAEACCCCCCCCCA 
ACCCCCCCCCAFFFFFFFFFABBBBBBBBBA DCCCCCCCCCAFFFFFFFFFABBBBBBBBBG DCCCCCCCCCAFFFFFFFFFABBBBBBBBBG DCCCCCCCCCAFFFFFFFFFABBBBBBBBBG DCCCCCCCCCAFFFFFFFFFABBBBBBBBBG DDDDDAAAAAAAAAAAAAAAAAAAAAGGGGG DDDDDAAAAAAAAAAAAAAAAAAAAAGGGGG DDDDDAAAAAAAAAAAAAAAAAAAAAGGGGG DDDDDAAAAAAAAAAAAAAAAAAAAAGGGGG DDDDDAAAAAAAAAAAAAAAAAAAAAGGGGG AAAAAAAAAAAAAAAAAAAAAAAAAAAAAAA CCCCCAAAAAAAAAAAAAAAAAAAAABBBBB CCCCCAAAAAAAAAAAAAAAAAAAAABBBBB CCCCCAAAAAAAAAAAAAAAAAAAAABBBBB CCCCCAAAAAAAAAAAAAAAAAAAAABBBBB CCCCCAAAAAAAAAAAAAAAAAAAAABBBBB CCCCCAAAAAAAAAAAAAAAAAAAAABBBBB CCCCCAAAAAAAAAAAAAAAAAAAAABBBBB CCCCCAAAAAAAAAAAAAAAAAAAAABBBBB CCCCCAAAAAAAAAAAAAAAAAAAAABBBBB AAAAAAAAAAAAAAAAAAAAAAAAAAAAAAA FFFFFAAAAAAAAAAAAAAAAAAAAAFFFFF FFFFFAAAAAAAAAAAAAAAAAAAAAFFFFF FFFFFAAAAAAAAAAAAAAAAAAAAAFFFFF FFFFFAAAAAAAAAAAAAAAAAAAAAFFFFF FFFFFAAAAAAAAAAAAAAAAAAAAAFFFFF FFFFFGGGGGAEEEEEEEEEACCCCCFFFFF FFFFFGGGGGAEEEEEEEEEACCCCCFFFFF FFFFFGGGGGAEEEEEEEEEACCCCCFFFFF FFFFFGGGGGAEEEEEEEEEACCCCCFFFFF AGGGGGGGGGAEEAAEAEAEACCCCCCCCCA 
ACCCCCCCCCAFFFFFFFFFABBBBBBBBBA DCCCCCCCCCAFFFFFFFFFABBBBBBBBBG DCCCCCCCCCAFFFFFFFFFABBBBBBBBBG DCCCCCCCCCAFFFFFFFFFABBBBBBBBBG DCCCCCCCCCAFFFFFFFFFABBBBBBBBBG DDDDDAAAAAAAAAAAAAAAAAAAAAGGGGG DDDDDAAAAAAAAAAAAAAAAAAAAAGGGGG DDDDDAAAAAAAAAAAAAAAAAAAAAGGGGG DDDDDAAAAAAAAAAAAAAAAAAAAAGGGGG DDDDDAAAAAAAAAAAAAAAAAAAAAGGGGG AAAAAAAAAAAAAAAAAAAAAAAAAAAAAAA CCCCCAAAAAAAAAAAAAAAAAAAAABBBBB CCCCCAAAAAAAAAAAAAAAAAAAAABBBBB CCCCCAAAAAAAAAAAAAAAAAAAAABBBBB CCCCCAAAAAAAAAAAAAAAAAAAAABBBBB CCCCCAAAAAAAAAAAAAAAAAAAAABBBBB CCCCCAAAAAAAAAAAAAAAAAAAAABBBBB CCCCCAAAAAAAAAAAAAAAAAAAAABBBBB CCCCCAAAAAAAAAAAAAAAAAAAAABBBBB CCCCCAAAAAAAAAAAAAAAAAAAAABBBBB AAAAAAAAAAAAAAAAAAAAAAAAAAAAAAA FFFFFAAAAAAAAAAAAAAAAAAAAAFFFFF FFFFFAAAAAAAAAAAAAAAAAAAAAFFFFF FFFFFAAAAAAAAAAAAAAAAAAAAAFFFFF FFFFFAAAAAAAAAAAAAAAAAAAAAFFFFF FFFFFAAAAAAAAAAAAAAAAAAAAAFFFFF FFFFFGGGGGAEEEEEEEEEACCCCCFFFFF FFFFFGGGGGAEEEEEEEEEACCCCCFFFFF FFFFFGGGGGAEEEEEEEEEACCCCCFFFFF FFFFFGGGGGAEEEEEEEEEACCCCCFFFFF AGGGGGGGGGAEEEEEEEEEACCCCCCCCCA 
ACCCCCCCCCAFFFFFFFFFABBBBBBBBBA DCCCCCCCCCAFFFFFFFFFABBBBBBBBBG DCCCCCCCCCAFFFFFFFFFABBBBBBBBBG DCCCCCCCCCAFFFFFFFFFABBBBBBBBBG DCCCCCCCCCAFFFFFFFFFABBBBBBBBBG DDDDDAAAAAAAAAAAAAAAAAAAAAGGGGG DDDDDAAAAAAAAAAAAAAAAAAAAAGGGGG DDDDDAAAAAAAAAAAAAAAAAAAAAGGGGG DDDDDAAAAAAAAAAAAAAAAAAAAAGGGGG DDDDDAAAAAAAAAAAAAAAAAAAAAGGGGG AAAAAAAAAAAAAAAAAAAAAAAAAAAAAAA CCCCCAAAAAAAAAAAAAAAAAAAAABBBBB CCCCCAAAAAAAAAAAAAAAAAAAAABBBBB CCCCCAAAAAAAAAAAAAAAAAAAAABBBBB CCCCCAAAAAAAAAAAAAAAAAAAAABBBBB CCCCCAAAAAAAAAAAAAAAAAAAAABBBBB CCCCCAAAAAAAAAAAAAAAAAAAAABBBBB CCCCCAAAAAAAAAAAAAAAAAAAAABBBBB CCCCCAAAAAAAAAAAAAAAAAAAAABBBBB CCCCCAAAAAAAAAAAAAAAAAAAAABBBBB AAAAAAAAAAAAAAAAAAAAAAAAAAAAAAA FFFFFAAAAAAAAAAAAAAAAAAAAAFFFFF FFFFFAAAAAAAAAAAAAAAAAAAAAFFFFF FFFFFAAAAAAAAAAAAAAAAAAAAAFFFFF FFFFFAAAAAAAAAAAAAAAAAAAAAFFFFF FFFFFAAAAAAAAAAAAAAAAAAAAAFFFFF FFFFFGGGGGAEEEEEEEEEACCCCCFFFFF FFFFFGGGGGAEEEEEEEEEACCCCCFFFFF FFFFFGGGGGAEEEEEEEEEACCCCCFFFFF FFFFFGGGGGAEEEEEEEEEACCCCCFFFFF AGGGGGGGGGAEEEEEEEEEACCCCCCCCCA 
AAAAAAAAAAAAAAAAAAAAAAAAAAAAAAA AAAAAAAAAAAAAAAAAAAAAAAAAAAAAAA AAAAAAAAAAAAAAAAAAAAAAAAAAAAAAA AAAAAAAAAAAAAAAAAAAAAAAAAAAAAAA AAAAAAAAAAAAAAAAAAAAAAAAAAAAAAA AAAAAAAAAAAAAAAAAAAAAAAAAAAAAAA AAAAAAAAAAAAAAAAAAAAAAAAAAAAAAA AAAAAAAAAAAAAAAAAAAAAAAAAAAAAAA AAAAAAAAAAAAAAAAAAAAAAAAAAAAAAA AAAAAAAAAAAAAAAAAAAAAAAAAAAAAAA AAAAAAAAAAAAAAAAAAAAAAAAAAAAAAA AAAAAAAAAAAAAAAAAAAAAAAAAAAAAAA AAAAAAAAAAAAAAAAAAAAAAAAAAAAAAA AAAAAAAAAAAAAAAAAAAAAAAAAAAAAAA AAAAAAAAAAAAAAAAAAAAAAAAAAAAAAA AAAAAAAAAAAAAAAAAAAAAAAAAAAAAAA AAAAAAAAAAAAAAAAAAAAAAAAAAAAAAA AAAAAAAAAAAAAAAAAAAAAAAAAAAAAAA AAAAAAAAAAAAAAAAAAAAAAAAAAAAAAA AAAAAAAAAAAAAAAAAAAAAAAAAAAAAAA AAAAAAAAAAAAAAAAAAAAAAAAAAAAAAA AAAAAAAAAAAAAAAAAAAAAAAAAAAAAAA AAAAAAAAAAAAAAAAAAAAAAAAAAAAAAA AAAAAAAAAAAAAAAAAAAAAAAAAAAAAAA AAAAAAAAAAAAAAAAAAAAAAAAAAAAAAA AAAAAAAAAAAAAAAAAAAAAAAAAAAAAAA AAAAAAAAAAAAAAAAAAAAAAAAAAAAAAA AAAAAAAAAAAAAAAAAAAAAAAAAAAAAAA AAAAAAAAAAAAAAAAAAAAAAAAAAAAAAA AAAAAAAAAAAAAAAAAAAAAAAAAAAAAAA AAAAAAAAAAAAAAAAAAAAAAAAAAAAAAA 
ABBBBBBBBBACCCCCCCCCACCCCCCCCCA FBBBBBBBBBACCCCCCCCCACCCCCCCCCG FBBBBBBBBBACCCCCCCCCACCCCCCCCCG FBBBBBBBBBACCCCCCCCCACCCCCCCCCG FBBBBBBBBBACCCCCCCCCACCCCCCCCCG FFFFFAAAAAAAAAAAAAAAAAAAAAGGGGG FFFFFAAAAAAAAAAAAAAAAAAAAAGGGGG FFFFFAAAAAAAAAAAAAAAAAAAAAGGGGG FFFFFAAAAAAAAAAAAAAAAAAAAAGGGGG FFFFFAAAAAAAAAAAAAAAAAAAAAGGGGG AAAAAAAAAAAAAAAAAAAAAAAAAAAAAAA BBBBBAAAAAAAAAAAAAAAAAAAAAGGGGG BBBBBAAAAAAAAAAAAAAAAAAAAAGGGGG BBBBBAAAAAAAAAAAAAAAAAAAAAGGGGG BBBBBAAAAAAAAAAAAAAAAAAAAAGGGGG BBBBBAAAAAAAAAAAAAAAAAAAAAGGGGG BBBBBAAAAAAAAAAAAAAAAAAAAAGGGGG BBBBBAAAAAAAAAAAAAAAAAAAAAGGGGG BBBBBAAAAAAAAAAAAAAAAAAAAAGGGGG BBBBBAAAAAAAAAAAAAAAAAAAAAGGGGG AAAAAAAAAAAAAAAAAAAAAAAAAAAAAAA GGGGGAAAAAAAAAAAAAAAAAAAAABBBBB GGGGGAAAAAAAAAAAAAAAAAAAAABBBBB GGGGGAAAAAAAAAAAAAAAAAAAAABBBBB GGGGGAAAAAAAAAAAAAAAAAAAAABBBBB GGGGGAAAAAAAAAAAAAAAAAAAAABBBBB GGGGGFFFFFAEEEEEEEEEEDDDDDBBBBB GGGGGFFFFFAEEEEEEEEEEDDDDDBBBBB GGGGGFFFFFAEEEEEEEEEEDDDDDBBBBB GGGGGFFFFFAEEEEEEEEEEDDDDDBBBBB AFFFFFFFFFAEEEEEEEEEADDDDDDDDDA 
ABBBBBBBBBACCCCCCCCCACCCCCCCCCA FBBBBBBBBBACCCCCCCCCACCCCCCCCCG FBBBBBBBBBACCCCCCCCCACCCCCCCCCG FBBBBBBBBBACCCCCCCCCACCCCCCCCCG FBBBBBBBBBACCCCCCCCCACCCCCCCCCG FFFFFAAAAAAAAAAAAAAAAAAAAAGGGGG FFFFFAAAAAAAAAAAAAAAAAAAAAGGGGG FFFFFAAAAAAAAAAAAAAAAAAAAAGGGGG FFFFFAAAAAAAAAAAAAAAAAAAAAGGGGG FFFFFAAAAAAAAAAAAAAAAAAAAAGGGGG AAAAAAAAAAAAAAAAAAAAAAAAAAAAAAA BBBBBAAAAAAAAAAAAAAAAAAAAAGGGGG BBBBBAAAAAAAAAAAAAAAAAAAAAGGGGG BBBBBAAAAAAAAAAAAAAAAAAAAAGGGGG BBBBBAAAAAAAAAAAAAAAAAAAAAGGGGG BBBBBAAAAAAAAAAAAAAAAAAAAAGGGGG BBBBBAAAAAAAAAAAAAAAAAAAAAGGGGG BBBBBAAAAAAAAAAAAAAAAAAAAAGGGGG BBBBBAAAAAAAAAAAAAAAAAAAAAGGGGG BBBBBAAAAAAAAAAAAAAAAAAAAAGGGGG AAAAAAAAAAAAAAAAAAAAAAAAAAAAAAA GGGGGAAAAAAAAAAAAAAAAAAAAABBBBB GGGGGAAAAAAAAAAAAAAAAAAAAABBBBB GGGGGAAAAAAAAAAAAAAAAAAAAABBBBB GGGGGAAAAAAAAAAAAAAAAAAAAABBBBB GGGGGAAAAAAAAAAAAAAAAAAAAABBBBB GGGGGFFFFFAEEEEEEEEEEDDDDDBBBBB GGGGGFFFFFAEEEEEEEEEEDDDDDBBBBB GGGGGFFFFFAEEEEEEEEEEDDDDDBBBBB GGGGGFFFFFAEEEEEEEEEEDDDDDBBBBB AFFFFFFFFFAEEEEEEEEEADDDDDDDDDA 
ABBBBBBBBBACCCCCCCCCACCCCCCCCCA FBBBBBBBBBACCCCCCCCCACCCCCCCCCG FBBBBBBBBBACCCCCCCCCACCCCCCCCCG FBBBBBBBBBACCCCCCCCCACCCCCCCCCG FBBBBBBBBBACCCCCCCCCACCCCCCCCCG FFFFFAAAAAAAAAAAAAAAAAAAAAGGGGG FFFFFAAAAAAAAAAAAAAAAAAAAAGGGGG FFFFFAAAAAAAAAAAAAAAAAAAAAGGGGG FFFFFAAAAAAAAAAAAAAAAAAAAAGGGGG FFFFFAAAAAAAAAAAAAAAAAAAAAGGGGG AAAAAAAAAAAAAAAAAAAAAAAAAAAAAAA BBBBBAAAAAAAAAAAAAAAAAAAAAGGGGG BBBBBAAAAAAAAAAAAAAAAAAAAAGGGGG BBBBBAAAAAAAAAAAAAAAAAAAAAGGGGG BBBBBAAAAAAAAAAAAAAAAAAAAAGGGGG BBBBBAAAAAAAAAAAAAAAAAAAAAGGGGG BBBBBAAAAAAAAAAAAAAAAAAAAAGGGGG BBBBBAAAAAAAAAAAAAAAAAAAAAGGGGG BBBBBAAAAAAAAAAAAAAAAAAAAAGGGGG BBBBBAAAAAAAAAAAAAAAAAAAAAGGGGG AAAAAAAAAAAAAAAAAAAAAAAAAAAAAAA GGGGGAAAAAAAAAAAAAAAAAAAAABBBBB GGGGGAAAAAAAAAAAAAAAAAAAAABBBBB GGGGGAAAAAAAAAAAAAAAAAAAAABBBBB GGGGGAAAAAAAAAAAAAAAAAAAAABBBBB GGGGGAAAAAAAAAAAAAAAAAAAAABBBBB GGGGGFFFFFAEEEEEEEEEEDDDDDBBBBB GGGGGFFFFFAEEEEEEEEEEDDDDDBBBBB GGGGGFFFFFAEEEEEEEEEEDDDDDBBBBB GGGGGFFFFFAEEEEEEEEEEDDDDDBBBBB AFFFFFFFFFAEEEEEEEEEADDDDDDDDDA 
ABBBBBBBBBACCCCCCCCCACCCCCCCCCA FBBBBBBBBBACCCCCCCCCACCCCCCCCCG FBBBBBBBBBACCCCCCCCCACCCCCCCCCG FBBBBBBBBBACCCCCCCCCACCCCCCCCCG FBBBBBBBBBACCCCCCCCCACCCCCCCCCG FFFFFAAAAAAAAAAAAAAAAAAAAAGGGGG FFFFFAAAAAAAAAAAAAAAAAAAAAGGGGG FFFFFAAAAAAAAAAAAAAAAAAAAAGGGGG FFFFFAAAAAAAAAAAAAAAAAAAAAGGGGG FFFFFAAAAAAAAAAAAAAAAAAAAAGGGGG AAAAAAAAAAAAAAAAAAAAAAAAAAAAAAA BBBBBAAAAAAAAAAAAAAAAAAAAAGGGGG BBBBBAAAAAAAAAAAAAAAAAAAAAGGGGG BBBBBAAAAAAAAAAAAAAAAAAAAAGGGGG BBBBBAAAAAAAAAAAAAAAAAAAAAGGGGG BBBBBAAAAAAAAAAAAAAAAAAAAAGGGGG BBBBBAAAAAAAAAAAAAAAAAAAAAGGGGG BBBBBAAAAAAAAAAAAAAAAAAAAAGGGGG BBBBBAAAAAAAAAAAAAAAAAAAAAGGGGG BBBBBAAAAAAAAAAAAAAAAAAAAAGGGGG AAAAAAAAAAAAAAAAAAAAAAAAAAAAAAA GGGGGAAAAAAAAAAAAAAAAAAAAABBBBB GGGGGAAAAAAAAAAAAAAAAAAAAABBBBB GGGGGAAAAAAAAAAAAAAAAAAAAABBBBB GGGGGAAAAAAAAAAAAAAAAAAAAABBBBB GGGGGAAAAAAAAAAAAAAAAAAAAABBBBB GGGGGFFFFFAEEEEEEEEEEDDDDDBBBBB GGGGGFFFFFAEEEEEEEEEEDDDDDBBBBB GGGGGFFFFFAEEEEEEEEEEDDDDDBBBBB GGGGGFFFFFAEEEEEEEEEEDDDDDBBBBB AFFFFFFFFFAEEEEEEEEEADDDDDDDDDA 
ABBBBBBBBBACCCCCCCCCACCCCCCCCCA FBBBBBBBBBACCCCCCCCCACCCCCCCCCG FBBBBBBBBBACCCCCCCCCACCCCCCCCCG FBBBBBBBBBACCCCCCCCCACCCCCCCCCG FBBBBBBBBBACCCCCCCCCACCCCCCCCCG FFFFFAAAAAAAAAAAAAAAAAAAAAGGGGG FFFFFAAAAAAAAAAAAAAAAAAAAAGGGGG FFFFFAAAAAAAAAAAAAAAAAAAAAGGGGG FFFFFAAAAAAAAAAAAAAAAAAAAAGGGGG FFFFFAAAAAAAAAAAAAAAAAAAAAGGGGG AAAAAAAAAAAAAAAAAAAAAAAAAAAAAAA BBBBBAAAAAAAAAAAAAAAAAAAAAGGGGG BBBBBAAAAAAAAAAAAAAAAAAAAAGGGGG BBBBBAAAAAAAAAAAAAAAAAAAAAGGGGG BBBBBAAAAAAAAAAAAAAAAAAAAAGGGGG BBBBBAAAAAAAAAAAAAAAAAAAAAGGGGG BBBBBAAAAAAAAAAAAAAAAAAAAAGGGGG BBBBBAAAAAAAAAAAAAAAAAAAAAGGGGG BBBBBAAAAAAAAAAAAAAAAAAAAAGGGGG BBBBBAAAAAAAAAAAAAAAAAAAAAGGGGG AAAAAAAAAAAAAAAAAAAAAAAAAAAAAAA GGGGGAAAAAAAAAAAAAAAAAAAAABBBBB GGGGGAAAAAAAAAAAAAAAAAAAAABBBBB GGGGGAAAAAAAAAAAAAAAAAAAAABBBBB GGGGGAAAAAAAAAAAAAAAAAAAAABBBBB GGGGGAAAAAAAAAAAAAAAAAAAAABBBBB GGGGGFFFFFAEEEEEEEEEEDDDDDBBBBB GGGGGFFFFFAEEEEEEEEEEDDDDDBBBBB GGGGGFFFFFAEEEEEEEEEEDDDDDBBBBB GGGGGFFFFFAEEEEEEEEEEDDDDDBBBBB AFFFFFFFFFAEEEEEEEEEADDDDDDDDDA 
ABBBBBBBBBACCCCCCCCCACCCCCCCCCA FBBBBBBBBBACCCCCCCCCACCCCCCCCCG FBBBBBBBBBACCCCCCCCCACCCCCCCCCG FBBBBBBBBBACCCCCCCCCACCCCCCCCCG FBBBBBBBBBACCCCCCCCCACCCCCCCCCG FGGGGGGGGGAEEEEEEEEEAEEEEEEEEEG FGGGGGGGGGAEEEEEEEEEAEEEEEEEEEG FGGGGGGGGGAEEEEEEEEEAEEEEEEEEEG FGGGGGGGGGAEEEEEEEEEAEEEEEEEEEG FGGGGGGGGGAEEEEEEEEEAEEEEEEEEEG AAAAAAAAAAAAAAAAAAAAAAAAAAAAAAA BDDDDDDDDDAGGGGGGGGGACCCCCCCCCG BDDDDDDDDDAGGGGGGGGGACCCCCCCCCG BDDDDDDDDDAGGGGGGGGGACCCCCCCCCG BDDDDDDDDDAGGGGGGGGGACCCCCCCCCG BDDDDDDDDDAGGGGGGGGGACCCCCCCCCG BDDDDDDDDDAGGGGGGGGGACCCCCCCCCG BDDDDDDDDDAGGGGGGGGGACCCCCCCCCG BDDDDDDDDDAGGGGGGGGGACCCCCCCCCG BDDDDDDDDDAGGGGGGGGGACCCCCCCCCG AAAAAAAAAAAAAAAAAAAAAAAAAAAAAAA GGGGGCCCCCADDDDDDDDDAEEEEEEEEEB GGGGGCCCCCADDDDDDDDDAEEEEEEEEEB GGGGGCCCCCADDDDDDDDDAEEEEEEEEEB GGGGGCCCCCADDDDDDDDDAEEEEEEEEEB GGGGGCCCCCADDDDDDDDDAEEEEEEEEEB GGGGGFFFFFADDDDDDDDDEEEEEEEEEEB GGGGGFFFFFADDDDDDDDDEEEEEEEEEEB GGGGGFFFFFADDDDDDDDDEEEEEEEEEEB GGGGGFFFFFADDDDDDDDDEEEEEEEEEEB AFFFFFFFFFAEEEEEEEEEADDDDDDDDDA 
ABBBBBBBBBACCCCCCCCCACCCCCCCCCA FBBBBBBBBBACCCCCCCCCACCCCCCCCCG FBBBBBBBBBACCCCCCCCCACCCCCCCCCG FBBBBBBBBBACCCCCCCCCACCCCCCCCCG FBBBBBBBBBACCCCCCCCCACCCCCCCCCG FGGGGGGGGGAEEEEEEEEEAEEEEEEEEEG FGGGGGGGGGAEEEEEEEEEAEEEEEEEEEG FGGGGGGGGGAEEEEEEEEEAEEEEEEEEEG FGGGGGGGGGAEEEEEEEEEAEEEEEEEEEG FGGGGGGGGGAEEEEEEEEEAEEEEEEEEEG AAAAAAAAAAAAAAAAAAAAAAAAAAAAAAA BDDDDDDDDDAGGGGGGGGGACCCCCCCCCG BDDDDDDDDDAGGGGGGGGGACCCCCCCCCG BDDDDDDDDDAGGGGGGGGGACCCCCCCCCG BDDDDDDDDDAGGGGGGGGGACCCCCCCCCG BDDDDDDDDDAGGGGGGGGGACCCCCCCCCG BDDDDDDDDDAGGGGGGGGGACCCCCCCCCG BDDDDDDDDDAGGGGGGGGGACCCCCCCCCG BDDDDDDDDDAGGGGGGGGGACCCCCCCCCG BDDDDDDDDDAGGGGGGGGGACCCCCCCCCG AAAAAAAAAAAAAAAAAAAAAAAAAAAAAAA GGGGGCCCCCADDDDDDDDDAEEEEEEEEEB GGGGGCCCCCADDDDDDDDDAEEEEEEEEEB GGGGGCCCCCADDDDDDDDDAEEEEEEEEEB GGGGGCCCCCADDDDDDDDDAEEEEEEEEEB GGGGGCCCCCADDDDDDDDDAEEEEEEEEEB GGGGGFFFFFADDDDDDDDDEEEEEEEEEEB GGGGGFFFFFADDDDDDDDDEEEEEEEEEEB GGGGGFFFFFADDDDDDDDDEEEEEEEEEEB GGGGGFFFFFADDDDDDDDDEEEEEEEEEEB AFFFFFFFFFAEEEEEEEEEADDDDDDDDDA 
ABBBBBBBBBACCCCCCCCCACCCCCCCCCA FBBBBBBBBBACCCCCCCCCACCCCCCCCCG FBBBBBBBBBACCCCCCCCCACCCCCCCCCG FBBBBBBBBBACCCCCCCCCACCCCCCCCCG FBBBBBBBBBACCCCCCCCCACCCCCCCCCG FGGGGGGGGGAEEEEEEEEEAEEEEEEEEEG FGGGGGGGGGAEEEEEEEEEAEEEEEEEEEG FGGGGGGGGGAEEEEEEEEEAEEEEEEEEEG FGGGGGGGGGAEEEEEEEEEAEEEEEEEEEG FGGGGGGGGGAEEEEEEEEEAEEEEEEEEEG AAAAAAAAAAAAAAAAAAAAAAAAAAAAAAA BDDDDDDDDDAGGGGGGGGGACCCCCCCCCG BDDDDDDDDDAGGGGGGGGGACCCCCCCCCG BDDDDDDDDDAGGGGGGGGGACCCCCCCCCG BDDDDDDDDDAGGGGGGGGGACCCCCCCCCG BDDDDDDDDDAGGGGGGGGGACCCCCCCCCG BDDDDDDDDDAGGGGGGGGGACCCCCCCCCG BDDDDDDDDDAGGGGGGGGGACCCCCCCCCG BDDDDDDDDDAGGGGGGGGGACCCCCCCCCG BDDDDDDDDDAGGGGGGGGGACCCCCCCCCG AAAAAAAAAAAAAAAAAAAAAAAAAAAAAAA GGGGGCCCCCADDDDDDDDDAEEEEEEEEEB GGGGGCCCCCADDDDDDDDDAEEEEEEEEEB GGGGGCCCCCADDDDDDDDDAEEEEEEEEEB GGGGGCCCCCADDDDDDDDDAEEEEEEEEEB GGGGGCCCCCADDDDDDDDDAEEEEEEEEEB GGGGGFFFFFADDDDDDDDDEEEEEEEEEEB GGGGGFFFFFADDDDDDDDDEEEEEEEEEEB GGGGGFFFFFADDDDDDDDDEEEEEEEEEEB GGGGGFFFFFADDDDDDDDDEEEEEEEEEEB AFFFFFFFFFAEEEEEEEEEADDDDDDDDDA 
ABBBBBBBBBACCCCCCCCCACCCCCCCCCA FBBBBBBBBBACCCCCCCCCACCCCCCCCCG FBBBBBBBBBACCCCCCCCCACCCCCCCCCG FBBBBBBBBBACCCCCCCCCACCCCCCCCCG FBBBBBBBBBACCCCCCCCCACCCCCCCCCG FGGGGGGGGGAEEEEEEEEEAEEEEEEEEEG FGGGGGGGGGAEEEEEEEEEAEEEEEEEEEG FGGGGGGGGGAEEEEEEEEEAEEEEEEEEEG FGGGGGGGGGAEEEEEEEEEAEEEEEEEEEG FGGGGGGGGGAEEEEEEEEEAEEEEEEEEEG AAAAAAAAAAAAAAAAAAAAAAAAAAAAAAA BDDDDDDDDDAGGGGGGGGGACCCCCCCCCG BDDDDDDDDDAGGGGGGGGGACCCCCCCCCG BDDDDDDDDDAGGGGGGGGGACCCCCCCCCG BDDDDDDDDDAGGGGGGGGGACCCCCCCCCG BDDDDDDDDDAGGGGGGGGGACCCCCCCCCG BDDDDDDDDDAGGGGGGGGGACCCCCCCCCG BDDDDDDDDDAGGGGGGGGGACCCCCCCCCG BDDDDDDDDDAGGGGGGGGGACCCCCCCCCG BDDDDDDDDDAGGGGGGGGGACCCCCCCCCG AAAAAAAAAAAAAAAAAAAAAAAAAAAAAAA GGGGGCCCCCADDDDDDDDDAEEEEEEEEEB GGGGGCCCCCADDDDDDDDDAEEEEEEEEEB GGGGGCCCCCADDDDDDDDDAEEEEEEEEEB GGGGGCCCCCADDDDDDDDDAEEEEEEEEEB GGGGGCCCCCADDDDDDDDDAEEEEEEEEEB GGGGGFFFFFADDDDDDDDDEEEEEEEEEEB GGGGGFFFFFADDDDDDDDDEEEEEEEEEEB GGGGGFFFFFADDDDDDDDDEEEEEEEEEEB GGGGGFFFFFADDDDDDDDDEEEEEEEEEEB AFFFFFFFFFAEEEEEEEEEADDDDDDDDDA 
AAAAAAAAAAAAAAAAAAAAAAAAAAAAAAA AGGGGGGGGGAEEEEEEEEEAEEEEEEEEEA AGGGGGGGGGAEEEEEEEEEAEEEEEEEEEA AGGGGGGGGGAEEEEEEEEEAEEEEEEEEEA AGGGGGGGGGAEEEEEEEEEAEEEEEEEEEA AGGGGGGGGGAEEEEEEEEEAEEEEEEEEEA AGGGGGGGGGAEEEEEEEEEAEEEEEEEEEA AGGGGGGGGGAEEEEEEEEEAEEEEEEEEEA AGGGGGGGGGAEEEEEEEEEAEEEEEEEEEA AGGGGGGGGGAEEEEEEEEEAEEEEEEEEEA AAAAAAAAAAAAAAAAAAAAAAAAAAAAAAA ADDDDDDDDDAGGGGGGGGGACCCCCCCCCA ADDDDDDDDDAGGGGGGGGGACCCCCCCCCA ADDDDDDDDDAGGGGGGGGGACCCCCCCCCA ADDDDDDDDDAGGGGGGGGGACCCCCCCCCA ADDDDDDDDDAGGGGGGGGGACCCCCCCCCA ADDDDDDDDDAGGGGGGGGGACCCCCCCCCA ADDDDDDDDDAGGGGGGGGGACCCCCCCCCA ADDDDDDDDDAGGGGGGGGGACCCCCCCCCA ADDDDDDDDDAGGGGGGGGGACCCCCCCCCA AAAAAAAAAAAAAAAAAAAAAAAAAAAAAAA ACCCCCCCCCADDDDDDDDDAEEEEEEEEEA ACCCCCCCCCADDDDDDDDDAEEEEEEEEEA ACCCCCCCCCADDDDDDDDDAEEEEEEEEEA ACCCCCCCCCADDDDDDDDDAEEEEEEEEEA ACCCCCCCCCADDDDDDDDDAEEEEEEEEEA ACCCCCCCCCADDDDDDDDDAEEEEEEEEEA ACCCCCCCCCADDDDDDDDDAEEEEEEEEEA ACCCCCCCCCADDDDDDDDDAEEEEEEEEEA ACCCCCCCCCADDDDDDDDDAEEEEEEEEEA AAAAAAAAAAAAAAAAAAAAAAAAAAAAAAA 
