model
size = 23 12 29, scale = 0.05, origin = -y
material 
  colors = A:#111 B:#444 C:#CA1515 D:#EEE
voxels
-------AAAAAAAAA------- -------AAAAAAAAA------- ----------------------- ----------------------- ----------------------- ----------------------- ----------------------- ----------------------- ----------------------- ----------------------- ----------------------- ----------------------- 
------AAABBBBBAAA------ ------AADDDDDDDAA------ ----------------------- ----------------------- ----------------------- ----------------------- ----------------------- ----------------------- ----------------------- ----------------------- ----------------------- ----------------------- 
-----AAABAAAAABAAA----- -----AADAAAAAAADAA----- ----------------------- ----------------------- ----------------------- ----------------------- ----------------------- ----------------------- ----------------------- ----------------------- ----------------------- ----------------------- 
----AAABABBBBBABAAA---- ----AADAAAAAAAAADAA---- ----------------------- ----------------------- ----------------------- ----------------------- ----------------------- ----------------------- ----------------------- ----------------------- ----------------------- ----------------------- 
---AAABABAAAAABABAAA--- ---AADAAAAAAAAAAADAA--- ----------------------- ----------------------- ----------------------- ----------------------- ----------------------- ----------------------- ----------------------- ----------------------- ----------------------- ----------------------- 
---AABABABBBBBABABAA--- ---ADAAAAAAAAAAAAADA--- ----------------------- ----------------------- ----------------------- ----------------------- ----------------------- ----------------------- ----------------------- ----------------------- ----------------------- ----------------------- 
--AABABABAAAAABABABAA-- --AADAAAAAAAAAAAAADAA-- ----------------------- ----------------------- ----------------------- ----------------------- ----------------------- ----------------------- ----------------------- ----------------------- ----------------------- ----------------------- 
--ABABABAABBBAABABABA-- --ADAAAAAAAAAAAAAAADA-- ----------CCC---------- ---------C---C--------- --------C---C-C-------- --------C--C--C-------- --------C-C---C-------- ---------C---C--------- ----------CCC---------- ----------------------- ----------------------- ----------------------- 
--ABABABABAAABABABABA-- --ADAAAAAAAAAAAAAAADA-- ------AAAACCCAAAA------ ------AAACAAACAAA------ ------AACAAACACAA------ ------AACAACAACAA------ ------AACACAAACAA------ -------AACAAACAA------- --------AAAAAAA-------- ----------------------- ----------------------- ----------------------- 
--ABABAAAAAAAAAAABABA-- --ADAAAAAAAAAAAAAAADA-- ----AAA----A----AAA---- ----AAA----A----AAA---- -----AA----A----AA----- -----AA----A----AA----- -----AA----A----AA----- ------AAAAAAAAAAA------ -------AAAAAAAAA------- ----------------------- ----------------------- ----------------------- 
--ABAAA---------AAABA-- --AAAAA---------AAAAA-- ---AAA-----------AAA--- ---AAA-----------AAA--- ----AA-----------AA---- ----AA-----------AA---- ----AAA---------AAA---- -----AAAAAAAAAAAAA----- ------AAAAAAAAAAA------ ----------AAA---------- ----------------------- ----------------------- 
--AAAA-----------AAAA-- --AAAA-----------AAAA-- --AAAA-----------AAAA-- --AAAA-----------AAAA-- ---AAA-----------AAA--- ---AAA-----------AAA--- ----AAA---------AAA---- -----AA---------AA----- ------AAAAAAAAAAA------ --------AAAAAAA-------- ----------------------- ----------------------- 
--AA---------------AA-- --AA---------------AA-- --A-----------------A-- --A-----------------A-- ---A---------------A--- ---A---------------A--- ----AAA---------AAA---- ----AAA---------AAA---- ------AAAAAAAAAAA------ --------AAAAAAA-------- ----------------------- ----------------------- 
-AAA---------------AAA- -AAA---------------AAA- -AA-----------------AA- -AA-----------------AA- --AA---------------AA-- --AA---------------AA-- ---A---------------A--- ---AAA-----------AAA--- -----AAAAAAAAAAAAA----- -------AAAAAAAAA------- ----------------------- ----------------------- 
-AA-----------------AA- -AA-----------------AA- -A-------------------A- -A-------------------A- --A-----------------A-- --A-----------------A-- ---A---------------A--- ---AAA-----------AAA--- -----AAAA-----AAAA----- -------AAAAAAAAA------- ----------AAA---------- ----------------------- 
AAA-----------------AAA AAA-----------------AAA AA-------------------AA -A-------------------A- -AA-----------------AA- --A-----------------A-- --AA---------------AA-- ---AAA-----------AAA--- ----AAAA-------AAAA---- ------AAAAAAAAAAA------ ---------AAAAA--------- ----------------------- 
AA-------------------AA AA-------------------AA AA-------------------AA AA-------------------AA -AA-----------------AA- -AA-----------------AA- --AA---------------AA-- --AAAA-----------AAAA-- ----AAAA-------AAAA---- ------AAAAAAAAAAA------ --------AAAAAAA-------- ----------DDD---------- 
AA-------------------AA AA-------------------AA AA-------------------AA AA-------------------AA -AA-----------------AA- -AA-----------------AA- --AA---------------AA-- --AAAA-----------AAAA-- ----AAAA-------AAAA---- ------AAAAAAAAAAA------ --------AAAAAAA-------- ----------DDD---------- 
AA-------------------AA AA-------------------AA AA-------------------AA AA-------------------AA -AA-----------------AA- -AA-----------------AA- --AA---------------AA-- --AAAA-----------AAAA-- ----AAAA-------AAAA---- ------AAAAAAAAAAA------ --------AAAAAAA-------- ----------DDD---------- 
AA-------------------AA AA-------------------AA AA-------------------AA AA-------------------AA -AA-----------------AA- -AA-----------------AA- --AA---------------AA-- --AAAA-----------AAAA-- ----AAAAAA---AAAAAA---- ------AAAAAAAAAAA------ ---------AAAAA--------- ----------------------- 
AA-------------------AA AA-------------------AA AA-------------------AA -A-------------------A- -AA-----------------AA- --A-----------------A-- --AA---------------AA-- ---AAA-----------AAA--- -----AAAAA---AAAAA----- -------AAAAAAAAA------- ----------AAA---------- ----------------------- 
AAA-----------------AAA AAA-----------------AAA -A-------------------A- -A-------------------A- --A-----------------A-- --A-----------------A-- ---A---------------A--- ---AAAAA-------AAAAA--- -----AAAAAAAAAAAAA----- -------AAAAAAAAA------- ----------------------- ----------------------- 
-AA-----------------AA- -AA-----------------AA- -A-------------------A- -A-------------------A- --A-----------------A-- --A-----------------A-- ---AAAA---------AAAA--- ---AAAAA-------AAAAA--- -----AAAAAAAAAAAAA----- -------AAAAAAAAA------- ----------------------- ----------------------- 
-AAA---------------AAA- -AAA---------------AAA- -AA-----------------AA- --A-----------------A-- --A-----------------A-- ---AAA-----------AAA--- ---AAAA---------AAAA--- ----AAAA-------AAAA---- ------AAAAAAAAAAA------ ---------AAAAA--------- ----------------------- ----------------------- 
--AAA-------------AAA-- --AAA-------------AAA-- --AAA-------------AAA-- --AAA-------------AAA-- ---AA-------------AA--- ---AAA-----------AAA--- ----AAA---------AAA---- -----AAAAAAAAAAAAA----- -------AAAAAAAAA------- ----------------------- ----------------------- ----------------------- 
--AAA-------------AAA-- --AAA-------------AAA-- --AAA-------------AAA-- --AAA-------------AAA-- ----A-------------A---- ----AA-----------AA---- -----AA---------AA----- -------AAAAAAAAA------- ---------AAAAA--------- ----------------------- ----------------------- ----------------------- 
---AAAA---------AAAA--- ---AAAA---------AAAA--- ---AAA-----------AAA--- ---AAA-----------AAA--- -----A-----------A----- -----A-----------A----- ------AAAAAAAAAAA------ ---------AAAAA--------- ----------------------- ----------------------- ----------------------- ----------------------- 
----AAAAA-----AAAAA---- ----AAAAA-----AAAAA---- ----AAAAA-----AAAAA---- ----AAAAAA---AAAAAA---- ------AAAAAAAAAAA------ ------AAAAAAAAAAA------ ---------AAAAA--------- ----------------------- ----------------------- ----------------------- ----------------------- ----------------------- 
------AAAAAAAAAAA------ ------AAAAAAAAAAA------ ------AAA-----AAA------ ------AAAA---AAAA------ --------AAAAAAA-------- ---------AAAAA--------- ----------------------- ----------------------- ----------------------- ----------------------- ----------------------- ----------------------- 
