model
size = 29 14 28, scale = 0.05, origin = -y
material 
  colors = A:#FF6905 B:#0A0000 C:#FFF D:#F6D644 E:#F2AB14 F:#F28214 G:#F29114 H:#FDF4B9 I:#B9E7FD J:#F23914 K:#4AA7F6 L:#1352F1 M:#FAEB88 N:#1224B0 O:#F26D14 P:#030303 Q:#912407
voxels
------------B---B------------ ------------BB-BB------------ ------------JB-BJ------------ ------------JQBQJ------------ -----------OJQQQJO----------- -----------OJJQJJO----------- -----------OOJQJOO----------- -----------OOJQJOO----------- -----------OOJQJOO----------- -----------OOJQJOO----------- ------------OJQJO------------ ------------AAJAA------------ -------------AAA------------- -------------BBB------------- 
---------BBBB---BBBB--------- --------EGFABB-BBAFGE-------- -------EEGFAAB-BAAFGEE------- -------EEGFAAABAAAFGEE------- -------EEGFAAAAAAAFGEE------- -------DEGFAAAAAAAFGED------- -------DEGFAAAAAAAFGED------- -------DEGFAAAAAAAFGED------- -------DEGFAAAAAAAFGED------- -------DEGFAAAAAAAFGED------- -------DEGFFAAAAAFFGED------- --------EGFFAAAAAFFGE-------- ---------EGFAAAAAFGE--------- ---------BBBBBBBBBBB--------- 
-----BBBBBBBB---BBBBBBBB----- ---BBBDDAAAABB-BBAAAADDBBB--- ---HMMDAAAAAAB-BAAAAAADMMH--- ---HMMDAAAAAAABAAAAAAADMMH--- ---HMMDAAAAAAAAAAAAAAADMMH--- ---IHMDAAAAAAAAAAAAAAADMHI--- ---IHMDAAAAAAAAAAAAAAADMHI--- ---IHMDAAAAAAAAAAAAAAADMHI--- ---IHMDAAAAAAAAAAAAAAADMHI--- ---IHMDAAAAAAAAAAAAAAADMHI--- ---IHMDAAAAAAAAAAAAAAADMHI--- ----HMDDAAAAAAAAAAAAADDMH---- ----HMMDDAAAAAAAAAAADDMMH---- ----BBBBBBBBBBBBBBBBBBBBB---- 
-----BBBBBBBB---BBBBBBBB----- --BBBBAAAAAABB-BBAAAAAABBBB-- --BAAAAAAAAAAB-BAAAAAAAAAAB-- --IAAAAAAAAAAABAAAAAAAAAAAI-- --IAAAAAAAAAAAAAAAAAAAAAAAI-- --IAAAAAAAAAAAAAAAAAAAAAAAI-- --KAAAAAAAAAAAAAAAAAAAAAAAK-- --KAAAAAAAAAAAAAAAAAAAAAAAK-- --KAAAAAAAAAAAAAAAAAAAAAAAK-- --KAAAAAAAAAAAAAAAAAAAAAAAK-- --KAAAAAAAAAAAAAAAAAAAAAAAK-- --KIAAAAAAAAAAAAAAAAAAAAAIK-- --BIAAAAAAAAAAAAAAAAAAAAAIB-- ---BBBBBBBBBBBBBBBBBBBBBBB--- 
-----BBBBBBBB---BBBBBBBB----- --BBBBAAAAAABB-BBAAAAAABBBB-- -BBAAAAAAAAAAB-BAAAAAAAAAABB- -KAAAAAAAAAAAABAAAAAAAAAAAAK- -KAAAAAAAAAAJAAAJAAAAAAAAAAK- -LAAAAAAAAAAJQAQJAAAAAAAAAAL- -LAAAAAAAAAAJJQJJAAAAAAAAAAL- -LAAAAAAAAAAAJQJAAAAAAAAAAAL- -LAAAAAAAAAAAJQJAAAAAAAAAAAL- -LAAAAAAAAAAAJQJAAAAAAAAAAAL- -LAAAAAAAAAAAAJAAAAAAAAAAAAL- -BAAAAAAAAAAAAJAAAAAAAAAAAAB- -BBBAAAAAAAAAAAAAAAAAAAAAABB- ---BBBBBBBBBBBBBBBBBBBBBBB--- 
-----BBBBBBBB---BBBBBBBB----- --BBBBAAAAAABB-BBAAAAAABBBB-- BBBAAAAAAAFAAB-BAAFAAAAAAABBB BAAAAAAAAAFAABBBAAFAAAAAAAAAB NAAAAAAAAAFA-BBB-AFAAAAAAAAAN NAAAAAAAAAFA--B--AFAAAAAAAAAN NAAAAAAAAAGF-----FGAAAAAAAAAN NAAAAAAAAAGF-----FGAAAAAAAAAN NAAAAAAAAAGF-----FGAAAAAAAAAN NAAAAAAAAAGF-----FGAAAAAAAAAN BAAAAAAAAAGF-----FGAAAAAAAAAB BBAAAAAAAAGF-----FGAAAAAAAABB -BBBAAAAAAAABBBBBAAAAAAAAABB- ---BBBBBBBBBBBBBBBBBBBBBBB--- 
-----BBBBBBBB---BBBBBBBB----- --BBBBAAAABBBB-BBBBAAAABBBB-- BBBAAAADEG---B-B---GEDAAAABBB BAAAAAADEG---BBB---GEDAAAAAAB BAAAAAADEG---BBB---GEDAAAAAAB BAAAAAADEG----B----GEDAAAAAAB BAAAAAAHDE---------EDHAAAAAAB BAAAAAAHDE---------EDHAAAAAAB BAAAAAAHDE---------EDHAAAAAAB BAAAAAAHDE---------EDHAAAAAAB BAAAAAAHDE---------EDHAAAAAAB BBAAAAAHDE---------EDHAAAAABB -BBBAAAAAABBBBBBBBBAAAAAAABB- ---BBBBBBBBBBBBBBBBBBBBBBB--- 
-----BBBBBBBB---BBBBBBBB----- --BBBBABBBBBBB-BBBBBBBABBBB-- BBBLKIH------B-B------HIKLBBB BAALKIH------BBB------HIKLAAB BAALKIH------BBB------HIKLAAB BAALKIH-------B-------HIKLAAB BAANLKI---------------IKLNAAB BAANLKI---------------IKLNAAB BAANLKI---------------IKLNAAB BAANLKI---------------IKLNAAB BAANLKI---------------IKLNAAB BBANLKI---------------IKLNABB -BBBAAABBBB-------BBBBAAAABB- ---BBBBBBBB-------BBBBBBBB--- 
-----BBBBBBBB---BBBBBBBB----- --BBBBBBB---BB-BB---BBBBBBB-- BBBB---------B-B---------BBBB BPP----------BBB----------PPB -PB-----------B-----------BB- BPB-----------------------BBB -PB-----------------------BP- BPB-----------------------BPB -PB-----------------------BP- BPB-----------------------BPB BPB-----------------------BPB BBBB---------------------BPBB -BBBBBBB-------------BBBBBBB- ---BBBBB-------------BBBBB--- 
----------------------------- ----------------------------- ----------------------------- B---------------------------B B---------------------------B B---------------------------B B---------------------------B B---------------------------B B---------------------------B B---------------------------B ----------------------------- ----------------------------- ----------------------------- ----------------------------- 
----------------------------- ----------------------------- ----------------------------- B---------------------------B C---------------------------C C---------------------------C C---------------------------C B---------------------------C C---------------------------C B---------------------------B ----------------------------- ----------------------------- ----------------------------- ----------------------------- 
----------------------------- ----------------------------- ----------------------------- B---------------------------B C---------------------------C B---------------------------B C---------------------------B B---------------------------B C---------------------------C B---------------------------B ----------------------------- ----------------------------- ----------------------------- ----------------------------- 
----------------------------- ----------------------------- ----------------------------- B---------------------------B C---------------------------C B---------------------------B C---------------------------B C---------------------------B C---------------------------C B---------------------------B ----------------------------- ----------------------------- ----------------------------- ----------------------------- 
----------------------------- ----------------------------- ----------------------------- B---------------------------B B---------------------------B B---------------------------B B---------------------------B B---------------------------B B---------------------------B B---------------------------B ----------------------------- ----------------------------- ----------------------------- ----------------------------- 
----------------------------- ----------------------------- ----------------------------- B---------------------------B C---------------------------C B---------------------------C B---------------------------C B---------------------------C B---------------------------C B---------------------------B ----------------------------- ----------------------------- ----------------------------- ----------------------------- 
----------------------------- ----------------------------- ----------------------------- B---------------------------B C---------------------------B B---------------------------B B---------------------------C B---------------------------B B---------------------------C B---------------------------B ----------------------------- ----------------------------- ----------------------------- ----------------------------- 
----------------------------- ----------------------------- ----------------------------- B---------------------------B C---------------------------C C---------------------------C C---------------------------B C---------------------------C C---------------------------C B---------------------------B ----------------------------- ----------------------------- ----------------------------- ----------------------------- 
----------------------------- ----------------------------- ----------------------------- B---------------------------B B---------------------------B B---------------------------B B---------------------------B B---------------------------B B---------------------------B B---------------------------B ----------------------------- ----------------------------- ----------------------------- ----------------------------- 
----------------------------- ----------------------------- ----------------------------- B---------------------------B C---------------------------B B---------------------------B C---------------------------C B---------------------------C C---------------------------C B---------------------------B ----------------------------- ----------------------------- ----------------------------- ----------------------------- 
----------------------------- ----------------------------- ----------------------------- BB-------------------------BB CC-------------------------CC BC-------------------------CC CC-------------------------CC BC-------------------------BB CC-------------------------BB BB-------------------------BB ----------------------------- ----------------------------- ----------------------------- ----------------------------- 
----------------------------- ----------------------------- ----------------------------- -BB-----------------------BB- -CB-----------------------BB- -CB-----------------------BB- -CB-----------------------CC- -CB-----------------------CC- -CB-----------------------CC- -BB-----------------------BB- ----------------------------- ----------------------------- ----------------------------- ----------------------------- 
----------------------------- ----------------------------- ----------------------------- --BB---------------------BB-- --BC---------------------BB-- --BC---------------------BB-- --BB---------------------BB-- --BC---------------------BB-- --BC---------------------BB-- --BB---------------------BB-- ----------------------------- ----------------------------- ----------------------------- ----------------------------- 
----------------------------- ----------------------------- ----------------------------- ---BB-------------------BB--- ---CB-------------------CC--- ---CB-------------------CC--- ---BC-------------------CC--- ---CC-------------------CC--- ---CB-------------------CC--- ---BB-------------------PB--- ----------------------------- ----------------------------- ----------------------------- ----------------------------- 
----------------------------- ----------------------------- ----------------------------- ----BB-----------------BB---- ----BC-----------------BB---- ----CC-----------------BB---- ----CB-----------------CC---- ----CC-----------------CB---- ----BC-----------------CC---- ----BB-----------------BB---- ----------------------------- ----------------------------- ----------------------------- ----------------------------- 
----------------------------- ----------------------------- ----------------------------- -----BB---------------BB----- -----CB---------------BB----- -----CB---------------BB----- -----BB---------------BC----- -----CB---------------BC----- -----CB---------------BC----- -----BB---------------BB----- ----------------------------- ----------------------------- ----------------------------- ----------------------------- 
----------------------------- ----------------------------- ----------------------------- ------BB-------------BB------ ------BC-------------BB------ ------BC-------------BB------ ------BC-------------BB------ ------BC-------------BB------ ------BC-------------CB------ ------BB-------------BB------ ----------------------------- ----------------------------- ----------------------------- ----------------------------- 
----------------------------- ----------------------------- ----------------------------- -------BBB---------BBB------- -------CCC---------BCB------- -------CBC---------BCB------- -------CBC---------BCB------- -------CBC---------BCB------- -------CCC---------CCC------- -------BBB---------BBB------- ----------------------------- ----------------------------- ----------------------------- ----------------------------- 
----------------------------- ----------------------------- ----------------------------- ---------BBBBBBBBBBB--------- ---------CBBCBBCCCBB--------- ---------CBCBCBCBCBB--------- ---------CBCBCBCBCBB--------- ---------CBCBCBCBCBB--------- ---------CBCBCBCCCBC--------- ---------BBBBBBBBBBB--------- ----------------------------- ----------------------------- ----------------------------- ----------------------------- 
