model
size = 29 27 25, scale = 0.05, origin = -y
material 
  colors = A:#9CF B:#0C0 C:#400
voxels
---------AAAAAAA------------- ---------AAAAAAA------------- ---------AAAAAAA------------- ---------AAAAAAA------------- ----------------------------- ----------------------------- ----------------------------- ----------------------------- ----------------------------- ----------------------------- ----------------------------- ----------------------------- ----------------------------- ----------------------------- ----------------------------- ----------------------------- ----------------------------- ----------------------------- ----------------------------- ----------------------------- ----------------------------- ----------------------------- ----------------------------- ----------------------------- ----------------------------- ----------------------------- ----------------------------- 
-------AAAAAAAAAAA----------- -------AAAAAAAAAAA----------- -------AAAAAAAAAAA----------- -------AAAAAAAAAAA----------- ----------------------------- ----------------------------- ----------------------------- ----------------------------- ----------------------------- ----------------------------- ----------------------------- ----------------------------- ----------------------------- ----------------------------- ----------------------------- ----------------------------- ----------------------------- ----------------------------- ----------------------------- ----------------------------- ----------------------------- ----------------------------- ----------------------------- ----------------------------- ----------------------------- ----------------------------- ----------------------------- 
-----AAAAAAAAAAAAAAA--------- -----AAAAAAAAAAAAAAA--------- -----AAAAAAAAAAAAAAA--------- -----AAAAAAAAAAAAAAA--------- ----------------------------- ----------------------------- ----------------------------- ----------------------------- ----------------------------- ----------------------------- ----------------------------- ----------------------------- ----------------------------- ----------------------------- ----------------------------- ----------------------------- ----------------------------- ----------------------------- ----------------------------- ----------------------------- ----------------------------- ----------------------------- ----------------------------- ----------------------------- ----------------------BBB---- ----------------------------- ----------------------------- 
----AAAA-------AAAAAA-------- ----AAAA-------AAAAAA-------- ----AAAA-------AAAAAA-------- ----AAAA-------AAAAAA-------- ----------------------------- ----------------------------- ----------------------------- ----------------------------- ----------------------------- ----------------------------- ----------------------------- ----------------------------- ----------------------------- ----------------------------- ----------------------------- ----------------------------- ----------------------------- ----------------------------- ----------------------------- ----------------------------- ----------------------------- ----------------------------- ----------------------------- ----------------------------- -----------------------B----- ----------------------------- ----------------------------- 
---AAA-----------AAAAA------- ---AAA-----------AAAAA------- ---AAA-----------AAAAA------- ---AAA-----------AAAAA------- ----------------------------- ----------------------------- ----------------------------- ----------------------------- ----------------------------- ----------------------------- ----------------------------- ----------------------------- ----------------------------- ----------------------------- ----------------------------- ----------------------------- ----------------------------- ----------------------------- ----------------------------- ----------------------------- ----------------------------- ----------------------------- ----------------------------- ----------------------------- -----------------------B----- ---------------------BBBBB--- ----------------------------- 
--AAA-------------AAAAA------ --AAA-------------AAAAA------ --AAA-------------AAAAA------ --AAA-------------AAAAA------ ----------------------------- ----------------------------- ----------------------------- ----------------------------- ----------------------------- ----------------------------- ----------------------------- ----------------------------- ----------------------------- ----------------------------- ----------------------------- ----------------------------- ----------------------------- ----------------------------- ----------------------------- ----------------------------- ----------------------------- ----------------------------- ----------------------------- ----------------------------- ----------------------------- -----------------------B----- ----------------------------- 
--AA---------------AAAA------ --AA---------------AAAA------ --AA---------------AAAA------ --AA---------------AAAA------ ----------------------------- ----------------------------- ----------------------------- ----------------------------- ----------------------------- ----------------------------- ----------------------------- ----------------------------- ----------------------------- ----------------------------- ----------------------------- ----------------------------- ----------------------------- ----------------------------- ----------------------------- ----------------------------- ----------------------------- ----------------------------- ----------------------------- ----------------------------- ----------------------------- -----------------------B----- --------------------BBBBBBB-- 
-AA-----------------AAAA----- -AA-----------------AAAA----- -AA-----------------AAAA----- -AA-----------------AAAA----- ----------------------------- ----------------------------- ----------------------------- ----------------------------- ----------------------------- ----------------------------- ----------------------------- ----------------------------- ----------------------------- ----------------------------- ----------------------------- ----------------------------- ----------------------------- ----------------------------- ----------------------------- ----------------------------- ----------------------------- ------------------------C---- ------------------------C---- ----------------------------- ----------------------------- ----------------------------- -----------------------B----- 
-AA-----------------AAAA----- -AA-----------------AAAA----- -AA-----------------AAAA----- -AA-----------------AAAA----- ----------------------------- ----------------------------- ----------------------------- ----------------------------- ----------------------------- ----------------------------- ----------------------------- ----------------------------- ----------------------------- ----------------------------- ----------------------------- ----------------------------- ----------------------------- ----------------------------- ----------------------------- ----------------------------- ------------------------C---- -----------------------CCC--- -----------------------CCC--- ------------------------C---- ----------------------------- -------------------BBBBBBBBB- -----------------------B----- 
AA-------------------AAAA---- AA-------------------AAAA---- AA-------------------AAAA---- AA-------------------AAAA---- ----------------------------- ----------------------------- ----------------------------- ----------------------------- ----------------------------- ----------------------------- ----------------------------- ----------------------------- ----------------------------- ----------------------------- ----------------------------- ----------------------------- ----------------------------- ----------------------------- ----------------------------- ----------------------------- ----------------------------- ------------------------C---- ------------------------C---- ------------------------C---- -----------------------B----- -----------------------B----- ----------------------------- 
AA-------------------AAAA---- AA-------------------AAAA---- AA-------------------AAAA---- AA-------------------AAAA---- ---------------------BBB----- ----------------------BB----- ---------------------BB------ ---------------------BBB----- ----------------------BB----- ---------------------BB------ ---------------------BBB----- ----------------------BB----- ---------------------BBB----- ---------------------BB------ ---------------------BBB----- ----------------------BB----- ---------------------BB------ ----------------------BB----- ---------------------BB------ ----------------------BBB---- -----------------------BB---- ----------------------BB----- -----------------------BBB--- ------------------------BB--- -----------------------BB---- ----------------------------- ----------------------------- 
AA-------------------AAAA---- AA-------------------AAAA---- AA-------------------AAAA---- AA-------------------AAAA---- ---------------------BBB----- ---------------------BBB----- ---------------------BBB----- ---------------------BBB----- ---------------------BBB----- ---------------------BBB----- ---------------------BBB----- ---------------------BBB----- ---------------------BBB----- ---------------------BBB----- ---------------------BBB----- ---------------------BBB----- ---------------------BBB----- ---------------------BBB----- ---------------------BBB----- ----------------------BBB---- ----------------------BBB---- ----------------------BBB---- -----------------------BBB--- -----------------------BBB--- -----------------------BBB--- ----------------------------- ----------------------------- 
AA-------------------AAAA---- AA-------------------AAAA---- AA-------------------AAAA---- AA-------------------AAAA---- ---------------------BBB----- ---------------------BB------ ----------------------BB----- ---------------------BBB----- ---------------------BB------ ----------------------BB----- ---------------------BBB----- ---------------------BB------ ----------------------BB----- ---------------------BBB----- ---------------------BBB----- ---------------------BB------ ----------------------BB----- ---------------------BB------ ----------------------BB----- ----------------------BBB---- ----------------------BB----- -----------------------BB---- -----------------------BBB--- -----------------------BB---- ------------------------BB--- ----------------------------- ----------------------------- 
AA-------------------AAAA---- AA-------------------AAAA---- AA-------------------AAAA---- AA-------------------AAAA---- ----------------------------- ----------------------------- ----------------------------- ----------------------------- ----------------------------- ----------------------------- ----------------------------- ----------------------------- ----------------------------- ----------------------------- ----------------------------- ----------------------------- ----------------------------- ----------------------------- ----------------------------- ----------------------------- ------------------------C---- ------------------------C---- ------------------------C---- ----------------------------- ------------------------B---- ------------------------B---- ----------------------------- 
AA-------------------AAAA---- AA-------------------AAAA---- AA-------------------AAAA---- AA-------------------AAAA---- -----------------------B----- -----------------------B----- -----------------------BB---- ------------------------B---- ----------------------------- ----------------------------- ----------------------------- ----------------------------- ----------------------------- ----------------------------- ----------------------------- ----------------------------- ----------------------------- ----------------------------- ----------------------------- ------------------------C---- -----------------------CCC--- -----------------------CCC--- ------------------------C---- ----------------------------- ----------------------------- -----------------------BB---- ----------------------------- 
AA-------------------AAAA---- AA-------------------AAAA---- AA-------------------AAAA---- AA-------------------AAAA---- ----------------------B------ ----------------------B------ ----------------------------- ----------------------------- ----------------------------- ----------------------------- ----------------------------- ----------------------------- ----------------------------- ----------------------------- ----------------------------- ----------------------------- ----------------------------- ----------------------------- ----------------------------- ----------------------------- ------------------------C---- ------------------------C---- ----------------------------- ----------------------------- ----------------------------- --------------------BBBBBBBBB ----------------------------- 
-AA-----------------AAAA----- -AA-----------------AAAA----- -AA-----------------AAAA----- -AA-----------------AAAA----- ----------------------------- ----------------------B------ ----------------------B------ ----------------------BB----- ----------------------------- ----------------------------- ----------------------------- ----------------------------- ----------------------------- ----------------------------- ----------------------------- ----------------------------- ----------------------------- ----------------------------- ----------------------------- ----------------------------- ----------------------------- ----------------------------- ----------------------------- ----------------------------- ----------------------------- ------------------------B---- ----------------------------- 
-AA-----------------AAAA----- -AA-----------------AAAA----- -AA-----------------AAAA----- -AA-----------------AAAA----- ----------------------------- ----------------------------- ----------------------------- -----------------------B----- ----------------------------- ----------------------------- ----------------------------- ----------------------------- ----------------------------- ----------------------------- ----------------------------- ----------------------------- ----------------------------- ----------------------------- ----------------------------- ----------------------------- ----------------------------- ----------------------------- ----------------------------- ----------------------------- ------------------------B---- ---------------------BBBBBBB- ----------------------------- 
--AA---------------AAAA------ --AA---------------AAAA------ --AA---------------AAAA------ --AA---------------AAAA------ ----------------------------- ----------------------------- ----------------------------- ----------------------------- ----------------------------- ----------------------------- ----------------------------- ----------------------------- ----------------------------- ----------------------------- ----------------------------- ----------------------------- ----------------------------- ----------------------------- ----------------------------- ----------------------------- ----------------------------- ----------------------------- ----------------------------- ----------------------------- ------------------------B---- ------------------------B---- ----------------------------- 
--AAA-------------AAAAA------ --AAA-------------AAAAA------ --AAA-------------AAAAA------ --AAA-------------AAAAA------ ----------------------------- ----------------------------- ----------------------------- ----------------------------- ----------------------------- ----------------------------- ----------------------------- ----------------------------- ----------------------------- ----------------------------- ----------------------------- ----------------------------- ----------------------------- ----------------------------- ----------------------------- ----------------------------- ----------------------------- ----------------------------- ----------------------------- ------------------------B---- ----------------------BBBBB-- ----------------------------- ----------------------------- 
---AAA-----------AAAAA------- ---AAA-----------AAAAA------- ---AAA-----------AAAAA------- ---AAA-----------AAAAA------- ----------------------------- ----------------------------- ----------------------------- ----------------------------- ----------------------------- ----------------------------- ----------------------------- ----------------------------- ----------------------------- ----------------------------- ----------------------------- ----------------------------- ----------------------------- ----------------------------- ----------------------------- ----------------------------- ----------------------------- ----------------------------- ----------------------------- ------------------------B---- ------------------------B---- ----------------------------- ----------------------------- 
----AAAA-------AAAAAA-------- ----AAAA-------AAAAAA-------- ----AAAA-------AAAAAA-------- ----AAAA-------AAAAAA-------- ----------------------------- ----------------------------- ----------------------------- ----------------------------- ----------------------------- ----------------------------- ----------------------------- ----------------------------- ----------------------------- ----------------------------- ----------------------------- ----------------------------- ----------------------------- ----------------------------- ----------------------------- ----------------------------- ----------------------------- ----------------------------- ----------------------------- -----------------------BBB--- ----------------------------- ----------------------------- ----------------------------- 
-----AAAAAAAAAAAAAAA--------- -----AAAAAAAAAAAAAAA--------- -----AAAAAAAAAAAAAAA--------- -----AAAAAAAAAAAAAAA--------- ----------------------------- ----------------------------- ----------------------------- ----------------------------- ----------------------------- ----------------------------- ----------------------------- ----------------------------- ----------------------------- ----------------------------- ----------------------------- ----------------------------- ----------------------------- ----------------------------- ----------------------------- ----------------------------- ----------------------------- ----------------------------- ----------------------------- ----------------------------- ----------------------------- ----------------------------- ----------------------------- 
-------AAAAAAAAAAA----------- -------AAAAAAAAAAA----------- -------AAAAAAAAAAA----------- -------AAAAAAAAAAA----------- ----------------------------- ----------------------------- ----------------------------- ----------------------------- ----------------------------- ----------------------------- ----------------------------- ----------------------------- ----------------------------- ----------------------------- ----------------------------- ----------------------------- ----------------------------- ----------------------------- ----------------------------- ----------------------------- ----------------------------- ----------------------------- ----------------------------- ----------------------------- ----------------------------- ----------------------------- ----------------------------- 
---------AAAAAAA------------- ---------AAAAAAA------------- ---------AAAAAAA------------- ---------AAAAAAA------------- ----------------------------- ----------------------------- ----------------------------- ----------------------------- ----------------------------- ----------------------------- ----------------------------- ----------------------------- ----------------------------- ----------------------------- ----------------------------- ----------------------------- ----------------------------- ----------------------------- ----------------------------- ----------------------------- ----------------------------- ----------------------------- ----------------------------- ----------------------------- ----------------------------- ----------------------------- ----------------------------- 
