model
size = 13 23 15, scale = 0.05, origin = -y
material 
  colors = A:#CA7A2C B:#ECB88A C:#724832 D:#EEE E:#6C6A2D F:#111
voxels
------------C ------------C -----------CC -----------CC -----------CC -----------CC -----------CC -----------CC -----------CC -----------CC -----------CC -----------CC -----------CC -----------CC CC---------CC CC---------CC CC---------CC CC-C-C--C--CC CCCCCC-CCC-CC CCCCCCCCCCCCC CCCCCCCCCCCCC -CCCCCCCCCCC- ------------- 
------------- ------------- ------------- ------------- ------------- ------------- ------------- ------------- ------------- -BBBBBBBBBBBC -BBBCCCCCBBBC -BBBBBBBBBBBC -BBBBBBBBBBBC CDDDDDBDDDDBC CBEEEDBDEEEBC CBEFEDBDEFEBC CBEEEDBDEEEBC CBDBDBBDBDDBC CBBBBBBBBBBBC CBBBBBBBBBBBC CBBBBBBBBBBBC CBBBBBBBBBBBC -CCCCCCCCCCC- 
------------- ------------- ------------- ------------- ------------- ------------- ------------- ------------- ------------- -BBBBBBBBBBB- -BAAAAAAAAAAC -BAAAAAAAAAAC -BAAAAAAAAAAC -BAAAAAAAAAAC -BAAAAAAAAAAC CBAAAAAAAAAAC CBAAAAAAAAAAC CBAAAAAAAAAAC CBAAAAAAAAAAC CBAAAAAAAAAAC CBAAAAAAAAAAC CBBBBBBBBBBBC -CCCCCCCCCCC- 
------------- ------------- ------------- ------------- ------------- ------------- ------------- ------------- ------------- -BBBBBBBBBBB- -BAAAAAAAAAB- -BAAAAAAAAAB- -BAAAAAAAAAB- -BAAAAAAAAAAC -BAAAAAAAAAAC CBAAAAAAAAAAC CBAAAAAAAAAAC CBAAAAAAAAAAC CBAAAAAAAAAAC CBAAAAAAAAAAC CBAAAAAAAAAAC CBBBBBBBBBBBC -CCCCCCCCCCC- 
------------- ------------- ------------- ------------- ------------- ------------- ------------- ------------- ------------- -BBBBBBBBBBB- -BAAAAAAAAAB- -BAAAAAAAAAB- -BAAAAAAAAAB- -BAAAAAAAAAB- CBAAAAAAAAAAC CBAAAAAAAAAAC CBAAAAAAAAAAC CBAAAAAAAAAAC CBAAAAAAAAAAC CBAAAAAAAAAAC CBAAAAAAAAAAC CBBBBBBBBBBBC -CCCCCCCCCCC- 
------------- ------------- ------------- ------------- ------------- ------------- ------------- ------------- ------------- -BBBBBBBBBBB- -BAAAAAAAAAB- -BAAAAAAAAAB- -BAAAAAAAAAB- -BAAAAAAAAAB- -BAAAAAAAAAAC CBAAAAAAAAAAC CBAAAAAAAAAAC CBAAAAAAAAAAC CBAAAAAAAAAAC CBAAAAAAAAAAC CBAAAAAAAAAAC CBBBBBBBBBBBC -CCCCCCCCCCC- 
------------- ------------- ------------- ------------- ------------- ------------- ------------- ------------- ------------- -BBBBBBBBBBB- -BAAAAAAAAAB- -BAAAAAAAAAB- -BAAAAAAAAAB- -BAAAAAAAAAAC CBAAAAAAAAAAC CBAAAAAAAAAAC CBAAAAAAAAAAC CBAAAAAAAAAAC CBAAAAAAAAAAC CBAAAAAAAAAAC CBAAAAAAAAAAC CBBBBBBBBBBBC -CCCCCCCCCCC- 
------------- ------------- ------------- ------------- ------------- ------------- ------------- ------------- ------------- -BBBBBBBBBBB- -BAAAAAAAAAB- -BAAAAAAAAAB- -BBBBBBBBBBB- -BAAAAAAAAAAC CBAAAAAAAAAAC CBAAAAAAAAAAC CBAAAAAAAAAAC CBAAAAAAAAAAC CBAAAAAAAAAAC CBAAAAAAAAAAC CBAAAAAAAAAAC CBBBBBBBBBBBC -CCCCCCCCCCC- 
------------- ------------- ------------- ------------- ------------- ------------- ------------- ------------- ------------- -BBBBBBBBBBB- -BAAAAAAAAAB- -BAAAAAAAAAB- -BAAAAAAAAAB- CBAAAAAAAAAB- CBAAAAAAAAAAC CBAAAAAAAAAAC CBAAAAAAAAAAC CBAAAAAAAAAAC CBAAAAAAAAAAC CBAAAAAAAAAAC CBAAAAAAAAAAC CBBBBBBBBBBBC -CCCCCCCCCCC- 
------------- ------------- ------------- ------------- ------------- ------------- ------------- ------------- ------------- -BBBBBBBBBBB- -BAAAAAAAAAB- -BAAAAAAAAAB- -BAAAAAAAAAB- -BAAAAAAAAAB- CBAAAAAAAAAAC CBAAAAAAAAAAC CBAAAAAAAAAAC CBAAAAAAAAAAC CBAAAAAAAAAAC CBAAAAAAAAAAC CBAAAAAAAAAAC CBBBBBBBBBBBC -CCCCCCCCCCC- 
------------- ------------- ------------- ------------- ------------- ------------- ------------- ------------- ------------- -BBBBBBBBBBB- -BAAAAAAAAAB- -BAAAAAAAAAB- -BAAAAAAAAAB- -BAAAAAAAAAB- CBAAAAAAAAAAC CBAAAAAAAAAAC CBAAAAAAAAAAC CBAAAAAAAAAAC CBAAAAAAAAAAC CBAAAAAAAAAAC CBAAAAAAAAAAC CBBBBBBBBBBBC -CCCCCCCCCCC- 
------------- ------------- ------------- ------------- ------------- ------------- ------------- ------------- ------------- -BBBBBBBBBBB- -BAAAAAAAAAB- -BAAAAAAAAAB- -BAAAAAAAAAB- -BAAAAAAAAAB- CBAAAAAAAAAB- CBAAAAAAAAAAC CBAAAAAAAAAAC CBAAAAAAAAAAC CBAAAAAAAAAAC CBAAAAAAAAAAC CBAAAAAAAAAAC CBBBBBBBBBBBC -CCCCCCCCCCC- 
------------- ------------- ------------- ------------- ------------- ------------- ------------- ------------- ------------- -BBBBBBBBBBB- -BAAAAAAAAAB- -BAAAAAAAAAB- -BAAAAAAAAAB- CBAAAAAAAAAAC CBAAAAAAAAAAC CBAAAAAAAAAAC CBAAAAAAAAAAC CBAAAAAAAAAAC CBAAAAAAAAAAC CBAAAAAAAAAAC CBAAAAAAAAAAC CBBBBBBBBBBBC -CCCCCCCCCCC- 
------------- ------------- ------------- ------------- ------------- ------------- ------------- ------------- ------------- -BBBBBBBBBBB- -BBBBBBBBBBB- -BBBBBBBBBBB- -BBBBBBBBBBBC CBBBBBBBBBBBC CBBBBBBBBBBBC CBBBBBBBBBBBC CBBBBBBBBBBBC CBBBBBBBBBBBC CBBBBBBBBBBBC CBBBBBBBBBBBC CBBBBBBBBBBBC CBBBBBBBBBBBC -CCCCCCCCCCC- 
------------- ------------- ------------- ------------- ------------- ------------- ------------- ------------- ------------- ------------- ------------- ---CC---CC--- CCCCCCCCCCCCC CCCCCCCCCCCCC CCCCCCCCCCCCC CCCCCCCCCCCCC CCCCCCCCCCCCC CCCCCCCCCCCCC CCCCCCCCCCCCC CCCCCCCCCCCCC CCCCCCCCCCCCC -CCCCCCCCCCC- ------------- 
