model
size = 13 7 27, scale = 0.05, origin = -y
material 
  colors = A:#F9BF45 B:#C99833
voxels
------------- ------------- ------------- ------B------ ------------- ------------- ------------- 
------------- ------B------ ------------- ------B------ ------------- ------B------ ------------- 
------------- ------------- ------B------ ------B------ ------B------ ------------- ------------- 
------B------ ------B------ ------B------ -----ABA----- ------B------ ------B------ ------B------ 
------------- ------------- ------B------ -----ABA----- ------B------ ------------- ------------- 
------------- ------B------ ------------- -----ABA----- ------------- ------B------ ------------- 
------------- ------------- ------------- -----ABA----- ------------- ------------- ------------- 
------------- ------------- ------------- -----A-A----- ------------- ------------- ------------- 
------------- ------------- ------------- -----AAA----- ------------- ------------- ------------- 
------------- ------------- ------------- ------A------ ------------- ------------- ------------- 
------------- ------------- ------------- ------A------ ------------- ------------- ------------- 
------------- ------------- ------------- ------A------ ------------- ------------- ------------- 
------------- ------------- ------------- ------A------ ------------- ------------- ------------- 
------------- ------------- ------------- ------A------ ------------- ------------- ------------- 
------------- ------------- ------------- ------A------ ------------- ------------- ------------- 
------------- ------------- ------A------ ------A------ ------A------ ------------- ------------- 
------------- ------------- ---AAAAAAA--- ---AAAAAAA--- ---AAAAAAA--- ------------- ------------- 
------------- ------------- --AA------A-- --AA-----AA-- --AA-----AA-- ------------- ------------- 
------------- ------------- -AA-------AA- -AA-------AA- -AA-------AA- ------------- ------------- 
------------- ------------- -A---------A- -A---------A- -A---------A- ------------- ------------- 
------------- ------------- AA---------AA AA---------AA AA---------AA ------------- ------------- 
------------- ------------- A-----------A ------------- A-----------A ------------- ------------- 
------------- ------------- A-----------A A-----------A A-----------A ------------- ------------- 
------------- ------------- A-----------A A-----------A A-----------A ------------- ------------- 
------------- ------------- A-----------A ------------- A-----------A ------------- ------------- 
------------- ------------- A-----------A A-----------A A-----------A ------------- ------------- 
------------- ------------- ------------- A-----------A ------------- ------------- ------------- 
