model
size = 9 29 5, scale = 0.05, origin = -y
material 
  colors = A:#7DFF09
voxels
--------- --------- ----A---- ---AAA--- ---AAA--- --AAAAA-- -AAAAAAA- -AAA-AAA- -AA---AA- -AA---AA- -AA---AA- -AA---AA- -AA---AA- AAA---AAA AA-----AA AA-----AA AA-----AA AA-----AA AA-----AA AA-----AA AA-----AA AA-----AA AA-----AA AA-----AA AA-----AA AA-----AA AA-----AA AA-----AA --------- 
----A---- ----A---- ----A---- --------- --------- --------- --------- --------- --------- --------- --------- --------- --------- --------- --------- --------- --------- --------- --------- --------- --------- --------- --------- --------- --------- --------- --------- A------AA AA-----AA 
----A---- --------- --------- --------- --------- --------- --------- --------- --------- --------- --------- --------- --------- --------- --------- --------- --------- --------- --------- --------- --------- --------- --------- --------- --------- --------- --------- --------- AA-----AA 
----A---- ----A---- ----A---- --------- --------- --------- --------- --------- --------- --------- --------- --------- --------- --------- --------- --------- --------- --------- --------- --------- --------- --------- --------- --------- --------- --------- --------- A------AA AA-----AA 
--------- --------- ----A---- ----A---- ----A---- ----A---- ----A---- ----A---- ----A---- ----A---- ----A---- ----A---- ----A---- ----A---- ----A---- ----A---- ----A---- ---AAA--- ---AAA--- ---AAA--- ---AAA--- ---AAA--- ---A-A--- --AA-AA-- -AA---AA- AA-----AA AA-----AA AA-----AA --------- 
