model
size = 28 16 26, scale = 0.05, origin = -y
material 
  colors = A:#F90 B:#D00 C:#EEE
voxels
-----------AAAAAA----------- ---------------------------- ---------------------------- ---------------------------- ---------------------------- ---------------------------- ---------------------------- ---------------------------- ---------------------------- ---------------------------- ---------------------------- ---------------------------- ---------------------------- ---------------------------- ---------------------------- ---------------------------- 
----------AAAAAAAA---------- ---------------------------- ---------------------------- ---------------------------- ---------------------------- ---------------------------- ---------------------------- ---------------------------- ---------------------------- ---------------------------- ---------------------------- ---------------------------- ---------------------------- ---------------------------- ---------------------------- ---------------------------- 
---------AAAAAAAAAA--------- ---------------------------- ---------------------------- ---------------------------- ---------------------------- ---------------------------- ---------------------------- ---------------------------- ---------------------------- ---------------------------- ---------------------------- ---------------------------- ---------------------------- ---------------------------- ---------------------------- ---------------------------- 
--------AAAAAAAAAAAA-------- ---------------------------- ---------------------------- ---------------------------- ---------------------------- ---------------------------- ---------------------------- ---------------------------- ---------------------------- ---------------------------- ---------------------------- ---------------------------- ---------------------------- ---------------------------- ---------------------------- ---------------------------- 
--------AAAAAAAAAAAA-------- ---------------------------- ---------------------------- ---------------------------- ---------------------------- ---------------------------- ---------------------------- ---------------------------- ---------------------------- ---------------------------- ---------------------------- ---------------------------- ---------------------------- ---------------------------- ---------------------------- ---------------------------- 
-------AAAAAAAAAAAAAA------- ---------------------------- ---------------------------- ---------------------------- ---------------------------- ---------------------------- ---------------------------- ---------------------------- ---------------------------- ---------------------------- ---------------------------- ---------------------------- ---------------------------- ---------------------------- ---------------------------- ---------------------------- 
-------AAAAAAAAAAAAAA------- ---------------------------- ---------------------------- ---------------------------- ---------------------------- ---------------------------- ---------------------------- ---------------------------- ---------------------------- ---------------------------- ---------------------------- ---------------------------- ---------------------------- ---------------------------- ---------------------------- ---------------------------- 
-------AAAAABABAAAAAA------- ---------------------------- ---------------------------- ---------------------------- ---------------------------- ---------------------------- ---------------------------- ---------------------------- ---------------------------- ---------------------------- ---------------------------- ---------------------------- ---------------------------- ---------------------------- ---------------------------- ---------------------------- 
-------AAAAABABAAAAAA------- ---------------------------- ---------------------------- ---------------------------- ---------------------------- ---------------------------- ---------------------------- ---------------------------- ---------------------------- ---------------------------- ---------------------------- ---------------------------- ---------------------------- ---------------------------- ---------------------------- ---------------------------- 
-------AAAAAAAAAAAAAA------- --------AAABBBBBBAAA-------- --------AAAABBBBBBAA-------- --------AAAABBAABBAA-------- ---------------------------- ---------------------------- ---------------------------- ---------------------------- ---------------------------- ---------------------------- ---------------------------- ---------------------------- ---------------------------- ---------------------------- ---------------------------- ---------------------------- 
------AA------------AA------ -------A------------A------- -------A------------A------- -------AAAAABAAAAAAAA------- -------AAAAABBBBBAAAA------- -------AAAAABBBBBBAAA------- --------AAAABBAABBAA-------- --------AAAABBBBBBAA-------- ---------AABBBBBBAA--------- ---------------------------- ---------------------------- ---------------------------- ---------------------------- ---------------------------- ---------------------------- ---------------------------- 
-----AA--------------AA----- ------A--------------A------ ------A--------------A------ ------A--------------A------ -------A------------A------- -------A------------A------- -------AAAAAAAAAAAAAA------- -------AAAAAAAAAAAAAA------- ---------AAAAAAAAAA--------- ---------AAABABAAAA--------- ---------------------------- ---------------------------- ---------------------------- ---------------------------- ---------------------------- ---------------------------- 
-----A----------------A----- -----AA--------------AA----- ------A--------------A------ ------A--------------A------ ------AA------------AA------ ------AA------------AA------ -------A------------A------- -------AAA--------AAA------- --------AA--------AA-------- ---------AAABABAAAA--------- ---------------------------- ---------------------------- ---------------------------- ---------------------------- ---------------------------- ---------------------------- 
-----A----------------A----- -----AA--------------AA----- -----AA--------------AA----- ------A--------------A------ ------A--------------A------ ------AA------------AA------ ------AA------------AA------ ------AA------------AA------ -------AAA--------AAA------- --------AAAAAAAAAAAA-------- ---------AAAAAAAAAA--------- ---------------------------- ---------------------------- ---------------------------- ---------------------------- ---------------------------- 
-----A----------------A----- -----AA--------------AA----- -----AA--------------AA----- -----AA--------------AA----- ------A--------------A------ ------AA------------AA------ ------AA------------AA------ ----CCAA------------AACC---- ---CCCCA------------ACCCC--- --CCC--AAAAAAAAAAAAAA--CCC-- -CCC-----AAAAAAAAAA-----CCC- -CC----------------------CC- CC------------------------CC -CC----------------------CC- --C----------------------C-- ---------------------------- 
-----A----------------A----- -----AA--------------AA----- -----AA--------------AA----- -----AA--------------AA----- -----AA--------------AA----- ------A--------------A------ -----CAAAAAAAAAAAAAAAAC----- ----CCAAAAAAAAAAAAAAAA-C---- ---CCCCAAAAAAAAAAAAAACCCC--- --CCC--AAAAAAAAAAAAAA--CCC-- -CCC-----AAAAAAAAAA-----CCC- CCC----------------------CCC CC------------------------CC CCC----------------------CCC -CC----------------------CC- --C----------------------C-- 
-----A----------------A----- -----AA--------------AA----- -----AA--------------AA----- -----AA--------------AA----- -----AA--------------AA----- -----AA--------------AA----- -----AAAAAAAAAAAAAAAAAA----- ----CCAAAAAAAAAAAAAAAACC---- ---CCCCAAAAAAAAAAAAAACCCC--- --CCC--AAAAAAAAAAAAAA--CCC-- -CCC-----AAAAAAAAAA-----CCC- -CC----------------------CC- CC------------------------CC -CC----------------------CC- --C----------------------C-- ---------------------------- 
-----A----------------A----- -----AA--------------AA----- -----AA--------------AA----- -----AA--------------AA----- -----AA--------------AA----- -----AAA------------AAA----- -----AAA------------AAA----- ------AA------------AA------ -------A------------A------- -------AAAAAAAAAAAAAA------- ---------AAAAAAAAAA--------- ---------------------------- ---------------------------- ---------------------------- ---------------------------- ---------------------------- 
-----A----------------A----- -----AA--------------AA----- -----AA--------------AA----- -----AA--------------AA----- ------A--------------A------ ------AA------------AA------ ------AA------------AA------ ------AA------------AA------ -------AAA--------AAA------- --------AAAAAAAAAAAA-------- ---------AAAAAAAAAA--------- ---------------------------- ---------------------------- ---------------------------- ---------------------------- ---------------------------- 
-----A----------------A----- -----AA--------------AA----- -----AA--------------AA----- -----AA--------------AA----- -----AAA------------AAA----- -----AAA------------AAA----- -----AAA------------AAA----- ------AAAA--------AAAA------ -------AAA--------AAA------- -------AAAAAAAAAAAAAA------- ---------AAAAAAAAAA--------- ---------------------------- ---------------------------- ---------------------------- ---------------------------- ---------------------------- 
-----AA--------------AA----- -----AA--------------AA----- -----AA--------------AA----- -----AA--------------AA----- ------AA------------AA------ ------AA------------AA------ ------AAAAAAAAAAAAAAAA------ ------AAAAAAAAAAAAAAAA------ -------AAAAAAAAAAAAAA------- --------AAAAAAAAAAAA-------- ---------AAAAAAAAAA--------- ---------------------------- ---------------------------- ---------------------------- ---------------------------- ---------------------------- 
-----AAA------------AAA----- -----AAA------------AAA----- -----AAA------------AAA----- ------AAAAAABAAAAAAAAA------ ------AAAAAABBBBBAAAAA------ ------AAAAABBBBBBAAAAA------ -------AAAABBAABBAAAA------- -------AAAABBBBBBAAAA------- --------AAAABBBBBBAA-------- ---------AAAAABABAA--------- ---------------------------- ---------------------------- ---------------------------- ---------------------------- ---------------------------- ---------------------------- 
-----AAAAAAAAAAAAAAAAAA----- ------A-AAAABBBBBBAA-A------ ------A-AAABBBBBBAAA-A------ ------A-AAABBAABBAAA-A------ -------A------------A------- -------A------------A------- -------AAAAAAAAAAAAAA------- -------AAAAAAAAAAAAAA------- ---------AAAAAAAAAA--------- ---------AAAAABABAA--------- ---------------------------- ---------------------------- ---------------------------- ---------------------------- ---------------------------- ---------------------------- 
------AAAAAAAABABAAAAA------ -------A------------A------- -------A------------A------- -------AAAAABAAAAAAAA------- -------AAAAABBBBBAAAA------- -------AAAABBBBBBAAAA------- --------AAABBAABBAAA-------- --------AAABBBBBBAAA-------- ---------AAABBBBBBA--------- ---------------------------- ---------------------------- ---------------------------- ---------------------------- ---------------------------- ---------------------------- ---------------------------- 
-------AAAAAAAAAAAAAA------- --------AAAABBBBBBAA-------- --------AAABBBBBBAAA-------- --------AAABBAABBAAA-------- ---------------------------- ---------------------------- ---------------------------- ---------------------------- ---------------------------- ---------------------------- ---------------------------- ---------------------------- ---------------------------- ---------------------------- ---------------------------- ---------------------------- 
--------AAAAAABABAAA-------- ---------------------------- ---------------------------- ---------------------------- ---------------------------- ---------------------------- ---------------------------- ---------------------------- ---------------------------- ---------------------------- ---------------------------- ---------------------------- ---------------------------- ---------------------------- ---------------------------- ---------------------------- 
