model
size = 14 29 9, scale = 0.05, origin = -y
material 
  colors = A:#111 B:#BBB C:#EEE
voxels
-------------- -------------- -------------- -------------- -------------- -------------- ------AA------ ------AA------ -------------- -------------- -------------- -------------- -------------- -------------- -------------- -------------- -------------- -------------- -------------- -------------- -------------- -------------- -------------- -------------- -------------- -------------- -------------- -------------- -------------- 
-------------- -------------- -------------- -------------- -------------- -----AAAA----- -----AAAA----- -----AAAA----- -----AAAA----- -----AAAA----- -------------- -------------- -------------- -------------- -------------- -------------- -------------- -------------- -------------- -------------- -------------- -------------- -------------- -------------- -------------- -------------- -------------- -------------- -------------- 
-------------- -------------- -------------- -------------- ------AA------ -----AAAA----- ----AAAAAA---- ----AAAAAA---- ----AAAAAA---- ----AAAAAA---- -----AAAA----- -----AAAA----- -------------- -------------- -------------- -------------- -------------- -------------- -------------- -------------- -------------- -------------- -------------- -------------- -------------- -------------- -------------- -------------- -------------- 
------AA------ -----AAAA----- ----AA--AA---- ----A----A---- ------AA------ -----AAAA----- ----AAAAAA---- ---AAAAAAAA--- ----AAAAAA---- ----AAAAAA---- -----AAAA----- -----AAAA----- ------AA------ -------------- -------------- -------------- -------------- -------------- -------------- -------------- -------------- -------------- -------------- -------------- -------------- -------------- -------------- -------------- -------------- 
------AA------ -----AAAA----- ----AA--AA---- ---AA----AA--- --AA--AA--AA-- -----AAAA----- ----AAAAAA---- ---AAAAAAAA--- ----AAAAAA---- ----AAAAAA---- -----AAAA----- -----AAAA----- ------AA------ -----CBBB----- ----B----B---- ---B------C--- ---B------B--- --C--------B-- --B--------B-- -C----------B- -C----------B- B------------B B------------B C------------B -------------- -------------- -------------- -------------- -------------- 
------AA------ -----AAAA----- ----AA--AA---- ----A----A---- ------AA------ -----AAAA----- ----AAAAAA---- ----AAAAAA---- ----AAAAAA---- ----AAAAAA---- -----AAAA----- -----AAAA----- -------------- -------------- -------------- -------------- -------------- -------------- -------------- -------------- -------------- -------------- -------------- B------------B B------------B -------------- -------------- -------------- -------------- 
-------------- -------------- -------------- -------------- -------------- -----AAAA----- -----AAAA----- -----AAAA----- -----AAAA----- -----AAAA----- -------------- -------------- -------------- -------------- -------------- -------------- -------------- -------------- -------------- -------------- -------------- -------------- -------------- -------------- B------------B B------------B -------------- -------------- -------------- 
-------------- -------------- -------------- -------------- -------------- -------------- ------AA------ ------AA------ -------------- -------------- -------------- -------------- -------------- -------------- -------------- -------------- -------------- -------------- -------------- -------------- -------------- -------------- -------------- -------------- -------------- B------------B B------------B -------------- -------------- 
-------------- -------------- -------------- -------------- -------------- -------------- -------------- -------------- -------------- -------------- -------------- -------------- -------------- -------------- -------------- -------------- -------------- -------------- -------------- -------------- -------------- -------------- -------------- -------------- -------------- -------------- B------------B BBB--------BBB --BBBBBBBBBB-- 
