model
size = 24 22 28, scale = 0.05, origin = -y
material 
  colors = A:#111 B:#555 C:#444 D:#222 E:#EEE F:#001 G:#060 H:#06F I:#C0C J:#D00 K:#36F L:#FFD000 M:#0CF N:#C3C O:#500 P:#00E Q:#C60 R:#960 S:#777 T:#888 U:#09C V:#400
voxels
-AAAAAAAAAAAAAAAAAAAAAAA -AAAAAAAAAAAAAAAAAAAAAAA -AAAAAAAAAAAAAAAAAAAAAAA -AAAAAAAAAAAAAAAAAAAAAAA -AAAAAAAAAAAAAAAAAAAAAAA -AAAAAAAAAAAAAAAAAAAAAAA -AAAAAAAAAAAAAAAAAAAAAAA -AAAAAAAAAAAAAAAAAAAAAAA -AAAAAAAAAAAAAAAAAAAAAAA -AAAAAAAAAAAAAAAAAAAAAAA -AAAAAAAAAAAAAAAAAAAAAAA -AAAAAAAAAAAAAAAAAAAAAAA -AAAAAAAAAAAAAAAAAAAAAAA -AAAAAAAAAAAAAAAAAAAAAAA -AAAAAAAAAAAAAAAAAAAAAAA -AAAAAAAAAAAAAAAAAAAAAAA -AAAAAAAAAAAAAAAAAAAAAAA -AAAAAAAAAAAAAAAAAAAAAAA -AAAAAAAAAAAAAAAAAAAAAAA -AAAAAAAAAAAAAAAAAAAAAAA -AAAAAAAAAAAAAAAAAAAAAAA -AAAAAAAAAAAAAAAAAAAAAAA 
-AAAAAAAAAAAAAAAAAAAAAAA -AAAAAAAAAAAAAAAAAAAAAAA -AAAAAAAAAAAAAAAAAAAAAAA -AAAAAAAAAAAAAAAAAAAAAAA -AAAAAAAAAAAAAAAAAAAAAAA -AAAAAAAAAAAAAAAAAAAAAAA -AAAAAAAAAAAAAAAAAAAAAAA -AAAAAAAAAAAAAAAAAAAAAAA -AAAAAAAAAAAAAAAAAAAAAAA -AAAAAAAAAAAAAAAAAAAAAAA -AAAAAAAAAAAAAAAAAAAAAAA -AAAAAAAAAAAAAAAAAAAAAAA -AAAAAAAAAAAAAAAAAAAAAAA -AAAAAAAAAAAAAAAAAAAAAAA -AAAAAAAAAAAAAAAAAAAAAAA -AAAAAAAAAAAAAAAAAAAAAAA -AAAAAAAAAAAAAAAAAAAAAAA -AAAAAAAAAAAAAAAAAAAAAAA -AAAAAAAAAAAAAAAAAAAAAAA -AAAAAAAAAAAAAAAAAAAAAAA -AAAAAAAAAAAAAAAAAAAAAAA -AAAAAAAAAAAAAAAAAAAAAAA 
-AAAAAAAAAAAAAAAAAAAAAAA -AAAAAAAAAAAAAAAAAAAAAAA -AAAAAAAAAAAAAAAAAAAAAAA -AAAAAAAAAAAAAAAAAAAAAAA -AAAAAAAAAAAAAAAAAAAAAD- -AAAAAAAAAAAAAAAAAAAAAB- -AAAAAAAAAAAAAAAAAAAAAD- -AAAAAAAAAAAAAAAAAAAAAB- -AAAAAAAAAAAAAAAAAAAAAD- -AAAAAAAAAAAAAAAAAAAAAB- -AAAAAAAAAAAAAAAAAAAAAD- -AAAAAAAAAAAAAAAAAAAAAB- -AAAAAAAAAAAAAAAAAAAAAD- -AAAAAAAAAAAAAAAAAAAAAB- -AAAAAAAAAAAAAAAAAAAAAD- -AAAAAAAAAAAAAAAAAAAAAB- -AAAAAAAAAAAAAAAAAAAAAD- -AAAAAAAAAAAAAAAAAAAAAB- -AAAAAAAAAAAAAAAAAAAAAD- -AAAAAAAAAAAAAAAAAAAAAB- -AAAAAAAAAAAAAAAAAAAAAAA -AAAAAAAAAAAAAAAAAAAAAAA 
-AAAAAAAAAAAAAAAAAAAAAAA -AAAAAAAAAAAAAAAAAAAAAAV -AAAAAAAAAAAAAAAAAAAAAAA -AAAAAAAAAAAAAAAAAAAAAAA -AAAAAAAAAAAAAAAAAAAAAB- -AAAAAAAAAAAAAAAAAAAAAD- -AAAAAAAAAAAAAAAAAAAAAB- -AAAAAAAAAAAAAAAAAAAAAD- -AAAAAAAAAAAAAAAAAAAAAB- -AAAAAAAAAAAAAAAAAAAAAD- -AAAAAAAAAAAAAAAAAAAAAB- -AAAAAAAAAAAAAAAAAAAAAD- -AAAAAAAAAAAAAAAAAAAAAB- -AAAAAAAAAAAAAAAAAAAAAD- -AAAAAAAAAAAAAAAAAAAAAB- -AAAAAAAAAAAAAAAAAAAAAD- -AAAAAAAAAAAAAAAAAAAAAB- -AAAAAAAAAAAAAAAAAAAAAD- -AAAAAAAAAAAAAAAAAAAAAB- -AAAAAAAAAAAAAAAAAAAAAD- -AAAAAAAAAAAAAAAAAAAAAAA -AAAAAAAAAAAAAAAAAAAAAAA 
-AAAAAAAAAAAAAAAAAAAAAAA -AAAAAAAAAAAAAAAAAAAAAAA -AAAAAAAAAAAAAAAAAAAAAAA -AAAAAAAAAAAAAAAAAAAAAAA -AAAAAAAAAAAAAAAAAAAAAD- -AAAAAAAAAAAAAAAAAAAAAB- -AAAAAAAAAAAAAAAAAAAAAD- --CAAAAAAAAAAAAAAAAAAAB- --CAAAAAAAAAAAAAAAAAAAD- --CAAAAAAAAAAAAAAAAAAAB- --CAAAAAAAAAAAAAAAAAAAD- --CAAAAAAAAAAAAAAAAAAAB- --CAAAAAAAAAAAAAAAAAAAD- --CAAAAAAAAAAAAAAAAAAAB- --CAAAAAAAAAAAAAAAAAAAD- --CAAAAAAAAAAAAAAAAAAAB- --CAAAAAAAAAAAAAAAAAAAD- --CAAAAAAAAAAAAAAAAAAAB- --CAAAAAAAAAAAAAAAAAAAD- --CAAAAAAAAAAAAAAAAAAAB- -AAAAAAAAAAAAAAAAAAAAAAA -AAAAAAAAAAAAAAAAAAAAAAA 
-AAAAAAAAAAAAAAAAAAAAAAA -AAAAAAAAAAAAAAAAAAAAAAA -AAAAAAAAAAAAAAAAAAAAAAA -CAAAAAAAAAAAAAAAAAAAAAA -OAAAAAAAAAAAAAAAAAAAAB- -AAAAAAAAAAAAAAAAAAAAAD- -AAAAAAAAAAAAAAAAAAAAAB- -AAAAAAAAAAAAAAAAAAAAAD- -AAAAAAAAAAAAAAAAAAAAAB- -AAAAAAAAAAAAAAAAAAAAAD- -AAAAAAAAAAAAAAAAAAAAAB- -AAAAAAAAAAAAAAAAAAAAAD- -AAAAAAAAAAAAAAAAAAAAAB- -AAAAAAAAAAAAAAAAAAAAAD- -AAAAAAAAAAAAAAAAAAAAAB- -AAAAAAAAAAAAAAAAAAAAAD- -AAAAAAAAAAAAAAAAAAAAAB- -AAAAAAAAAAAAAAAAAAAAAD- -AAAAAAAAAAAAAAAAAAAAAB- -AAAAAAAAAAAAAAAAAAAAAD- -AAAAAAAAAAAAAAAAAAAAAAA -AAAAAAAAAAAAAAAAAAAAAAA 
-AAAAAAAAAAAAAAAAAAAAAAA -AAAAAAAAAAAAAAAAAAAAAAA -AAAAAAAAAAAAAAAAAAAAAAA -AAAAAAAAAAAAAAAAAAAAAAA -AAAAAAAAAAAAAAAAAAAAAD- -AAAAAAAAAAAAAAAAAAAAAB- -AAAAAAAAAAAAAAAAAAAAAI- --CAAAAAAAAAAAAAAAAAAAI- --CAAAAAAAAAAAAAAAAAAAI- --CAAAAAAAAAAAAAAAAAAAI- --CAAAAAAAAAAAAAAAAAAAI- --CAAAAAAAAAAAAAAAAAAAI- --CAAAAAAAAAAAAAAAAAAAH- --CAAAAAAAAAAAAAAAAAAAH- --CAAAAAAAAAAAAAAAAAAAH- --CAAAAAAAAAAAAAAAAAAAH- --CAAAAAAAAAAAAAAAAAAAH- --CAAAAAAAAAAAAAAAAAAAH- --CAAAAAAAAAAAAAAAAAAAD- --CAAAAAAAAAAAAAAAAAAAB- -AAAAAAAAAAAAAAAAAAAAAAA -AAAAAAAAAAAAAAAAAAAAAAA 
-AAAAAAAAAAAAAAAAAAAAAAA -AAAAAAAAAAAAAAAAAAAAAAA -AAAAAAAAAAAAAAAAAAAAAAA -CAAAAAAAAAAAAAAAAAAAAAA -OAAAAAAAAAAAAAAAAAAAAB- -AAAAAAAAAAAAAAAAAAAAAD- -AAAAAAAAAAAAAAAAAAAAAQ- -AAAAAAAAAAAAAAAAAAAAAQ- -AAAAAAAAAAAAAAAAAAAAAB- -AAAAAAAAAAAAAAAAAAAAAD- -AAAAAAAAAAAAAAAAAAAAAB- -AAAAAAAAAAAAAAAAAAAAAD- -AAAAAAAAAAAAAAAAAAAAAB- -AAAAAAAAAAAAAAAAAAAAAD- -AAAAAAAAAAAAAAAAAAAAAB- -AAAAAAAAAAAAAAAAAAAAAD- -AAAAAAAAAAAAAAAAAAAAAH- -AAAAAAAAAAAAAAAAAAAAAH- -AAAAAAAAAAAAAAAAAAAAAB- -AAAAAAAAAAAAAAAAAAAAAD- -AAAAAAAAAAAAAAAAAAAAAAA -AAAAAAAAAAAAAAAAAAAAAAA 
-AAAAAAAAAAAAAAAAAAAAAAA -AAAAAAAAAAAAAAAAAAAAAAA -AAAAAAAAAAAAAAAAAAAAAAA -AAAAAAAAAAAAAAAAAAAAAAA -AAAAAAAAAAAAAAAAAAAAAD- -AAAAAAAAAAAAAAAAAAAAAB- -AAAAAAAAAAAAAAAAAAAAAD- --CAAAAAAAAAAAAAAAAAAAB- --CAAAAAAAAAAAAAAAAAAAD- --CAAAAAAAAAAAAAAAAAAAB- --CAAAAAAAAAAAAAAAAAAAD- --CAAAAAAAAAAAAAAAAAAAA- --CAAAAAAAAAAAAAAAAAAAL- --CAAAAAAAAAAAAAAAAAAAB- --CAAAAAAAAAAAAAAAAAAAD- --CAAAAAAAAAAAAAAAAAAAB- --CAAAAAAAAAAAAAAAAAAAD- --CAAAAAAAAAAAAAAAAAAAB- --CAAAAAAAAAAAAAAAAAAAD- --CAAAAAAAAAAAAAAAAAAAB- -AAAAAAAAAAAAAAAAAAAAAAA -AAAAAAAAAAAAAAAAAAAAAAA 
-AAAAAAAAAAAAAAAAAAAAAAA -AAAAAAAAAAAAAAAAAAAAAAA -AAAAAAAAAAAAAAAAAAAAAAA -CAAAAAAAAAAAAAAAAAAAAAA -OAAAAAAAAAAAAAAAAAAAAB- -AAAAAAAAAAAAAAAAAAAAAD- -AAAAAAAAAAAAAAAAAAAAAB- -AAAAAAAAAAAAAAAAAAAAAD- -AAAAAAAAAAAAAAAAAAAAAB- -AAAAAAAAAAAAAAAAAAAAAE- -AAAAAAAAAAAAAAAAAAAAAE- -AAAAAAAAAAAAAAAAAAAAAA- -AAAAAAAAAAAAAAAAAAAAAL- -AAAAAAAAAAAAAAAAAAAAAL- -AAAAAAAAAAAAAAAAAAAAAE- -AAAAAAAAAAAAAAAAAAAAAD- -AAAAAAAAAAAAAAAAAAAAAB- -AAAAAAAAAAAAAAAAAAAAAD- -AAAAAAAAAAAAAAAAAAAAAB- -AAAAAAAAAAAAAAAAAAAAAD- -AAAAAAAAAAAAAAAAAAAAAAA -AAAAAAAAAAAAAAAAAAAAAAA 
-AAAAAAAAAAAAAAAAAAAAAAA -AAAAAAAAAAAAAAAAAAAAAAA -AAAAAAAAAAAAAAAAAAAAAAA -AAAAAAAAAAAAAAAAAAAAAAA -AAAAAAAAAAAAAAAAAAAAAD- -AAAAAAAAAAAAAAAAAAAAAB- -AAAAAAAAAAAAAAAAAAAAAD- --CAAAAAAAAAAAAAAAAAAAB- --CAAAAAAAAAAAAAAAAAAAA- --CAAAAAAAAAAAAAAAAAAAF- --CAAAAAAAAAAAAAAAAAAAF- --CAAAAAAAAAAAAAAAAAAAA- --CAAAAAAAAAAAAAAAAAAAM- --CAAAAAAAAAAAAAAAAAAAM- --CAAAAAAAAAAAAAAAAAAAA- --CAAAAAAAAAAAAAAAAAAAA- --CAAAAAAAAAAAAAAAAAAAD- --CAAAAAAAAAAAAAAAAAAAB- --CAAAAAAAAAAAAAAAAAADD- --CAAAAAAAAAAAAAAAAAAAB- -AAAAAAAAAAAAAAAAAAAAAAA -AAAAAAAAAAAAAAAAAAAAAAA 
-AAAAAAAAAAAAAAAAAAAAAAA -AAAAAAAAAAAAAAAAAAAAAAA -AAAAAAAAAAAAAAAAAAAAAAA -AAAAAAAAAAAAAAAAAAAAAAA -AAAAAAAAAAAAAAAAAAAAAB- -AAAAAAAAAAAAAAAAAAAAAD- -AAAAAAAAAAAAAAAAAAAAAB- -AAAAAAAAAAAAAAAAAAAAAE- -AAAAAAAAAAAAAAAAAAAAAA- -AAAAAAAAAAAAAAAAAAAAAE- -AAAAAAAAAAAAAAAAAAAAAE- -AAAAAAAAAAAAAAAAAAAAAA- -AAAAAAAAAAAAAAAAAAAAAM- -AAAAAAAAAAAAAAAAAAAAAM- -AAAAAAAAAAAAAAAAAAAAAE- -AAAAAAAAAAAAAAAAAAAAAE- -AAAAAAAAAAAAAAAAAAAAAE- -AAAAAAAAAAAAAAAAAAAAAD- -AAAAAAAAAAAAAAAAAAAAAB- -AAAAAAAAAAAAAAAAAAAAAD- -AAAAAAAAAAAAAAAAAAAAAAA -AAAAAAAAAAAAAAAAAAAAAAA 
-AAAAAAAAAAAAAAAAAAAAAAA -AAAAAAAAAAAAAAAAAAAAAAA -BAAAAAAAAAAAAAAAAAAAAAA -BAAAAAAAAAAAAAAAAAAAAAA -BAAAAAAAAAAAAAAAAAAAAD- -BAAAAAAAAAAAAAAAAAAAAB- -AAAAAAAAAAAAAAAAAAAAAL- --CAAAAAAAAAAAAAAAAAAAF- --CAAAAAAAAAAAAAAAAAAAA- --CAAAAAAAAAAAAAAAAAAAF- --CAAAAAAAAAAAAAAAAAAAF- --CAAAAAAAAAAAAAAAAAAAA- --CAAAAAAAAAAAAAAAAAAAG- --CAAAAAAAAAAAAAAAAAAAG- --CAAAAAAAAAAAAAAAAAAAA- --CAAAAAAAAAAAAAAAAAAAE- --CAAAAAAAAAAAAAAAAAAAA- --CAAAAAAAAAAAAAAAAAAAE- --CAAAAAAAAAAAAAAAAAAAD- --CAAAAAAAAAAAAAAAAAAAB- -AAAAAAAAAAAAAAAAAAAAAAA -AAAAAAAAAAAAAAAAAAAAAAA 
-AAAAAAAAAAAAAAAAAAAAAAA -AAAAAAAAAAAAAAAAAAAAAAA -BAAAAAAAAAAAAAAAAAAAAAA -AAAAAAAAAAAAAAAAAAAAAAA -BAAAAAAAAAAAAAAAAAAAAB- -BAAAAAAAAAAAAAAAAAAAAD- -AAAAAAAAAAAAAAAAAAAAAJ- -AAAAAAAAAAAAAAAAAAAAAF- -AAAAAAAAAAAAAAAAAAAAAA- -AAAAAAAAAAAAAAAAAAAAAE- -AAAAAAAAAAAAAAAAAAAAAE- -AAAAAAAAAAAAAAAAAAAAAA- -AAAAAAAAAAAAAAAAAAAAAG- -AAAAAAAAAAAAAAAAAAAAAG- -AAAAAAAAAAAAAAAAAAAAAE- -AAAAAAAAAAAAAAAAAAAAAE- -AAAAAAAAAAAAAAAAAAAAAA- -AAAAAAAAAAAAAAAAAAAAAE- -AAAAAAAAAAAAAAAAAAAAAB- -AAAAAAAAAAAAAAAAAAAAAD- -AAAAAAAAAAAAAAAAAAAAAAA -AAAAAAAAAAAAAAAAAAAAAAA 
-AAAAAAAAAAAAAAAAAAAAAAA -AAAAAAAAAAAAAAAAAAAAAAA -BAAAAAAAAAAAAAAAAAAAAAA -BAAAAAAAAAAAAAAAAAAAAAA -BAAAAAAAAAAAAAAAAAAAAD- -BAAAAAAAAAAAAAAAAAAAAB- -AAAAAAAAAAAAAAAAAAAAAJ- --CAAAAAAAAAAAAAAAAAAAF- --CAAAAAAAAAAAAAAAAAAAS- --CAAAAAAAAAAAAAAAAAAAF- --CAAAAAAAAAAAAAAAAAAAF- --CAAAAAAAAAAAAAAAAAAAA- --CAAAAAAAAAAAAAAAAAAAN- --CAAAAAAAAAAAAAAAAAAAN- --CAAAAAAAAAAAAAAAAAAAA- --CAAAAAAAAAAAAAAAAAAAE- --CAAAAAAAAAAAAAAAAAAAA- --CAAAAAAAAAAAAAAAAAAAE- --CAAAAAAAAAAAAAAAAAAAD- --CAAAAAAAAAAAAAAAAAAAB- -AAAAAAAAAAAAAAAAAAAAAAA -AAAAAAAAAAAAAAAAAAAAAAA 
-AAAAAAAAAAAAAAAAAAAAAAA -AAAAAAAAAAAAAAAAAAAAAAA -BAAAAAAAAAAAAAAAAAAAAAA -AAAAAAAAAAAAAAAAAAAAAAA -BAAAAAAAAAAAAAAAAAAAAB- -BAAAAAAAAAAAAAAAAAAAAD- -AAAAAAAAAAAAAAAAAAAAAL- -AAAAAAAAAAAAAAAAAAAAAF- -AAAAAAAAAAAAAAAAAAAAAS- -AAAAAAAAAAAAAAAAAAAAAE- -AAAAAAAAAAAAAAAAAAAAAE- -AAAAAAAAAAAAAAAAAAAAAA- -AAAAAAAAAAAAAAAAAAAAAN- -AAAAAAAAAAAAAAAAAAAAAN- -AAAAAAAAAAAAAAAAAAAAAE- -AAAAAAAAAAAAAAAAAAAAAE- -AAAAAAAAAAAAAAAAAAAAAA- -AAAAAAAAAAAAAAAAAAAAAE- -AAAAAAAAAAAAAAAAAAAAAB- -AAAAAAAAAAAAAAAAAAAAAD- -AAAAAAAAAAAAAAAAAAAAAAA -AAAAAAAAAAAAAAAAAAAAAAA 
-AAAAAAAAAAAAAAAAAAAAAAA -AAAAAAAAAAAAAAAAAAAAAAA -BAAAAAAAAAAAAAAAAAAAAAA -BAAAAAAAAAAAAAAAAAAAAAA -BAAAAAAAAAAAAAAAAAAAAD- -BAAAAAAAAAAAAAAAAAAAAB- -AAAAAAAAAAAAAAAAAAAAAD- --CAAAAAAAAAAAAAAAAAAAE- --CAAAAAAAAAAAAAAAAAAAT- --CAAAAAAAAAAAAAAAAAAAF- --CAAAAAAAAAAAAAAAAAAAF- --CAAAAAAAAAAAAAAAAAAAA- --CAAAAAAAAAAAAAAAAAAAJ- --CAAAAAAAAAAAAAAAAAAAJ- --CAAAAAAAAAAAAAAAAAAAA- --CAAAAAAAAAAAAAAAAAAAE- --CAAAAAAAAAAAAAAAAAAAE- --CAAAAAAAAAAAAAAAAAAAB- --CAAAAAAAAAAAAAAAAAAAD- --CAAAAAAAAAAAAAAAAAAAB- -AAAAAAAAAAAAAAAAAAAAAAA -AAAAAAAAAAAAAAAAAAAAAAA 
AAAAAAAAAAAAAAAAAAAAAAAA AAAAAAAAAAAAAAAAAAAAAAAA ABAAAAAAAAAAAAAAAAAAAAAA AAAAAAAAAAAAAAAAAAAAAAAA -BAAAAAAAAAAAAAAAAAAAAB- -BAAAAAAAAAAAAAAAAAAAAD- -AAAAAAAAAAAAAAAAAAAAAB- -AAAAAAAAAAAAAAAAAAAAAD- -AAAAAAAAAAAAAAAAAAAAAT- -AAAAAAAAAAAAAAAAAAAAAE- -AAAAAAAAAAAAAAAAAAAAAE- -AAAAAAAAAAAAAAAAAAAAAA- -AAAAAAAAAAAAAAAAAAAAAJ- -AAAAAAAAAAAAAAAAAAAAAJ- -AAAAAAAAAAAAAAAAAAAAAE- -AAAAAAAAAAAAAAAAAAAAAE- -AAAAAAAAAAAAAAAAAAAAAB- -AAAAAAAAAAAAAAAAAAAAAD- -AAAAAAAAAAAAAAAAAAAAAB- -AAAAAAAAAAAAAAAAAAAAAD- -AAAAAAAAAAAAAAAAAAAAAAA -AAAAAAAAAAAAAAAAAAAAAAA 
-AAAAAAAAAAAAAAAAAAAAAAA -AAAAAAAAAAAAAAAAAAAAAAC -BAAAAAAAAAAAAAAAAAAAAAA -BAAAAAAAAAAAAAAAAAAAAAA -BAAAAAAAAAAAAAAAAAAAAD- -BAAAAAAAAAAAAAAAAAAAAB- -AAAAAAAAAAAAAAAAAAAAAD- --CAAAAAAAAAAAAAAAAAAAB- --CAAAAAAAAAAAAAAAAAAAD- --CAAAAAAAAAAAAAAAAAAAF- --CAAAAAAAAAAAAAAAAAAAF- --CAAAAAAAAAAAAAAAAAAAA- --CAAAAAAAAAAAAAAAAAAAP- --CAAAAAAAAAAAAAAAAAAAP- --CAAAAAAAAAAAAAAAAAAAA- --CAAAAAAAAAAAAAAAAAAAB- --CAAAAAAAAAAAAAAAAAAAD- --CAAAAAAAAAAAAAAAAAAAB- --CAAAAAAAAAAAAAAAAAAAD- --CAAAAAAAAAAAAAAAAAAAB- -AAAAAAAAAAAAAAAAAAAAAAA -AAAAAAAAAAAAAAAAAAAAAAA 
-AAAAAAAAAAAAAAAAAAAAAAA -AAAAAAAAAAAAAAAAAAAAAAA -BAAAAAAAAAAAAAAAAAAAAAA -BAAAAAAAAAAAAAAAAAAAAAA -BAAAAAAAAAAAAAAAAAAAAB- -BAAAAAAAAAAAAAAAAAAAAD- -AAAAAAAAAAAAAAAAAAAAAB- -AAAAAAAAAAAAAAAAAAAAAD- -AAAAAAAAAAAAAAAAAAAAAB- -AAAAAAAAAAAAAAAAAAAAAD- -AAAAAAAAAAAAAAAAAAAAAE- -AAAAAAAAAAAAAAAAAAAAAA- -AAAAAAAAAAAAAAAAAAAAAP- -AAAAAAAAAAAAAAAAAAAAAD- -AAAAAAAAAAAAAAAAAAAAAB- -AAAAAAAAAAAAAAAAAAAAAD- -AAAAAAAAAAAAAAAAAAAAAB- -AAAAAAAAAAAAAAAAAAAAAD- -AAAAAAAAAAAAAAAAAAAAAB- -AAAAAAAAAAAAAAAAAAAAAD- -AAAAAAAAAAAAAAAAAAAAAAA -AAAAAAAAAAAAAAAAAAAAAAA 
-AAAAAAAAAAAAAAAAAAAAAAA -AAAAAAAAAAAAAAAAAAAAAAC -AAAAAAAAAAAAAAAAAAAAAAA -AAAAAAAAAAAAAAAAAAAAAAA -AAAAAAAAAAAAAAAAAAAAAD- -AAAAAAAAAAAAAAAAAAAAAB- -AAAAAAAAAAAAAAAAAAAAAR- --CAAAAAAAAAAAAAAAAAAAR- --CAAAAAAAAAAAAAAAAAAAD- --CAAAAAAAAAAAAAAAAAAAB- --CAAAAAAAAAAAAAAAAAAAD- --CAAAAAAAAAAAAAAAAAAAB- --CAAAAAAAAAAAAAAAAAAAD- --CAAAAAAAAAAAAAAAAAAAB- --CAAAAAAAAAAAAAAAAAAAD- --CAAAAAAAAAAAAAAAAAAAB- --CAAAAAAAAAAAAAAAAAAAU- --CAAAAAAAAAAAAAAAAAAAU- --CAAAAAAAAAAAAAAAAAAAD- --CAAAAAAAAAAAAAAAAAAAB- -AAAAAAAAAAAAAAAAAAAAAAA -AAAAAAAAAAAAAAAAAAAAAAA 
-AAAAAAAAAAAAAAAAAAAAAAA -AAAAAAAAAAAAAAAAAAAAAAA -AAAAAAAAAAAAAAAAAAAAAAA -AAAAAAAAAAAAAAAAAAAAAAA -AAAAAAAAAAAAAAAAAAAAAB- -AAAAAAAAAAAAAAAAAAAAAD- -AAAAAAAAAAAAAAAAAAAAAK- -AAAAAAAAAAAAAAAAAAAAAK- -AAAAAAAAAAAAAAAAAAAAAK- -AAAAAAAAAAAAAAAAAAAAAK- -AAAAAAAAAAAAAAAAAAAAAK- -AAAAAAAAAAAAAAAAAAAAAK- -AAAAAAAAAAAAAAAAAAAAAG- -AAAAAAAAAAAAAAAAAAAAAG- -AAAAAAAAAAAAAAAAAAAAAG- -AAAAAAAAAAAAAAAAAAAAAG- -AAAAAAAAAAAAAAAAAAAAAG- -AAAAAAAAAAAAAAAAAAAAAG- -AAAAAAAAAAAAAAAAAAAAAB- -AAAAAAAAAAAAAAAAAAAAAD- -AAAAAAAAAAAAAAAAAAAAAAA -AAAAAAAAAAAAAAAAAAAAAAA 
-AAAAAAAAAAAAAAAAAAAAAAA -AAAAAAAAAAAAAAAAAAAAAAC -AAAAAAAAAAAAAAAAAAAAAAA -AAAAAAAAAAAAAAAAAAAAAAA -AAAAAAAAAAAAAAAAAAAAAD- -AAAAAAAAAAAAAAAAAAAAAB- -AAAAAAAAAAAAAAAAAAAAAD- --CAAAAAAAAAAAAAAAAAAAB- --CAAAAAAAAAAAAAAAAAAAD- --CAAAAAAAAAAAAAAAAAAAB- --CAAAAAAAAAAAAAAAAAAAD- --CAAAAAAAAAAAAAAAAAAAB- --CAAAAAAAAAAAAAAAAAAAD- --CAAAAAAAAAAAAAAAAAAAB- --CAAAAAAAAAAAAAAAAAAAD- --CAAAAAAAAAAAAAAAAAAAB- --CAAAAAAAAAAAAAAAAAAAD- --CAAAAAAAAAAAAAAAAAAAB- --CAAAAAAAAAAAAAAAAAAAD- --CAAAAAAAAAAAAAAAAAAAB- -AAAAAAAAAAAAAAAAAAAAAAA -AAAAAAAAAAAAAAAAAAAAAAA 
-AAAAAAAAAAAAAAAAAAAAAAA -AAAAAAAAAAAAAAAAAAAAAAA -AAAAAAAAAAAAAAAAAAAAAAA -AAAAAAAAAAAAAAAAAAAAAAA -AAAAAAAAAAAAAAAAAAAAAB- -AAAAAAAAAAAAAAAAAAAAAD- -AAAAAAAAAAAAAAAAAAAAAB- -AAAAAAAAAAAAAAAAAAAAAD- -AAAAAAAAAAAAAAAAAAAAAB- -AAAAAAAAAAAAAAAAAAAAAD- -AAAAAAAAAAAAAAAAAAAAAB- -AAAAAAAAAAAAAAAAAAAAAD- -AAAAAAAAAAAAAAAAAAAAAB- -AAAAAAAAAAAAAAAAAAAAAD- -AAAAAAAAAAAAAAAAAAAAAB- -AAAAAAAAAAAAAAAAAAAAAD- -AAAAAAAAAAAAAAAAAAAAAB- -AAAAAAAAAAAAAAAAAAAAAD- -AAAAAAAAAAAAAAAAAAAAAB- -AAAAAAAAAAAAAAAAAAAAAD- -AAAAAAAAAAAAAAAAAAAAAAA -AAAAAAAAAAAAAAAAAAAAAAA 
-AAAAAAAAAAAAAAAAAAAAAAA -AAAAAAAAAAAAAAAAAAAAAAA -AAAAAAAAAAAAAAAAAAAAAAA -AAAAAAAAAAAAAAAAAAAAAAA -AAAAAAAAAAAAAAAAAAAAAD- -AAAAAAAAAAAAAAAAAAAAAB- -AAAAAAAAAAAAAAAAAAAAAD- --CAAAAAAAAAAAAAAAAAAAB- --CAAAAAAAAAAAAAAAAAAAD- --CAAAAAAAAAAAAAAAAAAAB- --CAAAAAAAAAAAAAAAAAAAD- --CAAAAAAAAAAAAAAAAAAAB- --CAAAAAAAAAAAAAAAAAAAD- --CAAAAAAAAAAAAAAAAAAAB- --CAAAAAAAAAAAAAAAAAAAD- --CAAAAAAAAAAAAAAAAAAAB- --CAAAAAAAAAAAAAAAAAAAD- --CAAAAAAAAAAAAAAAAAAAB- --CAAAAAAAAAAAAAAAAAAAD- --CAAAAAAAAAAAAAAAAAAAB- -AAAAAAAAAAAAAAAAAAAAAAA -AAAAAAAAAAAAAAAAAAAAAAA 
-AAAAAAAAAAAAAAAAAAAAAAA -AAAAAAAAAAAAAAAAAAAAAAA -AAAAAAAAAAAAAAAAAAAAAAA -AAAAAAAAAAAAAAAAAAAAAAA -AAAAAAAAAAAAAAAAAAAAAB- -AAAAAAAAAAAAAAAAAAAAAD- -AAAAAAAAAAAAAAAAAAAAAB- -AAAAAAAAAAAAAAAAAAAAAD- -AAAAAAAAAAAAAAAAAAAAAB- -AAAAAAAAAAAAAAAAAAAAAD- -AAAAAAAAAAAAAAAAAAAAAB- -AAAAAAAAAAAAAAAAAAAAAD- -AAAAAAAAAAAAAAAAAAAAAB- -AAAAAAAAAAAAAAAAAAAAAD- -AAAAAAAAAAAAAAAAAAAAAB- -AAAAAAAAAAAAAAAAAAAAAD- -AAAAAAAAAAAAAAAAAAAAAB- -AAAAAAAAAAAAAAAAAAAAAD- -AAAAAAAAAAAAAAAAAAAAAB- -AAAAAAAAAAAAAAAAAAAAAD- -AAAAAAAAAAAAAAAAAAAAAAA -AAAAAAAAAAAAAAAAAAAAAAA 
-AAAAAAAAAAAAAAAAAAAAAAA -AAAAAAAAAAAAAAAAAAAAAAA -AAAAAAAAAAAAAAAAAAAAAAA -AAAAAAAAAAAAAAAAAAAAAAA -AAAAAAAAAAAAAAAAAAAAAAA -AAAAAAAAAAAAAAAAAAAAAAA -AAAAAAAAAAAAAAAAAAAAAAA -AAAAAAAAAAAAAAAAAAAAAAA -AAAAAAAAAAAAAAAAAAAAAAA -AAAAAAAAAAAAAAAAAAAAAAA -AAAAAAAAAAAAAAAAAAAAAAA -AAAAAAAAAAAAAAAAAAAAAAA -AAAAAAAAAAAAAAAAAAAAAAA -AAAAAAAAAAAAAAAAAAAAAAA -AAAAAAAAAAAAAAAAAAAAAAA -AAAAAAAAAAAAAAAAAAAAAAA -AAAAAAAAAAAAAAAAAAAAAAA -AAAAAAAAAAAAAAAAAAAAAAA -AAAAAAAAAAAAAAAAAAAAAAA -AAAAAAAAAAAAAAAAAAAAAAA -AAAAAAAAAAAAAAAAAAAAAAA -AAAAAAAAAAAAAAAAAAAAAAA 
-AAAAAAAAAAAAAAAAAAAAAAA -AAAAAAAAAAAAAAAAAAAAAAA -AAAAAAAAAAAAAAAAAAAAAAA -AAAAAAAAAAAAAAAAAAAAAAA -AAAAAAAAAAAAAAAAAAAAAAA -AAAAAAAAAAAAAAAAAAAAAAA -AAAAAAAAAAAAAAAAAAAAAAA -AAAAAAAAAAAAAAAAAAAAAAA -AAAAAAAAAAAAAAAAAAAAAAA -AAAAAAAAAAAAAAAAAAAAAAA -AAAAAAAAAAAAAAAAAAAAAAA -AAAAAAAAAAAAAAAAAAAAAAA -AAAAAAAAAAAAAAAAAAAAAAA -AAAAAAAAAAAAAAAAAAAAAAA -AAAAAAAAAAAAAAAAAAAAAAA -AAAAAAAAAAAAAAAAAAAAAAA -AAAAAAAAAAAAAAAAAAAAAAA -AAAAAAAAAAAAAAAAAAAAAAA -AAAAAAAAAAAAAAAAAAAAAAA -AAAAAAAAAAAAAAAAAAAAAAA -AAAAAAAAAAAAAAAAAAAAAAA -AAAAAAAAAAAAAAAAAAAAAAA 
