model
size = 18 30 27, scale = 0.05, origin = -y
material 
  colors = A:#FFF B:#EEE C:#111 D:#BBB
voxels
BA--------------AB BA--------------AB BA--------------AB BA--------------AB BA--------------AB BA--------------AB BA--------------AB BA--------------AB BA--------------AB BA--------------AB BA--------------AB BA--------------AB BA--------------AB BA--------------AB BA--------------AB BA--------------AB BA--------------AB BA--------------AB BA--------------AB BA--------------AB BA--------------AB BA--------------AB BA--------------AB ------------------ ------------------ ------------------ ------------------ ------------------ ------------------ ------------------ 
BA--------------AB BA--------------AB BA--------------AB BA--------------AC BA--------------AC BA--------------AC BA--------------AC CA--------------AC BA--------------AB BA--------------AB BA--------------AB BA--------------AB BA--------------AB BA--------------AB BA--------------AB CA--------------AC CA--------------AB BA--------------AB BA--------------AB CA--------------AC BA--------------AB BA--------------AB BA--------------AB ------------------ ------------------ ------------------ ------------------ ------------------ ------------------ ------------------ 
BA--------------AB BA--------------AB BA--------------AB BA--------------AB BA--------------AB CA--------------AB BA--------------AC CA--------------AC BA--------------AB BA--------------AB BA--------------AB BA--------------AB BA--------------AB BA--------------AB BA--------------AB BA--------------AC BA--------------AC CA--------------AC CA--------------AC BA--------------AC BA--------------AB BA--------------AB BA--------------AB ------------------ ------------------ ------------------ ------------------ ------------------ ------------------ ------------------ 
BA--------------AB BA--------------AB BA--------------AB CA--------------AB CA--------------AB CA--------------AC CA--------------AC CA--------------AB BA--------------AB BA--------------AB BA--------------AB BA--------------AB BA--------------AB BA--------------AB BA--------------AB BA--------------AC BA--------------AB CA--------------AB BA--------------AB BA--------------AC BA--------------AB BA--------------AB BA--------------AB ------------------ ------------------ ------------------ ------------------ ------------------ ------------------ ------------------ 
BA--------------AB BA--------------AB BA--------------AB BA--------------AB BA--------------AB BA--------------AB BA--------------AC BA--------------AC BA--------------AB BA--------------AB BA--------------AB BA--------------AB BA--------------AB BA--------------AB BA--------------AB CA--------------AB CA--------------AB CA--------------AB CA--------------AB CA--------------AB BA--------------AB BA--------------AB BA--------------AB ------------------ ------------------ ------------------ ------------------ ------------------ ------------------ ------------------ 
BA--------------AB BA--------------AB BA--------------AB CA--------------AC BA--------------AC BA--------------AC BA--------------AC BA--------------AC BA--------------AB BA--------------AB BA--------------AB BA--------------AB BA--------------AB BA--------------AB BA--------------AB BA--------------AB BA--------------AB BA--------------AB BA--------------AB BA--------------AB BA--------------AB BA--------------AB BA--------------AB ------------------ ------------------ ------------------ ------------------ ------------------ ------------------ ------------------ 
BA--------------AB BA--------------AB BA--------------AB CA--------------AB BA--------------AB BA--------------AB BA--------------AB BA--------------AB BA--------------AB BA--------------AC BA--------------AC BA--------------AC BA--------------AC BA--------------AC BA--------------AB CA--------------AB CA--------------AC BA--------------AC CA--------------AC BA--------------AC BA--------------AB BA--------------AB BA--------------AB D----------------- D----------------- D----------------- D----------------D D----------------D DD--------------DD -DDDDDDDDDDDDDDDD- 
BA--------------AB BA--------------AB BA--------------AB CA--------------AB CA--------------AB CA--------------AC CA--------------AC CA--------------AC BA--------------AB BA--------------AB BA--------------AB BA--------------AC BA--------------AB BA--------------AC BA--------------AB BA--------------AC BA--------------AC CA--------------AB BA--------------AB CA--------------AB BA--------------AB BA--------------AB BA--------------AB ------------------ ------------------ -----------------D -----------------D ------------------ ------------------ ------------------ 
BA--------------AB BA--------------AB BA--------------AB BA--------------AC BA--------------AC BA--------------AC BA--------------AB BA--------------AB BA--------------AB CA--------------AB CA--------------AB BA--------------AB CA--------------AB BA--------------AC BA--------------AB BA--------------AB BA--------------AC CA--------------AC BA--------------AC CA--------------AB BA--------------AB BA--------------AB BA--------------AB ------------------ -----------------D -----------------D ------------------ ------------------ ------------------ ------------------ 
BA--------------AB BA--------------AB BA--------------AB CA--------------AB BA--------------AB BA--------------AC BA--------------AC CA--------------AC BA--------------AB BA--------------AB BA--------------AB CA--------------AB BA--------------AB CA--------------AB BA--------------AB CA--------------AC CA--------------AC CA--------------AB CA--------------AB CA--------------AB BA--------------AB BA--------------AB BA--------------AB -----------------D -----------------D ------------------ ------------------ ------------------ ------------------ ------------------ 
BA--------------AB BA--------------AB BA--------------AB CA--------------AB BA--------------AB CA--------------AB BA--------------AB CA--------------AB BA--------------AB BA--------------AB BA--------------AC CA--------------AC BA--------------AC CA--------------AB BA--------------AB BA--------------AB BA--------------AC BA--------------AC BA--------------AC BA--------------AC BA--------------AB BA--------------AB BA--------------AB -----------------D ------------------ ------------------ ------------------ ------------------ ------------------ ------------------ 
BA--------------AB BA--------------AB BA--------------AB CA--------------AC CA--------------AB CA--------------AC CA--------------AC CA--------------AC BA--------------AB CA--------------AC CA--------------AB CA--------------AB CA--------------AB CA--------------AC BA--------------AB BA--------------AB CA--------------AB CA--------------AB CA--------------AB BA--------------AB BA--------------AB BA--------------AB BA--------------AB ------------------ ------------------ ------------------ ------------------ ------------------ ------------------ ------------------ 
BA--------------AB BA--------------AB BA--------------AB BA--------------AC BA--------------AB BA--------------AC BA--------------AB BA--------------AC BA--------------AB BA--------------AC BA--------------AB BA--------------AB BA--------------AB BA--------------AC BA--------------AB CA--------------AB BA--------------AC BA--------------AC BA--------------AC CA--------------AB BA--------------AB BA--------------AB BA--------------AB ------------------ ------------------ ------------------ ------------------ ------------------ ------------------ ------------------ 
BA--------------AB BA--------------AB BA--------------AB CA--------------AC CA--------------AC CA--------------AC BA--------------AB CA--------------AC BA--------------AB BA--------------AB CA--------------AC CA--------------AC CA--------------AC BA--------------AB BA--------------AB CA--------------AC BA--------------AB BA--------------AB BA--------------AB CA--------------AC BA--------------AB BA--------------AB BA--------------AB ------------------ ------------------ ------------------ ------------------ ------------------ ------------------ ------------------ 
BA--------------AB BA--------------AB BA--------------AB CA--------------AB BA--------------AB CA--------------AB BA--------------AB CA--------------AB BA--------------AB CA--------------AB BA--------------AB BA--------------AB BA--------------AB CA--------------AB BA--------------AB BA--------------AC CA--------------AB CA--------------AB CA--------------AB BA--------------AC BA--------------AB BA--------------AB BA--------------AB ------------------ ------------------ ------------------ ------------------ ------------------ ------------------ ------------------ 
BA--------------AB BA--------------AB BA--------------AB CA--------------AC BA--------------AC CA--------------AC CA--------------AC CA--------------AC BA--------------AB CA--------------AC BA--------------AC BA--------------AC BA--------------AC CA--------------AC BA--------------AB BA--------------AB BA--------------AC BA--------------AC BA--------------AC BA--------------AB BA--------------AB BA--------------AB BA--------------AB -----------------D ------------------ ------------------ ------------------ ------------------ ------------------ ------------------ 
BA--------------AB BA--------------AB BA--------------AB BA--------------AC BA--------------AB BA--------------AC BA--------------AB BA--------------AC BA--------------AB BA--------------AB CA--------------AB CA--------------AC CA--------------AB BA--------------AC BA--------------AB BA--------------AB CA--------------AB CA--------------AB CA--------------AB CA--------------AB BA--------------AB BA--------------AB BA--------------AB -----------------D -----------------D ------------------ ------------------ ------------------ ------------------ ------------------ 
BA--------------AB BA--------------AB BA--------------AB BA--------------AC BA--------------AB CA--------------AB CA--------------AB CA--------------AC BA--------------AB BA--------------AB BA--------------AB BA--------------AC BA--------------AB BA--------------AC BA--------------AB CA--------------AC CA--------------AC BA--------------AC BA--------------AC BA--------------AC BA--------------AB BA--------------AB BA--------------AB ------------------ -----------------D -----------------D ------------------ ------------------ ------------------ ------------------ 
BA--------------AB BA--------------AB BA--------------AB CA--------------AB CA--------------AB CA--------------AB BA--------------AB BA--------------AB BA--------------AB BA--------------AC BA--------------AC BA--------------AB BA--------------AC CA--------------AB BA--------------AB BA--------------AB CA--------------AB CA--------------AC CA--------------AB BA--------------AC BA--------------AB BA--------------AB BA--------------AB ------------------ ------------------ -----------------D -----------------D ------------------ ------------------ ------------------ 
BA--------------AB BA--------------AB BA--------------AB BA--------------AC BA--------------AC CA--------------AC CA--------------AC CA--------------AC BA--------------AB BA--------------AB BA--------------AB CA--------------AB BA--------------AB CA--------------AB BA--------------AB CA--------------AB CA--------------AB BA--------------AC BA--------------AB BA--------------AC BA--------------AB BA--------------AB BA--------------AB D----------------- D----------------- D----------------- D----------------D D----------------D DD--------------DD -DDDDDDDDDDDDDDDD- 
BA--------------AB BA--------------AB BA--------------AB BA--------------AC BA--------------AB BA--------------AB BA--------------AB BA--------------AB BA--------------AB CA--------------AB CA--------------AB CA--------------AB CA--------------AB CA--------------AB BA--------------AB BA--------------AC CA--------------AC CA--------------AB CA--------------AC CA--------------AB BA--------------AB BA--------------AB BA--------------AB ------------------ ------------------ ------------------ ------------------ ------------------ ------------------ ------------------ 
BA--------------AB BA--------------AB BA--------------AB CA--------------AC CA--------------AB CA--------------AB CA--------------AB CA--------------AB BA--------------AB BA--------------AB BA--------------AB BA--------------AB BA--------------AB BA--------------AB BA--------------AB BA--------------AB BA--------------AB BA--------------AB BA--------------AB BA--------------AB BA--------------AB BA--------------AB BA--------------AB ------------------ ------------------ ------------------ ------------------ ------------------ ------------------ ------------------ 
BA--------------AB BA--------------AB BA--------------AB BA--------------AB BA--------------AB BA--------------AB CA--------------AB CA--------------AB BA--------------AB BA--------------AB BA--------------AB BA--------------AB BA--------------AB BA--------------AB BA--------------AB BA--------------AC BA--------------AC BA--------------AC BA--------------AC BA--------------AC BA--------------AB BA--------------AB BA--------------AB ------------------ ------------------ ------------------ ------------------ ------------------ ------------------ ------------------ 
BA--------------AB BA--------------AB BA--------------AB BA--------------AC BA--------------AC CA--------------AC CA--------------AC BA--------------AC BA--------------AB BA--------------AB BA--------------AB BA--------------AB BA--------------AB BA--------------AB BA--------------AB CA--------------AB BA--------------AB BA--------------AC BA--------------AB CA--------------AB BA--------------AB BA--------------AB BA--------------AB ------------------ ------------------ ------------------ ------------------ ------------------ ------------------ ------------------ 
BA--------------AB BA--------------AB BA--------------AB BA--------------AB BA--------------AB BA--------------AC CA--------------AB CA--------------AC BA--------------AB BA--------------AB BA--------------AB BA--------------AB BA--------------AB BA--------------AB BA--------------AB CA--------------AB CA--------------AB CA--------------AC CA--------------AC CA--------------AB BA--------------AB BA--------------AB BA--------------AB ------------------ ------------------ ------------------ ------------------ ------------------ ------------------ ------------------ 
BA--------------AB BA--------------AB BA--------------AB CA--------------AB CA--------------AB CA--------------AB CA--------------AB CA--------------AC BA--------------AB BA--------------AB BA--------------AB BA--------------AB BA--------------AB BA--------------AB BA--------------AB CA--------------AC BA--------------AC BA--------------AB BA--------------AB CA--------------AC BA--------------AB BA--------------AB BA--------------AB ------------------ ------------------ ------------------ ------------------ ------------------ ------------------ ------------------ 
BA--------------AB BA--------------AB BA--------------AB BA--------------AB BA--------------AB BA--------------AB BA--------------AB BA--------------AB BA--------------AB BA--------------AB BA--------------AB BA--------------AB BA--------------AB BA--------------AB BA--------------AB BA--------------AB BA--------------AB BA--------------AB BA--------------AB BA--------------AB BA--------------AB BA--------------AB BA--------------AB ------------------ ------------------ ------------------ ------------------ ------------------ ------------------ ------------------ 
