model
size = 30 31 12, scale = 0.05, origin = -y
material 
  colors = A:#A0A0A0 B:#CE3925 C:#FFF D:#EEE E:#AAA F:#656765 G:#DCDCDC H:#FFFFFB I:#F05E1C J:#F75C2F K:#9B9B9B L:#FBE251 M:#ED784A N:#CC543A O:#B54434 P:#FFB11B Q:#F6C555 R:#BDC0BA S:#D19826
voxels
------------------------------ ------------------------------ ------------------------------ ------------------------------ ------------------------------ ------------------------------ ------------------------------ ------------------------------ ------------------------------ ------------------------------ ------------------------------ ------------------------------ ------------------------------ ------------------------------ ----FDBBBBDAFAFAFAFAFDBBDAF--- ----ADDBBDDAAAAAAAAAAADDAAA--- ----AADDDDAA---------AAAA----- -----AAAAAA-----------AA------ ------AAAA-------------------- -------AA--------------------- ------------------------------ ------------------------------ ------------------------------ ------------------------------ ------------------------------ ---------B-------------------- ---------H-------------------- ---------H-------------------- ------------------------------ ------------------------------ ------------------------------ 
------------------------------ ------------------------------ ------------------------------ ------------------------------ ------------------------------ ------------------------------ ------------------------------ ------------------------------ ------------------------------ ------------------------------ ------------------------------ ------------------------------ ------------------------------ ------------------------------ ---AGDDDDDDGGGGGGGGGGDDDDGGA-- ---AAAAAAAAAACCCCCCCCCCCCAAA-- ----DDDDDDDDEEEEEDDDDDDDDDD--- ----EDDDDDDFFEKEKEFFDDDDDDF--- ----FFDDDDFFFFEKEKEFFDDDD----- ----AFFDDFFAFFFEKEKEFFFF------ ----AAFFFFAAAF-EEKEE---------- -----AAAAAABA---EEKEE--------- ------AAAABA-----EEE---------- -------AAAAA-----E------------ ---------AA------------------- ------------------------------ ------------------------------ ---------H-------------------- ---------H-------------------- ------------------------------ ------------------------------ 
------------------------------ ------------------------------ ------------------------------ ------------------------------ ------------------------------ ------------------------------ ------------------------------ ------------------------------ ------------------------------ ------------------------------ ------N----------------------- -----BOB-------N--------N----- ------B-------BOB------BOB---- ------------------------------ -AFCCCCCCCECGCCCCCCECCCCCCCCF- -AAAACCCCCCCCCCCCCCCCCCCCCCAA- --DDABBBBBBBBBBBBBBBBBBBBBBD-- --EEA----------------------F-- --FFA--------------------FAA-- --ADA-------------------FAA--- --ADA---------F-----EEEEEE---- --ADDAAAAA-AAAAA---AAR-------- --ADDDAAAAAAAAAAAARA---------- --ADKDDAAAAAAAAREA------------ --AADKDDDAAAAAE--------------- --AADDDDDDAAER---------------- --AAADDDDAAE------------------ --AAADDAAAAE------------------ ---AAAA-EAER------------------ ----AA--AEA------------------- ------------------------------ 
------------------------------ ------------------------------ ------------------------------ ------------------------------ ------------------------------ ------------------------------ ------------------------------ ------------------------------ -----J------------------------ -----BI-------J----------J---- -----MBB------BI--------IB---- -----BBBN-----MBB------BBM---- -----BBB-----BBBBN----NBBBB--- ------B--------B--------B----- FCCCGEEEEEGEEEEEEEECEEEEEGECCA A-ACCCCCCCCCCCCCCCCCCCCCCCCCAA -DABBBBBBBBBBBBBBBBBBBBBBBBBD- -EA-------------------------F- -FA-------------------------A- -AA------------------------AA- -AA------------------DDDEEEE-- -AA----------------DDHHH------ -AA--------------DDHH--------- -AA------------DDHH----------- -AA-----------DHH------------- -AA---------DDH--------------- -A---------DHH---------------- ----------DAH----------------- ----------DAH----------------- ----------DD------------------ ------------------------------ 
------------------------------ ------------------------------ ------------------------------ ------------------------------ ------------------------------ --------------Q--------------- -----L--------L--------------- -----PM-------QM---------L---- -----MI-N-----PM--------MP---- -----IIIB-----MI-N----N-IM---- ----OBBBO-----IIIB----BIII---- ----NBBBB----OBBBO----OBBBO--- ---BBBBB----BNBBBB----BBBBNB-- -----BB-------BBB------BBB---- ACDEEGCCGCEGCGCGCGCEGCGGCEGDCF ACCCCCCCCCCCCCCCCCCCCCCCCCCCCA KBBBBBDBBDBDBDDDBDDDBDDBDBDBBD K----------------------------F FA---------------------------A FA--------------------------AA AA-----------------------EEEE- AA--------------------AAH----- BA------------------AH-------- AA----------------AH---------- -A--------------AH------------ -A-----------AAH-------------- -A---------DAH---------------- -A---------DA----------------- -R--------DAH----------------- ----------DD------------------ ----------DD------------------ 
------------------------------ ------------------------------ ------L--------L-------------- ------L--------L-------------- ------L-------LP-------------- -----LQ-------LQ--------L----- -----QP-------QP--------QL---- -----SIQ------PIQ-------PQ---- ----PJIM-----PSIQ------QIS---- ----JIJIJ----PJIM------MIJP--- ---BBBBBB----JIJ-J----JIJIJ--- ---BOBBBBB---BBBBB----BBBBB--- ----BBBBB---BOBBBB----BBBBOB-- ----BBBB-----BBBBB----BBBBB--- FCDGECGGCGECGCGCGCGECGCCGEGDCA ACCCCCCCCCCCCCCCCCCCCCCCCCCCCA ABBDDBDBDDBDBBBDBBBDBDBBDDDBBD K----------------------------F K----------------------------A F----------------------------A A------------------------EEEE- A---------------------AAH----- B-------------------AH-------- A-----------------AH---------- R---------------AH------------ D------------AAB-------------- -A---------DAH---------------- -A---------DA----------------- -R--------HAH----------------- -R--------HD------------------ ----------DD------------------ 
---------------L-------------- ---------------L-------------- ---------------L-------------- --------------LQ--------L----- --------------QP--------L----- ------L-------SLQ-------QL---- -----LQ------PLQS-------PQ---- -----QP------PJIQJ-----QIS---- -----SIQ-----PJIMJ-----MIJP--- ----PJIM----PJIJIJ----JIJIJ--- ----JIJIJ---BBBBBBJ---BBBBBB-- ----BBBBB---BOBBBBB--BBBBBOB-- ---BOBBBB----BBBBB----BBBBB--- ----BBBBB----BBBB------BBBB--- ACDGECGGCGECGCGCGCGECGCCGEGDCF ACCCCCCCCCCCCCCCCCCCCCCCCCCCCA ABBDDBDDBDBBBDDBBDDBBDBBDBDBBD K----------------------------F K----------------------------A F----------------------------A A------------------------EEEE- A---------------------AAH----- B-------------------AH-------- A-----------------AH---------- R---------------AH------------ D------------AAB-------------- -A---------DAH---------------- -A---------DA----------------- -R--------HAH----------------- -R--------HD------------------ ----------DD------------------ 
------------------------------ ------------------------------ ------------------------------ ------------------------------ ------------------------------ --------------Q--------------- --------------S----------L---- -----L--------PM--------MP---- -----PM-------MI-N----N-IM---- -----MI-N-----IIIB----BIII---- -----IIIB----OBBBO----OBBBO--- ----OBBBO----NBBBB----BBBBN--- ---BNBBBB---BBBBB------BBBBB-- -----BBB------BB--------BB---- FCDEEGCCGCEGCGCGCGCEGCGGCEGDCA ACCCCCCCCCCCCCCCCCCCCCCCCCCCCA KBBBBBDBBDBDBDDDBDDDBDBBDDDBBD K----------------------------F FA---------------------------A FA--------------------------AA AA-----------------------EEEE- AA--------------------AAH----- BA------------------AH-------- AA----------------AH---------- -A--------------AH------------ -A-----------AAH-------------- -A---------DAH---------------- -A---------DA----------------- -R--------DAH----------------- ----------DD------------------ ----------DD------------------ 
------------------------------ ------------------------------ ------------------------------ ------------------------------ ------------------------------ ------------------------------ ------------------------------ ------------------------------ --------------J----------J---- -----J--------BI--------IB---- -----BI-------MBB------BBM---- -----MBB------BBBN----NBBB---- ----BBBBN-----BBB------BBB---- ------B--------B--------B----- ACCCGEEEEEGEEEEEEEECEEEEEGECCF A-ACCCCCCCCCCCCCCCCCCCCCCCCCAA -DABBBBBBBBBBBBBBBBBBBBBBBBBD- -EA-------------------------F- -FA-------------------------A- -AA------------------------AA- -AA------------------DDDEEEE-- -AA----------------DDHHH------ -AA--------------DDHH--------- -AA------------DDHH----------- -AA-----------DHH------------- -AA---------DDH--------------- -A---------DHH---------------- ----------DAH----------------- ----------DAH----------------- ----------DD------------------ ------------------------------ 
------------------------------ ------------------------------ ------------------------------ ------------------------------ ------------------------------ ------------------------------ ------------------------------ ------------------------------ ------------------------------ ------------------------------ ---------------N--------N----- ------N-------BOB------BOB---- -----BOB-------B--------B----- ------------------------------ -FAGCCCCCCECGCCCCCCECCCCCCCCA- -AAAACCCCCCCCCCCCCCCCCCCCCCAA- --DDABBBBBBBBBBBBBBBBBBBBBBD-- --EEA----------------------F-- --FFA--------------------FAA-- --ADA-------------------FAA--- --ADA---------F-----EEEEEE---- --ADDAAAAA-AAAAA---AAR-------- --ADDDAAAAAAAAAAAARA---------- --ADKDDAAAAAAAAREA------------ --AADKDDDAAAAAE--------------- --AADDDDDDAAER---------------- --AAADDDDAAA------------------ --AAADDAAAAA------------------ ---AAAA-AAAR------------------ ----AA--AAA------------------- ------------------------------ 
------------------------------ ------------------------------ ------------------------------ ------------------------------ ------------------------------ ------------------------------ ------------------------------ ------------------------------ ------------------------------ ------------------------------ ------------------------------ ------------------------------ ------------------------------ ------------------------------ ---FGDDDDDDGGGGGGGGGGDDDDGGF-- ---AAAAAAAAAACCCCCCCCCCCCAAA-- ----DDDDDDDDEEEEEDDDDDDDDDD--- ----EDDDDDDFFEKEKEFFDDDDDDF--- ----FFDDDDFFFFEKEKEFFDDDD----- ----AFFDDFFAFFFEKEKEFFFF------ ----AAFFFFAAAF-EEKEE---------- -----AAAAAABA---EEKEE--------- ------AAAABA-----EEE---------- -------AAAAA-----E------------ ---------AA------------------- ------------------------------ ------------------------------ ---------H-------------------- ---------H-------------------- ------------------------------ ------------------------------ 
------------------------------ ------------------------------ ------------------------------ ------------------------------ ------------------------------ ------------------------------ ------------------------------ ------------------------------ ------------------------------ ------------------------------ ------------------------------ ------------------------------ ------------------------------ ------------------------------ ----ADBBBBDFAFAFAFAFADBBDFA--- ----ADDBBDDAAAAAAAAAAADDAAA--- ----AADDDDAA---------AAAA----- -----AAAAAA-----------AA------ ------AAAA-------------------- -------AA--------------------- ------------------------------ ------------------------------ ------------------------------ ------------------------------ ------------------------------ ---------B-------------------- ---------H-------------------- ---------H-------------------- ------------------------------ ------------------------------ ------------------------------ 
