model
size = 30, scale = 0.05, origin = -y
material 
  colors = A:#FFF B:#B00 C:#111 D:#A00 E:#800 F:#D00 G:#EE4242 H:#EF868A
voxels
AAAAAAAAAAAAAAAAAAAAAAAAAAAAAA AAAAAAAAAAAAAAAAAAAAAAAAAAAAAA AAAAAAAAAAAAAAAAAAAAAAAAAAAAAA AAAAAAAAAAAAAAAAAAAAAAAAAAAAAA AAAAAAAAAAAAAAAAAAAAAAAAAAAAAA AAAAAAAAAAAAAAAAAAAAAAAAAAAAAA AAAAAAAAAAAAAAAAAAAAAAAAAAAAAA AAAAAAAAAAAAAAAAAAAAAAAAAAAAAA AAAAAAAAAAAAAAAAAAAAAAAAAAAAAA AAAAAAAAAAAAAAAAAAAAAAAAAAAAAA AAAAAAAAAAAAAAAAAAAAAAAAAAAAAA AAAAAAAAAAAAAAAAAAAAAAAAAAAAAA AAAAAAAAAAAAAAAAAAAAAAAAAAAAAA AAAAAAAAAAAAAAAAAAAAAAAAAAAAAA AAAAAAAAAAAAAAAAAAAAAAAAAAAAAA AAAAAAAAAAAAAAAAAAAAAAAAAAAAAA AAAAAAAAAAAAAAAAAAAAAAAAAAAAAA AAAAAAAAAAAAAAAAAAAAAAAAAAAAAA AAAAAAAAAAAAAAAAAAAAAAAAAAAAAA AAAAAAAAAAAAAAAAAAAAAAAAAAAAAA AAAAAAAAAAAAAAAAAAAAAAAAAAAAAA AAAAAAAAAAAAAAAAAAAAAAAAAAAAAA AAAAAAAAAAAAAAAAAAAAAAAAAAAAAA AAAAAAAAAAAAAAAAAAAAAAAAAAAAAA AAAAAAAAAAAAAAAAAAAAAAAAAAAAAA AAAAAAAAAAAAAAAAAAAAAAAAAAAAAA AAAAAAAAAAAAAAAAAAAAAAAAAAAAAA AAAAAAAAAAAAAAAAAAAAAAAAAAAAAA AAAAAAAAAAAAAAAAAAAAAAAAAAAAAA AAAAAAAAAAAAAAAAAAAAAAAAAAAAAA 
AAAAAAAAAAAAAAAAAAAAAAAAAAAAAA A----------AAAAAAAAAAAAAAAAAAA A----------AAAAAAAAAAAAAAAAAAA A----------AAAAAAAAAAAAAAAAAAA A----------AAAAAAAAAAAAAAAAAAA A----------AAAAAAAAAAAAAAAAAAA A----------AAAAAAAAAAAAAAAAAAA A----------AAAAAAAAAAAAAAAAAAA A----------AAAAAAAAAAAAAAAAAAA A----------AAAAAAAAAAAAAAAAAAA A----------AAAAAAAAAAAAAAAAAAA A----------AAAAAAAAAAAAAAAAAAA A----------AAAAAAAAAAAAAAAAAAA A----------AAAAAAAAAAAAAAAAAAA A----------AAAAAAAAAAAAAAAAAAA A----------AAAAAAAAAAAAAAAAAAA A----------AAAAAAAAAAAAAAAAAAA A----------AAAAAAAAAAAAAAAAAAA A----------AAAAAAAAAAAAAAAAAAA A----------AAAAAAAAAAAAAAAAAAA A----------AAAAAAAAAAAAAAAAAAA A----------AAAAAAAAAAAAAAAAAAA A----------AAAAAAAAAAAAAAAAAAA A----------AAAAAAAAAAAAAAAAAAA A----------AAAAAAAAAAAAAAAAAAA A----------AAAAAAAAAAAAAAAAAAA A----------AAAAAAAAAAAAAAAAAAA A----------AAAAAAAAAAAAAAAAAAA A----------AAAAAAAAAAAAAAAAAAA AAAAAAAAAAAAAAAAAAAAAAAAAAAAAA 
AAAAAAAAAAAAAAAAAAAAAAAAAAAAAA A----------AAAAAAAAAAAAAAAAAAA -----------AAAAAAAAAAAAAAAAAAA -----------AAAAAAAAAAAAAAAAAAA -----------AAAAAAAAAAAAAAAAAAA -----------AAAAAAAAAAAAAAAAAAA -----------AAAAAAAAAAAAAAAAAAA -----------AAAAAAAAAAAAAAAAAAA -----------AAAAAAAAAAAAAAAAAAA -----------AAAAAAAAAAAAAAAAAAA -----------AAAAAAAAAAAAAAAAAAA -----------AAAAAAAAAAAAAAAAAAA -----------AAAAAAAAAAAAAAAAAAA -----------AAAAAAAAAAAAAAAAAAA -----------AAAAAAAAAAAAAAAAAAA ------CC---AAAAAAAAAAAAAAAAAAA ------CC---AAAAAAAAAAAAAAAAAAA ------CC---AAAAAAAAAAAAAAAAAAA ------CC---AAAAAAAAAAAAAAAAAAA ------CC---AAAAAAAAAAAAAAAAAAA ------CC---AAAAAAAAAAAAAAAAAAA ------CC---AAAAAAAAAAAAAAAAAAA ------CC---AAAAAAAAAAAAAAAAAAA ------CC---AAAAAAAAAAAAAAAAAAA ------CC---AAAAAAAAAAAAAAAAAAA -----------AAAAAAAAAAAAAAAAAAA -----------AAAAAAAAAAAAAAAAAAA -----------AAAAAAAAAAAAAAAAAAA A----------AAAAAAAAAAAAAAAAAAA AAAAAAAAAAAAAAAAAAAAAAAAAAAAAA 
AAAAAAAAAAAAAAAAAAAAAAAAAAAAAA A----------AAAAAAAAAAAAAAAAAAA -----------AAAAAAAAAAAAAAAAAAA -----------AAAAAAAAAAAAAAAAAAA -----------AAAAAAAAAAAAAAAAAAA -----------AAAAAAAAAAAAAAAAAAA -----------AAAAAAAAAAAAAAAAAAA -----------AAAAAAAAAAAAAAAAAAA -----------AAAAAAAAAAAAAAAAAAA -----------AAAAAAAAAAAAAAAAAAA -----------AAAAAAAAAAAAAAAAAAA -----------AAAAAAAAAAAAAAAAAAA -----------AAAAAAAAAAAAAAAAAAA -----------AAAAAAAAAAAAAAAAAAA -----------AAAAAAAAAAAAAAAAAAA ------CC---AAAAAAAAAAAAAAAAAAA ------CC---AAAAAAAAAAAAAAAAAAA ------CC---AAAAAAAAAAAAAAAAAAA ------CC---AAAAAAAAAAAAAAAAAAA ------CC---AAAAAAAAAAAAAAAAAAA ------CC---AAAAAAAAAAAAAAAAAAA ------CC---AAAAAAAAAAAAAAAAAAA ------CC---AAAAAAAAAAAAAAAAAAA ------CC---AAAAAAAAAAAAAAAAAAA ------CC---AAAAAAAAAAAAAAAAAAA -----------AAAAAAAAAAAAAAAAAAA -----------AAAAAAAAAAAAAAAAAAA -----------AAAAAAAAAAAAAAAAAAA A----------AAAAAAAAAAAAAAAAAAA AAAAAAAAAAAAAAAAAAAAAAAAAAAAAA 
AAAAAAAAAAAAAAAAAAAAAAAAAAAAAA A----------AAAAAAAAAAAAAAAAAAA -----------AAAAAAAAAAAAAAAAAAA -----------AAAAAAAAAAAAAAAAAAA -----------AAAAAAAAAAAAAAAAAAA -----------AAAAAAAAAAAAAAAAAAA -----------AAAAAAAAAAAAAAAAAAA -----------AAAAAAAAAAAAAAAAAAA -----------AAAAAAAAAAAAAAAAAAA -----------AAAAAAAAAAAAAAAAAAA -----------AAAAAAAAAAAAAAAAAAA -----------AAAAAAAAAAAAAAAAAAA -----------AAAAAAAAAAAAAAAAAAA ------CC---AAAAAAAAAAAAAAAAAAA ------CC---AAAAAAAAAAAAAAAAAAA ------BB---AAAAAAAAAAAAAAAAAAA ------BB---AAAAAAAAAAAAAAAAAAA ------BB---AAAAAAAAAAAAAAAAAAA ------FF---AAAAAAAAAAAAAAAAAAA ------FF---AAAAAAAAAAAAAAAAAAA ------GG---AAAAAAAAAAAAAAAAAAA ------GG---AAAAAAAAAAAAAAAAAAA ------GG---AAAAAAAAAAAAAAAAAAA ------HH---AAAAAAAAAAAAAAAAAAA ------HH---AAAAAAAAAAAAAAAAAAA ------CC---AAAAAAAAAAAAAAAAAAA ------CC---AAAAAAAAAAAAAAAAAAA -----------AAAAAAAAAAAAAAAAAAA A----------AAAAAAAAAAAAAAAAAAA AAAAAAAAAAAAAAAAAAAAAAAAAAAAAA 
AAAAAAAAAAAAAAAAAAAAAAAAAAAAAA A----------AAAAAAAAAAAAAAAAAAA -----------AAAAAAAAAAAAAAAAAAA -----------AAAAAAAAAAAAAAAAAAA -----------AAAAAAAAAAAAAAAAAAA -----------AAAAAAAAAAAAAAAAAAA -----------AAAAAAAAAAAAAAAAAAA -----------AAAAAAAAAAAAAAAAAAA -----------AAAAAAAAAAAAAAAAAAA -----------AAAAAAAAAAAAAAAAAAA -----------AAAAAAAAAAAAAAAAAAA -----------AAAAAAAAAAAAAAAAAAA -----------AAAAAAAAAAAAAAAAAAA ------CC---AAAAAAAAAAAAAAAAAAA ------CC---AAAAAAAAAAAAAAAAAAA ------BB---AAAAAAAAAAAAAAAAAAA ------BB---AAAAAAAAAAAAAAAAAAA ------BB---AAAAAAAAAAAAAAAAAAA ------FF---AAAAAAAAAAAAAAAAAAA ------FF---AAAAAAAAAAAAAAAAAAA ------GG---AAAAAAAAAAAAAAAAAAA ------GG---AAAAAAAAAAAAAAAAAAA ------GG---AAAAAAAAAAAAAAAAAAA ------HH---AAAAAAAAAAAAAAAAAAA ------HH---AAAAAAAAAAAAAAAAAAA ------CC---AAAAAAAAAAAAAAAAAAA ------CC---AAAAAAAAAAAAAAAAAAA -----------AAAAAAAAAAAAAAAAAAA A----------AAAAAAAAAAAAAAAAAAA AAAAAAAAAAAAAAAAAAAAAAAAAAAAAA 
AAAAAAAAAAAAAAAAAAAAAAAAAAAAAA A----------AAAAAAAAAAAAAAAAAAA -----------AAAAAAAAAAAAAAAAAAA -----------AAAAAAAAAAAAAAAAAAA -----------AAAAAAAAAAAAAAAAAAA -----------AAAAAAAAAAAAAAAAAAA -----------AAAAAAAAAAAAAAAAAAA -----------AAAAAAAAAAAAAAAAAAA -----------AAAAAAAAAAAAAAAAAAA -----------AAAAAAAAAAAAAAAAAAA -----------AAAAAAAAAAAAAAAAAAA ------CC---AAAAAAAAAAAAAAAAAAA ------CC---AAAAAAAAAAAAAAAAAAA ------BB---AAAAAAAAAAAAAAAAAAA ------BB---AAAAAAAAAAAAAAAAAAA ------BB---AAAAAAAAAAAAAAAAAAA ------BB---AAAAAAAAAAAAAAAAAAA ------BB---AAAAAAAAAAAAAAAAAAA ------BB---AAAAAAAAAAAAAAAAAAA ------BB---AAAAAAAAAAAAAAAAAAA ------FF---AAAAAAAAAAAAAAAAAAA ------FF---AAAAAAAAAAAAAAAAAAA ------FF---AAAAAAAAAAAAAAAAAAA ------GG---AAAAAAAAAAAAAAAAAAA ------GG---AAAAAAAAAAAAAAAAAAA ------CC---AAAAAAAAAAAAAAAAAAA ------CC---AAAAAAAAAAAAAAAAAAA -----------AAAAAAAAAAAAAAAAAAA A----------AAAAAAAAAAAAAAAAAAA AAAAAAAAAAAAAAAAAAAAAAAAAAAAAA 
AAAAAAAAAAAAAAAAAAAAAAAAAAAAAA A----------AAAAAAAAAAAAAAAAAAA A----------AAAAAAAAAAAAAAAAAAA A----------AAAAAAAAAAAAAAAAAAA A----------AAAAAAAAAAAAAAAAAAA A----------AAAAAAAAAAAAAAAAAAA A----------AAAAAAAAAAAAAAAAAAA A----------AAAAAAAAAAAAAAAAAAA A----------AAAAAAAAAAAAAAAAAAA A----------AAAAAAAAAAAAAAAAAAA A----------AAAAAAAAAAAAAAAAAAA A-----CC---AAAAAAAAAAAAAAAAAAA A-----CC---AAAAAAAAAAAAAAAAAAA A-----BB---AAAAAAAAAAAAAAAAAAA A-----BB---AAAAAAAAAAAAAAAAAAA A-----BB---AAAAAAAAAAAAAAAAAAA A-----BB---AAAAAAAAAAAAAAAAAAA A-----BB---AAAAAAAAAAAAAAAAAAA A-----BB---AAAAAAAAAAAAAAAAAAA A-----BB---AAAAAAAAAAAAAAAAAAA A-----FF---AAAAAAAAAAAAAAAAAAA A-----FF---AAAAAAAAAAAAAAAAAAA A-----FF---AAAAAAAAAAAAAAAAAAA A-----GG---AAAAAAAAAAAAAAAAAAA A-----GG---AAAAAAAAAAAAAAAAAAA A-----CC---AAAAAAAAAAAAAAAAAAA A-----CC---AAAAAAAAAAAAAAAAAAA A----------AAAAAAAAAAAAAAAAAAA A----------AAAAAAAAAAAAAAAAAAA AAAAAAAAAAAAAAAAAAAAAAAAAAAAAA 
AAAAAAAAAAAAAAAAAAAAAAAAAAAAAA A----------AAAAAAAAAAAAAAAAAAA A----------AAAAAAAAAAAAAAAAAAA A----------AAAAAAAAAAAAAAAAAAA A----------AAAAAAAAAAAAAAAAAAA A----------AAAAAAAAAAAAAAAAAAA A----------AAAAAAAAAAAAAAAAAAA A----------AAAAAAAAAAAAAAAAAAA A----------AAAAAAAAAAAAAAAAAAA A----------AAAAAAAAAAAAAAAAAAA A----------AAAAAAAAAAAAAAAAAAA A-----CC---AAAAAAAAAAAAAAAAAAA A-----CC---AAAAAAAAAAAAAAAAAAA A-----BB---AAAAAAAAAAAAAAAAAAA A-----BB---AAAAAAAAAAAAAAAAAAA A-----BB---AAAAAAAAAAAAAAAAAAA A-----BB---AAAAAAAAAAAAAAAAAAA A-----BB---AAAAAAAAAAAAAAAAAAA A-----BB---AAAAAAAAAAAAAAAAAAA A-----BB---AAAAAAAAAAAAAAAAAAA A-----FF---AAAAAAAAAAAAAAAAAAA A-----FF---AAAAAAAAAAAAAAAAAAA A-----FF---AAAAAAAAAAAAAAAAAAA A-----GG---AAAAAAAAAAAAAAAAAAA A-----GG---AAAAAAAAAAAAAAAAAAA A-----CC---AAAAAAAAAAAAAAAAAAA A-----CC---AAAAAAAAAAAAAAAAAAA A----------AAAAAAAAAAAAAAAAAAA A----------AAAAAAAAAAAAAAAAAAA AAAAAAAAAAAAAAAAAAAAAAAAAAAAAA 
AAAAAAAAAAAAAAAAAAAAAAAAAAAAAA A----------AAAAAAAAAAAAAAAAAAA -----------AAAAAAAAAAAAAAAAAAA -----------AAAAAAAAAAAAAAAAAAA -----------AAAAAAAAAAAAAAAAAAA -----------AAAAAAAAAAAAAAAAAAA -----------AAAAAAAAAAAAAAAAAAA -----------AAAAAAAAAAAAAAAAAAA ------CC---AAAAAAAAAAAAAAAAAAA ------CC---AAAAAAAAAAAAAAAAAAA ------CC---AAAAAAAAAAAAAAAAAAA ------BB---AAAAAAAAAAAAAAAAAAA ------BB---AAAAAAAAAAAAAAAAAAA ------BB---AAAAAAAAAAAAAAAAAAA ------BB---AAAAAAAAAAAAAAAAAAA ------BB---AAAAAAAAAAAAAAAAAAA ------BB---AAAAAAAAAAAAAAAAAAA ------BB---AAAAAAAAAAAAAAAAAAA ------BB---AAAAAAAAAAAAAAAAAAA ------BB---AAAAAAAAAAAAAAAAAAA ------BB---AAAAAAAAAAAAAAAAAAA ------BB---AAAAAAAAAAAAAAAAAAA ------BB---AAAAAAAAAAAAAAAAAAA ------FF---AAAAAAAAAAAAAAAAAAA ------FF---AAAAAAAAAAAAAAAAAAA ------CC---AAAAAAAAAAAAAAAAAAA ------CC---AAAAAAAAAAAAAAAAAAA -----------AAAAAAAAAAAAAAAAAAA A----------AAAAAAAAAAAAAAAAAAA AAAAAAAAAAAAAAAAAAAAAAAAAAAAAA 
AAAAAAAAAAAAAAAAAAAAAAAAAAAAAA A----------AAAAAAAAAAAAAAAAAAA -----------AAAAAAAAAAAAAAAAAAA -----------AAAAAAAAAAAAAAAAAAA -----------AAAAAAAAAAAAAAAAAAA -----------AAAAAAAAAAAAAAAAAAA -----------AAAAAAAAAAAAAAAAAAA -----------AAAAAAAAAAAAAAAAAAA ------CC---AAAAAAAAAAAAAAAAAAA ------CC---AAAAAAAAAAAAAAAAAAA ------CC---AAAAAAAAAAAAAAAAAAA ------BB---AAAAAAAAAAAAAAAAAAA ------BB---AAAAAAAAAAAAAAAAAAA ------BB---AAAAAAAAAAAAAAAAAAA ------BB---AAAAAAAAAAAAAAAAAAA ------BB---AAAAAAAAAAAAAAAAAAA ------BB---AAAAAAAAAAAAAAAAAAA ------BB---AAAAAAAAAAAAAAAAAAA ------BB---AAAAAAAAAAAAAAAAAAA ------BB---AAAAAAAAAAAAAAAAAAA ------BB---AAAAAAAAAAAAAAAAAAA ------BB---AAAAAAAAAAAAAAAAAAA ------BB---AAAAAAAAAAAAAAAAAAA ------FF---AAAAAAAAAAAAAAAAAAA ------FF---AAAAAAAAAAAAAAAAAAA ------CC---AAAAAAAAAAAAAAAAAAA ------CC---AAAAAAAAAAAAAAAAAAA -----------AAAAAAAAAAAAAAAAAAA A----------AAAAAAAAAAAAAAAAAAA AAAAAAAAAAAAAAAAAAAAAAAAAAAAAA 
AAAAAAAAAAAAAAAAAAAAAAAAAAAAAA A----------AAAAAAAAAAAAAAAAAAA -----------AAAAAAAAAAAAAAAAAAA -----------AAAAAAAAAAAAAAAAAAA -----------AAAAAAAAAAAAAAAAAAA -----------AAAAAAAAAAAAAAAAAAA ------CC---AAAAAAAAAAAAAAAAAAA ------CC---AAAAAAAAAAAAAAAAAAA ------BB---AAAAAAAAAAAAAAAAAAA ------BB---AAAAAAAAAAAAAAAAAAA ------BB---AAAAAAAAAAAAAAAAAAA ------BB---AAAAAAAAAAAAAAAAAAA ------BB---AAAAAAAAAAAAAAAAAAA ------BB---AAAAAAAAAAAAAAAAAAA ------BB---AAAAAAAAAAAAAAAAAAA ------BB---AAAAAAAAAAAAAAAAAAA ------BB---AAAAAAAAAAAAAAAAAAA ------BB---AAAAAAAAAAAAAAAAAAA ------BB---AAAAAAAAAAAAAAAAAAA ------BB---AAAAAAAAAAAAAAAAAAA ------BB---AAAAAAAAAAAAAAAAAAA ------BB---AAAAAAAAAAAAAAAAAAA ------BB---AAAAAAAAAAAAAAAAAAA ------CC---AAAAAAAAAAAAAAAAAAA ------CC---AAAAAAAAAAAAAAAAAAA -----------AAAAAAAAAAAAAAAAAAA -----------AAAAAAAAAAAAAAAAAAA -----------AAAAAAAAAAAAAAAAAAA A----------AAAAAAAAAAAAAAAAAAA AAAAAAAAAAAAAAAAAAAAAAAAAAAAAA 
AAAAAAAAAAAAAAAAAAAAAAAAAAAAAA A----------AAAAAAAAAAAAAAAAAAA -----------AAAAAAAAAAAAAAAAAAA -----------AAAAAAAAAAAAAAAAAAA -----------AAAAAAAAAAAAAAAAAAA -----------AAAAAAAAAAAAAAAAAAA ------CC---AAAAAAAAAAAAAAAAAAA ------CC---AAAAAAAAAAAAAAAAAAA ------BB---AAAAAAAAAAAAAAAAAAA ------BB---AAAAAAAAAAAAAAAAAAA ------BB---AAAAAAAAAAAAAAAAAAA ------BB---AAAAAAAAAAAAAAAAAAA ------BB---AAAAAAAAAAAAAAAAAAA ------BB---AAAAAAAAAAAAAAAAAAA ------BB---AAAAAAAAAAAAAAAAAAA ------BB---AAAAAAAAAAAAAAAAAAA ------BB---AAAAAAAAAAAAAAAAAAA ------BB---AAAAAAAAAAAAAAAAAAA ------BB---AAAAAAAAAAAAAAAAAAA ------BB---AAAAAAAAAAAAAAAAAAA ------BB---AAAAAAAAAAAAAAAAAAA ------BB---AAAAAAAAAAAAAAAAAAA ------BB---AAAAAAAAAAAAAAAAAAA ------CC---AAAAAAAAAAAAAAAAAAA ------CC---AAAAAAAAAAAAAAAAAAA -----------AAAAAAAAAAAAAAAAAAA -----------AAAAAAAAAAAAAAAAAAA -----------AAAAAAAAAAAAAAAAAAA A----------AAAAAAAAAAAAAAAAAAA AAAAAAAAAAAAAAAAAAAAAAAAAAAAAA 
AAAAAAAAAAAAAAAAAAAAAAAAAAAAAA A----------AAAAAAAAAAAAAAAAAAA -----------AAAAAAAAAAAAAAAAAAA -----------AAAAAAAAAAAAAAAAAAA ------CC---AAAAAAAAAAAAAAAAAAA ------CC---AAAAAAAAAAAAAAAAAAA ------EE---AAAAAAAAAAAAAAAAAAA ------EE---AAAAAAAAAAAAAAAAAAA ------DD---AAAAAAAAAAAAAAAAAAA ------DD---AAAAAAAAAAAAAAAAAAA ------DD---AAAAAAAAAAAAAAAAAAA ------BB---AAAAAAAAAAAAAAAAAAA ------BB---AAAAAAAAAAAAAAAAAAA ------BB---AAAAAAAAAAAAAAAAAAA ------BB---AAAAAAAAAAAAAAAAAAA ------BB---AAAAAAAAAAAAAAAAAAA ------BB---AAAAAAAAAAAAAAAAAAA ------BB---AAAAAAAAAAAAAAAAAAA ------BB---AAAAAAAAAAAAAAAAAAA ------BB---AAAAAAAAAAAAAAAAAAA ------CC---AAAAAAAAAAAAAAAAAAA ------CC---AAAAAAAAAAAAAAAAAAA ------CC---AAAAAAAAAAAAAAAAAAA -----------AAAAAAAAAAAAAAAAAAA -----------AAAAAAAAAAAAAAAAAAA -----------AAAAAAAAAAAAAAAAAAA -----------AAAAAAAAAAAAAAAAAAA -----------AAAAAAAAAAAAAAAAAAA A----------AAAAAAAAAAAAAAAAAAA AAAAAAAAAAAAAAAAAAAAAAAAAAAAAA 
AAAAAAAAAAAAAAAAAAAAAAAAAAAAAA A----------AAAAAAAAAAAAAAAAAAA A----------AAAAAAAAAAAAAAAAAAA A----------AAAAAAAAAAAAAAAAAAA A-----CC---AAAAAAAAAAAAAAAAAAA A-----CC---AAAAAAAAAAAAAAAAAAA A-----EE---AAAAAAAAAAAAAAAAAAA A-----EE---AAAAAAAAAAAAAAAAAAA A-----DD---AAAAAAAAAAAAAAAAAAA A-----DD---AAAAAAAAAAAAAAAAAAA A-----DD---AAAAAAAAAAAAAAAAAAA A-----BB---AAAAAAAAAAAAAAAAAAA A-----BB---AAAAAAAAAAAAAAAAAAA A-----BB---AAAAAAAAAAAAAAAAAAA A-----BB---AAAAAAAAAAAAAAAAAAA A-----BB---AAAAAAAAAAAAAAAAAAA A-----BB---AAAAAAAAAAAAAAAAAAA A-----BB---AAAAAAAAAAAAAAAAAAA A-----BB---AAAAAAAAAAAAAAAAAAA A-----BB---AAAAAAAAAAAAAAAAAAA A-----CC---AAAAAAAAAAAAAAAAAAA A-----CC---AAAAAAAAAAAAAAAAAAA A-----CC---AAAAAAAAAAAAAAAAAAA A----------AAAAAAAAAAAAAAAAAAA A----------AAAAAAAAAAAAAAAAAAA A----------AAAAAAAAAAAAAAAAAAA A----------AAAAAAAAAAAAAAAAAAA A----------AAAAAAAAAAAAAAAAAAA A----------AAAAAAAAAAAAAAAAAAA AAAAAAAAAAAAAAAAAAAAAAAAAAAAAA 
AAAAAAAAAAAAAAAAAAAAAAAAAAAAAA A----------AAAAAAAAAAAAAAAAAAA A----------AAAAAAAAAAAAAAAAAAA A----------AAAAAAAAAAAAAAAAAAA A-----CC---AAAAAAAAAAAAAAAAAAA A-----CC---AAAAAAAAAAAAAAAAAAA A-----EE---AAAAAAAAAAAAAAAAAAA A-----EE---AAAAAAAAAAAAAAAAAAA A-----DD---AAAAAAAAAAAAAAAAAAA A-----DD---AAAAAAAAAAAAAAAAAAA A-----DD---AAAAAAAAAAAAAAAAAAA A-----BB---AAAAAAAAAAAAAAAAAAA A-----BB---AAAAAAAAAAAAAAAAAAA A-----BB---AAAAAAAAAAAAAAAAAAA A-----BB---AAAAAAAAAAAAAAAAAAA A-----BB---AAAAAAAAAAAAAAAAAAA A-----BB---AAAAAAAAAAAAAAAAAAA A-----BB---AAAAAAAAAAAAAAAAAAA A-----BB---AAAAAAAAAAAAAAAAAAA A-----BB---AAAAAAAAAAAAAAAAAAA A-----CC---AAAAAAAAAAAAAAAAAAA A-----CC---AAAAAAAAAAAAAAAAAAA A-----CC---AAAAAAAAAAAAAAAAAAA A----------AAAAAAAAAAAAAAAAAAA A----------AAAAAAAAAAAAAAAAAAA A----------AAAAAAAAAAAAAAAAAAA A----------AAAAAAAAAAAAAAAAAAA A----------AAAAAAAAAAAAAAAAAAA A----------AAAAAAAAAAAAAAAAAAA AAAAAAAAAAAAAAAAAAAAAAAAAAAAAA 
AAAAAAAAAAAAAAAAAAAAAAAAAAAAAA A----------AAAAAAAAAAAAAAAAAAA -----------AAAAAAAAAAAAAAAAAAA -----------AAAAAAAAAAAAAAAAAAA -----------AAAAAAAAAAAAAAAAAAA -----------AAAAAAAAAAAAAAAAAAA ------CC---AAAAAAAAAAAAAAAAAAA ------CC---AAAAAAAAAAAAAAAAAAA ------EE---AAAAAAAAAAAAAAAAAAA ------EE---AAAAAAAAAAAAAAAAAAA ------EE---AAAAAAAAAAAAAAAAAAA ------DD---AAAAAAAAAAAAAAAAAAA ------DD---AAAAAAAAAAAAAAAAAAA ------BB---AAAAAAAAAAAAAAAAAAA ------BB---AAAAAAAAAAAAAAAAAAA ------BB---AAAAAAAAAAAAAAAAAAA ------BB---AAAAAAAAAAAAAAAAAAA ------BB---AAAAAAAAAAAAAAAAAAA ------BB---AAAAAAAAAAAAAAAAAAA ------BB---AAAAAAAAAAAAAAAAAAA ------FF---AAAAAAAAAAAAAAAAAAA ------FF---AAAAAAAAAAAAAAAAAAA ------FF---AAAAAAAAAAAAAAAAAAA ------CC---AAAAAAAAAAAAAAAAAAA ------CC---AAAAAAAAAAAAAAAAAAA -----------AAAAAAAAAAAAAAAAAAA -----------AAAAAAAAAAAAAAAAAAA -----------AAAAAAAAAAAAAAAAAAA A----------AAAAAAAAAAAAAAAAAAA AAAAAAAAAAAAAAAAAAAAAAAAAAAAAA 
AAAAAAAAAAAAAAAAAAAAAAAAAAAAAA A----------AAAAAAAAAAAAAAAAAAA -----------AAAAAAAAAAAAAAAAAAA -----------AAAAAAAAAAAAAAAAAAA -----------AAAAAAAAAAAAAAAAAAA -----------AAAAAAAAAAAAAAAAAAA ------CC---AAAAAAAAAAAAAAAAAAA ------CC---AAAAAAAAAAAAAAAAAAA ------EE---AAAAAAAAAAAAAAAAAAA ------EE---AAAAAAAAAAAAAAAAAAA ------EE---AAAAAAAAAAAAAAAAAAA ------DD---AAAAAAAAAAAAAAAAAAA ------DD---AAAAAAAAAAAAAAAAAAA ------BB---AAAAAAAAAAAAAAAAAAA ------BB---AAAAAAAAAAAAAAAAAAA ------BB---AAAAAAAAAAAAAAAAAAA ------BB---AAAAAAAAAAAAAAAAAAA ------BB---AAAAAAAAAAAAAAAAAAA ------BB---AAAAAAAAAAAAAAAAAAA ------BB---AAAAAAAAAAAAAAAAAAA ------FF---AAAAAAAAAAAAAAAAAAA ------FF---AAAAAAAAAAAAAAAAAAA ------FF---AAAAAAAAAAAAAAAAAAA ------CC---AAAAAAAAAAAAAAAAAAA ------CC---AAAAAAAAAAAAAAAAAAA -----------AAAAAAAAAAAAAAAAAAA -----------AAAAAAAAAAAAAAAAAAA -----------AAAAAAAAAAAAAAAAAAA A----------AAAAAAAAAAAAAAAAAAA AAAAAAAAAAAAAAAAAAAAAAAAAAAAAA 
AAAAAAAAAAAAAAAAAAAAAAAAAAAAAA A----------AAAAAAAAAAAAAAAAAAA -----------AAAAAAAAAAAAAAAAAAA -----------AAAAAAAAAAAAAAAAAAA -----------AAAAAAAAAAAAAAAAAAA -----------AAAAAAAAAAAAAAAAAAA -----------AAAAAAAAAAAAAAAAAAA -----------AAAAAAAAAAAAAAAAAAA ------CC---AAAAAAAAAAAAAAAAAAA ------CC---AAAAAAAAAAAAAAAAAAA ------CC---AAAAAAAAAAAAAAAAAAA ------EE---AAAAAAAAAAAAAAAAAAA ------EE---AAAAAAAAAAAAAAAAAAA ------DD---AAAAAAAAAAAAAAAAAAA ------DD---AAAAAAAAAAAAAAAAAAA ------BB---AAAAAAAAAAAAAAAAAAA ------BB---AAAAAAAAAAAAAAAAAAA ------BB---AAAAAAAAAAAAAAAAAAA ------BB---AAAAAAAAAAAAAAAAAAA ------BB---AAAAAAAAAAAAAAAAAAA ------BB---AAAAAAAAAAAAAAAAAAA ------BB---AAAAAAAAAAAAAAAAAAA ------BB---AAAAAAAAAAAAAAAAAAA ------FF---AAAAAAAAAAAAAAAAAAA ------FF---AAAAAAAAAAAAAAAAAAA ------CC---AAAAAAAAAAAAAAAAAAA ------CC---AAAAAAAAAAAAAAAAAAA -----------AAAAAAAAAAAAAAAAAAA A----------AAAAAAAAAAAAAAAAAAA AAAAAAAAAAAAAAAAAAAAAAAAAAAAAA 
AAAAAAAAAAAAAAAAAAAAAAAAAAAAAA A----------AAAAAAAAAAAAAAAAAAA -----------AAAAAAAAAAAAAAAAAAA -----------AAAAAAAAAAAAAAAAAAA -----------AAAAAAAAAAAAAAAAAAA -----------AAAAAAAAAAAAAAAAAAA -----------AAAAAAAAAAAAAAAAAAA -----------AAAAAAAAAAAAAAAAAAA ------CC---AAAAAAAAAAAAAAAAAAA ------CC---AAAAAAAAAAAAAAAAAAA ------CC---AAAAAAAAAAAAAAAAAAA ------EE---AAAAAAAAAAAAAAAAAAA ------EE---AAAAAAAAAAAAAAAAAAA ------DD---AAAAAAAAAAAAAAAAAAA ------DD---AAAAAAAAAAAAAAAAAAA ------BB---AAAAAAAAAAAAAAAAAAA ------BB---AAAAAAAAAAAAAAAAAAA ------BB---AAAAAAAAAAAAAAAAAAA ------BB---AAAAAAAAAAAAAAAAAAA ------BB---AAAAAAAAAAAAAAAAAAA ------BB---AAAAAAAAAAAAAAAAAAA ------BB---AAAAAAAAAAAAAAAAAAA ------BB---AAAAAAAAAAAAAAAAAAA ------FF---AAAAAAAAAAAAAAAAAAA ------FF---AAAAAAAAAAAAAAAAAAA ------CC---AAAAAAAAAAAAAAAAAAA ------CC---AAAAAAAAAAAAAAAAAAA -----------AAAAAAAAAAAAAAAAAAA A----------AAAAAAAAAAAAAAAAAAA AAAAAAAAAAAAAAAAAAAAAAAAAAAAAA 
AAAAAAAAAAAAAAAAAAAAAAAAAAAAAA A----------AAAAAAAAAAAAAAAAAAA -----------AAAAAAAAAAAAAAAAAAA -----------AAAAAAAAAAAAAAAAAAA -----------AAAAAAAAAAAAAAAAAAA -----------AAAAAAAAAAAAAAAAAAA -----------AAAAAAAAAAAAAAAAAAA -----------AAAAAAAAAAAAAAAAAAA ------CC---AAAAAAAAAAAAAAAAAAA ------CC---AAAAAAAAAAAAAAAAAAA ------CC---AAAAAAAAAAAAAAAAAAA ------EE---AAAAAAAAAAAAAAAAAAA ------EE---AAAAAAAAAAAAAAAAAAA ------DD---AAAAAAAAAAAAAAAAAAA ------DD---AAAAAAAAAAAAAAAAAAA ------BB---AAAAAAAAAAAAAAAAAAA ------BB---AAAAAAAAAAAAAAAAAAA ------BB---AAAAAAAAAAAAAAAAAAA ------BB---AAAAAAAAAAAAAAAAAAA ------BB---AAAAAAAAAAAAAAAAAAA ------BB---AAAAAAAAAAAAAAAAAAA ------BB---AAAAAAAAAAAAAAAAAAA ------BB---AAAAAAAAAAAAAAAAAAA ------FF---AAAAAAAAAAAAAAAAAAA ------FF---AAAAAAAAAAAAAAAAAAA ------CC---AAAAAAAAAAAAAAAAAAA ------CC---AAAAAAAAAAAAAAAAAAA -----------AAAAAAAAAAAAAAAAAAA A----------AAAAAAAAAAAAAAAAAAA AAAAAAAAAAAAAAAAAAAAAAAAAAAAAA 
AAAAAAAAAAAAAAAAAAAAAAAAAAAAAA A----------AAAAAAAAAAAAAAAAAAA A----------AAAAAAAAAAAAAAAAAAA A----------AAAAAAAAAAAAAAAAAAA A----------AAAAAAAAAAAAAAAAAAA A----------AAAAAAAAAAAAAAAAAAA A----------AAAAAAAAAAAAAAAAAAA A----------AAAAAAAAAAAAAAAAAAA A----------AAAAAAAAAAAAAAAAAAA A----------AAAAAAAAAAAAAAAAAAA A----------AAAAAAAAAAAAAAAAAAA A-----CC---AAAAAAAAAAAAAAAAAAA A-----CC---AAAAAAAAAAAAAAAAAAA A-----EE---AAAAAAAAAAAAAAAAAAA A-----EE---AAAAAAAAAAAAAAAAAAA A-----DD---AAAAAAAAAAAAAAAAAAA A-----DD---AAAAAAAAAAAAAAAAAAA A-----DD---AAAAAAAAAAAAAAAAAAA A-----DD---AAAAAAAAAAAAAAAAAAA A-----DD---AAAAAAAAAAAAAAAAAAA A-----DD---AAAAAAAAAAAAAAAAAAA A-----DD---AAAAAAAAAAAAAAAAAAA A-----DD---AAAAAAAAAAAAAAAAAAA A-----BB---AAAAAAAAAAAAAAAAAAA A-----BB---AAAAAAAAAAAAAAAAAAA A-----CC---AAAAAAAAAAAAAAAAAAA A-----CC---AAAAAAAAAAAAAAAAAAA A----------AAAAAAAAAAAAAAAAAAA A----------AAAAAAAAAAAAAAAAAAA AAAAAAAAAAAAAAAAAAAAAAAAAAAAAA 
AAAAAAAAAAAAAAAAAAAAAAAAAAAAAA A----------AAAAAAAAAAAAAAAAAAA A----------AAAAAAAAAAAAAAAAAAA A----------AAAAAAAAAAAAAAAAAAA A----------AAAAAAAAAAAAAAAAAAA A----------AAAAAAAAAAAAAAAAAAA A----------AAAAAAAAAAAAAAAAAAA A----------AAAAAAAAAAAAAAAAAAA A----------AAAAAAAAAAAAAAAAAAA A----------AAAAAAAAAAAAAAAAAAA A----------AAAAAAAAAAAAAAAAAAA A-----CC---AAAAAAAAAAAAAAAAAAA A-----CC---AAAAAAAAAAAAAAAAAAA A-----EE---AAAAAAAAAAAAAAAAAAA A-----EE---AAAAAAAAAAAAAAAAAAA A-----DD---AAAAAAAAAAAAAAAAAAA A-----DD---AAAAAAAAAAAAAAAAAAA A-----DD---AAAAAAAAAAAAAAAAAAA A-----DD---AAAAAAAAAAAAAAAAAAA A-----DD---AAAAAAAAAAAAAAAAAAA A-----DD---AAAAAAAAAAAAAAAAAAA A-----DD---AAAAAAAAAAAAAAAAAAA A-----DD---AAAAAAAAAAAAAAAAAAA A-----BB---AAAAAAAAAAAAAAAAAAA A-----BB---AAAAAAAAAAAAAAAAAAA A-----CC---AAAAAAAAAAAAAAAAAAA A-----CC---AAAAAAAAAAAAAAAAAAA A----------AAAAAAAAAAAAAAAAAAA A----------AAAAAAAAAAAAAAAAAAA AAAAAAAAAAAAAAAAAAAAAAAAAAAAAA 
AAAAAAAAAAAAAAAAAAAAAAAAAAAAAA A----------AAAAAAAAAAAAAAAAAAA -----------AAAAAAAAAAAAAAAAAAA -----------AAAAAAAAAAAAAAAAAAA -----------AAAAAAAAAAAAAAAAAAA -----------AAAAAAAAAAAAAAAAAAA -----------AAAAAAAAAAAAAAAAAAA -----------AAAAAAAAAAAAAAAAAAA -----------AAAAAAAAAAAAAAAAAAA -----------AAAAAAAAAAAAAAAAAAA -----------AAAAAAAAAAAAAAAAAAA -----------AAAAAAAAAAAAAAAAAAA -----------AAAAAAAAAAAAAAAAAAA ------CC---AAAAAAAAAAAAAAAAAAA ------CC---AAAAAAAAAAAAAAAAAAA ------EE---AAAAAAAAAAAAAAAAAAA ------EE---AAAAAAAAAAAAAAAAAAA ------EE---AAAAAAAAAAAAAAAAAAA ------EE---AAAAAAAAAAAAAAAAAAA ------EE---AAAAAAAAAAAAAAAAAAA ------EE---AAAAAAAAAAAAAAAAAAA ------EE---AAAAAAAAAAAAAAAAAAA ------EE---AAAAAAAAAAAAAAAAAAA ------DD---AAAAAAAAAAAAAAAAAAA ------DD---AAAAAAAAAAAAAAAAAAA ------CC---AAAAAAAAAAAAAAAAAAA ------CC---AAAAAAAAAAAAAAAAAAA -----------AAAAAAAAAAAAAAAAAAA A----------AAAAAAAAAAAAAAAAAAA AAAAAAAAAAAAAAAAAAAAAAAAAAAAAA 
AAAAAAAAAAAAAAAAAAAAAAAAAAAAAA A----------AAAAAAAAAAAAAAAAAAA -----------AAAAAAAAAAAAAAAAAAA -----------AAAAAAAAAAAAAAAAAAA -----------AAAAAAAAAAAAAAAAAAA -----------AAAAAAAAAAAAAAAAAAA -----------AAAAAAAAAAAAAAAAAAA -----------AAAAAAAAAAAAAAAAAAA -----------AAAAAAAAAAAAAAAAAAA -----------AAAAAAAAAAAAAAAAAAA -----------AAAAAAAAAAAAAAAAAAA -----------AAAAAAAAAAAAAAAAAAA -----------AAAAAAAAAAAAAAAAAAA ------CC---AAAAAAAAAAAAAAAAAAA ------CC---AAAAAAAAAAAAAAAAAAA ------EE---AAAAAAAAAAAAAAAAAAA ------EE---AAAAAAAAAAAAAAAAAAA ------EE---AAAAAAAAAAAAAAAAAAA ------EE---AAAAAAAAAAAAAAAAAAA ------EE---AAAAAAAAAAAAAAAAAAA ------EE---AAAAAAAAAAAAAAAAAAA ------EE---AAAAAAAAAAAAAAAAAAA ------EE---AAAAAAAAAAAAAAAAAAA ------DD---AAAAAAAAAAAAAAAAAAA ------DD---AAAAAAAAAAAAAAAAAAA ------CC---AAAAAAAAAAAAAAAAAAA ------CC---AAAAAAAAAAAAAAAAAAA -----------AAAAAAAAAAAAAAAAAAA A----------AAAAAAAAAAAAAAAAAAA AAAAAAAAAAAAAAAAAAAAAAAAAAAAAA 
AAAAAAAAAAAAAAAAAAAAAAAAAAAAAA A----------AAAAAAAAAAAAAAAAAAA -----------AAAAAAAAAAAAAAAAAAA -----------AAAAAAAAAAAAAAAAAAA -----------AAAAAAAAAAAAAAAAAAA -----------AAAAAAAAAAAAAAAAAAA -----------AAAAAAAAAAAAAAAAAAA -----------AAAAAAAAAAAAAAAAAAA -----------AAAAAAAAAAAAAAAAAAA -----------AAAAAAAAAAAAAAAAAAA -----------AAAAAAAAAAAAAAAAAAA -----------AAAAAAAAAAAAAAAAAAA -----------AAAAAAAAAAAAAAAAAAA -----------AAAAAAAAAAAAAAAAAAA -----------AAAAAAAAAAAAAAAAAAA ------CC---AAAAAAAAAAAAAAAAAAA ------CC---AAAAAAAAAAAAAAAAAAA ------CC---AAAAAAAAAAAAAAAAAAA ------CC---AAAAAAAAAAAAAAAAAAA ------CC---AAAAAAAAAAAAAAAAAAA ------CC---AAAAAAAAAAAAAAAAAAA ------CC---AAAAAAAAAAAAAAAAAAA ------CC---AAAAAAAAAAAAAAAAAAA ------CC---AAAAAAAAAAAAAAAAAAA ------CC---AAAAAAAAAAAAAAAAAAA -----------AAAAAAAAAAAAAAAAAAA -----------AAAAAAAAAAAAAAAAAAA -----------AAAAAAAAAAAAAAAAAAA A----------AAAAAAAAAAAAAAAAAAA AAAAAAAAAAAAAAAAAAAAAAAAAAAAAA 
AAAAAAAAAAAAAAAAAAAAAAAAAAAAAA A----------AAAAAAAAAAAAAAAAAAA -----------AAAAAAAAAAAAAAAAAAA -----------AAAAAAAAAAAAAAAAAAA -----------AAAAAAAAAAAAAAAAAAA -----------AAAAAAAAAAAAAAAAAAA -----------AAAAAAAAAAAAAAAAAAA -----------AAAAAAAAAAAAAAAAAAA -----------AAAAAAAAAAAAAAAAAAA -----------AAAAAAAAAAAAAAAAAAA -----------AAAAAAAAAAAAAAAAAAA -----------AAAAAAAAAAAAAAAAAAA -----------AAAAAAAAAAAAAAAAAAA -----------AAAAAAAAAAAAAAAAAAA -----------AAAAAAAAAAAAAAAAAAA ------CC---AAAAAAAAAAAAAAAAAAA ------CC---AAAAAAAAAAAAAAAAAAA ------CC---AAAAAAAAAAAAAAAAAAA ------CC---AAAAAAAAAAAAAAAAAAA ------CC---AAAAAAAAAAAAAAAAAAA ------CC---AAAAAAAAAAAAAAAAAAA ------CC---AAAAAAAAAAAAAAAAAAA ------CC---AAAAAAAAAAAAAAAAAAA ------CC---AAAAAAAAAAAAAAAAAAA ------CC---AAAAAAAAAAAAAAAAAAA -----------AAAAAAAAAAAAAAAAAAA -----------AAAAAAAAAAAAAAAAAAA -----------AAAAAAAAAAAAAAAAAAA A----------AAAAAAAAAAAAAAAAAAA AAAAAAAAAAAAAAAAAAAAAAAAAAAAAA 
AAAAAAAAAAAAAAAAAAAAAAAAAAAAAA A----------AAAAAAAAAAAAAAAAAAA -----------AAAAAAAAAAAAAAAAAAA -----------AAAAAAAAAAAAAAAAAAA -----------AAAAAAAAAAAAAAAAAAA -----------AAAAAAAAAAAAAAAAAAA -----------AAAAAAAAAAAAAAAAAAA -----------AAAAAAAAAAAAAAAAAAA -----------AAAAAAAAAAAAAAAAAAA -----------AAAAAAAAAAAAAAAAAAA -----------AAAAAAAAAAAAAAAAAAA -----------AAAAAAAAAAAAAAAAAAA -----------AAAAAAAAAAAAAAAAAAA -----------AAAAAAAAAAAAAAAAAAA -----------AAAAAAAAAAAAAAAAAAA -----------AAAAAAAAAAAAAAAAAAA -----------AAAAAAAAAAAAAAAAAAA -----------AAAAAAAAAAAAAAAAAAA -----------AAAAAAAAAAAAAAAAAAA -----------AAAAAAAAAAAAAAAAAAA -----------AAAAAAAAAAAAAAAAAAA -----------AAAAAAAAAAAAAAAAAAA -----------AAAAAAAAAAAAAAAAAAA -----------AAAAAAAAAAAAAAAAAAA -----------AAAAAAAAAAAAAAAAAAA -----------AAAAAAAAAAAAAAAAAAA -----------AAAAAAAAAAAAAAAAAAA -----------AAAAAAAAAAAAAAAAAAA A----------AAAAAAAAAAAAAAAAAAA AAAAAAAAAAAAAAAAAAAAAAAAAAAAAA 
AAAAAAAAAAAAAAAAAAAAAAAAAAAAAA A----------AAAAAAAAAAAAAAAAAAA A----------AAAAAAAAAAAAAAAAAAA A----------AAAAAAAAAAAAAAAAAAA A----------AAAAAAAAAAAAAAAAAAA A----------AAAAAAAAAAAAAAAAAAA A----------AAAAAAAAAAAAAAAAAAA A----------AAAAAAAAAAAAAAAAAAA A----------AAAAAAAAAAAAAAAAAAA A----------AAAAAAAAAAAAAAAAAAA A----------AAAAAAAAAAAAAAAAAAA A----------AAAAAAAAAAAAAAAAAAA A----------AAAAAAAAAAAAAAAAAAA A----------AAAAAAAAAAAAAAAAAAA A----------AAAAAAAAAAAAAAAAAAA A----------AAAAAAAAAAAAAAAAAAA A----------AAAAAAAAAAAAAAAAAAA A----------AAAAAAAAAAAAAAAAAAA A----------AAAAAAAAAAAAAAAAAAA A----------AAAAAAAAAAAAAAAAAAA A----------AAAAAAAAAAAAAAAAAAA A----------AAAAAAAAAAAAAAAAAAA A----------AAAAAAAAAAAAAAAAAAA A----------AAAAAAAAAAAAAAAAAAA A----------AAAAAAAAAAAAAAAAAAA A----------AAAAAAAAAAAAAAAAAAA A----------AAAAAAAAAAAAAAAAAAA A----------AAAAAAAAAAAAAAAAAAA A----------AAAAAAAAAAAAAAAAAAA AAAAAAAAAAAAAAAAAAAAAAAAAAAAAA 
AAAAAAAAAAAAAAAAAAAAAAAAAAAAAA AAAAAAAAAAAAAAAAAAAAAAAAAAAAAA AAAAAAAAAAAAAAAAAAAAAAAAAAAAAA AAAAAAAAAAAAAAAAAAAAAAAAAAAAAA AAAAAAAAAAAAAAAAAAAAAAAAAAAAAA AAAAAAAAAAAAAAAAAAAAAAAAAAAAAA AAAAAAAAAAAAAAAAAAAAAAAAAAAAAA AAAAAAAAAAAAAAAAAAAAAAAAAAAAAA AAAAAAAAAAAAAAAAAAAAAAAAAAAAAA AAAAAAAAAAAAAAAAAAAAAAAAAAAAAA AAAAAAAAAAAAAAAAAAAAAAAAAAAAAA AAAAAAAAAAAAAAAAAAAAAAAAAAAAAA AAAAAAAAAAAAAAAAAAAAAAAAAAAAAA AAAAAAAAAAAAAAAAAAAAAAAAAAAAAA AAAAAAAAAAAAAAAAAAAAAAAAAAAAAA AAAAAAAAAAAAAAAAAAAAAAAAAAAAAA AAAAAAAAAAAAAAAAAAAAAAAAAAAAAA AAAAAAAAAAAAAAAAAAAAAAAAAAAAAA AAAAAAAAAAAAAAAAAAAAAAAAAAAAAA AAAAAAAAAAAAAAAAAAAAAAAAAAAAAA AAAAAAAAAAAAAAAAAAAAAAAAAAAAAA AAAAAAAAAAAAAAAAAAAAAAAAAAAAAA AAAAAAAAAAAAAAAAAAAAAAAAAAAAAA AAAAAAAAAAAAAAAAAAAAAAAAAAAAAA AAAAAAAAAAAAAAAAAAAAAAAAAAAAAA AAAAAAAAAAAAAAAAAAAAAAAAAAAAAA AAAAAAAAAAAAAAAAAAAAAAAAAAAAAA AAAAAAAAAAAAAAAAAAAAAAAAAAAAAA AAAAAAAAAAAAAAAAAAAAAAAAAAAAAA AAAAAAAAAAAAAAAAAAAAAAAAAAAAAA 
