model
size = 30 32 14, scale = 0.05, origin = -y
material 
  colors = A:#A0A0A0 B:#FFF C:#EEE D:#24AFEB E:#7DB9DE F:#B4DBF4 G:#AAA H:#656765 I:#DCDCDC J:#FFFFFB K:#9B9B9B L:#BDC0BA M:#51A8DD
voxels
124-6E10-6E936-3E4-3E6-3E4-3E66-6F10-6F218-HC4DC5(AH)C2DCAH7-A2C2D2C11A2C3A7-2A4C2A9-4A10-6A11-2A12-4A27-2A180-D2(29-J)231-2E8-2E4-2E8-2E64-2F4-2F8-2F4-2F67-6E10-6E127-AI6C10I4C2IA5-10A12B3A6-8C5G10C7-G6C2H2(GK)G2H6CH7-2H4C4H2(GK)G2H4C9-A2H2C2HA3H2(GK)G4H10-2A4H3AH-2GK2G15-6ADA3-2GK2G15-4ADA5-3G17-5A5-G21-2A88-J29-J201-E10-E4-E10-E63-3(2F6-)2F65-2E4-2E8-2E4-2E124-AH9BG6BG8BH2-4A22B2A3-2CA22DC4-2GA22-H4-2HA20-H2A4-ACA19-H2A5-ACA9-H5-6G6-A2C5A-5A3-2AL10-A3C12ALA12-ACK2C8ALGA14-2ACK3C5AG17-2A6C2AGL18-3A4C2AG20-3A2C4AG21-4A-GAGL22-2A2-AGA169-2E10-2E2-2E10-2E61-2F8-2F4-2F6-D-2F26-F29-M4(6-2E)67-4F12-4F35-H3BG4IGI2B6GB2I2G2IG2B2A-A25B2A-CA25DC2-GA25-H2-HA25-A2-2A24-2A2-2A18-3C4G3-2A16-2C3J7-2A14-2C2J10-2A12-2C2J12-2A11-C2J14-2A9-2CJ16-A9-C2J26-2(CAJ27-)2C158-D9-E12-E2-E3-F8-E20-M14-F25-F3-D6-F4-F10-F6-F4-F24-M4-D21-E2-D4-FE6-E8-E12-M29-D23-2F2-2F10-2F2-2F34-ABCG2I2B2IG4(IB)2(2IB)2ICBHA28BAK5DC2D2(CD)2(3CD)2C2(DC)2DCK28-2HA27-AHA26-4A23-4G-2A20-2AJ5-DA18-AJ8-2A16-AJ11-A14-AJ13-A11-2AJ15-A9-CAJ17-A9-CA18-L8-CAJ27-2C28-2C41-D13-F15-F13-M14-2D13-D14-DF6-E5-2D5-E2-E5-F6-E6-FD14-DF12-DF14-2D7-F5-D2(4-F)4-2D4-F7-DF15-F12-DM14-DM8-E3-2D3-E6-E3-2D3-E8-F15-DF12-2D14-D11-2(F-2D-F10-)MF14-DM6-HBC2IB2CB2I3(BC)B2IBC2BCBICB2A28B2A2D2CDCD2CD2(C3D)CDC2D3C2DCK28-HK28-AH28-2A24-4G-A21-2AJ5-D19-AJ8-A17-AJ10-L15-AJ12-C12-2AD15-A9-CAJ17-A9-CA18-L8-DAJ18-L8-DC28-2C25-D29-M29-F28-2D15-M6-E5-2D5-E2-E5-DF5-E6-FD15-D12-MD14-2D7-F4-D5-2(F4-)DM4-F7-2D14-D13-2F14-MD8-E3-2D3-E6-E3-2D3-E8-DF15-D13-M14-D2(F10-F-2D-)F10-2D14-2D6-ABC2IB2CB2I3(BC)B2IBC2BCBICBHA28B2A2D2(2CD)C3D2(2C2D)C2DCDC2DCK28-HK28-AH28-2A24-4G-A21-2AJ5-D19-AJ8-A17-AJ10-L15-AJ12-C12-2AD15-A9-CAJ17-A9-CA18-L8-DAJ18-L8-DC28-2C138-E12-E2-E12-E61-F10-F4-F10-F63-E8-E6-E8-E66-2F2-2F10-2F2-2F34-HBCG2I2B2IG4(IB)2(2IB)2ICB2A28BAK5DC2D2(CD)2(3CD)C2D3C2DCK28-2HA27-AHA26-4A23-4G-2A20-2AJ5-DA18-AJ8-2A16-AJ11-A14-AJ13-A11-2AJ15-A9-CAJ17-A9-CA18-L8-CAJ27-2C28-2C84-F29-D23-2E4-F5-2E2-2E10-2E6-M29-D24-2F8-2F4-2F8-2F63-2(2E6-)2E3-D2-2E25-D29-D11-4F12-4F35-A3BG4IGI2B6GB2I2G2IG2BHA-A25B2A-CA25DC2-GA25-H2-HA25-A2-2A24-2A2-2A18-3C4G3-2A16-2C3J7-2A14-2C2J10-2A12-2C2J12-2A11-C2J14-2A9-2CJ16-A9-C2J26-2(CAJ27-)2C169-E10-E4-E10-E63-3(2F6-)2F65-2E4-2E8-2E4-2E124-HAI8BG6BG8BA2-4A22B2A3-2CA22DC4-2GA22-H4-2HA20-H2A4-ACA19-H2A5-ACA9-H5-6G6-A2C5A-5A3-2AL10-A3C12ALA12-ACK2C8ALGA14-2ACK3C5AG17-2A6C2AGL18-3A4C3A20-3A2C5A21-4A-3AL22-2A2-3A170-2E8-2E4-2E8-2E64-2F4-2F8-2F4-2F67-6E10-6E127-HI6C10I4C2IH5-10A12B3A6-8C5G10C7-G6C2H2(GK)G2H6CH7-2H4C4H2(GK)G2H4C9-A2H2C2HA3H2(GK)G4H10-2A4H3AH-2GK2G15-6ADA3-2GK2G15-4ADA5-3G17-5A5-G21-2A88-J29-J202-3E4-3E6-3E4-3E66-6F10-6F218-AC4DC5(HA)C2DCHA7-A2C2D2C11A2C3A7-2A4C2A9-4A10-6A11-2A12-4A27-2A180-D2(29-J)234-6E10-6E814-
