model
size = 32 29 11, scale = 0.05, origin = -y
material 
  colors = A:#EEE B:#F03 C:#FC9 D:#111 E:#FFF
voxels
367-2C30-2C892-6C26-6C28-2C862-2C27-8C27-2C30-2C830-2C30-2C27-8C26-4C29-2C795-8C24-8C26-2(4C28-)4C29-2C410-10B20-14B17-3B10-3B15-3B12-3B16-3B8-3B19-12B23-2B2-2B156-3(2C30-)2C29-4C28-4C29-2C377-12B19-14B16-18B14-3B12E3B15-4B8E4B17-14B20-10B154-7(2C30-)2C53-A3DA10-A3DA11-3(A5DA8-A5DA10-)2A3D2A8-2A3D2A10-7A8-7A11-5A10-5A80-12B19-14B16-18B14-18B15-16B17-14B19-12B20-5D2-5D18-2D3-6D3-2D14-2(2D7-)2D10-2D20-2D7-D11-2C11-D5-D12-2C12-D3-D13-2C13-D-D14-2C14-D15-3(2C30-)2C21-5A4-2C4-5A11-2A3D2A8-2A3D2A9-3(2A5D2A6-2A5D2A8-)3A3D3A6-3A3D3A8-9A6-9A9-7A8-7A11-5A10-5A272-5D2-5D23-6D28-2D62-6(2C30-)2C22-3A5-2C5-3A12-7A3-2C3-7A9-9A6-9A8-3A3D3A6-3A3D3A7-2(4A3D4A4-4A3D4A6-)11A4-11A7-9A6-9A8-9A6-9A9-7A8-7A2(12-3A)374-6(2C30-)2C21-5A4-2C4-5A11-7A3-2C3-7A9-9A6-9A7-4(11A4-11A6-)11A4-11A7-9A6-9A9-7A8-7A11-5A10-5A373-6(2C30-)2C21-5A4-2C4-5A11-7A3-2C3-7A9-9A6-9A7-4(11A4-11A6-)11A4-11A7-9A6-9A9-7A8-7A11-5A10-5A6-
