model
size = 30 21 21, scale = 0.05, origin = -y
material 
  colors = A:#343434 B:#393939 C:#CBC8BC D:#777 E:#111 F:#E83015 G:#2EA9DF H:#7DB9DE I:#FBE251 J:#EEE K:#444 L:#D52E19
voxels
------------------------------ AAAAAAAAAAAAAAAAAAAAAAAAAAAAA- AAAAAAAAAAAAAAAAAAAAAAAAAAAAA- AAAAAAAAAAAAAAAAAAAAAAAAAAAAA- AAAAAAAAAAAAAAAAAAAAAAAAAAAAA- -AAAAAAAAAAAAAAAAAAAAAAAAAAAA- --------AAAAAAABBBBBBBBBBBB--- ---------AAAAABBBBBBBBBBBB---- ---------AAAAABBBBBBBBBBB----- ---------AAAAABBBBBBBBBB------ ---------AAAAABBBBBBBBB------- ---------AAAAABBBBBBBB-------- ---------AAAAABBBBBBB--------- ---------AAAAABBBBBB---------- ---------AAAAABBBBB----------- ---------AAAAABBBB------------ ---------AAAAABBB------------- ---------AAAAABB-------------- ----------AAAAB--------------- -----------AA----------------- ------------------------------ 
AAAAAAAAAAAAAAAAAAAAAAAAAAAAA- AA---------------------------A A----------------------------A A----------------------------A A----------------------------A A---------------------------AA -CCCCCCC------------------BB-- --CCCCCCC----------------BB--- -----CCCC---------------BB---- -------CC--------------BB----- --------C-------------BB------ --------C------------BB------- --------C-----------BB-------- --------C----------BB--------- --------C---------A---------AA --------C---------AAAAAAAAAAAA --------C--------AAAAAAAAAAAAA --------C-------AAAAAAAAAAAAAA ---------A-----AAAA---------AA ----------AAAAAAAA------------ ------------------------------ 
AAAAAAAAAAAAAAAAAAAAAAAAAAAAA- -E---------------------------A D----------------------------A A----------------------------A A----------------------------A A----------------------------A CC------------------------BBB- -CCCC--------------------BB--- ----CCCC----------------BB---- -------CC--------------BB----- --------C-------------BB------ --------C------------BB------- --------C-----------BB-------- --------C-----------B--------A --------C----------AAAAAAAAAAA -------HC--------------------- -------HC--------------------- -------HC--------------------- --------C---------AAAAAAAAAAAA ---------AAAAAAAAAA----------A ------------------------------ 
AAAAAAAAAAAAAAAAAAAAAAAAAAAAA- -E---------------------------A D----------------------------A A----------------------------A A----------------------------A A---------------------------AA CC------------------------BBB- -CCCC--------------------BB--- ----CCCC----------------BB---- -------CC--------------BB----- --------C-------------BB------ ------KJC------------BB------- ------KJC-----------BB-------- --------C-----------B--------A --------C-----------AAAAAAAAAA -------HC--------------------- -------GC--------------------- -------GC--------------------- --------C---------AAAAAAAAAAAA ---------AAAAAAAAAA----------A ------------------------------ 
AAAAAAAAAAAAAAAAAAAAAAAAAAAAA- -E---------------------------A D----------------------------A A----------------------------A A----------------------------A A---------------------------AA CC------------------------BBB- -CCCC--------------------BB--- ----CCCC----------------BB---- -------CC--------------BB----- --------C-------------BB------ ------KJC------------BB------- ------AJC-----------BB-------- --------C-----------B--------A --------C-----------AAAAAAAAAA -------HC--------------------- -------GC--------------------- -------GC--------------------- --------C---------AAAAAAAAAAAA ---------AAAAAAAAAA----------A ------------------------------ 
AAAAAAAAAAAAAAAAAAAAAAAAAAAAA- -E---------------------------A D----------------------------A A----------------------------A A----------------------------A A---------------------------AA CC------------------------BBB- -CCCC--------------------BB--- ----CCCC----------------BB---- -------CC--------------BB----- --------C-------------BB------ --------C------------BB------- --------C-----------BB-------- --------C-----------B--------A --------C-----------AAAAAAAAAA --------C--------------------- --------C--------------------- --------C--------------------- --------C---------AAAAAAAAAAAA ---------AAAAAAAAAA----------A ------------------------------ 
AAAAAAAAAAAAAAAAAAAAAAAAAAAAA- -E---------------------------A D----------------------------A A----------------------------A A----------------------------A A---------------------------AA CC------------------------BBB- -CCCC--------------------BB--- ----CCCC----------------BB---- -------CC--------------BB----- --------C-------------BB------ --------C------------BB------- --------C-----------BB-------- --------C-----------B--------- -----AAAA----------A--------AA -----AAAA----------AAAAAAAAAAA --------C---------AAAAAAAAAAAA --------C--------AAAAAAAAAAAAA --------C-------AAA---------AA ---------AAAAAAAAA------------ ------------------------------ 
AAAAAAAAAAAAAAAAAAAAAAAAAAAAA- -E---------------------------A D----------------------------A A----------------------------A A----------------------------A A---------------------------AA CC------------------------BBB- -CCCC--------------------BB--- ----CCCC----------------BB---- -------CC--------------BB----- --------C-------------BB------ --------C------------BB------- --------C-----------BB-------- -----AAAA-----------B--------- ------AAA----------B---------- ------AAA---------B----------- -----AAAA--------B------------ --------C-------B------------- --------C------B-------------- ---------AAAAAB--------------- ------------------------------ 
AAAAAAAAAAAAAAAAAAAAAAAAAAAAA- -E---------------------------A D----------------------------A A----------------------------A A----------------------------A A---------------------------AA CC------------------------BBB- -CCCC--------------------BB--- ----CCCC----------------BB---- -------CC--------------BB----- --------C-------------BB------ --------C------------BB------- -----AAAA-----------BB-------- ------AAA-----------B--------- --------H----------B---------- --------H---------B----------- ------AAA--------B------------ -----AAAA-------B------------- --------C------B-------------- ---------AAAAAB--------------- ----------AAA----------------- 
AAAAAAAAAAAAAAAAAAAAAAAAAAAAA- -E---------------------------A D----------------------------A A----------------------------A A----------------------------A A---------------------------AA FC------------------------BBB- -FFFC--------------------BB--- ----FFFC----------------BB---- -------FC--------------BB----- --------F-------------BB------ -----AAAA------------BB------- ------AAA-----------BB-------- --------H-----------B--------- --------H----------B---------- --------G---------B----------- --------G--------B------------ ------AAA-------B------------- -----AAAC------B-------------- ---------AAAAAB--------------- ----------A-A----------------- 
AAAAAAAAAAAAAAAAAAAAAAAAAAAAA- -E---------------------------A D----------------------------A A----------------------------A A----------------------------A A---------------------------AA IC------------------------BBB- -IIIC--------------------BB--- ----IIIC----------------BB---- -------IC--------------BB----- --------I-------------BB------ -----AAAA------------BB------- ------AAA-----------BB-------- --------H-----------B--------- --------G----------B---------- --------G---------B----------- --------G--------B------------ ------AAA-------B------------- -----AAAC------B-------------- ---------AAAAAB--------------- ----------A-A----------------- 
AAAAAAAAAAAAAAAAAAAAAAAAAAAAA- -E---------------------------A D----------------------------A A----------------------------A A----------------------------A A---------------------------AA CC------------------------BBB- -CCCC--------------------BB--- ----CCCC----------------BB---- -------CC--------------BB----- --------C-------------BB------ --------C------------BB------- -----AAAA-----------BB-------- ------AAA-----------B--------- --------G----------B---------- --------G---------B----------- ------AAA--------B------------ -----AAAA-------B------------- --------C------B-------------- ---------AAAAAB--------------- ----------A-A----------------- 
AAAAAAAAAAAAAAAAAAAAAAAAAAAAA- -E---------------------------A D----------------------------A C----------------------------A A----------------------------A A---------------------------AA CC------------------------BBB- -CCCC--------------------BB--- ----CCCC----------------BB---- -------CC--------------BB----- --------C-------------BB------ --------C------------BB------- --------C-----------BB-------- -----AAAA-----------B--------- ------AAA----------B---------- ------AAA---------B----------- -----AAAA--------B------------ --------C-------B------------- --------C------B-------------- ---------AAAAAB--------------- ----------A-A----------------- 
AAAAAAAAAAAAAAAAAAAAAAAAAAAAA- -E---------------------------A D----------------------------A C----------------------------A A----------------------------A A---------------------------AA CC------------------------BBB- -CCCC--------------------BB--- ----CCCC----------------BB---- -------CC--------------BB----- --------C-------------BB------ --------C------------BB------- --------C-----------BB-------- --------C-----------B--------- -----AAAA----------B---------- -----AAAA---------B----------- --------C--------B------------ --------C-------B------------- --------C------B-------------- ---------AAAAAB--------------- ----------AAA----------------- 
AAAAAAAAAAAAAAAAAAAAAAAAAAAAA- -E---------------------------A D----------------------------A C----------------------------A A----------------------------A A---------------------------AA CC------------------------BBB- -CCCC--------------------BB--- ----CCCC----------------BB---- -------CC--------------BB----- --------C-------------BB------ --------C------------BB------- --------C-----------BB-------- --------C-----------B--------- --------C----------B---------- --------C---------B----------- --------C--------B------------ --------C-------B------------- --------C------B-------------- ---------AAAAAB--------------- ------------------------------ 
AAAAAAAAAAAAAAAAAAAAAAAAAAAAA- -E---------------------------A D----------------------------A C----------------------------A A----------------------------A A---------------------------AA CC------------------------BBB- -CCCC--------------------BB--- ----CCCC----------------BB---- -------CC--------------BB----- --------C-------------BB------ --------C------------BB------- --------C-----------BB-------- --------C-----------B--------- --------C----------B---------- -------AC---------B----------- -------AC--------B------------ --------C-------B------------- --------C------B-------------- ---------AAAAAB--------------- ------------------------------ 
AAAAAAAAAAAAAAAAAAAAAAAAAAAAA- -E---------------------------A D----------------------------A C----------------------------A A----------------------------A A---------------------------AA CC------------------------BBB- -CCCC--------------------BB--- ----CCCC----------------BB---- -------CC--------------BB----- --------C-------------BB------ -------FC------------BB------- -------FC-----------BB-------- --------C-----------B--------- --------C----------B---------- -------AC---------B----------- -------AC--------B------------ --------C-------B------------- --------C------B-------------- ---------AAAAAB--------------- ------------------------------ 
AAAAAAAAAAAAAAAAAAAAAAAAAAAAA- -E---------------------------A D----------------------------A C----------------------------A A----------------------------A A---------------------------AA CC------------------------BBB- -CCCC--------------------BB--- ----CCCC----------------BB---- -------CC--------------BB----- --------C-------------BB------ -------FC------------BB------- -------LC-----------BB-------- --------C-----------B--------- --------C----------B---------- -------AC---------B----------- -------AC--------B------------ --------C-------B------------- --------C------B-------------- ---------AAAAAB--------------- ------------------------------ 
AAAAAAAAAAAAAAAAAAAAAAAAAAAAA- -E---------------------------A D----------------------------A C----------------------------A A----------------------------A A---------------------------AA CC------------------------BBB- -CCCC--------------------BB--- ----CCCC----------------BB---- -------CC--------------BB----- --------C-------------BB------ --------C------------BB------- --------C-----------BB-------- --------C-----------B--------- --------C----------B---------- -------AC---------B----------- -------AC--------B------------ --------C-------B------------- --------C------B-------------- ---------AAAAAB--------------- ------------------------------ 
AAAAAAAAAAAAAAAAAAAAAAAAAAAAA- AA--------------------------AA A----------------------------A A----------------------------A A----------------------------A A---------------------------AA -CCCCCCC------------------BB-- --CCCCCCC----------------BB--- -----CCCC---------------BB---- -------CC--------------BB----- --------C-------------BB------ --------C------------BB------- --------C-----------BB-------- --------C-----------B--------- --------C----------B---------- --------C---------B----------- --------C--------B------------ --------C-------B------------- ---------A-----B-------------- ----------AAAAB--------------- ------------------------------ 
------------------------------ AAAAAAAAAAAAAAAAAAAAAAAAAAAAA- AAAAAAAAAAAAAAAAAAAAAAAAAAAAA- AAAAAAAAAAAAAAAAAAAAAAAAAAAAA- AAAAAAAAAAAAAAAAAAAAAAAAAAAAA- -AAAAAAAAAAAAAAAAAAAAAAAAAAAA- --------AAAAAAABBBBBBBBBBBB--- ---------AAAAABBBBBBBBBBBB---- ---------AAAAABBBBBBBBBBB----- ---------AAAAABBBBBBBBBB------ ---------AAAAABBBBBBBBB------- ---------AAAAABBBBBBBB-------- ---------AAAAABBBBBBB--------- ---------AAAAABBBBBB---------- ---------AAAAABBBBB----------- ---------AAAAABBBB------------ ---------AAAAABBB------------- ---------AAAAABB-------------- ----------AAAAB--------------- -----------AA----------------- ------------------------------ 
