model
size = 27 29 16, scale = 0.05, origin = -y
material 
  colors = A:#F9F9F9 B:#90C3E3 C:#C2EBFF D:#A1CDE8
voxels
--------------------------- --------------------------- --------------------------- --------------------------- --------------------------- --------------------------- --------------------------- --------------------------- --------------------------- ---------------------B----- --------------------------- --------------------------- --------------------------- --------------------------- --------------------------- --------------------------- --------------------------- --------------------------- --------------------------- --------------------------- --------------------------- --------------------------- --------------------------- --------------------------- --------------------------- --------------------------- --------------------------- --------------------------- --------------------------- 
--------------------------- --------------------------- --------------------------- --------------------------- --------------------------- --------------------------- --------------------------- --------------------------- ---------------------B----- --------------------BBB---- ---------------------B----- ---------------------B----- --------------------------- --------------------------- --------------------------- --------------------------- --------------------------- --------------------------- --------------------------- --------------------------- --------------------------- --------------------------- --------------------------- --------------------------- --------------------------- --------------------------- --------------------------- --------------------------- --------------------------- 
--------------------------- --------------------------- -----------B--------------- --------------------------- --------------------------- --------------------------- --------------------------- ---------------------B----- --------------------BBB---- -------------------BBBBB--- --------------------BBB---- --------------------BBB---- ---------------------B----- ---------------------B----- --------------------------- --------------------------- --------------------------- --------------------------- --------------------------- --------------------------- --------------------------- --------------------------- --------------------------- --------------------------- --------------------------- --------------------------- --------------------------- --------------------------- --------------------------- 
--------------------------- -----------B--------------- ----------BBB-------------- -----------B--------------- -----------B--------------- --------------------------- --------------------------- --------------------------- ---------------------B----- --------------------BBB---- ---------------------B----- ---------------------B----- --------------------------- --------------------------- --------------------------- --------------------------- --------------------------- --------------------------- --------------------------- --------------------------- --------------------------- --------------------------- --------------------------- --------------------------- --------------------------- --------------------------- --------------------------- --------------------------- --------------------------- 
-----------B--------------- ----------BBB-------------- ---------BBBBB------------- ----------BBB-------------- ----------BBB-------------- -----------B--------------- -----------B--------------- --------------------------- --------------------------- ---------------------B----- --------------------------- --------------------------- --------------------------- --------------------------- --------------------------- --------------------------- --------------------------- --------------------------- --------------------------- --------------------------- --------------------------- --------------------------- --------------------------- --------------------------- --------------------------- --------------------------- --------------------------- --------------------------- --------------------------- 
--------------------------- -----------B--------------- ----------BBB-------------- -----------B--------------- -----------B--------------- --------------------------- --------------------------- --------------------------- --------------------------- --------------------------- --------------------------- --------------------------- --------------------------- --------------------------- --------------------------- --------------------------- --------------------------- --------------------------- ----CCCCCCCCCCCCCCCCCCC---- ---AAAAAAAAAAAAAAAAAAAAA--- --CAAAAAAAAAAAAAAAAAACAAC-- --AAAAAAAAACAAAAAAAAC-AAA-- -CAAAAAAAAC-AAAAAAAA-AAAAA- --AAAAAAAA--AAAAAAAC--AAA-- ---AAAAAA--AAAAAAAA----C--- ----AAAA---AAAAAAA--------- -----AC-----AAAAA---------- -------------AAC----------- --------------------------- 
--------------------------- --------------------------- -----------B--------------- --------------------------- --------------------------- --------------------------- --------------------------- --------------------------- --------------------------- ------B-------------------- --------------------------- --------------------------- --------------------------- --------------------------- --------------------------- --------------------------- --------------------------- ----BBBBBBBBBBBBBBBBBBB---- ---CCCCCCCCCCCCCCCCCCCCC--- --CAAAAAAAAAAAAAAAAAAAAAC-- -BCAAAAAAAAAAAAAAAAAACAACB- -CAAAAAAAAACAAAAAAAACBAAAC- BCAAAAAAAACBAAAAAAAACAAAAAB -CAAAAAAAACBAAAAAAACBAAAAC- --DAAAAAACBAAAAAAAAC--DCC-- ---DAAAAC-DAAAAAAAC----B--- ----DACC---DAAAAAC--------- -----BB-----DAACC---------- -------------BBB----------- 
--------------------------- --------------------------- --------------------------- --------------------------- --------------------------- --------------------------- --------------------------- --------------------------- ------B-------------------- -----BBB------------------- ------B-------------------- ------B-------------------- --------------------------- --------------------------- --------------------------- --------------------------- --------------------------- ---BBBBBBBBBBBBBBBBBBBBB--- --BCCCCCCCCCCCCCCCCCCCCCB-- -BCAAAAAAAAAAAAAAAAAAAAACB- -BCAAAAAAAAAAAAAAAAAACAACB- BCAAAAAAAAACAAAAAAAACBAAACB BCAAAAAAAACBAAAAAAAACBAAAAB BCAAAAAAAACBAAAAAAACBAAAACB -BDAAAAAACBAAAAAAAACDBDCCB- --BDAAAACBDAAAAAAACB--DBB-- ---BDACCB-BDAAAAACB-------- ----DBBB---BDAACCB--------- ------------DBBBB---------- 
--------------------------- --------------------------- --------------------------- --------------------------- --------------------------- --------------------------- --------------------------- ------B-------------------- -----BBB------------------- ----BBBBB------------------ -----BBB------------------- -----BBB------------------- ------B-------------------- ------B-------------------- --------------------------- --------------------------- --------------------------- ----BBBBBBBBBBBBBBBBBBB---- ---CCCCCCCCCCCCCCCCCCCCC--- --CAAAAAAAAAAAAAAAAAAAAAC-- -BCAAAAAAAAAAAAAAAAAACAACB- -CAAAAAAAAACAAAAAAAACBAAAC- BCAAAAAAAACBAAAAAAAACBAAAAB -CAAAAAAAACBAAAAAAACBAAAAC- --DAAAAAACBAAAAAAAAC-BDCC-- ---DAAAAC-DAAAAAAAC----B--- ----DACC---DAAAAAC--------- -----BB-----DAACC---------- -------------BBB----------- 
--------------------------- --------------------------- --------------------------- --------------------------- --------------------------- --------------------------- --------------------------- --------------------------- ------B-------------------- -----BBB------------------- ------B-------------------- ------B-------------------- --------------------------- --------------------------- --------------------------- --------------------------- --------------------------- --------------------------- ----CCCCCCCCCCCCCCCCCCC---- ---AAAAAAAAAAAAAAAAAAAAA--- --CAAAAAAAAAAAAAAAAAACAAC-- --AAAAAAAAACAAAAAAAAC-AAA-- -CAAAAAAAAC-AAAAAAAA--AAAA- --AAAAAAAA--AAAAAAAC-AAAA-- ---AAAAAA--AAAAAAAA----C--- ----AAAA---AAAAAAA--------- -----AC-----AAAAA---------- -------------AAC----------- --------------------------- 
--------------------------- --------------------------- --------------------------- --------------------------- --------------------------- --------------------------- --------------------------- --------------------------- --------------------------- ------B-------------------- --------------------------- --------------------------- --------------------------- --------------------------- --------------------------- --------------------------- --------------------------- --------------------------- --------------------------- --------------------------- --------------------------- --------------------------- --------------------------- --------------------------- --------------------------- --------------------------- --------------------------- --------------------------- --------------------------- 
--------------------------- --------------------------- --------------------------- --------------------------- --------------------------- --------------------------- ---------------B----------- --------------------------- --------------------------- --------------------------- --------------------------- --------------------------- --------------------------- --------------------------- --------------------------- --------------------------- --------------------------- --------------------------- --------------------------- --------------------------- --------------------------- --------------------------- --------------------------- --------------------------- --------------------------- --------------------------- --------------------------- --------------------------- --------------------------- 
--------------------------- --------------------------- --------------------------- --------------------------- --------------------------- ---------------B----------- --------------BBB---------- ---------------B----------- ---------------B----------- --------------------------- --------------------------- --------------------------- --------------------------- --------------------------- --------------------------- --------------------------- --------------------------- --------------------------- --------------------------- --------------------------- --------------------------- --------------------------- --------------------------- --------------------------- --------------------------- --------------------------- --------------------------- --------------------------- --------------------------- 
--------------------------- --------------------------- --------------------------- --------------------------- ---------------B----------- --------------BBB---------- -------------BBBBB--------- --------------BBB---------- --------------BBB---------- ---------------B----------- ---------------B----------- --------------------------- --------------------------- --------------------------- --------------------------- --------------------------- --------------------------- --------------------------- --------------------------- --------------------------- --------------------------- --------------------------- --------------------------- --------------------------- --------------------------- --------------------------- --------------------------- --------------------------- --------------------------- 
--------------------------- --------------------------- --------------------------- --------------------------- --------------------------- ---------------B----------- --------------BBB---------- ---------------B----------- ---------------B----------- --------------------------- --------------------------- --------------------------- --------------------------- --------------------------- --------------------------- --------------------------- --------------------------- --------------------------- --------------------------- --------------------------- --------------------------- --------------------------- --------------------------- --------------------------- --------------------------- --------------------------- --------------------------- --------------------------- --------------------------- 
--------------------------- --------------------------- --------------------------- --------------------------- --------------------------- --------------------------- ---------------B----------- --------------------------- --------------------------- --------------------------- --------------------------- --------------------------- --------------------------- --------------------------- --------------------------- --------------------------- --------------------------- --------------------------- --------------------------- --------------------------- --------------------------- --------------------------- --------------------------- --------------------------- --------------------------- --------------------------- --------------------------- --------------------------- --------------------------- 
