model
size = 7 7 32, scale = 0.05, origin = -y
material 
  colors = A:#EEE B:#222 C:#A00 D:#BBB E:#777
voxels
9-B-B3-2(B-)2(B3-B-)B-B3-B-B17-4(5B2-)5B10-3(B-B3-2(5B-7B-)5B3-B-B4-)B-B3-5B-7B-13B-5B3-B-B2(4-3B3-5B-21B-5B3-3B)6(4-3A3-5A-21A-5A3-3A)4-3A3-5A-14AC5AC-5A3-3A4-3A3-5A-7AC5A2C5AC-5A3-3A4-3A3-5A-13A2C5AC-5A3-3A4-3A3-5A-E12A2(C6AC-5A3-3A4-3A3-5A-E5AEC5A)3(2C5AC-5A3-3A4-3A3-5A-E5AEC5A)2C6A-5A3-3A4-3A3-5A-6AE2(C6A)-5A3-3A4-3A3-5A-7AC6AC5AC-5A3-3A4-3A3-5A-7AC5A2C5AC-5A3-3A4-3A3-5A-14AC5AC4(-5A3-3A4-3A3-5A-21A)-5A3-3A11-3D3-2(5D2-)5D3-3D9-
