model
size = 11 28 11, scale = 0.05, origin = -y
material 
  colors = A:#EEE B:#CAAD5F C:#86C166 D:#AAA E:#555 F:#BBB G:#F05E1C
voxels
----------- ----------- ----CCC---- ---CCCCC--- ---CCCCC--- ---AAAAA--- ---AAAAA--- ---AAAAA--- ---AAAAA--- ---AAAAA--- ---AAAAA--- ---AAAAA--- ---AAAAA--- ---AAAAA--- ---AAAAA--- ---AAAAA--- ---AAAAA--- ---AAAAA--- ---AAAAA--- ---AAAAA--- ---AAAAA--- ---AAAAA--- ---AAAAA--- ---AAAAA--- ---CCCCC--- ---CCCCC--- ----DDD---- ----------- 
----------- ---DDDDD--- --CCCBBCC-- --CCCBBCC-- --CCCBBCC-- --AAAAAAA-- --AAAAAAA-- --AAAAAAA-- --AABBBAA-- --AABBBAA-- --AABBBAA-- --AABBBAA-- --AABBBAA-- --AABBBAA-- --AABBBAA-- --EABBBAE-- --EABBBAE-- --EABBBAE-- --EABBBAE-- --EABBBAE-- --AABBBAA-- --AAAAAAA-- --AAAAAAA-- --AAAAAAA-- --CCBBBCC-- --CC---CC-- ---DAAAD--- ----DDD---- 
----FFF---- --DDAAADD-- -CCCCBBCCC- -CCCCBBCCC- -CCCCBBCCC- -AAAAAAAAA- -AAAAAAAAA- -AAAAAAAAA- -AAABBBAAA- -AAABBBAAA- -AAABBBAAA- -AAABBBAAA- -AAABBBAAA- -AAABBBAAA- -EAABBBAAE- -EAABBBAAE- -AAABBBAAA- -AAABBBAAA- -AAABBBAAA- -EAABBBAAE- -EAABBBAAE- -AAAAAAAAA- -AAAAAAAAA- -AAAAAAAAA- -CCBBBBBCC- -CC-----CC- --DAFFFAD-- ---D---D--- 
---F---F--- -DDADDDADD- -CCCCBBCCC- CCCCCBBCCCC CCCCCBBCCCC AAACCBBCAAA AAACCBBCAAA AAACCBBCAAA EAAABBBAAAE EAAABBBAAAE AAAABBBAAAA AAAABBBAAAA AAAABBBAAAA EAAABBBAAAE EAAABBBAAAE AAAABBBAAAA AAAABBBAAAC CAAABBBAAAC CAAABBBAAAA AAAABBBAAAA EAAABBBAAAE EAAABBBAAAE AAAACCCAAAA AAAACCCAAAA CCBBBBBBBCC CC-------CC -DAFFFFFAD- --D-----D-- 
--F-----F-- -DADDDDDAD- CCCCCBBCCCC CCCCCBBCCCC CCCCCBBCCCC AAACCBBCAAA FAACCBBCAAF AAACCBBCAAA EAAABBBAAAE EAAABBBAAAE AAAABBBAAAA AAAABBBAAAA AAAABBBAAAA EAAABBBAAAE AAAABBBAAAA AAAABBBAAAC CAAABBBAAAC CAAABBBAAAA CAAABBBAAAC CAAABBBAAAA AAAABBBAAAA EAAABBBAAAE AAAABBBAAAA AAAABBBAAAA CCBBBBBBBCC CC-------CC DAF--FFFFAD -D---FFFFFF 
--F-----F-- -DADDDDDAD- CCCCCBBCCCC CCCCCBBCCCC CCCCCBBCCCC FAACCBBCAAF GAACCBBCAAG FAACCBBCAAF EAAABBBAAAE EAAABBBAAAE AAAABBBAAAA AAAABBBAAAA AAAABBBAAAA EAAABBBAAAE AAAABBBAAAA CAAABBBAAAC CAAABBBAAAC CAAABBBAAAC AAAABBBAAAA CAAABBBAAAC AAAABBBAAAA EAAABBBAAAE AAAABBBAAAA AAAABBBAAAA CCBBBBBBBCC CC-------CC DAF--FFFFFD -D---F-F--F 
--F-----F-- -DADDDDDAD- CCCCCBBCCCC CCCCCBBCCCC CCCCCBBCCCC AAACCBBCAAA FAACCBBCAAF AAACCBBCAAA EAAABBBAAAE EAAABBBAAAE AAAABBBAAAA AAAABBBAAAA AAAABBBAAAA EAAABBBAAAE AAAABBBAAAA CAAABBBAAAA CAAABBBAAAC AAAABBBAAAC CAAABBBAAAC AAAABBBAAAC AAAABBBAAAA EAAABBBAAAE AAAABBBAAAA AAAABBBAAAA CCBBBBBBBCC CC-------CC DAF--FFFFAD -D---FFFFFF 
---F---F--- -DDADDDADD- -CCCCCCCCC- CCCCCCCCCCC CCCCCCCCCCC AAACCCCCAAA AAACCCCCAAA AAACCCCCAAA EAAABBBAAAE EAAABBBAAAE AAAABBBAAAA AAAABBBAAAA AAAABBBAAAA EAAABBBAAAE EAAABBBAAAE AAAABBBAAAA CAAABBBAAAA CAAABBBAAAC AAAABBBAAAC AAAABBBAAAA EAAABBBAAAE EAAABBBAAAE AAAACCCAAAA AAAACCCAAAA CCBBBBBBBCC CC-------CC -DAFFFFFAD- --D-----D-- 
----FFF---- --DDAAADD-- -CCCCCCCCC- -CCCCCCCCC- -CCCCCCCCC- -AAAAAAAAA- -AAAAAAAAA- -AAAAAAAAA- -AAABBBAAA- -AAABBBAAA- -AAABBBAAA- -AAABBBAAA- -AAABBBAAA- -AAABBBAAA- -EAABBBAAE- -EAABBBAAE- -AAABBBAAA- -AAABBBAAA- -AAABBBAAA- -EAABBBAAE- -EAABBBAAE- -AAABBBAAA- -AAAAAAAAA- -AAAAAAAAA- -CCBBBBBCC- -CC-----CC- --DAFFFAD-- ---D---D--- 
----------- ---DDDDD--- --CCCCCCC-- --CCCCCCC-- --CCCCCCC-- --AAAAAAA-- --AAAAAAA-- --AAAAAAA-- --AABBBAA-- --AABBBAA-- --AABBBAA-- --AABBBAA-- --AABBBAA-- --AABBBAA-- --AABBBAA-- --EABBBAE-- --EABBBAE-- --EABBBAE-- --EABBBAE-- --EABBBAE-- --AABBBAA-- --AABBBAA-- --AAAAAAA-- --AAAAAAA-- --CCBBBCC-- --CC---CC-- ---DAAAD--- ----DDD---- 
----------- ----------- ----CCC---- ---CCCCC--- ---CCCCC--- ---AAAAA--- ---AAAAA--- ---AAAAA--- ---AAAAA--- ---AAAAA--- ---AAAAA--- ---AAAAA--- ---AAAAA--- ---AAAAA--- ---AAAAA--- ---AAAAA--- ---AAAAA--- ---AAAAA--- ---AAAAA--- ---AAAAA--- ---AAAAA--- ---AAAAA--- ---AAAAA--- ---AAAAA--- ---CCCCC--- ---CCCCC--- ----DDD---- ----------- 
