model
size = 32 32 8, scale = 0.05, origin = -y
material 
  colors = A:#EEE B:#111
voxels
386-28A3-30A-99A2(2B3A2(2B5A)6B7A)2(2B3A2B5A2B9A2B7A)2(7B5A2B7A4B7A)2(2B3A2B5A2B9A2B7A)2B3A2B2A8B2A6B7A2B3A2B2A8B2A6B100A-30A3-28A326-9A23-9A21-28A3-30A-512A-30A3-28A263-2(7A25-7A24-9A23-9A21-28A3-30A-512A-30A3-28A10-3(A31-)A30-3A29-3A28-5A27-5A26-)7A25-7A24-9A23-9A21-28A3-30A-512A-30A3-28A263-7A25-7A24-9A23-9A21-28A3-30A-512A-30A3-28A326-9A23-9A21-28A3-30A-512A-30A3-28A388-28A3-30A-100A2(2B4A2B2A2(2B9A))2B3A3B2A2(2B9A)2B2A4B2A2(2B9A)2BA5B2A4B7A2B9A5BA2B2A4B7A2B9A4B2(2A2B)9A2B9A3B3A2B2A2(2B9A)2B4A2B2A6B2A8B6A2B4A2B2A6B2A8B98A-30A3-28A2-
