model
size = 20 3 30, scale = 0.05, origin = -y
material 
  colors = A:#FF0
voxels
-------------------- ---AA--------------- -------------------- 
-------------------- ---AAA--------A----- -------------------- 
-------------------- ---AAA--------A----- ----A--------------- 
-------------------- ----AA-------AA----- ----AA-------------- 
------A------A------ ----AA------AAA----- ----AA--------A----- 
------A------AA----- ----AA------AAA----- ----A-------AA------ 
------------AA------ ----AAA-----AA------ -----------AAA------ 
------A-----A------- ------A-----A------- -----------A-------- 
------AA----A------- ------A-----A------- -----------A-------- 
------AA----A------- -------A----A------- --------A--A-------- 
------AAAAAAA------- ------AAAAAAA------- --------AAAA-------- 
-----AAAAAAAAAA----- -----AAAAAAAAAA----- -----AAAAAAAAAA----- 
----AAA------AAA---- ----AAA------AAA---- ----AAA------AAA---- 
---AA----------AA--- ---AA----------AA--- ---AA----------AA--- 
--AA------------AA-- --AA------------AA-- --AA------------AA-- 
-AA--------------AA- -AA--------------AA- -AA--------------AA- 
-AA--------------AA- -AA--------------AA- -AA--------------AA- 
AA----------------AA -A----------------AA -A----------------A- 
AA----------------AA AA----------------AA AA----------------AA 
AA----------------AA AA----------------AA AA----------------AA 
AA----------------AA AA----------------AA AA----------------AA 
AA----------------AA AA----------------AA AA----------------AA 
AA----------------AA AA----------------AA -A----------------A- 
-AA--------------AA- -AA--------------AA- -AA--------------AA- 
-AA--------------AA- -AA--------------AA- -AA--------------AA- 
--AA------------AA-- --AA------------AA-- --AA------------AA-- 
---AA----------AA--- ---AA----------AA--- ---AA----------AA--- 
----AAA------AAA---- ----AAA------AAA---- ----AAA------AAA---- 
-----AAAAAAAAAA----- -----AAAAAAAAAA----- -----AAAAAAAAAA----- 
-------AAAAAA------- -------AAAAAA------- --------AAAA-------- 
