model
size = 25 30 19, scale = 0.05, origin = -y
material 
  colors = A:#E00 B:#FF0 C:#EEE D:#CF3 E:#000 F:#00C G:#251505 H:#BBB I:#CF0 J:#CC6 K:#939 L:#960 M:#AAAAB9 N:#1C0900 O:#AAA P:#00F Q:#888 R:#FCF
voxels
------CCCCCCC------------ ------CAAAAAC------------ ------CAAAAAC------------ ------CAAAAAC------------ ------CAAAAAC------------ ------CAAAAAC------------ ------CAAAAAC------------ ------CAAAAAC------------ ------CAAAAAC------------ ------CAAAAAC------------ ------AAAAAAA------------ ------AAAAAAA------------ ------AAAAAAA------------ ------AAAAAAA------------ ------AAAAAAA------------ ------CAAAAAC------------ ------CAAAAAC------------ ------CAAAAAC------------ ------CAAAAAC------------ ------CAAAAAC------------ ------CAAAAAC------------ ------CAAAAAC------------ ------CAAAAAC------------ ------CAAAAAC------------ ------CCCCCCC------------ ------------------------- ------------------------- ------------------------- ------O------------------ ------------------------- 
----CCCCCCCCCCC---------- ----CCB---BBBCC---------- ----CCB---BBBCC---------- ----CCB---BBBCC---------- ----CCB---BBBCC---------- ----CCB---BBBCC---------- ----CCB---BBBCC---------- ----CCB--BBBBCC---------- ----CCA--AAAACC---------- ----CCA--AAAACC---------- ----AAA--AAAAAA---------- ----AAA-AAAAAAA---------- ----AAAAAAAAAAA---------- ----AAAAAAAAAAA---------- ----AAAAAAAAAAA---------- ----CCAAAAAAACC---------- ----CCAAAAAAACC---------- ----CCEEEEEEECC---------- ----CCMDDDDDMCC---------- ----CCMDDDDDMCC---------- ----CCMDDDDDMCC---------- ----CCMDDDDDMCC---------- ----CCMDDDDDMCC---------- ----CCGGGGGGGCC---------- ----CC-------CC---------- ------------------------- ------------------------- ------------------------- ------H------------------ ------H------------------ 
---CCCCCCCCCCCCC--------- ---CBB--------CC--------- ---CBBBBBBBBBCCC--------- ---CBBBBBBBBBCCC--------- ---CBBBBBBBBBCCC--------- ---CBBBBBBBBBCCC--------- ---CBBBBBBBBBCCC--------- ---CBBBBBBBBBCCC--------- ---CAAAAAAAAACCC--------- ---CAAAAAAAAACCC--------- ---AAAABBBBBAAAA--------- ---AAAAAAAAAAAAA--------- ---AAAAAAAAAAAAA--------- ---AAAAAAAAAAAAA--------- ---AAAAAAAAAAAAA--------- ---CABBBBBBBAAAC--------- ---CADDDDDBBAAAC--------- ---CEEEEEEEEEEEC--------- ---CFDDDDDDDDAAC--------- ---CFDDDDDDDDAAC--------- ---CFDDDDDDDDAAC--------- ---CFDDDDDDDDAAC--------- ---CMDDDDDDDDDMC--------- ---CGGGGGGLNGGGC--------- ---C-----------C--------- ------------------------- ------------------------- ------------------------- ------------------------- ------HH----------------- 
--CCCCCCCCCCCCCCC-------- --CBBBBBBBBBBCCCC-------- --CBBBBBBBBBBCCCC-------- --CBBBBBBBBBBCCCC-------- --CBBBBBBBBBBCCCC-------- --CBBBBBBBBBBCCCC-------- --CBBBBBBBBBBCCCC-------- --CBBBBBBBBBBCCCC-------- --CABBBBBBBBBCCCC-------- --CABB--------CCC-------- --AAAAABBBBBAAAAA-------- --AAABAAAAAAAAAAA-------- --AAAAAAAAAAAAAAA-------- --AAAAAAAA-AAAAAA-------- --AAAAAAAA-AAAAAA-------- --CAABBBBB-BAAAAC-------- --CAADDDDD-BAAAAC-------- --CEEEEEEE-EEEEEC-------- --CFFDDDDD-DDDDMC-------- --CFFDDDDD-DDDDMC-------- --CFFDDDDD-DDDDMC-------- --CFFDDDDD-DDDDMC-------- --CMDDDDDD-DDDDCC-------- --CGGGGLGLGGNNGGC-------- --C------J------C-------- ------------------------- ------------------------- ------------------------- ---H--------------------- -------H----------------- 
-CCCCCCCCCCCCCCCCC------- -CBBBBBBBBBBBCC-CC------- -CBBBBBBBBBBBCC-CC------- -CBBBBBBBBBBBCC-CC------- -CBBBBBBBBBBBCC-CC------- -CBBBBBBBBBBBCC-CC------- -CBBBBBBBBBBBCC-CC------- -CBBBBBBBBBBBCC-CC------- -CAABBBBBBBBBCC-CC------- -CAABBBBBBBBBCC-CC------- -CA-AAAAAABBAAA-AC------- -CA-AAAAAAAAAAA-AC------- -CA-AAAAAAAAAAA-AC------- -CA-AAAAAAAAAAA-AC------- -CA-AAAAAAAAAAA-AC------- -CAAAADDDDBBAAA-AC------- -CA-ADDDDDBBAAA-AC------- -CE-EEEEEEEEEEE-EC------- -CC-FDDDDDDDDDD-MC------- -CC-FDDDDDDDDDD-MC------- -CC-FDDDDDDDDDD-MC------- -CCFFDDDDDDDDDD-MC------- -CMBDDDDDDDDDDD-CC------- -CGGLGLGLGGLNLGGGC------- -C------J-J------C------- ------------------------- ------------------------- ------------------------- ---H--------------------- ---O---H----------------- 
-CCCCCCCCCCCCCCCCC------- -CBBBBBBBBBBBBPPPC------- -CBBBBBBBBBBBBPCCC------- -CBBBBBBBBBBBBPPPC------- -CBBBBBBBBBBBBBBBC------- -CBBBBBBBBBBBBBBBC------- -CBBBBBBBBBBBBBBBC------- -CBBBBBBBBBBBBBCCC------- -CAABBBBBBBBBBCCCC------- -CAABBBBBBBBBBCCCC------- -CAAAAAAAABBAAAAAC------- -CAAAAAAAAAAAAAAAC------- -CAAAAAAAAAAAAAAAC------- -CAAAAAAAAAAAAAAAC------- -CAAAAAAAAAAAAAAAC------- -CAAAADDDDBBAAAAAC------- -CAAADDDDDBBAAAAAC------- -CEEEEEDDAAAAAAAAC------- -CCFFDDDDDDDDDDDDC------- -CCFFDDDDDDDDDDDDC------- -CCFFDDDDDDDDDDDDC------- -CCFFDDDDDDDDDDDDC------- -CDDDDDDDDDDDDDCCC------- -CLGLLGLGGGLGGLLGC------- -C-----J-J-J-----C------- ------------------------- ------------------------- ------------------------- ------------------------- ---Q--HO----------------- 
CCCCCCCCCCCCCCCCCCC------ CBBBBBBBBBBBBBBBBCC------ CBBBBBBBBBBBBBBBBCC------ CBBBBBBBBBBBBBBBBCC------ CBBBBBBBBBBBBBBBBCC------ CBBBBBBBBBBBBBBBBCC------ CBBBBBBBBBBBBBBBBCC------ CBBBBBBBBBBBBBBBBCC------ CAAABBBBBBBBBBAAAAC------ CAAABBBBBBBBBBAAAAC------ CAAAAAAAAABBAAAAAAC------ CAAAAAAAAAAAAAAAAAC------ CAAAAAAAAAAAAAAAAAC------ CAAAAAAAAAAAAAAAAAC------ CAAAAAAAAAAAAAAAAAC------ CAAAAADDDDBBBBBBBBC------ CAAAADDDDDBBBBBBBBC------ CEEEEEEDDAAAAAAAAEC------ CFFFFDDDDDDDDKKKDMC------ CFFFFDDDDDDDDKKKDMC------ CFFFFDDDDDDDDKKKDMC------ CFFFFDDDDDDDDKKKDMC------ CMDDDDDDDDDDDKKCCCC------ CGGGGGLLGGGGGLNGGNC------ C-----J-J-J-J-----C------ ------------------------- ---------HHH------------- --------OH-HH------------ ----OOOOO---HH----------- ---OO-OO-----H----------- 
CCCCCCCCCCCCCCCCCCC------ CBBBBBBAAAAAAAACCCC------ CBBBBBBAAAAAAAACCCC------ CBBBBBBAAAAAAAACCCC------ CBBBBBBAAAAAAAACCCC------ CBBBBBBAAAAAAAACCCC------ C-BBBBBIDDDDIAICCCAAAAAAA C-BBBBBBBBBBBBBBBBAAAAAAA C-AABBABBBBBBBAAAAA-----A C-AABBABBBBBBBAAAAA-----A C-AAAA--AABBAAAAAAA-----A C-AAAA------AAAAAAA-----A C-AAAA------A--AA-A-----A C-AAAAAAAAAAAAAAA-A-----A C-AAAAAAAAAAAAAAA-A-----A C-AAAADDDDBBBBBBB-A-----A C-AAADDDDDBBBBBBB-A-----A C-EEEEEDDDCCCKKKD-AAAAAAA C-FFFDDDDDDDDKKKD-AAAAAAA C-FFFDDDDDDDDKKKD-C------ C-FFFDDDDDDDDKKKD-C------ C-FFFDDDDDDDDKKKDDC------ C-DDDDDDDDDDDKKCCCC------ CGGGGGGGGLGGGLGLNGC------ C----J-J-J-J-J----C------ ------------------------- ---------HHH------------- ------------------------- ----OHH------------------ ------------------------- 
CCCCCCCCCCCCCCCCCCC------ CBBBBBBAAAAAAAACCCC------ CBBBBBBAAAAAAAACCCC------ CBBBBBBAAAAAAAACCCC------ CBBBBBBAAAAAAAACCCC------ CBBBBBBAAAAAAAACCCC------ C-BBBBBIDDDDIAIIIIBAAAAAA C-BBBBBBBBBBBBBBBBBAAAAAA C-AABBABBBBBBBAAAAA-----A C-AABBABBBBBBBAAAAA-----A C-AAAA--AABBAAAAAAA-----A C-AAAA------AAAAAAA-----A C-AAAA------A-AAA-A-----A C-AAAAAAAAAAAAAAA-A-----A C-AAAAAAAAAAAAAAA-A-----A C-AAAAADDDBBBBBBB-A-----A C-AAAAADDDBBBBBBB-A-----A C-EEEEEDDDCCCKKKD-AAAAAAA C-FFFDDDDDDDDKKKD-MAAAAAA C-FFFDDDDDDDDKKKD-C------ C-FFFDDDDDDDDKKKD-C------ C-FFFDDDDDDDDKKKDDC------ C-DDDDDDDDDDDKKCCCC------ CGGGGGGLGGGGGGGGGNC------ C---J-J-J-J-J-J---C------ ------------------------- ---------HHH------------- --------OH-HH------------ ----OOORO---HH----------- ---OO-HH-----H----------- 
CCCCCCCCCCCCCCCCCCC------ CBBBBBBAAAAAAAACCCC------ CBBBBBBAAAAAAAACCCC------ CBBBBBBAAAAAAAACCCC------ CBBBBBBAAAAAAAACCCC------ CBBBBBBAAAAAAAACCCC------ C-BBBBBIADAAAAIIIIAAAAAAA C-BBBBBIDDAAAAIIIIAAAAAAA C-AABBADDDBBBBAAAAA-----A C-AABBADDDBBBBAAAAA-----A C-AAAAADDDBBAAAAAAA-----A C-AAAAADDDBBAAAAAAA-----A C-AAAAAAAAAAAAAAA-A-----A C-AAAAAAAAAAAAAAA-A-----A C-AAAAAAAAAAAAAAA-A-----A C-AAAAADDDBBBBBBB-A-----A C-AAAAADDDBBBBBBB-A-----A C-EEEEEDDDCCCCDDD-AAAAAAA C-FFFDCCCCDDDDDDD-AAAAAAA C-FFFDCCCCDDIDDDD-C------ C-FFFDCCCCDDIDDDD-C------ C-FFFDCCCCDDIDDDDDC------ C-DDDDDDDDDDIIDCCCC------ CGLGGGGGGLLGGGGLNNC------ C--J-J-J-J-J-J-J--C------ ---------HHO------------- --------HH-HH------------ -------HH--HHH----------- -----Q-H----HH----------- -------H----------------- 
CCCCCCCCCCCCCCCCCCC------ CBBBBBBAAAAAAAACCCC------ CBBBBBBAAAAAAAACCCC------ CBBBBBBAAAAAAAACCCC------ CBBBBBBAAAAAAAACCCC------ CBBBBBBAAAAAAAACCCC------ C-BBBBBIADAAAAIIIIAAAAAAA C-BBBBBIDDAAAAIIIIAAAAAAA C-AABBADDDBBBBAAAAA-----A C-AABBADDDBBBBAAAAA-----A C-AAAAADDDBBAAAAAAA-----A C-AAAAADDDBBAAAAAAA-----A C-AAAAAAAAAAAAAAA-A-----A C-AAAAAAAAAAAAAAA-A-----A C-AAAAAAAA-AAAAAA-A-----A C-AAAAADDDB---BBB-A-----A C-AAAAADDDB-B-BBB-A-----A C-EEEEEDDDD-D-DDD-AAAAAAA C-FFFDCCCCDDDDDDD-AAAAAAA C-FFFDCCCCDDIDDDD-C------ C-FFFDCCCCDDIDDDD-C------ C-FFFDCCCCDDIDDDDDC------ C-DDDDDDDDDDIIDCCCC------ CGGLLGGLGGGLGGGGGNC------ C---J-J-J-J-J-J---C------ ---------HHH------------- ------------------------- ------------------------- -----H------------------- ------------------------- 
CCCCCCCCCCCCCCCCCCC------ CBBBBBBBBBBBBBBBBBC------ CBBBBBBBBBBBBBBBBBC------ CBBBBBBBBBBBBBBBBBC------ CBBBBBBBBBBBBBBBBBC------ CBBBBBBBBBBBBBBBBBC------ C-BBBBBBBBBBBBBBBBAAAAAAA C-BBBBBBBBBBBBBBBBAAAAAAA C-AABBADDDBBBBAAAAA-----A C-AABBADDDBBBBAAAAA-----A C-AAAAADDDBBAAAAAAA-----A C-AAAAADDDBBAAAAAAA-----A C-AAAAAAAAAAAAAAA-A-----A C-AAAAAAAAAAAAAAA-A-----A C-AAAAAAAA-A-AAAA-A-----A C-AAAAADDDB---AAA-A-----A C-AAAAADDDB-B-AAA-A-----A C-EEEEEEEEE-E-EEE-AAAAAAA C-FFFDCCCCDDDEEEE-AAAAAAA C-FFFDCCCCDDIEEEE-C------ C-FFFDCCCCDDIEEEE-C------ C-FFFDCCCCDDIEEEEEC------ C-DDDDDDDDDDIEEEEEC------ CGNGLGGGLGGGGGGGGNC------ C----J-J-J-J-J----C------ ---------OOO------------- --------OO-HH------------ -------OOH--OH----------- -------O-----O----------- ------------------------- 
CCCCCCCCCCCCCCCCCCC------ CBBBBBBBBBBBBBBBBBC------ CBBBBBBBBBBBBBBBBBC------ CBBBBBBBBBBBBB---BC------ CBBBBBBBBBBBBB---BC------ CBBBBBBBBBBBBB---BC------ CBBBBBBBBBBBBB---BC------ CBBBBBBBBBBBBB---BC------ CAAAAAAAAAAAAA---AC------ CAAAAAAAAAAAAA---AC------ CAAAAAADDDBBAA---AC------ CAAAAAADDDBBAA---AC------ CAAAAAAAAAAAAA---AC------ CAAAAAAAAAAAAA---AC------ CAAAAAAAAA-AAAAA-AC------ CAAAAAADDDB--AAAAAC------ CAAAAAADDDB-BAAAAAC------ CEEEEEEEEEE-EEEEEEC------ CFFFFFCCCCDDDEEEEEC------ CFFFFFCCCCDDIEEEEEC------ CFFFFFCCCCDDIEEEEEC------ CFFFFFCCCCDDIEEEEEC------ CMDDDDDDDDDDIEEEEEC------ CGNNLGLGGGLGLNLGGNC------ C-----J-J-J-J-----C------ ----------Q-------------- ----------H-------------- ------QOQ---H------------ ------------------------- ------------------------- 
-CCCCCCCCCCCCCCCCC------- -CBBBBBBBBBBBBBBBC------- -CBBBBBBBBBBBBBBBC------- -CBBBBBBBBBBBB---C------- -CBBBBBBBBBBBB---C------- -CBBBBBBBBBBBB---C------- -CBBBBBBBBBBBB---C------- -CBBBBBBBBBBBB---C------- -CAAAAAAAAAAAA---C------- -CAAAAAAAAAAAA---C------- -CAAAAABBBBBAA---C------- -CAAAAABBBBBAA---C------- -CAAAAABBBBAAA---C------- -CAAAAABBBBAAA--AC------- -CAAAAABBB-A-AA-AC------- -CAAAAABBBB--AAAAC------- -CAAAAADDDD-DAAAAC------- -CEEEEEEEEE-EEEE-C------- -CFFFFDDDDDDDEEEEC------- -CFFFFDDDDDDIEEEEC------- -CFFFFDDDDDDIEEEEC------- -CFFFFDDDDDDIEEEEC------- -CDDDDDDDDDDIEEEEC------- -CGGLLGGGGLLGNGGNC------- -C-----J-J-J-----C------- ------------------------- ----------QH------------- ------H----H------------- ------------------------- ------------------------- 
-CCCCCCCCCCCCCCCCC------- -CBBBBBBB-BBBBBBBC------- -CBBBBBBB-BBBBBBBC------- -CBBBBBBBBBBBBB-BC------- -CBBBBBBBBBB----BC------- -CBBBBBBBB------BC------- -CBBBBBBBB------BC------- -CBBBBBBBB------BC------- -CAAAAAAAA------AC------- -CAAAAAAAA------AC------- -CAAAAABBB------AC------- -CAAAAABBB------AC------- -CAAAAABBB------AC------- -CAAAAABBB------AC------- -CAAAAABBBB-AAAAAC------- -CAAAAABBBB--AAAAC------- -CAAAAADDDD-DAAAAC------- -CEEEEEEEEE-EEEEEC------- -CFFFFDDDDDDDEEEEC------- -CFFFFDDDDDDIEEEEC------- -CFFFFDDDDDDIEEEEC------- -CFFFFDDDDDDIEEEEC------- -CMDDDDDDDDDIEEEEC------- -CGNNNLGGGGLGNGNNC------- -C------J-J------C------- ------------------------- ----------O-------------- ------------------------- ------------------------- ------------------------- 
--CCCCCCCCCCCCCCC-------- --CBBBBBBBBBBBBBC-------- --CBBBBBBBBBBBBBC-------- --CBBBBBBBBB--BBC-------- --CBBBBBBBB----BC-------- --CBBBBBBB-----BC-------- --CBBBBBBB-----BC-------- --CBBBBBBB-----BC-------- --CAAAAAAA-----AC-------- --CAAAAAAA-----AC-------- --AA--ABBB-----AA-------- --AA--ABBB-----AA-------- --AA--ABBB-----AA-------- --AA--ABBB-----AA-------- --AA--ABBBBAAAAAA-------- --CA--ABBB-B-AAAC-------- --CA--ADDD--DAAAC-------- --CE--EEEE--EEEEC-------- --CF--DDDD--DEEEC-------- --CF--DDDD--IEEEC-------- --CF--DDDD--IEEEC-------- --CF--DDDD--IEEEC-------- --CMDDDDDDDDIEEEC-------- --CGGGGGLGGNNGNNC-------- --C------J------C-------- ------------------------- ------------------------- ------------------------- ------------------------- ------------------------- 
---CCCCCCCCCCCCC--------- ---CBBBBBBBBBBBC--------- ---CBBBBBBBBBBBC--------- ---CB----BBB--BC--------- ---CB----BB---BC--------- ---CB---------BC--------- ---CB---------BC--------- ---CB---------BC--------- ---CA---------AC--------- ---CA---------AC--------- ---AA---------AA--------- ---AA---------AA--------- ---AA---------AA--------- ---AA---------AA--------- ---AA------AAAAA--------- ---CA------BBAAC--------- ---CA-------DAAC--------- ---CE-------EEEC--------- ---CF-------DEEC--------- ---CF--------EEC--------- ---CF--------EEC--------- ---CF--------EEC--------- ---CMDDDDDDDBEEC--------- ---CGGGNLNNLGGNC--------- ---C-----------C--------- ------------------------- ------------------------- ------------------------- ------------------------- ------------------------- 
----CCCCCCCCCCC---------- ----CCBBBBBBBCC---------- ----CCBBBBBBBCC---------- ----CCB---B-BCC---------- ----CCB-----BCC---------- ----CCB-----BCC---------- ----CCB-----BCC---------- ----CCB-----BCC---------- ----CCA-----ACC---------- ----CCA-----ACC---------- ----AAA-----AAA---------- ----AAA-----AAA---------- ----AAA-----AAA---------- ----AAA-----AAA---------- ----AAA-----AAA---------- ----CCA-----BCC---------- ----CCA-----MCC---------- ----CCE-----ECC---------- ----CCM-----MCC---------- ----CCM-----MCC---------- ----CCM-----MCC---------- ----CCM-----MCC---------- ----CCMDDDDDMCC---------- ----CCGGGNNGGCC---------- ----CC-------CC---------- ------------------------- ------------------------- ------------------------- ------------------------- ------------------------- 
------CCCCCCC------------ ------CAAAAAC------------ ------CAAAAAC------------ ------CAAAAAC------------ ------CAAAAAC------------ ------CAAAAAC------------ ------CAAAAAC------------ ------CAAAAAC------------ ------CAAAAAC------------ ------CAAAAAC------------ ------AAAAAAA------------ ------AAAAAAA------------ ------AAAAAAA------------ ------AAAAAAA------------ ------AAAAAAA------------ ------CAAAAAC------------ ------CAAAAAC------------ ------CAAAAAC------------ ------CAAAAAC------------ ------CAAAAAC------------ ------CAAAAAC------------ ------CAAAAAC------------ ------CAAAAAC------------ ------CAAAAAC------------ ------CCCCCCC------------ ------------------------- ------------------------- ------------------------- ------------------------- ------------------------- 
