model
size = 25 30 19, scale = 0.05, origin = -y
material 
  colors = A:#E00 B:#EEE C:#00C D:#CF3 E:#FF0 F:#251505 G:#CF0 H:#AAAAB9 I:#BBB J:#CC6 K:#939 L:#960 M:#1C0900 N:#AAA O:#040 P:#888 Q:#FCF
voxels
------BBBBBBB------------ ------BBBBBBB------------ ------BBBBBBB------------ ------BBBBBBB------------ ------BBBBBBB------------ ------BBBBBBB------------ ------BBBBBBB------------ ------BBBBBBB------------ ------BBBBBBB------------ ------BBBBBBB------------ ------BBBBBBB------------ ------BBBBBBB------------ ------BBBBBBB------------ ------BBBBBBB------------ ------BBBBBBB------------ ------BBBBBBB------------ ------BBBBBBB------------ ------BBBBBBB------------ ------BBBBBBB------------ ------BBBBBBB------------ ------BBBBBBB------------ ------BBBBBBB------------ ------BBBBBBB------------ ------BBBBBBB------------ ------BBBBBBB------------ ------------------------- ------------------------- ------------------------- ------N------------------ ------------------------- 
----BBBBBBBBBBB---------- ----BBA---AAABB---------- ----BBA---AAABB---------- ----BBA---AAABB---------- ----BBA---AAAAA---------- ----CCA---AAAAA---------- ----CCA---AAAAA---------- ----CCA--AAAAAA---------- ----CCE--EEEEAA---------- ----CCE--EEEEAA---------- ----CCE--EEEEAA---------- ----CCE-EEEEEAA---------- ----CCEEEEEEEAA---------- ----CCEEEEEEEAA---------- ----CCEEEEEEEAA---------- ----CCEEEEEEEAA---------- ----CCHDDDEEEAA---------- ----CCAAAAAAAAA---------- ----CCHDDDDDHAA---------- ----CCHDDDDDHAA---------- ----CCHDDDDDHAA---------- ----CCHDDDDDHAA---------- ----BBHDDDDDHBB---------- ----BBFFFFFFFBB---------- ----BB-------BB---------- ------------------------- ------------------------- ------------------------- ------I------------------ ------I------------------ 
---BBBBBBBBBBBBB--------- ---BAA--------AB--------- ---BAAAAAAAAAAAB--------- ---BAAAAAAAAAAAB--------- ---BAAAAAAAAAAAA--------- ---CCAAAAAAAAAAA--------- ---CCBBBBBBBBBAA--------- ---CCAAAAAAAAAAA--------- ---CCEEEEEEEEAAA--------- ---CCEEEEEEEEAAA--------- ---CCEEEEEEEEAAA--------- ---CCEEEEEEEEAAA--------- ---CCEEEEEEEEAAA--------- ---CCEEEEEEEEAAA--------- ---CCEEEEEEEEAAA--------- ---CCEEEEEEEEAAA--------- ---CCDDDDDEEEAAA--------- ---CCAAAAAAAAAAA--------- ---CCDDDDDDDDAAA--------- ---CCDDDDDDDDAAA--------- ---CCDDDDDDDDAAA--------- ---CCDDDDDDDDAAA--------- ---BHDDDDDDDDDHB--------- ---BFFFFFFLMFFFB--------- ---B-----------B--------- ------------------------- ------------------------- ------------------------- ------------------------- ------II----------------- 
--BBBBBBBBBBBBBBB-------- --BBAAAAAAAAAAABB-------- --BBAAAAAAAAAAABB-------- --BBAAAAAAAAAAABB-------- --BBAAAAAAAAAAAAA-------- --CCCAAAAAAAAAAAA-------- --CCCBBBBBBBBBAAA-------- --CCCAAAAAAAAAAAA-------- --CCCEEEEEEEEEEEA-------- --CCCE--------EEA-------- --CCCEEEEEEEEEEEA-------- --CCCEEEEEEEEEEEA-------- --CCCEEEEEEEEEEEA-------- --CCCEEEEE-EEEEEA-------- --CCCEEEEE-EEEEEA-------- --CCCEEEEE-EEEEEA-------- --CCCDDDDD-EEEEEA-------- --CCCAAAAA-AAAAAA-------- --CCCDDDDD-DDDDHA-------- --CCCDDDDD-DDDDHA-------- --CCCDDDDD-DDDDHA-------- --CCCDDDDD-DDDDHA-------- --BHDDDDDD-DDDDBB-------- --BFFFFLFLFFMMFFB-------- --B------J------B-------- ------------------------- ------------------------- ------------------------- ---I--------------------- -------I----------------- 
-BBBBBBBBBBBBBBBBB------- -BBBAAAAAAAAAAA-BB------- -BBBAAAAAAAAAAA-BB------- -BBBAAAAAAAAAAA-BB------- -BBBAAAAAAAAAAA-AA------- -CCCCAAAAAAAAAA-AA------- -CCCCAAAAAAAAAA-AA------- -CCCCAAAAAAAAAA-AA------- -CCCCAAAAAEEEEE-EA------- -CCCCAAAAAEEEEE-EA------- -CC-CAAAAAEEEEE-EA------- -CC-CAOOOOEEEEE-EA------- -CC-CADODOEEEEE-EA------- -CC-CADDDDEEEEE-EA------- -CC-CADDDDEEEEE-EA------- -CCCCADDDDEEEEE-EA------- -CC-CDDDDDEEEEE-EA------- -CC-CAAAAAAAAAA-AA------- -CC-CDDDDDDDDDD-HA------- -CC-CDDDDDDDDDD-HA------- -CC-CDDDDDDDDDD-HA------- -CCCCDDDDDDDDDD-HA------- -BHEDDDDDDDDDDD-BB------- -BFFLFLFLFFLMLFFFB------- -B------J-J------B------- ------------------------- ------------------------- ------------------------- ---I--------------------- ---N---I----------------- 
-BBBBBBBBBBBBBBBBB------- -BBBDDAAAAAAAAABBB------- -BBBDDAAAAAAAAABBB------- -BBBDDAAAAAAAAABBB------- -BBBDDAAAAAAAAAAAA------- -CCCCDAAAAAAAAAAAA------- -CCCCDAAAAAAAAAAAA------- -CCCCDAAAAAAAAAAAA------- -CCCCAAAAAEEEEEEEA------- -CCCCAAAAAEEEEEEEA------- -CCCCAAAAAEEEEEEEA------- -CCCCAAAOOEEEEEEEA------- -CCCCAAAOOEEEEEEEA------- -CCCCADDDDEEEEEEEA------- -CCCCADDDDEEEEEEEA------- -CCCCADDDDEEEEEEEA------- -CCCCDDDDDEEEEEEEA------- -CCCCADDDAAAAAAAAA------- -CCCCDDDDDDDDDDDDA------- -CCCCDDDDDDDDDDDDA------- -CCCCDDDDDDDDDDDDA------- -CCCCDDDDDDDDDDDDA------- -BDDDDDDDDDDDDDBBB------- -BLFLLFLFFFLFFLLFB------- -B-----J-J-J-----B------- ------------------------- ------------------------- ------------------------- ------------------------- ---P--IN----------------- 
BBBBBBBBBBBBBBBBBBB------ BBBBDDAAAAAAAAABBBB------ BBBBDDAAAAAAAAABBBB------ BBBBDDAAAAAAAAABBBB------ BBBBDDAAAAAAAAABBBA------ CCCCCDAAAAAAAAABBBA------ CCCCCDAAAAAAAAABBBA------ CCCCCDAAAAAAAAAAAAA------ CCCCCAAAAAEEEEEEEEA------ CCCCCAAAAAEEEEEEEEA------ CCCCCAAAAAEEEEEEEEA------ CCCCCAAAAAEEEEEEEEA------ CCCCCAAAAAEEEEEEEEA------ CCCCCADDDDEEEEEEEEA------ CCCCCADDDDEEEEEEEEA------ CCCCCADDDDEEEEEEEEA------ CCCCCDDDDDEEEEEEEEA------ CCCCCADDDAAAAAAAAAA------ CCCCCDDDDDDDDKKKDHA------ CCCCCDDDDDDDDKKKDHA------ CCCCCDDDDDDDDKKKDHA------ CCCCCDDDDDDDDKKKDHA------ BHDDDDDDDDDDDKKBBBB------ BFFFFFLLFFFFFLMFFMB------ B-----J-J-J-J-----B------ ------------------------- ---------III------------- --------NI-II------------ ----NNNNN---II----------- ---NN-NN-----I----------- 
BBBBBBBBBBBBBBBBBBB------ BBBBAAAAAAAAAAABBBB------ BBBBAAAAAAAAAAABBBB------ BBBBAAAAAAAAAAABBBB------ BBBBAAAAAAAAAAABBBA------ CCCCCAAAAAAAAAABBBA------ C-CCCGAGDDDDGAGBBBBBBBBBB C-CCCGAGDDDDGAGGGGGBBBBBB C-CCCAAAAAEEEEEEEEA-----B C-CCCAAAAAEEEEEEEEA-----B C-CCCA--AAEEEEEEEEA-----B C-CCCA------EEEEEEA-----B C-CCCA------E--EE-A-----B C-CCCADDDDEEEEEEE-A-----B C-CCCADDDDEEEEEEE-A-----B C-CCCADDDDEEEEEEE-A-----B C-CCCDDDDDEEEEEEE-A-----B C-CCCADDDDBBBKKKD-HBBBBBB C-CCCDDDDDDDDKKKD-HBBBBBB C-CCCDDDDDDDDKKKD-A------ C-CCCDDDDDDDDKKKD-A------ C-CCCDDDDDDDDKKKDDA------ B-DDDDDDDDDDDKKBBBB------ BFFFFFFFFLFFFLFLMFB------ B----J-J-J-J-J----B------ ------------------------- ---------III------------- ------------------------- ----NII------------------ ------------------------- 
BBBBBBBBBBBBBBBBBBB------ BBBBAAAAAAAAAAABBBB------ BBBBAAAAAAAAAAABBBB------ BBBBAAAAAAAAAAABBBB------ BBBBAAAAAAAAAAABBBA------ CCCCCAAAAAAAAAABBBA------ C-CCCGAGDDDDGAGGGGABBBBBB C-CCCGAGDDDDGAGGGGABBBBBB C-CCCAAAAAEEEEEEEEA-----B C-CCCAAAAAEEEEEEEEA-----B C-CCCA--AAEEEEEEEEA-----B C-CCCA------EEEEEEA-----B C-CCCA------E-EEE-A-----B C-CCCADDDDEEEEEEE-A-----B C-CCCADDDDEEEEEEE-A-----B C-CCCADDDDEEEEEEE-A-----B C-CCCDDDDDEEEEEEE-A-----B C-CCCADDDDBBBKKKD-HBBBBBB C-CCCDDDDDDDDKKKD-HBBBBBB C-CCCDDDDDDDDKKKD-A------ C-CCCDDDDDDDDKKKD-A------ C-CCCDDDDDDDDKKKDDA------ B-DDDDDDDDDDDKKBBBB------ BFFFFFFLFFFFFFFFFMB------ B---J-J-J-J-J-J---B------ ------------------------- ---------III------------- --------NI-II------------ ----NNNQN---II----------- ---NN-II-----I----------- 
BBBBBBBBBBBBBBBBBBB------ BBBBAAAAAAAAAAABBBB------ BBBBAAAAAAAAAAABBBB------ BBBBAAAAAAAAAAABBBB------ BBBBAAAAAAAAAAABBBA------ CCCCCAAAAAAAAAABBBA------ C-CCCGGGADAAAAGGGGABBBBBB C-CCCGGGDDAAAAGGGGABBBBBB C-CCCAADDDEEEEEEEEA-----B C-CCCAADDDEEEEEEEEA-----B C-CCCAADDDEEEEEEEEA-----B C-CCCAADDDEEEEEEEEA-----B C-CCCAADDDEEEEEEE-A-----B C-CCCAADDDEEEEEEE-A-----B C-CCCAADDDEEEEEEE-A-----B C-CCCAADDDEEEEEEE-A-----B C-CCCDDDDDEEEEEEE-A-----B C-CCCADDDDBBBBDDD-HBBBBBB C-CCCDBBBBDDDDDDD-HBBBBBB C-CCCDBBBBDDGDDDD-A------ C-CCCDBBBBDDGDDDD-A------ C-CCCDBBBBDDGDDDDDA------ B-DDDDDDDDDDGGDBBBB------ BFLFFFFFFLLFFFFLMMB------ B--J-J-J-J-J-J-J--B------ ---------IIN------------- --------II-II------------ -------II--III----------- -----P-I----II----------- -------I----------------- 
BBBBBBBBBBBBBBBBBBB------ BBBBAAAAAAAAAAABBBB------ BBBBAAAAAAAAAAABBBB------ BBBBAAAAAAAAAAABBBB------ BBBBAAAAAAAAAAABBBA------ CCCCCAAAAAAAAAABBBA------ C-CCCGGGADAAAAGGGGABBBBBB C-CCCGGGDDAAAAGGGGABBBBBB C-CCCAADDDEEEEEEEEA-----B C-CCCAADDDEEEEEEEEA-----B C-CCCAADDDEEEEEEEEA-----B C-CCCAADDDEEEEEEEEA-----B C-CCCAADDDEEEEEEE-A-----B C-CCCAADDDEEEEEEE-A-----B C-CCCAADDD-EEEEEE-A-----B C-CCCAADDDE---EEE-A-----B C-CCCDDDDDE-E-EEE-A-----B C-CCCADDDDD-D-DDD-HBBBBBB C-CCCDBBBBDDDDDDD-HBBBBBB C-CCCDBBBBDDGDDDD-A------ C-CCCDBBBBDDGDDDD-A------ C-CCCDBBBBDDGDDDDDA------ B-DDDDDDDDDDGGDBBBB------ BFFLLFFLFFFLFFFFFMB------ B---J-J-J-J-J-J---B------ ---------III------------- ------------------------- ------------------------- -----I------------------- ------------------------- 
BBBBBBBBBBBBBBBBBBB------ BBBBAAAAAAAAAAABBBB------ BBBBAAAAAAAAAAABBBB------ BBBBAAAAAAAAAAABBBB------ BBBBAAAAAAAAAAABBBA------ CCCCCAAAAAAAAAABBBA------ C-CCCGGGADAAAAAAAAA------ C-CCCGGGDDAAAAGGGAA------ C-CCCAADDDEEEEEEEEA------ C-CCCAADDDEEEEEEEEA------ C-CCCAADDDEEEEEEEEA------ C-CCCAADDDEEEEEEEEA------ C-CCCAADDDEEEEEEE-A------ C-CCCAADDDEEEEEEE-A------ C-CCCAADDD-E-EEEE-A------ C-CCCAADDDE---EEE-A------ C-CCCDDDDDE-E-EEE-A------ C-CCCAAAAAA-A-AAA-A------ C-CCCDBBBBDDDDDDD-A------ C-CCCDBBBBDDGDDDD-A------ C-CCCDBBBBDDGDDDD-A------ C-CCCDBBBBDDGDDDDDA------ B-DDDDDDDDDDGGDBBBB------ BFMFLFFFLFFFFFFFFMB------ B----J-J-J-J-J----B------ ---------NNN------------- --------NN-II------------ -------NNI--NI----------- -------N-----N----------- ------------------------- 
BBBBBBBBBBBBBBBBBBB------ BBBBAAAAAAAAAAABBBB------ BBBBAAAAAAAAAAABBBB------ BBBBAAAAAAAAAA---BB------ BBBBAAAAAAAAAA---BA------ CCCCCCAAAAAAAA---BA------ CCCCCCGGADAAAA---AA------ CCCCCCGGDDAAAA---AA------ CCCCCCADDDEEEE---EA------ CCCCCCADDDEEEE---EA------ CCCCCCADDDEEEE---EA------ CCCCCCADDDEEEE---EA------ CCCCCCADDDEEEE---EA------ CCCCCCADDDEEEE---EA------ CCCCCCADDD-EEEEE-EA------ CCCCCCADDDE--EEEEEA------ CCCCCCDDDDE-EEEEEEA------ CCCCCCAAAAA-AAAAAAA------ CCCCCCBBBBDDDDDDDHA------ CCCCCCBBBBDDGDDDDHA------ CCCCCCBBBBDDGDDDDHA------ CCCCCCBBBBDDGDDDDHA------ BHDDDDDDDDDDGDDBBBB------ BFMMLFLFFFLFLMLFFMB------ B-----J-J-J-J-----B------ ----------P-------------- ----------I-------------- ------PNP---I------------ ------------------------- ------------------------- 
-BBBBBBBBBBBBBBBBB------- -BBBAAAAAAAAAAABBB------- -BBBAAAAAAAAAAABBB------- -BBBAAAAAAAAAA---B------- -BBBAAAAAAAAAA---A------- -CCCCCAAAAAAAA---A------- -CCCCCAAAAAAAA---A------- -CCCCCAAAAAAAA---A------- -CCCCCEEEEEEEE---A------- -CCCCCEEEEEEEE---A------- -CCCCCEEEEEEEE---A------- -CCCCCEEEEEEEE---A------- -CCCCCEEEEEEEE---A------- -CCCCCEEEEEEEE--EA------- -CCCCCEEEE-E-EE-EA------- -CCCCCEEEEE--EEEEA------- -CCCCCDDDDD-DDDDDA------- -CCCCCAAAAA-AAAA-A------- -CCCCCDDDDDDDDDDEA------- -CCCCCDDDDDDGDDDEA------- -CCCCCDDDDDDGDDDEA------- -CCCCCDDDDDDGDDDEA------- -BDDDDDDDDDDGDBBBB------- -BFFLLFFFFLLFMFFMB------- -B-----J-J-J-----B------- ------------------------- ----------PI------------- ------I----I------------- ------------------------- ------------------------- 
-BBBBBBBBBBBBBBBBB------- -BBBAAAAA-AAAAABBB------- -BBBAAAAA-AAAAABBB------- -BBBAAAAAAAAAAA-BB------- -BBBAAAAAAAA----AA------- -CCCCCAAAA------AA------- -CCCCCAAAA------AA------- -CCCCCAAAA------AA------- -CCCCCEEEE------EA------- -CCCCCEEEE------EA------- -CCCCCEEEE------EA------- -CCCCCEEEE------EA------- -CCCCCEEEE------EA------- -CCCCCEEEE------EA------- -CCCCCEEEEE-EEEEEA------- -CCCCCEEEEE--EEEEA------- -CCCCCDDDDD-DDDDHA------- -CCCCCAAAAA-AAAAAA------- -CCCCCDDDDDDDDDDHA------- -CCCCCDDDDDDGDDDHA------- -CCCCCDDDDDDGDDDHA------- -CCCCCDDDDDDGDDDHA------- -BHDDDDDDDDDGDBBBB------- -BFMMMLFFFFLFMFMMB------- -B------J-J------B------- ------------------------- ----------N-------------- ------------------------- ------------------------- ------------------------- 
--BBBBBBBBBBBBBBB-------- --BBAAAAAAAAAAABB-------- --BBAAAAAAAAAAABB-------- --BBAAAAAAAA--ABB-------- --BBAAAAAAA----AA-------- --CCCCAAAA-----AA-------- --CCCCAAAA-----AA-------- --CCCCAAAA-----AA-------- --CCCCEEEE-----EA-------- --CCCCEEEE-----EA-------- --CC--EEEE-----EA-------- --CC--EEEE-----EA-------- --CC--EEEE-----EA-------- --CC--EEEE-----EA-------- --CC--EEEEEEEEEEA-------- --CC--EEEE-E-EEEA-------- --CC--DDDD--DDDHA-------- --CC--AAAA--AAAAA-------- --CC--DDDD--DDDHA-------- --CC--DDDD--GDDHA-------- --CC--DDDD--GDDHA-------- --CC--DDDD--GDDHA-------- --BHDDDDDDDDGDBBB-------- --BFFFFFLFFMMFMMB-------- --B------J------B-------- ------------------------- ------------------------- ------------------------- ------------------------- ------------------------- 
---BBBBBBBBBBBBB--------- ---BAAAAAAAAAAAB--------- ---BAAAAAAAAAAAB--------- ---BA----AAA--AB--------- ---BA----AA---AA--------- ---CC---------AA--------- ---CC---------AA--------- ---CC---------AA--------- ---CC---------EA--------- ---CC---------EA--------- ---CC---------EA--------- ---CC---------EA--------- ---CC---------EA--------- ---CC---------EA--------- ---CC------EEEEA--------- ---CC------EEEEA--------- ---CC-------DDHA--------- ---CC-------AAAA--------- ---CC-------DDHA--------- ---CC--------DHA--------- ---CC--------DHA--------- ---CC--------DHA--------- ---BHDDDDDDDEDBB--------- ---BFFFMLMMLFFMB--------- ---B-----------B--------- ------------------------- ------------------------- ------------------------- ------------------------- ------------------------- 
----BBBBBBBBBBB---------- ----BBAAAAAAABB---------- ----BBAAAAAAABB---------- ----BBA---A-ABB---------- ----BBA-----AAA---------- ----CCA-----AAA---------- ----CCA-----AAA---------- ----CCA-----AAA---------- ----CCE-----EAA---------- ----CCE-----EAA---------- ----CCE-----EAA---------- ----CCE-----EAA---------- ----CCE-----EAA---------- ----CCE-----EAA---------- ----CCE-----EAA---------- ----CCE-----EAA---------- ----CCH-----HAA---------- ----CCA-----AAA---------- ----CCH-----HAA---------- ----CCH-----HAA---------- ----CCH-----HAA---------- ----CCH-----HAA---------- ----BBHDDDDDHBB---------- ----BBFFFMMFFBB---------- ----BB-------BB---------- ------------------------- ------------------------- ------------------------- ------------------------- ------------------------- 
------BBBBBBB------------ ------BBBBBBB------------ ------BBBBBBB------------ ------BBBBBBB------------ ------BBBBBBB------------ ------BBBBBBB------------ ------BBBBBBB------------ ------BBBBBBB------------ ------BBBBBBB------------ ------BBBBBBB------------ ------BBBBBBB------------ ------BBBBBBB------------ ------BBBBBBB------------ ------BBBBBBB------------ ------BBBBBBB------------ ------BBBBBBB------------ ------BBBBBBB------------ ------BBBBBBB------------ ------BBBBBBB------------ ------BBBBBBB------------ ------BBBBBBB------------ ------BBBBBBB------------ ------BBBBBBB------------ ------BBBBBBB------------ ------BBBBBBB------------ ------------------------- ------------------------- ------------------------- ------------------------- ------------------------- 
