model
size = 25 30 19, scale = 0.05, origin = -y
material 
  colors = A:#FF0 B:#E00 C:#CF3 D:#000 E:#EEE F:#00C G:#251505 H:#BBB I:#CF0 J:#CC6 K:#AAAAB9 L:#939 M:#960 N:#1C0900 O:#AAA P:#040 Q:#888 R:#FCF
voxels
------AAAAAAA------------ ------AAAAAAA------------ ------AAAAAAA------------ ------AAAAAAA------------ ------AAAAAAA------------ ------AAAAAAA------------ ------AAAAAAA------------ ------AAAAAAA------------ ------BBBBBBB------------ ------BBBBBBB------------ ------BBBBBBB------------ ------BBBBBBB------------ ------BBBBBBB------------ ------BBBBBBB------------ ------BBBBBBB------------ ------BBBBBBB------------ ------BBBBBBB------------ ------DDDDDDD------------ ------DDDDDDD------------ ------DDDDDDD------------ ------DDDDDDD------------ ------DDDDDDD------------ ------DDDDDDD------------ ------DDDDDDD------------ ------DDDDDDD------------ ------------------------- ------------------------- ------------------------- ------O------------------ ------------------------- 
----AAAAAAAAAAA---------- ----AAA---AAAAA---------- ----AAA---AAAAA---------- ----AAA---AAAAA---------- ----AAA---AAAAA---------- ----AAA---AAAAA---------- ----AAA---AAAAA---------- ----AAA--AAAAAA---------- ----BBB--BBBBBB---------- ----BBB--BBBBBB---------- ----BBB--BBBBBB---------- ----BBB-BBBBBBB---------- ----BBBBBBBBBBB---------- ----BBBBBBBBBBB---------- ----BBBBBBBBBBB---------- ----BBBBBBBBBBB---------- ----BBBBBBBBBBB---------- ----DDDDDDDDDDD---------- ----DDKCCCCCKDD---------- ----DDKCCCCCKDD---------- ----DDKCCCCCKDD---------- ----DDKCCCCCKDD---------- ----DDKCCCCCKDD---------- ----DDGGGGGGGDD---------- ----DD-------DD---------- ------------------------- ------------------------- ------------------------- ------H------------------ ------H------------------ 
---AAAAAAAAAAAAA--------- ---AAA--------AA--------- ---AAAAAAAAAAAAA--------- ---AAAAAAAAAAAAA--------- ---AAAAAAAAAAAAA--------- ---AAAAAAAAAAAAA--------- ---AAAAAAAAAAAAA--------- ---AAAAAAAAAAAAA--------- ---BBBBBBBBBBABB--------- ---BBBBBBBBBBABB--------- ---BBAAAAAAABBBB--------- ---BBAAAAAAABBBB--------- ---BBAAAAAAABBBB--------- ---BBAAAAAAABBBB--------- ---BBAAAAAAABBBB--------- ---BBAAAAAAABBBB--------- ---BBCCCCCAABBBB--------- ---DDDDDDDDDDDDD--------- ---DFCCCCCCCCBBD--------- ---DFCCCCCCCCBBD--------- ---DFCCCCCCCCBBD--------- ---DFCCCCCCCCBBD--------- ---DKCCCCCCCCCKD--------- ---DGGGGGGMNGGGD--------- ---D-----------D--------- ------------------------- ------------------------- ------------------------- ------------------------- ------HH----------------- 
--AAAAAAAAAAAAAAA-------- --AAAAAAAAAAAAAAA-------- --AAAAAAAAAAAAAAA-------- --AAAAAAAAAAAAAAA-------- --AAAAAAAAAAAAAAA-------- --AAAAAAAAAAAAAAA-------- --AAAAAAAAAAAAAAA-------- --AAAAAAAAAAAAAAA-------- --BBAAAAAAAAAABBB-------- --BBAA--------BBB-------- --BBBAAAAAAABBBBB-------- --BBBAAAAAAABBBBB-------- --BBBAAAAAAABBBBB-------- --BBBAAAAA-ABBBBB-------- --BBBAAAAA-ABBBBB-------- --BBBAAAAA-ABBBBB-------- --BBBCCCCC-ABBBBB-------- --DDDDDDDD-DDDDDD-------- --DFFCCCCC-CCCCKD-------- --DFFCCCCC-CCCCKD-------- --DFFCCCCC-CCCCKD-------- --DFFCCCCC-CCCCKD-------- --DKCCCCCC-CCCCED-------- --DGGGGMGMGGNNGGD-------- --D------J------D-------- ------------------------- ------------------------- ------------------------- ---H--------------------- -------H----------------- 
-AAAAAAAAAAAAAAAAA------- -AAAAAAAAAAAAAA-AA------- -AAAAAAAAAAAAAA-AA------- -AAAAAAAAAAAAAA-AA------- -AAAAAAAAAAAAAA-AA------- -AAAAAAAAAAAAAA-AA------- -AAAAAAAAAAAAAA-AA------- -AAAAAAAAAAAAAA-AA------- -BBBAAAAAAAAAAB-BB------- -BBBAAAAAAAAAAB-BB------- -BB-BBBBBBAABBB-BB------- -BB-BBPPPPAABBB-BB------- -BB-BBCPCPAABBB-BB------- -BB-BBCCCCAABBB-BB------- -BB-BBCCCCAABBB-BB------- -BBBBBCCCCAABBB-BB------- -BB-BCCCCCAABBB-BB------- -DD-DDDDDDDDDDD-DD------- -DE-FCCCCCCCCCC-KD------- -DE-FCCCCCCCCCC-KD------- -DE-FCCCCCCCCCC-KD------- -DEFFCCCCCCCCCC-KD------- -DKACCCCCCCCCCC-ED------- -DGGMGMGMGGMNMGGGD------- -D------J-J------D------- ------------------------- ------------------------- ------------------------- ---H--------------------- ---O---H----------------- 
-AAAAAAAAAAAAAAAAA------- -AAAAAAAAAAAAAAAAA------- -AAAAAAAAAAAAAAAAA------- -AAAAAAAAAAAAAAAAA------- -AAAAAAAAAAAAAAAAA------- -AAAAAAAAAAAAAAAAA------- -AAAAAAAAAAAAAAAAA------- -AAAAAAAAAAAAAAAAA------- -BBBAAAAAAAAAABBBB------- -BBBAAAAAAAAAABBBB------- -BBBBBBBBBAABBBBBB------- -BBBBBBBPPAABBBBBB------- -BBBBBBBPPAABBBBBB------- -BBBBBCCCCAABBBBBB------- -BBBBBCCCCAABBBBBB------- -BBBBBCCCCAABBBBBB------- -BBBBCCCCCAABBBBBB------- -DDDDDDCCBBBBBBBBD------- -DEFFCCCCCCCCCCCCD------- -DEFFCCCCCCCCCCCCD------- -DEFFCCCCCCCCCCCCD------- -DEFFCCCCCCCCCCCCD------- -DCCCCCCCCCCCCCEED------- -DMGMMGMGGGMGGMMGD------- -D-----J-J-J-----D------- ------------------------- ------------------------- ------------------------- ------------------------- ---Q--HO----------------- 
AAAAAAAAAAAAAAAAAAA------ AAAAAAAAAAAAAAAAAAA------ AAAAAAAAAAAAAAAAAAA------ AAAAAAAAAAAAAAAAAAA------ AAAAAAAAAAAAAAAAAAA------ AAAAAAAAAAAAAAAAAAA------ AAAAAAAAAAAAAAAAAAA------ AAAAAAAAAAAAAAAAAAA------ BBBBAAAAAAAAAABBBBB------ BBBBAAAAAAAAAABBBBB------ BBBBBBBBBBAAAAAAAAB------ BBBBBBBBBBAAAAAAAAB------ BBBBBBBBBBAAAAAAAAB------ BBBBBBCCCCAAAAAAAAB------ BBBBBBCCCCAAAAAAAAB------ BBBBBBCCCCAAAAAAAAB------ BBBBBCCCCCAAAAAAAAB------ DDDDDDDCCBBBBBBBBDD------ DFFFFCCCCCCCCLLLCKD------ DFFFFCCCCCCCCLLLCKD------ DFFFFCCCCCCCCLLLCKD------ DFFFFCCCCCCCCLLLCKD------ DKCCCCCCCCCCCLLEEED------ DGGGGGMMGGGGGMNGGND------ D-----J-J-J-J-----D------ ------------------------- ---------HHH------------- --------OH-HH------------ ----OOOOO---HH----------- ---OO-OO-----H----------- 
AAAAAAAAAAAAAAAAAAA------ AAAAAAABBBBBBBBEEEA------ AAAAAAABBBBBBBBEEEA------ AAAAAAABBBBBBBBEEEA------ AAAAAAABBBBBBBBEEEA------ AAAAAAABBBBBBBBEEEA------ A-AAAAAICCCCIBIEEEAAAAAAA A-AAAAAAAAAAAAAAAAAAAAAAA B-BBAABAAAAAAABBBBB-----B B-BBAABAAAAAAABBBBB-----B B-BBBB--BBAAAAAAAAB-----B B-BBBB------AAAAAAB-----B B-BBBB------A--AA-B-----B B-BBBBCCCCAAAAAAA-B-----B B-BBBBCCCCAAAAAAA-B-----B B-BBBBCCCCAAAAAAA-B-----B B-BBBCCCCCAAAAAAA-B-----B D-DDDDDCCCEEELLLC-DDDDDDD D-FFFCCCCCCCCLLLC-KDDDDDD D-FFFCCCCCCCCLLLC-D------ D-FFFCCCCCCCCLLLC-D------ D-FFFCCCCCCCCLLLCCD------ D-CCCCCCCCCCCLLEEED------ DGGGGGGGGMGGGMGMNGD------ D----J-J-J-J-J----D------ ------------------------- ---------HHH------------- ------------------------- ----OHH------------------ ------------------------- 
AAAAAAAAAAAAAAAAAAA------ AAAAAAABBBBBBBBEEEA------ AAAAAAABBBBBBBBEEEA------ AAAAAAABBBBBBBBEEEA------ AAAAAAABBBBBBBBEEEA------ AAAAAAABBBBBBBBEEEA------ A-AAAAAICCCCIBIIIIAAAAAAA A-AAAAAAAAAAAAAAAAAAAAAAA B-BBAABAAAAAAABBBBB-----B B-BBAABAAAAAAABBBBB-----B B-BBBB--BBAAAAAAAAB-----B B-BBBB------AAAAAAB-----B B-BBBB------A-AAA-B-----B B-BBBBBCCCAAAAAAA-B-----B B-BBBBBCCCAAAAAAA-B-----B B-BBBBBCCCAAAAAAA-B-----B B-BBBBBCCCAAAAAAA-B-----B D-DDDDDCCCEEELLLC-KDDDDDD D-FFFCCCCCCCCLLLC-KDDDDDD D-FFFCCCCCCCCLLLC-D------ D-FFFCCCCCCCCLLLC-D------ D-FFFCCCCCCCCLLLCCD------ D-CCCCCCCCCCCLLEEED------ DGGGGGGMGGGGGGGGGND------ D---J-J-J-J-J-J---D------ ------------------------- ---------HHH------------- --------OH-HH------------ ----OOORO---HH----------- ---OO-HH-----H----------- 
AAAAAAAAAAAAAAAAAAA------ AAAAAAABBBBBBBBEEEA------ AAAAAAABBBBBBBBEEEA------ AAAAAAABBBBBBBBEEEA------ AAAAAAABBBBBBBBEEEA------ AAAAAAABBBBBBBBEEEA------ A-AAAAAIBCBBBBIIIIAAAAAAA A-AAAAAICCBBBBIIIIAAAAAAA B-BBAABCCCAAAABBBBB-----B B-BBAABCCCAAAABBBBB-----B B-BBBBBCCCAAAAAAAAB-----B B-BBBBBCCCAAAAAAAAB-----B B-BBBBBCCCAAAAAAA-B-----B B-BBBBBCCCAAAAAAA-B-----B B-BBBBBCCCAAAAAAA-B-----B B-BBBBBCCCAAAAAAA-B-----B B-BBBBBCCCAAAAAAA-B-----B D-DDDDDCCCEEEECCC-KDDDDDD D-FFFCEEEECCCCCCC-KDDDDDD D-FFFCEEEECCICCCC-D------ D-FFFCEEEECCICCCC-D------ D-FFFCEEEECCICCCCCD------ D-CCCCCCCCCCIICEEED------ DGMGGGGGGMMGGGGMNND------ D--J-J-J-J-J-J-J--D------ ---------HHO------------- --------HH-HH------------ -------HH--HHH----------- -----Q-H----HH----------- -------H----------------- 
AAAAAAAAAAAAAAAAAAA------ AAAAAAABBBBBBBBEEEA------ AAAAAAABBBBBBBBEEEA------ AAAAAAABBBBBBBBEEEA------ AAAAAAABBBBBBBBEEEA------ AAAAAAABBBBBBBBEEEA------ A-AAAAAIBCBBBBIIIIAAAAAAA A-AAAAAICCBBBBIIIIAAAAAAA B-BBAABCCCAAAABBBBB-----B B-BBAABCCCAAAABBBBB-----B B-BBBBBCCCAAAAAAAAB-----B B-BBBBBCCCAAAAAAAAB-----B B-BBBBBCCCAAAAAAA-B-----B B-BBBBBCCCAAAAAAA-B-----B B-BBBBBCCC-AAAAAA-B-----B B-BBBBBCCCA---AAA-B-----B B-BBBBBCCCA-A-AAA-B-----B D-DDDDDCCCC-C-CCC-KDDDDDD D-FFFCEEEECCCCCCC-KDDDDDD D-FFFCEEEECCICCCC-D------ D-FFFCEEEECCICCCC-D------ D-FFFCEEEECCICCCCCD------ D-CCCCCCCCCCIICEEED------ DGGMMGGMGGGMGGGGGND------ D---J-J-J-J-J-J---D------ ---------HHH------------- ------------------------- ------------------------- -----H------------------- ------------------------- 
AAAAAAAAAAAAAAAAAAA------ AAAAAAAAAAAAAAAAAAA------ AAAAAAAAAAAAAAAAAAA------ AAAAAAAAAAAAAAAAAAA------ AAAAAAAAAAAAAAAAAAA------ AAAAAAAAAAAAAAAAAAA------ A-AAAAAAAAAAAAAAAAA------ A-AAAAAAAAAAAAAAAAA------ B-BBAABCCCAAAABBBBB------ B-BBAABCCCAAAABBBBB------ B-BBBBBCCCAAABBBBBB------ B-BBBBBCCCAAABBBBBB------ B-BBBBBCCCAAABBBB-B------ B-BBBBBCCCAAABBBB-B------ B-BBBBBCCC-A-BBBB-B------ B-BBBBBCCCA---BBB-B------ B-BBBBBCCCA-A-BBB-B------ D-DDDDDDDDD-D-DDD-D------ D-FFFCEEEECCCDDDD-D------ D-FFFCEEEECCIDDDD-D------ D-FFFCEEEECCIDDDD-D------ D-FFFCEEEECCIDDDDDD------ D-CCCCCCCCCCIDDDDDD------ DGNGMGGGMGGGGGGGGND------ D----J-J-J-J-J----D------ ---------OOO------------- --------OO-HH------------ -------OOH--OH----------- -------O-----O----------- ------------------------- 
AAAAAAAAAAAAAAAAAAA------ AAAAAAAAAAAAAAAAAAA------ AAAAAAAAAAAAAAAAAAA------ AAAAAAAAAAAAAA---AA------ AAAAAAAAAAAAAA---AA------ AAAAAAAAAAAAAA---AA------ AAAAAAAAAAAAAA---AA------ AAAAAAAAAAAAAA---AA------ BBBBBBBBBBBBBB---BB------ BBBBBBBBBBBBBB---BB------ BBBBBBBCCCAAAB---BB------ BBBBBBBCCCAAAB---BB------ BBBBBBBCCCAAAB---BB------ BBBBBBBCCCAAAB---BB------ BBBBBBBCCC-AABBB-BB------ BBBBBBBCCCA--BBBBBB------ BBBBBBBCCCA-ABBBBBB------ DDDDDDDDDDD-DDDDDDD------ DFFFFFEEEECCCDDDDDD------ DFFFFFEEEECCIDDDDDD------ DFFFFFEEEECCIDDDDDD------ DFFFFFEEEECCIDDDDDD------ DKCCCCCCCCCCIDDDDDD------ DGNNMGMGGGMGMNMGGND------ D-----J-J-J-J-----D------ ----------Q-------------- ----------H-------------- ------QOQ---H------------ ------------------------- ------------------------- 
-AAAAAAAAAAAAAAAAA------- -AAAAAAAAAAAAAAAAA------- -AAAAAAAAAAAAAAAAA------- -AAAAAAAAAAAAA---A------- -AAAAAAAAAAAAA---A------- -AAAAAAAAAAAAA---A------- -AAAAAAAAAAAAA---A------- -AAAAAAAAAAAAA---A------- -BBBBBBBBBBBBB---B------- -BBBBBBBBBBBBB---B------- -BBBBBBAAAAAAB---B------- -BBBBBBAAAAAAB---B------- -BBBBBBAAAAAAB---B------- -BBBBBBAAAAAAB--BB------- -BBBBBBAAA-A-BB-BB------- -BBBBBBAAAA--BBBBB------- -BBBBBBCCCC-CBBBBB------- -DDDDDDDDDD-DDDD-D------- -DFFFFCCCCCCCDDDDD------- -DFFFFCCCCCCIDDDDD------- -DFFFFCCCCCCIDDDDD------- -DFFFFCCCCCCIDDDDD------- -DCCCCCCCCCCIDDDDD------- -DGGMMGGGGMMGNGGND------- -D-----J-J-J-----D------- ------------------------- ----------QH------------- ------H----H------------- ------------------------- ------------------------- 
-AAAAAAAAAAAAAAAAA------- -AAAAAAAA-AAAAAAAA------- -AAAAAAAA-AAAAAAAA------- -AAAAAAAAAAAAAA-AA------- -AAAAAAAAAAA----AA------- -AAAAAAAAA------AA------- -AAAAAAAAA------AA------- -AAAAAAAAA------AA------- -BBBBBBBBB------BB------- -BBBBBBBBB------BB------- -BBBBBBAAA------BB------- -BBBBBBAAA------BB------- -BBBBBBAAA------BB------- -BBBBBBAAA------BB------- -BBBBBBAAAA-ABBBBB------- -BBBBBBAAAA--BBBBB------- -BBBBBBCCCC-CBBBBB------- -DDDDDDDDDD-DDDDDD------- -DFFFFCCCCCCCDDDDD------- -DFFFFCCCCCCIDDDDD------- -DFFFFCCCCCCIDDDDD------- -DFFFFCCCCCCIDDDDD------- -DKCCCCCCCCCIDDDDD------- -DGNNNMGGGGMGNGNND------- -D------J-J------D------- ------------------------- ----------O-------------- ------------------------- ------------------------- ------------------------- 
--AAAAAAAAAAAAAAA-------- --AAAAAAAAAAAAAAA-------- --AAAAAAAAAAAAAAA-------- --AAAAAAAAAA--AAA-------- --AAAAAAAAA----AA-------- --AAAAAAAA-----AA-------- --AAAAAAAA-----AA-------- --AAAAAAAA-----AA-------- --BBBBBBBB-----BB-------- --BBBBBBBB-----BB-------- --BB--BAAA-----BB-------- --BB--BAAA-----BB-------- --BB--BAAA-----BB-------- --BB--BAAA-----BB-------- --BB--BAAAAAABBBB-------- --BB--BAAA-A-BBBB-------- --BB--BCCC--CBBBB-------- --DD--DDDD--DDDDD-------- --DF--CCCC--CDDDD-------- --DF--CCCC--IDDDD-------- --DF--CCCC--IDDDD-------- --DF--CCCC--IDDDD-------- --DKCCCCCCCCIDDDD-------- --DGGGGGMGGNNGNND-------- --D------J------D-------- ------------------------- ------------------------- ------------------------- ------------------------- ------------------------- 
---AAAAAAAAAAAAA--------- ---AAAAAAAAAAAAA--------- ---AAAAAAAAAAAAA--------- ---AA----AAA--AA--------- ---AA----AA---AA--------- ---AA---------AA--------- ---AA---------AA--------- ---AA---------AA--------- ---BB---------BB--------- ---BB---------BB--------- ---BB---------BB--------- ---BB---------BB--------- ---BB---------BB--------- ---BB---------BB--------- ---BB------AABBB--------- ---BB------AABBB--------- ---BB-------CBBB--------- ---DD-------DDDD--------- ---DF-------CDDD--------- ---DF--------DDD--------- ---DF--------DDD--------- ---DF--------DDD--------- ---DKCCCCCCCADDD--------- ---DGGGNMNNMGGND--------- ---D-----------D--------- ------------------------- ------------------------- ------------------------- ------------------------- ------------------------- 
----AAAAAAAAAAA---------- ----AAAAAAAAAAA---------- ----AAAAAAAAAAA---------- ----AAA---A-AAA---------- ----AAA-----AAA---------- ----AAA-----AAA---------- ----AAA-----AAA---------- ----AAA-----AAA---------- ----BBB-----BBB---------- ----BBB-----BBB---------- ----BBB-----ABB---------- ----BBB-----ABB---------- ----BBB-----ABB---------- ----BBB-----ABB---------- ----BBB-----ABB---------- ----BBB-----ABB---------- ----BBB-----KBB---------- ----DDD-----DDD---------- ----DDK-----KDD---------- ----DDK-----KDD---------- ----DDK-----KDD---------- ----DDK-----KDD---------- ----DDKCCCCCKDD---------- ----DDGGGNNGGDD---------- ----DD-------DD---------- ------------------------- ------------------------- ------------------------- ------------------------- ------------------------- 
------AAAAAAA------------ ------AAAAAAA------------ ------AAAAAAA------------ ------AAAAAAA------------ ------AAAAAAA------------ ------AAAAAAA------------ ------AAAAAAA------------ ------AAAAAAA------------ ------BBBBBBB------------ ------BBBBBBB------------ ------BBBBBBB------------ ------BBBBBBB------------ ------BBBBBBB------------ ------BBBBBBB------------ ------BBBBBBB------------ ------BBBBBBB------------ ------BBBBBBB------------ ------DDDDDDD------------ ------DDDDDDD------------ ------DDDDDDD------------ ------DDDDDDD------------ ------DDDDDDD------------ ------DDDDDDD------------ ------DDDDDDD------------ ------DDDDDDD------------ ------------------------- ------------------------- ------------------------- ------------------------- ------------------------- 
