model
size = 25 30 19, scale = 0.05, origin = -y
material 
  colors = A:#E00 B:#FF0 C:#CF3 D:#251505 E:#CF0 F:#AAAAB9 G:#EEE H:#BBB I:#960 J:#939 K:#CC6 L:#AAA M:#040 N:#888 O:#FCF
voxels
------AAAAAAA------------ ------AAAAAAA------------ ------AAAAAAA------------ ------AAAAAAA------------ ------AAAAAAA------------ ------AAAAAAA------------ ------AAAAAAA------------ ------AAAAAAA------------ ------BBBBBBB------------ ------BBBBBBB------------ ------BBBBBBB------------ ------BBBBBBB------------ ------BBBBBBB------------ ------BBBBBBB------------ ------BBBBBBB------------ ------BBBBBBB------------ ------BBBBBBB------------ ------AAAAAAA------------ ------AAAAAAA------------ ------AAAAAAA------------ ------AAAAAAA------------ ------AAAAAAA------------ ------AAAAAAA------------ ------AAAAAAA------------ ------AAAAAAA------------ ------------------------- ------------------------- ------------------------- ------L------------------ ------------------------- 
----AAAAAAAAAAA---------- ----AAA---AAAAA---------- ----AAA---AAAAA---------- ----AAA---AAAAA---------- ----AAA---AAAAA---------- ----AAA---AAAAA---------- ----AAA---AAAAA---------- ----AAA--AAAAAA---------- ----BBB--BBBBBB---------- ----BBB--BBBBBB---------- ----BBB--BBBBBB---------- ----BBB-BBBBBBB---------- ----BBBBBBBBBBB---------- ----BBBBBBBBBBB---------- ----BBBBBBBBBBB---------- ----BBBBBBBBBBB---------- ----BBFCCCBBBBB---------- ----AAAAAAAAAAA---------- ----AAFCCCCCFAA---------- ----AAFCCCCCFAA---------- ----AAFCCCCCFAA---------- ----AAFCCCCCFAA---------- ----AAFCCCCCFAA---------- ----AADDDDDDDAA---------- ----AA-------AA---------- ------------------------- ------------------------- ------------------------- ------H------------------ ------H------------------ 
---AAAAAAAAAAAAA--------- ---AAA--------AA--------- ---AAAAAAAAAAAAA--------- ---AAAAAAAAAAAAA--------- ---AAAAAAAAAAAAA--------- ---AAAAAAAAAAAAA--------- ---AAAAAAAAAAAAA--------- ---AAAAAAAAAAAAA--------- ---BBBBBBBBBBBBB--------- ---BBBBBBBBBBBBB--------- ---BBBBBBBBBBBBB--------- ---BBBBBBBBBBBBB--------- ---BBBBBBBBBBBBB--------- ---BBBBBBBBBBBBB--------- ---BBBBBBBBBBBBB--------- ---BBBBBBBBBBBBB--------- ---BFCCCCCBBBBBB--------- ---AAAAAAAAAAAAA--------- ---AFCCCCCCCCCFA--------- ---AFCCCCCCCCCFA--------- ---AFCCCCCCCCCFA--------- ---AFCCCCCCCCCFA--------- ---AFCCCCCCCCCFA--------- ---ADDDDDDIDDDDA--------- ---A-----------A--------- ------------------------- ------------------------- ------------------------- ------------------------- ------HH----------------- 
--AAAAAAAAAAAAAAA-------- --AAAAAAAAAAAAAAA-------- --AAAAAAAAAAAAAAA-------- --AAAAAAAAAAAAAAA-------- --AAAAAAAAAAAAAAA-------- --AAAAAAAAAAAAAAA-------- --AAAAAAAAAAAAAAA-------- --AAAAAAAAAAAAAAA-------- --BBBBBBBBBBBBBBB-------- --BBBB--------BBB-------- --BBBBBBBBBBBBBBB-------- --BBBBBBBBBBBBBBB-------- --BBBBBBBBBBBBBBB-------- --BBBBBBBB-BBBBBB-------- --BBBBBBBB-BBBBBB-------- --BBBBBBBB-BBBBBB-------- --BFCCCCCC-BBBBBB-------- --AAAAAAAA-AAAAAA-------- --AFCCCCCC-CCCCFA-------- --AFCCCCCC-CCCCFA-------- --AFCCCCCC-CCCCFA-------- --AFCCCCCC-CCCCFA-------- --AFCCCCCC-CCCCFA-------- --ADDDDIDIDDIIDDA-------- --A------K------A-------- ------------------------- ------------------------- ------------------------- ---H--------------------- -------H----------------- 
-AAAAAAAAAAAAAAAAA------- -AEAAAAAAAAAAAA-AA------- -AEAAAAAAAAAAAA-AA------- -AEAAAAAAAAAAAA-AA------- -AEAAAAAAAAAAAA-AA------- -AEAAAAAAAAAAAA-AA------- -AEAAAAAAAAAAAA-AA------- -AEAAAAAAAAAAAA-AA------- -BBBAAAAAABBBBB-BB------- -BBBAAAAAABBBBB-BB------- -BB-AAAAAABBBBB-BB------- -BB-AAMMMMBBBBB-BB------- -BB-AACMCMBBBBB-BB------- -BB-AACCCCBBBBB-BB------- -BB-AACCCCBBBBB-BB------- -BBBAACCCCBBBBB-BB------- -BF-CCCCCCBBBBB-BB------- -AA-AAAAAAAAAAA-AA------- -AF-CCCCCCCCCCC-FA------- -AF-CCCCCCCCCCC-FA------- -AF-CCCCCCCCCCC-FA------- -AFBCCCCCCCCCCC-FA------- -AFBCCCCCCCCCCC-FA------- -ADDIDIDIDDIIIDDDA------- -A------K-K------A------- ------------------------- ------------------------- ------------------------- ---H--------------------- ---L---H----------------- 
-AAAAAAAAAAAAAAAAA------- -AEECCAAAAAAAAAAAA------- -AEECCAAAAAAAAAAAA------- -AEECCAAAAAAAAAAAA------- -AEECCAAAAAAAAAAAA------- -AEECCAAAAAAAAAAAA------- -AEECCAAAAAAAAAAAA------- -AEECCAAAAAAAAAAAA------- -BBBAAAAAABBBBBBBB------- -BBBAAAAAABBBBBBBB------- -BBBAAAAAABBBBBBBB------- -BBBAAAAMMBBBBBBBB------- -BBBAAAAMMBBBBBBBB------- -BBBAACCCCBBBBBBBB------- -BBBAACCCCBBBBBBBB------- -BBBAACCCCBBBBBBBB------- -BCCCCCCCCBBBBBBBB------- -AAAAACCCAAAAAAAAA------- -ACCCCCCCCCCCCCCCA------- -ACCCCCCCCCCCCCCCA------- -ACCCCCCCCCCCCCCCA------- -ACCCCCCCCCCCCCCCA------- -ACCCCCCCCCCCCCCCA------- -AIDIIDIDDDIDDIIDA------- -A-----K-K-K-----A------- ------------------------- ------------------------- ------------------------- ------------------------- ---N--HL----------------- 
AAAAAAAAAAAAAAAAAAA------ AEEECCAAAAAAAAAAAAA------ AEEECCAAAAAAAAAAAAA------ AEEECCAAAAAAAAAAAAA------ AEEECCAAAAAAAAAAAAA------ AEEECCAAAAAAAAAAAAA------ AEEECCAAAAAAAAAAAAA------ AEEECCAAAAAAAAAAAAA------ BBBBAAAAAABBBBBBBBB------ BBBBAAAAAABBBBBBBBB------ BBBBAAAAAABBBBBBBBB------ BBBBAAAAAABBBBBBBBB------ BBBBAAAAAABBBBBBBBB------ BBBBAACCCCBBBBBBBBB------ BBBBAACCCCBBBBBBBBB------ BBBBAACCCCBBBBBBBBB------ BFCCCCCCCCBBBBBBBBB------ AAAAAACCCAAAAAAAAAA------ AFCCCCCCCCCCCJJJCFA------ AFCCCCCCCCCCCJJJCFA------ AFCCCCCCCCCCCJJJCFA------ AFCCCCCCCCCCCJJJCFA------ AFCCCCCCCCCCCJJJCFA------ ADDDDDIIDDDDDIIDIDA------ A-----K-K-K-K-----A------ ------------------------- ---------HHH------------- --------LH-HH------------ ----LLLLL---HH----------- ---LL-LL-----H----------- 
AAAAAAAAAAAAAAAAAAA------ AAAAAAAAAAAAAAAAAAA------ AAAAAAAAAAAAAAAAAAA------ AAAAAAAAAAAAAAAAAAA------ AAAAAAAAAAAAAAAAAAA------ AAAAAAAAAAAAAAAAAAA------ A-EEEEAECCCCEAEEEEEAAAAAA A-EEEEAECCCCEAEEEEEAAAAAA B-BBAAAAAABBBBBBBBB-----B B-BBAAAAAABBBBBBBBB-----B B-BBAA--AABBBBBBBBB-----B B-BBAA------BBBBBBB-----B B-BBAA------B--BB-B-----B B-BBAACCCCBBBBBBB-B-----B B-BBAACCCCBBBBBBB-B-----B B-BBAACCCCBBBBBBB-B-----B B-CCCCCCCCBBBBBBB-B-----B A-AAAACCCCGGGJJJC-FAAAAAA A-CCCCCCCCCCCJJJC-FAAAAAA A-CCCCCCCCCCCJJJC-A------ A-CCCCCCCCCCCJJJC-A------ A-CCCCCCCCCCCJJJCCA------ A-CCCCCCCCCCCJJJCCA------ ADDDDDDDDIDDDIDIIDA------ A----K-K-K-K-K----A------ ------------------------- ---------HHH------------- ------------------------- ----LHH------------------ ------------------------- 
AAAAAAAAAAAAAAAAAAA------ AAAAAAAAAAAAAAAAAAA------ AAAAAAAAAAAAAAAAAAA------ AAAAAAAAAAAAAAAAAAA------ AAAAAAAAAAAAAAAAAAA------ AAAAAAAAAAAAAAAAAAA------ A-EEEEAECCCCEAEEEEAAAAAAA A-EEEEAECCCCEAEEEEAAAAAAA B-BBAAAAAABBBBBBBBB-----B B-BBAAAAAABBBBBBBBB-----B B-BBAA--AABBBBBBBBB-----B B-BBAA------BBBBBBB-----B B-BBAA------B-BBB-B-----B B-BBAACCCCBBBBBBB-B-----B B-BBAACCCCBBBBBBB-B-----B B-BBAACCCCBBBBBBB-B-----B B-CCCCCCCCBBBBBBB-B-----B A-AAAACCCCGGGJJJC-FAAAAAA A-CCCCCCCCCCCJJJC-FAAAAAA A-CCCCCCCCCCCJJJC-A------ A-CCCCCCCCCCCJJJC-A------ A-CCCCCCCCCCCJJJCCA------ A-CCCCCCCCCCCJJJCCA------ ADDDDDDIDDDDDDDDDDA------ A---K-K-K-K-K-K---A------ ------------------------- ---------HHH------------- --------LH-HH------------ ----LLLOL---HH----------- ---LL-HH-----H----------- 
AAAAAAAAAAAAAAAAAAA------ AAAAAAAAAAAAAAAAAAA------ AAAAAAAAAAAAAAAAAAA------ AAAAAAAAAAAAAAAAAAA------ AAAAAAAAAAAAAAAAAAA------ AAAAAAAAAAAAAAAAAAA------ A-EEEEEEACAAAAEEEEAAAAAAA A-EEEEEECCAAAAEEEEAAAAAAA B-BBAAACCCBBBBBBBBB-----B B-BBAAACCCBBBBBBBBB-----B B-BBAAACCCBBBBBBBBB-----B B-BBAAACCCBBBBBBBBB-----B B-BBAAACCCBBBBBBB-B-----B B-BBAAACCCBBBBBBB-B-----B B-BBAAACCCBBBBBBB-B-----B B-BBAAACCCBBBBBBB-B-----B B-CCCCCCCCBBBBBBB-B-----B A-AAAACCCCGGGGCCC-FAAAAAA A-CCCCGGGGCCCCCCC-FAAAAAA A-CCCCGGGGCCECCCC-A------ A-CCCCGGGGCCECCCC-A------ A-CCCCGGGGCCECCCCCA------ A-CCCCCCCCCCEECCCCA------ ADIDDDDDDIIDDDDIDDA------ A--K-K-K-K-K-K-K--A------ ---------HHL------------- --------HH-HH------------ -------HH--HHH----------- -----N-H----HH----------- -------H----------------- 
AAAAAAAAAAAAAAAAAAA------ AAAAAAAAAAAAAAAAAAA------ AAAAAAAAAAAAAAAAAAA------ AAAAAAAAAAAAAAAAAAA------ AAAAAAAAAAAAAAAAAAA------ AAAAAAAAAAAAAAAAAAA------ A-EEEEEEACAAAAEEEEAAAAAAA A-EEEEEECCAAAAEEEEAAAAAAA B-BBAAACCCBBBBBBBBB-----B B-BBAAACCCBBBBBBBBB-----B B-BBAAACCCBBBBBBBBB-----B B-BBAAACCCBBBBBBBBB-----B B-BBAAACCCBBBBBBB-B-----B B-BBAAACCCBBBBBBB-B-----B B-BBAAACCC-BBBBBB-B-----B B-BBAAACCCB---BBB-B-----B B-CCCCCCCCB-B-BBB-B-----B A-AAAACCCCC-C-CCC-FAAAAAA A-CCCCGGGGCCCCCCC-FAAAAAA A-CCCCGGGGCCECCCC-A------ A-CCCCGGGGCCECCCC-A------ A-CCCCGGGGCCECCCCCA------ A-CCCCCCCCCCEECCCCA------ ADDIIDDIDDDIDDDDDDA------ A---K-K-K-K-K-K---A------ ---------HHH------------- ------------------------- ------------------------- -----H------------------- ------------------------- 
AAAAAAAAAAAAAAAAAAA------ AAAAAAAAAAAAAAAAAAA------ AAAAAAAAAAAAAAAAAAA------ AAAAAAAAAAAAAAAAAAA------ AAAAAAAAAAAAAAAAAAA------ AAAAAAAAAAAAAAAAAAA------ A-EEEEEEACAAAAEEEAA------ A-EEEEEECCAAAAEEEAA------ B-BBAAACCCBBBBBBBBB------ B-BBAAACCCBBBBBBBBB------ B-BBAAACCCBBBBBBBBB------ B-BBAAACCCBBBBBBBBB------ B-BBAAACCCBBBBBBB-B------ B-BBAAACCCBBBBBBB-B------ B-BBAAACCC-B-BBBB-B------ B-BBAAACCCB---BBB-B------ B-CCCCCCCCB-B-BBB-B------ A-AAAAAAAAA-A-AAA-A------ A-CCCCGGGGCCCCCCC-A------ A-CCCCGGGGCCECCCC-A------ A-CCCCGGGGCCECCCC-A------ A-CCCCGGGGCCECCCCCA------ A-CCCCCCCCCCEECCCCA------ ADDDIDDDIDDDDDDDDDA------ A----K-K-K-K-K----A------ ---------LLL------------- --------LL-HH------------ -------LLH--LH----------- -------L-----L----------- ------------------------- 
AAAAAAAAAAAAAAAAAAA------ AAAAAAAAAAAAAAAAAAA------ AAAAAAAAAAAAAAAAAAA------ AAAAAAAAAAAAAA---AA------ AAAAAAAAAAAAAA---AA------ AAAAAAAAAAAAAA---AA------ AAAAAAEEACAAAA---AA------ AAAAAAEECCAAAA---AA------ BBBBAAACCCBBBB---BB------ BBBBAAACCCBBBB---BB------ BBBBAAACCCBBBB---BB------ BBBBAAACCCBBBB---BB------ BBBBAAACCCBBBB---BB------ BBBBAAACCCBBBB---BB------ BBBBAAACCC-BBBBB-BB------ BBBBAAACCCB--BBBBBB------ BFCCCCCCCCB-BBBBBBB------ AAAAAAAAAAA-AAAAAAA------ AFCCCCGGGGCCCCCCCFA------ AFCCCCGGGGCCECCCCFA------ AFCCCCGGGGCCECCCCFA------ AFCCCCGGGGCCECCCCFA------ AFCCCCCCCCCCECCCCFA------ ADDDIDIDDDIDIDIDIDA------ A-----K-K-K-K-----A------ ----------N-------------- ----------H-------------- ------NLN---H------------ ------------------------- ------------------------- 
-AAAAAAAAAAAAAAAAA------- -AAAAAAAAAAAAAAAAA------- -AAAAAAAAAAAAAAAAA------- -AAAAAAAAAAAAA---A------- -AAAAAAAAAAAAA---A------- -AAAAAAAAAAAAA---A------- -AAAAAAAAAAAAA---A------- -AAAAAAAAAAAAA---A------- -BBBBBBBBBBBBB---B------- -BBBBBBBBBBBBB---B------- -BBBBBBBBBBBBB---B------- -BBBBBBBBBBBBB---B------- -BBBBBBBBBBBBB---B------- -BBBBBBBBBBBBB--BB------- -BBBBBBBBB-B-BB-BB------- -BBBBBBBBBB--BBBBB------- -BCCCCCCCCC-CCCCCB------- -AAAAAAAAAA-AAAA-A------- -ACCCCCCCCCCCCCCBA------- -ACCCCCCCCCCECCCBA------- -ACCCCCCCCCCECCCBA------- -ACCCCCCCCCCECCCBA------- -ACCCCCCCCCCECCCBA------- -ADDIIDDDDIIDDIDDA------- -A-----K-K-K-----A------- ------------------------- ----------NH------------- ------H----H------------- ------------------------- ------------------------- 
-AAAAAAAAAAAAAAAAA------- -AAAAAAAA-AAAAAAAA------- -AAAAAAAA-AAAAAAAA------- -AAAAAAAAAAAAAA-AA------- -AAAAAAAAAAA----AA------- -AAAAAAAAA------AA------- -AAAAAAAAA------AA------- -AAAAAAAAA------AA------- -BBBBBBBBB------BB------- -BBBBBBBBB------BB------- -BBBBBBBBB------BB------- -BBBBBBBBB------BB------- -BBBBBBBBB------BB------- -BBBBBBBBB------BB------- -BBBBBBBBBB-BBBBBB------- -BBBBBBBBBB--BBBBB------- -BFCCCCCCCC-CCCCFB------- -AAAAAAAAAA-AAAAAA------- -AFCCCCCCCCCCCCCFA------- -AFCCCCCCCCCECCCFA------- -AFCCCCCCCCCECCCFA------- -AFCCCCCCCCCECCCFA------- -AFCCCCCCCCCECCCFA------- -ADDDDIDDDDIDIDDDA------- -A------K-K------A------- ------------------------- ----------L-------------- ------------------------- ------------------------- ------------------------- 
--AAAAAAAAAAAAAAA-------- --AAAAAAAAAAAAAAA-------- --AAAAAAAAAAAAAAA-------- --AAAAAAAAAA--AAA-------- --AAAAAAAAA----AA-------- --AAAAAAAA-----AA-------- --AAAAAAAA-----AA-------- --AAAAAAAA-----AA-------- --BBBBBBBB-----BB-------- --BBBBBBBB-----BB-------- --BB--BBBB-----BB-------- --BB--BBBB-----BB-------- --BB--BBBB-----BB-------- --BB--BBBB-----BB-------- --BB--BBBBBBBBBBB-------- --BB--BBBB-B-BBBB-------- --BF--CCCC--CCCFB-------- --AA--AAAA--AAAAA-------- --AF--CCCC--CCCFA-------- --AF--CCCC--ECCFA-------- --AF--CCCC--ECCFA-------- --AF--CCCC--ECCFA-------- --AFCCCCCCCCECCFA-------- --ADDDDDIDDDDDDDA-------- --A------K------A-------- ------------------------- ------------------------- ------------------------- ------------------------- ------------------------- 
---AAAAAAAAAAAAA--------- ---AAAAAAAAAAAAA--------- ---AAAAAAAAAAAAA--------- ---AA----AAA--AA--------- ---AA----AA---AA--------- ---AA---------AA--------- ---AA---------AA--------- ---AA---------AA--------- ---BB---------BB--------- ---BB---------BB--------- ---BB---------BB--------- ---BB---------BB--------- ---BB---------BB--------- ---BB---------BB--------- ---BB------BBBBB--------- ---BB------BBBBB--------- ---BB-------CCFB--------- ---AA-------AAAA--------- ---AF-------CCFA--------- ---AF--------CFA--------- ---AF--------CFA--------- ---AF--------CFA--------- ---AFCCCCCCCBCFA--------- ---ADDDDIDDIDDDA--------- ---A-----------A--------- ------------------------- ------------------------- ------------------------- ------------------------- ------------------------- 
----AAAAAAAAAAA---------- ----AAAAAAAAAAA---------- ----AAAAAAAAAAA---------- ----AAA---A-AAA---------- ----AAA-----AAA---------- ----AAA-----AAA---------- ----AAA-----AAA---------- ----AAA-----AAA---------- ----BBB-----BBB---------- ----BBB-----BBB---------- ----BBB-----BBB---------- ----BBB-----BBB---------- ----BBB-----BBB---------- ----BBB-----BBB---------- ----BBB-----BBB---------- ----BBB-----BBB---------- ----BBF-----FBB---------- ----AAA-----AAA---------- ----AAF-----FAA---------- ----AAF-----FAA---------- ----AAF-----FAA---------- ----AAF-----FAA---------- ----AAFCCCCCFAA---------- ----AADDDDDDDAA---------- ----AA-------AA---------- ------------------------- ------------------------- ------------------------- ------------------------- ------------------------- 
------AAAAAAA------------ ------AAAAAAA------------ ------AAAAAAA------------ ------AAAAAAA------------ ------AAAAAAA------------ ------AAAAAAA------------ ------AAAAAAA------------ ------AAAAAAA------------ ------BBBBBBB------------ ------BBBBBBB------------ ------BBBBBBB------------ ------BBBBBBB------------ ------BBBBBBB------------ ------BBBBBBB------------ ------BBBBBBB------------ ------BBBBBBB------------ ------BBBBBBB------------ ------AAAAAAA------------ ------AAAAAAA------------ ------AAAAAAA------------ ------AAAAAAA------------ ------AAAAAAA------------ ------AAAAAAA------------ ------AAAAAAA------------ ------AAAAAAA------------ ------------------------- ------------------------- ------------------------- ------------------------- ------------------------- 
