model
size = 8 32 17, scale = 0.05, origin = -y
material 
  colors = A:#F7D94C B:#52433D
voxels
11-2(2B6-)2B229-4A3(4-A2-A)4-4A220-4A3-3(A4-A2-)A4-A3-4A211-6A2(2-A4-A)-A5-2(A2-A4-)A3-4A189-2B6-2B4-6A2-A4-A-A3(6-2A)6-A-A4-A3-5A180-2B6-2B4-6A2-A4-A-A4(6-2A)6-A-A4-A3-4A165-2(2B6-)2B5-4A3-A4-A-A5(6-2A)6-A-A4-A3-5A4-2A118-4(2A6-)2B6-2B13-4A3-A4-A-A6(6-2A)6-A-A4-A2(2-2A)3-4A84-4A4-4A3-6A6(2-2A)3-A2-A5-2B6-2B20-6A2-A4-A-A6(6-2A)6-A-2(A4-A2-)6A3-4A4-4A5-A23-2A5-4A4-4A3-6A7(2-A4-A)3-4A28-4A3-A4-A-A9(6-2A)6-A-2(A4-A2-)2A-3A2(2-6A)2(2-2A)2(2-A4-A)-A4(6-2A)6-A-2(A4-A2-)A3-2A3-3A37-4A3-A4-A-A21(6-2A)6-A-A4-A2-A4-A3-4A52-4A3-A4-A2-A5-20(2A6-)A-A4-A2(2-2A)4-2A61-4A3-A4-A2-A4-A-A17(6-2A)6-A-A4-A2-A4-A3-4A76-4A3-2(2A2-)A4-A2-A4-A-A14(6-2A)6-A-A4-A2(2-2A)3-4A93-2A5-4A3-2(2A2-)A4-A2-A4-A-A10(6-2A)6-A-A4-A2(2-2A)3-4A5-2A118-2A5-4A4-4A3-2(2A2-)8(A4-A2-)2(2A2-)6A3-4A5-2A158-2A5-7(4A4-)4A5-2A91-
