model
size = 22 32 17, scale = 0.05, origin = -y
material 
  colors = A:#FEEA41 B:#8E695F C:#000 D:#FFF E:#FFD240
voxels
31-4B17-2(2B2-2B16-)6B17-4B85-2A20-2A501-8B13-4B2C4B11-5B2C5B10-4BC2BC4B11-4B2C4B12-10B13-8B16-4A18-A2EA2(18-4A)35-4D6-4D8-2DCD6-DC2D3(8-4A6-4A)318-10B11-12B10-12B9-2(14B8-)14B9-12B10-12B11-3B4A3B15-2(4A18-)4A13-4D6-4D7-2(6D4-6D6-)2(2A2D2A4-2A2D2A6-)6A4-6A7-4A6-4A295-12B9-14B8-14B7-16B5-18B5-16B7-14B8-14B9-12B11-10B15-4A13-4D-4A-4D7-6D4-6D2(6-7D2-7D)3(6-A4D2A2-2A4DA)6-6A4-6A7-4A6-4A272-14B8-14B7-16B5-2(18B4-)18B5-3(16B6-)3A10B3A3-9AB2AB10A-A6D4A6DA-3A2(8D2A)2-2(18D4-)2(A6D4A6DA4-)A6D4A6DA5-A4D6A4DA5(6-16A)7-14A9-12A11-B8-B12-2B6-2B13-8B77-14B7-16B5-4(18B4-)18B5-16B5-3A12B3A4-3A12B3A2-7A8B8AE18AE23A2-10(18A4-)18A5-16A7-14A9-12A119-14B7-16B5-4(18B4-)18B5-16B5-2(3A12B3A4-)5A8B5A14(4-18A)5-16A7-14A118-14C7-16C5-4(18C4-)18C5-16C5-16(18C4-)18C5-16C7-14C9-7(C10-)C11-10C9-16C5-18C3-22(20C2-)20C3-18C5-16C7-2C10-2C9-5(C10-)C11-10C10-14C7-16C5-4(18C4-)18C5-16C5-16(18C4-)18C5-16C7-14C9-7(C10-)C11-10C10-14B7-16B5-4(18B4-)18B5-16B5-2(3A12B3A4-)5A8B5A14(4-18A)5-16A7-14A118-14B7-16B5-4(18B4-)18B5-16B5-3A12B3A4-3A12B3A2-7A8B8AE18AE23A2-10(18A4-)18A5-16A7-14A9-12A119-14B8-14B7-16B5-2(18B4-)18B5-3(16B6-)3A10B3A3-9AB2AB10A-A6D4A6DA-3A2(8D2A)2-2(18D4-)2(A6D4A6DA4-)A6D4A6DA5-A4D6A4DA5(6-16A)7-14A9-12A11-B8-B12-2B6-2B13-8B78-12B9-14B8-14B7-16B5-18B5-16B7-14B8-14B9-12B11-10B15-4A13-4D-4A-4D7-6D4-6D2(6-7D2-7D)3(6-A4D2A2-2A4DA)6-6A4-6A7-4A6-4A274-10B11-12B10-12B9-2(14B8-)14B9-12B10-12B11-3B4A3B15-2(4A18-)4A13-4D6-4D7-2(6D4-6D6-)2(2A2D2A4-2A2D2A6-)6A4-6A7-4A6-4A319-8B13-4B2C4B11-5B2C5B10-4BC2BC4B11-4B2C4B12-10B13-8B16-4A18-A2EA2(18-4A)35-4D6-4D8-2DCD6-DC2D3(8-4A6-4A)343-4B17-2(2B2-2B16-)6B17-4B85-2A20-2A472-
