model
size = 16 24 30, scale = 0.05, origin = -y
material 
  colors = A:#D7C4BB B:#EEE C:#9E7A7A D:#0F4C3A E:#F7D94C F:#B19693 G:#4F726C
voxels
---------------- ---------------- ---------------- ---------------- ---------------- ---------------- ---------------- ---------------- ---------------- ---------------- ---------------- ---------------- ---------------- ---------------- ---------------- ---------------- ---------------- ---------------- ---------------- ------EEEE------ ---------------- ---------------- ---------------- ---------------- 
---------------- ---------------- ---------------- ---------------- ---------------- ---------------- -------CC------- ------CCCC------ ------CCCC------ ------CCCC------ -------CC------- ---------------- ---------------- ---------------- ---------------- ---------------- ---------------- ---------------- ---------------- ------EEEE------ -------EE------- ---------------- ---------------- ---------------- 
---------------- ---------------- ---------------- ---------------- ---------------- -----CCCCCC----- ----CCCAACCC---- ----CC----CC---- ----CC----CC---- -----C----C----- -----CC--CC----- ------CCCC------ -------FF------- ---------------- ---------------- ---------------- ---------------- ---------------- ---------------- ------EEEE------ -------EE------- ---------------- ---------------- ---------------- 
---------------- ---------------- ---------------- ------AAAA------ ----AAAAAAAA---- ---AA------AA--- ---A--------A--- ---A--------A--- ---A--------A--- ----A------A---- ----A------A---- -----C----C----- ------F--F------ ------FFFF------ ---------------- ---------------- ---------------- ---------------- ---------------- ------EEEE------ ------E--E------ ------EEEE------ ---------------- ---------------- 
---------------- ---------------- -----BBBBBB----- ----BB----BB---- ---A--------A--- --A----------A-- --A----------A-- --A----------A-- --A----------A-- ---A--------A--- ----A------A---- ----A------A---- -----C----C----- ------F--F------ ------BBBB------ ---------------- ---------------- ---------------- ---------------- ------EEEE------ ------D--D------ ------D--D------ -------DD------- ---------------- 
---------------- ------BBBB------ ---AAA----AAA--- --AA--------AA-- --A----------A-- -BA-----------B- -B------------B- --A----------A-- --A----------A-- --A----------A-- ---B--------B--- ----A------A---- -----C----C----- ------F--F------ ------B--B------ ------GGGG------ ------DDDD------ ---------------- ---------------- -----DEEEED----- -----D----D----- ------D--D------ ------D--D------ ------DDDD------ 
---------------- ----AAAAAAAA---- --AA--------AA-- --A----------A-- -B------------B- -B------------A- -A------------A- -B------------B- -B------------B- --A----------A-- ---B--------B--- ----A------A---- -----C----C----- -----C----C----- ------B--B------ ------G--G------ ------D--D------ ------DDDD------ ------DDDD------ -----D----D----- -----D----D----- -----D----D----- ------D--D------ ------DDDD------ 
------BBBB------ ---AAA----AAA--- --A----------A-- -A------------A- -A------------A- -A------------A- -A------------A- -A------------A- -A------------A- --A----------A-- --BB--------BB-- ----A------A---- -----C----C----- -----C----C----- ------B--B------ ------G--G------ ------D--D------ ------D--D------ -----D----D----- -----D----D----- -----D----D----- -----D----D----- ------D--D------ ------DDDD------ 
---AAAAAAAAAA--- --A----------A-- -A------------A- -A------------A- B--------------B B--------------B B--------------B -A------------A- -A------------A- -A------------A- --B----------B-- ---AA------AA--- -----C----C----- ------A--A------ ------BBBB------ ------G--G------ ------D--D------ ------D--D------ -----D----D----- -----D----D----- -----D----D----- -----D----D----- ------D--D------ ------DDDD------ 
--AAA------AAA-- -A------------A- -A------------A- B--------------B B--------------B B--------------B B--------------B B--------------B -A------------A- -A------------A- --B----------B-- ---AA------AA--- -----CA--AC----- -------BB------- ---------------- -------GG------- ------DDDD------ ------DDDD------ ------D--D------ -----DD---D----- -----D----D----- -----DD--DD----- ------DDDD------ -------DD------- 
--A----------A-- -A------------A- B--------------B B--------------B B--------------B B--------------B B--------------B B--------------B -C------------A- -A------------A- --B----------B-- ---AAA----AAA--- ------AAAA------ ---------------- ---------------- ---------------- ---------------- ---------------- -------DD------- -------DDD------ ------DDDD------ -------DD------- ---------------- ---------------- 
-AA-----------A- B--------------B B--------------B B--------------B B--------------B B--------------B B--------------B B--------------B C--------------C -A------------A- --B----------B-- ---AAA----AAA--- ------AAAA------ ---------------- ---------------- ---------------- ---------------- ---------------- ---------------- ---------------- ---------------- ---------------- ---------------- ---------------- 
-A------------A- B--------------B B--------------B B--------------B B--------------B B--------------B B--------------B C--------------C -A------------A- -A------------A- --BB--------BB-- ----AAAAAAAA---- ---------------- ---------------- ---------------- ---------------- ---------------- ---------------- ---------------- ---------------- ---------------- ---------------- ---------------- ---------------- 
-A------------A- B--------------B B--------------B B--------------B B--------------B B--------------B C--------------B C--------------C -A------------A- -A------------A- --BB--------BB-- ----BBBAABBB---- ---------------- ---------------- ---------------- ---------------- ---------------- ---------------- ---------------- ---------------- ---------------- ---------------- ---------------- ---------------- 
-A------------A- B--------------B B--------------B B--------------B B--------------B B--------------B C--------------C -A------------A- -A------------A- --A----------A-- ---BBBB--BBBB--- -------CC------- ---------------- ---------------- ---------------- ---------------- ---------------- ---------------- ---------------- ---------------- ---------------- ---------------- ---------------- ---------------- 
-A------------A- B--------------B B--------------B B--------------B B--------------B C--------------C -A------------A- -A------------A- --A----------A-- --AA--------AA-- ----BBBAABBB---- ---------------- ---------------- ---------------- ---------------- ---------------- ---------------- ---------------- ---------------- ---------------- ---------------- ---------------- ---------------- ---------------- 
-A------------A- B--------------B B--------------B B--------------B C--------------C -A------------A- -A------------A- -A------------A- --A----------A-- ---BBAA--AABB--- -------CC------- ---------------- ---------------- ---------------- ---------------- ---------------- ---------------- ---------------- ---------------- ---------------- ---------------- ---------------- ---------------- ---------------- 
-A------------A- -A------------A- -A------------A- -C------------C- -C------------C- -A------------A- -A------------A- --A----------A-- ---BA------AB--- -----CCCCCC----- ---------------- ---------------- ---------------- ---------------- ---------------- ---------------- ---------------- ---------------- ---------------- ---------------- ---------------- ---------------- ---------------- ---------------- 
-A------------A- -A------------A- -A------------A- -C------------C- -C------------C- --A----------A-- --A----------A-- ---B--------B--- ----AAAAAAAA---- ---------------- ---------------- ---------------- ---------------- ---------------- ---------------- ---------------- ---------------- ---------------- ---------------- ---------------- ---------------- ---------------- ---------------- ---------------- 
--A----------A-- -A------------A- -C------------A- --A----------C-- --A----------A-- --A----------A-- ---B--------B--- ----AA----AA---- ------CCCC------ ---------------- ---------------- ---------------- ---------------- ---------------- ---------------- ---------------- ---------------- ---------------- ---------------- ---------------- ---------------- ---------------- ---------------- ---------------- 
--A----------A-- --C----------A-- --A----------C-- --A----------A-- --A----------A-- ---B--------B--- ----B------B---- -----CCCCCC----- ---------------- ---------------- ---------------- ---------------- ---------------- ---------------- ---------------- ---------------- ---------------- ---------------- ---------------- ---------------- ---------------- ---------------- ---------------- ---------------- 
--A----------A-- --A----------A-- --A----------A-- --A----------A-- ---B--------B--- ---B--------B--- ----BBBBBBBB---- ---------------- ---------------- ---------------- ---------------- ---------------- ---------------- ---------------- ---------------- ---------------- ---------------- ---------------- ---------------- ---------------- ---------------- ---------------- ---------------- ---------------- 
---BCCCCCCCCB--- ---B--------B--- ---B--------B--- ---B--------B--- ---B--------B--- ----B------B---- -----BBBBBB----- ---------------- ---------------- ---------------- ---------------- ---------------- ---------------- ---------------- ---------------- ---------------- ---------------- ---------------- ---------------- ---------------- ---------------- ---------------- ---------------- ---------------- 
---BCCCCCCCCB--- ---B--------B--- ---B--------B--- ---B--------B--- ---B--------B--- ----BBBBBBBB---- ---------------- ---------------- ---------------- ---------------- ---------------- ---------------- ---------------- ---------------- ---------------- ---------------- ---------------- ---------------- ---------------- ---------------- ---------------- ---------------- ---------------- ---------------- 
----ACCCCCCA---- ----A------A---- ----A------A---- ---B--------B--- ----A------A---- -----BBBBBB----- ---------------- ---------------- ---------------- ---------------- ---------------- ---------------- ---------------- ---------------- ---------------- ---------------- ---------------- ---------------- ---------------- ---------------- ---------------- ---------------- ---------------- ---------------- 
----ACCCCCCA---- ----A------A---- ----A------A---- ----C------C---- -----BBBBBB----- ---------------- ---------------- ---------------- ---------------- ---------------- ---------------- ---------------- ---------------- ---------------- ---------------- ---------------- ---------------- ---------------- ---------------- ---------------- ---------------- ---------------- ---------------- ---------------- 
-----CCCCCC----- -----A----A----- ----A------A---- ----CC----CC---- ------BBBB------ ---------------- ---------------- ---------------- ---------------- ---------------- ---------------- ---------------- ---------------- ---------------- ---------------- ---------------- ---------------- ---------------- ---------------- ---------------- ---------------- ---------------- ---------------- ---------------- 
-----CCCCCC----- -----A----A----- -----A----A----- -----CCCCCC----- ---------------- ---------------- ---------------- ---------------- ---------------- ---------------- ---------------- ---------------- ---------------- ---------------- ---------------- ---------------- ---------------- ---------------- ---------------- ---------------- ---------------- ---------------- ---------------- ---------------- 
------CCCC------ ------A--A------ ------CCCC------ ------CCCC------ ---------------- ---------------- ---------------- ---------------- ---------------- ---------------- ---------------- ---------------- ---------------- ---------------- ---------------- ---------------- ---------------- ---------------- ---------------- ---------------- ---------------- ---------------- ---------------- ---------------- 
-------CC------- ------CCCC------ ---------------- ---------------- ---------------- ---------------- ---------------- ---------------- ---------------- ---------------- ---------------- ---------------- ---------------- ---------------- ---------------- ---------------- ---------------- ---------------- ---------------- ---------------- ---------------- ---------------- ---------------- ---------------- 
