model
size = 32 32 7, scale = 0.05, origin = -y
material 
  colors = A:#FFF B:#100 C:#999 D:#666 E:#111 F:#001 G:#BBB H:#555 I:#333 J:#444 K:#DDD L:#777 M:#222 N:#EEE
voxels
651-21B10-B20AB10-B3A2B4A2B2(3AB)AB10-B4(2AE)2AKBABKAB10-B4(2AE)3ALBL2AB10-B4(2AE)3AKBK2AB10-B2(2AE)2AB2AM2AKBNBKAB10-B2(2AE)3AE2(B3A)BAB10-B20AB11-21B715-21B10-B20AB10-B3A2B3AD3B2AB3ABAB10-B2AJ2AH2AI2AJ2ADIABNAB10-3(B2A)J2A2G2AD2B2AB-6E3-B3(2AH)2ALC2A2BD2AB-B4AE3-BACH2AD2AB2AM2ABDAIDAB-2B3AE3-B2AD2AL3AJB3AI3ABAB2-2B2AE3-B20AB3-2BAE4-21B4-3B57-26B19(6-B24AB)6-B10AD14C7BAK7AC20A2B9AC3A2B3AD3B2AB3ABA2B2(AK)5AC2AJ2AH2AI2AJ2ADIABDA2B9AC2(2AB)2AJ2A2G2ADBG2A3B4EB3AC3(2AH)2ALC2A2BD2A3B4AE3ACACH2AD2AB2AM2ABDAIDAB-2B3AE3AC2AD2AL3AJB3AI3ABAB2-2B2AE3AC20AB3-2BAE4A21B4-3B18AB11-21B6-26B2(6-B24AB)6-B14AG9AB6-B8ALCAC2AD9AB6-B8AD6AC8AB6-B8AG5ACL8AB6-B6AMAH4M3AF7AB6-B5AGMAL6AF-3F4AB6-BF7AL5AF5-F3AB6-B-F4AGA2F3AF7-F2AB6-B2-F4AFG-FAF9-FAB6-B3-FA2F-G2-F5-2F4-AB6-B4-F3G-6G2-FAF3-AB6-BF5-2G2-G4-KF3A3FAB6-BAF6-F4-3F8AB6-B2A2F3-FDF2-FCM9AB6-B4A3FAHG2FM2AG8A2(B6-B24A)B6-B10AD14C7BAC7AC20A2B9AC3A2B3AD3B2AB3ABA2B2(AD)5AC2AJ2AH2AI2AJ2ADIABDA2B9AC2(2AB)2AJ2A2G2ADBG2A8B3AC3(2AH)2ALC2A2BD2A3B4AB3ACACH2AD2AB2AM2ABDAIDAB-2B3AB3AC2AD2AL3AJB3AI3ABAB2-2B2AB3AC20AB3-2BAB4A21B4-3B18AB11-21B6-26B19(6-B24AB)6-B10AD14C7BAK7AC20A2B9AC3A2B3AD3B2AB3ABA2B2(AK)5AC2AJ2AH2AI2AJ2ADIABDA2B9AC2(2AB)2AJ2A2G2ADBG2AB7-3AC3(2AH)2ALC2A2BD2AB7-3ACACH2AD2AB2AM2ABDAIDAB7-3AC2AD2AL3AJB3AI3ABAB7-3AC20AB7-4A21B7-18AB13-19B657-21B10-B20AB10-B3A2B3AD3B2AB3ABAB10-B2AJ2AH2AI2AJ2ADIABDAB10-3(B2A)J2A2G2ADBG2AB10-B3(2AH)2ALC2A2BD2AB10-BACH2AD2AB2AM2ABDAIDAB10-B2AD2AL3AJB3AI3ABAB10-B20AB11-21B715-21B10-B20AB10-BA2(B3A)2B4A2B3AB10-BAKBABK4(2AE)2AB10-B2ALBL3A4(E2A)B10-B2AKBK3A4(E2A)B10-BAKBNBK2AM2AB2(2AE)2AB10-BA2(B3A)BE3A2(B2A)B10-B20AB11-21B64-
