model
size = 12 30 12, scale = 0.05, origin = -y
material 
  colors = A:#08082F B:#1D1D56 C:#100 D:#003 E:#F90 F:#FC0 G:#F60 H:#FC3 I:#700 J:#500 K:#400
voxels
------------ ------------ ----EEEE---- -----EE----- ------------ ----G--G---- -----GG----- -----GG----- ----G--G---- ------------ ------------ ----J--J---- ----J--J---- ------------ ------------ ----J--J---- ----J--J---- ------------ ------------ ----G--G---- -----GG----- -----GG----- ----G--G---- ------------ -----EE----- ----EEEE---- ------------ ------------ ------------ ------------ 
---IIIIII--- ---BBBBBB--- ---BBBBBB--- ---BDBBDB--- ---BBBBBB--- ---BBBBBB--- ---BDBBDB--- ---BDBBDB--- ---BBBBBB--- ---BDBBDB--- ---BDBBDB--- ---BBBBBB--- ---BBBBBB--- ---BDBBDB--- ---BDBBDB--- ---BBBBBB--- ---BBBBBB--- ---BDBBDB--- ---BDBBDB--- ---BBBBBB--- ---BDBBDB--- ---BDBBDB--- ---BBBBBB--- ---BBBBBB--- ---BDBBDB--- ---BBBBBB--- ---BBBBBB--- ---BBBBBB--- ----BBBB---- ------------ 
----DDDD---- --IBDDDDBI-- --BBDDDDBB-- --BBDDDDBB-- --BBDDDDBB-- --BBDDDDBB-- --BBDDDDBB-- --BBDDDDBB-- --BBDDDDBB-- --BBDDDDBB-- --BBDDDDBB-- --BBDDDDBB-- --BBDDDDBB-- --BBDDDDBB-- --BBDDDDBB-- --BBDDDDBB-- --BBDDDDBB-- --BBDDDDBB-- --BBDDDDBB-- --BBDDDDBB-- --BBDDDDBB-- --BBDDDDBB-- --BBDDDDBB-- --BBDDDDBB-- --BBDDDDBB-- --BBDDDDBB-- --BBDDDDBB-- ---BDDDDB--- ---EDDDDE--- ----EEEE---- 
------------ --AA----AA-- -KAA----AAK- -AAA----AAA- -AAA----AAA- -AAA----AAA- -AAA----AAA- HAAA----AAAH HAAA----AAAH -AAA----AAA- -AAA----AAA- -AAA----AAA- -AAA----AAA- -AAA----AAA- -AAA----AAA- -AAA----AAA- -AAA----AAA- -AAA----AAA- -AAA----AAA- -AAA----AAA- HAAA----AAAH HAAA----AAAH HAAA----AAAH -AAA----AAA- -AAA----AAA- -AAA----AAA- --AA----AA-- --EA----AE-- ---E----E--- ------------ 
------------ ------------ -KA------AK- -AA------AA- -AA------AA- -AA------AA- FAA------AAF FAA------AAF FAA------AAF FAA------AAF -AA------AA- -AA------AA- -AA------AA- -AA------AA- -AA------AA- -AA------AA- -AA------AA- -AA------AA- -AA------AA- FAA------AAF FAA------AAF FAA------AAF FAA------AAF FAA------AAF -AA------AA- -AA------AA- -EA------AE- --E------E-- ------------ ------------ 
------------ ------------ ------------ ------------ ------------ ------------ -C--------C- -C--------C- -C--------C- ------------ ------------ ------------ ------------ ------------ ------------ ------------ ------------ ------------ ------------ -C--------C- -C--------C- -C--------C- -C--------C- ------------ ------------ ------------ ------------ ------------ ------------ ------------ 
------------ ------------ ------------ ------------ ------------ ------------ -C--------C- -C--------C- -C--------C- ------------ ------------ ------------ ------------ ------------ ------------ ------------ ------------ ------------ ------------ -C--------C- -C--------C- -C--------C- -C--------C- ------------ ------------ ------------ ------------ ------------ ------------ ------------ 
------------ ------------ ------------ ------------ ------------ ------------ -C--------C- -C--------C- -C--------C- ------------ ------------ ------------ ------------ ------------ ------------ ------------ ------------ ------------ ------------ -C--------C- -C--------C- -C--------C- -C--------C- ------------ ------------ ------------ ------------ ------------ ------------ ------------ 
------------ ------------ ------------ ------------ ------------ ------------ -C--------C- -C--------C- -C--------C- ------------ ------------ ------------ ------------ ------------ ------------ ------------ ------------ ------------ ------------ -C--------C- -C--------C- -C--------C- -C--------C- ------------ ------------ ------------ ------------ ------------ ------------ ------------ 
------------ ------------ ------------ ------------ ------------ ------------ -CC------CC- -CC------CC- -CC------CC- ------------ ------------ ------------ ------------ ------------ ------------ ------------ ------------ ------------ ------------ -CC------CC- -CC------CC- -CC------CC- -CC------CC- ------------ ------------ ------------ ------------ ------------ ------------ ------------ 
------------ ------------ ------------ ------------ ------------ ------------ --CC----CC-- --CC----CC-- --CC----CC-- ------------ ------------ ------------ ------------ ------------ ------------ ------------ ------------ ------------ ------------ --CC----CC-- --CC----CC-- --CC----CC-- --CC----CC-- ------------ ------------ ------------ ------------ ------------ ------------ ------------ 
------------ ------------ ------------ ------------ ------------ ------------ ---CCCCCC--- ---CCCCCC--- ---CCCCCC--- ------------ ------------ ------------ ------------ ------------ ------------ ------------ ------------ ------------ ------------ ---CCCCCC--- ---CCCCCC--- ---CCCCCC--- ---CCCCCC--- ------------ ------------ ------------ ------------ ------------ ------------ ------------ 
