model
size = 28 27 30, scale = 0.05, origin = -y
material 
  colors = A:#08082F B:#002 C:#1D1D56 D:#400 E:#F90 F:#FF1C1C G:#500 H:#FC3 I:#FC6
voxels
---------------------------- ---------EEEEEEEEEE--------- ---------------------------- -----------E----E----------- ------------E--E------------ ---------------------------- -----------H----H----------- -----------H----H----------- ---------------------------- ------------E--E------------ -------------EE------------- -----------H----H----------- -----------H----H----------- -------------EE------------- ------------E--E------------ ---------------------------- -----------H----H----------- -----------H----H----------- ---------------------------- ------------E--E------------ -----------E----E----------- ---------------------------- ---------------------------- ---------------------------- ---------------------------- ---------------------------- ---------------------------- 
---------------------------- -------EEEEEEEEEEEEEE------- ----------CCCCCCCC---------- ----------CCCCCCCC---------- ----------CCCCCCCC---------- ----------GGCCCCGG---------- ----------GGCCCCGG---------- ----------GGCCCCGG---------- ----------GGCCCCGG---------- ----------CCCCCCCC---------- ----------GGCCCCGG---------- ----------GGCCCCGG---------- ----------GGCCCCGG---------- ----------GGCCCCGG---------- ----------CCCCCCCC---------- ----------GGCCCCGG---------- ----------GGCCCCGG---------- ----------GGCCCCGG---------- ----------GGCCCCGG---------- ----------CCCCCCCC---------- ----------CCCCCCCC---------- ----------CCCCCCCC---------- ---------------------------- ---------------------------- ---------------------------- ---------------------------- ---------------------------- 
---------------------------- -----EEEEE--------EEEEE----- --------AAABBBBBBAAA-------- --------AAABBBBBBAAA-------- --------AIABBBBBBAIA-------- --------AAABBBBBBAAA-------- --------AAABBBBBBAAA-------- --------AIABBBBBBAIA-------- --------AAABBBBBBAAA-------- --------AAABBBBBBAAA-------- --------AIABBBBBBAIA-------- --------AAABBBBBBAAA-------- --------AAABBBBBBAAA-------- --------AIABBBBBBAIA-------- --------AAABBBBBBAAA-------- --------AAABBBBBBAAA-------- --------AIABBBBBBAIA-------- --------AAABBBBBBAAA-------- --------AAABBBBBBAAA-------- --------AIABBBBBBAIA-------- --------AAABBBBBBAAA-------- --------AAABBBBBBAAA-------- -----------F----F----------- -----------F----F----------- -----------F----F----------- -----------F----F----------- ---------------------------- 
---------------------------- -----E----------------E----- ------AAAAA------AAAAA------ ------AGAAA------AAAGA------ ------AAAAA------AAAAA------ ------AGAAA------AAAGA------ ------AGAAA------AAAGA------ ------AAAAA------AAAAA------ ------AGAAA------AAAGA------ ------AAAAA------AAAAA------ ------AAAAA------AAAAA------ ------AGAAA------AAAGA------ ------AGAAA------AAAGA------ ------AAAAA------AAAAA------ ------AAAAA------AAAAA------ ------AGAAA------AAAGA------ ------AAAAA------AAAAA------ ------AGAAA------AAAGA------ ------AGAAA------AAAGA------ ------AAAAA------AAAAA------ ------AGAAA------AAAGA------ ------AAAAA------AAAAA------ ---------------------------- ---------------------------- ---------------------------- -----------F----F----------- ---------------------------- 
---------------------------- -----E----------------E----- ------AA------------AA------ ------AA------------AA------ ------AA------------AA------ ------AA------------AA------ ------AA------------AA------ ------AA------------AA------ ------AA------------AA------ ------AA------------AA------ ------AA------------AA------ ------AA------------AA------ ------AA------------AA------ ------AA------------AA------ ------AA------------AA------ ------AA------------AA------ ------AA------------AA------ ------AA------------AA------ ------AA------------AA------ ------AA------------AA------ ------AA------------AA------ ------AA------------AA------ -------F------------F------- -------F------------F------- -------F------------F------- -------F---F----F---F------- ---------------------------- 
--EEE------------------EEE-- ---------------------------- ---------------------------- ---------------------------- ---------------------------- ---------------------------- ---------------------------- ---------------------------- ---------------------------- ---------------------------- ---------------------------- ---------------------------- ---------------------------- ---------------------------- ---------------------------- ---------------------------- ---------------------------- ---------------------------- ---------------------------- ---------------------------- ---------------------------- ---------------------------- ---------------------------- ---------------------------- -------F------------F------- -------FF----------FF------- ---------------------------- 
--EE--------------------EE-- ---AA------------------AA--- ---AA------------------AA--- ---AA------------------AA--- ---AA------------------AA--- ---AA------------------AA--- ---AA------------------AA--- ---AA------------------AA--- ---AA------------------AA--- ---AA------------------AA--- ---AA------------------AA--- ---AA------------------AA--- ---AA------------------AA--- ---AA------------------AA--- ---AA------------------AA--- ---AA------------------AA--- ---AA------------------AA--- ---AA------------------AA--- ---AA------------------AA--- ---AA------------------AA--- ---AA------------------AA--- ---AA------------------AA--- ---AA------------------AA--- ---------------------------- ---------------------------- -------FF----------FF------- ---------------------------- 
-EE----------------------EE- ---AA------------------AA--- ---AA------------------AA--- ---IA------------------AI--- ---AA------------------AA--- ---IA------------------AI--- ---AA------------------AA--- ---GA------------------AG--- ---GA------------------AG--- ---AA------------------AA--- ---IA------------------AI--- ---AA------------------AA--- ---AA------------------AA--- ---IA------------------AI--- ---AA------------------AA--- ---GA------------------AG--- ---GA------------------AG--- ---AA------------------AA--- ---IA------------------AI--- ---AA------------------AA--- ---AA------------------AA--- ---AA------------------AA--- ---AA------------------AA--- ---F--------------------F--- ---F--------------------F--- ---F--------------------F--- ---------------------------- 
-E------------------------E- --AAA------------------AAA-- --AAA------------------AAA-- --AAA------------------AAA-- --AAA------------------AAA-- --AAA------------------AAA-- --AAA------------------AAA-- --AAA------------------AAA-- --AAA------------------AAA-- --AAA------------------AAA-- --AAA------------------AAA-- --AAA------------------AAA-- --AAA------------------AAA-- --AAA------------------AAA-- --AAA------------------AAA-- --AAA------------------AAA-- --AAA------------------AAA-- --AAA------------------AAA-- --AAA------------------AAA-- --AAA------------------AAA-- --AAA------------------AAA-- --AAA------------------AAA-- --AAA------------------AAA-- ---------------------------- ---------------------------- ---------------------------- ---------------------------- 
EE------------------------EE --AA--------------------AA-- --AA--------------------AA-- --IA--------------------AI-- --AA--------------------AA-- --IA--------------------AI-- --AA--------------------AA-- --GA--------------------AG-- --GA--------------------AG-- --AA--------------------AA-- --IA--------------------AI-- --AA--------------------AA-- --AA--------------------AA-- --IA--------------------AI-- --AA--------------------AA-- --GA--------------------AG-- --GA--------------------AG-- --AA--------------------AA-- --IA--------------------AI-- --AA--------------------AA-- --AA--------------------AA-- --AA--------------------AA-- --AA--------------------AA-- ---------------------------- ---------------------------- ---------------------------- ---------------------------- 
EE------------------------EE -CAA--------------------AAC- -CAA--------------------AAC- -CAA--------------------AAC- -DAA--------------------AAD- -DAA--------------------AAD- -DAA--------------------AAD- -DAA--------------------AAD- -CAA--------------------AAC- -DAA--------------------AAD- -DAA--------------------AAD- -DAA--------------------AAD- -DAA--------------------AAD- -DAA--------------------AAD- -DAA--------------------AAD- -CAA--------------------AAC- -DAA--------------------AAD- -DAA--------------------AAD- -DAA--------------------AAD- -DAA--------------------AAD- -CAA--------------------AAC- -CAA--------------------AAC- -CAA--------------------AAC- --F----------------------F-- --F----------------------F-- --FF--------------------FF-- ---------------------------- 
EE------------------------EE -CB----------------------BC- ECB----------------------BCE -CB----------------------BC- -DB----------------------BD- HCB----------------------BCH HCB----------------------BCH -DB----------------------BD- -CB----------------------BC- -DB----------------------BD- HDB----------------------BDH HDB----------------------BDH HDB----------------------BDH HDB----------------------BDH -DB----------------------BD- -CB----------------------BC- -DB----------------------BD- HDB----------------------BDH HDB----------------------BDH -DB----------------------BD- -CB----------------------BC- ECB----------------------BCE -CB----------------------BC- ---------------------------- ---------------------------- ---------------------------- ---------------------------- 
EE------------------------EE -CB----------------------BC- -CB----------------------BC- ECB----------------------BCE -DB----------------------BD- -DB----------------------BD- -DB----------------------BD- -DB----------------------BD- ECB----------------------BCE -DB----------------------BD- -DB----------------------BD- -DB----------------------BD- -DB----------------------BD- -DB----------------------BD- -DB----------------------BD- ECB----------------------BCE -DB----------------------BD- -DB----------------------BD- -DB----------------------BD- -DB----------------------BD- ECB----------------------BCE -CB----------------------BC- -CB----------------------BC- ---------------------------- ---------------------------- ---------------------------- ---------------------------- 
EE------------------------EE -CB----------------------BC- -CB----------------------BC- -CB----------------------BC- -CB----------------------BC- -CB----------------------BC- -CB----------------------BC- -CB----------------------BC- -CB----------------------BC- ECB----------------------BCE -CB----------------------BC- -CB----------------------BC- -CB----------------------BC- -CB----------------------BC- ECB----------------------BCE -CB----------------------BC- -CB----------------------BC- -CB----------------------BC- -CB----------------------BC- -CB----------------------BC- -CB----------------------BC- -CB----------------------BC- -CB----------------------BC- ---------------------------- ---------------------------- ---------------------------- ---------------------------- 
EE------------------------EE -CB----------------------BC- -CB----------------------BC- -CB----------------------BC- -CB----------------------BC- -CB----------------------BC- -CB----------------------BC- -CB----------------------BC- -CB----------------------BC- -CB----------------------BC- ECB----------------------BCE -CB----------------------BC- -CB----------------------BC- ECB----------------------BCE -CB----------------------BC- -CB----------------------BC- -CB----------------------BC- -CB----------------------BC- -CB----------------------BC- -CB----------------------BC- -CB----------------------BC- -CB----------------------BC- -CB----------------------BC- --F----------------------F-- --F----------------------F-- --F----------------------F-- --FFF------------------FFF-- 
EE------------------------EE -CB----------------------BC- -CB----------------------BC- -CB----------------------BC- -CB----------------------BC- -CB----------------------BC- -CB----------------------BC- -CB----------------------BC- -CB----------------------BC- -CB----------------------BC- ECB----------------------BCE -CB----------------------BC- -CB----------------------BC- ECB----------------------BCE -CB----------------------BC- -CB----------------------BC- -CB----------------------BC- -CB----------------------BC- -CB----------------------BC- -CB----------------------BC- -CB----------------------BC- -CB----------------------BC- -CB----------------------BC- --F----------------------F-- --F----------------------F-- --F----------------------F-- --FFF------------------FFF-- 
EE------------------------EE -CB----------------------BC- -CB----------------------BC- -CB----------------------BC- -CB----------------------BC- -CB----------------------BC- -CB----------------------BC- -CB----------------------BC- -CB----------------------BC- ECB----------------------BCE -CB----------------------BC- -CB----------------------BC- -CB----------------------BC- -CB----------------------BC- ECB----------------------BCE -CB----------------------BC- -CB----------------------BC- -CB----------------------BC- -CB----------------------BC- -CB----------------------BC- -CB----------------------BC- -CB----------------------BC- -CB----------------------BC- ---------------------------- ---------------------------- ---------------------------- ---------------------------- 
EE------------------------EE -CB----------------------BC- -CB----------------------BC- ECB----------------------BCE -DB----------------------BD- -DB----------------------BD- -DB----------------------BD- -DB----------------------BD- ECB----------------------BCE -DB----------------------BD- -DB----------------------BD- -DB----------------------BD- -DB----------------------BD- -DB----------------------BD- -DB----------------------BD- ECB----------------------BCE -DB----------------------BD- -DB----------------------BD- -DB----------------------BD- -DB----------------------BD- ECB----------------------BCE -CB----------------------BC- -CB----------------------BC- ---------------------------- ---------------------------- ---------------------------- ---------------------------- 
EE------------------------EE -CB----------------------BC- ECB----------------------BCE -CB----------------------BC- -DB----------------------BD- HCB----------------------BCH HCB----------------------BCH -DB----------------------BD- -CB----------------------BC- -DB----------------------BD- HDB----------------------BDH HDB----------------------BDH HDB----------------------BDH HDB----------------------BDH -DB----------------------BD- -CB----------------------BC- -DB----------------------BD- HDB----------------------BDH HDB----------------------BDH -DB----------------------BD- -CB----------------------BC- ECB----------------------BCE -CB----------------------BC- ---------------------------- ---------------------------- ---------------------------- ---------------------------- 
EE------------------------EE -CAA--------------------AAC- -CAA--------------------AAC- -CAA--------------------AAC- -DAA--------------------AAD- -DAA--------------------AAD- -DAA--------------------AAD- -DAA--------------------AAD- -CAA--------------------AAC- -DAA--------------------AAD- -DAA--------------------AAD- -DAA--------------------AAD- -DAA--------------------AAD- -DAA--------------------AAD- -DAA--------------------AAD- -CAA--------------------AAC- -DAA--------------------AAD- -DAA--------------------AAD- -DAA--------------------AAD- -DAA--------------------AAD- -CAA--------------------AAC- -CAA--------------------AAC- -CAA--------------------AAC- --F----------------------F-- --F----------------------F-- --FF--------------------FF-- ---------------------------- 
EE------------------------EE --AA--------------------AA-- --AA--------------------AA-- --IA--------------------AI-- --AA--------------------AA-- --IA--------------------AI-- --AA--------------------AA-- --GA--------------------AG-- --GA--------------------AG-- --AA--------------------AA-- --IA--------------------AI-- --AA--------------------AA-- --AA--------------------AA-- --IA--------------------AI-- --AA--------------------AA-- --GA--------------------AG-- --GA--------------------AG-- --AA--------------------AA-- --IA--------------------AI-- --AA--------------------AA-- --AA--------------------AA-- --AA--------------------AA-- --AA--------------------AA-- ---------------------------- ---------------------------- ---------------------------- ---------------------------- 
-E------------------------E- --AAA------------------AAA-- --AAA------------------AAA-- --AAA------------------AAA-- --AAA------------------AAA-- --AAA------------------AAA-- --AAA------------------AAA-- --AAA------------------AAA-- --AAA------------------AAA-- --AAA------------------AAA-- --AAA------------------AAA-- --AAA------------------AAA-- --AAA------------------AAA-- --AAA------------------AAA-- --AAA------------------AAA-- --AAA------------------AAA-- --AAA------------------AAA-- --AAA------------------AAA-- --AAA------------------AAA-- --AAA------------------AAA-- --AAA------------------AAA-- --AAA------------------AAA-- --AAA------------------AAA-- ---------------------------- ---------------------------- ---------------------------- ---------------------------- 
-EE----------------------EE- ---AA------------------AA--- ---AA------------------AA--- ---IA------------------AI--- ---AA------------------AA--- ---IA------------------AI--- ---AA------------------AA--- ---GA------------------AG--- ---GA------------------AG--- ---AA------------------AA--- ---IA------------------AI--- ---AA------------------AA--- ---AA------------------AA--- ---IA------------------AI--- ---AA------------------AA--- ---GA------------------AG--- ---GA------------------AG--- ---AA------------------AA--- ---IA------------------AI--- ---AA------------------AA--- ---AA------------------AA--- ---AA------------------AA--- ---AA------------------AA--- ---F--------------------F--- ---F--------------------F--- ---F--------------------F--- ---------------------------- 
--EE--------------------EE-- ---AA------------------AA--- ---AA------------------AA--- ---AA------------------AA--- ---AA------------------AA--- ---AA------------------AA--- ---AA------------------AA--- ---AA------------------AA--- ---AA------------------AA--- ---AA------------------AA--- ---AA------------------AA--- ---AA------------------AA--- ---AA------------------AA--- ---AA------------------AA--- ---AA------------------AA--- ---AA------------------AA--- ---AA------------------AA--- ---AA------------------AA--- ---AA------------------AA--- ---AA------------------AA--- ---AA------------------AA--- ---AA------------------AA--- ---AA------------------AA--- ---------------------------- ---------------------------- -------FF----------FF------- ---------------------------- 
--EEE------------------EEE-- ---------------------------- ---------------------------- ---------------------------- ---------------------------- ---------------------------- ---------------------------- ---------------------------- ---------------------------- ---------------------------- ---------------------------- ---------------------------- ---------------------------- ---------------------------- ---------------------------- ---------------------------- ---------------------------- ---------------------------- ---------------------------- ---------------------------- ---------------------------- ---------------------------- ---------------------------- ---------------------------- -------F------------F------- -------FF----------FF------- ---------------------------- 
---------------------------- -----E----------------E----- ------AA------------AA------ ------AA------------AA------ ------AA------------AA------ ------AA------------AA------ ------AA------------AA------ ------AA------------AA------ ------AA------------AA------ ------AA------------AA------ ------AA------------AA------ ------AA------------AA------ ------AA------------AA------ ------AA------------AA------ ------AA------------AA------ ------AA------------AA------ ------AA------------AA------ ------AA------------AA------ ------AA------------AA------ ------AA------------AA------ ------AA------------AA------ ------AA------------AA------ -------F------------F------- -------F------------F------- -------F------------F------- -------F---F----F---F------- ---------------------------- 
---------------------------- -----E----------------E----- ------AAAAA------AAAAA------ ------ADAAA------AAADA------ ------AAAAA------AAAAA------ ------ADAAA------AAADA------ ------ADAAA------AAADA------ ------AAAAA------AAAAA------ ------ADAAA------AAADA------ ------AAAAA------AAAAA------ ------AAAAA------AAAAA------ ------ADAAA------AAADA------ ------ADAAA------AAADA------ ------AAAAA------AAAAA------ ------AAAAA------AAAAA------ ------ADAAA------AAADA------ ------AAAAA------AAAAA------ ------ADAAA------AAADA------ ------ADAAA------AAADA------ ------AAAAA------AAAAA------ ------ADAAA------AAADA------ ------AAAAA------AAAAA------ ---------------------------- ---------------------------- ---------------------------- -----------F----F----------- ---------------------------- 
---------------------------- -----EEEEE--------EEEEE----- --------AAABBBBBBAAA-------- --------AAABBBBBBAAA-------- --------AHABBBBBBAHA-------- --------AAABBBBBBAAA-------- --------AAABBBBBBAAA-------- --------AHABBBBBBAHA-------- --------AAABBBBBBAAA-------- --------AAABBBBBBAAA-------- --------AHABBBBBBAHA-------- --------AAABBBBBBAAA-------- --------AAABBBBBBAAA-------- --------AHABBBBBBAHA-------- --------AAABBBBBBAAA-------- --------AAABBBBBBAAA-------- --------AHABBBBBBAHA-------- --------AAABBBBBBAAA-------- --------AAABBBBBBAAA-------- --------AHABBBBBBAHA-------- --------AAABBBBBBAAA-------- --------AAABBBBBBAAA-------- -----------F----F----------- -----------F----F----------- -----------F----F----------- -----------F----F----------- ---------------------------- 
---------------------------- -------EEEEEEEEEEEEEE------- ----------CCCCCCCC---------- ----------CCCCCCCC---------- ----------CCCCCCCC---------- ----------DDCCCCDD---------- ----------DDCCCCDD---------- ----------DDCCCCDD---------- ----------DDCCCCDD---------- ----------CCCCCCCC---------- ----------DDCCCCDD---------- ----------DDCCCCDD---------- ----------DDCCCCDD---------- ----------DDCCCCDD---------- ----------CCCCCCCC---------- ----------DDCCCCDD---------- ----------DDCCCCDD---------- ----------DDCCCCDD---------- ----------DDCCCCDD---------- ----------CCCCCCCC---------- ----------CCCCCCCC---------- ----------CCCCCCCC---------- ---------------------------- ---------------------------- ---------------------------- ---------------------------- ---------------------------- 
---------------------------- ---------EEEEEEEEEE--------- ---------------------------- -----------E----E----------- ------------E--E------------ ---------------------------- -----------H----H----------- -----------H----H----------- ---------------------------- ------------E--E------------ -------------EE------------- -----------H----H----------- -----------H----H----------- -------------EE------------- ------------E--E------------ ---------------------------- -----------H----H----------- -----------H----H----------- ---------------------------- ------------E--E------------ -----------E----E----------- ---------------------------- ---------------------------- ---------------------------- ---------------------------- ---------------------------- ---------------------------- 
