model
size = 15 15 3, scale = 0.05, origin = -y
material 
  colors = A:#111 B:#100 C:#555 D:#222 E:#800 F:#200 G:#FC9 H:#300 I:#777 J:#E00
voxels
-------BB------ -------EE---DG- -------F---DGD- -------BBBBBD-- -------EHHHB--- -------FFFHB--- -----AAA-FHB-EB -------AAFEBFEB --------A------ --------A------ --------------- --------------- --------------- --------------- --------------- 
-------BB------ -------EE---DD- -------F---DDD- -------AAAADD-- -------JAAAD--- ------AAAAAD--- ------CACAAD-EB -----CCGCAJDFEB ----CCGIAA----- ---IIGCICA----- --CCGCC-------- CICGCC--------- CIGCI---------- CGCC----------- GCII----------- 
-------BB------ -------EE---DG- -------F---DGD- -------BBBBBD-- -------EHHHB--- -------FFFHB--- -----AAA-FHB-EB -------AAFEBFEB --------A------ --------A------ --------------- --------------- --------------- --------------- --------------- 
