model
size = 21 26 3, scale = 0.05, origin = -y
material 
  colors = A:#1B813E B:#0F4C3A C:#096148
voxels
--------------------- --------------------- --------------------- --------------------- --------------------- ----------B---------- --------------------- ----------A---------- --------------------- --------------------- --------------------- --------------------- --------------------- --------------------- --------------------- --------------------- --------------------- --------------------- --------------------- --------------------- --------------------- --------------------- --------------------- --------------------- --------------------- --------------------- 
--------------------- --------------------- --------------------- --------------------- --------------------- ----------A---------- ---B--B-A-A-A--A----- ---------A----C------ -----B------C--A----- --------A--A-A------- --B-------------BB--- ------C-----C-------- B----A-------------B- -------A-C--AA------B ------A-------B------ --------A-------B---- ---------------B----- ------B----C--------- ------B----------B--- ----B---------------- -----B-----BB----B--- ------------B-------- ------------B-------- --------------------- ----B---------------- -------------B------- 
---------B----------- ----------B---------- ----------B---------- ----------B---------- ----------B---------- -------AAAAAA-------- ---AAAAAAAAAAAAAA---- ---AAAAAAAAAAAAAAA--- --AAAAAAA-AAAAAAAA--- --AA---AAAAAA-AAAAA-- -AA-----ACAAAAAAAAA-- -AA--AAAAAA-AAC-AAAA- AA---AAAAAAAAAAA-AAA- A----A-AAAAAAAAA--AAA -----AAAAA-AAAAAA---A -----AAAAAAAAAAAA---- -----AAA--AAA-AAAA--- -----AAA--AAA--AAA--- ----AAAA--AAA---AA--- ----AAA---AAA---AAA-- ----AAA----AAA---AA-- ----AA-----AAA------- ----AA-----AAA------- ----AA-----AAA------- ----A-------AA------- ----A-------AA------- 
