model
size = 20 32 13, scale = 0.05, origin = -y
material 
  colors = A:#B00 B:#DDD C:#A00 D:#111 E:#800 F:#FF3 G:#777 H:#555 I:#222 J:#888
voxels
3-7E2(13-7C)4(13-7A)13-7D13-7F13-7D13-A3B2AB13-3A2(BA)13-A3BABA13-2(B2A)B13-7B13-B2A2BAB2(13-A3BABA)13-B2A2(BA)13-7D2(13-7A)13-7C192-9E2(11-9C)4(11-9A)11-9D11-9F11-9D9(11-9B)11-9D2(11-9A)11-9C13-5C172-11E9-5C2A4C9-11C4(9-11A)9-11D9-11F9-3D6B2D9(9-11B)9-11D9-11A9-3A6D2A9-11C11-7C14-5C151-12E8-6C2A4C8-12C8-12A8-4A6I2A2(8-12A)8-12D8-6F2A4F8-4D6B2D8-A11B2(8-12B)2(8-A11B8-12B)8-12B8-A11B8-12D2(8-12A)8-12C10-9C12-7C15-3C132-13E7-3C8A2C7-13C7-13A7-4A6I3A2(7-13A)7-13D7-6F2A5F7-4D6B3D7-13B2(7-A12B2(7-13B))7-A12B7-13B7-3D8B2D7-4A6F3A7-13A7-13C8-11C10-9C13-5C131-13E7-3C8A2C7-13C4(7-13A)7-3D8A2D7-6F2A5F7-4D6A3D2(7-2B10AB)7-2B11A7-AB10AB7-AB11A7-AB10AB7-2B11A2(7-2B10AB)7-3D8B2D7-9AI3A5-G-13A4-G2-5C4A4C3-G4-4C4A3C3-G6-3C4A2C3-G8-7C3-G11-3A4-G12-3J3-G10-2D2GH4G11-2D3J2(G19-)13G6E-6E7-3C8A2C7-13C4(7-13A)7-3D8A2D7-6F2A5F7-4D6A3D7-AB10AB7-2B11A7-AB10AB7-AB10AC7-2B10AB7-AB10AC7-AB10AB7-2B11A7-AB10AB7-2D10AD7-9AI3A5-H-13A4-H2-3C8A2C3-H4-2C8AC3-H6-2C6AC3-H8-7C3-H11-3A4-H12-3J3-H10-2D2(HJ)3H11-2D4H19-H19-13H13E7-3C8A2C7-13C4(7-13A)7-3D8A2D7-6F2A5F7-4D6A3D2(7-2B10AB)7-2B11A7-AB10AB7-AB11A7-AB10AB7-2B11A2(7-2B10AB)7-2D10AD7-9AI3A5-G-13A4-G2-3C8A2C3-G4-2C8AC3-G6-2C6AC3-G8-7C3-G11-3A4-G12-3J3-G10-2D2G-4G11-2D3J2(G19-)13G13E7-3C8A2C7-13C4(7-13A)7-3D8A2D7-6F2A5F7-4D6A3D7-2B2(10AB7-AB2(10AB7-2B))10AB7-AB10AB7-2B10AB7-3D8B2D7-9AI3A7-13A7-5C4A4C8-4C4A3C10-3C4A2C13-5C131-12E8-3C8AC8-12C8-12A8-4A6I2A2(8-12A)8-12D8-6F2A4F8-4D6B2D8-A11B2(8-12B)2(8-A11B8-12B)8-12B8-A11B8-3D8BD8-4A6F2A8-12A8-12C10-9C12-7C15-3C133-11E9-5C2A4C9-11C9-11A9-3A6I2A2(9-11A)9-11D9-5F2A4F9-3D6B2D9(9-11B)9-11D2(9-11A)9-11C11-7C14-5C153-9E11-4C2A3C11-9C4(11-9A)11-9D11-4F2A3F11-2D6BD9(11-9B)11-9D11-9A11-2A6DA11-9C13-5C174-7E2(13-7C)4(13-7A)13-7D13-7F13-7D13-B2A3BA13-2(AB)3A13-ABA3BA13-2(B2A)B13-7B13-BA2B2AB2(13-ABA3BA)13-2(AB)2AB13-7D2(13-7A)13-7C190-
