model
size = 21 30 30, scale = 0.05, origin = -y
material 
  colors = A:#B00 B:#222 C:#A00 D:#FF3 E:#CACACA
voxels
--------------------- --------------------- --------------------- --------------------- --------------------- --------------------- --------------------- --------------------- --------------------- --------------------- --------------------- --------------------- --------------------- --------------------- --------------------- --------------------- --------------------- --------------------- --------------------- --------------------- -------BBBBBBB------- --------------------- --------------------- --------------------- --------------------- --------------------- --------------------- --------------------- --------------------- --------------------- 
--------------------- --------------------- --------------------- --------------------- --------------------- --------------------- --------------------- --------------------- --------------------- --------------------- --------------------- --------------------- --------------------- --------------------- --------------------- --------------------- --------------------- --------------------- --------------------- --------------------- -----BBBBBBBBBBBB---- --------------------- --------------------- --------------------- --------------------- --------------------- --------------------- --------------------- --------------------- --------------------- 
--------------------- --------------------- --------------------- --------------------- --------------------- --------------------- --------------------- --------------------- --------------------- --------------------- --------------------- --------------------- --------------------- --------------------- --------------------- --------------------- --------------------- --------------------- --------------------- --------------------- ---BBBBBBBBBBBBBBB--- ------BBBBBBBBB------ --------------------- --------------------- --------------------- --------------------- --------------------- --------------------- --------------------- --------------------- 
--------------------- --------------------- --------------------- --------------------- --------------------- --------------------- --------------------- --------------------- --------------------- --------------------- --------------------- --------------------- --------------------- --------------------- --------------------- --------------------- --------------------- --------------------- --------------------- --------------------- --BBBBBBBBBBBBBBBBB-- ----------A---------- ------BEEEEEEEB------ --------------------- --------------------- --------------------- --------------------- --------------------- --------------------- --------------------- 
--------------------- --------------------- --------------------- --------------------- --------------------- --------------------- --------------------- --------------------- --------------------- --------------------- --------------------- --------------------- --------------------- --------------------- --------------------- --------------------- --------------------- --------------------- --------------------- --------------------- -BBBBBBBBBBBBBBBBBBB- ----------A---------- ----------A---------- ------BEAAEEAEB------ --------------------- --------------------- --------------------- --------------------- --------------------- --------------------- 
--------------------- --------------------- --------------------- --------------------- --------------------- --------------------- --------------------- --------------------- --------------------- --------------------- --------------------- --------------------- --------------------- --------------------- --------------------- --------------------- --------------------- --------------------- --------------------- --------------------- BBBBBBBAAAAAAABBBBBBB -------AAAAAAA------- ----------A---------- ----------A---------- ------BAEEEAEAB------ --------------------- --------------------- --------------------- --------------------- --------------------- 
--------------------- --------------------- --------------------- --------------------- --------------------- --------------------- --------------------- --------------------- --------------------- --------------------- --------------------- --------------------- --------------------- --------------------- --------------------- --------------------- --------------------- --------------------- --------------------- --------------------- BBBBBAAA-----AAABBBBB -----AAA-----AAA----- --------AAAAA-------- --------AADAA-------- ----------A---------- ------BAEEEAEAB------ --------------------- --------------------- --------------------- --------------------- 
--------------------- --------------------- --------------------- --------------------- --------------------- --------------------- --------------------- --------------------- --------------------- --------------------- --------------------- --------------------- --------------------- --------------------- --------------------- --------------------- --------------------- --------------------- --------------------- --------------------- BBBBAA---------AABBBB ----AA---------AA---- ------AA-----AA------ ------AAAAAAAAA------ --------AADAA-------- --------ADDDA-------- ------BEAAEAEAB------ --------------------- --------------------- --------------------- 
--------------------- --------------------- --------------------- --------------------- --------------------- --------------------- --------------------- --------------------- --------------------- --------------------- --------------------- --------------------- --------------------- --------------------- --------------------- --------------------- --------------------- --------------------- --------------------- --------------------- BBBA-------------ABBB ---A-------------A--- ----AA---------AA---- ----AAAA-----AAAA---- ------AAAAAAAAA------ ------CCAAAAACC------ --------ADDDA-------- ------BEEEEEEEB------ --------------------- --------------------- 
--------------------- --------------------- --------------------- --------------------- --------------------- --------------------- --------------------- --------------------- --------------------- --------------------- --------------------- --------------------- --------------------- --------------------- --------------------- --------------------- --------------------- --------------------- --------------------- --------------------- BBAA-------------AABB --AA-------------AA-- ----A-----------A---- ----AA---------AA---- -----AAA-----AAA----- -----CCCAAAAACCC----- ------AAAAAAAAA------ --------AADAA-------- ------BBBBBBBBB------ --------------------- 
--------------------- --------------------- --------------------- --------------------- --------------------- --------------------- --------------------- --------------------- --------------------- --------------------- --------------------- --------------------- --------------------- --------------------- --------------------- --------------------- --------------------- --------------------- --------------------- --------------------- BBA---------------ABB --A---------------A-- ---A-------------A--- ---AA-----------AA--- ----AAA-------AAA---- ----CCCC-----CCCC---- -----AAAAAAAAAAA----- -------AAAAAAA------- --------AACAA-------- --------------------- 
--------------------- --------------------- --------------------- --------------------- --------------------- --------------------- --------------------- --------------------- --------------------- --------------------- --------------------- --------------------- --------------------- --------------------- --------------------- --------------------- --------------------- --------------------- --------------------- --------------------- BAA---------------AAB -AA---------------AA- ---A-------------A--- ---AA-----------AA--- ----AA---------AA---- ----CCC-------CCC---- -----AAAA---AAAA----- ------AAAAAAAAA------ -------AAAAAAA------- ---------ACA--------- 
--------------------- --------------------- --------------------- --------------------- --------------------- --------------------- --------------------- --------------------- --------------------- --------------------- --------------------- --------------------- --------------------- --------------------- --------------------- --------------------- --------------------- --------------------- --------------------- --------------------- BA-----------------AB -A-----------------A- --A---------------A-- --AA-------------AA-- ---AA-----------AA--- ---DAA---------AAD--- ----AAAA-----AAAA---- -----AAAAAAAAAAA----- ------AAAACAAAA------ --------AACAA-------- 
--------BBBBB-------- -------B-----B------- ------B-------B------ -----B---------B----- ----B-----------B---- ---B-------------B--- --B---------------B-- -B-----------------B- B-------------------B B-------------------B B-------------------B B-------------------B B-------------------B B-------------------B B-------------------B B-------------------B B-------------------B B-------------------B B-------------------B B-------------------B BA-----------------AB -A-----------------A- --A---------------A-- --AA-------------AA-- ---DA-----------AD--- ---DAA---------AAD--- ----DAA-------AAD---- -----AAAACACAAAA----- ------AAACCCAAA------ -------AACCCAA------- 
--------------------- --------------------- --------------------- --------------------- --------------------- --------------------- --------------------- --------------------- --------------------- --------------------- --------------------- --------------------- --------------------- --------------------- --------------------- --------------------- --------------------- --------------------- --------------------- --------------------- BA-----------------AB -C-----------------C- --C---------------C-- --DA-------------AD-- ---DA-----------AD--- ---DAA---------AAD--- ----DAA-------AAD---- -----DAAAACAAAAD----- ------CACCCCCAC------ -------CCCCCCC------- 
--------------------- --------------------- --------------------- --------------------- --------------------- --------------------- --------------------- --------------------- --------------------- --------------------- --------------------- --------------------- --------------------- --------------------- --------------------- --------------------- --------------------- --------------------- --------------------- --------------------- BA-----------------AB -A-----------------A- --A---------------A-- --AA-------------AA-- ---DA-----------AD--- ---DAA---------AAD--- ----DAA-------AAD---- -----AAAACACAAAA----- ------AAACCCAAA------ -------AACCCAA------- 
--------------------- --------------------- --------------------- --------------------- --------------------- --------------------- --------------------- --------------------- --------------------- --------------------- --------------------- --------------------- --------------------- --------------------- --------------------- --------------------- --------------------- --------------------- --------------------- --------------------- BA-----------------AB -A-----------------A- --A---------------A-- --AA-------------AA-- ---AA-----------AA--- ---DAA---------AAD--- ----AAAA-----AAAA---- -----AAAAAAAAAAA----- ------AAAACAAAA------ --------AACAA-------- 
--------------------- --------------------- --------------------- --------------------- --------------------- --------------------- --------------------- --------------------- --------------------- --------------------- --------------------- --------------------- --------------------- --------------------- --------------------- --------------------- --------------------- --------------------- --------------------- --------------------- BAA---------------AAB -AA---------------AA- ---A-------------A--- ---AA-----------AA--- ----AA---------AA---- ----CCC-------CCC---- -----AAAA---AAAA----- ------AAAAAAAAA------ -------AAAAAAA------- ---------ACA--------- 
--------------------- --------------------- --------------------- --------------------- --------------------- --------------------- --------------------- --------------------- --------------------- --------------------- --------------------- --------------------- --------------------- --------------------- --------------------- --------------------- --------------------- --------------------- --------------------- --------------------- BBA---------------ABB --A---------------A-- ---A-------------A--- ---AA-----------AA--- ----AAA-------AAA---- ----CCCC-----CCCC---- -----AAAAAAAAAAA----- -------AAAAAAA------- --------AACAA-------- --------------------- 
--------------------- --------------------- --------------------- --------------------- --------------------- --------------------- --------------------- --------------------- --------------------- --------------------- --------------------- --------------------- --------------------- --------------------- --------------------- --------------------- --------------------- --------------------- --------------------- --------------------- BBAA-------------AABB --AA-------------AA-- ----A-----------A---- ----AA---------AA---- -----AAA-----AAA----- -----CCCAAAAACCC----- ------AAAAAAAAA------ --------AADAA-------- --------------------- --------------------- 
--------------------- --------------------- --------------------- --------------------- --------------------- --------------------- --------------------- --------------------- --------------------- --------------------- --------------------- --------------------- --------------------- --------------------- --------------------- --------------------- --------------------- --------------------- --------------------- --------------------- BBBA-------------ABBB ---A-------------A--- ----AA---------AA---- ----AAAA-----AAAA---- ------AAAAAAAAA------ ------CCAAAAACC------ --------ADDDA-------- --------------------- --------------------- --------------------- 
--------------------- --------------------- --------------------- --------------------- --------------------- --------------------- --------------------- --------------------- --------------------- --------------------- --------------------- --------------------- --------------------- --------------------- --------------------- --------------------- --------------------- --------------------- --------------------- --------------------- BBBBAA---------AABBBB ----AA---------AA---- ------AA-----AA------ ------AAAAAAAAA------ --------ADDDA-------- --------DDDDD-------- --------------------- --------------------- --------------------- --------------------- 
--------------------- --------------------- --------------------- --------------------- --------------------- --------------------- --------------------- --------------------- --------------------- --------------------- --------------------- --------------------- --------------------- --------------------- --------------------- --------------------- --------------------- --------------------- --------------------- --------------------- BBBBBAAA-----AAABBBBB -----AAA-----AAA----- --------AACAA-------- --------AADAA-------- --------------------- --------------------- --------------------- --------------------- --------------------- --------------------- 
--------------------- --------------------- --------------------- --------------------- --------------------- --------------------- --------------------- --------------------- --------------------- --------------------- --------------------- --------------------- --------------------- --------------------- --------------------- --------------------- --------------------- --------------------- --------------------- --------------------- BBBBBBBAAAAAAABBBBBBB -------AAACAAA------- --------------------- --------------------- --------------------- --------------------- --------------------- --------------------- --------------------- --------------------- 
--------------------- --------------------- --------------------- --------------------- --------------------- --------------------- --------------------- --------------------- --------------------- --------------------- --------------------- --------------------- --------------------- --------------------- --------------------- --------------------- --------------------- --------------------- --------------------- --------------------- BBBBBBBBBBBBBBBBBBBBB --------------------- --------------------- --------------------- --------------------- --------------------- --------------------- --------------------- --------------------- --------------------- 
--------------------- --------------------- --------------------- --------------------- --------------------- --------------------- --------------------- --------------------- --------------------- --------------------- --------------------- --------------------- --------------------- --------------------- --------------------- --------------------- --------------------- --------------------- --------------------- --------------------- -BBBBBBBAABAABBBBBBB- --------------------- --------------------- --------------------- --------------------- --------------------- --------------------- --------------------- --------------------- --------------------- 
--------------------- --------------------- --------------------- --------------------- --------------------- --------------------- --------------------- --------------------- --------------------- --------------------- --------------------- --------------------- --------------------- --------------------- --------------------- --------------------- --------------------- --------------------- --------------------- --------------------- --BBBBBABABBBABBBBB-- --------------------- --------------------- --------------------- --------------------- --------------------- --------------------- --------------------- --------------------- --------------------- 
--------------------- --------------------- --------------------- --------------------- --------------------- --------------------- --------------------- --------------------- --------------------- --------------------- --------------------- --------------------- --------------------- --------------------- --------------------- --------------------- --------------------- --------------------- --------------------- --------------------- ---BBBBABABAAABBBB--- --------------------- --------------------- --------------------- --------------------- --------------------- --------------------- --------------------- --------------------- --------------------- 
--------------------- --------------------- --------------------- --------------------- --------------------- --------------------- --------------------- --------------------- --------------------- --------------------- --------------------- --------------------- --------------------- --------------------- --------------------- --------------------- --------------------- --------------------- --------------------- --------------------- ----BBBBAABBBABBB---- --------------------- --------------------- --------------------- --------------------- --------------------- --------------------- --------------------- --------------------- --------------------- 
--------------------- --------------------- --------------------- --------------------- --------------------- --------------------- --------------------- --------------------- --------------------- --------------------- --------------------- --------------------- --------------------- --------------------- --------------------- --------------------- --------------------- --------------------- --------------------- --------------------- -----BBBBBBBBBBB----- --------------------- --------------------- --------------------- --------------------- --------------------- --------------------- --------------------- --------------------- --------------------- 
