model
size = 30 22 29, scale = 0.05, origin = -y
material 
  colors = A:#4AA8DB B:#FDEF14 C:#FF432E D:#393 E:#BBB F:#EEE G:#E11B22 H:#888 I:#578A3D J:#777
voxels
-----------EEEEEEE------------ -----------EEEEEEE------------ ------------------------------ ------------------------------ ------------------------------ ------------------------------ ------------------------------ ------------------------------ ------------------------------ ------------------------------ ------------------------------ ------------------------------ ------------------------------ ------------------------------ ------------------------------ ------------------------------ ------------------------------ ------------------------------ ------------------------------ ------------------------------ ------------------------------ ------------------------------ 
--------EEEEEEEEEEEEE--------- --------EEE--AA---EEE--------- -------------BB--------------- -------------CC--------------- -------------DD--------------- -------------AA--------------- -------------BB--------------- -------------CC--------------- -------------DD--------------- -------------AA--------------- -------------BB--------------- -------------CC--------------- -------------DD--------------- -------------AA--------------- ------------------------------ ------------------------------ ------------------------------ ------------------------------ ------------------------------ ------------------------------ ------------------------------ ------------------------------ 
------EEEEEEEEEEEEEEEEE------- ------EE----AAAA-----EE------- ------------BBBB-------------- ------------CCCC-------------- ------------DDDD-------------- ------------AAAA-------------- ------------BBBB-------------- ------------CCCC-------------- ------------DDDD-------------- ------------AAAA-------------- ------------BBBB-------------- ------------CCCC-------------- ------------DDDD-------------- ------------AAAA-------------- ------------------------------ ------------------------------ ------------------------------ ------------------------------ ------------------------------ ------------------------------ ------------------------------ ------------------------------ 
-----EEEEEEEEEEEEEEEEEEE------ -----E------AAAA-------E------ ------------BBBB-------------- ------------CCCC-------------- ------------DDDD-------------- ------------AAAA-------------- ------------BBBB-------------- ------------CCCC-------------- ------------DDDD-------------- ------------AAAA-------------- ------------BBBB-------------- ------------CCCC-------------- ------------DDDD-------------- ------------AAAA-------------- ------------------------------ ------------------------------ ------------------------------ ------------------------------ ------------------------------ ------------------------------ ------------------------------ ------------------------------ 
----EEEEEEEEEEEEEEEEEEEEE----- ----E------AAAAAA-------E----- -----------BBBBBB------------- -----------CCCCCC------------- -----------DDDDDD------------- -----------AAAAAA------------- -----------BBBBBB------------- -----------CCCCCC------------- -----------DDDDDD------------- -----------AAAAAA------------- -----------BBBBBB------------- -----------CCCCCC------------- -----------DDDDDD------------- -----------AAAAAA------------- ------------------------------ ------------------------------ ------------------------------ ------------------------------ ------------------------------ ------------------------------ ------------------------------ ------------------------------ 
---EEEEEEEEEEEEEEEEEEEEEEE---- ---E-------AAAAAA--------E---- -----------BBBBBB------------- -----------CCCCCC------------- -----------DDDDDD------------- -----------AAAAAA------------- -----------BBBBBB------------- -----------CCCCCC------------- -----------DDDDDD------------- -----------AAAAAA------------- -----------BBBBBB------------- -----------CCCCCC------------- -----------DDDDDD------------- -----------AAAAAA------------- ------------------------------ ------------------------------ ------------------------------ ------------------------------ ------------------------------ ------------------------------ ------------------------------ ------------------------------ 
--EEEEEEEEEEEEEEEEEEEEEEEEE--- --E-------AAAAAAAA--------E--- ----------BBBBBBBB------------ ----------CCCCCCCC------------ ----------DDDDDDDD------------ ----------AAAAAAAA------------ ----------BBBBBBBB------------ ----------CCCCCCCC------------ ----------DDDDDDDD------------ ----------AAAAAAAA------------ ----------BBBBBBBB------------ ----------CCCCCCCC------------ ----------DDDDDDDD------------ ----------AAAAAAAA------------ ------------------------------ ------------------------------ ------------------------------ ------------------------------ ------------------------------ ------------------------------ ------------------------------ ------------------------------ 
--EEEEEEEEEEEEEEEEEEEEEEEEE--- --E-------AAAAAAAA--------E--- ----------BBBBBBBB------------ ----------CCCCCCCC------------ ----------DDDDDDDD------------ ----------AAAAAAAA------------ ----------BBBBBBBB------------ ----------CCCCCCCC------------ ----------DDDDDDDD------------ ----------AAAAAAAA------------ ----------BBBBBBBB------------ ----------CCCCCCCC------------ ----------DDDDDDDD------------ ----------AAAAAAAA------------ ------------------------------ ------------------------------ ------------------------------ ------------------------------ ------------------------------ ------------------------------ ------------------------------ ------------------------------ 
-EEEEEEEEEEEEEEEEEEEEEEEEEEE-- -E-------AAAAAAAAAA--------E-- ---------BBBBBBBBBB----------- ---------CCCCCCCCCC----------- ---------DDDDDDDDDD----------- ---------AAAAAAAAAA----------- ---------BBBBBBBBBB----------- ---------CCCCCCCCCC----------- ---------DDDDDDDDDD----------- ---------AAAAAAAAAA----------- ---------BBBBBBBBBB----------- ---------CCCCCCCCCC----------- ---------DDDDDDDDDD----------- ---------AAAAAAAAAA----------- ------------------------------ ------------------------------ ------------------------------ ------------------------------ ------------------------------ ------------------------------ ------------------------------ ------------------------------ 
-EEEEEEEEEEEEEEEEEEEEEEEEEEE-- -E-------AAAAAAAAAA--------E-- ---------BBBBBBBBBB----------- ---------CCCCCCCCCC----------- ---------DDDDDDDDDD----------- ---------AAAAAAAAAA----------- ---------BBBBBBBBBB----------- ---------CCCCCCCCCC----------- ---------DDDDDDDDDD----------- ---------AAAAAAAAAA----------- ---------BBBBBBBBBB----------- ---------CCCCCCCCCC----------- ---------DDDDDDDDDD----------- ---------AAAAAAAAAA----------- ------------------------------ ------------------------------ ------------------------------ ------------------------------ ------------------------------ ------------------------------ ------------------------------ ------------------------------ 
-EEEEEEEEEEEEEEEEEEEEEEEEEEE-- -E------AAAAAAAAAAAA-------E-- --------BBBBBBBBBBBB---------- --------CCCCCCCCCCCC---------- --------DDDDDDDDDDDD---------- --------AAAAAAAAAAAA---------- --------BBBBBBBBBBBB---------- --------CCCCCCCCCCCC---------- --------DDDDDDDDDDDD---------- --------AAAAAAAAAAAA---------- --------BBBBBBBBBBBB---------- --------CCCCCCCCCCCC---------- --------DDDDDDDDDDDD---------- --------AAAAAAAAAAAA---------- ------------------------------ ------------------------------ ------------------------------ ------------------------------ ------------------------------ ------------------------------ ------------------------------ ------------------------------ 
EEEEEEEEEEEEEEEEEEEEEEEEEEEEE- E-------AAAAAAAAAAAA--------E- --------BBBBBBBBBBBB---------- --------CCCCCCCCCCCC---------- --------DDDDDDDDDDDD---------- --------AAAAAAAAAAAA---------- --------BBBBBBBBBBBB---------- --------CCCCCCCCCCCC---------- --------DDDDDDDDDDDD---------- --------AAAAAAAAAAAA---------- --------BBBBBBBBBBBB---------- --------CCCCCCCCCCCC---------- --------DDDDDDDDDDDD---------- --------AAAAAAAAAAAA---------- ------------------------------ ------------------------------ ------------------------------ ------------------------------ ------------------------------ ------------------------------ ------------------------------ ------------------------------ 
EEEEEEEEEEEEEEEEEEEEEEEEEEEEE- E------AAAAAAAAAAAAAAH------E- -------BBBBBBBBBBBBBBHHH------ -------CCCCCCCCCCCCCC--HHHHHHJ -------DDDDDDDDDDDDDD--------- -------AAAAAAAAAAAAAA--------- -------BBBBBBBBBBBBBB--------- -------CCCCCCCCCCCCCC--------- -------DDDDDDDDDDDDDD--------- -------AAAAAAAAAAAAAA--------- -------BBBBBBBBBBBBBB--------- -------CCCCCCCCCCCCCC--------- -------DDDDDDDDDDDDDD--------- -------AAAAAAAAAAAAAA--------- ------------FFFF-F------------ -------------F---------------- ------------------------------ ------------------------------ ------------------------------ ------------------------------ ------------------------------ ------------------------------ 
EEEEEEEEEEEEEEEEEEEEEEEEEEEEE- E------AAAAAAAAAAAAAAH------E- -------BBBBBBBBBBBBBBHHH------ -------CCCCCCCCCCCCCC--HHHHHHJ -------DDDDDDDDDDDDDD--------- -------AAAAAAAAAAAAAA--------- -------BBBBBBBBBBBBBB--------- -------CCCCCCCCCCCCCC--------- -------DDDDDDDDDDDDDD--------- -------AAAAAAAAAAAAAA--------- -------BBBBBBBBBBBBBB--------- -------CCCCCCCCCCCCCC--------- -------DDDDDDDDDDDDDD--------- -------AAAAAAAAAAAAAA--------- ------------FFFF-FF----------- ------------FF-F--F----------- ------------------------------ ------------------------------ ------------------------------ ------------------------------ ------------------------------ ------------------------------ 
EEEEEEEEEEEEEEEEEEEEEEEEEEEEE- E-----AAAAAAAAAAAAAAAA------E- ------BBBBBBBBBBBBBBBB-------- ------CCCCCCCCCCCCCCCC-------- ------DDDDDDDDDDDDDDDD-------- ------AAAAAAAAAAAAAAAA-------- ------BBBBBBBBBBBBBBBB-------- ------CCCCCCCCCCCCCCCC-------- ------DDDDDDDDDDDDDDDD-------- ------AAAAAAAAAAAAAAAA-------- ------BBBBBBBBBBBBBBBB-------- ------CCCCCCCCCCCCCCCC-------- ------DDDDDDDDDDDDDDDD-------- ------AAAAAAAAAAAAAAAA-------- -----------FFFFFFFFF---------- ------------FFFFFF------------ ------------------------------ ------------------------------ ------------------------------ ------------------------------ ------------------------------ ------------------------------ 
EEEEEEEEEEEEEEEEEEEEEEEEEEEEE- E-----AAAAAAAAAAAAAAAA------E- ------BBBBBBBBBBBBBBBB-------- ------CCCCCCCCCCCCCCCC-------- ------DDDDDDDDDDDDDDDD-------- ------AAAAAAAAAAAAAAAA-------- ------BBBBBBBBBBBBBBBB-------- ------CCCCCCCCCCCCCCCC-------- ------DDDDDDDDDDDDDDDD-------- ------AAAAAAAAAAAAAAAA-------- ------BBBBBBBBBBBBBBBB-------- ------CCCCCCCCCCCCCCCC-------- ------DDDDDDDDDDDDDDDD-------- ------AAAAAAAAAAAAAAAA-------- ------------FFFFFFFFF--------- -------------FFFFF-F---------- -------------GGF-F------------ -------------GGG-------------- -------------GGG-------------- ------------------------------ ------------------------------ ------------------------------ 
EEEEEEEEEEEEEEEEEEEEEEEEEEEEE- E----AAAAAAAAAAAAAAAAAA-----E- -----BBBBBBBBBBBBBBBBBB------- -----CCCCCCCCCCCCCCCCCC------- -----DDDDDDDDDDDDDDDDDD------- -----AAAAAAAAAAAAAAAAAA------- -----BBBBBBBBBBBBBBBBBB------- -----CCCCCCCCCCCCCCCCCC------- -----DDDDDDDDDDDDDDDDDD------- -----AAAAAAAAAAAAAAAAAA------- -----BBBBBBBBBBBBBBBBBB------- -----CCCCCCCCCCCCCCCCCC------- -----DDDDDDDDDDDDDDDDDD------- -----AAAAAAAAAAAAAAAAAA------- -----------FFF-FF-FFF--------- -----------F-FFFFF------------ ------------GGF-FF------------ ------------GGGGF------------- ------------GGGGG------------- -------------GGG-------------- ------------------------------ ------------------------------ 
EEEEEEEEEEEEEEEEEEEEEEEEEEEEE- E----AAAAAAAAAAAAAAAAAA-----E- -----BBBBBBBBBBBBBBBBBB------- -----CCCCCCCCCCCCCCCCCC------- -----DDDDDDDDDDDDDDDDDD------- -----AAAAAAAAAAAAAAAAAA------- -----BBBBBBBBBBBBBBBBBB------- -----CCCCCCCCCCCCCCCCCC------- -----DDDDDDDDDDDDDDDDDD------- -----AAAAAAAAAAAAAAAAAA------- -----BBBBBBBBBBBBBBBBBB------- -----CCCCCCCCCCCCCCCCCC------- -----DDDDDDDDDDDDDDDDDD------- -----AAAAAAAAAAAAAAAAAA------- ------------FFFFFFFF---------- ------------FGG---FF---------- ------------GGF-FF------------ ------------GGGGG------------- ------------GGGGG------------- -------------GGG-------------- --------------I--------------- --------------II-------------- 
-EEEEEEEEEEEEEEEEEEEEEEEEEEE-- -E--AAAAAAAAAAAAAAAAAAAA---E-- ----BBBBBBBBBBBBBBBBBBBB------ ----CCCCCCCCCCCCCCCCCCCC------ ----DDDDDDDDDDDDDDDDDDDD------ ----AAAAAAAAAAAAAAAAAAAA------ ----BBBBBBBBBBBBBBBBBBBB------ ----CCCCCCCCCCCCCCCCCCCC------ ----DDDDDDDDDDDDDDDDDDDD------ ----AAAAAAAAAAAAAAAAAAAA------ ----BBBBBBBBBBBBBBBBBBBB------ ----CCCCCCCCCCCCCCCCCCCC------ ----DDDDDDDDDDDDDDDDDDDD------ ----AAAAAAAAAAAAAAAAAAAA------ -----------FFFFFFFFFF--------- ------------FGGFFFF----------- ------------G---FFF----------- ------------GGGGFF------------ ------------GGGGG------------- -------------GGG-------------- ------------------------------ ------------------------------ 
-EEEEEEEEEEEEEEEEEEEEEEEEEEE-- -E--AAAAAAAAAAAAAAAAAAAA---E-- ----BBBBBBBBBBBBBBBBBBBB------ ----CCCCCCCCCCCCCCCCCCCC------ ----DDDDDDDDDDDDDDDDDDDD------ ----AAAAAAAAAAAAAAAAAAAA------ ----BBBBBBBBBBBBBBBBBBBB------ ----CCCCCCCCCCCCCCCCCCCC------ ----DDDDDDDDDDDDDDDDDDDD------ ----AAAAAAAAAAAAAAAAAAAA------ ----BBBBBBBBBBBBBBBBBBBB------ ----CCCCCCCCCCCCCCCCCCCC------ ----DDDDDDDDDDDDDDDDDDDD------ ----AAAAAAAAAAAAAAAAAAAA------ -----------FFFFFFFFFF--------- -------------FFF-FF----------- -------------GGGFF------------ -------------GGG-------------- -------------GGG-------------- ------------------------------ ------------------------------ ------------------------------ 
-EEEEEEEEEEEEEEEEEEEEEEEEEEE-- -E-AAAAAAAAAAAAAAAAAAAAAA--E-- ---BBBBBBBBBBBBBBBBBBBBBB----- ---CCCCCCCCCCCCCCCCCCCCCC----- ---DDDDDDDDDDDDDDDDDDDDDD----- ---AAAAAAAAAAAAAAAAAAAAAA----- ---BBBBBBBBBBBBBBBBBBBBBB----- ---CCCCCCCCCCCCCCCCCCCCCC----- ---DDDDDDDDDDDDDDDDDDDDDD----- ---AAAAAAAAAAAAAAAAAAAAAA----- ---BBBBBBBBBBBBBBBBBBBBBB----- ---CCCCCCCCCCCCCCCCCCCCCC----- ---DDDDDDDDDDDDDDDDDDDDDD----- ---AAAAAAAAAAAAAAAAAAAAAA----- ------------F-FFFFF----------- ---------------FF------------- ------------------------------ ------------------------------ ------------------------------ ------------------------------ ------------------------------ ------------------------------ 
--EEEEEEEEEEEEEEEEEEEEEEEEE--- --EAAAAAAAAAAAAAAAAAAAAAA-E--- ---BBBBBBBBBBBBBBBBBBBBBB----- ---CCCCCCCCCCCCCCCCCCCCCC----- ---DDDDDDDDDDDDDDDDDDDDDD----- ---AAAAAAAAAAAAAAAAAAAAAA----- ---BBBBBBBBBBBBBBBBBBBBBB----- ---CCCCCCCCCCCCCCCCCCCCCC----- ---DDDDDDDDDDDDDDDDDDDDDD----- ---AAAAAAAAAAAAAAAAAAAAAA----- ---BBBBBBBBBBBBBBBBBBBBBB----- ---CCCCCCCCCCCCCCCCCCCCCC----- ---DDDDDDDDDDDDDDDDDDDDDD----- ---AAAAAAAAAAAAAAAAAAAAAA----- ----------------F------------- ------------------------------ ------------------------------ ------------------------------ ------------------------------ ------------------------------ ------------------------------ ------------------------------ 
--EEEEEEEEEEEEEEEEEEEEEEEEE--- --EEAAAAAAAAAAAAAAAAAAAA--E--- ----BBBBBBBBBBBBBBBBBBBB------ ----CCCCCCCCCCCCCCCCCCCC------ ----DDDDDDDDDDDDDDDDDDDD------ ----AAAAAAAAAAAAAAAAAAAA------ ----BBBBBBBBBBBBBBBBBBBB------ ----CCCCCCCCCCCCCCCCCCCC------ ----DDDDDDDDDDDDDDDDDDDD------ ----AAAAAAAAAAAAAAAAAAAA------ ----BBBBBBBBBBBBBBBBBBBB------ ----CCCCCCCCCCCCCCCCCCCC------ ----DDDDDDDDDDDDDDDDDDDD------ ----AAAAAAAAAAAAAAAAAAAA------ ------------------------------ ------------------------------ ------------------------------ ------------------------------ ------------------------------ ------------------------------ ------------------------------ ------------------------------ 
---EEEEEEEEEEEEEEEEEEEEEEE---- ---EAAAAAAAAAAAAAAAAAAAA-E---- ----AAAAAAAAAAAAAAAAAAAA------ ----AAAAAAAAAAAAAAAAAAAA------ ----AAAAAAAAAAAAAAAAAAAA------ ----AAAAAAAAAAAAAAAAAAAA------ ----AAAAAAAAAAAAAAAAAAAA------ ----AAAAAAAAAAAAAAAAAAAA------ ----AAAAAAAAAAAAAAAAAAAA------ ----AAAAAAAAAAAAAAAAAAAA------ ----AAAAAAAAAAAAAAAAAAAA------ ----AAAAAAAAAAAAAAAAAAAA------ ----AAAAAAAAAAAAAAAAAAAA------ ----AAAAAAAAAAAAAAAAAAAA------ ------------------------------ ------------------------------ ------------------------------ ------------------------------ ------------------------------ ------------------------------ ------------------------------ ------------------------------ 
----EEEEEEEEEEEEEEEEEEEEE----- ----E-------------------E----- ------------------------------ ------------------------------ ------------------------------ ------------------------------ ------------------------------ ------------------------------ ------------------------------ ------------------------------ ------------------------------ ------------------------------ ------------------------------ ------------------------------ ------------------------------ ------------------------------ ------------------------------ ------------------------------ ------------------------------ ------------------------------ ------------------------------ ------------------------------ 
-----EEEEEEEEEEEEEEEEEEE------ -----E-----------------E------ ------------------------------ ------------------------------ ------------------------------ ------------------------------ ------------------------------ ------------------------------ ------------------------------ ------------------------------ ------------------------------ ------------------------------ ------------------------------ ------------------------------ ------------------------------ ------------------------------ ------------------------------ ------------------------------ ------------------------------ ------------------------------ ------------------------------ ------------------------------ 
------EEEEEEEEEEEEEEEEE------- ------EE-------------EE------- ------------------------------ ------------------------------ ------------------------------ ------------------------------ ------------------------------ ------------------------------ ------------------------------ ------------------------------ ------------------------------ ------------------------------ ------------------------------ ------------------------------ ------------------------------ ------------------------------ ------------------------------ ------------------------------ ------------------------------ ------------------------------ ------------------------------ ------------------------------ 
--------EEEEEEEEEEEEE--------- --------EEE-------EEE--------- ------------------------------ ------------------------------ ------------------------------ ------------------------------ ------------------------------ ------------------------------ ------------------------------ ------------------------------ ------------------------------ ------------------------------ ------------------------------ ------------------------------ ------------------------------ ------------------------------ ------------------------------ ------------------------------ ------------------------------ ------------------------------ ------------------------------ ------------------------------ 
-----------EEEEEEE------------ -----------EEEEEEE------------ ------------------------------ ------------------------------ ------------------------------ ------------------------------ ------------------------------ ------------------------------ ------------------------------ ------------------------------ ------------------------------ ------------------------------ ------------------------------ ------------------------------ ------------------------------ ------------------------------ ------------------------------ ------------------------------ ------------------------------ ------------------------------ ------------------------------ ------------------------------ 
