model
size = 31 26 21, scale = 0.05, origin = -y
material 
  colors = A:#111 B:#C63 C:#555 D:#444 E:#777 F:#90F G:#333 H:#222 I:#666 J:#663 K:#03F L:#888 M:#9F9 N:#999 O:#AAA
voxels
------------------------------- ------------------------------- ------------------------------- ------------------------------- ------------------------------- ------------------------------- ------------------------------- ------------------------------- ------------------------------- ------------------------------- ------------------------------- ------------------------------- ------------------------------- ------------------------------- ------------------------------- ------------------------------- ----------------AAAAGG--------- ----------------AAAACC--------- --------------------CC--------- ------------------------------- ------------------------------- ------------------------------- ------------------------------- ------------------------------- ------------------------------- ------------------------------- 
------------------------------- ------------------------------- ------------------------------- ------------------------------- ------------------------------- ------------------------------- ------------------------------- ------------------------------- ------------------------------- ------------------------------- ------------------------------- ------------------------------- ------------------------------- ------------------------------- ------------------------------- ----------------AAAADD--------- ----------------AAAAHH--------- ----------------AAAAGG--------- ----------------AAAADD--------- ----------------AAAADD--------- ------------------------------- ------------------------------- ------------------------------- ------------------------------- ------------------------------- ------------------------------- 
------------------------------- ------------------------------- ------------------------------- ------------------------------- ------------------------------- ------------------------------- ------------------------------- ------------------------------- ------------------------------- ------------------------------- ------------------------------- ------------------------------- ------------------------------- ----------------AAAACC--------- ----------------AAAADD--------- ----------------AAAAFF--------- ----------------AAAAF---------- ---BBBBBBBBBBBBBBAAAF---------- ---BBBBBBBBBBBBBBAAAFF--------- ---BBBBBBBBBBBBBBAAACC--------- ----BBBBBBBBBBBBBAAACC--------- ------------------------------- ------------------------------- ------------------------------- ------------------------------- ------------------------------- 
------------------------------- ------------------------------- ------------------------------- ------------------------------- ------------------------------- ------------------------------- ------------------------------- -----------A------------------- ---------AAAA------------------ -------AAAAAA------------------ ------AAAAAAA------------------ ------AAAAAAAAA---------------- -----AAAAAAAAAAA--------------- -----AAAAAAAAAAAAAAAII--------- -----AAAAAAAAAAAAAAAGG--------- -----AAAAAAAAAAAAAAAF---------- -----AAAAAAAAAAAAAAAM---------- --BBBBBBBBBBBBBBBAAAF---------- --BBBBBBBBBBBBBBBAAAF---------- --BBBBBBBBBBBBBBBAAAFF--------- --BBBBBBBBBBBBBBBAAAEE--------- -----AAAAAAAAAAAA-------------- -----AAAAAAAAAAAA-------------- -----AAAAAAAAAAD--------------- ------AAAAAAAAA---------------- -------AAAAAA------------------ 
------------------------------- ------------------------------- ------------------------------- ------------------------------- ------------------------------- ------------------------------- ------------------------------- -------AAAAAAAA---------------- ------AAAAAAAAA---------------- -----AAAAAAAAAAA--------------- -----AAAAAAAAAAAA-------------- ----AAAAAAAAAAAAAA------------- ----AAAAAAAAAAAAAAA------------ ---AAAAAAAAAAAAAAAAAII--------- ---AAAAAAAAAAAAAAAAAFF--------- ---AAAAAAAAAAAAAAAAAF---------- ---AAAAAAAAAAAAAAAAAM---------- --BBBBBBBBBBBBBBBAAAF---------- --BBBBBBBBBBBBBBBAAAF---------- --BBBBBBBBBBBBBBBAAAF---------- --BBBBBBBBBBBBBBBAAACC--------- ---AAAAAAAAAAAAAACAAJJ--------- ----AAAAAAAAAAAAAC------------- ----AAAAAAAAAAAAAA------------- ----AAAAAAAAAAAAA-------------- -----AAAAAAAAAA---------------- 
------------------------------- ------------------------------- ------------------------------- ------------------------------- ------------------------------- ------------------------------- ------------------------------- -----AAAAAAAAAAAA-------------- -----AAAAAAAAAAAA-------------- ----AAAAAAAAAAAAA-------------- ----AAAAAAAAAAAAAA------------- ---AAAAAAAAAAAAAAAA------------ ---AAAAAAAAAAAAAAAA------------ ---AAAAAAAAAAAAAAAAAEE--------- ---AAAAAAAAAAAAAAAAAFF--------- ---AAAAAAAAAAAAAAAAAF---------- ---AAAAAAAAAAAAAAAAAM---------- -BBBBBBBBBBBBBBBBAAAF---------- -BBBBBBBBBBBBBBBBAAAF---------- -BBBBBBBBBBBBBBBBAAAF---------- -BBBBBBBBBBBBBBBBAAADD--------- ---AAAAAAAAAAAAAAHAACC--------- ---AAAAAAAAAAAAAAE------------- ---AAAAAAAAAAAAAAA------------- ---AAAAAAAAAAAAAA-------------- ----AAAAAAAAAAAAA-------------- 
------------------------------- ------------------------------- ------------------------------- --------------------KKK-------- --------------------KKKK------- -------------------KKKKK------- ------------------D-KKKK------- -----AAAAAAAAAAAAAGGGKK-------- ----AAAAAAAAAAAAAAAAA---------- ---AAAAAAAAAAAAAAAAAA---------- ---AAAAAAAAAAAAAAAGIA---------- ---AAAAAAAAAAAAAAAGA----------- --AAAAAAAAAAAAAAAAAA----------- --AAAAAAAAAAAAAAAAAADD--------- --AAAAAAAAAAAAAAAAAAEE--------- --AAAAAAAAAAAAAAAAAAF---------- --AAAAAAAAAAAAAAAAAAM---------- BBBBBBBBBBBBBBBBBAAAF---------- BBBBBBBBBBBBBBBBBAAAF---------- BBBBBBBBBBBBBBBBBAACFF--------- BBBBBBBBBBBBBBBBBAAAEE--------- --AAAAAAAAAAAAAAAAA------------ --AAAAAAAAAAAAAAAAA------------ ---AAAAAAAAAAAAAAAA------------ ---AAAAAAAAAAAAAAA------------- ---AAAAAAAAAAAAAA-------------- 
------------------------------- ------------------------------- ---------------------AA-------- -------------------AAAAA------- -------------------AAAAAA------ ------------------EAAAAAA------ ------------------CAAAAAA------ ----AAAAAAAAAAAAAAGAAAAA------- ---AAAAAAAAAAAAAAAHHHAAH------- ---AAAAAAAAAAAAAAAAAAAA-------- ---AAAAAAAAAAAAAAAHEEA--------- --AAAAAAAAAAAAAAAADHH---------- --AAAAAAAAAAAAAAAADA----------- --AAAAAAAAAAAAAAAAAAII--------- -AAAAAAAAAAAAAAAAAAALL--------- -AAAAAAAAAAAAAAAAAAAFF--------- -AAAAAAAAAAAAAAAAAAAF---------- BBBBBBBBBBBBBBBBBAAAF---------- BBBBBBBBBBBBBBBBBAAAFF--------- BBBBBBBBBBBBBBBBBAACJJ--------- BBBBBBBBBBBBBBBBBAAJCC--------- --AAAAAAAAAAAAAAAAA------------ --AAAAAAAAAAAAAAAAA------------ --AAAAAAAAAAAAAAAAA------------ --AAAAAAAAAAAAAAAA------------- ---AAAAAAAAAAAAAAA------------- 
------------------------------- ------------------------------- ------------------------------- -------------------AAAAA------- -------------------AAAAAA-I---- ------------------IAAAAAAII---- ------------------DAAAAAAD----- ---AAAAAAAAAAAAAAAGGAAAAG------ ---AAAAAAAAAAAAAAAHHHHHHH------ ---AAAAAAAAAAAAAAAAAAAAAA------ --AAAAAAAAAAAAAAAAHEEHHA------- --AAAAAAAAAAAAAAAAGHHGG-------- -AAAAAAAAAAAAAAAAADAA---------- -AAAAAAAAAAAAAAAAAAA----------- -AAAAAAAAAAAAAAAAAA------------ -AAAAAAAAAAAAAAAAAAAII--------- -AAAAAAAAAAAAAAAAAAADD--------- BBBBBBBBBBBBBBBBBAAAII--------- BBBBBBBBBBBBBBBBBAAAII--------- BBBBBBBBBBBBBBBBBAAADD--------- BBBBBBBBBBBBBBBBBAAA----------- -AAAAAAAAAAAAAAAAAAA----------- -AAAAAAAAAAAAAAAAAAA----------- --AAAAAAAAAAAAAAAAA------------ --AAAAAAAAAAAAAAAAA------------ --AAAAAAAAAAAAAAAA------------- 
------------------------------- ------------------------------- ----------------------------E-- -------------------------CCCC-- --------------------AAAGGGGGG-- ------------------JJAAAJJJJJ--- ------------------JJAAAJJJJ---- ---AAAAAAAAAAAAAAACCCCCCCC----- ---AAAAAAAAAAAAAAAGGGGGGGG----- --AAAAAAAAAAAAAAAAAAAAAAA------ --AAAAAAAAAAAAAAAAHEEHHEA------ -AAAAAAAAAAAAAAAAADHHDD-------- -AAAAAAAAAAAAAAAAADHHDA-------- -AAAAAAAAAAAAAAAAAAAAC--------- -AAAAAAAAAAAAAAAAAAAA---------- -AAAAAAAAAAAAAAAAAAA----------- -AAAAAAAAAAAAAAAAAAAII--------- BBBBBBBBBBBBBBBBAAAAEE--------- BBBBBBBBBBBBBBBBAAAAJJ--------- BBBBBBBBBBBBBBBBAAAAL---------- BBBBBBBBBBBBBBBBAAAAA---------- -AAAAAAAAAAAAAAAAAAAL---------- -AAAAAAAAAAAAAAAAAAA----------- -AAAAAAAAAAAAAAAAAA------------ --AAAAAAAAAAAAAAAAA------------ --AAAAAAAAAAAAAAAA------------- 
------------------------------A ----------------------------AAA --------------------------MAAAA ------------------------AAAAAA- --------------------AAAAAAAAA-- ------------------AAAAAAAAAAA-- ------------------AAAAAAAAAA--- ---AAAAAAAAAIIIIIIAAAAAAAAA---- ---AAAAAAAAAEEEEEEAAAAAAAAA---- --AAAAAAAAAAEEEEEEAAAAAAAA----- --AAAAAAAAAAEEEEEEAAAAAAA------ -AAAAAAAAAAAAAAAAAAAAAAJ------- -AAAAAAAAAAAAAAAAAAAAAI-------- -AAAAAAAAAAAAAAAAACCCCC-------- -AAAAAAAAAAAAAAAAAHHHHH-------- -AAAAAAAAAAAAAAAAAAAA---------- -AAAAAAAAAAAAAAAAAEEE---------- BBBBBBBBBBBBBBBBAAIII---------- BBBBBBBBBBBBBBBBAADDD---------- BBBBBBBBBBBBBBBBAADDD---------- BBBBBBBBBBBBBBBBAACCC---------- -AAAAAAAAAAAAAAAAADDD---------- -AAAAAAAAAAAAAAAAADD----------- -AAAAAAAAAAAAAAAAACC----------- -AAAAAAAAAAAAAAAAAD------------ --AAAAAAAAAAAAAAAA------------- 
------------------------------A ----------------------------AAA --------------------------AAAAA ------------------------AAAAAA- --------------------AAAAAAAAA-- ------------------AAAAAAAAAAA-- ------------------AAAAAAAAAA--- ---AAAAAAAAALLLLLLAAAAAAAAA---- ---AAAAAAAAAEEEEEEAAAAAAAAA---- --AAAAAAAAAALLLLLLAAAAAAAA----- --AAAAAAAAAALLLLLLAAAAAAA------ -AAAAAAAAAAAAAAAAAAAAAAA------- -AAAAAAAAAAAAAAAAAAAAAI-------- -AAAAAAAAAAAAAAAAANNNNN-------- -AAAAAAAAAAAAAAAAALLLLH-------- -AAAAAAAAAAAAAAAAADDD---------- -AAAAAAAAAAAAAAAAADDD---------- BBBBBBBBBBBBBBBBAAGGG---------- BBBBBBBBBBBBBBBBAAOOO---------- BBBBBBBBBBBBBBBBAANNN---------- BBBBBBBBBBBBBBBBAAEEE---------- -AAAAAAAAAAAAAAAAAIII---------- -AAAAAAAAAAAAAAAAAII----------- -AAAAAAAAAAAAAAAAAEE----------- -AAAAAAAAAAAAAAAAAC------------ --AAAAAAAAAAAAAAAA------------- 
------------------------------- ------------------------------- ----------------------------E-- -------------------------CCCC-- --------------------AAAGGGGGG-- ------------------JJAAAJJJJJ--- ------------------JJAAAJJJJ---- ---AAAAAAAAAAAAAAACCCCCCCC----- ---AAAAAAAAAAAAAAAGGGGGGGG----- --AAAAAAAAAAAAAAAAAAAAAAA------ --AAAAAAAAAAAAAAAAHEEHHEA------ -AAAAAAAAAAAAAAAAADHHDD-------- -AAAAAAAAAAAAAAAAADHHDA-------- -AAAAAAAAAAAAAAAAAAAAC--------- -AAAAAAAAAAAAAAAAAAAA---------- -AAAAAAAAAAAAAAAAAAA----------- -AAAAAAAAAAAAAAAAAAAII--------- BBBBBBBBBBBBBBBBAAAAEE--------- BBBBBBBBBBBBBBBBAAAAJJ--------- BBBBBBBBBBBBBBBBAAAAL---------- BBBBBBBBBBBBBBBBAAAAA---------- -AAAAAAAAAAAAAAAAAAAL---------- -AAAAAAAAAAAAAAAAAAA----------- -AAAAAAAAAAAAAAAAAA------------ --AAAAAAAAAAAAAAAAA------------ --AAAAAAAAAAAAAAAA------------- 
------------------------------- ------------------------------- ------------------------------- -------------------AAAAA------- -------------------AAAAAA-I---- ------------------IAAAAAAII---- ------------------DAAAAAAD----- ---AAAAAAAAAAAAAAAGGAAAAG------ ---AAAAAAAAAAAAAAAHHHHHHH------ ---AAAAAAAAAAAAAAAAAAAAAA------ --AAAAAAAAAAAAAAAAHEEHHA------- --AAAAAAAAAAAAAAAAGHHGG-------- -AAAAAAAAAAAAAAAAADAA---------- -AAAAAAAAAAAAAAAAAAA----------- -AAAAAAAAAAAAAAAAAA------------ -AAAAAAAAAAAAAAAAAAAII--------- -AAAAAAAAAAAAAAAAAAADD--------- BBBBBBBBBBBBBBBBAAAAII--------- BBBBBBBBBBBBBBBBAAAAII--------- BBBBBBBBBBBBBBBBAAAADD--------- BBBBBBBBBBBBBBBBAAAA----------- -AAAAAAAAAAAAAAAAAAA----------- -AAAAAAAAAAAAAAAAAAA----------- --AAAAAAAAAAAAAAAAA------------ --AAAAAAAAAAAAAAAAA------------ --AAAAAAAAAAAAAAAA------------- 
------------------------------- ------------------------------- ---------------------AA-------- -------------------AAAAA------- -------------------AAAAAA------ ------------------EAAAAAA------ ------------------CAAAAAA------ ----AAAAAAAAAAAAAAGAAAAA------- ---AAAAAAAAAAAAAAAHHHAAH------- ---AAAAAAAAAAAAAAAAAAAA-------- ---AAAAAAAAAAAAAAAHEEA--------- --AAAAAAAAAAAAAAAADHH---------- --AAAAAAAAAAAAAAAADA----------- --AAAAAAAAAAAAAAAAAAII--------- -AAAAAAAAAAAAAAAAAAALL--------- -AAAAAAAAAAAAAAAAAAAFF--------- -AAAAAAAAAAAAAAAAAAAF---------- BBBBBBBBBBBBBBBBAAAAF---------- BBBBBBBBBBBBBBBBAAAAFF--------- BBBBBBBBBBBBBBBBAAACJJ--------- BBBBBBBBBBBBBBBBAAAJCC--------- --AAAAAAAAAAAAAAAAA------------ --AAAAAAAAAAAAAAAAA------------ --AAAAAAAAAAAAAAAAA------------ --AAAAAAAAAAAAAAAA------------- ---AAAAAAAAAAAAAAA------------- 
------------------------------- ------------------------------- ------------------------------- --------------------KKK-------- --------------------KKKK------- -------------------KKKKK------- ------------------D-KKKK------- -----AAAAAAAAAAAAAGGGKK-------- ----AAAAAAAAAAAAAAAAA---------- ---AAAAAAAAAAAAAAAAAA---------- ---AAAAAAAAAAAAAAAGIA---------- ---AAAAAAAAAAAAAAAGA----------- --AAAAAAAAAAAAAAAAAA----------- --AAAAAAAAAAAAAAAAAADD--------- --AAAAAAAAAAAAAAAAAAEE--------- --AAAAAAAAAAAAAAAAAAF---------- --AAAAAAAAAAAAAAAAAAM---------- BBBBBBBBBBBBBBBBAAAAF---------- BBBBBBBBBBBBBBBBAAAAF---------- BBBBBBBBBBBBBBBBAAACFF--------- BBBBBBBBBBBBBBBBAAAAEE--------- --AAAAAAAAAAAAAAAAA------------ --AAAAAAAAAAAAAAAAA------------ ---AAAAAAAAAAAAAAAA------------ ---AAAAAAAAAAAAAAA------------- ---AAAAAAAAAAAAAA-------------- 
------------------------------- ------------------------------- ------------------------------- ------------------------------- ------------------------------- ------------------------------- ------------------------------- -----AAAAAAAAAAAA-------------- -----AAAAAAAAAAAA-------------- ----AAAAAAAAAAAAA-------------- ----AAAAAAAAAAAAAA------------- ---AAAAAAAAAAAAAAAA------------ ---AAAAAAAAAAAAAAAA------------ ---AAAAAAAAAAAAAAAAAEE--------- ---AAAAAAAAAAAAAAAAAFF--------- ---AAAAAAAAAAAAAAAAAF---------- ---AAAAAAAAAAAAAAAAAM---------- -BBBBBBBBBBBBBBBAAAAF---------- -BBBBBBBBBBBBBBBAAAAF---------- -BBBBBBBBBBBBBBBAAAAF---------- -BBBBBBBBBBBBBBBAAAADD--------- ---AAAAAAAAAAAAAAHAACC--------- ---AAAAAAAAAAAAAAE------------- ---AAAAAAAAAAAAAAA------------- ---AAAAAAAAAAAAAA-------------- ----AAAAAAAAAAAAA-------------- 
------------------------------- ------------------------------- ------------------------------- ------------------------------- ------------------------------- ------------------------------- ------------------------------- -------AAAAAAAA---------------- ------AAAAAAAAA---------------- -----AAAAAAAAAAA--------------- -----AAAAAAAAAAAA-------------- ----AAAAAAAAAAAAAA------------- ----AAAAAAAAAAAAAAA------------ ---AAAAAAAAAAAAAAAAAII--------- ---AAAAAAAAAAAAAAAAAFF--------- ---AAAAAAAAAAAAAAAAAF---------- ---AAAAAAAAAAAAAAAAAM---------- --BBBBBBBBBBBBBBBAAAF---------- --BBBBBBBBBBBBBBBAAAF---------- --BBBBBBBBBBBBBBBAAAF---------- --BBBBBBBBBBBBBBBAAACC--------- ---AAAAAAAAAAAAAACAAJJ--------- ----AAAAAAAAAAAAAC------------- ----AAAAAAAAAAAAAA------------- ----AAAAAAAAAAAAA-------------- -----AAAAAAAAAA---------------- 
------------------------------- ------------------------------- ------------------------------- ------------------------------- ------------------------------- ------------------------------- ------------------------------- -----------A------------------- ---------AAAA------------------ -------AAAAAA------------------ ------AAAAAAA------------------ ------AAAAAAAAA---------------- -----AAAAAAAAAAA--------------- -----AAAAAAAAAAAAAAAII--------- -----AAAAAAAAAAAAAAAGG--------- -----AAAAAAAAAAAAAAAF---------- -----AAAAAAAAAAAAAAAM---------- --BBBBBBBBBBBBBBBAAAF---------- --BBBBBBBBBBBBBBBAAAF---------- --BBBBBBBBBBBBBBBAAAFF--------- --BBBBBBBBBBBBBBBAAAEE--------- -----AAAAAAAAAAAA-------------- -----AAAAAAAAAAAA-------------- -----AAAAAAAAAAD--------------- ------AAAAAAAAA---------------- -------AAAAAA------------------ 
------------------------------- ------------------------------- ------------------------------- ------------------------------- ------------------------------- ------------------------------- ------------------------------- ------------------------------- ------------------------------- ------------------------------- ------------------------------- ------------------------------- ------------------------------- ----------------AAAACC--------- ----------------AAAADD--------- ----------------AAAAFF--------- ----------------AAAAF---------- ---BBBBBBBBBBBBBBAAAF---------- ---BBBBBBBBBBBBBBAAAFF--------- ---BBBBBBBBBBBBBBAAACC--------- ----BBBBBBBBBBBBBAAACC--------- ------------------------------- ------------------------------- ------------------------------- ------------------------------- ------------------------------- 
------------------------------- ------------------------------- ------------------------------- ------------------------------- ------------------------------- ------------------------------- ------------------------------- ------------------------------- ------------------------------- ------------------------------- ------------------------------- ------------------------------- ------------------------------- ------------------------------- ------------------------------- ----------------AAAADD--------- ----------------AAAAHH--------- ----------------AAAAGG--------- ----------------AAAADD--------- ----------------AAAADD--------- ------------------------------- ------------------------------- ------------------------------- ------------------------------- ------------------------------- ------------------------------- 
