model
size = 29 32 14, scale = 0.05, origin = -y
material 
  colors = A:#FFE900 B:#630 C:#111 D:#EEE E:#222
voxels
240-2B2A24-3A2BA23-B2A3B24-BA2B388-C28-CE27-CE19-2A28-A104-2A8-2A16-4A6-3AB15-4A6-4A106-2B2A23-4BA3B20-A2B4A3B19-10A19-2B8A19-3B4AB2A20-2(2B2A)23-4A210-3(4A25-)4AC28-C2D26-C2D18-2A6-C2D18-3A5-C20-3A103-2A8-AB16-4A6-B3A15-4A6-2A2B15-3A7-3A16-BA8-AB17-BA2(3-2A)17-BA2B4A3BA17-10A2B2(17-B11A)2(17-B10AB)18-B8AB20-8A24-2A124-4A24-6A22-2(7AB21-)8A21-6ACD22-5ACDC22-4ACDC18-2A6-C2D18-3A5-CE20-2A250-6A21-10A18-11AB16-B12AB15-B13A2(15-B12AB)16-11AB18-11A20-2B2A4BA25-3BA26-2B27-2B4-4A24-6A22-8A20-2AB6AB19-A3B5AB19-5B4AB19-A3B3ACD20-2AB4ACDE19-7ACDC18-8AC2D18-4A4-CE50-A28-A165-2A24-10A17-11AB13-B2-13AB12-B2-13AB2(15-B13A)2(15-13AB)16-2B11A18-A2B8A21-BAB5A23-2B4A23-4ABA-6A17-4B-8A16-4BA3B6A15-4A5B5A16-2A7B3AB16-2A7B4A17-A7BACA18-2A5B2ACD19-2A3B3ACD19-8ACE19-7A-C22-4A25-3A26-2A27-AB133-9A18-12A16-12AB15-13AB12-A-15AB12-17A2(13-16A)14-B14A15-B12AB16-B11AB18-2B8AB22-6A2-4A17-15A-2A11-2(B6A)-3A11-B4A5B7AB11-4A7B6AB12-3A7B6A14-A9B4A15-BA7B4AB15-2A7B3AB17-BA5B5A17-4AB6A19-8A22-5A25-3A26-2A162-9A18-12A16-13A15-14A14-16A12-17A12-16AB13-15AB14-B14A15-B12AB16-B11AB18-10AB21-8A-4A3-2D11-B15AB2A11-B5A3B5AB3A2(11-B3A7B6AB)12-2A9B5A13-BA9B3AB15-10B3AB15-2A7B3AB17-8B4A17-3A3B4AB19-8A22-6A25-A191-9A18-11AB16-12AB15-13AB14-3(15AB13-)15AB14-15A15-B12AB16-12AB18-11A21-8A-4A3-2D11-B15AB2A11-B4A5B4AB3A11-B3A7B6AB11-B2A9B5AB12-2A9B5A13-BA9B2(3AB15-10B)2AB17-8B4A17-2A5B4A19-8A22-B5A25-A191-9A18-11AB16-12AB15-13AB14-15A3(B13-B14A)B14-15A15-14A16-13A18-11A22-6A2-2B2A17-15A-2A11-6A3B5A-3A2(11-B3A7B7A)12-2A9B5A14-2(10B4A15-)B2(A7B4A17-)B2A3B5A19-B7A22-B4A25-3A26-2A164-2A24-9AB17-11AB16-13AB15-14A2(15-B12AB)2(15-B13A)16-AB11A18-B10A21-8A23-AB2A2B23-AB2ABA-5AB17-A3B-AB6A16-4A5B5A15-3A7B4A16-2A7B4A16-A9B3A17-8BACA18-8BACD19-A5B2ACD19-B2AB4ACE19-B6A-C22-4A25-3A26-2A27-AB162-5AB21-9AB18-11AB16-14A3(15-B13A)16-11AB18-2B7A2B20-AB2AB4A25-4B26-2B27-2B4-2A2B24-5AB22-3B5A20-5B4AB19-6B3AB19-6B4A19-6BACD20-6BACDE19-A4B2ACDC18-B7AC2D18-B3A4-CE50-B28-A45-2A8-2A16-4A6-4A15-4A6-3AB15-3A7-3B16-AB8-2B17-2(2A3-)2B17-12A17-10ABA2(17-B10AB)17-B11A17-11AB18-9AB20-BAB2ABAB24-2B124-2A2B24-6A22-2B5AB21-3B4AB21-4B4A21-3B3ACD22-3B2ACDC22-2ABACDC18-2A6-C2D18-2AB5-CE20-2A103-2A8-2A16-2A2B6-B2AB15-3AB6-2(BA)106-4A23-7AB20-2(2B6A2B19-)2B8A19-2B6A2B20-2A4BAB23-4B210-2(2A2B25-)BA2B25-B3AC28-C2D26-C2D18-AB6-C2D18-3A5-C20-3A338-4B24-A4BA23-2A3BA24-4A388-C28-CE27-CE19-AB28-A99-
