model
size = 19 31 18, scale = 0.05, origin = -y
material 
  colors = A:#FC0 B:#F90 C:#FFF D:#FFC E:#FC6 F:#C60 G:#FC3 H:#930 I:#200 J:#CC3 K:#FF9 L:#500 M:#400 N:#600 O:#300 P:#F93 Q:#CC6 R:#C93 S:#C30 T:#700 U:#630 V:#F96 W:#C63 X:#800 Y:#F60 Z:#C96 Aa:#960 Ab:#900 Ac:#963
voxels
- - - - - - - - - - - - - - - - - - -   - - - - - - - - - - - - - - - - - - -   - - - - - - - - - - - - - - - - - - -   - - - - - - - - - - - - - - - - - - -   - - - - - - - - - - - - - - - - - - -   - - - - - - - A A A - - - - - - - - -   - - - - - - A A A A A - - - - - - - -   - - - - - - A A A A A A - - - - - - -   - - - - - - A A A A A A - - - - - - -   - - - - - - B B A A A - - - - - - - -   - - - - - - - B A A - - - - - - - - -   - - - I - - - - A A - - - - - - - - -   - - - - - - - - - - - - - - - - I - -   - - - - - - - - - - - - - - - - I - -   - - - - - - - - - - - - - - - - - - -   - - - - - - - - - - - - - - - - - - -   - - - - - - - - - - - - - - - - - - -   - - - - - M N - - - N - - - - - - - -   - - - - - - - - - - - - - - - - - - -   - - - - - - - - - - - - - - - - - - -   - - - - - - - - - - - - - - - - - - -   - - - - - - - - - - - - - - - - - - -   - - - - - - - - - - - - - - - - - - -   - - - - - - - - - - - - - - - - - - -   - - - - - - - - - - - - - - - - - - -   - - - - - - - - - - - - - - - - - - -   - - - - - - - - - - - - - - - - - - -   - - - - - - - - - - - - - - - - - - -   - - - - - - - - - - - - - - - - - - -   - - - - - - - - - - - - - - - - - - -   - - - - - - - - - - - - - - - - - - -   
- - - - - - - - - - - - - - - - - - -   - - - - - - - - - - - - - - - - - - -   - - - - - - - - - - - - - - - - - - -   - - - - - - - - A A - - - - - - - - -   - - - O - - B B A A A B - - - - - - -   - - - - - B B B A A A B B - - - - - -   - - - - - B B B A A A B B B - - - - -   - - - - B B B B A A A B B B - - - - -   - - - - B B B B A A A A A A - - - - -   - - - - B B B B A A A A A A - - - - -   - - - - - B B B A A A A A - - - - - -   - - - M - A A A A A A B B - - - - - -   - - O - - - - B A A - - - - - - I - -   - - O - - - - - - - - - - - - - I - -   - - - I - - - - - - - - - - - - I - -   - - - I - - - - - - - - - - - - I - -   - - - - - - - - - - - - - - - - - - -   - - - - - N - - - - - - - - N - - - -   - - - - - M B - - E - - - - - - - - -   - - - - - - - G - E - W - - - - - - -   - - - - - - - - - - - - - - - - - - -   - - - - - - - - - - - - - - - - - - -   - - - - - - - - - - - - - - - - - - -   - - - - - - - - - - - - - - - - - - -   - - - - - - - - - - - - - - - - - - -   - - - - - - - - - - - - - - - - - - -   - - - - - - - - - - - - - - - - - - -   - - - - - - - - - - - - - - - - - - -   - - - - - - - - - - - - - - - - - - -   - - - - - - - - - - - - - - - - - - -   - - - - - - - - - - - - - - - - - - -   
- - - - - - - - - - - - - - - - - - -   - - - - - - - - - - - - - - - - - - -   - - - - - - - A A A - - - - - - - - -   - - - M - - B B A A A B B - - - - - -   - - - N - B B B A A A A A A - - - - -   - - - - B B B B A A A A A A A - - - -   - - - B B B B B A A A B B B B - - - -   - - - A A A A A A A A B B B B - - - -   - - - A A A A A A A A B B B B - - - -   - - - B B B B B A A A B B B B - - - -   - - - - B B B B A A A A A A A - - - -   - - - - B B B B A A A A A A - - - - -   - - X - - B B B A A A A A - - - - - -   - - L - - - A A A A A A - - - - - - -   - - - M - - - - - - - - - O - M M - -   - - - I I - - - - - - - - - - I I - -   - - - - - - E - - - - - - E - - - - -   - - - - T M N - - - G - - N - - - - -   - - - M O I M - - - - - - B - - S O -   - - - - F I F - - - - - - - - - U - -   - - - - - H - - - - - - - - - - - - -   - - - - - - F - - - - - - - - - - - -   - - - - - - - - - - - - - - - - - - -   - - - - - - - - - - - - - - - - - - -   - - - - - - - - - - - - - - - - - - -   - - - - - - - - - - - - - - - - - - -   - - - - - - - - - - - - - - - - - - -   - - - - - - - - - - - - - - - - - - -   - - - - - - - - - - - - - - - - - - -   - - - - - - - - - - - - - - - - - - -   - - - - - - - - - - - - - - - - - - -   
- - - - - - - - - - - - - - - - - - -   - - - - - - - - - A - - - - - - - - -   - - - L - - A A A A A A A - - - - - -   - - - N B B B B A A A B B B - - - - -   - - - - B B B B A A A B B B B - - - -   - - - A E E E E A A A B B B B B - - -   - - - A A A A A A A A B B B B B - - -   - - - G G G G G A A A B B B B B - - -   - - - E E E E E A A A A A A A A - - -   - - - D D D D D A A A A A A A A - - -   - - - E E E E E A A J B B B B B - - -   - - - A A A A A A A A A A A A - - - -   - - - - A A A A A A A B B B B - - - -   - - - - - A A A A A A A A - - - H L O   - - AbH - - - B A A A - S S - - - H -   - - T H T - - - - - - - - - - T - H -   - - - T N T - - - - - - - - T N F H -   - - - - F N G G - - G - G - N - - - -   - - - - S M B - - - - - - - M - - - -   - - - - - I B - - - - - - B I - - - -   - - - - - - - - - - - - - - - T - - -   - - - - - - I - - - - - - - - - - - -   - - - - I M - - - - - - - - - - - - -   - - - - - - - - - - - - - - - - - - -   - - - - - - - - - - - - - - - - - - -   - - - - - - - - - - - - - - - - - - -   - - - - - - - - - - - - - - - - - - -   - - - - - - - Ac- - - - - - - - - - -   - - - - - - - - - - - - - - - - - - -   - - - - - - - - - - - - - - - - - - -   - - - - - - - - - - - - - - - - - - -   
- - - - - - - - - - - - - - - - - - -   - - - - - - A A A A A A - - - - - - -   - - - - - B B B A A A B B B - - - - -   - - - - A A A A A A A A A A A - - - -   - - - A A A A A A A A A A A A A - - -   - - C C C C C C J J A E E E E E - - -   - - C C C C C C D D C G G G G G - - -   - - - C C C C C A A D A A A A A - - -   - - C C C C C C A A E B B B B B - - -   - - C C C C C C A A C B B B B B - - -   - - C C C C C C A A C B B B B B - - -   - - - G G G G G A A A B B B B B - - -   - - - P P P P P A A A A A A A - - - -   - - - - A A A A A A A A A A - - - L O   - - - - - B B B A A A B B I - - - - -   - - - - - - - - A A - - - U - - - - -   - - - - - T - - - - - - - - T - - - -   - - - - - G - G - - - G G - G - - - -   - - - - - F E E - - - - - - - - - - -   - - - - - - - - G - - G - - - - - - -   - - - - - - - - - - - - - H - - - - -   - - - - - - L F - - - - F L - - - - -   - - - - - - - S - - - - S - - - - - -   - - - - - - - H - - - - - - - - - - -   - - - - - - - - - - - - - - - - - - -   - - - - - - - - - - - - - - - - - - -   - - - - - - - - - - - - - - - - - - -   - - - - - - - - - - - - - - - - - - -   - - - - - - - - - - - - - - - - - - -   - - - - - - - - - - - - - - - - - - -   - - - - - - - - - - - - - - - - - - -   
- - - - - - - - - - - - - - - - - - -   - - - - - - A A A A A B B - - - - - -   - - - - A A A A A A A B B B B - - - -   - - - B B B B B P P A A A A A A - - -   - - - D D D D D A A A B B B B B - - -   - - C C C C C C A A C D D D D D D - -   - - - A A A A A C C C A A A A A - - -   - - C C C C C C A A C B B B B B - - -   - - D D D D D D J J C B B B B B - - -   - - - Q Q Q Q Q A A D A A A A A - - -   - - D D D D D D A A D A A A A A - - -   - - D C C C C C A A A B B B B B - - -   - - - D D D D D E E Q B B B B B - - -   - - - - G G G G A A E B B B B - - - -   - - - - - A A A A A A A A A - - - - -   - - - - - E E A A A A B H I - - - - -   - - - - - E E - - - - R - H - - - - -   - - - - - O G E - - - H F - - - - - -   - - - - - F F G E - V L S - - - - - -   - - - - - F U F G E R W H E - - - - -   - - - - - - - - - - - R - - - - - - -   - - - - - - - F H - - H F - - - - - -   - - - - - - - S L - - L S - - - - - -   - - - - - - - H O - - O - - - - - - -   - - - - - - - - - - - - L - - - - - -   - - - - - - - - - - - - - - - - - - -   - - - - - - - - - - - - - - - - - - -   - - - - - - - - - - - - - - - - - - -   - - - - - - - - - - - - - - - - - - -   - - - - - - - - - - - - - - - - - - -   - - - - - - - - - - - - - - - - - - -   
- - - - - - - - A A A - - - - - - - -   - - - - - A A A A A A A A A - - - - -   - - - - A A A A A A A B B B B - - - -   - - - B B B B B A A A K K K K K - - -   - - D D D D D D K K J D D D D D D - -   - - - A A A A A C C C C C C C C C - -   - - - A A A A A C C J C C C C C C - -   - - - A A A A A C C Q D D D D D D - -   - - D D D D D D C C C A A A A A - - -   - - - A A A A A C C J E E E E E - - -   - - - E E E E E D D A P P P P P - - -   - - C C C C C C A A C E E E E E D - -   - - - - B B B B D D D K K K K K - - -   - - - G G G G G A A E B B B B B - - -   - - - - B B B B A A A B B B - - - - -   - - - - - - B B A A A A A - - - - - -   - - - T - - E - - - - E N - - E F - -   - - - - - I G E - - - H I - - - - - -   - - - - - I F G E - V F I - - - - - -   - - - - - U F F G E R F U - E H U - -   - - - - - - - R - - V - E E - - - - -   - - - - - - F H - - - E G - - - - - -   - - - - - - S L V V V V F F - - - - -   - - - - - - H O R R R R U F - - - - -   - - - - - - - L H - - H L - - - - - -   - - - - - E E - - - E W - - - - - - -   - - - - - - - - - - - - - - - - - - -   - - - - - - - - - - - - - - - - - - -   - - - - - - - - - - - - - - - - - - -   - - - - - - - - - - - - - - - - - - -   - - - - - - - - - - - - - - - - - - -   
- - - - - - - B A A A B - - - - - - -   - - - - - B B B A A A B B B - - - - -   - - - - G G G G A A A A A A A - - - -   - - - D D D D D K K A J J J J J - - -   - - C C C C C C K K A Q Q Q Q Q - - -   - - - A A A A A C C C D D D D D D - -   - - - A A A A A J J P D D D D D D - -   - - - J J J J J E E A D D D D D D - -   - - D D D D D D D D D C C C C C C - -   - - - E E E E E D D E C C C C C C - -   - - D D D D D D C C A C C C C C C - -   - - C C C C C C C C D C C C C C C - -   - - D D D D D D A A D E E E E - - - -   - - - K K K K K J J D A A A A A - - -   - - - - B B B B A A A B B B B - - - -   - - - - - F A A A A A A A - - - - - -   - - - - - H E - - - E E H - - - - - -   - - - - - L F G - - G F L - E - - - -   - - - - - M S F - - F S M - - - - - -   - - - - - - H U W - U H L - - - - - -   - - - - N H - - - V V - - - - T - - -   - - - - - L - - - - - - - - F O - - -   - - - - - - - - - E E - - - F - - - -   - - - - - - - - - G G - - - U - - - -   - - - - - - - H E E E E AaF - - - - -   - - - - - - - - H B E - - - - - - - -   - - - - - Y Y - F Y E - - - - - - - -   - - - - - F - - - E E E - - - - - - -   - - - - - - - - - E E - - - - - - - -   - - - - - - - - - - E - - - - - - - -   - - - - - - - - - W - - - - - - - - -   
- - - - - - - B A A A B - - - - - - -   - - - - - B B B A A A B B B - - - - -   - - - - A A A A A A A G G G G - - - -   - - - J J J J J A A K D D D D D - - -   - - - Q Q Q Q Q A A K C C C C C C - -   - - D D D D D D C C C A A A A A - - -   - - D D D D D D P P J A A A A A - - -   - - D D D D D D A A E J J J J J - - -   - - C C C C C C D D D D D D D D D - -   - - C C C C C C E E D E E E E E - - -   - - C C C C C C A A C D D D D D D - -   - - C C C C C C D D C C C C C C C - -   - - - - E E E E D D A D D D D D D - -   - - - A A A A A D D J K K K K K - - -   - - - - B B B B A A A B B B B - - - -   - - - - - B A A A A A A A - - - - - -   - - - - - - - - - - - - - - - - - - -   - - - - - - F E E E E - - - - - - - -   - - - - - - S G G G G - - - - - - - -   - - - - - - H F F F F E E B - - - - -   - - - - - - - - - - - - - - - - - - -   - - - - - - - - E E E E F - - - - - -   - - - - - - - - G G G G S - - - - - -   - - - - - - - - F F F F H - - - - - -   - - - - - - - - - E E - - - - - - - -   - - - - - B B - H B E - - - B - - - -   - - - - - F F - F F E - - - F - - - -   - - - - - Z Z - - F Z - - - - - - - -   - - - - - - E - H E E - - - E - - - -   - - - - - - - - - - E - - - - - - - -   - - - - - - - - - - - - - - - - - - -   
- - - - - - - - A A A - - - - - - - -   - - - - - A A A A A A A A A - - - - -   - - - - B B B B A A A A A A A - - - -   - - - K K K K K A A A B B B B B - - -   - - D D D D D D J J K D D D D D D - -   - - C C C C C C C C C A A A A A - - -   - - C C C C C C J J C A A A A A - - -   - - D D D D D D Q Q C A A A A A - - -   - - - A A A A A C C C D D D D D D - -   - - - E E E E E J J C A A A A A - - -   - - - P P P P P A A D E E E E E - - -   - - D E E E E E C C A C C C C C C - -   - - - K K K K K D D D B B B B - - - -   - - - B B B B B E E A G G G G G - - -   - - - - - B B B A A A B B B B - - - -   - - - - - - A A A A A B B - - - - - -   - - - - - - - - V V - - - - - - - - -   - - - - - - E G - - - G G - W - - - -   - - - - - - E E E E - - - - - - - - -   - - - - - - F E G G - - E F - - - - -   - - - - - - H E E - - - E H - - - - -   - - - - - - L F G - - G F L - - - - -   - - - - - - M S F - - F S M - - - - -   - - - - - - L H U - - U H - - - - - -   - - - - - - - - F F F F L - - - - - -   - - - - - H H F W - E W - - - - - - -   - - - - - F F H F - E F - - - - - - -   - - - - - R R - R R R Ac- - - - - - -   - - - - - H - - H - E - - - - - - - -   - - - - - - - - - - E - - - - - - - -   - - - - - - - - - - - - - - - - - - -   
- - - - - - - - - - - - - - - - - - -   - - - - - - B B A A A A A - - - - - -   - - - - B B B B A A A A A A A - - - -   - - - A A A A A A A P B B B B B - - -   - - - B B B B B A A A D D D D D - - -   - - D D D D D D C C A C C C C C C - -   - - - A A A A A C C C A A A A A - - -   - - - B B B B B C C A C C C C C C - -   - - - B B B B B C C J D D D D D D - -   - - - A A A A A D D A Q Q Q Q Q - - -   - - - A A A A A D D A D D D D D D - -   - - - B B B B B A A A C C C C C D - -   - - - B B B B B Q Q E D D D D D - - -   - - - - B B B B E E A G G G G - - - -   - - - - - A A A A A A A A A - - - - -   - - - - - - - B A A A A - - - - - - -   - - N T - E E - V - - R - - T E F H -   - - - - - H G E - - E H F - H - - - -   - - - - - F F V V V V L S - - - - - -   - - - - F F U R R R R O H - I H U - -   - - - - - - N E - - - - E - - - - - -   - - - - - - I H - - - E G I - - - - -   - - - - - - I F V - E G F I - - - - -   - - - - - - U F R - G F F U - - - - -   - - - - - - N L Aa- - AaL - - - - - -   - - - - - F U M M - F M M - - - - - -   - - - - - - H - - - H - - - H - - - -   - - - - - - - - - - - - - - - - - - -   - - - - - - - - - - - - - - - - - - -   - - - - - - - - - - - - - - - - - - -   - - - - - - - - - - - - - - - - - - -   
- - - - - - - - - - - - - - - - - - -   - - - - - - - A A A A A A - - - - - -   - - - - - B B B A A A B B B - - - - -   - - - - A A A A A A A A A A A - - - -   - - - A A A A A A A A A A A A A - - -   - - - E E E E E A A J C C C C C C - -   - - - G G G G G C C D C C C C C C - -   - - - A A A A A D D A C C C C C - - -   - - - B B B B B E E A C C C C C C - -   - - - B B B B B C C A C C C C C C - -   - - - B B B B B C C A C C C C C C - -   - - - B B B B B A A A G G G G G - - -   - - - - A A A A A A A P P P P P - - -   - - - - - A A A A A A A A A A - - - -   I M Ab- - - B B A A A B B B - - - H -   I I T H T E E W E A A G - - - T - H -   - - N T N F - R - - R - - - T N F H -   - - - - - N F H - - H F - N E - - - -   - - - - - M S L - - L S - - - - - - -   - - - - - I H O - - O H E E - - - - -   - - - - - H - R - - - - E E - T - - -   - - - - I L F H - - - E G O - - - - -   - - - - - M S L V - E G F F - - - - -   - - - - - L H - R - G F U F U - - - -   - - - - - - L F E E - F - - - - - - -   - - - - - - - O - - U - O - U - - - -   - - - - - - - - - - - - - - - - - - -   - - - - - - - - - - - - - - - - - - -   - - - - - - - - - - - - - - - - - - -   - - - - - - - - - - - - - - - - - - -   - - - - - - - - - - - - - - - - - - -   
- - - - - - - - - - - - - - - - - - -   - - - - - - - - - A - - - - - - - - -   - - - - - - A A A A A A A - - - - - -   - - - - - B B B A A A B B B B - - - -   - - - - B B B B A A A B B B B - - - -   - - - B B B B B A A A E E E E A - - -   - - - B B B B B A A A A A A A A - - -   - - - B B B B B A A A G G G G G - - -   - - - A A A A A A A A E E E E E - - -   - - - A A A A A A A A D D D D D - - -   - - - B B B B B J J A E E E E E - - -   - - - - A A A A A A A A A A A A - - -   - H - - B B B B A A A A A A A - - - -   O H - - - - A A A A A A A A - - H L -   I M AbH - - - - A A A B E - - - - H -   - - - I I - - G - - G - - - - I I - -   - - - - H H - - - - - - H - F H - - -   - - - - F L F - - - E F L - N - - - -   - - - - S M S - - - F S - - - - - - -   - - - - F L H - - - - H - - I H U - -   - - - - - - - - - - - - - - - T - - -   - - - - - - - - - - - - - - F O - - -   - - - - - - - - - - - - - - F - - - -   - - - - - - - - - - - - - - - - - - -   - - - - - - L - - - - - - - - - - - -   - - - - - - - - - - - - - - - - - - -   - - - - - - - - - - - - - - - - - - -   - - - - - - - - - - - - - - - - - - -   - - - - - - - - - - - - - - - - - - -   - - - - - - - - - - - - - - - - - - -   - - - - - - - - - - - - - - - - - - -   
- - - - - - - - - - - - - - - - - - -   - - - - - - - - - - - - - - - - - - -   - - - - - - - - - A A A - - - - - - -   - - - - - - B B A A A B B - - - - - -   - - - - - A A A A A A B B B - - - - -   - - - - A A A A A A A B B B B - - - -   - - - - B B B B A A A B B B B B - - -   - - - - B B B B A A A A A A A A - - -   - - - - B B B B A A A A A A A A - - -   - - - - B B B B A A A B B B B B - - -   - - - - A A A A A A A B B B B - - - -   - - - - - A A A A A A B B B B - - - -   - - X - - - A A A A A B B B - X - - -   - - L - - - - A A A A A A - - L - - -   - - - M M - - - - - - - B - - M M - -   - - - I - B - - - - - - B - - - I - -   - - - - - N - - - - - - N - - - - - -   - - - - T I F - - - F - I - M - - - -   - - - - O I S - - - S - - - - - - - -   - - - - - - - - - - - - - - U - - - -   - - - - - - - - - - - - - - - - - - -   - - - - - - - - - - - - - - - - - - -   - - - - - - - - - - - - - - - - - - -   - - - - - - - - - - - - - - - - - - -   - - - - - - - - - - - - - - - - - - -   - - - - - - - - - - - - - - - - - - -   - - - - - - - - - - - - - - - - - - -   - - - - - - - - - - - - - - - - - - -   - - - - - - - - - - - - - - - - - - -   - - - - - - - - - - - - - - - - - - -   - - - - - - - - - - - - - - - - - - -   
- - - - - - - - - - - - - - - - - - -   - - - - - - - - - - - - - - - - - - -   - - - - - - - - - - - - - - - - - - -   - - - - - - - - - A A - - - - - - - -   - - - - - - - B A A A B B - - - - - -   - - - - - - B B A A A B B B - - - - -   - - - - - B B B A A A B B B - - - - -   - - - - - B B B A A A B B B B - - - -   - - - - - A A A A A A B B B B - - - -   - - - - - A A A A A A B B B B - - - -   - - - - - - A A A A A B B B - - L - -   - - - M H - B B A A A A A A - H M - -   - - O - - - - - - A A B - - - O I - -   - - O - - - - - - - - - N - - O I - -   - - - I - B - - - - - - M - - - I - -   - - - - - F - - - - - - F - - - - - -   - - - - - E - - - - - - - - - - - - -   - - - - - T G E - - T H F - F - - - -   - - - - - F F G E - V L - - - - - - -   - - - - - F U F G - R O H - - - - - -   - - - - - - - - - - - - - - - - - - -   - - - - - - - - - - - - - - - - - - -   - - - - - - - - - - - - - - - - - - -   - - - - - - - - - - - - - - - - - - -   - - - - - - - - - - - - - - - - - - -   - - - - - - - - - - - - - - - - - - -   - - - - - - - - - - - - - - - - - - -   - - - - - - - - - - - - - - - - - - -   - - - - - - - - - - - - - - - - - - -   - - - - - - - - - - - - - - - - - - -   - - - - - - - - - - - - - - - - - - -   
- - - - - - - - - - - - - - - - - - -   - - - - - - - - - - - - - - - - - - -   - - - - - - - - - - - - - - - - - - -   - - - - - - - - - - - - - - - - - - -   - - - - - - - - - - - - - - - - - - -   - - - - - - - - - A A A - - - - - - -   - - - - - - - - A A A A A - - - - - -   - - - - - - - A A A A A A - - - - - -   - - - - - - - A A A A A A - - - - - -   - - - - - - - - A A A B B - - - - - -   - - - - - - - - - A A B - - F - - - -   - - - - - - - - - A A - - - F - - - -   - - - - - - - - - - - - - - - - I - -   - - - - - - - - - - - - - - - - I - -   - - - - - E - F B E - - B - - - I - -   - - - - - E E W E E - G - - - - - - -   - - - - - - E - V - - R - - - - - - -   - - - - - - - - - - - - - - T - - - -   - - - - - - - - - - - - - - - - - - -   - - - - - - - - - - - - - - - - - - -   - - - - - - - - - - - - - - - - - - -   - - - - - - - - - - - - - - - - - - -   - - - - - - - - - - - - - - - - - - -   - - - - - - - - - - - - - - - - - - -   - - - - - - - - - - - - - - - - - - -   - - - - - - - - - - - - - - - - - - -   - - - - - - - - - - - - - - - - - - -   - - - - - - - - - - - - - - - - - - -   - - - - - - - - - - - - - - - - - - -   - - - - - - - - - - - - - - - - - - -   - - - - - - - - - - - - - - - - - - -   
- - - - - - - - - - - - - - - - - - -   - - - - - - - - - - - - - - - - - - -   - - - - - - - - - - - - - - - - - - -   - - - - - - - - - - - - - - - - - - -   - - - - - - - - - - - - - - - - - - -   - - - - - - - - - - - - - - - - - - -   - - - - - - - - - - - - - - - - - - -   - - - - - - - - - - - - - - - - - - -   - - - - - - - - - - - - - - - - - - -   - - - - - - - - - - - - - - - - - - -   - - - - - - - - - - - - - - H - - - -   - - - - - - - - - - - - - - X - - - -   - - - - - - - - - - - - - - - - - - -   - - - - - - - - N - - - N - - - - - -   - - - - - - - - - - - - M - - - - - -   - - - - - - - - - - - - - - - - - - -   - - - - - - - - - - - - - - - - - - -   - - - - - - - - - - - - - - - - - - -   - - - - - - - - - - - - - - - - - - -   - - - - - - - - - - - - - - - - - - -   - - - - - - - - - - - - - - - - - - -   - - - - - - - - - - - - - - - - - - -   - - - - - - - - - - - - - - - - - - -   - - - - - - - - - - - - - - - - - - -   - - - - - - - - - - - - - - - - - - -   - - - - - - - - - - - - - - - - - - -   - - - - - - - - - - - - - - - - - - -   - - - - - - - - - - - - - - - - - - -   - - - - - - - - - - - - - - - - - - -   - - - - - - - - - - - - - - - - - - -   - - - - - - - - - - - - - - - - - - -   
- - - - - - - - - - - - - - - - - - -   - - - - - - - - - - - - - - - - - - -   - - - - - - - - - - - - - - - - - - -   - - - - - - - - - - - - - - - - - - -   - - - - - - - - - - - - - - - - - - -   - - - - - - - - - - - - - - - - - - -   - - - - - - - - - - - - - - - - - - -   - - - - - - - - - - - - - - - - - - -   - - - - - - - - - - - - - - - - - - -   - - - - - - - - - - - - - - - - - - -   - - - - - - - - - - - - - - - - - - -   - - - - - - - - - - - - - - - - - - -   - - - - - - - - - - - - - - - - - - -   - - - - - - - - - - - - M - - - - - -   - - - - - - - - - - - - - - - - - - -   - - - - - - - - - - - - - - - - - - -   - - - - - - - - - - - - - - - - - - -   - - - - - - - - - - - - - - - - - - -   - - - - - - - - - - - - - - - - - - -   - - - - - - - - - - - - - - - - - - -   - - - - - - - - - - - - - - - - - - -   - - - - - - - - - - - - - - - - - - -   - - - - - - - - - - - - - - - - - - -   - - - - - - - - - - - - - - - - - - -   - - - - - - - - - - - - - - - - - - -   - - - - - - - - - - - - - - - - - - -   - - - - - - - - - - - - - - - - - - -   - - - - - - - - - - - - - - - - - - -   - - - - - - - - - - - - - - - - - - -   - - - - - - - - - - - - - - - - - - -   - - - - - - - - - - - - - - - - - - -   
