model
size = 22 29 24, scale = 0.05, origin = -y
material 
  colors = A:#111 B:#777 C:#F93 D:#100 E:#666 F:#999 G:#EEE H:#FC0 I:#FC6 J:#FFF K:#FC3 L:#D00 M:#800 N:#300 O:#F90 P:#DDD Q:#0F0F0F R:#AAA S:#555 T:#900 U:#C00 V:#200 W:#BBB X:#A00 Y:#500 Z:#966 Aa:#001 Ab:#000 Ac:#996 Ad:#333 Ae:#FC9 Af:#CC6 Ag:#CCC Ah:#C90 Ai:#700 Aj:#E00 Ak:#600 Al:#400
voxels
- - - - - - - - - - - - - - - - - - - - - -   - - - - - - - - - - - - - - - - - - - - - -   - - - - - - - - - - - - - - - - - - - - - -   - - - - - - - - - - - - - - - - - - - - - -   - - - - - - - - - - - - - - - - - - - - - -   - - - - - - - - - - - - - - - - - - - - - -   - - - - - - - - - - - - - - - - - - - - - -   - - - - - - - - - - - - - - - - - - - - - -   - - - - - - - - - - - - - - - - - - - - - -   - - - - - - - - - - - - - - - - - - - - - -   - - - - - - - - - - - - - - - - - - - - - -   - - - - - - - - - - - - - - - - - - - - - -   - - - - - - - - - - - - - - - - - - - - - -   - - - - - - - - - - - - - - - - - - - - - -   - - - - - - - - - - - - - - - - - - - - - -   - - - - - - - - - - - - - - - - - - - - - -   - - - - - - - - - - - - - - - - - - - - - -   - - - - - - - - - - - - - - - - - - - - - -   - - - - - - - - - - - - - - - - - - - - - -   - - - - - - - - - - - - - - - - - - - - - -   - - - - - - - - - - - - - - - - C C - - - -   - - - - - - - - - - - - - - - - C C - - - -   - - - - - - - - - - - - - - - - C C - - - -   - - - - - - - - - - - - - - - - C C - - - -   - - - - - - - - - - - - - - - - - - - - - -   - - - - - - - - - - - - - - - - - - - - - -   - - - - - - - - - - - - - - - - - - - - - -   - - - - - - - - - - - - - - - - - - - - - -   - - - - - - - - - - - - - - - - - - - - - -   
- - - - - - - - - - - - - - - - - - - - - -   - - - - - - - - - - - - - - - - - - - - - -   - - - - - - - - - - - - - - - - - - - - - -   - - - - - - - - - - - - - - - - - - - - - -   - - - - - - - - - - - - - - - - - - - - - -   - - - - - - - - - - - - - - - - - - - - - -   - - - - - - - - - - - - - - - - - - - - - -   - - - - - - - - - - - - - - - - - - - - - -   - - - - - - - - - - - - - - - - - - - - - -   - - - - - - - - - - - - - - - - - - - - - -   - - - - - - - - - - - - - - - - - - - - - -   - - - - - - - - - - - - - - - - - - - - - -   - - - - - - - - - - - - - - - - - - - - - -   - - - - - - - - - - - - - - - - - - - - - -   - - - - - - - - - - - - - - - - - - - - - -   - - - - - - - - - - - - - - - - - - - - - -   - - - - - - - - - - - - - - - - - - - - - -   - - - - - - - - - - - - - - - - - - - - - -   - - - - - - - - - - - - - - - - C C - - - -   - - - - - - - - - - - - - - - C C C - - - -   - - - - - - - - - - - - - - C C C C O - - -   - - - - - - - - - - - - - - C C C C H - - -   - - - - - - - - - - - - - - C C C C H - - -   - - - - - - - - - - - - - - C C C C O - - -   - - - - - - - - - - - - - - - C C C - - - -   - - - - - - - - - - - - - - - - C C - - - -   - - - - - - - - - - - - - - - - - - - - - -   - - - - - - - - - - - - - - - - - - - - - -   - - - - - - - - - - - - - - - - - - - - - -   
- - - - - - - - - - - - - - - - - - - - - -   - - - - - - - - - - - - - - - - - - - - - -   - - - - - - - - - - - - - - - - - - - - - -   - - - - - - - - - - - - - - - - - - - - - -   - - - - - - - - - - - - - - - - - - - - - -   - - - - - - - - - - - - - - - - - - - - - -   - - - - - - - - - - - - - - - - - - - - - -   - - - - - - - - - - - - - - - - - - - - - -   - - - - - - - - - - - - - - - - - - - - - -   - - - - - - - - - - - - - - - - - - - - - -   - - - - - - - - - - - - - - - - - - - - - -   - - - - - - - - - - - - - - - - - - - - - -   - - - - - - - - - - - - - - - - - - - - - -   - - - - - - - - - - - - - - - - - - - - - -   - - - - - - - - - A A A A - - - - - - - - -   - - - - - - - - - - - - - - - - - - - - - -   - - - - - - - - - - - - - - - - - - - - - -   - - - - - - - - - - - - - - - - C C - - - -   - - - - - - - - - - - - - - - C C C - - - -   - - - - - - - - - - - - - - C C C C I I - -   - - - - - - - - - - - - - C C C C C B B - -   - - - - - - - - - - - - - C C C C C A A A -   - - - - - - - - - - - - - C C C C C AbAbAb-   - - - - - - - - - - - - - C C C C C F F - -   - - - - - - - - - - - - - - C C C C I I - -   - - - - - - - - - - - - - - - C C C - - - -   - - - - - - - - - - - - - - - - C C - - - -   - - - - - - - - - - - - - - - - - - - - - -   - - - - - - - - - - - - - - - - - - - - - -   
- - - - - - - - - - - - - - - - - - - - - -   - - - - - - - - - - - - - - - - - - - - - -   - - - - - - - - - - - - - - - - - - - - - -   - - - - - - - - - - - - - - - - - - - - - -   - - - - - - - - - - - - - - - - - - - - - -   - - - - - - - - - - - - - - - - - - - - - -   - - - - - - - - - - - - - - - - - - - - - -   - - - - - - - - - - - - - - - - - - - - - -   - - - - - - - - - - - - - - - - - - - - - -   - - - - - - - - - - - - - - - - - - - - - -   - - - - - - - - - - - - - - - - - - - - - -   - - - - - - - - - - - - - - - - - - - - - -   - - - - - - - - - - B B - - - - - - - - - -   - - - - - - - - - - A A - - - - - - - - - -   - - - - - - - - A A A A A A - - - - - - - -   - - - - - - - - - - A A - - - - - - - - - -   - - - - - - - - - - A A - - - - - - - - - -   - - - - - - - - - - - - - - - C C C - - - -   - - - - - - - - - - - - - - C C C C I I - -   - - - - - - - - - - - - - C C C C C A A A -   - - - - - - - - - - - - - C C C C C D D D -   - - - - - - - - - - - - - C C C C C D D D -   - - - - - - - - - - - - - C C C C C D D D -   - - - - - - - - - - - - - C C C C C D D D -   - - - - - - - - - - - - - C C C C C E E E -   - - - - - - - - - - - - - - C C C C I I - -   - - - - - - - - - - - - - - - C C C - - - -   - - - - - - - - - - - - - - - - - - - - - -   - - - - - - - - - - - - - - - - - - - - - -   
- - - - - - - - - - - - - - - - - - - - - -   - - - - - - - - - - - - - - - - - - - - - -   - - - - - - - - - - - - - - - - - - - - - -   - - - - - - - - - - - - - - - - - - - - - -   - - - - - - - - - - - - - - - - - - - - - -   - - - - - - - - - - - - - - - - - - - - - -   - - - - - - - - - - - - - - - - - - - - - -   - - - - - - - - - - - - - - - - - - - - - -   - - - - - - - - - - - - - - - - - - - - - -   - - - - - - - - - - - - - - - - - - - - - -   - - - - - - - - - - B B - - - - - - - - - -   - - - - - - - - - - B B - - - - - - - - - -   - - - - - - - - - B B B B - - - - - - - - -   - - - - - - - - - A A A A - - - - - - - - -   - - - - - - - A A A A A A A A - - - - - - -   - - - - - - - - - A A A A - - - - - - - - -   - - - - - - - - - A A A A - - - C C - - - -   - - - - - - - - - - A A - - C C C C H - - -   - - - - - - - - - - A A - C C C C C F F - -   - - - - - - - - - - - - - C C C C C B B G -   - - - - - - - - - - - - C C C C C C D D D D   - - - - - - - - - - - - C C C C C C D D D D   - - - - - - - - - - - - C C C C C C D D D D   - - - - - - - - - - - - C C C C C C A A A A   - - - - - - - - - - - - - C C C C C D D D -   - - - - - - - - - - - - - C C C C C AgAg- -   - - - - - - - - - - - - - - C C C C H - - -   - - - - - - - - - - - - - - - - C C - - - -   - - - - - - - - - - - - - - - - - - - - - -   
- - - - - - - - - - - - - - - - - - - - - -   - - - - - - - - - - - - - - - - - - - - - -   - - - - - - - - - - - - - - - - - - - - - -   - - - - - - - - - - - - - - - - - - - - - -   - - - - - - - - - - - - - - - - - - - - - -   - - - - - - - - - - - - - - - - - - - - - -   - - - - - - - - - - - - - - - - - - - - - -   - - - - - - - - - - - - - - - - - - - - - -   - - - - - - - - - - B B - - - - - - - - - -   - - - - - - - - - - B B - - - - - - - - - -   - - - - - - - - - B B B B - - - - - - - - -   - - - - - - - - - B B B B - - - - - - - - -   - - - - - - - - B B B B B B - - - - - - - -   - - - - - - - - A A A A A A - - - - - - - -   - - - - - - A A A A A A A A A A - - - - - -   - - - - - - - - A A A A A A - - - - - - - -   - - - - - - - - A A A A A A - - C C - - - -   - - - - - - - - - A A A A - C C C C H - - -   - - - - - - - - - A A A A C C C C C Q Q Q -   - - - - - - - - - - A A - C C C C C A A A -   - - - - - - - - - - A A C C C C C C D D D D   - - - - - - - - - - - - C C C C C C D D D D   - - - - - - - - - - - - C C C C C C P P P P   - - - - - - - - - - - - C C C C C C G G G G   - - - - - - - - - - - - - C C C C C A A A -   - - - - - - - - - - - - - C C C C C F F F -   - - - - - - - - - - - - - - C C C C H - - -   - - - - - - - - - - - - - - - - C C - - - -   - - - - - - - - - - - - - - - - - - - - - -   
- - - - - - - - - - - - - - - - - - - - - -   - - - - - - - - - - - - - - - - - - - - - -   - - - - - - - - - - - - - - - - - - - - - -   - - - - - - - - - - - - - - - - - - - - - -   - - - - - - - - - - - - - - - - - - - - - -   - - - - - - - - - - - - - - - - - - - - - -   - - - - - - - - - - - - - - - - - - - - - -   - - - - - - - - - - - - - - - - - - - - - -   - - - - - - - - - B B B B - - - - - - - - -   - - - - - - - - - B B B B - - - - - - - - -   - - - - - - - - B B B B B B - - - - - - - -   - - - - - - - - B B B B B B - - - - - - - -   - - - - - - - B B B B B B B B - - - - - - -   - - - - - - - A A A A A A A A - - - - - - -   - - - - - A A A A A A A A A A A A - - - - -   - - - - - - - A A A A A A A A - - - - - - -   - - - - - - - A A A A A A A A - C C - - - -   - - - - - - - - A A A A A A C C C C H - - -   - - - - - - - - A A A A A C C C C C AdAdAd-   - - - - - - - - - A A A A C C C C C D D D -   - - - - - - - - - A A A C C C C C C D D D D   - - - - - - - - - - - - C C C C C C A A A A   - - - - - - - - - - - - C C C C C C J J J J   - - - - - - - - - - - - C C C C C C J J J J   - - - - - - - - - - - - - C C C C C Q Q Q -   - - - - - - - - - - - - - C C C C C F F F -   - - - - - - - - - - - - - - C C C C H - - -   - - - - - - - - - - - - - - - - C C - - - -   - - - - - - - - - - - - - - - - - - - - - -   
- - - - - - - - - - - - - - - - - - - - - -   - - - - - - - - - - - - - - - - - - - - - -   - - - - - - - - - - - - - - - - - - - - - -   - - - - - - - - - - - - - - - - - - - - - -   - - - - - - - - - - - - - - - - - - - - - -   - - - - - - - - - - - - - - - - - - - - - -   - - - - - - - - - - B B - - - - - - - - - -   - - - - - - - - - - B B - - - - - - - - - -   - - - - - - - - B B B B B B - - - - - - - -   - - - - - - - - B B B B B B - - - - - - - -   - - - - - - - B B B B B B B B - - - - - - -   - - - - - - - B B B B B B B B - - D D D - -   - - - - - - B B B B B B B B B B - D D D - -   - - - - - - A A A A A A A A A A - D D D - -   - - - - A A A A A A A A A A A A A D D D - -   - - - - - - A A A A A A A A A A - - - - - -   - - - - - - A A A A A A A A A A C C - - - -   - - - - - - - A A A A A A A C C C C Ah- - -   - - - - - - - A A A A A A C C C C C R R - -   - - - - - - - - A A A A A C C C C C D D D -   - - - - - - - - A A A A C C C C C C D D D D   - - - - - - - - - - A A C C C C C C A A A A   - - - - - - - - - - A A C C C C C C G G G G   - - - - - - - - - - - - C C C C C C W W W W   - - - - - - - - - - - - - C C C C C AaAaAa-   - - - - - - - - - - - - - C C C C C P P - -   - - - - - - - - - - - - - - C C C C Ah- - -   - - - - - - - - - - - - - - - - C C - - - -   - - - - - - - - - - - - - - - - - - - - - -   
- - - - - - - - - - - - - - - - - - - - - -   - - - - - - - - - - - - - - - - - - - - - -   - - - - - - - - - - - - - - - - - - - - - -   - - - - - - - - - - - - - - - - - - - - - -   - - - - - - - - - - B B - - - - - - - - - -   - - - - - - - - - - B B - - - - - - - - - -   - - - - - - - - - B B B B - - - - - - - - -   - - - - - - - - - B B B B - - - - - - - - -   - - - - - - - B B B B B B B B - - D D D - -   - - - - - - - B B B B B B B B - - D D D - -   - - - - - - B B B B B B B B B B - D D D - -   - - - - - - B B B B B B B B B B - N N N - -   - - - - - B B B B B B B B B B B B D D D - -   - - - - - A A A A A A A A A A A A S S S - -   - - - A A A A A A A A A A A A A A D D D - -   - - - - - A A A A A A A A A A A A - - - - -   - - - - - A A A A A A A A A A A A - - - - -   - - - - - - A A A A A A A A A C C C - - - -   - - - - - - A A A A A A A A C C C C K K - -   - - - - - - - A A A A A A C C C C C S S S -   - - - - - - - A A A A A A C C C C C D D D -   - - - - - - - - - A A A A C C C C C D D D -   - - - - - - - - - A A A A C C C C C D D D -   - - - - - - - - - - A A - C C C C C D D D -   - - - - - - - - - - A A - C C C C C R R R -   - - - - - - - - - - - - - - C C C C K K - -   - - - - - - - - - - - - - - - C C C - - - -   - - - - - - - - - - - - - - - - - - - - - -   - - - - - - - - - - - - - - - - - - - - - -   
- - - - - - - - - - - - - - - - - - - - - -   - - - - - - - - - - - - - - - - - - - - - -   - - - - - - - - - - - - - - - - - - - - - -   - - - - - - - - - - - - - - - - - - - - - -   - - - - - - - - - B B B B - - - - - - - - -   - - - - - - - - - B B B B - - - - - - - - -   - - - - - - - - B B B B B B - - - D D D - -   - - - - - - - - B B B B B B - - - D D D - -   - - - - - - B B B B B B B B B B - X X X - -   - - - - - - B B B B B B B B B B - V V V - -   - - - - - B B B B B B B B B B B B N N N - -   - - - - - B B B B B B B B B B B B T T T - -   - - - - B B B B B B B B B B B B B D D D - -   - - - - A A A A A A A A A A A A A E E E - -   - - A A A A A A A A A A A A A A A D D D - -   - - - - A A A A A A A A A A A A A A - - - -   - - - - A A A A A A A A A A A A A A - - - -   - - - - - A A A A A A A A A A A C C - - - -   - - - - - A A A A A A A A A A C C C - - - -   - - - - - - A A A A A A A A C C C C K K - -   - - - - - - A A A A A A A C C C C C AfAf- -   - - - - - - - - A A A A A C C C C C Z Z Z -   - - - - - - - - A A A A A C C C C C AcAcAc-   - - - - - - - - - A A A A C C C C C AeAe- -   - - - - - - - - - A A A A - C C C C K K - -   - - - - - - - - - - - - - - - C C C - - - -   - - - - - - - - - - - - - - - - C C - - - -   - - - - - - - - - - - - - - - - - - - - - -   - - - - - - - - - - - - - - - - - - - - - -   
- - - - - - - - - - - - - - - - - - - - - -   - - - - - - - - - - - - - - - - - - - - - -   - - - - - - - - - - B B - - - - - - - - - -   - - - - - - - - - - B B - - - - - - - - - -   - - - - - - - - B B B B B B - - - - - - - -   - - - - - - - - B B B B B B - - - - - - - -   - - - - - - - B B B B B B B B - - D D D - -   - - - - - - - B B B B B B B B - - U U U - -   - - - - - B B B B B B B B B B B B AjAjAj- -   - - - - - B B B B B B B B B B B B Y Y Y - -   - - - - B B B B B B B B B B B B B D D D - -   - - - - B B B B B B B B B B B B B M M M - -   - - - B B B B B B B B B B B B B B D D D - -   - - - A A A A A A A A A A A A A A E E E - -   - A A A A A A A A A A A A A A A A D D D - -   - - - A A A A A A A A A A A A A A A A - - -   - - - A A A A A A A A A A A A A A A A - - -   - - - - A A A A A A A A A A A A A A - - - -   - - - - A A A A A A A A A A A A C C - - - -   - - - - - A A A A A A A A A A C C C - - - -   - - - - - A A A A A A A A A C C C C O - - -   - - - - - - - A A A A A A A C C C C O - - -   - - - - - - - A A A A A A A C C C C O - - -   - - - - - - - - A A A A A A C C C C O - - -   - - - - - - - - A A A A A A - C C C - - - -   - - - - - - - - - - A A - - - - C C - - - -   - - - - - - - - - - A A - - - - - - - - - -   - - - - - - - - - - - - - - - - - - - - - -   - - - - - - - - - - - - - - - - - - - - - -   
- - - - - - - - - - B B - - - - - - - - - -   - - - - - - - - - - B B - - - - - - - - - -   - - - - - - - - - B B B B - - - - - - - - -   - - - - - - - - - B B B B - - - - - - - - -   - - - - - - - B B B B B B B B - - - - - - -   - - - - - - - B B B B B B B B - - D D D - -   - - - - - - B B B B B B B B B B - M M M - -   - - - - - - B B B B B B B B B B - L L L - -   - - - - B B B B B B B B B B B B B L L L - -   - - - - B B B B B B B B B B B B B Y Y Y - -   - - - B B B B B B B B B B B B B B D D D - -   - - - B B B B B B B B B B B B B B M M M - -   - - B B B B B B B B B B B B B B B D D D - -   - - A A A A A A A A A A A A A A A E E E - -   A A A A A A A A A A A A A A A A A D D D - -   - - A A A A A A A A A A A A A A A A A A - -   - - A A A A A A A A A A A A A A A A A A - -   - - - A A A A A A A A A A A A A A A A - - -   - - - A A A A A A A A A A A A A A A A - - -   - - - - A A A A A A A A A A A A A A - - - -   - - - - A A A A A A A A A A A A C A - - - -   - - - - - - A A A A A A A A A A C A - - - -   - - - - - - A A A A A A A A A A C A - - - -   - - - - - - - A A A A A A A A - C A - - - -   - - - - - - - A A A A A A A A - - - - - - -   - - - - - - - - - A A A A - - - - - - - - -   - - - - - - - - - A A A A - - - - - - - - -   - - - - - - - - - - A A - - - - - - - - - -   - - - - - - - - - - A A - - - - - - - - - -   
- - - - - - - - - B B B B - - - - - - - - -   - - - - - - - - - B B B B - - - - - - - - -   - - - - - - - - B B B B B B - - - - - - - -   - - - - - - - - B B B B B B - - - - - - - -   - - - - - - B B B B B B B B B B - - - - - -   - - - - - - B B B B B B B B B B - D D D - -   - - - - - B B B B B B B B B B B B X X X - -   - - - - - B B B B B B B B B B B B L L L - -   - - - B B B B B B B B B B B B B B L L L - -   - - - B B B B B B B B B B B B B B AkAkAk- -   - - B B B B B B B B B B B B B B B D D D - -   - - B B B B B B B B B B B B B B B M M M - -   - B B B B B B B B B B B B B B B B D D D - -   - A A A A A A A A A A A A A A A A E E E - -   A A A A A A A A A A A A A A A A A D D D - -   - A A A A A A A A A A A A A A A A A A A A -   - A A A A A A A A A A A A A A A A A A A A -   - - A A A A A A A A A A A A A A A A A A - -   - - A A A A A A A A A A A A A A A A A A - -   - - - A A A A A A A A A A A A A A A A - - -   - - - A A A A A A A A A A A A A C C A - - -   - - - - - A A A A A A A A A A A C A - - - -   - - - - - A A A A A A A A A A A C A - - - -   - - - - - - A A A A A A A A A A C A - - - -   - - - - - - A A A A A A A A A A - - - - - -   - - - - - - - - A A A A A A - - - - - - - -   - - - - - - - - A A A A A A - - - - - - - -   - - - - - - - - - A A A A - - - - - - - - -   - - - - - - - - - A A A A - - - - - - - - -   
- - - - - - - - - - B B - - - - - - - - - -   - - - - - - - - - - B B - - - - - - - - - -   - - - - - - - - - B B B B - - - - - - - - -   - - - - - - - - - B B B B - - - - - - - - -   - - - - - - - B B B B B B B B - - - - - - -   - - - - - - - B B B B B B B B - - - - - - -   - - - - - - B B B B B B B B B B - D D D - -   - - - - - - B B B B B B B B B B - U U U - -   - - - - B B B B B B B B B B B B B L L L - -   - - - - B B B B B B B B B B B B B AlAlAl- -   - - - B B B B B B B B B B B B B B V V V - -   - - - B B B B B B B B B B B B B B T T T - -   - - B B B B B B B B B B B B B B B D D D - -   - - A A A A A A A A A A A A A A A E E E - -   A A A A A A A A A A A A A A A A A D D D - -   - - A A A A A A A A A A A A A A A A A A - -   - - A A A A A A A A A A A A A A A A A A - -   - - - A A A A A A A A A A A A A A A A - - -   - - - A A A A A A A A A A A A A C C A - - -   - - - - A A A A A A A A A A A C C C - - - -   - - - - A A A A A A A A A A C C C C O - - -   - - - - - - A A A A A A A A C C C C H - - -   - - - - - - A A A A A A A A C C C C H - - -   - - - - - - - A A A A A A A C C C C O - - -   - - - - - - - A A A A A A A A C C C - - - -   - - - - - - - - - A A A A - - - C C - - - -   - - - - - - - - - A A A A - - - - - - - - -   - - - - - - - - - - A A - - - - - - - - - -   - - - - - - - - - - A A - - - - - - - - - -   
- - - - - - - - - - - - - - - - - - - - - -   - - - - - - - - - - - - - - - - - - - - - -   - - - - - - - - - - B B - - - - - - - - - -   - - - - - - - - - - B B - - - - - - - - - -   - - - - - - - - B B B B B B - - - - - - - -   - - - - - - - - B B B B B B - - - - - - - -   - - - - - - - B B B B B B B B - - D D D - -   - - - - - - - B B B B B B B B - - D D D - -   - - - - - B B B B B B B B B B B B U U U - -   - - - - - B B B B B B B B B B B B V V V - -   - - - - B B B B B B B B B B B B B N N N - -   - - - - B B B B B B B B B B B B B T T T - -   - - - B B B B B B B B B B B B B B D D D - -   - - - A A A A A A A A A A A A A A E E E - -   - A A A A A A A A A A A A A A A A D D D - -   - - - A A A A A A A A A A A A A A A A - - -   - - - A A A A A A A A A A A A A A A A - - -   - - - - A A A A A A A A A A A A C C - - - -   - - - - A A A A A A A A A A A C C C - - - -   - - - - - A A A A A A A A A C C C C I I - -   - - - - - A A A A A A A A C C C C C B B - -   - - - - - - - A A A A A A C C C C C A A A -   - - - - - - - A A A A A A C C C C C AbAbAb-   - - - - - - - - A A A A A C C C C C F F - -   - - - - - - - - A A A A A A C C C C I I - -   - - - - - - - - - - A A - - - C C C - - - -   - - - - - - - - - - A A - - - - C C - - - -   - - - - - - - - - - - - - - - - - - - - - -   - - - - - - - - - - - - - - - - - - - - - -   
- - - - - - - - - - - - - - - - - - - - - -   - - - - - - - - - - - - - - - - - - - - - -   - - - - - - - - - - - - - - - - - - - - - -   - - - - - - - - - - - - - - - - - - - - - -   - - - - - - - - - B B B B - - - - - - - - -   - - - - - - - - - B B B B - - - - - - - - -   - - - - - - - - B B B B B B - - - - - - - -   - - - - - - - - B B B B B B - - - - - - - -   - - - - - - B B B B B B B B B B - D D D - -   - - - - - - B B B B B B B B B B - D D D - -   - - - - - B B B B B B B B B B B B N N N - -   - - - - - B B B B B B B B B B B B AiAiAi- -   - - - - B B B B B B B B B B B B B D D D - -   - - - - A A A A A A A A A A A A A B B B - -   - - A A A A A A A A A A A A A A A D D D - -   - - - - A A A A A A A A A A A A A A - - - -   - - - - A A A A A A A A A A A A A A - - - -   - - - - - A A A A A A A A A A C C C - - - -   - - - - - A A A A A A A A A C C C C I I - -   - - - - - - A A A A A A A C C C C C A A A -   - - - - - - A A A A A A A C C C C C D D D -   - - - - - - - - A A A A A C C C C C D D D -   - - - - - - - - A A A A A C C C C C D D D -   - - - - - - - - - A A A A C C C C C D D D -   - - - - - - - - - A A A A C C C C C E E E -   - - - - - - - - - - - - - - C C C C I I - -   - - - - - - - - - - - - - - - C C C - - - -   - - - - - - - - - - - - - - - - - - - - - -   - - - - - - - - - - - - - - - - - - - - - -   
- - - - - - - - - - - - - - - - - - - - - -   - - - - - - - - - - - - - - - - - - - - - -   - - - - - - - - - - - - - - - - - - - - - -   - - - - - - - - - - - - - - - - - - - - - -   - - - - - - - - - - B B - - - - - - - - - -   - - - - - - - - - - B B - - - - - - - - - -   - - - - - - - - - B B B B - - - - - - - - -   - - - - - - - - - B B B B - - - - - - - - -   - - - - - - - B B B B B B B B - - - - - - -   - - - - - - - B B B B B B B B - - - - - - -   - - - - - - B B B B B B B B B B - D D D - -   - - - - - - B B B B B B B B B B - D D D - -   - - - - - B B B B B B B B B B B B D D D - -   - - - - - A A A A A A A A A A A A D D D - -   - - - A A A A A A A A A A A A A A D D D - -   - - - - - A A A A A A A A A A A A - - - - -   - - - - - A A A A A A A A A A A C C - - - -   - - - - - - A A A A A A A A C C C C H - - -   - - - - - - A A A A A A A C C C C C F F - -   - - - - - - - A A A A A A C C C C C B B G -   - - - - - - - A A A A A C C C C C C D D D D   - - - - - - - - - A A A C C C C C C D D D D   - - - - - - - - - A A A C C C C C C D D D D   - - - - - - - - - - A A C C C C C C A A A A   - - - - - - - - - - A A - C C C C C D D D -   - - - - - - - - - - - - - C C C C C AgAg- -   - - - - - - - - - - - - - - C C C C H - - -   - - - - - - - - - - - - - - - - C C - - - -   - - - - - - - - - - - - - - - - - - - - - -   
- - - - - - - - - - - - - - - - - - - - - -   - - - - - - - - - - - - - - - - - - - - - -   - - - - - - - - - - - - - - - - - - - - - -   - - - - - - - - - - - - - - - - - - - - - -   - - - - - - - - - - - - - - - - - - - - - -   - - - - - - - - - - - - - - - - - - - - - -   - - - - - - - - - - B B - - - - - - - - - -   - - - - - - - - - - B B - - - - - - - - - -   - - - - - - - - B B B B B B - - - - - - - -   - - - - - - - - B B B B B B - - - - - - - -   - - - - - - - B B B B B B B B - - - - - - -   - - - - - - - B B B B B B B B - - - - - - -   - - - - - - B B B B B B B B B B - - - - - -   - - - - - - A A A A A A A A A A - - - - - -   - - - - A A A A A A A A A A A A A A - - - -   - - - - - - A A A A A A A A A A - - - - - -   - - - - - - A A A A A A A A A A C C - - - -   - - - - - - - A A A A A A A C C C C H - - -   - - - - - - - A A A A A A C C C C C Q Q Q -   - - - - - - - - A A A A A C C C C C A A A -   - - - - - - - - A A A A C C C C C C D D D D   - - - - - - - - - - A A C C C C C C D D D D   - - - - - - - - - - A A C C C C C C P P P P   - - - - - - - - - - - - C C C C C C G G G G   - - - - - - - - - - - - - C C C C C A A A -   - - - - - - - - - - - - - C C C C C F F F -   - - - - - - - - - - - - - - C C C C H - - -   - - - - - - - - - - - - - - - - C C - - - -   - - - - - - - - - - - - - - - - - - - - - -   
- - - - - - - - - - - - - - - - - - - - - -   - - - - - - - - - - - - - - - - - - - - - -   - - - - - - - - - - - - - - - - - - - - - -   - - - - - - - - - - - - - - - - - - - - - -   - - - - - - - - - - - - - - - - - - - - - -   - - - - - - - - - - - - - - - - - - - - - -   - - - - - - - - - - - - - - - - - - - - - -   - - - - - - - - - - - - - - - - - - - - - -   - - - - - - - - - B B B B - - - - - - - - -   - - - - - - - - - B B B B - - - - - - - - -   - - - - - - - - B B B B B B - - - - - - - -   - - - - - - - - B B B B B B - - - - - - - -   - - - - - - - B B B B B B B B - - - - - - -   - - - - - - - A A A A A A A A - - - - - - -   - - - - - A A A A A A A A A A A A - - - - -   - - - - - - - A A A A A A A A - - - - - - -   - - - - - - - A A A A A A A A - C C - - - -   - - - - - - - - A A A A A A C C C C H - - -   - - - - - - - - A A A A A C C C C C AdAdAd-   - - - - - - - - - A A A A C C C C C D D D -   - - - - - - - - - A A A C C C C C C D D D D   - - - - - - - - - - - - C C C C C C A A A A   - - - - - - - - - - - - C C C C C C J J J J   - - - - - - - - - - - - C C C C C C J J J J   - - - - - - - - - - - - - C C C C C Q Q Q -   - - - - - - - - - - - - - C C C C C F F F -   - - - - - - - - - - - - - - C C C C H - - -   - - - - - - - - - - - - - - - - C C - - - -   - - - - - - - - - - - - - - - - - - - - - -   
- - - - - - - - - - - - - - - - - - - - - -   - - - - - - - - - - - - - - - - - - - - - -   - - - - - - - - - - - - - - - - - - - - - -   - - - - - - - - - - - - - - - - - - - - - -   - - - - - - - - - - - - - - - - - - - - - -   - - - - - - - - - - - - - - - - - - - - - -   - - - - - - - - - - - - - - - - - - - - - -   - - - - - - - - - - - - - - - - - - - - - -   - - - - - - - - - - B B - - - - - - - - - -   - - - - - - - - - - B B - - - - - - - - - -   - - - - - - - - - B B B B - - - - - - - - -   - - - - - - - - - B B B B - - - - - - - - -   - - - - - - - - B B B B B B - - - - - - - -   - - - - - - - - A A A A A A - - - - - - - -   - - - - - - A A A A A A A A A A - - - - - -   - - - - - - - - A A A A A A - - - - - - - -   - - - - - - - - A A A A A A - - C C - - - -   - - - - - - - - - A A A A - C C C C Ah- - -   - - - - - - - - - A A A A C C C C C R R - -   - - - - - - - - - - A A - C C C C C D D D -   - - - - - - - - - - A A C C C C C C D D D D   - - - - - - - - - - - - C C C C C C A A A A   - - - - - - - - - - - - C C C C C C G G G G   - - - - - - - - - - - - C C C C C C W W W W   - - - - - - - - - - - - - C C C C C AaAaAa-   - - - - - - - - - - - - - C C C C C P P - -   - - - - - - - - - - - - - - C C C C Ah- - -   - - - - - - - - - - - - - - - - C C - - - -   - - - - - - - - - - - - - - - - - - - - - -   
- - - - - - - - - - - - - - - - - - - - - -   - - - - - - - - - - - - - - - - - - - - - -   - - - - - - - - - - - - - - - - - - - - - -   - - - - - - - - - - - - - - - - - - - - - -   - - - - - - - - - - - - - - - - - - - - - -   - - - - - - - - - - - - - - - - - - - - - -   - - - - - - - - - - - - - - - - - - - - - -   - - - - - - - - - - - - - - - - - - - - - -   - - - - - - - - - - - - - - - - - - - - - -   - - - - - - - - - - - - - - - - - - - - - -   - - - - - - - - - - B B - - - - - - - - - -   - - - - - - - - - - B B - - - - - - - - - -   - - - - - - - - - B B B B - - - - - - - - -   - - - - - - - - - A A A A - - - - - - - - -   - - - - - - - A A A A A A A A - - - - - - -   - - - - - - - - - A A A A - - - - - - - - -   - - - - - - - - - A A A A - - - - - - - - -   - - - - - - - - - - A A - - - C C C - - - -   - - - - - - - - - - A A - - C C C C K K - -   - - - - - - - - - - - - - C C C C C S S S -   - - - - - - - - - - - - - C C C C C D D D -   - - - - - - - - - - - - - C C C C C D D D -   - - - - - - - - - - - - - C C C C C D D D -   - - - - - - - - - - - - - C C C C C D D D -   - - - - - - - - - - - - - C C C C C R R R -   - - - - - - - - - - - - - - C C C C K K - -   - - - - - - - - - - - - - - - C C C - - - -   - - - - - - - - - - - - - - - - - - - - - -   - - - - - - - - - - - - - - - - - - - - - -   
- - - - - - - - - - - - - - - - - - - - - -   - - - - - - - - - - - - - - - - - - - - - -   - - - - - - - - - - - - - - - - - - - - - -   - - - - - - - - - - - - - - - - - - - - - -   - - - - - - - - - - - - - - - - - - - - - -   - - - - - - - - - - - - - - - - - - - - - -   - - - - - - - - - - - - - - - - - - - - - -   - - - - - - - - - - - - - - - - - - - - - -   - - - - - - - - - - - - - - - - - - - - - -   - - - - - - - - - - - - - - - - - - - - - -   - - - - - - - - - - - - - - - - - - - - - -   - - - - - - - - - - - - - - - - - - - - - -   - - - - - - - - - - B B - - - - - - - - - -   - - - - - - - - - - A A - - - - - - - - - -   - - - - - - - - A A A A A A - - - - - - - -   - - - - - - - - - - A A - - - - - - - - - -   - - - - - - - - - - A A - - - - - - - - - -   - - - - - - - - - - - - - - - - C C - - - -   - - - - - - - - - - - - - - - C C C - - - -   - - - - - - - - - - - - - - C C C C K K - -   - - - - - - - - - - - - - C C C C C AfAf- -   - - - - - - - - - - - - - C C C C C Z Z Z -   - - - - - - - - - - - - - C C C C C AcAcAc-   - - - - - - - - - - - - - C C C C C AeAe- -   - - - - - - - - - - - - - - C C C C K K - -   - - - - - - - - - - - - - - - C C C - - - -   - - - - - - - - - - - - - - - - C C - - - -   - - - - - - - - - - - - - - - - - - - - - -   - - - - - - - - - - - - - - - - - - - - - -   
- - - - - - - - - - - - - - - - - - - - - -   - - - - - - - - - - - - - - - - - - - - - -   - - - - - - - - - - - - - - - - - - - - - -   - - - - - - - - - - - - - - - - - - - - - -   - - - - - - - - - - - - - - - - - - - - - -   - - - - - - - - - - - - - - - - - - - - - -   - - - - - - - - - - - - - - - - - - - - - -   - - - - - - - - - - - - - - - - - - - - - -   - - - - - - - - - - - - - - - - - - - - - -   - - - - - - - - - - - - - - - - - - - - - -   - - - - - - - - - - - - - - - - - - - - - -   - - - - - - - - - - - - - - - - - - - - - -   - - - - - - - - - - - - - - - - - - - - - -   - - - - - - - - - - - - - - - - - - - - - -   - - - - - - - - - A A A A - - - - - - - - -   - - - - - - - - - - - - - - - - - - - - - -   - - - - - - - - - - - - - - - - - - - - - -   - - - - - - - - - - - - - - - - - - - - - -   - - - - - - - - - - - - - - - - C C - - - -   - - - - - - - - - - - - - - - C C C - - - -   - - - - - - - - - - - - - - C C C C O - - -   - - - - - - - - - - - - - - C C C C O - - -   - - - - - - - - - - - - - - C C C C O - - -   - - - - - - - - - - - - - - C C C C O - - -   - - - - - - - - - - - - - - - C C C - - - -   - - - - - - - - - - - - - - - - C C - - - -   - - - - - - - - - - - - - - - - - - - - - -   - - - - - - - - - - - - - - - - - - - - - -   - - - - - - - - - - - - - - - - - - - - - -   
- - - - - - - - - - - - - - - - - - - - - -   - - - - - - - - - - - - - - - - - - - - - -   - - - - - - - - - - - - - - - - - - - - - -   - - - - - - - - - - - - - - - - - - - - - -   - - - - - - - - - - - - - - - - - - - - - -   - - - - - - - - - - - - - - - - - - - - - -   - - - - - - - - - - - - - - - - - - - - - -   - - - - - - - - - - - - - - - - - - - - - -   - - - - - - - - - - - - - - - - - - - - - -   - - - - - - - - - - - - - - - - - - - - - -   - - - - - - - - - - - - - - - - - - - - - -   - - - - - - - - - - - - - - - - - - - - - -   - - - - - - - - - - - - - - - - - - - - - -   - - - - - - - - - - - - - - - - - - - - - -   - - - - - - - - - - - - - - - - - - - - - -   - - - - - - - - - - - - - - - - - - - - - -   - - - - - - - - - - - - - - - - - - - - - -   - - - - - - - - - - - - - - - - - - - - - -   - - - - - - - - - - - - - - - - - - - - - -   - - - - - - - - - - - - - - - - - - - - - -   - - - - - - - - - - - - - - - - C C - - - -   - - - - - - - - - - - - - - - - C C - - - -   - - - - - - - - - - - - - - - - C C - - - -   - - - - - - - - - - - - - - - - C C - - - -   - - - - - - - - - - - - - - - - - - - - - -   - - - - - - - - - - - - - - - - - - - - - -   - - - - - - - - - - - - - - - - - - - - - -   - - - - - - - - - - - - - - - - - - - - - -   - - - - - - - - - - - - - - - - - - - - - -   
