model
size = 13 32 22, scale = 0.05, origin = -y
material 
  colors = A:#100 B:#EEE C:#FC9 D:#963 E:#633 F:#FC6 G:#C63 H:#C93 I:#C96 J:#111 K:#330 L:#F96 M:#222 N:#663 O:#933 P:#996 Q:#333 R:#444 S:#966 T:#FFC U:#CC9 V:#630 W:#BBB X:#555 Y:#C99 Z:#888 Aa:#DDD Ab:#666 Ac:#CC6 Ad:#FCC
voxels
117-2A11-3A10-4A9-5A8-6(6A7-)2(7A6-)3(6A7-)5A8-2(4A9-)2A154-A12-3A10-A-2A9-K2-2K8-D3-2D7-H4-2H6-D5-D6-E5-E6-J5-J6-A4-A7-2(A5-A6-)2(A6-A5-)A5-2A2(5-A)6-A5-A6-A4-A2(7-A3-2A)7-A-3A8-2A89-A12-2A11-3A10-2(4A9-)K2-2K8-D3-2D7-I4-2I3(6-C5-C)6-F5-F6-I5-I6-G5-2B5-D5-2B5-V6-V5-D6-D5-E6-E5-M6-M5-A6-2(A5-)2(A6-A5-)A6-2(A4-A7-)A-3A8-3A62-4(3A11-)3K10-3D11-2G12-J13-J2(12-C)12-L11-BH10-2B2M8-3B2E8-3B3Q8-2B2J10-BZH12-L12-C11-I12-J11-E12-J12-2(A11-)2A10-A9-3A36-4A12-A13-2K12-2D12-G12-O13-2(J12-)2(E12-)2(J12-)J10-2B2R8-3B2S2(B7-3B2D)B7-3B2NB7-3B2J12-D12-F12-C11-P12-M12-F11-K2(12-A)2(10-2A)8-3A10-2A13-4O11-3H12-H13-L12-I12-A12-D2(12-I)13-F2(12-C)10-2BG8-3B2E8-3B2UB6-4B3E6-4B3A6-7B7-3B3P8-2BRD12-L12-C11-Q12-Ab2(12-F)11-D12-A11-A12-A8-4A9-5E2(13-H)12-I12-F13-C12-E12-J12-I2(12-L)2(12-C)10-2BC8-3B3N7-3B2YB6-4B3K6-4B3A6-4B2DB7-3B3E8-2BRO12-F12-I12-M12-U11-2(F12-)C11-E12-A11-A10-2A9-6G13-F12-L12-C13-H12-E12-L12-A12-E12-H13-2(F12-)C12-C8-2B2Q8-3B2SB6-4B2PB6-4B2(2DB7-3B)2E10-BWD12-Ac12-A12-N12-C12-F11-F12-C11-I12-2(A11-)A9-6G13-F12-C12-L13-G2(12-E)13-E12-A2(12-C)13-2I11-2F11-L8-2B-CF6-3B2MC2(7-3B3E)7-3B2E9-2B2XO12-G12-F11-N2(12-C)12-F11-C12-F11-F12-E2(11-A)9-7D12-F13-C12-L11-H13-H12-A13-D12-A12-C13-V14-F12-C11-F12-2(H11-)I11-I12-H13-H12-L12-C11-3(C12-)F11-C12-F12-C11-E2(11-A)9-7G12-C13-C12-C11-G13-I12-A13-D12-A12-C13-3G12-C12-T11-T12-2(C11-)C12-T11-7(C12-)F11-F12-F11-I12-2(A11-)A9-7D12-F13-C12-F11-G13-G12-A13-H12-A12-C13-3H12-C12-T11-T12-2(C11-)T12-T11-3(C12-)2(Ad12-)2(C12-)F11-C12-F11-I12-2(A11-)A9-7D12-F13-C12-L11-H13-H12-A13-D12-A12-C13-2V13-F12-C11-F12-2(H11-)I11-I12-H13-H12-L12-C11-3(C12-)F11-C12-F12-C11-E2(11-A)9-6G13-F12-C12-L13-G2(12-E)13-E12-A2(12-C)13-2I11-2F11-L8-B2-CF7-2B2MC7-3B2E8-3B3Q8-2B2J10-BZ-O12-G12-F11-N2(12-C)12-F11-C12-F11-F12-E2(11-A)9-6G13-F12-L12-C13-H12-E12-L12-A12-E12-H13-2(F12-)C12-C8-2B2R8-3B2S2(B7-3B2D)B7-3B2NB7-3B2J12-D12-Ac12-A12-N12-C12-F11-F12-C11-I12-2(A11-)A9-5E2(13-H)12-I12-F13-C12-E12-J12-I2(12-L)2(12-C)10-2BC8-3B2E8-3B2UB6-4B3E6-4B3A6-7B7-3B3P8-2BRO12-F12-I12-M12-U11-2(F12-)C11-E12-A11-A10-2A8-2A13-4O11-3H12-H13-L12-I12-A12-D2(12-I)13-F2(12-C)10-2BG8-3B3N7-3B2YB6-4B3K6-4B3A6-4B2DB7-3B3E8-2BRD12-L12-C11-Q12-Ab2(12-F)11-D12-A11-A12-A8-4A21-4A12-A13-2K12-2D12-G12-O13-2(J12-)2(E12-)2(J12-)J10-2B2Q8-3B2SB6-4B2PB6-4B2(2DB7-3B)2E10-BWD12-F12-C11-P12-M12-F11-K2(12-A)2(10-2A)8-3A36-4(3A11-)3K10-3D11-2G12-J13-J2(12-C)12-L11-2B9-3B2M8-2(3B3E7-)3B2E9-2B2X12-L12-C11-I12-J11-E12-J12-2(A11-)2A10-A9-3A62-A12-2A11-3A10-2(4A9-)K2-2K8-D3-2D7-I4-2I3(6-C5-C)6-F5-F6-I5-I6-G4-B2Aa5-D4-B2W5-V5-2B5-D6-D5-E6-E5-M6-M5-A6-2(A5-)2(A6-A5-)A6-2(A4-A7-)A-3A8-3A127-A12-3A10-A-2A9-K2-2K8-D3-2D7-H4-2H6-D5-D6-E5-E6-J5-J6-A4-A7-2(A5-A6-)2(A6-A5-)A5-2A2(5-A)6-A5-A6-A4-A2(7-A3-2A)7-A-3A8-2A167-2A11-3A10-4A9-5A8-6(6A7-)2(7A6-)3(6A7-)5A8-2(4A9-)2A63-
