model
size = 19 31 30, scale = 0.05, origin = -y
material 
  colors = A:#BBB B:#A00 C:#111 D:#222 E:#444 F:#EEE G:#333 H:#633 I:#777 J:#555 K:#0F3 L:#888 M:#336 N:#966 O:#999 P:#963 Q:#666 R:#369 S:#969 T:#96F U:#100 V:#96C W:#36C X:#669 Y:#663 Z:#996 Aa:#C99 Ab:#66C Ac:#330 Ad:#FC0 Ae:#CC9 Af:#99C Ag:#39C Ah:#700 Ai:#933 Aj:#DDD Ak:#9CF
voxels
- - - - - - - - - - - - - - - - - - -   - - - - - - - - - - - - - - - - - - -   - - - - - - - - - - - - - - - - - - -   - - - - - - - - - - - - - - - - - - -   - - - - - - - - B B - - - - - - - - -   - - - - - - - B B B B - - - - - - - -   - - - - - - - B B B B - - - - - - - -   - - - - - - - B B B B - - - - - - - -   - - - - - - - - B B - - - - - - - - -   - - - - - - - C C C C - - - - - - - -   - - - - - - - C C C C - - - - - - - -   - - - - - - - - C C - - - - - - - - -   - - - - - - - - C C - - - - - - - - -   - - - - - - - C C C C - - - - - - - -   - - - - - - - C C C C - - - - - - - -   - - - - - - - - C C - - - - - - - - -   - - - - - - - - - - - - - - - - - - -   - - - - - - - - - - - - - - - - - - -   - - - - - - - - - - - - - - - - - - -   - - - - - - - - - - - - - - - - - - -   - - - - - - - - - - - - - - - - - - -   - - - - - - - - - - - - - - - - - - -   - - - - - - - - - - - - - - - - - - -   - - - - - - - - - - - - - - - - - - -   - - - - - - - - - - - - - - - - - - -   - - - - - - - - - - - - - - - - - - -   - - - - - - - - - - - - - - - - - - -   - - - - - - - - - - - - - - - - - - -   - - - - - - - - - - - - - - - - - - -   - - - - - - - - - - - - - - - - - - -   - - - - - - - - - - - - - - - - - - -   
- - - - - - - - - - - - - - - - - - -   - - - - - - - - - - - - - - - - - - -   - - - - - - - - - - - - - - - - - - -   - - - - - - - B B B B - - - - - - - -   - - - - - - B B B B B B - - - - - - -   - - - - - - B B B B B B - - - - - - -   - - - - - - B B B B B B - - - - - - -   - - - - - - B B B B B B - - - - - - -   - - - - - - B B B B B B - - - - - - -   - - - - - - C C C C C C - - - - - - -   - - - - - - C C C C C C - - - - - - -   - - - - - - - C C C C - - - - - - - -   - - - - - - - C C C C - - - - - - - -   - - - - - - - C C C C - - - - - - - -   - - - - - - - C C C C - - - - - - - -   - - - - - - - C C C C - - - - - - - -   - - - - - - - D D - - - - - - - - - -   - - - - - - - - - - - - - - - - - - -   - - - - - - - - - - - - - - - - - - -   - - - - - - - - - - - - - - - - - - -   - - - - - - - - - - - - - - - - - - -   - - - - - - - - - - - - - - - - - - -   - - - - - - - - - - - - - - - - - - -   - - - - - - - - - - - - - - - - - - -   - - - - - - - - - - - - - - - - - - -   - - - - - - - - - - - - - - - - - - -   - - - - - - - - - - - - - - - - - - -   - - - - - - - - - - - - - - - - - - -   - - - - - - - - - - - - - - - - - - -   - - - - - - - - - - - - - - - - - - -   - - - - - - - - - - - - - - - - - - -   
- - - - - - - - - - - - - - - - - - -   - - - - - - - - - - - - - - - - - - -   - - - - - - - - B B - - - - - - - - -   - - - - - - B B B B B B - - - - - - -   - - - - - - B B B B B B - - - - - - -   - - - - - B B B B B B B B - - - - - -   - - - - - B B B B B B B B - - - - - -   - - - - - B B B B B B B B - - - - - -   - - - - - - B B B B B B - - - - - - -   - - - - - - C C C C C C - - - - - - -   - - - - - - C C C C C C - - - - - - -   - - - - - - C C C C C C - - - - - - -   - - - - - - C C C C C C - - - - - - -   - - - - - - - C C C C - - - - - - - -   - - - - - - - C C C C - - - - - - - -   - - - - - - - C C C C - - - - - - - -   - - - - - - - J J - - - - - - - - - -   - - - - - - - L L - - - - - - - - - -   - - - - - - - - - - - - - - - - - - -   - - - - - - - - - - - - - - - - - - -   - - - - - - - - - - - - - - - - - - -   - - - - - - - - - - - - - - - - - - -   - - - - - - - - - - - - - - - - - - -   - - - - - - - - - - - - - - - - - - -   - - - - - - - - - - - - - - - - - - -   - - - - - - - - - - - - - - - - - - -   - - - - - - - - - - - - - - - - - - -   - - - - - - - - - - - - - - - - - - -   - - - - - - - - - - - - - - - - - - -   - - - - - - - - - - - - - - - - - - -   - - - - - - - - - - - - - - - - - - -   
- - - - - - - - - - - - - - - - - - -   - - - - - - - - - - - - - - - - - - -   - - - - - - - B B B B - - - - - - - -   - - - - - - B B B B B B - - - - - - -   - - - - - B B B B B B B B - - - - - -   - - - - - B B B B B B B B - - - - - -   - - - - - B B B B B B B B - - - - - -   - - - - - B B B B B B B B - - - - - -   - - - - - B B B B B B B B - - - - - -   - - - - - - C C C C C C - - - - - - -   - - - - - - C C C C C C - - - - - - -   - - - - - - C C C C C C - - - - - - -   - - - - - - C C C C C C - - - - - - -   - - - - - - - C C C C - - - - - - - -   - - - - - - - C C C C - - - - - - - -   - - - - - - - - C C - - - - - - - - -   - - - - - - - I I - - - - - - - - - -   - - - - - - - C C - - - - - - - - - -   - - - - - - - I I - - - - - - - - - -   - - - - - - - C - - Ah- - - - - - - -   - - - - - - H H - - H Ah- - - - - - -   - - - - - - - - - - - - - - - - - - -   - - - - - - - - - - - - - - - - - - -   - - - - - - - - - - - - - - - - - - -   - - - - - E E E E E E E E - - - - - -   - - - - - E E E E E E E E - - - - - -   - - - - - - - - - - - - - - - - - - -   - - - - - - - - - - - - - - - - - - -   - - - - - - - - - - - - - - - - - - -   - - - - - - - - - - - - - - - - - - -   - - - - - - - - - - - - - - - - - - -   
- - - - - - - - - - - - - - - - - - -   - - - - - - - - - - - - - - - - - - -   - - - - - - - B B B B - - - - - - - -   - - - - - - B B B B B B - - - - - - -   - - - - - B B B B B B B B - - - - - -   - - - - - B B B B B B B B - - - - - -   - - - - - B B B B B B B B - - - - - -   - - - - - B B B B B B B B - - - - - -   - - - - - B B B B B B B B - - - - - -   - - - - - - C C C C C C - - - - - - -   - - - - - - C C C C C C - - - - - - -   - - - - - - - C C C C - - - - - - - -   - - - - - - - C C C C - - - - - - - -   - - - - - - - - - - - - - - - - - - -   - - - - - - - - - - - - - - - - - - -   - - - - - - - - - - - - - - - - - - -   - - - - - - - - - - - - - - - - - - -   - - - - - - - L L - L - - - - - - - -   - - - - - O O O O - O O O - - - - - -   - - - - - C C C C - C C C - - - - - -   - - - - - G G G - - G G G - - - - - -   - - - - - - - - - - - - - - - - - - -   - - - - - - - - - - - - - - - - - - -   - - - - - E E E E E E E E - - - - - -   - - - - - E E E E E E E Ad- - - - - -   - - - - - E E E E E E E Ad- - - - - -   - - - - - E E E E E E E E - - - - - -   - - - - - - - - - - - - - - - - - - -   - - - - - - - - - - - - - - - - - - -   - - - - - - - - - - - - - - - - - - -   - - - - - - - - - - - - - - - - - - -   
- - - - - - - - - - - - - - - - - - -   - - - - - - - - - - - - - - - - - - -   - - - - - - - - B B - - - - - - - - -   - - - - - - B B B B B B - - - - - - -   - - - - - - B B B B B B - - - - - - -   - - - - - B B B B B B B B - - - - - -   - - - - - B B B B B B B B - - - - - -   - - - - - B B B B B B B B - - - - - -   - - - - - - B B B B B B - - - - - - -   - - - - - - - C C C C - - - - - - - -   - - - - - - - C C C C - - - - - - - -   - - - - - - - - C C - - - - - - - - -   - - - - - - - - C C - - - - - - - - -   - - - - - - - - - - - - - - - - - - -   - - - - - - - - - - - - - - - - - - -   - - - - - - - - - - - - - - - - - - -   - - - - - - G G - - G G - - - - - - -   - - - - - H H H - - H H H - - - - - -   - - - - - E E E - - E E E - - - - - -   - - - - - D D D - - D D D - - - - - -   - - - - - D D D - - D D D - - - - - -   - - - - - - - - - - - - - - - - - - -   - - - - - - - - - - - - - - - - - - -   - - - - - E E E E E E E E - - - - - -   - - - - - E E E E E E E Ad- - - - - -   - - - - - E E E E E E E Ad- - - - - -   - - - - - E E E E E E E E - - - - - -   - - - - - - - - - - - - - - - - - - -   - - - - - - - - - - - - - - - - - - -   - - - - - - - - - - - - - - - - - - -   - - - - - - - - - - - - - - - - - - -   
- - - - - - - - - - - - - - - - - - -   - - - - - - - - - - - - - - - - - - -   - - - - - - - - - - - - - - - - - - -   - - - - - - - B B B B - - - - - - - -   - - - - - - B B B B B B - - - - - - -   - - - - - - B B B B B B - - - - - - -   - - - - - - B B B B B B - - - - - - -   - - - - - - B B B B B B - - - - - - -   - - - - - - B B B B B B - - - - - - -   - - - - - - - - - - - - - - - - - - -   - - - - - - - - - - - - - - - - - - -   - - - - - - - - - - - - - - - - - - -   - - - - - - - - - - - - - - - - - - -   - - - - - - - - - - - - - - - - - - -   - - - - - - - - - - - - - - - - - - -   - - - - - - C C - - C C - - - - - - -   - - - - - D D D - - D D D - - - - - -   - - - - - C C C - - C C C - - - - - -   - - - - - C C C - - C C C - - - - - -   - - - - - C C C - - C C C - - - - - -   - - - - - G A A A A A A G - - - - - -   - - - - - - A A A A A A - - - - - - -   - - - - - - A A A A A A - - - - - - -   - - - - - - A A A A A A - - - - - - -   - - - - - E E E E E E E E - - - - - -   - - - - - E E E E E E E E - - - - - -   - - - - - - - - - - - - - - - - - - -   - - - - - - - - - - - - - - - - - - -   - - - - - - - - - - - - - - - - - - -   - - - - - - - - - - - - - - - - - - -   - - - - - - - - - - - - - - - - - - -   
- - - - - - - B B B B B - - - - - - -   - - - - - - - B B B B B - - - - - - -   - - - - - - - - B B B - - - - - - - -   - - - - - - - - - - - - - - - - - - -   - - - - - - - - B B - - - - - - - - -   - - - - - - - B B B B - - - - - - - -   - - - - - - - B B B B - - - - - - - -   - - - - - - - B B B B - - - - - - - -   - - - - - - - - B B - - - - - - - - -   - - - - - - - - - - - - - - - - - - -   - - - - - - - - - - - - - - - - - - -   - - - - - - - - - - - - - - - - - - -   - - - - - - - - - - - - - - - - - - -   - - - - - - - - - - - - - - - - - - -   - - - - - - - D - - D - - - - - - - -   - - - - - C C C - - C C C - - - - - -   - - - - - D D D - - D D D - - - - - -   - - - - - D D D - - D D D - - - - - -   - - - - - D D D - - D D D - - - - - -   - - - - - D D D - - D D D - - - - - -   - - - - A A A A A A A A A A - - - - -   - - - - A A A A A A A A A A - - - - -   - - - - A A A A A A A A A A - - - - -   - - - - A A A A A A A A A A - - - - -   - - - - - A A A A A A A A - - - - - -   - - - - - A A A A A A A A - - - - - -   - - - - - - - A A A A - - - F F - - -   - - - - - - - - - - - - - - F F - - -   - - - - - - - - - - - - - - - - - - -   - - - - - - - - - - - - - - - - - - -   - - - - - - - - - - - - - - - - - - -   
- - - - - - - B B B B B B - - - - - -   - - - - - - - B B B B B B - - - - - -   - - - - - - - B B B B B B - - - - - -   - - - - - - - - B B B - - - - - - - -   - - - - - - - - - - - - - - - - - - -   - - - - - - - - - - - - - - - - - - -   - - - - - - - - - - - - - - - - - - -   - - - - - - - - - - - - - - - - - - -   - - - - - - - - - - - - - - - - - - -   - - - - - - - - - - - - - - - - - - -   - - - - - - - - - - - - - - - - - - -   - - - - - - - - - - - - - - - - - - -   - - - - - - - - - - - - - - - - - - -   - - - - - - - - - - - - - - - - - - -   - - - - - D D D - - D D D - - - - - -   - - - - - C C C - - C C C - - - - - -   - - - - - D D D - - D D D - - - - - -   - - - - - G G G - - G G G - - - - - -   - - - - - G G G - - G G G - - - - - -   - - - - - D D D - - D D D - - - - - -   H H H A A A A A A A A A A A A B B A -   - - - A A A A A A A A A A A A - - - -   - - - A A A A A A A A A A A A - - - -   - - - A A A A A A A A A A A A - - - -   - - - A A A A A A A A A A A F - - - -   - - - - A A A A A A A A A F F D D - -   - - - - - A A A A A A A F F F H H - -   - - - - - - A A A A A A F F F G G G -   - - - - - - - - - - - - - F F C C - -   - - - - - - - - - - - - - - F L - - -   - - - - - - - - - - - - - - - - - - -   
- - - - - - - B B B B B B B - - - - -   - - - - - - - B B B B B B B - - - - -   - - - - - - - B B B B B B - - - - - -   - - - - - - - B B B B B - - - - - - -   - - - - - - - H H H - - - - - - - - -   - - - - - - - H H H - - - - - - - - -   - - - - - - - G G G - - - - - - - - -   - - - - - - - D D D - - - - - - - - -   - - - - - - - - G - - - - - - - - - -   - - - - - - - - H - - - - - - - - - -   - - - - - - - - - - - - - - - - - - -   - - - - - - - - - - - - - - - - - - -   - - - - - - - - - - - - - - - - - - -   - - - - - - - Ak- - Ak- - - - - - - -   - - - - - D D D - - D D D - - - - - -   - - - - - D D D - - D D D - - - - - -   - - - - - D D D - - D D D - - - - - -   - - - - - G G G - - G G G - - - - - -   - Q Q Q Q Q Q Q Q Q Q Q Q Q B B N - -   - D D D D D D D D D D D D D B B N - -   H H A A A A A A A A A A A A A A B A -   - - A A A A A A A A A A A A A A - - -   - - A A A A A A A A A A A A A A - - -   - - A A A A A A A A A A A A A A - - -   - - A A A A A A A A A A A F F E E - -   - - - A A A A A A A A A F F F N N N -   - - - A A A A A A A A A F F F P P P -   - - - - A A A A A A A A F F F P P P -   - - - - - - A A A A A A F F F Y Y Y -   - - - - - - - - - - - - F F F C C - -   - - - - - - - - - - - - - - - - - - -   
- - - - - - - B B B B B B B - - - - -   - - - - - - - B B B B B B B - - - - -   - - - - - - - B B B B B B - - - - - -   - - - - - - - B B B B B - - - - - - -   - - - - - - - H H H - - - - - - - - -   - - - - - - - D D D - - - - - - - - -   - - - - - - - D D D - - - - - - - - -   - - - - - - - D D D - - - - - - - - -   - - - - - - H H H H K - - - - - - - -   - - - - - - H H H H K - - - - - - - -   - - - - - Q Q Q Q Q Q K - - - - - - -   - - - - - - D D D D D - - - - - - - -   - - - - - - W W W W W - - - - - - - -   - - - - - - AgAgAg- AgAg- - - - - - -   - - - - - D D D - - D D D - - - - - -   - - - - - C C C - - C C C - - - - - -   - - D D D D D D D D D D D D B S - - -   - - M M M M M M M M M M M M B S - - -   - E E E E E E E E E E E E E B B N - -   - C C C C C C C C C C C C C B B N - -   H A A A A A A A A A A A A A A A A A -   - A A A A A A A A A A A A A A A A - -   - A A A A A A A A A A A A A A A A - -   - A A A A A A A A A A A A A F F A - -   - - A A A A A A A A A A F F F H H - -   - - A A A A A A A A A A F F F AeAeAe-   - - - A A A A A A A A F F F F H H H H   - - - A A A A A A A A F F F F U U U U   - - - - - A A A A A A F F F F F F F -   - - - - - - - A A A A - F F F Z Z Z -   - - - - - - - - - - - - - F F E - - -   
- - - - - - - B B B B B B - - - - - -   - - - - - - - B B B B B B - - - - - -   - - - - - - - B B B B B B - - - - - -   - - - - - - - B B B B - - - - - - - -   - - - - - - - H H H - - - - - - - - -   - - - - - - - D D D - - - - - - - - -   - - - - - - - D D D - - - - - - - - -   - - - - - - - M M M - - - - - - - - -   - - - - - - X X X X K - - - - - - - -   - - - - - - AaAaAaAaK - - - - - - - -   - - - - - AfAfAfAfAfAfK - - - - - - -   - - - - - - D D D D D - - - - - - - -   - - - - - - AbAbAbAbAb- - - - - - - -   - - - - - - AbAbAb- AbAb- - - - - - -   - - - D D D D D D D D D D D V - - - -   - - - C C C C C C C C C C C V - - - -   - - E E E E E E E E E E E E B S - - -   - - G G G G G G G G G G G G B S - - -   - M M M M M M M M M M M M M B B N - -   - C C C C C C C C C C C C C B B N - -   H A A A A A A A A A A A A A A A A A -   - A A A A A A A A A A A A A A A A - -   - A A A A A A A A A A A A A A A A - -   - A A A A A A A A A A A A A F F A - -   - A A A A A A A A A A A F F F Y Y Y -   - A A A A A A A A A A A F F F AaAaAa-   - - A A A A A A A A A F F F F AcAcAcAc  - - - A A A A A A A A F F F F U U U U   - - - - A A A A A A A F F F F P P P -   - - - - - A A A A A A A F F F H H H -   - - - - - - - - - - - - - F F E - - -   
- - - - - - - B B B B B - - - - - - -   - - - - - - - B B B B B - - - - - - -   - - - - - - - - B B B - - - - - - - -   - - - - - - - - - - - - - - - - - - -   - - - - - - - - - - - - - - - - - - -   - - - - - - - - - - - - - - - - - - -   - - - - - - - - - - - - - - - - - - -   - - - - - - - - - - - - - - - - - - -   - - - - - - - - - - - - - - - - - - -   - - - - - - - K K K - - - - - - - - -   - - - - - - D D D D D - - - - - - - -   - - - - - - D D D D D - - - - - - - -   - - - - M M M M M M M M M T - - - - -   - - - - W W W W W W W W W T - - - - -   - - - C C C C C C C C C C C V - - - -   - - - C C C C C C C C C C C V - - - -   - - D D D D D D D D D D D D B S - - -   - - G G G G G G G G G G G G B S - - -   - R R R R R R R R R R R R R B B N - -   - D D D D D D D D D D D D D B B N - -   A A A A A A A A A A A A A A A A A A -   A A A A A A A A A A A A A A A A A A -   A A A A A A A A A A A A A A A A A A -   A A A A A A A A A A A A A A A A A A -   - A A A A A A A A A A A A F F G G - -   - A A A A A A A A A A A F F F N N N -   - - A A A A A A A A A F F F F Z Z Z -   - - A A A A A A A A A F F F F P P P -   - - - A A A A A A A A A F F F P P P -   - - - - - A A A A A A A F F F H H - -   - - - - - - - A A A A - - - F A - - -   
- - - - - - - - - - - - - - - - - - -   - - - - - - - - - - - - - - - - - - -   - - - - - - - - - - - - - - - - - - -   - - - - - - - - - - - - - - - - - - -   - - - - - - - - - - - - - - - - - - -   - - - - - - - - - - - - - - - - - - -   - - - - - - - - - - - - - - - - - - -   - - - - - K K K K K K K - - - - - - -   - - - - K E E E E E E E K - - - - - -   - - - H H H H H H H H H K - - - - - -   - - - E E E E E E E E E K - - - - - -   - - - J J J J J J J J J J T - - - - -   - - - E E E E E E E E E E T - - - - -   - - - J J J J J J J J J J T - - - - -   - - - C C C C C C C C C C C V - - - -   - - - D D D D D D D D D D D V - - - -   - - J J J J J J J J J J J J B S - - -   - - L L L L L L L L L L L L B S - - -   - I I I I I I I I I I I I I B B N - -   - G G G G G G G G G G G G G B B N - -   A A A A A A A A A A A A A A A A A A -   A A A A A A A A A A A A A A A A A A -   A A A A A A A A A A A A A A A A A A -   A A A A A A A A A A A A A A A A A A -   A A A A A A A A A A A A A A F F A A -   - A A A A A A A A A A A F F F D D - -   - A A A A A A A A A A A F F F H H H -   - - A A A A A A A A A A F F F H H H -   - - - A A A A A A A A A F F F H H - -   - - - - A A A A A A A A A F F J J - -   - - - - - - A A A A A A - - - - - - -   
- - - - - - - - - - - - - - - - - - -   - - - - - - - - - - - - - - - - - - -   - - - - - - - - - - - - - - - - - - -   - - - - - - - - - - - - - - - - - - -   - - - - - - - - - - - - - - - - - - -   - - - - - - - - - - - - - - - - - - -   - - - - - - - - - - - - - - - - - - -   - - - - - K K K K K K K - - - - - - -   - - - - K G G G G G G G K - - - - - -   - - - - K G G G G G G G K - - - - - -   - - - G G G G G G G G G G T - - - - -   - - - E E E E E E E E E E T - - - - -   - - - C C C C C C C C C C T - - - - -   - - - - E E E E E E E E E T - - - - -   - - - C C C C C C C C C C C V - - - -   - - - C C C C C C C C C C C V - - - -   - - I I I I I I I I I I I I B S - - -   - - C C C C C C C C C C C C B S - - -   - I I I I I I I I I I I I I B B N - -   - C C C C C C C C C C C C C B B N - -   A A A A A A A A A A A A A A A A A A -   A A A A A A A A A A A A A A A A A A -   A A A A A A A A A A A A A A A A A A -   A A A A A A A A A A A A A A A A A A -   A A A A A A A A A A A A A A A A A A -   - A A A A A A A A A A A A A A A A - -   - A A A A A A A A A A A A F F F A - -   - - A A A A A A A A A A A F F F - - -   - - - A A A A A A A A A A A F F - - -   - - - - A A A A A A A A A A - - - - -   - - - - - - A A A A A A - - - - - - -   
- - - - - - - - - - - - - - - - - - -   - - - - - - - - - - - - - - - - - - -   - - - - - - - - - - - - - - - - - - -   - - - - - - - - - - - - - - - - - - -   - - - - - - - - - - - - - - - - - - -   - - - - - - - - - - - - - - - - - - -   - - - - - - - - - - - - - - - - - - -   - - - - - K K K K K K K - - - - - - -   - - - - K D D D D D D D K - - - - - -   - - - - K D D D D D D D K - - - - - -   - - - G G G G G G G G G G T - - - - -   - - - G G G G G G G G G G T - - - - -   - - - E E E E E E E E E E T - - - - -   - - - - X X X X X X X X X T - - - - -   - - - C C C C C C C C C C C V - - - -   - - - C C C C C C C C C C C V - - - -   - - J J J J J J J J J J J J B S - - -   - - L L L L L L L L L L L L B S - - -   - O O O O O O O O O O O O O B B N - -   - C C C C C C C C C C C C C B B N - -   A A A A A A A A A A A A A A A A A A -   A A A A A A A A A A A A A A A A A A -   A A A A A A A A A A A A A A A A A A -   A A A A A A A A A A A A A A A A A A -   A A A A A A A A A A A A A A F A A A -   - A A A A A A A A A A A A F F D D - -   - A A A A A A A A A A A F F F H H - -   - - A A A A A A A A A A F F F G G G -   - - - A A A A A A A A A A F F C C - -   - - - - A A A A A A A A A A F L - - -   - - - - - - A A A A A A - - - - - - -   
- - - - - - - - - - - - - - - - - - -   - - - - - - - - - - - - - - - - - - -   - - - - - - - - - - - - - - - - - - -   - - - - - - - - - - - - - - - - - - -   - - - - - - - - - - - - - - - - - - -   - - - - - - - - - - - - - - - - - - -   - - - - - - - - - - - - - - - - - - -   - - - - - K K K K K K K - - - - - - -   - - - - K C C C C C C C K - - - - - -   - - - C C C C C C C C C K - - - - - -   - - - C C C C C C C C C K - - - - - -   - - - G G G G G G G G G G T - - - - -   - - - G G G G G G G G G G T - - - - -   - - - R R R R R R R R R R T - - - - -   - - - C C C C C C C C C C C V - - - -   - - - C C C C C C C C C C C V - - - -   - - D D D D D D D D D D D D B S - - -   - - D D D D D D D D D D D D B S - - -   - D D D D D D D D D D D D D B B N - -   - C C C C C C C C C C C C C B B N - -   A A A A A A A A A A A A A A A A A A -   A A A A A A A A A A A A A A A A A A -   A A A A A A A A A A A A A A A A A A -   A A A A A A A A A A A A A A A A A A -   A A A A A A A A A A A A A F F E E A -   - A A A A A A A A A A A F F F N N N -   - A A A A A A A A A A A F F F P P P -   - - A A A A A A A A A A F F F P P P -   - - - A A A A A A A A A F F F Y Y Y -   - - - - A A A A A A A A F F F C C - -   - - - - - - A A A A A A - - - - - - -   
- - - - - - - B B B B B - - - - - - -   - - - - - - - B B B B B - - - - - - -   - - - - - - - - B B B - - - - - - - -   - - - - - - - - - - - - - - - - - - -   - - - - - - - - - - - - - - - - - - -   - - - - - - - - - - - - - - - - - - -   - - - - - - - - - - - - - - - - - - -   - - - - - - - - - - - - - - - - - - -   - - - - - - - - - - - - - - - - - - -   - - - - - - - K K K - - - - - - - - -   - - - - - - D D D D D - - - - - - - -   - - - - - - D D D D D - - - - - - - -   - - - - D D D D D D D D D T - - - - -   - - - - C C C C C C C C C T - - - - -   - - - C C C C C C C C C C C V - - - -   - - - C C C C C C C C C C C V - - - -   - - D D D D D D D D D D D D B S - - -   - - C C C C C C C C C C C C B S - - -   - E E E E E E E E E E E E E B B N - -   - D D D D D D D D D D D D D B B N - -   A A A A A A A A A A A A A A A A A A -   A A A A A A A A A A A A A A A A A A -   A A A A A A A A A A A A A A A A A A -   A A A A A A A A A A A A A A F F A A -   - A A A A A A A A A A A F F F H H - -   - A A A A A A A A A A A F F F AeAeAe-   - - A A A A A A A A A F F F F H H H H   - - A A A A A A A A A F F F F U U U U   - - - A A A A A A A A F F F F F F F -   - - - - - A A A A A A A F F F Z Z Z -   - - - - - - - A A A A - - F F E - - -   
- - - - - - - B B B B B B - - - - - -   - - - - - - - B B B B B B - - - - - -   - - - - - - - B B B B B B - - - - - -   - - - - - - - B B B B - - - - - - - -   - - - - - - - H H H - - - - - - - - -   - - - - - - - D D D - - - - - - - - -   - - - - - - - D D D - - - - - - - - -   - - - - - - - D D D - - - - - - - - -   - - - - - - D D D D K - - - - - - - -   - - - - - - AiAiAiAiK - - - - - - - -   - - - - - G G G G G G K - - - - - - -   - - - - - - J J J J J - - - - - - - -   - - - - - - L L L L L - - - - - - - -   - - - - - - I I I - I I - - - - - - -   - - - E E E E E E E E E E E V - - - -   - - - C C C C C C C C C C C V - - - -   - - J J J J J J J J J J J J B S - - -   - - L L L L L L L L L L L L B S - - -   - I I I I I I I I I I I I I B B N - -   - C C C C C C C C C C C C C B B N - -   H A A A A A A A A A A A A A A A A A -   - A A A A A A A A A A A A A A A A - -   - A A A A A A A A A A A A A A A A - -   - A A A A A A A A A A A A A F F A - -   - A A A A A A A A A A A F F F Y Y Y -   - A A A A A A A A A A A F F F AaAaAa-   - - A A A A A A A A A F F F F AcAcAcAc  - - - A A A A A A A A F F F F U U U U   - - - - A A A A A A A F F F F P P P -   - - - - - A A A A A A A F F F H H H -   - - - - - - - - - - - - - F F E - - -   
- - - - - - - B B B B B B B - - - - -   - - - - - - - B B B B B B B - - - - -   - - - - - - - B B B B B B - - - - - -   - - - - - - - B B B B B - - - - - - -   - - - - - - - H H H - - - - - - - - -   - - - - - - - D D D - - - - - - - - -   - - - - - - - D D D - - - - - - - - -   - - - - - - - D D D - - - - - - - - -   - - - - - - D D D D K - - - - - - - -   - - - - - - J J J J K - - - - - - - -   - - - - - H H H H H H K - - - - - - -   - - - - - - I I I I I - - - - - - - -   - - - - - - C C C C C - - - - - - - -   - - - - - - I I I - I I - - - - - - -   - - - - - C C C - - C C C - - - - - -   - - - - - C C C - - C C C - - - - - -   - - I I I I I I I I I I I I B S - - -   - - C C C C C C C C C C C C B S - - -   - I I I I I I I I I I I I I B B N - -   - C C C C C C C C C C C C C B B N - -   H A A A A A A A A A A A A A A A A A -   - A A A A A A A A A A A A A A A A - -   - A A A A A A A A A A A A A A A A - -   - A A A A A A A A A A A A A A A A - -   - - A A A A A A A A A A A F F G G - -   - - A A A A A A A A A A F F F N N N -   - - - A A A A A A A A F F F F Z Z Z -   - - - A A A A A A A A F F F F P P P -   - - - - - A A A A A A A F F F P P P -   - - - - - - - A A A A - F F F H H - -   - - - - - - - - - - - - - - F A - - -   
- - - - - - - B B B B B B B - - - - -   - - - - - - - B B B B B B B - - - - -   - - - - - - - B B B B B B - - - - - -   - - - - - - - B B B B B - - - - - - -   - - - - - - - G G G - - - - - - - - -   - - - - - - - D D D - - - - - - - - -   - - - - - - - D D D - - - - - - - - -   - - - - - - - G G G - - - - - - - - -   - - - - - - - - D - - - - - - - - - -   - - - - - - - - E - - - - - - - - - -   - - - - - - - - - - - - - - - - - - -   - - - - - - - - - - - - - - - - - - -   - - - - - - - - - - - - - - - - - - -   - - - - - - - O - - O - - - - - - - -   - - - - - D D D - - D D D - - - - - -   - - - - - C C C - - C C C - - - - - -   - - - - - J J J - - J J J - - - - - -   - - - - - L L L - - L L L - - - - - -   - O O O O O O O O O O O O O B B N - -   - C C C C C C C C C C C C C B B N - -   G G A A A A A A A A A A A A A A B A -   - - A A A A A A A A A A A A A A - - -   - - A A A A A A A A A A A A A A - - -   - - A A A A A A A A A A A A A A - - -   - - A A A A A A A A A A A A F F - - -   - - - A A A A A A A A A F F F D D - -   - - - A A A A A A A A A F F F H H H -   - - - - A A A A A A A A F F F H H H -   - - - - - - A A A A A A F F F H H - -   - - - - - - - - - - - - - F F J J - -   - - - - - - - - - - - - - - - - - - -   
- - - - - - - B B B B B B - - - - - -   - - - - - - - B B B B B B - - - - - -   - - - - - - - B B B B B B - - - - - -   - - - - - - - - B B B - - - - - - - -   - - - - - - - - - - - - - - - - - - -   - - - - - - - - - - - - - - - - - - -   - - - - - - - - - - - - - - - - - - -   - - - - - - - - - - - - - - - - - - -   - - - - - - - - - - - - - - - - - - -   - - - - - - - - - - - - - - - - - - -   - - - - - - - - - - - - - - - - - - -   - - - - - - - - - - - - - - - - - - -   - - - - - - - - - - - - - - - - - - -   - - - - - - - - - - - - - - - - - - -   - - - - - D D D - - D D D - - - - - -   - - - - - C C C - - C C C - - - - - -   - - - - - G G G - - G G G - - - - - -   - - - - - H H H - - H H H - - - - - -   - - - - - E E E - - E E E - - - - - -   - - - - - D D D - - D D D - - - - - -   D D D A A A A A A A A A A A A B B A -   - - - A A A A A A A A A A A A - - - -   - - - A A A A A A A A A A A A - - - -   - - - A A A A A A A A A A A A - - - -   - - - A A A A A A A A A A A A - - - -   - - - - A A A A A A A A A A - - - - -   - - - - - A A A A A A A A F AjAj- - -   - - - - - - A A A A A A - F A A - - -   - - - - - - - - - - - - - - F F - - -   - - - - - - - - - - - - - - - - - - -   - - - - - - - - - - - - - - - - - - -   
- - - - - - - B B B B B - - - - - - -   - - - - - - - B B B B B - - - - - - -   - - - - - - - - B B B - - - - - - - -   - - - - - - - - - - - - - - - - - - -   - - - - - - - - B B - - - - - - - - -   - - - - - - - B B B B - - - - - - - -   - - - - - - - B B B B - - - - - - - -   - - - - - - - B B B B - - - - - - - -   - - - - - - - - B B - - - - - - - - -   - - - - - - - - - - - - - - - - - - -   - - - - - - - - - - - - - - - - - - -   - - - - - - - - - - - - - - - - - - -   - - - - - - - - - - - - - - - - - - -   - - - - - - - - - - - - - - - - - - -   - - - - - - - D - - D - - - - - - - -   - - - - - C C C - - C C C - - - - - -   - - - - - D D D - - D D D - - - - - -   - - - - - C C C - - C C C - - - - - -   - - - - - C C C - - C C C - - - - - -   - - - - - C C C - - C C C - - - - - -   - - - - A A A A A A A A A A - - - - -   - - - - A A A A A A A A A A - - - - -   - - - - A A A A A A A A A A - - - - -   - - - - A A A A A A A A A A - - - - -   - - - - - A A A A A A A A - - - - - -   - - - - - A A A A A A A A - - - - - -   - - - - - - - A A A A - - - - - - - -   - - - - - - - - - - - - - - - - - - -   - - - - - - - - - - - - - - - - - - -   - - - - - - - - - - - - - - - - - - -   - - - - - - - - - - - - - - - - - - -   
- - - - - - - - - - - - - - - - - - -   - - - - - - - - - - - - - - - - - - -   - - - - - - - - - - - - - - - - - - -   - - - - - - - B B B B - - - - - - - -   - - - - - - B B B B B B - - - - - - -   - - - - - - B B B B B B - - - - - - -   - - - - - - B B B B B B - - - - - - -   - - - - - - B B B B B B - - - - - - -   - - - - - - B B B B B B - - - - - - -   - - - - - - - - - - - - - - - - - - -   - - - - - - - - - - - - - - - - - - -   - - - - - - - - - - - - - - - - - - -   - - - - - - - - - - - - - - - - - - -   - - - - - - - - - - - - - - - - - - -   - - - - - - - - - - - - - - - - - - -   - - - - - - C C - - C C - - - - - - -   - - - - - D D D - - D D D - - - - - -   - - - - - D D D - - D D D - - - - - -   - - - - - D D D - - D D D - - - - - -   - - - - - D D D - - D D D - - - - - -   - - - - - G A A A A A A G - - - - - -   - - - - - - A A A A A A - - - - - - -   - - - - - - A A A A A A - - - - - - -   - - - - - - A A A A A A - - - - - - -   - - - - - E E E E E E E E - - - - - -   - - - - - E E E E E E E E - - - - - -   - - - - - - - - - - - - - - - - - - -   - - - - - - - - - - - - - - - - - - -   - - - - - - - - - - - - - - - - - - -   - - - - - - - - - - - - - - - - - - -   - - - - - - - - - - - - - - - - - - -   
- - - - - - - - - - - - - - - - - - -   - - - - - - - - - - - - - - - - - - -   - - - - - - - - B B - - - - - - - - -   - - - - - - B B B B B B - - - - - - -   - - - - - - B B B B B B - - - - - - -   - - - - - B B B B B B B B - - - - - -   - - - - - B B B B B B B B - - - - - -   - - - - - B B B B B B B B - - - - - -   - - - - - - B B B B B B - - - - - - -   - - - - - - - C C C C - - - - - - - -   - - - - - - - C C C C - - - - - - - -   - - - - - - - - C C - - - - - - - - -   - - - - - - - - C C - - - - - - - - -   - - - - - - - - - - - - - - - - - - -   - - - - - - - - - - - - - - - - - - -   - - - - - - - - - - - - - - - - - - -   - - - - - - D D - - D D - - - - - - -   - - - - - G G G - - G G G - - - - - -   - - - - - G G G - - G G G - - - - - -   - - - - - D D D - - D D D - - - - - -   - - - - - H H H - - H H H - - - - - -   - - - - - - - - - - - - - - - - - - -   - - - - - - - - - - - - - - - - - - -   - - - - - E E E E E E E E - - - - - -   - - - - - E E E E E E E Ad- - - - - -   - - - - - E E E E E E E Ad- - - - - -   - - - - - E E E E E E E E - - - - - -   - - - - - - - - - - - - - - - - - - -   - - - - - - - - - - - - - - - - - - -   - - - - - - - - - - - - - - - - - - -   - - - - - - - - - - - - - - - - - - -   
- - - - - - - - - - - - - - - - - - -   - - - - - - - - - - - - - - - - - - -   - - - - - - - B B B B - - - - - - - -   - - - - - - B B B B B B - - - - - - -   - - - - - B B B B B B B B - - - - - -   - - - - - B B B B B B B B - - - - - -   - - - - - B B B B B B B B - - - - - -   - - - - - B B B B B B B B - - - - - -   - - - - - B B B B B B B B - - - - - -   - - - - - - C C C C C C - - - - - - -   - - - - - - C C C C C C - - - - - - -   - - - - - - - C C C C - - - - - - - -   - - - - - - - C C C C - - - - - - - -   - - - - - - - - - - - - - - - - - - -   - - - - - - - - - - - - - - - - - - -   - - - - - - - - - - - - - - - - - - -   - - - - - - - - - - - - - - - - - - -   - - - - - - - G G - G - - - - - - - -   - - - - - Q Q Q Q - Q Q Q - - - - - -   - - - - - D D D D - D D D - - - - - -   - - - - - H H H - - H H H - - - - - -   - - - - - - - - - - - - - - - - - - -   - - - - - - - - - - - - - - - - - - -   - - - - - E E E E E E E E - - - - - -   - - - - - E E E E E E E Ad- - - - - -   - - - - - E E E E E E E Ad- - - - - -   - - - - - E E E E E E E E - - - - - -   - - - - - - - - - - - - - - - - - - -   - - - - - - - - - - - - - - - - - - -   - - - - - - - - - - - - - - - - - - -   - - - - - - - - - - - - - - - - - - -   
- - - - - - - - - - - - - - - - - - -   - - - - - - - - - - - - - - - - - - -   - - - - - - - B B B B - - - - - - - -   - - - - - - B B B B B B - - - - - - -   - - - - - B B B B B B B B - - - - - -   - - - - - B B B B B B B B - - - - - -   - - - - - B B B B B B B B - - - - - -   - - - - - B B B B B B B B - - - - - -   - - - - - B B B B B B B B - - - - - -   - - - - - - C C C C C C - - - - - - -   - - - - - - C C C C C C - - - - - - -   - - - - - - C C C C C C - - - - - - -   - - - - - - C C C C C C - - - - - - -   - - - - - - - C C C C - - - - - - - -   - - - - - - - C C C C - - - - - - - -   - - - - - - - - C C - - - - - - - - -   - - - - - - - C C - - - - - - - - - -   - - - - - - - M M - - - - - - - - - -   - - - - - - - E E - - - - - - - - - -   - - - - - - - C - - Ah- - - - - - - -   - - - - - - H H - - AhAh- - - - - - -   - - - - - - - - - - - - - - - - - - -   - - - - - - - - - - - - - - - - - - -   - - - - - - - - - - - - - - - - - - -   - - - - - E E E E E E E E - - - - - -   - - - - - E E E E E E E E - - - - - -   - - - - - - - - - - - - - - - - - - -   - - - - - - - - - - - - - - - - - - -   - - - - - - - - - - - - - - - - - - -   - - - - - - - - - - - - - - - - - - -   - - - - - - - - - - - - - - - - - - -   
- - - - - - - - - - - - - - - - - - -   - - - - - - - - - - - - - - - - - - -   - - - - - - - - B B - - - - - - - - -   - - - - - - B B B B B B - - - - - - -   - - - - - - B B B B B B - - - - - - -   - - - - - B B B B B B B B - - - - - -   - - - - - B B B B B B B B - - - - - -   - - - - - B B B B B B B B - - - - - -   - - - - - - B B B B B B - - - - - - -   - - - - - - C C C C C C - - - - - - -   - - - - - - C C C C C C - - - - - - -   - - - - - - C C C C C C - - - - - - -   - - - - - - C C C C C C - - - - - - -   - - - - - - - C C C C - - - - - - - -   - - - - - - - C C C C - - - - - - - -   - - - - - - - C C C C - - - - - - - -   - - - - - - - C C - - - - - - - - - -   - - - - - - - G G - - - - - - - - - -   - - - - - - - - - - - - - - - - - - -   - - - - - - - - - - - - - - - - - - -   - - - - - - - - - - - - - - - - - - -   - - - - - - - - - - - - - - - - - - -   - - - - - - - - - - - - - - - - - - -   - - - - - - - - - - - - - - - - - - -   - - - - - - - - - - - - - - - - - - -   - - - - - - - - - - - - - - - - - - -   - - - - - - - - - - - - - - - - - - -   - - - - - - - - - - - - - - - - - - -   - - - - - - - - - - - - - - - - - - -   - - - - - - - - - - - - - - - - - - -   - - - - - - - - - - - - - - - - - - -   
- - - - - - - - - - - - - - - - - - -   - - - - - - - - - - - - - - - - - - -   - - - - - - - - - - - - - - - - - - -   - - - - - - - B B B B - - - - - - - -   - - - - - - B B B B B B - - - - - - -   - - - - - - B B B B B B - - - - - - -   - - - - - - B B B B B B - - - - - - -   - - - - - - B B B B B B - - - - - - -   - - - - - - B B B B B B - - - - - - -   - - - - - - C C C C C C - - - - - - -   - - - - - - C C C C C C - - - - - - -   - - - - - - - C C C C - - - - - - - -   - - - - - - - C C C C - - - - - - - -   - - - - - - - C C C C - - - - - - - -   - - - - - - - C C C C - - - - - - - -   - - - - - - - C C C C - - - - - - - -   - - - - - - - C C - - - - - - - - - -   - - - - - - - - - - - - - - - - - - -   - - - - - - - - - - - - - - - - - - -   - - - - - - - - - - - - - - - - - - -   - - - - - - - - - - - - - - - - - - -   - - - - - - - - - - - - - - - - - - -   - - - - - - - - - - - - - - - - - - -   - - - - - - - - - - - - - - - - - - -   - - - - - - - - - - - - - - - - - - -   - - - - - - - - - - - - - - - - - - -   - - - - - - - - - - - - - - - - - - -   - - - - - - - - - - - - - - - - - - -   - - - - - - - - - - - - - - - - - - -   - - - - - - - - - - - - - - - - - - -   - - - - - - - - - - - - - - - - - - -   
- - - - - - - - - - - - - - - - - - -   - - - - - - - - - - - - - - - - - - -   - - - - - - - - - - - - - - - - - - -   - - - - - - - - - - - - - - - - - - -   - - - - - - - - B B - - - - - - - - -   - - - - - - - B B B B - - - - - - - -   - - - - - - - B B B B - - - - - - - -   - - - - - - - B B B B - - - - - - - -   - - - - - - - - B B - - - - - - - - -   - - - - - - - C C C C - - - - - - - -   - - - - - - - C C C C - - - - - - - -   - - - - - - - - C C - - - - - - - - -   - - - - - - - - C C - - - - - - - - -   - - - - - - - C C C C - - - - - - - -   - - - - - - - C C C C - - - - - - - -   - - - - - - - - C C - - - - - - - - -   - - - - - - - - - - - - - - - - - - -   - - - - - - - - - - - - - - - - - - -   - - - - - - - - - - - - - - - - - - -   - - - - - - - - - - - - - - - - - - -   - - - - - - - - - - - - - - - - - - -   - - - - - - - - - - - - - - - - - - -   - - - - - - - - - - - - - - - - - - -   - - - - - - - - - - - - - - - - - - -   - - - - - - - - - - - - - - - - - - -   - - - - - - - - - - - - - - - - - - -   - - - - - - - - - - - - - - - - - - -   - - - - - - - - - - - - - - - - - - -   - - - - - - - - - - - - - - - - - - -   - - - - - - - - - - - - - - - - - - -   - - - - - - - - - - - - - - - - - - -   
