model
size = 27 31 20, scale = 0.05, origin = -y
material 
  colors = A:#D00 B:#400 C:#700 D:#A00 E:#800 F:#B00 G:#E00 H:#500 I:#100 J:#FFF K:#EEE L:#DDD M:#111 N:#CCC O:#010 P:#020 Q:#999 R:#6CC S:#063 T:#066 U:#033 V:#333 W:#777 X:#BBB Y:#399 Z:#696 Aa:#699 Ab:#3CC Ac:#099 Ad:#9CC
voxels
- - - - - - - - - - - - - - - - - - - - - - - - - - -   - - - - - - - - - - - - - - - - - - - - - - - - - - -   - - - - - - - - - - - - - - - - - - - - - - - - - - -   - - - - - - - - - - - - - - - - - - - - - - - - - - -   - - - - - - - - - - - - - - - - - - - - - - - - - - -   - - - - - - - - - - - - - - - - - - - - - - - - - - -   - - - - - - - - - - - - - - - - - - - - - - - - - - -   - - - - - - - - - - - - - - - - - - - - - - - - - - -   - - - - - - - - - - - - - - - - - - - - - - - - - - -   - - - - - - - - - - - - - - - - - - - - - - - - - - -   - - - - - - - - - - - - - - - - - - - - - - - - - - -   - - - - - - - - - - - - - - - - - - - - - - - - - - -   - - - - - - - - - - - - - - - - - - - - - - - - - - -   - - - - - - - - - - - - - - - - - - - - - - - - - - -   - - - - - - - - - - - - - - - - - - - - - - - - - - -   - - - - - - - - - - - - - - - - - - - - - - - - - - -   - - - - - - - - - - - - - - - - - - C E D G - - - - -   - - - - - - - - - - - - - - - - - - C E D G - - - - -   - - - - - - - - - - - - - - - - - - C E D G - - - - -   - - - - - - - - - - - - - - - - - - C E D G - - - - -   - - - - - - - - - - - - - - - - - - - - - - - - - - -   - - - - - - - - - - - - - - - - - - - - - - - - - - -   - - - - - - - - - - - - - - - - - - - - - - - - - - -   - - - - - - - - - - - - - - - - - - - - - - - - - - -   - - - - - - - - - - - - - - - - - - - - - - - - - - -   - - - - - - - - - - - - - - - - - - - - - - - - - - -   - - - - - - - - - - - - - - - - - - - - - - - - - - -   - - - - - - - - - - - - - - - - - - - - - - - - - - -   - - - - - - - - - - - - - - - - - - - - - - - - - - -   - - - - - - - - - - - - - - - - - - - - - - - - - - -   - - - - - - - - - - - - - - - - - - - - - - - - - - -   
- - - - - - - - - - - - - - - - - - - - - - - - - - -   - - - - - - - - - - - - - - - - - - - - - - - - - - -   - - - - - - - - - - - - - - - - - - - - - - - - - - -   - - - - - - - - - - - - - - - - - - - - - - - - - - -   - - - - - - - - - - - - - - - - - - - - - - - - - - -   - - - - - - - - - - - - - - - - - - - - - - - - - - -   - - - - - - - - - - - - - - - - - - - - - - - - - - -   - - - - - - - - - - - - - - - - - - - - - - - - - - -   - - - - - - - - - - - - - - - - - - - - - - - - - - -   - - - - - - - - - - - - - - - - - - - - - - - - - - -   - - - - - - - - - - - - - - - - - - - - - - - - - - -   - - - - - - - - - - - - - - - - - - - - - - - - - - -   - - - - - - - - - - - - - - - - - - - - - - - - - - -   - - - - - - - - - - - - - - - - - - - - - - - - - - -   - - - - - - - - - - - - - - - - - - - D D - - - - - -   - - - - - - - - - - - - - - - - - C E D D G B - - - -   - - - - - - - - - - - - - - - - - C E D D G C - - - -   - - - - - - - - - - - - - - - - H C E D D G B J - - -   - - - - - - - - - - - - - - - - H C E D D G F J - - -   - - - - - - - - - - - - - - - - - C E D D G B - - - -   - - - - - - - - - - - - - - - - - C E D D G C - - - -   - - - - - - - - - - - - - - - - - - - D D - - - - - -   - - - - - - - - - - - - - - - - - - - - - - - - - - -   - - - - - - - - - - - - - - - - - - - - - - - - - - -   - - - - - - - - - - - - - - - - - - - - - - - - - - -   - - - - - - - - - - - - - - - - - - - - - - - - - - -   - - - - - - - - - - - - - - - - - - - - - - - - - - -   - - - - - - - - - - - - - - - - - - - - - - - - - - -   - - - - - - - - - - - - - - - - - - - - - - - - - - -   - - - - - - - - - - - - - - - - - - - - - - - - - - -   - - - - - - - - - - - - - - - - - - - - - - - - - - -   
- - - - - - - - - - - - - - - - - - - - - - - - - - -   - - - - - - - - - - - - - - - - - - - - - - - - - - -   - - - - - - - - - - - - - - - - - - - - - - - - - - -   - - - - - - - - - - - - - - - - - - - - - - - - - - -   - - - - - - - - - - - - - - - - - - - - - - - - - - -   - - - - - - - - - - - - - - - - - - - - - - - - - - -   - - - - - - - - - - - - - - - - - - - - - - - - - - -   - - - - - - - - - - - - - - - - - - - - - - - - - - -   - - - - - - - - - - - - - - - - - - - - - - - - - - -   - - - - - - - - - - - - - - - - - - - - - - - - - - -   - - - - - - - - - - - - - - - - - - - - - - - - - - -   - - - - - - - - - - - - - - - - - - - - - - - - - - -   - - - - - - - - - - - - - - - - - - - - - - - - - - -   - - - - - - - - - - - - - - - - - - - D F - - - - - -   - - - - - - - - - - - - - - - - - E D D F G B - - - -   - - - - - - - - - - - - - - - - C E D D F G B B - - -   - - - - - - - - - - - - - - - - C E D D F G L L - - -   - - - - - - - - - - - - - - - H C E D D F G J J J - -   - - - - - - - - - - - - - - - H C E D D F G J J J - -   - - - - - - - - - - - - - - - - C E D D F G J J - - -   - - - - - - - - - - - - - - - - C E D D F G L L - - -   - - - - - - - - - - - - - - - - - E D D F G B - - - -   - - - - - - - - - - - - - - - - - - - D F - - - - - -   - - - - - - - - - - - - - - - - - - - - - - - - - - -   - - - - - - - - - - - - - - - - - - - - - - - - - - -   - - - - - - - - - - - - - - - - - - - - - - - - - - -   - - - - - - - - - - - - - - - - - - - - - - - - - - -   - - - - - - - - - - - - - - - - - - - - - - - - - - -   - - - - - - - - - - - - - - - - - - - - - - - - - - -   - - - - - - - - - - - - - - - - - - - - - - - - - - -   - - - - - - - - - - - - - - - - - - - - - - - - - - -   
- - - - - - - - - - - - - - - - - - - - - - - - - - -   - - - - - - - - - - - - - - - - - - - - - - - - - - -   - - - - - - - - - - - - - - - - - - - - - - - - - - -   - - - - - - - - - - - - - - - - - - - - - - - - - - -   - - - - - - - - - - - - - - - - - - - - - - - - - - -   - - - - - - - - - - - - - - - - - - - - - - - - - - -   - - - - - - - - - - - - - - - - - - - - - - - - - - -   - - - - - - - - - - - - - - - - - - - - - - - - - - -   - - - - - - - - - - - - - - - - - - - - - - - - - - -   - - - - - - - - - - - - - - - - - - - - - - - - - - -   - - - - - - - - - - - - - - - - - - - - - - - - - - -   - - - - - - - - - - - - - - - - - - - - - - - - - - -   - - - - - - - - - - - - - - - - - - - - - - - - - - -   - - - - - - - - - - - - - - - - - E D F A G B - - - -   - - - - - - - - - - - - - - - - C E D F A G C C - - -   - - - - - - - - - - - - - - - C C E D F A G K K E - -   - - - - - - - - - - - - - - - C C E D F A G J J J - -   - - - - - - - - - - - - - - - C C E D F A G L L L - -   - - - - - - - - - - - - - - - C C E D F A G AdAdAd- -   - - - - - - - - - - - - - - - C C E D F A G L L L - -   - - - - - - - - - - - - - - - C C E D F C G J J J - -   - - - - - - - - - - - - - - - - C E D F C G L L - - -   - - - - - - - - - - - - - - - - - E D F C G C - - - -   - - - - - - - - - - - - - - - - - - - - - - - - - - -   - - - - - - - - - - - - - - - - - - - - - - - - - - -   - - - - - - - - - - - - - - - - - - - - - - - - - - -   - - - - - - - - - - - - - - - - - - - - - - - - - - -   - - - - - - - - - - - - - - - - - - - - - - - - - - -   - - - - - - - - - - - - - - - - - - - - - - - - - - -   - - - - - - - - - - - - - - - - - - - - - - - - - - -   - - - - - - - - - - - - - - - - - - - - - - - - - - -   
- - - - - - - - - - - - - - - - - - - M M M - - - - -   - - - - - - - - - - - - - - - - - - - - - - - - - - -   - - - - - - - - - - - - - - - - - - - - - - - - - - -   - - - - - - - - - - - - - - - - - - - - - - - - - - -   - - - - - - - - - - - - - - - - - - - - - - - - - - -   - - - - - - - - - - - - - - - - - - - - - - - - - - -   - - - - - - - A A A A A A - - - - - - - - - - - - - -   - - - - - - F A A A A A A F - - - - - - - - - - - - -   - - - - - - - A A A A A A - - - - - - - - - - - - - -   - - - - - - - - - - - - - - - - - - - - - - - - - - -   - - - - - - - - - - - - - - - - - - - - - - - - - - -   - - - - - - - - - - - - - - - - - - - - - - - - - - -   - - - - - - - - - - - - - - - - - - F A C G - - - - -   - - - - - - - - - - - - - - - - E D F A C G B B - - -   - - - - - - - - - - - - - - - C E D F A C G Q Q E - -   - - - - - - - - - - - - - - - C E D F A C G J J J - -   - - - - - - - - - - - - - - H C E D F A C G AbAbAbAb-   - - - - - - - - - - - - - - H C E D F A C G O O O O -   - - - - - - - - - - - - - - H C E D F A C G I I I I -   - - - - - - - - - - - - - - H C E D F A C G O O O O -   - - - - - - - - - - - - - - - C E D F A C G G G X - -   - - - - - - - - - - - - - - - C E D F A C G J J J - -   - - - - - - - - - - - - - - - - E D F A C G F F - - -   - - - - - - - - - - - - - - - - - - F A C G - - - - -   - - - - - - - - - - - - - - - - - - - - - - - - - - -   - - - - - - - - - - - - - - - - - - - - - - - - - - -   - - - - - - - - - - - - - - - - - - - - - - - - - - -   - - - - - - - - - - - - - - - - - - - B B - - - - - -   - - - - - - - - - - - - - - - - - - B B B - - - - - -   - - - - - - - - - - - - - - - - - - - - - - - - - - -   - - - - - - - - - - - - - - - - - - - - - - - - - - -   
- - - - - - - - - - - - - - - - - - - M M M M - - - -   - - - - - - - - - - - - - - - - - - - B B B - - - - -   - - - - - - - - - - - - - - - - - - - - - - - - - - -   - - - - - - - - - - - - - - - - - - - - - - - - - - -   - - - - - - - - - - - - - - - - - - - - - - - - - - -   - - - - - D F A A A A A A F D - - - - - - - - - - - -   - - - - E D F A A A A A A F D E - - - - - - - - - - -   - - - E E D F A A A A A A F D E E - - - - - - - - - -   - - - - E D F A A A A A A F D E - - - - - - - - - - -   - - - - - D F A A A A A A F D - - - - - - - - - - - -   - - - - - - - - - - - - - - - - - - - - - - - - - - -   - - - - - - - - - - - - - - - - - - - - - - - - - - -   - - - - - - - - - - - - - - - - - D F A C G G - - - -   - - - - - - - - - - - - - - - - E D F A C G B B - - -   - - - - - - - - - - - - - - - C E D F A C G E E E - -   - - - - - - - - - - - - - - H C E D F A C G K K K K -   - - - - - - - - - - - - - - H C E D F A C G S S S S -   - - - - - - - - - - - - - - H C E D F A C G I I I I -   - - - - - - - - - - - - - - H C E D F A C G I I I I -   - - - - - - - - - - - - - - H C E D F A C G I I I I -   - - - - - - - - - - - - - - H C E D F A C G P P P P -   - - - - - - - - - - - - - - - C E D F A C G J J J - -   - - - - - - - - - - - - - - - - E D F A C G E E - - -   - - - - - - - - - - - - - - - - - D F A C G B - - - -   - - - - - - - - - - - - - - - - - - - - - - - - - - -   - - - - - - - - - - - - - - - - - - - - - - - - - - -   - - - - - - - - - - - - - - - - - - - A - - - - - - -   - - - - - - - - - - - - - - - - - - B B B - - - - - -   - - - - - - - - - - - - - - - - - - B B B - - - - - -   - - - - - - - - - - - - - - - - - - - - - - - - - - -   - - - - - - - - - - - - - - - - - - - - - - - - - - -   
- - - - - - - - - - - - - - - - - - - M M M M - - - -   - - - - - - - - - - - - - - - - - - - B B B - - - - -   - - - - - - - - - - - - - - - - - - - B - - - - - - -   - - - - - - - - - - - - - - - - - - - B - - - - - - -   - - - - - F A A A A A A A A F - - - - - - - - - - - -   - - - E D F A A A A A A A A F D E - - - - - - - - - -   - - C E D F A A A A A A A A F D E C - - - - - - - - -   - - C E D F A A A A A A A A F D E C - - - - - - - - -   - - C E D F A A A A A A A A F D E C - - - - - - - - -   - - - E D F A A A A A A A A F D E - - - - - - - - - -   - - - - - F A A A A A A A A F - - - - - - - - - - - -   - - - - - - - - - - - - - - - - - - - B B B - - - - -   - - - - - - - - - - - - - - - - D D F B B B G G - - -   - - - - - - - - - - - - - - - E D D F B B B B B B - -   - - - - - - - - - - - - - - C E D D F B B B F F F F -   - - - - - - - - - - - - - - C E D D F B B B K K K K -   - - - - - - - - - - - - - - C E D D F B B B T T T T -   - - - - - - - - - - - - - H C E D D F A C G I I I I I   - - - - - - - - - - - - - H C E D D F A C G I I I I I   - - - - - - - - - - - - - - C E D D F A C G C C C X -   - - - - - - - - - - - - - - C E D D F A C G U U U U -   - - - - - - - - - - - - - - C E D D F A C G J J J J -   - - - - - - - - - - - - - - - E D D F A C G C C C - -   - - - - - - - - - - - - - - - - D D F A C G B B - - -   - - - - - - - - - - - - - - - - - - - A C - - - - - -   - - - - - - - - - - - - - - - - - - - A - - - - - - -   - - - - - - - - - - - - - - - - - - - - - - - - - - -   - - - - - - - - - - - - - - - - - - B B - - - - - - -   - - - - - - - - - - - - - - - - - - B B B - - - - - -   - - - - - - - - - - - - - - - - - - - - - - - - - - -   - - - - - - - - - - - - - - - - - - - - - - - - - - -   
- - - - - - - - - - - - - - - - - - - M M M - - - - -   - - - - - - - - - - - - - - - - - - - - - - - - - - -   - - - - - - - - - - - - - - - - - - - - - - - - - - -   - - - - - - - - A A A A - - - - - - - - - - - - - - -   - - - - D F A A A A A A A A F D - - - B - - - - - - -   - - C E D F A A A A A A A A F D E C - B - - - - - - -   - H C E D F A A A A A A A A F D E C H - - - - - - - -   - H C E D F A A A A A A A A F D E C H - - - - - - - -   - H C E D F A A A A A A A A F D E C H - - - - - - - -   - - C E D F A A A A A A A A F D E C - B B B - - - - -   - - - - D F A A A A A A A A F D - - - B B B - - - - -   - - - - - - - - A A A A - - - - - - B B B B B - - - -   - - - - - - - - - - - - - - - - D F B B B B B G - - -   - - - - - - - - - - - - - - - E D F B B B B B B B - -   - - - - - - - - - - - - - - C E D F B B B B B E C C -   - - - - - - - - - - - - - - C E D F B B B B B L L L -   - - - - - - - - - - - - - H C E D F B B B B B R R R R   - - - - - - - - - - - - - H C E D F A B B B P P P P P   - - - - - - - - - - - - - H C E D F A B B B O O O O O   - - - - - - - - - - - - - H C E D F A C C G N N N N N   - - - - - - - - - - - - - - C E D F A C C G K K K K -   - - - - - - - - - - - - - - C E D F A C C G N N N N -   - - - - - - - - - - - - - - - E D F A C C G C C C - -   - - - - - - - - - - - - - - - - D F A C C G B B - - -   - - - - - - - - - - - - - - - - - - A C C G - - - - -   - - - - - - - - - - - - - - - - - - - - - - - - - - -   - - - - - - - - - - - - - - - - - - - - - - - - - - -   - - - - - - - - - - - - - - - - - - - - - - - - - - -   - - - - - - - - - - - - - - - - - - - - - - - - - - -   - - - - - - - - - - - - - - - - - - - - - - - - - - -   - - - - - - - - - - - - - - - - - - - - - - - - - - -   
- - - - - - - - - - - - - - - - - - - - - - - - - - -   - - - - - - - - - - - - - - - - - - - - - - - - - - -   - - - - - - - - - - - - - - - - - - - - - - - - - - -   - - - - - - A A A A A A A A - - - - - - - - - - - - -   - - - E D F A A A A A A A A F D E - - - - - - - - - -   - H C E D F A A A A A A A A F D E C H - - - - - - - -   - H C E D F A A A A A A A A F D E C H - - - - - - - -   B H C E D F A A A A A A A A F D E C H B - - - - - - -   - H C E D F A A A A A A A A F D E C H B B B - - - - -   - H C E D F A A A A A A A A F D E C H B B B B E E E -   - - - E D F A A A A A A A A F D E - B B B B B - - - -   - - - - - - A A A A A A A A - - - - B B B B B - - - -   - - - - - - - - - - - - - - - - D B B B B B B B - L -   - - - - - - - - - - - - - - - E D B B B B B B B B L -   - - - - - - - - - - - - - - C E D B B B B B B B B B -   - - - - - - - - - - - - - - C E D B B B B B B B C C -   - - - - - - - - - - - - - H C E D F B B B B B N N N N   - - - - - - - - - - - - - H C E D F B B B B B L L L L   - - - - - - - - - - - - - H C E D F B B B B B L L L L   - - - - - - - - - - - - - H C E D F A B B B K K K K K   - - - - - - - - - - - - - - C E D F A C C G G G G X -   - - - - - - - - - - - - - - C E D F A C C G C C C C -   - - - - - - - - - - - - - - - E D F A C C G B B B - -   - - - - - - - - - - - - - - - - D F A C C G B B - - -   - - - - - - - - - - - - - - - - - - A C C G - - - - -   - - - - - - - - - - - - - - - - - - - - - - - - - - -   - - - - - - - - - - - - - - - - - - - - - - - - - - -   - - - - - - - - - - - - - - - - - - - - - - - - - - -   - - - - - - - - - - - - - - - - - - - - - - - - - - -   - - - - - - - - - - - - - - - - - - - - - - - - - - -   - - - - - - - - - - - - - - - - - - - - - - - - - - -   
- - - - - - - - - - - - - - - - - - - - - - - - - - -   - - - - - - - - - - - - - - - - - - - - - - - - - - -   - - - - - - - - - - - - - - - - - - - - - - - - - - -   - - - - - F A A A A A A A A F - - - - - - - - - - - -   - - - E D F A A A A A A A A F D E - - - - - - - - - -   - H C E D F A A A A A A A A F D E C H - - - - - - - -   B H C E D F A A A A A A A A F D E C H B - - - - - - -   B H C E D F A A A A A A A A F D E C H B B B - - - - -   B H C E D F A A A A A A A A F D E C H B B B B - - - -   - H C E D F A A A A A A A A F D E C H B B B B - - - -   - - - E D F A A A A A A A A F D E - B B B B B - - - -   - - - - - F A A A A A A A A F - - B B B B B B B - - -   - - - - - - - - - - - - - - - - D B B B B B B B - K -   - - - - - - - - - - - - - - - E D B B B B B B B B K -   - - - - - - - - - - - - - - C E D B B B B B B B C C -   - - - - - - - - - - - - - H C E D B B B B B B B C C C   - - - - - - - - - - - - - H C E D B B B B B B B C C C   - - - - - - - - - - - - - H C E D F B B B B B V V V E   - - - - - - - - - - - - - H C E D F B B B B B B B B B   - - - - - - - - - - - - - H C E D F B B B B B V V V E   - - - - - - - - - - - - - H C E D F A B B B B B B B B   - - - - - - - - - - - - - - C E D F A C C G B B B B -   - - - - - - - - - - - - - - - E D F A C C G B B B - -   - - - - - - - - - - - - - - - - D F A C C G B B - - -   - - - - - - - - - - - - - - - - - F A C C G G - - - -   - - - - - - - - - - - - - - - - - - - - - - - - - - -   - - - - - - - - - - - - - - - - - - - - - - - - - - -   - - - - - - - - - - - - - - - - - - - - - - - - - - -   - - - - - - - - - - - - - - - - - - - - - - - - - - -   - - - - - - - - - - - - - - - - - - - - - - - - - - -   - - - - - - - - - - - - - - - - - - - - - - - - - - -   
- - - - - - - - - - - - - - - - - - - - - - - - - - -   - - - - - - - - - - - - - - - - - - - - - - - - - - -   - - - - - - - - - - - - - - - - - - - - - - - - - - -   - - - - - F A A A A A A A A F - - - - - - - - - - - -   - - - E D F A A A A A A A A F D E - - - - - - - - - -   - H C E D F A A A A A A A A F D E C H - - - - - - - -   B H C E D F A A A A A A A A F D E C H B - - - - - - -   B H C E D F A A A A A A A A F D E C H B B B - - - - -   B H C E D F A A A A A A A A F D E C H B B B B - - - -   - H C E D F A A A A A A A A F D E C H B B B B - - - -   - - - E D F A A A A A A A A F D E B B B B B B B - - -   - - - - - F A A A A A A A A F - - B B B B B B B - - -   - - - - - - - - - - - - - - - - D B B B B B B B - K -   - - - - - - - - - - - - - - - E D B B B B B B B B K -   - - - - - - - - - - - - - - C E D B B B B B B B B B -   - - - - - - - - - - - - - H C E D B B B B B B B B B B   - - - - - - - - - - - - - H C E D B B B B B B B B B B   - - - - - - - - - - - - - H C E D B B B B B B B E E E   - - - - - - - - - - - - - H C E D F B B B B B G G G G   - - - - - - - - - - - - - H C E D F B B B B B E E E E   - - - - - - - - - - - - - H C E D F A B B B B B B B B   - - - - - - - - - - - - - - C E D F A C C G B B B B -   - - - - - - - - - - - - - - - E D F A C C G B B B - -   - - - - - - - - - - - - - - - - D F A C C G B B - - -   - - - - - - - - - - - - - - - - - F A C C G G - - - -   - - - - - - - - - - - - - - - - - - - - - - - - - - -   - - - - - - - - - - - - - - - - - - - - - - - - - - -   - - - - - - - - - - - - - - - - - - - - - - - - - - -   - - - - - - - - - - - - - - - - - - - - - - - - - - -   - - - - - - - - - - - - - - - - - - - - - - - - - - -   - - - - - - - - - - - - - - - - - - - - - - - - - - -   
- - - - - - - - - - - - - - - - - - - M M M - - - - -   - - - - - - - - - - - - - - - - - - - - - - - - - - -   - - - - - - - - - - - - - - - - - - - - - - - - - - -   - - - - - - A A A A A A A A - - - - - - - - - - - - -   - - - E D F A A A A A A A A F D E - - B - - - - - - -   - H C E D F A A A A A A A A F D E C H B - - - - - - -   - H C E D F A A A A A A A A F D E C H - - - - - - - -   B H C E D F A A A A A A A A F D E C H B B B - - - - -   - H C E D F A A A A A A A A F D E C H B B B B - - - -   - H C E D F A A A A A A A A F D E C H B B B B - - - -   - - - E D F A A A A A A A A F D E - B B B B B - - - -   - - - - - - A A A A A A A A - - - B B B B B B B - - -   - - - - - - - - - - - - - - - - D B B B B B B B - L -   - - - - - - - - - - - - - - - E D B B B B B B B B L -   - - - - - - - - - - - - - - C E D B B B B B B B B B -   - - - - - - - - - - - - - - C E D B B B B B B B F F -   - - - - - - - - - - - - - H C E D B B B B B B B K K K   - - - - - - - - - - - - - H C E D F B B B B B R R R R   - - - - - - - - - - - - - H C E D F B B B B B Y Y Y Y   - - - - - - - - - - - - - H C E D F B B B B B G G G X   - - - - - - - - - - - - - - C E D F A B B B K K K K -   - - - - - - - - - - - - - - C E D F A C C G W W W W -   - - - - - - - - - - - - - - - E D F A C C G B B B - -   - - - - - - - - - - - - - - - - D F A C C G B B - - -   - - - - - - - - - - - - - - - - - - A C C G - - - - -   - - - - - - - - - - - - - - - - - - - - - - - - - - -   - - - - - - - - - - - - - - - - - - - - - - - - - - -   - - - - - - - - - - - - - - - - - - - - - - - - - - -   - - - - - - - - - - - - - - - - - - - - - - - - - - -   - - - - - - - - - - - - - - - - - - - - - - - - - - -   - - - - - - - - - - - - - - - - - - - - - - - - - - -   
- - - - - - - - - - - - - - - - - - - M M M M - - - -   - - - - - - - - - - - - - - - - - - - B B B - - - - -   - - - - - - - - - - - - - - - - - - - B - - - - - - -   - - - - - - - - A A A A - - - - - - - B - - - - - - -   - - - - E D F A A A A A A F D E - - - - - - - - - - -   - - C E E D F A A A A A A F D E E C - - - - - - - - -   - H C E E D F A A A A A A F D E E C H - - - - - - - -   - H C E E D F A A A A A A F D E E C H - - - - - - - -   - H C E E D F A A A A A A F D E E C H B B B - - - - -   - - C E E D F A A A A A A F D E E C B B B B B E E E -   - - - - E D F A A A A A A F D E - - B B B B B - - - -   - - - - - - - - A A A A - - - - - - B B B B B - - - -   - - - - - - - - - - - - - - - - D B B B B B B B - - -   - - - - - - - - - - - - - - - E D B B B B B B B B - -   - - - - - - - - - - - - - - C E D B B B B B B B B B -   - - - - - - - - - - - - - - C E D B B B B B B B K K -   - - - - - - - - - - - - - H C E D F B B B B B AcAcAcAc  - - - - - - - - - - - - - H C E D F B B B B B I I I I   - - - - - - - - - - - - - H C E D F B B B B B I I I I   - - - - - - - - - - - - - H C E D F A B B B I I I I I   - - - - - - - - - - - - - - C E D F A C C G AaAaAaAa-   - - - - - - - - - - - - - - C E D F A C C G K K K K -   - - - - - - - - - - - - - - - E D F A C C G C C C - -   - - - - - - - - - - - - - - - - D F A C C G B B - - -   - - - - - - - - - - - - - - - - - - A C C G - - - - -   - - - - - - - - - - - - - - - - - - - - - - - - - - -   - - - - - - - - - - - - - - - - - - - - - - - - - - -   - - - - - - - - - - - - - - - - - - - - - - - - - - -   - - - - - - - - - - - - - - - - - - - - - - - - - - -   - - - - - - - - - - - - - - - - - - - - - - - - - - -   - - - - - - - - - - - - - - - - - - - - - - - - - - -   
- - - - - - - - - - - - - - - - - - - M M M M - - - -   - - - - - - - - - - - - - - - - - - - B B B - - - - -   - - - - - - - - - - - - - - - - - - - - - - - - - - -   - - - - - - - - - - - - - - - - - - - - - - - - - - -   - - - - - D F A A A A A A F D - - - - - - - - - - - -   - - - C E D F A A A A A A F D E C - - - - - - - - - -   - - H C E D F A A A A A A F D E C H - - - - - - - - -   - - H C E D F A A A A A A F D E C H - - - - - - - - -   - - H C E D F A A A A A A F D E C H - - - - - - - - -   - - - C E D F A A A A A A F D E C - - B B B - - - - -   - - - - - D F A A A A A A F D - - - - B B B - - - - -   - - - - - - - - - - - - - - - - - - B B B B B - - - -   - - - - - - - - - - - - - - - - D D B B B B B G - - -   - - - - - - - - - - - - - - - E D D B B B B B B B - -   - - - - - - - - - - - - - - C E D D B B B B B E E E -   - - - - - - - - - - - - - - C E D D B B B B B K K K -   - - - - - - - - - - - - - - C E D D B B B B B U U U -   - - - - - - - - - - - - - H C E D D F B B B I I I I I   - - - - - - - - - - - - - H C E D D F B B B I I I I I   - - - - - - - - - - - - - - C E D D F A C G I I I I -   - - - - - - - - - - - - - - C E D D F A C G P P P P -   - - - - - - - - - - - - - - C E D D F A C G J J J J -   - - - - - - - - - - - - - - - E D D F A C G Q Q Q - -   - - - - - - - - - - - - - - - - D D F A C G B B - - -   - - - - - - - - - - - - - - - - - - - A C - - - - - -   - - - - - - - - - - - - - - - - - - - - - - G - - - -   - - - - - - - - - - - - - - - - - - - - - - - - - - -   - - - - - - - - - - - - - - - - - - - - - - - - - - -   - - - - - - - - - - - - - - - - - - - - - - - - - - -   - - - - - - - - - - - - - - - - - - - - - - - - - - -   - - - - - - - - - - - - - - - - - - - - - - - - - - -   
- - - - - - - - - - - - - - - - - - - M M M - - - - -   - - - - - - - - - - - - - - - - - - - - - - - - - - -   - - - - - - - - - - - - - - - - - - - - - - - - - - -   - - - - - - - - - - - - - - - - - - - - - - - - - - -   - - - - - - - - - - - - - - - - - - - - - - - - - - -   - - - - - D F F A A A A F F D - - - - - - - - - - - -   - - - - E D F F A A A A F F D E - - - - - - - - - - -   - - - C E D F F A A A A F F D E C - - - - - - - - - -   - - - - E D F F A A A A F F D E - - - - - - - - - - -   - - - - - D F F A A A A F F D - - - - - - - - - - - -   - - - - - - - - - - - - - - - - - - - - - - - - - - -   - - - - - - - - - - - - - - - - - - - B B B - - - - -   - - - - - - - - - - - - - - - - - D F B B B G - - - -   - - - - - - - - - - - - - - - - E D F B B B C C - - -   - - - - - - - - - - - - - - - C E D F B B B E E E - -   - - - - - - - - - - - - - - H C E D F B B B K K K K -   - - - - - - - - - - - - - - H C E D F B B B T T T T -   - - - - - - - - - - - - - - H C E D F A C G I I I I -   - - - - - - - - - - - - - - H C E D F A C G I I I I -   - - - - - - - - - - - - - - H C E D F A C G Q Q Q Q -   - - - - - - - - - - - - - - H C E D F A C G Z Z Z Z -   - - - - - - - - - - - - - - - C E D F A C G J J J - -   - - - - - - - - - - - - - - - - E D F A C G Q Q - - -   - - - - - - - - - - - - - - - - - D F A C G C - - - -   - - - - - - - - - - - - - - - - - - - - - - - - - - -   - - - - - - - - - - - - - - - - - - - - - - - - - - -   - - - - - - - - - - - - - - - - - - - - - - G - - - -   - - - - - - - - - - - - - - - - - - - - - - - - - - -   - - - - - - - - - - - - - - - - - - - - - - - - - - -   - - - - - - - - - - - - - - - - - - - - - - - - - - -   - - - - - - - - - - - - - - - - - - - - - - - - - - -   
- - - - - - - - - - - - - - - - - - - - - - - - - - -   - - - - - - - - - - - - - - - - - - - - - - - - - - -   - - - - - - - - - - - - - - - - - - - - - - - - - - -   - - - - - - - - - - - - - - - - - - - - - - - - - - -   - - - - - - - - - - - - - - - - - - - - - - - - - - -   - - - - - - - - - - - - - - - - - - - - - - - - - - -   - - - - - - - F A A A A F - - - - - - - - - - - - - -   - - - - - - D F A A A A F D - - - - - - - - - - - - -   - - - - - - - F A A A A F - - - - - - - - - - - - - -   - - - - - - - - - - - - - - - - - - - - - - - - - - -   - - - - - - - - - - - - - - - - - - - - - - - - - - -   - - - - - - - - - - - - - - - - - - - - - - - - - - -   - - - - - - - - - - - - - - - - - - F A C G - - - - -   - - - - - - - - - - - - - - - - E D F A C G B B - - -   - - - - - - - - - - - - - - - C E D F A C G C C C - -   - - - - - - - - - - - - - - - C E D F A C G J J J - -   - - - - - - - - - - - - - - H C E D F A C G L L L L -   - - - - - - - - - - - - - - H C E D F A C G S S S S -   - - - - - - - - - - - - - - H C E D F C C G O O O O -   - - - - - - - - - - - - - - H C E D F C C G G G G X -   - - - - - - - - - - - - - - - C E D F C C G J J J - -   - - - - - - - - - - - - - - - C E D F C C G J J J - -   - - - - - - - - - - - - - - - - E D F C C G B B - - -   - - - - - - - - - - - - - - - - - - F C C G - - - - -   - - - - - - - - - - - - - - - - - - - - - - - - - - -   - - - - - - - - - - - - - - - - - - - - - - - - - - -   - - - - - - - - - - - - - - - - - - - - - - G - - - -   - - - - - - - - - - - - - - - - - - - - - - - - - - -   - - - - - - - - - - - - - - - - - - - - - - - - - - -   - - - - - - - - - - - - - - - - - - - - - - - B - - -   - - - - - - - - - - - - - - - - - - - - - - B B B - -   
- - - - - - - - - - - - - - - - - - - - - - - - - - -   - - - - - - - - - - - - - - - - - - - - - - - - - - -   - - - - - - - - - - - - - - - - - - - - - - - - - - -   - - - - - - - - - - - - - - - - - - - - - - - - - - -   - - - - - - - - - - - - - - - - - - - - - - - - - - -   - - - - - - - - - - - - - - - - - - - - - - - - - - -   - - - - - - - - - - - - - - - - - - - - - - - - - - -   - - - - - - - - - - - - - - - - - - - - - - - - - - -   - - - - - - - - - - - - - - - - - - - - - - - - - - -   - - - - - - - - - - - - - - - - - - - - - - - - - - -   - - - - - - - - - - - - - - - - - - - - - - - - - - -   - - - - - - - - - - - - - - - - - - - - - - - - - - -   - - - - - - - - - - - - - - - - - - - - - - - - - - -   - - - - - - - - - - - - - - - - - E D H C G B - - - -   - - - - - - - - - - - - - - - - C E D H C G C C - - -   - - - - - - - - - - - - - - - C C E D H C G G G G - -   - - - - - - - - - - - - - - - C C E D H C G J J J - -   - - - - - - - - - - - - - - - C C E D H C G K K K - -   - - - - - - - - - - - - - - - C C E D H C G K K K - -   - - - - - - - - - - - - - - - C C E D H C G J J J - -   - - - - - - - - - - - - - - - C C E D H C G J J J - -   - - - - - - - - - - - - - - - - C E D H C G E E - - -   - - - - - - - - - - - - - - - - - E D H C G B - - - -   - - - - - - - - - - - - - - - - - - - - - - - - - - -   - - - - - - - - - - - - - - - - - - - - - - - - - - -   - - - - - - - - - - - - - - - - - - - - - - - - - - -   - - - - - - - - - - - - - - - - - - - - - - - - - - -   - - - - - - - - - - - - - - - - - - - - - - - G - - -   - - - - - - - - - - - - - - - - - - - - - - - B - - -   - - - - - - - - - - - - - - - - - - - - - - B B B - -   - - - - - - - - - - - - - - - - - - - - - - B B B - -   
- - - - - - - - - - - - - - - - - - - - - - - - - - -   - - - - - - - - - - - - - - - - - - - - - - - - - - -   - - - - - - - - - - - - - - - - - - - - - - - - - - -   - - - - - - - - - - - - - - - - - - - - - - - - - - -   - - - - - - - - - - - - - - - - - - - - - - - - - - -   - - - - - - - - - - - - - - - - - - - - - - - - - - -   - - - - - - - - - - - - - - - - - - - - - - - - - - -   - - - - - - - - - - - - - - - - - - - - - - - - - - -   - - - - - - - - - - - - - - - - - - - - - - - - - - -   - - - - - - - - - - - - - - - - - - - - - - - - - - -   - - - - - - - - - - - - - - - - - - - - - - - - - - -   - - - - - - - - - - - - - - - - - - - - - - - - - - -   - - - - - - - - - - - - - - - - - - - - - - - - - - -   - - - - - - - - - - - - - - - - - - - G H - - - - - -   - - - - - - - - - - - - - - - - - E D G H G B - - - -   - - - - - - - - - - - - - - - - C E D G H G C C - - -   - - - - - - - - - - - - - - - - C E D G H G Q Q - - -   - - - - - - - - - - - - - - - H C E D G H G N N N - -   - - - - - - - - - - - - - - - H C E D G H G L L L - -   - - - - - - - - - - - - - - - - C E D G H G N N - - -   - - - - - - - - - - - - - - - - C E D G H G W W - - -   - - - - - - - - - - - - - - - - - E D G H G C - - - -   - - - - - - - - - - - - - - - - - - - G H - - - - - -   - - - - - - - - - - - - - - - - - - - - - - - - - - -   - - - - - - - - - - - - - - - - - - - - - - - - - - -   - - - - - - - - - - - - - - - - - - - - - - - - - - -   - - - - - - - - - - - - - - - - - - - - - - - - - - -   - - - - - - - - - - - - - - - - - - - - - - - - - - -   - - - - - - - - - - - - - - - - - - - - - - - - - - -   - - - - - - - - - - - - - - - - - - - - - - B B B - -   - - - - - - - - - - - - - - - - - - - - - - B B B - -   
- - - - - - - - - - - - - - - - - - - - - - - - - - -   - - - - - - - - - - - - - - - - - - - - - - - - - - -   - - - - - - - - - - - - - - - - - - - - - - - - - - -   - - - - - - - - - - - - - - - - - - - - - - - - - - -   - - - - - - - - - - - - - - - - - - - - - - - - - - -   - - - - - - - - - - - - - - - - - - - - - - - - - - -   - - - - - - - - - - - - - - - - - - - - - - - - - - -   - - - - - - - - - - - - - - - - - - - - - - - - - - -   - - - - - - - - - - - - - - - - - - - - - - - - - - -   - - - - - - - - - - - - - - - - - - - - - - - - - - -   - - - - - - - - - - - - - - - - - - - - - - - - - - -   - - - - - - - - - - - - - - - - - - - - - - - - - - -   - - - - - - - - - - - - - - - - - - - - - - - - - - -   - - - - - - - - - - - - - - - - - - - - - - - - - - -   - - - - - - - - - - - - - - - - - - - G G - - - - - -   - - - - - - - - - - - - - - - - - C E G G G B - - - -   - - - - - - - - - - - - - - - - - C E G G G C - - - -   - - - - - - - - - - - - - - - - H C E G G G B J - - -   - - - - - - - - - - - - - - - - H C E G G G C J - - -   - - - - - - - - - - - - - - - - - C E G G G B - - - -   - - - - - - - - - - - - - - - - - C E G G G B - - - -   - - - - - - - - - - - - - - - - - - - G G - - - - - -   - - - - - - - - - - - - - - - - - - - - - - - - - - -   - - - - - - - - - - - - - - - - - - - - - - - - - - -   - - - - - - - - - - - - - - - - - - - - - - - - - - -   - - - - - - - - - - - - - - - - - - - - - - - - - - -   - - - - - - - - - - - - - - - - - - - - - - - - - - -   - - - - - - - - - - - - - - - - - - - - - - - - - - -   - - - - - - - - - - - - - - - - - - - - - - - - - - -   - - - - - - - - - - - - - - - - - - - - - - - - - - -   - - - - - - - - - - - - - - - - - - - - - - - - - - -   
- - - - - - - - - - - - - - - - - - - - - - - - - - -   - - - - - - - - - - - - - - - - - - - - - - - - - - -   - - - - - - - - - - - - - - - - - - - - - - - - - - -   - - - - - - - - - - - - - - - - - - - - - - - - - - -   - - - - - - - - - - - - - - - - - - - - - - - - - - -   - - - - - - - - - - - - - - - - - - - - - - - - - - -   - - - - - - - - - - - - - - - - - - - - - - - - - - -   - - - - - - - - - - - - - - - - - - - - - - - - - - -   - - - - - - - - - - - - - - - - - - - - - - - - - - -   - - - - - - - - - - - - - - - - - - - - - - - - - - -   - - - - - - - - - - - - - - - - - - - - - - - - - - -   - - - - - - - - - - - - - - - - - - - - - - - - - - -   - - - - - - - - - - - - - - - - - - - - - - - - - - -   - - - - - - - - - - - - - - - - - - - - - - - - - - -   - - - - - - - - - - - - - - - - - - - - - - - - - - -   - - - - - - - - - - - - - - - - - - - - - - - - - - -   - - - - - - - - - - - - - - - - - - C A G G - - - - -   - - - - - - - - - - - - - - - - - - C A G G - - - - -   - - - - - - - - - - - - - - - - - - C A G G - - - - -   - - - - - - - - - - - - - - - - - - C A G G - - - - -   - - - - - - - - - - - - - - - - - - - - - - - - - - -   - - - - - - - - - - - - - - - - - - - - - - - - - - -   - - - - - - - - - - - - - - - - - - - - - - - - - - -   - - - - - - - - - - - - - - - - - - - - - - - - - - -   - - - - - - - - - - - - - - - - - - - - - - - - - - -   - - - - - - - - - - - - - - - - - - - - - - - - - - -   - - - - - - - - - - - - - - - - - - - - - - - - - - -   - - - - - - - - - - - - - - - - - - - - - - - - - - -   - - - - - - - - - - - - - - - - - - - - - - - - - - -   - - - - - - - - - - - - - - - - - - - - - - - - - - -   - - - - - - - - - - - - - - - - - - - - - - - - - - -   
