model
size = 21 32 18, scale = 0.05, origin = -y
material 
  colors = A:#111 B:#063 C:#093 D:#0C3 E:#CF0 F:#010 G:#363 H:#100 I:#CC0 J:#C90 K:#FF0 L:#F96 M:#690 N:#F90 O:#C60 P:#EEE Q:#633 R:#200 S:#990
voxels
365-6A14-2(8A13-)8A15-2(4A3B14-)4A2B15-4AB17-2A479-6A14-8A12-2(10A11-)10A2B3(10-8A3B)10-8A2B12-6AB14-6A16-4A383-B20-2B9-6A4-2B7-10A11-10A10-12A9-12A2B7-12A3B7-10A3BF7-10A4B7-10A3B8-10A2B10-8A2B11-8A14-6A16-4A341-B31-6A14-8A12-10A10-12A2B7-12AB2F6-12AB3F5-12A2B2F6-10A3BF6-12A3B6-12AB2(2A7-10A2B)9-10A2B10-8A13-11A12-4A2-3A294-B51-8A12-10A10-12A3B6-12A2B2F4-14ABI5-14ABH5-14AB2F5-12A3B6-12ABAPB5-12ABASO5-12ABAJO5-12A2B2A6-10A3B8-12AB9-12A10-11A11-4A2-3A273-B51-8A12-10AB9-12A3BF4-14AB2H2(4-14AB2E)4-14AB2F5-12A3B6-12ABAPB5-12ABA2K5-12ABA2J5-12A3BA5-12A2B8-13A8-14A8-13A9-11A142-3C17-5C16-5B16-2E3B2(16-5B)16-6B16-3B31-10A10-12A3B6-5A2B5A3BF4-6A2B6A2HI4-4A3B7ABH5-4A3B7ABR5-4A3B7AB2M4-14A2BF4-14A3B4-15A2L4-15AQA5-12A3B6-13AB2(7-15A)7-14A8-12A11-2A3-3A7-7G13-10D9-5DED2-2DE4D5-3D8-6D4-3C9-5C3-4C8-7C2-2C2E4-2C2-7C2-4B3-3B2-7B3-4B-3B3-7B4-6B4-E5BE5-5B4-8B5-E3B4-7B14-7B13-7B9-4A8B8-4A12B4-4A5B5A2BF4-4A5B5AB2E4-3A5B6AB2I4-2(3A5B6ABH5-)14AB2F4-14A3B4-14AB2A4-14A2B5-14A3B5-14A2(7-15A)6-15A7-13A10-4A-5A5-11G9-11DE3D5-5DE11D4-5D5-8D2-4C8-2(7C2-4C4-2C2-)8C-4B3-3B2-8B2-2(4B-)9B2-9B-E7BE3-7B2-9B5-E4B2-9B12-8B13-8B8-3A10B7-3A13B4-4A9BA2BF4-4A5B5ABHI4-2(3A5B6ABH5-)3A5B6AB2E4-14AB2F4-2(14A2B5-)14A3B4-14A3B5-14A7-15A6-16A6-15A7-13A10-4A-5A5-11G9-15D5-17D4-5D5-8D2-4C8-2(7C2-4C4-2C2-)8C-4B3-3B2-8B2-2(4B-)9B2-9B-8BE3-7B2-9B5-5B2-9B12-8B13-8B8-3A10B7-3A13B4-4A9BA2BF4-4A5B5ABHI4-2(3A5B6ABH5-)3A5B6AB2E4-14AB2F4-14A3B4-14AB2A4-14A2B5-14A3B5-14A7-15A6-16A6-15A7-13A10-4A-5A6-7G13-3DE6D9-5DED2-3DE3D5-3D8-E5D4-3C9-5C3-CE2C8-7C2-2C2E4-2C2-7C2-4B3-3B2-7B3-4B-3B3-E2(6B4-)6BE5-2BE2B4-8B5-E3B4-7B14-7B13-7B9-4A8B8-4A10B6-4A5B5AB2F4-4A5B5AB2E4-3A5B6AB2M4-2(3A5B6ABH5-)14A2BF4-14A3B4-15A2L4-15AQA4-14A2B6-14A2(7-15A)6-15A7-13A10-4A-5A121-3C17-5C16-5B16-E4B2(16-5B)16-6B16-3B17-B13-10AB9-12AB8-2(5A2B)6-6A2B6ABHF4-2(4A3B7ABH5-)4A3B7AB2I4-14A2BF4-15APB4-15A2K4-15A2J5-12A3BA5-13AB2(7-15A)7-14A8-12A11-2A3-3A252-B51-8A12-10AB9-12AB7-14AB2F2(4-14AB2E)4-14AB2F4-14A2B6-12A4B5-12ABA2N5-12ABAON5-12A2B2A5-12A2B8-13A8-14A8-13A9-11A272-B51-8A12-10A10-12AB8-12A3B5-14AB2F4-14AB2H4-14AB2E4-14A2BF5-12A3B2(6-12AB2A)6-12A2B8-10A3B8-12AB9-12A10-11A11-4A2-3A294-B31-6A14-8A12-10A10-12A2B7-12A4B4-14AB2F4-14ABHF4-14A2B6-12A3B6-12A2B8-10A3B8-10A2B9-10A2B10-8A13-11A12-4A2-3A336-B20-2B9-6A4-2B7-10A11-10AB9-3(12A2B7-)12A2BF7-2(10A3B8-)10A2B10-8A3B10-8A2B12-6A16-4A415-6A14-8A12-3(10A11-)10A12-8AB12-8A13-8A14-6A15-6A16-4A457-6A14-3(8A13-)8A15-2(4A17-)4A18-2A135-
