model
size = 31 31 13, scale = 0.05, origin = -y
material 
  colors = A:#FC0 B:#F96 C:#FF0
voxels
--------------ACA-------------- -------------BC-CB------------- ------------AC---CA------------ -----------BC-----CB----------- ----------BC-------CB---------- ----------AB-------BA---------- ----------BC-------CB---------- ----------AB--BCB--BA---------- ----------BC--CAC--CB---------- ----------AB--BCB--BA---------- ----BABABABAAAAAAAAABABABAB---- ---BCBCBCBA----A----ABCBCBCB--- --AC------A---BBB---A------CA-- -BC-------A--BCCCB--A-------CB- AC-----BCBA-BCAAACB-ABCB-----CA C------CACAABCACACBAACAC------C AC-----BCBA-BCAAACB-ABCB-----CA -BC-------A--BCCCB--A-------CB- --AC------A---BBB---A------CA-- ---BCBCBCBA----A----ABCBCBCB--- ----BABABABAAAAAAAAABABABAB---- ----------AB--BCB--BA---------- ----------BC--CAC--CB---------- ----------AB--BCB--BA---------- ----------BC-------CB---------- ----------AB-------BA---------- ----------BC-------CB---------- -----------BC-----CB----------- ------------AC---CA------------ -------------BC-CB------------- --------------ACA-------------- 
------------------------------- ------------------------------- ------------------------------- ------------------------------- ------------------------------- ------------------------------- ------------------------------- ------------------------------- ------------------------------- ------------------------------- ------------------------------- ------------------------------- ------------------------------- ------------------------------- ------------------------------- ---------------A--------------- ------------------------------- ------------------------------- ------------------------------- ------------------------------- ------------------------------- ------------------------------- ------------------------------- ------------------------------- ------------------------------- ------------------------------- ------------------------------- ------------------------------- ------------------------------- ------------------------------- ------------------------------- 
------------------------------- ------------------------------- ------------------------------- ------------------------------- ------------------------------- ------------------------------- ------------------------------- ------------------------------- ------------------------------- ------------------------------- ------------------------------- ------------------------------- ------------------------------- -------------AAAAA------------- ------------AABABAA------------ -------------AAAAA------------- ------------AABABAA------------ -------------AAAAA------------- ------------------------------- ------------------------------- ------------------------------- ------------------------------- ------------------------------- ------------------------------- ------------------------------- ------------------------------- ------------------------------- ------------------------------- ------------------------------- ------------------------------- ------------------------------- 
------------------------------- ------------------------------- ------------------------------- ------------------------------- ------------------------------- ------------------------------- ------------------------------- ------------------------------- ------------------------------- ------------------------------- ------------------------------- ------------------------------- ------------------------------- -------------AABAA------------- ------------AAAAAAA------------ ------------BBAAABB------------ ------------AAAAAAA------------ -------------AABAA------------- ------------------------------- ------------------------------- ------------------------------- ------------------------------- ------------------------------- ------------------------------- ------------------------------- ------------------------------- ------------------------------- ------------------------------- ------------------------------- ------------------------------- ------------------------------- 
------------------------------- ------------------------------- ------------------------------- ------------------------------- ------------------------------- ------------------------------- ------------------------------- ------------------------------- ------------------------------- ------------------------------- ------------------------------- ------------------------------- ------------------------------- ------------------------------- ------------------------------- ---------------A--------------- ------------------------------- ------------------------------- ------------------------------- ------------------------------- ------------------------------- ------------------------------- ------------------------------- ------------------------------- ------------------------------- ------------------------------- ------------------------------- ------------------------------- ------------------------------- ------------------------------- ------------------------------- 
------------------------------- ------------------------------- ------------------------------- ------------------------------- ------------------------------- ------------------------------- ------------------------------- ------------------------------- ------------------------------- ------------------------------- ------------------------------- ------------------------------- ------------------------------- ------------------------------- ------------------------------- ------------------------------- ------------------------------- ------------------------------- ------------------------------- ------------------------------- ------------------------------- ------------------------------- ------------------------------- ------------------------------- ------------------------------- ------------------------------- ------------------------------- ------------------------------- ------------------------------- ------------------------------- ------------------------------- 
------------------------------- ------------------------------- ------------------------------- ------------------------------- ------------------------------- ------------------------------- ------------------------------- ------------------------------- ------------------------------- ------------------------------- ------------------------------- ------------------------------- ------------------------------- ------------------------------- ------------------------------- ------------------------------- ------------------------------- ------------------------------- ------------------------------- ------------------------------- ------------------------------- ------------------------------- ------------------------------- ------------------------------- ------------------------------- ------------------------------- ------------------------------- ------------------------------- ------------------------------- ------------------------------- ------------------------------- 
------------------------------- ------------------------------- ------------------------------- ------------------------------- ------------------------------- ------------------------------- ------------------------------- ------------------------------- ------------------------------- ------------------------------- ------------------------------- ------------------------------- ------------------------------- ------------------------------- ------------------------------- ------------------------------- ------------------------------- ------------------------------- ------------------------------- ------------------------------- ------------------------------- ------------------------------- ------------------------------- ------------------------------- ------------------------------- ------------------------------- ------------------------------- ------------------------------- ------------------------------- ------------------------------- ------------------------------- 
------------------------------- ------------------------------- ------------------------------- ------------------------------- ------------------------------- ------------------------------- ------------------------------- ------------------------------- ------------------------------- ------------------------------- ------------------------------- ------------------------------- ------------------------------- ------------------------------- ------------------------------- ---------------A--------------- ------------------------------- ------------------------------- ------------------------------- ------------------------------- ------------------------------- ------------------------------- ------------------------------- ------------------------------- ------------------------------- ------------------------------- ------------------------------- ------------------------------- ------------------------------- ------------------------------- ------------------------------- 
------------------------------- ------------------------------- ------------------------------- ------------------------------- ------------------------------- ------------------------------- ------------------------------- ------------------------------- ------------------------------- ------------------------------- ------------------------------- ------------------------------- ------------------------------- -------------AABAA------------- ------------AAAAAAA------------ ------------BBAAABB------------ ------------AAAAAAA------------ -------------AABAA------------- ------------------------------- ------------------------------- ------------------------------- ------------------------------- ------------------------------- ------------------------------- ------------------------------- ------------------------------- ------------------------------- ------------------------------- ------------------------------- ------------------------------- ------------------------------- 
------------------------------- ------------------------------- ------------------------------- ------------------------------- ------------------------------- ------------------------------- ------------------------------- ------------------------------- ------------------------------- ------------------------------- ------------------------------- ------------------------------- ------------------------------- -------------AAAAA------------- ------------AABABAA------------ -------------AAAAA------------- ------------AABABAA------------ -------------AAAAA------------- ------------------------------- ------------------------------- ------------------------------- ------------------------------- ------------------------------- ------------------------------- ------------------------------- ------------------------------- ------------------------------- ------------------------------- ------------------------------- ------------------------------- ------------------------------- 
------------------------------- ------------------------------- ------------------------------- ------------------------------- ------------------------------- ------------------------------- ------------------------------- ------------------------------- ------------------------------- ------------------------------- ------------------------------- ------------------------------- ------------------------------- ------------------------------- ------------------------------- ---------------A--------------- ------------------------------- ------------------------------- ------------------------------- ------------------------------- ------------------------------- ------------------------------- ------------------------------- ------------------------------- ------------------------------- ------------------------------- ------------------------------- ------------------------------- ------------------------------- ------------------------------- ------------------------------- 
--------------ACA-------------- -------------BC-CB------------- ------------AC---CA------------ -----------BC-----CB----------- ----------BC-------CB---------- ----------AB-------BA---------- ----------BC-------CB---------- ----------AB--BCB--BA---------- ----------BC--CAC--CB---------- ----------AB--BCB--BA---------- ----BABABABAAAAAAAAABABABAB---- ---BCBCBCBA----A----ABCBCBCB--- --AC------A---BBB---A------CA-- -BC-------A--BCCCB--A-------CB- AC-----BCBA-BCAAACB-ABCB-----CA C------CACAABCACACBAACAC------C AC-----BCBA-BCAAACB-ABCB-----CA -BC-------A--BCCCB--A-------CB- --AC------A---BBB---A------CA-- ---BCBCBCBA----A----ABCBCBCB--- ----BABABABAAAAAAAAABABABAB---- ----------AB--BCB--BA---------- ----------BC--CAC--CB---------- ----------AB--BCB--BA---------- ----------BC-------CB---------- ----------AB-------BA---------- ----------BC-------CB---------- -----------BC-----CB----------- ------------AC---CA------------ -------------BC-CB------------- --------------ACA-------------- 
