model
size = 18 32 20, scale = 0.05, origin = -y
material 
  colors = A:#0B0 B:#0A0 C:#080 D:#050 E:#111 F:#00E
voxels
204-D16-3D16-D538-2(2BD15-)DBD536-2(3BD14-)5B14-3B71-2A15-2ADA13-3(6A12-)6A13-4A15-DA266-2(7A11-)7A10-5B3A10-5B13-5B14-3B2A14-4A13-6A12-6A11-8A10-8A9-3(10A8-)10A9-8A10-8A11-6A13-4A195-6A11-8A9-9A9-A5B3A9-9A8-5B4A9-2(5B2A11-)5B6A7-2(11A3(6-12A)6-)12A6-12A7-10A8-10A9-8A11-6A140-6A11-8A10-8A9-10A8-3AB6A8-A5B4A8-10A7-5B5A7-7B2A8-2C5B6A5-2C5B4A2E5-2C2AB6AEF2(5-12AE)5-14A4-13A4(4-14A)5-2(12A6-)12A7-10A9-8A11-6A47-6A12-7A11-8A2(10-9A)9-10A8-10A6-12A6-4A3B6A5-3A3B7A7-11A4-C7B6A4-2(C7B5A5-)2A5B5AE5-3A3B6AF2(5-12AE)4-15A3-6(14A4-)14A5-14A4-12A2-A4-10A4-A4-8A11-6A29-A3CB2A11-A4C3A10-A5C3A9-2A4C4A8-2A5C4A6-4A4C5A5-4A5C3A6-5A4C4A5-A2CA3B2C4A5-13A4-2CB11A4-C7B6A4-A7B5A5-A7B4AE5-2A5B5AE5-3A3B6A2(E4-13A)E4-15A3-14A3-3(16A2-)16A3-2(14A4-)14A5-12A6-12A7-10A9-8A13-2A13-A5CA11-A5C2A10-A6C3A8-A6C4A7-A7C4A5-2A7C2ADA5-A8CADA6-A2CA5C4A5-A2CA3B2C4A5-12A5-2C5B8A3-A7B7A3-A7B6A4-A7B5A4-3A5B5AE4-4A3B6A2(E4-13A)E4-15A6(2-16A)3-2(14A4-)14A5-12A7-10A9-8A12-4A12-2(A5CA11-A5C2A10-A6C3A8-A6C4A7-A7CAD2A5-2A7C2ADA5-A8CADA6-A2CA5C4A5-A2CA3B2C4A5-12A5-2A5B8A3-A7B7A3-A7B6A4-A7B6A3-3A5B7A3-4A3B8A2(3-15A)8(2-16A)3-14A4-14A5-12A7-10A9-8A11-6A11-)A5CA11-A5C2A10-A6C2AD8-A6C4A7-A7C4A5-2A7C2ADA5-A8CADA6-A2CA5C4A5-A2CA3B2C4A5-12A5-2C5B8A3-A7B7A3-A7B6A4-A7B5A4-3A5B5AE4-4A3B6A2(E4-13A)E4-15A6(2-16A)3-2(14A4-)14A5-12A7-10A9-8A12-4A12-A3CB2A11-A4C3A10-A5C3A9-2A4C4A8-2A5C4A6-4A4C5A5-4A5C3A6-5A4C4A5-A2CA3B2C4A5-13A4-2C5B7A4-C7B6A4-A7B5A5-A7B4AE5-2A5B5AE5-3A3B6A2(E4-13A)E4-15A3-14A3-3(16A2-)16A3-2(14A4-)14A5-12A6-12A7-10A9-8A13-2A13-6A12-7A11-8A10-3AD5A10-9A9-10A8-10A6-12A6-4A3B6A5-13A6-5B7A4-C7B6A4-2(C7B5A5-)2A5B5AE5-3A3B6AF2(5-12AE)4-15A3-6(14A4-)14A5-14A4-12A2-A4-10A4-A4-7AD11-6A104-6A11-8A10-8A9-10A8-3AB6A8-10A7-5B6A7-5B5A7-7B2A8-2C5B6A5-2C5B4A2E5-2C2AB6AEF2(5-12AE)5-14A4-13A4-14A4-13AD2(4-14A)5-2(12A6-)12A7-10A9-8A11-6A158-6A11-2(8A10-)8A8-5B5A8-5B4A9-2(5B2A11-)5B6A7-11A2(6-12A)6-11A7-11A5(6-12A)7-10A8-10A9-8A11-6A246-2BD14-2(5B13-)5B14-3B2A14-4A13-6A12-6A11-8A10-8A9-3(10A8-)10A9-8A10-8A11-6A13-4A265-2B2(D14-3B)D14-5B14-3B89-2A15-4A13-2(6A12-)6A13-4A15-AD320-DBD15-2BD15-DBD538-D16-3D16-D335-
