model
size = 7 29 14, scale = 0.05, origin = -y
material 
  colors = A:#030 B:#0E0 C:#630 D:#080 E:#070 F:#050 G:#0A0 H:#111 I:#020
voxels
------- ------- ------- ------- ------- ------- ------- ------- ------- ------- ------- ------- ------- A------ A------ CC----- GE----- GD----- DD----- DD----- DA----- CC----- FA----- GA----- EF----- ------- ------- ------- ------- 
------- ------- ------- ------- ------- ------- -DA---- -EA---- -CC---- -BD---- -EA---- -AA---- -AF---- -AF---- -EA---- -GC---- -GA---- -DD---- -DD---- -GA---- -DA---- -DC---- -EG---- -BA---- -BA---- -AA---- ------- ------- ------- 
------- ------- ------- ------- --CC--- --BF--- --EE--- --EA--- --GC--- --AA--- --BF--- --AF--- --AF--- --EF--- --EF--- --EC--- --DA--- --DA--- --BA--- --DA--- --DD--- --BC--- --BD--- --BG--- --DA--- --GA--- -CCC--- ------- ------- 
------- ------- ------- ---E--- ---C--- ---EF-- ---EA-- ---EA-- ---AC-- ---AA-- ---BA-- ---BF-- ---EF-- ---EF-- ---DA-- ---DC-- ---DA-- ---DA-- ---DA-- ---BA-- ---BA-- ---BC-- ---DA-- ---DA-- ---A--- --BA--- -BBC--- DDGF--- --DD--- 
------- ------- ------- ----A-- ----C-- ----A-- ----A-- ----A-- ----C-- ----A-- ----A-- ----B-- ----B-- ----A-- ----F-- ----C-- ----A-- ----B-- ----B-- ----B-- ----E-- ----C-- ----A-- ----D-- ---DA-- --EBA-- -BBBC-- -GBIA-- ---A--- 
------- ------- -----G- -----D- -----C- -----A- -----A- -----A- -----C- -----F- -----A- -----A- -----B- -----B- -----A- -----C- -----B- -----B- -----F- -----A- -----A- -----C- -----A- ----GA- ---DBA- --DBBE- --BBBC- --GID-- ---GF-- 
-----E- -----B- -----E- -----B- -----DH -----AC -----DC -----EC -----EH -----AC -----AC -----BC -----BC -----BC -----BC -----BH -----BC -----EC -----EC -----EC -----EC -----EH -----BC ----EBC ---GDDC --DDEBC --DDDHH --BEBA- ----F-- 
-----B- -----E- -----B- -----E- -----DH -----AC -----DC -----EC -----EH -----AC -----AC -----BC -----BC -----BC -----BC -----BH -----BC -----EC -----EC -----EC -----EC -----EH -----BC ----EBC ---GDDC --DDEBC --DDDHH --BEBA- ----F-- 
------- ------- -----G- -----D- -----C- -----A- -----A- -----A- -----C- -----F- -----A- -----A- -----B- -----B- -----A- -----C- -----B- -----B- -----F- -----A- -----A- -----C- -----A- ----GA- ---DBA- --DBBE- --BBBC- --GID-- ---GF-- 
------- ------- ------- ----A-- ----C-- ----A-- ----A-- ----A-- ----C-- ----A-- ----A-- ----B-- ----B-- ----A-- ----F-- ----C-- ----A-- ----B-- ----B-- ----B-- ----E-- ----C-- ----A-- ----D-- ---DA-- --EBA-- -BBBC-- -GBIA-- ---A--- 
------- ------- ------- ---E--- ---C--- ---EF-- ---EA-- ---EA-- ---AC-- ---AA-- ---BA-- ---BF-- ---EF-- ---EF-- ---DA-- ---DC-- ---DA-- ---DA-- ---DA-- ---BA-- ---BA-- ---BC-- ---DA-- ---DA-- ---A--- --BA--- -BBC--- DDGF--- --DD--- 
------- ------- ------- ------- --CC--- --BF--- --EE--- --EA--- --GC--- --AA--- --BF--- --AF--- --AF--- --EF--- --EF--- --EC--- --DA--- --DA--- --BA--- --DA--- --DD--- --BC--- --BD--- --BG--- --DA--- --GA--- -CCC--- ------- ------- 
------- ------- ------- ------- ------- ------- -DA---- -EA---- -CC---- -BD---- -EA---- -AA---- -AF---- -AF---- -EA---- -GC---- -GA---- -DD---- -DD---- -GA---- -DA---- -DC---- -EG---- -BA---- -BA---- -AA---- ------- ------- ------- 
------- ------- ------- ------- ------- ------- ------- ------- ------- ------- ------- ------- ------- A------ A------ CC----- GE----- GD----- DD----- DD----- DA----- CC----- FA----- GA----- EF----- ------- ------- ------- ------- 
