model
size = 19 16 19, scale = 0.05, origin = -y
material 
  colors = A:#200 B:#633 C:#00E D:#EEE E:#555 F:#050 G:#888
voxels
------AAAAAAA------ ------AAAAAAA------ ------AAAAAAA------ ------AACCCAA------ ------AACCCAA------ ------AACCCAA------ ------AACCCAA------ ------AACCCAA------ ------AACCCAA------ ------AACACAA------ ------ACCACCA------ ------AAAAAAA------ ------AAAAAAA------ ------AAAAAAA------ ------AAAAAAA------ AAAAAAAAAAAAAAAAAAA 
----EEAAAAAAAEE---- ----BBAAAAAAABB---- ----BBAAAAAAABB---- ----BBAACCCDDBB---- ----BBAA---FDBB---- ----BBAA---FDBB---- ----FBAA---BBBF---- ------------------- ------------------- ------------------- ------------------- ------------------- ------------------- ------------------- ------------------- A-----------------A 
---EEEAAAAAAAEEE--- ---BBBAAAAAAABBB--- ---BBBAAAAAAABBB--- ---BBBAACCCDDBBB--- ---BBBAA---FDBBB--- ---BBBAA---FDBBB--- ---FBBAA---FBBBF--- ------------------- ------------------- ------------------- ------------------- ------------------- ------------------- ------------------- ------------------- A-----------------A 
--EEEEAAAAAAAEEEE-- --BBBBAAAAAAABBBB-- --BBBBAAAAAAABBBB-- --BBBBAACCCDDBBBB-- --BBBBAA---FDBBBB-- --BBBBAA---FDBBBB-- --FBBBA-----FBBBF-- ------------------- ------------------- ------------------- ------------------- ------------------- ------------------- ------------------- ------------------- A-----------------A 
-EEEEEAAAAAAAEEEEE- -BBBBBAAAAAAABBBBB- -BBBBBAAAAAAABBBBB- -BBBBBAACCCDDBBBBB- -BBBBBAA---FDBBBBB- -BBBBBAA---FFBBBBB- -FBBF---------FBBF- ------------------- ------------------- ------------------- ------------------- ------------------- ------------------- ------------------- ------------------- A-----------------A 
-EEEEEAAAAAAAEEEEE- -BBBBBAAAAAAABBBBB- -BBBBBAAAAAAABBBBB- -BBBBBAACCCDDBBBBB- -BBBBBAA---FDBBBBB- -BBBBBAA---FFBBBBB- -BBB-----------FBB- ------------------- ------------------- ------------------- ------------------- ------------------- ------------------- ------------------- ------------------- A-----------------A 
AAAAAAGGGGGGGAAAAAA AAAAAADDDDDDDAAAAAA AAAAAADDDDDDDAAAAAA ADDDDDDDCCCDDAAAAAA ADDDDDDF---FDAAAAAA ADDDFFFF---FFAAAAAA ABBF-----------AAAA A-----------------A A-----------------A A-----------------A A-----------------A A-----------------A A-----------------A A-----------------A A-----------------A A-----------------A 
AAAAAAGGGGGGGAAAAAA AAAAAADDDDDDDAAAAAA AAAAAADDDDDDDAAAAAA ADDDDDDDDDDDDAAAAAA ACCCCCCCCCCCDAAAAAA ACCFFFF-----FAAAAAA AFB-------------AAA A-----------------A A-----------------A A-----------------A A-----------------A A-----------------A A-----------------A A----------------AA A---------------AAA A-----------------A 
AAAAAAGGGGGGGAAAAAA AAAAAADDDDDDDAAAAAA AAAAAADDDDDDDAAAAAA CCCCCCCDDDDDDAAAAAA C------CCCCCCCCCCCC C-----------------C C-----------------C C-----------------C C-----------------C C-----------------C A-----------------A A-----------------A A-----------------A A----------------AA A---------------AAA A-----------------A 
AAAAAAGGGGGGGAAAAAA AAAAAADDDDDDDAAAAAA AAAAAADDDDDDDAAAAAA CCCCCCCDDDDDDAAAAAA C------CCCCCCCCCCCC C--------F--------C C-----------------C C-----------------C C-----------------C C-----------------C A-----------------C A-----------------C A-----------------C A----------------AA A---------------AAA A-----------------A 
AAAAAAGGGGGGGAAAAAA AAAAAADDDDDDDAAAAAA AAAAAADDDDDDDAAAAAA CCCCCCCDDDDDDAAAAAA C------CCCCCCCCCCCC C-----------------C C-----------------C C-----------------C C-----------------C C-----------------C A-----------------A A-----------------A A-----------------A A----------------AA A---------------AAA A-----------------A 
AAAAAAGGGGGGGAAAAAA AAAAAADDDDDDDAAAAAA AAAAAADDDDDDDAAAAAA AAAAAACDDDDDDAAAAAA AAAAAAFCCCCCCAAAAAA AAAAAAF-----FAAAAAA AAA-------------AAA A-----------------A A-----------------A A-----------------A A-----------------A A-----------------A A-----------------A A----------------AA A---------------AAA A-----------------A 
AAAAAAGGGGGGGAAAAAA AAAAAADDDDDDDAAAAAA AAAAAADDDDDDDAAAAAA AAAAAADDDDDDDAAAAAA AAAAAADDCCCDDAAAAAA AAAAAAFF---FFAAAAAA AAAA-----------AAAA A-----------------A A-----------------A A-----------------A A-----------------A A-----------------A A-----------------A A-----------------A A-----------------A A-----------------A 
-EEEEEAAAAAAAEEEEE- -BBBBBAAAAAAABBBBB- -BBBBBAAAAAAABBBBB- -BBBBBAAAAAAABBBBB- -BBBBBAACCCAABBBBB- -BBBBBAA---AABBBBB- -FBF-----------FBB- ------------------- ------------------- ------------------- ------------------- ------------------- ------------------- ------------------- ------------------- A-----------------A 
-EEEEEAAAAAAAEEEEE- -BBBBBAAAAAAABBBBB- -BBBBBAAAAAAABBBBB- -BBBBBAAAAAAABBBBB- -BBBBBAACCCAABBBBB- -BBBBBAA---AABBBBB- -BBBF---------FBBF- ------------------- ------------------- ------------------- ------------------- ------------------- ------------------- ------------------- ------------------- A-----------------A 
--EEEEAAAAAAAEEEE-- --BBBBAAAAAAABBBB-- --BBBBAAAAAAABBBB-- --BBBBAAAAAAABBBB-- --BBBBAACCCAABBBB-- --BBBBAA---AABBBB-- --FBBFA-----AFBBF-- ------------------- ------------------- ------------------- ------------------- ------------------- ------------------- ------------------- ------------------- A-----------------A 
---EEEAAAAAAAEEE--- ---BBBAAAAAAABBB--- ---BBBAAAAAAABBB--- ---BBBAAAAAAABBB--- ---BBBAACCCAABBB--- ---BBBAACCCAABBB--- ---FBBA-----ABBF--- ------------------- ------------------- ------------------- ------------------- ------------------- ------------------- ------------------- ------------------- A-----------------A 
----EEAAAAAAAEE---- ----BBAAAAAAABB---- ----BBAAAAAAABB---- ----BBAAAAAAABB---- ----BBAACCCAABB---- ----BBAACCCAABB---- ----FBA-----ABF---- ------------------- ------------------- ------------------- ------------------- ------------------- ------------------- ------------------- ------------------- A-----------------A 
------AAAAAAA------ ------AAAAAAA------ ------AAAAAAA------ ------AAAAAAA------ ------AACCCAA------ ------AACCCAA------ ------AACCCAA------ ------AACCCAA------ ------AACCCAA------ ------ACCCCCA------ ------AAAAAAA------ ------AAAAAAA------ ------AAAAAAA------ ------AAAAAAA------ ------AAAAAAA------ AAAAAAAAAAAAAAAAAAA 
