model
size = 23 8 18, scale = 0.05, origin = -y
material 
  colors = A:#000 B:#F88C18 C:#F15E05 D:#F14805 E:#F12C05 F:#F8B524 G:#F10505 H:#FAC75A
voxels
-AAAAAAAAA---AAAAAAAAA- AAHFBBCDEAA-AAHFBBCDEAA AHFFBCCDEGA-AHFFBCCDEGA AHFBBCDDEGA-AHFBBCDDEGA AHFBCCDEEGA-AHFBCCDEEGA AHFBCDDEGGA-AHFBCDDEGGA AAFBCDEEGAAAAAFBCDEEGAA -AAAAAAAAA---AAAAAAAAA- 
----------------------- ----------------------- ----------------------- ----------------------- ----------------------- ----------------------- A---------------------A ----------------------- 
----------------------- ----------------------- ----------------------- ----------------------- ----------------------- ----------------------- A---------------------A ----------------------- 
----------------------- ----------------------- ----------------------- ----------------------- ----------------------- ----------------------- A---------------------A ----------------------- 
----------------------- ----------------------- ----------------------- ----------------------- ----------------------- ----------------------- A---------------------A ----------------------- 
----------------------- ----------------------- ----------------------- ----------------------- ----------------------- ----------------------- A---------------------A ----------------------- 
----------------------- ----------------------- ----------------------- ----------------------- ----------------------- ----------------------- A---------------------A ----------------------- 
----------------------- ----------------------- ----------------------- ----------------------- ----------------------- ----------------------- A---------------------A ----------------------- 
----------------------- ----------------------- ----------------------- ----------------------- ----------------------- ----------------------- A---------------------A ----------------------- 
----------------------- ----------------------- ----------------------- ----------------------- ----------------------- ----------------------- A---------------------A ----------------------- 
----------------------- ----------------------- ----------------------- ----------------------- ----------------------- ----------------------- A---------------------A ----------------------- 
----------------------- ----------------------- ----------------------- ----------------------- ----------------------- ----------------------- A---------------------A ----------------------- 
----------------------- ----------------------- ----------------------- ----------------------- ----------------------- ----------------------- A---------------------A ----------------------- 
----------------------- ----------------------- ----------------------- ----------------------- ----------------------- ----------------------- A---------------------A ----------------------- 
----------------------- ----------------------- ----------------------- ----------------------- ----------------------- A---------------------A A---------------------A ----------------------- 
----------------------- ----------------------- ----------------------- ----------------------- ----------------------- A---------------------A ----------------------- ----------------------- 
----------------------- ----------------------- ----------------------- ----------------------- ----------------------- A---------------------A ----------------------- ----------------------- 
----------------------- ----------------------- ----------------------- ----------------------- A---------------------A A---------------------A ----------------------- ----------------------- 
