model
size = 23 8 18, scale = 0.05, origin = -y
material 
  colors = A:#000 B:#A93AF6 C:#7A1FF5 D:#510BDF E:#2609BB F:#BE4FF7 G:#0B0894 H:#CB73F9
voxels
-AAAAAAAAA---AAAAAAAAA- AAHFBBCDEAA-AAHFBBCDEAA AHFFBCCDEGA-AHFFBCCDEGA AHFBBCDDEGA-AHFBBCDDEGA AHFBCCDEEGA-AHFBCCDEEGA AHFBCDDEGGA-AHFBCDDEGGA AAFBCDEEGAAAAAFBCDEEGAA -AAAAAAAAA---AAAAAAAAA- 
----------------------- ----------------------- ----------------------- ----------------------- ----------------------- ----------------------- A---------------------A ----------------------- 
----------------------- ----------------------- ----------------------- ----------------------- ----------------------- ----------------------- A---------------------A ----------------------- 
----------------------- ----------------------- ----------------------- ----------------------- ----------------------- ----------------------- A---------------------A ----------------------- 
----------------------- ----------------------- ----------------------- ----------------------- ----------------------- ----------------------- A---------------------A ----------------------- 
----------------------- ----------------------- ----------------------- ----------------------- ----------------------- ----------------------- A---------------------A ----------------------- 
----------------------- ----------------------- ----------------------- ----------------------- ----------------------- ----------------------- A---------------------A ----------------------- 
----------------------- ----------------------- ----------------------- ----------------------- ----------------------- ----------------------- A---------------------A ----------------------- 
----------------------- ----------------------- ----------------------- ----------------------- ----------------------- ----------------------- A---------------------A ----------------------- 
----------------------- ----------------------- ----------------------- ----------------------- ----------------------- ----------------------- A---------------------A ----------------------- 
----------------------- ----------------------- ----------------------- ----------------------- ----------------------- ----------------------- A---------------------A ----------------------- 
----------------------- ----------------------- ----------------------- ----------------------- ----------------------- ----------------------- A---------------------A ----------------------- 
----------------------- ----------------------- ----------------------- ----------------------- ----------------------- ----------------------- A---------------------A ----------------------- 
----------------------- ----------------------- ----------------------- ----------------------- ----------------------- ----------------------- A---------------------A ----------------------- 
----------------------- ----------------------- ----------------------- ----------------------- ----------------------- A---------------------A A---------------------A ----------------------- 
----------------------- ----------------------- ----------------------- ----------------------- ----------------------- A---------------------A ----------------------- ----------------------- 
----------------------- ----------------------- ----------------------- ----------------------- ----------------------- A---------------------A ----------------------- ----------------------- 
----------------------- ----------------------- ----------------------- ----------------------- A---------------------A A---------------------A ----------------------- ----------------------- 
