model
size = 29 14 27, scale = 0.05, origin = -y
material 
  colors = A:#FF6905 B:#0A0000 C:#FEFEFE D:#3825C5 E:#A08CEC F:#6F51DF G:#5F3EDC H:#D7AEF4 I:#DABCF8 J:#CB88EA K:#F6D644 L:#BB6CE0 M:#A553CB N:#7F63E5 O:#4C26D8 P:#22259E Q:#BB9FF3 R:#FAEB88 S:#2B24B2 T:#B465D9 U:#FDF4B9 V:#212489 W:#030303 X:#9144B4 Y:#FE3C00 Z:#1352F1 Aa:#1224B0
voxels
- - - - - - B B B B B B B - - - B B B B B B B - - - - - -   - - - - - - N N F G O D B B - B B D O G F N N - - - - - -   - - - - - E N N F G O D S B - B S D O G F N N E - - - - -   - - - - Q E E N F G O D S B B B S D O G F N E E Q - - - -   - - - - Q Q E N F G O D S P B P S D O G F N E Q Q - - - -   - - - - I Q E N F G O D S P V P S D O G F N E Q I - - - -   - - - - I Q E N F G O D S P V P S D O G F N E Q I - - - -   - - - - I Q E N F G O D S P V P S D O G F N E Q I - - - -   - - - - I Q E N F G O D S P V P S D O G F N E Q I - - - -   - - - - I Q E N F G O D S P V P S D O G F N E Q I - - - -   - - - - I Q E N F G O O D S P S D O O G F N E Q I - - - -   - - - - - Q E N F G O O D S P S D O O G F N E Q - - - - -   - - - - - - Q E N F G O D S P S D O G F N E Q - - - - - -   - - - - - - B B B B B B B B B B B B B B B B B - - - - - -   
- - - - - B B B B B B B B - - - B B B B B B B B - - - - -   - - - B B B K K A A A A B B - B B A A A A K K B B B - - -   - - - I Q R K A A A A A A B - B A A A A A A K R Q I - - -   - - - I R R K A A A A A A A B A A A A A A A K R R I - - -   - - - I R R K A A A A A A A A A A A A A A A K R R I - - -   - - - H U R K A A A A A A A A A A A A A A A K R U H - - -   - - - H U R K A A A A A A A A A A A A A A A K R U H - - -   - - - H U R K A A A A A A A A A A A A A A A K R U H - - -   - - - H U R K A A A A A A A A A A A A A A A K R U H - - -   - - - H U R K A A A A A A A A A A A A A A A K R U H - - -   - - - H U R K A A A A A A A A A A A A A A A K R U H - - -   - - - - I R K K A A A A A A A A A A A A A K K R I - - - -   - - - - I Q R K K A A A A A A A A A A A K K R Q I - - - -   - - - - B B B B B B B B B B B B B B B B B B B B B - - - -   
- - - - - B B B B B B B B - - - B B B B B B B B - - - - -   - - B B B B A A A A A A B B - B B A A A A A A B B B B - -   - - B A A A A A A A A A A B - B A A A A A A A A A A B - -   - - H A A A A A A A A A A A B A A A A A A A A A A A H - -   - - H A A A A A A A A A A A A A A A A A A A A A A A H - -   - - H A A A A A A A A A A A A A A A A A A A A A A A H - -   - - J A A A A A A A A A A A A A A A A A A A A A A A J - -   - - J A A A A A A A A A A A A A A A A A A A A A A A J - -   - - J A A A A A A A A A A A A A A A A A A A A A A A J - -   - - J A A A A A A A A A A A A A A A A A A A A A A A J - -   - - J A A A A A A A A A A A A A A A A A A A A A A A J - -   - - J H A A A A A A A A A A A A A A A A A A A A A H J - -   - - B H A A A A A A A A A A A A A A A A A A A A A B B - -   - - - B B B B B B B B B B B B B B B B B B B B B B B - - -   
- - - - - B B B B B B B B - - - B B B B B B B B - - - - -   - - B B B B A A A A A A B B - B B A A A A A A B B B B - -   - B B A A A A A A A A A A B - B A A A A A A A A A A B B -   - J A A A A A A A A A A A A B A D A A A A A A A A A A J -   - J A A A A A A A A A A D A A A D A A A A A A A A A A J -   - L A A A A A A A A A A D P A P D A A A A A A A A A A L -   - L A A A A A A A A A A D P V P D A A A A A A A A A A L -   - L A A A A A A A A A A D P V P D A A A A A A A A A A L -   - L A A A A A A A A A A D P V P D A A A A A A A A A A L -   - L A A A A A A A A A A D P V P D A A A A A A A A A A L -   - L A A A A A A A A A A D D P D D A A A A A A A A A A L -   - B A A A A A A A A A A G D P D G A A A A A A A A A A B -   - B B B A A A A A A A A A A A A A A A A A A A A A Y B B -   - - - B B B B B B B B B B B B B B B B B B B B B B B - - -   
- - - - - B B B B B B B B - - - B B B B B B B B - - - - -   - - B B B B A A A A A A Y B - B B A A A A A A B B B B - -   B B B A A A A A A A F G D B - B D G F A A A A A A A B B B   B A A A A A A A A A F G D B B B D G F A A A A A A A A A B   M A A A A A A A A A F G - B B B - G F A A A A A A A A A M   M A A A A A A A A A F G - - B - - G F A A A A A A A A A M   M A A A A A A A A A F G - - - - - G F A A A A A A A A A M   M A A A A A A A A A F G - - - - - G F A A A A A A A A A M   M A A A A A A A A A F G - - - - - G F A A A A A A A A A M   M A A A A A A A A A F G - - - - - G F A A A A A A A A A M   B A A A A A A A A A F G - - - - - G F A A A A A A A A A B   B B A A A A A A A A E F - - - - - F E A A A A A A A A Y B   - B B B A A A A A A A A B B B B B A A A A A A A A B B B -   - - - B B B B B B B B B B B B B B B B B B B B B B B - - -   
- - - - - B B B B B B B B - - - B B B B B B B B - - - - -   - - B B B B A A A A B B B B - B B B B A A A A B B B B - -   B B B A A A A H I E - - - B - B - - - E I H A A A A B B B   B A A A A A A H I E - - - B B B - - - E I H A A A A A A B   B A A A A A A H I E - - - B B B - - - E I H A A A A A A B   B A A A A A A H I E - - - - B - - - - E I H A A A A A A B   B A A A A A A H I E - - - - - - - - - E I H A A A A A A B   B A A A A A A H I E - - - - - - - - - E I H A A A A A A B   B A A A A A A H I E - - - - - - - - - E I H A A A A A A B   B A A A A A A H I E - - - - - - - - - E I H A A A A A A B   B A A A A A A H I E - - - - - - - - - E I H A A A A A A B   B B A A A A A J H E - - - - - - - - - E H J A A A A A B B   - B B B A A A A A A B B B B B B B B B A A A A A A B B B -   - - - B B B B B B B B B B B B B B B B B B B B B B B - - -   
- - - - - B B B B B B B B - - - B B B B B B B B - - - - -   - - B B B B A B B B B B B B - B B B B B B B A B B B B - -   B B B Z T L J - - - - - - B - B - - - - - - J L T Z B B B   B A A M T L J - - - - - - B B B - - - - - - J L T M A A B   B A A M T L J - - - - - - B B B - - - - - - J L T M A A B   B A A M T L J - - - - - - - B - - - - - - - J L T M A A B   B A A M T L J - - - - - - - - - - - - - - - J L T M A A B   B A A M T L J - - - - - - - - - - - - - - - J L T M A A B   B A A M T L J - - - - - - - - - - - - - - - J L T M A A B   B A A X M T J - - - - - - - - - - - - - - - J T M X A A B   B A A X M T L - - - - - - - - - - - - - - - L T M X A A B   B B A AaM T L - - - - - - - - - - - - - - - L T M AaA B B   - B B B A A A B B B B - - - - - - - B B B B A A A B B B -   - - - B B B B B B B B - - - - - - - B B B B B B B B - - -   
- - - - - B B B B B B B B - - - B B B B B B B B - - - - -   - - B B B B B B B - - - B B - B B - - - B B B B B B B - -   B B B B - - - - - - - - - B - B - - - - - - - - - B B B B   B W W - - - - - - - - - - B B B - - - - - - - - - - W B B   - C B - - - - - - - - - - - B - - - - - - - - - - - B C -   B W B - - - - - - - - - - - - - - - - - - - - - - - B B B   - C B - - - - - - - - - - - - - - - - - - - - - - - B C -   B W B - - - - - - - - - - - - - - - - - - - - - - - B B B   - C B - - - - - - - - - - - - - - - - - - - - - - - B C -   B W B - - - - - - - - - - - - - - - - - - - - - - - B B B   B W B - - - - - - - - - - - - - - - - - - - - - - - B B B   B B B B - - - - - - - - - - - - - - - - - - - - - B W B B   - B B B B B B B - - - - - - - - - - - - - B B B B B B B -   - - - B B B B B - - - - - - - - - - - - - B B B B B - - -   
- - - - - - - - - - - - - - - - - - - - - - - - - - - - -   - - - - - - - - - - - - - - - - - - - - - - - - - - - - -   - - - - - - - - - - - - - - - - - - - - - - - - - - - - -   B - - - - - - - - - - - - - - - - - - - - - - - - - - - B   B - - - - - - - - - - - - - - - - - - - - - - - - - - - B   B - - - - - - - - - - - - - - - - - - - - - - - - - - - B   B - - - - - - - - - - - - - - - - - - - - - - - - - - - B   B - - - - - - - - - - - - - - - - - - - - - - - - - - - B   B - - - - - - - - - - - - - - - - - - - - - - - - - - - B   B - - - - - - - - - - - - - - - - - - - - - - - - - - - B   - - - - - - - - - - - - - - - - - - - - - - - - - - - - -   - - - - - - - - - - - - - - - - - - - - - - - - - - - - -   - - - - - - - - - - - - - - - - - - - - - - - - - - - - -   - - - - - - - - - - - - - - - - - - - - - - - - - - - - -   
- - - - - - - - - - - - - - - - - - - - - - - - - - - - -   - - - - - - - - - - - - - - - - - - - - - - - - - - - - -   - - - - - - - - - - - - - - - - - - - - - - - - - - - - -   B - - - - - - - - - - - - - - - - - - - - - - - - - - - B   C - - - - - - - - - - - - - - - - - - - - - - - - - - - C   C - - - - - - - - - - - - - - - - - - - - - - - - - - - C   C - - - - - - - - - - - - - - - - - - - - - - - - - - - C   B - - - - - - - - - - - - - - - - - - - - - - - - - - - C   C - - - - - - - - - - - - - - - - - - - - - - - - - - - C   B - - - - - - - - - - - - - - - - - - - - - - - - - - - B   - - - - - - - - - - - - - - - - - - - - - - - - - - - - -   - - - - - - - - - - - - - - - - - - - - - - - - - - - - -   - - - - - - - - - - - - - - - - - - - - - - - - - - - - -   - - - - - - - - - - - - - - - - - - - - - - - - - - - - -   
- - - - - - - - - - - - - - - - - - - - - - - - - - - - -   - - - - - - - - - - - - - - - - - - - - - - - - - - - - -   - - - - - - - - - - - - - - - - - - - - - - - - - - - - -   B - - - - - - - - - - - - - - - - - - - - - - - - - - - B   C - - - - - - - - - - - - - - - - - - - - - - - - - - - C   B - - - - - - - - - - - - - - - - - - - - - - - - - - - B   C - - - - - - - - - - - - - - - - - - - - - - - - - - - B   B - - - - - - - - - - - - - - - - - - - - - - - - - - - B   C - - - - - - - - - - - - - - - - - - - - - - - - - - - C   B - - - - - - - - - - - - - - - - - - - - - - - - - - - B   - - - - - - - - - - - - - - - - - - - - - - - - - - - - -   - - - - - - - - - - - - - - - - - - - - - - - - - - - - -   - - - - - - - - - - - - - - - - - - - - - - - - - - - - -   - - - - - - - - - - - - - - - - - - - - - - - - - - - - -   
- - - - - - - - - - - - - - - - - - - - - - - - - - - - -   - - - - - - - - - - - - - - - - - - - - - - - - - - - - -   - - - - - - - - - - - - - - - - - - - - - - - - - - - - -   B - - - - - - - - - - - - - - - - - - - - - - - - - - - B   C - - - - - - - - - - - - - - - - - - - - - - - - - - - C   B - - - - - - - - - - - - - - - - - - - - - - - - - - - B   C - - - - - - - - - - - - - - - - - - - - - - - - - - - B   C - - - - - - - - - - - - - - - - - - - - - - - - - - - B   C - - - - - - - - - - - - - - - - - - - - - - - - - - - C   B - - - - - - - - - - - - - - - - - - - - - - - - - - - B   - - - - - - - - - - - - - - - - - - - - - - - - - - - - -   - - - - - - - - - - - - - - - - - - - - - - - - - - - - -   - - - - - - - - - - - - - - - - - - - - - - - - - - - - -   - - - - - - - - - - - - - - - - - - - - - - - - - - - - -   
- - - - - - - - - - - - - - - - - - - - - - - - - - - - -   - - - - - - - - - - - - - - - - - - - - - - - - - - - - -   - - - - - - - - - - - - - - - - - - - - - - - - - - - - -   B - - - - - - - - - - - - - - - - - - - - - - - - - - - B   B - - - - - - - - - - - - - - - - - - - - - - - - - - - B   B - - - - - - - - - - - - - - - - - - - - - - - - - - - B   B - - - - - - - - - - - - - - - - - - - - - - - - - - - B   B - - - - - - - - - - - - - - - - - - - - - - - - - - - B   B - - - - - - - - - - - - - - - - - - - - - - - - - - - B   B - - - - - - - - - - - - - - - - - - - - - - - - - - - B   - - - - - - - - - - - - - - - - - - - - - - - - - - - - -   - - - - - - - - - - - - - - - - - - - - - - - - - - - - -   - - - - - - - - - - - - - - - - - - - - - - - - - - - - -   - - - - - - - - - - - - - - - - - - - - - - - - - - - - -   
- - - - - - - - - - - - - - - - - - - - - - - - - - - - -   - - - - - - - - - - - - - - - - - - - - - - - - - - - - -   - - - - - - - - - - - - - - - - - - - - - - - - - - - - -   B - - - - - - - - - - - - - - - - - - - - - - - - - - - B   C - - - - - - - - - - - - - - - - - - - - - - - - - - - C   B - - - - - - - - - - - - - - - - - - - - - - - - - - - C   B - - - - - - - - - - - - - - - - - - - - - - - - - - - C   B - - - - - - - - - - - - - - - - - - - - - - - - - - - C   B - - - - - - - - - - - - - - - - - - - - - - - - - - - C   B - - - - - - - - - - - - - - - - - - - - - - - - - - - B   - - - - - - - - - - - - - - - - - - - - - - - - - - - - -   - - - - - - - - - - - - - - - - - - - - - - - - - - - - -   - - - - - - - - - - - - - - - - - - - - - - - - - - - - -   - - - - - - - - - - - - - - - - - - - - - - - - - - - - -   
- - - - - - - - - - - - - - - - - - - - - - - - - - - - -   - - - - - - - - - - - - - - - - - - - - - - - - - - - - -   - - - - - - - - - - - - - - - - - - - - - - - - - - - - -   B - - - - - - - - - - - - - - - - - - - - - - - - - - - B   C - - - - - - - - - - - - - - - - - - - - - - - - - - - B   B - - - - - - - - - - - - - - - - - - - - - - - - - - - B   B - - - - - - - - - - - - - - - - - - - - - - - - - - - C   B - - - - - - - - - - - - - - - - - - - - - - - - - - - B   B - - - - - - - - - - - - - - - - - - - - - - - - - - - C   B - - - - - - - - - - - - - - - - - - - - - - - - - - - B   - - - - - - - - - - - - - - - - - - - - - - - - - - - - -   - - - - - - - - - - - - - - - - - - - - - - - - - - - - -   - - - - - - - - - - - - - - - - - - - - - - - - - - - - -   - - - - - - - - - - - - - - - - - - - - - - - - - - - - -   
- - - - - - - - - - - - - - - - - - - - - - - - - - - - -   - - - - - - - - - - - - - - - - - - - - - - - - - - - - -   - - - - - - - - - - - - - - - - - - - - - - - - - - - - -   B - - - - - - - - - - - - - - - - - - - - - - - - - - - B   C - - - - - - - - - - - - - - - - - - - - - - - - - - - C   C - - - - - - - - - - - - - - - - - - - - - - - - - - - C   C - - - - - - - - - - - - - - - - - - - - - - - - - - - B   C - - - - - - - - - - - - - - - - - - - - - - - - - - - C   C - - - - - - - - - - - - - - - - - - - - - - - - - - - C   B - - - - - - - - - - - - - - - - - - - - - - - - - - - B   - - - - - - - - - - - - - - - - - - - - - - - - - - - - -   - - - - - - - - - - - - - - - - - - - - - - - - - - - - -   - - - - - - - - - - - - - - - - - - - - - - - - - - - - -   - - - - - - - - - - - - - - - - - - - - - - - - - - - - -   
- - - - - - - - - - - - - - - - - - - - - - - - - - - - -   - - - - - - - - - - - - - - - - - - - - - - - - - - - - -   - - - - - - - - - - - - - - - - - - - - - - - - - - - - -   B - - - - - - - - - - - - - - - - - - - - - - - - - - - B   B - - - - - - - - - - - - - - - - - - - - - - - - - - - B   B - - - - - - - - - - - - - - - - - - - - - - - - - - - B   B - - - - - - - - - - - - - - - - - - - - - - - - - - - B   B - - - - - - - - - - - - - - - - - - - - - - - - - - - B   B - - - - - - - - - - - - - - - - - - - - - - - - - - - B   B - - - - - - - - - - - - - - - - - - - - - - - - - - - B   - - - - - - - - - - - - - - - - - - - - - - - - - - - - -   - - - - - - - - - - - - - - - - - - - - - - - - - - - - -   - - - - - - - - - - - - - - - - - - - - - - - - - - - - -   - - - - - - - - - - - - - - - - - - - - - - - - - - - - -   
- - - - - - - - - - - - - - - - - - - - - - - - - - - - -   - - - - - - - - - - - - - - - - - - - - - - - - - - - - -   - - - - - - - - - - - - - - - - - - - - - - - - - - - - -   B - - - - - - - - - - - - - - - - - - - - - - - - - - - B   C - - - - - - - - - - - - - - - - - - - - - - - - - - - B   B - - - - - - - - - - - - - - - - - - - - - - - - - - - B   C - - - - - - - - - - - - - - - - - - - - - - - - - - - C   B - - - - - - - - - - - - - - - - - - - - - - - - - - - C   C - - - - - - - - - - - - - - - - - - - - - - - - - - - C   B - - - - - - - - - - - - - - - - - - - - - - - - - - - B   - - - - - - - - - - - - - - - - - - - - - - - - - - - - -   - - - - - - - - - - - - - - - - - - - - - - - - - - - - -   - - - - - - - - - - - - - - - - - - - - - - - - - - - - -   - - - - - - - - - - - - - - - - - - - - - - - - - - - - -   
- - - - - - - - - - - - - - - - - - - - - - - - - - - - -   - - - - - - - - - - - - - - - - - - - - - - - - - - - - -   - - - - - - - - - - - - - - - - - - - - - - - - - - - - -   B B - - - - - - - - - - - - - - - - - - - - - - - - - B B   C C - - - - - - - - - - - - - - - - - - - - - - - - - C C   B C - - - - - - - - - - - - - - - - - - - - - - - - - C C   C C - - - - - - - - - - - - - - - - - - - - - - - - - C C   B C - - - - - - - - - - - - - - - - - - - - - - - - - B B   C C - - - - - - - - - - - - - - - - - - - - - - - - - B B   B B - - - - - - - - - - - - - - - - - - - - - - - - - B B   - - - - - - - - - - - - - - - - - - - - - - - - - - - - -   - - - - - - - - - - - - - - - - - - - - - - - - - - - - -   - - - - - - - - - - - - - - - - - - - - - - - - - - - - -   - - - - - - - - - - - - - - - - - - - - - - - - - - - - -   
- - - - - - - - - - - - - - - - - - - - - - - - - - - - -   - - - - - - - - - - - - - - - - - - - - - - - - - - - - -   - - - - - - - - - - - - - - - - - - - - - - - - - - - - -   - B B - - - - - - - - - - - - - - - - - - - - - - - B B -   - C B - - - - - - - - - - - - - - - - - - - - - - - B B -   - C B - - - - - - - - - - - - - - - - - - - - - - - B B -   - C B - - - - - - - - - - - - - - - - - - - - - - - B C -   - C B - - - - - - - - - - - - - - - - - - - - - - - C C -   - C B - - - - - - - - - - - - - - - - - - - - - - - C C -   - B B - - - - - - - - - - - - - - - - - - - - - - - B B -   - - - - - - - - - - - - - - - - - - - - - - - - - - - - -   - - - - - - - - - - - - - - - - - - - - - - - - - - - - -   - - - - - - - - - - - - - - - - - - - - - - - - - - - - -   - - - - - - - - - - - - - - - - - - - - - - - - - - - - -   
- - - - - - - - - - - - - - - - - - - - - - - - - - - - -   - - - - - - - - - - - - - - - - - - - - - - - - - - - - -   - - - - - - - - - - - - - - - - - - - - - - - - - - - - -   - - B B - - - - - - - - - - - - - - - - - - - - - B B - -   - - B C - - - - - - - - - - - - - - - - - - - - - B B - -   - - B C - - - - - - - - - - - - - - - - - - - - - B B - -   - - B B - - - - - - - - - - - - - - - - - - - - - B B - -   - - B C - - - - - - - - - - - - - - - - - - - - - B B - -   - - B C - - - - - - - - - - - - - - - - - - - - - B B - -   - - B B - - - - - - - - - - - - - - - - - - - - - B B - -   - - - - - - - - - - - - - - - - - - - - - - - - - - - - -   - - - - - - - - - - - - - - - - - - - - - - - - - - - - -   - - - - - - - - - - - - - - - - - - - - - - - - - - - - -   - - - - - - - - - - - - - - - - - - - - - - - - - - - - -   
- - - - - - - - - - - - - - - - - - - - - - - - - - - - -   - - - - - - - - - - - - - - - - - - - - - - - - - - - - -   - - - - - - - - - - - - - - - - - - - - - - - - - - - - -   - - - B B - - - - - - - - - - - - - - - - - - - B B - - -   - - - C B - - - - - - - - - - - - - - - - - - - C C - - -   - - - C C - - - - - - - - - - - - - - - - - - - C C - - -   - - - B C - - - - - - - - - - - - - - - - - - - C C - - -   - - - C C - - - - - - - - - - - - - - - - - - - C C - - -   - - - C B - - - - - - - - - - - - - - - - - - - C C - - -   - - - B B - - - - - - - - - - - - - - - - - - - B B - - -   - - - - - - - - - - - - - - - - - - - - - - - - - - - - -   - - - - - - - - - - - - - - - - - - - - - - - - - - - - -   - - - - - - - - - - - - - - - - - - - - - - - - - - - - -   - - - - - - - - - - - - - - - - - - - - - - - - - - - - -   
- - - - - - - - - - - - - - - - - - - - - - - - - - - - -   - - - - - - - - - - - - - - - - - - - - - - - - - - - - -   - - - - - - - - - - - - - - - - - - - - - - - - - - - - -   - - - - B B - - - - - - - - - - - - - - - - - B B - - - -   - - - - B C - - - - - - - - - - - - - - - - - B B - - - -   - - - - C C - - - - - - - - - - - - - - - - - B B - - - -   - - - - C B - - - - - - - - - - - - - - - - - C C - - - -   - - - - C C - - - - - - - - - - - - - - - - - C B - - - -   - - - - B C - - - - - - - - - - - - - - - - - C C - - - -   - - - - B B - - - - - - - - - - - - - - - - - B B - - - -   - - - - - - - - - - - - - - - - - - - - - - - - - - - - -   - - - - - - - - - - - - - - - - - - - - - - - - - - - - -   - - - - - - - - - - - - - - - - - - - - - - - - - - - - -   - - - - - - - - - - - - - - - - - - - - - - - - - - - - -   
- - - - - - - - - - - - - - - - - - - - - - - - - - - - -   - - - - - - - - - - - - - - - - - - - - - - - - - - - - -   - - - - - - - - - - - - - - - - - - - - - - - - - - - - -   - - - - - B B - - - - - - - - - - - - - - - B B - - - - -   - - - - - C B - - - - - - - - - - - - - - - B B - - - - -   - - - - - C B - - - - - - - - - - - - - - - B B - - - - -   - - - - - B B - - - - - - - - - - - - - - - B C - - - - -   - - - - - C B - - - - - - - - - - - - - - - B C - - - - -   - - - - - C B - - - - - - - - - - - - - - - B C - - - - -   - - - - - B B - - - - - - - - - - - - - - - B B - - - - -   - - - - - - - - - - - - - - - - - - - - - - - - - - - - -   - - - - - - - - - - - - - - - - - - - - - - - - - - - - -   - - - - - - - - - - - - - - - - - - - - - - - - - - - - -   - - - - - - - - - - - - - - - - - - - - - - - - - - - - -   
- - - - - - - - - - - - - - - - - - - - - - - - - - - - -   - - - - - - - - - - - - - - - - - - - - - - - - - - - - -   - - - - - - - - - - - - - - - - - - - - - - - - - - - - -   - - - - - - B B - - - - - - - - - - - - - B B - - - - - -   - - - - - - B C - - - - - - - - - - - - - B B - - - - - -   - - - - - - B C - - - - - - - - - - - - - B B - - - - - -   - - - - - - B C - - - - - - - - - - - - - B B - - - - - -   - - - - - - B C - - - - - - - - - - - - - B B - - - - - -   - - - - - - B C - - - - - - - - - - - - - C B - - - - - -   - - - - - - B B - - - - - - - - - - - - - B B - - - - - -   - - - - - - - - - - - - - - - - - - - - - - - - - - - - -   - - - - - - - - - - - - - - - - - - - - - - - - - - - - -   - - - - - - - - - - - - - - - - - - - - - - - - - - - - -   - - - - - - - - - - - - - - - - - - - - - - - - - - - - -   
- - - - - - - - - - - - - - - - - - - - - - - - - - - - -   - - - - - - - - - - - - - - - - - - - - - - - - - - - - -   - - - - - - - - - - - - - - - - - - - - - - - - - - - - -   - - - - - - - B B B - - - - - - - - - B B B - - - - - - -   - - - - - - - C C C - - - - - - - - - B C B - - - - - - -   - - - - - - - C B C - - - - - - - - - B C B - - - - - - -   - - - - - - - C B C - - - - - - - - - B C B - - - - - - -   - - - - - - - C B C - - - - - - - - - B C B - - - - - - -   - - - - - - - C C C - - - - - - - - - C C C - - - - - - -   - - - - - - - B B B - - - - - - - - - B B B - - - - - - -   - - - - - - - - - - - - - - - - - - - - - - - - - - - - -   - - - - - - - - - - - - - - - - - - - - - - - - - - - - -   - - - - - - - - - - - - - - - - - - - - - - - - - - - - -   - - - - - - - - - - - - - - - - - - - - - - - - - - - - -   
- - - - - - - - - - - - - - - - - - - - - - - - - - - - -   - - - - - - - - - - - - - - - - - - - - - - - - - - - - -   - - - - - - - - - - - - - - - - - - - - - - - - - - - - -   - - - - - - - - - B B B B B B B B B B B - - - - - - - - -   - - - - - - - - - C B B C B B C C C B B - - - - - - - - -   - - - - - - - - - C B C B C B C B C B B - - - - - - - - -   - - - - - - - - - C B C B C B C B C B B - - - - - - - - -   - - - - - - - - - C B C B C B C B C B B - - - - - - - - -   - - - - - - - - - C B C B C B C C C B C - - - - - - - - -   - - - - - - - - - B B B B B B B B B B B - - - - - - - - -   - - - - - - - - - - - - - - - - - - - - - - - - - - - - -   - - - - - - - - - - - - - - - - - - - - - - - - - - - - -   - - - - - - - - - - - - - - - - - - - - - - - - - - - - -   - - - - - - - - - - - - - - - - - - - - - - - - - - - - -   
