model
size = 29 14 27, scale = 0.05, origin = -y
material 
  colors = A:#FF6905 B:#0A0000 C:#212489 D:#3825C5 E:#A08CEC F:#6F51DF G:#5F3EDC H:#D7AEF4 I:#DABCF8 J:#CB88EA K:#F6D644 L:#BB6CE0 M:#A553CB N:#7F63E5 O:#4C26D8 P:#22259E Q:#BB9FF3 R:#FAEB88 S:#2B24B2 T:#B465D9 U:#FDF4B9 V:#030303 W:#9144B4 X:#FE3C00 Y:#1352F1 Z:#1224B0
voxels
------BBBBBBB---BBBBBBB------ ------NNFGODBB-BBDOGFNN------ -----ENNFGODSB-BSDOGFNNE----- ----QEENFGODSBBBSDOGFNEEQ---- ----QQENFGODSPBPSDOGFNEQQ---- ----IQENFGODSPCPSDOGFNEQI---- ----IQENFGODSPCPSDOGFNEQI---- ----IQENFGODSPCPSDOGFNEQI---- ----IQENFGODSPCPSDOGFNEQI---- ----IQENFGODSPCPSDOGFNEQI---- ----IQENFGOODSPSDOOGFNEQI---- -----QENFGOODSPSDOOGFNEQ----- ------QENFGODSPSDOGFNEQ------ ------BBBBBBBBBBBBBBBBB------ 
-----BCCCCCCC---CCCCCCCB----- ---BBBKKAAAABC-CBAAAAKKBBB--- ---IQRKAAAAAAC-CAAAAAAKRQI--- ---IRRKAAAAAAACAAAAAAAKRRI--- ---IRRKAAAAAAAAAAAAAAAKRRI--- ---HURKAAAAAAAAAAAAAAAKRUH--- ---HURKAAAAAAAAAAAAAAAKRUH--- ---HURKAAAAAAAAAAAAAAAKRUH--- ---HURKAAAAAAAAAAAAAAAKRUH--- ---HURKAAAAAAAAAAAAAAAKRUH--- ---HURKAAAAAAAAAAAAAAAKRUH--- ----IRKKAAAAAAAAAAAAAKKRI---- ----IQRKKAAAAAAAAAAAKKRQI---- ----BBBCCCCCCCCCCCCCCCBBB---- 
-----CCCCCCCC---CCCCCCCC----- --BCCBAAAAAABC-CBAAAAAABCCB-- --BAAAAAAAAAAC-CAAAAAAAAAAB-- --HAAAAAAAAAAACAAAAAAAAAAAH-- --HAAAAAAAAAAAAAAAAAAAAAAAH-- --HAAAAAAAAAAAAAAAAAAAAAAAH-- --JAAAAAAAAAAAAAAAAAAAAAAAJ-- --JAAAAAAAAAAAAAAAAAAAAAAAJ-- --JAAAAAAAAAAAAAAAAAAAAAAAJ-- --JAAAAAAAAAAAAAAAAAAAAAAAJ-- --JAAAAAAAAAAAAAAAAAAAAAAAJ-- --JHAAAAAAAAAAAAAAAAAAAAAHJ-- --BHAAAAAAAAAAAAAAAAAAAAABB-- ---BCCCCCCCCCCCCCCCCCCCCCB--- 
-----CCCCCCCC---CCCCCCCC----- --CCCBAAAAAABC-CBAAAAAABCCC-- -BBAAAAAAAAAAC-CAAAAAAAAAABB- -JAAAAAAAAAAAACADAAAAAAAAAAJ- -JAAAAAAAAAADAAADAAAAAAAAAAJ- -LAAAAAAAAAADPAPDAAAAAAAAAAL- -LAAAAAAAAAADPCPDAAAAAAAAAAL- -LAAAAAAAAAADPCPDAAAAAAAAAAL- -LAAAAAAAAAADPCPDAAAAAAAAAAL- -LAAAAAAAAAADPCPDAAAAAAAAAAL- -LAAAAAAAAAADDPDDAAAAAAAAAAL- -BAAAAAAAAAAGDPDGAAAAAAAAAAB- -BCBAAAAAAAAAAAAAAAAAAAAAXBB- ---CCCCCCCCCCCCCCCCCCCCCCC--- 
-----CCCCCCCC---CCCCCCCC----- --CCCBAAAAAAXC-CBAAAAAABCCC-- BCBAAAAAAAFGDC-CDGFAAAAAAABCB BAAAAAAAAAFGDBCBDGFAAAAAAAAAB MAAAAAAAAAFG-BBB-GFAAAAAAAAAM MAAAAAAAAAFG--B--GFAAAAAAAAAM MAAAAAAAAAFG-----GFAAAAAAAAAM MAAAAAAAAAFG-----GFAAAAAAAAAM MAAAAAAAAAFG-----GFAAAAAAAAAM MAAAAAAAAAFG-----GFAAAAAAAAAM BAAAAAAAAAFG-----GFAAAAAAAAAB BBAAAAAAAAEF-----FEAAAAAAAAXB -CCBAAAAAAAABBBBBAAAAAAAACCB- ---CCCCCCCCCCCCCCCCCCCCCCC--- 
-----CCCCCCCC---CCCCCCCC----- --CCCBAAAABBBC-CBBBAAAACCCC-- CCBAAAAHIE---C-C---EIHAAAABCC BAAAAAAHIE---BCB---EIHAAAAAAB BAAAAAAHIE---BBB---EIHAAAAAAB BAAAAAAHIE----B----EIHAAAAAAB BAAAAAAHIE---------EIHAAAAAAB BAAAAAAHIE---------EIHAAAAAAB BAAAAAAHIE---------EIHAAAAAAB BAAAAAAHIE---------EIHAAAAAAB BAAAAAAHIE---------EIHAAAAAAB CBAAAAAJHE---------EHJAAAAACC -CCBAAAAAABBBBBBBBBAAAAAACCC- ---CCCCCCCBBBBBBBBBCCCCCCC--- 
-----CCCCCCCC---CCCCCCCC----- --CCCBABBBBBBC-CBBBBBBABCCC-- CCBYTLJ------C-C------JLTYBCC CAAMTLJ------BCB------JLTMAAC CAAMTLJ------BBB------JLTMAAC CAAMTLJ-------B-------JLTMAAC CAAMTLJ---------------JLTMAAC CAAMTLJ---------------JLTMAAC CAAMTLJ---------------JLTMAAC CAAWMTJ---------------JTMWAAC CAAWMTL---------------LTMWAAC CBAZMTL---------------LTMZACC -CCBAAABBBB-------BBBBAAACCC- ---CCCCBBBB-------BBBBCCCC--- 
-----BBBBBBBB---BBBBBBBB----- --BBBBBBB---BB-BB---BBBBBBB-- BBBB---------B-B---------BBBB BVV----------BBB----------VBB -CB-----------B-----------BC- BVB-----------------------BBB -CB-----------------------BC- BVB-----------------------BBB -CB-----------------------BC- BVB-----------------------BBB BVB-----------------------BBB BBBB---------------------BVBB -BBBBBBB-------------BBBBBBB- ---BBBBB-------------BBBBB--- 
----------------------------- ----------------------------- ----------------------------- B---------------------------B B---------------------------B B---------------------------B B---------------------------B B---------------------------B B---------------------------B B---------------------------B ----------------------------- ----------------------------- ----------------------------- ----------------------------- 
----------------------------- ----------------------------- ----------------------------- B---------------------------B C---------------------------C C---------------------------C C---------------------------C B---------------------------C C---------------------------C B---------------------------B ----------------------------- ----------------------------- ----------------------------- ----------------------------- 
----------------------------- ----------------------------- ----------------------------- B---------------------------B C---------------------------C B---------------------------B C---------------------------B B---------------------------B C---------------------------C B---------------------------B ----------------------------- ----------------------------- ----------------------------- ----------------------------- 
----------------------------- ----------------------------- ----------------------------- B---------------------------B C---------------------------C B---------------------------B C---------------------------B C---------------------------B C---------------------------C B---------------------------B ----------------------------- ----------------------------- ----------------------------- ----------------------------- 
----------------------------- ----------------------------- ----------------------------- B---------------------------B B---------------------------B B---------------------------B B---------------------------B B---------------------------B B---------------------------B B---------------------------B ----------------------------- ----------------------------- ----------------------------- ----------------------------- 
----------------------------- ----------------------------- ----------------------------- B---------------------------B C---------------------------C B---------------------------C B---------------------------C B---------------------------C B---------------------------C B---------------------------B ----------------------------- ----------------------------- ----------------------------- ----------------------------- 
----------------------------- ----------------------------- ----------------------------- B---------------------------B C---------------------------B B---------------------------B B---------------------------C B---------------------------B B---------------------------C B---------------------------B ----------------------------- ----------------------------- ----------------------------- ----------------------------- 
----------------------------- ----------------------------- ----------------------------- B---------------------------B C---------------------------C C---------------------------C C---------------------------B C---------------------------C C---------------------------C B---------------------------B ----------------------------- ----------------------------- ----------------------------- ----------------------------- 
----------------------------- ----------------------------- ----------------------------- B---------------------------B B---------------------------B B---------------------------B B---------------------------B B---------------------------B B---------------------------B B---------------------------B ----------------------------- ----------------------------- ----------------------------- ----------------------------- 
----------------------------- ----------------------------- ----------------------------- B---------------------------B C---------------------------B B---------------------------B C---------------------------C B---------------------------C C---------------------------C B---------------------------B ----------------------------- ----------------------------- ----------------------------- ----------------------------- 
----------------------------- ----------------------------- ----------------------------- BB-------------------------BB CC-------------------------CC BC-------------------------CC CC-------------------------CC BC-------------------------BB CC-------------------------BB BB-------------------------BB ----------------------------- ----------------------------- ----------------------------- ----------------------------- 
----------------------------- ----------------------------- ----------------------------- -BB-----------------------BB- -CB-----------------------BB- -CB-----------------------BB- -CB-----------------------CC- -CB-----------------------CC- -CB-----------------------CC- -BB-----------------------BB- ----------------------------- ----------------------------- ----------------------------- ----------------------------- 
----------------------------- ----------------------------- ----------------------------- --BB---------------------BB-- --BC---------------------BB-- --BC---------------------BB-- --BB---------------------BB-- --BC---------------------BB-- --BC---------------------BB-- --BB---------------------BB-- ----------------------------- ----------------------------- ----------------------------- ----------------------------- 
----------------------------- ----------------------------- ----------------------------- ---BB-------------------BB--- ---CB-------------------CC--- ---CC-------------------CC--- ---BC-------------------CC--- ---CC-------------------CC--- ---CB-------------------CC--- ---BB-------------------BB--- ----------------------------- ----------------------------- ----------------------------- ----------------------------- 
----------------------------- ----------------------------- ----------------------------- ----BB-----------------BB---- ----BC-----------------BB---- ----CC-----------------BB---- ----CB-----------------CC---- ----CC-----------------CB---- ----BC-----------------CC---- ----BB-----------------BB---- ----------------------------- ----------------------------- ----------------------------- ----------------------------- 
----------------------------- ----------------------------- ----------------------------- -----BB---------------BB----- -----CB---------------BB----- -----CB---------------BB----- -----BB---------------BC----- -----CB---------------BC----- -----CB---------------BC----- -----BB---------------BB----- ----------------------------- ----------------------------- ----------------------------- ----------------------------- 
----------------------------- ----------------------------- ----------------------------- ------BB-------------BB------ ------BC-------------BB------ ------BC-------------BB------ ------BC-------------BB------ ------BC-------------BB------ ------BC-------------CB------ ------BB-------------BB------ ----------------------------- ----------------------------- ----------------------------- ----------------------------- 
----------------------------- ----------------------------- ----------------------------- -------BBB---------BBB------- -------CCC---------BCB------- -------CBC---------BCB------- -------CBC---------BCB------- -------CBC---------BCB------- -------CCC---------CCC------- -------BBB---------BBB------- ----------------------------- ----------------------------- ----------------------------- ----------------------------- 
----------------------------- ----------------------------- ----------------------------- ---------BBBBBBBBBBB--------- ---------CBBCBBCCCBB--------- ---------CBCBCBCBCBB--------- ---------CBCBCBCBCBB--------- ---------CBCBCBCBCBB--------- ---------CBCBCBCCCBC--------- ---------BBBBBBBBBBB--------- ----------------------------- ----------------------------- ----------------------------- ----------------------------- 
