model
size = 29 14 27, scale = 0.05, origin = -y
material 
  colors = A:#FF6905 B:#0A0000 C:#FEFEFE D:#F6D644 E:#FDF4B9 F:#FAEB88 G:#F28214 H:#F2AB14 I:#F29114 J:#B9E7FD K:#4AA7F6 L:#1352F1 M:#F3BC27 N:#1224B0 O:#FF5705 P:#F23914 Q:#FF3A05 R:#ED2707 S:#030303 T:#FE3C00
voxels
------BBBBBBB---BBBBBBB------ ------MMHIGABB-BBAGIHMM------ -----DMMHIGAOB-BOAGIHMMD----- ----FDDMHIGAOBBBOAGIHMDDF---- ----FFDMHIGAOQBQOAGIHMDFF---- ----EFDMHIGAOQRQOAGIHMDFE---- ----EFDMHIGAOQRQOAGIHMDFE---- ----EFDMHIGAOQRQOAGIHMDFE---- ----EFDMHIGAOQRQOAGIHMDFE---- ----EFDMHIGAOQRQOAGIHMDFE---- ----EFDMHIGGAOQOAGGIHMDFE---- -----FDMHIGGAOQOAGGIHMDF----- ------FDMHIGAOQOAGIHMDF------ ------BBBBBBBBBBBBBBBBB------ 
-----BBBBBBBB---BBBBBBBB----- ---BBBDDAAAABB-BBAAAADDBBB--- ---EFFDAAAAAAB-BAAAAAADFFE--- ---EFFDAAAAAAABAAAAAAADFFE--- ---EFFDAAAAAAAAAAAAAAADFFE--- ---JEFDAAAAAAAAAAAAAAADFEJ--- ---JEFDAAAAAAAAAAAAAAADFEJ--- ---JEFDAAAAAAAAAAAAAAADFEJ--- ---JEFDAAAAAAAAAAAAAAADFEJ--- ---JEFDAAAAAAAAAAAAAAADFEJ--- ---JEFDAAAAAAAAAAAAAAADFEJ--- ----EFDDAAAAAAAAAAAAADDFE---- ----EFFDDAAAAAAAAAAADDFFE---- ----BBBBBBBBBBBBBBBBBBBBB---- 
-----BBBBBBBB---BBBBBBBB----- --BBBBAAAAAABB-BBAAAAAABBBB-- --BAAAAAAAAAAB-BAAAAAAAAAAB-- --JAAAAAAAAAAABAAAAAAAAAAAJ-- --JAAAAAAAAAAAAAAAAAAAAAAAJ-- --JAAAAAAAAAAAAAAAAAAAAAAAJ-- --KAAAAAAAAAAAAAAAAAAAAAAAK-- --KAAAAAAAAAAAAAAAAAAAAAAAK-- --KAAAAAAAAAAAAAAAAAAAAAAAK-- --KAAAAAAAAAAAAAAAAAAAAAAAK-- --KAAAAAAAAAAAAAAAAAAAAAAAK-- --KJAAAAAAAAAAAAAAAAAAAAAJK-- --BJAAAAAAAAAAAAAAAAAAAAABB-- ---BBBBBBBBBBBBBBBBBBBBBBB--- 
-----BBBBBBBB---BBBBBBBB----- --BBBBAAAAAABB-BBAAAAAABBBB-- -BBAAAAAAAAAAB-BAAAAAAAAAABB- -KAAAAAAAAAAAABAAAAAAAAAAAAK- -KAAAAAAAAAAPAAAPAAAAAAAAAAK- -LAAAAAAAAAAPRARPAAAAAAAAAAL- -LAAAAAAAAAAPPRPPAAAAAAAAAAL- -LAAAAAAAAAAAPRPAAAAAAAAAAAL- -LAAAAAAAAAAAPRPAAAAAAAAAAAL- -LAAAAAAAAAAAPRPAAAAAAAAAAAL- -LAAAAAAAAAAAAPAAAAAAAAAAAAL- -BAAAAAAAAAAAAPAAAAAAAAAAAAB- -BBBAAAAAAAAAAAAAAAAAAAAATBB- ---BBBBBBBBBBBBBBBBBBBBBBB--- 
-----BBBBBBBB---BBBBBBBB----- --BBBBAAAAAATB-BBAAAAAABBBB-- BBBAAAAAAAGAAB-BAAGAAAAAAABBB BAAAAAAAAAGAABBBAAGAAAAAAAAAB NAAAAAAAAAGA-BBB-AGAAAAAAAAAN NAAAAAAAAAGA--B--AGAAAAAAAAAN NAAAAAAAAAIG-----GIAAAAAAAAAN NAAAAAAAAAIG-----GIAAAAAAAAAN NAAAAAAAAAIG-----GIAAAAAAAAAN NAAAAAAAAAIG-----GIAAAAAAAAAN BAAAAAAAAAIG-----GIAAAAAAAAAB BBAAAAAAAAIG-----GIAAAAAAAATB -BBBAAAAAAAABBBBBAAAAAAAABBB- ---BBBBBBBBBBBBBBBBBBBBBBB--- 
-----BBBBBBBB---BBBBBBBB----- --BBBBAAAABBBB-BBBBAAAABBBB-- BBBAAAADHI---B-B---IHDAAAABBB BAAAAAADHI---BBB---IHDAAAAAAB BAAAAAADHI---BBB---IHDAAAAAAB BAAAAAADHI----B----IHDAAAAAAB BAAAAAAEDH---------HDEAAAAAAB BAAAAAAEDH---------HDEAAAAAAB BAAAAAAEDH---------HDEAAAAAAB BAAAAAAEDH---------HDEAAAAAAB BAAAAAAEDH---------HDEAAAAAAB BBAAAAAEDH---------HDEAAAAABB -BBBAAAAAABBBBBBBBBAAAAAABBB- ---BBBBBBBBBBBBBBBBBBBBBBB--- 
-----BBBBBBBB---BBBBBBBB----- --BBBBABBBBBBB-BBBBBBBABBBB-- BBBLKJE------B-B------EJKLBBB BAALKJE------BBB------EJKLAAB BAALKJE------BBB------EJKLAAB BAALKJE-------B-------EJKLAAB BAANLKJ---------------JKLNAAB BAANLKJ---------------JKLNAAB BAANLKJ---------------JKLNAAB BAANLKJ---------------JKLNAAB BAANLKJ---------------JKLNAAB BBANLKJ---------------JKLNABB -BBBAAABBBB-------BBBBAAABBB- ---BBBBBBBB-------BBBBBBBB--- 
-----BBBBBBBB---BBBBBBBB----- --BBBBBBB---BB-BB---BBBBBBB-- BBBB---------B-B---------BBBB BSS----------BBB----------SBB -CB-----------B-----------BC- BSB-----------------------BBB -CB-----------------------BC- BSB-----------------------BBB -CB-----------------------BC- BSB-----------------------BBB BSB-----------------------BBB BBBB---------------------BSBB -BBBBBBB-------------BBBBBBB- ---BBBBB-------------BBBBB--- 
----------------------------- ----------------------------- ----------------------------- B---------------------------B B---------------------------B B---------------------------B B---------------------------B B---------------------------B B---------------------------B B---------------------------B ----------------------------- ----------------------------- ----------------------------- ----------------------------- 
----------------------------- ----------------------------- ----------------------------- B---------------------------B C---------------------------C C---------------------------C C---------------------------C B---------------------------C C---------------------------C B---------------------------B ----------------------------- ----------------------------- ----------------------------- ----------------------------- 
----------------------------- ----------------------------- ----------------------------- B---------------------------B C---------------------------C B---------------------------B C---------------------------B B---------------------------B C---------------------------C B---------------------------B ----------------------------- ----------------------------- ----------------------------- ----------------------------- 
----------------------------- ----------------------------- ----------------------------- B---------------------------B C---------------------------C B---------------------------B C---------------------------B C---------------------------B C---------------------------C B---------------------------B ----------------------------- ----------------------------- ----------------------------- ----------------------------- 
----------------------------- ----------------------------- ----------------------------- B---------------------------B B---------------------------B B---------------------------B B---------------------------B B---------------------------B B---------------------------B B---------------------------B ----------------------------- ----------------------------- ----------------------------- ----------------------------- 
----------------------------- ----------------------------- ----------------------------- B---------------------------B C---------------------------C B---------------------------C B---------------------------C B---------------------------C B---------------------------C B---------------------------B ----------------------------- ----------------------------- ----------------------------- ----------------------------- 
----------------------------- ----------------------------- ----------------------------- B---------------------------B C---------------------------B B---------------------------B B---------------------------C B---------------------------B B---------------------------C B---------------------------B ----------------------------- ----------------------------- ----------------------------- ----------------------------- 
----------------------------- ----------------------------- ----------------------------- B---------------------------B C---------------------------C C---------------------------C C---------------------------B C---------------------------C C---------------------------C B---------------------------B ----------------------------- ----------------------------- ----------------------------- ----------------------------- 
----------------------------- ----------------------------- ----------------------------- B---------------------------B B---------------------------B B---------------------------B B---------------------------B B---------------------------B B---------------------------B B---------------------------B ----------------------------- ----------------------------- ----------------------------- ----------------------------- 
----------------------------- ----------------------------- ----------------------------- B---------------------------B C---------------------------B B---------------------------B C---------------------------C B---------------------------C C---------------------------C B---------------------------B ----------------------------- ----------------------------- ----------------------------- ----------------------------- 
----------------------------- ----------------------------- ----------------------------- BB-------------------------BB CC-------------------------CC BC-------------------------CC CC-------------------------CC BC-------------------------BB CC-------------------------BB BB-------------------------BB ----------------------------- ----------------------------- ----------------------------- ----------------------------- 
----------------------------- ----------------------------- ----------------------------- -BB-----------------------BB- -CB-----------------------BB- -CB-----------------------BB- -CB-----------------------BC- -CB-----------------------CC- -CB-----------------------CC- -BB-----------------------BB- ----------------------------- ----------------------------- ----------------------------- ----------------------------- 
----------------------------- ----------------------------- ----------------------------- --BB---------------------BB-- --BC---------------------BB-- --BC---------------------BB-- --BB---------------------BB-- --BC---------------------BB-- --BC---------------------BB-- --BB---------------------BB-- ----------------------------- ----------------------------- ----------------------------- ----------------------------- 
----------------------------- ----------------------------- ----------------------------- ---BB-------------------BB--- ---CB-------------------CC--- ---CC-------------------CC--- ---BC-------------------CC--- ---CC-------------------CC--- ---CB-------------------CC--- ---BB-------------------BB--- ----------------------------- ----------------------------- ----------------------------- ----------------------------- 
----------------------------- ----------------------------- ----------------------------- ----BB-----------------BB---- ----BC-----------------BB---- ----CC-----------------BB---- ----CB-----------------CC---- ----CC-----------------CB---- ----BC-----------------CC---- ----BB-----------------BB---- ----------------------------- ----------------------------- ----------------------------- ----------------------------- 
----------------------------- ----------------------------- ----------------------------- -----BB---------------BB----- -----CB---------------BB----- -----CB---------------BB----- -----BB---------------BC----- -----CB---------------BC----- -----CB---------------BC----- -----BB---------------BB----- ----------------------------- ----------------------------- ----------------------------- ----------------------------- 
----------------------------- ----------------------------- ----------------------------- ------BB-------------BB------ ------BC-------------BB------ ------BC-------------BB------ ------BC-------------BB------ ------BC-------------BB------ ------BC-------------CB------ ------BB-------------BB------ ----------------------------- ----------------------------- ----------------------------- ----------------------------- 
----------------------------- ----------------------------- ----------------------------- -------BBB---------BBB------- -------CCC---------BCB------- -------CBC---------BCB------- -------CBC---------BCB------- -------CBC---------BCB------- -------CCC---------CCC------- -------BBB---------BBB------- ----------------------------- ----------------------------- ----------------------------- ----------------------------- 
----------------------------- ----------------------------- ----------------------------- ---------BBBBBBBBBBB--------- ---------CBBCBBCCCBB--------- ---------CBCBCBCBCBB--------- ---------CBCBCBCBCBB--------- ---------CBCBCBCBCBB--------- ---------CBCBCBCCCBC--------- ---------BBBBBBBBBBB--------- ----------------------------- ----------------------------- ----------------------------- ----------------------------- 
