model
size = 29 14 27, scale = 0.05, origin = -y
material 
  colors = A:#FF6905 B:#FE3C00 C:#0A0000 D:#F6D644 E:#FDF4B9 F:#FAEB88 G:#F28214 H:#F2AB14 I:#F29114 J:#B9E7FD K:#4AA7F6 L:#1352F1 M:#F3BC27 N:#1224B0 O:#FF5705 P:#F23914 Q:#FF3A05 R:#ED2707 S:#030303
voxels
------CCCCCCC---CCCCCCC------ ------MMHIGACC-CCAGIHMM------ -----DMMHIGAOC-COAGIHMMD----- ----FDDMHIGAOCCCOAGIHMDDF---- ----FFDMHIGAOQCQOAGIHMDFF---- ----EFDMHIGAOQRQOAGIHMDFE---- ----EFDMHIGAOQRQOAGIHMDFE---- ----EFDMHIGAOQRQOAGIHMDFE---- ----EFDMHIGAOQRQOAGIHMDFE---- ----EFDMHIGAOQRQOAGIHMDFE---- ----EFDMHIGGAOQOAGGIHMDFE---- -----FDMHIGGAOQOAGGIHMDF----- ------FDMHIGAOQOAGIHMDF------ ------CCCCCCCCCCCCCCCCC------ 
-----CCBBBBBB---BBBBBBCC----- ---CCCDDAAAACB-BCAAAADDCCC--- ---EFFDAAAAAAB-BAAAAAADFFE--- ---EFFDAAAAAAABAAAAAAADFFE--- ---EFFDAAAAAAAAAAAAAAADFFE--- ---JEFDAAAAAAAAAAAAAAADFEJ--- ---JEFDAAAAAAAAAAAAAAADFEJ--- ---JEFDAAAAAAAAAAAAAAADFEJ--- ---JEFDAAAAAAAAAAAAAAADFEJ--- ---JEFDAAAAAAAAAAAAAAADFEJ--- ---JEFDAAAAAAAAAAAAAAADFEJ--- ----EFDDAAAAAAAAAAAAADDFE---- ----EFFDDAAAAAAAAAAADDFFE---- ----CCCBBBBBBBBBBBBBBBCCC---- 
-----BBBBBBBB---BBBBBBBB----- --CBBCAAAAAACB-BCAAAAAACBBC-- --CAAAAAAAAAAB-BAAAAAAAAAAC-- --JAAAAAAAAAAABAAAAAAAAAAAJ-- --JAAAAAAAAAAAAAAAAAAAAAAAJ-- --JAAAAAAAAAAAAAAAAAAAAAAAJ-- --KAAAAAAAAAAAAAAAAAAAAAAAK-- --KAAAAAAAAAAAAAAAAAAAAAAAK-- --KAAAAAAAAAAAAAAAAAAAAAAAK-- --KAAAAAAAAAAAAAAAAAAAAAAAK-- --KAAAAAAAAAAAAAAAAAAAAAAAK-- --KJAAAAAAAAAAAAAAAAAAAAAJK-- --CJAAAAAAAAAAAAAAAAAAAAACC-- ---CCBBBBBBBBBBBBBBBBBBBCC--- 
-----BBBBBBBB---BBBBBBBB----- --BBBCAAAAAACB-BCAAAAAACBBB-- -CCAAAAAAAAAAB-CAAAAAAAAAACC- -KAAAAAAAAAAAABAAAAAAAAAAAAK- -KAAAAAAAAAAPAAAPAAAAAAAAAAK- -LAAAAAAAAAAPRARPAAAAAAAAAAL- -LAAAAAAAAAAPPRPPAAAAAAAAAAL- -LAAAAAAAAAAAPRPAAAAAAAAAAAL- -LAAAAAAAAAAAPRPAAAAAAAAAAAL- -LAAAAAAAAAAAPRPAAAAAAAAAAAL- -LAAAAAAAAAAAAPAAAAAAAAAAAAL- -CAAAAAAAAAAAAPAAAAAAAAAAAAC- -CCCAAAAAAAAAAAAAAAAAAAAABCC- ---BBBBBBBBBBBBBBBBBBBBBBB--- 
-----BBBBBBBB---BBBBBBBB----- --BBBCAAAAAABB-BCAAAAAACBBB-- CBCAAAAAAAGAAB-BAAGAAAAAAACBC CAAAAAAAAAGAACBCAAGAAAAAAAAAC NAAAAAAAAAGA-CCC-AGAAAAAAAAAN NAAAAAAAAAGA--C--AGAAAAAAAAAN NAAAAAAAAAIG-----GIAAAAAAAAAN NAAAAAAAAAIG-----GIAAAAAAAAAN NAAAAAAAAAIG-----GIAAAAAAAAAN NAAAAAAAAAIG-----GIAAAAAAAAAN CAAAAAAAAAIG-----GIAAAAAAAAAC CCAAAAAAAAIG-----GIAAAAAAAABC -BBCAAAAAAAACCCCCAAAAAAAABBB- ---BBBBBBBBBBBBBBBBBBBBBBB--- 
-----BBBBBBBB---BBBBBBBB----- --BBBCAAAACCCB-BCCCAAAACBBB-- BBCAAAADHI---B-B---IHDAAAACBB CAAAAAADHI---CBC---IHDAAAAAAC CAAAAAADHI---CCC---IHDAAAAAAC CAAAAAADHI----C----IHDAAAAAAC CAAAAAAEDH---------HDEAAAAAAC CAAAAAAEDH---------HDEAAAAAAC CAAAAAAEDH---------HDEAAAAAAC CAAAAAAEDH---------HDEAAAAAAC CAAAAAAEDH---------HDEAAAAAAC BCAAAAAEDH---------HDEAAAAACB -BBCAAAAAACCCCCCCCCAAAAAABBB- ---BBBBBBBCCCCCCCCCBBBBBBB--- 
-----BBBBBBBB---BBBBBBBB----- --BBBCACCCCCCB-BCCCCCCACBBB-- BBCLKJE------B-B------EJKLCBB BAALKJE------CBC------EJKLAAB BAALKJE------CCC------EJKLAAB BAALKJE-------C-------EJKLAAB BAANLKJ---------------JKLNAAB BAANLKJ---------------JKLNAAB BAANLKJ---------------JKLNAAB BAANLKJ---------------JKLNAAB BAANLKJ---------------JKLNAAB BCANLKJ---------------JKLNABB -BBCAAACCCC-------CCCCAAAABB- ---BBBBCCCC-------CCCCBBBB--- 
-----CCCCCCCC---CCCCCCCC----- --CCCCCCC---CC-CC---CCCCCCC-- CCCC---------C-C---------CCCC BBS----------CCC----------SBB -CC-----------C-----------CC- BBC-----------------------CBB -CC-----------------------CC- BBC-----------------------CBB -CC-----------------------CC- BBC-----------------------CBB CSC-----------------------CCC CCCC---------------------CSCC -CCCCCCC-------------CCCCCCC- ---CCCCC-------------CCCCC--- 
----------------------------- ----------------------------- ----------------------------- B---------------------------B B---------------------------B B---------------------------B B---------------------------B B---------------------------B B---------------------------B B---------------------------B ----------------------------- ----------------------------- ----------------------------- ----------------------------- 
----------------------------- ----------------------------- ----------------------------- B---------------------------B C---------------------------C C---------------------------C C---------------------------C B---------------------------C C---------------------------C B---------------------------B ----------------------------- ----------------------------- ----------------------------- ----------------------------- 
----------------------------- ----------------------------- ----------------------------- B---------------------------B C---------------------------C B---------------------------B C---------------------------B B---------------------------B C---------------------------C B---------------------------B ----------------------------- ----------------------------- ----------------------------- ----------------------------- 
----------------------------- ----------------------------- ----------------------------- B---------------------------B C---------------------------C B---------------------------B C---------------------------B C---------------------------B C---------------------------C B---------------------------B ----------------------------- ----------------------------- ----------------------------- ----------------------------- 
----------------------------- ----------------------------- ----------------------------- B---------------------------B B---------------------------B B---------------------------B B---------------------------B B---------------------------B B---------------------------B B---------------------------B ----------------------------- ----------------------------- ----------------------------- ----------------------------- 
----------------------------- ----------------------------- ----------------------------- B---------------------------B C---------------------------C B---------------------------C B---------------------------C B---------------------------C B---------------------------C B---------------------------B ----------------------------- ----------------------------- ----------------------------- ----------------------------- 
----------------------------- ----------------------------- ----------------------------- B---------------------------B C---------------------------B B---------------------------B B---------------------------C B---------------------------B B---------------------------C B---------------------------B ----------------------------- ----------------------------- ----------------------------- ----------------------------- 
----------------------------- ----------------------------- ----------------------------- B---------------------------B C---------------------------C C---------------------------C C---------------------------B C---------------------------C C---------------------------C B---------------------------B ----------------------------- ----------------------------- ----------------------------- ----------------------------- 
----------------------------- ----------------------------- ----------------------------- B---------------------------B B---------------------------B B---------------------------B B---------------------------B B---------------------------B B---------------------------B B---------------------------B ----------------------------- ----------------------------- ----------------------------- ----------------------------- 
----------------------------- ----------------------------- ----------------------------- B---------------------------B C---------------------------B B---------------------------B C---------------------------C B---------------------------C C---------------------------C B---------------------------B ----------------------------- ----------------------------- ----------------------------- ----------------------------- 
----------------------------- ----------------------------- ----------------------------- BB-------------------------BB CC-------------------------CC BC-------------------------CC CC-------------------------CC BC-------------------------BB CC-------------------------BB BB-------------------------BB ----------------------------- ----------------------------- ----------------------------- ----------------------------- 
----------------------------- ----------------------------- ----------------------------- -BB-----------------------BB- -CB-----------------------BB- -CB-----------------------BB- -CB-----------------------BC- -CB-----------------------CC- -CB-----------------------CC- -BB-----------------------BB- ----------------------------- ----------------------------- ----------------------------- ----------------------------- 
----------------------------- ----------------------------- ----------------------------- --BB---------------------BB-- --BC---------------------BB-- --BC---------------------BB-- --BB---------------------BB-- --BC---------------------BB-- --BC---------------------BB-- --BB---------------------BB-- ----------------------------- ----------------------------- ----------------------------- ----------------------------- 
----------------------------- ----------------------------- ----------------------------- ---BB-------------------BB--- ---CB-------------------CC--- ---CC-------------------CC--- ---BC-------------------CC--- ---CC-------------------CC--- ---CB-------------------CC--- ---BB-------------------BB--- ----------------------------- ----------------------------- ----------------------------- ----------------------------- 
----------------------------- ----------------------------- ----------------------------- ----BB-----------------BB---- ----BC-----------------BB---- ----CC-----------------BB---- ----CB-----------------CC---- ----CC-----------------CB---- ----BC-----------------CC---- ----BB-----------------BB---- ----------------------------- ----------------------------- ----------------------------- ----------------------------- 
----------------------------- ----------------------------- ----------------------------- -----BB---------------BB----- -----CB---------------BB----- -----CB---------------BB----- -----BB---------------BC----- -----CB---------------BC----- -----CB---------------BC----- -----BB---------------BB----- ----------------------------- ----------------------------- ----------------------------- ----------------------------- 
----------------------------- ----------------------------- ----------------------------- ------BB-------------BB------ ------BC-------------BB------ ------BC-------------BB------ ------BC-------------BB------ ------BC-------------BB------ ------BC-------------CB------ ------BB-------------BB------ ----------------------------- ----------------------------- ----------------------------- ----------------------------- 
----------------------------- ----------------------------- ----------------------------- -------BBB---------BBB------- -------CCC---------BCB------- -------CBC---------BCB------- -------CBC---------BCB------- -------CBC---------BCB------- -------CCC---------CCC------- -------BBB---------BBB------- ----------------------------- ----------------------------- ----------------------------- ----------------------------- 
----------------------------- ----------------------------- ----------------------------- ---------BBBBBBBBBBB--------- ---------CBBCBBCCCBB--------- ---------CBCBCBCBCBB--------- ---------CBCBCBCBCBB--------- ---------CBCBCBCBCBB--------- ---------CBCBCBCCCBC--------- ---------BBBBBBBBBBB--------- ----------------------------- ----------------------------- ----------------------------- ----------------------------- 
