model
size = 20 26 13, scale = 0.05, origin = -y
material 
  colors = A:#555 B:#DFA59A
voxels
-------------------- -------------------- -------------------- -------------------- -------------------- -------------------- -------------------- -------------------- -------------------- BAA--------------AAB ABAAAAAAAAAAAAAAAAAB ABA--------------ABA AAB--------------ABA AABAAAAAAAAAAAAAABAA AAA--------------AAA AAB--------------BAA AABAAAAAAAAAAAAAAABA ABA--------------ABA ABA--------------AAB BAAAAAAAAAAAAAAAAAAB -------------------- -------------------- -------------------- -------------------- -------------------- -------------------- 
-------------------- -------------------- -------------------- -------------------- -------------------- -------------------- -------------------- -------------------- -------------------- ABBBBBBBBBBBBBBBBBBA ABBAAAAAAAAAAAAAABBA ABB--------------BBA ABB--------------BBA ABB--------------BBA ABB--------------BBA ABB--------------BBA ABB--------------BBA ABB--------------BBA ABB--------------BBA ABB--------------BBA -------------------- -------------------- -------------------- -------------------- -------------------- -------------------- 
BBA--------------ABB ABA--------------ABA ABA--------------ABA ABA--------------ABA ABA--------------ABA ABA--------------ABA ABA--------------ABA ABA--------------ABA BBBAAAAAAAAAAAAAABBB ABBBBBBBBBBBBBBBBBBA ABBAAAAAAAAAAAAAABBA ABB--------------BBA ABB--------------BBA ABB--------------BBA ABB--------------BBA ABB--------------BBA ABB--------------BBA ABB--------------BBA ABB--------------BBA ABB--------------BBA ABB--------------BBA ABB--------------BBA ABB--------------BBA ABB--------------BBA ABB--------------BBA ABB--------------BBA 
BBA--------------ABB A-A--------------A-A A-A--------------A-A A-A--------------A-A A-A--------------A-A A-A--------------A-A A-A--------------A-A A-A--------------A-A B--AAAAAAAAAAAAAAB-B A--BBBBBBBBBBBBBBB-A AAAAAAAAAAAAAAAAAAAA -------------------- ABB--------------BBA ABB--------------BBA -------------------- ABB--------------BBA ABB--------------BBA -------------------- -------------------- -------------------- -------------------- -------------------- -------------------- -------------------- -------------------- ABB--------------BBA 
ABA--------------ABA B-A--------------A-B A-A--------------A-A A-A--------------A-A A-A--------------A-A A-A--------------A-A A-A--------------A-A B-A--------------A-B A--AAAAAAAAAAAAAAB-A A--BBBBBBBBBBBBBBB-A AAAAAAAAAAAAAAAAAAAA -------------------- ABB--------------BBA -------------------- BBB--------------BBB -------------------- -------------------- ABB--------------BBA -------------------- ABB--------------BBA ABB--------------BBA -------------------- -------------------- -------------------- -------------------- ABB--------------BBA 
ABA--------------ABA B-A--------------A-B A-A--------------A-A A-A--------------A-A A-A--------------A-A A-A--------------A-A A-A--------------A-A B-A--------------A-B ABBAAAAAAAAAAAAAAB-A ABBBBBBBBBBBBBBBBBBA ABBAAAAAAAAAAAAAABBA ABB--------------BBA A-B--------------BBA ABB--------------BBA -------------------- ABB--------------BBA ABB--------------BBA ABB--------------BBA ABB--------------BBA ABB--------------BBA ABB--------------BBA ABB--------------BBA -------------------- -------------------- -------------------- ABB--------------BBA 
ABA--------------ABA B-A--------------A-B A-A--------------A-A A-A--------------A-A A-A--------------A-A A-A--------------A-A B-A--------------A-B A-A--------------A-A ABBAAAAAAAAAAAAAABBA ---BBBBBBBBBBBBBB--- ---AAAAAAAAAAAAAA--- A----------------B-- AB---------------BB- ABB--------------BBA ABB--------------BBA A-B--------------BBA ABB--------------BBA -------------------- ABB--------------BBA A-B--------------B-A -------------------- ABB--------------BBA ABB--------------BBA ABB--------------BBA ABB--------------BBA ABB--------------BBA 
ABA--------------ABA A-A--------------A-A B-A--------------A-B A-A--------------A-A A-A--------------A-A A-A--------------A-A B-A--------------A-B A-A--------------A-A ABBAAAAAAAAAAAAAAB-A ABBBBBBBBBBBBBBBBBBA ABBAAAAAAAAAAAAAABBA ABB--------------BBA A-B--------------BBA ABB--------------BBA -------------------- ABB--------------BBA ABB--------------BBA ABB--------------BBA ABB--------------BBA ABB--------------BBA ABB--------------BBA ABB--------------BBA -------------------- -------------------- -------------------- ABB--------------BBA 
ABA--------------ABA A-A--------------A-A B-A--------------A-B A-A--------------A-A A-A--------------A-A B-A--------------A-B A-A--------------A-A A-A--------------A-A A--AAAAAAAAAAAAAAB-A A--BBBBBBBBBBBBBBB-A AAAAAAAAAAAAAAAAAAAA -------------------- ABB--------------BBA -------------------- BBB--------------BBB -------------------- -------------------- ABB--------------BBA -------------------- ABB--------------BBA ABB--------------BBA -------------------- -------------------- -------------------- -------------------- ABB--------------BBA 
ABA--------------ABA A-A--------------A-A B-A--------------A-B A-A--------------A-A A-A--------------A-A B-A--------------A-B A-A--------------A-A A-A--------------A-A A--AAAAAAAAAAAAAAB-A A--BBBBBBBBBBBBBBB-A AAAAAAAAAAAAAAAAAAAA -------------------- ABB--------------BBA ABB--------------BBA -------------------- ABB--------------BBA ABB--------------BBA -------------------- -------------------- -------------------- -------------------- -------------------- -------------------- -------------------- -------------------- ABB--------------BBA 
ABA--------------ABA A-A--------------A-A A-A--------------A-A B-A--------------A-B B-A--------------A-B A-A--------------A-A A-A--------------A-A A-A--------------A-A A--AAAAAAAAAAAAAAB-A A--BBBBBBBBBBBBBBB-A A-BAAAAAAAAAAAAAAB-A ABB--------------BBA A-B--------------B-A A-B--------------B-A ABB--------------BBA A-B--------------B-A ABB--------------BBA -------------------- -------------------- -------------------- -------------------- -------------------- -------------------- -------------------- -------------------- ABB--------------BBA 
ABA--------------ABA ABA--------------ABA ABA--------------ABA BBA--------------ABB BBA--------------ABB ABA--------------ABA ABA--------------ABA ABA--------------ABA ABBAAAAAAAAAAAAAABBA ABBBBBBBBBBBBBBBBBBA ABBAAAAAAAAAAAAAABBA ABB--------------BBA ABB--------------BBA ABB--------------BBA ABB--------------BBA ABB--------------BBA ABB--------------BBA ABB--------------BBA ABB--------------BBA ABB--------------BBA ABB--------------BBA ABB--------------BBA ABB--------------BBA ABB--------------BBA ABB--------------BBA ABB--------------BBA 
-------------------- -------------------- -------------------- -------------------- -------------------- -------------------- -------------------- -------------------- -------------------- ---BBBBBBBBBBBBBB--- ---AAAAAAAAAAAAAA--- -------------------- -------------------- -------------------- -------------------- -------------------- -------------------- -------------------- -------------------- -------------------- -------------------- -------------------- -------------------- -------------------- -------------------- -------------------- 
