model
size = 5 24 14, scale = 0.05, origin = -y
material 
  colors = A:#111 B:#222 C:#612000 D:#E00 E:#0C0
voxels
----- ----- ----- --B-- --B-- --B-- --B-- --B-- --B-- --B-- ----- ----- ----- ----- ----- ----- ----- ----- ----- ----- ----- ----- ----- ----- 
----- ----- ----- --B-- ----- ----- --B-- --B-- --B-- ----- ----- ----- ----- ----- ----- ----- ----- ----- ----- BABAB ----- ----- ----- ----- 
--C-- --C-- --C-- --B-- ----- --B-- --B-- --B-- ----- ----- ----- ----- ----- ----- ----- ----- ----- ----- BAAAB ABABA ----- ----- ----- ----- 
--C-- ----- ----- -BBB- --B-- --B-- ----- ----- ----- ----- ----- ----- ----- ----- ----- ----- ----- BAAAB AAAAA BABAB ----- ----- ----- ----- 
--C-- ----- ----- BBBBB -BEB- --A-- --D-- --B-- --D-- --B-- --B-- --D-- --B-- --D-- --B-- --D-- --B-- AAAAA BAAAB ABABA ----- ----- ----- ----- 
-CCC- -CCC- -CCC- BBBBB -BCB- --A-- --D-- --D-- --B-- --D-- --D-- --B-- --D-- --B-- --D-- --B-- --D-- BAAAB AAAAA BAAAB AAAAA BABAB ABABA ----- 
--C-- --C-- -CCC- BBBBB -BBB- --A-- --D-- --D-- --B-- --D-- --D-- --B-- --D-- --B-- --D-- --B-- --D-- AAAAA BAAAB AAAAA BAAAB AAAAA BABAB ----- 
----- ----- ----- -BBB- --B-- --B-- ----- ----- ----- ----- ----- ----- ----- ----- ----- ----- ----- BAAAB AAAAA BAAAB AAAAA BAAAB ABABA ----- 
----- ----- ----- --B-- ----- --B-- --B-- --B-- ----- ----- ----- ----- ----- ----- ----- ----- ----- ----- BAAAB AAAAA BAAAB AAAAA BABAB ----- 
----- ----- ----- --B-- ----- ----- --B-- --B-- --B-- ----- ----- ----- ----- ----- ----- ----- ----- ----- ----- BABAB AAAAA BAAAB ABABA ----- 
----- ----- ----- --B-- --B-- --B-- --B-- --B-- --B-- --B-- ----- ----- ----- ----- ----- ----- ----- ----- ----- ABABA BAAAB AAAAA BABAB ----- 
----- ----- ----- ----- ----- ----- ----- ----- ----- ----- ----- ----- ----- ----- ----- ----- ----- ----- ----- BABAB AAAAA BAAAB AAAAA BABAB 
----- ----- ----- ----- ----- ----- ----- ----- ----- ----- ----- ----- ----- ----- ----- ----- ----- ----- ----- ABABA BAAAB AAAAA BAAAB AAAAA 
----- ----- ----- ----- ----- ----- ----- ----- ----- ----- ----- ----- ----- ----- ----- ----- ----- ----- ----- BABAB ABABA BAAAB ABABA BABAB 
