model
size = 25 30 19, scale = 0.05, origin = -y
material 
  colors = A:#E00 B:#FF0 C:#CF3 D:#EEE E:#080 F:#251505 G:#CF0 H:#AAAAB9 I:#BBB J:#960 K:#939 L:#CC6 M:#AAA N:#040 O:#888 P:#FCF
voxels
------DDDDDDD------------ ------DDDDDDD------------ ------DDDDDDD------------ ------DDDDDDD------------ ------DDDDDDD------------ ------DDDDDDD------------ ------DDDDDDD------------ ------DDDDDDD------------ ------DDDDDDD------------ ------DDDDDDD------------ ------DDDDDDD------------ ------DDDDDDD------------ ------DDDDDDD------------ ------DDDDDDD------------ ------DDDDDDD------------ ------DDDDDDD------------ ------DDDDDDD------------ ------DDDDDDD------------ ------DDDDDDD------------ ------DDDDDDD------------ ------DDDDDDD------------ ------DDDDDDD------------ ------DDDDDDD------------ ------DDDDDDD------------ ------DDDDDDD------------ ------------------------- ------------------------- ------------------------- ------M------------------ ------------------------- 
----DDDDDDDDDDD---------- ----DDA---AAADD---------- ----DDA---AAADD---------- ----DDA---AAADD---------- ----DDA---AAADD---------- ----DDA---AAADD---------- ----DDA---AAADD---------- ----DDA--AAAADD---------- ----DDB--BBBBDD---------- ----DDB--BBBBDD---------- ----DDB--BBBBDD---------- ----DDB-BBBBBDD---------- ----DDBBBBBBBDD---------- ----DDBBBBBBBDD---------- ----DDBBBBBBBDD---------- ----DDBBBBBBBDD---------- ----DDHCCCBBBDD---------- ----DDAAAAAAADD---------- ----DDHCCCCCHDD---------- ----DDHCCCCCHDD---------- ----DDHCCCCCHDD---------- ----DDHCCCCCHDD---------- ----DDHCCCCCHDD---------- ----DDFFFFFFFDD---------- ----DD-------DD---------- ------------------------- ------------------------- ------------------------- ------I------------------ ------I------------------ 
---EDDDDDDDDDDDA--------- ---EAA--------AA--------- ---EAAAAAAAAAAAA--------- ---EAAAAAAAAAAAA--------- ---EAAAAAAAAAAAA--------- ---EAAAAAAAAAAAA--------- ---EAAAAAAAAAAAA--------- ---EAAAAAAAAAAAA--------- ---EBBBBBBBBBBBA--------- ---EBBBBBBBBBBBA--------- ---EBBBBBBBBBBBA--------- ---EBBBBBBBBBBBA--------- ---EBBBBBBBBBBBA--------- ---EBBBBBBBBBBBA--------- ---EBBBBBBBBBBBA--------- ---EBBBBBBBBBBBA--------- ---EHCCCCCBBBBBA--------- ---EAAAAAAAAAAAA--------- ---EHCCCCCCCCCHA--------- ---EHCCCCCCCCCHA--------- ---EHCCCCCCCCCHA--------- ---EHCCCCCCCCCHA--------- ---EHCCCCCCCCCHA--------- ---EFFFFFFJFFFFA--------- ---E-----------A--------- ------------------------- ------------------------- ------------------------- ------------------------- ------II----------------- 
--EEDDDDDDDDDDDAA-------- --EAAAAAAAAAAAAAA-------- --EAAAAAAAAAAAAAA-------- --EAAAAAAAAAAAAAA-------- --EAAAAAAAAAAAAAA-------- --EAAAAAAAAAAAAAA-------- --EAAAAAAAAAAAAAA-------- --EAAAAAAAAAAAAAA-------- --EBBBBBBBBBBBBBA-------- --EBBB--------BBA-------- --EBBBBBBBBBBBBBA-------- --EBBBBBBBBBBBBBA-------- --EBBBBBBBBBBBBBA-------- --EBBBBBBB-BBBBBA-------- --EBBBBBBB-BBBBBA-------- --EBBBBBBB-BBBBBA-------- --EHCCCCCC-BBBBBA-------- --EAAAAAAA-AAAAAA-------- --EHCCCCCC-CCCCHA-------- --EHCCCCCC-CCCCHA-------- --EHCCCCCC-CCCCHA-------- --EHCCCCCC-CCCCHA-------- --EHCCCCCC-CCCCHA-------- --EFFFFJFJFFJJFFA-------- --E------L------A-------- ------------------------- ------------------------- ------------------------- ---I--------------------- -------I----------------- 
-EEEDDDDDDDDDDDAAA------- -EGAAAAAAAAAAAA-AA------- -EGAAAAAAAAAAAA-AA------- -EGAAAAAAAAAAAA-AA------- -EGAAAAAAAAAAAA-AA------- -EGAAAAAAAAAAAA-AA------- -EGAAAAAAAAAAAA-AA------- -EGAAAAAAAAAAAA-AA------- -EBBAAAAAABBBBB-BA------- -EBBAAAAAABBBBB-BA------- -EB-AAAAAABBBBB-BA------- -EB-AANNNNBBBBB-BA------- -EB-AACNCNBBBBB-BA------- -EB-AACCCCBBBBB-BA------- -EB-AACCCCBBBBB-BA------- -EBBAACCCCBBBBB-BA------- -EH-CCCCCCBBBBB-BA------- -EA-AAAAAAAAAAA-AA------- -EH-CCCCCCCCCCC-HA------- -EH-CCCCCCCCCCC-HA------- -EH-CCCCCCCCCCC-HA------- -EHBCCCCCCCCCCC-HA------- -EHBCCCCCCCCCCC-HA------- -EFFJFJFJFFJJJFFFA------- -E------L-L------A------- ------------------------- ------------------------- ------------------------- ---I--------------------- ---M---I----------------- 
-EEEDDDDDDDDDDDAAA------- -EGGCCAAAAAAAAAAAA------- -EGGCCAAAAAAAAAAAA------- -EGGCCAAAAAAAAAAAA------- -EGGCCAAAAAAAAAAAA------- -EGGCCAAAAAAAAAAAA------- -EGGCCAAAAAAAAAAAA------- -EGGCCAAAAAAAAAAAA------- -EBBAAAAAABBBBBBBA------- -EBBAAAAAABBBBBBBA------- -EBBAAAAAABBBBBBBA------- -EBBAAAANNBBBBBBBA------- -EBBAAAANNBBBBBBBA------- -EBBAACCCCBBBBBBBA------- -EBBAACCCCBBBBBBBA------- -EBBAACCCCBBBBBBBA------- -ECCCCCCCCBBBBBBBA------- -EAAAACCCAAAAAAAAA------- -ECCCCCCCCCCCCCCCA------- -ECCCCCCCCCCCCCCCA------- -ECCCCCCCCCCCCCCCA------- -ECCCCCCCCCCCCCCCA------- -ECCCCCCCCCCCCCCCA------- -EJFJJFJFFFJFFJJFA------- -E-----L-L-L-----A------- ------------------------- ------------------------- ------------------------- ------------------------- ---O--IM----------------- 
EEEEDDDDDDDDDDDAAAA------ EGGGCCAAAAAAAAAAAAA------ EGGGCCAAAAAAAAAAAAA------ EGGGCCAAAAAAAAAAAAA------ EGGGCCAAAAAAAAAAAAA------ EGGGCCAAAAAAAAAAAAA------ EGGGCCAAAAAAAAAAAAA------ EGGGCCAAAAAAAAAAAAA------ EBBBAAAAAABBBBBBBBA------ EBBBAAAAAABBBBBBBBA------ EBBBAAAAAABBBBBBBBA------ EBBBAAAAAABBBBBBBBA------ EBBBAAAAAABBBBBBBBA------ EBBBAACCCCBBBBBBBBA------ EBBBAACCCCBBBBBBBBA------ EBBBAACCCCBBBBBBBBA------ EHCCCCCCCCBBBBBBBBA------ EAAAAACCCAAAAAAAAAA------ EHCCCCCCCCCCCKKKCHA------ EHCCCCCCCCCCCKKKCHA------ EHCCCCCCCCCCCKKKCHA------ EHCCCCCCCCCCCKKKCHA------ EHCCCCCCCCCCCKKKCHA------ EFFFFFJJFFFFFJJFJFA------ E-----L-L-L-L-----A------ ------------------------- ---------III------------- --------MI-II------------ ----MMMMM---II----------- ---MM-MM-----I----------- 
EEEEDDDDDDDDDDDAAAA------ EAAAAAAAAAAAAAAAAAA------ EAAAAAAAAAAAAAAAAAA------ EAAAAAAAAAAAAAAAAAA------ EAAAAAAAAAAAAAAAAAA------ EAAAAAAAAAAAAAAAAAA------ E-GGGGAGCCCCGAGGGGGDDDDDD E-GGGGAGCCCCGAGGGGGDDDDDD E-BBAAAAAABBBBBBBBA-----D E-BBAAAAAABBBBBBBBA-----D E-BBAA--AABBBBBBBBA-----D E-BBAA------BBBBBBA-----D E-BBAA------B--BB-A-----D E-BBAACCCCBBBBBBB-A-----D E-BBAACCCCBBBBBBB-A-----D E-BBAACCCCBBBBBBB-A-----D E-CCCCCCCCBBBBBBB-A-----D E-AAAACCCCDDDKKKC-HDDDDDD E-CCCCCCCCCCCKKKC-HDDDDDD E-CCCCCCCCCCCKKKC-A------ E-CCCCCCCCCCCKKKC-A------ E-CCCCCCCCCCCKKKCCA------ E-CCCCCCCCCCCKKKCCA------ EFFFFFFFFJFFFJFJJFA------ E----L-L-L-L-L----A------ ------------------------- ---------III------------- ------------------------- ----MII------------------ ------------------------- 
EEEEDDDDDDDDDDDAAAA------ EAAAAAAAAAAAAAAAAAA------ EAAAAAAAAAAAAAAAAAA------ EAAAAAAAAAAAAAAAAAA------ EAAAAAAAAAAAAAAAAAA------ EAAAAAAAAAAAAAAAAAA------ E-GGGGAGCCCCGAGGGGADDDDDD E-GGGGAGCCCCGAGGGGADDDDDD E-BBAAAAAABBBBBBBBA-----D E-BBAAAAAABBBBBBBBA-----D E-BBAA--AABBBBBBBBA-----D E-BBAA------BBBBBBA-----D E-BBAA------B-BBB-A-----D E-BBAACCCCBBBBBBB-A-----D E-BBAACCCCBBBBBBB-A-----D E-BBAACCCCBBBBBBB-A-----D E-CCCCCCCCBBBBBBB-A-----D E-AAAACCCCDDDKKKC-HDDDDDD E-CCCCCCCCCCCKKKC-HDDDDDD E-CCCCCCCCCCCKKKC-A------ E-CCCCCCCCCCCKKKC-A------ E-CCCCCCCCCCCKKKCCA------ E-CCCCCCCCCCCKKKCCA------ EFFFFFFJFFFFFFFFFFA------ E---L-L-L-L-L-L---A------ ------------------------- ---------III------------- --------MI-II------------ ----MMMPM---II----------- ---MM-II-----I----------- 
EEEEDDDDDDDDDDDAAAA------ EAAAAAAAAAAAAAAAAAA------ EAAAAAAAAAAAAAAAAAA------ EAAAAAAAAAAAAAAAAAA------ EAAAAAAAAAAAAAAAAAA------ EAAAAAAAAAAAAAAAAAA------ E-GGGGGGACAAAAGGGGADDDDDD E-GGGGGGCCAAAAGGGGADDDDDD E-BBAAACCCBBBBBBBBA-----D E-BBAAACCCBBBBBBBBA-----D E-BBAAACCCBBBBBBBBA-----D E-BBAAACCCBBBBBBBBA-----D E-BBAAACCCBBBBBBB-A-----D E-BBAAACCCBBBBBBB-A-----D E-BBAAACCCBBBBBBB-A-----D E-BBAAACCCBBBBBBB-A-----D E-CCCCCCCCBBBBBBB-A-----D E-AAAACCCCDDDDCCC-HDDDDDD E-CCCCDDDDCCCCCCC-HDDDDDD E-CCCCDDDDCCGCCCC-A------ E-CCCCDDDDCCGCCCC-A------ E-CCCCDDDDCCGCCCCCA------ E-CCCCCCCCCCGGCCCCA------ EFJFFFFFFJJFFFFJFFA------ E--L-L-L-L-L-L-L--A------ ---------IIM------------- --------II-II------------ -------II--III----------- -----O-I----II----------- -------I----------------- 
EEEEDDDDDDDDDDDAAAA------ EAAAAAAAAAAAAAAAAAA------ EAAAAAAAAAAAAAAAAAA------ EAAAAAAAAAAAAAAAAAA------ EAAAAAAAAAAAAAAAAAA------ EAAAAAAAAAAAAAAAAAA------ E-GGGGGGACAAAAGGGGADDDDDD E-GGGGGGCCAAAAGGGGADDDDDD E-BBAAACCCBBBBBBBBA-----D E-BBAAACCCBBBBBBBBA-----D E-BBAAACCCBBBBBBBBA-----D E-BBAAACCCBBBBBBBBA-----D E-BBAAACCCBBBBBBB-A-----D E-BBAAACCCBBBBBBB-A-----D E-BBAAACCC-BBBBBB-A-----D E-BBAAACCCB---BBB-A-----D E-CCCCCCCCB-B-BBB-A-----D E-AAAACCCCC-C-CCC-HDDDDDD E-CCCCDDDDCCCCCCC-HDDDDDD E-CCCCDDDDCCGCCCC-A------ E-CCCCDDDDCCGCCCC-A------ E-CCCCDDDDCCGCCCCCA------ E-CCCCCCCCCCGGCCCCA------ EFFJJFFJFFFJFFFFFFA------ E---L-L-L-L-L-L---A------ ---------III------------- ------------------------- ------------------------- -----I------------------- ------------------------- 
EEEEDDDDDDDDDDDAAAA------ EAAAAAAAAAAAAAAAAAA------ EAAAAAAAAAAAAAAAAAA------ EAAAAAAAAAAAAAAAAAA------ EAAAAAAAAAAAAAAAAAA------ EAAAAAAAAAAAAAAAAAA------ E-GGGGGGACAAAAGGGAA------ E-GGGGGGCCAAAAGGGAA------ E-BBAAACCCBBBBBBBBA------ E-BBAAACCCBBBBBBBBA------ E-BBAAACCCBBBBBBBBA------ E-BBAAACCCBBBBBBBBA------ E-BBAAACCCBBBBBBB-A------ E-BBAAACCCBBBBBBB-A------ E-BBAAACCC-B-BBBB-A------ E-BBAAACCCB---BBB-A------ E-CCCCCCCCB-B-BBB-A------ E-AAAAAAAAA-A-AAA-A------ E-CCCCDDDDCCCCCCC-A------ E-CCCCDDDDCCGCCCC-A------ E-CCCCDDDDCCGCCCC-A------ E-CCCCDDDDCCGCCCCCA------ E-CCCCCCCCCCGGCCCCA------ EFFFJFFFJFFFFFFFFFA------ E----L-L-L-L-L----A------ ---------MMM------------- --------MM-II------------ -------MMI--MI----------- -------M-----M----------- ------------------------- 
EEEEDDDDDDDDDDDAAAA------ EAAAAAAAAAAAAAAAAAA------ EAAAAAAAAAAAAAAAAAA------ EAAAAAAAAAAAAA---AA------ EAAAAAAAAAAAAA---AA------ EAAAAAAAAAAAAA---AA------ EAAAAAGGACAAAA---AA------ EAAAAAGGCCAAAA---AA------ EBBBAAACCCBBBB---BA------ EBBBAAACCCBBBB---BA------ EBBBAAACCCBBBB---BA------ EBBBAAACCCBBBB---BA------ EBBBAAACCCBBBB---BA------ EBBBAAACCCBBBB---BA------ EBBBAAACCC-BBBBB-BA------ EBBBAAACCCB--BBBBBA------ EHCCCCCCCCB-BBBBBBA------ EAAAAAAAAAA-AAAAAAA------ EHCCCCDDDDCCCCCCCHA------ EHCCCCDDDDCCGCCCCHA------ EHCCCCDDDDCCGCCCCHA------ EHCCCCDDDDCCGCCCCHA------ EHCCCCCCCCCCGCCCCHA------ EFFFJFJFFFJFJFJFJFA------ E-----L-L-L-L-----A------ ----------O-------------- ----------I-------------- ------OMO---I------------ ------------------------- ------------------------- 
-EEEDDDDDDDDDDDAAA------- -EAAAAAAAAAAAAAAAA------- -EAAAAAAAAAAAAAAAA------- -EAAAAAAAAAAAA---A------- -EAAAAAAAAAAAA---A------- -EAAAAAAAAAAAA---A------- -EAAAAAAAAAAAA---A------- -EAAAAAAAAAAAA---A------- -EBBBBBBBBBBBB---A------- -EBBBBBBBBBBBB---A------- -EBBBBBBBBBBBB---A------- -EBBBBBBBBBBBB---A------- -EBBBBBBBBBBBB---A------- -EBBBBBBBBBBBB--BA------- -EBBBBBBBB-B-BB-BA------- -EBBBBBBBBB--BBBBA------- -ECCCCCCCCC-CCCCCA------- -EAAAAAAAAA-AAAA-A------- -ECCCCCCCCCCCCCCBA------- -ECCCCCCCCCCGCCCBA------- -ECCCCCCCCCCGCCCBA------- -ECCCCCCCCCCGCCCBA------- -ECCCCCCCCCCGCCCBA------- -EFFJJFFFFJJFFJFFA------- -E-----L-L-L-----A------- ------------------------- ----------OI------------- ------I----I------------- ------------------------- ------------------------- 
-EEEDDDDDDDDDDDAAA------- -EAAAAAAA-AAAAAAAA------- -EAAAAAAA-AAAAAAAA------- -EAAAAAAAAAAAAA-AA------- -EAAAAAAAAAA----AA------- -EAAAAAAAA------AA------- -EAAAAAAAA------AA------- -EAAAAAAAA------AA------- -EBBBBBBBB------BA------- -EBBBBBBBB------BA------- -EBBBBBBBB------BA------- -EBBBBBBBB------BA------- -EBBBBBBBB------BA------- -EBBBBBBBB------BA------- -EBBBBBBBBB-BBBBBA------- -EBBBBBBBBB--BBBBA------- -EHCCCCCCCC-CCCCHA------- -EAAAAAAAAA-AAAAAA------- -EHCCCCCCCCCCCCCHA------- -EHCCCCCCCCCGCCCHA------- -EHCCCCCCCCCGCCCHA------- -EHCCCCCCCCCGCCCHA------- -EHCCCCCCCCCGCCCHA------- -EFFFFJFFFFJFJFFFA------- -E------L-L------A------- ------------------------- ----------M-------------- ------------------------- ------------------------- ------------------------- 
--EEDDDDDDDDDDDAA-------- --EAAAAAAAAAAAAAA-------- --EAAAAAAAAAAAAAA-------- --EAAAAAAAAA--AAA-------- --EAAAAAAAA----AA-------- --EAAAAAAA-----AA-------- --EAAAAAAA-----AA-------- --EAAAAAAA-----AA-------- --EBBBBBBB-----BA-------- --EBBBBBBB-----BA-------- --EB--BBBB-----BA-------- --EB--BBBB-----BA-------- --EB--BBBB-----BA-------- --EB--BBBB-----BA-------- --EB--BBBBBBBBBBA-------- --EB--BBBB-B-BBBA-------- --EH--CCCC--CCCHA-------- --EA--AAAA--AAAAA-------- --EH--CCCC--CCCHA-------- --EH--CCCC--GCCHA-------- --EH--CCCC--GCCHA-------- --EH--CCCC--GCCHA-------- --EHCCCCCCCCGCCHA-------- --EFFFFFJFFFFFFFA-------- --E------L------A-------- ------------------------- ------------------------- ------------------------- ------------------------- ------------------------- 
---EDDDDDDDDDDDA--------- ---EAAAAAAAAAAAA--------- ---EAAAAAAAAAAAA--------- ---EA----AAA--AA--------- ---EA----AA---AA--------- ---EA---------AA--------- ---EA---------AA--------- ---EA---------AA--------- ---EB---------BA--------- ---EB---------BA--------- ---EB---------BA--------- ---EB---------BA--------- ---EB---------BA--------- ---EB---------BA--------- ---EB------BBBBA--------- ---EB------BBBBA--------- ---EB-------CCHA--------- ---EA-------AAAA--------- ---EH-------CCHA--------- ---EH--------CHA--------- ---EH--------CHA--------- ---EH--------CHA--------- ---EHCCCCCCCBCHA--------- ---EFFFFJFFJFFFA--------- ---E-----------A--------- ------------------------- ------------------------- ------------------------- ------------------------- ------------------------- 
----DDDDDDDDDDD---------- ----DDAAAAAAADD---------- ----DDAAAAAAADD---------- ----DDA---A-ADD---------- ----DDA-----ADD---------- ----DDA-----ADD---------- ----DDA-----ADD---------- ----DDA-----ADD---------- ----DDB-----BDD---------- ----DDB-----BDD---------- ----DDB-----BDD---------- ----DDB-----BDD---------- ----DDB-----BDD---------- ----DDB-----BDD---------- ----DDB-----BDD---------- ----DDB-----BDD---------- ----DDH-----HDD---------- ----DDA-----ADD---------- ----DDH-----HDD---------- ----DDH-----HDD---------- ----DDH-----HDD---------- ----DDH-----HDD---------- ----DDHCCCCCHDD---------- ----DDFFFFFFFDD---------- ----DD-------DD---------- ------------------------- ------------------------- ------------------------- ------------------------- ------------------------- 
------DDDDDDD------------ ------DDDDDDD------------ ------DDDDDDD------------ ------DDDDDDD------------ ------DDDDDDD------------ ------DDDDDDD------------ ------DDDDDDD------------ ------DDDDDDD------------ ------DDDDDDD------------ ------DDDDDDD------------ ------DDDDDDD------------ ------DDDDDDD------------ ------DDDDDDD------------ ------DDDDDDD------------ ------DDDDDDD------------ ------DDDDDDD------------ ------DDDDDDD------------ ------DDDDDDD------------ ------DDDDDDD------------ ------DDDDDDD------------ ------DDDDDDD------------ ------DDDDDDD------------ ------DDDDDDD------------ ------DDDDDDD------------ ------DDDDDDD------------ ------------------------- ------------------------- ------------------------- ------------------------- ------------------------- 
