model
size = 3 14 13, scale = 0.05, origin = -y
material 
  colors = A:#BBB B:#111
voxels
--- --- --- --- --- --- --- --- --B --- --- --- --- --- 
--- --- --- --- --- --- --B -BB --- --B --- --- --- --- 
--- --- --- --- --- --B --B --B --B --B --B --B --- --- 
--- --- --A --A --A -BA -BA --A --A --A -BA --B -BB --- 
--- --A -BA -BA --A --A --A -BA -BA --A --B --B --B --B 
--A --A --B --A --A -BA -BA -BA --A --A --B --B --B --- 
--A --A --B --A -BA --A --A --A --A --A --B --B --B --B 
--A --A --B --A --A --A --A --A --A --A -BA --B --B --- 
--A --A --B -BA --A -BA --A -BA -BA --A -BA -BB --B --- 
--- --A --A --A --A --A -BA -BA --A --A BBA --B --B --- 
--- --- --A --A --A -BA --A --A --A -BA BBA --B --- --- 
--- --- --- --- --- --- --- --B --B -BB --B --- --- --- 
--- --- --- --- --- --B --B --B --B --- --- --- --- --- 
