model
size = 25 30 19, scale = 0.05, origin = -y
material 
  colors = A:#E00 B:#FF0 C:#CF3 D:#080 E:#EEE F:#251505 G:#CF0 H:#AAAAB9 I:#777 J:#BBB K:#960 L:#939 M:#CC6 N:#AAA O:#040 P:#888 Q:#009 R:#FCF
voxels
------AAAAAAA------------ ------AAAAAAA------------ ------AAAAAAA------------ ------AAAAAAA------------ ------AAAAAAA------------ ------AAAAAAA------------ ------BAAAAAA------------ ------BBAAAAA------------ ------ABBBAAA------------ ------AABBAAA------------ ------AABBAAA------------ ------BBBBAAA------------ ------AABBAAA------------ ------AABBAAA------------ ------BABBAAA------------ ------ABBBAAA------------ ------ABBBAAA------------ ------BBAAAAA------------ ------BAAAAAA------------ ------AAAAAAA------------ ------AAAAAAA------------ ------AAAAAAA------------ ------AAAAAAA------------ ------AAAAAAA------------ ------AAAAAAA------------ ------------------------- ------------------------- ------------------------- ------N------------------ ------------------------- 
----AAAAAAAAAAA---------- ----AAA---AAAAA---------- ----AAA---AAAAA---------- ----BAA---AAAAA---------- ----BBA---AAAAA---------- ----BBA---AAAAA---------- ----BBA---AAAAA---------- ----AAA--AAAAAA---------- ----AAB--BBBBAA---------- ----BAB--BBBBAA---------- ----ABB--BBBBAA---------- ----AAB-BBBBBAA---------- ----BABBBBBBBAA---------- ----ABBBBBBBBAA---------- ----AABBBBBBBAA---------- ----BABBBBBBBAA---------- ----BAHCCCBBBAA---------- ----ABAAAAAAAAA---------- ----BBHCCCCCHAA---------- ----BBHCCCCCHAA---------- ----BAHCCCCCHAA---------- ----AAHCCCCCHAA---------- ----AAHCCCCCHAA---------- ----AAFFFFFFFAA---------- ----AA-------AA---------- ------------------------- ------------------------- ------------------------- ------J------------------ ------J------------------ 
---AAAAAAAAAAAAA--------- ---AAA--------AA--------- ---BAAAAAAAAAAAA--------- ---BAAAAAAAAAAAA--------- ---BAAAAAAAAAAAA--------- ---AAAAAAAAAAAAA--------- ---BBAAAAAAAAAAA--------- ---AAAAAAAAAAAAA--------- ---BBBBBBBBBBBBA--------- ---ABBBBBBBBBBBA--------- ---ABBBBBBBBBBBA--------- ---BBBBBBBBBBBBA--------- ---ABBBBBBBBBBBA--------- ---ABBBBBBBBBBBA--------- ---BBBBBBBBBBBBA--------- ---BBBBBBBBBBBBA--------- ---AHCCCCCBBBBBA--------- ---AAAAAAAAAAAAA--------- ---BHCCCCCCCCCHA--------- ---AHCCCCCCCCCHA--------- ---BHCCCCCCCCCHA--------- ---BHCCCCCCCCCHA--------- ---AHCCCCCCCCCHA--------- ---AFFFFFFKFFFFA--------- ---A-----------A--------- ------------------------- ------------------------- ------------------------- ------------------------- ------JJ----------------- 
--AAAAAAAAAAAAAAA-------- --BAAAAAAAAAAAAAA-------- --BAAAAAAAAAAAAAA-------- --BAAAAAAAAAAAAAA-------- --AAAAAAAAAAAAAAA-------- --AAAAAAAAAAAAAAA-------- --BBBAAAAAAAAAAAA-------- --AAAAAAAAAAAAAAA-------- --BBBBBBBBBBBBBBA-------- --ABBB--------BBA-------- --BBBBBBBBBBBBBBA-------- --ABBBBBBBBBBBBBA-------- --ABBBBBBBBBBBBBA-------- --BBBBBBBB-BBBBBA-------- --BBBBBBBB-BBBBBA-------- --ABBBBBBB-BBBBBA-------- --AHCCCCCC-BBBBBA-------- --BBAAAAAA-AAAAAA-------- --BBCCCCCC-CCCCHA-------- --AHCCCCCC-CCCCHA-------- --AHCCCCCC-CCCCHA-------- --BHCCCCCC-CCCCHA-------- --BHCCCCCC-CCCCHA-------- --AFFFFKFKFFKKFFA-------- --A------M------A-------- ------------------------- ------------------------- ------------------------- ---J--------------------- -------J----------------- 
-AAAAAAAAAAAAAAAAA------- -BGAAAAAAAAAAAA-AA------- -BGAAAAAAAAAAAA-AA------- -AGAAAAAAAAAAAA-AA------- -AGAAAAAAAAAAAA-AA------- -AGAAAAAAAAAAAA-AA------- -BBBBAAAAAAAAAA-AA------- -IGAAAAAAAAAAAA-AA------- -IBBAAAAAABBBBB-BA------- -IBBAAAAAABBBBB-BA------- -IB-AAAAAABBBBB-BA------- -IB-AAOOOOBBBBB-BA------- -IB-AACOCOBBBBB-BA------- -IB-AACCCCBBBBB-BA------- -IB-AACCCCBBBBB-BA------- -IBBAACCCCBBBBB-BA------- -IH-CCCCCCBBBBB-BA------- -IA-AAAAAAAAAAA-AA------- -IH-CCCCCCCCCCC-HA------- -AH-CCCCCCCCCCC-HA------- -AH-CCCCCCCCCCC-HA------- -AHBCCCCCCCCCCC-HA------- -BHBCCCCCCCCCCC-HA------- -BFFKFKFKFFKKKFFFA------- -A------M-M------A------- ------------------------- ------------------------- ------------------------- ---J--------------------- ---N---J----------------- 
-AAAAAAAAAAAAAAAAA------- -BGGCCAAAAAAAAAAAA------- -BGGCCAAAAAAAAAAAA------- -AGGCCAAAAAAAAAAAA------- -AGGCCAAAAAAAAAAAA------- -AGGCCAAAAAAAAAAAA------- -IGGCCAAAAAAAAAAAA------- -AGGCCAAAAAAAAAAAA------- -ABBAAAAAABBBBBBBA------- -ABBAAAAAABBBBBBBA------- -ABBAAAAAABBBBBBBA------- -ABBAAAAOOBBBBBBBA------- -BBBAAAAOOBBBBBBBA------- -ABBAACCCCBBBBBBBA------- -ABBAACCCCBBBBBBBA------- -ABBAACCCCBBBBBBBA------- -ACCCCCCCCBBBBBBBA------- -BAAAACCCAAAAAAAAA------- -ICCCCCCCCCCCCCCCA------- -ACCCCCCCCCCCCCCCA------- -ACCCCCCCCCCCCCCCA------- -ACCCCCCCCCCCCCCCA------- -BCCCCCCCCCCCCCCCA------- -BKFKKFKFFFKFFKKFA------- -A-----M-M-M-----A------- ------------------------- ------------------------- ------------------------- ------------------------- ---P--JN----------------- 
AAAAAAAAAAAAAAAAAAA------ BBGGCCAAAAAAAAAAAAA------ BBGGCCAAAAAAAAAAAAA------ AGGGCCAAAAAAAAAAAAA------ AGGGCCAAAAAAAAAAAAA------ IGGGCCAAAAAAAAAAAAA------ AGGGCCAAAAAAAAAAAAA------ BGGGCCAAAAAAAAAAAAA------ ABBBAAAAAABBBBBBBBA------ IBBBAAAAAABBBBBBBBA------ IBBBAAAAAABBBBBBBBA------ IBBBAAAAAABBBBBBBBA------ IBBBAAAAAABBBBBBBBA------ IBBBAACCCCBBBBBBBBA------ IBBBAACCCCBBBBBBBBA------ IBBBAACCCCBBBBBBBBA------ AHCCCCCCCCBBBBBBBBA------ AAAAAACCCAAAAAAAAAA------ IICCCCCCCCCCCLLLCHA------ AHCCCCCCCCCCCLLLCHA------ AHCCCCCCCCCCCLLLCHA------ AHCCCCCCCCCCCLLLCHA------ BBCCCCCCCCCCCLLLCHA------ BBFFFFKKFFFFFKKFKFA------ A-----M-M-M-M-----A------ ------------------------- ---------JJJ------------- --------NJ-JJ------------ ----NNNNN---JJ----------- ---NN-NN-----J----------- 
AAAAAAAAAAAAAAAAAAA------ BBAAAAAAAAAAAAAAAAA------ BBAAAAAAAAAAAAAAAAA------ AAAAAAAAAAAAAAAAAAA------ AAAAAAAAAAAAAAAAAAA------ IAAAAAAAAAAAAAAAAAA------ A-GGGGAGCCCCGAGGGGGEEEEEE A-GGGGAGCCCCGAGGGGGEEEEEE I-BBAAAAAABBBBBBBBA-----E E-BBAAAAAABBBBBBBBA-----E E-BBAA--AABBBBBBBBA-----E Q-BBAA------BBBBBBA-----E E-BBAA------B--BB-A-----E E-BBAACCCCBBBBBBB-A-----E E-BBAACCCCBBBBBBB-A-----E I-BBAACCCCBBBBBBB-A-----E A-CCCCCCCCBBBBBBB-A-----E A-AAAACCCCEEELLLC-HEEEEEE I-CCCCCCCCCCCLLLC-HEEEEEE A-CCCCCCCCCCCLLLC-A------ A-CCCCCCCCCCCLLLC-A------ A-CCCCCCCCCCCLLLCCA------ B-CCCCCCCCCCCLLLCCA------ BFFFFFFFFKFFFKFKKFA------ A----M-M-M-M-M----A------ ------------------------- ---------JJJ------------- ------------------------- ----NJJ------------------ ------------------------- 
AAAAAAAAAAAAAAAAAAA------ BBAAAAAAAAAAAAAAAAA------ BBAAAAAAAAAAAAAAAAA------ AAAAAAAAAAAAAAAAAAA------ AAAAAAAAAAAAAAAAAAA------ IAAAAAAAAAAAAAAAAAD------ A-GGGGAGCCCCGAGGGGAEEEEEE I-GGGGAGCCCCGAGGGGAEEEEEE E-BBAAAAAABBBBBBBBA-----E E-BBAAAAAABBBBBBBBA-----E E-BBAA--AABBBBBBBBA-----E E-BBAA------BBBBBBA-----E E-BBAA------B-BBB-A-----E E-BBAACCCCBBBBBBB-A-----E E-BBAACCCCBBBBBBB-A-----E I-BBAACCCCBBBBBBB-A-----E A-CCCCCCCCBBBBBBB-A-----E A-AAAACCCCEEELLLC-HEEEEEE I-CCCCCCCCCCCLLLC-HEEEEEE A-CCCCCCCCCCCLLLC-A------ A-CCCCCCCCCCCLLLC-A------ A-CCCCCCCCCCCLLLCCA------ B-CCCCCCCCCCCLLLCCA------ BFFFFFFKFFFFFFFFFFA------ A---M-M-M-M-M-M---A------ ------------------------- ---------JJJ------------- --------NJ-JJ------------ ----NNNRN---JJ----------- ---NN-JJ-----J----------- 
DDDDDDDDDDDDDDDDDDD------ BBAAAAAAAAAAAAAAAAD------ BBAAAAAAAAAAAAAAAAD------ BAAAAAAAAAAAAAAAAAD------ BAAAAAAAAAAAAAAAAAD------ IAAAAAAAAAAAAAAAAAD------ A-GGGGGGACAAAAGGGGAEEEEEE I-GGGGGGCCAAAAGGGGAEEEEEE E-BBAAACCCBBBBBBBBD-----E Q-BBAAACCCBBBBBBBBD-----E E-BBAAACCCBBBBBBBBD-----E Q-BBAAACCCBBBBBBBBD-----E E-BBAAACCCBBBBBBB-D-----E Q-BBAAACCCBBBBBBB-D-----E E-BBAAACCCBBBBBBB-D-----E I-BBAAACCCBBBBBBB-D-----E A-CCCCCCCCBBBBBBB-D-----E B-AAAACCCCEEEECCC-HEEEEEE I-CCCCEEEECCCCCCC-HEEEEEE B-CCCCEEEECCGCCCC-D------ B-CCCCEEEECCGCCCC-D------ B-CCCCEEEECCGCCCCCD------ B-CCCCCCCCCCGGCCCCD------ BFKFFFFFFKKFFFFKFFD------ D--M-M-M-M-M-M-M--D------ ---------JJN------------- --------JJ-JJ------------ -------JJ--JJJ----------- -----P-J----JJ----------- -------J----------------- 
DDDDDDDDDDDDDDDDDDD------ BBAAAAAAAAAAAAAAAAD------ BBAAAAAAAAAAAAAAAAD------ DAAAAAAAAAAAAAAAAAD------ DAAAAAAAAAAAAAAAAAD------ IAAAAAAAAAAAAAAAAAD------ A-GGGGGGACAAAAGGGGAEEEEEE I-GGGGGGCCAAAAGGGGAEEEEEE E-BBAAACCCBBBBBBBBD-----E E-BBAAACCCBBBBBBBBD-----E E-BBAAACCCBBBBBBBBD-----E E-BBAAACCCBBBBBBBBD-----E E-BBAAACCCBBBBBBB-D-----E E-BBAAACCCBBBBBBB-D-----E E-BBAAACCC-BBBBBB-D-----E I-BBAAACCCB---BBB-D-----E A-CCCCCCCCB-B-BBB-D-----E A-AAAACCCCC-C-CCC-HEEEEEE I-CCCCEEEECCCCCCC-HEEEEEE D-CCCCEEEECCGCCCC-D------ D-CCCCEEEECCGCCCC-D------ D-CCCCEEEECCGCCCCCD------ B-CCCCCCCCCCGGCCCCD------ BFFKKFFKFFFKFFFFFFD------ D---M-M-M-M-M-M---D------ ---------JJJ------------- ------------------------- ------------------------- -----J------------------- ------------------------- 
DDDDDDDDDDDDDDDDDDD------ BBAAAAAAAAAAAAAAAAD------ BBAAAAAAAAAAAAAAAAD------ DAAAAAAAAAAAAAAAAAD------ DAAAAAAAAAAAAAAAAAD------ IAAAAAAAAAAAAAAAAAD------ A-GGGGGGACAAAAGGGAD------ A-GGGGGGCCAAAAGGGAD------ I-BBAAACCCBBBBBBBBD------ E-BBAAACCCBBBBBBBBD------ E-BBAAACCCBBBBBBBBD------ Q-BBAAACCCBBBBBBBBD------ E-BBAAACCCBBBBBBB-D------ E-BBAAACCCBBBBBBB-D------ E-BBAAACCC-B-BBBB-D------ I-BBAAACCCB---BBB-D------ A-CCCCCCCCB-B-BBB-D------ A-AAAAAAAAA-A-AAA-D------ I-CCCCEEEECCCCCCC-D------ D-CCCCEEEECCGCCCC-D------ D-CCCCEEEECCGCCCC-D------ D-CCCCEEEECCGCCCCCD------ B-CCCCCCCCCCGGCCCCD------ BFFFKFFFKFFFFFFFFFD------ D----M-M-M-M-M----D------ ---------NNN------------- --------NN-JJ------------ -------NNJ--NJ----------- -------N-----N----------- ------------------------- 
DDDDDDDDDDDDDDDDDDD------ BBAAAAAAAAAAAAAAAAD------ BBAAAAAAAAAAAAAAAAD------ DAAAAAAAAAAAAA---AD------ DAAAAAAAAAAAAA---AD------ IAAAAAAAAAAAAA---AD------ AAAAAAGGACAAAA---AD------ BAAAAAGGCCAAAA---AD------ ABBBAAACCCBBBB---BD------ IBBBAAACCCBBBB---BD------ IBBBAAACCCBBBB---BD------ IBBBAAACCCBBBB---BD------ IBBBAAACCCBBBB---BD------ IBBBAAACCCBBBB---BD------ IBBBAAACCC-BBBBB-BD------ IBBBAAACCCB--BBBBBD------ AACCCCCCCCB-BBBBBBD------ AAAAAAAAAAA-AAAAAAD------ IICCCCEEEECCCCCCCHD------ DHCCCCEEEECCGCCCCHD------ DHCCCCEEEECCGCCCCHD------ DHCCCCEEEECCGCCCCHD------ BBCCCCCCCCCCGCCCCHD------ BFFFKFKFFFKFKFKFKFD------ D-----M-M-M-M-----D------ ----------P-------------- ----------J-------------- ------PNP---J------------ ------------------------- ------------------------- 
-DDDDDDDDDDDDDDDDD------- -BAAAAAAAAAAAAAAAD------- -BAAAAAAAAAAAAAAAD------- -DAAAAAAAAAAAA---D------- -DAAAAAAAAAAAA---D------- -DAAAAAAAAAAAA---D------- -IAAAAAAAAAAAA---D------- -AAAAAAAAAAAAA---D------- -ABBBBBBBBBBBB---D------- -ABBBBBBBBBBBB---D------- -ABBBBBBBBBBBB---D------- -ABBBBBBBBBBBB---D------- -BBBBBBBBBBBBB---D------- -ABBBBBBBBBBBB--BD------- -ABBBBBBBB-B-BB-BD------- -ABBBBBBBBB--BBBBD------- -ACCCCCCCCC-CCCCCD------- -BAAAAAAAAA-AAAA-D------- -ICCCCCCCCCCCCCCBD------- -DCCCCCCCCCCGCCCBD------- -DCCCCCCCCCCGCCCBD------- -DCCCCCCCCCCGCCCBD------- -BCCCCCCCCCCGCCCBD------- -BFFKKFFFFKKFFKFFD------- -D-----M-M-M-----D------- ------------------------- ----------PJ------------- ------J----J------------- ------------------------- ------------------------- 
-DDDDDDDDDDDDDDDDD------- -BAAAAAAA-AAAAAAAD------- -BAAAAAAA-AAAAAAAD------- -DAAAAAAAAAAAAA-AD------- -DAAAAAAAAAA----AD------- -DAAAAAAAA------AD------- -BBBBAAAAA------AD------- -IAAAAAAAA------AD------- -IBBBBBBBB------BD------- -IBBBBBBBB------BD------- -IBBBBBBBB------BD------- -IBBBBBBBB------BD------- -IBBBBBBBB------BD------- -IBBBBBBBB------BD------- -IBBBBBBBBB-BBBBBD------- -IBBBBBBBBB--BBBBD------- -IHCCCCCCCC-CCCCHD------- -IAAAAAAAAA-AAAAAD------- -IHCCCCCCCCCCCCCHD------- -DHCCCCCCCCCGCCCHD------- -DHCCCCCCCCCGCCCHD------- -DHCCCCCCCCCGCCCHD------- -BHCCCCCCCCCGCCCHD------- -BFFFFKFFFFKFKFFFD------- -D------M-M------D------- ------------------------- ----------N-------------- ------------------------- ------------------------- ------------------------- 
--DDDDDDDDDDDDDDD-------- --DAAAAAAAAAAAAAD-------- --BAAAAAAAAAAAAAD-------- --BAAAAAAAAA--AAD-------- --DAAAAAAAA----AD-------- --DAAAAAAA-----AD-------- --BBBAAAAA-----AD-------- --DAAAAAAA-----AD-------- --DBBBBBBB-----BD-------- --DBBBBBBB-----BD-------- --BB--BBBB-----BD-------- --BB--BBBB-----BD-------- --DB--BBBB-----BD-------- --DB--BBBB-----BD-------- --DB--BBBBBBBBBBD-------- --BB--BBBB-B-BBBD-------- --DH--CCCC--CCCHD-------- --BA--AAAA--AAAAD-------- --BH--CCCC--CCCHD-------- --DH--CCCC--GCCHD-------- --DH--CCCC--GCCHD-------- --BH--CCCC--GCCHD-------- --BHCCCCCCCCGCCHD-------- --DFFFFFKFFFFFFFD-------- --D------M------D-------- ------------------------- ------------------------- ------------------------- ------------------------- ------------------------- 
---DDDDDDDDDDDDD--------- ---DAAAAAAAAAAAD--------- ---DAAAAAAAAAAAD--------- ---BA----AAA--AD--------- ---BA----AA---AD--------- ---DA---------AD--------- ---BB---------AD--------- ---DA---------AD--------- ---DB---------BD--------- ---BB---------BD--------- ---BB---------BD--------- ---DB---------BD--------- ---DB---------BD--------- ---DB---------BD--------- ---BB------BBBBD--------- ---BB------BBBBD--------- ---DB-------CCHD--------- ---DA-------AAAD--------- ---BH-------CCHD--------- ---DH--------CHD--------- ---BH--------CHD--------- ---BH--------CHD--------- ---DHCCCCCCCBCHD--------- ---DFFFFKFFKFFFD--------- ---D-----------D--------- ------------------------- ------------------------- ------------------------- ------------------------- ------------------------- 
----DDDDDDDDDDD---------- ----DDAAAAAAADD---------- ----DDAAAAAAADD---------- ----DDA---A-ADD---------- ----BDA-----ADD---------- ----BBA-----ADD---------- ----BBA-----ADD---------- ----DBA-----ADD---------- ----BBB-----BDD---------- ----DDB-----BDD---------- ----DDB-----BDD---------- ----DDB-----BDD---------- ----DBB-----BDD---------- ----BBB-----BDD---------- ----BDB-----BDD---------- ----DDB-----BDD---------- ----DDH-----HDD---------- ----DDA-----ADD---------- ----BBH-----HDD---------- ----BBH-----HDD---------- ----BDH-----HDD---------- ----DDH-----HDD---------- ----DDHCCCCCHDD---------- ----DDFFFFFFFDD---------- ----DD-------DD---------- ------------------------- ------------------------- ------------------------- ------------------------- ------------------------- 
------DDDDDDD------------ ------DDDDDDD------------ ------DDDDDDD------------ ------DDDDDDD------------ ------DDDDDDD------------ ------DDDDDDD------------ ------DDDDDDD------------ ------BBDDDDD------------ ------BBBDDDD------------ ------DBBDDDD------------ ------DBBDDDD------------ ------BBBDDDD------------ ------BBBDDDD------------ ------DBBDDDD------------ ------DBBDDDD------------ ------DBBDDDD------------ ------DBBDDDD------------ ------BBBDDDD------------ ------BDDDDDD------------ ------DDDDDDD------------ ------DDDDDDD------------ ------DDDDDDD------------ ------DDDDDDD------------ ------DDDDDDD------------ ------DDDDDDD------------ ------------------------- ------------------------- ------------------------- ------------------------- ------------------------- 
