model
size = 25 30 19, scale = 0.05, origin = -y
material 
  colors = A:#FF0 B:#E00 C:#000 D:#CF3 E:#EEE F:#00C G:#251505 H:#BBB I:#CF0 J:#8F5F00 K:#CC6 L:#939 M:#1C0900 N:#AAA O:#AAAAB9 P:#00F Q:#888 R:#FCF
voxels
------AAAABBB------------ ------AAAABBB------------ ------AAAABBB------------ ------AAAABBB------------ ------AAAABBB------------ ------AAAABBB------------ ------AAAABBB------------ ------AAAABBB------------ ------AAAABBB------------ ------AAAABBB------------ ------AAAABBB------------ ------AAAABBB------------ ------AAAABBB------------ ------AAAABBB------------ ------AAAABBB------------ ------AAAABBB------------ ------AAAABBB------------ ------AAAABBB------------ ------AAAABBB------------ ------AAAABBB------------ ------AAAABBB------------ ------AAAABBB------------ ------AAAABBB------------ ------AAAABBB------------ ------AAAABBB------------ ------------------------- ------------------------- ------------------------- ------N------------------ ------------------------- 
----AAAAAABBBBB---------- ----AAA---AABBB---------- ----AAA---AABBB---------- ----AAA---AABBB---------- ----AAA---AABBB---------- ----AAA---AABBB---------- ----AAA---AABBB---------- ----AAA--AAABBB---------- ----AAA--BBBBBB---------- ----AAA--BBBBBB---------- ----AAA--BBBBBB---------- ----AAA-EBBBBBB---------- ----AAAEEBBBBBB---------- ----AAAEEBBBBBB---------- ----AAAEEBBBBBB---------- ----AAAEEBBBBBB---------- ----AAABBBBBBBB---------- ----AAACCCCCBBB---------- ----AAADDDDDBBB---------- ----AAADDDDDBBB---------- ----AAADDDDDBBB---------- ----AAADDDDDBBB---------- ----AAADDDDDBBB---------- ----AAGGGGGGMBB---------- ----AA-------BB---------- ------------------------- ------------------------- ------------------------- ------H------------------ ------H------------------ 
---AAAAAAABBBBBB--------- ---AAA--------EB--------- ---AAAAAAAAAAEEB--------- ---AAAAAAAAAAEEB--------- ---AAAAAAAAAAEEB--------- ---AAAAAAAAAAEEB--------- ---AAEAAAAAAAEEB--------- ---AAEAAAAAAEEEB--------- ---AAEBBBBBBEEEB--------- ---AAEBBBBBBEEEB--------- ---AAEBAAAAAEEEB--------- ---AAEBBBBBBEEEB--------- ---AAEBBBBBBEEEB--------- ---AAEBBBBBBEEEB--------- ---AAEBBBBBBEEEB--------- ---AAAAAAAAAEEEB--------- ---AADDDDDAAEEEB--------- ---AACCCCCCCCCCB--------- ---AADDDDDDDDBBB--------- ---AADDDDDDDDBBB--------- ---AADDDDDDDDBBB--------- ---AADDDDDDDDBBB--------- ---AADDDDDDDDDOB--------- ---AJGGGGGJMGGGB--------- ---A-----------B--------- ------------------------- ------------------------- ------------------------- ------------------------- ------HH----------------- 
--AAAAAAAABBBBBBB-------- --AAAAAAAAAAAEEEB-------- --AAAAAAAAAAAEEEB-------- --AAAAAAAAAAAEEEB-------- --AAAAAAAAAAAEEEB-------- --AAAAAAAAAAAEEEB-------- --AEEEAAAAAAAEEEB-------- --AEEEAAAAAAEEEEB-------- --AEEEAAAAAAEEEEB-------- --AEEE--------EEB-------- --AEEEBAAAAAEEEEB-------- --AEEEBBBBBBEEEEB-------- --AEEEBBBBBBEEEEB-------- --AEEEBBBB-BEEEEB-------- --AEEEBBBB-BEEEEB-------- --ABBAAAAA-AEEEEB-------- --ABBDDDDD-AEEEEB-------- --ACCCCCCC-CCCCCB-------- --AFFDDDDD-DDDDOB-------- --AFFDDDDD-DDDDOB-------- --AFFDDDDD-DDDDOB-------- --AFFDDDDD-DDDDOB-------- --AODDDDDD-DDDDEB-------- --AGGGGJGJGGMMGGB-------- --A------K------B-------- ------------------------- ------------------------- ------------------------- ---H--------------------- -------H----------------- 
-AAAAAAAAABBBBBBBB------- -AAAAAAAAAAAAEE-EB------- -AAAAAAAAAAAAEE-EB------- -AAAAAAAAAAAAEE-EB------- -AAAAAAAAAAAAEE-EB------- -AAAAAAAAAAAAEE-EB------- -AAEEEAAAAAAAEE-EB------- -AAEEEAAAAAAAEE-EB------- -AAEEEAAAAAAAEE-EB------- -AAEEEAAAAAAAEE-EB------- -AA-EEBBBBAABBB-BB------- -AA-EEBBBBBBBBB-BB------- -AA-EEBBBBBBBBB-BB------- -AA-EEBBBBBBBBB-BB------- -AA-EEBBBBBBBBB-BB------- -AABBBDDDDAABBB-BB------- -AA-BDDDDDAABBB-BB------- -AA-CCCCCCCCCCC-CB------- -AA-FDDDDDDDDDD-OB------- -AA-FDDDDDDDDDD-OB------- -AA-FDDDDDDDDDD-OB------- -AAFFDDDDDDDDDD-OB------- -AAADDDDDDDDDDD-EB------- -AJGJGJGJGGJMJGGGB------- -A------K-K------B------- ------------------------- ------------------------- ------------------------- ---H--------------------- ---N---H----------------- 
-CAAAAAAAABBBBBBBB------- -CAAAAAAAAAAAAPPPB------- -CAAAAAAAAAAAAPEEB------- -CAAAAAAAAAAAAPPPB------- -CAAAAAAAAAAAAAAAB------- -CAAAAAAAAAAAAAAAB------- -CAAAAAAAAAAAAAAAB------- -CAAAAAAAAAAAAAEEB------- -CBBAAAAAAAAAAEEEB------- -CBBAAAAAAAAAAEEEB------- -CBBBBBBBBAABBBBBB------- -CBBBBBBBBBBBBBBBB------- -CBBBBBBBBBBBBBBBB------- -CBBBBBBBBBBBBBBBB------- -CBBBBBBBBBBBBBBBB------- -CBBBBDDDDAABBBBBB------- -CBBBDDDDDAABBBBBB------- -CCCCCCDDBBBBBBBBB------- -CEFFDDDDDDDDDDDDB------- -CEFFDDDDDDDDDDDDB------- -CEFFDDDDDDDDDDDDB------- -CEFFDDDDDDDDDDDDB------- -CDDDDDDDDDDDDDEEB------- -CMJJJGJGGGJGGJJGB------- -C-----K-K-K-----B------- ------------------------- ------------------------- ------------------------- ------------------------- ---Q--HN----------------- 
CCCCCCCCCCCCCCCCCCC------ CAAAAAAAAAAAAAAAAEC------ CAAAAAAAAAAAAAAAAEC------ CAAAAAAAAAAAAAAAAEC------ CAAAAAAAAAAAAAAAAEC------ CAAAAAAAAAAAAAAAAEC------ CAAAAAAAAAAAAAAAAEC------ CAAAAAAAAAAAAAAAAEC------ CBBBAAAAAAAAAABBBEC------ CBBBAAAAAAAAAABBBEC------ CBBBBBBBBBAABBBBBEC------ CBBBBBBBBBBBBBBBBEC------ CBBBBBBBBBBBBBBBBEC------ CBBBBBBBBBBBBBBBBEC------ CBBBBBBBBBBBBBBBBEC------ CBBBBBDDDDAAAAAAAEC------ CBBBBDDDDDAAAAAAAEC------ CCCCCCCDDBBBBBBBBEC------ CFFFFDDDDDDDDLLLDEC------ CFFFFDDDDDDDDLLLDOC------ CFFFFDDDDDDDDLLLDOC------ CFFFFDDDDDDDDLLLDOC------ CODDDDDDDDDDDLLEEEC------ CGJGGGJJGGGGGJMGGMC------ C-----K-K-K-K-----C------ ------------------------- ---------HHH------------- --------NH-HH------------ ----NNNNN---HH----------- ---NN-NN-----H----------- 
CCCCCCCCCCCCCCCCCCC------ CAAAAAABBBBBBBBEEEC------ CAAAAAABBBBBBBBEEEC------ CAAAAAABBBBBBBBEEEC------ CAAAAAABBBBBBBBEEEC------ CAAAAAABBBBBBBBEEEC------ C-AAAAAIDDDDIBIEEEECBBBBB C-AAAAAAAAAAAAAAAEECBBBBB C-BBAABAAAAAAABBBEC-----B C-BBAABAAAAAAABBBEC-----B C-BBBB--BBAABBBBBEC-----B C-BBBB------BBBBBEC-----B C-BBBB------B--BB-C-----B C-BBBBBBBBBBBBBBB-C-----B C-BBBBBBBBBBBBBBB-C-----B C-BBBBDDDDAAAAAAA-C-----B C-BBBDDDDDAAAAAAA-C-----B C-CCCCCDDDEEELLLD-ECBBBBB C-FFFDDDDDDDDLLLD-ECBBBBB C-FFFDDDDDDDDLLLD-C------ C-FFFDDDDDDDDLLLD-C------ C-FFFDDDDDDDDLLLDDC------ C-DDDDDDDDDDDLLEEEC------ CMMGGGGGGJGGGJGJMGC------ C----K-K-K-K-K----C------ ------------------------- ---------HHH------------- ------------------------- ----NHH------------------ ------------------------- 
CCCCCCCCCCCCCCCCCCC------ CAAAAAABBCCCCCCCCCC------ CAAAAAABBCCCCCCCCCC------ CAAAAAABBCCCCCCCCCC------ CAAAAAABBCCCCCCCCCC------ CAAAAAABBCCCCCCCCCC------ C-AAAAAIDDDDIBIIIEECAAAAA C-AAAAAAAAAAAAAAAEECAAAAA C-BBAABAAAAAAABBBEC-----A C-BBAABAAAAAAABBBEC-----A C-BBBB--BBAABBBBBEC-----A C-BBBB------BBBBBEC-----A C-BBBB------B-BBB-C-----A C-BBBBBBBBBBBBBBB-C-----A C-BBBBBBBBBBBBBBB-C-----A C-BBBBBDDDAAAAAAA-C-----A C-BBBBBDDDAAAAAAA-C-----A C-CCCCCDDDEEELLLD-ECAAAAA C-FFFDDDDDDDDLLLD-ECAAAAA C-FFFDDDDDDDDLLLD-C------ C-FFFDDDDDDDDLLLD-C------ C-FFFDDDDDDDDLLLDDC------ C-DDDDDDDDDDDLLEEEC------ CGGGGGGJGGGGGGGGGMC------ C---K-K-K-K-K-K---C------ ------------------------- ---------HHH------------- --------NH-HH------------ ----NNNRN---HH----------- ---NN-HH-----H----------- 
CCCCCCCCCCCCCCCCCCC------ CAAAAAABBCCCCCCCCCC------ CAAAAAABBCCCCCCCCCC------ CAAAAAABBCCCCCCCCCC------ CAAAAAABBCCCCCCCCCC------ CAAAAAABBCCCCCCCCCC------ C-AAAAAIBDBBBBIIIEECCCCCC C-AAAAAIDDBBBBIIIEECCCCCC C-BBAABDDDAAAABBBEC-----C C-BBAABDDDAAAABBBEC-----C C-BBBBBDDDAABBBBBEC-----C C-BBBBBDDDAABBBBBEC-----C C-BBBBBBBBBBBBBBB-C-----C C-BBBBBBBBBBBBBBB-C-----C C-BBBBBBBBBBBBBBB-C-----C C-BBBBBDDDAAAAAAA-C-----C C-BBBBBDDDAAAAAAA-C-----C C-CCCCCDDDEEEEDDD-ECCCCCC C-FFFDEEEEDDDDDDD-ECCCCCC C-FFFDEEEEDDIDDDD-C------ C-FFFDEEEEDDIDDDD-C------ C-FFFDEEEEDDIDDDDDC------ C-DDDDDDDDDDIIDEEEC------ CGJGGGGGGJJGGGGJMMC------ C--K-K-K-K-K-K-K--C------ ---------HHN------------- --------HH-HH------------ -------HH--HHH----------- -----Q-H----HH----------- -------H----------------- 
CCCCCCCCCCCCCCCCCCC------ CAAAAAABBBBBBBBEEEC------ CAAAAAABBBBBBBBEEEC------ CAAAAAABBBBBBBBEEEC------ CAAAAAABBBBBBBBEEEC------ CAAAAAABBBBBBBBEEEC------ C-AAAAAIBDBBBBIIIIECAAAAA C-AAAAAIDDBBBBIIIIECAAAAA C-BBAABDDDAAAABBBBC-----A C-BBAABDDDAAAABBBBC-----A C-BBBBBDDDAABBBBBBC-----A C-BBBBBDDDAABBBBBBC-----A C-BBBBBBBBBBBBBBB-C-----A C-BBBBBBBBBBBBBBB-C-----A C-BBBBBBBB-BBBBBB-C-----A C-BBBBBDDDA---AAA-C-----A C-BBBBBDDDA-A-AAA-C-----A C-CCCCCDDDD-D-DDD-BCAAAAA C-FFFDEEEEDDDDDDD-ECAAAAA C-FFFDEEEEDDIDDDD-C------ C-FFFDEEEEDDIDDDD-C------ C-FFFDEEEEDDIDDDDDC------ C-DDDDDDDDDDIIDEEEC------ CGGJJGGJGGGJGGGGGMC------ C---K-K-K-K-K-K---C------ ---------HHH------------- ------------------------- ------------------------- -----H------------------- ------------------------- 
CCCCCCCCCCCCCCCCCCC------ CAAAAAAAAAAAAAAAAAC------ CAAAAAAAAAAAAAAAAAC------ CAAAAAAAAAAAAAAAAAC------ CAAAAAAAAAAAAAAAAAC------ CAAAAAAAAAAAAAAAAAC------ C-AAAAAAAAAAAAAAAAECBBBBB C-AAAAAAAAAAAAAAAAECBBBBB C-BBAABDDDAAAABBBBC-----B C-BBAABDDDAAAABBBBC-----B C-BBBBBDDDAABBBBBBC-----B C-BBBBBDDDAABBBBBBC-----B C-BBBBBBBBBBBBBBB-C-----B C-BBBBBBBBBBBBBBB-C-----B C-BBBBBBBB-B-BBBB-C-----B C-BBBBBDDDA---BBB-C-----B C-BBBBBDDDA-A-BBB-C-----B C-CCCCCCCCC-C-CCC-BCBBBBB C-FFFDEEEEDDDCCCC-ECBBBBB C-FFFDEEEEDDICCCC-C------ C-FFFDEEEEDDICCCC-C------ C-FFFDEEEEDDICCCCCC------ C-DDDDDDDDDDICCCCCC------ CJMGJGGGJGGGGGGGJMC------ C----K-K-K-K-K----C------ ---------NNN------------- --------NN-HH------------ -------NNH--NH----------- -------N-----N----------- ------------------------- 
CCCCCCCCCCCCCCCCCCC------ CCAAAAAAAAAAAAAAABC------ CCAAAAAAAAAAAAAAABC------ CCAAAAAAAAAAAA---BC------ CCAAAAAAAAAAAA---BC------ CCAAAAAAAAAAAA---BC------ CCAAAAAAAAAAAA---BC------ CCAAAAAAAAAAAA---BC------ CCBBBBBBBBBBBB---BC------ CCBBBBBBBBBBBB---BC------ CCBBBBBDDDAABB---BC------ CCBBBBBDDDAABB---BC------ CCBBBBBBBBBBBB---BC------ CCBBBBBBBBBBBB---BC------ CCBBBBBBBB-BBBBB-BC------ CCBBBBBDDDA--BBBBBC------ CCBBBBBDDDA-ABBBBBC------ CCCCCCCCCCC-CCCCCBC------ CCFFFFEEEEDDDCCCCBC------ CCFFFFEEEEDDICCCCBC------ CCFFFFEEEEDDICCCCBC------ CCFFFFEEEEDDICCCCBC------ CCDDDDDDDDDDICCCCBC------ CJMMJGJGGGJGJMJGGBC------ C-----K-K-K-K-----C------ ----------Q-------------- ----------H-------------- ------QNQ---H------------ ------------------------- ------------------------- 
-CAAAAAAAABBBBBBBB------- -CAAAAAAAAAAAAAAAB------- -CAAAAAAAAAAAAAAAB------- -CAAAAAAAAAAAA---B------- -CAAAAAAAAAAAA---B------- -CAAAAAAAAAAAA---B------- -CAAAAAAAAAAAA---B------- -CAAAAAAAAAAAA---B------- -CBBBBBBBBBBBB---B------- -CBBBBBBBBBBBB---B------- -CBBBBBAAAAABB---B------- -CBBBBBAAAAABB---B------- -CBBBBBAAAABBB---B------- -CBBBBBAAAABBB--BB------- -CBBBBBAAA-B-BB-BB------- -CBBBBBAAAA--BBBBB------- -CBBBBBDDDD-DBBBBB------- -CCCCCCCCCC-CCCC-B------- -CFFFFDDDDDDDCCCCB------- -CFFFFDDDDDDICCCCB------- -CFFFFDDDDDDICCCCB------- -CFFFFDDDDDDICCCCB------- -CDDDDDDDDDDICCCCB------- -CGGJJGGGGJJGMGGMB------- -C-----K-K-K-----B------- ------------------------- ----------QH------------- ------H----H------------- ------------------------- ------------------------- 
-AAAAAAAAABBBBBBBB------- -AEEEEEAA-AAAAAAAB------- -AEEEEEAA-AAAAAAAB------- -AEEEEEAAAAAAAA-AB------- -AEEEEEAAAAA----AB------- -AEEEEEAAA------AB------- -AEEEEEAAA------AB------- -AEEEEEAAA------AB------- -AEEEEEBBB------BB------- -AEEEEEBBB------BB------- -AEEEEEAAA------BB------- -AEEEEEAAA------BB------- -AEEEEEAAA------BB------- -AEEEEEAAA------BB------- -AEEEEEAAAA-BBBBBB------- -AEEEEEAAAA--BBBBB------- -AEEEEEDDDD-DBBBBB------- -AEEEEECCCC-CCCCCB------- -AFFFFDDDDDDDCCCCB------- -AFFFFDDDDDDICCCCB------- -AFFFFDDDDDDICCCCB------- -AFFFFDDDDDDICCCCB------- -AODDDDDDDDDICCCCB------- -AGMMMJGGGGJGMGMMB------- -A------K-K------B------- ------------------------- ----------N-------------- ------------------------- ------------------------- ------------------------- 
--AAAAAAAABBBBBBB-------- --AEEEEAAAAAAAAAB-------- --AEEEEAAAAAAAAAB-------- --AEEEEAAAAA--AAB-------- --AEEEEAAAA----AB-------- --AEEEEAAA-----EB-------- --AEEEEAAA-----EB-------- --AEEEEAAA-----EB-------- --AEEEEBBB-----EB-------- --AEEEEBBB-----EB-------- --AE--EAAA-----EB-------- --AE--EAAA-----EB-------- --AE--EAAA-----EB-------- --AE--EAAA-----EB-------- --AE--EAAAAEEEEEB-------- --AE--EAAA-A-BBBB-------- --AE--EDDD--DBBBB-------- --AE--ECCC--CCCCB-------- --AF--DDDD--DCCCB-------- --AF--DDDD--ICCCB-------- --AF--DDDD--ICCCB-------- --AF--DDDD--ICCCB-------- --AODDDDDDDDICCCB-------- --AJGGGGJGGMMGMMB-------- --A------K------B-------- ------------------------- ------------------------- ------------------------- ------------------------- ------------------------- 
---AAAAAAABBBBBB--------- ---AEEEAAAAAAAAB--------- ---AEEEAAAAAAAAB--------- ---AE----AAA--AB--------- ---AE----AA---AB--------- ---AE---------EB--------- ---AE---------EB--------- ---AE---------EB--------- ---AE---------EB--------- ---AE---------EB--------- ---AE---------EB--------- ---AE---------EB--------- ---AE---------EB--------- ---AE---------EB--------- ---AE------EEEEB--------- ---AE------AABBB--------- ---AE-------DBBB--------- ---AE-------CCCB--------- ---AF-------DCCB--------- ---AF--------CCB--------- ---AF--------CCB--------- ---AF--------CCB--------- ---AODDDDDDDACCB--------- ---AGJGMJMMJGGMB--------- ---A-----------B--------- ------------------------- ------------------------- ------------------------- ------------------------- ------------------------- 
----AAAAAABBBBB---------- ----AAAAAAAABBB---------- ----AAAAAAAABBB---------- ----AAA---A-BBB---------- ----AAA-----BBB---------- ----AAA-----BBB---------- ----AAA-----BBB---------- ----AAA-----BBB---------- ----AAA-----BBB---------- ----AAA-----BBB---------- ----AAA-----BBB---------- ----AAA-----BBB---------- ----AAA-----BBB---------- ----AAA-----BBB---------- ----AAA-----BBB---------- ----AAA-----BBB---------- ----AAA-----BBB---------- ----AAA-----BBB---------- ----AAO-----BBB---------- ----AAO-----BBB---------- ----AAO-----BBB---------- ----AAO-----BBB---------- ----AAODDDDDBBB---------- ----AAGGGMMGMBB---------- ----AA-------BB---------- ------------------------- ------------------------- ------------------------- ------------------------- ------------------------- 
------AAAABBB------------ ------AAAABBB------------ ------AAAABBB------------ ------AAAABBB------------ ------AAAABBB------------ ------AAAABBB------------ ------AAAABBB------------ ------AAAABBB------------ ------AAAABBB------------ ------AAAABBB------------ ------AAAABBB------------ ------AAAABBB------------ ------AAAABBB------------ ------AAAABBB------------ ------AAAABBB------------ ------AAAABBB------------ ------AAAABBB------------ ------AAAABBB------------ ------AAAABBB------------ ------AAAABBB------------ ------AAAABBB------------ ------AAAABBB------------ ------AAAABBB------------ ------AAAABBB------------ ------AAAABBB------------ ------------------------- ------------------------- ------------------------- ------------------------- ------------------------- 
