model
size = 25 30 19, scale = 0.05, origin = -y
material 
  colors = A:#E00 B:#00C C:#FF0 D:#CF3 E:#EEE F:#251505 G:#000 H:#BBB I:#CF0 J:#CC6 K:#939 L:#960 M:#AAAAB9 N:#1C0900 O:#AAA P:#888 Q:#FCF
voxels
------BBBBBBB------------ ------BBBBBBB------------ ------BBBBBBB------------ ------BBBBBBB------------ ------BBBBBBB------------ ------BBBBBBB------------ ------BBBBBBB------------ ------BBBBBBB------------ ------EEEEEEE------------ ------EEEEEEE------------ ------EEEEEEE------------ ------EEEEEEE------------ ------EEEEEEE------------ ------EEEEEEE------------ ------EEEEEEE------------ ------EEEEEEE------------ ------EEEEEEE------------ ------AAAAAAA------------ ------AAAAAAA------------ ------AAAAAAA------------ ------AAAAAAA------------ ------AAAAAAA------------ ------AAAAAAA------------ ------AAAAAAA------------ ------AAAAAAA------------ ------------------------- ------------------------- ------------------------- ------O------------------ ------------------------- 
----BBBBBBBBBBB---------- ----BBB---BBBBB---------- ----BBB---BBBBB---------- ----BBB---BBBBB---------- ----BBB---BBBBB---------- ----BBB---BBBBB---------- ----BBB---BBBBB---------- ----BBB--BBBBBB---------- ----EEA--AAAAEE---------- ----EEA--AAAAEE---------- ----EEA--AAAAEE---------- ----EEA-AAAAAEE---------- ----EEAAAAAAAEE---------- ----EEAAAAAAAEE---------- ----EEAAAAAAAEE---------- ----EEAAAAAAAEE---------- ----EEAAAAAAAEE---------- ----AAAGGGGGGAA---------- ----AAMDDDDDMAA---------- ----AAMDDDDDMAA---------- ----AAMDDDDDMAA---------- ----AAMDDDDDMAA---------- ----AAMDDDDDMAA---------- ----AAFFFFFFFAA---------- ----AA-------AA---------- ------------------------- ------------------------- ------------------------- ------H------------------ ------H------------------ 
---BBBBBBBBBBBBB--------- ---BBC--------BB--------- ---BBCCCCCBBBBBB--------- ---BBCCCCCBBBBBB--------- ---BBCCCCCBBBBBB--------- ---BBCCCCCBBBBBB--------- ---BBCCCCCBBBBBB--------- ---BBCCCCCBBBBBB--------- ---EAAAAAAAAAEEE--------- ---EAAAAAAAAAEEE--------- ---EAAACCCCCAAAE--------- ---EAAAAAAAAAAAE--------- ---EAAAAAAAAAAAE--------- ---EAAAAAAAAAAAE--------- ---EAAAAAAAAAAAE--------- ---EACCCCCCCAAAE--------- ---EADDDDDCCAAAE--------- ---AAAAGGGGGGAAA--------- ---AADDDDDDDDAAA--------- ---AADDDDDDDDAAA--------- ---ABDDDDDDDDAAA--------- ---ABDDDDDDDDAAA--------- ---AMDDDDDDDDDMA--------- ---AFFFFFFLNFFFA--------- ---A-----------A--------- ------------------------- ------------------------- ------------------------- ------------------------- ------HH----------------- 
--BBBBBBBBBBBBBBB-------- --BBBCCCCCBBBBBBB-------- --BBBCCCCCBBBBBBB-------- --BBBCCCCCBBBBBBB-------- --BBBCCCCCBBBBBBB-------- --BBBCCCCCBBBBBBB-------- --BBBCCCCCBBBBBBB-------- --BBBCCCCCBBBBBBB-------- --EACCCCCCCCCEEEE-------- --EACC--------EEE-------- --EAAAACCCCCAAAAE-------- --EAACAAAAAAAAAAE-------- --EAAAAAAAAAAAAAE-------- --EAAAAAAA-AAAAAE-------- --EAAAAAAA-AAAAAE-------- --EAACCCCC-CAAAAE-------- --EAADDDDD-CAAAAE-------- --AAAAAGGG-GGAAAA-------- --AAADDDDD-DDAAAA-------- --AAADDDDD-DDDDMA-------- --ABBDDDDD-DDDDMA-------- --ABBDDDDD-DDDDMA-------- --AMDDDDDD-DDDDEA-------- --AFFFFLFLFFNNFFA-------- --A------J------A-------- ------------------------- ------------------------- ------------------------- ---H--------------------- -------H----------------- 
-BBBBBBBBBBBBBBBBB------- -BBBBCCCCCBBBBB-BB------- -BBBBCCCCCBBBBB-BB------- -BBBBCCCCCBBBBB-BB------- -BBBBCCCCCBBBBB-BB------- -BBBBCCCCCBBBBB-BB------- -BBBBCCCCCBBBBB-BB------- -BBBBCCCCCBBBBB-BB------- -EAACCCCCCCCCEE-EE------- -EAACCCCCCCCCEE-EE------- -EA-AAAAAACCAAA-AE------- -EA-AAAAAAAAAAA-AE------- -EA-AAAAAAAAAAA-AE------- -EA-AAAAAAAAAAA-AE------- -EA-AAAAAAAAAAA-AE------- -EAAAADDDDCCAAA-AE------- -EA-ADDDDDCCAAA-AE------- -AA-AAAGGGGGGAA-AA------- -AA-ADDDDDDDDAA-AA------- -AA-ADDDDDDDDDD-MA------- -AE-BDDDDDDDDDD-MA------- -AEBBDDDDDDDDDD-MA------- -AMCDDDDDDDDDDD-EA------- -AFFLFLFLFFLNLFFFA------- -A------J-J------A------- ------------------------- ------------------------- ------------------------- ---H--------------------- ---O---H----------------- 
-BBBBBBBBBBBBBBBBB------- -BBBBCCCCCBBBBBBBB------- -BBBBCCCCCBBBBBBBB------- -BBBBCCCCCBBBBBBBB------- -BBBBCCCCCBBBBBBBB------- -BBBBCCCCCBBBBBBBB------- -BBBBCCCCCBBBBBBBB------- -BBBBCCCCCBBBBBBBB------- -EAACCCCCCCCCCEEEE------- -EAACCCCCCCCCCEEEE------- -EAAAAAAAACCAAAAAE------- -EAAAAAAAAAAAAAAAE------- -EAAAAAAAAAAAAAAAE------- -EAAAAAAAAAAAAAAAE------- -EAAAAAAAAAAAAAAAE------- -EAAAADDDDCCAAAAAE------- -EAAADDDDDCCAAAAAE------- -AAAAAADDAAAAAAAAA------- -AEBBDDDDDDDDDDDDA------- -AEBBDDDDDDDDDDDDA------- -AEBBDDDDDDDDDDDDA------- -AEBBDDDDDDDDDDDDA------- -ADDDDDDDDDDDDDEEA------- -ALFLLFLFFFLFFLLFA------- -A-----J-J-J-----A------- ------------------------- ------------------------- ------------------------- ------------------------- ---P--HO----------------- 
BBBBBBBBBBBBBBBBBBB------ BBCCCCCCCCCCCCCCCEB------ BBCCCCCCCCCCCCCCCEB------ BBCCCCCCCCCCCCCCCEB------ BBCCCCCCCCCCCCCCCEB------ BBCCCCCCCCCCCCCCCEB------ BBCCCCCCCCBBBBBBBBB------ BBCCCCCCCCBBBBBBBBB------ EAAACCCCCCCCCCAAAAE------ EAAACCCCCCCCCCAAAAE------ EAAAAAAAAACCAAAAAAE------ EAAAAAAAAAAAAAAAAAE------ EAAAAAAAAAAAAAAAAAE------ EAAAAAAAAAAAAAAAAAE------ EAAAAAAAAAAAAAAAAAE------ EAAAAADDDDCCCCCCCCE------ EAAAADDDDDCCCCCCCCE------ AAAAAAADDAAAAAAAAGA------ AAAAAAADDDDDDKKKDMA------ ABBBBDDDDDDDDKKKDMA------ ABBBBDDDDDDDDKKKDMA------ ABBBBDDDDDDDDKKKDMA------ AMDDDDDDDDDDDKKEEEA------ AFFFFFLLFFFFFLNFFNA------ A-----J-J-J-J-----A------ ------------------------- ---------HHH------------- --------OH-HH------------ ----OOOOO---HH----------- ---OO-OO-----H----------- 
BBBBBBBBBBBBBBBBBBB------ BBCCCCCAAAAAAAAEEEB------ BBCCCCCAAAAAAAAEEEB------ BBCCCCCAAAAAAAAEEEB------ BBCCCCCAAAAAAAAEEEB------ BBCCCCCAAAAAAAAEEEB------ B-CCCCCIDDDDIAIEEEABBBBBB B-CCCCCCCCCCCCCCCCABBBBBB E-AACCACCCCCCCAAAAE-----E E-AACCACCCCCCCAAAAE-----E E-AAAA--AACCAAAAAAE-----E E-AAAA------AAAAAAE-----E E-AAAA------A--AA-E-----E E-AAAAAAAAAAAAAAA-E-----E E-AAAAAAAAAAAAAAA-E-----E E-AAAADDDDCCCCCCC-E-----E E-AAADDDDDCCCCCCC-E-----E A-AAAAADDDEEEKKKD-AAAAAAA A-AAAAADDDDDDKKKD-AAAAAAA A-BBBDDDDDDDDKKKD-A------ A-BBBDDDDDDDDKKKD-A------ A-BBBDDDDDDDDKKKDDA------ A-DDDDDDDDDDDKKEEEA------ AFFFFFFFFLFFFLFLNFA------ A----J-J-J-J-J----A------ ------------------------- ---------HHH------------- ------------------------- ----OHH------------------ ------------------------- 
BBBBBBBBBBBBBBBBBBB------ BBCCCCCAAAAAAAAEEEB------ BBCCCCCAAAAAAAAEEEB------ BBCCCCCAAAAAAAAEEEB------ BBCCCCCAAAAAAAAEEEB------ BBCCCCCAAAAAAAAEEEB------ B-CCCCCIDDDDIAIIIICBBBBBB B-CCCCCCCCCCCCCCCCCBBBBBB E-AACCACCCCCCCAAAAE-----E E-AACCACCCCCCCAAAAE-----E E-AAAA--AACCAAAAAAE-----E E-AAAA------AAAAAAE-----E E-AAAA------A-AAA-E-----E E-AAAAAAAAAAAAAAA-E-----E E-AAAAAAAAAAAAAAA-E-----E E-AAAAADDDCCCCCCC-E-----E E-AAAAADDDCCCCCCC-E-----E A-AAAAADDDEEEKKKD-AAAAAAA A-AAAAADDDDDDKKKD-AAAAAAA A-BBBDDDDDDDDKKKD-A------ A-BBBDDDDDDDDKKKD-A------ A-BBBDDDDDDDDKKKDDA------ A-DDDDDDDDDDDKKEEEA------ AFFFFFFLFFFFFFFFFNA------ A---J-J-J-J-J-J---A------ ------------------------- ---------HHH------------- --------OH-HH------------ ----OOOQO---HH----------- ---OO-HH-----H----------- 
BBBBBBBBBBBBBBBBBBB------ BBCCCCCAAAAAAAAEEEB------ BBCCCCCAAAAAAAAEEEB------ BBCCCCCAAAAAAAAEEEB------ BBCCCCCAAAAAAAAEEEB------ BBCCCCCAAAAAAAAEEEB------ B-CCCCCIADAAAAIIIIABBBBBB B-CCCCCIDDAAAAIIIIABBBBBB E-AACCADDDCCCCAAAAE-----E E-AACCADDDCCCCAAAAE-----E E-AAAAADDDCCAAAAAAE-----E E-AAAAADDDCCAAAAAAE-----E E-AAAAAAAAAAAAAAA-E-----E E-AAAAAAAAAAAAAAA-E-----E E-AAAAAAAAAAAAAAA-E-----E E-AAAAADDDCCCCCCC-E-----E E-AAAAADDDCCCCCCC-E-----E A-AAAAADDDEEEEDDD-AAAAAAA A-AAAAAEEEDDDDDDD-AAAAAAA A-BBBDEEEEDDIDDDD-A------ A-BBBDEEEEDDIDDDD-A------ A-BBBDEEEEDDIDDDDDA------ A-DDDDDDDDDDIIDEEEA------ AFLFFFFFFLLFFFFLNNA------ A--J-J-J-J-J-J-J--A------ ---------HHO------------- --------HH-HH------------ -------HH--HHH----------- -----P-H----HH----------- -------H----------------- 
BBBBBBBBBBBBBBBBBBB------ BBCCCCCAAAAAAAAEEEB------ BBCCCCCAAAAAAAAEEEB------ BBCCCCCAAAAAAAAEEEB------ BBCCCCCAAAAAAAAEEEB------ BBCCCCCAAAAAAAAEEEB------ B-CCCCCIADAAAAIIIIABBBBBB B-CCCCCIDDAAAAIIIIABBBBBB E-AACCADDDCCCCAAAAE-----E E-AACCADDDCCCCAAAAE-----E E-AAAAADDDCCAAAAAAE-----E E-AAAAADDDCCAAAAAAE-----E E-AAAAAAAAAAAAAAA-E-----E E-AAAAAAAAAAAAAAA-E-----E E-AAAAAAAA-AAAAAA-E-----E E-AAAAADDDC---CCC-E-----E E-AAAAADDDC-C-CCC-E-----E A-AAAAADDDD-D-DDD-AAAAAAA A-AAAAAEEEDDDDDDD-AAAAAAA A-BBBDEEEEDDIDDDD-A------ A-BBBDEEEEDDIDDDD-A------ A-BBBDEEEEDDIDDDDDA------ A-DDDDDDDDDDIIDEEEA------ AFFLLFFLFFFLFFFFFNA------ A---J-J-J-J-J-J---A------ ---------HHH------------- ------------------------- ------------------------- -----H------------------- ------------------------- 
BBBBBBBBBBBBBBBBBBB------ BBCCCCCCCCCCCCCCCCB------ BBCCCCCCCCCCCCCCCCB------ BBCCCCCCCCCCCCCCCCB------ BBCCCCCCCCCCCCCCCCB------ BBCCCCCCCCCCCCCCCCB------ B-CCCCCCCCCCCCCCCCABBBBBB B-CCCCCCCCCCCCCCCCABBBBBB E-AACCADDDCCCCAAAAE-----E E-AACCADDDCCCCAAAAE-----E E-AAAAADDDCCAAAAAAE-----E E-AAAAADDDCCAAAAAAE-----E E-AAAAAAAAAAAAAAA-E-----E E-AAAAAAAAAAAAAAA-E-----E E-AAAAAAAA-A-AAAA-E-----E E-AAAAADDDC---AAA-E-----E E-AAAAADDDC-C-AAA-E-----E A-AAAAAGGGG-G-GGG-AAAAAAA A-AAAAAEEEDDDGGGG-AAAAAAA A-BBBDEEEEDDIGGGG-A------ A-BBBDEEEEDDIGGGG-A------ A-BBBDEEEEDDIGGGGGA------ A-DDDDDDDDDDIGGGGGA------ AFNFLFFFLFFFFFFFFNA------ A----J-J-J-J-J----A------ ---------OOO------------- --------OO-HH------------ -------OOH--OH----------- -------O-----O----------- ------------------------- 
BBBBBBBBBBBBBBBBBBB------ BBCCCCCCCCCCCBBBBBB------ BBCCCCCCCCCCCBBBBBB------ BBCCCCCCCCCCCB---BB------ BBCCCCCCCCCCCB---BB------ BBCCCCCCCCCCCB---BB------ BBCCCCCCCCCCCB---BB------ BBCCCCCCCCCCCB---BB------ EAAAAAAAAAAAAA---AE------ EAAAAAAAAAAAAA---AE------ EAAAAAADDDCCAA---AE------ EAAAAAADDDCCAA---AE------ EAAAAAAAAAAAAA---AE------ EAAAAAAAAAAAAA---AE------ EAAAAAAAAA-AAAAA-AE------ EAAAAAADDDC--AAAAAE------ EAAAAAADDDC-CAAAAAE------ AAAAAAAGGGG-GGGGGGA------ AAAAAAAEEEDDDGGGGGA------ ABBBBBEEEEDDIGGGGGA------ ABBBBBEEEEDDIGGGGGA------ ABBBBBEEEEDDIGGGGGA------ AMDDDDDDDDDDIGGGGGA------ AFNNLFLFFFLFLNLFFNA------ A-----J-J-J-J-----A------ ----------P-------------- ----------H-------------- ------POP---H------------ ------------------------- ------------------------- 
-BBBBBBBBBBBBBBBBB------- -BCCCCCCCCCCCBBBBB------- -BCCCCCCCCCCCBBBBB------- -BCCCCCCCCCCCB---B------- -BCCCCCCCCCCCB---B------- -BCCCCCCCCCCCB---B------- -BCCCCCCCCCCCB---B------- -BCCCCCCCCCCCB---B------- -EAAAAAAAAAAAA---E------- -EAAAAAAAAAAAA---E------- -EAAAAACCCCCAA---E------- -EAAAAACCCCCAA---E------- -EAAAAACCCCAAA---E------- -EAAAAACCCCAAA--AE------- -EAAAAACCC-A-AA-AE------- -EAAAAACCCC--AAAAE------- -EAAAAADDDD-DAAAAE------- -AAAAAAAAAA-AAAA-A------- -AAAAAAAAAAAAAAAAA------- -ABBBBDDDDDDIGGGGA------- -ABBBBDDDDDDIGGGGA------- -ABBBBDDDDDDIGGGGA------- -ADDDDDDDDDDIGGGGA------- -AFFLLFFFFLLFNFFNA------- -A-----J-J-J-----A------- ------------------------- ----------PH------------- ------H----H------------- ------------------------- ------------------------- 
-BBBBBBBBBBBBBBBBB------- -BCCCCCCC-CCCBBBBB------- -BCCCCCCC-CCCBBBBB------- -BCCCCCCCCCCCBB-BB------- -BCCCCCCCCCC----BB------- -BCCCCCCCC------BB------- -BCCCCCCCC------BB------- -BCCCCCCCC------BB------- -EAAAAAAAA------AE------- -EAAAAAAAA------AE------- -EAAAAACCC------AE------- -EAAAAACCC------AE------- -EAAAAACCC------AE------- -EAAAAACCC------AE------- -EAAAAACCCC-AAAAAE------- -EAAAAACCCC--AAAAE------- -EAAAAADDDD-DAAAAE------- -AAAAAAAAAA-AAAAAA------- -AAAAAAAAAAAAAAAAA------- -ABBBBDDDDDDIGGGGA------- -ABBBBDDDDDDIGGGGA------- -ABBBBDDDDDDIGGGGA------- -AMDDDDDDDDDIGGGGA------- -AFNNNLFFFFLFNFNNA------- -A------J-J------A------- ------------------------- ----------O-------------- ------------------------- ------------------------- ------------------------- 
--BBBBBBBBBBBBBBB-------- --BBBBBBBBBBBBBBB-------- --BBBBBBBBBBBBBBB-------- --BBBBBBBBBB--BBB-------- --BBBBBBBBB----BB-------- --BBBBBBBB-----BB-------- --BBBBBBBB-----BB-------- --BBBBBBBB-----BB-------- --EAAAAAAA-----AE-------- --EAAAAAAA-----AE-------- --EA--ACCC-----AE-------- --EA--ACCC-----AE-------- --EA--ACCC-----AE-------- --EA--ACCC-----AE-------- --EA--ACCCCAAAAAE-------- --EA--ACCC-C-AAAE-------- --EA--ADDD--DAAAE-------- --AA--AAAA--AAAAA-------- --AA--AAAA--AAAAA-------- --AB--DDDD--IGGGA-------- --AB--DDDD--IGGGA-------- --AB--DDDD--IGGGA-------- --AMDDDDDDDDIGGGA-------- --AFFFFFLFFNNFNNA-------- --A------J------A-------- ------------------------- ------------------------- ------------------------- ------------------------- ------------------------- 
---BBBBBBBBBBBBB--------- ---BBBBBBBBBBBBB--------- ---BBBBBBBBBBBBB--------- ---BB----BBB--BB--------- ---BB----BB---BB--------- ---BB---------BB--------- ---BB---------BB--------- ---BB---------BB--------- ---EA---------AE--------- ---EA---------AE--------- ---EA---------AE--------- ---EA---------AE--------- ---EA---------AE--------- ---EA---------AE--------- ---EA------AAAAE--------- ---EA------CCAAE--------- ---EA-------DAAE--------- ---AA-------AAAA--------- ---AA-------AAAA--------- ---AB--------GGA--------- ---AB--------GGA--------- ---AB--------GGA--------- ---AMDDDDDDDCGGA--------- ---AFFFNLNNLFFNA--------- ---A-----------A--------- ------------------------- ------------------------- ------------------------- ------------------------- ------------------------- 
----BBBBBBBBBBB---------- ----BBBBBBBBBBB---------- ----BBBBBBBBBBB---------- ----BBB---B-BBB---------- ----BBB-----BBB---------- ----BBB-----BBB---------- ----BBB-----BBB---------- ----BBB-----BBB---------- ----EEA-----AEE---------- ----EEA-----AEE---------- ----EEA-----AEE---------- ----EEA-----AEE---------- ----EEA-----AEE---------- ----EEA-----AEE---------- ----EEA-----AEE---------- ----EEA-----CEE---------- ----EEA-----MEE---------- ----AAA-----AAA---------- ----AAA-----AAA---------- ----AAM-----MAA---------- ----AAM-----MAA---------- ----AAM-----MAA---------- ----AAMDDDDDMAA---------- ----AAFFFNNFFAA---------- ----AA-------AA---------- ------------------------- ------------------------- ------------------------- ------------------------- ------------------------- 
------BBBBBBB------------ ------BBBBBBB------------ ------BBBBBBB------------ ------BBBBBBB------------ ------BBBBBBB------------ ------BBBBBBB------------ ------BBBBBBB------------ ------BBBBBBB------------ ------EEEEEEE------------ ------EEEEEEE------------ ------EEEEEEE------------ ------EEEEEEE------------ ------EEEEEEE------------ ------EEEEEEE------------ ------EEEEEEE------------ ------EEEEEEE------------ ------EEEEEEE------------ ------AAAAAAA------------ ------AAAAAAA------------ ------AAAAAAA------------ ------AAAAAAA------------ ------AAAAAAA------------ ------AAAAAAA------------ ------AAAAAAA------------ ------AAAAAAA------------ ------------------------- ------------------------- ------------------------- ------------------------- ------------------------- 
