model
size = 25 30 19, scale = 0.05, origin = -y
material 
  colors = A:#E00 B:#EEE C:#FF0 D:#CF3 E:#000 F:#251505 G:#BBB H:#960 I:#CC6 J:#1C0900 K:#00C L:#CF0 M:#AAA N:#939 O:#888 P:#AAAAB9 Q:#FCF
voxels
------BBBBBBB------------ ------AAAAAAA------------ ------AAAAAAA------------ ------AAAAAAA------------ ------AAAAAAA------------ ------AAAAAAA------------ ------AAAAAAA------------ ------AAAAAAA------------ ------AAAAAAA------------ ------BBBBBBB------------ ------BBBBBBB------------ ------BBBBBBB------------ ------BBBBBBB------------ ------BBBBBBB------------ ------BBBBBBB------------ ------BBBBBBB------------ ------AAAAAAA------------ ------AAAAAAA------------ ------AAAAAAA------------ ------AAAAAAA------------ ------AAAAAAA------------ ------AAAAAAA------------ ------AAAAAAA------------ ------BBBBBBB------------ ------EEEEEEE------------ ------------------------- ------------------------- ------------------------- ------M------------------ ------------------------- 
----BBBBBBBBBBB---------- ----AAA---ABAAA---------- ----AAA---ABAAA---------- ----AAA---ABAAA---------- ----AAA---ABAAA---------- ----AAA---AAAAA---------- ----AAA---AAAAA---------- ----AAA--AAAAAA---------- ----AAA--AAAAAA---------- ----BBB--BBBBBB---------- ----BBB--BBBBBB---------- ----BBB-BBBBBBB---------- ----BBBBBBBBBBB---------- ----BBBBBBBBBBB---------- ----BBBBBBBBBBB---------- ----BBABBBBBBBB---------- ----AAAAAAAAAAA---------- ----AAAAAAAAAAA---------- ----AAAAAAAAAAA---------- ----AAAAAAAAAAA---------- ----AAAAAAAAAAA---------- ----AAPBBBBBBAA---------- ----AAPBBBBBBAA---------- ----BBFHJHJHJBB---------- ----EE-------EE---------- ------------------------- ------------------------- ------------------------- ------G------------------ ------G------------------ 
---BBBBBBBBBBBBB--------- ---AAA--------AA--------- ---AAAAAAAABAAAA--------- ---AAAAAAAABAAAA--------- ---AAAAAAAABAAAA--------- ---AAAAAAAAAAAAA--------- ---AAAAAAAAAAAAA--------- ---AAAAAAAAAAAAA--------- ---AAAAAAAAAAAAA--------- ---BBBBBBBBBBBBB--------- ---BBBBBBBBBBBBB--------- ---BBBBBBBBBBBBB--------- ---BBBBBBBBBBBBB--------- ---BBBBBBBBBBBBB--------- ---BBBBBBBBBBBBB--------- ---BACCCCCCCABBB--------- ---AAAAAAAAAAAAA--------- ---AAAAAAAAAAAAA--------- ---AAAAAAAAAAAAA--------- ---AAAAAAAAAAAAA--------- ---AAAAAAAAAAAAA--------- ---AAADDDDDDDAAA--------- ---AAADDDDDDDAAA--------- ---BFFHFFFHJFFFB--------- ---E-----------E--------- ------------------------- ------------------------- ------------------------- ------------------------- ------GG----------------- 
--BBBBBBBBBBBBBBB-------- --AAAAAAAAACAAAAA-------- --AAAAAAAAACAAAAA-------- --AAAAAAAAACAAAAA-------- --AAAAAAAAACAAAAA-------- --AAAAAAAAAAAAAAA-------- --AAAAAAAAAAAAAAA-------- --AAAAAAAAAAAAAAA-------- --AAAAAAAAAAAAAAA-------- --BACC--------BBB-------- --BAAAACCCCCABBBB-------- --BAACAAAAAAABBBB-------- --BAAAAAAAAAABBBB-------- --BAAAAAAA-AABBBB-------- --BAAAAAAA-AABBBB-------- --BAACCCCC-CABBBB-------- --AAAAAAAA-AAAAAA-------- --AAAAAAAA-AAAAAA-------- --AAAAAAAA-AAAAAA-------- --AAAAAAAA-AAAAAA-------- --AAAADDDD-DDAAAA-------- --AAAADDDD-DDAAAA-------- --AAAADDDD-DDAAAA-------- --BFFFFHFHFFJJFFB-------- --E------I------E-------- ------------------------- ------------------------- ------------------------- ---G--------------------- -------G----------------- 
-BBBBBBBBBBBBBBBBB------- -AAAAAAAAAACAAA-AA------- -AAAAAAAAAACAAA-AA------- -AAAAAAAAAACAAA-AA------- -AAAAAAAAAACAAA-AA------- -AAAAAAAAAAAAAA-AA------- -AAAAAAAAAAAAAA-AA------- -AAAAAAAAAAAAAA-AA------- -AAAAAAAAAAAAAA-AA------- -BAACCCCCCCCCBB-BB------- -BA-AAAAAACCAAA-AB------- -BA-AAAAAAAAAAA-AB------- -BA-AAAAAAAAAAA-AB------- -BA-AAAAAAAAAAA-AB------- -BA-AAAAAAAAAAA-AB------- -BAAAADDDDCCAAA-AB------- -AA-AAAAAAAAAAA-AA------- -AA-AAAAAAAAAAA-AA------- -AA-AAAAAAAAAAA-AA------- -AA-AAAAAAAAAAA-AA------- -AA-KDDDDDDDDAA-AA------- -ABKKDDDDDDDDAA-AA------- -APCDDDDDDDDDAA-AA------- -BFFHFHFHFFHJHFFFB------- -E------I-I------E------- ------------------------- ------------------------- ------------------------- ---G--------------------- ---M---G----------------- 
-BBBBBBBBBBBBBBBBB------- -AAAAAAAAAACAAAAAA------- -AAAAAAAAAACAAAAAA------- -AAAAAAAAAACAAAAAA------- -AAAAAAAAAACAAAAAA------- -AAAAAAAAAAAAAAAAA------- -AAAAAAAAAAAAAAAAA------- -AAAAAAAAAAAAAAAAA------- -AAAAAAAAAAAAAAAAA------- -BAACCCCCCCCCCBBBB------- -BAAAAAAAACCAAAAAB------- -BAAAAAAAAAAAAAAAB------- -BAAAAAAAAAAAAAAAB------- -BAAAAAAAAAAAAAAAB------- -BAAAAAAAAAAAAAAAB------- -BAAAADDDDCCAAAAAB------- -AAAAAAAAAAAAAAAAA------- -AAAAAAAAAAAAAAAAA------- -AAAAAAAAAAAAAAAAA------- -AAAAAAAAAAAAAAAAA------- -AAKKDDDDDDDDAAAAA------- -ABKKDDDDDDDDAAAAA------- -ADDDDDDDDDDDAAAAA------- -BHFHHFHFFFHFFHHFB------- -E-----I-I-I-----E------- ------------------------- ------------------------- ------------------------- ------------------------- ---O--GM----------------- 
BBBBBBBBBBBBBBBBBBB------ ACCCCCCCCCCCAAAAAAA------ ACCCCCCCCCCCAAAAAAA------ ACCCCCCCCCCCAAAAAAA------ ACCCCCCCCCCCAAAAAAA------ ACCCCCAAAAAAAAAAAAA------ AAAAAAAAAAAAAAAAAAA------ AAAAAACCCCCCCCCCCBA------ AAAAAACCCCCCCCAAAAA------ BAAACCCCCCCCCCAAAAB------ BAAAAAAAAACCAAAAAAB------ BAAAAAAAAAAAAAAAAAB------ BAAAAAAAAAAAAAAAAAB------ BAAAAAAAAAAAAAAAAAB------ BAAAAAAAAAAAAAAAAAB------ BAAAAADDDDCCCCCCCCB------ AAAAAAAAAAAAAAAAAAA------ AAAAAAAAAAAAAAAAAAA------ AAAAAAAAAAAAAAAAAAA------ AAAAAAAAAAAAAAAAAAA------ AAAKKDDDDDDDDAAAAAA------ AAKKKDDDDDDDDAAAAAA------ AADDDDDDDDDDDAAAAAA------ BFFFFFHHFFFFFHJFFJB------ E-----I-I-I-I-----E------ ------------------------- ---------GGG------------- --------MG-GG------------ ----MMMMM---GG----------- ---MM-MM-----G----------- 
BBBBBBBBBBBBBBBBBBB------ ACCCCCCAAAAAAAABBBA------ ACCCCCCAAAAAAAABBBA------ ACCCCCCAAAAAAAABBBA------ ACCCCCCAAAAAAAABBAA------ ACCCCCCAAAAAAAABBAA------ A-AAAAALDDDDLALBBBAEEEEEE A-AAAACCCCCCCCCCCCBEEEEEE A-AAAAACCCCCCCAAAAA-----E B-AACCACCCCCCCAAAAB-----E B-AAAA--AACCAAAAAAB-----E B-AAAA------AAAAAAB-----E B-AAAA------A--AA-B-----E B-AAAAAAAAAAAAAAA-B-----E B-AAAAAAAAAAAAAAA-B-----E B-AAAADDDDCCCCCCC-B-----E A-AAAAADDDCCAAAAA-A-----E A-AAAAADDDBBAAAAA-AEEEEEE A-AAAAADDDDDAAAAA-AEEEEEE A-AAADDDDDDDDNNND-A------ A-AKKDDDDDDDDNNND-A------ A-KKKDDDDDDDDNNNDDA------ A-DDDDDDDDDDDNNBBBA------ BHFFFFFFFHFFFHFHJFB------ E----I-I-I-I-I----E------ ------------------------- ---------GGG------------- ------------------------- ----MGG------------------ ------------------------- 
BBBBBBBBBBBBBBBBBBB------ ACCCCCCAAAAAAAABBBA------ ACCCCCCAAAAAAAABBBA------ ACCCCCCAAAAAAAABBBA------ ACCCCCCAAAAAAAABBAA------ ACCCCCCAAAAAAAABBAA------ A-AAAAALDDDDLALLLLBEEEEEE A-AAAACCCCCCCCCCCCBEEEEEE A-AAAAACCCCCCCAAAAA-----E B-AACCACCCCCCCAAAAB-----E B-AAAA--AACCAAAAAAB-----E B-AAAA------AAAAAAB-----E B-AAAA------A-AAA-B-----E B-AAAAAAAAAAAAAAA-B-----E B-AAAAAAAAAAAAAAA-B-----E B-AAAAADDDCCCCCCC-B-----E A-AAAAADDDCCAAAAA-A-----E A-AAAAADDDBBAAAAA-AEEEEEE A-AAAAADDDDDAAAAA-AEEEEEE A-AAADDDDDDDDNNND-A------ A-AKKDDDDDDDDNNND-A------ A-KKKDDDDDDDDNNNDDA------ A-DDDDDDDDDDDNNBBBA------ BFFFFFFHFFFFFFFFFJB------ E---I-I-I-I-I-I---E------ ------------------------- ---------GGG------------- --------MG-GG------------ ----MMMQM---GG----------- ---MM-GG-----G----------- 
BBBBBBBBBBBBBBBBBBB------ ACCCCCCAAAAAAAABBBA------ ACCCCCCAAAAAAAABBBA------ ACCCCCCAAAAAAAABBBA------ ACCCCCCAAAAAAAABBAA------ ACCCCCCAAAAAAAABBAA------ A-AAAAALADAAAALLLLBEEEEEE A-AAAACLDDAAAALLLLBEEEEEE A-AAAAADDDCCCCAAAAA-----E B-AACCADDDCCCCAAAAB-----E B-AAAAADDDCCAAAAAAB-----E B-AAAAADDDCCAAAAAAB-----E B-AAAAAAAAAAAAAAA-B-----E B-AAAAAAAAAAAAAAA-B-----E B-AAAAAAAAAAAAAAA-B-----E B-AAAAADDDCCCCCCC-B-----E A-AAAAADDDCCAAAAA-A-----E A-AAAAADDDBBAAAAA-AEEEEEE A-AAAAABBBDDAAAAA-AEEEEEE A-AAADBBBBDDLDDDD-A------ A-AKKDBBBBDDLDDDD-A------ A-KKKDBBBBDDLDDDDDA------ A-DDDDDDDDDDLLDBBBA------ BFHFFFFFFHHFFFFHJJB------ E--I-I-I-I-I-I-I--E------ ---------GGM------------- --------GG-GG------------ -------GG--GGG----------- -----O-G----GG----------- -------G----------------- 
BBBBBBBBBBBBBBBBBBB------ AAAAAAAAAAAAAAABBBA------ AAAAAAAAAAAAAAABBBA------ AAAAAAAAAAAAAAABBBA------ AAAAAAAAAAAAAAABBAA------ AAAAAAAAAAAAAAABBAA------ A-AAAAALADAAAALLLLBEEEEEE A-AAAACLDDAAAALLLLBEEEEEE A-AAAAADDDCCCCAAAAA-----E B-AACCADDDCCCCAAAAB-----E B-AAAAADDDCCAAAAAAB-----E B-AAAAADDDCCAAAAAAB-----E B-AAAAAAAAAAAAAAA-B-----E B-AAAAAAAAAAAAAAA-B-----E B-AAAAAAAA-AAAAAA-B-----E B-AAAAADDDC---CCC-B-----E A-AAAAADDDC-A-AAA-A-----E A-AAAAADDDD-A-AAA-AEEEEEE A-AAAAABBBDDAAAAA-AEEEEEE A-AAADBBBBDDAAAAA-A------ A-AKKDBBBBDDAAAAA-A------ A-KKKDBBBBDDAAAAAAA------ A-DDDDDDDDDDLLAAAAA------ BHFHHFFHFFFHFFFFFJB------ E---I-I-I-I-I-I---E------ ---------GGG------------- ------------------------- ------------------------- -----G------------------- ------------------------- 
BBBBBBBBBBBBBBBBBBB------ AAAAAAAAACCCCCCCCCA------ AAAAAAAAACCCCCCCCCA------ AAAAAAAAACCCCCCCCCA------ AAAAAAAAACCCCCCCCAA------ AAAAAAAAACCCCCCCCAA------ A-AAAAACCCCCCCCCCCBEEEEEE A-AAAACCCCCCCCCCCCBEEEEEE A-AAAAADDDCCAAAAAAA-----E B-AACCADDDCCCCAAAAB-----E B-AAAAADDDCCAAAAAAB-----E B-AAAAADDDCCAAAAAAB-----E B-AAAAAAAAAAAAAAA-B-----E B-AAAAAAAAAAAAAAA-B-----E B-AAAAAAAA-A-AAAA-B-----E B-AAAAADDDC---AAA-B-----E A-AAAAADDDC-A-AAA-A-----E A-AAAAAEEEE-A-AAA-AEEEEEE A-AAAAABBBDDAAAAA-AEEEEEE A-AAADBBBBDDAAAAA-A------ A-AKKDBBBBDDAAAAA-A------ A-KKKDBBBBDDAAAAAAA------ A-DDDDDDDDDDLEAAAAA------ BFJFHFFFHFFFFFFFFJB------ E----I-I-I-I-I----E------ ---------MMM------------- --------MM-GG------------ -------MMG--MG----------- -------M-----M----------- ------------------------- 
BBBBBBBBBBBBBBBBBBB------ AAAAAAAAAAAAAAAAAAA------ AAAAAAAAAAAAAAAAAAA------ AAAAAAAAAAAAAA---AA------ AAAAAAAAAAAAAA---AA------ AAAAAAAAAAAAAA---AA------ AAAAAAAAAAAAAA---AA------ AAAAAAAAAAAAAA---AA------ AAAAAAAAAAAAAA---AA------ BBBBBBAAAAAAAA---AB------ BBBBBBADDDCCAA---AB------ BBBBBBADDDCCAA---AB------ BBBBBBAAAAAAAA---AB------ BBBBBBAAAAAAAA---AB------ BBBBBBAAAA-AAAAA-AB------ BAAAAAADDDC--AAAAAB------ AAAAAAADDDC-AAAAAAA------ AAAAAAAEEEE-AAAAAAA------ AAAAAAABBBDDAAAAAAA------ AAAAAKBBBBDDAAAAAAA------ AAAAAAAAAAAAAAAAAAA------ AAAAAAAAAAAAAAAAAAA------ AAAAAAAAAAAAAEAAAAA------ BFHJHFHFFFHFHJHJHJB------ E-----I-I-I-I-----E------ ----------O-------------- ----------G-------------- ------OMO---G------------ ------------------------- ------------------------- 
-BBBBBBBBBBBBBBBBB------- -AAAAAAAAAAAAAAAAA------- -AAAAAAAAAAAAAAAAA------- -AAAAAAAAAAAAA---A------- -AAAAAAAAAAAAA---A------- -AAAAAAAAAAAAA---A------- -AAAAAAAAAAAAA---A------- -AAAAAAAAAAAAA---A------- -AAAAAAAAAAAAA---A------- -BBBBBAAAAAAAA---B------- -BBBBBACCCCCAA---B------- -BBBBBACCCCCAA---B------- -BBBBBACCCCAAA---B------- -BBBBBACCCCAAA--AB------- -BBBBBACCC-A-AA-AB------- -BAAAAACCCC--AAAAB------- -AAAAAADDDD-AAAAAA------- -AAAAAAEEEE-AAAA-A------- -AAAAAADDDDDAAAAAA------- -AAAAKDDDDDDAAAAAA------- -AAAAAAAAAAAAAAAAA------- -AAAAAAAAAAAAAAAAA------- -AAAAAAAAAAAAEAAAA------- -BFFHHFFFFHHFJFFJB------- -E-----I-I-I-----E------- ------------------------- ----------OG------------- ------G----G------------- ------------------------- ------------------------- 
-BBBBBBBBBBBBBBBBB------- -AAAAAAAA-AAAAAAAA------- -AAAAAAAA-AAAAAAAA------- -AAAAAAAAAAAAAA-AA------- -AAAAAAAAAAA----AA------- -AAAAAAAAA------AA------- -AAAAAAAAA------AA------- -AAAAAAAAA------AA------- -AAAAAAAAA------AA------- -BBBBBAAAA------AB------- -BBBBBACCC------AB------- -BBBBBACCC------AB------- -BBBBBACCC------AB------- -BBBBBACCC------AB------- -BBBBBACCCC-AAAAAB------- -BAAAAACCCC--AAAAB------- -AAAAAADDDD-AAAAAA------- -AAAAAAEEEE-AAAAAA------- -AAAAAADDDDDAAAAAA------- -AAAAKDDDDDDAAAAAA------- -AAAAAAAAAAAAAAAAA------- -AAAAAAAAAAAAAAAAA------- -AAAAAAAAAAAAEAAAA------- -BFJJJHFFFFHFHFHJB------- -E------I-I------E------- ------------------------- ----------M-------------- ------------------------- ------------------------- ------------------------- 
--BBBBBBBBBBBBBBB-------- --AAAAAAAAAAAAAAA-------- --AAAAAAAAAAAAAAA-------- --AAAAAAAAAA--AAA-------- --AAAAAAAAA----AA-------- --AAAAAAAA-----AA-------- --AAAAAAAA-----AA-------- --AAAAAAAA-----AA-------- --AAAAAAAA-----AA-------- --BBBBBBBB-----BB-------- --BB--BBBB-----BB-------- --BB--BBBB-----BB-------- --BB--BBBB-----BB-------- --BB--BBBB-----BB-------- --BB--BBBBBBBBBBB-------- --BA--ACCC-C-AAAB-------- --AA--ADDD--AAAAA-------- --AA--AEEE--AAAAA-------- --AA--ADDD--AAAAA-------- --AA--DDDD--AAAAA-------- --AA--AAAA--AAAAA-------- --AA--AAAA--AAAAA-------- --AAAAAAAAAAAEAAA-------- --BFHHFFHFFJJFJJB-------- --E------I------E-------- ------------------------- ------------------------- ------------------------- ------------------------- ------------------------- 
---BBBBBBBBBBBBB--------- ---AAAAAAAAAAAAA--------- ---AAAAAAAAAAAAA--------- ---AA----AAA--AA--------- ---AA----AA---AA--------- ---AA---------AA--------- ---AA---------AA--------- ---AA---------AA--------- ---AA---------AA--------- ---BB---------BB--------- ---BB---------BB--------- ---BB---------BB--------- ---BB---------BB--------- ---BB---------BB--------- ---BB------BBBBB--------- ---BB------BBAAB--------- ---AA-------AAAA--------- ---AA-------AAAA--------- ---AA-------AAAA--------- ---AA--------AAA--------- ---AA--------AAA--------- ---AA--------AAA--------- ---AAAAAAAAAAEAA--------- ---BJJHJJHJHJFJB--------- ---E-----------E--------- ------------------------- ------------------------- ------------------------- ------------------------- ------------------------- 
----BBBBBBBBBBB---------- ----AAAAAAAAAAA---------- ----AAAAAAAAAAA---------- ----AAA---A-AAA---------- ----AAA-----AAA---------- ----AAA-----AAA---------- ----AAA-----AAA---------- ----AAA-----AAA---------- ----AAA-----AAA---------- ----BBB-----BBB---------- ----BBB-----BBB---------- ----BBB-----BBB---------- ----BBB-----BBB---------- ----BBB-----BBB---------- ----BBB-----BBB---------- ----BBB-----BBB---------- ----AAA-----AAA---------- ----AAA-----AAA---------- ----AAA-----AAA---------- ----AAA-----AAA---------- ----AAA-----AAA---------- ----AAA-----AAA---------- ----AAAAAAAAAAA---------- ----BBJHHJHJJBB---------- ----EE-------EE---------- ------------------------- ------------------------- ------------------------- ------------------------- ------------------------- 
------BBBBBBB------------ ------AAAAAAA------------ ------AAAAAAA------------ ------AAAAAAA------------ ------AAAAAAA------------ ------AAAAAAA------------ ------AAAAAAA------------ ------AAAAAAA------------ ------AAAAAAA------------ ------BBBBBBB------------ ------BBBBBBB------------ ------BBBBBBB------------ ------BBBBBBB------------ ------BBBBBBB------------ ------BBBBBBB------------ ------BBBBBBB------------ ------AAAAAAA------------ ------AAAAAAA------------ ------AAAAAAA------------ ------AAAAAAA------------ ------AAAAAAA------------ ------AAAAAAA------------ ------AAAAAAA------------ ------BBBBBBB------------ ------EEEEEEE------------ ------------------------- ------------------------- ------------------------- ------------------------- ------------------------- 
