model
size = 25 30 19, scale = 0.05, origin = -y
material 
  colors = A:#FF0 B:#06F C:#EEE D:#E00 E:#CF3 F:#000 G:#00C H:#251505 I:#BBB J:#CC6 K:#CF0 L:#939 M:#960 N:#1C0900 O:#AAAAB9 P:#AAA Q:#00F R:#888 S:#FCF
voxels
------AAAABBB------------ ------AAAABBB------------ ------AAAABBB------------ ------AAAABBB------------ ------AAAABBB------------ ------AAAABBB------------ ------AAAABBB------------ ------AAAABBB------------ ------AAAABBB------------ ------AAAABBB------------ ------AAAABBB------------ ------AAAABBB------------ ------AAAAAAA------------ ------AAAAAAA------------ ------AAAAAAA------------ ------AAAAAAA------------ ------AAAABBB------------ ------AAAABBB------------ ------AAAABBB------------ ------AAAABBB------------ ------AAAABBB------------ ------AAAABBB------------ ------AAAABBB------------ ------AAAABBB------------ ------AAAABBB------------ ------------------------- ------------------------- ------------------------- ------P------------------ ------------------------- 
----BBBBBBBBBBB---------- ----BBA---AAABB---------- ----BBA---AAABB---------- ----BBC---AAABB---------- ----BBC---AAABB---------- ----BBC---AAABB---------- ----BBC---AAABB---------- ----BBC--AAAABB---------- ----BBC--DDDDBB---------- ----BBC--DDDDBB---------- ----BBC--DDDDBB---------- ----BBC-DDDDDBB---------- ----AAADDDDDAAA---------- ----AAADDDDDDAA---------- ----AAADDDDDDAA---------- ----AACDDDDDAAA---------- ----BBCDDDDDDBB---------- ----BBCFFFFFFBB---------- ----BBCEEEEEOBB---------- ----BBOEEEEEOBB---------- ----BBOEEEEEOBB---------- ----BBOEEEEEOBB---------- ----BBOEEEEEOBB---------- ----BBHHHHHHHBB---------- ----BB-------BB---------- ------------------------- ------------------------- ------------------------- ------I------------------ ------I------------------ 
---BBBBBBBBBBBBB--------- ---BAA--------CB--------- ---BAAAAAAAAACCB--------- ---BAAAAAAAAACCB--------- ---BAAAAAAAAACCB--------- ---BAAAAAAAAACCB--------- ---BAAAAAAAAACCB--------- ---BAAAAAAAAACCB--------- ---BDDDDDDDDDCCB--------- ---BDDDDDDDDDCCB--------- ---BDDDAAAAADDCB--------- ---BDDDDDDDDDDCB--------- ---AAAADDDDDAAAA--------- ---AAAADDDDDDAAA--------- ---AAAADDDDDDAAA--------- ---ADAAAAAAAAAAA--------- ---BDEEEEEAADDDB--------- ---BFFFFFFFFFFFB--------- ---BGEEEEEEEEDDB--------- ---BGEEEEEEEEDDB--------- ---BGEEEEEEEEDDB--------- ---BGEEEEEEEEDDB--------- ---BOEEEEEEEEEOB--------- ---BHHHHHHMNHHHB--------- ---B-----------B--------- ------------------------- ------------------------- ------------------------- ------------------------- ------II----------------- 
--BBBBBBBBBBBBBBB-------- --BAAAAAAAAAACCCB-------- --BAAAAAAAAAACCCB-------- --BAAAAAAAAAACCCB-------- --BAAAAAAAAAACCCB-------- --BCAAAAAAAAACCCB-------- --BCAAAAAAAAACCCB-------- --BCAAAAAAAAACCCB-------- --BCAAAAAAAAACCCB-------- --BCAA--------CCB-------- --BCDDDAAAAADDDCB-------- --BCDADDDDDDDDDCB-------- --AADDDDDDDDAAAAA-------- --AAADDDDD-DDAAAA-------- --AADDDDDD-DDAAAA-------- --AADAAAAA-AAAAAA-------- --BCDEEEEE-ADDDCB-------- --BFFFFFFF-FFFFFB-------- --BGGEEEEE-EEEEOB-------- --BGGEEEEE-EEEEOB-------- --BGGEEEEE-EEEEOB-------- --BGGEEEEE-EEEEOB-------- --BOEEEEEE-EEEECB-------- --BHHHHMHMHHNNHHB-------- --B------J------B-------- ------------------------- ------------------------- ------------------------- ---I--------------------- -------I----------------- 
-BBBBBBBBBBBBBBBBB------- -BAAAAAAAAAAACC-CB------- -BAAAAAAAAAAACC-CB------- -BAAAAAAAAAAACC-CB------- -BAAAAAAAAAAACC-CB------- -BAAAAAAAAAAACC-CB------- -BAAAAAAAAAAACC-CB------- -BAAAAAAAAAAACC-CB------- -BDDAAAAAAAAACC-CB------- -BDDAAAAAAAAACC-CB------- -BD-DDDDDDAADDD-DB------- -BD-DDDDDDDDDDD-DB------- -AA-DDDDDDDDAAA-AA------- -AA-ADDDDDDDDAA-AA------- -AA-DDDDDDDDDAA-AA------- -AAADDEEEEAAAAA-AA------- -BD-DEEEEEAADDD-DB------- -BF-FFFFFFFFFFF-FB------- -BC-GEEEEEEEEEE-OB------- -BC-GEEEEEEEEEE-OB------- -BC-GEEEEEEEEEE-OB------- -BCGGEEEEEEEEEE-OB------- -BOAEEEEEEEEEEE-CB------- -BHHMHMHMHHMNMHHHB------- -B------J-J------B------- ------------------------- ------------------------- ------------------------- ---I--------------------- ---P---I----------------- 
-BBBBBBBBBBBBBBBBB------- -BAAAAAAAAAAAAQQQB------- -BAAAAAAAAAAAAQCCB------- -BAAAAAAAAAAAAQQQB------- -BAAAAAAAAAAAAAAAB------- -BAAAAAAAAAAAAAAAB------- -BAAAAAAAAAAAAAAAB------- -BAAAAAAAAAAAAACCB------- -BDDAAAAAAAAAACCCB------- -BDDAAAAAAAAAACCCB------- -BDDDDDDDDAADDDDDB------- -BDDDDDDDDDDDDDDDB------- -AAADDDDDDDDAAAAAA------- -AAAADDDDDDDDAAAAA------- -AAADDDDDDDDDAAAAA------- -AAADDEEEEAAAAAAAA------- -BDDDEEEEEAADDDDDB------- -BFFFFFEEDDDDDDDDB------- -BCGGEEEEEEEEEEEEB------- -BCGGEEEEEEEEEEEEB------- -BCGGEEEEEEEEEEEEB------- -BCGGEEEEEEEEEEEEB------- -BEEEEEEEEEEEEECCB------- -BMHMMHMHHHMHHMMHB------- -B-----J-J-J-----B------- ------------------------- ------------------------- ------------------------- ------------------------- ---R--IP----------------- 
BBBBBBBBBBBBBBBBBBB------ BAAAAAAAAAAAAAAAACB------ BAAAAAAAAAAAAAAAACB------ BAAAAAAAAAAAAAAAACB------ BAAAAAAAAAAAAAAAACB------ BAAAAAAAAAAAAAAAACB------ BAAAAAAAAAAAAAAAACB------ BAAAAAAAAAAAAAAAACB------ BDDDAAAAAAAAAADDDDB------ BDDDAAAAAAAAAADDDDB------ BDDDDDDDDDAADDDDDDB------ BDDDDDDDDDDDDDDDDDB------ AAAADDDDDDDDAAAAAAA------ AAAAADDDDDDDDAAAAAA------ AAAADDDDDDDDDAAAAAA------ AAAADDEEEEAAAAAAAAA------ BDDDDEEEEEAAAAAAAAB------ BFFFFFFEEDDDDDDDDFB------ BGGGGEEEEEEEELLLEOB------ BGGGGEEEEEEEELLLEOB------ BGGGGEEEEEEEELLLEOB------ BGGGGEEEEEEEELLLEOB------ BOEEEEEEEEEEELLCCCB------ BHHHHHMMHHHHHMNHHNB------ B-----J-J-J-J-----B------ ------------------------- ---------III------------- --------PI-II------------ ----PPPPP---II----------- ---PP-PP-----I----------- 
BBBBBBBBBBBBBBBBBBB------ BAAAAAADDDDDDDDCCCB------ BAAAAAADDDDDDDDCCCB------ BAAAAAADDDDDDDDCCCB------ BAAAAAADDDDDDDDCCCB------ BAAAAAADDDDDDDDCCCB------ B-AAAAAKEEEEKDKCCCCBBBBBB B-AAAAAAAAAAAAAAAACBBBBBB B-DDAADAAAAAAADDDDB-----B B-DDAADAAAAAAADDDDB-----B B-DDDD--DDAADDDDDDB-----B B-DDDD------DDDDDDB-----B A-AADD------D--DD-A-----A A-DDDDDDDDDDDDDDD-A-----A A-AADDDDDDDDDDDDD-A-----A A-AADDEEEEAAAAAAA-A-----A B-DDDEEEEEAAAAAAA-B-----B B-FFFFFEEECCCLLLE-BBBBBBB B-GGGEEEEEEEELLLE-BBBBBBB B-GGGEEEEEEEELLLE-B------ B-GGGEEEEEEEELLLE-B------ B-GGGEEEEEEEELLLEEB------ B-EEEEEEEEEEELLCCCB------ BHHHHHHHHMHHHMHMNHB------ B----J-J-J-J-J----B------ ------------------------- ---------III------------- ------------------------- ----PII------------------ ------------------------- 
BBBBBBBBBBBBBBBBBBB------ BAAAAAADDDDDDDDCCCB------ BAAAAAADDDDDDDDCCCB------ BAAAAAADDDDDDDDCCCB------ BAAAAAADDDDDDDDCCCB------ BAAAAAADDDDDDDDCCCB------ B-AAAAAKEEEEKDKKKKABBBBBB B-AAAAAAAAAAAAAAAAABBBBBB B-DDAADAAAAAAADDDDB-----B B-DDAADAAAAAAADDDDB-----B B-DDDD--DDAADDDDDDB-----B B-DDDD------DDDDDDB-----B A-DDDD------D-DDD-A-----A A-DDDDDDDDDDDDDDD-A-----A A-DDDDDDDDDDDDDDD-A-----A A-DDDDDEEEAAAAAAA-A-----A B-DDDDDEEEAAAAAAA-B-----B B-FFFFFEEECCCLLLE-DBBBBBB B-GGGEEEEEEEELLLE-BBBBBBB B-GGGEEEEEEEELLLE-B------ B-GGGEEEEEEEELLLE-B------ B-GGGEEEEEEEELLLEEB------ B-EEEEEEEEEEELLCCCB------ BHHHHHHMHHHHHHHHHNB------ B---J-J-J-J-J-J---B------ ------------------------- ---------III------------- --------PI-II------------ ----PPPSP---II----------- ---PP-II-----I----------- 
CBBBBBBBBBBBBBBBBBC------ CBBBBBBBBBBBBBBBBBC------ CBBBBBBBBBBBBBBBBBC------ CBBBBBBBBBBBBBBBBBC------ CBBBBBBBBBBBBBBBBBC------ CBBBBBBBBBBBBBBBBBC------ C-BBBBBBBBBBBBBBBBCCCCCCC C-AAAAAKEEDDDDKKKKCCCCCCC C-DDAADEEEAAAADDDDC-----C C-DDAADEEEAAAADDDDC-----C C-DDDDDEEEAADDDDDDC-----C C-DDDDDEEEAADDDDDDC-----C C-DDDDDDDDDDDDDDD-C-----C C-DDDDDDDDDDDDDDD-C-----C C-DDDDDDDDDDDDDDD-C-----C C-DDDDDEEEAAAAAAA-C-----C C-DDDDDEEEAAAAAAA-C-----C C-FFFFFEEECCCCEEE-DCCCCCC C-GGGECCCCEEEEEEE-DCCCCCC C-GGGECCCCEEKEEEE-C------ C-GGGECCCCEEKEEEE-C------ C-GGGECCCCEEKEEEEEC------ C-EEEEEEEEEEKKECCCC------ CHMHHHHHHMMHHHHMNNC------ C--J-J-J-J-J-J-J--C------ ---------IIP------------- --------II-II------------ -------II--III----------- -----R-I----II----------- -------I----------------- 
BBBBBBBBBBBBBBBBBBB------ BBBBBBBBBBBBBBBBBBB------ BBBBBBBBBBBBBBBBBBB------ BBBBBBBBBBBBBBBBBBB------ BBBBBBBBBBBBBBBBBBB------ BBBBBBBBBBBBBBBBBBB------ B-BBBBBBBBBBBBBBBBBBBBBBB B-AAAAAKEEDDDDKKKKBBBBBBB B-DDAADEEEAAAADDDDB-----B B-DDAADEEEAAAADDDDB-----B B-DDDDDEEEAADDDDDDB-----B B-DDDDDEEEAADDDDDDB-----B A-DDDDDDDDDDDDDDD-A-----A A-DDDDDDDDDDDDDDD-A-----A A-DDDDDDDD-DDDDDD-A-----A A-DDDDDEEEA---AAA-A-----A B-DDDDDEEEA-A-AAA-B-----B B-FFFFFEEEE-E-EEE-DBBBBBB B-GGGECCCCEEEEEEE-BBBBBBB B-GGGECCCCEEKEEEE-B------ B-GGGECCCCEEKEEEE-B------ B-GGGECCCCEEKEEEEEB------ B-EEEEEEEEEEKKECCCB------ BHHMMHHMHHHMHHHHHNB------ B---J-J-J-J-J-J---B------ ---------III------------- ------------------------- ------------------------- -----I------------------- ------------------------- 
BBBBBBBBBBBBBBBBBBB------ BAAAAAAAAAAAAAAAAAB------ BAAAAAAAAAAAAAAAAAB------ BAAAAAAAAAAAAAAAAAB------ BCCCCCCCCCCCCCCAAAB------ BCCCCCCCCCCCCCCAAAB------ B-CCCCCCCCCCCCCAAADBBBBBB B-CCCCCCCCCCCCCAAADBBBBBB B-CCCCCCCCCCCCCDDDB-----B B-CCCCCCCCCCCCCDDDB-----B B-CCCCCCCCCCCCCDDDB-----B B-CCCCCCCCCCCCCDDDB-----B A-AACCCCCCCCCCCDD-A-----A A-AACCCCCCCCCCCDD-A-----A A-AACCCCCC-C-CCDD-A-----A A-AACCCCCCC---CDD-A-----A B-CCCCCCCCC-C-CDD-B-----B B-FFFFFFFFF-F-FFF-DBBBBBB B-GGGECCCCEEEFFFF-BBBBBBB B-GGGECCCCEEKFFFF-B------ B-GGGECCCCEEKFFFF-B------ B-GGGECCCCEEKFFFFFB------ B-EEEEEEEEEEKFFFFFB------ BHNHMHHHMHHHHHHHHNB------ B----J-J-J-J-J----B------ ---------PPP------------- --------PP-II------------ -------PPI--PI----------- -------P-----P----------- ------------------------- 
BBBBBBBBBBBBBBBBBBB------ BAAAAAAAAAAAAAAAAAB------ BAAAAAAAAAAAAAAAAAB------ BAAAAAAAAAAAAA---AB------ BCCCCCCCCCCCCC---AB------ BCCCCCCCCCCCCC---AB------ BCCCCCCCCCCCCC---AB------ BCCCCCCCCCCCCC---AB------ BCCCCCCCCCCCCC---DB------ BCCCCCCCCCCCCC---DB------ BCCCCCCCCCCCCC---DB------ BCCCCCCCCCCCCC---DB------ AAAACCCCCCCCCC---AA------ AAAACCCCCCCCCC---AA------ AAAACCCCCC-CCCCA-AA------ AAAACCCCCCC--CCAAAA------ BCCCCCCCCCC-CCCDDDB------ BFFFFFFFFFF-FFFFFFB------ BGGGGGCCCCEEEFFFFFB------ BGGGGGCCCCEEKFFFFFB------ BGGGGGCCCCEEKFFFFFB------ BGGGGGCCCCEEKFFFFFB------ BOEEEEEEEEEEKFFFFFB------ BHNNMHMHHHMHMNMHHNB------ B-----J-J-J-J-----B------ ----------R-------------- ----------I-------------- ------RPR---I------------ ------------------------- ------------------------- 
-BBBBBBBBBBBBBBBBB------- -BAAAAAAAAAAAAAAAB------- -BAAAAAAAAAAAAAAAB------- -BAAAAAAAAAAAA---B------- -BCCCCCCCCCCCC---B------- -BCCCCCCCCCCCC---B------- -BCCCCCCCCCCCC---B------- -BCCCCCCCCCCCC---B------- -BCCCCCCCCCCCC---B------- -BCCCCCCCCCCCC---B------- -BCCCCCCCCCCCC---B------- -BCCCCCCCCCCCC---B------- -AAACCCCCCCCCC---A------- -AAACCCCCCCCCC--AA------- -AAACCCCCC-C-CC-AA------- -AAACCCCCCC--CCAAA------- -BCCCCCCCCC-CCCDDB------- -BFFFFFFFFF-FFFF-B------- -BGGGGEEEEEEEFFFFB------- -BGGGGEEEEEEKFFFFB------- -BGGGGEEEEEEKFFFFB------- -BGGGGEEEEEEKFFFFB------- -BEEEEEEEEEEKFFFFB------- -BHHMMHHHHMMHNHHNB------- -B-----J-J-J-----B------- ------------------------- ----------RI------------- ------I----I------------- ------------------------- ------------------------- 
-BBBBBBBBBBBBBBBBB------- -BAAAAAAA-AAAAAAAB------- -BAAAAAAA-AAAAAAAB------- -BAAAAAAAAAAAAA-AB------- -BCCCCCCCCCC----AB------- -BCCCCCCCC------AB------- -BCCCCCCCC------AB------- -BCCCCCCCC------AB------- -BCCCCCCCC------DB------- -BCCCCCCCC------DB------- -BCCCCCCCC------DB------- -BCCCCCCCC------DB------- -AAACCCCCC------AA------- -AAACCCCCC------AA------- -AAACCCCCCC-CCCAAA------- -AAACCCCCCC--CCAAA------- -BCCCCCCCCC-CCCDDB------- -BFFFFFFFFF-FFFFFB------- -BGGGGEEEEEEEFFFFB------- -BGGGGEEEEEEKFFFFB------- -BGGGGEEEEEEKFFFFB------- -BGGGGEEEEEEKFFFFB------- -BOEEEEEEEEEKFFFFB------- -BHNNNMHHHHMHNHNNB------- -B------J-J------B------- ------------------------- ----------P-------------- ------------------------- ------------------------- ------------------------- 
--BBBBBBBBBBBBBBB-------- --BACCCCCCCCCCCCB-------- --BACCCCCCCCCCCCB-------- --BACCCCCCCC--CCB-------- --BCCCCCCCC----CB-------- --BCCCCCCC-----CB-------- --BCCCCCCC-----CB-------- --BCCCCCCC-----CB-------- --BCCCCCCC-----CB-------- --BCCCCCCC-----CB-------- --BC--CCCC-----CB-------- --BC--CCCC-----CB-------- --AA--CCCC-----AA-------- --AA--CCCC-----AA-------- --AA--CCCCCCCCCAA-------- --AA--CCCC-C-CCAA-------- --BC--CCCC--CCCDB-------- --BF--FFFF--FFFFB-------- --BG--EEEE--EFFFB-------- --BG--EEEE--KFFFB-------- --BG--EEEE--KFFFB-------- --BG--EEEE--KFFFB-------- --BOEEEEEEEEKFFFB-------- --BHHHHHMHHNNHNNB-------- --B------J------B-------- ------------------------- ------------------------- ------------------------- ------------------------- ------------------------- 
---BBBBBBBBBBBBB--------- ---BCCCCCCCCCCCB--------- ---BCCCCCCCCCCCB--------- ---BC----CCC--CB--------- ---BC----CC---CB--------- ---BC---------CB--------- ---BC---------CB--------- ---BC---------CB--------- ---BC---------CB--------- ---BC---------CB--------- ---BC---------CB--------- ---BC---------CB--------- ---AC---------AA--------- ---AC---------AA--------- ---AC------CAAAA--------- ---AC------CAAAA--------- ---BC-------CCCB--------- ---BF-------FFFB--------- ---BG-------EFFB--------- ---BG--------FFB--------- ---BG--------FFB--------- ---BG--------FFB--------- ---BOEEEEEEEAFFB--------- ---BHHHNMNNMHHNB--------- ---B-----------B--------- ------------------------- ------------------------- ------------------------- ------------------------- ------------------------- 
----BBBBBBBBBBB---------- ----BBCCCCCAABB---------- ----BBCCCCCAABB---------- ----BBC---C-ABB---------- ----BBC-----ABB---------- ----BBC-----ABB---------- ----BBC-----ABB---------- ----BBC-----ABB---------- ----BBC-----ABB---------- ----BBC-----ABB---------- ----BBC-----ABB---------- ----BBC-----ABB---------- ----AAA-----AAA---------- ----AAA-----AAA---------- ----AAA-----AAA---------- ----AAA-----AAA---------- ----BBC-----ABB---------- ----BBF-----ABB---------- ----BBO-----ABB---------- ----BBO-----ABB---------- ----BBO-----ABB---------- ----BBO-----ABB---------- ----BBOEEEEAABB---------- ----BBHHHNNHHBB---------- ----BB-------BB---------- ------------------------- ------------------------- ------------------------- ------------------------- ------------------------- 
------BBBAAAA------------ ------BBBAAAA------------ ------BBBAAAA------------ ------BBBAAAA------------ ------BBBAAAA------------ ------BBBAAAA------------ ------BBBAAAA------------ ------BBBAAAA------------ ------BBBAAAA------------ ------BBBAAAA------------ ------BBBAAAA------------ ------BBBAAAA------------ ------AAAAAAA------------ ------AAAAAAA------------ ------AAAAAAA------------ ------AAAAAAA------------ ------BBBAAAA------------ ------BBBAAAA------------ ------BBBAAAA------------ ------BBBAAAA------------ ------BBBAAAA------------ ------BBBAAAA------------ ------BBBAAAA------------ ------BBBAAAA------------ ------BBBAAAA------------ ------------------------- ------------------------- ------------------------- ------------------------- ------------------------- 
