model
size = 25 30 19, scale = 0.05, origin = -y
material 
  colors = A:#E00 B:#EEE C:#FF0 D:#CF3 E:#000 F:#06F G:#00C H:#251505 I:#BBB J:#CC6 K:#CF0 L:#939 M:#960 N:#1C0900 O:#AAAAB9 P:#AAA Q:#00F R:#888 S:#FCF
voxels
------BBBBAAA------------ ------BBBBAAA------------ ------BBBBAAA------------ ------BBBBAAA------------ ------BBBBAAA------------ ------BBBBAAA------------ ------BBBBAAA------------ ------BBBBAAA------------ ------BBBBAAA------------ ------BBBBAAA------------ ------BBBBAAA------------ ------BBBBAAA------------ ------BBBBBBB------------ ------BBBBBBB------------ ------BBBBBBB------------ ------BBBBBBB------------ ------BBBBAAA------------ ------BBBBAAA------------ ------BBBBAAA------------ ------BBBBAAA------------ ------BBBBAAA------------ ------BBBBAAA------------ ------BBBBAAA------------ ------BBBBAAA------------ ------BBBBAAA------------ ------------------------- ------------------------- ------------------------- ------P------------------ ------------------------- 
----AAAAAAAAAAA---------- ----AAC---CCCAA---------- ----AAC---CCCAA---------- ----AAB---CCCAA---------- ----AAB---CCCAA---------- ----AAB---CCCAA---------- ----AAB---CCCAA---------- ----AAB--CCCCAA---------- ----AAB--AAAAAA---------- ----AAB--AAAAAA---------- ----AAB--AAAAAA---------- ----AAB-AAAAAAA---------- ----BBCAAAAACBB---------- ----BBCAAAAAABB---------- ----BBCAAAAAABB---------- ----BBBAAAAACBB---------- ----AABAAAAAAAA---------- ----AABEEEEEEAA---------- ----AABDDDDDOAA---------- ----AAODDDDDOAA---------- ----AAODDDDDOAA---------- ----AAODDDDDOAA---------- ----AAODDDDDOAA---------- ----AAHHHHHHHAA---------- ----AA-------AA---------- ------------------------- ------------------------- ------------------------- ------I------------------ ------I------------------ 
---AAAAAAAAAAAAA--------- ---ACC--------BA--------- ---ACCCCCCCCCBBA--------- ---ACCCCCCCCCBBA--------- ---ACCCCCCCCCBBA--------- ---ACCCCCCCCCBBA--------- ---ACCCCCCCCCBBA--------- ---ACCCCCCCCCBBA--------- ---AAAAAAAAAABBA--------- ---AAAAAAAAAABBA--------- ---AAAACCCCCAABA--------- ---AAAAAAAAAAABA--------- ---BCCCAAAAACCCB--------- ---BCCCAAAAAACCB--------- ---BCCCAAAAAACCB--------- ---BACCCCCCCCCCB--------- ---AADDDDDCCAAAA--------- ---AEEEEEEEEEEEA--------- ---AGDDDDDDDDAAA--------- ---AGDDDDDDDDAAA--------- ---AGDDDDDDDDAAA--------- ---AGDDDDDDDDAAA--------- ---AODDDDDDDDDOA--------- ---AHHHHHHMNHHHA--------- ---A-----------A--------- ------------------------- ------------------------- ------------------------- ------------------------- ------II----------------- 
--AAAAAAAAAAAAAAA-------- --ACCCCCCCCCCBBBA-------- --ACCCCCCCCCCBBBA-------- --ACCCCCCCCCCBBBA-------- --ACCCCCCCCCCBBBA-------- --ABCCCCCCCCCBBBA-------- --ABCCCCCCCCCBBBA-------- --ABCCCCCCCCCBBBA-------- --ABCCCCCCCCCBBBA-------- --ABCC--------BBA-------- --ABAAACCCCCAAABA-------- --ABACAAAAAAAAABA-------- --BCAAAAAAAACCCCB-------- --BCCAAAAA-AACCCB-------- --BCAAAAAA-AACCCB-------- --BCACCCCC-CCCCCB-------- --ABADDDDD-CAAABA-------- --AEEEEEEE-EEEEEA-------- --AGGDDDDD-DDDDOA-------- --AGGDDDDD-DDDDOA-------- --AGGDDDDD-DDDDOA-------- --AGGDDDDD-DDDDOA-------- --AODDDDDD-DDDDBA-------- --AHHHHMHMHHNNHHA-------- --A------J------A-------- ------------------------- ------------------------- ------------------------- ---I--------------------- -------I----------------- 
-AAAAAAAAAAAAAAAAA------- -ACCCCCCCCCCCBB-BA------- -ACCCCCCCCCCCBB-BA------- -ACCCCCCCCCCCBB-BA------- -ACCCCCCCCCCCBB-BA------- -ACCCCCCCCCCCBB-BA------- -ACCCCCCCCCCCBB-BA------- -ACCCCCCCCCCCBB-BA------- -AAACCCCCCCCCBB-BA------- -AAACCCCCCCCCBB-BA------- -AA-AAAAAACCAAA-AA------- -AA-AAAAAAAAAAA-AA------- -BC-AAAAAAAACCC-CB------- -BC-CAAAAAAAACC-CB------- -BC-AAAAAAAAACC-CB------- -BCCAADDDDCCCCC-CB------- -AA-ADDDDDCCAAA-AA------- -AE-EEEEEEEEEEE-EA------- -AB-GDDDDDDDDDD-OA------- -AB-GDDDDDDDDDD-OA------- -AB-GDDDDDDDDDD-OA------- -ABGGDDDDDDDDDD-OA------- -AOCDDDDDDDDDDD-BA------- -AHHMHMHMHHMNMHHHA------- -A------J-J------A------- ------------------------- ------------------------- ------------------------- ---I--------------------- ---P---I----------------- 
-AAAAAAAAAAAAAAAAA------- -ACCCCCCCCCCCCQQQA------- -ACCCCCCCCCCCCQBBA------- -ACCCCCCCCCCCCQQQA------- -ACCCCCCCCCCCCCCCA------- -ACCCCCCCCCCCCCCCA------- -ACCCCCCCCCCCCCCCA------- -ACCCCCCCCCCCCCBBA------- -AAACCCCCCCCCCBBBA------- -AAACCCCCCCCCCBBBA------- -AAAAAAAAACCAAAAAA------- -AAAAAAAAAAAAAAAAA------- -BCCAAAAAAAACCCCCB------- -BCCCAAAAAAAACCCCB------- -BCCAAAAAAAAACCCCB------- -BCCAADDDDCCCCCCCB------- -AAAADDDDDCCAAAAAA------- -AEEEEEDDAAAAAAAAA------- -ABGGDDDDDDDDDDDDA------- -ABGGDDDDDDDDDDDDA------- -ABGGDDDDDDDDDDDDA------- -ABGGDDDDDDDDDDDDA------- -ADDDDDDDDDDDDDBBA------- -AMHMMHMHHHMHHMMHA------- -A-----J-J-J-----A------- ------------------------- ------------------------- ------------------------- ------------------------- ---R--IP----------------- 
AAAAAAAAAAAAAAAAAAA------ ACCCCCCCCCCCCCCCCBA------ ACCCCCCCCCCCCCCCCBA------ ACCCCCCCCCCCCCCCCBA------ ACCCCCCCCCCCCCCCCBA------ ACCCCCCCCCCCCCCCCBA------ ACCCCCCCCCCCCCCCCBA------ ACCCCCCCCCCCCCCCCBA------ AAAACCCCCCCCCCAAAAA------ AAAACCCCCCCCCCAAAAA------ AAAAAAAAAACCAAAAAAA------ AAAAAAAAAAAAAAAAAAA------ BCCCAAAAAAAACCCCCCB------ BCCCCAAAAAAAACCCCCB------ BCCCAAAAAAAAACCCCCB------ BCCCAADDDDCCCCCCCCB------ AAAAADDDDDCCCCCCCCA------ AEEEEEEDDAAAAAAAAEA------ AGGGGDDDDDDDDLLLDOA------ AGGGGDDDDDDDDLLLDOA------ AGGGGDDDDDDDDLLLDOA------ AGGGGDDDDDDDDLLLDOA------ AODDDDDDDDDDDLLBBBA------ AHHHHHMMHHHHHMNHHNA------ A-----J-J-J-J-----A------ ------------------------- ---------III------------- --------PI-II------------ ----PPPPP---II----------- ---PP-PP-----I----------- 
AAAAAAAAAAAAAAAAAAA------ ACCCCCCAAAAAAAABBBA------ ACCCCCCAAAAAAAABBBA------ ACCCCCCAAAAAAAABBBA------ ACCCCCCAAAAAAAABBBA------ ACCCCCCAAAAAAAABBBA------ A-CCCCCKDDDDKAKBBBBAAAAAA A-CCCCCCCCCCCCCCCCBAAAAAA A-AACCACCCCCCCAAAAA-----A A-AACCACCCCCCCAAAAA-----A A-AAAA--AACCAAAAAAA-----A A-AAAA------AAAAAAA-----A B-CCAA------A--AA-B-----B B-AAAAAAAAAAAAAAA-B-----B B-CCAAAAAAAAAAAAA-B-----B B-CCAADDDDCCCCCCC-B-----B A-AAADDDDDCCCCCCC-A-----A A-EEEEEDDDBBBLLLD-FAAAAAA A-GGGDDDDDDDDLLLD-FAAAAAA A-GGGDDDDDDDDLLLD-A------ A-GGGDDDDDDDDLLLD-A------ A-GGGDDDDDDDDLLLDDA------ A-DDDDDDDDDDDLLBBBA------ AHHHHHHHHMHHHMHMNHA------ A----J-J-J-J-J----A------ ------------------------- ---------III------------- ------------------------- ----PII------------------ ------------------------- 
AAAAAAAAAAAAAAAAAAA------ ACCCCCCAAAAAAAABBBA------ ACCCCCCAAAAAAAABBBA------ ACCCCCCAAAAAAAABBBA------ ACCCCCCAAAAAAAABBBA------ ACCCCCCAAAAAAAABBBA------ A-CCCCCKDDDDKAKKKKCAAAAAA A-CCCCCCCCCCCCCCCCCAAAAAA A-AACCACCCCCCCAAAAA-----A A-AACCACCCCCCCAAAAA-----A A-AAAA--AACCAAAAAAA-----A A-AAAA------AAAAAAA-----A B-AAAA------A-AAA-B-----B B-AAAAAAAAAAAAAAA-B-----B B-AAAAAAAAAAAAAAA-B-----B B-AAAAADDDCCCCCCC-B-----B A-AAAAADDDCCCCCCC-A-----A A-EEEEEDDDBBBLLLD-AAAAAAA A-GGGDDDDDDDDLLLD-FAAAAAA A-GGGDDDDDDDDLLLD-A------ A-GGGDDDDDDDDLLLD-A------ A-GGGDDDDDDDDLLLDDA------ A-DDDDDDDDDDDLLBBBA------ AHHHHHHMHHHHHHHHHNA------ A---J-J-J-J-J-J---A------ ------------------------- ---------III------------- --------PI-II------------ ----PPPSP---II----------- ---PP-II-----I----------- 
BAAAAAAAAAAAAAAAAAB------ BFFFFFFFFFFFFFFFFFB------ BFFFFFFFFFFFFFFFFFB------ BFFFFFFFFFFFFFFFFFB------ BFFFFFFFFFFFFFFFFFB------ BFFFFFFFFFFFFFFFFFB------ B-FFFFFFFFFFFFFFFFBBBBBBB B-CCCCCKDDAAAAKKKKBBBBBBB B-AACCADDDCCCCAAAAB-----B B-AACCADDDCCCCAAAAB-----B B-AAAAADDDCCAAAAAAB-----B B-AAAAADDDCCAAAAAAB-----B B-AAAAAAAAAAAAAAA-B-----B B-AAAAAAAAAAAAAAA-B-----B B-AAAAAAAAAAAAAAA-B-----B B-AAAAADDDCCCCCCC-B-----B B-AAAAADDDCCCCCCC-B-----B B-EEEEEDDDBBBBDDD-ABBBBBB B-GGGDBBBBDDDDDDD-ABBBBBB B-GGGDBBBBDDKDDDD-B------ B-GGGDBBBBDDKDDDD-B------ B-GGGDBBBBDDKDDDDDB------ B-DDDDDDDDDDKKDBBBB------ BHMHHHHHHMMHHHHMNNB------ B--J-J-J-J-J-J-J--B------ ---------IIP------------- --------II-II------------ -------II--III----------- -----R-I----II----------- -------I----------------- 
AAAAAAAAAAAAAAAAAAA------ AFFFFFFFFFFFFFFFFFA------ AFFFFFFFFFFFFFFFFFA------ AFFFFFFFFFFFFFFFFFA------ AFFFFFFFFFFFFFFFFFA------ AFFFFFFFFFFFFFFFFFA------ A-FFFFFFFFFFFFFFFFFAAAAAA A-CCCCCKDDAAAAKKKKFAAAAAA A-AACCADDDCCCCAAAAA-----A A-AACCADDDCCCCAAAAA-----A A-AAAAADDDCCAAAAAAA-----A A-AAAAADDDCCAAAAAAA-----A B-AAAAAAAAAAAAAAA-B-----B B-AAAAAAAAAAAAAAA-B-----B B-AAAAAAAA-AAAAAA-B-----B B-AAAAADDDC---CCC-B-----B A-AAAAADDDC-C-CCC-A-----A A-EEEEEDDDD-D-DDD-AAAAAAA A-GGGDBBBBDDDDDDD-FAAAAAA A-GGGDBBBBDDKDDDD-A------ A-GGGDBBBBDDKDDDD-A------ A-GGGDBBBBDDKDDDDDA------ A-DDDDDDDDDDKKDBBBA------ AHHMMHHMHHHMHHHHHNA------ A---J-J-J-J-J-J---A------ ---------III------------- ------------------------- ------------------------- -----I------------------- ------------------------- 
AAAAAAAAAAAAAAAAAAA------ ACCCCCCCCCCCCCCCCCA------ ACCCCCCCCCCCCCCCCCA------ ACCCCCCCCCCCCCCCCCA------ ABBBBBBBBBBBBBBCCCA------ ABBBBBBBBBBBBBBCCCA------ A-BBBBBBBBBBBBBCCCAAAAAAA A-BBBBBBBBBBBBBCCCAAAAAAA A-BBBBBBBBBBBBBAAAA-----A A-BBBBBBBBBBBBBAAAA-----A A-BBBBBBBBBBBBBAAAA-----A A-BBBBBBBBBBBBBAAAA-----A B-CCBBBBBBBBBBBAA-B-----B B-CCBBBBBBBBBBBAA-B-----B B-CCBBBBBB-B-BBAA-B-----B B-CCBBBBBBB---BAA-B-----B A-BBBBBBBBB-B-BAA-A-----A A-EEEEEEEEE-E-EEE-AAAAAAA A-GGGDBBBBDDDEEEE-FAAAAAA A-GGGDBBBBDDKEEEE-A------ A-GGGDBBBBDDKEEEE-A------ A-GGGDBBBBDDKEEEEEA------ A-DDDDDDDDDDKEEEEEA------ AHNHMHHHMHHHHHHHHNA------ A----J-J-J-J-J----A------ ---------PPP------------- --------PP-II------------ -------PPI--PI----------- -------P-----P----------- ------------------------- 
AAAAAAAAAAAAAAAAAAA------ ACCCCCCCCCCCCCCCCCA------ ACCCCCCCCCCCCCCCCCA------ ACCCCCCCCCCCCC---CA------ ABBBBBBBBBBBBB---CA------ ABBBBBBBBBBBBB---CA------ ABBBBBBBBBBBBB---CA------ ABBBBBBBBBBBBB---CA------ ABBBBBBBBBBBBB---AA------ ABBBBBBBBBBBBB---AA------ ABBBBBBBBBBBBB---AA------ ABBBBBBBBBBBBB---AA------ BCCCBBBBBBBBBB---CB------ BCCCBBBBBBBBBB---CB------ BCCCBBBBBB-BBBBC-CB------ BCCCBBBBBBB--BBCCCB------ ABBBBBBBBBB-BBBAAAA------ AEEEEEEEEEE-EEEEEEA------ AGGGGGBBBBDDDEEEEEA------ AGGGGGBBBBDDKEEEEEA------ AGGGGGBBBBDDKEEEEEA------ AGGGGGBBBBDDKEEEEEA------ AODDDDDDDDDDKEEEEEA------ AHNNMHMHHHMHMNMHHNA------ A-----J-J-J-J-----A------ ----------R-------------- ----------I-------------- ------RPR---I------------ ------------------------- ------------------------- 
-AAAAAAAAAAAAAAAAA------- -ACCCCCCCCCCCCCCCA------- -ACCCCCCCCCCCCCCCA------- -ACCCCCCCCCCCC---A------- -ABBBBBBBBBBBB---A------- -ABBBBBBBBBBBB---A------- -ABBBBBBBBBBBB---A------- -ABBBBBBBBBBBB---A------- -ABBBBBBBBBBBB---A------- -ABBBBBBBBBBBB---A------- -ABBBBBBBBBBBB---A------- -ABBBBBBBBBBBB---A------- -BCCBBBBBBBBBB---B------- -BCCBBBBBBBBBB--CB------- -BCCBBBBBB-B-BB-CB------- -BCCBBBBBBB--BBCCB------- -ABBBBBBBBB-BBBAAA------- -AEEEEEEEEE-EEEE-A------- -AGGGGDDDDDDDEEEEA------- -AGGGGDDDDDDKEEEEA------- -AGGGGDDDDDDKEEEEA------- -AGGGGDDDDDDKEEEEA------- -ADDDDDDDDDDKEEEEA------- -AHHMMHHHHMMHNHHNA------- -A-----J-J-J-----A------- ------------------------- ----------RI------------- ------I----I------------- ------------------------- ------------------------- 
-AAAAAAAAAAAAAAAAA------- -ACCCCCCC-CCCCCCCA------- -ACCCCCCC-CCCCCCCA------- -ACCCCCCCCCCCCC-CA------- -ABBBBBBBBBB----CA------- -ABBBBBBBB------CA------- -ABBBBBBBB------CA------- -ABBBBBBBB------CA------- -ABBBBBBBB------AA------- -ABBBBBBBB------AA------- -ABBBBBBBB------AA------- -ABBBBBBBB------AA------- -BCCBBBBBB------CB------- -BCCBBBBBB------CB------- -BCCBBBBBBB-BBBCCB------- -BCCBBBBBBB--BBCCB------- -ABBBBBBBBB-BBBAAA------- -AEEEEEEEEE-EEEEEA------- -AGGGGDDDDDDDEEEEA------- -AGGGGDDDDDDKEEEEA------- -AGGGGDDDDDDKEEEEA------- -AGGGGDDDDDDKEEEEA------- -AODDDDDDDDDKEEEEA------- -AHNNNMHHHHMHNHNNA------- -A------J-J------A------- ------------------------- ----------P-------------- ------------------------- ------------------------- ------------------------- 
--AAAAAAAAAAAAAAA-------- --ACBBBBBBBBBBBBA-------- --ACBBBBBBBBBBBBA-------- --ACBBBBBBBB--BBA-------- --ABBBBBBBB----BA-------- --ABBBBBBB-----BA-------- --ABBBBBBB-----BA-------- --ABBBBBBB-----BA-------- --ABBBBBBB-----BA-------- --ABBBBBBB-----BA-------- --AB--BBBB-----BA-------- --AB--BBBB-----BA-------- --BC--BBBB-----CB-------- --BC--BBBB-----CB-------- --BC--BBBBBBBBBCB-------- --BC--BBBB-B-BBCB-------- --AB--BBBB--BBBAA-------- --AE--EEEE--EEEEA-------- --AG--DDDD--DEEEA-------- --AG--DDDD--KEEEA-------- --AG--DDDD--KEEEA-------- --AG--DDDD--KEEEA-------- --AODDDDDDDDKEEEA-------- --AHHHHHMHHNNHNNA-------- --A------J------A-------- ------------------------- ------------------------- ------------------------- ------------------------- ------------------------- 
---AAAAAAAAAAAAA--------- ---ABBBBBBBBBBBA--------- ---ABBBBBBBBBBBA--------- ---AB----BBB--BA--------- ---AB----BB---BA--------- ---AB---------BA--------- ---AB---------BA--------- ---AB---------BA--------- ---AB---------BA--------- ---AB---------BA--------- ---AB---------BA--------- ---AB---------BA--------- ---BB---------CB--------- ---BB---------CB--------- ---BB------BCCCB--------- ---BB------BCCCB--------- ---AB-------BBBA--------- ---AE-------EEEA--------- ---AG-------DEEA--------- ---AG--------EEA--------- ---AG--------EEA--------- ---AG--------EEA--------- ---AODDDDDDDCEEA--------- ---AHHHNMNNMHHNA--------- ---A-----------A--------- ------------------------- ------------------------- ------------------------- ------------------------- ------------------------- 
----AAAAAAAAAAA---------- ----AABBBBBCCAA---------- ----AABBBBBCCAA---------- ----AAB---B-CAA---------- ----AAB-----CAA---------- ----AAB-----CAA---------- ----AAB-----CAA---------- ----AAB-----CAA---------- ----AAB-----CAA---------- ----AAB-----CAA---------- ----AAB-----CAA---------- ----AAB-----CAA---------- ----BBC-----CBB---------- ----BBC-----CBB---------- ----BBC-----CBB---------- ----BBC-----CBB---------- ----AAB-----CAA---------- ----AAE-----CAA---------- ----AAO-----CAA---------- ----AAO-----CAA---------- ----AAO-----CAA---------- ----AAO-----CAA---------- ----AAODDDDCCAA---------- ----AAHHHNNHHAA---------- ----AA-------AA---------- ------------------------- ------------------------- ------------------------- ------------------------- ------------------------- 
------AAABBBB------------ ------AAABBBB------------ ------AAABBBB------------ ------AAABBBB------------ ------AAABBBB------------ ------AAABBBB------------ ------AAABBBB------------ ------AAABBBB------------ ------AAABBBB------------ ------AAABBBB------------ ------AAABBBB------------ ------AAABBBB------------ ------BBBBBBB------------ ------BBBBBBB------------ ------BBBBBBB------------ ------BBBBBBB------------ ------AAABBBB------------ ------AAABBBB------------ ------AAABBBB------------ ------AAABBBB------------ ------AAABBBB------------ ------AAABBBB------------ ------AAABBBB------------ ------AAABBBB------------ ------AAABBBB------------ ------------------------- ------------------------- ------------------------- ------------------------- ------------------------- 
