model
size = 25 30 19, scale = 0.05, origin = -y
material 
  colors = A:#E00 B:#EEE C:#FF0 D:#CF3 E:#30F F:#000 G:#06F H:#00C I:#251505 J:#BBB K:#CC6 L:#CF0 M:#939 N:#960 O:#1C0900 P:#AAAAB9 Q:#AAA R:#00F S:#888 T:#FCF
voxels
------BEEBAAA------------ ------BEEBAAA------------ ------BEEBAAA------------ ------BEEBAAA------------ ------BEEBAAA------------ ------BEEBAAA------------ ------BEEBAAA------------ ------BEEBAAA------------ ------BEEBAAA------------ ------BEEBAAA------------ ------BEEBAAA------------ ------BEEBAAA------------ ------BEEBBBB------------ ------EEEEEEE------------ ------EEEEEEE------------ ------BEEBBBB------------ ------BEEBAAA------------ ------BEEBAAA------------ ------BEEBAAA------------ ------BEEBAAA------------ ------BEEBAAA------------ ------BEEBAAA------------ ------BEEBAAA------------ ------BEEBAAA------------ ------BEEBAAA------------ ------------------------- ------------------------- ------------------------- ------Q------------------ ------------------------- 
----AAAAAAAAAAA---------- ----AAC---CCCAA---------- ----AAC---CCCAA---------- ----AAB---CCCAA---------- ----AAB---CCCAA---------- ----AAB---CCCAA---------- ----AAB---CCCAA---------- ----AAB--CCCCAA---------- ----AAB--AAAAAA---------- ----AAB--AAAAAA---------- ----AAB--AAAAAA---------- ----AAB-AAAAAAA---------- ----BBCAAAAACBB---------- ----EEEEEEEEEEE---------- ----EECAAAAAAEE---------- ----BBBAAAAACBB---------- ----AABAAAAAAAA---------- ----AABFFFFFFAA---------- ----AABDDDDDPAA---------- ----AAPDDDDDPAA---------- ----AAPDDDDDPAA---------- ----AAPDDDDDPAA---------- ----AAPDDDDDPAA---------- ----AAIIIIIIIAA---------- ----AA-------AA---------- ------------------------- ------------------------- ------------------------- ------J------------------ ------J------------------ 
---AAAAAAAAAAAAA--------- ---ACC--------BA--------- ---ACCCCCCCCCBBA--------- ---ACCCCCCCCCBBA--------- ---ACCCCCCCCCBBA--------- ---ACCCCCCCCCBBA--------- ---ACCCCCCCCCBBA--------- ---ACCCCCCCCCBBA--------- ---AAAAAAAAAABBA--------- ---AAAAAAAAAABBA--------- ---AAAACCCCCAABA--------- ---AAAAAAAAAAABA--------- ---BCCCAAAAACCCB--------- ---EEECAAAAAACEE--------- ---EEECAAAAAAEEE--------- ---BACCCCCCCCCCB--------- ---AADDDDDCCAAAA--------- ---AFFFFFFFFFFFA--------- ---AHDDDDDDDDAAA--------- ---AHDDDDDDDDAAA--------- ---AHDDDDDDDDAAA--------- ---AHDDDDDDDDAAA--------- ---APDDDDDDDDDPA--------- ---AIIIIIINOIIIA--------- ---A-----------A--------- ------------------------- ------------------------- ------------------------- ------------------------- ------JJ----------------- 
--AAAAAAAAAAAAAAA-------- --ACCCCCCCCCCBBBA-------- --ACCCCCCCCCCBBBA-------- --ACCCCCCCCCCBBBA-------- --ACCCCCCCCCCBBBA-------- --ABCCCCCCCCCBBBA-------- --ABCCCCCCCCCBBBA-------- --ABCCCCCCCCCBBBA-------- --ABCCCCCCCCCBBBA-------- --ABCC--------BBA-------- --ABAAACCCCCAAABA-------- --ABACAAAAAAAAABA-------- --BCAAAAAAAACCCCB-------- --EEEEAAAA-AACEEE-------- --EEEEAAAA-AAEEEE-------- --BCACCCCC-CCCCCB-------- --ABADDDDD-CAAABA-------- --AFFFFFFF-FFFFFA-------- --AHHDDDDD-DDDDPA-------- --AHHDDDDD-DDDDPA-------- --AHHDDDDD-DDDDPA-------- --AHHDDDDD-DDDDPA-------- --APDDDDDD-DDDDBA-------- --AIIIININIIOOIIA-------- --A------K------A-------- ------------------------- ------------------------- ------------------------- ---J--------------------- -------J----------------- 
-AAAAAAAAAAAAAAAAA------- -ACCCCCCCCCCCBB-BA------- -ACCCCCCCCCCCBB-BA------- -ACCCCCCCCCCCBB-BA------- -ACCCCCCCCCCCBB-BA------- -ACCCCCCCCCCCBB-BA------- -ACCCCCCCCCCCBB-BA------- -ACCCCCCCCCCCBB-BA------- -AAACCCCCCCCCBB-BA------- -AAACCCCCCCCCBB-BA------- -AA-AAAAAACCAAA-AA------- -AA-AAAAAAAAAAA-AA------- -BC-AAAAAAAACCC-CB------- -EE-EEAAAAAAACE-EE------- -EE-EEAAAAAAAEE-EE------- -BCCAADDDDCCCCC-CB------- -AA-ADDDDDCCAAA-AA------- -AF-FFFFFFFFFFF-FA------- -AB-HDDDDDDDDDD-PA------- -AB-HDDDDDDDDDD-PA------- -AB-HDDDDDDDDDD-PA------- -ABHHDDDDDDDDDD-PA------- -APCDDDDDDDDDDD-BA------- -AIINININIINONIIIA------- -A------K-K------A------- ------------------------- ------------------------- ------------------------- ---J--------------------- ---Q---J----------------- 
-AAAAAAAAAAAAAAAAA------- -ACCCCCCCCCCCCRRRA------- -ACCCCCCCCCCCCRBBA------- -ACCCCCCCCCCCCRRRA------- -ACCCCCCCCCCCCCCCA------- -ACCCCCCCCCCCCCCCA------- -ACCCCCCCCCCCCCCCA------- -ACCCCCCCCCCCCCBBA------- -AAACCCCCCCCCCBBBA------- -AAACCCCCCCCCCBBBA------- -AAAAAAAAACCAAAAAA------- -AAAAAAAAAAAAAAAAA------- -BCCAAAAAAAACCCCCB------- -EEEEEAAAAAAACEEEE------- -EEEEEAAAAAAAEEEEE------- -BCCAADDDDCCCCCCCB------- -AAAADDDDDCCAAAAAA------- -AFFFFFDDAAAAAAAAA------- -ABHHDDDDDDDDDDDDA------- -ABHHDDDDDDDDDDDDA------- -ABHHDDDDDDDDDDDDA------- -ABHHDDDDDDDDDDDDA------- -ADDDDDDDDDDDDDBBA------- -ANINNINIIINIINNIA------- -A-----K-K-K-----A------- ------------------------- ------------------------- ------------------------- ------------------------- ---S--JQ----------------- 
AAAAAAAAAAAAAAAAAAA------ ACCCCCCCCCCCCCCCCBA------ ACCCCCCCCCCCCCCCCBA------ ACCCCCCCCCCCCCCCCBA------ ACCCCCCCCCCCCCCCCBA------ ACCCCCCCCCCCCCCCCBA------ ACCCCCCCCCCCCCCCCBA------ ACCCCCCCCCCCCCCCCBA------ AAAACCCCCCCCCCAAAAA------ AAAACCCCCCCCCCAAAAA------ AAAAAAAAAACCAAAAAAA------ AAAAAAAAAAAAAAAAAAA------ BCCCAAAAAAAACCCCCCB------ ECCCCAAAAAAAACEEEEE------ EEEEEEAAAAAAAEEEEEE------ BCCCAADDDDCCCCCCCCB------ AAAAADDDDDCCCCCCCCA------ AFFFFFFDDAAAAAAAAFA------ AHHHHDDDDDDDDMMMDPA------ AHHHHDDDDDDDDMMMDPA------ AHHHHDDDDDDDDMMMDPA------ AHHHHDDDDDDDDMMMDPA------ APDDDDDDDDDDDMMBBBA------ AIIIIINNIIIIINOIIOA------ A-----K-K-K-K-----A------ ------------------------- ---------JJJ------------- --------QJ-JJ------------ ----QQQQQ---JJ----------- ---QQ-QQ-----J----------- 
AAAAAAAAAAAAAAAAAAA------ ACCCCCCAAAAAAAABBBA------ ACCCCCCAAAAAAAABBBA------ ACCCCCCAAAAAAAABBBA------ ACCCCCCAAAAAAAABBBA------ ACCCCCCAAAAAAAABBBA------ A-CCCCCLDDDDLALBBBBAAAAAA A-CCCCCCCCCCCCCCCCBAAAAAA A-AACCACCCCCCCAAAAA-----A A-AACCACCCCCCCAAAAA-----A A-AAAA--AACCAAAAAAA-----A A-AAAA------AAAAAAA-----A B-CCAA------A--AA-B-----B E-AAAAAAAAAAAAEEE-E-----E E-CCAAAAAAAAAEEEE-E-----E B-CCAADDDDCCCCCCC-B-----B A-AAADDDDDCCCCCCC-A-----A A-FFFFFDDDBBBMMMD-GAAAAAA A-HHHDDDDDDDDMMMD-GAAAAAA A-HHHDDDDDDDDMMMD-A------ A-HHHDDDDDDDDMMMD-A------ A-HHHDDDDDDDDMMMDDA------ A-DDDDDDDDDDDMMBBBA------ AIIIIIIIINIIININOIA------ A----K-K-K-K-K----A------ ------------------------- ---------JJJ------------- ------------------------- ----QJJ------------------ ------------------------- 
AAAAAAAAAAAAAAAAAAA------ ACCCCCCAAAAAAAABBBA------ ACCCCCCAAAAAAAABBBA------ ACCCCCCAAAAAAAABBBA------ ACCCCCCAAAAAAAABBBA------ ACCCCCCAAAAAAAABBBA------ A-CCCCCLDDDDLALLLLCAAAAAA A-CCCCCCCCCCCCCCCCCAAAAAA A-AACCACCCCCCCAAAAA-----A A-AACCACCCCCCCAAAAA-----A A-AAAA--AACCAAAAAAA-----A A-AAAA------AAAAAAA-----A B-AAAA------A-AAA-B-----B E-AAAAAAAAAAAAEEE-E-----E E-AAAAAAAAAAAEEEE-E-----E B-AAAAADDDCCCCCCC-B-----B A-AAAAADDDCCCCCCC-A-----A A-FFFFFDDDBBBMMMD-AAAAAAA A-HHHDDDDDDDDMMMD-GAAAAAA A-HHHDDDDDDDDMMMD-A------ A-HHHDDDDDDDDMMMD-A------ A-HHHDDDDDDDDMMMDDA------ A-DDDDDDDDDDDMMBBBA------ AIIIIIINIIIIIIIIIOA------ A---K-K-K-K-K-K---A------ ------------------------- ---------JJJ------------- --------QJ-JJ------------ ----QQQTQ---JJ----------- ---QQ-JJ-----J----------- 
BAAAAAAAAAAAAAAAAAB------ BGGGGGGGGGGGGGGGGGB------ BGGGGGGGGGGGGGGGGGB------ BGGGGGGGGGGGGGGGGGB------ BGGGGGGGGGGGGGGGGGB------ BGGGGGGGGGGGGGGGGGB------ B-GGGGGGGGGGGGGGGGBBBBBBB B-CCCCCLDDAAAALLLLBBBBBBB B-AACCADDDCCCCAAAAB-----B B-AACCADDDCCCCAAAAB-----B B-AAAAADDDCCAAAAAAB-----B B-AAAAADDDCCAAAAAAB-----B B-AAAAAAAAAAAAAAA-B-----B B-AAAAAAAAAAAAAAA-B-----B B-AAAAAAAAAAAAAAA-B-----B B-AAAAADDDCCCCCCC-B-----B B-AAAAADDDCCCCCCC-B-----B B-FFFFFDDDBBBBDDD-ABBBBBB B-HHHDBBBBDDDDDDD-ABBBBBB B-HHHDBBBBDDLDDDD-B------ B-HHHDBBBBDDLDDDD-B------ B-HHHDBBBBDDLDDDDDB------ B-DDDDDDDDDDLLDBBBB------ BINIIIIIINNIIIINOOB------ B--K-K-K-K-K-K-K--B------ ---------JJQ------------- --------JJ-JJ------------ -------JJ--JJJ----------- -----S-J----JJ----------- -------J----------------- 
AAAAAAAAAAAAAAAAAAA------ AGGGGGGGGGGGGGGGGGA------ AGGGGGGGGGGGGGGGGGA------ AGGGGGGGGGGGGGGGGGA------ AGGGGGGGGGGGGGGGGGA------ AGGGGGGGGGGGGGGGGGA------ A-GGGGGGGGGGGGGGGGGAAAAAA A-CCCCCLDDAAAALLLLGAAAAAA A-AACCADDDCCCCAAAAA-----A A-AACCADDDCCCCAAAAA-----A A-AAAAADDDCCAAAAAAA-----A A-AAAAADDDCCAAAAAAA-----A B-AAAAAAAAAAAAAAA-B-----B E-AAAAAAAAAAAEEEE-E-----E E-AAAAAAAA-AAAEEE-E-----E B-AAAAADDDC---CCC-B-----B A-AAAAADDDC-C-CCC-A-----A A-FFFFFDDDD-D-DDD-AAAAAAA A-HHHDBBBBDDDDDDD-GAAAAAA A-HHHDBBBBDDLDDDD-A------ A-HHHDBBBBDDLDDDD-A------ A-HHHDBBBBDDLDDDDDA------ A-DDDDDDDDDDLLDBBBA------ AIINNIINIIINIIIIIOA------ A---K-K-K-K-K-K---A------ ---------JJJ------------- ------------------------- ------------------------- -----J------------------- ------------------------- 
AAAAAAAAAAAAAAAAAAA------ ACCCCCCCCCCCCCCCCCA------ ACCCCCCCCCCCCCCCCCA------ ACCCCCCCCCCCCCCCCCA------ ABBBBBBBBBBBBBBCCCA------ ABBBBBBBBBBBBBBCCCA------ A-BBBBBBBBBBBBBCCCAAAAAAA A-BBBBBBBBBBBBBCCCAAAAAAA A-BBBBBBBBBBBBBAAAA-----A A-BBBBBBBBBBBBBAAAA-----A A-BBBBBBBBBBBBBAAAA-----A A-BBBBBBBBBBBBBAAAA-----A B-CCBBBBBBBBBBBAA-B-----B E-CCBBBBBBBBBEEEE-E-----E E-CCBBBBBB-B-BEEE-E-----E B-CCBBBBBBB---BAA-B-----B A-BBBBBBBBB-B-BAA-A-----A A-FFFFFFFFF-F-FFF-AAAAAAA A-HHHDBBBBDDDFFFF-GAAAAAA A-HHHDBBBBDDLFFFF-A------ A-HHHDBBBBDDLFFFF-A------ A-HHHDBBBBDDLFFFFFA------ A-DDDDDDDDDDLFFFFFA------ AIOINIIINIIIIIIIIOA------ A----K-K-K-K-K----A------ ---------QQQ------------- --------QQ-JJ------------ -------QQJ--QJ----------- -------Q-----Q----------- ------------------------- 
AAAAAAAAAAAAAAAAAAA------ ACCCCCCCCCCCCCCCCCA------ ACCCCCCCCCCCCCCCCCA------ ACCCCCCCCCCCCC---CA------ ABBBBBBBBBBBBB---CA------ ABBBBBBBBBBBBB---CA------ ABBBBBBBBBBBBB---CA------ ABBBBBBBBBBBBB---CA------ ABBBBBBBBBBBBB---AA------ ABBBBBBBBBBBBB---AA------ ABBBBBBBBBBBBB---AA------ ABBBBBBBBBBBBB---AA------ BCCCBBBBBBBBBB---CB------ EEEEEEEEBBBBBE---EE------ EEEEEEEEBB-BBBEE-EE------ BCCCBBBBBBB--BBCCCB------ ABBBBBBBBBB-BBBAAAA------ AFFFFFFFFFF-FFFFFFA------ AHHHHHBBBBDDDFFFFFA------ AHHHHHBBBBDDLFFFFFA------ AHHHHHBBBBDDLFFFFFA------ AHHHHHBBBBDDLFFFFFA------ APDDDDDDDDDDLFFFFFA------ AIOONINIIININONIIOA------ A-----K-K-K-K-----A------ ----------S-------------- ----------J-------------- ------SQS---J------------ ------------------------- ------------------------- 
-AAAAAAAAAAAAAAAAA------- -ACCCCCCCCCCCCCCCA------- -ACCCCCCCCCCCCCCCA------- -ACCCCCCCCCCCC---A------- -ABBBBBBBBBBBB---A------- -ABBBBBBBBBBBB---A------- -ABBBBBBBBBBBB---A------- -ABBBBBBBBBBBB---A------- -ABBBBBBBBBBBB---A------- -ABBBBBBBBBBBB---A------- -ABBBBBBBBBBBB---A------- -ABBBBBBBBBBBB---A------- -BCCBBBBBBBBBB---B------- -EEEEEEEBBBBBE--EE------- -EEEEEEEBB-B-BE-EE------- -BCCBBBBBBB--BBCCB------- -ABBBBBBBBB-BBBAAA------- -AFFFFFFFFF-FFFF-A------- -AHHHHDDDDDDDFFFFA------- -AHHHHDDDDDDLFFFFA------- -AHHHHDDDDDDLFFFFA------- -AHHHHDDDDDDLFFFFA------- -ADDDDDDDDDDLFFFFA------- -AIINNIIIINNIOIIOA------- -A-----K-K-K-----A------- ------------------------- ----------SJ------------- ------J----J------------- ------------------------- ------------------------- 
-AAAAAAAAAAAAAAAAA------- -ACCCCCCC-CCCCCCCA------- -ACCCCCCC-CCCCCCCA------- -ACCCCCCCCCCCCC-CA------- -ABBBBBBBBBB----CA------- -ABBBBBBBB------CA------- -ABBBBBBBB------CA------- -ABBBBBBBB------CA------- -ABBBBBBBB------AA------- -ABBBBBBBB------AA------- -ABBBBBBBB------AA------- -ABBBBBBBB------AA------- -BCCBBBBBB------CB------- -EEEEEEEBB------EE------- -EEEEEEEBBB-BBEEEE------- -BCCBBBBBBB--BBCCB------- -ABBBBBBBBB-BBBAAA------- -AFFFFFFFFF-FFFFFA------- -AHHHHDDDDDDDFFFFA------- -AHHHHDDDDDDLFFFFA------- -AHHHHDDDDDDLFFFFA------- -AHHHHDDDDDDLFFFFA------- -APDDDDDDDDDLFFFFA------- -AIOOONIIIINIOIOOA------- -A------K-K------A------- ------------------------- ----------Q-------------- ------------------------- ------------------------- ------------------------- 
--AAAAAAAAAAAAAAA-------- --ACBBBBBBBBBBBBA-------- --ACBBBBBBBBBBBBA-------- --ACBBBBBBBB--BBA-------- --ABBBBBBBB----BA-------- --ABBBBBBB-----BA-------- --ABBBBBBB-----BA-------- --ABBBBBBB-----BA-------- --ABBBBBBB-----BA-------- --ABBBBBBB-----BA-------- --AB--BBBB-----BA-------- --AB--BBBB-----BA-------- --BC--BBBB-----CB-------- --EE--EEBB-----EE-------- --EE--EEBBBBBBEEE-------- --BC--BBBB-B-BBCB-------- --AB--BBBB--BBBAA-------- --AF--FFFF--FFFFA-------- --AH--DDDD--DFFFA-------- --AH--DDDD--LFFFA-------- --AH--DDDD--LFFFA-------- --AH--DDDD--LFFFA-------- --APDDDDDDDDLFFFA-------- --AIIIIINIIOOIOOA-------- --A------K------A-------- ------------------------- ------------------------- ------------------------- ------------------------- ------------------------- 
---AAAAAAAAAAAAA--------- ---ABBBBBBBBBBBA--------- ---ABBBBBBBBBBBA--------- ---AB----BBB--BA--------- ---AB----BB---BA--------- ---AB---------BA--------- ---AB---------BA--------- ---AB---------BA--------- ---AB---------BA--------- ---AB---------BA--------- ---AB---------BA--------- ---AB---------BA--------- ---BB---------CB--------- ---EE---------EE--------- ---EE------BCCEE--------- ---BB------BCCCB--------- ---AB-------BBBA--------- ---AF-------FFFA--------- ---AH-------DFFA--------- ---AH--------FFA--------- ---AH--------FFA--------- ---AH--------FFA--------- ---APDDDDDDDCFFA--------- ---AIIIONOONIIOA--------- ---A-----------A--------- ------------------------- ------------------------- ------------------------- ------------------------- ------------------------- 
----AAAAAAAAAAA---------- ----AABBBBBCCAA---------- ----AABBBBBCCAA---------- ----AAB---B-CAA---------- ----AAB-----CAA---------- ----AAB-----CAA---------- ----AAB-----CAA---------- ----AAB-----CAA---------- ----AAB-----CAA---------- ----AAB-----CAA---------- ----AAB-----CAA---------- ----AAB-----CAA---------- ----BBC-----CBB---------- ----EEE-----EEE---------- ----EEE-----EEE---------- ----BBC-----CBB---------- ----AAB-----CAA---------- ----AAF-----CAA---------- ----AAP-----CAA---------- ----AAP-----CAA---------- ----AAP-----CAA---------- ----AAP-----CAA---------- ----AAPDDDDCCAA---------- ----AAIIIOOIIAA---------- ----AA-------AA---------- ------------------------- ------------------------- ------------------------- ------------------------- ------------------------- 
------AAABEEB------------ ------AAABEEB------------ ------AAABEEB------------ ------AAABEEB------------ ------AAABEEB------------ ------AAABEEB------------ ------AAABEEB------------ ------AAABEEB------------ ------AAABEEB------------ ------AAABEEB------------ ------AAABEEB------------ ------AAABEEB------------ ------BBBBEEB------------ ------EEEEEEE------------ ------EEEEEEE------------ ------BBBBEEB------------ ------AAABEEB------------ ------AAABEEB------------ ------AAABEEB------------ ------AAABEEB------------ ------AAABEEB------------ ------AAABEEB------------ ------AAABEEB------------ ------AAABEEB------------ ------AAABEEB------------ ------------------------- ------------------------- ------------------------- ------------------------- ------------------------- 
