model
size = 25 30 19, scale = 0.05, origin = -y
material 
  colors = A:#EEE B:#FF0 C:#E00 D:#CF3 E:#00F F:#000 G:#06F H:#00C I:#251505 J:#30F K:#BBB L:#CC6 M:#CF0 N:#939 O:#960 P:#1C0900 Q:#AAAAB9 R:#AAA S:#888 T:#FCF
voxels
------EEEEAAA------------ ------EEEEAAA------------ ------EEEEAAA------------ ------EEEEAAA------------ ------EEEEAAA------------ ------EEEEAAA------------ ------EEEEAAA------------ ------EEEEAAA------------ ------EEEEAAA------------ ------EEEEAAA------------ ------EEEEAAA------------ ------EEEEAAA------------ ------EEEEEEE------------ ------EEEEEEE------------ ------EEEEEEE------------ ------EEEEEEE------------ ------EEEEAAA------------ ------EEEEAAA------------ ------EEEEAAA------------ ------EEEEAAA------------ ------EEEEAAA------------ ------EEEEAAA------------ ------EEEEAAA------------ ------EEEEAAA------------ ------EEEEAAA------------ ------------------------- ------------------------- ------------------------- ------R------------------ ------------------------- 
----AAAAAAAAAAA---------- ----AAB---BBBAA---------- ----AAB---BBBAA---------- ----AAA---BBBAA---------- ----AAA---BBBAA---------- ----AAA---BBBAA---------- ----AAA---BBBAA---------- ----AAA--GBBBAA---------- ----AAA--GCCCAA---------- ----AAA--GCCCAA---------- ----AAA--GCCCAA---------- ----AAA-CGCCCAA---------- ----EEBCCGGGGEE---------- ----EEJJJJJJJEE---------- ----EEBCCCCCCEE---------- ----EEACCCCCBEE---------- ----AAACCCCCCAA---------- ----AAAFFFFFFAA---------- ----AAADDDDDQAA---------- ----AAQDDDDDQAA---------- ----AAQDDDDDQAA---------- ----AAQDDDDDQAA---------- ----AAQDDDDDQAA---------- ----AAIIIIIIIAA---------- ----AA-------AA---------- ------------------------- ------------------------- ------------------------- ------K------------------ ------K------------------ 
---AAAAAAAAAAAAA--------- ---ABB--------AA--------- ---ABBBBBGBBBAAA--------- ---ABBBBBGBBBAAA--------- ---ABBBBBGBBBAAA--------- ---ABBBBBGBBBAAA--------- ---ABBBBBGBBBAAA--------- ---ABBBBBGBBBAAA--------- ---ACCCCCGCCCAAA--------- ---ACCCCCGCCCAAA--------- ---ACCCBBGBBCCAA--------- ---ACCCCCGCCCCAA--------- ---EBBBCCGGGGBBE--------- ---EJJBCCCCCCBJE--------- ---EJJBCCCCCCJJE--------- ---ECBBBBBBBBBBE--------- ---ACDDDDDBBCCCA--------- ---AFFFFFFFFFFFA--------- ---AHDDDDDDDDCCA--------- ---AHDDDDDDDDCCA--------- ---AHDDDDDDDDCCA--------- ---AHDDDDDDDDCCA--------- ---AQDDDDDDDDDQA--------- ---AIIIIIIOPIIIA--------- ---A-----------A--------- ------------------------- ------------------------- ------------------------- ------------------------- ------KK----------------- 
--AAAAAAAAAAAAAAA-------- --ABBBBBBGBBBAAAA-------- --ABBBBBBGBBBAAAA-------- --ABBBBBBGBBBAAAA-------- --ABBBBBBGBBBAAAA-------- --AABBBBBGBBBAAAA-------- --AABBBBBGBBBAAAA-------- --AABBBBBGBBBAAAA-------- --AABBBBBGBBBAAAA-------- --AABB--------AAA-------- --AACCCBBGBBCCCAA-------- --AACBCCCGCCCCCAA-------- --EBCCCCCGGGGBBBE-------- --EJJJCCCC-CCBJJE-------- --EJJJCCCC-CCJJJE-------- --EBCBBBBB-BBBBBE-------- --AACDDDDD-BCCCAA-------- --AFFFFFFF-FFFFFA-------- --AHHDDDDD-DDDDQA-------- --AHHDDDDD-DDDDQA-------- --AHHDDDDD-DDDDQA-------- --AHHDDDDD-DDDDQA-------- --AQDDDDDD-DDDDAA-------- --AIIIIOIOIIPPIIA-------- --A------L------A-------- ------------------------- ------------------------- ------------------------- ---K--------------------- -------K----------------- 
-AAAAAAAAAAAAAAAAA------- -ABBBBBBBBBBBAA-AA------- -ABBBBBBBBBBBAA-AA------- -ABBBBBBBBBBBAA-AA------- -ABBBBBBBBBBBAA-AA------- -ABBBBBBBBBBBAA-AA------- -ABBBBBBBBBBBAA-AA------- -ABBBBBBBBBBBAA-AA------- -ACCBBBBBBBBBAA-AA------- -ACCBBBBBBBBBAA-AA------- -AC-CCCCCCBBCCC-CA------- -AC-CCCCCCCCCCC-CA------- -EB-CCCCCCCCBBB-BE------- -EJ-JJCCCCCCCBJ-JE------- -EJ-JJCCCCCCCJJ-JE------- -EBBCCDDDDBBBBB-BE------- -AC-CDDDDDBBCCC-CA------- -AF-FFFFFFFFFFF-FA------- -AA-HDDDDDDDDDD-QA------- -AA-HDDDDDDDDDD-QA------- -AA-HDDDDDDDDDD-QA------- -AAHHDDDDDDDDDD-QA------- -AQBDDDDDDDDDDD-AA------- -AIIOIOIOIIOPOIIIA------- -A------L-L------A------- ------------------------- ------------------------- ------------------------- ---K--------------------- ---R---K----------------- 
-AAAAAAAAAAAAAAAAA------- -ABBBBBBBBBBBBEEEA------- -ABBBBBBBBBBBBEAAA------- -ABBBBBBBBBBBBEEEA------- -ABBBBBBBBBBBBBBBA------- -ABBBBBBBBBBBBBBBA------- -ABBBBBBBBBBBBBBBA------- -ABBBBBBBBBBBBBAAA------- -ACCBBBBBBBBBBAAAA------- -ACCBBBBBBBBBBAAAA------- -ACCCCCCCCBBCCCCCA------- -ACCCCCCCCCCCCCCCA------- -EBBCCCCCCCCBBBBBE------- -EJJJJCCCCCCCBJJJE------- -EJJJJCCCCCCCJJJJE------- -EBBCCDDDDBBBBBBBE------- -ACCCDDDDDBBCCCCCA------- -AFFFFFDDCCCCCCCCA------- -AAHHDDDDDDDDDDDDA------- -AAHHDDDDDDDDDDDDA------- -AAHHDDDDDDDDDDDDA------- -AAHHDDDDDDDDDDDDA------- -ADDDDDDDDDDDDDAAA------- -AOIOOIOIIIOIIOOIA------- -A-----L-L-L-----A------- ------------------------- ------------------------- ------------------------- ------------------------- ---S--KR----------------- 
AAAAAAAAAAAAAAAAAAA------ ABBBBBBBBBBBBBBBBAA------ ABBBBBBBBBBBBBBBBAA------ ABBBBBBBBBBBBBBBBAA------ ABBBBBBBBBBBBBBBBAA------ ABBBBBBBBBBBBBBBBAA------ ABBBBBBBBBBBBBBBBAA------ ABBBBBBBBBBBBBBBBAA------ ACCCBBBBBBBBBBCCCCA------ ACCCBBBBBBBBBBCCCCA------ ACCCCCCCCCBBCCCCCCA------ ACCCCCCCCCCCCCCCCCA------ ABBBCCCCCCCCBBBBBBA------ ABBBBCCCCCCCCBJJJJA------ AJJJJJCCCCCCCJJJJJA------ ABBBCCDDDDBBBBBBBBA------ ACCCCDDDDDBBBBBBBBA------ AFFFFFFDDCCCCCCCCFA------ AHHHHDDDDDDDDNNNDQA------ AHHHHDDDDDDDDNNNDQA------ AHHHHDDDDDDDDNNNDQA------ AHHHHDDDDDDDDNNNDQA------ AQDDDDDDDDDDDNNAAAA------ AIIIIIOOIIIIIOPIIPA------ A-----L-L-L-L-----A------ ------------------------- ---------KKK------------- --------RK-KK------------ ----RRRRR---KK----------- ---RR-RR-----K----------- 
AAAAAAAAAAAAAAAAAAA------ ABBBBBBCCCCCCCCAAAA------ ABBBBBBCCCCCCCCAAAA------ ABBBBBBCCCCCCCCAAAA------ ABBBBBBCCCCCCCCAAAA------ ABBBBBBCCCCCCCCAAAA------ A-BBBBBMDDDDMCMAAAAAAAAAA A-BBBBBBBBBBBBBBBBAAAAAAA A-CCBBCBBBBBBBCCCCA-----A A-CCBBCBBBBBBBCCCCA-----A A-CCCC--CCBBCCCCCCA-----A A-CCCC------CCCCCCA-----A A-BBCC------C--CC-A-----A A-CCCCCCCCCCCCJJJ-A-----A A-BBCCCCCCCCCJJJJ-A-----A A-BBCCDDDDBBBBBBB-A-----A A-CCCDDDDDBBBBBBB-A-----A A-FFFFFDDDAAANNND-GAAAAAA A-HHHDDDDDDDDNNND-GAAAAAA A-HHHDDDDDDDDNNND-A------ A-HHHDDDDDDDDNNND-A------ A-HHHDDDDDDDDNNNDDA------ A-DDDDDDDDDDDNNAAAA------ AIIIIIIIIOIIIOIOPIA------ A----L-L-L-L-L----A------ ------------------------- ---------KKK------------- ------------------------- ----RKK------------------ ------------------------- 
AAAAAAAAAAAAAAAAAAA------ ABBBBBBCCCCCCCCAAAA------ ABBBBBBCCCCCCCCAAAA------ ABBBBBBCCCCCCCCAAAA------ ABBBBBBCCCCCCCCAAAA------ ABBBBBBCCCCCCCCAAAA------ A-BBBBBMDDDDMCMMMMBAAAAAA A-BBBBBBBBBBBBBBBBBAAAAAA A-CCBBCBBBBBBBCCCCA-----A A-CCBBCBBBBBBBCCCCA-----A A-CCCC--CCBBCCCCCCA-----A A-CCCC------CCCCCCA-----A A-CCCC------C-CCC-A-----A A-CCCCCCCCCCCCJJJ-A-----A A-CCCCCCCCCCCJJJJ-A-----A A-CCCCCDDDBBBBBBB-A-----A A-CCCCCDDDBBBBBBB-A-----A A-FFFFFDDDAAANNND-CAAAAAA A-HHHDDDDDDDDNNND-GAAAAAA A-HHHDDDDDDDDNNND-A------ A-HHHDDDDDDDDNNND-A------ A-HHHDDDDDDDDNNNDDA------ A-DDDDDDDDDDDNNAAAA------ AIIIIIIOIIIIIIIIIPA------ A---L-L-L-L-L-L---A------ ------------------------- ---------KKK------------- --------RK-KK------------ ----RRRTR---KK----------- ---RR-KK-----K----------- 
AAAAAAAAAAAAAAAAAAA------ AGGGGGGGGGGGGGGGGGA------ AGGGGGGGGGGGGGGGGGA------ AGGGGGGGGGGGGGGGGGA------ AGGGGGGGGGGGGGGGGGA------ AGGGGGGGGGGGGGGGGGA------ A-GGGGGGGGGGGGGGGGAAAAAAA A-BBBBBMDDCCCCMMMMAAAAAAA A-CCBBCDDDBBBBCCCCA-----A A-CCBBCDDDBBBBCCCCA-----A A-CCCCCDDDBBCCCCCCA-----A A-CCCCCDDDBBCCCCCCA-----A A-CCCCCCCCCCCCCCC-A-----A A-CCCCCCCCCCCCCCC-A-----A A-CCCCCCCCCCCCCCC-A-----A A-CCCCCDDDBBBBBBB-A-----A A-CCCCCDDDBBBBBBB-A-----A A-FFFFFDDDAAAADDD-CAAAAAA A-HHHDAAAADDDDDDD-CAAAAAA A-HHHDAAAADDMDDDD-A------ A-HHHDAAAADDMDDDD-A------ A-HHHDAAAADDMDDDDDA------ A-DDDDDDDDDDMMDAAAA------ AIOIIIIIIOOIIIIOPPA------ A--L-L-L-L-L-L-L--A------ ---------KKR------------- --------KK-KK------------ -------KK--KKK----------- -----S-K----KK----------- -------K----------------- 
AAAAAAAAAAAAAAAAAAA------ AGGGGGGGGGGGGGGGGGA------ AGGGGGGGGGGGGGGGGGA------ AGGGGGGGGGGGGGGGGGA------ AGGGGGGGGGGGGGGGGGA------ AGGGGGGGGGGGGGGGGGA------ A-GGGGGGGGGGGGGGGGGAAAAAA A-BBBBBMDDCCCCMMMMGAAAAAA A-CCBBCDDDBBBBCCCCA-----A A-CCBBCDDDBBBBCCCCA-----A A-CCCCCDDDBBCCCCCCA-----A A-CCCCCDDDBBCCCCCCA-----A A-CCCCCCCCCCCCCCC-A-----A A-CCCCCCCCCCCJJJJ-A-----A A-CCCCCCCC-CCCJJJ-A-----A A-CCCCCDDDB---BBB-A-----A A-CCCCCDDDB-B-BBB-A-----A A-FFFFFDDDD-D-DDD-CAAAAAA A-HHHDAAAADDDDDDD-GAAAAAA A-HHHDAAAADDMDDDD-A------ A-HHHDAAAADDMDDDD-A------ A-HHHDAAAADDMDDDDDA------ A-DDDDDDDDDDMMDAAAA------ AIIOOIIOIIIOIIIIIPA------ A---L-L-L-L-L-L---A------ ---------KKK------------- ------------------------- ------------------------- -----K------------------- ------------------------- 
AAAAAAAAAAAAAAAAAAA------ ABBBBBBBBBBBBBBBBBA------ ABBBBBBBBBBBBBBBBBA------ ABBBBBBBBBBBBBBBBBA------ AAAAAAAAAAAAAAABBBA------ AAAAAAAAAAAAAAABBBA------ A-AAAAAAAAAAAAABBBCAAAAAA A-AAAAAAAAAAAAABBBCAAAAAA A-AAAAAAAAAAAAACCCA-----A A-AAAAAAAAAAAAACCCA-----A A-AAAAAAAAAAAAACCCA-----A A-AAAAAAAAAAAAACCCA-----A A-EEAAAAAAAAAAACC-A-----A A-EEAAAAAAAAAJJJJ-A-----A A-EEAAAAAA-A-AJJJ-A-----A A-EEAAAAAAA---ACC-A-----A A-AAAAAAAAA-A-ACC-A-----A A-FFFFFFFFF-F-FFF-CAAAAAA A-HHHDAAAADDDFFFF-GAAAAAA A-HHHDAAAADDMFFFF-A------ A-HHHDAAAADDMFFFF-A------ A-HHHDAAAADDMFFFFFA------ A-DDDDDDDDDDMFFFFFA------ AIPIOIIIOIIIIIIIIPA------ A----L-L-L-L-L----A------ ---------RRR------------- --------RR-KK------------ -------RRK--RK----------- -------R-----R----------- ------------------------- 
AAAAAAAAAAAAAAAAAAA------ ABBBBBBBBBBBBBBBBBA------ ABBBBBBBBBBBBBBBBBA------ ABBBBBBBBBBBBB---BA------ AAAAAAAAAAAAAA---BA------ AAAAAAAAAAAAAA---BA------ AAAAAAAAAAAAAA---BA------ AAAAAAAAAAAAAA---BA------ AAAAAAAAAAAAAA---CA------ AAAAAAAAAAAAAA---CA------ AAAAAAAAAAAAAA---CA------ AAAAAAAAAAAAAA---CA------ AEEEAAAAAAAAAA---BA------ AEEEJJJJAAAAAJ---JA------ AEEEJJJJAA-AAAJJ-JA------ AEEEAAAAAAA--AABBBA------ AAAAAAAAAAA-AAACCCA------ AFFFFFFFFFF-FFFFFFA------ AHHHHHAAAADDDFFFFFA------ AHHHHHAAAADDMFFFFFA------ AHHHHHAAAADDMFFFFFA------ AHHHHHAAAADDMFFFFFA------ AQDDDDDDDDDDMFFFFFA------ AIPPOIOIIIOIOPOIIPA------ A-----L-L-L-L-----A------ ----------S-------------- ----------K-------------- ------SRS---K------------ ------------------------- ------------------------- 
-AAAAAAAAAAAAAAAAA------- -ABBBBBBBBBBBBBBBA------- -ABBBBBBBBBBBBBBBA------- -ABBBBBBBBBBBB---A------- -AAAAAAAAAAAAA---A------- -AAAAAAAAAAAAA---A------- -AAAAAAAAAAAAA---A------- -AAAAAAAAAAAAA---A------- -AAAAAAAAAAAAA---A------- -AAAAAAAAAAAAA---A------- -AAAAAAAAAAAAA---A------- -AAAAAAAAAAAAA---A------- -EEEAAAAAAAAAA---E------- -EEEJJJJAAAAAJ--JE------- -EEEJJJJAA-A-AJ-JE------- -EEEAAAAAAA--AABBE------- -AAAAAAAAAA-AAACCA------- -AFFFFFFFFF-FFFF-A------- -AHHHHDDDDDDDFFFFA------- -AHHHHDDDDDDMFFFFA------- -AHHHHDDDDDDMFFFFA------- -AHHHHDDDDDDMFFFFA------- -ADDDDDDDDDDMFFFFA------- -AIIOOIIIIOOIPIIPA------- -A-----L-L-L-----A------- ------------------------- ----------SK------------- ------K----K------------- ------------------------- ------------------------- 
-AAAAAAAAAAAAAAAAA------- -ABBBBBBB-BBBBBBBA------- -ABBBBBBB-BBBBBBBA------- -ABBBBBBBBBBBBB-BA------- -AAAAAAAAAAA----BA------- -AAAAAAAAA------BA------- -AAAAAAAAA------BA------- -AAAAAAAAA------BA------- -AAAAAAAAA------CA------- -AAAAAAAAA------CA------- -AAAAAAAAA------CA------- -AAAAAAAAA------CA------- -EEEAAAAAA------BE------- -EEEJJJJAA------JE------- -EEEJJJJAAA-AAJJJE------- -EEEAAAAAAA--AABBE------- -AAAAAAAAAA-AAACCA------- -AFFFFFFFFF-FFFFFA------- -AHHHHDDDDDDDFFFFA------- -AHHHHDDDDDDMFFFFA------- -AHHHHDDDDDDMFFFFA------- -AHHHHDDDDDDMFFFFA------- -AQDDDDDDDDDMFFFFA------- -AIPPPOIIIIOIPIPPA------- -A------L-L------A------- ------------------------- ----------R-------------- ------------------------- ------------------------- ------------------------- 
--AAAAAAAAAAAAAAA-------- --ABAAAAAAAAAAAAA-------- --ABAAAAAAAAAAAAA-------- --ABAAAAAAAA--AAA-------- --AAAAAAAAA----AA-------- --AAAAAAAA-----AA-------- --AAAAAAAA-----AA-------- --AAAAAAAA-----AA-------- --AAAAAAAA-----AA-------- --AAAAAAAA-----AA-------- --AA--AAAA-----AA-------- --AA--AAAA-----AA-------- --EE--AAAA-----BE-------- --EE--JJAA-----JE-------- --EE--JJAAAAAAJJE-------- --EE--AAAA-A-AABE-------- --AA--AAAA--AAACA-------- --AF--FFFF--FFFFA-------- --AH--DDDD--DFFFA-------- --AH--DDDD--MFFFA-------- --AH--DDDD--MFFFA-------- --AH--DDDD--MFFFA-------- --AQDDDDDDDDMFFFA-------- --AIIIIIOIIPPIPPA-------- --A------L------A-------- ------------------------- ------------------------- ------------------------- ------------------------- ------------------------- 
---AAAAAAAAAAAAA--------- ---AAAAAAAAAAAAA--------- ---AAAAAAAAAAAAA--------- ---AA----AAA--AA--------- ---AA----AA---AA--------- ---AA---------AA--------- ---AA---------AA--------- ---AA---------AA--------- ---AA---------AA--------- ---AA---------AA--------- ---AA---------AA--------- ---AA---------AA--------- ---EA---------BE--------- ---EJ---------JE--------- ---EJ------ABBJE--------- ---EA------ABBBE--------- ---AA-------AAAA--------- ---AF-------FFFA--------- ---AH-------DFFA--------- ---AH--------FFA--------- ---AH--------FFA--------- ---AH--------FFA--------- ---AQDDDDDDDBFFA--------- ---AIIIPOPPOIIPA--------- ---A-----------A--------- ------------------------- ------------------------- ------------------------- ------------------------- ------------------------- 
----AAAAAAAAAAA---------- ----AAAAAAABBAA---------- ----AAAAAAABBAA---------- ----AAA---A-BAA---------- ----AAA-----BAA---------- ----AAA-----BAA---------- ----AAA-----BAA---------- ----AAA-----BAA---------- ----AAA-----BAA---------- ----AAA-----BAA---------- ----AAA-----BAA---------- ----AAA-----BAA---------- ----EEE-----BEE---------- ----EEE-----JEE---------- ----EEE-----JEE---------- ----EEE-----BEE---------- ----AAA-----BAA---------- ----AAF-----BAA---------- ----AAQ-----BAA---------- ----AAQ-----BAA---------- ----AAQ-----BAA---------- ----AAQ-----BAA---------- ----AAQDDDDBBAA---------- ----AAIIIPPIIAA---------- ----AA-------AA---------- ------------------------- ------------------------- ------------------------- ------------------------- ------------------------- 
------AAAEEEE------------ ------AAAEEEE------------ ------AAAEEEE------------ ------AAAEEEE------------ ------AAAEEEE------------ ------AAAEEEE------------ ------AAAEEEE------------ ------AAAEEEE------------ ------AAAEEEE------------ ------AAAEEEE------------ ------AAAEEEE------------ ------AAAEEEE------------ ------EEEEEEE------------ ------EEEEEEE------------ ------EEEEEEE------------ ------EEEEEEE------------ ------AAAEEEE------------ ------AAAEEEE------------ ------AAAEEEE------------ ------AAAEEEE------------ ------AAAEEEE------------ ------AAAEEEE------------ ------AAAEEEE------------ ------AAAEEEE------------ ------AAAEEEE------------ ------------------------- ------------------------- ------------------------- ------------------------- ------------------------- 
