model
size = 25 30 19, scale = 0.05, origin = -y
material 
  colors = A:#E00 B:#EEE C:#FF0 D:#CF3 E:#DDD F:#00F G:#000 H:#06F I:#00C J:#251505 K:#30F L:#BBB M:#CC6 N:#CF0 O:#939 P:#960 Q:#1C0900 R:#AAAAB9 S:#AAA T:#888 U:#FCF
voxels
------AAAAAAA------------ ------AAAAAAA------------ ------AAAAAAA------------ ------AAAAAAA------------ ------AAAAAAA------------ ------FAAAAAA------------ ------FFAAAAA------------ ------FFFAAAA------------ ------FFFFAAA------------ ------FFFFFAA------------ ------FFFFFFA------------ ------FFFFFFF------------ ------FFFFFFF------------ ------FFFFFFF------------ ------FFFFFFB------------ ------FFFFFBB------------ ------FFFFBBB------------ ------FFFBBBB------------ ------FFBBBBB------------ ------FBBBBBB------------ ------BBBBBBB------------ ------BBBBBBB------------ ------BBBBBBB------------ ------BBBBBBB------------ ------BBBBBBB------------ ------------------------- ------------------------- ------------------------- ------S------------------ ------------------------- 
----AAEEEEEEEAA---------- ----AAC---CCCAA---------- ----AAC---CCCAA---------- ----FAB---CCCAA---------- ----FFB---CCCAA---------- ----FFB---CCCAA---------- ----FFB---CCCAA---------- ----FFB--HCCCAA---------- ----FFB--HAAAAA---------- ----FFB--HAAAAA---------- ----FFB--HAAAAA---------- ----FFB-AHAAAAA---------- ----FFCAAHHHHFA---------- ----FFKKKKKKKBB---------- ----FFCAAAAAABB---------- ----FFBAAAAACBB---------- ----FFBAAAAAABB---------- ----FFBGGGGGGBB---------- ----FFBDDDDDRBB---------- ----FFRDDDDDRBB---------- ----FFRDDDDDRBB---------- ----FBRDDDDDRBB---------- ----BBRDDDDDRBB---------- ----BBJJJJJJJBB---------- ----BB-------BB---------- ------------------------- ------------------------- ------------------------- ------L------------------ ------L------------------ 
---AEEEEEEEEEAAA--------- ---ACC--------AA--------- ---FCCCCCHCCCAAA--------- ---FCCCCCHCCCAAA--------- ---FCCCCCHCCCAAA--------- ---FCCCCCHCCCAAA--------- ---FCCCCCHCCCAAA--------- ---FCCCCCHCCCAAA--------- ---FAAAAAHAAAAAA--------- ---FAAAAAHAAAAAA--------- ---FAAACCHCCAAAA--------- ---FAAAAAHAAAAAA--------- ---FCCCAAHHHHCAA--------- ---FKKCAAAAAACKB--------- ---FKKCAAAAAAKKB--------- ---FACCCCCCCCCCB--------- ---FADDDDDCCAAAB--------- ---FGGGGGGGGGGGB--------- ---FIDDDDDDDDAAB--------- ---FIDDDDDDDDAAB--------- ---FIDDDDDDDDAAB--------- ---FIDDDDDDDDAAB--------- ---FRDDDDDDDDDRB--------- ---BJJJJJJPQJJJB--------- ---B-----------B--------- ------------------------- ------------------------- ------------------------- ------------------------- ------LL----------------- 
--AEEEEEEEEEEAAAA-------- --FCCCCCCHCCCAAAA-------- --FCCCCCCHCCCAAAA-------- --FCCCCCCHCCCAAAA-------- --FCCCCCCHCCCAAAA-------- --FBCCCCCHCCCAAAA-------- --FBCCCCCHCCCAAAA-------- --FBCCCCCHCCCAAAA-------- --FBCCCCCHCCCAAAA-------- --FBCC--------AAA-------- --FBAAACCHCCAAAAA-------- --FBACAAAHAAAAAAA-------- --FCAAAAAHHHHCAAA-------- --FKKKAAAA-AACKKB-------- --FKKKAAAA-AAKKKB-------- --FCACCCCC-CCCCCB-------- --FBADDDDD-CAAABB-------- --FGGGGGGG-GGGGGB-------- --FIIDDDDD-DDDDRB-------- --FIIDDDDD-DDDDRB-------- --FIIDDDDD-DDDDRB-------- --FIIDDDDD-DDDDRB-------- --FRDDDDDD-DDDDBB-------- --FJJJJPJPJJQQJJB-------- --B------M------B-------- ------------------------- ------------------------- ------------------------- ---L--------------------- -------L----------------- 
-FEEEEEEEEEEEAAAAA------- -FCCCCCCCCCCCAA-AA------- -FCCCCCCCCCCCAA-AA------- -FCCCCCCCCCCCAA-AA------- -FCCCCCCCCCCCAA-AA------- -FCCCCCCCCCCCAA-AA------- -FCCCCCCCCCCCAA-AA------- -FCCCCCCCCCCCAA-AA------- -FAACCCCCCCCCAA-AA------- -FAACCCCCCCCCAA-AA------- -FA-AAAAAACCAAA-AA------- -FA-AAAAAAAAAAA-AA------- -FC-AAAAAAAACCA-AA------- -FK-KKAAAAAAACK-KB------- -FK-KKAAAAAAAKK-KB------- -FCCAADDDDCCCCC-CB------- -FA-ADDDDDCCAAA-AB------- -FG-GGGGGGGGGGG-GB------- -FB-IDDDDDDDDDD-RB------- -FB-IDDDDDDDDDD-RB------- -FB-IDDDDDDDDDD-RB------- -FBIIDDDDDDDDDD-RB------- -FRCDDDDDDDDDDD-BB------- -FJJPJPJPJJPQPJJJB------- -F------M-M------B------- ------------------------- ------------------------- ------------------------- ---L--------------------- ---S---L----------------- 
-FEEEEEEEEEEEAAAAA------- -FCCCCCCCCCCCAAAAA------- -FCCCCCCCCCCCAAAAA------- -FCCCCCCCCCCCAAAAA------- -FCCCCCCCCCCCAAAAA------- -FCCCCCCCCCCCAAAAA------- -FCCCCCCCCCCCAAAAA------- -FCCCCCCCCCCCAAAAA------- -FAACCCCCCCCCAAAAA------- -FAACCCCCCCCCAAAAA------- -FAAAAAAAACCAAAAAA------- -FAAAAAAAAAAAAAAAA------- -FCCAAAAAAAACCAAAA------- -FKKKKAAAAAAACKKKB------- -FKKKKAAAAAAAKKKKB------- -FCCAADDDDCCCCCCCB------- -FAAADDDDDCCAAAAAB------- -FGGGGGDDAAAAAAAAB------- -FBIIDDDDDDDDDDDDB------- -FBIIDDDDDDDDDDDDB------- -FBIIDDDDDDDDDDDDB------- -FBIIDDDDDDDDDDDDB------- -FDDDDDDDDDDDDDBBB------- -FPJPPJPJJJPJJPPJB------- -F-----M-M-M-----B------- ------------------------- ------------------------- ------------------------- ------------------------- ---T--LS----------------- 
EEEEEEEEEEEEEAAAAAA------ ECCCCCCCCCCCCAAAAAA------ ECCCCCCCCCCCCAAAAAA------ ECCCCCCCCCCCCAAAAAA------ ECCCCCCCCCCCCAAAAAA------ ECCCCCCCCCCCCAAAAAA------ ECCCCCCCCCCCCAAAAAA------ ECCCCCCCCCCCCAAAAAA------ EAAACCCCCCCCCAAAAAA------ EAAACCCCCCCCCAAAAAA------ EAAAAAAAAACCAAAAAAA------ EAAAAAAAAAAAAAAAAAA------ ECCCAAAAAAAACCAAAAA------ ECCCCAAAAAAAACKKKKB------ EKKKKKAAAAAAAKKKKKB------ ECCCAADDDDCCCCCCCCB------ EAAAADDDDDCCCCCCCCB------ EGGGGGGDDAAAAAAAAGB------ EIIIIDDDDDDDDOOODRB------ EIIIIDDDDDDDDOOODRB------ EIIIIDDDDDDDDOOODRB------ EIIIIDDDDDDDDOOODRB------ ERDDDDDDDDDDDOOBBBB------ EJJJJJPPJJJJJPQJJQB------ E-----M-M-M-M-----B------ ------------------------- ---------LLL------------- --------SL-LL------------ ----SSSSS---LL----------- ---SS-SS-----L----------- 
EEEEEEEEEEEEEEEEEEE------ ECCCCCCAAAAAAAABBBE------ ECCCCCCAAAAAAAABBBE------ ECCCCCCAAAAAAAABBBE------ ECCCCCCAAAAAAAABBBE------ ECCCCCCAAAAAAAABBBE------ E-CCCCCNDDDDNANBBBBEEEEEE E-CCCCCCCCCCCCCCCCBEEEEEE E-AACCACCCCCCCAAAAE-----E E-AACCACCCCCCCAAAAE-----E E-AAAA--AACCAAAAAAE-----E E-AAAA------AAAAAAE-----E E-CCAA------A--AA-E-----E E-AAAAAAAAAAAAKKK-E-----E E-CCAAAAAAAAAKKKK-E-----E E-CCAADDDDCCCCCCC-E-----E E-AAADDDDDCCCCCCC-E-----E E-GGGGGDDDBBBOOOD-HEEEEEE E-IIIDDDDDDDDOOOD-HEEEEEE E-IIIDDDDDDDDOOOD-E------ E-IIIDDDDDDDDOOOD-E------ E-IIIDDDDDDDDOOODDE------ E-DDDDDDDDDDDOOBBBE------ EJJJJJJJJPJJJPJPQJE------ E----M-M-M-M-M----E------ ------------------------- ---------LLL------------- ------------------------- ----SLL------------------ ------------------------- 
EEEEEEEEEEEEEEEEEEE------ ECCCCCCAAAAAAAABBBE------ ECCCCCCAAAAAAAABBBE------ ECCCCCCAAAAAAAABBBE------ ECCCCCCAAAAAAAABBBE------ ECCCCCCAAAAAAAABBBE------ E-CCCCCNDDDDNANNNNCEEEEEE E-CCCCCCCCCCCCCCCCCEEEEEE E-AACCACCCCCCCAAAAE-----E E-AACCACCCCCCCAAAAE-----E E-AAAA--AACCAAAAAAE-----E E-AAAA------AAAAAAE-----E E-AAAA------A-AAA-E-----E E-AAAAAAAAAAAAKKK-E-----E E-AAAAAAAAAAAKKKK-E-----E E-AAAAADDDCCCCCCC-E-----E E-AAAAADDDCCCCCCC-E-----E E-GGGGGDDDBBBOOOD-AEEEEEE E-IIIDDDDDDDDOOOD-HEEEEEE E-IIIDDDDDDDDOOOD-E------ E-IIIDDDDDDDDOOOD-E------ E-IIIDDDDDDDDOOODDE------ E-DDDDDDDDDDDOOBBBE------ EJJJJJJPJJJJJJJJJQE------ E---M-M-M-M-M-M---E------ ------------------------- ---------LLL------------- --------SL-LL------------ ----SSSUS---LL----------- ---SS-LL-----L----------- 
EEEEEEEEEEEEEEEEEEE------ EHHHHHHHHHHHHHHHHHE------ EHHHHHHHHHHHHHHHHHE------ EHHHHHHHHHHHHHHHHHE------ EHHHHHHHHHHHHHHHHHE------ EHHHHHHHHHHHHHHHHHE------ E-HHHHHHHHHHHHHHHHBEEEEEE E-CCCCCNDDAAAANNNNBEEEEEE E-AACCADDDCCCCAAAAE-----E E-AACCADDDCCCCAAAAE-----E E-AAAAADDDCCAAAAAAE-----E E-AAAAADDDCCAAAAAAE-----E E-AAAAAAAAAAAAAAA-E-----E E-AAAAAAAAAAAAAAA-E-----E E-AAAAAAAAAAAAAAA-E-----E E-AAAAADDDCCCCCCC-E-----E E-AAAAADDDCCCCCCC-E-----E E-GGGGGDDDBBBBDDD-AEEEEEE E-IIIDBBBBDDDDDDD-AEEEEEE E-IIIDBBBBDDNDDDD-E------ E-IIIDBBBBDDNDDDD-E------ E-IIIDBBBBDDNDDDDDE------ E-DDDDDDDDDDNNDBBBE------ EJPJJJJJJPPJJJJPQQE------ E--M-M-M-M-M-M-M--E------ ---------LLS------------- --------LL-LL------------ -------LL--LLL----------- -----T-L----LL----------- -------L----------------- 
EEEEEEEEEEEEEEEEEEE------ EHHHHHHHHHHHHHHHHHE------ EHHHHHHHHHHHHHHHHHE------ EHHHHHHHHHHHHHHHHHE------ EHHHHHHHHHHHHHHHHHE------ EHHHHHHHHHHHHHHHHHE------ E-HHHHHHHHHHHHHHHHHEEEEEE E-CCCCCNDDAAAANNNNHEEEEEE E-AACCADDDCCCCAAAAE-----E E-AACCADDDCCCCAAAAE-----E E-AAAAADDDCCAAAAAAE-----E E-AAAAADDDCCAAAAAAE-----E E-AAAAAAAAAAAAAAA-E-----E E-AAAAAAAAAAAKKKK-E-----E E-AAAAAAAA-AAAKKK-E-----E E-AAAAADDDC---CCC-E-----E E-AAAAADDDC-C-CCC-E-----E E-GGGGGDDDD-D-DDD-AEEEEEE E-IIIDBBBBDDDDDDD-HEEEEEE E-IIIDBBBBDDNDDDD-E------ E-IIIDBBBBDDNDDDD-E------ E-IIIDBBBBDDNDDDDDE------ E-DDDDDDDDDDNNDBBBE------ EJJPPJJPJJJPJJJJJQE------ E---M-M-M-M-M-M---E------ ---------LLL------------- ------------------------- ------------------------- -----L------------------- ------------------------- 
EEEEEEEEEEEEEEEEEEE------ ECCCCCCCCCCCCCCCCCE------ ECCCCCCCCCCCCCCCCCE------ ECCCCCCCCCCCCCCCCCE------ EBBBBBBBBBBBBBBCCCE------ EBBBBBBBBBBBBBBCCCE------ E-BBBBBBBBBBBBBCCCAEEEEEE E-BBBBBBBBBBBBBCCCAEEEEEE E-BBBBBBBBBBBBBAAAE-----E E-BBBBBBBBBBBBBAAAE-----E E-BBBBBBBBBBBBBAAAE-----E E-BBBBBBBBBBBBBAAAE-----E E-FFBBBBBBBBBBBAA-E-----E E-FFBBBBBBBBBKKKK-E-----E E-FFBBBBBB-B-BKKK-E-----E E-FFBBBBBBB---BAA-E-----E E-BBBBBBBBB-B-BAA-E-----E E-GGGGGGGGG-G-GGG-AEEEEEE E-IIIDBBBBDDDGGGG-HEEEEEE E-IIIDBBBBDDNGGGG-E------ E-IIIDBBBBDDNGGGG-E------ E-IIIDBBBBDDNGGGGGE------ E-DDDDDDDDDDNGGGGGE------ EJQJPJJJPJJJJJJJJQE------ E----M-M-M-M-M----E------ ---------SSS------------- --------SS-LL------------ -------SSL--SL----------- -------S-----S----------- ------------------------- 
AEEEEEEEEEEEEEEEEEE------ AAAAACCCCCCCCCCCCCE------ AAAAACCCCCCCCCCCCCE------ AAAAACCCCCCCCC---CE------ AAAAABBBBBBBBB---CE------ AAAAABBBBBBBBB---CE------ AAAAABBBBBBBBB---CE------ AAAAABBBBBBBBB---CE------ AAAAABBBBBBBBB---AE------ AAAAABBBBBBBBB---AE------ AAAAABBBBBBBBB---AE------ AAAAABBBBBBBBB---AE------ AFFFBBBBBBBBBB---CE------ BFFFKKKKBBBBBK---KE------ BFFFKKKKBB-BBBKK-KE------ BFFFBBBBBBB--BBCCCE------ BBBBBBBBBBB-BBBAAAE------ BGGGGGGGGGG-GGGGGGE------ BIIIIIBBBBDDDGGGGGE------ BIIIIIBBBBDDNGGGGGE------ BIIIIIBBBBDDNGGGGGE------ BIIIIIBBBBDDNGGGGGE------ BRDDDDDDDDDDNGGGGGE------ BJQQPJPJJJPJPQPJJQE------ B-----M-M-M-M-----E------ ----------T-------------- ----------L-------------- ------TST---L------------ ------------------------- ------------------------- 
-AEEEEEEEEEEEEEEEF------- -AAAACCCCCCCCCCCCF------- -AAAACCCCCCCCCCCCF------- -AAAACCCCCCCCC---F------- -AAAABBBBBBBBB---F------- -AAAABBBBBBBBB---F------- -AAAABBBBBBBBB---F------- -AAAABBBBBBBBB---F------- -AAAABBBBBBBBB---F------- -AAAABBBBBBBBB---F------- -AAAABBBBBBBBB---F------- -AAAABBBBBBBBB---F------- -AAAABBBBBBBBB---F------- -BFFKKKKBBBBBK--KF------- -BFFKKKKBB-B-BK-KF------- -BFFBBBBBBB--BBCCF------- -BBBBBBBBBB-BBBAAF------- -BGGGGGGGGG-GGGG-F------- -BIIIIDDDDDDDGGGGF------- -BIIIIDDDDDDNGGGGF------- -BIIIIDDDDDDNGGGGF------- -BIIIIDDDDDDNGGGGF------- -BDDDDDDDDDDNGGGGF------- -BJJPPJJJJPPJQJJQF------- -B-----M-M-M-----F------- ------------------------- ----------TL------------- ------L----L------------- ------------------------- ------------------------- 
-AEEEEEEEEEEEEEEEF------- -AAAACCCC-CCCCCCCF------- -AAAACCCC-CCCCCCCF------- -AAAACCCCCCCCCC-CF------- -AAAABBBBBBB----CF------- -AAAABBBBB------CF------- -AAAABBBBB------CF------- -AAAABBBBB------CF------- -AAAABBBBB------AF------- -AAAABBBBB------AF------- -AAAABBBBB------AF------- -AAAABBBBB------AF------- -AAAABBBBB------CF------- -BFFKKKKBB------KF------- -BFFKKKKBBB-BBKKKF------- -BFFBBBBBBB--BBCCF------- -BBBBBBBBBB-BBBAAF------- -BGGGGGGGGG-GGGGGF------- -BIIIIDDDDDDDGGGGF------- -BIIIIDDDDDDNGGGGF------- -BIIIIDDDDDDNGGGGF------- -BIIIIDDDDDDNGGGGF------- -BRDDDDDDDDDNGGGGF------- -BJQQQPJJJJPJQJQQF------- -B------M-M------F------- ------------------------- ----------S-------------- ------------------------- ------------------------- ------------------------- 
--AEEEEEEEEEEEEEA-------- --AAABBBBBBBBBBBF-------- --AAABBBBBBBBBBBF-------- --AAABBBBBBB--BBF-------- --AAABBBBBB----BF-------- --AAABBBBB-----BF-------- --AAABBBBB-----BF-------- --AAABBBBB-----BF-------- --AAABBBBB-----BF-------- --AAABBBBB-----BF-------- --AA--BBBB-----BF-------- --AA--BBBB-----BF-------- --AA--BBBB-----CF-------- --BF--KKBB-----KF-------- --BF--KKBBBBBBKKF-------- --BF--BBBB-B-BBCF-------- --BB--BBBB--BBBAF-------- --BG--GGGG--GGGGF-------- --BI--DDDD--DGGGF-------- --BI--DDDD--NGGGF-------- --BI--DDDD--NGGGF-------- --BI--DDDD--NGGGF-------- --BRDDDDDDDDNGGGF-------- --BJJJJJPJJQQJQQF-------- --B------M------B-------- ------------------------- ------------------------- ------------------------- ------------------------- ------------------------- 
---AEEEEEEEEEEEA--------- ---AABBBBBBBBBBA--------- ---AABBBBBBBBBBF--------- ---AA----BBB--BF--------- ---AA----BB---BF--------- ---AA---------BF--------- ---AA---------BF--------- ---AA---------BF--------- ---AA---------BF--------- ---AA---------BF--------- ---AA---------BF--------- ---AA---------BF--------- ---AA---------CF--------- ---BK---------KF--------- ---BK------BCCKF--------- ---BB------BCCCF--------- ---BB-------BBBF--------- ---BG-------GGGF--------- ---BI-------DGGF--------- ---BI--------GGF--------- ---BI--------GGF--------- ---BI--------GGF--------- ---BRDDDDDDDCGGF--------- ---BJJJQPQQPJJQB--------- ---B-----------B--------- ------------------------- ------------------------- ------------------------- ------------------------- ------------------------- 
----AAEEEEEEEAA---------- ----AABBBBBCCAA---------- ----AABBBBBCCAA---------- ----AAB---B-CAF---------- ----AAB-----CFF---------- ----AAB-----CFF---------- ----AAB-----CFF---------- ----AAB-----CFF---------- ----AAB-----CFF---------- ----AAB-----CFF---------- ----AAB-----CFF---------- ----AAB-----CFF---------- ----AFF-----CFF---------- ----BBF-----KFF---------- ----BBF-----KFF---------- ----BBF-----CFF---------- ----BBB-----CFF---------- ----BBG-----CFF---------- ----BBR-----CFF---------- ----BBR-----CFF---------- ----BBR-----CFF---------- ----BBR-----CBF---------- ----BBRDDDDCCBB---------- ----BBJJJQQJJBB---------- ----BB-------BB---------- ------------------------- ------------------------- ------------------------- ------------------------- ------------------------- 
------AAAAAAA------------ ------AAAAAAA------------ ------AAAAAAA------------ ------AAAAAAA------------ ------AAAAAAA------------ ------AAAAAAF------------ ------AAAAAFF------------ ------AAAAFFF------------ ------AAAFFFF------------ ------AAFFFFF------------ ------AFFFFFF------------ ------FFFFFFF------------ ------FFFFFFF------------ ------FFFFFFF------------ ------BFFFFFF------------ ------BBFFFFF------------ ------BBBFFFF------------ ------BBBBFFF------------ ------BBBBBFF------------ ------BBBBBBF------------ ------BBBBBBB------------ ------BBBBBBB------------ ------BBBBBBB------------ ------BBBBBBB------------ ------BBBBBBB------------ ------------------------- ------------------------- ------------------------- ------------------------- ------------------------- 
