model
size = 19 30 25, scale = 0.05, origin = -y
material 
  colors = A:#E00 B:#EEE C:#CF3 D:#FF0 E:#000 F:#00C G:#251505 H:#BBB I:#CF0 J:#CC6 K:#939 L:#960 M:#AAAAB9 N:#1C0900 O:#AAA P:#888 Q:#FCF
voxels
------------------- ------------------- ------------------- ------------------- ------------------- ------------------- -------AAAAA------- -------AAAAA------- -------AAAAA------- -------AAAAA------- -------AAAAA------- -------AAAAA------- -------AAAAA------- -------BBBBB------- -------BBBBB------- -------BBBBB------- -------BBBBB------- -------BBBBB------- -------BBBBB------- ------------------- ------------------- ------------------- ------------------- ------------------- ------------------- ------------------- ------------------- ------------------- ------------------- ------------------- 
------------------- ------------------- ------------------- ------------------- ------------------- ------------------- -------AAAAA------- -------AAAAA------- ------------------- ------------------- ------------------- ------------------- ------------------- ------------------- ------------------- ------------------- ------------------- -------BBBBB------- -------BBBBB------- ------------------- ------------------- ------------------- ------------------- ------------------- ------------------- ------------------- ------------------- ------------------- ------------------- ------------------- 
------------------- ------------------- ------------------- ------------------- ------------------- ------------------- -------AAAAA------- -------AAAAA------- ------------------- ------------------- ------------------- ------------------- ------------------- ------------------- ------------------- ------------------- ------------------- -------BBBBB------- -------BBBBB------- ------------------- ------------------- ------------------- ------------------- ------------------- ------------------- ------------------- ------------------- ------------------- ------------------- ------------------- 
------------------- ------------------- ------------------- ------------------- ------------------- ------------------- -------AAAAA------- -------AAAAA------- ------------------- ------------------- ------------------- ------------------- ------------------- ------------------- ------------------- ------------------- ------------------- -------BBBBB------- -------BBBBB------- ------------------- ------------------- ------------------- ------------------- ------------------- ------------------- ------------------- ------------------- ------------------- ------------------- ------------------- 
------------------- ------------------- ------------------- ------------------- ------------------- ------------------- -------AAAAA------- -------AAAAA------- ------------------- ------------------- ------------------- ------------------- ------------------- ------------------- ------------------- ------------------- ------------------- -------BBBBB------- -------BBBBB------- ------------------- ------------------- ------------------- ------------------- ------------------- ------------------- ------------------- ------------------- ------------------- ------------------- ------------------- 
------------------- ------------------- ------------------- ------------------- ------------------- ------------------- -------AAAAA------- -------AAAAA------- ------------------- ------------------- ------------------- ------------------- ------------------- ------------------- ------------------- ------------------- ------------------- -------BBBBB------- -------BBBBB------- ------------------- ------------------- ------------------- ------------------- ------------------- ------------------- ------------------- ------------------- ------------------- ------------------- ------------------- 
------AAAAAAA------ ------AAAAAAA------ ------AAAAAAA------ ------AAAAAAA------ ------AAAAAAA------ ------AAAAAAA------ ------AADAAAA------ ------AADAAAA------ ------AAAAAAA------ ------AAAAAAA------ ------AAAAAAA------ ------AAAAAAA------ ------BBBBBBB------ ------BBBBBBB------ ------BBBBBBB------ ------BBBBBBB------ ------BBBBBBB------ ------BAAAAAB------ ------BAMAAAB------ ------BBBBBBB------ ------BBBBBBB------ ------BBBBBBB------ ------BBBBBBB------ ------BBBBBBB------ ------BBBBBBB------ ------------------- ------------------- ------------------- ------------------- ------------------- 
----AAAAAAAAAAA---- ----AAABBBBDAAA---- ----AAABBBBDAAA---- ----AAABBBBDAAA---- ----AAABBBBDAAA---- ----AAABBBBDAAA---- ----AAABIIIDAAA---- ----AAADDIIDAAA---- ----AAAAAAAAAAA---- ----AAAAAAAAAAA---- ----AAAAAAAAAAA---- ----AAAAAAAAAAA---- ----BBA-----ABB---- ----BBA-----ABB---- ----BBA-----ABB---- ----BBD-----ABB---- ----BBD-----ABB---- ----BBE-----EBB---- ----BBM-----EBB---- ----BBM-----EBB---- ----BBM-----EBB---- ----BBMCCCCEEBB---- ----BBBBBBBEEBB---- ----BBNGNNNNNBB---- ----BB-------BB---- ------------------- ------------------- ------------------- ------------------- ------------------- 
---AAAAAAAAAAAAA--- ---AAAABBBBDAAAA--- ---AAAABBBBDAAAA--- ---AAAABBBBD--AA--- ---AAAABBBBD--AA--- ---AAAABBBBD--AA--- ---AAAABIIID--AA--- ---AAAADDIID--AA--- ---AAAAAAAAA--AA--- ---AAAAAAAAA--AA--- ---AAAAAAAAA--AA--- ---AAAAAAAAA--AA--- ---BAAAAAAAA--AB--- ---BAAAAAAAA-AAB--- ---BAAAAAAAA-AAB--- ---BAADDDDDAAAAB--- ---BAADDDDDAAAAB--- ---BEAACCCCEE-EB--- ---BMCCCCCCEEEEB--- ---BMCCCCCCEEEEB--- ---BMCCCCCCEEEEB--- ---BMCCCCCCEEEEB--- ---BBBBBBBBEEEEB--- ---BGGGNGNGGGNNB--- ---B-----------B--- ------------------- ------------------- ------------------- ------------------- ------------------- 
--AAAAAAAAAAAAAAA-- --AA-AABBBBDAAAAA-- --AA-AABBBBDAAAAA-- --AA-AABBBBD---AA-- --AA-AABBBBD---AA-- --AA-AABBBBD---AA-- --AA-AABIIID---AA-- --AA-AADDIID---AA-- --AA-AAAAAAA---AA-- --AA-AAAAAAA---AA-- --AA-AAAAAAA---AA-- --AA-AAAAAAA---AA-- --BA-AAAAAAA---AB-- --BA-AAAAAAA---AB-- --BA-AAAAAAAA-AAB-- --BA-ADDDDDAAAAAB-- --BA-ADDDDDAAAAAB-- --BE-AAKKCCEEEEEB-- --BM-CKKKCCEEEEEB-- --BM-CKKKCCEEEEEB-- --BM-CKKKCCEEEEEB-- --BM-CKKKCCEEEEEB-- --BB-BBBBBBEEEEEB-- --BGGLGLGLGGGGNNB-- --B------J------B-- ------------------- ------------------- ------------------- ------------------- ------------------- 
-AAAAAAAAAAAAAAAAA- -AAAAAAAAAADAAAAAA- -AAAAAAAAAADAAAAAA- -AAAAAAAAAAD--AAAA- -AAAAAAAAAAD----AA- -AAAAAAAAAAD----AA- -AAAAAAIIIID----AA- -AAAAAADDIID----AA- -AAAAAAAAAAA----AA- -AAAAAAAAAAA----AA- -AAAAAAAAAAA----AA- -AAAAAAAAAAA----AA- -BAAAAA-AAAA----AB- -BAAAAAAAAAA----AB- -BAAAAAAAAAAAAAAAB- -BAAAADDDDDAAAAAAB- -BAAAADDDDDAAAAAAB- -BEEEAAKKCCEEEEEEB- -BACCCKKKCCEEEEEEB- -BACCCKKKCCEEEEEEB- -BACCCKKKCCEEEEEEB- -BACCCKKKCCEEEEEEB- -BMCCCKKKCCEEEEEEB- -BGGGLNGGGGGLGGNNB- -B------J-J------B- ------------------- ------------------- ------------------- ------------------- ------------------- 
-AAAAAAAAAAAAAAAAA- -A-AAAAAAAADAAAAAA- -AAAAAAAAAADAAAAAA- -AAAAAAAAAADAAA--A- -AAAAAAAAAADAA---A- -AAAAAAAAAADAA---A- -AAAAAAAAAADAA---A- -AAAAAADDAADAA---A- -AAAAAADDDDDAA---A- -AA-AAADDDDDAA---A- -AAAAAAAAAAAAA---A- -AAAAAAAAAAAAA---A- -BAAAAA--AAAAA---B- -BAAAAAAAAAAAA---B- -BAAAAAAAAAAAAAAAB- -BAAAADDDD--AAAAAB- -BAAAADDDD--AAAAAB- -BEEEAAKKB--EEEEEB- -BACCCKKKCCEEEEEEB- -BACCCKKKCCEEEEEEB- -BACCCKKKCCEEEEEEB- -BACCCKKKCCEEEEEEB- -BCCCCKKKIIEEEEEEB- -BGNLGLLGGGGNNNGGB- -B-----J-J-J-----B- ------------------- ------------------- ---------H-H------- ------H-HH-O------- ------H-H---------- 
AAAAAAAAAAAAAAAAAAA AA-AAAAAAAADAAAAAAA AAAAAAAAAAADAAAAAAA AAAAAAAAAAADAAA--AA AAAAAAAAAAADAA---AA AAAAAAAAAAADAA---AA AAAAAAAIIAADAA---AA AAAAAAADDAADAA---AA AAAAAAADDDDDAA---AA AAA-AAADDDDDAA---AA AAAAAAAAAAAAAA---AA AAAAAAAAAAAAAA---AA BAAAAAAAAAAAAA---AB BAAAAAAAAAAAAA---AB BAAAAAAAAAA-A-AAAAB BAAAAADDDD------DDB BAAAAADDDDDDDCCCCMB BEEEEAABBBCEEEEEEEB BMCCCCCCCCCCCCCCCMB BMCCCCCCCIIIIIII-MB BMCCCCCCCIIIIIII-MB BMCCCCCCCIIIIIII-MB BMCCCCCCCIIIIIIIDMB BGGNNGGGGGGGLGGNGGB B-----J-J-J-J-----B ------------------- ---------H-H------- ------H-HH-OH------ ------H-HH--------- ------------------- 
AAAAAAAAAAAAAAAAAAA AA-AAAAAAAADAAAAAAA AAAAAAAAAAADAAAAAAA AAAAAAAAAAADAAAAA-A AAAAAAAAAAADAAA---A AAAAAAAAAAADAA----A AAAAAAACCAADAA----A AAAAAAADDAADAA----A AAAAAAADDDDDAA----A AAA-AAADDDDDAA----A AAAAAAADDDDDAA----A AAAAAAA--DDDAA----A BAAAAAA--AAAAA----B BAAAAAAAAAAAAA----B BAAAAAAAAAAAAA-AA-B BADDDDDDDD-----DD-B BADDDDDDDD--------B BEEEEAABBB--------B BCCCCCCCCCCCCCC---B BCCCCCCCCCCCCCC---B BCCCCCCCCCCCCCC---B BCCCCCCCCCCCCCC---B BCCCCCCCCCCCCCCCCCB BGNGLLGGGGLGGLLNLGB B----J-J-J-J-J----B ---------OHO------- ------HHHH-H-H----- ------H-HH---H----- ------------------- ------------------- 
AAAAAAAAAAAAAAAAAAA AA-AAAAAAAADAAAAAAA AAAAAAAAAAADAAAAAAA AAAAAAAAAAADAAAAAAA AAAAAAAAAAADAAAAA-A AAAAAAAAAAADAA----A AAAAAAACCAADAA----A AAAAAAADDAADAA----A AAAAAAADDDDDAA----A AAA-AAADDDDDAA----A AAAAAAADDDDDAA----A AAAAAAA--DDDAA----A BAAAAAA--AAAAD----B BAA-AAAAAAAAAD----B BAA-AAAAAA----DD--B BAD-DDDDDDDDDDD---B BAD-DDDDDDDDDCC---B BEE-EAABBBCEEEE---B BCC-CCCCCCCCCCC---B BCC-CCCCCCCCCCC---B BCC-CCCCCCCCCCC---B BCC-CCCCCCCCCCC---B BCC-CCCCCCCCCCCCCCB BGLGGGGGGLGGLLGGNNB B---J-J-J-J-J-J---B ---------HHOP------ ------HHH---HPO---- ------------------- ------------------- ------------------- 
AAAAAAAAAAAAAAAAAAA A--AAAAAAAADAA-AAAA A-AAAAAAAAADAA-AAAA A-AAAAAAAAADAAAAA-A A-AAAAAAAAADAAAAA-A A-AAAAAAAAADAAAA--A A-AAAAACCCCDAAAA--A AAAAAAADDCCDAAAA--A AAAAAAADDCCCAAAA--A AAA-AAADDCCCAAAA--A AAAAAAAAACCCAAAA--A AAAAAAA--CCCAAAA--A BAAAAAA--AAAADDD--B BAAAAAAAAAAAADDD--B BAAAAAAAAAAAADDD--B BADDCCCCCCCCCDDD--B BACCCCCCCCCCCCCC--B BEEEEAACCCCEEEEE--B BCCCCCCCCBBBBCCC--B BCCCCCCCCBBBBCCC--B BCCCCCCCCBBBBCCC--B BCCCCCCCCBBBBCCC--B BCCCCCCCCCCCCCCCCCB BGGLGGGLGLGGGGGGNNB B--J-J-J-J-J-J-J--B ---------HHO------- ------HHHH-O------- ------H-H--H------- ------------------- ------------------- 
AAAAAAAAAAAAAAAAAAA A--AAAAAAAADAAAAAAA A-AAAAAAAAADAAAAAAA A-AAAAAAAAADAAAA--A A-AAAAAAAAADAAAA--A A-AAAAAAAAADAAAA--A A-AAAAACCAADAAAA--A A-AAAAADDCCDAAAA--A A-AAAAADDCCCAAAA--A A-A-AAADDCCCAAAA--A A-AAAAAAACCCAAAA--A AAAAAAA--CCCAAAA--A BAAAAAA--AAAADDD--B BAAAAAAAAAAAADDD--B BAAAAAAAAAAAADDD--B BADDCCCCCCCCCDDD--B BACCCCCCCCCCCCCC--B BEEEECCCCCCEEEEE--B BCCCCCCCCBBBBCCC--B BCCCCCCCCBBBBCCC--B BCCCCCCCCBBBBCCC--B BCCCCCCCCBBBBCCC--B BCCCCCCCCCCCCCCCCCB BGGGLGGGGGGLGGGLLGB B---J-J-J-J-J-J---B ------------------- ---------H-O------- ------O-OH-OP------ ------O-O---------- ------------------- 
AAAAAAAAAAAAAAAAAAA A--AAAAAAAAAAAAAAAA A-AAAAAAAAAAAAAAAAA A-AAAAAAAAAAAAAA--A A-AAAAAAAAAAAAAA--A A-AAAAAAAAAAAAAA--A A-AAAAAAAAAAAAAA--A A-AAAAAAAAAAAAAA--A A-AAAAAAAAAAAAAA--A A-A-AAAAAAAAAAAA--A A-AAAAA--AAAAAAA--A A-AAAAA--AAAAAAA--A BAAAAAA--AAAADDD--B BAAAAAAAAAAAADDD--B BAAAAAAAAAAAADDD--B BADDCCCCCCCCCDDD--B BACCCCCCCCCCCCCC--B BEEEECCCCCCEEEEE--B BCCCCCCCCBBBBCCC--B BCCCCCCCCBBBBCCC--B BCCCCCCCCBBBBCCC--B BCCCCCCCCBBBBCCC--B BCCCCCCCCCCCCCCCCCB BGGLGLLGLGLGGGGGNGB B----J-J-J-J-J----B ------------------- ------------------- ---------H-OO------ ------O-QH-O------- --HHHOO-HH--------- 
AAAAAAAAAAAAAAAAAAA AA-AAAAAAAAAAAAAAAA AAAAAAAAAAAAAAAAAAA AAAAAAAAAAAAAAAA-AA AAAAAAAAAAAAAAAA-AA AAAAAAAAAAAAAAAA-AA AAAAAAAAAAAAAAAA-AA AAAAAAAAAAAAAAAA-AA AAAAAAAAAAAAAAAA-AA AAA-AAAAAAAAAAAA-AA AAAAAAA--AAAAAAA-AA AAAAAAA--AAAAAAA-AA BAAAAAA--AAAAAAA-AB BAAAAAAAAAAAAAAA-AB BAAAAAAAAAAAAAAA-AB BADDCCCCAAAAAAAA-AB BACCCCCCAAAAAAAA-AB BEEEEEEEEEEEEEEE-EB BMCCCCCCCBBBBCCC-MB BMCCCCCCCBBBBCCC-MB BMCCCCCCCBBBBCCC-MB BMCCCCCCCBBBBCCC-MB BMCCCCCCCCCCCCCCCMB BGGGLGLGGGGGLGLGGGB B-----J-J-J-J-----B ------------------- ------------------- ------------PH----- OH----OHO---------- -HH--HO-H---------- 
-AAAAAAAAAAAAAAAAA- -AAAAAAAAAAAAAAAAA- -AAAAAAAAAAAAAAAAA- -AAAAAAAAAAAAAAA-A- -AAAAAAAAAAAAAAA-A- -AAAAAAAAAAAAAAA-A- -AAAAAAAAAAAAAAA-A- -AAAAAAAAAAAAAAA-A- -AAAAAAAAAAAAAAA-A- -AAAAAAAAAAAAAAA-A- -AAAAAAAAAAAAAA--A- -AAAAAAAAAAAAAA--A- -BAAAAAAAAAAAAA--B- -BAAAAAAAAAAAAA--B- -BAAAAAAAAAAAAA--B- -BDDAAAAAAAAAAA--B- -BCCCCCCAAAAAAA--B- -BEEEEEEEEEEEEE--B- -BCCCCCCCCCCFFF--B- -BCCCCCCCCCCFFF--B- -BCCCCCCCCCCFFF--B- -BCCCCCCCCCCFFF--B- -BCCCCCCCCCCCCCCCB- -BGGGLGGGGGGGLNGGB- -B-----J-J-J-----B- ------------------- ------------------- ------------------- ------OHOPH-------- ------------------- 
-AAAAAAAAAAAAAAAAA- -AAAAAAAAAAAAAAAAA- -AAAAAAAAAAAAAAAAA- -AAAAAAAAAAAAAAAAA- -AAAAAAAAAAAAAAAAA- -AAAAAAAAAAAAAAAAA- -AAAAAAAAAAAAAAAAA- -AAAAAAAAAAAAAAAAA- -AAAAAAAAAAAAAAAAA- -AAAAAAAAAAAAAAAAA- -AAAAAAAAAAAAAA-AA- -AAAAAAAAAAAAAA-AA- -BAAAAAAAAAAAAA-AB- -BAAAAAAAAAAAAA-AB- -BAAAAAAAAAAAAA-AB- -BAAAAAAAAAAAAA-AB- -BAAAAAAAAAAAAA-AB- -BEEEEEEEEEEEEE-EB- -BFFFFFFFFFFFFF-FB- -BFFFFFFFFFFFFF-FB- -BFFFFFFFFFFFFF-FB- -BFFFFFFFFFFFFF-FB- -BMCCCCCCCCCCCCCMB- -BGGLLGGGGLLLLNGGB- -B------J-J------B- ------------------- ------------------- ------------------- ------OOO---------- ------O-O---------- 
--AAAAAAAAAAAAAAA-- --AAAAAAAAAAAAAAA-- --AAAAAAAAAAAAAAA-- --AAAAAAAAAAAAAAA-- --AAAAAAAAAAAAAAA-- --AAAAAAAAAAAAAAA-- --AAAAAAAAAAAAAAA-- --AAAAAAAAAAAAAAA-- --AAAAAAAAAAAAAAA-- --AAAAAAAAAAAAAAA-- --AA-AAAAAAAAAAAA-- --AA-AAAAAAAAAAAA-- --BA-AAAAAAAAAAAB-- --BA-AAAAAAAAAAAB-- --BA-AAAAAAAAAAAB-- --BAAAAAAAAAAAAAB-- --BA-AAAAAAAAAAAB-- --BE-EEEEEEEEEEEB-- --BF-FFFFFFFFFFFB-- --BF-FFFFFFFFFFFB-- --BF-FFFFFFFFFFFB-- --BFFFFFFFFFFFFFB-- --BMDCCCCCCCCCCMB-- --BGGGGGGGLGNGNGB-- --B------J------B-- ------------------- ------------------- ------------------- ---HH-------------- ----OPO-O---------- 
---AAAAAAAAAAAAA--- ---AAAAAAAAAAAAA--- ---AAAAAAAAAAAAA--- ---AAAAAAAAAAAAA--- ---AAAAAAAAAAAAA--- ---AAAAAAAAAAAAA--- ---AAAAAAAAAAAAA--- ---AAAAAAAAAAAAA--- ---AAAAAAAAAAAAA--- ---AAAAAAAAAAAAA--- ---AAAAAAAAAAAAA--- ---AAAAAAAAAAAAA--- ---BAAAAAAAAAAAB--- ---BAAAAAAAAAAAB--- ---BAAAAAAAAAAAB--- ---BAAAAAAAAAAAB--- ---BAAAAAAAAAAAB--- ---BEEEEEEEEEEEB--- ---BBBFFFFFFFFFB--- ---BBBFFFFFFFFFB--- ---BBBFFFFFFFFFB--- ---BBBFFFFFFFFFB--- ---BMCCCCCCCCCMB--- ---BGLGGGLGNNGGB--- ---B-----------B--- ------------------- ------------------- ------------------- ------------------- ------------------- 
----AAAAAAAAAAA---- ----AAAAAAAAAAA---- ----AAAAAAAAAAA---- ----AAAAAAAAAAA---- ----AAAAAAAAAAA---- ----AAAAAAAAAAA---- ----AAA-----AAA---- ----AAA-----AAA---- ----AAA-----AAA---- ----AAA-----AAA---- ----AAA-----AAA---- ----AAA-----AAA---- ----BBA-----ABB---- ----BBA-----ABB---- ----BBA-----ABB---- ----BBA-----ABB---- ----BBA-----ABB---- ----BBE-----EBB---- ----BBF-----FBB---- ----BBF-----FBB---- ----BBF-----FBB---- ----BBF-----FBB---- ----BBM-----MBB---- ----BBGGGGGGGBB---- ----BB-------BB---- ------------------- ------------------- ------------------- ------------------- ------------------- 
------AAAAAAA------ ------AAAAAAA------ ------AAAAAAA------ ------AAAAAAA------ ------AAAAAAA------ ------AAAAAAA------ ------AAAAAAA------ ------AAAAAAA------ ------AAAAAAA------ ------AAAAAAA------ ------AAAAAAA------ ------AAAAAAA------ ------BBBBBBB------ ------BBBBBBB------ ------BBBBBBB------ ------BBBBBBB------ ------BBBBBBB------ ------BBBBBBB------ ------BBBBBBB------ ------BBBBBBB------ ------BBBBBBB------ ------BBBBBBB------ ------BBBBBBB------ ------BBBBBBB------ ------BBBBBBB------ ------------------- ------------------- ------------------- ------------------- ------------------- 
