model
size = 19 30 25, scale = 0.05, origin = -y
material 
  colors = A:#E00 B:#EEE C:#CF3 D:#00C E:#FF0 F:#000 G:#251505 H:#BBB I:#CF0 J:#CC6 K:#939 L:#960 M:#AAAAB9 N:#1C0900 O:#AAA P:#888 Q:#FCF
voxels
------------------- ------------------- ------------------- ------------------- ------------------- ------------------- -------BBBBB------- -------BBBBB------- -------BBBBB------- -------BBBBB------- -------BBBBB------- -------BBBBB------- -------BBBBB------- -------BBBBB------- -------BBBBB------- -------BBBBB------- -------BBBBB------- -------BBBBB------- -------BBBBB------- ------------------- ------------------- ------------------- ------------------- ------------------- ------------------- ------------------- ------------------- ------------------- ------------------- ------------------- 
------------------- ------------------- ------------------- ------------------- ------------------- ------------------- -------BBBBB------- -------BBBBB------- ------------------- ------------------- ------------------- ------------------- ------------------- ------------------- ------------------- ------------------- ------------------- -------BBBBB------- -------BBBBB------- ------------------- ------------------- ------------------- ------------------- ------------------- ------------------- ------------------- ------------------- ------------------- ------------------- ------------------- 
------------------- ------------------- ------------------- ------------------- ------------------- ------------------- -------BBBBB------- -------BBBBB------- ------------------- ------------------- ------------------- ------------------- ------------------- ------------------- ------------------- ------------------- ------------------- -------BBBBB------- -------BBBBB------- ------------------- ------------------- ------------------- ------------------- ------------------- ------------------- ------------------- ------------------- ------------------- ------------------- ------------------- 
------------------- ------------------- ------------------- ------------------- ------------------- ------------------- -------BBBBB------- -------BBBBB------- ------------------- ------------------- ------------------- ------------------- ------------------- ------------------- ------------------- ------------------- ------------------- -------BBBBB------- -------BBBBB------- ------------------- ------------------- ------------------- ------------------- ------------------- ------------------- ------------------- ------------------- ------------------- ------------------- ------------------- 
------------------- ------------------- ------------------- ------------------- ------------------- ------------------- -------BBBBB------- -------BBBBB------- ------------------- ------------------- ------------------- ------------------- ------------------- ------------------- ------------------- ------------------- ------------------- -------BBBBB------- -------BBBBB------- ------------------- ------------------- ------------------- ------------------- ------------------- ------------------- ------------------- ------------------- ------------------- ------------------- ------------------- 
------------------- ------------------- ------------------- ------------------- ------------------- ------------------- -------BBBBB------- -------BBBBB------- ------------------- ------------------- ------------------- ------------------- ------------------- ------------------- ------------------- ------------------- ------------------- -------BBBBB------- -------BBBBB------- ------------------- ------------------- ------------------- ------------------- ------------------- ------------------- ------------------- ------------------- ------------------- ------------------- ------------------- 
------ABBBBBA------ ------ABBBBBA------ ------ABBBBBA------ ------ABBBBBA------ ------ABBBBBA------ ------ABBBBBA------ ------AAEAAAA------ ------AAEAAAA------ ------DBBBBBD------ ------DBBBBBD------ ------DBBBBBD------ ------DBBBBBD------ ------DBBBBBD------ ------DBBBBBD------ ------DBBBBBD------ ------DBBBBBD------ ------DBBBBBD------ ------DAAAAAD------ ------BAMAAAB------ ------BBBBBBB------ ------BBBBBBB------ ------BBBBBBB------ ------BBBBBBB------ ------BBBBBBB------ ------BBBBBBB------ ------------------- ------------------- ------------------- ------------------- ------------------- 
----AAAAAAAAAAA---- ----AAABBBBEAAA---- ----AAABBBBEAAA---- ----AAABBBBEAAA---- ----AAABBBBEAAA---- ----AAABBBBEAAA---- ----AAABIIIEAAA---- ----AAAEEIIEAAA---- ----DDDAAAAADDD---- ----DDDAAAAADDD---- ----DDDAAAAADDD---- ----DDDAAAAADDD---- ----DDD-----DDD---- ----DDD-----DDD---- ----DDD-----DDD---- ----DDD-----DDD---- ----DDD-----DDD---- ----DDD-----DDD---- ----BBM-----FBB---- ----BBM-----FBB---- ----BBM-----FBB---- ----BBMCCCCFFBB---- ----BBBBBBBFFBB---- ----BBNGNNNNNBB---- ----BB-------BB---- ------------------- ------------------- ------------------- ------------------- ------------------- 
---AAAAAAAAAAAAA--- ---AAAABBBBEAAAA--- ---AAAABBBBEAAAA--- ---AAAABBBBE--AA--- ---AAAABBBBE--AA--- ---AAAABBBBE--AA--- ---AAAABIIIE--AA--- ---AAAAEEIIE--AA--- ---DDDDAAAAA--DD--- ---DDDDAAAAA--DD--- ---DDDDAAAAA--DD--- ---DDDDAAAAA--DD--- ---DDDDAAAAA--DD--- ---DDDDAAAAA-DDD--- ---DDDDAAAAA-DDD--- ---DDDDEEEEADDDD--- ---DDDDEEEEADDDD--- ---DDDDCCCCFD-DD--- ---BMCCCCCCFFFFB--- ---BMCCCCCCFFFFB--- ---BMCCCCCCFFFFB--- ---BMCCCCCCFFFFB--- ---BBBBBBBBFFFFB--- ---BGGGNGNGGGNNB--- ---B-----------B--- ------------------- ------------------- ------------------- ------------------- ------------------- 
--AAAAAAAAAAAAAAA-- --AA-AABBBBEAAAAA-- --AA-AABBBBEAAAAA-- --AA-AABBBBE---AA-- --AA-AABBBBE---AA-- --AA-AABBBBE---AA-- --AA-AABIIIE---AA-- --AA-AAEEIIE---AA-- --DD-DDAAAAA---AB-- --BD-DDAAAAA---AB-- --BD-DDAAAAA---AB-- --BD-DDAAAAA---AB-- --BD-DDAAAAA---AB-- --BD-DDAAAAA---AB-- --BD-DDAAAAAA-AAB-- --BD-DDEEEEAAAAAB-- --BD-DDEEEEAAAAAB-- --BD-DDKKCCFFFFFB-- --BM-CKKKCCFFFFFB-- --BM-CKKKCCFFFFFB-- --BM-CKKKCCFFFFFB-- --BM-CKKKCCFFFFFB-- --BB-BBBBBBFFFFFB-- --BGGLGLGLGGGGNNB-- --B------J------B-- ------------------- ------------------- ------------------- ------------------- ------------------- 
-AAAAAAAAAAAAAAAAA- -AAAAAAAAAAEAAAAAA- -AAAAAAAAAAEAAAAAA- -AAAAAAAAAAE--AAAA- -AAAAAAAAAAE----AA- -AAAAAAAAAAE----AA- -AAAAAAIIIIE----AA- -AAAAAAEEIIE----AA- -BAAAAAAAAAA----AB- -AAAAAAAAAAA----AA- -AAAAAAAAAAA----AA- -AAAAAAAAAAA----AA- -AAAAAA-AAAA----AA- -AAAAAAAAAAA----AA- -AAAAAAAAAAAAAAAAA- -AAAAAEEEEEAAAAAAA- -AAAAAEEEEEAAAAAAA- -AFFFAAKKCCFFFFFFA- -BACCCKKKCCFFFFFFB- -BACCCKKKCCFFFFFFB- -BACCCKKKCCFFFFFFB- -BACCCKKKCCFFFFFFB- -BMCCCKKKCCFFFFFFB- -BGGGLNGGGGGLGGNNB- -B------J-J------B- ------------------- ------------------- ------------------- ------------------- ------------------- 
-AAAAAAAAAAAAAAAAA- -A-AAAAAAAAEAAAAAA- -AAAAAAAAAAEAAAAAA- -AAAAAAAAAAEAAA--A- -AAAAAAAAAAEAA---A- -AAAAAAAAAAEAA---A- -AAAAAAAAAAEAA---A- -BAAAAAEEAAEAA---B- -DAAAAAEEEEEAA---D- -AA-AAAEEEEEAA---A- -AAAAAAAAAAAAA---A- -AAAAAAAAAAAAA---A- -AAAAAA--AAAAA---A- -AAAAAAAAAAAAA---A- -AAAAAAAAAAAAAAAAA- -AAAAAEEEE--AAAAAA- -AAAAAEEEE--AAAAAA- -AFFFAAKKB--FFFFFA- -BACCCKKKCCFFFFFFB- -BACCCKKKCCFFFFFFB- -BACCCKKKCCFFFFFFB- -BACCCKKKCCFFFFFFB- -BCCCCKKKIIFFFFFFB- -BGNLGLLGGGGNNNGGB- -B-----J-J-J-----B- ------------------- ------------------- ---------H-H------- ------H-HH-O------- ------H-H---------- 
AAAAAAAAAAAAAAAAAAA AA-AAAAAAAAEAAAAAAA AAAAAAAAAAAEAAAAAAA AAAAAAAAAAAEAAA--AA AAAAAAAAAAAEAA---AA AAAAAAAAAAAEAA---AA BAAAAAAIIAAEAA---AB DAAAAAAEEAAEAA---AD DDAAAAAEEEEEAA---AD DAA-AAAEEEEEAA---AD AAAAAAAAAAAAAA---AA AAAAAAAAAAAAAA---AA BAAAAAAAAAAAAA---AB AAAAAAAAAAAAAA---AA AAAAAAAAAAA-A-AAAAA AAAAAAEEEE------EEA AAAAAAEEEEEEECCCCMA AAFFFAABBBCFFFFFFAA BMCCCCCCCCCCCCCCCMB BMCCCCCCCIIIIIII-MB BMCCCCCCCIIIIIII-MB BMCCCCCCCIIIIIII-MB BMCCCCCCCIIIIIIIEMB BGGNNGGGGGGGLGGNGGB B-----J-J-J-J-----B ------------------- ---------H-H------- ------H-HH-OH------ ------H-HH--------- ------------------- 
AAAAAAAAAAAAAAAAAAA AA-AAAAAAAAEAAAAAAA AAAAAAAAAAAEAAAAAAA AAAAAAAAAAAEAAAAA-A AAAAAAAAAAAEAAA---A BAAAAAAAAAAEAA----B DAAAAAACCAAEAA----D DAAAAAAEEAAEAA----D DDAAAAAEEEEEAA----D AAA-AAAEEEEEAA----A AAAAAAAEEEEEAA----A AAAAAAA--EEEAA----A BAAAAAA--AAAAA----B AAAAAAAAAAAAAA----A AAAAAAAAAAAAAA-AA-A BAEEEEEEEE-----EE-B AAEEEEEEEE--------A AAFFFAABBB--------A BCCCCCCCCCCCCCC---B BCCCCCCCCCCCCCC---B BCCCCCCCCCCCCCC---B BCCCCCCCCCCCCCC---B BCCCCCCCCCCCCCCCCCB BGNGLLGGGGLGGLLNLGB B----J-J-J-J-J----B ---------OHO------- ------HHHH-H-H----- ------H-HH---H----- ------------------- ------------------- 
AAAAAAAAAAAAAAAAAAA AA-AAAAAAAAEAAAAAAA AAAAAAAAAAAEAAAAAAA AAAAAAAAAAAEAAAAAAA BAAAAAAAAAAEAAAAA-B DAAAAAAAAAAEAA----D DAAAAAACCAAEAA----D DAAAAAAEEAAEAA----D DDAAAAAEEEEEAA----D AAA-AAAEEEEEAA----A AAAAAAAEEEEEAA----A AAAAAAA--EEEAA----A BAAAAAA--AAAAE----B AAA-AAAAAAAAAE----A AAA-AAAAAA----EE--A BAE-EEEEEEEEEEE---B AAE-EEEEEEEEECC---A AAF-FAABBBCFFFF---A BCC-CCCCCCCCCCC---B BCC-CCCCCCCCCCC---B BCC-CCCCCCCCCCC---B BCC-CCCCCCCCCCC---B BCC-CCCCCCCCCCCCCCB BGLGGGGGGLGGLLGGNNB B---J-J-J-J-J-J---B ---------HHOP------ ------HHH---HPO---- ------------------- ------------------- ------------------- 
AAAAAAAAAAAAAAAAAAA A--AAAAAAAAEAA-AAAA A-AAAAAAAAAEAA-AAAA B-AAAAAAAAAEAAAAA-B D-AAAAAAAAAEAAAAA-D D-AAAAAAAAAEAAAA--D D-AAAAACCCCEAAAA--D DAAAAAAEECCEAAAA--D DDAAAAAEECCCAAAA--D DAA-AAAEECCCAAAA--D BAAAAAAAACCCAAAA--B BAAAAAA--CCCAAAA--B BAAAAAA--AAAAEEE--B BAAAAAAAAAAAAEEE--B BAAAAAAAAAAAAEEE--B BAEECCCCCCCCCEEE--B BACCCCCCCCCCCCCC--B AAFFFAACCCCFFFFF--A BCCCCCCCCBBBBCCC--B BCCCCCCCCBBBBCCC--B BCCCCCCCCBBBBCCC--B BCCCCCCCCBBBBCCC--B BCCCCCCCCCCCCCCCCCB BGGLGGGLGLGGGGGGNNB B--J-J-J-J-J-J-J--B ---------HHO------- ------HHHH-O------- ------H-H--H------- ------------------- ------------------- 
AAAAAAAAAAAAAAAAAAA A--AAAAAAAAEAAAAAAA A-AAAAAAAAAEAAAAAAA A-AAAAAAAAAEAAAA--A B-AAAAAAAAAEAAAA--B D-AAAAAAAAAEAAAA--D D-AAAAACCAAEAAAA--D D-AAAAAEECCEAAAA--D D-AAAAAEECCCAAAA--D A-A-AAAEECCCAAAA--A A-AAAAAAACCCAAAA--A AAAAAAA--CCCAAAA--A BAAAAAA--AAAAEEE--B AAAAAAAAAAAAAEEE--A AAAAAAAAAAAAAEEE--A BAEECCCCCCCCCEEE--B AACCCCCCCCCCCCCC--A AAFFFCCCCCCFFFFF--A BCCCCCCCCBBBBCCC--B BCCCCCCCCBBBBCCC--B BCCCCCCCCBBBBCCC--B BCCCCCCCCBBBBCCC--B BCCCCCCCCCCCCCCCCCB BGGGLGGGGGGLGGGLLGB B---J-J-J-J-J-J---B ------------------- ---------H-O------- ------O-OH-OP------ ------O-O---------- ------------------- 
AAAAAAAAAAAAAAAAAAA A--AAAAAAAAAAAAAAAA A-AAAAAAAAAAAAAAAAA A-AAAAAAAAAAAAAA--A A-AAAAAAAAAAAAAA--A B-AAAAAAAAAAAAAA--B D-AAAAAAAAAAAAAA--D D-AAAAAAAAAAAAAA--D D-AAAAAAAAAAAAAA--D A-A-AAAAAAAAAAAA--A A-AAAAA--AAAAAAA--A A-AAAAA--AAAAAAA--A BAAAAAA--AAAAEEE--B AAAAAAAAAAAAAEEE--A AAAAAAAAAAAAAEEE--A BAEECCCCCCCCCEEE--B AACCCCCCCCCCCCCC--A AAFFFCCCCCCFFFFF--A BCCCCCCCCBBBBCCC--B BCCCCCCCCBBBBCCC--B BCCCCCCCCBBBBCCC--B BCCCCCCCCBBBBCCC--B BCCCCCCCCCCCCCCCCCB BGGLGLLGLGLGGGGGNGB B----J-J-J-J-J----B ------------------- ------------------- ---------H-OO------ ------O-QH-O------- --HHHOO-HH--------- 
AAAAAAAAAAAAAAAAAAA AA-AAAAAAAAAAAAAAAA AAAAAAAAAAAAAAAAAAA AAAAAAAAAAAAAAAA-AA AAAAAAAAAAAAAAAA-AA AAAAAAAAAAAAAAAA-AA BAAAAAAAAAAAAAAA-AB DAAAAAAAAAAAAAAA-AD DDAAAAAAAAAAAAAA-AD DAA-AAAAAAAAAAAA-AD AAAAAAA--AAAAAAA-AA AAAAAAA--AAAAAAA-AA BAAAAAA--AAAAAAA-AB AAAAAAAAAAAAAAAA-AA AAAAAAAAAAAAAAAA-AA AAEECCCCAAAAAAAA-AA AACCCCCCAAAAAAAA-AA AAFFFFFFFFFFFFFF-AA BMCCCCCCCBBBBCCC-MB BMCCCCCCCBBBBCCC-MB BMCCCCCCCBBBBCCC-MB BMCCCCCCCBBBBCCC-MB BMCCCCCCCCCCCCCCCMB BGGGLGLGGGGGLGLGGGB B-----J-J-J-J-----B ------------------- ------------------- ------------PH----- OH----OHO---------- -HH--HO-H---------- 
-AAAAAAAAAAAAAAAAA- -AAAAAAAAAAAAAAAAA- -AAAAAAAAAAAAAAAAA- -AAAAAAAAAAAAAAA-A- -AAAAAAAAAAAAAAA-A- -AAAAAAAAAAAAAAA-A- -AAAAAAAAAAAAAAA-A- -BAAAAAAAAAAAAAA-B- -DAAAAAAAAAAAAAA-D- -AAAAAAAAAAAAAAA-A- -AAAAAAAAAAAAAA--A- -AAAAAAAAAAAAAA--A- -AAAAAAAAAAAAAA--A- -AAAAAAAAAAAAAA--A- -AAAAAAAAAAAAAA--A- -AEEAAAAAAAAAAA--A- -ACCCCCCAAAAAAA--A- -AFFFFFFFFFFFFF--A- -BCCCCCCCCCCDDD--B- -BCCCCCCCCCCDDD--B- -BCCCCCCCCCCDDD--B- -BCCCCCCCCCCDDD--B- -BCCCCCCCCCCCCCCCB- -BGGGLGGGGGGGLNGGB- -B-----J-J-J-----B- ------------------- ------------------- ------------------- ------OHOPH-------- ------------------- 
-AAAAAAAAAAAAAAAAA- -AAAAAAAAAAAAAAAAA- -AAAAAAAAAAAAAAAAA- -AAAAAAAAAAAAAAAAA- -AAAAAAAAAAAAAAAAA- -AAAAAAAAAAAAAAAAA- -AAAAAAAAAAAAAAAAA- -AAAAAAAAAAAAAAAAA- -BAAAAAAAAAAAAAAAB- -AAAAAAAAAAAAAAADA- -AAAAAAAAAAAAAA-DA- -AAAAAAAAAAAAAA-DA- -AAAAAAAAAAAAAA-DA- -AAAAAAAAAAAAAA-DA- -AAAAAAAAAAAAAA-DA- -AAAAAAAAAAAAAA-DA- -AAAAAAAAAAAAAA-DA- -AFFFFFFFFFFFFF-DA- -BDDDDDDDDDDDDD-DB- -BDDDDDDDDDDDDD-DB- -BDDDDDDDDDDDDD-DB- -BDDDDDDDDDDDDD-DB- -BMCCCCCCCCCCCCCMB- -BGGLLGGGGLLLLNGGB- -B------J-J------B- ------------------- ------------------- ------------------- ------OOO---------- ------O-O---------- 
--AAAAAAAAAAAAAAA-- --AAAAAAAAAAAAAAA-- --AAAAAAAAAAAAAAA-- --AAAAAAAAAAAAAAA-- --AAAAAAAAAAAAAAA-- --AAAAAAAAAAAAAAA-- --AAAAAAAAAAAAAAA-- --AAAAAAAAAAAAAAA-- --DDDDDDDADDDDDDB-- --BDDDDAAADDDDDDB-- --BD-DDAAADDDDDDB-- --BD-DDAAADDDDDDB-- --BD-DDAAADDDDDDB-- --BD-DDAAADDDDDDB-- --BD-DDAAADDDDDDB-- --BDDDDAAADDDDDDB-- --BD-DDAAADDDDDDB-- --BD-DDFFFDDDDDDB-- --BD-DDDDDDDDDDDB-- --BD-DDDDDDDDDDDB-- --BD-DDDDDDDDDDDB-- --BDDDDDDDDDDDDDB-- --BMECCCCCCCCCCMB-- --BGGGGGGGLGNGNGB-- --B------J------B-- ------------------- ------------------- ------------------- ---HH-------------- ----OPO-O---------- 
---AAAAAAAAAAAAA--- ---AAAAAAAAAAAAA--- ---AAAAAAAAAAAAA--- ---AAAAAAAAAAAAA--- ---AAAAAAAAAAAAA--- ---AAAAAAAAAAAAA--- ---AAAAAAAAAAAAA--- ---AAAAAAAAAAAAA--- ---DDDDDDADDDDDD--- ---DDDDAAADDDDDD--- ---DDDDAAADDDDDD--- ---DDDDAAADDDDDD--- ---DDDDAAADDDDDD--- ---DDDDAAADDDDDD--- ---DDDDAAADDDDDD--- ---DDDDAAADDDDDD--- ---DDDDAAADDDDDD--- ---DDDDFFFDDDDDD--- ---BBBDDDDDDDDDB--- ---BBBDDDDDDDDDB--- ---BBBDDDDDDDDDB--- ---BBBDDDDDDDDDB--- ---BMCCCCCCCCCMB--- ---BGLGGGLGNNGGB--- ---B-----------B--- ------------------- ------------------- ------------------- ------------------- ------------------- 
----AAAAAAAAAAA---- ----AAAAAAAAAAA---- ----AAAAAAAAAAA---- ----AAAAAAAAAAA---- ----AAAAAAAAAAA---- ----AAAAAAAAAAA---- ----AAA-----AAA---- ----AAA-----AAA---- ----DDD-----DDD---- ----DDD-----DDD---- ----DDD-----DDD---- ----DDD-----DDD---- ----DDD-----DDD---- ----DDD-----DDD---- ----DDD-----DDD---- ----DDD-----DDD---- ----DDD-----DDD---- ----DDD-----DDD---- ----BBD-----DBB---- ----BBD-----DBB---- ----BBD-----DBB---- ----BBD-----DBB---- ----BBM-----MBB---- ----BBGGGGGGGBB---- ----BB-------BB---- ------------------- ------------------- ------------------- ------------------- ------------------- 
------AAABAAA------ ------AAABAAA------ ------AAABAAA------ ------AAABAAA------ ------AAABAAA------ ------AAABAAA------ ------AAABAAA------ ------AAABAAA------ ------DDDBDDD------ ------DDDBDDD------ ------DDDBDDD------ ------DDDBDDD------ ------DDDBDDD------ ------DDDBDDD------ ------DDDBDDD------ ------DDDBDDD------ ------DDDBDDD------ ------DDDBDDD------ ------BBBBBBB------ ------BBBBBBB------ ------BBBBBBB------ ------BBBBBBB------ ------BBBBBBB------ ------BBBBBBB------ ------BBBBBBB------ ------------------- ------------------- ------------------- ------------------- ------------------- 
