model
size = 25 30 19, scale = 0.05, origin = -y
material 
  colors = A:#E00 B:#070 C:#FF0 D:#EEE E:#CF3 F:#251505 G:#BBB H:#000 I:#960 J:#CC6 K:#CF0 L:#1C0900 M:#AAA N:#939 O:#00F P:#888 Q:#00C R:#FCF S:#AAAAB9
voxels
------BBBBBBB------------ ------BBBBBBB------------ ------BBBBBBB------------ ------BBBBBBB------------ ------BBBBBBB------------ ------BBBBBBB------------ ------BBBBBBB------------ ------BBBBBBB------------ ------DDDDDDD------------ ------DDDDDDD------------ ------DDDDDDD------------ ------DDDDDDD------------ ------DDDDDDD------------ ------DDDDDDD------------ ------DDDDDDD------------ ------DDDDDDD------------ ------AAAAAAA------------ ------AAAAAAA------------ ------AAAAAAA------------ ------AAAAAAA------------ ------AAAAAAA------------ ------AAAAAAA------------ ------AAAAAAA------------ ------AAAAAAA------------ ------AAAAAAA------------ ------------------------- ------------------------- ------------------------- ------M------------------ ------------------------- 
----BBBBBBBBBBB---------- ----BBB---BBBBB---------- ----BBB---BBBBB---------- ----BBB---BBBBB---------- ----BBB---BBBBB---------- ----BBB---BBBBB---------- ----BBB---BBBBB---------- ----BBB--BBBBBB---------- ----DDA--AAAADD---------- ----DDA--AAAADD---------- ----DDA--AAAADD---------- ----DDA-AAAAADD---------- ----DDAAAAAAADD---------- ----DDAAAAAAADD---------- ----DDAAAAAAADD---------- ----DDAAAAAAADD---------- ----AAAAAAAAAAA---------- ----AAAAAAAAAAA---------- ----AAAAAAAAAAA---------- ----AAAAAAAAAAA---------- ----AAAAAAAAAAA---------- ----AAAAAAAAAAA---------- ----AAAAAAAAAAA---------- ----AAAFFFFFFAA---------- ----AA-------AA---------- ------------------------- ------------------------- ------------------------- ------G------------------ ------G------------------ 
---BBBBBBBBBBBBB--------- ---BBB--------BB--------- ---BBBBBBBBBBBBB--------- ---BBBBBBBBBBBBB--------- ---BBBBBBBBBBBBB--------- ---BBBBBBBBBBBBB--------- ---BBBBBBBBBBBBB--------- ---BBBBBBBBBBBBB--------- ---DAAAAAAAAADDD--------- ---DAAAAAAAAADDD--------- ---DAAACCCCCAAAD--------- ---DAAAAAAAAAAAD--------- ---DAAAAAAAAAAAD--------- ---DAAAAAAAAAAAD--------- ---DAAAAAAAAAAAD--------- ---DACCCCCCCAAAD--------- ---AAAAAAAAAAAAA--------- ---AAAAAAAAAAAAA--------- ---AAAAAAAAAAAAA--------- ---AAAAAAAAAAAAA--------- ---AAAAAAAAAAAAA--------- ---AAAAAAAAAAAAA--------- ---AAAAAAAAAAAAA--------- ---AFFFFFFILFFFA--------- ---A-----------A--------- ------------------------- ------------------------- ------------------------- ------------------------- ------GG----------------- 
--BBBBBBBBBBBBBBB-------- --BBBBBBBBBBBBBBB-------- --BBBBBBBBBBBBBBB-------- --BBBBBBBBBBBBBBB-------- --BBBBBBBBBBBBBBB-------- --BBBBBBBBBBBBBBB-------- --BBBBBBBBBBBBBBB-------- --BBBBBBBBBBBBBBB-------- --DACCCCCCCCCDDDD-------- --DACC--------DDD-------- --DAAAACCCCCAAAAD-------- --DAACAAAAAAAAAAD-------- --DAAAAAAAAAAAAAD-------- --DAAAAAAA-AAAAAD-------- --DAAAAAAA-AAAAAD-------- --DAACCCCC-CAAAAD-------- --AAAAAAAA-AAAAAA-------- --AAAAAAAA-AAAAAA-------- --AAAAAAAA-AAAAAA-------- --AAAAAAAA-AAAAAA-------- --AAAAAAAA-AAAAAA-------- --AAAAAAAA-AAAAAA-------- --AAAAAAAA-AAAAAA-------- --AAFFFIFIFFLLFFA-------- --A------J------A-------- ------------------------- ------------------------- ------------------------- ---G--------------------- -------G----------------- 
-BBBBBBBBBBBBBBBBB------- -BBBBBBBBBBBBBB-BB------- -BBBBBBBBBBBBBB-BB------- -BBBBBBBBBBBBBB-BB------- -BBBBBBBBBBBBBB-BB------- -BBBBBBBBBBBBBB-BB------- -BBBBBBBBBBBBBB-BB------- -BBBBBBBBBBBBBB-BB------- -DAACCCCCCCCCDD-DD------- -DAACCCCCCCCCDD-DD------- -DA-AAAAAACCAAA-AD------- -DA-AAAAAAAAAAA-AD------- -DA-AAAAAAAAAAA-AD------- -DA-AAAAAAAAAAA-AD------- -DA-AAAAAAAAAAA-AD------- -DAAAAEEEECCAAA-AD------- -AA-AAAAAAAAAAA-AA------- -AA-AAAAAAAAAAA-AA------- -AA-AAAAAAAAAAA-AA------- -AA-AAAAAAAAAAA-AA------- -AA-AAAAAAAAAAA-AA------- -AAAAAAAAAAAAAA-AA------- -AAAAAAAAAAAAAA-AA------- -AFFIFIFIFFILIFFFA------- -A------J-J------A------- ------------------------- ------------------------- ------------------------- ---G--------------------- ---M---G----------------- 
-BBBBBBBBBBBBBBBBB------- -BBBBBBBBBCCCCOOOB------- -BBBBBBBBBCCCCODDB------- -BBBBBBBBBCCCCOOOB------- -BBBBBBBBBCCCCCCCB------- -BBBBBBBBBCCCCCCCB------- -BBBBBBBBBCCCCCCCB------- -BBBBBBBBBCCCCCDDB------- -DAACCCCCCCCCCDDDD------- -DAACCCCCCCCCCDDDD------- -DAAAAAAAACCAAAAAD------- -DAAAAAAAAAAAAAAAD------- -DAAAAAAAAAAAAAAAD------- -DAAAAAAAAAAAAAAAD------- -DAAAAAAAAAAAAAAAD------- -DAAAAEEEECCAAAAAD------- -AAAAAAAAAAAAAAAAA------- -AAAAAAAAAAAAAAAAA------- -AAAAAAAAAAAAAAAAA------- -AAAAAAAAAAAAAAAAA------- -AAAAAAAAAAAAAAAAA------- -AAAAAAAAAAAAAAAAA------- -AAAAAAAAAAAAAAAAA------- -AIFIIFIFFFIFFIIFA------- -A-----J-J-J-----A------- ------------------------- ------------------------- ------------------------- ------------------------- ---P--GM----------------- 
BBBBBBBBBBBBBBBBBBB------ BBCCCCCCCCCCCCCCCDB------ BBCCCCCCCCCCCCCCCDB------ BBCCCCCCCCCCCCCCCDB------ BBCCCCCCCCCCCCCCCDB------ BBCCCCCCCCCCCCCCCDB------ BBCCCCCCCCCCCCCCCDB------ BBCCCCCCCCCCCCCCCDB------ DAAACCCCCCCCCCAAAAD------ DAAACCCCCCCCCCAAAAD------ DAAAAAAAAACCAAAAAAD------ DAAAAAAAAAAAAAAAAAD------ DAAAAAAAAAAAAAAAAAD------ DAAAAAAAAAAAAAAAAAD------ DAAAAAAAAAAAAAAAAAD------ DAAAAAEEEECCCCCCCCD------ AAAAAAAEEECCCAAAAAA------ AAAAAAAAAAAAAAAAAAA------ AAAAAAAAAAAAAAAAAAA------ AAAAAAAAAAAAAAAAAAA------ AAAAAAAAAAAAAAAAAAA------ AAAAAAAAAAAAAAAAAAA------ AAAAAAAAAAAAAAAAAAA------ AAFFFFIIFFFFFILFFLA------ A-----J-J-J-J-----A------ ------------------------- ---------GGG------------- --------MG-GG------------ ----MMMMM---GG----------- ---MM-MM-----G----------- 
BBBBBBBBBBBBBBBBBBB------ BBCCCCCAAAAAAAADDDB------ BBCCCCCAAAAAAAADDDB------ BBCCCCCAAAAAAAADDDB------ BBCCCCCAAAAAAAADDDB------ BBCCCCCAAAAAAAADDDB------ B-CCCCCKEEEEKAKDDDBBBBBBB B-CCCCCCCCCCCCCCCCBBBBBBB D-AACCACCCCCCCAAAAD-----D D-AACCACCCCCCCAAAAD-----D D-AAAA--AACCAAAAAAD-----D D-AAAA------AAAAAAD-----D D-AAAA------A--AA-D-----D D-AAAAAAAAAAAAAAA-D-----D D-AAAAAAAAAAAAAAA-D-----D D-AAAAEEEECCCCCCC-D-----D A-AAAAAEEECCCCCCC-A-----A A-AAAAAEEEDDDNNNE-AAAAAAA A-AAAAAEEEEEENNNE-AAAAAAA A-AAAAAEEEEEENNNE-A------ A-AAAAAEEEEEENNNE-A------ A-AAAAAEEEEEENNNEAA------ A-AAAAAEEEEEENNDDAA------ AFFFFFFFFIFFFIFILFA------ A----J-J-J-J-J----A------ ------------------------- ---------GGG------------- ------------------------- ----MGG------------------ ------------------------- 
BBBBBBBBBBBBBBBBBBB------ BBCCCCCAAAAAAAADDDB------ BBCCCCCAAAAAAAADDDB------ BBCCCCCAAAAAAAADDDB------ BBCCCCCAAAAAAAADDDB------ BBCCCCCAAAAAAAADDDB------ B-CCCCCKEEEEKAKKKKBBBBBBB B-CCCCCCCCCCCCCCCCCBBBBBB D-AACCACCCCCCCAAAAD-----D D-AACCACCCCCCCAAAAD-----D D-AAAA--AACCAAAAAAD-----D D-AAAA------AAAAAAD-----D D-AAAA------A-AAA-D-----D D-AAAAAAAAAAAAAAA-D-----D D-AAAAAAAAAAAAAAA-D-----D D-AAAAAEEECCCCCCC-D-----D A-AAAAAEEECCCCCCC-A-----A A-AAAAAEEEDDDNNNE-AAAAAAA A-AAAAAEEEEEENNNE-SAAAAAA A-AAAAAEEEEEENNNE-A------ A-AAAAAEEEEEENNNE-A------ A-AAAAAEEEEEENNNEAA------ A-AAAAAEEEEEENNDDAA------ AFFFFFFIFFFFFFFFFLA------ A---J-J-J-J-J-J---A------ ------------------------- ---------GGG------------- --------MG-GG------------ ----MMMRM---GG----------- ---MM-GG-----G----------- 
BBBBBBBBBBBBBBBBBBB------ BBCCCCCAAAAAAAADDDB------ BBCCCCCAAAAAAAADDDB------ BBCCCCCAAAAAAAADDDB------ BBCCCCCAAAAAAAADDDB------ BBCCCCCAAAAAAAADDDB------ B-CCCCCKAEAAAAKKKKBBBBBBB B-CCCCCKEEAAAAKKKKABBBBBB D-AACCAEEECCCCAAAAD-----D D-AACCAEEECCCCAAAAD-----D D-AAAAAEEECCAAAAAAD-----D D-AAAAAEEECCAAAAAAD-----D D-AAAAAAAAAAAAAAA-D-----D D-AAAAAAAAAAAAAAA-D-----D D-AAAAAAAAAAAAAAA-D-----D D-AAAAAEEECCCCCCC-D-----D A-AAAAAEEECCCCCCC-A-----A A-AAAAAEEEDDDDEEE-AAAAAAA A-AAAAADDDEEEEEEE-AAAAAAA A-AAAAADDDEEKEEEE-A------ A-AAAAADDDEEKEEEE-A------ A-AAAAADDDEEKEEEEAA------ A-AAAAAEEEEEKKEDDAA------ AFIFFFFFFIIFFFFILLA------ A--J-J-J-J-J-J-J--A------ ---------GGM------------- --------GG-GG------------ -------GG--GGG----------- -----P-G----GG----------- -------G----------------- 
BBBBBBBBBBBBBBBBBBB------ BBCCCCCAAAAAAAADDDB------ BBCCCCCAAAAAAAADDDB------ BBCCCCCAAAAAAAADDDB------ BBCCCCCAAAAAAAADDDB------ BBCCCCCAAAAAAAADDDB------ B-CCCCCKAEAAAAKKKKBBBBBBB B-CCCCCKEEAAAAKKKKABBBBBB D-AACCAEEECCCCAAAAD-----D D-AACCAEEECCCCAAAAD-----D D-AAAAAEEECCAAAAAAD-----D D-AAAAAEEECCAAAAAAD-----D D-AAAAAAAAAAAAAAA-D-----D D-AAAAAAAAAAAAAAA-D-----D D-AAAAAAAA-AAAAAA-D-----D D-AAAAAEEEC---CCC-D-----D A-AAAAAEEEC-C-CCC-A-----A A-AAAHHEEEE-E-EEE-AAAAAAA A-AAAEDDDDEEEEEEE-AAAAAAA A-AAAEDDDDEEKEEEE-A------ A-AAAEDDDDEEKEEEE-A------ A-AAAEDDDDEEKEEEEAA------ A-AAAEEEEEEEKKEDDAA------ AFFIIFFIFFFIFFFFFLA------ A---J-J-J-J-J-J---A------ ---------GGG------------- ------------------------- ------------------------- -----G------------------- ------------------------- 
BBBBBBBBBBBBBBBBBBB------ BBCCCCCCCCCCCCCCCCB------ BBCCCCCCCCCCCCCCCCB------ BBCCCCCCCCCCCCCCCCB------ BBCCCCCCCCCCCCCCCCB------ BBCCCCCCCCCCCCCCCCB------ B-CCCCCCCCCCCCCCCCBBBBBBB B-CCCCCCCCCCCCCCCCBBBBBBB D-AACCAEEECCCCAAAAD-----D D-AACCAEEECCCCAAAAD-----D D-AAAAAEEECCAAAAAAD-----D D-AAAAAEEECCAAAAAAD-----D D-AAAAAAAAAAAAAAA-D-----D D-AAAAAAAAAAAAAAA-D-----D D-AAAAAAAA-A-AAAA-D-----D D-AAAAAEEEC---AAA-D-----D A-AAAAAEEEC-C-AAA-A-----A A-AAAHHHHHH-H-HHH-AAAAAAA A-AAAEDDDDEEEHHHH-AAAAAAA A-AAAEDDDDEEKHHHH-A------ A-AAAEDDDDEEKHHHH-A------ A-AAAEDDDDEEKHHHHAA------ A-AAAEEEEEEEKHHHHAA------ AFLFIFFFIFFFFFFFFLA------ A----J-J-J-J-J----A------ ---------MMM------------- --------MM-GG------------ -------MMG--MG----------- -------M-----M----------- ------------------------- 
BBBBBBBBBBBBBBBBBBB------ BBCCCCCCCCCBBBBBBBB------ BBCCCCCCCCCBBBBBBBB------ BBCCCCCCCCCBBB---BB------ BBCCCCCCCCCBBB---BB------ BBCCCCCCCCCBBB---BB------ BBCCCCCCCCCBBB---BB------ BBCCCCCCCCCBBB---BB------ DAAAAAAAAAAAAA---AD------ DAAAAAAAAAAAAA---AD------ DAAAAAAEEECCAA---AD------ DAAAAAAEEECCAA---AD------ DAAAAAAAAAAAAA---AD------ DAAAAAAAAAAAAA---AD------ DAAAAAAAAA-AAAAA-AD------ DAAAAAAEEEC--AAAAAD------ AAAAAAAAAAA-AAAAAAA------ AAAAAHHHHHH-AAAAAAA------ AAAAAQDDDDEEEHHHHHA------ AAAAAQDDDDEEKHHHHHA------ AAAAAQDDDDEEKHHHHAA------ AAAAAQDDDDEEKHHHHAA------ AAAAAEEEEEEEKHHHHAA------ AFLLIFIFFFIFILIFFLA------ A-----J-J-J-J-----A------ ----------P-------------- ----------G-------------- ------PMP---G------------ ------------------------- ------------------------- 
-BBBBBBBBBBBBBBBBB------- -BCCCCCCCCCBBBBBBB------- -BCCCCCCCCCBBBBBBB------- -BCCCCCCCCCBBB---B------- -BCCCCCCCCCBBB---B------- -BCCCCCCCCCBBB---B------- -BCCCCCCCCCBBB---B------- -BCCCCCCCCCBBB---B------- -DAAAAAAAAAAAA---D------- -DAAAAAAAAAAAA---D------- -DAAAAACCCCCAA---D------- -DAAAAACCCCCAA---D------- -DAAAAACCCCAAA---D------- -DAAAAACCCCAAA--AD------- -DAAAAACCC-A-AA-AD------- -DAAAAACCCC--AAAAD------- -AAAAAAAAAA-AAAAAA------- -AAAAAAAAAA-AAAA-A------- -AAAAAAAAAAAAAAAAA------- -AAAAAAAAAAAAAAAAA------- -AAAAAAAAAAAAAAAAA------- -AAAAAAAAAAAAAAAAA------- -AAAAAAAAAAAAAAAAA------- -AFFIIFFFFIIFLFILA------- -A-----J-J-J-----A------- ------------------------- ----------PG------------- ------G----G------------- ------------------------- ------------------------- 
-BBBBBBBBBBBBBBBBB------- -BBBBBBBB-BBBBBBBB------- -BBBBBBBB-BBBBBBBB------- -BBBBBBBBBBBBBB-BB------- -BBBBBBBBBBB----BB------- -BBBBBBBBB------BB------- -BBBBBBBBB------BB------- -BBBBBBBBB------BB------- -DAAAAAAAA------AD------- -DAAAAAAAA------AD------- -DAAAAACCC------AD------- -DAAAAACCC------AD------- -DAAAAACCC------AD------- -DAAAAACCC------AD------- -DAAAAACCCC-AAAAAD------- -DAAAAACCCC--AAAAD------- -AAAAAAAAAA-AAAAAA------- -AAAAAAAAAA-AAAAAA------- -AAAAAAAAAAAAAAAAA------- -AAAAAAAAAAAAAAAAA------- -AAAAAAAAAAAAAAAAA------- -AAAAAAAAAAAAAAAAA------- -AAAAAAAAAAAAAAAAA------- -AALLLIFFFFIFLFLLA------- -A------J-J------A------- ------------------------- ----------M-------------- ------------------------- ------------------------- ------------------------- 
--BBBBBBBBBBBBBBB-------- --BBBBBBBBBBBBBBB-------- --BBBBBBBBBBBBBBB-------- --BBBBBBBBBB--BBB-------- --BBBBBBBBB----BB-------- --BBBBBBBB-----BB-------- --BBBBBBBB-----BB-------- --BBBBBBBB-----BB-------- --DAAAAAAA-----AD-------- --DAAAAAAA-----AD-------- --DA--ACCC-----AD-------- --DA--ACCC-----AD-------- --DA--ACCC-----AD-------- --DA--ACCC-----AD-------- --DA--ACCCCAAAAAD-------- --DA--ACCC-C-AAAD-------- --AA--AAAA--AAAAA-------- --AA--AAAA--AAAAA-------- --AA--AAAA--AAAAA-------- --AA--AAAA--AAAAA-------- --AA--AAAA--AAAAA-------- --AA--AAAA--AAAAA-------- --AAAAAAAAAAAAAAA-------- --AFFFFFIFFLIFLLA-------- --A------J------A-------- ------------------------- ------------------------- ------------------------- ------------------------- ------------------------- 
---BBBBBBBBBBBBB--------- ---BBBBBBBBBBBBB--------- ---BBBBBBBBBBBBB--------- ---BB----BBB--BB--------- ---BB----BB---BB--------- ---BB---------BB--------- ---BB---------BB--------- ---BB---------BB--------- ---DA---------AD--------- ---DA---------AD--------- ---DA---------AD--------- ---DA---------AD--------- ---DA---------AD--------- ---DA---------AD--------- ---DA------DDAAD--------- ---DA------DCAAD--------- ---AA-------AAAA--------- ---AA-------AAAA--------- ---AA-------AAAA--------- ---AA--------AAA--------- ---AA--------AAA--------- ---AA--------AAA--------- ---AAAAAAAAAAAAA--------- ---AFFILILLLIFLA--------- ---A-----------A--------- ------------------------- ------------------------- ------------------------- ------------------------- ------------------------- 
----BBBBBBBBBBB---------- ----BBBBBBBBBBB---------- ----BBBBBBBBBBB---------- ----BBB---B-BBB---------- ----BBB-----BBB---------- ----BBB-----BBB---------- ----BBB-----BBB---------- ----BBB-----BBB---------- ----DDA-----ADD---------- ----DDA-----ADD---------- ----DDD-----DDD---------- ----DDD-----DDD---------- ----DDD-----DDD---------- ----DDD-----DDD---------- ----DDD-----DDD---------- ----DDA-----CDD---------- ----AAA-----AAA---------- ----AAA-----AAA---------- ----AAA-----AAA---------- ----AAA-----AAA---------- ----AAA-----AAA---------- ----AAA-----AAA---------- ----AAAAAAAAAAA---------- ----AAFLLLILLAA---------- ----AA-------AA---------- ------------------------- ------------------------- ------------------------- ------------------------- ------------------------- 
------BBBBBBB------------ ------BBBBBBB------------ ------BBBBBBB------------ ------BBBBBBB------------ ------BBBBBBB------------ ------BBBBBBB------------ ------BBBBBBB------------ ------BBBBBBB------------ ------DDDDDDD------------ ------DDDDDDD------------ ------DDDDDDD------------ ------DDDDDDD------------ ------DDDDDDD------------ ------DDDDDDD------------ ------DDDDDDD------------ ------DDDDDDD------------ ------AAAAAAA------------ ------AAAAAAA------------ ------AAAAAAA------------ ------AAAAAAA------------ ------AAAAAAA------------ ------AAAAAAA------------ ------AAAAAAA------------ ------AAAAAAA------------ ------AAAAAAA------------ ------------------------- ------------------------- ------------------------- ------------------------- ------------------------- 
