model
size = 25 30 19, scale = 0.05, origin = -y
material 
  colors = A:#E00 B:#FF0 C:#CF3 D:#EEE E:#000 F:#251505 G:#00C H:#BBB I:#CF0 J:#CC6 K:#939 L:#960 M:#1C0900 N:#AAA O:#AAAAB9 P:#00F Q:#888 R:#FCF
voxels
------AAAAAAA------------ ------AAAAAAA------------ ------AAAAAAA------------ ------ADDDDDA------------ ------ADDDDDA------------ ------ADDDDDA------------ ------ADDDDDA------------ ------ADDDDDA------------ ------ADDDDDA------------ ------ADDDDDA------------ ------DDDDDDD------------ ------DDDDDDD------------ ------DDDDDDD------------ ------DDDDDDD------------ ------DDDDDDD------------ ------ADDDDDA------------ ------ADDDDDA------------ ------ADDDDDA------------ ------ADDDDDA------------ ------ADDDDDA------------ ------ADDDDDA------------ ------ADDDDDA------------ ------AAAAAAA------------ ------AAAAAAA------------ ------AAAAAAA------------ ------------------------- ------------------------- ------------------------- ------N------------------ ------------------------- 
----AAAAAAAAAAA---------- ----AAB---BBBAA---------- ----AAB---BBBAA---------- ----AAB---BBBAA---------- ----AAB---BBBAA---------- ----AAB---BBBAA---------- ----AAB---BBBAA---------- ----AAA--AAAAAA---------- ----AAA--AAAAAA---------- ----AAA--AAAAAA---------- ----DDD--AAADDD---------- ----DDD-AAAADDD---------- ----DDDDAAAADDD---------- ----DDDDAAAADDD---------- ----DDDAAAAAADD---------- ----AAAAAAAAAAA---------- ----AAAAAAAAAAA---------- ----AAAAAAAAAAA---------- ----AAAAAAAAAAA---------- ----AAAAAAAAAAA---------- ----AAAAAAAAAAA---------- ----AAAAAAAAAAA---------- ----AAAAAAAAAAA---------- ----AAFFFFFFFAA---------- ----AA-------AA---------- ------------------------- ------------------------- ------------------------- ------H------------------ ------H------------------ 
---AAAAAAAAAAAAA--------- ---ABB--------DA--------- ---ABBBBBBBBBDDA--------- ---ABBBBBBBBBDDA--------- ---ABBBBBBBBBDDA--------- ---ABBBBBBBBBDDA--------- ---ABBBBBBBBBDDA--------- ---AAAAAAAAAAAAA--------- ---AAAAAAAAAAAAA--------- ---AAAAAAAAAAAAA--------- ---DDDDAAAAADDDD--------- ---DDDDDAAAADDDD--------- ---DDDDDAAAADDDD--------- ---DDDDDAAAADDDD--------- ---DDDDAAAAAADDD--------- ---AAAAAAAAAAAAA--------- ---AAAAAAAAAAAAA--------- ---AAAAAAAAAAAAA--------- ---AAAAAAAAAAAAA--------- ---AAAAAAAAAAAAA--------- ---AAAAAAAAAAAAA--------- ---AAAAAAAAAAAAA--------- ---AOCCCCCCCCCOA--------- ---AFFFFFFLMFFFA--------- ---A-----------A--------- ------------------------- ------------------------- ------------------------- ------------------------- ------HH----------------- 
--AAAAAAAAAAAAAAA-------- --ABBBBBBBBBBDDDA-------- --ABBBBBBBBBBDDDA-------- --ABBBBBBBBBBDDDA-------- --ABBBBBBBBBBDDDA-------- --ABBBBBBBBBBDDDA-------- --ABBBBBBBBBBDDDA-------- --ABBBBBBBBBBDDDA-------- --AABBBBBBBBBDDDA-------- --AABB--------DDA-------- --DDDDDBBBBBDDDDD-------- --DDDDDDAAADDDDDD-------- --DDDDDDAAADDDDDD-------- --DDDDDDAA-DDDDDD-------- --DDDDDDAA-DDDDDD-------- --ADDDDDBB-DDDDDA-------- --AAACCCCC-BAAAAA-------- --AEEEEEEE-EEEEEA-------- --AGGCCCCC-CCCCOA-------- --AGGCCCCC-CCCCOA-------- --AGGCCCCC-CCCCOA-------- --AGGCCCCC-CCCCOA-------- --AOCCCCCC-CCCCDA-------- --AFFFFLFLFFMMFFA-------- --A------J------A-------- ------------------------- ------------------------- ------------------------- ---H--------------------- -------H----------------- 
-AAAAAAAAAAAAAAAAA------- -ABBBBBBBBBBBDD-DA------- -ABBBBBBBBBBBDD-DA------- -ABBBBBBBBBBBDD-DA------- -ABBBBBBBBBBBDD-DA------- -ABBBBBBBBBBBDD-DA------- -ABBBBBBBBBBBDD-DA------- -ABBBBBBBBBBBDD-DA------- -AAABBBBBBBBBDD-DA------- -AAABBBBBBBBBDD-DA------- -AA-AAAAAABBAAA-AA------- -AA-AAAAAAAAAAA-AA------- -AA-AAAAAAAAAAA-AA------- -AA-AAAAAAAAAAA-AA------- -AA-AAAAAAAAAAA-AA------- -AAAAACCCCBBAAA-AA------- -AA-ACCCCCBBAAA-AA------- -AE-EEEEEEEEEEE-EA------- -AD-GCCCCCCCCCC-OA------- -AD-GCCCCCCCCCC-OA------- -AD-GCCCCCCCCCC-OA------- -ADGGCCCCCCCCCC-OA------- -AOBCCCCCCCCCCC-DA------- -AFFLFLFLFFLMLFFFA------- -A------J-J------A------- ------------------------- ------------------------- ------------------------- ---H--------------------- ---N---H----------------- 
-AAAAAAAAAAAAAAAAA------- -ABBBBBBBBBBBBPPPA------- -ABBBBBBBBBBBBPDDA------- -ABBBBBBBBBBBBPPPA------- -ABBBBBBBBBBBBBBBA------- -ABBBBBBBBBBBBBBBA------- -ABBBBBBBBBBBBBBBA------- -ABBBBBBBBBBBBBDDA------- -AAABBBBBBBBBBDDDA------- -AAABBBBBBBBBBDDDA------- -AAAAAAAAABBAAAAAA------- -AAAAAAAAAAAAAAAAA------- -AAAAAAAAAAAAAAAAA------- -AAAAAAAAAAAAAAAAA------- -AAAAAAAAAAAAAAAAA------- -AAAAACCCCBBAAAAAA------- -AAAACCCCCBBAAAAAA------- -AEEEEECCAAAAAAAAA------- -ADGGCCCCCCCCCCCCA------- -ADGGCCCCCCCCCCCCA------- -ADGGCCCCCCCCCCCCA------- -ADGGCCCCCCCCCCCCA------- -ACCCCCCCCCCCCCDDA------- -ALFLLFLFFFLFFLLFA------- -A-----J-J-J-----A------- ------------------------- ------------------------- ------------------------- ------------------------- ---Q--HN----------------- 
AAAAAAAAAAAAAAAAAAA------ ABBBBBBBBBBBBBBBBDA------ ABBBBBBBBBBBBBBBBDA------ ABBBBBBBBBBBBBBBBDA------ ABBBBBBBBBBBBBBBBDA------ ABBBBBBBBBBBBBBBBDA------ ABBBBBBBBBBBBBBBBDA------ ABBBBBBBBBBBBBBBBDA------ AAAABBBBBBBBBBAAAAA------ AAAABBBBBBBBBBAAAAA------ AAAAAAAAAABBAAAAAAA------ AAAAAAAAAAAAAAAAAAA------ AAAAAAAAAAAAAAAAAAA------ AAAAAAAAAAAAAAAAAAA------ AAAAAAAAAAAAAAAAAAA------ AAAAAACCCCBBBBBBBBA------ AAAAACCCCCBBBBBBBBA------ AEEEEEECCAAAAAAAAEA------ AGGGGCCCCCCCCKKKCOA------ AGGGGCCCCCCCCKKKCOA------ AGGGGCCCCCCCCKKKCOA------ AGGGGCCCCCCCCKKKCOA------ AOCCCCCCCCCCCKKDDDA------ AFFFFFLLFFFFFLMFFMA------ A-----J-J-J-J-----A------ ------------------------- ---------HHH------------- --------NH-HH------------ ----NNNNN---HH----------- ---NN-NN-----H----------- 
AAAAAAAAAAAAAAAAAAA------ ABBBBBBAAAAAAAADDDA------ ABBBBBBAAAAAAAADDDA------ ABBBBBBAAAAAAAADDDA------ ABBBBBBAAAAAAAADDDA------ ABBBBBBAAAAAAAADDDA------ A-BBBBBICCCCIAIDDDAAAAAAA A-BBBBBBBBBBBBBBBBAAAAAAA A-AABBABBBBBBBAAAAA-----A A-AABBABBBBBBBAAAAA-----A A-AAAA--AABBAAAAAAA-----A A-AAAA------AAAAAAA-----A A-AAAA------A--AA-A-----A A-AAAAAAAAAAAAAAA-A-----A A-AAAAAAAAAAAAAAA-A-----A A-AAAACCCCBBBBBBB-A-----A A-AAACCCCCBBBBBBB-A-----A A-EEEEECCCDDDKKKC-AAAAAAA A-GGGCCCCCCCCKKKC-AAAAAAA A-GGGCCCCCCCCKKKC-A------ A-GGGCCCCCCCCKKKC-A------ A-GGGCCCCCCCCKKKCCA------ A-CCCCCCCCCCCKKDDDA------ AFFFFFFFFLFFFLFLMFA------ A----J-J-J-J-J----A------ ------------------------- ---------HHH------------- ------------------------- ----NHH------------------ ------------------------- 
AAAAAAAAAAAAAAAAAAA------ ABBBBBBAAAAAAAADDDA------ ABBBBBBAAAAAAAADDDA------ ABBBBBBAAAAAAAADDDA------ ABBBBBBAAAAAAAADDDA------ ABBBBBBAAAAAAAADDDA------ A-BBBBBICCCCIAIIIIBAAAAAA A-BBBBBBBBBBBBBBBBBAAAAAA A-AABBABBBBBBBAAAAA-----A A-AABBABBBBBBBAAAAA-----A A-AAAA--AABBAAAAAAA-----A A-AAAA------AAAAAAA-----A A-AAAA------A-AAA-A-----A A-AAAAAAAAAAAAAAA-A-----A A-AAAAAAAAAAAAAAA-A-----A A-AAAAACCCBBBBBBB-A-----A A-AAAAACCCBBBBBBB-A-----A A-EEEEECCCDDDKKKC-AAAAAAA A-GGGCCCCCCCCKKKC-OAAAAAA A-GGGCCCCCCCCKKKC-A------ A-GGGCCCCCCCCKKKC-A------ A-GGGCCCCCCCCKKKCCA------ A-CCCCCCCCCCCKKDDDA------ AFFFFFFLFFFFFFFFFMA------ A---J-J-J-J-J-J---A------ ------------------------- ---------HHH------------- --------NH-HH------------ ----NNNRN---HH----------- ---NN-HH-----H----------- 
AAAAAAAAAAAAAAAAAAA------ ABBBBBBAAAAAAAADDDA------ ABBBBBBAAAAAAAADDDA------ ABBBBBBAAAAAAAADDDA------ ABBBBBBAAAAAAAADDDA------ ABBBBBBAAAAAAAADDDA------ A-BBBBBIACAAAAIIIIAAAAAAA A-BBBBBICCAAAAIIIIAAAAAAA A-AABBACCCBBBBAAAAA-----A A-AABBACCCBBBBAAAAA-----A A-AAAAACCCBBAAAAAAA-----A A-AAAAACCCBBAAAAAAA-----A A-AAAAAAAAAAAAAAA-A-----A A-AAAAAAAAAAAAAAA-A-----A A-AAAAAAAAAAAAAAA-A-----A A-AAAAACCCBBBBBBB-A-----A A-AAAAACCCBBBBBBB-A-----A A-EEEEECCCDDDDCCC-AAAAAAA A-GGGCDDDDCCCCCCC-AAAAAAA A-GGGCDDDDCCICCCC-A------ A-GGGCDDDDCCICCCC-A------ A-GGGCDDDDCCICCCCCA------ A-CCCCCCCCCCIICDDDA------ AFLFFFFFFLLFFFFLMMA------ A--J-J-J-J-J-J-J--A------ ---------HHN------------- --------HH-HH------------ -------HH--HHH----------- -----Q-H----HH----------- -------H----------------- 
AAAAAAAAAAAAAAAAAAA------ ABBBBBBAAAAAAAADDDA------ ABBBBBBAAAAAAAADDDA------ ABBBBBBAAAAAAAADDDA------ ABBBBBBAAAAAAAADDDA------ ABBBBBBAAAAAAAADDDA------ A-BBBBBIACAAAAIIIIAAAAAAA A-BBBBBICCAAAAIIIIAAAAAAA A-AABBACCCBBBBAAAAA-----A A-AABBACCCBBBBAAAAA-----A A-AAAAACCCBBAAAAAAA-----A A-AAAAACCCBBAAAAAAA-----A A-AAAAAAAAAAAAAAA-A-----A A-AAAAAAAAAAAAAAA-A-----A A-AAAAAAAA-AAAAAA-A-----A A-AAAAACCCB---BBB-A-----A A-AAAAACCCB-B-BBB-A-----A A-EEEEECCCC-C-CCC-AAAAAAA A-GGGCDDDDCCCCCCC-AAAAAAA A-GGGCDDDDCCICCCC-A------ A-GGGCDDDDCCICCCC-A------ A-GGGCDDDDCCICCCCCA------ A-CCCCCCCCCCIICDDDA------ AFFLLFFLFFFLFFFFFMA------ A---J-J-J-J-J-J---A------ ---------HHH------------- ------------------------- ------------------------- -----H------------------- ------------------------- 
AAAAAAAAAAAAAAAAAAA------ ABBBBBBBBBBBBBBBBBA------ ABBBBBBBBBBBBBBBBBA------ ABBBBBBBBBBBBBBBBBA------ ABBBBBBBBBBBBBBBBBA------ ABBBBBBBBBBBBBBBBBA------ A-BBBBBBBBBBBBBBBBAAAAAAA A-BBBBBBBBBBBBBBBBAAAAAAA A-AABBACCCBBBBAAAAA-----A A-AABBACCCBBBBAAAAA-----A A-AAAAACCCBBAAAAAAA-----A A-AAAAACCCBBAAAAAAA-----A A-AAAAAAAAAAAAAAA-A-----A A-AAAAAAAAAAAAAAA-A-----A A-AAAAAAAA-A-AAAA-A-----A A-AAAAACCCB---AAA-A-----A A-AAAAACCCB-B-AAA-A-----A A-EEEEEEEEE-E-EEE-AAAAAAA A-GGGCDDDDCCCEEEE-AAAAAAA A-GGGCDDDDCCIEEEE-A------ A-GGGCDDDDCCIEEEE-A------ A-GGGCDDDDCCIEEEEEA------ A-CCCCCCCCCCIEEEEEA------ AFMFLFFFLFFFFFFFFMA------ A----J-J-J-J-J----A------ ---------NNN------------- --------NN-HH------------ -------NNH--NH----------- -------N-----N----------- ------------------------- 
AAAAAAAAAAAAAAAAAAA------ ABBBBBBBBBBBBBBBBBA------ ABBBBBBBBBBBBBBBBBA------ ABBBBBBBBBBBBB---BA------ ABBBBBBBBBBBBB---BA------ ABBBBBBBBBBBBB---BA------ ABBBBBBBBBBBBB---BA------ ABBBBBBBBBBBBB---BA------ AAAAAAAAAAAAAA---AA------ AAAAAAAAAAAAAA---AA------ AAAAAAACCCBBAA---AA------ AAAAAAACCCBBAA---AA------ AAAAAAAAAAAAAA---AA------ AAAAAAAAAAAAAA---AA------ AAAAAAAAAA-AAAAA-AA------ AAAAAAACCCB--AAAAAA------ AAAAAAACCCB-BAAAAAA------ AEEEEEEEEEE-EEEEEEA------ AGGGGGDDDDCCCEEEEEA------ AGGGGGDDDDCCIEEEEEA------ AGGGGGDDDDCCIEEEEEA------ AGGGGGDDDDCCIEEEEEA------ AOCCCCCCCCCCIEEEEEA------ AFMMLFLFFFLFLMLFFMA------ A-----J-J-J-J-----A------ ----------Q-------------- ----------H-------------- ------QNQ---H------------ ------------------------- ------------------------- 
-AAAAAAAAAAAAAAAAA------- -ABBBBBBBBBBBBBBBA------- -ABBBBBBBBBBBBBBBA------- -ABBBBBBBBBBBB---A------- -ABBBBBBBBBBBB---A------- -ABBBBBBBBBBBB---A------- -ABBBBBBBBBBBB---A------- -ABBBBBBBBBBBB---A------- -AAAAAAAAAAAAA---A------- -AAAAAAAAAAAAA---A------- -AAAAAABBBBBAA---A------- -AAAAAABBBBBAA---A------- -AAAAAABBBBAAA---A------- -AAAAAABBBBAAA--AA------- -AAAAAABBB-A-AA-AA------- -AAAAAABBBB--AAAAA------- -AAAAAACCCC-CAAAAA------- -AEEEEEEEEE-EEEE-A------- -AGGGGCCCCCCCEEEEA------- -AGGGGCCCCCCIEEEEA------- -AGGGGCCCCCCIEEEEA------- -AGGGGCCCCCCIEEEEA------- -ACCCCCCCCCCIEEEEA------- -AFFLLFFFFLLFMFFMA------- -A-----J-J-J-----A------- ------------------------- ----------QH------------- ------H----H------------- ------------------------- ------------------------- 
-AAAAAAAAAAAAAAAAA------- -ABBBBBBB-BBBBBBBA------- -ABBBBBBB-BBBBBBBA------- -ABBBBBBBBBBBBB-BA------- -ABBBBBBBBBB----BA------- -ABBBBBBBB------BA------- -ABBBBBBBB------BA------- -ABBBBBBBB------BA------- -AAAAAAAAA------AA------- -AAAAAAAAA------AA------- -AAAAAABBB------AA------- -AAAAAABBB------AA------- -AAAAAABBB------AA------- -AAAAAABBB------AA------- -AAAAAABBBB-AAAAAA------- -AAAAAABBBB--AAAAA------- -AAAAAACCCC-CAAAAA------- -AEEEEEEEEE-EEEEEA------- -AGGGGCCCCCCCEEEEA------- -AGGGGCCCCCCIEEEEA------- -AGGGGCCCCCCIEEEEA------- -AGGGGCCCCCCIEEEEA------- -AOCCCCCCCCCIEEEEA------- -AFMMMLFFFFLFMFMMA------- -A------J-J------A------- ------------------------- ----------N-------------- ------------------------- ------------------------- ------------------------- 
--AAAAAAAAAAAAAAA-------- --ABBBBBBBBBBBBBA-------- --ABBBBBBBBBBBBBA-------- --ABBBBBBBBB--BBA-------- --ABBBBBBBB----BA-------- --ABBBBBBB-----BA-------- --ABBBBBBB-----BA-------- --ABBBBBBB-----BA-------- --AAAAAAAA-----AA-------- --AAAAAAAA-----AA-------- --DA--ABBB-----DD-------- --DA--ABBB-----DD-------- --DA--ABBB-----DD-------- --DA--ABBB-----DD-------- --DA--ABBBBADDDDD-------- --AA--ABBB-B-AAAA-------- --AA--ACCC--CAAAA-------- --AE--EEEE--EEEEA-------- --AG--CCCC--CEEEA-------- --AG--CCCC--IEEEA-------- --AG--CCCC--IEEEA-------- --AG--CCCC--IEEEA-------- --AOCCCCCCCCIEEEA-------- --AFFFFFLFFMMFMMA-------- --A------J------A-------- ------------------------- ------------------------- ------------------------- ------------------------- ------------------------- 
---AAAAAAAAAAAAA--------- ---ABBBBBBBBBBBA--------- ---ABBBBBBBBBBBA--------- ---AB----BBB--BA--------- ---AB----BB---BA--------- ---AB---------BA--------- ---AB---------BA--------- ---AB---------BA--------- ---AA---------AA--------- ---AA---------AA--------- ---DD---------DD--------- ---DD---------DD--------- ---DD---------DD--------- ---DD---------DD--------- ---DD------ADDDD--------- ---AA------BBAAA--------- ---AA-------CAAA--------- ---AE-------EEEA--------- ---AG-------CEEA--------- ---AG--------EEA--------- ---AG--------EEA--------- ---AG--------EEA--------- ---AOCCCCCCCBEEA--------- ---AFFFMLMMLFFMA--------- ---A-----------A--------- ------------------------- ------------------------- ------------------------- ------------------------- ------------------------- 
----AAAAAAAAAAA---------- ----AABBBBBBBAA---------- ----AABBBBBBBAA---------- ----AAB---B-BAA---------- ----AAB-----BAA---------- ----AAB-----BAA---------- ----AAB-----BAA---------- ----AAB-----BAA---------- ----AAA-----AAA---------- ----AAA-----AAA---------- ----DDD-----DDD---------- ----DDD-----DDD---------- ----DDD-----DDD---------- ----DDD-----DDD---------- ----DDD-----DDD---------- ----AAA-----BAA---------- ----AAA-----OAA---------- ----AAE-----EAA---------- ----AAO-----OAA---------- ----AAO-----OAA---------- ----AAO-----OAA---------- ----AAO-----OAA---------- ----AAOCCCCCOAA---------- ----AAFFFMMFFAA---------- ----AA-------AA---------- ------------------------- ------------------------- ------------------------- ------------------------- ------------------------- 
------AAAAAAA------------ ------AAAAAAA------------ ------AAAAAAA------------ ------ADDDDDA------------ ------ADDDDDA------------ ------ADDDDDA------------ ------ADDDDDA------------ ------ADDDDDA------------ ------ADDDDDA------------ ------ADDDDDA------------ ------DDDDDDD------------ ------DDDDDDD------------ ------DDDDDDD------------ ------DDDDDDD------------ ------DDDDDDD------------ ------ADDDDDA------------ ------ADDDDDA------------ ------ADDDDDA------------ ------ADDDDDA------------ ------ADDDDDA------------ ------ADDDDDA------------ ------ADDDDDA------------ ------AAAAAAA------------ ------AAAAAAA------------ ------AAAAAAA------------ ------------------------- ------------------------- ------------------------- ------------------------- ------------------------- 
