model
size = 25 30 19, scale = 0.05, origin = -y
material 
  colors = A:#E00 B:#009 C:#CF3 D:#EEE E:#FF0 F:#251505 G:#00C H:#000 I:#BBB J:#CF0 K:#CC6 L:#960 M:#939 N:#1C0900 O:#AAA P:#AAAAB9 Q:#00F R:#888 S:#FCF
voxels
------AAAAAAA------------ ------AAAAAAA------------ ------AAAAAAA------------ ------AAAAAAA------------ ------AAAAAAA------------ ------AAAAAAA------------ ------AAAAAAA------------ ------AAAAAAA------------ ------AAAAAAA------------ ------BBBBBBB------------ ------BBBBBBB------------ ------BBBBBBB------------ ------BBBBBBB------------ ------BBBBBBB------------ ------BBBBBBB------------ ------BBBBBBB------------ ------BBBBBBB------------ ------BBBBBBB------------ ------DDDDDDD------------ ------DDDDDDD------------ ------DDDDDDD------------ ------DDDDDDD------------ ------DDDDDDD------------ ------DDDDDDD------------ ------DDDDDDD------------ ------------------------- ------------------------- ------------------------- ------O------------------ ------------------------- 
----AAAAAAAAAAA---------- ----AAA---AAAAA---------- ----AAA---AAAAA---------- ----AAA---AAAAA---------- ----AAA---AAAAA---------- ----AAA---AAAAA---------- ----AAA---AAAAA---------- ----AAA--AAAAAA---------- ----AAA--AAAAAA---------- ----BBB--BBBBBB---------- ----BBB--BBBBBB---------- ----BBB-BBBBBBB---------- ----BBBBBBBBBBB---------- ----BBBBBBBBBBB---------- ----BBBBBBBBBBB---------- ----BBBBBBBBBBB---------- ----BBBBBBBBBBB---------- ----BBBBBBBBBBB---------- ----DDAAAAAAADD---------- ----DDAAAAAAADD---------- ----DDAAAAAAADD---------- ----DDAAAAAAADD---------- ----DDAAAAAAADD---------- ----DDFFFFFFFDD---------- ----DD-------DD---------- ------------------------- ------------------------- ------------------------- ------I------------------ ------I------------------ 
---AAAAAAAAAAAAA--------- ---AAA--------AA--------- ---AAAAAAAAAAAAA--------- ---AAAAAAAAAAAAA--------- ---AAAAAAAAAAAAA--------- ---AAAAAAAAAAAAA--------- ---AAAAAAAAAAAAA--------- ---AAAAAAAAAAAAA--------- ---AAAAAAAAAAAAA--------- ---BBBBBBBBBBBBB--------- ---BBBBBBBBBBBBB--------- ---BBBBBBBBBBBBB--------- ---BBBBBBBBBBBBB--------- ---BBBBBBBBBBBBB--------- ---BBBBBBBBBBBBB--------- ---BBBBBBBBBBBBB--------- ---BBAAAAAAAAABB--------- ---BBAAAAAAAAABB--------- ---DAAAAAAAAAAAD--------- ---DAAAAAAAAAAAD--------- ---DAAAAAAAAAAAD--------- ---DAAAAAAAAAAAD--------- ---DPCCCCCCCCCPD--------- ---DFFFFFFLNFFFD--------- ---D-----------D--------- ------------------------- ------------------------- ------------------------- ------------------------- ------II----------------- 
--AAAAAAAAAAAAAAA-------- --AAAAAAAAAAAAAAA-------- --AAAAAAAAAAAAAAA-------- --AAAAAAAAAAAAAAA-------- --AAAAAAAAAAAAAAA-------- --AAAAAAAAAAAAAAA-------- --AAAAAAAAAAAAAAA-------- --AAAAAAAAAAAAAAA-------- --AAAAAAAAAAAAAAA-------- --BBBB--------BBB-------- --BBBBBBBBBBBBBBB-------- --BBBBBBBBBBBBBBB-------- --BBBBBBBBBBBBBBB-------- --BBBBBBBB-BBBBBB-------- --BBBBBBBB-BBBBBB-------- --BBBBBBBB-BBBBBB-------- --BBBCCCCC-EAABBB-------- --BBBHHHHH-HHHBBB-------- --DGGCCCCC-CCCCPD-------- --DGGCCCCC-CCCCPD-------- --DGGCCCCC-CCCCPD-------- --DGGCCCCC-CCCCPD-------- --DPCCCCCC-CCCCDD-------- --DFFFFLFLFFNNFFD-------- --D------K------D-------- ------------------------- ------------------------- ------------------------- ---I--------------------- -------I----------------- 
-AAAAAAAAAAAAAAAAA------- -AAAAAAAAAAAAAA-AA------- -AAAAAAAAAAAAAA-AA------- -AAAAAAAAAAAAAA-AA------- -AAAAAAAAAAAAAA-AA------- -AAAAAAAAAAAAAA-AA------- -AAAAAAAAAAAAAA-AA------- -AAAAAAAAAAAAAA-AA------- -AAAAAAAAAAAAAA-AA------- -BBBBBBBBBBBBBB-BB------- -BB-BBBBBBBBBBB-BB------- -BB-BBBBBBBBBBB-BB------- -BB-BBBBBBBBBBB-BB------- -BB-BBBBBBBBBBB-BB------- -BB-BBBBBBBBBBB-BB------- -BBBBBBBBBBBBBB-BB------- -BB-BCCCCCEEAAB-BB------- -BB-BHHHHHHHHHB-BB------- -DD-GCCCCCCCCCC-PD------- -DD-GCCCCCCCCCC-PD------- -DD-GCCCCCCCCCC-PD------- -DDGGCCCCCCCCCC-PD------- -DPECCCCCCCCCCC-DD------- -DFFLFLFLFFLNLFFFD------- -D------K-K------D------- ------------------------- ------------------------- ------------------------- ---I--------------------- ---O---I----------------- 
-AAAAAAAAAAAAAAAAA------- -AAAAAAAAAAAAEQQQA------- -AAAAAAAAAAAAEQDDA------- -AAAAAAAAAAAAEQQQA------- -AAAAAAAAAAAAEEEEA------- -AAAAAAAAAAAAEEEEA------- -AAAAAAAAAAAAEEEEA------- -AAAAAAAAAAAAEEDDA------- -AAAAAAAAAAAAEDDDA------- -BBBBEEEEEEEEEBBBB------- -BBBBAAAAAEEAABBBB------- -BBBBAAAAAAAAABBBB------- -BBBBAAAAAAAAABBBB------- -BBBBAAAAAAAAABBBB------- -BBBBAAAAAAAAABBBB------- -BBBBACCCCEEAAABBB------- -BBBBCCCCCEEAABBBB------- -BBBBHHCCAAAAABBBB------- -DDGGCCCCCCCCCCCCD------- -DDGGCCCCCCCCCCCCD------- -DDGGCCCCCCCCCCCCD------- -DDGGCCCCCCCCCCCCD------- -DCCCCCCCCCCCCCDDD------- -DLFLLFLFFFLFFLLFD------- -D-----K-K-K-----D------- ------------------------- ------------------------- ------------------------- ------------------------- ---R--IO----------------- 
AAAAAAAAAAAAAAAAAAA------ AAAAAEEEEEEEEEEEEDA------ AAAAAEEEEEEEEEEEEDA------ AAAAAEEEEEEEEEEEEDA------ AAAAAEEEEEEEEEEEEDA------ AAAAAEEEEEEEEEEEEDA------ AAAAAEEEEEEEEEEEEDA------ AAAAAEEEEEEEEEEEEDA------ AAAAAEEEEEEEEEAAAAA------ BBBBBBBEEEEEEEBBBBB------ BBBBBBBAAAEEAABBBBB------ BBBBBBBAAAAAAABBBBB------ BBBBBBBAAAAAAABBBBB------ BBBBBBBAAAAAAABBBBB------ BBBBBBBAAAAAAABBBBB------ BBBBBBBCCCEEEEEBBBB------ BBBBBCCCCCEEEEBBBBB------ BBBBBHHCCAAAAABBBBB------ DGGGGCCCCCCCCMMMCPD------ DGGGGCCCCCCCCMMMCPD------ DGGGGCCCCCCCCMMMCPD------ DGGGGCCCCCCCCMMMCPD------ DPCCCCCCCCCCCMMDDDD------ DFFFFFLLFFFFFLNFFND------ D-----K-K-K-K-----D------ ------------------------- ---------III------------- --------OI-II------------ ----OOOOO---II----------- ---OO-OO-----I----------- 
AAAAAAAAAAAAAAAAAAA------ AAAAAEEAAAAAAAADDDA------ AAAAAEEAAAAAAAADDDA------ AAAAAEEAAAAAAAADDDA------ AAAAAEEAAAAAAAADDDA------ AAAAAEEAAAAAAAADDDA------ A-AAAEEJCCCCJAJDDDAAAAAAA A-AAAEEEEEEEEEEEEEAAAAAAA A-AAAEAEEEEEEEAAAAA-----B B-BBBBBEEEEEEEBBBBB-----B B-BBBB--AAEEAABBBBB-----B B-BBBB------AABBBBB-----B B-BBBB------A--BB-B-----B B-BBBBBAAAAAAABBB-B-----B B-BBBBBAAAAAAABBB-B-----B B-BBBBBCCCEEEEEBB-B-----B B-BBBBBBBCEEEEBBB-B-----B B-BBBBBBBCDDDMBBB-BBBBBBB D-GGGCCCCCCCCMMMC-ADDDDDD D-GGGCCCCCCCCMMMC-D------ D-GGGCCCCCCCCMMMC-D------ D-GGGCCCCCCCCMMMCCD------ D-CCCCCCCCCCCMMDDDD------ DFFFFFFFFLFFFLFLNFD------ D----K-K-K-K-K----D------ ------------------------- ---------III------------- ------------------------- ----OII------------------ ------------------------- 
AAAAAAAAAAAAAAAAAAA------ AAAAAEEAAAAAAAADDDA------ AAAAAEEAAAAAAAADDDA------ AAAAAEEAAAAAAAADDDA------ AAAAAEEAAAAAAAADDDA------ AAAAAEEAAAAAAAADDDA------ A-AAAEEJCCCCJAJJJJEAAAAAA A-AAAEEEEEEEEEEEEEEAAAAAA A-AAAEAEEEEEEEAAAAA-----B B-BBBBBEEEEEEBBBBBB-----B B-BBBB--AAEEABBBBBB-----B B-BBBB------ABBBBBB-----B B-BBBB------A-BBB-B-----B B-BBBBBAAAAAABBBB-B-----B B-BBBBBAAAAAABBBB-B-----B B-BBBBBCCCEEEBBBB-B-----B B-BBBBBBBCEEEEEEE-B-----B B-BBBBBBBCDDDMMMC-BBBBBBB D-GGGCCCCCCCCMMMC-PDDDDDD D-GGGCCCCCCCCMMMC-D------ D-GGGCCCCCCCCMMMC-D------ D-GGGCCCCCCCCMMMCCD------ D-CCCCCCCCCCCMMDDDD------ DFFFFFFLFFFFFFFFFND------ D---K-K-K-K-K-K---D------ ------------------------- ---------III------------- --------OI-II------------ ----OOOSO---II----------- ---OO-II-----I----------- 
AAAAAAAAAAAAAAAAAAA------ AAAAAEEAAAAAAAADDDA------ AAAAAEEAAAAAAAADDDA------ AAAAAEEAAAAAAAADDDA------ AAAAAEEAAAAAAAADDDA------ AAAAAEEAAAAAAAADDDA------ A-AAAEEJACAAAAJJJJAAAAAAA A-AAAEEJCCAAAAJJJJAAAAAAA A-AAAEACCCEEEEAAAAA-----B B-BBBBBCCCEEEBBBBBB-----B B-BBBBBCCCEEABBBBBB-----B B-BBBBBCCCEEABBBBBB-----B B-BBBBBAAAAAABBBB-B-----B B-BBBBBAAAAAABBBB-B-----B B-BBBBBAAAAAABBBB-B-----B B-BBBBBCCCEEEBBBB-B-----B B-BBBBBBBCEEEEEEE-B-----B B-BBBBBBBCDDDDCCC-BBBBBBB D-GGGCDDDDCCCCCCC-ADDDDDD D-GGGCDDDDCCJCCCC-D------ D-GGGCDDDDCCJCCCC-D------ D-GGGCDDDDCCJCCCCCD------ D-CCCCCCCCCCJJCDDDD------ DFLFFFFFFLLFFFFLNND------ D--K-K-K-K-K-K-K--D------ ---------IIO------------- --------II-II------------ -------II--III----------- -----R-I----II----------- -------I----------------- 
AAAAAAAAAAAAAAAAAAA------ AAAAAEEAAAAAAAADDDA------ AAAAAEEAAAAAAAADDDA------ AAAAAEEAAAAAAAADDDA------ AAAAAEEAAAAAAAADDDA------ AAAAAEEAAAAAAAADDDA------ A-AAAEEJACAAAAJJJJAAAAAAA A-AAAEEJCCAAAAJJJJAAAAAAA A-AAAEACCCEEEEAAAAA-----B B-BBBBBCCCEEEBBBBBB-----B B-BBBBBCCCEEABBBBBB-----B B-BBBBBCCCEEABBBBBB-----B B-BBBBBAAAAAABBBB-B-----B B-BBBBBAAAAAABBBB-B-----B B-BBBBBAAA-AABBBB-B-----B B-BBBBBCCCE---BBB-B-----B B-BBBBBBBCE-E-EEE-B-----B B-BBBBBBBCC-C-CCC-BBBBBBB D-GGGCDDDDCCCCCCC-ADDDDDD D-GGGCDDDDCCJCCCC-D------ D-GGGCDDDDCCJCCCC-D------ D-GGGCDDDDCCJCCCCCD------ D-CCCCCCCCCCJJCDDDD------ DFFLLFFLFFFLFFFFFND------ D---K-K-K-K-K-K---D------ ---------III------------- ------------------------- ------------------------- -----I------------------- ------------------------- 
AAAAAAAAAAAAAAAAAAA------ AAAAAEEEEEEEEEEEEEA------ AAAAAEEEEEEEEEEEEEA------ AAAAAEEEEEEEEEEEEEA------ AAAAAEEEEEEEEEEEEEA------ AAAAAEEEEEEEEEEEEEA------ A-AAAEEEEEEEEEEEEEAAAAAAA A-AAAEEEEEEEEEEEEEAAAAAAA A-AAAEACCCEEEEAAAAA-----B B-BBBBBCCCEEEBBBBBB-----B B-BBBBBCCCEEABBBBBB-----B B-BBBBBCCCEEABBBBBB-----B B-BBBBBAAAAAABBBB-B-----B B-BBBBBAAAAAABBBB-B-----B B-BBBBBAAA-A-BBBB-B-----B B-BBBBBCCCE---BBB-B-----B B-BBBBBBBCE-E-AAA-B-----B B-BBBBBBBHH-H-HHH-BBBBBBB D-GGGCDDDDCCCHHHH-ADDDDDD D-GGGCDDDDCCJHHHH-D------ D-GGGCDDDDCCJHHHH-D------ D-GGGCDDDDCCJHHHHHD------ D-CCCCCCCCCCJHHHHHD------ DFNFLFFFLFFFFFFFFND------ D----K-K-K-K-K----D------ ---------OOO------------- --------OO-II------------ -------OOI--OI----------- -------O-----O----------- ------------------------- 
AAAAAAAAAAAAAAAAAAA------ AAAAAAAAAAAAAAAAAAA------ AAAAAAAAAAAAAAAAAAA------ AAAAAAAAAAAAAA---AA------ AAAAAAAAAAAAAA---AA------ AAAAAAAAAAAAAA---AA------ AAAAAAAAAAAAAA---AA------ AAAAAAAAAAAAAA---AA------ AAAAAAAAAAAAAA---AA------ BBBBBBBAAAAAAB---BB------ BBBBBBBCCCEEAB---BB------ BBBBBBBCCCEEAB---BB------ BBBBBBBAAAAAAB---BB------ BBBBBBBAAAAAAB---BB------ BBBBBBBAAA-AABBB-BB------ BBBBBBBCCBB--BBBBBB------ BBBBBBBBBBB-BBBBBBB------ BBBBBBBBBBB-BBBBBBB------ DGGGGGDDDDCCCHHHHHD------ DGGGGGDDDDCCJHHHHHD------ DGGGGGDDDDCCJHHHHHD------ DGGGGGDDDDCCJHHHHHD------ DPCCCCCCCCCCJHHHHHD------ DFNNLFLFFFLFLNLFFND------ D-----K-K-K-K-----D------ ----------R-------------- ----------I-------------- ------ROR---I------------ ------------------------- ------------------------- 
-AAAAAAAAAAAAAAAAA------- -AAAAAAAAAAAAAAAAA------- -AAAAAAAAAAAAAAAAA------- -AAAAAAAAAAAAA---A------- -AAAAAAAAAAAAA---A------- -AAAAAAAAAAAAA---A------- -AAAAAAAAAAAAA---A------- -AAAAAAAAAAAAA---A------- -AAAAAAAAAAAAA---A------- -BBBBBBAAAAAAB---B------- -BBBBBBEEEEEAB---B------- -BBBBBBEEEEEAB---B------- -BBBBBBEEEEAAB---B------- -BBBBBBEEEEAAB--BB------- -BBBBBBEEE-A-BB-BB------- -BBBBBBEEBB--BBBBB------- -BBBBBBBBBB-BBBBBB------- -BBBBBBBBBB-BBBB-B------- -DGGGGCCCCCCCHHHHD------- -DGGGGCCCCCCJHHHHD------- -DGGGGCCCCCCJHHHHD------- -DGGGGCCCCCCJHHHHD------- -DCCCCCCCCCCJHHHHD------- -DFFLLFFFFLLFNFFND------- -D-----K-K-K-----D------- ------------------------- ----------RI------------- ------I----I------------- ------------------------- ------------------------- 
-AAAAAAAAAAAAAAAAA------- -AAAAAAAA-AAAAAAAA------- -AAAAAAAA-AAAAAAAA------- -AAAAAAAAAAAAAA-AA------- -AAAAAAAAAAA----AA------- -AAAAAAAAA------AA------- -AAAAAAAAA------AA------- -AAAAAAAAA------AA------- -AAAAAAAAA------AA------- -BBBBBBAAA------BB------- -BBBBBBEEE------BB------- -BBBBBBEEE------BB------- -BBBBBBEEE------BB------- -BBBBBBEEE------BB------- -BBBBBBEEEE-ABBBBB------- -BBBBBBEEBB--BBBBB------- -BBBBBBBBBB-BBBBBB------- -BBBBBBBBBB-BBBBBB------- -DGGGGCCCCCCCHHHHD------- -DGGGGCCCCCCJHHHHD------- -DGGGGCCCCCCJHHHHD------- -DGGGGCCCCCCJHHHHD------- -DPCCCCCCCCCJHHHHD------- -DFNNNLFFFFLFNFNND------- -D------K-K------D------- ------------------------- ----------O-------------- ------------------------- ------------------------- ------------------------- 
--AAAAAAAAAAAAAAA-------- --AAAAAAAAAAAAAAA-------- --AAAAAAAAAAAAAAA-------- --AAAAAAAAAA--AAA-------- --AAAAAAAAA----AA-------- --AAAAAAAA-----AA-------- --AAAAAAAA-----AA-------- --AAAAAAAA-----AA-------- --AAAAAAAA-----AA-------- --BBBBBAAA-----BB-------- --BB--BEEE-----BB-------- --BB--BEEE-----BB-------- --BB--BEEE-----BB-------- --BB--BEEE-----BB-------- --BB--BEEEEADBBBB-------- --BB--BEEB-B-BBBB-------- --BB--BBBB--BBBBB-------- --BB--BBBB--BBBBB-------- --DG--CCCC--CHHHD-------- --DG--CCCC--JHHHD-------- --DG--CCCC--JHHHD-------- --DG--CCCC--JHHHD-------- --DPCCCCCCCCJHHHD-------- --DFFFFFLFFNNFNND-------- --D------K------D-------- ------------------------- ------------------------- ------------------------- ------------------------- ------------------------- 
---AAAAAAAAAAAAA--------- ---AAAAAAAAAAAAA--------- ---AAAAAAAAAAAAA--------- ---AA----AAA--AA--------- ---AA----AA---AA--------- ---AA---------AA--------- ---AA---------AA--------- ---AA---------AA--------- ---AA---------AA--------- ---BB---------BB--------- ---BB---------BB--------- ---BB---------BB--------- ---BB---------BB--------- ---BB---------BB--------- ---BB------ADBBB--------- ---BB------BBBBB--------- ---BB-------BBBB--------- ---BB-------BBBB--------- ---DG-------CHHD--------- ---DG--------HHD--------- ---DG--------HHD--------- ---DG--------HHD--------- ---DPCCCCCCCEHHD--------- ---DFFFNLNNLFFND--------- ---D-----------D--------- ------------------------- ------------------------- ------------------------- ------------------------- ------------------------- 
----AAAAAAAAAAA---------- ----AAAAAAAAAAA---------- ----AAAAAAAAAAA---------- ----AAA---A-AAA---------- ----AAA-----AAA---------- ----AAA-----AAA---------- ----AAA-----AAA---------- ----AAA-----AAA---------- ----AAA-----AAA---------- ----BBB-----BBB---------- ----BBB-----BBB---------- ----BBB-----BBB---------- ----BBB-----BBB---------- ----BBB-----BBB---------- ----BBB-----BBB---------- ----BBB-----BBB---------- ----BBB-----BBB---------- ----BBB-----BBB---------- ----DDP-----PDD---------- ----DDP-----PDD---------- ----DDP-----PDD---------- ----DDP-----PDD---------- ----DDPCCCCCPDD---------- ----DDFFFNNFFDD---------- ----DD-------DD---------- ------------------------- ------------------------- ------------------------- ------------------------- ------------------------- 
------AAAAAAA------------ ------AAAAAAA------------ ------AAAAAAA------------ ------AAAAAAA------------ ------AAAAAAA------------ ------AAAAAAA------------ ------AAAAAAA------------ ------AAAAAAA------------ ------AAAAAAA------------ ------BBBBBBB------------ ------BBBBBBB------------ ------BBBBBBB------------ ------BBBBBBB------------ ------BBBBBBB------------ ------BBBBBBB------------ ------BBBBBBB------------ ------BBBBBBB------------ ------BBBBBBB------------ ------DDDDDDD------------ ------DDDDDDD------------ ------DDDDDDD------------ ------DDDDDDD------------ ------DDDDDDD------------ ------DDDDDDD------------ ------DDDDDDD------------ ------------------------- ------------------------- ------------------------- ------------------------- ------------------------- 
