model
size = 25 30 19, scale = 0.05, origin = -y
material 
  colors = A:#FF0 B:#009 C:#06C D:#E00 E:#CF3 F:#251505 G:#EEE H:#00C I:#000 J:#BBB K:#CC6 L:#960 M:#939 N:#CF0 O:#1C0900 P:#AAA Q:#AAAAB9 R:#888 S:#FCF
voxels
------AAAAAAA------------ ------AAAAAAA------------ ------AAAAAAA------------ ------AAAAAAA------------ ------AAAAAAA------------ ------AAAAAAA------------ ------AAAAAAA------------ ------AAAAAAA------------ ------AAAAAAA------------ ------AAAAAAA------------ ------AAAAAAA------------ ------AAAAAAA------------ ------CCCCCCC------------ ------CCCCCCC------------ ------CCCCCCC------------ ------CCCCCCC------------ ------CCCCCCC------------ ------CCCCCCC------------ ------CCCCCCC------------ ------CCCCCCC------------ ------CCCCCCC------------ ------CCCCCCC------------ ------CCCCCCC------------ ------CCCCCCC------------ ------CCCCCCC------------ ------------------------- ------------------------- ------------------------- ------P------------------ ------------------------- 
----AAAAAAAAAAA---------- ----AAA---AAAAA---------- ----AAA---AAAAA---------- ----AAA---AAAAA---------- ----AAA---AAAAA---------- ----AAA---AAAAA---------- ----AAA---AAAAA---------- ----AAA--AAAAAA---------- ----AAA--AAAAAA---------- ----AAA--AAAAAA---------- ----AAA--AAAAAA---------- ----AAA-AAAAAAA---------- ----CCBBBBBBBCC---------- ----CCBBBBBBBCC---------- ----CCBBBBBBBCC---------- ----CCBBBBBBBCC---------- ----CCBBBBBBBCC---------- ----CCBBBBBBBCC---------- ----CCDDDDDDDCC---------- ----CCDDDDDDDCC---------- ----CCDDDDDDDCC---------- ----CCDDDDDDDCC---------- ----CCDDDDDDDCC---------- ----CCFFFFFFFCC---------- ----CC-------CC---------- ------------------------- ------------------------- ------------------------- ------J------------------ ------J------------------ 
---AAAAAAAAAAAAA--------- ---AAA--------AA--------- ---AAAAAAAAAAAAA--------- ---AAAAAAAAAAAAA--------- ---AAAAAAAAAAAAA--------- ---AAAAAAAAAAAAA--------- ---AAAAAAAAAAAAA--------- ---AAAAAAAAAAAAA--------- ---AAAAAAAAAAAAA--------- ---AAAAAAAAAAAAA--------- ---AAAAAAAAAAAAA--------- ---AAAAAAAAAAAAA--------- ---CGBBBBBBBBBBC--------- ---CGBBBBBBBBBBC--------- ---CGBBBBBBBBBBC--------- ---CGBBBBBBBBBBC--------- ---CGDDDDDDDDDBC--------- ---CGDDDDDDDDDBC--------- ---CGDDDDDDDDDDC--------- ---CGDDDDDDDDDDC--------- ---CGDDDDDDDDDDC--------- ---CGDDDDDDDDDDC--------- ---CGEEEEEEEEEQC--------- ---CLFFFFFLOFFFC--------- ---C-----------C--------- ------------------------- ------------------------- ------------------------- ------------------------- ------JJ----------------- 
--AAAAAAAAAAAAAAA-------- --AAAAAAAAAAAAAAA-------- --AAAAAAAAAAAAAAA-------- --AAAAAAAAAAAAAAA-------- --AAAAAAAAAAAAAAA-------- --AAAAAAAAAAAAAAA-------- --AAAAAAAAAAAAAAA-------- --AAAAAAAAAAAAAAA-------- --AAAAAAAAAAAAAAA-------- --AAAA--------AAA-------- --AAAAAAAAAAAAAAA-------- --AAAAAAAAAAAAAAA-------- --CGBBBBBBBBBBBBC-------- --CGBBBBBB-BBBBBC-------- --CGBBBBBB-BBBBBC-------- --CGBBBBBB-BBBBBC-------- --CGBEEEEE-ADDBBC-------- --CGBIIIII-IIIBBC-------- --CGHEEEEE-EEEEQC-------- --CGHEEEEE-EEEEQC-------- --CGHEEEEE-EEEEQC-------- --CGHEEEEE-EEEEQC-------- --CGEEEEEE-EEEEGC-------- --CLFFFLFLFFOOFFC-------- --C------K------C-------- ------------------------- ------------------------- ------------------------- ---J--------------------- -------J----------------- 
-AAAAAAAAAAAAAAAAA------- -AAAAAAAAAAAAAA-AA------- -AAAAAAAAAAAAAA-AA------- -AAAAAAAAAAAAAA-AA------- -AAAAAAAAAAAAAA-AA------- -AAAAAAAAAAAAAA-AA------- -AAAAAAAAAAAAAA-AA------- -AAAAAAAAAAAAAA-AA------- -AAAAAAAAAAAAAA-AA------- -AAAAAAAAAAAAAA-AA------- -AA-AAAAAAAAAAA-AA------- -AA-AAAAAAAAAAA-AA------- -CB-BBBBBBBBBBB-GC------- -CB-BBBBBBBBBBB-GC------- -CB-BBBBBBBBBBB-GC------- -CBBBBBBBBBBBBB-GC------- -CB-BEEEEEAADDB-GC------- -CB-BIIIIIIIIIB-GC------- -CG-HEEEEEEEEEE-GC------- -CG-HEEEEEEEEEE-GC------- -CG-HEEEEEEEEEE-GC------- -CGHHEEEEEEEEEE-GC------- -CQAEEEEEEEEEEE-GC------- -CFFLFLFLFFLOLFFLC------- -C------K-K------C------- ------------------------- ------------------------- ------------------------- ---J--------------------- ---P---J----------------- 
-AAAAAAAAAAAAAAAAA------- -AAAAAAAAAAAAAAAAA------- -AAAAAAAAAAAAAAAAA------- -AAAAAAAAAAAAAAAAA------- -AAAAAAAAAAAAAAAAA------- -AAAAAAAAAAAAAAAAA------- -AAAAAAAAAAAAAAAAA------- -AAAAAAAAAAAAAAAAA------- -AAAAAAAAAAAAAAAAA------- -AAAAAAAAAAAAAAAAA------- -AAAAAAAAAAAAAAAAA------- -AAAAAAAAAAAAAAAAA------- -CBBBDDDDDDDDDBBBC------- -CBBBDDDDDDDDDBBBC------- -CBBBDDDDDDDDDBBBC------- -CBBBDEEEEAADDDBBC------- -CBBBEEEEEAADDBBBC------- -CBBBIIEEDDDDDBBBC------- -CGHHEEEEEEEEEEEEC------- -CGHHEEEEEEEEEEEEC------- -CGHHEEEEEEEEEEEEC------- -CGHHEEEEEEEEEEEEC------- -CEEEEEEEEEEEEEGGC------- -CLFLLFLFFFLFFLLFC------- -C-----K-K-K-----C------- ------------------------- ------------------------- ------------------------- ------------------------- ---R--JP----------------- 
AAAAAAAAAAAAAAAAAAA------ AAAAAAAAAAAAAAAAAAA------ AAAAAAAAAAAAAAAAAAA------ AAAAAAAAAAAAAAAAAAA------ AAAAAAAAAAAAAAAAAAA------ AAAAAAAAAAAAAAAAAAA------ AAAAAAAAAAAAAAAAAAA------ AAAAAAAAAAAAAAAAAAA------ AAAAAAAAAAAAAAAAAAA------ AAAAAAAAAAAAAAAAAAA------ AAAAAAAAAAAAAAAAAAA------ AAAAAAAAAAAAAAAAAAA------ CBBBBBBDDDDDDDBBBBC------ CBBBBBBDDDDDDDBBBBC------ CBBBBBBDDDDDDDBBBBC------ CBBBBBBEEEAAAAABBBC------ CBBBBEEEEEAAAABBBBC------ CBBBBIIEEDDDDDBBBBC------ CHHHHEEEEEEEEMMMEQC------ CHHHHEEEEEEEEMMMEQC------ CHHHHEEEEEEEEMMMEQC------ CHHHHEEEEEEEEMMMEQC------ CQEEEEEEEEEEEMMGGGC------ CFFFFFLLFFFFFLOFFOC------ C-----K-K-K-K-----C------ ------------------------- ---------JJJ------------- --------PJ-JJ------------ ----PPPPP---JJ----------- ---PP-PP-----J----------- 
AAAAAAAAAAAAAAAAAAA------ AAAAAAADAAAAAAAAAAA------ AAAAAAADAAAAAAAAAAA------ AAAAAAADAAAAAAAAAAA------ AAAAAAADAAAAAAAAAAA------ AAAAAAADAAAAAAAAAAA------ A-AAAAANAAAAAAAAAAAAAAAAA A-AAAAAAAAAAAAAAAAAAAAAAA A-AAAADAAAAAAAAAAAA-----A A-AAABBAAAAAAAAAAAA-----A A-AAAB--AAAAAAAAAAA-----A A-AAAB------AAAAAAA-----A C-BBBB------D--BB-C-----C C-BBBBBDDDDDDDBBB-C-----C C-BBBBBDDDDDDDBBB-C-----C C-BBBBBEEEAAAAABB-C-----C C-BBBBBBBEAAAABBB-C-----C C-BBBBBBBEGGGMBBB-BCCCCCC C-HHHEEEEEEEEMMME-DCCCCCC C-HHHEEEEEEEEMMME-C------ C-HHHEEEEEEEEMMME-C------ C-HHHEEEEEEEEMMMEEC------ C-EEEEEEEEEEEMMGGGC------ CFFFFFFFFLFFFLFLOFC------ C----K-K-K-K-K----C------ ------------------------- ---------JJJ------------- ------------------------- ----PJJ------------------ ------------------------- 
AAAAAAAAAAAAAAAAAAA------ AAAAAAADDDDDDAAAAAA------ AAAAAAADDDDDDAAAAAA------ AAAAAAADDDDDDAAAAAA------ AAAAAAADDDDDDAAAAAA------ AAAAAAADDDDDDAAAAAA------ A-AAAAANEEEENAAAAAAAAAAAA A-AAAAAAAAAAAAAAAAAAAAAAA A-AAAADAAAAAAAAAAAA-----A A-AAABBAAAAAAAAAAAA-----A A-AAAB--DDAADAAAAAA-----A A-AAAB------DAAAAAA-----A C-BBBB------D-BBB-C-----C C-BBBBBDDDDDDBBBB-C-----C C-BBBBBDDDDDDBBBB-C-----C C-BBBBBEEEAAABBBB-C-----C C-BBBBBBBEAAAAAAA-C-----C C-BBBBBBBEGGGMMME-BCCCCCC C-HHHEEEEEEEEMMME-QCCCCCC C-HHHEEEEEEEEMMME-C------ C-HHHEEEEEEEEMMME-C------ C-HHHEEEEEEEEMMMEEC------ C-EEEEEEEEEEEMMGGGC------ CFFFFFFLFFFFFFFFFOC------ C---K-K-K-K-K-K---C------ ------------------------- ---------JJJ------------- --------PJ-JJ------------ ----PPPSP---JJ----------- ---PP-JJ-----J----------- 
AAAAAAAAAAAAAAAAAAA------ AAAAAAADDDDDDAAAAAA------ AAAAAAADDDDDDAAAAAA------ AAAAAAADDDDDDAAAAAA------ AAAAAAADDDDDDAAAAAA------ AAAAAAADDDDDDAAAAAA------ A-AAAAANDEDDDAAAAAAAAAAAA A-AAAAANEEDDDAAAAAAAAAAAA A-AAAADEEEAAAAAAAAA-----A A-AAABBEEEAAAAAAAAA-----A A-AAABBEEEAADAAAAAA-----A A-AAABBEEEAADAAAAAA-----A C-BBBBBDDDDDDBBBB-C-----C C-BBBBBDDDDDDBBBB-C-----C C-BBBBBDDDDDDBBBB-C-----C C-BBBBBEEEAAABBBB-C-----C C-BBBBBBBEAAAAAAA-C-----C C-BBBBBBBEGGGGEEE-BCCCCCC C-HHHEGGGGEEEEEEE-DCCCCCC C-HHHEGGGGEENEEEE-C------ C-HHHEGGGGEENEEEE-C------ C-HHHEGGGGEENEEEEEC------ C-EEEEEEEEEENNEGGGC------ CFLFFFFFFLLFFFFLOOC------ C--K-K-K-K-K-K-K--C------ ---------JJP------------- --------JJ-JJ------------ -------JJ--JJJ----------- -----R-J----JJ----------- -------J----------------- 
AAAAAAAAAAAAAAAAAAA------ AAAAAAADDDDDDAAAAAA------ AAAAAAADDDDDDAAAAAA------ AAAAAAADDDDDDAAAAAA------ AAAAAAADDDDDDAAAAAA------ AAAAAAADDDDDDAAAAAA------ A-AAAAANDEDDDAAAAAAAAAAAA A-AAAAANEEDDDAAAAAAAAAAAA A-AAAADEEEAAAAAAAAA-----A A-AAABBEEEAAAAAAAAA-----A A-AAABBEEEAADAAAAAA-----A A-AAABBEEEAADAAAAAA-----A C-BBBBBDDDDDDBBBB-C-----C C-BBBBBDDDDDDBBBB-C-----C C-BBBBBDDD-DDBBBB-C-----C C-BBBBBEEEA---BBB-C-----C C-BBBBBBBEA-A-AAA-C-----C C-BBBBBBBEE-E-EEE-BCCCCCC C-HHHEGGGGEEEEEEE-DCCCCCC C-HHHEGGGGEENEEEE-C------ C-HHHEGGGGEENEEEE-C------ C-HHHEGGGGEENEEEEEC------ C-EEEEEEEEEENNEGGGC------ CFFLLFFLFFFLFFFFFOC------ C---K-K-K-K-K-K---C------ ---------JJJ------------- ------------------------- ------------------------- -----J------------------- ------------------------- 
AAAAAAAAAAAAAAAAAAA------ AAAAAAAAAAAAAAAAAAA------ AAAAAAAAAAAAAAAAAAA------ AAAAAAAAAAAAAAAAAAA------ AAAAAAAAAAAAAAAAAAA------ AAAAAAAAAAAAAAAAAAA------ A-AAAAAAAAAAAAAAAAAAAAAAA A-AAAAAAAAAAAAAAAAAAAAAAA A-AAAADEEEAAAAAAAAA-----A A-AAABBEEEAAAAAAAAA-----A A-AAABBEEEAADAAAAAA-----A A-AAABBEEEAADAAAAAA-----A C-BBBBBDDDDDDBBBB-C-----C C-BBBBBDDDDDDBBBB-C-----C C-BBBBBDDD-D-BBBB-C-----C C-BBBBBEEEA---BBB-C-----C C-BBBBBBBEA-A-DDD-C-----C C-BBBBBBBII-I-III-BCCCCCC C-HHHEGGGGEEEIIII-DCCCCCC C-HHHEGGGGEENIIII-C------ C-HHHEGGGGEENIIII-C------ C-HHHEGGGGEENIIIIIC------ C-EEEEEEEEEENIIIIIC------ CFOFLFFFLFFFFFFFFOC------ C----K-K-K-K-K----C------ ---------PPP------------- --------PP-JJ------------ -------PPJ--PJ----------- -------P-----P----------- ------------------------- 
AAAAAAAAAAAAAAAAAAA------ AAAAADDDDDDDDAAAAAA------ AAAAADDDDDDDDAAAAAA------ AAAAADDDDDDDDA---AA------ AAAAADDDDDDDDA---AA------ AAAAADDDDDDDDA---AA------ AAAAADDDDDDDDA---AA------ AAAAADDDDDDDDA---AA------ AAAAADDDDDDDDA---AA------ AAAAABBDDDDDDA---AA------ AAAAABBEEEAADA---AA------ AAAAABBEEEAADA---AA------ CBBBBBBDDDDDDB---BC------ CBBBBBBDDDDDDB---BC------ CBBBBBBDDD-DDBBB-BC------ CBBBBBBEEBB--BBBBBC------ CBBBBBBBBBB-BBBBBBC------ CBBBBBBBBBB-BBBBBBC------ CHHHHHGGGGEEEIIIIIC------ CHHHHHGGGGEENIIIIIC------ CHHHHHGGGGEENIIIIIC------ CHHHHHGGGGEENIIIIIC------ CQEEEEEEEEEENIIIIIC------ CFOOLFLFFFLFLOLFFOC------ C-----K-K-K-K-----C------ ----------R-------------- ----------J-------------- ------RPR---J------------ ------------------------- ------------------------- 
-AAAAAAAAAAAAAAAAA------- -AAAADDDDDDDDAAAAA------- -AAAADDDDDDDDAAAAA------- -AAAADDDDDDDDA---A------- -AAAADDDDDDDDA---A------- -AAAADDDDDDDDA---A------- -AAAADDDDDDDDA---A------- -AAAADDDDDDDDA---A------- -AAAADDDDDDDDA---A------- -AAAABBDDDDDDA---A------- -AAAABBAAAAADA---A------- -AAAABBAAAAADA---A------- -CBBBBBAAAADDB---C------- -CBBBBBAAAADDB--BC------- -CBBBBBAAA-D-BB-BC------- -CBBBBBAABB--BBBBC------- -CBBBBBBBBB-BBBBBC------- -CBBBBBBBBB-BBBB-C------- -CHHHHEEEEEEEIIIIC------- -CHHHHEEEEEENIIIIC------- -CHHHHEEEEEENIIIIC------- -CHHHHEEEEEENIIIIC------- -CEEEEEEEEEENIIIIC------- -CFFLLFFFFLLFOFFOC------- -C-----K-K-K-----C------- ------------------------- ----------RJ------------- ------J----J------------- ------------------------- ------------------------- 
-AAAAAAAAAAAAAAAAA------- -AAAADDDD-DDDAAAAA------- -AAAADDDD-DDDAAAAA------- -AAAADDDDDDDDAA-AA------- -AAAADDDDDDD----AA------- -AAAADDDDD------AA------- -AAAADDDDD------AA------- -AAAADDDDD------AA------- -AAAADDDDD------AA------- -AAAABBDDD------AA------- -AAAABBAAA------AA------- -AAAABBAAA------AA------- -CBBBBBAAA------BC------- -CBBBBBAAA------BC------- -CBBBBBAAAA-DBBBBC------- -CBBBBBAABB--BBBBC------- -CBBBBBBBBB-BBBBBC------- -CBBBBBBBBB-BBBBBC------- -CHHHHEEEEEEEIIIIC------- -CHHHHEEEEEENIIIIC------- -CHHHHEEEEEENIIIIC------- -CHHHHEEEEEENIIIIC------- -CQEEEEEEEEENIIIIC------- -CFOOOLFFFFLFOFOOC------- -C------K-K------C------- ------------------------- ----------P-------------- ------------------------- ------------------------- ------------------------- 
--AAAAAAAAAAAAAAA-------- --AAADDDDDDDDAAAA-------- --AAADDDDDDDDAAAA-------- --AAADDDDDDD--AAA-------- --AAADDDDDD----AA-------- --AAADDDDD-----AA-------- --AAADDDDD-----AA-------- --AAADDDDD-----AA-------- --AAADDDDD-----AA-------- --AAABBDDD-----AA-------- --AA--BAAA-----AA-------- --AA--BAAA-----AA-------- --CB--BAAA-----BC-------- --CB--BAAA-----BC-------- --CB--BAAAADGBBBC-------- --CB--BAAB-B-BBBC-------- --CB--BBBB--BBBBC-------- --CB--BBBB--BBBBC-------- --CH--EEEE--EIIIC-------- --CH--EEEE--NIIIC-------- --CH--EEEE--NIIIC-------- --CH--EEEE--NIIIC-------- --CQEEEEEEEENIIIC-------- --CFFFFFLFFOOFOOC-------- --C------K------C-------- ------------------------- ------------------------- ------------------------- ------------------------- ------------------------- 
---AAAAAAAAAAAAA--------- ---AADDDDDDDDAAA--------- ---AADDDDDDDDAAA--------- ---AA----DDD--AA--------- ---AA----DD---AA--------- ---AA---------AA--------- ---AA---------AA--------- ---AA---------AA--------- ---AA---------AA--------- ---AA---------AA--------- ---AA---------AA--------- ---AA---------AA--------- ---CB---------BC--------- ---CB---------BC--------- ---CB------GGBBC--------- ---CB------GGBBC--------- ---CB-------GBBC--------- ---CB-------GBBC--------- ---CH-------EIIC--------- ---CH--------IIC--------- ---CH--------IIC--------- ---CH--------IIC--------- ---CQEEEEEEEAIIC--------- ---CFFFOLOOLFFOC--------- ---C-----------C--------- ------------------------- ------------------------- ------------------------- ------------------------- ------------------------- 
----AAAAAAAAAAA---------- ----AAAAAAADDAA---------- ----AAAAAAADDAA---------- ----AAA---A-DAA---------- ----AAA-----DAA---------- ----AAA-----DAA---------- ----AAA-----DAA---------- ----AAA-----DAA---------- ----AAA-----DAA---------- ----AAA-----GAA---------- ----AAA-----GAA---------- ----AAA-----GAA---------- ----CCG-----GCC---------- ----CCG-----GCC---------- ----CCG-----GCC---------- ----CCG-----GCC---------- ----CCG-----GCC---------- ----CCG-----GCC---------- ----CCQ-----QCC---------- ----CCQ-----QCC---------- ----CCQ-----QCC---------- ----CCQ-----QCC---------- ----CCQEEEEEQCC---------- ----CCFFFOOFFCC---------- ----CC-------CC---------- ------------------------- ------------------------- ------------------------- ------------------------- ------------------------- 
------AAAAAAA------------ ------AAAAAAA------------ ------AAAAAAA------------ ------AAAAAAA------------ ------AAAAAAA------------ ------AAAAAAA------------ ------AAAAAAA------------ ------AAAAAAA------------ ------AAAAAAA------------ ------AAAAAAA------------ ------AAAAAAA------------ ------AAAAAAA------------ ------CCCCCCC------------ ------CCCCCCC------------ ------CCCCCCC------------ ------CCCCCCC------------ ------CCCCCCC------------ ------CCCCCCC------------ ------CCCCCCC------------ ------CCCCCCC------------ ------CCCCCCC------------ ------CCCCCCC------------ ------CCCCCCC------------ ------CCCCCCC------------ ------CCCCCCC------------ ------------------------- ------------------------- ------------------------- ------------------------- ------------------------- 
