model
size = 25 30 19, scale = 0.05, origin = -y
material 
  colors = A:#EEE B:#009 C:#FF0 D:#E00 E:#CF3 F:#000 G:#06F H:#30F I:#00C J:#251505 K:#BBB L:#CC6 M:#CF0 N:#939 O:#960 P:#1C0900 Q:#AAAAB9 R:#AAA S:#00F T:#888 U:#FCF
voxels
------ADDABBB------------ ------ADDABBB------------ ------ADDABBB------------ ------ADDABBB------------ ------ADDABBB------------ ------ADDABBB------------ ------ADDABBB------------ ------ADDABBB------------ ------ADDABBB------------ ------ADDABBB------------ ------ADDABBB------------ ------ADDABBB------------ ------ADDAAAA------------ ------DDDDDDD------------ ------DDDDDDD------------ ------ADDAAAA------------ ------ADDABBB------------ ------ADDABBB------------ ------ADDABBB------------ ------ADDABBB------------ ------ADDABBB------------ ------ADDABBB------------ ------ADDABBB------------ ------ADDABBB------------ ------ADDABBB------------ ------------------------- ------------------------- ------------------------- ------R------------------ ------------------------- 
----BBBBBBBBBBB---------- ----BBC---CCCBB---------- ----BBC---CCCBB---------- ----BBA---CCCBB---------- ----BBA---CCCBB---------- ----BBA---CCCBB---------- ----BBA---CCCBB---------- ----BBA--CCCCBB---------- ----BBA--DDDDBB---------- ----BBA--DDDDBB---------- ----BBA--DDDDBB---------- ----BBA-DDDDDBB---------- ----AACDDDDDCAA---------- ----DDHHHHHHHDD---------- ----DDCDDDDDDDD---------- ----AAADDDDDCAA---------- ----BBADDDDDDBB---------- ----BBAFFFFFFBB---------- ----BBAEEEEEQBB---------- ----BBQEEEEEQBB---------- ----BBQEEEEEQBB---------- ----BBQEEEEEQBB---------- ----BBQEEEEEQBB---------- ----BBJJJJJJJBB---------- ----BB-------BB---------- ------------------------- ------------------------- ------------------------- ------K------------------ ------K------------------ 
---BBBBBBBBBBBBB--------- ---BCC--------AB--------- ---BCCCCCCCCCAAB--------- ---BCCCCCCCCCAAB--------- ---BCCCCCCCCCAAB--------- ---BCCCCCCCCCAAB--------- ---BCCCCCCCCCAAB--------- ---BCCCCCCCCCAAB--------- ---BDDDDDDDDDAAB--------- ---BDDDDDDDDDAAB--------- ---BDDDCCCCCDDAB--------- ---BDDDDDDDDDDAB--------- ---ACCCDDDDDCCCA--------- ---DHHCDDDDDDCHD--------- ---DHHCDDDDDDHHD--------- ---ADCCCCCCCCCCA--------- ---BDEEEEECCDDDB--------- ---BFFFFFFFFFFFB--------- ---BIEEEEEEEEDDB--------- ---BIEEEEEEEEDDB--------- ---BIEEEEEEEEDDB--------- ---BIEEEEEEEEDDB--------- ---BQEEEEEEEEEQB--------- ---BJJJJJJOPJJJB--------- ---B-----------B--------- ------------------------- ------------------------- ------------------------- ------------------------- ------KK----------------- 
--BBBBBBBBBBBBBBB-------- --BCCCCCCCCCCAAAB-------- --BCCCCCCCCCCAAAB-------- --BCCCCCCCCCCAAAB-------- --BCCCCCCCCCCAAAB-------- --BACCCCCCCCCAAAB-------- --BACCCCCCCCCAAAB-------- --BACCCCCCCCCAAAB-------- --BACCCCCCCCCAAAB-------- --BACC--------AAB-------- --BADDDCCCCCDDDAB-------- --BADCDDDDDDDDDAB-------- --ACDDDDDDDDCCCCA-------- --DHHHDDDD-DDCHHD-------- --DHHHDDDD-DDHHHD-------- --ACDCCCCC-CCCCCA-------- --BADEEEEE-CDDDAB-------- --BFFFFFFF-FFFFFB-------- --BIIEEEEE-EEEEQB-------- --BIIEEEEE-EEEEQB-------- --BIIEEEEE-EEEEQB-------- --BIIEEEEE-EEEEQB-------- --BQEEEEEE-EEEEAB-------- --BJJJJOJOJJPPJJB-------- --B------L------B-------- ------------------------- ------------------------- ------------------------- ---K--------------------- -------K----------------- 
-BBBBBBBBBBBBBBBBB------- -BCCCCCCCCCCCAA-AB------- -BCCCCCCCCCCCAA-AB------- -BCCCCCCCCCCCAA-AB------- -BCCCCCCCCCCCAA-AB------- -BCCCCCCCCCCCAA-AB------- -BCCCCCCCCCCCAA-AB------- -BCCCCCCCCCCCAA-AB------- -BDDCCCCCCCCCAA-AB------- -BDDCCCCCCCCCAA-AB------- -BD-DDDDDDCCDDD-DB------- -BD-DDDDDDDDDDD-DB------- -AC-DDDDDDDDCCC-CA------- -DH-HHDDDDDDDCH-HD------- -DH-HHDDDDDDDHH-HD------- -ACCDDEEEECCCCC-CA------- -BD-DEEEEECCDDD-DB------- -BF-FFFFFFFFFFF-FB------- -BA-IEEEEEEEEEE-QB------- -BA-IEEEEEEEEEE-QB------- -BA-IEEEEEEEEEE-QB------- -BAIIEEEEEEEEEE-QB------- -BQCEEEEEEEEEEE-AB------- -BJJOJOJOJJOPOJJJB------- -B------L-L------B------- ------------------------- ------------------------- ------------------------- ---K--------------------- ---R---K----------------- 
-BBBBBBBBBBBBBBBBB------- -BCCCCCCCCCCCCSSSB------- -BCCCCCCCCCCCCSAAB------- -BCCCCCCCCCCCCSSSB------- -BCCCCCCCCCCCCCCCB------- -BCCCCCCCCCCCCCCCB------- -BCCCCCCCCCCCCCCCB------- -BCCCCCCCCCCCCCAAB------- -BDDCCCCCCCCCCAAAB------- -BDDCCCCCCCCCCAAAB------- -BDDDDDDDDCCDDDDDB------- -BDDDDDDDDDDDDDDDB------- -ACCDDDDDDDDCCCCCA------- -DHHHHDDDDDDDCHHHD------- -DHHHHDDDDDDDHHHHD------- -ACCDDEEEECCCCCCCA------- -BDDDEEEEECCDDDDDB------- -BFFFFFEEDDDDDDDDB------- -BAIIEEEEEEEEEEEEB------- -BAIIEEEEEEEEEEEEB------- -BAIIEEEEEEEEEEEEB------- -BAIIEEEEEEEEEEEEB------- -BEEEEEEEEEEEEEAAB------- -BOJOOJOJJJOJJOOJB------- -B-----L-L-L-----B------- ------------------------- ------------------------- ------------------------- ------------------------- ---T--KR----------------- 
BBBBBBBBBBBBBBBBBBB------ BCCCCCCCCCCCCCCCCAB------ BCCCCCCCCCCCCCCCCAB------ BCCCCCCCCCCCCCCCCAB------ BCCCCCCCCCCCCCCCCAB------ BCCCCCCCCCCCCCCCCAB------ BCCCCCCCCCCCCCCCCAB------ BCCCCCCCCCCCCCCCCAB------ BDDDCCCCCCCCCCDDDDB------ BDDDCCCCCCCCCCDDDDB------ BDDDDDDDDDCCDDDDDDB------ BDDDDDDDDDDDDDDDDDB------ ACCCDDDDDDDDCCCCCCA------ DCCCCDDDDDDDDCHHHHD------ DHHHHHDDDDDDDHHHHHD------ ACCCDDEEEECCCCCCCCA------ BDDDDEEEEECCCCCCCCB------ BFFFFFFEEDDDDDDDDFB------ BIIIIEEEEEEEENNNEQB------ BIIIIEEEEEEEENNNEQB------ BIIIIEEEEEEEENNNEQB------ BIIIIEEEEEEEENNNEQB------ BQEEEEEEEEEEENNAAAB------ BJJJJJOOJJJJJOPJJPB------ B-----L-L-L-L-----B------ ------------------------- ---------KKK------------- --------RK-KK------------ ----RRRRR---KK----------- ---RR-RR-----K----------- 
BBBBBBBBBBBBBBBBBBB------ BCCCCCCDDDDDDDDAAAB------ BCCCCCCDDDDDDDDAAAB------ BCCCCCCDDDDDDDDAAAB------ BCCCCCCDDDDDDDDAAAB------ BCCCCCCDDDDDDDDAAAB------ B-CCCCCMEEEEMDMAAAABBBBBB B-CCCCCCCCCCCCCCCCABBBBBB B-DDCCDCCCCCCCDDDDB-----B B-DDCCDCCCCCCCDDDDB-----B B-DDDD--DDCCDDDDDDB-----B B-DDDD------DDDDDDB-----B A-CCDD------D--DD-A-----A D-DDDDDDDDDDDDHHH-D-----D D-CCDDDDDDDDDHHHH-D-----D A-CCDDEEEECCCCCCC-A-----A B-DDDEEEEECCCCCCC-B-----B B-FFFFFEEEAAANNNE-GBBBBBB B-IIIEEEEEEEENNNE-GBBBBBB B-IIIEEEEEEEENNNE-B------ B-IIIEEEEEEEENNNE-B------ B-IIIEEEEEEEENNNEEB------ B-EEEEEEEEEEENNAAAB------ BJJJJJJJJOJJJOJOPJB------ B----L-L-L-L-L----B------ ------------------------- ---------KKK------------- ------------------------- ----RKK------------------ ------------------------- 
BBBBBBBBBBBBBBBBBBB------ BCCCCCCDDDDDDDDAAAB------ BCCCCCCDDDDDDDDAAAB------ BCCCCCCDDDDDDDDAAAB------ BCCCCCCDDDDDDDDAAAB------ BCCCCCCDDDDDDDDAAAB------ B-CCCCCMEEEEMDMMMMCBBBBBB B-CCCCCCCCCCCCCCCCCBBBBBB B-DDCCDCCCCCCCDDDDB-----B B-DDCCDCCCCCCCDDDDB-----B B-DDDD--DDCCDDDDDDB-----B B-DDDD------DDDDDDB-----B A-DDDD------D-DDD-A-----A D-DDDDDDDDDDDDHHH-D-----D D-DDDDDDDDDDDHHHH-D-----D A-DDDDDEEECCCCCCC-A-----A B-DDDDDEEECCCCCCC-B-----B B-FFFFFEEEAAANNNE-DBBBBBB B-IIIEEEEEEEENNNE-GBBBBBB B-IIIEEEEEEEENNNE-B------ B-IIIEEEEEEEENNNE-B------ B-IIIEEEEEEEENNNEEB------ B-EEEEEEEEEEENNAAAB------ BJJJJJJOJJJJJJJJJPB------ B---L-L-L-L-L-L---B------ ------------------------- ---------KKK------------- --------RK-KK------------ ----RRRUR---KK----------- ---RR-KK-----K----------- 
ABBBBBBBBBBBBBBBBBA------ AGGGGGGGGGGGGGGGGGA------ AGGGGGGGGGGGGGGGGGA------ AGGGGGGGGGGGGGGGGGA------ AGGGGGGGGGGGGGGGGGA------ AGGGGGGGGGGGGGGGGGA------ A-GGGGGGGGGGGGGGGGAAAAAAA A-CCCCCMEEDDDDMMMMAAAAAAA A-DDCCDEEECCCCDDDDA-----A A-DDCCDEEECCCCDDDDA-----A A-DDDDDEEECCDDDDDDA-----A A-DDDDDEEECCDDDDDDA-----A A-DDDDDDDDDDDDDDD-A-----A A-DDDDDDDDDDDDDDD-A-----A A-DDDDDDDDDDDDDDD-A-----A A-DDDDDEEECCCCCCC-A-----A A-DDDDDEEECCCCCCC-A-----A A-FFFFFEEEAAAAEEE-DAAAAAA A-IIIEAAAAEEEEEEE-DAAAAAA A-IIIEAAAAEEMEEEE-A------ A-IIIEAAAAEEMEEEE-A------ A-IIIEAAAAEEMEEEEEA------ A-EEEEEEEEEEMMEAAAA------ AJOJJJJJJOOJJJJOPPA------ A--L-L-L-L-L-L-L--A------ ---------KKR------------- --------KK-KK------------ -------KK--KKK----------- -----T-K----KK----------- -------K----------------- 
BBBBBBBBBBBBBBBBBBB------ BGGGGGGGGGGGGGGGGGB------ BGGGGGGGGGGGGGGGGGB------ BGGGGGGGGGGGGGGGGGB------ BGGGGGGGGGGGGGGGGGB------ BGGGGGGGGGGGGGGGGGB------ B-GGGGGGGGGGGGGGGGGBBBBBB B-CCCCCMEEDDDDMMMMGBBBBBB B-DDCCDEEECCCCDDDDB-----B B-DDCCDEEECCCCDDDDB-----B B-DDDDDEEECCDDDDDDB-----B B-DDDDDEEECCDDDDDDB-----B A-DDDDDDDDDDDDDDD-A-----A D-DDDDDDDDDDDHHHH-D-----D D-DDDDDDDD-DDDHHH-D-----D A-DDDDDEEEC---CCC-A-----A B-DDDDDEEEC-C-CCC-B-----B B-FFFFFEEEE-E-EEE-DBBBBBB B-IIIEAAAAEEEEEEE-GBBBBBB B-IIIEAAAAEEMEEEE-B------ B-IIIEAAAAEEMEEEE-B------ B-IIIEAAAAEEMEEEEEB------ B-EEEEEEEEEEMMEAAAB------ BJJOOJJOJJJOJJJJJPB------ B---L-L-L-L-L-L---B------ ---------KKK------------- ------------------------- ------------------------- -----K------------------- ------------------------- 
BBBBBBBBBBBBBBBBBBB------ BCCCCCCCCCCCCCCCCCB------ BCCCCCCCCCCCCCCCCCB------ BCCCCCCCCCCCCCCCCCB------ BAAAAAAAAAAAAAACCCB------ BAAAAAAAAAAAAAACCCB------ B-AAAAAAAAAAAAACCCDBBBBBB B-AAAAAAAAAAAAACCCDBBBBBB B-AAAAAAAAAAAAADDDB-----B B-AAAAAAAAAAAAADDDB-----B B-AAAAAAAAAAAAADDDB-----B B-AAAAAAAAAAAAADDDB-----B A-CCAAAAAAAAAAADD-A-----A D-CCAAAAAAAAAHHHH-D-----D D-CCAAAAAA-A-AHHH-D-----D A-CCAAAAAAA---ADD-A-----A B-AAAAAAAAA-A-ADD-B-----B B-FFFFFFFFF-F-FFF-DBBBBBB B-IIIEAAAAEEEFFFF-GBBBBBB B-IIIEAAAAEEMFFFF-B------ B-IIIEAAAAEEMFFFF-B------ B-IIIEAAAAEEMFFFFFB------ B-EEEEEEEEEEMFFFFFB------ BJPJOJJJOJJJJJJJJPB------ B----L-L-L-L-L----B------ ---------RRR------------- --------RR-KK------------ -------RRK--RK----------- -------R-----R----------- ------------------------- 
BBBBBBBBBBBBBBBBBBB------ BCCCCCCCCCCCCCCCCCB------ BCCCCCCCCCCCCCCCCCB------ BCCCCCCCCCCCCC---CB------ BAAAAAAAAAAAAA---CB------ BAAAAAAAAAAAAA---CB------ BAAAAAAAAAAAAA---CB------ BAAAAAAAAAAAAA---CB------ BAAAAAAAAAAAAA---DB------ BAAAAAAAAAAAAA---DB------ BAAAAAAAAAAAAA---DB------ BAAAAAAAAAAAAA---DB------ ACCCAAAAAAAAAA---CA------ DHHHHHHHAAAAAH---HD------ DHHHHHHHAA-AAAHH-HD------ ACCCAAAAAAA--AACCCA------ BAAAAAAAAAA-AAADDDB------ BFFFFFFFFFF-FFFFFFB------ BIIIIIAAAAEEEFFFFFB------ BIIIIIAAAAEEMFFFFFB------ BIIIIIAAAAEEMFFFFFB------ BIIIIIAAAAEEMFFFFFB------ BQEEEEEEEEEEMFFFFFB------ BJPPOJOJJJOJOPOJJPB------ B-----L-L-L-L-----B------ ----------T-------------- ----------K-------------- ------TRT---K------------ ------------------------- ------------------------- 
-BBBBBBBBBBBBBBBBB------- -BCCCCCCCCCCCCCCCB------- -BCCCCCCCCCCCCCCCB------- -BCCCCCCCCCCCC---B------- -BAAAAAAAAAAAA---B------- -BAAAAAAAAAAAA---B------- -BAAAAAAAAAAAA---B------- -BAAAAAAAAAAAA---B------- -BAAAAAAAAAAAA---B------- -BAAAAAAAAAAAA---B------- -BAAAAAAAAAAAA---B------- -BAAAAAAAAAAAA---B------- -ACCAAAAAAAAAA---A------- -DHHHHHHAAAAAH--HD------- -DHHHHHHAA-A-AH-HD------- -ACCAAAAAAA--AACCA------- -BAAAAAAAAA-AAADDB------- -BFFFFFFFFF-FFFF-B------- -BIIIIEEEEEEEFFFFB------- -BIIIIEEEEEEMFFFFB------- -BIIIIEEEEEEMFFFFB------- -BIIIIEEEEEEMFFFFB------- -BEEEEEEEEEEMFFFFB------- -BJJOOJJJJOOJPJJPB------- -B-----L-L-L-----B------- ------------------------- ----------TK------------- ------K----K------------- ------------------------- ------------------------- 
-BBBBBBBBBBBBBBBBB------- -BCCCCCCC-CCCCCCCB------- -BCCCCCCC-CCCCCCCB------- -BCCCCCCCCCCCCC-CB------- -BAAAAAAAAAA----CB------- -BAAAAAAAA------CB------- -BAAAAAAAA------CB------- -BAAAAAAAA------CB------- -BAAAAAAAA------DB------- -BAAAAAAAA------DB------- -BAAAAAAAA------DB------- -BAAAAAAAA------DB------- -ACCAAAAAA------CA------- -DHHHHHHAA------HD------- -DHHHHHHAAA-AAHHHD------- -ACCAAAAAAA--AACCA------- -BAAAAAAAAA-AAADDB------- -BFFFFFFFFF-FFFFFB------- -BIIIIEEEEEEEFFFFB------- -BIIIIEEEEEEMFFFFB------- -BIIIIEEEEEEMFFFFB------- -BIIIIEEEEEEMFFFFB------- -BQEEEEEEEEEMFFFFB------- -BJPPPOJJJJOJPJPPB------- -B------L-L------B------- ------------------------- ----------R-------------- ------------------------- ------------------------- ------------------------- 
--BBBBBBBBBBBBBBB-------- --BCAAAAAAAAAAAAB-------- --BCAAAAAAAAAAAAB-------- --BCAAAAAAAA--AAB-------- --BAAAAAAAA----AB-------- --BAAAAAAA-----AB-------- --BAAAAAAA-----AB-------- --BAAAAAAA-----AB-------- --BAAAAAAA-----AB-------- --BAAAAAAA-----AB-------- --BA--AAAA-----AB-------- --BA--AAAA-----AB-------- --AC--AAAA-----CA-------- --DH--HHAA-----HD-------- --DH--HHAAAAAAHHD-------- --AC--AAAA-A-AACA-------- --BA--AAAA--AAADB-------- --BF--FFFF--FFFFB-------- --BI--EEEE--EFFFB-------- --BI--EEEE--MFFFB-------- --BI--EEEE--MFFFB-------- --BI--EEEE--MFFFB-------- --BQEEEEEEEEMFFFB-------- --BJJJJJOJJPPJPPB-------- --B------L------B-------- ------------------------- ------------------------- ------------------------- ------------------------- ------------------------- 
---BBBBBBBBBBBBB--------- ---BAAAAAAAAAAAB--------- ---BAAAAAAAAAAAB--------- ---BA----AAA--AB--------- ---BA----AA---AB--------- ---BA---------AB--------- ---BA---------AB--------- ---BA---------AB--------- ---BA---------AB--------- ---BA---------AB--------- ---BA---------AB--------- ---BA---------AB--------- ---AA---------CA--------- ---DH---------HD--------- ---DH------ACCHD--------- ---AA------ACCCA--------- ---BA-------AAAB--------- ---BF-------FFFB--------- ---BI-------EFFB--------- ---BI--------FFB--------- ---BI--------FFB--------- ---BI--------FFB--------- ---BQEEEEEEECFFB--------- ---BJJJPOPPOJJPB--------- ---B-----------B--------- ------------------------- ------------------------- ------------------------- ------------------------- ------------------------- 
----BBBBBBBBBBB---------- ----BBAAAAACCBB---------- ----BBAAAAACCBB---------- ----BBA---A-CBB---------- ----BBA-----CBB---------- ----BBA-----CBB---------- ----BBA-----CBB---------- ----BBA-----CBB---------- ----BBA-----CBB---------- ----BBA-----CBB---------- ----BBA-----CBB---------- ----BBA-----CBB---------- ----AAC-----CAA---------- ----DDH-----HDD---------- ----DDH-----HDD---------- ----AAC-----CAA---------- ----BBA-----CBB---------- ----BBF-----CBB---------- ----BBQ-----CBB---------- ----BBQ-----CBB---------- ----BBQ-----CBB---------- ----BBQ-----CBB---------- ----BBQEEEECCBB---------- ----BBJJJPPJJBB---------- ----BB-------BB---------- ------------------------- ------------------------- ------------------------- ------------------------- ------------------------- 
------BBBADDA------------ ------BBBADDA------------ ------BBBADDA------------ ------BBBADDA------------ ------BBBADDA------------ ------BBBADDA------------ ------BBBADDA------------ ------BBBADDA------------ ------BBBADDA------------ ------BBBADDA------------ ------BBBADDA------------ ------BBBADDA------------ ------AAAADDA------------ ------DDDDDDD------------ ------DDDDDDD------------ ------AAAADDA------------ ------BBBADDA------------ ------BBBADDA------------ ------BBBADDA------------ ------BBBADDA------------ ------BBBADDA------------ ------BBBADDA------------ ------BBBADDA------------ ------BBBADDA------------ ------BBBADDA------------ ------------------------- ------------------------- ------------------------- ------------------------- ------------------------- 
