model
size = 25 30 19, scale = 0.05, origin = -y
material 
  colors = A:#0A0 B:#E00 C:#EEE D:#FF0 E:#CF3 F:#F60 G:#00C H:#251505 I:#CF0 J:#AAAAB9 K:#BBB L:#CC6 M:#939 N:#960 O:#1C0900 P:#AAA Q:#F30 R:#040 S:#888 T:#FCF
voxels
------CCCCCCC------------ ------CCCCCCC------------ ------CCCCCCC------------ ------CCCCCCC------------ ------CCCCCCC------------ ------CCCCCCC------------ ------CCCCCCC------------ ------CCCCCCC------------ ------CCCCCCC------------ ------CCCCCCC------------ ------CCCCCCC------------ ------CCCCCCC------------ ------CCCCCCC------------ ------CCCCCCC------------ ------CCCCCCC------------ ------CCCCCCC------------ ------CCCCCCC------------ ------CCCCCCC------------ ------CCCCCCC------------ ------CCCCCCC------------ ------CCCCCCC------------ ------CCCCCCC------------ ------CCCCCCC------------ ------CCCCCCC------------ ------CCCCCCC------------ ------------------------- ------------------------- ------------------------- ------P------------------ ------------------------- 
----AACCCCCCCFF---------- ----AAB---BBBFF---------- ----AAB---BBBFF---------- ----AAB---BBBFF---------- ----AAB---BBBFF---------- ----AAB---BBBFF---------- ----AAB---BBBFF---------- ----AAB--BBBBFF---------- ----AAD--DDDDFF---------- ----AAD--DDDDFF---------- ----AAD--DDDDFF---------- ----AAD-DDDDDFF---------- ----AADDDDDDDFF---------- ----AADDDDDDDFF---------- ----AADDDDDDDFF---------- ----AADDDDDDDFF---------- ----AAJEEEDDDFF---------- ----AABBBBBBBFF---------- ----AAJEEEEEJFF---------- ----AAJEEEEEJFF---------- ----AAJEEEEEJFF---------- ----AAJEEEEEJFF---------- ----AAJEEEEEJFF---------- ----AAHHHHHHHFF---------- ----AA-------FF---------- ------------------------- ------------------------- ------------------------- ------K------------------ ------K------------------ 
---AAACCCCCCCFFF--------- ---ABB--------BF--------- ---ABBBBBBBBBBBF--------- ---ABBBBBBBBBBBF--------- ---AAABBBBBBBBBF--------- ---AGBBBBBBBBBBF--------- ---AGCCCCCCCCCBF--------- ---AGBBBBBBBBBBF--------- ---AGDDDDDDDDBBF--------- ---AGDDDDDDDDBBF--------- ---AGDDDDDDDDBBF--------- ---AGDDDDDDDDBBF--------- ---AGDDDDDDDDBBF--------- ---AGDDDDDDDDBBF--------- ---AGDDDDDDDDBBF--------- ---AGDDDDDDDDBBF--------- ---AGEEEEEDDDBBF--------- ---AGBBBBBBBBBBF--------- ---AGEEEEEEEEBBF--------- ---AGEEEEEEEEBBF--------- ---AGEEEEEEEEBBF--------- ---AGEEEEEEEEBBF--------- ---AJEEEEEEEEEJF--------- ---AHHHHHHNOHHHF--------- ---A-----------F--------- ------------------------- ------------------------- ------------------------- ------------------------- ------KK----------------- 
--AAAACCCCCCCFFFF-------- --ACBBBBBBBBBBBCF-------- --ACBBBBBBBBBBBCF-------- --ACBBBBBBBBBBBCF-------- --AAAABBBBBBBBBBF-------- --AGGBBBBBBBBBBBF-------- --AGGCCCCCCCCCBBF-------- --AGGBBBBBBBBBBBF-------- --AGGDDDDDDDDDDDF-------- --AGGD--------DDF-------- --AGGDDDDDDDDDDDF-------- --AGGDDDDDDDDDDDF-------- --AGGDDDDDDDDDDDF-------- --AGGDDDDD-DDDDDF-------- --AGGDDDDD-DDDDDF-------- --AGGDDDDD-DDDDDF-------- --AGGEEEEE-DDDDDF-------- --AGGBBBBB-BBBBBF-------- --AGGEEEEE-EEEEJF-------- --AGGEEEEE-EEEEJF-------- --AGGEEEEE-EEEEJF-------- --AGGEEEEE-EEEEJF-------- --AJEEEEEE-EEEECF-------- --AHHHHNHNHHOOHHF-------- --A------L------F-------- ------------------------- ------------------------- ------------------------- ---K--------------------- -------K----------------- 
-AAAAACCCCCCCFFFFF------- -ACCBBBBBBBBBBB-CF------- -ACCBBBBBBBBBBB-CF------- -ACCBBBBBBBBBBB-CF------- -AACBBBBBBBBBBB-BF------- -AGGGBBBBBBBBBB-BF------- -AGGGBBBBBBBBBB-BF------- -AGGGBBBBBBBBBB-BF------- -AGGGBBBBBDDDDD-DF------- -AGGGBBBBBDDDDD-DF------- -AG-GBBBBBDDDDD-DF------- -AG-GBRRRRDDDDD-DF------- -AG-GBERERDDDDD-DF------- -AG-GBEEEEDDDDD-DF------- -AG-GBEEEEDDDDD-DF------- -AGGGBEEEEDDDDD-DF------- -AG-GEEEEEDDDDD-DF------- -AG-GBBBBBBBBBB-BF------- -AG-GEEEEEEEEEE-JF------- -AG-GEEEEEEEEEE-JF------- -AG-GEEEEEEEEEE-JF------- -AGGGEEEEEEEEEE-JF------- -AJDEEEEEEEEEEE-CF------- -AHHNHNHNHHNONHHHF------- -A------L-L------F------- ------------------------- ------------------------- ------------------------- ---K--------------------- ---P---K----------------- 
-AAAAACCCCCCCFFFFF------- -ACCEEBBBBBBBBBCCF------- -ACCEEBBBBBBBBBCCF------- -ACCEEBBBBBBBBBCCF------- -AACEEBBBBBBBBBBBF------- -AGGGEBBBBBBBBBBBF------- -AGGGEBBBBBBBBBBBF------- -AGGGEBBBBBBBBBBBF------- -AGGGBBBBBDDDDDDDF------- -AGGGBBBBBDDDDDDDF------- -AGGGBBBBBDDDDDDDF------- -AGGGBBBRRDDDDDDDF------- -AGGGBBBRRDDDDDDDF------- -AGGGBEEEEDDDDDDDF------- -AGGGBEEEEDDDDDDDF------- -AGGGBEEEEDDDDDDDF------- -AGGGEEEEEDDDDDDDF------- -AGGGBEEEBBBBBBBBF------- -AGGGEEEEEEEEEEEEF------- -AGGGEEEEEEEEEEEEF------- -AGGGEEEEEEEEEEEEF------- -AGGGEEEEEEEEEEEEF------- -AEEEEEEEEEEEEECCF------- -ANHNNHNHHHNHHNNHF------- -A-----L-L-L-----F------- ------------------------- ------------------------- ------------------------- ------------------------- ---S--KP----------------- 
AAAAAACCCCCCCFFFFFF------ ACCCEEBBBBBBBBBCCCF------ ACCCEEBBBBBBBBBCCCF------ ACCCEEBBBBBBBBBCCCF------ AAACEEBBBBBBBBBCCCF------ AAAAAAABBBBBBBBCCCF------ AAAAAAABBBBBBBBCCCF------ AAAAAAABBBBBBBBBBBF------ AAAAAAABBBDDDDDDDDF------ AAAAAAABBBDDDDDDDDF------ AAAAAAABBBDDDDDDDDF------ AAAAAAABBBDDDDDDDDF------ AAAAAAABBBDDDDDDDDF------ AAAAAAAEEEDDDDDDDDF------ AAAAAAAEEEDDDDDDDDF------ AAAAAAAEEEDDDDDDDDF------ AAAAAAAEEEDDDDDDDDF------ AAAAAAAEEBBBBBBBBBF------ AAAAAAAEEEEEEMMMEJF------ AAAAAAAEEEEEEMMMEJF------ AAAAAAAEEEEEEMMMEJF------ AAAAAAAEEEEEEMMMEJF------ AJEEEEEEEEEEEMMCCCF------ AHHHHHNNHHHHHNOHHOF------ A-----L-L-L-L-----F------ ------------------------- ---------KKK------------- --------PK-KK------------ ----PPPPP---KK----------- ---PP-PP-----K----------- 
AAAAAACCCCCCCFFFFFF------ ACCCBBBBBBBBBBBCCCF------ ACCCBBBBBBBBBBBCCCF------ ACCCBBBBBBBBBBBCCCF------ AAACBBBBBBBBBBBCCCF------ AAAAAAABBBBBBBBCCCF------ A-AAAAAIEEEEIBICCCCCCCCCC A-AAAAAIEEEEIBIIIIICCCCCC A-AAAAABBBDDDDDDDDF-----C A-AAAAABBBDDDDDDDDF-----C A-AAAA--BBDDDDDDDDF-----C A-AAAA------DDDDDDF-----C A-AAAA------D--DD-F-----C A-AAAAAEEEDDDDDDD-F-----C A-AAAAAEEEDDDDDDD-F-----C A-AAAAAEEEDDDDDDD-F-----C A-AAAAAEEEDDDDDDD-F-----C A-AAAAAEEECCCMMME-JCCCCCC A-AAAAAEEEEEEMMME-JCCCCCC A-AAAAAEEEEEEMMME-F------ A-AAAAAEEEEEEMMME-F------ A-AAAAAEEEEEEMMMEEF------ A-EEEEEEEEEEEMMCCCF------ AHHHHHHHHNHHHNHNOHF------ A----L-L-L-L-L----F------ ------------------------- ---------KKK------------- ------------------------- ----PKK------------------ ------------------------- 
AAAAAACCCCCCCFFFFFF------ ACCCBBBBBBBBBBBCCCF------ ACCCBBBBBBBBBBBCCCF------ ACCCBBBBBBBBBBBCCCF------ AAACBBBBBBBBBBBCCCF------ AAAAAAABBBBBBBBCCCF------ A-AAAAAIEEEEIBIIIIBCCCCCC A-AAAAAIEEEEIBIIIIBCCCCCC A-AAAAABBBDDDDDDDDF-----C A-AAAAABBBDDDDDDDDF-----C A-AAAA--BBDDDDDDDDF-----C A-AAAA------DDDDDDF-----C A-AAAA------D-DDD-F-----C A-AAAAAEEEDDDDDDD-F-----C A-AAAAAEEEDDDDDDD-F-----C A-AAAAAEEEDDDDDDD-F-----C A-AAAAAEEEDDDDDDD-F-----C A-AAAAAEEECCCMMME-JCCCCCC A-AAAAAEEEEEEMMME-JCCCCCC A-AAAAAEEEEEEMMME-F------ A-AAAAAEEEEEEMMME-F------ A-AAAAAEEEEEEMMMEEF------ A-EEEEEEEEEEEMMCCCF------ AHHHHHHNHHHHHHHHHOF------ A---L-L-L-L-L-L---F------ ------------------------- ---------KKK------------- --------PK-KK------------ ----PPPTP---KK----------- ---PP-KK-----K----------- 
AAAAAACCCCCCCFFFFFF------ ACCCBBBBBBBBBBBCCCF------ ACCCBBBBBBBBBBBCCCF------ ACCCBBBBBBBBBBBCCCF------ AAACBBBBBBBBBBBCCCF------ AAAAAAABBBBBBBBCCCF------ A-AAAAAIBEBBBBIIIIBCCCCCC A-AAAAAIEEBBBBIIIIBCCCCCC A-AAAAAEEEDDDDDDDDF-----C A-AAAAAEEEDDDDDDDDF-----C A-AAAAAEEEDDDDDDDDF-----C A-AAAAAEEEDDDDDDDDF-----C A-AAAAAEEEDDDDDDD-F-----C A-AAAAAEEEDDDDDDD-F-----C A-AAAAAEEEDDDDDDD-F-----C A-AAAAAEEEDDDDDDD-F-----C A-AAAAAEEEDDDDDDD-F-----C A-AAAAAEEECCCCEEE-JCCCCCC A-AAAAACCCEEEEEEE-JCCCCCC A-AAAAACCCEEIEEEE-F------ A-AAAAACCCEEIEEEE-F------ A-AAAAACCCEEIEEEEEF------ A-EEEEEEEEEEIIECCCF------ AHNHHHHHHNNHHHHNOOF------ A--L-L-L-L-L-L-L--F------ ---------KKP------------- --------KK-KK------------ -------KK--KKK----------- -----S-K----KK----------- -------K----------------- 
AAAAAACCCCCCCFFFFFF------ ACCCBBBBBBBBBBBCCCF------ ACCCBBBBBBBBBBBCCCF------ ACCCBBBBBBBBBBBCCCF------ AAACBBBBBBBBBBBCCCF------ AAAAAAABBBBBBBBCCCF------ A-AAAAAIBEBBBBIIIIBCCCCCC A-AAAAAIEEBBBBIIIIBCCCCCC A-AAAAAEEEDDDDDDDDF-----C A-AAAAAEEEDDDDDDDDF-----C A-AAAAAEEEDDDDDDDDF-----C A-AAAAAEEEDDDDDDDDF-----C A-AAAAAEEEDDDDDDD-F-----C A-AAAAAEEEDDDDDDD-F-----C A-AAAAAEEE-DDDDDD-F-----C A-AAAAAEEED---DDD-F-----C A-AAAAAEEED-D-DDD-F-----C A-AAAAAEEEE-E-EEE-JCCCCCC A-AAAAACCCEEEEEEE-JCCCCCC A-AAAAACCCEEIEEEE-F------ A-AAAAACCCEEIEEEE-F------ A-AAAAACCCEEIEEEEEF------ A-EEEEEEEEEEIIECCCF------ AHHNNHHNHHHNHHHHHOF------ A---L-L-L-L-L-L---F------ ---------KKK------------- ------------------------- ------------------------- -----K------------------- ------------------------- 
AAAAAACCCCCCCFFFFFF------ ACCCBBBBBBBBBBBCCCF------ ACCCBBBBBBBBBBBCCCF------ ACCCBBBBBBBBBBBCCCF------ AAACBBBBBBBBBBBCCCF------ AAAAAAABBBBBBBBCCCF------ A-AAAAAIBEBBBBBBBBF------ A-AAAAAIEEBBBBIIIBF------ A-AAAAAEEEDDDDDDDDF------ A-AAAAAEEEDDDDDDDDF------ A-AAAAAEEEDDDDDDDDF------ A-AAAAAEEEDDDDDDDDF------ A-AAAAAEEEDDDDDDD-F------ A-AAAAAEEEDDDDDDD-F------ A-AAAAAEEE-D-DDDD-F------ A-AAAAAEEED---DDD-F------ A-AAAAAEEED-D-DDD-F------ A-AAAAABBBB-B-BBB-F------ A-AAAAACCCEEEEEEE-F------ A-AAAAACCCEEIEEEE-F------ A-AAAAACCCEEIEEEE-F------ A-AAAAACCCEEIEEEEEF------ A-EEEEEEEEEEIIECCCF------ AHOHNHHHNHHHHHHHHOF------ A----L-L-L-L-L----F------ ---------PPP------------- --------PP-KK------------ -------PPK--PK----------- -------P-----P----------- ------------------------- 
AAAAAACCCCCCCFFFFFF------ ACCCBBBBBBBBBBBCCCF------ ACCCBBBBBBBBBBBCCCF------ ACCCBBBBBBBBBB---CF------ AAAAAABBBBBBBB---CF------ AAAAAAABBBBBBB---CF------ AAAAAAAIBEBBBB---BF------ AAAAAAAIEEBBBB---BF------ AAAAAAAEEEDDDD---DF------ AAAAAAAEEEDDDD---DF------ AAAAAAAEEEDDDD---DF------ AAAAAAAEEEDDDD---DF------ AAAAAAAEEEDDDD---DF------ AAAAAAAEEEDDDD---DF------ AAAAAAAEEE-DDDDD-DF------ AAAAAAAEEED--DDDQDF------ AAAAAAAEEED-DDDDQDF------ AAAAAAABBBB-BBBBQBF------ AAAAAAACCCEEEEEEQJF------ AAAAAAACCCEEIEEEQJF------ AAAAAAACCCEEIEEEQJF------ AAAAAAACCCEEIEEEQJF------ AJEEEEEEEEEEIEECCCF------ AHOONHNHHHNHNONHHOF------ A-----L-L-L-L-----F------ ----------S-------------- ----------K-------------- ------SPS---K------------ ------------------------- ------------------------- 
-AAAAACCCCCCCFFFFF------- -ACCBBBBBBBBBBBCCF------- -ACCBBBBBBBBBBBCCF------- -ACCBBBBBBBBBB---F------- -AAAAABBBBBBBB---F------- -AGGGGBBBBBBBB---F------- -AGGGGBBBBBBBB---F------- -AGGGGBBBBBBBB---F------- -AGGGGDDDDDDDD---F------- -AGGGGDDDDDDDD---F------- -AGGGGDDDDDDDD---F------- -AGGGGDDDDDDDD---F------- -AGGGGDDDDDDDD---F------- -AGGGGDDDDDDDD--QF------- -AGGGGDDDD-D-DD-QF------- -AGGGGDDDDD--DDDQF------- -AGGGGEEEEE-EEEEQF------- -AGGGGBBBBB-BBBB-F------- -AGGGGEEEEEEEEEEQF------- -AGGGGEEEEEEIEEEQF------- -AGGGGEEEEEEIEEEQF------- -AGGGGEEEEEEIEEEQF------- -AEEEEEEEEEEIECCCF------- -AHHNNHHHHNNHOHHOF------- -A-----L-L-L-----F------- ------------------------- ----------SK------------- ------K----K------------- ------------------------- ------------------------- 
-AAAAACCCCCCCFFFFF------- -ACCBBBBB-BBBBBCCF------- -ACCBBBBB-BBBBBCCF------- -ACCBBBBBBBBBBB-CF------- -AAAAABBBBBB----QF------- -AGGGGBBBB------QF------- -AGGGGBBBB------QF------- -AGGGGBBBB------QF------- -AGGGGDDDD------QF------- -AGGGGDDDD------QF------- -AGGGGDDDD------QF------- -AGGGGDDDD------QF------- -AGGGGDDDD------QF------- -AGGGGDDDD------QF------- -AGGGGDDDDD-DDDDQF------- -AGGGGDDDDD--DDDQF------- -AGGGGEEEEE-EEEEQF------- -AGGGGBBBBB-BBBBQF------- -AGGGGEEEEEEEEEEQF------- -AGGGGEEEEEEIEEEQF------- -AGGGGEEEEEEIEEEQF------- -AGGGGEEEEEEIEEEQF------- -AJEEEEEEEEEIECCCF------- -AHOOONHHHHNHOHOOF------- -A------L-L------F------- ------------------------- ----------P-------------- ------------------------- ------------------------- ------------------------- 
--AAAACCCCCCCFFFF-------- --ACBBBBBBBBBBBCF-------- --ACBBBBBBBBBBBCF-------- --ACBBBBBBBB--BCF-------- --AAAABBBBB----BF-------- --AGGGBBBB-----BF-------- --AGGGBBBB-----BF-------- --AGGGBBBB-----BF-------- --AGGGDDDD-----DF-------- --AGGGDDDD-----DF-------- --AG--DDDD-----DF-------- --AG--DDDD-----DF-------- --AG--DDDD-----DF-------- --AG--DDDD-----DF-------- --AG--DDDDDDDDDDF-------- --AG--DDDD-D-DDDF-------- --AG--EEEE--EEEJF-------- --AG--BBBB--BBBBF-------- --AG--EEEE--EEEJF-------- --AG--EEEE--IEEJF-------- --AG--EEEE--IEEJF-------- --AG--EEEE--IEEJF-------- --AJEEEEEEEEIECCF-------- --AHHHHHNHHOOHOOF-------- --A------L------F-------- ------------------------- ------------------------- ------------------------- ------------------------- ------------------------- 
---AAACCCCCCCFFF--------- ---ABBBBBBBBBBBF--------- ---ABBBBBBBBBBBF--------- ---AB----BBB--BF--------- ---AA----BB---BF--------- ---AG---------BF--------- ---AG---------BF--------- ---AG---------BF--------- ---AG---------DF--------- ---AG---------DF--------- ---AG---------DF--------- ---AG---------DF--------- ---AG---------DF--------- ---AG---------DF--------- ---AG------DDDDF--------- ---AG------DDDDF--------- ---AG-------EEJF--------- ---AG-------BBBF--------- ---AG-------EEJF--------- ---AG--------EJF--------- ---AG--------EJF--------- ---AG--------EJF--------- ---AJEEEEEEEDECF--------- ---AHHHONOONHHOF--------- ---A-----------F--------- ------------------------- ------------------------- ------------------------- ------------------------- ------------------------- 
----AACCCCCCCFF---------- ----AABBBBBBBFF---------- ----AABBBBBBBFF---------- ----AAB---B-BFF---------- ----AAB-----BFF---------- ----AAB-----BFF---------- ----AAB-----BFF---------- ----AAB-----BFF---------- ----AAD-----DFF---------- ----AAD-----DFF---------- ----AAD-----DFF---------- ----AAD-----DFF---------- ----AAD-----DFF---------- ----AAD-----DFF---------- ----AAD-----DFF---------- ----AAD-----DFF---------- ----AAJ-----JFF---------- ----AAB-----BFF---------- ----AAJ-----JFF---------- ----AAJ-----JFF---------- ----AAJ-----JFF---------- ----AAJ-----JFF---------- ----AAJEEEEEJFF---------- ----AAHHHOOHHFF---------- ----AA-------FF---------- ------------------------- ------------------------- ------------------------- ------------------------- ------------------------- 
------CCCCCCC------------ ------CCCCCCC------------ ------CCCCCCC------------ ------CCCCCCC------------ ------CCCCCCC------------ ------CCCCCCC------------ ------CCCCCCC------------ ------CCCCCCC------------ ------CCCCCCC------------ ------CCCCCCC------------ ------CCCCCCC------------ ------CCCCCCC------------ ------CCCCCCC------------ ------CCCCCCC------------ ------CCCCCCC------------ ------CCCCCCC------------ ------CCCCCCC------------ ------CCCCCCC------------ ------CCCCCCC------------ ------CCCCCCC------------ ------CCCCCCC------------ ------CCCCCCC------------ ------CCCCCCC------------ ------CCCCCCC------------ ------CCCCCCC------------ ------------------------- ------------------------- ------------------------- ------------------------- ------------------------- 
