model
size = 25 30 19, scale = 0.05, origin = -y
material 
  colors = A:#EEE B:#E00 C:#FF0 D:#CF3 E:#006 F:#0A0 G:#251505 H:#00C I:#CF0 J:#AAA K:#BBB L:#AAAAB9 M:#939 N:#CC3 O:#960 P:#1C0900 Q:#F30 R:#040 S:#06C T:#CC6 U:#888 V:#FCF
voxels
------EEEEEEE------------ ------EEEEEEE------------ ------EEEEEEE------------ ------EEEEEEE------------ ------EEEEEEE------------ ------EEEEEEE------------ ------EEEEEEE------------ ------JJJJJJJ------------ ------AAABAAA------------ ------AAAAAAA------------ ------AABABAA------------ ------AAAAAAA------------ ------BAABAAB------------ ------AAAAAAA------------ ------AABABAA------------ ------AAAAAAA------------ ------BAABAAB------------ ------KKKKKKK------------ ------EESSEEE------------ ------EBBSBEB------------ ------BBBBBBB------------ ------BBBBBBB------------ ------BBBBBBB------------ ------BBBBBBB------------ ------BBBBBBB------------ ------------------------- ------------------------- ------------------------- ------J------------------ ------------------------- 
----EEEEEEEEEEE---------- ----EEB---BBBEE---------- ----EEB---BBBEE---------- ----EEB---BBBEE---------- ----EEB---BBBEE---------- ----EEB---BBBEE---------- ----EEB---BBBEE---------- ----EEB--BBBBEE---------- ----JJC--CCCCJE---------- ----JAC--CCCCAJ---------- ----JAC--CCCCAJ---------- ----JAC-CCCCCAJ---------- ----JACCCCCCCAJ---------- ----JACCCCCCCAJ---------- ----JACCCCCCCAJ---------- ----JACCCCCCCAJ---------- ----JALDDDCCCAJ---------- ----JJJJJJJJJJJ---------- ----SSLDDDDDLSS---------- ----SBLDDDDDLBS---------- ----BBLDDDDDLBB---------- ----BBLDDDDDLBB---------- ----BBLDDDDDLBB---------- ----BBGGGGGGGBB---------- ----BB-------BB---------- ------------------------- ------------------------- ------------------------- ------K------------------ ------K------------------ 
---EEEEEEEEEEEEE--------- ---EAA--------BE--------- ---EAABBBBBBBBBE--------- ---EAABBBBBBBBBE--------- ---EAABBBBBBBBBE--------- ---EAABBBBBBBBBE--------- ---EAAAAAAAAAABE--------- ---EAABBBBBBBBBE--------- ---EAACCCCCCCBEE--------- ---AAACCCCCCCBBA--------- ---AAACCCCCCCBBA--------- ---AAACCCCCCCBBA--------- ---AAACCCCCCCBBA--------- ---AAACCCCCCCBBA--------- ---AAACCCCCCCBBA--------- ---AAACCCCCCCBBA--------- ---AAADDDDCCCBBA--------- ---AAABBBBBBBBBA--------- ---BAADDDDDDDBBB--------- ---BAADDDDDDDBBB--------- ---BAADDDDDDDBBB--------- ---BAADDDDDDDBBB--------- ---BAADDDDDDDDLB--------- ---BGGGGGGOPGGGB--------- ---B-----------B--------- ------------------------- ------------------------- ------------------------- ------------------------- ------KK----------------- 
--EEEEEEEEEEEEEEE-------- --EAAABBBBBBBBBAE-------- --EAAABBBBBBBBBAE-------- --EAAABBBBBBBBBAE-------- --EFAABBBBBBBBBBE-------- --EHAABBBBBBBBBBE-------- --EHAAAAAAAAAABBE-------- --EHAABBBBBBBBBBE-------- --EHAACCCCCCCCEEE-------- --AHAA--------CCA-------- --AHAACCCCCCCCCCA-------- --AHAACCCCCCCCCCA-------- --AHAACCCCCCCCCCA-------- --AHAACCCC-CCCCCA-------- --AHAACCCC-CCCCCA-------- --AHAACCCC-CCCCCA-------- --AHAADDDD-CCCCCA-------- --AHAABBBB-BBBBBA-------- --BBAADDDD-DDDDLB-------- --BHAADDDD-DDDDLB-------- --BHAADDDD-DDDDLB-------- --BHAADDDD-DDDDLB-------- --BLAADDDD-DDDDAB-------- --BGGGGOGOGGPPGGB-------- --B------N------B-------- ------------------------- ------------------------- ------------------------- ---K--------------------- -------K----------------- 
-EEEEEEEEEEEEEEEEE------- -EAAAABBBBBBBBB-AE------- -EAAAABBBBBBBBB-AE------- -EAAAABBBBBBBBB-AE------- -EFAAABBBBBBBBB-BE------- -EHHAABBBBBBBBB-BE------- -EHHAABBBBBBBBB-BE------- -EHHAABBBBBBBBB-BE------- -EHHAABBBBCCCCE-EE------- -AHHAABBBBCCCCC-CA------- -AH-AABBBBCCCCC-CA------- -AH-AARRRRCCCCC-CA------- -AH-AADRDRCCCCC-CA------- -AH-AADDDDCCCCC-CA------- -AH-AADDDDCCCCC-CA------- -AHHAADDDDCCCCC-CA------- -AH-AADDDDCCCCC-CA------- -AH-AABBBBBBBBB-BA------- -BB-AADDDDDDDDD-BB------- -BH-AADDDDDDDDD-LB------- -BH-AADDDDDDDDD-LB------- -BHHAADDDDDDDDD-LB------- -BLCAADDDDDDDDD-AB------- -BGGOOOGOGGOPOGGGB------- -B------N-N------B------- ------------------------- ------------------------- ------------------------- ---K--------------------- ---J---K----------------- 
-EEEEEEEEEEEEEEEEE------- -EAAAABBBBBBBBBAAE------- -EAAAABBBBBBBBBAAE------- -EAAAABBBBBBBBBAAE------- -EFAAABBBBBBBBBBBE------- -EHHAABBBBBBBBBBBE------- -EHHAABBBBBBBBBBBE------- -EHHAABBBBBBBBBBBE------- -EHHAABBBBCCCCEEEE------- -AHHAABBBBCCCCCCCA------- -AHHAABBBBCCCCCCCA------- -AHHAABBRRCCCCCCCA------- -AHHAABBRRCCCCCCCA------- -AHHAADDDDCCCCCCCA------- -AHHAADDDDCCCCCCCA------- -AHHAADDDDCCCCCCCA------- -AHHAADDDDCCCCCCCA------- -AHHAADDDBBBBBBBBA------- -BHHAADDDDDDDDDDBB------- -BHHAADDDDDDDDDDDB------- -BHHAADDDDDDDDDDDB------- -BHHAADDDDDDDDDDDB------- -BDDAADDDDDDDDDAAB------- -BOGGGGOGGGOGGOOGB------- -B-----N-N-N-----B------- ------------------------- ------------------------- ------------------------- ------------------------- ---U--KJ----------------- 
EEEEEEEEEEEEEEEEEEE------ EAAAAABBBBBBBBBAAAE------ EAAAAABBBBBBBBBAAAE------ EAAAAABBBBBBBBBAAAE------ EFFAAABBBBBBBBBAAAE------ EFFFAAFBBBBBBBBAAAE------ EFFFAAFBBBBBBBBAAAE------ EFFFAAFBBBBBBBBBBBE------ EEFFAAFBBBCCCCEEEEE------ AFFFAAFBBBCCCCCCCCA------ AFFFAAFBBBCCCCCCCCA------ AFFFAAFBBBCCCCCCCCA------ AFFFAAFBBBCCCCCCCCA------ AFFFAAFDDDCCCCCCCCA------ AFFFAAFDDDCCCCCCCCA------ AFFFAAFDDDCCCCCCCCA------ AFFFAAFDDDCCCCCCCCA------ AFFFAAFDDBBBBBBBBBA------ BBBBBBFDDDDDDMMMBBB------ BFFFAAFDDDDDDMMMDLB------ BFFFAAFDDDDDDMMMDLB------ BFFFAAFDDDDDDMMMDLB------ BLDDAADDDDDDDMMAAAB------ BGGGGOOOGGGGGOPGGPB------ B-----N-N-N-N-----B------ ------------------------- ---------KKK------------- --------JK-KK------------ ----JJJJJ---KK----------- ---JJ-JJ-----K----------- 
EEEEEEEEEEEEEEEEEEE------ EAAAAABBBBBBBBBAAAE------ EAAAAABBBBBBBBBAAAE------ EAAAAABBBBBBBBBAAAE------ EFFAAABBBBBBBBBAAAE------ EFFFAAFBBBBBBBBAAAE------ E-FFAAFIDDDDIBIAAAAAAAAAA E-FFAAFIDDDDIBIIIIIAAAAAA E-FFAAFBBBCCCCEEEEE-----A A-FFAAFBBBCCCCCCCCA-----A A-FFAA--BBCCCCCCCCA-----A A-FFAA------CCCCCCA-----A A-FFAA------C--CC-A-----A A-FFAAFDDDCCCCCCC-A-----A A-FFAAFDDDCCCCCCC-A-----A A-FFAAFDDDCCCCCCC-A-----A A-FFAAFDDDCCCCCCC-A-----A A-FFAAFDDDAAAMMMD-LAAAAAA B-BBBBFDDDDDDMMMD-LAAAAAA B-FFAAFDDDDDDMMMD-B------ B-FFAAFDDDDDDMMMD-B------ B-FFAAFDDDDDDMMMDDB------ B-DDAADDDDDDDMMAAAB------ BGGGOAGGGOGGGOGOPGB------ B----N-N-N-N-N----B------ ------------------------- ---------KKK------------- ------------------------- ----JKK------------------ ------------------------- 
EEEEEEEEEEEEEEEEEEE------ EAAAAABBBBBBBBBAAAE------ EAAAAABBBBBBBBBAAAE------ EAAAAABBBBBBBBBAAAE------ EFFAAABBBBBBBBBAAAE------ EFFFAAFBBBBBBBBAAAE------ E-FFAAFIDDDDIBIIIIBAAAAAA E-FFAAFIDDDDIBIIIIBAAAAAA E-FFAAFBBBCCCCEEEEE-----A A-FFAAFBBBCCCCCCCCA-----A A-FFAA--BBCCCCCCCCA-----A A-FFAA------CCCCCCA-----A A-FFAA------C-CCC-A-----A A-FFAAFDDDCCCCCCC-A-----A A-FFAAFDDDCCCCCCC-A-----A A-FFAAFDDDCCCCCCC-A-----A A-FFAAFDDDCCCCCCC-A-----A A-FFAAFDDDAAAMMMD-LAAAAAA B-BBBBFDDDDDDMMMD-LAAAAAA B-FFAAFDDDDDDMMMD-B------ B-FFAAFDDDDDDMMMD-B------ B-FFAAFDDDDDDMMMDDB------ B-DDAADDDDDDDMMAAAB------ BGGGAGGOGGGGGGGGGPB------ B---N-N-N-N-N-N---B------ ------------------------- ---------KKK------------- --------JK-KK------------ ----JJJVJ---KK----------- ---JJ-KK-----K----------- 
EEEEEEEEEEEEEEEEEEE------ EAAAAABBBBBBBBBAAAE------ EAAAAABBBBBBBBBAAAE------ EAAAAABBBBBBBBBAAAE------ EFFAAABBBBBBBBBAAAE------ EFFFAAFBBBBBBBBAAAE------ E-FFAAFIBDBBBBIIIIBAAAAAA E-FFAAFIDDBBBBIIIIBAAAAAA E-FFAAFDDDCCCCEEEEE-----A A-FFAAFDDDCCCCCCCCA-----A A-FFAAFDDDCCCCCCCCA-----A A-FFAAFDDDCCCCCCCCA-----A A-FFAAFDDDCCCCCCC-A-----A A-FFAAFDDDCCCCCCC-A-----A A-FFAAFDDDCCCCCCC-A-----A A-FFAAFDDDCCCCCCC-A-----A A-FFAAFDDDCCCCCCC-A-----A A-FFAAFDDDAAAADDD-LAAAAAA B-BBBBFAAADDDDDDD-LAAAAAA B-FFAAFAAADDIDDDD-B------ B-FFAAFAAADDIDDDD-B------ B-FFAAFAAADDIDDDDDB------ B-DDAADDDDDDIIDAAAB------ BGOGGAGGGOOGGGGOPPB------ B--N-N-N-T-T-N-N--B------ ---------KKJ------------- --------KK-KK------------ -------KK--KKK----------- -----U-K----KK----------- -------K----------------- 
EEEEEEEEEEEEEEEEEEE------ EAAAAABBBBBBBBBAAAE------ EAAAAABBBBBBBBBAAAE------ EAAAAABBBBBBBBBAAAE------ EFFAAABBBBBBBBBAAAE------ EFFFAAFBBBBBBBBAAAE------ E-FFAAFIBDBBBBIIIIBAAAAAA E-FFAAFIDDBBBBIIIIBAAAAAA E-FFAAFDDDCCCCEEEEE-----A A-FFAAFDDDCCCCCCCCA-----A A-FFAAFDDDCCCCCCCCA-----A A-FFAAFDDDCCCCCCCCA-----A A-FFAAFDDDCCCCCCC-A-----A A-FFAAFDDDCCCCCCC-A-----A A-FFAAFDDD-CCCCCC-A-----A A-FFAAFDDDC---CCC-A-----A A-FFAAFDDDC-C-CCC-A-----A A-FFAAFDDDD-D-DDD-LAAAAAA B-BBBBFAAADDDDDDD-LAAAAAA B-FFAAFAAADDIDDDD-B------ B-FFAAFAAADDIDDDD-B------ B-FFAAFAAADDIDDDDDB------ B-DDAADDDDDDIIDAAAB------ BGGOAGGOGGGOGGGGGPB------ B---N-N-N-T-N-N---B------ ---------KKK------------- ------------------------- ------------------------- -----K------------------- ------------------------- 
EEEEEEEEEEEEEEEEEEE------ EAAAAABBBBBBBBBAAAE------ EAAAAABBBBBBBBBAAAE------ EAAAAABBBBBBBBBAAAE------ EFFAAABBBBBBBBBAAAE------ EFFFAAFBBBBBBBBAAAE------ E-FFAAFIBDBBBBBBBBE------ E-FFAAFIDDBBBBIIIBE------ E-FFAAFDDDCCCCCCCEE------ A-FFAAFDDDCCCCCCCCA------ A-FFAAFDDDCCCCCCCCA------ A-FFAAFDDDCCCCCCCCA------ A-FFAAFDDDCCCCCCC-A------ A-FFAAFDDDCCCCCCC-A------ A-FFAAFDDD-C-CCCC-A------ A-FFAAFDDDC---CCC-A------ A-FFAAFDDDC-C-CCC-A------ A-FFAAFBBBB-B-BBB-A------ B-BBBBFAAADDDBBBB-B------ B-FFAAFAAADDIBBBB-B------ B-FFAAFAAADDIDDDD-B------ B-FFAAFAAADDIDDDDDB------ B-DDAADDDDDDIIDAAAB------ BGPGGAGGOGGGGGGGGPB------ B----N-N-T-T-N----B------ ---------JJJ------------- --------JJ-KK------------ -------JJK--JK----------- -------J-----J----------- ------------------------- 
EEEEEEEEEEEEEEEEEEE------ EAAAAABBBBBBBBBAAAE------ EAAAAABBBBBBBBBAAAE------ EAAAAABBBBBBBB---AE------ EFFFAABBBBBBBB---AE------ EFFFAAFBBBBBBB---AE------ EFFFAAFIBDBBBB---BE------ EFFFAAFIDDBBBB---BE------ EEFFAAFDDDCCCC---EE------ AFFFAAFDDDCCCC---CA------ AFFFAAFDDDCCCC---CA------ AFFFAAFDDDCCCC---CA------ AFFFAAFDDDCCCC---CA------ AFFFAAFDDDCCCC---CA------ AFFFAAFDDD-CCCCC-CA------ AFFFAAFDDDC--CCCQCA------ AFFFAAFDDDC-CCCCQCA------ AFFFAAFBBBB-BBBBQBA------ BBBBBBFAAADDDBBBBBB------ BFFFAAFAAADDIBBBBBB------ BFFFAAFAAADDIDDDQLB------ BFFFAAFAAADDIDDDQLB------ BLDDAADDDDDDIDDAAAB------ BGPPGGOGGGOGOPOGGPB------ B-----N-N-T-N-----B------ ----------U-------------- ----------K-------------- ------UJU---K------------ ------------------------- ------------------------- 
-EEEEEEEEEEEEEEEEE------- -EAAAABBBBBBBBBAAE------- -EAAAABBBBBBBBBAAE------- -EAAAABBBBBBBB---E------- -EFFAABBBBBBBB---E------- -EHHAABBBBBBBB---E------- -EHHAABBBBBBBB---E------- -EHHAABBBBBBBB---E------- -EHHAACCCCCCCC---E------- -AHHAACCCCCCCC---A------- -AHHAACCCCCCCC---A------- -AHHAACCCCCCCC---A------- -AHHAACCCCCCCC---A------- -AHHAACCCCCCCC--QA------- -AHHAACCCC-C-CC-QA------- -AHHAACCCCC--CCCQA------- -AHHAADDDDD-DDDDQA------- -AHHAABBBBB-BBBB-A------- -BBBBBDDDDDDDBBBBB------- -BHHAADDDDDDIBBBBB------- -BHHAADDDDDDIDDDQB------- -BHHAADDDDDDIDDDQB------- -BDDAADDDDDDIDAAAB------- -BGGGGGGGGOOGPGGPB------- -B-----N-N-N-----B------- ------------------------- ----------UK------------- ------K----K------------- ------------------------- ------------------------- 
-EEEEEEEEEEEEEEEEE------- -EAAAABBB-BBBBBAAE------- -EAAAABBB-BBBBBAAE------- -EAAAABBBBBBBBB-AE------- -EFFAABBBBBB----QE------- -EHHAABBBB------QE------- -EHHAABBBB------QE------- -EHHAABBBB------QE------- -EHHAACCCC------QE------- -AHHAACCCC------QA------- -AHHAACCCC------QA------- -AHHAACCCC------QA------- -AHHAACCCC------QA------- -AHHAACCCC------QA------- -AHHAACCCCC-CCCCQA------- -AHHAACCCCC--CCCQA------- -AHHAADDDDD-DDDDQA------- -AHHAABBBBB-BBBBQA------- -BBBBBDDDDDDDBBBBB------- -BHHAADDDDDDIBBBBB------- -BHHAADDDDDDIDDDQB------- -BHHAADDDDDDIDDDQB------- -BLDAADDDDDDIDAAAB------- -BGPGGOGGGGOGPGPPB------- -B------N-N------B------- ------------------------- ----------J-------------- ------------------------- ------------------------- ------------------------- 
--EEEEEEEEEEEEEEE-------- --EAAABBBBBBBBBAE-------- --EAAABBBBBBBBBAE-------- --EAAABBBBBB--BAE-------- --EFAABBBBB----BE-------- --EHAABBBB-----BE-------- --EHAABBBB-----BE-------- --EHAABBBB-----BE-------- --EEEEEEEE-----EE-------- --AHAACCCC-----CA-------- --AH--CCCC-----CA-------- --AH--CCCC-----CA-------- --AH--CCCC-----CA-------- --AH--CCCC-----CA-------- --AH--CCCCCCCCCCA-------- --AH--CCCC-C-CCCA-------- --AH--DDDD--DDDLA-------- --AH--BBBB--BBBBA-------- --BB--DDDD--DBBBB-------- --BH--DDDD--IBBBB-------- --BH--DDDD--IDDLB-------- --BH--DDDD--IDDLB-------- --BLAADDDDDDIDAAB-------- --BGGGGGOGGPPGPPB-------- --B------N------B-------- ------------------------- ------------------------- ------------------------- ------------------------- ------------------------- 
---EEEEEEEEEEEEE--------- ---EAABBBBBBBBBE--------- ---EAABBBBBBBBBE--------- ---EA----BBB--BE--------- ---EA----BB---BE--------- ---EA---------BE--------- ---EA---------BE--------- ---EA---------BE--------- ---EE---------EE--------- ---AA---------CA--------- ---AA---------CA--------- ---AA---------CA--------- ---AA---------CA--------- ---AA---------CA--------- ---AA------CCCCA--------- ---AA------CCCCA--------- ---AA-------DDLA--------- ---AA-------BBBA--------- ---BB-------DBBB--------- ---BA--------BBB--------- ---BA--------DLB--------- ---BA--------DLB--------- ---BAADDDDDDCDAB--------- ---BGGGPOPPOGGPB--------- ---B-----------B--------- ------------------------- ------------------------- ------------------------- ------------------------- ------------------------- 
----EEEEEEEEEEE---------- ----EEBBBBBBBEE---------- ----EEBBBBBBBEE---------- ----EEB---B-BEE---------- ----EEB-----BEE---------- ----EEB-----BEE---------- ----EEB-----BEE---------- ----EEB-----BEE---------- ----EEE-----EEE---------- ----AAC-----CAA---------- ----AAC-----CAA---------- ----AAC-----CAA---------- ----AAC-----CAA---------- ----AAC-----CAA---------- ----AAC-----CAA---------- ----AAC-----CAA---------- ----AAL-----LAA---------- ----AAB-----BAA---------- ----BBB-----BBB---------- ----BBL-----LBB---------- ----BBL-----LBB---------- ----BBL-----LBB---------- ----BBLDDDDDLBB---------- ----BBGGGPPGGBB---------- ----BB-------BB---------- ------------------------- ------------------------- ------------------------- ------------------------- ------------------------- 
------EEEEEEE------------ ------EEEEEEE------------ ------EEEEEEE------------ ------EEEEEEE------------ ------EEEEEEE------------ ------EEEEEEE------------ ------EEEEEEE------------ ------EEEEEEE------------ ------EEEEEEE------------ ------AAAAAAA------------ ------AAAAAAA------------ ------AAAAAAA------------ ------AAAAAAA------------ ------AAAAAAA------------ ------AAAAAAA------------ ------AAAAAAA------------ ------AAAAAAA------------ ------AAAAAAA------------ ------BBBBBBB------------ ------BBBBBBB------------ ------BBBBBBB------------ ------BBBBBBB------------ ------BBBBBBB------------ ------BBBBBBB------------ ------BBBBBBB------------ ------------------------- ------------------------- ------------------------- ------------------------- ------------------------- 
