model
size = 25 30 19, scale = 0.05, origin = -y
material 
  colors = A:#E00 B:#FF0 C:#CF3 D:#00C E:#009 F:#EEE G:#251505 H:#CF0 I:#AAAAB9 J:#BBB K:#CC6 L:#939 M:#960 N:#1C0900 O:#AAA P:#040 Q:#888 R:#FCF
voxels
------BBBBBBB------------ ------BBBBBBB------------ ------BBBBBBB------------ ------BBBBBBB------------ ------BBBBBBB------------ ------BBBBBBB------------ ------BBBBBBB------------ ------BBBBBBB------------ ------BBBBBBB------------ ------BBBBBBB------------ ------BBBBBBB------------ ------BBBBBBB------------ ------BBBBBBB------------ ------BBBBBBB------------ ------BBBBBBB------------ ------BBBBBBB------------ ------BBBBBBB------------ ------BBBBBBB------------ ------BBBBBBB------------ ------BBBBBBB------------ ------BBBBBBB------------ ------BBBBBBB------------ ------BBBBBBB------------ ------BBBBBBB------------ ------BBBBBBB------------ ------------------------- ------------------------- ------------------------- ------O------------------ ------------------------- 
----EEBBBBBBBAA---------- ----EEA---AAAAA---------- ----EEA---AAAAA---------- ----EEA---AAAAA---------- ----EEA---AAAAA---------- ----EEA---AAAAA---------- ----EEA---AAAAA---------- ----EEA--AAAAAA---------- ----EEB--BBBBAA---------- ----EEB--BBBBAA---------- ----EEB--BBBBAA---------- ----EEB-BBBBBAA---------- ----EEBBBBBBBAA---------- ----EEBBBBBBBAA---------- ----EEBBBBBBBAA---------- ----EEBBBBBBBAA---------- ----EEICCCBBBAA---------- ----EEAAAAAAAAA---------- ----EEICCCCCIAA---------- ----EEICCCCCIAA---------- ----EEICCCCCIAA---------- ----EEICCCCCIAA---------- ----EEICCCCCIAA---------- ----EEGGGGGGGAA---------- ----EE-------AA---------- ------------------------- ------------------------- ------------------------- ------J------------------ ------J------------------ 
---EEEBBBBBBBAAA--------- ---EAA--------AA--------- ---EAAAAAAAAAAAA--------- ---EAAAAAAAAAAAA--------- ---EAAAAAAAAAAAA--------- ---EDAAAAAAAAAAA--------- ---EDFFFFFFFFFAA--------- ---EDAAAAAAAAAAA--------- ---EDBBBBBBBBAAA--------- ---EDBBBBBBBBAAA--------- ---EDBBBBBBBBAAA--------- ---EDBBBBBBBBAAA--------- ---EDBBBBBBBBAAA--------- ---EDBBBBBBBBAAA--------- ---EDBBBBBBBBAAA--------- ---EDBBBBBBBBAAA--------- ---EDCCCCCBBBAAA--------- ---EDAAAAAAAAAAA--------- ---EDCCCCCCCCAAA--------- ---EDCCCCCCCCAAA--------- ---EDCCCCCCCCAAA--------- ---EDCCCCCCCCAAA--------- ---EICCCCCCCCCIA--------- ---EGGGGGGMNGGGA--------- ---E-----------A--------- ------------------------- ------------------------- ------------------------- ------------------------- ------JJ----------------- 
--EEEEBBBBBBBAAAA-------- --EEEAAAAAAAAAAFA-------- --EEEAAAAAAAAAAFA-------- --EEEAAAAAAAAAAFA-------- --EEEAAAAAAAAAAAA-------- --EEEAAAAAAAAAAAA-------- --EEEFFFFFFFFFAAA-------- --EEEAAAAAAAAAAAA-------- --EEEBBBBBBBBBBBA-------- --EEEB--------BBA-------- --EEEBBBBBBBBBBBA-------- --EEEBBBBBBBBBBBA-------- --EEEBBBBBBBBBBBA-------- --EEEBBBBB-BBBBBA-------- --EEEBBBBB-BBBBBA-------- --EEEBBBBB-BBBBBA-------- --EEECCCCC-BBBBBA-------- --EEEAAAAA-AAAAAA-------- --EEECCCCC-CCCCIA-------- --EEECCCCC-CCCCIA-------- --EEECCCCC-CCCCIA-------- --EEECCCCC-CCCCIA-------- --EEECCCCC-CCCCFA-------- --EEEGGMGMGGNNGGA-------- --E------K------A-------- ------------------------- ------------------------- ------------------------- ---J--------------------- -------J----------------- 
-EEEEEBBBBBBBAAAAA------- -EEFAAAAAAAAAAA-FA------- -EEFAAAAAAAAAAA-FA------- -EEFAAAAAAAAAAA-FA------- -EEFAAAAAAAAAAA-AA------- -EEDDAAAAAAAAAA-AA------- -EEDDAAAAAAAAAA-AA------- -EEDDAAAAAAAAAA-AA------- -EEDDAAAAABBBBB-BA------- -EEDDAAAAABBBBB-BA------- -EE-DAAAAABBBBB-BA------- -EE-DAPPPPBBBBB-BA------- -EE-DACPCPBBBBB-BA------- -EE-DACCCCBBBBB-BA------- -EE-DACCCCBBBBB-BA------- -EEDDACCCCBBBBB-BA------- -EE-DCCCCCBBBBB-BA------- -EE-DAAAAAAAAAA-AA------- -EE-DCCCCCCCCCC-IA------- -EE-DCCCCCCCCCC-IA------- -EE-DCCCCCCCCCC-IA------- -EEDDCCCCCCCCCC-IA------- -EEBCCCCCCCCCCC-FA------- -EEGMGMGMGGMNMGGGA------- -E------K-K------A------- ------------------------- ------------------------- ------------------------- ---J--------------------- ---O---J----------------- 
-EEEEEBBBBBBBAAAAA------- -EFFCCAAAAAAAAAFFA------- -EFFCCAAAAAAAAAFFA------- -EFFCCAAAAAAAAAFFA------- -EFFCCAAAAAAAAAAAA------- -EDDDCAAAAAAAAAAAA------- -EDDDCAAAAAAAAAAAA------- -EDDDCAAAAAAAAAAAA------- -EDDDAAAAABBBBBBBA------- -EDDDAAAAABBBBBBBA------- -EDDDAAAAABBBBBBBA------- -EDDDAAAPPBBBBBBBA------- -EDDDAAAPPBBBBBBBA------- -EDDDACCCCBBBBBBBA------- -EDDDACCCCBBBBBBBA------- -EDDDACCCCBBBBBBBA------- -EDDDCCCCCBBBBBBBA------- -EDDDACCCAAAAAAAAA------- -EDDDCCCCCCCCCCCCA------- -EDDDCCCCCCCCCCCCA------- -EDDDCCCCCCCCCCCCA------- -EDDDCCCCCCCCCCCCA------- -ECCCCCCCCCCCCCFFA------- -EMGMMGMGGGMGGMMGA------- -E-----K-K-K-----A------- ------------------------- ------------------------- ------------------------- ------------------------- ---Q--JO----------------- 
EEEEEEBBBBBBBAAAAAA------ EFFFCCAAAAAAAAAFFFA------ EFFFCCAAAAAAAAAFFFA------ EFFFCCAAAAAAAAAFFFA------ EFFFCCAAAAAAAAAFFFA------ EDDDDCAAAAAAAAAFFFA------ EDDDDCAAAAAAAAAFFFA------ EDDDDCAAAAAAAAAAAAA------ EDDDDAAAAABBBBBBBBA------ EDDDDAAAAABBBBBBBBA------ EDDDDAAAAABBBBBBBBA------ EDDDDAAAAABBBBBBBBA------ EDDDDAAAAABBBBBBBBA------ EDDDDACCCCBBBBBBBBA------ EDDDDACCCCBBBBBBBBA------ EDDDDACCCCBBBBBBBBA------ EDDDDCCCCCBBBBBBBBA------ EDDDDACCCAAAAAAAAAA------ EDDDDCCCCCCCCLLLCIA------ EDDDDCCCCCCCCLLLCIA------ EDDDDCCCCCCCCLLLCIA------ EDDDDCCCCCCCCLLLCIA------ EICCCCCCCCCCCLLFFFA------ EGGGGGMMGGGGGMNGGNA------ E-----K-K-K-K-----A------ ------------------------- ---------JJJ------------- --------OJ-JJ------------ ----OOOOO---JJ----------- ---OO-OO-----J----------- 
EEEEEEBBBBBBBAAAAAA------ EFFFAAAAAAAAAAAFFFA------ EFFFAAAAAAAAAAAFFFA------ EFFFAAAAAAAAAAAFFFA------ EFFFAAAAAAAAAAAFFFA------ EDDDDAAAAAAAAAAFFFA------ E-DDDHAHCCCCHAHFFFFBBBBBA E-DDDHAHCCCCHAHHHHHBBBBBA E-DDDAAAAABBBBBBBBA-----A E-DDDAAAAABBBBBBBBA-----A E-DDDA--AABBBBBBBBA-----A E-DDDA------BBBBBBA-----A E-DDDA------B--BB-A-----A E-DDDACCCCBBBBBBB-A-----A E-DDDACCCCBBBBBBB-A-----A E-DDDACCCCBBBBBBB-A-----A E-DDDCCCCCBBBBBBB-A-----A E-DDDACCCCFFFLLLC-IBBBBBA E-DDDCCCCCCCCLLLC-IBBBBBA E-DDDCCCCCCCCLLLC-A------ E-DDDCCCCCCCCLLLC-A------ E-DDDCCCCCCCCLLLCCA------ E-CCCCCCCCCCCLLFFFA------ EGGGGGGGGMGGGMGMNGA------ E----K-K-K-K-K----A------ ------------------------- ---------JJJ------------- ------------------------- ----OJJ------------------ ------------------------- 
EEEEEEBBBBBBBAAAAAA------ EFFFAAAAAAAAAAAFFFA------ EFFFAAAAAAAAAAAFFFA------ EFFFAAAAAAAAAAAFFFA------ EFFFAAAAAAAAAAAFFFA------ EDDDDAAAAAAAAAAFFFA------ E-DDDHAHCCCCHAHHHHABBBBBA E-DDDHAHCCCCHAHHHHADDDDDA E-DDDAAAAABBBBBBBBA-----A E-DDDAAAAABBBBBBBBA-----A E-DDDA--AABBBBBBBBA-----A E-DDDA------BBBBBBA-----A E-DDDA------B-BBB-A-----A E-DDDACCCCBBBBBBB-A-----A E-DDDACCCCBBBBBBB-A-----A E-DDDACCCCBBBBBBB-A-----A E-DDDCCCCCBBBBBBB-A-----A E-DDDACCCCFFFLLLC-IDDDDDA E-DDDCCCCCCCCLLLC-IBBBBBA E-DDDCCCCCCCCLLLC-A------ E-DDDCCCCCCCCLLLC-A------ E-DDDCCCCCCCCLLLCCA------ E-CCCCCCCCCCCLLFFFA------ EGGGGGGMGGGGGGGGGNA------ E---K-K-K-K-K-K---A------ ------------------------- ---------JJJ------------- --------OJ-JJ------------ ----OOORO---JJ----------- ---OO-JJ-----J----------- 
EEEEEEBBBBBBBAAAAAA------ EFFFAAAAAAAAAAAFFFA------ EFFFAAAAAAAAAAAFFFA------ EFFFAAAAAAAAAAAFFFA------ EFFFAAAAAAAAAAAFFFA------ EDDDDAAAAAAAAAAFFFA------ E-DDDHHHACAAAAHHHHABBBBBA E-DDDHHHCCAAAAHHHHADDDDDA E-DDDAACCCBBBBBBBBA-----A E-DDDAACCCBBBBBBBBA-----A E-DDDAACCCBBBBBBBBA-----A E-DDDAACCCBBBBBBBBA-----A E-DDDAACCCBBBBBBB-A-----A E-DDDAACCCBBBBBBB-A-----A E-DDDAACCCBBBBBBB-A-----A E-DDDAACCCBBBBBBB-A-----A E-DDDCCCCCBBBBBBB-A-----A E-DDDACCCCFFFFCCC-IDDDDDA E-DDDCFFFFCCCCCCC-IBBBBBA E-DDDCFFFFCCHCCCC-A------ E-DDDCFFFFCCHCCCC-A------ E-DDDCFFFFCCHCCCCCA------ E-CCCCCCCCCCHHCFFFA------ EGMGGGGGGMMGGGGMNNA------ E--K-K-K-K-K-K-K--A------ ---------JJO------------- --------JJ-JJ------------ -------JJ--JJJ----------- -----Q-J----JJ----------- -------J----------------- 
EEEEEEBBBBBBBAAAAAA------ EFFFAAAAAAAAAAAFFFA------ EFFFAAAAAAAAAAAFFFA------ EFFFAAAAAAAAAAAFFFA------ EFFFAAAAAAAAAAAFFFA------ EDDDDAAAAAAAAAAFFFA------ E-DDDHHHACAAAAHHHHABBBBBA E-DDDHHHCCAAAAHHHHABBBBBA E-DDDAACCCBBBBBBBBA-----A E-DDDAACCCBBBBBBBBA-----A E-DDDAACCCBBBBBBBBA-----A E-DDDAACCCBBBBBBBBA-----A E-DDDAACCCBBBBBBB-A-----A E-DDDAACCCBBBBBBB-A-----A E-DDDAACCC-BBBBBB-A-----A E-DDDAACCCB---BBB-A-----A E-DDDCCCCCB-B-BBB-A-----A E-DDDACCCCC-C-CCC-IBBBBBA E-DDDCFFFFCCCCCCC-IBBBBBA E-DDDCFFFFCCHCCCC-A------ E-DDDCFFFFCCHCCCC-A------ E-DDDCFFFFCCHCCCCCA------ E-CCCCCCCCCCHHCFFFA------ EGGMMGGMGGGMGGGGGNA------ E---K-K-K-K-K-K---A------ ---------JJJ------------- ------------------------- ------------------------- -----J------------------- ------------------------- 
EEEEEEBBBBBBBAAAAAA------ EFFFAAAAAAAAAAAFFFA------ EFFFAAAAAAAAAAAFFFA------ EFFFAAAAAAAAAAAFFFA------ EFFFAAAAAAAAAAAFFFA------ EDDDDAAAAAAAAAAFFFA------ E-DDDHHHACAAAAAAAAA------ E-DDDHHHCCAAAAHHHAA------ E-DDDAACCCBBBBBBBBA------ E-DDDAACCCBBBBBBBBA------ E-DDDAACCCBBBBBBBBA------ E-DDDAACCCBBBBBBBBA------ E-DDDAACCCBBBBBBB-A------ E-DDDAACCCBBBBBBB-A------ E-DDDAACCC-B-BBBB-A------ E-DDDAACCCB---BBB-A------ E-DDDCCCCCB-B-BBB-A------ E-DDDAAAAAA-A-AAA-A------ E-DDDCFFFFCCCCCCC-A------ E-DDDCFFFFCCHCCCC-A------ E-DDDCFFFFCCHCCCC-A------ E-DDDCFFFFCCHCCCCCA------ E-CCCCCCCCCCHHCFFFA------ EGNGMGGGMGGGGGGGGNA------ E----K-K-K-K-K----A------ ---------OOO------------- --------OO-JJ------------ -------OOJ--OJ----------- -------O-----O----------- ------------------------- 
EEEEEEBBBBBBBAAAAAA------ EFFFAAAAAAAAAAAFFFA------ EFFFAAAAAAAAAAAFFFA------ EFFFAAAAAAAAAA---FA------ EFFFAAAAAAAAAA---FA------ EDDDDDAAAAAAAA---FA------ EDDDDDHHACAAAA---AA------ EDDDDDHHCCAAAA---AA------ EDDDDDACCCBBBB---BA------ EDDDDDACCCBBBB---BA------ EDDDDDACCCBBBB---BA------ EDDDDDACCCBBBB---BA------ EDDDDDACCCBBBB---BA------ EDDDDDACCCBBBB---BA------ EDDDDDACCC-BBBBB-BA------ EDDDDDACCCB--BBBBBA------ EDDDDDCCCCB-BBBBBBA------ EDDDDDAAAAA-AAAAAAA------ EDDDDDFFFFCCCCCCCIA------ EDDDDDFFFFCCHCCCCIA------ EDDDDDFFFFCCHCCCCIA------ EDDDDDFFFFCCHCCCCIA------ EICCCCCCCCCCHCCFFFA------ EGNNMGMGGGMGMNMGGNA------ E-----K-K-K-K-----A------ ----------Q-------------- ----------J-------------- ------QOQ---J------------ ------------------------- ------------------------- 
-EEEEEBBBBBBBAAAAA------- -EFFAAAAAAAAAAAFFA------- -EFFAAAAAAAAAAAFFA------- -EFFAAAAAAAAAA---A------- -EFFAAAAAAAAAA---A------- -EDDDDAAAAAAAA---A------- -EDDDDAAAAAAAA---A------- -EDDDDAAAAAAAA---A------- -EDDDDBBBBBBBB---A------- -EDDDDBBBBBBBB---A------- -EDDDDBBBBBBBB---A------- -EDDDDBBBBBBBB---A------- -EDDDDBBBBBBBB---A------- -EDDDDBBBBBBBB--BA------- -EDDDDBBBB-B-BB-BA------- -EDDDDBBBBB--BBBBA------- -EDDDDCCCCC-CCCCCA------- -EDDDDAAAAA-AAAA-A------- -EDDDDCCCCCCCCCCBA------- -EDDDDCCCCCCHCCCBA------- -EDDDDCCCCCCHCCCBA------- -EDDDDCCCCCCHCCCBA------- -ECCCCCCCCCCHCFFFA------- -EGGMMGGGGMMGNGGNA------- -E-----K-K-K-----A------- ------------------------- ----------QJ------------- ------J----J------------- ------------------------- ------------------------- 
-EEEEEBBBBBBBAAAAA------- -EFFAAAAA-AAAAAFFA------- -EFFAAAAA-AAAAAFFA------- -EFFAAAAAAAAAAA-FA------- -EFFAAAAAAAA----AA------- -EDDDDAAAA------AA------- -EDDDDAAAA------AA------- -EDDDDAAAA------AA------- -EDDDDBBBB------BA------- -EDDDDBBBB------BA------- -EDDDDBBBB------BA------- -EDDDDBBBB------BA------- -EDDDDBBBB------BA------- -EDDDDBBBB------BA------- -EDDDDBBBBB-BBBBBA------- -EDDDDBBBBB--BBBBA------- -EDDDDCCCCC-CCCCIA------- -EDDDDAAAAA-AAAAAA------- -EDDDDCCCCCCCCCCIA------- -EDDDDCCCCCCHCCCIA------- -EDDDDCCCCCCHCCCIA------- -EDDDDCCCCCCHCCCIA------- -EICCCCCCCCCHCFFFA------- -EGNNNMGGGGMGNGNNA------- -E------K-K------A------- ------------------------- ----------O-------------- ------------------------- ------------------------- ------------------------- 
--EEEEBBBBBBBAAAA-------- --EFAAAAAAAAAAAFA-------- --EFAAAAAAAAAAAFA-------- --EFAAAAAAAA--AFA-------- --EFAAAAAAA----AA-------- --EDDDAAAA-----AA-------- --EDDDAAAA-----AA-------- --EDDDAAAA-----AA-------- --EDDDBBBB-----BA-------- --EDDDBBBB-----BA-------- --ED--BBBB-----BA-------- --ED--BBBB-----BA-------- --ED--BBBB-----BA-------- --ED--BBBB-----BA-------- --ED--BBBBBBBBBBA-------- --ED--BBBB-B-BBBA-------- --ED--CCCC--CCCIA-------- --ED--AAAA--AAAAA-------- --ED--CCCC--CCCIA-------- --ED--CCCC--HCCIA-------- --ED--CCCC--HCCIA-------- --ED--CCCC--HCCIA-------- --EICCCCCCCCHCFFA-------- --EGGGGGMGGNNGNNA-------- --E------K------A-------- ------------------------- ------------------------- ------------------------- ------------------------- ------------------------- 
---EEEBBBBBBBAAA--------- ---EAAAAAAAAAAAA--------- ---EAAAAAAAAAAAA--------- ---EA----AAA--AA--------- ---EA----AA---AA--------- ---ED---------AA--------- ---ED---------AA--------- ---ED---------AA--------- ---ED---------BA--------- ---ED---------BA--------- ---ED---------BA--------- ---ED---------BA--------- ---ED---------BA--------- ---ED---------BA--------- ---ED------BBBBA--------- ---ED------BBBBA--------- ---ED-------CCIA--------- ---ED-------AAAA--------- ---ED-------CCIA--------- ---ED--------CIA--------- ---ED--------CIA--------- ---ED--------CIA--------- ---EICCCCCCCBCFA--------- ---EGGGNMNNMGGNA--------- ---E-----------A--------- ------------------------- ------------------------- ------------------------- ------------------------- ------------------------- 
----EEBBBBBBBAA---------- ----EEAAAAAAAAA---------- ----EEAAAAAAAAA---------- ----EEA---A-AAA---------- ----EEA-----AAA---------- ----EEA-----AAA---------- ----EEA-----AAA---------- ----EEA-----AAA---------- ----EEB-----BAA---------- ----EEB-----BAA---------- ----EEB-----BAA---------- ----EEB-----BAA---------- ----EEB-----BAA---------- ----EEB-----BAA---------- ----EEB-----BAA---------- ----EEB-----BAA---------- ----EEI-----IAA---------- ----EEA-----AAA---------- ----EEI-----IAA---------- ----EEI-----IAA---------- ----EEI-----IAA---------- ----EEI-----IAA---------- ----EEICCCCCIAA---------- ----EEGGGNNGGAA---------- ----EE-------AA---------- ------------------------- ------------------------- ------------------------- ------------------------- ------------------------- 
------BBBBBBB------------ ------BBBBBBB------------ ------BBBBBBB------------ ------BBBBBBB------------ ------BBBBBBB------------ ------BBBBBBB------------ ------BBBBBBB------------ ------BBBBBBB------------ ------BBBBBBB------------ ------BBBBBBB------------ ------BBBBBBB------------ ------BBBBBBB------------ ------BBBBBBB------------ ------BBBBBBB------------ ------BBBBBBB------------ ------BBBBBBB------------ ------BBBBBBB------------ ------BBBBBBB------------ ------BBBBBBB------------ ------BBBBBBB------------ ------BBBBBBB------------ ------BBBBBBB------------ ------BBBBBBB------------ ------BBBBBBB------------ ------BBBBBBB------------ ------------------------- ------------------------- ------------------------- ------------------------- ------------------------- 
