model
size = 30 28 26, scale = 0.05, origin = -y
material 
  colors = A:#292959 B:#0F0F32 C:#FFBB32 D:#555 E:#960 F:#007 G:#200 H:#002 I:#004 J:#FC3 K:#66F L:#500
voxels
------------------------------ ------------------------------ -----------EEEEEEEE----------- ------------------------------ ------------------------------ ------------------------------ ------------------------------ ------------------------------ ------------------------------ ------------------------------ ------------------------------ ------------------------------ ------------------------------ ------------------------------ ------------------------------ ------------------------------ ------------------------------ ------------------------------ ------------------------------ ------------------------------ ------------------------------ ------------------------------ ------------------------------ ------------------------------ ------------------------------ ------------------------------ ------------------------------ ------------------------------ 
------------------------------ ------------------------------ --------EEEBBBBBBBBEEE-------- -----------BBBBBBBB----------- -----------BBBBBBBB----------- -----------BBBBBBBB----------- -----------EEEEEEEE----------- ------------------------------ ------------------------------ ------------------------------ ------------------------------ ------------------------------ ------------------------------ ------------------------------ ------------------------------ ------------------------------ ------------------------------ ------------------------------ ------------------------------ ------------------------------ ------------------------------ ------------------------------ ------------------------------ ------------------------------ ------------------------------ ------------------------------ ------------------------------ ------------------------------ 
------------------------------ ------------------------------ ------EEBBBB------BBBBEE------ --------BBBB------BBBB-------- --------BBBB------BBBB-------- --------BBBB------BBBB-------- --------EEEB------BEEE-------- -----------BBBBBBBB----------- -----------BBBBBBBB----------- -----------BBBBBBBB----------- -----------BBBBBBBB----------- -----------BBBBBBBB----------- -----------BBBBBBBB----------- -----------BBBBBBBB----------- -----------EEEEEEEE----------- ------------------------------ ------------------------------ ------------------------------ ------------------------------ ------------------------------ ------------------------------ ------------------------------ ------------------------------ ------------------------------ ------------------------------ ------------------------------ ------------------------------ ------------------------------ 
------------------------------ ------------------------------ -----EBBBB----------BBBBE----- ------BBBB----------BBBB------ ------BBBB----------BBBB------ ------BBBB----------BBBB------ ------EEEB----------BEEE------ ---------BB--------BB--------- ---------BB--------BB--------- ---------BB--------BB--------- ---------BB--------BB--------- ---------BB--------BB--------- ---------BB--------BB--------- ---------BB--------BB--------- ---------EEBBBBBBBBEE--------- -----------AAAAAAAA----------- -----------CCCCCCCC----------- ------------------------------ ------------------------------ ------------------------------ ------------------------------ ------------------------------ ------------------------------ ------------------------------ ------------------------------ ------------------------------ ------------------------------ ------------------------------ 
------------------------------ ------------------------------ ----EBB----------------BBE---- -----BB----------------BB----- -----BB----------------BB----- -----BB----------------BB----- -----EE----------------EE----- -------BB------------BB------- -------BB------------BB------- -------BB------------BB------- -------BB------------BB------- -------BB------------BB------- -------BB------------BB------- -------BB------------BB------- -------EEBBBBBBBBBBBBEE------- ---------AABBBBBBBBAA--------- ---------CCAAAAAAAACC--------- -----------AAAAAAAA----------- -----------AAAAAAAA----------- ------------------------------ ------------------------------ ------------------------------ ------------------------------ ------------------------------ ------------------------------ ------------------------------ ------------------------------ ------------------------------ 
------------------------------ ------------------------------ ---EBB------------------BBE--- ----BB------------------BB---- ----BB------------------BB---- ----BB------------------BB---- ----EE------------------EE---- ------B----------------B------ ------B----------------B------ ------B----------------B------ ------B----------------B------ ------B----------------B------ ------B----------------B------ ------B----------------B------ ------EBBBB--------BBBBE------ -------AABB--------BBAA------- -------CCAAFFFFFFFFAACC------- ---------AAAAAAAAAAAA--------- ---------AAAAAAAAAAAA--------- ------------CCCCCC------------ ------------------------------ ------------------------------ ------------------------------ ------------------------------ ------------------------------ ------------------------------ ------------------------------ ------------------------------ 
------------------------------ ------------------------------ --EBB--------------------BBE-- ---BB--------------------BB--- ---BB--------------------BB--- ---BB--------------------BB--- ---EE--------------------EE--- -----B------------------B----- -----B------------------B----- -----B------------------B----- -----B------------------B----- -----B------------------B----- -----B------------------B----- -----B------------------B----- -----EBBB------------BBBE----- ------AAB------------BAA------ ------CAAFFFFFFFFFFFFAAC------ -------AAAAAAAAAAAAAAAA------- -------AAAAAAAAAAAAAAAA------- ----------CCAAAAAACC---------- ------------AAAAAA------------ ------------AAAAAA------------ ------------------------------ ------------------------------ ------------------------------ ------------------------------ ------------------------------ ------------------------------ 
------------------------------ ------------------------------ --EB----------------------BE-- ---B----------------------B--- ---B----------------------B--- ---B----------------------B--- ---E----------------------E--- ----B--------------------B---- ----B--------------------B---- ----B--------------------B---- ----B--------------------B---- ----B--------------------B---- ----B--------------------B---- ----B--------------------B---- ----EBBB--------------BBBE---- -----AAB--------------BAA----- -----CCAFFFF------FFFFACC----- -------AAAAAIIIIIIAAAAA------- -------AAAAAAAAAAAAAAAA------- --------CCAAAAAAAAAACC-------- ----------AAAAAAAAAA---------- ----------AAAAAAAAAA---------- ------------CCCCCC------------ ------------------------------ ------------------------------ ------------------------------ ------------------------------ ------------------------------ 
------------------------------ ------------------------------ -EBB----------------------BBE- --BB----------------------BB-- --BB----------------------BB-- --BB----------------------BB-- --EE----------------------EE-- ----B--------------------B---- ----B--------------------B---- ----B--------------------B---- ----B--------------------B---- ----B--------------------B---- ----B--------------------B---- ----B--------------------B---- ----EBB----------------BBE---- -----AB----------------BA----- -----CAFFF----------FFFAC----- ------AAAAIIIIIIIIIIAAAA------ ------AAAAAAAAAAAAAAAAAA------ -------CAAAAAAAAAAAAAAC------- --------AAAAAAAAAAAAAA-------- --------AAAAAAAAAAAAAA-------- ----------CCCAAAACCC---------- -------------AAAA------------- ------------------------------ ------------------------------ ------------------------------ ------------------------------ 
------------------------------ ------------------------------ -EB------------------------BE- --B------------------------B-- --B------------------------B-- --B------------------------B-- --E------------------------E-- ---B----------------------B--- ---B----------------------B--- ---B----------------------B--- ---B----------------------B--- ---B----------------------B--- ---B----------------------B--- ---B----------------------B--- ---EBB------------------BBE--- ----AB------------------BA---- ----CAFFF------------FFFAC---- -----AAAAIIII----IIIIAAAA----- -----AAAAAAAAHHHHAAAAAAAA----- -------CAAAAAAAAAAAAAAC------- --------AAAAAAAAAAAAAA-------- --------AAAAAAAAAAAAAA-------- ---------CAAAAAAAAAAC--------- ----------AAAAAAAAAA---------- ------------------------------ ------------------------------ ------------------------------ ------------------------------ 
------------------------------ ------------------------------ -EB------------------------BE- --B------------------------B-- --B------------------------B-- --B------------------------B-- --E------------------------E-- ---B----------------------B--- ---B----------------------B--- ---B----------------------B--- ---B----------------------B--- ---B----------------------B--- ---B----------------------B--- ---B----------------------B--- ---EBB------------------BBE--- ----AB------------------BA---- ----CAFF--------------FFAC---- -----AAAIII--------IIIAAA----- -----AAAAAAHHHHHHHHAAAAAA----- ------CAAAAAAAAAAAAAAAAC------ -------AAAAAAAAAAAAAAAA------- -------AAAAAAAAAAAAAAAA------- --------CAAAAAAAAAAAAC-------- ---------AAAAAAAAAAAA--------- ------------------------------ ------------------------------ ------------------------------ ------------------------------ 
------------------------------ ------------------------------ CCC------------------------CCC CCC------------------------CCC -CC------------------------CC- -CC------------------------CC- -CC------------------------CC- --B------------------------B-- --B------------------------B-- --B------------------------B-- --B------------------------B-- --B------------------------B-- --B------------------------B-- --B------------------------B-- --EBB--------------------BBE-- ---AB--------------------BA--- ---CAFFF--------------FFFAC--- ----AAAAII----------IIAAAA---- ----AAAAAAHHHHHHHHHHAAAAAA---- ------CAAAAAAAAAAAAAAAAC------ -------AAAAAAAAAAAAAAAA------- -------AAAAAAAAAAAAAAAA------- --------CAAAAAAAAAAAAC-------- ---------AAAAAAAAAAAA--------- ------------------------------ ------------------------------ ------------------------------ ------------------------------ 
------------------------------ ------------------------------ ------------------------------ ------------------------------ ------------------------------ ------------------------------ ------------------------------ -CB------------------------BC- -CB------------------------BC- -CB------------------------BC- --B------------------------B-- --B------------------------B-- --B------------------------B-- --B------------------------B-- --EBB--------------------BBE-- ---AB--------------------BA--- ---CAFF----------------FFAC--- ----AAAII------------IIAAA---- ----AAAAAHHHHHHHHHHHHAAAAA---- -----CAAAAAAAAAAAAAAAAAAC----- ------AAAAAAAAAAAAAAAAAA------ ------AAAAAAAAAAAAAAAAAA------ -------CCAAAAAAAAAAAACC------- ---------AAAAAAAAAAAA--------- -------------JJJJ------------- ------------------------------ ------------------------------ -------------JJJJ------------- 
------------------------------ ------------------------------ ------------------------------ ------------------------------ ------------------------------ ------------------------------ ------------------------------ ------------------------------ -C--------------------------C- -C--------------------------C- -C--------------------------C- --B------------------------B-- --B------------------------B-- --B------------------------B-- --EBB--------------------BBE-- ---AB--------------------BA--- ---CAFF----------------FFAC--- ----AAAII------------IIAAA---- ----AAAAAHHHHHHHHHHHHAAAAA---- -----CAAAAAAAAAAAAAAAAAAC----- ------AAAAAAAAAAAAAAAAAA------ ------AAAAAAAAAAAAAAAAAA------ -------CAAAAAAAAAAAAAAC------- --------AAAAAAAAAAAAAA-------- ------------JJJJJJ------------ -------------JJJJ------------- -------------JJJJ------------- ------------JJJJJJ------------ 
------------------------------ ------------------------------ ------------------------------ ------------------------------ ------------------------------ ------------------------------ ------------------------------ ------------------------------ ------------------------------ -C--------------------------C- -C--------------------------C- -C--------------------------C- --B------------------------B-- --B------------------------B-- --EBB--------------------BBE-- ---AB--------------------BA--- ---CAFF----------------FFAC--- ----AAAII------------IIAAA---- ----AAAAAHHHHHHHHHHHHAAAAA---- -----CAAAAAAAAAAAAAAAAAAC----- ------AAAAAAAAAAAAAAAAAA------ ------AAAAAAAAAAAAAAAAAA------ -------CAAAAAAAAAAAAAAC------- --------AAAAAAAAAAAAAA-------- ------------JJJJJJ------------ -------------JJJJ------------- -------------JJJJ------------- ------------JJJJJJ------------ 
------------------------------ ------------------------------ ------------------------------ ------------------------------ ------------------------------ ------------------------------ ------------------------------ ------------------------------ ------------------------------ ------------------------------ -C--------------------------C- -C--------------------------C- -C--------------------------C- --B------------------------B-- --EBB--------------------BBE-- ---AB--------------------BA--- ---CAFF----------------FFAC--- ----AAAII------------IIAAA---- ----AAAAAHHHHHHHHHHHHAAAAA---- -----CAAAAAAAAAAAAAAAAAAC----- ------AAAAAAAAAAAAAAAAAA------ ------AAAAAAAAAAAAAAAAAA------ -------CAAAAAAAAAAAAAAC------- --------AAAAAAAAAAAAAA-------- ------------JJJJJJ------------ -------------JJJJ------------- -------------JJJJ------------- ------------JJJJJJ------------ 
------------------------------ ------------------------------ ------------------------------ ------------------------------ ------------------------------ ------------------------------ ------------------------------ ------------------------------ ------------------------------ ------------------------------ ------------------------------ -C--------------------------C- -C--------------------------C- -C--------------------------C- -EEBB--------------------BBEE- ---AB--------------------BA--- ---CAFF----------------FFAC--- ----AAAII------------IIAAA---- ----AAAAAHHHHHHHHHHHHAAAAA---- -----CAAAAAAAAAAAAAAAAAAC----- ------AAAAAAAAAAAAAAAAAA------ ------AAAAAAAAAAAAAAAAAA------ -------CCAAAAAAAAAAAACC------- ---------AAAAAAAAAAAA--------- -------------JJJJ------------- ------------------------------ ------------------------------ -------------JJJJ------------- 
------------------------------ ------------------------------ ---LLLL----------------LLLL--- ------------------------------ ------------------------------ ------------------------------ ------------------------------ ------------------------------ ------------------------------ ------------------------------ ------------------------------ ------------------------------ ------------------------------ -C--------------------------C- -EEBB--------------------BBEE- ---AB--------------------BA--- ---CAFFF--------------FFFAC--- ----AAAAII----------IIAAAA---- ----AAAAAAHHHHHHHHHHAAAAAA---- ------CAAAAAAAAAAAAAAAAC------ -------AAAAAAAAAAAAAAAA------- -------AAAAAAAAAAAAAAAA------- --------CAAAAAAAAAAAAC-------- ---------AAAAAAAAAAAA--------- ------------------------------ ------------------------------ ------------------------------ ------------------------------ 
----GG------------------GG---- ----GG------------------GG---- ---LGGL----------------LGGL--- ----GG------------------GG---- ----GG------------------GG---- ----GG------------------GG---- ----GG------------------GG---- ----GG------------------GG---- ----GG------------------GG---- ----GG------------------GG---- ----GG------------------GG---- ----GG------------------GG---- D---GG------------------GG---D DDD-GG------------------GG-DDD ---DAA------------------AAD--- ----AA------------------AA---- ----CAFF--------------FFAC---- -----AAAIII--------IIIAAA----- -----AAAAAAHHHHHHHHAAAAAA----- ------CAAAAAAAAAAAAAAAAC------ -------AAAAAAAAAAAAAAAA------- -------AAAAAAAAAAAAAAAA------- --------CAAAAAAAAAAAAC-------- ---------AAAAAAAAAAAA--------- ------------------------------ ------------------------------ ------------------------------ ------------------------------ 
----GG------------------GG---- ----GG------------------GG---- ---LGGL----------------LGGL--- ----GG------------------GG---- ----GG------------------GG---- ----GG------------------GG---- ----GG------------------GG---- ----GG------------------GG---- ----GG------------------GG---- ----GG------------------GG---- ----GG------------------GG---- ----GG------------------GG---- -DD-GG------------------GG-DD- DDDDGG------------------GGDDDD DDDDAA------------------AADDDD ----AA------------------AA---- ----CAFFF------------FFFAC---- -----AAAAIII------IIIAAAA----- -----AAAAAAAHHHHHHAAAAAAA----- ------CAAAAAAAAAAAAAAAAC------ ----D--AAAAAAAAAAAAAAAA--D---- --DDD--AAAAAAAAAAAAAAAA--DDD-- --------CCAAAAAAAAAACC-------- ----------AAAAAAAAAA---------- ------------------------------ ------------------------------ ------------------------------ ------------------------------ 
------------------------------ ------------------------------ ---LLLL----------------LLLL--- ------------------------------ ------------------------------ ------------------------------ ------------------------------ ------------------------------ ------------------------------ ------------------------------ ------------------------------ ------------------------------ ------------------------------ -DDD----------------------DDD- DDDDDAA----------------AADDDDD DDDDDAA----------------AADDDDD ----DCAFFF----------FFFACD---- ----D-AAAAIIIIIIIIIIAAAA-D---- ----D-AAAAAAAAAAAAAAAAAA-D---- ----D--CAAAAAAAAAAAAAAC--D---- -DDDD---AAAAAAAAAAAAAA---DDDD- --DDD---AAAAAAAAAAAAAA---DDD-- ----------CCCAAAACCC---------- -------------AAAA------------- ------------------------------ ------------------------------ ------------------------------ ------------------------------ 
------------------------------ ------------------------------ ------------------------------ ------------------------------ ------------------------------ ------------------------------ ------------------------------ ------------------------------ ------------------------------ ------------------------------ ------------------------------ ------------------------------ ------------------------------ ------------------------------ -DDD-AAA--------------AAA-DDD- DDDDDAAA--------------AAADDDDD DDDDDCCAFFFF------FFFFACCDDDDD DDDDD--AAAAAIIIIIIAAAAA--DDDDD DDDDD--AAAAAAAAAAAAAAAA--DDDDD DDDDD---CCAAAAAAAAAACC---DDDDD -DDDD-----AAAAAAAAAA-----DDDD- ----------AAAAAAAAAA---------- ------------CCCCCC------------ ------------------------------ ------------------------------ ------------------------------ ------------------------------ ------------------------------ 
------------------------------ ------------------------------ ------------------------------ ------------------------------ ------------------------------ ------------------------------ ------------------------------ ------------------------------ ------------------------------ ------------------------------ ------------------------------ ------------------------------ ------------------------------ ------------------------------ ------AAA------------AAA------ -KKK--AAA------------AAA--KKK- K-K-K-CCAFFFFFFFFFFFFACC-K-K-K KKKKK---AAAAAAAAAAAAAA---KKKKK K-K-K---AAAAAAAAAAAAAA---K-K-K -KKK------CCAAAAAACC------KKK- ------------AAAAAA------------ ------------AAAAAA------------ ------------------------------ ------------------------------ ------------------------------ ------------------------------ ------------------------------ ------------------------------ 
------------------------------ ------------------------------ ------------------------------ ------------------------------ ------------------------------ ------------------------------ ------------------------------ ------------------------------ ------------------------------ ------------------------------ ------------------------------ ------------------------------ ------------------------------ ------------------------------ -------AAAA--------AAAA------- -------AAAA--------AAAA------- -------CCAAFFFFFFFFAACC------- ---------AAAAAAAAAAAA--------- ---------AAAAAAAAAAAA--------- ------------CCCCCC------------ ------------------------------ ------------------------------ ------------------------------ ------------------------------ ------------------------------ ------------------------------ ------------------------------ ------------------------------ 
------------------------------ ------------------------------ ------------------------------ ------------------------------ ------------------------------ ------------------------------ ------------------------------ ------------------------------ ------------------------------ ------------------------------ ------------------------------ ------------------------------ ------------------------------ ------------------------------ ---------AAAAAAAAAAAA--------- ---------AAAAAAAAAAAA--------- ---------CCAAAAAAAACC--------- -----------AAAAAAAA----------- -----------AAAAAAAA----------- ------------------------------ ------------------------------ ------------------------------ ------------------------------ ------------------------------ ------------------------------ ------------------------------ ------------------------------ ------------------------------ 
------------------------------ ------------------------------ ------------------------------ ------------------------------ ------------------------------ ------------------------------ ------------------------------ ------------------------------ ------------------------------ ------------------------------ ------------------------------ ------------------------------ ------------------------------ ------------------------------ -----------AAAAAAAA----------- -----------AAAAAAAA----------- -----------CCCCCCCC----------- ------------------------------ ------------------------------ ------------------------------ ------------------------------ ------------------------------ ------------------------------ ------------------------------ ------------------------------ ------------------------------ ------------------------------ ------------------------------ 
