model
size = 6 7 6, scale = 0.05, origin = -y
material 
  colors = A:#03F B:#03C C:#E70000 D:#800 E:#A00
voxels
AABCBA AABCBA AABCBA AABCBA AABCBA ------ ------ 
BBBCBB BAAAAB BAAAAB BAAAAB BBBABB ---E-- ------ 
CCCCCC CAAAAC CAAAAC CAAAAC CCAAAC --DCC- ---C-- 
BBBCBB BAAAAB BAAAAB BAAAAB BAAABB -CCD-- --C--- 
AABCBA AAAAAA AAAAAA AAAAAA ABACBA --E--- ------ 
AABCBA AABCBA AABCBA AABCBA AABCBA ------ ------ 
