model
size = 3 31 6, scale = 0.05, origin = -y
material 
  colors = A:#BBB B:#FFFF97 C:#7E5200
voxels
-A- --- --- --- --- --- -A- --- --- --- --- --- --- --- --- --- --- --- --- --- --- --- --- --- --- --- --- --- --- --- --- 
AAA --- --- --- --- --- AAA -B- -B- -B- -B- -B- -B- -B- -B- -B- -B- -B- -B- -B- -B- -B- -B- -B- -B- -B- -B- -B- --- --- --- 
AAA -C- -C- -C- -C- -C- AAA -A- -A- -A- -A- -A- -A- -A- -A- -A- -A- -A- -A- -A- -A- -A- -A- -A- -A- -A- -A- -A- -B- --- --- 
AAA -C- -C- -C- -C- -C- AAA -A- -A- -A- -A- -A- -B- -B- -B- -B- -B- -B- -B- -B- -B- -B- -B- -B- -B- -B- -B- -A- -A- -B- --- 
AAA --- --- --- --- --- AAA --- --- --- --- -A- -A- -A- -A- -A- -A- -A- -A- -A- -A- -A- -A- -A- -A- -A- -A- -A- -A- -A- -B- 
-A- --- --- --- --- --- -A- --- --- --- --- --- --- --- --- --- --- --- --- --- --- --- --- --- --- --- --- --- --- --- --- 
