model
size = 24 20 5, scale = 0.05, origin = -y
material 
  colors = A:#FC0 B:#F96 C:#FF0
voxels
-----B------------B----- ----ACA----------ACA---- ---BC-CB--------BC-CB--- --AC---CA------AC---CA-- -BC-----CB----BC-----CB- BC-------CB--BC-------CB AB-------BA--AB-------BA BC-------CB--BC-------CB AB--BCB--BA--AB--BCB--BA BC--CAC--CB--BC--CAC--CB AB--BCB--BA--AB--BCB--BA BAAAAAAAAAB--BAAAAAAAAAB -----A------------A----- ----BBB----------BBB---- ---BCCCB--------BCCCB--- --BCAAACB------BCAAACB-- --BCACACB------BCACACB-- --BCAAACB------BCAAACB-- ---BCCCB--------BCCCB--- ----BBB----------BBB---- 
------------------------ ------------------------ ------------------------ ------------------------ ------------------------ ------------------------ ------------------------ ------------------------ ------------------------ ------------------------ ------------------------ ------------------------ ------------------------ ------------------------ ------------------------ ------------------------ -----A------------A----- ------------------------ ------------------------ ------------------------ 
------------------------ ------------------------ ------------------------ ------------------------ ------------------------ ------------------------ ------------------------ ------------------------ ------------------------ ------------------------ ------------------------ ------------------------ ------------------------ ------------------------ -----A-A---------A-A---- ----ABABA-------ABABA--- -----A-A---------AAA---- ----ABABA-------ABABA--- -----A-A---------A-A---- ------------------------ 
------------------------ ------------------------ ------------------------ ------------------------ ------------------------ ------------------------ ------------------------ ------------------------ ------------------------ ------------------------ ------------------------ ------------------------ ------------------------ ------------------------ -----ABA---------ABA---- ----AAAAA-------AAAAA--- ----BA-AB-------BAAAB--- ----AAAAA-------AAAAA--- -----ABA---------ABA---- ------------------------ 
------------------------ ------------------------ ------------------------ ------------------------ ------------------------ ------------------------ ------------------------ ------------------------ ------------------------ ------------------------ ------------------------ ------------------------ ------------------------ ------------------------ ------------------------ ------------------------ -----A------------A----- ------------------------ ------------------------ ------------------------ 
