model
size = 5 7 7, scale = 0.05, origin = -y
material 
  colors = A:#FF0 B:#BBB C:#F96
voxels
----- ----- A-C-A B---B A-C-A ----- ----- 
----- -ABA- ----- ----- ----- -ABA- ----- 
A-C-A ----- ----- ----- ----- ----- A-C-A 
B---B ----- ----- ----- ----- ----- B---B 
A-C-A ----- ----- ----- ----- ----- A-C-A 
----- -ABA- ----- ----- ----- -ABA- ----- 
----- ----- A-C-A B---B A-C-A ----- ----- 
