model
size = 13 16 18, scale = 0.05, origin = -y
material 
  colors = A:#020 B:#111 C:#FFF D:#6C0 E:#E00 F:#FF0 G:#360
voxels
AA---AAA---AA -A---ABA---A- ------B------ ------B------ -----BBB----- -----BBB----- -----B-B----- -----B-B----- -----BBB----- ------B------ ------------- ------------- ------------- ------------- ------------- ------------- 
AAAA-AAA-AAAA -AAA-AAA-AAA- ------------- ------------- ------------- ------------- ------------- ------------- ------------- ------------- ------------- ------------- ------------- ------------- ------------- ------------- 
AAAAAAAAAAAAA -AAAAAAAAAAA- ------------- ------------- ------------- ------------- ------------- ------------- ------------- ------------- ------------- ------------- ------------- ------------- ------------- ------------- 
AAAAAAAAAAAAA -AAAAAAAAAAA- ----BBBBB---- ----BBBBB---- ------------- ------------- ------------- ------------- ------------- ------------- ------------- ------------- ------------- ------------- ------------- ------------- 
AAAAAAAAAAAAA -AAAAAAAAAAA- ---BBBBBBB--- ---BBCBCBB--- ------------- ------------- ------------- ------------- ------------- ------------- ------------- ------------- ------------- ------------- ------------- ------------- 
AAAAAAAAAAAAA -AAAAAAAAAAA- --BBBBBBBBB-- --BBCCBCCBB-- ------------- ------------- ------------- ------------- ------------- ------------- ------------- ------------- ------------- ------------- ------------- ------------- 
AAAAAAAAAAAAA -AAAAAAAAAAA- --BBBBBBBBB-- --BCCCBCCCB-- ------------- ------------- ------------- ------------- ------------- ------------- ------------- ------------- ------------- ------------- ------------- ------------- 
AAAAAAAAAAAAA -AAAAAAAAAAA- --BBBBBBBBB-- --BDCCDCCDB-- ------------- ------------- ------------- ------------- ------------- ------------- ------------- ------------- ------------- ------------- ------------- ------------- 
AAAAAAAAAAAAA -AAAAAAAAAAA- --BBBBBBBBB-- --BCCCECCCB-- ------------- ------------- ------------- ------------- ------------- ------------- ------------- ------------- ------------- ------------- ------------- ------------- 
AAAAAAAAAAAAA -AAAAAAAAAAA- --BBBBBBBBB-- --BBCCECCBB-- ------------- ------------- ------------- ------------- ------------- ------------- ------------- ------------- ------------- ------------- ------------- ------------- 
AAAAAAAAAAAAA -AAAAAAAAAAA- ---BBBBBBB--- ---BBCECBB--- ------------- ------------- ------------- ------------- ------------- ------------- ------------- ------------- ------------- ------------- ------------- ------------- 
AAAAAAAAAAAAA -AAAAAAAAAAA- ----BBBBB---- ----BFBBB---- ------------- ------------- ------------- ------------- ------------- ------------- ------------- ------------- ------------- ------------- ------------- ------------- 
AAAAAAAAAAAAA -AAAAAAAAAAA- ------------- ------------- ------------- ------------- ------------- ------------- ------------- ------------- ------------- ------------- ------------- ------------- ------------- ------------- 
AAA-A---A-AAA -AA-A---A-AA- ------------- ------------- ------------- ------------- ------------- ------------- ------------- ------------- ------------- ------------- ------------- ------------- ------------- ------------- 
----A---A---- ----AAGAA---- ------------- ------------- ------------- ------------- ------------- ------------- ------------- ------------- ------------- ------------- ------------- ------------- ------------- ------------- 
------------- ------------- -----A-A----- -AAAAAAA----- -AAAAAAAA---- -AAA-----A--- -AA-------A-- -A---------A- -A---------A- -A---------A- -A---------A- -A---------A- --A-------A-- ---A-----A--- ----AAAAA---- -----AAA----- 
------------- ------------- AAA---------- AAAAAAAA----- AAAAAAAAA---- AAAA-----A--- AAA-------A-- AA---------A- AA---------A- AA---------A- AA---------A- AA---------A- AAA-------A-- AAAA-----A--- AAAAAAAAA---- -----AAA----- 
------------- ------------- ------------- ------------- ------------- ----AAAAA---- ---AAAAAAA--- --AAAAAAAAA-- --AAAAAAAAA-- --AAAA-AAAA-- --AAAA-AAAA-- --AAAA-AAAA-- ---AAA-AAA--- ----AA-AA---- ------------- ------------- 
