model
size = 31 14 29, scale = 0.05, origin = -y
material 
  colors = A:#FF6905 B:#FE3C00 C:#0A0000 D:#F6D644 E:#F28214 F:#F2AB14 G:#F29114 H:#FAEB88 I:#FDF4B9 J:#F3BC27 K:#FF5705 L:#B9E7FD M:#4AA7F6 N:#1352F1 O:#FF3A05 P:#1224B0 Q:#F23914 R:#ED2707 S:#030303
voxels
---------CCCCC---CCCCC--------- -------------CC-CC------------- --------------C-C-------------- --------------CCC-------------- ---------------C--------------- ------------------------------- ------------------------------- ------------------------------- ------------------------------- ------------------------------- ------------------------------- ------------------------------- ------------------------------- ---------CCCCCCCCCCCCC--------- 
------CCCCBBBB---BBBBCCCC------ ------C--FGEACB-BCAEGF--C------ --------JFGEAKB-BKAEGFJ-------- -------DJFGEAKCBCKAEGFJD------- ------HDJFGEAKOCOKAEGFJDH------ ------HDJFGEAKOROKAEGFJDH------ ------HDJFGEAKOROKAEGFJDH------ ------HDJFGEAKOROKAEGFJDH------ ------HDJFGEAKOROKAEGFJDH------ ------HDJFGEAKOROKAEGFJDH------ -------DJFGEEAKOKAEEGFJD------- --------JFGEEAKOKAEEGFJ-------- ---------JFGEAKOKAEGFJ--------- -------CCBBBBBBBBBBBBBCC------- 
------CCBBBBBB---BBBBBBCC------ ----CCCJJFGEACB-BCAEGFJJCCC---- ------DJJFGEAKB-BKAEGFJJD------ -----HDDJFGEAKCBCKAEGFJDDH----- -----HHDJFGEAKOCOKAEGFJDHH----- -----IHDJFGEAKOROKAEGFJDHI----- -----IHDJFGEAKOROKAEGFJDHI----- -----IHDJFGEAKOROKAEGFJDHI----- -----IHDJFGEAKOROKAEGFJDHI----- -----IHDJFGEAKOROKAEGFJDHI----- -----IHDJFGEEAKOKAEEGFJDHI----- ------HDJFGEEAKOKAEEGFJDH------ -------HDJFGEAKOKAEGFJDH------- -----CCCBBBBBBBBBBBBBBBCCC----- 
------BBBBBBBB---BBBBBBBB------ ---CCBCDDAAAACB-BCAAAADDCBCC--- ---CIHHDAAAAAAB-BAAAAAADHHIC--- ----IHHDAAAAAAABAAAAAAADHHI---- ----IHHDAAAAAAAAAAAAAAADHHI---- ----LIHDAAAAAAAAAAAAAAADHIL---- ----LIHDAAAAAAAAAAAAAAADHIL---- ----LIHDAAAAAAAAAAAAAAADHIL---- ----LIHDAAAAAAAAAAAAAAADHIL---- ----LIHDAAAAAAAAAAAAAAADHIL---- ----LIHDAAAAAAAAAAAAAAADHIL---- -----IHDDAAAAAAAAAAAAADDHI----- ---C-IHHDDAAAAAAAAAAADDHHICC--- ----CCBBBBBBBBBBBBBBBBBBBCC---- 
------BBBBBBBB---BBBBBBBB------ ---BBBCAAAAAACB-BCAAAAAACBBB--- --CCAAAAAAAAAAB-BAAAAAAAAAACC-- ---LAAAAAAAAAAABAAAAAAAAAAAL--- ---LAAAAAAAAAAAAAAAAAAAAAAAL--- ---LAAAAAAAAAAAAAAAAAAAAAAAL--- ---MAAAAAAAAAAAAAAAAAAAAAAAM--- ---MAAAAAAAAAAAAAAAAAAAAAAAM--- ---MAAAAAAAAAAAAAAAAAAAAAAAM--- ---MAAAAAAAAAAAAAAAAAAAAAAAM--- ---MAAAAAAAAAAAAAAAAAAAAAAAM--- --CMLAAAAAAAAAAAAAAAAAAAAALMC-- --CCLAAAAAAAAAAAAAAAAAAAAACCC-- ----BBBBBBBBBBBBBBBBBBBBBBB---- 
------BBBBBBBB---BBBBBBBB------ ---BBBCAAAAAACB-BCAAAAAACBBB--- -CCCAAAAAAAAAAB-CAAAAAAAAAACCC- -CMAAAAAAAAAAAABAAAAAAAAAAAAMC- --MAAAAAAAAAAQAAAQAAAAAAAAAAM-- --NAAAAAAAAAAQRARQAAAAAAAAAAN-- --NAAAAAAAAAAQQRQQAAAAAAAAAAN-- --NAAAAAAAAAAAQRQAAAAAAAAAAAN-- --NAAAAAAAAAAAQRQAAAAAAAAAAAN-- --NAAAAAAAAAAAQRQAAAAAAAAAAAN-- -CNAAAAAAAAAAAAQAAAAAAAAAAAANC- -CCAAAAAAAAAAAAQAAAAAAAAAAAACC- --BBCAAAAAAAAAAAAAAAAAAAAABBB-- ----BBBBBBBBBBBBBBBBBBBBBBB---- 
------BBBBBBBB---BBBBBBBB------ ---BBBCAAAAAABB-BCAAAAAACBBB--- -BBCAAAAAAAEAAB-BAAEAAAAAAACBB- CCAAAAAAAAAEAACBCAAEAAAAAAAAACC -PAAAAAAAAAEA-CCC-AEAAAAAAAAAP- -PAAAAAAAAAEA--C--AEAAAAAAAAAP- -PAAAAAAAAAGE-----EGAAAAAAAAAP- -PAAAAAAAAAGE-----EGAAAAAAAAAP- -PAAAAAAAAAGE-----EGAAAAAAAAAP- -PAAAAAAAAAGE-----EGAAAAAAAAAP- CCAAAAAAAAAGE-----EGAAAAAAAAACC -BCAAAAAAAAGE-----EGAAAAAAAABB- --BBCAAAAAAAACCCCCAAAAAAAABBB-- ----BBBBBBBBBBBBBBBBBBBBBBB---- 
------BBBBBBBB---BBBBBBBB------ ---BBBCAAAACCCB-BCCCAAAACBBB--- -BBCAAAADFG---B-B---GFDAAAACBB- CCAAAAAADFG---CBC---GFDAAAAAACC CCAAAAAADFG---CCC---GFDAAAAAACC CCAAAAAADFG----C----GFDAAAAAACC CCAAAAAAIDF---------FDIAAAAAACC CCAAAAAAIDF---------FDIAAAAAACC CCAAAAAAIDF---------FDIAAAAAACC CCAAAAAAIDF---------FDIAAAAAACC CCAAAAAAIDF---------FDIAAAAAACC -BCAAAAAIDF---------FDIAAAAACB- --BBCAAAAAACCCCCCCCCAAAAAABBB-- ----BBBBBBBCCCCCCCCCBBBBBBB---- 
------BBBBBBBB---BBBBBBBB------ ---BBBCACCCCCCB-BCCCCCCACBBB--- -BBCNMLI------B-B------ILMNCBB- -BAANMLI------CBC------ILMNAAB- -BAANMLI------CCC------ILMNAAB- -BAANMLI-------C-------ILMNAAB- -BAAPNML---------------LMNPAAB- -BAAPNML---------------LMNPAAB- -BAAPNML---------------LMNPAAB- -BAAPNML---------------LMNPAAB- -BAAPNML---------------LMNPAAB- -BCAPNML---------------LMNPABB- --BBCAAACCCC-------CCCCAAAABB-- ----BBBBCCCC-------CCCCBBBB---- 
------CCCCCCCC---CCCCCCCC------ ---CCCCCCC---CC-CC---CCCCCCC--- -CCCC---------C-C---------CCCC- -BBS----------CCC----------SBB- --CC-----------C-----------CC-- -BBC-----------------------CBB- --CC-----------------------CC-- -BBC-----------------------CBB- --CC-----------------------CC-- -BBC-----------------------CBB- -CSC-----------------------CCC- -CCCC---------------------CSCC- --CCCCCCC-------------CCCCCCC-- ----CCCCC-------------CCCCC---- 
------------------------------- ------------------------------- ------------------------------- -B---------------------------B- -B---------------------------B- -B---------------------------B- -B---------------------------B- -B---------------------------B- -B---------------------------B- -B---------------------------B- ------------------------------- ------------------------------- ------------------------------- ------------------------------- 
------------------------------- ------------------------------- ------------------------------- -B---------------------------B- -C---------------------------C- -C---------------------------C- -C---------------------------C- -B---------------------------C- -C---------------------------C- -B---------------------------B- ------------------------------- ------------------------------- ------------------------------- ------------------------------- 
------------------------------- ------------------------------- ------------------------------- -B---------------------------B- -C---------------------------C- -B---------------------------B- -C---------------------------B- -B---------------------------B- -C---------------------------C- -B---------------------------B- ------------------------------- ------------------------------- ------------------------------- ------------------------------- 
------------------------------- ------------------------------- ------------------------------- -B---------------------------B- -C---------------------------C- -B---------------------------B- -C---------------------------B- -C---------------------------B- -C---------------------------C- -B---------------------------B- ------------------------------- ------------------------------- ------------------------------- ------------------------------- 
------------------------------- ------------------------------- ------------------------------- -B---------------------------B- -B---------------------------B- -B---------------------------B- -B---------------------------B- -B---------------------------B- -B---------------------------B- -B---------------------------B- ------------------------------- ------------------------------- ------------------------------- ------------------------------- 
------------------------------- ------------------------------- ------------------------------- -B---------------------------B- -C---------------------------C- -B---------------------------C- -B---------------------------C- -B---------------------------C- -B---------------------------C- -B---------------------------B- ------------------------------- ------------------------------- ------------------------------- ------------------------------- 
------------------------------- ------------------------------- ------------------------------- -B---------------------------B- -C---------------------------B- -B---------------------------B- -B---------------------------C- -B---------------------------B- -B---------------------------C- -B---------------------------B- ------------------------------- ------------------------------- ------------------------------- ------------------------------- 
------------------------------- ------------------------------- ------------------------------- -B---------------------------B- -C---------------------------C- -C---------------------------C- -C---------------------------B- -C---------------------------C- -C---------------------------C- -B---------------------------B- ------------------------------- ------------------------------- ------------------------------- ------------------------------- 
------------------------------- ------------------------------- ------------------------------- -B---------------------------B- -B---------------------------B- -B---------------------------B- -B---------------------------B- -B---------------------------B- -B---------------------------B- -B---------------------------B- ------------------------------- ------------------------------- ------------------------------- ------------------------------- 
------------------------------- ------------------------------- ------------------------------- -B---------------------------B- -C---------------------------B- -B---------------------------B- -C---------------------------C- -B---------------------------C- -C---------------------------C- -B---------------------------B- ------------------------------- ------------------------------- ------------------------------- ------------------------------- 
------------------------------- ------------------------------- ------------------------------- -BB-------------------------BB- -CC-------------------------CC- -BC-------------------------CC- -CC-------------------------CC- -BC-------------------------BB- -CC-------------------------BB- -BB-------------------------BB- ------------------------------- ------------------------------- ------------------------------- ------------------------------- 
------------------------------- ------------------------------- ------------------------------- --BB-----------------------BB-- --CB-----------------------BB-- --CB-----------------------BB-- --CB-----------------------BC-- --CB-----------------------CC-- --CB-----------------------CC-- --BB-----------------------BB-- ------------------------------- ------------------------------- ------------------------------- ------------------------------- 
------------------------------- ------------------------------- ------------------------------- ---BB---------------------BB--- ---BC---------------------BB--- ---BC---------------------BB--- ---BB---------------------BB--- ---BC---------------------BB--- ---BC---------------------BB--- ---BB---------------------BB--- ------------------------------- ------------------------------- ------------------------------- ------------------------------- 
------------------------------- ------------------------------- ------------------------------- ----BB-------------------BB---- ----CB-------------------CC---- ----CC-------------------CC---- ----BC-------------------CC---- ----CC-------------------CC---- ----CB-------------------CC---- ----BB-------------------BB---- ------------------------------- ------------------------------- ------------------------------- ------------------------------- 
------------------------------- ------------------------------- ------------------------------- -----BB-----------------BB----- -----BC-----------------BB----- -----CC-----------------BB----- -----CB-----------------CC----- -----CC-----------------CB----- -----BC-----------------CC----- -----BB-----------------BB----- ------------------------------- ------------------------------- ------------------------------- ------------------------------- 
------------------------------- ------------------------------- ------------------------------- ------BB---------------BB------ ------CB---------------BB------ ------CB---------------BB------ ------BB---------------BC------ ------CB---------------BC------ ------CB---------------BC------ ------BB---------------BB------ ------------------------------- ------------------------------- ------------------------------- ------------------------------- 
------------------------------- ------------------------------- ------------------------------- -------BB-------------BB------- -------BC-------------BB------- -------BC-------------BB------- -------BC-------------BB------- -------BC-------------BB------- -------BC-------------CB------- -------BB-------------BB------- ------------------------------- ------------------------------- ------------------------------- ------------------------------- 
------------------------------- ------------------------------- ------------------------------- --------BBB---------BBB-------- --------CCC---------BCB-------- --------CBC---------BCB-------- --------CBC---------BCB-------- --------CBC---------BCB-------- --------CCC---------CCC-------- --------BBB---------BBB-------- ------------------------------- ------------------------------- ------------------------------- ------------------------------- 
------------------------------- ------------------------------- ------------------------------- ----------BBBBBBBBBBB---------- ----------CBBCBBCCCBB---------- ----------CBCBCBCBCBB---------- ----------CBCBCBCBCBB---------- ----------CBCBCBCBCBB---------- ----------CBCBCBCCCBC---------- ----------BBBBBBBBBBB---------- ------------------------------- ------------------------------- ------------------------------- ------------------------------- 
