model
size = 20 32 20, scale = 0.05, origin = -y
material 
  colors = A:#E00 B:#30F C:#111 D:#FC9 E:#3C3 F:#FFF G:#800 H:#FF0 I:#F6C J:#6C0 K:#F03 L:#F0C M:#A00
voxels
107-A4FA14-2F2J2F14-FJ2FJF14-FK2FLF14-KHKLHL14-FK2FLF14-2D2F2(2D14-2D2A)2D14-D4AD14-6A14-AB2ABA14-2A2B2A14-6B354-6A12-2(10A10-)4(2F6A2F10-)GD6ADG10-ED6ADE10-GD6ADG4(10-10A)10-AB6ABA12-6D14-2D2A2D234-6C54-6A12-10A8-6(14A6-)2G10A2G6-2E10A2E6-EG10AGE6-G12AG4(6-14A)8-BD6ADB10-2D6A2D12-D4MD14-2D2A2D2(14-6D)15-B2DB17-2D114-10C12-6C14-6A12-10A9-12A6-6(16A4-)G14AG3(4-E14AE)4-G14AG3(4-16A)6-12A8-B10AB9-2(2D6A2D10-)2I6A2I10-2I6A2I11-2D4A2D12-3D2A3D13-2C2D2C16-2H73-12C10-8C12-8A10-12A7-14A5-6(16A4-)G14AG4(4-E14AE)4-G14AG2(4-16A)5-14A6-B12AB7-4(D10AD8-)BD8ADB9-D8AD10-BH6ADB11-B2H2A2HB14-B2HB51-14C8-10C10-10A8-14A5-16A3-6(18A2-)F16AF2-G16AG4(2-E16AE)2-G16AG2-18A3-16A4-16A5-3(B12AB6-)B12AB7-2(B10AB8-)B10AB9-B8AB11-3B2A3B15-2B32-14C7-12C8-12A7-14A5-16A3-6(18A2-)F16AF2-G16AG5(2-E16AE)2-G16AG3-16A4-16A5-14A5(6-B12AB)7-B10AB8-B10AB9-2B6A2B12-6B29-16C5-14C6-14A5-16A3-18A-120AF18AF20AG18AGE4(18A2E)18AE-G16AG2-18A3-16A3(4-B14AB)5-2(B12AB6-)B12AB7-B10AB9-B8AB11-3B2A3B15-2B11-16C5-14C6-14A5-16A3-18A-120AF18AF40AG18AGE3(18A2E)18AE-E16AE2-G16AG3-16A4(4-B14AB)5-B12AB6-B12AB7-B10AB8-2B8A2B10-2B4A2B14-4B10-16C5-14C6-14A5-16A3-18A-120AF18AF60AG18AGE2(18A2E)18AE-E16AE2-E16AE3-G14AG5(4-B14AB)5-B12AB6-B12AB7-B10AB9-2B6A2B12-6B9-16C5-14C6-14A5-16A3-18A-120AF18AF80AG18AGE18A2E18AE-E16AE2-E16AE3-G14AG5(4-B14AB)5-B12AB6-B12AB7-B10AB9-2B6A2B12-6B9-16C5-14C6-14A5-16A3-18A-120AF18AF100AG18AGE18AE-E16AE2-G16AG3-16A4(4-B14AB)5-B12AB6-B12AB7-B10AB8-2B8A2B10-2B4A2B14-4B10-16C5-14C6-14A5-16A3-18A-120AF18AF120AG18AG-G16AG2-18A3-16A3(4-B14AB)5-2(B12AB6-)B12AB7-B10AB9-B8AB11-3B2A3B15-2B12-14C7-12C8-12A7-14A5-16A3-6(18A2-)F16AF7(2-18A)3-16A4-16A5-14A5(6-B12AB)7-B10AB8-B10AB9-2B6A2B12-6B30-14C8-10C10-10A8-14A5-16A3-6(18A2-)F16AF7(2-18A)3-16A4-16A5-14A3(6-B12AB)7-2(B10AB8-)B10AB9-B8AB11-3B2A3B15-2B33-12C10-8C12-8A10-12A7-14A5-6(16A4-)F14AF7(4-16A)5-14A6-14A7-12A3(8-B10AB)8-2B8A2B9-B8AB10-2B6A2B11-3B2A3B14-4B53-10C12-6C14-6A12-10A9-12A6-6(16A4-)F14AF7(4-16A)6-12A8-12A9-3(2B6A2B10-)2B6A2B11-2B4A2B12-3B2A3B13-6B16-2B76-6C54-6A12-10A8-6(14A6-)2F10A2F7(6-14A)8-10A10-AB6ABA12-3(6B14-)6B15-4B17-2B196-6A12-6(10A10-)2F6A2F7(10-10A)12-6B14-6B334-4(6A14-)AF2AFA14-2A2F2A14-6F4(14-6A)2(14-2A2B2A)14-A4BA267-
