model
size = 19 26 16, scale = 0.05, origin = -y
material 
  colors = A:#FF0 B:#E00 C:#306 D:#60C E:#303 F:#3CC G:#111 H:#609 I:#EEE J:#888
voxels
------A-----C------ -------C---A------- --------A-C-------- ------------------- --------A-A-------- -------A---A------- ------A-----A------ ------A-----A------ C-----A-A-A-A-----C -A---AAA---AAC---A- --C-A-A-A-A-A-A-C-- ------A-----A------ A-----A-----A-----A -C---A-A---A-A---C- --A-C---A-A---C-A-- --------AAA-------- -----A-A---A-A----- ----AAA-I-I-AAA---- ---A-AA-----AAAA--- ---A-----A-----A--- ---AA--J-A-J--AA--- ----AA--AAA--AA---- -----AAA---AAA----G -----G-------G---G- G---G---------G-G-- -G-G--------------- 
------C-----A------ -------A---C------- --------C-A-------- ------------------- --------C-H-------- -------CCCCH------- ------CCCCCCC------ ------CCCCCCC------ A-----CCCCCCC-----A -C---AAACCCAAA---C- --A-H-ACACACA-C-A-- ------ACCCCCA------ C-----ACCCCCA-----C -A---H-ACCCA-H---A- --C-A---ACA---A-C-- --------AAA-------- -----A-ACCCA-A----- ----AAACFCFCAAA---- ---ACAACCCCCAAAA--- --CACCCCCACCCCCAC-- ---AACCFCACFCCAA--- ----AACCAAACCAA---- -----AAA---AAA----- ------------------- ------------------- ------------------- 
------------------- ------------------- ------------------- ------------------- --------A-A-------- -------ADDDA------- ------ADDDDDA------ ------ADDDDDA------ ------ADADADA------ ------AADDDAA------ ------ADADADA------ ------ADDDDDA------ ------ADDDDDA------ -------AAAAA------- --------AAA-------- --------AAA-------- -----A-AAAAA-A----- ----AAAFFFFFAAA---- ---AFAAFFFFFAAAA--- ---AFFFFFAFFFFFA--- ---CAFFFFAFFFFAC--- ----AAFFAAAFFAA---- -----AAA---AAA----- ------------------- ------------------- ------------------- 
------------------- ------------------- ------------------- ------------------- ------------------- --------CDC-------- -------DDDDD------- -------DCDCD------- -------D-D-D------- -------EDDDE------- -------D-D-D------- -------DDDDD------- -------DDDDD------- ------------------- ------------------- ------------------- ------------------- ----AAAAAAAAAAA---- ---AAAAAAAAAAAAA--- ---CADDDDADDDDAC--- ---CADDDDADDDDAC--- ----AADDAAADDAA---- -----AAA---AAA----- ------------------- ------------------- ------------------- 
------------------- ------------------- ------------------- ------------------- ------------------- ------------------- -------D-C-D------- -------D---D------- -------E-C-E------- -------EDDDE------- -------E-C-E------- -------EDDDE------- -------EDCDE------- -------E---E------- -------E---E------- -----EEE---EEE----- ------------------- ------------------- ------------------- ------------------- ------------------- ------------------- ------------------- ------------------- ------------------- ------------------- 
------------------- ------------------- ------------------- ------------------- ------------------- ------------------- ------------------- ------------------- ------------------- -----EEE---EEE----- -------E---E------- -------E---E------- -------EA-AE------- ------------------- ------------------- -----E-------E----- ------------------- ------------------- ------------------- ------------------- ------------------- ------------------- ------------------- ------------------- ------------------- ------------------- 
------------------- ------------------- ------------------- ------------------- ------------------- ------------------- ------------------- ------------------- ------------------- -----E-------E----- ------------------- ------------------- --------A-A-------- ------------------- ------------------- -----E-------E----- ------------------- ------------------- ------------------- ------------------- ------------------- ------------------- ------------------- ------------------- ------------------- ------------------- 
------------------- ------------------- ------------------- ------------------- ------------------- ------------------- ----A-A-----A-A---- ---A---A---A---A--- --A-BBB-A-A-BBB-A-- ----BBB-----BBB---- --A-----A-A-----A-- ---A---A---A---A--- ----A-A-A-A-A-A---- ----A-A-----A-A---- ---A---A---A---A--- --A--E--A-A--E--A-- ----BBB-----BBB---- --A-BBB-A-A-BBB-A-- ---A---A---A---A--- ----A-A-----A-A---- ------------------- ------------------- ------------------- ------------------- ------------------- ------------------- 
------------------- ------------------- ------------------- ------------------- ------------------- ------------------- ----A-A-----A-A---- ---A---A---A---A--- --A---BBA-A-BBBBA-- ---BBB-----BBBB---- --A--E--A-A--E--A-- ---A-EEEE-EEEE-A--- ----A-A-E-E-A-A---- ----A-A-E-E-A-A---- ---A---AE-EA---A--- --A--EEEE-EEEE--A-- ----BBB-----BBB---- --A-BBB-A-A-BBB-A-- ---A---A---A---A--- ----A-A-----A-A---- ------------------- ------------------- ------------------- ------------------- ------------------- ------------------- 
------------------- ------------------- ------------------- ------------------- ------------------- ------------------- ------------------- ------------------- ---B---B---B--BB--- ---B-B-----BBB----- ------------------- ------------------- ------------------- ------------------- ------------------- ------------------- ----BBB------BBB--- ----BBB----BB------ ------------------- ------------------- ------------------- ------------------- ------------------- ------------------- ------------------- ------------------- 
------------------- ------------------- ------------------- ------------------- ------------------- ------------------- ------------------- ------------------- ---B---B---B---B--- -----B-----B-B----- -----B-------B----- ------------------- ------------------- ------------------- ------------------- ------------------- -----BBB-----B-B--- ---BB------B---B--- ------------------- ------------------- ------------------- ------------------- ------------------- ------------------- ------------------- ------------------- 
------------------- ------------------- ------------------- ------------------- ------------------- ------------------- ------------------- ------------------- -----------B------- -------------B----- -------------B----- ------------------- ------------------- ------------------- ------------------- -------------B----- -----B-B-----B----- -------B----------- ------------------- ------------------- ------------------- ------------------- ------------------- ------------------- ------------------- ------------------- 
------------------- ------------------- ------------------- ------------------- ------------------- ------------------- ------------------- ------------------- -------B-------B--- ------------------- -----B-------B----- ------------------- ------------------- ------------------- ------------------- -------------B----- -----B------------- ---B-------B---B--- ------------------- ------------------- ------------------- ------------------- ------------------- ------------------- ------------------- ------------------- 
------------------- ------------------- ------------------- ------------------- ------------------- ------------------- ------------------- ------------------- ---B---B---B------- ------------------- ------------------- ------------------- ------------------- ------------------- ------------------- -----B------------- ------------------- -------B----------- ------------------- ------------------- ------------------- ------------------- ------------------- ------------------- ------------------- ------------------- 
------------------- ------------------- ------------------- ------------------- ------------------- ------------------- ------------------- ------------------- ---B-----------B--- ------------------- -----B-------B----- ------------------- ------------------- ------------------- ------------------- -------------B----- ------------------- ---B---B---B---B--- ------------------- ------------------- ------------------- ------------------- ------------------- ------------------- ------------------- ------------------- 
------------------- ------------------- ------------------- ------------------- ------------------- ------------------- ------------------- ------------------- -----------B------- ------------------- -----B------------- ------------------- ------------------- ------------------- ------------------- -----B------------- ------------------- ------------------- ------------------- ------------------- ------------------- ------------------- ------------------- ------------------- ------------------- ------------------- 
