model
size = 18 7 31, scale = 0.05, origin = -y
material 
  colors = A:#A4F814 B:#99F213
voxels
------------------ ------------------ ------------------ --------AA-------- --------AA-------- ------------------ ------------------ 
------------------ ------------------ --------AA-------- -------BAAB------- -------BAAB------- --------BB-------- ------------------ 
------------------ --------AA-------- -------AAAA------- ------B----B------ -------B--B------- -------BAAB------- --------AA-------- 
------------------ -------AAAA------- ------A-AA-A------ ------B----B------ ------B----B------ -------B--B------- -------AAAA------- 
--------AA-------- -------AAAA------- ------AAAAAA------ -----BBA--ABB----- ------B----B------ ------B----B------ -------AAAA------- 
--------AA-------- -------AAAA------- -------A--A------- ------A----A------ -----B------B----- ------B-AA-B------ ------AAAAAA------ 
--------AA-------- --------AA-------- -------A--A------- ------------------ -----B------B----- -----B--BB--B----- ------AA--AA------ 
--------AA-------- --------AA-------- ------------------ ------------------ ------------------ -----BAB--BAB----- -----BA----AB----- 
--------AA-------- ------------------ ------------------ ------------------ ------------------ -----AB----BA----- -----A------A----- 
--------AA-------- ------------------ ------------------ ------------------ ------------------ -----AB----BA----- ----BA------AB---- 
--------AA-------- ------------------ ------------------ ------------------ ------------------ -----B------B----- ----B--------B---- 
--------AA-------- ------------------ ------------------ ------------------ ------------------ ----AB------BA---- ----B--------B---- 
--------AA-------- --------AA-------- ------------------ ------------------ ------------------ ----AB------BA---- ----B--------B---- 
------------------ --------AA-------- ------------------ ------------------ ------------------ ----AB------BA---- ---BB--------BB--- 
------------------ --------AA-------- ------------------ ------------------ ------------------ ---AB--------BA--- ---B----------B--- 
------------------ --------AA-------- ------------------ ------------------ ------------------ ---AB--------BA--- ---B----------B--- 
------------------ -------AAAA------- ------------------ ------------------ ------------------ ---AB--------BA--- ---B----------B--- 
------------------ -------A--A------- ------------------ ------------------ ------------------ ---AB--------BA--- --BB----------BB-- 
------------------ ------BA--AB------ ------------------ ------------------ ------------------ --AB----------BA-- --B------------B-- 
------------------ ------B----B------ ------------------ ------------------ ------------------ --AB----------BA-- --B------------B-- 
------------------ -----BB----BB----- ------------------ ------------------ ------------------ --AB----------BA-- --B------------B-- 
------------------ -----B------B----- ------------------ ------------------ ------------------ --AB----------BA-- --B------------B-- 
------------------ ----BB------BB---- ------------------ ------------------ ------------------ --AB----------BA-- -BB------------BB- 
------------------ ----B--------B---- ------------------ ------------------ ------------------ -AB------------BA- -B--------------B- 
---A----------A--- ---BB--------BB--- ------------------ ------------------ ------------------ -AB------------BA- -B--------------B- 
---A----------A--- ------------------ ------------------ ------------------ ------------------ -AB------------BA- -B--------------B- 
--AA----------AA-- ------------------ ------------------ ------------------ ------------------ -AB------------BA- -B--------------B- 
--A------------A-- ------------------ ------------------ ------------------ ------------------ AAB------------BAA -B--------------B- 
-AA------------AA- ------------------ ------------------ ------------------ A----------------A AB--------------BA ------------------ 
-A--------------A- -A--------------A- ------------------ ------------------ BA--------------AB -B--------------B- ------------------ 
------------------ -A--------------A- -A--------------A- BA--------------AB -A--------------A- ------------------ ------------------ 
