model
size = 17 30 24, scale = 0.05, origin = -y
material 
  colors = A:#600 B:#0E0 C:#050 D:#080 E:#0A0 F:#070 G:#020 H:#FF0 I:#0B0 J:#0FC
voxels
----------------- ----------------- ----------------- ----------------- ----------------- ----------------- ----------------- ----------------- ----------------- ----------------- ---A------------- -AAAA------------ -AAAA------------ --A-------------- ----------------- ----------------- ----------------- ----------------- ----------------- ----------------- ----------------- ----------------- ----------------- ----------------- ----------------- ----------------- ----------------- ----------------- ----------------- ----------------- 
----------------- ----------------- ----------------- ----------------- ----------------- ----------------- ----------------- ----------------- ----------------- ----------------- ----------------- -AAA------------- -AAA------------- ----------------- ----------------- ----------------- ----------------- ----------------- ----------------- ----------------- ----------------- ----------------- ----------------- ----------------- ----------------- ----------------- ----------------- ----------------- ----------------- ----------------- 
----------------- ----------------- ----------------- ----------------- ----------------- ----------------- ----------------- ----------------- ----------------- -F-BFB----------- F---------------- -AAA-B----------- -AAA-F----------- F----B----------- ---FB------------ ----------------- ----------------- ----------------- ----------------- ----------------- ----------------- ----------------- ----------------- ----------------- ----------------- ----------------- ----------------- ----------------- ----------------- ----------------- 
----------------- ----------------- ----------------- ----------------- ----------------- ----------------- ----------------- ----------------- ----------------- ----------------- ----------------- -AAA------------- -AAA------------- ----------------- ----------------- ----------------- ----------------- ----------------- ----------------- ----------------- ----------------- ----------------- ----------------- ----------------- ----------------- ----------------- ----------------- ----------------- ----------------- ----------------- 
----------------- ----------------- ----------------- ----------------- ----------------- ----------------- ----------------- ----------------- ----------------- ---F-B----------- ----------------- -AAA-B----------- FAAA------------- -----F----------- B-B-F------------ ----------------- ----------------- ----------------- ----------------- ----------------- ----------------- ----------------- ----------------- ----------------- ----------------- ----------------- ----------------- ----------------- ----------------- ----------------- 
----------------- ----------------- ----------------- ----------------- ----------------- ----------------- ----------------- ----------------- ----------------- -F--------------- F---------------- -AAAA------------ -AAAA------------ -AAAA------------ ----------------- ----------------- ----------------- ----------------- ----------------- ----------------- ----------------- ----------------- ----------------- ----------------- ----------------- ----------------- ----------------- ----------------- ----------------- ----------------- 
----------------- ----------------- ----------------- ----------------- ----------------- ----------------- ----------------- ----------------- ----------------- ---B-B----------- ----------------- -AAAAB----------- BAAAA------------ -AAAAB----------- F-B-B------------ ----------------- ----------------- ----------------- ----------------- ----------------- ----------------- ----------------- ----------------- ----------------- ----E------------ ----------------- ----------------- ----------------- ----------------- ----------------- 
----------------- -----C--C--C----- ----------------- ----B-C---C-B---- ---B----C-------- -C----B---B-B---- ---C-B----------- ----------B-B---- -F--F------------ ----------------- ---F-B----------- -FAAA------------ -AAAAB----------- -FAAA------------ ---F-B----------- ----------------- -F--F------------ ----------------- ---F-B----------- -F----B---B-B---- ---B----D-------- ----B-D---D-B---- ----E------------ -----D--I--D----- ----------------- ----------------- ----E------------ ----------------- ----------------- ----------------- 
-AA--C--C--C---A- -AAAAAAAAAAAAA-A- -AAAAAAAAAAAAA--- -AAAAAAAAAAAAA--- -AAAA------------ CAAAA------------ -AAAA------------ -AAAA---C-------- EAAAA--C--------- -AAAA------------ -AAAA------------ CAAAA------------ -AAAA------------ EAAAA------------ ----------------- ----------------- F---------------- ----------------- ----------------- F---------------- ----E------------ ----------------- ----------------- ----------------- ----DD--E--D----- ----------------- ----------------- ----------------- ----E------------ ----------------- 
-A-------------AA -AAAAAAAAAAAAAAAA -AAAAAAAAAAAAAAA- -AAAAAAAAAAAAA--- -AAAA------------ -AAAA------------ -AAAA------------ -AAAA-----C-B---- -AAAA------------ -AAAA------------ -AAAA------------ -AAAA------------ -AAAAB----------- -AAAA------------ -AAAAB----------- -AAAA------------ -AAAA------------ -AAAA------------ -AAAAB----------- -AAAA-B---B-B---- -AAAA------------ -AAAA------------ -AAAA------------ ----F------------ ----------------- ----------------- ----------------- ----------------- ----------------- ----------------- 
----B-C---C-B--AA -AAAAAAAAAAAAAAAA -AAAAAAAAAAAAAAA- -AAAAAAAAAAAAA--- BAAAA------------ -AAAA------------ CAAAA------------ -AAAA------------ -AAAA------------ -AAAA------------ CAAAA------------ -AAAA------------ BAAAA------------ -AAAA------------ FAAAA------------ -AAAA------------ -AAAAF----------- -AAAA------------ FAAAA------------ -AAAE---D-------- BAAAA------------ -AAAA------------ -AAAD------H----- ----------------- ----C-D---D-B---- E--D--E---------- ----D------------ -E---E----------- ---E------------- ----E------------ 
---B----C------A- -AAAAAAAAAAAAA-A- -AAAAAAAAAAAAA--- BAAAAAAAAAAAAA--- -AAAA------------ -AAAA------------ -AAAA------------ -AAAA---C--C----- CAAAA------------ -AAAA------------ -AAAA------------ -AAAA------------ -AAAAB----------- -AAAA------------ ---AAC----------- ----------------- F---------------- ----------------- -----F----------- ------D---D-B---- ----------------- B----------H----- -----------J----- ----F------H----- ---B----E-------- ----------------- ----------------- ----------------- ----------------- ----------------- 
-C----B---B-B---- CAAAA------------ -AAAA-B---B-B---- -AAAA---C-------- ------E---C-B---- ----------------- B-B-E---E--E----- ----------------- ---C--E---------- ----------------- B-B-C------------ -AAAA------------ BAAAA------------ -AAAA------------ B-B-E------------ ----------------- ---F------------- ----------------- B-B-D------------ ----------------- ----E------------ ----------------- -----------H----- D---------------- -E--D-B---B-B---- ----------------- ----------------- ----------------- ----E------------ ----------------- 
---C-B----------- -AAAA------------ -AAAAB----------- CAAAA------------ -----C----------- B-B-C------------ ----------------- ----------------- ----------------- ---C-B----------- ----------------- -AAAAB----------- CAAAA------------ -AAAAC----------- B-B-E------------ ----------------- ----------------- ----------------- ----------------- B-B-D---E--D----- ----------------- D---------------- ----E------------ ----------------- ---D-B----------- ----------------- ----E------------ ----------------- ----------------- ----------------- 
----------------- -AAAA------------ -AAAA------------ -AAAA------------ ----------------- ----------------- ----------------- ----------------- ----------------- ----------------- ----------------- -AAAA------------ -AAAA------------ -AAAA------------ ----------------- ----------------- ----------------- ----------------- ----------------- ----------------- --------D--D----- --------G-------- ----------D-B---- --------D-------- ----E-----B-B---- ----------------- ----------------- ----------------- ----------------- ----------------- 
-C-BCB----------- CAAAA------------ -AAAAB----------- -AAAAC----------- I----B----------- ---CB------------ ----------------- ----------------- ----------------- -C-BCB----------- C---------------- -AAAAB----------- -AAAAC----------- IAAAAB----------- ---CB------------ ----------------- ----------------- ----------------- ----------------- ---D--E---------- D------D--------- -------GGG------- ----------------- D------D--------- -E--D------------ ----------------- ----------------- ----------------- ----------------- ----------------- 
----------------- -AAAA------------ -AAAA------------ -AAAA------------ ----------------- ----------------- ----------------- ----------------- ----------------- ----------------- ----------------- -AAAA------------ -AAAA------------ -AAAA------------ ----------------- ----------------- ----------------- ----------------- ----------------- ----------------- ----------------- --------GGG------ ----------------- ----------------- ----------------- ----------------- ----------------- ----------------- ----------------- ----------------- 
---C-B----------- -AAAA------------ -AAAAB----------- CAAAA------------ -----E----------- B-B-C------------ ----------------- ----------------- ----------------- ---C-B----------- ----------------- -AAAAB----------- CAAAA------------ -AAAAC----------- B-B-C------------ ----------------- ----------------- ----------------- ----------------- B-B-D------------ ----------------- D--------GG------ -------D--------- ----------------- ---D-B-B--------- ----------------- ----------------- ----------------- ----------------- ----------------- 
-C--------------- CAAAA------------ -AAAA------------ -AAAA------------ ----------------- ----------------- ----------------- ----------------- ----------------- -C--------------- C---------------- -AAAA------------ -AAAA------------ -AAAA------------ ----------------- ----------------- ----------------- ----------------- ----------------- ------D---------- -------I--------- ----------------- ----------------- I---------------- -D--------------- ----------------- ----------------- ----------------- ----------------- ----------------- 
---B-B----------- -AAAA------------ -AAAAB----------- BAAAA------------ -----B----------- B-B-B------------ ----------------- ----------------- ----------------- ---B-B----------- ----------------- -AAA-B----------- BAAA------------- -----B----------- B-B-B------------ ----------------- ----------------- ----------------- ----------------- B-B-B------------ ----------------- B--H------------- --HJH--B--------- ---H------------- ---B-B-B--------- ----------------- ----------------- ----------------- ----------------- ----------------- 
----------------- -AAAA------------ -AAAA------------ -AAAA------------ ----------------- ----------------- ----------------- ----------------- ----------------- ----------------- ----------------- -AAA------------- -AAA------------- ----------------- ----------------- ----------------- ----------------- ----------------- ----------------- ----------------- ----------------- ----------------- ----------------- ----------------- ----------------- ----------------- ----------------- ----------------- ----------------- ----------------- 
----------------- --AA------------- --AA------------- ----------------- ----------------- ----------------- ----------------- ----------------- ----------------- ----------------- --A-------------- -AAAA------------ -AAAA------------ ---A------------- ----------------- ----------------- ----------------- ----------------- ----------------- ----------------- ----------------- ----------------- ----------------- ----------------- ----------------- ----------------- ----------------- ----------------- ----------------- ----------------- 
-AAAA------------ -AAAA------------ --AA------------- ----------------- ----------------- ----------------- ----------------- ----------------- ----------------- ----------------- --A-------------- ----A------------ -A--------------- ---A------------- ----------------- ----------------- ----------------- ----------------- ----------------- ----------------- ----------------- ----------------- ----------------- ----------------- ----------------- ----------------- ----------------- ----------------- ----------------- ----------------- 
--AA------------- --AA------------- ----------------- ----------------- ----------------- ----------------- ----------------- ----------------- ----------------- ----------------- ----------------- ----------------- ----------------- ----------------- ----------------- ----------------- ----------------- ----------------- ----------------- ----------------- ----------------- ----------------- ----------------- ----------------- ----------------- ----------------- ----------------- ----------------- ----------------- ----------------- 
