model
size = 26 32 12, scale = 0.05, origin = -y
material 
  colors = A:#FFFFFB B:#555 C:#222 D:#72636E E:#FCFAF2 F:#BBB G:#5E3D50 H:#BDC0BA I:#FFF J:#FFC408 K:#111 L:#DDD M:#444
voxels
530-C4-C19-CJ4-JC17-CJ6-JC16-J8-J18-K4-K19-GC4-CG17-MDC4-CDM16-FDC4-CDF16-ADC4-CDA17-D6-D823-2AC4-C2A17-DC4-CD823-2A6-2A17-2C4-2C4(797-2A6-2A17-C6-C)770-3A6-3A15-2A6-2A17-C6-C720-2BE2AE2B16-4AB2AB4A14-4A4B4A15-4A2B4A17-8C9-4C5B8D5B5C3B3A3D6A3D3A3B2CB-CD7A2B7ADC-B3C2-C2D3AH4EH3A2DC2-2C5-2CDA8EAD2C6-A4-CDABEH2BHEBADC4-A7-3(CDA2E4B2EADC12-)2(CDA2EH2BH2(2EADC12-CDA2E4B)2EADC12-)CDA2EH2BH2EADC11-2CDABE4BEBAD2C10-C-DA2E4B2EAD-C12-DA2EH2BH2EAD14-DA2E4B2EAD12-A-DA2E4B2EAD-A12-DA2EH2BH2EAD12-C-DA2E4B2EAD-C10-2CDABE4BEBAD2C11-CDA3E2B3EADC12-CDAE6BEADC12-CDA8BADC12-C2D3A2C3A2DC13-C3AC2AC3AC14-CDAC4ACADC15-CD2A2D2ADC43-2B4A2B13-B3A2B6A2B3AB8-BAB2AB6AB2ABAB9-3AB8AB3A12-AB8ABA14-AB3A2J3ABA14-5A2C2(5A14-AB3A2B3ABA14-5A2B)5A14-AB3A2B3ABA14-5A2C5A14-AC3A2B3ACA3(14-12A)14-4A4C4A15-2AC4FC2A16-ACF4IFCA16-AB2I2K2IBA16-2ABI2KIB2A15-4A4B4A14-12A14-2AC6AC2A14-AC2LC2AC2LCA14-2A2C4A2C2A15-10A16-10A17-3A2D3A72-4F21-FG2DGF20-FD2ADF19-FGD2ADGF18-FD4A8(DF18-FDA2-A)DF18-FG4AGF17-F2(2DA)2DF16-FG2-2D2-GF16-2F6-2F16-F8-F120-F8-F16-2F6-2F16-FG2-2D2-GF16-FDGA2DAGDF17-FD4ADF18-FG4DGF19-6F88-
