model
size = 16 24 14, scale = 0.05, origin = -y
material 
  colors = A:#5DAC81 B:#20604F C:#0F4C3A D:#222 E:#111 F:#FFFFFB G:#91989F H:#DDD
voxels
---------------- ---------------- ---------------- -------CC------- -------CC------- ------ACCA------ -----AACCAA----- ----AAACCAAA---- ----AAACCAAA---- ----AAACCAAA---- ----AAACCAAA---- ----AAACCAAA---- ---AAAACCAAAA--- ---AAEEEEEEAA--- ---AEGGGGGGEA--- ---EGFFFFFFGE--- ---EFFEEEEFFE--- ---AEFEEEEFEA--- ---AAEEEEEEAA--- ----AAABBAAA---- -----AABBAA----- ---------------- ---------------- ---------------- 
---------------- -------CC------- ------CCCC------ ------CAAC------ -----CAAAAC----- ----CAAAAAAC---- ---CABAAAABAC--- ---AABAAAABAA--- ---AABAAAABAA--- ---AABAAAABAA--- ---CABAAAABAC--- --BCAAAAAAAACB-- --BAAAAAAAAAAB-- --BAAAAAAAAAAB-- --BAAAAAAAAAAB-- --BAAAAAAAAAAB-- --BAAAAAAAAAAB-- --BAHHAAAAHHAB-- --BAAAAAAAAAAB-- --BBAAABBAAABB-- --BBBAABBAABBB-- ---BBBBBBBBBB--- ----BBBBBBBB---- ---------------- 
-------DD------- ------DAAD------ -----DAAAAD----- -----DAAAAD----- ----DAAAAAAD---- --DDAAAAAAAADD-- --CCAAAAAAAACC-- --AAAAAAAAAAAA-- --AAAAAAAAAAAA-- --CAAAAAAAAAAC-- -BCAAAAAAAAAACB- -BAAAAAAAAAAAAB- -BAAAAAAAAAAAAB- -BAAAAAAAAAAAAB- -BAAAAAAAAAAAAB- -BAAAAAAAAAAAAB- -BAAAAAAAAAAAAB- -BAAAAAAAAAAAAB- -BAAAAAAAAAAAAB- -BAAAAABBAAAAAB- --AAAAABBAAAAA-- --AAAAABBAAAAA-- ---AAAABBAAAA--- ----AAABBAAA---- 
---------------- ---------------- ---------------- ---------------- ---------------- -D------------D- -C------------C- -A------------A- -C------------C- AC------------CA AA------------AA AA------------AA AA------------AA AA------------AA AA------------AA AA------------AA AA------------AA AA------------AA AA-AAAAAAAAAA-AA -BAAAAABBAAAAAB- -BAAAAABBAAAAAB- --AAAAABBAAAAA-- ---AAAABBAAAA--- ----AAABBAAA---- 
---------------- ---------------- ---------------- ---------------- -D------------D- -C------------C- AD------------DA A--------------A A--------------A A--------------A A--------------A A--------------A A--------------A A--------------A A--------------A A--------------A A--------------A A--------------A A--AAAAAAAAAA--A AAAAAAABBAAAAAAA -BAAAAABBAAAAAB- --AAAAABBAAAAA-- ---AAAABBAAAA--- ----AAABBAAA---- 
---------------- ---------------- ---------------- -D------------D- -C------------C- A--------------A A--------------A A--------------A A--------------A A--------------A A--------------A A--------------A A--------------A A--------------A A--------------A A--------------A A--------------A A--------------A A--AAAAAAAAAA--A AAAAAAABBAAAAAAA -BAAAAABBAAAAAB- --AAAAABBAAAAA-- ---AAAABBAAAA--- ----AAABBAAA---- 
---------------- ---------------- -D------------D- -C------------C- A--------------A A--------------A A--------------A A--------------A A--------------A A--------------A A--------------A A--------------A A--------------A A--------------A A--------------A A--------------A A--------------A A--------------A A--AAAAAAAAAA--A AAAAAAAAAAAAAAAA -BAAAAAAAAAAAAB- --AAAAABBAAAAA-- ---AAAABBAAAA--- ----AAABBAAA---- 
---------------- ---------------- -D------------D- -C------------C- A--------------A A--------------A A--------------A A--------------A A--------------A A--------------A A--------------A A--------------A A--------------A A--------------A A--------------A A--------------A A--------------A A--------------A A--AAAAAAAAAA--A AAAAAAAAAAAAAAAA -BAAAAAAAAAAAAB- --AAAAABBAAAAA-- ---AAAABBAAAA--- ----AAABBAAA---- 
---------------- ---------------- ---------------- -D------------D- -C------------C- A--------------A A--------------A A--------------A A--------------A A--------------A A--------------A A--------------A A--------------A A--------------A A--------------A A--------------A A--------------A A--------------A A--AAAAAAAAAA--A AAAAAAAAAAAAAAAA -BAAAAAAAAAAAAB- --AAAAABBAAAAA-- ---AAAABBAAAA--- ----AAABBAAA---- 
---------------- ---------------- ---------------- ---------------- -D------------D- -C------------C- A--------------A A--------------A A--------------A A--------------A A--------------A A--------------A A--------------A A--------------A A--------------A A--------------A A--------------A A--------------A A--AAAAAAAAAA--A AAAAAAAAAAAAAAAA -BAAAAAAAAAAAAB- --AAAAABBAAAAA-- ---AAAABBAAAA--- ----AAABBAAA---- 
---------------- ---------------- ---------------- ---------------- ---------------- -D------------D- -C------------C- -A------------A- -C------------C- AC------------CA AA------------AA AA------------AA AA------------AA AA------------AA AA------------AA AA------------AA AA------------AA AA------------AA AA-AAAAAAAAAA-AA -BAAAAAAAAAAAAB- -BAAAAAAAAAAAAB- --AAAAABBAAAAA-- ---AAAABBAAAA--- ----AAABBAAA---- 
-------DD------- ------DAAD------ -----DAAAAD----- -----DACCAD----- ----DAACCAAD---- --DDAAACCAAADD-- --CCCAACCAACCC-- --AAAAACCAAAAA-- --AAAAACCAAAAA-- --CAAAACCAAAAC-- -BCAAAACCAAAACB- -BAAAAACCAAAAAB- -BAAAAACCAAAAAB- -BAAAAACCAAAAAB- -BAAAAACCAAAAAB- -BAAAAACCAAAAAB- -BAAAAACCAAAAAB- -BAAAAACCAAAAAB- -BAAAAACCAAAAAB- -BAAAAACCAAAAAB- --AAAAACCAAAAA-- --AAAAABBAAAAA-- ---AAAABBAAAA--- ----AAABBAAA---- 
---------------- -------CC------- ------CCCC------ ------CCCC------ -----CACCAC----- ----CAACCAAC---- ----CAACCAAC---- ----AAACCAAA---- ----AAACCAAA---- ----AAACCAAA---- ---CCAACCAACC--- --BCAAACCAAACB-- --BAAAACCAAAAB-- --BAAAACCAAAAB-- --BAAAACCAAAAB-- --BAAAACCAAAAB-- --BAAAACCAAAAB-- --BAHHACCAHHAB-- --BAAAACCAAAAB-- --BAAAACCAAAAB-- --BBAAACCAAABB-- ---BBBBBBBBBB--- ----BBBBBBBB---- ---------------- 
---------------- ---------------- ---------------- -------BB------- -------BB------- ------ABBA------ -----AABBAA----- -----AABBAA----- -----AABBAA----- -----AABBAA----- -----AABBAA----- ----AAABBAAA---- ---AAAABBAAAA--- ---AAAABBAAAA--- ---AAAABBAAAA--- ---AAAABBAAAA--- ---AAAABBAAAA--- ---AAAABBAAAA--- ---AAAABBAAAA--- ---AAAABBAAAA--- ----AAABBAAA---- ---------------- ---------------- ---------------- 
