model
size = 27 32 30, scale = 0.05, origin = -y
material 
  colors = A:#FF0
voxels
84-A7-A4-2(A7-)2(A3-A8-)A5-A6-A5-A9-3A10-3A11-A-A10-A-A11-3A10-3A9-A5-A6-A5-2(A8-A3-)2(A7-)A4-A7-A167-A7-A3-2A6-2A7-A3-A7-2A2-2A8-2(A5-)2A4-2A9-3A10-3A11-A-A10-A-A11-3A10-3A9-2(A5-)2A5-A8-A3-A7-2A3-2(A7-)A3-2A7-A165-3A7-6A7-3A-A3-5A3-2A3-5A3-A-2(A5-)2A2(5-A)-A5-A6-A5-A8-A9-A2-A9-2(A3-)A-A3-A2-A3-A-2(A3-)3A5-3A2-3A5-3A2(3-A)-A3-A2-A3-A-2(A3-)A9-A2-A9-A8-A12-A7-2(A5-)2A2(5-A)-A3-5A3-2A3-5A3-A-3A7-6A7-3A-A11-2A11-A28-3A7-6A6-4A-A3-5A3-2A2-6A2-2A-2(A5-)2(2A4-)2A-2(A5-)2A4-2A8-A9-A-2A8-2A2(3-A)-A3-A-2A2-4A2-2A3-3A5-3A-4A4-4A2(3-A)-A3-A-2A2-4A2-2A3-A9-A-2(2A8-)A12-A7-2(A5-)2A5-A4-2A-A3-5A3-2A3-5A2-2A-3A7-6A6-4A-A11-2A10-2A82-3A7-6A7-3A-A12-A79-A12-4(A-A11-2A11-)A-A12-A94-A11-2A11-A-3A7-6A7-3A-3A7-6A6-4A-A11-2A79-A11-4(2A-A11-2A10-)2A-A11-2A94-A11-2A10-2A-3A7-6A6-4A55-A3-5A3-2A3-5A3-A-A12-A39-A12-A53-A12-A28-A11-2A11-A81-A12-A41-A11-2A11-A-A3-5A3-2A3-5A3-A-A3-5A3-2A2-6A2-2A-A11-2A39-A11-2A53-A11-2A28-A11-2A10-2A81-A11-2A41-A11-2A10-2A-A3-5A3-2A2-6A2-2A30-A7-A4-A7-A3-2(A5-)2A2(5-A)108-2(A12-)A28-A11-2A11-A27-A12-A107-A12-2(A-)2(A3-)A-4A3-A2-2A3(-A)2(3-A)-2A-A2-2A3-3A108-A2(11-2A)28-A11-2A10-2A27-A11-2A107-A11-2A-2(A5-)2(2A4-)2A3-A7-A3-2A6-2A7-A3-A8-A3-A11-A12-A34-A12-A39-A12-A26-A12-A40-A12-A54-A12-A41-A12-A44-2(A-)A7-2A-3A9-2(A-)A8-3A-A32-A11-2A39-A11-2A26-A11-2A40-A11-2A54-A11-2A41-A11-2A46-A11-2A11-A3-A7-2A2-2A8-A5-A6-2(A5-)A9-2A-A9-2A28-A12-A79-A12-3A11-2A2(12-A)12-3A11-2A94-A11-2A11-A29-A-A5-A-A2-3A4-2A-A3-A-A5-A-4A-A5-4A28-A11-2A79-A11-4A10-3A12-A11-2A11-4A10-3A94-A11-2A10-2A29-A9-A-2A8-2A2(5-A)5-2A4-2A9-3A10-3A7-A3-A-A3-2A-A3-A-A3-2A13-A12-3(A-A11-2A11-)A13-A12-2A12-A26-A12-2A2(12-A)13-A12-3(A-A11-2A11-)A29-A3-3A3-2(A2-)4A2(3-A)3-3A3-2(4A2-)3A13-A11-3(2A-A11-2A10-)2A13-A11-3A11-2A26-A11-3A2(11-2A)13-A11-3(2A-A11-2A10-)2A29-2(A3-A-)2A2-4A2-2A7-3A9-4A11-A-A10-A-A7-3A5-4A-3A5-4A28-A12-A93-2A11-2A2(12-A)13-2A11-2A94-A11-2A11-A29-3A2(-A)-3A2-7A-3A3-3A2(-A)-8A-A-6A28-A11-2A93-2A10-3A12-A11-2A13-2A10-3A94-A11-2A10-2A29-3A5-3A-4A4-4A7-A-A9-4A11-3A10-3A7-A3-A-A3-2A-A3-A-A3-2A13-A12-A-A11-2A11-A13-A12-2A2(12-A)13-A12-A40-2(A12-A13-)A12-2A2(12-A)13-A12-A-A11-2A11-A29-A3-3A3-2(A2-)4A2(3-A)3-3A3-2(4A2-)3A13-A11-2A-A11-2A10-2A13-A11-3A2(11-2A)13-A11-2A40-2(A11-2A13-)A11-3A2(11-2A)13-A11-2A-A11-2A10-2A29-2(A3-A-)2A2-4A2-2A7-3A9-4A9-A5-A6-2(A5-)A9-2A-A9-2A108-2(A12-)A28-A11-2A11-A27-A12-A80-A12-A29-A-A5-A-A2-3A4-2A-A3-A-A5-A-4A-A5-4A108-A2(11-2A)28-A11-2A10-2A27-A11-2A80-A11-2A29-A9-A-2A8-2A2(5-A)5-2A4-2A2(8-A3-A)11-A12-A7-A12-A39-A12-A53-A12-A28-A11-2A11-A81-A12-A41-A12-A17-2(A-)A7-2A-3A9-2(A-)A8-3A-A5-A11-2A39-A11-2A53-A11-2A28-A11-2A10-2A81-A11-2A41-A11-2A19-A11-2A11-A3-A7-2A2-2A2(7-A)4-A7-A3-A5-A6-A5-A7-A12-A94-2(A11-2A11-A-A12-A13-)A12-A94-A11-2A11-2(A-)2(A3-)A-4A3-A2-2A3(-A)2(3-A)-2A-A2-2A2(3-A)11-2A94-2(A11-2A10-2A-A11-2A13-)A11-2A94-A11-2A10-2A-2(A5-)2(2A4-)2A3-A7-A3-2A6-2A30-A3-5A4-A3-5A5-2(A12-A13-)A12-A52-A12-A40-A12-A82-2(A12-A13-)A11-2A11-A-A3-5A3-2A3-5A3-A-A3-5A3-2A2-6A5-2(A11-2A13-)A11-2A52-A11-2A40-A11-2A82-2(A11-2A13-)A11-2A10-2A-A3-5A3-2A2-6A2-2A55-2(3A7-6A7-3A-)2(A-)5A-A-2A-A-5A3(-A)3-2(A-)A3-2A3-2(A-)A3-A4-3(A2-)A3-4(A2-)A3-3A3-2A-A3-3A3-2A2-A3-A-A3-2A-A3-A-A3-2A2-2(3A-)4A2(-3A)-4A2-5(A-)2A5(-A)-2A2(2-A)3-3(A2-)A3-A2-2(A4-2(A3-))A3-2(A5-)2A2(5-A)-A3-5A3-2A3-5A3-A2(-3A7-6A7-3A)2(-3A7-6A6-4A)2(-A)-5A-A-2A-7A-3A-A3-2(A-)A3-2A3-3A-A2-2A4-3(A2-)A3-2(A-2A2-)A3-3A3-4A3-2(3A2-)A3-A-A3-2(4A2-)3A2-2(3A-)8A-8A2-5(A-)4A-5A-4A2(2-A)3-A2-A-2A2-A3-A-2A4-2(A3-)A4-A2-2A2(3-A)5-A5-2(2A4-)2A-A3-5A3-2A2-6A2-2A2(-3A7-6A6-4A)55-3A7-6A7-3A-A3-5A3-2A3-5A3-A-2(A5-)2A2(5-A)2(-A)2(3-A)2-A-2(A3-)A4-A2-A3-3(A2-)A3-A2-A3-5(A-)A2-5(A-)A3-2(3A-)3A2-2(3A-)3A2(3-A)-A3-A2-A3-A-3(A3-)3A3-A2-A3-3A3-A5-2(A2-)A6-2(A2-)A4-A3-2(A-)A3-2A2(3-2(A-)A)-5A-A-2A-A-5A2(-A)-3A7-6A7-3A-A11-2A11-A28-3A7-6A7-3A-A3-5A3-2A3-5A3-A-2(A5-)2A2(5-A)2(-A)2(3-A)2-3A3-A2-2A4-A2-A3-2(A2-)A-2(2A2-)A3-5(A-)A2-3A-A-3A-A3-2(3A-)3A2-7A-3A2(3-A)-A3-2(A2-)4A2(3-A)3-3A3-2(A2-)4A3-A5-2(A2-)A5-2A2-A-2A4-A3-2(A-)A3-2A2-2A-3A3-3(A-)5A-A-4A-7A-A-3A7-6A7-3A-A11-2A11-A82-3A7-6A7-3A-A12-A79-A12-4(A-A11-2A11-)A-A12-A94-A11-2A11-A2(-3A7-6A7-3A)-A12-A79-A12-4(A-A11-2A11-)A-A12-A94-A11-2A11-A-3A7-6A7-3A55-A3-5A3-2A3-5A3-A-A12-A39-A12-A53-A12-A28-A11-2A11-A81-A12-A41-A11-2A11-2(A-A3-5A3-2A3-5A3-)A-A12-A39-A12-A53-A12-A28-A11-2A11-A81-A12-A41-A11-2A11-A-A3-5A3-2A3-5A3-A30-A7-A4-A7-A3-2(A5-)2A2(5-A)108-2(A12-)A28-A11-2A11-A27-A12-A107-A12-2(A-)2(A3-)A-2A-2(A3-)3(A-)2(A3-)A-2A-2(A3-)A-A108-2(A12-)A28-A11-2A11-A27-A12-A107-A12-A-2(A5-)2A2(5-A)3-A7-A4-2(A7-)A3-A8-A3-A11-A12-A34-A12-A39-A12-A26-A12-A40-A12-A54-A12-A41-A12-A44-2(A-)A8-2(A-)A9-2(A-)A8-2(A-)A32-A12-A39-A12-A26-A12-A40-A12-A54-A12-A41-A12-A46-A12-A11-2(A3-A8-)A5-A6-2(A5-)A9-2A-A9-2A28-A12-A79-A12-3A11-2A2(12-A)12-3A11-2A94-A11-2A11-A29-A-A5-A-A2-A-A5-A-A3-A-A5-A-2A2(-A)5-A-2A28-A12-A79-A12-3A11-2A2(12-A)12-3A11-2A94-A11-2A11-A29-A9-A2-A9-2(A5-)A6-A5-A9-3A10-3A7-A3-A-A3-2A-A3-A-A3-2A13-A12-3(A-A11-2A11-)A13-A12-2A12-A26-A12-2A2(12-A)13-A12-3(A-A11-2A11-)A29-A3-3A3-A2-A3-3A2(3-A)3-3A3-2A-A3-3A3-2A13-A12-3(A-A11-2A11-)A13-A12-2A12-A26-A12-2A2(12-A)13-A12-3(A-A11-2A11-)A29-A3-A-A3-A2-A3-A-A3-A7-3A10-3A11-A-A10-A-A7-3A5-4A-3A5-4A28-A12-A93-2A11-2A2(12-A)13-2A11-2A94-A11-2A11-A29-3A2(-A)-3A2-3A2(-A)-3A3-3A2(-A)-4A-3A2(-A)-4A28-A12-A93-2A11-2A2(12-A)13-2A11-2A94-A11-2A11-A29-3A5-3A2-3A5-3A7-A-A10-A-A11-3A10-3A7-A3-A-A3-2A-A3-A-A3-2A13-A12-A-A11-2A11-A13-A12-2A2(12-A)13-A12-A40-2(A12-A13-)A12-2A2(12-A)13-A12-A-A11-2A11-A29-A3-3A3-A2-A3-3A2(3-A)3-3A3-2A-A3-3A3-2A13-A12-A-A11-2A11-A13-A12-2A2(12-A)13-A12-A40-2(A12-A13-)A12-2A2(12-A)13-A12-A-A11-2A11-A29-A3-A-A3-A2-A3-A-A3-A7-3A10-3A9-A5-A6-2(A5-)A9-2A-A9-2A108-2(A12-)A28-A11-2A11-A27-A12-A80-A12-A29-A-A5-A-A2-A-A5-A-A3-A-A5-A-2A2(-A)5-A-2A108-2(A12-)A28-A11-2A11-A27-A12-A80-A12-A29-A9-A2-A9-2(A5-)A6-A5-2(A8-A3-)A11-A12-A7-A12-A39-A12-A53-A12-A28-A11-2A11-A81-A12-A41-A12-A17-2(A-)A8-2(A-)A9-2(A-)A8-2(A-)A5-A12-A39-A12-A53-A12-A28-A11-2A11-A81-A12-A41-A12-A19-A12-A11-A3-A8-A3-2(A7-)A4-A7-A3-A5-A6-A5-A7-A12-A94-2(A11-2A11-A-A12-A13-)A12-A94-A11-2A11-2(A-)2(A3-)A-2A-2(A3-)3(A-)2(A3-)A2-A-3(A3-)A12-A94-2(A11-2A11-A-A12-A13-)A12-A94-A11-2A11-A-2(A5-)2A2(5-A)3-A7-A4-A7-A30-A3-5A4-A3-5A5-2(A12-A13-)A12-A52-A12-A40-A12-A82-2(A12-A13-)A11-2A11-A-A3-5A3-2A3-5A3-A-A3-5A4-A3-5A5-2(A12-A13-)A12-A52-A12-A40-A12-A82-2(A12-A13-)A11-2A11-A-A3-5A3-2A3-5A3-A55-2(3A7-6A7-3A-)A3-5A3-2A3-5A3-A-2(A5-)2A2(5-A)7-A5-A6-A5-A2-A9-2A-A9-2A2-A3-A-A3-2A-A3-A-A3-2A2-3A5-4A-3A5-4A2-A3-A-A3-2A-A3-A-A3-2A2(2-A9-A)8-A12-A7-2(A5-)2A2(5-A)-A3-5A3-2A3-5A3-A4(-3A7-6A7-3A)-A3-5A3-2A3-5A3-A-2(A5-)2A2(5-A)7-A5-A6-A5-A2-A9-2A-A9-2A2-A3-A-A3-2A-A3-A-A3-2A2-3A5-4A-3A5-4A2-A3-A-A3-2A-A3-A-A3-2A2(2-A9-A)8-A12-A7-2(A5-)2A2(5-A)-A3-5A3-2A3-5A3-A2(-3A7-6A7-3A)138-A7-A4-2(A7-)2(A3-A8-)A5-A6-A5-A9-3A10-3A11-A-A10-A-A11-3A10-3A9-A5-A6-A5-2(A8-A3-)2(A7-)A4-A7-A167-A7-A4-2(A7-)2(A3-A8-)A5-A6-A5-A9-3A10-3A11-A-A10-A-A11-3A10-3A9-A5-A6-A5-2(A8-A3-)2(A7-)A4-A7-A110-
