model
size = 27 30 19, scale = 0.05, origin = -y
material 
  colors = A:#888 B:#555 C:#AAA D:#DDD E:#111 F:#F9C G:#444 H:#996 I:#F66 J:#C03 K:#EEE
voxels
--------------------------- --------------------------- --------------------------- --------------------------- --------------------------- --------------------------- --------------------------- --------------------------- --------------------------- --------------------------- --------------------------- --------------------------- --------------------------- --------------------------- --------------------------- --------------------------- --------------------------- --------------------------- --------------------------- -----------G--------------- --------------------------- -----------G--------------- --------------------------- --------------------------- --------------------------- --------------------------- --------------------------- --------------------------- --------------------------- --------------------------- 
--------------------------- --------------------------- --------------------------- --------------------------- --------------------------- --------------------------- --------------------------- --------------------------- --------------------------- --------------------------- --------------------------- --------------------------- --------------------------- --------------------------- --------------------------- --------------------------- --------------------------- --------------------------- --------------------------- -----------G--------------- --------------------------- -----------G--------------- --------------------------- --------------------------- --------------------------- --------------------------- --------------------------- --------------------------- --------------------------- --------------------------- 
--------------------------B -------------------------B- ------------------------B-- -----------------------B--- ----------------------B---- ---------------------B----- --------------------B------ -------------------B------- ------------------B-------- -----------------B--------- ----------------B---------- ---------------B----------- --------------B------------ ---------BBBBB------------- --BBB----BBB--------------- --AAA----AAA--------------- --AAACCCCAAA--------------- --AAAAAAAAAA--------------- --AAAAAAAAAF--------------- --AAAAAAAAAF--------------- --AAAAAAAAAA--------------- --AAAAAAAAAA--------------- --AAAAAAAAAA--------------- --AAAAAAAAAA--------------- --AAAAAAAAAA--------------- --AAAAAAAAAA--------------- --AAAAAAAAAA--------------- --------AAAA--------------- --------AAAA--------------- --------AAAA--------------- 
--------------------------- --------------------------- --------------------------- --------------------------- --------------------------- --------------------------- --------------------------- --------------------------- --------------------------- --------------------------- --------------------------- --------------------------- --------------------------- --------------------------- --BBB----BBB--------------- --AAA----AAA--------------- --AAACCCCAAA--------------- --AAAAAAAAAA--------------- --AAAAAAAAAF--------------- --AAAAAAAAAF--------------- --AAAAAAAAAA--------------- --AAAAAAAAAA--------------- --AAAAAAAAAE--------------- --AAAAAAAEEE--------------- --AAAAAAAAAE--------------- --AAAAAAAAAD--------------- --AAAAAAAAAA--------------- --------AAAB--------------- --------AAAB--------------- --------AAAA--------------- 
--------------------------- --------------------------- --------------------------- --------------------------- --------------------------- --------------------------- --------------------------- --------------------------- --------------------------- --------------------------- --------------------------- --------------------------- --------------------------- --------------------------- --BBB----BBB--------------- --AAA----AAA--------------- --AAACCCCAAA--------------- --AAAAAAAAAA--------------- --AAAAAAAAAA--------------- --AAAAAAAAAA--------------- --AAAAAAAAAA--------------- --AAAAAAAAAA--------------- --AAAAAAAAAE--------------- --AAAAAAAAAE--------------- --AAAAAAAAAK--------------- --AAAAAAAAAD--------------- --AAAAAAAAAA--------------- --------AAAB--------------- --------AAAB--------------- --------AAAA--------------- 
--------------------------- --------------------------- --------------------------- --------------------------- --------------------------- --------------------------- --------------------------- --------------------------- --------------------------- --------------------------- --------------------------- --------------------------- --------------------------- --------------------------- --BBB----BBB--------------- --AAA----AAA--------------- --AAACCCCAAA--------------- --AAAAAAAAAA--------------- --AAAAAAAAAA--------------- --AAAAAAAAAA--------------- --AAAAAAAAAA--------------- --AAAAAAAAAA--------------- --AAAAAAAAAH--------------- --AAAAAAAAAH--------------- --AAAAAAAAAH--------------- --AAAAAAAAAD--------------- --AAAAAAAAAA--------------- --------AAAB--------------- --------AAAB--------------- --------AAAA--------------- 
--------------------------- --------------------------- --------------------------- --------------------------- --------------------------- --------------------------- --------------------------- --------------------------- --------------------------- --------------------------- --------------------------- --------------------------- --------------------------- --------------------------- --BBB----BBB--------------- --AAA----AAA--------------- --AAACCCCAAA--------------- --AAAAAAAAAA--------------- --AAAAAAAAAA--------------- --AAAAAAAAAAD-------------- --AAAAAAAAAAD-------------- --AAAAAAAAAAD-------------- --AAAAAAAAAD--------------- --AAAAAAAAAK--------------- --AAAAAAAAAD--------------- --AAAAAAAAAD--------------- --AAAAAAAAAA--------------- --------AAAA--------------- --------AAAA--------------- --------AAAA--------------- 
--------------------------- --------------------------- --------------------------- --------------------------- --------------------------- --------------------------- --------------------------- --------------------------- --------------------------- --------------------------- --------------------------- --------------------------- --------------------------- --------------------------- --------------------------- --------------------------- --CCCCCCCCCC--------------- --AAAAAAAAAA--------------- --AAAAAAAAAA--------------- --AAAAAAAAAAD-------------- --AAAAAAAAAAD-------------- --AAAAAAAAAAD-------------- --AAAAAAAAAA--------------- --AAAAAAAAAA--------------- --AAAAAAAAAA--------------- --AAAAAAAAAA--------------- --AAAAAAAAAA--------------- --------------------------- --------------------------- --------------------------- 
--------------------------- --------------------------- --------------------------- --------------------------- --------------------------- --------------------------- --------------------------- --------------------------- --------------------------- --------------------------- --------------------------- --------------------------- --------------------------- --------------------------- --------------------------- --------------------------- BBCCCCCCCCCC--------------- BBAAAAAAAAAJ--------------- BBAAAAAAAAAA--------------- BBAAAAAAAAAAD-------------- BBAAAAAAAAAAI-------------- BBAAAAAAAAAAI-------------- BBAAAAAAAAAA--------------- BBAAAAAAAAAA--------------- BBAAAAAAAAAA--------------- BBAAAAAAAAAA--------------- BBAAAAAAAAAA--------------- BB------------------------- BBBBBBB-------------------- BBBBBBB-------------------- 
--------------------------- --------------------------- --------------------------- --------------------------- --------------------------- --------------------------- --------------------------- --------------------------- --------------------------- --------------------------- --------------------------- --------------------------- --------------------------- --------------------------- --------------------------- --------------------------- BBCCCCCCCCCC--------------- BBAAAAAAAAAJ--------------- BBAAAAAAAAAA--------------- BBAAAAAAAAAA--------------- BBAAAAAAAAAAI-------------- BBAAAAAAAAAAI-------------- BBAAAAAAAAAA--------------- BBAAAAAAAAAA--------------- BBAAAAAAAAAA--------------- BBAAAAAAAAAA--------------- BBAAAAAAAAAA--------------- BB------------------------- BBBBBBB-------------------- BBBBBBB-------------------- 
--------------------------- --------------------------- --------------------------- --------------------------- --------------------------- --------------------------- --------------------------- --------------------------- --------------------------- --------------------------- --------------------------- --------------------------- --------------------------- --------------------------- --------------------------- --------------------------- BBCCCCCCCCCC--------------- BBAAAAAAAAAJ--------------- BBAAAAAAAAAA--------------- BBAAAAAAAAAAD-------------- BBAAAAAAAAAAI-------------- BBAAAAAAAAAAI-------------- BBAAAAAAAAAA--------------- BBAAAAAAAAAA--------------- BBAAAAAAAAAA--------------- BBAAAAAAAAAA--------------- BBAAAAAAAAAA--------------- BB------------------------- BBBBBBB-------------------- BBBBBBB-------------------- 
--------------------------- --------------------------- --------------------------- --------------------------- --------------------------- --------------------------- --------------------------- --------------------------- --------------------------- --------------------------- --------------------------- --------------------------- --------------------------- --------------------------- --------------------------- --------------------------- --CCCCCCCCCC--------------- --AAAAAAAAAA--------------- --AAAAAAAAAA--------------- --AAAAAAAAAAD-------------- --AAAAAAAAAAD-------------- --AAAAAAAAAAD-------------- --AAAAAAAAAA--------------- --AAAAAAAAAA--------------- --AAAAAAAAAA--------------- --AAAAAAAAAA--------------- --AAAAAAAAAA--------------- --------------------------- --------------------------- --------------------------- 
--------------------------- --------------------------- --------------------------- --------------------------- --------------------------- --------------------------- --------------------------- --------------------------- --------------------------- --------------------------- --------------------------- --------------------------- --------------------------- --------------------------- --BBB----BBB--------------- --AAA----AAA--------------- --AAACCCCAAA--------------- --AAAAAAAAAA--------------- --AAAAAAAAAA--------------- --AAAAAAAAAAD-------------- --AAAAAAAAAAD-------------- --AAAAAAAAAAD-------------- --AAAAAAAAAE--------------- --AAAAAAAAAE--------------- --AAAAAAAAAE--------------- --AAAAAAAAAD--------------- --AAAAAAAAAA--------------- --------AAAA--------------- --------AAAA--------------- --------AAAA--------------- 
--------------------------- --------------------------- --------------------------- --------------------------- --------------------------- --------------------------- --------------------------- --------------------------- --------------------------- --------------------------- --------------------------- --------------------------- --------------------------- --------------------------- --BBB----BBB--------------- --AAA----AAA--------------- --AAACCCCAAA--------------- --AAAAAAAAAA--------------- --AAAAAAAAAA--------------- --AAAAAAAAAA--------------- --AAAAAAAAAA--------------- --AAAAAAAAAA--------------- --AAAAAAAAAE--------------- --AAAAAAAAAE--------------- --AAAAAAAAAK--------------- --AAAAAAAAAD--------------- --AAAAAAAAAA--------------- --------AAAB--------------- --------AAAB--------------- --------AAAA--------------- 
--------------------------- --------------------------- --------------------------- --------------------------- --------------------------- --------------------------- --------------------------- --------------------------- --------------------------- --------------------------- --------------------------- --------------------------- --------------------------- --------------------------- --BBB----BBB--------------- --AAA----AAA--------------- --AAACCCCAAA--------------- --AAAAAAAAAA--------------- --AAAAAAAAAA--------------- --AAAAAAAAAA--------------- --AAAAAAAAAA--------------- --AAAAAAAAAA--------------- --AAAAAAAAAH--------------- --AAAAAAAAAH--------------- --AAAAAAAAAH--------------- --AAAAAAAAAD--------------- --AAAAAAAAAA--------------- --------AAAB--------------- --------AAAB--------------- --------AAAA--------------- 
--------------------------- --------------------------- --------------------------- --------------------------- --------------------------- --------------------------- --------------------------- --------------------------- --------------------------- --------------------------- --------------------------- --------------------------- --------------------------- --------------------------- --BBB----BBB--------------- --AAA----AAA--------------- --AAACCCCAAA--------------- --AAAAAAAAAA--------------- --AAAAAAAAAF--------------- --AAAAAAAAAF--------------- --AAAAAAAAAA--------------- --AAAAAAAAAA--------------- --AAAAAAAAAD--------------- --AAAAAAAEED--------------- --AAAAAAAAAD--------------- --AAAAAAAAAD--------------- --AAAAAAAAAA--------------- --------AAAB--------------- --------AAAB--------------- --------AAAA--------------- 
--------------------------- --------------------------- --------------------------- --------------------------- --------------------------- --------------------------- --------------------------- --------------------------- --------------------------- --------------------------- --------------------------- --------------------------- --------------------------- --------------------------- --BBB----BBB--------------- --AAA----AAA--------------- --AAACCCCAAA--------------- --AAAAAAAAAA--------------- --AAAAAAAAAF--------------- --AAAAAAAAAF--------------- --AAAAAAAAAA--------------- --AAAAAAAAAA--------------- --AAAAAAAAAA--------------- --AAAAAAAAAA--------------- --AAAAAAAAAA--------------- --AAAAAAAAAA--------------- --AAAAAAAAAA--------------- --------AAAA--------------- --------AAAA--------------- --------AAAA--------------- 
--------------------------- --------------------------- --------------------------- --------------------------- --------------------------- --------------------------- --------------------------- --------------------------- --------------------------- --------------------------- --------------------------- --------------------------- --------------------------- --------------------------- --------------------------- --------------------------- --------------------------- --------------------------- --------------------------- -----------G--------------- --------------------------- -----------G--------------- --------------------------- --------------------------- --------------------------- --------------------------- --------------------------- --------------------------- --------------------------- --------------------------- 
--------------------------- --------------------------- --------------------------- --------------------------- --------------------------- --------------------------- --------------------------- --------------------------- --------------------------- --------------------------- --------------------------- --------------------------- --------------------------- --------------------------- --------------------------- --------------------------- --------------------------- --------------------------- --------------------------- -----------G--------------- --------------------------- -----------G--------------- --------------------------- --------------------------- --------------------------- --------------------------- --------------------------- --------------------------- --------------------------- --------------------------- 
