model
size = 18 32 20, scale = 0.05, origin = -y
material 
  colors = A:#050 B:#222 C:#111 D:#070 E:#080 F:#0A0 G:#06C H:#EEE I:#FF0 J:#E00 K:#200 L:#FF3 M:#0B0 N:#020 O:#FF6 P:#960
voxels
8-2B16-2A16-FA16-FD16-AF16-2A16-AD16-2A16-AF16-EA16-2F16-2A16-2B356-6B12-6A12-A2F3A12-E2F3A12-6A12-E5A12-AFA2DA2(12-6A)12-3D2AD12-5AD12-6A12-6B353-8B10-8A2(10-DA4-AD)3(10-DA4-2A)10-2A4-AE2(10-2A4-2A)10-2A4-DA10-2A4-2A10-2B4-2B351-10B8-5A3G2A8-2A2(3-3G2D8-FD)6-AD8-FD6-2A8-2D6-2A2(8-2A6-DA)8-DA6-AE8-DA6-2A8-2A6-2A8-2B6-2B349-12B6-6AJ2H3A6-2A4-HGJ-2D6-2F4-3H-2D2(6-2F8-2A)6-2A8-2A6-FA2-A5-AE6-FA4M4-2A6-2A8-2A6-EA8-2A6-2A8-2A6-2B8-2B348-13B5-6AHJH4A5-A2(5-3H2-2D5-D)10-2A5-A10-AE5-A10-2D5-E10-2D5-A2-P7-2A5-A10-AF2(5-A10-2A)5-B10-2B346-14B4-7A2HJ4A4-2A5-JGH3-A4-2D5-3H3-A4-2D2(11-A4-2A)2(11-D4-2A)-2IL7-A4-EA2-L8-F2(4-2A11-A)4-2B11-B345-16B2-8A3G5A2-2A6-3G3-2A2-ED6-3G3-2A2-AD12-AD2-EA12-FD2-2A12-2D2-2A12-2(DA2-)2IL7-2(2A2-)OI8-2A2-FA12-AE2-2A12-2A2-2B12-2B344-16B2-8A3G5A2-2A2(6-3G3-2A2-AD)12-DA2-2A12-AF2-EA12-2(2A2-)3I7-2D2-2E2-3I7-2A2-2E2-L2I7-2(AE2-2A12-)DA2-2B12-2B345-14B4-14A4-A7-G4-2(A4-D12-)2(A4-A12-)A4-A3-I8-D4-E2-IPL7-A4-E3-O8-2(A4-A12-)A4-B12-B346-14B4-14A4-2E6-G3-AD4-ED10-2A4-2D10-AF4-FA4(10-2A4-2A)10-2A4-DA10-2D4-2A10-2A4-2B10-2B347-12B6-7AK4A6-EA4-3K-2D6-2A5-K2-2D6-2A8-2A6-2A8-AE6-2A8-2E6-DA2(8-2A6-2A)8-2A6-2E8-2D6-2A8-2A6-2B8-2B349-10B8-10A2(8-2A6-2D)8-2D6-2A8-2A6-2A8-FA6-AE2(8-2A6-2A)8-2A6-AD8-EA6-AD8-AB6-2A8-2B6-2B351-8B10-8A2(10-6A2D)10-E7A10-7AD10-4AF3A10-DAF5A10-D7A10-E7A10-4A2(FA)10-2B6A10-8B353-6B12-6A12-FA3(2CAD12-2A)2C2A12-AE2C2A12-2A2C2A12-AF2CAE12-2A2CAF12-2A2C2A12-BA2C2A12-6B356-2B2(16-2A)16-DF16-DA16-2A16-EA2(16-2A)16-2N16-2C16-2A16-2B519-4C14-4C68-4B12-8B9-B8AB7-B3AD6AB5-B5AFAE4AB3-B2AE7AF3AB2-B4A2D2AF5AB-2BAF2A2DFE3A2DA4B2ADA2D3ADA2DA4BAE7AD4A4B5AEAE2A2(FA)2B-B2A2E3AF3AD2AB3-BAFED7AFAB3-B2AD2A2D2AEAFB5-B3AE2AE3AB7-B2AF5AB9-8B12-4B176-C2-C14-C2-C68-4B15-2A14-ADAE2A11-2A4CAD9-2A6C2A7-EA8C2A5-2A10CDA4-A12CD3-2A12C2D2-DA12C2A3-A12CE4-2A10C2A5-2A8CDA7-DA6CAE9-AD4C2A11-2(2AD)14-2A195-C2-C14-C2-C50-C2-C14-4B50-4B13-6B11-3B2C3B9-3B4C3B7-3B6C3B2(6-2B8C2B)6-3B6C3B7-3B4C3B9-3B2C3B11-6B13-4B248-3(C2-C14-)C2-C105-2A15-AD2A13-3A2EA11-AE2A2E2A10-3AD2ADA11-3AE2A13-4A15-DA98-
