model
size = 30 6 10, scale = 0.05, origin = -y
material 
  colors = A:#111 B:#EEE C:#222 D:#00E E:#444 F:#777
voxels
------------------------------ ------------------------------ ------------------------------ ------------------------------ ------------------------------ ----CCCCCCCCCCCCCCCCCCCCCC---- 
-------D--------------D------- ------D-D------------D-D------ -------D--------------D------- ------------------------------ ----BBBBBBBBBBBBBBBBBBBBBB---- --CCAAAAAAAAAAAAAAAAAAAAAACC-- 
------------------------------ -------F--------------F------- ------------------------------ ------------------------------ --BBBBBBBBBBBBDDBBBDBBBBBBBB-- -CAAAAAAAAAAAAAAAAAAAAAAAAAAC- 
------------------------------ -------F--------------F------- -------E--------------E------- ------------------------------ -BBBBBEEEBBBDDBBBDDBBEEEBBBBB- CAAAAABABAAAAAAAAAAAABABAAAAAC 
------------------------------ ------------------------------ -------E--------------E------- -------E--------------E------- -BBBBBEBEBDDBBBDDBBBBEBEBBBBB- CAAAAAAAAAAAAAAAAAAAAAAAAAAAAC 
------------------------------ ------------------------------ -------E--------------E------- -------E--------------E------- -BBBBBEBEBBBBDDBBBDDBEBEBBBBB- CAAAAAAAAAAAAAAAAAAAAAAAAAAAAC 
------------------------------ -------F--------------F------- -------E--------------E------- ------------------------------ -BBBBBEEEBBDDBBBDDBBBEEEBBBBB- CAAAAABABAAAAAAAAAAAABABAAAAAC 
------------------------------ -------F--------------F------- ------------------------------ ------------------------------ --BBBBBBBBDBBBDDBBBBBBBBBBBB-- -CAAAAAAAAAAAAAAAAAAAAAAAAAAC- 
-------D--------------D------- ------D-D------------D-D------ -------D--------------D------- ------------------------------ ----BBBBBBBBBBBBBBBBBBBBBB---- --CCAAAAAAAAAAAAAAAAAAAAAACC-- 
------------------------------ ------------------------------ ------------------------------ ------------------------------ ------------------------------ ----CCCCCCCCCCCCCCCCCCCCCC---- 
