model
size = 32 17 23, scale = 0.05, origin = -y
material 
  colors = A:#0B0 B:#050 C:#0D0 D:#663 E:#555 F:#E00 G:#BBB
voxels
22-2B2(30-2C29-2C)28-4C28-2C335-2B17-2B11-2C17-2C12-2C15-2C13-2C14-2C15-2C13-2C15-4C2-5A2-4C17-C8B4C21-BA5B2C24-2A3B28-3B245-2B30-2(2C31-)2C30-2C4-6A20-4C2A5-2A21-4C6-C21-2B2C5-2C21-B2A5-3B22-B2A3-3B24-2A5B26-BA3B284-6A24-2A6-2A21-A9-A19-B2-C8-B19-B2-2C7-B19-B11-B19-BA9-2B20-2B7-2B22-2B5-2B24-4A3B249-10A21-A10-A18-2A11-A4(17-B13-B)18-B11-B19-2B9-2B20-2B7-2B23-A2BA3B216-11A19-2A11-A17-A14-A5(15-B)15-A15-B15-A16-B13-B17-B13-A18-B11-B20-2A7-2B23-A2B4A183-13A18-A12-A17-2(A14-)2(B17-B13-)B17-B14-3(B15-)A16-B13-B17-B13-A18-2A9-2A21-2A5-2A25-A4B151-14A17-A14-A15-A16-A4(13-B17-B)14-3(B15-)B16-B13-B18-A11-A20-2B7-2A23-B2AB3A149-16A15-A16-A13-A18-A2(11-B19-B)12-2(B17-B13-)B17-B14-3(B15-)B16-A13-A18-2B9-BA21-3B3-2AB26-B2A119-16A15-A16-A13-A18-A11-B19-B11-B31-B19-B2-5C5-B17-B4-4C5-B17-B5-3C5-B17-B14-B15-B16-A13-A18-B11-B20-3B5-3B24-B3AB117-18A13-A18-A11-A17-6C8-B17-8C6-A17-10C4-A22-C3-C2E2-A19-B2-C3-3C3-A17-B7-3C3-B17-A6-CF6-B15-A16-A13-A18-B11-B20-2B7-2B23-B3A3B116-18A13-A18-A11-A17-8C4-3C17-9C5-A17-10C4-A21-3C2-2CE2-A19-A2-2C2-CGC3-A17-A7-3C3-B17-A5-4CE4-B15-A16-A13-A18-B11-B20-BA7-2B23-3A4B116-18A13-A18-A11-A17-6C8-B17-8C6-B17-9C5-B22-2C2-C2E2-B19-B6-3C3-A17-B7-3C3-A17-B6-CF6-A15-B16-A13-A18-B11-B20-BA7-2B23-4A3B116-18A13-A18-A11-A31-B19-B11-B31-B19-B3-4C5-B17-B4-4C5-B17-B5-3C5-B17-B14-A15-B16-A13-A18-B11-B20-3B5-3B24-3A2B117-18A13-A18-A11-A31-B19-B11-B19-B12-2(B17-B13-)B17-B14-3(B15-)B16-A13-A18-BA9-2B21-B2A3-A2B26-2BA118-18A13-2(A18-A12-)3(B17-B13-)B17-B14-3(B15-)B16-B13-B18-A11-A20-2A7-AB23-A4B2A149-16A15-A16-A13-A18-A12-2(B17-B13-)B17-B14-3(B15-)B16-B13-B17-B13-B18-2A9-BA21-BA5-BA25-5B150-16A15-A16-A13-2A17-A13-7(B15-)B16-B13-B17-B13-B18-B11-B20-AB7-AB23-7B183-14A16-2A6-C23-A14-A16-3(B13-B17-)B13-B18-B11-A19-BA9-2A20-AB7-2A23-2B2AB2A217-12A18-2A29-2A11-B18-B2-C8-B19-B2-2C7-B19-B11-A19-BA9-BA20-2A7-2B22-2A5-2B24-BA5B147-2B30-2(2C31-)2C4-6A20-2C2-2A6-2A18-2C2D30-2D2C6-C21-AB2C5-2C21-2AB5-3B22-2AB3-3B24-A6B26-A4B180-2B17-2B11-2C17-2C12-2C15-2C13-2C14-2C15-2C4-6A3-2C15-2C2D7AC-4C17-D8B4C21-7B2C24-5B28-3B264-2B2(30-2C29-2C)28-4C28-2C332-
