model
size = 32 11 15, scale = 0.05, origin = -y
material 
  colors = A:#03F
voxels
225-A28-A322-A28-A2-9(A28-A322-)A28-A290-A28-A2-A28-A290-A28-A322-A28-A103-6A8-6A11-3(A6-)A9-A8-A4-A8-A7-A9-A4-A9-A5-A11-A2-A11-A4-A11-4A11-A4-A9-2A4-2A9-A3-2A7-2A8-2A7-2A2-9A12-9A2-4A22-4A-A30-A
