model
size = 27 25 28, scale = 0.05, origin = -y
material 
  colors = A:#606 B:#FFA850 C:#609 D:#222 E:#E00 F:#639 G:#FC0 H:#FF0 I:#F96 J:#F63 K:#D00 L:#B00 M:#FF3 N:#CC0
voxels
--------------------------- --------------------------- --------------------------- --------------------------- --------------------------- --------------------------- --------------------------- ---------------------H----- --------------------------- --------------------------- --------------------------- --------------------------- --------------------------- --------------------------- --------------------------- --------------------------- --------------------------- --------------------------- --------------------------- --------------------------- --------------------------- --------------------------- --------------------------- --------------------------- --------------------------- 
----------DDDDDDD---------- ----------BBBBBBB---------- ----------BBBJIBB---------- ----------BIBIIBI---------- --------------------------- --------------------------- ---------------------H----- ---------------------H----- ---------------------H----- --------------------------- --------------------------- --------------------------- --------------------------- --------------------------- --------------------------- --------------------------- --------------------------- --------------------------- --------------------------- --------------------------- --------------------------- --------------------------- --------------------------- --------------------------- --------------------------- 
-------DDDDDDDDDDDDDD------ -------BBJBBBBBBBBBBB------ -------BJJBBBBBBBBJBB------ -------BBIBBBBBBIIBIB------ ---------------------H----- ---------------------H----- ---------------------H----- ---------------------H----- ---------------------H----- ---------------------H----- --------------------------- --------------------------- --------------------------- --------------------------- --------------------------- --------------------------- --------------------------- --------------------------- --------------------------- --------------------------- --------------------------- --------------------------- --------------------------- --------------------------- --------------------------- 
-----DDDDDDDDDDDDDDDD------ -----BBBBBBBBBBBBBBBB------ -----IBBBBBBBBBBBBBBB------ -----IIIJJBBBBBBBBBBB------ --------------------------- ---------------------H----- ---------------------H----- ---------------------E----- ---------------------H----- ---------------------H----- ---------------------H----- --------------------------- --------------------------- --------------------------- --------------------------- --------------------------- --------------------------- --------------------------- --------------------------- --------------------------- --------------------------- --------------------------- --------------------------- --------------------------- --------------------------- 
----DDDDDDDDDDDDDDDDDDDD--- ----BBBBBBBAAAAAAABBBBBB--- ----BBBBBBBAAAAAAABBBJIJ--- ----BJBBJJBAAAAAAABBBIBI--- -----------EEEEEEE---H----- -----------LEKKLKK---H----- -----------LEEELEE---H----- -----------GMGMGMG---H----- -----------AFAAAAA---H----- -----------AFFFFFC---H----- -----------FAACCFC--------- -----------AFCCCCC--------- -----------CCCAFFA--------- -----------CAACAAC--------- -----------AAAFCAC--------- --------------------------- --------------------------- --------------------------- --------------------------- --------------------------- --------------------------- --------------------------- --------------------------- --------------------------- --------------------------- 
---DDDDDDDDDDDDDDDDDDDDD--- ---BBBBBBAAAAAAAAAAABBBB--- ---JBBBBBAAAAAAAAAAABBBB--- ---IBBBBBAAAAAAAAAAABBBI--- ---------LEEEEEEEEEE------- ---------KEEEEEEEELE------- ---------EEEEEEEEEEE-H----- ---------GMGGGGGGGGG-H----- ---------AAAAAAAAAAA-H----- ---------CAAAAAAAAAA------- ---------CAAAAAAAACC------- ---------AAAAAAAAAFF------- ---------FFAAAAAAAFF------- ---------FFAAAAAAACC------- ---------AAAACCCACAC------- --------------------------- --------------------------- --------------------------- --------------------------- --------------------------- --------------------------- --------------------------- --------------------------- --------------------------- --------------------------- 
---DDDDDDDDDDDDDDDDDDDDD--- ---BBBBBAAAAAAAAAAAAABBB--- ---BBBBBAAAAAAAAAAAAABBB--- ---BBJJBAAAAAAAAAAAAABBI--- --------EEEAAAAAEEAAK------ --------LEEAAAAAEEAAL------ --------EEEAAAAAEEAAE------ --------GGGAAAAAGGGGGH----- --------FAAAAAAAAAAAA------ --------FAAAAAAAAAAAA------ --------AAAAAAAAAAAAC------ --------CAAAAAAAAAAAC------ --------AAAAAAAAAAAAA------ --------FAAAAAAAAAAAC------ --------AACCAAAAAAAAC------ --------------------------- --------------------------- --------------------------- --------------------------- --------------------------- --------------------------- --------------------------- --------------------------- --------------------------- --------------------------- 
--DDDDDDDDD-----DDDDDDDDD-- --BBBBBAAAA-----AAAAAABBB-- --BBBBBAAAA-----AAAAAABBB-- --BBBBBAAAA-----AAAAAABBB-- -------EEAA-----AAAAKK----- -------LEAA-----AAAAEK----- -------EEAA-----AAAAEL----- -------GGAA-----AAGGGG----- -------FFAA-----AAAAAA----- -------FFAA-----AAAAAA----- -------AAAA-----AAAACC----- -------AAAA-----AAAAAA----- -------AAAAAAAAAAAAAAA----- -------FFAABBBBBAAAAAC----- -------AAACCAAAAAAFAAC----- --------------------------- --------------------------- --------------------------- --------------------------- --------------------------- --------------------------- --------------------------- --------------------------- --------------------------- --------------------------- 
-DDDDDDDD---------DDDDDDDDD -BBBBBAAA---------AAAAABBBB -JBBBBAAA---------AAAAABBBB -JBBBBAAA---------AAAAABBBI ------EAA---------AAEEE---- ------KAA---------AAEEE---- ------EAA---------AAEEE---- ------MGA---------AGGGG---- ------AAA---------AAAAA---- ------CCA---------AAAAC---- ------AAA---------AAAAA---- ------AAA---------AAAAA---- ------AAAAAAAAAAAAAAAAC---- ------FAABBBBBBBBBAAAAA---- ------AACAAAFACFAAAAAAA---- --------------------------- --------------------------- --------------------------- --------------------------- --------------------------- --------------------------- --------------------------- --------------------------- --------------------------- --------------------------- 
-DDDDDDD-----------DDDDDDDD -BBBBAAA-----------AAAAABBB -JBBBAAA-----------AAAAABBB -JJBBAAA-----------AAAAABIB -----EEA-----------AEEEE--- -----LEA-----------AEEEL--- -----EEA-----------AEEEE--- -----GAA-----------AAAGG--- -----AAA-----------AAAAA--- -----FAA-----------AAAAA--- -----CAA-----------AAAAC--- -----CAA-----------AAAAC--- -----AAAAAAAAAAAAAAAAAAA--- -----FFABBBBBBBBBBBAAAAA--- -----AAACCCAAACCCCACCCAC--- --------------------------- --------------------------- --------------------------- --------------------------- --------------------------- --------------------------- --------------------------- --------------------------- --------------------------- --------------------------- 
-DDDDDD-------------DDDDDDD -BBBBAA-------------AAAABBB -JBBBAA-------------AAAABBB -JIBBAA-------------AAAABBB -----EA-------------AEEE--- -----EA-------------AEEE--- -----EA-------------AEEE--- -----GA-------------AAGG--- -----AA-------------AAAA--- -----CA-------------AAAA--- -----CA-------------AAAC--- -----CA-------------AAAC--- -----AAAAAAAAAAAAAAAAAAA--- -----AABBBBBBBBBBBBBAAAA--- -----AFFAFFACCACCAACCACC--- --------------------------- --------------------------- --------------------------- --------------------------- --------------------------- --------------------------- --------------------------- --------------------------- --------------------------- --------------------------- 
DDDDDDD-------------DDDDDDD BBBBAAA-------------AABBBBB IBBBAAA-------------AABBBBB BBBBAAA-------------AABBBBB ----EEA-------------AEEEE-- ----EEA-------------AEEEK-- ----EEA-------------AEEEE-- ----GGA-------------AAGGG-- ----AAA-------------AAAAA-- ----CCA-------------AAAAA-- ----CCA-------------AAAAA-- ----FCA-------------AAAAC-- ----FAAAAAAAAAAAAAAAAAAAC-- ----AAABBBBBBBBBBBBBAAAAA-- ----AFAAAACAAAAAAAACCAAAF-- --------------------------- --------------------------- --------------------------- --------------------------- --------------------------- --------------------------- --------------------------- --------------------------- --------------------------- --------------------------- 
DDDDDD---------------DDDDDD BBBBAA---------------ABBBBB BBIBAA---------------ABBBBB ----BA---------------AAAB-- ----LA---------------AEEE-- ----EA---------------AEEK-- ----EA---------------AEEL-- ----GA---------------AGGG-- ----AA---------------AAAA-- ----AA---------------AAAF-- ----AA---------------AAAA-- ----AA---------------AAAC-- ----AAAAAAAAAAAAAAAAAAAAA-- ----AABBBBBBBBBBBBBBBAAAA-- ----AACCCAAAFFAAAAAFFAAAA-- --------------------------- --------------------------- --------------------------- --------------------------- --------------------------- --------------------------- --------------------------- --------------------------- --------------------------- --------------------------- 
DDDDDD---------------DDDDDD BBBBAA---------------ABBBBB ----BA---------------AAAB-- ----BA---------------AAAB-- ----LA---------------AEEE-- ----LA---------------AEEK-- ----EA---------------AEEE-- ----MA---------------AGGG-- ----AA---------------AAAA-- ----AA---------------AAAF-- ----AA---------------AAAA-- ----AA---------------AAAA-- ----AAAAAAAAAAAAAAAAAAAAA-- ----AABBBBBBBBBBBBBBBAAAF-- ----FACCCAAAAAAFCAACFFCAC-- --------------------------- --------------------------- --------------------------- --------------------------- --------------------------- --------------------------- --------------------------- --------------------------- --------------------------- --------------------------- 
DDDDDD---------------DDDDDD ----BA---------------AAAB-- ----BA---------------AAAB-- ----BA---------------AAAB-- ----EA---------------AEEE-- ----KA---------------AEEL-- ----EA---------------AEEE-- ----GA---------------AGGG-- ----CC---------------CCCC-- ----CC---------------CCCC-- ----CC---------------CCCC-- ----CC---------------CCCC-- ----CCCCCCCCCCCCCCCCCCCCC-- ----CCCCCCCCCCCCCCCCCCCCC-- ----CCCCCCCCCCCCCCCCCCCCC-- --------------------------- --------------------------- --------------------------- --------------------------- --------------------------- --------------------------- --------------------------- --------------------------- --------------------------- --------------------------- 
DDDDDD---------------DDDDDD IBIBAA---------------ABBBBB ----BA---------------AAAB-- ----BA---------------AAAB-- ----EA---------------AEEE-- ----LA---------------AEEE-- ----EA---------------AEEE-- ----MA---------------AGGG-- ----CC---------------CCCC-- ----CC---------------CCCC-- ----CC---------------CCCC-- ----CC---------------CCCC-- ----CCCCCCCCCCCCCCCCCCCCC-- ----CCCCCCCCCCCCCCCCCCCCC-- ----CCCCCCCCCCCCCCCCCCCCC-- --------------------------- --------------------------- --------------------------- --------------------------- --------------------------- --------------------------- --------------------------- --------------------------- --------------------------- --------------------------- 
DDDDDD---------------DDDDDD IBBBAA---------------ABBBBI IBIIAA---------------ABBBBI ----BA---------------AAAB-- ----EA---------------AEEE-- ----KA---------------AEEK-- ----EA---------------AEEE-- ----GA---------------AGGG-- ----FF---------------FFFF-- ----FF---------------FFFF-- ----FF---------------FFFF-- ----FF---------------FFFF-- ----FFFFFFFFFFFFFFFFFFFFF-- ----FFFFFFFFFFFFFFFFFFFFF-- ----FFFFFFFFFFFFFFFFFFFFF-- --------------------------- --------------------------- --------------------------- --------------------------- --------------------------- --------------------------- --------------------------- --------------------------- --------------------------- --------------------------- 
DDDDDDD-------------DDDDDDD BBBBAAA-------------AABBBBI BBBBAAA-------------AABBBBI BBBBAAA-------------AABBBBB ----EEA-------------AEEEE-- ----EEA-------------AEEEE-- ----EEA-------------AEEEL-- ----GGA-------------AGGGG-- ----AAA-------------AAAAC-- ----CCC-------------CCCCC-- ----CCC-------------CCCCC-- ----CCC-------------CCCCC-- ----CCCCCCCCCCCCCCCCCCCCC-- ----CCCCCCCCCCCCCCCCCCCCC-- ----CCCCCCCCCCCCCCCCCCCCC-- --------------------------- --------------------------- --------------------------- --------------------------- --------------------------- --------------------------- --------------------------- --------------------------- --------------------------- --------------------------- 
-DDDDDDD------------DDDDDDD -BBBBAA-------------AAAABBB -BBBBAA-------------AAAABBI -IJBBAA-------------AAAABBB -----EA-------------AEEE--- -----EA-------------AEEE--- -----EA-------------AEEE--- -----GA-------------AGGG--- -----AA-------------AAAA--- -----AA-------------AAAA--- -----AA-------------AAAA--- -----AA-------------AAAA--- -----AAAAAAAAAAAAAAAAAAA--- -----AABBBBBBBBBBBBBAAAA--- -----AAAAAAAAAFAAAAACAAA--- --------------------------- --------------------------- --------------------------- -------------------N------- --------------------------- -------------------M------- --------------------------- --------------------------- --------------------------- --------------------------- 
-DDDDDDD-----------DDDDDDDD -BBBBAAA-----------AAAAABBB -BBBBAAA-----------AAAAABBB -IIBBAAA-----------AAAAABBB -----LEA-----------AEEEE--- -----EEA-----------AEEKK--- -----EEA-----------AEEKK--- -----MGA-----------AGGGG--- -----AAA-----------AAAAA--- -----AAA-----------AAAAA--- -----AAA-----------AAAAA--- -----AAA-----------AAAAA--- -----CAAAAAAAAAAAAAAAAAA--- -----CCABBBBBBBBBBBAAAAA--- -----AAAAAAAAAACCCAACAAA--- --------------------------- --------------------------- -------------------M------- -------------------H------- -------------------H------- -------------------H------- -------------------M------- --------------------------- --------------------------- --------------------------- 
-DDDDDDDD---------DDDDDDDDD -BBBBBAAA---------AAAAABBBB -IIBBBAAA---------AAAAABJJI -IIBBBAAA---------AAAAABBBJ ------EEA---------AEEEE---- ------EEA---------AEEEK---- ------EEA---------AEEEK---- ------GGA---------AGGGG---- ------AAA---------AAAAA---- ------FAA---------AAAAA---- ------AAA---------AAAAA---- ------AAA---------AAAAC---- ------AAAAAAAAAAAAAAAAC---- ------CAABBBBBBBBBAAAAA---- ------FCCCCCCAACFAAAFAA---- --------------------------- -------------------H------- -------------------H------- -------------------H------- -------------------N------- -------------------H------- -------------------N------- -------------------H------- --------------------------- --------------------------- 
--DDDDDDDDD-----DDDDDDDDD-- --BBBBBAAAA-----AAAAAABBB-- --IBBBBAAAA-----AAAAAABBJ-- --IJIIBAAAA-----AAAAAABBB-- -------EEAA-----AAAEEE----- -------LEAA-----AAAEKK----- -------EEAA-----AAAEEE----- -------GGAA-----AAAGGG----- -------AAAA-----AAAAAA----- -------AAAA-----AAACCC----- -------AAAA-----AAACCC----- -------AAAA-----AAAAAA----- -------AAAAAAAAAAAAHAA----- -------AAAABBBBBAAAHAC----- -------AACCCCAACAAAHFA----- -------------------H------- -------------------H------- -------------------N------- -------------------E------- -------------------H------- -------------------E------- -------------------H------- -------------------M------- -------------------H------- --------------------------- 
---DDDDDDDDDDDDDDDDDDDDD--- ---BBBBBAAAAAAAAAAAAABBB--- ---BBBBBAAAAAAAAAAAAABBB--- ---JBBBBAAAAAAAAAAAAABBI--- --------EEEAAAAAAAAEE------ --------EEEAAAAAAAAEK------ --------EEEAAAAAAAAEE------ --------MAAAAAAAAAAGG------ --------AAAAAAAAAAAAA------ --------AAAAAAAAAAACC------ --------CCAAAAAAAAACC------ --------CCAAAAAAAAAAA------ --------FFAAAAAAAAAHA------ --------AAAAAAAAAAAHA------ --------AAAAACACAAFHA------ -------------------N------- -------------------H------- -------------------M------- -------------------H------- -------------------E------- -------------------H------- -------------------N------- -------------------H------- -------------------N------- -------------------M------- 
---DDDDDDDDDDDDDDDDDDDDD--- ---BBBBBBAAAAAAAAAAABBBB--- ---BBBBBBAAAAAAAAAAABBBI--- ---JBBIBBAAAAAAAAAAABBJJ--- ---------ELEEEEEEEEE------- ---------LKKKEEEEEEE------- ---------EEEEEEEEEEE------- ---------GGGGGGGGGGG------- ---------AAAAAAAAAAA------- ---------AAAAAAAAAAC------- ---------CAAAAAAAAAC------- ---------CAAAAAAACCA------- ---------FAAAAAAAAAH------- ---------AAAAAAAAAAN------- ---------AAAAAACAAAH------- -------------------H------- -------------------N------- -------------------H------- -------------------E------- -------------------H------- -------------------E------- -------------------H------- -------------------M------- -------------------H------- --------------------------- 
----DDDDDDDDDDDDDDDDDDD---- ----BBBBBBBAAAAAAABBBBB---- ----BBBBBBBAAAAAAABBBBB---- ----JIBBBBBAAAAAAABBBJB---- -----------EEEEEEE--------- -----------KKKLEKK--------- -----------EEELEEE--------- -----------GMGGMGG--------- -----------AACCAAA--------- -----------CCAAAAA--------- -----------CCAFAAA--------- -----------AAAAAAC--------- -----------ACFAAAC--------- -----------AFAAAAA--------- -----------AAFAAAC--------- --------------------------- -------------------H------- -------------------H------- -------------------N------- -------------------M------- -------------------H------- -------------------N------- -------------------H------- --------------------------- --------------------------- 
------DDDDDDDDDDDDDDD------ ------BBBBBBBBBBBBBBB------ ------BBBBBBBBBBBBBBB------ ------BBJBBBBIBBBBBJI------ --------------------------- --------------------------- --------------------------- --------------------------- --------------------------- --------------------------- --------------------------- --------------------------- --------------------------- --------------------------- --------------------------- --------------------------- --------------------------- -------------------H------- -------------------M------- -------------------H------- -------------------M------- -------------------H------- --------------------------- --------------------------- --------------------------- 
------DDDDDDDDDDDDDD------- ------BBBBBBBBBBBBBB------- ------BBBBBBBBBBBBJB------- ------BIBIIJBIBBBJBI------- --------------------------- --------------------------- --------------------------- --------------------------- --------------------------- --------------------------- --------------------------- --------------------------- --------------------------- --------------------------- --------------------------- --------------------------- --------------------------- --------------------------- -------------------H------- --------------------------- -------------------N------- --------------------------- --------------------------- --------------------------- --------------------------- 
----------DDDDDDD---------- ----------BBBJBBB---------- ----------BBBIJJB---------- ----------BBBIJBI---------- --------------------------- --------------------------- --------------------------- --------------------------- --------------------------- --------------------------- --------------------------- --------------------------- --------------------------- --------------------------- --------------------------- --------------------------- --------------------------- --------------------------- --------------------------- --------------------------- --------------------------- --------------------------- --------------------------- --------------------------- --------------------------- 
