model
size = 29 28 5, scale = 0.05, origin = -y
material 
  colors = A:#FF0 B:#111 C:#FC0 D:#FF3 E:#FF6
voxels
-----B-----------------B----- -----BB---------------BB----- -----BABB-----------BBAB----- -----BAAAB---------BAADB----- ------BACAB-------BAADB------ ------BAADABB---BBAAAAB------ -------BCEAAABBBAACAAB------- -------BAAAACAAAAAAACB------- -------BADAAABBBAAAAAB------- --------BAAABAAABAAAB-------- ------BBAAADAAAAACAEEBB------ -----BAACAAEADACADDAAAAB----- ----BAAAAAAAAEAAAAAADAAAB---- ---BAACAABBBAADAABBBAACAAB--- ---BEEAABABABAAABABABAAEAB--- --BAEECAADAAAAAAAAADDACADAB-- -BAAAAAAEABBACADBABBAAAAAAAB- BBBBBBBBBBAAAAAAAAABBBBBBBBBB ----------BDDADEACB---------- ----------BAAAADAAB---------- -----------BCCAAAB----------- -----------BCCACAB----------- ------------BAAAB------------ ------------BADAB------------ -------------BAB------------- -------------BAB------------- --------------B-------------- --------------B-------------- 
----AAA---------------AAA---- ----AAACA-----------CAAAA---- ----CAAAAA---------AAAAAC---- ----CAAAAAA-------AAAAAAA---- -----AAAAAAAC---ACAAAAAA----- -----AAAAAAAAAAAAAAAAAAC----- ------AAAAAAAAAAAAAAAAA------ ------CAAAAAAAAAAAAAAAA------ ------CAAAAAAAAAAAAAAAC------ ------CAAAAAAAAAAAAAAAD------ -----AAAAAAAAAAAAAAAAAAA----- ----CAAAAAAAAAAAAAAAAAAAC---- ---AAAAAAAAAAAAAAAAAAAAAAA--- --AAAAAAAAAAAAAAAAAAAAAAAAA-- --CAAAAAAAAAAAAAAAAAAAAAAAC-- -AAAAAAAAAAAAAAAAAAAAAAAAAAA- AAAAAAAAAAAAAAAAAAAAAAAAAAAAA AAAAAAAAAAAAAAAAAAAAAAAAAAAAA ACDCCDAECAAAAAAAAAADACADCDACA ----------AAAAAAAAA---------- ----------AAAAAAAAA---------- -----------AAAAAAA----------- -----------CAAAAAA----------- ------------AAAAA------------ ------------DAAAC------------ -------------AAA------------- -------------DAC------------- --------------A-------------- 
----BBB---------------BBB---- ----BBBBB-----------BBBBB---- ----BBBBBB---------BBBBBB---- ----BBBBBBB-------BBBBBBB---- -----BBBBBBBB---BBBBBBBB----- -----BBBBBBBBBBBBBBBBBBB----- ------BAAAAAAAAAAAAAAAB------ ------BAAAAAAAAAAAAAAAB------ ------BAAAAAAAAAAAAAAAB------ ------BAAAAAAAAAAAAAAAB------ -----BBAAAAAAAAAAAAAAABB----- ----BBAAAAAAAAAAAAAAAABBB---- ---BBBAAAAAAAAAAAAAAAABBBB--- --BBBBAAAAAAAAAAAAAAAABBBBB-- --BBBBAAAAAAAAAAAAAAAABBBBB-- -BBBBBAAAAAAAAAAAAAAAABBBBBB- BBAAAAAAAAAAAAAAAAAAAABBBBBBB BBAAAAAAAAAAAAAAAAAAAABBBBBBB BBBBBBBBBBBBBBAAAABBBBBBBBBBB ----------BBBBAAAAB---------- ----------BBBBAAAAB---------- -----------BBBBBBB----------- -----------BBBBBBB----------- ------------BBBBB------------ ------------BBBBB------------ -------------BBB------------- -------------BBB------------- --------------B-------------- 
----CAA---------------AAA---- ----AAAAC-----------CAAAE---- ----AAAAAA---------CCAAAE---- ----CAAAAAA-------CCCAAAA---- -----AAAAAAAA---CCCCCAAA----- -----AAAAAAAACAAAAAAAAAA----- ------AAAAAAAAAAAAAAAAA------ ------AAAAAAAAAAAAAAAAE------ ------CAAAAAAAAAAAAAAAA------ ------AAAAAAAAAAAAAAAAC------ -----AAAAAAAAAAAAAAAAAAA----- ----AAAAAAAAAAAAAAAAAAAAA---- ---AAAAAAAAAAAAAAAAAAAAAAC--- --AAAAAAAAAAAAAAAAAAAAAAAAE-- --CAAAAAAAAAAAAAAAAAAAAAAAE-- -AAAAAAAAAAAAAAAAAAAAAAAAAAA- AAAAAAAAAAAAAAAAAAAAAAAAAAAAC AAAAAAAAAAAAAAAAAAAAAAAAAAAAA CACAAAACAAAAAAAAAAAEACCCCCAEA ----------AAAAAAAAA---------- ----------AAAAAAAAE---------- -----------AAAAAAC----------- -----------AAAAAAC----------- ------------AAAAA------------ ------------AAAAA------------ -------------AAA------------- -------------AAA------------- --------------C-------------- 
-----B-----------------B----- -----BB---------------BB----- -----BABB-----------BBAB----- -----BAAAB---------BAAAB----- ------BDAAB-------BADAB------ ------BAAAABB---BBADDAB------ -------BAEEAABBBAAACAB------- -------BAEBAAAAAAABEAB------- -------BAAABABBBABAAAB------- --------BADABAAABAAAB-------- ------BBAADAAACACAAAABB------ -----BAAAAAAADDAAEAAEAAB----- ----BAAAEAAAACAAAAAADDAAB---- ---BAAAAABBBAADEEBBBAAAAAB--- ---BACDABABABAAABABABAEEAB--- --BAAEEAAAAAAADAAAAAACCDAAB-- -BACDAAEEBBBAEAACBBBAAAAAAAB- BBBBBBBBBBAEEAADCCABBBBBBBBBB ----------BEECAECAB---------- ----------BAAAAAAAB---------- -----------BADCADB----------- -----------BAADAAB----------- ------------BADAB------------ ------------BEEAB------------ -------------BAB------------- -------------BAB------------- --------------B-------------- --------------B-------------- 
