model
size = 22 30 5, scale = 0.05, origin = -y
material 
  colors = A:#200505 B:#372F7C C:#2F6ED4 D:#309 E:#2A6A9C F:#6868FF G:#545759 H:#2C0D09
voxels
BBBBBBBBBBBBBBBBBBBBBB BCCCCCCCCCCCCCCCCCCCCB BCDDDDDDDDDDDDDDDDDFCB BCDDFFFFDDDDFFFFDDFDCB BCDFDDDDFDDFDDDDFDDFCB BCDFDDDDFDDFDDDDFDFDCB BCDFDDDDFDDFDDDDFDDFCB BCDDDDDDDDDDDDDDDDFDCB BCDDDDFFFDDDFFFFFDDFCB BCFDDDFDDDDDDDFDDDFDCB BCDFDDDDDDDDDDFFFDDFCB BCFDDDFFFDFDDDDDDDFDCB BCDFDDDDFDFDDDFFFDDFCB BCFDDDFFFFFDDDFDFDFDCB BCDFDDDDDDDDDDFFFDDFCB BCFDDDFFFFFDDDDDDDFDCB BCDFDDFDFDDDDDFFFDDFCB BCFDDDFFFGGGGGGGGGGGGG BCDFDDDDDG------------ BCFDDDDFGG------------ BCDFDDFFG------------- BCFDDDDFG------------- BCDFDDDGG------------- BCFDDDDG-------------- BCDFDDGG-------------- BCFDDDG--------------- BCDFDDG--------------- BCFDDGG--------------- BCCCCG---------------- BBBBBG---------------- 
BCCCCCCCCCCCCCCCCCCCCB CBBBBBBBBBBBBBBBBBBBBC CBAAAAABAAAAAABAAAAABC CBAAAAABAAAAAABAAAAABC CBBBBBBBBBBBBBBBBBBBBC CBAAAAABAAAAAABAAAAABC CBAAAAABAAAAAABAAAAABC CBAAAAABAAAAAABAAAAABC CBBBBBBBBBBBBBBBBBBBBC CBAAAAABAAAAAABAAAAABC CBAAAAABAAAAAABAAAAABC CBAAAAABAAAAAABAAAAABC CBBBBBBBBBBBBBBBBBBBBC CBAAAAABAAAAAABAAAAABC CBAAAAABAAAAAABAAAAABC CBAAAAABAAAAAABAAAAABC CBBBBBBBBBBBBBBBBBBBGC CBBBBAABAAAAAAGAAAAA-G CBBBBAABAAAAAA-AAAAA-- CBBBBAABAAHHHH-HHHHH-- CBBBBBBBB------------- CBBBBAABAHHHHH-HHHHH-- CBBBBAABAAAAAA-AAAAA-- CBBBBAABHHHHHH-HHHHH-- CBBBBBBG-------------- CBBBBAA-HHHHHH-------- CBBBBAA-AAAAAA-------- CBBBBAA-HHHHHH-------- CBBBBG---------------- BCCCCG---------------- 
BCEEEEECCCCCCCCEEEEECB CAAAAAAAAAAAAAAAAAAAAC EAAAAAAAAAAAAAAAAAAAAE EAAAAAAAAAAAAAAAAAAAAE EAAAAAAAAAAAAAAAAAAAAE CAAAAAAAAAAAAAAAAAAAAC CAAAAAAAAAAAAAAAAAAAAC CAAAAAAAAAAAAAAAAAAAAC CAAAAAAAAAAAAAAAAAAAAC CAAAAAAAAAAAAAAAAAAAAC EAAAAAAAAAAAAAAAAAAAAE EAAAAAAAAAAAAAAAAAAAAE EAAAAAAAAAAAAAAAAAAAAE EAAAAAAAAAAAAAAAAAAAAE EAAAAAAAAAAAAAAAAAAAAE EAAAAAAAAAAAAAAAAAAAAE EAAAAAAAAAAAAAAAAAAAAE EBBBBAAAAAAAAAAAAAAAAG EBBBBAAAAAAAAAAAAAAAA- EBBBBAAAAAAAAAAAAAAAA- EBBBBAAAAAAAAAAAAAAAA- EBBBBAAAAAAAAAAAAAAAA- EBBBBAAAAAAAAAAAAAAAA- CBBBBAAAAAAAAAAAAAAAA- EBBBBAAAAAAAAAAAAAAAA- EBBBBAAAAAAAAAA------- EBBBBAAAAAAAAAA------- CBBBBAAAAAAAAAA------- CBBBBAAAAAAAAAA------- BCEEEG---------------- 
BCCCCCCCCCCCCCCCCCCCCB CAAAAAAAAAAAAAAAAAAAAC CAAAAAAAAAAAAAAAAAAAAC CAAAAAAAAAAAAAAAAAAAAC CAAAAAAAAAAAAAAAAAAAAC CAAAAAAAAAAAAAAAAAAAAC CAAAAAAAAAAAAAAAAAAAAC CAAAAAAAAAAAAAAAAAAAAC CAAAAAAAAAAAAAAAAAAAAC CAAAAAAAAAAAAAAAAAAAAC CAAAAAAAAAAAAAAAAAAAAC CAAAAAAAAAAAAAAAAAAAAC CAAAAAAAAAAAAAAAAAAAAC CAAAAAAAAAAAAAAAAAAAAC CAAAAAAAAAAAAAAAAAAAAC CAAAAAAAAAAAAAAAAAAAAC CAAAAAAAAAAAAAAAAAAAAC CBBBBAAAAAAAAAAAAAAAAG CBBBBAAAAAAAAAAAAAAAA- CBBBBAAAAAAAAAAAAAAAA- CBBBBAAAAAAAAAAAAAAAA- CBBBBAAAAAAAAAAAAAAAA- CBBBBAAAAAAAAAAAAAAAA- CBBBBAAAAAAAAAAAAAAAA- CBBBBAAAAAAAAAAAAAAAA- CBBBBAAAAAAAAAA------- CBBBBAAAAAAAAAA------- CBBBBAAAAAAAAAA------- CBBBBAAAAAAAAAA------- BCCCCG---------------- 
BBBBBBBBBBBBBBBBBBBBBB BCCCCCCCCCCCCCCCCCCCCB BCEEEEECCCEEEEEEEEEECB BCCCCCCCCCCCCCCCCCCCCB BBBBBBBBBBBBBBBBBBBBBB BCCCCCCCCCCCCCCCCCCCCB BCEEEEEEEECCCCCCCEEECB BCECCCCCCECCCCCCCCCCCB BCEEEEEEEECCCEEEEEEECB BCECCCCCCECCCCCCCCCCCB BCECCCCCCECCCCEEEEEECB BCECCCCCCECCCCCCCCCCCB BCEEEEEEEECCCEEEEEEECB BCECCCCCCECCCCCCCCCCCB BCEEEEEEEECCEEEEEEEECB BCCCCCCCCCCCCCCCCCCCCB BBBBBBBBBBBBBBBBBBBBBB BCCCCCCCCGGGGGGGGGGGGG BCCCCCCCCGGG---------- BCCEEEEEEGGG---------- BCCCCCCCCGG----------- BCCEEEEEGGG----------- BCCCCCCCGGG----------- BCCCCCCCGG------------ BCCCCCCGGG------------ BCCCCEEGG------------- BCCCCCCGG------------- BCCEEEEGG------------- BCCCCCGG-------------- BBBBBGG--------------- 
