model
size = 22 30 5, scale = 0.05, origin = -y
material 
  colors = A:#200505 B:#372F7C C:#2F6ED4 D:#309 E:#2A6A9C F:#D4AF37 G:#6868FF H:#545759 I:#2C0D09
voxels
BBBBBBBBBBBBBBBBBBBBBB BCCCCCCCCCCCCCCCCCCCCB BCDDDDDDDDDDDDDDDDDGCB BCDDGGGGDDDDGGGGDDGDCB BCDGDDDDGDDGDDDDGDDGCB BCDGDDDDGDDGDDDDGDGDCB BCDGDDDDGDDGDDDDGDDGCB BCDDDDDDDDDDDDDDDDGDCB BCDDDDGGGDDDGGGGGDDGCB BCGDDDGDDDDDDDGDDDGDCB BCDGDDDDDDDDDDGGGDDGCB BCGDDDGGGDGDDDDDDDGDCB BCDGDDDDGDGDDDGGGDDGCB BCGDDDGGGGGDDDGDGDGDCB BCDGDDDDDDDDDDGGGDDGCB BCGDDDGGGGGDDDDDDDGDCB BCDGDDGDGDDDDDGGGDDGCB BCGDDDGGGHHHHHHHHHHHHH BCDGDDDDDH------------ BCGDDDDGHH------------ BCDGDDGGH------------- BCGDDDDGH------------- BCDGDDDHH------------- BCGDDDDH-------------- BCDGDDHH-------------- BCGDDDH--------------- BCDGDDH--------------- BCGDDHH--------------- BCCCCH---------------- BBBBBH---------------- 
BCCCCCCCCCCCCCCCCCCCCB CBBBBBBBBBBBBBBBBBBBBC CBAAAAABAAAAAABAAAAABC CBAAAAABAAAAAABAAAAABC CBBBBBBBBBBBBBBBBBBBBC CBAAAAABAAAAAABAAAAABC CBAAAAABAAAAAABAAAAABC CBAAAAABAAAAAABAAAAABC CBBBBBBBBBBBBBBBBBBBBC CBAAAAABAAAAAABAAAAABC CBAAAAABAAAAAABAAAAABC CBAAAAABAAAAAABAAAAABC CBBBBBBBBBBBBBBBBBBBBC CBAAAAABAAAAAABAAAAABC CBAAAAABAAAAAABAAAAABC CBAAAAABAAAAAABAAAAABC CBBBBBBBBBBBBBBBBBBBHC CBBBBAABAAAAAAHAAAAA-H CBBBBAABAAAAAA-AAAAA-- CBBBBAABAAIIII-IIIII-- CBBBBBBBB------------- CBBBBAABAIIIII-IIIII-- CBBBBAABAAAAAA-AAAAA-- CBBBBAABIIIIII-IIIII-- CBBBBBBH-------------- CBBBBAA-IIIIII-------- CBBBBAA-AAAAAA-------- CBBBBAA-IIIIII-------- CBBBBH---------------- BCCCCH---------------- 
BCEEEEECCCCCCCCEEEEECB CAAAAAAAAAAAAAAAAAAAAC EAAAAAAAAAAAAAAAAAAAAE EAAAAAAAAAAAAAAAAAAAAE EAAAAAAAAAAAAAAAAAAAAE CAAAAAAAAAAAAAAAAAAAAC CAAAAAAAAAAAAAAAAAAAAC CAAAAAAAAAAAAAAAAAAAAC CAAAAAAAAAAAAAAAAAAAAC CAAAAAAAAAAAAAAAAAAAAC EAAAAAAAAAAAAAAAAAAAAE EAAAAAAAAAAAAAAAAAAAAE EAAAAAAAAAAAAAAAAAAAAE EAAAAAAAAAAAAAAAAAAAAE EAAAAAAAAAAAAAAAAAAAAE EAAAAAAAAAAAAAAAAAAAAE EAAAAAAAAAAAAAAAAAAAAE EBBBBAAAAAAAAAAAAAAAAH EBBBBAAAAAAAAAAAAAAAA- EBBBBAAAAAAAAAAAAAAAA- EBBBBAAAAAAAAAAAAAAAA- EBBBBAAAAAAAAAAAAAAAA- EBBBBAAAAAAAAAAAAAAAA- CBBBBAAAAAAAAAAAAAAAA- EBBBBAAAAAAAAAAAAAAAA- EBBBBAAAAAAAAAA------- EBBBBAAAAAAAAAA------- CBBBBAAAAAAAAAA------- CBBBBAAAAAAAAAA------- BCEEEH---------------- 
BCCCCCCCCCCCCCCCCCCCCB CAAAAAAAAAAAAAAAAAAAAC CAAAAAAAAAAAAAAAAAAAAC CAAAAAAAAAAAAAAAAAAAAC CAAAAAAAAAAAAAAAAAAAAC CAAAAAAAAAAAAAAAAAAAAC CAAAAAAAAAAAAAAAAAAAAC CAAAAAAAAAAAAAAAAAAAAC CAAAAAAAAAAAAAAAAAAAAC CAAAAAAAAAAAAAAAAAAAAC CAAAAAAAAAAAAAAAAAAAAC CAAAAAAAAAAAAAAAAAAAAC CAAAAAAAAAAAAAAAAAAAAC CAAAAAAAAAAAAAAAAAAAAC CAAAAAAAAAAAAAAAAAAAAC CAAAAAAAAAAAAAAAAAAAAC CAAAAAAAAAAAAAAAAAAAAC CBBBBAAAAAAAAAAAAAAAAH CBBBBAAAAAAAFFFFFFFFF- CBBBBAAAAAAAFFFFFFFFF- CBBBBAAAAAAFFFFFFFFFF- CBBBBAAAAAAFFFFFFFFFF- CBBBBAAAAAAFFFFFFFFFF- CBBBBAAAAAFFFFFFFFFFF- CBBBBAAAAAFFFFFFFFFFF- CBBBBAAAFFFFFFFFFFFFF- CBBBBAAAFFFFFFFFFFFFF- CBBBBAAAFFFFFFFFFFFFF- CBBBBAFFFFFFFFFFFFFFF- BCCCCH---------------- 
BBBBBBBBBBBBBBBBBBBBBB BCCCCCCCCCCCCCCCCCCCCB BCEEEEECCCEEEEEEEEEECB BCCCCCCCCCCCCCCCCCCCCB BBBBBBBBBBBBBBBBBBBBBB BCCCCCCCCCCCCCCCCCCCCB BCEEEEEEEECCCCCCCEEECB BCECCCCCCECCCCCCCCCCCB BCEEEEEEEECCCEEEEEEECB BCECCCCCCECCCCCCCCCCCB BCECCCCCCECCCCEEEEEECB BCECCCCCCECCCCCCCCCCCB BCEEEEEEEECCCEEEEEEECB BCECCCCCCECCCCCCCCCCCB BCEEEEEEEECCEEEEEEEECB BCCCCCCCCCCCCCCCCCCCCB BBBBBBBBBBBBBBBBBBBBBB BCCCCCCCCHHHHHHHHHHHHH BCCCCCCCCHHH---------- BCCEEEEEEHHH---------- BCCCCCCCCHH----------- BCCEEEEEHHH----------- BCCCCCCCHHH----------- BCCCCCCCHH------------ BCCCCCCHHH------------ BCCCCEEHH------------- BCCCCCCHH------------- BCCEEEEHH------------- BCCCCCHH-------------- BBBBBHH--------------- 
