model
size = 17 21 32, scale = 0.05, origin = -y
material 
  colors = A:#81846C B:#FFF5C2 C:#C4C09F D:#6F6D56 E:#A5A387 F:#111 G:#FF3200 H:#C91717
voxels
4-2B-4B-2B7-10B10-4C13-4D13-4A14-2A265-3B-4B-3B5-12B6-10C8-2D4A2D9-8A10-6A13-2D15-2C230-14B3-14B4-3C6A3C6-3D4A3D8-8A9-8A10-6D12-C2AC14-2E213-14B3-14B4-3C6A3C5-D7A4D6-10A8-8A9-8D10-C4AC12-4E211-16B-16B2-4C6A4C4-D7A4D5-12A6-10A8-8D9-2C4A2C10-6E13-2C195-14B3-16B2-4C6A4C3-2D11AD4-12A5-12A6-10D8-2C4A2C10-6E12-4B196-14B-16B2-4C6A4C3-2D11AD3-13A5-12A6-D7A2D7-C8AC8-E6HE10-C4HC11-E4-E176-16B-16B2-4C6A4C3-2D11AD3-13A5-12A6-D7A2D7-C8AC8-2A4E2A11-4B194-15B2-15B3-4C6A4C3-2D11AD3-13A5-12A6-D7A2D7-C8AC8-8E10-C4HC11-E4-E176-16B-16B2-4C6A4C3-2D11AD3-13A5-12A6-D7A2D7-C8AC8-2A3E3A11-4B196-14B-16B2-4C6A4C3-2D11AD3-13A5-12A6-D7A2D7-C8AC8-8E10-C4HC11-E4-E176-16B-16B2-4C6AC2A4-2D8A2D5-2(11A7-)D7A2D7-C8AC8-2A3E3A11-4B195-2(14B3-)3C9AC4-2D8A2D5-12A6-11A7-D7A2D7-C8AC8-8E10-C4HC11-E4-E114-E2-E29-E4-E24-12B5-14B3-CAC9AC4-2D8AD6-11A7-10A7-D8A2D7-C8AC8-8E11-4E13-4B12-E4-E29-E2-E47-4C13-C2HC12-6C11-C4HC11-6C9-10B6-12B4-CAC9AC4-2D8AD6-11A7-10A7-D8AD8-C8AC8-2A4E2A11-4A13-4E12-E4HE13-2B14-E2HE14-2B15-2C14-4A12-B4AB10-2(2C4A2C9-)2C4F2C8-B-B3-B2-B6-2BGB3GB2G2B4-CAC9AC4-2D8AD6-11A7-10A7-D8AD8-C8AC8-A6EA10-2(6A11-)6A12-3(4A13-)4A12-6A10-2B4A2B8-2(2C6A2C7-)2C6F2C7-2(B-)6B6-2BGBG7B4-CAC9AC4-2D8AD6-11A7-D9A7-D8AD6-EAC8AC8-A6EA3(9-8A)10-6A11-6A12-4A13-4A11-8A9-2B4A2B8-2(C8AC7-)C8FC7-2(B-)6B6-2BGBG4B-2B4-CAC9AC4-2D8AD6-11A7-D9A6-E9AD6-EAC8AC5-E2AC6AC3(9-8A)10-3(6A11-)6A9-10A7-3B4A3B6-2(2C8A2C5-)2C8F2C6-B-B3-B2-B6-2BGB3GB2-2B4-CAC6A2GAC4-2D7A2G6-9A2G6-E8A2G6-E11A5-G2(10AD5-E)10A2(8-9A)4(9-C7A)8-10A7-3B4A3B6-2(C10AC5-)C10FC6-2(B-)7B5-2BGBG4B-2B4-CAC9AC4-2D9AD5-12A6-3D8A5-E11A2(5-E10AD)6-10AD6-12A5-12A7-3(9A8-)9A7-10A7-3B4A3B6-2(C10AC5-)C10FC3-4B-B-8B2-4BGBG8B3-2C10AC4-2D9A2D4-12A7-2D8A7-D9A4-B2C9AD4-B2C11A3(5-12A)6-5(9AB7-)3B4A3B6-2(C10AC5-)C10FC2-5B-B3-B2-9BGB3GB2G3B2-3C10A2C2-2D12AD2-14A7-D8A4-B3C9A5-H2C10A4-G2C10A3-B2C11A5-11AC5-12A6-5(9AB7-)3B4A3B6-2(C10AC5-)C10FC4-31B2-3C10A2C2-2D12AD2-15A2-BC12A4-GC10A5-HC9AD5-GC11A4-HC10AC3-B2C10AC5-B11A6-3(B9A7-)2(10A7-)3B4A3B6-2(C10AC5-)C10FC2-5B-B3-B2-2B2-5BGB3GB2G3B2-3C10A2C2-2D12AD2-15A2-B14A3-G12A4-HC9AD5-GC9AD5-HC11A3-B2C11A4-2BC10A4-2B3(C8A7-B)C7AD7-BC9A6-BC2B4A3B6-2(C10AC5-)C10FC2-5B-B-14BGBG8B2-3C10A2C2-2D12AD2-15A4-D12A2-B14A3-HC9AD5-GC9AD4-B2C10A7-2(B9A6-A)B8A7-3(AB7A8-)AB9A7-3B4A3B6-2(2C8A2C5-)2C8F2C4-3B-B-14BGBG8B2-3C10A2C2-2D12AD2-15A4-D12A4-D11A3-B2C9AD4-B2C9AC2(6-11A)6-10A8-5(10A7-)3B4A3B6-2(2C8A2C5-)2C8F2C2-5B-B3-B2-2B3-4BGB3GB2G3B3-2C10A2C3-D11ABD3-12ABA4-12A5-11A2(7-D8AC)6-11A6-10A9-8A10-3(AB2ABA11-)AB2ABA10-8A9-B6AB8-2(C8AC7-)C8FC4-16B2-14B3-2C10A2C3-2B10ABD4-B10AB5-B10A6-11A6-D9AD6-2D8AD6-10A9-2(2AB)2A10-AB2ABA79-AB2ABA11-6B9-2(10C7-)2C6F2C5-14B3-14B5-10C3(7-B8AB)7-B9A7-D5AB2AD8-D2A2CBAD9-2AB2CB2A12-3(2C15-)2(2B15-2C15-)2C13-6C10-8C9-8C8-11B5-12B7-8C3(9-2B5AB)9-2BA2CA2B9-2BA2C3B10-2B2-2B132-2C15-2C62-10B7-10B9-6C3(11-2B2A2B)12-B2CB13-B2-B232-8B9-8B12-3(2C15-)2C262-
