model
size = 17 21 32, scale = 0.05, origin = -y
material 
  colors = A:#81846C B:#FFF5C2 C:#C4C09F D:#6F6D56 E:#A5A387 F:#111 G:#FF3200 H:#C91717
voxels
3-2B-4B-2B7-10B10-4C13-4D13-4A14-2A265-3B-4B-3B5-12B6-10C8-2D4A2D9-8A10-6A13-2D15-2C230-14B3-14B4-3C6A3C6-3D4A3D8-8A9-8A10-6D12-C2AC14-2E213-14B3-14B4-3C6A3C5-4D7AD6-10A8-8A9-8D10-C4AC12-4E211-16B-16B2-4C6A4C4-4D7AD5-12A6-10A8-8D9-2C4A2C10-6E13-2C197-14B-16B2-4C6A4C3-D11A2D4-12A5-12A6-10D8-2C4A2C10-6E12-4B194-14B3-16B2-4C6A4C3-D11A2D4-13A4-12A6-2D7AD7-C8AC8-E6HE10-C4HC11-E4-E176-16B-16B2-4C6A4C3-D11A2D4-13A4-12A6-2D7AD7-C8AC8-2A4E2A11-4B195-2(15B2-)4C6A4C3-D11A2D4-13A4-12A6-2D7AD7-C8AC8-8E10-C4HC11-E4-E176-16B-16B2-4C6A4C3-D11A2D4-13A4-12A6-2D7AD7-C8AC8-3A3E2A11-4B194-14B3-16B2-4C6A4C3-D11A2D4-13A4-12A6-2D7AD7-C8AC8-8E10-C4HC11-E4-E176-16B-16B3-2AC6A4C5-2D8A2D6-11A5-11A6-2D7AD7-C8AC8-3A3E2A11-4B195-14B3-14B4-C9A3C5-2D8A2D5-12A5-11A6-2D7AD7-C8AC8-8E10-C4HC11-E4-E114-E2-E29-E4-E26-12B3-14B4-C9ACAC6-D8A2D6-11A6-10A6-2D8AD6-C8AC8-8E11-4E13-4B12-E4-E29-E2-E47-4C13-C2HC12-6C11-C4HC11-6C9-10B6-12B5-C9ACAC6-D8A2D6-11A6-10A7-D8AD6-C8AC8-2A4E2A11-4A13-4E12-E4HE13-2B14-E2HE14-2B15-2C14-4A12-B4AB10-2(2C4A2C9-)2C4F2C8-B2-B3-B-B6-2B2GB3GBG2B5-C9ACAC6-D8A2D6-11A6-10A7-D8AD6-C8AC8-A6EA10-2(6A11-)6A12-3(4A13-)4A12-6A10-2B4A2B8-2(2C6A2C7-)2C6F2C7-6B2(-B)6-7BGBG2B5-C9ACAC6-D8A2D6-11A6-9AD7-D8AD6-C8ACAE6-A6EA3(9-8A)10-6A11-6A12-4A13-4A11-8A9-2B4A2B8-2(C8AC7-)C8FC7-6B2(-B)6-2B-4BGBG2B5-C9ACAC6-D8A2D6-11A6-9AD7-D9AE5-C8ACAE6-C6AC2AE6-2(8A9-)8A10-3(6A11-)6A9-10A7-3B4A3B6-2(2C8A2C5-)2C8F2C6-B2-B3-B-B6-2B2-B3GBG2B5-CA2G6ACAC6-DG7A2D6-AG9A6-AG8AE5-11AE5-D10AG5-D2(10AE6-)2(9A8-)3(7AC9-)7AC8-10A7-3B4A3B6-2(C10AC5-)C10FC5-11B6-2B-4BGBG2B5-C9ACAC5-D9A2D5-12A5-8A3D6-11A3(E5-D10A)2(5-12A)6-4(9A8-)10A7-3B4A3B6-2(C10AC5-)C10FC4-3B2-B3-B-4B2-3B2GB3GBG4B3-C10A2C4-2D9A2D5-12A5-8A2D7-9AD7-D9A2CB3-11A2CB3-2(12A5-)12A6-5(B9A7-)3B4A3B6-2(C10AC5-)C10FC3-9B-B-5B-3B2GB3GBG5B-2C10A3C2-D12A2D3-14A4-8AD8-9A3CB3-10A2CH4-10A2CG4-11A2CB3-C11A5-12A6-5(B9A7-)3B4A3B6-2(C10AC5-)C10FC3-9B-B-3B3-8BGBG5B-2C10A3C2-D12A2D2-15A3-12ACB4-10ACG5-D9ACH4-11ACG4-C10ACH4-C10A2CB3-11AB6-3(9AB7-)2(10A7-)3B4A3B6-2(C10AC5-)C10FC5-2B2-B3-B-5B-3B2GB3GBG5B-2C10A3C2-D12A2D2-15A2-14AB3-12AG5-D9ACH5-D9ACG4-11ACH4-11A2CB3-10A2(C2B6-8A)CB7-8ACB7-D7ACB6-9ACB6-3B4A2BCB2(5-C10AC)5-C10FC3-9B-B-5B-8BGBG5B-2C10A3C2-D12A2D2-15A2-12AD4-14AB4-D9ACH5-D9ACG5-10A2CB4-9AB7-9ABA7-8A3(BA8-7A)BA6-9ABA6-3B4A3B6-2(2C8A2C5-)2C8F2C3-9B-B-3B3-8BGBG5B-2C10A3C2-D12A2D2-15A2-12AD5-11AD6-D9A2CB4-C9A2CB4-11A6-11A7-10A6-5(10A7-)3B4A3B6-2(2C8A2C5-)2C8F2C5-2B2-B3-B-5B-3B2GB3GBG4B2-2C10A2C3-DB11AD3-AB12A4-12A6-11A6-2(C8AD7-)11A7-10A7-8A10-3(AB2ABA11-)AB2ABA10-8A9-B6AB8-2(C8AC7-)C8FC4-16B2-14B3-2C10A2C3-DB10A2B4-B2(10AB6-)11A6-D9AD6-D8A2D7-10A7-2(2AB)2A10-AB2ABA79-AB2ABA11-6B9-2(10C7-)2C6F2C5-14B3-14B5-10C3(7-B8AB)7-9AB7-D2AB5AD8-DAB2C2AD9-2AB2CB2A12-3(2C15-)2(2B15-2C15-)2C13-6C10-8C9-8C7-11B6-12B7-8C3(9-B5A2B)9-2BA2CA2B9-3B2CA2B10-2B2-2B132-2C15-2C62-10B7-10B9-6C3(11-2B2A2B)12-B2CB13-B2-B232-8B9-8B12-3(2C15-)2C263-
