model
size = 32, scale = 0.05, origin = -y
material 
  colors = A:#6F6D56 B:#FFF5C2 C:#81846C D:#A5A387 E:#C4C09F F:#FF3200 G:#111 H:#AAA I:#566C73 J:#24936E
voxels
198-20D11-D20-D9-D22-D7-D24-D5-2D24-2D4-2D24-2D6-D22-D9-D20-D11-20D117-2C629-20H11-H20-H9-H22-H7-H24-H6-H24-H5-2H24-2H6-H22-H9-H20-H11-20H113-3C-2C-3C26-2C597-20D11-D20GD9-D22GD7-D24GD6-D12(FG)D5-2D24G2D6-D22GD9-D20GD11-20D111-14C24-2B30-2B950-5C8-5C18-4B2C4B24-2B2D2B28-2B917-6C8-6C15-3B8C3B19-5B2D5B22-8B27-2B884-6CA8-A6C12-4BA3C2A3CA4B16-6B2D6B19-12B22-8B27-2B851-5C3A8-3A5C10-5B10A5B13-4B-8A-4B16-2B-3A2B3A-2B19-12B23-6B28-2B786-3C20-3C8-BC5A8-5ACB10-6B10A6B11-5B2A6-2A5B13-4B4A2B4A4B16-14B20-10B26-2B30-2B753-4C20-4C6-BC-5A8-5A-CB9-BA4B10A4BAB11-5BA8-A5B13-4B10A4B15-7B2D7B17-14B21-8B27-2B720-3C24-3C4-B2C-4A10-4A-2CB6-2BC-5A8-5A-C2B7-2BA4B10A4BA2B9-6B10A6B11-5B10-5B13-4B10A4B15-16B18-4B4-4B24-4B686-3C26-3C2-BC-A20-A-CB4-2BCA20-AC2B5-2BA-5A8-5A-A2B7-B2A4BA8-A4B2AB8-7B10A7B9-6B10-6B11-5BA8-A5B14-16B17-14B21-8B27-2E239-3C2(26-6C)26-5C28-2C256-2C28-5C26-3C2-BC-A20-A-CB4-2BCA20-AC2B5-2BA-5A8-5A-A2B6-2B2A4BA8-A4B2A2B7-7B10A7B9-6B10-6B11-5BA8-A5B13-18B16-14B20-10B26-2E239-3CA24-A4C2BA24-A2B4C26-5C2(28-4C)28-2C160-2C28-4C28-3CB2C24-2CBC-DBA24-ABD3-B3A20-3AB4-2B7A10-7A2B5-2B-B4A10-4AB-2B7-3B18A3B8-3B4A10-4A3B9-2B4A10-4A2B12-18B15-16B18-12B24-4E207-2(DCA24-ACD2-)DBA24-ABD-CDBA24-ABD4C26-4C30-3C28-4C28-2C96-2C2(28-4C)A26-A3C2BA24-A2BC-DBA24-ABD3-B3A20-3AB4-2B24A2B5-4B2A14-2A4B6-4B18A4B7-3B18A3B9-2B4A10-4A2B11-20B14-5B6-5B18-12B23-2E2-2E206-3(DCA24-ACD2-)DBA24-ABD-C2BA24-A2B4C26-5C2(28-4C)28-2C64-2C28-4C28-5C26-4C2B4A18-4A2BC-DBA-2A18-2A-ABD2-DB4A18-4ABD3-2B24A2B5-2B-3A14-3A-2B6-2B-20A-2B7-B-20A-B9-2B-16A-2B11-2BA14BA2B14-3B10-3B17-14B21-2E4-2E173-DC26-CD2-DCA24-ACD-FBCA24-ACB2FBCA24-ACBF-DCA24-ACD2-DBA24-ABD-CBC26-CB3C7(A26-A4C)A26-A3C2B4A18-4A2BC-DB2-2A18-2A2-BD2-DB2-2A18-2A2-BD3-2B-4A4-A5-8A-2B4-3B-3A14-3A-3B5-2B-3A4FA5F7A-2B7-B-20A-B9-2B-16A-2B11-2BA14BA2B13-4B10-4B16-14B21-E2-2E2-E173-DC26-CD2-DCA24-ACD-FBCA24-ACB2FBCA24-ACBF-DCA24-ACD2-DCA24-ACD-CBC26-CB3CA26-A4C3A22-3A2C-2(H3A22-3AH2-)H3A22-3AH-2C2(3A22-3A4C)3A22-3A2C-D-4A18-4A-2(D2-DB4A18-4AB)D3-2B-4A-2A3(-A)-8A-2B4-3B-3A14-3A-3B5-2B-3AF2A3(FA)F7A-2B7-B-20A-B9-3B16A3B11-2BA14BA2B13-4B10-4B16-14B21-E2-2E2-E205-DC26-CD2-DCA24-ACD-CBCA24-ACB2CDCA24-ACDC-DBA24-ABD2-2BA24-A2B-C2B2A22-2A2B2C2B2A22-2A2BC-H3A22-3AH-EJ3A22-3AJF-H3A22-3AH2-H3A22-3AH-2C-2A22-2A-4C-2A22-2A-2C-2(DB4A18-4ABD2-)DB4A18-4ABD3-2B-4A-2A3(-A)-8A-2B5-2B-3A14-3A-2B6-2B-3AF2A3(FA)F7A-2B7-B-20A-B9-3B16A3B11-2BA14BA2B14-3B10-3B17-14B21-2E4-2E237-DCA24-ACD-CBCA24-ACBC-DB2A22-2ABD2-DB26-BD2-DB4A18-4ABD2-DB2-2A18-2A2-BD-C2B2-2A18-2A2-2BC-HBA-2A18-2A-A2(BH2-HB2-2A18-2A2-)BH-C2B2-2A18-2A2-2B2C2B2-2A18-2A2-2BC-2(DB2-2A18-2A2-BD2-)DB2-2A18-2A2-BD3-B2-2A18-2A2-B4-2B-22A-2B5-2B-3A14-3A-2B5-2CB-20A-B2C4-C2B-20A-2BC7-3B16A3B11-2BA14BA2B14-16B18-12B23-2E2-2E168-E71-A24-A3-3CA24-A3C-DB2A22-2ABD2-DB3A20-3ABD2-DB4A18-4A2(BD2-DB2-2A18-2A2-)BD-C3(2B2-2A18-2A2-2B2C)2B2-2A18-2A2-2BC-3(DB2-2A18-2A2-BD2-)D2B-2A18-2A-2BD3-2B-2A18-2A-2B5-B-4A-2A3(-A)-8A-B5-C2B-3A14-3A-2BC4-2CB-3AF2A3(FA)F7A-B2C4-C2B-20A-2BC4-2CE2CB16AB2CE2C9-BA14BAB2-E12-16B3-E14-12B5-E18-4E9-E4(31-D)30-3E99-3CA24-A3C2-E2A22-2AE4-E3A20-3AE3-DB4A18-4A8(BD2-DB2-2A18-2A2-)BD2-D3B2A18-2A3BD3-2B-2A18-2A-2B4-2B-2A18-2A-2B5-B-4A-2A3(-A)-8A-B5-C2B-3A14-3A-2BC5-CB-3AF2A3(FA)F7A-BC3-2F4B20A4B2F2-5CB7A2E7AB5C9-8B2E8B16-6B2E6B20-4B2E4B198-E100-4C24-4C2-EBA22-ABE4-E3A20-3AE4-B4A18-4AB3-7(DB2-2A18-2A2-BD2-)DB-3A18-3A-BD3-3B2A18-2A3B2(4-2B-2A18-2A-2B)5-C-22A-C3-F-C2B-3A14-3A-2BC-2F-C2B-20A-2BC-2F-C3B20A3BC-F2-5CB7A2E7AB5C10-7B2E7B17-6B2E6B21-3B2E3B301-3C24-3C3-EBA22-ABE4-E3A20-4E4-B4A18-4A2(B4-B2-2A18-2A2-)B3-3(DB2-2A18-2A2-BD2-)DB2-2A18-2A2-BD3-2(B2-2A18-2A2-B4-)4BA18-A4B4-4BA18-A4B5-2B2A18-2A2B7-B22AB4-F3-C-3A14-3A-C3-F2-4C20A4C4-5C18A5C9-2B6A2E6A2B15-7B2E7B18-5B2E5B24-B2EB304-2C24-2C4-CB2A20-2ABC5-3E20-3E6-B3A18-3AB5-7(B2-2A18-2A2-B4-)B2-2A18-2A2-B5-3BA18-A3B6-3BA18-A3B3-F2-3BA18-A3B2-2F3-B5A12-5AB3-2F4-B-3A12-3A-B4-F6-B-7A2E7A-B13-3B5A2E5A3B15-3B4A2E4A3B16-7B2E7B20-3B2E3B334-3C22-3C4-2CBA20-AB2C5-3E20-3E3(6-2B2A18-2A2B)6-B-2A18-2A-B5-2B-2A18-2A-2B4-2B-2A18-2A-2B5-2(B-2A18-2A-B6-)2B2A18-2A2B6-2B2A18-2A2B7-2BA18-A2B4-F3-2BA18-A2B3-F5-2B3A12-3A2B10-3B2A12-2A3B11-3B6A2E6A3B13-2B-5A2E5A-2B15-4B3A2E3A4B16-7B2E7B23-2E337-3C22-3C4-2CB5A12-5AB2C6-2E-2E14-2E-2E2(8-B-3A14-3A-B)7-2(2B-3A14-3A-2B6-)2(B2-3A14-3A2-B6-)B2-A18-A2-B6-B2-2A16-2A2-B3-F2(3-B-2A16-2A-B3-2F)3-2B2A16-2A2B3-2F4-B2A16-2AB4-F6-B3A12-3AB12-2B2A12-2A2B13-2B6A2E6A2B16-B5A2E5AB18-6B2E6B22-2B2E2B368-3C20-3C6-2CB4A12-4AB2C8-5E2-8A2-5E10-B4A2-8A2-4AB9-6(2B4A2-8A2-4A2B8-)2B3A3-8A3-3A2B4-F3-3B2A3-8A3-2A3B3-F5-2B2A3-3A2E3A3-2A2B10-2B2A3-3A2E3A3-2A2B11-B2A14-2AB13-B2A12-2AB14-2B6A2E6A2B15-7B2E7B18-5B2E5B22-3B2E3B400-3C18-3C8-3C3A12-3A3C10-4E10A6E12-B-2A2-8A2-2A-B11-3(2B-2A2-8A2-2A-2B10-)B2-2A2-8A2-2A3(2-B10-B2-5A6B5A)2-B5-F4-2B-16A-2B4-F6-2B7A2E7A2B12-2B7A2E7A2B13-B7A2E7AB15-B6A2E6AB17-2B4A2E4A2B19-5B2E5B22-3B2E3B410-4A19-2C6-6A6-2C10-5C12A5C12-3E10A5E2(14-3B12A3B)13-4B12A4B12-2B-14A-2B12-3B4A6B4A3B12-3B2A10B2A3B8-F3-3B2ABA6BAB2A3B3-F4-F3-3B-ABA6BABA-3B3-F2-3F4-2B-AB8ABA-2B4-3F7-2B-AB3A2E3ABA-2B15-4B3A2E3A4B16-4B3A2E3A4B17-6B2E6B20-4B2E4B24-2B2E2B410-6C25-C6DC18-2C3-C9D3-2C12-5C3D4C3D5C15-3E8B3E18-14B17-16B16-16B18-BABFH2BHFBAB17-6B2F2B2F6B14-6B2F2B2F6B9-2F4-4B-BH2BHB-4B4-2F10-4B-6B-4B16-4B8-4B17-3B8-3B18-3B8-3B19-5B2E5B22-3B2E3B27-2E444-6C23-3C6-3C17-5C2-4D2-5C14-4C2-D4FD2-4C19-3B2F3B23-4B2F4B21-12B20-5B2H5B19-4BF-2H-F2(4B18-4B2H2I2H)4B12-2F4-4BH-2H-H4B4-2F13-3BF4HF3B20-12B21-4B2E4B23-3B2E3B26-B2EB507-6C23-3C6-3C18-4C8-4C17-2C10-2C87-4F27-2F2-2F19-3F3-2F4-2F3-3F10-2(3F-)F2-2D2-F2(-3F)8-F5-3F2-2D2-3F5-F8-F7-F6-F7-F17-F4-F27-4F558-
