model
size = 32 32 16, scale = 0.05, origin = -y
material 
  colors = A:#DDD B:#FFF5C2 C:#C4C09F D:#6F6D56 E:#111 F:#A5A387 G:#C6C085 H:#8A8D60 I:#FF3200 J:#C91717 K:#A96360 L:#00FFFA
voxels
527-2D29-3(B2-B60-)B2-B733-2D62-2D28-6B2(25-D6-D25-6D)25-D6-D24-8D64-L666-2D62-2D26-D8BD2(22-2D6E2D22-2H6D2H)22-2D6E2D22-10D21-2F8D2F20-3F6-3F29-3F631-6D26-D4-D24-10D7(22-E8AE)18-J2-F10EF2-J15-4IF6-F4I27-3F309-I8-I281-4D27-6D26-D4ED24-10D22-E8AE21-2(C10AC20-E10AE20-)C10AC17-J2-D10AD2-J17-F3AE2AE3AF21-F2(2C-)2CF21-2F7-3F307-5B4-5B248-2D29-4D27-6D26-6D23-3C6A3C19-2E10A2E2(18-C12AC18-E12AE)18-C12AC15-J2-2D10A2D2-J15-2C3AB2AB3A2C18-2CA2(2E-)2EA2C19-2(2CDCD)2C276-3G6-3G18-7B2I7B49-4B6-4B184-2D29-4D27-6D21-5C6A5C16-3C10A3C3(16-E14AE16-C14AC)14-J-3D10A3D-J13-F3C3AB2AB3A3CF15-3CE-EB2ABE-E3C18-2(2C-C-)2C243-5B4-5B18-5G4-5G16-18B16-4DE4-E4D17-7B2-7B17-2DBD6-DB2D17-J2-BD6-DB2-J15-J3-2D6-2D3-J13-I18-I12-I18-I11-I9-2D9-I19-4D22-6C4A6C2(16-D14AD)3(17-B12AB17-D14AD)15-2FB12AB2F13-JFD3AEAB2ABAE3ADFJ12-2FDCAE-EB2ABE-EACD2F16-2(2C-C-)2C212-IJI6-IJI19-5B4-5B17-7G2-7G15-BD14BDB16-DB-B6-B-BD16-3B2(2-B-B)2-3B16-D3B-B2-B-3BD19-FDFB4-BFDF21-2D6-2D22-D8-D22-B8-B22-H3-2H3-H16-J2-7H2E7H2-J11-J-D14AD-J13-JIE12AEIJ15-JE12AEJ17-2(B12AB18-E12AE18-)B12AB18-E12AE17-FK12AKF14-F2IE2AEAB2ABAE2AE2IF13-FD2AE-EB2ABE-E2ADF15-4C-C-2E-C-4C18-2(2CDCD)2C149-I8-I21-JIJ6-JIJ18-6B4-6B15-6G2B2-2B6G12-IB2D6B2I6B2DBI13-D2B-2B4-2B-2BD15-6B-B2-B-6B16-4F2B2-2B4F19-3FB4-B3F21-2(2F6-2F22-)2B6-2B22-2H6-2H19-16H3(16-D14AD)3(17-B12AB17-D14AD)16-FB12ABF15-FD3AEAB2ABAE3ADF14-FD2AE-EB2ABE-E2ADF15-4C-CB2ABC-4C18-2(2C-C-)2C180-IJI6-IJI19-5B4-5B17-7B2-7B15-BD6B2-6BDB15-D5B4-5BD15-5BD-B2-B-D5B14-2F3D2FB2-B2F3D2F15-4DFB4-BF4D17-2(DF)6-2(FD)19-F2D6-2DF20-BDB6-BDB21-10H19-C2H3A4E3A2H2(C16-C14A)C14-3(2B16A2B12-2BC14AC2B12-)2B16A2B12-B2C14A2CB12-B3C2AEAB2ABAE2A3CB13-2BCAE-EB2ABE-EAC2B16-B2C-CB2ABC-2CB17-4C-C-2F-C-4C18-2C-CD2CDC-2C241-8B2-8B16-6D2-6D16-8B2-8B16-F5D2-5DF19-F2DB4-B2DF21-2F6-2F54-2EB4-B2E20-2H3A4C3A2H17-C14AC11-B4-C14AC4-B6-2B3-C14AC3-2B6-3B2C16A2C3B6-BGB20ABGB6-3G20A3G6-GBG20AGBG6-3G20A3G6-3B20A3B7-2B20A2B9-B20AB11-B3C2AEAB2ABAE2A3CB13-2BC2AEAB2ABAE2AC2B16-BCAECB2ABCEACB17-2(CA)ECB2ABCE2(AC)17-2CAEC-2A-CEA2C20-3CD2CD3C22-D8-D22-B8-B117-3B6-3B18-2B3D2B2-2B3D2B48-7B2-7B18-4F4-4F20-F2DF4-F2DF42-I30-IG10-E3C2-3CE10-2GB7-2(2C4A)2C7-B2G2B5-C14AC5-2B2G3B4-C14AC4-3B2G4B3-C14AC3-4B2G7B16A7BG-2B4AB16AB4A2B2-2B4AB16AB4A2B3-B4AB16AB4AB4-B4AB16AB4AB5-B3AB16AB3AB7-B2AB16AB2AB9-BAB16ABAB11-2B2C4AB2AB4A2C2B13-2BC4AB2AB4AC2B16-BC3AB2AB3ACB17-CAC3AB2AB3ACAC17-2C3AB2AB3A2C20-3C-2C-3C182-B8-B20-5B4-5B50-5B4-5B52-2D6-2D86-E3C2-3CE20-2(2C4A)2C17-CE12AEC9-B6-CE12AEC6-B2(2-2B5-CE12AEC5-2B)2-7BAE12AEA7B3-6BAE12AEA6B4-6BAE12AEA6B5-5BAE12AEA5B7-4BAE12AEA4B9-3BAE12AEA3B11-2BAE12AEA2B13-BCB12ABCB14-3B12A3B16-BC10ACB17-CEC10ACEC17-EC10ACE20-10C213-3B6-3B213-4E2-4E21-2E2AE2CE2A2E18-2(B-EAC6ACAE-B16-B-EC8ACE-B16-)B-EAC6ACAE-B11-6B-EAC6ACAE-6B7-5B-EAC6ACAE-5B9-4B-EAC6ACAE-4B11-3B-EAC6ACAE-3B13-2B-EC8ACE-2B15-B-EAC6ACAE-B16-B-EC8ACE-B16-B-EAC6ACAE-B18-EC8ACE18-C-EAC6ACAE-C18-3E6C3E245-I8-I216-2(E4-E26-)15(6E26-)6E109-
