model
size = 29 31 27, scale = 0.05, origin = -y
material 
  colors = A:#FF0 B:#FF3
voxels
----------------------------- ----------------------------- ----------------------------- ----------------------------- ----------------------------- ----------------------------- ----------------------------- ----------------------------- ----------------------------- ----------------------------- ----------------------------- ----------------------------- ----------------------------- ----------------------------- ----------------------------- ----------------------------- --------------A-------------- ----------------------------- ----------------------------- ----------------------------- ----------------------------- ----------------------------- ----------------------------- ----------------------------- ----------------------------- ----------------------------- ----------------------------- ----------------------------- ----------------------------- ----------------------------- ----------------------------- 
----------------------------- ----------------------------- ----------------------------- ----------------------------- ----------------------------- ----------------------------- ----------------------------- ----------------------------- ----------------------------- ----------------------------- ----------------------------- ----------------------------- ----------------------------- ----------------------------- --------------B-------------- --------------A-------------- -------------AAA------------- --------------B-------------- --------------A-------------- ----------------------------- ----------------------------- ----------------------------- ----------------------------- ----------------------------- ----------------------------- ----------------------------- ----------------------------- ----------------------------- ----------------------------- ----------------------------- ----------------------------- 
----------------------------- ----------------------------- ----------------------------- ----------------------------- ----------------------------- ----------------------------- ----------------------------- ----------------------------- ----------------------------- --------------A-------------- --------------B-------------- -------------A-A------------- -------------B-B------------- ------------A---A------------ ------------B-A-B------------ ----------AB--A--BA---------- --------AB---A-A---AA-------- ----------AB--A--BA---------- ------------B-A-B------------ ------------A---A------------ -------------A-B------------- -------------B-A------------- --------------A-------------- --------------A-------------- ----------------------------- ----------------------------- ----------------------------- ----------------------------- ----------------------------- ----------------------------- ----------------------------- 
----------------------------- ----------------------------- ----------------------------- ----------------------------- --------------B-------------- --------------B-------------- -------------BAB------------- -------------AAA------------- -------------ABA------------- ------------ABABA------------ ------------ABABA------------ ------------AABAA------------ -----------AAABAAA----------- ---------BAAABABAAAB--------- -------BAAAAABABAAAAAB------- ----BAAABBAAAAAAAAABBAAAA---- --BBABABAABBAAAAABBAABBABAB-- ----BAAABBAAAAABBAABBAAAA---- -------AAAAAABABABBAAA------- ---------AAAABABAAAA--------- -----------ABABAAA----------- ------------BBBAB------------ ------------ABABA------------ ------------ABABA------------ -------------ABA------------- -------------AAA------------- -------------AAA------------- --------------B-------------- --------------B-------------- ----------------------------- ----------------------------- 
----------------------------- ----------------------------- --------------B-------------- --------------A-------------- -------------BAB------------- -------------AAA------------- ----B-------AAAAA--------B--- -----A------BAAAB-------A---- ------B-----AAAAA------B----- -------A---AAAAAAA----A------ --------B--BAAAAAB---B------- -----------AAAAAAA----------- ---------ABAAAAAAABA--------- -------ABAAAAAAAAAAABA------- ----AABAAAAAAAAAAAAAAABAB---- --BAAAAAAAAAAAAAAAAAAAAAAAB-- ABBBAAAAAAAAAAAAAAAAAAAAAAAAB --ABAAAAAAAAAAAAAAAAAAAAAAB-- ----AABAAAAAAAAAAAAAAABAB---- -------ABAAAAAAAAAAABA------- ---------ABAAAAAAABA--------- -------B---AAAAAAA----------- ------A----BAAAAAB---B------- -----B-----AAAAAAA----A------ ----A-------AAAAA------B----- ---B--------BAAAB-------A---- ------------AAAAA--------B--- -------------BAA------------- -------------AAB------------- --------------A-------------- --------------B-------------- 
----------------------------- ----------------------------- ----------------------------- ----------------------------- --------------B-------------- --------------B-------------- -------------BAB------------- -------------ABA------------- -------------ABA------------- ------------ABABA------------ ------------ABABA------------ ------------BABAB------------ -----------ABABABA----------- ---------AABABABAAAA--------- -------AAAABABABABBAAA------- ----BAAABBAAAAAABAABBAAAB---- --BBAABBAABBAAAAABBAABBAABB-- ----BAAABBAAAAAAAABBBAAAB---- -------AAABBABABABAAAA------- ---------AAAABABABAA--------- -----------ABABABA----------- ------------BABAB------------ ------------ABABA------------ ------------ABABA------------ -------------ABA------------- -------------ABA------------- -------------BAB------------- --------------B-------------- --------------B-------------- ----------------------------- ----------------------------- 
----------------------------- ----------------------------- ----------------------------- ----------------------------- ----------------------------- ----------------------------- ----------------------------- ----------------------------- ----------------------------- --------------A-------------- --------------B-------------- -------------A-A------------- -------------B-B------------- ------------A---A------------ ------------B-A-B------------ ----------AB--B--AA---------- --------AA---AAA---AA-------- ----------AB--A--AB---------- ------------B-A-B------------ ------------A---A------------ -------------B-B------------- -------------A-A------------- --------------A-------------- --------------B-------------- ----------------------------- ----------------------------- ----------------------------- ----------------------------- ----------------------------- ----------------------------- ----------------------------- 
----------------------------- ----------------------------- ----------------------------- ----------------------------- ----------------------------- ----------------------------- ----------------------------- ----------------------------- ----------------------------- ----------------------------- ----------------------------- ----------------------------- ----------------------------- ----------------------------- --------------B-------------- --------------A-------------- -------------AAB------------- --------------A-------------- --------------B-------------- ----------------------------- ----------------------------- ----------------------------- ----------------------------- ----------------------------- ----------------------------- ----------------------------- ----------------------------- ----------------------------- ----------------------------- ----------------------------- ----------------------------- 
----------------------------- ----------------------------- ----------------------------- ----------------------------- ----------------------------- ----------------------------- ----------------------------- ----------------------------- ----------------------------- ----------------------------- ----------------------------- ----------------------------- ----------------------------- ----------------------------- -------------A--A------------ -------------A--A------------ ----------------------------- ----------------------------- ----------------------------- ----------------------------- ----------------------------- ----------------------------- ----------------------------- ----------------------------- ----------------------------- ----------------------------- ----------------------------- ----------------------------- ----------------------------- ----------------------------- ----------------------------- 
----------------------------- ----------------------------- ----------------------------- ----------------------------- ----------------------------- ----------------------------- ----------------------------- ----------------------------- ----------------------------- ----------------------------- ----------------------------- ----------------------------- ----------------------------- -------------A--A------------ -------------A--A------------ ------------A----A----------- -------------A--A------------ ----------------------------- ----------------------------- ----------------------------- ----------------------------- ----------------------------- ----------------------------- ----------------------------- ----------------------------- ----------------------------- ----------------------------- ----------------------------- ----------------------------- ----------------------------- ----------------------------- 
----------------------------- ----------------------------- ----------------------------- ----------------------------- ----------------------------- ----------------------------- ----------------------------- ----------------------------- ----------------------------- ----------------------------- ----------------------------- ----------------------------- -------------A--A------------ ----------------------------- ----------------------------- -----------A------A---------- ----------------------------- -------------A--A------------ ----------------------------- ----------------------------- ----------------------------- ----------------------------- ----------------------------- ----------------------------- ----------------------------- ----------------------------- ----------------------------- ----------------------------- ----------------------------- ----------------------------- ----------------------------- 
----------------------------- ----------------------------- ----------------------------- ----------------------------- ----------------------------- ----------------------------- ----------------------------- ----------------------------- ----------------------------- ----------------------------- ----------------------------- -------------A--A------------ ----------------------------- ----------------------------- -------------A--A------------ ----------A--------A--------- ----------------------------- ----------------------------- -------------A--A------------ ----------------------------- ----------------------------- ----------------------------- ----------------------------- ----------------------------- ----------------------------- ----------------------------- ----------------------------- ----------------------------- ----------------------------- ----------------------------- ----------------------------- 
----------------------------- ----------------------------- ----------------------------- ----------------------------- ----------------------------- ----------------------------- ----------------------------- ----------------------------- ----------------------------- ----------------------------- -------------A--A------------ ----------------------------- ----------------------------- ----------------------------- -------------A--A------------ ---------A----------A-------- ----------------------------- ----------------------------- ----------------------------- -------------A--A------------ ----------------------------- ----------------------------- ----------------------------- ----------------------------- ----------------------------- ----------------------------- ----------------------------- ----------------------------- ----------------------------- ----------------------------- ----------------------------- 
----------------------------- ----------------------------- ----------------------------- ----------------------------- ----------------------------- ----------------------------- ----------------------------- ----------------------------- ----------------------------- -------------A--A------------ ----------------------------- ----------------------------- ----------------------------- ----------------------------- ----------------------------- --------A------------A------- ----------------------------- ----------------------------- ----------------------------- ----------------------------- -------------A--A------------ ----------------------------- ----------------------------- ----------------------------- ----------------------------- ----------------------------- ----------------------------- ----------------------------- ----------------------------- ----------------------------- ----------------------------- 
----------------------------- ----------------------------- ----------------------------- ----------------------------- ----------------------------- ----------------------------- ----------------------------- ----------------------------- -------------A--A------------ ----------------------------- ----------------------------- ----------------------------- ----------------------------- ----------------------------- -------------A--A------------ -------A--------------A------ ----------------------------- ----------------------------- ----------------------------- ----------------------------- ----------------------------- -------------A--A------------ ----------------------------- ----------------------------- ----------------------------- ----------------------------- ----------------------------- ----------------------------- ----------------------------- ----------------------------- ----------------------------- 
----------------------------- ----------------------------- ----------------------------- ----------------------------- ----------------------------- ----------------------------- ----------------------------- -------------A--A------------ ----------------------------- ----------------------------- ----------------------------- ----------------------------- ----------------------------- ----------------------------- -------------A--A------------ ------A----------------A----- ----------------------------- ----------------------------- ----------------------------- ----------------------------- ----------------------------- ----------------------------- -------------A--A------------ ----------------------------- ----------------------------- ----------------------------- ----------------------------- ----------------------------- ----------------------------- ----------------------------- ----------------------------- 
----------------------------- ----------------------------- ----------------------------- ----------------------------- ----------------------------- ----------------------------- -------------A--A------------ ----------------------------- ----------------------------- ----------------------------- ----------------------------- ----------------------------- ----------------------------- ----------------------------- ----------------------------- -----A------------------A---- ----------------------------- ----------------------------- ----------------------------- ----------------------------- ----------------------------- ----------------------------- ----------------------------- -------------A--A------------ ----------------------------- ----------------------------- ----------------------------- ----------------------------- ----------------------------- ----------------------------- ----------------------------- 
----------------------------- ----------------------------- ----------------------------- ----------------------------- ----------------------------- -------------A--A------------ ----------------------------- ----------------------------- ----------------------------- ----------------------------- ----------------------------- ----------------------------- ----------------------------- ----------------------------- -------------A--A------------ ----A--------------------A--- ----------------------------- ----------------------------- ----------------------------- ----------------------------- ----------------------------- ----------------------------- ----------------------------- ----------------------------- -------------A--A------------ ----------------------------- ----------------------------- ----------------------------- ----------------------------- ----------------------------- ----------------------------- 
----------------------------- ----------------------------- ----------------------------- ----------------------------- -------------A--A------------ ----------------------------- ----------------------------- ----------------------------- ----------------------------- ----------------------------- ----------------------------- ----------------------------- ----------------------------- ----------------------------- -------------A--A------------ ---A----------------------A-- ----------------------------- ----------------------------- ----------------------------- ----------------------------- ----------------------------- ----------------------------- ----------------------------- ----------------------------- ----------------------------- -------------A--A------------ ----------------------------- ----------------------------- ----------------------------- ----------------------------- ----------------------------- 
----------------------------- ----------------------------- ----------------------------- -------------A--A------------ ----------------------------- ----------------------------- ----------------------------- ----------------------------- ----------------------------- ----------------------------- ----------------------------- ----------------------------- ----------------------------- ----------------------------- ----------------------------- --A------------------------A- ----------------------------- ----------------------------- ----------------------------- ----------------------------- ----------------------------- ----------------------------- ----------------------------- ----------------------------- ----------------------------- ----------------------------- -------------A--A------------ ----------------------------- ----------------------------- ----------------------------- ----------------------------- 
----------------------------- ----------------------------- -------------A--A------------ ----------------------------- ----------------------------- ----------------------------- ----------------------------- ----------------------------- ----------------------------- ----------------------------- ----------------------------- ----------------------------- ----------------------------- ----------------------------- -------------A--A------------ -A--------------------------A ----------------------------- ----------------------------- ----------------------------- ----------------------------- ----------------------------- ----------------------------- ----------------------------- ----------------------------- ----------------------------- ----------------------------- ----------------------------- -------------A--A------------ ----------------------------- ----------------------------- ----------------------------- 
----------------------------- -------------A--A------------ ----------------------------- ----------------------------- ----------------------------- ----------------------------- ----------------------------- ----------------------------- ----------------------------- ----------------------------- ----------------------------- ----------------------------- ----------------------------- ----------------------------- -------------A--A------------ A---------------------------- ----------------------------- ----------------------------- ----------------------------- ----------------------------- ----------------------------- ----------------------------- ----------------------------- ----------------------------- ----------------------------- ----------------------------- ----------------------------- ----------------------------- -------------A--A------------ ----------------------------- ----------------------------- 
-------------A--A------------ ----------------------------- ----------------------------- ----------------------------- ----------------------------- ----------------------------- ----------------------------- ----------------------------- ----------------------------- ----------------------------- ----------------------------- ----------------------------- ----------------------------- ----------------------------- ----------------------------- ----------------------------- ----------------------------- ----------------------------- ----------------------------- ----------------------------- ----------------------------- ----------------------------- ----------------------------- ----------------------------- ----------------------------- ----------------------------- ----------------------------- ----------------------------- ----------------------------- -------------A--A------------ ----------------------------- 
----------------------------- ----------------------------- ----------------------------- ----------------------------- ----------------------------- ----------------------------- ----------------------------- ----------------------------- ----------------------------- ----------------------------- ----------------------------- ----------------------------- ----------------------------- ----------------------------- -------------A--A------------ ----------------------------- ----------------------------- ----------------------------- ----------------------------- ----------------------------- ----------------------------- ----------------------------- ----------------------------- ----------------------------- ----------------------------- ----------------------------- ----------------------------- ----------------------------- ----------------------------- ----------------------------- ----------------------------- 
----------------------------- ----------------------------- ----------------------------- ----------------------------- ----------------------------- ----------------------------- ----------------------------- ----------------------------- ----------------------------- ----------------------------- ----------------------------- ----------------------------- ----------------------------- ----------------------------- -------------A--A------------ ----------------------------- ----------------------------- ----------------------------- ----------------------------- ----------------------------- ----------------------------- ----------------------------- ----------------------------- ----------------------------- ----------------------------- ----------------------------- ----------------------------- ----------------------------- ----------------------------- ----------------------------- ----------------------------- 
----------------------------- ----------------------------- ----------------------------- ----------------------------- ----------------------------- ----------------------------- ----------------------------- ----------------------------- ----------------------------- ----------------------------- ----------------------------- ----------------------------- ----------------------------- ----------------------------- ----------------------------- ----------------------------- ----------------------------- ----------------------------- ----------------------------- ----------------------------- ----------------------------- ----------------------------- ----------------------------- ----------------------------- ----------------------------- ----------------------------- ----------------------------- ----------------------------- ----------------------------- ----------------------------- ----------------------------- 
----------------------------- ----------------------------- ----------------------------- ----------------------------- ----------------------------- ----------------------------- ----------------------------- ----------------------------- ----------------------------- ----------------------------- ----------------------------- ----------------------------- ----------------------------- ----------------------------- -------------A--A------------ ----------------------------- ----------------------------- ----------------------------- ----------------------------- ----------------------------- ----------------------------- ----------------------------- ----------------------------- ----------------------------- ----------------------------- ----------------------------- ----------------------------- ----------------------------- ----------------------------- ----------------------------- ----------------------------- 
