model
size = 17 21 23, scale = 0.05, origin = -y
material 
  colors = A:#EEE B:#633 C:#BBB D:#555 E:#963 F:#CF0 G:#930 H:#933 I:#777 J:#444
voxels
------AAAAA------ ------AAAAA------ ------AAAAA------ ------AAAAA------ ------AAAAA------ ------AAAAA------ ------AAAAA------ ------AAAAA------ ------AAAAA------ ------AAAAA------ ------AAAAA------ ------AAAAA------ ------AAAAA------ ------AAAAA------ ------AAAAA------ ------AAAAA------ ------AAAAA------ ------AAAAA------ ------AAAAA------ ------AAAAA------ ------AAAAA------ 
----AAAAAAAAA---- ----AAAAAAAAA---- ----AAAAAAAAA---- ----AAAAAAAAA---- ----AAAAAAAAA---- ----AAAAAAAAA---- ----AAAAAAAAA---- ----AAAAAAAAA---- ----AAAAAAAAA---- ----AAAAAAADD---- ----AAAAAAADD---- ----AAABBBADD---- ----AAABEEAJJ---- ----AAA---AJJ---- ----AAA---AJJ---- ----AAA---AAA---- ----AAA---AAA---- ----AAA---AAA---- ----AAA---AAA---- ----AAA---AAA---- ----AAA---AAA---- 
--AACCCCCCCCCAA-- --AAAAAAAAAAAAA-- --AAAAAAAAAAAAA-- --AAAAAAAAAAAAA-- --AAAAAAAAAAAAA-- --AAAAAAAAAAAAA-- --AAAAAAAAAAAAA-- --AAAAAAAAAAAAA-- --AAAAAAAAAAAAA-- --AAAAAAAAAAADD-- --AAAAAAAAAAADD-- --AAABBBBBBBADD-- --AAABBEBBBBAJJ-- --AAA-------AJJ-- --AAA-------AJJ-- --AAA-------AAA-- --AAA-------AAA-- --AAA-------AAA-- --AAA-------AAA-- --AAA-------AAA-- --AAA-------AAA-- 
--ACCCCCCCCCCCA-- --AAAAAAAAAAAAA-- --AAAAAAAAAAAAA-- --AAAAAAAAAAAAA-- --AAAAAAAAAAAAA-- --AAAAAAAAAAAAA-- --AAAAAAAAAAAAC-- --AAAAAAAAAAAAC-- --AAAAAAAAAAAAC-- --AAAAAAAAAAAAA-- --AAAAAAAAAAAAA-- --ABBBBBBBBBBAA-- --ABBBEBBBEBBAA-- --A------G---AA-- --A------G---AA-- --A----------AD-- --A----------AD-- --A----------AD-- --A----------AA-- --A----------AA-- --A----------AA-- 
-ACCFCFCCCFCFCCA- -AAAAAAAAAAAAAAA- -AAAAAAAAAAAAAAA- -AAAAAAAAAAAAAAA- -AAAAAAAAAAAAAAA- -AAAAAAAAAAAAAAA- -AAAAAAAAAAAAAAC- -IAAAAAAAAAAAAAC- -IAAAAAAAAAAAAAC- -IAAAAAAAAAAAAAA- -AAAAAAAAAAAAAAA- -AABBBBBBBBBBBBA- -AABBBBBBBBBBEBA- -AAAEEEHGA--G--A- -AAA-E-E-------A- -DA------------D- -DA------------D- -DA------------D- -AA------------A- -AA------------A- -AA------------A- 
-ACFFFFCCFFFFCCA- -AAAAAAAAAAAAAAA- -AAAAAAAAAAAAAAA- -AAAAAAAAAAAAAAA- -AAAAAAAAAAAAAAA- -AAAAAAAAAAAAAAA- -AAAAAAAAAAAAAAC- -IAAAAAAAAAAAAAC- -IAAAAAAAAAAAAAC- -IAAAAAAAAAAAAAA- -AAAAAAAAAAAAAAA- -ABBBBBBBBBBBBBA- -ABBEEBBEBBBBEBA- -A-E---G-AGGG--A- -A-------E-----A- -D-------------D- -D-------------D- -D-------------D- -A-------------A- -A-------------A- -A-------------A- 
AACFCCCFCFCCCFCAA AAAAAAAAAAAAAAAAA AAAAAAAAAAAAAAAAA AAAAAAAAAAAAAAAAA AAAAAAAAAAAAAAAAA AAAAAAAAAAAAAAAAA AAAAAAAAAAAAAAAAD IAAAAAAAAAAAAAAAD IAAAAAAAAAAAAAAAD IAAAAAAAAAAAAAAAA AAAAAAAAAAAAAAAAA AABBBBBBBBBBBBBAA AABEBBBBBBBBEBBAA AAA---GG-EHE---AA AA--------A----AA DA--------G----AC DA-------------AC DA-------------AC AA-------------AA AA-------------AA AA-------------AA 
AACFCCCFCFCCCFCAA AAAAAAAAAAAAAAAAA AAAAAAAAAAAAAAAAA AAAAAAAAAAAAAAAAA AAAAAAAAAAAAAAAAA AAAAAAAAAAAAAAAAA AAAAAAAAAAAAAAAAD DAAAAAAAAAAAAAAAD DAAAAAAAAAAAAAAAD DAAAAAAAAAAAAAAAA AAAAAAAAAAAAAAAAA ABBBBBBBBBBBBBBBA ABBEBBBBBBBBBBBBA A---HG-GAEHG-GG-A A---------A--E--A C---------------C C---------------C C---------------C A---------------A A---------------A A---------------A 
AACFFFFCCFFFFCCAA AAAAAAAABAAAAAAAA AAAAAAAABAAAAAAAA AAAAAAAABAAAAAAAA AAAAAAAABAAAAAAAA AAAAAAAABAAAAAAAA AAAAAAAABAAAAAAAD DAAAAAAABAAAAAAAD DAAAAAAABAAAAAAAD DAAAAAAABAAAAAAAA AAAAAAAABAAAAAAAA ABBBBBBBBBBBBBBBA ABBBBBBEBEBBBBBBA AGGE-H----H-GG--A A------------G--A C---------------C C---------------C C---------------C A---------------A A---------------A A---------------B 
AACFCCCFCFCCCFCAA AAAAAAAAAAAAAAAAA AAAAAAAAAAAAAAAAA AAAAAAAAAAAAAAAAA AAAAAAAAAAAAAAAAA AAAAAAAAAAAAAAAAA AAAAAAAAAAAAAAAAA DAAAAAAAAAAAAAAAA DAAAAAAAAAAAAAAAA DAAAAAAAAAAAAAAAA AAAAAAAAAAAAAAAAA ABBBBBBBBBBBBBBBA ABBBBBBBBEBBBBBBA A--H-EHA--E--G--A A--E--E------G--A C---------------A C---------------A C---------------A A---------------A A---------------B A---------------A 
AACFCCCFCFCCCFCAA AAAAAAAAAAAAAAAAA AAAAAAAAAAAAAAAAA AAAAAAAAAAAAAAAAA AAAAAAAAAAAAAAAAA AAAAAAAAAAAAAAAAA AAAAAAAAAAAAAAAAA AAAAAAAAAAAAAAAAA AAAAAAAAAAAAAAAAA IAAAAAAAAAAAAAAAA IAAAAAAAAAAAAAAAA IABBBBBBBBBBBBBAA DABBBBBBBEBBBBBAA DA-GH--HH-AEAG-AA DA--A--AE--E-H-AA AA--E----------AA AA-------------AA AA-------------AB AA-------------AA AA-------------AB AA-------------BE 
-ACFFFFCCFFFFCCA- -AAAAAAAAAAAAAAA- -AAAAAAAAAAAAAAA- -AAAAAAAAAAAAAAA- -AAAAAAAAAAAAAAA- -AAAAAAAAAAAAAAA- -AAAAAAAAAAAAAAA- -AAAAAAAAAAAAAAA- -AAAAAAAAAAAAAAA- -IAAAAAAAAAAAAAA- -IAAAAAAAAAAAAAA- -IBBBBBBBBBBBBBA- -DBBBBEEEBBEBBBA- -D--AH---E--AH-E- -D--GG---------A- -A-------------E- -A-------------A- -A-------------B- -A-------------A- -A-------------E- -A-------------B- 
-AACFCFCCCFCFCAA- -AAAAAAAAAAAAAAA- -AAAAAAAAAAAAAAA- -AAAAAAAAAAAAAAA- -AAAAAAAAAAAAAAA- -AAAAAAAAAAAAAAA- -AAAAAAAAAAAAAAA- -AAAAAAAAAAAAAAA- -AAAAAAAAAAAAAAA- -IAAAAAAAAAAAAAA- -IAAAAAAAAAAAAAA- -IABBBBBBBBBBBAA- -DABBBBBBBBBBBAA- -DA--G-HHH-G--AA- -DA-----E-----AA- -AA-----------AA- -AA-----------AA- -AA-----------AA- -AA-----------AA- -AA-----------AA- -AA-----------BA- 
--AACCCCCCCCCAA-- --AAAAAAAAAAAAA-- --AAAAAAAAAAAAA-- --AAAAAAAAAAAAA-- --AAAAAAAAAAAAA-- --AAAAAAAAAAAAA-- --AAAAAAAAAAAAA-- --AAAAAAAAAAAAA-- --AAAAAAAAAAAAA-- --AAAAAAAAAAAAA-- --AAAAAAAAAAAAA-- --AABBBBBBBBBAA-- --AABBBBBBBBBAB-- --AA----HHGA-AA-- --AA---------AA-- --AA---------AB-- --AA---------AB-- --AA---------AA-- --AA---------AA-- --AA---------AB-- --AA---------EE-- 
--AAAAAAAAAAAAA-- --AAAAAAAAAAAAA-- --AAAAAAAAAAAAA-- --AAAAAAAAAAAAA-- --AAAAAAAAAAAAA-- --AAAAAAAAAAAAA-- --AAAAAAAAAAAAA-- --AAAAAAAAAAAAA-- --AAAAAAAAAAAAA-- --AAAAAAAAAAAAA-- --AAAAAAAAAAAAA-- --AAA--BBBBBAAA-- --AAA--BBBBBAAA-- --AAA--G-GG-AAA-- --AAA-------AAA-- --AAA-------AAA-- --AAA-------AAA-- --AAA-------AAA-- --AAA-------AAA-- --AAA-------AAA-- --AAA-------AAE-- 
----AAAAAAAAA---- ----AAAAAAAAA---- ----AAAAAAAAA---- ----AAAAAAAAA---- ----AAAAAAAAA---- ----AAAAAAAAA---- ----AAAAAAAAA---- ----AAAAAAAAA---- ----AAAAAAAAA---- ----AAAAAAAAA---- ----AAAAAAAAA---- ----AAABBBAAA---- ----AAABBBAAA---- ----AAA---AAA---- ----AAA---AAA---- ----AAA---AAA---- ----AAA---AAA---- ----AAA---AAA---- ----AAA---AAA---- ----AAA---AAA---- ----AAA---AAA---- 
------AAAAA------ ------AAAAA------ ------AAAAA------ ------AAAAA------ ------AAAAA------ ------AAAAA------ ------AAAAA------ ------AAAAA------ ------AAAAA------ ------AAAAA------ ------AAAAA------ ------AAAAA------ ------AAAAA------ ------AAAAA------ ------AAAAA------ ------AAAAA------ ------AAAAA------ ------AAAAA------ ------AAAAA------ ------AAAAA------ ------AAAAA------ 
----------------- ------AAAAA------ ------AAAAA------ ------AAAAA------ ------AAAAA------ ----------------- ----------------- ----------------- ----------------- ----------------- ----------------- ----------------- ----------------- ----------------- ----------------- ----------------- ----------------- ------AAAAA------ ------AAAAA------ ------AAAAA------ ----------------- 
----------------- ----------------- -------AAA------- -------AAA------- -------AAA------- -------AAA------- ----------------- ----------------- ----------------- ----------------- ----------------- ----------------- ----------------- ----------------- ----------------- ----------------- ----------------- -------AAA------- -------AAA------- ----------------- ----------------- 
----------------- ----------------- ----------------- ----------------- -------AAA------- -------AAA------- -------AAA------- ----------------- ----------------- ----------------- ----------------- ----------------- ----------------- ----------------- ----------------- ----------------- -------AAA------- -------AAA------- ----------------- ----------------- ----------------- 
----------------- ----------------- ----------------- ----------------- ----------------- -------AAA------- -------AAA------- -------AAA------- ----------------- ----------------- ----------------- ----------------- ----------------- ----------------- ----------------- -------AAA------- -------AAA------- ----------------- ----------------- ----------------- ----------------- 
----------------- ----------------- ----------------- ----------------- ----------------- ----------------- ----------------- -------AAA------- -------AAA------- -------AAA------- ----------------- ----------------- ----------------- ----------------- -------AAA------- -------AAA------- ----------------- ----------------- ----------------- ----------------- ----------------- 
----------------- ----------------- ----------------- ----------------- ----------------- ----------------- ----------------- ----------------- ----------------- -------AAA------- -------AAA------- -------AAA------- -------AAA------- -------AAA------- -------AAA------- ----------------- ----------------- ----------------- ----------------- ----------------- ----------------- 
