model
size = 32 23 31, scale = 0.05, origin = -y
material 
  colors = A:#0E0 B:#777 C:#111 D:#080 E:#000 F:#FF3 G:#444 H:#555 I:#00E J:#D00 K:#00F L:#E00
voxels
34A2I24A2J34A640-33A30B3A4B6A7C9A2E2A640-33A30B3AB2GB6A7C9A2E2A640-33A30B3AG3B6A3CL3C2(13A640-33A30B13A7C)6A2(CA)C2A640-33A30B33A640-33A30B3A2(2CA)2(CA)7C2(AC)E3(AC)2A640-33A30B33A640-32A-E29B3A2E13(AE)2A640-32A-E28BE-32A640-33A30B3A3E11(AE)A2E2A640-32A-E28BE-32A640-32A-E28BE-2A2E11(AE)A3E2A640-33A30B33A640-32A-I28BE-2A3E11(AE)A2E2A640-33A29BE-32A640-2(33A30DA672-)C30A2C27B2FB2C30DC2A3D22A3D34A576-33CKIK22CJC2-34CA2(30B2A)30C2A30CA608-65A2(30B2A)30C2A30CA608-54A2(3F2A3F3A2(30B2A)30C2A30CA608-21AF2AFAF2AF24A)3F2A3F3A2(30B2A)30C2A30CA608-8A2B2H28A2B2H21A2(30B2A)30C2A30CA608-12A2B30A2B19A2(30B2A)30C2A30CA608-12A2G30A2G19A2(30B2A)30C2A30CA608-8A2H2G28A2H2G21A2(30B2A)30C33A609-31A-32A30B33A672-64A
