model
size = 31 26 31, scale = 0.05, origin = -y
material 
  colors = A:#0FF B:#03F C:#F0C D:#009 E:#FF0 F:#0E0 G:#3CC
voxels
------------------------------- ------------------------------- ------------------------------- ------------------------------- ------------------------------- ------------------------------- ------------------------------- ------------------------------- ------------------------------- ------------------------------- ------------------------------- ------------------------------- ------------------------------- --------------DDD-------------- ------------D-DCD-D------------ ------------D-DCD-D------------ ------------D-DDD-D------------ ------------------------------- ------------------------------- ------------------------------- ------------------------------- ------------------------------- ------------------------------- ------------------------------- ------------------------------- ------------------------------- 
------------------------------- ------------------------------- ------------------------------- ------------------------------- ------------------------------- ------------------------------- ------------------------------- ------------------------------- ------------------------------- ------------------------------- ------------------------------- ------------------------------- ------------------------------- ----------DDBBBBBBBDD---------- ---------DDCBBBBBBBCDD--------- ----------DCBBBBBBBCD---------- -----------DBBBBBBBD----------- ------------EEEEEEE------------ ------------------------------- ------------------------------- ------------------------------- ------------------------------- ------------------------------- ------------------------------- ------------------------------- ------------------------------- 
------------------------------- ------------------------------- ------------------------------- ------------------------------- ------------------------------- ------------------------------- ------------------------------- ------------------------------- ------------------------------- ------------------------------- ------------------------------- ------------------------------- ------------------------------- ---------BBB-------BBB--------- -------DDDBB-------BBDDD------- ---------BBB-------BBB--------- ---------BBB-------BBB--------- ---------EEEAAAAAAAEEE--------- ------------AAAAAAA------------ ------------CCCCCCC------------ -------------CC-CC------------- ------------------------------- ------------------------------- ------------------------------- ------------------------------- ------------------------------- 
------------------------------- ------------------------------- ------------------------------- ------------------------------- ------------------------------- ------------------------------- ------------------------------- ------------------------------- ------------------------------- ------------------------------- ------------------------------- ------------------------------- ------------------------------- -------BB-------------BB------- ------DDD-------------DDD------ ------DBB-------------BBD------ -------BB-------------BB------- --------EAAA-------AAAE-------- ---------AAA-------AAA--------- ----------CCAAAAAAACC---------- -----------CAAAAAAAC----------- -------------CC-CC------------- ------------C-C-C-C------------ ------------------------------- ------------------------------- ------------------------------- 
------------------------------- ------------------------------- ------------------------------- ------------------------------- ------------------------------- ------------------------------- ------------------------------- ------------------------------- ------------------------------- ------------------------------- ------------------------------- ------------------------------- ------------------------------- ------B-----------------B------ ------B-----------------B------ -----DD-----------------DD----- ------BG---------------GB------ ------EEA-------------AEE------ -------EAA-----------AAE------- ---------CAA-------AAC--------- ---------CAA-------AAC--------- -----------CAAAAAAAC----------- ----------C-AAAAAAA-C---------- ------------C-C-C-C------------ ------------------------------- ------------------------------- 
------------------------------- ------------------------------- ------------------------------- ------------------------------- ------------------------------- ------------------------------- ------------------------------- ------------------------------- ------------------------------- ------------------------------- ------------------------------- ------------------------------- ------------------------------- -----B-------------------B----- -----B-------------------B----- ----DD-------------------DD---- -----B-------------------B----- -----EAA---------------AAE----- ------AA---------------AA------ -------EAA-----------AAE------- -------EAA-----------AAE------- ---------CAA-------AAC--------- ---------CAAAAAAAAAAAC--------- ----------C-CCC-CCC-C---------- ------------------------------- ------------------------------- 
------------------------------- ------------------------------- ------------------------------- ------------------------------- ------------------------------- ------------------------------- ------------------------------- ------------------------------- ------------------------------- ------------------------------- ------------------------------- ---D-----------------------D--- ------------------------------- ----B---------------------B---- ---DB---------------------B---- ---DD---------------------DD--- ----B---------------------B---- ----EA-------------------AE---- -----AA-----------------AA----- -------A---------------A------- -------A---------------A------- -------EAA-----------AAE------- -------EAAAA-------AAAAE------- ---------CCCAAAAAAACCC--------- -------------CC-CC------------- ------------------------------- 
---B-----------------------B--- ---B-----------------------B--- ---B-----------------------B--- ---B-----------------------B--- ---B-----------------------B--- ---B-----------------------B--- ---B-----------------------B--- ---B-----------------------B--- ---B-----------------------B--- ---B-----------------------B--- ---B-----------------------B--- --DD-----------------------DD-- ---B-----------------------B--- ---B-----------------------B--- --DD-----------------------DD-- ---B-----------------------B--- ---BG---------------------GB--- ----EA-------------------AE---- -----A-------------------A----- -----EA-----------------AE----- -----EA-----------------AE----- -------A---------------A------- ------EAAA-----------AAAE------ --------CCAAAAAAAAAAACC-------- -----------C-CCCCC-C----------- ------------------------------- 
---B-----------------------B--- ---B-----------------------B--- --FF-----------------------FF-- --FF-----------------------FF-- --FF-----------------------FF-- --FF-----------------------FF-- --FF-----------------------FF-- --FF-----------------------FF-- --FF-----------------------FF-- --FF-----------------------FF-- ---B-----------------------B--- --DD-----------------------DD-- ---B-----------------------B--- ---B-----------------------B--- --DD-----------------------DD-- ---B-----------------------B--- ---B-----------------------B--- ---EA---------------------AE--- ----A---------------------A---- ----EA-------------------AE---- ----EA-------------------AE---- ------A-----------------A------ ------AAA-------------AAA------ ------E-CAAAAAAAAAAAAAC-E------ ---------C-CC-C-C-CC-C--------- ------------------------------- 
------------------------------- --B-------------------------B-- --B-------------------------B-- -FF-------------------------FF- -FF-------------------------FF- -FF-------------------------FF- -FF-------------------------FF- -FF-------------------------FF- -FF-------------------------FF- --B-------------------------B-- --B-------------------------B-- -DD-------------------------DD- --B-------------------------B-- --B-------------------------B-- -DD-------------------------DD- --B-------------------------B-- --B-------------------------B-- --EA-----------------------AE-- ---AA---------------------AA--- ----EA-------------------AE---- ----EA-------------------AE---- ------A-----------------A------ ------AA---------------AA------ ------E-AAAAAAAAAAAAAAA-E------ --------CCC-C-C-C-C-CCC-------- ------------------------------- 
------------------------------- --B-------------------------B-- --B-------------------------B-- --B-------------------------B-- -FF-------------------------FF- -FF-------------------------FF- -FF-------------------------FF- -FF-------------------------FF- --B-------------------------B-- --B-------------------------B-- -DD-------------------------DD- --B-------------------------B-- --B-------------------------B-- --B-------------------------B-- --B-------------------------B-- -DD-------------------------DD- --B-------------------------B-- --EA-----------------------AE-- ---A-----------------------A--- ---EA---------------------AE--- ---EA---------------------AE--- ----EA-------------------AE---- -----AA-----------------AA----- ------EAAAAAAAAAAAAAAAAAE------ --------CCC-CCCCCCC-CCC-------- ------------------------------- 
------------------------------- --B-------------------------B-- --B-------------------------B-- --B-------------------------B-- --B-------------------------B-- --B-------------------------B-- --B-------------------------B-- --B-------------------------B-- --B-------------------------B-- --B-------------------------B-- -DD-------------------------DD- --B-------------------------B-- -CC-------------------------CC- -CC-------------------------CC- --B-------------------------B-- -DD-------------------------DD- --B-------------------------B-- --EA-----------------------AE-- ---A-----------------------A--- ---EA---------------------AE--- ---EA---------------------AE--- ----EA-------------------AE---- -----AA-----------------AA----- ------EAAAAAA-----AAAAAAE------ --------CCCCCAAAAACCCCC-------- -------------CC-CC------------- 
------------------------------- ------------------------------- ------------------------------- ------------------------------- ------------------------------- ------------------------------- ------------------------------- ------------------------------- ------------------------------- ------------------------------- ------------------------------- -DD-------------------------DD- ------------------------------- -B---------------------------B- -B---------------------------B- DD---------------------------DD -B---------------------------B- -EA-------------------------AE- --A-------------------------A-- --EA-----------------------AE-- --EA-----------------------AE-- ---EA---------------------AE--- ----AA-------------------AA---- -----EAAAAAA-------AAAAAAE----- -------CCC-CAAAAAAAC-CCC------- -------------CCCCC------------- 
------------------------------- ------------------------------- ------------------------------- ------------------------------- ------------------------------- ------------------------------- ------------------------------- ------------------------------- ------------------------------- ------------------------------- ------------------------------- ------------------------------- ------------------------------- -B---------------------------B- DD---------------------------DD -B---------------------------B- -B---------------------------B- -EA-------------------------AE- --A-------------------------A-- --EA-----------------------AE-- --EA-----------------------AE-- ---EA---------------------AE--- ----AA-------------------AA---- -----EAAAAA---------AAAAAE----- -------CCCCAAAAAAAAACCCC------- -----------CCCC-CCCC----------- 
------------------------------- ------------------------------- ------------------------------- ------------------------------- ------------------------------- ------------------------------- ------------------------------- ------------------------------- ------------------------------- ------------------------------- ------------------------------- ------------------------------- ------------------------------- -B---------------------------B- DD---------------------------DD -B---------------------------B- -B---------------------------B- -EA-------------------------AE- --A-------------------------A-- --EA-----------------------AE-- --EA-----------------------AE-- ---EA---------------------AE--- ---EAA-------------------AA---- -----EAAAAA---------AAAAAE----- -------CCCCAAAAAAAAACCCC------- -----------CCC---CCC----------- 
------------------------------- ------------------------------- ------------------------------- ------------------------------- ------------------------------- ------------------------------- ------------------------------- ------------------------------- ------------------------------- ------------------------------- ------------------------------- ------------------------------- ------------------------------- -B---------------------------B- DD---------------------------DD -B---------------------------B- -B---------------------------B- -EA-------------------------AE- --A-------------------------A-- --EA-----------------------AE-- --EA-----------------------AE-- ---EA---------------------AE--- ---EAA-------------------AA---- -----EAAAAA---------AAAAAE----- -------C--CAAAAAAAAAC--C------- ------------C-----C------------ 
------------------------------- ------------------------------- ------------------------------- ------------------------------- ------------------------------- ------------------------------- ------------------------------- ------------------------------- ------------------------------- ------------------------------- ------------------------------- ------------------------------- ------------------------------- -B---------------------------B- -B---------------------------B- DD---------------------------DD -B---------------------------B- -EA-------------------------AE- --A-------------------------A-- --EA-----------------------AE-- --EA-----------------------AE-- ---EA---------------------AE--- ---EAA-------------------AA---- -----EAAAAA---------AAAAAE----- -------CCCCAAAAAAAAACCCC------- -----------CCC---CCC----------- 
------------------------------- ------------------------------- ------------------------------- ------------------------------- ------------------------------- ------------------------------- ------------------------------- ------------------------------- ------------------------------- ------------------------------- ------------------------------- ------------------------------- ------------------------------- -B---------------------------B- -B---------------------------B- DD---------------------------DD -B---------------------------B- -EA-------------------------AE- --A-------------------------A-- --EA-----------------------AE-- --EA-----------------------AE-- ---EA---------------------AE--- ----AA-------------------AA---- -----EAAAAA---------AAAAAE----- -------CCCCAAAAAAAAACCCC------- -----------CCCC-CCCC----------- 
------------------------------- ------------------------------- ------------------------------- ------------------------------- ------------------------------- ------------------------------- ------------------------------- ------------------------------- ------------------------------- ------------------------------- -DD-------------------------DD- ------------------------------- ------------------------------- -B---------------------------B- -B---------------------------B- DD---------------------------DD -B---------------------------B- -EA-------------------------AE- --A-------------------------A-- --EA-----------------------AE-- --EA-----------------------AE-- ---EA---------------------AE--- ----AA-------------------AA---- -----EAAAAAA-------AAAAAAE----- -------CCC-CAAAAAAAC-CCC------- -------------CCCCC------------- 
------------------------------- ------------------------------- --B-------------------------B-- --B-------------------------B-- --B-------------------------B-- --B-------------------------B-- --B-------------------------B-- --B-------------------------B-- --B-------------------------B-- --B-------------------------B-- --B-------------------------B-- -DD-------------------------DD- --B-------------------------B-- --B-------------------------B-- -DD-------------------------DD- --B-------------------------B-- --B-------------------------B-- --EA-----------------------AE-- ---A-----------------------A--- ---EA---------------------AE--- ---EA---------------------AE--- ----EA-------------------AE---- -----AA-----------------AA----- ------EAAAAAA-----AAAAAAE------ --------CCCCCAAAAACCCCC-------- -------------CC-CC------------- 
------------------------------- ------------------------------- --B-------------------------B-- -FF-------------------------FF- -FF-------------------------FF- -FF-------------------------FF- -FF-------------------------FF- -FF-------------------------FF- -FF-------------------------FF- -FF-------------------------FF- --B-------------------------B-- -DD-------------------------DD- --B-------------------------B-- --B-------------------------B-- -DD-------------------------DD- --B-------------------------B-- --B-------------------------B-- --EA-----------------------AE-- ---A-----------------------A--- ---EA---------------------AE--- ---EA---------------------AE--- ----EA-------------------AE---- -----AA-----------------AA----- ------EAAAAAAAAAAAAAAAAAE------ --------CCC-CCCCCCC-CCC-------- ------------------------------- 
------------------------------- ------------------------------- --B-------------------------B-- --B-------------------------B-- --B-------------------------B-- --B-------------------------B-- --B-------------------------B-- --B-------------------------B-- --B-------------------------B-- --B-------------------------B-- --B-------------------------B-- -DD-------------------------DD- --B-------------------------B-- --B-------------------------B-- -DD-------------------------DD- --B-------------------------B-- --B-------------------------B-- --EA-----------------------AE-- ---AA---------------------AA--- ----EA-------------------AE---- ----EA-------------------AE---- -----EA-----------------AE----- ------AA---------------AA------ ------E-AAAAAAAAAAAAAAA-E------ --------CCC-C-C-C-C-CCC-------- ------------------------------- 
------------------------------- ------------------------------- ------------------------------- ---B-----------------------B--- --FF-----------------------FF-- --FF-----------------------FF-- --FF-----------------------FF-- --FF-----------------------FF-- --FF-----------------------FF-- ---B-----------------------B--- --DD-----------------------DD-- --DB-----------------------BD-- ---B-----------------------B--- ---B-----------------------B--- --DB-----------------------BD-- --DD-----------------------DD-- ---B-----------------------B--- ---EA---------------------AE--- ----A---------------------A---- ----EA-------------------AE---- ----EA-------------------AE---- -----EA-----------------AE----- ------AAA-------------AAA------ ------E--AAAAAAAAAAAAA--E------ ---------C-CCCC-CCCC-C--------- ------------------------------- 
------------------------------- ------------------------------- ------------------------------- ---B-----------------------B--- ---B-----------------------B--- ---B-----------------------B--- ---B-----------------------B--- ---B-----------------------B--- ---B-----------------------B--- ---B-----------------------B--- --DD-----------------------DD-- ---B-----------------------B--- ---B-----------------------B--- ---B-----------------------B--- ---B-----------------------B--- --DD-----------------------DD-- ---BG---------------------GB--- ----EA-------------------AE---- -----A-------------------A----- -----EA-----------------AE----- -----EA-----------------AE----- -------A---------------A------- -------AAA-----------AAA------- -------E-CAAAAAAAAAAAC-E------- -----------CCCC-CCCC----------- ------------------------------- 
------------------------------- ------------------------------- ------------------------------- ------------------------------- ----B---------------------B---- ---FBB--------------------BF--- ---FFB--------------------FF--- ---FFB--------------------FF--- ---FFB--------------------FF--- ----BB--------------------B---- ---DDB--------------------DD--- ----BD--------------------B---- ---CBB--------------------BC--- ---CBB--------------------BC--- ----BD--------------------B---- ---DDB--------------------DD--- ----BB--------------------B---- ----EA-------------------AE---- -----AA-----------------AA----- -------A---------------A------- -------A---------------A------- -------EAA-----------AAE------- -------EAAAA-------AAAAE------- ---------CCCAAAAAAACCC--------- ------------CCCCCCC------------ ------------------------------- 
------------------------------- ------------------------------- ------------------------------- ------------------------------- ------------------------------- -------------------------B----- ----F-B------------------BF---- ----F-B------------------BF---- ----F-B------------------BF---- ------B------------------B----- ----D-B------------------BD---- -----DD------------------DD---- ------B------------------B----- ------B------------------B----- -----DD------------------DD---- ----D-B------------------BD---- ------B------------------B----- -----EAA---------------AAE----- ------AA---------------AA------ -------EAA-----------AAE------- -------EAA-----------AAE------- ---------CAA-------AAC--------- ---------CAAAAAAAAAAAC--------- ----------CCCCC-CCCCC---------- ------------------------------- ------------------------------- 
------------------------------- ------------------------------- ------------------------------- ------------------------------- ------------------------------- ------------------------------- ------B-----------------B------ -----FB-----------------BF----- -----FF-----------------FF----- ------B-----------------B------ ------B-----------------B------ -----DD-----------------DD----- ------B-----------------B------ ------B-----------------B------ -----DD-----------------DD----- ------B-----------------B------ ------BG---------------GB------ ------EEA-------------AEE------ -------EAA-----------AAE------- ---------CAA-------AAC--------- ---------CAA-------AAC--------- ----------CCAAAAAAACC---------- ----------CCAAAAAAACC---------- ------------CCC-CCC------------ ------------------------------- ------------------------------- 
------------------------------- ------------------------------- ------------------------------- ------------------------------- ------------------------------- ------------------------------- ------------------------------- -------BB-------------BB------- ------FBF-------------FBF------ -------BB-------------BB------- ------DDD-------------DB------- ------DBB-------------BDD------ -------BC-------------BB------- -------BC-------------BB------- ------DBB-------------BDD------ ------DDD-------------DB------- -------BBG------------BB------- --------EAAA-------AAAE-------- ---------AAA-------AAA--------- ----------CCAAAAAAACC---------- ----------CCAAAAAAACC---------- ------------CCC-CCC------------ ------------CCC-CCC------------ ------------------------------- ------------------------------- ------------------------------- 
------------------------------- ------------------------------- ------------------------------- ------------------------------- ------------------------------- ------------------------------- ------------------------------- ------------------------------- --------FBBB-------BBBF-------- ---------BBB-------BBB--------- -------DDDBB-------BDDD-------- ---------BDD-------DBB-D------- --------CBBB-------BBC--------- --------CBBB-------BBC--------- ---------BDD-------DBB-D------- -------DDDBB-------BDDD-------- ---------BBB-------BBB--------- ---------EEEAAAAAAAEEE--------- ------------AAAAAAA------------ ------------CCCCCCC------------ ------------CCC-CCC------------ ------------------------------- ------------------------------- ------------------------------- ------------------------------- ------------------------------- 
------------------------------- ------------------------------- ------------------------------- ------------------------------- ------------------------------- ------------------------------- ------------------------------- ------------------------------- ------------------------------- ------------BBBBBBB------------ ---------D--BDDDDDB-DD--------- ----------DDDBBBBBDD----------- ------------BBDDDBB--C--------- ------------BBDDDBB--C--------- ----------DDDBBBBBDD----------- ---------D--BDDDDDB-DD--------- ------------BBBBBBB------------ ------------EEEEEEE------------ ------------------------------- ------------------------------- ------------------------------- ------------------------------- ------------------------------- ------------------------------- ------------------------------- ------------------------------- 
------------------------------- ------------------------------- ------------------------------- ------------------------------- ------------------------------- ------------------------------- ------------------------------- ------------------------------- ------------------------------- ------------------------------- -------------DDDDD------------- ------------D-----D------------ --------------DCD-------------- --------------DCD-------------- ------------D-----D------------ -------------DDDDD------------- ------------------------------- ------------------------------- ------------------------------- ------------------------------- ------------------------------- ------------------------------- ------------------------------- ------------------------------- ------------------------------- ------------------------------- 
