model
size = 23 8 18, scale = 0.05, origin = -y
material 
  colors = A:#000 B:#2609BB C:#A93AF6 D:#7A1FF5 E:#510BDF F:#BE4FF7 G:#0B0894 H:#CB73F9
voxels
-AAAAAAAAA---AAAAAAAAA- AAHFCCDEBA---AHFCCDEBAA AHFFCDDEBAA-AAFFCDDEBGA AHFCCDEEBGA-AHFCCDEEBGA AHFCDDEBBGA-AHFCDDEBBGA AHFCDEEBGGA-AHFCDEEBGGA AAFCDEBBGAABAAFCDEBBGAA -AAAAAAAAA---AAAAAAAAA- 
----------------------- ----------------------- ----------------------- ----------------------- ----------------------- ----------------------- B---------------------B ----------------------- 
----------------------- ----------------------- ----------------------- ----------------------- ----------------------- ----------------------- B---------------------B ----------------------- 
----------------------- ----------------------- ----------------------- ----------------------- ----------------------- ----------------------- B---------------------B ----------------------- 
----------------------- ----------------------- ----------------------- ----------------------- ----------------------- ----------------------- B---------------------B ----------------------- 
----------------------- ----------------------- ----------------------- ----------------------- ----------------------- ----------------------- B---------------------B ----------------------- 
----------------------- ----------------------- ----------------------- ----------------------- ----------------------- ----------------------- B---------------------B ----------------------- 
----------------------- ----------------------- ----------------------- ----------------------- ----------------------- ----------------------- B---------------------B ----------------------- 
----------------------- ----------------------- ----------------------- ----------------------- ----------------------- ----------------------- B---------------------B ----------------------- 
----------------------- ----------------------- ----------------------- ----------------------- ----------------------- ----------------------- B---------------------B ----------------------- 
----------------------- ----------------------- ----------------------- ----------------------- ----------------------- ----------------------- B---------------------B ----------------------- 
----------------------- ----------------------- ----------------------- ----------------------- ----------------------- ----------------------- B---------------------B ----------------------- 
----------------------- ----------------------- ----------------------- ----------------------- ----------------------- ----------------------- B---------------------B ----------------------- 
----------------------- ----------------------- ----------------------- ----------------------- ----------------------- ----------------------- B---------------------B ----------------------- 
----------------------- ----------------------- ----------------------- ----------------------- ----------------------- B---------------------B B---------------------B ----------------------- 
----------------------- ----------------------- ----------------------- ----------------------- ----------------------- B---------------------B ----------------------- ----------------------- 
----------------------- ----------------------- ----------------------- ----------------------- ----------------------- B---------------------B ----------------------- ----------------------- 
----------------------- ----------------------- ----------------------- ----------------------- B---------------------B B---------------------B ----------------------- ----------------------- 
