model
size = 23 8 18, scale = 0.05, origin = -y
material 
  colors = A:#000 B:#F85D00 C:#F88C18 D:#F15E05 E:#F14805 F:#F12C05 G:#F8B524 H:#F10505 I:#FAC75A
voxels
-AAAAAAAAA---AAAAAAAAA- AAIGCCDEFA---AIGCCDEFAA AIGGCDDEFAA-AAGGCDDEFHA AIGCCDEEFHA-AIGCCDEEFHA AIGCDDEFFHA-AIGCDDEFFHA AIGCDEEFHHA-AIGCDEEFHHA AAGCDEFFHAABAAGCDEFFHAA -AAAAAAAAA---AAAAAAAAA- 
----------------------- ----------------------- ----------------------- ----------------------- ----------------------- ----------------------- B---------------------B ----------------------- 
----------------------- ----------------------- ----------------------- ----------------------- ----------------------- ----------------------- B---------------------B ----------------------- 
----------------------- ----------------------- ----------------------- ----------------------- ----------------------- ----------------------- B---------------------B ----------------------- 
----------------------- ----------------------- ----------------------- ----------------------- ----------------------- ----------------------- B---------------------B ----------------------- 
----------------------- ----------------------- ----------------------- ----------------------- ----------------------- ----------------------- B---------------------B ----------------------- 
----------------------- ----------------------- ----------------------- ----------------------- ----------------------- ----------------------- B---------------------B ----------------------- 
----------------------- ----------------------- ----------------------- ----------------------- ----------------------- ----------------------- B---------------------B ----------------------- 
----------------------- ----------------------- ----------------------- ----------------------- ----------------------- ----------------------- B---------------------B ----------------------- 
----------------------- ----------------------- ----------------------- ----------------------- ----------------------- ----------------------- B---------------------B ----------------------- 
----------------------- ----------------------- ----------------------- ----------------------- ----------------------- ----------------------- B---------------------B ----------------------- 
----------------------- ----------------------- ----------------------- ----------------------- ----------------------- ----------------------- B---------------------B ----------------------- 
----------------------- ----------------------- ----------------------- ----------------------- ----------------------- ----------------------- B---------------------B ----------------------- 
----------------------- ----------------------- ----------------------- ----------------------- ----------------------- ----------------------- B---------------------B ----------------------- 
----------------------- ----------------------- ----------------------- ----------------------- ----------------------- B---------------------B B---------------------B ----------------------- 
----------------------- ----------------------- ----------------------- ----------------------- ----------------------- B---------------------B ----------------------- ----------------------- 
----------------------- ----------------------- ----------------------- ----------------------- ----------------------- B---------------------B ----------------------- ----------------------- 
----------------------- ----------------------- ----------------------- ----------------------- B---------------------B B---------------------B ----------------------- ----------------------- 
