model
size = 27 32 7, scale = 0.05, origin = -y
material 
  colors = A:#3A4155 B:#FFF C:#111 D:#30F E:#FC0 F:#0C0 G:#F00
voxels
297-A20(25-2A)25-A271-A23-A-2A20(23-4A)23-2A192-A19-A5-2A19-2A4-2A19-2A3-3A19-3A-E20(3A19-3A2E)3A19-3AE140-A15-A9-2A15-2A7-3A15-3A5-4A15-4A4-4A15-4A3-E4A15-4AE2(2-C4A15-4AB2-B4A15-4AB)2-C4A15-4AB2-C4A15-4AC2(2-D4A15-4AG)2-B2(2(4A15-4AB2-D)2(4A15-4AG2-D))2(4A15-4AB2-D)4A15-4AG2-D4A15-4AG2-E4A15-4AE14-A25-3A22-7A18-11A14-15A11-17A9-19A7-E19AE5-EB19AFE4-EC19AFE4-CB19ACB4-BC19A2B4-CB19A2B4-BC19ABC4-CB19A2B4-BC19ABD4-2C19A2C4-DB19A2G4-BC19A2G4-CB19A2B4-BC19A2B4-DB2(2(19A2G4-DC)2(19A2B4-DC))19A2G4-2D19A2G4-2E19A2E15-A25-3A22-7A18-11A14-15A11-E15AE9-EB15AFE8-BC15A2F8-CB15ACF8-BC15AFC8-CB15A2B8-BC15A2B8-CB15A2B8-BC15ABC8-CB15A2B8-BC15ABD8-2C15A2C8-2D15A2G8-BD15A2G8-CB15A2B8-BD15A2B2(8-2D15A2G)2(8-2D15A2B)2(8-2D15A2G)8-DC15A2B8-CB15A2B8-BC15A2G8-2D15A2G8-2E15A2E17-E25-ECE22-2E2CF2E18-2E2(BC)FCF2E14-2E2(CB)2C2FC2F2E12-4(BC)3FC3F12-3(CB)2C3FC3F12-4(BC)4F2CF12-3(CB)2C6FC12-4(BC)7F12-3(CB)2C2BC2B2F12-4(BC)5B2D12-CB11C2D12-B2C4FB4FC2B12-2(CB)2F3B2FBC2D12-B2C2BF3BF2BC2D12-3C3BFBF3B3C12-2DCFBF3BFBFC2G12-2DC3F3B3FC2G2(12-2DC2F5B2FC2B)12-2DC3F3B3FC2G12-2DC4FB4FC2G12-2D11C2B12-2DCBC2DC7B12-DCBC3DC7G12-CBC4DC7G12-BC5DC7B12-C6DC7B2(12-7DC7G)12-15E6-
