model
size = 31, scale = 0.05, origin = -y
material 
  colors = A:#36C B:#E00 C:#010 D:#EEE E:#B00 F:#C90 G:#CF3 H:#DDD
voxels
------------------------------- ------------------------------- ------------------------------- ------------------------------- ------------------------------- -------------EEEEE------------- ------------EEEEDEE------------ ------------EEEEEDE------------ ------------EEEEEEE------------ ------------------------------- ------------------------------- ------------------------------- ------------------------------- ------------------------------- ------------------------------- ------------DDDDDDD------------ ------------GGGGGGG------------ ------------GGGGGGG------------ -------------GGGGG------------- ------------------------------- ------------------------------- ------------------------------- ------------------------------- ------------------------------- ------------------------------- ------------------------------- ------------------------------- ------------------------------- ------------------------------- ------------------------------- ------------------------------- 
------------------------------- ------------------------------- ------------------------------- ------------------------------- ------------------------------- ------------------------------- ------------------------------- -----------EEEEEEEEE----------- -----------EEEEEEEEE----------- -----------EEEEEEEEE----------- ------------------------------- ------------DDD-DDD------------ ------------DDD-DDD------------ ------------DDD-DDD------------ ------------HHH-HHH------------ ---------DDDAAACAAADDD--------- ---------GGGAAABAAAGGG--------- ---------GGGAAABAAAGGG--------- ----------GGGAAAAAGGG---------- --------C--GGGGGGGGG--C-------- -------CCC-GGGGGGGGG-CCC------- -------CCD---GGGGG---CCD------- ------------------------------- ------------------------------- ------------------------------- ------------------------------- ------------------------------- ------------------------------- ------------------------------- ------------------------------- ------------------------------- 
------------------------------- ------------------------------- ------------------------------- ------------------------------- ------------------------------- ------------------------------- ------------------------------- ------------------------------- -----------EEEEEEEEE----------- ----------EEEEEEEEEEE---------- -------------EEEE-------------- ------------------------------- ---------DD---------DD--------- ---------DD---------DD--------- ---------HH---------HH--------- -------DDAACCCCCCCCCAADD------- -------GGAABBBBBBBBBAAGG------- -------GGAABBBBBBBBBAAGG------- -------CCCAAAAAAAAAAACCC------- -------CGCCAAAAAAAAACCGC------- -------CCGCAAAAAAAAACGCC------- -------CCCCGGAAAAAGGCCCC------- --------C--GGGGGGGGG--C-------- -------------GGGGG------------- ------------------------------- ------------------------------- ------------------------------- ------------------------------- ------------------------------- ------------------------------- ------------------------------- 
------------------------------- ------------------------------- ------------------------------- ------------------------------- ------------------------------- ------------------------------- ------------------------------- ------------------------------- ------------------------------- ----------EEEEEEEEEEE---------- ------------EEEEEE------------- ------------------------------- --------D-------------D-------- --------D-------------D-------- --------H-------------H-------- ------DCACCCCCCCCCCCCCACD------ ------GBABBBBBBBBBBBBBABG------ ------GBABBBBBBBBBBBBBABG------ ------GGAAAAAAAAAAAAAAAGG------ ------CGAAAAAAAAAAAAAAAGC------ ------CGCAAAAAAAAAAAAACGC------ ------CCCCAAAAAAAAAAACCCC------ -------CCCGAAAAAAAAAGCCC------- ----------GGGAAAAAGGG---------- ------------GGGGGGG------------ ------------------------------- ------------------------------- ------------------------------- ------------------------------- ------------------------------- ------------------------------- 
------------------------------- ------------------------------- ------------------------------- ------------------------------- ------------------------------- ---------DDDDDDDDDDDDD--------- ------------------------------- ------------------------------- ------------------------------- ----------EEEEEEEEEEE---------- -----------EEEEEEEE------------ ------------------------------- ------------------------------- ------D-----------------D------ ------H-----------------H------ -----DACCCCCCCCCCCCCCCCCAD----- -----GABBBBBBBBBBBBBBBBBAG----- -----GABBBBBBBBBBBBBBBBBAG----- -----GAAAAAAAAAAAAAAAAAAAG----- -----GGAAAAAAAAAAAAAAAAAGG----- ------GAAAAAAAAAAAAAAAAAG------ ------GCAAAAAAAAAAAAAAACG------ -------GCAAAAAAAAAAAAACG------- --------GGAAAAAAAAAAAGG-------- ---------GGGAAAAAAAGGG--------- -----------GGGGGGGGG----------- ------------------------------- ------------------------------- ------------------------------- ------------------------------- ------------------------------- 
------------------------------- ------------------------------- ------------------------------- ------------------------------- -----------FFFFFFFFF----------- ---------FFCBBBBBBBCFF--------- -------DDHH-HHH-HHH-HHDD------- ---------DD-DDD-DDD-DD--------- ------------------------------- ----------EEEEEEEEEEE---------- -----------EEEEEEEEE----------- ------------------------------- ------------------------------- -----D-------------------D----- -----H-------------------H----- ----DACCCCCCCCCCCCCCCCCCCAD---- ----GABBBBBBBBBBBBBBBBBBBAG---- ----GABBBBBBBBBBBBBBBBBBBAG---- ----GAAAAAAAAAAAAAAAAAAAAAG---- ----GAAAAAAAAAAAAAAAAAAAAAG---- -----GAAAAAAAAAAAAAAAAAAAG----- -----GAAAAAAAAAAAAAAAAAAAG----- ------GAAAAAAAAAAAAAAAAAG------ -------GAAAAAAAAAAAAAAAG------- --------GAAAAAAAAAAAAAG-------- ---------GGAAAAAAAAAGG--------- ---------DDDDDDDDDDDDD--------- ------------------------------- ------------------------------- ------------------------------- ------------------------------- 
------------------------------- ------------------------------- ------------------------------- ------------FFFFFFF------------ ---------FFFAAAAAAAFFF--------- --------FBBBCCCCCCCBBBF-------- -------FF-------------FF------- -----DD-D-------------D-DD----- ------------------------------- ----------EEEEEEEEEEE---------- -----------EEEEEEEEE----------- ------------------------------- ------------------------------- ------------------------------- ------------------------------- ---DCCCCCCCCCCCCCCCCCCCCCCCD--- ---GBBBBBBBBBBBBBBBBBBBBBBBG--- ---GBBBBBBBBBBBBBBBBBBBBBBBG--- ---GAAAAAAAAAAAAAAAAAAAAAAAG--- ----GAAAAAAAAAAAAAAAAAAAAAG---- ----GAAAAAAAAAAAAAAAAAAAAAG---- ----GAAAAAAAAAAAAAAAAAAAAAG---- -----GAAAAAAAAAAAAAAAAAAAG----- ------GAAAAAAAAAAAAAAAAAG------ -------GAAAAAAAAAAAAAAAG------- -------DDAAAAAAAAAAAAADD------- ---------AAAAAAAAAAAAA--------- ------------AAAAAAA------------ ------------------------------- ------------------------------- ------------------------------- 
------------------------------- ------------------------------- -------------FFFFF------------- ----------FFFAAAAAFFF---------- --------FFAAAAAAAAAAAFF-------- -------FABCCCCCCCCCCCBAF------- ------FCC-------------CCF------ -----FC-----------------CF----- ----D---------------------D---- ----------EEEEEEEEEEE---------- -----------EEEEEEEEE----------- ------------------------------- ------------------------------- ------------------------------- ---D-----------------------D--- --DBCCCCCCCCCCCCCCCCCCCCCCCBD-- --GBBBBBBBBBBBBBBBBBBBBBBBBBG-- --GBBBBBBBBBBBBBBBBBBBBBBBBBG-- ---GAAAAAAAAAAAAAAAAAAAAAAAG--- ---GAAAAAAAAAAAAAAAAAAAAAAAG--- ---GAAAAAAAAAAAAAAAAAAAAAAAG--- ----GAAAAAAAAAAAAAAAAAAAAAG---- ----GAAAAAAAAAAAAAAAAAAAAAG---- -----GAAAAAAAAAAAAAAAAAAAG----- -----DDAAAAAAAAAAAAAAAAADD----- -------AAAAAAAAAAAAAAAAA------- --------AAAAAAAAAAAAAAA-------- ----------AAAAAAAAAAA---------- -------------AAAAA------------- ------------------------------- ------------------------------- 
------------------------------- ------------------------------- -----------FFFFFFFFF----------- ---------FFAAAAAAAAAFF--------- -------FFAAAAAAAAAAAAAFF------- ------FAACCCCCCCCCCCCCAAF------ -----FACC-------------CCAF----- ----FFC-----------------CFF---- ----F-----EEEEEEEEEEE-----F---- ---D------EEEEEEEEEEE------D--- -----------EEEEEEEEE----------- ------------------------------- ------------------------------- ------------------------------- ---D-----------------------D--- --DBCCCCCCCCCCCCCCCCCCCCCCCBD-- --GBBBBBBBBBBBBBBBBBBBBBBBBBG-- --GBBBBBBBBBBBBBBBBBBBBBBBBBG-- --GAAAAAAAAAAAAAAAAAAAAAAAAAG-- --GAAAAAAAAAAAAAAAAAAAAAAAAAG-- ---GAAAAAAAAAAAAAAAAAAAAAAAG--- ---GAAAAAAAAAAAAAAAAAAAAAAAG--- ----GAAAAAAAAAAAAAAAAAAAAAG---- ----DAAAAAAAAAAAAAAAAAAAAAD---- -----AAAAAAAAAAAAAAAAAAAAA----- ------AAAAAAAAAAAAAAAAAAA------ -------AAAAAAAAAAAAAAAAA------- ---------AAAAAAAAAAAAA--------- -----------AAAAAAAAA----------- ------------------------------- ------------------------------- 
------------------------------- -------------FFFFF------------- ----------FFFAAAAAFFF---------- --------FFAAAAAAAAAAAFF-------- ------FFAAAAAAAAAAAAAAAFF------ -----FAAACCCCCCCCCCCCCAAAF----- ----FAACC-------------CCAAF---- ----FCC-----------------CCF---- ---FC-----EEEEEEEEEEE-----CF--- ---F-------EEEEEEEEE-------F--- --D--------EEEEEEEEE--------D-- ------------------------------- ------------------------------- ------------------------------- ------------------------------- -DCCCCCCCCCCCCCCCCCCCCCCCCCCCD- -GBBBBBBBBBBBBBBBBBBBBBBBBBBBG- -GBBBBBBBBBBBBBBBBBBBBBBBBBBBG- --GAAAAAAAAAAAAAAAAAAAAAAAAAG-- --GAAAAAAAAAAAAAAAAAAAAAAAAAG-- --GAAAAAAAAAAAAAAAAAAAAAAAAAG-- ---GAAAAAAAAAAAAAAAAAAAAAAAG--- ---DAAAAAAAAAAAAAAAAAAAAAAAD--- ----AAAAAAAAAAAAAAAAAAAAAAA---- ----AAAAAAAAAAAAAAAAAAAAAAA---- -----AAAAAAAAAAAAAAAAAAAAA----- ------AAAAAAAAAAAAAAAAAAA------ --------AAAAAAAAAAAAAAA-------- ----------AAAAAAAAAAA---------- -------------AAAAA------------- ------------------------------- 
------------------------------- -----------FFFFFFFFF----------- ---------FFAAAAAAAAAFF--------- -------FFAAAAAAAAAAAAAFF------- ------FAAAAAAAAAAAAAAAAAF------ -----FAAACCCCCCBCCCCCCAAAF----- ----FAACC-------------CCAAF---- ---FACC---EEEEEEEEEEE---CCAF--- ---FC-----EEEEEEEEEEE-----CF--- --FC-------EEEEEEEEE-------CF-- --F--------EEEEEEEEE--------F-- -D---------------------------D- ------------------------------- ------------------------------- ------------------------------- DDCCCCCCCCCCCCCCCCCCCCCCCCCCCD- -GBBBBBBBBBBBBBBBBBBBBBBBBBBBG- -GBBBBBBBBBBBBBBBBBBBBBBBBBBBG- -GAAAAAAAAAAAAAAAAAAAAAAAAAAAG- -GAAAAAAAAAAAAAAAAAAAAAAAAAAAG- --GAAAAAAAAAAAAAAAAAAAAAAAAAG-- --DAAAAAAAAAAAAAAAAAAAAAAAAAD-- ---AAAAAAAAAAAAAAAAAAAAAAAAA--- ---AAAAAAAAAAAAAAAAAAAAAAAAA--- ----AAAAAAAAAAAAAAAAAAAAAAA---- -----AAAAAAAAAAAAAAAAAAAAA----- ------AAAAAAAAAAAAAAAAAAA------ -------AAAAAAAAAAAAAAAAA------- ---------AAAAAAAAAAAAA--------- -----------AAAAAAAAA----------- ------------------------------- 
------------------------------- ----------FFFFFFFFFFF---------- --------FFAAAAAAAAAAAFF-------- -------FAAAAAAAAAAAAAAAF------- -----FFAAAAAAAAAAAAAAAAAFF----- ----FAAAACCCCBBBBBCCCCAAAAF---- ----FAACC-------------CCAAF---- ---FACC---EEEEEEEEEEE---CCAF--- --FAC------EEEEEEEEE------CAF-- --FC-------EEEEEEEEE-------CF-- -FC-------------------------CF- -F---------------------------F- -D---------------------------DD ------------------------------- ------------------------------- DDCCCCCCCCCCCCCCCCCCCCCCCCCCCDD -GBBBBBBBBBBBBBBBBBBBBBBBBBBBG- -GBBBBBBBBBBBBBBBBBBBBBBBBBBBG- -GAAAAAAAAAAAAAAAAAAAAAAAAAAAG- -GAAAAAAAAAAAAAAAAAAAAAAAAAAAG- -DAAAAAAAAAAAAAAAAAAAAAAAAAAAD- --AAAAAAAAAAAAAAAAAAAAAAAAAAA-- --AAAAAAAAAAAAAAAAAAAAAAAAAAA-- ---AAAAAAAAAAAAAAAAAAAAAAAAA--- ----AAAAAAAAAAAAAAAAAAAAAAA---- ----AAAAAAAAAAAAAAAAAAAAAAA---- -----AAAAAAAAAAAAAAAAAAAAA----- -------AAAAAAAAAAAAAAAAA------- --------AAAAAAAAAAAAAAA-------- ----------AAAAAAAAAAA---------- ------------------------------- 
-------------FFFFF------------- ----------FFFAAAAAFFF---------- --------FFAAAAAAAAAAAFF-------- ------FFAAAAAAAAAAAAAAAFF------ -----FAAAAAAAAAAAAAAAAAAAF----- ----FAAAACBBBBBBBBBBBCAAAAF---- ---FAAACC-EEEEEEEEEEE-CCAAAF--- ---FACC---EEEEEEEEEEE---CCAF--- --FAC------EEEEEEEEE------CAF-- --FC-----------------------CF-- -FC-------------------------CF- -F---------------------------F- -F---------------------------F- D-----------------------------D ------------------------------- DCCCCCCCCCCCCCCCCCCCCCCCCCCCCCD GBBBBBBBBBBBBBBBBBBBBBBBBBBBBBG GBBBBBBBBBBBBBBBBBBBBBBBBBBBBBG -GAAAAAAAAAAAAAAAAAAAAAAAAAAAG- DDAAAAAAAAAAAAAAAAAAAAAAAAAAADD -AAAAAAAAAAAAAAAAAAAAAAAAAAAAA- --AAAAAAAAAAAAAAAAAAAAAAAAAAA-- --AAAAAAAAAAAAAAAAAAAAAAAAAAA-- ---AAAAAAAAAAAAAAAAAAAAAAAAA--- ---AAAAAAAAAAAAAAAAAAAAAAAAA--- ----AAAAAAAAAAAAAAAAAAAAAAA---- -----AAAAAAAAAAAAAAAAAAAAA----- ------AAAAAAAAAAAAAAAAAAA------ --------AAAAAAAAAAAAAAA-------- ----------AAAAAAAAAAA---------- -------------AAAAA------------- 
------------FFFFFFF------------ ---------FFFAAAAAAAFFF--------- -------FFAAAAAAAAAAAAAFF------- ------FAAAAAAAAAAAAAAAAAF------ -----FAAAAAAAAAAAAAAAAAAAF----- ----FAAAAAAAAAAAAAAAAAAAAAF---- ---FAAAAACBBBBBBBBBBBCAAAAAF--- --FAAAACCCBBBBBBBBBBBCCCAAAAF-- --FAACCCCCCBBBBBBBBBCCCCCCAAF-- -FAACCCCCCCCCCCCCCCCCCCCCCCAAF- -FACCCCCCCCCCCCCCCCCCCCCCCCCAF- -FCCCCCCCCCCCCCCCCCCCCCCCCCCCF- FACCCCCCCCCCCCCCCCCCCCCCCCCCCAF FCCCCCCCCCCCCCCCCCCCCCCCCCCCCCF DCCCCCCCCCCCCCCCCCCCCCCCCCCCCCD DAAAAAAAAAAAAAAAAAAAAAAAAAAAAAD DAAAAAAAAAAAAAAAAAAAAAAAAAAAAAD GAAAAAAAAAAAAAAAAAAAAAAAAAAAAAG DAAAAAAAAAAAAAAAAAAAAAAAAAAAAAD -AAAAAAAAAAAAAAAAAAAAAAAAAAAAA- -AAAAAAAAAAAAAAAAAAAAAAAAAAAAA- -AAAAAAAAAAAAAAAAAAAAAAAAAAAAA- --AAAAAAAAAAAAAAAAAAAAAAAAAAA-- --AAAAAAAAAAAAAAAAAAAAAAAAAAA-- ---AAAAAAAAAAAAAAAAAAAAAAAAA--- ----AAAAAAAAAAAAAAAAAAAAAAA---- -----AAAAAAAAAAAAAAAAAAAAA----- ------AAAAAAAAAAAAAAAAAAA------ -------AAAAAAAAAAAAAAAAA------- ---------AAAAAAAAAAAAA--------- ------------AAAAAAA------------ 
------------FFFFFFF------------ ---------FFFAAAAAAAFFF--------- -------FFAAAAAAAAAAAAAFF------- ------FAAAAAAAAAAAAAAAAAF------ -----FAAAAAAAAAAAAAAAAAAAF----- ----FAAAAAAAAAAAAAAAAAAAAAF---- ---FAAAAAAAAAAAAAAAAAAAAAAAF--- --FAAAAAAAAAAAAAAAAAAAAAAAAAF-- --FAAAAAAAAAAAAAAAAAAAAAAAAAF-- -FAAAAAAAAAAAAAAAAAAAAAAAAAAAF- -FAAAAAAAAAAAAAAAAAAAAAAAAAAAF- -FAAAAAAAAAAAAAAAAAAAAAAAAAAAF- FAAAAAAAAAAAAAAAAAAAAAAAAAAAAAF DAAAAAAAAAAAAAAAAAAAAAAAAAAAAAD DAAAAAAAAAAAAAAAAAAAAAAAAAAAAAD DAAAAAAAAAAAAAAAAAAAAAAAAAAAAAD DAAAAAAAAAAAAAAAAAAAAAAAAAAAAAD DAAAAAAAAAAAAAAAAAAAAAAAAAAAAAD AAAAAAAAAAAAAAAAAAAAAAAAAAAAAAA -AAAAAAAAAAAAAAAAAAAAAAAAAAAAA- -AAAAAAAAAAAAAAAAAAAAAAAAAAAAA- -AAAAAAAAAAAAAAAAAAAAAAAAAAAAA- --AAAAAAAAAAAAAAAAAAAAAAAAAAA-- --AAAAAAAAAAAAAAAAAAAAAAAAAAA-- ---AAAAAAAAAAAAAAAAAAAAAAAAA--- ----AAAAAAAAAAAAAAAAAAAAAAA---- -----AAAAAAAAAAAAAAAAAAAAA----- ------AAAAAAAAAAAAAAAAAAA------ -------AAAAAAAAAAAAAAAAA------- ---------AAAAAAAAAAAAA--------- ------------AAAAAAA------------ 
------------DDDDDDD------------ ---------DDDAAAAAAADDD--------- -------DDAAAAAAAAAAAAADD------- ------DAAAAAAAAAAAAAAAAAD------ -----DAAAAAAAAAAAAAAAAAAAD----- ----DAAAAAAAAAAAAAAAAAAAAAD---- ---DAAAAAAAAAAAAAAAAAAAAAAAD--- --DAAAAAAAAAAAAAAAAAAAAAAAAAD-- --DAAAAAAAAAAAAAAAAAAAAAAAAAD-- -DAAAAAAAAAAAAAAAAAAAAAAAAAAAD- DDAAAAAAAAAAAAAAAAAAAAAAAAAAAD- DDAAAAAAAAAAAAAAAAAAAAAAAAAAADD DAAAAAAAAAAAAAAAAAAAAAAAAAAAAAD DAAAAAAAAAAAAAAAAAAAAAAAAAAAAAD DAAAAAAAAAAAAAAAAAAAAAAAAAAAAAD DAAAAAAAAAAAAAAAAAAAAAAAAAAAAAD DAAAAAAAAAAAAAAAAAAAAAAAAAAAAAD DAAAAAAAAAAAAAAAAAAAAAAAAAAAAAD DAAAAAAAAAAAAAAAAAAAAAAAAAAAAAD DDAAAAAAAAAAAAAAAAAAAAAAAAAAADD DDAAAAAAAAAAAAAAAAAAAAAAAAAAAD- -DAAAAAAAAAAAAAAAAAAAAAAAAAAAD- -DDAAAAAAAAAAAAAAAAAAAAAAAAAD-- --DAAAAAAAAAAAAAAAAAAAAAAAAAD-- --DDAAAAAAAAAAAAAAAAAAAAAAAD--- ---DDAAAAAAAAAAAAAAAAAAAAAD---- ----DDAAAAAAAAAAAAAAAAAAAD----- -----DDAAAAAAAAAAAAAAAAAD------ ------DDDAAAAAAAAAAAAADD------- --------DDDDAAAAAAADDDD-------- -----------DDDDDDDDD----------- 
------------AAAAAAA------------ ---------AAAAAAAAAAAAA--------- -------AAAAAAAAAAAAAAAAA------- ------AAAAAAAAAAAAAAAAAAA------ -----AAAAAAAAAAAAAAAAAAAAA----- ----AAAAAAAAAAAAAAAAAAAAAAA---- ---AAAAAAAAAAAAAAAAAAAAAAAAA--- --AAAAAAAAAAAAAAAAAAAAAAAAAAA-- --AAAAAAAAAAAAAAAAAAAAAAAAAAA-- -AAAAAAAAAAAAAAAAAAAAAAAAAAAAA- -AAAAAAAAAAAAAAAAAAAAAAAAAAAAA- -AAAAAAAAAAAAAAAAAAAAAAAAAAAAA- AAAAAAAAAAAAAAAAAAAAAAAAAAAAAAA DAAAAAAAAAAAAAAAAAAAAAAAAAAAAAD DAAAAAAAAAAAAAAAAAAAAAAAAAAAAAD DAAAAAAAAAAAAAAAAAAAAAAAAAAAAAD DAAAAAAAAAAAAAAAAAAAAAAAAAAAAAD DAAAAAAAAAAAAAAAAAAAAAAAAAAAAAD BAAAAAAAAAAAAAAAAAAAAAAAAAAAAAB -BAAAAAAAAAAAAAAAAAAAAAAAAAAAB- -BAAAAAAAAAAAAAAAAAAAAAAAAAAAB- -BAAAAAAAAAAAAAAAAAAAAAAAAAAAB- --BAAAAAAAAAAAAAAAAAAAAAAAAAB-- --BAAAAAAAAAAAAAAAAAAAAAAAAAB-- ---BAAAAAAAAAAAAAAAAAAAAAAAB--- ----BAAAAAAAAAAAAAAAAAAAAAB---- -----BBBAAAAAAAAAAAAAAAAAB----- ------BAAAAAAAAAAAAAAAAAB------ -------BBAAAAAAAAAAAAABB------- ---------BBBAAAAAAABBB--------- ------------BBBBBBB------------ 
------------AAAAAAA------------ ---------AAAAAAAAAAAAA--------- -------AAAAAAAAAAAAAAAAA------- ------AAAAAAAAAAAAAAAAAAA------ -----AAAAAAAAAAAAAAAAAAAAA----- ----AAAAAAAAAAAAAAAAAAAAAAA---- ---AAAAAAAAAAAAAAAAAAAAAAAAA--- --AAAAAAAAAAAAAAAAAAAAAAAAAAA-- --AAAAAAAAAAAAAAAAAAAAAAAAAAA-- -AAAAAAAAAAAAAAAAAAAAAAAAAAAAA- -AAAAAAAAAAAAAAAAAAAAAAAAAAAAA- -AAAAAAAAAAAAAAAAAAAAAAAAAAAAA- AAAAAAAAAAAAAAAAAAAAAAAAAAAAAAA AAAAAAAAAAAAAAAAAAAAAAAAAAAAAAA DAAAAAAAAAAAAAAAAAAAAAAAAAAAAAD DAAAAAAAAAAAAAAAAAAAAAAAAAAAAAD DAAAAAAAAAAAAAAAAAAAAAAAAAAAAAD BAAAAAAAAAAAAAAAAAAAAAAAAAAAAAB BAAAAAAAAAAAAAAAAAAAAAAAAAAAAAB -BAAAAAAAAAAAAAAAAAAAAAAAAAAAB- -BAAAAAAAAAAAAAAAAAAAAAAAAAAAB- -BAAAAAAAAAAAAAAAAAAAAAAAAAAAB- --BAAAAAAAAAAAAAAAAAAAAAAAAAB-- --BAAAAAAAAAAAAAAAAAAAAAAAAAB-- ---BAAAAAAAAAAAAAAAAAAAAAAAB--- ----BAAAAAAAAAAAAAAAAAAAAAB---- -----BBBAAAAAAAAAAAAAAAAAB----- ------BAAAAAAAAAAAAAAAAAB------ -------BBAAAAAAAAAAAAABB------- ---------BBBAAAAAAABBB--------- ------------BBBBBBB------------ 
-------------AAAAA------------- ----------AAAAAAAAAAA---------- --------AAAAAAAAAAAAAAA-------- ------AAAAAAAAAAAAAAAAAAA------ -----AAAAAAAAAAAAAAAAAAAAA----- ----AAAAAAAAAAAAAAAAAAAAAAA---- ---AAAAAAAAAAAAAAAAAAAAAAAAA--- ---AAAAAAAAAAAAAAAAAAAAAAAAA--- --AAAAAAAAAAAAAAAAAAAAAAAAAAA-- --AAAAAAAAAAAAAAAAAAAAAAAAAAA-- -AAAAAAAAAAAAAAAAAAAAAAAAAAAAA- -AAAAAAAAAAAAAAAAAAAAAAAAAAAAA- -AAAAAAAAAAAAAAAAAAAAAAAAAAAAA- DAAAAAAAAAAAAAAAAAAAAAAAAAAAAAD BAAAAAAAAAAAAAAAAAAAAAAAAAAAAAB DAAAAAAAAAAAAAAAAAAAAAAAAAAAAAD AAAAAAAAAAAAAAAAAAAAAAAAAAAAAAA DAAAAAAAAAAAAAAAAAAAAAAAAAAAAAD -BAAAAAAAAAAAAAAAAAAAAAAAAAAAB- -BAAAAAAAAAAAAAAAAAAAAAAAAAAAB- -BAAAAAAAAAAAAAAAAAAAAAAAAAAAB- --BAAAAAAAAAAAAAAAAAAAAAAAAAB-- --BAAAAAAAAAAAAAAAAAAAAAAAAAB-- ---BAAAAAAAAAAAAAAAAAAAAAAAB--- ---BAAAAAAAAAAAAAAAAAAAAAAAB--- ----BAAAAAAAAAAAAAAAAAAAAAB---- -----BBBAAAAAAAAAAAAAAAAAB----- ------BBAAAAAAAAAAAAAAABB------ --------BBAAAAAAAAAAABB-------- ----------BBBAAAAABBB---------- -------------BBBBB------------- 
------------------------------- ----------AAAAAAAAAAA---------- --------AAAAAAAAAAAAAAA-------- -------AAAAAAAAAAAAAAAAA------- -----AAAAAAAAAAAAAAAAAAAAA----- ----AAAAAAAAAAAAAAAAAAAAAAA---- ----AAAAAAAAAAAAAAAAAAAAAAA---- ---AAAAAAAAAAAAAAAAAAAAAAAAA--- --AAAAAAAAAAAAAAAAAAAAAAAAAAA-- --AAAAAAAAAAAAAAAAAAAAAAAAAAA-- -AAAAAAAAAAAAAAAAAAAAAAAAAAAAA- -AAAAAAAAAAAAAAAAAAAAAAAAAAAAA- DDAAAAAAAAAAAAAAAAAAAAAAAAAAADD -BAAAAAAAAAAAAAAAAAAAAAAAAAAAB- -BAAAAAAAAAAAAAAAAAAAAAAAAAAAB- DDAAAAAAAAAAAAAAAAAAAAAAAAAAADD -AAAAAAAAAAAAAAAAAAAAAAAAAAAAA- -AAAAAAAAAAAAAAAAAAAAAAAAAAAAA- DDAAAAAAAAAAAAAAAAAAAAAAAAAAADD -BAAAAAAAAAAAAAAAAAAAAAAAAAAAB- -BAAAAAAAAAAAAAAAAAAAAAAAAAAAB- --BAAAAAAAAAAAAAAAAAAAAAAAAAB-- --BAAAAAAAAAAAAAAAAAAAAAAAAAB-- ---BAAAAAAAAAAAAAAAAAAAAAAAB--- ----BAAAAAAAAAAAAAAAAAAAAAB---- ----BAAAAAAAAAAAAAAAAAAAAAB---- -----BBBAAAAAAAAAAAAAAAABB----- -------BAAAAAAAAAAAAAAAB------- --------BBAAAAAAAAAAABB-------- ----------BBBBBBBBBBB---------- ------------------------------- 
------------------------------- -----------AAAAAAAAA----------- ---------AAAAAAAAAAAAA--------- -------AAAAAAAAAAAAAAAAA------- ------AAAAAAAAAAAAAAAAAAA------ -----AAAAAAAAAAAAAAAAAAAAA----- ----AAAAAAAAAAAAAAAAAAAAAAA---- ---AAAAAAAAAAAAAAAAAAAAAAAAA--- ---AAAAAAAAAAAAAAAAAAAAAAAAA--- --AAAAAAAAAAAAAAAAAAAAAAAAAAA-- --AAAAAAAAAAAAAAAAAAAAAAAAAAA-- -DAAAAAAAAAAAAAAAAAAAAAAAAAAAD- -BAAAAAAAAAAAAAAAAAAAAAAAAAAAB- -BAAAAAAAAAAAAAAAAAAAAAAAAAAAB- -BAAAAAAAAAAAAAAAAAAAAAAAAAAAB- DDAAAAAAAAAAAAAAAAAAAAAAAAAAAD- -AAAAAAAAAAAAAAAAAAAAAAAAAAAAA- -AAAAAAAAAAAAAAAAAAAAAAAAAAAAA- -AAAAAAAAAAAAAAAAAAAAAAAAAAAAA- -DAAAAAAAAAAAAAAAAAAAAAAAAAAAD- --BAAAAAAAAAAAAAAAAAAAAAAAAAB-- --BAAAAAAAAAAAAAAAAAAAAAAAAAB-- ---BAAAAAAAAAAAAAAAAAAAAAAAB--- ---BAAAAAAAAAAAAAAAAAAAAAAAB--- ----BAAAAAAAAAAAAAAAAAAAAAB---- -----BAAAAAAAAAAAAAAAAAAAB----- ------BAAAAAAAAAAAAAAAAAB------ -------BBAAAAAAAAAAAAABB------- ---------BBAAAAAAAAABB--------- -----------BBBBBBBBB----------- ------------------------------- 
------------------------------- -------------AAAAA------------- ----------AAAAAAAAAAA---------- --------AAAAAAAAAAAAAAA-------- ------AAAAAAAAAAAAAAAAAAA------ -----AAAAAAAAAAAAAAAAAAAAA----- ----AAAAAAAAAAAAAAAAAAAAAAA---- ----AAAAAAAAAAAAAAAAAAAAAAA---- ---AAAAAAAAAAAAAAAAAAAAAAAAA--- ---AAAAAAAAAAAAAAAAAAAAAAAAA--- --DAAAAAAAAAAAAAAAAAAAAAAAAAD-- --BAAAAAAAAAAAAAAAAAAAAAAAAAB-- --BAAAAAAAAAAAAAAAAAAAAAAAAAB-- -BAAAAAAAAAAAAAAAAAAAAAAAAAAAB- -BAAAAAAAAAAAAAAAAAAAAAAAAAAAB- -DAAAAAAAAAAAAAAAAAAAAAAAAAAAD- -AAAAAAAAAAAAAAAAAAAAAAAAAAAAA- -AAAAAAAAAAAAAAAAAAAAAAAAAAAAA- --AAAAAAAAAAAAAAAAAAAAAAAAAAA-- --AAAAAAAAAAAAAAAAAAAAAAAAAAA-- --DAAAAAAAAAAAAAAAAAAAAAAAAAD-- ---BAAAAAAAAAAAAAAAAAAAAAAAB--- ---BAAAAAAAAAAAAAAAAAAAAAAAB--- ----BAAAAAAAAAAAAAAAAAAAAAB---- ----BAAAAAAAAAAAAAAAAAAAAAB---- -----BAAAAAAAAAAAAAAAAAAAB----- ------BBAAAAAAAAAAAAAAABB------ --------BBAAAAAAAAAAABB-------- ----------BBBAAAAABBB---------- -------------BBBBB------------- ------------------------------- 
------------------------------- ------------------------------- -----------AAAAAAAAA----------- ---------AAAAAAAAAAAAA--------- -------AAAAAAAAAAAAAAAAA------- ------AAAAAAAAAAAAAAAAAAA------ -----AAAAAAAAAAAAAAAAAAAAA----- ----AAAAAAAAAAAAAAAAAAAAAAA---- ----AAAAAAAAAAAAAAAAAAAAAAA---- ---DAAAAAAAAAAAAAAAAAAAAAAAD--- ---BAAAAAAAAAAAAAAAAAAAAAAAB--- --BAAAAAAAAAAAAAAAAAAAAAAAAAB-- --BAAAAAAAAAAAAAAAAAAAAAAAAAB-- --BAAAAAAAAAAAAAAAAAAAAAAAAAB-- --BAAAAAAAAAAAAAAAAAAAAAAAAAB-- -DDAAAAAAAAAAAAAAAAAAAAAAAAAD-- --AAAAAAAAAAAAAAAAAAAAAAAAAAA-- --AAAAAAAAAAAAAAAAAAAAAAAAAAA-- --AAAAAAAAAAAAAAAAAAAAAAAAAAA-- --AAAAAAAAAAAAAAAAAAAAAAAAAAA-- ---AAAAAAAAAAAAAAAAAAAAAAAAA--- ---DAAAAAAAAAAAAAAAAAAAAAAAD--- ----BAAAAAAAAAAAAAAAAAAAAAB---- ----BAAAAAAAAAAAAAAAAAAAAAB---- -----BAAAAAAAAAAAAAAAAAAAB----- ------BAAAAAAAAAAAAAAAAAB------ -------BBAAAAAAAAAAAAABB------- ---------BBAAAAAAAAABB--------- -----------BBBBBBBBB----------- ------------------------------- ------------------------------- 
------------------------------- ------------------------------- -------------AAAAA------------- ----------AAAAAAAAAAA---------- --------AAAAAAAAAAAAAAA-------- -------AAAAAAAAAAAAAAAAA------- ------AAAAAAAAAAAAAAAAAAA------ -----AAAAAAAAAAAAAAAAAAAAA----- ----DAAAAAAAAAAAAAAAAAAAAAD---- ----BAAAAAAAAAAAAAAAAAAAAAB---- ---BAAAAAAAAAAAAAAAAAAAAAAAB--- ---BAAAAAAAAAAAAAAAAAAAAAAAB--- ---BAAAAAAAAAAAAAAAAAAAAAAAB--- --BAAAAAAAAAAAAAAAAAAAAAAAAAB-- --BAAAAAAAAAAAAAAAAAAAAAAAAAB-- --DAAAAAAAAAAAAAAAAAAAAAAAAAD-- --AAAAAAAAAAAAAAAAAAAAAAAAAAA-- --AAAAAAAAAAAAAAAAAAAAAAAAAAA-- ---AAAAAAAAAAAAAAAAAAAAAAAAA--- ---AAAAAAAAAAAAAAAAAAAAAAAAA--- ---AAAAAAAAAAAAAAAAAAAAAAAAA--- ----AAAAAAAAAAAAAAAAAAAAAAA---- ----DAAAAAAAAAAAAAAAAAAAAAD---- -----BAAAAAAAAAAAAAAAAAAAB----- ------BAAAAAAAAAAAAAAAAAB------ -------BAAAAAAAAAAAAAAAB------- --------BBAAAAAAAAAAABB-------- ----------BBBAAAAABBB---------- -------------BBBBB------------- ------------------------------- ------------------------------- 
------------------------------- ------------------------------- ------------------------------- ------------AAAAAAA------------ ---------AAAAAAAAAAAAA--------- --------AAAAAAAAAAAAAAA-------- -------AAAAAAAAAAAAAAAAA------- -----DDAAAAAAAAAAAAAAAAADD----- -----BAAAAAAAAAAAAAAAAAAAB----- ----BAAAAAAAAAAAAAAAAAAAAAB---- ----BAAAAAAAAAAAAAAAAAAAAAB---- ----BAAAAAAAAAAAAAAAAAAAAAB---- ---BAAAAAAAAAAAAAAAAAAAAAAAB--- ---BAAAAAAAAAAAAAAAAAAAAAAAB--- ---BAAAAAAAAAAAAAAAAAAAAAAAB--- --DDAAAAAAAAAAAAAAAAAAAAAAAD--- ---AAAAAAAAAAAAAAAAAAAAAAAAA--- ---AAAAAAAAAAAAAAAAAAAAAAAAA--- ---AAAAAAAAAAAAAAAAAAAAAAAAA--- ----AAAAAAAAAAAAAAAAAAAAAAA---- ----AAAAAAAAAAAAAAAAAAAAAAA---- ----AAAAAAAAAAAAAAAAAAAAAAA---- -----AAAAAAAAAAAAAAAAAAAAA----- -----DDAAAAAAAAAAAAAAAAADD----- -------BAAAAAAAAAAAAAAAB------- --------BAAAAAAAAAAAAAB-------- ---------BBBAAAAAAABBB--------- ------------BBBBBBB------------ ------------------------------- ------------------------------- ------------------------------- 
------------------------------- ------------------------------- ------------------------------- ------------------------------- -----------AAAAAAAAA----------- ---------AAAAAAAAAAAAA--------- -------DDAAAAAAAAAAAAADD------- -------BAAAAAAAAAAAAAAAB------- ------BAAAAAAAAAAAAAAAAAB------ -----BAAAAAAAAAAAAAAAAAAAB----- -----BAAAAAAAAAAAAAAAAAAAB----- ----BAAAAAAAAAAAAAAAAAAAAAB---- ----BAAAAAAAAAAAAAAAAAAAAAB---- ----BAAAAAAAAAAAAAAAAAAAAAB---- ----BAAAAAAAAAAAAAAAAAAAAAB---- ---DDAAAAAAAAAAAAAAAAAAAAAD---- ----AAAAAAAAAAAAAAAAAAAAAAA---- ----AAAAAAAAAAAAAAAAAAAAAAA---- ----AAAAAAAAAAAAAAAAAAAAAAA---- ----AAAAAAAAAAAAAAAAAAAAAAA---- -----AAAAAAAAAAAAAAAAAAAAA----- -----AAAAAAAAAAAAAAAAAAAAA----- ------AAAAAAAAAAAAAAAAAAA------ -------AAAAAAAAAAAAAAAAA------- -------DDAAAAAAAAAAAAADD------- ---------BBAAAAAAAAABB--------- -----------BBBBBBBBB----------- ------------------------------- ------------------------------- ------------------------------- ------------------------------- 
------------------------------- ------------------------------- ------------------------------- ------------------------------- ------------------------------- ---------DDDDDDDDDDDDD--------- ---------BBBAAAAAAABBB--------- --------BBAAAAAAAAAAABB-------- -------BBAAAAAAAAAAAAABB------- ------BBAAAAAAAAAAAAAAABB------ ------BAAAAAAAAAAAAAAAAAB------ -----BBAAAAAAAAAAAAAAAAABB----- -----BAAAAAAAAAAAAAAAAAAAB----- -----BAAAAAAAAAAAAAAAAAAAB----- -----BAAAAAAAAAAAAAAAAAAAB----- ----DDAAAAAAAAAAAAAAAAAAAD----- -----AAAAAAAAAAAAAAAAAAAAA----- -----AAAAAAAAAAAAAAAAAAAAA----- -----AAAAAAAAAAAAAAAAAAAAA----- -----AAAAAAAAAAAAAAAAAAAAA----- ------AAAAAAAAAAAAAAAAAAA------ ------AAAAAAAAAAAAAAAAAAA------ -------AAAAAAAAAAAAAAAAA------- --------AAAAAAAAAAAAAAA-------- ---------AAAAAAAAAAAAA--------- ---------DDDDDDDDDDDDD--------- ------------------------------- ------------------------------- ------------------------------- ------------------------------- ------------------------------- 
------------------------------- ------------------------------- ------------------------------- ------------------------------- ------------------------------- ------------------------------- ------------BBBBBBB------------ ----------BBBAAAAABBB---------- ---------BBAAAAAAAAABB--------- --------BBAAAAAAAAAAABB-------- -------BBAAAAAAAAAAAAABB------- -------BAAAAAAAAAAAAAAAB------- ------BBAAAAAAAAAAAAAAABB------ ------BAAAAAAAAAAAAAAAAAB------ ------BAAAAAAAAAAAAAAAAAB------ -----DDAAAAAAAAAAAAAAAAAD------ ------AAAAAAAAAAAAAAAAAAA------ ------AAAAAAAAAAAAAAAAAAA------ ------AAAAAAAAAAAAAAAAAAA------ -------AAAAAAAAAAAAAAAAA------- -------AAAAAAAAAAAAAAAAA------- --------AAAAAAAAAAAAAAA-------- ---------AAAAAAAAAAAAA--------- ----------AAAAAAAAAAA---------- ------------AAAAAAA------------ ------------------------------- ------------------------------- ------------------------------- ------------------------------- ------------------------------- ------------------------------- 
------------------------------- ------------------------------- ------------------------------- ------------------------------- ------------------------------- ------------------------------- ------------------------------- -------------BBBBB------------- -----------BBBBBBBBB----------- ----------BBBAAAAABBB---------- ---------BBAAAAAAAAABB--------- --------BBAAAAAAAAAAABB-------- --------BBAAAAAAAAAAABB-------- -------BBAAAAAAAAAAAAABB------- -------BBAAAAAAAAAAAAABB------- ------DDDAAAAAAAAAAAAADD------- -------AAAAAAAAAAAAAAAAA------- -------AAAAAAAAAAAAAAAAA------- --------AAAAAAAAAAAAAAA-------- --------AAAAAAAAAAAAAAA-------- ---------AAAAAAAAAAAAA--------- ----------AAAAAAAAAAA---------- -----------AAAAAAAAA----------- -------------AAAAA------------- ------------------------------- ------------------------------- ------------------------------- ------------------------------- ------------------------------- ------------------------------- ------------------------------- 
------------------------------- ------------------------------- ------------------------------- ------------------------------- ------------------------------- ------------------------------- ------------------------------- ------------------------------- ------------------------------- -------------BBBBB------------- -----------BBBBBBBBB----------- ----------BBBBBBBBBBB---------- ----------BBBAAAAABBB---------- ---------BBBAAAAAAABBB--------- ---------BBBAAAAAAABBB--------- --------DDDDAAAAAAADDDD-------- ---------AAAAAAAAAAAAA--------- ---------AAAAAAAAAAAAA--------- ----------AAAAAAAAAAA---------- ----------AAAAAAAAAAA---------- -----------AAAAAAAAA----------- -------------AAAAA------------- ------------------------------- ------------------------------- ------------------------------- ------------------------------- ------------------------------- ------------------------------- ------------------------------- ------------------------------- ------------------------------- 
------------------------------- ------------------------------- ------------------------------- ------------------------------- ------------------------------- ------------------------------- ------------------------------- ------------------------------- ------------------------------- ------------------------------- ------------------------------- ------------------------------- -------------BBBBB------------- ------------BBBBBBB------------ ------------BBBBBBB------------ -----------DDDDDDDDD----------- ------------AAAAAAA------------ ------------AAAAAAA------------ -------------AAAAA------------- ------------------------------- ------------------------------- ------------------------------- ------------------------------- ------------------------------- ------------------------------- ------------------------------- ------------------------------- ------------------------------- ------------------------------- ------------------------------- ------------------------------- 
