model
size = 17 32 23, scale = 0.05, origin = -y
material 
  colors = A:#FFF B:#303 C:#100 D:#306 E:#F90 F:#CCF G:#66C H:#FF9 I:#EEE J:#FF3 K:#FC3 L:#96C M:#DDD N:#99C O:#222 P:#300 Q:#111 R:#F93 S:#666 T:#999 U:#60F
voxels
7-3(4A13-)4A14-3A15-A181-6B10-2B4-B10-B6-B9-B7-2B2(6-B9-B)5-B10-B5-3(B11-B4-)B9-AB5-2B8-AB6-3B4-3B10-4B47-2(9A8-)7(8A9-)7A10-6A12-4A13-4A12-5A11-7A10-8A2(8-A6-2A)7-A8-A7-B9-A5-B9-AOA4-B9-AQA4-B10-2A4-BA10-A2(4-BA10-B)4-BA8-AB5-B9-2B6-2B5-2B10-B3DB46-2(11A6-)5(10A7-)10A6-11A7(5-12A)4-2(2A7-5A3-)2A4(8-A-2A2-3A)9-A-A3-2A9-2A4-2A10-A4-2(2A8-2A5-)2A2(8-A)5-2A10-2A2-A14-2A29-12A8(5-A7-4A)3(4-A8-4A)2(3-2A8-4A)2(3-2A8-A-2A)3-2A8-A2(-3A)5(8-A2-2A-3A)8-A-2A2-2CA8-A-2A2-3A8-3A3-2PA8-3A3-2CA8-2A5-2A2(8-A)6-A10-A3-2A12-3A27-14A4(3-2A8-4A)3-2A8-5A2-3A7-6(5A2-2A8-)4AM2-2A4(8-5A-3A)4(8-9A)8-5A-3A8-5A-2(2CA8-4A2-)2CA8-3A3-2CA8-2A5-2A8-2A7-A6-A9-A5-B11-2A3B26-15A2-A9-6(5A2-2A8-)6A-2A4(8-9A)2(8-4A2B3A)8(8-9A)2(8-5A-3A)8-4A2-3A8-3A3-3A8-3A4-2A8-2A6-2(A8-)A6-B10-B3-2B12-3B10-15A2(2-A9-5A)4(2-2A8-5A)-3A5(8-9A)3(8-4A2B3A)2(8-4A2I3A8-9A)3(8-9A)8-5A-2CA8-5A-2(3A8-4A2-)3A8-3A4-2A8-2A6-A8-B8-A6-B10-B4-D12-B3D9-15A2(2-A9-5A)2(2-2A8-5A)2-2A8-6A-2A4(8-9A)2(8-6AC2A)4(8-4A2BC2A)8-4A2F2(C2A8-4A2B)C2A3(8-9A)2(8-5A-2CA)2(8-4A2-2CA)8-3A4-2A8-3A5-A8-2B7-A6-U10-B16-B13-16A2(-A9-6A)3(-2A8-6A)-2A4(8-9A)8-6AC2A8-9A8-4ALB3(3A8-4A2B)C2A8-4A2F2(3A8-4A2B)C2A2(8-4A2B3A)8-4AG4A2(8-5A-3A)2(8-4A2-3A)8-3A4-2A8-2AB5-A8-2B7-A16-B31-16A2(-A9-6A)3(-2A8-6A)-2A4(8-9A)8-6AC2A8-9A8-4A2F3(3A8-4A2B)C2A2(8-4A2B3A)8-4A2BC2A2(8-4A2B3A)8-4ALB3A8-4AG-2CA8-4AB-3A2(8-4A2-2CA)8-4A3-2A8-3B5-A8-B8-A16-B31-16A2(-A9-6A)3(-2A8-6A)-2A4(8-9A)2(8-6AC2A)8-9A8-4A2N4(3A8-4A2B)2(C2A8-4A2B)3A8-4A2B3A8-4A2F3A2(8-4AB-2CA)8-4A2-3A8-4A2-2CA8-4A3-2A8-3B5-A8-B8-A16-B31-16A2(-A9-6A)3(-2A8-6A)-2A4(8-9A)2(8-6AC2A)8-4A2B3A8-4A2L3A8-4A2I3(3A8-4A2B)2(C2A8-4A2B)3A8-4A2N3A8-4A2B3A8-4AB-3A8-5A-2(3A8-4A2-)3A8-4A3-2A8-3B5-A8-B8-A16-B31-16A2(-A9-6A)3(-2A8-6A)-2A6(8-9A)3(8-4A2B3A)8-4A2G5(3A8-4A2B)3A8-4AGB3A8-5A-2CA8-5A-3A2(8-4A2-2CA)8-4A3-2A8-3B5-A8-B8-A16-B31-16A2(-A9-6A)3(-2A8-6A)-2A4(8-9A)2(8-6AC2A)7(8-4A2BC2A)8-4A2B3A8-4A2M3A8-9A2(8-5A-2CA)8-4A2-3A8-4A2-2CA8-4A3-2A8-3B5-A8-B8-A16-B31-16A2(-A9-6A)3(-2A8-6A)-2A4(8-9A)2(8-6AC2A)8-4A2BC2A8-4ABG2(C2A8-4A2G)C2A8-4ALB2(C2A8-4A2B)C2A3(8-9A)2(8-5A-3A)2(8-4A2-3A)8-3A4-2A8-2AB5-A8-2B7-A16-B31-15A2(2-A9-5A)2(2-2A8-5A)2-2A8-6A-2A6(8-9A)8-4A2B3A8-4ALB3A8-9A8-4A2F3A8-9A8-4A2BC2A8-4A2M3A8-4A2H3A2(8-9A)2(8-5A-2CA)2(8-4A2-2CA)8-3A4-2A8-3A5-A8-2B7-A6-B10-B16-B13-15A2(2-A9-5A)4(2-2A8-5A)-3A5(8-9A)8-4A2I3A3(8-9A)8-4A2H3A8-4A2E3A8-4A2J3A8-4A2E3A2(8-9A)2(8-5A-3A)2(8-4A2-3A)8-3A4-2A8-2A6-A8-B8-A6-B10-B4-D12-B3D9-15A2-A9-6(5A2-2A8-)6A-2A9(8-9A)8-4A2K3A8-4AKR3A8-4AJE3A8-4A2E3A8-9A8-5A-2CA8-5A-3A8-4A2-2CA8-3A3-3A8-3A4-2A8-2A6-2(A8-)A6-B10-B3-2B12-3B10-14A4(3-2A8-4A)3-2A8-5A3-2A7-2(5A3-A8-)5(5A2-2A8-)3(5A-3A8-)AH2AH-3A8-A2KA2E3A8-2(A2J)3A8-A2KA2E3A8-9A2(8-5A-3A)8-4A2-2CA8-4A2-3A8-3A3-2CA8-2A5-2A8-2A7-A6-A9-A5-B11-2A3B28-12A8(5-A7-4A)3(4-A8-4A)2(3-2A8-4A)2(3-2A8-A-2A)3-2A8-A2(-3A)2(8-A2-2A-3A)8-A2-2H2(-3A8-A2-2A)-3A2(8-A-2A2-2CA)2(8-3A3-2CA)8-2A5-2A2(8-A)6-A10-A3-2A12-3A30-11A6-3A4-4A6-2(3A4-3A7-)4A3-3A7-5A-4A2(7-10A)6-11A2(5-12A)5-2(11A6-)2(12A5-)12A4-2(2A7-5A3-)A2(9-A-2A2-2A)9-A-2A2-3A8-A-OA2-3A8-AT-A3-2A8-ASA4-2A8-3A4-2A2(8-2A6-A)2(8-A)5-2A10-2A2-A14-2A31-9A8-2A4-3A8-2(2A4-2A9-)3A3-2A9-4A-3A10-7A2(9-8A)9-7A10-6A12-4A13-4A12-5A11-7A10-8A2(8-A6-2A)16-A7-B8-2A5-B9-AOA4-B9-AQA2(4-BA9-2A)4-BA10-A4-BA10-B4-BA8-AB5-BA8-2B6-2B5-2B10-B3DB49-3(4A13-)4A14-3A15-A181-6B10-2B4-B10-B6-B9-B7-2B2(6-B9-B)5-B10-B5-3(B11-B4-)B10-B5-2B9-B6-3B4-3B10-4B42-
