model
size = 17 31 24, scale = 0.05, origin = -y
material 
  colors = A:#100 B:#E00 C:#C03 D:#111 E:#222 F:#BBB G:#933 H:#B00 I:#C33 J:#633 K:#963 L:#696 M:#C66 N:#D00 O:#500 P:#C96 Q:#363 R:#C00 S:#A00 T:#396 U:#993 V:#333 W:#C36 X:#F03 Y:#09F Z:#C63 Aa:#CC6 Ab:#330 Ac:#800 Ad:#903 Ae:#400 Af:#936 Ag:#09C Ah:#099 Ai:#066 Aj:#366 Ak:#069 Al:#900 Am:#555
voxels
- - - - - - - - - - - - - - - - -   - - - - - - - - - - - - - - - - -   - - - - - - - - - - - - - - - - -   - - - - - - - - - - - - - - - - -   - - - - - - - - - - - - - - - - -   - - - - - - - - - - - - - - - - -   - - - - - - - - - - - - - - - - -   - - - - - - - - - - - - - - - - -   - - - - - - - - - - - - - - - - -   - - - - - - - - - - - - - - - - -   - - - - - - - - - - - - - - - - -   - - - - - - - - - - - - - - - - -   - - - - - - - - - - - - - - - - -   - - - - - - - - - - - - - - - - -   - - - - - - - - - - - - - - - - -   - - - - B B B B - - - - - - - - -   - - - B - - - - B - - - - - - - -   - - B - - - - - - B - - - - - - -   - - B - - - - - - - B - - - - - -   - B B - - - - - - - B - - - - - -   - B - - - - - - - - B B - - - - -   - B - - - - - - - - - B - - - - -   - B - - - - - - - - - B - - - - -   - B - - - - - - - - B B - - - - -   - - B - - - - - - - B - - - - - -   - - B B - - - - - B B - - - - - -   - - - B B B - - B B - - - - - - -   - - - - - B B B B - - - - - - - -   - - - - - - - - - - - - - - - - -   - - - - - - - - - - - - - - - - -   - - - - - - - - - - - - - - - - -   
- - - - - - - - C AlAl- - - - - -   - - - - - - - C C AcAcAc- - - - -   - - - - - - - - - C C - - - - - -   - - - - - - - - - - - - - - - - -   - - - - - - - - - - - - - - - - -   - - - - - - - - - - - - - - - - -   - - - - - - - - - - - - - - - - -   - - - - - - - - - - - - - - - - -   - - - - - - - - - - - - - - - - -   - - - - - - - - - - - - - - - - -   - - - - - - - - - - - - - - - - -   - - - - - - - - - - - - - - - - -   - - - A A A A A A A - - - - - - -   - - - A A A A A A A - - - - - - -   - - - A A A A A A A - - - - - - -   - - A A - - - - A A - - - - - - -   - - A - - - - - - A A - - - - - -   - - A - - - - - - - A A - - - - -   - A - - - - - - - - - A - - - - -   - A - - - - - - - - - A A - - - -   - A - - - - - - - - - - A - - - -   - A - - - - - - - - - - A - - - -   - A - - - - - - - - - A - - - - -   - A - - - - - - - - - A - - - - -   - A - - - - - - - - - A - - - - -   - - A - - - - - - - - A - - - - -   - - - A - - - - - - A - - - - - -   - - - - A - - - - A - - - - - - -   - - - - - A A A A - - - - - - - -   - - - - - - - - - - - - - - - - -   - - - - - - - - - - - - - - - - -   
- - - - - H H H - - - H H H - - -   - - - - - H C - - - - - H H - - -   - - - - - H H C C - - I H - - - -   - - - - - - H C C C C H C - - - -   - - - - - - H C O C H H O - - - -   - - - - - - O H O O O O O - - - -   - - - - E E E E E E E E E - - - -   - - - - - A A A A A A A - - - - -   - - - - - A A A A A A - - - - - -   - - - - - A A A A A A - - - - - -   - - - - A A A A A A A A - - - - -   - - - - A A A A A A A A - - - - -   - - - - A - - - - - A - - - - - -   - - - A - - - - - - A A - - - - -   - - - A - - - - - - A A - - - - -   - - A - - - - - - - A A A - - - -   - - A - - - - - - - - A A A - - -   - A - - - - - - - - - - A A - - -   - A - - - - - - - - - - A A - - -   - A - - - - - - - - - - - A - - -   - A - - - - - - - - - - - A - - -   - A - - - - - - - - - - - A - - -   - A - - - - - - - - - - A - - - -   - A - - - - - - - - - - A - - - -   - A - - - - - - - - - A - - - - -   - - A - - - - - - - - A - - - - -   - - - A - - - - - - A - - - - - -   - - - A A - - - - A - - - - - - -   - - - - - A A A A - - - - - - - -   - - - - - - - - - - - - - - - - -   - - - - - - - - - - - - - - - - -   
- - - - S - - - - - - - - - S - -   - - - - S - - - - - - - - - S - -   - - - - H - - - - - - - - H - - -   - - - - G G - - - - - - - G - - -   - - - - - G - - - - - - - G - - -   - - - - - E - - - - - - - E - - -   - - - D D - - - - - - - - D - - -   - - A A A - - - - - - - A A - - -   - - A A A - - - - - - A A - - - -   - - A A A - - - - - - A A - - - -   - - A A - - - - - - - - A A - - -   - - A A - - - - - - - - A A - - -   - - A A - - - - - - - A A A - - -   - - A - - - - - - - - - A - - - -   - - A - - - - - - - - - A A - - -   - A - - - - - - - - - - - A - - -   - A - - - - - - - - - - - - A - -   - A - - - - - - - - - - - - A - -   A - - - - - - - - - - - - - A - -   A - - - - - - - - - - - - - A - -   A - - - - - - - - - - - - - A - -   A - - - - - - - - - - - - - A - -   A - - - - - - - - - - - - A - - -   - A - - - - - - - - - - A - - - -   - A - - - - - - - - - - A - - - -   - - A - - - - - - - - A - - - - -   - - A - - - - - - - - A - - - - -   - - - A - - - - - A A - - - - - -   - - - - A A - A A - - - - - - - -   - - - - - - A - - - - - - - - - -   - - - - - - - - - - - - - - - - -   
- - - N - - - - - - - - - - N - -   - - - R - - - - - - - - - - R - -   - - - I - - - - - - - - - - I - -   - - - J - - - - - - - - - - J - -   - - - - E - - - - - - - - - E - -   - - - - D - - - - - - - - - D - -   - - A A - - - - - - - - - - A - -   - - A - - - - - - - - - - - A - -   - A - - - - - - - - - - - A A - -   - A - - - - - - - - - - - A A - -   - A - - - - - - - - - - - - A - -   - A - - - - - - - - - - - - A - -   - A - - - - - - - - - - - - A - -   - A - - - - - - - - - - - A A - -   - A - - - - - - - - - - - - A - -   A - - - - - - - - - - - - - A - -   A - - - - - - - - - - - - - - A -   A - - - - - - - - - - - - - - A -   A - - - - - - - - - - - - - - A -   A - - - - - - - - - - - - - - A -   A - - - - - - - - - - - - - - A -   A - - - - - - - - - - - - - A - -   A - - - - - - - - - - - - - A - -   A - - - - - - - - - - - - A - - -   - A - - - - - - - - - - - A - - -   - - A - - - - - - - - - A - - - -   - - A - - - - - - - - A - - - - -   - - - A - - - - - - A - - - - - -   - - - - A - - - A A - - - - - - -   - - - - - A A A - - - - - - - - -   - - - - - - - - - - - - - - - - -   
- - H - - - - - - - - - - - H - -   - - I - - - - - - - - - - - - I -   - - H - - - - - - - - - - - J - -   - - - O - - - - - - - - - - - O -   - - - O - - - - - - - - - - - O -   - - - E - - - - - - - - - - - E -   - - A - - - - - - - - - - - - A -   - - A - - - - - - - - - - - - A -   - A - - - - - - - - - - - - - A -   - A - - - - - - - - - - - - - A -   - A - - - - - - - - - - - - - K -   - A - - - - - - - - - - - - - K -   - A - - - - - - - - - - - - - E -   A - - - - - - - - - - - - - - A -   A - - - - - - - - - - - - - - A -   A - - - - - - - - - - - - - - K -   A - - - - - - - - - - - - - - K -   A - - - - - - - - - - - - - - - A   A - - - - - - - - - - - - - - - A   A - - - - - - - - - - - - - - D -   A - - - - - - - - - - - - - - Q -   A - - - - - - - - - - - - - - Q -   A - - - - - - - - - - - - - A - -   A - - - - - - - - - - - - - A - -   - A - - - - - - - - - - - A - - -   - A - - - - - - - - - - A - - - -   - - A - - - - - - - - A - - - - -   - - - A - - - - - - A - - - - - -   - - - A - - - - - A - - - - - - -   - - - - A A A A A - - - - - - - -   - - - - - - - - - - - - - - - - -   
- - S - - - - - - - - - - - - S -   - - H - - - - - - - - - - - - H -   - - G - - - - - - - - - - - - G -   - - G - - - - - - - - - - - - G -   - - - E - - - - - - - - - - - E -   - - - D - - - - - - - - - - - D -   - - D - - - - - - - - - - - - D -   - - A - - - - - - - - - - - - A -   - A - - - - - - - - - - - - - - A   - A - - - - - - - - - - - - - - K   - A - - - - - - - - - - - - - - P   - A - - - - - - - - - - - - - - P   - A - - - - - - - - - - - - - - Z   A - - - - - - - - - - - - - - - A   A - - - - - - - - - - - - - - - U   A - - - - - - - - - - - - - - - Aa  A - - - - - - - - - - - - - - - Aa  A - - - - - - - - - - - - - - - U   A - - - - - - - - - - - - - - - A   A - - - - - - - - - - - - - - - T   A - - - - - - - - - - - - - - L -   A - - - - - - - - - - - - - - L -   A - - - - - - - - - - - - - - Q -   A - - - - - - - - - - - - - A - -   - A - - - - - - - - - - - A - - -   - A - - - - - - - - - - - A - - -   - - A - - - - - - - - - A - - - -   - - A - - - - - - - - A - - - - -   - - - A - - A - - A A - - - - - -   - - - - A - A - A - - - - - - - -   - - - - - B B B - - - - - - - - -   
- R - - - - - - - - - - - - - R -   - - I - - - - - - - - - - - - I -   - - J - - - - - - - - - - - - J -   - - E - - - - - - - - - - - - E -   - - A - - - - - - - - - - - - - D   - - - A - - - - - - - - - - - - A   - A A - - - - - - - - - - - - - A   - A - - - - - - - - - - - - - - A   - A - - - - - - - - - - - - - - A   - A - - - - - - - - - - - - - - K   - A - - - - - - - - - - - - - - P   - A - - - - - - - - - - - - - - P   - A - - - - - - - - - - - - - - M   A A - - - - - - - - - - - - - - A   F - - - - - - - - - - - - - - - U   F - - - - - - - - - - - - - - - Aa  F - - - - - - - - - - - - - - - Aa  F - - - - - - - - - - - - - - - U   F - - - - - - - - - - - - - - - A   F - - - - - - - - - - - - - - - L   A - - - - - - - - - - - - - - - L   A - - - - - - - - - - - - - - L -   A - - - - - - - - - - - - - - Q -   A - - - - - - - - - - - - - A - -   - A - - - - - - - - - - - - A - -   - A - - - - - - - - - - - A - - -   - - A - - - - - - - - - A - - - -   - - A - - - A - - - - A - - - - -   - - - A - A - A - - A - - - - - -   - - - - A A - A - B - - - - - - -   - - - - - B B B B - - - - - - - -   
- R - - - - - - - - - - - - - R -   - R - - - - - - - - - - - - - - R   - - I - - - - - - - - - - - - I -   - - Ae- - - - - - - - - - - - - Ae  - - A - - - - - - - - - - - - - A   - - A - - - - - - - - - - - - - A   - A - - - - - - - - - - - - - - A   A - - - - - - - - - - - - - - - A   A - - - - - - - - - - - - - - - A   A - - - - - - - - - - - - - - - Ab  A - - - - - - - - - - - - - - - Z   A - - - - - - - - - - - - - - - M   A - - - - - - - - - - - - - - - J   A - - - - - - - - - - - - - - - A   F - - - - - - - - - - - - - - - Ab  F - - - - - - - - - - - - - - - U   F - - - - - - - - - - - - - - - U   F - - - - - - - - - - - - - - - Ab  F - - - - - - - - - - - - - - - A   A - - - - - - - - - - - - - - - V   A - - - - - - - - - - - - - - - L   A - - - - - - - - - - - - - - T -   A - - - - - - - - - - - - - - D -   - A - - - - - - - - - - - - A - -   - A - - - - - - - - - - - - A - -   - A - - - - - - - - - - - A - - -   - - A - - - - - - - - - - A - - -   - - A - - - - - - - - - A - - - -   - - - A - - - - - - B B - - - - -   - - - - A - - - B B - - - - - - -   - - - - B - - - - - - - - - - - -   
- G - - - - - - - - - - - - - - G   - J - - - - - - - - - - - - - - J   - - E - - - - - - - - - - - - E -   - - D - - - - - - - - - - - - - D   - - A - - - - - - - - - - - - - D   - - A - - - - - - - - - - - - - A   A A - - - - - - - - - - - - - - A   A - - - - - - - - - - - - - - - A   A - - - - - - - - - - - - - - - A   A - - - - - - - - - - - - - - - A   A - - - - - - - - - - - - - - - A   A - - - - - - - - - - - - - - - A   A - - - - - - - - - - - - - - - A   A - - - - - - - - - - - - - - - A   A - - - - - - - - - - - - - - - A   A - - - - - - - - - - - - - - - A   A - - - - - - - - - - - - - - - A   A - - - - - - - - - - - - - - - A   F - - - - - - - - - - - - - - - A   A - - - - - - - - - - - - - - - A   A - - - - - - - - - - - - - - - A   A - - - - - - - - - - - - - - A -   A - - - - - - - - - - - - - - A -   - A - - - - - - - - - - - - A - -   - A - - - - - - - - - - - - A - -   - A - - - - - - - - - - - A - - -   - - A - - - - - - - - - - A - - -   - - A - - - - - - - - - B - - - -   - - - A - - - - - - - B - - - - -   - - - B B - - - - - - - - - - - -   - - - - - - - - - - - - - - - - -   
- N - - - - - - - - - - - - - - N   - M - - - - - - - - - - - - - - M   - - E - - - - - - - - - - - - - E   - - D - - - - - - - - - - - - - D   - - A - - - - - - - - - - - - - A   - - A - - - - - - - - - - - - - J   A A - - - - - - - - - - - - - - G   A - - - - - - - - - - - - - - - J   A - - - - - - - - - - - - - - - A   A - - - - - - - - - - - - - - - A   A - - - - - - - - - - - - - - - K   A - - - - - - - - - - - - - - - K   A - - - - - - - - - - - - - - - E   A - - - - - - - - - - - - - - - A   A - - - - - - - - - - - - - - - A   A - - - - - - - - - - - - - - - A   A - - - - - - - - - - - - - - - A   A - - - - - - - - - - - - - - - A   A - - - - - - - - - - - - - - - A   A - - - - - - - - - - - - - - - E   A - - - - - - - - - - - - - - - Aj  A - - - - - - - - - - - - - - Q -   A - - - - - - - - - - - - - - A -   - A - - - - - - - - - - - - A - -   - A - - - - - - - - - - - - Ai- -   - A - - - - - - - - - - - - Ah- -   - - A - - - - - - - - - - Ak- - -   - - A - - - A A A A A A B - - - -   - - - A - - - - - - - - - - - - -   - - - B B - - - - - - - - - - - -   - - - - - - - - - - - - - - - - -   
- G - - - - - - - - - - - - - - G   - D - - - - - - - - - - - - - - D   - - D - - - - - - - - - - - - - D   - - A - - - - - - - - - - - - - D   - - A - - - - - - - - - - - - - A   - - A - - - - - - - - - - - - - M   A A - - - - - - - - - - - - - - M   A - - - - - - - - - - - - - - - W   A - - - - - - - - - - - - - - - A   A - - - - - - - - - - - - - - - K   A - - - - - - - - - - - - - - - P   A - - - - - - - - - - - - - - - P   A - - - - - - - - - - - - - - - M   A - - - - - - - - - - - - - - - A   A - - - - - - - - - - - - - - - A   A - - - - - - - - - - - - - - - A   A - - - - - - - - - - - - - - - A   A - - - - - - - - - - - - - - - A   A - - - - - - - - - - - - - - - A   A - - - - - - - - - - - - - - - T   A - - - - - - - - - - - - - - - L   A - - - - - - - - - - - - - - L -   A - - - - - - - - - - - - - - Q -   - A - - - - - - - - - - - - A - -   - A - - - - - - - - - - - - Ag- -   - A - - - - - - - - - - - - Y - -   - - A - - - - - - - - - - Y - - -   - - A - - - - - - - - - B - - - -   - - - A - - - - - - - - - - - - -   - - - B B - - - - - - - - - - - -   - - - - - - - - - - - - - - - - -   
- N - - - - - - - - - - - - - - N   - E - - - - - - - - - - - - - - E   - - D - - - - - - - - - - - - - D   - - A - - - - - - - - - - - - - D   - - A - - - - - - - - - - - - - A   - A - - - - - - - - - - - - - - M   A - - - - - - - - - - - - - - - M   A - - - - - - - - - - - - - - - W   A - - - - - - - - - - - - - - - A   A - - - - - - - - - - - - - - - K   A - - - - - - - - - - - - - - - P   A - - - - - - - - - - - - - - - P   A - - - - - - - - - - - - - - - M   A - - - - - - - - - - - - - - - A   A - - - - - - - - - - - - - - - A   F - - - - - - - - - - - - - - - A   F - - - - - - - - - - - - - - - A   F - - - - - - - - - - - - - - - A   F - - - - - - - - - - - - - - - A   A - - - - - - - - - - - - - - - T   A - - - - - - - - - - - - - - - L   A - - - - - - - - - - - - - - L -   A - - - - - - - - - - - - - - Q -   - A - - - - - - - - - - - - A - -   - A - - - - - - - - - - - - Ag- -   - A - - - - - - - - - - - - Y - -   - - A - - - - - - - - - - Y - - -   - - A - - - - - - - - - B - - - -   - - - A - - - - - - - - - - - - -   - - - B B - - - - - - - - - - - -   - - - - - - - - - - - - - - - - -   
- Af- - - - - - - - - - - - - - Af  - D - - - - - - - - - - - - - - D   - - D - - - - - - - - - - - - - D   - - A - - - - - - - - - - - - - D   - - A - - - - - - - - - - - - - A   - A - - - - - - - - - - - - - - J   A - - - - - - - - - - - - - - - G   A - - - - - - - - - - - - - - - J   A - - - - - - - - - - - - - - - A   A - - - - - - - - - - - - - - - A   A - - - - - - - - - - - - - - - K   A - - - - - - - - - - - - - - - K   A - - - - - - - - - - - - - - - E   A - - - - - - - - - - - - - - - A   F - - - - - - - - - - - - - - - A   F - - - - - - - - - - - - - - - A   F - - - - - - - - - - - - - - - A   F - - - - - - - - - - - - - - - A   F - - - - - - - - - - - - - - - A   F - - - - - - - - - - - - - - - E   A - - - - - - - - - - - - - - - Aj  A - - - - - - - - - - - - - - Q -   A - - - - - - - - - - - - - - A -   - A - - - - - - - - - - - - A - -   - A - - - - - - - - - - - - Ai- -   - A - - - - - - - - - - - - Ah- -   - - A - - - - - - - - - - Ak- - -   - - A - - - - - - - - - B - - - -   - - - A - - - - - - - - - - - - -   - - - B B - - - - - - - - - - - -   - - - - - - - - - - - - - - - - -   
- B - - - - - - - - - - - - - - B   - I - - - - - - - - - - - - - - I   - - D - - - - - - - - - - - - D -   - - A - - - - - - - - - - - - - D   - - A - - - - - - - - - - - - - D   - - A - - - - - - - - - - - - - A   A A - - - - - - - - - - - - - - A   A - - - - - - - - - - - - - - - A   A - - - - - - - - - - - - - - - A   A - - - - - - - - - - - - - - - A   A - - - - - - - - - - - - - - - A   A - - - - - - - - - - - - - - - A   A - - - - - - - - - - - - - - - A   A - - - - - - - - - - - - - - - A   F - - - - - - - - - - - - - - - A   A - - - - - - - - - - - - - - - A   A - - - - - - - - - - - - - - - A   A - - - - - - - - - - - - - - - A   A - - - - - - - - - - - - - - - A   F - - - - - - - - - - - - - - - A   A - - - - - - - - - - - - - - - A   A - - - - - - - - - - - - - - A -   A - - - - - - - - - - - - - - A -   - A - - - - - - - - - - - - A - -   - A - - - - - - - - - - - - A - -   - A - - - - - - - - - - - A - - -   - - A - - - - - - - - - - A - - -   - - A - - - - - - - - - B - - - -   - - - A - - - - - - - B - - - - -   - - - B B - - - - - - - - - - - -   - - - - - - - - - - - - - - - - -   
- G - - - - - - - - - - - - - G -   - E - - - - - - - - - - - - - E -   - - E - - - - - - - - - - - - E -   - - A - - - - - - - - - - - - D -   - - A - - - - - - - - - - - - - D   - - A - - - - - - - - - - - - - A   A A - - - - - - - - - - - - - - A   A - - - - - - - - - - - - - - - A   A - - - - - - - - - - - - - - - A   A - - - - - - - - - - - - - - - E   A - - - - - - - - - - - - - - - Z   A - - - - - - - - - - - - - - - M   A - - - - - - - - - - - - - - - J   A - - - - - - - - - - - - - - - A   F - - - - - - - - - - - - - - - A   A - - - - - - - - - - - - - - - A   A - - - - - - - - - - - - - - - A   A - - - - - - - - - - - - - - - A   A - - - - - - - - - - - - - - - A   F - - - - - - - - - - - - - - - V   A - - - - - - - - - - - - - - - L   A - - - - - - - - - - - - - - T -   A - - - - - - - - - - - - - - D -   - A - - - - - - - - - - - - A - -   - A - - - - - - - - - - - - A - -   - A - - - - - - - - - - - A - - -   - - A - - - - - - - - - - A - - -   - - A - - - - - - - - A A - - - -   - - - A - - - - - - B - - - - - -   - - - - A - - - - B - - - - - - -   - - - - B - - - - - - - - - - - -   
- N - - - - - - - - - - - - - N -   - N - - - - - - - - - - - - - N -   - - I - - - - - - - - - - - - I -   - - E - - - - - - - - - - - - E -   - - A - - - - - - - - - - - - D -   - - A - - - - - - - - - - - - A -   A A - - - - - - - - - - - - - - A   A - - - - - - - - - - - - - - - A   A - - - - - - - - - - - - - - - A   A - - - - - - - - - - - - - - - K   A - - - - - - - - - - - - - - - P   A - - - - - - - - - - - - - - - P   A - - - - - - - - - - - - - - - M   A - - - - - - - - - - - - - - - A   F - - - - - - - - - - - - - - - A   A - - - - - - - - - - - - - - - A   A - - - - - - - - - - - - - - - A   A - - - - - - - - - - - - - - - A   A - - - - - - - - - - - - - - - A   F - - - - - - - - - - - - - - - L   A - - - - - - - - - - - - - - - L   A - - - - - - - - - - - - - - L -   A - - - - - - - - - - - - - - Q -   A - - - - - - - - - - - - - A - -   - A - - - - - - - - - - - - A - -   - A - - - - - - - - - - - A - - -   - - A - - - - - - - - - A - - - -   - - A - - - - - - - - A - - - - -   - - - A - - - - - - A - - - - - -   - - - - A - - - - A - - - - - - -   - - - - - B B B B - - - - - - - -   
- B - - - - - - - - - - - - - B -   - - I - - - - - - - - - - - - I -   - - G - - - - - - - - - - - G - -   - - J - - - - - - - - - - - - J -   - - A - - - - - - - - - - - - D -   - - A - - - - - - - - - - - - A -   - A - - - - - - - - - - - - - - A   - A - - - - - - - - - - - - - - A   A - - - - - - - - - - - - - - - A   A - - - - - - - - - - - - - - - K   A - - - - - - - - - - - - - - - P   A - - - - - - - - - - - - - - - P   A - - - - - - - - - - - - - - - Z   A - - - - - - - - - - - - - - - A   F - - - - - - - - - - - - - - - A   F - - - - - - - - - - - - - - - A   F - - - - - - - - - - - - - - - A   F - - - - - - - - - - - - - - - A   F - - - - - - - - - - - - - - - A   A - - - - - - - - - - - - - - - T   A - - - - - - - - - - - - - - - L   A - - - - - - - - - - - - - - L -   A - - - - - - - - - - - - - - Q -   A - - - - - - - - - - - - - A - -   - A - - - - - - - - - - - A - - -   - A - - - - - - - - - - - A - - -   - - A - - - - - - - - - A - - - -   - - A - - - - - - - - A - - - - -   - - - A - - - - - - A - - - - - -   - - - - A - - - A A - - - - - - -   - - - - - B B B - - - - - - - - -   
- - X - - - - - - - - - - - X - -   - - W - - - - - - - - - - - W - -   - - G - - - - - - - - - - - G - -   - - E - - - - - - - - - - - E - -   - - A - - - - - - - - - - - - D -   - - - A - - - - - - - - - - - D -   - - A - - - - - - - - - - - - D -   - - A - - - - - - - - - - - - A -   - A - - - - - - - - - - - - - A -   - A - - - - - - - - - - - - - A -   - A - - - - - - - - - - - - - K -   - A - - - - - - - - - - - - - K -   - A - - - - - - - - - - - - - E -   A - - - - - - - - - - - - - - A -   A - - - - - - - - - - - - - - A -   F - - - - - - - - - - - - - - A -   F - - - - - - - - - - - - - - - A   F - - - - - - - - - - - - - - - A   F - - - - - - - - - - - - - - - A   A - - - - - - - - - - - - - - - D   A - - - - - - - - - - - - - - Q -   A - - - - - - - - - - - - - - Q -   A - - - - - - - - - - - - - A - -   A - - - - - - - - - - - - - A - -   - A - - - - - - - - - - - A - - -   - A - - - - - - - - - - A - - - -   - - A - - - - - - - - A A - - - -   - - - A - - - - - - A - - - - - -   - - - A - - - - - A - - - - - - -   - - - - A A A A A - - - - - - - -   - - - - - - - - - - - - - - - - -   
- - - B - - - - - - - - - - B - -   - - - B - - - - - - - - - - B - -   - - - I - - - - - - - - - - I - -   - - - I - - - - - - - - - - I - -   - - - A - - - - - - - - - - J - -   - - - A - - - - - - - - - - D - -   - - - A - - - - - - - - - - D - -   - - - A - - - - - - - - - - A - -   - - A - - - - - - - - - - - A A -   - - A - - - - - - - - - - - A - -   - - A - - - - - - - - - - A A - -   - A - - - - - - - - - - - A A - -   - A - - - - - - - - - - - - A - -   - A - - - - - - - - - - - - A - -   - A - - - - - - - - - - - - A - -   - A - - - - - - - - - - - - - A -   A - - - - - - - - - - - - - - A -   A - - - - - - - - - - - - - - A -   A - - - - - - - - - - - - - - A -   A - - - - - - - - - - - - - - A -   A - - - - - - - - - - - - - - A -   A - - - - - - - - - - - - - A - -   A - - - - - - - - - - - - - A - -   A - - - - - - - - - - - - A - - -   - A - - - - - - - - - - - A - - -   - A - - - - - - - - - - A - - - -   - - A - - - - - - - - A - - - - -   - - - A - - - - - - A - - - - - -   - - - - A - - - A A - - - - - - -   - - - - - A A A - - - - - - - - -   - - - - - - - - - - - - - - - - -   
- - - - X - - - - - - - - - X - -   - - - - C - - - - - - - - C - - -   - - - - J - - - - - - - - J - - -   - - - - E - - - - - - - - E - - -   - - - - A - - - - - - - - D - - -   - - - - A A - - - - - - - D - - -   - - - - A - - - - - - - - D - - -   - - - A A - - - - - - - - A - - -   - - A A - - - - - - - - - A - - -   - - A A - - - - - - - A A A - - -   - - A A - - - - - - - A A - - - -   - - A A - - - - - - - - A - - - -   - - A - - - - - - - - - A A - - -   - - A - - - - - - - - - A A - - -   - - A - - - - - - - - - A A - - -   - A - - - - - - - - - - - A A - -   - A - - - - - - - - - - - - A - -   - A - - - - - - - - - - - - A - -   A - - - - - - - - - - - - - A - -   A - - - - - - - - - - - - - A - -   A - - - - - - - - - - - - - A - -   A - - - - - - - - - - - - - A - -   A - - - - - - - - - - - - A - - -   - A - - - - - - - - - - - A - - -   - A - - - - - - - - - - A - - - -   - - A - - - - - - - - - A - - - -   - - A - - - - - - - - A - - - - -   - - - A - - - - - A A - - - - - -   - - - - A A - - A - - - - - - - -   - - - - - - A A - - - - - - - - -   - - - - - - - - - - - - - - - - -   
- - - - - C N - - - - N C C - - -   - - - - - C C - - - - C C - - - -   - - - - - G C - - - - C C - - - -   - - - - - AdAdC - - - C C - - - -   - - - - - G G C C - C G G - - - -   - - - - - - V C C V V C C - - - -   - - - - - D D D D D D C C - - - -   - - - - - A A A A A A AmC - - - -   - - - - A A A A A A A A A - - - -   - - - - A A A A A A A - - - - - -   - - - - A A A A A A A - - - - - -   - - - - A A - - - A A A - - - - -   - - - A - - - - - A A A - - - - -   - - - A - - - - - - A A - - - - -   - - A - - - - - - - A A - - - - -   - - A - - - - - - - - A A - - - -   - A - - - - - - - - - A A A - - -   - A - - - - - - - - - - A A - - -   - A - - - - - - - - - - A A - - -   - A - - - - - - - - - - A A - - -   - A - - - - - - - - - - A A - - -   - A - - - - - - - - - - A A - - -   - A - - - - - - - - - - A - - - -   - A - - - - - - - - - - A - - - -   - A - - - - - - - - - - A - - - -   - - A - - - - - - - - A - - - - -   - - - A - - - - - - A A - - - - -   - - - A - - - - - A A - - - - - -   - - - - A A A A A - - - - - - - -   - - - - - - - - - - - - - - - - -   - - - - - - - - - - - - - - - - -   
- - - - - - - C C C C - - - - - -   - - - - - - - C C C C - - - - - -   - - - - - - - C C C C - - - - - -   - - - - - - - - C C C - - - - - -   - - - - - - - - - C - - - - - - -   - - - - - - - - - - - - - - - - -   - - - - - - - - - - - - - - - - -   - - - - - - - - - - - - - - - - -   - - - - - - - - - - - - - - - - -   - - - - - - - - - - - - - - - - -   - - - - - - - - - - - - - - - - -   - - - - - - A A A - - - - - - - -   - - - - A A A A A A A - - - - - -   - - - - A A A A A A A - - - - - -   - - - A A A A A A A A - - - - - -   - - - A A A - - - - A A - - - - -   - - A A A - - - - - - A - - - - -   - - A A - - - - - - - A - - - - -   - - A - - - - - - - - - A - - - -   - A A - - - - - - - - - A - - - -   - A - - - - - - - - - - A - - - -   - A - - - - - - - - - - A - - - -   - - A - - - - - - - - - A - - - -   - - A - - - - - - - - - A - - - -   - - A - - - - - - - - - A - - - -   - - A - - - - - - - - A - - - - -   - - - A - - - - - - A - - - - - -   - - - - A - - - - A - - - - - - -   - - - - - A A A A - - - - - - - -   - - - - - - - - - - - - - - - - -   - - - - - - - - - - - - - - - - -   
- - - - - - - - - - - - - - - - -   - - - - - - - - - - - - - - - - -   - - - - - - - - - - - - - - - - -   - - - - - - - - - - - - - - - - -   - - - - - - - - - - - - - - - - -   - - - - - - - - - - - - - - - - -   - - - - - - - - - - - - - - - - -   - - - - - - - - - - - - - - - - -   - - - - - - - - - - - - - - - - -   - - - - - - - - - - - - - - - - -   - - - - - - - - - - - - - - - - -   - - - - - - - - - - - - - - - - -   - - - - - - - - - - - - - - - - -   - - - - - - - - - - - - - - - - -   - - - - - - - - - - - - - - - - -   - - - - - - B B B B - - - - - - -   - - - - - B - - - - B - - - - - -   - - - - B - - - - - - B - - - - -   - - - B - - - - - - - B - - - - -   - - - B - - - - - - - B B - - - -   - - B B - - - - - - - - B - - - -   - - B - - - - - - - - - B - - - -   - - B - - - - - - - - - B - - - -   - - B B - - - - - - - - B - - - -   - - - B - - - - - - - B - - - - -   - - - B B - - - - - B B - - - - -   - - - - B B - - B B B - - - - - -   - - - - - B B B B - - - - - - - -   - - - - - - - - - - - - - - - - -   - - - - - - - - - - - - - - - - -   - - - - - - - - - - - - - - - - -   
