model
size = 24 31 17, scale = 0.05, origin = -y
material 
  colors = A:#100 B:#E00 C:#C03 D:#111 E:#222 F:#BBB G:#933 H:#B00 I:#C33 J:#633 K:#963 L:#696 M:#D00 N:#C66 O:#500 P:#C96 Q:#363 R:#C00 S:#A00 T:#396 U:#993 V:#333 W:#F03 X:#C36 Y:#09F Z:#C63 Aa:#CC6 Ab:#330 Ac:#800 Ad:#936 Ae:#400 Af:#903 Ag:#09C Ah:#099 Ai:#066 Aj:#366 Ak:#069 Al:#900 Am:#555
voxels
- - - - - - - - - - - - - - - - - - - - - - - -   - - - - - - - - - - - - - - - - - - - - - - - -   - - - - - - - - - - - - - - - - - - - - - - - -   - - - - - - - - - - - - - - - - - - - - - - - -   - - - - - - - - - - - - - - - - - - - - - - - -   - - - - - - - - - - - - - - - - - - - - - - - -   - - - - - - - A A A A A A A A - - - - - - - - -   - - - - - - - A A A A A A A A A - - - - - - - -   - - - - - - A A A A A A A A A A - - - - - - - -   - - - - - - A A A A A A A A A A - - - - - - - -   - - - - - - A A A A A A A A A A - - - - - - - -   - - - - - - A A A A A A A A A A - - - - - - - -   - - - - - - A A A A A A A A A A - - - - - - - -   - - - - - A A A A A A A A A A A A A A - - - - -   - - - - - A A F F A A A A F F F A A A - - - - -   - - - - - A A F F A A A A A A F F A A A - - - -   - - - - A A A F F A A A A A A F F A A A - - - -   - - - - A A A F F A A A A A F F A A A A - - - -   - - - A A A F F F A A A A A A F F A A A A - - -   - - - A A A A A F A A A A F F F A A A A A - - -   - - - A A A A A A A A A A A A A A A A A A - - -   - - - A A A A A A A A A A A A A A A A A A - - -   - - - A A A A A A A A A A A A A A A A A A - - -   - - - - A A A A - - - - - - - - A A A A - - - -   - - - - - - - - - - - - - - - - - - - - - - - -   - - - - - - - - - - - - - - - - - - - - - - - -   - - - - - - - - - - - - - - - - - - - - - - - -   - - - - - - - - - - - - - - - - - - - - - - - -   - - - - - - - - - - - - - - - - - - - - - - - -   - - - - - - - - - - - - - - - - - - - - - - - -   - - - - - - - - - - - - - - - - - - - - - - - -   
- - - - - - B M G B AdM G M G R R - - - - - - -   - - - - - - - M E I D E D N J R - - - - - - - -   - - - - - - - - - - - - - - - - - - - - - - - -   - - - - - - - - - - - - - - - - - - - - - - - -   - - - - - - - - - - - - - - - - - - - - - - - -   - - - - - - - - - - A A - - - - - - - - - - - -   - - - - - - A A A A - - A A A A A - - - - - - -   - - - - - - A - - - - - - - - - A - - - - - - -   - - - - - A - - - - - - - - - - A A A A - - - -   - - - - - A - - - - - - - - - - A A A A - - - -   - - - - - A - - - - - - - - - - A A A A - - - -   - - - - A A - - - - - - - - - - A A A A - - - -   - - - - A A - - - - - - - - - - A A A A - - - -   - - - - A - - - - - - - - - - - A - - A - - - -   - - - - A - - - - - - - - - - - - - - A - - - -   - - - A A - - - - - - - - - - - - - - - A - - -   - - A A - - - - - - - - - - - - - - - - A - - -   - - A A - - - - - - - - - - - - - - - - A A - -   - - A - - - - - - - - - - - - - - - - - - A A -   - A A - - - - - - - - - - - - - - - - - - A A B   - A A - - - - - - - - - - - - - - - - - - A A B   - A A - - - - - - - - - - - - - - - - - - A A B   - - A - - - - - - - - - - - - - - - - - - A A B   - - A A - - - - A A A A A A A A - - - - A A A B   - - A A A A A A A A A A A A A A A A A A A A A -   - - - - A A A A A A A A A A A A A A A - - - - -   - - - - - - - - - - - - - - - - - - - - - - - -   - - - - - - - - - - - - - - - - - - - - - - - -   - - - - - - - - - - - - - - - - - - - - - - - -   - - - - - - - - - - - - - - - - - - - - - - - -   - - - - - - - - - - - - - - - - - - - - - - - -   
- - - - - W - - - - - - - - - - - S H - - - - -   - - - - - X I - - - - - - - - - I H I - - - - -   - - - - - G G I E D D D D E E I J G H - - - - -   - - - - - E J E A A A A A D D AeE G - - - - - -   - - - - - A A A A A A A A A A A A - - - - - - -   - - - - - - A A A A - - A A A A - - - - - - - -   - - - - - A - - - - - - - - - - A D A A - - - -   - - - - - A - - - - - - - - - - - A A A A - - -   - - - A A - - - - - - - - - - - - - - - A - - -   - - - A A - - - - - - - - - - - - - - - A - - -   - - - A A - - - - - - - - - - - - - - - A - - -   - - - A - - - - - - - - - - - - - - - - A - - -   - - - A - - - - - - - - - - - - - - - - A - - -   - - - A - - - - - - - - - - - - - - - - A - - -   - - A A - - - - - - - - - - - - - - - - A - - -   - - A - - - - - - - - - - - - - - - - - - A A -   - A - - - - - - - - - - - - - - - - - - - A A -   - A - - - - - - - - - - - - - - - - - - - - A B   - A - - - - - - - - - - - - - - - - - - - - - B   - A - - - - - - - - - - - - - - - - - - - - - B   B - - - - - - - - - - - - - - - - - - - - - - -   B - - - - - - - - - - - - - - - - - - - - - - -   B A - - - - - - - - - - - - - - - - - - - - - -   B A - - - - - - - - - - - - - - - - - - - - - -   - A - - - - - - - - - - - - - - - - - - - - - B   - A A A - - - - - - - - - - - - - - - A A A A B   - - - A A A A A A A A A A A A A A A A A A - - -   - - - - - - A A A A A A A A A A A A - - - - - -   - - - - - - - - - - - - - - - - - - - - - - - -   - - - - - - - - - - - - - - - - - - - - - - - -   - - - - - - - - - - - - - - - - - - - - - - - -   
- - - - B - - - - - - - - - - - - - - M - - - -   - - - - B - - - - - - - - - - - - - - R - - - -   - - - - I - - - - - - - - - - - - - - I - - - -   - - - - I - - - - - - - - - - - - - O J - - - -   - - - - A - - - - - - - - - - - - E O - - - - -   - - - - A A - - - - - - - - - - A D E - - - - -   - - - - A - - - - - - - - - - - - - - A D - - -   - - - A A - - - - - - - - - - - - - - - A - - -   - - - A - - - - - - - - - - - - - - - - A - - -   - - - A - - - - - - - - - - - - - - - - A - - -   - - - A - - - - - - - - - - - - - - - - A - - -   - - - A - - - - - - - - - - - - - - - - A - - -   - - A - - - - - - - - - - - - - - - - - A - A -   - - A - - - - - - - - - - - - - - - - - - A A -   - A - - - - - - - - - - - - - - - - - - - A A -   - A - - - - - - - - - - - - - - - - - - - - A -   - A - - - - - - - - - - - - - - - - - - - - - B   - A - - - - - - - - - - - - - - - - - - - - - -   B - - - - - - - - - - - - - - - - - - - - - - -   B - - - - - - - - - - - - - - - - - - - - - - -   B - - - - - - - - - - - - - - - - - - - - - - -   - - - - - - - - - - - - - - - - - - - - - - - -   - - - - - - - - - - - - - - - - - - - - - - - -   B - - - - - - - - - - - - - - - - - - - - - - -   B - - - - - - - - - - - - - - - - - - - - - - -   B - - - - - - - - - - - - - - - - - - - - - - B   - A A - - - - - - - - - - - - - - - - - - A A B   - - A A A A - - - - - - - - - - - - A A A A - -   - - - - - A A A A A A A A A A A A A A - - - - -   - - - - - - - - - B B B B B B - - - - - - - - -   - - - - - - - - - - - - - - - - - - - - - - - -   
- - - W - - - - - - - - - - - - - - - - S - - -   - - - C - - - - - - - - - - - - - - - - S - - -   - - - J - - - - - - - - - - - - - - - - H - - -   - - - E - - - - - - - - - - - - - - - - G - - -   - - - A - - - - - - - - - - - - - - - E - - - -   - - - A - - - - - - - - - - - - - - - D - - - -   - - - A - - - - - - - - - - - - - - - - D E - -   - - - A - - - - - - - - - - - - - - - - A - - -   - - A - - - - - - - - - - - - - - - - - A - - -   - - A - - - - - - - - - - - - - - - - - A - - -   - - A - - - - - - - - - - - - - - - - - - A - -   - - A - - - - - - - - - - - - - - - - - - A - -   - A - - - - - - - - - - - - - - - - - - - A A -   - A - - - - - - - - - - - - - - - - - - - - A -   - A - - - - - - - - - - - - - - - - - - - - A -   - A - - - - - - - - - - - - - - - - - - - - - B   - A - - - - - - - - - - - - - - - - - - - - - -   B - - - - - - - - - - - - - - - - - - - - - - -   - - - - - - - - - - - - - - - - - - - - - - - -   - - - - - - - - - - - - - - - - - - - - - - - -   - - - - - - - - - - - - - - - - - - - - - - - -   - - - - - - - - - - - - - - - - - - - - - - - -   - - - - - - - - - - - - - - - - - - - - - - - -   - - - - - - - - - - - - - - - - - - - - - - - -   - - - - - - - - - - - - - - - - - - - - - - - -   B - - - - - - - - - - - - - - - - - - - - - - -   B - - - - - - - - - - - - - - - - - - - - - - B   - A - - - - - - - - - - - - - - - - - - - A A -   - - A A A - - - - - - - - - - - - - - A A - - -   - - - - - A A A A B B B B B B A A A A - - - - -   - - - - - - - - B - - - - - - B - - - - - - - -   
- - C - - - - - - - - - - - - - - - - - - H - -   - - C - - - - - - - - - - - - - - - - - - H - -   - - G - - - - - - - - - - - - - - - - - - H - -   - - Af- - - - - - - - - - - - - - - - - G - - -   - - G - - - - - - - - - - - - - - - - - G - - -   - - - A - - - - - - - - - - - - - - - - E - - -   - - D - - - - - - - - - - - - - - - - - - E - -   - - A - - - - - - - - - - - - - - - - - - A - -   - - A - - - - - - - - - - - - - - - - - - A - -   - - A - - - - - - - - - - - - - - - - - - A - -   - - A - - - - - - - - - - - - - - - - - - A - -   - - A - - - - - - - - - - - - - - - - - - A - -   - A - - - - - - - - - - - - - - - - - - - - A -   - A - - - - - - - - - - - - - - - - - - - - A -   - A - - - - - - - - - - - - - - - - - - - - A -   - A - - - - - - - - - - - - - - - - - - - - - B   B - - - - - - - - - - - - - - - - - - - - - - -   - - - - - - - - - - - - - - - - - - - - - - - -   - - - - - - - - - - - - - - - - - - - - - - - -   - - - - - - - - - - - - - - - - - - - - - - - -   - - - - - - - - - - - - - - - - - - - - - - - -   - - - - - - - - - - - - - - - - - - - - - - - -   - - - - - - - - - - - - - - - - - - - - - - - -   - - - - - - - - - - - - - - - - - - - - - - - -   - - - - - - - - - - - - - - - - - - - - - - - -   - - - - - - - - - - - - - - - - - - - - - - - -   B - - - - - - - - - - - - - - - - - - - - - - B   B - - - - - - - - - - - - - - - - - - - - - - B   - A A A - - - - - - - - - - - - A - - - A A A -   - - - - A A - - - - - - - - - - A - A A - - - -   - - - - - - B B - - - - - - - - B B - - - - - -   
- - M - - - - - - - - - - - - - - - - - - H - -   - - C - - - - - - - - - - - - - - - - - - C - -   - - C - - - - - - - - - - - - - - - - - - H - -   - - Af- - - - - - - - - - - - - - - - - - H - -   - - G - - - - - - - - - - - - - - - - - - H - -   - - V - - - - - - - - - - - - - - - - - - O - -   - - D - - - - - - - - - - - - - - - - - - E - -   - - A - - - - - - - - - - - - - - - - - - A - -   - - A - - - - - - - - - - - - - - - - - - A - -   - - A - - - - - - - - - - - - - - - - - - A - -   - - A - - - - - - - - - - - - - - - - - - A - -   - A - - - - - - - - - - - - - - - - - - - A - -   - A - - - - - - - - - - - - - - - - - - - - A -   - A - - - - - - - - - - - - - - - - - - - - A -   - A - - - - - - - - - - - - - - - - - - - - A -   B - - - - - - - - - - - - - - - - - - - - - - B   - - - - - - - - - - - - - - - - - - - - - - - -   - - - - - - - - - - - - - - - - - - - - - - - -   - - - - - - - - - - - - - - - - - - - - - - - -   - - - - - - - - - - - - - - - - - - - - - - - -   - - - - - - - - - - - - - - - - - - - - - - - -   - - - - - - - - - - - - - - - - - - - - - - - -   - - - - - - - - - - - - - - - - - - - - - - - -   - - - - - - - - - - - - - - - - - - - - - - - -   - - - - - - - - - - - - - - - - - - - - - - - -   - - - - - - - - - - - - - - - - - - - - - - - -   - - - - - - - - - - - - - - - - - - - - - - - -   B - - - - - - - - - - - - A - - A - - - - - - B   - A A - - - - - - - - - - - - - - A - - - A A -   - - - A A A - - - - - - - - - - - A A A A - - -   - - - - - - B B - - - - - - - - B B - - - - - -   
- C - - - - - - - - - - - - - - - - - - - H - -   - C - - - - - - - - - - - - - - - - - - - - C -   - C - - - - - - - - - - - - - - - - - - - C - -   - - C - - - - - - - - - - - - - - - - - - C - -   - - C - - - - - - - - - - - - - - - - - - C - -   - - C - - - - - - - - - - - - - - - - - - H - -   - - D - - - - - - - - - - - - - - - - - - E - -   - - A - - - - - - - - - - - - - - - - - - A - -   - - A - - - - - - - - - - - - - - - - - - A - -   - - A - - - - - - - - - - - - - - - - - - A - -   - - A - - - - - - - - - - - - - - - - - - A - -   - A - - - - - - - - - - - - - - - - - - - A - -   - A - - - - - - - - - - - - - - - - - - - - A -   - A - - - - - - - - - - - - - - - - - - - - A -   - A - - - - - - - - - - - - - - - - - - - - A -   B - - - - - - - - - - - - - - - - - - - - - - B   - - - - - - - - - - - - - - - - - - - - - - - -   - - - - - - - - - - - - - - - - - - - - - - - -   - - - - - - - - - - - - - - - - - - - - - - - -   - - - - - - - - - - - - - - - - - - - - - - - -   - - - - - - - - - - - - - - - - - - - - - - - -   - - - - - - - - - - - - - - - - - - - - - - - -   - - - - - - - - - - - - - - - - - - - - - - - -   - - - - - - - - - - - - - - - - - - - - - - - -   - - - - - - - - - - - - - - - - - - - - - - - -   - - - - - - - - - - - - - - - - - - - - - - - -   - - - - - - - - - - - - - - - - - - - - - - - -   B - - - - - - - - - - - - A - - - - - - - - - B   - A A - - - - - - - - - - - - - A - - - A A A -   - - - A A A - - - - - - - - - - A - A A - - - -   - - - - - - B B - - - - - - - - B B - - - - - -   
- C - - - - - - - - - - - - - - - - - - - - C -   - C - - - - - - - - - - - - - - - - - - - - C -   - C - - - - - - - - - - - - - - - - - - - C - -   - C - - - - - - - - - - - - - - - - - - - C - -   - - C - - - - - - - - - - - - - - - - - - O - -   - - C - - - - - - - - - - - - - - - - - - O - -   - - D - - - - - - - - - - - - - - - - - - E - -   - - A - - - - - - - - - - - - - - - - - - A - -   - - A - - - - - - - - - - - - - - - - - - A - -   - - A - - - - - - - - - - - - - - - - - - A - -   - - A - - - - - - - - - - - - - - - - - - A - -   - A - - - - - - - - - - - - - - - - - - - A - -   - A - - - - - - - - - - - - - - - - - - - - A -   - A - - - - - - - - - - - - - - - - - - - - A -   - A - - - - - - - - - - - - - - - - - - - - A -   B - - - - - - - - - - - - - - - - - - - - - A -   - - - - - - - - - - - - - - - - - - - - - - - B   - - - - - - - - - - - - - - - - - - - - - - - -   - - - - - - - - - - - - - - - - - - - - - - - -   - - - - - - - - - - - - - - - - - - - - - - - -   - - - - - - - - - - - - - - - - - - - - - - - -   - - - - - - - - - - - - - - - - - - - - - - - -   - - - - - - - - - - - - - - - - - - - - - - - -   - - - - - - - - - - - - - - - - - - - - - - - -   - - - - - - - - - - - - - - - - - - - - - - - -   - - - - - - - - - - - - - - - - - - - - - - - -   B - - - - - - - - - - - - - - - - - - - - - - B   B - - - - - - - - - - - - A - - - - - - - - - B   - A A A A - - - - - - - - - - - - - - A A A A -   - - - - - A A - - - - - - - - B - A A - - - - -   - - - - - - - B - - - - - - - - B - - - - - - -   
- C - - - - - - - - - - - - - - - - - - - - Al-   - C - - - - - - - - - - - - - - - - - - - - Ac-   - C - - - - - - - - - - - - - - - - - - - - C -   - C - - - - - - - - - - - - - - - - - - - C - -   - C - - - - - - - - - - - - - - - - - - - C - -   - - V - - - - - - - - - - - - - - - - - - O - -   - - D - - - - - - - - - - - - - - - - - - E - -   - - A - - - - - - - - - - - - - - - - - - A - -   - - A - - - - - - - - - - - - - - - - - - A - -   - - A - - - - - - - - - - - - - - - - - - A - -   - - A - - - - - - - - - - - - - - - - - - A - -   - - A - - - - - - - - - - - - - - - - - - A - -   - A A - - - - - - - - - - - - - - - - - - - A -   - A - - - - - - - - - - - - - - - - - - - - A -   - A - - - - - - - - - - - - - - - - - - - - A -   B - - - - - - - - - - - - - - - - - - - - - A -   - - - - - - - - - - - - - - - - - - - - - - A -   - - - - - - - - - - - - - - - - - - - - - - - B   - - - - - - - - - - - - - - - - - - - - - - - -   - - - - - - - - - - - - - - - - - - - - - - - -   - - - - - - - - - - - - - - - - - - - - - - - -   - - - - - - - - - - - - - - - - - - - - - - - -   - - - - - - - - - - - - - - - - - - - - - - - -   - - - - - - - - - - - - - - - - - - - - - - - -   - - - - - - - - - - - - - - - - - - - - - - - -   - - - - - - - - - - - - - - - - - - - - - - - B   B - - - - - - - - - - - - - - - - - - - - - - B   - A A A - - - - - - - - - A - - - - - - A A A -   - - - - A A - - - - - - - - - - - A A A - - - -   - - - - - - A A B - - - - - - B B - - - - - - -   - - - - - - - - - - - - - - - - - - - - - - - -   
- C - - - - - - - - - - - - - - - - - - - - Al-   - C - - - - - - - - - - - - - - - - - - - - Ac-   - C - - - - - - - - - - - - - - - - - - - - C -   - C - - - - - - - - - - - - - - - - - - - C - -   - - C - - - - - - - - - - - - - - - - - - H - -   - - V - - - - - - - - - - - - - - - - - - O - -   - - D - - - - - - - - - - - - - - - - - - E - -   - - A - - - - - - - - - - - - - - - - - - A - -   - - A - - - - - - - - - - - - - - - - - - A - -   - - A - - - - - - - - - - - - - - - - - - A - -   - - A - - - - - - - - - - - - - - - - - - A - -   - - A - - - - - - - - - - - - - - - - - - A - -   - A A - - - - - - - - - - - - - - - - - - A - -   - A A - - - - - - - - - - - - - - - - - - A - -   - A A - - - - - - - - - - - - - - - - - - A - -   - A - - - - - - - - - - - - - - - - - - - A - -   B - - - - - - - - - - - - - - - - - - - - - A -   - - - - - - - - - - - - - - - - - - - - - - A -   - - - - - - - - - - - - - - - - - - - - - - - B   - - - - - - - - - - - - - - - - - - - - - - - B   - - - - - - - - - - - - - - - - - - - - - - - B   - - - - - - - - - - - - - - - - - - - - - - - -   - - - - - - - - - - - - - - - - - - - - - - - -   - - - - - - - - - - - - - - - - - - - - - - - B   - - - - - - - - - - - - - - - - - - - - - - - B   B - - - - - - - - - - - - - - - - - - - - - - B   B A A - - - - - - - - - - - - - - - - - - A A -   - - A A A A - - - - - - - A - - - - A A A - - -   - - - - - - A A B - - - - - - B A A - - - - - -   - - - - - - - - - - - - - - - - - - - - - - - -   - - - - - - - - - - - - - - - - - - - - - - - -   
- - M - - - - - - - - - - - - - - - - - - H - -   - - C - - - - - - - - - - - - - - - - - - - Ac-   - - C - - - - - - - - - - - - - - - - - - I - -   - - C - - - - - - - - - - - - - - - - - - H - -   - - G - - - - - - - - - - - - - - - - - - H - -   - - C - - - - - - - - - - - - - - - - - - O - -   - - C - - - - - - - - - - - - - - - - - - E - -   - - Am- - - - - - - - - - - - - - - - - - A - -   - - A - - - - - - - - - - - - - - - - - A - - -   - - - A - - - - - - - - - - - - - - - - A - - -   - - - A - - - - - - - - - - - - - - - - - A - -   - - A - - - - - - - - - - - - - - - - - - A - -   - - A - - - - - - - - - - - - - - - - - A - - -   - - A - - - - - - - - - - - - - - - - - - A - -   - - A - - - - - - - - - - - - - - - - - - A - -   - A A - - - - - - - - - - - - - - - - - - A - -   - A A - - - - - - - - - - - - - - - - - - A - -   B A - - - - - - - - - - - - - - - - - - - - A -   B - - - - - - - - - - - - - - - - - - - - - A -   B - - - - - - - - - - - - - - - - - - - - - A -   - - - - - - - - - - - - - - - - - - - - - - - B   - - - - - - - - - - - - - - - - - - - - - - - B   - - - - - - - - - - - - - - - - - - - - - - A B   - - - - - - - - - - - - - - - - - - - - - - A B   B - - - - - - - - - - - - - - - - - - - - A A -   B A A - - - - - - - - - - - - - - - - - A A A -   - - A A A A - - - - - - - - - - - - A A A - - -   - - - - - - A A A - - - - A - - A A - - - - - -   - - - - - - - - - B - - - - B B - - - - - - - -   - - - - - - - - - - - - - - - - - - - - - - - -   - - - - - - - - - - - - - - - - - - - - - - - -   
- - C - - - - - - - - - - - - - - - - - - H - -   - - C - - - - - - - - - - - - - - - - - - H - -   - - C - - - - - - - - - - - - - - - - - - H - -   - - C - - - - - - - - - - - - - - - - - - C - -   - - G - - - - - - - - - - - - - - - - - - O - -   - - C - - - - - - - - - - - - - - - - - - O - -   - - C - - - - - - - - - - - - - - - - - - E - -   - - C - - - - - - - - - - - - - - - - - A - - -   - - A - - - - - - - - - - - - - - - - - A - - -   - - - A - - - - - - - - - - - - - - - - A - - -   - - - A - - - - - - - - - - - - - - - - A - - -   - - - A - - - - - - - - - - - - - - - - A - - -   - - - A - - - - - - - - - - - - - - - - A - - -   - - - A - - - - - - - - - - - - - - - - A - - -   - - - A - - - - - - - - - - - - - - - - A - - -   - - A - - - - - - - - - - - - - - - - - - A - -   - - A - - - - - - - - - - - - - - - - - - A - -   - - A - - - - - - - - - - - - - - - - - - A - -   - A A - - - - - - - - - - - - - - - - - - A - -   B A A - - - - - - - - - - - - - - - - - - - A -   B A A - - - - - - - - - - - - - - - - - - - A -   B A A - - - - - - - - - - - - - - - - - - - A -   B A A - - - - - - - - - - - - - - - - - - A - -   B A A - - - - - - - - - - - - - - - - - A A - -   - A A A - - - - - - - - - - - - - - - - A - - -   - - - A A A - - - - - - - - - - - - A A - - - -   - - - - - A A A - - - - - - - - A A - - - - - -   - - - - - - - - A B B B B B B A - - - - - - - -   - - - - - - - - - - - - - - - - - - - - - - - -   - - - - - - - - - - - - - - - - - - - - - - - -   - - - - - - - - - - - - - - - - - - - - - - - -   
- - C - - - - - - - - - - - - - - - - - - H - -   - - - C - - - - - - - - - - - - - - - - - H - -   - - - J - - - - - - - - - - - - - - - - H - - -   - - - E - - - - - - - - - - - - - - - - G - - -   - - - D - - - - - - - - - - - - - - - - G - - -   - - - D - - - - - - - - - - - - - - - - E - - -   - - - D - - - - - - - - - - - - - - - - D - - -   - - - A - - - - - - - - - - - - - - - - A - - -   - - - A - - - - - - - - - - - - - - - A - - - -   - - - A - - - - - - - - - - - - - - - A - - - -   - - - - A - - - - - - - - - - - - - - - A - - -   - - - - A - - - - - - - - - - - - - - - A - - -   - - - A - - - - - - - - - - - - - - - - A - - -   - - - A - - - - - - - - - - - - - - - A - - - -   - - - A - - - - - - - - - - - - - - - - A - - -   - - - A - - - - - - - - - - - - - - - - A - - -   - - A - - - - - - - - - - - - - - - - - - A - -   - - A - - - - - - - - - - - - - - - - - - A - -   - - A - - - - - - - - - - - - - - - - - - A - -   - - A - - - - - - - - - - - - - - - - - - A - -   - - A - - - - - - - - - - - - - - - - - - A - -   - - A - - - - - - - - - - - - - - - - - - A - -   - - - A - - - - - - - - - - - - - - - - A - - -   - - - A A - - - - - - - - - - - - - - A - - - -   - - - - A A A - - - - - - - - - - A A A - - - -   - - - - - - A A A A - - - - A A A A - - - - - -   - - - - - - - - A A AkY Y AkA A - - - - - - - -   - - - - - - - - - - - - - - - - - - - - - - - -   - - - - - - - - - - - - - - - - - - - - - - - -   - - - - - - - - - - - - - - - - - - - - - - - -   - - - - - - - - - - - - - - - - - - - - - - - -   
- - - W B W - - - - - - - - - - - - H M S - - -   - - - - B X - - - - - - - - - - - - - R S - - -   - - - - I G G - - - - - - - - - - - J I - - - -   - - - - I E - - - - - - - - - - - - - J - - - -   - - - - J - - - - - - - - - - - - - - E - - - -   - - - - D - - - - - - - - - - - - - - D - - - -   - - - - D - - - - - - - - - - - - - - A - - - -   - - - - A - - - - - - - - - - - - - - A - - - -   - - - - A - - - - - - - - - - - - - - A - - - -   - - - - A - - - - - - - - - - - - - - A - - - -   - - - - A - - - - - - - - - - - - - - A - - - -   - - - - A - - - - - - - - - - - - - - A - - - -   - - - - A - - - - - - - - - - - - - - A - - - -   - - - - A - - - - - - - - - - - - - - A - - - -   - - - - A - - - - - - - - - - - - - - A - - - -   - - - A - - - - - - - - - - - - - - - A - - - -   - - - A - - - - - - - - - - - - - - - - A - - -   - - - A - - - - - - - - - - - - - - - - A - - -   - - - A - - - - - - - - - - - - - - - - A - - -   - - - A - - - - - - - - - - - - - - - - A - - -   - - - A - - - - - - - - - - - - - - - - A - - -   - - - A A - - - - - - - - - - - - - - A A - - -   - - - - A A - - - - - - - - - - - - A A - - - -   - - - - - A A A A A A A A A A A A A A - - - - -   - - - - - - - A A A AiAgAgAiA A A - - - - - - -   - - - - - - - - - - AhY Y Ah- - - - - - - - - -   - - - - - - - - - - - - - - - - - - - - - - - -   - - - - - - - - - - - - - - - - - - - - - - - -   - - - - - - - - - - - - - - - - - - - - - - - -   - - - - - - - - - - - - - - - - - - - - - - - -   - - - - - - - - - - - - - - - - - - - - - - - -   
- - - - - - B M G - - - - - - R R S - - - - - -   - - - - - - I M E - - - - - - - I H I - - - - -   - - - - - - - I E D - - - - E I J G - - - - - -   - - - - - - J E D - - - - - - - E G O - - - - -   - - - - - D D D - - - - - - - - - E O - - - - -   - - - - - D A A - - - - - - - - - D E - - - - -   - - - - - D - - - - - - - - - - - D A - - - - -   - - - - - A - - - - - - - - - - - A A - - - - -   - - - - A A - - - - - - - - - - - - A - - - - -   - - - - - A - - - - - - - - - - - - A - - - - -   - - - - - K - - - - - - - - - - - - K - - - - -   - - - - - K - - - - - - - - - - - - K - - - - -   - - - - - E - - - - - - - - - - - - E - - - - -   - - - - - A - - - - - - - - - - - - A - - - - -   - - - - - A - - - - - - - - - - - - A - - - - -   - - - - A A - - - - - - - - - - - - K - - - - -   - - - - A - - - - - - - - - - - - - K A - - - -   - - - - A - - - - - - - - - - - - - - A - - - -   - - - - A - - - - - - - - - - - - - - A - - - -   - - - - A - - - - - - - - - - - - - D A - - - -   - - - - A Q - - - - - - - - - - - L Q A - - - -   - - - - - Q L L T A Q L L Q A T L L Q - - - - -   - - - - - - Q Q D A A Q Q A A D Q Q - - - - - -   - - - - - - - - - - - - - - - - - - - - - - - -   - - - - - - - - - - - - - - - - - - - - - - - -   - - - - - - - - - - - - - - - - - - - - - - - -   - - - - - - - - - - - - - - - - - - - - - - - -   - - - - - - - - - - - - - - - - - - - - - - - -   - - - - - - - - - - - - - - - - - - - - - - - -   - - - - - - - - - - - - - - - - - - - - - - - -   - - - - - - - - - - - - - - - - - - - - - - - -   
- - - - - - - - - B AdM G M G - - - - - - - - -   - - - - - - - - - I D E D N J R - - - - - - - -   - - - - - - - - - - D D D E - - - - - - - - - -   - - - - - - - - - D D D D D D Ae- - - - - - - -   - - - - - - - - D D A A A A D A D - - - - - - -   - - - - - - - - A A J N N J A A A - - - - - - -   - - - - - - A A A A G N N G A A A - - - - - - -   - - - - - - A A A A J X X J A A A - - - - - - -   - - - - - - A A A A A A A A A A A A - - - - - -   - - - - - - K K E A A K K A A AbK K - - - - - -   - - - - - - P P Z A K P P K A Z P P - - - - - -   - - - - - - P P N A K P P K A N P P - - - - - -   - - - - - - Z N J A E N N E A J N Z - - - - - -   - - - - - - A A A A A A A A A A A A - - - - - -   - - - - - - A A A A A A A A A AbU U - - - - - -   - - - - - - A A A A A A A A A U AaAa- - - - - -   - - - - - A A A A A A A A A A U AaAa- - - - - -   - - - - - A A A A A A A A A A AbU U A - - - - -   - - - - - A A A A A A A A A A A A A A - - - - -   - - - - - D T L V A E T T E A V L T - - - - - -   - - - - - - L L L A AjL L AjA L L - - - - - - -   - - - - - - - - - - - - - - - - - - - - - - - -   - - - - - - - - - - - - - - - - - - - - - - - -   - - - - - - - - - - - - - - - - - - - - - - - -   - - - - - - - - - - - - - - - - - - - - - - - -   - - - - - - - - - - - - - - - - - - - - - - - -   - - - - - - - - - - - - - - - - - - - - - - - -   - - - - - - - - - - - - - - - - - - - - - - - -   - - - - - - - - - - - - - - - - - - - - - - - -   - - - - - - - - - - - - - - - - - - - - - - - -   - - - - - - - - - - - - - - - - - - - - - - - -   
