model
size = 22 19 31, scale = 0.05, origin = -y
material 
  colors = A:#EEE B:#303 C:#96C
voxels
---BBBBBBBBBBB-------- ---AAAAAAAAAAA-------- ----AAAAAAAAAA-------- ----AAAAAAAAAA-------- -----AAAAAAAAA-------- ----------AAA--------- ---------------------- ---------------------- ---------------------- ---------------------- ---------------------- ---------------------- ---------------------- ---------------------- ---------------------- ---------------------- ---------------------- ---------------------- ---------------------- 
--BAA--------ABB------ --AAA--------AA------- ---AA--------AA------- ---AAA-------AA------- ---AAAAAAAA-AAA------- ---AAAAAAAAAAAA------- ----AAAAAAAAAA-------- ----AAAAAAAAAA-------- -----AAAAAAAAA-------- ----------AAA--------- ---------------------- ---------------------- ---------------------- ---------------------- ---------------------- ---------------------- ---------------------- ---------------------- ---------------------- 
-BAA----------AAB----- -AAA----------AAA----- --AA----------AA------ --AA----------AA------ --AA----------AA------ --AAA--------AAA------ ---AA--------AA------- ---AAA-------AA------- ----AAAAAAA-AAA------- ----AAAAAAAAAAA------- ----AAAAAAAAAA-------- -----AAAAAAAAA-------- -----AAAAAAAAA-------- ------AAAAAAAA-------- ---------------------- ---------------------- ----CCCCCCCCCC-------- ----BBBBBBBBBB-------- ----BBBBBBBBBB-------- 
-BA-------------AB---- -AA------------AA----- -AA------------AA----- -AA------------AA----- -AA------------AA----- --AA----------AAA----- --AA----------AAA----- --AAA---------AA------ ---AA---------AA------ ---AA--------AAA------ ---AAA-------AAA------ ---AAA-------AA------- ----AAA------AA------- ----AAAAAAAAAAA------- ----AAAAAAAAAAA------- ----AAAAAAAAAA-------- ---CAAAAAAAAAAC------- ---BBBBBBBBBBBBB------ ---BBBBBBBBBBBBB------ 
BA--------------AB---- AA--------------AA---- AA--------------AA---- -A--------------AA---- -AA-------------AA---- -AA-------------AA---- -AA------------AA----- -AAA-----------AA----- --AA-----------AA----- --AA-----------AA----- --AA----------AAA----- --AAA---------AA------ --AAA---------AA------ --AAA---------AA------ ---AA--------AAA------ ---AAA-------AAA------ --CAAAAAAAAAAAAC------ --BBBBBBBBBBBBBBB----- --BBBBBBBBBBBBBBB----- 
B----------------B---- A----------------A---- AA---------------A---- AA---------------A---- -A---------------A---- -A--------------AA---- -A--------------AA---- -AA-------------AA---- -AA-------------AA---- -AA-------------AA---- -AA------------AAA---- -AA------------AA----- -AA------------AA----- -AAA-----------AA----- -AAA-----------AA----- --AA----------AAA----- -CAAAAA----AAAAC------ -BBBBBBB---BBBBBB----- -BBBBBBB---BBBBBB----- 
B----------------B---- A----------------A---- A----------------A---- AA---------------A---- -A---------------A---- -A---------------A---- -A---------------A---- -A---------------A---- -A---------------A---- AA---------------A---- AA--------------AA---- AA--------------AA---- AA--------------AA---- AA--------------AA---- AAA-------------AA---- -AA------------AAA---- CAAAAA-------AAAC----- BBBBBB-------BBBBB---- BBBBBB-------BBBBB---- 
B----------------B---- A----------------A---- AA---------------A---- AA---------------A---- -A---------------A---- -A---------------A---- -A---------------A---- -A---------------A---- AA---------------A---- AA---------------A---- A----------------A---- A----------------A---- A----------------A---- A----------------A---- AA---------------A---- AA--------------AA---- CAAAA---------AAAC---- BBBBB---------BBBBB--- BBBBB---------BBBBB--- 
BA---------------B---- AA---------------A---- AA---------------A---- -A---------------A---- -A---------------A---- -A---------------A---- -A---------------A---- -A---------------A---- AA---------------A---- A----------------A---- A----------------A---- A----------------A---- A----------------A---- A----------------A---- A-----------------A--- A----------------AA--- CAAA-----------AAC---- BBBB-----------BBBB--- BBBB-----------BBBB--- 
-B--------------AB---- -A--------------AA---- -A--------------AA---- -A---------------A---- -A---------------A---- -A---------------A---- -A---------------A---- -A---------------A---- AA---------------A---- A----------------A---- A----------------A---- A----------------AA--- A-----------------A--- A-----------------A--- A-----------------A--- A-----------------A--- CAA-------------AC---- BBB-------------BBB--- BBB-------------BBB--- 
-BA------------AB----- -AA-------------A----- -AA-------------AA---- -A--------------AA---- -A--------------AA---- -A---------------A---- -A---------------A---- -A---------------A---- AA---------------A---- A----------------A---- A----------------AA--- A----------------AA--- A-----------------A--- A-----------------A--- A-----------------A--- A-----------------A--- CA---------------AC--- BB---------------BBB-- BB---------------BBB-- 
--BA----------ABB----- --AA----------AAA----- -AAA-----------AA----- -AA------------AA----- -AA-------------AA---- -A--------------AA---- -A---------------A---- -A---------------A---- AA---------------A---- A----------------A---- A----------------AA--- A-----------------A--- A-----------------A--- A-----------------A--- A-----------------A--- A-----------------AA-- CA---------------AC--- BB---------------BBB-- BB---------------BBB-- 
---BA------AAAB------- ---AA--------AAA------ --AAA--------AAA------ --AA----------AAA----- -AA------------AA----- -AA-------------AA---- -A---------------A---- AA---------------A---- AA---------------A---- A----------------A---- A----------------AA--- A-----------------AA-- A-----------------A--- A-----------------A--- A-----------------AA-- A-----------------AA-- CA---------------AC--- BB---------------BBB-- BB---------------BBB-- 
----BBBBBBBBBB-------- ----AAAAAAAAAA-------- ---AAAAAAAAAAAA------- --AAAA------AAAA------ --AAA--------AAAA----- -AA------------AAA---- -A--------------AA---- -A---------------A---- AA---------------A---- A----------------A---- A----------------AA--- A-----------------A--- A-----------------AA-- A-----------------AAA- A-----------------AA-- A-----------------AA-- CA---------------AC--- BB---------------BBB-- BB---------------BBB-- 
---------------------- ---------------------- -----AAAAAAAA--------- ----AAAAAAAAAA-------- --AAAAAAAAAAAAAA------ -AAAAAA-------AAA----- -AAAA-----------AA---- -A---------------A---- AA---------------A---- A----------------A---- A----------------AA--- A-----------------A--- A-----------------A--- A-----------------AA-- A-----------------AAA- A-----------------AAA- CA---------------AAC-- BB---------------BBBB- BB---------------BBB-- 
---------------------- ---------------------- ---------------------- ---------------------- ------AAAAAAAAA------- ----AAAAAAAAAAAAA----- -AAAAAAAA------AAA---- -AAAA-----------AA---- AA---------------A---- A----------------AA--- A----------------AA--- A-----------------A--- A-----------------A--- A-----------------AA-- A-----------------AA-- A-----------------AAA- CA---------------AACC- BB---------------BBBBB BB---------------BBB-- 
---------------------- ---------------------- ---------------------- -----AAAAAAAA--------- ----AAAAAAAAAAAA------ --AAAAAAAAAAAAAAA----- -AAAAAA--------AAA---- -AAA------------AA---- AA---------------A---- A----------------AA--- A----------------AA--- A-----------------A--- A-----------------A--- A-----------------AA-- A-----------------AAA- A-----------------AA-- CA---------------AC--- BB---------------BBB-- BB---------------BBB-- 
-----BBBBBBBB--------- -----AAAAAAAA--------- ----AAAAAAAAAA-------- ---AAAAAAAAAAAA------- --AAAA------AAAAA----- -AAAA----------AA----- -AA-------------AA---- -A---------------A---- AA---------------A---- A----------------A---- A----------------AA--- A-----------------A--- A-----------------A--- A-----------------AAA- A-----------------AA-- A-----------------AA-- CA---------------AC--- BB---------------BBB-- BB---------------BBB-- 
---BAAAAAAAAABB------- ---AAAAAAAAAAAA------- --AAAA------AAAA------ --AAA--------AAAA----- -AAA----------AAA----- -AA-------------AA---- -A--------------AA---- AA---------------A---- AA---------------A---- A----------------A---- A----------------AA--- A-----------------A--- A-----------------A--- A-----------------AA-- A-----------------AA-- A-----------------AA-- CA---------------AC--- BB---------------BBB-- BB---------------BBB-- 
--BAA--------AAB------ --AAA---------AA------ --AA----------AAA----- -AA------------AA----- -AA-------------A----- -A--------------AA---- -A---------------A---- AA---------------A---- AA---------------A---- A----------------A---- A----------------AA--- A-----------------A--- A-----------------A--- A-----------------A--- A-----------------AA-- A-----------------AA-- CA---------------AC--- BB---------------BBB-- BB---------------BBB-- 
-BAA-----------AB----- -AAA-----------AA----- -AA------------AA----- -AA-------------AA---- -A--------------AA---- -A--------------AA---- -A---------------A---- -A---------------A---- AA---------------A---- A----------------A---- A----------------AA--- A----------------AA--- A-----------------A--- A-----------------A--- A-----------------A--- A-----------------A--- CA---------------AC--- BB---------------BBB-- BB---------------BBB-- 
-BA-------------AB---- -AA-------------AA---- -A--------------AA---- -A--------------AA---- -A---------------A---- -A---------------A---- -A---------------A---- -A---------------A---- AA---------------A---- A----------------A---- A----------------A---- A----------------AA--- A-----------------A--- A-----------------A--- A-----------------A--- A-----------------A--- CA--------------AC---- BB--------------BBB--- BB--------------BBB--- 
BA---------------B---- AA---------------A---- -A---------------A---- -A---------------A---- -A---------------A---- -A---------------A---- -A---------------A---- -A---------------A---- AA---------------A---- A----------------A---- A----------------A---- A----------------A---- A----------------A---- A----------------A---- A-----------------A--- A-----------------A--- CAA------------AAC---- BBB------------BBBB--- BBB------------BBBB--- 
BA---------------B---- AA---------------A---- AA---------------A---- -A---------------A---- -A---------------A---- -A---------------A---- -A---------------A---- -A---------------A---- AA---------------A---- AA---------------A---- A----------------A---- A----------------A---- A----------------A---- A----------------A---- A----------------A---- A----------------A---- CAAA----------AAAC---- BBBB----------BBBBB--- BBBB----------BBBBB--- 
B----------------B---- A----------------A---- AA---------------A---- AA---------------A---- -A---------------A---- -A---------------A---- -A---------------A---- -A---------------A---- -A---------------A---- AA---------------A---- AA---------------A---- AA---------------A---- AA---------------A---- AA--------------AA---- AA--------------AA---- AAA-------------AA---- CAAAA--------AAAC----- BBBBB--------BBBBB---- BBBBB--------BBBBB---- 
B----------------B---- A----------------A---- A----------------A---- AA---------------A---- -A---------------A---- -A---------------A---- -A---------------A---- -A--------------AA---- -A--------------AA---- -A--------------AA---- -AA-------------AA---- AAA-------------AA---- AAA------------AAA---- -AA------------AAA---- -AA------------AA----- -AAA-----------A------ -CAAAA------AAAC------ -BBBBB------BBBBB----- -BBBBB------BBBBB----- 
BA---------------B---- AA---------------A---- AA---------------A---- AA--------------AA---- -A--------------AA---- -A--------------AA---- -AA-------------AA---- -AA-------------AA---- -AA------------AA----- -AAA-----------AA----- -AAA-----------AA----- --AA-----------AA----- --AA----------AAA----- --AAA---------AA------ --AAA---------AA------ --AAA---------AA------ --CAAAAAAAAAAAC------- -BBBBBBBBBBBBBBB------ -BBBBBBBBBBBBBBB------ 
BA--------------AB---- AA--------------AA---- -A--------------AA---- -AA------------AAA---- -AA------------AA----- -AA------------AA----- -AAA-----------AA----- --AA----------AAA----- --AAA---------AAA----- --AAA---------AA------ ---AA---------AA------ ---AA---------AA------ ---AA--------AAA------ ---AAA-------AA------- ---AAA-------AA------- ----AAA-----AAA------- ---CCCCCCCCCCC-------- --BBBBBBBBBBBBB------- --BBBBBBBBBBBBB------- 
-BA------------AB----- -AA------------AA----- -AA------------AA----- -AAA----------AAA----- --AA----------AA------ --AA----------AA------ --AAA---------AA------ ---AA--------AAA------ ---AAA-------AA------- ----AA-------AA------- ----AAAA----AAA------- ----AAAAAAAAAAA------- ----AAAAAAAAAAA------- ----AAAAAAAAAA-------- -----AAAAAAAAA-------- -----AAAAAAAAA-------- ---------------------- ---BBBBBBBBBBB-------- ---BBBBBBBBBBB-------- 
--BA----------AB------ --AA----------AA------ --AA---------AAA------ --AAA--------AAA------ ---AA--------AA------- ---AAA-------AA------- ---AAAAAAAAAAAA------- ----AAAAAAAAAAA------- ----AAAAAAAAAA-------- -----AAAAAAAAA-------- -----AAAAAAAAA-------- -------AAAAAA--------- ---------------------- ---------------------- ---------------------- ---------------------- ---------------------- ---------------------- ---------------------- 
---BBBBBBBBBBBB------- ---AAAAAAAAAAAA------- ---AAAAAAAAAAAA------- ---AAAAAAAAAAA-------- ----AAAAAAAAAA-------- ----AAAAAAAAAA-------- -----AAAAAAAAA-------- -----------AA--------- ---------------------- ---------------------- ---------------------- ---------------------- ---------------------- ---------------------- ---------------------- ---------------------- ---------------------- ---------------------- ---------------------- 
