model
size = 32 28 20, scale = 0.05, origin = -y
material 
  colors = A:#FF9 B:#306 C:#EDED8E D:#000 E:#9E6D00 F:#EEE G:#06C
voxels
466-2(8B24-)7B26-6B27-4B569-2(A31-)CA29-3A30-DACD16-5B7-3D16-16B2D-5B14-18B19-12B2(21-11B)22-9B24-8B26-4B442-2A-2D26-3A-3D22-4DAC4D21-5DAC4D21-2(12D20-)12D-B8-12B11D3B6-14B8D4B14-7B2A5D4B16-6B5D5B17-7BD6B18-14B19-12B21-11B23-7B350-2D26-2A4D24-3AC4D24-2ACA4D20-5D2A5DA19-5D2C5DCA17-4DC4A4D2A17-3D4AC2A4DA17-2D7ACA3DA3B4-6B4-2D2CAC4ACA3D3B4-12B7AC2A3D3B7-10B7ACA3D3B13-4BA2C7AD3B15-5BC5ACD4B16-5B2A2C2D5B16-15B18-14B19-12B22-9B26-3B150-7AC24-CA2C3AC25-7AC2A22-AC2AC5ACA20-A2C4ACAC2A19-5A2C4AC2A18-AC5AC3A2C2A17-5AC2AC3A2C2A15-2D3AC7A2(CA)14-2D2A2C7AC3AF14-2DAC5AC7AC13-3DAC4A3(CA)C2AD12-4D12AC2A2B11-3D6A2C3AC2A2D2B3-9B2D10AC3A2D2B3-12BC8A3CA2D2B10-6B5AC3A2(CA)3B13-3BC3AC7A4B14-3B4ACA2C2AC4B14-5B6AC5B16-7B2A7B17-14B18-13B21-10B147-4AC3AC22-4AC2A2C3A20-3ACAC3AC5AC16-5A2(CA)C6AC15-11AC5A15-A2(C2A)3CA2C4A15-3ACA2C8ACA15-4A2CA3(C2A)C14-2D9AC4ACA13-3D2A2(C3A)2C4AF12-3DC4AC5A2C3A12-4D3(AC)9AD12-3D3A3CAC3A2C4A2B10-2D18A2B2-3B5-2D3(2AC)3AC3A2D2B2-10B2A2C3A3(C2A)D3B5-8B8AC4ACAD3B10-4B3ACAC4A2C2A3B13-3BC2A2C7AC3B13-4B5AC3A2C4B14-5BA2CA3CA4B16-6BA3D6B16-15B19-12B22-8B85-C6A24-AC2AC6A19-C3A2(C2A)C4A2C15-3AC3A2C2AC4A2C14-4ACAC6AC3AC14-A2C2AC6A2CACA2E13-4AC2A2CAC5A2C15-10AC6A14-12AC4AC13-3DAC2AC4ACAC2ACA13-2DA2CA3C2AC5ACAG11-3DC14ACAD11-3D2C4A3C2(AC)3ACA11-2D6AC9ACADB10-DC2AC6ACAC5AC2B10-DAC15ACD2B-8B-D6AC2ACA4CACAD2B3-9B8AC8AD2B9-4BC11A2C2A3B10-4B2A2(CA)C4A3C4B11-4B9AC3A3B13-4BAC5AC3A4B13-6BAC5AC4B15-7B4D5B18-13B20-11B25-3B56-2AC2A2C24-7A2CAC2A17-9AC5A2CA14-C6AC9ACA13-5A2C6AC3A2E13-4AC3A3C3A2C2AC13-2A2C5A3(CA)C3A13-2AC2A3C6AC4A13-A2C5A5C6A11-4D7ACAC3A2CAC11-3D7AC5A2(CA)F11-2D9AC3AC2A2CD11-2DACA2C3AC9AC11-D6AC3ACA2(C3A)B10-DC4AC2A2C4AC2ACACB10-D2ACA2C4AC2AC3ACACB-5B4-D7AC4A2(C2A)D2B2-9BACA4CAC4A2(C2A)2B7-5B5AC8ACAC3B10-3B3ACAC2A2C2AC3A3B11-3BC4ACAC2AC3A4B11-4B2(C4A)C2A3B13-5B4A2(C2A)4B14-5B5A2D5B16-7BD-6B19-12B22-7B54-AC2A3C24-2AC6AC5A15-CA3C3ACAC3AC4A13-9AC2A2(2CA)C13-2ACAC3AC8A2E13-C6A2(CA)5CACA13-AC2A2C7AC7A11-2ACAC2AC3AC7ACA11-AC12ACAC2AC10-3DACA2CAC4AC7A10-2D4AC3AC2ACA2C4AF10-D3(AC)2(5AC)AC10-2D3A4C6ACAC4A10-D15AC5AB9-D2(CA)2(C2A)C4AC2A2CAB9-DAC3A2C2A3C2ACA5CB-3B5-D4AC2ACAC3ACAC4ADB-9B7A2(C2A)C4ACA2B6-6B2(AC)2AC3A2(C2A)CA2B10-2B5ACA2C2AC3ACA3B11-2B2AC3ACAC3A3CA3B11-3B7AC6A3B13-4BCA3C6A4B14-4BAC7A4B16-5B6D4B18-13B21-9B53-7A24-2(2AC)6AC2A15-A3C2(3AC)AC2A2CA13-3AC5A2(C3A)CA13-C3AC2A2(CA)C3ACA2E13-2A2(2CA)CAC8A13-11AC5A3CA11-A2C8A2C7AC11-5AC6AC3ACAC2A9-2D7A2(C4A)CAC10-D4A2C3AC2AC8A10-D3C5AC2AC7ACD9-2D2ACAC4A3(C2A)CA10-DAC7AC4AC6ABD8-D5ACAC4A2C7ABD8-D2C5AC10A2CDB-2B6-D2AC7ACAC7ADB-8B-2C2(4AC)6ACADB6-6B2(2AC)9AC2A2B10-2B6AC2AC4A3CA2B11-2B5AC6A2CAC3B11-3B2AC11A4B12-3B2(5AC)D3B14-4BC6ACAD3B16-4B7D5B17-13B20-10B29-2B22-7A24-2(2AC)6AC2A15-6AC5ACAC2ACA13-AC2A2C13A13-4AC6A3C3A2E13-3C8AC2AC3AC13-11AC9A11-C9AC3AC6A11-3A2C6AC9A9-2D5AC2AC3AC4AC2A10-DAC2AC3AC2AC5AC3A10-DC9AC5AC3AD9-D2AC4ACAC5A2C2ACA2D8-DC4AC2A3C2(3AC)2AB9-D2(AC)7AC2ACAC3ADBD8-D4A2C4ACAC4AC2ADB9-D3C2AC9AC3ACDB-8B-D2C2AC10AC2ACDB6-5B3(C2A)C9A2B10-2B3AC14A2B11-2BC4A2(CA)C6A3B11-3B8AC4ACA3B12-3B3ACA2C5AD3B14-3B10AD4B14-5B7D-4B17-5B2D6B20-10B29-2B22-2A2C3A24-C6ACAC5A15-AC2AC3A2C3AC5A13-A4C2A2C2ACA2C4A13-2AC6A2CA2C3A2E13-14A4CA13-CAC6A2(CA)2(C3A)11-3A2C16A11-2AC7A2C3AC4A10-2D10A2CA2C5A10-2D2ACA2(C7A)10-D2(8AC)2A10-2D4A2C2AC8A2CA10-DA2C3AC6A2(CA)C2ACB9-D4A2C4AC2A3C3A2CB9-2DAC6AC2A2(CA)C2ACAB-2B6-2D4A2(2CA)C5AC2ADB-8B-D2(A2C)3AC2A3C4ADB6-6B6AC8A2CA2B10-2B2(2AC)AC5AC4A2B11-2B2AC2A2C6A2CA3B11-3B4ACAC7A4B12-3B2(A2C)3AC2A-3B14-4B9AD3B16-4B7D5B17-13B20-10B29-2B22-7A24-C5A2(C2A)C17-6AC4A2C4AC14-A2CAC6A2(C3A)13-C5AC2A2C2A2(CA)2E13-2A2C2ACAC4A2(2CA)13-5ACA2C2(AC)6A13-C7AC2A2C6A13-6A2(CA)C2ACAC3A11-4DC3A2(C2A)2CACA2C11-3D2(AC)3AC2AC7A11-2D2(3AC)6AC3AD11-2D12AC3AC2A11-D4ACAC13AB10-D2A2C2AC5AC7AB10-DAC4AC13AB-3B6-D3C8AC4A2C2DB-9BDAC7A4C4ACA2B7-5BAC5AC2AC4AC2A2B10-3B16A3B11-2B4ACAC3A5CA3B11-3BCAC2A2(CA)C2ACA3B13-4BCAC2AC5A4B14-4B6A3D4B16-5B3D2-5B18-13B21-9B53-2(2AC)A24-A2(C4A)19-7ACA2C4ACA15-2(2AC)6ACAC3A14-5AC5A3CAC2A14-C6ACA2C2AC3A2E13-CA2C4ACAC7A15-2A2CAC6A3C2A14-4AC2ACA2C7A13-3D9AC3AC2A13-2D6AC5AC4AF11-3DA3C3A2C2(2AC)2AD11-3D2AC3AC2AC6ACA11-2D5AC2ACAC7ADB10-D4A5C6A2C3AB10-DA2(C2A)C4A2C3ACDCB-6B3-D2(AC)2(3AC)5ACD2B2-9BD3A2C4A3C2AC2AD2B8-4B12ACAC2A3B10-3B2ACAC3AC7A3B11-3BC3A2C2AC4AC4B11-4BC3AC4ACAC4B13-5B3AC2ACACD4B14-6B6D5B16-7B-7B19-12B22-7B85-C3AC4A22-3A4C2A2CA20-10AC3ACA16-C5AC2AC7A15-5AC6A2C3A15-AC3AC11A15-2ACA2(C2A)CAC4A15-A2C3A2(C2A)2C3A14-2D4A2C8ACA13-3DC6ACA2C2AC2AG12-3D6AC5AC3AD11-4D2ACA2C9ACA11-3DC3ACAC7AC2ADB10-2D8A2CA3C4A2B10-2DAC3A2C9A2D2B-8B-2D2AC4A2C7A2D2B3-9BDAC5AC4ACACD3B9-4B14A2C3B11-3B3AC10A4B12-3B4AC7AD3B13-4B4A2C4AD4B14-5BA2C5D4B16-6B4D5B18-13B21-10B25-3B87-3AC4A24-5AC2A25-9AC22-11AC20-2(AC2AC)AC19-7AC6A18-6AC4AC2AC17-5AC3AC2A2(CA)15-2D2(C3A)C6A14-2D3AC2A2C4AC3AF13-2DC4A2(C2A)CA2CA13-3DC8AC3ACAD12-4D6ACAC7A2B10-3DA2C6AC4A2DA2B2-4B4-3DCAC2AC4A2(CA)3D2B2-10BDAC8AC3A2D3B6-7BD6AC4AC2AD3B11-3BAC4AC7A3B13-3B3AC4AC3AD3B13-4B2(CA)C3A2CD4B14-5B6A2D4B16-7B2D7B17-14B19-12B22-8B254-2D26-2A4D24-2(AC)4D24-2ACA4D20-5D2A5DA-2A16-5D2A5D3AF15-4D2CACA4D2ACA15-3DAC5A4D2AD15-2D2C2(AC)3A3DA3B14-2D2AC2A2C3A3D-2B3-9B2-D2(4AC)A3D-2B4-11BD10A3D3B10-6BD5AC3AC2D3B13-3BD2A2C3ACA2D4B14-4B2(2AC)3D4B15-5B7D5B16-16B17-14B19-12B21-10B344-2A-2D26-3A-3D22-4D2C4D21-5D2A4D21-2(12D20-)12D2(-B)5-7B4-13D-3B4-12B12D-3B7-10B3DCA6D4B13-5B10D3B15-5B2D2A4D4B16-6B5D5B17-14B18-14B19-12B22-9B407-A31-C31-2C29-2ACD29-2(AD)16-3B9-3D15-13B6D4-3B7-14B4D3-4B14-7B7D4B17-5B5D4B18-14B19-13B19-12B21-10B24-7B570-D17-5B9-D16-23B16-16B20-12B21-11B22-10B22-9B24-7B28-2B201-
