model
size = 17 30 32, scale = 0.05, origin = -y
material 
  colors = A:#111 B:#EEE C:#DDD
voxels
276-2(5A12-)5A469-8A2(9-2A5-A)3(9-8A)3(11-6A)13-4A349-9A5(8-A7-A)8-2(2A6-2A7-)2A6-2A9-2A4-A11-6A12-3A316-10A8(7-A8-A)8-A7-A8-2A6-A8-9A296-5A12-A4-6A8(6-A9-A)7-A8-2(A7-)A8-3A3-3A11-3A282-5A12-A4-7A4(5-A10-A)5-A9-A6-3(A10-A5-)A9-A7-A8-A7-A6-2A9-6A31-6A2(12-5A)2(13-4A)14-3A14-4A3(14-3A)49-2A10-7A9-9A4-4A-8A5(4-A11-A)4-A10-2A3(4-A11-A)4-A10-2A4-A10-A5-A7-3A7-7A26-5A6-2(2A4-6A5-)2(2A4-7A4-)2A4-8A3-2A4-8A4-3(A4-9A3-)A4-13A4-14A3-10A2-2A3-5A7-2A3-4A9-5(A3-A12-)4(2A2-A12-)A3-A12-A3-A11-A4-A10-A5-A7-3A7-A3-3A10-4A2(12-A)17(3-A12-A)2(3-A12-B)5(3-A12-A)3-A11-A4-A10-2A4-A7-3A7-A4-2A10-5A11-7(A12-A3-)10(A13-A2-)2(A13-B2-)A13-A2-A13-B2-A13-A2-A12-3(A2-A13-)A3-A11-A4-A7-4A5-A5-2A10-A3-A11-3(A12-A3-)13(A13-A2-)2(A13-B2-)3(A13-A2-)A13-B-A14-A-3(A13-A2-)A12-A3-A9-3A5-A6-2A8-A5-A9-2A12-A2-13(2A13-A-)2(2A13-B-)6(2A13-A-)A14-B-3(A13-A2-)A12-A3-A10-2A5-A8-A7-A6-2A7-2A12-A2-11(2A13-A-)2(2A13-B-)2A13-A2(-2A13-C)-2A13-A-2A13-C3(-2A13-A)-A14-B-A14-A-2(A13-A2-)A12-A3-A10-2A4-A9-A5-2A9-A6-2A12-A2-9(2A13-A-)2(2A13-B-)2(2A13-A-)2(2A13-C-)2A13-A-2A13-C-2A13-B-2A13-C2(-2A13-A)-A14-B-A14-A-2(A13-A2-)A12-A3-A10-2A3-A10-A5-A10-A6-2A12-A2-7(2A13-A-)2(2A13-B-)2(2A13-A-)3(2A13-C-)2A13-A-2A13-C3(-2A13-B)-2A13-C-2A13-A-A14-B-A14-A-2(A13-A2-)2(A12-A3-A10-2A3-A10-A5-A10-A6-2A12-A2-6(2A13-A-)2A13-B3(-2A13-A)3(-2A13-C)-2A13-A-2A13-C5(-2A13-B)-2A13-C-A14-B-3(A13-A2-))A12-A3-A10-2A3-A10-A5-A10-A6-2A12-A2-7(2A13-A-)2(2A13-B-)2(2A13-A-)3(2A13-C-)2A13-A-2A13-C3(-2A13-B)-2A13-C-2A13-A-A14-B-A14-A-2(A13-A2-)A12-A3-A10-2A3-A10-A5-A10-A6-2A12-A2-9(2A13-A-)2(2A13-B-)2(2A13-A-)2(2A13-C-)2A13-A-2A13-C-2A13-B-2A13-C2(-2A13-A)-A14-B-A14-A-2(A13-A2-)A12-A3-A10-2A3-A10-A5-A10-A6-2A12-A2-11(2A13-A-)2(2A13-B-)2(2A13-A-)2(2A13-C-2A13-A-)2(2A13-A-)A14-B-A14-A-2(A13-A2-)A12-A3-A10-2A4-A9-A5-2A9-A6-2A12-A2-13(2A13-A-)2(2A13-B-)5(2A13-A-)2A13-B-A14-B-3(A13-A2-)A12-A3-A10-2A5-A8-A7-A6-2A8-3(A12-A3-)13(A13-A2-)2(A13-B2-)3(A13-A2-)A13-B-A14-A-3(A13-A2-)A12-A3-A9-3A5-A6-2A8-A5-A10-7(A12-A3-)10(A13-A2-)2(A13-B2-)A13-A2(2-A13-B)2-A12-3(A2-A13-)A3-A11-A4-A7-4A5-A5-2A10-A3-A11-3(4A9-A3-)5A8-A3-6A7-6(A3-7A6-)A3-6A7-A3-5A8-2(A3-4A9-)4(A3-A12-)3(B3-A12-)3(A3-A12-)A3-A11-A4-A10-2A4-A7-3A7-A4-2A10-5A15-A2(7-2A)6-2A7-2A6-2A8-2A5-2A9-A5-2(2A10-A4-)3(2A10-2A3-)2A10-7A9-8A8-5A3-2(A7-A8-)A3-4A9-4(A3-A12-)4(2A2-A12-)A3-A12-A3-A11-A4-A10-A5-A7-3A7-A3-3A10-4A17-7A2(11-6A)2(12-5A)2(13-4A)3(14-3A)49-3A9-8A8-9A4-4A-8A9(4-A11-A)4-A10-2A4-A10-A5-A7-3A7-7A281-5A12-A4-7A8(5-A10-A)5-A9-A7-A8-A7-A6-2A9-6A281-5A12-A4-6A8(6-A9-A)7-A8-2(A7-)A8-3A3-3A11-3A299-10A8(7-A8-A)8-A7-A8-2A6-A8-9A313-9A5(8-A7-A)8-2(2A6-2A7-)2A6-2A9-2A4-A11-6A12-3A316-8A2(9-2A5-A)3(9-8A)3(11-6A)13-4A351-2(5A12-)5A195-
