model
size = 17 31 24, scale = 0.05, origin = -y
material 
  colors = A:#100 B:#E00 C:#EEE D:#C03 E:#111 F:#222 G:#933 H:#B00 I:#C33 J:#633 K:#963 L:#696 M:#500 N:#D00 O:#C66 P:#363 Q:#C96 R:#C00 S:#A00 T:#396 U:#993 V:#333 W:#F03 X:#C36 Y:#09F Z:#C63 Aa:#CC6 Ab:#330 Ac:#800 Ad:#400 Ae:#903 Af:#936 Ag:#09C Ah:#099 Ai:#066 Aj:#366 Ak:#069 Al:#900 Am:#555
voxels
- - - - - - - - - - - - - - - - -   - - - - - - - - - - - - - - - - -   - - - - - - - - - - - - - - - - -   - - - - - - - - - - - - - - - - -   - - - - - - - - - - - - - - - - -   - - - - - - - - - - - - - - - - -   - - - - - - - - - - - - - - - - -   - - - - - - - - - - - - - - - - -   - - - - - - - - - - - - - - - - -   - - - - - - - - - - - - - - - - -   - - - - - - - - - - - - - - - - -   - - - - - - - - - - - - - - - - -   - - - - - - - - - - - - - - - - -   - - - - - - - - - - - - - - - - -   - - - - - - - - - - - - - - - - -   - - - - B B B B - - - - - - - - -   - - - B - - - - B - - - - - - - -   - - B - - - - - - B - - - - - - -   - - B - - - - - - - B - - - - - -   - B B - - - - - - - B - - - - - -   - B - - - - - - - - B B - - - - -   - B - - - - - - - - - B - - - - -   - B - - - - - - - - - B - - - - -   - B - - - - - - - - B B - - - - -   - - B - - - - - - - B - - - - - -   - - B B - - - - - B B - - - - - -   - - - B B B - - B B - - - - - - -   - - - - - B B B B - - - - - - - -   - - - - - - - - - - - - - - - - -   - - - - - - - - - - - - - - - - -   - - - - - - - - - - - - - - - - -   
- - - - - - - - D AlAl- - - - - -   - - - - - - - D D AcAcAc- - - - -   - - - - - - - - - D D - - - - - -   - - - - - - - - - - - - - - - - -   - - - - - - - - - - - - - - - - -   - - - - - - - - - - - - - - - - -   - - - - - - - - - - - - - - - - -   - - - - - - - - - - - - - - - - -   - - - - - - - - - - - - - - - - -   - - - - - - - - - - - - - - - - -   - - - - - - - - - - - - - - - - -   - - - - - - - - - - - - - - - - -   - - - A A A A A A A - - - - - - -   - - - A A A A A A A - - - - - - -   - - - A A A A A A A - - - - - - -   - - A A - - - - A A - - - - - - -   - - A - - - - - - A A - - - - - -   - - A - - - - - - - A A - - - - -   - A - - - - - - - - - A - - - - -   - A - - - - - - - - - A A - - - -   - A - - - - - - - - - - A - - - -   - A - - - - - - - - - - A - - - -   - A - - - - - - - - - A - - - - -   - A - - - - - - - - - A - - - - -   - A - - - - - - - - - A - - - - -   - - A - - - - - - - - A - - - - -   - - - A - - - - - - A - - - - - -   - - - - A - - - - A - - - - - - -   - - - - - A A A A - - - - - - - -   - - - - - - - - - - - - - - - - -   - - - - - - - - - - - - - - - - -   
- - - - - H H H - - - H H H - - -   - - - - - H D - - - - - H H - - -   - - - - - H H D D - - I H - - - -   - - - - - - H D D D D H D - - - -   - - - - - - H D M D H H M - - - -   - - - - - - M H M M M M M - - - -   - - - - F F F F F F F F F - - - -   - - - - - A A A A A A A - - - - -   - - - - - A A A A A A - - - - - -   - - - - - A A A A A A - - - - - -   - - - - A A A A A A A A - - - - -   - - - - A A A A A A A A - - - - -   - - - - A - - - - - A - - - - - -   - - - A - - - - - - A A - - - - -   - - - A - - - - - - A A - - - - -   - - A - - - - - - - A A A - - - -   - - A - - - - - - - - A A A - - -   - A - - - - - - - - - - A A - - -   - A - - - - - - - - - - A A - - -   - A - - - - - - - - - - - A - - -   - A - - - - - - - - - - - A - - -   - A - - - - - - - - - - - A - - -   - A - - - - - - - - - - A - - - -   - A - - - - - - - - - - A - - - -   - A - - - - - - - - - A - - - - -   - - A - - - - - - - - A - - - - -   - - - A - - - - - - A - - - - - -   - - - A A - - - - A - - - - - - -   - - - - - A A A A - - - - - - - -   - - - - - - - - - - - - - - - - -   - - - - - - - - - - - - - - - - -   
- - - - S - - - - - - - - - S - -   - - - - S - - - - - - - - - S - -   - - - - H - - - - - - - - H - - -   - - - - G G - - - - - - - G - - -   - - - - - G - - - - - - - G - - -   - - - - - F - - - - - - - F - - -   - - - E E - - - - - - - - E - - -   - - A A A - - - - - - - A A - - -   - - A A A - - - - - - A A - - - -   - - A A A - - - - - - A A - - - -   - - A A - - - - - - - - A A - - -   - - A A - - - - - - - - A A - - -   - - A A - - - - - - - A A A - - -   - - A - - - - - - - - - A - - - -   - - A - - - - - - - - - A A - - -   - A - - - - - - - - - - - A - - -   - A - - - - - - - - - - - - A - -   - A - - - - - - - - - - - - A - -   A - - - - - - - - - - - - - A - -   A - - - - - - - - - - - - - A - -   A - - - - - - - - - - - - - A - -   A - - - - - - - - - - - - - A - -   A - - - - - - - - - - - - A - - -   - A - - - - - - - - - - A - - - -   - A - - - - - - - - - - A - - - -   - - A - - - - - - - - A - - - - -   - - A - - - - - - - - A - - - - -   - - - A - - - - - A A - - - - - -   - - - - A A - A A - - - - - - - -   - - - - - - A - - - - - - - - - -   - - - - - - - - - - - - - - - - -   
- - - N - - - - - - - - - - N - -   - - - R - - - - - - - - - - R - -   - - - I - - - - - - - - - - I - -   - - - J - - - - - - - - - - J - -   - - - - F - - - - - - - - - F - -   - - - - E - - - - - - - - - E - -   - - A A - - - - - - - - - - A - -   - - A - - - - - - - - - - - A - -   - A - - - - - - - - - - - A A - -   - A - - - - - - - - - - - A A - -   - A - - - - - - - - - - - - A - -   - A - - - - - - - - - - - - A - -   - A - - - - - - - - - - - - A - -   - A - - - - - - - - - - - A A - -   - A - - - - - - - - - - - - A - -   A - - - - - - - - - - - - - A - -   A - - - - - - - - - - - - - - A -   A - - - - - - - - - - - - - - A -   A - - - - - - - - - - - - - - A -   A - - - - - - - - - - - - - - A -   A - - - - - - - - - - - - - - A -   A - - - - - - - - - - - - - A - -   A - - - - - - - - - - - - - A - -   A - - - - - - - - - - - - A - - -   - A - - - - - - - - - - - A - - -   - - A - - - - - - - - - A - - - -   - - A - - - - - - - - A - - - - -   - - - A - - - - - - A - - - - - -   - - - - A - - - A A - - - - - - -   - - - - - A A A - - - - - - - - -   - - - - - - - - - - - - - - - - -   
- - H - - - - - - - - - - - H - -   - - I - - - - - - - - - - - - I -   - - H - - - - - - - - - - - J - -   - - - M - - - - - - - - - - - M -   - - - M - - - - - - - - - - - M -   - - - F - - - - - - - - - - - F -   - - A - - - - - - - - - - - - A -   - - A - - - - - - - - - - - - A -   - A - - - - - - - - - - - - - A -   - A - - - - - - - - - - - - - A -   - A - - - - - - - - - - - - - K -   - A - - - - - - - - - - - - - K -   - A - - - - - - - - - - - - - F -   A - - - - - - - - - - - - - - A -   A - - - - - - - - - - - - - - A -   A - - - - - - - - - - - - - - K -   A - - - - - - - - - - - - - - K -   A - - - - - - - - - - - - - - - A   A - - - - - - - - - - - - - - - A   A - - - - - - - - - - - - - - E -   A - - - - - - - - - - - - - - P -   A - - - - - - - - - - - - - - P -   A - - - - - - - - - - - - - A - -   A - - - - - - - - - - - - - A - -   - A - - - - - - - - - - - A - - -   - A - - - - - - - - - - A - - - -   - - A - - - - - - - - A - - - - -   - - - A - - - - - - A - - - - - -   - - - A - - - - - A - - - - - - -   - - - - A A A A A - - - - - - - -   - - - - - - - - - - - - - - - - -   
- - S - - - - - - - - - - - - S -   - - H - - - - - - - - - - - - H -   - - G - - - - - - - - - - - - G -   - - G - - - - - - - - - - - - G -   - - - F - - - - - - - - - - - F -   - - - E - - - - - - - - - - - E -   - - E - - - - - - - - - - - - E -   - - A - - - - - - - - - - - - A -   - A - - - - - - - - - - - - - - A   - A - - - - - - - - - - - - - - K   - A - - - - - - - - - - - - - - Q   - A - - - - - - - - - - - - - - Q   - A - - - - - - - - - - - - - - Z   C - - - - - - - - - - - - - - - A   C - - - - - - - - - - - - - - - U   A - - - - - - - - - - - - - - - Aa  A - - - - - - - - - - - - - - - Aa  A - - - - - - - - - - - - - - - U   A - - - - - - - - - - - - - - - A   A - - - - - - - - - - - - - - - T   A - - - - - - - - - - - - - - L -   A - - - - - - - - - - - - - - L -   A - - - - - - - - - - - - - - P -   A - - - - - - - - - - - - - A - -   - A - - - - - - - - - - - A - - -   - A - - - - - - - - - - - A - - -   - - A - - - - - - - - - A - - - -   - - A - - - - - - - - A - - - - -   - - - A - - A - - A A - - - - - -   - - - - A - A - A - - - - - - - -   - - - - - B B B - - - - - - - - -   
- R - - - - - - - - - - - - - R -   - - I - - - - - - - - - - - - I -   - - J - - - - - - - - - - - - J -   - - F - - - - - - - - - - - - F -   - - A - - - - - - - - - - - - - E   - - - A - - - - - - - - - - - - A   - A A - - - - - - - - - - - - - A   - A - - - - - - - - - - - - - - A   - A - - - - - - - - - - - - - - A   - A - - - - - - - - - - - - - - K   - A - - - - - - - - - - - - - - Q   - A - - - - - - - - - - - - - - Q   - A - - - - - - - - - - - - - - O   C C - - - - - - - - - - - - - - A   C - - - - - - - - - - - - - - - U   C - - - - - - - - - - - - - - - Aa  C - - - - - - - - - - - - - - - Aa  C - - - - - - - - - - - - - - - U   C - - - - - - - - - - - - - - - A   C - - - - - - - - - - - - - - - L   C - - - - - - - - - - - - - - - L   C - - - - - - - - - - - - - - L -   C - - - - - - - - - - - - - - P -   A - - - - - - - - - - - - - A - -   - A - - - - - - - - - - - - A - -   - A - - - - - - - - - - - A - - -   - - A - - - - - - - - - A - - - -   - - A - - - A - - - - A - - - - -   - - - A - A - A - - A - - - - - -   - - - - A A - A - B - - - - - - -   - - - - - B B B B - - - - - - - -   
- R - - - - - - - - - - - - - R -   - R - - - - - - - - - - - - - - R   - - I - - - - - - - - - - - - I -   - - Ad- - - - - - - - - - - - - Ad  - - A - - - - - - - - - - - - - A   - - A - - - - - - - - - - - - - A   - A - - - - - - - - - - - - - - A   A - - - - - - - - - - - - - - - A   A - - - - - - - - - - - - - - - A   A - - - - - - - - - - - - - - - Ab  A - - - - - - - - - - - - - - - Z   A - - - - - - - - - - - - - - - O   A - - - - - - - - - - - - - - - J   C - - - - - - - - - - - - - - - A   C - - - - - - - - - - - - - - - Ab  C - - - - - - - - - - - - - - - U   C - - - - - - - - - - - - - - - U   C - - - - - - - - - - - - - - - Ab  C - - - - - - - - - - - - - - - A   C - - - - - - - - - - - - - - - V   C - - - - - - - - - - - - - - - L   C - - - - - - - - - - - - - - T -   C - - - - - - - - - - - - - - E -   - A - - - - - - - - - - - - A - -   - A - - - - - - - - - - - - A - -   - A - - - - - - - - - - - A - - -   - - A - - - - - - - - - - A - - -   - - A - - - - - - - - - A - - - -   - - - A - - - - - - B B - - - - -   - - - - A - - - B B - - - - - - -   - - - - B - - - - - - - - - - - -   
- G - - - - - - - - - - - - - - G   - J - - - - - - - - - - - - - - J   - - F - - - - - - - - - - - - F -   - - E - - - - - - - - - - - - - E   - - A - - - - - - - - - - - - - E   - - A - - - - - - - - - - - - - A   A A - - - - - - - - - - - - - - A   A - - - - - - - - - - - - - - - A   A - - - - - - - - - - - - - - - A   A - - - - - - - - - - - - - - - A   A - - - - - - - - - - - - - - - A   A - - - - - - - - - - - - - - - A   A - - - - - - - - - - - - - - - A   C - - - - - - - - - - - - - - - A   C - - - - - - - - - - - - - - - A   A - - - - - - - - - - - - - - - A   A - - - - - - - - - - - - - - - A   A - - - - - - - - - - - - - - - A   A - - - - - - - - - - - - - - - A   A - - - - - - - - - - - - - - - A   C - - - - - - - - - - - - - - - A   C - - - - - - - - - - - - - - A -   A - - - - - - - - - - - - - - A -   - A - - - - - - - - - - - - A - -   - A - - - - - - - - - - - - A - -   - A - - - - - - - - - - - A - - -   - - A - - - - - - - - - - A - - -   - - A - - - - - - - - - B - - - -   - - - A - - - - - - - B - - - - -   - - - B B - - - - - - - - - - - -   - - - - - - - - - - - - - - - - -   
- N - - - - - - - - - - - - - - N   - O - - - - - - - - - - - - - - O   - - F - - - - - - - - - - - - - F   - - E - - - - - - - - - - - - - E   - - A - - - - - - - - - - - - - A   - - A - - - - - - - - - - - - - J   A A - - - - - - - - - - - - - - G   A - - - - - - - - - - - - - - - J   A - - - - - - - - - - - - - - - A   A - - - - - - - - - - - - - - - A   A - - - - - - - - - - - - - - - K   A - - - - - - - - - - - - - - - K   A - - - - - - - - - - - - - - - F   A - - - - - - - - - - - - - - - A   A - - - - - - - - - - - - - - - A   A - - - - - - - - - - - - - - - A   A - - - - - - - - - - - - - - - A   A - - - - - - - - - - - - - - - A   A - - - - - - - - - - - - - - - A   A - - - - - - - - - - - - - - - F   A - - - - - - - - - - - - - - - Aj  A - - - - - - - - - - - - - - P -   A - - - - - - - - - - - - - - A -   - A - - - - - - - - - - - - A - -   - A - - - - - - - - - - - - Ai- -   - A - - - - - - - - - - - - Ah- -   - - A - - - - - - - - - - Ak- - -   - - A - - - A A A A A A B - - - -   - - - A - - - - - - - - - - - - -   - - - B B - - - - - - - - - - - -   - - - - - - - - - - - - - - - - -   
- G - - - - - - - - - - - - - - G   - E - - - - - - - - - - - - - - E   - - E - - - - - - - - - - - - - E   - - A - - - - - - - - - - - - - E   - - A - - - - - - - - - - - - - A   - - A - - - - - - - - - - - - - O   A A - - - - - - - - - - - - - - O   A - - - - - - - - - - - - - - - X   A - - - - - - - - - - - - - - - A   A - - - - - - - - - - - - - - - K   A - - - - - - - - - - - - - - - Q   A - - - - - - - - - - - - - - - Q   A - - - - - - - - - - - - - - - O   A - - - - - - - - - - - - - - - A   A - - - - - - - - - - - - - - - A   A - - - - - - - - - - - - - - - A   A - - - - - - - - - - - - - - - A   A - - - - - - - - - - - - - - - A   A - - - - - - - - - - - - - - - A   A - - - - - - - - - - - - - - - T   A - - - - - - - - - - - - - - - L   A - - - - - - - - - - - - - - L -   A - - - - - - - - - - - - - - P -   - A - - - - - - - - - - - - A - -   - A - - - - - - - - - - - - Ag- -   - A - - - - - - - - - - - - Y - -   - - A - - - - - - - - - - Y - - -   - - A - - - - - - - - - B - - - -   - - - A - - - - - - - - - - - - -   - - - B B - - - - - - - - - - - -   - - - - - - - - - - - - - - - - -   
- N - - - - - - - - - - - - - - N   - F - - - - - - - - - - - - - - F   - - E - - - - - - - - - - - - - E   - - A - - - - - - - - - - - - - E   - - A - - - - - - - - - - - - - A   - A - - - - - - - - - - - - - - O   A - - - - - - - - - - - - - - - O   A - - - - - - - - - - - - - - - X   A - - - - - - - - - - - - - - - A   A - - - - - - - - - - - - - - - K   A - - - - - - - - - - - - - - - Q   A - - - - - - - - - - - - - - - Q   A - - - - - - - - - - - - - - - O   A - - - - - - - - - - - - - - - A   A - - - - - - - - - - - - - - - A   A - - - - - - - - - - - - - - - A   A - - - - - - - - - - - - - - - A   A - - - - - - - - - - - - - - - A   A - - - - - - - - - - - - - - - A   A - - - - - - - - - - - - - - - T   A - - - - - - - - - - - - - - - L   A - - - - - - - - - - - - - - L -   A - - - - - - - - - - - - - - P -   - A - - - - - - - - - - - - A - -   - A - - - - - - - - - - - - Ag- -   - A - - - - - - - - - - - - Y - -   - - A - - - - - - - - - - Y - - -   - - A - - - - - - - - - B - - - -   - - - A - - - - - - - - - - - - -   - - - B B - - - - - - - - - - - -   - - - - - - - - - - - - - - - - -   
- Af- - - - - - - - - - - - - - Af  - E - - - - - - - - - - - - - - E   - - E - - - - - - - - - - - - - E   - - A - - - - - - - - - - - - - E   - - A - - - - - - - - - - - - - A   - A - - - - - - - - - - - - - - J   A - - - - - - - - - - - - - - - G   A - - - - - - - - - - - - - - - J   A - - - - - - - - - - - - - - - A   A - - - - - - - - - - - - - - - A   A - - - - - - - - - - - - - - - K   A - - - - - - - - - - - - - - - K   A - - - - - - - - - - - - - - - F   A - - - - - - - - - - - - - - - A   C - - - - - - - - - - - - - - - A   C - - - - - - - - - - - - - - - A   C - - - - - - - - - - - - - - - A   C - - - - - - - - - - - - - - - A   C - - - - - - - - - - - - - - - A   C - - - - - - - - - - - - - - - F   C - - - - - - - - - - - - - - - Aj  C - - - - - - - - - - - - - - P -   A - - - - - - - - - - - - - - A -   - A - - - - - - - - - - - - A - -   - A - - - - - - - - - - - - Ai- -   - A - - - - - - - - - - - - Ah- -   - - A - - - - - - - - - - Ak- - -   - - A - - - - - - - - - B - - - -   - - - A - - - - - - - - - - - - -   - - - B B - - - - - - - - - - - -   - - - - - - - - - - - - - - - - -   
- B - - - - - - - - - - - - - - B   - I - - - - - - - - - - - - - - I   - - E - - - - - - - - - - - - E -   - - A - - - - - - - - - - - - - E   - - A - - - - - - - - - - - - - E   - - A - - - - - - - - - - - - - A   A A - - - - - - - - - - - - - - A   A - - - - - - - - - - - - - - - A   A - - - - - - - - - - - - - - - A   A - - - - - - - - - - - - - - - A   A - - - - - - - - - - - - - - - A   A - - - - - - - - - - - - - - - A   A - - - - - - - - - - - - - - - A   C - - - - - - - - - - - - - - - A   C - - - - - - - - - - - - - - - A   A - - - - - - - - - - - - - - - A   A - - - - - - - - - - - - - - - A   A - - - - - - - - - - - - - - - A   A - - - - - - - - - - - - - - - A   A - - - - - - - - - - - - - - - A   C - - - - - - - - - - - - - - - A   C - - - - - - - - - - - - - - A -   C - - - - - - - - - - - - - - A -   - A - - - - - - - - - - - - A - -   - A - - - - - - - - - - - - A - -   - A - - - - - - - - - - - A - - -   - - A - - - - - - - - - - A - - -   - - A - - - - - - - - - B - - - -   - - - A - - - - - - - B - - - - -   - - - B B - - - - - - - - - - - -   - - - - - - - - - - - - - - - - -   
- G - - - - - - - - - - - - - G -   - F - - - - - - - - - - - - - F -   - - F - - - - - - - - - - - - F -   - - A - - - - - - - - - - - - E -   - - A - - - - - - - - - - - - - E   - - A - - - - - - - - - - - - - A   A A - - - - - - - - - - - - - - A   A - - - - - - - - - - - - - - - A   A - - - - - - - - - - - - - - - A   A - - - - - - - - - - - - - - - F   A - - - - - - - - - - - - - - - Z   A - - - - - - - - - - - - - - - O   A - - - - - - - - - - - - - - - J   C - - - - - - - - - - - - - - - A   A - - - - - - - - - - - - - - - A   A - - - - - - - - - - - - - - - A   A - - - - - - - - - - - - - - - A   A - - - - - - - - - - - - - - - A   A - - - - - - - - - - - - - - - A   A - - - - - - - - - - - - - - - V   A - - - - - - - - - - - - - - - L   A - - - - - - - - - - - - - - T -   C - - - - - - - - - - - - - - E -   - A - - - - - - - - - - - - A - -   - A - - - - - - - - - - - - A - -   - A - - - - - - - - - - - A - - -   - - A - - - - - - - - - - A - - -   - - A - - - - - - - - A A - - - -   - - - A - - - - - - B - - - - - -   - - - - A - - - - B - - - - - - -   - - - - B - - - - - - - - - - - -   
- N - - - - - - - - - - - - - N -   - N - - - - - - - - - - - - - N -   - - I - - - - - - - - - - - - I -   - - F - - - - - - - - - - - - F -   - - A - - - - - - - - - - - - E -   - - A - - - - - - - - - - - - A -   A A - - - - - - - - - - - - - - A   A - - - - - - - - - - - - - - - A   A - - - - - - - - - - - - - - - A   A - - - - - - - - - - - - - - - K   A - - - - - - - - - - - - - - - Q   A - - - - - - - - - - - - - - - Q   A - - - - - - - - - - - - - - - O   C - - - - - - - - - - - - - - - A   C - - - - - - - - - - - - - - - A   C - - - - - - - - - - - - - - - A   C - - - - - - - - - - - - - - - A   C - - - - - - - - - - - - - - - A   A - - - - - - - - - - - - - - - A   A - - - - - - - - - - - - - - - L   A - - - - - - - - - - - - - - - L   A - - - - - - - - - - - - - - L -   C - - - - - - - - - - - - - - P -   A - - - - - - - - - - - - - A - -   - A - - - - - - - - - - - - A - -   - A - - - - - - - - - - - A - - -   - - A - - - - - - - - - A - - - -   - - A - - - - - - - - A - - - - -   - - - A - - - - - - A - - - - - -   - - - - A - - - - A - - - - - - -   - - - - - B B B B - - - - - - - -   
- B - - - - - - - - - - - - - B -   - - I - - - - - - - - - - - - I -   - - G - - - - - - - - - - - G - -   - - J - - - - - - - - - - - - J -   - - A - - - - - - - - - - - - E -   - - A - - - - - - - - - - - - A -   - A - - - - - - - - - - - - - - A   - A - - - - - - - - - - - - - - A   A - - - - - - - - - - - - - - - A   A - - - - - - - - - - - - - - - K   A - - - - - - - - - - - - - - - Q   A - - - - - - - - - - - - - - - Q   A - - - - - - - - - - - - - - - Z   A - - - - - - - - - - - - - - - A   C - - - - - - - - - - - - - - - A   C - - - - - - - - - - - - - - - A   C - - - - - - - - - - - - - - - A   C - - - - - - - - - - - - - - - A   C - - - - - - - - - - - - - - - A   C - - - - - - - - - - - - - - - T   C - - - - - - - - - - - - - - - L   C - - - - - - - - - - - - - - L -   A - - - - - - - - - - - - - - P -   A - - - - - - - - - - - - - A - -   - A - - - - - - - - - - - A - - -   - A - - - - - - - - - - - A - - -   - - A - - - - - - - - - A - - - -   - - A - - - - - - - - A - - - - -   - - - A - - - - - - A - - - - - -   - - - - A - - - A A - - - - - - -   - - - - - B B B - - - - - - - - -   
- - W - - - - - - - - - - - W - -   - - X - - - - - - - - - - - X - -   - - G - - - - - - - - - - - G - -   - - F - - - - - - - - - - - F - -   - - A - - - - - - - - - - - - E -   - - - A - - - - - - - - - - - E -   - - A - - - - - - - - - - - - E -   - - A - - - - - - - - - - - - A -   - A - - - - - - - - - - - - - A -   - A - - - - - - - - - - - - - A -   - A - - - - - - - - - - - - - K -   - A - - - - - - - - - - - - - K -   - A - - - - - - - - - - - - - F -   A - - - - - - - - - - - - - - A -   A - - - - - - - - - - - - - - A -   A - - - - - - - - - - - - - - A -   A - - - - - - - - - - - - - - - A   A - - - - - - - - - - - - - - - A   A - - - - - - - - - - - - - - - A   A - - - - - - - - - - - - - - - E   A - - - - - - - - - - - - - - P -   A - - - - - - - - - - - - - - P -   A - - - - - - - - - - - - - A - -   A - - - - - - - - - - - - - A - -   - A - - - - - - - - - - - A - - -   - A - - - - - - - - - - A - - - -   - - A - - - - - - - - A A - - - -   - - - A - - - - - - A - - - - - -   - - - A - - - - - A - - - - - - -   - - - - A A A A A - - - - - - - -   - - - - - - - - - - - - - - - - -   
- - - B - - - - - - - - - - B - -   - - - B - - - - - - - - - - B - -   - - - I - - - - - - - - - - I - -   - - - I - - - - - - - - - - I - -   - - - A - - - - - - - - - - J - -   - - - A - - - - - - - - - - E - -   - - - A - - - - - - - - - - E - -   - - - A - - - - - - - - - - A - -   - - A - - - - - - - - - - - A A -   - - A - - - - - - - - - - - A - -   - - A - - - - - - - - - - A A - -   - A - - - - - - - - - - - A A - -   - A - - - - - - - - - - - - A - -   - A - - - - - - - - - - - - A - -   - A - - - - - - - - - - - - A - -   - A - - - - - - - - - - - - - A -   A - - - - - - - - - - - - - - A -   A - - - - - - - - - - - - - - A -   A - - - - - - - - - - - - - - A -   A - - - - - - - - - - - - - - A -   A - - - - - - - - - - - - - - A -   A - - - - - - - - - - - - - A - -   A - - - - - - - - - - - - - A - -   A - - - - - - - - - - - - A - - -   - A - - - - - - - - - - - A - - -   - A - - - - - - - - - - A - - - -   - - A - - - - - - - - A - - - - -   - - - A - - - - - - A - - - - - -   - - - - A - - - A A - - - - - - -   - - - - - A A A - - - - - - - - -   - - - - - - - - - - - - - - - - -   
- - - - W - - - - - - - - - W - -   - - - - D - - - - - - - - D - - -   - - - - J - - - - - - - - J - - -   - - - - F - - - - - - - - F - - -   - - - - A - - - - - - - - E - - -   - - - - A E - - - - - - - E - - -   - - - - A - - - - - - - - E - - -   - - - A A - - - - - - - - A - - -   - - A A - - - - - - - - - A - - -   - - A A - - - - - - - A A A - - -   - - A A - - - - - - - A A - - - -   - - A A - - - - - - - - A - - - -   - - A - - - - - - - - - A A - - -   - - A - - - - - - - - - A A - - -   - - A - - - - - - - - - A A - - -   - A - - - - - - - - - - - A A - -   - A - - - - - - - - - - - - A - -   - A - - - - - - - - - - - - A - -   A - - - - - - - - - - - - - A - -   A - - - - - - - - - - - - - A - -   A - - - - - - - - - - - - - A - -   A - - - - - - - - - - - - - A - -   A - - - - - - - - - - - - A - - -   - A - - - - - - - - - - - A - - -   - A - - - - - - - - - - A - - - -   - - A - - - - - - - - - A - - - -   - - A - - - - - - - - A - - - - -   - - - A - - - - - A A - - - - - -   - - - - A A - - A - - - - - - - -   - - - - - - A A - - - - - - - - -   - - - - - - - - - - - - - - - - -   
- - - - - D N - - - - N D D - - -   - - - - - D D - - - - D D - - - -   - - - - - G D - - - - D D - - - -   - - - - - AeAeD - - - D D - - - -   - - - - - G G D D - D G G - - - -   - - - - - - V D D V V D D - - - -   - - - - - E E E E E E D D - - - -   - - - - - A A A A A A AmD - - - -   - - - - A A A A A A A A A - - - -   - - - - A A A A A A A - - - - - -   - - - - A A A A A A A - - - - - -   - - - - A A - - - A A A - - - - -   - - - A - - - - - - A A - - - - -   - - - A - - - - - - A A - - - - -   - - A - - - - - - - - A - - - - -   - - A - - - - - - - - - A - - - -   - A - - - - - - - - - - - A - - -   - A - - - - - - - - - - - A - - -   - A - - - - - - - - - - - A - - -   - A - - - - - - - - - - - A - - -   - A - - - - - - - - - - - A - - -   - A - - - - - - - - - - - A - - -   - A - - - - - - - - - - A - - - -   - A - - - - - - - - - - A - - - -   - A - - - - - - - - - - A - - - -   - - A - - - - - - - - A - - - - -   - - - A - - - - - - - A - - - - -   - - - A - - - - - A A - - - - - -   - - - - A A A A A - - - - - - - -   - - - - - - - - - - - - - - - - -   - - - - - - - - - - - - - - - - -   
- - - - - - - D D D D - - - - - -   - - - - - - - D D D D - - - - - -   - - - - - - - D D D D - - - - - -   - - - - - - - - D D D - - - - - -   - - - - - - - - - D - - - - - - -   - - - - - - - - - - - - - - - - -   - - - - - - - - - - - - - - - - -   - - - - - - - - - - - - - - - - -   - - - - - - - - - - - - - - - - -   - - - - - - - - - - - - - - - - -   - - - - - - - - - - - - - - - - -   - - - - - - A A A - - - - - - - -   - - - - A A A A A A - - - - - - -   - - - A A A - - - A - - - - - - -   - - - A A - - - - - A - - - - - -   - - - A - - - - - - - A A - - - -   - - A - - - - - - - - - A - - - -   - - A - - - - - - - - - A - - - -   - A - - - - - - - - - - A - - - -   - A - - - - - - - - - - - A - - -   - A - - - - - - - - - - - A - - -   - A - - - - - - - - - - - A - - -   - A - - - - - - - - - - A - - - -   - A - - - - - - - - - - A - - - -   - - A - - - - - - - - - A - - - -   - - A - - - - - - - - A - - - - -   - - - A - - - - - - A - - - - - -   - - - - A - - - - A A - - - - - -   - - - - - A A A A - - - - - - - -   - - - - - - - - - - - - - - - - -   - - - - - - - - - - - - - - - - -   
- - - - - - - - - - - - - - - - -   - - - - - - - - - - - - - - - - -   - - - - - - - - - - - - - - - - -   - - - - - - - - - - - - - - - - -   - - - - - - - - - - - - - - - - -   - - - - - - - - - - - - - - - - -   - - - - - - - - - - - - - - - - -   - - - - - - - - - - - - - - - - -   - - - - - - - - - - - - - - - - -   - - - - - - - - - - - - - - - - -   - - - - - - - - - - - - - - - - -   - - - - - - - - - - - - - - - - -   - - - - - - - - - - - - - - - - -   - - - - - - B B B - - - - - - - -   - - - - - B B - B B B - - - - - -   - - - - B - - - - - B B - - - - -   - - - B B - - - - - - - B - - - -   - - B - - - - - - - - - B - - - -   - - B - - - - - - - - - B - - - -   - - B - - - - - - - - - B B - - -   - B - - - - - - - - - - - B - - -   - B - - - - - - - - - - B - - - -   - B - - - - - - - - - - B - - - -   - B B - - - - - - - - - B - - - -   - - B - - - - - - - - B B - - - -   - - B B - - - - - - - B - - - - -   - - - B B - - - - - B - - - - - -   - - - - B B B - - B - - - - - - -   - - - - - - B B B - - - - - - - -   - - - - - - - - - - - - - - - - -   - - - - - - - - - - - - - - - - -   
