model
size = 16 31 31, scale = 0.05, origin = -y
material 
  colors = A:#FFF B:#63C C:#66C D:#CCF E:#96C F:#EEE G:#FC3 H:#DDD I:#FC6 J:#99C K:#99F L:#C9F M:#FF9 N:#FC9 O:#FFC P:#BBB
voxels
---------------- ---------------- ---------------- ---------------- ---------------- ---------------- ---------------- ---------------- ---------------- ---------------- ---------------- ---------------- ---------------- ---------------- ---------------- ---------------- ---------------- ---------------- ----AAAAA------- ----AAAAAA------ ----AAAAAA------ -----AAAA------- ---------------- ---------------- ---------------- ---------------- ---------------- ---------------- ---------------- ---------------- ---------------- 
---------------- ---------------- ---------------- ---------------- ---------------- ---------------- ---------------- ---------------- ---------------- ---------------- ---------------- ---------------- ---------------- ---------------- ---------------- ---------------- ---------------- ---AAAA--------- ---AAAAAAA------ ---AAAAAAA------ ---AAAAAAA------ ---AAAAAAA------ ---AAAAAAA------ ---AAAAAAA------ ----AAAAAA------ ---------------- ---------------- ---------------- ---------------- ---------------- ---------------- 
---------------- ---------------- ---------------- ---------------- ---------------- ---------------- ---------------- ---------------- ---------------- ---------------- ---------------- ---------------- ---------------- ---------------- ---------------- ---------------- ---------------- --AAAAAA-------- --AAAAAAAAA----- --AAAAAAAAA----- --AAAAAAAAA----- --AAAAAAAAA----- --AAAAAAAAA----- --AAAAAAAAA----- --AAAAAAAAA----- ---AAAAAAAA----- ---AAAAAAA------ ---------------- ---------------- ---------------- ---------------- 
---------------- ---------------- ---------------- ---------------- ---------------- ---------------- ---------------- ---------------- ---------------- ---------------- ---------------- ---------------- ---------------- ---------------- ---------------- ---------------- ---------------- ---AAAAAAA------ --AAAAAAAAA----- -AAAAAAAAAA----- -AAAAAAAAAA----- -AAAAAAAAAA----- -AAAAAAAAAA----- -AAAAAAAAAA----- --AAAAAAAAA----- --AAAAAAAAA----- ---AAAAAAAA----- ---AAAAAAA------ ---------------- ---------------- ---------------- 
---------------- ---------------- ---------------- ---------------- ---------------- ---------------- ---------------- ---------------- ---------------- ---------------- ---------------- ---------------- ---------------- ---------------- ---------------- ---------------- ---------------- ---AAA-AAAA----- --AAAAAAAAA----- -AAAAAAAAAAA---- -AAAAAAAAAAA---- -AAAAAAAAAAA---- -AAAAAAAAAAA---- -AAAAAAAAAA----- -AAAAAAAAAA----- -AAAAAAAAAA----- --AAAAAAAAA----- ---AAAAAAAA----- ----AAAAA------- ---------------- ---------------- 
-----AAAAAAA---- -----AAAAAA----- ------AAAAA----- -----AAAAAA----- -----AAAAAA----- -----AAAAAA----- -----AAAAA------ -----AAAAA------ -----AAAA------- ---------------- ---------------- ---------------- ---------------- ---AAAAAAA------ --AAAAAAAAA----- --AAAAAAAAF----- --AAAAAAAAA----- --AAAAAAAAA----- -AAAAAAAAAAA---- -AAAAAAAAAAAA--- -AAAAAAAAAAAA--- -AAAAA-AAAAAA--- -AAAAA-AAAAAA--- -AAAAAAAAAAAA--- -AAAAAAAAAAA---- -AAAAAAAAAAA---- -AAAAAAAAAAA---- --AAAAAAAAA----- ---AAAAAAA------ ---------------- ---------------- 
---AAAAAAAAAAA-- ---AAAAAAAAAA--- ----AAAAAAAAA--- ---AAAAAAAAAA--- ---AAAAAAAAAA--- ---AAAAAAAAAA--- ---AAAAAAAAA---- ---AAAAAAACC---- --AAAAAAAABB---- --AAAAAAAABB---- --AAAAAAAABB---- --AAAAAAAAB----- --AAAAAAAAJJ---- --AAAAAAAAAA---- --AAAAAAAADDD--- -AAAAAAAAABBB--- -AAAAAAAAAKKK--- -AAAAAAAAAHHHH-- AAAAAAAAAAAAAA-- AAAAAAAAAAAAAA-- AAAAAAAAAAAAAA-- AAAAAA--AAAAAA-- AAAAA---AAAAAA-- AAAAAA-AAAAAA--- AAAAAAAAAAAAA--- -AAAAAAAAAAA---- -AAAAAAAAAAA---- --AAAAAAAAA----- ---AAAAAAA------ -----AAA-------- ---------------- 
--AAAAAAAAAAAA-- --AAAAAAAAAAAA-- ---AAAAAAAAAAA-- --AAAAAAAAAAAA-- --AAAAAAAAAAAA-- --AAAAAAAAAAAA-- --AAAAAAAAAAAA-- --AAAAAAAACCCC-- --AAAAAAAABBBB-- -AAAAAAAAABBBB-- -AAAAAAAAABBBB-- -AAAAAAAAABBBB-- -AAAAAAAAABBB--- -AAAAAAAAAFFFF-- -AAAAAAAAADDDDD- AAAAAAAAAABBBBB- AAAAAAAAAABBBBB- AAAAAAAAAABBBBB- AAAAAAAAAAEEEEE- AAAAAAAAAADDDDD- AAAAAAAAAAAAAAA- AAAAAA--AAAAAAA- AAAAA---AAAAAAA- AAAAA---AAAAAA-- AAAAAA-AAAAAAA-- AAAAAAAAAAAAA--- -AAAAAAAAAAA---- --AAAAAAAAAA---- --AAAAAAAA------ ----AAAAA------- ---------------- 
--AAAAAAAAAAAAA- --AAAAAAAAAAAAA- --AAAAAAAAAAAAA- -AAAAAAAAAAAAAA- -AAAAAAAAAAAAAA- --AAAAAAAAAAAAA- --AAAAAAAAAAAAA- --AAAAAAAACCCCC- --AAAAAAAABBBBB- -AAAAAAAAABBBBB- -AAAAAAAAABBBBB- AAAAAAAAAABBBBB- -AAAAAAAAABBBBB- AAAAAAAAAADDDDD- AAAAAAAAAADDDDD- AAAAAAAAAABBBBBB AAAAAAAAAABBBBBB AAAAAAAAAABBBBBB AAAAAAAAAABBBBBB AAAAAAAAAABBBBBB AAAAAAAAAACCCCCC AAAAA---AADDDDDD AAAA----AAFFFFFF AAAAA---AAAAAAA- AAAAAA-AAAAAAA-- AAAAAAAAAAAAA--- -AAAAAAAAAAAA--- --AAAAAAAAAA---- --AAAAAAAAA----- ---AAAAAA------- ---------------- 
-AAAAAAA-AAAAAA- AAAAAAAA-AAAAAA- AAAAAAAA-AAAAAAA -AAAAAAAAAAAAAAA -AAAAAAAAAAAAAAA -AAAAAAAAAAAAAAA -AAAAAAAAAAAAAAA -AAAAAAAAAEEEEEE -AAAAAAAAABBBBBB -AAAAAAAAABBBBBB AAAAAAAAAABBBBBB AAAAAAAAAABBBBBB AAAAAAAAAABBBBBB AAAAAAAAAAKKKKKK AAAAAAAAAADDDDDD AAAAAA-AAABBBBBB AAAAAA--AABBBBBB AAAAA---AABBBBBB AAAAA----ABBBBBB AAAAA----ABBBBBB AAAA------BBBBBB AAAA-----ABBBBBB AAAA-----ACCCCCC AAAAA---AAFFFFFF AAAAA---AAAAAA-- AAAAAA-AAAAAAA-- -AAAAAAAAAAAA--- -AAAAAAAAAAA---- --AAAAAAAAA----- ---AAAAAAA------ ----AAAAA------- 
-AAAAA----AAAAAA AAAAAAA---AAAAAA AAAAAAA---AAAAAA AAAAAAA---AAAAAA -AAAAAA---AAAAAA -AAAAAA---AAAAAA AAAAAAA---AAAAAA AAAAAAA---DDDDDD AAAAAAA---BBBBBB AAAAAA---ABBBBBB AAAAAA---ABBBBBB AAAAA----ABBBBBB AAAAA----ABBBBBB AAAAA----ACCCCCC AAAA------HHHHHH AAAA------BBBBBB AAAA------BBBBBB AAAA------BBBBBB AAAA------BBBBBB AAAA-------BBBBB AAA--------BBBBB AAA-------BBBBBB AAAA------EEEEEE AAAA-----AFFFFFF AAAAA---AAPPPPP- AAAAAA-AAALLLL-- -AAAAAAAAAFFFF-- -AAAAAAAAAAAA--- --AAAAAAAAAA---- ---AAA---------- ---AA----------- 
-AAAAA-----AAAAA AAAAAA-----AAAAA AAAAAA-----AAAAA -AAAAA-----AAAAA -AAAAA-----AAAAA AAAAAA-----AAAAA AAAAAA-----AAAAA AAAAAA-----AAAAA AAAAAA-----JJJJJ AAAAAA-----BBBBB AAAAA------BBBBB AAAAA------BBBBB AAAAA------BBBBB AAAA-------BBBBB AAAA-------DDDDD AAAA-------BBBBB AAAA-------BBBBB AAAA-------BBBBB AAA---------BBBB AAA---------BBBB AAA--------BBBBB AAA--------BBBBB AAAA------DDDDDD AAAA-----AKKKKKK AAAAA---AABBBBB- AAAAAA-AAABBBB-- -AAAAAAAAABBBB-- -AAAAAAAAAJJJ--- --AAAAAAAAHH---- --AAA----------- ---A------------ 
-AAAA------AAAAA AAAAAA-----AAAAA AAAAAA-----AAAAA -AAAAA-----AAAAA -AAAAA-----AAAAA AAAAA------AAAAA AAAAA------AAAAA AAAAA------AAAAA AAAAA------AAAAA AAAAA------JJJJJ AAAAA-------BBBB AAAAA-------BBBB AAAAA-------BBBB AAAA--------BBBB AAAA--------DDDD AAAA--------BBBB AAAA--------BBBB AAAA--------BBBB AAA---------BBBB AAA---------BBBB AAA---------BBBB AAA--------EEEEE AAAA------DDDDDD AAAA------BBBBBB AAAAA----ABBBBB- AAAAA--AAABBBB-- -AAAAAAAAABBBB-- -AAAAAAAAABBB--- --AAAAAAAACC---- --AAA----------- ---A------------ 
AAAAA-------AAAA AAAAA-------AAAA AAAAA-------AAAA -AAAA-------AAAA -AAAA-------AAAA AAAAA-------AAAA AAAAA-------AAAA AAAA--------DDDD AAAA--------DDDD AAAA--------FFFF AAAA--------EEEE AAAA--------BBBB AAAA--------BBBB AAAA--------BBBB AAAA--------LLLL AAAA--------BBBB AAAA---------BBB AAA----------BBB AAA----------BBB AAA---------BBBB AAA---------BBBB AAAA-------DDDDD AAAA-------BBBBB AAAA------BBBBBB AAAAA----ABBBBB- AAAAA---AABBBB-- -AAAAA-AAABBBB-- -AAAAAAAAAKKK--- --AAAA---AFF---- --AAA----------- ---A------------ 
AAAAA-------AAAA AAAAA-------AAAA AAAAA-------AAAA -AAAA-------AAAA -AAAA-------AAAA AAAAA-------AAAA AAAAA-------AAAA AAAA--------CCCC AAAA--------BBBB AAAA--------PPPP AAA---------FFFF AAA---------EEEE AAA---------BBBB AAA---------BBBB AAA---------JJJJ AAA---------BBBB AAA----------BBB AAA----------BBB AAA----------BBB AAA---------BBBB AAA---------JJJJ AAAA-------EEEEE AAAA-------BBBBB AAAA------BBBBBB AAAAA-----CCCCC- AAAAA---AAPPPP-- -AAAAA--AAFFFF-- -AAAAA--AAAAA--- --AAAA---AAA---- --AAA----------- ---A------------ 
AAAAA-------AAAA AAAAA-------AAAA AAAAAA------AAAA -AAAAA------AAAA -AAAAA------AAAA AAAAAA------AAAA AAAAA-------AAAA AAAA--------CCCC AAAA--------BBBB AAAA--------BBBB AAA----------JJJ AAA----------FFF AAA----------CCC AAA----------BBB AAA----------CCC AAA----------BBB AAA----------BBB AAA----------BBB AAA----------BBB AAA---------BBBB AAA---------EEEE AAAA-------BBBBB AAAA-------CCCCC AAAA------DDDDDD AAAAA-----AAAAA- AAAAA---AAAAAA-- -AAAAA--AAAAAA-- -AAAAA--AAAAA--- --AAAA---AAA---- --AAA----------- ---A------------ 
AAAAA-------AAAA AAAAA-------AAAA AAAAAA------AAAA AAAAAA------AAAA -AAAAA------AAAA AAAAAA------AAAA AAAAAA------AAAA AAAAA-------CCCC AAAA--------BBBB AAAA--------BBBB AAA----------BBB AAA----------EEE AAA----------DDD AAA----------CCC AAA----------BBB AAA----------BBB AAA----------BBB AAA----------BBB AAA----------BBB AAA---------BBBB AAA---------BBBB AAAA-------LLLLL AAAA-------AAAAA AAAA------AAAAAA AAAAA----AAAAAA- AAAAA---AAAAAA-- -AAAAA-AAAAAAA-- -AAAAAAAAAAAA--- --AAAA---AAA---- --AAA----------- ---A------------ 
AAAAA------AAAAA AAAAA------AAAAA AAAAAA-----AAAAA AAAAAA-----AAAAA -AAAAA-----AAAAA AAAAAA-----AAAAA AAAAAA-----AAAAA AAAAA------CCCCC AAAA-------BBBBB AAAA-------BBBBB AAAA--------BBBB AAAA--------BBBB AAAA--------CCCC AAAA--------LLLL AAA---------BBBB AAA---------BBBB AAA---------BBBB AAA---------BBBB AAA---------BBBB AAA---------CCCC AAA---------HHHH AAA--------AAAAA AAAA------AAAAAA AAAA------AAAAAA AAAAA----AAAAAA- AAAAA---AAAAAA-- -AAAAAAAAAAAAA-- -AAAAAAAAAAAA--- --AAAAAAAAAA---- --AAA----------- ---A------------ 
AAAAA------AAAAA AAAAAA-----AAAAA AAAAAA-----AAAAA AAAAAA-----AAAAA -AAAAA-----AAAAA -AAAAA-----AAAAA AAAAAA----AAAAAA AAAAAA----CCCCCC AAAAAA----BBBBBB AAAAAA----BBBBBB AAAAAA-----BBBBB AAAAA------BBBBB AAAAA-------BBBB AAAA-------BBBBB AAAA-------EEEEE AAAA-------BBBBB AAAA-------BBBBB AAA--------BBBBB AAA---------EEEE AAA---------FFFF AAA--------AAAAA AAA--------AAAAA AAAA------AAAAAA AAAA-----AAAAAAA AAAAA---AAAAAAA- AAAAAA-AAAAAAA-- -AAAAAAAAAAAAA-- -AAAAAAAAAAAA--- --AAAAAAAAAA---- --AAA----------- ---A------------ 
AAAAAA----AAAAAA AAAAAA----AAAAAA AAAAAAA---AAAAAA AAAAAAA---AAAAAA -AAAAAA---AAAAAA -AAAAAA---AAAAAA AAAAAAA--AAAAAAA AAAAAAA--CCCCCCC AAAAAAA--BBBBBBB AAAAAAA--CCCCCCC AAAAAAA--EEEEEEE AAAAAA----BBBBBB AAAAA-----BBBBBB AAAAA-----BBBBBB AAAAA-----BBBBBB AAAA------BBBBBB AAAA------BBBBBB AAAA------CCCCCC AAAA-------FFFFF AAAA-------AAAAA AAA--------AAAAA AAA-------AAAAAA AAAA------AAAAAA AAAA-----AAAAAAA AAAAA---AAAAAAA- AAAAAA-AAAAAAA-- -AAAAAAAAAAAAA-- -AAAAAAAAAAAA--- --AAAAAAAAAA---- ---AAA---------- ---AA----------- 
AAAAAAA--A-AAAAA AAAAAAAA-A-AAAAA -AAAAAAA-A-AAAAA AAAAAAAA-A-AAAAA AAAAAAAAAA-AAAAA -AAAAAAAAAAAAAAA -AAAAAAAAAAAAAAA AAAAAAAAACCCCCCC AAAAAAAAABBBBBBB AAAAAAAAABBBBBBB AAAAAAAAAEEEEEEE AAAAAAAAAHHHHHHH AAAAAAAAADDDDDDD AAAAAAAAALLLLLLL AAAAAAAAAEEEEEEE AAAAAA-AABBBBBBB AAAAAA--ABBBBBBB AAAAA---AHHHHHHH AAAAA----NNNNNNN AAAA----AAAAAAAA AAAA----AAAAAAAA AAAA--AAAAAAAAAA AAAA--AAAAAAAAAA AAAAA---AAAAAAAA AAAAA---AAAAAAA- AAAAAA-AAAAAAA-- -AAAAAAAAAAAAA-- -AAAAAAAAAAAA--- --AAAAAAAAAA---- ---AAAAAAAA----- ----AAAAA------- 
AAAAAAAA-AAAAAAA -AAAAAAA-AAAAAAA -AAAAAAA-AAAAAAA -AAAAAAAAAAAAAAA AAAAAAAAAAAAAAAA -AAAAAAAAAAAAAAA AAAAAAAAAAAAAAAA AAAAAAAAACCCCCCC AAAAAAAAABBBBBBB AAAAAAAAAKKKKKKK AAAAAAAAAHHHHHHH AAAAAAAAAAAAAAAA AAAAAAAAAAAAAAAA AAAAAAAAAAAAAAAA AAAAAAAAAOOOOOOO AAAAAA-AAHHHHHHH AAAAAA--AHHHHHHH AAAAA---ANNNNNNN AAAAA----IIIIIII AAAAA---AAAAAAAA AAAAA---AAAAAAAA AAAAA-AAAAAAAAAA AAAAA-AAAAAAAAAA AAAAA---AAAAAAA- AAAAA---AAAAAA-- AAAAAA-AAAAAAA-- --AAAAAAAAAAA--- --AAAAAAAAAA---- --AAAAAAAAA----- ---AAAAAAA------ ----AAAAA------- 
-AAAAAAAAAAAAAA- -AAAAAAAAAAAAAA- -AAAAAAAAAAAAAA- -AAAAAAAAAAAAAA- -AAAAAAAAAAAAAA- -AAAAAAAAAAAAAA- -AAAAAAAAAAAAAA- -AAAAAAAAFFFFFF- -AAAAAAAAFFFFFF- -AAAAAAAAAAAAAA- -AAAAAAAAAAAAAA- -AAAAAAAAAAAAAAA -AAAAAAAAAAAAAAA AAAAAAAAAAAAAAAA AAAAAAAAAMMMMMMM AAAAAAAAAGGGGGGG AAAAAAAAAIIIIIII AAAAAAAAAGGGGGGG AAAAAAAAAIIIIIII AAAAAAAAAAAAAAAA AAAAAAAAAAAAAAAA AAAAA---AAAAAAAA AAAA----AAAAAAA- AAAAA---AAAAAAA- AAAAAA-AAAAAAA-- AAAAAAAAAAAAA--- -AAAAAAAAAAAA--- --AAAAAAAAAA---- --AAAAAAAAA----- ---AAAAAA------- ---------------- 
-AAAAAAAAAAAAA-- -AAAAAAAAAAAAA-- ---AAAAAAAAAAA-- -AAAAAAAAAAAAA-- -AAAAAAAAAAAAA-- -AAAAAAAAAAAAA-- -AAAAAAAAAAAAA-- -AAAAAAAAAAAAA-- -AAAAAAAAAAAAA-- -AAAAAAAAAAAAA-- -AAAAAAAAAAAAA-- -AAAAAAAAAAAAA-- -AAAAAAAAAAAA--- -AAAAAAAAAAAAA-- -AAAAAAAAAAAAA-- AAAAAAAAAIIIII-- AAAAAAAAAGGGGGG- AAAAAAAAAGGGGGGG AAAAAAAAAGGGGGGG AAAAAAAAAIIIIIII AAAAAAAAAMMMMMMM AAAAAA--AOOOOOO- AAAAA---AAAAAAA- AAAAA---AAAAAA-- AAAAAA-AAAAAAA-- AAAAAAAAAAAAA--- -AAAAAAAAAAA---- --AAAAAAAAAA---- --AAAAAAAA------ ----AAAAA------- ---------------- 
---AAAAAAAAAAA-- ---AAAAAAAAAA--- ----AAAAAAAAA--- ---AAAAAAAAAA--- ---AAAAAAAAAA--- ---AAAAAAAAAA--- ---AAAAAAAAA---- ---AAAAAAAAA---- -AAAAAAAAAAA---- -AAAAAAAAAAA---- -AAAAAAAAAAA---- -AAAAAAAAAA----- -AAAAAAAAAAA---- -AAAAAAAAAAA---- -AAAAAAAAAAA---- -AAAAAAAAIIII--- -AAAAAAAAGGGG--- -AAAAAAAAGGGGG-- AAAAAAAAAGGGGG-- AAAAAAAAAIIIII-- AAAAAAAAAMMMMM-- AAAAAA--AFFFFF-- AAAAA---AAAAAA-- AAAAAA-AAAAAA--- AAAAAAAAAAAAA--- -AAAAAAAAAAA---- -AAAAAAAAAAA---- --AAAAAAAAA----- ---AAAAAAA------ -----AAA-------- ---------------- 
-----AAAAAAA---- -----AAAAAA----- ------AAAAA----- -----AAAAAA----- -----AAAAAA----- -----AAAAAA----- -----AAAAA------ -----AAAAA------ -----AAAA------- ---------------- ---------------- ---------------- ---------------- ---AAAAAAA------ -AAAAAAAAMM----- -AAAAAAAAGG----- -AAAAAAAAII----- -AAAAAAAAGG----- -AAAAAAAAIII---- -AAAAAAAAAAAA--- -AAAAAAAAAAAA--- -AAAAA-AAAAAA--- -AAAAA-AAAAAA--- -AAAAAAAAAAAA--- -AAAAAAAAAAA---- -AAAAAAAAAAA---- -AAAAAAAAAAA---- --AAAAAAAAA----- ---AAAAAAA------ ---------------- ---------------- 
---------------- ---------------- ---------------- ---------------- ---------------- ---------------- ---------------- ---------------- ---------------- ---------------- ---------------- ---------------- ---------------- ---------------- ---------------- ---------------- ---------------- ---AAA-AANN----- --AAAAAAAII----- -AAAAAAAAAAA---- -AAAAAAAAAAA---- -AAAAAAAAAAA---- -AAAAAAAAAAA---- -AAAAAAAAAA----- -AAAAAAAAAA----- -AAAAAAAAAA----- --AAAAAAAAA----- ---AAAAAAAA----- ----AAAAA------- ---------------- ---------------- 
---------------- ---------------- ---------------- ---------------- ---------------- ---------------- ---------------- ---------------- ---------------- ---------------- ---------------- ---------------- ---------------- ---------------- ---------------- ---------------- ---------------- ---AAAAAAA------ --AAAAAAANN----- -AAAAAAAAAA----- -AAAAAAAAAA----- -AAAAAAAAAA----- -AAAAAAAAAA----- -AAAAAAAAAA----- --AAAAAAAAA----- --AAAAAAAAA----- ---AAAAAAAA----- ---AAAAAAA------ ---------------- ---------------- ---------------- 
---------------- ---------------- ---------------- ---------------- ---------------- ---------------- ---------------- ---------------- ---------------- ---------------- ---------------- ---------------- ---------------- ---------------- ---------------- ---------------- ---------------- --AAAAAA-------- --AAAAAAAAA----- --AAAAAAAAA----- --AAAAAAAAA----- --AAAAAAAAA----- --AAAAAAAAA----- --AAAAAAAAA----- --AAAAAAAAA----- ---AAAAAAAA----- ---AAAAAAA------ ---------------- ---------------- ---------------- ---------------- 
---------------- ---------------- ---------------- ---------------- ---------------- ---------------- ---------------- ---------------- ---------------- ---------------- ---------------- ---------------- ---------------- ---------------- ---------------- ---------------- ---------------- ---AAAA--------- ---AAAAAAA------ ---AAAAAAA------ ---AAAAAAA------ ---AAAAAAA------ ---AAAAAAA------ ---AAAAAAA------ ----AAAAAA------ ---------------- ---------------- ---------------- ---------------- ---------------- ---------------- 
---------------- ---------------- ---------------- ---------------- ---------------- ---------------- ---------------- ---------------- ---------------- ---------------- ---------------- ---------------- ---------------- ---------------- ---------------- ---------------- ---------------- ---------------- ----AAAAA------- ----AAAAAA------ ----AAAAAA------ -----AAAA------- ---------------- ---------------- ---------------- ---------------- ---------------- ---------------- ---------------- ---------------- ---------------- 
