model
size = 16 31 31, scale = 0.05, origin = -y
material 
  colors = A:#000 B:#63C C:#222 D:#66C E:#444 F:#96C G:#111 H:#FC3 I:#FC6 J:#777 K:#555
voxels
---------------- ---------------- ---------------- ---------------- ---------------- ---------------- ---------------- ---------------- ---------------- ---------------- ---------------- ---------------- ---------------- ---------------- ---------------- ---------------- ---------------- ---------------- ----AAAAA------- ----AAAAAA------ ----AAAAAA------ -----AAAA------- ---------------- ---------------- ---------------- ---------------- ---------------- ---------------- ---------------- ---------------- ---------------- 
---------------- ---------------- ---------------- ---------------- ---------------- ---------------- ---------------- ---------------- ---------------- ---------------- ---------------- ---------------- ---------------- ---------------- ---------------- ---------------- ---------------- ---AAAA--------- ---AAAAAAA------ ---AAAAAAA------ ---AAAAAAA------ ---AAAAAAA------ ---AAAAAAA------ ---AAAAAAA------ ----AAAAAA------ ---------------- ---------------- ---------------- ---------------- ---------------- ---------------- 
---------------- ---------------- ---------------- ---------------- ---------------- ---------------- ---------------- ---------------- ---------------- ---------------- ---------------- ---------------- ---------------- ---------------- ---------------- ---------------- ---------------- --AAAAAA-------- --AAAAAAAAA----- --AAAAAAAAA----- --AAAAAAAAA----- --AAAAAAAAA----- --AAAAAAAAA----- --AAAAAAAAA----- --AAAAAAAAA----- ---AAAAAAAA----- ---AAAAAAA------ ---------------- ---------------- ---------------- ---------------- 
---------------- ---------------- ---------------- ---------------- ---------------- ---------------- ---------------- ---------------- ---------------- ---------------- ---------------- ---------------- ---------------- ---------------- ---------------- ---------------- ---------------- ---AAAAAAA------ --AAAAAAAAA----- -AAAAAAAAAA----- -AAAAAAAAAA----- -AAAAAAAAAA----- -AAAAAAAAAA----- -AAAAAAAAAA----- --AAAAAAAAA----- --AAAAAAAAA----- ---AAAAAAAA----- ---AAAAAAA------ ---------------- ---------------- ---------------- 
---------------- ---------------- ---------------- ---------------- ---------------- ---------------- ---------------- ---------------- ---------------- ---------------- ---------------- ---------------- ---------------- ---------------- ---------------- ---------------- ---------------- ---AAA-AAAA----- --AAAAAAAAA----- -AAAAAAAAAAA---- -AAAAAAAAAAA---- -AAAAAAAAAAA---- -AAAAAAAAAAA---- -AAAAAAAAAA----- -AAAAAAAAAA----- -AAAAAAAAAA----- --AAAAAAAAA----- ---AAAAAAAA----- ----AAAAA------- ---------------- ---------------- 
-----AAAAAAA---- -----AAAAAA----- ------AAAAA----- -----AAAAAA----- -----AAAAAA----- -----AAAAAA----- -----AAAAA------ -----AAAAA------ -----AAAA------- ---------------- ---------------- ---------------- ---------------- ---AAAAAAA------ --AAAAAAAAA----- --AAAAAAAAG----- --AAAAAAAAA----- --AAAAAAAAA----- -AAAAAAAAAAA---- -AAAAAAAAAAAA--- -AAAAAAAAAAAA--- -AAAAA-AAAAAA--- -AAAAA-AAAAAA--- -AAAAAAAAAAAA--- -AAAAAAAAAAA---- -AAAAAAAAAAA---- -AAAAAAAAAAA---- --AAAAAAAAA----- ---AAAAAAA------ ---------------- ---------------- 
---AAAAAAAAAAA-- ---AAAAAAAAAA--- ----AAAAAAAAA--- ---AAAAAAAAAA--- ---AAAAAAAAAA--- ---AAAAAAAAAA--- ---AAAAAAAAA---- ---AAAAAAADD---- --AAAAAAAABB---- --AAAAAAAABB---- --AAAAAAAABB---- --AAAAAAAAB----- --AAAAAAAACC---- --AAAAAAAAAA---- --AAAAAAAAEEE--- -AAAAAAAAABBB--- -AAAAAAAAACCC--- -AAAAAAAAACCCC-- AAAAAAAAAAAAAA-- AAAAAAAAAAAAAA-- AAAAAAAAAAAAAA-- AAAAAA--AAAAAA-- AAAAA---AAAAAA-- AAAAAA-AAAAAA--- AAAAAAAAAAAAA--- -AAAAAAAAAAA---- -AAAAAAAAAAA---- --AAAAAAAAA----- ---AAAAAAA------ -----AAA-------- ---------------- 
--AAAAAAAAAAAA-- --AAAAAAAAAAAA-- ---AAAAAAAAAAA-- --AAAAAAAAAAAA-- --AAAAAAAAAAAA-- --AAAAAAAAAAAA-- --AAAAAAAAAAAA-- --AAAAAAAADDDD-- --AAAAAAAABBBB-- -AAAAAAAAABBBB-- -AAAAAAAAABBBB-- -AAAAAAAAABBBB-- -AAAAAAAAABBB--- -AAAAAAAAAGGGG-- -AAAAAAAAAEEEEE- AAAAAAAAAABBBBB- AAAAAAAAAABBBBB- AAAAAAAAAABBBBB- AAAAAAAAAAFFFFF- AAAAAAAAAAEEEEE- AAAAAAAAAAAAAAA- AAAAAA--AAAAAAA- AAAAA---AAAAAAA- AAAAA---AAAAAA-- AAAAAA-AAAAAAA-- AAAAAAAAAAAAA--- -AAAAAAAAAAA---- --AAAAAAAAAA---- --AAAAAAAA------ ----AAAAA------- ---------------- 
--AAAAAAAAAAAAA- --AAAAAAAAAAAAA- --AAAAAAAAAAAAA- -AAAAAAAAAAAAAA- -AAAAAAAAAAAAAA- --AAAAAAAAAAAAA- --AAAAAAAAAAAAA- --AAAAAAAADDDDD- --AAAAAAAABBBBB- -AAAAAAAAABBBBB- -AAAAAAAAABBBBB- AAAAAAAAAABBBBB- -AAAAAAAAABBBBB- AAAAAAAAAAEEEEE- AAAAAAAAAAEEEEE- AAAAAAAAAABBBBBB AAAAAAAAAABBBBBB AAAAAAAAAABBBBBB AAAAAAAAAABBBBBB AAAAAAAAAABBBBBB AAAAAAAAAADDDDDD AAAAA---AAEEEEEE AAAA----AAGGGGGG AAAAA---AAAAAAA- AAAAAA-AAAAAAA-- AAAAAAAAAAAAA--- -AAAAAAAAAAAA--- --AAAAAAAAAA---- --AAAAAAAAA----- ---AAAAAA------- ---------------- 
-AAAAAAA-AAAAAA- AAAAAAAA-AAAAAA- AAAAAAAA-AAAAAAA -AAAAAAAAAAAAAAA -AAAAAAAAAAAAAAA -AAAAAAAAAAAAAAA -AAAAAAAAAAAAAAA -AAAAAAAAAFFFFFF -AAAAAAAAABBBBBB -AAAAAAAAABBBBBB AAAAAAAAAABBBBBB AAAAAAAAAABBBBBB AAAAAAAAAABBBBBB AAAAAAAAAACCCCCC AAAAAAAAAAEEEEEE AAAAAA-AAABBBBBB AAAAAA--AABBBBBB AAAAA---AABBBBBB AAAAA----ABBBBBB AAAAA----ABBBBBB AAAA------BBBBBB AAAA-----ABBBBBB AAAA-----ADDDDDD AAAAA---AAGGGGGG AAAAA---AAAAAA-- AAAAAA-AAAAAAA-- -AAAAAAAAAAAA--- -AAAAAAAAAAA---- --AAAAAAAAA----- ---AAAAAAA------ ----AAAAA------- 
-AAAAA----AAAAAA AAAAAAA---AAAAAA AAAAAAA---AAAAAA AAAAAAA---AAAAAA -AAAAAA---AAAAAA -AAAAAA---AAAAAA AAAAAAA---AAAAAA AAAAAAA---EEEEEE AAAAAAA---BBBBBB AAAAAA---ABBBBBB AAAAAA---ABBBBBB AAAAA----ABBBBBB AAAAA----ABBBBBB AAAAA----ADDDDDD AAAA------CCCCCC AAAA------BBBBBB AAAA------BBBBBB AAAA------BBBBBB AAAA------BBBBBB AAAA-------BBBBB AAA--------BBBBB AAA-------BBBBBB AAAA------FFFFFF AAAA-----AGGGGGG AAAAA---AACCCCC- AAAAAA-AAACCCC-- -AAAAAAAAAGGGG-- -AAAAAAAAAAAA--- --AAAAAAAAAA---- ---AAA---------- ---AA----------- 
-AAAAA-----AAAAA AAAAAA-----AAAAA AAAAAA-----AAAAA -AAAAA-----AAAAA -AAAAA-----AAAAA AAAAAA-----AAAAA AAAAAA-----AAAAA AAAAAA-----AAAAA AAAAAA-----CCCCC AAAAAA-----BBBBB AAAAA------BBBBB AAAAA------BBBBB AAAAA------BBBBB AAAA-------BBBBB AAAA-------EEEEE AAAA-------BBBBB AAAA-------BBBBB AAAA-------BBBBB AAA---------BBBB AAA---------BBBB AAA--------BBBBB AAA--------BBBBB AAAA------EEEEEE AAAA-----ACCCCCC AAAAA---AABBBBB- AAAAAA-AAABBBB-- -AAAAAAAAABBBB-- -AAAAAAAAACCC--- --AAAAAAAACC---- --AAA----------- ---A------------ 
-AAAA------AAAAA AAAAAA-----AAAAA AAAAAA-----AAAAA -AAAAA-----AAAAA -AAAAA-----AAAAA AAAAA------AAAAA AAAAA------AAAAA AAAAA------AAAAA AAAAA------AAAAA AAAAA------CCCCC AAAAA-------BBBB AAAAA-------BBBB AAAAA-------BBBB AAAA--------BBBB AAAA--------EEEE AAAA--------BBBB AAAA--------BBBB AAAA--------BBBB AAA---------BBBB AAA---------BBBB AAA---------BBBB AAA--------FFFFF AAAA------EEEEEE AAAA------BBBBBB AAAAA----ABBBBB- AAAAA--AAABBBB-- -AAAAAAAAABBBB-- -AAAAAAAAABBB--- --AAAAAAAADD---- --AAA----------- ---A------------ 
AAAAA-------AAAA AAAAA-------AAAA AAAAA-------AAAA -AAAA-------AAAA -AAAA-------AAAA AAAAA-------AAAA AAAAA-------AAAA AAAA--------EEEE AAAA--------EEEE AAAA--------GGGG AAAA--------FFFF AAAA--------BBBB AAAA--------BBBB AAAA--------BBBB AAAA--------CCCC AAAA--------BBBB AAAA---------BBB AAA----------BBB AAA----------BBB AAA---------BBBB AAA---------BBBB AAAA-------EEEEE AAAA-------BBBBB AAAA------BBBBBB AAAAA----ABBBBB- AAAAA---AABBBB-- -AAAAA-AAABBBB-- -AAAAAAAAACCC--- --AAAA---AGG---- --AAA----------- ---A------------ 
AAAAA-------AAAA AAAAA-------AAAA AAAAA-------AAAA -AAAA-------AAAA -AAAA-------AAAA AAAAA-------AAAA AAAAA-------AAAA AAAA--------DDDD AAAA--------BBBB AAAA--------CCCC AAA---------GGGG AAA---------FFFF AAA---------BBBB AAA---------BBBB AAA---------CCCC AAA---------BBBB AAA----------BBB AAA----------BBB AAA----------BBB AAA---------BBBB AAA---------CCCC AAAA-------FFFFF AAAA-------BBBBB AAAA------BBBBBB AAAAA-----DDDDD- AAAAA---AACCCC-- -AAAAA--AAGGGG-- -AAAAA--AAAAA--- --AAAA---AAA---- --AAA----------- ---A------------ 
AAAAA-------AAAA AAAAA-------AAAA AAAAAA------AAAA -AAAAA------AAAA -AAAAA------AAAA AAAAAA------AAAA AAAAA-------AAAA AAAA--------DDDD AAAA--------BBBB AAAA--------BBBB AAA----------CCC AAA----------GGG AAA----------DDD AAA----------BBB AAA----------DDD AAA----------BBB AAA----------BBB AAA----------BBB AAA----------BBB AAA---------BBBB AAA---------FFFF AAAA-------BBBBB AAAA-------DDDDD AAAA------EEEEEE AAAAA-----AAAAA- AAAAA---AAAAAA-- -AAAAA--AAAAAA-- -AAAAA--AAAAA--- --AAAA---AAA---- --AAA----------- ---A------------ 
AAAAA-------AAAA AAAAA-------AAAA AAAAAA------AAAA AAAAAA------AAAA -AAAAA------AAAA AAAAAA------AAAA AAAAAA------AAAA AAAAA-------DDDD AAAA--------BBBB AAAA--------BBBB AAA----------BBB AAA----------FFF AAA----------EEE AAA----------DDD AAA----------BBB AAA----------BBB AAA----------BBB AAA----------BBB AAA----------BBB AAA---------BBBB AAA---------BBBB AAAA-------CCCCC AAAA-------AAAAA AAAA------AAAAAA AAAAA----AAAAAA- AAAAA---AAAAAA-- -AAAAA-AAAAAAA-- -AAAAAAAAAAAA--- --AAAA---AAA---- --AAA----------- ---A------------ 
AAAAA------AAAAA AAAAA------AAAAA AAAAAA-----AAAAA AAAAAA-----AAAAA -AAAAA-----AAAAA AAAAAA-----AAAAA AAAAAA-----AAAAA AAAAA------DDDDD AAAA-------BBBBB AAAA-------BBBBB AAAA--------BBBB AAAA--------BBBB AAAA--------DDDD AAAA--------CCCC AAA---------BBBB AAA---------BBBB AAA---------BBBB AAA---------BBBB AAA---------BBBB AAA---------DDDD AAA---------CCCC AAA--------AAAAA AAAA------AAAAAA AAAA------AAAAAA AAAAA----AAAAAA- AAAAA---AAAAAA-- -AAAAAAAAAAAAA-- -AAAAAAAAAAAA--- --AAAAAAAAAA---- --AAA----------- ---A------------ 
AAAAA------AAAAA AAAAAA-----AAAAA AAAAAA-----AAAAA AAAAAA-----AAAAA -AAAAA-----AAAAA -AAAAA-----AAAAA AAAAAA----AAAAAA AAAAAA----DDDDDD AAAAAA----BBBBBB AAAAAA----BBBBBB AAAAAA-----BBBBB AAAAA------BBBBB AAAAA-------BBBB AAAA-------BBBBB AAAA-------FFFFF AAAA-------BBBBB AAAA-------BBBBB AAA--------BBBBB AAA---------FFFF AAA---------GGGG AAA--------AAAAA AAA--------AAAAA AAAA------AAAAAA AAAA-----AAAAAAA AAAAA---AAAAAAA- AAAAAA-AAAAAAA-- -AAAAAAAAAAAAA-- -AAAAAAAAAAAA--- --AAAAAAAAAA---- --AAA----------- ---A------------ 
AAAAAA----AAAAAA AAAAAA----AAAAAA AAAAAAA---AAAAAA AAAAAAA---AAAAAA -AAAAAA---AAAAAA -AAAAAA---AAAAAA AAAAAAA--AAAAAAA AAAAAAA--DDDDDDD AAAAAAA--BBBBBBB AAAAAAA--DDDDDDD AAAAAAA--FFFFFFF AAAAAA----BBBBBB AAAAA-----BBBBBB AAAAA-----BBBBBB AAAAA-----BBBBBB AAAA------BBBBBB AAAA------BBBBBB AAAA------DDDDDD AAAA-------GGGGG AAAA-------AAAAA AAA--------AAAAA AAA-------AAAAAA AAAA------AAAAAA AAAA-----AAAAAAA AAAAA---AAAAAAA- AAAAAA-AAAAAAA-- -AAAAAAAAAAAAA-- -AAAAAAAAAAAA--- --AAAAAAAAAA---- ---AAA---------- ---AA----------- 
AAAAAAA--A-AAAAA AAAAAAAA-A-AAAAA -AAAAAAA-A-AAAAA AAAAAAAA-A-AAAAA AAAAAAAAAA-AAAAA -AAAAAAAAAAAAAAA -AAAAAAAAAAAAAAA AAAAAAAAADDDDDDD AAAAAAAAABBBBBBB AAAAAAAAABBBBBBB AAAAAAAAAFFFFFFF AAAAAAAAACCCCCCC AAAAAAAAAEEEEEEE AAAAAAAAACCCCCCC AAAAAAAAAFFFFFFF AAAAAA-AABBBBBBB AAAAAA--ABBBBBBB AAAAA---ACCCCCCC AAAAA----EEEEEEE AAAA----AAAAAAAA AAAA----AAAAAAAA AAAA--AAAAAAAAAA AAAA--AAAAAAAAAA AAAAA---AAAAAAAA AAAAA---AAAAAAA- AAAAAA-AAAAAAA-- -AAAAAAAAAAAAA-- -AAAAAAAAAAAA--- --AAAAAAAAAA---- ---AAAAAAAA----- ----AAAAA------- 
AAAAAAAA-AAAAAAA -AAAAAAA-AAAAAAA -AAAAAAA-AAAAAAA -AAAAAAAAAAAAAAA AAAAAAAAAAAAAAAA -AAAAAAAAAAAAAAA AAAAAAAAAAAAAAAA AAAAAAAAADDDDDDD AAAAAAAAABBBBBBB AAAAAAAAACCCCCCC AAAAAAAAACCCCCCC AAAAAAAAAAAAAAAA AAAAAAAAAAAAAAAA AAAAAAAAAAAAAAAA AAAAAAAAAKKKKKKK AAAAAA-AACCCCCCC AAAAAA--ACCCCCCC AAAAA---AEEEEEEE AAAAA----IIIIIII AAAAA---AAAAAAAA AAAAA---AAAAAAAA AAAAA-AAAAAAAAAA AAAAA-AAAAAAAAAA AAAAA---AAAAAAA- AAAAA---AAAAAA-- AAAAAA-AAAAAAA-- --AAAAAAAAAAA--- --AAAAAAAAAA---- --AAAAAAAAA----- ---AAAAAAA------ ----AAAAA------- 
-AAAAAAAAAAAAAA- -AAAAAAAAAAAAAA- -AAAAAAAAAAAAAA- -AAAAAAAAAAAAAA- -AAAAAAAAAAAAAA- -AAAAAAAAAAAAAA- -AAAAAAAAAAAAAA- -AAAAAAAAGGGGGG- -AAAAAAAAGGGGGG- -AAAAAAAAAAAAAA- -AAAAAAAAAAAAAA- -AAAAAAAAAAAAAAA -AAAAAAAAAAAAAAA AAAAAAAAAAAAAAAA AAAAAAAAAJJJJJJJ AAAAAAAAAHHHHHHH AAAAAAAAAIIIIIII AAAAAAAAAHHHHHHH AAAAAAAAAIIIIIII AAAAAAAAAAAAAAAA AAAAAAAAAAAAAAAA AAAAA---AAAAAAAA AAAA----AAAAAAA- AAAAA---AAAAAAA- AAAAAA-AAAAAAA-- AAAAAAAAAAAAA--- -AAAAAAAAAAAA--- --AAAAAAAAAA---- --AAAAAAAAA----- ---AAAAAA------- ---------------- 
-AAAAAAAAAAAAA-- -AAAAAAAAAAAAA-- ---AAAAAAAAAAA-- -AAAAAAAAAAAAA-- -AAAAAAAAAAAAA-- -AAAAAAAAAAAAA-- -AAAAAAAAAAAAA-- -AAAAAAAAAAAAA-- -AAAAAAAAAAAAA-- -AAAAAAAAAAAAA-- -AAAAAAAAAAAAA-- -AAAAAAAAAAAAA-- -AAAAAAAAAAAA--- -AAAAAAAAAAAAA-- -AAAAAAAAAAAAA-- AAAAAAAAAIIIII-- AAAAAAAAAHHHHHH- AAAAAAAAAHHHHHHH AAAAAAAAAHHHHHHH AAAAAAAAAIIIIIII AAAAAAAAAJJJJJJJ AAAAAA--AKKKKKK- AAAAA---AAAAAAA- AAAAA---AAAAAA-- AAAAAA-AAAAAAA-- AAAAAAAAAAAAA--- -AAAAAAAAAAA---- --AAAAAAAAAA---- --AAAAAAAA------ ----AAAAA------- ---------------- 
---AAAAAAAAAAA-- ---AAAAAAAAAA--- ----AAAAAAAAA--- ---AAAAAAAAAA--- ---AAAAAAAAAA--- ---AAAAAAAAAA--- ---AAAAAAAAA---- ---AAAAAAAAA---- -AAAAAAAAAAA---- -AAAAAAAAAAA---- -AAAAAAAAAAA---- -AAAAAAAAAA----- -AAAAAAAAAAA---- -AAAAAAAAAAA---- -AAAAAAAAAAA---- -AAAAAAAAIIII--- -AAAAAAAAHHHH--- -AAAAAAAAHHHHH-- AAAAAAAAAHHHHH-- AAAAAAAAAIIIII-- AAAAAAAAAJJJJJ-- AAAAAA--AGGGGG-- AAAAA---AAAAAA-- AAAAAA-AAAAAA--- AAAAAAAAAAAAA--- -AAAAAAAAAAA---- -AAAAAAAAAAA---- --AAAAAAAAA----- ---AAAAAAA------ -----AAA-------- ---------------- 
-----AAAAAAA---- -----AAAAAA----- ------AAAAA----- -----AAAAAA----- -----AAAAAA----- -----AAAAAA----- -----AAAAA------ -----AAAAA------ -----AAAA------- ---------------- ---------------- ---------------- ---------------- ---AAAAAAA------ -AAAAAAAAJJ----- -AAAAAAAAHH----- -AAAAAAAAII----- -AAAAAAAAHH----- -AAAAAAAAIII---- -AAAAAAAAAAAA--- -AAAAAAAAAAAA--- -AAAAA-AAAAAA--- -AAAAA-AAAAAA--- -AAAAAAAAAAAA--- -AAAAAAAAAAA---- -AAAAAAAAAAA---- -AAAAAAAAAAA---- --AAAAAAAAA----- ---AAAAAAA------ ---------------- ---------------- 
---------------- ---------------- ---------------- ---------------- ---------------- ---------------- ---------------- ---------------- ---------------- ---------------- ---------------- ---------------- ---------------- ---------------- ---------------- ---------------- ---------------- ---AAA-AAEE----- --AAAAAAAII----- -AAAAAAAAAAA---- -AAAAAAAAAAA---- -AAAAAAAAAAA---- -AAAAAAAAAAA---- -AAAAAAAAAA----- -AAAAAAAAAA----- -AAAAAAAAAA----- --AAAAAAAAA----- ---AAAAAAAA----- ----AAAAA------- ---------------- ---------------- 
---------------- ---------------- ---------------- ---------------- ---------------- ---------------- ---------------- ---------------- ---------------- ---------------- ---------------- ---------------- ---------------- ---------------- ---------------- ---------------- ---------------- ---AAAAAAA------ --AAAAAAAEE----- -AAAAAAAAAA----- -AAAAAAAAAA----- -AAAAAAAAAA----- -AAAAAAAAAA----- -AAAAAAAAAA----- --AAAAAAAAA----- --AAAAAAAAA----- ---AAAAAAAA----- ---AAAAAAA------ ---------------- ---------------- ---------------- 
---------------- ---------------- ---------------- ---------------- ---------------- ---------------- ---------------- ---------------- ---------------- ---------------- ---------------- ---------------- ---------------- ---------------- ---------------- ---------------- ---------------- --AAAAAA-------- --AAAAAAAAA----- --AAAAAAAAA----- --AAAAAAAAA----- --AAAAAAAAA----- --AAAAAAAAA----- --AAAAAAAAA----- --AAAAAAAAA----- ---AAAAAAAA----- ---AAAAAAA------ ---------------- ---------------- ---------------- ---------------- 
---------------- ---------------- ---------------- ---------------- ---------------- ---------------- ---------------- ---------------- ---------------- ---------------- ---------------- ---------------- ---------------- ---------------- ---------------- ---------------- ---------------- ---AAAA--------- ---AAAAAAA------ ---AAAAAAA------ ---AAAAAAA------ ---AAAAAAA------ ---AAAAAAA------ ---AAAAAAA------ ----AAAAAA------ ---------------- ---------------- ---------------- ---------------- ---------------- ---------------- 
---------------- ---------------- ---------------- ---------------- ---------------- ---------------- ---------------- ---------------- ---------------- ---------------- ---------------- ---------------- ---------------- ---------------- ---------------- ---------------- ---------------- ---------------- ----AAAAA------- ----AAAAAA------ ----AAAAAA------ -----AAAA------- ---------------- ---------------- ---------------- ---------------- ---------------- ---------------- ---------------- ---------------- ---------------- 
