model
size = 19 23 17, scale = 0.05, origin = -y
material 
  colors = A:#C96 B:#C60 C:#111 D:#930 E:#960 F:#630 G:#FF0 H:#C90
voxels
------------------- ------------------- ------------------- ------------------- ------------------- ------------------- ------------------- ------------------- ------------------- ------------------- ------------------- ------------------- ------------------- ------------------- ------------------- ------------------- -------DBDBD------- -------DDDDD------- ------------------- ------------------- ------------------- ------------------- ------------------- 
------------------- ------------------- ------------------- ------------------- ------------------- ------------------- ------------------- ------------------- ------------------- ------------------- --------AAA-------- ------------------- ------------------- ------------------- ------------------- ------------------- -----DBAAAAABD----- -----DDBBBBBDD----- -------BBBBB------- ------------------- ------------------- ------------------- ------------------- 
--------CCC-------- ------CCCCCCC------ -----CCCCCCCCC----- -----CCCCCCCCC----- -----CCCCCCCCC----- -----CCCCCCCCC----- -----CCCCCCCCC----- -----CCCFFFCCC----- -----CCCCCCCCC----- -----CAAAAAAAC----- -----AAAAAAAAA----- -----AAAAAAAAA----- -----AAAAAAAAA----- -----CHAAAAACH----- -----EEAAAAAEE----- -----AAAAAAAAA----- ---DBAAAAAAAAABD--- ---DDBBBBBBBBBDD--- -----BBBBBBBBB----- -------BBBBB------- ------------------- ------------------- ------------------- 
--------CCC-------- ------CCAAACC------ -----CAAAAAAAC----- ----CAAAAAAAAAC---- ----CAAAAAAAAAC---- ----CAAAAAAAAAC---- ----CAAAAAAAACC---- ----CAAAAAAAACC---- ----CAAAAAAAACC---- ----CAAAAAAAAAC---- ----AAAAAAAAAAA---- ----AAAAAAAAAAA---- ----AAAAAAAAAAA---- ----AAAAAAAAAAA---- ----AAAAAAAAAAA---- ----AAAAAAAAAAA---- ---BAAAAAAAAAAAB--- ---DBBBBBBBBBBBD--- ----BBBBBBBBBBB---- -----BBBBBBBBB----- ------------------- ------------------- ------------------- 
------------------- -------CCCCC------- -----CCAAAAACC----- ----CAAAAAAAAAC---- ---CAAAAAAAAAAC---- ---CAAAAAAAAAAAC--- ---CAAAAAAAAAAAC--- ---CAAAAAAAAAAAC--- ---CAAAAAAAAAAAC--- ---CAAAAAAAAAAAC--- ---CAAAAAAAAAAAC--- ---AAAAAAAAAAAAA--- ---AAAAAAAAAAAAA--- ---AAAAAAAAAAAAA--- ---AAAAAAAAAAAAA--- ---AAAAAAAAAAAAA--- --DAAAAAAAAAAAAAD-- --DBBBBBBBBBBBBBD-- ---BBBBBBBBBBBBB--- ----BBBBBBBBBBB---- -------BBBBB------- ------------------- ------------------- 
------------------- ------------------- -------AAAAA------- -----CAAAAAAAC----- ----CAAAAAAAAAC---- ---CAAAAAAAAAAC---- ---CAAAAAAAAAAAC--- ---CAAAAAAAAAAAC--- ---CAAAAAAAAAAAC--- ---CAAAAAAAAAAAC--- ---CAAAAAAAAAAAC--- ---AAAAAAAAAAAAA--- ---AAAAAAAAAAAAA--- ---AAAAAAAAAAAAA--- ---AAAAAAAAAAAAA--- ---AAAAAAAAAAAAA--- --BAAAAAAAAAAAAAB-- --DBBBBBBBBBBBBBD-- ---BBBBBBBBBBBBB--- ----BBBBBBBBBBB---- ------BBBBBBB------ ------------------- ------------------- 
------------------- ---------A--------- ------AAAAAAA------ -----AAAAAAAAA----- -----AAAAAAAAA----- ----CAAAAAAAAAC---- ---CAAAAAAAAAAC---- ---CAAAAAAAAAAAC--- --CAAAAAAAAAAAAAC-- --CAAAAAAAAAAAAAC-- --CAAAAAAAAAAAAAC-- --AAAAAAAAAAAAAAA-- --AAAAAAAAAAAAAAA-- --AAAAAAAAAAAAAAA-- --AAAAAAAAAAAAAAA-- ---AAAAAAAAAAAAA--- -DAAAAAAAAAAAAAAAD- -DBBBBBBBBBBBBBBBD- --BBBBBBBBBBBBBBB-- ---BBBBBBBBBBBBB--- -----BBBBBBBBB----- ------------------- ------------------- 
------------------- -------AAAAA------- ------AAAAAAA------ -----AAAAAAAAA----- -----AAAAAAAAA----- ----AAAAAAAAAAA---- ----CAAAAAAAAAC---- ---CAAAAAAAAAAAC--- ---CAAAAAAAAAAAC--- --CCAAAAAAAAAAACC-- --CAAAAAAAAAAAAAC-- --CAAAAAAAAAAAAAC-- --AAAAAAAAAAAAAAA-- --AAAAAAAAAAAAAAA-- --AAAAAAAAAAAAAAA-- --AAAAAAAAAAAAAAA-- -BAAAAAAAAAAAAAAAB- -DBBBBBBBBBBBBBBBD- --BBBBBBBBBBBBBBB-- ---BBBBBBBBBBBBB--- -----BBBBBBBBB----- -------BBBBB------- ------------------- 
------------------- -------AA-AA------- ------AAA-AAA------ -----AAAA-AAAA----- -----AAAA-AAAA----- ----AAAAA-AAAAA---- ----AAAAA-AAAAA---- ----AAAAA-AAAAA---- ----AAAAA-AAAAA---- --AAAAAAA-AAAAAAA-- GAAAAAAAA-AAAAAAAAG AAAAAAAAA-AAAAAAAAA AAAAAAAAA-AAAAAAAAA AAAAAAAAA-AAAAAAAAA --AAAAAAA-AAAAAAA-- --AAAAAAA-AAAAAAA-- CDAAAAAAABAAAAAAADC CDBBBBBBBBBBBBBBBDC -CBBBBBBBBBBBBBBBC- --CBBBBBBBBBBBBBC-- ---CCBBBBBBBBBCC--- -----CCCCCCCCC----- -------CCCCC------- 
------------------- --------AAA-------- -------AAAAA------- ------AAAAAAA------ -----AAAAAAAAA----- -----AAAAAAAAA----- ----AAAAAAAAAAA---- ----AAAAAAAAAAA---- ---AAAAAAAAAAAAA--- --AAAAAAAAAAAAAAA-- --AAAAAAAAAAAAAAA-- --AAAAAAAAAAAAAAA-- --AAAAAAAAAAAAAAA-- --AAAAAAAAAAAAAAA-- --AAAAAAAAAAAAAAA-- --AAAAAAAAAAAAAAA-- -BAAAAAAAAAAAAAAAB- -DBBBBBBBBBBBBBBBD- --BBBBBBBBBBBBBBB-- ---BBBBBBBBBBBBB--- -----BBBBBBBBB----- -------BBBBB------- ------------------- 
------------------- ------------------- --------AAA-------- -------AAAAA------- ------AAAAAAA------ -----AAAAAAAAA----- ----AAAAAAAAAAA---- ----AAAAAAAAAAA---- ---AAAAAAAAAAAAA--- ---AAAAAAAAAAAAA--- --AAAAAAAAAAAAAAA-- --AAAAAAAAAAAAAAA-- --AAAAAAAAAAAAAAA-- --AAAAAAAAAAAAAAA-- --AAAAAAAAAAAAAAA-- ---AAAAAAAAAAAAA--- -DAAAAAAAAAAAAAAAD- -DBBBBBBBBBBBBBBBD- --BBBBBBBBBBBBBBB-- ---BBBBBBBBBBBBB--- -----BBBBBBBBB----- ------------------- ------------------- 
------------------- ------------------- ------------------- --------AAA-------- -------AAAAA------- ------AAAAAAA------ -----AAAAAAAAA----- ----AAAAAAAAAAA---- ---AAAAAAAAAAAAA--- ---AAAAAAAAAAAAA--- ---AAAAAAAAAAAAA--- ---AAAAAAAAAAAAA--- ---AAAAAAAAAAAAA--- ---AAAAAAAAAAAAA--- ---AAAAAAAAAAAAA--- ---AAAAAAAAAAAAA--- --BAAAAAAAAAAAAAB-- --DBBBBBBBBBBBBBD-- ---BBBBBBBBBBBBB--- ----BBBBBBBBBBB---- ------BBBBBBB------ ------------------- ------------------- 
------------------- ------------------- ------------------- ---------A--------- --------AAA-------- -------AAAAA------- -----AAAAAAAAA----- -----AAAAAAAAA----- ----AAAAAAAAAAA---- ---AAAAAAAAAAAAA--- ---AAAAAAAAAAAAA--- ---AAAAAAAAAAAAA--- ---AAAAAAAAAAAAA--- ---AAAAAAAAAAAAA--- ---AAAAAAAAAAAAA--- ---AAAAAAAAAAAAA--- --DAAAAAAAAAAAAAD-- --DBBBBBBBBBBBBBD-- ---BBBBBBBBBBBBB--- ----BBBBBBBBBBB---- -------BBBBB------- ------------------- ------------------- 
------------------- ------------------- ------------------- ------------------- ------------------- --------AAA-------- ------AAAAAAA------ -----AAAAAAAAA----- -----AAAAAAAAA----- ----AAAAAAAAAAA---- ----AAAAAAAAAAA---- ----AAAAAAAAAAA---- ----AAAAAAAAAAA---- ----AAAAAAAAAAA---- ----AAAAAAAAAAA---- ----AAAAAAAAAAA---- ---BAAAAAAAAAAAB--- ---DBBBBBBBBBBBD--- ----BBBBBBBBBBB---- -----BBBBBBBBB----- ------------------- ------------------- ------------------- 
------------------- ------------------- ------------------- ------------------- ------------------- ------------------- ---------A--------- -------AAAAA------- -------AAAAA------- ------AAAAAAA------ -----AAAAAAAAA----- -----AAAAAAAAA----- -----AAAAAAAAA----- -----AAAAAAAAA----- -----AAAAAAAAA----- -----AAAAAAAAA----- ---DBAAAAAAAAABD--- ---DDBBBBBBBBBDD--- -----BBBBBBBBB----- -------BBBBB------- ------------------- ------------------- ------------------- 
------------------- ------------------- ------------------- ------------------- ------------------- ------------------- ------------------- ------------------- ------------------- --------AAA-------- -------AAAAA------- -------AAAAA------- -------AAAAA------- -------AAAAA------- -------AAAAA------- -------AAAAA------- -----DBAAAAABD----- -----DDBBBBBDD----- -------BBBBB------- ------------------- ------------------- ------------------- ------------------- 
------------------- ------------------- ------------------- ------------------- ------------------- ------------------- ------------------- ------------------- ------------------- ------------------- ------------------- ------------------- ------------------- ------------------- ------------------- ------------------- -------DBDBD------- -------DDDDD------- ------------------- ------------------- ------------------- ------------------- ------------------- 
