model
size = 32, scale = 0.05, origin = -y
material 
  colors = A:#555 B:#600 C:#111 D:#F99 E:#EEE F:#888 G:#222 H:#AAA I:#DDD J:#444
voxels
13-4(6A26-)3AG2A2(26-6A)26-2AG3A3(26-6A)26-3AG2A26-5AG3(26-6A)26-G5A26-6A26-3AG2A26-6A27-4A377-10A3(22-2A6-2A)22-HA4(6-2A22-2A)6-2A22-FA6-AF8(22-2A6-2A)23-A6-A2(24-8A)25-2AG3A27-4A29-2A281-12A3(20-A10-A)20-H4(10-A20-A)2(10-H20-A10-A20-A)10-A20-G10-G20-A10-A20-H2(10-A20-A)10-H20-2A8-2A21-A8-A22-A3-2A3-A22-FA2-2A2-AF23-2A4-2A25-2A2-2A27-4A247-14A6(18-A12-A)18-G12-G4(18-A12-A)18-H2(12-A18-A)12-A18-F12-F3(18-A12-A)18-HA10-2A18-2(2A4-)2A19-A10-H20-2A8-2A21-GA6-AG23-2A4-2A25-3AG2A213-16A4(16-A14-A)16-F14-F5(16-A14-A)16-A14-H6(16-A14-A)16-F14-F2(16-A14-A)16-2A12-AH17-A12-A18-GA10-AG19-2A8-2A21-2A6-HA24-6A180-18A14-G16-G5(14-A16-A)14-H2(16-A14-A)16-A14-F16-F2(14-A16-A)14-G16-G6(14-A16-A)2(14-2A)14-3A12-3A15-A14-A16-A14-A17-A12-A19-2A8-2A22-2A4-2A26-G3A148-20A3(12-A18-A)12-F18-F11(12-A18-A)12-H18-H2(12-A18-A)12-F18-F12-A-A14-A-A13-2(2A14-)HA14-2A15-A-A10-A-A16-A2-A8-A2-A17-2A-A6-A-2A20-2A6-2A24-2A2-2A28-2A117-20A8(12-A18-A)12-G18-G11(12-A18-A)2(12-4A)13-8A2-8A14-18A16-14A19-12A22-8A25-6A27-4A29-2A84-22A12(10-A20-A)10-A20-H2(10-A20-A)2(10-D20-D)10-DA18-AD10-D2A16-2AD11-4D12-4D13-D2-12B2-D15-D3-8B3-D17-D3-6B3-D19-D3-4B3-D21-2D2-2B2-2D24-D4-D27-D2-D29-2D111-32AF5A20-5AF-2AF2A20-2AF2A2-AF3A20-3AFA3-4A20-4A4-AG2A20-2AGA5-3A20-3A6-3A20-3A7-2A20-2A8-2A20-2A9-2(A20-A10-)F20-F2(10-A20-A)2(10-D20-D)11-2(E18BE12-)I-16B-I12-E18BE13-I16-I15-E14-E17-I12-I19-E10-E21-IE6-EI24-E4-I27-I2-I29-EI116-G20AG10(10-A20-A)10-F20-F3(10-A20-A)10-D20-D10-IA18BAI11-I18-I2(44-E18-E)46-E14-E50-E-E6-E-E23-E4-E178-22A5(10-A20-A)10-F20-F10-A20-A10-H4(20-A10-A)20-A10-F20-F10-A20-A10-DA18-AD10-2D18B2D11-2(E18-E12-I18-I12-)E18-E13-I16-I15-E14-E17-I12-I19-E10-E20-I10-I21-E8-E24-E4-E27-2(EI)83-22A3(10-A20-A)10-A20-H6(10-A20-A)10-G20-G4(10-A20-A)10-DA18-AD10-3D16B3D11-2(D18BD12-)D2-2C10-2C2-D12-D2-2C10-2C2-D13-D16-D15-D14-D17-D12-D19-D10-D20-D10-D21-2E6-2E24-E4-E27-2(EI)83-22A10-A20-G10-A20-A10-H2(20-A10-A)20-H3(10-A20-A)10-F20-F4(10-A20-A)10-F5(20-A10-A)3-2C10-2C3-A11-A18BA12-A18BA13-A16BA15-D14BD17-D12BD19-D10-D20-D-B6-B-D21-2D6-2D24-D4-D27-4D29-2J53-20A3(12-A18-A)12-A18-H2(12-A18-A)12-G18-G8(12-A18-A)12-H2(18-A12-A)18-A12-F2-2C10-2C2-F2(12-A-4C8-4C-A)13-A-2C10-2C-A15-A14-A17-A12-A19-A10BA20-ABA6BABA21-2A6B2A24-A4BA27-4A29-2A30-2J21-20A12-A18-A12-H4(18-A12-A)18-A12-F18-F3(12-A18-A)12-H18-A12-A18-H4(12-A18-A)12-G18-G12-A2-2C10-2C2-2(A12-A-4C8-4C-)A13-A-2C10-2C-A14-A16-A15-A14-A16-A14-A17-2A10-2A20-A8-A23-2A4-2A26-A2-A29-2A86-18A4(14-A16-A)14-F16-F3(14-A16-A)14-A16-H2(14-A16-A)14-A16-H14-A16-A14-F16-F3(14-A16-A)14-A-2C10-2C-A14-AE3C8-3CE2(A14-A4C8-4C)A15-H2C10-2CA16-A14-G17-A12-A19-A10-A21-3A4-3A24-CA2-AC28-2A119-16A16-H14-H5(16-A14-A)2(16-G14-G3(16-A14-A))2(16-A14-A)16-A14-H16-A14-A16-2EC10-C2E2(16-E3C8-3CE)17-EC10-CE18-2A10-2A19-2A8-AH21-3A4-3A25-4A29-2A152-14A2(18-A12-A)18-A12-H8(18-A12-A)18-H12-A18-A12-H18-A12-A18-G12-G3(18-A12-A)18-2E10-2E18-CE10-EC18-CEA8-AEC18-E2A8-2AE20-2A6-2A23-FA4-AF26-H3A216-12A3(20-A10-A)20-G10-G20-A10-A20-H10-A20-A10-A2(20-F10-F3(20-A10-A))2(20-A10-A)20-2A8-2A21-2(A8-A22-)2A6-2A23-2A4-HA25-2A2-2A27-4A249-10A22-GA6-AG3(22-2A6-2A)22-2A6-AH10(22-2A6-2A)22-2A6-HA22-2A6-2A23-2(A6-A24-)2A4-2A25-AG4A27-4A29-2A284-6A7(26-2A2-2A)26-2A2-AH2(26-2A2-2A)26-2A2-HA26-2A2-2A26-6A26-2AG3A26-F4AG2(26-6A)26-2AH3A26-2AG3A27-3AH381-12(2A30-)2A638-2A30-AG2(30-2A)30-2F3(30-2A)30-HA3(30-2A)670-10(2A30-)AG702-2A30-2F3(30-2A)30-AG4(30-2A)734-3(2A30-)AH30-2A30-GA2(30-2A)30-HA766-5(2A30-)AH2(30-2A)798-2A30-2F2(30-2A)30-AH2(30-2A)830-4(2A30-)2A894-2(2A30-)2A958-2A1007-
