model
size = 30, scale = 0.05, origin = -y
material 
  colors = A:#86C166
voxels
AAAAAAAAAAAA------AAAAAAAAAAAA AAAAAAAAAAAA------AAAAAAAAAAAA AAAAAAAAAAAA------AAAAAAAAAAAA AAAAAAAAAAAA------AAAAAAAAAAAA AAAAAAAAAAAA------AAAAAAAAAAAA AAAAAAAAAAAA------AAAAAAAAAAAA AAAAAAAAAAAA------AAAAAAAAAAAA AAAAAAAAAAAA------AAAAAAAAAAAA AAAAAAAAAAAA------AAAAAAAAAAAA AAAAAAAAAAAA------AAAAAAAAAAAA AAAAAAAAAAAA------AAAAAAAAAAAA AAAAAAAAAAAA------AAAAAAAAAAAA AAAAAAAAAAAA------AAAAAAAAAAAA AAAAAAAAAAAA------AAAAAAAAAAAA AAAAAAAAAAAA------AAAAAAAAAAAA AAAAAAAAAAAAAAAAAAAAAAAAAAAAAA AAAAAAAAAAAAAAAAAAAAAAAAAAAAAA AAAAAAAAAAAAAAAAAAAAAAAAAAAAAA AAAAAAAAAAAAAAAAAAAAAAAAAAAAAA AAAAAAAAAAAAAAAAAAAAAAAAAAAAAA AAAAAAAAAAAAAAAAAAAAAAAAAAAAAA AAAAAAAAAAAAAAAAAAAAAAAAAAAAAA AAAAAAAAAAAAAAAAAAAAAAAAAAAAAA AAAAAAAAAAAAAAAAAAAAAAAAAAAAAA AAAAAAAAAAAAAAAAAAAAAAAAAAAAAA AAAAAAAAAAAAAAAAAAAAAAAAAAAAAA AAAAAAAAAAAAAAAAAAAAAAAAAAAAAA AAAAAAAAAAAAAAAAAAAAAAAAAAAAAA AAAAAAAAAAAAAAAAAAAAAAAAAAAAAA AAAAAAAAAAAAAAAAAAAAAAAAAAAAAA 
AAAAAAAAAAAA------AAAAAAAAAAAA AAAAAAAAAAAA------AAAAAAAAAAAA AAAAAAAAAAAA------AAAAAAAAAAAA AAAAAAAAAAAA------AAAAAAAAAAAA AAAAAAAAAAAA------AAAAAAAAAAAA AAAAAAAAAAAA------AAAAAAAAAAAA AAAAAAAAAAAA------AAAAAAAAAAAA AAAAAAAAAAAA------AAAAAAAAAAAA AAAAAAAAAAAA------AAAAAAAAAAAA AAAAAAAAAAAA------AAAAAAAAAAAA AAAAAAAAAAAA------AAAAAAAAAAAA AAAAAAAAAAAA------AAAAAAAAAAAA AAAAAAAAAAAA------AAAAAAAAAAAA AAAAAAAAAAAA------AAAAAAAAAAAA AAAAAAAAAAAA------AAAAAAAAAAAA AAAAAAAAAAAAAAAAAAAAAAAAAAAAAA AAAAAAAAAAAAAAAAAAAAAAAAAAAAAA AAAAAAAAAAAAAAAAAAAAAAAAAAAAAA AAAAAAAAAAAAAAAAAAAAAAAAAAAAAA AAAAAAAAAAAAAAAAAAAAAAAAAAAAAA AAAAAAAAAAAAAAAAAAAAAAAAAAAAAA AAAAAAAAAAAAAAAAAAAAAAAAAAAAAA AAAAAAAAAAAAAAAAAAAAAAAAAAAAAA AAAAAAAAAAAAAAAAAAAAAAAAAAAAAA AAAAAAAAAAAAAAAAAAAAAAAAAAAAAA AAAAAAAAAAAAAAAAAAAAAAAAAAAAAA AAAAAAAAAAAAAAAAAAAAAAAAAAAAAA AAAAAAAAAAAAAAAAAAAAAAAAAAAAAA AAAAAAAAAAAAAAAAAAAAAAAAAAAAAA AAAAAAAAAAAAAAAAAAAAAAAAAAAAAA 
AAAAAAAAAAAA------AAAAAAAAAAAA AAAAAAAAAAAA------AAAAAAAAAAAA AAAAAAAAAAAA------AAAAAAAAAAAA AAAAAAAAAAAA------AAAAAAAAAAAA AAAAAAAAAAAA------AAAAAAAAAAAA AAAAAAAAAAAA------AAAAAAAAAAAA AAAAAAAAAAAA------AAAAAAAAAAAA AAAAAAAAAAAA------AAAAAAAAAAAA AAAAAAAAAAAA------AAAAAAAAAAAA AAAAAAAAAAAA------AAAAAAAAAAAA AAAAAAAAAAAA------AAAAAAAAAAAA AAAAAAAAAAAA------AAAAAAAAAAAA AAAAAAAAAAAA------AAAAAAAAAAAA AAAAAAAAAAAA------AAAAAAAAAAAA AAAAAAAAAAAA------AAAAAAAAAAAA AAAAAAAAAAAAAAAAAAAAAAAAAAAAAA AAAAAAAAAAAAAAAAAAAAAAAAAAAAAA AAAAAAAAAAAAAAAAAAAAAAAAAAAAAA AAAAAAAAAAAAAAAAAAAAAAAAAAAAAA AAAAAAAAAAAAAAAAAAAAAAAAAAAAAA AAAAAAAAAAAAAAAAAAAAAAAAAAAAAA AAAAAAAAAAAAAAAAAAAAAAAAAAAAAA AAAAAAAAAAAAAAAAAAAAAAAAAAAAAA AAAAAAAAAAAAAAAAAAAAAAAAAAAAAA AAAAAAAAAAAAAAAAAAAAAAAAAAAAAA AAAAAAAAAAAAAAAAAAAAAAAAAAAAAA AAAAAAAAAAAAAAAAAAAAAAAAAAAAAA AAAAAAAAAAAAAAAAAAAAAAAAAAAAAA AAAAAAAAAAAAAAAAAAAAAAAAAAAAAA AAAAAAAAAAAAAAAAAAAAAAAAAAAAAA 
AAAAAAAAAAAA------AAAAAAAAAAAA AAAAAAAAAAAA------AAAAAAAAAAAA AAAAAAAAAAAA------AAAAAAAAAAAA AAAAAAAAAAAA------AAAAAAAAAAAA AAAAAAAAAAAA------AAAAAAAAAAAA AAAAAAAAAAAA------AAAAAAAAAAAA AAAAAAAAAAAA------AAAAAAAAAAAA AAAAAAAAAAAA------AAAAAAAAAAAA AAAAAAAAAAAA------AAAAAAAAAAAA AAAAAAAAAAAA------AAAAAAAAAAAA AAAAAAAAAAAA------AAAAAAAAAAAA AAAAAAAAAAAA------AAAAAAAAAAAA AAAAAAAAAAAA------AAAAAAAAAAAA AAAAAAAAAAAA------AAAAAAAAAAAA AAAAAAAAAAAA------AAAAAAAAAAAA AAAAAAAAAAAAAAAAAAAAAAAAAAAAAA AAAAAAAAAAAAAAAAAAAAAAAAAAAAAA AAAAAAAAAAAAAAAAAAAAAAAAAAAAAA AAAAAAAAAAAAAAAAAAAAAAAAAAAAAA AAAAAAAAAAAAAAAAAAAAAAAAAAAAAA AAAAAAAAAAAAAAAAAAAAAAAAAAAAAA AAAAAAAAAAAAAAAAAAAAAAAAAAAAAA AAAAAAAAAAAAAAAAAAAAAAAAAAAAAA AAAAAAAAAAAAAAAAAAAAAAAAAAAAAA AAAAAAAAAAAAAAAAAAAAAAAAAAAAAA AAAAAAAAAAAAAAAAAAAAAAAAAAAAAA AAAAAAAAAAAAAAAAAAAAAAAAAAAAAA AAAAAAAAAAAAAAAAAAAAAAAAAAAAAA AAAAAAAAAAAAAAAAAAAAAAAAAAAAAA AAAAAAAAAAAAAAAAAAAAAAAAAAAAAA 
AAAAAAAAAAAA------AAAAAAAAAAAA AAAAAAAAAAAA------AAAAAAAAAAAA AAAAAAAAAAAA------AAAAAAAAAAAA AAAAAAAAAAAA------AAAAAAAAAAAA AAAAAAAAAAAA------AAAAAAAAAAAA AAAAAAAAAAAA------AAAAAAAAAAAA AAAAAAAAAAAA------AAAAAAAAAAAA AAAAAAAAAAAA------AAAAAAAAAAAA AAAAAAAAAAAA------AAAAAAAAAAAA AAAAAAAAAAAA------AAAAAAAAAAAA AAAAAAAAAAAA------AAAAAAAAAAAA AAAAAAAAAAAA------AAAAAAAAAAAA AAAAAAAAAAAA------AAAAAAAAAAAA AAAAAAAAAAAA------AAAAAAAAAAAA AAAAAAAAAAAA------AAAAAAAAAAAA AAAAAAAAAAAAAAAAAAAAAAAAAAAAAA AAAAAAAAAAAAAAAAAAAAAAAAAAAAAA AAAAAAAAAAAAAAAAAAAAAAAAAAAAAA AAAAAAAAAAAAAAAAAAAAAAAAAAAAAA AAAAAAAAAAAAAAAAAAAAAAAAAAAAAA AAAAAAAAAAAAAAAAAAAAAAAAAAAAAA AAAAAAAAAAAAAAAAAAAAAAAAAAAAAA AAAAAAAAAAAAAAAAAAAAAAAAAAAAAA AAAAAAAAAAAAAAAAAAAAAAAAAAAAAA AAAAAAAAAAAAAAAAAAAAAAAAAAAAAA AAAAAAAAAAAAAAAAAAAAAAAAAAAAAA AAAAAAAAAAAAAAAAAAAAAAAAAAAAAA AAAAAAAAAAAAAAAAAAAAAAAAAAAAAA AAAAAAAAAAAAAAAAAAAAAAAAAAAAAA AAAAAAAAAAAAAAAAAAAAAAAAAAAAAA 
AAAAAAAAAAAA------AAAAAAAAAAAA AAAAAAAAAAAA------AAAAAAAAAAAA AAAAAAAAAAAA------AAAAAAAAAAAA AAAAAAAAAAAA------AAAAAAAAAAAA AAAAAAAAAAAA------AAAAAAAAAAAA AAAAAAAAAAAA------AAAAAAAAAAAA AAAAAAAAAAAA------AAAAAAAAAAAA AAAAAAAAAAAA------AAAAAAAAAAAA AAAAAAAAAAAA------AAAAAAAAAAAA AAAAAAAAAAAA------AAAAAAAAAAAA AAAAAAAAAAAA------AAAAAAAAAAAA AAAAAAAAAAAA------AAAAAAAAAAAA AAAAAAAAAAAA------AAAAAAAAAAAA AAAAAAAAAAAA------AAAAAAAAAAAA AAAAAAAAAAAA------AAAAAAAAAAAA AAAAAAAAAAAAAAAAAAAAAAAAAAAAAA AAAAAAAAAAAAAAAAAAAAAAAAAAAAAA AAAAAAAAAAAAAAAAAAAAAAAAAAAAAA AAAAAAAAAAAAAAAAAAAAAAAAAAAAAA AAAAAAAAAAAAAAAAAAAAAAAAAAAAAA AAAAAAAAAAAAAAAAAAAAAAAAAAAAAA AAAAAAAAAAAAAAAAAAAAAAAAAAAAAA AAAAAAAAAAAAAAAAAAAAAAAAAAAAAA AAAAAAAAAAAAAAAAAAAAAAAAAAAAAA AAAAAAAAAAAAAAAAAAAAAAAAAAAAAA AAAAAAAAAAAAAAAAAAAAAAAAAAAAAA AAAAAAAAAAAAAAAAAAAAAAAAAAAAAA AAAAAAAAAAAAAAAAAAAAAAAAAAAAAA AAAAAAAAAAAAAAAAAAAAAAAAAAAAAA AAAAAAAAAAAAAAAAAAAAAAAAAAAAAA 
AAAAAAAAAAAA------AAAAAAAAAAAA AAAAAAAAAAAA------AAAAAAAAAAAA AAAAAAAAAAAA------AAAAAAAAAAAA AAAAAAAAAAAA------AAAAAAAAAAAA AAAAAAAAAAAA------AAAAAAAAAAAA AAAAAAAAAAAA------AAAAAAAAAAAA AAAAAAAAAAAA------AAAAAAAAAAAA AAAAAAAAAAAA------AAAAAAAAAAAA AAAAAAAAAAAA------AAAAAAAAAAAA AAAAAAAAAAAA------AAAAAAAAAAAA AAAAAAAAAAAA------AAAAAAAAAAAA AAAAAAAAAAAA------AAAAAAAAAAAA AAAAAAAAAAAA------AAAAAAAAAAAA AAAAAAAAAAAA------AAAAAAAAAAAA AAAAAAAAAAAA------AAAAAAAAAAAA AAAAAAAAAAAAAAAAAAAAAAAAAAAAAA AAAAAAAAAAAAAAAAAAAAAAAAAAAAAA AAAAAAAAAAAAAAAAAAAAAAAAAAAAAA AAAAAAAAAAAAAAAAAAAAAAAAAAAAAA AAAAAAAAAAAAAAAAAAAAAAAAAAAAAA AAAAAAAAAAAAAAAAAAAAAAAAAAAAAA AAAAAAAAAAAAAAAAAAAAAAAAAAAAAA AAAAAAAAAAAAAAAAAAAAAAAAAAAAAA AAAAAAAAAAAAAAAAAAAAAAAAAAAAAA AAAAAAAAAAAAAAAAAAAAAAAAAAAAAA AAAAAAAAAAAAAAAAAAAAAAAAAAAAAA AAAAAAAAAAAAAAAAAAAAAAAAAAAAAA AAAAAAAAAAAAAAAAAAAAAAAAAAAAAA AAAAAAAAAAAAAAAAAAAAAAAAAAAAAA AAAAAAAAAAAAAAAAAAAAAAAAAAAAAA 
AAAAAAAAAAAA------AAAAAAAAAAAA AAAAAAAAAAAA------AAAAAAAAAAAA AAAAAAAAAAAA------AAAAAAAAAAAA AAAAAAAAAAAA------AAAAAAAAAAAA AAAAAAAAAAAA------AAAAAAAAAAAA AAAAAAAAAAAA------AAAAAAAAAAAA AAAAAAAAAAAA------AAAAAAAAAAAA AAAAAAAAAAAA------AAAAAAAAAAAA AAAAAAAAAAAA------AAAAAAAAAAAA AAAAAAAAAAAA------AAAAAAAAAAAA AAAAAAAAAAAA------AAAAAAAAAAAA AAAAAAAAAAAA------AAAAAAAAAAAA AAAAAAAAAAAA------AAAAAAAAAAAA AAAAAAAAAAAA------AAAAAAAAAAAA AAAAAAAAAAAA------AAAAAAAAAAAA AAAAAAAAAAAAAAAAAAAAAAAAAAAAAA AAAAAAAAAAAAAAAAAAAAAAAAAAAAAA AAAAAAAAAAAAAAAAAAAAAAAAAAAAAA AAAAAAAAAAAAAAAAAAAAAAAAAAAAAA AAAAAAAAAAAAAAAAAAAAAAAAAAAAAA AAAAAAAAAAAAAAAAAAAAAAAAAAAAAA AAAAAAAAAAAAAAAAAAAAAAAAAAAAAA AAAAAAAAAAAAAAAAAAAAAAAAAAAAAA AAAAAAAAAAAAAAAAAAAAAAAAAAAAAA AAAAAAAAAAAAAAAAAAAAAAAAAAAAAA AAAAAAAAAAAAAAAAAAAAAAAAAAAAAA AAAAAAAAAAAAAAAAAAAAAAAAAAAAAA AAAAAAAAAAAAAAAAAAAAAAAAAAAAAA AAAAAAAAAAAAAAAAAAAAAAAAAAAAAA AAAAAAAAAAAAAAAAAAAAAAAAAAAAAA 
AAAAAAAAAAAA------AAAAAAAAAAAA AAAAAAAAAAAA------AAAAAAAAAAAA AAAAAAAAAAAA------AAAAAAAAAAAA AAAAAAAAAAAA------AAAAAAAAAAAA AAAAAAAAAAAA------AAAAAAAAAAAA AAAAAAAAAAAA------AAAAAAAAAAAA AAAAAAAAAAAA------AAAAAAAAAAAA AAAAAAAAAAAA------AAAAAAAAAAAA AAAAAAAAAAAA------AAAAAAAAAAAA AAAAAAAAAAAA------AAAAAAAAAAAA AAAAAAAAAAAA------AAAAAAAAAAAA AAAAAAAAAAAA------AAAAAAAAAAAA AAAAAAAAAAAA------AAAAAAAAAAAA AAAAAAAAAAAA------AAAAAAAAAAAA AAAAAAAAAAAA------AAAAAAAAAAAA AAAAAAAAAAAAAAAAAAAAAAAAAAAAAA AAAAAAAAAAAAAAAAAAAAAAAAAAAAAA AAAAAAAAAAAAAAAAAAAAAAAAAAAAAA AAAAAAAAAAAAAAAAAAAAAAAAAAAAAA AAAAAAAAAAAAAAAAAAAAAAAAAAAAAA AAAAAAAAAAAAAAAAAAAAAAAAAAAAAA AAAAAAAAAAAAAAAAAAAAAAAAAAAAAA AAAAAAAAAAAAAAAAAAAAAAAAAAAAAA AAAAAAAAAAAAAAAAAAAAAAAAAAAAAA AAAAAAAAAAAAAAAAAAAAAAAAAAAAAA AAAAAAAAAAAAAAAAAAAAAAAAAAAAAA AAAAAAAAAAAAAAAAAAAAAAAAAAAAAA AAAAAAAAAAAAAAAAAAAAAAAAAAAAAA AAAAAAAAAAAAAAAAAAAAAAAAAAAAAA AAAAAAAAAAAAAAAAAAAAAAAAAAAAAA 
AAAAAAAAAAAA------AAAAAAAAAAAA AAAAAAAAAAAA------AAAAAAAAAAAA AAAAAAAAAAAA------AAAAAAAAAAAA AAAAAAAAAAAA------AAAAAAAAAAAA AAAAAAAAAAAA------AAAAAAAAAAAA AAAAAAAAAAAA------AAAAAAAAAAAA AAAAAAAAAAAA------AAAAAAAAAAAA AAAAAAAAAAAA------AAAAAAAAAAAA AAAAAAAAAAAA------AAAAAAAAAAAA AAAAAAAAAAAA------AAAAAAAAAAAA AAAAAAAAAAAA------AAAAAAAAAAAA AAAAAAAAAAAA------AAAAAAAAAAAA AAAAAAAAAAAA------AAAAAAAAAAAA AAAAAAAAAAAA------AAAAAAAAAAAA AAAAAAAAAAAA------AAAAAAAAAAAA AAAAAAAAAAAAAAAAAAAAAAAAAAAAAA AAAAAAAAAAAAAAAAAAAAAAAAAAAAAA AAAAAAAAAAAAAAAAAAAAAAAAAAAAAA AAAAAAAAAAAAAAAAAAAAAAAAAAAAAA AAAAAAAAAAAAAAAAAAAAAAAAAAAAAA AAAAAAAAAAAAAAAAAAAAAAAAAAAAAA AAAAAAAAAAAAAAAAAAAAAAAAAAAAAA AAAAAAAAAAAAAAAAAAAAAAAAAAAAAA AAAAAAAAAAAAAAAAAAAAAAAAAAAAAA AAAAAAAAAAAAAAAAAAAAAAAAAAAAAA AAAAAAAAAAAAAAAAAAAAAAAAAAAAAA AAAAAAAAAAAAAAAAAAAAAAAAAAAAAA AAAAAAAAAAAAAAAAAAAAAAAAAAAAAA AAAAAAAAAAAAAAAAAAAAAAAAAAAAAA AAAAAAAAAAAAAAAAAAAAAAAAAAAAAA 
AAAAAAAAAAAA------AAAAAAAAAAAA AAAAAAAAAAAA------AAAAAAAAAAAA AAAAAAAAAAAA------AAAAAAAAAAAA AAAAAAAAAAAA------AAAAAAAAAAAA AAAAAAAAAAAA------AAAAAAAAAAAA AAAAAAAAAAAA------AAAAAAAAAAAA AAAAAAAAAAAA------AAAAAAAAAAAA AAAAAAAAAAAA------AAAAAAAAAAAA AAAAAAAAAAAA------AAAAAAAAAAAA AAAAAAAAAAAA------AAAAAAAAAAAA AAAAAAAAAAAA------AAAAAAAAAAAA AAAAAAAAAAAA------AAAAAAAAAAAA AAAAAAAAAAAA------AAAAAAAAAAAA AAAAAAAAAAAA------AAAAAAAAAAAA AAAAAAAAAAAA------AAAAAAAAAAAA AAAAAAAAAAAAAAAAAAAAAAAAAAAAAA AAAAAAAAAAAAAAAAAAAAAAAAAAAAAA AAAAAAAAAAAAAAAAAAAAAAAAAAAAAA AAAAAAAAAAAAAAAAAAAAAAAAAAAAAA AAAAAAAAAAAAAAAAAAAAAAAAAAAAAA AAAAAAAAAAAAAAAAAAAAAAAAAAAAAA AAAAAAAAAAAAAAAAAAAAAAAAAAAAAA AAAAAAAAAAAAAAAAAAAAAAAAAAAAAA AAAAAAAAAAAAAAAAAAAAAAAAAAAAAA AAAAAAAAAAAAAAAAAAAAAAAAAAAAAA AAAAAAAAAAAAAAAAAAAAAAAAAAAAAA AAAAAAAAAAAAAAAAAAAAAAAAAAAAAA AAAAAAAAAAAAAAAAAAAAAAAAAAAAAA AAAAAAAAAAAAAAAAAAAAAAAAAAAAAA AAAAAAAAAAAAAAAAAAAAAAAAAAAAAA 
AAAAAAAAAAAA------AAAAAAAAAAAA AAAAAAAAAAAA------AAAAAAAAAAAA AAAAAAAAAAAA------AAAAAAAAAAAA AAAAAAAAAAAA------AAAAAAAAAAAA AAAAAAAAAAAA------AAAAAAAAAAAA AAAAAAAAAAAA------AAAAAAAAAAAA AAAAAAAAAAAA------AAAAAAAAAAAA AAAAAAAAAAAA------AAAAAAAAAAAA AAAAAAAAAAAA------AAAAAAAAAAAA AAAAAAAAAAAA------AAAAAAAAAAAA AAAAAAAAAAAA------AAAAAAAAAAAA AAAAAAAAAAAA------AAAAAAAAAAAA AAAAAAAAAAAA------AAAAAAAAAAAA AAAAAAAAAAAA------AAAAAAAAAAAA AAAAAAAAAAAA------AAAAAAAAAAAA AAAAAAAAAAAAAAAAAAAAAAAAAAAAAA AAAAAAAAAAAAAAAAAAAAAAAAAAAAAA AAAAAAAAAAAAAAAAAAAAAAAAAAAAAA AAAAAAAAAAAAAAAAAAAAAAAAAAAAAA AAAAAAAAAAAAAAAAAAAAAAAAAAAAAA AAAAAAAAAAAAAAAAAAAAAAAAAAAAAA AAAAAAAAAAAAAAAAAAAAAAAAAAAAAA AAAAAAAAAAAAAAAAAAAAAAAAAAAAAA AAAAAAAAAAAAAAAAAAAAAAAAAAAAAA AAAAAAAAAAAAAAAAAAAAAAAAAAAAAA AAAAAAAAAAAAAAAAAAAAAAAAAAAAAA AAAAAAAAAAAAAAAAAAAAAAAAAAAAAA AAAAAAAAAAAAAAAAAAAAAAAAAAAAAA AAAAAAAAAAAAAAAAAAAAAAAAAAAAAA AAAAAAAAAAAAAAAAAAAAAAAAAAAAAA 
AAAAAAAAAAAA------AAAAAAAAAAAA AAAAAAAAAAAA------AAAAAAAAAAAA AAAAAAAAAAAA------AAAAAAAAAAAA AAAAAAAAAAAA------AAAAAAAAAAAA AAAAAAAAAAAA------AAAAAAAAAAAA AAAAAAAAAAAA------AAAAAAAAAAAA AAAAAAAAAAAA------AAAAAAAAAAAA AAAAAAAAAAAA------AAAAAAAAAAAA AAAAAAAAAAAA------AAAAAAAAAAAA AAAAAAAAAAAA------AAAAAAAAAAAA AAAAAAAAAAAA------AAAAAAAAAAAA AAAAAAAAAAAA------AAAAAAAAAAAA AAAAAAAAAAAA------AAAAAAAAAAAA AAAAAAAAAAAA------AAAAAAAAAAAA AAAAAAAAAAAA------AAAAAAAAAAAA AAAAAAAAAAAAAAAAAAAAAAAAAAAAAA AAAAAAAAAAAAAAAAAAAAAAAAAAAAAA AAAAAAAAAAAAAAAAAAAAAAAAAAAAAA AAAAAAAAAAAAAAAAAAAAAAAAAAAAAA AAAAAAAAAAAAAAAAAAAAAAAAAAAAAA AAAAAAAAAAAAAAAAAAAAAAAAAAAAAA AAAAAAAAAAAAAAAAAAAAAAAAAAAAAA AAAAAAAAAAAAAAAAAAAAAAAAAAAAAA AAAAAAAAAAAAAAAAAAAAAAAAAAAAAA AAAAAAAAAAAAAAAAAAAAAAAAAAAAAA AAAAAAAAAAAAAAAAAAAAAAAAAAAAAA AAAAAAAAAAAAAAAAAAAAAAAAAAAAAA AAAAAAAAAAAAAAAAAAAAAAAAAAAAAA AAAAAAAAAAAAAAAAAAAAAAAAAAAAAA AAAAAAAAAAAAAAAAAAAAAAAAAAAAAA 
AAAAAAAAAAAA------AAAAAAAAAAAA AAAAAAAAAAAA------AAAAAAAAAAAA AAAAAAAAAAAA------AAAAAAAAAAAA AAAAAAAAAAAA------AAAAAAAAAAAA AAAAAAAAAAAA------AAAAAAAAAAAA AAAAAAAAAAAA------AAAAAAAAAAAA AAAAAAAAAAAA------AAAAAAAAAAAA AAAAAAAAAAAA------AAAAAAAAAAAA AAAAAAAAAAAA------AAAAAAAAAAAA AAAAAAAAAAAA------AAAAAAAAAAAA AAAAAAAAAAAA------AAAAAAAAAAAA AAAAAAAAAAAA------AAAAAAAAAAAA AAAAAAAAAAAA------AAAAAAAAAAAA AAAAAAAAAAAA------AAAAAAAAAAAA AAAAAAAAAAAA------AAAAAAAAAAAA AAAAAAAAAAAAAAAAAAAAAAAAAAAAAA AAAAAAAAAAAAAAAAAAAAAAAAAAAAAA AAAAAAAAAAAAAAAAAAAAAAAAAAAAAA AAAAAAAAAAAAAAAAAAAAAAAAAAAAAA AAAAAAAAAAAAAAAAAAAAAAAAAAAAAA AAAAAAAAAAAAAAAAAAAAAAAAAAAAAA AAAAAAAAAAAAAAAAAAAAAAAAAAAAAA AAAAAAAAAAAAAAAAAAAAAAAAAAAAAA AAAAAAAAAAAAAAAAAAAAAAAAAAAAAA AAAAAAAAAAAAAAAAAAAAAAAAAAAAAA AAAAAAAAAAAAAAAAAAAAAAAAAAAAAA AAAAAAAAAAAAAAAAAAAAAAAAAAAAAA AAAAAAAAAAAAAAAAAAAAAAAAAAAAAA AAAAAAAAAAAAAAAAAAAAAAAAAAAAAA AAAAAAAAAAAAAAAAAAAAAAAAAAAAAA 
AAAAAAAAAAAA------AAAAAAAAAAAA AAAAAAAAAAAA------AAAAAAAAAAAA AAAAAAAAAAAA------AAAAAAAAAAAA AAAAAAAAAAAA------AAAAAAAAAAAA AAAAAAAAAAAA------AAAAAAAAAAAA AAAAAAAAAAAA------AAAAAAAAAAAA AAAAAAAAAAAA------AAAAAAAAAAAA AAAAAAAAAAAA------AAAAAAAAAAAA AAAAAAAAAAAA------AAAAAAAAAAAA AAAAAAAAAAAA------AAAAAAAAAAAA AAAAAAAAAAAA------AAAAAAAAAAAA AAAAAAAAAAAA------AAAAAAAAAAAA AAAAAAAAAAAA------AAAAAAAAAAAA AAAAAAAAAAAA------AAAAAAAAAAAA AAAAAAAAAAAA------AAAAAAAAAAAA AAAAAAAAAAAAAAAAAAAAAAAAAAAAAA AAAAAAAAAAAAAAAAAAAAAAAAAAAAAA AAAAAAAAAAAAAAAAAAAAAAAAAAAAAA AAAAAAAAAAAAAAAAAAAAAAAAAAAAAA AAAAAAAAAAAAAAAAAAAAAAAAAAAAAA AAAAAAAAAAAAAAAAAAAAAAAAAAAAAA AAAAAAAAAAAAAAAAAAAAAAAAAAAAAA AAAAAAAAAAAAAAAAAAAAAAAAAAAAAA AAAAAAAAAAAAAAAAAAAAAAAAAAAAAA AAAAAAAAAAAAAAAAAAAAAAAAAAAAAA AAAAAAAAAAAAAAAAAAAAAAAAAAAAAA AAAAAAAAAAAAAAAAAAAAAAAAAAAAAA AAAAAAAAAAAAAAAAAAAAAAAAAAAAAA AAAAAAAAAAAAAAAAAAAAAAAAAAAAAA AAAAAAAAAAAAAAAAAAAAAAAAAAAAAA 
AAAAAAAAAAAA------AAAAAAAAAAAA AAAAAAAAAAAA------AAAAAAAAAAAA AAAAAAAAAAAA------AAAAAAAAAAAA AAAAAAAAAAAA------AAAAAAAAAAAA AAAAAAAAAAAA------AAAAAAAAAAAA AAAAAAAAAAAA------AAAAAAAAAAAA AAAAAAAAAAAA------AAAAAAAAAAAA AAAAAAAAAAAA------AAAAAAAAAAAA AAAAAAAAAAAA------AAAAAAAAAAAA AAAAAAAAAAAA------AAAAAAAAAAAA AAAAAAAAAAAA------AAAAAAAAAAAA AAAAAAAAAAAA------AAAAAAAAAAAA AAAAAAAAAAAA------AAAAAAAAAAAA AAAAAAAAAAAA------AAAAAAAAAAAA AAAAAAAAAAAA------AAAAAAAAAAAA AAAAAAAAAAAAAAAAAAAAAAAAAAAAAA AAAAAAAAAAAAAAAAAAAAAAAAAAAAAA AAAAAAAAAAAAAAAAAAAAAAAAAAAAAA AAAAAAAAAAAAAAAAAAAAAAAAAAAAAA AAAAAAAAAAAAAAAAAAAAAAAAAAAAAA AAAAAAAAAAAAAAAAAAAAAAAAAAAAAA AAAAAAAAAAAAAAAAAAAAAAAAAAAAAA AAAAAAAAAAAAAAAAAAAAAAAAAAAAAA AAAAAAAAAAAAAAAAAAAAAAAAAAAAAA AAAAAAAAAAAAAAAAAAAAAAAAAAAAAA AAAAAAAAAAAAAAAAAAAAAAAAAAAAAA AAAAAAAAAAAAAAAAAAAAAAAAAAAAAA AAAAAAAAAAAAAAAAAAAAAAAAAAAAAA AAAAAAAAAAAAAAAAAAAAAAAAAAAAAA AAAAAAAAAAAAAAAAAAAAAAAAAAAAAA 
AAAAAAAAAAAA------AAAAAAAAAAAA AAAAAAAAAAAA------AAAAAAAAAAAA AAAAAAAAAAAA------AAAAAAAAAAAA AAAAAAAAAAAA------AAAAAAAAAAAA AAAAAAAAAAAA------AAAAAAAAAAAA AAAAAAAAAAAA------AAAAAAAAAAAA AAAAAAAAAAAA------AAAAAAAAAAAA AAAAAAAAAAAA------AAAAAAAAAAAA AAAAAAAAAAAA------AAAAAAAAAAAA AAAAAAAAAAAA------AAAAAAAAAAAA AAAAAAAAAAAA------AAAAAAAAAAAA AAAAAAAAAAAA------AAAAAAAAAAAA AAAAAAAAAAAA------AAAAAAAAAAAA AAAAAAAAAAAA------AAAAAAAAAAAA AAAAAAAAAAAA------AAAAAAAAAAAA AAAAAAAAAAAAAAAAAAAAAAAAAAAAAA AAAAAAAAAAAAAAAAAAAAAAAAAAAAAA AAAAAAAAAAAAAAAAAAAAAAAAAAAAAA AAAAAAAAAAAAAAAAAAAAAAAAAAAAAA AAAAAAAAAAAAAAAAAAAAAAAAAAAAAA AAAAAAAAAAAAAAAAAAAAAAAAAAAAAA AAAAAAAAAAAAAAAAAAAAAAAAAAAAAA AAAAAAAAAAAAAAAAAAAAAAAAAAAAAA AAAAAAAAAAAAAAAAAAAAAAAAAAAAAA AAAAAAAAAAAAAAAAAAAAAAAAAAAAAA AAAAAAAAAAAAAAAAAAAAAAAAAAAAAA AAAAAAAAAAAAAAAAAAAAAAAAAAAAAA AAAAAAAAAAAAAAAAAAAAAAAAAAAAAA AAAAAAAAAAAAAAAAAAAAAAAAAAAAAA AAAAAAAAAAAAAAAAAAAAAAAAAAAAAA 
AAAAAAAAAAAA------AAAAAAAAAAAA AAAAAAAAAAAA------AAAAAAAAAAAA AAAAAAAAAAAA------AAAAAAAAAAAA AAAAAAAAAAAA------AAAAAAAAAAAA AAAAAAAAAAAA------AAAAAAAAAAAA AAAAAAAAAAAA------AAAAAAAAAAAA AAAAAAAAAAAA------AAAAAAAAAAAA AAAAAAAAAAAA------AAAAAAAAAAAA AAAAAAAAAAAA------AAAAAAAAAAAA AAAAAAAAAAAA------AAAAAAAAAAAA AAAAAAAAAAAA------AAAAAAAAAAAA AAAAAAAAAAAA------AAAAAAAAAAAA AAAAAAAAAAAA------AAAAAAAAAAAA AAAAAAAAAAAA------AAAAAAAAAAAA AAAAAAAAAAAA------AAAAAAAAAAAA AAAAAAAAAAAAAAAAAAAAAAAAAAAAAA AAAAAAAAAAAAAAAAAAAAAAAAAAAAAA AAAAAAAAAAAAAAAAAAAAAAAAAAAAAA AAAAAAAAAAAAAAAAAAAAAAAAAAAAAA AAAAAAAAAAAAAAAAAAAAAAAAAAAAAA AAAAAAAAAAAAAAAAAAAAAAAAAAAAAA AAAAAAAAAAAAAAAAAAAAAAAAAAAAAA AAAAAAAAAAAAAAAAAAAAAAAAAAAAAA AAAAAAAAAAAAAAAAAAAAAAAAAAAAAA AAAAAAAAAAAAAAAAAAAAAAAAAAAAAA AAAAAAAAAAAAAAAAAAAAAAAAAAAAAA AAAAAAAAAAAAAAAAAAAAAAAAAAAAAA AAAAAAAAAAAAAAAAAAAAAAAAAAAAAA AAAAAAAAAAAAAAAAAAAAAAAAAAAAAA AAAAAAAAAAAAAAAAAAAAAAAAAAAAAA 
AAAAAA------AAAAAA------AAAAAA AAAAAA------AAAAAA------AAAAAA AAAAAA------AAAAAA------AAAAAA AAAAAA------AAAAAA------AAAAAA AAAAAA------AAAAAA------AAAAAA AAAAAA------AAAAAA------AAAAAA AAAAAA------AAAAAA------AAAAAA AAAAAA------AAAAAA------AAAAAA AAAAAA------AAAAAA------AAAAAA AAAAAA------AAAAAA------AAAAAA AAAAAA------AAAAAA------AAAAAA AAAAAA------AAAAAA------AAAAAA AAAAAA------AAAAAA------AAAAAA AAAAAA------AAAAAA------AAAAAA AAAAAA------AAAAAA------AAAAAA AAAAAAAAAAAAAAAAAAAAAAAAAAAAAA AAAAAAAAAAAAAAAAAAAAAAAAAAAAAA AAAAAAAAAAAAAAAAAAAAAAAAAAAAAA AAAAAAAAAAAAAAAAAAAAAAAAAAAAAA AAAAAAAAAAAAAAAAAAAAAAAAAAAAAA AAAAAAAAAAAAAAAAAAAAAAAAAAAAAA AAAAAAAAAAAAAAAAAAAAAAAAAAAAAA AAAAAAAAAAAAAAAAAAAAAAAAAAAAAA AAAAAAAAAAAAAAAAAAAAAAAAAAAAAA AAAAAAAAAAAAAAAAAAAAAAAAAAAAAA AAAAAAAAAAAAAAAAAAAAAAAAAAAAAA AAAAAAAAAAAAAAAAAAAAAAAAAAAAAA AAAAAAAAAAAAAAAAAAAAAAAAAAAAAA AAAAAAAAAAAAAAAAAAAAAAAAAAAAAA AAAAAAAAAAAAAAAAAAAAAAAAAAAAAA 
AAAAAA------AAAAAA------AAAAAA AAAAAA------AAAAAA------AAAAAA AAAAAA------AAAAAA------AAAAAA AAAAAA------AAAAAA------AAAAAA AAAAAA------AAAAAA------AAAAAA AAAAAA------AAAAAA------AAAAAA AAAAAA------AAAAAA------AAAAAA AAAAAA------AAAAAA------AAAAAA AAAAAA------AAAAAA------AAAAAA AAAAAA------AAAAAA------AAAAAA AAAAAA------AAAAAA------AAAAAA AAAAAA------AAAAAA------AAAAAA AAAAAA------AAAAAA------AAAAAA AAAAAA------AAAAAA------AAAAAA AAAAAA------AAAAAA------AAAAAA AAAAAAAAAAAAAAAAAAAAAAAAAAAAAA AAAAAAAAAAAAAAAAAAAAAAAAAAAAAA AAAAAAAAAAAAAAAAAAAAAAAAAAAAAA AAAAAAAAAAAAAAAAAAAAAAAAAAAAAA AAAAAAAAAAAAAAAAAAAAAAAAAAAAAA AAAAAAAAAAAAAAAAAAAAAAAAAAAAAA AAAAAAAAAAAAAAAAAAAAAAAAAAAAAA AAAAAAAAAAAAAAAAAAAAAAAAAAAAAA AAAAAAAAAAAAAAAAAAAAAAAAAAAAAA AAAAAAAAAAAAAAAAAAAAAAAAAAAAAA AAAAAAAAAAAAAAAAAAAAAAAAAAAAAA AAAAAAAAAAAAAAAAAAAAAAAAAAAAAA AAAAAAAAAAAAAAAAAAAAAAAAAAAAAA AAAAAAAAAAAAAAAAAAAAAAAAAAAAAA AAAAAAAAAAAAAAAAAAAAAAAAAAAAAA 
AAAAAA------AAAAAA------AAAAAA AAAAAA------AAAAAA------AAAAAA AAAAAA------AAAAAA------AAAAAA AAAAAA------AAAAAA------AAAAAA AAAAAA------AAAAAA------AAAAAA AAAAAA------AAAAAA------AAAAAA AAAAAA------AAAAAA------AAAAAA AAAAAA------AAAAAA------AAAAAA AAAAAA------AAAAAA------AAAAAA AAAAAA------AAAAAA------AAAAAA AAAAAA------AAAAAA------AAAAAA AAAAAA------AAAAAA------AAAAAA AAAAAA------AAAAAA------AAAAAA AAAAAA------AAAAAA------AAAAAA AAAAAA------AAAAAA------AAAAAA AAAAAAAAAAAAAAAAAAAAAAAAAAAAAA AAAAAAAAAAAAAAAAAAAAAAAAAAAAAA AAAAAAAAAAAAAAAAAAAAAAAAAAAAAA AAAAAAAAAAAAAAAAAAAAAAAAAAAAAA AAAAAAAAAAAAAAAAAAAAAAAAAAAAAA AAAAAAAAAAAAAAAAAAAAAAAAAAAAAA AAAAAAAAAAAAAAAAAAAAAAAAAAAAAA AAAAAAAAAAAAAAAAAAAAAAAAAAAAAA AAAAAAAAAAAAAAAAAAAAAAAAAAAAAA AAAAAAAAAAAAAAAAAAAAAAAAAAAAAA AAAAAAAAAAAAAAAAAAAAAAAAAAAAAA AAAAAAAAAAAAAAAAAAAAAAAAAAAAAA AAAAAAAAAAAAAAAAAAAAAAAAAAAAAA AAAAAAAAAAAAAAAAAAAAAAAAAAAAAA AAAAAAAAAAAAAAAAAAAAAAAAAAAAAA 
AAAAAA------AAAAAA------AAAAAA AAAAAA------AAAAAA------AAAAAA AAAAAA------AAAAAA------AAAAAA AAAAAA------AAAAAA------AAAAAA AAAAAA------AAAAAA------AAAAAA AAAAAA------AAAAAA------AAAAAA AAAAAA------AAAAAA------AAAAAA AAAAAA------AAAAAA------AAAAAA AAAAAA------AAAAAA------AAAAAA AAAAAA------AAAAAA------AAAAAA AAAAAA------AAAAAA------AAAAAA AAAAAA------AAAAAA------AAAAAA AAAAAA------AAAAAA------AAAAAA AAAAAA------AAAAAA------AAAAAA AAAAAA------AAAAAA------AAAAAA AAAAAAAAAAAAAAAAAAAAAAAAAAAAAA AAAAAAAAAAAAAAAAAAAAAAAAAAAAAA AAAAAAAAAAAAAAAAAAAAAAAAAAAAAA AAAAAAAAAAAAAAAAAAAAAAAAAAAAAA AAAAAAAAAAAAAAAAAAAAAAAAAAAAAA AAAAAAAAAAAAAAAAAAAAAAAAAAAAAA AAAAAAAAAAAAAAAAAAAAAAAAAAAAAA AAAAAAAAAAAAAAAAAAAAAAAAAAAAAA AAAAAAAAAAAAAAAAAAAAAAAAAAAAAA AAAAAAAAAAAAAAAAAAAAAAAAAAAAAA AAAAAAAAAAAAAAAAAAAAAAAAAAAAAA AAAAAAAAAAAAAAAAAAAAAAAAAAAAAA AAAAAAAAAAAAAAAAAAAAAAAAAAAAAA AAAAAAAAAAAAAAAAAAAAAAAAAAAAAA AAAAAAAAAAAAAAAAAAAAAAAAAAAAAA 
AAAAAA------AAAAAA------AAAAAA AAAAAA------AAAAAA------AAAAAA AAAAAA------AAAAAA------AAAAAA AAAAAA------AAAAAA------AAAAAA AAAAAA------AAAAAA------AAAAAA AAAAAA------AAAAAA------AAAAAA AAAAAA------AAAAAA------AAAAAA AAAAAA------AAAAAA------AAAAAA AAAAAA------AAAAAA------AAAAAA AAAAAA------AAAAAA------AAAAAA AAAAAA------AAAAAA------AAAAAA AAAAAA------AAAAAA------AAAAAA AAAAAA------AAAAAA------AAAAAA AAAAAA------AAAAAA------AAAAAA AAAAAA------AAAAAA------AAAAAA AAAAAAAAAAAAAAAAAAAAAAAAAAAAAA AAAAAAAAAAAAAAAAAAAAAAAAAAAAAA AAAAAAAAAAAAAAAAAAAAAAAAAAAAAA AAAAAAAAAAAAAAAAAAAAAAAAAAAAAA AAAAAAAAAAAAAAAAAAAAAAAAAAAAAA AAAAAAAAAAAAAAAAAAAAAAAAAAAAAA AAAAAAAAAAAAAAAAAAAAAAAAAAAAAA AAAAAAAAAAAAAAAAAAAAAAAAAAAAAA AAAAAAAAAAAAAAAAAAAAAAAAAAAAAA AAAAAAAAAAAAAAAAAAAAAAAAAAAAAA AAAAAAAAAAAAAAAAAAAAAAAAAAAAAA AAAAAAAAAAAAAAAAAAAAAAAAAAAAAA AAAAAAAAAAAAAAAAAAAAAAAAAAAAAA AAAAAAAAAAAAAAAAAAAAAAAAAAAAAA AAAAAAAAAAAAAAAAAAAAAAAAAAAAAA 
AAAAAA------AAAAAA------AAAAAA AAAAAA------AAAAAA------AAAAAA AAAAAA------AAAAAA------AAAAAA AAAAAA------AAAAAA------AAAAAA AAAAAA------AAAAAA------AAAAAA AAAAAA------AAAAAA------AAAAAA AAAAAA------AAAAAA------AAAAAA AAAAAA------AAAAAA------AAAAAA AAAAAA------AAAAAA------AAAAAA AAAAAA------AAAAAA------AAAAAA AAAAAA------AAAAAA------AAAAAA AAAAAA------AAAAAA------AAAAAA AAAAAA------AAAAAA------AAAAAA AAAAAA------AAAAAA------AAAAAA AAAAAA------AAAAAA------AAAAAA AAAAAAAAAAAAAAAAAAAAAAAAAAAAAA AAAAAAAAAAAAAAAAAAAAAAAAAAAAAA AAAAAAAAAAAAAAAAAAAAAAAAAAAAAA AAAAAAAAAAAAAAAAAAAAAAAAAAAAAA AAAAAAAAAAAAAAAAAAAAAAAAAAAAAA AAAAAAAAAAAAAAAAAAAAAAAAAAAAAA AAAAAAAAAAAAAAAAAAAAAAAAAAAAAA AAAAAAAAAAAAAAAAAAAAAAAAAAAAAA AAAAAAAAAAAAAAAAAAAAAAAAAAAAAA AAAAAAAAAAAAAAAAAAAAAAAAAAAAAA AAAAAAAAAAAAAAAAAAAAAAAAAAAAAA AAAAAAAAAAAAAAAAAAAAAAAAAAAAAA AAAAAAAAAAAAAAAAAAAAAAAAAAAAAA AAAAAAAAAAAAAAAAAAAAAAAAAAAAAA AAAAAAAAAAAAAAAAAAAAAAAAAAAAAA 
AAAAAAAAAAAAAAAAAAAAAAAAAAAAAA AAAAAAAAAAAAAAAAAAAAAAAAAAAAAA AAAAAAAAAAAAAAAAAAAAAAAAAAAAAA AAAAAAAAAAAAAAAAAAAAAAAAAAAAAA AAAAAAAAAAAAAAAAAAAAAAAAAAAAAA AAAAAAAAAAAAAAAAAAAAAAAAAAAAAA AAAAAAAAAAAAAAAAAAAAAAAAAAAAAA AAAAAAAAAAAAAAAAAAAAAAAAAAAAAA AAAAAAAAAAAAAAAAAAAAAAAAAAAAAA AAAAAAAAAAAAAAAAAAAAAAAAAAAAAA AAAAAAAAAAAAAAAAAAAAAAAAAAAAAA AAAAAAAAAAAAAAAAAAAAAAAAAAAAAA AAAAAAAAAAAAAAAAAAAAAAAAAAAAAA AAAAAAAAAAAAAAAAAAAAAAAAAAAAAA AAAAAAAAAAAAAAAAAAAAAAAAAAAAAA AAAAAAAAAAAAAAAAAAAAAAAAAAAAAA AAAAAAAAAAAAAAAAAAAAAAAAAAAAAA AAAAAAAAAAAAAAAAAAAAAAAAAAAAAA AAAAAAAAAAAAAAAAAAAAAAAAAAAAAA AAAAAAAAAAAAAAAAAAAAAAAAAAAAAA AAAAAAAAAAAAAAAAAAAAAAAAAAAAAA AAAAAAAAAAAAAAAAAAAAAAAAAAAAAA AAAAAAAAAAAAAAAAAAAAAAAAAAAAAA AAAAAAAAAAAAAAAAAAAAAAAAAAAAAA AAAAAAAAAAAAAAAAAAAAAAAAAAAAAA AAAAAAAAAAAAAAAAAAAAAAAAAAAAAA AAAAAAAAAAAAAAAAAAAAAAAAAAAAAA AAAAAAAAAAAAAAAAAAAAAAAAAAAAAA AAAAAAAAAAAAAAAAAAAAAAAAAAAAAA AAAAAAAAAAAAAAAAAAAAAAAAAAAAAA 
AAAAAAAAAAAAAAAAAAAAAAAAAAAAAA AAAAAAAAAAAAAAAAAAAAAAAAAAAAAA AAAAAAAAAAAAAAAAAAAAAAAAAAAAAA AAAAAAAAAAAAAAAAAAAAAAAAAAAAAA AAAAAAAAAAAAAAAAAAAAAAAAAAAAAA AAAAAAAAAAAAAAAAAAAAAAAAAAAAAA AAAAAAAAAAAAAAAAAAAAAAAAAAAAAA AAAAAAAAAAAAAAAAAAAAAAAAAAAAAA AAAAAAAAAAAAAAAAAAAAAAAAAAAAAA AAAAAAAAAAAAAAAAAAAAAAAAAAAAAA AAAAAAAAAAAAAAAAAAAAAAAAAAAAAA AAAAAAAAAAAAAAAAAAAAAAAAAAAAAA AAAAAAAAAAAAAAAAAAAAAAAAAAAAAA AAAAAAAAAAAAAAAAAAAAAAAAAAAAAA AAAAAAAAAAAAAAAAAAAAAAAAAAAAAA AAAAAAAAAAAAAAAAAAAAAAAAAAAAAA AAAAAAAAAAAAAAAAAAAAAAAAAAAAAA AAAAAAAAAAAAAAAAAAAAAAAAAAAAAA AAAAAAAAAAAAAAAAAAAAAAAAAAAAAA AAAAAAAAAAAAAAAAAAAAAAAAAAAAAA AAAAAAAAAAAAAAAAAAAAAAAAAAAAAA AAAAAAAAAAAAAAAAAAAAAAAAAAAAAA AAAAAAAAAAAAAAAAAAAAAAAAAAAAAA AAAAAAAAAAAAAAAAAAAAAAAAAAAAAA AAAAAAAAAAAAAAAAAAAAAAAAAAAAAA AAAAAAAAAAAAAAAAAAAAAAAAAAAAAA AAAAAAAAAAAAAAAAAAAAAAAAAAAAAA AAAAAAAAAAAAAAAAAAAAAAAAAAAAAA AAAAAAAAAAAAAAAAAAAAAAAAAAAAAA AAAAAAAAAAAAAAAAAAAAAAAAAAAAAA 
AAAAAAAAAAAAAAAAAAAAAAAAAAAAAA AAAAAAAAAAAAAAAAAAAAAAAAAAAAAA AAAAAAAAAAAAAAAAAAAAAAAAAAAAAA AAAAAAAAAAAAAAAAAAAAAAAAAAAAAA AAAAAAAAAAAAAAAAAAAAAAAAAAAAAA AAAAAAAAAAAAAAAAAAAAAAAAAAAAAA AAAAAAAAAAAAAAAAAAAAAAAAAAAAAA AAAAAAAAAAAAAAAAAAAAAAAAAAAAAA AAAAAAAAAAAAAAAAAAAAAAAAAAAAAA AAAAAAAAAAAAAAAAAAAAAAAAAAAAAA AAAAAAAAAAAAAAAAAAAAAAAAAAAAAA AAAAAAAAAAAAAAAAAAAAAAAAAAAAAA AAAAAAAAAAAAAAAAAAAAAAAAAAAAAA AAAAAAAAAAAAAAAAAAAAAAAAAAAAAA AAAAAAAAAAAAAAAAAAAAAAAAAAAAAA AAAAAAAAAAAAAAAAAAAAAAAAAAAAAA AAAAAAAAAAAAAAAAAAAAAAAAAAAAAA AAAAAAAAAAAAAAAAAAAAAAAAAAAAAA AAAAAAAAAAAAAAAAAAAAAAAAAAAAAA AAAAAAAAAAAAAAAAAAAAAAAAAAAAAA AAAAAAAAAAAAAAAAAAAAAAAAAAAAAA AAAAAAAAAAAAAAAAAAAAAAAAAAAAAA AAAAAAAAAAAAAAAAAAAAAAAAAAAAAA AAAAAAAAAAAAAAAAAAAAAAAAAAAAAA AAAAAAAAAAAAAAAAAAAAAAAAAAAAAA AAAAAAAAAAAAAAAAAAAAAAAAAAAAAA AAAAAAAAAAAAAAAAAAAAAAAAAAAAAA AAAAAAAAAAAAAAAAAAAAAAAAAAAAAA AAAAAAAAAAAAAAAAAAAAAAAAAAAAAA AAAAAAAAAAAAAAAAAAAAAAAAAAAAAA 
AAAAAAAAAAAAAAAAAAAAAAAAAAAAAA AAAAAAAAAAAAAAAAAAAAAAAAAAAAAA AAAAAAAAAAAAAAAAAAAAAAAAAAAAAA AAAAAAAAAAAAAAAAAAAAAAAAAAAAAA AAAAAAAAAAAAAAAAAAAAAAAAAAAAAA AAAAAAAAAAAAAAAAAAAAAAAAAAAAAA AAAAAAAAAAAAAAAAAAAAAAAAAAAAAA AAAAAAAAAAAAAAAAAAAAAAAAAAAAAA AAAAAAAAAAAAAAAAAAAAAAAAAAAAAA AAAAAAAAAAAAAAAAAAAAAAAAAAAAAA AAAAAAAAAAAAAAAAAAAAAAAAAAAAAA AAAAAAAAAAAAAAAAAAAAAAAAAAAAAA AAAAAAAAAAAAAAAAAAAAAAAAAAAAAA AAAAAAAAAAAAAAAAAAAAAAAAAAAAAA AAAAAAAAAAAAAAAAAAAAAAAAAAAAAA AAAAAAAAAAAAAAAAAAAAAAAAAAAAAA AAAAAAAAAAAAAAAAAAAAAAAAAAAAAA AAAAAAAAAAAAAAAAAAAAAAAAAAAAAA AAAAAAAAAAAAAAAAAAAAAAAAAAAAAA AAAAAAAAAAAAAAAAAAAAAAAAAAAAAA AAAAAAAAAAAAAAAAAAAAAAAAAAAAAA AAAAAAAAAAAAAAAAAAAAAAAAAAAAAA AAAAAAAAAAAAAAAAAAAAAAAAAAAAAA AAAAAAAAAAAAAAAAAAAAAAAAAAAAAA AAAAAAAAAAAAAAAAAAAAAAAAAAAAAA AAAAAAAAAAAAAAAAAAAAAAAAAAAAAA AAAAAAAAAAAAAAAAAAAAAAAAAAAAAA AAAAAAAAAAAAAAAAAAAAAAAAAAAAAA AAAAAAAAAAAAAAAAAAAAAAAAAAAAAA AAAAAAAAAAAAAAAAAAAAAAAAAAAAAA 
AAAAAAAAAAAAAAAAAAAAAAAAAAAAAA AAAAAAAAAAAAAAAAAAAAAAAAAAAAAA AAAAAAAAAAAAAAAAAAAAAAAAAAAAAA AAAAAAAAAAAAAAAAAAAAAAAAAAAAAA AAAAAAAAAAAAAAAAAAAAAAAAAAAAAA AAAAAAAAAAAAAAAAAAAAAAAAAAAAAA AAAAAAAAAAAAAAAAAAAAAAAAAAAAAA AAAAAAAAAAAAAAAAAAAAAAAAAAAAAA AAAAAAAAAAAAAAAAAAAAAAAAAAAAAA AAAAAAAAAAAAAAAAAAAAAAAAAAAAAA AAAAAAAAAAAAAAAAAAAAAAAAAAAAAA AAAAAAAAAAAAAAAAAAAAAAAAAAAAAA AAAAAAAAAAAAAAAAAAAAAAAAAAAAAA AAAAAAAAAAAAAAAAAAAAAAAAAAAAAA AAAAAAAAAAAAAAAAAAAAAAAAAAAAAA AAAAAAAAAAAAAAAAAAAAAAAAAAAAAA AAAAAAAAAAAAAAAAAAAAAAAAAAAAAA AAAAAAAAAAAAAAAAAAAAAAAAAAAAAA AAAAAAAAAAAAAAAAAAAAAAAAAAAAAA AAAAAAAAAAAAAAAAAAAAAAAAAAAAAA AAAAAAAAAAAAAAAAAAAAAAAAAAAAAA AAAAAAAAAAAAAAAAAAAAAAAAAAAAAA AAAAAAAAAAAAAAAAAAAAAAAAAAAAAA AAAAAAAAAAAAAAAAAAAAAAAAAAAAAA AAAAAAAAAAAAAAAAAAAAAAAAAAAAAA AAAAAAAAAAAAAAAAAAAAAAAAAAAAAA AAAAAAAAAAAAAAAAAAAAAAAAAAAAAA AAAAAAAAAAAAAAAAAAAAAAAAAAAAAA AAAAAAAAAAAAAAAAAAAAAAAAAAAAAA AAAAAAAAAAAAAAAAAAAAAAAAAAAAAA 
AAAAAAAAAAAAAAAAAAAAAAAAAAAAAA AAAAAAAAAAAAAAAAAAAAAAAAAAAAAA AAAAAAAAAAAAAAAAAAAAAAAAAAAAAA AAAAAAAAAAAAAAAAAAAAAAAAAAAAAA AAAAAAAAAAAAAAAAAAAAAAAAAAAAAA AAAAAAAAAAAAAAAAAAAAAAAAAAAAAA AAAAAAAAAAAAAAAAAAAAAAAAAAAAAA AAAAAAAAAAAAAAAAAAAAAAAAAAAAAA AAAAAAAAAAAAAAAAAAAAAAAAAAAAAA AAAAAAAAAAAAAAAAAAAAAAAAAAAAAA AAAAAAAAAAAAAAAAAAAAAAAAAAAAAA AAAAAAAAAAAAAAAAAAAAAAAAAAAAAA AAAAAAAAAAAAAAAAAAAAAAAAAAAAAA AAAAAAAAAAAAAAAAAAAAAAAAAAAAAA AAAAAAAAAAAAAAAAAAAAAAAAAAAAAA AAAAAAAAAAAAAAAAAAAAAAAAAAAAAA AAAAAAAAAAAAAAAAAAAAAAAAAAAAAA AAAAAAAAAAAAAAAAAAAAAAAAAAAAAA AAAAAAAAAAAAAAAAAAAAAAAAAAAAAA AAAAAAAAAAAAAAAAAAAAAAAAAAAAAA AAAAAAAAAAAAAAAAAAAAAAAAAAAAAA AAAAAAAAAAAAAAAAAAAAAAAAAAAAAA AAAAAAAAAAAAAAAAAAAAAAAAAAAAAA AAAAAAAAAAAAAAAAAAAAAAAAAAAAAA AAAAAAAAAAAAAAAAAAAAAAAAAAAAAA AAAAAAAAAAAAAAAAAAAAAAAAAAAAAA AAAAAAAAAAAAAAAAAAAAAAAAAAAAAA AAAAAAAAAAAAAAAAAAAAAAAAAAAAAA AAAAAAAAAAAAAAAAAAAAAAAAAAAAAA AAAAAAAAAAAAAAAAAAAAAAAAAAAAAA 
