model
size = 30 18 32, scale = 0.05, origin = -y
material 
  colors = A:#222 B:#111 C:#F63
voxels
101-4A25-5B3A23-7BA25-4B410-3A27-3B4A22-3B5-3A30-4A26-3B27-3B375-B4A25-2B3-4A30-3A30-4A29-B29-2B29-B312-2A28-B-4A24-B5-4A30-3A30-4A30-2A2(29-B)310-3A27-B2-4A23-B6-4A30-3A30-4A30-3A2(29-B)278-A29-4A26-B3-4A22-B7-4A30-3A2(30-4A)3(29-B)246-2A28-B4A25-B4-2(4A30-)3A2(30-4A)30-A2(29-B)245-2A27-B-4A24-B5-2(4A30-)3A2(30-4A)30-A30-B29-B243-3A27-B-4A24-B5-2(4A30-)3A2(30-4A)30-2A2(29-B)242-4A26-B2-4A23-B6-4A30-A30-3A27-10A20-C5A4-4A16-4CA9-3A14-3C12-B29-B241-4A26-B2-4A23-B6-4A29-A29-2A28-2C8-2A18-2C6-2A2-4A14-2C5-2A7-3A11-3C3-2C10-B11-A6C11-B11-2A4C24-4AC25-3A167-4A26-B2-4A23-B6-4A28-A2(29-C)11-A17-C10-A-4A13-C9-A6-3A10-C8-C9-B9-2A7-2C9-B9-2A6-2C19-3A5-2C19-4A3-2AC19-10A-2C17-8A2-2C18-5A80-4A26-B2-4A23-B6-4A27-C29-C30-C11-A17-C10-A-4A12-C11-A5-4A8-A10-A9-A8-A9-C10-B7-A9-2C17-A10-2C14-3A10-2C15-2A10-A2C15-2A8-2A2B16-2A5-3AC20-6A50-4A26-B2-4A23-B6-4A27-2(C29-)C12-A16-C12-5A12-C11-A5-4A8-A11-A8-A7-A11-C9-B7-A9-2C17-A10-2B15-2A10-2B15-A12-2B14-A11-A2B15-A9-2A2C17-2A4-3A23-4A21-2(4A26-B2-4A23-B6-4A27-2(C29-)C12-A16-C12-5A12-C11-A5-4A8-A11-A8-A7-A11-C9-B6-A12-C16-A10-BC15-2A10-2B15-A12-2B14-A11-A2B15-A9-2AC2B16-A6-2A2-2C18-6A4-C15-)4A26-B2-4A23-B6-4A27-2(C29-)C12-A16-C12-5A12-C11-A5-4A8-A11-A8-A7-A11-C9-B7-A9-3C16-A10-2B15-2A10-2B15-A12-2B14-A11-A2B15-A9-2A2C17-A6-2A22-6A20-4A26-B2-4A23-B6-4A27-2(C29-)C12-A16-C12-5A12-C11-A5-4A8-A10-A9-A7-A11-C9-B7-A9-2C17-A10-2C14-3A10-2C15-A11-A2C14-2A10-A2B16-A7-3AC19-2A-4A25-A23-4A26-B2-4A23-B6-4A27-C30-C29-C11-A17-C10-6A13-C9-A6-4A8-A10-A9-A8-A9-C10-B7-2A8-C19-A8-2C16-3A8-AC17-3A6-2A-C17-3A4-3A-2C17-8A23-4A51-4A26-B2-4A23-B6-4A28-C29-2C28-2C9-2A17-2C8-A2-4A13-2C7-A7-4A9-2A6-CA10-A9-2A5-2C11-B9-2A4-2C21-7AC21-8A22-6A24-4A109-4A26-B2-4A23-B6-4A29-A30-2A28-CA6-3A19-3C2-3A3-4A15-5C3A7-3A12-6C11-B12-A4C12-B12-3AC225-4A26-B2-4A23-B6-4A2(30-2A)2-A25-9A22-2A-A4-4A30-3A2(29-B)241-4A26-B2-4A23-B6-2(4A30-)3A2(30-4A)30-3A2(29-B)242-3A27-B-4A24-B5-2(4A30-)3A2(30-4A)30-2A2(29-B)244-2A27-B-4A24-B5-2(4A30-)3A2(30-4A)30-A30-B29-B244-2A28-B4A25-B4-2(4A30-)3A2(30-4A)30-A2(29-B)246-A29-4A26-B3-4A22-B7-4A30-3A2(30-4A)3(29-B)278-3A27-B2-4A23-B6-4A30-3A30-4A30-3A2(29-B)310-2A28-B-4A24-B5-4A30-3A30-4A30-2A2(29-B)342-B4A25-2B3-4A30-3A30-4A29-B29-2B29-B345-3A27-3B4A22-3B5-3A30-4A26-3B27-3B410-4A25-5B3A23-7BA25-4B342-
