model
size = 16 10 32, scale = 0.05, origin = -y
material 
  colors = A:#DDD B:#200 C:#E00 D:#000 E:#222
voxels
19-4A2C4A153-A2CA12-A2CA139-2A2C2A10-2A2C2A11-A2CA13-2C108-2A2C2A5-2D2(3-2A2C2A3-4D)3-2A2C2A3-2D96-2D3-2A2C2A3-2D-E3-2A2C2A2(3-E2-E3-2A3-A)3-E-2D3-2A2C2A3-2D64-2D12-2D-E-4A2C4A-E2-E-4A2C4A-E-2D-2A6-2A-2D-E-2A6-2A-E2-E3-2A3-A3-E-2D4-A2CA4-2D48-2D12-2D-E-4A2C4A-E-2D-4A2C4A2(-4D-2A6-2A)-2D-E3-2A3-A3-E-2D4-A2CA4-2D48-2D12-2D-E-4A2C4A-E2-E-4A2C4A-E-2D-2A6-2A-2D-E-2A6-2A-E2-E-2A-4B-2A-E-2D3-A4BA3-2D64-2D-4A2C4A-2D-E-4A2C4A-E2-E-2A6-2A-E2-E-2A6B2A-E-2D-A2B4-2BA-2D4-2BA2CA2B9-6B56-4A2C4A3-2D-4A2C4A-4D-2A6B2A-4D-2B6-2B-2D3-BA6-AB6-B-2A2C2A-B2(6-2B)8-6B40-2(4A2C4A6-)A8BA6-BA6-AB5-B2A6-2AB4-B2-2A2C2A2-B5-B8-B7-8B39-4A2C4A6-3A4B3A6-3B4-3B5-2(B2A6-2AB4-)B2-2A2C2A7-B16-3B4-3B9-4B25-4A2C4A6-2A6B2A2(6-2B)5-B2A6-2AB3-B-2A6-2A-B6-2A3-A72-4(4A2C4A6-2A6B2A2(6-2B)5-B2A6-2AB3-B-2A6-2A-B84-)4A2C4A6-3A4B3A6-3B4-3B5-B2A6-2AB4-B2A6-2AB7-2A2C2A72-2(4A2C4A6-)A8BA6-BA6-AB5-B2A6-2AB7-2A2C2A72-2(4A2C4A6-)2A6B2A2(6-2B)6-BA6-AB8-2A2C2A72-3(4A2C4A6-)2A6B2A7-2BA2CA2B8-2B4-2B9-6B58-3(2A2C2A10-)2A2C2A11-4B12-4B75-3(2A2C2A10-)2A2C2A106-2A2C2A5-2D2(3-2A2C2A3-4D)3-2A2C2A3-2D96-2D3-2A2C2A3-2D-2(E3-2A2C2A3-E2-)E3-2A2C2A3-E-2D12-2D64-2D12-2D-E3-2A2C2A3-E2-E3-2A2C2A3-E-2D3-2A2C2A3-2D-E3-2A2C2A3-E2-E12-E-2D12-2D48-2D12-2D-E-4A2C4A-E-2D2(-4A2C4A-4D)-4A2C4A-2D-E3-2A2C2A3-E-2D12-2D48-2D12-2D-E-4A2C4A-E2-E-4A2C4A-E-2D-4A2C4A-2D-E-4A2C4A-E2-E3-2A2C2A3-E-2D12-2D64-2D-4A2C4A-2D-2(E-4A2C4A-E2-)E-4A2C4A-E-2D-2A6-2A-2D83-4A2C4A3-2D2(-4A2C4A-4D)-4A2C4A-2D3-4A2C4A8-2A2C2A88-3(A8-A6-)4A2C4A8-2A2C2A104-2(A8-A6-)4A2C4A8-2A2C2A53-
