model
size = 32 3 32, scale = 0.05, origin = -y
material 
  colors = A:#FFF B:#DEBF43 C:#F3E8BA D:#E1D5DA E:#DCCCD4 F:#9D697D G:#483360 H:#BB9AA2 I:#CAABB1 J:#CAA9B2 K:#C4A2B0 L:#BD9EAE M:#E5DADF N:#C9B5C0 O:#B39BAF P:#B29FB3 Q:#AB9AAF R:#AC9AAF S:#948098 T:#B3A6B8 U:#E5D9DE V:#BFA7B1 W:#A76271 X:#9B5D6F Y:#72314D Z:#A07C90 Aa:#F7F3F5 Ab:#9E7E97 Ac:#502250 Ad:#5C3D64 Ae:#563B63 Af:#2B0B3F Ag:#675073 Ah:#C49AA9 Ai:#693851 Aj:#BAA6B4 Ak:#E8E2E8 Al:#63426B Am:#664A72 An:#644E74 Ao:#483662 Ap:#A58299 Aq:#815573 Ar:#7E5975 As:#593052 At:#AD9BAB Au:#745D81 Av:#462A59 Aw:#5C486E Ax:#4E3C65 Ay:#BEBAC8 Az:#91728F Ba:#6C496F Bb:#715475 Bc:#4E2D52 Bd:#AC9CAD Be:#ADA0B2 Bf:#351B4A Bg:#54416B Bh:#524368 Bi:#231242 Bj:#736886 Bk:#816989 Bl:#5A3C66 Bm:#64486F Bn:#47254C Bo:#C2B4BF Bp:#EFEEF0 Bq:#3F274F Br:#4A3660 Bs:#4E3F67 Bt:#392A57 Bu:#302351 Bv:#766185 Bw:#4E315F Bx:#5A426B By:#48315B Bz:#897C94 Ca:#67546F Cb:#372048 Cc:#504067 Cd:#473861 Ce:#16063B Cf:#ADA8BB Cg:#6E5B80 Ch:#442E5D Ci:#4D3D6A Cj:#2E1E51 Ck:#A49DB3 Cl:#A69BAB Cm:#26103D Cn:#493B63 Co:#1D0F40 Cp:#5F5576 Cq:#5F5378 Cr:#332558 Cs:#3F376C Ct:#20144D Cu:#AAA3B7 Cv:#706785 Cw:#04002D Cx:#261B48 Cy:#E5E3E8 Cz:#544C71 Da:#291D4E Db:#463C6C Dc:#261A55 Dd:#968FA9 De:#2A224E Df:#8E889F Dg:#524C6E Dh:#291E4B Di:#453A67 Dj:#211653 Dk:#9793AF Dl:#DEDEE5 Dm:#B0AEBF Dn:#514A6B Do:#201744 Dp:#36305B Dq:#100A46 Dr:#9693AF Ds:#B7B5C2 Dt:#E5E4E8 Du:#0F0B32 Dv:#00001B Dw:#05012A Dx:#00000E Dy:#5B587A Dz:#6F6C84 Ea:#7C7A8D Eb:#CAC9D1 Ec:#8F8D9F Ed:#57556E Ee:#616077 Ef:#636179 Eg:#5A5871 Eh:#686681 Ei:#AFAFBE Ej:#CCCCD5 Ek:#807E93 El:#46435B Em:#9C9BA5 En:#D1D0D5 Eo:#C2C0CC
voxels
6A2-24A32-2(6A2-30A2-24A-6BC23B-)6(6A2-30A2-24A-B4ABC22AB-)6A2-30A2-4A5-2A8-5A-B4ABC4AEnEmElEkEj2AEiEhEgEfEeEdEcEb3AB-6A2-4A5-2A8-11A2-6A2-4A6-6A-B4ABC6AEaDz4ADyDxDwDvDuDt4AB-2(6A2-)4A6-12A2-7A2-3A5-7A-B4ABC7ADsEo3ADrDqDpDoDn5AB-6A2-7A2-3A5-13A2-8A2-2A5-7A-B4ABC8ADmDl2ADkDjDiDhDg5AB-6A2-8A2-2A5-13A2-8A2-2A5-7A-B4ABC8ADfDe2ADdDcDbDaCz5AB-6A2-8A2-2A5-13A2-7A4-A5-7A-B4ABC7ACyCxCwCvACuCtCsCrCq5AB-6A2-7A4-A5-13A2-7A10-7A-B4ABC7ACpCoCnCmClCkCjCiChCg5AB-6A2-7A10-13A2-6A11-7A-B4ABC6ACfCeCdCcCbCaBzByBxBwBv5AB-6A2-6A11-13A2-6A11-7A-B4ABC6ABuBtBsBrBqBpBoBnBmBlBk5AB-6A2-6A11-13A2-5A6-A5-7A-B4ABC5ABjBiBhBgBfBeABdBcBbBaAz5AB-6A2-5A6-A5-13A2-4A6-2A5-7A-B4ABC4AAyGAxAwAvAu2AAtAsArAqAp5AB-6A2-4A6-2A5-13A2-4A6-2A5-7A-B4ABC4AAoGAnAmAlAk2AAjAi2FAh5AB-6A2-4A6-2A5-13A2-3A6-2A7-6A-B4ABC3AAgAfAeAdAcAb2AAaZYXWVU4AB-6A2-3A6-2A7-12A2-2A17-5A-B4ABC2ATSRQPONM2ELKJIH2D3AB-6A2-2A17-11A7(2-24A-B4ABC22AB-6A2-30A)2-24A-6BC23B-6A2-30A2-24A32-6A2-24A
