model
size = 31 31 13, scale = 0.05, origin = -y
material 
  colors = A:#888 B:#111 C:#9CF
voxels
---------AAAAAAAAAAAAA--------- ---------AAAAAAAAAAAAA--------- ---------AAAAAAAAAAAAA--------- ---------AAAAAAAAAAAAA--------- ---------AAAAAAAAAAAAA--------- ---------AAAAAAAAAAAAA--------- ---------AAAAAAAAAAAAA--------- ---------AAAAAAAAAAAAA--------- ---------AAAAAAAAAAAAA--------- ---------AAAAAAAAAAAAA--------- ---------AAAAAAAAAAAAA--------- ---------AAAAAAAAAAAAA--------- ---------AAAAAAAAAAAAA--------- ---------AAAAAAAAAAAAA--------- ---------AAAAAAAAAAAAA--------- --------AAAAAAAAAAAAAAA-------- --------AAAAAAAAAAAAAAA-------- -------AAAAAAAAAAAAAAAAA------- -------AAAAAAAAAAAAAAAAA------- ------AAAAAAAAAAAAAAAAAAA------ ------AAAAAAAAAAAAAAAAAAA------ ------AAAAAAAAAAAAAAAAAAA------ -----AAAAAAAAAAAAAAAAAAAAA----- -----AAAAAAAAAAAAAAAAAAAAA----- ------AAAAAAAAAAAAAAAAAAA------ -------AAAAAAAAAAAAAAAAA------- ----------AAAAAAAAAAA---------- ------------------------------- ------------------------------- ------------------------------- ------------------------------- 
--------A-------------A-------- --------A-------------A-------- --------A-------------A-------- --------A-------------A-------- --------A-------------A-------- --------A-------------A-------- --------A-------------A-------- --------A-------------A-------- --------A-------------A-------- --------A-------------A-------- --------A-------------A-------- --------A-------------A-------- --------A-------------A-------- --------A-------------A-------- --------A-------------A-------- --------A-------------A-------- -------A---------------A------- -------A---------------A------- ------AA---------------AA------ ------AA---------------AA------ -----AAA---------------AAA----- ----AAAA---------------AAAA---- ----AAAA---------------AAAA---- ----AAAAA-------------AAAAA---- ------AAAA-----------AAAAA----- ------AAAAAA-------AAAAAA------ -------AAAAAAAAAAAAAAAAA------- ---------AAAAAAAAAAAAA--------- -----------AAAAAAAAA----------- ------------------------------- ------------------------------- 
-------A---------------A------- -------A---------------A------- -------A---------------A------- -------A---------------A------- -------A---------------A------- -------A---------------A------- -------A---------------A------- -------A---------------A------- -------A---------------A------- -------A---------------A------- -------A---------------A------- -------A---------------A------- -------A---------------A------- -------A---------------A------- -------A---------------A------- -------A---------------A------- -------A---------------A------- ------A-----------------A------ ------A-----------------A------ -----AA-----------------AA----- -----AA-----------------AA----- -----AA-----------------AA----- ---AAA-------------------AAA--- --A-AAA-----------------AAAAA-- -----AAA---------------AAAA---- -----AAAA-------------AAAA----- ------AAAAAAAAAAAAAAAAAAA------ -------AAAAAAAAAAAAAAAAA------- ---------AAAAAAAAAAAAA--------- ------------AAAAAAA------------ ------------------------------- 
-------A---------------A------- -------A---------------A------- -------A---------------A------- -------A---------------A------- -------A---------------A------- -------A---------------A------- -------A---------------A------- -------A---------------A------- -------A---------------A------- -------A---------------A------- -------A---------------A------- -------A---------------A------- -------A---------------A------- -------A---------------A------- -------A---------------A------- -------A---------------A------- ------A-----------------A------ ------A-----------------A------ -----AA-----------------AA----- -----AA-----------------AA----- ------------------------------- ------------------------------- --AA-----------------------AA-- --AAA---------------------AAA-- -AAAA---------------------AAAA- -----A-------------------AAA--- ----AAAA---------------AAAA---- -----AAAAAA---------AAAAAA----- -------AAAAAA-----AAAAAA------- ---------AAAA-----AAAA--------- ------------AAAAAAA------------ 
------A-----------------A------ ------A-----------------A------ ------A-----------------A------ ------A-----------------A------ ------A-----------------A------ ------A-----------------A------ ------A-----------------A------ ------A-----------------A------ ------A-----------------A------ ------A-----------------A------ ------A-----------------A------ ------A-----------------A------ ------A-----------------A------ ------A-----------------A------ ------A-----------------A------ ------A-----------------A------ ------A-----------------A------ -----AA-----------------AA----- ------------------------------- ------------------------------- ------------------------------- ------------------------------- ------------------------------- ------------------------------- -AAA-----------------------AAA- AAAAA---------------------AAAAA --AAA---------------------AAA-- ----AAAAA-------------AAAAA---- -----AAAAA-----------AAAAA----- --------AA-----------AA-------- ----------AAA-----AAA---------- 
------A-----------------A------ ------A-----------------A------ ------A-----------------A------ ------A-----------------A------ ------A-----------------A------ ------A-----------------A------ ------A-----------------A------ ------A-----------------A------ ------A-----------------A------ ------A-----------------A------ ------A-----------------A------ ------A-----------------A------ ------A-----------------A------ ------A-----------------A------ ------A-----------------A------ ------A-----------------A------ -----AA-----------------AA----- ------------------------------- ------------------------------- ------------------------------- ------------------------------- ------------------------------- ------------------------------- ------------------------------- -AAA-----------------------AAA- AAAAA---------------------AAAAA -AAAA---------------------ACAA- ---AAA-------------------AAA--- ----AAAAAA-----------AAAAAA---- ------AAAA-----------AAAA------ ----------A---------A---------- 
------A-----------------A------ ------A-----------------A------ ------A-----------------A------ ------A-----------------A------ ------A-----------------A------ ------A-----------------A------ ------A-----------------A------ ------A-----------------A------ ------A-----------------A------ ------A-----------------A------ ------A-----------------A------ ------A-----------------A------ ------A-----------------A------ ------A-----------------A------ ------A-----------------A------ ------A-----------------A------ -----AA-----------------AA----- ------------------------------- ------------------------------- ------------------------------- ------------------------------- ------------------------------- ------------------------------- ------------------------------- -AAA-----------------------AAA- AAAAA---------------------AAAAA -AAAA---------------------ACAA- ---AAA-------------------AAA--- ----AAAAAA-----------AAAAAA---- ------AAAA-----------AAAA------ ----------A---------A---------- 
------A-----------------A------ ------A-----------------A------ ------A-----------------A------ ------A-----------------A------ ------A-----------------A------ ------A-----------------A------ ------A-----------------A------ ------A-----------------A------ ------A-----------------A------ ------A-----------------A------ ------A-----------------A------ ------A-----------------A------ ------A-----------------A------ ------A-----------------A------ ------A-----------------A------ ------A-----------------A------ ------A-----------------A------ -----AA-----------------AA----- ------------------------------- ------------------------------- ------------------------------- ------------------------------- ------------------------------- ------------------------------- -AAA-----------------------AAA- AAAAA---------------------AAAAA --AAA---------------------AAA-- ----AAAAA-------------AAAAA---- -----AAAAA-----------AAAAA----- --------AA-----------AA-------- ----------AAA-----AAA---------- 
-------A---------------A------- -------A---------------A------- -------A---------------A------- -------A---------------A------- -------A---------------A------- -------A---------------A------- -------A---------------A------- -------A---------------A------- -------A---------------A------- -------A---------------A------- -------A---------------A------- -------A---------------A------- -------A---------------A------- -------A---------------A------- -------A---------------A------- -------A---------------A------- ------A-----------------A------ ------A-----------------A------ -----AA-----------------AA----- -----AA-----------------AA----- ------------------------------- ------------------------------- --AA-----------------------AA-- --AAA---------------------AAA-- -AAAAA-------------------AAAAA- ---AAAAAA-------------AAAAAA--- ----AAAAAA-----------AAAAAA---- -----AAAAA-----------AAAAA----- -------AACAA-------AAAAA------- ---------AAA-------AAA--------- ------------A-----A------------ 
--------A-------------A-------- --------A-------------A-------- --------A-------------A-------- --------A-------------A-------- --------A-------------A-------- --------A-------------A-------- --------A-------------A-------- --------A-------------A-------- --------A-------------A-------- --------A-------------A-------- --------A-------------A-------- --------A-------------A-------- --------A-------------A-------- --------A-------------A-------- --------A-------------A-------- -------A---------------A------- -------A---------------A------- ------A-----------------A------ ------A-----------------A------ -----AA-----------------AA----- -----AA-----------------AA----- -----AA-----------------AA----- ---AAAA-----------------AAAA--- --AAAAA-----------------AAAAA-- ----AAAA---------------AAAA---- -----AAAAA-----------AAAAA----- ------AAAA-----------AAAA------ -------AAAAAAAAAAAAAAAAA------- ---------AAAAAAAAAAAAA--------- ------------AAAAAAA------------ ------------------------------- 
---------A-----------A--------- ---------A-----------A--------- ---------A-----------A--------- ---------A-----------A--------- ---------A-----------A--------- ---------A-----------A--------- ---------A-----------A--------- ---------A-----------A--------- ---------A-----------A--------- ---------A-----------A--------- ---------A-----------A--------- ---------A-----------A--------- ---------A-----------A--------- ---------A-----------A--------- --------AA-----------AA-------- --------A-------------A-------- --------A-------------A-------- -------A---------------A------- ------AA---------------AA------ ------AA---------------AA------ -----AAA---------------AAA----- ----AAAA---------------AAAA---- ----AAAA---------------AAAA---- ----AAAA---------------AAAA---- -----AAAA-------------AAAA----- ------AAAAA---------AAAAA------ -------AAAAAAAAAAAAAAAAA------- ---------AAAAAAAAAAAAA--------- ------------AAAAAAA------------ ------------------------------- ------------------------------- 
----------AAAAAAAAAAA---------- ----------AAAAAAAAAAA---------- ----------AAAAAAAAAAA---------- ----------ABAAAAAAABA---------- ----------BBAAAAAAABB---------- ----------AABAAAAABAA---------- ----------AAABAAABAAA---------- ----------AAAABABAAAA---------- ----------AAAAABAAAAA---------- ----------AAAABABAAAA---------- ----------AAABAAABAAA---------- ----------AABAAAAABAA---------- ----------BBAAAAAAABB---------- ---------AABABBBBBABAA--------- ---------AAABBBBBBBAAA--------- ---------AAABAAAAABAAA--------- --------AAAAABBBBBAAAAA-------- --------AAAABAAAABBBAAA-------- -------AAAAABAABAAABBAAA------- -------AAAABAAAAAAABBAAA------- ------AAAAABABBABBABBAAAA------ ------AAAAABABBABBABBAAAA------ -----AAAAAAABAAAAAABBAAAAA----- -----AAAAAAABBAAAABBAAAAAA----- ------AAAAAAABBBBBBAAAAAA------ -------AAAAAAAAAAAAAAAAA------- ----------AAAAAAAAAAA---------- ------------------------------- ------------------------------- ------------------------------- ------------------------------- 
------------------------------- ------------------------------- ------------------------------- ------------------------------- -----------B-------B----------- ------------B-----B------------ -------------B---B------------- --------------B-B-------------- ---------------B--------------- --------------B-B-------------- -------------B---B------------- ------------B-----B------------ -----------B-------B----------- --------------BBB-------------- ------------BBBBBBB------------ ------------B-----B------------ -------------BBBB-------------- ------------B----BB------------ ------------B------B----------- -----------B-------B----------- -----------B-BB-BB-B----------- -----------B--B--B-B----------- ------------B------B----------- -------------B----B------------ --------------BBBB------------- ------------------------------- ------------------------------- ------------------------------- ------------------------------- ------------------------------- ------------------------------- 
