model
size = 31 3 31, scale = 0.05, origin = -y
material 
  colors = A:#555 B:#2B1E00
voxels
------------AAAAAAA------------ ------------------------------- ------------AAAAAAA------------ 
---------AAAAAAAAAAAAA--------- ------------------------------- ---------AAAAAAAAAAAAA--------- 
-------AAAAA-------AAAAA------- ------------------------------- -------AAAAA-------AAAAA------- 
------AAAAAA-------AAAAAA------ ------------BBBBBBB------------ ------AAAAAA-------AAAAAA------ 
-----AAAAAAA-------AAAAAAA----- ----------BBBBBBBBBBB---------- -----AAAAAAA-------AAAAAAA----- 
----AAAAAAAA-------AAAAAAAA---- --------BBBBBBBBBBBBBBB-------- ----AAAAAAAA-------AAAAAAAA---- 
---AAAAAAAAA-------AAAAAAAAA--- -------BBBBBBBBBBBBBBBBB------- ---AAAAAAAAA-------AAAAAAAAA--- 
--AAAAAAAAAAA-----AAAAAAAAAAA-- ------BBBBBBBBBBBBBBBBBBB------ --AAAAAAAAAAA-----AAAAAAAAAAA-- 
--AAAAAAAAAAA-----AAAAAAAAAAA-- -----BBBBBBBBBBBBBBBBBBBBB----- --AAAAAAAAAAA-----AAAAAAAAAAA-- 
-AAAAAAAAAAAAA---AAAAAAAAAAAAA- -----BBBBBBBBBBBBBBBBBBBBB----- -AAAAAAAAAAAAA---AAAAAAAAAAAAA- 
-AAAAAAAAAAAAA---AAAAAAAAAAAAA- ----BBBBBBBBBBBBBBBBBBBBBBB---- -AAAAAAAAAAAAA---AAAAAAAAAAAAA- 
-AAAAAAAAAAAAAA-AAAAAAAAAAAAAA- ----BBBBBBBBBBBBBBBBBBBBBBB---- -AAAAAAAAAAAAAA-AAAAAAAAAAAAAA- 
AA-----AAAAAAAA-AAAAAAAA-----AA ---BBBBBBBBBBBBBBBBBBBBBBBBB--- AA-----AAAAAAAA-AAAAAAAA-----AA 
AA-------AAAAAAAAAAAAA-------AA ---BBBBBBBBBBBBBBBBBBBBBBBBB--- AA-------AAAAAAAAAAAAA-------AA 
AA---------AAAAAAAAA---------AA ---BBBBBBBBBBBBBBBBBBBBBBBBB--- AA---------AAAAAAAAA---------AA 
AA-----------AA-AA-----------AA ---BBBBBBBBBBBB-BBBBBBBBBBBB--- AA-----------AA-AA-----------AA 
AA---------AAAAAAAAA---------AA ---BBBBBBBBBBBBBBBBBBBBBBBBB--- AA---------AAAAAAAAA---------AA 
AA-------AAAAAAAAAAAAA-------AA ---BBBBBBBBBBBBBBBBBBBBBBBBB--- AA-------AAAAAAAAAAAAA-------AA 
AA-----AAAAAAAA-AAAAAAAA-----AA ---BBBBBBBBBBBBBBBBBBBBBBBBB--- AA-----AAAAAAAA-AAAAAAAA-----AA 
-AAAAAAAAAAAAAA-AAAAAAAAAAAAAA- ----BBBBBBBBBBBBBBBBBBBBBBB---- -AAAAAAAAAAAAAA-AAAAAAAAAAAAAA- 
-AAAAAAAAAAAAA---AAAAAAAAAAAAA- ----BBBBBBBBBBBBBBBBBBBBBBB---- -AAAAAAAAAAAAA---AAAAAAAAAAAAA- 
-AAAAAAAAAAAAA---AAAAAAAAAAAAA- -----BBBBBBBBBBBBBBBBBBBBB----- -AAAAAAAAAAAAA---AAAAAAAAAAAAA- 
--AAAAAAAAAAA-----AAAAAAAAAAA-- -----BBBBBBBBBBBBBBBBBBBBB----- --AAAAAAAAAAA-----AAAAAAAAAAA-- 
--AAAAAAAAAAA-----AAAAAAAAAAA-- ------BBBBBBBBBBBBBBBBBBB------ --AAAAAAAAAAA-----AAAAAAAAAAA-- 
---AAAAAAAAA-------AAAAAAAAA--- -------BBBBBBBBBBBBBBBBB------- ---AAAAAAAAA-------AAAAAAAAA--- 
----AAAAAAAA-------AAAAAAAA---- --------BBBBBBBBBBBBBBB-------- ----AAAAAAAA-------AAAAAAAA---- 
-----AAAAAAA-------AAAAAAA----- ----------BBBBBBBBBBB---------- -----AAAAAAA-------AAAAAAA----- 
------AAAAAA-------AAAAAA------ ------------BBBBBBB------------ ------AAAAAA-------AAAAAA------ 
-------AAAAA-------AAAAA------- ------------------------------- -------AAAAA-------AAAAA------- 
---------AAAAAAAAAAAAA--------- ------------------------------- ---------AAAAAAAAAAAAA--------- 
------------AAAAAAA------------ ------------------------------- ------------AAAAAAA------------ 
