model
size = 31 19 27, scale = 0.05, origin = -y
material 
  colors = A:#FF0 B:#6F6 C:#3FF D:#F93 E:#66F F:#F0F G:#F06
voxels
------------------------------- ------------------------------- ------------------------------- ------------------------------- ---------------F--------------- --------------FFF-------------- -------------FF-FF------------- ------------FF---FF------------ -----------FF-----FF----------- ----------FF-------FF---------- ---------FF---------FF--------- --------FF-----------FF-------- --------F-------------F-------- --------FF----FFF----FF-------- ---------FF--FF-FF--FF--------- ----------FFFF---FFFF---------- -----------FF-----FF----------- ------------------------------- ------------------------------- 
------------------------------- ------------------------------- ---------------E--------------- --------------EEE-------------- -------------EEEEE------------- ------------EEEEEEE------------ -----------EEEEEEEEE----------- ----------EEE-E-E-EEE---------- ---------EEEEE---EEEEE--------- --------EEE-E-----EEEEE-------- -------EEEEE-------E-EEE------- ------EEEEE---------EEEEE------ ------EEEE----EEE----EEEE------ ------EEEEE--EE--E--EEEEE------ -------EEEEEEEEEE-EEEEEE------- --------EEEEEEEEEEEEEEE-------- ---------EEEEEE-EEEEEE--------- ----------EEEE---EEEE---------- ------------------------------- 
---------------C--------------- --------------CCC-------------- -------------CCCCC------------- ------------CCCCCCC------------ -----------CCC---CCC----------- ----------CCC-----CCC---------- ---------CCC-------CCC--------- --------CCC----C----CCC-------- -------CCC----C-C----CCC------- ------CCC----C---C----CCC------ -----CCCC---C-----C----CCC----- -----CCC---C--CCC--C---CCC----- -----CCC--C--C---C--C--CCC----- -----CCC---CC----CCC---CCC----- -----CCC---------------CCC----- ------CCC--C--CCC-----CCC------ -------CCC--CCCCCCC-CCCC------- --------CCCCCCCCCCCCCCC-------- ---------CCCCCC-CCCCCC--------- 
------------------------------- ---------------B--------------- --------------BBB-------------- -------------BBBBB------------- ------------BBB-BBB------------ -----------BBB---BBB----------- ----------BBB------BB---------- ---------BBB--------BB--------- --------BBB----B-----BB-------- -------BBB----BBB-----BB------- ------BBB----BBBBB----BBB------ ------BB----BB---BB----BB------ ------BB---BB-----BB---BB------ ------BB---------------BB------ ------BBB--------------BB------ -------BBBBBBBBBBBBBBBBB------- --------BBBBBBB-BBBBBBB-------- ---------BBBBB---BBBBB--------- ------------------------------- 
------------------------------- ------------------------------- ---------------A--------------- --------------AAA-------------- -------------AAAAA------------- ------------AAAAAAA------------ -----------AAAAAAAAA----------- ----------AAAAAAAAAAA---------- ---------AAAA-----AAAA--------- --------AAAA-------AAAA-------- -------AAAAAAAAAAAAAAAAA------- -------AAAA-AAAAAAA-AAAA------- -------AAAA-AAAAAAA-AAAA------- -------AAAA-AAAAAAA-AAAA------- -------AAAAAAAAAAAAAAAAA------- --------AAAAAAA-AAAAAAA-------- ---------AAAAA---AAAAA--------- ------------------------------- ------------------------------- 
------------------------------- ------------------------------- ------------------------------- ---------------D--------------- --------------DDD-------------- -------------DDDDD------------- ------------DDDDDDD------------ -----------DDDDDDDDD----------- ----------DDDDDDDDDDD---------- ---------DDDDDDDDDDDDD--------- --------DDDDDDDDDDDDDDD-------- --------DDDDDDDDDDDDDDD-------- --------DDDDDDDDDDDDDDD-------- --------DDDDDDDDDDDDDDD-------- --------DDDDDDD-DDDDDDD-------- ---------DDDDD---DDDDD--------- ------------------------------- ------------------------------- ------------------------------- 
------------------------------- ------------------------------- ------------------------------- ------------------------------- ------------------------------- ------------------------------- ------------------------------- ------------------------------- ------GGGGGGGGGGGGGGGGGGG------ ------GGG---GGGGGGG---GGG------ ------GGG---GGGGGGG---GGG------ ------GGG---GGGGGGG---GGG------ ------GGG---GGGGGGG---GGG------ ------GGGGGGGGGGGGGGGGGGG------ ------------------------------- ------------------------------- ------------------------------- ------------------------------- ------------------------------- 
------------------------------- ------------------------------- ------------------------------- ------------------------------- ------------------------------- ------------------------------- ------------------------------- ------------------------------- ----FFFFFFFFF-----FFFFFFFFF---- ----FFF-FFFFF-----FFFFF-FFF---- ----FFF-FFFFF-----FFFFF-FFF---- ----FFF-FFFFF-----FFFFF-FFF---- ----FFF-FFFFF-----FFFFF-FFF---- ----FFFFFFFFF-----FFFFFFFFF---- ------------------------------- ------------------------------- ------------------------------- ------------------------------- ------------------------------- 
------------------------------- ------------------------------- ------------------------------- ------------------------------- ------------------------------- ------------------------------- ------------------------------- ------------------------------- ---EEEEEE-------------EEEEEE--- ---EE-EEE-------------EEE-EE--- ---EE-EEE-------------EEE-EE--- ---EE-EEE-------------EEE-EE--- ---EE-EEE-------------EEE-EE--- ---EEEEEE-------------EEEEEE--- ------------------------------- ------------------------------- ------------------------------- ------------------------------- ------------------------------- 
------------------------------- ------------------------------- ------------------------------- ------------------------------- ------------------------------- ------------------------------- ------------------------------- ------------------------------- --CCCCC-----------------CCCCC-- --CC-CC-----------------CC-CC-- --CC-CC-----------------CC-CC-- --CC-CC-----------------CC-CC-- --CC-CC-----------------CC-CC-- --CCCCC-----------------CCCCC-- ------------------------------- ------------------------------- ------------------------------- ------------------------------- ------------------------------- 
------------------------------- ------------------------------- ------------------------------- ------------------------------- ------------------------------- ------------------------------- ------------------------------- ------------------------------- -BBBBB-------------------BBBBB- -BB-BB-------------------BB-BB- -BB-BB-------------------BB-BB- -BB-BB-------------------BB-BB- -BB-BB-------------------BB-BB- -BBBBB-------------------BBBBB- ------------------------------- ------------------------------- ------------------------------- ------------------------------- ------------------------------- 
------------------------------- ------------------------------- ------------------------------- ------------------------------- ------------------------------- ------------------------------- ------------------------------- ------------------------------- AAAAA---------------------AAAAA AA-AA---------------------AA-AA AA-AA---------------------AA-AA AA-AA---------------------AA-AA AA-AA---------------------AA-AA AAAAA---------------------AAAAA ------------------------------- ------------------------------- ------------------------------- ------------------------------- ------------------------------- 
------------------------------- ------------------------------- ------------------------------- ------------------------------- ------------------------------- ------------------------------- ------------------------------- ------------------------------- DDDD-----------------------DDDD D--D-----------------------D--D D--D-----------------------D--D D--D-----------------------D--D D--D-----------------------D--D DDDD-----------------------DDDD ------------------------------- ------------------------------- ------------------------------- ------------------------------- ------------------------------- 
------------------------------- ------------------------------- ------------------------------- ------------------------------- ------------------------------- ------------------------------- ------------------------------- ------------------------------- GGG-------------------------GGG G-G-------------------------G-G G-G-------------------------G-G G-G-------------------------G-G G-G-------------------------G-G GGG-------------------------GGG ------------------------------- ------------------------------- ------------------------------- ------------------------------- ------------------------------- 
------------------------------- ------------------------------- ------------------------------- ------------------------------- ------------------------------- ------------------------------- ------------------------------- ------------------------------- FFF-------------------------FFF F-F-------------------------F-F F-F-------------------------F-F F-F-------------------------F-F F-F-------------------------F-F FFF-------------------------FFF ------------------------------- ------------------------------- ------------------------------- ------------------------------- ------------------------------- 
------------------------------- ------------------------------- ------------------------------- ------------------------------- ------------------------------- ------------------------------- ------------------------------- ------------------------------- EEE-------------------------EEE E-E-------------------------E-E E-E-------------------------E-E E-E-------------------------E-E E-E-------------------------E-E EEE-------------------------EEE ------------------------------- ------------------------------- ------------------------------- ------------------------------- ------------------------------- 
------------------------------- ------------------------------- ------------------------------- ------------------------------- ------------------------------- ------------------------------- ------------------------------- ------------------------------- CCC-------------------------CCC C-C-------------------------C-C C-C-------------------------C-C C-C-------------------------C-C C-C-------------------------C-C CCC-------------------------CCC ------------------------------- ------------------------------- ------------------------------- ------------------------------- ------------------------------- 
------------------------------- ------------------------------- ------------------------------- ------------------------------- ------------------------------- ------------------------------- ------------------------------- ------------------------------- BBB-------------------------BBB B-B-------------------------B-B B-B-------------------------B-B B-B-------------------------B-B B-B-------------------------B-B BBB-------------------------BBB ------------------------------- ------------------------------- ------------------------------- ------------------------------- ------------------------------- 
------------------------------- ------------------------------- ------------------------------- ------------------------------- ------------------------------- ------------------------------- ------------------------------- ------------------------------- AAA-------------------------AAA AAA-------------------------AAA AAA-------------------------AAA AAA-------------------------AAA A-A-------------------------AAA AAA-------------------------AAA ------------------------------- ------------------------------- ------------------------------- ------------------------------- ------------------------------- 
------------------------------- ------------------------------- ------------------------------- ------------------------------- ------------------------------- ------------------------------- ------------------------------- ------------------------------- DDDD-----------------------DDDD DD-D-----------------------D-DD DD-D-----------------------D-DD DD-D-----------------------D-DD DD-D-----------------------D-DD DDDD-----------------------DDDD ------------------------------- ------------------------------- ------------------------------- ------------------------------- ------------------------------- 
------------------------------- ------------------------------- ------------------------------- ------------------------------- ------------------------------- ------------------------------- ------------------------------- ------------------------------- -GGGG---------------------GGGG- -G--G---------------------G--G- -G--G---------------------G--G- -G--G---------------------G--G- -G--G---------------------G--G- -GGGG---------------------GGGG- ------------------------------- ------------------------------- ------------------------------- ------------------------------- ------------------------------- 
------------------------------- ------------------------------- ------------------------------- ------------------------------- ------------------------------- ------------------------------- ------------------------------- ------------------------------- --FFFF-------------------FFFF-- --F-FF-------------------FF-F-- --F-FF-------------------FF-F-- --F-FF-------------------FF-F-- --F-FF-------------------FF-F-- --FFFF-------------------FFFF-- ------------------------------- ------------------------------- ------------------------------- ------------------------------- ------------------------------- 
------------------------------- ------------------------------- ------------------------------- ------------------------------- ------------------------------- ------------------------------- ------------------------------- ------------------------------- ---EEEEE---------------EEEEE--- ---E--EE---------------EE--E--- ---E--EE---------------EE--E--- ---E--EE---------------EE--E--- ---E--EE---------------EE--E--- ---EEEEE---------------EEEEE--- ------------------------------- ------------------------------- ------------------------------- ------------------------------- ------------------------------- 
------------------------------- ------------------------------- ------------------------------- ------------------------------- ------------------------------- ------------------------------- ------------------------------- ------------------------------- ----CCCCCC-----------CCCCCC---- ----C--CCC-----------CCC--C---- ----C--CCC-----------CCC--C---- ----C--CCC-----------CCC--C---- ----C--CCC-----------CCC--C---- ----CCCCCC-----------CCCCCC---- ------------------------------- ------------------------------- ------------------------------- ------------------------------- ------------------------------- 
------------------------------- ------------------------------- ------------------------------- ------------------------------- ------------------------------- ------------------------------- ------------------------------- ------------------------------- -----BBBBBBBBBB-BBBBBBBBBB----- -----BB--BBBBBB-BBBBBB--BB----- -----BB--BBBBBB-BBBBBB--BB----- -----BB--BBBBBB-BBBBBB--BB----- -----BB--BBBBBB-BBBBBB--BB----- -----BBBBBBBBBB-BBBBBBBBBB----- ------------------------------- ------------------------------- ------------------------------- ------------------------------- ------------------------------- 
------------------------------- ------------------------------- ------------------------------- ------------------------------- ------------------------------- ------------------------------- ------------------------------- ------------------------------- -------AAAAAAAAAAAAAAAAA------- -------AAA----AAA----AAA------- -------AAA----AAA----AAA------- -------AAA----AAA----AAA------- -------AAA----AAA----AAA------- -------AAAAAAAAAAAAAAAAA------- ------------------------------- ------------------------------- ------------------------------- ------------------------------- ------------------------------- 
------------------------------- ------------------------------- ------------------------------- ------------------------------- ------------------------------- ------------------------------- ------------------------------- ------------------------------- ---------DDDDDDDDDDDDD--------- ---------DDDDDDDDDDDDD--------- ---------DDDDDDDDDDDDD--------- ---------DDDDDDDDDDDDD--------- ---------DDDDDDDDDDDDD--------- ---------DDDDDDDDDDDDD--------- ------------------------------- ------------------------------- ------------------------------- ------------------------------- ------------------------------- 
