model
size = 13 14 32, scale = 0.05, origin = -y
material 
  colors = A:#66F B:#F0F C:#FF0 D:#3FF E:#F93 F:#6F6 G:#F06
voxels
45-B11-3B9-2B-2B7-2B3-2(2B5-)2B3-2B7-2B2-B9-B2-2(B4-)B2-2B2-3B2-2B3-4B-4B47-A11-3A9-5A7-7A5-4A-2(4A3-)4A-4A5-7A3-A3-6A2-3A2-16A2(-5A)2(3-3A)47-D11-3D9-2D-2D7-2D3-2(2D5-)2D3-2D7-2D2-D9-D2-2(D4-)D2-2D2-3D2-2D3-4D-4D632-F11-F-F9-F3-F7-2(F5-)F7-F4-2F2-F2-2F5-3F-3F87-C11-3C9-2C-2C7-2C3-2(2C5-)2C3-2C7-2C2-3C2-C2-3C3-4C-4C5-3C-3C87-E11-E-E9-E3-E7-2(E5-)E7-E4-2E2-E2-2E5-3E-3E659-G11-G-G9-G3-G7-2(G2-)G7-2G-2G114-B11-3B9-2B-2B7-2B3-2B5-2B2-B2-2B4-9B5-3B-3B113-A11-A-A9-A3-A7-2(A2-)A7-2A-2A504-D11-D-D11-D155-F11-F-F11-F155-C11-C-C11-C155-E11-E-E11-E155-G11-G-G11-G155-B11-B-B11-B155-A11-3A11-A155-D11-3D11-D142-F11-3F9-5F9-3F11-F103-2(C12-)C11-3C9-5C9-3C11-C90-E38-E11-3E9-5E9-3E11-E90-G38-G11-3G9-5G9-3G11-G51-3(B12-)B25-B11-2(3B10-)3B11-B63-7(3A10-)3A11-2(A12-)A51-7(D12-)D38-D45-
