model
size = 32 32 11, scale = 0.05, origin = -y
material 
  colors = A:#010 B:#100 C:#111 D:#020 E:#222 F:#696 G:#333 H:#363 I:#CC0 J:#555 K:#BBB L:#330 M:#F90 N:#E00 O:#663 P:#C99 Q:#444 R:#800 S:#966 T:#660 U:#C33 V:#999 W:#700 X:#AAA Y:#C90 Z:#666 Aa:#F00 Ab:#200 Ac:#A00 Ad:#990 Ae:#888 Af:#FC0 Ag:#969 Ah:#F9C Ai:#EEE Aj:#FFF Ak:#9C9 Al:#C00 Am:#777 An:#D00 Ao:#030 Ap:#DDD Aq:#F30 Ar:#500 As:#900 At:#F60 Au:#633 Av:#CCC Aw:#933 Ax:#C30 Ay:#033 Az:#366 Ba:#960 Bb:#FF9 Bc:#400 Bd:#B00 Be:#630 Bf:#C60 Bg:#C96 Bh:#FFE0E0 Bi:#FCF Bj:#F93 Bk:#C9C Bl:#993 Bm:#FC3 Bn:#996 Bo:#693 Bp:#F33 Bq:#F63
voxels
-SP2-E-A-Ay10-B-2B5-PS-3S2-Am-BQB9-DAeAAmC5-2AuS-SP2-JAmGAmBA8-APAZJB4-SAu6-AAvJAvGB8-AKAmKVC12-BEVGQA8-QGVAmKE13-AAeZA2-3ACD3-AGKZC12-CDJE2A5BADA-BEAgA12-A2BJADCGC2GHAzDAECEJA12-BRAE2A2G3D2BD2ACEGA2E10-AqArCA2CEBKCKBEC2A2E2ACDC9-MArCAEAFCF2CAHAy2(DA)CDWAxC2A7-L4AOVXCAEAkHAzE3A2DWBaMUN7-BAsDAEFAeAjVEApK2FED2ADCAlBaCAC7-MAnDCAoHFApAvHAiAe2XJD2A2C3MAD7-MBgBGHJ2F2HF2X2FD3A2L2MIU7-Bd2BAoFABFAhBhBiH3FGE2BLCLAqBbU7-RBJEFAAj2(JH)FACFQAhAg2BAfALAfI7-BEAGJD2A3H2AAjDAoFAmAgBIAfABpAf7-CGAECEQ2JAHF2HFHAoQAhBAtMUAwAl7-DJEAgQC2ACA2C2QGBkHGVBWAqAAwA7-AB2ZE2BL5OELAe2AhAgBAMIB9-2BG2ATYIYAa2YAdTBZJQ2BMBjB324-PSP2-E-A-Ay10-B-2B5-3P3S2-CJBQB9-DAeAAmC5-Au2(PS)P2-C2GAmBA8-APAZJB4-SAuP5-AAvJAvGB8-AKEKVC12-BEVGQA8-QGVAmKC13-AAeZA2-3ACD3-AGKZC12-CDJE2A5BADA-BEAgA12-A2B2ADCGC3GAzDAECAJA11-ABRAE2A2G3D2BD2ACAGA2E8-AAcAqArCA2CEBKCKBEC6ACDC7-WAlMArCAEAFCF2CAHAy2(DA)CDWAxC3A4-AuML4AOVXCAEAkHAzE3A2DWBaMU2N4-MABAsDAEFAeAjVEApK2FED2ADCAlBaCACAa4-BqAMAnDCAoHFApAvHAiAe2XJD2A2C3MADC4-AfAMBgBGHJ2F2HF2X2FD3A2L2MIUD4-ANBd2BAoFABFAhBhBiH3FGE2BLCLAqBbUA5-ARBJEFAAj2(JH)FACFQAhAg2BAfALBbIL5-3BAGJD2A3H2AAjDAoFAmAgBIAfA2AfU5-AnCGA2CE3JAHF2HFHAoQAhBIAUAwAlC5-IDGEAgQC2ACA3CQGBkHGVBUAqAAwAAc5-2AB2Z3B5O3LAe2AhAgBAMIBCAc5-AdY2BG2ATYIYAa2YTLBZJQ2BMBjB8-BeBcB2CTAaAd2IY2AdIAaT3BABWAtB292-PSP2-E-A-Ay10-B-2B5-3P3S2-CJBEB9-DAeAAmC5-Au2(PS)P2-C2GAmBA8-APAZJB4-SAuP5-AAvJAvGB8-AKEKVC12-BEVGQA8-QGVAmKC13-AAeZA2-3ACD3-AGKZC12-CDJE2A5BADA-BEAgA12-A2B2ADCGC3GAzDAECAJA11-ABRAE2A2G3D2BD2ACAGA2E8-AAcAqArCA2CEBKCKBEC6ACDC6-BWAlMArCAEAFCF2CAHAy2(DA)CDWAxC3A3-WAuML4AOVXCAEAkHAzE3A2DWBaMU2NL2-AcMABAsDAEFAeAjVEApK2FED2ADCAlBaCACAaN2-AtAxAMAnDCAoHFApAvHAiAe2XJD2A2C3MADCAa2-BAfAMBgBGHJ2F2HF2X2FD3A2L2MIUDL2-AtANBd2BAoFABFAhBhBiH3FGE2BLCLAqBbUA3-BNARBJEFAAj2(JH)FACFQAhAg2BAfALBbILA4-3BAGJD2A3H2AAjDAoFAmAgBIAfA2AfUA3-WAnCGA2CE3JAHF2HFHAoQAhBIAUAwAlCR2-BNIDGEAgQC2ACA3CQGBkHGVBUAqAAwAAcR2-BN2AB2Z3B5O3LAe2AhAgBAMIBCBR3-MAdY2BG2ATYIYAa2YTLBZJQ2BMBjB-AbR3-AtBc2BeB2CAAaO2IYAdTIAaL3BABWAtB2-Ab5-MNUCETITAd2IOAd2IAdCZBANBNRA259-PSP2-E-A-Ay10-B-2B5-3P3S2-CJBEB9-DAeAAmC5-Au2(PS)P2-C2GAmBA8-APAZJB4-SAuP5-AAvJAvGB8-AKEKVC12-BEVGQA8-QGVAmKC13-AAeZA2-3ACD3-AGKZC12-CDJE2A5BAD2-BEAgA12-A2B2ADCGC3GAzDAECAJA11-ABRAE2A2G3D2BD2ACAGA2E8-AAcAqArCA2CEBKCKBEC6ACDC6-BWAlMArCAEAFCF2CAHAy2(DA)CDWAxC3A3-WAuML4AOVXCAEAkHAzE3A2DWBaMU2NL-AAcMABAsDAEFAeAjVEApK2FED2ADCAlBaCACAaNLEAtAxAMAnDCAoHFApAvHAiAe2XJD2A2C3MADCAaAsAcBAfAMBgBGHJ2F2HF2X2FD3A2L2MIUDLAcBcAtANBd2BAoFABFAhBhBiH3FGE2BLCLAqBbUA-Aa-BNARBJEFAAj2(JH)FACFQAhAg2BAfALBbILA4-3BAGJD2A3H2AAjDAoFAmAgBIAfA2AfUA3-WAnCGA2CE3JAHF2HFHAoQAhBIAUAwAlCRAr-BNIDGEAgQC2ACA3CQGBkHGVBUAqAAwAAcRBcAbBN2AB2Z3B5O3LAe2AhAgBAMIBCBRCAbAcMAdY2BG2ATYIYAa2YTLBZJQ2BMBjB-AbAqR2-AtBd2BeB2CAAaO2IYAdTIAaL3BABWAtB2-Ab3-BcAwMNUCVBIQAd2IOT2IAdCJBAAkB2NA6-NBfAsAAiETIBEIAd2BOAdLJX2A2NAAaA227-PSP2-E-A-Ay10-B-2B5-3P3S2-CJBEB9-DAeAAmC5-Au2(PS)P2-C2GAmBA8-APAZJB4-SAuP5-AAvJAvGB8-AKEKVC12-BEVGQA8-QGVAmKC13-AAeZA2-3ACD4-GKZC12-CDJE2A5BADA2-EAgA12-A2B2ADCGC3GAzDAECAJA11-ABRAE2A2G3D2BD2ACAGA2E8-AbAcAqArCA2CEBKCKBEC6ACDC6-BWAlMArCAEAFCF2CAHAy2(DA)CDWAxC3A3-WAuML4AOVXCAEAkHAzE3A2DWBaMU2NL-AAcMABAsDAEFAeAjVEApK2FED2ADCAlBaCACAaNLEAtAxAMAnDCAoHFApAvHAiAe2XJD2A2C3MADCAaAsAcBAfAMBgBGHJ2F2HF2X2FD3A2L2MIUDLAcBcAtANBd2BAoFABFAhBhBiH3FGE2BLCLAqBbUA-Aa-BNARBJEFAAj2(JH)FACFQAhAg2BAfALBbILA4-3BAGJD2A3H2AAjDAoFAmAgBIAfA2AfUA3-WAnCGA2CE3JAHF2HFHAoQAhBIAUAwAlCRAr-BNIDGEAgQC2ACA3CQGBkHGVBUAqAAwAAcRBcAbBN2AB2Z3B5O3LAe2AhAgBAMIBCBRCAbAcMAdY2BG2ATYIYAa2YTLBZJQ2BMBjB-AbAqRAbAxAtBd2BeB2CAAaO2IYAdTIAaL3BABWAtB2-2(AbR)BAwMNUCVBIQAd2IOT2IAdCJBAAkB2NA4-ArAnNBfAsA2KBIBEIG2BOTLCAj2A2AkAAaA5-RBfAsAiKAi-LIABAdA3BIAdCAj2AMAiAWA195-PSP2-E-A-Ay10-B-2B5-3P3S2-CJBEB9-DAeAAmC5-Au2(PS)P2-C2GAmBA8-APAZJB4-SAuP5-AAvJAvGB8-AKEKVC12-BEVGQA8-QGVAmKC13-AAeZA2-3ACD4-GKZC12-CDJE2A5BADA2-EAgA12-A2B2ADCGC3GAzDAECAJA11-ABRAE2A2G3D2BD2ACAGA2E8-AbAcAqArCA2CEBKCKBEC6ACDC6-BWAlMArCAEAFCF2CAHAy2(DA)CDWAxC3A3-WAuML4AOVXCAEAkHAzE3A2DWBaMU2NL-AAcMABAsDAEFAeAjVEApK2FED2ADCAlBaCACAaNLEAtAxAMAnDCAoHFApAvHAiAe2XJD2A2C3MADCAaAsAcBAfAMBgBGHJ2F2HF2X2FD3A2L2MIUDLAcBcAtANBd2BAoFABFAhBhBiH3FGE2BLCLAqBbUA-Aa-BNARBJEFAAj2(JH)FACFQAhAg2BAfALBbILA4-3BAGJD2A3H2AAjDAoFAmAgBIAfA2AfUA3-WAnCGA2CE3JAHF2HFHAoQAhBIAUAwAlCRAr-BNIDGEAgQC2ACA3CQGBkHGVBUAqAAwAAcRBcAbBN2AB2Z3B5O3LAe2AhAgBAMIBCBRCAbAcMAdY2BG2ATYIYAa2YTLBZJQ2BMBjB-AbAqRAbAxAtBd2BeB2CAAaO2IYAdTIAaL3BABWAtB2-2(AbR)BAwMNUCVBIQAd2IOT2IAdCJBAAkB2NA2-RAbJAnNBfAsA2KBIBEIG2BOTLCAj2A2AkAAaA4-ARBfAsAi2KECIABAdA3BIAdCAj2AAk-AWA5-AlAsArK2AiTIO-TIHBBlBAfTLAiJAMAiMAnAr163-PSP2-E-A-Ay10-B-2B5-3P3S2-CJBEB9-DAeAAmC5-Au2(PS)P2-C2GAmBA8-APAZJB4-SAuP5-AAvJAvGB8-AKEKVC12-BEVGQ9-QGVAmKC13-AAeZA2-3ACD4-GKZC12-CDJE2A5BADA2-EAgA12-A2B2ADCGC3GAzDAECAJA11-ABRAE2A2G3D2BD2ACAGA2E8-AAcAqArCA2CEBKCKBEC6ACDC6-BWAlMArCAEAFCF2CAHAy2(DA)CDWAxC3A3-WAuML4AOVXCAEAkHAzE3A2DWBaMU2NL-AAcMABAsDAEFAeAjVEApK2FED2ADCAlBaCACAaNLEAtAxAMAnDCAoHFApAvHAiAe2XJD2A2C3MADCAaAsAcBAfAMBgBGHJ2F2HF2X2FD3A2L2MIUDLAcBcAtANBd2BAoFABFAhBhBiH3FGE2BLCLAqBbUA-Aa-BNARBJEFAAj2(JH)FACFQAhAg2BAfALBbILA4-3BAGJD2A3H2AAjDAoFAmAgBIAfA2AfUA3-WAnCGA2CE3JAHF2HFHAoQAhBIAUAwAlCRAr-BNIDGEAgQC2ACA3CQGBkHGVBUAqAAwAAcRBcAbBN2AB2Z3B5O3LAe2AhAgBAMIBCBRCAbAcMAdY2BG2ATYIYAa2YTLBZJQ2BMBjB-AbAqRAbAxAtBd2BeB2CAAaO2IYAdTIAaL3BABWAtB2-2(AbR)BAwMNUCVBIQAd2IOT2IAdCJBAAkB2NA2-RAbJAnNBfAsA2KBIBEIG2BOTLCAj2A2AkAAaA4-ARBfAsAi2KAiCIABAdA3BIAdCAj2A2AkAWA4-CAlAs-K2AiTIO-TIHBBlBY2TAiXAF2AiAnAr5-AnAlAr3KETBKFLBCIF2BLApAiAAoMNAl132-PSP2-E-A-Ay10-B-2B5-3P3S2-CJBEB9-DAeAAmC5-Au2(PS)P2-C2GAmBA8-APAZJB4-SAuP5-AAvJAvGB8-AKEKVC12-BEVGQ9-QGVAmKC13-AAeZA2-3ACD3-AGKZC12-CDJE2A5BADA-BEAgA12-A2B2ADCGC3GAzDAECAJA11-ABRAE2A2G3D2BD2ACAGA2E8-AAcAqArCA2CEBKCKBEC6ACDC6-BWAlMArCAEAFCF2CAHAy2(DA)CDWAxC3A3-WAuML4AOVXCAEAkHAzE3A2DWBaMU2NL-AAcMABAsDAEFAeAjVEApK2FED2ADCAlBaCACAaNLEAtAxAMAnDCAoHFApAvHAiAe2XJD2A2C3MADCAaAsAcBAfAMBgBGHJ2F2HF2X2FD3A2L2MIUDLAcBcAtANBd2BAoFABFAhBhBiH3FGE2BLCLAqBbUA-Aa-BNARBJEFAAj2(JH)FACFQAhAg2BAfALBbILA4-3BAGJD2A3H2AAjDAoFAmAgBIAfA2AfUA3-WAnCGA2CE3JAHF2HFHAoQAhBIAUAwAlCRAr-BNIDGEAgQC2ACA3CQGBkHGVBUAqAAwAAcRBcAbBN2AB2Z3B5O3LAe2AhAgBAMIBCBRCAbAcMAdY2BG2ATYIYAa2YTLBZJQ2BMBjB-AbAqRAbAxAtBd2BeB2CAAaO2IYAdTIAaL3BABWAtB2-2(AbR)BAwMNUCVBIQAd2IOT2IAdCJBAAkB2NA2-RAbJAnNBfAsA2KBIBEIG2BOTLCAj2A2AkAAaA4-ARBfAs-2K-CIABAdA3BIAdCAj2A2AkAWA4-CAlAs-K2AiTIO-TIHBBlBY2TAiXAFAiAkAnAr4-CAnAlN3KBnTBKF2BCIF2BLApAi2AHNAl6-AbAnNArKAiKBXKOBmF-OKAjOX2Ap3AAcW100-PSP2-C-A-Ay10-B-2B5-3P3S2-CJBEB9-DAeAAmC5-AuPSP2S2-C2GAmBA8-APAZJB4-SAuP5-CEJAvGB8-AKEKVC13-EVGQ9-QGVAmKC13-AAeZA2-3ACD3-AGKZC12-CDJE2A5BADA-BEAgA12-A2B2ADCGC3GAzDAECAJA11-ABRAE2A2G3D2BD2ACAGA2E8-AAcAqArCA2CEBKCKBEC6ACDC6-BWAlMArCAEAFCF2CAHAy2(DA)CDWAxC3A3-WAuML4AOVXCAEAkHAzE3A2DWBaMU2NL-AAcMABAsDAEFAeAjVEApK2FED2ADCAlBaCACAaNLEAtAxAMAnDCAoHFApAvHAiAe2XJD2A2C3MADCAaAsAcBAfAMBgBGHJ2F2HF2X2FD3A2L2MIUDLAcBcAtANBd2BAoFABFAhBhBiH3FGE2BLCLAqBbUA-Aa-BNARBJEFAAj2(JH)FACFQAhAg2BAfALBbILA4-3BAGJD2A3H2AAjDAoFAmAgBIAfA2AfUA3-WAnCGA2CE3JAHF2HFHAoQAhBIAUAwAlCRAr-BNIDGEAgQC2ACA3CQGBkHGVBUAqAAwAAcRBcAbBN2AB2Z3B5O3LAe2AhAgBAMIBCBRCAbAcMAdY2BG2ATYIYAa2YTLBZJQ2BMBjB-AbAqRAbAxAtBd2BeB2CAAaO2IYAdTIAaL3BABWAtB2-2(AbR)BAwMNUCVBIQAd2IOT2IAdC-BAAkB2NA2-RAbJAnNBfAsA2KBIBEIG2BOTLCAj2A2AkAAaA4-ARBfAs-2K-CIABAdA3BIAdCAj2A2AkAWA4-CAlAs-K2-TIO-TIHBBlBY2TAiXAF2AkAnAr4-CAnAlN3KBnTBKF2BCIF2BLApAi2AHNAl6-AbAnNAnKAiKBXKBoBmF-OKAjOX2Ap3AAcW7-ENUAr-2Ai2K4-3KAp2AiApK3A69-PSP2-C-A-Ay10-B-2B5-3P3S2-CJBEB9-DAeAAmC5-AuPSP2S2-C2GAmBA8-APAZJB4-SAuP5-CEJAvGB9-KEKVC13-EVGQA9-GVAmKC13-AAeZA2-3ACD3-AGKZC12-CDJE2A5BADA-BEAgA12-A2B2ADCGC3GAzDAECAJA11-ABRAE2A2G3D2BD2ACAGA2E8-AAcAqArCA2CEBKCKBEC6ACDC6-BWAlMArCAEAFCF2CAHAy2(DA)CDWAxC3A3-WAuML4AOVXCAEAkHAzE3A2DWBaMU2NL-AAcMABAsDAEFAeAjVEApK2FED2ADCAlBaCACAaNLEAtAxAMAnDCAoHFApAvHAiAe2XJD2A2C3MADCAaAsAcBAfAMBgBGHJ2F2HF2X2FD3A2L2MIUDLAcBcAtANBd2BAoFABFAhBhBiH3FGE2BLCLAqBbUA-Aa-BNARBJEFAAj2(JH)FACFQAhAg2BAfALBbILA4-3BAGJD2A3H2AAjDAoFAmAgBIAfA2AfUA3-WAnCGA2CE3JAHF2HFHAoQAhBIAUAwAlCRAr-BNIDGEAgQC2ACA3CQGBkHGVBUAqAAwAAcRBcAbBN2AB2Z3B5O3LAe2AhAgBAMIBCBRCAbAcMAdY2BG2ATYIYAa2YTLBZJQ2BMBjB-AbAqRAbAxAtBd2BeB2CAAaO2IYAdTIAaL3BABWAtB2-2(AbR)BAwMNUCVBIQAd2IOT2IAdC-BAAkB2NA2-RAbJAnNBfAsA2KBIBEIG2BOTLCAj2A2AkAAaA4-ARBfAs-2K-CIABAdA3BIAdCAj2A2AkAWA4-CAlAs-K2-TIO-TIHBBlBY2TAiXAF2AkAnAr4-CAnAlN3KBnTBKF2BCIF2BLApAi2A-NAl6-AbAnNAnKAiKBXKBoBmF-OKAjOX2Ap3AAcW7-2E2UAi4K4-3KAp2AiApK3A2-CJ5-AbN3-2K6-2KXAi2ApK-3ADH34-PSP2-C-A-Ay10-B-2B5-3P3S2-CJBEJ9-DAeAAmC5-AuPSP2S2-CVAeEJA8-APAZJB4-SAuP5-CEJAvAeB9-KEKVC13-EVGQA9-GVAmKC13-AAeZA2-3ACD3-AGKZC12-CDJE2A5BADA-BEAgA12-A2B2ADCGC3GAzDAECAJA11-ABRAE2A2G3D2BD2ACAGA2E8-AAcAqArCA2CEBKCKBEC6ACDC6-BWAlMArCAEAFCF2CAHAy2(DA)CDWAxC3A3-WAuML4AOVXCAEAkHAzE3A2DWBaMU2NL-AAcMABAsDAEFAeAjVEApK2FED2ADCAlBaCACAaNLEAtAxAMAnDCAoHFApAvHAiAe2XJD2A2C3MADCAaAsAcBAfAMBgBGHJ2F2HF2X2FD3A2L2MIUDLAcBcAtANBd2BAoFABFAhBhBiH3FGE2BLCLAqBbUA-Aa-BNARBJEFAAj2(JH)FACFQAhAg2BAfALBbILA4-3BAGJD2A3H2AAjDAoFAmAgBIAfA2AfUA3-WAnCGA2CE3JAHF2HFHAoQAhBIAUAwAlCRAr-BNIDJEAgQC2ACA3CQGBkHGVBUAqAAwAAcRBcAbBN2AB2Z3B5O3LAe2AhAgBAMIBCBRCAbAcMAdY2BG2ATYIYAa2YTLBZJQ2BMBjB-AbAqRAbAxAtBd2BeB2CAAaO2IYAdTIAaL3BABWAtB2-2(AbR)BAwMNUCVBIQAd2IOT2IAdCJBAAkB2NA2-RAbJAnNBfAsA2KBIBEIG2BOTLCAj2A2AkAAaA4-ARBfAs-2K-CIABAdA3BIAdCAj2A2AkAWA4-CAlAs-K2-TIO-TIHBBlBY2TAiXAF2AkAnAr4-CAnAlN3KBnTBKF2BCIF2BLApAi2A-NAl6-AbAnNAnK-KBXKBoBmF-OKAjOX2Ap3AAcW7-2E2U-4K4-3KAp2AiApK3A2-CJ5-3Ab2-2K6-2KXAv2ApK-3ADH7-Ab13-KAi2K3-AHJ3-
