model
size = 19 20 32, scale = 0.05, origin = -y
material 
  colors = A:#F0F B:#66F C:#F06 D:#F93 E:#FF0 F:#3FF G:#6F6
voxels
235-F17-G17-E17-D17-C17-A17-B234-BA16-FB16-GFB15-EGF15-DEG15-CDE15-ACD15-BAC16-BA16-FB197-A16-FBA15-GFBA14-EGFB14-DEGF14-CDEG14-ACDE15-ACD15-BAC15-FBA16-FB196-BAC15-FBA15-GFBA14-EGFB14-DEGF14-CDEG14-ACDE14-BAC16-2(BA16-F)B124-EG16-DE16-CD16-AC16-BAC15-FBA15-GFB15-EGFB14-DEG15-CDE15-ACD15-BAC15-FBA16-FB124-EGF15-DEGF14-CDEG14-ACDE14-BACD14-FBAC14-GFBA14-EGFB14-DEGF14-CDEG14-ACDE14-BACD15-BA16-FBA124-GF16-EGF15-DEGF14-CDEG14-ACDE14-BACD14-FBAC14-GFBA14-EGFB14-DEGF14-CDE15-ACD15-BAC15-FBA16-FBA72-D15-BAC14-G2(FBA15-GFB15-EGF15-DEG15-CDE15-ACD15-BAC15-)FBA17-B89-BAC14-GFBA14-EGFB14-DEGF14-CDEG14-ACDE14-BACD14-FBAC14-GFBA14-EGFB14-DEGF14-CDEG14-ACDE15-ACD15-BA16-FBA124-GFB15-EGFB14-DEGF14-CDE15-ACDE14-BAC15-FBAC14-GFB15-EGF15-DEG15-CDE15-ACD15-BAC16-BA17-B125-G17-EG16-DEG15-CDE15-ACD15-BAC15-FBA15-GFB15-EGF15-DEG15-CDE15-ACD15-BAC16-BA160-DEG15-CDEG14-ACDE14-BACD14-FBAC14-GFBA15-GFB14-DEGF14-CDEG15-CD16-AC16-BA179-DE16-CDE15-ACD15-BAC15-FBA15-GFB15-EGF15-DEG15-CDE15-ACD16-AC17-A197-CD16-ACD15-BAC15-FBA15-GFB15-EGF15-DEG15-CDE15-ACD16-AC233-AC16-BAC15-FBA15-GF16-EG16-DE16-CDE15-A2(C269-FBA15-GFB15-EGF15-DEG15-CDE16-CD17-)C252-AC16-BAC15-FBA15-GF16-EG16-DE16-CDE15-AC234-CD16-ACD15-BAC15-FBA15-GFB15-EGF15-DEG15-CDE15-ACD16-AC197-DE16-CDE15-ACD15-BAC15-FBA15-GFB15-EGF15-DEG15-CDE15-ACD16-AC17-A179-DEG15-CDEG14-ACDE14-BACD14-FBAC14-GFBA15-GFB14-DEGF14-CDEG15-CD16-AC16-BA162-G17-EGF15-DEGF14-CDE15-ACD15-BAC15-FBA15-GFB15-EGF15-DEG15-CDE15-ACD15-BAC16-BA143-GFB15-EGFB14-DEGF14-CDE15-ACDE14-BAC15-FBAC14-GFB15-EGF15-DEG15-CDE15-ACD15-BAC16-BA17-B108-BAC14-GFBA14-EGFB14-DEGF14-CDEG14-ACDE14-BACD14-FBAC14-GFBA14-EGFB14-DEGF14-CDEG14-ACDE15-ACD15-BA16-FBA91-D15-BAC14-G2(FBA15-GFB15-EGF15-DEG15-CDE15-ACD15-BAC15-)FBA17-B125-GF16-EGF15-DEGF14-CDEG14-ACDE14-BACD14-FBAC14-GFBA14-EGFB14-DEGF14-CDE15-ACD15-BAC15-FBA16-FBA142-EGF15-DEGF14-CDEG14-ACDE14-BACD14-FBAC14-GFBA14-EGFB14-DEGF14-CDEG14-ACDE14-BACD15-BA16-FBA161-EG16-DE16-CD16-AC16-BAC15-FBA15-GFB15-EGFB14-DEG15-CDE15-ACD15-BAC15-FBA16-FB215-BAC15-FBA15-GFBA14-EGFB14-DEGF14-CDEG14-ACDE14-BAC16-2(BA16-F)B197-A16-FBA15-GFBA14-EGFB14-DEGF14-CDEG14-ACDE15-ACD15-BAC15-FBA16-FB215-BA16-FB16-GFB15-EGF15-DEG15-CDE15-ACD15-BAC16-BA16-FB252-F17-G17-E17-D17-C17-A17-B36-
