model
size = 32, scale = 0.05, origin = -y
material 
  colors = A:#111 B:#A00 C:#FF0 D:#EEE
voxels
390-5B3-4A3-5B11-B5-B-6A-B5-B9-4(B7-B6AB7-B8-)B7-B6AB7-B9-B5-B2-4A2-B5-B11-5B10-5B499-6C25-C6-C23-2(C8-C22-)10C25-4A26-8A23-10A17-5B10A5B11-B5CB8AB5CB9-4(BC5-CB6ABC5-CB8-)BC5-CB6ABC5-CB9-B5CB8AB5CB11-5B10A5B18-8A26-4A443-6C25-C6DC23-C8-C22-C8DC22-C8AC21-12A19-14A18-14A15-6B8A6B11-B5-B8AB5-B9-4(B7-B6AB7-B8-)B7-B6AB7-B9-B5-B8AB5-B11-5B10A5B15-14A19-12A22-8A27-2A380-6C25-C6DC23-C-6A-C22-2C6A2C20-14A17-16A16-16A15-2A2B10A2B2A13-6B8A6B11-B5-B8AB5-B9-4(B7-B6AB7-B8-)B7-B6AB7-B9-B5-B8AB5-B11-5B10A5B14-16A16-16A17-14A20-10A24-6A346-6C25-C6AC22-AC8ACA19-14A17-16A15-18A13-20A12-A4B10A4BA11-A6B8A6BA10-B5-B8AB5-B9-4(B7-B6AB7-B8-)B7-B6AB7-B9-B5-B8AB5-B11-5B10A5B12-20A13-18A15-16A17-14A19-12A22-8A312-A6CA22-12A19-14A16-18A14-18A13-20A11-22A10-A5B10A5BA9-A7B8A7BA8-AB5-B8AB5-BA5(8-B7-B6AB7-B)8-AB5-B8AB5-BA9-A5B10A5BA10-22A11-20A13-18A14-18A16-14A19-12A22-8A249-6A23-12A19-14A16-18A13-20A12-20A11-22A9-24A8-2A5B10A5B2A8-A7B8A7BA7-2AB5-B8AB5-B2A5(6-AB7-B6AB7-BA)7-AB5-B8AB5-BA8-2A5B10A5B2A8-24A9-22A11-20A12-20A13-18A16-14A19-12A23-6A188-2A26-10A20-14A16-18A13-20A11-22A10-22A9-24A8-24A7-3A5B10A5B3A6-2A7B8A7B2A6-2AB5-B8AB5-B2A6-AB7-B6AB7-BA5-2AB7-B6AB7-B2A4-2AB7-B6AB7-B2A5-2(AB7-B6AB7-BA6-)2AB5-B8AB5-B2A6-3A5B10A5B3A7-24A8-24A9-22A10-22A11-20A13-18A16-14A20-10A26-2A155-8A21-14A17-16A15-18A13-20A11-22A9-24A7-2(26A6-)3A5B10A5B3A5-3A7B8A7B3A4-3AB5-B8AB5-B3A5(4-2AB7-B6AB7-B2A)4-3AB5-B8AB5-B3A5-3A5B10A5B3A2(6-26A)7-24A9-22A11-20A13-18A15-16A17-14A21-8A122-4A24-12A18-16A15-18A13-20A11-22A9-24A7-26A6-26A5-28A4-4A5B10A5B4A4-3A7B8A7B3A4-3AB5-B8AB5-B3A3-3(3AB7-B6AB7-B3A2-)3AB7-B6AB7-B3A3-2AB7-B6AB7-B2A4-3AB5-B8AB5-B3A4-4A5B10A5B4A4-28A5-26A6-26A7-24A9-22A11-20A13-18A15-16A18-12A24-4A90-8A21-14A17-16A14-20A11-22A9-24A8-24A7-26A5-2(28A4-)4A5B10A5B4A3-4A7B8A7B4A2-4AB5-B8AB5-B4A5(2-3AB7-B6AB7-B3A)2-4AB5-B8AB5-B4A3-4A5B10A5B4A2(4-28A)5-26A7-24A8-24A9-22A11-20A14-16A17-14A21-8A87-10A20-14A16-18A13-20A11-22A9-24A7-26A6-26A5-28A4-28A3-5A5B10A5B5A2-4A7B8A7B4A2-4AB5-B8AB5-B4A5(2-3AB7-B6AB7-B3A)2-4AB5-B8AB5-B4A2-5A5B10A5B5A3-28A4-28A5-26A6-26A7-24A9-22A11-20A13-18A16-14A20-10A57-4A24-12A18-16A15-18A12-22A9-24A8-24A7-26A5-28A4-28A3-30A2-5A5B10A5B5A2-4A7B8A7B4A2-4AB5-B8AB5-B4A-4A3(B7-B6AB7-B8A)B7-B6AB7-B4A-3AB7-B6AB7-B3A2-4AB5-B8AB5-B4A2-5A5B10A5B5A2-30A3-28A4-28A5-26A7-24A8-24A9-22A12-18A15-16A18-12A24-4A27-6A23-12A18-16A14-20A11-22A9-24A7-26A6-26A5-28A4-28A3-30A2-5A5B10A5B5A2-4A7B8A7B4A-5AB5-B8AB5-B9A4(B7-B6AB7-B8A)B7-B6AB7-B4A-4AB5-B8AB5-B4A2-5A5B10A5B5A2-30A3-28A4-28A5-26A6-26A7-24A9-22A11-20A14-16A18-12A23-6A25-8A21-14A17-16A14-20A11-22A9-24A7-26A6-26A5-28A3-2(30A2-)5A5B10A5B5A-5A2(6B10A)B5-B8AB5-B9A4(B7-B6AB7-B8A)B7-B6AB7-B9AB5-B8AB5-B5A-5A5B10A5B5A2(2-30A)3-28A5-26A6-26A7-24A9-22A11-20A14-16A17-2(14A21-8A24-8A21-14A16-18A13-20A11-22A9-24A7-26A5-28A4-28A3-2(30A2-)5A5B10A5B5A-5A2(6B10A)B5-B8AB5-B9A4(B7-B6AB7-B8A)B7-B6AB7-B9AB5-B8AB5-B5A-5A5B10A5B5A2(2-30A)3-28A4-28A5-26A7-24A9-22A11-20A13-18A16-)14A21-8A24-8A21-14A17-16A14-20A11-22A9-24A7-26A6-26A5-28A3-2(30A2-)5A5B10A5B5A-5A2(6B10A)B5-B8AB5-B9AB7-B6AB7-B8AB3-C3-B6AB3-C3-B8AB2-3C2-B6AB2-3C2-B8AB3-C3-B6AB3-C3-B8AB7-B6AB7-B9AB5-B8AB5-B5A-5A5B10A5B5A2(2-30A)3-28A5-26A6-26A7-24A9-22A11-20A14-16A17-14A21-8A25-6A23-12A18-16A14-20A11-22A9-24A7-26A6-26A5-28A4-28A3-30A2-5A5B10A5B5A2-4A6B10A6B4A-5AB5-B8AB5-B9AB7-B6AB7-B8AB3-C3-B6AB3-C3-B8AB2-3C2-B6AB2-3C2-B8AB3-C3-B6AB3-C3-B8AB7-B6AB7-B4A-4AB5-B8AB5-B4A2-5A5B10A5B5A2-30A3-28A4-28A5-26A6-26A7-24A9-22A11-20A14-16A18-12A23-6A27-4A24-12A18-16A15-18A12-22A9-24A8-24A7-26A5-28A4-28A3-30A2-5A5B10A5B5A2-4A6B10A6B4A2-4A7B8A7B4A-4A2B5-2B6A2B5-2B8A2B2-C2-2B6A2B2-C2-2B8A2B-3C-2B6A2B-3C-2B8A2B2-C2-2B6A2B2-C2-2B4A-3A2B5-2B6A2B5-2B3A2-4A7B8A7B4A2-5A5B10A5B5A2-30A3-28A4-28A5-26A7-24A8-24A9-22A12-18A15-16A18-12A24-4A57-10A20-14A16-18A13-20A11-22A9-24A7-26A6-26A5-28A4-28A3-5A5B10A5B5A2-4A6B10A6B4A2-4A7B8A7B4A5(2-3A9B6A9B3A)2-4A7B8A7B4A2-5A5B10A5B5A3-28A4-28A5-26A6-26A7-24A9-22A11-20A13-18A16-14A20-10A87-8A21-14A17-16A14-20A11-22A9-24A8-24A7-26A5-2(28A4-)28A3-2(5A5B10A5B5A2-)5(4A7B8A7B4A2-)5A5B10A5B5A3-2(28A4-)28A5-26A7-24A8-24A9-22A11-20A14-16A17-14A21-8A90-4A24-12A18-16A15-18A13-20A11-22A9-24A7-26A6-26A5-3(28A4-)28A3-3(30A2-)30A3-3(28A4-)28A5-26A6-26A7-24A9-22A11-20A13-18A15-16A18-12A24-4A122-8A21-14A17-16A15-18A13-20A11-22A9-24A7-2(26A6-)26A5-7(28A4-)28A5-2(26A6-)26A7-24A9-22A11-20A13-18A15-16A17-14A21-8A155-2A26-10A20-14A16-18A13-20A11-22A10-22A9-24A8-24A7-3(26A6-)26A5-28A4-28A5-3(26A6-)26A7-24A8-24A9-22A10-22A11-20A13-18A16-14A20-10A26-2A188-6A23-12A19-14A16-18A13-20A12-20A11-22A9-2(24A8-)24A7-5(26A6-)26A7-2(24A8-)24A9-22A11-20A12-20A13-18A16-14A19-12A23-6A249-8A22-12A19-14A16-18A14-18A13-20A11-22A10-22A9-7(24A8-)24A9-22A10-22A11-20A13-18A14-18A16-14A19-12A22-8A312-8A22-12A19-14A17-16A15-18A13-20A12-20A11-7(22A10-)22A11-20A12-20A13-18A15-16A17-14A19-12A22-8A377-6A24-10A20-14A17-16A16-16A15-18A14-18A13-5(20A12-)20A13-18A14-18A15-16A16-16A17-14A20-10A24-6A444-2A27-8A22-12A19-14A18-14A17-2(16A16-)16A15-18A14-18A15-2(16A16-)16A17-14A18-14A19-12A22-8A27-2A541-4A26-8A23-10A21-12A20-12A19-3(14A18-)14A19-12A20-12A21-10A23-8A26-4A700-4A27-6A25-3(8A24-)8A25-6A27-4A398-
