model
size = 31, scale = 0.05, origin = -y
material 
  colors = A:#EEE B:#001 C:#111 D:#B00
voxels
------------------------------- ------------------------------- ------------------------------- ------------------------------- ------------------------------- ------------------------------- ------------------------------- ------------------------------- ------------------------------- ------------------------------- ------------------------------- ------------------------------- -------------BBCBB------------- ------------BDDCDDB------------ ------------ABDCDBA------------ ------------AABABAA------------ ------------AAACAAA------------ ------------AAACAAA------------ -------------AACAA------------- ------------------------------- ------------------------------- ------------------------------- ------------------------------- ------------------------------- ------------------------------- ------------------------------- ------------------------------- ------------------------------- ------------------------------- ------------------------------- ------------------------------- 
------------------------------- ------------------------------- ------------------------------- ------------------------------- ------------------------------- ------------------------------- ------------------------------- ------------------------------- ------------------------------- -------------AACAA------------- -----------AAAACAAAA----------- ----------AAAAACAAAAA---------- ----------AAAAAAAAAAA---------- ---------BAAAAAAAAAAAB--------- ---------BAAAAAAAAAAAB--------- ---------BAAAAAAAAAAAB--------- ---------ABAAAAAAAAABA--------- ---------DABAAAAAAABAD--------- ----------DABAAAAABAD---------- ----------BBBBBCBBBBB---------- -----------AAAACAAAA----------- -------------AACAA------------- ------------------------------- ------------------------------- ------------------------------- ------------------------------- ------------------------------- ------------------------------- ------------------------------- ------------------------------- ------------------------------- 
------------------------------- ------------------------------- ------------------------------- ------------------------------- ------------------------------- ------------------------------- ------------------------------- -------------DDCDD------------- -----------BBBBBBBBB----------- ----------AAAAAAAAAAA---------- ---------BAAAAAAAAAAAB--------- --------ABAAAAAAAAAAABA-------- --------ABAAAAAAAAAAABA-------- -------AAAAAAAAAAAAAAAAA------- -------AAAAAAAAAAAAAAAAA------- -------AAAAAAAAAAAAAAAAA------- -------ABAAAAAAAAAAAAABA------- -------BAAAAAAAAAAAAAAAB------- --------DDAAAAAAAAAAADD-------- --------BBAAAAAAAAAAABB-------- ---------BAAAAAAAAAAAB--------- ----------AAAAAAAAAAA---------- -----------AAAACAAAA----------- -------------AACAA------------- ------------------------------- ------------------------------- ------------------------------- ------------------------------- ------------------------------- ------------------------------- ------------------------------- 
------------------------------- ------------------------------- ------------------------------- ------------------------------- ------------------------------- ------------------------------- ------------DDDCDDD------------ ----------BDDAAAAADDB---------- ---------BBAAAAAAAAABB--------- --------ABAAAAAAAAAAABA-------- -------AAAAAAAAAAAAAAAAA------- -------AAAAAAAAAAAAAAAAA------- ------AAAAAAAAAAAAAAAAAAA------ ------AAAAAAAAAAAAAAAAAAA------ ------AAAAAAAAAAAAAAAAAAA------ ------AAAAAAAAAAAAAAAAAAA------ ------AAAAAAAAAAAAAAAAAAA------ ------AAAAAAAAAAAAAAAAAAA------ ------BAAAAAAAAAAAAAAAAAB------ -------BAAAAAAAAAAAAAAAB------- -------AAAAAAAAAAAAAAAAA------- --------ABAAAAAAAAAAABA-------- ---------BAAAAAAAAAAAB--------- ----------AAAAAAAAAAA---------- ------------AAACAAA------------ ------------------------------- ------------------------------- ------------------------------- ------------------------------- ------------------------------- ------------------------------- 
------------------------------- ------------------------------- ------------------------------- ------------------------------- ------------------------------- -----------ABBBBBBBA----------- ---------BABAAAAAAABAB--------- --------ABAAAAAAAAAAABA-------- -------AAAAAAAAAAAAAAAAA------- ------AAAAAAAAAAAAAAAAAAA------ ------AAAAAAAAAAAAAAAAAAA------ -----AAAAAAAAAAAAAAAAAAAAA----- -----AAAAAAAAAAAAAAAAAAAAA----- -----AAAAAAAAAAAAAAAAAAAAA----- -----AAAAAAAAAAAAAAAAAAAAA----- -----AAAAAAAAAAAAAAAAAAAAA----- -----AAAAAAAAAAAAAAAAAAAAA----- -----AAAAAAAAAAAAAAAAAAAAA----- -----AAAAAAAAAAAAAAAAAAAAA----- -----BAAAAAAAAAAAAAAAAAAAB----- ------AAAAAAAAAAAAAAAAAAA------ ------AAAAAAAAAAAAAAAAAAA------ -------AAAAAAAAAAAAAAAAA------- --------ABAAAAAAAAAAABA-------- ---------BAAAAAAAAAAAB--------- -----------AAAACAAAA----------- ------------------------------- ------------------------------- ------------------------------- ------------------------------- ------------------------------- 
------------------------------- ------------------------------- ------------------------------- ------------------------------- -----------AAAACAAAA----------- ---------BAAAAAAAAAAAB--------- --------AAAAAAAAAAAAAAA-------- -------AAAAAAAAAAAAAAAAA------- ------AAAAAAAAAAAAAAAAAAA------ -----AAAAAAAAAAAAAAAAAAAAA----- -----AAAAAAAAAAAAAAAAAAAAA----- ----AAAAAAAAAAAAAAAAAAAAAAA---- ----AAAAAAAAAAAAAAAAAAAAAAA---- ----AAAAAAAAAAAAAAAAAAAAAAA---- ----AAAAAAAAAAAAAAAAAAAAAAA---- ----AAAAAAAAAAAAAAAAAAAAAAA---- ----AAAAAAAAAAAAAAAAAAAAAAA---- ----AAAAAAAAAAAAAAAAAAAAAAA---- ----AAAAAAAAAAAAAAAAAAAAAAA---- ----BAAAAAAAAAAAAAAAAAAAAAB---- -----AAAAAAAAAAAAAAAAAAAAA----- -----AAAAAAAAAAAAAAAAAAAAA----- ------AAAAAAAAAAAAAAAAAAA------ -------AAAAAAAAAAAAAAAAA------- --------AAAAAAAAAAAAAAA-------- ---------BAAAAAAAAAAAB--------- -----------AAAACAAAA----------- ------------------------------- ------------------------------- ------------------------------- ------------------------------- 
------------------------------- ------------------------------- ------------------------------- ------------AAACAAA------------ ---------BAAAAAAAAAAAB--------- --------AAAAAAAAAAAAAAA-------- -------AAAAAAAAAAAAAAAAA------- ------AAAAAAAAAAAAAAAAAAA------ -----AAAAAAAAAAAAAAAAAAAAA----- ----AAAAAAAAAAAAAAAAAAAAAAA---- ----AAAAAAAAAAAAAAAAAAAAAAA---- ----AAAAAAAAAAAAAAAAAAAAAAA---- ---AAAAAAAAAAAAAAAAAAAAAAAAA--- ---AAAAAAAAAAAAAAAAAAAAAAAAA--- ---AAAAAAAAAAAAAAAAAAAAAAAAA--- ---AAAAAAAAAAAAAAAAAAAAAAAAA--- ---AAAAAAAAAAAAAAAAAAAAAAAAA--- ---AAAAAAAAAAAAAAAAAAAAAAAAA--- ---AAAAAAAAAAAAAAAAAAAAAAAAA--- ----BAAAAAAAAAAAAAAAAAAAAAB---- ----AAAAAAAAAAAAAAAAAAAAAAA---- ----AAAAAAAAAAAAAAAAAAAAAAA---- -----AAAAAAAAAAAAAAAAAAAAA----- ------AAAAAAAAAAAAAAAAAAA------ -------AAAAAAAAAAAAAAAAA------- --------AAAAAAAAAAAAAAA-------- ---------BAAAAAAAAAAAB--------- ------------AAACAAA------------ ------------------------------- ------------------------------- ------------------------------- 
------------------------------- ------------------------------- -------------AACAA------------- ----------AAAAAAAAAAA---------- --------ABAAAAAAAAAAABA-------- -------AAAAAAAAAAAAAAAAA------- ------AAAAAAAAAAAAAAAAAAA------ -----AAAAAAAAAAAAAAAAAAAAA----- ----AAAAAAAAAAAAAAAAAAAAAAA---- ----AAAAAAAAAAAAAAAAAAAAAAA---- ---AAAAAAAAAAAAAAAAAAAAAAAAA--- ---AAAAAAAAAAAAAAAAAAAAAAAAA--- ---AAAAAAAAAAAAAAAAAAAAAAAAA--- --AAAAAAAAAAAAAAAAAAAAAAAAAAA-- --AAAAAAAAAAAAAAAAAAAAAAAAAAA-- --AAAAAAAAAAAAAAAAAAAAAAAAAAA-- --AAAAAAAAAAAAAAAAAAAAAAAAAAA-- --AAAAAAAAAAAAAAAAAAAAAAAAAAA-- ---AAAAAAAAAAAAAAAAAAAAAAAAA--- ---BAAAAAAAAAAAAAAAAAAAAAAAB--- ---AAAAAAAAAAAAAAAAAAAAAAAAA--- ----AAAAAAAAAAAAAAAAAAAAAAA---- ----AAAAAAAAAAAAAAAAAAAAAAA---- -----AAAAAAAAAAAAAAAAAAAAA----- ------AAAAAAAAAAAAAAAAAAA------ -------AAAAAAAAAAAAAAAAA------- --------ABAAAAAAAAAAABA-------- ----------AAAAAAAAAAA---------- -------------AACAA------------- ------------------------------- ------------------------------- 
------------------------------- ------------------------------- -----------AAAACAAAA----------- ---------BAAAAAAAAAAAB--------- -------AAAAAAAAAAAAAAAAA------- ------AAAAAAAAAAAAAAAAAAA------ -----AAAAAAAAAAAAAAAAAAAAA----- ----AAAAAAAAAAAAAAAAAAAAAAA---- ----AAAAAAAAAAAAAAAAAAAAAAA---- ---AAAAAAAAAAAAAAAAAAAAAAAAA--- ---AAAAAAAAAAAAAAAAAAAAAAAAA--- --AAAAAAAAAAAAAAAAAAAAAAAAAAA-- --AAAAAAAAAAAAAAAAAAAAAAAAAAA-- --AAAAAAAAAAAAAAAAAAAAAAAAAAA-- --AAAAAAAAAAAAAAAAAAAAAAAAAAA-- --AAAAAAAAAAAAAAAAAAAAAAAAAAA-- --AAAAAAAAAAAAAAAAAAAAAAAAAAA-- --AAAAAAAAAAAAAAAAAAAAAAAAAAA-- --AAAAAAAAAAAAAAAAAAAAAAAAAAA-- --BAAAAAAAAAAAAAAAAAAAAAAAAAB-- ---AAAAAAAAAAAAAAAAAAAAAAAAA--- ---AAAAAAAAAAAAAAAAAAAAAAAAA--- ----AAAAAAAAAAAAAAAAAAAAAAA---- ----AAAAAAAAAAAAAAAAAAAAAAA---- -----AAAAAAAAAAAAAAAAAAAAA----- ------AAAAAAAAAAAAAAAAAAA------ -------AAAAAAAAAAAAAAAAA------- ---------BAAAAAAAAAAAB--------- -----------AAAACAAAA----------- ------------------------------- ------------------------------- 
------------------------------- -------------AACAA------------- ----------AAAAAAAAAAA---------- --------ABAAAAAAAAAAABA-------- ------AAAAAAAAAAAAAAAAAAA------ -----AAAAAAAAAAAAAAAAAAAAA----- ----AAAAAAAAAAAAAAAAAAAAAAA---- ----AAAAAAAAAAAAAAAAAAAAAAA---- ---AAAAAAAAAAAAAAAAAAAAAAAAA--- ---AAAAAAAAAAAAAAAAAAAAAAAAA--- --AAAAAAAAAAAAAAAAAAAAAAAAAAA-- --AAAAAAAAAAAAAAAAAAAAAAAAAAA-- --AAAAAAAAAAAAAAAAAAAAAAAAAAA-- -AAAAAAAAAAAAAAAAAAAAAAAAAAAAA- -AAAAAAAAAAAAAAAAAAAAAAAAAAAAA- -AAAAAAAAAAAAAAAAAAAAAAAAAAAAA- -AAAAAAAAAAAAAAAAAAAAAAAAAAAAA- -AAAAAAAAAAAAAAAAAAAAAAAAAAAAA- --AAAAAAAAAAAAAAAAAAAAAAAAAAA-- --BAAAAAAAAAAAAAAAAAAAAAAAAAB-- --AAAAAAAAAAAAAAAAAAAAAAAAAAA-- ---AAAAAAAAAAAAAAAAAAAAAAAAA--- ---AAAAAAAAAAAAAAAAAAAAAAAAA--- ----AAAAAAAAAAAAAAAAAAAAAAA---- ----AAAAAAAAAAAAAAAAAAAAAAA---- -----AAAAAAAAAAAAAAAAAAAAA----- ------AAAAAAAAAAAAAAAAAAA------ --------ABAAAAAAAAAAABA-------- ----------AAAAAAAAAAA---------- -------------AACAA------------- ------------------------------- 
------------------------------- -----------AAAACAAAA----------- ---------BAAAAAAAAAAAB--------- -------AAAAAAAAAAAAAAAAA------- ------AAAAAAAAAAAAAAAAAAA------ -----AAAAAAAAAAAAAAAAAAAAA----- ----AAAAAAAAAAAAAAAAAAAAAAA---- ---AAAAAAAAAAAAAAAAAAAAAAAAA--- ---AAAAAAAAAAAAAAAAAAAAAAAAA--- --AAAAAAAAAAAAAAAAAAAAAAAAAAA-- --AAAAAAAAAAAAAAAAAAAAAAAAAAA-- -AAAAAAAAAAAAAAAAAAAAAAAAAAAAA- -AAAAAAAAAAAAAAAAAAAAAAAAAAAAA- -AAAAAAAAAAAAAAAAAAAAAAAAAAAAA- -AAAAAAAAAAAAAAAAAAAAAAAAAAAAA- -AAAAAAAAAAAAAAAAAAAAAAAAAAAAA- -AAAAAAAAAAAAAAAAAAAAAAAAAAAAA- -AAAAAAAAAAAAAAAAAAAAAAAAAAAAA- -AAAAAAAAAAAAAAAAAAAAAAAAAAAAA- -BAAAAAAAAAAAAAAAAAAAAAAAAAAAB- --AAAAAAAAAAAAAAAAAAAAAAAAAAA-- --AAAAAAAAAAAAAAAAAAAAAAAAAAA-- ---AAAAAAAAAAAAAAAAAAAAAAAAA--- ---AAAAAAAAAAAAAAAAAAAAAAAAA--- ----AAAAAAAAAAAAAAAAAAAAAAA---- -----AAAAAAAAAAAAAAAAAAAAA----- ------AAAAAAAAAAAAAAAAAAA------ -------AAAAAAAAAAAAAAAAA------- ---------BAAAAAAAAAAAB--------- -----------AAAACAAAA----------- ------------------------------- 
------------------------------- ----------AAAAACAAAAA---------- --------ABAAAAAAAAAAABA-------- -------AAAAAAAAAAAAAAAAA------- -----AAAAAAAAAAAAAAAAAAAAA----- ----AAAAAAAAAAAAAAAAAAAAAAA---- ----AAAAAAAAAAAAAAAAAAAAAAA---- ---AAAAAAAAAAAAAAAAAAAAAAAAA--- --AAAAAAAAAAAAAAAAAAAAAAAAAAA-- --AAAAAAAAAAAAAAAAAAAAAAAAAAA-- -AAAAAAAAAAAAAAAAAAAAAAAAAAAAA- -AAAAAAAAAAAAAAAAAAAAAAAAAAAAA- -AAAAAAAAAAAAAAAAAAAAAAAAAAAAA- -AAAAAAAAAAAAAAAAAAAAAAAAAAAAA- -AAAAAAAAAAAAAAAAAAAAAAAAAAAAA- -AAAAAAAAAAAAAAAAAAAAAAAAAAAAA- -AAAAAAAAAAAAAAAAAAAAAAAAAAAAA- -AAAAAAAAAAAAAAAAAAAAAAAAAAAAA- -AAAAAAAAAAAAAAAAAAAAAAAAAAAAA- -BAAAAAAAAAAAAAAAAAAAAAAAAAAAB- -AAAAAAAAAAAAAAAAAAAAAAAAAAAAA- --AAAAAAAAAAAAAAAAAAAAAAAAAAA-- --AAAAAAAAAAAAAAAAAAAAAAAAAAA-- ---AAAAAAAAAAAAAAAAAAAAAAAAA--- ----AAAAAAAAAAAAAAAAAAAAAAA---- ----AAAAAAAAAAAAAAAAAAAAAAA---- -----AAAAAAAAAAAAAAAAAAAAA----- -------AAAAAAAAAAAAAAAAA------- --------ABAAAAAAAAAAABA-------- ----------AAAAACAAAAA---------- ------------------------------- 
-------------AACAA------------- ----------AAAAAAAAAAA---------- --------ABAAAAAAAAAAABA-------- ------AAAAAAAAAAAAAAAAAAA------ -----AAAAAAAAAAAAAAAAAAAAA----- ----AAAAAAAAAAAAAAAAAAAAAAA---- ---AAAAAAAAAAAAAAAAAAAAAAAAA--- ---AAAAAAAAAAAAAAAAAAAAAAAAA--- --AAAAAAAAAAAAAAAAAAAAAAAAAAA-- --AAAAAAAAAAAAAAAAAAAAAAAAAAA-- -AAAAAAAAAAAAAAAAAAAAAAAAAAAAA- -AAAAAAAAAAAAAAAAAAAAAAAAAAAAA- -AAAAAAAAAAAAAAAAAAAAAAAAAAAAA- AAAAAAAAAAAAAAAAAAAAAAAAAAAAAAA AAAAAAAAAAAAAAAAAAAAAAAAAAAAAAA AAAAAAAAAAAAAAAAAAAAAAAAAAAAAAA AAAAAAAAAAAAAAAAAAAAAAAAAAAAAAA AAAAAAAAAAAAAAAAAAAAAAAAAAAAAAA -AAAAAAAAAAAAAAAAAAAAAAAAAAAAA- -BAAAAAAAAAAAAAAAAAAAAAAAAAAAB- -AAAAAAAAAAAAAAAAAAAAAAAAAAAAA- --AAAAAAAAAAAAAAAAAAAAAAAAAAA-- --AAAAAAAAAAAAAAAAAAAAAAAAAAA-- ---AAAAAAAAAAAAAAAAAAAAAAAAA--- ---AAAAAAAAAAAAAAAAAAAAAAAAA--- ----AAAAAAAAAAAAAAAAAAAAAAA---- -----AAAAAAAAAAAAAAAAAAAAA----- ------AAAAAAAAAAAAAAAAAAA------ --------ABAAAAAAAAAAABA-------- ----------AAAAAAAAAAA---------- -------------AACAA------------- 
------------AAACAAA------------ ---------BAAAAAAAAAAAB--------- -------AAAAAAAAAAAAAAAAA------- ------AAAAAAAAAAAAAAAAAAA------ -----AAAAAAAAAAAAAAAAAAAAA----- ----AAAAAAAAAAAAAAAAAAAAAAA---- ---AAAAAAAAAAAAAAAAAAAAAAAAA--- --AAAAAAAAAAAAAAAAAAAAAAAAAAA-- --AAAAAAAAAAAAAAAAAAAAAAAAAAA-- -AAAAAAAAAAAAAAAAAAAAAAAAAAAAA- -AAAAAAAAAAAAAAAAAAAAAAAAAAAAA- -AAAAAAAAAAAAAAAAAAAAAAAAAAAAA- AAAAAAAAAAAAAAAAAAAAAAAAAAAAAAA AAAAAAAAAAAAAAAAAAAAAAAAAAAAAAA AAAAAAAAAAAAAAAAAAAAAAAAAAAAAAA AAAAAAAAAAAAAAAAAAAAAAAAAAAAAAA AAAAAAAAAAAAAAAAAAAAAAAAAAAAAAA AAAAAAAAAAAAAAAAAAAAAAAAAAAAAAA AAAAAAAAAAAAAAAAAAAAAAAAAAAAAAA -BAAAAAAAAAAAAAAAAAAAAAAAAAAAB- -AAAAAAAAAAAAAAAAAAAAAAAAAAAAA- -AAAAAAAAAAAAAAAAAAAAAAAAAAAAA- --AAAAAAAAAAAAAAAAAAAAAAAAAAA-- --AAAAAAAAAAAAAAAAAAAAAAAAAAA-- ---AAAAAAAAAAAAAAAAAAAAAAAAA--- ----AAAAAAAAAAAAAAAAAAAAAAA---- -----AAAAAAAAAAAAAAAAAAAAA----- ------AAAAAAAAAAAAAAAAAAA------ -------AAAAAAAAAAAAAAAAA------- ---------BAAAAAAAAAAAB--------- ------------AAACAAA------------ 
------------AAACAAA------------ ---------BAAAAAAAAAAAB--------- -------AAAAAAAAAAAAAAAAA------- ------AAAAAAAAAAAAAAAAAAA------ -----AAAAAAAAAAAAAAAAAAAAA----- ----AAAAAAAAAAAAAAAAAAAAAAA---- ---AAAAAAAAAAAAAAAAAAAAAAAAA--- --AAAAAAAAAAAAAAAAAAAAAAAAAAA-- --AAAAAAAAAAAAAAAAAAAAAAAAAAA-- -AAAAAAAAAAAAAAAAAAAAAAAAAAAAA- -AAAAAAAAAAAAAAAAAAAAAAAAAAAAA- -AAAAAAAAAAAAAAAAAAAAAAAAAAAAA- AAAAAAAAAAAAAAAAAAAAAAAAAAAAAAA AAAAAAAAAAAAAAAAAAAAAAAAAAAAAAA AAAAAAAAAAAAAAAAAAAAAAAAAAAAAAA AAAAAAAAAAAAAAAAAAAAAAAAAAAAAAA AAAAAAAAAAAAAAAAAAAAAAAAAAAAAAA AAAAAAAAAAAAAAAAAAAAAAAAAAAAAAA AAAAAAAAAAAAAAAAAAAAAAAAAAAAAAA -BAAAAAAAAAAAAAAAAAAAAAAAAAAAB- -AAAAAAAAAAAAAAAAAAAAAAAAAAAAA- -AAAAAAAAAAAAAAAAAAAAAAAAAAAAA- --AAAAAAAAAAAAAAAAAAAAAAAAAAA-- --AAAAAAAAAAAAAAAAAAAAAAAAAAA-- ---AAAAAAAAAAAAAAAAAAAAAAAAA--- ----AAAAAAAAAAAAAAAAAAAAAAA---- -----AAAAAAAAAAAAAAAAAAAAA----- ------AAAAAAAAAAAAAAAAAAA------ -------AAAAAAAAAAAAAAAAA------- ---------BAAAAAAAAAAAB--------- ------------AAACAAA------------ 
------------CCCCCCC------------ ---------CCCAAAAAAACCC--------- -------CCAAAAAAAAAAAAACC------- ------CAAAAAAAAAAAAAAAAAC------ -----CAAAAAAAAAAAAAAAAAAAC----- ----CAAAAAAAAAAAAAAAAAAAAAC---- ---CAAAAAAAAAAAAAAAAAAAAAAAC--- --CAAAAAAAAAAAAAAAAAAAAAAAAAC-- --CAAAAAAAAAAAAAAAAAAAAAAAAAC-- -CAAAAAAAAAAAAAAAAAAAAAAAAAAAC- -CAAAAAAAAAAAAAAAAAAAAAAAAAAAC- -CAAAAAAAAAAAAAAAAAAAAAAAAAAAC- CAAAAAAAAAAAAAAAAAAAAAAAAAAAAAC CAAAAAAAAAAAAAAAAAAAAAAAAAAAAAC CAAAAAAAAAAAAAAAAAAAAAAAAAAAAAC CAAAAAAAAAAAAAAAAAAAAAAAAAAAAAC CAAAAAAAAAAAAAAAAAAAAAAAAAAAAAC CAAAAAAAAAAAAAAAAAAAAAAAAAAAAAC CAAAAAAAAAAAAAAAAAAAAAAAAAAAAAC -CAAAAAAAAAAAAAAAAAAAAAAAAAAAC- -CAAAAAAAAAAAAAAAAAAAAAAAAAAAC- -CAAAAAAAAAAAAAAAAAAAAAAAAAAAC- --CAAAAAAAAAAAAAAAAAAAAAAAAAC-- --CAAAAAAAAAAAAAAAAAAAAAAAAAC-- ---CAAAAAAAAAAAAAAAAAAAAAAAC--- ----CAAAAAAAAAAAAAAAAAAAAAC---- -----CAAAAAAAAAAAAAAAAAAAC----- ------CAAAAAAAAAAAAAAAAAC------ -------CCAAAAAAAAAAAAACC------- ---------CCCAAAAAAACCC--------- ------------CCCCCCC------------ 
------------AAACAAA------------ ---------BAAAAAAAAAAAB--------- -------AAAAAAAAAAAAAAAAA------- ------AAAAAAAAAAAAAAAAAAA------ -----AAAAAAAAAAAAAAAAAAAAA----- ----AAAAAAAAAAAAAAAAAAAAAAA---- ---AAAAAAAAAAAAAAAAAAAAAAAAA--- --AAAAAAAAAAAAAAAAAAAAAAAAAAA-- --AAAAAAAAAAAAAAAAAAAAAAAAAAA-- -AAAAAAAAAAAAAAAAAAAAAAAAAAAAA- -AAAAAAAAAAAAAAAAAAAAAAAAAAAAA- -AAAAAAAAAAAAAAAAAAAAAAAAAAAAA- AAAAAAAAAAAAAAAAAAAAAAAAAAAAAAA AAAAAAAAAAAAAAAAAAAAAAAAAAAAAAA AAAAAAAAAAAAAAAAAAAAAAAAAAAAAAA AAAAAAAAAAAAAAAAAAAAAAAAAAAAAAA AAAAAAAAAAAAAAAAAAAAAAAAAAAAAAA AAAAAAAAAAAAAAAAAAAAAAAAAAAAAAA AAAAAAAAAAAAAAAAAAAAAAAAAAAAAAA -BAAAAAAAAAAAAAAAAAAAAAAAAAAAB- -AAAAAAAAAAAAAAAAAAAAAAAAAAAAA- -AAAAAAAAAAAAAAAAAAAAAAAAAAAAA- --AAAAAAAAAAAAAAAAAAAAAAAAAAA-- --AAAAAAAAAAAAAAAAAAAAAAAAAAA-- ---AAAAAAAAAAAAAAAAAAAAAAAAA--- ----AAAAAAAAAAAAAAAAAAAAAAA---- -----AAAAAAAAAAAAAAAAAAAAA----- ------AAAAAAAAAAAAAAAAAAA------ -------AAAAAAAAAAAAAAAAA------- ---------BAAAAAAAAAAAB--------- ------------AAACAAA------------ 
------------AAACAAA------------ ---------BAAAAAAAAAAAB--------- -------AAAAAAAAAAAAAAAAA------- ------AAAAAAAAAAAAAAAAAAA------ -----AAAAAAAAAAAAAAAAAAAAA----- ----AAAAAAAAAAAAAAAAAAAAAAA---- ---AAAAAAAAAAAAAAAAAAAAAAAAA--- --AAAAAAAAAAAAAAAAAAAAAAAAAAA-- --AAAAAAAAAAAAAAAAAAAAAAAAAAA-- -AAAAAAAAAAAAAAAAAAAAAAAAAAAAA- -AAAAAAAAAAAAAAAAAAAAAAAAAAAAA- -AAAAAAAAAAAAAAAAAAAAAAAAAAAAA- AAAAAAAAAAAAAAAAAAAAAAAAAAAAAAA AAAAAAAAAAAAAAAAAAAAAAAAAAAAAAA AAAAAAAAAAAAAAAAAAAAAAAAAAAAAAA AAAAAAAAAAAAAAAAAAAAAAAAAAAAAAA AAAAAAAAAAAAAAAAAAAAAAAAAAAAAAA AAAAAAAAAAAAAAAAAAAAAAAAAAAAAAA AAAAAAAAAAAAAAAAAAAAAAAAAAAAAAA -BAAAAAAAAAAAAAAAAAAAAAAAAAAAB- -AAAAAAAAAAAAAAAAAAAAAAAAAAAAA- -AAAAAAAAAAAAAAAAAAAAAAAAAAAAA- --AAAAAAAAAAAAAAAAAAAAAAAAAAA-- --AAAAAAAAAAAAAAAAAAAAAAAAAAA-- ---AAAAAAAAAAAAAAAAAAAAAAAAA--- ----AAAAAAAAAAAAAAAAAAAAAAA---- -----AAAAAAAAAAAAAAAAAAAAA----- ------AAAAAAAAAAAAAAAAAAA------ -------AAAAAAAAAAAAAAAAA------- ---------BAAAAAAAAAAAB--------- ------------AAACAAA------------ 
-------------AACAA------------- ----------AAAAAAAAAAA---------- --------ABAAAAAAAAAAABA-------- ------AAAAAAAAAAAAAAAAAAA------ -----AAAAAAAAAAAAAAAAAAAAA----- ----AAAAAAAAAAAAAAAAAAAAAAA---- ---AAAAAAAAAAAAAAAAAAAAAAAAA--- ---AAAAAAAAAAAAAAAAAAAAAAAAA--- --AAAAAAAAAAAAAAAAAAAAAAAAAAA-- --AAAAAAAAAAAAAAAAAAAAAAAAAAA-- -AAAAAAAAAAAAAAAAAAAAAAAAAAAAA- -AAAAAAAAAAAAAAAAAAAAAAAAAAAAA- -AAAAAAAAAAAAAAAAAAAAAAAAAAAAA- AAAAAAAAAAAAAAAAAAAAAAAAAAAAAAA AAAAAAAAAAAAAAAAAAAAAAAAAAAAAAA AAAAAAAAAAAAAAAAAAAAAAAAAAAAAAA AAAAAAAAAAAAAAAAAAAAAAAAAAAAAAA AAAAAAAAAAAAAAAAAAAAAAAAAAAAAAA -AAAAAAAAAAAAAAAAAAAAAAAAAAAAA- -BAAAAAAAAAAAAAAAAAAAAAAAAAAAB- -AAAAAAAAAAAAAAAAAAAAAAAAAAAAA- --AAAAAAAAAAAAAAAAAAAAAAAAAAA-- --AAAAAAAAAAAAAAAAAAAAAAAAAAA-- ---AAAAAAAAAAAAAAAAAAAAAAAAA--- ---AAAAAAAAAAAAAAAAAAAAAAAAA--- ----AAAAAAAAAAAAAAAAAAAAAAA---- -----AAAAAAAAAAAAAAAAAAAAA----- ------AAAAAAAAAAAAAAAAAAA------ --------ABAAAAAAAAAAABA-------- ----------AAAAAAAAAAA---------- -------------AACAA------------- 
------------------------------- ----------AAAAACAAAAA---------- --------ABAAAAAAAAAAABA-------- -------AAAAAAAAAAAAAAAAA------- -----AAAAAAAAAAAAAAAAAAAAA----- ----AAAAAAAAAAAAAAAAAAAAAAA---- ----AAAAAAAAAAAAAAAAAAAAAAA---- ---AAAAAAAAAAAAAAAAAAAAAAAAA--- --AAAAAAAAAAAAAAAAAAAAAAAAAAA-- --AAAAAAAAAAAAAAAAAAAAAAAAAAA-- -AAAAAAAAAAAAAAAAAAAAAAAAAAAAA- -AAAAAAAAAAAAAAAAAAAAAAAAAAAAA- -AAAAAAAAAAAAAAAAAAAAAAAAAAAAA- -AAAAAAAAAAAAAAAAAAAAAAAAAAAAA- -AAAAAAAAAAAAAAAAAAAAAAAAAAAAA- -AAAAAAAAAAAAAAAAAAAAAAAAAAAAA- -AAAAAAAAAAAAAAAAAAAAAAAAAAAAA- -AAAAAAAAAAAAAAAAAAAAAAAAAAAAA- -AAAAAAAAAAAAAAAAAAAAAAAAAAAAA- -BAAAAAAAAAAAAAAAAAAAAAAAAAAAB- -AAAAAAAAAAAAAAAAAAAAAAAAAAAAA- --AAAAAAAAAAAAAAAAAAAAAAAAAAA-- --AAAAAAAAAAAAAAAAAAAAAAAAAAA-- ---AAAAAAAAAAAAAAAAAAAAAAAAA--- ----AAAAAAAAAAAAAAAAAAAAAAA---- ----AAAAAAAAAAAAAAAAAAAAAAA---- -----AAAAAAAAAAAAAAAAAAAAA----- -------AAAAAAAAAAAAAAAAA------- --------ABAAAAAAAAAAABA-------- ----------AAAAACAAAAA---------- ------------------------------- 
------------------------------- -----------AAAACAAAA----------- ---------BAAAAAAAAAAAB--------- -------AAAAAAAAAAAAAAAAA------- ------AAAAAAAAAAAAAAAAAAA------ -----AAAAAAAAAAAAAAAAAAAAA----- ----AAAAAAAAAAAAAAAAAAAAAAA---- ---AAAAAAAAAAAAAAAAAAAAAAAAA--- ---AAAAAAAAAAAAAAAAAAAAAAAAA--- --AAAAAAAAAAAAAAAAAAAAAAAAAAA-- --AAAAAAAAAAAAAAAAAAAAAAAAAAA-- -AAAAAAAAAAAAAAAAAAAAAAAAAAAAA- -AAAAAAAAAAAAAAAAAAAAAAAAAAAAA- -AAAAAAAAAAAAAAAAAAAAAAAAAAAAA- -AAAAAAAAAAAAAAAAAAAAAAAAAAAAA- -AAAAAAAAAAAAAAAAAAAAAAAAAAAAA- -AAAAAAAAAAAAAAAAAAAAAAAAAAAAA- -AAAAAAAAAAAAAAAAAAAAAAAAAAAAA- -AAAAAAAAAAAAAAAAAAAAAAAAAAAAA- -BAAAAAAAAAAAAAAAAAAAAAAAAAAAB- --AAAAAAAAAAAAAAAAAAAAAAAAAAA-- --AAAAAAAAAAAAAAAAAAAAAAAAAAA-- ---AAAAAAAAAAAAAAAAAAAAAAAAA--- ---AAAAAAAAAAAAAAAAAAAAAAAAA--- ----AAAAAAAAAAAAAAAAAAAAAAA---- -----AAAAAAAAAAAAAAAAAAAAA----- ------AAAAAAAAAAAAAAAAAAA------ -------AAAAAAAAAAAAAAAAA------- ---------BAAAAAAAAAAAB--------- -----------AAAACAAAA----------- ------------------------------- 
------------------------------- -------------AACAA------------- ----------AAAAAAAAAAA---------- --------ABAAAAAAAAAAABA-------- ------AAAAAAAAAAAAAAAAAAA------ -----AAAAAAAAAAAAAAAAAAAAA----- ----AAAAAAAAAAAAAAAAAAAAAAA---- ----AAAAAAAAAAAAAAAAAAAAAAA---- ---AAAAAAAAAAAAAAAAAAAAAAAAA--- ---AAAAAAAAAAAAAAAAAAAAAAAAA--- --AAAAAAAAAAAAAAAAAAAAAAAAAAA-- --AAAAAAAAAAAAAAAAAAAAAAAAAAA-- --AAAAAAAAAAAAAAAAAAAAAAAAAAA-- -AAAAAAAAAAAAAAAAAAAAAAAAAAAAA- -AAAAAAAAAAAAAAAAAAAAAAAAAAAAA- -AAAAAAAAAAAAAAAAAAAAAAAAAAAAA- -AAAAAAAAAAAAAAAAAAAAAAAAAAAAA- -AAAAAAAAAAAAAAAAAAAAAAAAAAAAA- --AAAAAAAAAAAAAAAAAAAAAAAAAAA-- --BAAAAAAAAAAAAAAAAAAAAAAAAAB-- --AAAAAAAAAAAAAAAAAAAAAAAAAAA-- ---AAAAAAAAAAAAAAAAAAAAAAAAA--- ---AAAAAAAAAAAAAAAAAAAAAAAAA--- ----AAAAAAAAAAAAAAAAAAAAAAA---- ----AAAAAAAAAAAAAAAAAAAAAAA---- -----AAAAAAAAAAAAAAAAAAAAA----- ------AAAAAAAAAAAAAAAAAAA------ --------ABAAAAAAAAAAABA-------- ----------AAAAAAAAAAA---------- -------------AACAA------------- ------------------------------- 
------------------------------- ------------------------------- -----------AAAACAAAA----------- ---------BAAAAAAAAAAAB--------- -------AAAAAAAAAAAAAAAAA------- ------AAAAAAAAAAAAAAAAAAA------ -----AAAAAAAAAAAAAAAAAAAAA----- ----AAAAAAAAAAAAAAAAAAAAAAA---- ----AAAAAAAAAAAAAAAAAAAAAAA---- ---AAAAAAAAAAAAAAAAAAAAAAAAA--- ---AAAAAAAAAAAAAAAAAAAAAAAAA--- --AAAAAAAAAAAAAAAAAAAAAAAAAAA-- --AAAAAAAAAAAAAAAAAAAAAAAAAAA-- --AAAAAAAAAAAAAAAAAAAAAAAAAAA-- --AAAAAAAAAAAAAAAAAAAAAAAAAAA-- --AAAAAAAAAAAAAAAAAAAAAAAAAAA-- --AAAAAAAAAAAAAAAAAAAAAAAAAAA-- --AAAAAAAAAAAAAAAAAAAAAAAAAAA-- --AAAAAAAAAAAAAAAAAAAAAAAAAAA-- --BAAAAAAAAAAAAAAAAAAAAAAAAAB-- ---AAAAAAAAAAAAAAAAAAAAAAAAA--- ---AAAAAAAAAAAAAAAAAAAAAAAAA--- ----AAAAAAAAAAAAAAAAAAAAAAA---- ----AAAAAAAAAAAAAAAAAAAAAAA---- -----AAAAAAAAAAAAAAAAAAAAA----- ------AAAAAAAAAAAAAAAAAAA------ -------AAAAAAAAAAAAAAAAA------- ---------BAAAAAAAAAAAB--------- -----------AAAACAAAA----------- ------------------------------- ------------------------------- 
------------------------------- ------------------------------- -------------AACAA------------- ----------AAAAAAAAAAA---------- --------ABAAAAAAAAAAABA-------- -------AAAAAAAAAAAAAAAAA------- ------AAAAAAAAAAAAAAAAAAA------ -----AAAAAAAAAAAAAAAAAAAAA----- ----AAAAAAAAAAAAAAAAAAAAAAA---- ----AAAAAAAAAAAAAAAAAAAAAAA---- ---AAAAAAAAAAAAAAAAAAAAAAAAA--- ---AAAAAAAAAAAAAAAAAAAAAAAAA--- ---AAAAAAAAAAAAAAAAAAAAAAAAA--- --AAAAAAAAAAAAAAAAAAAAAAAAAAA-- --AAAAAAAAAAAAAAAAAAAAAAAAAAA-- --AAAAAAAAAAAAAAAAAAAAAAAAAAA-- --AAAAAAAAAAAAAAAAAAAAAAAAAAA-- --AAAAAAAAAAAAAAAAAAAAAAAAAAA-- ---AAAAAAAAAAAAAAAAAAAAAAAAA--- ---BAAAAAAAAAAAAAAAAAAAAAAAB--- ---AAAAAAAAAAAAAAAAAAAAAAAAA--- ----AAAAAAAAAAAAAAAAAAAAAAA---- ----AAAAAAAAAAAAAAAAAAAAAAA---- -----AAAAAAAAAAAAAAAAAAAAA----- ------AAAAAAAAAAAAAAAAAAA------ -------AAAAAAAAAAAAAAAAA------- --------ABAAAAAAAAAAABA-------- ----------AAAAAAAAAAA---------- -------------AACAA------------- ------------------------------- ------------------------------- 
------------------------------- ------------------------------- ------------------------------- ------------AAACAAA------------ ---------BAAAAAAAAAAAB--------- --------AAAAAAAAAAAAAAA-------- -------AAAAAAAAAAAAAAAAA------- ------AAAAAAAAAAAAAAAAAAA------ -----AAAAAAAAAAAAAAAAAAAAA----- ----AAAAAAAAAAAAAAAAAAAAAAA---- ----AAAAAAAAAAAAAAAAAAAAAAA---- ----AAAAAAAAAAAAAAAAAAAAAAA---- ---AAAAAAAAAAAAAAAAAAAAAAAAA--- ---AAAAAAAAAAAAAAAAAAAAAAAAA--- ---AAAAAAAAAAAAAAAAAAAAAAAAA--- ---AAAAAAAAAAAAAAAAAAAAAAAAA--- ---AAAAAAAAAAAAAAAAAAAAAAAAA--- ---AAAAAAAAAAAAAAAAAAAAAAAAA--- ---AAAAAAAAAAAAAAAAAAAAAAAAA--- ----BAAAAAAAAAAAAAAAAAAAAAB---- ----AAAAAAAAAAAAAAAAAAAAAAA---- ----AAAAAAAAAAAAAAAAAAAAAAA---- -----AAAAAAAAAAAAAAAAAAAAA----- ------AAAAAAAAAAAAAAAAAAA------ -------AAAAAAAAAAAAAAAAA------- --------AAAAAAAAAAAAAAA-------- ---------BAAAAAAAAAAAB--------- ------------AAACAAA------------ ------------------------------- ------------------------------- ------------------------------- 
------------------------------- ------------------------------- ------------------------------- ------------------------------- -----------AAAACAAAA----------- ---------BAAAAAAAAAAAB--------- --------AAAAAAAAAAAAAAA-------- -------AAAAAAAAAAAAAAAAA------- ------AAAAAAAAAAAAAAAAAAA------ -----AAAAAAAAAAAAAAAAAAAAA----- -----AAAAAAAAAAAAAAAAAAAAA----- ----AAAAAAAAAAAAAAAAAAAAAAA---- ----AAAAAAAAAAAAAAAAAAAAAAA---- ----AAAAAAAAAAAAAAAAAAAAAAA---- ----AAAAAAAAAAAAAAAAAAAAAAA---- ----AAAAAAAAAAAAAAAAAAAAAAA---- ----AAAAAAAAAAAAAAAAAAAAAAA---- ----AAAAAAAAAAAAAAAAAAAAAAA---- ----AAAAAAAAAAAAAAAAAAAAAAA---- ----BAAAAAAAAAAAAAAAAAAAAAB---- -----AAAAAAAAAAAAAAAAAAAAA----- -----AAAAAAAAAAAAAAAAAAAAA----- ------AAAAAAAAAAAAAAAAAAA------ -------AAAAAAAAAAAAAAAAA------- --------AAAAAAAAAAAAAAA-------- ---------BAAAAAAAAAAAB--------- -----------AAAACAAAA----------- ------------------------------- ------------------------------- ------------------------------- ------------------------------- 
------------------------------- ------------------------------- ------------------------------- ------------------------------- ------------------------------- -----------AAAACAAAA----------- ---------BAAAAAAAAAAAB--------- --------ABAAAAAAAAAAABA-------- -------AAAAAAAAAAAAAAAAA------- ------AAAAAAAAAAAAAAAAAAA------ ------AAAAAAAAAAAAAAAAAAA------ -----AAAAAAAAAAAAAAAAAAAAA----- -----AAAAAAAAAAAAAAAAAAAAA----- -----AAAAAAAAAAAAAAAAAAAAA----- -----AAAAAAAAAAAAAAAAAAAAA----- -----AAAAAAAAAAAAAAAAAAAAA----- -----AAAAAAAAAAAAAAAAAAAAA----- -----AAAAAAAAAAAAAAAAAAAAA----- -----AAAAAAAAAAAAAAAAAAAAA----- -----BBAAAAAAAAAAAAAAAAABB----- ------AAAAAAAAAAAAAAAAAAA------ ------AAAAAAAAAAAAAAAAAAA------ -------AAAAAAAAAAAAAAAAA------- --------ABAAAAAAAAAAABA-------- ---------BAAAAAAAAAAAB--------- -----------AAAACAAAA----------- ------------------------------- ------------------------------- ------------------------------- ------------------------------- ------------------------------- 
------------------------------- ------------------------------- ------------------------------- ------------------------------- ------------------------------- ------------------------------- ------------DDDCDDD------------ ----------ADDAAAAADDA---------- ---------BAAAAAAAAAAAB--------- --------ABAAAAAAAAAAABA-------- -------AAAAAAAAAAAAAAAAA------- -------AAAAAAAAAAAAAAAAA------- ------AAAAAAAAAAAAAAAAAAA------ ------AAAAAAAAAAAAAAAAAAA------ ------AAAAAAAAAAAAAAAAAAA------ ------AAAAAAAAAAAAAAAAAAA------ ------AAAAAAAAAAAAAAAAAAA------ ------AAAAAAAAAAAAAAAAAAA------ ------AAAAAAAAAAAAAAAAAAA------ -------BAAAAAAAAAAAAAAAB------- -------AAAAAAAAAAAAAAAAA------- --------ABAAAAAAAAAAABA-------- ---------BAAAAAAAAAAAB--------- ----------AAAAAAAAAAA---------- ------------AAACAAA------------ ------------------------------- ------------------------------- ------------------------------- ------------------------------- ------------------------------- ------------------------------- 
------------------------------- ------------------------------- ------------------------------- ------------------------------- ------------------------------- ------------------------------- ------------------------------- -------------DDCDD------------- -----------AAAACAAAA----------- ----------AAAAAAAAAAA---------- ---------BAAAAAAAAAAAB--------- --------ABAAAAAAAAAAABA-------- --------ABAAAAAAAAAAABA-------- -------AAAAAAAAAAAAAAAAA------- -------AAAAAAAAAAAAAAAAA------- -------AAAAAAAAAAAAAAAAA------- -------AAAAAAAAAAAAAAAAA------- -------AAAAAAAAAAAAAAAAA------- --------ABAAAAAAAAAAABA-------- --------BBAAAAAAAAAAABB-------- ---------BAAAAAAAAAAAB--------- ----------AAAAAAAAAAA---------- -----------AAAACAAAA----------- -------------AACAA------------- ------------------------------- ------------------------------- ------------------------------- ------------------------------- ------------------------------- ------------------------------- ------------------------------- 
------------------------------- ------------------------------- ------------------------------- ------------------------------- ------------------------------- ------------------------------- ------------------------------- ------------------------------- ------------------------------- -------------AACAA------------- -----------AAAACAAAA----------- ----------AAAAACAAAAA---------- ----------AAAAAAAAAAA---------- ---------BAAAAAAAAAAAB--------- ---------BAAAAAAAAAAAB--------- ---------BAAAAAAAAAAAB--------- ---------BAAAAAAAAAAAB--------- ---------BAAAAAAAAAAAB--------- ----------AAAAAAAAAAA---------- ----------BBBBBCBBBBB---------- -----------AAAACAAAA----------- -------------AACAA------------- ------------------------------- ------------------------------- ------------------------------- ------------------------------- ------------------------------- ------------------------------- ------------------------------- ------------------------------- ------------------------------- 
------------------------------- ------------------------------- ------------------------------- ------------------------------- ------------------------------- ------------------------------- ------------------------------- ------------------------------- ------------------------------- ------------------------------- ------------------------------- ------------------------------- -------------AACAA------------- ------------ADDCDDA------------ ------------AADCDAA------------ ------------AAACAAA------------ ------------AAACAAA------------ ------------AAACAAA------------ -------------AACAA------------- ------------------------------- ------------------------------- ------------------------------- ------------------------------- ------------------------------- ------------------------------- ------------------------------- ------------------------------- ------------------------------- ------------------------------- ------------------------------- ------------------------------- 
