model
size = 31 30 22, scale = 0.05, origin = -y
material 
  colors = A:#BBB B:#444 C:#111 D:#0E0 E:#222
voxels
-----CCCCCCCCCCCCCCCCCCCCCCC--- ------DDDDDDDDDDDDDDDDDDDDDD--- -------DDDAAAAAAAAAAAAAAAAAD--- --------DDAAAAAAAAAAAAAAAAAD--- ---------DDDDDDDDDDDDDDDDDDD--- ------------------------------- ------------------------------- ------------------------------- ------------------------------- ------------------------------- ------------------------------- ------------------------------- ------------------------------- ------------------------------- ------------------------------- ------------------------------- ------------------------------- ------------------------------- ------------------------------- ------------------------------- ------------------------------- ------------------------------- ------------------------------- ------------------------------- ------------------------------- ------------------------------- ------------------------------- ------------------------------- ------------------------------- ------------------------------- 
---CCCCCCCCCCCCCCCCCCCCCCCCCC-- ----CCCCCCCCCCCCCCCCCCCCCCCCC-- -----CCCCCCCCCCCCCCCCCCCCCCCC-- ------CCCCCCCCCCCCCCCCCCCCCCC-- -------CCCCCCCCCCCCCCCCCCCCCC-- --------CCCCCCCCCCCCCCCCCCCCC-- ------------------------------- ------------------------------- ------------------------------- ------------------------------- ------------------------------- ------------------------------- ------------------------------- ------------------------------- ------------------------------- ------------------------------- ------------------------------- ------------------------------- ------------------------------- ------------------------------- ------------------------------- ------------------------------- ------------------------------- ------------------------------- ------------------------------- ------------------------------- ------------------------------- ------------------------------- ------------------------------- ------------------------------- 
-CCBBBBBBBBBBBBBBBBBBBBBBBBBBC- --BBBBBBBBBBBBBBBBBBBBBBBBBBBB- ---BBBBBBBBBBBBBBBBBBBBBBBBBBB- ----BBBBBBBBBBBBBBBBBBBBBBBBBB- -----BBBBBBBBBBBBBBBBBBBBBBBBB- ------BBBBBBBBBBBBBBBBBBBBBBBB- -------BBBBBBBBBBBBBBBBBBBBBBB- ------------------------------- ------------------------------- ------------------------------- ------------------------------- ------------------------------- ------------------------------- ------------------------------- ------------------------------- ------------------------------- ------------------------------- ------------------------------- ------------------------------- ------------------------------- ------------------------------- ------------------------------- ------------------------------- ------------------------------- ------------------------------- ------------------------------- ------------------------------- ------------------------------- ------------------------------- ------------------------------- 
CBBBAEAEAEAEAEAEAEAEAEAEAEAEBBC -CCCCCCCCCCCCCCCCCCCAAAAAAAABBB --CCCCCCCCCCCCCCCCCCAAAAAAAABBB ---CCCCCCCCCCCCCCCCCAAAAAAAABBB ----CCCCCCCCCCCCCCCCAAAAAAAABBB -----CCCCCCCCCCCCCCCAAAAAAAABBB ------CCCCCCCCCCCCCCAAAAAAAABBB -------CCCCCCCCCCCCCCCCCCCBBBBB ---------------------DDDD------ ---------------------DAAD------ ---------------------DAAD------ ---------------------DAAD------ ---------------------DAAD------ ---------------------DAAD------ ---------------------DAAD------ ---------------------DAAD------ ---------------------DAAD------ ---------------------DAAD------ ---------------------DAAD------ ---------------------DAAD------ ---------------------DAAD------ ---------------------DAAD------ ---------------------DAAD------ ---------------------DAAD------ ---------------------DAAD------ ---------------------DAAD------ ---------------------DAAD------ ---------------------DAAD------ ---------------------DAAD------ ---------------------DDDD------ 
CBECEAEAECEAEAEAEAEAEAEAEAECBBC -BAAAAAAAAAAAAAAAAAAAAAAAAAABBB --BAAAAAAAAAAAAAAAAAAAAAAAAABBB ---BAAAAAAAAAAAAAAAAAAAAAAAABBB ----BAAAAAAAAAAAAAAAAAAAAAAABBB -----BAAAAAAAAAAAAAAAAAAAAAABBB ------BAAAAAAAAAAAAAAAAAAAAABBB -------BBBBBBBBBBBBBAAAAACBABBB ----------BBBBBBBBBBCAAAACBB--- -------------------BCAAAACBB--- -------------------BCAAAACBB--- -------------------BCAAAACBB--- -------------------BCAAAACBB--- -------------------BCAAAACBB--- -------------------BCAAAACBB--- -------------------BCAAAACBB--- -------------------BCAAAACBB--- -------------------BCAAAACBB--- -------------------BCAAAACBB--- -------------------BCAAAACBB--- -------------------BCAAAACBB--- -------------------BCAAAACBB--- -------------------BCAAAACBB--- -------------------BCAAAACBB--- -------------------BCAAAACBB--- -------------------BCAAAACBB--- -------------------BCAAAACBB--- -------------------BCAAAACBB--- -------------------BCAAAACBB--- -------------------BCCCCCCBB--- 
CBAEAEEEAEAECEAEAECEAEAECEAEABC -BA-----------AAAAAAAAAAAAAAABB --B-----------AAAAAAAAAAAAAAABB ---BB---------AAAAAAAAAAAAAAABB ----B---------AAAAAAAAAAAAAAABB -----BBBBA----AAAAAAAAAAAAAAABB ------BBBAAAAAAAAAAAAAAAAAAAABB -------BBBBBBBBBBBBAAAAAAAAAABB ---------BBBBBBBBBBAAAAAAAABB-- ---------------DDDBAAAAAAAABB-- ------------------BAAAAAAAABB-- ------------------BAAAAAAAABB-- ------------------BAAAAAAAABB-- ------------------BAAAAAAAABB-- ------------------BAAAAAAAABB-- ------------------BAAAAAAAABB-- ------------------BAAAAAAAABB-- ------------------BAAAAAAAABB-- ------------------BAAAAAAAABB-- ------------------BAAAAAAAABB-- ------------------BAAAAAAAABB-- ------------------BAAAAAAAABB-- ------------------BAAAAAAAABB-- ------------------BAAAAAAAABB-- ------------------BAAAAAAAABB-- ------------------BAAAAAAAABB-- ------------------BAAAAAAAABB-- ------------------BAAAAAAAABB-- ------------------BAAAAAAAABB-- ------------------BBBBBBBBBBB-- 
CBEAEAEAEAEAEAECEAEAECEAEAEAEBC -BA-----------AAAAAAA-----AAAAB --A-----------AAAAAAA-----AAAAB ---AA---------AAAAAAA-----AAAAB ----A---------AAAAAAA-----AAAAB -----AAAAA----AAAAAAA-----AAAAB ------AAAAAAAAAAAAAAA-----AAAAB -------AAAAAAAAAAAAAA-----AAAAB --------ABBBBBADDAAAA-----AAAB- --------------DDDDAAA-----AAAB- -----------------BBAA-----AAAB- -----------------BBAA-----AAAB- -----------------BBAA-----AAAB- -----------------BBAA-----AAAB- -----------------BBAA-----AAAB- -----------------BBAA-----AAAB- -----------------BBAA-----AAAB- -----------------BBAA-----AAAB- -----------------BBAA-----AAAB- -----------------BBAA-----AAAB- -----------------BBAA-----AAAB- -----------------BBAA-----AAAB- -----------------BBAA-----AAAB- -----------------BBAA-----AAAB- -----------------BBAA-----AAAB- -----------------BBAA-----AAAB- -----------------BBAA-----AAAB- -----------------BBAA-----AAAB- -----------------BBAA-----AAAB- -----------------BBBB-----BBBB- 
CBAEAEAEAEAEAEAEAEAEAEAEAEAEABC -BA-----------AAAAAA-------AACC --A-----------AAAAAA-------AACC ---AA---------AAAAAA-------AACC ----A---------AAAAAA-------AACC -----AAAAA----AAAAAA-------AACC ------AAAAAAAAAAAAAA-------AACC -------AAAAAAAAAAAAA-------AACC --------ABBBBBDDDAAA-------AAC- -----------DDDDDDDAA-------AAC- ----------------BAAA-------AAC- ----------------BAAA-------AAC- ----------------BAAA-------AAC- ----------------BAAA-------AAC- ----------------BAAA-------AAC- ----------------BAAA-------AAC- ----------------BAAA-------AAC- ----------------BAAA-------AAC- ----------------BAAA-------AAC- ----------------BAAA-------AAC- ----------------BAAA-------AAC- ----------------BAAA-------AAC- ----------------BAAA-------AAC- ----------------BAAA-------AAC- ----------------BAAA-------AAC- ----------------BAAA-------AAC- ----------------BAAA-------AAC- ----------------BAAA-------AAC- ----------------BAAA-------AAC- ----------------BBBB-------BBC- 
CBEEEAEAECEAEAEAEAEAEAEAEAECEBC -BA------------AAA----------AAD --C------------AAA----------AAD ---CC----------AAA----------AAD ----C----------AAA----------AAD -----CCC-------AAA----------AAD ------CCAAAAAA-AAA----------AAD -------CAAAAAAAAAA----------AAD --------CCADDAAAAA----------AAD ----------DCCCCCCA----------AAD ----------------CA----------AAD ----------------CA----------AAD ----------------CA----------AAD ----------------CA----------AAD ----------------CA----------AAD ----------------CA----------AAD ----------------CA----------AAD ----------------CA----------AAD ----------------CA----------AAD ----------------CA----------AAD ----------------CAA---------AAD ----------------CAA---------AAD ----------------CAA---------AAD ----------------CAA---------AAD ----------------CAA---------AAD ----------------CAA---------AAD ----------------CAA---------AAD ----------------CAA---------AAD ----------------CAA---------AAD ----------------CBB---------BCD 
CBAEAEEEAEAECEAEAECEAEAECEAEABC -BA------------AA------------AD --D------------AA------------AD ---DD----------AA------------AD ----D----------AA------------AD -----DDD-------AA------------AD ------DDDDDDD--AA------------AD -------DDDDDDAAAA------------AD --------CAADDAAAA------------AD ---------DCCDDDDA------------AD ---------------DA------------AD ---------------DA------------AD ---------------DA------------AD ---------------DA------------AD ---------------DA------------AD ---------------DA------------AD ---------------DA------------AD ---------------DA------------AD ---------------DA------------AD ---------------DAA-----------AD ---------------DAA-----------AD ---------------DAA-----------AD ---------------DAA-----------AD ---------------DAA-----------AD ---------------DAA-----------AD ---------------DAA-----------AD ---------------DAA-----------AD ---------------DAA-----------AD ---------------DAA-----------AD ---------------DCB-----------CD 
CBEAEAEAEAEAEAECEAEAECEAEAEAEBC -BA--------------------------AC --C--------------------------AC ---CC------------------------AC ----C------------------------AC -----CCC---------------------AC ------CCDDDDD----------------AA -------CDDDDDAAA-------------AC --------CAADDAAA-------------AC --------DCCDAAAA-------------AC ---------------A-------------AC ---------------A-------------AC ---------------A-------------AA ---------------A-------------AC ---------------A-------------AC ---------------A-------------AC ---------------AA------------AC ---------------AA------------AC ---------------AA------------AA ---------------AAA-----------AC ---------------AAA-----------AC ---------------AAA-----------AC ---------------AAA-----------AC ---------------AAA-----------AC ---------------AAA-----------AA ---------------AAA-----------AC ---------------AAA-----------AC ---------------AAA-----------AC ---------------AAA-----------AA ---------------DCB-----------CC 
CBAEAEAEAEAEAEAEAEAEAEAEAEAEABC -BA--------------------------AA --C--------------------------AA ---CC------------------------AA ----C------------------------AA -----CCC---------------------AC ------CCDDDDD----------------AA -------CDDDDDAAA-------------AC --------CAADDAAA-------------AA --------DCCDAAAA-------------AA ---------------A-------------AA ---------------A-------------AC ---------------A-------------AA ---------------A-------------AC ---------------A-------------AA ---------------A-------------AA ---------------AA------------AA ---------------AA------------AC ---------------AA------------AA ---------------AAA-----------AA ---------------AAA-----------AA ---------------AAA-----------AA ---------------AAA-----------AC ---------------AAA-----------AA ---------------AAA-----------AA ---------------AAA-----------AC ---------------AAA-----------AA ---------------AAA-----------AC ---------------AAA-----------AA ---------------DCB-----------CC 
CBEEEAEAECEAEAEAEAEAEAEAEAECEBC -BA--------------------------AC --D--------------------------AC ---DD------------------------AC ----D------------------------AC -----DDD---------------------AC ------DDDDDDD----------------AA -------DDDDDDAAA-------------AC --------CAADDAAA-------------AC ---------DCCDDDAA------------AC ---------------DA------------AC ---------------DA------------AC ---------------DA------------AA ---------------DA------------AC ---------------DA------------AC ---------------DA------------AC ---------------DA------------AC ---------------DA------------AC ---------------DA------------AA ---------------DAA-----------AC ---------------DAA-----------AC ---------------DAA-----------AC ---------------DAA-----------AC ---------------DAA-----------AC ---------------DAA-----------AA ---------------DAA-----------AC ---------------DAA-----------AA ---------------DAA-----------AC ---------------DAA-----------AC ---------------DCB-----------CC 
CBAEAEEEAEAECEAEAECEAEAECEAEABC -BA--------------------------AD --C--------------------------AD ---CC------------------------AD ----C------------------------AD -----CCC---------------------AD ------CCAAAAA----------------AD -------CAAAAAAAA-------------AD --------CCADDAAA-------------AD ----------DCCCCCA------------AD ----------------CA-----------AD ----------------CA-----------AD ----------------CA-----------AD ----------------CA-----------AD ----------------CA-----------AD ----------------CA-----------AD ----------------CA-----------AD ----------------CA-----------AD ----------------CA-----------AD ----------------CA-----------AD ----------------CA-----------AD ----------------CA-----------AD ----------------CA-----------AD ----------------CA-----------AD ----------------CA-----------AD ----------------CA-----------AD ----------------CA-----------AD ----------------CA-----------AD ----------------CA-----------AD ----------------CB-----------CD 
CBEAEAEAEAEAEAECEAEAECEAEAEAEBC -BA-------------------------AAD --A-------------------------AAD ---AA-----------------------AAD ----A-----------------------AAD -----AAAAA------------------AAD ------AAAAAAAA--------------AAD -------AAAAAAAAA------------AAD --------ABBBBAAA------------AAD -----------DDDDDA-----------AAD ----------------BAA---------AAD ----------------B-A---------AAD ----------------BAA---------AAD ----------------BAA---------AAD ----------------B-A---------AAD ----------------BAA---------AAD ----------------BAA---------AAD ----------------B-A---------AAD ----------------BAA---------AAD ----------------BAA---------AAD ----------------BAA---------AAD ----------------BAA---------AAD ----------------BAA---------AAD ----------------BAA---------AAD ----------------BAA---------AAD ----------------BAA---------AAD ----------------BAA---------AAD ----------------BAA---------AAD ----------------BAA---------AAD ----------------BBB---------BCD 
CBAEAEAEAEAEAEAEAEAEAEAEAEAEABC -BA------------AAAAA-------AACC --A------------AAAAA-------AACC ---AA----------AAAAA-------AACC ----A----------AAAAA-------AACC -----AAAAA-----AAAAA-------AACC ------AAAAAAAAAAAAAA-------AACC -------AAAAAAAAAAAAA-------AACC --------ABBBBBAAAAAA-------AAC- --------------DDDAAA-------AAC- ----------------BBBA-------AAC- ----------------BBBA-------AAC- ----------------BBBA-------AAC- ----------------BBBA-------AAC- ----------------BBBA-------AAC- ----------------BBBA-------AAC- ----------------BBBA-------AAC- ----------------BBBA-------AAC- ----------------BBBA-------AAC- ----------------BBBA-------AAC- ----------------BBBA-------AAC- ----------------BBBA-------AAC- ----------------BBBA-------AAC- ----------------BBBA-------AAC- ----------------BBBA-------AAC- ----------------BBBA-------AAC- ----------------BBBA-------AAC- ----------------BBBA-------AAC- ----------------BBBA-------AAC- ----------------BBBB-------BBC- 
CBEEEAEAECEAEAEAEAEAEAEAEAECEBC -BA-----------AAAAAAA-----AAABB --B-----------AAAAAAA-----AAABB ---BB---------AAAAAAA-----AAABB ----B---------AAAAAAA-----AAABB -----BBBBA----AAAAAAA-----AAABB ------BBBAAAAAAAAAAAA-----AAABB -------BBAAAAAAAAAAAA-----AAABB ---------BBBBBBBBBAAA-----ABB-- ---------------DDBBAA-----ABB-- -----------------BBAA-----ABB-- -----------------BBAA-----ABB-- -----------------BBAA-----ABB-- -----------------BBAA-----ABB-- -----------------BBAA-----ABB-- -----------------BBAA-----ABB-- -----------------BBAA-----ABB-- -----------------BBAA-----ABB-- -----------------BBAA-----ABB-- -----------------BBAA-----ABB-- -----------------BBAA-----ABB-- -----------------BBAA-----ABB-- -----------------BBAA-----ABB-- -----------------BBAA-----ABB-- -----------------BBAA-----ABB-- -----------------BBAA-----ABB-- -----------------BBAA-----ABB-- -----------------BBAA-----ABB-- -----------------BBAA-----ABB-- -----------------BBBB-----BBB-- 
CBAEAEEEAEAECEAEAECEAEAECEAEBBC -BA-----------AAAAAAAAAAAAAABBB --B-----------AAAAAAAAAAAAAABBB ---BA---------AAAAAAAAAAAAAABBB ----B---------AAAAAAAAAAAAAABBB -----BAAAA----AAAAAAAAAAAAAABBB ------BAAAAAAAAAAAAAAAAAAAAABBB -------BBBAAAAAAAAAAAAAAAAAABBB ----------BBBBBBBBBBAAAAAAAB--- ------------------BBAAAAAAAB--- ------------------BBAAAAAAAB--- ------------------BBAAAAAAAB--- ------------------BBAAAAAAAB--- ------------------BBAAAAAAAB--- ------------------BBAAAAAAAB--- ------------------BBAAAAAAAB--- ------------------BBAAAAAAAB--- ------------------BBAAAAAAAB--- ------------------BBAAAAAAAB--- ------------------BBAAAAAAAB--- ------------------BBAAAAAAAB--- ------------------BBAAAAAAAB--- ------------------BBAAAAAAAB--- ------------------BBAAAAAAAB--- ------------------BBAAAAAAAB--- ------------------BBAAAAAAAB--- ------------------BBAAAAAAAB--- ------------------BBAAAAAAAB--- ------------------BBAAAAAAAB--- ------------------BBCCCCCCBB--- 
CBBBEAEAEAEAEAECEAEAECEAEAEABBC -CCCCCCAAAAAAAAAAAAAAAAAAAAABBB --CCCCCAAAAAAAAAAAAAAAAAAAAABBB ---CCCCAAAAAAAAAAAAAAAAAAAAABBB ----CCCAAAAAAAAAAAAAAAAAAAAABBB -----CCAAAAAAAAAAAAAAAAAAAAABBB ------CAAAAAAAAAAAAAAAAAAAAABBB -------CCCCCCCCCCCCCCCCCCCBBBBB --------------------CDDDDCB---- --------------------CDAADCB---- --------------------CDAADCB---- --------------------CDAADCB---- --------------------CDAADCB---- --------------------CDAADCB---- --------------------CDAADCB---- --------------------CDAADCB---- --------------------CDAADCB---- --------------------CDAADCB---- --------------------CDAADCB---- --------------------CDAADCB---- --------------------CDAADCB---- --------------------CDAADCB---- --------------------CDAADCB---- --------------------CDAADCB---- --------------------CDAADCB---- --------------------CDAADCB---- --------------------CDAADCB---- --------------------CDAADCB---- --------------------CDAADCB---- --------------------CDDDDCB---- 
-CCBBBAEAEAEAEAEAEAEAEAEAEABBC- --BBAAAAAAAAAAAAAAAAAAAAAAAAAB- ---BBAAAAAAAAAAAAAAAAAAAAAAAAB- ----BBAAAAAAAAAAAAAAAAAAAAAAAB- -----BBAAAAAAAAAAAAAAAAAAAAAAB- ------BBAAAAAAAAAAAAAAAAAAAAAB- -------BBBBBBBBBBBBBBBBBBBBBBB- ------------------------------- ------------------------------- ------------------------------- ------------------------------- ------------------------------- ------------------------------- ------------------------------- ------------------------------- ------------------------------- ------------------------------- ------------------------------- ------------------------------- ------------------------------- ------------------------------- ------------------------------- ------------------------------- ------------------------------- ------------------------------- ------------------------------- ------------------------------- ------------------------------- ------------------------------- ------------------------------- 
---CCBBBBBBBBBBBBBBBBBBBBBBBC-- ----CCCCCCCCCCCCCCCCCCCCCCCCC-- -----CCCCCCCCCCCCCCCCCCCCCCCC-- ------CCCCCCCCCCCCCCCCCCCCCCC-- -------CCCCCCCCCCCCCCCCCCCCCC-- --------CCCCCCCCCCCCCCCCCCCCC-- ------------------------------- ------------------------------- ------------------------------- ------------------------------- ------------------------------- ------------------------------- ------------------------------- ------------------------------- ------------------------------- ------------------------------- ------------------------------- ------------------------------- ------------------------------- ------------------------------- ------------------------------- ------------------------------- ------------------------------- ------------------------------- ------------------------------- ------------------------------- ------------------------------- ------------------------------- ------------------------------- ------------------------------- 
-----CCCCCCCCCCCCCCCCCCCCCCC--- ------DDDDDDDDDDDDDDDDDDDDDD--- -------DDDAAAAAAAAAAAAAAAAAD--- --------DDAAAAAAAAAAAAAAAAAD--- ---------DDDDDDDDDDDDDDDDDDD--- ------------------------------- ------------------------------- ------------------------------- ------------------------------- ------------------------------- ------------------------------- ------------------------------- ------------------------------- ------------------------------- ------------------------------- ------------------------------- ------------------------------- ------------------------------- ------------------------------- ------------------------------- ------------------------------- ------------------------------- ------------------------------- ------------------------------- ------------------------------- ------------------------------- ------------------------------- ------------------------------- ------------------------------- ------------------------------- 
