model
size = 17 20 17, scale = 0.05, origin = -y
material 
  colors = A:#FF0 B:#FF3 C:#AAA D:#FF6 E:#444
voxels
----------------- ----------------- ----------------- ----------------- ----------------- ----------------- ----------------- ----------------- ----------------- ----------------- ----------------- ----------------- ----------------- ----------------- ----------------- ----------------- ------BAABD------ ----------------- ----------------- ----------------- 
----------------- ----------------- ----------------- ----------------- ----------------- ----------------- ----------------- ----------------- ----------------- ----------------- ----------------- ----------------- ----------------- ----------------- ----------------- ----------------- ----BBB---ABA---- ----------------- ----------------- ----------------- 
------AAAAA------ ------BAAAB------ --------A-------- ----------------- ----------------- ----------------- ----------------- ----------------- ----------------- ----------------- ----------------- ----------------- ----------------- ----------------- ----------------- ----------------- --DAA-------AAA-- ----------------- ----------------- ----------------- 
-----AA---AA----- -----BA---AB----- ------BAAAB------ --------D-------- ----------------- ----------------- ----------------- ----------------- ----------------- ----------------- ----------------- ----------------- ----------------- ----------------- ----------------- ----------------- --A--CCCCCC---D-- ----------------- ----------------- ----------------- 
----AA-----AA---- ----BA-----AD---- -----ABAAAAA----- ------BBDAD------ ----------------- ----------------- ----------------- ----------------- ----------------- ----------------- ----------------- ----------------- ----------------- ----------------- ----------------- ----------------- -BA-C------C--AA- ----------------- ----------------- ----------------- 
---AA-------AA--- ---AA-------AB--- ----BABBBBBBD---- -----DAABAAA----- ----------------- ----------------- ----------------- ----------------- ----------------- ----------------- ----------------- ----------------- ----------------- ----------------- ----------------- ----------------- -B----CCCCC-C--A- ----------------- ----------------- ----------------- 
--AA---------AA-- --AA---------AA-- ---BBABBBBBBAA--- ----BDAAAAAAA---- -------ADD------- ----------------- ----------------- ----------------- ----------------- ----------------- ----------------- ----------------- ----------------- ----------------- ----------------- ----------------- AA-C-C-----C-C-DA ----------------- ----------------- ----------------- 
--AA---------AA-- --AA---------AA-- ---DAAAAAAAAAB--- ----AAAAAAADA---- ------AA-AA------ ----------------- ----------------- ----------------- ----------------- ----------------- ----------------- ----------------- ----------------- -------D-A------- -------B-D------- -------A-A------- A-C----A-A----C-A -------A-D------- --------B-------- ----------------- 
--AA---------AA-- --AA---------AA-- --AAAAAAAAAAABA-- ---ADAAAAAAADD--- ------A-A-A------ --------A-------- --------B-------- --------A-------- --------A-------- --------B-------- --------A-------- --------D-------- --------A-------- -------AAA------- ----------------- ----------------- B-C-----E-----C-A --------A-------- -------ABB------- --------D-------- 
--AA---------AA-- --AA---------AB-- ---BAAAAAAAAAA--- ----DAAAAAAAB---- ------DA-AD------ ----------------- ----------------- ----------------- ----------------- ----------------- ----------------- ----------------- ----------------- -------A-D------- -------D-B------- -------A-A------- A-C----A-B----C-B -------D-A------- --------B-------- ----------------- 
--AA---------AA-- --AA---------AB-- ---ABAAAAAAAAA--- ----BAAAAAAAA---- -------ABA------- ----------------- ----------------- ----------------- ----------------- ----------------- ----------------- ----------------- ----------------- ----------------- ----------------- ----------------- AA-C-C-----C-C-AA ----------------- ----------------- ----------------- 
---AA-------AA--- ---AA-------AB--- ----BAAAAAAAB---- -----DAADBAD----- ----------------- ----------------- ----------------- ----------------- ----------------- ----------------- ----------------- ----------------- ----------------- ----------------- ----------------- ----------------- -D----CCCCC----D- ----------------- ----------------- ----------------- 
----AA-----AA---- ----BA-----AB---- -----AAAAAAA----- ------ADAAA------ ----------------- ----------------- ----------------- ----------------- ----------------- ----------------- ----------------- ----------------- ----------------- ----------------- ----------------- ----------------- -AA-C------C--AB- ----------------- ----------------- ----------------- 
-----AA---AA----- -----AA---AA----- ------BBBAA------ --------B-------- ----------------- ----------------- ----------------- ----------------- ----------------- ----------------- ----------------- ----------------- ----------------- ----------------- ----------------- ----------------- --A--CCCCCC---B-- ----------------- ----------------- ----------------- 
------AAAAA------ ------AADAD------ --------A-------- ----------------- ----------------- ----------------- ----------------- ----------------- ----------------- ----------------- ----------------- ----------------- ----------------- ----------------- ----------------- ----------------- --BAB-------ADA-- ----------------- ----------------- ----------------- 
----------------- ----------------- ----------------- ----------------- ----------------- ----------------- ----------------- ----------------- ----------------- ----------------- ----------------- ----------------- ----------------- ----------------- ----------------- ----------------- ----ADA---BBB---- ----------------- ----------------- ----------------- 
----------------- ----------------- ----------------- ----------------- ----------------- ----------------- ----------------- ----------------- ----------------- ----------------- ----------------- ----------------- ----------------- ----------------- ----------------- ----------------- ------ADBAB------ ----------------- ----------------- ----------------- 
