model
size = 32 11 32, scale = 0.05, origin = -y
material 
  colors = A:#2A2A2A B:#1F1F1F
voxels
77-6A315-4A24-12A308-12A18-5A6-5A304-16A15-3A12-3A277-4A21-12AB5A12-3A5-6B5-3A18-6B27-4B28-4B185-10A17-20A10-3A3-3B6A3B3-3A14-12B21-10B22-10B23-4(8A24-)8A21-3A8-3A14-9A4-9A9-2A3-B4A4-4AB3-2A13-2(5B4-5B18-)5B4-5B19-3(4A4-4A20-)12A20-2A8-2A18-2(2A12-)7A10-7A7-2A3-B2A10-2AB3-2A11-3(3B10-3B16-)2(3A10-3A16-)3A10-3A17-14A18-A12-A16-2A14-2A10-6A14-6A5-2A3-BA14-AB3-2A9-6(2B14-)5(2A14-)2A15-16A16-2(A14-)2A16-2A9-5A16-5A5-2A2-BA16-AB2-2A8-2(2B16-2B12-)2B16-2B13-3(A16-A14-)18A14-A16-A13-A18-A8-6A16-6A3-2A2-B2A16-2AB2-2A6-3B16-3B11-2(2B16-2B12-)3(2A16-2A12-)20A12-A18-A11-2A18-2A7-5A18-5A3-2A2-BA18-AB2-2A6-2(2B18-2B10-)2B18-2B11-3(A18-A12-)20A12-A18-A11-A20-A7-5A18-5A3-2A2-BA18-AB2-2A6-B20-B2(10-2B18-2B)3(10-2A18-2A)10-22A2(10-A20-A)7-4A20-4A2-2A2-BA20-AB2-2A4-2B20-2B9-2(B20-B10-)4(3(A20-A10-)22A10-A20-A9-2A20-2A5-5A20-5A-2A2-BA20-AB2-2A4-2(2B20-2B8-)2B20-2B9-)3(A20-A10-)22A2(10-A20-A)7-4A20-4A2-2A2-BA20-AB2-2A4-2B20-2B9-2(B20-B10-)3(A20-A10-)22A2(10-A20-A)7-5A18-5A3-2A2-BA18-AB2-2A6-B20-B2(10-2B18-2B)3(10-2A18-2A)10-22A10-A20-A10-2A18-2A7-5A18-5A3-2A2-BA18-AB2-2A6-2(2B18-2B10-)2B18-2B11-3(A18-A12-)20A2(12-A18-A)8-6A16-6A3-2A2-B2A16-2AB2-2A6-3B16-3B11-2(2B16-2B12-)3(2A16-2A12-)20A12-A18-A12-2A16-2A9-5A16-5A5-2A2-BA16-AB2-2A8-2(2B16-2B12-)2B16-2B13-3(A16-A14-)18A14-A16-A2(14-2A)10-6A14-6A5-2A3-BA14-AB3-2A9-6(2B14-)5(2A14-)2A15-16A16-A14-A16-2(2A12-)7A10-7A7-2A3-B2A10-2AB3-2A11-3(3B10-3B16-)2(3A10-3A16-)3A10-3A17-14A18-A12-A18-3A8-3A14-9A4-9A9-2A3-B4A4-4AB3-2A13-2(5B4-5B18-)5B4-5B19-3(4A4-4A20-)12A20-2A8-2A21-10A17-20A10-3A3-3B6A3B3-3A14-12B21-10B22-10B23-4(8A24-)8A26-4A21-18A12-3A5-6B5-3A18-6B27-4B28-4B214-16A15-3A12-3A305-12A18-5A6-5A310-4A24-12A343-6A269-
