model
size = 25 8 30, scale = 0.05, origin = -y
material 
  colors = A:#0F0F0F B:#1F1F1F C:#1A1A1A D:#191919 E:#141414 F:#1E1E1E
voxels
------------------------- A------------------------ -A----------------------- -A----------------------- --A---------------------- --A---------------------- ---AAACCCCCCCCCCCCCCCCCCB ------------------------- 
------------------------- ------------------------B ------------------------B ------------------------B ------------------------B ------------------------B ------------------------B ------------------------- 
------------------------B ------------------------B ------------------------A ------------------------A ------------------------A ------------------------A ------------------------A ------------------------B 
------------------------B ------------------------A ------------------------A ------------------------A ------------------------A ------------------------A ------------------------A ------------------------B 
------------------------B ------------------------A ------------------------A ------------------------A ------------------------A ------------------------D ------------------------D ------------------------B 
------------------------B ------------------------A ------------------------A ------------------------F ------------------------D ------------------------A ------------------------A ------------------------B 
------------------------B ------------------------E ------------------------D ------------------------D ------------------------A ------------------------A ------------------------A ------------------------B 
------------------------B ------------------------E ------------------------A ------------------------A ------------------------A ------------------------E ------------------------F ------------------------B 
------------------------B ------------------------A ------------------------A ------------------------E ------------------------F ------------------------D ------------------------A ------------------------B 
------------------------B ------------------------A ------------------------A ------------------------F ------------------------E ------------------------A ------------------------A ------------------------B 
------------------------B ------------------------A ------------------------D ------------------------A ------------------------A ------------------------A ------------------------A ------------------------B 
------------------------- ------------------------B ------------------------A ------------------------A ------------------------A ------------------------A ------------------------A ------------------------B 
------------------------- ------------------------B ------------------------B ------------------------B ------------------------A ------------------------A ------------------------B ------------------------B 
------------------------- ------------------------- ------------------------- ------------------------- ------------------------B ------------------------B ------------------------B ------------------------- 
------------------------- ------------------------- ------------------------- ------------------------- ------------------------- ------------------------B ------------------------B ------------------------- 
------------------------- ------------------------- ------------------------- ------------------------- ------------------------- ------------------------B ------------------------B ------------------------- 
------------------------- ------------------------- ------------------------- ------------------------- ------------------------B ------------------------B ------------------------B ------------------------- 
------------------------- ------------------------B ------------------------B ------------------------B ------------------------A ------------------------A ------------------------B ------------------------B 
------------------------B ------------------------A ------------------------A ------------------------A ------------------------A ------------------------A ------------------------A ------------------------B 
------------------------B ------------------------A ------------------------A ------------------------A ------------------------A ------------------------A ------------------------A ------------------------B 
------------------------B ------------------------A ------------------------A ------------------------A ------------------------A ------------------------D ------------------------D ------------------------B 
------------------------B ------------------------A ------------------------A ------------------------F ------------------------D ------------------------A ------------------------A ------------------------B 
------------------------B ------------------------E ------------------------D ------------------------D ------------------------A ------------------------A ------------------------A ------------------------B 
------------------------B ------------------------E ------------------------A ------------------------A ------------------------A ------------------------E ------------------------F ------------------------B 
------------------------B ------------------------A ------------------------A ------------------------E ------------------------F ------------------------D ------------------------A ------------------------B 
------------------------B ------------------------A ------------------------A ------------------------F ------------------------E ------------------------A ------------------------A ------------------------B 
------------------------B ------------------------A ------------------------D ------------------------A ------------------------A ------------------------A ------------------------A ------------------------B 
------------------------B ------------------------B ------------------------A ------------------------A ------------------------A ------------------------A ------------------------A ------------------------B 
------------------------- ------------------------B ------------------------B ------------------------B ------------------------B ------------------------B ------------------------B ------------------------- 
------------------------- A------------------------ -A----------------------- -A----------------------- --A---------------------- --A---------------------- ---AAACCCCCCCCCCCCCCCCCCB ------------------------- 
