model
size = 26 30 26, scale = 0.05, origin = -y
material 
  colors = A:#565656 B:#1352F1 C:#7F7F7F D:#FE3C00 E:#A35803 F:#B67831
voxels
----------AAAAAA---------- ----------AAAAAA---------- ----------AAAAAA---------- ----------AAAAAA---------- ----------AAAAAA---------- ----------AAAAAA---------- -------------------------- -------------------------- -------------------------- -------------------------- -------------------------- -------------------------- -------------------------- -------------------------- -------------------------- -------------------------- -------------------------- -------------------------- -------------------------- -------------------------- -------------------------- -------------------------- -------------------------- -------------------------- -------------------------- -------------------------- -------------------------- -------------------------- -------------------------- -------------------------- 
-------AAAAAAAAAAAA------- -------AAAAAAAAAAAA------- -------AAAAAAAAAAAA------- -------AAAAAAAAAAAA------- -------AAAAAAAAAAAA------- -------AAAAAAAAAAAA------- -----------CCCC----------- -----------CCCC----------- -----------CCCC----------- -------------------------- -------------------------- -------------------------- -------------------------- -------------------------- -------------------------- -------------------------- -------------------------- -------------------------- -------------------------- -------------------------- -------------------------- -------------------------- -------------------------- -------------------------- -------------------------- -------------------------- -------------------------- -------------------------- -------------------------- -------------------------- 
------AAAA------AAAA------ ------AAAA------AAAA------ ------AAAA------AAAA------ ------AAAA------AAAA------ ------AAAA------AAAA------ ------AAAA------AAAA------ --------CCC----CCC-------- --------CCC----CCC-------- --------CCC----CCC-------- --------CCCCCCCCCC-------- ---------CCCCCCCC--------- -----------BBBB----------- -----------BBBB----------- -----------BBBB----------- -------------------------- -------------------------- -------------------------- -------------------------- -------------------------- -------------------------- -------------------------- -------------------------- -------------------------- -------------------------- -------------------------- -------------------------- -------------------------- -------------------------- -------------------------- -------------------------- 
-----AA------------AA----- -----AA------------AA----- -----EA------------AA----- -----AA------------AA----- -----AA------------AA----- -----AAA----------AAA----- ------CC----------CC------ ------CC----------CC------ ------CC----------CC------ -------CC--------CC------- -------CCC------CCC------- --------BBBB--BBBB-------- --------BBBB--BBBB-------- --------BBBB--BBBB-------- ----------BBBBBB---------- -------------------------- -------------------------- -------------------------- -------------------------- -------------------------- -------------------------- -------------------------- -------------------------- -------------------------- -------------------------- -------------------------- -------------------------- -------------------------- -------------------------- -------------------------- 
----AA--------------AA---- ----AA--------------AA---- ----EA--------------AA---- ----AA--------------AA---- ----AA--------------AA---- ----AA--------------AA---- -----C--------------C----- -----C--------------C----- -----C--------------C----- -----CC------------CC----- ------CC----------CC------ -------BB--------BB------- -------BB--------BB------- -------BB--------BB------- --------BB------BB-------- ---------BBBBBBBB--------- ---------BBBBBBBB--------- -------------------------- -------------------------- -------------------------- -------------------------- -------------------------- -------------------------- -------------------------- -------------------------- -------------------------- -------------------------- -------------------------- -------------------------- -------------------------- 
---AA----------------AA--- ---AA----------------AA--- ---EA----------------AA--- ---AA----------------AA--- ---AA----------------AA--- ---AA----------------AA--- ----C----------------C---- ----C----------------C---- ----C----------------C---- ----CC--------------CC---- -----C--------------C----- -----BB------------BB----- -----BB------------BB----- -----BB------------BB----- ------BB----------BB------ -------BBB------BBB------- --------BBBBBBBBBBB------- ---------DDDDDDDD--------- -------------------------- -------------------------- -------------------------- -------------------------- -------------------------- -------------------------- -------------------------- -------------------------- -------------------------- -------------------------- -------------------------- -------------------------- 
--AA------------------AA-- --AA------------------AA-- --AA------------------AA-- --AA------------------AA-- --AA------------------AA-- --AA------------------AA-- ---C------------------C--- ---C------------------C--- ---C------------------C--- ----C----------------C---- ----C----------------C---- -----B--------------B----- -----B--------------B----- -----B--------------B----- -----BB------------BB----- ------BB----------BB------ -------BBB------BBBB------ --------DD------DD-------- ----------DDDDDD---------- ----------DDDDDD---------- -------------------------- -------------------------- -------------------------- -------------------------- -------------------------- -------------------------- -------------------------- -------------------------- -------------------------- -------------------------- 
-AA--------------------AA- -AA--------------------AA- -AA--------------------AA- -AA--------------------AA- -AA--------------------AA- -AAA------------------AAA- ---C------------------C--- ---C------------------C--- ---C------------------C--- ---C------------------C--- ---CC----------------CC--- ----B----------------B---- ----B----------------B---- ----B----------------B---- -----B--------------B----- -----BB------------BB----- ------BBB--------BBBB----- -------DD--------DD------- --------DDDD--DDDD-------- --------DDDD--DDDD-------- -----------DDDD----------- -------------------------- -------------------------- -------------------------- -------------------------- -------------------------- -------------------------- -------------------------- -------------------------- -------------------------- 
-AA--------------------AA- -AA--------------------AA- -AA--------------------AA- -AA--------------------AA- -AA--------------------AA- -AA--------------------AA- --C--------------------C-- --C--------------------C-- --C--------------------C-- --CC------------------CC-- ---C------------------C--- ---BB----------------BB--- ---BB----------------BB--- ---BB----------------BB--- ----B----------------B---- -----B--------------B----- -----BBB----------BBB----- ------DD----------DD------ -------DDD------DDD------- -------DDD------DDD------- ---------DDDDDDDD--------- -------------------------- -------------------------- -----------CACA----------- -----------AAAA----------- -----------AACA----------- -----------AAAA----------- -------------------------- -------------------------- -------------------------- 
-AA--------------------AA- -AA--------------------AA- -AA--------------------AA- -AA--------------------AA- -AA--------------------AA- -AA--------------------AA- --C--------------------C-- --C--------------------C-- --C--------------------C-- --C--------------------C-- --CC------------------CC-- ---B------------------B--- ---B------------------B--- ---B------------------B--- ----B----------------B---- ----BB--------------BB---- ----BBB------------BBB---- -----DD------------DD----- -------DD--------DD------- -------DD--------DD------- --------DDDDDDDDDD-------- ------------CA------------ ----------AAAAAC---------- ----------AAAAAA---------- ---------AAAAAAAA--------- ---------CAAAAACA--------- ----------AAAAAA---------- ----------CAACAA---------- ------------AA------------ -------------------------- 
AA----------------------AA AA----------------------AA AA---------------------EAA AA---------------------EAA AA---------------------EAA AA----------------------AA --C--------------------C-- --C--------------------C-- --C--------------------C-- --C--------------------C-- --C--------------------C-- ---B------------------B--- ---B------------------B--- ---B------------------B--- ---B------------------B--- ----B----------------B---- ----BB--------------BB---- -----D--------------D----- ------DD----------DD------ ------DD----------DD------ --------DDD----DDD-------- ----------AAAAAA---------- ---------CAAAAAAA--------- ---------AAAAAAAA--------- ---------AAAAAAAA--------- ---------AAAAAAAC--------- ---------AAAAAAAA--------- ---------AAAAAAAA--------- ----------AAAAAA---------- -------------------------- 
AA----------------------AA AA----------------------AA AA---------------------EAA AA---------------------FAA AA---------------------EAA AA----------------------AA -C----------------------C- -C----------------------C- -C----------------------C- --C--------------------C-- --C--------------------C-- --BB------------------BB-- --BB------------------BB-- --BB------------------BB-- ---B------------------B--- ----B----------------B---- ----BB--------------BB---- -----D--------------D----- ------DD----------DD------ ------DD----------DD------ -------DDD------DDD------- ----------AAAAAA---------- ---------AAAAAAAA--------- --------AAAAAAAAAA-------- --------CAAAAAAAAA-------- --------AAAAAAAAAA-------- --------AAAAAAAAAA-------- ---------AAAAAAAC--------- ----------CAAAAA---------- -----------AAAC----------- 
AA----------------------AA AA----------------------AA AA---------------------EAA AA---------------------FAA AA---------------------EAA AA----------------------AA -C----------------------C- -C----------------------C- -C----------------------C- --C--------------------C-- --C--------------------C-- --B--------------------B-- --B--------------------B-- --B--------------------B-- ---B------------------B--- ----B----------------B---- ----BB--------------BB---- -----D--------------D----- ------D------------D------ ------D------------D------ -------DDD------DDD------- ---------AAACCAAA--------- ---------AAAAAAAC--------- --------AAAAAAAAAA-------- --------AAAAAAAAAC-------- --------AAAAAAAAAA-------- --------CAAAAAAAAA-------- ---------AAAAAAAA--------- ---------AAAAAAAA--------- -----------ACAA----------- 
AA----------------------AA AA----------------------AA AA---------------------EAA AA---------------------FAA AA---------------------EAA AA----------------------AA -C----------------------C- -C----------------------C- -C----------------------C- --C--------------------C-- --C--------------------C-- --B--------------------B-- --B--------------------B-- --B--------------------B-- ---B------------------B--- ----B----------------B---- ----BB--------------BB---- -----D--------------D----- ------D------------D------ ------D------------D------ -------DDD------DDD------- ---------AAACCAAA--------- ---------CAAAAAAA--------- --------AAAAAAAAAA-------- --------AAAAAAAAAA-------- --------AAAAAAAAAA-------- --------AAAAAAAAAA-------- ---------AAAAAAAA--------- ---------CAAAAAAC--------- -----------AAAA----------- 
AA----------------------AA AA----------------------AA AA---------------------EAA AA---------------------FAA AA---------------------EAA AA----------------------AA -C----------------------C- -C----------------------C- -C----------------------C- --C--------------------C-- --C--------------------C-- --BB------------------BB-- --BB------------------BB-- --BB------------------BB-- ---B------------------B--- ----B----------------B---- ----BB--------------BB---- -----D--------------D----- ------DD----------DD------ ------DD----------DD------ -------DDD------DDD------- ----------AAAAAA---------- ---------AAAAAAAA--------- --------AAAAAAAAAC-------- --------AAAAAAAAAA-------- --------CAAAAAAAAA-------- --------AAAAAAAAAC-------- ---------AAAAAAAA--------- ----------AAAAAA---------- -----------AACA----------- 
AA----------------------AA AA----------------------AA AA---------------------EAA AA---------------------EAA AA---------------------EAA AA----------------------AA --C--------------------C-- --C--------------------C-- --C--------------------C-- --C--------------------C-- --C--------------------C-- ---B------------------B--- ---B------------------B--- ---B------------------B--- ---B------------------B--- ----B----------------B---- ----BB--------------BB---- -----D--------------D----- ------DD----------DD------ ------DD----------DD------ --------DDD----DDD-------- ----------CAAAAC---------- ---------AAAAAAAA--------- ---------CAAAAAAA--------- ---------AAAAAAAC--------- ---------AAAAAAAA--------- ---------CAAAAAAA--------- ---------AAAAAAAA--------- ----------AAAAAA---------- -------------------------- 
-AA--------------------AA- -AA--------------------AA- -AA--------------------AA- -AA--------------------AA- -AA--------------------AA- -AA--------------------AA- --C--------------------C-- --C--------------------C-- --C--------------------C-- --C--------------------C-- --CC------------------CC-- ---B------------------B--- ---B------------------B--- ---B------------------B--- ----B----------------B---- ----BB--------------BB---- ----BBB------------BBB---- -----DD------------DD----- -------DD--------DD------- -------DD--------DD------- --------DDDDDDDDDD-------- ------------AA------------ ----------ACAAAA---------- ----------AAAAAC---------- ---------AAAAAAAA--------- ---------AAAAAAAA--------- ----------AAAAAC---------- ----------AAAAAA---------- ------------AC------------ -------------------------- 
-AA--------------------AA- -AA--------------------AA- -AA--------------------AA- -AA--------------------AA- -AA--------------------AA- -AA--------------------AA- --C--------------------C-- --C--------------------C-- --C--------------------C-- --CC------------------CC-- ---C------------------C--- ---BB----------------BB--- ---BB----------------BB--- ---BB----------------BB--- ----B----------------B---- -----B--------------B----- -----BBB----------BBB----- ------DD----------DD------ -------DDD------DDD------- -------DDD------DDD------- ---------DDDDDDDD--------- -------------------------- -------------------------- -----------AACA----------- -----------AAAA----------- -----------CAAA----------- -----------AACA----------- -------------------------- -------------------------- -------------------------- 
-AA--------------------AA- -AA--------------------AA- -AA--------------------AA- -AA--------------------AA- -AA--------------------AA- -AAA------------------AAA- ---C------------------C--- ---C------------------C--- ---C------------------C--- ---C------------------C--- ---CC----------------CC--- ----B----------------B---- ----B----------------B---- ----B----------------B---- -----B--------------B----- -----BB------------BB----- ------BBB--------BBBB----- -------DD--------DD------- --------DDDD--DDDD-------- --------DDDD--DDDD-------- -----------DDDD----------- -------------------------- -------------------------- -------------------------- -------------------------- -------------------------- -------------------------- -------------------------- -------------------------- -------------------------- 
--AA------------------AA-- --AA------------------AA-- --AA------------------AA-- --AA------------------AA-- --AA------------------AA-- --AA------------------AA-- ---C------------------C--- ---C------------------C--- ---C------------------C--- ----C----------------C---- ----C----------------C---- -----B--------------B----- -----B--------------B----- -----B--------------B----- -----BB------------BB----- ------BB----------BB------ -------BBB------BBBB------ --------DD------DD-------- ----------DDDDDD---------- ----------DDDDDD---------- -------------------------- -------------------------- -------------------------- -------------------------- -------------------------- -------------------------- -------------------------- -------------------------- -------------------------- -------------------------- 
---AA----------------AA--- ---AA----------------AA--- ---AA----------------AA--- ---AA----------------AA--- ---AA----------------AA--- ---AA----------------AA--- ----C----------------C---- ----C----------------C---- ----C----------------C---- ----CC--------------CC---- -----C--------------C----- -----BB------------BB----- -----BB------------BB----- -----BB------------BB----- ------BB----------BB------ -------BBB------BBB------- --------BBBBBBBBBBB------- ---------DDDDDDDD--------- -------------------------- -------------------------- -------------------------- -------------------------- -------------------------- -------------------------- -------------------------- -------------------------- -------------------------- -------------------------- -------------------------- -------------------------- 
----AA--------------AA---- ----AA--------------AA---- ----AA--------------AA---- ----AA--------------AA---- ----AA--------------AA---- ----AA--------------AA---- -----C--------------C----- -----C--------------C----- -----C--------------C----- -----CC------------CC----- ------CC----------CC------ -------BB--------BB------- -------BB--------BB------- -------BB--------BB------- --------BB------BB-------- ---------BBBBBBBB--------- ---------BBBBBBBB--------- -------------------------- -------------------------- -------------------------- -------------------------- -------------------------- -------------------------- -------------------------- -------------------------- -------------------------- -------------------------- -------------------------- -------------------------- -------------------------- 
-----AA------------AA----- -----AA------------AA----- -----AA------------AA----- -----AA------------AA----- -----AA------------AA----- -----AAA----------AAA----- ------CC----------CC------ ------CC----------CC------ ------CC----------CC------ -------CC--------CC------- -------CCC------CCC------- --------BBBB--BBBB-------- --------BBBB--BBBB-------- --------BBBB--BBBB-------- ----------BBBBBB---------- -------------------------- -------------------------- -------------------------- -------------------------- -------------------------- -------------------------- -------------------------- -------------------------- -------------------------- -------------------------- -------------------------- -------------------------- -------------------------- -------------------------- -------------------------- 
------AAAA------AAAA------ ------AAAA------AAAA------ ------AAAA------AAAA------ ------AAAA------AAAA------ ------AAAA------AAAA------ ------AAAA------AAAA------ --------CCC----CCC-------- --------CCC----CCC-------- --------CCC----CCC-------- --------CCCCCCCCCC-------- ---------CCCCCCCC--------- -----------BBBB----------- -----------BBBB----------- -----------BBBB----------- -------------------------- -------------------------- -------------------------- -------------------------- -------------------------- -------------------------- -------------------------- -------------------------- -------------------------- -------------------------- -------------------------- -------------------------- -------------------------- -------------------------- -------------------------- -------------------------- 
-------AAAAAAAAAAAA------- -------AAAAAAAAAAAA------- -------AAAAAAAAAAAA------- -------AAAAAAAAAAAA------- -------AAAAAAAAAAAA------- -------AAAAAAAAAAAA------- -----------CCCC----------- -----------CCCC----------- -----------CCCC----------- -------------------------- -------------------------- -------------------------- -------------------------- -------------------------- -------------------------- -------------------------- -------------------------- -------------------------- -------------------------- -------------------------- -------------------------- -------------------------- -------------------------- -------------------------- -------------------------- -------------------------- -------------------------- -------------------------- -------------------------- -------------------------- 
----------AAAAAA---------- ----------AAAAAA---------- ----------AAAAAA---------- ----------AAAAAA---------- ----------AAAAAA---------- ----------AAAAAA---------- -------------------------- -------------------------- -------------------------- -------------------------- -------------------------- -------------------------- -------------------------- -------------------------- -------------------------- -------------------------- -------------------------- -------------------------- -------------------------- -------------------------- -------------------------- -------------------------- -------------------------- -------------------------- -------------------------- -------------------------- -------------------------- -------------------------- -------------------------- -------------------------- 
