model
size = 26 30 26, scale = 0.05, origin = -y
material 
  colors = A:#000 B:#FC0 C:#F50000 D:#007F1B E:#A35803 F:#B67831
voxels
----------AAAAAA---------- ----------AAAAAA---------- ----------AAAAAA---------- ----------AAAAAA---------- ----------AAAAAA---------- ----------AAAAAA---------- -------------------------- -------------------------- -------------------------- -------------------------- -------------------------- -------------------------- -------------------------- -------------------------- -------------------------- -------------------------- -------------------------- -------------------------- -------------------------- -------------------------- -------------------------- -------------------------- -------------------------- -------------------------- -------------------------- -------------------------- -------------------------- -------------------------- -------------------------- -------------------------- 
-------AAAAAAAAAAAA------- -------AAAAAAAAAAAA------- -------AAAAAAAAAAAA------- -------AAAAAAAAAAAA------- -------AAAAAAAAAAAA------- -------AAAAAAAAAAAA------- -----------CCCC----------- -----------CCCC----------- -----------CCCC----------- -------------------------- -------------------------- -------------------------- -------------------------- -------------------------- -------------------------- -------------------------- -------------------------- -------------------------- -------------------------- -------------------------- -------------------------- -------------------------- -------------------------- -------------------------- -------------------------- -------------------------- -------------------------- -------------------------- -------------------------- -------------------------- 
------AAAA------AAAA------ ------AAAA------AAAA------ ------AAAA------AAAA------ ------AAAA------AAAA------ ------AAAA------AAAA------ ------AAAA------AAAA------ --------CCC----CCC-------- --------CCC----CCC-------- --------CCC----CCC-------- --------CCCCCCCCCC-------- ---------CCCCCCCC--------- -----------BBBB----------- -----------BBBB----------- -----------BBBB----------- -------------------------- -------------------------- -------------------------- -------------------------- -------------------------- -------------------------- -------------------------- -------------------------- -------------------------- -------------------------- -------------------------- -------------------------- -------------------------- -------------------------- -------------------------- -------------------------- 
-----AA------------AA----- -----AA------------AA----- -----EA------------AA----- -----AA------------AA----- -----AA------------AA----- -----AAA----------AAA----- ------CC----------CC------ ------CC----------CC------ ------CC----------CC------ -------CC--------CC------- -------CCC------CCC------- --------BBBB--BBBB-------- --------BBBB--BBBB-------- --------BBBB--BBBB-------- ----------BBBBBB---------- -------------------------- -------------------------- -------------------------- -------------------------- -------------------------- -------------------------- -------------------------- -------------------------- -------------------------- -------------------------- -------------------------- -------------------------- -------------------------- -------------------------- -------------------------- 
----AA--------------AA---- ----AA--------------AA---- ----EA--------------AA---- ----AA--------------AA---- ----AA--------------AA---- ----AA--------------AA---- -----C--------------C----- -----C--------------C----- -----C--------------C----- -----CC------------CC----- ------CC----------CC------ -------BB--------BB------- -------BB--------BB------- -------BB--------BB------- --------BB------BB-------- ---------BBBBBBBB--------- ---------BBBBBBBB--------- -------------------------- -------------------------- -------------------------- -------------------------- -------------------------- -------------------------- -------------------------- -------------------------- -------------------------- -------------------------- -------------------------- -------------------------- -------------------------- 
---AA----------------AA--- ---AA----------------AA--- ---EA----------------AA--- ---AA----------------AA--- ---AA----------------AA--- ---AA----------------AA--- ----C----------------C---- ----C----------------C---- ----C----------------C---- ----CC--------------CC---- -----C--------------C----- -----BB------------BB----- -----BB------------BB----- -----BB------------BB----- ------BB----------BB------ -------BBB------BBB------- --------BBBBBBBBBBB------- ---------DDDDDDDD--------- -------------------------- -------------------------- -------------------------- -------------------------- -------------------------- -------------------------- -------------------------- -------------------------- -------------------------- -------------------------- -------------------------- -------------------------- 
--AA------------------AA-- --AA------------------AA-- --AA------------------AA-- --AA------------------AA-- --AA------------------AA-- --AA------------------AA-- ---C------------------C--- ---C------------------C--- ---C------------------C--- ----C----------------C---- ----C----------------C---- -----B--------------B----- -----B--------------B----- -----B--------------B----- -----BB------------BB----- ------BB----------BB------ -------BBB------BBBB------ --------DD------DD-------- ----------DDDDDD---------- ----------DDDDDD---------- -------------------------- -------------------------- -------------------------- -------------------------- -------------------------- -------------------------- -------------------------- -------------------------- -------------------------- -------------------------- 
-AA--------------------AA- -AA--------------------AA- -AA--------------------AA- -AA--------------------AA- -AA--------------------AA- -AAA------------------AAA- ---C------------------C--- ---C------------------C--- ---C------------------C--- ---C------------------C--- ---CC----------------CC--- ----B----------------B---- ----B----------------B---- ----B----------------B---- -----B--------------B----- -----BB------------BB----- ------BBB--------BBBB----- -------DD--------DD------- --------DDDD--DDDD-------- --------DDDD--DDDD-------- -----------DDDD----------- -------------------------- -------------------------- -------------------------- -------------------------- -------------------------- -------------------------- -------------------------- -------------------------- -------------------------- 
-AA--------------------AA- -AA--------------------AA- -AA--------------------AA- -AA--------------------AA- -AA--------------------AA- -AA--------------------AA- --C--------------------C-- --C--------------------C-- --C--------------------C-- --CC------------------CC-- ---C------------------C--- ---BB----------------BB--- ---BB----------------BB--- ---BB----------------BB--- ----B----------------B---- -----B--------------B----- -----BBB----------BBB----- ------DD----------DD------ -------DDD------DDD------- -------DDD------DDD------- ---------DDDDDDDD--------- -------------------------- -------------------------- -----------CBCB----------- -----------BADA----------- -----------DACB----------- -----------BDAD----------- -------------------------- -------------------------- -------------------------- 
-AA--------------------AA- -AA--------------------AA- -AA--------------------AA- -AA--------------------AA- -AA--------------------AA- -AA--------------------AA- --C--------------------C-- --C--------------------C-- --C--------------------C-- --C--------------------C-- --CC------------------CC-- ---B------------------B--- ---B------------------B--- ---B------------------B--- ----B----------------B---- ----BB--------------BB---- ----BBB------------BBB---- -----DD------------DD----- -------DD--------DD------- -------DD--------DD------- --------DDDDDDDDDD-------- ------------CD------------ ----------DAABAC---------- ----------DAAAAD---------- ---------BAAAAAAB--------- ---------CAAAAADA--------- ----------DAAAAB---------- ----------CADCBC---------- ------------BA------------ -------------------------- 
AA----------------------AA AA----------------------AA AA---------------------EAA AA---------------------EAA AA---------------------EAA AA----------------------AA --C--------------------C-- --C--------------------C-- --C--------------------C-- --C--------------------C-- --C--------------------C-- ---B------------------B--- ---B------------------B--- ---B------------------B--- ---B------------------B--- ----B----------------B---- ----BB--------------BB---- -----D--------------D----- ------DD----------DD------ ------DD----------DD------ --------DDD----DDD-------- ----------BDAAAB---------- ---------CAAAAAAD--------- ---------BAAAAAAA--------- ---------AAAAAAAB--------- ---------BAAAAAAC--------- ---------DAAAAAAB--------- ---------AAAAAAAD--------- ----------BDABDA---------- -------------------------- 
AA----------------------AA AA----------------------AA AA---------------------EAA AA---------------------FAA AA---------------------EAA AA----------------------AA -C----------------------C- -C----------------------C- -C----------------------C- --C--------------------C-- --C--------------------C-- --BB------------------BB-- --BB------------------BB-- --BB------------------BB-- ---B------------------B--- ----B----------------B---- ----BB--------------BB---- -----D--------------D----- ------DD----------DD------ ------DD----------DD------ -------DDD-BDAC-DDD------- ----------AAAAAD---------- ---------BAAAAAAA--------- --------AAAAAAAAAC-------- --------CAAAAAAAAD-------- --------AAAAAAAAAB-------- --------DAAAAAAAAA-------- ---------BAAAAAAC--------- ----------CAAAAD---------- -----------ADAC----------- 
AA----------------------AA AA----------------------AA AA---------------------EAA AA---------------------FAA AA---------------------EAA AA----------------------AA -C----------------------C- -C----------------------C- -C----------------------C- --C--------------------C-- --C--------------------C-- --B--------------------B-- --B--------------------B-- --B--------------------B-- ---B------------------B--- ----B----------------B---- ----BB--------------BB---- -----D--------------D----- ------D------------D------ ------D------------D------ -------DDD-ACCA-DDD------- ---------DAACCAAB--------- ---------AAAAAAAC--------- --------DAAAAAAAAD-------- --------AAAAAAAAAC-------- --------DAAAAAAAAA-------- --------CAAAAAAAAD-------- ---------DAAAAAAD--------- ---------ADAAAAAB--------- -----------BCDB----------- 
AA----------------------AA AA----------------------AA AA---------------------EAA AA---------------------FAA AA---------------------EAA AA----------------------AA -C----------------------C- -C----------------------C- -C----------------------C- --C--------------------C-- --C--------------------C-- --B--------------------B-- --B--------------------B-- --B--------------------B-- ---B------------------B--- ----B----------------B---- ----BB--------------BB---- -----D--------------D----- ------D------------D------ ------D------------D------ -------DDD-CCCD-DDD------- ---------BDACCAAD--------- ---------CAAAAAAA--------- --------AAAAAAAAAB-------- --------BAAAAAAAAD-------- --------AAAAAAAAAC-------- --------BAAAAAAAAB-------- ---------AAAAAAAA--------- ---------CAAAAABC--------- -----------DBAD----------- 
AA----------------------AA AA----------------------AA AA---------------------EAA AA---------------------FAA AA---------------------EAA AA----------------------AA -C----------------------C- -C----------------------C- -C----------------------C- --C--------------------C-- --C--------------------C-- --BB------------------BB-- --BB------------------BB-- --BB------------------BB-- ---B------------------B--- ----B----------------B---- ----BB--------------BB---- -----D--------------D----- ------DD----------DD------ ------DD----------DD------ -------DDD-DCAB-DDD------- ----------AAAAAA---------- ---------AAAAAAAB--------- --------DAAAAAAAAC-------- --------AAAAAAAAAA-------- --------CAAAAAAAAD-------- --------DAAAAAAAAC-------- ---------AAAAAAAD--------- ----------DAAAAA---------- -----------ADCB----------- 
AA----------------------AA AA----------------------AA AA---------------------EAA AA---------------------EAA AA---------------------EAA AA----------------------AA --C--------------------C-- --C--------------------C-- --C--------------------C-- --C--------------------C-- --C--------------------C-- ---B------------------B--- ---B------------------B--- ---B------------------B--- ---B------------------B--- ----B----------------B---- ----BB--------------BB---- -----D--------------D----- ------DD----------DD------ ------DD----------DD------ --------DDD----DDD-------- ----------CBDADC---------- ---------BAAAAAAA--------- ---------CAAAAAAB--------- ---------DAAAAAAC--------- ---------AAAAAAAA--------- ---------CAAAAAAD--------- ---------DAAAAAAA--------- ----------BCADCD---------- -------------------------- 
-AA--------------------AA- -AA--------------------AA- -AA--------------------AA- -AA--------------------AA- -AA--------------------AA- -AA--------------------AA- --C--------------------C-- --C--------------------C-- --C--------------------C-- --C--------------------C-- --CC------------------CC-- ---B------------------B--- ---B------------------B--- ---B------------------B--- ----B----------------B---- ----BB--------------BB---- ----BBB------------BBB---- -----DD------------DD----- -------DD--------DD------- -------DD--------DD------- --------DDDDDDDDDD-------- ------------AD------------ ----------ACBAAB---------- ----------DAAAAC---------- ---------ABAAAADA--------- ---------DAAAAAAB--------- ----------BAAAAC---------- ----------DADBAB---------- ------------BC------------ -------------------------- 
-AA--------------------AA- -AA--------------------AA- -AA--------------------AA- -AA--------------------AA- -AA--------------------AA- -AA--------------------AA- --C--------------------C-- --C--------------------C-- --C--------------------C-- --CC------------------CC-- ---C------------------C--- ---BB----------------BB--- ---BB----------------BB--- ---BB----------------BB--- ----B----------------B---- -----B--------------B----- -----BBB----------BBB----- ------DD----------DD------ -------DDD------DDD------- -------DDD------DDD------- ---------DDDDDDDD--------- -------------------------- -------------------------- -----------DBCD----------- -----------ADAB----------- -----------CADA----------- -----------DBCD----------- -------------------------- -------------------------- -------------------------- 
-AA--------------------AA- -AA--------------------AA- -AA--------------------AA- -AA--------------------AA- -AA--------------------AA- -AAA------------------AAA- ---C------------------C--- ---C------------------C--- ---C------------------C--- ---C------------------C--- ---CC----------------CC--- ----B----------------B---- ----B----------------B---- ----B----------------B---- -----B--------------B----- -----BB------------BB----- ------BBB--------BBBB----- -------DD--------DD------- --------DDDD--DDDD-------- --------DDDD--DDDD-------- -----------DDDD----------- -------------------------- -------------------------- -------------------------- -------------------------- -------------------------- -------------------------- -------------------------- -------------------------- -------------------------- 
--AA------------------AA-- --AA------------------AA-- --AA------------------AA-- --AA------------------AA-- --AA------------------AA-- --AA------------------AA-- ---C------------------C--- ---C------------------C--- ---C------------------C--- ----C----------------C---- ----C----------------C---- -----B--------------B----- -----B--------------B----- -----B--------------B----- -----BB------------BB----- ------BB----------BB------ -------BBB------BBBB------ --------DD------DD-------- ----------DDDDDD---------- ----------DDDDDD---------- -------------------------- -------------------------- -------------------------- -------------------------- -------------------------- -------------------------- -------------------------- -------------------------- -------------------------- -------------------------- 
---AA----------------AA--- ---AA----------------AA--- ---AA----------------AA--- ---AA----------------AA--- ---AA----------------AA--- ---AA----------------AA--- ----C----------------C---- ----C----------------C---- ----C----------------C---- ----CC--------------CC---- -----C--------------C----- -----BB------------BB----- -----BB------------BB----- -----BB------------BB----- ------BB----------BB------ -------BBB------BBB------- --------BBBBBBBBBBB------- ---------DDDDDDDD--------- -------------------------- -------------------------- -------------------------- -------------------------- -------------------------- -------------------------- -------------------------- -------------------------- -------------------------- -------------------------- -------------------------- -------------------------- 
----AA--------------AA---- ----AA--------------AA---- ----AA--------------AA---- ----AA--------------AA---- ----AA--------------AA---- ----AA--------------AA---- -----C--------------C----- -----C--------------C----- -----C--------------C----- -----CC------------CC----- ------CC----------CC------ -------BB--------BB------- -------BB--------BB------- -------BB--------BB------- --------BB------BB-------- ---------BBBBBBBB--------- ---------BBBBBBBB--------- -------------------------- -------------------------- -------------------------- -------------------------- -------------------------- -------------------------- -------------------------- -------------------------- -------------------------- -------------------------- -------------------------- -------------------------- -------------------------- 
-----AA------------AA----- -----AA------------AA----- -----AA------------AA----- -----AA------------AA----- -----AA------------AA----- -----AAA----------AAA----- ------CC----------CC------ ------CC----------CC------ ------CC----------CC------ -------CC--------CC------- -------CCC------CCC------- --------BBBB--BBBB-------- --------BBBB--BBBB-------- --------BBBB--BBBB-------- ----------BBBBBB---------- -------------------------- -------------------------- -------------------------- -------------------------- -------------------------- -------------------------- -------------------------- -------------------------- -------------------------- -------------------------- -------------------------- -------------------------- -------------------------- -------------------------- -------------------------- 
------AAAA------AAAA------ ------AAAA------AAAA------ ------AAAA------AAAA------ ------AAAA------AAAA------ ------AAAA------AAAA------ ------AAAA------AAAA------ --------CCC----CCC-------- --------CCC----CCC-------- --------CCC----CCC-------- --------CCCCCCCCCC-------- ---------CCCCCCCC--------- -----------BBBB----------- -----------BBBB----------- -----------BBBB----------- -------------------------- -------------------------- -------------------------- -------------------------- -------------------------- -------------------------- -------------------------- -------------------------- -------------------------- -------------------------- -------------------------- -------------------------- -------------------------- -------------------------- -------------------------- -------------------------- 
-------AAAAAAAAAAAA------- -------AAAAAAAAAAAA------- -------AAAAAAAAAAAA------- -------AAAAAAAAAAAA------- -------AAAAAAAAAAAA------- -------AAAAAAAAAAAA------- -----------CCCC----------- -----------CCCC----------- -----------CCCC----------- -------------------------- -------------------------- -------------------------- -------------------------- -------------------------- -------------------------- -------------------------- -------------------------- -------------------------- -------------------------- -------------------------- -------------------------- -------------------------- -------------------------- -------------------------- -------------------------- -------------------------- -------------------------- -------------------------- -------------------------- -------------------------- 
----------AAAAAA---------- ----------AAAAAA---------- ----------AAAAAA---------- ----------AAAAAA---------- ----------AAAAAA---------- ----------AAAAAA---------- -------------------------- -------------------------- -------------------------- -------------------------- -------------------------- -------------------------- -------------------------- -------------------------- -------------------------- -------------------------- -------------------------- -------------------------- -------------------------- -------------------------- -------------------------- -------------------------- -------------------------- -------------------------- -------------------------- -------------------------- -------------------------- -------------------------- -------------------------- -------------------------- 
