model
size = 30 28 10, scale = 0.05, origin = -y
material 
  colors = A:#FFFFFB B:#111
voxels
BBBBBBBBBBBBBBBBBBBBBBBBBBBBBB AAAAAAAAAAAAAAAAAAAAAAAAAAAAAA BBBBBBBBBBBBBBBBBBBBBBBBBBBBBB AAAAAAAAAAAAAAAAAAAAAAAAAAAAAA AAAAAAAAAAAABAAAABAAAAAAAAAAAA AAAAAAAAAAAABAABBBBAAAAAAAAAAA AAAAAAAAAAAABAABABAAAAAAAAAAAA AAAAAAAAAAAABAABABAAAAAAAAAAAA AAAAAAAAAAAABAABABAAAAAAAAAAAA AAAAAAAAAAAAAAAAAAAAAAAAAAAAAA AAAAAAAAAAAAAAAAAAAAAAAAAAAAAA AAAAAAAAAAAAAAAAAAAAAAAAAAAAAA AAAAAAABAAABAABBBABAAABAAAAAAA AAAAAAABABABABAAAAABABAAAAAAAA AAAAAAABABABABAAAAAABAAAAAAAAA BAAAAAABABABABAAAAABABAAAAAAAB ABAAAAABBABBAABBBABAAABAAAAABA AABAAAAAAAAAAAAAAAAAAAAAAAABAA BAABAAAAAAAAAAAAAAAAAAAAAABAAB -BAABAAAAAAAAAAAAAAAAAAAABAAB- --BAABAAAAAAAAAAAAAAAAAABAAB-- ---BAABAAAAAAAAAAAAAAAABAAB--- ----BABAAAAAAABBAAAAAAABAB---- ----BABAAAAAAB--BAAAAAABAB---- ----BABAAAAAB----BAAAAABAB---- ----BABAAAAB------BAAAABAB---- ----BABAAAB--------BAAABAB---- ----BBBBBB----------BBBBBB---- 
B----------------------------B A----------------------------A B----------------------------B A----------------------------A A----------------------------A A----------------------------A A----------------------------A A----------------------------A A----------------------------A A----------------------------A A----------------------------A A----------------------------A A----------------------------A A----------------------------A A----------------------------A A----------------------------A B----------------------------B A----------------------------A B----------------------------B ------------------------------ ------------------------------ ------------------------------ ------------------------------ ------------------------------ ------------------------------ ------------------------------ ------------------------------ ----BABAAB----------BAABAB---- 
B----------------------------B A----------------------------A B----------------------------B A----------------------------A A----------------------------A A----------------------------A A----------------------------A A----------------------------A A----------------------------A A----------------------------A A----------------------------A A----------------------------A A----------------------------A A----------------------------A A----------------------------A A----------------------------A B----------------------------B A----------------------------A B----------------------------B ------------------------------ ------------------------------ ------------------------------ ------------------------------ ------------------------------ ------------------------------ ------------------------------ ------------------------------ ----BABAAB----------BAABAB---- 
B----------------------------B A----------------------------A B----------------------------B A----------------------------A A----------------------------A A----------------------------A A----------------------------A A----------------------------A A----------------------------A A----------------------------A A----------------------------A A----------------------------A A----------------------------A A----------------------------A A----------------------------A A----------------------------A B----------------------------B A----------------------------A B----------------------------B ------------------------------ ------------------------------ ------------------------------ ------------------------------ ------------------------------ ------------------------------ ------------------------------ ------------------------------ ----BABAAB----------BAABAB---- 
B----------------------------B A----------------------------A B----------------------------B A----------------------------A A----------------------------A A----------------------------A A----------------------------A A----------------------------A A----------------------------A A----------------------------A A----------------------------A A----------------------------A A----------------------------A A----------------------------A A----------------------------A A----------------------------A B----------------------------B A----------------------------A B----------------------------B ------------------------------ ------------------------------ ------------------------------ ------------------------------ ------------------------------ ------------------------------ ------------------------------ ------------------------------ ----BABAAB----------BAABAB---- 
B----------------------------B A----------------------------A B----------------------------B A----------------------------A A----------------------------A A----------------------------A A----------------------------A A----------------------------A A----------------------------A A----------------------------A A----------------------------A A----------------------------A A----------------------------A A----------------------------A A----------------------------A A----------------------------A B----------------------------B A----------------------------A B----------------------------B ------------------------------ ------------------------------ ------------------------------ ------------------------------ ------------------------------ ------------------------------ ------------------------------ ------------------------------ ----BABAAB----------BAABAB---- 
B----------------------------B A----------------------------A B----------------------------B A----------------------------A A----------------------------A A----------------------------A A----------------------------A A----------------------------A A----------------------------A A----------------------------A A----------------------------A A----------------------------A A----------------------------A A----------------------------A A----------------------------A A----------------------------A B----------------------------B A----------------------------A B----------------------------B ------------------------------ ------------------------------ ------------------------------ ------------------------------ ------------------------------ ------------------------------ ------------------------------ ------------------------------ ----BABAAB----------BAABAB---- 
B----------------------------B A----------------------------A B----------------------------B A----------------------------A A----------------------------A A----------------------------A A----------------------------A A----------------------------A A----------------------------A A----------------------------A A----------------------------A A----------------------------A A----------------------------A A----------------------------A A----------------------------A A----------------------------A B----------------------------B A----------------------------A B----------------------------B ------------------------------ ------------------------------ ------------------------------ ------------------------------ ------------------------------ ------------------------------ ------------------------------ ------------------------------ ----BABAAB----------BAABAB---- 
B----------------------------B A----------------------------A B----------------------------B A----------------------------A A----------------------------A A----------------------------A A----------------------------A A----------------------------A A----------------------------A A----------------------------A A----------------------------A A----------------------------A A----------------------------A A----------------------------A A----------------------------A A----------------------------A B----------------------------B A----------------------------A B----------------------------B ------------------------------ ------------------------------ ------------------------------ ------------------------------ ------------------------------ ------------------------------ ------------------------------ ------------------------------ ----BABAAB----------BAABAB---- 
BBBBBBBBBBBBBBBBBBBBBBBBBBBBBB AAAAAAAAAAAAAAAAAAAAAAAAAAAAAA BBBBBBBBBBBBBBBBBBBBBBBBBBBBBB AAAAAAAAAAAAAAAAAAAAAAAAAAAAAA AAAAAAAAAAAABAAAABAAAAAAAAAAAA AAAAAAAAAAABBBBAABAAAAAAAAAAAA AAAAAAAAAAAABABAABAAAAAAAAAAAA AAAAAAAAAAAABABAABAAAAAAAAAAAA AAAAAAAAAAAABABAABAAAAAAAAAAAA AAAAAAAAAAAAAAAAAAAAAAAAAAAAAA AAAAAAAAAAAAAAAAAAAAAAAAAAAAAA AAAAAAAAAAAAAAAAAAAAAAAAAAAAAA AAAAAAABAAABABBBAABAAABAAAAAAA AAAAAAAABABAAAAABABABABAAAAAAA AAAAAAAAABAAAAAABABABABAAAAAAA AAAAAAAABABAAAAABABABABAAAAAAA BAAAAAABAAABABBBAABBABBAAAAAAB ABAAAAAAAAAAAAAAAAAAAAAAAAAABA BABAAAAAAAAAAAAAAAAAAAAAAAABAB -BABAAAAAAAAAAAAAAAAAAAAAABAB- --BABAAAAAAAAAAAAAAAAAAAABAB-- ---BABAAAAAAAAAAAAAAAAAABAB--- ----BABAAAAAAABBAAAAAAABAB---- ----BABAAAAAAB--BAAAAAABAB---- ----BABAAAAAB----BAAAAABAB---- ----BABAAAAB------BAAAABAB---- ----BABAAAB--------BAAABAB---- ----BBBBBB----------BBBBBB---- 
