model
size = 30 26 10, scale = 0.05, origin = -y
material 
  colors = A:#FCFAF2 B:#111 C:#FFFFFB
voxels
--BBBBBBBBBBB----BBBBBBBBBBB-- --BAAAAAAAAAA----AAAAAAAAAAB-- --BABBBBBBBBB----BBBBBBBBBAB-- -BBABAAAAAAAAA--AAAAAAAAABABB- -BAABAAAAAAAAA--AAAAAAAAABAAB- BBABBAAAAAAAAAAAAAAAAAAAABBABB AAABAAAAAAAAAAAAAAAAAAAAAABAAA BBBBAAAAAAAAAAAAAAAAAAAAAABBBB AAAAAAAAAAAAAAAAAAAAAAAAAAAAAA -AAAAAAAAAAAAAAAAAAAAAAAAAAAA- -AAAAAAAAAAAAAAAAAAAAAAAAAAAA- -AAAAAAAAAAAAAAAAAAAAAAAAAAAA- -AAAAAAAAAAAAAACAAAAAAAAAACAA- -AAACACBCAABCCBBBABCAABAAACAA- -AAACACBCBCBCBAACACBABAAAACAA- --AACACBCBCBABAACCAABAAAAACA-- --AACACBCBCBABAACACBABAAAACA-- --AACCABBABBCCBBBABCAABAAACA-- --AAAAAAAAAAAAAACAAAAAAAAACA-- --AAAAAAAAAAAAAAACAAAAAAAAAA-- --AAAAAAAAAAAAAAACCAAAAAAAAA-- ---AAAAAAAAAAAAAAAAAAAAAAAA--- ---BBBBBBBBBBBBBBBBBBBBBBBB--- ---CCCCCCCCCCCCCCCCCCCCCCCC--- ---BBBBBBBBBBBBBBBBBBBBBBBB--- ---BBBBBBBBBBBBBBBBBBBBBBBB--- 
--B------------------------B-- --B------------------------B-- --B------------------------B-- -B--------------------------B- -B--------------------------B- B----------------------------B A----------------------------A B----------------------------B AA--------------------------AA -A--------------------------A- -A--------------------------A- -A--------------------------A- -A--------------------------A- -A--------------------------A- -AA------------------------AA- --A------------------------A-- --A------------------------A-- --A------------------------A-- --A------------------------A-- --A------------------------A-- --A------------------------A-- ---A----------------------A--- ---B----------------------B--- ---C----------------------C--- ---B----------------------B--- ---B----------------------B--- 
--B------------------------B-- --B------------------------B-- --B------------------------B-- -B--------------------------B- -B--------------------------B- B----------------------------B B----------------------------B B----------------------------B BB--------------------------BB -B--------------------------B- -B--------------------------B- -B--------------------------B- -B--------------------------B- -B--------------------------B- -BB------------------------BB- --B------------------------B-- --B------------------------B-- --B------------------------B-- --B------------------------B-- --B------------------------B-- --B------------------------B-- ---B----------------------B--- ---B----------------------B--- ---B----------------------B--- ---B----------------------B--- ---B----------------------B--- 
--B------------------------B-- --B------------------------B-- --B------------------------B-- -B--------------------------B- -B--------------------------B- B----------------------------B B----------------------------B B----------------------------B BB--------------------------BB -B--------------------------B- -B--------------------------B- -B--------------------------B- -B--------------------------B- -B--------------------------B- -BB------------------------BB- --B------------------------B-- --B------------------------B-- --B------------------------B-- --B------------------------B-- --B------------------------B-- --B------------------------B-- ---B----------------------B--- ---B----------------------B--- ---B----------------------B--- ---B----------------------B--- ---B----------------------B--- 
--B------------------------B-- --B------------------------B-- --B------------------------B-- -B--------------------------B- -B--------------------------B- B----------------------------B A----------------------------A B----------------------------B AA--------------------------AA -A--------------------------A- -A--------------------------A- -A--------------------------A- -A--------------------------A- -A--------------------------A- -AA------------------------AA- --A------------------------A-- --A------------------------A-- --A------------------------A-- --A------------------------A-- --A------------------------A-- --A------------------------A-- ---A----------------------A--- ---B----------------------B--- ---C----------------------C--- ---B----------------------B--- ---B----------------------B--- 
--B------------------------B-- --B------------------------B-- --B------------------------B-- -B--------------------------B- -B--------------------------B- B----------------------------B A----------------------------A B----------------------------B AA--------------------------AA -A--------------------------A- -A--------------------------A- -A--------------------------A- -A--------------------------A- -A--------------------------A- -AA------------------------AA- --A------------------------A-- --A------------------------A-- --A------------------------A-- --A------------------------A-- --A------------------------A-- --A------------------------A-- ---A----------------------A--- ---B----------------------B--- ---C----------------------C--- ---B----------------------B--- ---B----------------------B--- 
--B------------------------B-- --B------------------------B-- --B------------------------B-- -B--------------------------B- -B--------------------------B- B----------------------------B B----------------------------B B----------------------------B BB--------------------------BB -B--------------------------B- -B--------------------------B- -B--------------------------B- -B--------------------------B- -B--------------------------B- -BB------------------------BB- --B------------------------B-- --B------------------------B-- --B------------------------B-- --B------------------------B-- --B------------------------B-- --B------------------------B-- ---B----------------------B--- ---B----------------------B--- ---B----------------------B--- ---B----------------------B--- ---B----------------------B--- 
--B------------------------B-- --B------------------------B-- --B------------------------B-- -B--------------------------B- -B--------------------------B- B----------------------------B B----------------------------B B----------------------------B BB--------------------------BB -B--------------------------B- -B--------------------------B- -B--------------------------B- -B--------------------------B- -B--------------------------B- -BB------------------------BB- --B------------------------B-- --B------------------------B-- --B------------------------B-- --B------------------------B-- --B------------------------B-- --B------------------------B-- ---B----------------------B--- ---B----------------------B--- ---B----------------------B--- ---B----------------------B--- ---B----------------------B--- 
--B------------------------B-- --B------------------------B-- --B------------------------B-- -B--------------------------B- -B--------------------------B- B----------------------------B A----------------------------A B----------------------------B AA--------------------------AA -A--------------------------A- -A--------------------------A- -A--------------------------A- -A--------------------------A- -A--------------------------A- -AA------------------------AA- --A------------------------A-- --A------------------------A-- --A------------------------A-- --A------------------------A-- --A------------------------A-- --A------------------------A-- ---A----------------------A--- ---B----------------------B--- ---C----------------------C--- ---B----------------------B--- ---B----------------------B--- 
--BBBBBBBBBBB----BBBBBBBBBBB-- --BAAAAAAAAAA----AAAAAAAAAAB-- --BABBBBBBBBB----BBBBBBBBBAB-- -BBABAAAAAAAAA--AAAAAAAAABABB- -BAABAAAAAAAAA--AAAAAAAAABAAB- BBABBAAAAAAAAAAAAAAAAAAAABBABB AAABAAAAAAAAAAAAAAAAAAAAAABAAA BBBBAAAAAAAAAAAAAAAAAAAAAABBBB AAAAAAAAAAAAAAAAAAAAAAAAAAAAAA -AAAAAAAAAAAAAAAAAAAAAAAAAAAA- -AAAAAAAAAAAAAAAAAAAAAAAAAAAA- -AAAAAAAAAAAAAAAAAAAAAAAAAAAA- -AAAAAAAAAAAAAAAAAAAAAAAAAAAA- -AAAAAABAAABABBBAABAAABAAAAAA- -AAAAAAABABAAAAABABABABAAAAAA- --AAAAAAABAAAAAABABABABAAAAA-- --AAAAAABABAAAAABABABABAAAAA-- --AAAAABAAABABBBAABBABBAAAAA-- --AAAAAAAAAAAAAAAAAAAAAAAAAA-- --AAAAAAAAAAAAAAAAAAAAAAAAAA-- --AAAAAAAAAAAAAAAAAAAAAAAAAA-- ---AAAAAAAAAAAAAAAAAAAAAAAA--- ---BBBBBBBBBBBBBBBBBBBBBBBB--- ---CCCCCCCCCCCCCCCCCCCCCCCC--- ---BBBBBBBBBBBBBBBBBBBBBBBB--- ---BBBBBBBBBBBBBBBBBBBBBBBB--- 
