model
size = 26 28 26, scale = 0.05, origin = -y
material 
  colors = A:#AAA B:#888 C:#555 D:#222 E:#BBB F:#777 G:#111 H:#E00 I:#FF0
voxels
-------------------------- -------------------------- -------------------------- -------------------------- -------------------------- -------------------------- -------------------------- -------------------------- ---------CCCCCCCC--------- ---------CCCCCCCC--------- ----------HHHHHH---------- -----------HHHH----------- -------------------------- -------------------------- -------------------------- -------------------------- -------------------------- -------------------------- -------------------------- -------------------------- -------------------------- -------------------------- -------------------------- -------------------------- -------------------------- -------------------------- -------------------------- -------------------------- 
-------------------------- -------------------------- -------------------------- --------BBBBBBBBBB-----G-- --------BA-A-A-A-B-------- G-------B-A-A-A-AB-----G-- -------BBBBBBBBBBBB------- -G-----AAAAAAAAAAAA---G--- -------CCAAAAAAAACC------- ---G---CCAAAAAAAACC-G----- -----G-GCCAAAAAACCG------- --------GCCAAAACCG-G------ ------G--CCCCCCCC----G---- -----------CCCC----------- ----G------------------G-- -------------------------- ---G--------------------G- -------------------------- ---G---------------------- -------------------------- -------------------------- -------------------------- -------------------------- -------------------------- -------------------------- -------------------------- -------------------------- -------------------------- 
-------------------------- -------------------------- -------------------------- -------------------------- -------------------------- -------------------------- -----BBBBBBBBBBBBBBBB----- -----AAAAAAAAAAAAAAAA----- -----CCAAAAAAAAAAAACC----- ------CCAAAAAAAAAAAC------ ------CCAAAAAAAAAACC------ -------CAAAAAAAAAAC------- -------CCAAAAAAAACC------- --------CCCAAAACCC-------- ----------CCCCCC---------- ------------CC------------ -------------------------- -------------------------- -------------------------- -------------------------- -------------------------- -------------------------- -------------------------- -------------------------- -------------------------- -------------------------- -------------------------- -------------------------- 
-------------------------- -------------------------- -------------------------- -------------------------- -------------------------- -------------------------- ----BBBBB-------BBBBBB---- ----AAAAA-------AAAAAA---- ----CCCAA-------AAACCC---- ----CCCAA-------AAACCC---- -----CCAA-------AAACC----- -----CCAA-------AAACC----- ------CAA-------AAAC------ -------CADDDDDDDAAC------- --------HHAAAAAAHH-------- ---------HHCCCCHHH-------- -----------CCCC----------- -------------------------- -------------------------- -------------------------- -------------------------- -------------------------- -------------------------- -------------------------- -------------------------- -------------------------- -------------------------- -------------------------- 
-------------------------- -------------------------- -------------------------- -------------------------- -------------------------- -------------------------- ---BBBB-----------BBBBB--- ---AAAA-----------AAAAA--- ---CAAA-----------ACCCC--- ---CAAA-----------ACCCC--- ----CAA-----------ACCC---- ----CAA-----------ACCC---- -----CA-----------ACC----- ------CDDDDDDDDDDDAC------ ------CIAAAAAAAAAAIC------ --------HAAAAAAAAH-------- --------HAHAAAAHAH-------- -----------CCCC----------- -------------------------- -------------------------- -------------------------- -------------------------- -------------------------- -------------------------- -------------------------- -------------------------- -------------------------- -------------------------- 
-------------------------- -------------------------- -------------------------- -------------------------- -------------------------- -------------------------- --BBBB-------------BBBBB-- --AAAA-------------AAAAA-- --CAAA-------------AAAAC-- ---CAA-------------AAAC--- ---CAA-------------AAAC--- ---CAA-------------AAAC--- ----CA-------------AAC---- -----EDDDDDDDDDDDDDAE----- -----EAIAAAAAAAAAAAAE----- ------IIAAAAAAAAAAII------ --------HAAAAAAAAH-------- --------HHHCCCCHHH-------- ------------CC------------ -------------------------- -------------------------- -------------------------- -------------------------- -------------------------- -------------------------- -------------------------- -------------------------- -------------------------- 
-------------------------- -------------------------- -------------------------- -------------------------- -------------------------- -------------------------- --BBB---------------BBBB-- --AAA---------------AAAA-- --CAA---------------AAAC-- --CAA---------------AAAC-- --CAA---------------AAAC-- ---CA---------------AAC--- ---CCD--------------ACC--- ----ECDDDDDDDDDDDDDDAE---- ----EAAIAAAAAAAAAAAAAE---- -----EAIAAAAAAAAAAAAE----- ------IIAAAAAAAAAAII------ --------HCAAAAAACH-------- ----------CCCCCC---------- -------------------------- -------------------------- -------------------------- -------------------------- -------------------------- -------------------------- -------------------------- -------------------------- -------------------------- 
-------------------------- -------------------------- -------------------------- -------------------------- -------------------------- -------------------------- -BB------------------BBBB- -AA------------------AAAA- -EAA-----------------AAAE- -EAA-----------------AAAE- --CA-----------------AAC-- --CA-----------------AAC-- --CADD---------------ACC-- ---ECCDDDDDDDDDDDDDDDCE--- ----EAAIAAAAAAAAAAAAAE---- -----EAIAAAAAAAAAAAAE----- ------IIAAAAAAAAAAAI------ -------IAAAAAAAAAAI------- --------CCCAAAACCC-------- -----------FCCF----------- -------------------------- -------------------------- -------------------------- -------------------------- -------------------------- -------------------------- -------------------------- -------------------------- 
-------------------------- -------------------------- -------------------------- -------------------------- -------------------------- -------------------------- -BB-------------------BBB- -AA-------------------AAA- -EA-------------------AAE- -EA-------------------AAE- -EA-------------------AAE- -EA-------------------AAE- --C------------------ACC-- --CDDDDDDDDDDDDDDDDDDCCC-- ---EAAAAAAAAAAAAAAAAAAE--- ----EAAAAAAAAAAAAAAAAE---- -----EAAAAAAAAAAAAAAE----- ------IAAAAAAAAAAAAI------ -------CCAAAAAAAACC------- ---------FFFFFFFF--------- -------------------------- -------------------------- -------------------------- -------------------------- -------------------------- -------------------------- -------------------------- -------------------------- 
-------------------------- -------------------------- -------------------------- -------------------------- -------------------------- -------------------------- BBB-------------------BBBB AAA-------------------AAAA EAA-------------------AAAE EAA-------------------AAAE -EA-------------------AAE- -EA-------------------AAE- -EA-------------------AAE- --CDDDDDDDDDDDDDDDDDDDAC-- ---CAAAAAAAAAAAAAAAAAAC--- ---CAAAAAAAAAAAAAAAAAAC--- ----CAAAAAAAAAAAAAAAAC---- -----CCAAAAAAAAAAAACC----- -------BAAAAAAAAAAB------- --------FFFAAAAFFF-------- -----------FFFF----------- -------------------------- -------------------------- -------------------------- -------------------------- -------------------------- -------------------------- -------------------------- 
-------------------------- -------------------------- -------------------------- -------------------------- -------------------------- -------------------------- AB---------------------BBA AA---------------------AAA EA---------------------AAE EA---------------------AAE EA---------------------AAE -E---------------------AE- -E---------------------AE- --CDDDDDDDDDDDDDDDDDDDDC-- --CAAAAAAAAAAAAAAAAAAAAC-- ---CAAAAAAAAAAAAAAAAAAC--- ----CAAAAAAAAAAAAAAAAC---- -----CAAAAAAAAAAAAAAC----- ------BBAAAAAAAAAABB------ --------FFAAAAAAFF-------- ----------FFFFFF---------- -------------------------- -------------------------- -------------------------- -------------------------- -------------------------- -------------------------- -------------------------- 
-------------------------- -------------------------- -------------------------- -------------------------- A------------------------A A------------------------A AB---------------------BBA FA---------------------AAA EA---------------------AAF EA---------------------AAE EA---------------------AAE EA---------------------AAE -E---------------------AE- -EDDDDDDDDDDDDDDDDDDDDDAE- --EAAAAAAAAAAAAAAAAAAAAE-- ---BAAAAAAAAAAAAAAAAAAB--- ---BAAAAAAAAAAAAAAAAAAB--- ----BBAAAAAAAAAAAAAABB---- ------BAAAAAAAAAAAAB------ -------FFAAAAAAAAFF------- ---------FFFFFFFF--------- -------------------------- -------------------------- -------------------------- -------------------------- -------------------------- -------------------------- -------------------------- 
A------------------------A A------------------------A A------------------------A A------------------------A A------------------------A F------------------------A AB---------------------BBF AA---------------------AAA EA---------------------AAE EA---------------------AAE EA---------------------AAE EA---------------------AAE -E---------------------AE- -EDDDDDDDDDDDDDDDDDDDDDAE- --EAAAAAAAAAAAAAAAAAAAAE-- --EAAAAAAAAAAAAAAAAAAAAE-- ---BAAAAAAAAAAAAAAAAAAB--- ----BAAAAAAAAAAAAAAAAB---- -----BBAAAAAAAAAAAABB----- -------FFAAAAAAAAFF------- ---------FFFFFFFF--------- -------------------------- -------------------------- -------------------------- -------------------------- -------------------------- -------------------------- -------------------------- 
A------------------------A A------------------------A A------------------------A A------------------------A A------------------------A A------------------------A AB---------------------BBA AA---------------------AAA EA---------------------AAE FA---------------------AAE EA---------------------AAF EA---------------------AAE -E---------------------AE- -EDDDDDDDDDDDDDDDDDDDDDAE- --EAAAAAAAAAAAAAAAAAAAAE-- --EAAAAAAAAAAAAAAAAAAAAE-- ---AAAAAAAAAAAAAAAAAAAB--- ---BAAAAAAAAAAAAAAAAAAB--- ---BBBAAAAAAAAAAAAAAAAB--- ---BGGGAAAAAAAAAAAAGGGB--- ---BGGGGBAFFFFFFABGGGGB--- ---BGGGGBB------BBGGGGB--- ---BBGGGBB------BBGGGBB--- ---BBGGBBB------BBBGGBB--- ---BBBGBBB------BBBGBBB--- ----BBBBB--------BBBBB---- -----BBB----------BBB----- ------B------------B------ 
-------------------------- -------------------------- -------------------------- -------------------------- A------------------------A A------------------------A AB---------------------BBA FA---------------------AAA EA---------------------AAF EA---------------------AAE EA---------------------AAE EA---------------------AAE -E---------------------AE- -EDDDDDDDDDDDDDDDDDDDDDAE- --EAAAAAAAAAAAAAAAAAAAAE-- ---BAAAAAAAAAAAAAAAAAAA--- ---BAAAAAAAAAAAAAAAAAAB--- ----BBAAAAAAAAAAAAAABB---- ------BAAAAAAAAAAAAB------ -------BBAAAAAAAABB------- ---------FFFFFFFF--------- -------------------------- -------------------------- -------------------------- -------------------------- -------------------------- -------------------------- -------------------------- 
-------------------------- -------------------------- -------------------------- -------------------------- -------------------------- -------------------------- AB---------------------BBA AA---------------------AAA EA---------------------AAE EA---------------------AAE EA---------------------AAE -E---------------------AE- -E---------------------AE- --EDDDDDDDDDDDDDDDDDDDDE-- --EAAAAAAAAAAAAAAAAAAAAE-- ---BAAAAAAAAAAAAAAAAAAB--- ----BAAAAAAAAAAAAAAAAA---- -----BAAAAAAAAAAAAAABB---- ------BBAAAAAAAAAABB------ --------BBAAAAAABB-------- ----------FFFFFF---------- -------------------------- -------------------------- -------------------------- -------------------------- -------------------------- -------------------------- -------------------------- 
BA---------------------AAB BA---------------------AAB BA---------------------AAB BA---------------------AAB BA---------------------AAB BB---------------------BBB BB---------------------BBB AA---------------------AAA EA---------------------AAE EA---------------------AAE -E---------------------AE- -E---------------------AE- -E---------------------AE- --EDDDDDDDDDDDDDDDDDDDDC-- ---BAAAAAAAAAAAAAAAACCC--- ---BAAAAAAAAAAAAAAAACCC--- ----BAAAAAAAAAAAAAAACC---- -----BBAAAAAAAAAAAACC----- -------BAAAAAAAAAAB------- --------BBBAAAABBB-------- -----------FFFF----------- -------------------------- -------------------------- -------------------------- -------------------------- -------------------------- -------------------------- -------------------------- 
--A-------------------BA-- --A-------------------BA-- --A-------------------BA-- --A-------------------BA-- --A-------------------BA-- -BB-------------------BBB- -BB-------------------BBB- -AB-------------------AAA- -EA-------------------AAE- -EA-------------------AAE- -EA-------------------AAE- -EA-------------------AAE- --C-------------------CC-- --CDDDDDDDDDDDDDDDDDDDCC-- ---CCCCAAAAAAAAAAAACCCC--- ----CCCAAAAAAAAAAAACCC---- -----CCAAAAAAAAAAAACC----- ------CAAAAAAAAAAAAC------ -------BBAAAAAAAABB------- ---------BBBBBBBB--------- -------------------------- -------------------------- -------------------------- -------------------------- -------------------------- -------------------------- -------------------------- -------------------------- 
-BBB------------------AAB- -BBB------------------AAB- -BBB------------------AAB- -BBB------------------AAB- -BBB------------------AAB- -BBB------------------BBB- -BBB------------------BBB- -AAA------------------AAA- -EAA------------------AAE- -EAA------------------AAE- --CA------------------AE-- --CA------------------AE-- --CA------------------CC-- ---CDDDDDDDDDDDDDDDDDDC--- ----CCCCAAAAAAAAAACCCC---- -----CCCAAAAAAAAAACCC----- ------CCAAAAAAAAAACC------ -------CAAAAAAAAAAC------- --------BBBAAAABBB-------- -----------BBBB----------- -------------------------- -------------------------- -------------------------- -------------------------- -------------------------- -------------------------- -------------------------- -------------------------- 
---AB----------------BA--- ---AB----------------BA--- ---AB----------------BA--- ---AB----------------BA--- ---AB----------------BA--- --BBB----------------BBB-- --BBB----------------BBB-- --AAA----------------AAA-- --CAA----------------AAE-- --CAA----------------AAE-- --CAA----------------AAE-- ---CA----------------AC--- ---CA----------------CC--- ----CDDDDDDDDDDDDDDDDC---- ----CCCCCAAAAAAAACCCCC---- -----CCCCAAAAAAAACCCC----- ------CCCAAAAAAAACCC------ --------CCAAAAAACC-------- ----------BBBBBB---------- -------------------------- -------------------------- -------------------------- -------------------------- -------------------------- -------------------------- -------------------------- -------------------------- -------------------------- 
--ABBB--------------BBBB-- --ABBB--------------BBBB-- --ABBB--------------BBBB-- --ABBB--------------BBBB-- --ABBB--------------BBBB-- --BBBB--------------BBBB-- --BBBB--------------BBBB-- --AAAA--------------AAAA-- --CAAA--------------AAAE-- ---CAA--------------AAC--- ---CAA--------------AAC--- ---CAA--------------AAC--- ---CCA--------------CC---- -----CDDDDDDDDDDDDDDC----- -----CAACCCCCCCCCCCAC----- ------CCCCCCCCCCCCCC------ --------CCCCCCCCCC-------- ---------CCCCCCCC--------- ------------CC------------ -------------------------- -------------------------- -------------------------- -------------------------- -------------------------- -------------------------- -------------------------- -------------------------- -------------------------- 
---BBBB------------BBBA--- ---BBBB------------BBBA--- ---BBBB------------BBBA--- ---BBBB------------BBBA--- ---BBBB------------BBBA--- ---BBBB------------BBBB--- ---BBBB------------BBBB--- ---AAAA------------AAAA--- ---CAAA------------AACC--- ---CAAA------------AACC--- ---CCAA------------AAC---- ---CCAA------------AAC---- ----CCA------------CC----- ------CDDDDDDDDDDDDC------ ------CCCCCCCCCCCCCC------ --------CCCCCCCCCC-------- ---------CCCCCCCC--------- -----------CCCC----------- -------------------------- -------------------------- -------------------------- -------------------------- -------------------------- -------------------------- -------------------------- -------------------------- -------------------------- -------------------------- 
----ABAB----------AABB---- ----ABAB----------AABB---- ----ABAB----------AABB---- ----ABAB----------AABB---- ----ABAB----------AABB---- ----BBBB----------BBBB---- ----BBBB----------BBBB---- ----AAAA----------AAAA---- ----CAAA----------AAAC---- ----CCAA----------AACC---- ----CCAA----------AAC----- ----CCCA----------ACC----- -----CCA----------CC------ -------CDDDDDDDDDDC------- --------CCCCCCCCCC-------- ---------CCCCCCCC--------- -----------CCCC----------- -------------------------- -------------------------- -------------------------- -------------------------- -------------------------- -------------------------- -------------------------- -------------------------- -------------------------- -------------------------- -------------------------- 
-----B-BA-------BAA-B----- -----B-BA-------BAA-B----- -----B-BA-------BAA-B----- -----B-BA-------BAA-B----- -----B-BA-------BAA-B----- -----BBBB-------BBBBB----- -----BBBB-------BBBBB----- -----AAAA-------AAAAA----- -----CCAA-------AAACC----- -----CCAA-------AAAC------ -----CCCA-------AACC------ -----CCCA-------AAC------- -------CC-------CCC------- --------CCCDDDDCCC-------- ----------CCCCCC---------- ------------CC------------ -------------------------- -------------------------- -------------------------- -------------------------- -------------------------- -------------------------- -------------------------- -------------------------- -------------------------- -------------------------- -------------------------- -------------------------- 
-------B-BBABBABB-B------- -------B-BBABBABB-B------- -------B-BBABBABB-B------- -------B-BBABBABB-B------- -------B-BBABBABB-B------- -------BBBBBBBBBBBB------- -------BBBBBBBBBBBB------- -------AAAAAAAAAAAA------- -------CCAAAAAAAACC------- -------CCAAAAAAAACC------- -------CCCAAAAAACC-------- -------CCCCAAAACCC-------- -------C-CCCCCCCC--------- -----------CCCC----------- -------------------------- -------------------------- -------------------------- -------------------------- -------------------------- -------------------------- -------------------------- -------------------------- -------------------------- -------------------------- -------------------------- -------------------------- -------------------------- -------------------------- 
-------------------------- -------------------------- -------------------------- -------------------------- -------------------------- -------------------------- -------------------------- -------------------------- ---------CCCCCCCC--------- ---------CCCCCCCC--------- ----------CCCCCC---------- -----------CCCC----------- -------------------------- -------------------------- -------------------------- -------------------------- -------------------------- -------------------------- -------------------------- -------------------------- -------------------------- -------------------------- -------------------------- -------------------------- -------------------------- -------------------------- -------------------------- -------------------------- 
