model
size = 20 24 32, scale = 0.05, origin = -y
material 
  colors = A:#D2D2D2 B:#D9CDC1 C:#9AA9BC D:#7D0028 E:#000 F:#84492C G:#8E695F H:#BB25A2 I:#F5E5D8 J:#71F7B2 K:#2F2641 L:#FFF M:#EDE8FF N:#FDA228 O:#FFE888 P:#990027
voxels
118-N38-3J17-3H418-N19-J18-3J2(17-3H)301-2C4A14-2C6A2C10-8A2C5A2(5-15A)2-JE-10A2C3A2-L2-10A2C3A-3J-15A-3H-A2C12A-3H-3(A2C3A14-)C5A3(14-C4AC)14-C5A154-2C4A14-2C8A10-14A4G2-14AG-JK2-14AG-JL2-15A2-L2-15A-3J2(-15A-3H)-3(6A14-)C5A3(14-C4AC)14-C5A14-6A134-2C4A14-2C8A10-14A4G2(2-14AG-GK)2-15A2-K2-15A-JK2-2(15A-3H-)3(6A14-)C5A3(14-C4AC)14-C5A14-6A14-5A115-2C4A14-2C8A10-14A4G2(2-14AG-GM)2-15A2-J2-15A-2J2-2(15A-3H-)3(6A14-)5(C5A14-)2(6A14-)6A94-2C4A14-2C8A10-15A3G2(2-15A-GJ)2-7A3C5A2-O2-7A3C5A-2J2-2(15A-3H-)3(6A14-)5(C5A14-)3(6A14-)6A74-6A54-A19-A16-O2-A16-P2-3(A15-3H-)3(A5E14-)5(C5E14-)3(A5E14-)3ABAE17-B153-E142-C3B16-C5B14-C2A3B2(14-C5A)14-3A2BA4(14-6B)151-E102-2A18-4A16-C3B16-C5B14-C2A3B2(14-C5A)14-6A14-4(4BA15-)4AE16-2A18-A3(17-3A)17-4A14-E-6(4A16-)6AC13-2C4AC2(13-2C2A3B)2(13-2C5A)13-7A13-2(A4BA14-)2(A4BE14-)5AE14-5A2C13-A3DA2C4(13-A2D4A)11-E-A2D4A5(13-A2DA3B)13-A2D2(3AC13-2CD)2(A3B13-2CD)4A13-2CD4A13-A5DA13-2(A4BI14-)A4BE14-A4BI14-A4FI14-5A2C13-3ADA2C4(13-7A)11-E-7A5(13-4A3B)2(13-7A)2(13-4A3B)2(13-A2D4A)13-A5DA13-2(A4BI14-)A4BE14-A4BI14-A4FI14-5(7A13-)7A11-E-8(7A13-)2(4A3B13-)2(7A13-)A5DA13-A4D2(I14-A4F)E2(14-A4FI)14-5(7A13-)7A11-E-8(7A13-)2(4A3B13-)2(7A13-)A5DA13-A4DI14-A4FE3(14-A4FI)14-5(7A13-)7A11-E-12(7A13-)A5DA13-A4D2(I14-A3FD)E2(14-A2F2DI)14-3(7A13-)2(6AC13-)6AC11-E-2(6AC13-)10(7A13-)A5DA13-A4D2(I14-A3FD)E14-A3FDI14-A4FI14-3(7A13-)2(6AC13-)C5AC11-E-2(C5AC13-)8(7A13-)2(6AC13-)A5DA13-A4D2(I14-AB3F)E14-AB3FE14-A4FI14-3(7A13-)2(6AC13-)C5AC11-E-2(C5AC13-)8(7A13-)6AC13-AD4AC13-A5DA13-A4D3(2I13-AB3F)E14-A4FI14-5(7A13-)C6A11-E-3(C6A13-)2(A6B13-)3(7A13-)A6B3(13-7A)2(13-3A3DA)2(13-ABA3FA)13-ABA2FE14-3A2FE14-7A3(13-3A2D2A)13-3A3DA13-C2A3DA11-E-2(C2A3DA13-)3A3DA2(13-A6B)13-3A3DA13-3AD3A13-3A3DE13-A5B2(E13-6A)2(E13-3A3D)E13-3A2D3(BE13-ABA2F)B152-E187-A3(15-5A)2(15-3A2B)15-5A55-2A18-A95-E187-A6(15-5A)55-5A15-4A16-3(3A6-6A2G3-)3A6-6A-E3-3(3A6-6A5-)6(3A17-)6(6A14-)6A54-2(6A14-)3(15A2G3-)15A-E3-3(15A5-)12(6A14-)6A54-2(6A14-)2(15A2G3-)14AC2G3-14AC-E3-3(15A5-)10(6A14-)6A94-2(6A14-)3(15A2G3-)15A-E3-3(15A5-)9(6A14-)6A114-6A14-2A2C2A14-2A2C11A2(G4-15A)G4-9A3C3A-E3-9A3C3A2(5-15A)5-2(6A14-)4(A2C3A14-)6A14-6A270-3(E479-)E361-
